{
  "version": 8,
  "blockIdVersion": 11,
  "anchorX": 0,
  "anchorY": 4,
  "anchorZ": -3,
  "blocks": [
    {
      "x": -10,
      "y": 0,
      "z": -3,
      "name": "Cloth_Block_Wool_Blue"
    },
    {
      "x": -10,
      "y": 1,
      "z": -3,
      "name": "Cloth_Block_Wool_Blue"
    },
    {
      "x": -10,
      "y": 2,
      "z": -3,
      "name": "Cloth_Block_Wool_Blue"
    },
    {
      "x": -10,
      "y": 3,
      "z": -3,
      "name": "Cloth_Block_Wool_Blue"
    },
    {
      "x": -10,
      "y": 4,
      "z": -3,
      "name": "Cloth_Block_Wool_Blue"
    },
    {
      "x": -10,
      "y": 5,
      "z": -3,
      "name": "Cloth_Block_Wool_Blue"
    },
    {
      "x": -10,
      "y": 6,
      "z": -3,
      "name": "Cloth_Block_Wool_Blue"
    },
    {
      "x": -10,
      "y": 7,
      "z": -3,
      "name": "Cloth_Block_Wool_Blue"
    },
    {
      "x": -10,
      "y": 8,
      "z": -3,
      "name": "Cloth_Block_Wool_Blue"
    },
    {
      "x": -10,
      "y": 9,
      "z": -3,
      "name": "Cloth_Block_Wool_Blue"
    },
    {
      "x": -10,
      "y": 10,
      "z": -3,
      "name": "Cloth_Block_Wool_Blue"
    },
    {
      "x": -10,
      "y": 11,
      "z": -3,
      "name": "Cloth_Block_Wool_Blue"
    },
    {
      "x": -10,
      "y": 12,
      "z": -3,
      "name": "Cloth_Block_Wool_Blue"
    },
    {
      "x": -10,
      "y": 13,
      "z": -3,
      "name": "Cloth_Block_Wool_Blue"
    },
    {
      "x": -10,
      "y": 14,
      "z": -3,
      "name": "Cloth_Block_Wool_Blue"
    },
    {
      "x": -10,
      "y": 15,
      "z": -3,
      "name": "Cloth_Block_Wool_Blue"
    },
    {
      "x": -10,
      "y": 16,
      "z": -3,
      "name": "Cloth_Block_Wool_Blue"
    },
    {
      "x": -10,
      "y": 17,
      "z": -3,
      "name": "Cloth_Block_Wool_Blue"
    },
    {
      "x": -10,
      "y": 18,
      "z": -3,
      "name": "Cloth_Block_Wool_Blue"
    },
    {
      "x": -10,
      "y": 19,
      "z": -3,
      "name": "Cloth_Block_Wool_Blue"
    },
    {
      "x": -10,
      "y": 20,
      "z": -3,
      "name": "Cloth_Block_Wool_Blue"
    },
    {
      "x": -10,
      "y": 21,
      "z": -3,
      "name": "Cloth_Block_Wool_Blue"
    },
    {
      "x": -10,
      "y": 22,
      "z": -3,
      "name": "Cloth_Block_Wool_Blue"
    },
    {
      "x": -10,
      "y": 23,
      "z": -3,
      "name": "Cloth_Block_Wool_Blue"
    },
    {
      "x": -10,
      "y": 24,
      "z": -3,
      "name": "Cloth_Block_Wool_Blue"
    },
    {
      "x": -10,
      "y": 25,
      "z": -3,
      "name": "Cloth_Block_Wool_Blue"
    },
    {
      "x": -10,
      "y": 0,
      "z": -2,
      "name": "Cloth_Block_Wool_Blue"
    },
    {
      "x": -10,
      "y": 1,
      "z": -2,
      "name": "Cloth_Block_Wool_Blue"
    },
    {
      "x": -10,
      "y": 2,
      "z": -2,
      "name": "Cloth_Block_Wool_Blue"
    },
    {
      "x": -10,
      "y": 3,
      "z": -2,
      "name": "Cloth_Block_Wool_Blue"
    },
    {
      "x": -10,
      "y": 4,
      "z": -2,
      "name": "Cloth_Block_Wool_Blue"
    },
    {
      "x": -10,
      "y": 5,
      "z": -2,
      "name": "Cloth_Block_Wool_Blue"
    },
    {
      "x": -10,
      "y": 6,
      "z": -2,
      "name": "Cloth_Block_Wool_Blue"
    },
    {
      "x": -10,
      "y": 7,
      "z": -2,
      "name": "Cloth_Block_Wool_Blue"
    },
    {
      "x": -10,
      "y": 8,
      "z": -2,
      "name": "Cloth_Block_Wool_Blue"
    },
    {
      "x": -10,
      "y": 9,
      "z": -2,
      "name": "Cloth_Block_Wool_Blue"
    },
    {
      "x": -10,
      "y": 10,
      "z": -2,
      "name": "Cloth_Block_Wool_Blue"
    },
    {
      "x": -10,
      "y": 11,
      "z": -2,
      "name": "Cloth_Block_Wool_Blue"
    },
    {
      "x": -10,
      "y": 12,
      "z": -2,
      "name": "Cloth_Block_Wool_Blue"
    },
    {
      "x": -10,
      "y": 13,
      "z": -2,
      "name": "Cloth_Block_Wool_Blue"
    },
    {
      "x": -10,
      "y": 14,
      "z": -2,
      "name": "Cloth_Block_Wool_Blue"
    },
    {
      "x": -10,
      "y": 15,
      "z": -2,
      "name": "Cloth_Block_Wool_Blue"
    },
    {
      "x": -10,
      "y": 16,
      "z": -2,
      "name": "Cloth_Block_Wool_Blue"
    },
    {
      "x": -10,
      "y": 17,
      "z": -2,
      "name": "Cloth_Block_Wool_Blue"
    },
    {
      "x": -10,
      "y": 18,
      "z": -2,
      "name": "Cloth_Block_Wool_Blue"
    },
    {
      "x": -10,
      "y": 19,
      "z": -2,
      "name": "Cloth_Block_Wool_Blue"
    },
    {
      "x": -10,
      "y": 20,
      "z": -2,
      "name": "Cloth_Block_Wool_Blue"
    },
    {
      "x": -10,
      "y": 21,
      "z": -2,
      "name": "Cloth_Block_Wool_Blue"
    },
    {
      "x": -10,
      "y": 22,
      "z": -2,
      "name": "Cloth_Block_Wool_Blue"
    },
    {
      "x": -10,
      "y": 23,
      "z": -2,
      "name": "Cloth_Block_Wool_Blue"
    },
    {
      "x": -10,
      "y": 24,
      "z": -2,
      "name": "Cloth_Block_Wool_Blue"
    },
    {
      "x": -10,
      "y": 25,
      "z": -2,
      "name": "Cloth_Block_Wool_Blue"
    },
    {
      "x": -10,
      "y": 0,
      "z": -1,
      "name": "Cloth_Block_Wool_Blue"
    },
    {
      "x": -10,
      "y": 1,
      "z": -1,
      "name": "Cloth_Block_Wool_Blue"
    },
    {
      "x": -10,
      "y": 2,
      "z": -1,
      "name": "Cloth_Block_Wool_Blue"
    },
    {
      "x": -10,
      "y": 3,
      "z": -1,
      "name": "Cloth_Block_Wool_Blue"
    },
    {
      "x": -10,
      "y": 4,
      "z": -1,
      "name": "Cloth_Block_Wool_Blue"
    },
    {
      "x": -10,
      "y": 5,
      "z": -1,
      "name": "Cloth_Block_Wool_Blue"
    },
    {
      "x": -10,
      "y": 6,
      "z": -1,
      "name": "Cloth_Block_Wool_Blue"
    },
    {
      "x": -10,
      "y": 7,
      "z": -1,
      "name": "Cloth_Block_Wool_Blue"
    },
    {
      "x": -10,
      "y": 8,
      "z": -1,
      "name": "Cloth_Block_Wool_Blue"
    },
    {
      "x": -10,
      "y": 9,
      "z": -1,
      "name": "Cloth_Block_Wool_Blue"
    },
    {
      "x": -10,
      "y": 10,
      "z": -1,
      "name": "Cloth_Block_Wool_Blue"
    },
    {
      "x": -10,
      "y": 11,
      "z": -1,
      "name": "Cloth_Block_Wool_Blue"
    },
    {
      "x": -10,
      "y": 12,
      "z": -1,
      "name": "Cloth_Block_Wool_Blue"
    },
    {
      "x": -10,
      "y": 13,
      "z": -1,
      "name": "Cloth_Block_Wool_Blue"
    },
    {
      "x": -10,
      "y": 14,
      "z": -1,
      "name": "Cloth_Block_Wool_Blue"
    },
    {
      "x": -10,
      "y": 15,
      "z": -1,
      "name": "Cloth_Block_Wool_Blue"
    },
    {
      "x": -10,
      "y": 16,
      "z": -1,
      "name": "Cloth_Block_Wool_Blue"
    },
    {
      "x": -10,
      "y": 17,
      "z": -1,
      "name": "Cloth_Block_Wool_Blue"
    },
    {
      "x": -10,
      "y": 18,
      "z": -1,
      "name": "Cloth_Block_Wool_Blue"
    },
    {
      "x": -10,
      "y": 19,
      "z": -1,
      "name": "Cloth_Block_Wool_Blue"
    },
    {
      "x": -10,
      "y": 20,
      "z": -1,
      "name": "Cloth_Block_Wool_Blue"
    },
    {
      "x": -10,
      "y": 21,
      "z": -1,
      "name": "Cloth_Block_Wool_Blue"
    },
    {
      "x": -10,
      "y": 22,
      "z": -1,
      "name": "Cloth_Block_Wool_Blue"
    },
    {
      "x": -10,
      "y": 23,
      "z": -1,
      "name": "Cloth_Block_Wool_Blue"
    },
    {
      "x": -10,
      "y": 24,
      "z": -1,
      "name": "Cloth_Block_Wool_Blue"
    },
    {
      "x": -10,
      "y": 25,
      "z": -1,
      "name": "Cloth_Block_Wool_Blue"
    },
    {
      "x": -10,
      "y": 0,
      "z": 0,
      "name": "Cloth_Block_Wool_Blue"
    },
    {
      "x": -10,
      "y": 1,
      "z": 0,
      "name": "Cloth_Block_Wool_Blue"
    },
    {
      "x": -10,
      "y": 2,
      "z": 0,
      "name": "Cloth_Block_Wool_Blue"
    },
    {
      "x": -10,
      "y": 3,
      "z": 0,
      "name": "Cloth_Block_Wool_Blue"
    },
    {
      "x": -10,
      "y": 4,
      "z": 0,
      "name": "Cloth_Block_Wool_Blue"
    },
    {
      "x": -10,
      "y": 5,
      "z": 0,
      "name": "Cloth_Block_Wool_Blue"
    },
    {
      "x": -10,
      "y": 6,
      "z": 0,
      "name": "Cloth_Block_Wool_Blue"
    },
    {
      "x": -10,
      "y": 7,
      "z": 0,
      "name": "Cloth_Block_Wool_Blue"
    },
    {
      "x": -10,
      "y": 8,
      "z": 0,
      "name": "Cloth_Block_Wool_Blue"
    },
    {
      "x": -10,
      "y": 9,
      "z": 0,
      "name": "Cloth_Block_Wool_Blue"
    },
    {
      "x": -10,
      "y": 10,
      "z": 0,
      "name": "Cloth_Block_Wool_Blue"
    },
    {
      "x": -10,
      "y": 11,
      "z": 0,
      "name": "Cloth_Block_Wool_Blue"
    },
    {
      "x": -10,
      "y": 12,
      "z": 0,
      "name": "Cloth_Block_Wool_Blue"
    },
    {
      "x": -10,
      "y": 13,
      "z": 0,
      "name": "Cloth_Block_Wool_Blue"
    },
    {
      "x": -10,
      "y": 14,
      "z": 0,
      "name": "Cloth_Block_Wool_Blue"
    },
    {
      "x": -10,
      "y": 15,
      "z": 0,
      "name": "Cloth_Block_Wool_Blue"
    },
    {
      "x": -10,
      "y": 16,
      "z": 0,
      "name": "Cloth_Block_Wool_Blue"
    },
    {
      "x": -10,
      "y": 17,
      "z": 0,
      "name": "Cloth_Block_Wool_Blue"
    },
    {
      "x": -10,
      "y": 18,
      "z": 0,
      "name": "Cloth_Block_Wool_Blue"
    },
    {
      "x": -10,
      "y": 19,
      "z": 0,
      "name": "Cloth_Block_Wool_Blue"
    },
    {
      "x": -10,
      "y": 20,
      "z": 0,
      "name": "Cloth_Block_Wool_Blue"
    },
    {
      "x": -10,
      "y": 21,
      "z": 0,
      "name": "Cloth_Block_Wool_Blue"
    },
    {
      "x": -10,
      "y": 22,
      "z": 0,
      "name": "Cloth_Block_Wool_Blue"
    },
    {
      "x": -10,
      "y": 23,
      "z": 0,
      "name": "Cloth_Block_Wool_Blue"
    },
    {
      "x": -10,
      "y": 24,
      "z": 0,
      "name": "Cloth_Block_Wool_Blue"
    },
    {
      "x": -10,
      "y": 25,
      "z": 0,
      "name": "Cloth_Block_Wool_Blue"
    },
    {
      "x": -10,
      "y": 0,
      "z": 1,
      "name": "Cloth_Block_Wool_Blue"
    },
    {
      "x": -10,
      "y": 1,
      "z": 1,
      "name": "Cloth_Block_Wool_Blue"
    },
    {
      "x": -10,
      "y": 2,
      "z": 1,
      "name": "Cloth_Block_Wool_Blue"
    },
    {
      "x": -10,
      "y": 3,
      "z": 1,
      "name": "Cloth_Block_Wool_Blue"
    },
    {
      "x": -10,
      "y": 4,
      "z": 1,
      "name": "Cloth_Block_Wool_Blue"
    },
    {
      "x": -10,
      "y": 5,
      "z": 1,
      "name": "Cloth_Block_Wool_Blue"
    },
    {
      "x": -10,
      "y": 6,
      "z": 1,
      "name": "Cloth_Block_Wool_Blue"
    },
    {
      "x": -10,
      "y": 7,
      "z": 1,
      "name": "Cloth_Block_Wool_Blue"
    },
    {
      "x": -10,
      "y": 8,
      "z": 1,
      "name": "Cloth_Block_Wool_Blue"
    },
    {
      "x": -10,
      "y": 9,
      "z": 1,
      "name": "Cloth_Block_Wool_Blue"
    },
    {
      "x": -10,
      "y": 10,
      "z": 1,
      "name": "Cloth_Block_Wool_Blue"
    },
    {
      "x": -10,
      "y": 11,
      "z": 1,
      "name": "Cloth_Block_Wool_Blue"
    },
    {
      "x": -10,
      "y": 12,
      "z": 1,
      "name": "Cloth_Block_Wool_Blue"
    },
    {
      "x": -10,
      "y": 13,
      "z": 1,
      "name": "Cloth_Block_Wool_Blue"
    },
    {
      "x": -10,
      "y": 14,
      "z": 1,
      "name": "Cloth_Block_Wool_Blue"
    },
    {
      "x": -10,
      "y": 15,
      "z": 1,
      "name": "Cloth_Block_Wool_Blue"
    },
    {
      "x": -10,
      "y": 16,
      "z": 1,
      "name": "Cloth_Block_Wool_Blue"
    },
    {
      "x": -10,
      "y": 17,
      "z": 1,
      "name": "Cloth_Block_Wool_Blue"
    },
    {
      "x": -10,
      "y": 18,
      "z": 1,
      "name": "Cloth_Block_Wool_Blue"
    },
    {
      "x": -10,
      "y": 19,
      "z": 1,
      "name": "Cloth_Block_Wool_Blue"
    },
    {
      "x": -10,
      "y": 20,
      "z": 1,
      "name": "Cloth_Block_Wool_Blue"
    },
    {
      "x": -10,
      "y": 21,
      "z": 1,
      "name": "Cloth_Block_Wool_Blue"
    },
    {
      "x": -10,
      "y": 22,
      "z": 1,
      "name": "Cloth_Block_Wool_Blue"
    },
    {
      "x": -10,
      "y": 23,
      "z": 1,
      "name": "Cloth_Block_Wool_Blue"
    },
    {
      "x": -10,
      "y": 24,
      "z": 1,
      "name": "Cloth_Block_Wool_Blue"
    },
    {
      "x": -10,
      "y": 25,
      "z": 1,
      "name": "Cloth_Block_Wool_Blue"
    },
    {
      "x": -10,
      "y": 0,
      "z": 2,
      "name": "Cloth_Block_Wool_Blue"
    },
    {
      "x": -10,
      "y": 1,
      "z": 2,
      "name": "Cloth_Block_Wool_Blue"
    },
    {
      "x": -10,
      "y": 2,
      "z": 2,
      "name": "Cloth_Block_Wool_Blue"
    },
    {
      "x": -10,
      "y": 3,
      "z": 2,
      "name": "Cloth_Block_Wool_Blue"
    },
    {
      "x": -10,
      "y": 4,
      "z": 2,
      "name": "Cloth_Block_Wool_Blue"
    },
    {
      "x": -10,
      "y": 5,
      "z": 2,
      "name": "Cloth_Block_Wool_Blue"
    },
    {
      "x": -10,
      "y": 6,
      "z": 2,
      "name": "Cloth_Block_Wool_Blue"
    },
    {
      "x": -10,
      "y": 7,
      "z": 2,
      "name": "Cloth_Block_Wool_Blue"
    },
    {
      "x": -10,
      "y": 8,
      "z": 2,
      "name": "Cloth_Block_Wool_Blue"
    },
    {
      "x": -10,
      "y": 9,
      "z": 2,
      "name": "Cloth_Block_Wool_Blue"
    },
    {
      "x": -10,
      "y": 10,
      "z": 2,
      "name": "Cloth_Block_Wool_Blue"
    },
    {
      "x": -10,
      "y": 11,
      "z": 2,
      "name": "Cloth_Block_Wool_Blue"
    },
    {
      "x": -10,
      "y": 12,
      "z": 2,
      "name": "Cloth_Block_Wool_Blue"
    },
    {
      "x": -10,
      "y": 13,
      "z": 2,
      "name": "Cloth_Block_Wool_Blue"
    },
    {
      "x": -10,
      "y": 14,
      "z": 2,
      "name": "Cloth_Block_Wool_Blue"
    },
    {
      "x": -10,
      "y": 15,
      "z": 2,
      "name": "Cloth_Block_Wool_Blue"
    },
    {
      "x": -10,
      "y": 16,
      "z": 2,
      "name": "Cloth_Block_Wool_Blue"
    },
    {
      "x": -10,
      "y": 17,
      "z": 2,
      "name": "Cloth_Block_Wool_Blue"
    },
    {
      "x": -10,
      "y": 18,
      "z": 2,
      "name": "Cloth_Block_Wool_Blue"
    },
    {
      "x": -10,
      "y": 19,
      "z": 2,
      "name": "Cloth_Block_Wool_Blue"
    },
    {
      "x": -10,
      "y": 20,
      "z": 2,
      "name": "Cloth_Block_Wool_Blue"
    },
    {
      "x": -10,
      "y": 21,
      "z": 2,
      "name": "Cloth_Block_Wool_Blue"
    },
    {
      "x": -10,
      "y": 22,
      "z": 2,
      "name": "Cloth_Block_Wool_Blue"
    },
    {
      "x": -10,
      "y": 23,
      "z": 2,
      "name": "Cloth_Block_Wool_Blue"
    },
    {
      "x": -10,
      "y": 24,
      "z": 2,
      "name": "Cloth_Block_Wool_Blue"
    },
    {
      "x": -10,
      "y": 25,
      "z": 2,
      "name": "Cloth_Block_Wool_Blue"
    },
    {
      "x": -10,
      "y": 0,
      "z": 3,
      "name": "Cloth_Block_Wool_Blue"
    },
    {
      "x": -10,
      "y": 1,
      "z": 3,
      "name": "Cloth_Block_Wool_Blue"
    },
    {
      "x": -10,
      "y": 2,
      "z": 3,
      "name": "Cloth_Block_Wool_Blue"
    },
    {
      "x": -10,
      "y": 3,
      "z": 3,
      "name": "Cloth_Block_Wool_Blue"
    },
    {
      "x": -10,
      "y": 4,
      "z": 3,
      "name": "Cloth_Block_Wool_Blue"
    },
    {
      "x": -10,
      "y": 5,
      "z": 3,
      "name": "Cloth_Block_Wool_Blue"
    },
    {
      "x": -10,
      "y": 6,
      "z": 3,
      "name": "Cloth_Block_Wool_Blue"
    },
    {
      "x": -10,
      "y": 7,
      "z": 3,
      "name": "Cloth_Block_Wool_Blue"
    },
    {
      "x": -10,
      "y": 8,
      "z": 3,
      "name": "Cloth_Block_Wool_Blue"
    },
    {
      "x": -10,
      "y": 9,
      "z": 3,
      "name": "Cloth_Block_Wool_Blue"
    },
    {
      "x": -10,
      "y": 10,
      "z": 3,
      "name": "Cloth_Block_Wool_Blue"
    },
    {
      "x": -10,
      "y": 11,
      "z": 3,
      "name": "Cloth_Block_Wool_Blue"
    },
    {
      "x": -10,
      "y": 12,
      "z": 3,
      "name": "Cloth_Block_Wool_Blue"
    },
    {
      "x": -10,
      "y": 13,
      "z": 3,
      "name": "Cloth_Block_Wool_Blue"
    },
    {
      "x": -10,
      "y": 14,
      "z": 3,
      "name": "Cloth_Block_Wool_Blue"
    },
    {
      "x": -10,
      "y": 15,
      "z": 3,
      "name": "Cloth_Block_Wool_Blue"
    },
    {
      "x": -10,
      "y": 16,
      "z": 3,
      "name": "Cloth_Block_Wool_Blue"
    },
    {
      "x": -10,
      "y": 17,
      "z": 3,
      "name": "Cloth_Block_Wool_Blue"
    },
    {
      "x": -10,
      "y": 18,
      "z": 3,
      "name": "Cloth_Block_Wool_Blue"
    },
    {
      "x": -10,
      "y": 19,
      "z": 3,
      "name": "Cloth_Block_Wool_Blue"
    },
    {
      "x": -10,
      "y": 20,
      "z": 3,
      "name": "Cloth_Block_Wool_Blue"
    },
    {
      "x": -10,
      "y": 21,
      "z": 3,
      "name": "Cloth_Block_Wool_Blue"
    },
    {
      "x": -10,
      "y": 22,
      "z": 3,
      "name": "Cloth_Block_Wool_Blue"
    },
    {
      "x": -10,
      "y": 23,
      "z": 3,
      "name": "Cloth_Block_Wool_Blue"
    },
    {
      "x": -10,
      "y": 24,
      "z": 3,
      "name": "Cloth_Block_Wool_Blue"
    },
    {
      "x": -10,
      "y": 25,
      "z": 3,
      "name": "Cloth_Block_Wool_Blue"
    },
    {
      "x": -10,
      "y": 0,
      "z": 4,
      "name": "Cloth_Block_Wool_Blue"
    },
    {
      "x": -10,
      "y": 1,
      "z": 4,
      "name": "Cloth_Block_Wool_Blue"
    },
    {
      "x": -10,
      "y": 2,
      "z": 4,
      "name": "Cloth_Block_Wool_Blue"
    },
    {
      "x": -10,
      "y": 3,
      "z": 4,
      "name": "Cloth_Block_Wool_Blue"
    },
    {
      "x": -10,
      "y": 4,
      "z": 4,
      "name": "Cloth_Block_Wool_Blue"
    },
    {
      "x": -10,
      "y": 5,
      "z": 4,
      "name": "Cloth_Block_Wool_Blue"
    },
    {
      "x": -10,
      "y": 6,
      "z": 4,
      "name": "Cloth_Block_Wool_Blue"
    },
    {
      "x": -10,
      "y": 7,
      "z": 4,
      "name": "Cloth_Block_Wool_Blue"
    },
    {
      "x": -10,
      "y": 8,
      "z": 4,
      "name": "Cloth_Block_Wool_Blue"
    },
    {
      "x": -10,
      "y": 9,
      "z": 4,
      "name": "Cloth_Block_Wool_Blue"
    },
    {
      "x": -10,
      "y": 10,
      "z": 4,
      "name": "Cloth_Block_Wool_Blue"
    },
    {
      "x": -10,
      "y": 11,
      "z": 4,
      "name": "Cloth_Block_Wool_Blue"
    },
    {
      "x": -10,
      "y": 12,
      "z": 4,
      "name": "Cloth_Block_Wool_Blue"
    },
    {
      "x": -10,
      "y": 13,
      "z": 4,
      "name": "Cloth_Block_Wool_Blue"
    },
    {
      "x": -10,
      "y": 14,
      "z": 4,
      "name": "Cloth_Block_Wool_Blue"
    },
    {
      "x": -10,
      "y": 15,
      "z": 4,
      "name": "Cloth_Block_Wool_Blue"
    },
    {
      "x": -10,
      "y": 16,
      "z": 4,
      "name": "Cloth_Block_Wool_Blue"
    },
    {
      "x": -10,
      "y": 17,
      "z": 4,
      "name": "Cloth_Block_Wool_Blue"
    },
    {
      "x": -10,
      "y": 18,
      "z": 4,
      "name": "Cloth_Block_Wool_Blue"
    },
    {
      "x": -10,
      "y": 19,
      "z": 4,
      "name": "Cloth_Block_Wool_Blue"
    },
    {
      "x": -10,
      "y": 20,
      "z": 4,
      "name": "Cloth_Block_Wool_Blue"
    },
    {
      "x": -10,
      "y": 21,
      "z": 4,
      "name": "Cloth_Block_Wool_Blue"
    },
    {
      "x": -10,
      "y": 22,
      "z": 4,
      "name": "Cloth_Block_Wool_Blue"
    },
    {
      "x": -10,
      "y": 23,
      "z": 4,
      "name": "Cloth_Block_Wool_Blue"
    },
    {
      "x": -10,
      "y": 24,
      "z": 4,
      "name": "Cloth_Block_Wool_Blue"
    },
    {
      "x": -10,
      "y": 25,
      "z": 4,
      "name": "Cloth_Block_Wool_Blue"
    },
    {
      "x": -9,
      "y": 0,
      "z": -3,
      "name": "Cloth_Block_Wool_Blue"
    },
    {
      "x": -9,
      "y": 1,
      "z": -3,
      "name": "Cloth_Block_Wool_Blue"
    },
    {
      "x": -9,
      "y": 2,
      "z": -3,
      "name": "Cloth_Block_Wool_Blue"
    },
    {
      "x": -9,
      "y": 3,
      "z": -3,
      "name": "Cloth_Block_Wool_Blue"
    },
    {
      "x": -9,
      "y": 4,
      "z": -3,
      "name": "Cloth_Block_Wool_Blue"
    },
    {
      "x": -9,
      "y": 5,
      "z": -3,
      "name": "Cloth_Block_Wool_Blue"
    },
    {
      "x": -9,
      "y": 6,
      "z": -3,
      "name": "Cloth_Block_Wool_Blue"
    },
    {
      "x": -9,
      "y": 7,
      "z": -3,
      "name": "Cloth_Block_Wool_Blue"
    },
    {
      "x": -9,
      "y": 8,
      "z": -3,
      "name": "Cloth_Block_Wool_Blue"
    },
    {
      "x": -9,
      "y": 9,
      "z": -3,
      "name": "Cloth_Block_Wool_Blue"
    },
    {
      "x": -9,
      "y": 10,
      "z": -3,
      "name": "Cloth_Block_Wool_Blue"
    },
    {
      "x": -9,
      "y": 11,
      "z": -3,
      "name": "Cloth_Block_Wool_Blue"
    },
    {
      "x": -9,
      "y": 12,
      "z": -3,
      "name": "Cloth_Block_Wool_Blue"
    },
    {
      "x": -9,
      "y": 13,
      "z": -3,
      "name": "Cloth_Block_Wool_Blue"
    },
    {
      "x": -9,
      "y": 14,
      "z": -3,
      "name": "Cloth_Block_Wool_Blue"
    },
    {
      "x": -9,
      "y": 15,
      "z": -3,
      "name": "Cloth_Block_Wool_Blue"
    },
    {
      "x": -9,
      "y": 16,
      "z": -3,
      "name": "Cloth_Block_Wool_Blue"
    },
    {
      "x": -9,
      "y": 17,
      "z": -3,
      "name": "Cloth_Block_Wool_Blue"
    },
    {
      "x": -9,
      "y": 18,
      "z": -3,
      "name": "Cloth_Block_Wool_Blue"
    },
    {
      "x": -9,
      "y": 19,
      "z": -3,
      "name": "Cloth_Block_Wool_Blue"
    },
    {
      "x": -9,
      "y": 20,
      "z": -3,
      "name": "Cloth_Block_Wool_Blue"
    },
    {
      "x": -9,
      "y": 21,
      "z": -3,
      "name": "Cloth_Block_Wool_Blue"
    },
    {
      "x": -9,
      "y": 22,
      "z": -3,
      "name": "Cloth_Block_Wool_Blue"
    },
    {
      "x": -9,
      "y": 23,
      "z": -3,
      "name": "Cloth_Block_Wool_Blue"
    },
    {
      "x": -9,
      "y": 24,
      "z": -3,
      "name": "Cloth_Block_Wool_Blue"
    },
    {
      "x": -9,
      "y": 25,
      "z": -3,
      "name": "Cloth_Block_Wool_Blue"
    },
    {
      "x": -9,
      "y": 0,
      "z": -2,
      "name": "Cloth_Block_Wool_Blue"
    },
    {
      "x": -9,
      "y": 1,
      "z": -2,
      "name": "Cloth_Block_Wool_Blue"
    },
    {
      "x": -9,
      "y": 2,
      "z": -2,
      "name": "Cloth_Block_Wool_Blue"
    },
    {
      "x": -9,
      "y": 3,
      "z": -2,
      "name": "Cloth_Block_Wool_Blue"
    },
    {
      "x": -9,
      "y": 4,
      "z": -2,
      "name": "Cloth_Block_Wool_Blue"
    },
    {
      "x": -9,
      "y": 5,
      "z": -2,
      "name": "Cloth_Block_Wool_Blue"
    },
    {
      "x": -9,
      "y": 6,
      "z": -2,
      "name": "Cloth_Block_Wool_Blue"
    },
    {
      "x": -9,
      "y": 7,
      "z": -2,
      "name": "Cloth_Block_Wool_Blue"
    },
    {
      "x": -9,
      "y": 8,
      "z": -2,
      "name": "Cloth_Block_Wool_Blue"
    },
    {
      "x": -9,
      "y": 9,
      "z": -2,
      "name": "Cloth_Block_Wool_Blue"
    },
    {
      "x": -9,
      "y": 10,
      "z": -2,
      "name": "Cloth_Block_Wool_Blue"
    },
    {
      "x": -9,
      "y": 11,
      "z": -2,
      "name": "Cloth_Block_Wool_Blue"
    },
    {
      "x": -9,
      "y": 12,
      "z": -2,
      "name": "Cloth_Block_Wool_Blue"
    },
    {
      "x": -9,
      "y": 13,
      "z": -2,
      "name": "Cloth_Block_Wool_Blue"
    },
    {
      "x": -9,
      "y": 14,
      "z": -2,
      "name": "Cloth_Block_Wool_Blue"
    },
    {
      "x": -9,
      "y": 15,
      "z": -2,
      "name": "Cloth_Block_Wool_Blue"
    },
    {
      "x": -9,
      "y": 16,
      "z": -2,
      "name": "Cloth_Block_Wool_Blue"
    },
    {
      "x": -9,
      "y": 17,
      "z": -2,
      "name": "Cloth_Block_Wool_Blue"
    },
    {
      "x": -9,
      "y": 18,
      "z": -2,
      "name": "Cloth_Block_Wool_Blue"
    },
    {
      "x": -9,
      "y": 19,
      "z": -2,
      "name": "Cloth_Block_Wool_Blue"
    },
    {
      "x": -9,
      "y": 20,
      "z": -2,
      "name": "Cloth_Block_Wool_Blue"
    },
    {
      "x": -9,
      "y": 21,
      "z": -2,
      "name": "Cloth_Block_Wool_Blue"
    },
    {
      "x": -9,
      "y": 22,
      "z": -2,
      "name": "Cloth_Block_Wool_Blue"
    },
    {
      "x": -9,
      "y": 23,
      "z": -2,
      "name": "Cloth_Block_Wool_Blue"
    },
    {
      "x": -9,
      "y": 24,
      "z": -2,
      "name": "Cloth_Block_Wool_Blue"
    },
    {
      "x": -9,
      "y": 25,
      "z": -2,
      "name": "Cloth_Block_Wool_Blue"
    },
    {
      "x": -9,
      "y": 0,
      "z": -1,
      "name": "Cloth_Block_Wool_Blue"
    },
    {
      "x": -9,
      "y": 1,
      "z": -1,
      "name": "Cloth_Block_Wool_Blue"
    },
    {
      "x": -9,
      "y": 2,
      "z": -1,
      "name": "Cloth_Block_Wool_Blue"
    },
    {
      "x": -9,
      "y": 3,
      "z": -1,
      "name": "Cloth_Block_Wool_Blue"
    },
    {
      "x": -9,
      "y": 4,
      "z": -1,
      "name": "Cloth_Block_Wool_Blue"
    },
    {
      "x": -9,
      "y": 5,
      "z": -1,
      "name": "Cloth_Block_Wool_Blue"
    },
    {
      "x": -9,
      "y": 6,
      "z": -1,
      "name": "Cloth_Block_Wool_Blue"
    },
    {
      "x": -9,
      "y": 7,
      "z": -1,
      "name": "Cloth_Block_Wool_Blue"
    },
    {
      "x": -9,
      "y": 8,
      "z": -1,
      "name": "Cloth_Block_Wool_Blue"
    },
    {
      "x": -9,
      "y": 9,
      "z": -1,
      "name": "Cloth_Block_Wool_Blue"
    },
    {
      "x": -9,
      "y": 10,
      "z": -1,
      "name": "Cloth_Block_Wool_Blue"
    },
    {
      "x": -9,
      "y": 11,
      "z": -1,
      "name": "Cloth_Block_Wool_Blue"
    },
    {
      "x": -9,
      "y": 12,
      "z": -1,
      "name": "Cloth_Block_Wool_Blue"
    },
    {
      "x": -9,
      "y": 13,
      "z": -1,
      "name": "Cloth_Block_Wool_Blue"
    },
    {
      "x": -9,
      "y": 14,
      "z": -1,
      "name": "Cloth_Block_Wool_Blue"
    },
    {
      "x": -9,
      "y": 15,
      "z": -1,
      "name": "Cloth_Block_Wool_Blue"
    },
    {
      "x": -9,
      "y": 16,
      "z": -1,
      "name": "Cloth_Block_Wool_Blue"
    },
    {
      "x": -9,
      "y": 17,
      "z": -1,
      "name": "Cloth_Block_Wool_Blue"
    },
    {
      "x": -9,
      "y": 18,
      "z": -1,
      "name": "Cloth_Block_Wool_Blue"
    },
    {
      "x": -9,
      "y": 19,
      "z": -1,
      "name": "Cloth_Block_Wool_Blue"
    },
    {
      "x": -9,
      "y": 20,
      "z": -1,
      "name": "Cloth_Block_Wool_Blue"
    },
    {
      "x": -9,
      "y": 21,
      "z": -1,
      "name": "Cloth_Block_Wool_Blue"
    },
    {
      "x": -9,
      "y": 22,
      "z": -1,
      "name": "Cloth_Block_Wool_Blue"
    },
    {
      "x": -9,
      "y": 23,
      "z": -1,
      "name": "Cloth_Block_Wool_Blue"
    },
    {
      "x": -9,
      "y": 24,
      "z": -1,
      "name": "Cloth_Block_Wool_Blue"
    },
    {
      "x": -9,
      "y": 25,
      "z": -1,
      "name": "Cloth_Block_Wool_Blue"
    },
    {
      "x": -9,
      "y": 0,
      "z": 0,
      "name": "Cloth_Block_Wool_Blue"
    },
    {
      "x": -9,
      "y": 1,
      "z": 0,
      "name": "Cloth_Block_Wool_Blue"
    },
    {
      "x": -9,
      "y": 2,
      "z": 0,
      "name": "Cloth_Block_Wool_Blue"
    },
    {
      "x": -9,
      "y": 3,
      "z": 0,
      "name": "Cloth_Block_Wool_Blue"
    },
    {
      "x": -9,
      "y": 4,
      "z": 0,
      "name": "Cloth_Block_Wool_Blue"
    },
    {
      "x": -9,
      "y": 5,
      "z": 0,
      "name": "Cloth_Block_Wool_Blue"
    },
    {
      "x": -9,
      "y": 6,
      "z": 0,
      "name": "Cloth_Block_Wool_Blue"
    },
    {
      "x": -9,
      "y": 7,
      "z": 0,
      "name": "Cloth_Block_Wool_Blue"
    },
    {
      "x": -9,
      "y": 8,
      "z": 0,
      "name": "Cloth_Block_Wool_Blue"
    },
    {
      "x": -9,
      "y": 9,
      "z": 0,
      "name": "Cloth_Block_Wool_Blue"
    },
    {
      "x": -9,
      "y": 10,
      "z": 0,
      "name": "Cloth_Block_Wool_Blue"
    },
    {
      "x": -9,
      "y": 11,
      "z": 0,
      "name": "Cloth_Block_Wool_Blue"
    },
    {
      "x": -9,
      "y": 12,
      "z": 0,
      "name": "Cloth_Block_Wool_Blue"
    },
    {
      "x": -9,
      "y": 13,
      "z": 0,
      "name": "Cloth_Block_Wool_Blue"
    },
    {
      "x": -9,
      "y": 14,
      "z": 0,
      "name": "Cloth_Block_Wool_Blue"
    },
    {
      "x": -9,
      "y": 15,
      "z": 0,
      "name": "Cloth_Block_Wool_Blue"
    },
    {
      "x": -9,
      "y": 16,
      "z": 0,
      "name": "Cloth_Block_Wool_Blue"
    },
    {
      "x": -9,
      "y": 17,
      "z": 0,
      "name": "Cloth_Block_Wool_Blue"
    },
    {
      "x": -9,
      "y": 18,
      "z": 0,
      "name": "Cloth_Block_Wool_Blue"
    },
    {
      "x": -9,
      "y": 19,
      "z": 0,
      "name": "Cloth_Block_Wool_Blue"
    },
    {
      "x": -9,
      "y": 20,
      "z": 0,
      "name": "Cloth_Block_Wool_Blue"
    },
    {
      "x": -9,
      "y": 21,
      "z": 0,
      "name": "Cloth_Block_Wool_Blue"
    },
    {
      "x": -9,
      "y": 22,
      "z": 0,
      "name": "Cloth_Block_Wool_Blue"
    },
    {
      "x": -9,
      "y": 23,
      "z": 0,
      "name": "Cloth_Block_Wool_Blue"
    },
    {
      "x": -9,
      "y": 24,
      "z": 0,
      "name": "Cloth_Block_Wool_Blue"
    },
    {
      "x": -9,
      "y": 25,
      "z": 0,
      "name": "Cloth_Block_Wool_Blue"
    },
    {
      "x": -9,
      "y": 0,
      "z": 1,
      "name": "Cloth_Block_Wool_Blue"
    },
    {
      "x": -9,
      "y": 1,
      "z": 1,
      "name": "Cloth_Block_Wool_Blue"
    },
    {
      "x": -9,
      "y": 2,
      "z": 1,
      "name": "Cloth_Block_Wool_Blue"
    },
    {
      "x": -9,
      "y": 3,
      "z": 1,
      "name": "Cloth_Block_Wool_Blue"
    },
    {
      "x": -9,
      "y": 4,
      "z": 1,
      "name": "Cloth_Block_Wool_Blue"
    },
    {
      "x": -9,
      "y": 5,
      "z": 1,
      "name": "Cloth_Block_Wool_Blue"
    },
    {
      "x": -9,
      "y": 6,
      "z": 1,
      "name": "Cloth_Block_Wool_Blue"
    },
    {
      "x": -9,
      "y": 7,
      "z": 1,
      "name": "Cloth_Block_Wool_Blue"
    },
    {
      "x": -9,
      "y": 8,
      "z": 1,
      "name": "Cloth_Block_Wool_Blue"
    },
    {
      "x": -9,
      "y": 9,
      "z": 1,
      "name": "Cloth_Block_Wool_Blue"
    },
    {
      "x": -9,
      "y": 10,
      "z": 1,
      "name": "Cloth_Block_Wool_Blue"
    },
    {
      "x": -9,
      "y": 11,
      "z": 1,
      "name": "Cloth_Block_Wool_Blue"
    },
    {
      "x": -9,
      "y": 12,
      "z": 1,
      "name": "Cloth_Block_Wool_Blue"
    },
    {
      "x": -9,
      "y": 13,
      "z": 1,
      "name": "Cloth_Block_Wool_Blue"
    },
    {
      "x": -9,
      "y": 14,
      "z": 1,
      "name": "Cloth_Block_Wool_Blue"
    },
    {
      "x": -9,
      "y": 15,
      "z": 1,
      "name": "Cloth_Block_Wool_Blue"
    },
    {
      "x": -9,
      "y": 16,
      "z": 1,
      "name": "Cloth_Block_Wool_Blue"
    },
    {
      "x": -9,
      "y": 17,
      "z": 1,
      "name": "Cloth_Block_Wool_Blue"
    },
    {
      "x": -9,
      "y": 18,
      "z": 1,
      "name": "Cloth_Block_Wool_Blue"
    },
    {
      "x": -9,
      "y": 19,
      "z": 1,
      "name": "Cloth_Block_Wool_Blue"
    },
    {
      "x": -9,
      "y": 20,
      "z": 1,
      "name": "Cloth_Block_Wool_Blue"
    },
    {
      "x": -9,
      "y": 21,
      "z": 1,
      "name": "Cloth_Block_Wool_Blue"
    },
    {
      "x": -9,
      "y": 22,
      "z": 1,
      "name": "Cloth_Block_Wool_Blue"
    },
    {
      "x": -9,
      "y": 23,
      "z": 1,
      "name": "Cloth_Block_Wool_Blue"
    },
    {
      "x": -9,
      "y": 24,
      "z": 1,
      "name": "Cloth_Block_Wool_Blue"
    },
    {
      "x": -9,
      "y": 25,
      "z": 1,
      "name": "Cloth_Block_Wool_Blue"
    },
    {
      "x": -9,
      "y": 0,
      "z": 2,
      "name": "Cloth_Block_Wool_Blue"
    },
    {
      "x": -9,
      "y": 1,
      "z": 2,
      "name": "Cloth_Block_Wool_Blue"
    },
    {
      "x": -9,
      "y": 2,
      "z": 2,
      "name": "Cloth_Block_Wool_Blue"
    },
    {
      "x": -9,
      "y": 3,
      "z": 2,
      "name": "Cloth_Block_Wool_Blue"
    },
    {
      "x": -9,
      "y": 4,
      "z": 2,
      "name": "Cloth_Block_Wool_Blue"
    },
    {
      "x": -9,
      "y": 5,
      "z": 2,
      "name": "Cloth_Block_Wool_Blue"
    },
    {
      "x": -9,
      "y": 6,
      "z": 2,
      "name": "Cloth_Block_Wool_Blue"
    },
    {
      "x": -9,
      "y": 7,
      "z": 2,
      "name": "Cloth_Block_Wool_Blue"
    },
    {
      "x": -9,
      "y": 8,
      "z": 2,
      "name": "Cloth_Block_Wool_Blue"
    },
    {
      "x": -9,
      "y": 9,
      "z": 2,
      "name": "Cloth_Block_Wool_Blue"
    },
    {
      "x": -9,
      "y": 10,
      "z": 2,
      "name": "Cloth_Block_Wool_Blue"
    },
    {
      "x": -9,
      "y": 11,
      "z": 2,
      "name": "Cloth_Block_Wool_Blue"
    },
    {
      "x": -9,
      "y": 12,
      "z": 2,
      "name": "Cloth_Block_Wool_Blue"
    },
    {
      "x": -9,
      "y": 13,
      "z": 2,
      "name": "Cloth_Block_Wool_Blue"
    },
    {
      "x": -9,
      "y": 14,
      "z": 2,
      "name": "Cloth_Block_Wool_Blue"
    },
    {
      "x": -9,
      "y": 15,
      "z": 2,
      "name": "Cloth_Block_Wool_Blue"
    },
    {
      "x": -9,
      "y": 16,
      "z": 2,
      "name": "Cloth_Block_Wool_Blue"
    },
    {
      "x": -9,
      "y": 17,
      "z": 2,
      "name": "Cloth_Block_Wool_Blue"
    },
    {
      "x": -9,
      "y": 18,
      "z": 2,
      "name": "Cloth_Block_Wool_Blue"
    },
    {
      "x": -9,
      "y": 19,
      "z": 2,
      "name": "Cloth_Block_Wool_Blue"
    },
    {
      "x": -9,
      "y": 20,
      "z": 2,
      "name": "Cloth_Block_Wool_Blue"
    },
    {
      "x": -9,
      "y": 21,
      "z": 2,
      "name": "Cloth_Block_Wool_Blue"
    },
    {
      "x": -9,
      "y": 22,
      "z": 2,
      "name": "Cloth_Block_Wool_Blue"
    },
    {
      "x": -9,
      "y": 23,
      "z": 2,
      "name": "Cloth_Block_Wool_Blue"
    },
    {
      "x": -9,
      "y": 24,
      "z": 2,
      "name": "Cloth_Block_Wool_Blue"
    },
    {
      "x": -9,
      "y": 25,
      "z": 2,
      "name": "Cloth_Block_Wool_Blue"
    },
    {
      "x": -9,
      "y": 0,
      "z": 3,
      "name": "Cloth_Block_Wool_Blue"
    },
    {
      "x": -9,
      "y": 1,
      "z": 3,
      "name": "Cloth_Block_Wool_Blue"
    },
    {
      "x": -9,
      "y": 2,
      "z": 3,
      "name": "Cloth_Block_Wool_Blue"
    },
    {
      "x": -9,
      "y": 3,
      "z": 3,
      "name": "Cloth_Block_Wool_Blue"
    },
    {
      "x": -9,
      "y": 4,
      "z": 3,
      "name": "Cloth_Block_Wool_Blue"
    },
    {
      "x": -9,
      "y": 5,
      "z": 3,
      "name": "Cloth_Block_Wool_Blue"
    },
    {
      "x": -9,
      "y": 6,
      "z": 3,
      "name": "Cloth_Block_Wool_Blue"
    },
    {
      "x": -9,
      "y": 7,
      "z": 3,
      "name": "Cloth_Block_Wool_Blue"
    },
    {
      "x": -9,
      "y": 8,
      "z": 3,
      "name": "Cloth_Block_Wool_Blue"
    },
    {
      "x": -9,
      "y": 9,
      "z": 3,
      "name": "Cloth_Block_Wool_Blue"
    },
    {
      "x": -9,
      "y": 10,
      "z": 3,
      "name": "Cloth_Block_Wool_Blue"
    },
    {
      "x": -9,
      "y": 11,
      "z": 3,
      "name": "Cloth_Block_Wool_Blue"
    },
    {
      "x": -9,
      "y": 12,
      "z": 3,
      "name": "Cloth_Block_Wool_Blue"
    },
    {
      "x": -9,
      "y": 13,
      "z": 3,
      "name": "Cloth_Block_Wool_Blue"
    },
    {
      "x": -9,
      "y": 14,
      "z": 3,
      "name": "Cloth_Block_Wool_Blue"
    },
    {
      "x": -9,
      "y": 15,
      "z": 3,
      "name": "Cloth_Block_Wool_Blue"
    },
    {
      "x": -9,
      "y": 16,
      "z": 3,
      "name": "Cloth_Block_Wool_Blue"
    },
    {
      "x": -9,
      "y": 17,
      "z": 3,
      "name": "Cloth_Block_Wool_Blue"
    },
    {
      "x": -9,
      "y": 18,
      "z": 3,
      "name": "Cloth_Block_Wool_Blue"
    },
    {
      "x": -9,
      "y": 19,
      "z": 3,
      "name": "Cloth_Block_Wool_Blue"
    },
    {
      "x": -9,
      "y": 20,
      "z": 3,
      "name": "Cloth_Block_Wool_Blue"
    },
    {
      "x": -9,
      "y": 21,
      "z": 3,
      "name": "Cloth_Block_Wool_Blue"
    },
    {
      "x": -9,
      "y": 22,
      "z": 3,
      "name": "Cloth_Block_Wool_Blue"
    },
    {
      "x": -9,
      "y": 23,
      "z": 3,
      "name": "Cloth_Block_Wool_Blue"
    },
    {
      "x": -9,
      "y": 24,
      "z": 3,
      "name": "Cloth_Block_Wool_Blue"
    },
    {
      "x": -9,
      "y": 25,
      "z": 3,
      "name": "Cloth_Block_Wool_Blue"
    },
    {
      "x": -9,
      "y": 0,
      "z": 4,
      "name": "Cloth_Block_Wool_Blue"
    },
    {
      "x": -9,
      "y": 1,
      "z": 4,
      "name": "Cloth_Block_Wool_Blue"
    },
    {
      "x": -9,
      "y": 2,
      "z": 4,
      "name": "Cloth_Block_Wool_Blue"
    },
    {
      "x": -9,
      "y": 3,
      "z": 4,
      "name": "Cloth_Block_Wool_Blue"
    },
    {
      "x": -9,
      "y": 4,
      "z": 4,
      "name": "Cloth_Block_Wool_Blue"
    },
    {
      "x": -9,
      "y": 5,
      "z": 4,
      "name": "Cloth_Block_Wool_Blue"
    },
    {
      "x": -9,
      "y": 6,
      "z": 4,
      "name": "Cloth_Block_Wool_Blue"
    },
    {
      "x": -9,
      "y": 7,
      "z": 4,
      "name": "Cloth_Block_Wool_Blue"
    },
    {
      "x": -9,
      "y": 8,
      "z": 4,
      "name": "Cloth_Block_Wool_Blue"
    },
    {
      "x": -9,
      "y": 9,
      "z": 4,
      "name": "Cloth_Block_Wool_Blue"
    },
    {
      "x": -9,
      "y": 10,
      "z": 4,
      "name": "Cloth_Block_Wool_Blue"
    },
    {
      "x": -9,
      "y": 11,
      "z": 4,
      "name": "Cloth_Block_Wool_Blue"
    },
    {
      "x": -9,
      "y": 12,
      "z": 4,
      "name": "Cloth_Block_Wool_Blue"
    },
    {
      "x": -9,
      "y": 13,
      "z": 4,
      "name": "Cloth_Block_Wool_Blue"
    },
    {
      "x": -9,
      "y": 14,
      "z": 4,
      "name": "Cloth_Block_Wool_Blue"
    },
    {
      "x": -9,
      "y": 15,
      "z": 4,
      "name": "Cloth_Block_Wool_Blue"
    },
    {
      "x": -9,
      "y": 16,
      "z": 4,
      "name": "Cloth_Block_Wool_Blue"
    },
    {
      "x": -9,
      "y": 17,
      "z": 4,
      "name": "Cloth_Block_Wool_Blue"
    },
    {
      "x": -9,
      "y": 18,
      "z": 4,
      "name": "Cloth_Block_Wool_Blue"
    },
    {
      "x": -9,
      "y": 19,
      "z": 4,
      "name": "Cloth_Block_Wool_Blue"
    },
    {
      "x": -9,
      "y": 20,
      "z": 4,
      "name": "Cloth_Block_Wool_Blue"
    },
    {
      "x": -9,
      "y": 21,
      "z": 4,
      "name": "Cloth_Block_Wool_Blue"
    },
    {
      "x": -9,
      "y": 22,
      "z": 4,
      "name": "Cloth_Block_Wool_Blue"
    },
    {
      "x": -9,
      "y": 23,
      "z": 4,
      "name": "Cloth_Block_Wool_Blue"
    },
    {
      "x": -9,
      "y": 24,
      "z": 4,
      "name": "Cloth_Block_Wool_Blue"
    },
    {
      "x": -9,
      "y": 25,
      "z": 4,
      "name": "Cloth_Block_Wool_Blue"
    },
    {
      "x": -8,
      "y": 0,
      "z": -3,
      "name": "Cloth_Block_Wool_Blue"
    },
    {
      "x": -8,
      "y": 1,
      "z": -3,
      "name": "Cloth_Block_Wool_Blue"
    },
    {
      "x": -8,
      "y": 2,
      "z": -3,
      "name": "Cloth_Block_Wool_Blue"
    },
    {
      "x": -8,
      "y": 3,
      "z": -3,
      "name": "Cloth_Block_Wool_Blue"
    },
    {
      "x": -8,
      "y": 4,
      "z": -3,
      "name": "Cloth_Block_Wool_Blue"
    },
    {
      "x": -8,
      "y": 5,
      "z": -3,
      "name": "Cloth_Block_Wool_Blue"
    },
    {
      "x": -8,
      "y": 6,
      "z": -3,
      "name": "Cloth_Block_Wool_Blue"
    },
    {
      "x": -8,
      "y": 7,
      "z": -3,
      "name": "Cloth_Block_Wool_Blue"
    },
    {
      "x": -8,
      "y": 8,
      "z": -3,
      "name": "Cloth_Block_Wool_Blue"
    },
    {
      "x": -8,
      "y": 9,
      "z": -3,
      "name": "Cloth_Block_Wool_Blue"
    },
    {
      "x": -8,
      "y": 10,
      "z": -3,
      "name": "Cloth_Block_Wool_Blue"
    },
    {
      "x": -8,
      "y": 11,
      "z": -3,
      "name": "Cloth_Block_Wool_Blue"
    },
    {
      "x": -8,
      "y": 12,
      "z": -3,
      "name": "Cloth_Block_Wool_Blue"
    },
    {
      "x": -8,
      "y": 13,
      "z": -3,
      "name": "Cloth_Block_Wool_Blue"
    },
    {
      "x": -8,
      "y": 14,
      "z": -3,
      "name": "Cloth_Block_Wool_Blue"
    },
    {
      "x": -8,
      "y": 15,
      "z": -3,
      "name": "Cloth_Block_Wool_Blue"
    },
    {
      "x": -8,
      "y": 16,
      "z": -3,
      "name": "Cloth_Block_Wool_Blue"
    },
    {
      "x": -8,
      "y": 17,
      "z": -3,
      "name": "Cloth_Block_Wool_Blue"
    },
    {
      "x": -8,
      "y": 18,
      "z": -3,
      "name": "Cloth_Block_Wool_Blue"
    },
    {
      "x": -8,
      "y": 19,
      "z": -3,
      "name": "Cloth_Block_Wool_Blue"
    },
    {
      "x": -8,
      "y": 20,
      "z": -3,
      "name": "Cloth_Block_Wool_Blue"
    },
    {
      "x": -8,
      "y": 21,
      "z": -3,
      "name": "Cloth_Block_Wool_Blue"
    },
    {
      "x": -8,
      "y": 22,
      "z": -3,
      "name": "Cloth_Block_Wool_Blue"
    },
    {
      "x": -8,
      "y": 23,
      "z": -3,
      "name": "Cloth_Block_Wool_Blue"
    },
    {
      "x": -8,
      "y": 24,
      "z": -3,
      "name": "Cloth_Block_Wool_Blue"
    },
    {
      "x": -8,
      "y": 25,
      "z": -3,
      "name": "Cloth_Block_Wool_Blue"
    },
    {
      "x": -8,
      "y": 0,
      "z": -2,
      "name": "Cloth_Block_Wool_Blue"
    },
    {
      "x": -8,
      "y": 1,
      "z": -2,
      "name": "Cloth_Block_Wool_Blue"
    },
    {
      "x": -8,
      "y": 2,
      "z": -2,
      "name": "Cloth_Block_Wool_Blue"
    },
    {
      "x": -8,
      "y": 3,
      "z": -2,
      "name": "Cloth_Block_Wool_Blue"
    },
    {
      "x": -8,
      "y": 4,
      "z": -2,
      "name": "Cloth_Block_Wool_Blue"
    },
    {
      "x": -8,
      "y": 5,
      "z": -2,
      "name": "Cloth_Block_Wool_Blue"
    },
    {
      "x": -8,
      "y": 6,
      "z": -2,
      "name": "Cloth_Block_Wool_Blue"
    },
    {
      "x": -8,
      "y": 7,
      "z": -2,
      "name": "Cloth_Block_Wool_Blue"
    },
    {
      "x": -8,
      "y": 8,
      "z": -2,
      "name": "Cloth_Block_Wool_Blue"
    },
    {
      "x": -8,
      "y": 9,
      "z": -2,
      "name": "Cloth_Block_Wool_Blue"
    },
    {
      "x": -8,
      "y": 10,
      "z": -2,
      "name": "Cloth_Block_Wool_Blue"
    },
    {
      "x": -8,
      "y": 11,
      "z": -2,
      "name": "Cloth_Block_Wool_Blue"
    },
    {
      "x": -8,
      "y": 12,
      "z": -2,
      "name": "Cloth_Block_Wool_Blue"
    },
    {
      "x": -8,
      "y": 13,
      "z": -2,
      "name": "Cloth_Block_Wool_Blue"
    },
    {
      "x": -8,
      "y": 14,
      "z": -2,
      "name": "Cloth_Block_Wool_Blue"
    },
    {
      "x": -8,
      "y": 15,
      "z": -2,
      "name": "Cloth_Block_Wool_Blue"
    },
    {
      "x": -8,
      "y": 16,
      "z": -2,
      "name": "Cloth_Block_Wool_Blue"
    },
    {
      "x": -8,
      "y": 17,
      "z": -2,
      "name": "Cloth_Block_Wool_Blue"
    },
    {
      "x": -8,
      "y": 18,
      "z": -2,
      "name": "Cloth_Block_Wool_Blue"
    },
    {
      "x": -8,
      "y": 19,
      "z": -2,
      "name": "Cloth_Block_Wool_Blue"
    },
    {
      "x": -8,
      "y": 20,
      "z": -2,
      "name": "Cloth_Block_Wool_Blue"
    },
    {
      "x": -8,
      "y": 21,
      "z": -2,
      "name": "Cloth_Block_Wool_Blue"
    },
    {
      "x": -8,
      "y": 22,
      "z": -2,
      "name": "Cloth_Block_Wool_Blue"
    },
    {
      "x": -8,
      "y": 23,
      "z": -2,
      "name": "Cloth_Block_Wool_Blue"
    },
    {
      "x": -8,
      "y": 24,
      "z": -2,
      "name": "Cloth_Block_Wool_Blue"
    },
    {
      "x": -8,
      "y": 25,
      "z": -2,
      "name": "Cloth_Block_Wool_Blue"
    },
    {
      "x": -8,
      "y": 0,
      "z": -1,
      "name": "Cloth_Block_Wool_Blue"
    },
    {
      "x": -8,
      "y": 1,
      "z": -1,
      "name": "Cloth_Block_Wool_Blue"
    },
    {
      "x": -8,
      "y": 2,
      "z": -1,
      "name": "Cloth_Block_Wool_Blue"
    },
    {
      "x": -8,
      "y": 3,
      "z": -1,
      "name": "Cloth_Block_Wool_Blue"
    },
    {
      "x": -8,
      "y": 4,
      "z": -1,
      "name": "Cloth_Block_Wool_Blue"
    },
    {
      "x": -8,
      "y": 5,
      "z": -1,
      "name": "Cloth_Block_Wool_Blue"
    },
    {
      "x": -8,
      "y": 6,
      "z": -1,
      "name": "Cloth_Block_Wool_Blue"
    },
    {
      "x": -8,
      "y": 7,
      "z": -1,
      "name": "Cloth_Block_Wool_Blue"
    },
    {
      "x": -8,
      "y": 8,
      "z": -1,
      "name": "Cloth_Block_Wool_Blue"
    },
    {
      "x": -8,
      "y": 9,
      "z": -1,
      "name": "Cloth_Block_Wool_Blue"
    },
    {
      "x": -8,
      "y": 10,
      "z": -1,
      "name": "Cloth_Block_Wool_Blue"
    },
    {
      "x": -8,
      "y": 11,
      "z": -1,
      "name": "Cloth_Block_Wool_Blue"
    },
    {
      "x": -8,
      "y": 12,
      "z": -1,
      "name": "Cloth_Block_Wool_Blue"
    },
    {
      "x": -8,
      "y": 13,
      "z": -1,
      "name": "Cloth_Block_Wool_Blue"
    },
    {
      "x": -8,
      "y": 14,
      "z": -1,
      "name": "Cloth_Block_Wool_Blue"
    },
    {
      "x": -8,
      "y": 15,
      "z": -1,
      "name": "Cloth_Block_Wool_Blue"
    },
    {
      "x": -8,
      "y": 16,
      "z": -1,
      "name": "Cloth_Block_Wool_Blue"
    },
    {
      "x": -8,
      "y": 17,
      "z": -1,
      "name": "Cloth_Block_Wool_Blue"
    },
    {
      "x": -8,
      "y": 18,
      "z": -1,
      "name": "Cloth_Block_Wool_Blue"
    },
    {
      "x": -8,
      "y": 19,
      "z": -1,
      "name": "Cloth_Block_Wool_Blue"
    },
    {
      "x": -8,
      "y": 20,
      "z": -1,
      "name": "Cloth_Block_Wool_Blue"
    },
    {
      "x": -8,
      "y": 21,
      "z": -1,
      "name": "Cloth_Block_Wool_Blue"
    },
    {
      "x": -8,
      "y": 22,
      "z": -1,
      "name": "Cloth_Block_Wool_Blue"
    },
    {
      "x": -8,
      "y": 23,
      "z": -1,
      "name": "Cloth_Block_Wool_Blue"
    },
    {
      "x": -8,
      "y": 24,
      "z": -1,
      "name": "Cloth_Block_Wool_Blue"
    },
    {
      "x": -8,
      "y": 25,
      "z": -1,
      "name": "Cloth_Block_Wool_Blue"
    },
    {
      "x": -8,
      "y": 0,
      "z": 0,
      "name": "Cloth_Block_Wool_Blue"
    },
    {
      "x": -8,
      "y": 1,
      "z": 0,
      "name": "Cloth_Block_Wool_Blue"
    },
    {
      "x": -8,
      "y": 2,
      "z": 0,
      "name": "Cloth_Block_Wool_Blue"
    },
    {
      "x": -8,
      "y": 3,
      "z": 0,
      "name": "Cloth_Block_Wool_Blue"
    },
    {
      "x": -8,
      "y": 4,
      "z": 0,
      "name": "Cloth_Block_Wool_Blue"
    },
    {
      "x": -8,
      "y": 5,
      "z": 0,
      "name": "Cloth_Block_Wool_Blue"
    },
    {
      "x": -8,
      "y": 6,
      "z": 0,
      "name": "Cloth_Block_Wool_Blue"
    },
    {
      "x": -8,
      "y": 7,
      "z": 0,
      "name": "Cloth_Block_Wool_Blue"
    },
    {
      "x": -8,
      "y": 8,
      "z": 0,
      "name": "Cloth_Block_Wool_Blue"
    },
    {
      "x": -8,
      "y": 9,
      "z": 0,
      "name": "Cloth_Block_Wool_Blue"
    },
    {
      "x": -8,
      "y": 10,
      "z": 0,
      "name": "Cloth_Block_Wool_Blue"
    },
    {
      "x": -8,
      "y": 11,
      "z": 0,
      "name": "Cloth_Block_Wool_Blue"
    },
    {
      "x": -8,
      "y": 12,
      "z": 0,
      "name": "Cloth_Block_Wool_Blue"
    },
    {
      "x": -8,
      "y": 13,
      "z": 0,
      "name": "Cloth_Block_Wool_Blue"
    },
    {
      "x": -8,
      "y": 14,
      "z": 0,
      "name": "Cloth_Block_Wool_Blue"
    },
    {
      "x": -8,
      "y": 15,
      "z": 0,
      "name": "Cloth_Block_Wool_Blue"
    },
    {
      "x": -8,
      "y": 16,
      "z": 0,
      "name": "Cloth_Block_Wool_Blue"
    },
    {
      "x": -8,
      "y": 17,
      "z": 0,
      "name": "Cloth_Block_Wool_Blue"
    },
    {
      "x": -8,
      "y": 18,
      "z": 0,
      "name": "Cloth_Block_Wool_Blue"
    },
    {
      "x": -8,
      "y": 19,
      "z": 0,
      "name": "Cloth_Block_Wool_Blue"
    },
    {
      "x": -8,
      "y": 20,
      "z": 0,
      "name": "Cloth_Block_Wool_Blue"
    },
    {
      "x": -8,
      "y": 21,
      "z": 0,
      "name": "Cloth_Block_Wool_Blue"
    },
    {
      "x": -8,
      "y": 22,
      "z": 0,
      "name": "Cloth_Block_Wool_Blue"
    },
    {
      "x": -8,
      "y": 23,
      "z": 0,
      "name": "Cloth_Block_Wool_Blue"
    },
    {
      "x": -8,
      "y": 24,
      "z": 0,
      "name": "Cloth_Block_Wool_Blue"
    },
    {
      "x": -8,
      "y": 25,
      "z": 0,
      "name": "Cloth_Block_Wool_Blue"
    },
    {
      "x": -8,
      "y": 0,
      "z": 1,
      "name": "Cloth_Block_Wool_Blue"
    },
    {
      "x": -8,
      "y": 1,
      "z": 1,
      "name": "Cloth_Block_Wool_Blue"
    },
    {
      "x": -8,
      "y": 2,
      "z": 1,
      "name": "Cloth_Block_Wool_Blue"
    },
    {
      "x": -8,
      "y": 3,
      "z": 1,
      "name": "Cloth_Block_Wool_Blue"
    },
    {
      "x": -8,
      "y": 4,
      "z": 1,
      "name": "Cloth_Block_Wool_Blue"
    },
    {
      "x": -8,
      "y": 5,
      "z": 1,
      "name": "Cloth_Block_Wool_Blue"
    },
    {
      "x": -8,
      "y": 6,
      "z": 1,
      "name": "Cloth_Block_Wool_Blue"
    },
    {
      "x": -8,
      "y": 7,
      "z": 1,
      "name": "Cloth_Block_Wool_Blue"
    },
    {
      "x": -8,
      "y": 8,
      "z": 1,
      "name": "Cloth_Block_Wool_Blue"
    },
    {
      "x": -8,
      "y": 9,
      "z": 1,
      "name": "Cloth_Block_Wool_Blue"
    },
    {
      "x": -8,
      "y": 10,
      "z": 1,
      "name": "Cloth_Block_Wool_Blue"
    },
    {
      "x": -8,
      "y": 11,
      "z": 1,
      "name": "Cloth_Block_Wool_Blue"
    },
    {
      "x": -8,
      "y": 12,
      "z": 1,
      "name": "Cloth_Block_Wool_Blue"
    },
    {
      "x": -8,
      "y": 13,
      "z": 1,
      "name": "Cloth_Block_Wool_Blue"
    },
    {
      "x": -8,
      "y": 14,
      "z": 1,
      "name": "Cloth_Block_Wool_Blue"
    },
    {
      "x": -8,
      "y": 15,
      "z": 1,
      "name": "Cloth_Block_Wool_Blue"
    },
    {
      "x": -8,
      "y": 16,
      "z": 1,
      "name": "Cloth_Block_Wool_Blue"
    },
    {
      "x": -8,
      "y": 17,
      "z": 1,
      "name": "Cloth_Block_Wool_Blue"
    },
    {
      "x": -8,
      "y": 18,
      "z": 1,
      "name": "Cloth_Block_Wool_Blue"
    },
    {
      "x": -8,
      "y": 19,
      "z": 1,
      "name": "Cloth_Block_Wool_Blue"
    },
    {
      "x": -8,
      "y": 20,
      "z": 1,
      "name": "Cloth_Block_Wool_Blue"
    },
    {
      "x": -8,
      "y": 21,
      "z": 1,
      "name": "Cloth_Block_Wool_Blue"
    },
    {
      "x": -8,
      "y": 22,
      "z": 1,
      "name": "Cloth_Block_Wool_Blue"
    },
    {
      "x": -8,
      "y": 23,
      "z": 1,
      "name": "Cloth_Block_Wool_Blue"
    },
    {
      "x": -8,
      "y": 24,
      "z": 1,
      "name": "Cloth_Block_Wool_Blue"
    },
    {
      "x": -8,
      "y": 25,
      "z": 1,
      "name": "Cloth_Block_Wool_Blue"
    },
    {
      "x": -8,
      "y": 0,
      "z": 2,
      "name": "Cloth_Block_Wool_Blue"
    },
    {
      "x": -8,
      "y": 1,
      "z": 2,
      "name": "Cloth_Block_Wool_Blue"
    },
    {
      "x": -8,
      "y": 2,
      "z": 2,
      "name": "Cloth_Block_Wool_Blue"
    },
    {
      "x": -8,
      "y": 3,
      "z": 2,
      "name": "Cloth_Block_Wool_Blue"
    },
    {
      "x": -8,
      "y": 4,
      "z": 2,
      "name": "Cloth_Block_Wool_Blue"
    },
    {
      "x": -8,
      "y": 5,
      "z": 2,
      "name": "Cloth_Block_Wool_Blue"
    },
    {
      "x": -8,
      "y": 6,
      "z": 2,
      "name": "Cloth_Block_Wool_Blue"
    },
    {
      "x": -8,
      "y": 7,
      "z": 2,
      "name": "Cloth_Block_Wool_Blue"
    },
    {
      "x": -8,
      "y": 8,
      "z": 2,
      "name": "Cloth_Block_Wool_Blue"
    },
    {
      "x": -8,
      "y": 9,
      "z": 2,
      "name": "Cloth_Block_Wool_Blue"
    },
    {
      "x": -8,
      "y": 10,
      "z": 2,
      "name": "Cloth_Block_Wool_Blue"
    },
    {
      "x": -8,
      "y": 11,
      "z": 2,
      "name": "Cloth_Block_Wool_Blue"
    },
    {
      "x": -8,
      "y": 12,
      "z": 2,
      "name": "Cloth_Block_Wool_Blue"
    },
    {
      "x": -8,
      "y": 13,
      "z": 2,
      "name": "Cloth_Block_Wool_Blue"
    },
    {
      "x": -8,
      "y": 14,
      "z": 2,
      "name": "Cloth_Block_Wool_Blue"
    },
    {
      "x": -8,
      "y": 15,
      "z": 2,
      "name": "Cloth_Block_Wool_Blue"
    },
    {
      "x": -8,
      "y": 16,
      "z": 2,
      "name": "Cloth_Block_Wool_Blue"
    },
    {
      "x": -8,
      "y": 17,
      "z": 2,
      "name": "Cloth_Block_Wool_Blue"
    },
    {
      "x": -8,
      "y": 18,
      "z": 2,
      "name": "Cloth_Block_Wool_Blue"
    },
    {
      "x": -8,
      "y": 19,
      "z": 2,
      "name": "Cloth_Block_Wool_Blue"
    },
    {
      "x": -8,
      "y": 20,
      "z": 2,
      "name": "Cloth_Block_Wool_Blue"
    },
    {
      "x": -8,
      "y": 21,
      "z": 2,
      "name": "Cloth_Block_Wool_Blue"
    },
    {
      "x": -8,
      "y": 22,
      "z": 2,
      "name": "Cloth_Block_Wool_Blue"
    },
    {
      "x": -8,
      "y": 23,
      "z": 2,
      "name": "Cloth_Block_Wool_Blue"
    },
    {
      "x": -8,
      "y": 24,
      "z": 2,
      "name": "Cloth_Block_Wool_Blue"
    },
    {
      "x": -8,
      "y": 25,
      "z": 2,
      "name": "Cloth_Block_Wool_Blue"
    },
    {
      "x": -8,
      "y": 0,
      "z": 3,
      "name": "Cloth_Block_Wool_Blue"
    },
    {
      "x": -8,
      "y": 1,
      "z": 3,
      "name": "Cloth_Block_Wool_Blue"
    },
    {
      "x": -8,
      "y": 2,
      "z": 3,
      "name": "Cloth_Block_Wool_Blue"
    },
    {
      "x": -8,
      "y": 3,
      "z": 3,
      "name": "Cloth_Block_Wool_Blue"
    },
    {
      "x": -8,
      "y": 4,
      "z": 3,
      "name": "Cloth_Block_Wool_Blue"
    },
    {
      "x": -8,
      "y": 5,
      "z": 3,
      "name": "Cloth_Block_Wool_Blue"
    },
    {
      "x": -8,
      "y": 6,
      "z": 3,
      "name": "Cloth_Block_Wool_Blue"
    },
    {
      "x": -8,
      "y": 7,
      "z": 3,
      "name": "Cloth_Block_Wool_Blue"
    },
    {
      "x": -8,
      "y": 8,
      "z": 3,
      "name": "Cloth_Block_Wool_Blue"
    },
    {
      "x": -8,
      "y": 9,
      "z": 3,
      "name": "Cloth_Block_Wool_Blue"
    },
    {
      "x": -8,
      "y": 10,
      "z": 3,
      "name": "Cloth_Block_Wool_Blue"
    },
    {
      "x": -8,
      "y": 11,
      "z": 3,
      "name": "Cloth_Block_Wool_Blue"
    },
    {
      "x": -8,
      "y": 12,
      "z": 3,
      "name": "Cloth_Block_Wool_Blue"
    },
    {
      "x": -8,
      "y": 13,
      "z": 3,
      "name": "Cloth_Block_Wool_Blue"
    },
    {
      "x": -8,
      "y": 14,
      "z": 3,
      "name": "Cloth_Block_Wool_Blue"
    },
    {
      "x": -8,
      "y": 15,
      "z": 3,
      "name": "Cloth_Block_Wool_Blue"
    },
    {
      "x": -8,
      "y": 16,
      "z": 3,
      "name": "Cloth_Block_Wool_Blue"
    },
    {
      "x": -8,
      "y": 17,
      "z": 3,
      "name": "Cloth_Block_Wool_Blue"
    },
    {
      "x": -8,
      "y": 18,
      "z": 3,
      "name": "Cloth_Block_Wool_Blue"
    },
    {
      "x": -8,
      "y": 19,
      "z": 3,
      "name": "Cloth_Block_Wool_Blue"
    },
    {
      "x": -8,
      "y": 20,
      "z": 3,
      "name": "Cloth_Block_Wool_Blue"
    },
    {
      "x": -8,
      "y": 21,
      "z": 3,
      "name": "Cloth_Block_Wool_Blue"
    },
    {
      "x": -8,
      "y": 22,
      "z": 3,
      "name": "Cloth_Block_Wool_Blue"
    },
    {
      "x": -8,
      "y": 23,
      "z": 3,
      "name": "Cloth_Block_Wool_Blue"
    },
    {
      "x": -8,
      "y": 24,
      "z": 3,
      "name": "Cloth_Block_Wool_Blue"
    },
    {
      "x": -8,
      "y": 25,
      "z": 3,
      "name": "Cloth_Block_Wool_Blue"
    },
    {
      "x": -8,
      "y": 0,
      "z": 4,
      "name": "Cloth_Block_Wool_Blue"
    },
    {
      "x": -8,
      "y": 1,
      "z": 4,
      "name": "Cloth_Block_Wool_Blue"
    },
    {
      "x": -8,
      "y": 2,
      "z": 4,
      "name": "Cloth_Block_Wool_Blue"
    },
    {
      "x": -8,
      "y": 3,
      "z": 4,
      "name": "Cloth_Block_Wool_Blue"
    },
    {
      "x": -8,
      "y": 4,
      "z": 4,
      "name": "Cloth_Block_Wool_Blue"
    },
    {
      "x": -8,
      "y": 5,
      "z": 4,
      "name": "Cloth_Block_Wool_Blue"
    },
    {
      "x": -8,
      "y": 6,
      "z": 4,
      "name": "Cloth_Block_Wool_Blue"
    },
    {
      "x": -8,
      "y": 7,
      "z": 4,
      "name": "Cloth_Block_Wool_Blue"
    },
    {
      "x": -8,
      "y": 8,
      "z": 4,
      "name": "Cloth_Block_Wool_Blue"
    },
    {
      "x": -8,
      "y": 9,
      "z": 4,
      "name": "Cloth_Block_Wool_Blue"
    },
    {
      "x": -8,
      "y": 10,
      "z": 4,
      "name": "Cloth_Block_Wool_Blue"
    },
    {
      "x": -8,
      "y": 11,
      "z": 4,
      "name": "Cloth_Block_Wool_Blue"
    },
    {
      "x": -8,
      "y": 12,
      "z": 4,
      "name": "Cloth_Block_Wool_Blue"
    },
    {
      "x": -8,
      "y": 13,
      "z": 4,
      "name": "Cloth_Block_Wool_Blue"
    },
    {
      "x": -8,
      "y": 14,
      "z": 4,
      "name": "Cloth_Block_Wool_Blue"
    },
    {
      "x": -8,
      "y": 15,
      "z": 4,
      "name": "Cloth_Block_Wool_Blue"
    },
    {
      "x": -8,
      "y": 16,
      "z": 4,
      "name": "Cloth_Block_Wool_Blue"
    },
    {
      "x": -8,
      "y": 17,
      "z": 4,
      "name": "Cloth_Block_Wool_Blue"
    },
    {
      "x": -8,
      "y": 18,
      "z": 4,
      "name": "Cloth_Block_Wool_Blue"
    },
    {
      "x": -8,
      "y": 19,
      "z": 4,
      "name": "Cloth_Block_Wool_Blue"
    },
    {
      "x": -8,
      "y": 20,
      "z": 4,
      "name": "Cloth_Block_Wool_Blue"
    },
    {
      "x": -8,
      "y": 21,
      "z": 4,
      "name": "Cloth_Block_Wool_Blue"
    },
    {
      "x": -8,
      "y": 22,
      "z": 4,
      "name": "Cloth_Block_Wool_Blue"
    },
    {
      "x": -8,
      "y": 23,
      "z": 4,
      "name": "Cloth_Block_Wool_Blue"
    },
    {
      "x": -8,
      "y": 24,
      "z": 4,
      "name": "Cloth_Block_Wool_Blue"
    },
    {
      "x": -8,
      "y": 25,
      "z": 4,
      "name": "Cloth_Block_Wool_Blue"
    },
    {
      "x": -7,
      "y": 0,
      "z": -3,
      "name": "Cloth_Block_Wool_Blue"
    },
    {
      "x": -7,
      "y": 1,
      "z": -3,
      "name": "Cloth_Block_Wool_Blue"
    },
    {
      "x": -7,
      "y": 2,
      "z": -3,
      "name": "Cloth_Block_Wool_Blue"
    },
    {
      "x": -7,
      "y": 3,
      "z": -3,
      "name": "Cloth_Block_Wool_Blue"
    },
    {
      "x": -7,
      "y": 4,
      "z": -3,
      "name": "Cloth_Block_Wool_Blue"
    },
    {
      "x": -7,
      "y": 5,
      "z": -3,
      "name": "Cloth_Block_Wool_Blue"
    },
    {
      "x": -7,
      "y": 6,
      "z": -3,
      "name": "Cloth_Block_Wool_Blue"
    },
    {
      "x": -7,
      "y": 7,
      "z": -3,
      "name": "Cloth_Block_Wool_Blue"
    },
    {
      "x": -7,
      "y": 8,
      "z": -3,
      "name": "Cloth_Block_Wool_Blue"
    },
    {
      "x": -7,
      "y": 9,
      "z": -3,
      "name": "Cloth_Block_Wool_Blue"
    },
    {
      "x": -7,
      "y": 10,
      "z": -3,
      "name": "Cloth_Block_Wool_Blue"
    },
    {
      "x": -7,
      "y": 11,
      "z": -3,
      "name": "Cloth_Block_Wool_Blue"
    },
    {
      "x": -7,
      "y": 12,
      "z": -3,
      "name": "Cloth_Block_Wool_Blue"
    },
    {
      "x": -7,
      "y": 13,
      "z": -3,
      "name": "Cloth_Block_Wool_Blue"
    },
    {
      "x": -7,
      "y": 14,
      "z": -3,
      "name": "Cloth_Block_Wool_Blue"
    },
    {
      "x": -7,
      "y": 15,
      "z": -3,
      "name": "Cloth_Block_Wool_Blue"
    },
    {
      "x": -7,
      "y": 16,
      "z": -3,
      "name": "Cloth_Block_Wool_Blue"
    },
    {
      "x": -7,
      "y": 17,
      "z": -3,
      "name": "Cloth_Block_Wool_Blue"
    },
    {
      "x": -7,
      "y": 18,
      "z": -3,
      "name": "Cloth_Block_Wool_Blue"
    },
    {
      "x": -7,
      "y": 19,
      "z": -3,
      "name": "Cloth_Block_Wool_Blue"
    },
    {
      "x": -7,
      "y": 20,
      "z": -3,
      "name": "Cloth_Block_Wool_Blue"
    },
    {
      "x": -7,
      "y": 21,
      "z": -3,
      "name": "Cloth_Block_Wool_Blue"
    },
    {
      "x": -7,
      "y": 22,
      "z": -3,
      "name": "Cloth_Block_Wool_Blue"
    },
    {
      "x": -7,
      "y": 23,
      "z": -3,
      "name": "Cloth_Block_Wool_Blue"
    },
    {
      "x": -7,
      "y": 24,
      "z": -3,
      "name": "Cloth_Block_Wool_Blue"
    },
    {
      "x": -7,
      "y": 25,
      "z": -3,
      "name": "Cloth_Block_Wool_Blue"
    },
    {
      "x": -7,
      "y": 0,
      "z": -2,
      "name": "Cloth_Block_Wool_Blue"
    },
    {
      "x": -7,
      "y": 1,
      "z": -2,
      "name": "Cloth_Block_Wool_Blue"
    },
    {
      "x": -7,
      "y": 2,
      "z": -2,
      "name": "Cloth_Block_Wool_Blue"
    },
    {
      "x": -7,
      "y": 3,
      "z": -2,
      "name": "Cloth_Block_Wool_Blue"
    },
    {
      "x": -7,
      "y": 4,
      "z": -2,
      "name": "Cloth_Block_Wool_Blue"
    },
    {
      "x": -7,
      "y": 5,
      "z": -2,
      "name": "Cloth_Block_Wool_Blue"
    },
    {
      "x": -7,
      "y": 6,
      "z": -2,
      "name": "Cloth_Block_Wool_Blue"
    },
    {
      "x": -7,
      "y": 7,
      "z": -2,
      "name": "Cloth_Block_Wool_Blue"
    },
    {
      "x": -7,
      "y": 8,
      "z": -2,
      "name": "Cloth_Block_Wool_Blue"
    },
    {
      "x": -7,
      "y": 9,
      "z": -2,
      "name": "Cloth_Block_Wool_Blue"
    },
    {
      "x": -7,
      "y": 10,
      "z": -2,
      "name": "Cloth_Block_Wool_Blue"
    },
    {
      "x": -7,
      "y": 11,
      "z": -2,
      "name": "Cloth_Block_Wool_Blue"
    },
    {
      "x": -7,
      "y": 12,
      "z": -2,
      "name": "Cloth_Block_Wool_Blue"
    },
    {
      "x": -7,
      "y": 13,
      "z": -2,
      "name": "Cloth_Block_Wool_Blue"
    },
    {
      "x": -7,
      "y": 14,
      "z": -2,
      "name": "Cloth_Block_Wool_Blue"
    },
    {
      "x": -7,
      "y": 15,
      "z": -2,
      "name": "Cloth_Block_Wool_Blue"
    },
    {
      "x": -7,
      "y": 16,
      "z": -2,
      "name": "Cloth_Block_Wool_Blue"
    },
    {
      "x": -7,
      "y": 17,
      "z": -2,
      "name": "Cloth_Block_Wool_Blue"
    },
    {
      "x": -7,
      "y": 18,
      "z": -2,
      "name": "Cloth_Block_Wool_Blue"
    },
    {
      "x": -7,
      "y": 19,
      "z": -2,
      "name": "Cloth_Block_Wool_Blue"
    },
    {
      "x": -7,
      "y": 20,
      "z": -2,
      "name": "Cloth_Block_Wool_Blue"
    },
    {
      "x": -7,
      "y": 21,
      "z": -2,
      "name": "Cloth_Block_Wool_Blue"
    },
    {
      "x": -7,
      "y": 22,
      "z": -2,
      "name": "Cloth_Block_Wool_Blue"
    },
    {
      "x": -7,
      "y": 23,
      "z": -2,
      "name": "Cloth_Block_Wool_Blue"
    },
    {
      "x": -7,
      "y": 24,
      "z": -2,
      "name": "Cloth_Block_Wool_Blue"
    },
    {
      "x": -7,
      "y": 25,
      "z": -2,
      "name": "Cloth_Block_Wool_Blue"
    },
    {
      "x": -7,
      "y": 0,
      "z": -1,
      "name": "Cloth_Block_Wool_Blue"
    },
    {
      "x": -7,
      "y": 1,
      "z": -1,
      "name": "Cloth_Block_Wool_Blue"
    },
    {
      "x": -7,
      "y": 2,
      "z": -1,
      "name": "Cloth_Block_Wool_Blue"
    },
    {
      "x": -7,
      "y": 3,
      "z": -1,
      "name": "Cloth_Block_Wool_Blue"
    },
    {
      "x": -7,
      "y": 4,
      "z": -1,
      "name": "Cloth_Block_Wool_Blue"
    },
    {
      "x": -7,
      "y": 5,
      "z": -1,
      "name": "Cloth_Block_Wool_Blue"
    },
    {
      "x": -7,
      "y": 6,
      "z": -1,
      "name": "Cloth_Block_Wool_Blue"
    },
    {
      "x": -7,
      "y": 7,
      "z": -1,
      "name": "Cloth_Block_Wool_Blue"
    },
    {
      "x": -7,
      "y": 8,
      "z": -1,
      "name": "Cloth_Block_Wool_Blue"
    },
    {
      "x": -7,
      "y": 9,
      "z": -1,
      "name": "Cloth_Block_Wool_Blue"
    },
    {
      "x": -7,
      "y": 10,
      "z": -1,
      "name": "Cloth_Block_Wool_Blue"
    },
    {
      "x": -7,
      "y": 11,
      "z": -1,
      "name": "Cloth_Block_Wool_Blue"
    },
    {
      "x": -7,
      "y": 12,
      "z": -1,
      "name": "Cloth_Block_Wool_Blue"
    },
    {
      "x": -7,
      "y": 13,
      "z": -1,
      "name": "Cloth_Block_Wool_Blue"
    },
    {
      "x": -7,
      "y": 14,
      "z": -1,
      "name": "Cloth_Block_Wool_Blue"
    },
    {
      "x": -7,
      "y": 15,
      "z": -1,
      "name": "Cloth_Block_Wool_Blue"
    },
    {
      "x": -7,
      "y": 16,
      "z": -1,
      "name": "Cloth_Block_Wool_Blue"
    },
    {
      "x": -7,
      "y": 17,
      "z": -1,
      "name": "Cloth_Block_Wool_Blue"
    },
    {
      "x": -7,
      "y": 18,
      "z": -1,
      "name": "Cloth_Block_Wool_Blue"
    },
    {
      "x": -7,
      "y": 19,
      "z": -1,
      "name": "Cloth_Block_Wool_Blue"
    },
    {
      "x": -7,
      "y": 20,
      "z": -1,
      "name": "Cloth_Block_Wool_Blue"
    },
    {
      "x": -7,
      "y": 21,
      "z": -1,
      "name": "Cloth_Block_Wool_Blue"
    },
    {
      "x": -7,
      "y": 22,
      "z": -1,
      "name": "Cloth_Block_Wool_Blue"
    },
    {
      "x": -7,
      "y": 23,
      "z": -1,
      "name": "Cloth_Block_Wool_Blue"
    },
    {
      "x": -7,
      "y": 24,
      "z": -1,
      "name": "Cloth_Block_Wool_Blue"
    },
    {
      "x": -7,
      "y": 25,
      "z": -1,
      "name": "Cloth_Block_Wool_Blue"
    },
    {
      "x": -7,
      "y": 0,
      "z": 0,
      "name": "Cloth_Block_Wool_Blue"
    },
    {
      "x": -7,
      "y": 1,
      "z": 0,
      "name": "Cloth_Block_Wool_Blue"
    },
    {
      "x": -7,
      "y": 2,
      "z": 0,
      "name": "Cloth_Block_Wool_Blue"
    },
    {
      "x": -7,
      "y": 3,
      "z": 0,
      "name": "Cloth_Block_Wool_Blue"
    },
    {
      "x": -7,
      "y": 4,
      "z": 0,
      "name": "Cloth_Block_Wool_Blue"
    },
    {
      "x": -7,
      "y": 5,
      "z": 0,
      "name": "Cloth_Block_Wool_Blue"
    },
    {
      "x": -7,
      "y": 6,
      "z": 0,
      "name": "Cloth_Block_Wool_Blue"
    },
    {
      "x": -7,
      "y": 7,
      "z": 0,
      "name": "Cloth_Block_Wool_Blue"
    },
    {
      "x": -7,
      "y": 8,
      "z": 0,
      "name": "Cloth_Block_Wool_Blue"
    },
    {
      "x": -7,
      "y": 9,
      "z": 0,
      "name": "Cloth_Block_Wool_Blue"
    },
    {
      "x": -7,
      "y": 10,
      "z": 0,
      "name": "Cloth_Block_Wool_Blue"
    },
    {
      "x": -7,
      "y": 11,
      "z": 0,
      "name": "Cloth_Block_Wool_Blue"
    },
    {
      "x": -7,
      "y": 12,
      "z": 0,
      "name": "Cloth_Block_Wool_Blue"
    },
    {
      "x": -7,
      "y": 13,
      "z": 0,
      "name": "Cloth_Block_Wool_Blue"
    },
    {
      "x": -7,
      "y": 14,
      "z": 0,
      "name": "Cloth_Block_Wool_Blue"
    },
    {
      "x": -7,
      "y": 15,
      "z": 0,
      "name": "Cloth_Block_Wool_Blue"
    },
    {
      "x": -7,
      "y": 16,
      "z": 0,
      "name": "Cloth_Block_Wool_Blue"
    },
    {
      "x": -7,
      "y": 17,
      "z": 0,
      "name": "Cloth_Block_Wool_Blue"
    },
    {
      "x": -7,
      "y": 18,
      "z": 0,
      "name": "Cloth_Block_Wool_Blue"
    },
    {
      "x": -7,
      "y": 19,
      "z": 0,
      "name": "Cloth_Block_Wool_Blue"
    },
    {
      "x": -7,
      "y": 20,
      "z": 0,
      "name": "Cloth_Block_Wool_Blue"
    },
    {
      "x": -7,
      "y": 21,
      "z": 0,
      "name": "Cloth_Block_Wool_Blue"
    },
    {
      "x": -7,
      "y": 22,
      "z": 0,
      "name": "Cloth_Block_Wool_Blue"
    },
    {
      "x": -7,
      "y": 23,
      "z": 0,
      "name": "Cloth_Block_Wool_Blue"
    },
    {
      "x": -7,
      "y": 24,
      "z": 0,
      "name": "Cloth_Block_Wool_Blue"
    },
    {
      "x": -7,
      "y": 25,
      "z": 0,
      "name": "Cloth_Block_Wool_Blue"
    },
    {
      "x": -7,
      "y": 0,
      "z": 1,
      "name": "Cloth_Block_Wool_Blue"
    },
    {
      "x": -7,
      "y": 1,
      "z": 1,
      "name": "Cloth_Block_Wool_Blue"
    },
    {
      "x": -7,
      "y": 2,
      "z": 1,
      "name": "Cloth_Block_Wool_Blue"
    },
    {
      "x": -7,
      "y": 3,
      "z": 1,
      "name": "Cloth_Block_Wool_Blue"
    },
    {
      "x": -7,
      "y": 4,
      "z": 1,
      "name": "Cloth_Block_Wool_Blue"
    },
    {
      "x": -7,
      "y": 5,
      "z": 1,
      "name": "Cloth_Block_Wool_Blue"
    },
    {
      "x": -7,
      "y": 6,
      "z": 1,
      "name": "Cloth_Block_Wool_Blue"
    },
    {
      "x": -7,
      "y": 7,
      "z": 1,
      "name": "Cloth_Block_Wool_Blue"
    },
    {
      "x": -7,
      "y": 8,
      "z": 1,
      "name": "Cloth_Block_Wool_Blue"
    },
    {
      "x": -7,
      "y": 9,
      "z": 1,
      "name": "Cloth_Block_Wool_Blue"
    },
    {
      "x": -7,
      "y": 10,
      "z": 1,
      "name": "Cloth_Block_Wool_Blue"
    },
    {
      "x": -7,
      "y": 11,
      "z": 1,
      "name": "Cloth_Block_Wool_Blue"
    },
    {
      "x": -7,
      "y": 12,
      "z": 1,
      "name": "Cloth_Block_Wool_Blue"
    },
    {
      "x": -7,
      "y": 13,
      "z": 1,
      "name": "Cloth_Block_Wool_Blue"
    },
    {
      "x": -7,
      "y": 14,
      "z": 1,
      "name": "Cloth_Block_Wool_Blue"
    },
    {
      "x": -7,
      "y": 15,
      "z": 1,
      "name": "Cloth_Block_Wool_Blue"
    },
    {
      "x": -7,
      "y": 16,
      "z": 1,
      "name": "Cloth_Block_Wool_Blue"
    },
    {
      "x": -7,
      "y": 17,
      "z": 1,
      "name": "Cloth_Block_Wool_Blue"
    },
    {
      "x": -7,
      "y": 18,
      "z": 1,
      "name": "Cloth_Block_Wool_Blue"
    },
    {
      "x": -7,
      "y": 19,
      "z": 1,
      "name": "Cloth_Block_Wool_Blue"
    },
    {
      "x": -7,
      "y": 20,
      "z": 1,
      "name": "Cloth_Block_Wool_Blue"
    },
    {
      "x": -7,
      "y": 21,
      "z": 1,
      "name": "Cloth_Block_Wool_Blue"
    },
    {
      "x": -7,
      "y": 22,
      "z": 1,
      "name": "Cloth_Block_Wool_Blue"
    },
    {
      "x": -7,
      "y": 23,
      "z": 1,
      "name": "Cloth_Block_Wool_Blue"
    },
    {
      "x": -7,
      "y": 24,
      "z": 1,
      "name": "Cloth_Block_Wool_Blue"
    },
    {
      "x": -7,
      "y": 25,
      "z": 1,
      "name": "Cloth_Block_Wool_Blue"
    },
    {
      "x": -7,
      "y": 0,
      "z": 2,
      "name": "Cloth_Block_Wool_Blue"
    },
    {
      "x": -7,
      "y": 1,
      "z": 2,
      "name": "Cloth_Block_Wool_Blue"
    },
    {
      "x": -7,
      "y": 2,
      "z": 2,
      "name": "Cloth_Block_Wool_Blue"
    },
    {
      "x": -7,
      "y": 3,
      "z": 2,
      "name": "Cloth_Block_Wool_Blue"
    },
    {
      "x": -7,
      "y": 4,
      "z": 2,
      "name": "Cloth_Block_Wool_Blue"
    },
    {
      "x": -7,
      "y": 5,
      "z": 2,
      "name": "Cloth_Block_Wool_Blue"
    },
    {
      "x": -7,
      "y": 6,
      "z": 2,
      "name": "Cloth_Block_Wool_Blue"
    },
    {
      "x": -7,
      "y": 7,
      "z": 2,
      "name": "Cloth_Block_Wool_Blue"
    },
    {
      "x": -7,
      "y": 8,
      "z": 2,
      "name": "Cloth_Block_Wool_Blue"
    },
    {
      "x": -7,
      "y": 9,
      "z": 2,
      "name": "Cloth_Block_Wool_Blue"
    },
    {
      "x": -7,
      "y": 10,
      "z": 2,
      "name": "Cloth_Block_Wool_Blue"
    },
    {
      "x": -7,
      "y": 11,
      "z": 2,
      "name": "Cloth_Block_Wool_Blue"
    },
    {
      "x": -7,
      "y": 12,
      "z": 2,
      "name": "Cloth_Block_Wool_Blue"
    },
    {
      "x": -7,
      "y": 13,
      "z": 2,
      "name": "Cloth_Block_Wool_Blue"
    },
    {
      "x": -7,
      "y": 14,
      "z": 2,
      "name": "Cloth_Block_Wool_Blue"
    },
    {
      "x": -7,
      "y": 15,
      "z": 2,
      "name": "Cloth_Block_Wool_Blue"
    },
    {
      "x": -7,
      "y": 16,
      "z": 2,
      "name": "Cloth_Block_Wool_Blue"
    },
    {
      "x": -7,
      "y": 17,
      "z": 2,
      "name": "Cloth_Block_Wool_Blue"
    },
    {
      "x": -7,
      "y": 18,
      "z": 2,
      "name": "Cloth_Block_Wool_Blue"
    },
    {
      "x": -7,
      "y": 19,
      "z": 2,
      "name": "Cloth_Block_Wool_Blue"
    },
    {
      "x": -7,
      "y": 20,
      "z": 2,
      "name": "Cloth_Block_Wool_Blue"
    },
    {
      "x": -7,
      "y": 21,
      "z": 2,
      "name": "Cloth_Block_Wool_Blue"
    },
    {
      "x": -7,
      "y": 22,
      "z": 2,
      "name": "Cloth_Block_Wool_Blue"
    },
    {
      "x": -7,
      "y": 23,
      "z": 2,
      "name": "Cloth_Block_Wool_Blue"
    },
    {
      "x": -7,
      "y": 24,
      "z": 2,
      "name": "Cloth_Block_Wool_Blue"
    },
    {
      "x": -7,
      "y": 25,
      "z": 2,
      "name": "Cloth_Block_Wool_Blue"
    },
    {
      "x": -7,
      "y": 0,
      "z": 3,
      "name": "Cloth_Block_Wool_Blue"
    },
    {
      "x": -7,
      "y": 1,
      "z": 3,
      "name": "Cloth_Block_Wool_Blue"
    },
    {
      "x": -7,
      "y": 2,
      "z": 3,
      "name": "Cloth_Block_Wool_Blue"
    },
    {
      "x": -7,
      "y": 3,
      "z": 3,
      "name": "Cloth_Block_Wool_Blue"
    },
    {
      "x": -7,
      "y": 4,
      "z": 3,
      "name": "Cloth_Block_Wool_Blue"
    },
    {
      "x": -7,
      "y": 5,
      "z": 3,
      "name": "Cloth_Block_Wool_Blue"
    },
    {
      "x": -7,
      "y": 6,
      "z": 3,
      "name": "Cloth_Block_Wool_Blue"
    },
    {
      "x": -7,
      "y": 7,
      "z": 3,
      "name": "Cloth_Block_Wool_Blue"
    },
    {
      "x": -7,
      "y": 8,
      "z": 3,
      "name": "Cloth_Block_Wool_Blue"
    },
    {
      "x": -7,
      "y": 9,
      "z": 3,
      "name": "Cloth_Block_Wool_Blue"
    },
    {
      "x": -7,
      "y": 10,
      "z": 3,
      "name": "Cloth_Block_Wool_Blue"
    },
    {
      "x": -7,
      "y": 11,
      "z": 3,
      "name": "Cloth_Block_Wool_Blue"
    },
    {
      "x": -7,
      "y": 12,
      "z": 3,
      "name": "Cloth_Block_Wool_Blue"
    },
    {
      "x": -7,
      "y": 13,
      "z": 3,
      "name": "Cloth_Block_Wool_Blue"
    },
    {
      "x": -7,
      "y": 14,
      "z": 3,
      "name": "Cloth_Block_Wool_Blue"
    },
    {
      "x": -7,
      "y": 15,
      "z": 3,
      "name": "Cloth_Block_Wool_Blue"
    },
    {
      "x": -7,
      "y": 16,
      "z": 3,
      "name": "Cloth_Block_Wool_Blue"
    },
    {
      "x": -7,
      "y": 17,
      "z": 3,
      "name": "Cloth_Block_Wool_Blue"
    },
    {
      "x": -7,
      "y": 18,
      "z": 3,
      "name": "Cloth_Block_Wool_Blue"
    },
    {
      "x": -7,
      "y": 19,
      "z": 3,
      "name": "Cloth_Block_Wool_Blue"
    },
    {
      "x": -7,
      "y": 20,
      "z": 3,
      "name": "Cloth_Block_Wool_Blue"
    },
    {
      "x": -7,
      "y": 21,
      "z": 3,
      "name": "Cloth_Block_Wool_Blue"
    },
    {
      "x": -7,
      "y": 22,
      "z": 3,
      "name": "Cloth_Block_Wool_Blue"
    },
    {
      "x": -7,
      "y": 23,
      "z": 3,
      "name": "Cloth_Block_Wool_Blue"
    },
    {
      "x": -7,
      "y": 24,
      "z": 3,
      "name": "Cloth_Block_Wool_Blue"
    },
    {
      "x": -7,
      "y": 25,
      "z": 3,
      "name": "Cloth_Block_Wool_Blue"
    },
    {
      "x": -7,
      "y": 0,
      "z": 4,
      "name": "Cloth_Block_Wool_Blue"
    },
    {
      "x": -7,
      "y": 1,
      "z": 4,
      "name": "Cloth_Block_Wool_Blue"
    },
    {
      "x": -7,
      "y": 2,
      "z": 4,
      "name": "Cloth_Block_Wool_Blue"
    },
    {
      "x": -7,
      "y": 3,
      "z": 4,
      "name": "Cloth_Block_Wool_Blue"
    },
    {
      "x": -7,
      "y": 4,
      "z": 4,
      "name": "Cloth_Block_Wool_Blue"
    },
    {
      "x": -7,
      "y": 5,
      "z": 4,
      "name": "Cloth_Block_Wool_Blue"
    },
    {
      "x": -7,
      "y": 6,
      "z": 4,
      "name": "Cloth_Block_Wool_Blue"
    },
    {
      "x": -7,
      "y": 7,
      "z": 4,
      "name": "Cloth_Block_Wool_Blue"
    },
    {
      "x": -7,
      "y": 8,
      "z": 4,
      "name": "Cloth_Block_Wool_Blue"
    },
    {
      "x": -7,
      "y": 9,
      "z": 4,
      "name": "Cloth_Block_Wool_Blue"
    },
    {
      "x": -7,
      "y": 10,
      "z": 4,
      "name": "Cloth_Block_Wool_Blue"
    },
    {
      "x": -7,
      "y": 11,
      "z": 4,
      "name": "Cloth_Block_Wool_Blue"
    },
    {
      "x": -7,
      "y": 12,
      "z": 4,
      "name": "Cloth_Block_Wool_Blue"
    },
    {
      "x": -7,
      "y": 13,
      "z": 4,
      "name": "Cloth_Block_Wool_Blue"
    },
    {
      "x": -7,
      "y": 14,
      "z": 4,
      "name": "Cloth_Block_Wool_Blue"
    },
    {
      "x": -7,
      "y": 15,
      "z": 4,
      "name": "Cloth_Block_Wool_Blue"
    },
    {
      "x": -7,
      "y": 16,
      "z": 4,
      "name": "Cloth_Block_Wool_Blue"
    },
    {
      "x": -7,
      "y": 17,
      "z": 4,
      "name": "Cloth_Block_Wool_Blue"
    },
    {
      "x": -7,
      "y": 18,
      "z": 4,
      "name": "Cloth_Block_Wool_Blue"
    },
    {
      "x": -7,
      "y": 19,
      "z": 4,
      "name": "Cloth_Block_Wool_Blue"
    },
    {
      "x": -7,
      "y": 20,
      "z": 4,
      "name": "Cloth_Block_Wool_Blue"
    },
    {
      "x": -7,
      "y": 21,
      "z": 4,
      "name": "Cloth_Block_Wool_Blue"
    },
    {
      "x": -7,
      "y": 22,
      "z": 4,
      "name": "Cloth_Block_Wool_Blue"
    },
    {
      "x": -7,
      "y": 23,
      "z": 4,
      "name": "Cloth_Block_Wool_Blue"
    },
    {
      "x": -7,
      "y": 24,
      "z": 4,
      "name": "Cloth_Block_Wool_Blue"
    },
    {
      "x": -7,
      "y": 25,
      "z": 4,
      "name": "Cloth_Block_Wool_Blue"
    },
    {
      "x": -6,
      "y": 0,
      "z": -3,
      "name": "Cloth_Block_Wool_Blue"
    },
    {
      "x": -6,
      "y": 1,
      "z": -3,
      "name": "Cloth_Block_Wool_Blue"
    },
    {
      "x": -6,
      "y": 2,
      "z": -3,
      "name": "Cloth_Block_Wool_Blue"
    },
    {
      "x": -6,
      "y": 3,
      "z": -3,
      "name": "Cloth_Block_Wool_Blue"
    },
    {
      "x": -6,
      "y": 4,
      "z": -3,
      "name": "Cloth_Block_Wool_Blue"
    },
    {
      "x": -6,
      "y": 5,
      "z": -3,
      "name": "Cloth_Block_Wool_Blue"
    },
    {
      "x": -6,
      "y": 6,
      "z": -3,
      "name": "Cloth_Block_Wool_Blue"
    },
    {
      "x": -6,
      "y": 7,
      "z": -3,
      "name": "Cloth_Block_Wool_Blue"
    },
    {
      "x": -6,
      "y": 8,
      "z": -3,
      "name": "Cloth_Block_Wool_Blue"
    },
    {
      "x": -6,
      "y": 9,
      "z": -3,
      "name": "Cloth_Block_Wool_Blue"
    },
    {
      "x": -6,
      "y": 10,
      "z": -3,
      "name": "Cloth_Block_Wool_Blue"
    },
    {
      "x": -6,
      "y": 11,
      "z": -3,
      "name": "Cloth_Block_Wool_Blue"
    },
    {
      "x": -6,
      "y": 12,
      "z": -3,
      "name": "Cloth_Block_Wool_Blue"
    },
    {
      "x": -6,
      "y": 13,
      "z": -3,
      "name": "Cloth_Block_Wool_Blue"
    },
    {
      "x": -6,
      "y": 14,
      "z": -3,
      "name": "Cloth_Block_Wool_Blue"
    },
    {
      "x": -6,
      "y": 15,
      "z": -3,
      "name": "Cloth_Block_Wool_Blue"
    },
    {
      "x": -6,
      "y": 16,
      "z": -3,
      "name": "Cloth_Block_Wool_Blue"
    },
    {
      "x": -6,
      "y": 17,
      "z": -3,
      "name": "Cloth_Block_Wool_Blue"
    },
    {
      "x": -6,
      "y": 18,
      "z": -3,
      "name": "Cloth_Block_Wool_Blue"
    },
    {
      "x": -6,
      "y": 19,
      "z": -3,
      "name": "Cloth_Block_Wool_Blue"
    },
    {
      "x": -6,
      "y": 20,
      "z": -3,
      "name": "Cloth_Block_Wool_Blue"
    },
    {
      "x": -6,
      "y": 21,
      "z": -3,
      "name": "Cloth_Block_Wool_Blue"
    },
    {
      "x": -6,
      "y": 22,
      "z": -3,
      "name": "Cloth_Block_Wool_Blue"
    },
    {
      "x": -6,
      "y": 23,
      "z": -3,
      "name": "Cloth_Block_Wool_Blue"
    },
    {
      "x": -6,
      "y": 24,
      "z": -3,
      "name": "Cloth_Block_Wool_Blue"
    },
    {
      "x": -6,
      "y": 25,
      "z": -3,
      "name": "Cloth_Block_Wool_Blue"
    },
    {
      "x": -6,
      "y": 0,
      "z": -2,
      "name": "Cloth_Block_Wool_Blue"
    },
    {
      "x": -6,
      "y": 1,
      "z": -2,
      "name": "Cloth_Block_Wool_Blue"
    },
    {
      "x": -6,
      "y": 2,
      "z": -2,
      "name": "Cloth_Block_Wool_Blue"
    },
    {
      "x": -6,
      "y": 3,
      "z": -2,
      "name": "Cloth_Block_Wool_Blue"
    },
    {
      "x": -6,
      "y": 4,
      "z": -2,
      "name": "Cloth_Block_Wool_Blue"
    },
    {
      "x": -6,
      "y": 5,
      "z": -2,
      "name": "Cloth_Block_Wool_Blue"
    },
    {
      "x": -6,
      "y": 6,
      "z": -2,
      "name": "Cloth_Block_Wool_Blue"
    },
    {
      "x": -6,
      "y": 7,
      "z": -2,
      "name": "Cloth_Block_Wool_Blue"
    },
    {
      "x": -6,
      "y": 8,
      "z": -2,
      "name": "Cloth_Block_Wool_Blue"
    },
    {
      "x": -6,
      "y": 9,
      "z": -2,
      "name": "Cloth_Block_Wool_Blue"
    },
    {
      "x": -6,
      "y": 10,
      "z": -2,
      "name": "Cloth_Block_Wool_Blue"
    },
    {
      "x": -6,
      "y": 11,
      "z": -2,
      "name": "Cloth_Block_Wool_Blue"
    },
    {
      "x": -6,
      "y": 12,
      "z": -2,
      "name": "Cloth_Block_Wool_Blue"
    },
    {
      "x": -6,
      "y": 13,
      "z": -2,
      "name": "Cloth_Block_Wool_Blue"
    },
    {
      "x": -6,
      "y": 14,
      "z": -2,
      "name": "Cloth_Block_Wool_Blue"
    },
    {
      "x": -6,
      "y": 15,
      "z": -2,
      "name": "Cloth_Block_Wool_Blue"
    },
    {
      "x": -6,
      "y": 16,
      "z": -2,
      "name": "Cloth_Block_Wool_Blue"
    },
    {
      "x": -6,
      "y": 17,
      "z": -2,
      "name": "Cloth_Block_Wool_Blue"
    },
    {
      "x": -6,
      "y": 18,
      "z": -2,
      "name": "Cloth_Block_Wool_Blue"
    },
    {
      "x": -6,
      "y": 19,
      "z": -2,
      "name": "Cloth_Block_Wool_Blue"
    },
    {
      "x": -6,
      "y": 20,
      "z": -2,
      "name": "Cloth_Block_Wool_Blue"
    },
    {
      "x": -6,
      "y": 21,
      "z": -2,
      "name": "Cloth_Block_Wool_Blue"
    },
    {
      "x": -6,
      "y": 22,
      "z": -2,
      "name": "Cloth_Block_Wool_Blue"
    },
    {
      "x": -6,
      "y": 23,
      "z": -2,
      "name": "Cloth_Block_Wool_Blue"
    },
    {
      "x": -6,
      "y": 24,
      "z": -2,
      "name": "Cloth_Block_Wool_Blue"
    },
    {
      "x": -6,
      "y": 25,
      "z": -2,
      "name": "Cloth_Block_Wool_Blue"
    },
    {
      "x": -6,
      "y": 0,
      "z": -1,
      "name": "Cloth_Block_Wool_Blue"
    },
    {
      "x": -6,
      "y": 1,
      "z": -1,
      "name": "Cloth_Block_Wool_Blue"
    },
    {
      "x": -6,
      "y": 2,
      "z": -1,
      "name": "Cloth_Block_Wool_Blue"
    },
    {
      "x": -6,
      "y": 3,
      "z": -1,
      "name": "Cloth_Block_Wool_Blue"
    },
    {
      "x": -6,
      "y": 4,
      "z": -1,
      "name": "Cloth_Block_Wool_Blue"
    },
    {
      "x": -6,
      "y": 5,
      "z": -1,
      "name": "Cloth_Block_Wool_Blue"
    },
    {
      "x": -6,
      "y": 6,
      "z": -1,
      "name": "Cloth_Block_Wool_Blue"
    },
    {
      "x": -6,
      "y": 7,
      "z": -1,
      "name": "Cloth_Block_Wool_Blue"
    },
    {
      "x": -6,
      "y": 8,
      "z": -1,
      "name": "Cloth_Block_Wool_Blue"
    },
    {
      "x": -6,
      "y": 9,
      "z": -1,
      "name": "Cloth_Block_Wool_Blue"
    },
    {
      "x": -6,
      "y": 10,
      "z": -1,
      "name": "Cloth_Block_Wool_Blue"
    },
    {
      "x": -6,
      "y": 11,
      "z": -1,
      "name": "Cloth_Block_Wool_Blue"
    },
    {
      "x": -6,
      "y": 12,
      "z": -1,
      "name": "Cloth_Block_Wool_Blue"
    },
    {
      "x": -6,
      "y": 13,
      "z": -1,
      "name": "Cloth_Block_Wool_Blue"
    },
    {
      "x": -6,
      "y": 14,
      "z": -1,
      "name": "Cloth_Block_Wool_Blue"
    },
    {
      "x": -6,
      "y": 15,
      "z": -1,
      "name": "Cloth_Block_Wool_Blue"
    },
    {
      "x": -6,
      "y": 16,
      "z": -1,
      "name": "Cloth_Block_Wool_Blue"
    },
    {
      "x": -6,
      "y": 17,
      "z": -1,
      "name": "Cloth_Block_Wool_Blue"
    },
    {
      "x": -6,
      "y": 18,
      "z": -1,
      "name": "Cloth_Block_Wool_Blue"
    },
    {
      "x": -6,
      "y": 19,
      "z": -1,
      "name": "Cloth_Block_Wool_Blue"
    },
    {
      "x": -6,
      "y": 20,
      "z": -1,
      "name": "Cloth_Block_Wool_Blue"
    },
    {
      "x": -6,
      "y": 21,
      "z": -1,
      "name": "Cloth_Block_Wool_Blue"
    },
    {
      "x": -6,
      "y": 22,
      "z": -1,
      "name": "Cloth_Block_Wool_Blue"
    },
    {
      "x": -6,
      "y": 23,
      "z": -1,
      "name": "Cloth_Block_Wool_Blue"
    },
    {
      "x": -6,
      "y": 24,
      "z": -1,
      "name": "Cloth_Block_Wool_Blue"
    },
    {
      "x": -6,
      "y": 25,
      "z": -1,
      "name": "Cloth_Block_Wool_Blue"
    },
    {
      "x": -6,
      "y": 0,
      "z": 0,
      "name": "Cloth_Block_Wool_Blue"
    },
    {
      "x": -6,
      "y": 1,
      "z": 0,
      "name": "Cloth_Block_Wool_Blue"
    },
    {
      "x": -6,
      "y": 2,
      "z": 0,
      "name": "Cloth_Block_Wool_Blue"
    },
    {
      "x": -6,
      "y": 3,
      "z": 0,
      "name": "Cloth_Block_Wool_Blue"
    },
    {
      "x": -6,
      "y": 4,
      "z": 0,
      "name": "Cloth_Block_Wool_Blue"
    },
    {
      "x": -6,
      "y": 5,
      "z": 0,
      "name": "Cloth_Block_Wool_Blue"
    },
    {
      "x": -6,
      "y": 6,
      "z": 0,
      "name": "Cloth_Block_Wool_Blue"
    },
    {
      "x": -6,
      "y": 7,
      "z": 0,
      "name": "Cloth_Block_Wool_Blue"
    },
    {
      "x": -6,
      "y": 8,
      "z": 0,
      "name": "Cloth_Block_Wool_Blue"
    },
    {
      "x": -6,
      "y": 9,
      "z": 0,
      "name": "Cloth_Block_Wool_Blue"
    },
    {
      "x": -6,
      "y": 10,
      "z": 0,
      "name": "Cloth_Block_Wool_Blue"
    },
    {
      "x": -6,
      "y": 11,
      "z": 0,
      "name": "Cloth_Block_Wool_Blue"
    },
    {
      "x": -6,
      "y": 12,
      "z": 0,
      "name": "Cloth_Block_Wool_Blue"
    },
    {
      "x": -6,
      "y": 13,
      "z": 0,
      "name": "Cloth_Block_Wool_Blue"
    },
    {
      "x": -6,
      "y": 14,
      "z": 0,
      "name": "Cloth_Block_Wool_Blue"
    },
    {
      "x": -6,
      "y": 15,
      "z": 0,
      "name": "Cloth_Block_Wool_Blue"
    },
    {
      "x": -6,
      "y": 16,
      "z": 0,
      "name": "Cloth_Block_Wool_Blue"
    },
    {
      "x": -6,
      "y": 17,
      "z": 0,
      "name": "Cloth_Block_Wool_Blue"
    },
    {
      "x": -6,
      "y": 18,
      "z": 0,
      "name": "Cloth_Block_Wool_Blue"
    },
    {
      "x": -6,
      "y": 19,
      "z": 0,
      "name": "Cloth_Block_Wool_Blue"
    },
    {
      "x": -6,
      "y": 20,
      "z": 0,
      "name": "Cloth_Block_Wool_Blue"
    },
    {
      "x": -6,
      "y": 21,
      "z": 0,
      "name": "Cloth_Block_Wool_Blue"
    },
    {
      "x": -6,
      "y": 22,
      "z": 0,
      "name": "Cloth_Block_Wool_Blue"
    },
    {
      "x": -6,
      "y": 23,
      "z": 0,
      "name": "Cloth_Block_Wool_Blue"
    },
    {
      "x": -6,
      "y": 24,
      "z": 0,
      "name": "Cloth_Block_Wool_Blue"
    },
    {
      "x": -6,
      "y": 25,
      "z": 0,
      "name": "Cloth_Block_Wool_Blue"
    },
    {
      "x": -6,
      "y": 0,
      "z": 1,
      "name": "Cloth_Block_Wool_Blue"
    },
    {
      "x": -6,
      "y": 1,
      "z": 1,
      "name": "Cloth_Block_Wool_Blue"
    },
    {
      "x": -6,
      "y": 2,
      "z": 1,
      "name": "Cloth_Block_Wool_Blue"
    },
    {
      "x": -6,
      "y": 3,
      "z": 1,
      "name": "Cloth_Block_Wool_Blue"
    },
    {
      "x": -6,
      "y": 4,
      "z": 1,
      "name": "Cloth_Block_Wool_Blue"
    },
    {
      "x": -6,
      "y": 5,
      "z": 1,
      "name": "Cloth_Block_Wool_Blue"
    },
    {
      "x": -6,
      "y": 6,
      "z": 1,
      "name": "Cloth_Block_Wool_Blue"
    },
    {
      "x": -6,
      "y": 7,
      "z": 1,
      "name": "Cloth_Block_Wool_Blue"
    },
    {
      "x": -6,
      "y": 8,
      "z": 1,
      "name": "Cloth_Block_Wool_Blue"
    },
    {
      "x": -6,
      "y": 9,
      "z": 1,
      "name": "Cloth_Block_Wool_Blue"
    },
    {
      "x": -6,
      "y": 10,
      "z": 1,
      "name": "Cloth_Block_Wool_Blue"
    },
    {
      "x": -6,
      "y": 11,
      "z": 1,
      "name": "Cloth_Block_Wool_Blue"
    },
    {
      "x": -6,
      "y": 12,
      "z": 1,
      "name": "Cloth_Block_Wool_Blue"
    },
    {
      "x": -6,
      "y": 13,
      "z": 1,
      "name": "Cloth_Block_Wool_Blue"
    },
    {
      "x": -6,
      "y": 14,
      "z": 1,
      "name": "Cloth_Block_Wool_Blue"
    },
    {
      "x": -6,
      "y": 15,
      "z": 1,
      "name": "Cloth_Block_Wool_Blue"
    },
    {
      "x": -6,
      "y": 16,
      "z": 1,
      "name": "Cloth_Block_Wool_Blue"
    },
    {
      "x": -6,
      "y": 17,
      "z": 1,
      "name": "Cloth_Block_Wool_Blue"
    },
    {
      "x": -6,
      "y": 18,
      "z": 1,
      "name": "Cloth_Block_Wool_Blue"
    },
    {
      "x": -6,
      "y": 19,
      "z": 1,
      "name": "Cloth_Block_Wool_Blue"
    },
    {
      "x": -6,
      "y": 20,
      "z": 1,
      "name": "Cloth_Block_Wool_Blue"
    },
    {
      "x": -6,
      "y": 21,
      "z": 1,
      "name": "Cloth_Block_Wool_Blue"
    },
    {
      "x": -6,
      "y": 22,
      "z": 1,
      "name": "Cloth_Block_Wool_Blue"
    },
    {
      "x": -6,
      "y": 23,
      "z": 1,
      "name": "Cloth_Block_Wool_Blue"
    },
    {
      "x": -6,
      "y": 24,
      "z": 1,
      "name": "Cloth_Block_Wool_Blue"
    },
    {
      "x": -6,
      "y": 25,
      "z": 1,
      "name": "Cloth_Block_Wool_Blue"
    },
    {
      "x": -6,
      "y": 0,
      "z": 2,
      "name": "Cloth_Block_Wool_Blue"
    },
    {
      "x": -6,
      "y": 1,
      "z": 2,
      "name": "Cloth_Block_Wool_Blue"
    },
    {
      "x": -6,
      "y": 2,
      "z": 2,
      "name": "Cloth_Block_Wool_Blue"
    },
    {
      "x": -6,
      "y": 3,
      "z": 2,
      "name": "Cloth_Block_Wool_Blue"
    },
    {
      "x": -6,
      "y": 4,
      "z": 2,
      "name": "Cloth_Block_Wool_Blue"
    },
    {
      "x": -6,
      "y": 5,
      "z": 2,
      "name": "Cloth_Block_Wool_Blue"
    },
    {
      "x": -6,
      "y": 6,
      "z": 2,
      "name": "Cloth_Block_Wool_Blue"
    },
    {
      "x": -6,
      "y": 7,
      "z": 2,
      "name": "Cloth_Block_Wool_Blue"
    },
    {
      "x": -6,
      "y": 8,
      "z": 2,
      "name": "Cloth_Block_Wool_Blue"
    },
    {
      "x": -6,
      "y": 9,
      "z": 2,
      "name": "Cloth_Block_Wool_Blue"
    },
    {
      "x": -6,
      "y": 10,
      "z": 2,
      "name": "Cloth_Block_Wool_Blue"
    },
    {
      "x": -6,
      "y": 11,
      "z": 2,
      "name": "Cloth_Block_Wool_Blue"
    },
    {
      "x": -6,
      "y": 12,
      "z": 2,
      "name": "Cloth_Block_Wool_Blue"
    },
    {
      "x": -6,
      "y": 13,
      "z": 2,
      "name": "Cloth_Block_Wool_Blue"
    },
    {
      "x": -6,
      "y": 14,
      "z": 2,
      "name": "Cloth_Block_Wool_Blue"
    },
    {
      "x": -6,
      "y": 15,
      "z": 2,
      "name": "Cloth_Block_Wool_Blue"
    },
    {
      "x": -6,
      "y": 16,
      "z": 2,
      "name": "Cloth_Block_Wool_Blue"
    },
    {
      "x": -6,
      "y": 17,
      "z": 2,
      "name": "Cloth_Block_Wool_Blue"
    },
    {
      "x": -6,
      "y": 18,
      "z": 2,
      "name": "Cloth_Block_Wool_Blue"
    },
    {
      "x": -6,
      "y": 19,
      "z": 2,
      "name": "Cloth_Block_Wool_Blue"
    },
    {
      "x": -6,
      "y": 20,
      "z": 2,
      "name": "Cloth_Block_Wool_Blue"
    },
    {
      "x": -6,
      "y": 21,
      "z": 2,
      "name": "Cloth_Block_Wool_Blue"
    },
    {
      "x": -6,
      "y": 22,
      "z": 2,
      "name": "Cloth_Block_Wool_Blue"
    },
    {
      "x": -6,
      "y": 23,
      "z": 2,
      "name": "Cloth_Block_Wool_Blue"
    },
    {
      "x": -6,
      "y": 24,
      "z": 2,
      "name": "Cloth_Block_Wool_Blue"
    },
    {
      "x": -6,
      "y": 25,
      "z": 2,
      "name": "Cloth_Block_Wool_Blue"
    },
    {
      "x": -6,
      "y": 0,
      "z": 3,
      "name": "Cloth_Block_Wool_Blue"
    },
    {
      "x": -6,
      "y": 1,
      "z": 3,
      "name": "Cloth_Block_Wool_Blue"
    },
    {
      "x": -6,
      "y": 2,
      "z": 3,
      "name": "Cloth_Block_Wool_Blue"
    },
    {
      "x": -6,
      "y": 3,
      "z": 3,
      "name": "Cloth_Block_Wool_Blue"
    },
    {
      "x": -6,
      "y": 4,
      "z": 3,
      "name": "Cloth_Block_Wool_Blue"
    },
    {
      "x": -6,
      "y": 5,
      "z": 3,
      "name": "Cloth_Block_Wool_Blue"
    },
    {
      "x": -6,
      "y": 6,
      "z": 3,
      "name": "Cloth_Block_Wool_Blue"
    },
    {
      "x": -6,
      "y": 7,
      "z": 3,
      "name": "Cloth_Block_Wool_Blue"
    },
    {
      "x": -6,
      "y": 8,
      "z": 3,
      "name": "Cloth_Block_Wool_Blue"
    },
    {
      "x": -6,
      "y": 9,
      "z": 3,
      "name": "Cloth_Block_Wool_Blue"
    },
    {
      "x": -6,
      "y": 10,
      "z": 3,
      "name": "Cloth_Block_Wool_Blue"
    },
    {
      "x": -6,
      "y": 11,
      "z": 3,
      "name": "Cloth_Block_Wool_Blue"
    },
    {
      "x": -6,
      "y": 12,
      "z": 3,
      "name": "Cloth_Block_Wool_Blue"
    },
    {
      "x": -6,
      "y": 13,
      "z": 3,
      "name": "Cloth_Block_Wool_Blue"
    },
    {
      "x": -6,
      "y": 14,
      "z": 3,
      "name": "Cloth_Block_Wool_Blue"
    },
    {
      "x": -6,
      "y": 15,
      "z": 3,
      "name": "Cloth_Block_Wool_Blue"
    },
    {
      "x": -6,
      "y": 16,
      "z": 3,
      "name": "Cloth_Block_Wool_Blue"
    },
    {
      "x": -6,
      "y": 17,
      "z": 3,
      "name": "Cloth_Block_Wool_Blue"
    },
    {
      "x": -6,
      "y": 18,
      "z": 3,
      "name": "Cloth_Block_Wool_Blue"
    },
    {
      "x": -6,
      "y": 19,
      "z": 3,
      "name": "Cloth_Block_Wool_Blue"
    },
    {
      "x": -6,
      "y": 20,
      "z": 3,
      "name": "Cloth_Block_Wool_Blue"
    },
    {
      "x": -6,
      "y": 21,
      "z": 3,
      "name": "Cloth_Block_Wool_Blue"
    },
    {
      "x": -6,
      "y": 22,
      "z": 3,
      "name": "Cloth_Block_Wool_Blue"
    },
    {
      "x": -6,
      "y": 23,
      "z": 3,
      "name": "Cloth_Block_Wool_Blue"
    },
    {
      "x": -6,
      "y": 24,
      "z": 3,
      "name": "Cloth_Block_Wool_Blue"
    },
    {
      "x": -6,
      "y": 25,
      "z": 3,
      "name": "Cloth_Block_Wool_Blue"
    },
    {
      "x": -6,
      "y": 0,
      "z": 4,
      "name": "Cloth_Block_Wool_Blue"
    },
    {
      "x": -6,
      "y": 1,
      "z": 4,
      "name": "Cloth_Block_Wool_Blue"
    },
    {
      "x": -6,
      "y": 2,
      "z": 4,
      "name": "Cloth_Block_Wool_Blue"
    },
    {
      "x": -6,
      "y": 3,
      "z": 4,
      "name": "Cloth_Block_Wool_Blue"
    },
    {
      "x": -6,
      "y": 4,
      "z": 4,
      "name": "Cloth_Block_Wool_Blue"
    },
    {
      "x": -6,
      "y": 5,
      "z": 4,
      "name": "Cloth_Block_Wool_Blue"
    },
    {
      "x": -6,
      "y": 6,
      "z": 4,
      "name": "Cloth_Block_Wool_Blue"
    },
    {
      "x": -6,
      "y": 7,
      "z": 4,
      "name": "Cloth_Block_Wool_Blue"
    },
    {
      "x": -6,
      "y": 8,
      "z": 4,
      "name": "Cloth_Block_Wool_Blue"
    },
    {
      "x": -6,
      "y": 9,
      "z": 4,
      "name": "Cloth_Block_Wool_Blue"
    },
    {
      "x": -6,
      "y": 10,
      "z": 4,
      "name": "Cloth_Block_Wool_Blue"
    },
    {
      "x": -6,
      "y": 11,
      "z": 4,
      "name": "Cloth_Block_Wool_Blue"
    },
    {
      "x": -6,
      "y": 12,
      "z": 4,
      "name": "Cloth_Block_Wool_Blue"
    },
    {
      "x": -6,
      "y": 13,
      "z": 4,
      "name": "Cloth_Block_Wool_Blue"
    },
    {
      "x": -6,
      "y": 14,
      "z": 4,
      "name": "Cloth_Block_Wool_Blue"
    },
    {
      "x": -6,
      "y": 15,
      "z": 4,
      "name": "Cloth_Block_Wool_Blue"
    },
    {
      "x": -6,
      "y": 16,
      "z": 4,
      "name": "Cloth_Block_Wool_Blue"
    },
    {
      "x": -6,
      "y": 17,
      "z": 4,
      "name": "Cloth_Block_Wool_Blue"
    },
    {
      "x": -6,
      "y": 18,
      "z": 4,
      "name": "Cloth_Block_Wool_Blue"
    },
    {
      "x": -6,
      "y": 19,
      "z": 4,
      "name": "Cloth_Block_Wool_Blue"
    },
    {
      "x": -6,
      "y": 20,
      "z": 4,
      "name": "Cloth_Block_Wool_Blue"
    },
    {
      "x": -6,
      "y": 21,
      "z": 4,
      "name": "Cloth_Block_Wool_Blue"
    },
    {
      "x": -6,
      "y": 22,
      "z": 4,
      "name": "Cloth_Block_Wool_Blue"
    },
    {
      "x": -6,
      "y": 23,
      "z": 4,
      "name": "Cloth_Block_Wool_Blue"
    },
    {
      "x": -6,
      "y": 24,
      "z": 4,
      "name": "Cloth_Block_Wool_Blue"
    },
    {
      "x": -6,
      "y": 25,
      "z": 4,
      "name": "Cloth_Block_Wool_Blue"
    },
    {
      "x": -5,
      "y": 0,
      "z": -3,
      "name": "Cloth_Block_Wool_Blue"
    },
    {
      "x": -5,
      "y": 1,
      "z": -3,
      "name": "Cloth_Block_Wool_Blue"
    },
    {
      "x": -5,
      "y": 2,
      "z": -3,
      "name": "Cloth_Block_Wool_Blue"
    },
    {
      "x": -5,
      "y": 3,
      "z": -3,
      "name": "Cloth_Block_Wool_Blue"
    },
    {
      "x": -5,
      "y": 4,
      "z": -3,
      "name": "Cloth_Block_Wool_Blue"
    },
    {
      "x": -5,
      "y": 5,
      "z": -3,
      "name": "Cloth_Block_Wool_Blue"
    },
    {
      "x": -5,
      "y": 6,
      "z": -3,
      "name": "Cloth_Block_Wool_Blue"
    },
    {
      "x": -5,
      "y": 7,
      "z": -3,
      "name": "Cloth_Block_Wool_Blue"
    },
    {
      "x": -5,
      "y": 8,
      "z": -3,
      "name": "Cloth_Block_Wool_Blue"
    },
    {
      "x": -5,
      "y": 9,
