{"anchorX":0,"anchorY":-7,"anchorZ":0,"blockIdVersion":10,"blocks":[{"name":"Plant_Leaves_Palo","x":1,"y":0,"z":0},{"name":"Plant_Leaves_Palo","x":1,"y":1,"z":0},{"name":"Plant_Leaves_Palo","x":1,"y":2,"z":0},{"name":"Plant_Leaves_Palo","x":1,"y":2,"z":1},{"name":"Plant_Leaves_Palo","x":1,"y":3,"z":1},{"name":"Plant_Leaves_Palo","x":2,"y":3,"z":1},{"name":"Plant_Leaves_Palo","x":2,"y":3,"z":2},{"name":"Plant_Leaves_Palo","x":2,"y":3,"z":3},{"name":"Plant_Leaves_Palo","x":2,"y":2,"z":4},{"name":"Plant_Leaves_Palo","x":2,"y":3,"z":4},{"name":"Plant_Leaves_Palo","x":2,"y":0,"z":5},{"name":"Plant_Leaves_Palo","x":2,"y":1,"z":5},{"name":"Plant_Leaves_Palo","x":2,"y":2,"z":5},{"name":"Plant_Leaves_Palo","x":0,"y":-4,"z":0},{"name":"Plant_Leaves_Palo","x":0,"y":-3,"z":0},{"name":"Plant_Leaves_Palo","x":0,"y":-2,"z":0},{"name":"Plant_Leaves_Palo","x":0,"y":-1,"z":0},{"name":"Plant_Leaves_Palo","x":1,"y":-1,"z":0},{"name":"Plant_Leaves_Palo","x":0,"y":-7,"z":1},{"name":"Plant_Leaves_Palo","x":0,"y":-6,"z":1},{"name":"Plant_Leaves_Palo","x":0,"y":-5,"z":1},{"name":"Plant_Leaves_Palo","x":0,"y":-4,"z":1},{"name":"Plant_Leaves_Palo","x":2,"y":-2,"z":3},{"name":"Plant_Leaves_Palo","x":2,"y":-2,"z":4},{"name":"Plant_Leaves_Palo","x":2,"y":-1,"z":4},{"name":"Plant_Leaves_Palo","x":2,"y":-1,"z":5}],"entities":[],"fluids":[{"level":1,"name":"Water_Source","x":1,"y":0,"z":0},{"level":1,"name":"Water_Source","x":1,"y":1,"z":0},{"level":1,"name":"Water_Source","x":1,"y":2,"z":0},{"level":1,"name":"Water_Source","x":1,"y":2,"z":1},{"level":1,"name":"Water_Source","x":1,"y":3,"z":1},{"level":1,"name":"Water_Source","x":2,"y":3,"z":1},{"level":1,"name":"Water_Source","x":2,"y":3,"z":2},{"level":1,"name":"Water_Source","x":2,"y":3,"z":3},{"level":1,"name":"Water_Source","x":2,"y":2,"z":4},{"level":1,"name":"Water_Source","x":2,"y":3,"z":4},{"level":1,"name":"Water_Source","x":2,"y":0,"z":5},{"level":1,"name":"Water_Source","x":2,"y":1,"z":5},{"level":1,"name":"Water_Source","x":2,"y":2,"z":5},{"level":1,"name":"Water_Source","x":0,"y":-4,"z":0},{"level":1,"name":"Water_Source","x":0,"y":-3,"z":0},{"level":1,"name":"Water_Source","x":0,"y":-2,"z":0},{"level":1,"name":"Water_Source","x":0,"y":-1,"z":0},{"level":1,"name":"Water_Source","x":1,"y":-1,"z":0},{"level":1,"name":"Water_Source","x":0,"y":-7,"z":1},{"level":1,"name":"Water_Source","x":0,"y":-6,"z":1},{"level":1,"name":"Water_Source","x":0,"y":-5,"z":1},{"level":1,"name":"Water_Source","x":0,"y":-4,"z":1},{"level":1,"name":"Water_Source","x":2,"y":-2,"z":3},{"level":1,"name":"Water_Source","x":2,"y":-2,"z":4},{"level":1,"name":"Water_Source","x":2,"y":-1,"z":4},{"level":1,"name":"Water_Source","x":2,"y":-1,"z":5}],"version":8}