{
  "version": 8,
  "blockIdVersion": 10,
  "anchorX": 0,
  "anchorY": -7,
  "anchorZ": 0,
  "blocks": [
    {
      "x": 3,
      "y": 1,
      "z": 0,
      "name": "Plant_Leaves_Palo"
    },
    {
      "x": 3,
      "y": 2,
      "z": 0,
      "name": "Plant_Leaves_Palo"
    },
    {
      "x": 3,
      "y": 2,
      "z": 1,
      "name": "Plant_Leaves_Palo"
    },
    {
      "x": 3,
      "y": 2,
      "z": 2,
      "name": "Plant_Leaves_Palo"
    },
    {
      "x": 3,
      "y": 0,
      "z": 3,
      "name": "Plant_Leaves_Palo"
    },
    {
      "x": 3,
      "y": 1,
      "z": 3,
      "name": "Plant_Leaves_Palo"
    },
    {
      "x": 3,
      "y": 2,
      "z": 3,
      "name": "Plant_Leaves_Palo"
    },
    {
      "x": 3,
      "y": 0,
      "z": 4,
      "name": "Plant_Leaves_Palo"
    },
    {
      "x": 2,
      "y": -5,
      "z": -2,
      "name": "Plant_Leaves_Palo"
    },
    {
      "x": 2,
      "y": -4,
      "z": -2,
      "name": "Plant_Leaves_Palo"
    },
    {
      "x": 2,
      "y": -3,
      "z": -2,
      "name": "Plant_Leaves_Palo"
    },
    {
      "x": 2,
      "y": -2,
      "z": -2,
      "name": "Plant_Leaves_Palo"
    },
    {
      "x": 2,
      "y": -1,
      "z": -2,
      "name": "Plant_Leaves_Palo"
    },
    {
      "x": 2,
      "y": -7,
      "z": -1,
      "name": "Plant_Leaves_Palo"
    },
    {
      "x": 2,
      "y": -6,
      "z": -1,
      "name": "Plant_Leaves_Palo"
    },
    {
      "x": 2,
      "y": -5,
      "z": -1,
      "name": "Plant_Leaves_Palo"
    },
    {
      "x": 2,
      "y": -1,
      "z": -1,
      "name": "Plant_Leaves_Palo"
    },
    {
      "x": 3,
      "y": -1,
      "z": -1,
      "name": "Plant_Leaves_Palo"
    },
    {
      "x": 3,
      "y": 0,
      "z": -1,
      "name": "Plant_Leaves_Palo"
    },
    {
      "x": 3,
      "y": 1,
      "z": -1,
      "name": "Plant_Leaves_Palo"
    },
    {
      "x": -2,
      "y": 0,
      "z": -3,
      "name": "Plant_Leaves_Palo"
    },
    {
      "x": -2,
      "y": 0,
      "z": -2,
      "name": "Plant_Leaves_Palo"
    },
    {
      "x": -2,
      "y": 1,
      "z": -2,
      "name": "Plant_Leaves_Palo"
    },
    {
      "x": -2,
      "y": 2,
      "z": -2,
      "name": "Plant_Leaves_Palo"
    },
    {
      "x": -2,
      "y": 2,
      "z": -1,
      "name": "Plant_Leaves_Palo"
    },
    {
      "x": -2,
      "y": 3,
      "z": -1,
      "name": "Plant_Leaves_Palo"
    },
    {
      "x": -2,
      "y": -4,
      "z": -3,
      "name": "Plant_Leaves_Palo"
    },
    {
      "x": -2,
      "y": -3,
      "z": -3,
      "name": "Plant_Leaves_Palo"
    },
    {
      "x": -2,
      "y": -2,
      "z": -3,
      "name": "Plant_Leaves_Palo"
    },
    {
      "x": -2,
      "y": -1,
      "z": -3,
      "name": "Plant_Leaves_Palo"
    },
    {
      "x": -2,
      "y": -7,
      "z": -2,
      "name": "Plant_Leaves_Palo"
    },
    {
      "x": -2,
      "y": -6,
      "z": -2,
      "name": "Plant_Leaves_Palo"
    },
    {
      "x": -2,
      "y": -5,
      "z": -2,
      "name": "Plant_Leaves_Palo"
    },
    {
      "x": -2,
      "y": -4,
      "z": -2,
      "name": "Plant_Leaves_Palo"
    },
    {
      "x": -2,
      "y": -7,
      "z": 1,
      "name": "Plant_Leaves_Palo"
    },
    {
      "x": -1,
      "y": -7,
      "z": 1,
      "name": "Plant_Leaves_Palo"
    },
    {
      "x": -2,
      "y": -6,
      "z": 1,
      "name": "Plant_Leaves_Palo"
    },
    {
      "x": -3,
      "y": -5,
      "z": 1,
      "name": "Plant_Leaves_Palo"
    },
    {
      "x": -2,
      "y": -5,
      "z": 1,
      "name": "Plant_Leaves_Palo"
    },
    {
      "x": -3,
      "y": -4,
      "z": 1,
      "name": "Plant_Leaves_Palo"
    },
    {
      "x": -3,
      "y": -3,
      "z": 1,
      "name": "Plant_Leaves_Palo"
    },
    {
      "x": -3,
      "y": -2,
      "z": 1,
      "name": "Plant_Leaves_Palo"
    },
    {
      "x": -2,
      "y": -2,
      "z": 1,
      "name": "Plant_Leaves_Palo"
    },
    {
      "x": -1,
      "y": -2,
      "z": 1,
      "name": "Plant_Leaves_Palo"
    },
    {
      "x": -4,
      "y": -3,
      "z": 3,
      "name": "Plant_Leaves_Palo"
    },
    {
      "x": -4,
      "y": -2,
      "z": 3,
      "name": "Plant_Leaves_Palo"
    },
    {
      "x": -4,
      "y": -1,
      "z": 3,
      "name": "Plant_Leaves_Palo"
    },
    {
      "x": -4,
      "y": -4,
      "z": 4,
      "name": "Plant_Leaves_Palo"
    },
    {
      "x": -4,
      "y": -3,
      "z": 4,
      "name": "Plant_Leaves_Palo"
    },
    {
      "x": -4,
      "y": -4,
      "z": 5,
      "name": "Plant_Leaves_Palo"
    },
    {
      "x": -4,
      "y": -4,
      "z": 6,
      "name": "Plant_Leaves_Palo"
    },
    {
      "x": -3,
      "y": -4,
      "z": 6,
      "name": "Plant_Leaves_Palo"
    },
    {
      "x": -3,
      "y": -3,
      "z": 6,
      "name": "Plant_Leaves_Palo"
    },
    {
      "x": -3,
      "y": -3,
      "z": 7,
      "name": "Plant_Leaves_Palo"
    },
    {
      "x": -3,
      "y": -2,
      "z": 7,
      "name": "Plant_Leaves_Palo"
    },
    {
      "x": -3,
      "y": -1,
      "z": 7,
      "name": "Plant_Leaves_Palo"
    },
    {
      "x": 0,
      "y": -5,
      "z": 1,
      "name": "Plant_Leaves_Palo"
    },
    {
      "x": 1,
      "y": -5,
      "z": 1,
      "name": "Plant_Leaves_Palo"
    },
    {
      "x": 1,
      "y": -4,
      "z": 1,
      "name": "Plant_Leaves_Palo"
    },
    {
      "x": 0,
      "y": -3,
      "z": 1,
      "name": "Plant_Leaves_Palo"
    },
    {
      "x": 1,
      "y": -3,
      "z": 1,
      "name": "Plant_Leaves_Palo"
    },
    {
      "x": 3,
      "y": -3,
      "z": 1,
      "name": "Plant_Leaves_Palo"
    },
    {
      "x": 0,
      "y": -2,
      "z": 1,
      "name": "Plant_Leaves_Palo"
    },
    {
      "x": 3,
      "y": -3,
      "z": 2,
      "name": "Plant_Leaves_Palo"
    },
    {
      "x": 3,
      "y": -3,
      "z": 3,
      "name": "Plant_Leaves_Palo"
    },
    {
      "x": 3,
      "y": -2,
      "z": 3,
      "name": "Plant_Leaves_Palo"
    },
    {
      "x": 3,
      "y": -2,
      "z": 4,
      "name": "Plant_Leaves_Palo"
    },
    {
      "x": 3,
      "y": -1,
      "z": 4,
      "name": "Plant_Leaves_Palo"
    },
    {
      "x": -2,
      "y": 3,
      "z": 0,
      "name": "Plant_Leaves_Palo"
    },
    {
      "x": -2,
      "y": 4,
      "z": 0,
      "name": "Plant_Leaves_Palo"
    },
    {
      "x": -2,
      "y": 4,
      "z": 1,
      "name": "Plant_Leaves_Palo"
    },
    {
      "x": -2,
      "y": 4,
      "z": 2,
      "name": "Plant_Leaves_Palo"
    },
    {
      "x": -3,
      "y": 4,
      "z": 3,
      "name": "Plant_Leaves_Palo"
    },
    {
      "x": -2,
      "y": 4,
      "z": 3,
      "name": "Plant_Leaves_Palo"
    },
    {
      "x": -3,
      "y": 4,
      "z": 4,
      "name": "Plant_Leaves_Palo"
    },
    {
      "x": -3,
      "y": 3,
      "z": 5,
      "name": "Plant_Leaves_Palo"
    },
    {
      "x": -3,
      "y": 4,
      "z": 5,
      "name": "Plant_Leaves_Palo"
    },
    {
      "x": -3,
      "y": 0,
      "z": 6,
      "name": "Plant_Leaves_Palo"
    },
    {
      "x": -3,
      "y": 1,
      "z": 6,
      "name": "Plant_Leaves_Palo"
    },
    {
      "x": -3,
      "y": 2,
      "z": 6,
      "name": "Plant_Leaves_Palo"
    },
    {
      "x": -3,
      "y": 3,
      "z": 6,
      "name": "Plant_Leaves_Palo"
    },
    {
      "x": -3,
      "y": 0,
      "z": 7,
      "name": "Plant_Leaves_Palo"
    }
  ],
  "fluids": [],
  "entities": []
}