{
  "version": 8,
  "blockIdVersion": 10,
  "anchorX": 0,
  "anchorY": -7,
  "anchorZ": 0,
  "blocks": [
    {
      "x": 2,
      "y": 2,
      "z": 0,
      "name": "Plant_Leaves_Palo"
    },
    {
      "x": 2,
      "y": 3,
      "z": 0,
      "name": "Plant_Leaves_Palo"
    },
    {
      "x": 3,
      "y": 3,
      "z": 0,
      "name": "Plant_Leaves_Palo"
    },
    {
      "x": 2,
      "y": 0,
      "z": 1,
      "name": "Plant_Leaves_Palo"
    },
    {
      "x": 2,
      "y": 1,
      "z": 1,
      "name": "Plant_Leaves_Palo"
    },
    {
      "x": 2,
      "y": 2,
      "z": 1,
      "name": "Plant_Leaves_Palo"
    },
    {
      "x": 5,
      "y": -1,
      "z": -4,
      "name": "Plant_Leaves_Palo"
    },
    {
      "x": 4,
      "y": -2,
      "z": -3,
      "name": "Plant_Leaves_Palo"
    },
    {
      "x": 5,
      "y": -2,
      "z": -3,
      "name": "Plant_Leaves_Palo"
    },
    {
      "x": 5,
      "y": -1,
      "z": -3,
      "name": "Plant_Leaves_Palo"
    },
    {
      "x": 4,
      "y": -3,
      "z": -2,
      "name": "Plant_Leaves_Palo"
    },
    {
      "x": 4,
      "y": -2,
      "z": -2,
      "name": "Plant_Leaves_Palo"
    },
    {
      "x": 5,
      "y": 0,
      "z": -4,
      "name": "Plant_Leaves_Palo"
    },
    {
      "x": 5,
      "y": 1,
      "z": -4,
      "name": "Plant_Leaves_Palo"
    },
    {
      "x": 5,
      "y": 2,
      "z": -4,
      "name": "Plant_Leaves_Palo"
    },
    {
      "x": 4,
      "y": 2,
      "z": -3,
      "name": "Plant_Leaves_Palo"
    },
    {
      "x": 5,
      "y": 2,
      "z": -3,
      "name": "Plant_Leaves_Palo"
    },
    {
      "x": 4,
      "y": 3,
      "z": -3,
      "name": "Plant_Leaves_Palo"
    },
    {
      "x": 3,
      "y": 3,
      "z": -2,
      "name": "Plant_Leaves_Palo"
    },
    {
      "x": 4,
      "y": 3,
      "z": -2,
      "name": "Plant_Leaves_Palo"
    },
    {
      "x": 3,
      "y": 3,
      "z": -1,
      "name": "Plant_Leaves_Palo"
    },
    {
      "x": -4,
      "y": -2,
      "z": 0,
      "name": "Plant_Leaves_Palo"
    },
    {
      "x": -3,
      "y": -2,
      "z": 0,
      "name": "Plant_Leaves_Palo"
    },
    {
      "x": -3,
      "y": -1,
      "z": 0,
      "name": "Plant_Leaves_Palo"
    },
    {
      "x": -2,
      "y": -1,
      "z": 0,
      "name": "Plant_Leaves_Palo"
    },
    {
      "x": -5,
      "y": -7,
      "z": 1,
      "name": "Plant_Leaves_Palo"
    },
    {
      "x": -5,
      "y": -6,
      "z": 1,
      "name": "Plant_Leaves_Palo"
    },
    {
      "x": -6,
      "y": -5,
      "z": 1,
      "name": "Plant_Leaves_Palo"
    },
    {
      "x": -5,
      "y": -5,
      "z": 1,
      "name": "Plant_Leaves_Palo"
    },
    {
      "x": -6,
      "y": -4,
      "z": 1,
      "name": "Plant_Leaves_Palo"
    },
    {
      "x": -6,
      "y": -3,
      "z": 1,
      "name": "Plant_Leaves_Palo"
    },
    {
      "x": -7,
      "y": -2,
      "z": 1,
      "name": "Plant_Leaves_Palo"
    },
    {
      "x": -6,
      "y": -2,
      "z": 1,
      "name": "Plant_Leaves_Palo"
    },
    {
      "x": -7,
      "y": -1,
      "z": 1,
      "name": "Plant_Leaves_Palo"
    },
    {
      "x": -2,
      "y": -7,
      "z": 4,
      "name": "Plant_Leaves_Palo"
    },
    {
      "x": -2,
      "y": -6,
      "z": 4,
      "name": "Plant_Leaves_Palo"
    },
    {
      "x": -2,
      "y": -5,
      "z": 4,
      "name": "Plant_Leaves_Palo"
    },
    {
      "x": -1,
      "y": -5,
      "z": 4,
      "name": "Plant_Leaves_Palo"
    },
    {
      "x": -1,
      "y": -4,
      "z": 4,
      "name": "Plant_Leaves_Palo"
    },
    {
      "x": -1,
      "y": -3,
      "z": 4,
      "name": "Plant_Leaves_Palo"
    },
    {
      "x": -2,
      "y": -2,
      "z": 4,
      "name": "Plant_Leaves_Palo"
    },
    {
      "x": -1,
      "y": -2,
      "z": 4,
      "name": "Plant_Leaves_Palo"
    },
    {
      "x": -5,
      "y": -4,
      "z": 5,
      "name": "Plant_Leaves_Palo"
    },
    {
      "x": -4,
      "y": -4,
      "z": 5,
      "name": "Plant_Leaves_Palo"
    },
    {
      "x": -6,
      "y": -3,
      "z": 5,
      "name": "Plant_Leaves_Palo"
    },
    {
      "x": -5,
      "y": -3,
      "z": 5,
      "name": "Plant_Leaves_Palo"
    },
    {
      "x": -6,
      "y": -2,
      "z": 5,
      "name": "Plant_Leaves_Palo"
    },
    {
      "x": -2,
      "y": -2,
      "z": 5,
      "name": "Plant_Leaves_Palo"
    },
    {
      "x": -6,
      "y": -1,
      "z": 5,
      "name": "Plant_Leaves_Palo"
    },
    {
      "x": -5,
      "y": -1,
      "z": 5,
      "name": "Plant_Leaves_Palo"
    },
    {
      "x": -3,
      "y": -1,
      "z": 5,
      "name": "Plant_Leaves_Palo"
    },
    {
      "x": -2,
      "y": -1,
      "z": 5,
      "name": "Plant_Leaves_Palo"
    },
    {
      "x": 2,
      "y": -7,
      "z": 0,
      "name": "Plant_Leaves_Palo"
    },
    {
      "x": 2,
      "y": -6,
      "z": 0,
      "name": "Plant_Leaves_Palo"
    },
    {
      "x": 1,
      "y": -5,
      "z": 0,
      "name": "Plant_Leaves_Palo"
    },
    {
      "x": 2,
      "y": -5,
      "z": 0,
      "name": "Plant_Leaves_Palo"
    },
    {
      "x": 1,
      "y": -4,
      "z": 0,
      "name": "Plant_Leaves_Palo"
    },
    {
      "x": 1,
      "y": -4,
      "z": 1,
      "name": "Plant_Leaves_Palo"
    },
    {
      "x": 1,
      "y": -3,
      "z": 1,
      "name": "Plant_Leaves_Palo"
    },
    {
      "x": 1,
      "y": -2,
      "z": 1,
      "name": "Plant_Leaves_Palo"
    },
    {
      "x": 1,
      "y": -1,
      "z": 1,
      "name": "Plant_Leaves_Palo"
    },
    {
      "x": 2,
      "y": -1,
      "z": 1,
      "name": "Plant_Leaves_Palo"
    },
    {
      "x": -2,
      "y": 0,
      "z": 0,
      "name": "Plant_Leaves_Palo"
    },
    {
      "x": -6,
      "y": 1,
      "z": 0,
      "name": "Plant_Leaves_Palo"
    },
    {
      "x": -2,
      "y": 1,
      "z": 0,
      "name": "Plant_Leaves_Palo"
    },
    {
      "x": -6,
      "y": 2,
      "z": 0,
      "name": "Plant_Leaves_Palo"
    },
    {
      "x": -5,
      "y": 2,
      "z": 0,
      "name": "Plant_Leaves_Palo"
    },
    {
      "x": -3,
      "y": 2,
      "z": 0,
      "name": "Plant_Leaves_Palo"
    },
    {
      "x": -2,
      "y": 2,
      "z": 0,
      "name": "Plant_Leaves_Palo"
    },
    {
      "x": -5,
      "y": 3,
      "z": 0,
      "name": "Plant_Leaves_Palo"
    },
    {
      "x": -4,
      "y": 3,
      "z": 0,
      "name": "Plant_Leaves_Palo"
    },
    {
      "x": -3,
      "y": 3,
      "z": 0,
      "name": "Plant_Leaves_Palo"
    },
    {
      "x": -7,
      "y": 0,
      "z": 1,
      "name": "Plant_Leaves_Palo"
    },
    {
      "x": -7,
      "y": 1,
      "z": 1,
      "name": "Plant_Leaves_Palo"
    },
    {
      "x": -6,
      "y": 1,
      "z": 1,
      "name": "Plant_Leaves_Palo"
    },
    {
      "x": -5,
      "y": 0,
      "z": 5,
      "name": "Plant_Leaves_Palo"
    },
    {
      "x": -4,
      "y": 0,
      "z": 5,
      "name": "Plant_Leaves_Palo"
    },
    {
      "x": -3,
      "y": 0,
      "z": 5,
      "name": "Plant_Leaves_Palo"
    }
  ],
  "fluids": [],
  "entities": []
}