{
  "version": 8,
  "blockIdVersion": 11,
  "anchorX": -2,
  "anchorY": 8,
  "anchorZ": -6,
  "blocks": [
    {
      "x": -2,
      "y": 8,
      "z": -6,
      "name": "Wood_Tropicalwood_Planks_Half",
      "rotation": 8
    },
    {
      "x": -2,
      "y": 9,
      "z": -6,
      "name": "Empty"
    },
    {
      "x": -2,
      "y": 10,
      "z": -6,
      "name": "Empty"
    },
    {
      "x": -2,
      "y": 8,
      "z": -5,
      "name": "Wood_Tropicalwood_Planks_Half",
      "rotation": 8
    },
    {
      "x": -2,
      "y": 9,
      "z": -5,
      "name": "Wood_Tropicalwood_Fence",
      "rotation": 3
    },
    {
      "x": -2,
      "y": 10,
      "z": -5,
      "name": "Empty"
    },
    {
      "x": -2,
      "y": 8,
      "z": -4,
      "name": "Wood_Tropicalwood_Planks_Half",
      "rotation": 8
    },
    {
      "x": -2,
      "y": 9,
      "z": -4,
      "name": "Wood_Tropicalwood_Fence",
      "rotation": 1
    },
    {
      "x": -2,
      "y": 10,
      "z": -4,
      "name": "Empty"
    },
    {
      "x": -2,
      "y": 8,
      "z": -3,
      "name": "Wood_Tropicalwood_Planks_Half",
      "rotation": 8
    },
    {
      "x": -2,
      "y": 9,
      "z": -3,
      "name": "Wood_Tropicalwood_Fence",
      "rotation": 1
    },
    {
      "x": -2,
      "y": 10,
      "z": -3,
      "name": "Empty"
    },
    {
      "x": -2,
      "y": 8,
      "z": -2,
      "name": "Wood_Tropicalwood_Planks_Half",
      "rotation": 8
    },
    {
      "x": -2,
      "y": 9,
      "z": -2,
      "name": "Wood_Tropicalwood_Fence",
      "rotation": 1
    },
    {
      "x": -2,
      "y": 10,
      "z": -2,
      "name": "Empty"
    },
    {
      "x": -2,
      "y": 8,
      "z": -1,
      "name": "Wood_Tropicalwood_Planks_Half",
      "rotation": 8
    },
    {
      "x": -2,
      "y": 9,
      "z": -1,
      "name": "Wood_Tropicalwood_Fence",
      "rotation": 1
    },
    {
      "x": -2,
      "y": 8,
      "z": 0,
      "name": "Wood_Tropicalwood_Planks_Half",
      "rotation": 8
    },
    {
      "x": -2,
      "y": 9,
      "z": 0,
      "name": "Wood_Tropicalwood_Fence",
      "rotation": 1
    },
    {
      "x": -2,
      "y": 8,
      "z": 1,
      "name": "Wood_Tropicalwood_Planks_Half",
      "rotation": 8
    },
    {
      "x": -2,
      "y": 9,
      "z": 1,
      "name": "Wood_Tropicalwood_Fence",
      "rotation": 3
    },
    {
      "x": -2,
      "y": 8,
      "z": 2,
      "name": "Wood_Tropicalwood_Planks_Half",
      "rotation": 8
    },
    {
      "x": -2,
      "y": 9,
      "z": 2,
      "name": "Wood_Tropicalwood_Fence",
      "rotation": 3
    },
    {
      "x": -2,
      "y": 8,
      "z": 3,
      "name": "Wood_Tropicalwood_Planks_Half",
      "rotation": 8
    },
    {
      "x": -2,
      "y": 9,
      "z": 3,
      "name": "Wood_Tropicalwood_Fence",
      "rotation": 3
    },
    {
      "x": -2,
      "y": 8,
      "z": 4,
      "name": "Wood_Tropicalwood_Planks_Half",
      "rotation": 8
    },
    {
      "x": -2,
      "y": 9,
      "z": 4,
      "name": "Wood_Tropicalwood_Fence",
      "rotation": 3
    },
    {
      "x": -2,
      "y": 8,
      "z": 5,
      "name": "Wood_Tropicalwood_Planks_Half",
      "rotation": 8
    },
    {
      "x": -2,
      "y": 9,
      "z": 5,
      "name": "Wood_Tropicalwood_Fence",
      "rotation": 3
    },
    {
      "x": -2,
      "y": 0,
      "z": 6,
      "name": "Wood_Bamboo_Branch_Long_Deco",
      "support": 15
    },
    {
      "x": -2,
      "y": 1,
      "z": 6,
      "name": "Wood_Bamboo_Branch_Long_Deco",
      "support": 15
    },
    {
      "x": -2,
      "y": 2,
      "z": 6,
      "name": "Wood_Bamboo_Branch_Long_Deco",
      "support": 15
    },
    {
      "x": -2,
      "y": 3,
      "z": 6,
      "name": "Wood_Bamboo_Branch_Long_Deco",
      "support": 15
    },
    {
      "x": -2,
      "y": 4,
      "z": 6,
      "name": "Wood_Bamboo_Branch_Long_Deco",
      "support": 15
    },
    {
      "x": -2,
      "y": 5,
      "z": 6,
      "name": "Wood_Bamboo_Branch_Long_Deco",
      "support": 15
    },
    {
      "x": -2,
      "y": 6,
      "z": 6,
      "name": "Wood_Bamboo_Branch_Long_Deco",
      "support": 15
    },
    {
      "x": -2,
      "y": 7,
      "z": 6,
      "name": "Wood_Bamboo_Branch_Long_Deco",
      "support": 15
    },
    {
      "x": -2,
      "y": 8,
      "z": 6,
      "name": "Wood_Bamboo_Trunk_Deco",
      "support": 15
    },
    {
      "x": -2,
      "y": 9,
      "z": 6,
      "name": "*Wood_Tropicalwood_Fence_State_Definitions_Corner",
      "rotation": 2
    },
    {
      "x": -1,
      "y": 8,
      "z": -6,
      "name": "Wood_Tropicalwood_Planks_Half",
      "rotation": 8
    },
    {
      "x": -1,
      "y": 9,
      "z": -6,
      "name": "Empty"
    },
    {
      "x": -1,
      "y": 10,
      "z": -6,
      "name": "Empty"
    },
    {
      "x": -1,
      "y": 11,
      "z": -6,
      "name": "Empty"
    },
    {
      "x": -1,
      "y": 8,
      "z": -5,
      "name": "Wood_Tropicalwood_Planks_Half",
      "rotation": 8
    },
    {
      "x": -1,
      "y": 9,
      "z": -5,
      "name": "Empty"
    },
    {
      "x": -1,
      "y": 10,
      "z": -5,
      "name": "Empty"
    },
    {
      "x": -1,
      "y": 11,
      "z": -5,
      "name": "Empty"
    },
    {
      "x": -1,
      "y": 8,
      "z": -4,
      "name": "Wood_Tropicalwood_Planks_Half",
      "rotation": 8
    },
    {
      "x": -1,
      "y": 9,
      "z": -4,
      "name": "Empty"
    },
    {
      "x": -1,
      "y": 10,
      "z": -4,
      "name": "Empty"
    },
    {
      "x": -1,
      "y": 11,
      "z": -4,
      "name": "Empty"
    },
    {
      "x": -1,
      "y": 8,
      "z": -3,
      "name": "Wood_Tropicalwood_Planks_Half",
      "rotation": 8
    },
    {
      "x": -1,
      "y": 9,
      "z": -3,
      "name": "Empty"
    },
    {
      "x": -1,
      "y": 10,
      "z": -3,
      "name": "Empty"
    },
    {
      "x": -1,
      "y": 11,
      "z": -3,
      "name": "Empty"
    },
    {
      "x": -1,
      "y": 8,
      "z": -2,
      "name": "Wood_Tropicalwood_Planks_Half",
      "rotation": 8
    },
    {
      "x": -1,
      "y": 9,
      "z": -2,
      "name": "Empty"
    },
    {
      "x": -1,
      "y": 10,
      "z": -2,
      "name": "Empty"
    },
    {
      "x": -1,
      "y": 11,
      "z": -2,
      "name": "Empty"
    },
    {
      "x": -1,
      "y": 8,
      "z": -1,
      "name": "Wood_Tropicalwood_Planks_Half",
      "rotation": 8
    },
    {
      "x": -1,
      "y": 8,
      "z": 0,
      "name": "Wood_Tropicalwood_Planks_Half",
      "rotation": 8
    },
    {
      "x": -1,
      "y": 8,
      "z": 1,
      "name": "Wood_Tropicalwood_Planks_Half",
      "rotation": 8
    },
    {
      "x": -1,
      "y": 8,
      "z": 2,
      "name": "Wood_Tropicalwood_Planks_Half",
      "rotation": 8
    },
    {
      "x": -1,
      "y": 8,
      "z": 3,
      "name": "Wood_Tropicalwood_Planks_Half",
      "rotation": 8
    },
    {
      "x": -1,
      "y": 8,
      "z": 4,
      "name": "Wood_Tropicalwood_Planks_Half",
      "rotation": 8
    },
    {
      "x": -1,
      "y": 8,
      "z": 5,
      "name": "Wood_Tropicalwood_Planks_Half",
      "rotation": 8
    },
    {
      "x": -1,
      "y": 8,
      "z": 6,
      "name": "Wood_Tropicalwood_Planks_Half",
      "rotation": 8
    },
    {
      "x": -1,
      "y": 9,
      "z": 6,
      "name": "Wood_Tropicalwood_Fence"
    },
    {
      "x": 0,
      "y": 8,
      "z": -6,
      "name": "Wood_Tropicalwood_Planks_Half",
      "rotation": 8
    },
    {
      "x": 0,
      "y": 9,
      "z": -6,
      "name": "Empty"
    },
    {
      "x": 0,
      "y": 10,
      "z": -6,
      "name": "Empty"
    },
    {
      "x": 0,
      "y": 11,
      "z": -6,
      "name": "Empty"
    },
    {
      "x": 0,
      "y": 8,
      "z": -5,
      "name": "Wood_Tropicalwood_Planks_Half",
      "rotation": 8
    },
    {
      "x": 0,
      "y": 9,
      "z": -5,
      "name": "Empty"
    },
    {
      "x": 0,
      "y": 10,
      "z": -5,
      "name": "Empty"
    },
    {
      "x": 0,
      "y": 11,
      "z": -5,
      "name": "Empty"
    },
    {
      "x": 0,
      "y": 8,
      "z": -4,
      "name": "Wood_Tropicalwood_Planks_Half",
      "rotation": 8
    },
    {
      "x": 0,
      "y": 9,
      "z": -4,
      "name": "Empty"
    },
    {
      "x": 0,
      "y": 10,
      "z": -4,
      "name": "Empty"
    },
    {
      "x": 0,
      "y": 11,
      "z": -4,
      "name": "Empty"
    },
    {
      "x": 0,
      "y": 8,
      "z": -3,
      "name": "Wood_Tropicalwood_Planks_Half",
      "rotation": 8
    },
    {
      "x": 0,
      "y": 9,
      "z": -3,
      "name": "Empty"
    },
    {
      "x": 0,
      "y": 10,
      "z": -3,
      "name": "Empty"
    },
    {
      "x": 0,
      "y": 11,
      "z": -3,
      "name": "Empty"
    },
    {
      "x": 0,
      "y": 8,
      "z": -2,
      "name": "Wood_Tropicalwood_Planks_Half",
      "rotation": 8
    },
    {
      "x": 0,
      "y": 9,
      "z": -2,
      "name": "Empty"
    },
    {
      "x": 0,
      "y": 10,
      "z": -2,
      "name": "Empty"
    },
    {
      "x": 0,
      "y": 11,
      "z": -2,
      "name": "Empty"
    },
    {
      "x": 0,
      "y": 8,
      "z": -1,
      "name": "Wood_Tropicalwood_Planks_Half",
      "rotation": 8
    },
    {
      "x": 0,
      "y": 8,
      "z": 0,
      "name": "Wood_Tropicalwood_Planks_Half",
      "rotation": 8
    },
    {
      "x": 0,
      "y": 8,
      "z": 1,
      "name": "Wood_Tropicalwood_Planks_Half",
      "rotation": 8
    },
    {
      "x": 0,
      "y": 8,
      "z": 2,
      "name": "Wood_Tropicalwood_Planks_Half",
      "rotation": 8
    },
    {
      "x": 0,
      "y": 8,
      "z": 3,
      "name": "Wood_Tropicalwood_Planks_Half",
      "rotation": 8
    },
    {
      "x": 0,
      "y": 8,
      "z": 4,
      "name": "Wood_Tropicalwood_Planks_Half",
      "rotation": 8
    },
    {
      "x": 0,
      "y": 8,
      "z": 5,
      "name": "Wood_Tropicalwood_Planks_Half",
      "rotation": 8
    },
    {
      "x": 0,
      "y": 8,
      "z": 6,
      "name": "Wood_Tropicalwood_Planks_Half",
      "rotation": 8
    },
    {
      "x": 0,
      "y": 9,
      "z": 6,
      "name": "Wood_Tropicalwood_Fence"
    },
    {
      "x": 1,
      "y": 8,
      "z": -6,
      "name": "Wood_Tropicalwood_Planks_Half",
      "rotation": 8
    },
    {
      "x": 1,
      "y": 9,
      "z": -6,
      "name": "Empty"
    },
    {
      "x": 1,
      "y": 10,
      "z": -6,
      "name": "Empty"
    },
    {
      "x": 1,
      "y": 11,
      "z": -6,
      "name": "Empty"
    },
    {
      "x": 1,
      "y": 8,
      "z": -5,
      "name": "Wood_Tropicalwood_Planks_Half",
      "rotation": 8
    },
    {
      "x": 1,
      "y": 9,
      "z": -5,
      "name": "Empty"
    },
    {
      "x": 1,
      "y": 10,
      "z": -5,
      "name": "Empty"
    },
    {
      "x": 1,
      "y": 11,
      "z": -5,
      "name": "Empty"
    },
    {
      "x": 1,
      "y": 8,
      "z": -4,
      "name": "Wood_Tropicalwood_Planks_Half",
      "rotation": 8
    },
    {
      "x": 1,
      "y": 9,
      "z": -4,
      "name": "Empty"
    },
    {
      "x": 1,
      "y": 10,
      "z": -4,
      "name": "Empty"
    },
    {
      "x": 1,
      "y": 11,
      "z": -4,
      "name": "Empty"
    },
    {
      "x": 1,
      "y": 8,
      "z": -3,
      "name": "Wood_Tropicalwood_Planks_Half",
      "rotation": 8
    },
    {
      "x": 1,
      "y": 9,
      "z": -3,
      "name": "Empty"
    },
    {
      "x": 1,
      "y": 10,
      "z": -3,
      "name": "Empty"
    },
    {
      "x": 1,
      "y": 11,
      "z": -3,
      "name": "Empty"
    },
    {
      "x": 1,
      "y": 8,
      "z": -2,
      "name": "Wood_Tropicalwood_Planks_Half",
      "rotation": 8
    },
    {
      "x": 1,
      "y": 9,
      "z": -2,
      "name": "Empty"
    },
    {
      "x": 1,
      "y": 10,
      "z": -2,
      "name": "Empty"
    },
    {
      "x": 1,
      "y": 11,
      "z": -2,
      "name": "Empty"
    },
    {
      "x": 1,
      "y": 8,
      "z": -1,
      "name": "Wood_Tropicalwood_Planks_Half",
      "rotation": 8
    },
    {
      "x": 1,
      "y": 8,
      "z": 0,
      "name": "Wood_Tropicalwood_Planks_Half",
      "rotation": 8
    },
    {
      "x": 1,
      "y": 8,
      "z": 1,
      "name": "Wood_Tropicalwood_Planks_Half",
      "rotation": 8
    },
    {
      "x": 1,
      "y": 8,
      "z": 2,
      "name": "Wood_Tropicalwood_Planks_Half",
      "rotation": 8
    },
    {
      "x": 1,
      "y": 8,
      "z": 3,
      "name": "Wood_Tropicalwood_Planks_Half",
      "rotation": 8
    },
    {
      "x": 1,
      "y": 8,
      "z": 4,
      "name": "Wood_Tropicalwood_Planks_Half",
      "rotation": 8
    },
    {
      "x": 1,
      "y": 8,
      "z": 5,
      "name": "Wood_Tropicalwood_Planks_Half",
      "rotation": 8
    },
    {
      "x": 1,
      "y": 8,
      "z": 6,
      "name": "Wood_Tropicalwood_Planks_Half",
      "rotation": 8
    },
    {
      "x": 1,
      "y": 9,
      "z": 6,
      "name": "Wood_Tropicalwood_Fence"
    },
    {
      "x": 2,
      "y": 8,
      "z": -6,
      "name": "Wood_Tropicalwood_Planks_Half",
      "rotation": 8
    },
    {
      "x": 2,
      "y": 9,
      "z": -6,
      "name": "Empty"
    },
    {
      "x": 2,
      "y": 10,
      "z": -6,
      "name": "Empty"
    },
    {
      "x": 2,
      "y": 8,
      "z": -5,
      "name": "Wood_Tropicalwood_Planks_Half",
      "rotation": 8
    },
    {
      "x": 2,
      "y": 9,
      "z": -5,
      "name": "Wood_Tropicalwood_Fence",
      "rotation": 1
    },
    {
      "x": 2,
      "y": 10,
      "z": -5,
      "name": "Empty"
    },
    {
      "x": 2,
      "y": 8,
      "z": -4,
      "name": "Wood_Tropicalwood_Planks_Half",
      "rotation": 8
    },
    {
      "x": 2,
      "y": 9,
      "z": -4,
      "name": "Wood_Tropicalwood_Fence",
      "rotation": 3
    },
    {
      "x": 2,
      "y": 10,
      "z": -4,
      "name": "Empty"
    },
    {
      "x": 2,
      "y": 8,
      "z": -3,
      "name": "Wood_Tropicalwood_Planks_Half",
      "rotation": 8
    },
    {
      "x": 2,
      "y": 9,
      "z": -3,
      "name": "Wood_Tropicalwood_Fence",
      "rotation": 3
    },
    {
      "x": 2,
      "y": 10,
      "z": -3,
      "name": "Empty"
    },
    {
      "x": 2,
      "y": 8,
      "z": -2,
      "name": "Wood_Tropicalwood_Planks_Half",
      "rotation": 8
    },
    {
      "x": 2,
      "y": 9,
      "z": -2,
      "name": "Wood_Tropicalwood_Fence",
      "rotation": 3
    },
    {
      "x": 2,
      "y": 10,
      "z": -2,
      "name": "Empty"
    },
    {
      "x": 2,
      "y": 8,
      "z": -1,
      "name": "Wood_Tropicalwood_Planks_Half",
      "rotation": 8
    },
    {
      "x": 2,
      "y": 9,
      "z": -1,
      "name": "Wood_Tropicalwood_Fence",
      "rotation": 1
    },
    {
      "x": 2,
      "y": 8,
      "z": 0,
      "name": "Wood_Tropicalwood_Planks_Half",
      "rotation": 8
    },
    {
      "x": 2,
      "y": 9,
      "z": 0,
      "name": "Wood_Tropicalwood_Fence",
      "rotation": 1
    },
    {
      "x": 2,
      "y": 8,
      "z": 1,
      "name": "Wood_Tropicalwood_Planks_Half",
      "rotation": 8
    },
    {
      "x": 2,
      "y": 9,
      "z": 1,
      "name": "Wood_Tropicalwood_Fence",
      "rotation": 1
    },
    {
      "x": 2,
      "y": 8,
      "z": 2,
      "name": "Wood_Tropicalwood_Planks_Half",
      "rotation": 8
    },
    {
      "x": 2,
      "y": 8,
      "z": 3,
      "name": "Wood_Tropicalwood_Planks_Half",
      "rotation": 8
    },
    {
      "x": 2,
      "y": 8,
      "z": 4,
      "name": "Wood_Tropicalwood_Planks_Half",
      "rotation": 8
    },
    {
      "x": 2,
      "y": 9,
      "z": 4,
      "name": "Wood_Tropicalwood_Fence",
      "rotation": 3
    },
    {
      "x": 2,
      "y": 8,
      "z": 5,
      "name": "Wood_Tropicalwood_Planks_Half",
      "rotation": 8
    },
    {
      "x": 2,
      "y": 9,
      "z": 5,
      "name": "Wood_Tropicalwood_Fence",
      "rotation": 1
    },
    {
      "x": 2,
      "y": 0,
      "z": 6,
      "name": "Wood_Bamboo_Branch_Long_Deco",
      "support": 15
    },
    {
      "x": 2,
      "y": 1,
      "z": 6,
      "name": "Wood_Bamboo_Branch_Long_Deco",
      "support": 15
    },
    {
      "x": 2,
      "y": 2,
      "z": 6,
      "name": "Wood_Bamboo_Branch_Long_Deco",
      "support": 15
    },
    {
      "x": 2,
      "y": 3,
      "z": 6,
      "name": "Wood_Bamboo_Branch_Long_Deco",
      "support": 15
    },
    {
      "x": 2,
      "y": 4,
      "z": 6,
      "name": "Wood_Bamboo_Branch_Long_Deco",
      "support": 15
    },
    {
      "x": 2,
      "y": 5,
      "z": 6,
      "name": "Wood_Bamboo_Branch_Long_Deco",
      "support": 15
    },
    {
      "x": 2,
      "y": 6,
      "z": 6,
      "name": "Wood_Bamboo_Branch_Long_Deco",
      "support": 15
    },
    {
      "x": 2,
      "y": 7,
      "z": 6,
      "name": "Wood_Bamboo_Branch_Long_Deco",
      "support": 15
    },
    {
      "x": 2,
      "y": 8,
      "z": 6,
      "name": "Wood_Bamboo_Trunk_Deco",
      "support": 15
    },
    {
      "x": 2,
      "y": 9,
      "z": 6,
      "name": "*Wood_Tropicalwood_Fence_State_Definitions_Corner",
      "rotation": 3
    },
    {
      "x": 3,
      "y": 4,
      "z": 3,
      "name": "Furniture_Jungle_Ladder",
      "rotation": 1
    },
    {
      "x": 3,
      "y": 5,
      "z": 3,
      "name": "Furniture_Jungle_Ladder",
      "rotation": 1
    },
    {
      "x": 3,
      "y": 6,
      "z": 3,
      "name": "Furniture_Jungle_Ladder",
      "rotation": 1
    },
    {
      "x": 3,
      "y": 7,
      "z": 3,
      "name": "Furniture_Jungle_Ladder",
      "rotation": 1
    },
    {
      "x": 3,
      "y": 8,
      "z": 3,
      "name": "Furniture_Jungle_Ladder",
      "rotation": 1
    }
  ]
}