{
  "version": 8,
  "blockIdVersion": 11,
  "anchorX": 0,
  "anchorY": 5,
  "anchorZ": 0,
  "blocks": [
    {
      "x": -4,
      "y": 2,
      "z": -1,
      "name": "Cloth_Roof_Blue_Shallow",
      "rotation": 9
    },
    {
      "x": -4,
      "y": 3,
      "z": 0,
      "name": "Cloth_Roof_Blue_Steep",
      "rotation": 1
    },
    {
      "x": -4,
      "y": 4,
      "z": 0,
      "name": "Cloth_Roof_Blue_Steep",
      "filler": 1024,
      "rotation": 1
    },
    {
      "x": -4,
      "y": 2,
      "z": 1,
      "name": "Cloth_Roof_Blue_Shallow",
      "rotation": 9
    },
    {
      "x": -3,
      "y": 2,
      "z": -1,
      "name": "Cloth_Roof_Blue_Shallow",
      "filler": 1,
      "rotation": 9
    },
    {
      "x": -3,
      "y": 3,
      "z": 0,
      "name": "Cloth_Roof_Blue_Shallow",
      "filler": 31,
      "rotation": 11
    },
    {
      "x": -3,
      "y": 2,
      "z": 1,
      "name": "Cloth_Roof_Blue_Shallow",
      "filler": 1,
      "rotation": 9
    },
    {
      "x": -2,
      "y": 2,
      "z": -1,
      "name": "Cloth_Roof_Blue_Steep",
      "filler": 31744,
      "rotation": 11
    },
    {
      "x": -2,
      "y": 3,
      "z": -1,
      "name": "Cloth_Roof_Blue_Steep",
      "rotation": 11
    },
    {
      "x": -2,
      "y": 3,
      "z": 0,
      "name": "Cloth_Roof_Blue_Shallow",
      "rotation": 11
    },
    {
      "x": -2,
      "y": 2,
      "z": 1,
      "name": "Cloth_Roof_Blue_Steep",
      "filler": 31744,
      "rotation": 11
    },
    {
      "x": -2,
      "y": 3,
      "z": 1,
      "name": "Cloth_Roof_Blue_Steep",
      "rotation": 11
    },
    {
      "x": -1,
      "y": 2,
      "z": -4,
      "name": "Cloth_Roof_Blue_Shallow",
      "rotation": 8
    },
    {
      "x": -1,
      "y": 2,
      "z": -3,
      "name": "Cloth_Roof_Blue_Shallow",
      "filler": 32,
      "rotation": 8
    },
    {
      "x": -1,
      "y": 2,
      "z": -2,
      "name": "Cloth_Roof_Blue_Steep",
      "filler": 31744,
      "rotation": 10
    },
    {
      "x": -1,
      "y": 3,
      "z": -2,
      "name": "Cloth_Roof_Blue_Steep",
      "rotation": 10
    },
    {
      "x": -1,
      "y": 4,
      "z": -1,
      "name": "*Cloth_Roof_Blue_State_Definitions_Inverted_Corner_Right",
      "rotation": 10
    },
    {
      "x": -1,
      "y": 3,
      "z": 0,
      "name": "Cloth_Roof_Yellow",
      "rotation": 11
    },
    {
      "x": -1,
      "y": 4,
      "z": 0,
      "name": "Cloth_Roof_Blue",
      "rotation": 11
    },
    {
      "x": -1,
      "y": 5,
      "z": 0,
      "name": "Cloth_Roof_Green",
      "rotation": 9
    },
    {
      "x": -1,
      "y": 4,
      "z": 1,
      "name": "*Cloth_Roof_Blue_State_Definitions_Inverted_Corner_Right",
      "rotation": 11
    },
    {
      "x": -1,
      "y": 2,
      "z": 2,
      "name": "Cloth_Roof_Blue_Steep",
      "filler": 31744,
      "rotation": 8
    },
    {
      "x": -1,
      "y": 3,
      "z": 2,
      "name": "Cloth_Roof_Blue_Steep",
      "rotation": 8
    },
    {
      "x": -1,
      "y": 2,
      "z": 3,
      "name": "Cloth_Roof_Blue_Shallow",
      "filler": 992,
      "rotation": 10
    },
    {
      "x": -1,
      "y": 2,
      "z": 4,
      "name": "Cloth_Roof_Blue_Shallow",
      "rotation": 10
    },
    {
      "x": 0,
      "y": 3,
      "z": -4,
      "name": "Cloth_Roof_Blue_Steep"
    },
    {
      "x": 0,
      "y": 4,
      "z": -4,
      "name": "Cloth_Roof_Blue_Steep",
      "filler": 1024
    },
    {
      "x": 0,
      "y": 3,
      "z": -3,
      "name": "Cloth_Roof_Blue_Shallow",
      "filler": 992,
      "rotation": 10
    },
    {
      "x": 0,
      "y": 3,
      "z": -2,
      "name": "Cloth_Roof_Blue_Shallow",
      "rotation": 10
    },
    {
      "x": 0,
      "y": 3,
      "z": -1,
      "name": "Cloth_Roof_Yellow",
      "rotation": 10
    },
    {
      "x": 0,
      "y": 4,
      "z": -1,
      "name": "Cloth_Roof_Blue",
      "rotation": 10
    },
    {
      "x": 0,
      "y": 5,
      "z": -1,
      "name": "Cloth_Roof_Green",
      "rotation": 8
    },
    {
      "x": 0,
      "y": 3,
      "z": 0,
      "name": "Plant_Crop_Mushroom_Block_Blue_Mycelium"
    },
    {
      "x": 0,
      "y": 4,
      "z": 0,
      "name": "Rock_Crystal_Cyan_Block",
      "rotation": 10
    },
    {
      "x": 0,
      "y": 5,
      "z": 0,
      "name": "Cloth_Block_Wool_Green",
      "rotation": 10
    },
    {
      "x": 0,
      "y": 3,
      "z": 1,
      "name": "Cloth_Roof_Yellow",
      "rotation": 8
    },
    {
      "x": 0,
      "y": 4,
      "z": 1,
      "name": "Cloth_Roof_Blue",
      "rotation": 8
    },
    {
      "x": 0,
      "y": 5,
      "z": 1,
      "name": "Cloth_Roof_Green",
      "rotation": 10
    },
    {
      "x": 0,
      "y": 3,
      "z": 2,
      "name": "Cloth_Roof_Blue_Shallow",
      "rotation": 8
    },
    {
      "x": 0,
      "y": 3,
      "z": 3,
      "name": "Cloth_Roof_Blue_Shallow",
      "filler": 32,
      "rotation": 8
    },
    {
      "x": 0,
      "y": 3,
      "z": 4,
      "name": "Cloth_Roof_Blue_Steep",
      "rotation": 2
    },
    {
      "x": 0,
      "y": 4,
      "z": 4,
      "name": "Cloth_Roof_Blue_Steep",
      "filler": 1024,
      "rotation": 2
    },
    {
      "x": 1,
      "y": 2,
      "z": -4,
      "name": "Cloth_Roof_Blue_Shallow",
      "rotation": 8
    },
    {
      "x": 1,
      "y": 2,
      "z": -3,
      "name": "Cloth_Roof_Blue_Shallow",
      "filler": 32,
      "rotation": 8
    },
    {
      "x": 1,
      "y": 2,
      "z": -2,
      "name": "Cloth_Roof_Blue_Steep",
      "filler": 31744,
      "rotation": 10
    },
    {
      "x": 1,
      "y": 3,
      "z": -2,
      "name": "Cloth_Roof_Blue_Steep",
      "rotation": 10
    },
    {
      "x": 1,
      "y": 4,
      "z": -1,
      "name": "*Cloth_Roof_Blue_State_Definitions_Inverted_Corner_Right",
      "rotation": 9
    },
    {
      "x": 1,
      "y": 3,
      "z": 0,
      "name": "Cloth_Roof_Yellow",
      "rotation": 9
    },
    {
      "x": 1,
      "y": 4,
      "z": 0,
      "name": "Cloth_Roof_Blue",
      "rotation": 9
    },
    {
      "x": 1,
      "y": 5,
      "z": 0,
      "name": "Cloth_Roof_Green",
      "rotation": 11
    },
    {
      "x": 1,
      "y": 4,
      "z": 1,
      "name": "*Cloth_Roof_Blue_State_Definitions_Inverted_Corner_Right",
      "rotation": 8
    },
    {
      "x": 1,
      "y": 2,
      "z": 2,
      "name": "Cloth_Roof_Blue_Steep",
      "filler": 31744,
      "rotation": 8
    },
    {
      "x": 1,
      "y": 3,
      "z": 2,
      "name": "Cloth_Roof_Blue_Steep",
      "rotation": 8
    },
    {
      "x": 1,
      "y": 2,
      "z": 3,
      "name": "Cloth_Roof_Blue_Shallow",
      "filler": 992,
      "rotation": 10
    },
    {
      "x": 1,
      "y": 2,
      "z": 4,
      "name": "Cloth_Roof_Blue_Shallow",
      "rotation": 10
    },
    {
      "x": 2,
      "y": 2,
      "z": -1,
      "name": "Cloth_Roof_Blue_Steep",
      "filler": 31744,
      "rotation": 9
    },
    {
      "x": 2,
      "y": 3,
      "z": -1,
      "name": "Cloth_Roof_Blue_Steep",
      "rotation": 9
    },
    {
      "x": 2,
      "y": 3,
      "z": 0,
      "name": "Cloth_Roof_Blue_Shallow",
      "rotation": 9
    },
    {
      "x": 2,
      "y": 2,
      "z": 1,
      "name": "Cloth_Roof_Blue_Steep",
      "filler": 31744,
      "rotation": 9
    },
    {
      "x": 2,
      "y": 3,
      "z": 1,
      "name": "Cloth_Roof_Blue_Steep",
      "rotation": 9
    },
    {
      "x": 3,
      "y": 2,
      "z": -1,
      "name": "Cloth_Roof_Blue_Shallow",
      "filler": 31,
      "rotation": 11
    },
    {
      "x": 3,
      "y": 3,
      "z": 0,
      "name": "Cloth_Roof_Blue_Shallow",
      "filler": 1,
      "rotation": 9
    },
    {
      "x": 3,
      "y": 2,
      "z": 1,
      "name": "Cloth_Roof_Blue_Shallow",
      "filler": 31,
      "rotation": 11
    },
    {
      "x": 4,
      "y": 2,
      "z": -1,
      "name": "Cloth_Roof_Blue_Shallow",
      "rotation": 11
    },
    {
      "x": 4,
      "y": 3,
      "z": 0,
      "name": "Cloth_Roof_Blue_Steep",
      "rotation": 3
    },
    {
      "x": 4,
      "y": 4,
      "z": 0,
      "name": "Cloth_Roof_Blue_Steep",
      "filler": 1024,
      "rotation": 3
    },
    {
      "x": 4,
      "y": 2,
      "z": 1,
      "name": "Cloth_Roof_Blue_Shallow",
      "rotation": 11
    }
  ]
}