{
  "version": 8,
  "blockIdVersion": 11,
  "anchorX": 0,
  "anchorY": 5,
  "anchorZ": 0,
  "blocks": [
    {
      "x": -4,
      "y": 3,
      "z": -1,
      "name": "Cloth_Roof_Red_Vertical",
      "rotation": 11
    },
    {
      "x": -4,
      "y": 4,
      "z": -1,
      "name": "Cloth_Roof_Red_Shallow",
      "filler": 31,
      "rotation": 11
    },
    {
      "x": -4,
      "y": 3,
      "z": 1,
      "name": "Cloth_Roof_Red_Vertical",
      "rotation": 11
    },
    {
      "x": -4,
      "y": 4,
      "z": 1,
      "name": "Cloth_Roof_Red_Shallow",
      "filler": 31,
      "rotation": 11
    },
    {
      "x": -3,
      "y": 4,
      "z": -1,
      "name": "Cloth_Roof_Red_Shallow",
      "rotation": 11
    },
    {
      "x": -3,
      "y": 1,
      "z": 0,
      "name": "Cloth_Roof_Red_Steep",
      "filler": 31744,
      "rotation": 9
    },
    {
      "x": -3,
      "y": 2,
      "z": 0,
      "name": "Cloth_Roof_Red_Steep",
      "rotation": 9
    },
    {
      "x": -3,
      "y": 3,
      "z": 0,
      "name": "Cloth_Roof_Red_Shallow",
      "filler": 31,
      "rotation": 11
    },
    {
      "x": -3,
      "y": 4,
      "z": 1,
      "name": "Cloth_Roof_Red_Shallow",
      "rotation": 11
    },
    {
      "x": -2,
      "y": 4,
      "z": -1,
      "name": "Cloth_Roof_Red",
      "rotation": 9
    },
    {
      "x": -2,
      "y": 3,
      "z": 0,
      "name": "Cloth_Roof_Red_Shallow",
      "rotation": 11
    },
    {
      "x": -2,
      "y": 4,
      "z": 1,
      "name": "Cloth_Roof_Red",
      "rotation": 9
    },
    {
      "x": -1,
      "y": 3,
      "z": -4,
      "name": "Cloth_Roof_Red_Vertical",
      "rotation": 10
    },
    {
      "x": -1,
      "y": 4,
      "z": -4,
      "name": "Cloth_Roof_Red_Shallow",
      "filler": 992,
      "rotation": 10
    },
    {
      "x": -1,
      "y": 4,
      "z": -3,
      "name": "Cloth_Roof_Red_Shallow",
      "rotation": 10
    },
    {
      "x": -1,
      "y": 4,
      "z": -2,
      "name": "Cloth_Roof_Red",
      "rotation": 8
    },
    {
      "x": -1,
      "y": 4,
      "z": -1,
      "name": "*Cloth_Roof_Red_State_Definitions_Inverted_Corner_Left",
      "rotation": 11
    },
    {
      "x": -1,
      "y": 3,
      "z": 0,
      "name": "Cloth_Roof_Orange",
      "rotation": 11
    },
    {
      "x": -1,
      "y": 4,
      "z": 0,
      "name": "Cloth_Roof_Red",
      "rotation": 11
    },
    {
      "x": -1,
      "y": 5,
      "z": 0,
      "name": "Cloth_Roof_Green",
      "rotation": 9
    },
    {
      "x": -1,
      "y": 4,
      "z": 1,
      "name": "*Cloth_Roof_Red_State_Definitions_Inverted_Corner_Left",
      "rotation": 8
    },
    {
      "x": -1,
      "y": 4,
      "z": 2,
      "name": "Cloth_Roof_Red",
      "rotation": 10
    },
    {
      "x": -1,
      "y": 4,
      "z": 3,
      "name": "Cloth_Roof_Red_Shallow",
      "rotation": 8
    },
    {
      "x": -1,
      "y": 3,
      "z": 4,
      "name": "Cloth_Roof_Red_Vertical",
      "rotation": 8
    },
    {
      "x": -1,
      "y": 4,
      "z": 4,
      "name": "Cloth_Roof_Red_Shallow",
      "filler": 32,
      "rotation": 8
    },
    {
      "x": 0,
      "y": 1,
      "z": -3,
      "name": "Cloth_Roof_Red_Steep",
      "filler": 31744,
      "rotation": 8
    },
    {
      "x": 0,
      "y": 2,
      "z": -3,
      "name": "Cloth_Roof_Red_Steep",
      "rotation": 8
    },
    {
      "x": 0,
      "y": 3,
      "z": -3,
      "name": "Cloth_Roof_Red_Shallow",
      "filler": 992,
      "rotation": 10
    },
    {
      "x": 0,
      "y": 3,
      "z": -2,
      "name": "Cloth_Roof_Red_Shallow",
      "rotation": 10
    },
    {
      "x": 0,
      "y": 3,
      "z": -1,
      "name": "Cloth_Roof_Orange",
      "rotation": 10
    },
    {
      "x": 0,
      "y": 4,
      "z": -1,
      "name": "Cloth_Roof_Red",
      "rotation": 10
    },
    {
      "x": 0,
      "y": 5,
      "z": -1,
      "name": "Cloth_Roof_Green",
      "rotation": 8
    },
    {
      "x": 0,
      "y": 2,
      "z": 0,
      "name": "Plant_Seaweed_Arid_Red",
      "filler": 31744,
      "rotation": 10
    },
    {
      "x": 0,
      "y": 3,
      "z": 0,
      "name": "Plant_Seaweed_Arid_Red",
      "rotation": 10
    },
    {
      "x": 0,
      "y": 4,
      "z": 0,
      "name": "Rock_Crystal_Red_Block",
      "rotation": 10
    },
    {
      "x": 0,
      "y": 5,
      "z": 0,
      "name": "Cloth_Block_Wool_Green",
      "rotation": 10
    },
    {
      "x": 0,
      "y": 3,
      "z": 1,
      "name": "Cloth_Roof_Orange",
      "rotation": 8
    },
    {
      "x": 0,
      "y": 4,
      "z": 1,
      "name": "Cloth_Roof_Red",
      "rotation": 8
    },
    {
      "x": 0,
      "y": 5,
      "z": 1,
      "name": "Cloth_Roof_Green",
      "rotation": 10
    },
    {
      "x": 0,
      "y": 3,
      "z": 2,
      "name": "Cloth_Roof_Red_Shallow",
      "rotation": 8
    },
    {
      "x": 0,
      "y": 1,
      "z": 3,
      "name": "Cloth_Roof_Red_Steep",
      "filler": 31744,
      "rotation": 10
    },
    {
      "x": 0,
      "y": 2,
      "z": 3,
      "name": "Cloth_Roof_Red_Steep",
      "rotation": 10
    },
    {
      "x": 0,
      "y": 3,
      "z": 3,
      "name": "Cloth_Roof_Red_Shallow",
      "filler": 32,
      "rotation": 8
    },
    {
      "x": 1,
      "y": 3,
      "z": -4,
      "name": "Cloth_Roof_Red_Vertical",
      "rotation": 10
    },
    {
      "x": 1,
      "y": 4,
      "z": -4,
      "name": "Cloth_Roof_Red_Shallow",
      "filler": 992,
      "rotation": 10
    },
    {
      "x": 1,
      "y": 4,
      "z": -3,
      "name": "Cloth_Roof_Red_Shallow",
      "rotation": 10
    },
    {
      "x": 1,
      "y": 4,
      "z": -2,
      "name": "Cloth_Roof_Red",
      "rotation": 8
    },
    {
      "x": 1,
      "y": 4,
      "z": -1,
      "name": "*Cloth_Roof_Red_State_Definitions_Inverted_Corner_Left",
      "rotation": 10
    },
    {
      "x": 1,
      "y": 3,
      "z": 0,
      "name": "Cloth_Roof_Orange",
      "rotation": 9
    },
    {
      "x": 1,
      "y": 4,
      "z": 0,
      "name": "Cloth_Roof_Red",
      "rotation": 9
    },
    {
      "x": 1,
      "y": 5,
      "z": 0,
      "name": "Cloth_Roof_Green",
      "rotation": 11
    },
    {
      "x": 1,
      "y": 4,
      "z": 1,
      "name": "*Cloth_Roof_Red_State_Definitions_Inverted_Corner_Left",
      "rotation": 9
    },
    {
      "x": 1,
      "y": 4,
      "z": 2,
      "name": "Cloth_Roof_Red",
      "rotation": 10
    },
    {
      "x": 1,
      "y": 4,
      "z": 3,
      "name": "Cloth_Roof_Red_Shallow",
      "rotation": 8
    },
    {
      "x": 1,
      "y": 3,
      "z": 4,
      "name": "Cloth_Roof_Red_Vertical",
      "rotation": 8
    },
    {
      "x": 1,
      "y": 4,
      "z": 4,
      "name": "Cloth_Roof_Red_Shallow",
      "filler": 32,
      "rotation": 8
    },
    {
      "x": 2,
      "y": 4,
      "z": -1,
      "name": "Cloth_Roof_Red",
      "rotation": 11
    },
    {
      "x": 2,
      "y": 3,
      "z": 0,
      "name": "Cloth_Roof_Red_Shallow",
      "rotation": 9
    },
    {
      "x": 2,
      "y": 4,
      "z": 1,
      "name": "Cloth_Roof_Red",
      "rotation": 11
    },
    {
      "x": 3,
      "y": 4,
      "z": -1,
      "name": "Cloth_Roof_Red_Shallow",
      "rotation": 9
    },
    {
      "x": 3,
      "y": 1,
      "z": 0,
      "name": "Cloth_Roof_Red_Steep",
      "filler": 31744,
      "rotation": 11
    },
    {
      "x": 3,
      "y": 2,
      "z": 0,
      "name": "Cloth_Roof_Red_Steep",
      "rotation": 11
    },
    {
      "x": 3,
      "y": 3,
      "z": 0,
      "name": "Cloth_Roof_Red_Shallow",
      "filler": 1,
      "rotation": 9
    },
    {
      "x": 3,
      "y": 4,
      "z": 1,
      "name": "Cloth_Roof_Red_Shallow",
      "rotation": 9
    },
    {
      "x": 4,
      "y": 3,
      "z": -1,
      "name": "Cloth_Roof_Red_Vertical",
      "rotation": 9
    },
    {
      "x": 4,
      "y": 4,
      "z": -1,
      "name": "Cloth_Roof_Red_Shallow",
      "filler": 1,
      "rotation": 9
    },
    {
      "x": 4,
      "y": 3,
      "z": 1,
      "name": "Cloth_Roof_Red_Vertical",
      "rotation": 9
    },
    {
      "x": 4,
      "y": 4,
      "z": 1,
      "name": "Cloth_Roof_Red_Shallow",
      "filler": 1,
      "rotation": 9
    }
  ]
}