{
  "version": 8,
  "blockIdVersion": 11,
  "anchorX": 0,
  "anchorY": 0,
  "anchorZ": 0,
  "blocks": [
    {
      "x": 0,
      "y": -35,
      "z": 1,
      "name": "Rock_Sandstone_Cobble"
    },
    {
      "x": 0,
      "y": -34,
      "z": 1,
      "name": "Rock_Sandstone"
    },
    {
      "x": 0,
      "y": -33,
      "z": 1,
      "name": "Rock_Sandstone_Brick"
    },
    {
      "x": 0,
      "y": -32,
      "z": 1,
      "name": "Rock_Sandstone_Brick"
    },
    {
      "x": 0,
      "y": -31,
      "z": 1,
      "name": "Rock_Sandstone_Brick"
    },
    {
      "x": 0,
      "y": -30,
      "z": 1,
      "name": "Rock_Sandstone_Brick"
    },
    {
      "x": 0,
      "y": -29,
      "z": 1,
      "name": "Rock_Sandstone_Brick"
    },
    {
      "x": 0,
      "y": -28,
      "z": 1,
      "name": "Rock_Sandstone_Brick"
    },
    {
      "x": 0,
      "y": -27,
      "z": 1,
      "name": "Rock_Sandstone"
    },
    {
      "x": 0,
      "y": -26,
      "z": 1,
      "name": "Rock_Sandstone_Brick"
    },
    {
      "x": 0,
      "y": -25,
      "z": 1,
      "name": "Rock_Sandstone_Cobble"
    },
    {
      "x": 0,
      "y": -24,
      "z": 1,
      "name": "Rock_Sandstone_Brick"
    },
    {
      "x": 0,
      "y": -23,
      "z": 1,
      "name": "Rock_Sandstone_Brick"
    },
    {
      "x": 0,
      "y": -22,
      "z": 1,
      "name": "Rock_Sandstone_Cobble"
    },
    {
      "x": 0,
      "y": -21,
      "z": 1,
      "name": "Rock_Sandstone_Brick"
    },
    {
      "x": 0,
      "y": -20,
      "z": 1,
      "name": "Rock_Sandstone_Cobble"
    },
    {
      "x": 0,
      "y": -19,
      "z": 1,
      "name": "Rock_Sandstone_Brick"
    },
    {
      "x": 0,
      "y": -18,
      "z": 1,
      "name": "Rock_Sandstone_Brick"
    },
    {
      "x": 0,
      "y": -17,
      "z": 1,
      "name": "Rock_Sandstone_Brick"
    },
    {
      "x": 0,
      "y": -16,
      "z": 1,
      "name": "Rock_Sandstone_Brick"
    },
    {
      "x": 0,
      "y": -15,
      "z": 1,
      "name": "Rock_Sandstone"
    },
    {
      "x": 0,
      "y": -14,
      "z": 1,
      "name": "Rock_Sandstone_Brick"
    },
    {
      "x": 0,
      "y": -13,
      "z": 1,
      "name": "Rock_Sandstone_Brick"
    },
    {
      "x": 0,
      "y": -12,
      "z": 1,
      "name": "Rock_Sandstone_Brick"
    },
    {
      "x": 0,
      "y": -11,
      "z": 1,
      "name": "Rock_Sandstone_Cobble"
    },
    {
      "x": 0,
      "y": -10,
      "z": 1,
      "name": "Rock_Sandstone_Cobble"
    },
    {
      "x": 0,
      "y": -9,
      "z": 1,
      "name": "Rock_Sandstone"
    },
    {
      "x": 0,
      "y": -8,
      "z": 1,
      "name": "Rock_Sandstone"
    },
    {
      "x": 0,
      "y": -7,
      "z": 1,
      "name": "Rock_Sandstone_Brick"
    },
    {
      "x": 0,
      "y": -6,
      "z": 1,
      "name": "Rock_Sandstone"
    },
    {
      "x": 0,
      "y": -5,
      "z": 1,
      "name": "Rock_Sandstone"
    },
    {
      "x": 0,
      "y": -4,
      "z": 1,
      "name": "Rock_Sandstone_Cobble"
    },
    {
      "x": 0,
      "y": -3,
      "z": 1,
      "name": "Rock_Sandstone_Brick"
    },
    {
      "x": 0,
      "y": -2,
      "z": 1,
      "name": "Rock_Sandstone_Brick"
    },
    {
      "x": 0,
      "y": -35,
      "z": 2,
      "name": "Rock_Sandstone"
    },
    {
      "x": 0,
      "y": -34,
      "z": 2,
      "name": "Rock_Sandstone_Brick"
    },
    {
      "x": 0,
      "y": -33,
      "z": 2,
      "name": "Rock_Sandstone"
    },
    {
      "x": 0,
      "y": -32,
      "z": 2,
      "name": "Rock_Sandstone_Cobble"
    },
    {
      "x": 0,
      "y": -31,
      "z": 2,
      "name": "Rock_Sandstone_Brick"
    },
    {
      "x": 0,
      "y": -30,
      "z": 2,
      "name": "Rock_Sandstone_Brick"
    },
    {
      "x": 0,
      "y": -29,
      "z": 2,
      "name": "Rock_Sandstone_Brick"
    },
    {
      "x": 0,
      "y": -28,
      "z": 2,
      "name": "Rock_Sandstone_Cobble"
    },
    {
      "x": 0,
      "y": -27,
      "z": 2,
      "name": "Rock_Sandstone_Brick"
    },
    {
      "x": 0,
      "y": -26,
      "z": 2,
      "name": "Rock_Sandstone_Brick"
    },
    {
      "x": 0,
      "y": -25,
      "z": 2,
      "name": "Rock_Sandstone_Brick"
    },
    {
      "x": 0,
      "y": -24,
      "z": 2,
      "name": "Rock_Sandstone_Brick"
    },
    {
      "x": 0,
      "y": -23,
      "z": 2,
      "name": "Rock_Sandstone_Brick"
    },
    {
      "x": 0,
      "y": -22,
      "z": 2,
      "name": "Rock_Sandstone"
    },
    {
      "x": 0,
      "y": -21,
      "z": 2,
      "name": "Rock_Sandstone_Brick"
    },
    {
      "x": 0,
      "y": -20,
      "z": 2,
      "name": "Rock_Sandstone_Brick"
    },
    {
      "x": 0,
      "y": -19,
      "z": 2,
      "name": "Rock_Sandstone_Brick"
    },
    {
      "x": 0,
      "y": -18,
      "z": 2,
      "name": "Rock_Sandstone_Brick"
    },
    {
      "x": 0,
      "y": -17,
      "z": 2,
      "name": "Rock_Sandstone_Brick"
    },
    {
      "x": 0,
      "y": -16,
      "z": 2,
      "name": "Rock_Sandstone_Brick"
    },
    {
      "x": 0,
      "y": -15,
      "z": 2,
      "name": "Rock_Sandstone_Brick"
    },
    {
      "x": 0,
      "y": -14,
      "z": 2,
      "name": "Rock_Sandstone"
    },
    {
      "x": 0,
      "y": -13,
      "z": 2,
      "name": "Rock_Sandstone_Brick"
    },
    {
      "x": 0,
      "y": -12,
      "z": 2,
      "name": "Rock_Sandstone"
    },
    {
      "x": 0,
      "y": -11,
      "z": 2,
      "name": "Rock_Sandstone_Brick"
    },
    {
      "x": 0,
      "y": -10,
      "z": 2,
      "name": "Rock_Sandstone"
    },
    {
      "x": 0,
      "y": -9,
      "z": 2,
      "name": "Rock_Sandstone_Brick"
    },
    {
      "x": 0,
      "y": -8,
      "z": 2,
      "name": "Rock_Sandstone_Brick"
    },
    {
      "x": 0,
      "y": -7,
      "z": 2,
      "name": "Rock_Sandstone_Brick"
    },
    {
      "x": 0,
      "y": -6,
      "z": 2,
      "name": "Rock_Sandstone_Brick"
    },
    {
      "x": 0,
      "y": -5,
      "z": 2,
      "name": "Rock_Sandstone"
    },
    {
      "x": 0,
      "y": -4,
      "z": 2,
      "name": "Rock_Sandstone_Brick"
    },
    {
      "x": 0,
      "y": -3,
      "z": 2,
      "name": "Rock_Sandstone_Brick"
    },
    {
      "x": 0,
      "y": -2,
      "z": 2,
      "name": "Rock_Sandstone_Brick"
    },
    {
      "x": 0,
      "y": -3,
      "z": 3,
      "name": "Rock_Sandstone_Brick_Stairs",
      "rotation": 32
    },
    {
      "x": 0,
      "y": -2,
      "z": 3,
      "name": "Rock_Sandstone_Brick"
    },
    {
      "x": 0,
      "y": -35,
      "z": 7,
      "name": "Rock_Sandstone"
    },
    {
      "x": 0,
      "y": -34,
      "z": 7,
      "name": "Rock_Sandstone_Brick"
    },
    {
      "x": 0,
      "y": -33,
      "z": 7,
      "name": "Rock_Sandstone_Brick"
    },
    {
      "x": 0,
      "y": -32,
      "z": 7,
      "name": "Rock_Sandstone_Brick"
    },
    {
      "x": 0,
      "y": -31,
      "z": 7,
      "name": "Rock_Sandstone"
    },
    {
      "x": 0,
      "y": -30,
      "z": 7,
      "name": "Rock_Sandstone_Brick"
    },
    {
      "x": 0,
      "y": -29,
      "z": 7,
      "name": "Rock_Sandstone_Brick"
    },
    {
      "x": 0,
      "y": -28,
      "z": 7,
      "name": "Rock_Sandstone_Cobble"
    },
    {
      "x": 0,
      "y": -27,
      "z": 7,
      "name": "Rock_Sandstone_Cobble"
    },
    {
      "x": 0,
      "y": -26,
      "z": 7,
      "name": "Rock_Sandstone_Brick"
    },
    {
      "x": 0,
      "y": -25,
      "z": 7,
      "name": "Rock_Sandstone_Brick"
    },
    {
      "x": 0,
      "y": -24,
      "z": 7,
      "name": "Rock_Sandstone"
    },
    {
      "x": 0,
      "y": -23,
      "z": 7,
      "name": "Rock_Sandstone_Brick"
    },
    {
      "x": 0,
      "y": -22,
      "z": 7,
      "name": "Rock_Sandstone"
    },
    {
      "x": 0,
      "y": -21,
      "z": 7,
      "name": "Rock_Sandstone"
    },
    {
      "x": 0,
      "y": -20,
      "z": 7,
      "name": "Rock_Sandstone_Brick"
    },
    {
      "x": 0,
      "y": -19,
      "z": 7,
      "name": "Rock_Sandstone_Brick"
    },
    {
      "x": 0,
      "y": -18,
      "z": 7,
      "name": "Rock_Sandstone_Brick"
    },
    {
      "x": 0,
      "y": -17,
      "z": 7,
      "name": "Rock_Sandstone_Brick"
    },
    {
      "x": 0,
      "y": -16,
      "z": 7,
      "name": "Rock_Sandstone"
    },
    {
      "x": 0,
      "y": -15,
      "z": 7,
      "name": "Rock_Sandstone"
    },
    {
      "x": 0,
      "y": -14,
      "z": 7,
      "name": "Rock_Sandstone_Brick"
    },
    {
      "x": 0,
      "y": -13,
      "z": 7,
      "name": "Rock_Sandstone_Brick"
    },
    {
      "x": 0,
      "y": -12,
      "z": 7,
      "name": "Rock_Sandstone"
    },
    {
      "x": 0,
      "y": -11,
      "z": 7,
      "name": "Rock_Sandstone_Brick"
    },
    {
      "x": 0,
      "y": -10,
      "z": 7,
      "name": "Rock_Sandstone"
    },
    {
      "x": 0,
      "y": -9,
      "z": 7,
      "name": "Rock_Sandstone_Brick"
    },
    {
      "x": 0,
      "y": -8,
      "z": 7,
      "name": "Rock_Sandstone"
    },
    {
      "x": 0,
      "y": -7,
      "z": 7,
      "name": "Rock_Sandstone_Brick"
    },
    {
      "x": 0,
      "y": -6,
      "z": 7,
      "name": "Rock_Sandstone_Brick"
    },
    {
      "x": 0,
      "y": -35,
      "z": 8,
      "name": "Rock_Sandstone_Brick"
    },
    {
      "x": 0,
      "y": -34,
      "z": 8,
      "name": "Rock_Sandstone"
    },
    {
      "x": 0,
      "y": -33,
      "z": 8,
      "name": "Rock_Sandstone_Brick"
    },
    {
      "x": 0,
      "y": -32,
      "z": 8,
      "name": "Rock_Sandstone"
    },
    {
      "x": 0,
      "y": -31,
      "z": 8,
      "name": "Rock_Sandstone"
    },
    {
      "x": 0,
      "y": -30,
      "z": 8,
      "name": "Rock_Sandstone_Brick"
    },
    {
      "x": 0,
      "y": -29,
      "z": 8,
      "name": "Rock_Sandstone_Brick"
    },
    {
      "x": 0,
      "y": -28,
      "z": 8,
      "name": "Rock_Sandstone_Brick"
    },
    {
      "x": 0,
      "y": -27,
      "z": 8,
      "name": "Rock_Sandstone_Brick"
    },
    {
      "x": 0,
      "y": -26,
      "z": 8,
      "name": "Rock_Sandstone_Brick"
    },
    {
      "x": 0,
      "y": -25,
      "z": 8,
      "name": "Rock_Sandstone"
    },
    {
      "x": 0,
      "y": -24,
      "z": 8,
      "name": "Rock_Sandstone_Brick"
    },
    {
      "x": 0,
      "y": -23,
      "z": 8,
      "name": "Rock_Sandstone_Brick"
    },
    {
      "x": 0,
      "y": -22,
      "z": 8,
      "name": "Rock_Sandstone"
    },
    {
      "x": 0,
      "y": -21,
      "z": 8,
      "name": "Rock_Sandstone"
    },
    {
      "x": 0,
      "y": -20,
      "z": 8,
      "name": "Rock_Sandstone_Brick"
    },
    {
      "x": 0,
      "y": -19,
      "z": 8,
      "name": "Rock_Sandstone"
    },
    {
      "x": 0,
      "y": -18,
      "z": 8,
      "name": "Rock_Sandstone"
    },
    {
      "x": 0,
      "y": -17,
      "z": 8,
      "name": "Rock_Sandstone_Brick"
    },
    {
      "x": 0,
      "y": -16,
      "z": 8,
      "name": "Rock_Sandstone"
    },
    {
      "x": 0,
      "y": -15,
      "z": 8,
      "name": "Rock_Sandstone"
    },
    {
      "x": 0,
      "y": -14,
      "z": 8,
      "name": "Rock_Sandstone_Brick"
    },
    {
      "x": 0,
      "y": -13,
      "z": 8,
      "name": "Rock_Sandstone_Cobble"
    },
    {
      "x": 0,
      "y": -12,
      "z": 8,
      "name": "Rock_Sandstone_Brick"
    },
    {
      "x": 0,
      "y": -11,
      "z": 8,
      "name": "Rock_Sandstone_Brick"
    },
    {
      "x": 0,
      "y": -10,
      "z": 8,
      "name": "Rock_Sandstone_Brick"
    },
    {
      "x": 0,
      "y": -9,
      "z": 8,
      "name": "Rock_Sandstone_Brick"
    },
    {
      "x": 0,
      "y": -8,
      "z": 8,
      "name": "Rock_Sandstone_Brick"
    },
    {
      "x": 0,
      "y": -7,
      "z": 8,
      "name": "Rock_Sandstone_Brick"
    },
    {
      "x": 0,
      "y": -6,
      "z": 8,
      "name": "Rock_Sandstone_Brick"
    },
    {
      "x": 1,
      "y": -35,
      "z": 0,
      "name": "Rock_Sandstone_Brick"
    },
    {
      "x": 1,
      "y": -34,
      "z": 0,
      "name": "Rock_Sandstone_Brick"
    },
    {
      "x": 1,
      "y": -33,
      "z": 0,
      "name": "Rock_Sandstone_Brick"
    },
    {
      "x": 1,
      "y": -32,
      "z": 0,
      "name": "Rock_Sandstone_Brick"
    },
    {
      "x": 1,
      "y": -31,
      "z": 0,
      "name": "Rock_Sandstone_Brick"
    },
    {
      "x": 1,
      "y": -30,
      "z": 0,
      "name": "Rock_Sandstone_Brick"
    },
    {
      "x": 1,
      "y": -29,
      "z": 0,
      "name": "Rock_Sandstone_Cobble"
    },
    {
      "x": 1,
      "y": -28,
      "z": 0,
      "name": "Rock_Sandstone_Brick"
    },
    {
      "x": 1,
      "y": -27,
      "z": 0,
      "name": "Rock_Sandstone_Brick"
    },
    {
      "x": 1,
      "y": -26,
      "z": 0,
      "name": "Rock_Sandstone_Brick"
    },
    {
      "x": 1,
      "y": -25,
      "z": 0,
      "name": "Rock_Sandstone_Cobble"
    },
    {
      "x": 1,
      "y": -24,
      "z": 0,
      "name": "Rock_Sandstone_Cobble"
    },
    {
      "x": 1,
      "y": -23,
      "z": 0,
      "name": "Rock_Sandstone_Brick"
    },
    {
      "x": 1,
      "y": -22,
      "z": 0,
      "name": "Rock_Sandstone"
    },
    {
      "x": 1,
      "y": -21,
      "z": 0,
      "name": "Rock_Sandstone_Cobble"
    },
    {
      "x": 1,
      "y": -20,
      "z": 0,
      "name": "Rock_Sandstone"
    },
    {
      "x": 1,
      "y": -19,
      "z": 0,
      "name": "Rock_Sandstone_Brick"
    },
    {
      "x": 1,
      "y": -18,
      "z": 0,
      "name": "Rock_Sandstone_Brick"
    },
    {
      "x": 1,
      "y": -17,
      "z": 0,
      "name": "Rock_Sandstone"
    },
    {
      "x": 1,
      "y": -16,
      "z": 0,
      "name": "Rock_Sandstone_Brick"
    },
    {
      "x": 1,
      "y": -15,
      "z": 0,
      "name": "Rock_Sandstone_Cobble"
    },
    {
      "x": 1,
      "y": -14,
      "z": 0,
      "name": "Rock_Sandstone"
    },
    {
      "x": 1,
      "y": -13,
      "z": 0,
      "name": "Rock_Sandstone_Brick"
    },
    {
      "x": 1,
      "y": -12,
      "z": 0,
      "name": "Rock_Sandstone_Brick"
    },
    {
      "x": 1,
      "y": -11,
      "z": 0,
      "name": "Rock_Sandstone_Brick"
    },
    {
      "x": 1,
      "y": -10,
      "z": 0,
      "name": "Rock_Sandstone_Brick"
    },
    {
      "x": 1,
      "y": -9,
      "z": 0,
      "name": "Rock_Sandstone"
    },
    {
      "x": 1,
      "y": -8,
      "z": 0,
      "name": "Rock_Sandstone_Brick"
    },
    {
      "x": 1,
      "y": -7,
      "z": 0,
      "name": "Rock_Sandstone_Cobble"
    },
    {
      "x": 1,
      "y": -6,
      "z": 0,
      "name": "Rock_Sandstone_Brick"
    },
    {
      "x": 1,
      "y": -5,
      "z": 0,
      "name": "Rock_Sandstone_Brick"
    },
    {
      "x": 1,
      "y": -4,
      "z": 0,
      "name": "Rock_Sandstone_Brick"
    },
    {
      "x": 1,
      "y": -3,
      "z": 0,
      "name": "Rock_Sandstone_Brick"
    },
    {
      "x": 1,
      "y": -2,
      "z": 0,
      "name": "Rock_Sandstone_Brick"
    },
    {
      "x": 1,
      "y": -1,
      "z": 0,
      "name": "Rock_Sandstone_Brick"
    },
    {
      "x": 1,
      "y": -35,
      "z": 1,
      "name": "Rock_Sandstone_Brick"
    },
    {
      "x": 1,
      "y": -34,
      "z": 1,
      "name": "Rock_Sandstone_Brick"
    },
    {
      "x": 1,
      "y": -33,
      "z": 1,
      "name": "Rock_Sandstone"
    },
    {
      "x": 1,
      "y": -32,
      "z": 1,
      "name": "Rock_Sandstone_Brick"
    },
    {
      "x": 1,
      "y": -31,
      "z": 1,
      "name": "Rock_Sandstone_Brick"
    },
    {
      "x": 1,
      "y": -30,
      "z": 1,
      "name": "Rock_Sandstone_Brick"
    },
    {
      "x": 1,
      "y": -29,
      "z": 1,
      "name": "Rock_Sandstone_Brick"
    },
    {
      "x": 1,
      "y": -28,
      "z": 1,
      "name": "Rock_Sandstone_Brick"
    },
    {
      "x": 1,
      "y": -27,
      "z": 1,
      "name": "Rock_Sandstone_Brick"
    },
    {
      "x": 1,
      "y": -26,
      "z": 1,
      "name": "Rock_Sandstone_Brick"
    },
    {
      "x": 1,
      "y": -25,
      "z": 1,
      "name": "Rock_Sandstone"
    },
    {
      "x": 1,
      "y": -24,
      "z": 1,
      "name": "Rock_Sandstone_Brick"
    },
    {
      "x": 1,
      "y": -23,
      "z": 1,
      "name": "Rock_Sandstone_Brick"
    },
    {
      "x": 1,
      "y": -22,
      "z": 1,
      "name": "Rock_Sandstone_Brick"
    },
    {
      "x": 1,
      "y": -21,
      "z": 1,
      "name": "Rock_Sandstone_Brick"
    },
    {
      "x": 1,
      "y": -20,
      "z": 1,
      "name": "Rock_Sandstone_Brick"
    },
    {
      "x": 1,
      "y": -19,
      "z": 1,
      "name": "Rock_Sandstone_Brick"
    },
    {
      "x": 1,
      "y": -18,
      "z": 1,
      "name": "Rock_Sandstone_Brick"
    },
    {
      "x": 1,
      "y": -17,
      "z": 1,
      "name": "Rock_Sandstone_Brick"
    },
    {
      "x": 1,
      "y": -16,
      "z": 1,
      "name": "Rock_Sandstone_Brick"
    },
    {
      "x": 1,
      "y": -15,
      "z": 1,
      "name": "Rock_Sandstone_Brick"
    },
    {
      "x": 1,
      "y": -14,
      "z": 1,
      "name": "Rock_Sandstone_Cobble"
    },
    {
      "x": 1,
      "y": -13,
      "z": 1,
      "name": "Rock_Sandstone"
    },
    {
      "x": 1,
      "y": -12,
      "z": 1,
      "name": "Rock_Sandstone_Cobble"
    },
    {
      "x": 1,
      "y": -11,
      "z": 1,
      "name": "Rock_Sandstone_Brick"
    },
    {
      "x": 1,
      "y": -10,
      "z": 1,
      "name": "Rock_Sandstone_Brick"
    },
    {
      "x": 1,
      "y": -9,
      "z": 1,
      "name": "Rock_Sandstone_Brick"
    },
    {
      "x": 1,
      "y": -8,
      "z": 1,
      "name": "Rock_Sandstone_Brick"
    },
    {
      "x": 1,
      "y": -7,
      "z": 1,
      "name": "Rock_Sandstone_Brick"
    },
    {
      "x": 1,
      "y": -6,
      "z": 1,
      "name": "Rock_Sandstone_Cobble"
    },
    {
      "x": 1,
      "y": -5,
      "z": 1,
      "name": "Rock_Sandstone_Brick"
    },
    {
      "x": 1,
      "y": -4,
      "z": 1,
      "name": "Rock_Sandstone_Brick"
    },
    {
      "x": 1,
      "y": -3,
      "z": 1,
      "name": "Rock_Sandstone_Brick"
    },
    {
      "x": 1,
      "y": -2,
      "z": 1,
      "name": "Rock_Sandstone_Brick"
    },
    {
      "x": 1,
      "y": -35,
      "z": 2,
      "name": "Rock_Sandstone"
    },
    {
      "x": 1,
      "y": -34,
      "z": 2,
      "name": "Rock_Sandstone"
    },
    {
      "x": 1,
      "y": -33,
      "z": 2,
      "name": "Rock_Sandstone_Brick"
    },
    {
      "x": 1,
      "y": -32,
      "z": 2,
      "name": "Rock_Sandstone"
    },
    {
      "x": 1,
      "y": -31,
      "z": 2,
      "name": "Rock_Sandstone_Brick"
    },
    {
      "x": 1,
      "y": -30,
      "z": 2,
      "name": "Rock_Sandstone_Cobble"
    },
    {
      "x": 1,
      "y": -29,
      "z": 2,
      "name": "Rock_Sandstone_Brick"
    },
    {
      "x": 1,
      "y": -28,
      "z": 2,
      "name": "Rock_Sandstone_Cobble"
    },
    {
      "x": 1,
      "y": -27,
      "z": 2,
      "name": "Rock_Sandstone"
    },
    {
      "x": 1,
      "y": -26,
      "z": 2,
      "name": "Rock_Sandstone_Brick"
    },
    {
      "x": 1,
      "y": -25,
      "z": 2,
      "name": "Rock_Sandstone_Brick"
    },
    {
      "x": 1,
      "y": -24,
      "z": 2,
      "name": "Rock_Sandstone_Brick"
    },
    {
      "x": 1,
      "y": -23,
      "z": 2,
      "name": "Rock_Sandstone_Brick"
    },
    {
      "x": 1,
      "y": -22,
      "z": 2,
      "name": "Rock_Sandstone_Cobble"
    },
    {
      "x": 1,
      "y": -21,
      "z": 2,
      "name": "Rock_Sandstone_Brick"
    },
    {
      "x": 1,
      "y": -20,
      "z": 2,
      "name": "Rock_Sandstone_Brick"
    },
    {
      "x": 1,
      "y": -19,
      "z": 2,
      "name": "Rock_Sandstone_Brick"
    },
    {
      "x": 1,
      "y": -18,
      "z": 2,
      "name": "Rock_Sandstone_Brick"
    },
    {
      "x": 1,
      "y": -17,
      "z": 2,
      "name": "Rock_Sandstone_Brick"
    },
    {
      "x": 1,
      "y": -16,
      "z": 2,
      "name": "Rock_Sandstone_Brick"
    },
    {
      "x": 1,
      "y": -15,
      "z": 2,
      "name": "Rock_Sandstone_Brick"
    },
    {
      "x": 1,
      "y": -14,
      "z": 2,
      "name": "Rock_Sandstone"
    },
    {
      "x": 1,
      "y": -13,
      "z": 2,
      "name": "Rock_Sandstone_Brick"
    },
    {
      "x": 1,
      "y": -12,
      "z": 2,
      "name": "Rock_Sandstone_Brick"
    },
    {
      "x": 1,
      "y": -11,
      "z": 2,
      "name": "Rock_Sandstone_Brick"
    },
    {
      "x": 1,
      "y": -10,
      "z": 2,
      "name": "Rock_Sandstone_Brick"
    },
    {
      "x": 1,
      "y": -9,
      "z": 2,
      "name": "Rock_Sandstone_Brick"
    },
    {
      "x": 1,
      "y": -8,
      "z": 2,
      "name": "Rock_Sandstone_Brick"
    },
    {
      "x": 1,
      "y": -7,
      "z": 2,
      "name": "Rock_Sandstone_Brick"
    },
    {
      "x": 1,
      "y": -6,
      "z": 2,
      "name": "Rock_Sandstone_Brick"
    },
    {
      "x": 1,
      "y": -5,
      "z": 2,
      "name": "Rock_Sandstone_Brick"
    },
    {
      "x": 1,
      "y": -4,
      "z": 2,
      "name": "Rock_Sandstone"
    },
    {
      "x": 1,
      "y": -3,
      "z": 2,
      "name": "Rock_Sandstone"
    },
    {
      "x": 1,
      "y": -2,
      "z": 2,
      "name": "Rock_Sandstone_Brick"
    },
    {
      "x": 1,
      "y": -35,
      "z": 7,
      "name": "Rock_Sandstone_Brick"
    },
    {
      "x": 1,
      "y": -34,
      "z": 7,
      "name": "Rock_Sandstone_Brick"
    },
    {
      "x": 1,
      "y": -33,
      "z": 7,
      "name": "Rock_Sandstone_Brick"
    },
    {
      "x": 1,
      "y": -32,
      "z": 7,
      "name": "Rock_Sandstone_Brick"
    },
    {
      "x": 1,
      "y": -31,
      "z": 7,
      "name": "Rock_Sandstone_Brick"
    },
    {
      "x": 1,
      "y": -30,
      "z": 7,
      "name": "Rock_Sandstone_Brick"
    },
    {
      "x": 1,
      "y": -29,
      "z": 7,
      "name": "Rock_Sandstone_Brick"
    },
    {
      "x": 1,
      "y": -28,
      "z": 7,
      "name": "Rock_Sandstone_Brick"
    },
    {
      "x": 1,
      "y": -27,
      "z": 7,
      "name": "Rock_Sandstone_Brick"
    },
    {
      "x": 1,
      "y": -26,
      "z": 7,
      "name": "Rock_Sandstone_Cobble"
    },
    {
      "x": 1,
      "y": -25,
      "z": 7,
      "name": "Rock_Sandstone_Brick"
    },
    {
      "x": 1,
      "y": -24,
      "z": 7,
      "name": "Rock_Sandstone_Brick"
    },
    {
      "x": 1,
      "y": -23,
      "z": 7,
      "name": "Rock_Sandstone_Brick"
    },
    {
      "x": 1,
      "y": -22,
      "z": 7,
      "name": "Rock_Sandstone"
    },
    {
      "x": 1,
      "y": -21,
      "z": 7,
      "name": "Rock_Sandstone_Brick"
    },
    {
      "x": 1,
      "y": -20,
      "z": 7,
      "name": "Rock_Sandstone_Brick"
    },
    {
      "x": 1,
      "y": -19,
      "z": 7,
      "name": "Rock_Sandstone_Brick"
    },
    {
      "x": 1,
      "y": -18,
      "z": 7,
      "name": "Rock_Sandstone_Brick"
    },
    {
      "x": 1,
      "y": -17,
      "z": 7,
      "name": "Rock_Sandstone"
    },
    {
      "x": 1,
      "y": -16,
      "z": 7,
      "name": "Rock_Sandstone_Brick"
    },
    {
      "x": 1,
      "y": -15,
      "z": 7,
      "name": "Rock_Sandstone_Brick"
    },
    {
      "x": 1,
      "y": -14,
      "z": 7,
      "name": "Rock_Sandstone_Cobble"
    },
    {
      "x": 1,
      "y": -13,
      "z": 7,
      "name": "Rock_Sandstone"
    },
    {
      "x": 1,
      "y": -12,
      "z": 7,
      "name": "Rock_Sandstone"
    },
    {
      "x": 1,
      "y": -11,
      "z": 7,
      "name": "Rock_Sandstone_Cobble"
    },
    {
      "x": 1,
      "y": -10,
      "z": 7,
      "name": "Rock_Sandstone_Brick"
    },
    {
      "x": 1,
      "y": -9,
      "z": 7,
      "name": "Rock_Sandstone_Brick"
    },
    {
      "x": 1,
      "y": -8,
      "z": 7,
      "name": "Rock_Sandstone_Brick"
    },
    {
      "x": 1,
      "y": -7,
      "z": 7,
      "name": "Rock_Sandstone_Brick"
    },
    {
      "x": 1,
      "y": -35,
      "z": 8,
      "name": "Rock_Sandstone_Brick"
    },
    {
      "x": 1,
      "y": -34,
      "z": 8,
      "name": "Rock_Sandstone_Cobble"
    },
    {
      "x": 1,
      "y": -33,
      "z": 8,
      "name": "Rock_Sandstone_Brick"
    },
    {
      "x": 1,
      "y": -32,
      "z": 8,
      "name": "Rock_Sandstone_Brick"
    },
    {
      "x": 1,
      "y": -31,
      "z": 8,
      "name": "Rock_Sandstone"
    },
    {
      "x": 1,
      "y": -30,
      "z": 8,
      "name": "Rock_Sandstone_Brick"
    },
    {
      "x": 1,
      "y": -29,
      "z": 8,
      "name": "Rock_Sandstone_Brick"
    },
    {
      "x": 1,
      "y": -28,
      "z": 8,
      "name": "Rock_Sandstone_Brick"
    },
    {
      "x": 1,
      "y": -27,
      "z": 8,
      "name": "Rock_Sandstone_Brick"
    },
    {
      "x": 1,
      "y": -26,
      "z": 8,
      "name": "Rock_Sandstone_Brick"
    },
    {
      "x": 1,
      "y": -25,
      "z": 8,
      "name": "Rock_Sandstone_Brick"
    },
    {
      "x": 1,
      "y": -24,
      "z": 8,
      "name": "Rock_Sandstone_Brick"
    },
    {
      "x": 1,
      "y": -23,
      "z": 8,
      "name": "Rock_Sandstone_Cobble"
    },
    {
      "x": 1,
      "y": -22,
      "z": 8,
      "name": "Rock_Sandstone"
    },
    {
      "x": 1,
      "y": -21,
      "z": 8,
      "name": "Rock_Sandstone"
    },
    {
      "x": 1,
      "y": -20,
      "z": 8,
      "name": "Rock_Sandstone_Brick"
    },
    {
      "x": 1,
      "y": -19,
      "z": 8,
      "name": "Rock_Sandstone_Brick"
    },
    {
      "x": 1,
      "y": -18,
      "z": 8,
      "name": "Rock_Sandstone_Brick"
    },
    {
      "x": 1,
      "y": -17,
      "z": 8,
      "name": "Rock_Sandstone_Brick"
    },
    {
      "x": 1,
      "y": -16,
      "z": 8,
      "name": "Rock_Sandstone"
    },
    {
      "x": 1,
      "y": -15,
      "z": 8,
      "name": "Rock_Sandstone"
    },
    {
      "x": 1,
      "y": -14,
      "z": 8,
      "name": "Rock_Sandstone_Brick"
    },
    {
      "x": 1,
      "y": -13,
      "z": 8,
      "name": "Rock_Sandstone_Brick"
    },
    {
      "x": 1,
      "y": -12,
      "z": 8,
      "name": "Rock_Sandstone_Cobble"
    },
    {
      "x": 1,
      "y": -11,
      "z": 8,
      "name": "Rock_Sandstone"
    },
    {
      "x": 1,
      "y": -10,
      "z": 8,
      "name": "Rock_Sandstone_Cobble"
    },
    {
      "x": 1,
      "y": -9,
      "z": 8,
      "name": "Rock_Sandstone_Cobble"
    },
    {
      "x": 1,
      "y": -8,
      "z": 8,
      "name": "Rock_Sandstone_Brick"
    },
    {
      "x": 1,
      "y": -7,
      "z": 8,
      "name": "Rock_Sandstone_Cobble"
    },
    {
      "x": 1,
      "y": -35,
      "z": 9,
      "name": "Rock_Sandstone_Brick"
    },
    {
      "x": 1,
      "y": -34,
      "z": 9,
      "name": "Rock_Sandstone_Brick"
    },
    {
      "x": 1,
      "y": -33,
      "z": 9,
      "name": "Rock_Sandstone_Brick"
    },
    {
      "x": 1,
      "y": -32,
      "z": 9,
      "name": "Rock_Sandstone_Brick"
    },
    {
      "x": 1,
      "y": -31,
      "z": 9,
      "name": "Rock_Sandstone"
    },
    {
      "x": 1,
      "y": -30,
      "z": 9,
      "name": "Rock_Sandstone_Cobble"
    },
    {
      "x": 1,
      "y": -29,
      "z": 9,
      "name": "Rock_Sandstone_Brick"
    },
    {
      "x": 1,
      "y": -28,
      "z": 9,
      "name": "Rock_Sandstone_Brick"
    },
    {
      "x": 1,
      "y": -27,
      "z": 9,
      "name": "Rock_Sandstone"
    },
    {
      "x": 1,
      "y": -26,
      "z": 9,
      "name": "Rock_Sandstone_Brick"
    },
    {
      "x": 1,
      "y": -25,
      "z": 9,
      "name": "Rock_Sandstone_Brick"
    },
    {
      "x": 1,
      "y": -24,
      "z": 9,
      "name": "Rock_Sandstone"
    },
    {
      "x": 1,
      "y": -23,
      "z": 9,
      "name": "Rock_Sandstone_Brick"
    },
    {
      "x": 1,
      "y": -22,
      "z": 9,
      "name": "Rock_Sandstone_Brick"
    },
    {
      "x": 1,
      "y": -21,
      "z": 9,
      "name": "Rock_Sandstone"
    },
    {
      "x": 1,
      "y": -20,
      "z": 9,
      "name": "Rock_Sandstone_Cobble"
    },
    {
      "x": 1,
      "y": -19,
      "z": 9,
      "name": "Rock_Sandstone_Brick"
    },
    {
      "x": 1,
      "y": -18,
      "z": 9,
      "name": "Rock_Sandstone_Brick"
    },
    {
      "x": 1,
      "y": -17,
      "z": 9,
      "name": "Rock_Sandstone_Cobble"
    },
    {
      "x": 1,
      "y": -16,
      "z": 9,
      "name": "Rock_Sandstone_Brick"
    },
    {
      "x": 1,
      "y": -15,
      "z": 9,
      "name": "Rock_Sandstone_Brick"
    },
    {
      "x": 1,
      "y": -14,
      "z": 9,
      "name": "Rock_Sandstone_Cobble"
    },
    {
      "x": 1,
      "y": -13,
      "z": 9,
      "name": "Rock_Sandstone_Brick"
    },
    {
      "x": 1,
      "y": -12,
      "z": 9,
      "name": "Rock_Sandstone_Brick"
    },
    {
      "x": 1,
      "y": -11,
      "z": 9,
      "name": "Rock_Sandstone_Brick"
    },
    {
      "x": 1,
      "y": -10,
      "z": 9,
      "name": "Rock_Sandstone_Cobble"
    },
    {
      "x": 1,
      "y": -9,
      "z": 9,
      "name": "Rock_Sandstone"
    },
    {
      "x": 1,
      "y": -8,
      "z": 9,
      "name": "Rock_Sandstone_Cobble"
    },
    {
      "x": 1,
      "y": -7,
      "z": 9,
      "name": "Rock_Sandstone"
    },
    {
      "x": 2,
      "y": -35,
      "z": 0,
      "name": "Rock_Sandstone"
    },
    {
      "x": 2,
      "y": -34,
      "z": 0,
      "name": "Rock_Sandstone_Cobble"
    },
    {
      "x": 2,
      "y": -33,
      "z": 0,
      "name": "Rock_Sandstone_Brick"
    },
    {
      "x": 2,
      "y": -32,
      "z": 0,
      "name": "Rock_Sandstone_Brick"
    },
    {
      "x": 2,
      "y": -31,
      "z": 0,
      "name": "Rock_Sandstone_Cobble"
    },
    {
      "x": 2,
      "y": -30,
      "z": 0,
      "name": "Rock_Sandstone_Brick"
    },
    {
      "x": 2,
      "y": -29,
      "z": 0,
      "name": "Rock_Sandstone"
    },
    {
      "x": 2,
      "y": -28,
      "z": 0,
      "name": "Rock_Sandstone_Brick"
    },
    {
      "x": 2,
      "y": -27,
      "z": 0,
      "name": "Rock_Sandstone_Brick"
    },
    {
      "x": 2,
      "y": -26,
      "z": 0,
      "name": "Rock_Sandstone_Brick"
    },
    {
      "x": 2,
      "y": -25,
      "z": 0,
      "name": "Rock_Sandstone_Cobble"
    },
    {
      "x": 2,
      "y": -24,
      "z": 0,
      "name": "Rock_Sandstone_Brick"
    },
    {
      "x": 2,
      "y": -23,
      "z": 0,
      "name": "Rock_Sandstone"
    },
    {
      "x": 2,
      "y": -22,
      "z": 0,
      "name": "Rock_Sandstone_Brick"
    },
    {
      "x": 2,
      "y": -21,
      "z": 0,
      "name": "Rock_Sandstone_Brick"
    },
    {
      "x": 2,
      "y": -20,
      "z": 0,
      "name": "Rock_Sandstone_Brick"
    },
    {
      "x": 2,
      "y": -19,
      "z": 0,
      "name": "Rock_Sandstone"
    },
    {
      "x": 2,
      "y": -18,
      "z": 0,
      "name": "Rock_Sandstone_Brick"
    },
    {
      "x": 2,
      "y": -17,
      "z": 0,
      "name": "Rock_Sandstone_Brick"
    },
    {
      "x": 2,
      "y": -16,
      "z": 0,
      "name": "Rock_Sandstone_Brick"
    },
    {
      "x": 2,
      "y": -15,
      "z": 0,
      "name": "Rock_Sandstone_Brick"
    },
    {
      "x": 2,
      "y": -14,
      "z": 0,
      "name": "Rock_Sandstone"
    },
    {
      "x": 2,
      "y": -13,
      "z": 0,
      "name": "Rock_Sandstone_Brick"
    },
    {
      "x": 2,
      "y": -12,
      "z": 0,
      "name": "Rock_Sandstone_Brick"
    },
    {
      "x": 2,
      "y": -11,
      "z": 0,
      "name": "Rock_Sandstone_Brick"
    },
    {
      "x": 2,
      "y": -10,
      "z": 0,
      "name": "Rock_Sandstone_Brick"
    },
    {
      "x": 2,
      "y": -9,
      "z": 0,
      "name": "Rock_Sandstone_Brick"
    },
    {
      "x": 2,
      "y": -8,
      "z": 0,
      "name": "Rock_Sandstone_Brick"
    },
    {
      "x": 2,
      "y": -7,
      "z": 0,
      "name": "Rock_Sandstone_Brick"
    },
    {
      "x": 2,
      "y": -6,
      "z": 0,
      "name": "Rock_Sandstone_Cobble"
    },
    {
      "x": 2,
      "y": -5,
      "z": 0,
      "name": "Rock_Sandstone"
    },
    {
      "x": 2,
      "y": -4,
      "z": 0,
      "name": "Rock_Sandstone_Brick"
    },
    {
      "x": 2,
      "y": -3,
      "z": 0,
      "name": "Rock_Sandstone_Brick"
    },
    {
      "x": 2,
      "y": -2,
      "z": 0,
      "name": "Rock_Sandstone_Brick"
    },
    {
      "x": 2,
      "y": -1,
      "z": 0,
      "name": "Rock_Sandstone_Brick"
    },
    {
      "x": 2,
      "y": -35,
      "z": 1,
      "name": "Rock_Sandstone_Cobble"
    },
    {
      "x": 2,
      "y": -34,
      "z": 1,
      "name": "Rock_Sandstone_Brick"
    },
    {
      "x": 2,
      "y": -33,
      "z": 1,
      "name": "Rock_Sandstone_Brick"
    },
    {
      "x": 2,
      "y": -32,
      "z": 1,
      "name": "Rock_Sandstone"
    },
    {
      "x": 2,
      "y": -31,
      "z": 1,
      "name": "Rock_Sandstone_Brick"
    },
    {
      "x": 2,
      "y": -30,
      "z": 1,
      "name": "Rock_Sandstone_Brick"
    },
    {
      "x": 2,
      "y": -29,
      "z": 1,
      "name": "Rock_Sandstone_Brick"
    },
    {
      "x": 2,
      "y": -28,
      "z": 1,
      "name": "Rock_Sandstone_Cobble"
    },
    {
      "x": 2,
      "y": -27,
      "z": 1,
      "name": "Rock_Sandstone_Brick"
    },
    {
      "x": 2,
      "y": -26,
      "z": 1,
      "name": "Rock_Sandstone_Brick"
    },
    {
      "x": 2,
      "y": -25,
      "z": 1,
      "name": "Rock_Sandstone_Cobble"
    },
    {
      "x": 2,
      "y": -24,
      "z": 1,
      "name": "Rock_Sandstone_Brick"
    },
    {
      "x": 2,
      "y": -23,
      "z": 1,
      "name": "Rock_Sandstone"
    },
    {
      "x": 2,
      "y": -22,
      "z": 1,
      "name": "Rock_Sandstone_Brick"
    },
    {
      "x": 2,
      "y": -21,
      "z": 1,
      "name": "Rock_Sandstone_Brick"
    },
    {
      "x": 2,
      "y": -20,
      "z": 1,
      "name": "Rock_Sandstone_Brick"
    },
    {
      "x": 2,
      "y": -19,
      "z": 1,
      "name": "Rock_Sandstone_Brick"
    },
    {
      "x": 2,
      "y": -18,
      "z": 1,
      "name": "Rock_Sandstone_Brick"
    },
    {
      "x": 2,
      "y": -17,
      "z": 1,
      "name": "Rock_Sandstone_Brick"
    },
    {
      "x": 2,
      "y": -16,
      "z": 1,
      "name": "Rock_Sandstone_Brick"
    },
    {
      "x": 2,
      "y": -15,
      "z": 1,
      "name": "Rock_Sandstone_Brick"
    },
    {
      "x": 2,
      "y": -14,
      "z": 1,
      "name": "Rock_Sandstone_Cobble"
    },
    {
      "x": 2,
      "y": -13,
      "z": 1,
      "name": "Rock_Sandstone_Brick"
    },
    {
      "x": 2,
      "y": -12,
      "z": 1,
      "name": "Rock_Sandstone_Brick"
    },
    {
      "x": 2,
      "y": -11,
      "z": 1,
      "name": "Rock_Sandstone_Brick"
    },
    {
      "x": 2,
      "y": -10,
      "z": 1,
      "name": "Rock_Sandstone"
    },
    {
      "x": 2,
      "y": -9,
      "z": 1,
      "name": "Rock_Sandstone_Brick"
    },
    {
      "x": 2,
      "y": -8,
      "z": 1,
      "name": "Rock_Sandstone"
    },
    {
      "x": 2,
      "y": -7,
      "z": 1,
      "name": "Rock_Sandstone"
    },
    {
      "x": 2,
      "y": -6,
      "z": 1,
      "name": "Rock_Sandstone_Brick"
    },
    {
      "x": 2,
      "y": -5,
      "z": 1,
      "name": "Rock_Sandstone"
    },
    {
      "x": 2,
      "y": -4,
      "z": 1,
      "name": "Rock_Sandstone"
    },
    {
      "x": 2,
      "y": -3,
      "z": 1,
      "name": "Rock_Sandstone_Brick"
    },
    {
      "x": 2,
      "y": -2,
      "z": 1,
      "name": "Rock_Sandstone_Brick"
    },
    {
      "x": 2,
      "y": -1,
      "z": 1,
      "name": "Rock_Sandstone_Brick"
    },
    {
      "x": 2,
      "y": -35,
      "z": 2,
      "name": "Rock_Sandstone_Cobble"
    },
    {
      "x": 2,
      "y": -34,
      "z": 2,
      "name": "Rock_Sandstone_Brick"
    },
    {
      "x": 2,
      "y": -33,
      "z": 2,
      "name": "Rock_Sandstone"
    },
    {
      "x": 2,
      "y": -32,
      "z": 2,
      "name": "Rock_Sandstone_Brick"
    },
    {
      "x": 2,
      "y": -31,
      "z": 2,
      "name": "Rock_Sandstone_Brick"
    },
    {
      "x": 2,
      "y": -30,
      "z": 2,
      "name": "Rock_Sandstone_Brick"
    },
    {
      "x": 2,
      "y": -29,
      "z": 2,
      "name": "Rock_Sandstone_Brick"
    },
    {
      "x": 2,
      "y": -28,
      "z": 2,
      "name": "Rock_Sandstone"
    },
    {
      "x": 2,
      "y": -27,
      "z": 2,
      "name": "Rock_Sandstone"
    },
    {
      "x": 2,
      "y": -26,
      "z": 2,
      "name": "Rock_Sandstone_Brick"
    },
    {
      "x": 2,
      "y": -25,
      "z": 2,
      "name": "Rock_Sandstone"
    },
    {
      "x": 2,
      "y": -24,
      "z": 2,
      "name": "Rock_Sandstone"
    },
    {
      "x": 2,
      "y": -23,
      "z": 2,
      "name": "Rock_Sandstone_Brick"
    },
    {
      "x": 2,
      "y": -22,
      "z": 2,
      "name": "Rock_Sandstone_Brick"
    },
    {
      "x": 2,
      "y": -21,
      "z": 2,
      "name": "Rock_Sandstone_Brick"
    },
    {
      "x": 2,
      "y": -20,
      "z": 2,
      "name": "Rock_Sandstone"
    },
    {
      "x": 2,
      "y": -19,
      "z": 2,
      "name": "Rock_Sandstone_Brick"
    },
    {
      "x": 2,
      "y": -18,
      "z": 2,
      "name": "Rock_Sandstone_Brick"
    },
    {
      "x": 2,
      "y": -17,
      "z": 2,
      "name": "Rock_Sandstone_Brick"
    },
    {
      "x": 2,
      "y": -16,
      "z": 2,
      "name": "Rock_Sandstone_Brick"
    },
    {
      "x": 2,
      "y": -15,
      "z": 2,
      "name": "Rock_Sandstone_Brick"
    },
    {
      "x": 2,
      "y": -14,
      "z": 2,
      "name": "Rock_Sandstone"
    },
    {
      "x": 2,
      "y": -13,
      "z": 2,
      "name": "Rock_Sandstone_Brick"
    },
    {
      "x": 2,
      "y": -12,
      "z": 2,
      "name": "Rock_Sandstone_Brick"
    },
    {
      "x": 2,
      "y": -11,
      "z": 2,
      "name": "Rock_Sandstone"
    },
    {
      "x": 2,
      "y": -10,
      "z": 2,
      "name": "Rock_Sandstone"
    },
    {
      "x": 2,
      "y": -9,
      "z": 2,
      "name": "Rock_Sandstone_Brick"
    },
    {
      "x": 2,
      "y": -8,
      "z": 2,
      "name": "Rock_Sandstone_Brick"
    },
    {
      "x": 2,
      "y": -7,
      "z": 2,
      "name": "Rock_Sandstone_Brick"
    },
    {
      "x": 2,
      "y": -6,
      "z": 2,
      "name": "Rock_Sandstone_Brick"
    },
    {
      "x": 2,
      "y": -5,
      "z": 2,
      "name": "Rock_Sandstone_Brick"
    },
    {
      "x": 2,
      "y": -35,
      "z": 7,
      "name": "Rock_Sandstone_Brick"
    },
    {
      "x": 2,
      "y": -34,
      "z": 7,
      "name": "Rock_Sandstone_Brick"
    },
    {
      "x": 2,
      "y": -33,
      "z": 7,
      "name": "Rock_Sandstone_Brick"
    },
    {
      "x": 2,
      "y": -32,
      "z": 7,
      "name": "Rock_Sandstone_Brick"
    },
    {
      "x": 2,
      "y": -31,
      "z": 7,
      "name": "Rock_Sandstone_Brick"
    },
    {
      "x": 2,
      "y": -30,
      "z": 7,
      "name": "Rock_Sandstone_Brick"
    },
    {
      "x": 2,
      "y": -29,
      "z": 7,
      "name": "Rock_Sandstone_Brick"
    },
    {
      "x": 2,
      "y": -28,
      "z": 7,
      "name": "Rock_Sandstone_Cobble"
    },
    {
      "x": 2,
      "y": -27,
      "z": 7,
      "name": "Rock_Sandstone_Brick"
    },
    {
      "x": 2,
      "y": -26,
      "z": 7,
      "name": "Rock_Sandstone_Brick"
    },
    {
      "x": 2,
      "y": -25,
      "z": 7,
      "name": "Rock_Sandstone"
    },
    {
      "x": 2,
      "y": -24,
      "z": 7,
      "name": "Rock_Sandstone_Brick"
    },
    {
      "x": 2,
      "y": -23,
      "z": 7,
      "name": "Rock_Sandstone_Cobble"
    },
    {
      "x": 2,
      "y": -22,
      "z": 7,
      "name": "Rock_Sandstone_Cobble"
    },
    {
      "x": 2,
      "y": -21,
      "z": 7,
      "name": "Rock_Sandstone_Brick"
    },
    {
      "x": 2,
      "y": -20,
      "z": 7,
      "name": "Rock_Sandstone_Brick"
    },
    {
      "x": 2,
      "y": -19,
      "z": 7,
      "name": "Rock_Sandstone_Brick"
    },
    {
      "x": 2,
      "y": -18,
      "z": 7,
      "name": "Rock_Sandstone_Brick"
    },
    {
      "x": 2,
      "y": -17,
      "z": 7,
      "name": "Rock_Sandstone"
    },
    {
      "x": 2,
      "y": -16,
      "z": 7,
      "name": "Rock_Sandstone"
    },
    {
      "x": 2,
      "y": -15,
      "z": 7,
      "name": "Rock_Sandstone_Brick"
    },
    {
      "x": 2,
      "y": -14,
      "z": 7,
      "name": "Rock_Sandstone"
    },
    {
      "x": 2,
      "y": -13,
      "z": 7,
      "name": "Rock_Sandstone_Brick"
    },
    {
      "x": 2,
      "y": -12,
      "z": 7,
      "name": "Rock_Sandstone"
    },
    {
      "x": 2,
      "y": -11,
      "z": 7,
      "name": "Rock_Sandstone_Cobble"
    },
    {
      "x": 2,
      "y": -10,
      "z": 7,
      "name": "Rock_Sandstone_Brick"
    },
    {
      "x": 2,
      "y": -9,
      "z": 7,
      "name": "Rock_Sandstone_Cobble"
    },
    {
      "x": 2,
      "y": -8,
      "z": 7,
      "name": "Rock_Sandstone"
    },
    {
      "x": 2,
      "y": -35,
      "z": 8,
      "name": "Rock_Sandstone_Brick"
    },
    {
      "x": 2,
      "y": -34,
      "z": 8,
      "name": "Rock_Sandstone_Brick"
    },
    {
      "x": 2,
      "y": -33,
      "z": 8,
      "name": "Rock_Sandstone_Cobble"
    },
    {
      "x": 2,
      "y": -32,
      "z": 8,
      "name": "Rock_Sandstone_Cobble"
    },
    {
      "x": 2,
      "y": -31,
      "z": 8,
      "name": "Rock_Sandstone"
    },
    {
      "x": 2,
      "y": -30,
      "z": 8,
      "name": "Rock_Sandstone"
    },
    {
      "x": 2,
      "y": -29,
      "z": 8,
      "name": "Rock_Sandstone_Brick"
    },
    {
      "x": 2,
      "y": -28,
      "z": 8,
      "name": "Rock_Sandstone_Cobble"
    },
    {
      "x": 2,
      "y": -27,
      "z": 8,
      "name": "Rock_Sandstone_Brick"
    },
    {
      "x": 2,
      "y": -26,
      "z": 8,
      "name": "Rock_Sandstone_Brick"
    },
    {
      "x": 2,
      "y": -25,
      "z": 8,
      "name": "Rock_Sandstone_Brick"
    },
    {
      "x": 2,
      "y": -24,
      "z": 8,
      "name": "Rock_Sandstone"
    },
    {
      "x": 2,
      "y": -23,
      "z": 8,
      "name": "Rock_Sandstone_Brick"
    },
    {
      "x": 2,
      "y": -22,
      "z": 8,
      "name": "Rock_Sandstone_Brick"
    },
    {
      "x": 2,
      "y": -21,
      "z": 8,
      "name": "Rock_Sandstone_Brick"
    },
    {
      "x": 2,
      "y": -20,
      "z": 8,
      "name": "Rock_Sandstone_Brick"
    },
    {
      "x": 2,
      "y": -19,
      "z": 8,
      "name": "Rock_Sandstone_Brick"
    },
    {
      "x": 2,
      "y": -18,
      "z": 8,
      "name": "Rock_Sandstone_Brick"
    },
    {
      "x": 2,
      "y": -17,
      "z": 8,
      "name": "Rock_Sandstone_Cobble"
    },
    {
      "x": 2,
      "y": -16,
      "z": 8,
      "name": "Rock_Sandstone_Cobble"
    },
    {
      "x": 2,
      "y": -15,
      "z": 8,
      "name": "Rock_Sandstone_Brick"
    },
    {
      "x": 2,
      "y": -14,
      "z": 8,
      "name": "Rock_Sandstone"
    },
    {
      "x": 2,
      "y": -13,
      "z": 8,
      "name": "Rock_Sandstone_Brick"
    },
    {
      "x": 2,
      "y": -12,
      "z": 8,
      "name": "Rock_Sandstone_Brick"
    },
    {
      "x": 2,
      "y": -11,
      "z": 8,
      "name": "Rock_Sandstone_Brick"
    },
    {
      "x": 2,
      "y": -10,
      "z": 8,
      "name": "Rock_Sandstone_Cobble"
    },
    {
      "x": 2,
      "y": -9,
      "z": 8,
      "name": "Rock_Sandstone_Brick"
    },
    {
      "x": 2,
      "y": -8,
      "z": 8,
      "name": "Rock_Sandstone_Brick"
    },
    {
      "x": 2,
      "y": -35,
      "z": 9,
      "name": "Rock_Sandstone"
    },
    {
      "x": 2,
      "y": -34,
      "z": 9,
      "name": "Rock_Sandstone_Brick"
    },
    {
      "x": 2,
      "y": -33,
      "z": 9,
      "name": "Rock_Sandstone_Brick"
    },
    {
      "x": 2,
      "y": -32,
      "z": 9,
      "name": "Rock_Sandstone_Brick"
    },
    {
      "x": 2,
      "y": -31,
      "z": 9,
      "name": "Rock_Sandstone_Brick"
    },
    {
      "x": 2,
      "y": -30,
      "z": 9,
      "name": "Rock_Sandstone_Brick"
    },
    {
      "x": 2,
      "y": -29,
      "z": 9,
      "name": "Rock_Sandstone_Cobble"
    },
    {
      "x": 2,
      "y": -28,
      "z": 9,
      "name": "Rock_Sandstone_Brick"
    },
    {
      "x": 2,
      "y": -27,
      "z": 9,
      "name": "Rock_Sandstone_Brick"
    },
    {
      "x": 2,
      "y": -26,
      "z": 9,
      "name": "Rock_Sandstone"
    },
    {
      "x": 2,
      "y": -25,
      "z": 9,
      "name": "Rock_Sandstone_Cobble"
    },
    {
      "x": 2,
      "y": -24,
      "z": 9,
      "name": "Rock_Sandstone_Brick"
    },
    {
      "x": 2,
      "y": -23,
      "z": 9,
      "name": "Rock_Sandstone_Brick"
    },
    {
      "x": 2,
      "y": -22,
      "z": 9,
      "name": "Rock_Sandstone_Brick"
    },
    {
      "x": 2,
      "y": -21,
      "z": 9,
      "name": "Rock_Sandstone"
    },
    {
      "x": 2,
      "y": -20,
      "z": 9,
      "name": "Rock_Sandstone_Brick"
    },
    {
      "x": 2,
      "y": -19,
      "z": 9,
      "name": "Rock_Sandstone"
    },
    {
      "x": 2,
      "y": -18,
      "z": 9,
      "name": "Rock_Sandstone_Brick"
    },
    {
      "x": 2,
      "y": -17,
      "z": 9,
      "name": "Rock_Sandstone_Brick"
    },
    {
      "x": 2,
      "y": -16,
      "z": 9,
      "name": "Rock_Sandstone_Brick"
    },
    {
      "x": 2,
      "y": -15,
      "z": 9,
      "name": "Rock_Sandstone_Brick"
    },
    {
      "x": 2,
      "y": -14,
      "z": 9,
      "name": "Rock_Sandstone_Brick"
    },
    {
      "x": 2,
      "y": -13,
      "z": 9,
      "name": "Rock_Sandstone_Brick"
    },
    {
      "x": 2,
      "y": -12,
      "z": 9,
      "name": "Rock_Sandstone_Brick"
    },
    {
      "x": 2,
      "y": -11,
      "z": 9,
      "name": "Rock_Sandstone_Brick"
    },
    {
      "x": 2,
      "y": -10,
      "z": 9,
      "name": "Rock_Sandstone_Brick"
    },
    {
      "x": 2,
      "y": -9,
      "z": 9,
      "name": "Rock_Sandstone"
    },
    {
      "x": 2,
      "y": -8,
      "z": 9,
      "name": "Rock_Sandstone_Brick"
    },
    {
      "x": 3,
      "y": -3,
      "z": 0,
      "name": "Rock_Sandstone_Brick_Stairs",
      "rotation": 33
    },
    {
      "x": 3,
      "y": -2,
      "z": 0,
      "name": "Rock_Sandstone_Brick",
      "rotation": 3
    },
    {
      "x": 3,
      "y": -1,
      "z": 0,
      "name": "Rock_Sandstone_Brick",
      "rotation": 3
    },
    {
      "x": 3,
      "y": -4,
      "z": 1,
      "name": "Rock_Sandstone_Brick_Stairs",
      "rotation": 33
    },
    {
      "x": 4,
      "y": -2,
      "z": 0,
      "name": "Rock_Sandstone_Brick",
      "rotation": 3
    },
    {
      "x": 4,
      "y": -1,
      "z": 0,
      "name": "Rock_Sandstone_Brick",
      "rotation": 3
    },
    {
      "x": 4,
      "y": 0,
      "z": 0,
      "name": "Rock_Sandstone_Brick"
    },
    {
      "x": 7,
      "y": -35,
      "z": 0,
      "name": "Rock_Sandstone_Brick"
    },
    {
      "x": 7,
      "y": -34,
      "z": 0,
      "name": "Rock_Sandstone_Brick"
    },
    {
      "x": 7,
      "y": -33,
      "z": 0,
      "name": "Rock_Sandstone"
    },
    {
      "x": 7,
      "y": -32,
      "z": 0,
      "name": "Rock_Sandstone_Brick"
    },
    {
      "x": 7,
      "y": -31,
      "z": 0,
      "name": "Rock_Sandstone_Brick"
    },
    {
      "x": 7,
      "y": -30,
      "z": 0,
      "name": "Rock_Sandstone"
    },
    {
      "x": 7,
      "y": -29,
      "z": 0,
      "name": "Rock_Sandstone_Brick"
    },
    {
      "x": 7,
      "y": -28,
      "z": 0,
      "name": "Rock_Sandstone_Brick"
    },
    {
      "x": 7,
      "y": -27,
      "z": 0,
      "name": "Rock_Sandstone_Brick"
    },
    {
      "x": 7,
      "y": -26,
      "z": 0,
      "name": "Rock_Sandstone_Brick"
    },
    {
      "x": 7,
      "y": -25,
      "z": 0,
      "name": "Rock_Sandstone_Brick"
    },
    {
      "x": 7,
      "y": -24,
      "z": 0,
      "name": "Rock_Sandstone_Brick"
    },
    {
      "x": 7,
      "y": -23,
      "z": 0,
      "name": "Rock_Sandstone_Brick"
    },
    {
      "x": 7,
      "y": -22,
      "z": 0,
      "name": "Rock_Sandstone_Brick"
    },
    {
      "x": 7,
      "y": -21,
      "z": 0,
      "name": "Rock_Sandstone_Cobble"
    },
    {
      "x": 7,
      "y": -20,
      "z": 0,
      "name": "Rock_Sandstone_Brick"
    },
    {
      "x": 7,
      "y": -19,
      "z": 0,
      "name": "Rock_Sandstone"
    },
    {
      "x": 7,
      "y": -18,
      "z": 0,
      "name": "Rock_Sandstone_Brick"
    },
    {
      "x": 7,
      "y": -17,
      "z": 0,
      "name": "Rock_Sandstone_Brick"
    },
    {
      "x": 7,
      "y": -16,
      "z": 0,
      "name": "Rock_Sandstone"
    },
    {
      "x": 7,
      "y": -15,
      "z": 0,
      "name": "Rock_Sandstone_Brick"
    },
    {
      "x": 7,
      "y": -14,
      "z": 0,
      "name": "Rock_Sandstone_Cobble"
    },
    {
      "x": 7,
      "y": -13,
      "z": 0,
      "name": "Rock_Sandstone_Brick"
    },
    {
      "x": 7,
      "y": -12,
      "z": 0,
      "name": "Rock_Sandstone_Brick"
    },
    {
      "x": 7,
      "y": -11,
      "z": 0,
      "name": "Rock_Sandstone_Brick"
    },
    {
      "x": 7,
      "y": -10,
      "z": 0,
      "name": "Rock_Sandstone_Brick"
    },
    {
      "x": 7,
      "y": -9,
      "z": 0,
      "name": "Rock_Sandstone"
    },
    {
      "x": 7,
      "y": -8,
      "z": 0,
      "name": "Rock_Sandstone_Brick"
    },
    {
      "x": 7,
      "y": -7,
      "z": 0,
      "name": "Rock_Sandstone"
    },
    {
      "x": 7,
      "y": -6,
      "z": 0,
      "name": "Rock_Sandstone_Brick"
    },
    {
      "x": 7,
      "y": -5,
      "z": 0,
      "name": "Rock_Sandstone"
    },
    {
      "x": 7,
      "y": -4,
      "z": 0,
      "name": "Rock_Sandstone_Brick"
    },
    {
      "x": 7,
      "y": -35,
      "z": 1,
      "name": "Rock_Sandstone_Brick"
    },
    {
      "x": 7,
      "y": -34,
      "z": 1,
      "name": "Rock_Sandstone"
    },
    {
      "x": 7,
      "y": -33,
      "z": 1,
      "name": "Rock_Sandstone_Brick"
    },
    {
      "x": 7,
      "y": -32,
      "z": 1,
      "name": "Rock_Sandstone_Cobble"
    },
    {
      "x": 7,
      "y": -31,
      "z": 1,
      "name": "Rock_Sandstone_Brick"
    },
    {
      "x": 7,
      "y": -30,
      "z": 1,
      "name": "Rock_Sandstone_Brick"
    },
    {
      "x": 7,
      "y": -29,
      "z": 1,
      "name": "Rock_Sandstone"
    },
    {
      "x": 7,
      "y": -28,
      "z": 1,
      "name": "Rock_Sandstone"
    },
    {
      "x": 7,
      "y": -27,
      "z": 1,
      "name": "Rock_Sandstone_Brick"
    },
    {
      "x": 7,
      "y": -26,
      "z": 1,
      "name": "Rock_Sandstone_Brick"
    },
    {
      "x": 7,
      "y": -25,
      "z": 1,
      "name": "Rock_Sandstone"
    },
    {
      "x": 7,
      "y": -24,
      "z": 1,
      "name": "Rock_Sandstone_Brick"
    },
    {
      "x": 7,
      "y": -23,
      "z": 1,
      "name": "Rock_Sandstone_Brick"
    },
    {
      "x": 7,
      "y": -22,
      "z": 1,
      "name": "Rock_Sandstone_Brick"
    },
    {
      "x": 7,
      "y": -21,
      "z": 1,
      "name": "Rock_Sandstone_Brick"
    },
    {
      "x": 7,
      "y": -20,
      "z": 1,
      "name": "Rock_Sandstone_Brick"
    },
    {
      "x": 7,
      "y": -19,
      "z": 1,
      "name": "Rock_Sandstone_Cobble"
    },
    {
      "x": 7,
      "y": -18,
      "z": 1,
      "name": "Rock_Sandstone"
    },
    {
      "x": 7,
      "y": -17,
      "z": 1,
      "name": "Rock_Sandstone_Brick"
    },
    {
      "x": 7,
      "y": -16,
      "z": 1,
      "name": "Rock_Sandstone_Brick"
    },
    {
      "x": 7,
      "y": -15,
      "z": 1,
      "name": "Rock_Sandstone_Brick"
    },
    {
      "x": 7,
      "y": -14,
      "z": 1,
      "name": "Rock_Sandstone_Brick"
    },
    {
      "x": 7,
      "y": -13,
      "z": 1,
      "name": "Rock_Sandstone_Brick"
    },
    {
      "x": 7,
      "y": -12,
      "z": 1,
      "name": "Rock_Sandstone_Brick"
    },
    {
      "x": 7,
      "y": -11,
      "z": 1,
      "name": "Rock_Sandstone_Brick"
    },
    {
      "x": 7,
      "y": -10,
      "z": 1,
      "name": "Rock_Sandstone_Brick"
    },
    {
      "x": 7,
      "y": -9,
      "z": 1,
      "name": "Rock_Sandstone"
    },
    {
      "x": 7,
      "y": -8,
      "z": 1,
      "name": "Rock_Sandstone_Brick"
    },
    {
      "x": 7,
      "y": -7,
      "z": 1,
      "name": "Rock_Sandstone_Brick"
    },
    {
      "x": 7,
      "y": -6,
      "z": 1,
      "name": "Rock_Sandstone_Brick"
    },
    {
      "x": 7,
      "y": -35,
      "z": 2,
      "name": "Rock_Sandstone"
    },
    {
      "x": 7,
      "y": -34,
      "z": 2,
      "name": "Rock_Sandstone_Brick"
    },
    {
      "x": 7,
      "y": -33,
      "z": 2,
      "name": "Rock_Sandstone_Brick"
    },
    {
      "x": 7,
      "y": -32,
      "z": 2,
      "name": "Rock_Sandstone_Brick"
    },
    {
      "x": 7,
      "y": -31,
      "z": 2,
      "name": "Rock_Sandstone_Brick"
    },
    {
      "x": 7,
      "y": -30,
      "z": 2,
      "name": "Rock_Sandstone_Brick"
    },
    {
      "x": 7,
      "y": -29,
      "z": 2,
      "name": "Rock_Sandstone_Brick"
    },
    {
      "x": 7,
      "y": -28,
      "z": 2,
      "name": "Rock_Sandstone_Cobble"
    },
    {
      "x": 7,
      "y": -27,
      "z": 2,
      "name": "Rock_Sandstone_Cobble"
    },
    {
      "x": 7,
      "y": -26,
      "z": 2,
      "name": "Rock_Sandstone_Brick"
    },
    {
      "x": 7,
      "y": -25,
      "z": 2,
      "name": "Rock_Sandstone_Cobble"
    },
    {
      "x": 7,
      "y": -24,
      "z": 2,
      "name": "Rock_Sandstone_Brick"
    },
    {
      "x": 7,
      "y": -23,
      "z": 2,
      "name": "Rock_Sandstone_Brick"
    },
    {
      "x": 7,
      "y": -22,
      "z": 2,
      "name": "Rock_Sandstone_Brick"
    },
    {
      "x": 7,
      "y": -21,
      "z": 2,
      "name": "Rock_Sandstone_Brick"
    },
    {
      "x": 7,
      "y": -20,
      "z": 2,
      "name": "Rock_Sandstone_Brick"
    },
    {
      "x": 7,
      "y": -19,
      "z": 2,
      "name": "Rock_Sandstone_Brick"
    },
    {
      "x": 7,
      "y": -18,
      "z": 2,
      "name": "Rock_Sandstone_Brick"
    },
    {
      "x": 7,
      "y": -17,
      "z": 2,
      "name": "Rock_Sandstone"
    },
    {
      "x": 7,
      "y": -16,
      "z": 2,
      "name": "Rock_Sandstone_Brick"
    },
    {
      "x": 7,
      "y": -15,
      "z": 2,
      "name": "Rock_Sandstone"
    },
    {
      "x": 7,
      "y": -14,
      "z": 2,
      "name": "Rock_Sandstone_Brick"
    },
    {
      "x": 7,
      "y": -13,
      "z": 2,
      "name": "Rock_Sandstone_Brick"
    },
    {
      "x": 7,
      "y": -12,
      "z": 2,
      "name": "Rock_Sandstone"
    },
    {
      "x": 7,
      "y": -11,
      "z": 2,
      "name": "Rock_Sandstone_Brick"
    },
    {
      "x": 7,
      "y": -10,
      "z": 2,
      "name": "Rock_Sandstone_Brick"
    },
    {
      "x": 7,
      "y": -9,
      "z": 2,
      "name": "Rock_Sandstone_Brick"
    },
    {
      "x": 7,
      "y": -8,
      "z": 2,
      "name": "Rock_Sandstone_Brick"
    },
    {
      "x": 7,
      "y": -7,
      "z": 2,
      "name": "Rock_Sandstone_Cobble"
    },
    {
      "x": 7,
      "y": -35,
      "z": 7,
      "name": "Rock_Sandstone"
    },
    {
      "x": 7,
      "y": -34,
      "z": 7,
      "name": "Rock_Sandstone"
    },
    {
      "x": 7,
      "y": -33,
      "z": 7,
      "name": "Rock_Sandstone"
    },
    {
      "x": 7,
      "y": -32,
      "z": 7,
      "name": "Rock_Sandstone"
    },
    {
      "x": 7,
      "y": -31,
      "z": 7,
      "name": "Rock_Sandstone"
    },
    {
      "x": 7,
      "y": -30,
      "z": 7,
      "name": "Rock_Sandstone_Brick"
    },
    {
      "x": 7,
      "y": -29,
      "z": 7,
      "name": "Rock_Sandstone_Brick"
    },
    {
      "x": 7,
      "y": -28,
      "z": 7,
      "name": "Rock_Sandstone_Brick"
    },
    {
      "x": 7,
      "y": -27,
      "z": 7,
      "name": "Rock_Sandstone_Brick"
    },
    {
      "x": 7,
      "y": -26,
      "z": 7,
      "name": "Rock_Sandstone"
    },
    {
      "x": 7,
      "y": -25,
      "z": 7,
      "name": "Rock_Sandstone_Brick"
    },
    {
      "x": 7,
      "y": -24,
      "z": 7,
      "name": "Rock_Sandstone_Cobble"
    },
    {
      "x": 7,
      "y": -23,
      "z": 7,
      "name": "Rock_Sandstone_Cobble"
    },
    {
      "x": 7,
      "y": -22,
      "z": 7,
      "name": "Rock_Sandstone_Brick"
    },
    {
      "x": 7,
      "y": -21,
      "z": 7,
      "name": "Rock_Sandstone_Cobble"
    },
    {
      "x": 7,
      "y": -20,
      "z": 7,
      "name": "Rock_Sandstone"
    },
    {
      "x": 7,
      "y": -19,
      "z": 7,
      "name": "Rock_Sandstone_Brick"
    },
    {
      "x": 7,
      "y": -18,
      "z": 7,
      "name": "Rock_Sandstone_Cobble"
    },
    {
      "x": 7,
      "y": -17,
      "z": 7,
      "name": "Rock_Sandstone_Brick"
    },
    {
      "x": 7,
      "y": -16,
      "z": 7,
      "name": "Rock_Sandstone"
    },
    {
      "x": 7,
      "y": -15,
      "z": 7,
      "name": "Rock_Sandstone_Brick"
    },
    {
      "x": 7,
      "y": -14,
      "z": 7,
      "name": "Rock_Sandstone"
    },
    {
      "x": 7,
      "y": -13,
      "z": 7,
      "name": "Rock_Sandstone_Brick"
    },
    {
      "x": 7,
      "y": -12,
      "z": 7,
      "name": "Rock_Sandstone_Brick"
    },
    {
      "x": 7,
      "y": -11,
      "z": 7,
      "name": "Rock_Sandstone_Brick"
    },
    {
      "x": 7,
      "y": -10,
      "z": 7,
      "name": "Rock_Sandstone"
    },
    {
      "x": 7,
      "y": -35,
      "z": 8,
      "name": "Rock_Sandstone_Cobble"
    },
    {
      "x": 7,
      "y": -34,
      "z": 8,
      "name": "Rock_Sandstone_Brick"
    },
    {
      "x": 7,
      "y": -33,
      "z": 8,
      "name": "Rock_Sandstone_Brick"
    },
    {
      "x": 7,
      "y": -32,
      "z": 8,
      "name": "Rock_Sandstone"
    },
    {
      "x": 7,
      "y": -31,
      "z": 8,
      "name": "Rock_Sandstone"
    },
    {
      "x": 7,
      "y": -30,
      "z": 8,
      "name": "Rock_Sandstone_Brick"
    },
    {
      "x": 7,
      "y": -29,
      "z": 8,
      "name": "Rock_Sandstone"
    },
    {
      "x": 7,
      "y": -28,
      "z": 8,
      "name": "Rock_Sandstone"
    },
    {
      "x": 7,
      "y": -27,
      "z": 8,
      "name": "Rock_Sandstone_Brick"
    },
    {
      "x": 7,
      "y": -26,
      "z": 8,
      "name": "Rock_Sandstone"
    },
    {
      "x": 7,
      "y": -25,
      "z": 8,
      "name": "Rock_Sandstone_Brick"
    },
    {
      "x": 7,
      "y": -24,
      "z": 8,
      "name": "Rock_Sandstone_Brick"
    },
    {
      "x": 7,
      "y": -23,
      "z": 8,
      "name": "Rock_Sandstone_Brick"
    },
    {
      "x": 7,
      "y": -22,
      "z": 8,
      "name": "Rock_Sandstone_Brick"
    },
    {
      "x": 7,
      "y": -21,
      "z": 8,
      "name": "Rock_Sandstone_Brick"
    },
    {
      "x": 7,
      "y": -20,
      "z": 8,
      "name": "Rock_Sandstone_Cobble"
    },
    {
      "x": 7,
      "y": -19,
      "z": 8,
      "name": "Rock_Sandstone_Brick"
    },
    {
      "x": 7,
      "y": -18,
      "z": 8,
      "name": "Rock_Sandstone_Brick"
    },
    {
      "x": 7,
      "y": -17,
      "z": 8,
      "name": "Rock_Sandstone_Brick"
    },
    {
      "x": 7,
      "y": -16,
      "z": 8,
      "name": "Rock_Sandstone_Brick"
    },
    {
      "x": 7,
      "y": -15,
      "z": 8,
      "name": "Rock_Sandstone_Brick"
    },
    {
      "x": 7,
      "y": -14,
      "z": 8,
      "name": "Rock_Sandstone_Cobble"
    },
    {
      "x": 7,
      "y": -13,
      "z": 8,
      "name": "Rock_Sandstone_Brick"
    },
    {
      "x": 7,
      "y": -12,
      "z": 8,
      "name": "Rock_Sandstone_Brick"
    },
    {
      "x": 7,
      "y": -11,
      "z": 8,
      "name": "Rock_Sandstone"
    },
    {
      "x": 7,
      "y": -10,
      "z": 8,
      "name": "Rock_Sandstone_Brick"
    },
    {
      "x": 7,
      "y": -35,
      "z": 9,
      "name": "Rock_Sandstone_Brick"
    },
    {
      "x": 7,
      "y": -34,
      "z": 9,
      "name": "Rock_Sandstone_Brick"
    },
    {
      "x": 7,
      "y": -33,
      "z": 9,
      "name": "Rock_Sandstone_Brick"
    },
    {
      "x": 7,
      "y": -32,
      "z": 9,
      "name": "Rock_Sandstone_Cobble"
    },
    {
      "x": 7,
      "y": -31,
      "z": 9,
      "name": "Rock_Sandstone_Cobble"
    },
    {
      "x": 7,
      "y": -30,
      "z": 9,
      "name": "Rock_Sandstone"
    },
    {
      "x": 7,
      "y": -29,
      "z": 9,
      "name": "Rock_Sandstone_Brick"
    },
    {
      "x": 7,
      "y": -28,
      "z": 9,
      "name": "Rock_Sandstone"
    },
    {
      "x": 7,
      "y": -27,
      "z": 9,
      "name": "Rock_Sandstone_Cobble"
    },
    {
      "x": 7,
      "y": -26,
      "z": 9,
      "name": "Rock_Sandstone_Cobble"
    },
    {
      "x": 7,
      "y": -25,
      "z": 9,
      "name": "Rock_Sandstone_Brick"
    },
    {
      "x": 7,
      "y": -24,
      "z": 9,
      "name": "Rock_Sandstone_Brick"
    },
    {
      "x": 7,
      "y": -23,
      "z": 9,
      "name": "Rock_Sandstone"
    },
    {
      "x": 7,
      "y": -22,
      "z": 9,
      "name": "Rock_Sandstone_Brick"
    },
    {
      "x": 7,
      "y": -21,
      "z": 9,
      "name": "Rock_Sandstone_Brick"
    },
    {
      "x": 7,
      "y": -20,
      "z": 9,
      "name": "Rock_Sandstone_Brick"
    },
    {
      "x": 7,
      "y": -19,
      "z": 9,
      "name": "Rock_Sandstone_Brick"
    },
    {
      "x": 7,
      "y": -18,
      "z": 9,
      "name": "Rock_Sandstone_Brick"
    },
    {
      "x": 7,
      "y": -17,
      "z": 9,
      "name": "Rock_Sandstone_Brick"
    },
    {
      "x": 7,
      "y": -16,
      "z": 9,
      "name": "Rock_Sandstone_Brick"
    },
    {
      "x": 7,
      "y": -15,
      "z": 9,
      "name": "Rock_Sandstone"
    },
    {
      "x": 7,
      "y": -14,
      "z": 9,
      "name": "Rock_Sandstone_Brick"
    },
    {
      "x": 7,
      "y": -13,
      "z": 9,
      "name": "Rock_Sandstone"
    },
    {
      "x": 7,
      "y": -12,
      "z": 9,
      "name": "Rock_Sandstone"
    },
    {
      "x": 7,
      "y": -11,
      "z": 9,
      "name": "Rock_Sandstone_Brick"
    },
    {
      "x": 7,
      "y": -10,
      "z": 9,
      "name": "Rock_Sandstone"
    },
    {
      "x": 8,
      "y": -35,
      "z": 0,
      "name": "Rock_Sandstone_Brick"
    },
    {
      "x": 8,
      "y": -34,
      "z": 0,
      "name": "Rock_Sandstone_Brick"
    },
    {
      "x": 8,
      "y": -33,
      "z": 0,
      "name": "Rock_Sandstone_Brick"
    },
    {
      "x": 8,
      "y": -32,
      "z": 0,
      "name": "Rock_Sandstone_Cobble"
    },
    {
      "x": 8,
      "y": -31,
      "z": 0,
      "name": "Rock_Sandstone"
    },
    {
      "x": 8,
      "y": -30,
      "z": 0,
      "name": "Rock_Sandstone_Brick"
    },
    {
      "x": 8,
      "y": -29,
      "z": 0,
      "name": "Rock_Sandstone"
    },
    {
      "x": 8,
      "y": -28,
      "z": 0,
      "name": "Rock_Sandstone_Brick"
    },
    {
      "x": 8,
      "y": -27,
      "z": 0,
      "name": "Rock_Sandstone_Brick"
    },
    {
      "x": 8,
      "y": -26,
      "z": 0,
      "name": "Rock_Sandstone_Brick"
    },
    {
      "x": 8,
      "y": -25,
      "z": 0,
      "name": "Rock_Sandstone_Cobble"
    },
    {
      "x": 8,
      "y": -24,
      "z": 0,
      "name": "Rock_Sandstone"
    },
    {
      "x": 8,
      "y": -23,
      "z": 0,
      "name": "Rock_Sandstone_Cobble"
    },
    {
      "x": 8,
      "y": -22,
      "z": 0,
      "name": "Rock_Sandstone_Brick"
    },
    {
      "x": 8,
      "y": -21,
      "z": 0,
      "name": "Rock_Sandstone"
    },
    {
      "x": 8,
      "y": -20,
      "z": 0,
      "name": "Rock_Sandstone"
    },
    {
      "x": 8,
      "y": -19,
      "z": 0,
      "name": "Rock_Sandstone_Brick"
    },
    {
      "x": 8,
      "y": -18,
      "z": 0,
      "name": "Rock_Sandstone"
    },
    {
      "x": 8,
      "y": -17,
      "z": 0,
      "name": "Rock_Sandstone_Brick"
    },
    {
      "x": 8,
      "y": -16,
      "z": 0,
      "name": "Rock_Sandstone_Brick"
    },
    {
      "x": 8,
      "y": -15,
      "z": 0,
      "name": "Rock_Sandstone"
    },
    {
      "x": 8,
      "y": -14,
      "z": 0,
      "name": "Rock_Sandstone_Cobble"
    },
    {
      "x": 8,
      "y": -13,
      "z": 0,
      "name": "Rock_Sandstone"
    },
    {
      "x": 8,
      "y": -12,
      "z": 0,
      "name": "Rock_Sandstone_Brick"
    },
    {
      "x": 8,
      "y": -11,
      "z": 0,
      "name": "Rock_Sandstone"
    },
    {
      "x": 8,
      "y": -10,
      "z": 0,
      "name": "Rock_Sandstone_Brick"
    },
    {
      "x": 8,
      "y": -9,
      "z": 0,
      "name": "Rock_Sandstone"
    },
    {
      "x": 8,
      "y": -8,
      "z": 0,
      "name": "Rock_Sandstone_Brick"
    },
    {
      "x": 8,
      "y": -7,
      "z": 0,
      "name": "Rock_Sandstone_Brick"
    },
    {
      "x": 8,
      "y": -6,
      "z": 0,
      "name": "Rock_Sandstone_Brick"
    },
    {
      "x": 8,
      "y": -5,
      "z": 0,
      "name": "Rock_Sandstone_Brick"
    },
    {
      "x": 8,
      "y": -4,
      "z": 0,
      "name": "Rock_Sandstone_Cobble"
    },
    {
      "x": 8,
      "y": -35,
      "z": 1,
      "name": "Rock_Sandstone_Brick"
    },
    {
      "x": 8,
      "y": -34,
      "z": 1,
      "name": "Rock_Sandstone_Brick"
    },
    {
      "x": 8,
      "y": -33,
      "z": 1,
      "name": "Rock_Sandstone_Brick"
    },
    {
      "x": 8,
      "y": -32,
      "z": 1,
      "name": "Rock_Sandstone_Brick"
    },
    {
      "x": 8,
      "y": -31,
      "z": 1,
      "name": "Rock_Sandstone"
    },
    {
      "x": 8,
      "y": -30,
      "z": 1,
      "name": "Rock_Sandstone_Brick"
    },
    {
      "x": 8,
      "y": -29,
      "z": 1,
      "name": "Rock_Sandstone_Brick"
    },
    {
      "x": 8,
      "y": -28,
      "z": 1,
      "name": "Rock_Sandstone_Cobble"
    },
    {
      "x": 8,
      "y": -27,
      "z": 1,
      "name": "Rock_Sandstone_Brick"
    },
    {
      "x": 8,
      "y": -26,
      "z": 1,
      "name": "Rock_Sandstone_Brick"
    },
    {
      "x": 8,
      "y": -25,
      "z": 1,
      "name": "Rock_Sandstone_Cobble"
    },
    {
      "x": 8,
      "y": -24,
      "z": 1,
      "name": "Rock_Sandstone_Cobble"
    },
    {
      "x": 8,
      "y": -23,
      "z": 1,
      "name": "Rock_Sandstone_Brick"
    },
    {
      "x": 8,
      "y": -22,
      "z": 1,
      "name": "Rock_Sandstone_Brick"
    },
    {
      "x": 8,
      "y": -21,
      "z": 1,
      "name": "Rock_Sandstone_Brick"
    },
    {
      "x": 8,
      "y": -20,
      "z": 1,
      "name": "Rock_Sandstone_Brick"
    },
    {
      "x": 8,
      "y": -19,
      "z": 1,
      "name": "Rock_Sandstone_Brick"
    },
    {
      "x": 8,
      "y": -18,
      "z": 1,
      "name": "Rock_Sandstone_Cobble"
    },
    {
      "x": 8,
      "y": -17,
      "z": 1,
      "name": "Rock_Sandstone_Cobble"
    },
    {
      "x": 8,
      "y": -16,
      "z": 1,
      "name": "Rock_Sandstone"
    },
    {
      "x": 8,
      "y": -15,
      "z": 1,
      "name": "Rock_Sandstone_Brick"
    },
    {
      "x": 8,
      "y": -14,
      "z": 1,
      "name": "Rock_Sandstone_Brick"
    },
    {
      "x": 8,
      "y": -13,
      "z": 1,
      "name": "Rock_Sandstone_Brick"
    },
    {
      "x": 8,
      "y": -12,
      "z": 1,
      "name": "Rock_Sandstone_Brick"
    },
    {
      "x": 8,
      "y": -11,
      "z": 1,
      "name": "Rock_Sandstone_Brick"
    },
    {
      "x": 8,
      "y": -10,
      "z": 1,
      "name": "Rock_Sandstone_Brick"
    },
    {
      "x": 8,
      "y": -9,
      "z": 1,
      "name": "Rock_Sandstone"
    },
    {
      "x": 8,
      "y": -8,
      "z": 1,
      "name": "Rock_Sandstone_Brick"
    },
    {
      "x": 8,
      "y": -7,
      "z": 1,
      "name": "Rock_Sandstone_Cobble"
    },
    {
      "x": 8,
      "y": -6,
      "z": 1,
      "name": "Rock_Sandstone_Brick"
    },
    {
      "x": 8,
      "y": -35,
      "z": 2,
      "name": "Rock_Sandstone_Brick"
    },
    {
      "x": 8,
      "y": -34,
      "z": 2,
      "name": "Rock_Sandstone_Brick"
    },
    {
      "x": 8,
      "y": -33,
      "z": 2,
      "name": "Rock_Sandstone_Brick"
    },
    {
      "x": 8,
      "y": -32,
      "z": 2,
      "name": "Rock_Sandstone_Brick"
    },
    {
      "x": 8,
      "y": -31,
      "z": 2,
      "name": "Rock_Sandstone"
    },
    {
      "x": 8,
      "y": -30,
      "z": 2,
      "name": "Rock_Sandstone_Brick"
    },
    {
      "x": 8,
      "y": -29,
      "z": 2,
      "name": "Rock_Sandstone_Brick"
    },
    {
      "x": 8,
      "y": -28,
      "z": 2,
      "name": "Rock_Sandstone_Brick"
    },
    {
      "x": 8,
      "y": -27,
      "z": 2,
      "name": "Rock_Sandstone_Brick"
    },
    {
      "x": 8,
      "y": -26,
      "z": 2,
      "name": "Rock_Sandstone"
    },
    {
      "x": 8,
      "y": -25,
      "z": 2,
      "name": "Rock_Sandstone_Brick"
    },
    {
      "x": 8,
      "y": -24,
      "z": 2,
      "name": "Rock_Sandstone_Brick"
    },
    {
      "x": 8,
      "y": -23,
      "z": 2,
      "name": "Rock_Sandstone_Brick"
    },
    {
      "x": 8,
      "y": -22,
      "z": 2,
      "name": "Rock_Sandstone"
    },
    {
      "x": 8,
      "y": -21,
      "z": 2,
      "name": "Rock_Sandstone_Cobble"
    },
    {
      "x": 8,
      "y": -20,
      "z": 2,
      "name": "Rock_Sandstone_Brick"
    },
    {
      "x": 8,
      "y": -19,
      "z": 2,
      "name": "Rock_Sandstone_Brick"
    },
    {
      "x": 8,
      "y": -18,
      "z": 2,
      "name": "Rock_Sandstone_Brick"
    },
    {
      "x": 8,
      "y": -17,
      "z": 2,
      "name": "Rock_Sandstone_Cobble"
    },
    {
      "x": 8,
      "y": -16,
      "z": 2,
      "name": "Rock_Sandstone_Brick"
    },
    {
      "x": 8,
      "y": -15,
      "z": 2,
      "name": "Rock_Sandstone_Brick"
    },
    {
      "x": 8,
      "y": -14,
      "z": 2,
      "name": "Rock_Sandstone_Cobble"
    },
    {
      "x": 8,
      "y": -13,
      "z": 2,
      "name": "Rock_Sandstone_Brick"
    },
    {
      "x": 8,
      "y": -12,
      "z": 2,
      "name": "Rock_Sandstone_Brick"
    },
    {
      "x": 8,
      "y": -11,
      "z": 2,
      "name": "Rock_Sandstone_Brick"
    },
    {
      "x": 8,
      "y": -10,
      "z": 2,
      "name": "Rock_Sandstone_Brick"
    },
    {
      "x": 8,
      "y": -9,
      "z": 2,
      "name": "Rock_Sandstone_Brick"
    },
    {
      "x": 8,
      "y": -8,
      "z": 2,
      "name": "Rock_Sandstone_Brick"
    },
    {
      "x": 8,
      "y": -7,
      "z": 2,
      "name": "Rock_Sandstone_Cobble"
    },
    {
      "x": 8,
      "y": -35,
      "z": 7,
      "name": "Rock_Sandstone_Brick"
    },
    {
      "x": 8,
      "y": -34,
      "z": 7,
      "name": "Rock_Sandstone_Brick"
    },
    {
      "x": 8,
      "y": -33,
      "z": 7,
      "name": "Rock_Sandstone_Brick"
    },
    {
      "x": 8,
      "y": -32,
      "z": 7,
      "name": "Rock_Sandstone_Brick"
    },
    {
      "x": 8,
      "y": -31,
      "z": 7,
      "name": "Rock_Sandstone_Brick"
    },
    {
      "x": 8,
      "y": -30,
      "z": 7,
      "name": "Rock_Sandstone"
    },
    {
      "x": 8,
      "y": -29,
      "z": 7,
      "name": "Rock_Sandstone_Brick"
    },
    {
      "x": 8,
      "y": -28,
      "z": 7,
      "name": "Rock_Sandstone_Brick"
    },
    {
      "x": 8,
      "y": -27,
      "z": 7,
      "name": "Rock_Sandstone_Brick"
    },
    {
      "x": 8,
      "y": -26,
      "z": 7,
      "name": "Rock_Sandstone_Cobble"
    },
    {
      "x": 8,
      "y": -25,
      "z": 7,
      "name": "Rock_Sandstone"
    },
    {
      "x": 8,
      "y": -24,
      "z": 7,
      "name": "Rock_Sandstone_Brick"
    },
    {
      "x": 8,
      "y": -23,
      "z": 7,
      "name": "Rock_Sandstone"
    },
    {
      "x": 8,
      "y": -22,
      "z": 7,
      "name": "Rock_Sandstone_Brick"
    },
    {
      "x": 8,
      "y": -21,
      "z": 7,
      "name": "Rock_Sandstone_Brick"
    },
    {
      "x": 8,
      "y": -20,
      "z": 7,
      "name": "Rock_Sandstone_Brick"
    },
    {
      "x": 8,
      "y": -19,
      "z": 7,
      "name": "Rock_Sandstone"
    },
    {
      "x": 8,
      "y": -18,
      "z": 7,
      "name": "Rock_Sandstone"
    },
    {
      "x": 8,
      "y": -17,
      "z": 7,
      "name": "Rock_Sandstone_Cobble"
    },
    {
      "x": 8,
      "y": -16,
      "z": 7,
      "name": "Rock_Sandstone_Brick"
    },
    {
      "x": 8,
      "y": -15,
      "z": 7,
      "name": "Rock_Sandstone"
    },
    {
      "x": 8,
      "y": -14,
      "z": 7,
      "name": "Rock_Sandstone_Cobble"
    },
    {
      "x": 8,
      "y": -13,
      "z": 7,
      "name": "Rock_Sandstone_Brick"
    },
    {
      "x": 8,
      "y": -12,
      "z": 7,
      "name": "Rock_Sandstone"
    },
    {
      "x": 8,
      "y": -11,
      "z": 7,
      "name": "Rock_Sandstone"
    },
    {
      "x": 8,
      "y": -10,
      "z": 7,
      "name": "Rock_Sandstone_Brick"
    },
    {
      "x": 8,
      "y": -35,
      "z": 8,
      "name": "Rock_Sandstone_Brick"
    },
    {
      "x": 8,
      "y": -34,
      "z": 8,
      "name": "Rock_Sandstone_Brick"
    },
    {
      "x": 8,
      "y": -33,
      "z": 8,
      "name": "Rock_Sandstone_Brick"
    },
    {
      "x": 8,
      "y": -32,
      "z": 8,
      "name": "Rock_Sandstone_Brick"
    },
    {
      "x": 8,
      "y": -31,
      "z": 8,
      "name": "Rock_Sandstone_Brick"
    },
    {
      "x": 8,
      "y": -30,
      "z": 8,
      "name": "Rock_Sandstone_Brick"
    },
    {
      "x": 8,
      "y": -29,
      "z": 8,
      "name": "Rock_Sandstone_Brick"
    },
    {
      "x": 8,
      "y": -28,
      "z": 8,
      "name": "Rock_Sandstone"
    },
    {
      "x": 8,
      "y": -27,
      "z": 8,
      "name": "Rock_Sandstone_Brick"
    },
    {
      "x": 8,
      "y": -26,
      "z": 8,
      "name": "Rock_Sandstone_Brick"
    },
    {
      "x": 8,
      "y": -25,
      "z": 8,
      "name": "Rock_Sandstone_Brick"
    },
    {
      "x": 8,
      "y": -24,
      "z": 8,
      "name": "Rock_Sandstone_Brick"
    },
    {
      "x": 8,
      "y": -23,
      "z": 8,
      "name": "Rock_Sandstone_Brick"
    },
    {
      "x": 8,
      "y": -22,
      "z": 8,
      "name": "Rock_Sandstone_Brick"
    },
    {
      "x": 8,
      "y": -21,
      "z": 8,
      "name": "Rock_Sandstone_Brick"
    },
    {
      "x": 8,
      "y": -20,
      "z": 8,
      "name": "Rock_Sandstone_Brick"
    },
    {
      "x": 8,
      "y": -19,
      "z": 8,
      "name": "Rock_Sandstone_Brick"
    },
    {
      "x": 8,
      "y": -18,
      "z": 8,
      "name": "Rock_Sandstone"
    },
    {
      "x": 8,
      "y": -17,
      "z": 8,
      "name": "Rock_Sandstone_Cobble"
    },
    {
      "x": 8,
      "y": -16,
      "z": 8,
      "name": "Rock_Sandstone_Cobble"
    },
    {
      "x": 8,
      "y": -15,
      "z": 8,
      "name": "Rock_Sandstone"
    },
    {
      "x": 8,
      "y": -14,
      "z": 8,
      "name": "Rock_Sandstone_Cobble"
    },
    {
      "x": 8,
      "y": -13,
      "z": 8,
      "name": "Rock_Sandstone_Cobble"
    },
    {
      "x": 8,
      "y": -12,
      "z": 8,
      "name": "Rock_Sandstone"
    },
    {
      "x": 8,
      "y": -11,
      "z": 8,
      "name": "Rock_Sandstone"
    },
    {
      "x": 8,
      "y": -10,
      "z": 8,
      "name": "Rock_Sandstone_Brick"
    },
    {
      "x": 8,
      "y": -35,
      "z": 9,
      "name": "Rock_Sandstone_Brick"
    },
    {
      "x": 8,
      "y": -34,
      "z": 9,
      "name": "Rock_Sandstone_Brick"
    },
    {
      "x": 8,
      "y": -33,
      "z": 9,
      "name": "Rock_Sandstone_Brick"
    },
    {
      "x": 8,
      "y": -32,
      "z": 9,
      "name": "Rock_Sandstone_Brick"
    },
    {
      "x": 8,
      "y": -31,
      "z": 9,
      "name": "Rock_Sandstone_Brick"
    },
    {
      "x": 8,
      "y": -30,
      "z": 9,
      "name": "Rock_Sandstone_Brick"
    },
    {
      "x": 8,
      "y": -29,
      "z": 9,
      "name": "Rock_Sandstone"
    },
    {
      "x": 8,
      "y": -28,
      "z": 9,
      "name": "Rock_Sandstone_Cobble"
    },
    {
      "x": 8,
      "y": -27,
      "z": 9,
      "name": "Rock_Sandstone_Brick"
    },
    {
      "x": 8,
      "y": -26,
      "z": 9,
      "name": "Rock_Sandstone_Brick"
    },
    {
      "x": 8,
      "y": -25,
      "z": 9,
      "name": "Rock_Sandstone_Cobble"
    },
    {
      "x": 8,
      "y": -24,
      "z": 9,
      "name": "Rock_Sandstone_Brick"
    },
    {
      "x": 8,
      "y": -23,
      "z": 9,
      "name": "Rock_Sandstone_Brick"
    },
    {
      "x": 8,
      "y": -22,
      "z": 9,
      "name": "Rock_Sandstone_Brick"
    },
    {
      "x": 8,
      "y": -21,
      "z": 9,
      "name": "Rock_Sandstone_Brick"
    },
    {
      "x": 8,
      "y": -20,
      "z": 9,
      "name": "Rock_Sandstone_Brick"
    },
    {
      "x": 8,
      "y": -19,
      "z": 9,
      "name": "Rock_Sandstone_Cobble"
    },
    {
      "x": 8,
      "y": -18,
      "z": 9,
      "name": "Rock_Sandstone"
    },
    {
      "x": 8,
      "y": -17,
      "z": 9,
      "name": "Rock_Sandstone_Brick"
    },
    {
      "x": 8,
      "y": -16,
      "z": 9,
      "name": "Rock_Sandstone_Brick"
    },
    {
      "x": 8,
      "y": -15,
      "z": 9,
      "name": "Rock_Sandstone_Brick"
    },
    {
      "x": 8,
      "y": -14,
      "z": 9,
      "name": "Rock_Sandstone_Brick"
    },
    {
      "x": 8,
      "y": -13,
      "z": 9,
      "name": "Rock_Sandstone_Brick"
    },
    {
      "x": 8,
      "y": -12,
      "z": 9,
      "name": "Rock_Sandstone_Brick"
    },
    {
      "x": 8,
      "y": -11,
      "z": 9,
      "name": "Rock_Sandstone"
    },
    {
      "x": 8,
      "y": -10,
      "z": 9,
      "name": "Rock_Sandstone"
    },
    {
      "x": 9,
      "y": -35,
      "z": 1,
      "name": "Rock_Sandstone_Brick"
    },
    {
      "x": 9,
      "y": -34,
      "z": 1,
      "name": "Rock_Sandstone_Brick"
    },
    {
      "x": 9,
      "y": -33,
      "z": 1,
      "name": "Rock_Sandstone_Brick"
    },
    {
      "x": 9,
      "y": -32,
      "z": 1,
      "name": "Rock_Sandstone_Brick"
    },
    {
      "x": 9,
      "y": -31,
      "z": 1,
      "name": "Rock_Sandstone_Brick"
    },
    {
      "x": 9,
      "y": -30,
      "z": 1,
      "name": "Rock_Sandstone_Brick"
    },
    {
      "x": 9,
      "y": -29,
      "z": 1,
      "name": "Rock_Sandstone"
    },
    {
      "x": 9,
      "y": -28,
      "z": 1,
      "name": "Rock_Sandstone_Brick"
    },
    {
      "x": 9,
      "y": -27,
      "z": 1,
      "name": "Rock_Sandstone_Brick"
    },
    {
      "x": 9,
      "y": -26,
      "z": 1,
      "name": "Rock_Sandstone_Brick"
    },
    {
      "x": 9,
      "y": -25,
      "z": 1,
      "name": "Rock_Sandstone_Brick"
    },
    {
      "x": 9,
      "y": -24,
      "z": 1,
      "name": "Rock_Sandstone_Brick"
    },
    {
      "x": 9,
      "y": -23,
      "z": 1,
      "name": "Rock_Sandstone_Brick"
    },
    {
      "x": 9,
      "y": -22,
      "z": 1,
      "name": "Rock_Sandstone_Brick"
    },
    {
      "x": 9,
      "y": -21,
      "z": 1,
      "name": "Rock_Sandstone"
    },
    {
      "x": 9,
      "y": -20,
      "z": 1,
      "name": "Rock_Sandstone_Brick"
    },
    {
      "x": 9,
      "y": -19,
      "z": 1,
      "name": "Rock_Sandstone_Brick"
    },
    {
      "x": 9,
      "y": -18,
      "z": 1,
      "name": "Rock_Sandstone_Brick"
    },
    {
      "x": 9,
      "y": -17,
      "z": 1,
      "name": "Rock_Sandstone_Brick"
    },
    {
      "x": 9,
      "y": -16,
      "z": 1,
      "name": "Rock_Sandstone_Brick"
    },
    {
      "x": 9,
      "y": -15,
      "z": 1,
      "name": "Rock_Sandstone"
    },
    {
      "x": 9,
      "y": -14,
      "z": 1,
      "name": "Rock_Sandstone_Brick"
    },
    {
      "x": 9,
      "y": -13,
      "z": 1,
      "name": "Rock_Sandstone_Brick"
    },
    {
      "x": 9,
      "y": -12,
      "z": 1,
      "name": "Rock_Sandstone_Brick"
    },
    {
      "x": 9,
      "y": -11,
      "z": 1,
      "name": "Rock_Sandstone_Brick"
    },
    {
      "x": 9,
      "y": -10,
      "z": 1,
      "name": "Rock_Sandstone_Cobble"
    },
    {
      "x": 9,
      "y": -9,
      "z": 1,
      "name": "Rock_Sandstone_Brick"
    },
    {
      "x": 9,
      "y": -8,
      "z": 1,
      "name": "Rock_Sandstone_Brick"
    },
    {
      "x": 9,
      "y": -7,
      "z": 1,
      "name": "Rock_Sandstone_Brick"
    },
    {
      "x": 9,
      "y": -6,
      "z": 1,
      "name": "Rock_Sandstone_Brick"
    },
    {
      "x": 9,
      "y": -35,
      "z": 2,
      "name": "Rock_Sandstone_Brick"
    },
    {
      "x": 9,
      "y": -34,
      "z": 2,
      "name": "Rock_Sandstone_Brick"
    },
    {
      "x": 9,
      "y": -33,
      "z": 2,
      "name": "Rock_Sandstone"
    },
    {
      "x": 9,
      "y": -32,
      "z": 2,
      "name": "Rock_Sandstone_Brick"
    },
    {
      "x": 9,
      "y": -31,
      "z": 2,
      "name": "Rock_Sandstone_Brick"
    },
    {
      "x": 9,
      "y": -30,
      "z": 2,
      "name": "Rock_Sandstone_Brick"
    },
    {
      "x": 9,
      "y": -29,
      "z": 2,
      "name": "Rock_Sandstone_Brick"
    },
    {
      "x": 9,
      "y": -28,
      "z": 2,
      "name": "Rock_Sandstone_Brick"
    },
    {
      "x": 9,
      "y": -27,
      "z": 2,
      "name": "Rock_Sandstone_Cobble"
    },
    {
      "x": 9,
      "y": -26,
      "z": 2,
      "name": "Rock_Sandstone_Cobble"
    },
    {
      "x": 9,
      "y": -25,
      "z": 2,
      "name": "Rock_Sandstone_Brick"
    },
    {
      "x": 9,
      "y": -24,
      "z": 2,
      "name": "Rock_Sandstone"
    },
    {
      "x": 9,
      "y": -23,
      "z": 2,
      "name": "Rock_Sandstone_Brick"
    },
    {
      "x": 9,
      "y": -22,
      "z": 2,
      "name": "Rock_Sandstone"
    },
    {
      "x": 9,
      "y": -21,
      "z": 2,
      "name": "Rock_Sandstone_Brick"
    },
    {
      "x": 9,
      "y": -20,
      "z": 2,
      "name": "Rock_Sandstone_Brick"
    },
    {
      "x": 9,
      "y": -19,
      "z": 2,
      "name": "Rock_Sandstone_Brick"
    },
    {
      "x": 9,
      "y": -18,
      "z": 2,
      "name": "Rock_Sandstone_Brick"
    },
    {
      "x": 9,
      "y": -17,
      "z": 2,
      "name": "Rock_Sandstone_Brick"
    },
    {
      "x": 9,
      "y": -16,
      "z": 2,
      "name": "Rock_Sandstone"
    },
    {
      "x": 9,
      "y": -15,
      "z": 2,
      "name": "Rock_Sandstone"
    },
    {
      "x": 9,
      "y": -14,
      "z": 2,
      "name": "Rock_Sandstone_Brick"
    },
    {
      "x": 9,
      "y": -13,
      "z": 2,
      "name": "Rock_Sandstone_Brick"
    },
    {
      "x": 9,
      "y": -12,
      "z": 2,
      "name": "Rock_Sandstone"
    },
    {
      "x": 9,
      "y": -11,
      "z": 2,
      "name": "Rock_Sandstone"
    },
    {
      "x": 9,
      "y": -10,
      "z": 2,
      "name": "Rock_Sandstone_Brick"
    },
    {
      "x": 9,
      "y": -9,
      "z": 2,
      "name": "Rock_Sandstone_Brick"
    },
    {
      "x": 9,
      "y": -8,
      "z": 2,
      "name": "Rock_Sandstone_Brick"
    },
    {
      "x": 9,
      "y": -7,
      "z": 2,
      "name": "Rock_Sandstone_Brick"
    },
    {
      "x": 9,
      "y": -35,
      "z": 7,
      "name": "Rock_Sandstone_Brick"
    },
    {
      "x": 9,
      "y": -34,
      "z": 7,
      "name": "Rock_Sandstone"
    },
    {
      "x": 9,
      "y": -33,
      "z": 7,
      "name": "Rock_Sandstone_Cobble"
    },
    {
      "x": 9,
      "y": -32,
      "z": 7,
      "name": "Rock_Sandstone_Brick"
    },
    {
      "x": 9,
      "y": -31,
      "z": 7,
      "name": "Rock_Sandstone_Brick"
    },
    {
      "x": 9,
      "y": -30,
      "z": 7,
      "name": "Rock_Sandstone_Brick"
    },
    {
      "x": 9,
      "y": -29,
      "z": 7,
      "name": "Rock_Sandstone_Cobble"
    },
    {
      "x": 9,
      "y": -28,
      "z": 7,
      "name": "Rock_Sandstone_Brick"
    },
    {
      "x": 9,
      "y": -27,
      "z": 7,
      "name": "Rock_Sandstone_Brick"
    },
    {
      "x": 9,
      "y": -26,
      "z": 7,
      "name": "Rock_Sandstone_Brick"
    },
    {
      "x": 9,
      "y": -25,
      "z": 7,
      "name": "Rock_Sandstone_Cobble"
    },
    {
      "x": 9,
      "y": -24,
      "z": 7,
      "name": "Rock_Sandstone_Cobble"
    },
    {
      "x": 9,
      "y": -23,
      "z": 7,
      "name": "Rock_Sandstone_Brick"
    },
    {
      "x": 9,
      "y": -22,
      "z": 7,
      "name": "Rock_Sandstone"
    },
    {
      "x": 9,
      "y": -21,
      "z": 7,
      "name": "Rock_Sandstone_Cobble"
    },
    {
      "x": 9,
      "y": -20,
      "z": 7,
      "name": "Rock_Sandstone_Brick"
    },
    {
      "x": 9,
      "y": -19,
      "z": 7,
      "name": "Rock_Sandstone_Brick"
    },
    {
      "x": 9,
      "y": -18,
      "z": 7,
      "name": "Rock_Sandstone_Brick"
    },
    {
      "x": 9,
      "y": -17,
      "z": 7,
      "name": "Rock_Sandstone_Brick"
    },
    {
      "x": 9,
      "y": -16,
      "z": 7,
      "name": "Rock_Sandstone_Brick"
    },
    {
      "x": 9,
      "y": -15,
      "z": 7,
      "name": "Rock_Sandstone"
    },
    {
      "x": 9,
      "y": -14,
      "z": 7,
      "name": "Rock_Sandstone_Brick"
    },
    {
      "x": 9,
      "y": -13,
      "z": 7,
      "name": "Rock_Sandstone_Brick"
    },
    {
      "x": 9,
      "y": -12,
      "z": 7,
      "name": "Rock_Sandstone_Brick"
    },
    {
      "x": 9,
      "y": -11,
      "z": 7,
      "name": "Rock_Sandstone_Cobble"
    },
    {
      "x": 9,
      "y": -10,
      "z": 7,
      "name": "Rock_Sandstone_Brick"
    },
    {
      "x": 9,
      "y": -35,
      "z": 8,
      "name": "Rock_Sandstone_Brick"
    },
    {
      "x": 9,
      "y": -34,
      "z": 8,
      "name": "Rock_Sandstone"
    },
    {
      "x": 9,
      "y": -33,
      "z": 8,
      "name": "Rock_Sandstone_Brick"
    },
    {
      "x": 9,
      "y": -32,
      "z": 8,
      "name": "Rock_Sandstone_Brick"
    },
    {
      "x": 9,
      "y": -31,
      "z": 8,
      "name": "Rock_Sandstone_Cobble"
    },
    {
      "x": 9,
      "y": -30,
      "z": 8,
      "name": "Rock_Sandstone"
    },
    {
      "x": 9,
      "y": -29,
      "z": 8,
      "name": "Rock_Sandstone_Cobble"
    },
    {
      "x": 9,
      "y": -28,
      "z": 8,
      "name": "Rock_Sandstone_Brick"
    },
    {
      "x": 9,
      "y": -27,
      "z": 8,
      "name": "Rock_Sandstone_Brick"
    },
    {
      "x": 9,
      "y": -26,
      "z": 8,
      "name": "Rock_Sandstone_Cobble"
    },
    {
      "x": 9,
      "y": -25,
      "z": 8,
      "name": "Rock_Sandstone_Brick"
    },
    {
      "x": 9,
      "y": -24,
      "z": 8,
      "name": "Rock_Sandstone_Brick"
    },
    {
      "x": 9,
      "y": -23,
      "z": 8,
      "name": "Rock_Sandstone_Brick"
    },
    {
      "x": 9,
      "y": -22,
      "z": 8,
      "name": "Rock_Sandstone"
    },
    {
      "x": 9,
      "y": -21,
      "z": 8,
      "name": "Rock_Sandstone_Brick"
    },
    {
      "x": 9,
      "y": -20,
      "z": 8,
      "name": "Rock_Sandstone"
    },
    {
      "x": 9,
      "y": -19,
      "z": 8,
      "name": "Rock_Sandstone_Brick"
    },
    {
      "x": 9,
      "y": -18,
      "z": 8,
      "name": "Rock_Sandstone_Brick"
    },
    {
      "x": 9,
      "y": -17,
      "z": 8,
      "name": "Rock_Sandstone_Brick"
    },
    {
      "x": 9,
      "y": -16,
      "z": 8,
      "name": "Rock_Sandstone_Brick"
    },
    {
      "x": 9,
      "y": -15,
      "z": 8,
      "name": "Rock_Sandstone_Cobble"
    },
    {
      "x": 9,
      "y": -14,
      "z": 8,
      "name": "Rock_Sandstone_Brick"
    },
    {
      "x": 9,
      "y": -13,
      "z": 8,
      "name": "Rock_Sandstone"
    },
    {
      "x": 9,
      "y": -12,
      "z": 8,
      "name": "Rock_Sandstone_Brick"
    },
    {
      "x": 9,
      "y": -11,
      "z": 8,
      "name": "Rock_Sandstone_Cobble"
    },
    {
      "x": 9,
      "y": -10,
      "z": 8,
      "name": "Rock_Sandstone_Brick"
    }
  ]
}