{
  "version": 8,
  "blockIdVersion": 11,
  "anchorX": 0,
  "anchorY": 3,
  "anchorZ": 0,
  "blocks": [
    {
      "x": -8,
      "y": 6,
      "z": 2,
      "name": "Plant_Coral_Block_Pink"
    },
    {
      "x": -8,
      "y": 7,
      "z": 2,
      "name": "Plant_Coral_Block_Pink"
    },
    {
      "x": -8,
      "y": 5,
      "z": 3,
      "name": "Plant_Coral_Block_Pink"
    },
    {
      "x": -8,
      "y": 6,
      "z": 3,
      "name": "Plant_Coral_Block_Pink"
    },
    {
      "x": -8,
      "y": 7,
      "z": 3,
      "name": "Plant_Coral_Block_Pink"
    },
    {
      "x": -8,
      "y": 6,
      "z": 4,
      "name": "Plant_Coral_Block_Pink"
    },
    {
      "x": -8,
      "y": 7,
      "z": 4,
      "name": "Plant_Coral_Block_Pink"
    },
    {
      "x": -7,
      "y": 13,
      "z": -2,
      "name": "Plant_Coral_Block_Pink"
    },
    {
      "x": -7,
      "y": 14,
      "z": -2,
      "name": "Plant_Coral_Block_Pink"
    },
    {
      "x": -7,
      "y": 12,
      "z": -1,
      "name": "Plant_Coral_Block_Pink"
    },
    {
      "x": -7,
      "y": 13,
      "z": -1,
      "name": "Plant_Coral_Block_Pink"
    },
    {
      "x": -7,
      "y": 14,
      "z": -1,
      "name": "Plant_Coral_Block_Pink"
    },
    {
      "x": -7,
      "y": 11,
      "z": 0,
      "name": "Plant_Coral_Block_Orange"
    },
    {
      "x": -7,
      "y": 12,
      "z": 0,
      "name": "Plant_Coral_Block_Orange"
    },
    {
      "x": -7,
      "y": 13,
      "z": 0,
      "name": "Plant_Coral_Block_Pink"
    },
    {
      "x": -7,
      "y": 14,
      "z": 0,
      "name": "Plant_Coral_Block_Pink"
    },
    {
      "x": -7,
      "y": 5,
      "z": 1,
      "name": "Plant_Coral_Block_Pink"
    },
    {
      "x": -7,
      "y": 6,
      "z": 1,
      "name": "Plant_Coral_Block_Pink"
    },
    {
      "x": -7,
      "y": 7,
      "z": 1,
      "name": "Plant_Coral_Block_Pink"
    },
    {
      "x": -7,
      "y": 11,
      "z": 1,
      "name": "Plant_Coral_Block_Orange"
    },
    {
      "x": -7,
      "y": 12,
      "z": 1,
      "name": "Plant_Coral_Block_Orange"
    },
    {
      "x": -7,
      "y": 4,
      "z": 2,
      "name": "Plant_Coral_Block_Pink"
    },
    {
      "x": -7,
      "y": 5,
      "z": 2,
      "name": "Plant_Coral_Block_Pink"
    },
    {
      "x": -7,
      "y": 6,
      "z": 2,
      "name": "Rock_Volcanic_Cracked_Incandescent_Bubbles"
    },
    {
      "x": -7,
      "y": 3,
      "z": 3,
      "name": "Plant_Coral_Block_Orange"
    },
    {
      "x": -7,
      "y": 4,
      "z": 3,
      "name": "Plant_Coral_Block_Pink"
    },
    {
      "x": -7,
      "y": 5,
      "z": 3,
      "name": "Plant_Coral_Block_Pink"
    },
    {
      "x": -7,
      "y": 6,
      "z": 3,
      "name": "Rock_Volcanic_Cracked_Incandescent"
    },
    {
      "x": -7,
      "y": 3,
      "z": 4,
      "name": "Plant_Coral_Block_Orange"
    },
    {
      "x": -7,
      "y": 4,
      "z": 4,
      "name": "Plant_Coral_Block_Pink"
    },
    {
      "x": -7,
      "y": 5,
      "z": 4,
      "name": "Plant_Coral_Block_Pink"
    },
    {
      "x": -7,
      "y": 6,
      "z": 4,
      "name": "Rock_Volcanic_Cracked_Incandescent_Bubbles"
    },
    {
      "x": -7,
      "y": 5,
      "z": 5,
      "name": "Plant_Coral_Block_Pink"
    },
    {
      "x": -7,
      "y": 6,
      "z": 5,
      "name": "Plant_Coral_Block_Pink"
    },
    {
      "x": -7,
      "y": 7,
      "z": 5,
      "name": "Plant_Coral_Block_Pink"
    },
    {
      "x": -6,
      "y": 6,
      "z": -5,
      "name": "Plant_Coral_Block_Pink"
    },
    {
      "x": -6,
      "y": 7,
      "z": -5,
      "name": "Plant_Coral_Block_Pink"
    },
    {
      "x": -6,
      "y": 5,
      "z": -4,
      "name": "Plant_Coral_Block_Pink"
    },
    {
      "x": -6,
      "y": 6,
      "z": -4,
      "name": "Plant_Coral_Block_Pink"
    },
    {
      "x": -6,
      "y": 7,
      "z": -4,
      "name": "Plant_Coral_Block_Pink"
    },
    {
      "x": -6,
      "y": 12,
      "z": -4,
      "name": "Plant_Coral_Block_Pink"
    },
    {
      "x": -6,
      "y": 13,
      "z": -4,
      "name": "Plant_Coral_Block_Pink"
    },
    {
      "x": -6,
      "y": 14,
      "z": -4,
      "name": "Plant_Coral_Block_Pink"
    },
    {
      "x": -6,
      "y": 6,
      "z": -3,
      "name": "Plant_Coral_Block_Pink"
    },
    {
      "x": -6,
      "y": 7,
      "z": -3,
      "name": "Plant_Coral_Block_Pink"
    },
    {
      "x": -6,
      "y": 11,
      "z": -3,
      "name": "Plant_Coral_Block_Orange"
    },
    {
      "x": -6,
      "y": 12,
      "z": -3,
      "name": "Plant_Coral_Block_Pink"
    },
    {
      "x": -6,
      "y": 13,
      "z": -3,
      "name": "Plant_Coral_Block_Pink"
    },
    {
      "x": -6,
      "y": 14,
      "z": -3,
      "name": "Plant_Coral_Block_Pink"
    },
    {
      "x": -6,
      "y": 10,
      "z": -2,
      "name": "Plant_Coral_Block_Orange"
    },
    {
      "x": -6,
      "y": 11,
      "z": -2,
      "name": "Plant_Coral_Block_Pink"
    },
    {
      "x": -6,
      "y": 12,
      "z": -2,
      "name": "Plant_Coral_Block_Pink"
    },
    {
      "x": -6,
      "y": 13,
      "z": -2,
      "name": "Rock_Volcanic_Cracked_Incandescent"
    },
    {
      "x": -6,
      "y": 3,
      "z": -1,
      "name": "Plant_Coral_Block_Pink"
    },
    {
      "x": -6,
      "y": 4,
      "z": -1,
      "name": "Plant_Coral_Block_Pink"
    },
    {
      "x": -6,
      "y": 9,
      "z": -1,
      "name": "Plant_Coral_Block_Orange"
    },
    {
      "x": -6,
      "y": 10,
      "z": -1,
      "name": "Plant_Coral_Block_Orange"
    },
    {
      "x": -6,
      "y": 11,
      "z": -1,
      "name": "Plant_Coral_Block_Pink"
    },
    {
      "x": -6,
      "y": 12,
      "z": -1,
      "name": "Plant_Coral_Block_Pink"
    },
    {
      "x": -6,
      "y": 13,
      "z": -1,
      "name": "Rock_Volcanic"
    },
    {
      "x": -6,
      "y": 4,
      "z": 0,
      "name": "Plant_Coral_Block_Orange"
    },
    {
      "x": -6,
      "y": 5,
      "z": 0,
      "name": "Plant_Coral_Block_Pink"
    },
    {
      "x": -6,
      "y": 6,
      "z": 0,
      "name": "Plant_Coral_Block_Pink"
    },
    {
      "x": -6,
      "y": 7,
      "z": 0,
      "name": "Plant_Coral_Block_Pink"
    },
    {
      "x": -6,
      "y": 8,
      "z": 0,
      "name": "Plant_Coral_Block_Pink"
    },
    {
      "x": -6,
      "y": 9,
      "z": 0,
      "name": "Plant_Coral_Block_Pink"
    },
    {
      "x": -6,
      "y": 10,
      "z": 0,
      "name": "Plant_Coral_Block_Orange"
    },
    {
      "x": -6,
      "y": 11,
      "z": 0,
      "name": "Plant_Coral_Block_Orange"
    },
    {
      "x": -6,
      "y": 12,
      "z": 0,
      "name": "Plant_Coral_Block_Pink"
    },
    {
      "x": -6,
      "y": 13,
      "z": 0,
      "name": "Plant_Coral_Block_Pink"
    },
    {
      "x": -6,
      "y": 14,
      "z": 0,
      "name": "Plant_Coral_Block_Pink"
    },
    {
      "x": -6,
      "y": 0,
      "z": 1,
      "name": "Plant_Coral_Block_Pink"
    },
    {
      "x": -6,
      "y": 1,
      "z": 1,
      "name": "Plant_Coral_Block_Pink"
    },
    {
      "x": -6,
      "y": 2,
      "z": 1,
      "name": "Plant_Coral_Block_Pink"
    },
    {
      "x": -6,
      "y": 3,
      "z": 1,
      "name": "Plant_Coral_Block_Orange"
    },
    {
      "x": -6,
      "y": 4,
      "z": 1,
      "name": "Plant_Coral_Block_Pink"
    },
    {
      "x": -6,
      "y": 5,
      "z": 1,
      "name": "Plant_Coral_Block_Pink"
    },
    {
      "x": -6,
      "y": 6,
      "z": 1,
      "name": "Rock_Volcanic_Cracked_Incandescent"
    },
    {
      "x": -6,
      "y": 8,
      "z": 1,
      "name": "Plant_Coral_Block_Pink"
    },
    {
      "x": -6,
      "y": 9,
      "z": 1,
      "name": "Plant_Coral_Block_Pink"
    },
    {
      "x": -6,
      "y": 10,
      "z": 1,
      "name": "Plant_Coral_Block_Pink"
    },
    {
      "x": -6,
      "y": 11,
      "z": 1,
      "name": "Plant_Coral_Block_Orange"
    },
    {
      "x": -6,
      "y": 12,
      "z": 1,
      "name": "Plant_Coral_Block_Pink"
    },
    {
      "x": -6,
      "y": 13,
      "z": 1,
      "name": "Plant_Coral_Block_Pink"
    },
    {
      "x": -6,
      "y": 14,
      "z": 1,
      "name": "Plant_Coral_Block_Pink"
    },
    {
      "x": -6,
      "y": 0,
      "z": 2,
      "name": "Plant_Coral_Block_Orange"
    },
    {
      "x": -6,
      "y": 1,
      "z": 2,
      "name": "Plant_Coral_Block_Orange"
    },
    {
      "x": -6,
      "y": 2,
      "z": 2,
      "name": "Plant_Coral_Block_Orange"
    },
    {
      "x": -6,
      "y": 3,
      "z": 2,
      "name": "Plant_Coral_Block_Pink"
    },
    {
      "x": -6,
      "y": 4,
      "z": 2,
      "name": "Plant_Coral_Block_Pink"
    },
    {
      "x": -6,
      "y": 5,
      "z": 2,
      "name": "Rock_Volcanic_Cracked_Incandescent"
    },
    {
      "x": -6,
      "y": 10,
      "z": 2,
      "name": "Plant_Coral_Block_Orange"
    },
    {
      "x": -6,
      "y": 11,
      "z": 2,
      "name": "Plant_Coral_Block_Orange"
    },
    {
      "x": -6,
      "y": 12,
      "z": 2,
      "name": "Plant_Coral_Block_Orange"
    },
    {
      "x": -6,
      "y": 13,
      "z": 2,
      "name": "Plant_Coral_Block_Pink"
    },
    {
      "x": -6,
      "y": 0,
      "z": 3,
      "name": "Plant_Coral_Block_Orange"
    },
    {
      "x": -6,
      "y": 1,
      "z": 3,
      "name": "Plant_Coral_Block_Orange"
    },
    {
      "x": -6,
      "y": 2,
      "z": 3,
      "name": "Plant_Coral_Block_Orange"
    },
    {
      "x": -6,
      "y": 3,
      "z": 3,
      "name": "Plant_Coral_Block_Pink"
    },
    {
      "x": -6,
      "y": 4,
      "z": 3,
      "name": "Plant_Coral_Block_Pink"
    },
    {
      "x": -6,
      "y": 5,
      "z": 3,
      "name": "Rock_Volcanic_Cracked_Incandescent"
    },
    {
      "x": -6,
      "y": 12,
      "z": 3,
      "name": "Plant_Coral_Block_Orange"
    },
    {
      "x": -6,
      "y": 13,
      "z": 3,
      "name": "Plant_Coral_Block_Pink"
    },
    {
      "x": -6,
      "y": 0,
      "z": 4,
      "name": "Plant_Coral_Block_Orange"
    },
    {
      "x": -6,
      "y": 1,
      "z": 4,
      "name": "Plant_Coral_Block_Orange"
    },
    {
      "x": -6,
      "y": 2,
      "z": 4,
      "name": "Plant_Coral_Block_Orange"
    },
    {
      "x": -6,
      "y": 3,
      "z": 4,
      "name": "Plant_Coral_Block_Pink"
    },
    {
      "x": -6,
      "y": 4,
      "z": 4,
      "name": "Plant_Coral_Block_Pink"
    },
    {
      "x": -6,
      "y": 5,
      "z": 4,
      "name": "Rock_Volcanic_Cracked_Incandescent_Bubbles"
    },
    {
      "x": -6,
      "y": 3,
      "z": 5,
      "name": "Plant_Coral_Block_Orange"
    },
    {
      "x": -6,
      "y": 4,
      "z": 5,
      "name": "Plant_Coral_Block_Pink"
    },
    {
      "x": -6,
      "y": 5,
      "z": 5,
      "name": "Plant_Coral_Block_Pink"
    },
    {
      "x": -6,
      "y": 6,
      "z": 5,
      "name": "Rock_Volcanic_Cracked_Incandescent_Bubbles"
    },
    {
      "x": -6,
      "y": 6,
      "z": 6,
      "name": "Plant_Coral_Block_Pink"
    },
    {
      "x": -6,
      "y": 7,
      "z": 6,
      "name": "Plant_Coral_Block_Pink"
    },
    {
      "x": -5,
      "y": 5,
      "z": -6,
      "name": "Plant_Coral_Block_Pink"
    },
    {
      "x": -5,
      "y": 6,
      "z": -6,
      "name": "Plant_Coral_Block_Pink"
    },
    {
      "x": -5,
      "y": 7,
      "z": -6,
      "name": "Plant_Coral_Block_Pink"
    },
    {
      "x": -5,
      "y": 4,
      "z": -5,
      "name": "Plant_Coral_Block_Pink"
    },
    {
      "x": -5,
      "y": 5,
      "z": -5,
      "name": "Plant_Coral_Block_Pink"
    },
    {
      "x": -5,
      "y": 6,
      "z": -5,
      "name": "Rock_Volcanic_Cracked_Incandescent_Bubbles"
    },
    {
      "x": -5,
      "y": 12,
      "z": -5,
      "name": "Plant_Coral_Block_Pink"
    },
    {
      "x": -5,
      "y": 13,
      "z": -5,
      "name": "Plant_Coral_Block_Pink"
    },
    {
      "x": -5,
      "y": 14,
      "z": -5,
      "name": "Plant_Coral_Block_Pink"
    },
    {
      "x": -5,
      "y": 3,
      "z": -4,
      "name": "Plant_Coral_Block_Orange"
    },
    {
      "x": -5,
      "y": 4,
      "z": -4,
      "name": "Plant_Coral_Block_Pink"
    },
    {
      "x": -5,
      "y": 5,
      "z": -4,
      "name": "Plant_Coral_Block_Pink"
    },
    {
      "x": -5,
      "y": 6,
      "z": -4,
      "name": "Rock_Volcanic_Cracked_Incandescent"
    },
    {
      "x": -5,
      "y": 8,
      "z": -4,
      "name": "Plant_Coral_Block_Pink"
    },
    {
      "x": -5,
      "y": 9,
      "z": -4,
      "name": "Plant_Coral_Block_Pink"
    },
    {
      "x": -5,
      "y": 10,
      "z": -4,
      "name": "Plant_Coral_Block_Pink"
    },
    {
      "x": -5,
      "y": 11,
      "z": -4,
      "name": "Plant_Coral_Block_Pink"
    },
    {
      "x": -5,
      "y": 12,
      "z": -4,
      "name": "Plant_Coral_Block_Pink"
    },
    {
      "x": -5,
      "y": 13,
      "z": -4,
      "name": "Rock_Volcanic_Cracked_Lava"
    },
    {
      "x": -5,
      "y": 3,
      "z": -3,
      "name": "Plant_Coral_Block_Pink"
    },
    {
      "x": -5,
      "y": 4,
      "z": -3,
      "name": "Plant_Coral_Block_Orange"
    },
    {
      "x": -5,
      "y": 5,
      "z": -3,
      "name": "Plant_Coral_Block_Pink"
    },
    {
      "x": -5,
      "y": 6,
      "z": -3,
      "name": "Plant_Coral_Block_Pink"
    },
    {
      "x": -5,
      "y": 7,
      "z": -3,
      "name": "Plant_Coral_Block_Pink"
    },
    {
      "x": -5,
      "y": 8,
      "z": -3,
      "name": "Plant_Coral_Block_Pink"
    },
    {
      "x": -5,
      "y": 9,
      "z": -3,
      "name": "Plant_Coral_Block_Pink"
    },
    {
      "x": -5,
      "y": 10,
      "z": -3,
      "name": "Plant_Coral_Block_Pink"
    },
    {
      "x": -5,
      "y": 11,
      "z": -3,
      "name": "Plant_Coral_Block_Pink"
    },
    {
      "x": -5,
      "y": 12,
      "z": -3,
      "name": "Plant_Coral_Block_Pink"
    },
    {
      "x": -5,
      "y": 13,
      "z": -3,
      "name": "Rock_Volcanic"
    },
    {
      "x": -5,
      "y": 0,
      "z": -2,
      "name": "Plant_Coral_Block_Pink"
    },
    {
      "x": -5,
      "y": 1,
      "z": -2,
      "name": "Plant_Coral_Block_Pink"
    },
    {
      "x": -5,
      "y": 2,
      "z": -2,
      "name": "Plant_Coral_Block_Pink"
    },
    {
      "x": -5,
      "y": 3,
      "z": -2,
      "name": "Plant_Coral_Block_Pink"
    },
    {
      "x": -5,
      "y": 4,
      "z": -2,
      "name": "Plant_Coral_Block_Pink"
    },
    {
      "x": -5,
      "y": 5,
      "z": -2,
      "name": "Plant_Coral_Block_Orange"
    },
    {
      "x": -5,
      "y": 6,
      "z": -2,
      "name": "Plant_Coral_Block_Pink"
    },
    {
      "x": -5,
      "y": 7,
      "z": -2,
      "name": "Plant_Coral_Block_Pink"
    },
    {
      "x": -5,
      "y": 8,
      "z": -2,
      "name": "Plant_Coral_Block_Pink"
    },
    {
      "x": -5,
      "y": 9,
      "z": -2,
      "name": "Plant_Coral_Block_Orange"
    },
    {
      "x": -5,
      "y": 10,
      "z": -2,
      "name": "Plant_Coral_Block_Orange"
    },
    {
      "x": -5,
      "y": 11,
      "z": -2,
      "name": "Plant_Coral_Block_Pink"
    },
    {
      "x": -5,
      "y": 12,
      "z": -2,
      "name": "Plant_Coral_Block_Pink"
    },
    {
      "x": -5,
      "y": 13,
      "z": -2,
      "name": "Rock_Volcanic"
    },
    {
      "x": -5,
      "y": 3,
      "z": -1,
      "name": "Plant_Coral_Block_Pink"
    },
    {
      "x": -5,
      "y": 4,
      "z": -1,
      "name": "Plant_Coral_Block_Orange"
    },
    {
      "x": -5,
      "y": 5,
      "z": -1,
      "name": "Plant_Coral_Block_Pink"
    },
    {
      "x": -5,
      "y": 6,
      "z": -1,
      "name": "Plant_Coral_Block_Pink"
    },
    {
      "x": -5,
      "y": 7,
      "z": -1,
      "name": "Plant_Coral_Block_Pink"
    },
    {
      "x": -5,
      "y": 8,
      "z": -1,
      "name": "Plant_Coral_Block_Orange"
    },
    {
      "x": -5,
      "y": 9,
      "z": -1,
      "name": "Plant_Coral_Block_Orange"
    },
    {
      "x": -5,
      "y": 10,
      "z": -1,
      "name": "Plant_Coral_Block_Orange"
    },
    {
      "x": -5,
      "y": 11,
      "z": -1,
      "name": "Plant_Coral_Block_Pink"
    },
    {
      "x": -5,
      "y": 12,
      "z": -1,
      "name": "Plant_Coral_Block_Pink"
    },
    {
      "x": -5,
      "y": 13,
      "z": -1,
      "name": "Rock_Volcanic_Cracked_Lava"
    },
    {
      "x": -5,
      "y": 4,
      "z": 0,
      "name": "Plant_Coral_Block_Pink"
    },
    {
      "x": -5,
      "y": 5,
      "z": 0,
      "name": "Plant_Coral_Block_Pink"
    },
    {
      "x": -5,
      "y": 6,
      "z": 0,
      "name": "Plant_Coral_Block_Pink"
    },
    {
      "x": -5,
      "y": 7,
      "z": 0,
      "name": "Plant_Coral_Block_Pink"
    },
    {
      "x": -5,
      "y": 8,
      "z": 0,
      "name": "Plant_Coral_Block_Pink"
    },
    {
      "x": -5,
      "y": 9,
      "z": 0,
      "name": "Plant_Coral_Block_Orange"
    },
    {
      "x": -5,
      "y": 10,
      "z": 0,
      "name": "Plant_Coral_Block_Orange"
    },
    {
      "x": -5,
      "y": 11,
      "z": 0,
      "name": "Plant_Coral_Block_Pink"
    },
    {
      "x": -5,
      "y": 12,
      "z": 0,
      "name": "Plant_Coral_Block_Pink"
    },
    {
      "x": -5,
      "y": 13,
      "z": 0,
      "name": "Rock_Volcanic_Cracked_Lava"
    },
    {
      "x": -5,
      "y": 0,
      "z": 1,
      "name": "Plant_Coral_Block_Orange"
    },
    {
      "x": -5,
      "y": 1,
      "z": 1,
      "name": "Plant_Coral_Block_Orange"
    },
    {
      "x": -5,
      "y": 2,
      "z": 1,
      "name": "Plant_Coral_Block_Orange"
    },
    {
      "x": -5,
      "y": 3,
      "z": 1,
      "name": "Plant_Coral_Block_Pink"
    },
    {
      "x": -5,
      "y": 4,
      "z": 1,
      "name": "Plant_Coral_Block_Pink"
    },
    {
      "x": -5,
      "y": 5,
      "z": 1,
      "name": "Plant_Coral_Block_Pink"
    },
    {
      "x": -5,
      "y": 6,
      "z": 1,
      "name": "Plant_Coral_Block_Pink"
    },
    {
      "x": -5,
      "y": 7,
      "z": 1,
      "name": "Plant_Coral_Block_Pink"
    },
    {
      "x": -5,
      "y": 8,
      "z": 1,
      "name": "Plant_Coral_Block_Pink"
    },
    {
      "x": -5,
      "y": 9,
      "z": 1,
      "name": "Plant_Coral_Block_Pink"
    },
    {
      "x": -5,
      "y": 10,
      "z": 1,
      "name": "Plant_Coral_Block_Orange"
    },
    {
      "x": -5,
      "y": 11,
      "z": 1,
      "name": "Plant_Coral_Block_Pink"
    },
    {
      "x": -5,
      "y": 12,
      "z": 1,
      "name": "Plant_Coral_Block_Pink"
    },
    {
      "x": -5,
      "y": 13,
      "z": 1,
      "name": "Rock_Volcanic"
    },
    {
      "x": -5,
      "y": 0,
      "z": 2,
      "name": "Plant_Coral_Block_Pink"
    },
    {
      "x": -5,
      "y": 1,
      "z": 2,
      "name": "Plant_Coral_Block_Pink"
    },
    {
      "x": -5,
      "y": 2,
      "z": 2,
      "name": "Plant_Coral_Block_Pink"
    },
    {
      "x": -5,
      "y": 3,
      "z": 2,
      "name": "Plant_Coral_Block_Pink"
    },
    {
      "x": -5,
      "y": 4,
      "z": 2,
      "name": "Rock_Volcanic_Cracked_Incandescent"
    },
    {
      "x": -5,
      "y": 8,
      "z": 2,
      "name": "Plant_Coral_Block_Pink"
    },
    {
      "x": -5,
      "y": 9,
      "z": 2,
      "name": "Plant_Coral_Block_Pink"
    },
    {
      "x": -5,
      "y": 10,
      "z": 2,
      "name": "Plant_Coral_Block_Pink"
    },
    {
      "x": -5,
      "y": 11,
      "z": 2,
      "name": "Plant_Coral_Block_Pink"
    },
    {
      "x": -5,
      "y": 12,
      "z": 2,
      "name": "Plant_Coral_Block_Pink"
    },
    {
      "x": -5,
      "y": 13,
      "z": 2,
      "name": "Plant_Coral_Block_Pink"
    },
    {
      "x": -5,
      "y": 14,
      "z": 2,
      "name": "Plant_Coral_Block_Pink"
    },
    {
      "x": -5,
      "y": 0,
      "z": 3,
      "name": "Plant_Coral_Block_Pink"
    },
    {
      "x": -5,
      "y": 1,
      "z": 3,
      "name": "Plant_Coral_Block_Pink"
    },
    {
      "x": -5,
      "y": 2,
      "z": 3,
      "name": "Plant_Coral_Block_Pink"
    },
    {
      "x": -5,
      "y": 3,
      "z": 3,
      "name": "Plant_Coral_Block_Pink"
    },
    {
      "x": -5,
      "y": 4,
      "z": 3,
      "name": "Rock_Volcanic_Cracked_Incandescent"
    },
    {
      "x": -5,
      "y": 9,
      "z": 3,
      "name": "Plant_Coral_Block_Pink"
    },
    {
      "x": -5,
      "y": 10,
      "z": 3,
      "name": "Plant_Coral_Block_Orange"
    },
    {
      "x": -5,
      "y": 11,
      "z": 3,
      "name": "Plant_Coral_Block_Orange"
    },
    {
      "x": -5,
      "y": 12,
      "z": 3,
      "name": "Plant_Coral_Block_Pink"
    },
    {
      "x": -5,
      "y": 13,
      "z": 3,
      "name": "Plant_Coral_Block_Pink"
    },
    {
      "x": -5,
      "y": 14,
      "z": 3,
      "name": "Plant_Coral_Block_Pink"
    },
    {
      "x": -5,
      "y": 0,
      "z": 4,
      "name": "Plant_Coral_Block_Orange"
    },
    {
      "x": -5,
      "y": 1,
      "z": 4,
      "name": "Plant_Coral_Block_Orange"
    },
    {
      "x": -5,
      "y": 2,
      "z": 4,
      "name": "Plant_Coral_Block_Orange"
    },
    {
      "x": -5,
      "y": 3,
      "z": 4,
      "name": "Plant_Coral_Block_Pink"
    },
    {
      "x": -5,
      "y": 4,
      "z": 4,
      "name": "Plant_Coral_Block_Pink"
    },
    {
      "x": -5,
      "y": 5,
      "z": 4,
      "name": "Rock_Volcanic_Cracked_Incandescent"
    },
    {
      "x": -5,
      "y": 12,
      "z": 4,
      "name": "Plant_Coral_Block_Orange"
    },
    {
      "x": -5,
      "y": 13,
      "z": 4,
      "name": "Plant_Coral_Block_Pink"
    },
    {
      "x": -5,
      "y": 14,
      "z": 4,
      "name": "Plant_Coral_Block_Pink"
    },
    {
      "x": -5,
      "y": 3,
      "z": 5,
      "name": "Plant_Coral_Block_Orange"
    },
    {
      "x": -5,
      "y": 4,
      "z": 5,
      "name": "Plant_Coral_Block_Pink"
    },
    {
      "x": -5,
      "y": 5,
      "z": 5,
      "name": "Plant_Coral_Block_Pink"
    },
    {
      "x": -5,
      "y": 6,
      "z": 5,
      "name": "Rock_Volcanic_Cracked_Incandescent_Bubbles"
    },
    {
      "x": -5,
      "y": 5,
      "z": 6,
      "name": "Plant_Coral_Block_Pink"
    },
    {
      "x": -5,
      "y": 6,
      "z": 6,
      "name": "Plant_Coral_Block_Pink"
    },
    {
      "x": -5,
      "y": 7,
      "z": 6,
      "name": "Plant_Coral_Block_Pink"
    },
    {
      "x": -4,
      "y": 6,
      "z": -7,
      "name": "Plant_Coral_Block_Pink"
    },
    {
      "x": -4,
      "y": 7,
      "z": -7,
      "name": "Plant_Coral_Block_Pink"
    },
    {
      "x": -4,
      "y": 4,
      "z": -6,
      "name": "Plant_Coral_Block_Pink"
    },
    {
      "x": -4,
      "y": 5,
      "z": -6,
      "name": "Plant_Coral_Block_Pink"
    },
    {
      "x": -4,
      "y": 6,
      "z": -6,
      "name": "Rock_Volcanic_Cracked_Incandescent_Bubbles"
    },
    {
      "x": -4,
      "y": 13,
      "z": -6,
      "name": "Plant_Coral_Block_Pink"
    },
    {
      "x": -4,
      "y": 14,
      "z": -6,
      "name": "Plant_Coral_Block_Pink"
    },
    {
      "x": -4,
      "y": 3,
      "z": -5,
      "name": "Plant_Coral_Block_Orange"
    },
    {
      "x": -4,
      "y": 4,
      "z": -5,
      "name": "Plant_Coral_Block_Pink"
    },
    {
      "x": -4,
      "y": 5,
      "z": -5,
      "name": "Plant_Coral_Block_Pink"
    },
    {
      "x": -4,
      "y": 6,
      "z": -5,
      "name": "Rock_Volcanic_Cracked_Incandescent_Bubbles"
    },
    {
      "x": -4,
      "y": 10,
      "z": -5,
      "name": "Plant_Coral_Block_Orange"
    },
    {
      "x": -4,
      "y": 11,
      "z": -5,
      "name": "Plant_Coral_Block_Pink"
    },
    {
      "x": -4,
      "y": 12,
      "z": -5,
      "name": "Plant_Coral_Block_Pink"
    },
    {
      "x": -4,
      "y": 13,
      "z": -5,
      "name": "Rock_Volcanic"
    },
    {
      "x": -4,
      "y": 3,
      "z": -4,
      "name": "Plant_Coral_Block_Pink"
    },
    {
      "x": -4,
      "y": 4,
      "z": -4,
      "name": "Plant_Coral_Block_Orange"
    },
    {
      "x": -4,
      "y": 5,
      "z": -4,
      "name": "Plant_Coral_Block_Pink"
    },
    {
      "x": -4,
      "y": 6,
      "z": -4,
      "name": "Plant_Coral_Block_Pink"
    },
    {
      "x": -4,
      "y": 7,
      "z": -4,
      "name": "Plant_Coral_Block_Pink"
    },
    {
      "x": -4,
      "y": 8,
      "z": -4,
      "name": "Plant_Coral_Block_Pink"
    },
    {
      "x": -4,
      "y": 9,
      "z": -4,
      "name": "Plant_Coral_Block_Pink"
    },
    {
      "x": -4,
      "y": 10,
      "z": -4,
      "name": "Plant_Coral_Block_Pink"
    },
    {
      "x": -4,
      "y": 11,
      "z": -4,
      "name": "Plant_Coral_Block_Pink"
    },
    {
      "x": -4,
      "y": 12,
      "z": -4,
      "name": "Rock_Volcanic_Cracked_Incandescent"
    },
    {
      "x": -4,
      "y": 0,
      "z": -3,
      "name": "Plant_Coral_Block_Pink"
    },
    {
      "x": -4,
      "y": 1,
      "z": -3,
      "name": "Plant_Coral_Block_Pink"
    },
    {
      "x": -4,
      "y": 2,
      "z": -3,
      "name": "Plant_Coral_Block_Pink"
    },
    {
      "x": -4,
      "y": 3,
      "z": -3,
      "name": "Plant_Coral_Block_Pink"
    },
    {
      "x": -4,
      "y": 4,
      "z": -3,
      "name": "Plant_Coral_Block_Orange"
    },
    {
      "x": -4,
      "y": 5,
      "z": -3,
      "name": "Plant_Coral_Block_Orange"
    },
    {
      "x": -4,
      "y": 6,
      "z": -3,
      "name": "Plant_Coral_Block_Pink"
    },
    {
      "x": -4,
      "y": 7,
      "z": -3,
      "name": "Plant_Coral_Block_Pink"
    },
    {
      "x": -4,
      "y": 8,
      "z": -3,
      "name": "Plant_Coral_Block_Pink"
    },
    {
      "x": -4,
      "y": 9,
      "z": -3,
      "name": "Plant_Coral_Block_Pink"
    },
    {
      "x": -4,
      "y": 10,
      "z": -3,
      "name": "Plant_Coral_Block_Pink"
    },
    {
      "x": -4,
      "y": 11,
      "z": -3,
      "name": "Plant_Coral_Block_Pink"
    },
    {
      "x": -4,
      "y": 12,
      "z": -3,
      "name": "Rock_Volcanic_Cracked_Incandescent"
    },
    {
      "x": -4,
      "y": 0,
      "z": -2,
      "name": "Plant_Coral_Block_Pink"
    },
    {
      "x": -4,
      "y": 1,
      "z": -2,
      "name": "Plant_Coral_Block_Pink"
    },
    {
      "x": -4,
      "y": 2,
      "z": -2,
      "name": "Plant_Coral_Block_Pink"
    },
    {
      "x": -4,
      "y": 3,
      "z": -2,
      "name": "Plant_Coral_Block_Pink"
    },
    {
      "x": -4,
      "y": 4,
      "z": -2,
      "name": "Plant_Coral_Block_Orange"
    },
    {
      "x": -4,
      "y": 5,
      "z": -2,
      "name": "Plant_Coral_Block_Orange"
    },
    {
      "x": -4,
      "y": 6,
      "z": -2,
      "name": "Plant_Coral_Block_Orange"
    },
    {
      "x": -4,
      "y": 7,
      "z": -2,
      "name": "Plant_Coral_Block_Pink"
    },
    {
      "x": -4,
      "y": 8,
      "z": -2,
      "name": "Plant_Coral_Block_Orange"
    },
    {
      "x": -4,
      "y": 9,
      "z": -2,
      "name": "Plant_Coral_Block_Orange"
    },
    {
      "x": -4,
      "y": 10,
      "z": -2,
      "name": "Plant_Coral_Block_Pink"
    },
    {
      "x": -4,
      "y": 11,
      "z": -2,
      "name": "Plant_Coral_Block_Pink"
    },
    {
      "x": -4,
      "y": 12,
      "z": -2,
      "name": "Rock_Volcanic_Cracked_Lava"
    },
    {
      "x": -4,
      "y": 3,
      "z": -1,
      "name": "Plant_Coral_Block_Orange"
    },
    {
      "x": -4,
      "y": 4,
      "z": -1,
      "name": "Plant_Coral_Block_Orange"
    },
    {
      "x": -4,
      "y": 5,
      "z": -1,
      "name": "Plant_Coral_Block_Pink"
    },
    {
      "x": -4,
      "y": 6,
      "z": -1,
      "name": "Plant_Coral_Block_Pink"
    },
    {
      "x": -4,
      "y": 7,
      "z": -1,
      "name": "Plant_Coral_Block_Orange"
    },
    {
      "x": -4,
      "y": 8,
      "z": -1,
      "name": "Plant_Coral_Block_Orange"
    },
    {
      "x": -4,
      "y": 9,
      "z": -1,
      "name": "Plant_Coral_Block_Orange"
    },
    {
      "x": -4,
      "y": 10,
      "z": -1,
      "name": "Plant_Coral_Block_Pink"
    },
    {
      "x": -4,
      "y": 11,
      "z": -1,
      "name": "Plant_Coral_Block_Pink"
    },
    {
      "x": -4,
      "y": 12,
      "z": -1,
      "name": "Rock_Volcanic_Cracked_Incandescent"
    },
    {
      "x": -4,
      "y": 4,
      "z": 0,
      "name": "Plant_Coral_Block_Pink"
    },
    {
      "x": -4,
      "y": 5,
      "z": 0,
      "name": "Plant_Coral_Block_Pink"
    },
    {
      "x": -4,
      "y": 6,
      "z": 0,
      "name": "Plant_Coral_Block_Pink"
    },
    {
      "x": -4,
      "y": 7,
      "z": 0,
      "name": "Plant_Coral_Block_Pink"
    },
    {
      "x": -4,
      "y": 8,
      "z": 0,
      "name": "Plant_Coral_Block_Orange"
    },
    {
      "x": -4,
      "y": 9,
      "z": 0,
      "name": "Plant_Coral_Block_Orange"
    },
    {
      "x": -4,
      "y": 10,
      "z": 0,
      "name": "Plant_Coral_Block_Pink"
    },
    {
      "x": -4,
      "y": 11,
      "z": 0,
      "name": "Plant_Coral_Block_Pink"
    },
    {
      "x": -4,
      "y": 12,
      "z": 0,
      "name": "Rock_Volcanic"
    },
    {
      "x": -4,
      "y": 0,
      "z": 1,
      "name": "Plant_Coral_Block_Orange"
    },
    {
      "x": -4,
      "y": 1,
      "z": 1,
      "name": "Plant_Coral_Block_Orange"
    },
    {
      "x": -4,
      "y": 2,
      "z": 1,
      "name": "Plant_Coral_Block_Orange"
    },
    {
      "x": -4,
      "y": 3,
      "z": 1,
      "name": "Plant_Coral_Block_Pink"
    },
    {
      "x": -4,
      "y": 4,
      "z": 1,
      "name": "Plant_Coral_Block_Pink"
    },
    {
      "x": -4,
      "y": 5,
      "z": 1,
      "name": "Plant_Coral_Block_Pink"
    },
    {
      "x": -4,
      "y": 6,
      "z": 1,
      "name": "Plant_Coral_Block_Pink"
    },
    {
      "x": -4,
      "y": 7,
      "z": 1,
      "name": "Plant_Coral_Block_Pink"
    },
    {
      "x": -4,
      "y": 8,
      "z": 1,
      "name": "Plant_Coral_Block_Pink"
    },
    {
      "x": -4,
      "y": 9,
      "z": 1,
      "name": "Plant_Coral_Block_Orange"
    },
    {
      "x": -4,
      "y": 10,
      "z": 1,
      "name": "Plant_Coral_Block_Pink"
    },
    {
      "x": -4,
      "y": 11,
      "z": 1,
      "name": "Plant_Coral_Block_Pink"
    },
    {
      "x": -4,
      "y": 12,
      "z": 1,
      "name": "Plant_Coral_Block_Pink"
    },
    {
      "x": -4,
      "y": 13,
      "z": 1,
      "name": "Rock_Volcanic_Cracked_Incandescent"
    },
    {
      "x": -4,
      "y": 0,
      "z": 2,
      "name": "Plant_Coral_Block_Pink"
    },
    {
      "x": -4,
      "y": 1,
      "z": 2,
      "name": "Plant_Coral_Block_Pink"
    },
    {
      "x": -4,
      "y": 2,
      "z": 2,
      "name": "Plant_Coral_Block_Pink"
    },
    {
      "x": -4,
      "y": 3,
      "z": 2,
      "name": "Plant_Coral_Block_Pink"
    },
    {
      "x": -4,
      "y": 4,
      "z": 2,
      "name": "Rock_Volcanic_Cracked_Incandescent_Bubbles"
    },
    {
      "x": -4,
      "y": 7,
      "z": 2,
      "name": "Plant_Coral_Block_Pink"
    },
    {
      "x": -4,
      "y": 8,
      "z": 2,
      "name": "Plant_Coral_Block_Pink"
    },
    {
      "x": -4,
      "y": 9,
      "z": 2,
      "name": "Plant_Coral_Block_Pink"
    },
    {
      "x": -4,
      "y": 10,
      "z": 2,
      "name": "Plant_Coral_Block_Pink"
    },
    {
      "x": -4,
      "y": 11,
      "z": 2,
      "name": "Plant_Coral_Block_Pink"
    },
    {
      "x": -4,
      "y": 12,
      "z": 2,
      "name": "Plant_Coral_Block_Pink"
    },
    {
      "x": -4,
      "y": 13,
      "z": 2,
      "name": "Rock_Volcanic_Cracked_Incandescent"
    },
    {
      "x": -4,
      "y": 0,
      "z": 3,
      "name": "Plant_Coral_Block_Pink"
    },
    {
      "x": -4,
      "y": 1,
      "z": 3,
      "name": "Plant_Coral_Block_Pink"
    },
    {
      "x": -4,
      "y": 2,
      "z": 3,
      "name": "Plant_Coral_Block_Pink"
    },
    {
      "x": -4,
      "y": 3,
      "z": 3,
      "name": "Plant_Coral_Block_Pink"
    },
    {
      "x": -4,
      "y": 4,
      "z": 3,
      "name": "Rock_Volcanic_Cracked_Incandescent"
    },
    {
      "x": -4,
      "y": 7,
      "z": 3,
      "name": "Plant_Coral_Block_Pink"
    },
    {
      "x": -4,
      "y": 8,
      "z": 3,
      "name": "Plant_Coral_Block_Pink"
    },
    {
      "x": -4,
      "y": 9,
      "z": 3,
      "name": "Plant_Coral_Block_Pink"
    },
    {
      "x": -4,
      "y": 10,
      "z": 3,
      "name": "Plant_Coral_Block_Orange"
    },
    {
      "x": -4,
      "y": 11,
      "z": 3,
      "name": "Plant_Coral_Block_Pink"
    },
    {
      "x": -4,
      "y": 12,
      "z": 3,
      "name": "Plant_Coral_Block_Pink"
    },
    {
      "x": -4,
      "y": 13,
      "z": 3,
      "name": "Rock_Volcanic"
    },
    {
      "x": -4,
      "y": 0,
      "z": 4,
      "name": "Plant_Coral_Block_Pink"
    },
    {
      "x": -4,
      "y": 1,
      "z": 4,
      "name": "Plant_Coral_Block_Pink"
    },
    {
      "x": -4,
      "y": 2,
      "z": 4,
      "name": "Plant_Coral_Block_Pink"
    },
    {
      "x": -4,
      "y": 3,
      "z": 4,
      "name": "Plant_Coral_Block_Pink"
    },
    {
      "x": -4,
      "y": 4,
      "z": 4,
      "name": "Rock_Volcanic_Cracked_Incandescent_Bubbles"
    },
    {
      "x": -4,
      "y": 8,
      "z": 4,
      "name": "Plant_Coral_Block_Pink"
    },
    {
      "x": -4,
      "y": 9,
      "z": 4,
      "name": "Plant_Coral_Block_Pink"
    },
    {
      "x": -4,
      "y": 10,
      "z": 4,
      "name": "Plant_Coral_Block_Pink"
    },
    {
      "x": -4,
      "y": 11,
      "z": 4,
      "name": "Plant_Coral_Block_Orange"
    },
    {
      "x": -4,
      "y": 12,
      "z": 4,
      "name": "Plant_Coral_Block_Pink"
    },
    {
      "x": -4,
      "y": 13,
      "z": 4,
      "name": "Plant_Coral_Block_Pink"
    },
    {
      "x": -4,
      "y": 14,
      "z": 4,
      "name": "Plant_Coral_Block_Pink"
    },
    {
      "x": -4,
      "y": 4,
      "z": 5,
      "name": "Plant_Coral_Block_Pink"
    },
    {
      "x": -4,
      "y": 5,
      "z": 5,
      "name": "Plant_Coral_Block_Pink"
    },
    {
      "x": -4,
      "y": 6,
      "z": 5,
      "name": "Rock_Volcanic_Cracked_Incandescent"
    },
    {
      "x": -4,
      "y": 11,
      "z": 5,
      "name": "Plant_Coral_Block_Orange"
    },
    {
      "x": -4,
      "y": 12,
      "z": 5,
      "name": "Plant_Coral_Block_Pink"
    },
    {
      "x": -4,
      "y": 13,
      "z": 5,
      "name": "Plant_Coral_Block_Pink"
    },
    {
      "x": -4,
      "y": 14,
      "z": 5,
      "name": "Plant_Coral_Block_Pink"
    },
    {
      "x": -4,
      "y": 6,
      "z": 6,
      "name": "Plant_Coral_Block_Pink"
    },
    {
      "x": -4,
      "y": 7,
      "z": 6,
      "name": "Plant_Coral_Block_Pink"
    },
    {
      "x": -3,
      "y": 5,
      "z": -7,
      "name": "Plant_Coral_Block_Pink"
    },
    {
      "x": -3,
      "y": 6,
      "z": -7,
      "name": "Plant_Coral_Block_Pink"
    },
    {
      "x": -3,
      "y": 7,
      "z": -7,
      "name": "Plant_Coral_Block_Pink"
    },
    {
      "x": -3,
      "y": 3,
      "z": -6,
      "name": "Plant_Coral_Block_Orange"
    },
    {
      "x": -3,
      "y": 4,
      "z": -6,
      "name": "Plant_Coral_Block_Pink"
    },
    {
      "x": -3,
      "y": 5,
      "z": -6,
      "name": "Plant_Coral_Block_Pink"
    },
    {
      "x": -3,
      "y": 6,
      "z": -6,
      "name": "Rock_Volcanic_Cracked_Incandescent_Bubbles"
    },
    {
      "x": -3,
      "y": 14,
      "z": -6,
      "name": "Plant_Coral_Block_Pink"
    },
    {
      "x": -3,
      "y": 3,
      "z": -5,
      "name": "Plant_Coral_Block_Orange"
    },
    {
      "x": -3,
      "y": 4,
      "z": -5,
      "name": "Plant_Coral_Block_Orange"
    },
    {
      "x": -3,
      "y": 5,
      "z": -5,
      "name": "Plant_Coral_Block_Pink"
    },
    {
      "x": -3,
      "y": 6,
      "z": -5,
      "name": "Plant_Coral_Block_Pink"
    },
    {
      "x": -3,
      "y": 7,
      "z": -5,
      "name": "Plant_Coral_Block_Pink"
    },
    {
      "x": -3,
      "y": 8,
      "z": -5,
      "name": "Plant_Coral_Block_Pink"
    },
    {
      "x": -3,
      "y": 9,
      "z": -5,
      "name": "Plant_Coral_Block_Pink"
    },
    {
      "x": -3,
      "y": 10,
      "z": -5,
      "name": "Plant_Coral_Block_Orange"
    },
    {
      "x": -3,
      "y": 11,
      "z": -5,
      "name": "Plant_Coral_Block_Pink"
    },
    {
      "x": -3,
      "y": 12,
      "z": -5,
      "name": "Plant_Coral_Block_Pink"
    },
    {
      "x": -3,
      "y": 13,
      "z": -5,
      "name": "Plant_Coral_Block_Pink"
    },
    {
      "x": -3,
      "y": 0,
      "z": -4,
      "name": "Plant_Coral_Block_Pink"
    },
    {
      "x": -3,
      "y": 1,
      "z": -4,
      "name": "Plant_Coral_Block_Pink"
    },
    {
      "x": -3,
      "y": 2,
      "z": -4,
      "name": "Plant_Coral_Block_Pink"
    },
    {
      "x": -3,
      "y": 3,
      "z": -4,
      "name": "Plant_Coral_Block_Orange"
    },
    {
      "x": -3,
      "y": 4,
      "z": -4,
      "name": "Plant_Coral_Block_Orange"
    },
    {
      "x": -3,
      "y": 5,
      "z": -4,
      "name": "Plant_Coral_Block_Orange"
    },
    {
      "x": -3,
      "y": 6,
      "z": -4,
      "name": "Plant_Coral_Block_Pink"
    },
    {
      "x": -3,
      "y": 7,
      "z": -4,
      "name": "Plant_Coral_Block_Pink"
    },
    {
      "x": -3,
      "y": 8,
      "z": -4,
      "name": "Plant_Coral_Block_Pink"
    },
    {
      "x": -3,
      "y": 9,
      "z": -4,
      "name": "Plant_Coral_Block_Orange"
    },
    {
      "x": -3,
      "y": 10,
      "z": -4,
      "name": "Plant_Coral_Block_Pink"
    },
    {
      "x": -3,
      "y": 11,
      "z": -4,
      "name": "Plant_Coral_Block_Pink"
    },
    {
      "x": -3,
      "y": 12,
      "z": -4,
      "name": "Rock_Volcanic_Cracked_Incandescent"
    },
    {
      "x": -3,
      "y": 0,
      "z": -3,
      "name": "Plant_Coral_Block_Pink"
    },
    {
      "x": -3,
      "y": 1,
      "z": -3,
      "name": "Plant_Coral_Block_Pink"
    },
    {
      "x": -3,
      "y": 2,
      "z": -3,
      "name": "Plant_Coral_Block_Pink"
    },
    {
      "x": -3,
      "y": 3,
      "z": -3,
      "name": "Plant_Coral_Block_Orange"
    },
    {
      "x": -3,
      "y": 4,
      "z": -3,
      "name": "Plant_Coral_Block_Orange"
    },
    {
      "x": -3,
      "y": 5,
      "z": -3,
      "name": "Plant_Coral_Block_Orange"
    },
    {
      "x": -3,
      "y": 6,
      "z": -3,
      "name": "Plant_Coral_Block_Pink"
    },
    {
      "x": -3,
      "y": 7,
      "z": -3,
      "name": "Plant_Coral_Block_Pink"
    },
    {
      "x": -3,
      "y": 8,
      "z": -3,
      "name": "Plant_Coral_Block_Pink"
    },
    {
      "x": -3,
      "y": 9,
      "z": -3,
      "name": "Plant_Coral_Block_Pink"
    },
    {
      "x": -3,
      "y": 10,
      "z": -3,
      "name": "Plant_Coral_Block_Pink"
    },
    {
      "x": -3,
      "y": 11,
      "z": -3,
      "name": "Plant_Coral_Block_Pink"
    },
    {
      "x": -3,
      "y": 12,
      "z": -3,
      "name": "Rock_Volcanic_Cracked_Incandescent"
    },
    {
      "x": -3,
      "y": 0,
      "z": -2,
      "name": "Plant_Coral_Block_Pink"
    },
    {
      "x": -3,
      "y": 1,
      "z": -2,
      "name": "Plant_Coral_Block_Pink"
    },
    {
      "x": -3,
      "y": 2,
      "z": -2,
      "name": "Plant_Coral_Block_Pink"
    },
    {
      "x": -3,
      "y": 3,
      "z": -2,
      "name": "Plant_Coral_Block_Orange"
    },
    {
      "x": -3,
      "y": 4,
      "z": -2,
      "name": "Plant_Coral_Block_Orange"
    },
    {
      "x": -3,
      "y": 5,
      "z": -2,
      "name": "Plant_Coral_Block_Orange"
    },
    {
      "x": -3,
      "y": 6,
      "z": -2,
      "name": "Plant_Coral_Block_Orange"
    },
    {
      "x": -3,
      "y": 7,
      "z": -2,
      "name": "Plant_Coral_Block_Pink"
    },
    {
      "x": -3,
      "y": 8,
      "z": -2,
      "name": "Plant_Coral_Block_Orange"
    },
    {
      "x": -3,
      "y": 9,
      "z": -2,
      "name": "Plant_Coral_Block_Orange"
    },
    {
      "x": -3,
      "y": 10,
      "z": -2,
      "name": "Plant_Coral_Block_Pink"
    },
    {
      "x": -3,
      "y": 11,
      "z": -2,
      "name": "Plant_Coral_Block_Pink"
    },
    {
      "x": -3,
      "y": 12,
      "z": -2,
      "name": "Rock_Volcanic_Cracked_Incandescent"
    },
    {
      "x": -3,
      "y": 3,
      "z": -1,
      "name": "Plant_Coral_Block_Orange"
    },
    {
      "x": -3,
      "y": 4,
      "z": -1,
      "name": "Plant_Coral_Block_Orange"
    },
    {
      "x": -3,
      "y": 5,
      "z": -1,
      "name": "Plant_Coral_Block_Pink"
    },
    {
      "x": -3,
      "y": 6,
      "z": -1,
      "name": "Plant_Coral_Block_Pink"
    },
    {
      "x": -3,
      "y": 7,
      "z": -1,
      "name": "Plant_Coral_Block_Orange"
    },
    {
      "x": -3,
      "y": 8,
      "z": -1,
      "name": "Plant_Coral_Block_Orange"
    },
    {
      "x": -3,
      "y": 9,
      "z": -1,
      "name": "Plant_Coral_Block_Orange"
    },
    {
      "x": -3,
      "y": 10,
      "z": -1,
      "name": "Plant_Coral_Block_Pink"
    },
    {
      "x": -3,
      "y": 11,
      "z": -1,
      "name": "Plant_Coral_Block_Pink"
    },
    {
      "x": -3,
      "y": 12,
      "z": -1,
      "name": "Rock_Volcanic_Cracked_Lava"
    },
    {
      "x": -3,
      "y": 4,
      "z": 0,
      "name": "Plant_Coral_Block_Pink"
    },
    {
      "x": -3,
      "y": 5,
      "z": 0,
      "name": "Plant_Coral_Block_Pink"
    },
    {
      "x": -3,
      "y": 6,
      "z": 0,
      "name": "Plant_Coral_Block_Pink"
    },
    {
      "x": -3,
      "y": 7,
      "z": 0,
      "name": "Plant_Coral_Block_Pink"
    },
    {
      "x": -3,
      "y": 8,
      "z": 0,
      "name": "Plant_Coral_Block_Orange"
    },
    {
      "x": -3,
      "y": 9,
      "z": 0,
      "name": "Plant_Coral_Block_Orange"
    },
    {
      "x": -3,
      "y": 10,
      "z": 0,
      "name": "Plant_Coral_Block_Pink"
    },
    {
      "x": -3,
      "y": 11,
      "z": 0,
      "name": "Plant_Coral_Block_Pink"
    },
    {
      "x": -3,
      "y": 12,
      "z": 0,
      "name": "Rock_Volcanic_Cracked_Incandescent"
    },
    {
      "x": -3,
      "y": 0,
      "z": 1,
      "name": "Plant_Coral_Block_Orange"
    },
    {
      "x": -3,
      "y": 1,
      "z": 1,
      "name": "Plant_Coral_Block_Orange"
    },
    {
      "x": -3,
      "y": 2,
      "z": 1,
      "name": "Plant_Coral_Block_Orange"
    },
    {
      "x": -3,
      "y": 3,
      "z": 1,
      "name": "Plant_Coral_Block_Orange"
    },
    {
      "x": -3,
      "y": 4,
      "z": 1,
      "name": "Plant_Coral_Block_Pink"
    },
    {
      "x": -3,
      "y": 5,
      "z": 1,
      "name": "Plant_Coral_Block_Pink"
    },
    {
      "x": -3,
      "y": 6,
      "z": 1,
      "name": "Plant_Coral_Block_Pink"
    },
    {
      "x": -3,
      "y": 7,
      "z": 1,
      "name": "Plant_Coral_Block_Pink"
    },
    {
      "x": -3,
      "y": 8,
      "z": 1,
      "name": "Plant_Coral_Block_Pink"
    },
    {
      "x": -3,
      "y": 9,
      "z": 1,
      "name": "Plant_Coral_Block_Orange"
    },
    {
      "x": -3,
      "y": 10,
      "z": 1,
      "name": "Plant_Coral_Block_Pink"
    },
    {
      "x": -3,
      "y": 11,
      "z": 1,
      "name": "Plant_Coral_Block_Pink"
    },
    {
      "x": -3,
      "y": 12,
      "z": 1,
      "name": "Rock_Volcanic_Cracked_Incandescent"
    },
    {
      "x": -3,
      "y": 0,
      "z": 2,
      "name": "Plant_Coral_Block_Orange"
    },
    {
      "x": -3,
      "y": 1,
      "z": 2,
      "name": "Plant_Coral_Block_Orange"
    },
    {
      "x": -3,
      "y": 2,
      "z": 2,
      "name": "Plant_Coral_Block_Orange"
    },
    {
      "x": -3,
      "y": 3,
      "z": 2,
      "name": "Plant_Coral_Block_Pink"
    },
    {
      "x": -3,
      "y": 4,
      "z": 2,
      "name": "Plant_Coral_Block_Pink"
    },
    {
      "x": -3,
      "y": 5,
      "z": 2,
      "name": "Plant_Coral_Block_Pink"
    },
    {
      "x": -3,
      "y": 6,
      "z": 2,
      "name": "Plant_Coral_Block_Pink"
    },
    {
      "x": -3,
      "y": 7,
      "z": 2,
      "name": "Plant_Coral_Block_Pink"
    },
    {
      "x": -3,
      "y": 8,
      "z": 2,
      "name": "Plant_Coral_Block_Pink"
    },
    {
      "x": -3,
      "y": 9,
      "z": 2,
      "name": "Plant_Coral_Block_Pink"
    },
    {
      "x": -3,
      "y": 10,
      "z": 2,
      "name": "Plant_Coral_Block_Pink"
    },
    {
      "x": -3,
      "y": 11,
      "z": 2,
      "name": "Plant_Coral_Block_Pink"
    },
    {
      "x": -3,
      "y": 12,
      "z": 2,
      "name": "Rock_Volcanic"
    },
    {
      "x": -3,
      "y": 0,
      "z": 3,
      "name": "Plant_Coral_Block_Orange"
    },
    {
      "x": -3,
      "y": 1,
      "z": 3,
      "name": "Plant_Coral_Block_Orange"
    },
    {
      "x": -3,
      "y": 2,
      "z": 3,
      "name": "Plant_Coral_Block_Orange"
    },
    {
      "x": -3,
      "y": 3,
      "z": 3,
      "name": "Plant_Coral_Block_Pink"
    },
    {
      "x": -3,
      "y": 4,
      "z": 3,
      "name": "Plant_Coral_Block_Pink"
    },
    {
      "x": -3,
      "y": 5,
      "z": 3,
      "name": "Plant_Coral_Block_Pink"
    },
    {
      "x": -3,
      "y": 6,
      "z": 3,
      "name": "Plant_Coral_Block_Pink"
    },
    {
      "x": -3,
      "y": 7,
      "z": 3,
      "name": "Plant_Coral_Block_Pink"
    },
    {
      "x": -3,
      "y": 8,
      "z": 3,
      "name": "Plant_Coral_Block_Pink"
    },
    {
      "x": -3,
      "y": 9,
      "z": 3,
      "name": "Plant_Coral_Block_Pink"
    },
    {
      "x": -3,
      "y": 10,
      "z": 3,
      "name": "Plant_Coral_Block_Orange"
    },
    {
      "x": -3,
      "y": 11,
      "z": 3,
      "name": "Plant_Coral_Block_Pink"
    },
    {
      "x": -3,
      "y": 12,
      "z": 3,
      "name": "Plant_Coral_Block_Pink"
    },
    {
      "x": -3,
      "y": 13,
      "z": 3,
      "name": "Rock_Volcanic_Cracked_Lava"
    },
    {
      "x": -3,
      "y": 0,
      "z": 4,
      "name": "Plant_Coral_Block_Orange"
    },
    {
      "x": -3,
      "y": 1,
      "z": 4,
      "name": "Plant_Coral_Block_Orange"
    },
    {
      "x": -3,
      "y": 2,
      "z": 4,
      "name": "Plant_Coral_Block_Orange"
    },
    {
      "x": -3,
      "y": 3,
      "z": 4,
      "name": "Plant_Coral_Block_Pink"
    },
    {
      "x": -3,
      "y": 4,
      "z": 4,
      "name": "Plant_Coral_Block_Pink"
    },
    {
      "x": -3,
      "y": 5,
      "z": 4,
      "name": "Plant_Coral_Block_Pink"
    },
    {
      "x": -3,
      "y": 6,
      "z": 4,
      "name": "Plant_Coral_Block_Pink"
    },
    {
      "x": -3,
      "y": 7,
      "z": 4,
      "name": "Plant_Coral_Block_Pink"
    },
    {
      "x": -3,
      "y": 8,
      "z": 4,
      "name": "Plant_Coral_Block_Pink"
    },
    {
      "x": -3,
      "y": 9,
      "z": 4,
      "name": "Plant_Coral_Block_Pink"
    },
    {
      "x": -3,
      "y": 10,
      "z": 4,
      "name": "Plant_Coral_Block_Pink"
    },
    {
      "x": -3,
      "y": 11,
      "z": 4,
      "name": "Plant_Coral_Block_Pink"
    },
    {
      "x": -3,
      "y": 12,
      "z": 4,
      "name": "Plant_Coral_Block_Pink"
    },
    {
      "x": -3,
      "y": 13,
      "z": 4,
      "name": "Rock_Volcanic_Cracked_Lava"
    },
    {
      "x": -3,
      "y": 4,
      "z": 5,
      "name": "Plant_Coral_Block_Pink"
    },
    {
      "x": -3,
      "y": 5,
      "z": 5,
      "name": "Plant_Coral_Block_Pink"
    },
    {
      "x": -3,
      "y": 6,
      "z": 5,
      "name": "Plant_Coral_Block_Pink"
    },
    {
      "x": -3,
      "y": 7,
      "z": 5,
      "name": "Plant_Coral_Block_Pink"
    },
    {
      "x": -3,
      "y": 8,
      "z": 5,
      "name": "Plant_Coral_Block_Pink"
    },
    {
      "x": -3,
      "y": 9,
      "z": 5,
      "name": "Plant_Coral_Block_Pink"
    },
    {
      "x": -3,
      "y": 10,
      "z": 5,
      "name": "Plant_Coral_Block_Orange"
    },
    {
      "x": -3,
      "y": 11,
      "z": 5,
      "name": "Plant_Coral_Block_Pink"
    },
    {
      "x": -3,
      "y": 12,
      "z": 5,
      "name": "Plant_Coral_Block_Pink"
    },
    {
      "x": -3,
      "y": 13,
      "z": 5,
      "name": "Rock_Volcanic_Cracked_Lava"
    },
    {
      "x": -3,
      "y": 11,
      "z": 6,
      "name": "Plant_Coral_Block_Orange"
    },
    {
      "x": -3,
      "y": 12,
      "z": 6,
      "name": "Plant_Coral_Block_Pink"
    },
    {
      "x": -3,
      "y": 13,
      "z": 6,
      "name": "Plant_Coral_Block_Pink"
    },
    {
      "x": -3,
      "y": 14,
      "z": 6,
      "name": "Plant_Coral_Block_Pink"
    },
    {
      "x": -2,
      "y": 6,
      "z": -7,
      "name": "Plant_Coral_Block_Pink"
    },
    {
      "x": -2,
      "y": 7,
      "z": -7,
      "name": "Plant_Coral_Block_Pink"
    },
    {
      "x": -2,
      "y": 3,
      "z": -6,
      "name": "Plant_Coral_Block_Orange"
    },
    {
      "x": -2,
      "y": 4,
      "z": -6,
      "name": "Plant_Coral_Block_Pink"
    },
    {
      "x": -2,
      "y": 5,
      "z": -6,
      "name": "Plant_Coral_Block_Pink"
    },
    {
      "x": -2,
      "y": 6,
      "z": -6,
      "name": "Rock_Volcanic_Cracked_Incandescent_Bubbles"
    },
    {
      "x": -2,
      "y": 9,
      "z": -6,
      "name": "Plant_Coral_Block_Orange"
    },
    {
      "x": -2,
      "y": 10,
      "z": -6,
      "name": "Plant_Coral_Block_Orange"
    },
    {
      "x": -2,
      "y": 11,
      "z": -6,
      "name": "Plant_Coral_Block_Orange"
    },
    {
      "x": -2,
      "y": 12,
      "z": -6,
      "name": "Plant_Coral_Block_Pink"
    },
    {
      "x": -2,
      "y": 13,
      "z": -6,
      "name": "Plant_Coral_Block_Pink"
    },
    {
      "x": -2,
      "y": 14,
      "z": -6,
      "name": "Plant_Coral_Block_Pink"
    },
    {
      "x": -2,
      "y": 15,
      "z": -6,
      "name": "Plant_Coral_Block_Pink"
    },
    {
      "x": -2,
      "y": 16,
      "z": -6,
      "name": "Plant_Coral_Block_Pink"
    },
    {
      "x": -2,
      "y": 3,
      "z": -5,
      "name": "Plant_Coral_Block_Orange"
    },
    {
      "x": -2,
      "y": 4,
      "z": -5,
      "name": "Plant_Coral_Block_Orange"
    },
    {
      "x": -2,
      "y": 5,
      "z": -5,
      "name": "Plant_Coral_Block_Pink"
    },
    {
      "x": -2,
      "y": 6,
      "z": -5,
      "name": "Plant_Coral_Block_Pink"
    },
    {
      "x": -2,
      "y": 7,
      "z": -5,
      "name": "Plant_Coral_Block_Pink"
    },
    {
      "x": -2,
      "y": 8,
      "z": -5,
      "name": "Plant_Coral_Block_Pink"
    },
    {
      "x": -2,
      "y": 9,
      "z": -5,
      "name": "Plant_Coral_Block_Pink"
    },
    {
      "x": -2,
      "y": 10,
      "z": -5,
      "name": "Plant_Coral_Block_Orange"
    },
    {
      "x": -2,
      "y": 11,
      "z": -5,
      "name": "Plant_Coral_Block_Pink"
    },
    {
      "x": -2,
      "y": 12,
      "z": -5,
      "name": "Plant_Coral_Block_Pink"
    },
    {
      "x": -2,
      "y": 13,
      "z": -5,
      "name": "Plant_Coral_Block_Pink"
    },
    {
      "x": -2,
      "y": 14,
      "z": -5,
      "name": "Plant_Coral_Block_Pink"
    },
    {
      "x": -2,
      "y": 15,
      "z": -5,
      "name": "Plant_Coral_Block_Pink"
    },
    {
      "x": -2,
      "y": 16,
      "z": -5,
      "name": "Plant_Coral_Block_Pink"
    },
    {
      "x": -2,
      "y": 17,
      "z": -5,
      "name": "Plant_Coral_Block_Pink"
    },
    {
      "x": -2,
      "y": 4,
      "z": -4,
      "name": "Plant_Coral_Block_Orange"
    },
    {
      "x": -2,
      "y": 5,
      "z": -4,
      "name": "Plant_Coral_Block_Orange"
    },
    {
      "x": -2,
      "y": 6,
      "z": -4,
      "name": "Plant_Coral_Block_Pink"
    },
    {
      "x": -2,
      "y": 7,
      "z": -4,
      "name": "Plant_Coral_Block_Pink"
    },
    {
      "x": -2,
      "y": 8,
      "z": -4,
      "name": "Plant_Coral_Block_Pink"
    },
    {
      "x": -2,
      "y": 9,
      "z": -4,
      "name": "Plant_Coral_Block_Orange"
    },
    {
      "x": -2,
      "y": 10,
      "z": -4,
      "name": "Plant_Coral_Block_Pink"
    },
    {
      "x": -2,
      "y": 11,
      "z": -4,
      "name": "Plant_Coral_Block_Pink"
    },
    {
      "x": -2,
      "y": 12,
      "z": -4,
      "name": "Plant_Coral_Block_Pink"
    },
    {
      "x": -2,
      "y": 13,
      "z": -4,
      "name": "Plant_Coral_Block_Pink"
    },
    {
      "x": -2,
      "y": 14,
      "z": -4,
      "name": "Plant_Coral_Block_Pink"
    },
    {
      "x": -2,
      "y": 15,
      "z": -4,
      "name": "Plant_Coral_Block_Pink"
    },
    {
      "x": -2,
      "y": 16,
      "z": -4,
      "name": "Plant_Coral_Block_Pink"
    },
    {
      "x": -2,
      "y": 17,
      "z": -4,
      "name": "Plant_Coral_Block_Pink"
    },
    {
      "x": -2,
      "y": 4,
      "z": -3,
      "name": "Plant_Coral_Block_Orange"
    },
    {
      "x": -2,
      "y": 5,
      "z": -3,
      "name": "Plant_Coral_Block_Orange"
    },
    {
      "x": -2,
      "y": 6,
      "z": -3,
      "name": "Plant_Coral_Block_Pink"
    },
    {
      "x": -2,
      "y": 7,
      "z": -3,
      "name": "Plant_Coral_Block_Pink"
    },
    {
      "x": -2,
      "y": 8,
      "z": -3,
      "name": "Plant_Coral_Block_Pink"
    },
    {
      "x": -2,
      "y": 9,
      "z": -3,
      "name": "Plant_Coral_Block_Pink"
    },
    {
      "x": -2,
      "y": 10,
      "z": -3,
      "name": "Plant_Coral_Block_Pink"
    },
    {
      "x": -2,
      "y": 11,
      "z": -3,
      "name": "Rock_Volcanic_Cracked_Incandescent"
    },
    {
      "x": -2,
      "y": 15,
      "z": -3,
      "name": "Plant_Coral_Block_Pink"
    },
    {
      "x": -2,
      "y": 16,
      "z": -3,
      "name": "Plant_Coral_Block_Pink"
    },
    {
      "x": -2,
      "y": 17,
      "z": -3,
      "name": "Plant_Coral_Block_Pink"
    },
    {
      "x": -2,
      "y": 5,
      "z": -2,
      "name": "Plant_Coral_Block_Orange"
    },
    {
      "x": -2,
      "y": 6,
      "z": -2,
      "name": "Plant_Coral_Block_Orange"
    },
    {
      "x": -2,
      "y": 7,
      "z": -2,
      "name": "Plant_Coral_Block_Pink"
    },
    {
      "x": -2,
      "y": 8,
      "z": -2,
      "name": "Plant_Coral_Block_Orange"
    },
    {
      "x": -2,
      "y": 9,
      "z": -2,
      "name": "Plant_Coral_Block_Pink"
    },
    {
      "x": -2,
      "y": 10,
      "z": -2,
      "name": "Plant_Coral_Block_Pink"
    },
    {
      "x": -2,
      "y": 11,
      "z": -2,
      "name": "Rock_Volcanic"
    },
    {
      "x": -2,
      "y": 16,
      "z": -2,
      "name": "Plant_Coral_Block_Pink"
    },
    {
      "x": -2,
      "y": 17,
      "z": -2,
      "name": "Plant_Coral_Block_Pink"
    },
    {
      "x": -2,
      "y": 5,
      "z": -1,
      "name": "Plant_Coral_Block_Orange"
    },
    {
      "x": -2,
      "y": 6,
      "z": -1,
      "name": "Plant_Coral_Block_Orange"
    },
    {
      "x": -2,
      "y": 7,
      "z": -1,
      "name": "Plant_Coral_Block_Orange"
    },
    {
      "x": -2,
      "y": 8,
      "z": -1,
      "name": "Plant_Coral_Block_Orange"
    },
    {
      "x": -2,
      "y": 9,
      "z": -1,
      "name": "Plant_Coral_Block_Pink"
    },
    {
      "x": -2,
      "y": 10,
      "z": -1,
      "name": "Plant_Coral_Block_Pink"
    },
    {
      "x": -2,
      "y": 11,
      "z": -1,
      "name": "Rock_Volcanic"
    },
    {
      "x": -2,
      "y": 4,
      "z": 0,
      "name": "Plant_Coral_Block_Orange"
    },
    {
      "x": -2,
      "y": 5,
      "z": 0,
      "name": "Plant_Coral_Block_Orange"
    },
    {
      "x": -2,
      "y": 6,
      "z": 0,
      "name": "Plant_Coral_Block_Orange"
    },
    {
      "x": -2,
      "y": 7,
      "z": 0,
      "name": "Plant_Coral_Block_Orange"
    },
    {
      "x": -2,
      "y": 8,
      "z": 0,
      "name": "Plant_Coral_Block_Orange"
    },
    {
      "x": -2,
      "y": 9,
      "z": 0,
      "name": "Plant_Coral_Block_Orange"
    },
    {
      "x": -2,
      "y": 10,
      "z": 0,
      "name": "Plant_Coral_Block_Pink"
    },
    {
      "x": -2,
      "y": 11,
      "z": 0,
      "name": "Plant_Coral_Block_Pink"
    },
    {
      "x": -2,
      "y": 12,
      "z": 0,
      "name": "Rock_Volcanic"
    },
    {
      "x": -2,
      "y": 4,
      "z": 1,
      "name": "Plant_Coral_Block_Orange"
    },
    {
      "x": -2,
      "y": 5,
      "z": 1,
      "name": "Plant_Coral_Block_Pink"
    },
    {
      "x": -2,
      "y": 6,
      "z": 1,
      "name": "Plant_Coral_Block_Pink"
    },
    {
      "x": -2,
      "y": 7,
      "z": 1,
      "name": "Plant_Coral_Block_Orange"
    },
    {
      "x": -2,
      "y": 8,
      "z": 1,
      "name": "Plant_Coral_Block_Orange"
    },
    {
      "x": -2,
      "y": 9,
      "z": 1,
      "name": "Plant_Coral_Block_Orange"
    },
    {
      "x": -2,
      "y": 10,
      "z": 1,
      "name": "Plant_Coral_Block_Pink"
    },
    {
      "x": -2,
      "y": 11,
      "z": 1,
      "name": "Plant_Coral_Block_Pink"
    },
    {
      "x": -2,
      "y": 12,
      "z": 1,
      "name": "Rock_Volcanic_Cracked_Incandescent"
    },
    {
      "x": -2,
      "y": 4,
      "z": 2,
      "name": "Plant_Coral_Block_Pink"
    },
    {
      "x": -2,
      "y": 5,
      "z": 2,
      "name": "Plant_Coral_Block_Pink"
    },
    {
      "x": -2,
      "y": 6,
      "z": 2,
      "name": "Plant_Coral_Block_Pink"
    },
    {
      "x": -2,
      "y": 7,
      "z": 2,
      "name": "Plant_Coral_Block_Pink"
    },
    {
      "x": -2,
      "y": 8,
      "z": 2,
      "name": "Plant_Coral_Block_Orange"
    },
    {
      "x": -2,
      "y": 9,
      "z": 2,
      "name": "Plant_Coral_Block_Orange"
    },
    {
      "x": -2,
      "y": 10,
      "z": 2,
      "name": "Plant_Coral_Block_Pink"
    },
    {
      "x": -2,
      "y": 11,
      "z": 2,
      "name": "Plant_Coral_Block_Pink"
    },
    {
      "x": -2,
      "y": 12,
      "z": 2,
      "name": "Rock_Volcanic_Cracked_Lava"
    },
    {
      "x": -2,
      "y": 5,
      "z": 3,
      "name": "Plant_Coral_Block_Pink"
    },
    {
      "x": -2,
      "y": 6,
      "z": 3,
      "name": "Plant_Coral_Block_Pink"
    },
    {
      "x": -2,
      "y": 7,
      "z": 3,
      "name": "Plant_Coral_Block_Pink"
    },
    {
      "x": -2,
      "y": 8,
      "z": 3,
      "name": "Plant_Coral_Block_Orange"
    },
    {
      "x": -2,
      "y": 9,
      "z": 3,
      "name": "Plant_Coral_Block_Orange"
    },
    {
      "x": -2,
      "y": 10,
      "z": 3,
      "name": "Plant_Coral_Block_Pink"
    },
    {
      "x": -2,
      "y": 11,
      "z": 3,
      "name": "Plant_Coral_Block_Pink"
    },
    {
      "x": -2,
      "y": 12,
      "z": 3,
      "name": "Rock_Volcanic_Cracked_Incandescent"
    },
    {
      "x": -2,
      "y": 5,
      "z": 4,
      "name": "Plant_Coral_Block_Pink"
    },
    {
      "x": -2,
      "y": 6,
      "z": 4,
      "name": "Plant_Coral_Block_Pink"
    },
    {
      "x": -2,
      "y": 7,
      "z": 4,
      "name": "Plant_Coral_Block_Pink"
    },
    {
      "x": -2,
      "y": 8,
      "z": 4,
      "name": "Plant_Coral_Block_Pink"
    },
    {
      "x": -2,
      "y": 9,
      "z": 4,
      "name": "Plant_Coral_Block_Orange"
    },
    {
      "x": -2,
      "y": 10,
      "z": 4,
      "name": "Plant_Coral_Block_Pink"
    },
    {
      "x": -2,
      "y": 11,
      "z": 4,
      "name": "Plant_Coral_Block_Pink"
    },
    {
      "x": -2,
      "y": 12,
      "z": 4,
      "name": "Rock_Volcanic_Cracked_Incandescent"
    },
    {
      "x": -2,
      "y": 6,
      "z": 5,
      "name": "Plant_Coral_Block_Pink"
    },
    {
      "x": -2,
      "y": 7,
      "z": 5,
      "name": "Plant_Coral_Block_Pink"
    },
    {
      "x": -2,
      "y": 8,
      "z": 5,
      "name": "Plant_Coral_Block_Pink"
    },
    {
      "x": -2,
      "y": 9,
      "z": 5,
      "name": "Plant_Coral_Block_Orange"
    },
    {
      "x": -2,
      "y": 10,
      "z": 5,
      "name": "Plant_Coral_Block_Orange"
    },
    {
      "x": -2,
      "y": 11,
      "z": 5,
      "name": "Plant_Coral_Block_Pink"
    },
    {
      "x": -2,
      "y": 12,
      "z": 5,
      "name": "Plant_Coral_Block_Pink"
    },
    {
      "x": -2,
      "y": 13,
      "z": 5,
      "name": "Rock_Volcanic_Cracked_Incandescent"
    },
    {
      "x": -2,
      "y": 8,
      "z": 6,
      "name": "Plant_Coral_Block_Orange"
    },
    {
      "x": -2,
      "y": 9,
      "z": 6,
      "name": "Plant_Coral_Block_Orange"
    },
    {
      "x": -2,
      "y": 10,
      "z": 6,
      "name": "Plant_Coral_Block_Orange"
    },
    {
      "x": -2,
      "y": 11,
      "z": 6,
      "name": "Plant_Coral_Block_Orange"
    },
    {
      "x": -2,
      "y": 12,
      "z": 6,
      "name": "Plant_Coral_Block_Pink"
    },
    {
      "x": -2,
      "y": 13,
      "z": 6,
      "name": "Plant_Coral_Block_Pink"
    },
    {
      "x": -2,
      "y": 14,
      "z": 6,
      "name": "Plant_Coral_Block_Pink"
    },
    {
      "x": -2,
      "y": 12,
      "z": 7,
      "name": "Plant_Coral_Block_Orange"
    },
    {
      "x": -2,
      "y": 13,
      "z": 7,
      "name": "Plant_Coral_Block_Pink"
    },
    {
      "x": -1,
      "y": 12,
      "z": -7,
      "name": "Plant_Coral_Block_Orange"
    },
    {
      "x": -1,
      "y": 13,
      "z": -7,
      "name": "Plant_Coral_Block_Orange"
    },
    {
      "x": -1,
      "y": 14,
      "z": -7,
      "name": "Plant_Coral_Block_Orange"
    },
    {
      "x": -1,
      "y": 15,
      "z": -7,
      "name": "Plant_Coral_Block_Orange"
    },
    {
      "x": -1,
      "y": 16,
      "z": -7,
      "name": "Plant_Coral_Block_Pink"
    },
    {
      "x": -1,
      "y": 5,
      "z": -6,
      "name": "Plant_Coral_Block_Pink"
    },
    {
      "x": -1,
      "y": 6,
      "z": -6,
      "name": "Plant_Coral_Block_Pink"
    },
    {
      "x": -1,
      "y": 7,
      "z": -6,
      "name": "Plant_Coral_Block_Pink"
    },
    {
      "x": -1,
      "y": 8,
      "z": -6,
      "name": "Plant_Coral_Block_Pink"
    },
    {
      "x": -1,
      "y": 9,
      "z": -6,
      "name": "Plant_Coral_Block_Pink"
    },
    {
      "x": -1,
      "y": 10,
      "z": -6,
      "name": "Plant_Coral_Block_Orange"
    },
    {
      "x": -1,
      "y": 11,
      "z": -6,
      "name": "Plant_Coral_Block_Orange"
    },
    {
      "x": -1,
      "y": 12,
      "z": -6,
      "name": "Plant_Coral_Block_Orange"
    },
    {
      "x": -1,
      "y": 13,
      "z": -6,
      "name": "Plant_Coral_Block_Orange"
    },
    {
      "x": -1,
      "y": 14,
      "z": -6,
      "name": "Plant_Coral_Block_Pink"
    },
    {
      "x": -1,
      "y": 15,
      "z": -6,
      "name": "Plant_Coral_Block_Pink"
    },
    {
      "x": -1,
      "y": 16,
      "z": -6,
      "name": "Plant_Coral_Block_Pink"
    },
    {
      "x": -1,
      "y": 17,
      "z": -6,
      "name": "Plant_Coral_Block_Pink"
    },
    {
      "x": -1,
      "y": 4,
      "z": -5,
      "name": "Plant_Coral_Block_Orange"
    },
    {
      "x": -1,
      "y": 5,
      "z": -5,
      "name": "Plant_Coral_Block_Orange"
    },
    {
      "x": -1,
      "y": 6,
      "z": -5,
      "name": "Plant_Coral_Block_Pink"
    },
    {
      "x": -1,
      "y": 7,
      "z": -5,
      "name": "Plant_Coral_Block_Pink"
    },
    {
      "x": -1,
      "y": 8,
      "z": -5,
      "name": "Plant_Coral_Block_Pink"
    },
    {
      "x": -1,
      "y": 9,
      "z": -5,
      "name": "Plant_Coral_Block_Orange"
    },
    {
      "x": -1,
      "y": 10,
      "z": -5,
      "name": "Plant_Coral_Block_Orange"
    },
    {
      "x": -1,
      "y": 11,
      "z": -5,
      "name": "Plant_Coral_Block_Orange"
    },
    {
      "x": -1,
      "y": 12,
      "z": -5,
      "name": "Plant_Coral_Block_Pink"
    },
    {
      "x": -1,
      "y": 13,
      "z": -5,
      "name": "Plant_Coral_Block_Pink"
    },
    {
      "x": -1,
      "y": 14,
      "z": -5,
      "name": "Plant_Coral_Block_Pink"
    },
    {
      "x": -1,
      "y": 15,
      "z": -5,
      "name": "Plant_Coral_Block_Pink"
    },
    {
      "x": -1,
      "y": 16,
      "z": -5,
      "name": "Rock_Volcanic"
    },
    {
      "x": -1,
      "y": 4,
      "z": -4,
      "name": "Plant_Coral_Block_Orange"
    },
    {
      "x": -1,
      "y": 5,
      "z": -4,
      "name": "Plant_Coral_Block_Orange"
    },
    {
      "x": -1,
      "y": 6,
      "z": -4,
      "name": "Plant_Coral_Block_Pink"
    },
    {
      "x": -1,
      "y": 7,
      "z": -4,
      "name": "Plant_Coral_Block_Pink"
    },
    {
      "x": -1,
      "y": 8,
      "z": -4,
      "name": "Plant_Coral_Block_Orange"
    },
    {
      "x": -1,
      "y": 9,
      "z": -4,
      "name": "Plant_Coral_Block_Orange"
    },
    {
      "x": -1,
      "y": 10,
      "z": -4,
      "name": "Plant_Coral_Block_Orange"
    },
    {
      "x": -1,
      "y": 11,
      "z": -4,
      "name": "Plant_Coral_Block_Pink"
    },
    {
      "x": -1,
      "y": 12,
      "z": -4,
      "name": "Plant_Coral_Block_Pink"
    },
    {
      "x": -1,
      "y": 13,
      "z": -4,
      "name": "Plant_Coral_Block_Pink"
    },
    {
      "x": -1,
      "y": 14,
      "z": -4,
      "name": "Plant_Coral_Block_Pink"
    },
    {
      "x": -1,
      "y": 15,
      "z": -4,
      "name": "Plant_Coral_Block_Pink"
    },
    {
      "x": -1,
      "y": 16,
      "z": -4,
      "name": "Rock_Volcanic_Cracked_Lava"
    },
    {
      "x": -1,
      "y": 4,
      "z": -3,
      "name": "Plant_Coral_Block_Orange"
    },
    {
      "x": -1,
      "y": 5,
      "z": -3,
      "name": "Plant_Coral_Block_Orange"
    },
    {
      "x": -1,
      "y": 6,
      "z": -3,
      "name": "Plant_Coral_Block_Pink"
    },
    {
      "x": -1,
      "y": 7,
      "z": -3,
      "name": "Plant_Coral_Block_Pink"
    },
    {
      "x": -1,
      "y": 8,
      "z": -3,
      "name": "Plant_Coral_Block_Orange"
    },
    {
      "x": -1,
      "y": 9,
      "z": -3,
      "name": "Plant_Coral_Block_Orange"
    },
    {
      "x": -1,
      "y": 10,
      "z": -3,
      "name": "Plant_Coral_Block_Pink"
    },
    {
      "x": -1,
      "y": 11,
      "z": -3,
      "name": "Plant_Coral_Block_Pink"
    },
    {
      "x": -1,
      "y": 12,
      "z": -3,
      "name": "Plant_Coral_Block_Pink"
    },
    {
      "x": -1,
      "y": 13,
      "z": -3,
      "name": "Plant_Coral_Block_Pink"
    },
    {
      "x": -1,
      "y": 14,
      "z": -3,
      "name": "Plant_Coral_Block_Pink"
    },
    {
      "x": -1,
      "y": 15,
      "z": -3,
      "name": "Plant_Coral_Block_Pink"
    },
    {
      "x": -1,
      "y": 16,
      "z": -3,
      "name": "Rock_Volcanic_Cracked_Incandescent"
    },
    {
      "x": -1,
      "y": 5,
      "z": -2,
      "name": "Plant_Coral_Block_Orange"
    },
    {
      "x": -1,
      "y": 6,
      "z": -2,
      "name": "Plant_Coral_Block_Orange"
    },
    {
      "x": -1,
      "y": 7,
      "z": -2,
      "name": "Plant_Coral_Block_Orange"
    },
    {
      "x": -1,
      "y": 8,
      "z": -2,
      "name": "Plant_Coral_Block_Orange"
    },
    {
      "x": -1,
      "y": 9,
      "z": -2,
      "name": "Plant_Coral_Block_Pink"
    },
    {
      "x": -1,
      "y": 10,
      "z": -2,
      "name": "Plant_Coral_Block_Pink"
    },
    {
      "x": -1,
      "y": 11,
      "z": -2,
      "name": "Rock_Volcanic_Cracked_Incandescent"
    },
    {
      "x": -1,
      "y": 13,
      "z": -2,
      "name": "Plant_Coral_Block_Pink"
    },
    {
      "x": -1,
      "y": 14,
      "z": -2,
      "name": "Plant_Coral_Block_Pink"
    },
    {
      "x": -1,
      "y": 15,
      "z": -2,
      "name": "Plant_Coral_Block_Pink"
    },
    {
      "x": -1,
      "y": 16,
      "z": -2,
      "name": "Rock_Volcanic_Cracked_Incandescent"
    },
    {
      "x": -1,
      "y": 5,
      "z": -1,
      "name": "Plant_Coral_Block_Orange"
    },
    {
      "x": -1,
      "y": 6,
      "z": -1,
      "name": "Plant_Coral_Block_Orange"
    },
    {
      "x": -1,
      "y": 7,
      "z": -1,
      "name": "Plant_Coral_Block_Orange"
    },
    {
      "x": -1,
      "y": 8,
      "z": -1,
      "name": "Plant_Coral_Block_Orange"
    },
    {
      "x": -1,
      "y": 9,
      "z": -1,
      "name": "Plant_Coral_Block_Pink"
    },
    {
      "x": -1,
      "y": 10,
      "z": -1,
      "name": "Plant_Coral_Block_Pink"
    },
    {
      "x": -1,
      "y": 11,
      "z": -1,
      "name": "Rock_Volcanic_Cracked_Incandescent"
    },
    {
      "x": -1,
      "y": 15,
      "z": -1,
      "name": "Plant_Coral_Block_Pink"
    },
    {
      "x": -1,
      "y": 16,
      "z": -1,
      "name": "Plant_Coral_Block_Pink"
    },
    {
      "x": -1,
      "y": 17,
      "z": -1,
      "name": "Plant_Coral_Block_Pink"
    },
    {
      "x": -1,
      "y": 5,
      "z": 0,
      "name": "Plant_Coral_Block_Orange"
    },
    {
      "x": -1,
      "y": 6,
      "z": 0,
      "name": "Plant_Coral_Block_Orange"
    },
    {
      "x": -1,
      "y": 7,
      "z": 0,
      "name": "Plant_Coral_Block_Orange"
    },
    {
      "x": -1,
      "y": 8,
      "z": 0,
      "name": "Plant_Coral_Block_Orange"
    },
    {
      "x": -1,
      "y": 9,
      "z": 0,
      "name": "Plant_Coral_Block_Pink"
    },
    {
      "x": -1,
      "y": 10,
      "z": 0,
      "name": "Plant_Coral_Block_Pink"
    },
    {
      "x": -1,
      "y": 11,
      "z": 0,
      "name": "Rock_Volcanic_Cracked_Incandescent"
    },
    {
      "x": -1,
      "y": 16,
      "z": 0,
      "name": "Plant_Coral_Block_Pink"
    },
    {
      "x": -1,
      "y": 17,
      "z": 0,
      "name": "Plant_Coral_Block_Pink"
    },
    {
      "x": -1,
      "y": 4,
      "z": 1,
      "name": "Plant_Coral_Block_Orange"
    },
    {
      "x": -1,
      "y": 5,
      "z": 1,
      "name": "Plant_Coral_Block_Orange"
    },
    {
      "x": -1,
      "y": 6,
      "z": 1,
      "name": "Plant_Coral_Block_Orange"
    },
    {
      "x": -1,
      "y": 7,
      "z": 1,
      "name": "Plant_Coral_Block_Orange"
    },
    {
      "x": -1,
      "y": 8,
      "z": 1,
      "name": "Plant_Coral_Block_Orange"
    },
    {
      "x": -1,
      "y": 9,
      "z": 1,
      "name": "Plant_Coral_Block_Pink"
    },
    {
      "x": -1,
      "y": 10,
      "z": 1,
      "name": "Plant_Coral_Block_Pink"
    },
    {
      "x": -1,
      "y": 11,
      "z": 1,
      "name": "Rock_Volcanic_Cracked_Incandescent"
    },
    {
      "x": -1,
      "y": 17,
      "z": 1,
      "name": "Plant_Coral_Block_Pink"
    },
    {
      "x": -1,
      "y": 4,
      "z": 2,
      "name": "Plant_Coral_Block_Orange"
    },
    {
      "x": -1,
      "y": 5,
      "z": 2,
      "name": "Plant_Coral_Block_Pink"
    },
    {
      "x": -1,
      "y": 6,
      "z": 2,
      "name": "Plant_Coral_Block_Pink"
    },
    {
      "x": -1,
      "y": 7,
      "z": 2,
      "name": "Plant_Coral_Block_Orange"
    },
    {
      "x": -1,
      "y": 8,
      "z": 2,
      "name": "Plant_Coral_Block_Orange"
    },
    {
      "x": -1,
      "y": 9,
      "z": 2,
      "name": "Plant_Coral_Block_Orange"
    },
    {
      "x": -1,
      "y": 10,
      "z": 2,
      "name": "Plant_Coral_Block_Pink"
    },
    {
      "x": -1,
      "y": 11,
      "z": 2,
      "name": "Plant_Coral_Block_Pink"
    },
    {
      "x": -1,
      "y": 12,
      "z": 2,
      "name": "Rock_Volcanic"
    },
    {
      "x": -1,
      "y": 4,
      "z": 3,
      "name": "Plant_Coral_Block_Orange"
    },
    {
      "x": -1,
      "y": 5,
      "z": 3,
      "name": "Plant_Coral_Block_Pink"
    },
    {
      "x": -1,
      "y": 6,
      "z": 3,
      "name": "Plant_Coral_Block_Pink"
    },
    {
      "x": -1,
      "y": 7,
      "z": 3,
      "name": "Plant_Coral_Block_Orange"
    },
    {
      "x": -1,
      "y": 8,
      "z": 3,
      "name": "Plant_Coral_Block_Orange"
    },
    {
      "x": -1,
      "y": 9,
      "z": 3,
      "name": "Plant_Coral_Block_Orange"
    },
    {
      "x": -1,
      "y": 10,
      "z": 3,
      "name": "Plant_Coral_Block_Pink"
    },
    {
      "x": -1,
      "y": 11,
      "z": 3,
      "name": "Plant_Coral_Block_Pink"
    },
    {
      "x": -1,
      "y": 12,
      "z": 3,
      "name": "Rock_Volcanic_Cracked_Incandescent"
    },
    {
      "x": -1,
      "y": 3,
      "z": 4,
      "name": "Plant_Coral_Block_Orange"
    },
    {
      "x": -1,
      "y": 4,
      "z": 4,
      "name": "Plant_Coral_Block_Orange"
    },
    {
      "x": -1,
      "y": 5,
      "z": 4,
      "name": "Plant_Coral_Block_Pink"
    },
    {
      "x": -1,
      "y": 6,
      "z": 4,
      "name": "Plant_Coral_Block_Pink"
    },
    {
      "x": -1,
      "y": 7,
      "z": 4,
      "name": "Plant_Coral_Block_Pink"
    },
    {
      "x": -1,
      "y": 8,
      "z": 4,
      "name": "Plant_Coral_Block_Orange"
    },
    {
      "x": -1,
      "y": 9,
      "z": 4,
      "name": "Plant_Coral_Block_Orange"
    },
    {
      "x": -1,
      "y": 10,
      "z": 4,
      "name": "Plant_Coral_Block_Pink"
    },
    {
      "x": -1,
      "y": 11,
      "z": 4,
      "name": "Plant_Coral_Block_Pink"
    },
    {
      "x": -1,
      "y": 12,
      "z": 4,
      "name": "Rock_Volcanic_Cracked_Lava"
    },
    {
      "x": -1,
      "y": 4,
      "z": 5,
      "name": "Plant_Coral_Block_Orange"
    },
    {
      "x": -1,
      "y": 5,
      "z": 5,
      "name": "Plant_Coral_Block_Orange"
    },
    {
      "x": -1,
      "y": 6,
      "z": 5,
      "name": "Plant_Coral_Block_Orange"
    },
    {
      "x": -1,
      "y": 7,
      "z": 5,
      "name": "Plant_Coral_Block_Pink"
    },
    {
      "x": -1,
      "y": 8,
      "z": 5,
      "name": "Plant_Coral_Block_Orange"
    },
    {
      "x": -1,
      "y": 9,
      "z": 5,
      "name": "Plant_Coral_Block_Orange"
    },
    {
      "x": -1,
      "y": 10,
      "z": 5,
      "name": "Plant_Coral_Block_Pink"
    },
    {
      "x": -1,
      "y": 11,
      "z": 5,
      "name": "Plant_Coral_Block_Pink"
    },
    {
      "x": -1,
      "y": 12,
      "z": 5,
      "name": "Rock_Volcanic_Cracked_Incandescent"
    },
    {
      "x": -1,
      "y": 7,
      "z": 6,
      "name": "Plant_Coral_Block_Orange"
    },
    {
      "x": -1,
      "y": 8,
      "z": 6,
      "name": "Plant_Coral_Block_Orange"
    },
    {
      "x": -1,
      "y": 9,
      "z": 6,
      "name": "Plant_Coral_Block_Orange"
    },
    {
      "x": -1,
      "y": 10,
      "z": 6,
      "name": "Plant_Coral_Block_Orange"
    },
    {
      "x": -1,
      "y": 11,
      "z": 6,
      "name": "Plant_Coral_Block_Pink"
    },
    {
      "x": -1,
      "y": 12,
      "z": 6,
      "name": "Plant_Coral_Block_Pink"
    },
    {
      "x": -1,
      "y": 13,
      "z": 6,
      "name": "Rock_Volcanic_Cracked_Incandescent"
    },
    {
      "x": -1,
      "y": 10,
      "z": 7,
      "name": "Plant_Coral_Block_Orange"
    },
    {
      "x": -1,
      "y": 11,
      "z": 7,
      "name": "Plant_Coral_Block_Orange"
    },
    {
      "x": -1,
      "y": 12,
      "z": 7,
      "name": "Plant_Coral_Block_Pink"
    },
    {
      "x": -1,
      "y": 13,
      "z": 7,
      "name": "Plant_Coral_Block_Pink"
    },
    {
      "x": -1,
      "y": 14,
      "z": 7,
      "name": "Plant_Coral_Block_Pink"
    },
    {
      "x": 0,
      "y": 12,
      "z": -7,
      "name": "Plant_Coral_Block_Orange"
    },
    {
      "x": 0,
      "y": 13,
      "z": -7,
      "name": "Plant_Coral_Block_Orange"
    },
    {
      "x": 0,
      "y": 14,
      "z": -7,
      "name": "Plant_Coral_Block_Orange"
    },
    {
      "x": 0,
      "y": 15,
      "z": -7,
      "name": "Plant_Coral_Block_Pink"
    },
    {
      "x": 0,
      "y": 16,
      "z": -7,
      "name": "Plant_Coral_Block_Pink"
    },
    {
      "x": 0,
      "y": 17,
      "z": -7,
      "name": "Plant_Coral_Block_Pink"
    },
    {
      "x": 0,
      "y": 8,
      "z": -6,
      "name": "Plant_Coral_Block_Pink"
    },
    {
      "x": 0,
      "y": 9,
      "z": -6,
      "name": "Plant_Coral_Block_Orange"
    },
    {
      "x": 0,
      "y": 10,
      "z": -6,
      "name": "Plant_Coral_Block_Orange"
    },
    {
      "x": 0,
      "y": 11,
      "z": -6,
      "name": "Plant_Coral_Block_Orange"
    },
    {
      "x": 0,
      "y": 12,
      "z": -6,
      "name": "Plant_Coral_Block_Orange"
    },
    {
      "x": 0,
      "y": 13,
      "z": -6,
      "name": "Plant_Coral_Block_Orange"
    },
    {
      "x": 0,
      "y": 14,
      "z": -6,
      "name": "Plant_Coral_Block_Pink"
    },
    {
      "x": 0,
      "y": 15,
      "z": -6,
      "name": "Plant_Coral_Block_Pink"
    },
    {
      "x": 0,
      "y": 16,
      "z": -6,
      "name": "Rock_Volcanic"
    },
    {
      "x": 0,
      "y": 4,
      "z": -5,
      "name": "Plant_Coral_Block_Orange"
    },
    {
      "x": 0,
      "y": 5,
      "z": -5,
      "name": "Plant_Coral_Block_Orange"
    },
    {
      "x": 0,
      "y": 6,
      "z": -5,
      "name": "Plant_Coral_Block_Pink"
    },
    {
      "x": 0,
      "y": 7,
      "z": -5,
      "name": "Plant_Coral_Block_Pink"
    },
    {
      "x": 0,
      "y": 8,
      "z": -5,
      "name": "Plant_Coral_Block_Pink"
    },
    {
      "x": 0,
      "y": 9,
      "z": -5,
      "name": "Plant_Coral_Block_Orange"
    },
    {
      "x": 0,
      "y": 10,
      "z": -5,
      "name": "Plant_Coral_Block_Orange"
    },
    {
      "x": 0,
      "y": 11,
      "z": -5,
      "name": "Plant_Coral_Block_Orange"
    },
    {
      "x": 0,
      "y": 12,
      "z": -5,
      "name": "Plant_Coral_Block_Orange"
    },
    {
      "x": 0,
      "y": 13,
      "z": -5,
      "name": "Plant_Coral_Block_Orange"
    },
    {
      "x": 0,
      "y": 14,
      "z": -5,
      "name": "Plant_Coral_Block_Pink"
    },
    {
      "x": 0,
      "y": 15,
      "z": -5,
      "name": "Plant_Coral_Block_Pink"
    },
    {
      "x": 0,
      "y": 16,
      "z": -5,
      "name": "Rock_Volcanic_Cracked_Incandescent"
    },
    {
      "x": 0,
      "y": 4,
      "z": -4,
      "name": "Plant_Coral_Block_Orange"
    },
    {
      "x": 0,
      "y": 5,
      "z": -4,
      "name": "Plant_Coral_Block_Pink"
    },
    {
      "x": 0,
      "y": 6,
      "z": -4,
      "name": "Plant_Coral_Block_Pink"
    },
    {
      "x": 0,
      "y": 7,
      "z": -4,
      "name": "Plant_Coral_Block_Pink"
    },
    {
      "x": 0,
      "y": 8,
      "z": -4,
      "name": "Plant_Coral_Block_Pink"
    },
    {
      "x": 0,
      "y": 9,
      "z": -4,
      "name": "Plant_Coral_Block_Orange"
    },
    {
      "x": 0,
      "y": 10,
      "z": -4,
      "name": "Plant_Coral_Block_Orange"
    },
    {
      "x": 0,
      "y": 11,
      "z": -4,
      "name": "Plant_Coral_Block_Pink"
    },
    {
      "x": 0,
      "y": 12,
      "z": -4,
      "name": "Plant_Coral_Block_Pink"
    },
    {
      "x": 0,
      "y": 13,
      "z": -4,
      "name": "Plant_Coral_Block_Pink"
    },
    {
      "x": 0,
      "y": 14,
      "z": -4,
      "name": "Plant_Coral_Block_Pink"
    },
    {
      "x": 0,
      "y": 15,
      "z": -4,
      "name": "Rock_Volcanic_Cracked_Lava"
    },
    {
      "x": 0,
      "y": 3,
      "z": -3,
      "name": "Plant_Coral_Block_Orange"
    },
    {
      "x": 0,
      "y": 4,
      "z": -3,
      "name": "Plant_Coral_Block_Orange"
    },
    {
      "x": 0,
      "y": 5,
      "z": -3,
      "name": "Plant_Coral_Block_Pink"
    },
    {
      "x": 0,
      "y": 6,
      "z": -3,
      "name": "Plant_Coral_Block_Pink"
    },
    {
      "x": 0,
      "y": 7,
      "z": -3,
      "name": "Plant_Coral_Block_Pink"
    },
    {
      "x": 0,
      "y": 8,
      "z": -3,
      "name": "Plant_Coral_Block_Pink"
    },
    {
      "x": 0,
      "y": 9,
      "z": -3,
      "name": "Plant_Coral_Block_Orange"
    },
    {
      "x": 0,
      "y": 10,
      "z": -3,
      "name": "Plant_Coral_Block_Pink"
    },
    {
      "x": 0,
      "y": 11,
      "z": -3,
      "name": "Plant_Coral_Block_Pink"
    },
    {
      "x": 0,
      "y": 12,
      "z": -3,
      "name": "Plant_Coral_Block_Pink"
    },
    {
      "x": 0,
      "y": 13,
      "z": -3,
      "name": "Plant_Coral_Block_Pink"
    },
    {
      "x": 0,
      "y": 14,
      "z": -3,
      "name": "Plant_Coral_Block_Pink"
    },
    {
      "x": 0,
      "y": 15,
      "z": -3,
      "name": "Rock_Volcanic_Cracked_Incandescent"
    },
    {
      "x": 0,
      "y": 3,
      "z": -2,
      "name": "Plant_Coral_Block_Orange"
    },
    {
      "x": 0,
      "y": 4,
      "z": -2,
      "name": "Plant_Coral_Block_Orange"
    },
    {
      "x": 0,
      "y": 5,
      "z": -2,
      "name": "Plant_Coral_Block_Orange"
    },
    {
      "x": 0,
      "y": 6,
      "z": -2,
      "name": "Plant_Coral_Block_Pink"
    },
    {
      "x": 0,
      "y": 7,
      "z": -2,
      "name": "Plant_Coral_Block_Pink"
    },
    {
      "x": 0,
      "y": 8,
      "z": -2,
      "name": "Plant_Coral_Block_Orange"
    },
    {
      "x": 0,
      "y": 9,
      "z": -2,
      "name": "Plant_Coral_Block_Pink"
    },
    {
      "x": 0,
      "y": 10,
      "z": -2,
      "name": "Plant_Coral_Block_Pink"
    },
    {
      "x": 0,
      "y": 11,
      "z": -2,
      "name": "Plant_Coral_Block_Pink"
    },
    {
      "x": 0,
      "y": 12,
      "z": -2,
      "name": "Plant_Coral_Block_Pink"
    },
    {
      "x": 0,
      "y": 13,
      "z": -2,
      "name": "Plant_Coral_Block_Pink"
    },
    {
      "x": 0,
      "y": 14,
      "z": -2,
      "name": "Plant_Coral_Block_Pink"
    },
    {
      "x": 0,
      "y": 15,
      "z": -2,
      "name": "Plant_Coral_Block_Pink"
    },
    {
      "x": 0,
      "y": 16,
      "z": -2,
      "name": "Rock_Volcanic"
    },
    {
      "x": 0,
      "y": 3,
      "z": -1,
      "name": "Plant_Coral_Block_Orange"
    },
    {
      "x": 0,
      "y": 4,
      "z": -1,
      "name": "Plant_Coral_Block_Orange"
    },
    {
      "x": 0,
      "y": 5,
      "z": -1,
      "name": "Plant_Coral_Block_Orange"
    },
    {
      "x": 0,
      "y": 6,
      "z": -1,
      "name": "Plant_Coral_Block_Orange"
    },
    {
      "x": 0,
      "y": 7,
      "z": -1,
      "name": "Plant_Coral_Block_Orange"
    },
    {
      "x": 0,
      "y": 8,
      "z": -1,
      "name": "Plant_Coral_Block_Pink"
    },
    {
      "x": 0,
      "y": 9,
      "z": -1,
      "name": "Plant_Coral_Block_Pink"
    },
    {
      "x": 0,
      "y": 10,
      "z": -1,
      "name": "Rock_Volcanic"
    },
    {
      "x": 0,
      "y": 13,
      "z": -1,
      "name": "Plant_Coral_Block_Pink"
    },
    {
      "x": 0,
      "y": 14,
      "z": -1,
      "name": "Plant_Coral_Block_Pink"
    },
    {
      "x": 0,
      "y": 15,
      "z": -1,
      "name": "Plant_Coral_Block_Pink"
    },
    {
      "x": 0,
      "y": 16,
      "z": -1,
      "name": "Rock_Volcanic_Cracked_Lava"
    },
    {
      "x": 0,
      "y": 0,
      "z": 0,
      "name": "Plant_Coral_Block_Orange"
    },
    {
      "x": 0,
      "y": 1,
      "z": 0,
      "name": "Plant_Coral_Block_Orange"
    },
    {
      "x": 0,
      "y": 2,
      "z": 0,
      "name": "Plant_Coral_Block_Orange"
    },
    {
      "x": 0,
      "y": 3,
      "z": 0,
      "name": "Plant_Coral_Block_Orange"
    },
    {
      "x": 0,
      "y": 4,
      "z": 0,
      "name": "Plant_Coral_Block_Orange"
    },
    {
      "x": 0,
      "y": 5,
      "z": 0,
      "name": "Plant_Coral_Block_Orange"
    },
    {
      "x": 0,
      "y": 6,
      "z": 0,
      "name": "Plant_Coral_Block_Orange"
    },
    {
      "x": 0,
      "y": 7,
      "z": 0,
      "name": "Plant_Coral_Block_Orange"
    },
    {
      "x": 0,
      "y": 8,
      "z": 0,
      "name": "Plant_Coral_Block_Pink"
    },
    {
      "x": 0,
      "y": 9,
      "z": 0,
      "name": "Plant_Coral_Block_Pink"
    },
    {
      "x": 0,
      "y": 10,
      "z": 0,
      "name": "Rock_Volcanic"
    },
    {
      "x": 0,
      "y": 14,
      "z": 0,
      "name": "Plant_Coral_Block_Pink"
    },
    {
      "x": 0,
      "y": 15,
      "z": 0,
      "name": "Plant_Coral_Block_Pink"
    },
    {
      "x": 0,
      "y": 16,
      "z": 0,
      "name": "Rock_Volcanic"
    },
    {
      "x": 0,
      "y": 0,
      "z": 1,
      "name": "Plant_Coral_Block_Orange"
    },
    {
      "x": 0,
      "y": 1,
      "z": 1,
      "name": "Plant_Coral_Block_Orange"
    },
    {
      "x": 0,
      "y": 2,
      "z": 1,
      "name": "Plant_Coral_Block_Orange"
    },
    {
      "x": 0,
      "y": 3,
      "z": 1,
      "name": "Plant_Coral_Block_Orange"
    },
    {
      "x": 0,
      "y": 4,
      "z": 1,
      "name": "Plant_Coral_Block_Orange"
    },
    {
      "x": 0,
      "y": 5,
      "z": 1,
      "name": "Plant_Coral_Block_Orange"
    },
    {
      "x": 0,
      "y": 6,
      "z": 1,
      "name": "Plant_Coral_Block_Orange"
    },
    {
      "x": 0,
      "y": 7,
      "z": 1,
      "name": "Plant_Coral_Block_Orange"
    },
    {
      "x": 0,
      "y": 8,
      "z": 1,
      "name": "Plant_Coral_Block_Orange"
    },
    {
      "x": 0,
      "y": 9,
      "z": 1,
      "name": "Plant_Coral_Block_Pink"
    },
    {
      "x": 0,
      "y": 10,
      "z": 1,
      "name": "Plant_Coral_Block_Pink"
    },
    {
      "x": 0,
      "y": 11,
      "z": 1,
      "name": "Rock_Volcanic"
    },
    {
      "x": 0,
      "y": 15,
      "z": 1,
      "name": "Plant_Coral_Block_Pink"
    },
    {
      "x": 0,
      "y": 16,
      "z": 1,
      "name": "Plant_Coral_Block_Pink"
    },
    {
      "x": 0,
      "y": 17,
      "z": 1,
      "name": "Plant_Coral_Block_Pink"
    },
    {
      "x": 0,
      "y": 0,
      "z": 2,
      "name": "Plant_Coral_Block_Orange"
    },
    {
      "x": 0,
      "y": 1,
      "z": 2,
      "name": "Plant_Coral_Block_Orange"
    },
    {
      "x": 0,
      "y": 2,
      "z": 2,
      "name": "Plant_Coral_Block_Orange"
    },
    {
      "x": 0,
      "y": 3,
      "z": 2,
      "name": "Plant_Coral_Block_Orange"
    },
    {
      "x": 0,
      "y": 4,
      "z": 2,
      "name": "Plant_Coral_Block_Orange"
    },
    {
      "x": 0,
      "y": 5,
      "z": 2,
      "name": "Plant_Coral_Block_Orange"
    },
    {
      "x": 0,
      "y": 6,
      "z": 2,
      "name": "Plant_Coral_Block_Orange"
    },
    {
      "x": 0,
      "y": 7,
      "z": 2,
      "name": "Plant_Coral_Block_Orange"
    },
    {
      "x": 0,
      "y": 8,
      "z": 2,
      "name": "Plant_Coral_Block_Orange"
    },
    {
      "x": 0,
      "y": 9,
      "z": 2,
      "name": "Plant_Coral_Block_Pink"
    },
    {
      "x": 0,
      "y": 10,
      "z": 2,
      "name": "Plant_Coral_Block_Pink"
    },
    {
      "x": 0,
      "y": 11,
      "z": 2,
      "name": "Rock_Volcanic_Cracked_Incandescent"
    },
    {
      "x": 0,
      "y": 16,
      "z": 2,
      "name": "Plant_Coral_Block_Pink"
    },
    {
      "x": 0,
      "y": 17,
      "z": 2,
      "name": "Plant_Coral_Block_Pink"
    },
    {
      "x": 0,
      "y": 0,
      "z": 3,
      "name": "Plant_Coral_Block_Orange"
    },
    {
      "x": 0,
      "y": 1,
      "z": 3,
      "name": "Plant_Coral_Block_Orange"
    },
    {
      "x": 0,
      "y": 2,
      "z": 3,
      "name": "Plant_Coral_Block_Orange"
    },
    {
      "x": 0,
      "y": 3,
      "z": 3,
      "name": "Plant_Coral_Block_Orange"
    },
    {
      "x": 0,
      "y": 4,
      "z": 3,
      "name": "Plant_Coral_Block_Orange"
    },
    {
      "x": 0,
      "y": 5,
      "z": 3,
      "name": "Plant_Coral_Block_Orange"
    },
    {
      "x": 0,
      "y": 6,
      "z": 3,
      "name": "Plant_Coral_Block_Orange"
    },
    {
      "x": 0,
      "y": 7,
      "z": 3,
      "name": "Plant_Coral_Block_Orange"
    },
    {
      "x": 0,
      "y": 8,
      "z": 3,
      "name": "Plant_Coral_Block_Orange"
    },
    {
      "x": 0,
      "y": 9,
      "z": 3,
      "name": "Plant_Coral_Block_Orange"
    },
    {
      "x": 0,
      "y": 10,
      "z": 3,
      "name": "Plant_Coral_Block_Pink"
    },
    {
      "x": 0,
      "y": 11,
      "z": 3,
      "name": "Plant_Coral_Block_Pink"
    },
    {
      "x": 0,
      "y": 12,
      "z": 3,
      "name": "Rock_Volcanic_Cracked_Incandescent"
    },
    {
      "x": 0,
      "y": 0,
      "z": 4,
      "name": "Plant_Coral_Block_Orange"
    },
    {
      "x": 0,
      "y": 1,
      "z": 4,
      "name": "Plant_Coral_Block_Orange"
    },
    {
      "x": 0,
      "y": 2,
      "z": 4,
      "name": "Plant_Coral_Block_Orange"
    },
    {
      "x": 0,
      "y": 3,
      "z": 4,
      "name": "Plant_Coral_Block_Orange"
    },
    {
      "x": 0,
      "y": 4,
      "z": 4,
      "name": "Plant_Coral_Block_Orange"
    },
    {
      "x": 0,
      "y": 5,
      "z": 4,
      "name": "Plant_Coral_Block_Orange"
    },
    {
      "x": 0,
      "y": 6,
      "z": 4,
      "name": "Plant_Coral_Block_Orange"
    },
    {
      "x": 0,
      "y": 7,
      "z": 4,
      "name": "Plant_Coral_Block_Orange"
    },
    {
      "x": 0,
      "y": 8,
      "z": 4,
      "name": "Plant_Coral_Block_Orange"
    },
    {
      "x": 0,
      "y": 9,
      "z": 4,
      "name": "Plant_Coral_Block_Orange"
    },
    {
      "x": 0,
      "y": 10,
      "z": 4,
      "name": "Plant_Coral_Block_Pink"
    },
    {
      "x": 0,
      "y": 11,
      "z": 4,
      "name": "Plant_Coral_Block_Pink"
    },
    {
      "x": 0,
      "y": 12,
      "z": 4,
      "name": "Rock_Volcanic_Cracked_Incandescent"
    },
    {
      "x": 0,
      "y": 4,
      "z": 5,
      "name": "Plant_Coral_Block_Orange"
    },
    {
      "x": 0,
      "y": 5,
      "z": 5,
      "name": "Plant_Coral_Block_Orange"
    },
    {
      "x": 0,
      "y": 6,
      "z": 5,
      "name": "Plant_Coral_Block_Orange"
    },
    {
      "x": 0,
      "y": 7,
      "z": 5,
      "name": "Plant_Coral_Block_Orange"
    },
    {
      "x": 0,
      "y": 8,
      "z": 5,
      "name": "Plant_Coral_Block_Orange"
    },
    {
      "x": 0,
      "y": 9,
      "z": 5,
      "name": "Plant_Coral_Block_Orange"
    },
    {
      "x": 0,
      "y": 10,
      "z": 5,
      "name": "Plant_Coral_Block_Pink"
    },
    {
      "x": 0,
      "y": 11,
      "z": 5,
      "name": "Plant_Coral_Block_Pink"
    },
    {
      "x": 0,
      "y": 12,
      "z": 5,
      "name": "Rock_Volcanic"
    },
    {
      "x": 0,
      "y": 6,
      "z": 6,
      "name": "Plant_Coral_Block_Orange"
    },
    {
      "x": 0,
      "y": 7,
      "z": 6,
      "name": "Plant_Coral_Block_Orange"
    },
    {
      "x": 0,
      "y": 8,
      "z": 6,
      "name": "Plant_Coral_Block_Orange"
    },
    {
      "x": 0,
      "y": 9,
      "z": 6,
      "name": "Plant_Coral_Block_Orange"
    },
    {
      "x": 0,
      "y": 10,
      "z": 6,
      "name": "Plant_Coral_Block_Orange"
    },
    {
      "x": 0,
      "y": 11,
      "z": 6,
      "name": "Plant_Coral_Block_Pink"
    },
    {
      "x": 0,
      "y": 12,
      "z": 6,
      "name": "Plant_Coral_Block_Pink"
    },
    {
      "x": 0,
      "y": 13,
      "z": 6,
      "name": "Rock_Volcanic_Cracked_Lava"
    },
    {
      "x": 0,
      "y": 9,
      "z": 7,
      "name": "Plant_Coral_Block_Orange"
    },
    {
      "x": 0,
      "y": 10,
      "z": 7,
      "name": "Plant_Coral_Block_Orange"
    },
    {
      "x": 0,
      "y": 11,
      "z": 7,
      "name": "Plant_Coral_Block_Orange"
    },
    {
      "x": 0,
      "y": 12,
      "z": 7,
      "name": "Plant_Coral_Block_Pink"
    },
    {
      "x": 0,
      "y": 13,
      "z": 7,
      "name": "Plant_Coral_Block_Pink"
    },
    {
      "x": 0,
      "y": 14,
      "z": 7,
      "name": "Plant_Coral_Block_Pink"
    },
    {
      "x": 1,
      "y": 13,
      "z": -7,
      "name": "Plant_Coral_Block_Orange"
    },
    {
      "x": 1,
      "y": 14,
      "z": -7,
      "name": "Plant_Coral_Block_Orange"
    },
    {
      "x": 1,
      "y": 15,
      "z": -7,
      "name": "Plant_Coral_Block_Orange"
    },
    {
      "x": 1,
      "y": 16,
      "z": -7,
      "name": "Plant_Coral_Block_Pink"
    },
    {
      "x": 1,
      "y": 5,
      "z": -6,
      "name": "Plant_Coral_Block_Orange"
    },
    {
      "x": 1,
      "y": 6,
      "z": -6,
      "name": "Plant_Coral_Block_Pink"
    },
    {
      "x": 1,
      "y": 7,
      "z": -6,
      "name": "Plant_Coral_Block_Pink"
    },
    {
      "x": 1,
      "y": 9,
      "z": -6,
      "name": "Plant_Coral_Block_Orange"
    },
    {
      "x": 1,
      "y": 10,
      "z": -6,
      "name": "Plant_Coral_Block_Orange"
    },
    {
      "x": 1,
      "y": 11,
      "z": -6,
      "name": "Plant_Coral_Block_Orange"
    },
    {
      "x": 1,
      "y": 12,
      "z": -6,
      "name": "Plant_Coral_Block_Orange"
    },
    {
      "x": 1,
      "y": 13,
      "z": -6,
      "name": "Plant_Coral_Block_Orange"
    },
    {
      "x": 1,
      "y": 14,
      "z": -6,
      "name": "Plant_Coral_Block_Orange"
    },
    {
      "x": 1,
      "y": 15,
      "z": -6,
      "name": "Plant_Coral_Block_Pink"
    },
    {
      "x": 1,
      "y": 16,
      "z": -6,
      "name": "Plant_Coral_Block_Pink"
    },
    {
      "x": 1,
      "y": 17,
      "z": -6,
      "name": "Plant_Coral_Block_Pink"
    },
    {
      "x": 1,
      "y": 3,
      "z": -5,
      "name": "Plant_Coral_Block_Orange"
    },
    {
      "x": 1,
      "y": 4,
      "z": -5,
      "name": "Plant_Coral_Block_Orange"
    },
    {
      "x": 1,
      "y": 5,
      "z": -5,
      "name": "Plant_Coral_Block_Pink"
    },
    {
      "x": 1,
      "y": 6,
      "z": -5,
      "name": "Plant_Coral_Block_Pink"
    },
    {
      "x": 1,
      "y": 7,
      "z": -5,
      "name": "Plant_Coral_Block_Pink"
    },
    {
      "x": 1,
      "y": 8,
      "z": -5,
      "name": "Plant_Coral_Block_Pink"
    },
    {
      "x": 1,
      "y": 9,
      "z": -5,
      "name": "Plant_Coral_Block_Pink"
    },
    {
      "x": 1,
      "y": 10,
      "z": -5,
      "name": "Plant_Coral_Block_Orange"
    },
    {
      "x": 1,
      "y": 11,
      "z": -5,
      "name": "Plant_Coral_Block_Orange"
    },
    {
      "x": 1,
      "y": 12,
      "z": -5,
      "name": "Plant_Coral_Block_Orange"
    },
    {
      "x": 1,
      "y": 13,
      "z": -5,
      "name": "Plant_Coral_Block_Orange"
    },
    {
      "x": 1,
      "y": 14,
      "z": -5,
      "name": "Plant_Coral_Block_Pink"
    },
    {
      "x": 1,
      "y": 15,
      "z": -5,
      "name": "Plant_Coral_Block_Pink"
    },
    {
      "x": 1,
      "y": 16,
      "z": -5,
      "name": "Rock_Volcanic_Cracked_Incandescent"
    },
    {
      "x": 1,
      "y": 0,
      "z": -4,
      "name": "Plant_Coral_Block_Pink"
    },
    {
      "x": 1,
      "y": 1,
      "z": -4,
      "name": "Plant_Coral_Block_Pink"
    },
    {
      "x": 1,
      "y": 2,
      "z": -4,
      "name": "Plant_Coral_Block_Pink"
    },
    {
      "x": 1,
      "y": 3,
      "z": -4,
      "name": "Plant_Coral_Block_Orange"
    },
    {
      "x": 1,
      "y": 4,
      "z": -4,
      "name": "Plant_Coral_Block_Pink"
    },
    {
      "x": 1,
      "y": 5,
      "z": -4,
      "name": "Plant_Coral_Block_Pink"
    },
    {
      "x": 1,
      "y": 6,
      "z": -4,
      "name": "Plant_Coral_Block_Pink"
    },
    {
      "x": 1,
      "y": 7,
      "z": -4,
      "name": "Plant_Coral_Block_Pink"
    },
    {
      "x": 1,
      "y": 8,
      "z": -4,
      "name": "Plant_Coral_Block_Pink"
    },
    {
      "x": 1,
      "y": 9,
      "z": -4,
      "name": "Plant_Coral_Block_Pink"
    },
    {
      "x": 1,
      "y": 10,
      "z": -4,
      "name": "Plant_Coral_Block_Orange"
    },
    {
      "x": 1,
      "y": 11,
      "z": -4,
      "name": "Plant_Coral_Block_Orange"
    },
    {
      "x": 1,
      "y": 12,
      "z": -4,
      "name": "Plant_Coral_Block_Orange"
    },
    {
      "x": 1,
      "y": 13,
      "z": -4,
      "name": "Plant_Coral_Block_Pink"
    },
    {
      "x": 1,
      "y": 14,
      "z": -4,
      "name": "Plant_Coral_Block_Pink"
    },
    {
      "x": 1,
      "y": 15,
      "z": -4,
      "name": "Rock_Volcanic_Cracked_Incandescent"
    },
    {
      "x": 1,
      "y": 0,
      "z": -3,
      "name": "Plant_Coral_Block_Pink"
    },
    {
      "x": 1,
      "y": 1,
      "z": -3,
      "name": "Plant_Coral_Block_Pink"
    },
    {
      "x": 1,
      "y": 2,
      "z": -3,
      "name": "Plant_Coral_Block_Pink"
    },
    {
      "x": 1,
      "y": 3,
      "z": -3,
      "name": "Plant_Coral_Block_Orange"
    },
    {
      "x": 1,
      "y": 4,
      "z": -3,
      "name": "Plant_Coral_Block_Pink"
    },
    {
      "x": 1,
      "y": 5,
      "z": -3,
      "name": "Plant_Coral_Block_Pink"
    },
    {
      "x": 1,
      "y": 6,
      "z": -3,
      "name": "Plant_Coral_Block_Pink"
    },
    {
      "x": 1,
      "y": 7,
      "z": -3,
      "name": "Plant_Coral_Block_Pink"
    },
    {
      "x": 1,
      "y": 8,
      "z": -3,
      "name": "Plant_Coral_Block_Pink"
    },
    {
      "x": 1,
      "y": 9,
      "z": -3,
      "name": "Plant_Coral_Block_Pink"
    },
    {
      "x": 1,
      "y": 10,
      "z": -3,
      "name": "Plant_Coral_Block_Orange"
    },
    {
      "x": 1,
      "y": 11,
      "z": -3,
      "name": "Plant_Coral_Block_Pink"
    },
    {
      "x": 1,
      "y": 12,
      "z": -3,
      "name": "Plant_Coral_Block_Pink"
    },
    {
      "x": 1,
      "y": 13,
      "z": -3,
      "name": "Plant_Coral_Block_Pink"
    },
    {
      "x": 1,
      "y": 14,
      "z": -3,
      "name": "Plant_Coral_Block_Pink"
    },
    {
      "x": 1,
      "y": 15,
      "z": -3,
      "name": "Rock_Volcanic"
    },
    {
      "x": 1,
      "y": 0,
      "z": -2,
      "name": "Plant_Coral_Block_Orange"
    },
    {
      "x": 1,
      "y": 1,
      "z": -2,
      "name": "Plant_Coral_Block_Orange"
    },
    {
      "x": 1,
      "y": 2,
      "z": -2,
      "name": "Plant_Coral_Block_Orange"
    },
    {
      "x": 1,
      "y": 3,
      "z": -2,
      "name": "Plant_Coral_Block_Orange"
    },
    {
      "x": 1,
      "y": 4,
      "z": -2,
      "name": "Plant_Coral_Block_Orange"
    },
    {
      "x": 1,
      "y": 5,
      "z": -2,
      "name": "Plant_Coral_Block_Pink"
    },
    {
      "x": 1,
      "y": 6,
      "z": -2,
      "name": "Plant_Coral_Block_Pink"
    },
    {
      "x": 1,
      "y": 7,
      "z": -2,
      "name": "Plant_Coral_Block_Pink"
    },
    {
      "x": 1,
      "y": 8,
      "z": -2,
      "name": "Plant_Coral_Block_Pink"
    },
    {
      "x": 1,
      "y": 9,
      "z": -2,
      "name": "Plant_Coral_Block_Orange"
    },
    {
      "x": 1,
      "y": 10,
      "z": -2,
      "name": "Plant_Coral_Block_Pink"
    },
    {
      "x": 1,
      "y": 11,
      "z": -2,
      "name": "Plant_Coral_Block_Pink"
    },
    {
      "x": 1,
      "y": 12,
      "z": -2,
      "name": "Plant_Coral_Block_Pink"
    },
    {
      "x": 1,
      "y": 13,
      "z": -2,
      "name": "Plant_Coral_Block_Pink"
    },
    {
      "x": 1,
      "y": 14,
      "z": -2,
      "name": "Plant_Coral_Block_Pink"
    },
    {
      "x": 1,
      "y": 15,
      "z": -2,
