{
  "version": 8,
  "blockIdVersion": 11,
  "anchorX": -13,
  "anchorY": 5,
  "anchorZ": -13,
  "blocks": [
    {
      "x": -13,
      "y": 5,
      "z": 7,
      "name": "Rock_Sandstone_Brick_Smooth_Half",
      "rotation": 7
    },
    {
      "x": -13,
      "y": 6,
      "z": 7,
      "name": "Rock_Sandstone_Brick_Smooth_Half",
      "rotation": 7
    },
    {
      "x": -13,
      "y": 7,
      "z": 7,
      "name": "Rock_Sandstone_Brick_Smooth_Half",
      "rotation": 7
    },
    {
      "x": -13,
      "y": 8,
      "z": 7,
      "name": "Rock_Sandstone_Brick_Smooth_Half",
      "rotation": 7
    },
    {
      "x": -13,
      "y": 9,
      "z": 7,
      "name": "Rock_Sandstone_Brick_Smooth_Half",
      "rotation": 7
    },
    {
      "x": -13,
      "y": 5,
      "z": 8,
      "name": "Rock_Sandstone_Brick_Smooth_Half",
      "rotation": 7
    },
    {
      "x": -13,
      "y": 6,
      "z": 8,
      "name": "Rock_Sandstone_Brick_Smooth_Half",
      "rotation": 7
    },
    {
      "x": -13,
      "y": 7,
      "z": 8,
      "name": "Rock_Sandstone_Brick_Smooth_Half",
      "rotation": 7
    },
    {
      "x": -13,
      "y": 8,
      "z": 8,
      "name": "Rock_Sandstone_Brick_Smooth_Half",
      "rotation": 7
    },
    {
      "x": -13,
      "y": 9,
      "z": 8,
      "name": "Rock_Sandstone_Brick_Smooth_Half",
      "rotation": 7
    },
    {
      "x": -13,
      "y": 5,
      "z": 9,
      "name": "Rock_Sandstone_Brick_Smooth_Half",
      "rotation": 7
    },
    {
      "x": -13,
      "y": 6,
      "z": 9,
      "name": "Rock_Sandstone_Brick_Smooth_Half",
      "rotation": 7
    },
    {
      "x": -13,
      "y": 7,
      "z": 9,
      "name": "Rock_Sandstone_Brick_Smooth_Half",
      "rotation": 7
    },
    {
      "x": -13,
      "y": 8,
      "z": 9,
      "name": "Rock_Sandstone_Brick_Smooth_Half",
      "rotation": 7
    },
    {
      "x": -13,
      "y": 9,
      "z": 9,
      "name": "Rock_Sandstone_Brick_Smooth_Half",
      "rotation": 7
    },
    {
      "x": -12,
      "y": 11,
      "z": 6,
      "name": "Wood_Dry_Branch_Short",
      "rotation": 3
    },
    {
      "x": -12,
      "y": 19,
      "z": 6,
      "name": "Rock_Sandstone_Brick_Smooth_Half",
      "rotation": 7
    },
    {
      "x": -12,
      "y": 5,
      "z": 7,
      "name": "Rock_Sandstone_Brick_Smooth"
    },
    {
      "x": -12,
      "y": 6,
      "z": 7,
      "name": "Rock_Sandstone_Brick_Smooth"
    },
    {
      "x": -12,
      "y": 7,
      "z": 7,
      "name": "Rock_Sandstone_Brick_Smooth"
    },
    {
      "x": -12,
      "y": 8,
      "z": 7,
      "name": "Rock_Sandstone_Brick_Smooth"
    },
    {
      "x": -12,
      "y": 9,
      "z": 7,
      "name": "Rock_Sandstone_Brick_Smooth"
    },
    {
      "x": -12,
      "y": 10,
      "z": 7,
      "name": "Rock_Sandstone_Brick_Smooth"
    },
    {
      "x": -12,
      "y": 11,
      "z": 7,
      "name": "Rock_Sandstone_Brick_Smooth"
    },
    {
      "x": -12,
      "y": 12,
      "z": 7,
      "name": "Rock_Sandstone_Brick_Smooth"
    },
    {
      "x": -12,
      "y": 13,
      "z": 7,
      "name": "Rock_Sandstone_Brick_Smooth"
    },
    {
      "x": -12,
      "y": 18,
      "z": 7,
      "name": "Wood_Dry_Branch_Short",
      "rotation": 3
    },
    {
      "x": -12,
      "y": 19,
      "z": 7,
      "name": "Rock_Sandstone_Brick_Smooth_Half",
      "rotation": 7
    },
    {
      "x": -12,
      "y": 20,
      "z": 7,
      "name": "Rock_Sandstone_Brick_Smooth_Half",
      "rotation": 7
    },
    {
      "x": -12,
      "y": 5,
      "z": 8,
      "name": "Rock_Sandstone_Brick_Smooth"
    },
    {
      "x": -12,
      "y": 6,
      "z": 8,
      "name": "Rock_Sandstone_Brick_Smooth"
    },
    {
      "x": -12,
      "y": 7,
      "z": 8,
      "name": "Rock_Sandstone_Brick_Smooth"
    },
    {
      "x": -12,
      "y": 8,
      "z": 8,
      "name": "Rock_Sandstone_Brick_Smooth"
    },
    {
      "x": -12,
      "y": 9,
      "z": 8,
      "name": "Rock_Sandstone_Brick_Smooth"
    },
    {
      "x": -12,
      "y": 10,
      "z": 8,
      "name": "Rock_Sandstone_Brick_Smooth"
    },
    {
      "x": -12,
      "y": 11,
      "z": 8,
      "name": "Rock_Sandstone_Brick_Smooth"
    },
    {
      "x": -12,
      "y": 12,
      "z": 8,
      "name": "Rock_Sandstone_Brick_Smooth"
    },
    {
      "x": -12,
      "y": 13,
      "z": 8,
      "name": "Rock_Sandstone_Brick_Smooth"
    },
    {
      "x": -12,
      "y": 19,
      "z": 8,
      "name": "Rock_Sandstone_Brick_Smooth_Half",
      "rotation": 7
    },
    {
      "x": -12,
      "y": 5,
      "z": 9,
      "name": "Rock_Sandstone_Brick_Smooth"
    },
    {
      "x": -12,
      "y": 6,
      "z": 9,
      "name": "Rock_Sandstone_Brick_Smooth"
    },
    {
      "x": -12,
      "y": 7,
      "z": 9,
      "name": "Rock_Sandstone_Brick_Smooth"
    },
    {
      "x": -12,
      "y": 8,
      "z": 9,
      "name": "Rock_Sandstone_Brick_Smooth"
    },
    {
      "x": -12,
      "y": 9,
      "z": 9,
      "name": "Rock_Sandstone_Brick_Smooth"
    },
    {
      "x": -12,
      "y": 10,
      "z": 9,
      "name": "Rock_Sandstone_Brick_Smooth"
    },
    {
      "x": -12,
      "y": 11,
      "z": 9,
      "name": "Rock_Sandstone_Brick_Smooth"
    },
    {
      "x": -12,
      "y": 12,
      "z": 9,
      "name": "Rock_Sandstone_Brick_Smooth"
    },
    {
      "x": -12,
      "y": 13,
      "z": 9,
      "name": "Rock_Sandstone_Brick_Smooth"
    },
    {
      "x": -12,
      "y": 18,
      "z": 9,
      "name": "Wood_Dry_Branch_Short",
      "rotation": 3
    },
    {
      "x": -12,
      "y": 19,
      "z": 9,
      "name": "Rock_Sandstone_Brick_Smooth_Half",
      "rotation": 7
    },
    {
      "x": -12,
      "y": 20,
      "z": 9,
      "name": "Rock_Sandstone_Brick_Smooth_Half",
      "rotation": 7
    },
    {
      "x": -12,
      "y": 11,
      "z": 10,
      "name": "Wood_Dry_Branch_Short",
      "rotation": 3
    },
    {
      "x": -12,
      "y": 19,
      "z": 10,
      "name": "Rock_Sandstone_Brick_Smooth_Half",
      "rotation": 7
    },
    {
      "x": -12,
      "y": 18,
      "z": 11,
      "name": "Wood_Dry_Branch_Short",
      "rotation": 3
    },
    {
      "x": -12,
      "y": 19,
      "z": 11,
      "name": "Rock_Sandstone_Brick_Smooth_Half",
      "rotation": 7
    },
    {
      "x": -12,
      "y": 20,
      "z": 11,
      "name": "Rock_Sandstone_Brick_Smooth_Half",
      "rotation": 7
    },
    {
      "x": -11,
      "y": 9,
      "z": -9,
      "name": "Rock_Sandstone_Brick_Smooth_Half",
      "rotation": 7
    },
    {
      "x": -11,
      "y": 9,
      "z": -8,
      "name": "Rock_Sandstone_Brick_Smooth_Half",
      "rotation": 7
    },
    {
      "x": -11,
      "y": 9,
      "z": 0,
      "name": "Rock_Sandstone_Brick_Smooth_Half",
      "rotation": 7
    },
    {
      "x": -11,
      "y": 9,
      "z": 1,
      "name": "Rock_Sandstone_Brick_Smooth_Half",
      "rotation": 7
    },
    {
      "x": -11,
      "y": 9,
      "z": 2,
      "name": "Rock_Sandstone_Brick_Smooth_Half",
      "rotation": 7
    },
    {
      "x": -11,
      "y": 10,
      "z": 2,
      "name": "Rock_Sandstone_Brick_Smooth_Half",
      "rotation": 7
    },
    {
      "x": -11,
      "y": 9,
      "z": 3,
      "name": "Rock_Sandstone_Brick_Smooth_Half",
      "rotation": 7
    },
    {
      "x": -11,
      "y": 9,
      "z": 4,
      "name": "Rock_Sandstone_Brick_Smooth_Half",
      "rotation": 7
    },
    {
      "x": -11,
      "y": 10,
      "z": 4,
      "name": "Rock_Sandstone_Brick_Smooth_Half",
      "rotation": 7
    },
    {
      "x": -11,
      "y": 5,
      "z": 5,
      "name": "Rock_Sandstone_Cobble"
    },
    {
      "x": -11,
      "y": 6,
      "z": 5,
      "name": "Rock_Sandstone_Cobble"
    },
    {
      "x": -11,
      "y": 7,
      "z": 5,
      "name": "Rock_Sandstone_Cobble"
    },
    {
      "x": -11,
      "y": 8,
      "z": 5,
      "name": "Rock_Sandstone_Brick"
    },
    {
      "x": -11,
      "y": 9,
      "z": 5,
      "name": "Rock_Sandstone_Brick_Ornate"
    },
    {
      "x": -11,
      "y": 10,
      "z": 5,
      "name": "Rock_Sandstone_Brick"
    },
    {
      "x": -11,
      "y": 11,
      "z": 5,
      "name": "Rock_Sandstone_Brick"
    },
    {
      "x": -11,
      "y": 12,
      "z": 5,
      "name": "Rock_Sandstone_Brick"
    },
    {
      "x": -11,
      "y": 13,
      "z": 5,
      "name": "Rock_Sandstone_Brick"
    },
    {
      "x": -11,
      "y": 14,
      "z": 5,
      "name": "Rock_Sandstone_Brick"
    },
    {
      "x": -11,
      "y": 15,
      "z": 5,
      "name": "Rock_Sandstone_Brick"
    },
    {
      "x": -11,
      "y": 16,
      "z": 5,
      "name": "Rock_Sandstone_Brick"
    },
    {
      "x": -11,
      "y": 17,
      "z": 5,
      "name": "Rock_Sandstone_Brick"
    },
    {
      "x": -11,
      "y": 18,
      "z": 5,
      "name": "Rock_Sandstone_Brick_Half",
      "rotation": 7
    },
    {
      "x": -11,
      "y": 19,
      "z": 5,
      "name": "Rock_Sandstone_Brick_Half",
      "rotation": 7
    },
    {
      "x": -11,
      "y": 5,
      "z": 6,
      "name": "Rock_Sandstone_Cobble"
    },
    {
      "x": -11,
      "y": 6,
      "z": 6,
      "name": "Rock_Sandstone_Cobble"
    },
    {
      "x": -11,
      "y": 7,
      "z": 6,
      "name": "Rock_Sandstone_Cobble"
    },
    {
      "x": -11,
      "y": 8,
      "z": 6,
      "name": "Rock_Sandstone_Brick"
    },
    {
      "x": -11,
      "y": 9,
      "z": 6,
      "name": "Rock_Sandstone_Brick_Ornate"
    },
    {
      "x": -11,
      "y": 10,
      "z": 6,
      "name": "Rock_Sandstone_Brick"
    },
    {
      "x": -11,
      "y": 11,
      "z": 6,
      "name": "Rock_Sandstone_Brick"
    },
    {
      "x": -11,
      "y": 12,
      "z": 6,
      "name": "Rock_Sandstone_Brick"
    },
    {
      "x": -11,
      "y": 13,
      "z": 6,
      "name": "Rock_Sandstone_Brick"
    },
    {
      "x": -11,
      "y": 14,
      "z": 6,
      "name": "Rock_Sandstone_Brick"
    },
    {
      "x": -11,
      "y": 15,
      "z": 6,
      "name": "Rock_Sandstone_Brick"
    },
    {
      "x": -11,
      "y": 16,
      "z": 6,
      "name": "Rock_Sandstone_Brick"
    },
    {
      "x": -11,
      "y": 17,
      "z": 6,
      "name": "Rock_Sandstone_Brick"
    },
    {
      "x": -11,
      "y": 18,
      "z": 6,
      "name": "Rock_Sandstone_Brick"
    },
    {
      "x": -11,
      "y": 19,
      "z": 6,
      "name": "Rock_Sandstone_Brick_Smooth"
    },
    {
      "x": -11,
      "y": 20,
      "z": 6,
      "name": "Rock_Sandstone_Brick_Smooth_Half"
    },
    {
      "x": -11,
      "y": 5,
      "z": 7,
      "name": "Rock_Sandstone_Cobble"
    },
    {
      "x": -11,
      "y": 6,
      "z": 7,
      "name": "Rock_Sandstone_Cobble"
    },
    {
      "x": -11,
      "y": 7,
      "z": 7,
      "name": "Rock_Sandstone_Brick"
    },
    {
      "x": -11,
      "y": 8,
      "z": 7,
      "name": "Rock_Sandstone_Brick"
    },
    {
      "x": -11,
      "y": 9,
      "z": 7,
      "name": "Rock_Sandstone_Brick_Ornate"
    },
    {
      "x": -11,
      "y": 10,
      "z": 7,
      "name": "Rock_Sandstone_Brick"
    },
    {
      "x": -11,
      "y": 11,
      "z": 7,
      "name": "Rock_Sandstone_Brick"
    },
    {
      "x": -11,
      "y": 12,
      "z": 7,
      "name": "Rock_Sandstone_Brick"
    },
    {
      "x": -11,
      "y": 13,
      "z": 7,
      "name": "Rock_Sandstone_Brick"
    },
    {
      "x": -11,
      "y": 14,
      "z": 7,
      "name": "Rock_Sandstone_Brick"
    },
    {
      "x": -11,
      "y": 15,
      "z": 7,
      "name": "Rock_Sandstone_Brick"
    },
    {
      "x": -11,
      "y": 16,
      "z": 7,
      "name": "Rock_Sandstone_Brick_Half",
      "rotation": 6
    },
    {
      "x": -11,
      "y": 17,
      "z": 7,
      "name": "Rock_Sandstone_Brick_Half",
      "rotation": 6
    },
    {
      "x": -11,
      "y": 18,
      "z": 7,
      "name": "Rock_Sandstone_Brick"
    },
    {
      "x": -11,
      "y": 19,
      "z": 7,
      "name": "Rock_Sandstone_Brick_Smooth"
    },
    {
      "x": -11,
      "y": 20,
      "z": 7,
      "name": "Rock_Sandstone_Brick_Smooth"
    },
    {
      "x": -11,
      "y": 5,
      "z": 8,
      "name": "Rock_Sandstone_Brick"
    },
    {
      "x": -11,
      "y": 6,
      "z": 8,
      "name": "Rock_Sandstone_Brick"
    },
    {
      "x": -11,
      "y": 7,
      "z": 8,
      "name": "Rock_Sandstone_Brick"
    },
    {
      "x": -11,
      "y": 8,
      "z": 8,
      "name": "Rock_Sandstone_Brick"
    },
    {
      "x": -11,
      "y": 9,
      "z": 8,
      "name": "Rock_Sandstone_Brick_Ornate"
    },
    {
      "x": -11,
      "y": 10,
      "z": 8,
      "name": "Rock_Sandstone_Brick"
    },
    {
      "x": -11,
      "y": 11,
      "z": 8,
      "name": "Rock_Sandstone_Brick"
    },
    {
      "x": -11,
      "y": 12,
      "z": 8,
      "name": "Rock_Sandstone_Brick"
    },
    {
      "x": -11,
      "y": 13,
      "z": 8,
      "name": "Rock_Sandstone_Brick"
    },
    {
      "x": -11,
      "y": 14,
      "z": 8,
      "name": "Rock_Sandstone_Brick"
    },
    {
      "x": -11,
      "y": 15,
      "z": 8,
      "name": "Rock_Sandstone_Brick"
    },
    {
      "x": -11,
      "y": 16,
      "z": 8,
      "name": "Rock_Sandstone_Brick"
    },
    {
      "x": -11,
      "y": 17,
      "z": 8,
      "name": "Rock_Sandstone_Brick"
    },
    {
      "x": -11,
      "y": 18,
      "z": 8,
      "name": "Rock_Sandstone_Brick"
    },
    {
      "x": -11,
      "y": 19,
      "z": 8,
      "name": "Rock_Sandstone_Brick_Smooth"
    },
    {
      "x": -11,
      "y": 20,
      "z": 8,
      "name": "Rock_Sandstone_Brick_Smooth_Half"
    },
    {
      "x": -11,
      "y": 5,
      "z": 9,
      "name": "Soil_Dirt_Dry"
    },
    {
      "x": -11,
      "y": 6,
      "z": 9,
      "name": "Rock_Sandstone_Brick_Half",
      "rotation": 4
    },
    {
      "x": -11,
      "y": 7,
      "z": 9,
      "name": "Rock_Sandstone_Brick"
    },
    {
      "x": -11,
      "y": 8,
      "z": 9,
      "name": "Rock_Sandstone_Brick"
    },
    {
      "x": -11,
      "y": 9,
      "z": 9,
      "name": "Rock_Sandstone_Brick_Ornate"
    },
    {
      "x": -11,
      "y": 10,
      "z": 9,
      "name": "Rock_Sandstone_Brick"
    },
    {
      "x": -11,
      "y": 11,
      "z": 9,
      "name": "Rock_Sandstone_Brick"
    },
    {
      "x": -11,
      "y": 12,
      "z": 9,
      "name": "Rock_Sandstone_Brick"
    },
    {
      "x": -11,
      "y": 13,
      "z": 9,
      "name": "Rock_Sandstone_Brick"
    },
    {
      "x": -11,
      "y": 14,
      "z": 9,
      "name": "Rock_Sandstone_Brick"
    },
    {
      "x": -11,
      "y": 15,
      "z": 9,
      "name": "Rock_Sandstone_Brick"
    },
    {
      "x": -11,
      "y": 16,
      "z": 9,
      "name": "Rock_Sandstone_Brick_Half",
      "rotation": 4
    },
    {
      "x": -11,
      "y": 17,
      "z": 9,
      "name": "Rock_Sandstone_Brick_Half",
      "rotation": 4
    },
    {
      "x": -11,
      "y": 18,
      "z": 9,
      "name": "Rock_Sandstone_Brick"
    },
    {
      "x": -11,
      "y": 19,
      "z": 9,
      "name": "Rock_Sandstone_Brick_Smooth"
    },
    {
      "x": -11,
      "y": 20,
      "z": 9,
      "name": "Rock_Sandstone_Brick_Smooth"
    },
    {
      "x": -11,
      "y": 5,
      "z": 10,
      "name": "Soil_Dirt_Dry"
    },
    {
      "x": -11,
      "y": 8,
      "z": 10,
      "name": "Rock_Sandstone_Brick_Half",
      "rotation": 8
    },
    {
      "x": -11,
      "y": 9,
      "z": 10,
      "name": "Rock_Sandstone_Brick_Ornate"
    },
    {
      "x": -11,
      "y": 10,
      "z": 10,
      "name": "Rock_Sandstone_Brick"
    },
    {
      "x": -11,
      "y": 11,
      "z": 10,
      "name": "Rock_Sandstone_Brick"
    },
    {
      "x": -11,
      "y": 12,
      "z": 10,
      "name": "Rock_Sandstone_Brick"
    },
    {
      "x": -11,
      "y": 13,
      "z": 10,
      "name": "Rock_Sandstone_Brick"
    },
    {
      "x": -11,
      "y": 14,
      "z": 10,
      "name": "Rock_Sandstone_Brick"
    },
    {
      "x": -11,
      "y": 15,
      "z": 10,
      "name": "Rock_Sandstone_Brick"
    },
    {
      "x": -11,
      "y": 16,
      "z": 10,
      "name": "Rock_Sandstone_Brick"
    },
    {
      "x": -11,
      "y": 17,
      "z": 10,
      "name": "Rock_Sandstone_Brick"
    },
    {
      "x": -11,
      "y": 18,
      "z": 10,
      "name": "Rock_Sandstone_Brick"
    },
    {
      "x": -11,
      "y": 19,
      "z": 10,
      "name": "Rock_Sandstone_Brick_Smooth"
    },
    {
      "x": -11,
      "y": 20,
      "z": 10,
      "name": "Rock_Sandstone_Brick_Smooth_Half"
    },
    {
      "x": -11,
      "y": 10,
      "z": 11,
      "name": "Rock_Sandstone_Brick"
    },
    {
      "x": -11,
      "y": 11,
      "z": 11,
      "name": "Rock_Sandstone_Brick"
    },
    {
      "x": -11,
      "y": 12,
      "z": 11,
      "name": "Rock_Sandstone_Brick"
    },
    {
      "x": -11,
      "y": 13,
      "z": 11,
      "name": "Rock_Sandstone_Brick"
    },
    {
      "x": -11,
      "y": 14,
      "z": 11,
      "name": "Rock_Sandstone_Brick"
    },
    {
      "x": -11,
      "y": 15,
      "z": 11,
      "name": "Rock_Sandstone_Brick"
    },
    {
      "x": -11,
      "y": 16,
      "z": 11,
      "name": "Rock_Sandstone_Brick"
    },
    {
      "x": -11,
      "y": 17,
      "z": 11,
      "name": "Rock_Sandstone_Brick"
    },
    {
      "x": -11,
      "y": 18,
      "z": 11,
      "name": "Rock_Sandstone_Brick"
    },
    {
      "x": -11,
      "y": 19,
      "z": 11,
      "name": "Rock_Sandstone_Brick_Smooth"
    },
    {
      "x": -11,
      "y": 20,
      "z": 11,
      "name": "Rock_Sandstone_Brick_Smooth"
    },
    {
      "x": -11,
      "y": 18,
      "z": 12,
      "name": "Wood_Dry_Branch_Short"
    },
    {
      "x": -11,
      "y": 19,
      "z": 12,
      "name": "Rock_Sandstone_Brick_Smooth_Half",
      "rotation": 4
    },
    {
      "x": -11,
      "y": 20,
      "z": 12,
      "name": "Rock_Sandstone_Brick_Smooth_Half",
      "rotation": 4
    },
    {
      "x": -10,
      "y": 5,
      "z": -12,
      "name": "Rock_Sandstone_Cobble"
    },
    {
      "x": -10,
      "y": 6,
      "z": -12,
      "name": "Rock_Sandstone_Cobble"
    },
    {
      "x": -10,
      "y": 5,
      "z": -11,
      "name": "Rock_Sandstone_Brick"
    },
    {
      "x": -10,
      "y": 6,
      "z": -11,
      "name": "Rock_Sandstone_Brick"
    },
    {
      "x": -10,
      "y": 7,
      "z": -11,
      "name": "Rock_Sandstone_Brick"
    },
    {
      "x": -10,
      "y": 8,
      "z": -11,
      "name": "Rock_Sandstone_Brick"
    },
    {
      "x": -10,
      "y": 5,
      "z": -10,
      "name": "Rock_Sandstone_Brick"
    },
    {
      "x": -10,
      "y": 6,
      "z": -10,
      "name": "Rock_Sandstone_Brick"
    },
    {
      "x": -10,
      "y": 7,
      "z": -10,
      "name": "Rock_Sandstone_Brick"
    },
    {
      "x": -10,
      "y": 8,
      "z": -10,
      "name": "Rock_Sandstone_Brick"
    },
    {
      "x": -10,
      "y": 9,
      "z": -10,
      "name": "Rock_Sandstone_Brick_Half"
    },
    {
      "x": -10,
      "y": 5,
      "z": -9,
      "name": "Rock_Sandstone_Brick"
    },
    {
      "x": -10,
      "y": 6,
      "z": -9,
      "name": "Rock_Sandstone_Brick"
    },
    {
      "x": -10,
      "y": 7,
      "z": -9,
      "name": "Rock_Sandstone_Brick"
    },
    {
      "x": -10,
      "y": 8,
      "z": -9,
      "name": "Rock_Sandstone_Brick"
    },
    {
      "x": -10,
      "y": 9,
      "z": -9,
      "name": "Rock_Sandstone_Brick"
    },
    {
      "x": -10,
      "y": 5,
      "z": -8,
      "name": "Rock_Sandstone_Brick"
    },
    {
      "x": -10,
      "y": 6,
      "z": -8,
      "name": "Rock_Sandstone_Brick"
    },
    {
      "x": -10,
      "y": 7,
      "z": -8,
      "name": "Rock_Sandstone_Brick"
    },
    {
      "x": -10,
      "y": 8,
      "z": -8,
      "name": "Rock_Sandstone_Brick"
    },
    {
      "x": -10,
      "y": 9,
      "z": -8,
      "name": "Rock_Sandstone_Brick"
    },
    {
      "x": -10,
      "y": 5,
      "z": -7,
      "name": "Rock_Sandstone_Brick"
    },
    {
      "x": -10,
      "y": 6,
      "z": -7,
      "name": "Rock_Sandstone_Brick"
    },
    {
      "x": -10,
      "y": 7,
      "z": -7,
      "name": "Rock_Sandstone_Brick"
    },
    {
      "x": -10,
      "y": 8,
      "z": -7,
      "name": "Rock_Sandstone_Brick"
    },
    {
      "x": -10,
      "y": 9,
      "z": -7,
      "name": "Rock_Sandstone_Brick"
    },
    {
      "x": -10,
      "y": 10,
      "z": -7,
      "name": "Rock_Sandstone_Brick_Smooth_Half"
    },
    {
      "x": -10,
      "y": 5,
      "z": -6,
      "name": "Rock_Sandstone_Cobble"
    },
    {
      "x": -10,
      "y": 6,
      "z": -6,
      "name": "Rock_Sandstone_Brick"
    },
    {
      "x": -10,
      "y": 7,
      "z": -6,
      "name": "Rock_Sandstone_Brick"
    },
    {
      "x": -10,
      "y": 8,
      "z": -6,
      "name": "Rock_Sandstone_Brick"
    },
    {
      "x": -10,
      "y": 9,
      "z": -6,
      "name": "Rock_Sandstone_Brick"
    },
    {
      "x": -10,
      "y": 5,
      "z": -5,
      "name": "Rock_Sandstone_Brick"
    },
    {
      "x": -10,
      "y": 6,
      "z": -5,
      "name": "Rock_Sandstone_Brick"
    },
    {
      "x": -10,
      "y": 7,
      "z": -5,
      "name": "Soil_Gravel_Sand_White"
    },
    {
      "x": -10,
      "y": 5,
      "z": -4,
      "name": "Rock_Sandstone_Cobble"
    },
    {
      "x": -10,
      "y": 6,
      "z": -4,
      "name": "Rock_Sandstone_Brick"
    },
    {
      "x": -10,
      "y": 7,
      "z": -4,
      "name": "Soil_Gravel_Sand_White"
    },
    {
      "x": -10,
      "y": 6,
      "z": -1,
      "name": "Rock_Sandstone_Brick"
    },
    {
      "x": -10,
      "y": 7,
      "z": -1,
      "name": "Rock_Sandstone_Brick"
    },
    {
      "x": -10,
      "y": 8,
      "z": -1,
      "name": "Rock_Sandstone_Brick"
    },
    {
      "x": -10,
      "y": 9,
      "z": -1,
      "name": "Rock_Sandstone_Brick"
    },
    {
      "x": -10,
      "y": 5,
      "z": 0,
      "name": "Rock_Sandstone_Brick"
    },
    {
      "x": -10,
      "y": 6,
      "z": 0,
      "name": "Rock_Sandstone_Brick"
    },
    {
      "x": -10,
      "y": 7,
      "z": 0,
      "name": "Rock_Sandstone_Brick"
    },
    {
      "x": -10,
      "y": 8,
      "z": 0,
      "name": "Rock_Sandstone_Brick"
    },
    {
      "x": -10,
      "y": 9,
      "z": 0,
      "name": "Rock_Sandstone_Brick"
    },
    {
      "x": -10,
      "y": 10,
      "z": 0,
      "name": "Rock_Sandstone_Brick_Smooth"
    },
    {
      "x": -10,
      "y": 5,
      "z": 1,
      "name": "Rock_Sandstone_Brick"
    },
    {
      "x": -10,
      "y": 6,
      "z": 1,
      "name": "Rock_Sandstone_Brick"
    },
    {
      "x": -10,
      "y": 7,
      "z": 1,
      "name": "Rock_Sandstone_Brick"
    },
    {
      "x": -10,
      "y": 8,
      "z": 1,
      "name": "Rock_Sandstone_Brick"
    },
    {
      "x": -10,
      "y": 9,
      "z": 1,
      "name": "Rock_Sandstone_Brick"
    },
    {
      "x": -10,
      "y": 10,
      "z": 1,
      "name": "Rock_Sandstone_Brick_Smooth_Half"
    },
    {
      "x": -10,
      "y": 5,
      "z": 2,
      "name": "Rock_Sandstone_Brick"
    },
    {
      "x": -10,
      "y": 6,
      "z": 2,
      "name": "Rock_Sandstone_Brick"
    },
    {
      "x": -10,
      "y": 7,
      "z": 2,
      "name": "Rock_Sandstone_Brick"
    },
    {
      "x": -10,
      "y": 8,
      "z": 2,
      "name": "Rock_Sandstone_Brick"
    },
    {
      "x": -10,
      "y": 9,
      "z": 2,
      "name": "Rock_Sandstone_Brick"
    },
    {
      "x": -10,
      "y": 10,
      "z": 2,
      "name": "Rock_Sandstone_Brick_Smooth"
    },
    {
      "x": -10,
      "y": 5,
      "z": 3,
      "name": "Rock_Sandstone_Cobble"
    },
    {
      "x": -10,
      "y": 6,
      "z": 3,
      "name": "Rock_Sandstone_Brick"
    },
    {
      "x": -10,
      "y": 7,
      "z": 3,
      "name": "Rock_Sandstone_Brick"
    },
    {
      "x": -10,
      "y": 8,
      "z": 3,
      "name": "Rock_Sandstone_Brick"
    },
    {
      "x": -10,
      "y": 9,
      "z": 3,
      "name": "Rock_Sandstone_Brick"
    },
    {
      "x": -10,
      "y": 10,
      "z": 3,
      "name": "Rock_Sandstone_Brick_Smooth_Half"
    },
    {
      "x": -10,
      "y": 5,
      "z": 4,
      "name": "Rock_Sandstone_Cobble"
    },
    {
      "x": -10,
      "y": 6,
      "z": 4,
      "name": "Rock_Sandstone_Cobble"
    },
    {
      "x": -10,
      "y": 7,
      "z": 4,
      "name": "Rock_Sandstone_Brick"
    },
    {
      "x": -10,
      "y": 8,
      "z": 4,
      "name": "Rock_Sandstone_Brick"
    },
    {
      "x": -10,
      "y": 9,
      "z": 4,
      "name": "Wood_Dry_Branch_Short",
      "rotation": 2
    },
    {
      "x": -10,
      "y": 10,
      "z": 4,
      "name": "Rock_Sandstone_Brick_Smooth"
    },
    {
      "x": -10,
      "y": 5,
      "z": 5,
      "name": "Rock_Sandstone_Cobble"
    },
    {
      "x": -10,
      "y": 6,
      "z": 5,
      "name": "Rock_Sandstone_Cobble"
    },
    {
      "x": -10,
      "y": 7,
      "z": 5,
      "name": "Rock_Sandstone_Cobble"
    },
    {
      "x": -10,
      "y": 8,
      "z": 5,
      "name": "Rock_Sandstone_Brick"
    },
    {
      "x": -10,
      "y": 9,
      "z": 5,
      "name": "Rock_Sandstone_Brick_Ornate"
    },
    {
      "x": -10,
      "y": 10,
      "z": 5,
      "name": "Rock_Sandstone_Brick"
    },
    {
      "x": -10,
      "y": 11,
      "z": 5,
      "name": "Rock_Sandstone_Brick"
    },
    {
      "x": -10,
      "y": 12,
      "z": 5,
      "name": "Rock_Sandstone_Brick"
    },
    {
      "x": -10,
      "y": 13,
      "z": 5,
      "name": "Rock_Sandstone_Brick"
    },
    {
      "x": -10,
      "y": 14,
      "z": 5,
      "name": "Rock_Sandstone_Brick"
    },
    {
      "x": -10,
      "y": 15,
      "z": 5,
      "name": "Rock_Sandstone_Brick"
    },
    {
      "x": -10,
      "y": 16,
      "z": 5,
      "name": "Rock_Sandstone_Brick"
    },
    {
      "x": -10,
      "y": 17,
      "z": 5,
      "name": "Rock_Sandstone_Brick"
    },
    {
      "x": -10,
      "y": 18,
      "z": 5,
      "name": "Rock_Sandstone_Brick"
    },
    {
      "x": -10,
      "y": 19,
      "z": 5,
      "name": "Rock_Sandstone_Brick_Smooth"
    },
    {
      "x": -10,
      "y": 5,
      "z": 6,
      "name": "Soil_Dirt_Dry"
    },
    {
      "x": -10,
      "y": 6,
      "z": 6,
      "name": "Furniture_Ancient_Crate",
      "components": {
        "Components": {
          "ItemContainerBlock": {
            "ItemContainer": {
              "Capacity": 20,
              "Items": {}
            },
            "Capacity": 20
          }
        }
      }
    },
    {
      "x": -10,
      "y": 7,
      "z": 6,
      "name": "Furniture_Ancient_Barrel"
    },
    {
      "x": -10,
      "y": 11,
      "z": 6,
      "name": "Wood_Drywood_Planks"
    },
    {
      "x": -10,
      "y": 12,
      "z": 6,
      "name": "Furniture_Village_Pot"
    },
    {
      "x": -10,
      "y": 19,
      "z": 6,
      "name": "Wood_Drywood_Planks"
    },
    {
      "x": -10,
      "y": 5,
      "z": 7,
      "name": "Soil_Dirt_Dry"
    },
    {
      "x": -10,
      "y": 11,
      "z": 7,
      "name": "Wood_Drywood_Planks_Half",
      "rotation": 5
    },
    {
      "x": -10,
      "y": 19,
      "z": 7,
      "name": "Wood_Drywood_Planks"
    },
    {
      "x": -10,
      "y": 5,
      "z": 8,
      "name": "Soil_Dirt_Dry"
    },
    {
      "x": -10,
      "y": 6,
      "z": 8,
      "name": "Furniture_Desert_Ladder",
      "rotation": 1
    },
    {
      "x": -10,
      "y": 7,
      "z": 8,
      "name": "Furniture_Desert_Ladder",
      "rotation": 1
    },
    {
      "x": -10,
      "y": 8,
      "z": 8,
      "name": "Furniture_Desert_Ladder",
      "rotation": 1
    },
    {
      "x": -10,
      "y": 9,
      "z": 8,
      "name": "Furniture_Desert_Ladder",
      "rotation": 1
    },
    {
      "x": -10,
      "y": 10,
      "z": 8,
      "name": "Furniture_Desert_Ladder",
      "rotation": 1
    },
    {
      "x": -10,
      "y": 11,
      "z": 8,
      "name": "Furniture_Desert_Ladder",
      "rotation": 1
    },
    {
      "x": -10,
      "y": 12,
      "z": 8,
      "name": "Furniture_Desert_Ladder",
      "rotation": 1
    },
    {
      "x": -10,
      "y": 13,
      "z": 8,
      "name": "Furniture_Desert_Ladder",
      "rotation": 1
    },
    {
      "x": -10,
      "y": 14,
      "z": 8,
      "name": "Furniture_Desert_Ladder",
      "rotation": 1
    },
    {
      "x": -10,
      "y": 15,
      "z": 8,
      "name": "Furniture_Desert_Ladder",
      "rotation": 1
    },
    {
      "x": -10,
      "y": 16,
      "z": 8,
      "name": "Furniture_Desert_Ladder",
      "rotation": 1
    },
    {
      "x": -10,
      "y": 17,
      "z": 8,
      "name": "Furniture_Desert_Ladder",
      "rotation": 1
    },
    {
      "x": -10,
      "y": 18,
      "z": 8,
      "name": "Furniture_Desert_Ladder",
      "rotation": 1
    },
    {
      "x": -10,
      "y": 19,
      "z": 8,
      "name": "Furniture_Desert_Ladder",
      "rotation": 1
    },
    {
      "x": -10,
      "y": 5,
      "z": 9,
      "name": "Soil_Dirt_Dry"
    },
    {
      "x": -10,
      "y": 11,
      "z": 9,
      "name": "Wood_Drywood_Planks"
    },
    {
      "x": -10,
      "y": 19,
      "z": 9,
      "name": "Wood_Drywood_Planks"
    },
    {
      "x": -10,
      "y": 5,
      "z": 10,
      "name": "Soil_Dirt_Dry"
    },
    {
      "x": -10,
      "y": 11,
      "z": 10,
      "name": "Wood_Drywood_Planks"
    },
    {
      "x": -10,
      "y": 12,
      "z": 10,
      "name": "Furniture_Ancient_Barrel"
    },
    {
      "x": -10,
      "y": 19,
      "z": 10,
      "name": "Wood_Drywood_Planks"
    },
    {
      "x": -10,
      "y": 5,
      "z": 11,
      "name": "Soil_Dirt_Dry"
    },
    {
      "x": -10,
      "y": 10,
      "z": 11,
      "name": "Rock_Sandstone_Brick_Half",
      "rotation": 8
    },
    {
      "x": -10,
      "y": 11,
      "z": 11,
      "name": "Rock_Sandstone_Brick"
    },
    {
      "x": -10,
      "y": 12,
      "z": 11,
      "name": "Rock_Sandstone_Brick"
    },
    {
      "x": -10,
      "y": 13,
      "z": 11,
      "name": "Rock_Sandstone_Brick"
    },
    {
      "x": -10,
      "y": 14,
      "z": 11,
      "name": "Rock_Sandstone_Brick"
    },
    {
      "x": -10,
      "y": 15,
      "z": 11,
      "name": "Rock_Sandstone_Brick"
    },
    {
      "x": -10,
      "y": 16,
      "z": 11,
      "name": "Rock_Sandstone_Brick"
    },
    {
      "x": -10,
      "y": 17,
      "z": 11,
      "name": "Rock_Sandstone_Brick"
    },
    {
      "x": -10,
      "y": 18,
      "z": 11,
      "name": "Rock_Sandstone_Brick"
    },
    {
      "x": -10,
      "y": 19,
      "z": 11,
      "name": "Rock_Sandstone_Brick_Smooth"
    },
    {
      "x": -10,
      "y": 20,
      "z": 11,
      "name": "Rock_Sandstone_Brick_Smooth_Half"
    },
    {
      "x": -10,
      "y": 11,
      "z": 12,
      "name": "Wood_Dry_Branch_Short"
    },
    {
      "x": -10,
      "y": 19,
      "z": 12,
      "name": "Rock_Sandstone_Brick_Smooth_Half",
      "rotation": 4
    },
    {
      "x": -9,
      "y": 5,
      "z": -13,
      "name": "Rock_Sandstone"
    },
    {
      "x": -9,
      "y": 5,
      "z": -12,
      "name": "Rock_Sandstone"
    },
    {
      "x": -9,
      "y": 6,
      "z": -12,
      "name": "Rock_Sandstone"
    },
    {
      "x": -9,
      "y": 7,
      "z": -12,
      "name": "Soil_Gravel_Sand_White"
    },
    {
      "x": -9,
      "y": 5,
      "z": -11,
      "name": "Rock_Sandstone"
    },
    {
      "x": -9,
      "y": 6,
      "z": -11,
      "name": "Rock_Sandstone"
    },
    {
      "x": -9,
      "y": 7,
      "z": -11,
      "name": "Rock_Sandstone"
    },
    {
      "x": -9,
      "y": 8,
      "z": -11,
      "name": "Soil_Gravel_Sand_White"
    },
    {
      "x": -9,
      "y": 5,
      "z": -10,
      "name": "Rock_Sandstone"
    },
    {
      "x": -9,
      "y": 6,
      "z": -10,
      "name": "Rock_Sandstone"
    },
    {
      "x": -9,
      "y": 7,
      "z": -10,
      "name": "Rock_Sandstone"
    },
    {
      "x": -9,
      "y": 8,
      "z": -10,
      "name": "Soil_Gravel_Sand_White"
    },
    {
      "x": -9,
      "y": 5,
      "z": -9,
      "name": "Rock_Sandstone"
    },
    {
      "x": -9,
      "y": 6,
      "z": -9,
      "name": "Rock_Sandstone"
    },
    {
      "x": -9,
      "y": 7,
      "z": -9,
      "name": "Rock_Sandstone"
    },
    {
      "x": -9,
      "y": 8,
      "z": -9,
      "name": "Rock_Sandstone"
    },
    {
      "x": -9,
      "y": 9,
      "z": -9,
      "name": "Rock_Sandstone_White_Cobble_Half"
    },
    {
      "x": -9,
      "y": 5,
      "z": -8,
      "name": "Rock_Sandstone"
    },
    {
      "x": -9,
      "y": 6,
      "z": -8,
      "name": "Rock_Sandstone"
    },
    {
      "x": -9,
      "y": 7,
      "z": -8,
      "name": "Rock_Sandstone"
    },
    {
      "x": -9,
      "y": 8,
      "z": -8,
      "name": "Rock_Sandstone"
    },
    {
      "x": -9,
      "y": 9,
      "z": -8,
      "name": "Rock_Sandstone_White_Cobble"
    },
    {
      "x": -9,
      "y": 5,
      "z": -7,
      "name": "Rock_Sandstone"
    },
    {
      "x": -9,
      "y": 6,
      "z": -7,
      "name": "Rock_Sandstone"
    },
    {
      "x": -9,
      "y": 7,
      "z": -7,
      "name": "Rock_Sandstone"
    },
    {
      "x": -9,
      "y": 8,
      "z": -7,
      "name": "Rock_Sandstone"
    },
    {
      "x": -9,
      "y": 9,
      "z": -7,
      "name": "Rock_Sandstone_White_Cobble"
    },
    {
      "x": -9,
      "y": 5,
      "z": -6,
      "name": "Rock_Sandstone"
    },
    {
      "x": -9,
      "y": 6,
      "z": -6,
      "name": "Rock_Sandstone"
    },
    {
      "x": -9,
      "y": 7,
      "z": -6,
      "name": "Rock_Sandstone"
    },
    {
      "x": -9,
      "y": 8,
      "z": -6,
      "name": "Rock_Sandstone"
    },
    {
      "x": -9,
      "y": 9,
      "z": -6,
      "name": "Rock_Sandstone_White_Cobble"
    },
    {
      "x": -9,
      "y": 5,
      "z": -5,
      "name": "Rock_Sandstone"
    },
    {
      "x": -9,
      "y": 6,
      "z": -5,
      "name": "Rock_Sandstone"
    },
    {
      "x": -9,
      "y": 7,
      "z": -5,
      "name": "Rock_Sandstone"
    },
    {
      "x": -9,
      "y": 8,
      "z": -5,
      "name": "Soil_Gravel_Sand_White"
    },
    {
      "x": -9,
      "y": 5,
      "z": -4,
      "name": "Rock_Sandstone"
    },
    {
      "x": -9,
      "y": 6,
      "z": -4,
      "name": "Rock_Sandstone"
    },
    {
      "x": -9,
      "y": 7,
      "z": -4,
      "name": "Rock_Sandstone"
    },
    {
      "x": -9,
      "y": 8,
      "z": -4,
      "name": "Soil_Gravel_Sand_White"
    },
    {
      "x": -9,
      "y": 5,
      "z": -3,
      "name": "Rock_Sandstone"
    },
    {
      "x": -9,
      "y": 6,
      "z": -3,
      "name": "Rock_Sandstone"
    },
    {
      "x": -9,
      "y": 7,
      "z": -3,
      "name": "Rock_Sandstone"
    },
    {
      "x": -9,
      "y": 8,
      "z": -3,
      "name": "Soil_Gravel_Sand_White"
    },
    {
      "x": -9,
      "y": 5,
      "z": -2,
      "name": "Rock_Sandstone"
    },
    {
      "x": -9,
      "y": 6,
      "z": -2,
      "name": "Rock_Sandstone"
    },
    {
      "x": -9,
      "y": 7,
      "z": -2,
      "name": "Rock_Sandstone"
    },
    {
      "x": -9,
      "y": 8,
      "z": -2,
      "name": "Soil_Gravel_Sand_White"
    },
    {
      "x": -9,
      "y": 5,
      "z": -1,
      "name": "Rock_Sandstone"
    },
    {
      "x": -9,
      "y": 6,
      "z": -1,
      "name": "Rock_Sandstone"
    },
    {
      "x": -9,
      "y": 7,
      "z": -1,
      "name": "Rock_Sandstone"
    },
    {
      "x": -9,
      "y": 8,
      "z": -1,
      "name": "Soil_Gravel_Sand_White"
    },
    {
      "x": -9,
      "y": 9,
      "z": -1,
      "name": "Soil_Gravel_Sand_White"
    },
    {
      "x": -9,
      "y": 5,
      "z": 0,
      "name": "Rock_Sandstone"
    },
    {
      "x": -9,
      "y": 6,
      "z": 0,
      "name": "Rock_Sandstone"
    },
    {
      "x": -9,
      "y": 7,
      "z": 0,
      "name": "Rock_Sandstone"
    },
    {
      "x": -9,
      "y": 8,
      "z": 0,
      "name": "Rock_Sandstone"
    },
    {
      "x": -9,
      "y": 9,
      "z": 0,
      "name": "Soil_Gravel_Sand_White"
    },
    {
      "x": -9,
      "y": 5,
      "z": 1,
      "name": "Rock_Sandstone"
    },
    {
      "x": -9,
      "y": 6,
      "z": 1,
      "name": "Rock_Sandstone"
    },
    {
      "x": -9,
      "y": 7,
      "z": 1,
      "name": "Rock_Sandstone"
    },
    {
      "x": -9,
      "y": 8,
      "z": 1,
      "name": "Rock_Sandstone"
    },
    {
      "x": -9,
      "y": 9,
      "z": 1,
      "name": "Rock_Sandstone_White_Cobble"
    },
    {
      "x": -9,
      "y": 5,
      "z": 2,
      "name": "Rock_Sandstone"
    },
    {
      "x": -9,
      "y": 6,
      "z": 2,
      "name": "Rock_Sandstone"
    },
    {
      "x": -9,
      "y": 7,
      "z": 2,
      "name": "Rock_Sandstone"
    },
    {
      "x": -9,
      "y": 8,
      "z": 2,
      "name": "Rock_Sandstone"
    },
    {
      "x": -9,
      "y": 9,
      "z": 2,
      "name": "Rock_Sandstone_White_Cobble"
    },
    {
      "x": -9,
      "y": 5,
      "z": 3,
      "name": "Rock_Sandstone"
    },
    {
      "x": -9,
      "y": 6,
      "z": 3,
      "name": "Rock_Sandstone"
    },
    {
      "x": -9,
      "y": 7,
      "z": 3,
      "name": "Rock_Sandstone"
    },
    {
      "x": -9,
      "y": 8,
      "z": 3,
      "name": "Rock_Sandstone"
    },
    {
      "x": -9,
      "y": 9,
      "z": 3,
      "name": "Rock_Sandstone_White_Cobble"
    },
    {
      "x": -9,
      "y": 10,
      "z": 3,
      "name": "Rock_Sandstone_White_Cobble_Stairs",
      "rotation": 2
    },
    {
      "x": -9,
      "y": 5,
      "z": 4,
      "name": "Rock_Sandstone"
    },
    {
      "x": -9,
      "y": 6,
      "z": 4,
      "name": "Rock_Sandstone"
    },
    {
      "x": -9,
      "y": 7,
      "z": 4,
      "name": "Rock_Sandstone"
    },
    {
      "x": -9,
      "y": 8,
      "z": 4,
      "name": "Rock_Sandstone"
    },
    {
      "x": -9,
      "y": 9,
      "z": 4,
      "name": "Rock_Sandstone_White_Cobble"
    },
    {
      "x": -9,
      "y": 10,
      "z": 4,
      "name": "Rock_Sandstone_White_Cobble"
    },
    {
      "x": -9,
      "y": 11,
      "z": 4,
      "name": "Rock_Sandstone_White_Cobble_Stairs",
      "rotation": 2
    },
    {
      "x": -9,
      "y": 18,
      "z": 4,
      "name": "Wood_Dry_Branch_Short",
      "rotation": 2
    },
    {
      "x": -9,
      "y": 19,
      "z": 4,
      "name": "Rock_Sandstone_Brick_Smooth_Half",
      "rotation": 6
    },
    {
      "x": -9,
      "y": 5,
      "z": 5,
      "name": "Rock_Sandstone_Cobble"
    },
    {
      "x": -9,
      "y": 6,
      "z": 5,
      "name": "Rock_Sandstone_Cobble"
    },
    {
      "x": -9,
      "y": 7,
      "z": 5,
      "name": "Rock_Sandstone_Brick"
    },
    {
      "x": -9,
      "y": 8,
      "z": 5,
      "name": "Rock_Sandstone_Brick"
    },
    {
      "x": -9,
      "y": 9,
      "z": 5,
      "name": "Rock_Sandstone_Brick_Ornate"
    },
    {
      "x": -9,
      "y": 10,
      "z": 5,
      "name": "Rock_Sandstone_Brick"
    },
    {
      "x": -9,
      "y": 11,
      "z": 5,
      "name": "Rock_Sandstone_Brick_Smooth"
    },
    {
      "x": -9,
      "y": 12,
      "z": 5,
      "name": "Rock_Sandstone_Brick_Half",
      "rotation": 5
    },
    {
      "x": -9,
      "y": 13,
      "z": 5,
      "name": "Rock_Sandstone_Brick_Half",
      "rotation": 5
    },
    {
      "x": -9,
      "y": 14,
      "z": 5,
      "name": "Rock_Sandstone_Brick_Stairs",
      "rotation": 11
    },
    {
      "x": -9,
      "y": 15,
      "z": 5,
      "name": "Rock_Sandstone_Brick"
    },
    {
      "x": -9,
      "y": 16,
      "z": 5,
      "name": "Rock_Sandstone_Brick_Half",
      "rotation": 7
    },
    {
      "x": -9,
      "y": 17,
      "z": 5,
      "name": "Rock_Sandstone_Brick_Half",
      "rotation": 7
    },
    {
      "x": -9,
      "y": 18,
      "z": 5,
      "name": "Rock_Sandstone_Brick"
    },
    {
      "x": -9,
      "y": 19,
      "z": 5,
      "name": "Rock_Sandstone_Brick_Smooth"
    },
    {
      "x": -9,
      "y": 5,
      "z": 6,
      "name": "Soil_Dirt_Dry"
    },
    {
      "x": -9,
      "y": 6,
      "z": 6,
      "name": "Furniture_Ancient_Crate",
      "components": {
        "Components": {
          "ItemContainerBlock": {
            "ItemContainer": {
              "Capacity": 20,
              "Items": {}
            },
            "Capacity": 20
          }
        }
      }
    },
    {
      "x": -9,
      "y": 11,
      "z": 6,
      "name": "Wood_Drywood_Planks"
    },
    {
      "x": -9,
      "y": 12,
      "z": 6,
      "name": "Furniture_Temple_Wind_Pot"
    },
    {
      "x": -9,
      "y": 13,
      "z": 6,
      "name": "Furniture_Temple_Wind_Pot",
      "filler": 1024
    },
    {
      "x": -9,
      "y": 19,
      "z": 6,
      "name": "Wood_Drywood_Planks"
    },
    {
      "x": -9,
      "y": 5,
      "z": 7,
      "name": "Soil_Dirt_Dry"
    },
    {
      "x": -9,
      "y": 6,
      "z": 7,
      "name": "Furniture_Ancient_Barrel"
    },
    {
      "x": -9,
      "y": 11,
      "z": 7,
      "name": "Wood_Drywood_Planks"
    },
    {
      "x": -9,
      "y": 19,
      "z": 7,
      "name": "Wood_Drywood_Planks"
    },
    {
      "x": -9,
      "y": 5,
      "z": 8,
      "name": "Soil_Dirt_Dry"
    },
    {
      "x": -9,
      "y": 11,
      "z": 8,
      "name": "Wood_Drywood_Planks_Half",
      "rotation": 7
    },
    {
      "x": -9,
      "y": 19,
      "z": 8,
      "name": "Wood_Drywood_Planks_Half",
      "rotation": 7
    },
    {
      "x": -9,
      "y": 5,
      "z": 9,
      "name": "Soil_Dirt_Dry"
    },
    {
      "x": -9,
      "y": 11,
      "z": 9,
      "name": "Wood_Drywood_Planks"
    },
    {
      "x": -9,
      "y": 19,
      "z": 9,
      "name": "Wood_Drywood_Planks"
    },
    {
      "x": -9,
      "y": 5,
      "z": 10,
      "name": "Soil_Dirt_Dry"
    },
    {
      "x": -9,
      "y": 11,
      "z": 10,
      "name": "Wood_Drywood_Planks"
    },
    {
      "x": -9,
      "y": 12,
      "z": 10,
      "name": "Furniture_Crude_Wardrobe",
      "rotation": 2
    },
    {
      "x": -9,
      "y": 13,
      "z": 10,
      "name": "Furniture_Crude_Wardrobe",
      "filler": 1024,
      "rotation": 2
    },
    {
      "x": -9,
      "y": 19,
      "z": 10,
      "name": "Wood_Drywood_Planks"
    },
    {
      "x": -9,
      "y": 20,
      "z": 10,
      "name": "Block_Spawner_Block",
      "components": {
        "Components": {
          "PlacedByInteraction": {
            "WhoPlacedUuid": {
              "$binary": "qA/t28wKPUewuu66t1XEYQ==",
              "$type": "04"
            }
          },
          "BlockSpawner": {
            "BlockSpawnerId": "Zone2_Undead_Tier2"
          }
        }
      },
      "rotation": 2
    },
    {
      "x": -9,
      "y": 5,
      "z": 11,
      "name": "Soil_Dirt_Dry"
    },
    {
      "x": -9,
      "y": 6,
      "z": 11,
      "name": "Rock_Sandstone_Brick_Half",
      "rotation": 7
    },
    {
      "x": -9,
      "y": 7,
      "z": 11,
      "name": "Rock_Sandstone_Brick_Half",
      "rotation": 7
    },
    {
      "x": -9,
      "y": 10,
      "z": 11,
      "name": "Rock_Sandstone_Brick"
    },
    {
      "x": -9,
      "y": 11,
      "z": 11,
      "name": "Rock_Sandstone_Brick"
    },
    {
      "x": -9,
      "y": 12,
      "z": 11,
      "name": "Rock_Sandstone_Brick"
    },
    {
      "x": -9,
      "y": 13,
      "z": 11,
      "name": "Rock_Sandstone_Brick"
    },
    {
      "x": -9,
      "y": 14,
      "z": 11,
      "name": "Rock_Sandstone_Brick"
    },
    {
      "x": -9,
      "y": 15,
      "z": 11,
      "name": "Rock_Sandstone_Brick"
    },
    {
      "x": -9,
      "y": 16,
      "z": 11,
      "name": "Rock_Sandstone_Brick_Half",
      "rotation": 7
    },
    {
      "x": -9,
      "y": 18,
      "z": 11,
      "name": "Rock_Sandstone_Brick"
    },
    {
      "x": -9,
      "y": 19,
      "z": 11,
      "name": "Rock_Sandstone_Brick_Smooth"
    },
    {
      "x": -9,
      "y": 20,
      "z": 11,
      "name": "Rock_Sandstone_Brick_Smooth"
    },
    {
      "x": -9,
      "y": 5,
      "z": 12,
      "name": "Rock_Sandstone_Brick_Smooth"
    },
    {
      "x": -9,
      "y": 6,
      "z": 12,
      "name": "Rock_Sandstone_Brick_Smooth"
    },
    {
      "x": -9,
      "y": 7,
      "z": 12,
      "name": "Rock_Sandstone_Brick_Smooth"
    },
    {
      "x": -9,
      "y": 8,
      "z": 12,
      "name": "Rock_Sandstone_Brick_Smooth"
    },
    {
      "x": -9,
      "y": 9,
      "z": 12,
      "name": "Rock_Sandstone_Brick_Smooth"
    },
    {
      "x": -9,
      "y": 10,
      "z": 12,
      "name": "Rock_Sandstone_Brick_Smooth"
    },
    {
      "x": -9,
      "y": 11,
      "z": 12,
      "name": "Rock_Sandstone_Brick_Smooth"
    },
    {
      "x": -9,
      "y": 12,
      "z": 12,
      "name": "Rock_Sandstone_Brick_Smooth"
    },
    {
      "x": -9,
      "y": 13,
      "z": 12,
      "name": "Rock_Sandstone_Brick_Smooth"
    },
    {
      "x": -9,
      "y": 18,
      "z": 12,
      "name": "Wood_Dry_Branch_Short"
    },
    {
      "x": -9,
      "y": 19,
      "z": 12,
      "name": "Rock_Sandstone_Brick_Smooth_Half",
      "rotation": 4
    },
    {
      "x": -9,
      "y": 20,
      "z": 12,
      "name": "Rock_Sandstone_Brick_Smooth_Half",
      "rotation": 4
    },
    {
      "x": -9,
      "y": 5,
      "z": 13,
      "name": "Rock_Sandstone_Brick_Smooth_Half",
      "rotation": 4
    },
    {
      "x": -9,
      "y": 6,
      "z": 13,
      "name": "Rock_Sandstone_Brick_Smooth_Half",
      "rotation": 4
    },
    {
      "x": -9,
      "y": 7,
      "z": 13,
      "name": "Rock_Sandstone_Brick_Smooth_Half",
      "rotation": 4
    },
    {
      "x": -9,
      "y": 8,
      "z": 13,
      "name": "Rock_Sandstone_Brick_Smooth_Half",
      "rotation": 4
    },
    {
      "x": -9,
      "y": 9,
      "z": 13,
      "name": "Rock_Sandstone_Brick_Smooth_Half",
      "rotation": 4
    },
    {
      "x": -8,
      "y": 5,
      "z": -13,
      "name": "Rock_Sandstone_Cobble_Stairs",
      "rotation": 1
    },
    {
      "x": -8,
      "y": 5,
      "z": -12,
      "name": "Rock_Sandstone"
    },
    {
      "x": -8,
      "y": 6,
      "z": -12,
      "name": "Soil_Gravel_Sand_White"
    },
    {
      "x": -8,
      "y": 7,
      "z": -12,
      "name": "Soil_Gravel_Sand_White"
    },
    {
      "x": -8,
      "y": 5,
      "z": -11,
      "name": "Rock_Sandstone"
    },
    {
      "x": -8,
      "y": 6,
      "z": -11,
      "name": "Rock_Sandstone"
    },
    {
      "x": -8,
      "y": 7,
      "z": -11,
      "name": "Soil_Gravel_Sand_White"
    },
    {
      "x": -8,
      "y": 5,
      "z": -10,
      "name": "Rock_Sandstone"
    },
    {
      "x": -8,
      "y": 6,
      "z": -10,
      "name": "Rock_Sandstone"
    },
    {
      "x": -8,
      "y": 7,
      "z": -10,
      "name": "Rock_Sandstone"
    },
    {
      "x": -8,
      "y": 8,
      "z": -10,
      "name": "Soil_Gravel_Sand_White"
    },
    {
      "x": -8,
      "y": 5,
      "z": -9,
      "name": "Rock_Sandstone"
    },
    {
      "x": -8,
      "y": 6,
      "z": -9,
      "name": "Rock_Sandstone"
    },
    {
      "x": -8,
      "y": 7,
      "z": -9,
      "name": "Rock_Sandstone"
    },
    {
      "x": -8,
      "y": 8,
      "z": -9,
      "name": "Soil_Gravel_Sand_White"
    },
    {
      "x": -8,
      "y": 5,
      "z": -8,
      "name": "Rock_Sandstone"
    },
    {
      "x": -8,
      "y": 6,
      "z": -8,
      "name": "Rock_Sandstone"
    },
    {
      "x": -8,
      "y": 7,
      "z": -8,
      "name": "Rock_Sandstone"
    },
    {
      "x": -8,
      "y": 8,
      "z": -8,
      "name": "Rock_Sandstone"
    },
    {
      "x": -8,
      "y": 9,
      "z": -8,
      "name": "Soil_Gravel_Sand_White"
    },
    {
      "x": -8,
      "y": 5,
      "z": -7,
      "name": "Rock_Sandstone"
    },
    {
      "x": -8,
      "y": 6,
      "z": -7,
      "name": "Rock_Sandstone"
    },
    {
      "x": -8,
      "y": 7,
      "z": -7,
      "name": "Rock_Sandstone"
    },
    {
      "x": -8,
      "y": 8,
      "z": -7,
      "name": "Rock_Sandstone"
    },
    {
      "x": -8,
      "y": 9,
      "z": -7,
      "name": "Rock_Sandstone_White_Cobble"
    },
    {
      "x": -8,
      "y": 5,
      "z": -6,
      "name": "Rock_Sandstone"
    },
    {
      "x": -8,
      "y": 6,
      "z": -6,
      "name": "Rock_Sandstone"
    },
    {
      "x": -8,
      "y": 7,
      "z": -6,
      "name": "Rock_Sandstone"
    },
    {
      "x": -8,
      "y": 8,
      "z": -6,
      "name": "Rock_Sandstone"
    },
    {
      "x": -8,
      "y": 9,
      "z": -6,
      "name": "Rock_Sandstone_White_Cobble_Half"
    },
    {
      "x": -8,
      "y": 5,
      "z": -5,
      "name": "Rock_Sandstone"
    },
    {
      "x": -8,
      "y": 6,
      "z": -5,
      "name": "Rock_Sandstone"
    },
    {
      "x": -8,
      "y": 7,
      "z": -5,
      "name": "Rock_Sandstone"
    },
    {
      "x": -8,
      "y": 8,
      "z": -5,
      "name": "Soil_Gravel_Sand_White"
    },
    {
      "x": -8,
      "y": 5,
      "z": -4,
      "name": "Rock_Sandstone"
    },
    {
      "x": -8,
      "y": 6,
      "z": -4,
      "name": "Rock_Sandstone"
    },
    {
      "x": -8,
      "y": 7,
      "z": -4,
      "name": "Rock_Sandstone"
    },
    {
      "x": -8,
      "y": 8,
      "z": -4,
      "name": "Soil_Gravel_Sand_White"
    },
    {
      "x": -8,
      "y": 5,
      "z": -3,
      "name": "Rock_Sandstone"
    },
    {
      "x": -8,
      "y": 6,
      "z": -3,
      "name": "Rock_Sandstone"
    },
    {
      "x": -8,
      "y": 7,
      "z": -3,
      "name": "Rock_Sandstone"
    },
    {
      "x": -8,
      "y": 8,
      "z": -3,
      "name": "Soil_Gravel_Sand_White"
    },
    {
      "x": -8,
      "y": 5,
      "z": -2,
      "name": "Rock_Sandstone"
    },
    {
      "x": -8,
      "y": 6,
      "z": -2,
      "name": "Rock_Sandstone"
    },
    {
      "x": -8,
      "y": 7,
      "z": -2,
      "name": "Rock_Sandstone"
    },
    {
      "x": -8,
      "y": 8,
      "z": -2,
      "name": "Soil_Gravel_Sand_White"
    },
    {
      "x": -8,
      "y": 5,
      "z": -1,
      "name": "Rock_Sandstone"
    },
    {
      "x": -8,
      "y": 6,
      "z": -1,
      "name": "Rock_Sandstone"
    },
    {
      "x": -8,
      "y": 7,
      "z": -1,
      "name": "Rock_Sandstone"
    },
    {
      "x": -8,
      "y": 8,
      "z": -1,
      "name": "Soil_Gravel_Sand_White"
    },
    {
      "x": -8,
      "y": 9,
      "z": -1,
      "name": "Soil_Gravel_Sand_White"
    },
    {
      "x": -8,
      "y": 5,
      "z": 0,
      "name": "Rock_Sandstone"
    },
    {
      "x": -8,
      "y": 6,
      "z": 0,
      "name": "Rock_Sandstone"
    },
    {
      "x": -8,
      "y": 7,
      "z": 0,
      "name": "Rock_Sandstone"
    },
    {
      "x": -8,
      "y": 8,
      "z": 0,
      "name": "Rock_Sandstone"
    },
    {
      "x": -8,
      "y": 9,
      "z": 0,
      "name": "Soil_Gravel_Sand_White"
    },
    {
      "x": -8,
      "y": 5,
      "z": 1,
      "name": "Rock_Sandstone"
    },
    {
      "x": -8,
      "y": 6,
      "z": 1,
      "name": "Rock_Sandstone"
    },
    {
      "x": -8,
      "y": 7,
      "z": 1,
      "name": "Rock_Sandstone"
    },
    {
      "x": -8,
      "y": 8,
      "z": 1,
      "name": "Rock_Sandstone"
    },
    {
      "x": -8,
      "y": 9,
      "z": 1,
      "name": "Rock_Sandstone_White_Cobble"
    },
    {
      "x": -8,
      "y": 5,
      "z": 2,
      "name": "Rock_Sandstone"
    },
    {
      "x": -8,
      "y": 6,
      "z": 2,
      "name": "Rock_Sandstone"
    },
    {
      "x": -8,
      "y": 7,
      "z": 2,
      "name": "Rock_Sandstone"
    },
    {
      "x": -8,
      "y": 8,
      "z": 2,
      "name": "Rock_Sandstone"
    },
    {
      "x": -8,
      "y": 9,
      "z": 2,
      "name": "Rock_Sandstone_White_Cobble"
    },
    {
      "x": -8,
      "y": 5,
      "z": 3,
      "name": "Rock_Sandstone"
    },
    {
      "x": -8,
      "y": 6,
      "z": 3,
      "name": "Rock_Sandstone"
    },
    {
      "x": -8,
      "y": 7,
      "z": 3,
      "name": "Rock_Sandstone"
    },
    {
      "x": -8,
      "y": 8,
      "z": 3,
      "name": "Rock_Sandstone"
    },
    {
      "x": -8,
      "y": 9,
      "z": 3,
      "name": "Rock_Sandstone_White_Cobble"
    },
    {
      "x": -8,
      "y": 10,
      "z": 3,
      "name": "Rock_Sandstone_White_Cobble_Stairs",
      "rotation": 2
    },
    {
      "x": -8,
      "y": 5,
      "z": 4,
      "name": "Rock_Sandstone"
    },
    {
      "x": -8,
      "y": 6,
      "z": 4,
      "name": "Rock_Sandstone"
    },
    {
      "x": -8,
      "y": 7,
      "z": 4,
      "name": "Rock_Sandstone"
    },
    {
      "x": -8,
      "y": 8,
      "z": 4,
      "name": "Rock_Sandstone"
    },
    {
      "x": -8,
      "y": 9,
      "z": 4,
      "name": "Rock_Sandstone_White_Cobble"
    },
    {
      "x": -8,
      "y": 10,
      "z": 4,
      "name": "Rock_Sandstone_White_Cobble"
    },
    {
      "x": -8,
      "y": 11,
      "z": 4,
      "name": "Rock_Sandstone_White_Cobble_Stairs",
      "rotation": 2
    },
    {
      "x": -8,
      "y": 19,
      "z": 4,
      "name": "Rock_Sandstone_Brick_Smooth_Half",
      "rotation": 6
    },
    {
      "x": -8,
      "y": 5,
      "z": 5,
      "name": "Rock_Sandstone_Brick"
    },
    {
      "x": -8,
      "y": 6,
      "z": 5,
      "name": "Rock_Sandstone_Brick"
    },
    {
      "x": -8,
      "y": 7,
      "z": 5,
      "name": "Rock_Sandstone_Brick"
    },
    {
      "x": -8,
      "y": 8,
      "z": 5,
      "name": "Rock_Sandstone_Brick"
    },
    {
      "x": -8,
      "y": 9,
      "z": 5,
      "name": "Rock_Sandstone_Brick_Ornate"
    },
    {
      "x": -8,
      "y": 10,
      "z": 5,
      "name": "Rock_Sandstone_Brick"
    },
    {
      "x": -8,
      "y": 11,
      "z": 5,
      "name": "Rock_Sandstone_Brick_Smooth"
    },
    {
      "x": -8,
      "y": 14,
      "z": 5,
      "name": "Rock_Sandstone_Brick_Half",
      "rotation": 8
    },
    {
      "x": -8,
      "y": 15,
      "z": 5,
      "name": "Rock_Sandstone_Brick"
    },
    {
      "x": -8,
      "y": 16,
      "z": 5,
      "name": "Rock_Sandstone_Brick"
    },
    {
      "x": -8,
      "y": 17,
      "z": 5,
      "name": "Rock_Sandstone_Brick"
    },
    {
      "x": -8,
      "y": 18,
      "z": 5,
      "name": "Rock_Sandstone_Brick"
    },
    {
      "x": -8,
      "y": 19,
      "z": 5,
      "name": "Rock_Sandstone_Brick_Smooth"
    },
    {
      "x": -8,
      "y": 20,
      "z": 5,
      "name": "Rock_Sandstone_Brick_Smooth_Half"
    },
    {
      "x": -8,
      "y": 5,
      "z": 6,
      "name": "Soil_Dirt_Dry"
    },
    {
      "x": -8,
      "y": 6,
      "z": 6,
      "name": "Soil_Dirt_Dry"
    },
    {
      "x": -8,
      "y": 11,
      "z": 6,
      "name": "Wood_Drywood_Planks"
    },
    {
      "x": -8,
      "y": 19,
      "z": 6,
      "name": "Wood_Drywood_Planks"
    },
    {
      "x": -8,
      "y": 20,
      "z": 6,
      "name": "Furniture_Ancient_Pot"
    },
    {
      "x": -8,
      "y": 5,
      "z": 7,
      "name": "Soil_Dirt_Dry"
    },
    {
      "x": -8,
      "y": 6,
      "z": 7,
      "name": "Soil_Dirt_Dry"
    },
    {
      "x": -8,
      "y": 11,
      "z": 7,
      "name": "Wood_Drywood_Planks"
    },
    {
      "x": -8,
      "y": 19,
      "z": 7,
      "name": "Wood_Drywood_Planks"
    },
    {
      "x": -8,
      "y": 5,
      "z": 8,
      "name": "Soil_Dirt_Dry"
    },
    {
      "x": -8,
      "y": 6,
      "z": 8,
      "name": "Soil_Dirt_Dry"
    },
    {
      "x": -8,
      "y": 11,
      "z": 8,
      "name": "Wood_Drywood_Planks"
    },
    {
      "x": -8,
      "y": 19,
      "z": 8,
      "name": "Wood_Drywood_Planks_Half",
      "rotation": 5
    },
    {
      "x": -8,
      "y": 5,
      "z": 9,
      "name": "Soil_Dirt_Dry"
    },
    {
      "x": -8,
      "y": 11,
      "z": 9,
      "name": "Wood_Drywood_Planks"
    },
    {
      "x": -8,
      "y": 19,
      "z": 9,
      "name": "Wood_Drywood_Planks_Half",
      "rotation": 5
    },
    {
      "x": -8,
      "y": 5,
      "z": 10,
      "name": "Soil_Dirt_Dry"
    },
    {
      "x": -8,
      "y": 6,
      "z": 10,
      "name": "Plant_Bush_Arid_Sharp"
    },
    {
      "x": -8,
      "y": 11,
      "z": 10,
      "name": "Wood_Drywood_Planks"
    },
    {
      "x": -8,
      "y": 12,
      "z": 10,
      "name": "Furniture_Crude_Wardrobe",
      "filler": 1,
      "rotation": 2
    },
    {
      "x": -8,
      "y": 13,
      "z": 10,
      "name": "Furniture_Crude_Wardrobe",
      "filler": 1025,
      "rotation": 2
    },
    {
      "x": -8,
      "y": 19,
      "z": 10,
      "name": "Wood_Drywood_Planks"
    },
    {
      "x": -8,
      "y": 5,
      "z": 11,
      "name": "Rock_Sandstone_Brick"
    },
    {
      "x": -8,
      "y": 6,
      "z": 11,
      "name": "Rock_Sandstone_Brick"
    },
    {
      "x": -8,
      "y": 7,
      "z": 11,
      "name": "Rock_Sandstone_Brick"
    },
    {
      "x": -8,
      "y": 8,
      "z": 11,
      "name": "Rock_Sandstone_Brick"
    },
    {
      "x": -8,
      "y": 9,
      "z": 11,
      "name": "Rock_Sandstone_Brick_Ornate"
    },
    {
      "x": -8,
      "y": 10,
      "z": 11,
      "name": "Rock_Sandstone_Brick"
    },
    {
      "x": -8,
      "y": 11,
      "z": 11,
      "name": "Rock_Sandstone_Brick"
    },
    {
      "x": -8,
      "y": 12,
      "z": 11,
      "name": "Rock_Sandstone_Brick"
    },
    {
      "x": -8,
      "y": 13,
      "z": 11,
      "name": "Rock_Sandstone_Brick"
    },
    {
      "x": -8,
      "y": 14,
      "z": 11,
      "name": "Rock_Sandstone_Brick"
    },
    {
      "x": -8,
      "y": 15,
      "z": 11,
      "name": "Rock_Sandstone_Brick"
    },
    {
      "x": -8,
      "y": 16,
      "z": 11,
      "name": "Rock_Sandstone_Brick"
    },
    {
      "x": -8,
      "y": 5,
      "z": 12,
      "name": "Rock_Sandstone_Brick_Smooth"
    },
    {
      "x": -8,
      "y": 6,
      "z": 12,
      "name": "Rock_Sandstone_Brick_Smooth"
    },
    {
      "x": -8,
      "y": 7,
      "z": 12,
      "name": "Rock_Sandstone_Brick_Smooth"
    },
    {
      "x": -8,
      "y": 8,
      "z": 12,
      "name": "Rock_Sandstone_Brick_Smooth"
    },
    {
      "x": -8,
      "y": 9,
      "z": 12,
      "name": "Rock_Sandstone_Brick_Smooth"
    },
    {
      "x": -8,
      "y": 10,
      "z": 12,
      "name": "Rock_Sandstone_Brick_Smooth"
    },
    {
      "x": -8,
      "y": 11,
      "z": 12,
      "name": "Rock_Sandstone_Brick_Smooth"
    },
    {
      "x": -8,
      "y": 12,
      "z": 12,
      "name": "Rock_Sandstone_Brick_Smooth"
    },
    {
      "x": -8,
      "y": 13,
      "z": 12,
      "name": "Rock_Sandstone_Brick_Smooth"
    },
    {
      "x": -8,
      "y": 5,
      "z": 13,
      "name": "Rock_Sandstone_Brick_Smooth_Half",
      "rotation": 4
    },
    {
      "x": -8,
      "y": 6,
      "z": 13,
      "name": "Rock_Sandstone_Brick_Smooth_Half",
      "rotation": 4
    },
    {
      "x": -8,
      "y": 7,
      "z": 13,
      "name": "Rock_Sandstone_Brick_Smooth_Half",
      "rotation": 4
    },
    {
      "x": -8,
      "y": 8,
      "z": 13,
      "name": "Rock_Sandstone_Brick_Smooth_Half",
      "rotation": 4
    },
    {
      "x": -8,
      "y": 9,
      "z": 13,
      "name": "Rock_Sandstone_Brick_Smooth_Half",
      "rotation": 4
    },
    {
      "x": -7,
      "y": 5,
      "z": -12,
      "name": "Rock_Sandstone"
    },
    {
      "x": -7,
      "y": 6,
      "z": -12,
      "name": "Soil_Gravel_Sand_White"
    },
    {
      "x": -7,
      "y": 5,
      "z": -11,
      "name": "Rock_Sandstone"
    },
    {
      "x": -7,
      "y": 6,
      "z": -11,
      "name": "Rock_Sandstone"
    },
    {
      "x": -7,
      "y": 7,
      "z": -11,
      "name": "Soil_Gravel_Sand_White"
    },
    {
      "x": -7,
      "y": 5,
      "z": -10,
      "name": "Rock_Sandstone"
    },
    {
      "x": -7,
      "y": 6,
      "z": -10,
      "name": "Rock_Sandstone"
    },
    {
      "x": -7,
      "y": 7,
      "z": -10,
      "name": "Soil_Gravel_Sand_White"
    },
    {
      "x": -7,
      "y": 5,
      "z": -9,
      "name": "Rock_Sandstone"
    },
    {
      "x": -7,
      "y": 6,
      "z": -9,
      "name": "Rock_Sandstone"
    },
    {
      "x": -7,
      "y": 7,
      "z": -9,
      "name": "Rock_Sandstone"
    },
    {
      "x": -7,
      "y": 8,
      "z": -9,
      "name": "Soil_Gravel_Sand_White"
    },
    {
      "x": -7,
      "y": 5,
      "z": -8,
      "name": "Rock_Sandstone"
    },
    {
      "x": -7,
      "y": 6,
      "z": -8,
      "name": "Rock_Sandstone"
    },
    {
      "x": -7,
      "y": 7,
      "z": -8,
      "name": "Rock_Sandstone"
    },
    {
      "x": -7,
      "y": 8,
      "z": -8,
      "name": "Soil_Gravel_Sand_White"
    },
    {
      "x": -7,
      "y": 5,
      "z": -7,
      "name": "Rock_Sandstone"
    },
    {
      "x": -7,
      "y": 6,
      "z": -7,
      "name": "Rock_Sandstone"
    },
    {
      "x": -7,
      "y": 7,
      "z": -7,
      "name": "Rock_Sandstone"
    },
    {
      "x": -7,
      "y": 8,
      "z": -7,
      "name": "Soil_Gravel_Sand_White"
    },
    {
      "x": -7,
      "y": 5,
      "z": -6,
      "name": "Rock_Sandstone"
    },
    {
      "x": -7,
      "y": 6,
      "z": -6,
      "name": "Rock_Sandstone"
    },
    {
      "x": -7,
      "y": 7,
      "z": -6,
      "name": "Rock_Sandstone"
    },
    {
      "x": -7,
      "y": 8,
      "z": -6,
      "name": "Soil_Gravel_Sand_White"
    },
    {
      "x": -7,
      "y": 5,
      "z": -5,
      "name": "Rock_Sandstone"
    },
    {
      "x": -7,
      "y": 6,
      "z": -5,
      "name": "Rock_Sandstone"
    },
    {
      "x": -7,
      "y": 7,
      "z": -5,
      "name": "Soil_Gravel_Sand_White"
    },
    {
      "x": -7,
      "y": 8,
      "z": -5,
      "name": "Soil_Gravel_Sand_White"
    },
    {
      "x": -7,
      "y": 5,
      "z": -4,
      "name": "Rock_Sandstone"
    },
    {
      "x": -7,
      "y": 6,
      "z": -4,
      "name": "Rock_Sandstone"
    },
    {
      "x": -7,
      "y": 7,
      "z": -4,
      "name": "Soil_Gravel_Sand_White"
    },
    {
      "x": -7,
      "y": 5,
      "z": -3,
      "name": "Rock_Sandstone"
    },
    {
      "x": -7,
      "y": 6,
      "z": -3,
      "name": "Rock_Sandstone"
    },
    {
      "x": -7,
      "y": 7,
      "z": -3,
      "name": "Soil_Gravel_Sand_White"
    },
    {
      "x": -7,
      "y": 5,
      "z": -2,
      "name": "Rock_Sandstone"
    },
    {
      "x": -7,
      "y": 6,
      "z": -2,
      "name": "Rock_Sandstone"
    },
    {
      "x": -7,
      "y": 7,
      "z": -2,
      "name": "Rock_Sandstone"
    },
    {
      "x": -7,
      "y": 8,
      "z": -2,
      "name": "Soil_Gravel_Sand_White"
    },
    {
      "x": -7,
      "y": 5,
      "z": -1,
      "name": "Rock_Sandstone"
    },
    {
      "x": -7,
      "y": 6,
      "z": -1,
      "name": "Rock_Sandstone"
    },
    {
      "x": -7,
      "y": 7,
      "z": -1,
      "name": "Rock_Sandstone"
    },
    {
      "x": -7,
      "y": 8,
      "z": -1,
      "name": "Soil_Gravel_Sand_White"
    },
    {
      "x": -7,
      "y": 5,
      "z": 0,
      "name": "Rock_Sandstone"
    },
    {
      "x": -7,
      "y": 6,
      "z": 0,
      "name": "Rock_Sandstone"
    },
    {
      "x": -7,
      "y": 7,
      "z": 0,
      "name": "Rock_Sandstone"
    },
    {
      "x": -7,
      "y": 8,
      "z": 0,
      "name": "Rock_Sandstone"
    },
    {
      "x": -7,
      "y": 9,
      "z": 0,
      "name": "Soil_Gravel_Sand_White"
    },
    {
      "x": -7,
      "y": 5,
      "z": 1,
      "name": "Rock_Sandstone"
    },
    {
      "x": -7,
      "y": 6,
      "z": 1,
      "name": "Rock_Sandstone"
    },
    {
      "x": -7,
      "y": 7,
      "z": 1,
      "name": "Rock_Sandstone"
    },
    {
      "x": -7,
      "y": 8,
      "z": 1,
      "name": "Rock_Sandstone"
    },
    {
      "x": -7,
      "y": 9,
      "z": 1,
      "name": "Rock_Sandstone_White_Cobble"
    },
    {
      "x": -7,
      "y": 5,
      "z": 2,
      "name": "Rock_Sandstone"
    },
    {
      "x": -7,
      "y": 6,
      "z": 2,
      "name": "Rock_Sandstone"
    },
    {
      "x": -7,
      "y": 7,
      "z": 2,
      "name": "Rock_Sandstone"
    },
    {
      "x": -7,
      "y": 8,
      "z": 2,
      "name": "Rock_Sandstone"
    },
    {
      "x": -7,
      "y": 9,
      "z": 2,
      "name": "Rock_Sandstone_White_Cobble"
    },
    {
      "x": -7,
      "y": 5,
      "z": 3,
      "name": "Rock_Sandstone"
    },
    {
      "x": -7,
      "y": 6,
      "z": 3,
      "name": "Rock_Sandstone"
    },
    {
      "x": -7,
      "y": 7,
      "z": 3,
      "name": "Rock_Sandstone"
    },
    {
      "x": -7,
      "y": 8,
      "z": 3,
      "name": "Rock_Sandstone"
    },
    {
      "x": -7,
      "y": 9,
      "z": 3,
      "name": "Rock_Sandstone_White_Cobble"
    },
    {
      "x": -7,
      "y": 10,
      "z": 3,
      "name": "Rock_Sandstone_White_Cobble_Stairs",
      "rotation": 2
    },
    {
      "x": -7,
      "y": 5,
      "z": 4,
      "name": "Rock_Sandstone"
    },
    {
      "x": -7,
      "y": 6,
      "z": 4,
      "name": "Rock_Sandstone"
    },
    {
      "x": -7,
      "y": 7,
      "z": 4,
      "name": "Rock_Sandstone"
    },
    {
      "x": -7,
      "y": 8,
      "z": 4,
      "name": "Rock_Sandstone"
    },
    {
      "x": -7,
      "y": 9,
      "z": 4,
      "name": "Rock_Sandstone_White_Cobble"
    },
    {
      "x": -7,
      "y": 10,
      "z": 4,
      "name": "Rock_Sandstone_White_Cobble"
    },
    {
      "x": -7,
      "y": 11,
      "z": 4,
      "name": "Rock_Sandstone_White_Cobble_Stairs",
      "rotation": 2
    },
    {
      "x": -7,
      "y": 18,
      "z": 4,
      "name": "Wood_Dry_Branch_Short",
      "rotation": 2
    },
    {
      "x": -7,
      "y": 19,
      "z": 4,
      "name": "Rock_Sandstone_Brick_Smooth_Half",
      "rotation": 6
    },
    {
      "x": -7,
      "y": 20,
      "z": 4,
      "name": "Rock_Sandstone_Brick_Smooth_Half",
      "rotation": 6
    },
    {
      "x": -7,
      "y": 5,
      "z": 5,
      "name": "Rock_Sandstone_Brick"
    },
    {
      "x": -7,
      "y": 6,
      "z": 5,
      "name": "Rock_Sandstone_Brick"
    },
    {
      "x": -7,
      "y": 7,
      "z": 5,
      "name": "Rock_Sandstone_Brick"
    },
    {
      "x": -7,
      "y": 8,
      "z": 5,
      "name": "Rock_Sandstone_Brick"
    },
    {
      "x": -7,
      "y": 9,
      "z": 5,
      "name": "Rock_Sandstone_Brick_Ornate"
    },
    {
      "x": -7,
      "y": 10,
      "z": 5,
      "name": "Rock_Sandstone_Brick"
    },
    {
      "x": -7,
      "y": 11,
      "z": 5,
      "name": "Rock_Sandstone_Brick_Smooth"
    },
    {
      "x": -7,
      "y": 12,
      "z": 5,
      "name": "Rock_Sandstone_Brick_Half",
      "rotation": 7
    },
    {
      "x": -7,
      "y": 13,
      "z": 5,
      "name": "Rock_Sandstone_Brick_Half",
      "rotation": 7
    },
    {
      "x": -7,
      "y": 14,
      "z": 5,
      "name": "Rock_Sandstone_Brick_Stairs",
      "rotation": 9
    },
    {
      "x": -7,
      "y": 15,
      "z": 5,
      "name": "Rock_Sandstone_Brick"
    },
    {
      "x": -7,
      "y": 16,
      "z": 5,
      "name": "Rock_Sandstone_Brick_Half",
      "rotation": 5
    },
    {
      "x": -7,
      "y": 17,
      "z": 5,
      "name": "Rock_Sandstone_Brick_Half",
      "rotation": 5
    },
    {
      "x": -7,
      "y": 18,
      "z": 5,
      "name": "Rock_Sandstone_Brick"
    },
    {
      "x": -7,
      "y": 19,
      "z": 5,
      "name": "Rock_Sandstone_Brick_Smooth"
    },
    {
      "x": -7,
      "y": 20,
      "z": 5,
      "name": "Rock_Sandstone_Brick_Smooth"
    },
    {
      "x": -7,
      "y": 5,
      "z": 6,
      "name": "Soil_Dirt_Dry"
    },
    {
      "x": -7,
      "y": 6,
      "z": 6,
      "name": "Soil_Dirt_Dry"
    },
    {
      "x": -7,
      "y": 7,
      "z": 6,
      "name": "Plant_Bush_Arid_Sharp"
    },
    {
      "x": -7,
      "y": 11,
      "z": 6,
      "name": "Wood_Drywood_Planks"
    },
    {
      "x": -7,
      "y": 19,
      "z": 6,
      "name": "Wood_Drywood_Planks"
    },
    {
      "x": -7,
      "y": 20,
      "z": 6,
      "name": "Furniture_Ancient_Barrel"
    },
    {
      "x": -7,
      "y": 5,
      "z": 7,
      "name": "Soil_Dirt_Dry"
    },
    {
      "x": -7,
      "y": 6,
      "z": 7,
      "name": "Soil_Dirt_Dry"
    },
    {
      "x": -7,
      "y": 11,
      "z": 7,
      "name": "Wood_Drywood_Planks"
    },
    {
      "x": -7,
      "y": 19,
      "z": 7,
      "name": "Wood_Drywood_Beam",
      "rotation": 5
    },
    {
      "x": -7,
      "y": 5,
      "z": 8,
      "name": "Soil_Dirt_Dry"
    },
    {
      "x": -7,
      "y": 6,
      "z": 8,
      "name": "Soil_Dirt_Dry"
    },
    {
      "x": -7,
      "y": 11,
      "z": 8,
      "name": "Wood_Drywood_Planks"
    },
    {
      "x": -7,
      "y": 5,
      "z": 9,
      "name": "Soil_Dirt_Dry"
    },
    {
      "x": -7,
      "y": 6,
      "z": 9,
      "name": "Soil_Dirt_Dry"
    },
    {
      "x": -7,
      "y": 11,
      "z": 9,
      "name": "Wood_Drywood_Planks"
    },
    {
      "x": -7,
      "y": 5,
      "z": 10,
      "name": "Soil_Dirt_Dry"
    },
    {
      "x": -7,
      "y": 6,
      "z": 10,
      "name": "Soil_Dirt_Dry"
    },
    {
      "x": -7,
      "y": 7,
      "z": 10,
      "name": "Plant_Bush_Arid_Sharp"
    },
    {
      "x": -7,
      "y": 11,
      "z": 10,
      "name": "Wood_Drywood_Planks_Half",
      "rotation": 6
    },
    {
      "x": -7,
      "y": 19,
      "z": 10,
      "name": "Wood_Drywood_Beam",
      "rotation": 5
    },
    {
      "x": -7,
      "y": 5,
      "z": 11,
      "name": "Rock_Sandstone_Brick"
    },
    {
      "x": -7,
      "y": 6,
      "z": 11,
      "name": "Rock_Sandstone_Brick"
    },
    {
      "x": -7,
      "y": 7,
      "z": 11,
      "name": "Rock_Sandstone_Brick"
    },
    {
      "x": -7,
      "y": 8,
      "z": 11,
      "name": "Rock_Sandstone_Brick"
    },
    {
      "x": -7,
      "y": 9,
      "z": 11,
      "name": "Rock_Sandstone_Brick_Ornate"
    },
    {
      "x": -7,
      "y": 10,
      "z": 11,
      "name": "Rock_Sandstone_Brick"
    },
    {
      "x": -7,
      "y": 11,
      "z": 11,
      "name": "Rock_Sandstone_Brick"
    },
    {
      "x": -7,
      "y": 12,
      "z": 11,
      "name": "Rock_Sandstone_Brick"
    },
    {
      "x": -7,
      "y": 13,
      "z": 11,
      "name": "Rock_Sandstone_Brick"
    },
    {
      "x": -7,
      "y": 14,
      "z": 11,
      "name": "Rock_Sandstone_Brick"
    },
    {
      "x": -7,
      "y": 15,
      "z": 11,
      "name": "Rock_Sandstone_Brick_Half"
    },
    {
      "x": -7,
      "y": 5,
      "z": 12,
      "name": "Rock_Sandstone_Brick_Smooth"
    },
    {
      "x": -7,
      "y": 6,
      "z": 12,
      "name": "Rock_Sandstone_Brick_Smooth"
    },
    {
      "x": -7,
      "y": 7,
      "z": 12,
      "name": "Rock_Sandstone_Brick_Smooth"
    },
    {
      "x": -7,
      "y": 8,
      "z": 12,
      "name": "Rock_Sandstone_Brick_Smooth"
    },
    {
      "x": -7,
      "y": 9,
      "z": 12,
      "name": "Rock_Sandstone_Brick_Smooth"
    },
    {
      "x": -7,
      "y": 10,
      "z": 12,
      "name": "Rock_Sandstone_Brick_Smooth"
    },
    {
      "x": -7,
      "y": 11,
      "z": 12,
      "name": "Rock_Sandstone_Brick_Smooth"
    },
    {
      "x": -7,
      "y": 12,
      "z": 12,
      "name": "Rock_Sandstone_Brick_Smooth"
    },
    {
      "x": -7,
      "y": 13,
      "z": 12,
      "name": "Rock_Sandstone_Brick_Smooth"
    },
    {
      "x": -7,
      "y": 5,
      "z": 13,
      "name": "Rock_Sandstone_Brick_Smooth_Half",
      "rotation": 4
    },
    {
      "x": -7,
      "y": 6,
      "z": 13,
      "name": "Rock_Sandstone_Brick_Smooth_Half",
      "rotation": 4
    },
    {
      "x": -7,
      "y": 7,
      "z": 13,
      "name": "Rock_Sandstone_Brick_Smooth_Half",
      "rotation": 4
    },
    {
      "x": -7,
      "y": 8,
      "z": 13,
      "name": "Rock_Sandstone_Brick_Smooth_Half",
      "rotation": 4
    },
    {
      "x": -7,
      "y": 9,
      "z": 13,
      "name": "Rock_Sandstone_Brick_Smooth_Half",
      "rotation": 4
    },
    {
      "x": -6,
      "y": 5,
      "z": -12,
      "name": "Soil_Gravel_Sand_White"
    },
    {
      "x": -6,
      "y": 5,
      "z": -11,
      "name": "Rock_Sandstone_Brick"
    },
    {
      "x": -6,
      "y": 6,
      "z": -11,
      "name": "Soil_Gravel_Sand_White"
    },
    {
      "x": -6,
      "y": 5,
      "z": -10,
      "name": "Rock_Sandstone_Brick"
    },
    {
      "x": -6,
      "y": 6,
      "z": -10,
      "name": "Soil_Gravel_Sand_White"
    },
    {
      "x": -6,
      "y": 7,
      "z": -10,
      "name": "Soil_Gravel_Sand_White"
    },
    {
      "x": -6,
      "y": 5,
      "z": -9,
      "name": "Rock_Sandstone_Brick"
    },
    {
      "x": -6,
      "y": 6,
      "z": -9,
      "name": "Rock_Sandstone_Brick"
    },
    {
      "x": -6,
      "y": 7,
      "z": -9,
      "name": "Soil_Gravel_Sand_White"
    },
    {
      "x": -6,
      "y": 5,
      "z": -8,
      "name": "Rock_Sandstone_Cobble"
    },
    {
      "x": -6,
      "y": 6,
      "z": -8,
      "name": "Rock_Sandstone_Cobble"
    },
    {
      "x": -6,
      "y": 7,
      "z": -8,
      "name": "Soil_Gravel_Sand_White"
    },
    {
      "x": -6,
      "y": 5,
      "z": -7,
      "name": "Rock_Sandstone_Cobble"
    },
    {
      "x": -6,
      "y": 6,
      "z": -7,
      "name": "Rock_Sandstone_Cobble"
    },
    {
      "x": -6,
      "y": 7,
      "z": -7,
      "name": "Rock_Sandstone_Cobble"
    },
    {
      "x": -6,
      "y": 5,
      "z": -6,
      "name": "Rock_Sandstone_Cobble"
    },
    {
      "x": -6,
      "y": 6,
      "z": -6,
      "name": "Rock_Sandstone_Cobble"
    },
    {
      "x": -6,
      "y": 7,
      "z": -6,
      "name": "Rock_Sandstone_Cobble"
    },
    {
      "x": -6,
      "y": 5,
      "z": -5,
      "name": "Rock_Sandstone_Cobble"
    },
    {
      "x": -6,
      "y": 6,
      "z": -5,
      "name": "Soil_Gravel_Sand_White"
    },
    {
      "x": -6,
      "y": 5,
      "z": -4,
      "name": "Rock_Sandstone_Cobble"
    },
    {
      "x": -6,
      "y": 6,
      "z": -4,
      "name": "Soil_Gravel_Sand_White"
    },
    {
      "x": -6,
      "y": 5,
      "z": -3,
      "name": "Rock_Sandstone_Cobble"
    },
    {
      "x": -6,
      "y": 6,
      "z": -3,
      "name": "Soil_Gravel_Sand_White"
    },
    {
      "x": -6,
      "y": 7,
      "z": -3,
      "name": "Soil_Gravel_Sand_White"
    },
    {
      "x": -6,
      "y": 5,
      "z": -2,
      "name": "Rock_Sandstone_Cobble"
    },
    {
      "x": -6,
      "y": 6,
      "z": -2,
      "name": "Rock_Sandstone_Brick"
    },
    {
      "x": -6,
      "y": 7,
      "z": -2,
      "name": "Soil_Gravel_Sand_White"
    },
    {
      "x": -6,
      "y": 5,
      "z": -1,
      "name": "Rock_Sandstone_Cobble"
    },
    {
      "x": -6,
      "y": 6,
      "z": -1,
      "name": "Rock_Sandstone_Brick"
    },
    {
      "x": -6,
      "y": 7,
      "z": -1,
      "name": "Soil_Gravel_Sand_White"
    },
    {
      "x": -6,
      "y": 8,
      "z": -1,
      "name": "Soil_Gravel_Sand_White"
    },
    {
      "x": -6,
      "y": 5,
      "z": 0,
      "name": "Rock_Sandstone_Cobble"
    },
    {
      "x": -6,
      "y": 6,
      "z": 0,
      "name": "Rock_Sandstone_Cobble"
    },
    {
      "x": -6,
      "y": 7,
      "z": 0,
      "name": "Rock_Sandstone_Brick"
    },
    {
      "x": -6,
      "y": 8,
      "z": 0,
      "name": "Soil_Gravel_Sand_White"
    },
    {
      "x": -6,
      "y": 5,
      "z": 1,
      "name": "Rock_Sandstone_Cobble"
    },
    {
      "x": -6,
      "y": 6,
      "z": 1,
      "name": "Rock_Sandstone_Brick"
    },
    {
      "x": -6,
      "y": 7,
      "z": 1,
      "name": "Rock_Sandstone_Brick"
    },
    {
      "x": -6,
      "y": 8,
      "z": 1,
      "name": "Rock_Sandstone_Brick"
    },
    {
      "x": -6,
      "y": 9,
      "z": 1,
      "name": "Rock_Sandstone_Brick"
    },
    {
      "x": -6,
      "y": 10,
      "z": 1,
      "name": "Rock_Sandstone_Brick_Smooth_Half"
    },
    {
      "x": -6,
      "y": 5,
      "z": 2,
      "name": "Rock_Sandstone_Brick"
    },
    {
      "x": -6,
      "y": 6,
      "z": 2,
      "name": "Rock_Sandstone_Brick"
    },
    {
      "x": -6,
      "y": 7,
      "z": 2,
      "name": "Rock_Sandstone_Brick"
    },
    {
      "x": -6,
      "y": 8,
      "z": 2,
      "name": "Rock_Sandstone_Brick"
    },
    {
      "x": -6,
      "y": 9,
      "z": 2,
      "name": "Rock_Sandstone_Brick"
    },
    {
      "x": -6,
      "y": 10,
      "z": 2,
      "name": "Rock_Sandstone_Brick_Smooth"
    },
    {
      "x": -6,
      "y": 5,
      "z": 3,
      "name": "Rock_Sandstone_Brick"
    },
    {
      "x": -6,
      "y": 6,
      "z": 3,
      "name": "Rock_Sandstone_Brick"
    },
    {
      "x": -6,
      "y": 7,
      "z": 3,
      "name": "Rock_Sandstone_Brick"
    },
    {
      "x": -6,
      "y": 8,
      "z": 3,
      "name": "Rock_Sandstone_Brick"
    },
    {
      "x": -6,
      "y": 9,
      "z": 3,
      "name": "Rock_Sandstone_Brick"
    },
    {
      "x": -6,
      "y": 10,
      "z": 3,
      "name": "Rock_Sandstone_Brick_Smooth_Half"
    },
    {
      "x": -6,
      "y": 5,
      "z": 4,
      "name": "Rock_Sandstone_Brick"
    },
    {
      "x": -6,
      "y": 6,
      "z": 4,
      "name": "Rock_Sandstone_Brick"
    },
    {
      "x": -6,
      "y": 7,
      "z": 4,
      "name": "Rock_Sandstone_Brick"
    },
    {
      "x": -6,
      "y": 8,
      "z": 4,
      "name": "Rock_Sandstone_Brick"
    },
    {
      "x": -6,
      "y": 9,
      "z": 4,
      "name": "Wood_Dry_Branch_Short",
      "rotation": 2
    },
    {
      "x": -6,
      "y": 10,
      "z": 4,
      "name": "Rock_Sandstone_Brick_Smooth"
    },
    {
      "x": -6,
      "y": 19,
      "z": 4,
      "name": "Rock_Sandstone_Brick_Smooth_Half",
      "rotation": 6
    },
    {
      "x": -6,
      "y": 5,
      "z": 5,
      "name": "Rock_Sandstone_Cobble"
    },
    {
      "x": -6,
      "y": 6,
      "z": 5,
      "name": "Rock_Sandstone_Brick"
    },
    {
      "x": -6,
      "y": 7,
      "z": 5,
      "name": "Rock_Sandstone_Brick"
    },
    {
      "x": -6,
      "y": 8,
      "z": 5,
      "name": "Rock_Sandstone_Brick"
    },
    {
      "x": -6,
      "y": 9,
      "z": 5,
      "name": "Rock_Sandstone_Brick_Ornate"
    },
    {
      "x": -6,
      "y": 10,
      "z": 5,
      "name": "Rock_Sandstone_Brick"
    },
    {
      "x": -6,
      "y": 11,
      "z": 5,
      "name": "Rock_Sandstone_Brick"
    },
    {
      "x": -6,
      "y": 12,
      "z": 5,
      "name": "Rock_Sandstone_Brick"
    },
    {
      "x": -6,
      "y": 13,
      "z": 5,
      "name": "Rock_Sandstone_Brick"
    },
    {
      "x": -6,
      "y": 14,
      "z": 5,
      "name": "Rock_Sandstone_Brick"
    },
    {
      "x": -6,
      "y": 15,
      "z": 5,
      "name": "Rock_Sandstone_Brick"
    },
    {
      "x": -6,
      "y": 16,
      "z": 5,
      "name": "Rock_Sandstone_Brick"
    },
    {
      "x": -6,
      "y": 17,
      "z": 5,
      "name": "Rock_Sandstone_Brick"
    },
    {
      "x": -6,
      "y": 18,
      "z": 5,
      "name": "Rock_Sandstone_Brick"
    },
    {
      "x": -6,
      "y": 19,
      "z": 5,
      "name": "Rock_Sandstone_Brick_Smooth"
    },
    {
      "x": -6,
      "y": 20,
      "z": 5,
      "name": "Rock_Sandstone_Brick_Smooth_Half"
    },
    {
      "x": -6,
      "y": 5,
      "z": 6,
      "name": "Soil_Dirt_Dry"
    },
    {
      "x": -6,
      "y": 6,
      "z": 6,
      "name": "Soil_Dirt_Dry"
    },
    {
      "x": -6,
      "y": 11,
      "z": 6,
      "name": "Wood_Drywood_Planks"
    },
    {
      "x": -6,
      "y": 13,
      "z": 6,
      "name": "Wood_Torch_Wall"
    },
    {
      "x": -6,
      "y": 19,
      "z": 6,
      "name": "Wood_Drywood_Planks"
    },
    {
      "x": -6,
      "y": 5,
      "z": 7,
      "name": "Soil_Dirt_Dry"
    },
    {
      "x": -6,
      "y": 6,
      "z": 7,
      "name": "Soil_Dirt_Dry"
    },
    {
      "x": -6,
      "y": 11,
      "z": 7,
      "name": "Wood_Drywood_Planks"
    },
    {
      "x": -6,
      "y": 19,
      "z": 7,
      "name": "Wood_Drywood_Beam",
      "rotation": 5
    },
    {
      "x": -6,
      "y": 5,
      "z": 8,
      "name": "Soil_Dirt_Dry"
    },
    {
      "x": -6,
      "y": 6,
      "z": 8,
      "name": "Soil_Dirt_Dry"
    },
    {
      "x": -6,
      "y": 11,
      "z": 8,
      "name": "Wood_Drywood_Planks"
    },
    {
      "x": -6,
      "y": 5,
      "z": 9,
      "name": "Soil_Dirt_Dry"
    },
    {
      "x": -6,
      "y": 6,
      "z": 9,
      "name": "Soil_Dirt_Dry"
    },
    {
      "x": -6,
      "y": 11,
      "z": 9,
      "name": "Wood_Drywood_Beam",
      "rotation": 5
    },
    {
      "x": -6,
      "y": 5,
      "z": 10,
      "name": "Soil_Dirt_Dry"
    },
    {
      "x": -6,
      "y": 6,
      "z": 10,
      "name": "Soil_Dirt_Dry"
    },
    {
      "x": -6,
      "y": 11,
      "z": 10,
      "name": "Wood_Drywood_Planks_Half",
      "rotation": 6
    },
    {
      "x": -6,
      "y": 5,
      "z": 11,
      "name": "Rock_Sandstone_Brick"
    },
    {
      "x": -6,
      "y": 6,
      "z": 11,
      "name": "Rock_Sandstone_Brick"
    },
    {
      "x": -6,
      "y": 7,
      "z": 11,
      "name": "Rock_Sandstone_Brick"
    },
    {
      "x": -6,
      "y": 8,
      "z": 11,
      "name": "Rock_Sandstone_Brick"
    },
    {
      "x": -6,
      "y": 9,
      "z": 11,
      "name": "Rock_Sandstone_Brick_Ornate"
    },
    {
      "x": -6,
      "y": 10,
      "z": 11,
      "name": "Rock_Sandstone_Brick"
    },
    {
      "x": -6,
      "y": 11,
      "z": 11,
      "name": "Rock_Sandstone_Brick"
    },
    {
      "x": -6,
      "y": 12,
      "z": 11,
      "name": "Rock_Sandstone_Brick"
    },
    {
      "x": -6,
      "y": 13,
      "z": 11,
      "name": "Rock_Sandstone_Brick"
    },
    {
      "x": -6,
      "y": 14,
      "z": 11,
      "name": "Rock_Sandstone_Brick"
    },
    {
      "x": -6,
      "y": 11,
      "z": 12,
      "name": "Wood_Dry_Branch_Short"
    },
    {
      "x": -5,
      "y": 5,
      "z": -8,
      "name": "Rock_Sandstone_Brick"
    },
    {
      "x": -5,
      "y": 6,
      "z": -8,
      "name": "Rock_Sandstone_Brick"
    },
    {
      "x": -5,
      "y": 5,
      "z": -7,
      "name": "Rock_Sandstone_Cobble"
    },
    {
      "x": -5,
      "y": 6,
      "z": -7,
      "name": "Rock_Sandstone_Cobble"
    },
    {
      "x": -5,
      "y": 7,
      "z": -7,
      "name": "Rock_Sandstone_Cobble_Half"
    },
    {
      "x": -5,
      "y": 5,
      "z": -6,
      "name": "Rock_Sandstone_Cobble"
    },
    {
      "x": -5,
      "y": 6,
      "z": -6,
      "name": "Rock_Sandstone_Cobble"
    },
    {
      "x": -5,
      "y": 7,
      "z": -6,
      "name": "Rock_Sandstone_Cobble"
    },
    {
      "x": -5,
      "y": 5,
      "z": -5,
      "name": "Rock_Sandstone_Cobble"
    },
    {
      "x": -5,
      "y": 9,
      "z": 3,
      "name": "Rock_Sandstone_Brick_Smooth_Half",
      "rotation": 5
    },
    {
      "x": -5,
      "y": 9,
      "z": 4,
      "name": "Rock_Sandstone_Brick_Smooth_Half",
      "rotation": 5
    },
    {
      "x": -5,
      "y": 10,
      "z": 4,
      "name": "Rock_Sandstone_Brick_Smooth_Half",
      "rotation": 5
    },
    {
      "x": -5,
      "y": 18,
      "z": 4,
      "name": "Wood_Dry_Branch_Short",
      "rotation": 2
    },
    {
      "x": -5,
      "y": 19,
      "z": 4,
      "name": "Rock_Sandstone_Brick_Smooth_Half",
      "rotation": 6
    },
    {
      "x": -5,
      "y": 20,
      "z": 4,
      "name": "Rock_Sandstone_Brick_Smooth_Half",
      "rotation": 6
    },
    {
      "x": -5,
      "y": 5,
      "z": 5,
      "name": "Rock_Sandstone_Cobble"
    },
    {
      "x": -5,
      "y": 6,
      "z": 5,
      "name": "Rock_Sandstone_Brick"
    },
    {
      "x": -5,
      "y": 7,
      "z": 5,
      "name": "Rock_Sandstone_Brick"
    },
    {
      "x": -5,
      "y": 8,
      "z": 5,
      "name": "Rock_Sandstone_Brick"
    },
    {
      "x": -5,
      "y": 9,
      "z": 5,
      "name": "Rock_Sandstone_Brick_Ornate"
    },
    {
      "x": -5,
      "y": 10,
      "z": 5,
      "name": "Rock_Sandstone_Brick"
    },
    {
      "x": -5,
      "y": 11,
      "z": 5,
      "name": "Rock_Sandstone_Brick_Half",
      "rotation": 6
    },
    {
      "x": -5,
      "y": 12,
      "z": 5,
      "name": "Rock_Sandstone_Brick_Half",
      "rotation": 6
    },
    {
      "x": -5,
      "y": 13,
      "z": 5,
      "name": "Rock_Sandstone_Brick_Half",
      "rotation": 6
    },
    {
      "x": -5,
      "y": 14,
      "z": 5,
      "name": "Rock_Sandstone_Brick"
    },
    {
      "x": -5,
      "y": 15,
      "z": 5,
      "name": "Rock_Sandstone_Brick"
    },
    {
      "x": -5,
      "y": 16,
      "z": 5,
      "name": "Rock_Sandstone_Brick"
    },
    {
      "x": -5,
      "y": 17,
      "z": 5,
      "name": "Rock_Sandstone_Brick"
    },
    {
      "x": -5,
      "y": 18,
      "z": 5,
      "name": "Rock_Sandstone_Brick"
    },
    {
      "x": -5,
      "y": 19,
      "z": 5,
      "name": "Rock_Sandstone_Brick_Smooth"
    },
    {
      "x": -5,
      "y": 20,
      "z": 5,
      "name": "Rock_Sandstone_Brick_Smooth"
    },
    {
      "x": -5,
      "y": 5,
      "z": 6,
      "name": "Rock_Sandstone_Cobble"
    },
    {
      "x": -5,
      "y": 6,
      "z": 6,
      "name": "Rock_Sandstone_Cobble"
    },
    {
      "x": -5,
      "y": 7,
      "z": 6,
      "name": "Rock_Sandstone_Brick"
    },
    {
      "x": -5,
      "y": 8,
      "z": 6,
      "name": "Rock_Sandstone_Brick"
    },
    {
      "x": -5,
      "y": 9,
      "z": 6,
      "name": "Rock_Sandstone_Brick_Ornate"
    },
    {
      "x": -5,
      "y": 10,
      "z": 6,
      "name": "Rock_Sandstone_Brick"
    },
    {
      "x": -5,
      "y": 11,
      "z": 6,
      "name": "Rock_Sandstone_Brick"
    },
    {
      "x": -5,
      "y": 12,
      "z": 6,
      "name": "Rock_Sandstone_Brick"
    },
    {
      "x": -5,
      "y": 13,
      "z": 6,
      "name": "Rock_Sandstone_Brick"
    },
    {
      "x": -5,
      "y": 14,
      "z": 6,
      "name": "Rock_Sandstone_Brick"
    },
    {
      "x": -5,
      "y": 15,
      "z": 6,
      "name": "Rock_Sandstone_Brick"
    },
    {
      "x": -5,
      "y": 16,
      "z": 6,
      "name": "Rock_Sandstone_Brick"
    },
    {
      "x": -5,
      "y": 17,
      "z": 6,
      "name": "Rock_Sandstone_Brick"
    },
    {
      "x": -5,
      "y": 18,
      "z": 6,
      "name": "Rock_Sandstone_Brick"
    },
    {
      "x": -5,
      "y": 19,
      "z": 6,
      "name": "Rock_Sandstone_Brick_Smooth"
    },
    {
      "x": -5,
      "y": 20,
      "z": 6,
      "name": "Rock_Sandstone_Brick_Smooth_Half"
    },
    {
      "x": -5,
      "y": 5,
      "z": 7,
      "name": "Rock_Sandstone_Cobble"
    },
    {
      "x": -5,
      "y": 6,
      "z": 7,
      "name": "Rock_Sandstone_Brick"
    },
    {
      "x": -5,
      "y": 7,
      "z": 7,
      "name": "Rock_Sandstone_Brick"
    },
    {
      "x": -5,
      "y": 8,
      "z": 7,
      "name": "Rock_Sandstone_Brick"
    },
    {
      "x": -5,
      "y": 9,
      "z": 7,
      "name": "Rock_Sandstone_Brick_Ornate"
    },
    {
      "x": -5,
      "y": 10,
      "z": 7,
      "name": "Rock_Sandstone_Brick"
    },
    {
      "x": -5,
      "y": 11,
      "z": 7,
      "name": "Rock_Sandstone_Brick_Smooth"
    },
    {
      "x": -5,
      "y": 12,
      "z": 7,
      "name": "Rock_Sandstone_Brick_Half",
      "rotation": 4
    },
    {
      "x": -5,
      "y": 13,
      "z": 7,
      "name": "Rock_Sandstone_Brick_Half",
      "rotation": 4
    },
    {
      "x": -5,
      "y": 14,
      "z": 7,
      "name": "Rock_Sandstone_Brick_Stairs",
      "rotation": 10
    },
    {
      "x": -5,
      "y": 15,
      "z": 7,
      "name": "Rock_Sandstone_Brick"
    },
    {
      "x": -5,
      "y": 16,
      "z": 7,
      "name": "Rock_Sandstone_Brick_Half"
    },
    {
      "x": -5,
      "y": 5,
      "z": 8,
      "name": "Rock_Sandstone_Brick"
    },
    {
      "x": -5,
      "y": 6,
      "z": 8,
      "name": "Rock_Sandstone_Brick"
    },
    {
      "x": -5,
      "y": 7,
      "z": 8,
      "name": "Rock_Sandstone_Brick"
    },
    {
      "x": -5,
      "y": 8,
      "z": 8,
      "name": "Rock_Sandstone_Brick"
    },
    {
      "x": -5,
      "y": 9,
      "z": 8,
      "name": "Rock_Sandstone_Brick_Ornate"
    },
    {
      "x": -5,
      "y": 10,
      "z": 8,
      "name": "Rock_Sandstone_Brick"
    },
    {
      "x": -5,
      "y": 11,
      "z": 8,
      "name": "Rock_Sandstone_Brick_Smooth"
    },
    {
      "x": -5,
      "y": 5,
      "z": 9,
      "name": "Rock_Sandstone_Brick"
    },
    {
      "x": -5,
      "y": 6,
      "z": 9,
      "name": "Rock_Sandstone_Brick"
    },
    {
      "x": -5,
      "y": 7,
      "z": 9,
      "name": "Rock_Sandstone_Brick"
    },
    {
      "x": -5,
      "y": 8,
      "z": 9,
      "name": "Rock_Sandstone_Brick"
    },
    {
      "x": -5,
      "y": 9,
      "z": 9,
      "name": "Rock_Sandstone_Brick_Ornate"
    },
    {
      "x": -5,
      "y": 10,
      "z": 9,
      "name": "Rock_Sandstone_Brick"
    },
    {
      "x": -5,
      "y": 11,
      "z": 9,
      "name": "Rock_Sandstone_Brick_Smooth"
    },
    {
      "x": -5,
      "y": 12,
      "z": 9,
      "name": "Rock_Sandstone_Brick_Half",
      "rotation": 6
    },
    {
      "x": -5,
      "y": 13,
      "z": 9,
      "name": "Rock_Sandstone_Brick_Half",
      "rotation": 6
    },
    {
      "x": -5,
      "y": 5,
      "z": 10,
      "name": "Rock_Sandstone_Brick"
    },
    {
      "x": -5,
      "y": 6,
      "z": 10,
      "name": "Rock_Sandstone_Brick"
    },
    {
      "x": -5,
      "y": 7,
      "z": 10,
      "name": "Rock_Sandstone_Brick"
    },
    {
      "x": -5,
      "y": 8,
      "z": 10,
      "name": "Rock_Sandstone_Brick"
    },
    {
      "x": -5,
      "y": 9,
      "z": 10,
      "name": "Rock_Sandstone_Brick_Ornate"
    },
    {
      "x": -5,
      "y": 10,
      "z": 10,
      "name": "Rock_Sandstone_Brick"
    },
    {
      "x": -5,
      "y": 11,
      "z": 10,
      "name": "Rock_Sandstone_Brick"
    },
    {
      "x": -5,
      "y": 12,
      "z": 10,
      "name": "Rock_Sandstone_Brick"
    },
    {
      "x": -5,
      "y": 13,
      "z": 10,
      "name": "Rock_Sandstone_Brick"
    },
    {
      "x": -5,
      "y": 14,
      "z": 10,
      "name": "Rock_Sandstone_Brick"
    },
    {
      "x": -5,
      "y": 5,
      "z": 11,
      "name": "Rock_Sandstone_Brick"
    },
    {
      "x": -5,
      "y": 6,
      "z": 11,
      "name": "Rock_Sandstone_Brick"
    },
    {
      "x": -5,
      "y": 7,
      "z": 11,
      "name": "Rock_Sandstone_Brick"
    },
    {
      "x": -5,
      "y": 8,
      "z": 11,
      "name": "Rock_Sandstone_Brick"
    },
    {
      "x": -5,
      "y": 9,
      "z": 11,
      "name": "Rock_Sandstone_Brick_Ornate"
    },
    {
      "x": -5,
      "y": 10,
      "z": 11,
      "name": "Rock_Sandstone_Brick"
    },
    {
      "x": -5,
      "y": 11,
      "z": 11,
      "name": "Rock_Sandstone_Brick"
    },
    {
      "x": -5,
      "y": 12,
      "z": 11,
      "name": "Rock_Sandstone_Brick"
    },
    {
      "x": -5,
      "y": 13,
      "z": 11,
      "name": "Rock_Sandstone_Brick"
    },
    {
      "x": -5,
      "y": 14,
      "z": 11,
      "name": "Rock_Sandstone_Brick"
    },
    {
      "x": -4,
      "y": 11,
      "z": 5,
      "name": "Rock_Sandstone_Brick_Smooth_Half",
      "rotation": 6
    },
    {
      "x": -4,
      "y": 12,
      "z": 5,
      "name": "Rock_Sandstone_Brick_Smooth_Half",
      "rotation": 6
    },
    {
      "x": -4,
      "y": 18,
      "z": 5,
      "name": "Wood_Dry_Branch_Short",
      "rotation": 1
    },
    {
      "x": -4,
      "y": 19,
      "z": 5,
      "name": "Rock_Sandstone_Brick_Smooth_Half",
      "rotation": 5
    },
    {
      "x": -4,
      "y": 20,
      "z": 5,
      "name": "Rock_Sandstone_Brick_Smooth_Half",
      "rotation": 5
    },
    {
      "x": -4,
      "y": 5,
      "z": 6,
      "name": "Rock_Sandstone_Cobble"
    },
    {
      "x": -4,
      "y": 6,
      "z": 6,
      "name": "Rock_Sandstone_Cobble"
    },
    {
      "x": -4,
      "y": 7,
      "z": 6,
      "name": "Rock_Sandstone_Brick"
    },
    {
      "x": -4,
      "y": 8,
      "z": 6,
      "name": "Rock_Sandstone_Brick"
    },
    {
      "x": -4,
      "y": 9,
      "z": 6,
      "name": "Rock_Sandstone_Brick_Ornate"
    },
    {
      "x": -4,
      "y": 10,
      "z": 6,
      "name": "Rock_Sandstone_Brick"
    },
    {
      "x": -4,
      "y": 11,
      "z": 6,
      "name": "Wood_Dry_Branch_Short",
      "rotation": 1
    },
    {
      "x": -4,
      "y": 12,
      "z": 6,
      "name": "Rock_Sandstone_Brick_Smooth"
    },
    {
      "x": -4,
      "y": 5,
      "z": 7,
      "name": "Rock_Sandstone"
    },
    {
      "x": -4,
      "y": 6,
      "z": 7,
      "name": "Rock_Sandstone"
    },
    {
      "x": -4,
      "y": 7,
      "z": 7,
      "name": "Rock_Sandstone"
    },
    {
      "x": -4,
      "y": 8,
      "z": 7,
      "name": "Rock_Sandstone"
    },
    {
      "x": -4,
      "y": 9,
      "z": 7,
      "name": "Rock_Sandstone"
    },
    {
      "x": -4,
      "y": 10,
      "z": 7,
      "name": "Rock_Sandstone"
    },
    {
      "x": -4,
      "y": 11,
      "z": 7,
      "name": "Rock_Sandstone_White_Cobble"
    },
    {
      "x": -4,
      "y": 5,
      "z": 8,
      "name": "Rock_Sandstone"
    },
    {
      "x": -4,
      "y": 6,
      "z": 8,
      "name": "Rock_Sandstone"
    },
    {
      "x": -4,
      "y": 7,
      "z": 8,
      "name": "Rock_Sandstone"
    },
    {
      "x": -4,
      "y": 8,
      "z": 8,
      "name": "Rock_Sandstone"
    },
    {
      "x": -4,
      "y": 9,
      "z": 8,
      "name": "Rock_Sandstone"
    },
    {
      "x": -4,
      "y": 10,
      "z": 8,
      "name": "Rock_Sandstone"
    },
    {
      "x": -4,
      "y": 11,
      "z": 8,
      "name": "Rock_Sandstone_White_Cobble"
    },
    {
      "x": -4,
      "y": 5,
      "z": 9,
      "name": "Rock_Sandstone"
    },
    {
      "x": -4,
      "y": 6,
      "z": 9,
      "name": "Rock_Sandstone"
    },
    {
      "x": -4,
      "y": 7,
      "z": 9,
      "name": "Rock_Sandstone"
    },
    {
      "x": -4,
      "y": 8,
      "z": 9,
      "name": "Rock_Sandstone"
    },
    {
      "x": -4,
      "y": 9,
      "z": 9,
      "name": "Rock_Sandstone"
    },
    {
      "x": -4,
      "y": 10,
      "z": 9,
      "name": "Rock_Sandstone"
    },
    {
      "x": -4,
      "y": 11,
      "z": 9,
      "name": "Rock_Sandstone_White_Cobble"
    },
    {
      "x": -4,
      "y": 5,
      "z": 10,
      "name": "Rock_Sandstone_Brick"
    },
    {
      "x": -4,
      "y": 6,
      "z": 10,
      "name": "Rock_Sandstone_Brick"
    },
    {
      "x": -4,
      "y": 7,
      "z": 10,
      "name": "Rock_Sandstone_Brick"
    },
    {
      "x": -4,
      "y": 8,
      "z": 10,
      "name": "Rock_Sandstone_Brick"
    },
    {
      "x": -4,
      "y": 9,
      "z": 10,
      "name": "Rock_Sandstone_Brick_Ornate"
    },
    {
      "x": -4,
      "y": 10,
      "z": 10,
      "name": "Rock_Sandstone_Brick"
    },
    {
      "x": -4,
      "y": 11,
      "z": 10,
      "name": "Wood_Dry_Branch_Short",
      "rotation": 1
    },
    {
      "x": -4,
      "y": 12,
      "z": 10,
      "name": "Rock_Sandstone_Brick_Smooth"
    },
    {
      "x": -4,
      "y": 11,
      "z": 11,
      "name": "Rock_Sandstone_Brick_Smooth_Half",
      "rotation": 4
    },
    {
      "x": -4,
      "y": 12,
      "z": 11,
      "name": "Rock_Sandstone_Brick_Smooth_Half",
      "rotation": 4
    },
    {
      "x": -3,
      "y": 11,
      "z": 5,
      "name": "Rock_Sandstone_Brick_Smooth_Half",
      "rotation": 6
    },
    {
      "x": -3,
      "y": 5,
      "z": 6,
      "name": "Rock_Sandstone_Cobble"
    },
    {
      "x": -3,
      "y": 6,
      "z": 6,
      "name": "Rock_Sandstone_Cobble"
    },
    {
      "x": -3,
      "y": 7,
      "z": 6,
      "name": "Rock_Sandstone_Brick"
    },
    {
      "x": -3,
      "y": 8,
      "z": 6,
      "name": "Rock_Sandstone_Brick"
    },
    {
      "x": -3,
      "y": 9,
      "z": 6,
      "name": "Rock_Sandstone_Brick_Ornate"
    },
    {
      "x": -3,
      "y": 10,
      "z": 6,
      "name": "Rock_Sandstone_Brick"
    },
    {
      "x": -3,
      "y": 11,
      "z": 6,
      "name": "Rock_Sandstone_Brick"
    },
    {
      "x": -3,
      "y": 12,
      "z": 6,
      "name": "Rock_Sandstone_Brick_Smooth_Half"
    },
    {
      "x": -3,
      "y": 5,
      "z": 7,
      "name": "Rock_Sandstone"
    },
    {
      "x": -3,
      "y": 6,
      "z": 7,
      "name": "Rock_Sandstone"
    },
    {
      "x": -3,
      "y": 7,
      "z": 7,
      "name": "Rock_Sandstone"
    },
    {
      "x": -3,
      "y": 8,
      "z": 7,
      "name": "Rock_Sandstone"
    },
    {
      "x": -3,
      "y": 9,
      "z": 7,
      "name": "Rock_Sandstone"
    },
    {
      "x": -3,
      "y": 10,
      "z": 7,
      "name": "Rock_Sandstone"
    },
    {
      "x": -3,
      "y": 11,
      "z": 7,
      "name": "Rock_Sandstone_White_Cobble"
    },
    {
      "x": -3,
      "y": 5,
      "z": 8,
      "name": "Rock_Sandstone"
    },
    {
      "x": -3,
      "y": 6,
      "z": 8,
      "name": "Rock_Sandstone"
    },
    {
      "x": -3,
      "y": 7,
      "z": 8,
      "name": "Rock_Sandstone"
    },
    {
      "x": -3,
      "y": 8,
      "z": 8,
      "name": "Rock_Sandstone"
    },
    {
      "x": -3,
      "y": 9,
      "z": 8,
      "name": "Rock_Sandstone"
    },
    {
      "x": -3,
      "y": 10,
      "z": 8,
      "name": "Rock_Sandstone"
    },
    {
      "x": -3,
      "y": 11,
      "z": 8,
      "name": "Rock_Sandstone_White_Cobble"
    },
    {
      "x": -3,
      "y": 5,
      "z": 9,
      "name": "Rock_Sandstone"
    },
    {
      "x": -3,
      "y": 6,
      "z": 9,
      "name": "Rock_Sandstone"
    },
    {
      "x": -3,
      "y": 7,
      "z": 9,
      "name": "Rock_Sandstone"
    },
    {
      "x": -3,
      "y": 8,
      "z": 9,
      "name": "Rock_Sandstone"
    },
    {
      "x": -3,
      "y": 9,
      "z": 9,
      "name": "Rock_Sandstone"
    },
    {
      "x": -3,
      "y": 10,
      "z": 9,
      "name": "Rock_Sandstone"
    },
    {
      "x": -3,
      "y": 11,
      "z": 9,
      "name": "Rock_Sandstone_White_Cobble"
    },
    {
      "x": -3,
      "y": 5,
      "z": 10,
      "name": "Rock_Sandstone_Brick"
    },
    {
