{
  "version": 8,
  "blockIdVersion": 11,
  "anchorX": 0,
  "anchorY": 0,
  "anchorZ": 0,
  "blocks": [
    {
      "x": -11,
      "y": 0,
      "z": -12,
      "name": "Rock_Sandstone_Cobble"
    },
    {
      "x": -11,
      "y": 1,
      "z": -12,
      "name": "Rock_Sandstone_Cobble"
    },
    {
      "x": -11,
      "y": 2,
      "z": -12,
      "name": "Rock_Sandstone_Cobble"
    },
    {
      "x": -11,
      "y": 3,
      "z": -12,
      "name": "Rock_Sandstone_Cobble"
    },
    {
      "x": -11,
      "y": 4,
      "z": -12,
      "name": "Rock_Sandstone_Cobble"
    },
    {
      "x": -11,
      "y": 5,
      "z": -12,
      "name": "Rock_Sandstone_Cobble"
    },
    {
      "x": -11,
      "y": 6,
      "z": -12,
      "name": "Rock_Sandstone_Cobble"
    },
    {
      "x": -11,
      "y": 7,
      "z": -12,
      "name": "Rock_Sandstone_Cobble"
    },
    {
      "x": -11,
      "y": 8,
      "z": -12,
      "name": "Rock_Sandstone_Cobble"
    },
    {
      "x": -11,
      "y": 0,
      "z": -11,
      "name": "Rock_Sandstone_Cobble"
    },
    {
      "x": -11,
      "y": 1,
      "z": -11,
      "name": "Rock_Sandstone_Cobble"
    },
    {
      "x": -11,
      "y": 2,
      "z": -11,
      "name": "Rock_Sandstone_Cobble"
    },
    {
      "x": -11,
      "y": 3,
      "z": -11,
      "name": "Rock_Sandstone_Cobble"
    },
    {
      "x": -11,
      "y": 4,
      "z": -11,
      "name": "Rock_Sandstone_Cobble"
    },
    {
      "x": -11,
      "y": 5,
      "z": -11,
      "name": "Rock_Sandstone_Cobble"
    },
    {
      "x": -11,
      "y": 6,
      "z": -11,
      "name": "Rock_Sandstone_Cobble"
    },
    {
      "x": -11,
      "y": 7,
      "z": -11,
      "name": "Rock_Sandstone_Cobble"
    },
    {
      "x": -11,
      "y": 8,
      "z": -11,
      "name": "Rock_Sandstone_Cobble"
    },
    {
      "x": -11,
      "y": 0,
      "z": -10,
      "name": "Rock_Sandstone_Brick_Smooth"
    },
    {
      "x": -11,
      "y": 1,
      "z": -10,
      "name": "Rock_Sandstone_Brick_Smooth"
    },
    {
      "x": -11,
      "y": 2,
      "z": -10,
      "name": "Rock_Sandstone_Brick_Smooth"
    },
    {
      "x": -11,
      "y": 3,
      "z": -10,
      "name": "Rock_Sandstone_Brick_Smooth"
    },
    {
      "x": -11,
      "y": 4,
      "z": -10,
      "name": "Rock_Sandstone_Brick_Smooth"
    },
    {
      "x": -11,
      "y": 5,
      "z": -10,
      "name": "Rock_Sandstone_Brick_Smooth"
    },
    {
      "x": -11,
      "y": 6,
      "z": -10,
      "name": "Rock_Sandstone_Brick_Smooth"
    },
    {
      "x": -11,
      "y": 7,
      "z": -10,
      "name": "Rock_Sandstone_Brick_Smooth"
    },
    {
      "x": -11,
      "y": 8,
      "z": -10,
      "name": "Rock_Sandstone_Brick_Smooth"
    },
    {
      "x": -11,
      "y": 9,
      "z": -10,
      "name": "Rock_Sandstone_Brick_Smooth"
    },
    {
      "x": -11,
      "y": 10,
      "z": -10,
      "name": "Rock_Sandstone_Brick_Smooth"
    },
    {
      "x": -11,
      "y": 11,
      "z": -10,
      "name": "Rock_Sandstone_Brick_Smooth"
    },
    {
      "x": -11,
      "y": 12,
      "z": -10,
      "name": "Rock_Sandstone_Brick_Smooth"
    },
    {
      "x": -11,
      "y": 13,
      "z": -10,
      "name": "Rock_Sandstone_Brick_Smooth"
    },
    {
      "x": -11,
      "y": 14,
      "z": -10,
      "name": "Rock_Sandstone_Brick_Smooth_Half"
    },
    {
      "x": -11,
      "y": 0,
      "z": -9,
      "name": "Rock_Sandstone_Cobble"
    },
    {
      "x": -11,
      "y": 1,
      "z": -9,
      "name": "Rock_Sandstone_Cobble"
    },
    {
      "x": -11,
      "y": 2,
      "z": -9,
      "name": "Rock_Sandstone_Cobble"
    },
    {
      "x": -11,
      "y": 3,
      "z": -9,
      "name": "Rock_Sandstone_Cobble"
    },
    {
      "x": -11,
      "y": 4,
      "z": -9,
      "name": "Rock_Sandstone_Cobble"
    },
    {
      "x": -11,
      "y": 5,
      "z": -9,
      "name": "Rock_Sandstone_Cobble"
    },
    {
      "x": -11,
      "y": 6,
      "z": -9,
      "name": "Rock_Sandstone_Cobble"
    },
    {
      "x": -11,
      "y": 7,
      "z": -9,
      "name": "Rock_Sandstone_Brick"
    },
    {
      "x": -11,
      "y": 8,
      "z": -9,
      "name": "Rock_Sandstone_Brick"
    },
    {
      "x": -11,
      "y": 9,
      "z": -9,
      "name": "Rock_Sandstone_Brick_Ornate"
    },
    {
      "x": -11,
      "y": 10,
      "z": -9,
      "name": "Rock_Sandstone_Brick"
    },
    {
      "x": -11,
      "y": 11,
      "z": -9,
      "name": "Rock_Sandstone_Brick"
    },
    {
      "x": -11,
      "y": 12,
      "z": -9,
      "name": "Rock_Sandstone_Brick"
    },
    {
      "x": -11,
      "y": 13,
      "z": -9,
      "name": "Rock_Sandstone_Brick"
    },
    {
      "x": -11,
      "y": 14,
      "z": -9,
      "name": "Rock_Sandstone_Brick_Smooth"
    },
    {
      "x": -11,
      "y": 0,
      "z": -8,
      "name": "Rock_Sandstone_Cobble"
    },
    {
      "x": -11,
      "y": 1,
      "z": -8,
      "name": "Rock_Sandstone_Cobble"
    },
    {
      "x": -11,
      "y": 2,
      "z": -8,
      "name": "Rock_Sandstone_Cobble"
    },
    {
      "x": -11,
      "y": 3,
      "z": -8,
      "name": "Rock_Sandstone_Cobble"
    },
    {
      "x": -11,
      "y": 4,
      "z": -8,
      "name": "Rock_Sandstone_Cobble"
    },
    {
      "x": -11,
      "y": 5,
      "z": -8,
      "name": "Rock_Sandstone_Brick"
    },
    {
      "x": -11,
      "y": 6,
      "z": -8,
      "name": "Rock_Sandstone_Brick"
    },
    {
      "x": -11,
      "y": 7,
      "z": -8,
      "name": "Rock_Sandstone_Brick"
    },
    {
      "x": -11,
      "y": 8,
      "z": -8,
      "name": "Rock_Sandstone_Brick"
    },
    {
      "x": -11,
      "y": 9,
      "z": -8,
      "name": "Rock_Sandstone_Brick_Ornate"
    },
    {
      "x": -11,
      "y": 10,
      "z": -8,
      "name": "Rock_Sandstone_Brick"
    },
    {
      "x": -11,
      "y": 11,
      "z": -8,
      "name": "Rock_Sandstone_Brick"
    },
    {
      "x": -11,
      "y": 12,
      "z": -8,
      "name": "Rock_Sandstone_Brick"
    },
    {
      "x": -11,
      "y": 13,
      "z": -8,
      "name": "Rock_Sandstone_Brick"
    },
    {
      "x": -11,
      "y": 14,
      "z": -8,
      "name": "Rock_Sandstone_Brick_Smooth_Half"
    },
    {
      "x": -11,
      "y": 0,
      "z": -7,
      "name": "Rock_Sandstone_Cobble"
    },
    {
      "x": -11,
      "y": 1,
      "z": -7,
      "name": "Rock_Sandstone_Cobble"
    },
    {
      "x": -11,
      "y": 2,
      "z": -7,
      "name": "Rock_Sandstone_Cobble"
    },
    {
      "x": -11,
      "y": 3,
      "z": -7,
      "name": "Rock_Sandstone_Cobble"
    },
    {
      "x": -11,
      "y": 4,
      "z": -7,
      "name": "Rock_Sandstone_Cobble"
    },
    {
      "x": -11,
      "y": 5,
      "z": -7,
      "name": "Rock_Sandstone_Brick"
    },
    {
      "x": -11,
      "y": 6,
      "z": -7,
      "name": "Rock_Sandstone_Brick"
    },
    {
      "x": -11,
      "y": 7,
      "z": -7,
      "name": "Rock_Sandstone_Brick"
    },
    {
      "x": -11,
      "y": 8,
      "z": -7,
      "name": "Rock_Sandstone_Brick"
    },
    {
      "x": -11,
      "y": 9,
      "z": -7,
      "name": "Wood_Drywood_Fence",
      "rotation": 1
    },
    {
      "x": -11,
      "y": 10,
      "z": -7,
      "name": "Wood_Drywood_Fence",
      "rotation": 1
    },
    {
      "x": -11,
      "y": 11,
      "z": -7,
      "name": "Rock_Sandstone_Brick"
    },
    {
      "x": -11,
      "y": 12,
      "z": -7,
      "name": "Rock_Sandstone_Brick"
    },
    {
      "x": -11,
      "y": 13,
      "z": -7,
      "name": "Rock_Sandstone_Brick"
    },
    {
      "x": -11,
      "y": 14,
      "z": -7,
      "name": "Rock_Sandstone_Brick_Smooth"
    },
    {
      "x": -11,
      "y": 0,
      "z": -6,
      "name": "Rock_Sandstone_Cobble"
    },
    {
      "x": -11,
      "y": 1,
      "z": -6,
      "name": "Rock_Sandstone_Cobble"
    },
    {
      "x": -11,
      "y": 2,
      "z": -6,
      "name": "Rock_Sandstone_Cobble"
    },
    {
      "x": -11,
      "y": 3,
      "z": -6,
      "name": "Rock_Sandstone_Cobble"
    },
    {
      "x": -11,
      "y": 4,
      "z": -6,
      "name": "Rock_Sandstone_Brick"
    },
    {
      "x": -11,
      "y": 5,
      "z": -6,
      "name": "Rock_Sandstone_Brick"
    },
    {
      "x": -11,
      "y": 6,
      "z": -6,
      "name": "Rock_Sandstone_Brick"
    },
    {
      "x": -11,
      "y": 7,
      "z": -6,
      "name": "Rock_Sandstone_Brick"
    },
    {
      "x": -11,
      "y": 8,
      "z": -6,
      "name": "Rock_Sandstone_Brick"
    },
    {
      "x": -11,
      "y": 9,
      "z": -6,
      "name": "Rock_Sandstone_Brick_Ornate"
    },
    {
      "x": -11,
      "y": 10,
      "z": -6,
      "name": "Rock_Sandstone_Brick"
    },
    {
      "x": -11,
      "y": 11,
      "z": -6,
      "name": "Rock_Sandstone_Brick"
    },
    {
      "x": -11,
      "y": 12,
      "z": -6,
      "name": "Rock_Sandstone_Brick"
    },
    {
      "x": -11,
      "y": 13,
      "z": -6,
      "name": "Rock_Sandstone_Brick"
    },
    {
      "x": -11,
      "y": 14,
      "z": -6,
      "name": "Rock_Sandstone_Brick_Smooth_Half"
    },
    {
      "x": -11,
      "y": 0,
      "z": -5,
      "name": "Rock_Sandstone_Cobble"
    },
    {
      "x": -11,
      "y": 1,
      "z": -5,
      "name": "Rock_Sandstone_Cobble"
    },
    {
      "x": -11,
      "y": 2,
      "z": -5,
      "name": "Rock_Sandstone_Cobble"
    },
    {
      "x": -11,
      "y": 3,
      "z": -5,
      "name": "Rock_Sandstone_Cobble"
    },
    {
      "x": -11,
      "y": 4,
      "z": -5,
      "name": "Rock_Sandstone_Brick"
    },
    {
      "x": -11,
      "y": 5,
      "z": -5,
      "name": "Rock_Sandstone_Brick"
    },
    {
      "x": -11,
      "y": 6,
      "z": -5,
      "name": "Rock_Sandstone_Brick"
    },
    {
      "x": -11,
      "y": 7,
      "z": -5,
      "name": "Rock_Sandstone_Brick"
    },
    {
      "x": -11,
      "y": 8,
      "z": -5,
      "name": "Rock_Sandstone_Brick"
    },
    {
      "x": -11,
      "y": 9,
      "z": -5,
      "name": "Rock_Sandstone_Brick_Ornate"
    },
    {
      "x": -11,
      "y": 10,
      "z": -5,
      "name": "Rock_Sandstone_Brick"
    },
    {
      "x": -11,
      "y": 11,
      "z": -5,
      "name": "Rock_Sandstone_Brick"
    },
    {
      "x": -11,
      "y": 12,
      "z": -5,
      "name": "Rock_Sandstone_Brick"
    },
    {
      "x": -11,
      "y": 13,
      "z": -5,
      "name": "Rock_Sandstone_Brick"
    },
    {
      "x": -11,
      "y": 14,
      "z": -5,
      "name": "Rock_Sandstone_Brick_Smooth"
    },
    {
      "x": -11,
      "y": 0,
      "z": -4,
      "name": "Rock_Sandstone_Cobble"
    },
    {
      "x": -11,
      "y": 1,
      "z": -4,
      "name": "Rock_Sandstone_Cobble"
    },
    {
      "x": -11,
      "y": 2,
      "z": -4,
      "name": "Rock_Sandstone_Cobble"
    },
    {
      "x": -11,
      "y": 3,
      "z": -4,
      "name": "Rock_Sandstone_Cobble"
    },
    {
      "x": -11,
      "y": 4,
      "z": -4,
      "name": "Rock_Sandstone_Brick"
    },
    {
      "x": -11,
      "y": 5,
      "z": -4,
      "name": "Rock_Sandstone_Brick"
    },
    {
      "x": -11,
      "y": 6,
      "z": -4,
      "name": "Rock_Sandstone_Brick"
    },
    {
      "x": -11,
      "y": 7,
      "z": -4,
      "name": "Rock_Sandstone_Brick"
    },
    {
      "x": -11,
      "y": 8,
      "z": -4,
      "name": "Rock_Sandstone_Brick"
    },
    {
      "x": -11,
      "y": 9,
      "z": -4,
      "name": "Wood_Drywood_Fence",
      "rotation": 1
    },
    {
      "x": -11,
      "y": 10,
      "z": -4,
      "name": "Wood_Drywood_Fence",
      "rotation": 1
    },
    {
      "x": -11,
      "y": 11,
      "z": -4,
      "name": "Rock_Sandstone_Brick"
    },
    {
      "x": -11,
      "y": 12,
      "z": -4,
      "name": "Rock_Sandstone_Brick"
    },
    {
      "x": -11,
      "y": 13,
      "z": -4,
      "name": "Rock_Sandstone_Brick"
    },
    {
      "x": -11,
      "y": 14,
      "z": -4,
      "name": "Rock_Sandstone_Brick_Smooth_Half"
    },
    {
      "x": -11,
      "y": 0,
      "z": -3,
      "name": "Rock_Sandstone_Cobble"
    },
    {
      "x": -11,
      "y": 1,
      "z": -3,
      "name": "Rock_Sandstone_Cobble"
    },
    {
      "x": -11,
      "y": 2,
      "z": -3,
      "name": "Rock_Sandstone_Cobble"
    },
    {
      "x": -11,
      "y": 3,
      "z": -3,
      "name": "Rock_Sandstone_Cobble"
    },
    {
      "x": -11,
      "y": 4,
      "z": -3,
      "name": "Rock_Sandstone_Cobble"
    },
    {
      "x": -11,
      "y": 5,
      "z": -3,
      "name": "Rock_Sandstone_Brick"
    },
    {
      "x": -11,
      "y": 6,
      "z": -3,
      "name": "Rock_Sandstone_Brick"
    },
    {
      "x": -11,
      "y": 7,
      "z": -3,
      "name": "Rock_Sandstone_Brick"
    },
    {
      "x": -11,
      "y": 8,
      "z": -3,
      "name": "Rock_Sandstone_Brick"
    },
    {
      "x": -11,
      "y": 9,
      "z": -3,
      "name": "Rock_Sandstone_Brick_Ornate"
    },
    {
      "x": -11,
      "y": 10,
      "z": -3,
      "name": "Rock_Sandstone_Brick"
    },
    {
      "x": -11,
      "y": 11,
      "z": -3,
      "name": "Rock_Sandstone_Brick"
    },
    {
      "x": -11,
      "y": 12,
      "z": -3,
      "name": "Rock_Sandstone_Brick"
    },
    {
      "x": -11,
      "y": 13,
      "z": -3,
      "name": "Rock_Sandstone_Brick"
    },
    {
      "x": -11,
      "y": 14,
      "z": -3,
      "name": "Rock_Sandstone_Brick_Smooth"
    },
    {
      "x": -11,
      "y": 0,
      "z": -2,
      "name": "Rock_Sandstone_Cobble"
    },
    {
      "x": -11,
      "y": 1,
      "z": -2,
      "name": "Rock_Sandstone_Cobble"
    },
    {
      "x": -11,
      "y": 2,
      "z": -2,
      "name": "Rock_Sandstone_Cobble"
    },
    {
      "x": -11,
      "y": 3,
      "z": -2,
      "name": "Rock_Sandstone_Cobble"
    },
    {
      "x": -11,
      "y": 4,
      "z": -2,
      "name": "Rock_Sandstone_Cobble"
    },
    {
      "x": -11,
      "y": 5,
      "z": -2,
      "name": "Rock_Sandstone_Brick"
    },
    {
      "x": -11,
      "y": 6,
      "z": -2,
      "name": "Rock_Sandstone_Brick"
    },
    {
      "x": -11,
      "y": 7,
      "z": -2,
      "name": "Rock_Sandstone_Brick"
    },
    {
      "x": -11,
      "y": 8,
      "z": -2,
      "name": "Rock_Sandstone_Brick"
    },
    {
      "x": -11,
      "y": 9,
      "z": -2,
      "name": "Rock_Sandstone_Brick_Ornate"
    },
    {
      "x": -11,
      "y": 10,
      "z": -2,
      "name": "Rock_Sandstone_Brick"
    },
    {
      "x": -11,
      "y": 11,
      "z": -2,
      "name": "Rock_Sandstone_Brick"
    },
    {
      "x": -11,
      "y": 12,
      "z": -2,
      "name": "Rock_Sandstone_Brick"
    },
    {
      "x": -11,
      "y": 13,
      "z": -2,
      "name": "Rock_Sandstone_Brick"
    },
    {
      "x": -11,
      "y": 14,
      "z": -2,
      "name": "Rock_Sandstone_Brick_Smooth"
    },
    {
      "x": -11,
      "y": 0,
      "z": -1,
      "name": "Rock_Sandstone_Brick_Smooth"
    },
    {
      "x": -11,
      "y": 1,
      "z": -1,
      "name": "Rock_Sandstone_Brick_Smooth"
    },
    {
      "x": -11,
      "y": 2,
      "z": -1,
      "name": "Rock_Sandstone_Brick_Smooth"
    },
    {
      "x": -11,
      "y": 3,
      "z": -1,
      "name": "Rock_Sandstone_Brick_Smooth"
    },
    {
      "x": -11,
      "y": 4,
      "z": -1,
      "name": "Rock_Sandstone_Brick_Smooth"
    },
    {
      "x": -11,
      "y": 5,
      "z": -1,
      "name": "Rock_Sandstone_Brick_Smooth"
    },
    {
      "x": -11,
      "y": 6,
      "z": -1,
      "name": "Rock_Sandstone_Brick_Smooth"
    },
    {
      "x": -11,
      "y": 7,
      "z": -1,
      "name": "Rock_Sandstone_Brick_Smooth"
    },
    {
      "x": -11,
      "y": 8,
      "z": -1,
      "name": "Rock_Sandstone_Brick_Smooth"
    },
    {
      "x": -11,
      "y": 9,
      "z": -1,
      "name": "Rock_Sandstone_Brick_Smooth"
    },
    {
      "x": -11,
      "y": 10,
      "z": -1,
      "name": "Rock_Sandstone_Brick_Smooth"
    },
    {
      "x": -11,
      "y": 11,
      "z": -1,
      "name": "Rock_Sandstone_Brick_Smooth"
    },
    {
      "x": -11,
      "y": 12,
      "z": -1,
      "name": "Rock_Sandstone_Brick_Smooth"
    },
    {
      "x": -11,
      "y": 13,
      "z": -1,
      "name": "Rock_Sandstone_Brick_Smooth_Half",
      "rotation": 4
    },
    {
      "x": -11,
      "y": 14,
      "z": -1,
      "name": "Rock_Sandstone_Brick_Smooth_Half",
      "rotation": 4
    },
    {
      "x": -11,
      "y": 0,
      "z": 0,
      "name": "Rock_Sandstone_Cobble"
    },
    {
      "x": -11,
      "y": 1,
      "z": 0,
      "name": "Rock_Sandstone_Cobble"
    },
    {
      "x": -11,
      "y": 2,
      "z": 0,
      "name": "Rock_Sandstone_Cobble"
    },
    {
      "x": -11,
      "y": 3,
      "z": 0,
      "name": "Rock_Sandstone_Cobble"
    },
    {
      "x": -11,
      "y": 4,
      "z": 0,
      "name": "Rock_Sandstone_Cobble"
    },
    {
      "x": -11,
      "y": 5,
      "z": 0,
      "name": "Rock_Sandstone_Cobble"
    },
    {
      "x": -11,
      "y": 6,
      "z": 0,
      "name": "Rock_Sandstone_Brick"
    },
    {
      "x": -11,
      "y": 7,
      "z": 0,
      "name": "Rock_Sandstone_Brick"
    },
    {
      "x": -11,
      "y": 8,
      "z": 0,
      "name": "Rock_Sandstone_Brick"
    },
    {
      "x": -11,
      "y": 9,
      "z": 0,
      "name": "Rock_Sandstone_Brick_Ornate"
    },
    {
      "x": -11,
      "y": 10,
      "z": 0,
      "name": "Rock_Sandstone_Brick"
    },
    {
      "x": -11,
      "y": 11,
      "z": 0,
      "name": "Rock_Sandstone_Brick_Half",
      "rotation": 4
    },
    {
      "x": -11,
      "y": 0,
      "z": 1,
      "name": "Rock_Sandstone_Cobble"
    },
    {
      "x": -11,
      "y": 1,
      "z": 1,
      "name": "Rock_Sandstone_Cobble"
    },
    {
      "x": -11,
      "y": 2,
      "z": 1,
      "name": "Rock_Sandstone_Cobble"
    },
    {
      "x": -11,
      "y": 3,
      "z": 1,
      "name": "Rock_Sandstone_Cobble"
    },
    {
      "x": -11,
      "y": 4,
      "z": 1,
      "name": "Rock_Sandstone_Cobble"
    },
    {
      "x": -11,
      "y": 0,
      "z": 2,
      "name": "Rock_Sandstone_Cobble"
    },
    {
      "x": -11,
      "y": 1,
      "z": 2,
      "name": "Rock_Sandstone_Cobble"
    },
    {
      "x": -11,
      "y": 2,
      "z": 2,
      "name": "Rock_Sandstone_Cobble"
    },
    {
      "x": -11,
      "y": 3,
      "z": 2,
      "name": "Rock_Sandstone_Cobble"
    },
    {
      "x": -11,
      "y": 4,
      "z": 2,
      "name": "Rock_Sandstone_Cobble"
    },
    {
      "x": -11,
      "y": 5,
      "z": 2,
      "name": "Rock_Sandstone_Brick"
    },
    {
      "x": -11,
      "y": 6,
      "z": 2,
      "name": "Rock_Sandstone_Brick"
    },
    {
      "x": -11,
      "y": 0,
      "z": 3,
      "name": "Rock_Sandstone_Cobble"
    },
    {
      "x": -11,
      "y": 1,
      "z": 3,
      "name": "Rock_Sandstone_Cobble"
    },
    {
      "x": -11,
      "y": 2,
      "z": 3,
      "name": "Rock_Sandstone_Cobble"
    },
    {
      "x": -11,
      "y": 3,
      "z": 3,
      "name": "Rock_Sandstone_Cobble"
    },
    {
      "x": -11,
      "y": 4,
      "z": 3,
      "name": "Rock_Sandstone_Brick"
    },
    {
      "x": -11,
      "y": 5,
      "z": 3,
      "name": "Rock_Sandstone_Brick"
    },
    {
      "x": -11,
      "y": 6,
      "z": 3,
      "name": "Rock_Sandstone_Brick_Half",
      "rotation": 4
    },
    {
      "x": -10,
      "y": 0,
      "z": -12,
      "name": "Rock_Sandstone"
    },
    {
      "x": -10,
      "y": 1,
      "z": -12,
      "name": "Rock_Sandstone"
    },
    {
      "x": -10,
      "y": 2,
      "z": -12,
      "name": "Rock_Sandstone"
    },
    {
      "x": -10,
      "y": 3,
      "z": -12,
      "name": "Rock_Sandstone"
    },
    {
      "x": -10,
      "y": 4,
      "z": -12,
      "name": "Rock_Sandstone"
    },
    {
      "x": -10,
      "y": 5,
      "z": -12,
      "name": "Rock_Sandstone"
    },
    {
      "x": -10,
      "y": 6,
      "z": -12,
      "name": "Rock_Sandstone"
    },
    {
      "x": -10,
      "y": 7,
      "z": -12,
      "name": "Rock_Sandstone"
    },
    {
      "x": -10,
      "y": 8,
      "z": -12,
      "name": "Rock_Sandstone_Cobble_Stairs",
      "rotation": 1
    },
    {
      "x": -10,
      "y": 0,
      "z": -11,
      "name": "Rock_Sandstone"
    },
    {
      "x": -10,
      "y": 1,
      "z": -11,
      "name": "Rock_Sandstone"
    },
    {
      "x": -10,
      "y": 2,
      "z": -11,
      "name": "Rock_Sandstone"
    },
    {
      "x": -10,
      "y": 3,
      "z": -11,
      "name": "Rock_Sandstone"
    },
    {
      "x": -10,
      "y": 4,
      "z": -11,
      "name": "Rock_Sandstone"
    },
    {
      "x": -10,
      "y": 5,
      "z": -11,
      "name": "Rock_Sandstone"
    },
    {
      "x": -10,
      "y": 6,
      "z": -11,
      "name": "Rock_Sandstone"
    },
    {
      "x": -10,
      "y": 7,
      "z": -11,
      "name": "Rock_Sandstone"
    },
    {
      "x": -10,
      "y": 8,
      "z": -11,
      "name": "Rock_Sandstone"
    },
    {
      "x": -10,
      "y": 9,
      "z": -11,
      "name": "Rock_Sandstone_Cobble_Stairs",
      "rotation": 3
    },
    {
      "x": -10,
      "y": 0,
      "z": -10,
      "name": "Rock_Sandstone"
    },
    {
      "x": -10,
      "y": 1,
      "z": -10,
      "name": "Rock_Sandstone"
    },
    {
      "x": -10,
      "y": 2,
      "z": -10,
      "name": "Rock_Sandstone"
    },
    {
      "x": -10,
      "y": 3,
      "z": -10,
      "name": "Rock_Sandstone"
    },
    {
      "x": -10,
      "y": 4,
      "z": -10,
      "name": "Rock_Sandstone"
    },
    {
      "x": -10,
      "y": 5,
      "z": -10,
      "name": "Rock_Sandstone"
    },
    {
      "x": -10,
      "y": 6,
      "z": -10,
      "name": "Rock_Sandstone"
    },
    {
      "x": -10,
      "y": 7,
      "z": -10,
      "name": "Rock_Sandstone"
    },
    {
      "x": -10,
      "y": 8,
      "z": -10,
      "name": "Rock_Sandstone"
    },
    {
      "x": -10,
      "y": 9,
      "z": -10,
      "name": "Rock_Sandstone"
    },
    {
      "x": -10,
      "y": 10,
      "z": -10,
      "name": "Rock_Sandstone"
    },
    {
      "x": -10,
      "y": 11,
      "z": -10,
      "name": "Rock_Sandstone"
    },
    {
      "x": -10,
      "y": 12,
      "z": -10,
      "name": "Rock_Sandstone"
    },
    {
      "x": -10,
      "y": 13,
      "z": -10,
      "name": "Rock_Sandstone_Cobble"
    },
    {
      "x": -10,
      "y": 0,
      "z": -9,
      "name": "Rock_Sandstone"
    },
    {
      "x": -10,
      "y": 1,
      "z": -9,
      "name": "Rock_Sandstone"
    },
    {
      "x": -10,
      "y": 2,
      "z": -9,
      "name": "Rock_Sandstone"
    },
    {
      "x": -10,
      "y": 3,
      "z": -9,
      "name": "Rock_Sandstone"
    },
    {
      "x": -10,
      "y": 4,
      "z": -9,
      "name": "Rock_Sandstone"
    },
    {
      "x": -10,
      "y": 5,
      "z": -9,
      "name": "Rock_Sandstone"
    },
    {
      "x": -10,
      "y": 6,
      "z": -9,
      "name": "Rock_Sandstone"
    },
    {
      "x": -10,
      "y": 7,
      "z": -9,
      "name": "Rock_Sandstone"
    },
    {
      "x": -10,
      "y": 8,
      "z": -9,
      "name": "Rock_Sandstone"
    },
    {
      "x": -10,
      "y": 9,
      "z": -9,
      "name": "Rock_Sandstone"
    },
    {
      "x": -10,
      "y": 10,
      "z": -9,
      "name": "Rock_Sandstone"
    },
    {
      "x": -10,
      "y": 11,
      "z": -9,
      "name": "Rock_Sandstone"
    },
    {
      "x": -10,
      "y": 12,
      "z": -9,
      "name": "Rock_Sandstone"
    },
    {
      "x": -10,
      "y": 13,
      "z": -9,
      "name": "Rock_Sandstone_White_Cobble"
    },
    {
      "x": -10,
      "y": 0,
      "z": -8,
      "name": "Rock_Sandstone"
    },
    {
      "x": -10,
      "y": 1,
      "z": -8,
      "name": "Rock_Sandstone"
    },
    {
      "x": -10,
      "y": 2,
      "z": -8,
      "name": "Rock_Sandstone"
    },
    {
      "x": -10,
      "y": 3,
      "z": -8,
      "name": "Rock_Sandstone"
    },
    {
      "x": -10,
      "y": 4,
      "z": -8,
      "name": "Rock_Sandstone"
    },
    {
      "x": -10,
      "y": 5,
      "z": -8,
      "name": "Rock_Sandstone"
    },
    {
      "x": -10,
      "y": 6,
      "z": -8,
      "name": "Rock_Sandstone"
    },
    {
      "x": -10,
      "y": 7,
      "z": -8,
      "name": "Rock_Sandstone_White_Cobble"
    },
    {
      "x": -10,
      "y": 12,
      "z": -8,
      "name": "Rock_Sandstone"
    },
    {
      "x": -10,
      "y": 13,
      "z": -8,
      "name": "Rock_Sandstone_White_Cobble"
    },
    {
      "x": -10,
      "y": 0,
      "z": -7,
      "name": "Rock_Sandstone"
    },
    {
      "x": -10,
      "y": 1,
      "z": -7,
      "name": "Rock_Sandstone"
    },
    {
      "x": -10,
      "y": 2,
      "z": -7,
      "name": "Rock_Sandstone"
    },
    {
      "x": -10,
      "y": 3,
      "z": -7,
      "name": "Rock_Sandstone"
    },
    {
      "x": -10,
      "y": 4,
      "z": -7,
      "name": "Rock_Sandstone"
    },
    {
      "x": -10,
      "y": 5,
      "z": -7,
      "name": "Rock_Sandstone"
    },
    {
      "x": -10,
      "y": 6,
      "z": -7,
      "name": "Rock_Sandstone"
    },
    {
      "x": -10,
      "y": 7,
      "z": -7,
      "name": "Rock_Sandstone_White_Cobble"
    },
    {
      "x": -10,
      "y": 12,
      "z": -7,
      "name": "Rock_Sandstone"
    },
    {
      "x": -10,
      "y": 13,
      "z": -7,
      "name": "Rock_Sandstone_White_Cobble"
    },
    {
      "x": -10,
      "y": 0,
      "z": -6,
      "name": "Rock_Sandstone"
    },
    {
      "x": -10,
      "y": 1,
      "z": -6,
      "name": "Rock_Sandstone"
    },
    {
      "x": -10,
      "y": 2,
      "z": -6,
      "name": "Rock_Sandstone"
    },
    {
      "x": -10,
      "y": 3,
      "z": -6,
      "name": "Rock_Sandstone"
    },
    {
      "x": -10,
      "y": 4,
      "z": -6,
      "name": "Rock_Sandstone"
    },
    {
      "x": -10,
      "y": 5,
      "z": -6,
      "name": "Rock_Sandstone"
    },
    {
      "x": -10,
      "y": 6,
      "z": -6,
      "name": "Rock_Sandstone"
    },
    {
      "x": -10,
      "y": 7,
      "z": -6,
      "name": "Rock_Sandstone_White_Cobble"
    },
    {
      "x": -10,
      "y": 12,
      "z": -6,
      "name": "Rock_Sandstone"
    },
    {
      "x": -10,
      "y": 13,
      "z": -6,
      "name": "Rock_Sandstone_White_Cobble"
    },
    {
      "x": -10,
      "y": 0,
      "z": -5,
      "name": "Rock_Sandstone"
    },
    {
      "x": -10,
      "y": 1,
      "z": -5,
      "name": "Rock_Sandstone"
    },
    {
      "x": -10,
      "y": 2,
      "z": -5,
      "name": "Rock_Sandstone"
    },
    {
      "x": -10,
      "y": 3,
      "z": -5,
      "name": "Rock_Sandstone"
    },
    {
      "x": -10,
      "y": 4,
      "z": -5,
      "name": "Rock_Sandstone"
    },
    {
      "x": -10,
      "y": 5,
      "z": -5,
      "name": "Rock_Sandstone"
    },
    {
      "x": -10,
      "y": 6,
      "z": -5,
      "name": "Rock_Sandstone"
    },
    {
      "x": -10,
      "y": 7,
      "z": -5,
      "name": "Rock_Sandstone_White_Cobble"
    },
    {
      "x": -10,
      "y": 12,
      "z": -5,
      "name": "Rock_Sandstone"
    },
    {
      "x": -10,
      "y": 13,
      "z": -5,
      "name": "Rock_Sandstone_White_Cobble"
    },
    {
      "x": -10,
      "y": 0,
      "z": -4,
      "name": "Rock_Sandstone"
    },
    {
      "x": -10,
      "y": 1,
      "z": -4,
      "name": "Rock_Sandstone"
    },
    {
      "x": -10,
      "y": 2,
      "z": -4,
      "name": "Rock_Sandstone"
    },
    {
      "x": -10,
      "y": 3,
      "z": -4,
      "name": "Rock_Sandstone"
    },
    {
      "x": -10,
      "y": 4,
      "z": -4,
      "name": "Rock_Sandstone"
    },
    {
      "x": -10,
      "y": 5,
      "z": -4,
      "name": "Rock_Sandstone"
    },
    {
      "x": -10,
      "y": 6,
      "z": -4,
      "name": "Rock_Sandstone"
    },
    {
      "x": -10,
      "y": 7,
      "z": -4,
      "name": "Rock_Sandstone_White_Cobble"
    },
    {
      "x": -10,
      "y": 12,
      "z": -4,
      "name": "Rock_Sandstone"
    },
    {
      "x": -10,
      "y": 13,
      "z": -4,
      "name": "Rock_Sandstone_White_Cobble"
    },
    {
      "x": -10,
      "y": 0,
      "z": -3,
      "name": "Rock_Sandstone"
    },
    {
      "x": -10,
      "y": 1,
      "z": -3,
      "name": "Rock_Sandstone"
    },
    {
      "x": -10,
      "y": 2,
      "z": -3,
      "name": "Rock_Sandstone"
    },
    {
      "x": -10,
      "y": 3,
      "z": -3,
      "name": "Rock_Sandstone"
    },
    {
      "x": -10,
      "y": 4,
      "z": -3,
      "name": "Rock_Sandstone"
    },
    {
      "x": -10,
      "y": 5,
      "z": -3,
      "name": "Rock_Sandstone"
    },
    {
      "x": -10,
      "y": 6,
      "z": -3,
      "name": "Rock_Sandstone"
    },
    {
      "x": -10,
      "y": 7,
      "z": -3,
      "name": "Rock_Sandstone_White_Cobble_Stairs"
    },
    {
      "x": -10,
      "y": 11,
      "z": -3,
      "name": "Rock_Sandstone_Brick_Stairs",
      "rotation": 8
    },
    {
      "x": -10,
      "y": 12,
      "z": -3,
      "name": "Rock_Sandstone"
    },
    {
      "x": -10,
      "y": 13,
      "z": -3,
      "name": "Rock_Sandstone_White_Cobble"
    },
    {
      "x": -10,
      "y": 0,
      "z": -2,
      "name": "Rock_Sandstone"
    },
    {
      "x": -10,
      "y": 1,
      "z": -2,
      "name": "Rock_Sandstone"
    },
    {
      "x": -10,
      "y": 2,
      "z": -2,
      "name": "Rock_Sandstone"
    },
    {
      "x": -10,
      "y": 3,
      "z": -2,
      "name": "Rock_Sandstone"
    },
    {
      "x": -10,
      "y": 4,
      "z": -2,
      "name": "Rock_Sandstone"
    },
    {
      "x": -10,
      "y": 5,
      "z": -2,
      "name": "Rock_Sandstone"
    },
    {
      "x": -10,
      "y": 6,
      "z": -2,
      "name": "Rock_Sandstone_White_Cobble_Stairs"
    },
    {
      "x": -10,
      "y": 10,
      "z": -2,
      "name": "Rock_Sandstone_Brick_Stairs",
      "rotation": 8
    },
    {
      "x": -10,
      "y": 11,
      "z": -2,
      "name": "Rock_Sandstone"
    },
    {
      "x": -10,
      "y": 12,
      "z": -2,
      "name": "Rock_Sandstone"
    },
    {
      "x": -10,
      "y": 13,
      "z": -2,
      "name": "Rock_Sandstone_White_Cobble_Stairs"
    },
    {
      "x": -10,
      "y": 0,
      "z": -1,
      "name": "Rock_Sandstone"
    },
    {
      "x": -10,
      "y": 1,
      "z": -1,
      "name": "Rock_Sandstone"
    },
    {
      "x": -10,
      "y": 2,
      "z": -1,
      "name": "Rock_Sandstone"
    },
    {
      "x": -10,
      "y": 3,
      "z": -1,
      "name": "Rock_Sandstone"
    },
    {
      "x": -10,
      "y": 4,
      "z": -1,
      "name": "Rock_Sandstone"
    },
    {
      "x": -10,
      "y": 5,
      "z": -1,
      "name": "Rock_Sandstone_White_Cobble_Stairs"
    },
    {
      "x": -10,
      "y": 10,
      "z": -1,
      "name": "Rock_Sandstone"
    },
    {
      "x": -10,
      "y": 11,
      "z": -1,
      "name": "Rock_Sandstone_White_Cobble"
    },
    {
      "x": -10,
      "y": 12,
      "z": -1,
      "name": "Rock_Sandstone_White_Cobble_Stairs"
    },
    {
      "x": -10,
      "y": 0,
      "z": 0,
      "name": "Rock_Sandstone"
    },
    {
      "x": -10,
      "y": 1,
      "z": 0,
      "name": "Rock_Sandstone"
    },
    {
      "x": -10,
      "y": 2,
      "z": 0,
      "name": "Rock_Sandstone"
    },
    {
      "x": -10,
      "y": 3,
      "z": 0,
      "name": "Rock_Sandstone"
    },
    {
      "x": -10,
      "y": 4,
      "z": 0,
      "name": "Rock_Sandstone_White_Cobble"
    },
    {
      "x": -10,
      "y": 10,
      "z": 0,
      "name": "Rock_Sandstone"
    },
    {
      "x": -10,
      "y": 11,
      "z": 0,
      "name": "Rock_Sandstone_White_Cobble"
    },
    {
      "x": -10,
      "y": 0,
      "z": 1,
      "name": "Rock_Sandstone"
    },
    {
      "x": -10,
      "y": 1,
      "z": 1,
      "name": "Rock_Sandstone"
    },
    {
      "x": -10,
      "y": 2,
      "z": 1,
      "name": "Rock_Sandstone"
    },
    {
      "x": -10,
      "y": 3,
      "z": 1,
      "name": "Rock_Sandstone"
    },
    {
      "x": -10,
      "y": 4,
      "z": 1,
      "name": "Rock_Sandstone_White_Cobble"
    },
    {
      "x": -10,
      "y": 10,
      "z": 1,
      "name": "Rock_Sandstone_White_Cobble_Half",
      "rotation": 8
    },
    {
      "x": -10,
      "y": 11,
      "z": 1,
      "name": "Rock_Sandstone_White_Cobble"
    },
    {
      "x": -10,
      "y": 0,
      "z": 2,
      "name": "Rock_Sandstone"
    },
    {
      "x": -10,
      "y": 1,
      "z": 2,
      "name": "Rock_Sandstone"
    },
    {
      "x": -10,
      "y": 2,
      "z": 2,
      "name": "Rock_Sandstone"
    },
    {
      "x": -10,
      "y": 3,
      "z": 2,
      "name": "Rock_Sandstone"
    },
    {
      "x": -10,
      "y": 4,
      "z": 2,
      "name": "Rock_Sandstone_Cobble"
    },
    {
      "x": -10,
      "y": 5,
      "z": 2,
      "name": "Rock_Sandstone_Cobble"
    },
    {
      "x": -10,
      "y": 6,
      "z": 2,
      "name": "Rock_Sandstone_Cobble"
    },
    {
      "x": -10,
      "y": 0,
      "z": 3,
      "name": "Rock_Sandstone_Cobble"
    },
    {
      "x": -10,
      "y": 1,
      "z": 3,
      "name": "Rock_Sandstone_Cobble"
    },
    {
      "x": -10,
      "y": 2,
      "z": 3,
      "name": "Rock_Sandstone_Cobble"
    },
    {
      "x": -10,
      "y": 3,
      "z": 3,
      "name": "Rock_Sandstone_Cobble"
    },
    {
      "x": -10,
      "y": 4,
      "z": 3,
      "name": "Rock_Sandstone_Cobble"
    },
    {
      "x": -10,
      "y": 5,
      "z": 3,
      "name": "Rock_Sandstone_Brick"
    },
    {
      "x": -10,
      "y": 6,
      "z": 3,
      "name": "Rock_Sandstone_Brick"
    },
    {
      "x": -10,
      "y": 7,
      "z": 3,
      "name": "Rock_Sandstone_Brick"
    },
    {
      "x": -9,
      "y": 0,
      "z": -12,
      "name": "Rock_Sandstone"
    },
    {
      "x": -9,
      "y": 1,
      "z": -12,
      "name": "Rock_Sandstone"
    },
    {
      "x": -9,
      "y": 2,
      "z": -12,
      "name": "Rock_Sandstone"
    },
    {
      "x": -9,
      "y": 3,
      "z": -12,
      "name": "Rock_Sandstone"
    },
    {
      "x": -9,
      "y": 4,
      "z": -12,
      "name": "Rock_Sandstone"
    },
    {
      "x": -9,
      "y": 5,
      "z": -12,
      "name": "Rock_Sandstone"
    },
    {
      "x": -9,
      "y": 6,
      "z": -12,
      "name": "Rock_Sandstone"
    },
    {
      "x": -9,
      "y": 7,
      "z": -12,
      "name": "Rock_Sandstone_Cobble_Stairs",
      "rotation": 1
    },
    {
      "x": -9,
      "y": 0,
      "z": -11,
      "name": "Rock_Sandstone"
    },
    {
      "x": -9,
      "y": 1,
      "z": -11,
      "name": "Rock_Sandstone"
    },
    {
      "x": -9,
      "y": 2,
      "z": -11,
      "name": "Rock_Sandstone"
    },
    {
      "x": -9,
      "y": 3,
      "z": -11,
      "name": "Rock_Sandstone"
    },
    {
      "x": -9,
      "y": 4,
      "z": -11,
      "name": "Rock_Sandstone"
    },
    {
      "x": -9,
      "y": 5,
      "z": -11,
      "name": "Rock_Sandstone"
    },
    {
      "x": -9,
      "y": 6,
      "z": -11,
      "name": "Rock_Sandstone"
    },
    {
      "x": -9,
      "y": 7,
      "z": -11,
      "name": "Rock_Sandstone"
    },
    {
      "x": -9,
      "y": 8,
      "z": -11,
      "name": "Rock_Sandstone"
    },
    {
      "x": -9,
      "y": 9,
      "z": -11,
      "name": "Rock_Sandstone"
    },
    {
      "x": -9,
      "y": 10,
      "z": -11,
      "name": "Rock_Sandstone_Cobble_Stairs",
      "rotation": 3
    },
    {
      "x": -9,
      "y": 0,
      "z": -10,
      "name": "Rock_Sandstone"
    },
    {
      "x": -9,
      "y": 1,
      "z": -10,
      "name": "Rock_Sandstone"
    },
    {
      "x": -9,
      "y": 2,
      "z": -10,
      "name": "Rock_Sandstone"
    },
    {
      "x": -9,
      "y": 3,
      "z": -10,
      "name": "Rock_Sandstone"
    },
    {
      "x": -9,
      "y": 4,
      "z": -10,
      "name": "Rock_Sandstone"
    },
    {
      "x": -9,
      "y": 5,
      "z": -10,
      "name": "Rock_Sandstone"
    },
    {
      "x": -9,
      "y": 6,
      "z": -10,
      "name": "Rock_Sandstone"
    },
    {
      "x": -9,
      "y": 7,
      "z": -10,
      "name": "Rock_Sandstone"
    },
    {
      "x": -9,
      "y": 8,
      "z": -10,
      "name": "Rock_Sandstone"
    },
    {
      "x": -9,
      "y": 9,
      "z": -10,
      "name": "Rock_Sandstone"
    },
    {
      "x": -9,
      "y": 10,
      "z": -10,
      "name": "Rock_Sandstone"
    },
    {
      "x": -9,
      "y": 11,
      "z": -10,
      "name": "Rock_Sandstone"
    },
    {
      "x": -9,
      "y": 12,
      "z": -10,
      "name": "Rock_Sandstone"
    },
    {
      "x": -9,
      "y": 13,
      "z": -10,
      "name": "Rock_Sandstone_Cobble_Stairs",
      "rotation": 1
    },
    {
      "x": -9,
      "y": 0,
      "z": -9,
      "name": "Rock_Sandstone"
    },
    {
      "x": -9,
      "y": 1,
      "z": -9,
      "name": "Rock_Sandstone"
    },
    {
      "x": -9,
      "y": 2,
      "z": -9,
      "name": "Rock_Sandstone"
    },
    {
      "x": -9,
      "y": 3,
      "z": -9,
      "name": "Rock_Sandstone"
    },
    {
      "x": -9,
      "y": 4,
      "z": -9,
      "name": "Rock_Sandstone"
    },
    {
      "x": -9,
      "y": 5,
      "z": -9,
      "name": "Rock_Sandstone"
    },
    {
      "x": -9,
      "y": 6,
      "z": -9,
      "name": "Rock_Sandstone"
    },
    {
      "x": -9,
      "y": 7,
      "z": -9,
      "name": "Rock_Sandstone"
    },
    {
      "x": -9,
      "y": 8,
      "z": -9,
      "name": "Rock_Sandstone"
    },
    {
      "x": -9,
      "y": 9,
      "z": -9,
      "name": "Rock_Sandstone"
    },
    {
      "x": -9,
      "y": 10,
      "z": -9,
      "name": "Rock_Sandstone"
    },
    {
      "x": -9,
      "y": 11,
      "z": -9,
      "name": "Rock_Sandstone"
    },
    {
      "x": -9,
      "y": 12,
      "z": -9,
      "name": "Rock_Sandstone"
    },
    {
      "x": -9,
      "y": 13,
      "z": -9,
      "name": "Rock_Sandstone_White_Cobble"
    },
    {
      "x": -9,
      "y": 0,
      "z": -8,
      "name": "Rock_Sandstone"
    },
    {
      "x": -9,
      "y": 1,
      "z": -8,
      "name": "Rock_Sandstone"
    },
    {
      "x": -9,
      "y": 2,
      "z": -8,
      "name": "Rock_Sandstone"
    },
    {
      "x": -9,
      "y": 3,
      "z": -8,
      "name": "Rock_Sandstone"
    },
    {
      "x": -9,
      "y": 4,
      "z": -8,
      "name": "Rock_Sandstone"
    },
    {
      "x": -9,
      "y": 5,
      "z": -8,
      "name": "Rock_Sandstone"
    },
    {
      "x": -9,
      "y": 6,
      "z": -8,
      "name": "Rock_Sandstone"
    },
    {
      "x": -9,
      "y": 7,
      "z": -8,
      "name": "Rock_Sandstone_White_Cobble"
    },
    {
      "x": -9,
      "y": 12,
      "z": -8,
      "name": "Rock_Sandstone"
    },
    {
      "x": -9,
      "y": 13,
      "z": -8,
      "name": "Rock_Sandstone_White_Cobble"
    },
    {
      "x": -9,
      "y": 0,
      "z": -7,
      "name": "Rock_Sandstone"
    },
    {
      "x": -9,
      "y": 1,
      "z": -7,
      "name": "Rock_Sandstone"
    },
    {
      "x": -9,
      "y": 2,
      "z": -7,
      "name": "Rock_Sandstone"
    },
    {
      "x": -9,
      "y": 3,
      "z": -7,
      "name": "Rock_Sandstone"
    },
    {
      "x": -9,
      "y": 4,
      "z": -7,
      "name": "Rock_Sandstone"
    },
    {
      "x": -9,
      "y": 5,
      "z": -7,
      "name": "Rock_Sandstone"
    },
    {
      "x": -9,
      "y": 6,
      "z": -7,
      "name": "Rock_Sandstone"
    },
    {
      "x": -9,
      "y": 7,
      "z": -7,
      "name": "Rock_Sandstone_White_Cobble"
    },
    {
      "x": -9,
      "y": 12,
      "z": -7,
      "name": "Rock_Sandstone"
    },
    {
      "x": -9,
      "y": 13,
      "z": -7,
      "name": "Rock_Sandstone_White_Cobble"
    },
    {
      "x": -9,
      "y": 0,
      "z": -6,
      "name": "Rock_Sandstone"
    },
    {
      "x": -9,
      "y": 1,
      "z": -6,
      "name": "Rock_Sandstone"
    },
    {
      "x": -9,
      "y": 2,
      "z": -6,
      "name": "Rock_Sandstone"
    },
    {
      "x": -9,
      "y": 3,
      "z": -6,
      "name": "Rock_Sandstone"
    },
    {
      "x": -9,
      "y": 4,
      "z": -6,
      "name": "Rock_Sandstone"
    },
    {
      "x": -9,
      "y": 5,
      "z": -6,
      "name": "Rock_Sandstone"
    },
    {
      "x": -9,
      "y": 6,
      "z": -6,
      "name": "Rock_Sandstone"
    },
    {
      "x": -9,
      "y": 7,
      "z": -6,
      "name": "Rock_Sandstone_White_Cobble"
    },
    {
      "x": -9,
      "y": 12,
      "z": -6,
      "name": "Rock_Sandstone"
    },
    {
      "x": -9,
      "y": 13,
      "z": -6,
      "name": "Rock_Sandstone_White_Cobble"
    },
    {
      "x": -9,
      "y": 0,
      "z": -5,
      "name": "Rock_Sandstone"
    },
    {
      "x": -9,
      "y": 1,
      "z": -5,
      "name": "Rock_Sandstone"
    },
    {
      "x": -9,
      "y": 2,
      "z": -5,
      "name": "Rock_Sandstone"
    },
    {
      "x": -9,
      "y": 3,
      "z": -5,
      "name": "Rock_Sandstone"
    },
    {
      "x": -9,
      "y": 4,
      "z": -5,
      "name": "Rock_Sandstone"
    },
    {
      "x": -9,
      "y": 5,
      "z": -5,
      "name": "Rock_Sandstone"
    },
    {
      "x": -9,
      "y": 6,
      "z": -5,
      "name": "Rock_Sandstone"
    },
    {
      "x": -9,
      "y": 7,
      "z": -5,
      "name": "Rock_Sandstone_White_Cobble"
    },
    {
      "x": -9,
      "y": 12,
      "z": -5,
      "name": "Rock_Sandstone"
    },
    {
      "x": -9,
      "y": 13,
      "z": -5,
      "name": "Rock_Sandstone_White_Cobble"
    },
    {
      "x": -9,
      "y": 0,
      "z": -4,
      "name": "Rock_Sandstone"
    },
    {
      "x": -9,
      "y": 1,
      "z": -4,
      "name": "Rock_Sandstone"
    },
    {
      "x": -9,
      "y": 2,
      "z": -4,
      "name": "Rock_Sandstone"
    },
    {
      "x": -9,
      "y": 3,
      "z": -4,
      "name": "Rock_Sandstone"
    },
    {
      "x": -9,
      "y": 4,
      "z": -4,
      "name": "Rock_Sandstone"
    },
    {
      "x": -9,
      "y": 5,
      "z": -4,
      "name": "Rock_Sandstone"
    },
    {
      "x": -9,
      "y": 6,
      "z": -4,
      "name": "Rock_Sandstone"
    },
    {
      "x": -9,
      "y": 7,
      "z": -4,
      "name": "Rock_Sandstone_White_Cobble"
    },
    {
      "x": -9,
      "y": 12,
      "z": -4,
      "name": "Rock_Sandstone"
    },
    {
      "x": -9,
      "y": 13,
      "z": -4,
      "name": "Rock_Sandstone_White_Cobble"
    },
    {
      "x": -9,
      "y": 0,
      "z": -3,
      "name": "Rock_Sandstone"
    },
    {
      "x": -9,
      "y": 1,
      "z": -3,
      "name": "Rock_Sandstone"
    },
    {
      "x": -9,
      "y": 2,
      "z": -3,
      "name": "Rock_Sandstone"
    },
    {
      "x": -9,
      "y": 3,
      "z": -3,
      "name": "Rock_Sandstone"
    },
    {
      "x": -9,
      "y": 4,
      "z": -3,
      "name": "Rock_Sandstone"
    },
    {
      "x": -9,
      "y": 5,
      "z": -3,
      "name": "Rock_Sandstone"
    },
    {
      "x": -9,
      "y": 6,
      "z": -3,
      "name": "Rock_Sandstone"
    },
    {
      "x": -9,
      "y": 7,
      "z": -3,
      "name": "Rock_Sandstone_White_Cobble_Stairs"
    },
    {
      "x": -9,
      "y": 11,
      "z": -3,
      "name": "Rock_Sandstone_Brick_Stairs",
      "rotation": 8
    },
    {
      "x": -9,
      "y": 12,
      "z": -3,
      "name": "Rock_Sandstone"
    },
    {
      "x": -9,
      "y": 13,
      "z": -3,
      "name": "Rock_Sandstone_White_Cobble"
    },
    {
      "x": -9,
      "y": 0,
      "z": -2,
      "name": "Rock_Sandstone"
    },
    {
      "x": -9,
      "y": 1,
      "z": -2,
      "name": "Rock_Sandstone"
    },
    {
      "x": -9,
      "y": 2,
      "z": -2,
      "name": "Rock_Sandstone"
    },
    {
      "x": -9,
      "y": 3,
      "z": -2,
      "name": "Rock_Sandstone"
    },
    {
      "x": -9,
      "y": 4,
      "z": -2,
      "name": "Rock_Sandstone"
    },
    {
      "x": -9,
      "y": 5,
      "z": -2,
      "name": "Rock_Sandstone"
    },
    {
      "x": -9,
      "y": 6,
      "z": -2,
      "name": "Rock_Sandstone_White_Cobble_Stairs"
    },
    {
      "x": -9,
      "y": 10,
      "z": -2,
      "name": "Rock_Sandstone_Brick_Stairs",
      "rotation": 8
    },
    {
      "x": -9,
      "y": 11,
      "z": -2,
      "name": "Rock_Sandstone"
    },
    {
      "x": -9,
      "y": 12,
      "z": -2,
      "name": "Rock_Sandstone"
    },
    {
      "x": -9,
      "y": 13,
      "z": -2,
      "name": "Rock_Sandstone_White_Cobble_Stairs"
    },
    {
      "x": -9,
      "y": 0,
      "z": -1,
      "name": "Rock_Sandstone"
    },
    {
      "x": -9,
      "y": 1,
      "z": -1,
      "name": "Rock_Sandstone"
    },
    {
      "x": -9,
      "y": 2,
      "z": -1,
      "name": "Rock_Sandstone"
    },
    {
      "x": -9,
      "y": 3,
      "z": -1,
      "name": "Rock_Sandstone"
    },
    {
      "x": -9,
      "y": 4,
      "z": -1,
      "name": "Rock_Sandstone"
    },
    {
      "x": -9,
      "y": 5,
      "z": -1,
      "name": "Rock_Sandstone_White_Cobble_Stairs"
    },
    {
      "x": -9,
      "y": 10,
      "z": -1,
      "name": "Rock_Sandstone"
    },
    {
      "x": -9,
      "y": 11,
      "z": -1,
      "name": "Rock_Sandstone_White_Cobble"
    },
    {
      "x": -9,
      "y": 12,
      "z": -1,
      "name": "Rock_Sandstone_White_Cobble_Stairs"
    },
    {
      "x": -9,
      "y": 0,
      "z": 0,
      "name": "Rock_Sandstone"
    },
    {
      "x": -9,
      "y": 1,
      "z": 0,
      "name": "Rock_Sandstone"
    },
    {
      "x": -9,
      "y": 2,
      "z": 0,
      "name": "Rock_Sandstone"
    },
    {
      "x": -9,
      "y": 3,
      "z": 0,
      "name": "Rock_Sandstone"
    },
    {
      "x": -9,
      "y": 4,
      "z": 0,
      "name": "Rock_Sandstone_White_Cobble"
    },
    {
      "x": -9,
      "y": 10,
      "z": 0,
      "name": "Rock_Sandstone"
    },
    {
      "x": -9,
      "y": 11,
      "z": 0,
      "name": "Rock_Sandstone_White_Cobble"
    },
    {
      "x": -9,
      "y": 0,
      "z": 1,
      "name": "Rock_Sandstone"
    },
    {
      "x": -9,
      "y": 1,
      "z": 1,
      "name": "Rock_Sandstone"
    },
    {
      "x": -9,
      "y": 2,
      "z": 1,
      "name": "Rock_Sandstone"
    },
    {
      "x": -9,
      "y": 3,
      "z": 1,
      "name": "Rock_Sandstone"
    },
    {
      "x": -9,
      "y": 4,
      "z": 1,
      "name": "Rock_Sandstone_White_Cobble"
    },
    {
      "x": -9,
      "y": 10,
      "z": 1,
      "name": "Rock_Sandstone"
    },
    {
      "x": -9,
      "y": 11,
      "z": 1,
      "name": "Rock_Sandstone_White_Cobble"
    },
    {
      "x": -9,
      "y": 0,
      "z": 2,
      "name": "Rock_Sandstone"
    },
    {
      "x": -9,
      "y": 1,
      "z": 2,
      "name": "Rock_Sandstone"
    },
    {
      "x": -9,
      "y": 2,
      "z": 2,
      "name": "Rock_Sandstone"
    },
    {
      "x": -9,
      "y": 3,
      "z": 2,
      "name": "Rock_Sandstone"
    },
    {
      "x": -9,
      "y": 4,
      "z": 2,
      "name": "Rock_Sandstone_Cobble"
    },
    {
      "x": -9,
      "y": 5,
      "z": 2,
      "name": "Rock_Sandstone_Cobble"
    },
    {
      "x": -9,
      "y": 6,
      "z": 2,
      "name": "Rock_Sandstone_Brick_Half"
    },
    {
      "x": -9,
      "y": 0,
      "z": 3,
      "name": "Rock_Sandstone_Cobble"
    },
    {
      "x": -9,
      "y": 1,
      "z": 3,
      "name": "Rock_Sandstone_Cobble"
    },
    {
      "x": -9,
      "y": 2,
      "z": 3,
      "name": "Rock_Sandstone_Cobble"
    },
    {
      "x": -9,
      "y": 3,
      "z": 3,
      "name": "Rock_Sandstone_Cobble"
    },
    {
      "x": -9,
      "y": 4,
      "z": 3,
      "name": "Rock_Sandstone_Cobble"
    },
    {
      "x": -9,
      "y": 5,
      "z": 3,
      "name": "Rock_Sandstone_Cobble"
    },
    {
      "x": -9,
      "y": 6,
      "z": 3,
      "name": "Rock_Sandstone_Brick"
    },
    {
      "x": -9,
      "y": 7,
      "z": 3,
      "name": "Rock_Sandstone_Brick"
    },
    {
      "x": -9,
      "y": 8,
      "z": 3,
      "name": "Rock_Sandstone_Brick"
    },
    {
      "x": -9,
      "y": 9,
      "z": 3,
      "name": "Rock_Sandstone_Brick_Ornate"
    },
    {
      "x": -9,
      "y": 10,
      "z": 3,
      "name": "Rock_Sandstone_Brick_Half"
    },
    {
      "x": -8,
      "y": 0,
      "z": -12,
      "name": "Rock_Sandstone"
    },
    {
      "x": -8,
      "y": 1,
      "z": -12,
      "name": "Rock_Sandstone"
    },
    {
      "x": -8,
      "y": 2,
      "z": -12,
      "name": "Rock_Sandstone"
    },
    {
      "x": -8,
      "y": 3,
      "z": -12,
      "name": "Rock_Sandstone"
    },
    {
      "x": -8,
      "y": 4,
      "z": -12,
      "name": "Rock_Sandstone"
    },
    {
      "x": -8,
      "y": 5,
      "z": -12,
      "name": "Rock_Sandstone"
    },
    {
      "x": -8,
      "y": 6,
      "z": -12,
      "name": "Rock_Sandstone_Cobble_Stairs",
      "rotation": 1
    },
    {
      "x": -8,
      "y": 0,
      "z": -11,
      "name": "Rock_Sandstone"
    },
    {
      "x": -8,
      "y": 1,
      "z": -11,
      "name": "Rock_Sandstone"
    },
    {
      "x": -8,
      "y": 2,
      "z": -11,
      "name": "Rock_Sandstone"
    },
    {
      "x": -8,
      "y": 3,
      "z": -11,
      "name": "Rock_Sandstone"
    },
    {
      "x": -8,
      "y": 4,
      "z": -11,
      "name": "Rock_Sandstone"
    },
    {
      "x": -8,
      "y": 5,
      "z": -11,
      "name": "Rock_Sandstone"
    },
    {
      "x": -8,
      "y": 6,
      "z": -11,
      "name": "Rock_Sandstone"
    },
    {
      "x": -8,
      "y": 7,
      "z": -11,
      "name": "Rock_Sandstone"
    },
    {
      "x": -8,
      "y": 8,
      "z": -11,
      "name": "Rock_Sandstone"
    },
    {
      "x": -8,
      "y": 9,
      "z": -11,
      "name": "Rock_Sandstone"
    },
    {
      "x": -8,
      "y": 10,
      "z": -11,
      "name": "Rock_Sandstone"
    },
    {
      "x": -8,
      "y": 11,
      "z": -11,
      "name": "Rock_Sandstone_Cobble_Stairs",
      "rotation": 3
    },
    {
      "x": -8,
      "y": 0,
      "z": -10,
      "name": "Rock_Sandstone"
    },
    {
      "x": -8,
      "y": 1,
      "z": -10,
      "name": "Rock_Sandstone"
    },
    {
      "x": -8,
      "y": 2,
      "z": -10,
      "name": "Rock_Sandstone"
    },
    {
      "x": -8,
      "y": 3,
      "z": -10,
      "name": "Rock_Sandstone"
    },
    {
      "x": -8,
      "y": 4,
      "z": -10,
      "name": "Rock_Sandstone"
    },
    {
      "x": -8,
      "y": 5,
      "z": -10,
      "name": "Rock_Sandstone"
    },
    {
      "x": -8,
      "y": 6,
      "z": -10,
      "name": "Rock_Sandstone"
    },
    {
      "x": -8,
      "y": 7,
      "z": -10,
      "name": "Rock_Sandstone"
    },
    {
      "x": -8,
      "y": 8,
      "z": -10,
      "name": "Rock_Sandstone"
    },
    {
      "x": -8,
      "y": 9,
      "z": -10,
      "name": "Rock_Sandstone"
    },
    {
      "x": -8,
      "y": 10,
      "z": -10,
      "name": "Rock_Sandstone"
    },
    {
      "x": -8,
      "y": 11,
      "z": -10,
      "name": "Rock_Sandstone"
    },
    {
      "x": -8,
      "y": 12,
      "z": -10,
      "name": "Rock_Sandstone_Cobble_Stairs",
      "rotation": 1
    },
    {
      "x": -8,
      "y": 0,
      "z": -9,
      "name": "Rock_Sandstone"
    },
    {
      "x": -8,
      "y": 1,
      "z": -9,
      "name": "Rock_Sandstone"
    },
    {
      "x": -8,
      "y": 2,
      "z": -9,
      "name": "Rock_Sandstone"
    },
    {
      "x": -8,
      "y": 3,
      "z": -9,
      "name": "Rock_Sandstone"
    },
    {
      "x": -8,
      "y": 4,
      "z": -9,
      "name": "Rock_Sandstone"
    },
    {
      "x": -8,
      "y": 5,
      "z": -9,
      "name": "Rock_Sandstone"
    },
    {
      "x": -8,
      "y": 6,
      "z": -9,
      "name": "Rock_Sandstone"
    },
    {
      "x": -8,
      "y": 7,
      "z": -9,
      "name": "Rock_Sandstone"
    },
    {
      "x": -8,
      "y": 8,
      "z": -9,
      "name": "Rock_Sandstone"
    },
    {
      "x": -8,
      "y": 9,
      "z": -9,
      "name": "Rock_Sandstone"
    },
    {
      "x": -8,
      "y": 10,
      "z": -9,
      "name": "Rock_Sandstone"
    },
    {
      "x": -8,
      "y": 11,
      "z": -9,
      "name": "Rock_Sandstone"
    },
    {
      "x": -8,
      "y": 12,
      "z": -9,
      "name": "Rock_Sandstone"
    },
    {
      "x": -8,
      "y": 13,
      "z": -9,
      "name": "Rock_Sandstone_White_Cobble_Half"
    },
    {
      "x": -8,
      "y": 0,
      "z": -8,
      "name": "Rock_Sandstone"
    },
    {
      "x": -8,
      "y": 1,
      "z": -8,
      "name": "Rock_Sandstone"
    },
    {
      "x": -8,
      "y": 2,
      "z": -8,
      "name": "Rock_Sandstone"
    },
    {
      "x": -8,
      "y": 3,
      "z": -8,
      "name": "Rock_Sandstone"
    },
    {
      "x": -8,
      "y": 4,
      "z": -8,
      "name": "Rock_Sandstone"
    },
    {
      "x": -8,
      "y": 5,
      "z": -8,
      "name": "Rock_Sandstone"
    },
    {
      "x": -8,
      "y": 6,
      "z": -8,
      "name": "Rock_Sandstone"
    },
    {
      "x": -8,
      "y": 7,
      "z": -8,
      "name": "Rock_Sandstone_White_Cobble"
    },
    {
      "x": -8,
      "y": 12,
      "z": -8,
      "name": "Rock_Sandstone"
    },
    {
      "x": -8,
      "y": 13,
      "z": -8,
      "name": "Rock_Sandstone_White_Cobble_Half"
    },
    {
      "x": -8,
      "y": 0,
      "z": -7,
      "name": "Rock_Sandstone"
    },
    {
      "x": -8,
      "y": 1,
      "z": -7,
      "name": "Rock_Sandstone"
    },
    {
      "x": -8,
      "y": 2,
      "z": -7,
      "name": "Rock_Sandstone"
    },
    {
      "x": -8,
      "y": 3,
      "z": -7,
      "name": "Rock_Sandstone"
    },
    {
      "x": -8,
      "y": 4,
      "z": -7,
      "name": "Rock_Sandstone"
    },
    {
      "x": -8,
      "y": 5,
      "z": -7,
      "name": "Rock_Sandstone"
    },
    {
      "x": -8,
      "y": 6,
      "z": -7,
      "name": "Rock_Sandstone"
    },
    {
      "x": -8,
      "y": 7,
      "z": -7,
      "name": "Rock_Sandstone_White_Cobble"
    },
    {
      "x": -8,
      "y": 12,
      "z": -7,
      "name": "Rock_Sandstone"
    },
    {
      "x": -8,
      "y": 13,
      "z": -7,
      "name": "Rock_Sandstone_White_Cobble"
    },
    {
      "x": -8,
      "y": 0,
      "z": -6,
      "name": "Rock_Sandstone"
    },
    {
      "x": -8,
      "y": 1,
      "z": -6,
      "name": "Rock_Sandstone"
    },
    {
      "x": -8,
      "y": 2,
      "z": -6,
      "name": "Rock_Sandstone"
    },
    {
      "x": -8,
      "y": 3,
      "z": -6,
      "name": "Rock_Sandstone"
    },
    {
      "x": -8,
      "y": 4,
      "z": -6,
      "name": "Rock_Sandstone"
    },
    {
      "x": -8,
      "y": 5,
      "z": -6,
      "name": "Rock_Sandstone"
    },
    {
      "x": -8,
      "y": 6,
      "z": -6,
      "name": "Rock_Sandstone"
    },
    {
      "x": -8,
      "y": 7,
      "z": -6,
      "name": "Rock_Sandstone_White_Cobble"
    },
    {
      "x": -8,
      "y": 12,
      "z": -6,
      "name": "Rock_Sandstone"
    },
    {
      "x": -8,
      "y": 13,
      "z": -6,
      "name": "Rock_Sandstone_White_Cobble"
    },
    {
      "x": -8,
      "y": 0,
      "z": -5,
      "name": "Rock_Sandstone"
    },
    {
      "x": -8,
      "y": 1,
      "z": -5,
      "name": "Rock_Sandstone"
    },
    {
      "x": -8,
      "y": 2,
      "z": -5,
      "name": "Rock_Sandstone"
    },
    {
      "x": -8,
      "y": 3,
      "z": -5,
      "name": "Rock_Sandstone"
    },
    {
      "x": -8,
      "y": 4,
      "z": -5,
      "name": "Rock_Sandstone"
    },
    {
      "x": -8,
      "y": 5,
      "z": -5,
      "name": "Rock_Sandstone"
    },
    {
      "x": -8,
      "y": 6,
      "z": -5,
      "name": "Rock_Sandstone"
    },
    {
      "x": -8,
      "y": 7,
      "z": -5,
      "name": "Rock_Sandstone_White_Cobble"
    },
    {
      "x": -8,
      "y": 12,
      "z": -5,
      "name": "Rock_Sandstone"
    },
    {
      "x": -8,
      "y": 13,
      "z": -5,
      "name": "Rock_Sandstone_White_Cobble"
    },
    {
      "x": -8,
      "y": 0,
      "z": -4,
      "name": "Rock_Sandstone"
    },
    {
      "x": -8,
      "y": 1,
      "z": -4,
      "name": "Rock_Sandstone"
    },
    {
      "x": -8,
      "y": 2,
      "z": -4,
      "name": "Rock_Sandstone"
    },
    {
      "x": -8,
      "y": 3,
      "z": -4,
      "name": "Rock_Sandstone"
    },
    {
      "x": -8,
      "y": 4,
      "z": -4,
      "name": "Rock_Sandstone"
    },
    {
      "x": -8,
      "y": 5,
      "z": -4,
      "name": "Rock_Sandstone"
    },
    {
      "x": -8,
      "y": 6,
      "z": -4,
      "name": "Rock_Sandstone"
    },
    {
      "x": -8,
      "y": 7,
      "z": -4,
      "name": "Rock_Sandstone_White_Cobble"
    },
    {
      "x": -8,
      "y": 12,
      "z": -4,
      "name": "Rock_Sandstone"
    },
    {
      "x": -8,
      "y": 13,
      "z": -4,
      "name": "Rock_Sandstone_White_Cobble"
    },
    {
      "x": -8,
      "y": 0,
      "z": -3,
      "name": "Rock_Sandstone"
    },
    {
      "x": -8,
      "y": 1,
      "z": -3,
      "name": "Rock_Sandstone"
    },
    {
      "x": -8,
      "y": 2,
      "z": -3,
      "name": "Rock_Sandstone"
    },
    {
      "x": -8,
      "y": 3,
      "z": -3,
      "name": "Rock_Sandstone"
    },
    {
      "x": -8,
      "y": 4,
      "z": -3,
      "name": "Rock_Sandstone"
    },
    {
      "x": -8,
      "y": 5,
      "z": -3,
      "name": "Rock_Sandstone"
    },
    {
      "x": -8,
      "y": 6,
      "z": -3,
      "name": "Rock_Sandstone"
    },
    {
      "x": -8,
      "y": 7,
      "z": -3,
      "name": "Rock_Sandstone_White_Cobble_Stairs"
    },
    {
      "x": -8,
      "y": 11,
      "z": -3,
      "name": "Rock_Sandstone_Brick_Stairs",
      "rotation": 8
    },
    {
      "x": -8,
      "y": 12,
      "z": -3,
      "name": "Rock_Sandstone"
    },
    {
      "x": -8,
      "y": 13,
      "z": -3,
      "name": "Rock_Sandstone_White_Cobble"
    },
    {
      "x": -8,
      "y": 0,
      "z": -2,
      "name": "Rock_Sandstone"
    },
    {
      "x": -8,
      "y": 1,
      "z": -2,
      "name": "Rock_Sandstone"
    },
    {
      "x": -8,
      "y": 2,
      "z": -2,
      "name": "Rock_Sandstone"
    },
    {
      "x": -8,
      "y": 3,
      "z": -2,
      "name": "Rock_Sandstone"
    },
    {
      "x": -8,
      "y": 4,
      "z": -2,
      "name": "Rock_Sandstone"
    },
    {
      "x": -8,
      "y": 5,
      "z": -2,
      "name": "Rock_Sandstone"
    },
    {
      "x": -8,
      "y": 6,
      "z": -2,
      "name": "Rock_Sandstone_White_Cobble_Stairs"
    },
    {
      "x": -8,
      "y": 10,
      "z": -2,
      "name": "Rock_Sandstone_Brick_Stairs",
      "rotation": 8
    },
    {
      "x": -8,
      "y": 11,
      "z": -2,
      "name": "Rock_Sandstone"
    },
    {
      "x": -8,
      "y": 12,
      "z": -2,
      "name": "Rock_Sandstone"
    },
    {
      "x": -8,
      "y": 13,
      "z": -2,
      "name": "Rock_Sandstone_White_Cobble_Stairs"
    },
    {
      "x": -8,
      "y": 0,
      "z": -1,
      "name": "Rock_Sandstone"
    },
    {
      "x": -8,
      "y": 1,
      "z": -1,
      "name": "Rock_Sandstone"
    },
    {
      "x": -8,
      "y": 2,
      "z": -1,
      "name": "Rock_Sandstone"
    },
    {
      "x": -8,
      "y": 3,
      "z": -1,
      "name": "Rock_Sandstone"
    },
    {
      "x": -8,
      "y": 4,
      "z": -1,
      "name": "Rock_Sandstone"
    },
    {
      "x": -8,
      "y": 5,
      "z": -1,
      "name": "Rock_Sandstone_White_Cobble_Stairs"
    },
    {
      "x": -8,
      "y": 10,
      "z": -1,
      "name": "Rock_Sandstone"
    },
    {
      "x": -8,
      "y": 11,
      "z": -1,
      "name": "Rock_Sandstone_White_Cobble"
    },
    {
      "x": -8,
      "y": 12,
      "z": -1,
      "name": "Rock_Sandstone_White_Cobble_Stairs"
    },
    {
      "x": -8,
      "y": 0,
      "z": 0,
      "name": "Rock_Sandstone"
    },
    {
      "x": -8,
      "y": 1,
      "z": 0,
      "name": "Rock_Sandstone"
    },
    {
      "x": -8,
      "y": 2,
      "z": 0,
      "name": "Rock_Sandstone"
    },
    {
      "x": -8,
      "y": 3,
      "z": 0,
      "name": "Rock_Sandstone"
    },
    {
      "x": -8,
      "y": 4,
      "z": 0,
      "name": "Rock_Sandstone_White_Cobble"
    },
    {
      "x": -8,
      "y": 10,
      "z": 0,
      "name": "Rock_Sandstone"
    },
    {
      "x": -8,
      "y": 11,
      "z": 0,
      "name": "Rock_Sandstone_White_Cobble"
    },
    {
      "x": -8,
      "y": 0,
      "z": 1,
      "name": "Rock_Sandstone"
    },
    {
      "x": -8,
      "y": 1,
      "z": 1,
      "name": "Rock_Sandstone"
    },
    {
      "x": -8,
      "y": 2,
      "z": 1,
      "name": "Rock_Sandstone"
    },
    {
      "x": -8,
      "y": 3,
      "z": 1,
      "name": "Rock_Sandstone"
    },
    {
      "x": -8,
      "y": 4,
      "z": 1,
      "name": "Rock_Sandstone_White_Cobble"
    },
    {
      "x": -8,
      "y": 10,
      "z": 1,
      "name": "Rock_Sandstone"
    },
    {
      "x": -8,
      "y": 11,
      "z": 1,
      "name": "Rock_Sandstone_White_Cobble"
    },
    {
      "x": -8,
      "y": 0,
      "z": 2,
      "name": "Rock_Sandstone"
    },
    {
      "x": -8,
      "y": 1,
      "z": 2,
      "name": "Rock_Sandstone"
    },
    {
      "x": -8,
      "y": 2,
      "z": 2,
      "name": "Rock_Sandstone"
    },
    {
      "x": -8,
      "y": 3,
      "z": 2,
      "name": "Rock_Sandstone"
    },
    {
      "x": -8,
      "y": 4,
      "z": 2,
      "name": "Rock_Sandstone_White_Cobble"
    },
    {
      "x": -8,
      "y": 10,
      "z": 2,
      "name": "Rock_Sandstone"
    },
    {
      "x": -8,
      "y": 11,
      "z": 2,
      "name": "Rock_Sandstone_White_Cobble"
    },
    {
      "x": -8,
      "y": 0,
      "z": 3,
      "name": "Rock_Sandstone_Cobble"
    },
    {
      "x": -8,
      "y": 1,
      "z": 3,
      "name": "Rock_Sandstone_Cobble"
    },
    {
      "x": -8,
      "y": 2,
      "z": 3,
      "name": "Rock_Sandstone_Cobble"
    },
    {
      "x": -8,
      "y": 3,
      "z": 3,
      "name": "Rock_Sandstone_Cobble"
    },
    {
      "x": -8,
      "y": 4,
      "z": 3,
      "name": "Rock_Sandstone_Cobble"
    },
    {
      "x": -8,
      "y": 5,
      "z": 3,
      "name": "Rock_Sandstone_Cobble"
    },
    {
      "x": -8,
      "y": 6,
      "z": 3,
      "name": "Rock_Sandstone_Brick"
    },
    {
      "x": -8,
      "y": 7,
      "z": 3,
      "name": "Rock_Sandstone_Brick"
    },
    {
      "x": -8,
      "y": 8,
      "z": 3,
      "name": "Rock_Sandstone_Brick"
    },
    {
      "x": -8,
      "y": 9,
      "z": 3,
      "name": "Rock_Sandstone_Brick_Ornate"
    },
    {
      "x": -8,
      "y": 10,
      "z": 3,
      "name": "Rock_Sandstone_Brick"
    },
    {
      "x": -8,
      "y": 11,
      "z": 3,
      "name": "Rock_Sandstone_Brick"
    },
    {
      "x": -8,
      "y": 12,
      "z": 3,
      "name": "Rock_Sandstone_Brick_Half"
    },
    {
      "x": -8,
      "y": 11,
      "z": 6,
      "name": "Rock_Sandstone_Brick_Smooth_Half",
      "rotation": 7
    },
    {
      "x": -8,
      "y": 11,
      "z": 7,
      "name": "Rock_Sandstone_Brick_Smooth_Half",
      "rotation": 7
    },
    {
      "x": -8,
      "y": 12,
      "z": 7,
      "name": "Rock_Sandstone_Brick_Smooth_Half",
      "rotation": 7
    },
    {
      "x": -8,
      "y": 11,
      "z": 8,
      "name": "Rock_Sandstone_Brick_Smooth_Half",
      "rotation": 7
    },
    {
      "x": -8,
      "y": 11,
      "z": 9,
      "name": "Rock_Sandstone_Brick_Smooth_Half",
      "rotation": 7
    },
    {
      "x": -8,
      "y": 12,
      "z": 9,
      "name": "Rock_Sandstone_Brick_Smooth_Half",
      "rotation": 7
    },
    {
      "x": -8,
      "y": 11,
      "z": 10,
      "name": "Rock_Sandstone_Brick_Smooth_Half",
      "rotation": 7
    },
    {
      "x": -8,
      "y": 11,
      "z": 11,
      "name": "Rock_Sandstone_Brick_Smooth_Half",
      "rotation": 7
    },
    {
      "x": -8,
      "y": 12,
      "z": 11,
      "name": "Rock_Sandstone_Brick_Smooth_Half",
      "rotation": 7
    },
    {
      "x": -7,
      "y": 0,
      "z": -12,
      "name": "Rock_Sandstone_Cobble"
    },
    {
      "x": -7,
      "y": 1,
      "z": -12,
      "name": "Rock_Sandstone_Cobble"
    },
    {
      "x": -7,
      "y": 2,
      "z": -12,
      "name": "Rock_Sandstone_Cobble"
    },
    {
      "x": -7,
      "y": 3,
      "z": -12,
      "name": "Rock_Sandstone_Cobble"
    },
    {
      "x": -7,
      "y": 4,
      "z": -12,
      "name": "Rock_Sandstone_Cobble"
    },
    {
      "x": -7,
      "y": 5,
      "z": -12,
      "name": "Rock_Sandstone_Cobble_Stairs",
      "rotation": 1
    },
    {
      "x": -7,
      "y": 0,
      "z": -11,
      "name": "Rock_Sandstone_Cobble"
    },
    {
      "x": -7,
      "y": 1,
      "z": -11,
      "name": "Rock_Sandstone_Cobble"
    },
    {
      "x": -7,
      "y": 2,
      "z": -11,
      "name": "Rock_Sandstone_Cobble"
    },
    {
      "x": -7,
      "y": 3,
      "z": -11,
      "name": "Rock_Sandstone_Cobble"
    },
    {
      "x": -7,
      "y": 4,
      "z": -11,
      "name": "Rock_Sandstone_Cobble"
    },
    {
      "x": -7,
      "y": 5,
      "z": -11,
      "name": "Rock_Sandstone_Brick"
    },
    {
      "x": -7,
      "y": 6,
      "z": -11,
      "name": "Rock_Sandstone_Brick"
    },
    {
      "x": -7,
      "y": 7,
      "z": -11,
      "name": "Rock_Sandstone_Brick"
    },
    {
      "x": -7,
      "y": 8,
      "z": -11,
      "name": "Rock_Sandstone_Brick"
    },
    {
      "x": -7,
      "y": 9,
      "z": -11,
      "name": "Rock_Sandstone_Brick"
    },
    {
      "x": -7,
      "y": 10,
      "z": -11,
      "name": "Rock_Sandstone_Brick"
    },
    {
      "x": -7,
      "y": 11,
      "z": -11,
      "name": "Rock_Sandstone_Cobble"
    },
    {
      "x": -7,
      "y": 0,
      "z": -10,
      "name": "Rock_Sandstone_Cobble"
    },
    {
      "x": -7,
      "y": 1,
      "z": -10,
      "name": "Rock_Sandstone_Cobble"
    },
    {
      "x": -7,
      "y": 2,
      "z": -10,
      "name": "Rock_Sandstone_Cobble"
    },
    {
      "x": -7,
      "y": 3,
      "z": -10,
      "name": "Rock_Sandstone_Cobble"
    },
    {
      "x": -7,
      "y": 4,
      "z": -10,
      "name": "Rock_Sandstone_Cobble"
    },
    {
      "x": -7,
      "y": 5,
      "z": -10,
      "name": "Rock_Sandstone_Brick"
    },
    {
      "x": -7,
      "y": 6,
      "z": -10,
      "name": "Rock_Sandstone_Brick"
    },
    {
      "x": -7,
      "y": 7,
      "z": -10,
      "name": "Rock_Sandstone_Brick"
    },
    {
      "x": -7,
      "y": 8,
      "z": -10,
      "name": "Rock_Sandstone_Brick"
    },
    {
      "x": -7,
      "y": 9,
      "z": -10,
      "name": "Rock_Sandstone_Brick"
    },
    {
      "x": -7,
      "y": 10,
      "z": -10,
      "name": "Rock_Sandstone_Brick"
    },
    {
      "x": -7,
      "y": 11,
      "z": -10,
      "name": "Rock_Sandstone_Cobble"
    },
    {
      "x": -7,
      "y": 0,
      "z": -9,
      "name": "Rock_Sandstone_Cobble"
    },
    {
      "x": -7,
      "y": 1,
      "z": -9,
      "name": "Rock_Sandstone_Cobble"
    },
    {
      "x": -7,
      "y": 2,
      "z": -9,
      "name": "Rock_Sandstone_Cobble"
    },
    {
      "x": -7,
      "y": 3,
      "z": -9,
      "name": "Rock_Sandstone_Cobble"
    },
    {
      "x": -7,
      "y": 4,
      "z": -9,
      "name": "Rock_Sandstone_Cobble"
    },
    {
      "x": -7,
      "y": 5,
      "z": -9,
      "name": "Rock_Sandstone_Brick"
    },
    {
      "x": -7,
      "y": 6,
      "z": -9,
      "name": "Rock_Sandstone_Brick"
    },
    {
      "x": -7,
      "y": 7,
      "z": -9,
      "name": "Rock_Sandstone_Brick"
    },
    {
      "x": -7,
      "y": 8,
      "z": -9,
      "name": "Rock_Sandstone_Brick"
    },
    {
      "x": -7,
      "y": 9,
      "z": -9,
      "name": "Rock_Sandstone_Brick_Ornate"
    },
    {
      "x": -7,
      "y": 10,
      "z": -9,
      "name": "Rock_Sandstone_Brick"
    },
    {
      "x": -7,
      "y": 11,
      "z": -9,
      "name": "Rock_Sandstone_Brick"
    },
    {
      "x": -7,
      "y": 12,
      "z": -9,
      "name": "Rock_Sandstone_Brick"
    },
    {
      "x": -7,
      "y": 0,
      "z": -8,
      "name": "Rock_Sandstone_Brick"
    },
    {
      "x": -7,
      "y": 1,
      "z": -8,
      "name": "Rock_Sandstone_Cobble"
    },
    {
      "x": -7,
      "y": 2,
      "z": -8,
      "name": "Rock_Sandstone_Cobble"
    },
    {
      "x": -7,
      "y": 3,
      "z": -8,
      "name": "Rock_Sandstone_Cobble"
    },
    {
      "x": -7,
      "y": 4,
      "z": -8,
      "name": "Rock_Sandstone_Brick"
    },
    {
      "x": -7,
      "y": 5,
      "z": -8,
      "name": "Rock_Sandstone_Brick"
    },
    {
      "x": -7,
      "y": 6,
      "z": -8,
      "name": "Rock_Sandstone_Brick"
    },
    {
      "x": -7,
      "y": 7,
      "z": -8,
      "name": "Rock_Sandstone_Brick"
    },
    {
      "x": -7,
      "y": 8,
      "z": -8,
      "name": "Rock_Sandstone_Brick"
    },
    {
      "x": -7,
      "y": 9,
      "z": -8,
      "name": "Rock_Sandstone_Brick_Ornate"
    },
    {
      "x": -7,
      "y": 10,
      "z": -8,
      "name": "Rock_Sandstone_Brick"
    },
    {
      "x": -7,
      "y": 11,
      "z": -8,
      "name": "Rock_Sandstone_Brick"
    },
    {
      "x": -7,
      "y": 12,
      "z": -8,
      "name": "Rock_Sandstone_Brick"
    },
    {
      "x": -7,
      "y": 13,
      "z": -8,
      "name": "Rock_Sandstone_Brick_Half"
    },
    {
      "x": -7,
      "y": 0,
      "z": -7,
      "name": "Rock_Sandstone_Brick"
    },
    {
      "x": -7,
      "y": 1,
      "z": -7,
      "name": "Rock_Sandstone_Brick"
    },
    {
      "x": -7,
      "y": 2,
      "z": -7,
      "name": "Rock_Sandstone_Cobble"
    },
    {
      "x": -7,
      "y": 3,
      "z": -7,
      "name": "Rock_Sandstone_Brick"
    },
    {
      "x": -7,
      "y": 4,
      "z": -7,
      "name": "Rock_Sandstone_Brick"
    },
    {
      "x": -7,
      "y": 5,
      "z": -7,
      "name": "Rock_Sandstone_Brick"
    },
    {
      "x": -7,
      "y": 6,
      "z": -7,
      "name": "Rock_Sandstone_Brick"
    },
    {
      "x": -7,
      "y": 7,
      "z": -7,
      "name": "Rock_Sandstone_White_Cobble"
    },
    {
      "x": -7,
      "y": 0,
      "z": -6,
      "name": "Rock_Sandstone_Brick"
    },
    {
      "x": -7,
      "y": 1,
      "z": -6,
      "name": "Rock_Sandstone_Brick"
    },
    {
      "x": -7,
      "y": 2,
      "z": -6,
      "name": "Rock_Sandstone_Brick"
    },
    {
      "x": -7,
      "y": 3,
      "z": -6,
      "name": "Rock_Sandstone_Brick"
    },
    {
      "x": -7,
      "y": 4,
      "z": -6,
      "name": "Rock_Sandstone_Brick"
    },
    {
      "x": -7,
      "y": 5,
      "z": -6,
      "name": "Rock_Sandstone_Brick"
    },
    {
      "x": -7,
      "y": 6,
      "z": -6,
      "name": "Rock_Sandstone_Brick"
    },
    {
      "x": -7,
      "y": 7,
      "z": -6,
      "name": "Rock_Sandstone_White_Cobble"
    },
    {
      "x": -7,
      "y": 10,
      "z": -6,
      "name": "Rock_Sandstone_Brick_Stairs",
      "rotation": 8
    },
    {
      "x": -7,
      "y": 11,
      "z": -6,
      "name": "Rock_Sandstone_Brick"
    },
    {
      "x": -7,
      "y": 12,
      "z": -6,
      "name": "Rock_Sandstone_Brick"
    },
    {
      "x": -7,
      "y": 13,
      "z": -6,
      "name": "Rock_Sandstone_Brick"
    },
    {
      "x": -7,
      "y": 14,
      "z": -6,
      "name": "Rock_Sandstone_Brick_Smooth_Half"
    },
    {
      "x": -7,
      "y": 0,
      "z": -5,
      "name": "Rock_Sandstone_Brick"
    },
    {
      "x": -7,
      "y": 1,
      "z": -5,
      "name": "Rock_Sandstone_Brick"
    },
    {
      "x": -7,
      "y": 2,
      "z": -5,
      "name": "Rock_Sandstone_Brick"
    },
    {
      "x": -7,
      "y": 3,
      "z": -5,
      "name": "Rock_Sandstone_Brick"
    },
    {
      "x": -7,
      "y": 4,
      "z": -5,
      "name": "Rock_Sandstone_Brick"
    },
    {
      "x": -7,
      "y": 5,
      "z": -5,
      "name": "Rock_Sandstone_Brick"
    },
    {
      "x": -7,
      "y": 6,
      "z": -5,
      "name": "Rock_Sandstone_Brick"
    },
    {
      "x": -7,
      "y": 7,
      "z": -5,
      "name": "Rock_Sandstone_Brick"
    },
    {
      "x": -7,
      "y": 8,
      "z": -5,
      "name": "Rock_Sandstone_Brick"
    },
    {
      "x": -7,
      "y": 9,
      "z": -5,
      "name": "Rock_Sandstone_Brick_Ornate"
    },
    {
      "x": -7,
      "y": 10,
      "z": -5,
      "name": "Rock_Sandstone_Brick"
    },
    {
      "x": -7,
      "y": 11,
      "z": -5,
      "name": "Rock_Sandstone_Brick"
    },
    {
      "x": -7,
      "y": 12,
      "z": -5,
      "name": "Rock_Sandstone_Brick"
    },
    {
      "x": -7,
      "y": 13,
      "z": -5,
      "name": "Rock_Sandstone_Brick"
    },
    {
      "x": -7,
      "y": 14,
      "z": -5,
      "name": "Rock_Sandstone_Brick_Smooth"
    },
    {
      "x": -7,
      "y": 0,
      "z": -4,
      "name": "Rock_Sandstone_Brick"
    },
    {
      "x": -7,
      "y": 1,
      "z": -4,
      "name": "Rock_Sandstone_Brick"
    },
    {
      "x": -7,
      "y": 2,
      "z": -4,
      "name": "Rock_Sandstone_Brick"
    },
    {
      "x": -7,
      "y": 3,
      "z": -4,
      "name": "Rock_Sandstone_Brick"
    },
    {
      "x": -7,
      "y": 4,
      "z": -4,
      "name": "Rock_Sandstone_Brick"
    },
    {
      "x": -7,
      "y": 5,
      "z": -4,
      "name": "Rock_Sandstone_Brick"
    },
    {
      "x": -7,
      "y": 6,
      "z": -4,
      "name": "Rock_Sandstone_Brick"
    },
    {
      "x": -7,
      "y": 7,
      "z": -4,
      "name": "Rock_Sandstone_Brick"
    },
    {
      "x": -7,
      "y": 8,
      "z": -4,
      "name": "Rock_Sandstone_Brick"
    },
    {
      "x": -7,
      "y": 9,
      "z": -4,
      "name": "Rock_Sandstone_Brick_Ornate"
    },
    {
      "x": -7,
      "y": 10,
      "z": -4,
      "name": "Rock_Sandstone_Brick"
    },
    {
      "x": -7,
      "y": 11,
      "z": -4,
      "name": "Rock_Sandstone_Brick"
    },
    {
      "x": -7,
      "y": 12,
      "z": -4,
      "name": "Rock_Sandstone_Brick"
    },
    {
      "x": -7,
      "y": 13,
      "z": -4,
      "name": "Rock_Sandstone_Brick"
    },
    {
      "x": -7,
      "y": 14,
      "z": -4,
      "name": "Rock_Sandstone_Brick_Smooth_Half"
    },
    {
      "x": -7,
      "y": 0,
      "z": -3,
      "name": "Rock_Sandstone_Brick"
    },
    {
      "x": -7,
      "y": 1,
      "z": -3,
      "name": "Rock_Sandstone_Brick"
    },
    {
      "x": -7,
      "y": 2,
      "z": -3,
      "name": "Rock_Sandstone_Brick"
    },
    {
      "x": -7,
      "y": 3,
      "z": -3,
      "name": "Rock_Sandstone_Brick"
    },
    {
      "x": -7,
      "y": 4,
      "z": -3,
      "name": "Rock_Sandstone_Brick"
    },
    {
      "x": -7,
      "y": 5,
      "z": -3,
      "name": "Rock_Sandstone_Brick"
    },
    {
      "x": -7,
      "y": 6,
      "z": -3,
      "name": "Rock_Sandstone_Brick"
    },
    {
      "x": -7,
      "y": 7,
      "z": -3,
      "name": "Rock_Sandstone_Brick"
    },
    {
      "x": -7,
      "y": 8,
      "z": -3,
      "name": "Rock_Sandstone_Brick"
    },
    {
      "x": -7,
      "y": 9,
      "z": -3,
      "name": "Rock_Sandstone_Brick_Ornate"
    },
    {
      "x": -7,
      "y": 10,
      "z": -3,
      "name": "Rock_Sandstone_Brick"
    },
    {
      "x": -7,
      "y": 11,
      "z": -3,
      "name": "Rock_Sandstone_Brick"
    },
    {
      "x": -7,
      "y": 12,
      "z": -3,
      "name": "Rock_Sandstone_Brick"
    },
    {
      "x": -7,
      "y": 13,
      "z": -3,
      "name": "Rock_Sandstone_Brick"
    },
    {
      "x": -7,
      "y": 14,
      "z": -3,
      "name": "Rock_Sandstone_Brick_Smooth"
    },
    {
      "x": -7,
      "y": 0,
      "z": -2,
      "name": "Rock_Sandstone_Brick"
    },
    {
      "x": -7,
      "y": 1,
      "z": -2,
      "name": "Rock_Sandstone_Brick"
    },
    {
      "x": -7,
      "y": 2,
      "z": -2,
      "name": "Rock_Sandstone_Brick"
    },
    {
      "x": -7,
      "y": 3,
      "z": -2,
      "name": "Rock_Sandstone_Brick"
    },
    {
      "x": -7,
      "y": 4,
      "z": -2,
      "name": "Rock_Sandstone_Brick"
    },
    {
      "x": -7,
      "y": 5,
      "z": -2,
      "name": "Rock_Sandstone_Cobble"
    },
    {
      "x": -7,
      "y": 6,
      "z": -2,
      "name": "Rock_Sandstone_Cobble"
    },
    {
      "x": -7,
      "y": 7,
      "z": -2,
      "name": "Rock_Sandstone_Brick"
    },
    {
      "x": -7,
      "y": 8,
      "z": -2,
      "name": "Rock_Sandstone_Brick"
    },
    {
      "x": -7,
      "y": 9,
      "z": -2,
      "name": "Rock_Sandstone_Brick_Ornate"
    },
    {
      "x": -7,
      "y": 10,
      "z": -2,
      "name": "Rock_Sandstone_Brick"
    },
    {
      "x": -7,
      "y": 11,
      "z": -2,
      "name": "Rock_Sandstone_Brick"
    },
    {
      "x": -7,
      "y": 12,
      "z": -2,
      "name": "Rock_Sandstone_Brick"
    },
    {
      "x": -7,
      "y": 13,
      "z": -2,
      "name": "Rock_Sandstone_Brick"
    },
    {
      "x": -7,
      "y": 14,
      "z": -2,
      "name": "Rock_Sandstone_Brick_Smooth"
    },
    {
      "x": -7,
      "y": 0,
      "z": -1,
      "name": "Rock_Sandstone_Brick"
    },
    {
      "x": -7,
      "y": 1,
      "z": -1,
      "name": "Rock_Sandstone_Brick"
    },
    {
      "x": -7,
      "y": 2,
      "z": -1,
      "name": "Rock_Sandstone_Brick"
    },
    {
      "x": -7,
      "y": 3,
      "z": -1,
      "name": "Rock_Sandstone_Brick"
    },
    {
      "x": -7,
      "y": 4,
      "z": -1,
      "name": "Rock_Sandstone_Brick"
    },
    {
      "x": -7,
      "y": 5,
      "z": -1,
      "name": "Rock_Sandstone_Cobble"
    },
    {
      "x": -7,
      "y": 6,
      "z": -1,
      "name": "Rock_Sandstone_Cobble"
    },
    {
      "x": -7,
      "y": 7,
      "z": -1,
      "name": "Rock_Sandstone_Brick"
    },
    {
      "x": -7,
      "y": 8,
      "z": -1,
      "name": "Rock_Sandstone_Brick"
    },
    {
      "x": -7,
      "y": 9,
      "z": -1,
      "name": "Rock_Sandstone_Brick_Ornate"
    },
    {
      "x": -7,
      "y": 10,
      "z": -1,
      "name": "Rock_Sandstone_Brick"
    },
    {
      "x": -7,
      "y": 11,
      "z": -1,
      "name": "Rock_Sandstone_Brick"
    },
    {
      "x": -7,
      "y": 12,
      "z": -1,
      "name": "Rock_Sandstone_Brick_Smooth"
    },
    {
      "x": -7,
      "y": 13,
      "z": -1,
      "name": "Rock_Sandstone_Brick_Smooth_Half",
      "rotation": 4
    },
    {
      "x": -7,
      "y": 14,
      "z": -1,
      "name": "Rock_Sandstone_Brick_Smooth_Half",
      "rotation": 4
    },
    {
      "x": -7,
      "y": 0,
      "z": 0,
      "name": "Rock_Sandstone"
    },
    {
      "x": -7,
      "y": 1,
      "z": 0,
      "name": "Rock_Sandstone"
    },
    {
      "x": -7,
      "y": 2,
      "z": 0,
      "name": "Rock_Sandstone"
    },
    {
      "x": -7,
      "y": 3,
      "z": 0,
      "name": "Rock_Sandstone"
    },
    {
      "x": -7,
      "y": 4,
      "z": 0,
      "name": "Rock_Sandstone_White_Cobble"
    },
    {
      "x": -7,
      "y": 10,
      "z": 0,
      "name": "Rock_Sandstone"
    },
    {
      "x": -7,
      "y": 11,
      "z": 0,
      "name": "Rock_Sandstone_White_Cobble"
    },
    {
      "x": -7,
      "y": 0,
      "z": 1,
      "name": "Rock_Sandstone"
    },
    {
      "x": -7,
      "y": 1,
      "z": 1,
      "name": "Rock_Sandstone"
    },
    {
      "x": -7,
      "y": 2,
      "z": 1,
      "name": "Rock_Sandstone"
    },
    {
      "x": -7,
      "y": 3,
      "z": 1,
      "name": "Rock_Sandstone"
    },
    {
      "x": -7,
      "y": 4,
      "z": 1,
      "name": "Rock_Sandstone_White_Cobble"
    },
    {
      "x": -7,
      "y": 10,
      "z": 1,
      "name": "Rock_Sandstone"
    },
    {
      "x": -7,
      "y": 11,
      "z": 1,
      "name": "Rock_Sandstone_White_Cobble"
    },
    {
      "x": -7,
      "y": 0,
      "z": 2,
      "name": "Rock_Sandstone"
    },
    {
      "x": -7,
      "y": 1,
      "z": 2,
      "name": "Rock_Sandstone"
    },
    {
      "x": -7,
      "y": 2,
      "z": 2,
      "name": "Rock_Sandstone"
    },
    {
      "x": -7,
      "y": 3,
      "z": 2,
      "name": "Rock_Sandstone"
    },
    {
      "x": -7,
      "y": 4,
      "z": 2,
      "name": "Rock_Sandstone_White_Cobble"
    },
    {
      "x": -7,
      "y": 10,
      "z": 2,
      "name": "Rock_Sandstone"
    },
    {
      "x": -7,
      "y": 11,
      "z": 2,
      "name": "Rock_Sandstone_White_Cobble"
    },
    {
      "x": -7,
      "y": 0,
      "z": 3,
      "name": "Rock_Sandstone_Cobble"
    },
    {
      "x": -7,
      "y": 1,
      "z": 3,
      "name": "Rock_Sandstone_Cobble"
    },
    {
      "x": -7,
      "y": 2,
      "z": 3,
      "name": "Rock_Sandstone_Cobble"
    },
    {
      "x": -7,
      "y": 3,
      "z": 3,
      "name": "Rock_Sandstone_Cobble"
    },
    {
      "x": -7,
      "y": 4,
      "z": 3,
      "name": "Rock_Sandstone_Cobble"
    },
    {
      "x": -7,
      "y": 5,
      "z": 3,
      "name": "Rock_Sandstone_Cobble"
    },
    {
      "x": -7,
      "y": 6,
      "z": 3,
      "name": "Rock_Sandstone_Cobble"
    },
    {
      "x": -7,
      "y": 7,
      "z": 3,
      "name": "Rock_Sandstone_Brick"
    },
    {
      "x": -7,
      "y": 8,
      "z": 3,
      "name": "Rock_Sandstone_Brick"
    },
    {
      "x": -7,
      "y": 9,
      "z": 3,
      "name": "Rock_Sandstone_Brick_Ornate"
    },
    {
      "x": -7,
      "y": 10,
      "z": 3,
      "name": "Rock_Sandstone_Brick"
    },
    {
      "x": -7,
      "y": 11,
      "z": 3,
      "name": "Rock_Sandstone_Brick"
    },
    {
      "x": -7,
      "y": 0,
      "z": 4,
      "name": "Rock_Sandstone_Cobble"
    },
    {
      "x": -7,
      "y": 1,
      "z": 4,
      "name": "Rock_Sandstone_Cobble"
    },
    {
      "x": -7,
      "y": 2,
      "z": 4,
      "name": "Rock_Sandstone_Cobble"
    },
    {
      "x": -7,
      "y": 3,
      "z": 4,
      "name": "Rock_Sandstone_Cobble"
    },
    {
      "x": -7,
      "y": 4,
      "z": 4,
      "name": "Rock_Sandstone_Cobble"
    },
    {
      "x": -7,
      "y": 5,
      "z": 4,
      "name": "Rock_Sandstone_Cobble"
    },
    {
      "x": -7,
      "y": 6,
      "z": 4,
      "name": "Rock_Sandstone_Cobble"
    },
    {
      "x": -7,
      "y": 7,
      "z": 4,
      "name": "Rock_Sandstone_Brick"
    },
    {
      "x": -7,
      "y": 8,
      "z": 4,
      "name": "Rock_Sandstone_Brick"
    },
    {
      "x": -7,
      "y": 9,
      "z": 4,
      "name": "Rock_Sandstone_Brick_Ornate"
    },
    {
      "x": -7,
      "y": 0,
      "z": 5,
      "name": "Rock_Sandstone_Cobble"
    },
    {
      "x": -7,
      "y": 1,
      "z": 5,
      "name": "Rock_Sandstone_Cobble"
    },
    {
      "x": -7,
      "y": 2,
      "z": 5,
      "name": "Rock_Sandstone_Cobble"
    },
    {
      "x": -7,
      "y": 3,
      "z": 5,
      "name": "Rock_Sandstone_Cobble"
    },
    {
      "x": -7,
      "y": 4,
      "z": 5,
      "name": "Rock_Sandstone_Cobble"
    },
    {
      "x": -7,
      "y": 5,
      "z": 5,
      "name": "Rock_Sandstone_Cobble"
    },
    {
      "x": -7,
      "y": 6,
      "z": 5,
      "name": "Rock_Sandstone_Brick"
    },
    {
      "x": -7,
      "y": 7,
      "z": 5,
      "name": "Rock_Sandstone_Brick"
    },
    {
      "x": -7,
      "y": 8,
      "z": 5,
      "name": "Rock_Sandstone_Brick"
    },
    {
      "x": -7,
      "y": 9,
      "z": 5,
      "name": "Rock_Sandstone_Brick_Ornate"
    },
    {
      "x": -7,
      "y": 10,
      "z": 5,
      "name": "Rock_Sandstone_Brick"
    },
    {
      "x": -7,
      "y": 11,
      "z": 5,
      "name": "Rock_Sandstone_Brick_Half"
    },
    {
      "x": -7,
      "y": 0,
      "z": 6,
      "name": "Rock_Sandstone_Cobble"
    },
    {
      "x": -7,
      "y": 1,
      "z": 6,
      "name": "Rock_Sandstone_Cobble"
    },
    {
      "x": -7,
      "y": 2,
      "z": 6,
      "name": "Rock_Sandstone_Cobble"
    },
    {
      "x": -7,
      "y": 3,
      "z": 6,
      "name": "Rock_Sandstone_Cobble"
    },
    {
      "x": -7,
      "y": 4,
      "z": 6,
      "name": "Rock_Sandstone_Cobble"
    },
    {
      "x": -7,
      "y": 5,
      "z": 6,
      "name": "Rock_Sandstone_Cobble"
    },
    {
      "x": -7,
      "y": 6,
      "z": 6,
      "name": "Rock_Sandstone_Cobble"
    },
    {
      "x": -7,
      "y": 7,
      "z": 6,
      "name": "Rock_Sandstone_Brick"
    },
    {
      "x": -7,
      "y": 8,
      "z": 6,
      "name": "Rock_Sandstone_Brick"
    },
    {
      "x": -7,
      "y": 9,
      "z": 6,
      "name": "Rock_Sandstone_Brick_Ornate"
    },
    {
      "x": -7,
      "y": 10,
      "z": 6,
      "name": "Rock_Sandstone_Brick"
    },
    {
      "x": -7,
      "y": 11,
      "z": 6,
      "name": "Rock_Sandstone_Brick"
    },
    {
      "x": -7,
      "y": 12,
      "z": 6,
      "name": "Rock_Sandstone_Brick_Smooth_Half"
    },
    {
      "x": -7,
      "y": 0,
      "z": 7,
      "name": "Rock_Sandstone_Cobble"
    },
    {
      "x": -7,
      "y": 1,
      "z": 7,
      "name": "Rock_Sandstone_Cobble"
    },
    {
      "x": -7,
      "y": 2,
      "z": 7,
      "name": "Rock_Sandstone_Cobble"
    },
    {
      "x": -7,
      "y": 3,
      "z": 7,
      "name": "Rock_Sandstone_Cobble"
    },
    {
      "x": -7,
      "y": 4,
      "z": 7,
      "name": "Rock_Sandstone_Cobble"
    },
    {
      "x": -7,
      "y": 5,
      "z": 7,
      "name": "Rock_Sandstone_Cobble"
    },
    {
      "x": -7,
      "y": 6,
      "z": 7,
      "name": "Rock_Sandstone_Cobble"
    },
    {
      "x": -7,
      "y": 7,
      "z": 7,
      "name": "Rock_Sandstone_Cobble"
    },
    {
      "x": -7,
      "y": 8,
      "z": 7,
      "name": "Rock_Sandstone_Brick"
    },
    {
      "x": -7,
      "y": 9,
      "z": 7,
      "name": "Rock_Sandstone_Brick_Ornate"
    },
    {
      "x": -7,
      "y": 10,
      "z": 7,
      "name": "Rock_Sandstone_Brick"
    },
    {
      "x": -7,
      "y": 11,
      "z": 7,
      "name": "Rock_Sandstone_Brick"
    },
    {
      "x": -7,
      "y": 12,
      "z": 7,
      "name": "Rock_Sandstone_Brick_Smooth"
    },
    {
      "x": -7,
      "y": 0,
      "z": 8,
      "name": "Rock_Sandstone_Cobble"
    },
    {
      "x": -7,
      "y": 1,
      "z": 8,
      "name": "Rock_Sandstone_Cobble"
    },
    {
      "x": -7,
      "y": 2,
      "z": 8,
      "name": "Rock_Sandstone_Cobble"
    },
    {
      "x": -7,
      "y": 3,
      "z": 8,
      "name": "Rock_Sandstone_Cobble"
    },
    {
      "x": -7,
      "y": 4,
      "z": 8,
      "name": "Rock_Sandstone_Cobble"
    },
    {
      "x": -7,
      "y": 5,
      "z": 8,
      "name": "Rock_Sandstone_Cobble"
    },
    {
      "x": -7,
      "y": 6,
      "z": 8,
      "name": "Rock_Sandstone_Cobble"
    },
    {
      "x": -7,
      "y": 7,
      "z": 8,
      "name": "Rock_Sandstone_Cobble"
    },
    {
      "x": -7,
      "y": 8,
      "z": 8,
      "name": "Rock_Sandstone_Brick"
    },
    {
      "x": -7,
      "y": 9,
      "z": 8,
      "name": "Rock_Sandstone_Brick_Ornate"
    },
    {
      "x": -7,
      "y": 10,
      "z": 8,
      "name": "Rock_Sandstone_Brick"
    },
    {
      "x": -7,
      "y": 11,
      "z": 8,
      "name": "Rock_Sandstone_Brick"
    },
    {
      "x": -7,
      "y": 12,
      "z": 8,
      "name": "Rock_Sandstone_Brick_Smooth_Half"
    },
    {
      "x": -7,
      "y": 0,
      "z": 9,
      "name": "Rock_Sandstone_Cobble"
    },
    {
      "x": -7,
      "y": 1,
      "z": 9,
      "name": "Rock_Sandstone_Cobble"
    },
    {
      "x": -7,
      "y": 2,
      "z": 9,
      "name": "Rock_Sandstone_Cobble"
    },
    {
      "x": -7,
      "y": 3,
      "z": 9,
      "name": "Rock_Sandstone_Cobble"
    },
    {
      "x": -7,
      "y": 4,
      "z": 9,
      "name": "Rock_Sandstone_Cobble"
    },
    {
      "x": -7,
      "y": 5,
      "z": 9,
      "name": "Rock_Sandstone_Cobble"
    },
    {
      "x": -7,
      "y": 6,
      "z": 9,
      "name": "Rock_Sandstone_Cobble"
    },
    {
      "x": -7,
      "y": 7,
      "z": 9,
      "name": "Rock_Sandstone_Brick"
    },
    {
      "x": -7,
      "y": 8,
      "z": 9,
      "name": "Rock_Sandstone_Brick"
    },
    {
      "x": -7,
      "y": 9,
      "z": 9,
      "name": "Rock_Sandstone_Brick_Ornate"
    },
    {
      "x": -7,
      "y": 10,
      "z": 9,
      "name": "Rock_Sandstone_Brick"
    },
    {
      "x": -7,
      "y": 11,
      "z": 9,
      "name": "Rock_Sandstone_Brick"
    },
    {
      "x": -7,
      "y": 12,
      "z": 9,
      "name": "Rock_Sandstone_Brick_Smooth"
    },
    {
      "x": -7,
      "y": 0,
      "z": 10,
      "name": "Rock_Sandstone_Cobble"
    },
    {
      "x": -7,
      "y": 1,
      "z": 10,
      "name": "Rock_Sandstone_Cobble"
    },
    {
      "x": -7,
      "y": 2,
      "z": 10,
      "name": "Rock_Sandstone_Cobble"
    },
    {
      "x": -7,
      "y": 3,
      "z": 10,
      "name": "Rock_Sandstone_Cobble"
    },
    {
      "x": -7,
      "y": 4,
      "z": 10,
      "name": "Rock_Sandstone_Cobble"
    },
    {
      "x": -7,
      "y": 5,
      "z": 10,
      "name": "Rock_Sandstone_Cobble"
    },
    {
      "x": -7,
      "y": 6,
      "z": 10,
      "name": "Rock_Sandstone_Brick"
    },
    {
      "x": -7,
      "y": 7,
      "z": 10,
      "name": "Rock_Sandstone_Brick"
    },
    {
      "x": -7,
      "y": 8,
      "z": 10,
      "name": "Rock_Sandstone_Brick"
    },
    {
      "x": -7,
      "y": 9,
      "z": 10,
      "name": "Rock_Sandstone_Brick_Ornate"
    },
    {
      "x": -7,
      "y": 10,
      "z": 10,
      "name": "Rock_Sandstone_Brick"
    },
    {
      "x": -7,
      "y": 11,
      "z": 10,
      "name": "Rock_Sandstone_Brick"
    },
    {
      "x": -7,
      "y": 12,
      "z": 10,
      "name": "Rock_Sandstone_Brick_Smooth_Half"
    },
    {
      "x": -7,
      "y": 0,
      "z": 11,
      "name": "Rock_Sandstone_Cobble"
    },
    {
      "x": -7,
      "y": 1,
      "z": 11,
      "name": "Rock_Sandstone_Cobble"
    },
    {
      "x": -7,
      "y": 2,
      "z": 11,
      "name": "Rock_Sandstone_Cobble"
    },
    {
      "x": -7,
      "y": 3,
      "z": 11,
      "name": "Rock_Sandstone_Cobble"
    },
    {
      "x": -7,
      "y": 4,
      "z": 11,
      "name": "Rock_Sandstone_Cobble"
    },
    {
      "x": -7,
      "y": 5,
      "z": 11,
      "name": "Rock_Sandstone_Cobble"
    },
    {
      "x": -7,
      "y": 6,
      "z": 11,
      "name": "Rock_Sandstone_Cobble"
    },
    {
      "x": -7,
      "y": 7,
      "z": 11,
      "name": "Rock_Sandstone_Brick"
    },
    {
      "x": -7,
      "y": 8,
      "z": 11,
      "name": "Rock_Sandstone_Brick"
    },
    {
      "x": -7,
      "y": 9,
      "z": 11,
      "name": "Rock_Sandstone_Brick_Ornate"
    },
    {
      "x": -7,
      "y": 10,
      "z": 11,
      "name": "Rock_Sandstone_Brick"
    },
    {
      "x": -7,
      "y": 11,
      "z": 11,
      "name": "Rock_Sandstone_Brick"
    },
    {
      "x": -7,
      "y": 12,
      "z": 11,
      "name": "Rock_Sandstone_Brick_Smooth"
    },
    {
      "x": -7,
      "y": 11,
      "z": 12,
      "name": "Rock_Sandstone_Brick_Smooth_Half",
      "rotation": 4
    },
    {
      "x": -7,
      "y": 12,
      "z": 12,
      "name": "Rock_Sandstone_Brick_Smooth_Half",
      "rotation": 4
    },
    {
      "x": -6,
      "y": 0,
      "z": -9,
      "name": "Rock_Sandstone_Cobble"
    },
    {
      "x": -6,
      "y": 1,
      "z": -9,
      "name": "Rock_Sandstone_Cobble"
    },
    {
      "x": -6,
      "y": 2,
      "z": -9,
      "name": "Rock_Sandstone_Cobble"
    },
    {
      "x": -6,
      "y": 3,
      "z": -9,
      "name": "Rock_Sandstone_Cobble"
    },
    {
      "x": -6,
      "y": 4,
      "z": -9,
      "name": "Rock_Sandstone_Cobble"
    },
    {
      "x": -6,
      "y": 5,
      "z": -9,
      "name": "Rock_Sandstone_Brick"
    },
    {
      "x": -6,
      "y": 6,
      "z": -9,
      "name": "Rock_Sandstone_Brick"
    },
    {
      "x": -6,
      "y": 7,
      "z": -9,
      "name": "Rock_Sandstone_Brick"
    },
    {
      "x": -6,
      "y": 8,
      "z": -9,
      "name": "Rock_Sandstone_Cobble_Wall"
    },
    {
      "x": -6,
      "y": 0,
      "z": -8,
      "name": "Rock_Sandstone"
    },
    {
      "x": -6,
      "y": 1,
      "z": -8,
      "name": "Rock_Sandstone"
    },
    {
      "x": -6,
      "y": 2,
      "z": -8,
      "name": "Rock_Sandstone"
    },
    {
      "x": -6,
      "y": 3,
      "z": -8,
      "name": "Rock_Sandstone"
    },
    {
      "x": -6,
      "y": 4,
      "z": -8,
      "name": "Rock_Sandstone"
    },
    {
      "x": -6,
      "y": 5,
      "z": -8,
      "name": "Rock_Sandstone"
    },
    {
      "x": -6,
      "y": 6,
      "z": -8,
      "name": "Rock_Sandstone"
    },
    {
      "x": -6,
      "y": 7,
      "z": -8,
      "name": "Rock_Sandstone_White_Cobble"
    },
    {
      "x": -6,
      "y": 0,
      "z": -7,
      "name": "Rock_Sandstone"
    },
    {
      "x": -6,
      "y": 1,
      "z": -7,
      "name": "Rock_Sandstone"
    },
    {
      "x": -6,
      "y": 2,
      "z": -7,
      "name": "Rock_Sandstone"
    },
    {
      "x": -6,
      "y": 3,
      "z": -7,
      "name": "Rock_Sandstone"
    },
    {
      "x": -6,
      "y": 4,
      "z": -7,
      "name": "Rock_Sandstone"
    },
    {
      "x": -6,
      "y": 5,
      "z": -7,
      "name": "Rock_Sandstone"
    },
    {
      "x": -6,
      "y": 6,
      "z": -7,
      "name": "Rock_Sandstone"
    },
    {
      "x": -6,
      "y": 7,
      "z": -7,
      "name": "Rock_Sandstone_White_Cobble"
    },
    {
      "x": -6,
      "y": 0,
      "z": -6,
      "name": "Rock_Sandstone"
    },
    {
      "x": -6,
      "y": 1,
      "z": -6,
      "name": "Rock_Sandstone"
    },
    {
      "x": -6,
      "y": 2,
      "z": -6,
      "name": "Rock_Sandstone"
    },
    {
      "x": -6,
      "y": 3,
      "z": -6,
      "name": "Rock_Sandstone"
    },
    {
      "x": -6,
      "y": 4,
      "z": -6,
      "name": "Rock_Sandstone"
    },
    {
      "x": -6,
      "y": 5,
      "z": -6,
      "name": "Rock_Sandstone"
    },
    {
      "x": -6,
      "y": 6,
      "z": -6,
      "name": "Rock_Sandstone"
    },
    {
      "x": -6,
      "y": 7,
      "z": -6,
      "name": "Rock_Sandstone_White_Cobble"
    },
    {
      "x": -6,
      "y": 13,
      "z": -6,
      "name": "Rock_Sandstone_Brick_Smooth_Half",
      "rotation": 5
    },
    {
      "x": -6,
      "y": 0,
      "z": -5,
      "name": "Rock_Sandstone"
    },
    {
      "x": -6,
      "y": 1,
      "z": -5,
      "name": "Rock_Sandstone"
    },
    {
      "x": -6,
      "y": 2,
      "z": -5,
      "name": "Rock_Sandstone"
    },
    {
      "x": -6,
      "y": 3,
      "z": -5,
      "name": "Rock_Sandstone"
    },
    {
      "x": -6,
      "y": 4,
      "z": -5,
      "name": "Rock_Sandstone"
    },
    {
      "x": -6,
      "y": 5,
      "z": -5,
      "name": "Rock_Sandstone"
    },
    {
      "x": -6,
      "y": 6,
      "z": -5,
      "name": "Rock_Sandstone"
    },
    {
      "x": -6,
      "y": 7,
      "z": -5,
      "name": "Rock_Sandstone_White_Cobble"
    },
    {
      "x": -6,
      "y": 13,
      "z": -5,
      "name": "Rock_Sandstone_Brick_Smooth_Half",
      "rotation": 5
    },
    {
      "x": -6,
      "y": 14,
      "z": -5,
      "name": "Rock_Sandstone_Brick_Smooth_Half",
      "rotation": 5
    },
    {
      "x": -6,
      "y": 0,
      "z": -4,
      "name": "Rock_Sandstone"
    },
    {
      "x": -6,
      "y": 1,
      "z": -4,
      "name": "Rock_Sandstone"
    },
    {
      "x": -6,
      "y": 2,
      "z": -4,
      "name": "Rock_Sandstone"
    },
    {
      "x": -6,
      "y": 3,
      "z": -4,
      "name": "Rock_Sandstone"
    },
    {
      "x": -6,
      "y": 4,
      "z": -4,
      "name": "Rock_Sandstone"
    },
    {
      "x": -6,
      "y": 5,
      "z": -4,
      "name": "Rock_Sandstone"
    },
    {
      "x": -6,
      "y": 6,
      "z": -4,
      "name": "Rock_Sandstone"
    },
    {
      "x": -6,
      "y": 7,
      "z": -4,
      "name": "Rock_Sandstone"
    },
    {
      "x": -6,
      "y": 8,
      "z": -4,
      "name": "Rock_Sandstone_White_Cobble_Stairs",
      "rotation": 2
    },
    {
      "x": -6,
      "y": 13,
      "z": -4,
      "name": "Rock_Sandstone_Brick_Smooth_Half",
      "rotation": 5
    },
    {
      "x": -6,
      "y": 0,
      "z": -3,
      "name": "Rock_Sandstone"
    },
    {
      "x": -6,
      "y": 1,
      "z": -3,
      "name": "Rock_Sandstone"
    },
    {
      "x": -6,
      "y": 2,
      "z": -3,
      "name": "Rock_Sandstone"
    },
    {
      "x": -6,
      "y": 3,
      "z": -3,
      "name": "Rock_Sandstone"
    },
    {
      "x": -6,
      "y": 4,
      "z": -3,
      "name": "Rock_Sandstone"
    },
    {
      "x": -6,
      "y": 5,
      "z": -3,
      "name": "Rock_Sandstone"
    },
    {
      "x": -6,
      "y": 6,
      "z": -3,
      "name": "Rock_Sandstone"
    },
    {
      "x": -6,
      "y": 7,
      "z": -3,
      "name": "Rock_Sandstone"
    },
    {
      "x": -6,
      "y": 8,
      "z": -3,
      "name": "Rock_Sandstone"
    },
    {
      "x": -6,
      "y": 9,
      "z": -3,
      "name": "Rock_Sandstone_White_Cobble_Stairs",
      "rotation": 2
    },
    {
      "x": -6,
      "y": 13,
      "z": -3,
      "name": "Rock_Sandstone_Brick_Smooth_Half",
      "rotation": 5
    },
    {
      "x": -6,
      "y": 14,
      "z": -3,
      "name": "Rock_Sandstone_Brick_Smooth_Half",
      "rotation": 5
    },
    {
      "x": -6,
      "y": 0,
      "z": -2,
      "name": "Rock_Sandstone"
    },
    {
      "x": -6,
      "y": 1,
      "z": -2,
      "name": "Rock_Sandstone"
    },
    {
      "x": -6,
      "y": 2,
      "z": -2,
      "name": "Rock_Sandstone"
    },
    {
      "x": -6,
      "y": 3,
      "z": -2,
      "name": "Rock_Sandstone"
    },
    {
      "x": -6,
      "y": 4,
      "z": -2,
      "name": "Rock_Sandstone"
    },
    {
      "x": -6,
      "y": 5,
      "z": -2,
      "name": "Rock_Sandstone"
    },
    {
      "x": -6,
      "y": 6,
      "z": -2,
      "name": "Rock_Sandstone"
    },
    {
      "x": -6,
      "y": 7,
      "z": -2,
      "name": "Rock_Sandstone"
    },
    {
      "x": -6,
      "y": 8,
      "z": -2,
      "name": "Rock_Sandstone"
    },
    {
      "x": -6,
      "y": 9,
      "z": -2,
      "name": "Rock_Sandstone_White_Cobble"
    },
    {
      "x": -6,
      "y": 10,
      "z": -2,
      "name": "Rock_Sandstone_White_Cobble_Stairs",
      "rotation": 2
    },
    {
      "x": -6,
      "y": 13,
      "z": -2,
      "name": "Rock_Sandstone_Brick_Smooth_Half",
      "rotation": 5
    },
    {
      "x": -6,
      "y": 0,
      "z": -1,
      "name": "Rock_Sandstone_Brick"
    },
    {
      "x": -6,
