{
  "version": 8,
  "blockIdVersion": 11,
  "anchorX": 0,
  "anchorY": 0,
  "anchorZ": 0,
  "blocks": [
    {
      "x": -5,
      "y": 0,
      "z": -4,
      "name": "Plant_Leaves_Beech"
    },
    {
      "x": -5,
      "y": 0,
      "z": -2,
      "name": "Plant_Leaves_Beech"
    },
    {
      "x": -5,
      "y": 0,
      "z": -1,
      "name": "Plant_Leaves_Beech"
    },
    {
      "x": -5,
      "y": 0,
      "z": 0,
      "name": "Plant_Leaves_Beech"
    },
    {
      "x": -5,
      "y": 1,
      "z": 0,
      "name": "Plant_Leaves_Beech"
    },
    {
      "x": -5,
      "y": 0,
      "z": 1,
      "name": "Plant_Leaves_Beech"
    },
    {
      "x": -5,
      "y": 0,
      "z": 2,
      "name": "Plant_Leaves_Beech"
    },
    {
      "x": -5,
      "y": 1,
      "z": 2,
      "name": "Plant_Leaves_Beech"
    },
    {
      "x": -4,
      "y": 0,
      "z": -4,
      "name": "Plant_Leaves_Beech"
    },
    {
      "x": -4,
      "y": 0,
      "z": -3,
      "name": "Plant_Leaves_Beech"
    },
    {
      "x": -4,
      "y": 0,
      "z": -2,
      "name": "Plant_Leaves_Beech"
    },
    {
      "x": -4,
      "y": 1,
      "z": -2,
      "name": "Plant_Leaves_Beech"
    },
    {
      "x": -4,
      "y": 0,
      "z": -1,
      "name": "Plant_Leaves_Beech"
    },
    {
      "x": -4,
      "y": 1,
      "z": -1,
      "name": "Plant_Leaves_Beech"
    },
    {
      "x": -4,
      "y": 0,
      "z": 0,
      "name": "Plant_Leaves_Beech"
    },
    {
      "x": -4,
      "y": 0,
      "z": 1,
      "name": "Plant_Leaves_Beech"
    },
    {
      "x": -4,
      "y": 0,
      "z": 2,
      "name": "Plant_Leaves_Beech"
    },
    {
      "x": -4,
      "y": 0,
      "z": 3,
      "name": "Plant_Leaves_Beech"
    },
    {
      "x": -4,
      "y": 0,
      "z": 4,
      "name": "Plant_Leaves_Beech"
    },
    {
      "x": -4,
      "y": 0,
      "z": 5,
      "name": "Plant_Leaves_Beech"
    },
    {
      "x": -3,
      "y": 0,
      "z": -5,
      "name": "Plant_Leaves_Beech"
    },
    {
      "x": -3,
      "y": 0,
      "z": -4,
      "name": "Plant_Leaves_Beech"
    },
    {
      "x": -3,
      "y": 0,
      "z": -3,
      "name": "Plant_Leaves_Beech"
    },
    {
      "x": -3,
      "y": 1,
      "z": -3,
      "name": "Plant_Leaves_Beech"
    },
    {
      "x": -3,
      "y": 0,
      "z": -2,
      "name": "Plant_Leaves_Beech"
    },
    {
      "x": -3,
      "y": 1,
      "z": -2,
      "name": "Plant_Leaves_Beech"
    },
    {
      "x": -3,
      "y": 0,
      "z": -1,
      "name": "Plant_Leaves_Beech"
    },
    {
      "x": -3,
      "y": 1,
      "z": -1,
      "name": "Plant_Leaves_Beech"
    },
    {
      "x": -3,
      "y": 2,
      "z": -1,
      "name": "Plant_Leaves_Beech"
    },
    {
      "x": -3,
      "y": -1,
      "z": 0,
      "name": "Wood_Windwillow_Branch_Corner",
      "rotation": 3
    },
    {
      "x": -3,
      "y": 0,
      "z": 0,
      "name": "Plant_Leaves_Beech"
    },
    {
      "x": -3,
      "y": 1,
      "z": 0,
      "name": "Plant_Leaves_Beech"
    },
    {
      "x": -3,
      "y": 0,
      "z": 1,
      "name": "Plant_Leaves_Beech"
    },
    {
      "x": -3,
      "y": 1,
      "z": 1,
      "name": "Plant_Leaves_Beech"
    },
    {
      "x": -3,
      "y": 0,
      "z": 2,
      "name": "Plant_Leaves_Beech"
    },
    {
      "x": -3,
      "y": 1,
      "z": 2,
      "name": "Plant_Leaves_Beech"
    },
    {
      "x": -3,
      "y": 2,
      "z": 2,
      "name": "Plant_Leaves_Beech"
    },
    {
      "x": -3,
      "y": 0,
      "z": 3,
      "name": "Plant_Leaves_Beech"
    },
    {
      "x": -3,
      "y": 0,
      "z": 4,
      "name": "Plant_Leaves_Beech"
    },
    {
      "x": -2,
      "y": 0,
      "z": -4,
      "name": "Plant_Leaves_Beech"
    },
    {
      "x": -2,
      "y": 1,
      "z": -4,
      "name": "Plant_Leaves_Beech"
    },
    {
      "x": -2,
      "y": 0,
      "z": -3,
      "name": "Plant_Leaves_Beech"
    },
    {
      "x": -2,
      "y": 1,
      "z": -3,
      "name": "Plant_Leaves_Beech"
    },
    {
      "x": -2,
      "y": 0,
      "z": -2,
      "name": "Plant_Leaves_Beech"
    },
    {
      "x": -2,
      "y": 1,
      "z": -2,
      "name": "Plant_Leaves_Beech"
    },
    {
      "x": -2,
      "y": 2,
      "z": -2,
      "name": "Plant_Leaves_Beech"
    },
    {
      "x": -2,
      "y": 0,
      "z": -1,
      "name": "Plant_Leaves_Beech"
    },
    {
      "x": -2,
      "y": 1,
      "z": -1,
      "name": "Plant_Leaves_Beech"
    },
    {
      "x": -2,
      "y": 2,
      "z": -1,
      "name": "Plant_Leaves_Beech"
    },
    {
      "x": -2,
      "y": -7,
      "z": 0,
      "name": "Wood_Windwillow_Branch_Corner"
    },
    {
      "x": -2,
      "y": -6,
      "z": 0,
      "name": "Wood_Windwillow_Branch_Long"
    },
    {
      "x": -2,
      "y": -5,
      "z": 0,
      "name": "Wood_Windwillow_Branch_Long"
    },
    {
      "x": -2,
      "y": -4,
      "z": 0,
      "name": "Wood_Windwillow_Branch_Corner",
      "rotation": 9
    },
    {
      "x": -2,
      "y": -1,
      "z": 0,
      "name": "Wood_Windwillow_Branch_Long",
      "rotation": 5
    },
    {
      "x": -2,
      "y": 0,
      "z": 0,
      "name": "Plant_Leaves_Beech"
    },
    {
      "x": -2,
      "y": 2,
      "z": 0,
      "name": "Plant_Leaves_Beech"
    },
    {
      "x": -2,
      "y": 3,
      "z": 0,
      "name": "Plant_Leaves_Beech"
    },
    {
      "x": -2,
      "y": 0,
      "z": 1,
      "name": "Plant_Leaves_Beech"
    },
    {
      "x": -2,
      "y": 1,
      "z": 1,
      "name": "Plant_Leaves_Beech"
    },
    {
      "x": -2,
      "y": 2,
      "z": 1,
      "name": "Plant_Leaves_Beech"
    },
    {
      "x": -2,
      "y": 0,
      "z": 2,
      "name": "Plant_Leaves_Beech"
    },
    {
      "x": -2,
      "y": 1,
      "z": 2,
      "name": "Plant_Leaves_Beech"
    },
    {
      "x": -2,
      "y": 1,
      "z": 3,
      "name": "Plant_Leaves_Beech"
    },
    {
      "x": -2,
      "y": 0,
      "z": 4,
      "name": "Plant_Leaves_Beech"
    },
    {
      "x": -2,
      "y": 1,
      "z": 4,
      "name": "Plant_Leaves_Beech"
    },
    {
      "x": -2,
      "y": 0,
      "z": 5,
      "name": "Plant_Leaves_Beech"
    },
    {
      "x": -1,
      "y": 0,
      "z": -6,
      "name": "Plant_Leaves_Beech"
    },
    {
      "x": -1,
      "y": 0,
      "z": -5,
      "name": "Plant_Leaves_Beech"
    },
    {
      "x": -1,
      "y": 0,
      "z": -4,
      "name": "Plant_Leaves_Beech"
    },
    {
      "x": -1,
      "y": 1,
      "z": -4,
      "name": "Plant_Leaves_Beech"
    },
    {
      "x": -1,
      "y": 0,
      "z": -3,
      "name": "Plant_Leaves_Beech"
    },
    {
      "x": -1,
      "y": 1,
      "z": -3,
      "name": "Plant_Leaves_Beech"
    },
    {
      "x": -1,
      "y": 2,
      "z": -3,
      "name": "Plant_Leaves_Beech"
    },
    {
      "x": -1,
      "y": 0,
      "z": -2,
      "name": "Plant_Leaves_Beech"
    },
    {
      "x": -1,
      "y": 1,
      "z": -2,
      "name": "Plant_Leaves_Beech"
    },
    {
      "x": -1,
      "y": -1,
      "z": -1,
      "name": "Wood_Windwillow_Branch_Corner",
      "rotation": 3
    },
    {
      "x": -1,
      "y": 0,
      "z": -1,
      "name": "Plant_Leaves_Beech"
    },
    {
      "x": -1,
      "y": 1,
      "z": -1,
      "name": "Plant_Leaves_Beech"
    },
    {
      "x": -1,
      "y": 2,
      "z": -1,
      "name": "Plant_Leaves_Beech"
    },
    {
      "x": -1,
      "y": -4,
      "z": 0,
      "name": "Wood_Windwillow_Branch_Corner",
      "rotation": 1
    },
    {
      "x": -1,
      "y": -3,
      "z": 0,
      "name": "Wood_Windwillow_Branch_Long"
    },
    {
      "x": -1,
      "y": -2,
      "z": 0,
      "name": "Wood_Windwillow_Branch_Corner",
      "rotation": 9
    },
    {
      "x": -1,
      "y": -1,
      "z": 0,
      "name": "Wood_Windwillow_Trunk_Full",
      "support": 15
    },
    {
      "x": -1,
      "y": 0,
      "z": 0,
      "name": "Plant_Leaves_Beech"
    },
    {
      "x": -1,
      "y": 1,
      "z": 0,
      "name": "Plant_Leaves_Beech"
    },
    {
      "x": -1,
      "y": 2,
      "z": 0,
      "name": "Plant_Leaves_Beech"
    },
    {
      "x": -1,
      "y": -1,
      "z": 1,
      "name": "Wood_Windwillow_Branch_Long",
      "rotation": 4
    },
    {
      "x": -1,
      "y": 0,
      "z": 1,
      "name": "Plant_Leaves_Beech"
    },
    {
      "x": -1,
      "y": 1,
      "z": 1,
      "name": "Plant_Leaves_Beech"
    },
    {
      "x": -1,
      "y": 2,
      "z": 1,
      "name": "Plant_Leaves_Beech"
    },
    {
      "x": -1,
      "y": -1,
      "z": 2,
      "name": "Wood_Windwillow_Branch_Corner"
    },
    {
      "x": -1,
      "y": 0,
      "z": 2,
      "name": "Plant_Leaves_Beech"
    },
    {
      "x": -1,
      "y": 1,
      "z": 2,
      "name": "Plant_Leaves_Beech"
    },
    {
      "x": -1,
      "y": 2,
      "z": 2,
      "name": "Plant_Leaves_Beech"
    },
    {
      "x": -1,
      "y": 3,
      "z": 2,
      "name": "Plant_Leaves_Beech"
    },
    {
      "x": -1,
      "y": 0,
      "z": 3,
      "name": "Plant_Leaves_Beech"
    },
    {
      "x": -1,
      "y": 1,
      "z": 3,
      "name": "Plant_Leaves_Beech"
    },
    {
      "x": -1,
      "y": 0,
      "z": 4,
      "name": "Plant_Leaves_Beech"
    },
    {
      "x": -1,
      "y": 1,
      "z": 4,
      "name": "Plant_Leaves_Beech"
    },
    {
      "x": -1,
      "y": 0,
      "z": 5,
      "name": "Plant_Leaves_Beech"
    },
    {
      "x": -1,
      "y": 0,
      "z": 6,
      "name": "Plant_Leaves_Beech"
    },
    {
      "x": 0,
      "y": 0,
      "z": -4,
      "name": "Plant_Leaves_Beech"
    },
    {
      "x": 0,
      "y": 1,
      "z": -4,
      "name": "Plant_Leaves_Beech"
    },
    {
      "x": 0,
      "y": -1,
      "z": -3,
      "name": "Wood_Windwillow_Branch_Corner",
      "rotation": 2
    },
    {
      "x": 0,
      "y": 0,
      "z": -3,
      "name": "Plant_Leaves_Beech"
    },
    {
      "x": 0,
      "y": 1,
      "z": -3,
      "name": "Plant_Leaves_Beech"
    },
    {
      "x": 0,
      "y": 2,
      "z": -3,
      "name": "Plant_Leaves_Beech"
    },
    {
      "x": 0,
      "y": -6,
      "z": -2,
      "name": "Wood_Windwillow_Branch_Corner"
    },
    {
      "x": 0,
      "y": -5,
      "z": -2,
      "name": "Wood_Windwillow_Branch_Long"
    },
    {
      "x": 0,
      "y": -4,
      "z": -2,
      "name": "Wood_Windwillow_Branch_Corner",
      "rotation": 8
    },
    {
      "x": 0,
      "y": -1,
      "z": -2,
      "name": "Wood_Windwillow_Branch_Long",
      "rotation": 4
    },
    {
      "x": 0,
      "y": 0,
      "z": -2,
      "name": "Plant_Leaves_Beech"
    },
    {
      "x": 0,
      "y": 1,
      "z": -2,
      "name": "Plant_Leaves_Beech"
    },
    {
      "x": 0,
      "y": -4,
      "z": -1,
      "name": "Wood_Windwillow_Branch_Corner"
    },
    {
      "x": 0,
      "y": -3,
      "z": -1,
      "name": "Wood_Windwillow_Branch_Corner",
      "rotation": 8
    },
    {
      "x": 0,
      "y": -1,
      "z": -1,
      "name": "Wood_Windwillow_Trunk_Full",
      "support": 15
    },
    {
      "x": 0,
      "y": 0,
      "z": -1,
      "name": "Plant_Leaves_Beech"
    },
    {
      "x": 0,
      "y": 1,
      "z": -1,
      "name": "Plant_Leaves_Beech"
    },
    {
      "x": 0,
      "y": 2,
      "z": -1,
      "name": "Plant_Leaves_Beech"
    },
    {
      "x": 0,
      "y": 3,
      "z": -1,
      "name": "Plant_Leaves_Beech"
    },
    {
      "x": 0,
      "y": -9,
      "z": 0,
      "name": "Wood_Windwillow_Branch_Corner",
      "rotation": 2
    },
    {
      "x": 0,
      "y": -8,
      "z": 0,
      "name": "Wood_Windwillow_Branch_Long"
    },
    {
      "x": 0,
      "y": -7,
      "z": 0,
      "name": "Wood_Windwillow_Branch_Long"
    },
    {
      "x": 0,
      "y": -6,
      "z": 0,
      "name": "Wood_Windwillow_Branch_Long",
      "support": 15
    },
    {
      "x": 0,
      "y": -5,
      "z": 0,
      "name": "Wood_Windwillow_Trunk_Full",
      "support": 15
    },
    {
      "x": 0,
      "y": -4,
      "z": 0,
      "name": "Wood_Windwillow_Trunk_Full",
      "support": 15
    },
    {
      "x": 0,
      "y": -3,
      "z": 0,
      "name": "Wood_Windwillow_Trunk_Full",
      "support": 15
    },
    {
      "x": 0,
      "y": -2,
      "z": 0,
      "name": "Wood_Windwillow_Trunk_Full",
      "support": 15
    },
    {
      "x": 0,
      "y": -1,
      "z": 0,
      "name": "Wood_Windwillow_Trunk_Full",
      "support": 15
    },
    {
      "x": 0,
      "y": 0,
      "z": 0,
      "name": "Wood_Windwillow_Trunk_Full",
      "support": 15
    },
    {
      "x": 0,
      "y": 1,
      "z": 0,
      "name": "Plant_Leaves_Beech"
    },
    {
      "x": 0,
      "y": 2,
      "z": 0,
      "name": "Plant_Leaves_Beech"
    },
    {
      "x": 0,
      "y": 3,
      "z": 0,
      "name": "Plant_Leaves_Beech"
    },
    {
      "x": 0,
      "y": -10,
      "z": 1,
      "name": "Wood_Windwillow_Branch_Long"
    },
    {
      "x": 0,
      "y": -9,
      "z": 1,
      "name": "Wood_Windwillow_Branch_Corner",
      "rotation": 10
    },
    {
      "x": 0,
      "y": -5,
      "z": 1,
      "name": "Wood_Windwillow_Branch_Corner",
      "rotation": 2
    },
    {
      "x": 0,
      "y": -4,
      "z": 1,
      "name": "Wood_Windwillow_Branch_Corner",
      "rotation": 10
    },
    {
      "x": 0,
      "y": -1,
      "z": 1,
      "name": "Wood_Windwillow_Branch_Long",
      "rotation": 4
    },
    {
      "x": 0,
      "y": 1,
      "z": 1,
      "name": "Plant_Leaves_Beech"
    },
    {
      "x": 0,
      "y": 3,
      "z": 1,
      "name": "Plant_Leaves_Beech"
    },
    {
      "x": 0,
      "y": -7,
      "z": 2,
      "name": "Wood_Windwillow_Branch_Long"
    },
    {
      "x": 0,
      "y": -6,
      "z": 2,
      "name": "Wood_Windwillow_Branch_Long"
    },
    {
      "x": 0,
      "y": -5,
      "z": 2,
      "name": "Wood_Windwillow_Branch_Corner",
      "rotation": 10
    },
    {
      "x": 0,
      "y": -1,
      "z": 2,
      "name": "Wood_Windwillow_Branch_Long",
      "rotation": 4
    },
    {
      "x": 0,
      "y": 0,
      "z": 2,
      "name": "Plant_Leaves_Beech"
    },
    {
      "x": 0,
      "y": 1,
      "z": 2,
      "name": "Plant_Leaves_Beech"
    },
    {
      "x": 0,
      "y": 2,
      "z": 2,
      "name": "Plant_Leaves_Beech"
    },
    {
      "x": 0,
      "y": -1,
      "z": 3,
      "name": "Wood_Windwillow_Branch_Corner"
    },
    {
      "x": 0,
      "y": 0,
      "z": 3,
      "name": "Plant_Leaves_Beech"
    },
    {
      "x": 0,
      "y": 1,
      "z": 3,
      "name": "Plant_Leaves_Beech"
    },
    {
      "x": 0,
      "y": 2,
      "z": 3,
      "name": "Plant_Leaves_Beech"
    },
    {
      "x": 0,
      "y": 3,
      "z": 3,
      "name": "Plant_Leaves_Beech"
    },
    {
      "x": 0,
      "y": 0,
      "z": 4,
      "name": "Plant_Leaves_Beech"
    },
    {
      "x": 0,
      "y": 1,
      "z": 4,
      "name": "Plant_Leaves_Beech"
    },
    {
      "x": 0,
      "y": 0,
      "z": 5,
      "name": "Plant_Leaves_Beech"
    },
    {
      "x": 0,
      "y": 0,
      "z": 6,
      "name": "Plant_Leaves_Beech"
    },
    {
      "x": 1,
      "y": 0,
      "z": -6,
      "name": "Plant_Leaves_Beech"
    },
    {
      "x": 1,
      "y": 0,
      "z": -5,
      "name": "Plant_Leaves_Beech"
    },
    {
      "x": 1,
      "y": 0,
      "z": -4,
      "name": "Plant_Leaves_Beech"
    },
    {
      "x": 1,
      "y": 1,
      "z": -4,
      "name": "Plant_Leaves_Beech"
    },
    {
      "x": 1,
      "y": 0,
      "z": -3,
      "name": "Plant_Leaves_Beech"
    },
    {
      "x": 1,
      "y": 1,
      "z": -3,
      "name": "Plant_Leaves_Beech"
    },
    {
      "x": 1,
      "y": 0,
      "z": -2,
      "name": "Plant_Leaves_Beech"
    },
    {
      "x": 1,
      "y": 1,
      "z": -2,
      "name": "Plant_Leaves_Beech"
    },
    {
      "x": 1,
      "y": 2,
      "z": -2,
      "name": "Plant_Leaves_Beech"
    },
    {
      "x": 1,
      "y": 3,
      "z": -2,
      "name": "Plant_Leaves_Beech"
    },
    {
      "x": 1,
      "y": 0,
      "z": -1,
      "name": "Plant_Leaves_Beech"
    },
    {
      "x": 1,
      "y": 1,
      "z": -1,
      "name": "Plant_Leaves_Beech"
    },
    {
      "x": 1,
      "y": 2,
      "z": -1,
      "name": "Plant_Leaves_Beech"
    },
    {
      "x": 1,
      "y": -5,
      "z": 0,
      "name": "Wood_Windwillow_Branch_Corner",
      "rotation": 3
    },
    {
      "x": 1,
      "y": -4,
      "z": 0,
      "name": "Wood_Windwillow_Branch_Corner",
      "rotation": 11
    },
    {
      "x": 1,
      "y": -3,
      "z": 0,
      "name": "Wood_Windwillow_Branch_Corner",
      "rotation": 3
    },
    {
      "x": 1,
      "y": -2,
      "z": 0,
      "name": "Wood_Windwillow_Branch_Corner",
      "rotation": 11
    },
    {
      "x": 1,
      "y": -1,
      "z": 0,
      "name": "Wood_Windwillow_Branch_Long",
      "rotation": 5
    },
    {
      "x": 1,
      "y": 0,
      "z": 0,
      "name": "Plant_Leaves_Beech"
    },
    {
      "x": 1,
      "y": 1,
      "z": 0,
      "name": "Plant_Leaves_Beech"
    },
    {
      "x": 1,
      "y": 2,
      "z": 0,
      "name": "Plant_Leaves_Beech"
    },
    {
      "x": 1,
      "y": 3,
      "z": 0,
      "name": "Plant_Leaves_Beech"
    },
    {
      "x": 1,
      "y": 0,
      "z": 1,
      "name": "Plant_Leaves_Beech"
    },
    {
      "x": 1,
      "y": 1,
      "z": 1,
      "name": "Plant_Leaves_Beech"
    },
    {
      "x": 1,
      "y": 3,
      "z": 1,
      "name": "Plant_Leaves_Beech"
    },
    {
      "x": 1,
      "y": 0,
      "z": 2,
      "name": "Plant_Leaves_Beech"
    },
    {
      "x": 1,
      "y": 1,
      "z": 2,
      "name": "Plant_Leaves_Beech"
    },
    {
      "x": 1,
      "y": 2,
      "z": 2,
      "name": "Plant_Leaves_Beech"
    },
    {
      "x": 1,
      "y": 0,
      "z": 3,
      "name": "Plant_Leaves_Beech"
    },
    {
      "x": 1,
      "y": 1,
      "z": 3,
      "name": "Plant_Leaves_Beech"
    },
    {
      "x": 1,
      "y": 0,
      "z": 4,
      "name": "Plant_Leaves_Beech"
    },
    {
      "x": 1,
      "y": 1,
      "z": 4,
      "name": "Plant_Leaves_Beech"
    },
    {
      "x": 1,
      "y": 0,
      "z": 5,
      "name": "Plant_Leaves_Beech"
    },
    {
      "x": 1,
      "y": 0,
      "z": 6,
      "name": "Plant_Leaves_Beech"
    },
    {
      "x": 2,
      "y": 0,
      "z": -5,
      "name": "Plant_Leaves_Beech"
    },
    {
      "x": 2,
      "y": 1,
      "z": -5,
      "name": "Plant_Leaves_Beech"
    },
    {
      "x": 2,
      "y": 0,
      "z": -4,
      "name": "Plant_Leaves_Beech"
    },
    {
      "x": 2,
      "y": 1,
      "z": -4,
      "name": "Plant_Leaves_Beech"
    },
    {
      "x": 2,
      "y": 0,
      "z": -3,
      "name": "Plant_Leaves_Beech"
    },
    {
      "x": 2,
      "y": 1,
      "z": -3,
      "name": "Plant_Leaves_Beech"
    },
    {
      "x": 2,
      "y": 2,
      "z": -3,
      "name": "Plant_Leaves_Beech"
    },
    {
      "x": 2,
      "y": 0,
      "z": -2,
      "name": "Plant_Leaves_Beech"
    },
    {
      "x": 2,
      "y": 2,
      "z": -1,
      "name": "Plant_Leaves_Beech"
    },
    {
      "x": 2,
      "y": -6,
      "z": 0,
      "name": "Wood_Windwillow_Branch_Long"
    },
    {
      "x": 2,
      "y": -5,
      "z": 0,
      "name": "Wood_Windwillow_Branch_Corner",
      "rotation": 11
    },
    {
      "x": 2,
      "y": -1,
      "z": 0,
      "name": "Wood_Windwillow_Branch_Long",
      "rotation": 5
    },
    {
      "x": 2,
      "y": 0,
      "z": 0,
      "name": "Plant_Leaves_Beech"
    },
    {
      "x": 2,
      "y": 2,
      "z": 0,
      "name": "Plant_Leaves_Beech"
    },
    {
      "x": 2,
      "y": 3,
      "z": 0,
      "name": "Plant_Leaves_Beech"
    },
    {
      "x": 2,
      "y": 0,
      "z": 1,
      "name": "Plant_Leaves_Beech"
    },
    {
      "x": 2,
      "y": 1,
      "z": 1,
      "name": "Plant_Leaves_Beech"
    },
    {
      "x": 2,
      "y": 2,
      "z": 1,
      "name": "Plant_Leaves_Beech"
    },
    {
      "x": 2,
      "y": 3,
      "z": 1,
      "name": "Plant_Leaves_Beech"
    },
    {
      "x": 2,
      "y": 0,
      "z": 2,
      "name": "Plant_Leaves_Beech"
    },
    {
      "x": 2,
      "y": 1,
      "z": 2,
      "name": "Plant_Leaves_Beech"
    },
    {
      "x": 2,
      "y": 2,
      "z": 2,
      "name": "Plant_Leaves_Beech"
    },
    {
      "x": 2,
      "y": 3,
      "z": 2,
      "name": "Plant_Leaves_Beech"
    },
    {
      "x": 2,
      "y": 0,
      "z": 3,
      "name": "Plant_Leaves_Beech"
    },
    {
      "x": 2,
      "y": 1,
      "z": 3,
      "name": "Plant_Leaves_Beech"
    },
    {
      "x": 2,
      "y": 2,
      "z": 3,
      "name": "Plant_Leaves_Beech"
    },
    {
      "x": 2,
      "y": 0,
      "z": 4,
      "name": "Plant_Leaves_Beech"
    },
    {
      "x": 2,
      "y": 1,
      "z": 4,
      "name": "Plant_Leaves_Beech"
    },
    {
      "x": 2,
      "y": 2,
      "z": 4,
      "name": "Plant_Leaves_Beech"
    },
    {
      "x": 3,
      "y": 0,
      "z": -4,
      "name": "Plant_Leaves_Beech"
    },
    {
      "x": 3,
      "y": 1,
      "z": -4,
      "name": "Plant_Leaves_Beech"
    },
    {
      "x": 3,
      "y": 0,
      "z": -3,
      "name": "Plant_Leaves_Beech"
    },
    {
      "x": 3,
      "y": 1,
      "z": -3,
      "name": "Plant_Leaves_Beech"
    },
    {
      "x": 3,
      "y": 0,
      "z": -2,
      "name": "Plant_Leaves_Beech"
    },
    {
      "x": 3,
      "y": 0,
      "z": -1,
      "name": "Plant_Leaves_Beech"
    },
    {
      "x": 3,
      "y": 1,
      "z": -1,
      "name": "Plant_Leaves_Beech"
    },
    {
      "x": 3,
      "y": 2,
      "z": -1,
      "name": "Plant_Leaves_Beech"
    },
    {
      "x": 3,
      "y": -1,
      "z": 0,
      "name": "Wood_Windwillow_Branch_Corner",
      "rotation": 1
    },
    {
      "x": 3,
      "y": 0,
      "z": 0,
      "name": "Plant_Leaves_Beech"
    },
    {
      "x": 3,
      "y": 2,
      "z": 0,
      "name": "Plant_Leaves_Beech"
    },
    {
      "x": 3,
      "y": 3,
      "z": 0,
      "name": "Plant_Leaves_Beech"
    },
    {
      "x": 3,
      "y": 0,
      "z": 1,
      "name": "Plant_Leaves_Beech"
    },
    {
      "x": 3,
      "y": 2,
      "z": 1,
      "name": "Plant_Leaves_Beech"
    },
    {
      "x": 3,
      "y": 0,
      "z": 2,
      "name": "Plant_Leaves_Beech"
    },
    {
      "x": 3,
      "y": 1,
      "z": 2,
      "name": "Plant_Leaves_Beech"
    },
    {
      "x": 3,
      "y": 2,
      "z": 2,
      "name": "Plant_Leaves_Beech"
    },
    {
      "x": 3,
      "y": 0,
      "z": 3,
      "name": "Plant_Leaves_Beech"
    },
    {
      "x": 3,
      "y": 1,
      "z": 3,
      "name": "Plant_Leaves_Beech"
    },
    {
      "x": 3,
      "y": 2,
      "z": 3,
      "name": "Plant_Leaves_Beech"
    },
    {
      "x": 3,
      "y": 0,
      "z": 4,
      "name": "Plant_Leaves_Beech"
    },
    {
      "x": 3,
      "y": 0,
      "z": 5,
      "name": "Plant_Leaves_Beech"
    },
    {
      "x": 4,
      "y": 0,
      "z": -4,
      "name": "Plant_Leaves_Beech"
    },
    {
      "x": 4,
      "y": 0,
      "z": -3,
      "name": "Plant_Leaves_Beech"
    },
    {
      "x": 4,
      "y": 0,
      "z": -2,
      "name": "Plant_Leaves_Beech"
    },
    {
      "x": 4,
      "y": 0,
      "z": -1,
      "name": "Plant_Leaves_Beech"
    },
    {
      "x": 4,
      "y": 1,
      "z": -1,
      "name": "Plant_Leaves_Beech"
    },
    {
      "x": 4,
      "y": 2,
      "z": -1,
      "name": "Plant_Leaves_Beech"
    },
    {
      "x": 4,
      "y": 0,
      "z": 0,
      "name": "Plant_Leaves_Beech"
    },
    {
      "x": 4,
      "y": 1,
      "z": 0,
      "name": "Plant_Leaves_Beech"
    },
    {
      "x": 4,
      "y": 2,
      "z": 0,
      "name": "Plant_Leaves_Beech"
    },
    {
      "x": 4,
      "y": 0,
      "z": 1,
      "name": "Plant_Leaves_Beech"
    },
    {
      "x": 4,
      "y": 1,
      "z": 1,
      "name": "Plant_Leaves_Beech"
    },
    {
      "x": 4,
      "y": 2,
      "z": 1,
      "name": "Plant_Leaves_Beech"
    },
    {
      "x": 4,
      "y": 0,
      "z": 2,
      "name": "Plant_Leaves_Beech"
    },
    {
      "x": 4,
      "y": 2,
      "z": 2,
      "name": "Plant_Leaves_Beech"
    },
    {
      "x": 4,
      "y": 0,
      "z": 3,
      "name": "Plant_Leaves_Beech"
    },
    {
      "x": 4,
      "y": 1,
      "z": 3,
      "name": "Plant_Leaves_Beech"
    },
    {
      "x": 4,
      "y": 0,
      "z": 4,
      "name": "Plant_Leaves_Beech"
    },
    {
      "x": 5,
      "y": 0,
      "z": -3,
      "name": "Plant_Leaves_Beech"
    },
    {
      "x": 5,
      "y": 0,
      "z": -1,
      "name": "Plant_Leaves_Beech"
    },
    {
      "x": 5,
      "y": 0,
      "z": 0,
      "name": "Plant_Leaves_Beech"
    },
    {
      "x": 5,
      "y": 1,
      "z": 0,
      "name": "Plant_Leaves_Beech"
    },
    {
      "x": 5,
      "y": 0,
      "z": 1,
      "name": "Plant_Leaves_Beech"
    },
    {
      "x": 5,
      "y": 0,
      "z": 2,
      "name": "Plant_Leaves_Beech"
    },
    {
      "x": 5,
      "y": 0,
      "z": 3,
      "name": "Plant_Leaves_Beech"
    },
    {
      "x": 5,
      "y": 0,
      "z": 4,
      "name": "Plant_Leaves_Beech"
    },
    {
      "x": 6,
      "y": 0,
      "z": -1,
      "name": "Plant_Leaves_Beech"
    },
    {
      "x": 6,
      "y": 0,
      "z": 0,
      "name": "Plant_Leaves_Beech"
    },
    {
      "x": 6,
      "y": 0,
      "z": 2,
      "name": "Plant_Leaves_Beech"
    }
  ],
  "fluids": [
    {
      "x": -3,
      "y": -1,
      "z": 0,
      "name": "Water_Source",
      "level": 1
    },
    {
      "x": -2,
      "y": -7,
      "z": 0,
      "name": "Water_Source",
      "level": 1
    },
    {
      "x": -2,
      "y": -6,
      "z": 0,
      "name": "Water_Source",
      "level": 1
    },
    {
      "x": -2,
      "y": -5,
      "z": 0,
      "name": "Water_Source",
      "level": 1
    },
    {
      "x": -2,
      "y": -4,
      "z": 0,
      "name": "Water_Source",
      "level": 1
    },
    {
      "x": -2,
      "y": -1,
      "z": 0,
      "name": "Water_Source",
      "level": 1
    },
    {
      "x": -1,
      "y": -1,
      "z": -1,
      "name": "Water_Source",
      "level": 1
    },
    {
      "x": -1,
      "y": -4,
      "z": 0,
      "name": "Water_Source",
      "level": 1
    },
    {
      "x": -1,
      "y": -3,
      "z": 0,
      "name": "Water_Source",
      "level": 1
    },
    {
      "x": -1,
      "y": -2,
      "z": 0,
      "name": "Water_Source",
      "level": 1
    },
    {
      "x": -1,
      "y": -1,
      "z": 1,
      "name": "Water_Source",
      "level": 1
    },
    {
      "x": -1,
      "y": -1,
      "z": 2,
      "name": "Water_Source",
      "level": 1
    },
    {
      "x": 0,
      "y": -1,
      "z": -3,
      "name": "Water_Source",
      "level": 1
    },
    {
      "x": 0,
      "y": -6,
      "z": -2,
      "name": "Water_Source",
      "level": 1
    },
    {
      "x": 0,
      "y": -5,
      "z": -2,
      "name": "Water_Source",
      "level": 1
    },
    {
      "x": 0,
      "y": -4,
      "z": -2,
      "name": "Water_Source",
      "level": 1
    },
    {
      "x": 0,
      "y": -1,
      "z": -2,
      "name": "Water_Source",
      "level": 1
    },
    {
      "x": 0,
      "y": -4,
      "z": -1,
      "name": "Water_Source",
      "level": 1
    },
    {
      "x": 0,
      "y": -3,
      "z": -1,
      "name": "Water_Source",
      "level": 1
    },
    {
      "x": 0,
      "y": -9,
      "z": 0,
      "name": "Water_Source",
      "level": 1
    },
    {
      "x": 0,
      "y": -8,
      "z": 0,
      "name": "Water_Source",
      "level": 1
    },
    {
      "x": 0,
      "y": -7,
      "z": 0,
      "name": "Water_Source",
      "level": 1
    },
    {
      "x": 0,
      "y": -6,
      "z": 0,
      "name": "Water_Source",
      "level": 1
    },
    {
      "x": 0,
      "y": -10,
      "z": 1,
      "name": "Water_Source",
      "level": 1
    },
    {
      "x": 0,
      "y": -9,
      "z": 1,
      "name": "Water_Source",
      "level": 1
    },
    {
      "x": 0,
      "y": -5,
      "z": 1,
      "name": "Water_Source",
      "level": 1
    },
    {
      "x": 0,
      "y": -4,
      "z": 1,
      "name": "Water_Source",
      "level": 1
    },
    {
      "x": 0,
      "y": -1,
      "z": 1,
      "name": "Water_Source",
      "level": 1
    },
    {
      "x": 0,
      "y": -7,
      "z": 2,
      "name": "Water_Source",
      "level": 1
    },
    {
      "x": 0,
      "y": -6,
      "z": 2,
      "name": "Water_Source",
      "level": 1
    },
    {
      "x": 0,
      "y": -5,
      "z": 2,
      "name": "Water_Source",
      "level": 1
    },
    {
      "x": 0,
      "y": -1,
      "z": 2,
      "name": "Water_Source",
      "level": 1
    },
    {
      "x": 0,
      "y": -1,
      "z": 3,
      "name": "Water_Source",
      "level": 1
    },
    {
      "x": 1,
      "y": -5,
      "z": 0,
      "name": "Water_Source",
      "level": 1
    },
    {
      "x": 1,
      "y": -4,
      "z": 0,
      "name": "Water_Source",
      "level": 1
    },
    {
      "x": 1,
      "y": -3,
      "z": 0,
      "name": "Water_Source",
      "level": 1
    },
    {
      "x": 1,
      "y": -2,
      "z": 0,
      "name": "Water_Source",
      "level": 1
    },
    {
      "x": 1,
      "y": -1,
      "z": 0,
      "name": "Water_Source",
      "level": 1
    },
    {
      "x": 2,
      "y": -6,
      "z": 0,
      "name": "Water_Source",
      "level": 1
    },
    {
      "x": 2,
      "y": -5,
      "z": 0,
      "name": "Water_Source",
      "level": 1
    },
    {
      "x": 2,
      "y": -1,
      "z": 0,
      "name": "Water_Source",
      "level": 1
    },
    {
      "x": 3,
      "y": -1,
      "z": 0,
      "name": "Water_Source",
      "level": 1
    }
  ]
}