{
  "version": 8,
  "blockIdVersion": 11,
  "anchorX": 0,
  "anchorY": 0,
  "anchorZ": 0,
  "blocks": [
    {
      "x": -1,
      "y": -2,
      "z": 0,
      "name": "Rock_Volcanic_Cracked_Incandescent"
    },
    {
      "x": -1,
      "y": -1,
      "z": 0,
      "name": "Rock_Volcanic_Cracked_Incandescent"
    },
    {
      "x": -1,
      "y": 0,
      "z": 0,
      "name": "Rock_Volcanic_Cracked_Incandescent"
    },
    {
      "x": -1,
      "y": 1,
      "z": 0,
      "name": "Rock_Volcanic_Cracked_Lava"
    },
    {
      "x": -1,
      "y": 2,
      "z": 0,
      "name": "Rock_Volcanic"
    },
    {
      "x": 0,
      "y": -2,
      "z": -1,
      "name": "Rock_Volcanic_Cracked_Incandescent"
    },
    {
      "x": 0,
      "y": -1,
      "z": -1,
      "name": "Rock_Volcanic_Cracked_Incandescent"
    },
    {
      "x": 0,
      "y": 0,
      "z": -1,
      "name": "Rock_Volcanic_Cracked_Incandescent"
    },
    {
      "x": 0,
      "y": 1,
      "z": -1,
      "name": "Rock_Volcanic_Cracked_Lava"
    },
    {
      "x": 0,
      "y": 2,
      "z": -1,
      "name": "SS_Rock_Volcanic_Vent_Small"
    },
    {
      "x": 0,
      "y": -2,
      "z": 0,
      "name": "Rock_Volcanic_Cracked_Incandescent"
    },
    {
      "x": 0,
      "y": -1,
      "z": 0,
      "name": "Rock_Volcanic_Cracked_Incandescent"
    },
    {
      "x": 0,
      "y": 0,
      "z": 0,
      "name": "Rock_Volcanic_Cracked_Incandescent"
    },
    {
      "x": 0,
      "y": 1,
      "z": 0,
      "name": "Rock_Volcanic_Cracked_Incandescent"
    },
    {
      "x": 0,
      "y": 2,
      "z": 0,
      "name": "Rock_Volcanic_Cracked_Lava"
    },
    {
      "x": 0,
      "y": 3,
      "z": 0,
      "name": "Rock_Volcanic"
    },
    {
      "x": 0,
      "y": 4,
      "z": 0,
      "name": "SS_Rock_Volcanic_Vent_Large"
    },
    {
      "x": 0,
      "y": 5,
      "z": 0,
      "name": "SS_Rock_Volcanic_Vent_Large",
      "filler": 1024
    },
    {
      "x": 0,
      "y": -2,
      "z": 1,
      "name": "Rock_Volcanic_Cracked_Incandescent"
    },
    {
      "x": 0,
      "y": -1,
      "z": 1,
      "name": "Rock_Volcanic_Cracked_Incandescent"
    },
    {
      "x": 0,
      "y": 0,
      "z": 1,
      "name": "Rock_Volcanic_Cracked_Incandescent"
    },
    {
      "x": 0,
      "y": 1,
      "z": 1,
      "name": "SS_Rock_Volcanic_Vent_Small"
    },
    {
      "x": 1,
      "y": -2,
      "z": 0,
      "name": "Rock_Volcanic_Cracked_Incandescent"
    },
    {
      "x": 1,
      "y": -1,
      "z": 0,
      "name": "Rock_Volcanic_Cracked_Incandescent"
    },
    {
      "x": 1,
      "y": 0,
      "z": 0,
      "name": "Rock_Volcanic_Cracked_Incandescent"
    },
    {
      "x": 1,
      "y": 1,
      "z": 0,
      "name": "Rock_Volcanic_Cracked_Lava"
    },
    {
      "x": 1,
      "y": 2,
      "z": 0,
      "name": "SS_Rock_Volcanic_Vent_Small"
    }
  ],
  "fluids": [
    {
      "x": 0,
      "y": 2,
      "z": -1,
      "name": "Water_Source",
      "level": 1
    },
    {
      "x": 0,
      "y": 4,
      "z": 0,
      "name": "Water_Source",
      "level": 1
    },
    {
      "x": 0,
      "y": 5,
      "z": 0,
      "name": "Water_Source",
      "level": 1
    },
    {
      "x": 0,
      "y": 1,
      "z": 1,
      "name": "Water_Source",
      "level": 1
    },
    {
      "x": 1,
      "y": 2,
      "z": 0,
      "name": "Water_Source",
      "level": 1
    }
  ]
}