{
  "version": 8,
  "blockIdVersion": 11,
  "anchorX": 0,
  "anchorY": 0,
  "anchorZ": 0,
  "blocks": [
    {
      "x": -11,
      "y": 0,
      "z": -3,
      "name": "*Rock_Calcite_Brick_Stairs_State_Definitions_Corner_Left",
      "rotation": 2
    },
    {
      "x": -11,
      "y": 4,
      "z": -3,
      "name": "*Rock_Calcite_Brick_Stairs_State_Definitions_Corner_Left",
      "rotation": 9
    },
    {
      "x": -11,
      "y": 5,
      "z": -3,
      "name": "Rock_Calcite_Brick"
    },
    {
      "x": -11,
      "y": 6,
      "z": -3,
      "name": "Rock_Calcite_Brick_Decorative"
    },
    {
      "x": -11,
      "y": 7,
      "z": -3,
      "name": "*Rock_Calcite_Brick_Stairs_State_Definitions_Corner_Left",
      "rotation": 2
    },
    {
      "x": -11,
      "y": 8,
      "z": -3,
      "name": "*Rock_Calcite_Brick_Stairs_State_Definitions_Corner_Right",
      "rotation": 8
    },
    {
      "x": -11,
      "y": 10,
      "z": -3,
      "name": "*Rock_Calcite_Brick_Stairs_State_Definitions_Corner_Right",
      "rotation": 8
    },
    {
      "x": -11,
      "y": 11,
      "z": -3,
      "name": "*Rock_Calcite_Brick_Stairs_State_Definitions_Corner_Left",
      "rotation": 9
    },
    {
      "x": -11,
      "y": 0,
      "z": -2,
      "name": "Rock_Calcite_Brick_Stairs",
      "rotation": 3
    },
    {
      "x": -11,
      "y": 4,
      "z": -2,
      "name": "Rock_Calcite_Brick_Stairs",
      "rotation": 9
    },
    {
      "x": -11,
      "y": 5,
      "z": -2,
      "name": "Rock_Calcite_Brick"
    },
    {
      "x": -11,
      "y": 6,
      "z": -2,
      "name": "Rock_Calcite_Brick_Decorative"
    },
    {
      "x": -11,
      "y": 7,
      "z": -2,
      "name": "Rock_Calcite_Brick_Stairs",
      "rotation": 3
    },
    {
      "x": -11,
      "y": 8,
      "z": -2,
      "name": "Rock_Calcite_Brick_Stairs",
      "rotation": 9
    },
    {
      "x": -11,
      "y": 10,
      "z": -2,
      "name": "Rock_Calcite_Brick_Stairs",
      "rotation": 9
    },
    {
      "x": -11,
      "y": 11,
      "z": -2,
      "name": "Rock_Calcite_Brick_Stairs",
      "rotation": 9
    },
    {
      "x": -11,
      "y": 0,
      "z": -1,
      "name": "*Rock_Calcite_Brick_Stairs_State_Definitions_Corner_Left",
      "rotation": 3
    },
    {
      "x": -11,
      "y": 4,
      "z": -1,
      "name": "*Rock_Calcite_Brick_Stairs_State_Definitions_Corner_Left",
      "rotation": 10
    },
    {
      "x": -11,
      "y": 5,
      "z": -1,
      "name": "Rock_Calcite_Brick"
    },
    {
      "x": -11,
      "y": 6,
      "z": -1,
      "name": "Rock_Calcite_Brick_Decorative"
    },
    {
      "x": -11,
      "y": 7,
      "z": -1,
      "name": "*Rock_Calcite_Brick_Stairs_State_Definitions_Corner_Right"
    },
    {
      "x": -11,
      "y": 8,
      "z": -1,
      "name": "Rock_Calcite_Brick_Stairs",
      "rotation": 9
    },
    {
      "x": -11,
      "y": 9,
      "z": -1,
      "name": "Rock_Calcite_Brick_Beam"
    },
    {
      "x": -11,
      "y": 10,
      "z": -1,
      "name": "Rock_Calcite_Brick_Stairs",
      "rotation": 9
    },
    {
      "x": -11,
      "y": 11,
      "z": -1,
      "name": "Rock_Calcite_Brick_Stairs",
      "rotation": 9
    },
    {
      "x": -11,
      "y": 5,
      "z": 0,
      "name": "Rock_Calcite_Brick_Stairs",
      "rotation": 10
    },
    {
      "x": -11,
      "y": 6,
      "z": 0,
      "name": "Rock_Calcite_Brick_Decorative"
    },
    {
      "x": -11,
      "y": 7,
      "z": 0,
      "name": "Rock_Calcite_Brick_Beam"
    },
    {
      "x": -11,
      "y": 8,
      "z": 0,
      "name": "Rock_Calcite_Brick_Stairs",
      "rotation": 9
    },
    {
      "x": -11,
      "y": 9,
      "z": 0,
      "name": "Rock_Calcite_Brick_Beam"
    },
    {
      "x": -11,
      "y": 10,
      "z": 0,
      "name": "Rock_Calcite_Brick_Stairs",
      "rotation": 9
    },
    {
      "x": -11,
      "y": 11,
      "z": 0,
      "name": "Rock_Calcite_Brick_Stairs",
      "rotation": 9
    },
    {
      "x": -11,
      "y": 5,
      "z": 1,
      "name": "Rock_Calcite_Brick_Stairs",
      "rotation": 8
    },
    {
      "x": -11,
      "y": 6,
      "z": 1,
      "name": "Rock_Calcite_Brick_Decorative"
    },
    {
      "x": -11,
      "y": 7,
      "z": 1,
      "name": "Rock_Calcite_Brick_Beam"
    },
    {
      "x": -11,
      "y": 8,
      "z": 1,
      "name": "Rock_Calcite_Brick_Stairs",
      "rotation": 9
    },
    {
      "x": -11,
      "y": 9,
      "z": 1,
      "name": "Rock_Calcite_Brick_Beam"
    },
    {
      "x": -11,
      "y": 10,
      "z": 1,
      "name": "Rock_Calcite_Brick_Stairs",
      "rotation": 9
    },
    {
      "x": -11,
      "y": 11,
      "z": 1,
      "name": "Rock_Calcite_Brick_Stairs",
      "rotation": 9
    },
    {
      "x": -11,
      "y": 0,
      "z": 2,
      "name": "*Rock_Calcite_Brick_Stairs_State_Definitions_Corner_Left",
      "rotation": 2
    },
    {
      "x": -11,
      "y": 4,
      "z": 2,
      "name": "*Rock_Calcite_Brick_Stairs_State_Definitions_Corner_Left",
      "rotation": 9
    },
    {
      "x": -11,
      "y": 5,
      "z": 2,
      "name": "Rock_Calcite_Brick"
    },
    {
      "x": -11,
      "y": 6,
      "z": 2,
      "name": "Rock_Calcite_Brick_Decorative"
    },
    {
      "x": -11,
      "y": 7,
      "z": 2,
      "name": "*Rock_Calcite_Brick_Stairs_State_Definitions_Corner_Left",
      "rotation": 2
    },
    {
      "x": -11,
      "y": 8,
      "z": 2,
      "name": "Rock_Calcite_Brick_Stairs",
      "rotation": 9
    },
    {
      "x": -11,
      "y": 9,
      "z": 2,
      "name": "Rock_Calcite_Brick_Beam"
    },
    {
      "x": -11,
      "y": 10,
      "z": 2,
      "name": "Rock_Calcite_Brick_Stairs",
      "rotation": 9
    },
    {
      "x": -11,
      "y": 11,
      "z": 2,
      "name": "Rock_Calcite_Brick_Stairs",
      "rotation": 9
    },
    {
      "x": -11,
      "y": 0,
      "z": 3,
      "name": "Rock_Calcite_Brick_Stairs",
      "rotation": 3
    },
    {
      "x": -11,
      "y": 4,
      "z": 3,
      "name": "Rock_Calcite_Brick_Stairs",
      "rotation": 9
    },
    {
      "x": -11,
      "y": 5,
      "z": 3,
      "name": "Rock_Calcite_Brick"
    },
    {
      "x": -11,
      "y": 6,
      "z": 3,
      "name": "Rock_Calcite_Brick_Decorative"
    },
    {
      "x": -11,
      "y": 7,
      "z": 3,
      "name": "Rock_Calcite_Brick_Stairs",
      "rotation": 3
    },
    {
      "x": -11,
      "y": 8,
      "z": 3,
      "name": "Rock_Calcite_Brick_Stairs",
      "rotation": 9
    },
    {
      "x": -11,
      "y": 10,
      "z": 3,
      "name": "Rock_Calcite_Brick_Stairs",
      "rotation": 9
    },
    {
      "x": -11,
      "y": 11,
      "z": 3,
      "name": "Rock_Calcite_Brick_Stairs",
      "rotation": 9
    },
    {
      "x": -11,
      "y": 0,
      "z": 4,
      "name": "*Rock_Calcite_Brick_Stairs_State_Definitions_Corner_Right"
    },
    {
      "x": -11,
      "y": 4,
      "z": 4,
      "name": "*Rock_Calcite_Brick_Stairs_State_Definitions_Corner_Left",
      "rotation": 10
    },
    {
      "x": -11,
      "y": 5,
      "z": 4,
      "name": "Rock_Calcite_Brick"
    },
    {
      "x": -11,
      "y": 6,
      "z": 4,
      "name": "Rock_Calcite_Brick_Decorative"
    },
    {
      "x": -11,
      "y": 7,
      "z": 4,
      "name": "*Rock_Calcite_Brick_Stairs_State_Definitions_Corner_Right"
    },
    {
      "x": -11,
      "y": 8,
      "z": 4,
      "name": "*Rock_Calcite_Brick_Stairs_State_Definitions_Corner_Left",
      "rotation": 10
    },
    {
      "x": -11,
      "y": 10,
      "z": 4,
      "name": "*Rock_Calcite_Brick_Stairs_State_Definitions_Corner_Left",
      "rotation": 10
    },
    {
      "x": -11,
      "y": 11,
      "z": 4,
      "name": "*Rock_Calcite_Brick_Stairs_State_Definitions_Corner_Left",
      "rotation": 10
    },
    {
      "x": -10,
      "y": 0,
      "z": -3,
      "name": "Rock_Calcite_Brick_Stairs",
      "rotation": 2
    },
    {
      "x": -10,
      "y": 4,
      "z": -3,
      "name": "Rock_Calcite_Brick_Stairs",
      "rotation": 8
    },
    {
      "x": -10,
      "y": 5,
      "z": -3,
      "name": "Rock_Calcite_Brick"
    },
    {
      "x": -10,
      "y": 6,
      "z": -3,
      "name": "Rock_Calcite_Brick_Decorative"
    },
    {
      "x": -10,
      "y": 7,
      "z": -3,
      "name": "Rock_Calcite_Brick_Stairs",
      "rotation": 2
    },
    {
      "x": -10,
      "y": 8,
      "z": -3,
      "name": "Rock_Calcite_Brick_Stairs",
      "rotation": 8
    },
    {
      "x": -10,
      "y": 10,
      "z": -3,
      "name": "Rock_Calcite_Brick_Stairs",
      "rotation": 8
    },
    {
      "x": -10,
      "y": 11,
      "z": -3,
      "name": "Rock_Calcite_Brick_Stairs",
      "rotation": 8
    },
    {
      "x": -10,
      "y": 0,
      "z": -2,
      "name": "Rock_Calcite_Brick"
    },
    {
      "x": -10,
      "y": 1,
      "z": -2,
      "name": "Rock_Calcite_Brick_Pillar_Base"
    },
    {
      "x": -10,
      "y": 2,
      "z": -2,
      "name": "Rock_Calcite_Brick_Pillar_Middle"
    },
    {
      "x": -10,
      "y": 3,
      "z": -2,
      "name": "Rock_Calcite_Brick_Pillar_Base",
      "rotation": 8
    },
    {
      "x": -10,
      "y": 4,
      "z": -2,
      "name": "Rock_Calcite_Brick"
    },
    {
      "x": -10,
      "y": 5,
      "z": -2,
      "name": "Rock_Calcite_Brick"
    },
    {
      "x": -10,
      "y": 6,
      "z": -2,
      "name": "Rock_Calcite_Brick"
    },
    {
      "x": -10,
      "y": 7,
      "z": -2,
      "name": "Rock_Calcite_Brick"
    },
    {
      "x": -10,
      "y": 8,
      "z": -2,
      "name": "Rock_Calcite_Brick_Pillar_Base"
    },
    {
      "x": -10,
      "y": 9,
      "z": -2,
      "name": "Rock_Calcite_Brick_Pillar_Middle"
    },
    {
      "x": -10,
      "y": 10,
      "z": -2,
      "name": "Rock_Calcite_Brick_Pillar_Base",
      "rotation": 8
    },
    {
      "x": -10,
      "y": 11,
      "z": -2,
      "name": "Rock_Calcite_Brick"
    },
    {
      "x": -10,
      "y": 12,
      "z": -2,
      "name": "Rock_Calcite_Brick_Smooth"
    },
    {
      "x": -10,
      "y": 0,
      "z": -1,
      "name": "Rock_Calcite_Brick_Stairs"
    },
    {
      "x": -10,
      "y": 4,
      "z": -1,
      "name": "Rock_Calcite_Brick_Stairs",
      "rotation": 10
    },
    {
      "x": -10,
      "y": 5,
      "z": -1,
      "name": "Rock_Calcite_Brick"
    },
    {
      "x": -10,
      "y": 6,
      "z": -1,
      "name": "Rock_Calcite_Brick"
    },
    {
      "x": -10,
      "y": 7,
      "z": -1,
      "name": "Rock_Calcite_Brick_Stairs"
    },
    {
      "x": -10,
      "y": 11,
      "z": -1,
      "name": "Rock_Calcite_Brick_Stairs",
      "rotation": 10
    },
    {
      "x": -10,
      "y": 12,
      "z": -1,
      "name": "Rock_Calcite_Brick"
    },
    {
      "x": -10,
      "y": 5,
      "z": 0,
      "name": "Rock_Calcite_Brick_Stairs",
      "rotation": 10
    },
    {
      "x": -10,
      "y": 6,
      "z": 0,
      "name": "Rock_Calcite_Brick"
    },
    {
      "x": -10,
      "y": 11,
      "z": 0,
      "name": "Rock_Calcite_Brick_Smooth_Half",
      "rotation": 8
    },
    {
      "x": -10,
      "y": 12,
      "z": 0,
      "name": "Rock_Calcite_Brick"
    },
    {
      "x": -10,
      "y": 5,
      "z": 1,
      "name": "Rock_Calcite_Brick_Stairs",
      "rotation": 8
    },
    {
      "x": -10,
      "y": 6,
      "z": 1,
      "name": "Rock_Calcite_Brick"
    },
    {
      "x": -10,
      "y": 11,
      "z": 1,
      "name": "Rock_Calcite_Brick_Smooth_Half",
      "rotation": 8
    },
    {
      "x": -10,
      "y": 12,
      "z": 1,
      "name": "Rock_Calcite_Brick"
    },
    {
      "x": -10,
      "y": 0,
      "z": 2,
      "name": "Rock_Calcite_Brick_Stairs",
      "rotation": 2
    },
    {
      "x": -10,
      "y": 4,
      "z": 2,
      "name": "Rock_Calcite_Brick_Stairs",
      "rotation": 8
    },
    {
      "x": -10,
      "y": 5,
      "z": 2,
      "name": "Rock_Calcite_Brick"
    },
    {
      "x": -10,
      "y": 6,
      "z": 2,
      "name": "Rock_Calcite_Brick"
    },
    {
      "x": -10,
      "y": 7,
      "z": 2,
      "name": "Rock_Calcite_Brick_Stairs",
      "rotation": 2
    },
    {
      "x": -10,
      "y": 11,
      "z": 2,
      "name": "Rock_Calcite_Brick_Stairs",
      "rotation": 8
    },
    {
      "x": -10,
      "y": 12,
      "z": 2,
      "name": "Rock_Calcite_Brick_Smooth"
    },
    {
      "x": -10,
      "y": 0,
      "z": 3,
      "name": "Rock_Calcite_Brick"
    },
    {
      "x": -10,
      "y": 1,
      "z": 3,
      "name": "Rock_Calcite_Brick_Pillar_Base"
    },
    {
      "x": -10,
      "y": 2,
      "z": 3,
      "name": "Rock_Calcite_Brick_Pillar_Middle"
    },
    {
      "x": -10,
      "y": 3,
      "z": 3,
      "name": "Rock_Calcite_Brick_Pillar_Base",
      "rotation": 8
    },
    {
      "x": -10,
      "y": 4,
      "z": 3,
      "name": "Rock_Calcite_Brick"
    },
    {
      "x": -10,
      "y": 5,
      "z": 3,
      "name": "Rock_Calcite_Brick"
    },
    {
      "x": -10,
      "y": 6,
      "z": 3,
      "name": "Rock_Calcite_Brick"
    },
    {
      "x": -10,
      "y": 7,
      "z": 3,
      "name": "Rock_Calcite_Brick"
    },
    {
      "x": -10,
      "y": 8,
      "z": 3,
      "name": "Rock_Calcite_Brick_Pillar_Base"
    },
    {
      "x": -10,
      "y": 9,
      "z": 3,
      "name": "Rock_Calcite_Brick_Pillar_Middle"
    },
    {
      "x": -10,
      "y": 10,
      "z": 3,
      "name": "Rock_Calcite_Brick_Pillar_Base",
      "rotation": 8
    },
    {
      "x": -10,
      "y": 11,
      "z": 3,
      "name": "Rock_Calcite_Brick"
    },
    {
      "x": -10,
      "y": 12,
      "z": 3,
      "name": "Rock_Calcite_Brick_Smooth"
    },
    {
      "x": -10,
      "y": 0,
      "z": 4,
      "name": "Rock_Calcite_Brick_Stairs"
    },
    {
      "x": -10,
      "y": 4,
      "z": 4,
      "name": "Rock_Calcite_Brick_Stairs",
      "rotation": 10
    },
    {
      "x": -10,
      "y": 5,
      "z": 4,
      "name": "Rock_Calcite_Brick"
    },
    {
      "x": -10,
      "y": 6,
      "z": 4,
      "name": "Rock_Calcite_Brick_Decorative"
    },
    {
      "x": -10,
      "y": 7,
      "z": 4,
      "name": "Rock_Calcite_Brick_Stairs"
    },
    {
      "x": -10,
      "y": 8,
      "z": 4,
      "name": "Rock_Calcite_Brick_Stairs",
      "rotation": 10
    },
    {
      "x": -10,
      "y": 10,
      "z": 4,
      "name": "Rock_Calcite_Brick_Stairs",
      "rotation": 10
    },
    {
      "x": -10,
      "y": 11,
      "z": 4,
      "name": "Rock_Calcite_Brick_Stairs",
      "rotation": 10
    },
    {
      "x": -9,
      "y": 0,
      "z": -3,
      "name": "*Rock_Calcite_Brick_Stairs_State_Definitions_Corner_Right",
      "rotation": 2
    },
    {
      "x": -9,
      "y": 4,
      "z": -3,
      "name": "*Rock_Calcite_Brick_Stairs_State_Definitions_Corner_Right",
      "rotation": 11
    },
    {
      "x": -9,
      "y": 5,
      "z": -3,
      "name": "Rock_Calcite_Brick"
    },
    {
      "x": -9,
      "y": 6,
      "z": -3,
      "name": "Rock_Calcite_Brick_Decorative"
    },
    {
      "x": -9,
      "y": 7,
      "z": -3,
      "name": "*Rock_Calcite_Brick_Stairs_State_Definitions_Corner_Left",
      "rotation": 1
    },
    {
      "x": -9,
      "y": 8,
      "z": -3,
      "name": "Rock_Calcite_Brick_Stairs",
      "rotation": 8
    },
    {
      "x": -9,
      "y": 9,
      "z": -3,
      "name": "Rock_Calcite_Brick_Beam"
    },
    {
      "x": -9,
      "y": 10,
      "z": -3,
      "name": "Rock_Calcite_Brick_Stairs",
      "rotation": 8
    },
    {
      "x": -9,
      "y": 11,
      "z": -3,
      "name": "*Rock_Calcite_Brick_Stairs_State_Definitions_Corner_Right",
      "rotation": 11
    },
    {
      "x": -9,
      "y": 0,
      "z": -2,
      "name": "Rock_Calcite_Brick_Stairs",
      "rotation": 1
    },
    {
      "x": -9,
      "y": 4,
      "z": -2,
      "name": "Rock_Calcite_Brick_Stairs",
      "rotation": 11
    },
    {
      "x": -9,
      "y": 5,
      "z": -2,
      "name": "Rock_Calcite_Brick"
    },
    {
      "x": -9,
      "y": 6,
      "z": -2,
      "name": "Rock_Calcite_Brick"
    },
    {
      "x": -9,
      "y": 7,
      "z": -2,
      "name": "Rock_Calcite_Brick_Stairs",
      "rotation": 1
    },
    {
      "x": -9,
      "y": 11,
      "z": -2,
      "name": "Rock_Calcite_Brick_Stairs",
      "rotation": 11
    },
    {
      "x": -9,
      "y": 12,
      "z": -2,
      "name": "Rock_Calcite_Brick"
    },
    {
      "x": -9,
      "y": 0,
      "z": -1,
      "name": "*Rock_Calcite_Brick_Stairs_State_Definitions_Corner_Left"
    },
    {
      "x": -9,
      "y": 4,
      "z": -1,
      "name": "*Rock_Calcite_Brick_Stairs_State_Definitions_Corner_Right",
      "rotation": 10
    },
    {
      "x": -9,
      "y": 5,
      "z": -1,
      "name": "Rock_Calcite_Brick"
    },
    {
      "x": -9,
      "y": 6,
      "z": -1,
      "name": "Rock_Calcite_Brick"
    },
    {
      "x": -9,
      "y": 7,
      "z": -1,
      "name": "*Rock_Calcite_Brick_Stairs_State_Definitions_Corner_Right",
      "rotation": 1
    },
    {
      "x": -9,
      "y": 11,
      "z": -1,
      "name": "*Rock_Calcite_Brick_Stairs_State_Definitions_Corner_Right",
      "rotation": 10
    },
    {
      "x": -9,
      "y": 12,
      "z": -1,
      "name": "*Rock_Calcite_Brick_Smooth_Half_State_Definitions_Block"
    },
    {
      "x": -9,
      "y": 13,
      "z": -1,
      "name": "Rock_Calcite_Brick_Beam"
    },
    {
      "x": -9,
      "y": 5,
      "z": 0,
      "name": "Rock_Calcite_Brick_Stairs",
      "rotation": 10
    },
    {
      "x": -9,
      "y": 6,
      "z": 0,
      "name": "Rock_Calcite_Brick"
    },
    {
      "x": -9,
      "y": 12,
      "z": 0,
      "name": "Rock_Calcite_Brick_Smooth_Half"
    },
    {
      "x": -9,
      "y": 5,
      "z": 1,
      "name": "Rock_Calcite_Brick_Stairs",
      "rotation": 8
    },
    {
      "x": -9,
      "y": 6,
      "z": 1,
      "name": "Rock_Calcite_Brick"
    },
    {
      "x": -9,
      "y": 12,
      "z": 1,
      "name": "Rock_Calcite_Brick_Half"
    },
    {
      "x": -9,
      "y": 0,
      "z": 2,
      "name": "*Rock_Calcite_Brick_Stairs_State_Definitions_Corner_Right",
      "rotation": 2
    },
    {
      "x": -9,
      "y": 4,
      "z": 2,
      "name": "*Rock_Calcite_Brick_Stairs_State_Definitions_Corner_Right",
      "rotation": 11
    },
    {
      "x": -9,
      "y": 5,
      "z": 2,
      "name": "Rock_Calcite_Brick"
    },
    {
      "x": -9,
      "y": 6,
      "z": 2,
      "name": "Rock_Calcite_Brick"
    },
    {
      "x": -9,
      "y": 7,
      "z": 2,
      "name": "*Rock_Calcite_Brick_Stairs_State_Definitions_Corner_Right",
      "rotation": 2
    },
    {
      "x": -9,
      "y": 11,
      "z": 2,
      "name": "*Rock_Calcite_Brick_Stairs_State_Definitions_Corner_Right",
      "rotation": 11
    },
    {
      "x": -9,
      "y": 12,
      "z": 2,
      "name": "*Rock_Calcite_Brick_Half_State_Definitions_Block"
    },
    {
      "x": -9,
      "y": 13,
      "z": 2,
      "name": "Rock_Calcite_Brick_Beam"
    },
    {
      "x": -9,
      "y": 0,
      "z": 3,
      "name": "Rock_Calcite_Brick_Stairs",
      "rotation": 1
    },
    {
      "x": -9,
      "y": 4,
      "z": 3,
      "name": "Rock_Calcite_Brick_Stairs",
      "rotation": 11
    },
    {
      "x": -9,
      "y": 5,
      "z": 3,
      "name": "Rock_Calcite_Brick"
    },
    {
      "x": -9,
      "y": 6,
      "z": 3,
      "name": "Rock_Calcite_Brick"
    },
    {
      "x": -9,
      "y": 7,
      "z": 3,
      "name": "Rock_Calcite_Brick_Stairs",
      "rotation": 1
    },
    {
      "x": -9,
      "y": 11,
      "z": 3,
      "name": "Rock_Calcite_Brick_Stairs",
      "rotation": 11
    },
    {
      "x": -9,
      "y": 12,
      "z": 3,
      "name": "Rock_Calcite_Brick_Smooth"
    },
    {
      "x": -9,
      "y": 0,
      "z": 4,
      "name": "*Rock_Calcite_Brick_Stairs_State_Definitions_Corner_Right",
      "rotation": 1
    },
    {
      "x": -9,
      "y": 4,
      "z": 4,
      "name": "*Rock_Calcite_Brick_Stairs_State_Definitions_Corner_Right",
      "rotation": 10
    },
    {
      "x": -9,
      "y": 5,
      "z": 4,
      "name": "Rock_Calcite_Brick"
    },
    {
      "x": -9,
      "y": 6,
      "z": 4,
      "name": "Rock_Calcite_Brick_Decorative"
    },
    {
      "x": -9,
      "y": 7,
      "z": 4,
      "name": "*Rock_Calcite_Brick_Stairs_State_Definitions_Corner_Right",
      "rotation": 1
    },
    {
      "x": -9,
      "y": 8,
      "z": 4,
      "name": "Rock_Calcite_Brick_Stairs",
      "rotation": 10
    },
    {
      "x": -9,
      "y": 9,
      "z": 4,
      "name": "Rock_Calcite_Brick_Beam"
    },
    {
      "x": -9,
      "y": 10,
      "z": 4,
      "name": "Rock_Calcite_Brick_Stairs",
      "rotation": 10
    },
    {
      "x": -9,
      "y": 11,
      "z": 4,
      "name": "Rock_Calcite_Brick_Stairs",
      "rotation": 10
    },
    {
      "x": -8,
      "y": 5,
      "z": -3,
      "name": "Rock_Calcite_Brick_Stairs",
      "rotation": 11
    },
    {
      "x": -8,
      "y": 6,
      "z": -3,
      "name": "Rock_Calcite_Brick_Decorative"
    },
    {
      "x": -8,
      "y": 7,
      "z": -3,
      "name": "*Rock_Calcite_Brick_Stairs_State_Definitions_Corner_Left",
      "rotation": 2
    },
    {
      "x": -8,
      "y": 8,
      "z": -3,
      "name": "Rock_Calcite_Brick_Stairs",
      "rotation": 8
    },
    {
      "x": -8,
      "y": 9,
      "z": -3,
      "name": "Rock_Calcite_Brick_Beam"
    },
    {
      "x": -8,
      "y": 10,
      "z": -3,
      "name": "Rock_Calcite_Brick_Stairs",
      "rotation": 8
    },
    {
      "x": -8,
      "y": 11,
      "z": -3,
      "name": "*Rock_Calcite_Brick_Stairs_State_Definitions_Corner_Left",
      "rotation": 9
    },
    {
      "x": -8,
      "y": 5,
      "z": -2,
      "name": "Rock_Calcite_Brick_Stairs",
      "rotation": 11
    },
    {
      "x": -8,
      "y": 6,
      "z": -2,
      "name": "Rock_Calcite_Brick"
    },
    {
      "x": -8,
      "y": 7,
      "z": -2,
      "name": "Rock_Calcite_Brick_Stairs",
      "rotation": 3
    },
    {
      "x": -8,
      "y": 11,
      "z": -2,
      "name": "Rock_Calcite_Brick_Stairs",
      "rotation": 9
    },
    {
      "x": -8,
      "y": 12,
      "z": -2,
      "name": "Rock_Calcite_Brick"
    },
    {
      "x": -8,
      "y": 5,
      "z": -1,
      "name": "Rock_Calcite_Brick_Stairs",
      "rotation": 11
    },
    {
      "x": -8,
      "y": 6,
      "z": -1,
      "name": "Rock_Calcite_Brick"
    },
    {
      "x": -8,
      "y": 7,
      "z": -1,
      "name": "*Rock_Calcite_Brick_Stairs_State_Definitions_Corner_Right"
    },
    {
      "x": -8,
      "y": 11,
      "z": -1,
      "name": "*Rock_Calcite_Brick_Stairs_State_Definitions_Corner_Right",
      "rotation": 9
    },
    {
      "x": -8,
      "y": 12,
      "z": -1,
      "name": "Rock_Calcite_Brick_Half"
    },
    {
      "x": -8,
      "y": 5,
      "z": 0,
      "name": "*Rock_Calcite_Brick_Stairs_State_Definitions_Corner_Right",
      "rotation": 10
    },
    {
      "x": -8,
      "y": 6,
      "z": 0,
      "name": "Rock_Calcite_Brick"
    },
    {
      "x": -8,
      "y": 12,
      "z": 0,
      "name": "Rock_Calcite_Brick_Half"
    },
    {
      "x": -8,
      "y": 5,
      "z": 1,
      "name": "*Rock_Calcite_Brick_Stairs_State_Definitions_Corner_Left",
      "rotation": 8
    },
    {
      "x": -8,
      "y": 6,
      "z": 1,
      "name": "Rock_Calcite_Brick"
    },
    {
      "x": -8,
      "y": 12,
      "z": 1,
      "name": "Rock_Calcite_Brick_Half"
    },
    {
      "x": -8,
      "y": 5,
      "z": 2,
      "name": "Rock_Calcite_Brick_Stairs",
      "rotation": 11
    },
    {
      "x": -8,
      "y": 6,
      "z": 2,
      "name": "Rock_Calcite_Brick"
    },
    {
      "x": -8,
      "y": 7,
      "z": 2,
      "name": "*Rock_Calcite_Brick_Stairs_State_Definitions_Corner_Right",
      "rotation": 3
    },
    {
      "x": -8,
      "y": 11,
      "z": 2,
      "name": "*Rock_Calcite_Brick_Stairs_State_Definitions_Corner_Right",
      "rotation": 8
    },
    {
      "x": -8,
      "y": 12,
      "z": 2,
      "name": "Rock_Calcite_Brick_Smooth_Half"
    },
    {
      "x": -8,
      "y": 5,
      "z": 3,
      "name": "Rock_Calcite_Brick_Stairs",
      "rotation": 11
    },
    {
      "x": -8,
      "y": 6,
      "z": 3,
      "name": "Rock_Calcite_Brick"
    },
    {
      "x": -8,
      "y": 7,
      "z": 3,
      "name": "Rock_Calcite_Brick_Stairs",
      "rotation": 3
    },
    {
      "x": -8,
      "y": 11,
      "z": 3,
      "name": "Rock_Calcite_Brick_Stairs",
      "rotation": 9
    },
    {
      "x": -8,
      "y": 12,
      "z": 3,
      "name": "Rock_Calcite_Brick"
    },
    {
      "x": -8,
      "y": 5,
      "z": 4,
      "name": "Rock_Calcite_Brick_Stairs",
      "rotation": 11
    },
    {
      "x": -8,
      "y": 6,
      "z": 4,
      "name": "Rock_Calcite_Brick_Decorative"
    },
    {
      "x": -8,
      "y": 7,
      "z": 4,
      "name": "*Rock_Calcite_Brick_Stairs_State_Definitions_Corner_Right"
    },
    {
      "x": -8,
      "y": 8,
      "z": 4,
      "name": "Rock_Calcite_Brick_Stairs",
      "rotation": 10
    },
    {
      "x": -8,
      "y": 9,
      "z": 4,
      "name": "Rock_Calcite_Brick_Beam"
    },
    {
      "x": -8,
      "y": 10,
      "z": 4,
      "name": "Rock_Calcite_Brick_Stairs",
      "rotation": 10
    },
    {
      "x": -8,
      "y": 11,
      "z": 4,
      "name": "Rock_Calcite_Brick_Stairs",
      "rotation": 10
    },
    {
      "x": -7,
      "y": 5,
      "z": -3,
      "name": "Rock_Calcite_Brick_Half",
      "rotation": 8
    },
    {
      "x": -7,
      "y": 6,
      "z": -3,
      "name": "Rock_Calcite_Brick_Decorative"
    },
    {
      "x": -7,
      "y": 7,
      "z": -3,
      "name": "Rock_Calcite_Brick_Stairs",
      "rotation": 2
    },
    {
      "x": -7,
      "y": 8,
      "z": -3,
      "name": "Rock_Calcite_Brick_Stairs",
      "rotation": 8
    },
    {
      "x": -7,
      "y": 10,
      "z": -3,
      "name": "Rock_Calcite_Brick_Stairs",
      "rotation": 8
    },
    {
      "x": -7,
      "y": 11,
      "z": -3,
      "name": "Rock_Calcite_Brick_Stairs",
      "rotation": 8
    },
    {
      "x": -7,
      "y": 5,
      "z": -2,
      "name": "Rock_Calcite_Brick_Half",
      "rotation": 8
    },
    {
      "x": -7,
      "y": 6,
      "z": -2,
      "name": "Rock_Calcite_Brick"
    },
    {
      "x": -7,
      "y": 7,
      "z": -2,
      "name": "Rock_Calcite_Brick"
    },
    {
      "x": -7,
      "y": 8,
      "z": -2,
      "name": "Rock_Calcite_Brick_Pillar_Base"
    },
    {
      "x": -7,
      "y": 9,
      "z": -2,
      "name": "Rock_Calcite_Brick_Pillar_Middle"
    },
    {
      "x": -7,
      "y": 10,
      "z": -2,
      "name": "Rock_Calcite_Brick_Pillar_Base",
      "rotation": 8
    },
    {
      "x": -7,
      "y": 11,
      "z": -2,
      "name": "Rock_Calcite_Brick"
    },
    {
      "x": -7,
      "y": 12,
      "z": -2,
      "name": "Rock_Calcite_Brick"
    },
    {
      "x": -7,
      "y": 5,
      "z": -1,
      "name": "Rock_Calcite_Brick_Half",
      "rotation": 8
    },
    {
      "x": -7,
      "y": 6,
      "z": -1,
      "name": "Rock_Calcite_Brick"
    },
    {
      "x": -7,
      "y": 7,
      "z": -1,
      "name": "Rock_Calcite_Brick_Stairs"
    },
    {
      "x": -7,
      "y": 11,
      "z": -1,
      "name": "Rock_Calcite_Brick_Stairs",
      "rotation": 10
    },
    {
      "x": -7,
      "y": 12,
      "z": -1,
      "name": "*Rock_Calcite_Brick_Half_State_Definitions_Block"
    },
    {
      "x": -7,
      "y": 13,
      "z": -1,
      "name": "Rock_Calcite_Brick_Beam"
    },
    {
      "x": -7,
      "y": 5,
      "z": 0,
      "name": "Rock_Calcite_Brick_Half",
      "rotation": 8
    },
    {
      "x": -7,
      "y": 6,
      "z": 0,
      "name": "Rock_Calcite_Brick"
    },
    {
      "x": -7,
      "y": 12,
      "z": 0,
      "name": "Rock_Calcite_Brick_Half"
    },
    {
      "x": -7,
      "y": 5,
      "z": 1,
      "name": "Rock_Calcite_Brick_Half",
      "rotation": 8
    },
    {
      "x": -7,
      "y": 6,
      "z": 1,
      "name": "Rock_Calcite_Brick"
    },
    {
      "x": -7,
      "y": 12,
      "z": 1,
      "name": "Rock_Calcite_Brick_Half"
    },
    {
      "x": -7,
      "y": 5,
      "z": 2,
      "name": "Rock_Calcite_Brick_Half",
      "rotation": 8
    },
    {
      "x": -7,
      "y": 6,
      "z": 2,
      "name": "Rock_Calcite_Brick"
    },
    {
      "x": -7,
      "y": 7,
      "z": 2,
      "name": "Rock_Calcite_Brick_Stairs",
      "rotation": 2
    },
    {
      "x": -7,
      "y": 11,
      "z": 2,
      "name": "Rock_Calcite_Brick_Stairs",
      "rotation": 8
    },
    {
      "x": -7,
      "y": 12,
      "z": 2,
      "name": "*Rock_Calcite_Brick_Smooth_Half_State_Definitions_Block"
    },
    {
      "x": -7,
      "y": 13,
      "z": 2,
      "name": "Rock_Calcite_Brick_Beam"
    },
    {
      "x": -7,
      "y": 5,
      "z": 3,
      "name": "Rock_Calcite_Brick_Half",
      "rotation": 8
    },
    {
      "x": -7,
      "y": 6,
      "z": 3,
      "name": "Rock_Calcite_Brick"
    },
    {
      "x": -7,
      "y": 7,
      "z": 3,
      "name": "Rock_Calcite_Brick"
    },
    {
      "x": -7,
      "y": 8,
      "z": 3,
      "name": "Rock_Calcite_Brick_Pillar_Base"
    },
    {
      "x": -7,
      "y": 9,
      "z": 3,
      "name": "Rock_Calcite_Brick_Pillar_Middle"
    },
    {
      "x": -7,
      "y": 10,
      "z": 3,
      "name": "Rock_Calcite_Brick_Pillar_Base",
      "rotation": 8
    },
    {
      "x": -7,
      "y": 11,
      "z": 3,
      "name": "Rock_Calcite_Brick"
    },
    {
      "x": -7,
      "y": 12,
      "z": 3,
      "name": "Rock_Calcite_Brick"
    },
    {
      "x": -7,
      "y": 5,
      "z": 4,
      "name": "Rock_Calcite_Brick_Half",
      "rotation": 8
    },
    {
      "x": -7,
      "y": 6,
      "z": 4,
      "name": "Rock_Calcite_Brick_Decorative"
    },
    {
      "x": -7,
      "y": 7,
      "z": 4,
      "name": "Rock_Calcite_Brick_Stairs"
    },
    {
      "x": -7,
      "y": 8,
      "z": 4,
      "name": "Rock_Calcite_Brick_Stairs",
      "rotation": 10
    },
    {
      "x": -7,
      "y": 10,
      "z": 4,
      "name": "Rock_Calcite_Brick_Stairs",
      "rotation": 10
    },
    {
      "x": -7,
      "y": 11,
      "z": 4,
      "name": "Rock_Calcite_Brick_Stairs",
      "rotation": 10
    },
    {
      "x": -6,
      "y": 5,
      "z": -3,
      "name": "Rock_Calcite_Brick_Stairs",
      "rotation": 9
    },
    {
      "x": -6,
      "y": 6,
      "z": -3,
      "name": "Rock_Calcite_Brick_Decorative"
    },
    {
      "x": -6,
      "y": 7,
      "z": -3,
      "name": "*Rock_Calcite_Brick_Stairs_State_Definitions_Corner_Left",
      "rotation": 1
    },
    {
      "x": -6,
      "y": 8,
      "z": -3,
      "name": "Rock_Calcite_Brick_Stairs",
      "rotation": 8
    },
    {
      "x": -6,
      "y": 9,
      "z": -3,
      "name": "Rock_Calcite_Brick_Beam"
    },
    {
      "x": -6,
      "y": 10,
      "z": -3,
      "name": "Rock_Calcite_Brick_Stairs",
      "rotation": 8
    },
    {
      "x": -6,
      "y": 11,
      "z": -3,
      "name": "*Rock_Calcite_Brick_Stairs_State_Definitions_Corner_Right",
      "rotation": 11
    },
    {
      "x": -6,
      "y": 5,
      "z": -2,
      "name": "Rock_Calcite_Brick_Stairs",
      "rotation": 9
    },
    {
      "x": -6,
      "y": 6,
      "z": -2,
      "name": "Rock_Calcite_Brick"
    },
    {
      "x": -6,
      "y": 7,
      "z": -2,
      "name": "Rock_Calcite_Brick_Stairs",
      "rotation": 1
    },
    {
      "x": -6,
      "y": 11,
      "z": -2,
      "name": "Rock_Calcite_Brick_Stairs",
      "rotation": 11
    },
    {
      "x": -6,
      "y": 12,
      "z": -2,
      "name": "Rock_Calcite_Brick_Smooth"
    },
    {
      "x": -6,
      "y": 5,
      "z": -1,
      "name": "Rock_Calcite_Brick_Stairs",
      "rotation": 9
    },
    {
      "x": -6,
      "y": 6,
      "z": -1,
      "name": "Rock_Calcite_Brick"
    },
    {
      "x": -6,
      "y": 7,
      "z": -1,
      "name": "*Rock_Calcite_Brick_Stairs_State_Definitions_Corner_Right",
      "rotation": 1
    },
    {
      "x": -6,
      "y": 11,
      "z": -1,
      "name": "*Rock_Calcite_Brick_Stairs_State_Definitions_Corner_Left",
      "rotation": 11
    },
    {
      "x": -6,
      "y": 12,
      "z": -1,
      "name": "Rock_Calcite_Brick_Half"
    },
    {
      "x": -6,
      "y": 5,
      "z": 0,
      "name": "*Rock_Calcite_Brick_Stairs_State_Definitions_Corner_Left",
      "rotation": 10
    },
    {
      "x": -6,
      "y": 6,
      "z": 0,
      "name": "Rock_Calcite_Brick"
    },
    {
      "x": -6,
      "y": 12,
      "z": 0,
      "name": "Rock_Calcite_Brick_Half"
    },
    {
      "x": -6,
      "y": 5,
      "z": 1,
      "name": "*Rock_Calcite_Brick_Stairs_State_Definitions_Corner_Right",
      "rotation": 8
    },
    {
      "x": -6,
      "y": 6,
      "z": 1,
      "name": "Rock_Calcite_Brick"
    },
    {
      "x": -6,
      "y": 12,
      "z": 1,
      "name": "Rock_Calcite_Brick_Smooth_Half"
    },
    {
      "x": -6,
      "y": 5,
      "z": 2,
      "name": "Rock_Calcite_Brick_Stairs",
      "rotation": 9
    },
    {
      "x": -6,
      "y": 6,
      "z": 2,
      "name": "Rock_Calcite_Brick"
    },
    {
      "x": -6,
      "y": 7,
      "z": 2,
      "name": "*Rock_Calcite_Brick_Stairs_State_Definitions_Corner_Right",
      "rotation": 2
    },
    {
      "x": -6,
      "y": 11,
      "z": 2,
      "name": "*Rock_Calcite_Brick_Stairs_State_Definitions_Corner_Right",
      "rotation": 11
    },
    {
      "x": -6,
      "y": 12,
      "z": 2,
      "name": "Rock_Calcite_Brick_Half"
    },
    {
      "x": -6,
      "y": 5,
      "z": 3,
      "name": "Rock_Calcite_Brick_Stairs",
      "rotation": 9
    },
    {
      "x": -6,
      "y": 6,
      "z": 3,
      "name": "Rock_Calcite_Brick"
    },
    {
      "x": -6,
      "y": 7,
      "z": 3,
      "name": "Rock_Calcite_Brick_Stairs",
      "rotation": 1
    },
    {
      "x": -6,
      "y": 11,
      "z": 3,
      "name": "Rock_Calcite_Brick_Stairs",
      "rotation": 11
    },
    {
      "x": -6,
      "y": 12,
      "z": 3,
      "name": "Rock_Calcite_Brick"
    },
    {
      "x": -6,
      "y": 5,
      "z": 4,
      "name": "Rock_Calcite_Brick_Stairs",
      "rotation": 9
    },
    {
      "x": -6,
      "y": 6,
      "z": 4,
      "name": "Rock_Calcite_Brick_Decorative"
    },
    {
      "x": -6,
      "y": 7,
      "z": 4,
      "name": "*Rock_Calcite_Brick_Stairs_State_Definitions_Corner_Right",
      "rotation": 1
    },
    {
      "x": -6,
      "y": 8,
      "z": 4,
      "name": "Rock_Calcite_Brick_Stairs",
      "rotation": 10
    },
    {
      "x": -6,
      "y": 9,
      "z": 4,
      "name": "Rock_Calcite_Brick_Beam"
    },
    {
      "x": -6,
      "y": 10,
      "z": 4,
      "name": "Rock_Calcite_Brick_Stairs",
      "rotation": 10
    },
    {
      "x": -6,
      "y": 11,
      "z": 4,
      "name": "Rock_Calcite_Brick_Stairs",
      "rotation": 10
    },
    {
      "x": -5,
      "y": 0,
      "z": -3,
      "name": "*Rock_Calcite_Brick_Stairs_State_Definitions_Corner_Left",
      "rotation": 2
    },
    {
      "x": -5,
      "y": 4,
      "z": -3,
      "name": "*Rock_Calcite_Brick_Stairs_State_Definitions_Corner_Left",
      "rotation": 9
    },
    {
      "x": -5,
      "y": 5,
      "z": -3,
      "name": "Rock_Calcite_Brick"
    },
    {
      "x": -5,
      "y": 6,
      "z": -3,
      "name": "Rock_Calcite_Brick_Decorative"
    },
    {
      "x": -5,
      "y": 7,
      "z": -3,
      "name": "*Rock_Calcite_Brick_Stairs_State_Definitions_Corner_Left",
      "rotation": 2
    },
    {
      "x": -5,
      "y": 8,
      "z": -3,
      "name": "Rock_Calcite_Brick_Stairs",
      "rotation": 8
    },
    {
      "x": -5,
      "y": 9,
      "z": -3,
      "name": "Rock_Calcite_Brick_Beam"
    },
    {
      "x": -5,
      "y": 10,
      "z": -3,
      "name": "Rock_Calcite_Brick_Stairs",
      "rotation": 8
    },
    {
      "x": -5,
      "y": 11,
      "z": -3,
      "name": "*Rock_Calcite_Brick_Stairs_State_Definitions_Corner_Left",
      "rotation": 9
    },
    {
      "x": -5,
      "y": 0,
      "z": -2,
      "name": "Rock_Calcite_Brick_Stairs",
      "rotation": 3
    },
    {
      "x": -5,
      "y": 4,
      "z": -2,
      "name": "Rock_Calcite_Brick_Stairs",
      "rotation": 9
    },
    {
      "x": -5,
      "y": 5,
      "z": -2,
      "name": "Rock_Calcite_Brick"
    },
    {
      "x": -5,
      "y": 6,
      "z": -2,
      "name": "Rock_Calcite_Brick"
    },
    {
      "x": -5,
      "y": 7,
      "z": -2,
      "name": "Rock_Calcite_Brick_Stairs",
      "rotation": 3
    },
    {
      "x": -5,
      "y": 11,
      "z": -2,
      "name": "Rock_Calcite_Brick_Stairs",
      "rotation": 9
    },
    {
      "x": -5,
      "y": 12,
      "z": -2,
      "name": "Rock_Calcite_Brick"
    },
    {
      "x": -5,
      "y": 0,
      "z": -1,
      "name": "*Rock_Calcite_Brick_Stairs_State_Definitions_Corner_Right"
    },
    {
      "x": -5,
      "y": 4,
      "z": -1,
      "name": "*Rock_Calcite_Brick_Stairs_State_Definitions_Corner_Left",
      "rotation": 10
    },
    {
      "x": -5,
      "y": 5,
      "z": -1,
      "name": "Rock_Calcite_Brick"
    },
    {
      "x": -5,
      "y": 6,
      "z": -1,
      "name": "Rock_Calcite_Brick"
    },
    {
      "x": -5,
      "y": 7,
      "z": -1,
      "name": "*Rock_Calcite_Brick_Stairs_State_Definitions_Corner_Right"
    },
    {
      "x": -5,
      "y": 11,
      "z": -1,
      "name": "*Rock_Calcite_Brick_Stairs_State_Definitions_Corner_Left",
      "rotation": 10
    },
    {
      "x": -5,
      "y": 12,
      "z": -1,
      "name": "*Rock_Calcite_Brick_Half_State_Definitions_Block"
    },
    {
      "x": -5,
      "y": 13,
      "z": -1,
      "name": "Rock_Calcite_Brick_Beam"
    },
    {
      "x": -5,
      "y": 5,
      "z": 0,
      "name": "Rock_Calcite_Brick_Stairs",
      "rotation": 10
    },
    {
      "x": -5,
      "y": 6,
      "z": 0,
      "name": "Rock_Calcite_Brick"
    },
    {
      "x": -5,
      "y": 12,
      "z": 0,
      "name": "Rock_Calcite_Brick_Smooth_Half"
    },
    {
      "x": -5,
      "y": 5,
      "z": 1,
      "name": "Rock_Calcite_Brick_Stairs",
      "rotation": 8
    },
    {
      "x": -5,
      "y": 6,
      "z": 1,
      "name": "Rock_Calcite_Brick"
    },
    {
      "x": -5,
      "y": 12,
      "z": 1,
      "name": "Rock_Calcite_Brick_Half"
    },
    {
      "x": -5,
      "y": 0,
      "z": 2,
      "name": "*Rock_Calcite_Brick_Stairs_State_Definitions_Corner_Left",
      "rotation": 2
    },
    {
      "x": -5,
      "y": 4,
      "z": 2,
      "name": "*Rock_Calcite_Brick_Stairs_State_Definitions_Corner_Left",
      "rotation": 9
    },
    {
      "x": -5,
      "y": 5,
      "z": 2,
      "name": "Rock_Calcite_Brick"
    },
    {
      "x": -5,
      "y": 6,
      "z": 2,
      "name": "Rock_Calcite_Brick"
    },
    {
      "x": -5,
      "y": 7,
      "z": 2,
      "name": "*Rock_Calcite_Brick_Stairs_State_Definitions_Corner_Right",
      "rotation": 3
    },
    {
      "x": -5,
      "y": 11,
      "z": 2,
      "name": "*Rock_Calcite_Brick_Stairs_State_Definitions_Corner_Left",
      "rotation": 9
    },
    {
      "x": -5,
      "y": 12,
      "z": 2,
      "name": "*Rock_Calcite_Brick_Half_State_Definitions_Block"
    },
    {
      "x": -5,
      "y": 13,
      "z": 2,
      "name": "Rock_Calcite_Brick_Beam"
    },
    {
      "x": -5,
      "y": 0,
      "z": 3,
      "name": "Rock_Calcite_Brick_Stairs",
      "rotation": 3
    },
    {
      "x": -5,
      "y": 4,
      "z": 3,
      "name": "Rock_Calcite_Brick_Stairs",
      "rotation": 9
    },
    {
      "x": -5,
      "y": 5,
      "z": 3,
      "name": "Rock_Calcite_Brick"
    },
    {
      "x": -5,
      "y": 6,
      "z": 3,
      "name": "Rock_Calcite_Brick"
    },
    {
      "x": -5,
      "y": 7,
      "z": 3,
      "name": "Rock_Calcite_Brick_Stairs",
      "rotation": 3
    },
    {
      "x": -5,
      "y": 11,
      "z": 3,
      "name": "Rock_Calcite_Brick_Stairs",
      "rotation": 9
    },
    {
      "x": -5,
      "y": 12,
      "z": 3,
      "name": "Rock_Calcite_Brick_Smooth"
    },
    {
      "x": -5,
      "y": 0,
      "z": 4,
      "name": "*Rock_Calcite_Brick_Stairs_State_Definitions_Corner_Right"
    },
    {
      "x": -5,
      "y": 4,
      "z": 4,
      "name": "*Rock_Calcite_Brick_Stairs_State_Definitions_Corner_Left",
      "rotation": 10
    },
    {
      "x": -5,
      "y": 5,
      "z": 4,
      "name": "Rock_Calcite_Brick"
    },
    {
      "x": -5,
      "y": 6,
      "z": 4,
      "name": "Rock_Calcite_Brick_Decorative"
    },
    {
      "x": -5,
      "y": 7,
      "z": 4,
      "name": "*Rock_Calcite_Brick_Stairs_State_Definitions_Corner_Right"
    },
    {
      "x": -5,
      "y": 8,
      "z": 4,
      "name": "Rock_Calcite_Brick_Stairs",
      "rotation": 10
    },
    {
      "x": -5,
      "y": 9,
      "z": 4,
      "name": "Rock_Calcite_Brick_Beam"
    },
    {
      "x": -5,
      "y": 10,
      "z": 4,
      "name": "Rock_Calcite_Brick_Stairs",
      "rotation": 10
    },
    {
      "x": -5,
      "y": 11,
      "z": 4,
      "name": "Rock_Calcite_Brick_Stairs",
      "rotation": 10
    },
    {
      "x": -4,
      "y": 0,
      "z": -3,
      "name": "Rock_Calcite_Brick_Stairs",
      "rotation": 2
    },
    {
      "x": -4,
      "y": 4,
      "z": -3,
      "name": "Rock_Calcite_Brick_Stairs",
      "rotation": 8
    },
    {
      "x": -4,
      "y": 5,
      "z": -3,
      "name": "Rock_Calcite_Brick"
    },
    {
      "x": -4,
      "y": 6,
      "z": -3,
      "name": "Rock_Calcite_Brick_Decorative"
    },
    {
      "x": -4,
      "y": 7,
      "z": -3,
      "name": "Rock_Calcite_Brick_Stairs",
      "rotation": 2
    },
    {
      "x": -4,
      "y": 8,
      "z": -3,
      "name": "Rock_Calcite_Brick_Stairs",
      "rotation": 8
    },
    {
      "x": -4,
      "y": 10,
      "z": -3,
      "name": "Rock_Calcite_Brick_Stairs",
      "rotation": 8
    },
    {
      "x": -4,
      "y": 11,
      "z": -3,
      "name": "Rock_Calcite_Brick_Stairs",
      "rotation": 8
    },
    {
      "x": -4,
      "y": 0,
      "z": -2,
      "name": "Rock_Calcite_Brick"
    },
    {
      "x": -4,
      "y": 1,
      "z": -2,
      "name": "Rock_Calcite_Brick_Pillar_Base"
    },
    {
      "x": -4,
      "y": 2,
      "z": -2,
      "name": "Rock_Calcite_Brick_Pillar_Middle"
    },
    {
      "x": -4,
      "y": 3,
      "z": -2,
      "name": "Rock_Calcite_Brick_Pillar_Base",
      "rotation": 8
    },
    {
      "x": -4,
      "y": 4,
      "z": -2,
      "name": "Rock_Calcite_Brick"
    },
    {
      "x": -4,
      "y": 5,
      "z": -2,
      "name": "Rock_Calcite_Brick"
    },
    {
      "x": -4,
      "y": 6,
      "z": -2,
      "name": "Rock_Calcite_Brick"
    },
    {
      "x": -4,
      "y": 7,
      "z": -2,
      "name": "Rock_Calcite_Brick"
    },
    {
      "x": -4,
      "y": 8,
      "z": -2,
      "name": "Rock_Calcite_Brick_Pillar_Base"
    },
    {
      "x": -4,
      "y": 9,
      "z": -2,
      "name": "Rock_Calcite_Brick_Pillar_Middle"
    },
    {
      "x": -4,
      "y": 10,
      "z": -2,
      "name": "Rock_Calcite_Brick_Pillar_Base",
      "rotation": 8
    },
    {
      "x": -4,
      "y": 11,
      "z": -2,
      "name": "Rock_Calcite_Brick"
    },
    {
      "x": -4,
      "y": 12,
      "z": -2,
      "name": "Rock_Calcite_Brick_Smooth"
    },
    {
      "x": -4,
      "y": 0,
      "z": -1,
      "name": "Rock_Calcite_Brick_Stairs"
    },
    {
      "x": -4,
      "y": 4,
      "z": -1,
      "name": "Rock_Calcite_Brick_Stairs",
      "rotation": 10
    },
    {
      "x": -4,
      "y": 5,
      "z": -1,
      "name": "Rock_Calcite_Brick"
    },
    {
      "x": -4,
      "y": 6,
      "z": -1,
      "name": "Rock_Calcite_Brick"
    },
    {
      "x": -4,
      "y": 7,
      "z": -1,
      "name": "Rock_Calcite_Brick_Stairs"
    },
    {
      "x": -4,
      "y": 11,
      "z": -1,
      "name": "Rock_Calcite_Brick_Stairs",
      "rotation": 10
    },
    {
      "x": -4,
      "y": 12,
      "z": -1,
      "name": "Rock_Calcite_Brick_Half"
    },
    {
      "x": -4,
      "y": 5,
      "z": 0,
      "name": "Rock_Calcite_Brick_Stairs",
      "rotation": 10
    },
    {
      "x": -4,
      "y": 6,
      "z": 0,
      "name": "Rock_Calcite_Brick"
    },
    {
      "x": -4,
      "y": 12,
      "z": 0,
      "name": "Rock_Calcite_Brick_Smooth_Half"
    },
    {
      "x": -4,
      "y": 5,
      "z": 1,
      "name": "Rock_Calcite_Brick_Stairs",
      "rotation": 8
    },
    {
      "x": -4,
      "y": 6,
      "z": 1,
      "name": "Rock_Calcite_Brick"
    },
    {
      "x": -4,
      "y": 12,
      "z": 1,
      "name": "Rock_Calcite_Brick_Smooth_Half"
    },
    {
      "x": -4,
      "y": 0,
      "z": 2,
      "name": "Rock_Calcite_Brick_Stairs",
      "rotation": 2
    },
    {
      "x": -4,
      "y": 4,
      "z": 2,
      "name": "Rock_Calcite_Brick_Stairs",
      "rotation": 8
    },
    {
      "x": -4,
      "y": 5,
      "z": 2,
      "name": "Rock_Calcite_Brick"
    },
    {
      "x": -4,
      "y": 6,
      "z": 2,
      "name": "Rock_Calcite_Brick"
    },
    {
      "x": -4,
      "y": 7,
      "z": 2,
      "name": "Rock_Calcite_Brick_Stairs",
      "rotation": 2
    },
    {
      "x": -4,
      "y": 11,
      "z": 2,
      "name": "Rock_Calcite_Brick_Stairs",
      "rotation": 8
    },
    {
      "x": -4,
      "y": 12,
      "z": 2,
      "name": "Rock_Calcite_Brick_Half"
    },
    {
      "x": -4,
      "y": 0,
      "z": 3,
      "name": "Rock_Calcite_Brick"
    },
    {
      "x": -4,
      "y": 1,
      "z": 3,
      "name": "Rock_Calcite_Brick_Pillar_Base"
    },
    {
      "x": -4,
      "y": 2,
      "z": 3,
      "name": "Rock_Calcite_Brick_Pillar_Middle"
    },
    {
      "x": -4,
      "y": 3,
      "z": 3,
      "name": "Rock_Calcite_Brick_Pillar_Base",
      "rotation": 8
    },
    {
      "x": -4,
      "y": 4,
      "z": 3,
      "name": "Rock_Calcite_Brick"
    },
    {
      "x": -4,
      "y": 5,
      "z": 3,
      "name": "Rock_Calcite_Brick"
    },
    {
      "x": -4,
      "y": 6,
      "z": 3,
      "name": "Rock_Calcite_Brick"
    },
    {
      "x": -4,
      "y": 7,
      "z": 3,
      "name": "Rock_Calcite_Brick"
    },
    {
      "x": -4,
      "y": 8,
      "z": 3,
      "name": "Rock_Calcite_Brick_Pillar_Base"
    },
    {
      "x": -4,
      "y": 9,
      "z": 3,
      "name": "Rock_Calcite_Brick_Pillar_Middle"
    },
    {
      "x": -4,
      "y": 10,
      "z": 3,
      "name": "Rock_Calcite_Brick_Pillar_Base",
      "rotation": 8
    },
    {
      "x": -4,
      "y": 11,
      "z": 3,
      "name": "Rock_Calcite_Brick"
    },
    {
      "x": -4,
      "y": 12,
      "z": 3,
      "name": "Rock_Calcite_Brick_Smooth"
    },
    {
      "x": -4,
      "y": 0,
      "z": 4,
      "name": "Rock_Calcite_Brick_Stairs"
    },
    {
      "x": -4,
      "y": 4,
      "z": 4,
      "name": "Rock_Calcite_Brick_Stairs",
      "rotation": 10
    },
    {
      "x": -4,
      "y": 5,
      "z": 4,
      "name": "Rock_Calcite_Brick"
    },
    {
      "x": -4,
      "y": 6,
      "z": 4,
      "name": "Rock_Calcite_Brick_Decorative"
    },
    {
      "x": -4,
      "y": 7,
      "z": 4,
      "name": "Rock_Calcite_Brick_Stairs"
    },
    {
      "x": -4,
      "y": 8,
      "z": 4,
      "name": "Rock_Calcite_Brick_Stairs",
      "rotation": 10
    },
    {
      "x": -4,
      "y": 10,
      "z": 4,
      "name": "Rock_Calcite_Brick_Stairs",
      "rotation": 10
    },
    {
      "x": -4,
      "y": 11,
      "z": 4,
      "name": "Rock_Calcite_Brick_Stairs",
      "rotation": 10
    },
    {
      "x": -3,
      "y": 0,
      "z": -3,
      "name": "*Rock_Calcite_Brick_Stairs_State_Definitions_Corner_Right",
      "rotation": 2
    },
    {
      "x": -3,
      "y": 4,
      "z": -3,
      "name": "*Rock_Calcite_Brick_Stairs_State_Definitions_Corner_Right",
      "rotation": 11
    },
    {
      "x": -3,
      "y": 5,
      "z": -3,
      "name": "Rock_Calcite_Brick"
    },
    {
      "x": -3,
      "y": 6,
      "z": -3,
      "name": "Rock_Calcite_Brick_Decorative"
    },
    {
      "x": -3,
      "y": 7,
      "z": -3,
      "name": "*Rock_Calcite_Brick_Stairs_State_Definitions_Corner_Right",
      "rotation": 2
    },
    {
      "x": -3,
      "y": 8,
      "z": -3,
      "name": "Rock_Calcite_Brick_Stairs",
      "rotation": 8
    },
    {
      "x": -3,
      "y": 9,
      "z": -3,
      "name": "Rock_Calcite_Brick_Beam"
    },
    {
      "x": -3,
      "y": 10,
      "z": -3,
      "name": "Rock_Calcite_Brick_Stairs",
      "rotation": 8
    },
    {
      "x": -3,
      "y": 11,
      "z": -3,
      "name": "*Rock_Calcite_Brick_Stairs_State_Definitions_Corner_Right",
      "rotation": 11
    },
    {
      "x": -3,
      "y": 14,
      "z": -3,
      "name": "Rock_Calcite_Brick_Half",
      "rotation": 7
    },
    {
      "x": -3,
      "y": 0,
      "z": -2,
      "name": "Rock_Calcite_Brick_Stairs",
      "rotation": 1
    },
    {
      "x": -3,
      "y": 4,
      "z": -2,
      "name": "Rock_Calcite_Brick_Stairs",
      "rotation": 11
    },
    {
      "x": -3,
      "y": 5,
      "z": -2,
      "name": "Rock_Calcite_Brick"
    },
    {
      "x": -3,
      "y": 6,
      "z": -2,
      "name": "Rock_Calcite_Brick"
    },
    {
      "x": -3,
      "y": 7,
      "z": -2,
      "name": "Rock_Calcite_Brick_Stairs",
      "rotation": 1
    },
    {
      "x": -3,
      "y": 11,
      "z": -2,
      "name": "Rock_Calcite_Brick_Stairs",
      "rotation": 11
    },
    {
      "x": -3,
      "y": 12,
      "z": -2,
      "name": "Rock_Calcite_Brick_Smooth"
    },
    {
      "x": -3,
      "y": 14,
      "z": -2,
      "name": "Rock_Calcite_Brick_Half",
      "rotation": 7
    },
    {
      "x": -3,
      "y": 0,
      "z": -1,
      "name": "*Rock_Calcite_Brick_Stairs_State_Definitions_Corner_Right",
      "rotation": 1
    },
    {
      "x": -3,
      "y": 4,
      "z": -1,
      "name": "*Rock_Calcite_Brick_Stairs_State_Definitions_Corner_Right",
      "rotation": 10
    },
    {
      "x": -3,
      "y": 5,
      "z": -1,
      "name": "Rock_Calcite_Brick"
    },
    {
      "x": -3,
      "y": 6,
      "z": -1,
      "name": "Rock_Calcite_Brick"
    },
    {
      "x": -3,
      "y": 7,
      "z": -1,
      "name": "*Rock_Calcite_Brick_Stairs_State_Definitions_Corner_Right",
      "rotation": 1
    },
    {
      "x": -3,
      "y": 11,
      "z": -1,
      "name": "*Rock_Calcite_Brick_Stairs_State_Definitions_Corner_Right",
      "rotation": 10
    },
    {
      "x": -3,
      "y": 12,
      "z": -1,
      "name": "*Rock_Calcite_Brick_Smooth_Half_State_Definitions_Block"
    },
    {
      "x": -3,
      "y": 13,
      "z": -1,
      "name": "Rock_Calcite_Brick_Beam"
    },
    {
      "x": -3,
      "y": 14,
      "z": -1,
      "name": "Rock_Calcite_Brick_Half",
      "rotation": 7
    },
    {
      "x": -3,
      "y": 5,
      "z": 0,
      "name": "Rock_Calcite_Brick_Stairs",
      "rotation": 10
    },
    {
      "x": -3,
      "y": 6,
      "z": 0,
      "name": "Rock_Calcite_Brick"
    },
    {
      "x": -3,
      "y": 11,
      "z": 0,
      "name": "Rock_Calcite_Brick_Smooth_Half",
      "rotation": 8
    },
    {
      "x": -3,
      "y": 12,
      "z": 0,
      "name": "Rock_Calcite_Brick_Half"
    },
    {
      "x": -3,
      "y": 14,
      "z": 0,
      "name": "Rock_Calcite_Brick_Half",
      "rotation": 7
    },
    {
      "x": -3,
      "y": 5,
      "z": 1,
      "name": "Rock_Calcite_Brick_Stairs",
      "rotation": 8
    },
    {
      "x": -3,
      "y": 6,
      "z": 1,
      "name": "Rock_Calcite_Brick"
    },
    {
      "x": -3,
      "y": 11,
      "z": 1,
      "name": "Rock_Calcite_Brick_Smooth_Half",
      "rotation": 8
    },
    {
      "x": -3,
      "y": 12,
      "z": 1,
      "name": "Rock_Calcite_Brick_Smooth_Half"
    },
    {
      "x": -3,
      "y": 14,
      "z": 1,
      "name": "Rock_Calcite_Brick_Smooth_Half",
      "rotation": 7
    },
    {
      "x": -3,
      "y": 0,
      "z": 2,
      "name": "*Rock_Calcite_Brick_Stairs_State_Definitions_Corner_Right",
      "rotation": 2
    },
    {
      "x": -3,
      "y": 4,
      "z": 2,
      "name": "*Rock_Calcite_Brick_Stairs_State_Definitions_Corner_Right",
      "rotation": 11
    },
    {
      "x": -3,
      "y": 5,
      "z": 2,
      "name": "Rock_Calcite_Brick"
    },
    {
      "x": -3,
      "y": 6,
      "z": 2,
      "name": "Rock_Calcite_Brick"
    },
    {
      "x": -3,
      "y": 7,
      "z": 2,
      "name": "*Rock_Calcite_Brick_Stairs_State_Definitions_Corner_Left",
      "rotation": 1
    },
    {
      "x": -3,
      "y": 11,
      "z": 2,
      "name": "*Rock_Calcite_Brick_Stairs_State_Definitions_Corner_Right",
      "rotation": 11
    },
    {
      "x": -3,
      "y": 12,
      "z": 2,
      "name": "*Rock_Calcite_Brick_Smooth_Half_State_Definitions_Block"
    },
    {
      "x": -3,
      "y": 13,
      "z": 2,
      "name": "Rock_Calcite_Brick_Beam"
    },
    {
      "x": -3,
      "y": 14,
      "z": 2,
      "name": "Rock_Calcite_Brick_Smooth_Half",
      "rotation": 7
    },
    {
      "x": -3,
      "y": 0,
      "z": 3,
      "name": "Rock_Calcite_Brick_Stairs",
      "rotation": 1
    },
    {
      "x": -3,
      "y": 4,
      "z": 3,
      "name": "Rock_Calcite_Brick_Stairs",
      "rotation": 11
    },
    {
      "x": -3,
      "y": 5,
      "z": 3,
      "name": "Rock_Calcite_Brick"
    },
    {
      "x": -3,
      "y": 6,
      "z": 3,
      "name": "Rock_Calcite_Brick"
    },
    {
      "x": -3,
      "y": 7,
      "z": 3,
      "name": "Rock_Calcite_Brick_Stairs",
      "rotation": 1
    },
    {
      "x": -3,
      "y": 11,
      "z": 3,
      "name": "Rock_Calcite_Brick_Stairs",
      "rotation": 11
    },
    {
      "x": -3,
      "y": 12,
      "z": 3,
      "name": "Rock_Calcite_Brick"
    },
    {
      "x": -3,
      "y": 14,
      "z": 3,
      "name": "Rock_Calcite_Brick_Smooth_Half",
      "rotation": 7
    },
    {
      "x": -3,
      "y": 0,
      "z": 4,
      "name": "*Rock_Calcite_Brick_Stairs_State_Definitions_Corner_Right",
      "rotation": 1
    },
    {
      "x": -3,
      "y": 4,
      "z": 4,
      "name": "*Rock_Calcite_Brick_Stairs_State_Definitions_Corner_Right",
      "rotation": 10
    },
    {
      "x": -3,
      "y": 5,
      "z": 4,
      "name": "Rock_Calcite_Brick"
    },
    {
      "x": -3,
      "y": 6,
      "z": 4,
      "name": "Rock_Calcite_Brick_Decorative"
    },
    {
      "x": -3,
      "y": 7,
      "z": 4,
      "name": "*Rock_Calcite_Brick_Stairs_State_Definitions_Corner_Right",
      "rotation": 1
    },
    {
      "x": -3,
      "y": 8,
      "z": 4,
      "name": "Rock_Calcite_Brick_Stairs",
      "rotation": 10
    },
    {
      "x": -3,
      "y": 9,
      "z": 4,
      "name": "Rock_Calcite_Brick_Beam"
    },
    {
      "x": -3,
      "y": 10,
      "z": 4,
      "name": "Rock_Calcite_Brick_Stairs",
      "rotation": 10
    },
    {
      "x": -3,
      "y": 11,
      "z": 4,
      "name": "*Rock_Calcite_Brick_Stairs_State_Definitions_Corner_Right",
      "rotation": 10
    },
    {
      "x": -3,
      "y": 14,
      "z": 4,
      "name": "Rock_Calcite_Brick_Smooth_Half",
      "rotation": 7
    },
    {
      "x": -2,
      "y": 14,
      "z": -4,
      "name": "Rock_Calcite_Brick_Half",
      "rotation": 6
    },
    {
      "x": -2,
      "y": 5,
      "z": -3,
      "name": "Rock_Calcite_Brick_Stairs",
      "rotation": 11
    },
    {
      "x": -2,
      "y": 6,
      "z": -3,
      "name": "Rock_Calcite_Brick_Decorative"
    },
    {
      "x": -2,
      "y": 7,
      "z": -3,
      "name": "Rock_Calcite_Brick"
    },
    {
      "x": -2,
      "y": 8,
      "z": -3,
      "name": "Rock_Calcite_Brick_Pillar_Base"
    },
    {
      "x": -2,
      "y": 9,
      "z": -3,
      "name": "Rock_Calcite_Brick_Pillar_Middle"
    },
    {
      "x": -2,
      "y": 10,
      "z": -3,
      "name": "Rock_Calcite_Brick_Pillar_Middle"
    },
    {
      "x": -2,
      "y": 11,
      "z": -3,
      "name": "Rock_Calcite_Brick_Pillar_Middle"
    },
    {
      "x": -2,
      "y": 12,
      "z": -3,
      "name": "Rock_Calcite_Brick_Pillar_Base",
      "rotation": 8
    },
    {
      "x": -2,
      "y": 13,
      "z": -3,
      "name": "Rock_Calcite_Brick"
    },
    {
      "x": -2,
      "y": 14,
      "z": -3,
      "name": "Rock_Calcite_Brick"
    },
    {
      "x": -2,
      "y": 15,
      "z": -3,
      "name": "Rock_Calcite_Brick_Beam"
    },
    {
      "x": -2,
      "y": 16,
      "z": -3,
      "name": "Rock_Calcite_Brick_Beam"
    },
    {
      "x": -2,
      "y": 5,
      "z": -2,
      "name": "Rock_Calcite_Brick_Stairs",
      "rotation": 11
    },
    {
      "x": -2,
      "y": 6,
      "z": -2,
      "name": "Rock_Calcite_Brick"
    },
    {
      "x": -2,
      "y": 7,
      "z": -2,
      "name": "Rock_Calcite_Brick"
    },
    {
      "x": -2,
      "y": 8,
      "z": -2,
      "name": "Rock_Calcite_Brick"
    },
    {
      "x": -2,
      "y": 9,
      "z": -2,
      "name": "Rock_Calcite_Brick"
    },
    {
      "x": -2,
      "y": 10,
      "z": -2,
      "name": "Rock_Calcite_Brick"
    },
    {
      "x": -2,
      "y": 11,
      "z": -2,
      "name": "Rock_Calcite_Brick"
    },
    {
      "x": -2,
      "y": 12,
      "z": -2,
      "name": "Rock_Calcite_Brick"
    },
    {
      "x": -2,
      "y": 13,
      "z": -2,
      "name": "Rock_Calcite_Brick"
    },
    {
      "x": -2,
      "y": 14,
      "z": -2,
      "name": "Rock_Calcite_Brick"
    },
    {
      "x": -2,
      "y": 15,
      "z": -2,
      "name": "Rock_Calcite_Brick_Stairs",
      "rotation": 3
    },
    {
      "x": -2,
      "y": 5,
      "z": -1,
      "name": "Rock_Calcite_Brick_Stairs",
      "rotation": 11
    },
    {
      "x": -2,
      "y": 6,
      "z": -1,
      "name": "Rock_Calcite_Brick"
    },
    {
      "x": -2,
      "y": 7,
      "z": -1,
      "name": "Rock_Calcite_Brick_Stairs"
    },
    {
      "x": -2,
      "y": 9,
      "z": -1,
      "name": "Rock_Calcite_Brick_Stairs",
      "rotation": 10
    },
    {
      "x": -2,
      "y": 10,
      "z": -1,
      "name": "Rock_Calcite_Brick_Smooth"
    },
    {
      "x": -2,
      "y": 11,
      "z": -1,
      "name": "Rock_Calcite_Brick"
    },
    {
      "x": -2,
      "y": 12,
      "z": -1,
      "name": "Rock_Calcite_Brick_Smooth"
    },
    {
      "x": -2,
      "y": 13,
      "z": -1,
      "name": "Rock_Calcite_Brick_Smooth"
    },
    {
      "x": -2,
      "y": 14,
      "z": -1,
      "name": "Rock_Calcite_Brick"
    },
    {
      "x": -2,
      "y": 15,
      "z": -1,
      "name": "Rock_Calcite_Brick_Stairs",
      "rotation": 3
    },
    {
      "x": -2,
      "y": 5,
      "z": 0,
      "name": "*Rock_Calcite_Brick_Stairs_State_Definitions_Corner_Right",
      "rotation": 10
    },
    {
      "x": -2,
      "y": 6,
      "z": 0,
      "name": "Rock_Calcite_Brick"
    },
    {
      "x": -2,
      "y": 10,
      "z": 0,
      "name": "Rock_Calcite_Brick_Stairs",
      "rotation": 10
    },
    {
      "x": -2,
      "y": 11,
      "z": 0,
      "name": "Rock_Calcite_Brick_Smooth"
    },
    {
      "x": -2,
      "y": 12,
      "z": 0,
      "name": "Rock_Calcite_Brick"
    },
    {
      "x": -2,
      "y": 13,
      "z": 0,
      "name": "Rock_Calcite_Brick"
    },
    {
      "x": -2,
      "y": 14,
      "z": 0,
      "name": "Rock_Calcite_Brick_Smooth"
    },
    {
      "x": -2,
      "y": 15,
      "z": 0,
      "name": "Rock_Calcite_Brick_Stairs",
      "rotation": 3
    },
    {
      "x": -2,
      "y": 5,
      "z": 1,
      "name": "*Rock_Calcite_Brick_Stairs_State_Definitions_Corner_Left",
      "rotation": 8
    },
    {
      "x": -2,
      "y": 6,
      "z": 1,
      "name": "Rock_Calcite_Brick"
    },
    {
      "x": -2,
      "y": 10,
      "z": 1,
      "name": "Rock_Calcite_Brick_Stairs",
      "rotation": 8
    },
    {
      "x": -2,
      "y": 11,
      "z": 1,
      "name": "Rock_Calcite_Brick_Smooth"
    },
    {
      "x": -2,
      "y": 12,
      "z": 1,
      "name": "Rock_Calcite_Brick"
    },
    {
      "x": -2,
      "y": 13,
      "z": 1,
      "name": "Rock_Calcite_Brick"
    },
    {
      "x": -2,
      "y": 14,
      "z": 1,
      "name": "Rock_Calcite_Brick"
    },
    {
      "x": -2,
      "y": 15,
      "z": 1,
      "name": "Rock_Calcite_Brick_Stairs",
      "rotation": 3
    },
    {
      "x": -2,
      "y": 5,
      "z": 2,
      "name": "Rock_Calcite_Brick_Stairs",
      "rotation": 11
    },
    {
      "x": -2,
      "y": 6,
      "z": 2,
      "name": "Rock_Calcite_Brick"
    },
    {
      "x": -2,
      "y": 7,
      "z": 2,
      "name": "Rock_Calcite_Brick_Stairs",
      "rotation": 2
    },
    {
      "x": -2,
      "y": 9,
      "z": 2,
      "name": "Rock_Calcite_Brick_Stairs",
      "rotation": 8
    },
    {
      "x": -2,
      "y": 10,
      "z": 2,
      "name": "Rock_Calcite_Brick_Smooth"
    },
    {
      "x": -2,
      "y": 11,
      "z": 2,
      "name": "Rock_Calcite_Brick_Smooth"
    },
    {
      "x": -2,
      "y": 12,
      "z": 2,
      "name": "Rock_Calcite_Brick_Smooth"
    },
    {
      "x": -2,
      "y": 13,
      "z": 2,
      "name": "Rock_Calcite_Brick"
    },
    {
      "x": -2,
      "y": 14,
      "z": 2,
      "name": "Rock_Calcite_Brick"
    },
    {
      "x": -2,
      "y": 15,
      "z": 2,
      "name": "Rock_Calcite_Brick_Stairs",
      "rotation": 3
    },
    {
      "x": -2,
      "y": 5,
      "z": 3,
      "name": "Rock_Calcite_Brick_Stairs",
      "rotation": 11
    },
    {
      "x": -2,
      "y": 6,
      "z": 3,
      "name": "Rock_Calcite_Brick"
    },
    {
      "x": -2,
      "y": 7,
      "z": 3,
      "name": "Rock_Calcite_Brick"
    },
    {
      "x": -2,
      "y": 8,
      "z": 3,
      "name": "Rock_Calcite_Brick"
    },
    {
      "x": -2,
      "y": 9,
      "z": 3,
      "name": "Rock_Calcite_Brick"
    },
    {
      "x": -2,
      "y": 10,
      "z": 3,
      "name": "Rock_Calcite_Brick"
    },
    {
      "x": -2,
      "y": 11,
      "z": 3,
      "name": "Rock_Calcite_Brick"
    },
    {
      "x": -2,
      "y": 12,
      "z": 3,
      "name": "Rock_Calcite_Brick"
    },
    {
      "x": -2,
      "y": 13,
      "z": 3,
      "name": "Rock_Calcite_Brick"
    },
    {
      "x": -2,
      "y": 14,
      "z": 3,
      "name": "Rock_Calcite_Brick"
    },
    {
      "x": -2,
      "y": 15,
      "z": 3,
      "name": "Rock_Calcite_Brick_Stairs",
      "rotation": 3
    },
    {
      "x": -2,
      "y": 5,
      "z": 4,
      "name": "Rock_Calcite_Brick_Stairs",
      "rotation": 11
    },
    {
      "x": -2,
      "y": 6,
      "z": 4,
      "name": "Rock_Calcite_Brick_Decorative"
    },
    {
      "x": -2,
      "y": 7,
      "z": 4,
      "name": "Rock_Calcite_Brick"
    },
    {
      "x": -2,
      "y": 8,
      "z": 4,
      "name": "Rock_Calcite_Brick_Pillar_Base"
    },
    {
      "x": -2,
      "y": 9,
      "z": 4,
      "name": "Rock_Calcite_Brick_Pillar_Middle"
    },
    {
      "x": -2,
      "y": 10,
      "z": 4,
      "name": "Rock_Calcite_Brick_Pillar_Middle"
    },
    {
      "x": -2,
      "y": 11,
      "z": 4,
      "name": "Rock_Calcite_Brick_Pillar_Middle"
    },
    {
      "x": -2,
      "y": 12,
      "z": 4,
      "name": "Rock_Calcite_Brick_Pillar_Base",
      "rotation": 8
    },
    {
      "x": -2,
      "y": 13,
      "z": 4,
      "name": "Rock_Calcite_Brick"
    },
    {
      "x": -2,
      "y": 14,
      "z": 4,
      "name": "Rock_Calcite_Brick"
    },
    {
      "x": -2,
      "y": 15,
      "z": 4,
      "name": "Rock_Calcite_Brick_Beam"
    },
    {
      "x": -2,
      "y": 16,
      "z": 4,
      "name": "Rock_Calcite_Brick_Beam"
    },
    {
      "x": -2,
      "y": 14,
      "z": 5,
      "name": "Rock_Calcite_Brick_Smooth_Half",
      "rotation": 4
    },
    {
      "x": -1,
      "y": 14,
      "z": -4,
      "name": "Rock_Calcite_Brick_Smooth_Half",
      "rotation": 6
    },
    {
      "x": -1,
      "y": 5,
      "z": -3,
      "name": "Rock_Calcite_Brick_Half",
      "rotation": 8
    },
    {
      "x": -1,
      "y": 6,
      "z": -3,
      "name": "Rock_Calcite_Brick_Decorative"
    },
    {
      "x": -1,
      "y": 7,
      "z": -3,
      "name": "Rock_Calcite_Brick_Stairs",
      "rotation": 1
    },
    {
      "x": -1,
      "y": 13,
      "z": -3,
      "name": "Rock_Calcite_Brick_Stairs",
      "rotation": 11
    },
    {
      "x": -1,
      "y": 14,
      "z": -3,
      "name": "Rock_Calcite_Brick"
    },
    {
      "x": -1,
      "y": 15,
      "z": -3,
      "name": "Rock_Calcite_Brick_Stairs",
      "rotation": 2
    },
    {
      "x": -1,
      "y": 5,
      "z": -2,
      "name": "Rock_Calcite_Brick_Half",
      "rotation": 8
    },
    {
      "x": -1,
      "y": 6,
      "z": -2,
      "name": "Rock_Calcite_Brick"
    },
    {
      "x": -1,
      "y": 7,
      "z": -2,
      "name": "Rock_Calcite_Brick_Decorative"
    },
    {
      "x": -1,
      "y": 8,
      "z": -2,
      "name": "Rock_Calcite_Brick"
    },
    {
      "x": -1,
      "y": 9,
      "z": -2,
      "name": "Rock_Calcite_Brick_Smooth"
    },
    {
      "x": -1,
      "y": 10,
      "z": -2,
      "name": "Rock_Calcite_Brick_Smooth"
    },
    {
      "x": -1,
      "y": 11,
      "z": -2,
      "name": "Rock_Calcite_Brick"
    },
    {
      "x": -1,
      "y": 12,
      "z": -2,
      "name": "Rock_Calcite_Brick"
    },
    {
      "x": -1,
      "y": 13,
      "z": -2,
      "name": "Rock_Calcite_Brick_Smooth"
    },
    {
      "x": -1,
      "y": 14,
      "z": -2,
      "name": "Rock_Calcite_Brick_Beam"
    },
    {
      "x": -1,
      "y": 15,
      "z": -2,
      "name": "Rock_Calcite_Brick_Beam"
    },
    {
      "x": -1,
      "y": 16,
      "z": -2,
      "name": "Rock_Calcite_Brick_Beam"
    },
    {
      "x": -1,
      "y": 17,
      "z": -2,
      "name": "Rock_Calcite_Brick_Beam"
    },
    {
      "x": -1,
      "y": 5,
      "z": -1,
      "name": "Rock_Calcite_Brick_Half",
      "rotation": 8
    },
    {
      "x": -1,
      "y": 6,
      "z": -1,
      "name": "Rock_Calcite_Brick"
    },
    {
      "x": -1,
      "y": 7,
      "z": -1,
      "name": "*Rock_Calcite_Brick_Stairs_State_Definitions_Inverted_Corner_Left",
      "rotation": 3
    },
    {
      "x": -1,
      "y": 14,
      "z": -1,
      "name": "Rock_Calcite_Brick_Stairs",
      "rotation": 3
    },
    {
      "x": -1,
      "y": 5,
      "z": 0,
      "name": "Rock_Calcite_Brick_Half",
      "rotation": 8
    },
    {
      "x": -1,
      "y": 6,
      "z": 0,
      "name": "Rock_Calcite_Brick"
    },
    {
      "x": -1,
      "y": 7,
      "z": 0,
      "name": "Rock_Calcite_Brick_Stairs",
      "rotation": 3
    },
    {
      "x": -1,
      "y": 14,
      "z": 0,
      "name": "Rock_Calcite_Brick_Stairs",
      "rotation": 3
    },
    {
      "x": -1,
      "y": 5,
      "z": 1,
      "name": "Rock_Calcite_Brick_Half",
      "rotation": 8
    },
    {
      "x": -1,
      "y": 6,
      "z": 1,
      "name": "Rock_Calcite_Brick"
    },
    {
      "x": -1,
      "y": 7,
      "z": 1,
      "name": "Rock_Calcite_Brick_Stairs",
      "rotation": 3
    },
    {
      "x": -1,
      "y": 14,
      "z": 1,
      "name": "Rock_Calcite_Brick_Stairs",
      "rotation": 3
    },
    {
      "x": -1,
      "y": 5,
      "z": 2,
      "name": "Rock_Calcite_Brick_Half",
      "rotation": 8
    },
    {
      "x": -1,
      "y": 6,
      "z": 2,
      "name": "Rock_Calcite_Brick"
    },
    {
      "x": -1,
      "y": 7,
      "z": 2,
      "name": "*Rock_Calcite_Brick_Stairs_State_Definitions_Inverted_Corner_Right",
      "rotation": 3
    },
    {
      "x": -1,
      "y": 14,
      "z": 2,
      "name": "Rock_Calcite_Brick_Stairs",
      "rotation": 3
    },
    {
      "x": -1,
      "y": 5,
      "z": 3,
      "name": "Rock_Calcite_Brick_Half",
      "rotation": 8
    },
    {
      "x": -1,
      "y": 6,
      "z": 3,
      "name": "Rock_Calcite_Brick"
    },
    {
      "x": -1,
      "y": 7,
      "z": 3,
      "name": "Rock_Calcite_Brick_Smooth"
    },
    {
      "x": -1,
      "y": 8,
      "z": 3,
      "name": "Rock_Calcite_Brick"
    },
    {
      "x": -1,
      "y": 9,
      "z": 3,
      "name": "Rock_Calcite_Brick_Smooth"
    },
    {
      "x": -1,
      "y": 10,
      "z": 3,
      "name": "Rock_Calcite_Brick_Smooth"
    },
    {
      "x": -1,
      "y": 11,
      "z": 3,
      "name": "Rock_Calcite_Brick"
    },
    {
      "x": -1,
      "y": 12,
      "z": 3,
      "name": "Rock_Calcite_Brick"
    },
    {
      "x": -1,
      "y": 13,
      "z": 3,
      "name": "Rock_Calcite_Brick"
    },
    {
      "x": -1,
      "y": 14,
      "z": 3,
      "name": "Rock_Calcite_Brick_Beam"
    },
    {
      "x": -1,
      "y": 15,
      "z": 3,
      "name": "Rock_Calcite_Brick_Beam"
    },
    {
      "x": -1,
      "y": 16,
      "z": 3,
      "name": "Rock_Calcite_Brick_Beam"
    },
    {
      "x": -1,
      "y": 17,
      "z": 3,
      "name": "Rock_Calcite_Brick_Beam"
    },
    {
      "x": -1,
      "y": 5,
      "z": 4,
      "name": "Rock_Calcite_Brick_Half",
      "rotation": 8
    },
    {
      "x": -1,
      "y": 6,
      "z": 4,
      "name": "Rock_Calcite_Brick_Decorative"
    },
    {
      "x": -1,
      "y": 7,
      "z": 4,
      "name": "Rock_Calcite_Brick_Stairs",
      "rotation": 1
    },
    {
      "x": -1,
      "y": 13,
      "z": 4,
      "name": "Rock_Calcite_Brick_Stairs",
      "rotation": 11
    },
    {
      "x": -1,
      "y": 14,
      "z": 4,
      "name": "Rock_Calcite_Brick"
    },
    {
      "x": -1,
      "y": 15,
      "z": 4,
      "name": "Rock_Calcite_Brick_Stairs"
    },
    {
      "x": -1,
      "y": 14,
      "z": 5,
      "name": "Rock_Calcite_Brick_Half",
      "rotation": 4
    },
    {
      "x": 0,
      "y": 14,
      "z": -4,
      "name": "Rock_Calcite_Brick_Smooth_Half",
      "rotation": 6
    },
    {
      "x": 0,
      "y": 5,
      "z": -3,
      "name": "Rock_Calcite_Brick_Stairs",
      "rotation": 9
    },
    {
      "x": 0,
      "y": 6,
      "z": -3,
      "name": "Rock_Calcite_Brick_Decorative"
    },
    {
      "x": 0,
      "y": 7,
      "z": -3,
      "name": "Rock_Calcite_Brick_Beam"
    },
    {
      "x": 0,
      "y": 8,
      "z": -3,
      "name": "Rock_Calcite_Brick_Beam"
    },
    {
      "x": 0,
      "y": 9,
      "z": -3,
      "name": "Rock_Calcite_Brick_Beam"
    },
    {
      "x": 0,
      "y": 10,
      "z": -3,
      "name": "Rock_Calcite_Brick_Beam"
    },
    {
      "x": 0,
      "y": 11,
      "z": -3,
      "name": "Rock_Calcite_Brick_Beam"
    },
    {
      "x": 0,
      "y": 12,
      "z": -3,
      "name": "Rock_Calcite_Brick_Beam"
    },
    {
      "x": 0,
      "y": 13,
      "z": -3,
      "name": "Rock_Calcite_Brick_Beam"
    },
    {
      "x": 0,
      "y": 14,
      "z": -3,
      "name": "Rock_Calcite_Brick"
    },
    {
      "x": 0,
      "y": 15,
      "z": -3,
      "name": "Rock_Calcite_Brick_Stairs",
      "rotation": 2
    },
    {
      "x": 0,
      "y": 5,
      "z": -2,
      "name": "Rock_Calcite_Brick_Stairs",
      "rotation": 9
    },
    {
      "x": 0,
      "y": 6,
      "z": -2,
      "name": "Rock_Calcite_Brick"
    },
    {
      "x": 0,
      "y": 7,
      "z": -2,
      "name": "Rock_Calcite_Brick_Decorative"
    },
    {
      "x": 0,
      "y": 8,
      "z": -2,
      "name": "Rock_Calcite_Brick"
    },
    {
      "x": 0,
      "y": 12,
      "z": -2,
      "name": "Rock_Calcite_Brick"
    },
    {
      "x": 0,
      "y": 13,
      "z": -2,
      "name": "Rock_Calcite_Brick_Smooth"
    },
    {
      "x": 0,
      "y": 14,
      "z": -2,
      "name": "Rock_Calcite_Brick_Stairs",
      "rotation": 2
    },
    {
      "x": 0,
      "y": 5,
      "z": -1,
      "name": "Rock_Calcite_Brick_Stairs",
      "rotation": 9
    },
    {
      "x": 0,
      "y": 6,
      "z": -1,
      "name": "Rock_Calcite_Brick"
    },
    {
      "x": 0,
      "y": 7,
      "z": -1,
      "name": "Rock_Calcite_Brick_Smooth"
    },
    {
      "x": 0,
      "y": 14,
      "z": -1,
      "name": "Rock_Calcite_Brick_Smooth_Half"
    },
    {
      "x": 0,
      "y": 5,
      "z": 0,
      "name": "*Rock_Calcite_Brick_Stairs_State_Definitions_Corner_Left",
      "rotation": 10
    },
    {
      "x": 0,
      "y": 6,
      "z": 0,
      "name": "Rock_Calcite_Brick"
    },
    {
      "x": 0,
      "y": 7,
      "z": 0,
      "name": "Rock_Calcite_Brick_Smooth"
    },
    {
      "x": 0,
      "y": 14,
      "z": 0,
      "name": "Rock_Calcite_Brick_Smooth_Half"
    },
    {
      "x": 0,
      "y": 5,
      "z": 1,
      "name": "*Rock_Calcite_Brick_Stairs_State_Definitions_Corner_Right",
      "rotation": 8
    },
    {
      "x": 0,
      "y": 6,
      "z": 1,
      "name": "Rock_Calcite_Brick"
    },
    {
      "x": 0,
      "y": 7,
      "z": 1,
      "name": "Rock_Calcite_Brick_Smooth"
    },
    {
      "x": 0,
      "y": 14,
      "z": 1,
      "name": "Rock_Calcite_Brick_Smooth_Half"
    },
    {
      "x": 0,
      "y": 5,
      "z": 2,
      "name": "Rock_Calcite_Brick_Stairs",
      "rotation": 9
    },
    {
      "x": 0,
      "y": 6,
      "z": 2,
      "name": "Rock_Calcite_Brick"
    },
    {
      "x": 0,
      "y": 7,
      "z": 2,
      "name": "Rock_Calcite_Brick"
    },
    {
      "x": 0,
      "y": 14,
      "z": 2,
      "name": "Rock_Calcite_Brick_Smooth_Half"
    },
    {
      "x": 0,
      "y": 5,
      "z": 3,
      "name": "Rock_Calcite_Brick_Stairs",
      "rotation": 9
    },
    {
      "x": 0,
      "y": 6,
      "z": 3,
      "name": "Rock_Calcite_Brick"
    },
    {
      "x": 0,
      "y": 7,
      "z": 3,
      "name": "Rock_Calcite_Brick_Smooth"
    },
    {
      "x": 0,
      "y": 8,
      "z": 3,
      "name": "Rock_Calcite_Brick"
    },
    {
      "x": 0,
      "y": 12,
      "z": 3,
      "name": "Rock_Calcite_Brick"
    },
    {
      "x": 0,
      "y": 13,
      "z": 3,
      "name": "Rock_Calcite_Brick"
    },
    {
      "x": 0,
      "y": 14,
      "z": 3,
      "name": "Rock_Calcite_Brick_Stairs"
    },
    {
      "x": 0,
      "y": 5,
      "z": 4,
      "name": "Rock_Calcite_Brick_Stairs",
      "rotation": 9
    },
    {
      "x": 0,
      "y": 6,
      "z": 4,
      "name": "Rock_Calcite_Brick_Decorative"
    },
    {
      "x": 0,
      "y": 7,
      "z": 4,
      "name": "Rock_Calcite_Brick_Beam"
    },
    {
      "x": 0,
      "y": 8,
      "z": 4,
      "name": "Rock_Calcite_Brick_Beam"
    },
    {
      "x": 0,
      "y": 9,
      "z": 4,
      "name": "Rock_Calcite_Brick_Beam"
    },
    {
      "x": 0,
      "y": 10,
      "z": 4,
      "name": "Rock_Calcite_Brick_Beam"
    },
    {
      "x": 0,
      "y": 11,
      "z": 4,
      "name": "Rock_Calcite_Brick_Beam"
    },
    {
      "x": 0,
      "y": 12,
      "z": 4,
      "name": "Rock_Calcite_Brick_Beam"
    },
    {
      "x": 0,
      "y": 13,
      "z": 4,
      "name": "Rock_Calcite_Brick_Beam"
    },
    {
      "x": 0,
      "y": 14,
      "z": 4,
      "name": "Rock_Calcite_Brick"
    },
    {
      "x": 0,
      "y": 15,
      "z": 4,
      "name": "Rock_Calcite_Brick_Stairs"
    },
    {
      "x": 0,
      "y": 14,
      "z": 5,
      "name": "Rock_Calcite_Brick_Half",
      "rotation": 4
    },
    {
      "x": 1,
      "y": 14,
      "z": -4,
      "name": "Rock_Calcite_Brick_Smooth_Half",
      "rotation": 6
    },
    {
      "x": 1,
      "y": 0,
      "z": -3,
      "name": "*Rock_Calcite_Brick_Stairs_State_Definitions_Corner_Left",
      "rotation": 2
    },
    {
      "x": 1,
      "y": 4,
      "z": -3,
      "name": "*Rock_Calcite_Brick_Stairs_State_Definitions_Corner_Left",
      "rotation": 9
    },
    {
      "x": 1,
      "y": 5,
      "z": -3,
      "name": "Rock_Calcite_Brick"
    },
    {
      "x": 1,
      "y": 6,
      "z": -3,
      "name": "Rock_Calcite_Brick_Decorative"
    },
    {
      "x": 1,
      "y": 7,
      "z": -3,
      "name": "Rock_Calcite_Brick_Beam"
    },
    {
      "x": 1,
      "y": 8,
      "z": -3,
      "name": "Rock_Calcite_Brick_Beam"
    },
    {
      "x": 1,
      "y": 9,
      "z": -3,
      "name": "Rock_Calcite_Brick_Beam"
    },
    {
      "x": 1,
      "y": 10,
      "z": -3,
      "name": "Rock_Calcite_Brick_Beam"
    },
    {
      "x": 1,
      "y": 11,
      "z": -3,
      "name": "Rock_Calcite_Brick_Beam"
    },
    {
      "x": 1,
      "y": 12,
      "z": -3,
      "name": "Rock_Calcite_Brick_Beam"
    },
    {
      "x": 1,
      "y": 13,
      "z": -3,
      "name": "Rock_Calcite_Brick_Beam"
    },
    {
      "x": 1,
      "y": 14,
      "z": -3,
      "name": "Rock_Calcite_Brick"
    },
    {
      "x": 1,
      "y": 15,
      "z": -3,
      "name": "Rock_Calcite_Brick_Stairs",
      "rotation": 2
    },
    {
      "x": 1,
      "y": 0,
      "z": -2,
      "name": "Rock_Calcite_Brick_Stairs",
      "rotation": 3
    },
    {
      "x": 1,
      "y": 4,
      "z": -2,
      "name": "Rock_Calcite_Brick_Stairs",
      "rotation": 9
    },
    {
      "x": 1,
      "y": 5,
      "z": -2,
      "name": "Rock_Calcite_Brick"
    },
    {
      "x": 1,
      "y": 6,
      "z": -2,
      "name": "Rock_Calcite_Brick"
    },
    {
      "x": 1,
      "y": 7,
      "z": -2,
      "name": "Rock_Calcite_Brick_Smooth"
    },
    {
      "x": 1,
      "y": 8,
      "z": -2,
      "name": "Rock_Calcite_Brick_Smooth"
    },
    {
      "x": 1,
      "y": 12,
      "z": -2,
      "name": "Rock_Calcite_Brick_Smooth"
    },
    {
      "x": 1,
      "y": 13,
      "z": -2,
      "name": "Rock_Calcite_Brick_Smooth"
    },
    {
      "x": 1,
      "y": 14,
      "z": -2,
      "name": "Rock_Calcite_Brick_Stairs",
      "rotation": 2
    },
    {
      "x": 1,
      "y": 0,
      "z": -1,
      "name": "*Rock_Calcite_Brick_Stairs_State_Definitions_Corner_Right"
    },
    {
      "x": 1,
      "y": 4,
      "z": -1,
      "name": "*Rock_Calcite_Brick_Stairs_State_Definitions_Corner_Left",
      "rotation": 10
    },
    {
      "x": 1,
      "y": 5,
      "z": -1,
      "name": "Rock_Calcite_Brick"
    },
    {
      "x": 1,
      "y": 6,
      "z": -1,
      "name": "Rock_Calcite_Brick"
    },
    {
      "x": 1,
      "y": 7,
      "z": -1,
      "name": "Rock_Calcite_Brick_Smooth"
    },
    {
      "x": 1,
      "y": 14,
      "z": -1,
      "name": "Rock_Calcite_Brick_Smooth_Half"
    },
    {
      "x": 1,
      "y": 5,
      "z": 0,
      "name": "Rock_Calcite_Brick_Stairs",
      "rotation": 10
    },
    {
      "x": 1,
      "y": 6,
      "z": 0,
      "name": "Rock_Calcite_Brick"
    },
    {
      "x": 1,
      "y": 7,
      "z": 0,
      "name": "Rock_Calcite_Brick_Smooth"
    },
    {
      "x": 1,
      "y": 14,
      "z": 0,
      "name": "Rock_Calcite_Brick_Smooth_Half"
    },
    {
      "x": 1,
      "y": 5,
      "z": 1,
      "name": "Rock_Calcite_Brick_Stairs",
      "rotation": 8
    },
    {
      "x": 1,
      "y": 6,
      "z": 1,
      "name": "Rock_Calcite_Brick"
    },
    {
      "x": 1,
      "y": 7,
      "z": 1,
      "name": "Rock_Calcite_Brick_Smooth"
    },
    {
      "x": 1,
      "y": 14,
      "z": 1,
      "name": "Rock_Calcite_Brick_Smooth_Half"
    },
    {
      "x": 1,
      "y": 0,
      "z": 2,
      "name": "*Rock_Calcite_Brick_Stairs_State_Definitions_Corner_Left",
      "rotation": 2
    },
    {
      "x": 1,
      "y": 4,
      "z": 2,
      "name": "*Rock_Calcite_Brick_Stairs_State_Definitions_Corner_Left",
      "rotation": 9
    },
    {
      "x": 1,
      "y": 5,
      "z": 2,
      "name": "Rock_Calcite_Brick"
    },
    {
      "x": 1,
      "y": 6,
      "z": 2,
      "name": "Rock_Calcite_Brick"
    },
    {
      "x": 1,
      "y": 7,
      "z": 2,
      "name": "Rock_Calcite_Brick"
    },
    {
      "x": 1,
      "y": 14,
      "z": 2,
      "name": "Rock_Calcite_Brick_Smooth_Half"
    },
    {
      "x": 1,
      "y": 0,
      "z": 3,
      "name": "Rock_Calcite_Brick_Stairs",
      "rotation": 3
    },
    {
      "x": 1,
      "y": 4,
      "z": 3,
      "name": "Rock_Calcite_Brick_Stairs",
      "rotation": 9
    },
    {
      "x": 1,
      "y": 5,
      "z": 3,
      "name": "Rock_Calcite_Brick"
    },
    {
      "x": 1,
      "y": 6,
      "z": 3,
      "name": "Rock_Calcite_Brick"
    },
    {
      "x": 1,
      "y": 7,
      "z": 3,
      "name": "Rock_Calcite_Brick_Decorative"
    },
    {
      "x": 1,
      "y": 8,
      "z": 3,
      "name": "Rock_Calcite_Brick_Smooth"
    },
    {
      "x": 1,
      "y": 12,
      "z": 3,
      "name": "Rock_Calcite_Brick_Smooth"
    },
    {
      "x": 1,
      "y": 13,
      "z": 3,
      "name": "Rock_Calcite_Brick_Smooth"
    },
    {
      "x": 1,
      "y": 14,
      "z": 3,
      "name": "Rock_Calcite_Brick_Stairs"
    },
    {
      "x": 1,
      "y": 0,
      "z": 4,
      "name": "*Rock_Calcite_Brick_Stairs_State_Definitions_Corner_Right"
    },
    {
      "x": 1,
      "y": 4,
      "z": 4,
      "name": "*Rock_Calcite_Brick_Stairs_State_Definitions_Corner_Left",
      "rotation": 10
    },
    {
      "x": 1,
      "y": 5,
      "z": 4,
      "name": "Rock_Calcite_Brick"
    },
    {
      "x": 1,
      "y": 6,
      "z": 4,
      "name": "Rock_Calcite_Brick_Decorative"
    },
    {
      "x": 1,
      "y": 7,
      "z": 4,
      "name": "Rock_Calcite_Brick_Beam"
    },
    {
      "x": 1,
      "y": 8,
      "z": 4,
      "name": "Rock_Calcite_Brick_Beam"
    },
    {
      "x": 1,
      "y": 9,
      "z": 4,
      "name": "Rock_Calcite_Brick_Beam"
    },
    {
      "x": 1,
      "y": 10,
      "z": 4,
      "name": "Rock_Calcite_Brick_Beam"
    },
    {
      "x": 1,
      "y": 11,
      "z": 4,
      "name": "Rock_Calcite_Brick_Beam"
    },
    {
      "x": 1,
      "y": 12,
      "z": 4,
      "name": "Rock_Calcite_Brick_Beam"
    },
    {
      "x": 1,
      "y": 13,
      "z": 4,
      "name": "Rock_Calcite_Brick_Beam"
    },
    {
      "x": 1,
      "y": 14,
      "z": 4,
      "name": "Rock_Calcite_Brick"
    },
    {
      "x": 1,
      "y": 15,
      "z": 4,
      "name": "Rock_Calcite_Brick_Stairs"
    },
    {
      "x": 1,
      "y": 14,
      "z": 5,
      "name": "Rock_Calcite_Brick_Smooth_Half",
      "rotation": 4
    },
    {
      "x": 2,
      "y": 14,
      "z": -4,
      "name": "Rock_Calcite_Brick_Half",
      "rotation": 6
    },
    {
      "x": 2,
      "y": 0,
      "z": -3,
      "name": "Rock_Calcite_Brick_Stairs",
      "rotation": 2
    },
    {
      "x": 2,
      "y": 4,
      "z": -3,
      "name": "Rock_Calcite_Brick_Stairs",
      "rotation": 8
    },
    {
      "x": 2,
      "y": 5,
      "z": -3,
      "name": "Rock_Calcite_Brick"
    },
    {
      "x": 2,
      "y": 6,
      "z": -3,
      "name": "Rock_Calcite_Brick_Decorative"
    },
    {
      "x": 2,
      "y": 7,
      "z": -3,
      "name": "Rock_Calcite_Brick_Stairs",
      "rotation": 3
    },
    {
      "x": 2,
      "y": 13,
      "z": -3,
      "name": "Rock_Calcite_Brick_Stairs",
      "rotation": 9
    },
    {
      "x": 2,
      "y": 14,
      "z": -3,
      "name": "Rock_Calcite_Brick"
    },
    {
      "x": 2,
      "y": 15,
      "z": -3,
      "name": "Rock_Calcite_Brick_Stairs",
      "rotation": 2
    },
    {
      "x": 2,
      "y": 0,
      "z": -2,
      "name": "Rock_Calcite_Brick"
    },
    {
      "x": 2,
      "y": 1,
      "z": -2,
      "name": "Rock_Calcite_Brick_Pillar_Base"
    },
    {
      "x": 2,
      "y": 2,
      "z": -2,
      "name": "Rock_Calcite_Brick_Pillar_Middle"
    },
    {
      "x": 2,
      "y": 3,
      "z": -2,
      "name": "Rock_Calcite_Brick_Pillar_Base",
      "rotation": 8
    },
    {
      "x": 2,
      "y": 4,
      "z": -2,
      "name": "Rock_Calcite_Brick"
    },
    {
      "x": 2,
      "y": 5,
      "z": -2,
      "name": "Rock_Calcite_Brick"
    },
    {
      "x": 2,
      "y": 6,
      "z": -2,
      "name": "Rock_Calcite_Brick"
    },
    {
      "x": 2,
      "y": 7,
      "z": -2,
      "name": "Rock_Calcite_Brick"
    },
    {
      "x": 2,
      "y": 8,
      "z": -2,
      "name": "Rock_Calcite_Brick_Smooth"
    },
    {
      "x": 2,
      "y": 9,
      "z": -2,
      "name": "Rock_Calcite_Brick_Smooth"
    },
    {
      "x": 2,
      "y": 10,
      "z": -2,
      "name": "Rock_Calcite_Brick"
    },
    {
      "x": 2,
      "y": 11,
      "z": -2,
      "name": "Rock_Calcite_Brick"
    },
    {
      "x": 2,
      "y": 12,
      "z": -2,
      "name": "Rock_Calcite_Brick"
    },
    {
      "x": 2,
      "y": 13,
      "z": -2,
      "name": "Rock_Calcite_Brick_Smooth"
    },
    {
      "x": 2,
      "y": 14,
      "z": -2,
      "name": "Rock_Calcite_Brick_Stairs",
      "rotation": 2
    },
    {
      "x": 2,
      "y": 0,
      "z": -1,
      "name": "Rock_Calcite_Brick_Stairs"
    },
    {
      "x": 2,
      "y": 4,
      "z": -1,
      "name": "Rock_Calcite_Brick_Stairs",
      "rotation": 10
    },
    {
      "x": 2,
      "y": 5,
      "z": -1,
      "name": "Rock_Calcite_Brick"
    },
    {
      "x": 2,
      "y": 6,
      "z": -1,
      "name": "Rock_Calcite_Brick"
    },
    {
      "x": 2,
      "y": 7,
      "z": -1,
      "name": "Rock_Calcite_Brick_Smooth"
    },
    {
      "x": 2,
      "y": 14,
      "z": -1,
      "name": "Rock_Calcite_Brick_Smooth_Half"
    },
    {
      "x": 2,
      "y": 5,
      "z": 0,
      "name": "Rock_Calcite_Brick_Stairs",
      "rotation": 10
    },
    {
      "x": 2,
      "y": 6,
      "z": 0,
      "name": "Rock_Calcite_Brick"
    },
    {
      "x": 2,
      "y": 7,
      "z": 0,
      "name": "Rock_Calcite_Brick_Smooth"
    },
    {
      "x": 2,
      "y": 14,
      "z": 0,
      "name": "Rock_Calcite_Brick_Smooth_Half"
    },
    {
      "x": 2,
      "y": 5,
      "z": 1,
      "name": "Rock_Calcite_Brick_Stairs",
      "rotation": 8
    },
    {
      "x": 2,
      "y": 6,
      "z": 1,
      "name": "Rock_Calcite_Brick"
    },
    {
      "x": 2,
      "y": 7,
      "z": 1,
      "name": "Rock_Calcite_Brick"
    },
    {
      "x": 2,
      "y": 14,
      "z": 1,
      "name": "Rock_Calcite_Brick_Smooth_Half"
    },
    {
      "x": 2,
      "y": 0,
      "z": 2,
      "name": "Rock_Calcite_Brick_Stairs",
      "rotation": 2
    },
    {
      "x": 2,
      "y": 4,
      "z": 2,
      "name": "Rock_Calcite_Brick_Stairs",
      "rotation": 8
    },
    {
      "x": 2,
      "y": 5,
      "z": 2,
      "name": "Rock_Calcite_Brick"
    },
    {
      "x": 2,
      "y": 6,
      "z": 2,
      "name": "Rock_Calcite_Brick"
    },
    {
      "x": 2,
      "y": 7,
      "z": 2,
      "name": "Rock_Calcite_Brick_Smooth"
    },
    {
      "x": 2,
      "y": 14,
      "z": 2,
      "name": "Rock_Calcite_Brick_Smooth_Half"
    },
    {
      "x": 2,
      "y": 0,
      "z": 3,
      "name": "Rock_Calcite_Brick"
    },
    {
      "x": 2,
      "y": 1,
      "z": 3,
      "name": "Rock_Calcite_Brick_Pillar_Base"
    },
    {
      "x": 2,
      "y": 2,
      "z": 3,
      "name": "Rock_Calcite_Brick_Pillar_Middle"
    },
    {
      "x": 2,
      "y": 3,
      "z": 3,
      "name": "Rock_Calcite_Brick_Pillar_Base",
      "rotation": 8
    },
    {
      "x": 2,
      "y": 4,
      "z": 3,
      "name": "Rock_Calcite_Brick"
    },
    {
      "x": 2,
      "y": 5,
      "z": 3,
      "name": "Rock_Calcite_Brick"
    },
    {
      "x": 2,
      "y": 6,
      "z": 3,
      "name": "Rock_Calcite_Brick"
    },
    {
      "x": 2,
      "y": 7,
      "z": 3,
      "name": "Rock_Calcite_Brick_Smooth"
    },
    {
      "x": 2,
      "y": 8,
      "z": 3,
      "name": "Rock_Calcite_Brick"
    },
    {
      "x": 2,
      "y": 9,
      "z": 3,
      "name": "Rock_Calcite_Brick"
    },
    {
      "x": 2,
      "y": 10,
      "z": 3,
      "name": "Rock_Calcite_Brick"
    },
    {
      "x": 2,
      "y": 11,
      "z": 3,
      "name": "Rock_Calcite_Brick_Smooth"
    },
    {
      "x": 2,
      "y": 12,
      "z": 3,
      "name": "Rock_Calcite_Brick"
    },
    {
      "x": 2,
      "y": 13,
      "z": 3,
      "name": "Rock_Calcite_Brick"
    },
    {
      "x": 2,
      "y": 14,
      "z": 3,
      "name": "Rock_Calcite_Brick_Stairs"
    },
    {
      "x": 2,
      "y": 0,
      "z": 4,
      "name": "Rock_Calcite_Brick_Stairs"
    },
    {
      "x": 2,
      "y": 4,
      "z": 4,
      "name": "Rock_Calcite_Brick_Stairs",
      "rotation": 10
    },
    {
      "x": 2,
      "y": 5,
      "z": 4,
      "name": "Rock_Calcite_Brick"
    },
    {
      "x": 2,
      "y": 6,
      "z": 4,
      "name": "Rock_Calcite_Brick_Decorative"
    },
    {
      "x": 2,
      "y": 7,
      "z": 4,
      "name": "Rock_Calcite_Brick_Stairs",
      "rotation": 3
    },
    {
      "x": 2,
      "y": 13,
      "z": 4,
      "name": "Rock_Calcite_Brick_Stairs",
      "rotation": 9
    },
    {
      "x": 2,
      "y": 14,
      "z": 4,
      "name": "Rock_Calcite_Brick"
    },
    {
      "x": 2,
      "y": 15,
      "z": 4,
      "name": "Rock_Calcite_Brick_Stairs"
    },
    {
      "x": 2,
      "y": 14,
      "z": 5,
      "name": "Rock_Calcite_Brick_Smooth_Half",
      "rotation": 4
    },
    {
      "x": 3,
      "y": 14,
      "z": -4,
      "name": "Rock_Calcite_Brick_Half",
      "rotation": 6
    },
    {
      "x": 3,
      "y": 0,
      "z": -3,
      "name": "*Rock_Calcite_Brick_Stairs_State_Definitions_Corner_Right",
      "rotation": 2
    },
    {
      "x": 3,
      "y": 4,
      "z": -3,
      "name": "*Rock_Calcite_Brick_Stairs_State_Definitions_Corner_Right",
      "rotation": 11
    },
    {
      "x": 3,
      "y": 5,
      "z": -3,
      "name": "Rock_Calcite_Brick"
    },
    {
      "x": 3,
      "y": 6,
      "z": -3,
      "name": "Rock_Calcite_Brick_Decorative"
    },
    {
      "x": 3,
      "y": 7,
      "z": -3,
      "name": "Rock_Calcite_Brick"
    },
    {
      "x": 3,
      "y": 8,
      "z": -3,
      "name": "Rock_Calcite_Brick_Pillar_Base"
    },
    {
      "x": 3,
      "y": 9,
      "z": -3,
      "name": "Rock_Calcite_Brick_Pillar_Middle"
    },
    {
      "x": 3,
      "y": 10,
      "z": -3,
      "name": "Rock_Calcite_Brick_Pillar_Middle"
    },
    {
      "x": 3,
      "y": 11,
      "z": -3,
      "name": "Rock_Calcite_Brick_Pillar_Middle"
    },
    {
      "x": 3,
      "y": 12,
      "z": -3,
      "name": "Rock_Calcite_Brick_Pillar_Base",
      "rotation": 8
    },
    {
      "x": 3,
      "y": 13,
      "z": -3,
      "name": "Rock_Calcite_Brick"
    },
    {
      "x": 3,
      "y": 14,
      "z": -3,
      "name": "Rock_Calcite_Brick"
    },
    {
      "x": 3,
      "y": 15,
      "z": -3,
      "name": "Rock_Calcite_Brick_Stairs",
      "rotation": 2
    },
    {
      "x": 3,
      "y": 0,
      "z": -2,
      "name": "Rock_Calcite_Brick_Stairs",
      "rotation": 1
    },
    {
      "x": 3,
      "y": 4,
      "z": -2,
      "name": "Rock_Calcite_Brick_Stairs",
      "rotation": 11
    },
    {
      "x": 3,
      "y": 5,
      "z": -2,
      "name": "Rock_Calcite_Brick"
    },
    {
      "x": 3,
      "y": 6,
      "z": -2,
      "name": "Rock_Calcite_Brick"
    },
    {
      "x": 3,
      "y": 7,
      "z": -2,
      "name": "Rock_Calcite_Brick_Decorative"
    },
    {
      "x": 3,
      "y": 8,
      "z": -2,
      "name": "Rock_Calcite_Brick"
    },
    {
      "x": 3,
      "y": 9,
      "z": -2,
      "name": "Rock_Calcite_Brick"
    },
    {
      "x": 3,
      "y": 10,
      "z": -2,
      "name": "Rock_Calcite_Brick_Smooth"
    },
    {
      "x": 3,
      "y": 11,
      "z": -2,
      "name": "Rock_Calcite_Brick_Smooth"
    },
    {
      "x": 3,
      "y": 12,
      "z": -2,
      "name": "Rock_Calcite_Brick_Smooth"
    },
    {
      "x": 3,
      "y": 13,
      "z": -2,
      "name": "Rock_Calcite_Brick_Smooth"
    },
    {
      "x": 3,
      "y": 14,
      "z": -2,
      "name": "Rock_Calcite_Brick_Stairs",
      "rotation": 2
    },
    {
      "x": 3,
      "y": 0,
      "z": -1,
      "name": "*Rock_Calcite_Brick_Stairs_State_Definitions_Corner_Right",
      "rotation": 1
    },
    {
      "x": 3,
      "y": 4,
      "z": -1,
      "name": "*Rock_Calcite_Brick_Stairs_State_Definitions_Corner_Right",
      "rotation": 10
    },
    {
      "x": 3,
      "y": 5,
      "z": -1,
      "name": "Rock_Calcite_Brick"
    },
    {
      "x": 3,
      "y": 6,
      "z": -1,
      "name": "Rock_Calcite_Brick"
    },
    {
      "x": 3,
      "y": 7,
      "z": -1,
      "name": "Rock_Calcite_Brick_Smooth"
    },
    {
      "x": 3,
      "y": 14,
      "z": -1,
      "name": "Rock_Calcite_Brick_Smooth_Half"
    },
    {
      "x": 3,
      "y": 5,
      "z": 0,
      "name": "Rock_Calcite_Brick_Stairs",
      "rotation": 10
    },
    {
      "x": 3,
      "y": 6,
      "z": 0,
      "name": "Rock_Calcite_Brick"
    },
    {
      "x": 3,
      "y": 7,
      "z": 0,
      "name": "Rock_Calcite_Brick"
    },
    {
      "x": 3,
      "y": 14,
      "z": 0,
      "name": "Rock_Calcite_Brick_Smooth_Half"
    },
    {
      "x": 3,
      "y": 5,
      "z": 1,
      "name": "Rock_Calcite_Brick_Stairs",
      "rotation": 8
    },
    {
      "x": 3,
      "y": 6,
      "z": 1,
      "name": "Rock_Calcite_Brick"
    },
    {
      "x": 3,
      "y": 7,
      "z": 1,
      "name": "Rock_Calcite_Brick_Smooth"
    },
    {
      "x": 3,
      "y": 14,
      "z": 1,
      "name": "Rock_Calcite_Brick_Smooth_Half"
    },
    {
      "x": 3,
      "y": 0,
      "z": 2,
      "name": "*Rock_Calcite_Brick_Stairs_State_Definitions_Corner_Right",
      "rotation": 2
    },
    {
      "x": 3,
      "y": 4,
      "z": 2,
      "name": "*Rock_Calcite_Brick_Stairs_State_Definitions_Corner_Right",
      "rotation": 11
    },
    {
      "x": 3,
      "y": 5,
      "z": 2,
      "name": "Rock_Calcite_Brick"
    },
    {
      "x": 3,
      "y": 6,
      "z": 2,
      "name": "Rock_Calcite_Brick"
    },
    {
      "x": 3,
      "y": 7,
      "z": 2,
      "name": "Rock_Calcite_Brick_Smooth"
    },
    {
      "x": 3,
      "y": 14,
      "z": 2,
      "name": "Rock_Calcite_Brick_Smooth_Half"
    },
    {
      "x": 3,
      "y": 0,
      "z": 3,
      "name": "Rock_Calcite_Brick_Stairs",
      "rotation": 1
    },
    {
      "x": 3,
      "y": 4,
      "z": 3,
      "name": "Rock_Calcite_Brick_Stairs",
      "rotation": 11
    },
    {
      "x": 3,
      "y": 5,
      "z": 3,
      "name": "Rock_Calcite_Brick"
    },
    {
      "x": 3,
      "y": 6,
      "z": 3,
      "name": "Rock_Calcite_Brick"
    },
    {
      "x": 3,
      "y": 7,
      "z": 3,
      "name": "Rock_Calcite_Brick"
    },
    {
      "x": 3,
      "y": 8,
      "z": 3,
      "name": "Rock_Calcite_Brick"
    },
    {
      "x": 3,
      "y": 9,
      "z": 3,
      "name": "Rock_Calcite_Brick"
    },
    {
      "x": 3,
      "y": 10,
      "z": 3,
      "name": "Rock_Calcite_Brick_Smooth"
    },
    {
      "x": 3,
      "y": 11,
      "z": 3,
      "name": "Rock_Calcite_Brick_Smooth"
    },
    {
      "x": 3,
      "y": 12,
      "z": 3,
      "name": "Rock_Calcite_Brick_Smooth"
    },
    {
      "x": 3,
      "y": 13,
      "z": 3,
      "name": "Rock_Calcite_Brick_Smooth"
    },
    {
      "x": 3,
      "y": 14,
      "z": 3,
      "name": "Rock_Calcite_Brick_Stairs"
    },
    {
      "x": 3,
      "y": 0,
      "z": 4,
      "name": "*Rock_Calcite_Brick_Stairs_State_Definitions_Corner_Right",
      "rotation": 1
    },
    {
      "x": 3,
      "y": 4,
      "z": 4,
      "name": "*Rock_Calcite_Brick_Stairs_State_Definitions_Corner_Right",
      "rotation": 10
    },
    {
      "x": 3,
      "y": 5,
      "z": 4,
      "name": "Rock_Calcite_Brick"
    },
    {
      "x": 3,
      "y": 6,
      "z": 4,
      "name": "Rock_Calcite_Brick_Decorative"
    },
    {
      "x": 3,
      "y": 7,
      "z": 4,
      "name": "Rock_Calcite_Brick"
    },
    {
      "x": 3,
      "y": 8,
      "z": 4,
      "name": "Rock_Calcite_Brick_Pillar_Base"
    },
    {
      "x": 3,
      "y": 9,
      "z": 4,
      "name": "Rock_Calcite_Brick_Pillar_Middle"
    },
    {
      "x": 3,
      "y": 10,
      "z": 4,
      "name": "Rock_Calcite_Brick_Pillar_Middle"
    },
    {
      "x": 3,
      "y": 11,
      "z": 4,
      "name": "Rock_Calcite_Brick_Pillar_Middle"
    },
    {
      "x": 3,
      "y": 12,
      "z": 4,
      "name": "Rock_Calcite_Brick_Pillar_Base",
      "rotation": 8
    },
    {
      "x": 3,
      "y": 13,
      "z": 4,
      "name": "Rock_Calcite_Brick"
    },
    {
      "x": 3,
      "y": 14,
      "z": 4,
      "name": "Rock_Calcite_Brick"
    },
    {
      "x": 3,
      "y": 15,
      "z": 4,
      "name": "Rock_Calcite_Brick_Stairs"
    },
    {
      "x": 3,
      "y": 14,
      "z": 5,
      "name": "Rock_Calcite_Brick_Half",
      "rotation": 4
    },
    {
      "x": 4,
      "y": 14,
      "z": -4,
      "name": "Rock_Calcite_Brick_Half",
      "rotation": 6
    },
    {
      "x": 4,
      "y": 5,
      "z": -3,
      "name": "Rock_Calcite_Brick_Stairs",
      "rotation": 11
    },
    {
      "x": 4,
      "y": 6,
      "z": -3,
      "name": "Rock_Calcite_Brick_Decorative"
    },
    {
      "x": 4,
      "y": 7,
      "z": -3,
      "name": "Rock_Calcite_Brick"
    },
    {
      "x": 4,
      "y": 8,
      "z": -3,
      "name": "Rock_Calcite_Brick_Half"
    },
    {
      "x": 4,
      "y": 12,
      "z": -3,
      "name": "Rock_Calcite_Brick_Half",
      "rotation": 8
    },
    {
      "x": 4,
      "y": 13,
      "z": -3,
      "name": "Rock_Calcite_Brick"
    },
    {
      "x": 4,
      "y": 14,
      "z": -3,
      "name": "Rock_Calcite_Brick"
    },
    {
      "x": 4,
      "y": 15,
      "z": -3,
      "name": "Rock_Calcite_Brick_Stairs",
      "rotation": 2
    },
    {
      "x": 4,
      "y": 5,
      "z": -2,
      "name": "Rock_Calcite_Brick_Stairs",
      "rotation": 11
    },
    {
      "x": 4,
      "y": 6,
      "z": -2,
      "name": "Rock_Calcite_Brick"
    },
    {
      "x": 4,
      "y": 7,
      "z": -2,
      "name": "Rock_Calcite_Brick"
    },
    {
      "x": 4,
      "y": 8,
      "z": -2,
      "name": "Rock_Calcite_Brick_Smooth"
    },
    {
      "x": 4,
      "y": 9,
      "z": -2,
      "name": "Rock_Calcite_Brick"
    },
    {
      "x": 4,
      "y": 10,
      "z": -2,
      "name": "Rock_Calcite_Brick"
    },
    {
      "x": 4,
      "y": 11,
      "z": -2,
      "name": "Rock_Calcite_Brick_Smooth"
    },
    {
      "x": 4,
      "y": 12,
      "z": -2,
      "name": "Rock_Calcite_Brick"
    },
    {
      "x": 4,
      "y": 13,
      "z": -2,
      "name": "Rock_Calcite_Brick"
    },
    {
      "x": 4,
      "y": 14,
      "z": -2,
      "name": "Rock_Calcite_Brick_Stairs",
      "rotation": 2
    },
    {
      "x": 4,
      "y": 5,
      "z": -1,
      "name": "Rock_Calcite_Brick_Stairs",
      "rotation": 11
    },
    {
      "x": 4,
      "y": 6,
      "z": -1,
      "name": "Rock_Calcite_Brick"
    },
    {
      "x": 4,
      "y": 7,
      "z": -1,
      "name": "Rock_Calcite_Brick_Smooth"
    },
    {
      "x": 4,
      "y": 14,
      "z": -1,
      "name": "Rock_Calcite_Brick_Smooth_Half"
    },
    {
      "x": 4,
