{"anchorX":2,"anchorY":7,"anchorZ":2,"blockIdVersion":8,"blocks":[{"name":"Rock_Sandstone_Brick_Smooth_Half","rotation":7,"x":-10,"y":3,"z":12},{"name":"Rock_Sandstone_Brick_Smooth_Half","rotation":7,"x":-10,"y":4,"z":12},{"name":"Rock_Sandstone_Brick_Smooth_Half","rotation":7,"x":-10,"y":6,"z":12},{"name":"Rock_Sandstone_Brick_Smooth_Half","rotation":7,"x":-10,"y":7,"z":12},{"name":"Rock_Sandstone_Brick_Smooth_Half","rotation":7,"x":-10,"y":9,"z":12},{"name":"Rock_Sandstone_Brick_Smooth_Half","rotation":7,"x":-10,"y":10,"z":12},{"name":"Rock_Sandstone_Brick_Smooth_Half","rotation":7,"x":-10,"y":3,"z":13},{"name":"Rock_Sandstone_Brick_Smooth_Half","rotation":7,"x":-10,"y":4,"z":13},{"name":"Rock_Sandstone_Brick_Smooth_Half","rotation":7,"x":-10,"y":6,"z":13},{"name":"Rock_Sandstone_Brick_Smooth_Half","rotation":7,"x":-10,"y":7,"z":13},{"name":"Rock_Sandstone_Brick_Smooth_Half","rotation":7,"x":-10,"y":9,"z":13},{"name":"Rock_Sandstone_Brick_Smooth_Half","rotation":7,"x":-10,"y":10,"z":13},{"name":"Rock_Sandstone_Brick","x":-9,"y":3,"z":0},{"name":"Rock_Sandstone_Brick","x":-9,"y":4,"z":0},{"name":"Rock_Sandstone_Brick","x":-9,"y":5,"z":0},{"name":"Rock_Sandstone_Brick","x":-9,"y":6,"z":0},{"name":"Rock_Sandstone_Brick","x":-9,"y":7,"z":0},{"name":"Rock_Sandstone_Brick","x":-9,"y":8,"z":0},{"name":"Rock_Sandstone_Brick","x":-9,"y":3,"z":1},{"name":"Rock_Sandstone_Brick","x":-9,"y":4,"z":1},{"name":"Rock_Sandstone_Brick","x":-9,"y":5,"z":1},{"name":"Rock_Sandstone_Brick","x":-9,"y":6,"z":1},{"name":"Rock_Sandstone_Brick","x":-9,"y":7,"z":1},{"name":"Rock_Sandstone_Brick","x":-9,"y":8,"z":1},{"name":"Rock_Sandstone_Brick","x":-9,"y":9,"z":1},{"name":"Rock_Sandstone_Brick","x":-9,"y":10,"z":1},{"name":"Rock_Sandstone_Brick","x":-9,"y":3,"z":2},{"name":"Rock_Sandstone_Brick","x":-9,"y":4,"z":2},{"name":"Rock_Sandstone_Brick","x":-9,"y":5,"z":2},{"name":"Rock_Sandstone_Brick","x":-9,"y":6,"z":2},{"name":"Rock_Sandstone_Brick","x":-9,"y":7,"z":2},{"name":"Rock_Sandstone_Brick","x":-9,"y":8,"z":2},{"name":"Rock_Sandstone_Brick","x":-9,"y":3,"z":3},{"name":"Rock_Sandstone_Brick","x":-9,"y":4,"z":3},{"name":"Rock_Sandstone_Brick","x":-9,"y":5,"z":3},{"name":"Rock_Sandstone_Brick","x":-9,"y":6,"z":3},{"name":"Rock_Sandstone_Brick","x":-9,"y":7,"z":3},{"name":"Rock_Sandstone_Brick","x":-9,"y":8,"z":3},{"name":"Rock_Sandstone_Brick","x":-9,"y":3,"z":4},{"name":"Rock_Sandstone_Brick","x":-9,"y":4,"z":4},{"name":"Rock_Sandstone_Brick","x":-9,"y":5,"z":4},{"name":"Rock_Sandstone_Brick","x":-9,"y":6,"z":4},{"name":"Rock_Sandstone_Brick","x":-9,"y":7,"z":4},{"name":"Rock_Sandstone_Brick","x":-9,"y":8,"z":4},{"name":"Rock_Sandstone_Brick","x":-9,"y":3,"z":5},{"name":"Rock_Sandstone_Brick","x":-9,"y":4,"z":5},{"name":"Rock_Sandstone_Brick","x":-9,"y":5,"z":5},{"name":"Rock_Sandstone_Brick","x":-9,"y":6,"z":5},{"name":"Rock_Sandstone_Brick","x":-9,"y":7,"z":5},{"name":"Rock_Sandstone_Brick","x":-9,"y":8,"z":5},{"name":"Rock_Sandstone_Brick_Half","rotation":6,"x":-9,"y":11,"z":5},{"name":"Rock_Sandstone_Brick","x":-9,"y":3,"z":6},{"name":"Rock_Sandstone_Brick","x":-9,"y":4,"z":6},{"name":"Rock_Sandstone_Brick","x":-9,"y":5,"z":6},{"name":"Rock_Sandstone_Brick","x":-9,"y":6,"z":6},{"name":"Rock_Sandstone_Brick","x":-9,"y":7,"z":6},{"name":"Rock_Sandstone_Brick","x":-9,"y":8,"z":6},{"name":"Rock_Sandstone_Brick","x":-9,"y":9,"z":6},{"name":"Rock_Sandstone_Brick","x":-9,"y":10,"z":6},{"name":"Rock_Sandstone_Brick","x":-9,"y":11,"z":6},{"name":"Rock_Sandstone_Brick","x":-9,"y":3,"z":7},{"name":"Rock_Sandstone_Brick","x":-9,"y":4,"z":7},{"name":"Rock_Sandstone_Brick","x":-9,"y":5,"z":7},{"name":"Rock_Sandstone_Brick","x":-9,"y":6,"z":7},{"name":"Rock_Sandstone_Brick","x":-9,"y":7,"z":7},{"name":"Rock_Sandstone_Brick","x":-9,"y":8,"z":7},{"name":"Rock_Sandstone_Brick","x":-9,"y":9,"z":7},{"name":"Rock_Sandstone_Brick","x":-9,"y":3,"z":8},{"name":"Rock_Sandstone_Brick","x":-9,"y":4,"z":8},{"name":"Rock_Sandstone_Brick","x":-9,"y":5,"z":8},{"name":"Rock_Sandstone_Brick","x":-9,"y":6,"z":8},{"name":"Rock_Sandstone_Brick","x":-9,"y":7,"z":8},{"name":"Rock_Sandstone_Brick","x":-9,"y":8,"z":8},{"name":"Rock_Sandstone_Brick","x":-9,"y":9,"z":8},{"name":"Rock_Sandstone_Brick","x":-9,"y":3,"z":9},{"name":"Rock_Sandstone_Brick","x":-9,"y":4,"z":9},{"name":"Rock_Sandstone_Brick","x":-9,"y":5,"z":9},{"name":"Rock_Sandstone_Brick","x":-9,"y":6,"z":9},{"name":"Rock_Sandstone_Brick","x":-9,"y":7,"z":9},{"name":"Rock_Sandstone_Brick","x":-9,"y":8,"z":9},{"name":"Rock_Sandstone_Brick","x":-9,"y":9,"z":9},{"name":"Rock_Sandstone_Brick","x":-9,"y":10,"z":9},{"name":"Rock_Sandstone_Brick","x":-9,"y":3,"z":10},{"name":"Rock_Sandstone_Brick","x":-9,"y":4,"z":10},{"name":"Rock_Sandstone_Brick","x":-9,"y":5,"z":10},{"name":"Rock_Sandstone_Brick","x":-9,"y":6,"z":10},{"name":"Rock_Sandstone_Brick","x":-9,"y":7,"z":10},{"name":"Rock_Sandstone_Brick","x":-9,"y":8,"z":10},{"name":"Rock_Sandstone_Brick","x":-9,"y":9,"z":10},{"name":"Rock_Sandstone_Brick","x":-9,"y":10,"z":10},{"name":"Rock_Sandstone_Brick","x":-9,"y":3,"z":11},{"name":"Rock_Sandstone_Brick","x":-9,"y":4,"z":11},{"name":"Rock_Sandstone_Brick","x":-9,"y":5,"z":11},{"name":"Rock_Sandstone_Brick","x":-9,"y":6,"z":11},{"name":"Rock_Sandstone_Brick","x":-9,"y":7,"z":11},{"name":"Rock_Sandstone_Brick","x":-9,"y":8,"z":11},{"name":"Rock_Sandstone_Brick","x":-9,"y":9,"z":11},{"name":"Rock_Sandstone_Brick","x":-9,"y":10,"z":11},{"name":"Rock_Sandstone_Brick","x":-9,"y":11,"z":11},{"name":"Rock_Sandstone_Brick","x":-9,"y":3,"z":12},{"name":"Rock_Sandstone_Brick","x":-9,"y":4,"z":12},{"name":"Rock_Sandstone_Brick","x":-9,"y":5,"z":12},{"name":"Rock_Sandstone_Brick","x":-9,"y":6,"z":12},{"name":"Rock_Sandstone_Brick","x":-9,"y":7,"z":12},{"name":"Rock_Sandstone_Brick","x":-9,"y":8,"z":12},{"name":"Rock_Sandstone_Brick","x":-9,"y":9,"z":12},{"name":"Rock_Sandstone_Brick","x":-9,"y":10,"z":12},{"name":"Rock_Sandstone_Brick","x":-9,"y":11,"z":12},{"name":"Rock_Sandstone_Brick_Smooth","x":-9,"y":3,"z":13},{"name":"Rock_Sandstone_Brick_Smooth","x":-9,"y":4,"z":13},{"name":"Rock_Sandstone_Brick_Smooth","x":-9,"y":5,"z":13},{"name":"Rock_Sandstone_Brick_Smooth","x":-9,"y":6,"z":13},{"name":"Rock_Sandstone_Brick_Smooth","x":-9,"y":7,"z":13},{"name":"Rock_Sandstone_Brick_Smooth","x":-9,"y":8,"z":13},{"name":"Rock_Sandstone_Brick_Smooth","x":-9,"y":9,"z":13},{"name":"Rock_Sandstone_Brick_Smooth","x":-9,"y":10,"z":13},{"name":"Rock_Sandstone_Brick_Smooth","x":-9,"y":11,"z":13},{"name":"Rock_Sandstone_Brick_Smooth_Half","rotation":4,"x":-9,"y":3,"z":14},{"name":"Rock_Sandstone_Brick_Smooth_Half","rotation":4,"x":-9,"y":4,"z":14},{"name":"Rock_Sandstone_Brick_Smooth_Half","rotation":4,"x":-9,"y":6,"z":14},{"name":"Rock_Sandstone_Brick_Smooth_Half","rotation":4,"x":-9,"y":7,"z":14},{"name":"Rock_Sandstone_Brick_Smooth_Half","rotation":4,"x":-9,"y":9,"z":14},{"name":"Rock_Sandstone_Brick_Smooth_Half","rotation":4,"x":-9,"y":10,"z":14},{"name":"Soil_Gravel_Sand_White","x":-8,"y":3,"z":0},{"name":"Soil_Gravel_Sand_White","x":-8,"y":4,"z":0},{"name":"Soil_Gravel_Sand_White","x":-8,"y":5,"z":0},{"name":"Soil_Gravel_Sand_White","x":-8,"y":6,"z":0},{"name":"Soil_Gravel_Sand_White","x":-8,"y":7,"z":0},{"name":"Soil_Gravel_Sand_White","x":-8,"y":8,"z":0},{"name":"Soil_Gravel_Sand_White","x":-8,"y":9,"z":0},{"name":"Soil_Gravel_Sand_White","x":-8,"y":3,"z":1},{"name":"Soil_Gravel_Sand_White","x":-8,"y":4,"z":1},{"name":"Soil_Gravel_Sand_White","x":-8,"y":5,"z":1},{"name":"Soil_Gravel_Sand_White","x":-8,"y":6,"z":1},{"name":"Soil_Gravel_Sand_White","x":-8,"y":7,"z":1},{"name":"Soil_Gravel_Sand_White","x":-8,"y":8,"z":1},{"name":"Soil_Gravel_Sand_White","x":-8,"y":9,"z":1},{"name":"Soil_Gravel_Sand_White","x":-8,"y":10,"z":1},{"name":"Soil_Gravel_Sand_White","x":-8,"y":3,"z":2},{"name":"Soil_Gravel_Sand_White","x":-8,"y":4,"z":2},{"name":"Soil_Gravel_Sand_White","x":-8,"y":5,"z":2},{"name":"Soil_Gravel_Sand_White","x":-8,"y":6,"z":2},{"name":"Soil_Gravel_Sand_White","x":-8,"y":7,"z":2},{"name":"Soil_Gravel_Sand_White","x":-8,"y":8,"z":2},{"name":"Rock_Sandstone_Brick_Smooth","x":-8,"y":9,"z":2},{"name":"Rock_Sandstone_Brick_Smooth","x":-8,"y":10,"z":2},{"name":"Rock_Sandstone_Brick_Smooth","x":-8,"y":11,"z":2},{"name":"Soil_Gravel_Sand_White","x":-8,"y":3,"z":3},{"name":"Soil_Gravel_Sand_White","x":-8,"y":4,"z":3},{"name":"Soil_Gravel_Sand_White","x":-8,"y":5,"z":3},{"name":"Soil_Gravel_Sand_White","x":-8,"y":6,"z":3},{"name":"Soil_Gravel_Sand_White","x":-8,"y":7,"z":3},{"name":"Soil_Gravel_Sand_White","x":-8,"y":8,"z":3},{"name":"Rock_Sandstone_Brick_Smooth","x":-8,"y":9,"z":3},{"name":"Soil_Gravel_Sand_White","x":-8,"y":3,"z":4},{"name":"Soil_Gravel_Sand_White","x":-8,"y":4,"z":4},{"name":"Soil_Gravel_Sand_White","x":-8,"y":5,"z":4},{"name":"Soil_Gravel_Sand_White","x":-8,"y":6,"z":4},{"name":"Soil_Gravel_Sand_White","x":-8,"y":7,"z":4},{"name":"Soil_Gravel_Sand_White","x":-8,"y":8,"z":4},{"name":"Rock_Sandstone_Brick_Smooth","x":-8,"y":9,"z":4},{"name":"Soil_Gravel_Sand_White","x":-8,"y":3,"z":5},{"name":"Soil_Gravel_Sand_White","x":-8,"y":4,"z":5},{"name":"Soil_Gravel_Sand_White","x":-8,"y":5,"z":5},{"name":"Soil_Gravel_Sand_White","x":-8,"y":6,"z":5},{"name":"Soil_Gravel_Sand_White","x":-8,"y":7,"z":5},{"name":"Soil_Gravel_Sand_White","x":-8,"y":8,"z":5},{"name":"Rock_Sandstone_Brick_Smooth","x":-8,"y":9,"z":5},{"name":"Rock_Sandstone_Brick_Smooth","x":-8,"y":10,"z":5},{"name":"Rock_Sandstone_Brick_Smooth","x":-8,"y":11,"z":5},{"name":"Soil_Gravel_Sand_White","x":-8,"y":3,"z":6},{"name":"Soil_Gravel_Sand_White","x":-8,"y":4,"z":6},{"name":"Soil_Gravel_Sand_White","x":-8,"y":5,"z":6},{"name":"Soil_Gravel_Sand_White","x":-8,"y":6,"z":6},{"name":"Soil_Gravel_Sand_White","x":-8,"y":7,"z":6},{"name":"Soil_Gravel_Sand_White","x":-8,"y":8,"z":6},{"name":"Soil_Gravel_Sand_White","x":-8,"y":9,"z":6},{"name":"Soil_Gravel_Sand_White","x":-8,"y":10,"z":6},{"name":"Soil_Gravel_Sand_White","x":-8,"y":11,"z":6},{"name":"Soil_Gravel_Sand_White","x":-8,"y":3,"z":7},{"name":"Soil_Gravel_Sand_White","x":-8,"y":4,"z":7},{"name":"Soil_Gravel_Sand_White","x":-8,"y":5,"z":7},{"name":"Soil_Gravel_Sand_White","x":-8,"y":6,"z":7},{"name":"Soil_Gravel_Sand_White","x":-8,"y":7,"z":7},{"name":"Soil_Gravel_Sand_White","x":-8,"y":8,"z":7},{"name":"Soil_Gravel_Sand_White","x":-8,"y":9,"z":7},{"name":"Soil_Gravel_Sand_White","x":-8,"y":3,"z":8},{"name":"Soil_Gravel_Sand_White","x":-8,"y":4,"z":8},{"name":"Soil_Gravel_Sand_White","x":-8,"y":5,"z":8},{"name":"Soil_Gravel_Sand_White","x":-8,"y":6,"z":8},{"name":"Soil_Gravel_Sand_White","x":-8,"y":7,"z":8},{"name":"Soil_Gravel_Sand_White","x":-8,"y":8,"z":8},{"name":"Soil_Gravel_Sand_White","x":-8,"y":9,"z":8},{"name":"Soil_Gravel_Sand_White","x":-8,"y":10,"z":8},{"name":"Soil_Gravel_Sand_White","x":-8,"y":3,"z":9},{"name":"Soil_Gravel_Sand_White","x":-8,"y":4,"z":9},{"name":"Soil_Gravel_Sand_White","x":-8,"y":5,"z":9},{"name":"Soil_Gravel_Sand_White","x":-8,"y":6,"z":9},{"name":"Soil_Gravel_Sand_White","x":-8,"y":7,"z":9},{"name":"Soil_Gravel_Sand_White","x":-8,"y":8,"z":9},{"name":"Soil_Gravel_Sand_White","x":-8,"y":9,"z":9},{"name":"Soil_Gravel_Sand_White","x":-8,"y":10,"z":9},{"name":"Soil_Gravel_Sand_White","x":-8,"y":3,"z":10},{"name":"Soil_Gravel_Sand_White","x":-8,"y":4,"z":10},{"name":"Soil_Gravel_Sand_White","x":-8,"y":5,"z":10},{"name":"Soil_Gravel_Sand_White","x":-8,"y":6,"z":10},{"name":"Soil_Gravel_Sand_White","x":-8,"y":7,"z":10},{"name":"Soil_Gravel_Sand_White","x":-8,"y":8,"z":10},{"name":"Soil_Gravel_Sand_White","x":-8,"y":9,"z":10},{"name":"Soil_Gravel_Sand_White","x":-8,"y":10,"z":10},{"name":"Soil_Gravel_Sand_White","x":-8,"y":11,"z":10},{"name":"Soil_Gravel_Sand_White","x":-8,"y":3,"z":11},{"name":"Soil_Gravel_Sand_White","x":-8,"y":4,"z":11},{"name":"Soil_Gravel_Sand_White","x":-8,"y":5,"z":11},{"name":"Soil_Gravel_Sand_White","x":-8,"y":6,"z":11},{"name":"Soil_Gravel_Sand_White","x":-8,"y":7,"z":11},{"name":"Soil_Gravel_Sand_White","x":-8,"y":8,"z":11},{"name":"Soil_Gravel_Sand_White","x":-8,"y":9,"z":11},{"name":"Soil_Gravel_Sand_White","x":-8,"y":10,"z":11},{"name":"Soil_Gravel_Sand_White","x":-8,"y":11,"z":11},{"name":"Soil_Gravel_Sand_White","x":-8,"y":3,"z":12},{"name":"Soil_Gravel_Sand_White","x":-8,"y":4,"z":12},{"name":"Soil_Gravel_Sand_White","x":-8,"y":5,"z":12},{"name":"Soil_Gravel_Sand_White","x":-8,"y":6,"z":12},{"name":"Soil_Gravel_Sand_White","x":-8,"y":7,"z":12},{"name":"Soil_Gravel_Sand_White","x":-8,"y":8,"z":12},{"name":"Soil_Gravel_Sand_White","x":-8,"y":9,"z":12},{"name":"Soil_Gravel_Sand_White","x":-8,"y":10,"z":12},{"name":"Soil_Gravel_Sand_White","x":-8,"y":11,"z":12},{"name":"Rock_Sandstone_Brick","x":-8,"y":3,"z":13},{"name":"Rock_Sandstone_Brick","x":-8,"y":4,"z":13},{"name":"Rock_Sandstone_Brick","x":-8,"y":5,"z":13},{"name":"Rock_Sandstone_Brick","x":-8,"y":6,"z":13},{"name":"Rock_Sandstone_Brick","x":-8,"y":7,"z":13},{"name":"Rock_Sandstone_Brick","x":-8,"y":8,"z":13},{"name":"Rock_Sandstone_Brick","x":-8,"y":9,"z":13},{"name":"Rock_Sandstone_Brick","x":-8,"y":10,"z":13},{"name":"Rock_Sandstone_Brick","x":-8,"y":11,"z":13},{"name":"Rock_Sandstone_Brick_Smooth_Half","rotation":4,"x":-8,"y":3,"z":14},{"name":"Rock_Sandstone_Brick_Smooth_Half","rotation":4,"x":-8,"y":4,"z":14},{"name":"Rock_Sandstone_Brick_Smooth_Half","rotation":4,"x":-8,"y":6,"z":14},{"name":"Rock_Sandstone_Brick_Smooth_Half","rotation":4,"x":-8,"y":7,"z":14},{"name":"Rock_Sandstone_Brick_Smooth_Half","rotation":4,"x":-8,"y":9,"z":14},{"name":"Rock_Sandstone_Brick_Smooth_Half","rotation":4,"x":-8,"y":10,"z":14},{"name":"Rock_Sandstone_Brick","x":-7,"y":3,"z":0},{"name":"Rock_Sandstone_Brick","x":-7,"y":4,"z":0},{"name":"Rock_Sandstone_Brick","x":-7,"y":5,"z":0},{"name":"Rock_Sandstone_Brick","x":-7,"y":6,"z":0},{"name":"Rock_Sandstone_Brick","x":-7,"y":7,"z":0},{"name":"Rock_Sandstone_Brick","x":-7,"y":8,"z":0},{"name":"Rock_Sandstone_Brick","x":-7,"y":9,"z":0},{"name":"Rock_Sandstone_Brick","x":-7,"y":3,"z":1},{"name":"Rock_Sandstone_Brick","x":-7,"y":4,"z":1},{"name":"Rock_Sandstone_Brick","x":-7,"y":5,"z":1},{"name":"Rock_Sandstone_Brick","x":-7,"y":6,"z":1},{"name":"Rock_Sandstone_Brick","x":-7,"y":7,"z":1},{"name":"Rock_Sandstone_Brick","x":-7,"y":8,"z":1},{"name":"Rock_Sandstone_Brick","x":-7,"y":9,"z":1},{"name":"Rock_Sandstone_Brick","x":-7,"y":10,"z":1},{"name":"Rock_Sandstone_Brick","x":-7,"y":3,"z":2},{"name":"Rock_Sandstone_Brick","x":-7,"y":4,"z":2},{"name":"Rock_Sandstone_Brick","x":-7,"y":5,"z":2},{"name":"Rock_Sandstone_Brick","x":-7,"y":6,"z":2},{"name":"Rock_Sandstone_Brick","x":-7,"y":7,"z":2},{"name":"Rock_Sandstone_Brick","x":-7,"y":8,"z":2},{"name":"Rock_Sandstone_Brick","x":-7,"y":9,"z":2},{"name":"Rock_Sandstone_Brick","x":-7,"y":10,"z":2},{"name":"Rock_Sandstone_Brick","x":-7,"y":11,"z":2},{"name":"Rock_Sandstone_Brick","x":-7,"y":3,"z":3},{"name":"Rock_Sandstone_Brick","x":-7,"y":4,"z":3},{"name":"Rock_Sandstone_Brick","x":-7,"y":5,"z":3},{"name":"Rock_Sandstone_Brick","x":-7,"y":6,"z":3},{"name":"Rock_Sandstone_Brick","x":-7,"y":7,"z":3},{"name":"Rock_Sandstone_Brick","x":-7,"y":8,"z":3},{"name":"Rock_Sandstone_Brick","x":-7,"y":9,"z":3},{"name":"Rock_Sandstone_Brick","x":-7,"y":3,"z":4},{"name":"Rock_Sandstone_Brick","x":-7,"y":4,"z":4},{"name":"Rock_Sandstone_Brick","x":-7,"y":5,"z":4},{"name":"Rock_Sandstone_Brick","x":-7,"y":6,"z":4},{"name":"Rock_Sandstone_Brick","x":-7,"y":7,"z":4},{"name":"Rock_Sandstone_Brick","x":-7,"y":8,"z":4},{"name":"Rock_Sandstone_Brick","x":-7,"y":9,"z":4},{"name":"Rock_Sandstone_Brick","x":-7,"y":3,"z":5},{"name":"Rock_Sandstone_Brick","x":-7,"y":4,"z":5},{"name":"Rock_Sandstone_Brick","x":-7,"y":5,"z":5},{"name":"Rock_Sandstone_Brick","x":-7,"y":6,"z":5},{"name":"Rock_Sandstone_Brick","x":-7,"y":7,"z":5},{"name":"Rock_Sandstone_Brick","x":-7,"y":8,"z":5},{"name":"Rock_Sandstone_Brick","x":-7,"y":9,"z":5},{"name":"Rock_Sandstone_Brick","x":-7,"y":10,"z":5},{"name":"Rock_Sandstone_Brick","x":-7,"y":11,"z":5},{"name":"Rock_Sandstone_Brick","x":-7,"y":3,"z":6},{"name":"Rock_Sandstone_Brick","x":-7,"y":4,"z":6},{"name":"Rock_Sandstone_Brick","x":-7,"y":5,"z":6},{"name":"Rock_Sandstone_Brick","x":-7,"y":6,"z":6},{"name":"Rock_Sandstone_Brick","x":-7,"y":7,"z":6},{"name":"Rock_Sandstone_Brick","x":-7,"y":8,"z":6},{"name":"Rock_Sandstone_Brick","x":-7,"y":9,"z":6},{"name":"Rock_Sandstone_Brick","x":-7,"y":10,"z":6},{"name":"Rock_Sandstone_Brick","x":-7,"y":3,"z":7},{"name":"Rock_Sandstone_Brick","x":-7,"y":4,"z":7},{"name":"Rock_Sandstone_Brick","x":-7,"y":5,"z":7},{"name":"Rock_Sandstone_Brick","x":-7,"y":6,"z":7},{"name":"Rock_Sandstone_Brick","x":-7,"y":7,"z":7},{"name":"Rock_Sandstone_Brick","x":-7,"y":8,"z":7},{"name":"Rock_Sandstone_Brick","x":-7,"y":9,"z":7},{"name":"Rock_Sandstone_Brick","x":-7,"y":10,"z":7},{"name":"Rock_Sandstone_Brick","x":-7,"y":3,"z":8},{"name":"Rock_Sandstone_Brick","x":-7,"y":4,"z":8},{"name":"Rock_Sandstone_Brick","x":-7,"y":5,"z":8},{"name":"Rock_Sandstone_Brick","x":-7,"y":6,"z":8},{"name":"Rock_Sandstone_Brick","x":-7,"y":7,"z":8},{"name":"Rock_Sandstone_Brick","x":-7,"y":8,"z":8},{"name":"Rock_Sandstone_Brick","x":-7,"y":9,"z":8},{"name":"Rock_Sandstone_Brick","x":-7,"y":10,"z":8},{"name":"Rock_Sandstone_Brick","x":-7,"y":3,"z":9},{"name":"Rock_Sandstone_Brick","x":-7,"y":4,"z":9},{"name":"Rock_Sandstone_Brick","x":-7,"y":5,"z":9},{"name":"Rock_Sandstone_Brick","x":-7,"y":6,"z":9},{"name":"Rock_Sandstone_Brick","x":-7,"y":7,"z":9},{"name":"Rock_Sandstone_Brick","x":-7,"y":8,"z":9},{"name":"Rock_Sandstone_Brick","x":-7,"y":9,"z":9},{"name":"Rock_Sandstone_Brick","x":-7,"y":10,"z":9},{"name":"Rock_Sandstone_Brick","x":-7,"y":11,"z":9},{"name":"Rock_Sandstone_Brick","x":-7,"y":3,"z":10},{"name":"Rock_Sandstone_Brick","x":-7,"y":4,"z":10},{"name":"Rock_Sandstone_Brick","x":-7,"y":5,"z":10},{"name":"Rock_Sandstone_Brick","x":-7,"y":6,"z":10},{"name":"Rock_Sandstone_Brick","x":-7,"y":7,"z":10},{"name":"Rock_Sandstone_Brick","x":-7,"y":8,"z":10},{"name":"Rock_Sandstone_Brick","x":-7,"y":9,"z":10},{"name":"Rock_Sandstone_Brick","x":-7,"y":10,"z":10},{"name":"Rock_Sandstone_Brick","x":-7,"y":11,"z":10},{"name":"Rock_Sandstone_Brick","x":-7,"y":3,"z":11},{"name":"Rock_Sandstone_Brick","x":-7,"y":4,"z":11},{"name":"Rock_Sandstone_Brick","x":-7,"y":5,"z":11},{"name":"Rock_Sandstone_Brick","x":-7,"y":6,"z":11},{"name":"Rock_Sandstone_Brick","x":-7,"y":7,"z":11},{"name":"Rock_Sandstone_Brick","x":-7,"y":8,"z":11},{"name":"Rock_Sandstone_Brick","x":-7,"y":9,"z":11},{"name":"Rock_Sandstone_Brick","x":-7,"y":10,"z":11},{"name":"Rock_Sandstone_Brick","x":-7,"y":11,"z":11},{"name":"Rock_Sandstone_Brick","x":-7,"y":12,"z":11},{"name":"Soil_Gravel_Sand_White","x":-7,"y":3,"z":12},{"name":"Soil_Gravel_Sand_White","x":-7,"y":4,"z":12},{"name":"Soil_Gravel_Sand_White","x":-7,"y":5,"z":12},{"name":"Soil_Gravel_Sand_White","x":-7,"y":6,"z":12},{"name":"Soil_Gravel_Sand_White","x":-7,"y":7,"z":12},{"name":"Soil_Gravel_Sand_White","x":-7,"y":8,"z":12},{"name":"Soil_Gravel_Sand_White","x":-7,"y":9,"z":12},{"name":"Soil_Gravel_Sand_White","x":-7,"y":10,"z":12},{"name":"Soil_Gravel_Sand_White","x":-7,"y":11,"z":12},{"name":"Soil_Gravel_Sand_White","x":-7,"y":12,"z":12},{"name":"Rock_Sandstone_Brick","x":-7,"y":3,"z":13},{"name":"Rock_Sandstone_Brick","x":-7,"y":4,"z":13},{"name":"Rock_Sandstone_Brick","x":-7,"y":5,"z":13},{"name":"Rock_Sandstone_Brick","x":-7,"y":6,"z":13},{"name":"Rock_Sandstone_Brick","x":-7,"y":7,"z":13},{"name":"Rock_Sandstone_Brick","x":-7,"y":8,"z":13},{"name":"Rock_Sandstone_Brick","x":-7,"y":9,"z":13},{"name":"Rock_Sandstone_Brick","x":-7,"y":10,"z":13},{"name":"Rock_Sandstone_Brick","x":-7,"y":11,"z":13},{"name":"Rock_Sandstone_Brick","x":-7,"y":12,"z":13},{"name":"Rock_Sandstone_Brick","x":-6,"y":3,"z":11},{"name":"Rock_Sandstone_Brick","x":-6,"y":4,"z":11},{"name":"Rock_Sandstone_Brick","x":-6,"y":5,"z":11},{"name":"Rock_Sandstone_Brick","x":-6,"y":6,"z":11},{"name":"Rock_Sandstone_Brick","x":-6,"y":7,"z":11},{"name":"Rock_Sandstone_Brick","x":-6,"y":8,"z":11},{"name":"Rock_Sandstone_Brick","x":-6,"y":9,"z":11},{"name":"Rock_Sandstone_Brick","x":-6,"y":10,"z":11},{"name":"Rock_Sandstone_Brick","x":-6,"y":11,"z":11},{"name":"Rock_Sandstone_Brick","x":-6,"y":12,"z":11},{"name":"Soil_Gravel_Sand_White","x":-6,"y":3,"z":12},{"name":"Soil_Gravel_Sand_White","x":-6,"y":4,"z":12},{"name":"Soil_Gravel_Sand_White","x":-6,"y":5,"z":12},{"name":"Soil_Gravel_Sand_White","x":-6,"y":6,"z":12},{"name":"Soil_Gravel_Sand_White","x":-6,"y":7,"z":12},{"name":"Soil_Gravel_Sand_White","x":-6,"y":8,"z":12},{"name":"Soil_Gravel_Sand_White","x":-6,"y":9,"z":12},{"name":"Soil_Gravel_Sand_White","x":-6,"y":10,"z":12},{"name":"Soil_Gravel_Sand_White","x":-6,"y":11,"z":12},{"name":"Soil_Gravel_Sand_White","x":-6,"y":12,"z":12},{"name":"Soil_Gravel_Sand_White","x":-6,"y":13,"z":12},{"name":"Rock_Sandstone_Brick","x":-6,"y":3,"z":13},{"name":"Rock_Sandstone_Brick","x":-6,"y":4,"z":13},{"name":"Rock_Sandstone_Brick","x":-6,"y":5,"z":13},{"name":"Rock_Sandstone_Brick","x":-6,"y":6,"z":13},{"name":"Rock_Sandstone_Brick","x":-6,"y":7,"z":13},{"name":"Rock_Sandstone_Brick","x":-6,"y":8,"z":13},{"name":"Rock_Sandstone_Brick","x":-6,"y":9,"z":13},{"name":"Rock_Sandstone_Brick","x":-6,"y":10,"z":13},{"name":"Rock_Sandstone_Brick","x":-6,"y":11,"z":13},{"name":"Rock_Sandstone_Brick","x":-6,"y":12,"z":13},{"name":"Rock_Sandstone_Brick","x":-6,"y":13,"z":13},{"name":"Rock_Sandstone_Brick","x":-5,"y":3,"z":11},{"name":"Rock_Sandstone_Brick","x":-5,"y":4,"z":11},{"name":"Rock_Sandstone_Brick","x":-5,"y":5,"z":11},{"name":"Rock_Sandstone_Brick","x":-5,"y":6,"z":11},{"name":"Rock_Sandstone_Brick","x":-5,"y":7,"z":11},{"name":"Rock_Sandstone_Brick","x":-5,"y":8,"z":11},{"name":"Rock_Sandstone_Brick","x":-5,"y":9,"z":11},{"name":"Rock_Sandstone_Brick","x":-5,"y":10,"z":11},{"name":"Rock_Sandstone_Brick","x":-5,"y":11,"z":11},{"name":"Rock_Sandstone_Brick","x":-5,"y":12,"z":11},{"name":"Rock_Sandstone_Brick","x":-5,"y":13,"z":11},{"name":"Soil_Gravel_Sand_White","x":-5,"y":3,"z":12},{"name":"Soil_Gravel_Sand_White","x":-5,"y":4,"z":12},{"name":"Soil_Gravel_Sand_White","x":-5,"y":5,"z":12},{"name":"Soil_Gravel_Sand_White","x":-5,"y":6,"z":12},{"name":"Soil_Gravel_Sand_White","x":-5,"y":7,"z":12},{"name":"Soil_Gravel_Sand_White","x":-5,"y":8,"z":12},{"name":"Soil_Gravel_Sand_White","x":-5,"y":9,"z":12},{"name":"Soil_Gravel_Sand_White","x":-5,"y":10,"z":12},{"name":"Soil_Gravel_Sand_White","x":-5,"y":11,"z":12},{"name":"Soil_Gravel_Sand_White","x":-5,"y":12,"z":12},{"name":"Soil_Gravel_Sand_White","x":-5,"y":13,"z":12},{"name":"Rock_Sandstone_Brick","x":-5,"y":3,"z":13},{"name":"Rock_Sandstone_Brick","x":-5,"y":4,"z":13},{"name":"Rock_Sandstone_Brick","x":-5,"y":5,"z":13},{"name":"Rock_Sandstone_Brick","x":-5,"y":6,"z":13},{"name":"Rock_Sandstone_Brick","x":-5,"y":7,"z":13},{"name":"Rock_Sandstone_Brick","x":-5,"y":8,"z":13},{"name":"Rock_Sandstone_Brick","x":-5,"y":9,"z":13},{"name":"Rock_Sandstone_Brick","x":-5,"y":10,"z":13},{"name":"Rock_Sandstone_Brick","x":-5,"y":11,"z":13},{"name":"Rock_Sandstone_Brick","x":-5,"y":12,"z":13},{"name":"Rock_Sandstone_Brick","x":-5,"y":13,"z":13},{"name":"Rock_Sandstone_Brick","x":-4,"y":3,"z":11},{"name":"Rock_Sandstone_Brick","x":-4,"y":4,"z":11},{"name":"Rock_Sandstone_Brick","x":-4,"y":5,"z":11},{"name":"Rock_Sandstone_Brick","x":-4,"y":6,"z":11},{"name":"Rock_Sandstone_Brick","x":-4,"y":7,"z":11},{"name":"Rock_Sandstone_Brick","x":-4,"y":8,"z":11},{"name":"Rock_Sandstone_Brick","x":-4,"y":9,"z":11},{"name":"Rock_Sandstone_Brick","x":-4,"y":10,"z":11},{"name":"Rock_Sandstone_Brick","x":-4,"y":11,"z":11},{"name":"Rock_Sandstone_Brick","x":-4,"y":12,"z":11},{"name":"Rock_Sandstone_Brick","x":-4,"y":13,"z":11},{"name":"Soil_Gravel_Sand_White","x":-4,"y":3,"z":12},{"name":"Soil_Gravel_Sand_White","x":-4,"y":4,"z":12},{"name":"Soil_Gravel_Sand_White","x":-4,"y":5,"z":12},{"name":"Soil_Gravel_Sand_White","x":-4,"y":6,"z":12},{"name":"Soil_Gravel_Sand_White","x":-4,"y":7,"z":12},{"name":"Soil_Gravel_Sand_White","x":-4,"y":8,"z":12},{"name":"Soil_Gravel_Sand_White","x":-4,"y":9,"z":12},{"name":"Soil_Gravel_Sand_White","x":-4,"y":10,"z":12},{"name":"Soil_Gravel_Sand_White","x":-4,"y":11,"z":12},{"name":"Soil_Gravel_Sand_White","x":-4,"y":12,"z":12},{"name":"Soil_Gravel_Sand_White","x":-4,"y":13,"z":12},{"name":"Rock_Sandstone_Brick","x":-4,"y":3,"z":13},{"name":"Rock_Sandstone_Brick","x":-4,"y":4,"z":13},{"name":"Rock_Sandstone_Brick","x":-4,"y":5,"z":13},{"name":"Rock_Sandstone_Brick","x":-4,"y":6,"z":13},{"name":"Rock_Sandstone_Brick","x":-4,"y":7,"z":13},{"name":"Rock_Sandstone_Brick","x":-4,"y":8,"z":13},{"name":"Rock_Sandstone_Brick","x":-4,"y":9,"z":13},{"name":"Rock_Sandstone_Brick","x":-4,"y":10,"z":13},{"name":"Rock_Sandstone_Brick","x":-4,"y":11,"z":13},{"name":"Rock_Sandstone_Brick","x":-4,"y":12,"z":13},{"name":"Rock_Sandstone_Brick","x":-4,"y":13,"z":13},{"name":"Rock_Sandstone_Brick","x":-3,"y":3,"z":11},{"name":"Rock_Sandstone_Brick","x":-3,"y":4,"z":11},{"name":"Rock_Sandstone_Brick","x":-3,"y":5,"z":11},{"name":"Rock_Sandstone_Brick","x":-3,"y":6,"z":11},{"name":"Rock_Sandstone_Brick","x":-3,"y":7,"z":11},{"name":"Rock_Sandstone_Brick","x":-3,"y":8,"z":11},{"name":"Rock_Sandstone_Brick","x":-3,"y":9,"z":11},{"name":"Rock_Sandstone_Brick","x":-3,"y":10,"z":11},{"name":"Rock_Sandstone_Brick","x":-3,"y":11,"z":11},{"name":"Rock_Sandstone_Brick","x":-3,"y":12,"z":11},{"name":"Rock_Sandstone_Brick","x":-3,"y":13,"z":11},{"name":"Soil_Gravel_Sand_White","x":-3,"y":3,"z":12},{"name":"Soil_Gravel_Sand_White","x":-3,"y":4,"z":12},{"name":"Soil_Gravel_Sand_White","x":-3,"y":5,"z":12},{"name":"Soil_Gravel_Sand_White","x":-3,"y":6,"z":12},{"name":"Soil_Gravel_Sand_White","x":-3,"y":7,"z":12},{"name":"Soil_Gravel_Sand_White","x":-3,"y":8,"z":12},{"name":"Soil_Gravel_Sand_White","x":-3,"y":9,"z":12},{"name":"Soil_Gravel_Sand_White","x":-3,"y":10,"z":12},{"name":"Soil_Gravel_Sand_White","x":-3,"y":11,"z":12},{"name":"Soil_Gravel_Sand_White","x":-3,"y":12,"z":12},{"name":"Soil_Gravel_Sand_White","x":-3,"y":13,"z":12},{"name":"Rock_Sandstone_Brick","x":-3,"y":3,"z":13},{"name":"Rock_Sandstone_Brick","x":-3,"y":4,"z":13},{"name":"Rock_Sandstone_Brick","x":-3,"y":5,"z":13},{"name":"Rock_Sandstone_Brick","x":-3,"y":6,"z":13},{"name":"Rock_Sandstone_Brick","x":-3,"y":7,"z":13},{"name":"Rock_Sandstone_Brick","x":-3,"y":8,"z":13},{"name":"Rock_Sandstone_Brick","x":-3,"y":9,"z":13},{"name":"Rock_Sandstone_Brick","x":-3,"y":10,"z":13},{"name":"Rock_Sandstone_Brick","x":-3,"y":11,"z":13},{"name":"Rock_Sandstone_Brick","x":-3,"y":12,"z":13},{"name":"Rock_Sandstone_Brick","x":-2,"y":3,"z":11},{"name":"Rock_Sandstone_Brick","x":-2,"y":4,"z":11},{"name":"Rock_Sandstone_Brick","x":-2,"y":5,"z":11},{"name":"Rock_Sandstone_Brick","x":-2,"y":6,"z":11},{"name":"Rock_Sandstone_Brick","x":-2,"y":7,"z":11},{"name":"Rock_Sandstone_Brick","x":-2,"y":8,"z":11},{"name":"Rock_Sandstone_Brick","x":-2,"y":9,"z":11},{"name":"Rock_Sandstone_Brick","x":-2,"y":10,"z":11},{"name":"Rock_Sandstone_Brick","x":-2,"y":11,"z":11},{"name":"Rock_Sandstone_Brick","x":-2,"y":12,"z":11},{"name":"Soil_Gravel_Sand_White","x":-2,"y":3,"z":12},{"name":"Soil_Gravel_Sand_White","x":-2,"y":4,"z":12},{"name":"Soil_Gravel_Sand_White","x":-2,"y":5,"z":12},{"name":"Soil_Gravel_Sand_White","x":-2,"y":6,"z":12},{"name":"Soil_Gravel_Sand_White","x":-2,"y":7,"z":12},{"name":"Soil_Gravel_Sand_White","x":-2,"y":8,"z":12},{"name":"Soil_Gravel_Sand_White","x":-2,"y":9,"z":12},{"name":"Soil_Gravel_Sand_White","x":-2,"y":10,"z":12},{"name":"Soil_Gravel_Sand_White","x":-2,"y":11,"z":12},{"name":"Soil_Gravel_Sand_White","x":-2,"y":12,"z":12},{"name":"Rock_Sandstone_Brick","x":-2,"y":3,"z":13},{"name":"Rock_Sandstone_Brick","x":-2,"y":4,"z":13},{"name":"Rock_Sandstone_Brick","x":-2,"y":5,"z":13},{"name":"Rock_Sandstone_Brick","x":-2,"y":6,"z":13},{"name":"Rock_Sandstone_Brick","x":-2,"y":7,"z":13},{"name":"Rock_Sandstone_Brick","x":-2,"y":8,"z":13},{"name":"Rock_Sandstone_Brick","x":-2,"y":9,"z":13},{"name":"Rock_Sandstone_Brick","x":-2,"y":10,"z":13},{"name":"Rock_Sandstone_Brick","x":-2,"y":11,"z":13},{"name":"Rock_Sandstone_Brick","x":-2,"y":12,"z":13},{"name":"Rock_Sandstone_Brick","x":-1,"y":3,"z":11},{"name":"Rock_Sandstone_Brick","x":-1,"y":4,"z":11},{"name":"Rock_Sandstone_Brick","x":-1,"y":5,"z":11},{"name":"Rock_Sandstone_Brick","x":-1,"y":6,"z":11},{"name":"Rock_Sandstone_Brick","x":-1,"y":7,"z":11},{"name":"Rock_Sandstone_Brick","x":-1,"y":8,"z":11},{"name":"Rock_Sandstone_Brick","x":-1,"y":9,"z":11},{"name":"Rock_Sandstone_Brick","x":-1,"y":10,"z":11},{"name":"Rock_Sandstone_Brick","x":-1,"y":11,"z":11},{"name":"Rock_Sandstone_Brick","x":-1,"y":12,"z":11},{"name":"Soil_Gravel_Sand_White","x":-1,"y":3,"z":12},{"name":"Soil_Gravel_Sand_White","x":-1,"y":4,"z":12},{"name":"Soil_Gravel_Sand_White","x":-1,"y":5,"z":12},{"name":"Soil_Gravel_Sand_White","x":-1,"y":6,"z":12},{"name":"Soil_Gravel_Sand_White","x":-1,"y":7,"z":12},{"name":"Soil_Gravel_Sand_White","x":-1,"y":8,"z":12},{"name":"Soil_Gravel_Sand_White","x":-1,"y":9,"z":12},{"name":"Soil_Gravel_Sand_White","x":-1,"y":10,"z":12},{"name":"Soil_Gravel_Sand_White","x":-1,"y":11,"z":12},{"name":"Soil_Gravel_Sand_White","x":-1,"y":12,"z":12},{"name":"Soil_Gravel_Sand_White","x":-1,"y":13,"z":12},{"name":"Rock_Sandstone_Brick","x":-1,"y":3,"z":13},{"name":"Rock_Sandstone_Brick","x":-1,"y":4,"z":13},{"name":"Rock_Sandstone_Brick","x":-1,"y":5,"z":13},{"name":"Rock_Sandstone_Brick","x":-1,"y":6,"z":13},{"name":"Rock_Sandstone_Brick","x":-1,"y":7,"z":13},{"name":"Rock_Sandstone_Brick","x":-1,"y":8,"z":13},{"name":"Rock_Sandstone_Brick","x":-1,"y":9,"z":13},{"name":"Rock_Sandstone_Brick","x":-1,"y":10,"z":13},{"name":"Rock_Sandstone_Brick","x":-1,"y":11,"z":13},{"name":"Rock_Sandstone_Brick","x":-1,"y":12,"z":13},{"name":"Rock_Sandstone_Brick","x":-1,"y":13,"z":13},{"name":"Rock_Sandstone_Brick","x":0,"y":3,"z":11},{"name":"Rock_Sandstone_Brick","x":0,"y":4,"z":11},{"name":"Rock_Sandstone_Brick","x":0,"y":5,"z":11},{"name":"Rock_Sandstone_Brick","x":0,"y":6,"z":11},{"name":"Rock_Sandstone_Brick","x":0,"y":7,"z":11},{"name":"Rock_Sandstone_Brick","x":0,"y":8,"z":11},{"name":"Rock_Sandstone_Brick","x":0,"y":9,"z":11},{"name":"Rock_Sandstone_Brick","x":0,"y":10,"z":11},{"name":"Rock_Sandstone_Brick","x":0,"y":11,"z":11},{"name":"Rock_Sandstone_Brick","x":0,"y":12,"z":11},{"name":"Rock_Sandstone_Brick","x":0,"y":13,"z":11},{"name":"Soil_Gravel_Sand_White","x":0,"y":3,"z":12},{"name":"Soil_Gravel_Sand_White","x":0,"y":4,"z":12},{"name":"Soil_Gravel_Sand_White","x":0,"y":5,"z":12},{"name":"Soil_Gravel_Sand_White","x":0,"y":6,"z":12},{"name":"Soil_Gravel_Sand_White","x":0,"y":7,"z":12},{"name":"Soil_Gravel_Sand_White","x":0,"y":8,"z":12},{"name":"Soil_Gravel_Sand_White","x":0,"y":9,"z":12},{"name":"Soil_Gravel_Sand_White","x":0,"y":10,"z":12},{"name":"Soil_Gravel_Sand_White","x":0,"y":11,"z":12},{"name":"Soil_Gravel_Sand_White","x":0,"y":12,"z":12},{"name":"Soil_Gravel_Sand_White","x":0,"y":13,"z":12},{"name":"Rock_Sandstone_Brick","x":0,"y":3,"z":13},{"name":"Rock_Sandstone_Brick","x":0,"y":4,"z":13},{"name":"Rock_Sandstone_Brick","x":0,"y":5,"z":13},{"name":"Rock_Sandstone_Brick","x":0,"y":6,"z":13},{"name":"Rock_Sandstone_Brick","x":0,"y":7,"z":13},{"name":"Rock_Sandstone_Brick","x":0,"y":8,"z":13},{"name":"Rock_Sandstone_Brick","x":0,"y":9,"z":13},{"name":"Rock_Sandstone_Brick","x":0,"y":10,"z":13},{"name":"Rock_Sandstone_Brick","x":0,"y":11,"z":13},{"name":"Rock_Sandstone_Brick","x":0,"y":12,"z":13},{"name":"Rock_Sandstone_Brick","x":0,"y":13,"z":13},{"name":"Rock_Sandstone_Brick","x":1,"y":3,"z":11},{"name":"Rock_Sandstone_Brick","x":1,"y":4,"z":11},{"name":"Rock_Sandstone_Brick","x":1,"y":5,"z":11},{"name":"Rock_Sandstone_Brick","x":1,"y":6,"z":11},{"name":"Rock_Sandstone_Brick","x":1,"y":7,"z":11},{"name":"Rock_Sandstone_Brick","x":1,"y":8,"z":11},{"name":"Rock_Sandstone_Brick","x":1,"y":9,"z":11},{"name":"Rock_Sandstone_Brick","x":1,"y":10,"z":11},{"name":"Rock_Sandstone_Brick","x":1,"y":11,"z":11},{"name":"Rock_Sandstone_Brick","x":1,"y":12,"z":11},{"name":"Soil_Gravel_Sand_White","x":1,"y":3,"z":12},{"name":"Soil_Gravel_Sand_White","x":1,"y":4,"z":12},{"name":"Soil_Gravel_Sand_White","x":1,"y":5,"z":12},{"name":"Soil_Gravel_Sand_White","x":1,"y":6,"z":12},{"name":"Soil_Gravel_Sand_White","x":1,"y":7,"z":12},{"name":"Soil_Gravel_Sand_White","x":1,"y":8,"z":12},{"name":"Soil_Gravel_Sand_White","x":1,"y":9,"z":12},{"name":"Soil_Gravel_Sand_White","x":1,"y":10,"z":12},{"name":"Soil_Gravel_Sand_White","x":1,"y":11,"z":12},{"name":"Soil_Gravel_Sand_White","x":1,"y":12,"z":12},{"name":"Rock_Sandstone_Brick","x":1,"y":3,"z":13},{"name":"Rock_Sandstone_Brick","x":1,"y":4,"z":13},{"name":"Rock_Sandstone_Brick","x":1,"y":5,"z":13},{"name":"Rock_Sandstone_Brick","x":1,"y":6,"z":13},{"name":"Rock_Sandstone_Brick","x":1,"y":7,"z":13},{"name":"Rock_Sandstone_Brick","x":1,"y":8,"z":13},{"name":"Rock_Sandstone_Brick","x":1,"y":9,"z":13},{"name":"Rock_Sandstone_Brick","x":1,"y":10,"z":13},{"name":"Rock_Sandstone_Brick","x":1,"y":11,"z":13},{"name":"Rock_Sandstone_Brick","x":1,"y":12,"z":13},{"name":"Rock_Sandstone_Brick","x":2,"y":3,"z":11},{"name":"Rock_Sandstone_Brick","x":2,"y":4,"z":11},{"name":"Rock_Sandstone_Brick","x":2,"y":5,"z":11},{"name":"Rock_Sandstone_Brick","x":2,"y":6,"z":11},{"name":"Rock_Sandstone_Brick","x":2,"y":7,"z":11},{"name":"Rock_Sandstone_Brick","x":2,"y":8,"z":11},{"name":"Rock_Sandstone_Brick","x":2,"y":9,"z":11},{"name":"Rock_Sandstone_Brick","x":2,"y":10,"z":11},{"name":"Rock_Sandstone_Brick","x":2,"y":11,"z":11},{"name":"Rock_Sandstone_Brick","x":2,"y":12,"z":11},{"name":"Soil_Gravel_Sand_White","x":2,"y":3,"z":12},{"name":"Soil_Gravel_Sand_White","x":2,"y":4,"z":12},{"name":"Soil_Gravel_Sand_White","x":2,"y":5,"z":12},{"name":"Soil_Gravel_Sand_White","x":2,"y":6,"z":12},{"name":"Soil_Gravel_Sand_White","x":2,"y":7,"z":12},{"name":"Soil_Gravel_Sand_White","x":2,"y":8,"z":12},{"name":"Soil_Gravel_Sand_White","x":2,"y":9,"z":12},{"name":"Soil_Gravel_Sand_White","x":2,"y":10,"z":12},{"name":"Soil_Gravel_Sand_White","x":2,"y":11,"z":12},{"name":"Soil_Gravel_Sand_White","x":2,"y":12,"z":12},{"name":"Rock_Sandstone_Brick","x":2,"y":3,"z":13},{"name":"Rock_Sandstone_Brick","x":2,"y":4,"z":13},{"name":"Rock_Sandstone_Brick","x":2,"y":5,"z":13},{"name":"Rock_Sandstone_Brick","x":2,"y":6,"z":13},{"name":"Rock_Sandstone_Brick","x":2,"y":7,"z":13},{"name":"Rock_Sandstone_Brick","x":2,"y":8,"z":13},{"name":"Rock_Sandstone_Brick","x":2,"y":9,"z":13},{"name":"Rock_Sandstone_Brick","x":2,"y":10,"z":13},{"name":"Rock_Sandstone_Brick","x":2,"y":11,"z":13},{"name":"Rock_Sandstone_Brick","x":3,"y":3,"z":4},{"name":"Rock_Sandstone_Brick","x":3,"y":4,"z":4},{"name":"Rock_Sandstone_Brick","x":3,"y":5,"z":4},{"name":"Rock_Sandstone_Brick","x":3,"y":6,"z":4},{"name":"Rock_Sandstone_Brick","x":3,"y":7,"z":4},{"name":"Rock_Sandstone_Brick","x":3,"y":8,"z":4},{"name":"Rock_Sandstone_Brick","x":3,"y":9,"z":4},{"name":"Rock_Sandstone_Brick","x":3,"y":10,"z":4},{"name":"Rock_Sandstone_Brick","x":3,"y":3,"z":5},{"name":"Rock_Sandstone_Brick","x":3,"y":4,"z":5},{"name":"Rock_Sandstone_Brick","x":3,"y":5,"z":5},{"name":"Rock_Sandstone_Brick","x":3,"y":6,"z":5},{"name":"Rock_Sandstone_Brick","x":3,"y":7,"z":5},{"name":"Rock_Sandstone_Brick","x":3,"y":8,"z":5},{"name":"Rock_Sandstone_Brick","x":3,"y":9,"z":5},{"name":"Rock_Sandstone_Brick","x":3,"y":3,"z":6},{"name":"Rock_Sandstone_Brick","x":3,"y":4,"z":6},{"name":"Rock_Sandstone_Brick","x":3,"y":5,"z":6},{"name":"Rock_Sandstone_Brick","x":3,"y":6,"z":6},{"name":"Rock_Sandstone_Brick","x":3,"y":7,"z":6},{"name":"Rock_Sandstone_Brick","x":3,"y":8,"z":6},{"name":"Rock_Sandstone_Brick","x":3,"y":9,"z":6},{"name":"Rock_Sandstone_Brick","x":3,"y":3,"z":7},{"name":"Rock_Sandstone_Brick","x":3,"y":4,"z":7},{"name":"Rock_Sandstone_Brick","x":3,"y":5,"z":7},{"name":"Rock_Sandstone_Brick","x":3,"y":6,"z":7},{"name":"Rock_Sandstone_Brick","x":3,"y":7,"z":7},{"name":"Rock_Sandstone_Brick","x":3,"y":8,"z":7},{"name":"Rock_Sandstone_Brick","x":3,"y":9,"z":7},{"name":"Rock_Sandstone_Brick","x":3,"y":3,"z":8},{"name":"Rock_Sandstone_Brick","x":3,"y":4,"z":8},{"name":"Rock_Sandstone_Brick","x":3,"y":5,"z":8},{"name":"Rock_Sandstone_Brick","x":3,"y":6,"z":8},{"name":"Rock_Sandstone_Brick","x":3,"y":7,"z":8},{"name":"Rock_Sandstone_Brick","x":3,"y":8,"z":8},{"name":"Rock_Sandstone_Brick","x":3,"y":9,"z":8},{"name":"Rock_Sandstone_Brick","x":3,"y":10,"z":8},{"name":"Rock_Sandstone_Brick","x":3,"y":3,"z":9},{"name":"Rock_Sandstone_Brick","x":3,"y":4,"z":9},{"name":"Rock_Sandstone_Brick","x":3,"y":5,"z":9},{"name":"Rock_Sandstone_Brick","x":3,"y":6,"z":9},{"name":"Rock_Sandstone_Brick","x":3,"y":7,"z":9},{"name":"Rock_Sandstone_Brick","x":3,"y":8,"z":9},{"name":"Rock_Sandstone_Brick","x":3,"y":9,"z":9},{"name":"Rock_Sandstone_Brick","x":3,"y":10,"z":9},{"name":"Rock_Sandstone_Brick","x":3,"y":3,"z":10},{"name":"Rock_Sandstone_Brick","x":3,"y":4,"z":10},{"name":"Rock_Sandstone_Brick","x":3,"y":5,"z":10},{"name":"Rock_Sandstone_Brick","x":3,"y":6,"z":10},{"name":"Rock_Sandstone_Brick","x":3,"y":7,"z":10},{"name":"Rock_Sandstone_Brick","x":3,"y":8,"z":10},{"name":"Rock_Sandstone_Brick","x":3,"y":9,"z":10},{"name":"Rock_Sandstone_Brick","x":3,"y":10,"z":10},{"name":"Rock_Sandstone_Brick","x":3,"y":3,"z":11},{"name":"Rock_Sandstone_Brick","x":3,"y":4,"z":11},{"name":"Rock_Sandstone_Brick","x":3,"y":5,"z":11},{"name":"Rock_Sandstone_Brick","x":3,"y":6,"z":11},{"name":"Rock_Sandstone_Brick","x":3,"y":7,"z":11},{"name":"Rock_Sandstone_Brick","x":3,"y":8,"z":11},{"name":"Rock_Sandstone_Brick","x":3,"y":9,"z":11},{"name":"Rock_Sandstone_Brick","x":3,"y":10,"z":11},{"name":"Rock_Sandstone_Brick","x":3,"y":11,"z":11},{"name":"Soil_Gravel_Sand_White","x":3,"y":3,"z":12},{"name":"Soil_Gravel_Sand_White","x":3,"y":4,"z":12},{"name":"Soil_Gravel_Sand_White","x":3,"y":5,"z":12},{"name":"Soil_Gravel_Sand_White","x":3,"y":6,"z":12},{"name":"Soil_Gravel_Sand_White","x":3,"y":7,"z":12},{"name":"Soil_Gravel_Sand_White","x":3,"y":8,"z":12},{"name":"Soil_Gravel_Sand_White","x":3,"y":9,"z":12},{"name":"Soil_Gravel_Sand_White","x":3,"y":10,"z":12},{"name":"Soil_Gravel_Sand_White","x":3,"y":11,"z":12},{"name":"Rock_Sandstone_Brick","x":3,"y":3,"z":13},{"name":"Rock_Sandstone_Brick","x":3,"y":4,"z":13},{"name":"Rock_Sandstone_Brick","x":3,"y":5,"z":13},{"name":"Rock_Sandstone_Brick","x":3,"y":6,"z":13},{"name":"Rock_Sandstone_Brick","x":3,"y":7,"z":13},{"name":"Rock_Sandstone_Brick","x":3,"y":8,"z":13},{"name":"Rock_Sandstone_Brick","x":3,"y":9,"z":13},{"name":"Rock_Sandstone_Brick","x":3,"y":10,"z":13},{"name":"Rock_Sandstone_Brick","x":3,"y":11,"z":13},{"name":"Rock_Sandstone_Brick","x":4,"y":3,"z":4},{"name":"Rock_Sandstone_Brick","x":4,"y":4,"z":4},{"name":"Rock_Sandstone_Brick","x":4,"y":5,"z":4},{"name":"Rock_Sandstone_Brick","x":4,"y":6,"z":4},{"name":"Rock_Sandstone_Brick","x":4,"y":7,"z":4},{"name":"Rock_Sandstone_Brick","x":4,"y":8,"z":4},{"name":"Rock_Sandstone_Brick","x":4,"y":9,"z":4},{"name":"Rock_Sandstone_Brick","x":4,"y":10,"z":4},{"name":"Rock_Sandstone_Brick","x":4,"y":11,"z":4},{"name":"Rock_Sandstone_Brick","x":4,"y":3,"z":11},{"name":"Rock_Sandstone_Brick","x":4,"y":4,"z":11},{"name":"Rock_Sandstone_Brick","x":4,"y":5,"z":11},{"name":"Rock_Sandstone_Brick","x":4,"y":6,"z":11},{"name":"Rock_Sandstone_Brick","x":4,"y":7,"z":11},{"name":"Rock_Sandstone_Brick","x":4,"y":8,"z":11},{"name":"Rock_Sandstone_Brick","x":4,"y":9,"z":11},{"name":"Rock_Sandstone_Brick","x":4,"y":10,"z":11},{"name":"Rock_Sandstone_Brick","x":4,"y":11,"z":11},{"name":"Soil_Gravel_Sand_White","x":4,"y":3,"z":12},{"name":"Soil_Gravel_Sand_White","x":4,"y":4,"z":12},{"name":"Soil_Gravel_Sand_White","x":4,"y":5,"z":12},{"name":"Soil_Gravel_Sand_White","x":4,"y":6,"z":12},{"name":"Soil_Gravel_Sand_White","x":4,"y":7,"z":12},{"name":"Soil_Gravel_Sand_White","x":4,"y":8,"z":12},{"name":"Soil_Gravel_Sand_White","x":4,"y":9,"z":12},{"name":"Soil_Gravel_Sand_White","x":4,"y":10,"z":12},{"name":"Rock_Sandstone_Brick","x":4,"y":3,"z":13},{"name":"Rock_Sandstone_Brick","x":4,"y":4,"z":13},{"name":"Rock_Sandstone_Brick","x":4,"y":5,"z":13},{"name":"Rock_Sandstone_Brick","x":4,"y":6,"z":13},{"name":"Rock_Sandstone_Brick","x":4,"y":7,"z":13},{"name":"Rock_Sandstone_Brick","x":4,"y":8,"z":13},{"name":"Rock_Sandstone_Brick","x":4,"y":9,"z":13},{"name":"Rock_Sandstone_Brick","x":4,"y":10,"z":13},{"name":"Rock_Sandstone_Brick","x":5,"y":3,"z":4},{"name":"Rock_Sandstone_Brick","x":5,"y":4,"z":4},{"name":"Rock_Sandstone_Brick","x":5,"y":5,"z":4},{"name":"Rock_Sandstone_Brick","x":5,"y":6,"z":4},{"name":"Rock_Sandstone_Brick","x":5,"y":7,"z":4},{"name":"Rock_Sandstone_Brick","x":5,"y":8,"z":4},{"name":"Rock_Sandstone_Brick","x":5,"y":9,"z":4},{"name":"Rock_Sandstone_Brick","x":5,"y":10,"z":4},{"name":"Rock_Sandstone_Brick","x":5,"y":11,"z":4},{"name":"Rock_Sandstone_Brick","x":5,"y":12,"z":4},{"name":"Rock_Sandstone_Brick","x":6,"y":3,"z":4},{"name":"Rock_Sandstone_Brick","x":6,"y":4,"z":4},{"name":"Rock_Sandstone_Brick","x":6,"y":5,"z":4},{"name":"Rock_Sandstone_Brick","x":6,"y":6,"z":4},{"name":"Rock_Sandstone_Brick","x":6,"y":7,"z":4},{"name":"Rock_Sandstone_Brick","x":6,"y":8,"z":4},{"name":"Rock_Sandstone_Brick","x":6,"y":9,"z":4},{"name":"Rock_Sandstone_Brick","x":6,"y":10,"z":4},{"name":"Rock_Sandstone_Brick","x":6,"y":11,"z":4},{"name":"Rock_Sandstone_Brick","x":6,"y":12,"z":4},{"name":"Rock_Sandstone_Brick","x":7,"y":3,"z":-9},{"name":"Rock_Sandstone_Brick","x":7,"y":4,"z":-9},{"name":"Rock_Sandstone_Brick","x":7,"y":5,"z":-9},{"name":"Rock_Sandstone_Brick","x":7,"y":6,"z":-9},{"name":"Rock_Sandstone_Brick","x":7,"y":7,"z":-9},{"name":"Rock_Sandstone_Brick","x":7,"y":8,"z":-9},{"name":"Rock_Sandstone_Brick","x":7,"y":9,"z":-9},{"name":"Soil_Gravel_Sand_White","x":7,"y":3,"z":-8},{"name":"Soil_Gravel_Sand_White","x":7,"y":4,"z":-8},{"name":"Soil_Gravel_Sand_White","x":7,"y":5,"z":-8},{"name":"Soil_Gravel_Sand_White","x":7,"y":6,"z":-8},{"name":"Soil_Gravel_Sand_White","x":7,"y":7,"z":-8},{"name":"Soil_Gravel_Sand_White","x":7,"y":8,"z":-8},{"name":"Soil_Gravel_Sand_White","x":7,"y":9,"z":-8},{"name":"Soil_Gravel_Sand_White","x":7,"y":10,"z":-8},{"name":"Rock_Sandstone_Brick","x":7,"y":3,"z":-7},{"name":"Rock_Sandstone_Brick","x":7,"y":4,"z":-7},{"name":"Rock_Sandstone_Brick","x":7,"y":5,"z":-7},{"name":"Rock_Sandstone_Brick","x":7,"y":6,"z":-7},{"name":"Rock_Sandstone_Brick","x":7,"y":7,"z":-7},{"name":"Rock_Sandstone_Brick","x":7,"y":8,"z":-7},{"name":"Rock_Sandstone_Brick","x":7,"y":9,"z":-7},{"name":"Rock_Sandstone_Brick","x":7,"y":10,"z":-7},{"name":"Rock_Sandstone_Brick","x":7,"y":3,"z":4},{"name":"Rock_Sandstone_Brick","x":7,"y":4,"z":4},{"name":"Rock_Sandstone_Brick","x":7,"y":5,"z":4},{"name":"Rock_Sandstone_Brick","x":7,"y":6,"z":4},{"name":"Rock_Sandstone_Brick","x":7,"y":7,"z":4},{"name":"Rock_Sandstone_Brick","x":7,"y":8,"z":4},{"name":"Rock_Sandstone_Brick","x":7,"y":9,"z":4},{"name":"Rock_Sandstone_Brick","x":7,"y":10,"z":4},{"name":"Rock_Sandstone_Brick","x":7,"y":11,"z":4},{"name":"Rock_Sandstone_Brick","x":7,"y":12,"z":4},{"name":"Rock_Sandstone_Brick","x":8,"y":3,"z":-9},{"name":"Rock_Sandstone_Brick","x":8,"y":4,"z":-9},{"name":"Rock_Sandstone_Brick","x":8,"y":5,"z":-9},{"name":"Rock_Sandstone_Brick","x":8,"y":6,"z":-9},{"name":"Rock_Sandstone_Brick","x":8,"y":7,"z":-9},{"name":"Rock_Sandstone_Brick","x":8,"y":8,"z":-9},{"name":"Rock_Sandstone_Brick","x":8,"y":9,"z":-9},{"name":"Rock_Sandstone_Brick","x":8,"y":10,"z":-9},{"name":"Soil_Gravel_Sand_White","x":8,"y":3,"z":-8},{"name":"Soil_Gravel_Sand_White","x":8,"y":4,"z":-8},{"name":"Soil_Gravel_Sand_White","x":8,"y":5,"z":-8},{"name":"Soil_Gravel_Sand_White","x":8,"y":6,"z":-8},{"name":"Soil_Gravel_Sand_White","x":8,"y":7,"z":-8},{"name":"Soil_Gravel_Sand_White","x":8,"y":8,"z":-8},{"name":"Soil_Gravel_Sand_White","x":8,"y":9,"z":-8},{"name":"Soil_Gravel_Sand_White","x":8,"y":10,"z":-8},{"name":"Rock_Sandstone_Brick","x":8,"y":3,"z":-7},{"name":"Rock_Sandstone_Brick","x":8,"y":4,"z":-7},{"name":"Rock_Sandstone_Brick","x":8,"y":5,"z":-7},{"name":"Rock_Sandstone_Brick","x":8,"y":6,"z":-7},{"name":"Rock_Sandstone_Brick","x":8,"y":7,"z":-7},{"name":"Rock_Sandstone_Brick","x":8,"y":8,"z":-7},{"name":"Rock_Sandstone_Brick","x":8,"y":9,"z":-7},{"name":"Rock_Sandstone_Brick","x":8,"y":10,"z":-7},{"name":"Rock_Sandstone_Brick","x":8,"y":3,"z":4},{"name":"Rock_Sandstone_Brick","x":8,"y":4,"z":4},{"name":"Rock_Sandstone_Brick","x":8,"y":5,"z":4},{"name":"Rock_Sandstone_Brick","x":8,"y":6,"z":4},{"name":"Rock_Sandstone_Brick","x":8,"y":7,"z":4},{"name":"Rock_Sandstone_Brick","x":8,"y":8,"z":4},{"name":"Rock_Sandstone_Brick","x":8,"y":9,"z":4},{"name":"Rock_Sandstone_Brick","x":8,"y":10,"z":4},{"name":"Rock_Sandstone_Brick","x":9,"y":3,"z":-9},{"name":"Rock_Sandstone_Brick","x":9,"y":4,"z":-9},{"name":"Rock_Sandstone_Brick","x":9,"y":5,"z":-9},{"name":"Rock_Sandstone_Brick","x":9,"y":6,"z":-9},{"name":"Rock_Sandstone_Brick","x":9,"y":7,"z":-9},{"name":"Rock_Sandstone_Brick","x":9,"y":8,"z":-9},{"name":"Rock_Sandstone_Brick","x":9,"y":9,"z":-9},{"name":"Rock_Sandstone_Brick","x":9,"y":10,"z":-9},{"name":"Soil_Gravel_Sand_White","x":9,"y":3,"z":-8},{"name":"Soil_Gravel_Sand_White","x":9,"y":4,"z":-8},{"name":"Soil_Gravel_Sand_White","x":9,"y":5,"z":-8},{"name":"Soil_Gravel_Sand_White","x":9,"y":6,"z":-8},{"name":"Soil_Gravel_Sand_White","x":9,"y":7,"z":-8},{"name":"Soil_Gravel_Sand_White","x":9,"y":8,"z":-8},{"name":"Soil_Gravel_Sand_White","x":9,"y":9,"z":-8},{"name":"Soil_Gravel_Sand_White","x":9,"y":10,"z":-8},{"name":"Soil_Gravel_Sand_White","x":9,"y":11,"z":-8},{"name":"Rock_Sandstone_Brick","x":9,"y":3,"z":-7},{"name":"Rock_Sandstone_Brick","x":9,"y":4,"z":-7},{"name":"Rock_Sandstone_Brick","x":9,"y":5,"z":-7},{"name":"Rock_Sandstone_Brick","x":9,"y":6,"z":-7},{"name":"Rock_Sandstone_Brick","x":9,"y":7,"z":-7},{"name":"Rock_Sandstone_Brick","x":9,"y":8,"z":-7},{"name":"Rock_Sandstone_Brick","x":9,"y":9,"z":-7},{"name":"Rock_Sandstone_Brick","x":9,"y":10,"z":-7},{"name":"Rock_Sandstone_Brick","x":9,"y":3,"z":4},{"name":"Rock_Sandstone_Brick","x":9,"y":4,"z":4},{"name":"Rock_Sandstone_Brick","x":9,"y":5,"z":4},{"name":"Rock_Sandstone_Brick","x":9,"y":6,"z":4},{"name":"Rock_Sandstone_Brick","x":9,"y":7,"z":4},{"name":"Rock_Sandstone_Brick","x":9,"y":8,"z":4},{"name":"Rock_Sandstone_Brick","x":10,"y":3,"z":-9},{"name":"Rock_Sandstone_Brick","x":10,"y":4,"z":-9},{"name":"Rock_Sandstone_Brick","x":10,"y":5,"z":-9},{"name":"Rock_Sandstone_Brick","x":10,"y":6,"z":-9},{"name":"Rock_Sandstone_Brick","x":10,"y":7,"z":-9},{"name":"Rock_Sandstone_Brick","x":10,"y":8,"z":-9},{"name":"Rock_Sandstone_Brick","x":10,"y":9,"z":-9},{"name":"Rock_Sandstone_Brick","x":10,"y":10,"z":-9},{"name":"Soil_Gravel_Sand_White","x":10,"y":3,"z":-8},{"name":"Soil_Gravel_Sand_White","x":10,"y":4,"z":-8},{"name":"Soil_Gravel_Sand_White","x":10,"y":5,"z":-8},{"name":"Soil_Gravel_Sand_White","x":10,"y":6,"z":-8},{"name":"Soil_Gravel_Sand_White","x":10,"y":7,"z":-8},{"name":"Soil_Gravel_Sand_White","x":10,"y":8,"z":-8},{"name":"Soil_Gravel_Sand_White","x":10,"y":9,"z":-8},{"name":"Soil_Gravel_Sand_White","x":10,"y":10,"z":-8},{"name":"Soil_Gravel_Sand_White","x":10,"y":11,"z":-8},{"name":"Rock_Sandstone_Brick","x":10,"y":3,"z":-7},{"name":"Rock_Sandstone_Brick","x":10,"y":4,"z":-7},{"name":"Rock_Sandstone_Brick","x":10,"y":5,"z":-7},{"name":"Rock_Sandstone_Brick","x":10,"y":6,"z":-7},{"name":"Rock_Sandstone_Brick","x":10,"y":7,"z":-7},{"name":"Rock_Sandstone_Brick","x":10,"y":8,"z":-7},{"name":"Rock_Sandstone_Brick","x":10,"y":9,"z":-7},{"name":"Rock_Sandstone_Brick","x":10,"y":10,"z":-7},{"name":"Rock_Sandstone_Brick","x":10,"y":11,"z":-7},{"name":"Rock_Sandstone_Brick","x":11,"y":3,"z":-9},{"name":"Rock_Sandstone_Brick","x":11,"y":4,"z":-9},{"name":"Rock_Sandstone_Brick","x":11,"y":5,"z":-9},{"name":"Rock_Sandstone_Brick","x":11,"y":6,"z":-9},{"name":"Rock_Sandstone_Brick","x":11,"y":7,"z":-9},{"name":"Rock_Sandstone_Brick","x":11,"y":8,"z":-9},{"name":"Rock_Sandstone_Brick","x":11,"y":9,"z":-9},{"name":"Rock_Sandstone_Brick","x":11,"y":10,"z":-9},{"name":"Rock_Sandstone_Brick","x":11,"y":11,"z":-9},{"name":"Soil_Gravel_Sand_White","x":11,"y":3,"z":-8},{"name":"Soil_Gravel_Sand_White","x":11,"y":4,"z":-8},{"name":"Soil_Gravel_Sand_White","x":11,"y":5,"z":-8},{"name":"Soil_Gravel_Sand_White","x":11,"y":6,"z":-8},{"name":"Soil_Gravel_Sand_White","x":11,"y":7,"z":-8},{"name":"Soil_Gravel_Sand_White","x":11,"y":8,"z":-8},{"name":"Soil_Gravel_Sand_White","x":11,"y":9,"z":-8},{"name":"Soil_Gravel_Sand_White","x":11,"y":10,"z":-8},{"name":"Soil_Gravel_Sand_White","x":11,"y":11,"z":-8},{"name":"Rock_Sandstone_Brick","x":11,"y":3,"z":-7},{"name":"Rock_Sandstone_Brick","x":11,"y":4,"z":-7},{"name":"Rock_Sandstone_Brick","x":11,"y":5,"z":-7},{"name":"Rock_Sandstone_Brick","x":11,"y":6,"z":-7},{"name":"Rock_Sandstone_Brick","x":11,"y":7,"z":-7},{"name":"Rock_Sandstone_Brick","x":11,"y":8,"z":-7},{"name":"Rock_Sandstone_Brick","x":11,"y":9,"z":-7},{"name":"Rock_Sandstone_Brick","x":11,"y":10,"z":-7},{"name":"Rock_Sandstone_Brick","x":11,"y":11,"z":-7},{"name":"Rock_Sandstone_Brick","x":11,"y":3,"z":-6},{"name":"Rock_Sandstone_Brick","x":11,"y":4,"z":-6},{"name":"Rock_Sandstone_Brick","x":11,"y":5,"z":-6},{"name":"Rock_Sandstone_Brick","x":11,"y":6,"z":-6},{"name":"Rock_Sandstone_Brick","x":11,"y":7,"z":-6},{"name":"Rock_Sandstone_Brick","x":11,"y":8,"z":-6},{"name":"Rock_Sandstone_Brick","x":11,"y":9,"z":-6},{"name":"Rock_Sandstone_Brick","x":11,"y":10,"z":-6},{"name":"Rock_Sandstone_Brick","x":11,"y":3,"z":-5},{"name":"Rock_Sandstone_Brick","x":11,"y":4,"z":-5},{"name":"Rock_Sandstone_Brick","x":11,"y":5,"z":-5},{"name":"Rock_Sandstone_Brick","x":11,"y":6,"z":-5},{"name":"Rock_Sandstone_Brick","x":11,"y":7,"z":-5},{"name":"Rock_Sandstone_Brick","x":11,"y":8,"z":-5},{"name":"Rock_Sandstone_Brick","x":11,"y":9,"z":-5},{"name":"Rock_Sandstone_Brick","x":11,"y":10,"z":-5},{"name":"Rock_Sandstone_Brick","x":11,"y":3,"z":-4},{"name":"Rock_Sandstone_Brick","x":11,"y":4,"z":-4},{"name":"Rock_Sandstone_Brick","x":11,"y":5,"z":-4},{"name":"Rock_Sandstone_Brick","x":11,"y":6,"z":-4},{"name":"Rock_Sandstone_Brick","x":11,"y":7,"z":-4},{"name":"Rock_Sandstone_Brick","x":11,"y":8,"z":-4},{"name":"Rock_Sandstone_Brick","x":11,"y":9,"z":-4},{"name":"Rock_Sandstone_Brick","x":11,"y":3,"z":-3},{"name":"Rock_Sandstone_Brick","x":11,"y":4,"z":-3},{"name":"Rock_Sandstone_Brick","x":11,"y":5,"z":-3},{"name":"Rock_Sandstone_Brick","x":11,"y":6,"z":-3},{"name":"Rock_Sandstone_Brick","x":11,"y":7,"z":-3},{"name":"Rock_Sandstone_Brick","x":11,"y":8,"z":-3},{"name":"Rock_Sandstone_Brick","x":11,"y":9,"z":-3},{"name":"Rock_Sandstone_Brick_Smooth_Half","rotation":6,"x":12,"y":3,"z":-10},{"name":"Rock_Sandstone_Brick_Smooth_Half","rotation":6,"x":12,"y":4,"z":-10},{"name":"Rock_Sandstone_Brick_Smooth_Half","rotation":6,"x":12,"y":6,"z":-10},{"name":"Rock_Sandstone_Brick_Smooth_Half","rotation":6,"x":12,"y":7,"z":-10},{"name":"Rock_Sandstone_Brick_Smooth_Half","rotation":6,"x":12,"y":9,"z":-10},{"name":"Rock_Sandstone_Brick_Smooth_Half","rotation":6,"x":12,"y":10,"z":-10},{"name":"Rock_Sandstone_Brick","x":12,"y":3,"z":-9},{"name":"Rock_Sandstone_Brick","x":12,"y":4,"z":-9},{"name":"Rock_Sandstone_Brick","x":12,"y":5,"z":-9},{"name":"Rock_Sandstone_Brick","x":12,"y":6,"z":-9},{"name":"Rock_Sandstone_Brick","x":12,"y":7,"z":-9},{"name":"Rock_Sandstone_Brick","x":12,"y":8,"z":-9},{"name":"Rock_Sandstone_Brick","x":12,"y":9,"z":-9},{"name":"Rock_Sandstone_Brick","x":12,"y":10,"z":-9},{"name":"Rock_Sandstone_Brick","x":12,"y":11,"z":-9},{"name":"Soil_Gravel_Sand_White","x":12,"y":3,"z":-8},{"name":"Soil_Gravel_Sand_White","x":12,"y":4,"z":-8},{"name":"Soil_Gravel_Sand_White","x":12,"y":5,"z":-8},{"name":"Soil_Gravel_Sand_White","x":12,"y":6,"z":-8},{"name":"Soil_Gravel_Sand_White","x":12,"y":7,"z":-8},{"name":"Soil_Gravel_Sand_White","x":12,"y":8,"z":-8},{"name":"Soil_Gravel_Sand_White","x":12,"y":9,"z":-8},{"name":"Soil_Gravel_Sand_White","x":12,"y":10,"z":-8},{"name":"Soil_Gravel_Sand_White","x":12,"y":11,"z":-8},{"name":"Soil_Gravel_Sand_White","x":12,"y":3,"z":-7},{"name":"Soil_Gravel_Sand_White","x":12,"y":4,"z":-7},{"name":"Soil_Gravel_Sand_White","x":12,"y":5,"z":-7},{"name":"Soil_Gravel_Sand_White","x":12,"y":6,"z":-7},{"name":"Soil_Gravel_Sand_White","x":12,"y":7,"z":-7},{"name":"Soil_Gravel_Sand_White","x":12,"y":8,"z":-7},{"name":"Soil_Gravel_Sand_White","x":12,"y":9,"z":-7},{"name":"Soil_Gravel_Sand_White","x":12,"y":10,"z":-7},{"name":"Soil_Gravel_Sand_White","x":12,"y":3,"z":-6},{"name":"Soil_Gravel_Sand_White","x":12,"y":4,"z":-6},{"name":"Soil_Gravel_Sand_White","x":12,"y":5,"z":-6},{"name":"Soil_Gravel_Sand_White","x":12,"y":6,"z":-6},{"name":"Soil_Gravel_Sand_White","x":12,"y":7,"z":-6},{"name":"Soil_Gravel_Sand_White","x":12,"y":8,"z":-6},{"name":"Soil_Gravel_Sand_White","x":12,"y":9,"z":-6},{"name":"Soil_Gravel_Sand_White","x":12,"y":10,"z":-6},{"name":"Soil_Gravel_Sand_White","x":12,"y":3,"z":-5},{"name":"Soil_Gravel_Sand_White","x":12,"y":4,"z":-5},{"name":"Soil_Gravel_Sand_White","x":12,"y":5,"z":-5},{"name":"Soil_Gravel_Sand_White","x":12,"y":6,"z":-5},{"name":"Soil_Gravel_Sand_White","x":12,"y":7,"z":-5},{"name":"Soil_Gravel_Sand_White","x":12,"y":8,"z":-5},{"name":"Soil_Gravel_Sand_White","x":12,"y":9,"z":-5},{"name":"Soil_Gravel_Sand_White","x":12,"y":10,"z":-5},{"name":"Soil_Gravel_Sand_White","x":12,"y":3,"z":-4},{"name":"Soil_Gravel_Sand_White","x":12,"y":4,"z":-4},{"name":"Soil_Gravel_Sand_White","x":12,"y":5,"z":-4},{"name":"Soil_Gravel_Sand_White","x":12,"y":6,"z":-4},{"name":"Soil_Gravel_Sand_White","x":12,"y":7,"z":-4},{"name":"Soil_Gravel_Sand_White","x":12,"y":8,"z":-4},{"name":"Soil_Gravel_Sand_White","x":12,"y":9,"z":-4},{"name":"Soil_Gravel_Sand_White","x":12,"y":3,"z":-3},{"name":"Soil_Gravel_Sand_White","x":12,"y":4,"z":-3},{"name":"Soil_Gravel_Sand_White","x":12,"y":5,"z":-3},{"name":"Soil_Gravel_Sand_White","x":12,"y":6,"z":-3},{"name":"Soil_Gravel_Sand_White","x":12,"y":7,"z":-3},{"name":"Soil_Gravel_Sand_White","x":12,"y":8,"z":-3},{"name":"Soil_Gravel_Sand_White","x":12,"y":9,"z":-3},{"name":"Rock_Sandstone_Brick_Smooth_Half","rotation":6,"x":13,"y":3,"z":-10},{"name":"Rock_Sandstone_Brick_Smooth_Half","rotation":6,"x":13,"y":4,"z":-10},{"name":"Rock_Sandstone_Brick_Smooth_Half","rotation":6,"x":13,"y":6,"z":-10},{"name":"Rock_Sandstone_Brick_Smooth_Half","rotation":6,"x":13,"y":7,"z":-10},{"name":"Rock_Sandstone_Brick_Smooth_Half","rotation":6,"x":13,"y":9,"z":-10},{"name":"Rock_Sandstone_Brick_Smooth_Half","rotation":6,"x":13,"y":10,"z":-10},{"name":"Rock_Sandstone_Brick_Smooth","x":13,"y":3,"z":-9},{"name":"Rock_Sandstone_Brick_Smooth","x":13,"y":4,"z":-9},{"name":"Rock_Sandstone_Brick_Smooth","x":13,"y":5,"z":-9},{"name":"Rock_Sandstone_Brick_Smooth","x":13,"y":6,"z":-9},{"name":"Rock_Sandstone_Brick_Smooth","x":13,"y":7,"z":-9},{"name":"Rock_Sandstone_Brick_Smooth","x":13,"y":8,"z":-9},{"name":"Rock_Sandstone_Brick_Smooth","x":13,"y":9,"z":-9},{"name":"Rock_Sandstone_Brick_Smooth","x":13,"y":10,"z":-9},{"name":"Rock_Sandstone_Brick","x":13,"y":3,"z":-8},{"name":"Rock_Sandstone_Brick","x":13,"y":4,"z":-8},{"name":"Rock_Sandstone_Brick","x":13,"y":5,"z":-8},{"name":"Rock_Sandstone_Brick","x":13,"y":6,"z":-8},{"name":"Rock_Sandstone_Brick","x":13,"y":7,"z":-8},{"name":"Rock_Sandstone_Brick","x":13,"y":8,"z":-8},{"name":"Rock_Sandstone_Brick","x":13,"y":9,"z":-8},{"name":"Rock_Sandstone_Brick","x":13,"y":10,"z":-8},{"name":"Rock_Sandstone_Brick","x":13,"y":3,"z":-7},{"name":"Rock_Sandstone_Brick","x":13,"y":4,"z":-7},{"name":"Rock_Sandstone_Brick","x":13,"y":5,"z":-7},{"name":"Rock_Sandstone_Brick","x":13,"y":6,"z":-7},{"name":"Rock_Sandstone_Brick","x":13,"y":7,"z":-7},{"name":"Rock_Sandstone_Brick","x":13,"y":8,"z":-7},{"name":"Rock_Sandstone_Brick","x":13,"y":9,"z":-7},{"name":"Rock_Sandstone_Brick","x":13,"y":10,"z":-7},{"name":"Rock_Sandstone_Brick","x":13,"y":3,"z":-6},{"name":"Rock_Sandstone_Brick","x":13,"y":4,"z":-6},{"name":"Rock_Sandstone_Brick","x":13,"y":5,"z":-6},{"name":"Rock_Sandstone_Brick","x":13,"y":6,"z":-6},{"name":"Rock_Sandstone_Brick","x":13,"y":7,"z":-6},{"name":"Rock_Sandstone_Brick","x":13,"y":8,"z":-6},{"name":"Rock_Sandstone_Brick","x":13,"y":9,"z":-6},{"name":"Rock_Sandstone_Brick","x":13,"y":10,"z":-6},{"name":"Rock_Sandstone_Brick","x":13,"y":3,"z":-5},{"name":"Rock_Sandstone_Brick","x":13,"y":4,"z":-5},{"name":"Rock_Sandstone_Brick","x":13,"y":5,"z":-5},{"name":"Rock_Sandstone_Brick","x":13,"y":6,"z":-5},{"name":"Rock_Sandstone_Brick","x":13,"y":7,"z":-5},{"name":"Rock_Sandstone_Brick","x":13,"y":8,"z":-5},{"name":"Rock_Sandstone_Brick","x":13,"y":9,"z":-5},{"name":"Rock_Sandstone_Brick","x":13,"y":3,"z":-4},{"name":"Rock_Sandstone_Brick","x":13,"y":4,"z":-4},{"name":"Rock_Sandstone_Brick","x":13,"y":5,"z":-4},{"name":"Rock_Sandstone_Brick","x":13,"y":6,"z":-4},{"name":"Rock_Sandstone_Brick","x":13,"y":7,"z":-4},{"name":"Rock_Sandstone_Brick","x":13,"y":8,"z":-4},{"name":"Rock_Sandstone_Brick","x":13,"y":9,"z":-4},{"name":"Rock_Sandstone_Brick","x":13,"y":3,"z":-3},{"name":"Rock_Sandstone_Brick","x":13,"y":4,"z":-3},{"name":"Rock_Sandstone_Brick","x":13,"y":5,"z":-3},{"name":"Rock_Sandstone_Brick","x":13,"y":6,"z":-3},{"name":"Rock_Sandstone_Brick","x":13,"y":7,"z":-3},{"name":"Rock_Sandstone_Brick","x":13,"y":8,"z":-3},{"name":"Rock_Sandstone_Brick_Smooth_Half","rotation":5,"x":14,"y":3,"z":-9},{"name":"Rock_Sandstone_Brick_Smooth_Half","rotation":5,"x":14,"y":4,"z":-9},{"name":"Rock_Sandstone_Brick_Smooth_Half","rotation":5,"x":14,"y":6,"z":-9},{"name":"Rock_Sandstone_Brick_Smooth_Half","rotation":5,"x":14,"y":7,"z":-9},{"name":"Rock_Sandstone_Brick_Smooth_Half","rotation":5,"x":14,"y":9,"z":-9},{"name":"Rock_Sandstone_Brick_Smooth_Half","rotation":5,"x":14,"y":10,"z":-9},{"name":"Rock_Sandstone_Brick_Smooth_Half","rotation":5,"x":14,"y":3,"z":-8},{"name":"Rock_Sandstone_Brick_Smooth_Half","rotation":5,"x":14,"y":4,"z":-8},{"name":"Rock_Sandstone_Brick_Smooth_Half","rotation":5,"x":14,"y":6,"z":-8},{"name":"Rock_Sandstone_Brick_Smooth_Half","rotation":5,"x":14,"y":7,"z":-8},{"name":"Rock_Sandstone_Brick_Smooth_Half","rotation":5,"x":14,"y":9,"z":-8},{"name":"Rock_Sandstone_Brick_Smooth_Half","rotation":5,"x":14,"y":10,"z":-8}],"fluids":[{"level":1,"name":"-y","x":-10,"y":3,"z":12},{"level":1,"name":"-y","x":-10,"y":4,"z":12},{"level":1,"name":"-y","x":-10,"y":6,"z":12},{"level":1,"name":"-y","x":-10,"y":7,"z":12},{"level":1,"name":"-y","x":-10,"y":9,"z":12},{"level":1,"name":"-y","x":-10,"y":10,"z":12},{"level":1,"name":"-y","x":-10,"y":3,"z":13},{"level":1,"name":"-y","x":-10,"y":4,"z":13},{"level":1,"name":"-y","x":-10,"y":6,"z":13},{"level":1,"name":"-y","x":-10,"y":7,"z":13},{"level":1,"name":"-y","x":-10,"y":9,"z":13},{"level":1,"name":"-y","x":-10,"y":10,"z":13},{"level":1,"name":"-y","x":-9,"y":3,"z":0},{"level":1,"name":"-y","x":-9,"y":4,"z":0},{"level":1,"name":"-y","x":-9,"y":5,"z":0},{"level":1,"name":"-y","x":-9,"y":6,"z":0},{"level":1,"name":"-y","x":-9,"y":7,"z":0},{"level":1,"name":"-y","x":-9,"y":8,"z":0},{"level":1,"name":"-y","x":-9,"y":3,"z":1},{"level":1,"name":"-y","x":-9,"y":4,"z":1},{"level":1,"name":"-y","x":-9,"y":5,"z":1},{"level":1,"name":"-y","x":-9,"y":6,"z":1},{"level":1,"name":"-y","x":-9,"y":7,"z":1},{"level":1,"name":"-y","x":-9,"y":8,"z":1},{"level":1,"name":"-y","x":-9,"y":9,"z":1},{"level":1,"name":"-y","x":-9,"y":10,"z":1},{"level":1,"name":"-y","x":-9,"y":3,"z":2},{"level":1,"name":"-y","x":-9,"y":4,"z":2},{"level":1,"name":"-y","x":-9,"y":5,"z":2},{"level":1,"name":"-y","x":-9,"y":6,"z":2},{"level":1,"name":"-y","x":-9,"y":7,"z":2},{"level":1,"name":"-y","x":-9,"y":8,"z":2},{"level":1,"name":"-y","x":-9,"y":3,"z":3},{"level":1,"name":"-y","x":-9,"y":4,"z":3},{"level":1,"name":"-y","x":-9,"y":5,"z":3},{"level":1,"name":"-y","x":-9,"y":6,"z":3},{"level":1,"name":"-y","x":-9,"y":7,"z":3},{"level":1,"name":"-y","x":-9,"y":8,"z":3},{"level":1,"name":"-y","x":-9,"y":3,"z":4},{"level":1,"name":"-y","x":-9,"y":4,"z":4},{"level":1,"name":"-y","x":-9,"y":5,"z":4},{"level":1,"name":"-y","x":-9,"y":6,"z":4},{"level":1,"name":"-y","x":-9,"y":7,"z":4},{"level":1,"name":"-y","x":-9,"y":8,"z":4},{"level":1,"name":"-y","x":-9,"y":3,"z":5},{"level":1,"name":"-y","x":-9,"y":4,"z":5},{"level":1,"name":"-y","x":-9,"y":5,"z":5},{"level":1,"name":"-y","x":-9,"y":6,"z":5},{"level":1,"name":"-y","x":-9,"y":7,"z":5},{"level":1,"name":"-y","x":-9,"y":8,"z":5},{"level":1,"name":"-y","x":-9,"y":11,"z":5},{"level":1,"name":"-y","x":-9,"y":3,"z":6},{"level":1,"name":"-y","x":-9,"y":4,"z":6},{"level":1,"name":"-y","x":-9,"y":5,"z":6},{"level":1,"name":"-y","x":-9,"y":6,"z":6},{"level":1,"name":"-y","x":-9,"y":7,"z":6},{"level":1,"name":"-y","x":-9,"y":8,"z":6},{"level":1,"name":"-y","x":-9,"y":9,"z":6},{"level":1,"name":"-y","x":-9,"y":10,"z":6},{"level":1,"name":"-y","x":-9,"y":11,"z":6},{"level":1,"name":"-y","x":-9,"y":3,"z":7},{"level":1,"name":"-y","x":-9,"y":4,"z":7},{"level":1,"name":"-y","x":-9,"y":5,"z":7},{"level":1,"name":"-y","x":-9,"y":6,"z":7},{"level":1,"name":"-y","x":-9,"y":7,"z":7},{"level":1,"name":"-y","x":-9,"y":8,"z":7},{"level":1,"name":"-y","x":-9,"y":9,"z":7},{"level":1,"name":"-y","x":-9,"y":3,"z":8},{"level":1,"name":"-y","x":-9,"y":4,"z":8},{"level":1,"name":"-y","x":-9,"y":5,"z":8},{"level":1,"name":"-y","x":-9,"y":6,"z":8},{"level":1,"name":"-y","x":-9,"y":7,"z":8},{"level":1,"name":"-y","x":-9,"y":8,"z":8},{"level":1,"name":"-y","x":-9,"y":9,"z":8},{"level":1,"name":"-y","x":-9,"y":3,"z":9},{"level":1,"name":"-y","x":-9,"y":4,"z":9},{"level":1,"name":"-y","x":-9,"y":5,"z":9},{"level":1,"name":"-y","x":-9,"y":6,"z":9},{"level":1,"name":"-y","x":-9,"y":7,"z":9},{"level":1,"name":"-y","x":-9,"y":8,"z":9},{"level":1,"name":"-y","x":-9,"y":9,"z":9},{"level":1,"name":"-y","x":-9,"y":10,"z":9},{"level":1,"name":"-y","x":-9,"y":3,"z":10},{"level":1,"name":"-y","x":-9,"y":4,"z":10},{"level":1,"name":"-y","x":-9,"y":5,"z":10},{"level":1,"name":"-y","x":-9,"y":6,"z":10},{"level":1,"name":"-y","x":-9,"y":7,"z":10},{"level":1,"name":"-y","x":-9,"y":8,"z":10},{"level":1,"name":"-y","x":-9,"y":9,"z":10},{"level":1,"name":"-y","x":-9,"y":10,"z":10},{"level":1,"name":"-y","x":-9,"y":3,"z":11},{"level":1,"name":"-y","x":-9,"y":4,"z":11},{"level":1,"name":"-y","x":-9,"y":5,"z":11},{"level":1,"name":"-y","x":-9,"y":6,"z":11},{"level":1,"name":"-y","x":-9,"y":7,"z":11},{"level":1,"name":"-y","x":-9,"y":8,"z":11},{"level":1,"name":"-y","x":-9,"y":9,"z":11},{"level":1,"name":"-y","x":-9,"y":10,"z":11},{"level":1,"name":"-y","x":-9,"y":11,"z":11},{"level":1,"name":"-y","x":-9,"y":3,"z":12},{"level":1,"name":"-y","x":-9,"y":4,"z":12},{"level":1,"name":"-y","x":-9,"y":5,"z":12},{"level":1,"name":"-y","x":-9,"y":6,"z":12},{"level":1,"name":"-y","x":-9,"y":7,"z":12},{"level":1,"name":"-y","x":-9,"y":8,"z":12},{"level":1,"name":"-y","x":-9,"y":9,"z":12},{"level":1,"name":"-y","x":-9,"y":10,"z":12},{"level":1,"name":"-y","x":-9,"y":11,"z":12},{"level":1,"name":"-y","x":-9,"y":3,"z":13},{"level":1,"name":"-y","x":-9,"y":4,"z":13},{"level":1,"name":"-y","x":-9,"y":5,"z":13},{"level":1,"name":"-y","x":-9,"y":6,"z":13},{"level":1,"name":"-y","x":-9,"y":7,"z":13},{"level":1,"name":"-y","x":-9,"y":8,"z":13},{"level":1,"name":"-y","x":-9,"y":9,"z":13},{"level":1,"name":"-y","x":-9,"y":10,"z":13},{"level":1,"name":"-y","x":-9,"y":11,"z":13},{"level":1,"name":"-y","x":-9,"y":3,"z":14},{"level":1,"name":"-y","x":-9,"y":4,"z":14},{"level":1,"name":"-y","x":-9,"y":6,"z":14},{"level":1,"name":"-y","x":-9,"y":7,"z":14},{"level":1,"name":"-y","x":-9,"y":9,"z":14},{"level":1,"name":"-y","x":-9,"y":10,"z":14},{"level":1,"name":"-y","x":-8,"y":3,"z":0},{"level":1,"name":"-y","x":-8,"y":4,"z":0},{"level":1,"name":"-y","x":-8,"y":5,"z":0},{"level":1,"name":"-y","x":-8,"y":6,"z":0},{"level":1,"name":"-y","x":-8,"y":7,"z":0},{"level":1,"name":"-y","x":-8,"y":8,"z":0},{"level":1,"name":"-y","x":-8,"y":9,"z":0},{"level":1,"name":"-y","x":-8,"y":3,"z":1},{"level":1,"name":"-y","x":-8,"y":4,"z":1},{"level":1,"name":"-y","x":-8,"y":5,"z":1},{"level":1,"name":"-y","x":-8,"y":6,"z":1},{"level":1,"name":"-y","x":-8,"y":7,"z":1},{"level":1,"name":"-y","x":-8,"y":8,"z":1},{"level":1,"name":"-y","x":-8,"y":9,"z":1},{"level":1,"name":"-y","x":-8,"y":10,"z":1},{"level":1,"name":"-y","x":-8,"y":3,"z":2},{"level":1,"name":"-y","x":-8,"y":4,"z":2},{"level":1,"name":"-y","x":-8,"y":5,"z":2},{"level":1,"name":"-y","x":-8,"y":6,"z":2},{"level":1,"name":"-y","x":-8,"y":7,"z":2},{"level":1,"name":"-y","x":-8,"y":8,"z":2},{"level":1,"name":"-y","x":-8,"y":9,"z":2},{"level":1,"name":"-y","x":-8,"y":10,"z":2},{"level":1,"name":"-y","x":-8,"y":11,"z":2},{"level":1,"name":"-y","x":-8,"y":3,"z":3},{"level":1,"name":"-y","x":-8,"y":4,"z":3},{"level":1,"name":"-y","x":-8,"y":5,"z":3},{"level":1,"name":"-y","x":-8,"y":6,"z":3},{"level":1,"name":"-y","x":-8,"y":7,"z":3},{"level":1,"name":"-y","x":-8,"y":8,"z":3},{"level":1,"name":"-y","x":-8,"y":9,"z":3},{"level":1,"name":"-y","x":-8,"y":3,"z":4},{"level":1,"name":"-y","x":-8,"y":4,"z":4},{"level":1,"name":"-y","x":-8,"y":5,"z":4},{"level":1,"name":"-y","x":-8,"y":6,"z":4},{"level":1,"name":"-y","x":-8,"y":7,"z":4},{"level":1,"name":"-y","x":-8,"y":8,"z":4},{"level":1,"name":"-y","x":-8,"y":9,"z":4},{"level":1,"name":"-y","x":-8,"y":3,"z":5},{"level":1,"name":"-y","x":-8,"y":4,"z":5},{"level":1,"name":"-y","x":-8,"y":5,"z":5},{"level":1,"name":"-y","x":-8,"y":6,"z":5},{"level":1,"name":"-y","x":-8,"y":7,"z":5},{"level":1,"name":"-y","x":-8,"y":8,"z":5},{"level":1,"name":"-y","x":-8,"y":9,"z":5},{"level":1,"name":"-y","x":-8,"y":10,"z":5},{"level":1,"name":"-y","x":-8,"y":11,"z":5},{"level":1,"name":"-y","x":-8,"y":3,"z":6},{"level":1,"name":"-y","x":-8,"y":4,"z":6},{"level":1,"name":"-y","x":-8,"y":5,"z":6},{"level":1,"name":"-y","x":-8,"y":6,"z":6},{"level":1,"name":"-y","x":-8,"y":7,"z":6},{"level":1,"name":"-y","x":-8,"y":8,"z":6},{"level":1,"name":"-y","x":-8,"y":9,"z":6},{"level":1,"name":"-y","x":-8,"y":10,"z":6},{"level":1,"name":"-y","x":-8,"y":11,"z":6},{"level":1,"name":"-y","x":-8,"y":3,"z":7},{"level":1,"name":"-y","x":-8,"y":4,"z":7},{"level":1,"name":"-y","x":-8,"y":5,"z":7},{"level":1,"name":"-y","x":-8,"y":6,"z":7},{"level":1,"name":"-y","x":-8,"y":7,"z":7},{"level":1,"name":"-y","x":-8,"y":8,"z":7},{"level":1,"name":"-y","x":-8,"y":9,"z":7},{"level":1,"name":"-y","x":-8,"y":3,"z":8},{"level":1,"name":"-y","x":-8,"y":4,"z":8},{"level":1,"name":"-y","x":-8,"y":5,"z":8},{"level":1,"name":"-y","x":-8,"y":6,"z":8},{"level":1,"name":"-y","x":-8,"y":7,"z":8},{"level":1,"name":"-y","x":-8,"y":8,"z":8},{"level":1,"name":"-y","x":-8,"y":9,"z":8},{"level":1,"name":"-y","x":-8,"y":10,"z":8},{"level":1,"name":"-y","x":-8,"y":3,"z":9},{"level":1,"name":"-y","x":-8,"y":4,"z":9},{"level":1,"name":"-y","x":-8,"y":5,"z":9},{"level":1,"name":"-y","x":-8,"y":6,"z":9},{"level":1,"name":"-y","x":-8,"y":7,"z":9},{"level":1,"name":"-y","x":-8,"y":8,"z":9},{"level":1,"name":"-y","x":-8,"y":9,"z":9},{"level":1,"name":"-y","x":-8,"y":10,"z":9},{"level":1,"name":"-y","x":-8,"y":3,"z":10},{"level":1,"name":"-y","x":-8,"y":4,"z":10},{"level":1,"name":"-y","x":-8,"y":5,"z":10},{"level":1,"name":"-y","x":-8,"y":6,"z":10},{"level":1,"name":"-y","x":-8,"y":7,"z":10},{"level":1,"name":"-y","x":-8,"y":8,"z":10},{"level":1,"name":"-y","x":-8,"y":9,"z":10},{"level":1,"name":"-y","x":-8,"y":10,"z":10},{"level":1,"name":"-y","x":-8,"y":11,"z":10},{"level":1,"name":"-y","x":-8,"y":3,"z":11},{"level":1,"name":"-y","x":-8,"y":4,"z":11},{"level":1,"name":"-y","x":-8,"y":5,"z":11},{"level":1,"name":"-y","x":-8,"y":6,"z":11},{"level":1,"name":"-y","x":-8,"y":7,"z":11},{"level":1,"name":"-y","x":-8,"y":8,"z":11},{"level":1,"name":"-y","x":-8,"y":9,"z":11},{"level":1,"name":"-y","x":-8,"y":10,"z":11},{"level":1,"name":"-y","x":-8,"y":11,"z":11},{"level":1,"name":"-y","x":-8,"y":3,"z":12},{"level":1,"name":"-y","x":-8,"y":4,"z":12},{"level":1,"name":"-y","x":-8,"y":5,"z":12},{"level":1,"name":"-y","x":-8,"y":6,"z":12},{"level":1,"name":"-y","x":-8,"y":7,"z":12},{"level":1,"name":"-y","x":-8,"y":8,"z":12},{"level":1,"name":"-y","x":-8,"y":9,"z":12},{"level":1,"name":"-y","x":-8,"y":10,"z":12},{"level":1,"name":"-y","x":-8,"y":11,"z":12},{"level":1,"name":"-y","x":-8,"y":3,"z":13},{"level":1,"name":"-y","x":-8,"y":4,"z":13},{"level":1,"name":"-y","x":-8,"y":5,"z":13},{"level":1,"name":"-y","x":-8,"y":6,"z":13},{"level":1,"name":"-y","x":-8,"y":7,"z":13},{"level":1,"name":"-y","x":-8,"y":8,"z":13},{"level":1,"name":"-y","x":-8,"y":9,"z":13},{"level":1,"name":"-y","x":-8,"y":10,"z":13},{"level":1,"name":"-y","x":-8,"y":11,"z":13},{"level":1,"name":"-y","x":-8,"y":3,"z":14},{"level":1,"name":"-y","x":-8,"y":4,"z":14},{"level":1,"name":"-y","x":-8,"y":6,"z":14},{"level":1,"name":"-y","x":-8,"y":7,"z":14},{"level":1,"name":"-y","x":-8,"y":9,"z":14},{"level":1,"name":"-y","x":-8,"y":10,"z":14},{"level":1,"name":"-y","x":-7,"y":3,"z":0},{"level":1,"name":"-y","x":-7,"y":4,"z":0},{"level":1,"name":"-y","x":-7,"y":5,"z":0},{"level":1,"name":"-y","x":-7,"y":6,"z":0},{"level":1,"name":"-y","x":-7,"y":7,"z":0},{"level":1,"name":"-y","x":-7,"y":8,"z":0},{"level":1,"name":"-y","x":-7,"y":9,"z":0},{"level":1,"name":"-y","x":-7,"y":3,"z":1},{"level":1,"name":"-y","x":-7,"y":4,"z":1},{"level":1,"name":"-y","x":-7,"y":5,"z":1},{"level":1,"name":"-y","x":-7,"y":6,"z":1},{"level":1,"name":"-y","x":-7,"y":7,"z":1},{"level":1,"name":"-y","x":-7,"y":8,"z":1},{"level":1,"name":"-y","x":-7,"y":9,"z":1},{"level":1,"name":"-y","x":-7,"y":10,"z":1},{"level":1,"name":"-y","x":-7,"y":3,"z":2},{"level":1,"name":"-y","x":-7,"y":4,"z":2},{"level":1,"name":"-y","x":-7,"y":5,"z":2},{"level":1,"name":"-y","x":-7,"y":6,"z":2},{"level":1,"name":"-y","x":-7,"y":7,"z":2},{"level":1,"name":"-y","x":-7,"y":8,"z":2},{"level":1,"name":"-y","x":-7,"y":9,"z":2},{"level":1,"name":"-y","x":-7,"y":10,"z":2},{"level":1,"name":"-y","x":-7,"y":11,"z":2},{"level":1,"name":"-y","x":-7,"y":3,"z":3},{"level":1,"name":"-y","x":-7,"y":4,"z":3},{"level":1,"name":"-y","x":-7,"y":5,"z":3},{"level":1,"name":"-y","x":-7,"y":6,"z":3},{"level":1,"name":"-y","x":-7,"y":7,"z":3},{"level":1,"name":"-y","x":-7,"y":8,"z":3},{"level":1,"name":"-y","x":-7,"y":9,"z":3},{"level":1,"name":"-y","x":-7,"y":3,"z":4},{"level":1,"name":"-y","x":-7,"y":4,"z":4},{"level":1,"name":"-y","x":-7,"y":5,"z":4},{"level":1,"name":"-y","x":-7,"y":6,"z":4},{"level":1,"name":"-y","x":-7,"y":7,"z":4},{"level":1,"name":"-y","x":-7,"y":8,"z":4},{"level":1,"name":"-y","x":-7,"y":9,"z":4},{"level":1,"name":"-y","x":-7,"y":3,"z":5},{"level":1,"name":"-y","x":-7,"y":4,"z":5},{"level":1,"name":"-y","x":-7,"y":5,"z":5},{"level":1,"name":"-y","x":-7,"y":6,"z":5},{"level":1,"name":"-y","x":-7,"y":7,"z":5},{"level":1,"name":"-y","x":-7,"y":8,"z":5},{"level":1,"name":"-y","x":-7,"y":9,"z":5},{"level":1,"name":"-y","x":-7,"y":10,"z":5},{"level":1,"name":"-y","x":-7,"y":11,"z":5},{"level":1,"name":"-y","x":-7,"y":3,"z":6},{"level":1,"name":"-y","x":-7,"y":4,"z":6},{"level":1,"name":"-y","x":-7,"y":5,"z":6},{"level":1,"name":"-y","x":-7,"y":6,"z":6},{"level":1,"name":"-y","x":-7,"y":7,"z":6},{"level":1,"name":"-y","x":-7,"y":8,"z":6},{"level":1,"name":"-y","x":-7,"y":9,"z":6},{"level":1,"name":"-y","x":-7,"y":10,"z":6},{"level":1,"name":"-y","x":-7,"y":3,"z":7},{"level":1,"name":"-y","x":-7,"y":4,"z":7},{"level":1,"name":"-y","x":-7,"y":5,"z":7},{"level":1,"name":"-y","x":-7,"y":6,"z":7},{"level":1,"name":"-y","x":-7,"y":7,"z":7},{"level":1,"name":"-y","x":-7,"y":8,"z":7},{"level":1,"name":"-y","x":-7,"y":9,"z":7},{"level":1,"name":"-y","x":-7,"y":10,"z":7},{"level":1,"name":"-y","x":-7,"y":3,"z":8},{"level":1,"name":"-y","x":-7,"y":4,"z":8},{"level":1,"name":"-y","x":-7,"y":5,"z":8},{"level":1,"name":"-y","x":-7,"y":6,"z":8},{"level":1,"name":"-y","x":-7,"y":7,"z":8},{"level":1,"name":"-y","x":-7,"y":8,"z":8},{"level":1,"name":"-y","x":-7,"y":9,"z":8},{"level":1,"name":"-y","x":-7,"y":10,"z":8},{"level":1,"name":"-y","x":-7,"y":3,"z":9},{"level":1,"name":"-y","x":-7,"y":4,"z":9},{"level":1,"name":"-y","x":-7,"y":5,"z":9},{"level":1,"name":"-y","x":-7,"y":6,"z":9},{"level":1,"name":"-y","x":-7,"y":7,"z":9},{"level":1,"name":"-y","x":-7,"y":8,"z":9},{"level":1,"name":"-y","x":-7,"y":9,"z":9},{"level":1,"name":"-y","x":-7,"y":10,"z":9},{"level":1,"name":"-y","x":-7,"y":11,"z":9},{"level":1,"name":"-y","x":-7,"y":3,"z":10},{"level":1,"name":"-y","x":-7,"y":4,"z":10},{"level":1,"name":"-y","x":-7,"y":5,"z":10},{"level":1,"name":"-y","x":-7,"y":6,"z":10},{"level":1,"name":"-y","x":-7,"y":7,"z":10},{"level":1,"name":"-y","x":-7,"y":8,"z":10},{"level":1,"name":"-y","x":-7,"y":9,"z":10},{"level":1,"name":"-y","x":-7,"y":10,"z":10},{"level":1,"name":"-y","x":-7,"y":11,"z":10},{"level":1,"name":"-y","x":-7,"y":3,"z":11},{"level":1,"name":"-y","x":-7,"y":4,"z":11},{"level":1,"name":"-y","x":-7,"y":5,"z":11},{"level":1,"name":"-y","x":-7,"y":6,"z":11},{"level":1,"name":"-y","x":-7,"y":7,"z":11},{"level":1,"name":"-y","x":-7,"y":8,"z":11},{"level":1,"name":"-y","x":-7,"y":9,"z":11},{"level":1,"name":"-y","x":-7,"y":10,"z":11},{"level":1,"name":"-y","x":-7,"y":11,"z":11},{"level":1,"name":"-y","x":-7,"y":12,"z":11},{"level":1,"name":"-y","x":-7,"y":3,"z":12},{"level":1,"name":"-y","x":-7,"y":4,"z":12},{"level":1,"name":"-y","x":-7,"y":5,"z":12},{"level":1,"name":"-y","x":-7,"y":6,"z":12},{"level":1,"name":"-y","x":-7,"y":7,"z":12},{"level":1,"name":"-y","x":-7,"y":8,"z":12},{"level":1,"name":"-y","x":-7,"y":9,"z":12},{"level":1,"name":"-y","x":-7,"y":10,"z":12},{"level":1,"name":"-y","x":-7,"y":11,"z":12},{"level":1,"name":"-y","x":-7,"y":12,"z":12},{"level":1,"name":"-y","x":-7,"y":3,"z":13},{"level":1,"name":"-y","x":-7,"y":4,"z":13},{"level":1,"name":"-y","x":-7,"y":5,"z":13},{"level":1,"name":"-y","x":-7,"y":6,"z":13},{"level":1,"name":"-y","x":-7,"y":7,"z":13},{"level":1,"name":"-y","x":-7,"y":8,"z":13},{"level":1,"name":"-y","x":-7,"y":9,"z":13},{"level":1,"name":"-y","x":-7,"y":10,"z":13},{"level":1,"name":"-y","x":-7,"y":11,"z":13},{"level":1,"name":"-y","x":-7,"y":12,"z":13},{"level":1,"name":"-y","x":-6,"y":3,"z":11},{"level":1,"name":"-y","x":-6,"y":4,"z":11},{"level":1,"name":"-y","x":-6,"y":5,"z":11},{"level":1,"name":"-y","x":-6,"y":6,"z":11},{"level":1,"name":"-y","x":-6,"y":7,"z":11},{"level":1,"name":"-y","x":-6,"y":8,"z":11},{"level":1,"name":"-y","x":-6,"y":9,"z":11},{"level":1,"name":"-y","x":-6,"y":10,"z":11},{"level":1,"name":"-y","x":-6,"y":11,"z":11},{"level":1,"name":"-y","x":-6,"y":12,"z":11},{"level":1,"name":"-y","x":-6,"y":3,"z":12},{"level":1,"name":"-y","x":-6,"y":4,"z":12},{"level":1,"name":"-y","x":-6,"y":5,"z":12},{"level":1,"name":"-y","x":-6,"y":6,"z":12},{"level":1,"name":"-y","x":-6,"y":7,"z":12},{"level":1,"name":"-y","x":-6,"y":8,"z":12},{"level":1,"name":"-y","x":-6,"y":9,"z":12},{"level":1,"name":"-y","x":-6,"y":10,"z":12},{"level":1,"name":"-y","x":-6,"y":11,"z":12},{"level":1,"name":"-y","x":-6,"y":12,"z":12},{"level":1,"name":"-y","x":-6,"y":13,"z":12},{"level":1,"name":"-y","x":-6,"y":3,"z":13},{"level":1,"name":"-y","x":-6,"y":4,"z":13},{"level":1,"name":"-y","x":-6,"y":5,"z":13},{"level":1,"name":"-y","x":-6,"y":6,"z":13},{"level":1,"name":"-y","x":-6,"y":7,"z":13},{"level":1,"name":"-y","x":-6,"y":8,"z":13},{"level":1,"name":"-y","x":-6,"y":9,"z":13},{"level":1,"name":"-y","x":-6,"y":10,"z":13},{"level":1,"name":"-y","x":-6,"y":11,"z":13},{"level":1,"name":"-y","x":-6,"y":12,"z":13},{"level":1,"name":"-y","x":-6,"y":13,"z":13},{"level":1,"name":"-y","x":-5,"y":3,"z":11},{"level":1,"name":"-y","x":-5,"y":4,"z":11},{"level":1,"name":"-y","x":-5,"y":5,"z":11},{"level":1,"name":"-y","x":-5,"y":6,"z":11},{"level":1,"name":"-y","x":-5,"y":7,"z":11},{"level":1,"name":"-y","x":-5,"y":8,"z":11},{"level":1,"name":"-y","x":-5,"y":9,"z":11},{"level":1,"name":"-y","x":-5,"y":10,"z":11},{"level":1,"name":"-y","x":-5,"y":11,"z":11},{"level":1,"name":"-y","x":-5,"y":12,"z":11},{"level":1,"name":"-y","x":-5,"y":13,"z":11},{"level":1,"name":"-y","x":-5,"y":3,"z":12},{"level":1,"name":"-y","x":-5,"y":4,"z":12},{"level":1,"name":"-y","x":-5,"y":5,"z":12},{"level":1,"name":"-y","x":-5,"y":6,"z":12},{"level":1,"name":"-y","x":-5,"y":7,"z":12},{"level":1,"name":"-y","x":-5,"y":8,"z":12},{"level":1,"name":"-y","x":-5,"y":9,"z":12},{"level":1,"name":"-y","x":-5,"y":10,"z":12},{"level":1,"name":"-y","x":-5,"y":11,"z":12},{"level":1,"name":"-y","x":-5,"y":12,"z":12},{"level":1,"name":"-y","x":-5,"y":13,"z":12},{"level":1,"name":"-y","x":-5,"y":3,"z":13},{"level":1,"name":"-y","x":-5,"y":4,"z":13},{"level":1,"name":"-y","x":-5,"y":5,"z":13},{"level":1,"name":"-y","x":-5,"y":6,"z":13},{"level":1,"name":"-y","x":-5,"y":7,"z":13},{"level":1,"name":"-y","x":-5,"y":8,"z":13},{"level":1,"name":"-y","x":-5,"y":9,"z":13},{"level":1,"name":"-y","x":-5,"y":10,"z":13},{"level":1,"name":"-y","x":-5,"y":11,"z":13},{"level":1,"name":"-y","x":-5,"y":12,"z":13},{"level":1,"name":"-y","x":-5,"y":13,"z":13},{"level":1,"name":"-y","x":-4,"y":3,"z":11},{"level":1,"name":"-y","x":-4,"y":4,"z":11},{"level":1,"name":"-y","x":-4,"y":5,"z":11},{"level":1,"name":"-y","x":-4,"y":6,"z":11},{"level":1,"name":"-y","x":-4,"y":7,"z":11},{"level":1,"name":"-y","x":-4,"y":8,"z":11},{"level":1,"name":"-y","x":-4,"y":9,"z":11},{"level":1,"name":"-y","x":-4,"y":10,"z":11},{"level":1,"name":"-y","x":-4,"y":11,"z":11},{"level":1,"name":"-y","x":-4,"y":12,"z":11},{"level":1,"name":"-y","x":-4,"y":13,"z":11},{"level":1,"name":"-y","x":-4,"y":3,"z":12},{"level":1,"name":"-y","x":-4,"y":4,"z":12},{"level":1,"name":"-y","x":-4,"y":5,"z":12},{"level":1,"name":"-y","x":-4,"y":6,"z":12},{"level":1,"name":"-y","x":-4,"y":7,"z":12},{"level":1,"name":"-y","x":-4,"y":8,"z":12},{"level":1,"name":"-y","x":-4,"y":9,"z":12},{"level":1,"name":"-y","x":-4,"y":10,"z":12},{"level":1,"name":"-y","x":-4,"y":11,"z":12},{"level":1,"name":"-y","x":-4,"y":12,"z":12},{"level":1,"name":"-y","x":-4,"y":13,"z":12},{"level":1,"name":"-y","x":-4,"y":3,"z":13},{"level":1,"name":"-y","x":-4,"y":4,"z":13},{"level":1,"name":"-y","x":-4,"y":5,"z":13},{"level":1,"name":"-y","x":-4,"y":6,"z":13},{"level":1,"name":"-y","x":-4,"y":7,"z":13},{"level":1,"name":"-y","x":-4,"y":8,"z":13},{"level":1,"name":"-y","x":-4,"y":9,"z":13},{"level":1,"name":"-y","x":-4,"y":10,"z":13},{"level":1,"name":"-y","x":-4,"y":11,"z":13},{"level":1,"name":"-y","x":-4,"y":12,"z":13},{"level":1,"name":"-y","x":-4,"y":13,"z":13},{"level":1,"name":"-y","x":-3,"y":3,"z":11},{"level":1,"name":"-y","x":-3,"y":4,"z":11},{"level":1,"name":"-y","x":-3,"y":5,"z":11},{"level":1,"name":"-y","x":-3,"y":6,"z":11},{"level":1,"name":"-y","x":-3,"y":7,"z":11},{"level":1,"name":"-y","x":-3,"y":8,"z":11},{"level":1,"name":"-y","x":-3,"y":9,"z":11},{"level":1,"name":"-y","x":-3,"y":10,"z":11},{"level":1,"name":"-y","x":-3,"y":11,"z":11},{"level":1,"name":"-y","x":-3,"y":12,"z":11},{"level":1,"name":"-y","x":-3,"y":13,"z":11},{"level":1,"name":"-y","x":-3,"y":3,"z":12},{"level":1,"name":"-y","x":-3,"y":4,"z":12},{"level":1,"name":"-y","x":-3,"y":5,"z":12},{"level":1,"name":"-y","x":-3,"y":6,"z":12},{"level":1,"name":"-y","x":-3,"y":7,"z":12},{"level":1,"name":"-y","x":-3,"y":8,"z":12},{"level":1,"name":"-y","x":-3,"y":9,"z":12},{"level":1,"name":"-y","x":-3,"y":10,"z":12},{"level":1,"name":"-y","x":-3,"y":11,"z":12},{"level":1,"name":"-y","x":-3,"y":12,"z":12},{"level":1,"name":"-y","x":-3,"y":13,"z":12},{"level":1,"name":"-y","x":-3,"y":3,"z":13},{"level":1,"name":"-y","x":-3,"y":4,"z":13},{"level":1,"name":"-y","x":-3,"y":5,"z":13},{"level":1,"name":"-y","x":-3,"y":6,"z":13},{"level":1,"name":"-y","x":-3,"y":7,"z":13},{"level":1,"name":"-y","x":-3,"y":8,"z":13},{"level":1,"name":"-y","x":-3,"y":9,"z":13},{"level":1,"name":"-y","x":-3,"y":10,"z":13},{"level":1,"name":"-y","x":-3,"y":11,"z":13},{"level":1,"name":"-y","x":-3,"y":12,"z":13},{"level":1,"name":"-y","x":-2,"y":3,"z":11},{"level":1,"name":"-y","x":-2,"y":4,"z":11},{"level":1,"name":"-y","x":-2,"y":5,"z":11},{"level":1,"name":"-y","x":-2,"y":6,"z":11},{"level":1,"name":"-y","x":-2,"y":7,"z":11},{"level":1,"name":"-y","x":-2,"y":8,"z":11},{"level":1,"name":"-y","x":-2,"y":9,"z":11},{"level":1,"name":"-y","x":-2,"y":10,"z":11},{"level":1,"name":"-y","x":-2,"y":11,"z":11},{"level":1,"name":"-y","x":-2,"y":12,"z":11},{"level":1,"name":"-y","x":-2,"y":3,"z":12},{"level":1,"name":"-y","x":-2,"y":4,"z":12},{"level":1,"name":"-y","x":-2,"y":5,"z":12},{"level":1,"name":"-y","x":-2,"y":6,"z":12},{"level":1,"name":"-y","x":-2,"y":7,"z":12},{"level":1,"name":"-y","x":-2,"y":8,"z":12},{"level":1,"name":"-y","x":-2,"y":9,"z":12},{"level":1,"name":"-y","x":-2,"y":10,"z":12},{"level":1,"name":"-y","x":-2,"y":11,"z":12},{"level":1,"name":"-y","x":-2,"y":12,"z":12},{"level":1,"name":"-y","x":-2,"y":3,"z":13},{"level":1,"name":"-y","x":-2,"y":4,"z":13},{"level":1,"name":"-y","x":-2,"y":5,"z":13},{"level":1,"name":"-y","x":-2,"y":6,"z":13},{"level":1,"name":"-y","x":-2,"y":7,"z":13},{"level":1,"name":"-y","x":-2,"y":8,"z":13},{"level":1,"name":"-y","x":-2,"y":9,"z":13},{"level":1,"name":"-y","x":-2,"y":10,"z":13},{"level":1,"name":"-y","x":-2,"y":11,"z":13},{"level":1,"name":"-y","x":-2,"y":12,"z":13},{"level":1,"name":"-y","x":-1,"y":3,"z":11},{"level":1,"name":"-y","x":-1,"y":4,"z":11},{"level":1,"name":"-y","x":-1,"y":5,"z":11},{"level":1,"name":"-y","x":-1,"y":6,"z":11},{"level":1,"name":"-y","x":-1,"y":7,"z":11},{"level":1,"name":"-y","x":-1,"y":8,"z":11},{"level":1,"name":"-y","x":-1,"y":9,"z":11},{"level":1,"name":"-y","x":-1,"y":10,"z":11},{"level":1,"name":"-y","x":-1,"y":11,"z":11},{"level":1,"name":"-y","x":-1,"y":12,"z":11},{"level":1,"name":"-y","x":-1,"y":3,"z":12},{"level":1,"name":"-y","x":-1,"y":4,"z":12},{"level":1,"name":"-y","x":-1,"y":5,"z":12},{"level":1,"name":"-y","x":-1,"y":6,"z":12},{"level":1,"name":"-y","x":-1,"y":7,"z":12},{"level":1,"name":"-y","x":-1,"y":8,"z":12},{"level":1,"name":"-y","x":-1,"y":9,"z":12},{"level":1,"name":"-y","x":-1,"y":10,"z":12},{"level":1,"name":"-y","x":-1,"y":11,"z":12},{"level":1,"name":"-y","x":-1,"y":12,"z":12},{"level":1,"name":"-y","x":-1,"y":13,"z":12},{"level":1,"name":"-y","x":-1,"y":3,"z":13},{"level":1,"name":"-y","x":-1,"y":4,"z":13},{"level":1,"name":"-y","x":-1,"y":5,"z":13},{"level":1,"name":"-y","x":-1,"y":6,"z":13},{"level":1,"name":"-y","x":-1,"y":7,"z":13},{"level":1,"name":"-y","x":-1,"y":8,"z":13},{"level":1,"name":"-y","x":-1,"y":9,"z":13},{"level":1,"name":"-y","x":-1,"y":10,"z":13},{"level":1,"name":"-y","x":-1,"y":11,"z":13},{"level":1,"name":"-y","x":-1,"y":12,"z":13},{"level":1,"name":"-y","x":-1,"y":13,"z":13},{"level":1,"name":"-y","x":0,"y":3,"z":11},{"level":1,"name":"-y","x":0,"y":4,"z":11},{"level":1,"name":"-y","x":0,"y":5,"z":11},{"level":1,"name":"-y","x":0,"y":6,"z":11},{"level":1,"name":"-y","x":0,"y":7,"z":11},{"level":1,"name":"-y","x":0,"y":8,"z":11},{"level":1,"name":"-y","x":0,"y":9,"z":11},{"level":1,"name":"-y","x":0,"y":10,"z":11},{"level":1,"name":"-y","x":0,"y":11,"z":11},{"level":1,"name":"-y","x":0,"y":12,"z":11},{"level":1,"name":"-y","x":0,"y":13,"z":11},{"level":1,"name":"-y","x":0,"y":3,"z":12},{"level":1,"name":"-y","x":0,"y":4,"z":12},{"level":1,"name":"-y","x":0,"y":5,"z":12},{"level":1,"name":"-y","x":0,"y":6,"z":12},{"level":1,"name":"-y","x":0,"y":7,"z":12},{"level":1,"name":"-y","x":0,"y":8,"z":12},{"level":1,"name":"-y","x":0,"y":9,"z":12},{"level":1,"name":"-y","x":0,"y":10,"z":12},{"level":1,"name":"-y","x":0,"y":11,"z":12},{"level":1,"name":"-y","x":0,"y":12,"z":12},{"level":1,"name":"-y","x":0,"y":13,"z":12},{"level":1,"name":"-y","x":0,"y":3,"z":13},{"level":1,"name":"-y","x":0,"y":4,"z":13},{"level":1,"name":"-y","x":0,"y":5,"z":13},{"level":1,"name":"-y","x":0,"y":6,"z":13},{"level":1,"name":"-y","x":0,"y":7,"z":13},{"level":1,"name":"-y","x":0,"y":8,"z":13},{"level":1,"name":"-y","x":0,"y":9,"z":13},{"level":1,"name":"-y","x":0,"y":10,"z":13},{"level":1,"name":"-y","x":0,"y":11,"z":13},{"level":1,"name":"-y","x":0,"y":12,"z":13},{"level":1,"name":"-y","x":0,"y":13,"z":13},{"level":1,"name":"-y","x":1,"y":3,"z":11},{"level":1,"name":"-y","x":1,"y":4,"z":11},{"level":1,"name":"-y","x":1,"y":5,"z":11},{"level":1,"name":"-y","x":1,"y":6,"z":11},{"level":1,"name":"-y","x":1,"y":7,"z":11},{"level":1,"name":"-y","x":1,"y":8,"z":11},{"level":1,"name":"-y","x":1,"y":9,"z":11},{"level":1,"name":"-y","x":1,"y":10,"z":11},{"level":1,"name":"-y","x":1,"y":11,"z":11},{"level":1,"name":"-y","x":1,"y":12,"z":11},{"level":1,"name":"-y","x":1,"y":3,"z":12},{"level":1,"name":"-y","x":1,"y":4,"z":12},{"level":1,"name":"-y","x":1,"y":5,"z":12},{"level":1,"name":"-y","x":1,"y":6,"z":12},{"level":1,"name":"-y","x":1,"y":7,"z":12},{"level":1,"name":"-y","x":1,"y":8,"z":12},{"level":1,"name":"-y","x":1,"y":9,"z":12},{"level":1,"name":"-y","x":1,"y":10,"z":12},{"level":1,"name":"-y","x":1,"y":11,"z":12},{"level":1,"name":"-y","x":1,"y":12,"z":12},{"level":1,"name":"-y","x":1,"y":3,"z":13},{"level":1,"name":"-y","x":1,"y":4,"z":13},{"level":1,"name":"-y","x":1,"y":5,"z":13},{"level":1,"name":"-y","x":1,"y":6,"z":13},{"level":1,"name":"-y","x":1,"y":7,"z":13},{"level":1,"name":"-y","x":1,"y":8,"z":13},{"level":1,"name":"-y","x":1,"y":9,"z":13},{"level":1,"name":"-y","x":1,"y":10,"z":13},{"level":1,"name":"-y","x":1,"y":11,"z":13},{"level":1,"name":"-y","x":1,"y":12,"z":13},{"level":1,"name":"-y","x":2,"y":3,"z":11},{"level":1,"name":"-y","x":2,"y":4,"z":11},{"level":1,"name":"-y","x":2,"y":5,"z":11},{"level":1,"name":"-y","x":2,"y":6,"z":11},{"level":1,"name":"-y","x":2,"y":7,"z":11},{"level":1,"name":"-y","x":2,"y":8,"z":11},{"level":1,"name":"-y","x":2,"y":9,"z":11},{"level":1,"name":"-y","x":2,"y":10,"z":11},{"level":1,"name":"-y","x":2,"y":11,"z":11},{"level":1,"name":"-y","x":2,"y":12,"z":11},{"level":1,"name":"-y","x":2,"y":3,"z":12},{"level":1,"name":"-y","x":2,"y":4,"z":12},{"level":1,"name":"-y","x":2,"y":5,"z":12},{"level":1,"name":"-y","x":2,"y":6,"z":12},{"level":1,"name":"-y","x":2,"y":7,"z":12},{"level":1,"name":"-y","x":2,"y":8,"z":12},{"level":1,"name":"-y","x":2,"y":9,"z":12},{"level":1,"name":"-y","x":2,"y":10,"z":12},{"level":1,"name":"-y","x":2,"y":11,"z":12},{"level":1,"name":"-y","x":2,"y":12,"z":12},{"level":1,"name":"-y","x":2,"y":3,"z":13},{"level":1,"name":"-y","x":2,"y":4,"z":13},{"level":1,"name":"-y","x":2,"y":5,"z":13},{"level":1,"name":"-y","x":2,"y":6,"z":13},{"level":1,"name":"-y","x":2,"y":7,"z":13},{"level":1,"name":"-y","x":2,"y":8,"z":13},{"level":1,"name":"-y","x":2,"y":9,"z":13},{"level":1,"name":"-y","x":2,"y":10,"z":13},{"level":1,"name":"-y","x":2,"y":11,"z":13},{"level":1,"name":"-y","x":3,"y":3,"z":4},{"level":1,"name":"-y","x":3,"y":4,"z":4},{"level":1,"name":"-y","x":3,"y":5,"z":4},{"level":1,"name":"-y","x":3,"y":6,"z":4},{"level":1,"name":"-y","x":3,"y":7,"z":4},{"level":1,"name":"-y","x":3,"y":8,"z":4},{"level":1,"name":"-y","x":3,"y":9,"z":4},{"level":1,"name":"-y","x":3,"y":10,"z":4},{"level":1,"name":"-y","x":3,"y":3,"z":5},{"level":1,"name":"-y","x":3,"y":4,"z":5},{"level":1,"name":"-y","x":3,"y":5,"z":5},{"level":1,"name":"-y","x":3,"y":6,"z":5},{"level":1,"name":"-y","x":3,"y":7,"z":5},{"level":1,"name":"-y","x":3,"y":8,"z":5},{"level":1,"name":"-y","x":3,"y":9,"z":5},{"level":1,"name":"-y","x":3,"y":3,"z":6},{"level":1,"name":"-y","x":3,"y":4,"z":6},{"level":1,"name":"-y","x":3,"y":5,"z":6},{"level":1,"name":"-y","x":3,"y":6,"z":6},{"level":1,"name":"-y","x":3,"y":7,"z":6},{"level":1,"name":"-y","x":3,"y":8,"z":6},{"level":1,"name":"-y","x":3,"y":9,"z":6},{"level":1,"name":"-y","x":3,"y":3,"z":7},{"level":1,"name":"-y","x":3,"y":4,"z":7},{"level":1,"name":"-y","x":3,"y":5,"z":7},{"level":1,"name":"-y","x":3,"y":6,"z":7},{"level":1,"name":"-y","x":3,"y":7,"z":7},{"level":1,"name":"-y","x":3,"y":8,"z":7},{"level":1,"name":"-y","x":3,"y":9,"z":7},{"level":1,"name":"-y","x":3,"y":3,"z":8},{"level":1,"name":"-y","x":3,"y":4,"z":8},{"level":1,"name":"-y","x":3,"y":5,"z":8},{"level":1,"name":"-y","x":3,"y":6,"z":8},{"level":1,"name":"-y","x":3,"y":7,"z":8},{"level":1,"name":"-y","x":3,"y":8,"z":8},{"level":1,"name":"-y","x":3,"y":9,"z":8},{"level":1,"name":"-y","x":3,"y":10,"z":8},{"level":1,"name":"-y","x":3,"y":3,"z":9},{"level":1,"name":"-y","x":3,"y":4,"z":9},{"level":1,"name":"-y","x":3,"y":5,"z":9},{"level":1,"name":"-y","x":3,"y":6,"z":9},{"level":1,"name":"-y","x":3,"y":7,"z":9},{"level":1,"name":"-y","x":3,"y":8,"z":9},{"level":1,"name":"-y","x":3,"y":9,"z":9},{"level":1,"name":"-y","x":3,"y":10,"z":9},{"level":1,"name":"-y","x":3,"y":3,"z":10},{"level":1,"name":"-y","x":3,"y":4,"z":10},{"level":1,"name":"-y","x":3,"y":5,"z":10},{"level":1,"name":"-y","x":3,"y":6,"z":10},{"level":1,"name":"-y","x":3,"y":7,"z":10},{"level":1,"name":"-y","x":3,"y":8,"z":10},{"level":1,"name":"-y","x":3,"y":9,"z":10},{"level":1,"name":"-y","x":3,"y":10,"z":10},{"level":1,"name":"-y","x":3,"y":3,"z":11},{"level":1,"name":"-y","x":3,"y":4,"z":11},{"level":1,"name":"-y","x":3,"y":5,"z":11},{"level":1,"name":"-y","x":3,"y":6,"z":11},{"level":1,"name":"-y","x":3,"y":7,"z":11},{"level":1,"name":"-y","x":3,"y":8,"z":11},{"level":1,"name":"-y","x":3,"y":9,"z":11},{"level":1,"name":"-y","x":3,"y":10,"z":11},{"level":1,"name":"-y","x":3,"y":11,"z":11},{"level":1,"name":"-y","x":3,"y":3,"z":12},{"level":1,"name":"-y","x":3,"y":4,"z":12},{"level":1,"name":"-y","x":3,"y":5,"z":12},{"level":1,"name":"-y","x":3,"y":6,"z":12},{"level":1,"name":"-y","x":3,"y":7,"z":12},{"level":1,"name":"-y","x":3,"y":8,"z":12},{"level":1,"name":"-y","x":3,"y":9,"z":12},{"level":1,"name":"-y","x":3,"y":10,"z":12},{"level":1,"name":"-y","x":3,"y":11,"z":12},{"level":1,"name":"-y","x":3,"y":3,"z":13},{"level":1,"name":"-y","x":3,"y":4,"z":13},{"level":1,"name":"-y","x":3,"y":5,"z":13},{"level":1,"name":"-y","x":3,"y":6,"z":13},{"level":1,"name":"-y","x":3,"y":7,"z":13},{"level":1,"name":"-y","x":3,"y":8,"z":13},{"level":1,"name":"-y","x":3,"y":9,"z":13},{"level":1,"name":"-y","x":3,"y":10,"z":13},{"level":1,"name":"-y","x":3,"y":11,"z":13},{"level":1,"name":"-y","x":4,"y":3,"z":4},{"level":1,"name":"-y","x":4,"y":4,"z":4},{"level":1,"name":"-y","x":4,"y":5,"z":4},{"level":1,"name":"-y","x":4,"y":6,"z":4},{"level":1,"name":"-y","x":4,"y":7,"z":4},{"level":1,"name":"-y","x":4,"y":8,"z":4},{"level":1,"name":"-y","x":4,"y":9,"z":4},{"level":1,"name":"-y","x":4,"y":10,"z":4},{"level":1,"name":"-y","x":4,"y":11,"z":4},{"level":1,"name":"-y","x":4,"y":3,"z":11},{"level":1,"name":"-y","x":4,"y":4,"z":11},{"level":1,"name":"-y","x":4,"y":5,"z":11},{"level":1,"name":"-y","x":4,"y":6,"z":11},{"level":1,"name":"-y","x":4,"y":7,"z":11},{"level":1,"name":"-y","x":4,"y":8,"z":11},{"level":1,"name":"-y","x":4,"y":9,"z":11},{"level":1,"name":"-y","x":4,"y":10,"z":11},{"level":1,"name":"-y","x":4,"y":11,"z":11},{"level":1,"name":"-y","x":4,"y":3,"z":12},{"level":1,"name":"-y","x":4,"y":4,"z":12},{"level":1,"name":"-y","x":4,"y":5,"z":12},{"level":1,"name":"-y","x":4,"y":6,"z":12},{"level":1,"name":"-y","x":4,"y":7,"z":12},{"level":1,"name":"-y","x":4,"y":8,"z":12},{"level":1,"name":"-y","x":4,"y":9,"z":12},{"level":1,"name":"-y","x":4,"y":10,"z":12},{"level":1,"name":"-y","x":4,"y":3,"z":13},{"level":1,"name":"-y","x":4,"y":4,"z":13},{"level":1,"name":"-y","x":4,"y":5,"z":13},{"level":1,"name":"-y","x":4,"y":6,"z":13},{"level":1,"name":"-y","x":4,"y":7,"z":13},{"level":1,"name":"-y","x":4,"y":8,"z":13},{"level":1,"name":"-y","x":4,"y":9,"z":13},{"level":1,"name":"-y","x":4,"y":10,"z":13},{"level":1,"name":"-y","x":5,"y":3,"z":4},{"level":1,"name":"-y","x":5,"y":4,"z":4},{"level":1,"name":"-y","x":5,"y":5,"z":4},{"level":1,"name":"-y","x":5,"y":6,"z":4},{"level":1,"name":"-y","x":5,"y":7,"z":4},{"level":1,"name":"-y","x":5,"y":8,"z":4},{"level":1,"name":"-y","x":5,"y":9,"z":4},{"level":1,"name":"-y","x":5,"y":10,"z":4},{"level":1,"name":"-y","x":5,"y":11,"z":4},{"level":1,"name":"-y","x":5,"y":12,"z":4},{"level":1,"name":"-y","x":6,"y":3,"z":4},{"level":1,"name":"-y","x":6,"y":4,"z":4},{"level":1,"name":"-y","x":6,"y":5,"z":4},{"level":1,"name":"-y","x":6,"y":6,"z":4},{"level":1,"name":"-y","x":6,"y":7,"z":4},{"level":1,"name":"-y","x":6,"y":8,"z":4},{"level":1,"name":"-y","x":6,"y":9,"z":4},{"level":1,"name":"-y","x":6,"y":10,"z":4},{"level":1,"name":"-y","x":6,"y":11,"z":4},{"level":1,"name":"-y","x":6,"y":12,"z":4},{"level":1,"name":"-y","x":7,"y":3,"z":-9},{"level":1,"name":"-y","x":7,"y":4,"z":-9},{"level":1,"name":"-y","x":7,"y":5,"z":-9},{"level":1,"name":"-y","x":7,"y":6,"z":-9},{"level":1,"name":"-y","x":7,"y":7,"z":-9},{"level":1,"name":"-y","x":7,"y":8,"z":-9},{"level":1,"name":"-y","x":7,"y":9,"z":-9},{"level":1,"name":"-y","x":7,"y":3,"z":-8},{"level":1,"name":"-y","x":7,"y":4,"z":-8},{"level":1,"name":"-y","x":7,"y":5,"z":-8},{"level":1,"name":"-y","x":7,"y":6,"z":-8},{"level":1,"name":"-y","x":7,"y":7,"z":-8},{"level":1,"name":"-y","x":7,"y":8,"z":-8},{"level":1,"name":"-y","x":7,"y":9,"z":-8},{"level":1,"name":"-y","x":7,"y":10,"z":-8},{"level":1,"name":"-y","x":7,"y":3,"z":-7},{"level":1,"name":"-y","x":7,"y":4,"z":-7},{"level":1,"name":"-y","x":7,"y":5,"z":-7},{"level":1,"name":"-y","x":7,"y":6,"z":-7},{"level":1,"name":"-y","x":7,"y":7,"z":-7},{"level":1,"name":"-y","x":7,"y":8,"z":-7},{"level":1,"name":"-y","x":7,"y":9,"z":-7},{"level":1,"name":"-y","x":7,"y":10,"z":-7},{"level":1,"name":"-y","x":7,"y":3,"z":4},{"level":1,"name":"-y","x":7,"y":4,"z":4},{"level":1,"name":"-y","x":7,"y":5,"z":4},{"level":1,"name":"-y","x":7,"y":6,"z":4},{"level":1,"name":"-y","x":7,"y":7,"z":4},{"level":1,"name":"-y","x":7,"y":8,"z":4},{"level":1,"name":"-y","x":7,"y":9,"z":4},{"level":1,"name":"-y","x":7,"y":10,"z":4},{"level":1,"name":"-y","x":7,"y":11,"z":4},{"level":1,"name":"-y","x":7,"y":12,"z":4},{"level":1,"name":"-y","x":8,"y":3,"z":-9},{"level":1,"name":"-y","x":8,"y":4,"z":-9},{"level":1,"name":"-y","x":8,"y":5,"z":-9},{"level":1,"name":"-y","x":8,"y":6,"z":-9},{"level":1,"name":"-y","x":8,"y":7,"z":-9},{"level":1,"name":"-y","x":8,"y":8,"z":-9},{"level":1,"name":"-y","x":8,"y":9,"z":-9},{"level":1,"name":"-y","x":8,"y":10,"z":-9},{"level":1,"name":"-y","x":8,"y":3,"z":-8},{"level":1,"name":"-y","x":8,"y":4,"z":-8},{"level":1,"name":"-y","x":8,"y":5,"z":-8},{"level":1,"name":"-y","x":8,"y":6,"z":-8},{"level":1,"name":"-y","x":8,"y":7,"z":-8},{"level":1,"name":"-y","x":8,"y":8,"z":-8},{"level":1,"name":"-y","x":8,"y":9,"z":-8},{"level":1,"name":"-y","x":8,"y":10,"z":-8},{"level":1,"name":"-y","x":8,"y":3,"z":-7},{"level":1,"name":"-y","x":8,"y":4,"z":-7},{"level":1,"name":"-y","x":8,"y":5,"z":-7},{"level":1,"name":"-y","x":8,"y":6,"z":-7},{"level":1,"name":"-y","x":8,"y":7,"z":-7},{"level":1,"name":"-y","x":8,"y":8,"z":-7},{"level":1,"name":"-y","x":8,"y":9,"z":-7},{"level":1,"name":"-y","x":8,"y":10,"z":-7},{"level":1,"name":"-y","x":8,"y":3,"z":4},{"level":1,"name":"-y","x":8,"y":4,"z":4},{"level":1,"name":"-y","x":8,"y":5,"z":4},{"level":1,"name":"-y","x":8,"y":6,"z":4},{"level":1,"name":"-y","x":8,"y":7,"z":4},{"level":1,"name":"-y","x":8,"y":8,"z":4},{"level":1,"name":"-y","x":8,"y":9,"z":4},{"level":1,"name":"-y","x":8,"y":10,"z":4},{"level":1,"name":"-y","x":9,"y":3,"z":-9},{"level":1,"name":"-y","x":9,"y":4,"z":-9},{"level":1,"name":"-y","x":9,"y":5,"z":-9},{"level":1,"name":"-y","x":9,"y":6,"z":-9},{"level":1,"name":"-y","x":9,"y":7,"z":-9},{"level":1,"name":"-y","x":9,"y":8,"z":-9},{"level":1,"name":"-y","x":9,"y":9,"z":-9},{"level":1,"name":"-y","x":9,"y":10,"z":-9},{"level":1,"name":"-y","x":9,"y":3,"z":-8},{"level":1,"name":"-y","x":9,"y":4,"z":-8},{"level":1,"name":"-y","x":9,"y":5,"z":-8},{"level":1,"name":"-y","x":9,"y":6,"z":-8},{"level":1,"name":"-y","x":9,"y":7,"z":-8},{"level":1,"name":"-y","x":9,"y":8,"z":-8},{"level":1,"name":"-y","x":9,"y":9,"z":-8},{"level":1,"name":"-y","x":9,"y":10,"z":-8},{"level":1,"name":"-y","x":9,"y":11,"z":-8},{"level":1,"name":"-y","x":9,"y":3,"z":-7},{"level":1,"name":"-y","x":9,"y":4,"z":-7},{"level":1,"name":"-y","x":9,"y":5,"z":-7},{"level":1,"name":"-y","x":9,"y":6,"z":-7},{"level":1,"name":"-y","x":9,"y":7,"z":-7},{"level":1,"name":"-y","x":9,"y":8,"z":-7},{"level":1,"name":"-y","x":9,"y":9,"z":-7},{"level":1,"name":"-y","x":9,"y":10,"z":-7},{"level":1,"name":"-y","x":9,"y":3,"z":4},{"level":1,"name":"-y","x":9,"y":4,"z":4},{"level":1,"name":"-y","x":9,"y":5,"z":4},{"level":1,"name":"-y","x":9,"y":6,"z":4},{"level":1,"name":"-y","x":9,"y":7,"z":4},{"level":1,"name":"-y","x":9,"y":8,"z":4},{"level":1,"name":"-y","x":10,"y":3,"z":-9},{"level":1,"name":"-y","x":10,"y":4,"z":-9},{"level":1,"name":"-y","x":10,"y":5,"z":-9},{"level":1,"name":"-y","x":10,"y":6,"z":-9},{"level":1,"name":"-y","x":10,"y":7,"z":-9},{"level":1,"name":"-y","x":10,"y":8,"z":-9},{"level":1,"name":"-y","x":10,"y":9,"z":-9},{"level":1,"name":"-y","x":10,"y":10,"z":-9},{"level":1,"name":"-y","x":10,"y":3,"z":-8},{"level":1,"name":"-y","x":10,"y":4,"z":-8},{"level":1,"name":"-y","x":10,"y":5,"z":-8},{"level":1,"name":"-y","x":10,"y":6,"z":-8},{"level":1,"name":"-y","x":10,"y":7,"z":-8},{"level":1,"name":"-y","x":10,"y":8,"z":-8},{"level":1,"name":"-y","x":10,"y":9,"z":-8},{"level":1,"name":"-y","x":10,"y":10,"z":-8},{"level":1,"name":"-y","x":10,"y":11,"z":-8},{"level":1,"name":"-y","x":10,"y":3,"z":-7},{"level":1,"name":"-y","x":10,"y":4,"z":-7},{"level":1,"name":"-y","x":10,"y":5,"z":-7},{"level":1,"name":"-y","x":10,"y":6,"z":-7},{"level":1,"name":"-y","x":10,"y":7,"z":-7},{"level":1,"name":"-y","x":10,"y":8,"z":-7},{"level":1,"name":"-y","x":10,"y":9,"z":-7},{"level":1,"name":"-y","x":10,"y":10,"z":-7},{"level":1,"name":"-y","x":10,"y":11,"z":-7},{"level":1,"name":"-y","x":11,"y":3,"z":-9},{"level":1,"name":"-y","x":11,"y":4,"z":-9},{"level":1,"name":"-y","x":11,"y":5,"z":-9},{"level":1,"name":"-y","x":11,"y":6,"z":-9},{"level":1,"name":"-y","x":11,"y":7,"z":-9},{"level":1,"name":"-y","x":11,"y":8,"z":-9},{"level":1,"name":"-y","x":11,"y":9,"z":-9},{"level":1,"name":"-y","x":11,"y":10,"z":-9},{"level":1,"name":"-y","x":11,"y":11,"z":-9},{"level":1,"name":"-y","x":11,"y":3,"z":-8},{"level":1,"name":"-y","x":11,"y":4,"z":-8},{"level":1,"name":"-y","x":11,"y":5,"z":-8},{"level":1,"name":"-y","x":11,"y":6,"z":-8},{"level":1,"name":"-y","x":11,"y":7,"z":-8},{"level":1,"name":"-y","x":11,"y":8,"z":-8},{"level":1,"name":"-y","x":11,"y":9,"z":-8},{"level":1,"name":"-y","x":11,"y":10,"z":-8},{"level":1,"name":"-y","x":11,"y":11,"z":-8},{"level":1,"name":"-y","x":11,"y":3,"z":-7},{"level":1,"name":"-y","x":11,"y":4,"z":-7},{"level":1,"name":"-y","x":11,"y":5,"z":-7},{"level":1,"name":"-y","x":11,"y":6,"z":-7},{"level":1,"name":"-y","x":11,"y":7,"z":-7},{"level":1,"name":"-y","x":11,"y":8,"z":-7},{"level":1,"name":"-y","x":11,"y":9,"z":-7},{"level":1,"name":"-y","x":11,"y":10,"z":-7},{"level":1,"name":"-y","x":11,"y":11,"z":-7},{"level":1,"name":"-y","x":11,"y":3,"z":-6},{"level":1,"name":"-y","x":11,"y":4,"z":-6},{"level":1,"name":"-y","x":11,"y":5,"z":-6},{"level":1,"name":"-y","x":11,"y":6,"z":-6},{"level":1,"name":"-y","x":11,"y":7,"z":-6},{"level":1,"name":"-y","x":11,"y":8,"z":-6},{"level":1,"name":"-y","x":11,"y":9,"z":-6},{"level":1,"name":"-y","x":11,"y":10,"z":-6},{"level":1,"name":"-y","x":11,"y":3,"z":-5},{"level":1,"name":"-y","x":11,"y":4,"z":-5},{"level":1,"name":"-y","x":11,"y":5,"z":-5},{"level":1,"name":"-y","x":11,"y":6,"z":-5},{"level":1,"name":"-y","x":11,"y":7,"z":-5},{"level":1,"name":"-y","x":11,"y":8,"z":-5},{"level":1,"name":"-y","x":11,"y":9,"z":-5},{"level":1,"name":"-y","x":11,"y":10,"z":-5},{"level":1,"name":"-y","x":11,"y":3,"z":-4},{"level":1,"name":"-y","x":11,"y":4,"z":-4},{"level":1,"name":"-y","x":11,"y":5,"z":-4},{"level":1,"name":"-y","x":11,"y":6,"z":-4},{"level":1,"name":"-y","x":11,"y":7,"z":-4},{"level":1,"name":"-y","x":11,"y":8,"z":-4},{"level":1,"name":"-y","x":11,"y":9,"z":-4},{"level":1,"name":"-y","x":11,"y":3,"z":-3},