{"anchorX":0,"anchorY":0,"anchorZ":0,"blockIdVersion":11,"blocks":[{"filler":1023,"name":"Deco_Naval_Proximity_Mine","x":-1,"y":11,"z":-1},{"filler":2047,"name":"Deco_Naval_Proximity_Mine","x":-1,"y":12,"z":-1},{"filler":3071,"name":"Deco_Naval_Proximity_Mine","x":-1,"y":13,"z":-1},{"filler":31,"name":"Deco_Naval_Proximity_Mine","x":-1,"y":11,"z":0},{"filler":1055,"name":"Deco_Naval_Proximity_Mine","x":-1,"y":12,"z":0},{"filler":2079,"name":"Deco_Naval_Proximity_Mine","x":-1,"y":13,"z":0},{"filler":63,"name":"Deco_Naval_Proximity_Mine","x":-1,"y":11,"z":1},{"filler":1087,"name":"Deco_Naval_Proximity_Mine","x":-1,"y":12,"z":1},{"filler":2111,"name":"Deco_Naval_Proximity_Mine","x":-1,"y":13,"z":1},{"filler":992,"name":"Deco_Naval_Proximity_Mine","x":0,"y":11,"z":-1},{"filler":2016,"name":"Deco_Naval_Proximity_Mine","x":0,"y":12,"z":-1},{"filler":3040,"name":"Deco_Naval_Proximity_Mine","x":0,"y":13,"z":-1},{"name":"Rock_Basalt_Stalactite_Large","x":0,"y":0,"z":0},{"filler":1024,"name":"Rock_Basalt_Stalactite_Large","x":0,"y":1,"z":0},{"name":"Deco_Iron_Chain_Small","x":0,"y":2,"z":0},{"name":"Deco_Iron_Chain_Small","x":0,"y":3,"z":0},{"name":"Deco_Iron_Chain_Small","x":0,"y":4,"z":0},{"name":"Deco_Iron_Chain_Small","x":0,"y":5,"z":0},{"name":"Deco_Iron_Chain_Small","x":0,"y":6,"z":0},{"name":"Deco_Iron_Chain_Small","x":0,"y":7,"z":0},{"name":"Deco_Iron_Chain_Small","x":0,"y":8,"z":0},{"name":"Deco_Iron_Chain_Small","x":0,"y":9,"z":0},{"name":"Deco_Iron_Chain_Small","x":0,"y":10,"z":0},{"name":"Deco_Naval_Proximity_Mine","x":0,"y":11,"z":0},{"filler":1024,"name":"Deco_Naval_Proximity_Mine","x":0,"y":12,"z":0},{"filler":2048,"name":"Deco_Naval_Proximity_Mine","x":0,"y":13,"z":0},{"filler":32,"name":"Deco_Naval_Proximity_Mine","x":0,"y":11,"z":1},{"filler":1056,"name":"Deco_Naval_Proximity_Mine","x":0,"y":12,"z":1},{"filler":2080,"name":"Deco_Naval_Proximity_Mine","x":0,"y":13,"z":1},{"filler":993,"name":"Deco_Naval_Proximity_Mine","x":1,"y":11,"z":-1},{"filler":2017,"name":"Deco_Naval_Proximity_Mine","x":1,"y":12,"z":-1},{"filler":3041,"name":"Deco_Naval_Proximity_Mine","x":1,"y":13,"z":-1},{"filler":1,"name":"Deco_Naval_Proximity_Mine","x":1,"y":11,"z":0},{"filler":1025,"name":"Deco_Naval_Proximity_Mine","x":1,"y":12,"z":0},{"filler":2049,"name":"Deco_Naval_Proximity_Mine","x":1,"y":13,"z":0},{"filler":33,"name":"Deco_Naval_Proximity_Mine","x":1,"y":11,"z":1},{"filler":1057,"name":"Deco_Naval_Proximity_Mine","x":1,"y":12,"z":1},{"filler":2081,"name":"Deco_Naval_Proximity_Mine","x":1,"y":13,"z":1}],"fluids":[{"level":1,"name":"Water_Source","x":-1,"y":11,"z":-1},{"level":1,"name":"Water_Source","x":-1,"y":12,"z":-1},{"level":1,"name":"Water_Source","x":-1,"y":13,"z":-1},{"level":1,"name":"Water_Source","x":-1,"y":11,"z":0},{"level":1,"name":"Water_Source","x":-1,"y":12,"z":0},{"level":1,"name":"Water_Source","x":-1,"y":13,"z":0},{"level":1,"name":"Water_Source","x":-1,"y":11,"z":1},{"level":1,"name":"Water_Source","x":-1,"y":12,"z":1},{"level":1,"name":"Water_Source","x":-1,"y":13,"z":1},{"level":1,"name":"Water_Source","x":0,"y":11,"z":-1},{"level":1,"name":"Water_Source","x":0,"y":12,"z":-1},{"level":1,"name":"Water_Source","x":0,"y":13,"z":-1},{"level":1,"name":"Water_Source","x":0,"y":0,"z":0},{"level":1,"name":"Water_Source","x":0,"y":1,"z":0},{"level":1,"name":"Water_Source","x":0,"y":2,"z":0},{"level":1,"name":"Water_Source","x":0,"y":3,"z":0},{"level":1,"name":"Water_Source","x":0,"y":4,"z":0},{"level":1,"name":"Water_Source","x":0,"y":5,"z":0},{"level":1,"name":"Water_Source","x":0,"y":6,"z":0},{"level":1,"name":"Water_Source","x":0,"y":7,"z":0},{"level":1,"name":"Water_Source","x":0,"y":8,"z":0},{"level":1,"name":"Water_Source","x":0,"y":9,"z":0},{"level":1,"name":"Water_Source","x":0,"y":10,"z":0},{"level":1,"name":"Water_Source","x":0,"y":11,"z":0},{"level":1,"name":"Water_Source","x":0,"y":12,"z":0},{"level":1,"name":"Water_Source","x":0,"y":13,"z":0},{"level":1,"name":"Water_Source","x":0,"y":11,"z":1},{"level":1,"name":"Water_Source","x":0,"y":12,"z":1},{"level":1,"name":"Water_Source","x":0,"y":13,"z":1},{"level":1,"name":"Water_Source","x":1,"y":11,"z":-1},{"level":1,"name":"Water_Source","x":1,"y":12,"z":-1},{"level":1,"name":"Water_Source","x":1,"y":13,"z":-1},{"level":1,"name":"Water_Source","x":1,"y":11,"z":0},{"level":1,"name":"Water_Source","x":1,"y":12,"z":0},{"level":1,"name":"Water_Source","x":1,"y":13,"z":0},{"level":1,"name":"Water_Source","x":1,"y":11,"z":1},{"level":1,"name":"Water_Source","x":1,"y":12,"z":1},{"level":1,"name":"Water_Source","x":1,"y":13,"z":1}],"version":8}