{
  "version": 8,
  "blockIdVersion": 11,
  "anchorX": 0,
  "anchorY": 0,
  "anchorZ": 0,
  "blocks": [
    {
      "x": -1,
      "y": 9,
      "z": -1,
      "name": "Deco_Naval_Proximity_Mine",
      "filler": 1023
    },
    {
      "x": -1,
      "y": 10,
      "z": -1,
      "name": "Deco_Naval_Proximity_Mine",
      "filler": 2047
    },
    {
      "x": -1,
      "y": 11,
      "z": -1,
      "name": "Deco_Naval_Proximity_Mine",
      "filler": 3071
    },
    {
      "x": -1,
      "y": 9,
      "z": 0,
      "name": "Deco_Naval_Proximity_Mine",
      "filler": 31
    },
    {
      "x": -1,
      "y": 10,
      "z": 0,
      "name": "Deco_Naval_Proximity_Mine",
      "filler": 1055
    },
    {
      "x": -1,
      "y": 11,
      "z": 0,
      "name": "Deco_Naval_Proximity_Mine",
      "filler": 2079
    },
    {
      "x": -1,
      "y": 9,
      "z": 1,
      "name": "Deco_Naval_Proximity_Mine",
      "filler": 63
    },
    {
      "x": -1,
      "y": 10,
      "z": 1,
      "name": "Deco_Naval_Proximity_Mine",
      "filler": 1087
    },
    {
      "x": -1,
      "y": 11,
      "z": 1,
      "name": "Deco_Naval_Proximity_Mine",
      "filler": 2111
    },
    {
      "x": 0,
      "y": 9,
      "z": -1,
      "name": "Deco_Naval_Proximity_Mine",
      "filler": 992
    },
    {
      "x": 0,
      "y": 10,
      "z": -1,
      "name": "Deco_Naval_Proximity_Mine",
      "filler": 2016
    },
    {
      "x": 0,
      "y": 11,
      "z": -1,
      "name": "Deco_Naval_Proximity_Mine",
      "filler": 3040
    },
    {
      "x": 0,
      "y": 0,
      "z": 0,
      "name": "Rock_Basalt_Stalactite_Large"
    },
    {
      "x": 0,
      "y": 1,
      "z": 0,
      "name": "Rock_Basalt_Stalactite_Large",
      "filler": 1024
    },
    {
      "x": 0,
      "y": 2,
      "z": 0,
      "name": "Deco_Iron_Chain_Heavy"
    },
    {
      "x": 0,
      "y": 3,
      "z": 0,
      "name": "Deco_Iron_Chain_Heavy"
    },
    {
      "x": 0,
      "y": 4,
      "z": 0,
      "name": "Deco_Iron_Chain_Heavy"
    },
    {
      "x": 0,
      "y": 5,
      "z": 0,
      "name": "Deco_Iron_Chain_Heavy"
    },
    {
      "x": 0,
      "y": 6,
      "z": 0,
      "name": "Deco_Iron_Chain_Heavy"
    },
    {
      "x": 0,
      "y": 7,
      "z": 0,
      "name": "Deco_Iron_Chain_Heavy"
    },
    {
      "x": 0,
      "y": 8,
      "z": 0,
      "name": "Deco_Iron_Chain_Heavy"
    },
    {
      "x": 0,
      "y": 9,
      "z": 0,
      "name": "Deco_Naval_Proximity_Mine"
    },
    {
      "x": 0,
      "y": 10,
      "z": 0,
      "name": "Deco_Naval_Proximity_Mine",
      "filler": 1024
    },
    {
      "x": 0,
      "y": 11,
      "z": 0,
      "name": "Deco_Naval_Proximity_Mine",
      "filler": 2048
    },
    {
      "x": 0,
      "y": 9,
      "z": 1,
      "name": "Deco_Naval_Proximity_Mine",
      "filler": 32
    },
    {
      "x": 0,
      "y": 10,
      "z": 1,
      "name": "Deco_Naval_Proximity_Mine",
      "filler": 1056
    },
    {
      "x": 0,
      "y": 11,
      "z": 1,
      "name": "Deco_Naval_Proximity_Mine",
      "filler": 2080
    },
    {
      "x": 1,
      "y": 9,
      "z": -1,
      "name": "Deco_Naval_Proximity_Mine",
      "filler": 993
    },
    {
      "x": 1,
      "y": 10,
      "z": -1,
      "name": "Deco_Naval_Proximity_Mine",
      "filler": 2017
    },
    {
      "x": 1,
      "y": 11,
      "z": -1,
      "name": "Deco_Naval_Proximity_Mine",
      "filler": 3041
    },
    {
      "x": 1,
      "y": 9,
      "z": 0,
      "name": "Deco_Naval_Proximity_Mine",
      "filler": 1
    },
    {
      "x": 1,
      "y": 10,
      "z": 0,
      "name": "Deco_Naval_Proximity_Mine",
      "filler": 1025
    },
    {
      "x": 1,
      "y": 11,
      "z": 0,
      "name": "Deco_Naval_Proximity_Mine",
      "filler": 2049
    },
    {
      "x": 1,
      "y": 9,
      "z": 1,
      "name": "Deco_Naval_Proximity_Mine",
      "filler": 33
    },
    {
      "x": 1,
      "y": 10,
      "z": 1,
      "name": "Deco_Naval_Proximity_Mine",
      "filler": 1057
    },
    {
      "x": 1,
      "y": 11,
      "z": 1,
      "name": "Deco_Naval_Proximity_Mine",
      "filler": 2081
    }
  ],
  "fluids": [
    {
      "x": -1,
      "y": 9,
      "z": -1,
      "name": "Water_Source",
      "level": 1
    },
    {
      "x": -1,
      "y": 10,
      "z": -1,
      "name": "Water_Source",
      "level": 1
    },
    {
      "x": -1,
      "y": 11,
      "z": -1,
      "name": "Water_Source",
      "level": 1
    },
    {
      "x": -1,
      "y": 9,
      "z": 0,
      "name": "Water_Source",
      "level": 1
    },
    {
      "x": -1,
      "y": 10,
      "z": 0,
      "name": "Water_Source",
      "level": 1
    },
    {
      "x": -1,
      "y": 11,
      "z": 0,
      "name": "Water_Source",
      "level": 1
    },
    {
      "x": -1,
      "y": 9,
      "z": 1,
      "name": "Water_Source",
      "level": 1
    },
    {
      "x": -1,
      "y": 10,
      "z": 1,
      "name": "Water_Source",
      "level": 1
    },
    {
      "x": -1,
      "y": 11,
      "z": 1,
      "name": "Water_Source",
      "level": 1
    },
    {
      "x": 0,
      "y": 9,
      "z": -1,
      "name": "Water_Source",
      "level": 1
    },
    {
      "x": 0,
      "y": 10,
      "z": -1,
      "name": "Water_Source",
      "level": 1
    },
    {
      "x": 0,
      "y": 11,
      "z": -1,
      "name": "Water_Source",
      "level": 1
    },
    {
      "x": 0,
      "y": 0,
      "z": 0,
      "name": "Water_Source",
      "level": 1
    },
    {
      "x": 0,
      "y": 1,
      "z": 0,
      "name": "Water_Source",
      "level": 1
    },
    {
      "x": 0,
      "y": 2,
      "z": 0,
      "name": "Water_Source",
      "level": 1
    },
    {
      "x": 0,
      "y": 3,
      "z": 0,
      "name": "Water_Source",
      "level": 1
    },
    {
      "x": 0,
      "y": 4,
      "z": 0,
      "name": "Water_Source",
      "level": 1
    },
    {
      "x": 0,
      "y": 5,
      "z": 0,
      "name": "Water_Source",
      "level": 1
    },
    {
      "x": 0,
      "y": 6,
      "z": 0,
      "name": "Water_Source",
      "level": 1
    },
    {
      "x": 0,
      "y": 7,
      "z": 0,
      "name": "Water_Source",
      "level": 1
    },
    {
      "x": 0,
      "y": 8,
      "z": 0,
      "name": "Water_Source",
      "level": 1
    },
    {
      "x": 0,
      "y": 9,
      "z": 0,
      "name": "Water_Source",
      "level": 1
    },
    {
      "x": 0,
      "y": 10,
      "z": 0,
      "name": "Water_Source",
      "level": 1
    },
    {
      "x": 0,
      "y": 11,
      "z": 0,
      "name": "Water_Source",
      "level": 1
    },
    {
      "x": 0,
      "y": 9,
      "z": 1,
      "name": "Water_Source",
      "level": 1
    },
    {
      "x": 0,
      "y": 10,
      "z": 1,
      "name": "Water_Source",
      "level": 1
    },
    {
      "x": 0,
      "y": 11,
      "z": 1,
      "name": "Water_Source",
      "level": 1
    },
    {
      "x": 1,
      "y": 9,
      "z": -1,
      "name": "Water_Source",
      "level": 1
    },
    {
      "x": 1,
      "y": 10,
      "z": -1,
      "name": "Water_Source",
      "level": 1
    },
    {
      "x": 1,
      "y": 11,
      "z": -1,
      "name": "Water_Source",
      "level": 1
    },
    {
      "x": 1,
      "y": 9,
      "z": 0,
      "name": "Water_Source",
      "level": 1
    },
    {
      "x": 1,
      "y": 10,
      "z": 0,
      "name": "Water_Source",
      "level": 1
    },
    {
      "x": 1,
      "y": 11,
      "z": 0,
      "name": "Water_Source",
      "level": 1
    },
    {
      "x": 1,
      "y": 9,
      "z": 1,
      "name": "Water_Source",
      "level": 1
    },
    {
      "x": 1,
      "y": 10,
      "z": 1,
      "name": "Water_Source",
      "level": 1
    },
    {
      "x": 1,
      "y": 11,
      "z": 1,
      "name": "Water_Source",
      "level": 1
    }
  ]
}