{"anchorX":0,"anchorY":0,"anchorZ":0,"blockIdVersion":11,"blocks":[{"name":"Rock_Sandstone_Red_Brick_Stairs","rotation":10,"x":-2,"y":0,"z":-4},{"name":"Rock_Sandstone_Red_Brick","x":-2,"y":1,"z":-4},{"name":"Rock_Sandstone_Red_Brick_Stairs","rotation":2,"x":-2,"y":2,"z":-4},{"name":"Rock_Sandstone_Red_Brick","x":-2,"y":1,"z":-3},{"name":"*Rock_Sandstone_Red_Brick_Half_State_Definitions_Block","x":-2,"y":2,"z":-3},{"name":"Rock_Sandstone_Red_Brick_Beam","x":-2,"y":3,"z":-3},{"name":"Rock_Sandstone_Red_Brick_Beam","x":-2,"y":4,"z":-3},{"name":"*Soil_Clay_Ocean_Brick_Roof_State_Definitions_Corner_Right","rotation":3,"x":-2,"y":5,"z":-3},{"name":"Rock_Sandstone_Red_Brick_Half","rotation":8,"x":-2,"y":1,"z":-2},{"name":"*Rock_Sandstone_Red_Brick_Half_State_Definitions_Block","x":-2,"y":2,"z":-2},{"name":"Rock_Sandstone_Red_Brick_Wall","rotation":3,"x":-2,"y":3,"z":-2},{"name":"Soil_Clay_Ocean_Brick_Roof_Hollow","rotation":3,"x":-2,"y":5,"z":-2},{"name":"*Rock_Sandstone_Red_Brick_Half_State_Definitions_Block","x":-2,"y":2,"z":-1},{"name":"Rock_Sandstone_Red_Brick_Wall","rotation":3,"x":-2,"y":3,"z":-1},{"name":"Soil_Clay_Ocean_Brick_Roof_Hollow","rotation":3,"x":-2,"y":5,"z":-1},{"name":"*Rock_Sandstone_Red_Brick_Half_State_Definitions_Block","x":-2,"y":2,"z":0},{"name":"Rock_Sandstone_Red_Brick_Wall","rotation":3,"x":-2,"y":3,"z":0},{"name":"Soil_Clay_Ocean_Brick_Roof_Hollow","rotation":3,"x":-2,"y":5,"z":0},{"name":"*Rock_Sandstone_Red_Brick_Half_State_Definitions_Block","x":-2,"y":2,"z":1},{"name":"Rock_Sandstone_Red_Brick_Wall","rotation":3,"x":-2,"y":3,"z":1},{"name":"Soil_Clay_Ocean_Brick_Roof_Hollow","rotation":3,"x":-2,"y":5,"z":1},{"name":"*Rock_Sandstone_Red_Brick_Half_State_Definitions_Block","x":-2,"y":2,"z":2},{"name":"Rock_Sandstone_Red_Brick_Wall","rotation":3,"x":-2,"y":3,"z":2},{"name":"Soil_Clay_Ocean_Brick_Roof_Hollow","rotation":3,"x":-2,"y":5,"z":2},{"name":"Rock_Sandstone_Red_Brick_Half","rotation":8,"x":-2,"y":1,"z":3},{"name":"Rock_Sandstone_Red_Brick","x":-2,"y":2,"z":3},{"name":"Rock_Sandstone_Red_Brick_Wall","rotation":3,"x":-2,"y":3,"z":3},{"name":"Soil_Clay_Ocean_Brick_Roof_Hollow","rotation":3,"x":-2,"y":5,"z":3},{"name":"Rock_Sandstone_Red_Brick","x":-2,"y":1,"z":4},{"name":"Rock_Sandstone_Red_Brick","x":-2,"y":2,"z":4},{"name":"Rock_Sandstone_Red_Brick_Beam","x":-2,"y":3,"z":4},{"name":"Rock_Sandstone_Red_Brick_Beam","x":-2,"y":4,"z":4},{"name":"*Soil_Clay_Ocean_Brick_Roof_State_Definitions_Corner_Left","rotation":3,"x":-2,"y":5,"z":4},{"name":"Rock_Sandstone_Red_Brick_Stairs","rotation":8,"x":-2,"y":0,"z":5},{"name":"Rock_Sandstone_Red_Brick","x":-2,"y":1,"z":5},{"name":"Rock_Sandstone_Red_Brick_Stairs","x":-2,"y":2,"z":5},{"name":"Rock_Sandstone_Cobble_Half","rotation":8,"x":-1,"y":0,"z":-4},{"name":"Rock_Sandstone_Cobble_Half","x":-1,"y":1,"z":-3},{"name":"Soil_Clay_Ocean_Brick_Roof_Hollow","rotation":2,"x":-1,"y":5,"z":-3},{"name":"Rock_Sandstone_Cobble_Half","rotation":8,"x":-1,"y":1,"z":-2},{"name":"Soil_Clay_Ocean_Brick_Roof_Flat","rotation":2,"x":-1,"y":6,"z":-2},{"name":"Rock_Sandstone_Cobble_Half","x":-1,"y":2,"z":-1},{"name":"Soil_Clay_Ocean_Brick_Roof_Flat","rotation":2,"x":-1,"y":6,"z":-1},{"name":"Rock_Sandstone_Cobble_Half","x":-1,"y":2,"z":0},{"name":"Soil_Clay_Ocean_Brick_Roof_Flat","rotation":2,"x":-1,"y":6,"z":0},{"name":"Rock_Sandstone_Cobble_Half","x":-1,"y":2,"z":1},{"name":"Soil_Clay_Ocean_Brick_Roof_Flat","rotation":2,"x":-1,"y":6,"z":1},{"name":"Rock_Sandstone_Cobble_Half","x":-1,"y":2,"z":2},{"name":"Soil_Clay_Ocean_Brick_Roof_Flat","rotation":2,"x":-1,"y":6,"z":2},{"name":"Rock_Sandstone_Cobble_Half","rotation":8,"x":-1,"y":1,"z":3},{"name":"Soil_Clay_Ocean_Brick_Roof_Flat","rotation":2,"x":-1,"y":6,"z":3},{"name":"Rock_Sandstone_Cobble_Half","x":-1,"y":1,"z":4},{"name":"Soil_Clay_Ocean_Brick_Roof_Hollow","x":-1,"y":5,"z":4},{"name":"Rock_Sandstone_Cobble_Half","rotation":8,"x":-1,"y":0,"z":5},{"name":"Rock_Sandstone_Cobble_Half","rotation":8,"x":0,"y":0,"z":-4},{"name":"Rock_Sandstone_Cobble_Half","x":0,"y":1,"z":-3},{"name":"Soil_Clay_Ocean_Brick_Roof_Hollow","rotation":2,"x":0,"y":5,"z":-3},{"name":"Rock_Sandstone_Cobble_Half","rotation":8,"x":0,"y":1,"z":-2},{"name":"Soil_Clay_Ocean_Brick_Roof_Flat","x":0,"y":6,"z":-2},{"name":"Rock_Sandstone_Cobble_Half","x":0,"y":2,"z":-1},{"name":"Soil_Clay_Ocean_Brick_Roof_Flat","x":0,"y":6,"z":-1},{"name":"Rock_Sandstone_Cobble_Half","x":0,"y":2,"z":0},{"name":"Soil_Clay_Ocean_Brick_Roof_Flat","x":0,"y":6,"z":0},{"name":"Rock_Sandstone_Cobble_Half","x":0,"y":2,"z":1},{"name":"Soil_Clay_Ocean_Brick_Roof_Flat","x":0,"y":6,"z":1},{"name":"Rock_Sandstone_Cobble_Half","x":0,"y":2,"z":2},{"name":"Soil_Clay_Ocean_Brick_Roof_Flat","x":0,"y":6,"z":2},{"name":"Rock_Sandstone_Cobble_Half","rotation":8,"x":0,"y":1,"z":3},{"name":"Soil_Clay_Ocean_Brick_Roof_Flat","x":0,"y":6,"z":3},{"name":"Rock_Sandstone_Cobble_Half","x":0,"y":1,"z":4},{"name":"Soil_Clay_Ocean_Brick_Roof_Hollow","x":0,"y":5,"z":4},{"name":"Rock_Sandstone_Cobble_Half","rotation":8,"x":0,"y":0,"z":5},{"name":"Rock_Sandstone_Cobble_Half","rotation":8,"x":1,"y":0,"z":-4},{"name":"Rock_Sandstone_Cobble_Half","x":1,"y":1,"z":-3},{"name":"Soil_Clay_Ocean_Brick_Roof_Hollow","rotation":2,"x":1,"y":5,"z":-3},{"name":"Rock_Sandstone_Cobble_Half","rotation":8,"x":1,"y":1,"z":-2},{"name":"Soil_Clay_Ocean_Brick_Roof_Flat","rotation":2,"x":1,"y":6,"z":-2},{"name":"Rock_Sandstone_Cobble_Half","x":1,"y":2,"z":-1},{"name":"Soil_Clay_Ocean_Brick_Roof_Flat","rotation":2,"x":1,"y":6,"z":-1},{"name":"Rock_Sandstone_Cobble_Half","x":1,"y":2,"z":0},{"name":"Soil_Clay_Ocean_Brick_Roof_Flat","rotation":2,"x":1,"y":6,"z":0},{"name":"Rock_Sandstone_Cobble_Half","x":1,"y":2,"z":1},{"name":"Soil_Clay_Ocean_Brick_Roof_Flat","rotation":2,"x":1,"y":6,"z":1},{"name":"Rock_Sandstone_Cobble_Half","x":1,"y":2,"z":2},{"name":"Soil_Clay_Ocean_Brick_Roof_Flat","rotation":2,"x":1,"y":6,"z":2},{"name":"Rock_Sandstone_Cobble_Half","rotation":8,"x":1,"y":1,"z":3},{"name":"Soil_Clay_Ocean_Brick_Roof_Flat","rotation":2,"x":1,"y":6,"z":3},{"name":"Rock_Sandstone_Cobble_Half","x":1,"y":1,"z":4},{"name":"Soil_Clay_Ocean_Brick_Roof_Hollow","x":1,"y":5,"z":4},{"name":"Rock_Sandstone_Cobble_Half","rotation":8,"x":1,"y":0,"z":5},{"name":"Rock_Sandstone_Cobble_Half","rotation":8,"x":2,"y":0,"z":-4},{"name":"Rock_Sandstone_Cobble_Half","x":2,"y":1,"z":-3},{"name":"Soil_Clay_Ocean_Brick_Roof_Hollow","rotation":2,"x":2,"y":5,"z":-3},{"name":"Rock_Sandstone_Cobble_Half","rotation":8,"x":2,"y":1,"z":-2},{"name":"Soil_Clay_Ocean_Brick_Roof_Flat","x":2,"y":6,"z":-2},{"name":"Rock_Sandstone_Cobble_Half","x":2,"y":2,"z":-1},{"name":"Soil_Clay_Ocean_Brick_Roof_Flat","x":2,"y":6,"z":-1},{"name":"Rock_Sandstone_Cobble_Half","x":2,"y":2,"z":0},{"name":"Soil_Clay_Ocean_Brick_Roof_Flat","x":2,"y":6,"z":0},{"name":"Rock_Sandstone_Cobble_Half","x":2,"y":2,"z":1},{"name":"Soil_Clay_Ocean_Brick_Roof_Flat","x":2,"y":6,"z":1},{"name":"Rock_Sandstone_Cobble_Half","x":2,"y":2,"z":2},{"name":"Soil_Clay_Ocean_Brick_Roof_Flat","x":2,"y":6,"z":2},{"name":"Rock_Sandstone_Cobble_Half","rotation":8,"x":2,"y":1,"z":3},{"name":"Soil_Clay_Ocean_Brick_Roof_Flat","x":2,"y":6,"z":3},{"name":"Rock_Sandstone_Cobble_Half","x":2,"y":1,"z":4},{"name":"Soil_Clay_Ocean_Brick_Roof_Hollow","x":2,"y":5,"z":4},{"name":"Rock_Sandstone_Cobble_Half","rotation":8,"x":2,"y":0,"z":5},{"name":"Rock_Sandstone_Red_Brick_Stairs","rotation":10,"x":3,"y":0,"z":-4},{"name":"Rock_Sandstone_Red_Brick","x":3,"y":1,"z":-4},{"name":"Rock_Sandstone_Red_Brick_Stairs","rotation":2,"x":3,"y":2,"z":-4},{"name":"Rock_Sandstone_Red_Brick","x":3,"y":1,"z":-3},{"name":"Rock_Sandstone_Red_Brick","x":3,"y":2,"z":-3},{"name":"Rock_Sandstone_Red_Brick_Beam","x":3,"y":3,"z":-3},{"name":"Rock_Sandstone_Red_Brick_Beam","x":3,"y":4,"z":-3},{"name":"*Soil_Clay_Ocean_Brick_Roof_State_Definitions_Corner_Left","rotation":1,"x":3,"y":5,"z":-3},{"name":"Rock_Sandstone_Red_Brick_Half","rotation":8,"x":3,"y":1,"z":-2},{"name":"Rock_Sandstone_Red_Brick","x":3,"y":2,"z":-2},{"name":"Rock_Sandstone_Red_Brick_Wall","rotation":3,"x":3,"y":3,"z":-2},{"name":"Soil_Clay_Ocean_Brick_Roof_Hollow","rotation":1,"x":3,"y":5,"z":-2},{"name":"Rock_Sandstone_Red_Brick","x":3,"y":2,"z":-1},{"name":"Rock_Sandstone_Red_Brick_Wall","rotation":3,"x":3,"y":3,"z":-1},{"name":"Soil_Clay_Ocean_Brick_Roof_Hollow","rotation":1,"x":3,"y":5,"z":-1},{"name":"Rock_Sandstone_Red_Brick","x":3,"y":2,"z":0},{"name":"Rock_Sandstone_Red_Brick_Wall","rotation":3,"x":3,"y":3,"z":0},{"name":"Soil_Clay_Ocean_Brick_Roof_Hollow","rotation":1,"x":3,"y":5,"z":0},{"name":"Rock_Sandstone_Red_Brick","x":3,"y":2,"z":1},{"name":"Rock_Sandstone_Red_Brick_Wall","rotation":3,"x":3,"y":3,"z":1},{"name":"Soil_Clay_Ocean_Brick_Roof_Hollow","rotation":1,"x":3,"y":5,"z":1},{"name":"Rock_Sandstone_Red_Brick","x":3,"y":2,"z":2},{"name":"Rock_Sandstone_Red_Brick_Wall","rotation":3,"x":3,"y":3,"z":2},{"name":"Soil_Clay_Ocean_Brick_Roof_Hollow","rotation":1,"x":3,"y":5,"z":2},{"name":"Rock_Sandstone_Red_Brick_Half","rotation":8,"x":3,"y":1,"z":3},{"name":"Rock_Sandstone_Red_Brick","x":3,"y":2,"z":3},{"name":"Rock_Sandstone_Red_Brick_Wall","rotation":3,"x":3,"y":3,"z":3},{"name":"Soil_Clay_Ocean_Brick_Roof_Hollow","rotation":1,"x":3,"y":5,"z":3},{"name":"Rock_Sandstone_Red_Brick","x":3,"y":1,"z":4},{"name":"Rock_Sandstone_Red_Brick","x":3,"y":2,"z":4},{"name":"Rock_Sandstone_Red_Brick_Beam","x":3,"y":3,"z":4},{"name":"Rock_Sandstone_Red_Brick_Beam","x":3,"y":4,"z":4},{"name":"*Soil_Clay_Ocean_Brick_Roof_State_Definitions_Corner_Left","x":3,"y":5,"z":4},{"name":"Rock_Sandstone_Red_Brick_Stairs","rotation":8,"x":3,"y":0,"z":5},{"name":"Rock_Sandstone_Red_Brick","x":3,"y":1,"z":5},{"name":"Rock_Sandstone_Red_Brick_Stairs","x":3,"y":2,"z":5}],"fluids":[{"level":1,"name":"Water_Source","x":-2,"y":0,"z":-4},{"level":1,"name":"Water_Source","x":-2,"y":1,"z":-4},{"level":1,"name":"Water_Source","x":-2,"y":2,"z":-4},{"level":1,"name":"Water_Source","x":-2,"y":1,"z":-3},{"level":1,"name":"Water_Source","x":-2,"y":2,"z":-3},{"level":1,"name":"Water_Source","x":-2,"y":3,"z":-3},{"level":1,"name":"Water_Source","x":-2,"y":4,"z":-3},{"level":1,"name":"Water_Source","x":-2,"y":5,"z":-3},{"level":1,"name":"Water_Source","x":-2,"y":1,"z":-2},{"level":1,"name":"Water_Source","x":-2,"y":2,"z":-2},{"level":1,"name":"Water_Source","x":-2,"y":3,"z":-2},{"level":1,"name":"Water_Source","x":-2,"y":5,"z":-2},{"level":1,"name":"Water_Source","x":-2,"y":2,"z":-1},{"level":1,"name":"Water_Source","x":-2,"y":3,"z":-1},{"level":1,"name":"Water_Source","x":-2,"y":5,"z":-1},{"level":1,"name":"Water_Source","x":-2,"y":2,"z":0},{"level":1,"name":"Water_Source","x":-2,"y":3,"z":0},{"level":1,"name":"Water_Source","x":-2,"y":5,"z":0},{"level":1,"name":"Water_Source","x":-2,"y":2,"z":1},{"level":1,"name":"Water_Source","x":-2,"y":3,"z":1},{"level":1,"name":"Water_Source","x":-2,"y":5,"z":1},{"level":1,"name":"Water_Source","x":-2,"y":2,"z":2},{"level":1,"name":"Water_Source","x":-2,"y":3,"z":2},{"level":1,"name":"Water_Source","x":-2,"y":5,"z":2},{"level":1,"name":"Water_Source","x":-2,"y":1,"z":3},{"level":1,"name":"Water_Source","x":-2,"y":2,"z":3},{"level":1,"name":"Water_Source","x":-2,"y":3,"z":3},{"level":1,"name":"Water_Source","x":-2,"y":5,"z":3},{"level":1,"name":"Water_Source","x":-2,"y":1,"z":4},{"level":1,"name":"Water_Source","x":-2,"y":2,"z":4},{"level":1,"name":"Water_Source","x":-2,"y":3,"z":4},{"level":1,"name":"Water_Source","x":-2,"y":4,"z":4},{"level":1,"name":"Water_Source","x":-2,"y":5,"z":4},{"level":1,"name":"Water_Source","x":-2,"y":0,"z":5},{"level":1,"name":"Water_Source","x":-2,"y":1,"z":5},{"level":1,"name":"Water_Source","x":-2,"y":2,"z":5},{"level":1,"name":"Water_Source","x":-1,"y":0,"z":-4},{"level":1,"name":"Water_Source","x":-1,"y":1,"z":-3},{"level":1,"name":"Water_Source","x":-1,"y":5,"z":-3},{"level":1,"name":"Water_Source","x":-1,"y":1,"z":-2},{"level":1,"name":"Water_Source","x":-1,"y":6,"z":-2},{"level":1,"name":"Water_Source","x":-1,"y":2,"z":-1},{"level":1,"name":"Water_Source","x":-1,"y":6,"z":-1},{"level":1,"name":"Water_Source","x":-1,"y":2,"z":0},{"level":1,"name":"Water_Source","x":-1,"y":6,"z":0},{"level":1,"name":"Water_Source","x":-1,"y":2,"z":1},{"level":1,"name":"Water_Source","x":-1,"y":6,"z":1},{"level":1,"name":"Water_Source","x":-1,"y":2,"z":2},{"level":1,"name":"Water_Source","x":-1,"y":6,"z":2},{"level":1,"name":"Water_Source","x":-1,"y":1,"z":3},{"level":1,"name":"Water_Source","x":-1,"y":6,"z":3},{"level":1,"name":"Water_Source","x":-1,"y":1,"z":4},{"level":1,"name":"Water_Source","x":-1,"y":5,"z":4},{"level":1,"name":"Water_Source","x":-1,"y":0,"z":5},{"level":1,"name":"Water_Source","x":0,"y":0,"z":-4},{"level":1,"name":"Water_Source","x":0,"y":1,"z":-3},{"level":1,"name":"Water_Source","x":0,"y":5,"z":-3},{"level":1,"name":"Water_Source","x":0,"y":1,"z":-2},{"level":1,"name":"Water_Source","x":0,"y":6,"z":-2},{"level":1,"name":"Water_Source","x":0,"y":2,"z":-1},{"level":1,"name":"Water_Source","x":0,"y":6,"z":-1},{"level":1,"name":"Water_Source","x":0,"y":2,"z":0},{"level":1,"name":"Water_Source","x":0,"y":6,"z":0},{"level":1,"name":"Water_Source","x":0,"y":2,"z":1},{"level":1,"name":"Water_Source","x":0,"y":6,"z":1},{"level":1,"name":"Water_Source","x":0,"y":2,"z":2},{"level":1,"name":"Water_Source","x":0,"y":6,"z":2},{"level":1,"name":"Water_Source","x":0,"y":1,"z":3},{"level":1,"name":"Water_Source","x":0,"y":6,"z":3},{"level":1,"name":"Water_Source","x":0,"y":1,"z":4},{"level":1,"name":"Water_Source","x":0,"y":5,"z":4},{"level":1,"name":"Water_Source","x":0,"y":0,"z":5},{"level":1,"name":"Water_Source","x":1,"y":0,"z":-4},{"level":1,"name":"Water_Source","x":1,"y":1,"z":-3},{"level":1,"name":"Water_Source","x":1,"y":5,"z":-3},{"level":1,"name":"Water_Source","x":1,"y":1,"z":-2},{"level":1,"name":"Water_Source","x":1,"y":6,"z":-2},{"level":1,"name":"Water_Source","x":1,"y":2,"z":-1},{"level":1,"name":"Water_Source","x":1,"y":6,"z":-1},{"level":1,"name":"Water_Source","x":1,"y":2,"z":0},{"level":1,"name":"Water_Source","x":1,"y":6,"z":0},{"level":1,"name":"Water_Source","x":1,"y":2,"z":1},{"level":1,"name":"Water_Source","x":1,"y":6,"z":1},{"level":1,"name":"Water_Source","x":1,"y":2,"z":2},{"level":1,"name":"Water_Source","x":1,"y":6,"z":2},{"level":1,"name":"Water_Source","x":1,"y":1,"z":3},{"level":1,"name":"Water_Source","x":1,"y":6,"z":3},{"level":1,"name":"Water_Source","x":1,"y":1,"z":4},{"level":1,"name":"Water_Source","x":1,"y":5,"z":4},{"level":1,"name":"Water_Source","x":1,"y":0,"z":5},{"level":1,"name":"Water_Source","x":2,"y":0,"z":-4},{"level":1,"name":"Water_Source","x":2,"y":1,"z":-3},{"level":1,"name":"Water_Source","x":2,"y":5,"z":-3},{"level":1,"name":"Water_Source","x":2,"y":1,"z":-2},{"level":1,"name":"Water_Source","x":2,"y":6,"z":-2},{"level":1,"name":"Water_Source","x":2,"y":2,"z":-1},{"level":1,"name":"Water_Source","x":2,"y":6,"z":-1},{"level":1,"name":"Water_Source","x":2,"y":2,"z":0},{"level":1,"name":"Water_Source","x":2,"y":6,"z":0},{"level":1,"name":"Water_Source","x":2,"y":2,"z":1},{"level":1,"name":"Water_Source","x":2,"y":6,"z":1},{"level":1,"name":"Water_Source","x":2,"y":2,"z":2},{"level":1,"name":"Water_Source","x":2,"y":6,"z":2},{"level":1,"name":"Water_Source","x":2,"y":1,"z":3},{"level":1,"name":"Water_Source","x":2,"y":6,"z":3},{"level":1,"name":"Water_Source","x":2,"y":1,"z":4},{"level":1,"name":"Water_Source","x":2,"y":5,"z":4},{"level":1,"name":"Water_Source","x":2,"y":0,"z":5},{"level":1,"name":"Water_Source","x":3,"y":0,"z":-4},{"level":1,"name":"Water_Source","x":3,"y":1,"z":-4},{"level":1,"name":"Water_Source","x":3,"y":2,"z":-4},{"level":1,"name":"Water_Source","x":3,"y":1,"z":-3},{"level":1,"name":"Water_Source","x":3,"y":2,"z":-3},{"level":1,"name":"Water_Source","x":3,"y":3,"z":-3},{"level":1,"name":"Water_Source","x":3,"y":4,"z":-3},{"level":1,"name":"Water_Source","x":3,"y":5,"z":-3},{"level":1,"name":"Water_Source","x":3,"y":1,"z":-2},{"level":1,"name":"Water_Source","x":3,"y":2,"z":-2},{"level":1,"name":"Water_Source","x":3,"y":3,"z":-2},{"level":1,"name":"Water_Source","x":3,"y":5,"z":-2},{"level":1,"name":"Water_Source","x":3,"y":2,"z":-1},{"level":1,"name":"Water_Source","x":3,"y":3,"z":-1},{"level":1,"name":"Water_Source","x":3,"y":5,"z":-1},{"level":1,"name":"Water_Source","x":3,"y":2,"z":0},{"level":1,"name":"Water_Source","x":3,"y":3,"z":0},{"level":1,"name":"Water_Source","x":3,"y":5,"z":0},{"level":1,"name":"Water_Source","x":3,"y":2,"z":1},{"level":1,"name":"Water_Source","x":3,"y":3,"z":1},{"level":1,"name":"Water_Source","x":3,"y":5,"z":1},{"level":1,"name":"Water_Source","x":3,"y":2,"z":2},{"level":1,"name":"Water_Source","x":3,"y":3,"z":2},{"level":1,"name":"Water_Source","x":3,"y":5,"z":2},{"level":1,"name":"Water_Source","x":3,"y":1,"z":3},{"level":1,"name":"Water_Source","x":3,"y":2,"z":3},{"level":1,"name":"Water_Source","x":3,"y":3,"z":3},{"level":1,"name":"Water_Source","x":3,"y":5,"z":3},{"level":1,"name":"Water_Source","x":3,"y":1,"z":4},{"level":1,"name":"Water_Source","x":3,"y":2,"z":4},{"level":1,"name":"Water_Source","x":3,"y":3,"z":4},{"level":1,"name":"Water_Source","x":3,"y":4,"z":4},{"level":1,"name":"Water_Source","x":3,"y":5,"z":4},{"level":1,"name":"Water_Source","x":3,"y":0,"z":5},{"level":1,"name":"Water_Source","x":3,"y":1,"z":5},{"level":1,"name":"Water_Source","x":3,"y":2,"z":5}],"version":8}