{"anchorX":0,"anchorY":0,"anchorZ":0,"blockIdVersion":11,"blocks":[{"name":"Rock_Sandstone_Red_Brick_Stairs","rotation":10,"x":-1,"y":0,"z":-4},{"name":"Rock_Sandstone_Red_Brick","x":-1,"y":1,"z":-4},{"name":"Rock_Sandstone_Red_Brick_Stairs","rotation":2,"x":-1,"y":2,"z":-4},{"name":"Rock_Sandstone_Red_Brick","x":-1,"y":1,"z":-3},{"name":"*Rock_Sandstone_Red_Brick_Half_State_Definitions_Block","x":-1,"y":2,"z":-3},{"name":"Rock_Sandstone_Red_Brick_Half","rotation":8,"x":-1,"y":1,"z":-2},{"name":"*Rock_Sandstone_Red_Brick_Half_State_Definitions_Block","x":-1,"y":2,"z":-2},{"name":"Rock_Sandstone_Red_Brick_Half","x":-1,"y":3,"z":-2},{"name":"*Rock_Sandstone_Red_Brick_Half_State_Definitions_Block","x":-1,"y":2,"z":-1},{"name":"Rock_Sandstone_Red_Brick_Half","x":-1,"y":3,"z":-1},{"name":"*Rock_Sandstone_Red_Brick_Half_State_Definitions_Block","x":-1,"y":2,"z":0},{"name":"Rock_Sandstone_Red_Brick_Half","x":-1,"y":3,"z":0},{"name":"*Rock_Sandstone_Red_Brick_Half_State_Definitions_Block","x":-1,"y":2,"z":1},{"name":"Rock_Sandstone_Red_Brick_Half","x":-1,"y":3,"z":1},{"name":"*Rock_Sandstone_Red_Brick_Half_State_Definitions_Block","x":-1,"y":2,"z":2},{"name":"Rock_Sandstone_Red_Brick_Half","x":-1,"y":3,"z":2},{"name":"Rock_Sandstone_Red_Brick_Half","rotation":8,"x":-1,"y":1,"z":3},{"name":"Rock_Sandstone_Red_Brick","x":-1,"y":2,"z":3},{"name":"Rock_Sandstone_Red_Brick_Half","x":-1,"y":3,"z":3},{"name":"Rock_Sandstone_Red_Brick","x":-1,"y":1,"z":4},{"name":"Rock_Sandstone_Red_Brick","x":-1,"y":2,"z":4},{"name":"Rock_Sandstone_Red_Brick_Stairs","rotation":8,"x":-1,"y":0,"z":5},{"name":"Rock_Sandstone_Red_Brick","x":-1,"y":1,"z":5},{"name":"Rock_Sandstone_Red_Brick_Stairs","x":-1,"y":2,"z":5},{"name":"Rock_Sandstone_Cobble_Half","rotation":8,"x":0,"y":0,"z":-4},{"name":"Rock_Sandstone_Cobble_Half","x":0,"y":1,"z":-3},{"name":"Rock_Sandstone_Cobble_Half","rotation":8,"x":0,"y":1,"z":-2},{"name":"Rock_Sandstone_Cobble_Half","x":0,"y":2,"z":-1},{"name":"Rock_Sandstone_Cobble_Half","x":0,"y":2,"z":0},{"name":"Rock_Sandstone_Cobble_Half","x":0,"y":2,"z":1},{"name":"Rock_Sandstone_Cobble_Half","x":0,"y":2,"z":2},{"name":"Rock_Sandstone_Cobble_Half","rotation":8,"x":0,"y":1,"z":3},{"name":"Rock_Sandstone_Cobble_Half","x":0,"y":1,"z":4},{"name":"Rock_Sandstone_Cobble_Half","rotation":8,"x":0,"y":0,"z":5},{"name":"Rock_Sandstone_Cobble_Half","rotation":8,"x":1,"y":0,"z":-4},{"name":"Rock_Sandstone_Cobble_Half","x":1,"y":1,"z":-3},{"name":"Rock_Sandstone_Cobble_Half","rotation":8,"x":1,"y":1,"z":-2},{"name":"Rock_Sandstone_Cobble_Half","x":1,"y":2,"z":-1},{"name":"Rock_Sandstone_Cobble_Half","x":1,"y":2,"z":0},{"name":"Rock_Sandstone_Cobble_Half","x":1,"y":2,"z":1},{"name":"Rock_Sandstone_Cobble_Half","x":1,"y":2,"z":2},{"name":"Rock_Sandstone_Cobble_Half","rotation":8,"x":1,"y":1,"z":3},{"name":"Rock_Sandstone_Cobble_Half","x":1,"y":1,"z":4},{"name":"Rock_Sandstone_Cobble_Half","rotation":8,"x":1,"y":0,"z":5},{"name":"Rock_Sandstone_Red_Brick_Stairs","rotation":10,"x":2,"y":0,"z":-4},{"name":"Rock_Sandstone_Red_Brick","x":2,"y":1,"z":-4},{"name":"Rock_Sandstone_Red_Brick_Stairs","rotation":2,"x":2,"y":2,"z":-4},{"name":"Rock_Sandstone_Red_Brick","x":2,"y":1,"z":-3},{"name":"Rock_Sandstone_Red_Brick","x":2,"y":2,"z":-3},{"name":"Rock_Sandstone_Red_Brick_Half","rotation":8,"x":2,"y":1,"z":-2},{"name":"Rock_Sandstone_Red_Brick","x":2,"y":2,"z":-2},{"name":"Rock_Sandstone_Red_Brick_Half","x":2,"y":3,"z":-2},{"name":"Rock_Sandstone_Red_Brick","x":2,"y":2,"z":-1},{"name":"Rock_Sandstone_Red_Brick_Half","x":2,"y":3,"z":-1},{"name":"Rock_Sandstone_Red_Brick","x":2,"y":2,"z":0},{"name":"Rock_Sandstone_Red_Brick_Half","x":2,"y":3,"z":0},{"name":"Rock_Sandstone_Red_Brick","x":2,"y":2,"z":1},{"name":"Rock_Sandstone_Red_Brick_Half","x":2,"y":3,"z":1},{"name":"Rock_Sandstone_Red_Brick","x":2,"y":2,"z":2},{"name":"Rock_Sandstone_Red_Brick_Half","x":2,"y":3,"z":2},{"name":"Rock_Sandstone_Red_Brick_Half","rotation":8,"x":2,"y":1,"z":3},{"name":"Rock_Sandstone_Red_Brick","x":2,"y":2,"z":3},{"name":"Rock_Sandstone_Red_Brick_Half","x":2,"y":3,"z":3},{"name":"Rock_Sandstone_Red_Brick","x":2,"y":1,"z":4},{"name":"Rock_Sandstone_Red_Brick","x":2,"y":2,"z":4},{"name":"Rock_Sandstone_Red_Brick_Stairs","rotation":8,"x":2,"y":0,"z":5},{"name":"Rock_Sandstone_Red_Brick","x":2,"y":1,"z":5},{"name":"Rock_Sandstone_Red_Brick_Stairs","x":2,"y":2,"z":5}],"fluids":[{"level":1,"name":"Water_Source","x":-1,"y":0,"z":-4},{"level":1,"name":"Water_Source","x":-1,"y":1,"z":-4},{"level":1,"name":"Water_Source","x":-1,"y":2,"z":-4},{"level":1,"name":"Water_Source","x":-1,"y":1,"z":-3},{"level":1,"name":"Water_Source","x":-1,"y":2,"z":-3},{"level":1,"name":"Water_Source","x":-1,"y":1,"z":-2},{"level":1,"name":"Water_Source","x":-1,"y":2,"z":-2},{"level":1,"name":"Water_Source","x":-1,"y":3,"z":-2},{"level":1,"name":"Water_Source","x":-1,"y":2,"z":-1},{"level":1,"name":"Water_Source","x":-1,"y":3,"z":-1},{"level":1,"name":"Water_Source","x":-1,"y":2,"z":0},{"level":1,"name":"Water_Source","x":-1,"y":3,"z":0},{"level":1,"name":"Water_Source","x":-1,"y":2,"z":1},{"level":1,"name":"Water_Source","x":-1,"y":3,"z":1},{"level":1,"name":"Water_Source","x":-1,"y":2,"z":2},{"level":1,"name":"Water_Source","x":-1,"y":3,"z":2},{"level":1,"name":"Water_Source","x":-1,"y":1,"z":3},{"level":1,"name":"Water_Source","x":-1,"y":2,"z":3},{"level":1,"name":"Water_Source","x":-1,"y":3,"z":3},{"level":1,"name":"Water_Source","x":-1,"y":1,"z":4},{"level":1,"name":"Water_Source","x":-1,"y":2,"z":4},{"level":1,"name":"Water_Source","x":-1,"y":0,"z":5},{"level":1,"name":"Water_Source","x":-1,"y":1,"z":5},{"level":1,"name":"Water_Source","x":-1,"y":2,"z":5},{"level":1,"name":"Water_Source","x":0,"y":0,"z":-4},{"level":1,"name":"Water_Source","x":0,"y":1,"z":-3},{"level":1,"name":"Water_Source","x":0,"y":1,"z":-2},{"level":1,"name":"Water_Source","x":0,"y":2,"z":-1},{"level":1,"name":"Water_Source","x":0,"y":2,"z":0},{"level":1,"name":"Water_Source","x":0,"y":2,"z":1},{"level":1,"name":"Water_Source","x":0,"y":2,"z":2},{"level":1,"name":"Water_Source","x":0,"y":1,"z":3},{"level":1,"name":"Water_Source","x":0,"y":1,"z":4},{"level":1,"name":"Water_Source","x":0,"y":0,"z":5},{"level":1,"name":"Water_Source","x":1,"y":0,"z":-4},{"level":1,"name":"Water_Source","x":1,"y":1,"z":-3},{"level":1,"name":"Water_Source","x":1,"y":1,"z":-2},{"level":1,"name":"Water_Source","x":1,"y":2,"z":-1},{"level":1,"name":"Water_Source","x":1,"y":2,"z":0},{"level":1,"name":"Water_Source","x":1,"y":2,"z":1},{"level":1,"name":"Water_Source","x":1,"y":2,"z":2},{"level":1,"name":"Water_Source","x":1,"y":1,"z":3},{"level":1,"name":"Water_Source","x":1,"y":1,"z":4},{"level":1,"name":"Water_Source","x":1,"y":0,"z":5},{"level":1,"name":"Water_Source","x":2,"y":0,"z":-4},{"level":1,"name":"Water_Source","x":2,"y":1,"z":-4},{"level":1,"name":"Water_Source","x":2,"y":2,"z":-4},{"level":1,"name":"Water_Source","x":2,"y":1,"z":-3},{"level":1,"name":"Water_Source","x":2,"y":2,"z":-3},{"level":1,"name":"Water_Source","x":2,"y":1,"z":-2},{"level":1,"name":"Water_Source","x":2,"y":2,"z":-2},{"level":1,"name":"Water_Source","x":2,"y":3,"z":-2},{"level":1,"name":"Water_Source","x":2,"y":2,"z":-1},{"level":1,"name":"Water_Source","x":2,"y":3,"z":-1},{"level":1,"name":"Water_Source","x":2,"y":2,"z":0},{"level":1,"name":"Water_Source","x":2,"y":3,"z":0},{"level":1,"name":"Water_Source","x":2,"y":2,"z":1},{"level":1,"name":"Water_Source","x":2,"y":3,"z":1},{"level":1,"name":"Water_Source","x":2,"y":2,"z":2},{"level":1,"name":"Water_Source","x":2,"y":3,"z":2},{"level":1,"name":"Water_Source","x":2,"y":1,"z":3},{"level":1,"name":"Water_Source","x":2,"y":2,"z":3},{"level":1,"name":"Water_Source","x":2,"y":3,"z":3},{"level":1,"name":"Water_Source","x":2,"y":1,"z":4},{"level":1,"name":"Water_Source","x":2,"y":2,"z":4},{"level":1,"name":"Water_Source","x":2,"y":0,"z":5},{"level":1,"name":"Water_Source","x":2,"y":1,"z":5},{"level":1,"name":"Water_Source","x":2,"y":2,"z":5}],"version":8}