{
  "version": 8,
  "blockIdVersion": 11,
  "anchorX": 0,
  "anchorY": 0,
  "anchorZ": 0,
  "blocks": [
    {
      "x": -5,
      "y": 2,
      "z": -1,
      "name": "Plant_Coral_Block_Green"
    },
    {
      "x": -5,
      "y": 2,
      "z": 0,
      "name": "Plant_Coral_Block_Green"
    },
    {
      "x": -5,
      "y": 2,
      "z": 1,
      "name": "Plant_Coral_Block_Green"
    },
    {
      "x": -5,
      "y": 3,
      "z": 1,
      "name": "Plant_Coral_Bush_Green"
    },
    {
      "x": -4,
      "y": 2,
      "z": -3,
      "name": "Plant_Coral_Block_Green"
    },
    {
      "x": -4,
      "y": 2,
      "z": -2,
      "name": "Plant_Coral_Block_Green"
    },
    {
      "x": -4,
      "y": 1,
      "z": -1,
      "name": "Plant_Coral_Block_Green"
    },
    {
      "x": -4,
      "y": 2,
      "z": -1,
      "name": "Plant_Coral_Block_Green"
    },
    {
      "x": -4,
      "y": 3,
      "z": -1,
      "name": "Plant_Coral_Bush_Green"
    },
    {
      "x": -4,
      "y": 1,
      "z": 0,
      "name": "Plant_Coral_Block_Green"
    },
    {
      "x": -4,
      "y": 2,
      "z": 0,
      "name": "Plant_Coral_Block_Green"
    },
    {
      "x": -4,
      "y": 1,
      "z": 1,
      "name": "Plant_Coral_Block_Green"
    },
    {
      "x": -4,
      "y": 2,
      "z": 1,
      "name": "Plant_Coral_Block_Green"
    },
    {
      "x": -4,
      "y": 2,
      "z": 2,
      "name": "Plant_Coral_Block_Green"
    },
    {
      "x": -4,
      "y": 2,
      "z": 3,
      "name": "Plant_Coral_Block_Green"
    },
    {
      "x": -4,
      "y": 3,
      "z": 3,
      "name": "Plant_Coral_Bush_Green"
    },
    {
      "x": -3,
      "y": 2,
      "z": -4,
      "name": "Plant_Coral_Block_Green"
    },
    {
      "x": -3,
      "y": 2,
      "z": -3,
      "name": "Plant_Coral_Block_Green"
    },
    {
      "x": -3,
      "y": 3,
      "z": -3,
      "name": "Plant_Coral_Bush_Green"
    },
    {
      "x": -3,
      "y": 1,
      "z": -2,
      "name": "Plant_Coral_Block_Green"
    },
    {
      "x": -3,
      "y": 2,
      "z": -2,
      "name": "Plant_Coral_Block_Green"
    },
    {
      "x": -3,
      "y": 1,
      "z": -1,
      "name": "Plant_Coral_Block_Green"
    },
    {
      "x": -3,
      "y": 2,
      "z": -1,
      "name": "Plant_Coral_Block_Green"
    },
    {
      "x": -3,
      "y": 1,
      "z": 0,
      "name": "Plant_Coral_Block_Green"
    },
    {
      "x": -3,
      "y": 2,
      "z": 0,
      "name": "Plant_Coral_Block_Green"
    },
    {
      "x": -3,
      "y": 1,
      "z": 1,
      "name": "Plant_Coral_Block_Green"
    },
    {
      "x": -3,
      "y": 2,
      "z": 1,
      "name": "Plant_Coral_Block_Green"
    },
    {
      "x": -3,
      "y": 1,
      "z": 2,
      "name": "Plant_Coral_Block_Green"
    },
    {
      "x": -3,
      "y": 2,
      "z": 2,
      "name": "Plant_Coral_Block_Green"
    },
    {
      "x": -3,
      "y": 2,
      "z": 3,
      "name": "Plant_Coral_Block_Green"
    },
    {
      "x": -3,
      "y": 2,
      "z": 4,
      "name": "Plant_Coral_Block_Green"
    },
    {
      "x": -2,
      "y": 2,
      "z": -4,
      "name": "Plant_Coral_Block_Green"
    },
    {
      "x": -2,
      "y": 1,
      "z": -3,
      "name": "Plant_Coral_Block_Green"
    },
    {
      "x": -2,
      "y": 2,
      "z": -3,
      "name": "Plant_Coral_Block_Green"
    },
    {
      "x": -2,
      "y": 1,
      "z": -2,
      "name": "Plant_Coral_Block_Green"
    },
    {
      "x": -2,
      "y": 2,
      "z": -2,
      "name": "Plant_Coral_Block_Green"
    },
    {
      "x": -2,
      "y": 0,
      "z": -1,
      "name": "Plant_Coral_Block_Green"
    },
    {
      "x": -2,
      "y": 1,
      "z": -1,
      "name": "Plant_Coral_Block_Green"
    },
    {
      "x": -2,
      "y": 0,
      "z": 0,
      "name": "Plant_Coral_Block_Green"
    },
    {
      "x": -2,
      "y": 1,
      "z": 0,
      "name": "Plant_Coral_Block_Green"
    },
    {
      "x": -2,
      "y": 2,
      "z": 0,
      "name": "Plant_Coral_Bush_Green"
    },
    {
      "x": -2,
      "y": 0,
      "z": 1,
      "name": "Plant_Coral_Block_Green"
    },
    {
      "x": -2,
      "y": 1,
      "z": 1,
      "name": "Plant_Coral_Block_Green"
    },
    {
      "x": -2,
      "y": 1,
      "z": 2,
      "name": "Plant_Coral_Block_Green"
    },
    {
      "x": -2,
      "y": 2,
      "z": 2,
      "name": "Plant_Coral_Block_Green"
    },
    {
      "x": -2,
      "y": 1,
      "z": 3,
      "name": "Plant_Coral_Block_Green"
    },
    {
      "x": -2,
      "y": 2,
      "z": 3,
      "name": "Plant_Coral_Block_Green"
    },
    {
      "x": -2,
      "y": 2,
      "z": 4,
      "name": "Plant_Coral_Block_Green"
    },
    {
      "x": -2,
      "y": 3,
      "z": 4,
      "name": "Plant_Coral_Bush_Green"
    },
    {
      "x": -1,
      "y": 2,
      "z": -5,
      "name": "Plant_Coral_Block_Green"
    },
    {
      "x": -1,
      "y": 1,
      "z": -4,
      "name": "Plant_Coral_Block_Green"
    },
    {
      "x": -1,
      "y": 2,
      "z": -4,
      "name": "Plant_Coral_Block_Green"
    },
    {
      "x": -1,
      "y": 1,
      "z": -3,
      "name": "Plant_Coral_Block_Green"
    },
    {
      "x": -1,
      "y": 2,
      "z": -3,
      "name": "Plant_Coral_Block_Green"
    },
    {
      "x": -1,
      "y": 3,
      "z": -3,
      "name": "Plant_Coral_Bush_Green"
    },
    {
      "x": -1,
      "y": 0,
      "z": -2,
      "name": "Plant_Coral_Block_Green"
    },
    {
      "x": -1,
      "y": 1,
      "z": -2,
      "name": "Plant_Coral_Block_Green"
    },
    {
      "x": -1,
      "y": 2,
      "z": -2,
      "name": "Plant_Coral_Bush_Green"
    },
    {
      "x": -1,
      "y": 0,
      "z": -1,
      "name": "Plant_Coral_Block_Green"
    },
    {
      "x": -1,
      "y": 1,
      "z": -1,
      "name": "Plant_Coral_Block_Green"
    },
    {
      "x": -1,
      "y": 0,
      "z": 0,
      "name": "Plant_Coral_Block_Green"
    },
    {
      "x": -1,
      "y": 1,
      "z": 0,
      "name": "Plant_Coral_Block_Green"
    },
    {
      "x": -1,
      "y": 0,
      "z": 1,
      "name": "Plant_Coral_Block_Green"
    },
    {
      "x": -1,
      "y": 1,
      "z": 1,
      "name": "Plant_Coral_Block_Green"
    },
    {
      "x": -1,
      "y": 0,
      "z": 2,
      "name": "Plant_Coral_Block_Green"
    },
    {
      "x": -1,
      "y": 1,
      "z": 2,
      "name": "Plant_Coral_Block_Green"
    },
    {
      "x": -1,
      "y": 1,
      "z": 3,
      "name": "Plant_Coral_Block_Green"
    },
    {
      "x": -1,
      "y": 2,
      "z": 3,
      "name": "Plant_Coral_Block_Green"
    },
    {
      "x": -1,
      "y": 1,
      "z": 4,
      "name": "Plant_Coral_Block_Green"
    },
    {
      "x": -1,
      "y": 2,
      "z": 4,
      "name": "Plant_Coral_Block_Green"
    },
    {
      "x": -1,
      "y": 2,
      "z": 5,
      "name": "Plant_Coral_Block_Green"
    },
    {
      "x": 0,
      "y": 2,
      "z": -5,
      "name": "Plant_Coral_Block_Green"
    },
    {
      "x": 0,
      "y": 3,
      "z": -5,
      "name": "Plant_Coral_Bush_Green"
    },
    {
      "x": 0,
      "y": 1,
      "z": -4,
      "name": "Plant_Coral_Block_Green"
    },
    {
      "x": 0,
      "y": 2,
      "z": -4,
      "name": "Plant_Coral_Block_Green"
    },
    {
      "x": 0,
      "y": 1,
      "z": -3,
      "name": "Plant_Coral_Block_Green"
    },
    {
      "x": 0,
      "y": 2,
      "z": -3,
      "name": "Plant_Coral_Block_Green"
    },
    {
      "x": 0,
      "y": 0,
      "z": -2,
      "name": "Plant_Coral_Block_Green"
    },
    {
      "x": 0,
      "y": 1,
      "z": -2,
      "name": "Plant_Coral_Block_Green"
    },
    {
      "x": 0,
      "y": 0,
      "z": -1,
      "name": "Plant_Coral_Block_Green"
    },
    {
      "x": 0,
      "y": 1,
      "z": -1,
      "name": "Plant_Coral_Block_Green"
    },
    {
      "x": 0,
      "y": 0,
      "z": 0,
      "name": "Plant_Coral_Block_Green"
    },
    {
      "x": 0,
      "y": 1,
      "z": 0,
      "name": "Plant_Coral_Block_Green"
    },
    {
      "x": 0,
      "y": 0,
      "z": 1,
      "name": "Plant_Coral_Block_Green"
    },
    {
      "x": 0,
      "y": 1,
      "z": 1,
      "name": "Plant_Coral_Block_Green"
    },
    {
      "x": 0,
      "y": 0,
      "z": 2,
      "name": "Plant_Coral_Block_Green"
    },
    {
      "x": 0,
      "y": 1,
      "z": 2,
      "name": "Plant_Coral_Block_Green"
    },
    {
      "x": 0,
      "y": 2,
      "z": 2,
      "name": "Plant_Coral_Bush_Green"
    },
    {
      "x": 0,
      "y": 1,
      "z": 3,
      "name": "Plant_Coral_Block_Green"
    },
    {
      "x": 0,
      "y": 2,
      "z": 3,
      "name": "Plant_Coral_Block_Green"
    },
    {
      "x": 0,
      "y": 1,
      "z": 4,
      "name": "Plant_Coral_Block_Green"
    },
    {
      "x": 0,
      "y": 2,
      "z": 4,
      "name": "Plant_Coral_Block_Green"
    },
    {
      "x": 0,
      "y": 2,
      "z": 5,
      "name": "Plant_Coral_Block_Green"
    },
    {
      "x": 1,
      "y": 2,
      "z": -5,
      "name": "Plant_Coral_Block_Green"
    },
    {
      "x": 1,
      "y": 1,
      "z": -4,
      "name": "Plant_Coral_Block_Green"
    },
    {
      "x": 1,
      "y": 2,
      "z": -4,
      "name": "Plant_Coral_Block_Green"
    },
    {
      "x": 1,
      "y": 1,
      "z": -3,
      "name": "Plant_Coral_Block_Green"
    },
    {
      "x": 1,
      "y": 2,
      "z": -3,
      "name": "Plant_Coral_Block_Green"
    },
    {
      "x": 1,
      "y": 0,
      "z": -2,
      "name": "Plant_Coral_Block_Green"
    },
    {
      "x": 1,
      "y": 1,
      "z": -2,
      "name": "Plant_Coral_Block_Green"
    },
    {
      "x": 1,
      "y": 0,
      "z": -1,
      "name": "Plant_Coral_Block_Green"
    },
    {
      "x": 1,
      "y": 1,
      "z": -1,
      "name": "Plant_Coral_Block_Green"
    },
    {
      "x": 1,
      "y": 2,
      "z": -1,
      "name": "Plant_Coral_Bush_Green"
    },
    {
      "x": 1,
      "y": 0,
      "z": 0,
      "name": "Plant_Coral_Block_Green"
    },
    {
      "x": 1,
      "y": 1,
      "z": 0,
      "name": "Plant_Coral_Block_Green"
    },
    {
      "x": 1,
      "y": 0,
      "z": 1,
      "name": "Plant_Coral_Block_Green"
    },
    {
      "x": 1,
      "y": 1,
      "z": 1,
      "name": "Plant_Coral_Block_Green"
    },
    {
      "x": 1,
      "y": 0,
      "z": 2,
      "name": "Plant_Coral_Block_Green"
    },
    {
      "x": 1,
      "y": 1,
      "z": 2,
      "name": "Plant_Coral_Block_Green"
    },
    {
      "x": 1,
      "y": 2,
      "z": 2,
      "name": "Plant_Coral_Bush_Green"
    },
    {
      "x": 1,
      "y": 1,
      "z": 3,
      "name": "Plant_Coral_Block_Green"
    },
    {
      "x": 1,
      "y": 2,
      "z": 3,
      "name": "Plant_Coral_Block_Green"
    },
    {
      "x": 1,
      "y": 1,
      "z": 4,
      "name": "Plant_Coral_Block_Green"
    },
    {
      "x": 1,
      "y": 2,
      "z": 4,
      "name": "Plant_Coral_Block_Green"
    },
    {
      "x": 1,
      "y": 2,
      "z": 5,
      "name": "Plant_Coral_Block_Green"
    },
    {
      "x": 1,
      "y": 3,
      "z": 5,
      "name": "Plant_Coral_Bush_Green"
    },
    {
      "x": 2,
      "y": 2,
      "z": -4,
      "name": "Plant_Coral_Block_Green"
    },
    {
      "x": 2,
      "y": 1,
      "z": -3,
      "name": "Plant_Coral_Block_Green"
    },
    {
      "x": 2,
      "y": 2,
      "z": -3,
      "name": "Plant_Coral_Block_Green"
    },
    {
      "x": 2,
      "y": 1,
      "z": -2,
      "name": "Plant_Coral_Block_Green"
    },
    {
      "x": 2,
      "y": 2,
      "z": -2,
      "name": "Plant_Coral_Block_Green"
    },
    {
      "x": 2,
      "y": 3,
      "z": -2,
      "name": "Plant_Coral_Bush_Green"
    },
    {
      "x": 2,
      "y": 0,
      "z": -1,
      "name": "Plant_Coral_Block_Green"
    },
    {
      "x": 2,
      "y": 1,
      "z": -1,
      "name": "Plant_Coral_Block_Green"
    },
    {
      "x": 2,
      "y": 0,
      "z": 0,
      "name": "Plant_Coral_Block_Green"
    },
    {
      "x": 2,
      "y": 1,
      "z": 0,
      "name": "Plant_Coral_Block_Green"
    },
    {
      "x": 2,
      "y": 0,
      "z": 1,
      "name": "Plant_Coral_Block_Green"
    },
    {
      "x": 2,
      "y": 1,
      "z": 1,
      "name": "Plant_Coral_Block_Green"
    },
    {
      "x": 2,
      "y": 2,
      "z": 1,
      "name": "Plant_Coral_Bush_Green"
    },
    {
      "x": 2,
      "y": 1,
      "z": 2,
      "name": "Plant_Coral_Block_Green"
    },
    {
      "x": 2,
      "y": 2,
      "z": 2,
      "name": "Plant_Coral_Block_Green"
    },
    {
      "x": 2,
      "y": 3,
      "z": 2,
      "name": "Plant_Coral_Bush_Green"
    },
    {
      "x": 2,
      "y": 1,
      "z": 3,
      "name": "Plant_Coral_Block_Green"
    },
    {
      "x": 2,
      "y": 2,
      "z": 3,
      "name": "Plant_Coral_Block_Green"
    },
    {
      "x": 2,
      "y": 2,
      "z": 4,
      "name": "Plant_Coral_Block_Green"
    },
    {
      "x": 3,
      "y": 2,
      "z": -4,
      "name": "Plant_Coral_Block_Green"
    },
    {
      "x": 3,
      "y": 3,
      "z": -4,
      "name": "Plant_Coral_Bush_Green"
    },
    {
      "x": 3,
      "y": 2,
      "z": -3,
      "name": "Plant_Coral_Block_Green"
    },
    {
      "x": 3,
      "y": 1,
      "z": -2,
      "name": "Plant_Coral_Block_Green"
    },
    {
      "x": 3,
      "y": 2,
      "z": -2,
      "name": "Plant_Coral_Block_Green"
    },
    {
      "x": 3,
      "y": 1,
      "z": -1,
      "name": "Plant_Coral_Block_Green"
    },
    {
      "x": 3,
      "y": 2,
      "z": -1,
      "name": "Plant_Coral_Block_Green"
    },
    {
      "x": 3,
      "y": 1,
      "z": 0,
      "name": "Plant_Coral_Block_Green"
    },
    {
      "x": 3,
      "y": 2,
      "z": 0,
      "name": "Plant_Coral_Block_Green"
    },
    {
      "x": 3,
      "y": 1,
      "z": 1,
      "name": "Plant_Coral_Block_Green"
    },
    {
      "x": 3,
      "y": 2,
      "z": 1,
      "name": "Plant_Coral_Block_Green"
    },
    {
      "x": 3,
      "y": 1,
      "z": 2,
      "name": "Plant_Coral_Block_Green"
    },
    {
      "x": 3,
      "y": 2,
      "z": 2,
      "name": "Plant_Coral_Block_Green"
    },
    {
      "x": 3,
      "y": 2,
      "z": 3,
      "name": "Plant_Coral_Block_Green"
    },
    {
      "x": 3,
      "y": 2,
      "z": 4,
      "name": "Plant_Coral_Block_Green"
    },
    {
      "x": 4,
      "y": 2,
      "z": -3,
      "name": "Plant_Coral_Block_Green"
    },
    {
      "x": 4,
      "y": 2,
      "z": -2,
      "name": "Plant_Coral_Block_Green"
    },
    {
      "x": 4,
      "y": 1,
      "z": -1,
      "name": "Plant_Coral_Block_Green"
    },
    {
      "x": 4,
      "y": 2,
      "z": -1,
      "name": "Plant_Coral_Block_Green"
    },
    {
      "x": 4,
      "y": 3,
      "z": -1,
      "name": "Plant_Coral_Bush_Green"
    },
    {
      "x": 4,
      "y": 1,
      "z": 0,
      "name": "Plant_Coral_Block_Green"
    },
    {
      "x": 4,
      "y": 2,
      "z": 0,
      "name": "Plant_Coral_Block_Green"
    },
    {
      "x": 4,
      "y": 1,
      "z": 1,
      "name": "Plant_Coral_Block_Green"
    },
    {
      "x": 4,
      "y": 2,
      "z": 1,
      "name": "Plant_Coral_Block_Green"
    },
    {
      "x": 4,
      "y": 2,
      "z": 2,
      "name": "Plant_Coral_Block_Green"
    },
    {
      "x": 4,
      "y": 2,
      "z": 3,
      "name": "Plant_Coral_Block_Green"
    },
    {
      "x": 4,
      "y": 3,
      "z": 3,
      "name": "Plant_Coral_Bush_Green"
    },
    {
      "x": 5,
      "y": 2,
      "z": -1,
      "name": "Plant_Coral_Block_Green"
    },
    {
      "x": 5,
      "y": 2,
      "z": 0,
      "name": "Plant_Coral_Block_Green"
    },
    {
      "x": 5,
      "y": 2,
      "z": 1,
      "name": "Plant_Coral_Block_Green"
    },
    {
      "x": 5,
      "y": 3,
      "z": 1,
      "name": "Plant_Coral_Bush_Green"
    }
  ],
  "fluids": [
    {
      "x": -5,
      "y": 2,
      "z": -1,
      "name": "Empty",
      "level": 0
    },
    {
      "x": -5,
      "y": 2,
      "z": 0,
      "name": "Empty",
      "level": 0
    },
    {
      "x": -5,
      "y": 2,
      "z": 1,
      "name": "Empty",
      "level": 0
    },
    {
      "x": -5,
      "y": 3,
      "z": 1,
      "name": "Empty",
      "level": 0
    },
    {
      "x": -4,
      "y": 2,
      "z": -3,
      "name": "Empty",
      "level": 0
    },
    {
      "x": -4,
      "y": 2,
      "z": -2,
      "name": "Empty",
      "level": 0
    },
    {
      "x": -4,
      "y": 1,
      "z": -1,
      "name": "Empty",
      "level": 0
    },
    {
      "x": -4,
      "y": 2,
      "z": -1,
      "name": "Empty",
      "level": 0
    },
    {
      "x": -4,
      "y": 3,
      "z": -1,
      "name": "Empty",
      "level": 0
    },
    {
      "x": -4,
      "y": 1,
      "z": 0,
      "name": "Empty",
      "level": 0
    },
    {
      "x": -4,
      "y": 2,
      "z": 0,
      "name": "Empty",
      "level": 0
    },
    {
      "x": -4,
      "y": 1,
      "z": 1,
      "name": "Empty",
      "level": 0
    },
    {
      "x": -4,
      "y": 2,
      "z": 1,
      "name": "Empty",
      "level": 0
    },
    {
      "x": -4,
      "y": 2,
      "z": 2,
      "name": "Empty",
      "level": 0
    },
    {
      "x": -4,
      "y": 2,
      "z": 3,
      "name": "Empty",
      "level": 0
    },
    {
      "x": -4,
      "y": 3,
      "z": 3,
      "name": "Empty",
      "level": 0
    },
    {
      "x": -3,
      "y": 2,
      "z": -4,
      "name": "Empty",
      "level": 0
    },
    {
      "x": -3,
      "y": 2,
      "z": -3,
      "name": "Empty",
      "level": 0
    },
    {
      "x": -3,
      "y": 3,
      "z": -3,
      "name": "Empty",
      "level": 0
    },
    {
      "x": -3,
      "y": 1,
      "z": -2,
      "name": "Empty",
      "level": 0
    },
    {
      "x": -3,
      "y": 2,
      "z": -2,
      "name": "Empty",
      "level": 0
    },
    {
      "x": -3,
      "y": 1,
      "z": -1,
      "name": "Empty",
      "level": 0
    },
    {
      "x": -3,
      "y": 2,
      "z": -1,
      "name": "Empty",
      "level": 0
    },
    {
      "x": -3,
      "y": 1,
      "z": 0,
      "name": "Empty",
      "level": 0
    },
    {
      "x": -3,
      "y": 2,
      "z": 0,
      "name": "Empty",
      "level": 0
    },
    {
      "x": -3,
      "y": 1,
      "z": 1,
      "name": "Empty",
      "level": 0
    },
    {
      "x": -3,
      "y": 2,
      "z": 1,
      "name": "Empty",
      "level": 0
    },
    {
      "x": -3,
      "y": 1,
      "z": 2,
      "name": "Empty",
      "level": 0
    },
    {
      "x": -3,
      "y": 2,
      "z": 2,
      "name": "Empty",
      "level": 0
    },
    {
      "x": -3,
      "y": 2,
      "z": 3,
      "name": "Empty",
      "level": 0
    },
    {
      "x": -3,
      "y": 2,
      "z": 4,
      "name": "Empty",
      "level": 0
    },
    {
      "x": -2,
      "y": 2,
      "z": -4,
      "name": "Empty",
      "level": 0
    },
    {
      "x": -2,
      "y": 1,
      "z": -3,
      "name": "Empty",
      "level": 0
    },
    {
      "x": -2,
      "y": 2,
      "z": -3,
      "name": "Empty",
      "level": 0
    },
    {
      "x": -2,
      "y": 1,
      "z": -2,
      "name": "Empty",
      "level": 0
    },
    {
      "x": -2,
      "y": 2,
      "z": -2,
      "name": "Empty",
      "level": 0
    },
    {
      "x": -2,
      "y": 0,
      "z": -1,
      "name": "Empty",
      "level": 0
    },
    {
      "x": -2,
      "y": 1,
      "z": -1,
      "name": "Empty",
      "level": 0
    },
    {
      "x": -2,
      "y": 0,
      "z": 0,
      "name": "Empty",
      "level": 0
    },
    {
      "x": -2,
      "y": 1,
      "z": 0,
      "name": "Empty",
      "level": 0
    },
    {
      "x": -2,
      "y": 2,
      "z": 0,
      "name": "Empty",
      "level": 0
    },
    {
      "x": -2,
      "y": 0,
      "z": 1,
      "name": "Empty",
      "level": 0
    },
    {
      "x": -2,
      "y": 1,
      "z": 1,
      "name": "Empty",
      "level": 0
    },
    {
      "x": -2,
      "y": 1,
      "z": 2,
      "name": "Empty",
      "level": 0
    },
    {
      "x": -2,
      "y": 2,
      "z": 2,
      "name": "Empty",
      "level": 0
    },
    {
      "x": -2,
      "y": 1,
      "z": 3,
      "name": "Empty",
      "level": 0
    },
    {
      "x": -2,
      "y": 2,
      "z": 3,
      "name": "Empty",
      "level": 0
    },
    {
      "x": -2,
      "y": 2,
      "z": 4,
      "name": "Empty",
      "level": 0
    },
    {
      "x": -2,
      "y": 3,
      "z": 4,
      "name": "Empty",
      "level": 0
    },
    {
      "x": -1,
      "y": 2,
      "z": -5,
      "name": "Empty",
      "level": 0
    },
    {
      "x": -1,
      "y": 1,
      "z": -4,
      "name": "Empty",
      "level": 0
    },
    {
      "x": -1,
      "y": 2,
      "z": -4,
      "name": "Empty",
      "level": 0
    },
    {
      "x": -1,
      "y": 1,
      "z": -3,
      "name": "Empty",
      "level": 0
    },
    {
      "x": -1,
      "y": 2,
      "z": -3,
      "name": "Empty",
      "level": 0
    },
    {
      "x": -1,
      "y": 3,
      "z": -3,
      "name": "Empty",
      "level": 0
    },
    {
      "x": -1,
      "y": 0,
      "z": -2,
      "name": "Empty",
      "level": 0
    },
    {
      "x": -1,
      "y": 1,
      "z": -2,
      "name": "Empty",
      "level": 0
    },
    {
      "x": -1,
      "y": 2,
      "z": -2,
      "name": "Empty",
      "level": 0
    },
    {
      "x": -1,
      "y": 0,
      "z": -1,
      "name": "Empty",
      "level": 0
    },
    {
      "x": -1,
      "y": 1,
      "z": -1,
      "name": "Empty",
      "level": 0
    },
    {
      "x": -1,
      "y": 0,
      "z": 0,
      "name": "Empty",
      "level": 0
    },
    {
      "x": -1,
      "y": 1,
      "z": 0,
      "name": "Empty",
      "level": 0
    },
    {
      "x": -1,
      "y": 0,
      "z": 1,
      "name": "Empty",
      "level": 0
    },
    {
      "x": -1,
      "y": 1,
      "z": 1,
      "name": "Empty",
      "level": 0
    },
    {
      "x": -1,
      "y": 0,
      "z": 2,
      "name": "Empty",
      "level": 0
    },
    {
      "x": -1,
      "y": 1,
      "z": 2,
      "name": "Empty",
      "level": 0
    },
    {
      "x": -1,
      "y": 1,
      "z": 3,
      "name": "Empty",
      "level": 0
    },
    {
      "x": -1,
      "y": 2,
      "z": 3,
      "name": "Empty",
      "level": 0
    },
    {
      "x": -1,
      "y": 1,
      "z": 4,
      "name": "Empty",
      "level": 0
    },
    {
      "x": -1,
      "y": 2,
      "z": 4,
      "name": "Empty",
      "level": 0
    },
    {
      "x": -1,
      "y": 2,
      "z": 5,
      "name": "Empty",
      "level": 0
    },
    {
      "x": 0,
      "y": 2,
      "z": -5,
      "name": "Empty",
      "level": 0
    },
    {
      "x": 0,
      "y": 3,
      "z": -5,
      "name": "Empty",
      "level": 0
    },
    {
      "x": 0,
      "y": 1,
      "z": -4,
      "name": "Empty",
      "level": 0
    },
    {
      "x": 0,
      "y": 2,
      "z": -4,
      "name": "Empty",
      "level": 0
    },
    {
      "x": 0,
      "y": 1,
      "z": -3,
      "name": "Empty",
      "level": 0
    },
    {
      "x": 0,
      "y": 2,
      "z": -3,
      "name": "Empty",
      "level": 0
    },
    {
      "x": 0,
      "y": 0,
      "z": -2,
      "name": "Empty",
      "level": 0
    },
    {
      "x": 0,
      "y": 1,
      "z": -2,
      "name": "Empty",
      "level": 0
    },
    {
      "x": 0,
      "y": 0,
      "z": -1,
      "name": "Empty",
      "level": 0
    },
    {
      "x": 0,
      "y": 1,
      "z": -1,
      "name": "Empty",
      "level": 0
    },
    {
      "x": 0,
      "y": 0,
      "z": 0,
      "name": "Empty",
      "level": 0
    },
    {
      "x": 0,
      "y": 1,
      "z": 0,
      "name": "Empty",
      "level": 0
    },
    {
      "x": 0,
      "y": 0,
      "z": 1,
      "name": "Empty",
      "level": 0
    },
    {
      "x": 0,
      "y": 1,
      "z": 1,
      "name": "Empty",
      "level": 0
    },
    {
      "x": 0,
      "y": 0,
      "z": 2,
      "name": "Empty",
      "level": 0
    },
    {
      "x": 0,
      "y": 1,
      "z": 2,
      "name": "Empty",
      "level": 0
    },
    {
      "x": 0,
      "y": 2,
      "z": 2,
      "name": "Empty",
      "level": 0
    },
    {
      "x": 0,
      "y": 1,
      "z": 3,
      "name": "Empty",
      "level": 0
    },
    {
      "x": 0,
      "y": 2,
      "z": 3,
      "name": "Empty",
      "level": 0
    },
    {
      "x": 0,
      "y": 1,
      "z": 4,
      "name": "Empty",
      "level": 0
    },
    {
      "x": 0,
      "y": 2,
      "z": 4,
      "name": "Empty",
      "level": 0
    },
    {
      "x": 0,
      "y": 2,
      "z": 5,
      "name": "Empty",
      "level": 0
    },
    {
      "x": 1,
      "y": 2,
      "z": -5,
      "name": "Empty",
      "level": 0
    },
    {
      "x": 1,
      "y": 1,
      "z": -4,
      "name": "Empty",
      "level": 0
    },
    {
      "x": 1,
      "y": 2,
      "z": -4,
      "name": "Empty",
      "level": 0
    },
    {
      "x": 1,
      "y": 1,
      "z": -3,
      "name": "Empty",
      "level": 0
    },
    {
      "x": 1,
      "y": 2,
      "z": -3,
      "name": "Empty",
      "level": 0
    },
    {
      "x": 1,
      "y": 0,
      "z": -2,
      "name": "Empty",
      "level": 0
    },
    {
      "x": 1,
      "y": 1,
      "z": -2,
      "name": "Empty",
      "level": 0
    },
    {
      "x": 1,
      "y": 0,
      "z": -1,
      "name": "Empty",
      "level": 0
    },
    {
      "x": 1,
      "y": 1,
      "z": -1,
      "name": "Empty",
      "level": 0
    },
    {
      "x": 1,
      "y": 2,
      "z": -1,
      "name": "Empty",
      "level": 0
    },
    {
      "x": 1,
      "y": 0,
      "z": 0,
      "name": "Empty",
      "level": 0
    },
    {
      "x": 1,
      "y": 1,
      "z": 0,
      "name": "Empty",
      "level": 0
    },
    {
      "x": 1,
      "y": 0,
      "z": 1,
      "name": "Empty",
      "level": 0
    },
    {
      "x": 1,
      "y": 1,
      "z": 1,
      "name": "Empty",
      "level": 0
    },
    {
      "x": 1,
      "y": 0,
      "z": 2,
      "name": "Empty",
      "level": 0
    },
    {
      "x": 1,
      "y": 1,
      "z": 2,
      "name": "Empty",
      "level": 0
    },
    {
      "x": 1,
      "y": 2,
      "z": 2,
      "name": "Empty",
      "level": 0
    },
    {
      "x": 1,
      "y": 1,
      "z": 3,
      "name": "Empty",
      "level": 0
    },
    {
      "x": 1,
      "y": 2,
      "z": 3,
      "name": "Empty",
      "level": 0
    },
    {
      "x": 1,
      "y": 1,
      "z": 4,
      "name": "Empty",
      "level": 0
    },
    {
      "x": 1,
      "y": 2,
      "z": 4,
      "name": "Empty",
      "level": 0
    },
    {
      "x": 1,
      "y": 2,
      "z": 5,
      "name": "Empty",
      "level": 0
    },
    {
      "x": 1,
      "y": 3,
      "z": 5,
      "name": "Empty",
      "level": 0
    },
    {
      "x": 2,
      "y": 2,
      "z": -4,
      "name": "Empty",
      "level": 0
    },
    {
      "x": 2,
      "y": 1,
      "z": -3,
      "name": "Empty",
      "level": 0
    },
    {
      "x": 2,
      "y": 2,
      "z": -3,
      "name": "Empty",
      "level": 0
    },
    {
      "x": 2,
      "y": 1,
      "z": -2,
      "name": "Empty",
      "level": 0
    },
    {
      "x": 2,
      "y": 2,
      "z": -2,
      "name": "Empty",
      "level": 0
    },
    {
      "x": 2,
      "y": 3,
      "z": -2,
      "name": "Empty",
      "level": 0
    },
    {
      "x": 2,
      "y": 0,
      "z": -1,
      "name": "Empty",
      "level": 0
    },
    {
      "x": 2,
      "y": 1,
      "z": -1,
      "name": "Empty",
      "level": 0
    },
    {
      "x": 2,
      "y": 0,
      "z": 0,
      "name": "Empty",
      "level": 0
    },
    {
      "x": 2,
      "y": 1,
      "z": 0,
      "name": "Empty",
      "level": 0
    },
    {
      "x": 2,
      "y": 0,
      "z": 1,
      "name": "Empty",
      "level": 0
    },
    {
      "x": 2,
      "y": 1,
      "z": 1,
      "name": "Empty",
      "level": 0
    },
    {
      "x": 2,
      "y": 2,
      "z": 1,
      "name": "Empty",
      "level": 0
    },
    {
      "x": 2,
      "y": 1,
      "z": 2,
      "name": "Empty",
      "level": 0
    },
    {
      "x": 2,
      "y": 2,
      "z": 2,
      "name": "Empty",
      "level": 0
    },
    {
      "x": 2,
      "y": 3,
      "z": 2,
      "name": "Empty",
      "level": 0
    },
    {
      "x": 2,
      "y": 1,
      "z": 3,
      "name": "Empty",
      "level": 0
    },
    {
      "x": 2,
      "y": 2,
      "z": 3,
      "name": "Empty",
      "level": 0
    },
    {
      "x": 2,
      "y": 2,
      "z": 4,
      "name": "Empty",
      "level": 0
    },
    {
      "x": 3,
      "y": 2,
      "z": -4,
      "name": "Empty",
      "level": 0
    },
    {
      "x": 3,
      "y": 3,
      "z": -4,
      "name": "Empty",
      "level": 0
    },
    {
      "x": 3,
      "y": 2,
      "z": -3,
      "name": "Empty",
      "level": 0
    },
    {
      "x": 3,
      "y": 1,
      "z": -2,
      "name": "Empty",
      "level": 0
    },
    {
      "x": 3,
      "y": 2,
      "z": -2,
      "name": "Empty",
      "level": 0
    },
    {
      "x": 3,
      "y": 1,
      "z": -1,
      "name": "Empty",
      "level": 0
    },
    {
      "x": 3,
      "y": 2,
      "z": -1,
      "name": "Empty",
      "level": 0
    },
    {
      "x": 3,
      "y": 1,
      "z": 0,
      "name": "Empty",
      "level": 0
    },
    {
      "x": 3,
      "y": 2,
      "z": 0,
      "name": "Empty",
      "level": 0
    },
    {
      "x": 3,
      "y": 1,
      "z": 1,
      "name": "Empty",
      "level": 0
    },
    {
      "x": 3,
      "y": 2,
      "z": 1,
      "name": "Empty",
      "level": 0
    },
    {
      "x": 3,
      "y": 1,
      "z": 2,
      "name": "Empty",
      "level": 0
    },
    {
      "x": 3,
      "y": 2,
      "z": 2,
      "name": "Empty",
      "level": 0
    },
    {
      "x": 3,
      "y": 2,
      "z": 3,
      "name": "Empty",
      "level": 0
    },
    {
      "x": 3,
      "y": 2,
      "z": 4,
      "name": "Empty",
      "level": 0
    },
    {
      "x": 4,
      "y": 2,
      "z": -3,
      "name": "Empty",
      "level": 0
    },
    {
      "x": 4,
      "y": 2,
      "z": -2,
      "name": "Empty",
      "level": 0
    },
    {
      "x": 4,
      "y": 1,
      "z": -1,
      "name": "Empty",
      "level": 0
    },
    {
      "x": 4,
      "y": 2,
      "z": -1,
      "name": "Empty",
      "level": 0
    },
    {
      "x": 4,
      "y": 3,
      "z": -1,
      "name": "Empty",
      "level": 0
    },
    {
      "x": 4,
      "y": 1,
      "z": 0,
      "name": "Empty",
      "level": 0
    },
    {
      "x": 4,
      "y": 2,
      "z": 0,
      "name": "Empty",
      "level": 0
    },
    {
      "x": 4,
      "y": 1,
      "z": 1,
      "name": "Empty",
      "level": 0
    },
    {
      "x": 4,
      "y": 2,
      "z": 1,
      "name": "Empty",
      "level": 0
    },
    {
      "x": 4,
      "y": 2,
      "z": 2,
      "name": "Empty",
      "level": 0
    },
    {
      "x": 4,
      "y": 2,
      "z": 3,
      "name": "Empty",
      "level": 0
    },
    {
      "x": 4,
      "y": 3,
      "z": 3,
      "name": "Empty",
      "level": 0
    },
    {
      "x": 5,
      "y": 2,
      "z": -1,
      "name": "Empty",
      "level": 0
    },
    {
      "x": 5,
      "y": 2,
      "z": 0,
      "name": "Empty",
      "level": 0
    },
    {
      "x": 5,
      "y": 2,
      "z": 1,
      "name": "Empty",
      "level": 0
    },
    {
      "x": 5,
      "y": 3,
      "z": 1,
      "name": "Empty",
      "level": 0
    }
  ]
}