{
  "version": 8,
  "blockIdVersion": 11,
  "anchorX": 0,
  "anchorY": 0,
  "anchorZ": 0,
  "blocks": [
    {
      "x": -58,
      "y": 6,
      "z": -1,
      "name": "Rock_Sandstone_Brick_Pillar_Base",
      "rotation": 5
    },
    {
      "x": -58,
      "y": 6,
      "z": 2,
      "name": "Rock_Sandstone_Brick_Pillar_Base",
      "rotation": 5
    },
    {
      "x": -57,
      "y": 5,
      "z": -4,
      "name": "Rock_Sandstone_Brick_Beam",
      "rotation": 13
    },
    {
      "x": -57,
      "y": 6,
      "z": -2,
      "name": "Soil_Clay_Ocean_Brick_Smooth",
      "rotation": 13
    },
    {
      "x": -57,
      "y": 3,
      "z": -1,
      "name": "Rock_Sandstone_Brick_Beam",
      "rotation": 13
    },
    {
      "x": -57,
      "y": 6,
      "z": -1,
      "name": "Soil_Clay_Ocean_Brick_Smooth",
      "rotation": 13
    },
    {
      "x": -57,
      "y": 5,
      "z": 0,
      "name": "Soil_Clay_Ocean_Brick_Smooth",
      "rotation": 13
    },
    {
      "x": -57,
      "y": 6,
      "z": 0,
      "name": "Soil_Clay_Ocean_Brick_Smooth",
      "rotation": 13
    },
    {
      "x": -57,
      "y": 5,
      "z": 1,
      "name": "Soil_Clay_Ocean_Brick_Smooth",
      "rotation": 13
    },
    {
      "x": -57,
      "y": 6,
      "z": 1,
      "name": "Soil_Clay_Ocean_Brick_Smooth",
      "rotation": 13
    },
    {
      "x": -57,
      "y": 3,
      "z": 2,
      "name": "Rock_Sandstone_Brick_Beam",
      "rotation": 13
    },
    {
      "x": -57,
      "y": 6,
      "z": 2,
      "name": "Soil_Clay_Ocean_Brick_Smooth",
      "rotation": 13
    },
    {
      "x": -57,
      "y": 6,
      "z": 3,
      "name": "Soil_Clay_Ocean_Brick_Smooth",
      "rotation": 13
    },
    {
      "x": -57,
      "y": 5,
      "z": 5,
      "name": "Rock_Sandstone_Brick_Beam",
      "rotation": 13
    },
    {
      "x": -56,
      "y": 5,
      "z": -4,
      "name": "Rock_Sandstone_Brick_Beam",
      "rotation": 13
    },
    {
      "x": -56,
      "y": 6,
      "z": -3,
      "name": "Soil_Clay_Ocean_Brick_Smooth",
      "rotation": 13
    },
    {
      "x": -56,
      "y": 5,
      "z": -2,
      "name": "Soil_Clay_Ocean_Brick_Smooth",
      "rotation": 13
    },
    {
      "x": -56,
      "y": 6,
      "z": -2,
      "name": "Soil_Clay_Ocean_Brick_Smooth",
      "rotation": 13
    },
    {
      "x": -56,
      "y": 3,
      "z": -1,
      "name": "Rock_Sandstone_Brick_Beam",
      "rotation": 13
    },
    {
      "x": -56,
      "y": 5,
      "z": -1,
      "name": "Soil_Clay_Ocean_Brick_Smooth",
      "rotation": 13
    },
    {
      "x": -56,
      "y": 6,
      "z": -1,
      "name": "Soil_Clay_Ocean_Brick_Smooth",
      "rotation": 13
    },
    {
      "x": -56,
      "y": 4,
      "z": 0,
      "name": "Soil_Clay_Ocean_Brick_Smooth",
      "rotation": 13
    },
    {
      "x": -56,
      "y": 5,
      "z": 0,
      "name": "Soil_Clay_Ocean_Brick_Smooth",
      "rotation": 13
    },
    {
      "x": -56,
      "y": 4,
      "z": 1,
      "name": "Soil_Clay_Ocean_Brick_Smooth",
      "rotation": 13
    },
    {
      "x": -56,
      "y": 5,
      "z": 1,
      "name": "Soil_Clay_Ocean_Brick_Smooth",
      "rotation": 13
    },
    {
      "x": -56,
      "y": 3,
      "z": 2,
      "name": "Rock_Sandstone_Brick_Beam",
      "rotation": 13
    },
    {
      "x": -56,
      "y": 5,
      "z": 2,
      "name": "Soil_Clay_Ocean_Brick_Smooth",
      "rotation": 13
    },
    {
      "x": -56,
      "y": 6,
      "z": 2,
      "name": "Soil_Clay_Ocean_Brick_Smooth",
      "rotation": 13
    },
    {
      "x": -56,
      "y": 5,
      "z": 3,
      "name": "Soil_Clay_Ocean_Brick_Smooth",
      "rotation": 13
    },
    {
      "x": -56,
      "y": 6,
      "z": 3,
      "name": "Soil_Clay_Ocean_Brick_Smooth",
      "rotation": 13
    },
    {
      "x": -56,
      "y": 6,
      "z": 4,
      "name": "Soil_Clay_Ocean_Brick_Smooth",
      "rotation": 13
    },
    {
      "x": -56,
      "y": 5,
      "z": 5,
      "name": "Rock_Sandstone_Brick_Beam",
      "rotation": 13
    },
    {
      "x": -55,
      "y": 5,
      "z": -4,
      "name": "Rock_Sandstone_Brick",
      "rotation": 13
    },
    {
      "x": -55,
      "y": 6,
      "z": -4,
      "name": "Soil_Clay_Ocean_Brick_Smooth",
      "rotation": 13
    },
    {
      "x": -55,
      "y": 5,
      "z": -3,
      "name": "Soil_Clay_Ocean_Brick_Smooth",
      "rotation": 13
    },
    {
      "x": -55,
      "y": 6,
      "z": -3,
      "name": "Wood_Dry_Trunk_Full",
      "support": 15,
      "rotation": 49
    },
    {
      "x": -55,
      "y": 5,
      "z": -2,
      "name": "Soil_Clay_Ocean_Brick_Smooth",
      "rotation": 13
    },
    {
      "x": -55,
      "y": 6,
      "z": -2,
      "name": "Wood_Dry_Trunk_Full",
      "support": 15,
      "rotation": 49
    },
    {
      "x": -55,
      "y": 3,
      "z": -1,
      "name": "Rock_Sandstone_Brick",
      "rotation": 13
    },
    {
      "x": -55,
      "y": 4,
      "z": -1,
      "name": "Soil_Clay_Ocean_Brick_Smooth",
      "rotation": 13
    },
    {
      "x": -55,
      "y": 5,
      "z": -1,
      "name": "Wood_Dry_Trunk",
      "support": 15,
      "rotation": 49
    },
    {
      "x": -55,
      "y": 4,
      "z": 0,
      "name": "Soil_Clay_Ocean_Brick_Smooth",
      "rotation": 13
    },
    {
      "x": -55,
      "y": 5,
      "z": 0,
      "name": "Wood_Dry_Trunk",
      "support": 15,
      "rotation": 49
    },
    {
      "x": -55,
      "y": 4,
      "z": 1,
      "name": "Soil_Clay_Ocean_Brick_Smooth",
      "rotation": 13
    },
    {
      "x": -55,
      "y": 5,
      "z": 1,
      "name": "Wood_Dry_Trunk",
      "support": 15,
      "rotation": 49
    },
    {
      "x": -55,
      "y": 3,
      "z": 2,
      "name": "Rock_Sandstone_Brick",
      "rotation": 13
    },
    {
      "x": -55,
      "y": 4,
      "z": 2,
      "name": "Soil_Clay_Ocean_Brick_Smooth",
      "rotation": 13
    },
    {
      "x": -55,
      "y": 5,
      "z": 2,
      "name": "Wood_Dry_Trunk",
      "support": 15,
      "rotation": 49
    },
    {
      "x": -55,
      "y": 5,
      "z": 3,
      "name": "Soil_Clay_Ocean_Brick_Smooth",
      "rotation": 13
    },
    {
      "x": -55,
      "y": 6,
      "z": 3,
      "name": "Wood_Dry_Trunk_Full",
      "support": 15,
      "rotation": 49
    },
    {
      "x": -55,
      "y": 5,
      "z": 4,
      "name": "Soil_Clay_Ocean_Brick_Smooth",
      "rotation": 13
    },
    {
      "x": -55,
      "y": 6,
      "z": 4,
      "name": "Wood_Dry_Trunk_Full",
      "support": 15,
      "rotation": 1
    },
    {
      "x": -55,
      "y": 5,
      "z": 5,
      "name": "Rock_Sandstone_Brick",
      "rotation": 13
    },
    {
      "x": -55,
      "y": 6,
      "z": 5,
      "name": "Soil_Clay_Ocean_Brick_Smooth",
      "rotation": 13
    },
    {
      "x": -54,
      "y": 6,
      "z": -5,
      "name": "Rock_Sandstone_Brick_Smooth",
      "rotation": 13
    },
    {
      "x": -54,
      "y": 5,
      "z": -4,
      "name": "Rock_Sandstone_Brick",
      "rotation": 13
    },
    {
      "x": -54,
      "y": 6,
      "z": -4,
      "name": "Rock_Sandstone_Brick",
      "rotation": 13
    },
    {
      "x": -54,
      "y": 4,
      "z": -3,
      "name": "Rock_Sandstone_Brick_Smooth",
      "rotation": 13
    },
    {
      "x": -54,
      "y": 5,
      "z": -3,
      "name": "Rock_Sandstone_Brick",
      "rotation": 13
    },
    {
      "x": -54,
      "y": 6,
      "z": -3,
      "name": "Furniture_Village_Bookcase",
      "rotation": 13
    },
    {
      "x": -54,
      "y": 4,
      "z": -2,
      "name": "Rock_Sandstone_Brick_Smooth",
      "rotation": 13
    },
    {
      "x": -54,
      "y": 5,
      "z": -2,
      "name": "Rock_Sandstone_Brick",
      "rotation": 13
    },
    {
      "x": -54,
      "y": 6,
      "z": -2,
      "name": "Furniture_Village_Bookcase",
      "rotation": 13
    },
    {
      "x": -54,
      "y": 3,
      "z": -1,
      "name": "Rock_Sandstone_Brick",
      "rotation": 13
    },
    {
      "x": -54,
      "y": 4,
      "z": -1,
      "name": "Rock_Sandstone_Brick",
      "rotation": 13
    },
    {
      "x": -54,
      "y": 5,
      "z": -1,
      "name": "Furniture_Village_Bookcase",
      "rotation": 13
    },
    {
      "x": -54,
      "y": 3,
      "z": 0,
      "name": "Rock_Sandstone_Brick_Smooth",
      "rotation": 13
    },
    {
      "x": -54,
      "y": 4,
      "z": 0,
      "name": "Rock_Sandstone_Brick",
      "rotation": 13
    },
    {
      "x": -54,
      "y": 5,
      "z": 0,
      "name": "Furniture_Village_Bookcase",
      "rotation": 13
    },
    {
      "x": -54,
      "y": 3,
      "z": 1,
      "name": "Rock_Sandstone_Brick_Smooth",
      "rotation": 13
    },
    {
      "x": -54,
      "y": 4,
      "z": 1,
      "name": "Rock_Sandstone_Brick",
      "rotation": 13
    },
    {
      "x": -54,
      "y": 5,
      "z": 1,
      "name": "Furniture_Village_Bookcase",
      "rotation": 13
    },
    {
      "x": -54,
      "y": 3,
      "z": 2,
      "name": "Rock_Sandstone_Brick",
      "rotation": 13
    },
    {
      "x": -54,
      "y": 4,
      "z": 2,
      "name": "Rock_Sandstone_Brick",
      "rotation": 13
    },
    {
      "x": -54,
      "y": 5,
      "z": 2,
      "name": "Furniture_Village_Bookcase",
      "rotation": 13
    },
    {
      "x": -54,
      "y": 4,
      "z": 3,
      "name": "Rock_Sandstone_Brick_Smooth",
      "rotation": 13
    },
    {
      "x": -54,
      "y": 5,
      "z": 3,
      "name": "Rock_Sandstone_Brick",
      "rotation": 13
    },
    {
      "x": -54,
      "y": 6,
      "z": 3,
      "name": "Furniture_Village_Bookcase",
      "rotation": 13
    },
    {
      "x": -54,
      "y": 4,
      "z": 4,
      "name": "Rock_Sandstone_Brick_Smooth",
      "rotation": 13
    },
    {
      "x": -54,
      "y": 5,
      "z": 4,
      "name": "Rock_Sandstone_Brick",
      "rotation": 13
    },
    {
      "x": -54,
      "y": 6,
      "z": 4,
      "name": "Furniture_Village_Bookcase",
      "rotation": 13
    },
    {
      "x": -54,
      "y": 5,
      "z": 5,
      "name": "Rock_Sandstone_Brick",
      "rotation": 13
    },
    {
      "x": -54,
      "y": 6,
      "z": 5,
      "name": "Rock_Sandstone_Brick",
      "rotation": 13
    },
    {
      "x": -54,
      "y": 6,
      "z": 6,
      "name": "Rock_Sandstone_Brick_Smooth",
      "rotation": 13
    },
    {
      "x": -53,
      "y": 5,
      "z": -5,
      "name": "Rock_Sandstone_Brick_Pillar_Base",
      "rotation": 5
    },
    {
      "x": -53,
      "y": 6,
      "z": -5,
      "name": "Rock_Gold_Brick_Smooth_Half",
      "rotation": 49
    },
    {
      "x": -53,
      "y": 4,
      "z": -4,
      "name": "Rock_Gold_Brick_Smooth_Half",
      "rotation": 49
    },
    {
      "x": -53,
      "y": 5,
      "z": -4,
      "name": "Rock_Sandstone_Brick",
      "rotation": 13
    },
    {
      "x": -53,
      "y": 6,
      "z": -4,
      "name": "Rock_Sandstone_Brick",
      "rotation": 13
    },
    {
      "x": -53,
      "y": 3,
      "z": -3,
      "name": "Rock_Sandstone_Brick_Pillar_Base",
      "rotation": 5
    },
    {
      "x": -53,
      "y": 4,
      "z": -3,
      "name": "*Rock_Gold_Brick_Smooth_Half_State_Definitions_Block",
      "rotation": 49
    },
    {
      "x": -53,
      "y": 5,
      "z": -3,
      "name": "Rock_Sandstone_Brick",
      "rotation": 13
    },
    {
      "x": -53,
      "y": 6,
      "z": -3,
      "name": "Furniture_Village_Bookcase",
      "rotation": 13
    },
    {
      "x": -53,
      "y": 3,
      "z": -2,
      "name": "Rock_Gold_Brick_Smooth_Half",
      "rotation": 33
    },
    {
      "x": -53,
      "y": 4,
      "z": -2,
      "name": "Rock_Sandstone_Brick",
      "rotation": 13
    },
    {
      "x": -53,
      "y": 5,
      "z": -2,
      "name": "Rock_Sandstone_Brick",
      "rotation": 13
    },
    {
      "x": -53,
      "y": 6,
      "z": -2,
      "name": "Furniture_Village_Bookcase",
      "rotation": 13
    },
    {
      "x": -53,
      "y": 3,
      "z": -1,
      "name": "Rock_Sandstone_Brick",
      "rotation": 16
    },
    {
      "x": -53,
      "y": 4,
      "z": -1,
      "name": "Rock_Sandstone_Brick",
      "rotation": 13
    },
    {
      "x": -53,
      "y": 5,
      "z": -1,
      "name": "Furniture_Village_Bookcase",
      "rotation": 13
    },
    {
      "x": -53,
      "y": 2,
      "z": 0,
      "name": "Rock_Gold_Brick_Smooth_Half",
      "rotation": 33
    },
    {
      "x": -53,
      "y": 3,
      "z": 0,
      "name": "Rock_Sandstone_Brick",
      "rotation": 13
    },
    {
      "x": -53,
      "y": 4,
      "z": 0,
      "name": "Rock_Sandstone_Brick",
      "rotation": 13
    },
    {
      "x": -53,
      "y": 5,
      "z": 0,
      "name": "Furniture_Village_Bookcase",
      "rotation": 13
    },
    {
      "x": -53,
      "y": 2,
      "z": 1,
      "name": "Rock_Sandstone_Brick_Smooth_Half",
      "rotation": 13
    },
    {
      "x": -53,
      "y": 3,
      "z": 1,
      "name": "Rock_Sandstone_Brick",
      "rotation": 13
    },
    {
      "x": -53,
      "y": 4,
      "z": 1,
      "name": "Rock_Sandstone_Brick",
      "rotation": 13
    },
    {
      "x": -53,
      "y": 5,
      "z": 1,
      "name": "Furniture_Village_Bookcase",
      "rotation": 13
    },
    {
      "x": -53,
      "y": 2,
      "z": 2,
      "name": "Rock_Gold_Brick_Smooth_Half",
      "rotation": 33
    },
    {
      "x": -53,
      "y": 3,
      "z": 2,
      "name": "Rock_Gold_Brick_Smooth_Half",
      "rotation": 33
    },
    {
      "x": -53,
      "y": 4,
      "z": 2,
      "name": "Rock_Sandstone_Brick",
      "rotation": 13
    },
    {
      "x": -53,
      "y": 5,
      "z": 2,
      "name": "Furniture_Village_Bookcase",
      "rotation": 13
    },
    {
      "x": -53,
      "y": 3,
      "z": 3,
      "name": "Rock_Sandstone_Brick",
      "rotation": 16
    },
    {
      "x": -53,
      "y": 4,
      "z": 3,
      "name": "Rock_Sandstone_Brick",
      "rotation": 16
    },
    {
      "x": -53,
      "y": 5,
      "z": 3,
      "name": "Rock_Sandstone_Brick",
      "rotation": 13
    },
    {
      "x": -53,
      "y": 6,
      "z": 3,
      "name": "Furniture_Village_Bookcase",
      "rotation": 13
    },
    {
      "x": -53,
      "y": 3,
      "z": 4,
      "name": "Rock_Gold_Brick_Smooth_Half",
      "rotation": 33
    },
    {
      "x": -53,
      "y": 4,
      "z": 4,
      "name": "Rock_Gold_Brick_Smooth_Half",
      "rotation": 33
    },
    {
      "x": -53,
      "y": 5,
      "z": 4,
      "name": "Rock_Sandstone_Cobble",
      "rotation": 13
    },
    {
      "x": -53,
      "y": 6,
      "z": 4,
      "name": "Furniture_Village_Bookcase",
      "rotation": 13
    },
    {
      "x": -53,
      "y": 3,
      "z": 5,
      "name": "Rock_Sandstone_Brick_Pillar_Base",
      "rotation": 5
    },
    {
      "x": -53,
      "y": 4,
      "z": 5,
      "name": "Rock_Sandstone_Brick",
      "rotation": 13
    },
    {
      "x": -53,
      "y": 5,
      "z": 5,
      "name": "Rock_Sandstone_Brick",
      "rotation": 13
    },
    {
      "x": -53,
      "y": 6,
      "z": 5,
      "name": "Rock_Sandstone_Cobble",
      "rotation": 13
    },
    {
      "x": -53,
      "y": 4,
      "z": 6,
      "name": "Rock_Gold_Brick_Smooth_Half",
      "rotation": 17
    },
    {
      "x": -53,
      "y": 5,
      "z": 6,
      "name": "Rock_Sandstone_Brick",
      "rotation": 13
    },
    {
      "x": -53,
      "y": 6,
      "z": 6,
      "name": "Rock_Gold_Brick_Smooth_Half",
      "rotation": 17
    },
    {
      "x": -53,
      "y": 5,
      "z": 7,
      "name": "Rock_Sandstone_Brick_Pillar_Base",
      "rotation": 5
    },
    {
      "x": -53,
      "y": 6,
      "z": 7,
      "name": "Rock_Gold_Brick_Smooth_Half",
      "rotation": 17
    },
    {
      "x": -52,
      "y": 5,
      "z": -5,
      "name": "Rock_Sandstone_Brick_Pillar_Middle",
      "rotation": 13
    },
    {
      "x": -52,
      "y": 5,
      "z": -4,
      "name": "Wood_Drywood_Planks",
      "rotation": 13
    },
    {
      "x": -52,
      "y": 3,
      "z": -3,
      "name": "Rock_Sandstone_Brick_Pillar_Middle",
      "rotation": 13
    },
    {
      "x": -52,
      "y": 4,
      "z": -3,
      "name": "Wood_Drywood_Planks",
      "rotation": 13
    },
    {
      "x": -52,
      "y": 5,
      "z": -3,
      "name": "Wood_Drywood_Planks",
      "rotation": 13
    },
    {
      "x": -52,
      "y": 4,
      "z": -2,
      "name": "Wood_Drywood_Planks",
      "rotation": 13
    },
    {
      "x": -52,
      "y": 3,
      "z": -1,
      "name": "Wood_Drywood_Planks",
      "rotation": 13
    },
    {
      "x": -52,
      "y": 2,
      "z": 0,
      "name": "Rock_Sandstone_Brick_Stairs",
      "rotation": 50
    },
    {
      "x": -52,
      "y": 3,
      "z": 0,
      "name": "Wood_Drywood_Planks",
      "rotation": 13
    },
    {
      "x": -52,
      "y": 2,
      "z": 1,
      "name": "Rock_Sandstone_Brick_Smooth_Half",
      "rotation": 5
    },
    {
      "x": -52,
      "y": 3,
      "z": 1,
      "name": "Furniture_Desert_Window",
      "rotation": 13
    },
    {
      "x": -52,
      "y": 2,
      "z": 2,
      "name": "Rock_Sandstone_Brick_Stairs",
      "rotation": 16
    },
    {
      "x": -52,
      "y": 3,
      "z": 2,
      "name": "Wood_Drywood_Planks",
      "rotation": 13
    },
    {
      "x": -52,
      "y": 3,
      "z": 3,
      "name": "Wood_Drywood_Planks",
      "rotation": 13
    },
    {
      "x": -52,
      "y": 4,
      "z": 4,
      "name": "Wood_Drywood_Planks",
      "rotation": 13
    },
    {
      "x": -52,
      "y": 3,
      "z": 5,
      "name": "Rock_Sandstone_Brick_Pillar_Middle",
      "rotation": 13
    },
    {
      "x": -52,
      "y": 4,
      "z": 5,
      "name": "Wood_Drywood_Planks",
      "rotation": 13
    },
    {
      "x": -52,
      "y": 5,
      "z": 5,
      "name": "Wood_Drywood_Planks",
      "rotation": 13
    },
    {
      "x": -52,
      "y": 5,
      "z": 6,
      "name": "Wood_Drywood_Planks",
      "rotation": 13
    },
    {
      "x": -52,
      "y": 6,
      "z": 6,
      "name": "Wood_Drywood_Planks",
      "rotation": 13
    },
    {
      "x": -52,
      "y": 5,
      "z": 7,
      "name": "Rock_Sandstone_Brick_Pillar_Middle",
      "rotation": 13
    },
    {
      "x": -51,
      "y": 5,
      "z": -5,
      "name": "Rock_Sandstone_Brick_Pillar_Middle",
      "rotation": 13
    },
    {
      "x": -51,
      "y": 5,
      "z": -4,
      "name": "Wood_Drywood_Planks",
      "rotation": 13
    },
    {
      "x": -51,
      "y": 3,
      "z": -3,
      "name": "Rock_Sandstone_Brick_Pillar_Middle",
      "rotation": 13
    },
    {
      "x": -51,
      "y": 4,
      "z": -3,
      "name": "Wood_Drywood_Planks",
      "rotation": 13
    },
    {
      "x": -51,
      "y": 5,
      "z": -3,
      "name": "Wood_Drywood_Planks",
      "rotation": 13
    },
    {
      "x": -51,
      "y": 4,
      "z": -2,
      "name": "Wood_Drywood_Planks",
      "rotation": 13
    },
    {
      "x": -51,
      "y": 2,
      "z": -1,
      "name": "Rock_Sandstone_Brick_Smooth_Half",
      "rotation": 49
    },
    {
      "x": -51,
      "y": 3,
      "z": -1,
      "name": "Wood_Drywood_Planks",
      "rotation": 13
    },
    {
      "x": -51,
      "y": 2,
      "z": 0,
      "name": "Rock_Sandstone_Brick_Smooth_Half",
      "rotation": 17
    },
    {
      "x": -51,
      "y": 3,
      "z": 0,
      "name": "Furniture_Desert_Window",
      "rotation": 13
    },
    {
      "x": -51,
      "y": 3,
      "z": 1,
      "name": "Furniture_Desert_Window",
      "rotation": 13
    },
    {
      "x": -51,
      "y": 2,
      "z": 2,
      "name": "Rock_Sandstone_Brick_Smooth_Half",
      "rotation": 49
    },
    {
      "x": -51,
      "y": 3,
      "z": 2,
      "name": "Furniture_Desert_Window",
      "rotation": 13
    },
    {
      "x": -51,
      "y": 2,
      "z": 3,
      "name": "Rock_Sandstone_Brick_Smooth_Half",
      "rotation": 17
    },
    {
      "x": -51,
      "y": 3,
      "z": 3,
      "name": "Wood_Drywood_Planks",
      "rotation": 13
    },
    {
      "x": -51,
      "y": 4,
      "z": 4,
      "name": "Wood_Drywood_Planks",
      "rotation": 13
    },
    {
      "x": -51,
      "y": 3,
      "z": 5,
      "name": "Rock_Sandstone_Brick_Pillar_Middle",
      "rotation": 13
    },
    {
      "x": -51,
      "y": 4,
      "z": 5,
      "name": "Wood_Drywood_Planks",
      "rotation": 13
    },
    {
      "x": -51,
      "y": 5,
      "z": 5,
      "name": "Wood_Drywood_Planks",
      "rotation": 13
    },
    {
      "x": -51,
      "y": 5,
      "z": 6,
      "name": "Wood_Drywood_Planks",
      "rotation": 13
    },
    {
      "x": -51,
      "y": 6,
      "z": 6,
      "name": "Wood_Drywood_Planks",
      "rotation": 13
    },
    {
      "x": -51,
      "y": 5,
      "z": 7,
      "name": "Rock_Sandstone_Brick_Pillar_Middle",
      "rotation": 13
    },
    {
      "x": -50,
      "y": 5,
      "z": -5,
      "name": "Rock_Sandstone_Brick_Pillar_Middle",
      "rotation": 13
    },
    {
      "x": -50,
      "y": 5,
      "z": -4,
      "name": "Wood_Drywood_Planks",
      "rotation": 13
    },
    {
      "x": -50,
      "y": 3,
      "z": -3,
      "name": "Rock_Sandstone_Brick_Pillar_Middle",
      "rotation": 13
    },
    {
      "x": -50,
      "y": 4,
      "z": -3,
      "name": "Wood_Drywood_Planks",
      "rotation": 13
    },
    {
      "x": -50,
      "y": 5,
      "z": -3,
      "name": "Wood_Drywood_Planks",
      "rotation": 13
    },
    {
      "x": -50,
      "y": 4,
      "z": -2,
      "name": "Wood_Drywood_Planks",
      "rotation": 13
    },
    {
      "x": -50,
      "y": 2,
      "z": -1,
      "name": "Rock_Sandstone_Brick_Half",
      "rotation": 49
    },
    {
      "x": -50,
      "y": 3,
      "z": -1,
      "name": "Wood_Drywood_Planks",
      "rotation": 13
    },
    {
      "x": -50,
      "y": 3,
      "z": 0,
      "name": "Furniture_Desert_Window",
      "rotation": 13
    },
    {
      "x": -50,
      "y": 3,
      "z": 1,
      "name": "Furniture_Desert_Window",
      "rotation": 13
    },
    {
      "x": -50,
      "y": 3,
      "z": 2,
      "name": "Furniture_Desert_Window",
      "rotation": 13
    },
    {
      "x": -50,
      "y": 2,
      "z": 3,
      "name": "Rock_Sandstone_Brick_Half",
      "rotation": 17
    },
    {
      "x": -50,
      "y": 3,
      "z": 3,
      "name": "Wood_Drywood_Planks",
      "rotation": 13
    },
    {
      "x": -50,
      "y": 4,
      "z": 4,
      "name": "Wood_Drywood_Planks",
      "rotation": 13
    },
    {
      "x": -50,
      "y": 3,
      "z": 5,
      "name": "Rock_Sandstone_Brick_Pillar_Middle",
      "rotation": 13
    },
    {
      "x": -50,
      "y": 4,
      "z": 5,
      "name": "Wood_Drywood_Planks",
      "rotation": 13
    },
    {
      "x": -50,
      "y": 5,
      "z": 5,
      "name": "Wood_Drywood_Planks",
      "rotation": 13
    },
    {
      "x": -50,
      "y": 5,
      "z": 6,
      "name": "Wood_Drywood_Planks",
      "rotation": 13
    },
    {
      "x": -50,
      "y": 6,
      "z": 6,
      "name": "Wood_Drywood_Planks",
      "rotation": 13
    },
    {
      "x": -50,
      "y": 5,
      "z": 7,
      "name": "Rock_Sandstone_Brick_Pillar_Middle",
      "rotation": 13
    },
    {
      "x": -49,
      "y": 5,
      "z": -5,
      "name": "Rock_Sandstone_Brick_Pillar_Middle",
      "rotation": 13
    },
    {
      "x": -49,
      "y": 5,
      "z": -4,
      "name": "Wood_Drywood_Planks",
      "rotation": 13
    },
    {
      "x": -49,
      "y": 3,
      "z": -3,
      "name": "Rock_Sandstone_Brick_Pillar_Middle",
      "rotation": 13
    },
    {
      "x": -49,
      "y": 4,
      "z": -3,
      "name": "Wood_Drywood_Planks",
      "rotation": 13
    },
    {
      "x": -49,
      "y": 5,
      "z": -3,
      "name": "Wood_Drywood_Planks",
      "rotation": 13
    },
    {
      "x": -49,
      "y": 4,
      "z": -2,
      "name": "Wood_Drywood_Planks",
      "rotation": 13
    },
    {
      "x": -49,
      "y": 2,
      "z": -1,
      "name": "Rock_Sandstone_Brick_Half",
      "rotation": 49
    },
    {
      "x": -49,
      "y": 3,
      "z": -1,
      "name": "Wood_Drywood_Planks",
      "rotation": 13
    },
    {
      "x": -49,
      "y": 3,
      "z": 0,
      "name": "Furniture_Desert_Window",
      "rotation": 13
    },
    {
      "x": -49,
      "y": 3,
      "z": 1,
      "name": "Wood_Drywood_Beam",
      "rotation": 16
    },
    {
      "x": -49,
      "y": 3,
      "z": 2,
      "name": "Furniture_Desert_Window",
      "rotation": 13
    },
    {
      "x": -49,
      "y": 2,
      "z": 3,
      "name": "Rock_Sandstone_Brick_Half",
      "rotation": 17
    },
    {
      "x": -49,
      "y": 3,
      "z": 3,
      "name": "Wood_Drywood_Planks",
      "rotation": 13
    },
    {
      "x": -49,
      "y": 4,
      "z": 4,
      "name": "Wood_Drywood_Planks",
      "rotation": 13
    },
    {
      "x": -49,
      "y": 3,
      "z": 5,
      "name": "Rock_Sandstone_Brick_Pillar_Middle",
      "rotation": 13
    },
    {
      "x": -49,
      "y": 4,
      "z": 5,
      "name": "Wood_Drywood_Planks",
      "rotation": 13
    },
    {
      "x": -49,
      "y": 5,
      "z": 5,
      "name": "Wood_Drywood_Planks",
      "rotation": 13
    },
    {
      "x": -49,
      "y": 5,
      "z": 6,
      "name": "Wood_Drywood_Planks",
      "rotation": 13
    },
    {
      "x": -49,
      "y": 6,
      "z": 6,
      "name": "Wood_Drywood_Planks",
      "rotation": 13
    },
    {
      "x": -49,
      "y": 5,
      "z": 7,
      "name": "Rock_Sandstone_Brick_Pillar_Middle",
      "rotation": 13
    },
    {
      "x": -48,
      "y": 5,
      "z": -5,
      "name": "Rock_Sandstone_Brick_Pillar_Middle",
      "rotation": 13
    },
    {
      "x": -48,
      "y": 5,
      "z": -4,
      "name": "Wood_Drywood_Planks",
      "rotation": 13
    },
    {
      "x": -48,
      "y": 3,
      "z": -3,
      "name": "Rock_Sandstone_Brick_Pillar_Middle",
      "rotation": 13
    },
    {
      "x": -48,
      "y": 4,
      "z": -3,
      "name": "Wood_Drywood_Planks",
      "rotation": 13
    },
    {
      "x": -48,
      "y": 5,
      "z": -3,
      "name": "Wood_Drywood_Planks",
      "rotation": 13
    },
    {
      "x": -48,
      "y": 4,
      "z": -2,
      "name": "Wood_Drywood_Planks",
      "rotation": 13
    },
    {
      "x": -48,
      "y": 2,
      "z": -1,
      "name": "Rock_Sandstone_Brick_Half",
      "rotation": 49
    },
    {
      "x": -48,
      "y": 3,
      "z": -1,
      "name": "Wood_Drywood_Planks",
      "rotation": 13
    },
    {
      "x": -48,
      "y": 3,
      "z": 2,
      "name": "Furniture_Desert_Window",
      "rotation": 13
    },
    {
      "x": -48,
      "y": 2,
      "z": 3,
      "name": "Rock_Sandstone_Brick_Half",
      "rotation": 17
    },
    {
      "x": -48,
      "y": 3,
      "z": 3,
      "name": "Wood_Drywood_Planks",
      "rotation": 13
    },
    {
      "x": -48,
      "y": 4,
      "z": 4,
      "name": "Wood_Drywood_Planks",
      "rotation": 13
    },
    {
      "x": -48,
      "y": 3,
      "z": 5,
      "name": "Rock_Sandstone_Brick_Beam",
      "rotation": 13
    },
    {
      "x": -48,
      "y": 4,
      "z": 5,
      "name": "Wood_Drywood_Planks",
      "rotation": 13
    },
    {
      "x": -48,
      "y": 5,
      "z": 5,
      "name": "Wood_Drywood_Planks",
      "rotation": 13
    },
    {
      "x": -48,
      "y": 5,
      "z": 6,
      "name": "Wood_Drywood_Planks",
      "rotation": 13
    },
    {
      "x": -48,
      "y": 6,
      "z": 6,
      "name": "Wood_Drywood_Planks",
      "rotation": 13
    },
    {
      "x": -48,
      "y": 4,
      "z": 7,
      "name": "Rock_Sandstone_Brick_Beam",
      "rotation": 13
    },
    {
      "x": -48,
      "y": 5,
      "z": 7,
      "name": "Rock_Sandstone_Brick_Pillar_Middle",
      "rotation": 13
    },
    {
      "x": -47,
      "y": 5,
      "z": -5,
      "name": "Rock_Sandstone_Brick_Pillar_Middle",
      "rotation": 13
    },
    {
      "x": -47,
      "y": 5,
      "z": -4,
      "name": "Wood_Drywood_Planks",
      "rotation": 13
    },
    {
      "x": -47,
      "y": 3,
      "z": -3,
      "name": "Rock_Sandstone_Brick_Pillar_Middle",
      "rotation": 13
    },
    {
      "x": -47,
      "y": 4,
      "z": -3,
      "name": "Wood_Drywood_Planks",
      "rotation": 13
    },
    {
      "x": -47,
      "y": 5,
      "z": -3,
      "name": "Wood_Drywood_Planks",
      "rotation": 13
    },
    {
      "x": -47,
      "y": 4,
      "z": -2,
      "name": "Wood_Drywood_Planks",
      "rotation": 13
    },
    {
      "x": -47,
      "y": 2,
      "z": -1,
      "name": "Rock_Sandstone_Brick_Half",
      "rotation": 49
    },
    {
      "x": -47,
      "y": 3,
      "z": -1,
      "name": "Wood_Drywood_Planks",
      "rotation": 13
    },
    {
      "x": -47,
      "y": 3,
      "z": 2,
      "name": "Wood_Drywood_Beam",
      "rotation": 16
    },
    {
      "x": -47,
      "y": 2,
      "z": 3,
      "name": "Rock_Sandstone_Brick_Half",
      "rotation": 17
    },
    {
      "x": -47,
      "y": 3,
      "z": 3,
      "name": "Wood_Drywood_Planks",
      "rotation": 13
    },
    {
      "x": -47,
      "y": 4,
      "z": 4,
      "name": "Wood_Drywood_Planks",
      "rotation": 13
    },
    {
      "x": -47,
      "y": 3,
      "z": 5,
      "name": "Rock_Sandstone_Brick_Beam",
      "rotation": 13
    },
    {
      "x": -47,
      "y": 4,
      "z": 5,
      "name": "Wood_Drywood_Planks",
      "rotation": 13
    },
    {
      "x": -47,
      "y": 5,
      "z": 5,
      "name": "Wood_Drywood_Planks",
      "rotation": 13
    },
    {
      "x": -47,
      "y": 5,
      "z": 6,
      "name": "Wood_Drywood_Planks",
      "rotation": 13
    },
    {
      "x": -47,
      "y": 6,
      "z": 6,
      "name": "Wood_Drywood_Planks",
      "rotation": 13
    },
    {
      "x": -47,
      "y": 4,
      "z": 7,
      "name": "Rock_Sandstone_Brick_Beam",
      "rotation": 13
    },
    {
      "x": -47,
      "y": 5,
      "z": 7,
      "name": "Rock_Sandstone_Brick_Pillar_Middle",
      "rotation": 13
    },
    {
      "x": -46,
      "y": 5,
      "z": -5,
      "name": "Rock_Sandstone_Brick_Pillar_Base",
      "rotation": 13
    },
    {
      "x": -46,
      "y": 5,
      "z": -4,
      "name": "Rock_Sandstone_Brick",
      "rotation": 13
    },
    {
      "x": -46,
      "y": 3,
      "z": -3,
      "name": "Rock_Sandstone_Brick_Pillar_Base",
      "rotation": 13
    },
    {
      "x": -46,
      "y": 4,
      "z": -3,
      "name": "Rock_Sandstone_Brick",
      "rotation": 13
    },
    {
      "x": -46,
      "y": 5,
      "z": -3,
      "name": "Rock_Sandstone_Brick",
      "rotation": 13
    },
    {
      "x": -46,
      "y": 6,
      "z": -3,
      "name": "*Furniture_Temple_Dark_Candle_State_Definitions_Off",
      "filler": 31,
      "rotation": 13
    },
    {
      "x": -46,
      "y": 4,
      "z": -2,
      "name": "Rock_Sandstone_Brick",
      "rotation": 13
    },
    {
      "x": -46,
      "y": 2,
      "z": -1,
      "name": "Rock_Sandstone_Brick_Smooth_Half",
      "rotation": 49
    },
    {
      "x": -46,
      "y": 3,
      "z": -1,
      "name": "Rock_Sandstone_Brick",
      "rotation": 13
    },
    {
      "x": -46,
      "y": 2,
      "z": 3,
      "name": "Rock_Sandstone_Brick_Smooth_Half",
      "rotation": 17
    },
    {
      "x": -46,
      "y": 3,
      "z": 3,
      "name": "Rock_Sandstone_Brick",
      "rotation": 13
    },
    {
      "x": -46,
      "y": 4,
      "z": 4,
      "name": "Rock_Sandstone_Brick",
      "rotation": 13
    },
    {
      "x": -46,
      "y": 3,
      "z": 5,
      "name": "Rock_Sandstone_Brick",
      "rotation": 13
    },
    {
      "x": -46,
      "y": 4,
      "z": 5,
      "name": "Rock_Sandstone_Brick",
      "rotation": 13
    },
    {
      "x": -46,
      "y": 5,
      "z": 5,
      "name": "Rock_Sandstone_Brick",
      "rotation": 13
    },
    {
      "x": -46,
      "y": 6,
      "z": 5,
      "name": "*Furniture_Temple_Dark_Candle_State_Definitions_Off",
      "filler": 31,
      "rotation": 13
    },
    {
      "x": -46,
      "y": 5,
      "z": 6,
      "name": "Rock_Sandstone_Brick",
      "rotation": 13
    },
    {
      "x": -46,
      "y": 6,
      "z": 6,
      "name": "Rock_Sandstone_Brick",
      "rotation": 13
    },
    {
      "x": -46,
      "y": 4,
      "z": 7,
      "name": "Rock_Sandstone_Brick",
      "rotation": 13
    },
    {
      "x": -46,
      "y": 5,
      "z": 7,
      "name": "Rock_Sandstone_Brick_Pillar_Base",
      "rotation": 13
    },
    {
      "x": -45,
      "y": 5,
      "z": -8,
      "name": "Rock_Sandstone_Brick_Half",
      "rotation": 7
    },
    {
      "x": -45,
      "y": 6,
      "z": -8,
      "name": "Rock_Sandstone_Brick_Half",
      "rotation": 7
    },
    {
      "x": -45,
      "y": 5,
      "z": -7,
      "name": "Rock_Sandstone_Brick_Half",
      "rotation": 7
    },
    {
      "x": -45,
      "y": 6,
      "z": -7,
      "name": "Rock_Sandstone_Brick",
      "rotation": 7
    },
    {
      "x": -45,
      "y": 5,
      "z": -6,
      "name": "Rock_Sandstone_Brick",
      "rotation": 16
    },
    {
      "x": -45,
      "y": 6,
      "z": -6,
      "name": "Rock_Sandstone_Brick",
      "rotation": 16
    },
    {
      "x": -45,
      "y": 5,
      "z": -5,
      "name": "Rock_Sandstone_Brick",
      "rotation": 16
    },
    {
      "x": -45,
      "y": 6,
      "z": -5,
      "name": "Rock_Sandstone_Brick_Smooth",
      "rotation": 13
    },
    {
      "x": -45,
      "y": 4,
      "z": -4,
      "name": "Rock_Sandstone_Brick_Smooth",
      "rotation": 13
    },
    {
      "x": -45,
      "y": 5,
      "z": -4,
      "name": "Wood_Drywood_Planks",
      "rotation": 13
    },
    {
      "x": -45,
      "y": 2,
      "z": -3,
      "name": "Rock_Sandstone_Brick",
      "rotation": 16
    },
    {
      "x": -45,
      "y": 3,
      "z": -3,
      "name": "Rock_Sandstone_Brick",
      "rotation": 16
    },
    {
      "x": -45,
      "y": 4,
      "z": -3,
      "name": "Wood_Drywood_Planks",
      "rotation": 13
    },
    {
      "x": -45,
      "y": 5,
      "z": -3,
      "name": "Wood_Drywood_Planks",
      "rotation": 13
    },
    {
      "x": -45,
      "y": 6,
      "z": -3,
      "name": "*Furniture_Temple_Dark_Candle_State_Definitions_Off",
      "rotation": 13
    },
    {
      "x": -45,
      "y": 1,
      "z": -2,
      "name": "Rock_Sandstone_Brick",
      "rotation": 16
    },
    {
      "x": -45,
      "y": 2,
      "z": -2,
      "name": "Rock_Sandstone_Brick",
      "rotation": 16
    },
    {
      "x": -45,
      "y": 3,
      "z": -2,
      "name": "Rock_Sandstone_Brick_Smooth",
      "rotation": 13
    },
    {
      "x": -45,
      "y": 4,
      "z": -2,
      "name": "Wood_Drywood_Planks",
      "rotation": 13
    },
    {
      "x": -45,
      "y": 1,
      "z": -1,
      "name": "Rock_Sandstone_Brick",
      "rotation": 16
    },
    {
      "x": -45,
      "y": 2,
      "z": -1,
      "name": "Rock_Sandstone_Brick",
      "rotation": 13
    },
    {
      "x": -45,
      "y": 3,
      "z": -1,
      "name": "Wood_Drywood_Planks",
      "rotation": 13
    },
    {
      "x": -45,
      "y": 1,
      "z": 0,
      "name": "Rock_Sandstone_Brick",
      "rotation": 16
    },
    {
      "x": -45,
      "y": 2,
      "z": 0,
      "name": "Rock_Sandstone_Brick",
      "rotation": 13
    },
    {
      "x": -45,
      "y": 3,
      "z": 0,
      "name": "Wood_Drywood_Planks",
      "rotation": 13
    },
    {
      "x": -45,
      "y": 1,
      "z": 1,
      "name": "Rock_Sandstone_Brick",
      "rotation": 16
    },
    {
      "x": -45,
      "y": 2,
      "z": 1,
      "name": "Rock_Sandstone_Brick",
      "rotation": 13
    },
    {
      "x": -45,
      "y": 3,
      "z": 1,
      "name": "Wood_Drywood_Planks",
      "rotation": 13
    },
    {
      "x": -45,
      "y": 1,
      "z": 2,
      "name": "Rock_Sandstone_Brick",
      "rotation": 16
    },
    {
      "x": -45,
      "y": 2,
      "z": 2,
      "name": "Rock_Sandstone_Brick",
      "rotation": 13
    },
    {
      "x": -45,
      "y": 3,
      "z": 2,
      "name": "Wood_Drywood_Planks",
      "rotation": 13
    },
    {
      "x": -45,
      "y": 1,
      "z": 3,
      "name": "Rock_Sandstone_Brick",
      "rotation": 16
    },
    {
      "x": -45,
      "y": 2,
      "z": 3,
      "name": "Rock_Sandstone_Brick",
      "rotation": 13
    },
    {
      "x": -45,
      "y": 3,
      "z": 3,
      "name": "Wood_Drywood_Planks",
      "rotation": 13
    },
    {
      "x": -45,
      "y": 1,
      "z": 4,
      "name": "Rock_Sandstone_Brick",
      "rotation": 16
    },
    {
      "x": -45,
      "y": 2,
      "z": 4,
      "name": "Rock_Sandstone_Brick",
      "rotation": 16
    },
    {
      "x": -45,
      "y": 3,
      "z": 4,
      "name": "Rock_Sandstone_Brick",
      "rotation": 16
    },
    {
      "x": -45,
      "y": 4,
      "z": 4,
      "name": "Wood_Drywood_Planks",
      "rotation": 13
    },
    {
      "x": -45,
      "y": 1,
      "z": 5,
      "name": "Rock_Sandstone_Brick",
      "rotation": 16
    },
    {
      "x": -45,
      "y": 2,
      "z": 5,
      "name": "Rock_Sandstone_Brick",
      "rotation": 16
    },
    {
      "x": -45,
      "y": 3,
      "z": 5,
      "name": "Rock_Sandstone_Brick",
      "rotation": 13
    },
    {
      "x": -45,
      "y": 4,
      "z": 5,
      "name": "Wood_Drywood_Planks",
      "rotation": 13
    },
    {
      "x": -45,
      "y": 5,
      "z": 5,
      "name": "Wood_Drywood_Planks",
      "rotation": 13
    },
    {
      "x": -45,
      "y": 6,
      "z": 5,
      "name": "*Furniture_Temple_Dark_Candle_State_Definitions_Off",
      "rotation": 13
    },
    {
      "x": -45,
      "y": 1,
      "z": 6,
      "name": "Rock_Sandstone_Brick",
      "rotation": 16
    },
    {
      "x": -45,
      "y": 2,
      "z": 6,
      "name": "Rock_Sandstone_Brick",
      "rotation": 16
    },
    {
      "x": -45,
      "y": 3,
      "z": 6,
      "name": "Rock_Sandstone_Brick",
      "rotation": 16
    },
    {
      "x": -45,
      "y": 4,
      "z": 6,
      "name": "Rock_Sandstone_Brick",
      "rotation": 16
    },
    {
      "x": -45,
      "y": 5,
      "z": 6,
      "name": "Wood_Drywood_Planks",
      "rotation": 13
    },
    {
      "x": -45,
      "y": 6,
      "z": 6,
      "name": "Wood_Drywood_Planks",
      "rotation": 13
    },
    {
      "x": -45,
      "y": 1,
      "z": 7,
      "name": "Rock_Sandstone_Brick",
      "rotation": 16
    },
    {
      "x": -45,
      "y": 2,
      "z": 7,
      "name": "Rock_Sandstone_Brick",
      "rotation": 16
    },
    {
      "x": -45,
      "y": 3,
      "z": 7,
      "name": "Rock_Sandstone_Brick",
      "rotation": 16
    },
    {
      "x": -45,
      "y": 4,
      "z": 7,
      "name": "Rock_Sandstone_Brick",
      "rotation": 13
    },
    {
      "x": -45,
      "y": 5,
      "z": 7,
      "name": "Rock_Sandstone_Brick",
      "rotation": 16
    },
    {
      "x": -45,
      "y": 6,
      "z": 7,
      "name": "Rock_Sandstone_Brick",
      "rotation": 16
    },
    {
      "x": -45,
      "y": 1,
      "z": 8,
      "name": "Rock_Sandstone_Brick",
      "rotation": 7
    },
    {
      "x": -45,
      "y": 2,
      "z": 8,
      "name": "Rock_Sandstone_Brick",
      "rotation": 7
    },
    {
      "x": -45,
      "y": 3,
      "z": 8,
      "name": "Rock_Sandstone_Brick",
      "rotation": 7
    },
    {
      "x": -45,
      "y": 1,
      "z": 9,
      "name": "Rock_Sandstone_Brick",
      "rotation": 7
    },
    {
      "x": -45,
      "y": 2,
      "z": 9,
      "name": "Rock_Sandstone_Brick",
      "rotation": 7
    },
    {
      "x": -45,
      "y": 3,
      "z": 9,
      "name": "Rock_Sandstone_Brick",
      "rotation": 7
    },
    {
      "x": -44,
      "y": 5,
      "z": -8,
      "name": "Rock_Sandstone_Brick",
      "rotation": 7
    },
    {
      "x": -44,
      "y": 6,
      "z": -8,
      "name": "Rock_Sandstone_Brick",
      "rotation": 7
    },
    {
      "x": -44,
      "y": 5,
      "z": -7,
      "name": "Rock_Sandstone_Brick",
      "rotation": 7
    },
    {
      "x": -44,
      "y": 6,
      "z": -7,
      "name": "Rock_Sandstone_Brick",
      "rotation": 7
    },
    {
      "x": -44,
      "y": 5,
      "z": -6,
      "name": "Rock_Sandstone_Cobble",
      "rotation": 16
    },
    {
      "x": -44,
      "y": 6,
      "z": -6,
      "name": "Rock_Sandstone_Cobble",
      "rotation": 16
    },
    {
      "x": -44,
      "y": 3,
      "z": -5,
      "name": "Rock_Sandstone_Cobble",
      "rotation": 16
    },
    {
      "x": -44,
      "y": 4,
      "z": -5,
      "name": "Rock_Sandstone_Cobble",
      "rotation": 16
    },
    {
      "x": -44,
      "y": 5,
      "z": -5,
      "name": "Rock_Sandstone_Cobble",
      "rotation": 16
    },
    {
      "x": -44,
      "y": 6,
      "z": -5,
      "name": "Rock_Sandstone_Cobble",
      "rotation": 16
    },
    {
      "x": -44,
      "y": 1,
      "z": -4,
      "name": "Rock_Sandstone_Cobble",
      "rotation": 16
    },
    {
      "x": -44,
      "y": 2,
      "z": -4,
      "name": "Rock_Sandstone_Cobble",
      "rotation": 16
    },
    {
      "x": -44,
      "y": 3,
      "z": -4,
      "name": "Rock_Sandstone_Cobble",
      "rotation": 16
    },
    {
      "x": -44,
      "y": 4,
      "z": -4,
      "name": "Rock_Sandstone_Cobble",
      "rotation": 16
    },
    {
      "x": -44,
      "y": 5,
      "z": -4,
      "name": "Rock_Sandstone_Cobble",
      "rotation": 16
    },
    {
      "x": -44,
      "y": 6,
      "z": -4,
      "name": "Rock_Sandstone_Cobble",
      "rotation": 16
    },
    {
      "x": -44,
      "y": 1,
      "z": -3,
      "name": "Rock_Sandstone_Cobble",
      "rotation": 16
    },
    {
      "x": -44,
      "y": 2,
      "z": -3,
      "name": "Rock_Sandstone_Cobble",
      "rotation": 16
    },
    {
      "x": -44,
      "y": 3,
      "z": -3,
      "name": "Rock_Sandstone_Cobble_Half",
      "rotation": 18
    },
    {
      "x": -44,
      "y": 4,
      "z": -3,
      "name": "Rock_Sandstone_Cobble",
      "rotation": 16
    },
    {
      "x": -44,
      "y": 5,
      "z": -3,
      "name": "Rock_Sandstone_Cobble",
      "rotation": 16
    },
    {
      "x": -44,
      "y": 6,
      "z": -3,
      "name": "Rock_Sandstone_Cobble_Half",
      "rotation": 18
    },
    {
      "x": -44,
      "y": 1,
      "z": -2,
      "name": "Rock_Sandstone_Cobble",
      "rotation": 16
    },
    {
      "x": -44,
      "y": 2,
      "z": -2,
      "name": "Rock_Sandstone_Cobble",
      "rotation": 16
    },
    {
      "x": -44,
      "y": 3,
      "z": -2,
      "name": "Rock_Sandstone_Cobble",
      "rotation": 16
    },
    {
      "x": -44,
      "y": 4,
      "z": -2,
      "name": "Rock_Sandstone_Cobble",
      "rotation": 16
    },
    {
      "x": -44,
      "y": 1,
      "z": -1,
      "name": "Rock_Sandstone_Cobble",
      "rotation": 16
    },
    {
      "x": -44,
      "y": 2,
      "z": -1,
      "name": "Rock_Sandstone_Cobble",
      "rotation": 16
    },
    {
      "x": -44,
      "y": 3,
      "z": -1,
      "name": "Rock_Sandstone_Cobble",
      "rotation": 16
    },
    {
      "x": -44,
      "y": 4,
      "z": -1,
      "name": "Rock_Sandstone_Cobble",
      "rotation": 16
    },
    {
      "x": -44,
      "y": 1,
      "z": 0,
      "name": "Rock_Sandstone_Cobble",
      "rotation": 16
    },
    {
      "x": -44,
      "y": 2,
      "z": 0,
      "name": "Rock_Sandstone_Cobble",
      "rotation": 16
    },
    {
      "x": -44,
      "y": 3,
      "z": 0,
      "name": "Rock_Sandstone_Cobble",
      "rotation": 16
    },
    {
      "x": -44,
      "y": 4,
      "z": 0,
      "name": "Rock_Sandstone_Cobble",
      "rotation": 16
    },
    {
      "x": -44,
      "y": 1,
      "z": 1,
      "name": "Rock_Sandstone_Cobble",
      "rotation": 16
    },
    {
      "x": -44,
      "y": 2,
      "z": 1,
      "name": "Rock_Sandstone_Cobble",
      "rotation": 7
    },
    {
      "x": -44,
      "y": 3,
      "z": 1,
      "name": "Rock_Sandstone_Cobble",
      "rotation": 16
    },
    {
      "x": -44,
      "y": 4,
      "z": 1,
      "name": "Rock_Sandstone_Cobble",
      "rotation": 16
    },
    {
      "x": -44,
      "y": 1,
      "z": 2,
      "name": "Rock_Sandstone_Cobble",
      "rotation": 7
    },
    {
      "x": -44,
      "y": 2,
      "z": 2,
      "name": "Rock_Sandstone_Cobble",
      "rotation": 7
    },
    {
      "x": -44,
      "y": 3,
      "z": 2,
      "name": "Rock_Sandstone_Cobble",
      "rotation": 7
    },
    {
      "x": -44,
      "y": 4,
      "z": 2,
      "name": "Rock_Sandstone_Cobble_Half",
      "rotation": 15
    },
    {
      "x": -44,
      "y": 1,
      "z": 3,
      "name": "Rock_Sandstone_Cobble",
      "rotation": 7
    },
    {
      "x": -44,
      "y": 2,
      "z": 3,
      "name": "Rock_Sandstone_Cobble",
      "rotation": 7
    },
    {
      "x": -44,
      "y": 3,
      "z": 3,
      "name": "Rock_Sandstone_Cobble",
      "rotation": 7
    },
    {
      "x": -44,
      "y": 4,
      "z": 3,
      "name": "Rock_Sandstone_Cobble",
      "rotation": 16
    },
    {
      "x": -44,
      "y": 1,
      "z": 4,
      "name": "Rock_Sandstone_Cobble",
      "rotation": 7
    },
    {
      "x": -44,
      "y": 2,
      "z": 4,
      "name": "Rock_Sandstone_Cobble",
      "rotation": 7
    },
    {
      "x": -44,
      "y": 3,
      "z": 4,
      "name": "Rock_Sandstone_Cobble",
      "rotation": 7
    },
    {
      "x": -44,
      "y": 4,
      "z": 4,
      "name": "Rock_Sandstone_Cobble",
      "rotation": 7
    },
    {
      "x": -44,
      "y": 5,
      "z": 4,
      "name": "Rock_Sandstone_Cobble_Half",
      "rotation": 49
    },
    {
      "x": -44,
      "y": 6,
      "z": 4,
      "name": "Rock_Sandstone_Cobble",
      "rotation": 7
    },
    {
      "x": -44,
      "y": 1,
      "z": 5,
      "name": "Rock_Sandstone",
      "rotation": 7
    },
    {
      "x": -44,
      "y": 2,
      "z": 5,
      "name": "Rock_Sandstone",
      "rotation": 7
    },
    {
      "x": -44,
      "y": 3,
      "z": 5,
      "name": "Rock_Sandstone_Cobble",
      "rotation": 7
    },
    {
      "x": -44,
      "y": 4,
      "z": 5,
      "name": "Rock_Sandstone_Cobble",
      "rotation": 7
    },
    {
      "x": -44,
      "y": 5,
      "z": 5,
      "name": "Rock_Sandstone_Cobble",
      "rotation": 7
    },
    {
      "x": -44,
      "y": 6,
      "z": 5,
      "name": "Rock_Sandstone_Cobble",
      "rotation": 7
    },
    {
      "x": -44,
      "y": 1,
      "z": 6,
      "name": "Rock_Sandstone",
      "rotation": 7
    },
    {
      "x": -44,
      "y": 2,
      "z": 6,
      "name": "Rock_Sandstone",
      "rotation": 7
    },
    {
      "x": -44,
      "y": 3,
      "z": 6,
      "name": "Rock_Sandstone",
      "rotation": 7
    },
    {
      "x": -44,
      "y": 4,
      "z": 6,
      "name": "Rock_Sandstone_Cobble",
      "rotation": 7
    },
    {
      "x": -44,
      "y": 5,
      "z": 6,
      "name": "Rock_Sandstone_Cobble",
      "rotation": 7
    },
    {
      "x": -44,
      "y": 6,
      "z": 6,
      "name": "Rock_Sandstone_Cobble",
      "rotation": 7
    },
    {
      "x": -44,
      "y": 1,
      "z": 7,
      "name": "Rock_Sandstone",
      "rotation": 7
    },
    {
      "x": -44,
      "y": 2,
      "z": 7,
      "name": "Rock_Sandstone",
      "rotation": 7
    },
    {
      "x": -44,
      "y": 3,
      "z": 7,
      "name": "Rock_Sandstone",
      "rotation": 7
    },
    {
      "x": -44,
      "y": 4,
      "z": 7,
      "name": "Rock_Sandstone",
      "rotation": 7
    },
    {
      "x": -44,
      "y": 5,
      "z": 7,
      "name": "Rock_Sandstone_Cobble",
      "rotation": 7
    },
    {
      "x": -44,
      "y": 6,
      "z": 7,
      "name": "Rock_Sandstone_Cobble",
      "rotation": 7
    },
    {
      "x": -44,
      "y": 1,
      "z": 8,
      "name": "Rock_Sandstone_Brick",
      "rotation": 7
    },
    {
      "x": -44,
      "y": 2,
      "z": 8,
      "name": "Rock_Sandstone_Brick",
      "rotation": 7
    },
    {
      "x": -44,
      "y": 3,
      "z": 8,
      "name": "Rock_Sandstone_Brick",
      "rotation": 7
    },
    {
      "x": -44,
      "y": 4,
      "z": 8,
      "name": "Rock_Sandstone_Brick",
      "rotation": 7
    },
    {
      "x": -44,
      "y": 5,
      "z": 8,
      "name": "Rock_Sandstone_Brick",
      "rotation": 7
    },
    {
      "x": -44,
      "y": 1,
      "z": 9,
      "name": "Rock_Sandstone_Brick",
      "rotation": 7
    },
    {
      "x": -44,
      "y": 2,
      "z": 9,
      "name": "Rock_Sandstone_Brick",
      "rotation": 7
    },
    {
      "x": -44,
      "y": 3,
      "z": 9,
      "name": "Rock_Sandstone_Brick",
      "rotation": 7
    },
    {
      "x": -44,
      "y": 4,
      "z": 9,
      "name": "Rock_Sandstone_Brick",
      "rotation": 7
    },
    {
      "x": -43,
      "y": 5,
      "z": -8,
      "name": "Rock_Sandstone_Brick_Stairs",
      "rotation": 18
    },
    {
      "x": -43,
      "y": 6,
      "z": -8,
      "name": "Rock_Sandstone_Brick_Stairs",
      "rotation": 18
    },
    {
      "x": -43,
      "y": 5,
      "z": -7,
      "name": "Rock_Sandstone_Cobble",
      "rotation": 7
    },
    {
      "x": -43,
      "y": 6,
      "z": -7,
      "name": "Rock_Sandstone_Cobble",
      "rotation": 7
    },
    {
      "x": -43,
      "y": 2,
      "z": -6,
      "name": "Rock_Sandstone_Red_Brick",
      "rotation": 16
    },
    {
      "x": -43,
      "y": 3,
      "z": -6,
      "name": "Rock_Sandstone_Red_Cobble",
      "rotation": 16
    },
    {
      "x": -43,
      "y": 4,
      "z": -6,
      "name": "Rock_Sandstone_Red_Cobble",
      "rotation": 16
    },
    {
      "x": -43,
      "y": 5,
      "z": -6,
      "name": "Rock_Sandstone_Red_Cobble",
      "rotation": 7
    },
    {
      "x": -43,
      "y": 6,
      "z": -6,
      "name": "Rock_Sandstone_Red_Cobble",
      "rotation": 7
    },
    {
      "x": -43,
      "y": 1,
      "z": -5,
      "name": "Rock_Sandstone_Red_Brick",
      "rotation": 16
    },
    {
      "x": -43,
      "y": 1,
      "z": -4,
      "name": "Rock_Sandstone_Red_Brick",
      "rotation": 16
    },
    {
      "x": -43,
      "y": 1,
      "z": -3,
      "name": "Rock_Sandstone_Red_Brick",
      "rotation": 16
    },
    {
      "x": -43,
      "y": 1,
      "z": -2,
      "name": "Rock_Sandstone_Red_Brick",
      "rotation": 16
    },
    {
      "x": -43,
      "y": 1,
      "z": -1,
      "name": "Rock_Sandstone_Red_Brick",
      "rotation": 7
    },
    {
      "x": -43,
      "y": 0,
      "z": 0,
      "name": "Rock_Sandstone_Red_Brick"
    },
    {
      "x": -43,
      "y": 1,
      "z": 0,
      "name": "Rock_Sandstone_Red_Brick",
      "rotation": 7
    },
    {
      "x": -43,
      "y": 0,
      "z": 1,
      "name": "Rock_Sandstone_Red_Brick"
    },
    {
      "x": -43,
      "y": 1,
      "z": 1,
      "name": "Rock_Sandstone_Red_Brick",
      "rotation": 7
    },
    {
      "x": -43,
      "y": 0,
      "z": 2,
      "name": "Rock_Sandstone_Red_Brick"
    },
    {
      "x": -43,
      "y": 1,
      "z": 2,
      "name": "Rock_Sandstone_Red_Brick",
      "rotation": 7
    },
    {
      "x": -43,
      "y": 0,
      "z": 3,
      "name": "Rock_Sandstone_Red_Brick"
    },
    {
      "x": -43,
      "y": 1,
      "z": 3,
      "name": "Soil_Sand"
    },
    {
      "x": -43,
      "y": 0,
      "z": 4,
      "name": "Rock_Sandstone_Red_Brick"
    },
    {
      "x": -43,
      "y": 1,
      "z": 4,
      "name": "Rock_Sandstone_Red_Brick",
      "rotation": 7
    },
    {
      "x": -43,
      "y": 2,
      "z": 4,
      "name": "Rock_Sandstone_Cobble_Half",
      "rotation": 15
    },
    {
      "x": -43,
      "y": 0,
      "z": 5,
      "name": "Rock_Sandstone_Red_Brick"
    },
    {
      "x": -43,
      "y": 1,
      "z": 5,
      "name": "Rock_Sandstone_Red_Brick",
      "rotation": 7
    },
    {
      "x": -43,
      "y": 2,
      "z": 5,
      "name": "Rock_Sandstone_Cobble_Half",
      "rotation": 15
    },
    {
      "x": -43,
      "y": 3,
      "z": 5,
      "name": "Rock_Sandstone_Cobble_Half",
      "rotation": 15
    },
    {
      "x": -43,
      "y": 0,
      "z": 6,
      "name": "Rock_Sandstone_Red_Brick"
    },
    {
      "x": -43,
      "y": 1,
      "z": 6,
      "name": "Rock_Sandstone_Red_Brick",
      "rotation": 7
    },
    {
      "x": -43,
      "y": 2,
      "z": 6,
      "name": "Rock_Sandstone_Cobble_Half",
      "rotation": 15
    },
    {
      "x": -43,
      "y": 3,
      "z": 6,
      "name": "Rock_Sandstone_Cobble_Half",
      "rotation": 15
    },
    {
      "x": -43,
      "y": 4,
      "z": 6,
      "name": "Rock_Sandstone_Cobble_Half",
      "rotation": 15
    },
    {
      "x": -43,
      "y": 5,
      "z": 6,
      "name": "Rock_Sandstone_Cobble_Half",
      "rotation": 15
    },
    {
      "x": -43,
      "y": 0,
      "z": 7,
      "name": "Rock_Sandstone_Red_Brick"
    },
    {
      "x": -43,
      "y": 1,
      "z": 7,
      "name": "Rock_Sandstone_Red_Brick",
      "rotation": 7
    },
    {
      "x": -43,
      "y": 2,
      "z": 7,
      "name": "Rock_Sandstone_Red_Brick",
      "rotation": 7
    },
    {
      "x": -43,
      "y": 3,
      "z": 7,
      "name": "Rock_Sandstone_Red_Cobble",
      "rotation": 7
    },
    {
      "x": -43,
      "y": 4,
      "z": 7,
      "name": "Rock_Sandstone_Red_Cobble",
      "rotation": 7
    },
    {
      "x": -43,
      "y": 5,
      "z": 7,
      "name": "Rock_Sandstone_Red_Cobble",
      "rotation": 7
    },
    {
      "x": -43,
      "y": 6,
      "z": 7,
      "name": "Rock_Sandstone_Red_Brick",
      "rotation": 7
    },
    {
      "x": -43,
      "y": 0,
      "z": 8,
      "name": "Rock_Sandstone_Red_Brick"
    },
    {
      "x": -43,
      "y": 1,
      "z": 8,
      "name": "Rock_Sandstone_Brick",
      "rotation": 7
    },
    {
      "x": -43,
      "y": 2,
      "z": 8,
      "name": "Rock_Sandstone_Cobble",
      "rotation": 7
    },
    {
      "x": -43,
      "y": 3,
      "z": 8,
      "name": "Rock_Sandstone_Cobble",
      "rotation": 7
    },
    {
      "x": -43,
      "y": 4,
      "z": 8,
      "name": "Rock_Sandstone_Cobble",
      "rotation": 7
    },
    {
      "x": -43,
      "y": 5,
      "z": 8,
      "name": "Rock_Sandstone_Cobble",
      "rotation": 7
    },
    {
      "x": -43,
      "y": 1,
      "z": 9,
      "name": "Rock_Sandstone_Brick_Stairs",
      "rotation": 48
    },
    {
      "x": -43,
      "y": 2,
      "z": 9,
      "name": "Rock_Sandstone_Brick_Stairs",
      "rotation": 48
    },
    {
      "x": -43,
      "y": 3,
      "z": 9,
      "name": "Rock_Sandstone_Brick_Stairs",
      "rotation": 48
    },
    {
      "x": -43,
      "y": 4,
      "z": 9,
      "name": "Rock_Sandstone_Brick_Stairs",
      "rotation": 48
    },
    {
      "x": -43,
      "y": 5,
      "z": 9,
      "name": "Rock_Sandstone_Brick_Stairs",
      "rotation": 48
    },
    {
      "x": -42,
      "y": 2,
      "z": -7,
      "name": "Rock_Sandstone_Cobble",
      "rotation": 16
    },
    {
      "x": -42,
      "y": 3,
      "z": -7,
      "name": "Rock_Sandstone_Cobble",
      "rotation": 16
    },
    {
      "x": -42,
      "y": 4,
      "z": -7,
      "name": "Rock_Sandstone_Cobble",
      "rotation": 16
    },
    {
      "x": -42,
      "y": 5,
      "z": -7,
      "name": "Rock_Sandstone_Cobble",
      "rotation": 7
    },
    {
      "x": -42,
      "y": 6,
      "z": -7,
      "name": "Rock_Sandstone_Cobble",
      "rotation": 7
    },
    {
      "x": -42,
      "y": 1,
      "z": -6,
      "name": "Rock_Sandstone_Red_Brick",
      "rotation": 16
    },
    {
      "x": -42,
      "y": 2,
      "z": -6,
      "name": "Rock_Sandstone_Red_Brick",
      "rotation": 16
    },
    {
      "x": -42,
      "y": 3,
      "z": -6,
      "name": "Rock_Sandstone_Red_Brick",
      "rotation": 16
    },
    {
      "x": -42,
      "y": 4,
      "z": -6,
      "name": "Rock_Sandstone_Red_Cobble",
      "rotation": 16
    },
    {
      "x": -42,
      "y": 5,
      "z": -6,
      "name": "Rock_Sandstone_Red_Cobble",
      "rotation": 16
    },
    {
      "x": -42,
      "y": 6,
      "z": -6,
      "name": "Rock_Sandstone_Red_Cobble",
      "rotation": 7
    },
    {
      "x": -42,
      "y": 1,
      "z": -5,
      "name": "Rock_Sandstone_Red_Brick",
      "rotation": 16
    },
    {
      "x": -42,
      "y": 1,
      "z": -4,
      "name": "Rock_Sandstone_Red_Brick",
      "rotation": 16
    },
    {
      "x": -42,
      "y": 1,
      "z": -3,
      "name": "Rock_Sandstone_Red_Brick",
      "rotation": 16
    },
    {
      "x": -42,
      "y": 1,
      "z": -2,
      "name": "Rock_Sandstone_Red_Brick",
      "rotation": 16
    },
    {
      "x": -42,
      "y": 1,
      "z": -1,
      "name": "Rock_Sandstone_Red_Brick",
      "rotation": 16
    },
    {
      "x": -42,
      "y": 0,
      "z": 0,
      "name": "Rock_Sandstone_Red_Brick"
    },
    {
      "x": -42,
      "y": 1,
      "z": 0,
      "name": "Rock_Sandstone_Red_Cobble",
      "rotation": 7
    },
    {
      "x": -42,
      "y": 0,
      "z": 1,
      "name": "Rock_Sandstone_Red_Brick"
    },
    {
      "x": -42,
      "y": 1,
      "z": 1,
      "name": "Soil_Sand"
    },
    {
      "x": -42,
      "y": 0,
      "z": 2,
      "name": "Rock_Sandstone_Red_Brick"
    },
    {
      "x": -42,
      "y": 1,
      "z": 2,
      "name": "Rock_Sandstone_Red_Brick",
      "rotation": 7
    },
    {
      "x": -42,
      "y": 0,
      "z": 3,
      "name": "Rock_Sandstone_Red_Brick"
    },
    {
      "x": -42,
      "y": 1,
      "z": 3,
      "name": "Rock_Sandstone_Red_Brick",
      "rotation": 7
    },
    {
      "x": -42,
      "y": 0,
      "z": 4,
      "name": "Rock_Sandstone_Red_Brick"
    },
    {
      "x": -42,
      "y": 1,
      "z": 4,
      "name": "Rock_Sandstone_Red_Brick",
      "rotation": 7
    },
    {
      "x": -42,
      "y": 0,
      "z": 5,
      "name": "Rock_Sandstone_Red_Brick"
    },
    {
      "x": -42,
      "y": 1,
      "z": 5,
      "name": "Soil_Sand"
    },
    {
      "x": -42,
      "y": 0,
      "z": 6,
      "name": "Rock_Sandstone_Red_Brick"
    },
    {
      "x": -42,
      "y": 1,
      "z": 6,
      "name": "Rock_Sandstone_Red_Brick",
      "rotation": 7
    },
    {
      "x": -42,
      "y": 2,
      "z": 6,
      "name": "*Furniture_Temple_Dark_Candle_State_Definitions_Off"
    },
    {
      "x": -42,
      "y": 3,
      "z": 6,
      "name": "*Furniture_Temple_Dark_Candle_State_Definitions_Off",
      "filler": 1024
    },
    {
      "x": -42,
      "y": 0,
      "z": 7,
      "name": "Rock_Sandstone_Red_Brick"
    },
    {
      "x": -42,
      "y": 1,
      "z": 7,
      "name": "Rock_Sandstone_Red_Brick",
      "rotation": 7
    },
    {
      "x": -42,
      "y": 5,
      "z": 7,
      "name": "Rock_Sandstone_Red_Cobble",
      "rotation": 7
    },
    {
      "x": -42,
      "y": 6,
      "z": 7,
      "name": "Rock_Sandstone_Red_Cobble",
      "rotation": 7
    },
    {
      "x": -42,
      "y": 0,
      "z": 8,
      "name": "Rock_Sandstone_Red_Brick"
    },
    {
      "x": -42,
      "y": 1,
      "z": 8,
      "name": "Rock_Sandstone_Brick",
      "rotation": 7
    },
    {
      "x": -42,
      "y": 2,
      "z": 8,
      "name": "Rock_Sandstone_Brick_Half"
    },
    {
      "x": -42,
      "y": 4,
      "z": 8,
      "name": "Rock_Sandstone_Cobble_Half",
      "rotation": 5
    },
    {
      "x": -42,
      "y": 5,
      "z": 8,
      "name": "Rock_Sandstone_Cobble",
      "rotation": 7
    },
    {
      "x": -42,
      "y": 6,
      "z": 8,
      "name": "Rock_Sandstone_Cobble",
      "rotation": 7
    },
    {
      "x": -42,
      "y": 1,
      "z": 9,
      "name": "Rock_Sandstone_Brick_Half",
      "rotation": 4
    },
    {
      "x": -41,
      "y": 1,
      "z": -7,
      "name": "Rock_Sandstone_Cobble",
      "rotation": 16
    },
    {
      "x": -41,
      "y": 2,
      "z": -7,
      "name": "Rock_Sandstone_Cobble",
      "rotation": 7
    },
    {
      "x": -41,
      "y": 3,
      "z": -7,
      "name": "Rock_Sandstone_Cobble",
      "rotation": 7
    },
    {
      "x": -41,
      "y": 4,
      "z": -7,
      "name": "Rock_Sandstone_Cobble",
      "rotation": 16
    },
    {
      "x": -41,
      "y": 5,
      "z": -7,
      "name": "Rock_Sandstone_Cobble",
      "rotation": 7
    },
    {
      "x": -41,
      "y": 6,
      "z": -7,
      "name": "Rock_Sandstone_Cobble",
      "rotation": 7
    },
    {
      "x": -41,
      "y": 1,
      "z": 2,
      "name": "Rock_Sandstone_Brick_Half"
    },
    {
      "x": -41,
      "y": 1,
      "z": 3,
      "name": "Rock_Sandstone_Brick_Stairs",
      "rotation": 15
    },
    {
      "x": -41,
      "y": 1,
      "z": 4,
      "name": "Rock_Sandstone_Brick_Stairs",
      "rotation": 15
    },
    {
      "x": -41,
      "y": 1,
      "z": 5,
      "name": "Rock_Sandstone_Brick_Half"
    },
    {
      "x": -41,
      "y": 1,
      "z": 6,
      "name": "Rock_Sandstone_Brick_Half"
    },
    {
      "x": -41,
      "y": 1,
      "z": 7,
      "name": "Rock_Sandstone_Brick_Stairs",
      "rotation": 15
    },
    {
      "x": -41,
      "y": 6,
      "z": 7,
      "name": "Rock_Sandstone_Brick_Stairs",
      "rotation": 18
    },
    {
      "x": -41,
      "y": 1,
      "z": 8,
      "name": "Rock_Sandstone_Cobble",
      "rotation": 7
    },
    {
      "x": -41,
      "y": 5,
      "z": 8,
      "name": "Rock_Sandstone_Cobble_Half",
      "rotation": 8
    },
    {
      "x": -41,
      "y": 6,
      "z": 8,
      "name": "Rock_Sandstone_Cobble",
      "rotation": 7
    },
    {
      "x": -40,
      "y": 1,
      "z": -7,
      "name": "Rock_Sandstone_Cobble",
      "rotation": 16
    },
    {
      "x": -40,
      "y": 2,
      "z": -7,
      "name": "Rock_Sandstone_Cobble",
      "rotation": 7
    },
    {
      "x": -40,
      "y": 3,
      "z": -7,
      "name": "Rock_Sandstone_Cobble",
      "rotation": 7
    },
    {
      "x": -40,
      "y": 4,
      "z": -7,
      "name": "Rock_Sandstone_Cobble",
      "rotation": 7
    },
    {
      "x": -40,
      "y": 5,
      "z": -7,
      "name": "Rock_Sandstone_Cobble",
      "rotation": 7
    },
    {
      "x": -40,
      "y": 6,
      "z": -7,
      "name": "Rock_Sandstone_Cobble",
      "rotation": 7
    },
    {
      "x": -40,
      "y": 1,
      "z": 8,
      "name": "Rock_Sandstone_Cobble",
      "rotation": 7
    },
    {
      "x": -40,
      "y": 2,
      "z": 8,
      "name": "Rock_Sandstone_Cobble_Half",
      "rotation": 7
    },
    {
      "x": -40,
      "y": 4,
      "z": 8,
      "name": "Rock_Sandstone_Cobble_Half",
      "rotation": 7
    },
    {
      "x": -40,
      "y": 5,
      "z": 8,
      "name": "Rock_Sandstone_Cobble",
      "rotation": 7
    },
    {
      "x": -40,
      "y": 6,
      "z": 8,
      "name": "Rock_Sandstone_Cobble",
      "rotation": 7
    },
    {
      "x": -39,
      "y": 1,
      "z": -8,
      "name": "Rock_Sandstone_Brick_Stairs",
      "rotation": 50
    },
    {
      "x": -39,
      "y": 2,
      "z": -8,
      "name": "Rock_Sandstone_Brick_Stairs",
      "rotation": 50
    },
    {
      "x": -39,
      "y": 3,
      "z": -8,
      "name": "Rock_Sandstone_Brick_Stairs",
      "rotation": 50
    },
    {
      "x": -39,
      "y": 4,
      "z": -8,
      "name": "Rock_Sandstone_Brick_Stairs",
      "rotation": 50
    },
    {
      "x": -39,
      "y": 5,
      "z": -8,
      "name": "Rock_Sandstone_Brick_Stairs",
      "rotation": 50
    },
    {
      "x": -39,
      "y": 6,
      "z": -8,
      "name": "Rock_Sandstone_Brick_Stairs",
      "rotation": 50
    },
    {
      "x": -39,
      "y": 1,
      "z": -7,
      "name": "Rock_Sandstone_Cobble",
      "rotation": 7
    },
    {
      "x": -39,
      "y": 2,
      "z": -7,
      "name": "Rock_Sandstone_Cobble",
      "rotation": 7
    },
    {
      "x": -39,
      "y": 3,
      "z": -7,
      "name": "Rock_Sandstone_Cobble",
      "rotation": 7
    },
    {
      "x": -39,
      "y": 4,
      "z": -7,
      "name": "Rock_Sandstone_Cobble",
      "rotation": 7
    },
    {
      "x": -39,
      "y": 5,
      "z": -7,
      "name": "Rock_Sandstone_Cobble",
      "rotation": 7
    },
    {
      "x": -39,
      "y": 6,
      "z": -7,
      "name": "Rock_Sandstone_Cobble",
      "rotation": 7
    },
    {
      "x": -39,
      "y": 1,
      "z": -6,
      "name": "Rubble_Sandstone",
      "support": 15,
      "rotation": 16
    },
    {
      "x": -39,
      "y": 1,
      "z": 8,
      "name": "Rock_Sandstone_Cobble",
      "rotation": 7
    },
    {
      "x": -39,
      "y": 2,
      "z": 8,
      "name": "Rock_Sandstone_Cobble",
      "rotation": 7
    },
    {
      "x": -39,
      "y": 3,
      "z": 8,
      "name": "Rock_Sandstone_Cobble",
      "rotation": 7
    },
    {
      "x": -39,
      "y": 4,
      "z": 8,
      "name": "Rock_Sandstone_Cobble",
      "rotation": 7
    },
    {
      "x": -39,
      "y": 5,
      "z": 8,
      "name": "Rock_Sandstone_Cobble",
      "rotation": 7
    },
    {
      "x": -39,
      "y": 6,
      "z": 8,
      "name": "Rock_Sandstone_Cobble",
      "rotation": 7
    },
    {
      "x": -39,
      "y": 1,
      "z": 9,
      "name": "Rock_Sandstone_Brick_Stairs",
      "rotation": 16
    },
    {
      "x": -39,
      "y": 2,
      "z": 9,
      "name": "Rock_Sandstone_Brick_Stairs",
      "rotation": 16
    },
    {
      "x": -39,
      "y": 3,
      "z": 9,
      "name": "Rock_Sandstone_Brick_Stairs",
      "rotation": 16
    },
    {
      "x": -39,
      "y": 4,
      "z": 9,
      "name": "Rock_Sandstone_Brick_Stairs",
      "rotation": 16
    },
    {
      "x": -39,
      "y": 5,
      "z": 9,
      "name": "Rock_Sandstone_Brick_Stairs",
      "rotation": 16
    },
    {
      "x": -39,
      "y": 6,
      "z": 9,
      "name": "Rock_Sandstone_Brick_Stairs",
      "rotation": 16
    },
    {
      "x": -38,
      "y": 1,
      "z": -8,
      "name": "Rock_Sandstone_Brick_Ornate",
      "rotation": 7
    },
    {
      "x": -38,
      "y": 2,
      "z": -8,
      "name": "Rock_Sandstone_Brick_Ornate",
      "rotation": 7
    },
    {
      "x": -38,
      "y": 3,
      "z": -8,
      "name": "Rock_Sandstone_Brick_Ornate",
      "rotation": 7
    },
    {
      "x": -38,
      "y": 4,
      "z": -8,
      "name": "Rock_Sandstone_Brick_Ornate",
      "rotation": 7
    },
    {
      "x": -38,
      "y": 5,
      "z": -8,
      "name": "Rock_Sandstone_Brick_Ornate",
      "rotation": 7
    },
    {
      "x": -38,
      "y": 6,
      "z": -8,
      "name": "Rock_Sandstone_Brick_Ornate",
      "rotation": 7
    },
    {
      "x": -38,
      "y": 1,
      "z": -7,
      "name": "Rock_Sandstone_Brick",
      "rotation": 7
    },
    {
      "x": -38,
      "y": 2,
      "z": -7,
      "name": "Rock_Sandstone_Brick",
      "rotation": 7
    },
    {
      "x": -38,
      "y": 3,
      "z": -7,
      "name": "Rock_Sandstone_Brick",
      "rotation": 7
    },
    {
      "x": -38,
      "y": 4,
      "z": -7,
      "name": "Rock_Sandstone_Brick",
      "rotation": 7
    },
    {
      "x": -38,
      "y": 5,
      "z": -7,
      "name": "Rock_Sandstone_Brick",
      "rotation": 7
    },
    {
      "x": -38,
      "y": 6,
      "z": -7,
      "name": "Rock_Sandstone_Brick",
      "rotation": 7
    },
    {
      "x": -38,
      "y": 1,
      "z": -6,
      "name": "Soil_Sand",
      "rotation": 7
    },
    {
      "x": -38,
      "y": 1,
      "z": 7,
      "name": "Soil_Sand",
      "rotation": 16
    },
    {
      "x": -38,
      "y": 1,
      "z": 8,
      "name": "Rock_Sandstone_Brick",
      "rotation": 7
    },
    {
      "x": -38,
      "y": 2,
      "z": 8,
      "name": "Rock_Sandstone_Brick",
      "rotation": 7
    },
    {
      "x": -38,
      "y": 3,
      "z": 8,
      "name": "Rock_Sandstone_Brick",
      "rotation": 7
    },
    {
      "x": -38,
      "y": 4,
      "z": 8,
      "name": "Rock_Sandstone_Brick",
      "rotation": 7
    },
    {
      "x": -38,
      "y": 5,
      "z": 8,
      "name": "Rock_Sandstone_Brick",
      "rotation": 7
    },
    {
      "x": -38,
      "y": 6,
      "z": 8,
      "name": "Rock_Sandstone_Brick",
      "rotation": 7
    },
    {
      "x": -38,
      "y": 1,
      "z": 9,
      "name": "Rock_Sandstone_Brick_Ornate",
      "rotation": 7
    },
    {
      "x": -38,
      "y": 2,
      "z": 9,
      "name": "Rock_Sandstone_Brick_Ornate",
      "rotation": 7
    },
    {
      "x": -38,
      "y": 3,
      "z": 9,
      "name": "Rock_Sandstone_Brick_Ornate",
      "rotation": 7
    },
    {
      "x": -38,
      "y": 4,
      "z": 9,
      "name": "Rock_Sandstone_Brick_Ornate",
      "rotation": 7
    },
    {
      "x": -38,
      "y": 5,
      "z": 9,
      "name": "Rock_Sandstone_Brick_Ornate",
      "rotation": 7
    },
    {
      "x": -38,
      "y": 6,
      "z": 9,
      "name": "Rock_Sandstone_Brick_Ornate",
      "rotation": 7
    },
    {
      "x": -37,
      "y": 3,
      "z": -9,
      "name": "Rock_Sandstone_Red_Brick_Stairs",
      "rotation": 50
    },
    {
      "x": -37,
      "y": 4,
      "z": -9,
      "name": "Rock_Sandstone_Red_Brick_Stairs",
      "rotation": 50
    },
    {
      "x": -37,
      "y": 1,
      "z": -8,
      "name": "Rock_Sandstone_Cobble",
      "rotation": 7
    },
    {
      "x": -37,
      "y": 2,
      "z": -8,
      "name": "Rock_Sandstone_Cobble",
      "rotation": 7
    },
    {
      "x": -37,
      "y": 3,
      "z": -8,
      "name": "Rock_Sandstone_Brick",
      "rotation": 7
    },
    {
      "x": -37,
      "y": 4,
      "z": -8,
      "name": "Rock_Sandstone_Brick",
      "rotation": 7
    },
    {
      "x": -37,
      "y": 5,
      "z": -8,
      "name": "Rock_Sandstone_Cobble",
      "rotation": 7
    },
    {
      "x": -37,
      "y": 6,
      "z": -8,
      "name": "Rock_Sandstone_Cobble",
      "rotation": 7
    },
    {
      "x": -37,
      "y": 1,
      "z": -7,
      "name": "Rock_Sandstone_Brick",
      "rotation": 7
    },
    {
      "x": -37,
      "y": 2,
      "z": -7,
      "name": "Rock_Sandstone_Brick",
      "rotation": 7
    },
    {
      "x": -37,
      "y": 3,
      "z": -7,
      "name": "Rock_Sandstone_Brick",
      "rotation": 7
    },
    {
      "x": -37,
      "y": 4,
      "z": -7,
      "name": "Rock_Sandstone_Brick",
      "rotation": 7
    },
    {
      "x": -37,
      "y": 5,
      "z": -7,
      "name": "Rock_Sandstone_Brick",
      "rotation": 7
    },
    {
      "x": -37,
      "y": 6,
      "z": -7,
      "name": "Rock_Sandstone_Brick",
      "rotation": 7
    },
    {
      "x": -37,
      "y": 1,
      "z": -6,
      "name": "Soil_Sand",
      "rotation": 7
    },
    {
      "x": -37,
      "y": 2,
      "z": -6,
      "name": "Soil_Sand",
      "rotation": 7
    },
    {
      "x": -37,
      "y": 3,
      "z": -6,
      "name": "Rock_Sandstone_Red_Brick_Half",
      "rotation": 17
    },
    {
      "x": -37,
      "y": 4,
      "z": -6,
      "name": "Rock_Sandstone_Red_Brick_Half",
      "rotation": 17
    },
    {
      "x": -37,
      "y": 5,
      "z": -6,
      "name": "Rock_Sandstone_Red_Brick_Half",
      "rotation": 17
    },
    {
      "x": -37,
      "y": 6,
      "z": -6,
      "name": "Rock_Sandstone_Red_Brick_Half",
      "rotation": 17
    },
    {
      "x": -37,
      "y": 1,
      "z": -5,
      "name": "Soil_Sand",
      "rotation": 7
    },
    {
      "x": -37,
      "y": 1,
      "z": -3,
      "name": "Rubble_Sandstone",
      "rotation": 7
    },
    {
      "x": -37,
      "y": 1,
      "z": 6,
      "name": "Soil_Sand",
      "rotation": 16
    },
    {
      "x": -37,
      "y": 1,
      "z": 7,
      "name": "Soil_Sand",
      "rotation": 16
    },
    {
      "x": -37,
      "y": 2,
      "z": 7,
      "name": "Rock_Sandstone_Red_Brick_Half",
      "rotation": 49
    },
    {
      "x": -37,
      "y": 3,
      "z": 7,
      "name": "Rock_Sandstone_Red_Brick_Half",
      "rotation": 49
    },
    {
      "x": -37,
      "y": 4,
      "z": 7,
      "name": "Rock_Sandstone_Red_Brick_Half",
      "rotation": 49
    },
    {
      "x": -37,
      "y": 5,
      "z": 7,
      "name": "Rock_Sandstone_Red_Brick_Half",
      "rotation": 49
    },
    {
      "x": -37,
      "y": 6,
      "z": 7,
      "name": "Rock_Sandstone_Red_Brick_Half",
      "rotation": 49
    },
    {
      "x": -37,
      "y": 1,
      "z": 8,
      "name": "Rock_Sandstone_Brick",
      "rotation": 7
    },
    {
      "x": -37,
      "y": 2,
      "z": 8,
      "name": "Rock_Sandstone_Brick",
      "rotation": 7
    },
    {
      "x": -37,
      "y": 3,
      "z": 8,
      "name": "Rock_Sandstone_Brick",
      "rotation": 7
    },
    {
      "x": -37,
      "y": 4,
      "z": 8,
      "name": "Rock_Sandstone_Brick",
      "rotation": 7
    },
    {
      "x": -37,
      "y": 5,
      "z": 8,
      "name": "Rock_Sandstone_Brick",
      "rotation": 7
    },
    {
      "x": -37,
      "y": 6,
      "z": 8,
      "name": "Rock_Sandstone_Brick",
      "rotation": 7
    },
    {
      "x": -37,
      "y": 1,
      "z": 9,
      "name": "Rock_Sandstone_Cobble",
      "rotation": 7
    },
    {
      "x": -37,
      "y": 2,
      "z": 9,
      "name": "Rock_Sandstone_Cobble",
      "rotation": 7
    },
    {
      "x": -37,
      "y": 3,
      "z": 9,
      "name": "Rock_Sandstone_Brick",
      "rotation": 7
    },
    {
      "x": -37,
      "y": 4,
      "z": 9,
      "name": "Rock_Sandstone_Brick",
      "rotation": 7
    },
    {
      "x": -37,
      "y": 5,
      "z": 9,
      "name": "Rock_Sandstone_Cobble",
      "rotation": 7
    },
    {
      "x": -37,
      "y": 6,
      "z": 9,
      "name": "Rock_Sandstone_Cobble",
      "rotation": 7
    },
    {
      "x": -37,
      "y": 3,
      "z": 10,
      "name": "Rock_Sandstone_Red_Brick_Stairs",
      "rotation": 16
    },
    {
      "x": -37,
      "y": 4,
      "z": 10,
      "name": "Rock_Sandstone_Red_Brick_Stairs",
      "rotation": 16
    },
    {
      "x": -36,
      "y": 3,
      "z": -10,
      "name": "Rock_Sandstone_Red_Brick_Stairs",
      "rotation": 50
    },
    {
      "x": -36,
      "y": 4,
      "z": -10,
      "name": "Rock_Sandstone_Red_Brick_Stairs",
      "rotation": 50
    },
    {
      "x": -36,
      "y": 3,
      "z": -9,
      "name": "Rock_Sandstone_Red_Brick",
      "rotation": 7
    },
    {
      "x": -36,
      "y": 4,
      "z": -9,
      "name": "Rock_Sandstone_Red_Brick",
      "rotation": 7
    },
    {
      "x": -36,
      "y": 1,
      "z": -8,
      "name": "Rock_Sandstone_Cobble",
      "rotation": 7
    },
    {
      "x": -36,
      "y": 2,
      "z": -8,
      "name": "Rock_Sandstone_Cobble",
      "rotation": 7
    },
    {
      "x": -36,
      "y": 3,
      "z": -8,
      "name": "Rock_Sandstone_Brick",
      "rotation": 7
    },
    {
      "x": -36,
      "y": 4,
      "z": -8,
      "name": "Rock_Sandstone_Brick",
      "rotation": 7
    },
    {
      "x": -36,
      "y": 5,
      "z": -8,
      "name": "Rock_Sandstone_Cobble",
      "rotation": 7
    },
    {
      "x": -36,
      "y": 6,
      "z": -8,
      "name": "Rock_Sandstone_Cobble",
      "rotation": 7
    },
    {
      "x": -36,
      "y": 1,
      "z": -7,
      "name": "Rock_Sandstone_Brick",
      "rotation": 7
    },
    {
      "x": -36,
      "y": 2,
      "z": -7,
      "name": "Rock_Sandstone_Brick",
      "rotation": 7
    },
    {
      "x": -36,
      "y": 3,
      "z": -7,
      "name": "Rock_Sandstone_Brick",
      "rotation": 7
    },
    {
      "x": -36,
      "y": 4,
      "z": -7,
      "name": "Rock_Sandstone_Brick",
      "rotation": 7
    },
    {
      "x": -36,
      "y": 5,
      "z": -7,
      "name": "Rock_Sandstone_Brick",
      "rotation": 7
    },
    {
      "x": -36,
      "y": 6,
      "z": -7,
      "name": "Rock_Sandstone_Brick",
      "rotation": 7
    },
    {
      "x": -36,
      "y": 1,
      "z": -6,
      "name": "Rock_Sandstone_Brick",
      "rotation": 7
    },
    {
      "x": -36,
      "y": 2,
      "z": -6,
      "name": "Rock_Sandstone_Brick",
      "rotation": 7
    },
    {
      "x": -36,
      "y": 1,
      "z": -5,
      "name": "Soil_Sand",
      "rotation": 7
    },
    {
      "x": -36,
      "y": 2,
      "z": -5,
      "name": "Rock_Sandstone_Brick",
      "rotation": 7
    },
    {
      "x": -36,
      "y": 1,
      "z": -4,
      "name": "Soil_Sand",
      "rotation": 7
    },
    {
      "x": -36,
      "y": 2,
      "z": -4,
      "name": "Rock_Sandstone_Brick",
      "rotation": 7
    },
    {
      "x": -36,
      "y": 1,
      "z": -3,
      "name": "Soil_Sand",
      "rotation": 7
    },
    {
      "x": -36,
      "y": 2,
      "z": -3,
      "name": "Rock_Sandstone_Brick",
      "rotation": 7
    },
    {
      "x": -36,
      "y": 1,
      "z": -2,
      "name": "Rock_Sandstone_Brick",
      "rotation": 7
    },
    {
      "x": -36,
      "y": 2,
      "z": -2,
      "name": "Rock_Sandstone_Brick",
      "rotation": 7
    },
    {
      "x": -36,
      "y": 1,
      "z": 3,
      "name": "Rock_Sandstone_Brick",
      "rotation": 7
    },
    {
      "x": -36,
      "y": 2,
      "z": 3,
      "name": "Rock_Sandstone_Brick",
      "rotation": 7
    },
    {
      "x": -36,
      "y": 1,
      "z": 4,
      "name": "Soil_Sand",
      "rotation": 16
    },
    {
      "x": -36,
      "y": 2,
      "z": 4,
      "name": "Rock_Sandstone_Brick",
      "rotation": 7
    },
    {
      "x": -36,
      "y": 1,
      "z": 5,
      "name": "Soil_Sand",
      "rotation": 16
    },
    {
      "x": -36,
      "y": 2,
      "z": 5,
      "name": "Rock_Sandstone_Brick",
      "rotation": 7
    },
    {
      "x": -36,
      "y": 1,
      "z": 6,
      "name": "Soil_Sand",
      "rotation": 16
    },
    {
      "x": -36,
      "y": 2,
      "z": 6,
      "name": "Rock_Sandstone_Brick",
      "rotation": 7
    },
    {
      "x": -36,
      "y": 1,
      "z": 7,
      "name": "Rock_Sandstone_Brick",
      "rotation": 7
    },
    {
      "x": -36,
      "y": 2,
      "z": 7,
      "name": "Rock_Sandstone_Brick",
      "rotation": 7
    },
    {
      "x": -36,
      "y": 1,
      "z": 8,
      "name": "Rock_Sandstone_Brick",
      "rotation": 7
    },
    {
      "x": -36,
      "y": 2,
      "z": 8,
      "name": "Rock_Sandstone_Brick",
      "rotation": 7
    },
    {
      "x": -36,
      "y": 3,
      "z": 8,
      "name": "Rock_Sandstone_Brick",
      "rotation": 7
    },
    {
      "x": -36,
      "y": 4,
      "z": 8,
      "name": "Rock_Sandstone_Brick",
      "rotation": 7
    },
    {
      "x": -36,
      "y": 5,
      "z": 8,
      "name": "Rock_Sandstone_Brick",
      "rotation": 7
    },
    {
      "x": -36,
      "y": 6,
      "z": 8,
      "name": "Rock_Sandstone_Brick",
      "rotation": 7
    },
    {
      "x": -36,
      "y": 1,
      "z": 9,
      "name": "Rock_Sandstone_Cobble",
      "rotation": 7
    },
    {
      "x": -36,
      "y": 2,
      "z": 9,
      "name": "Rock_Sandstone_Cobble",
      "rotation": 7
    },
    {
      "x": -36,
      "y": 3,
      "z": 9,
      "name": "Rock_Sandstone_Brick",
      "rotation": 7
    },
    {
      "x": -36,
      "y": 4,
      "z": 9,
      "name": "Rock_Sandstone_Brick",
      "rotation": 7
    },
    {
      "x": -36,
      "y": 5,
      "z": 9,
      "name": "Rock_Sandstone_Cobble",
      "rotation": 7
    },
    {
      "x": -36,
      "y": 6,
      "z": 9,
      "name": "Rock_Sandstone_Brick",
      "rotation": 7
    },
    {
      "x": -36,
      "y": 2,
      "z": 10,
      "name": "Soil_Sand",
      "rotation": 16
    },
    {
      "x": -36,
      "y": 3,
      "z": 10,
      "name": "Rock_Sandstone_Red_Brick",
      "rotation": 7
    },
    {
      "x": -36,
      "y": 4,
      "z": 10,
      "name": "Rock_Sandstone_Red_Brick",
      "rotation": 7
    },
    {
      "x": -36,
      "y": 3,
      "z": 11,
      "name": "Rock_Sandstone_Red_Brick_Stairs",
      "rotation": 16
    },
    {
      "x": -36,
      "y": 4,
      "z": 11,
      "name": "Rock_Sandstone_Red_Brick_Stairs",
      "rotation": 16
    },
    {
      "x": -35,
      "y": 3,
      "z": -10,
      "name": "Rock_Sandstone_Red_Brick",
      "rotation": 7
    },
    {
      "x": -35,
      "y": 4,
      "z": -10,
      "name": "Rock_Sandstone_Red_Brick",
      "rotation": 7
    },
    {
      "x": -35,
      "y": 3,
      "z": -9,
      "name": "Rock_Sandstone_Red_Brick",
      "rotation": 7
    },
    {
      "x": -35,
      "y": 4,
      "z": -9,
      "name": "Rock_Sandstone_Red_Brick",
      "rotation": 7
    },
    {
      "x": -35,
      "y": 1,
      "z": -8,
      "name": "Rock_Sandstone_Cobble",
      "rotation": 7
    },
    {
      "x": -35,
      "y": 2,
      "z": -8,
      "name": "Rock_Sandstone_Cobble",
      "rotation": 7
    },
    {
      "x": -35,
      "y": 3,
      "z": -8,
      "name": "Rock_Sandstone_Brick",
      "rotation": 7
    },
    {
      "x": -35,
      "y": 4,
      "z": -8,
      "name": "Rock_Sandstone_Brick",
      "rotation": 7
    },
    {
      "x": -35,
      "y": 5,
      "z": -8,
      "name": "Rock_Sandstone_Cobble",
      "rotation": 7
    },
    {
      "x": -35,
      "y": 6,
      "z": -8,
      "name": "Rock_Sandstone_Brick",
      "rotation": 7
    },
    {
      "x": -35,
      "y": 1,
      "z": -7,
      "name": "Rock_Sandstone_Brick",
      "rotation": 7
    },
    {
      "x": -35,
      "y": 2,
      "z": -7,
      "name": "Rock_Sandstone_Brick",
      "rotation": 7
    },
    {
      "x": -35,
      "y": 3,
      "z": -7,
      "name": "Rock_Sandstone_Brick",
      "rotation": 7
    },
    {
      "x": -35,
      "y": 4,
      "z": -7,
      "name": "Rock_Sandstone_Brick",
      "rotation": 7
    },
    {
      "x": -35,
      "y": 5,
      "z": -7,
      "name": "Rock_Sandstone_Brick",
      "rotation": 7
    },
    {
      "x": -35,
      "y": 6,
      "z": -7,
      "name": "Rock_Sandstone_Brick",
      "rotation": 7
    },
    {
      "x": -35,
      "y": 1,
      "z": -6,
      "name": "Rock_Sandstone_Brick",
      "rotation": 7
    },
    {
      "x": -35,
      "y": 2,
      "z": -6,
      "name": "Rock_Sandstone_Brick_Stairs",
      "rotation": 15
    },
    {
      "x": -35,
      "y": 1,
      "z": -5,
      "name": "Rock_Sandstone_Brick",
      "rotation": 7
    },
    {
      "x": -35,
      "y": 2,
      "z": -5,
      "name": "Rock_Sandstone_Brick_Stairs",
      "rotation": 15
    },
    {
      "x": -35,
      "y": 1,
      "z": -4,
      "name": "Rock_Sandstone_Brick",
      "rotation": 7
    },
    {
      "x": -35,
      "y": 2,
      "z": -4,
      "name": "Rock_Sandstone_Brick_Stairs",
      "rotation": 15
    },
    {
      "x": -35,
      "y": 1,
      "z": -3,
      "name": "Rock_Sandstone_Brick",
      "rotation": 7
    },
    {
      "x": -35,
      "y": 2,
      "z": -3,
      "name": "Rock_Sandstone_Brick_Stairs",
      "rotation": 15
    },
    {
      "x": -35,
      "y": 1,
      "z": -2,
      "name": "Rock_Sandstone_Brick",
      "rotation": 7
    },
    {
      "x": -35,
      "y": 2,
      "z": -2,
      "name": "Rock_Sandstone_Brick_Stairs",
      "rotation": 15
    },
    {
      "x": -35,
      "y": 1,
      "z": 3,
      "name": "Rock_Sandstone_Brick",
      "rotation": 7
    },
    {
      "x": -35,
      "y": 2,
      "z": 3,
      "name": "Rock_Sandstone_Brick_Stairs",
      "rotation": 15
    },
    {
      "x": -35,
      "y": 1,
      "z": 4,
      "name": "Rock_Sandstone_Brick",
      "rotation": 7
    },
    {
      "x": -35,
      "y": 2,
      "z": 4,
      "name": "Rock_Sandstone_Brick_Stairs",
      "rotation": 15
    },
    {
      "x": -35,
      "y": 1,
      "z": 5,
      "name": "Rock_Sandstone_Brick",
      "rotation": 7
    },
    {
      "x": -35,
      "y": 2,
      "z": 5,
      "name": "Rock_Sandstone_Brick_Stairs",
      "rotation": 15
    },
    {
      "x": -35,
      "y": 1,
      "z": 6,
      "name": "Rock_Sandstone_Brick",
      "rotation": 7
    },
    {
      "x": -35,
      "y": 2,
      "z": 6,
      "name": "Rock_Sandstone_Brick_Stairs",
      "rotation": 15
    },
    {
      "x": -35,
      "y": 1,
      "z": 7,
      "name": "Rock_Sandstone_Brick",
      "rotation": 7
    },
    {
      "x": -35,
      "y": 2,
      "z": 7,
      "name": "Rock_Sandstone_Brick_Stairs",
      "rotation": 15
    },
    {
      "x": -35,
      "y": 1,
      "z": 8,
      "name": "Rock_Sandstone_Brick",
      "rotation": 7
    },
    {
      "x": -35,
      "y": 2,
      "z": 8,
      "name": "Rock_Sandstone_Brick",
      "rotation": 7
    },
    {
      "x": -35,
      "y": 3,
      "z": 8,
      "name": "Rock_Sandstone_Brick",
      "rotation": 7
    },
    {
      "x": -35,
      "y": 4,
      "z": 8,
      "name": "Rock_Sandstone_Brick",
      "rotation": 7
    },
    {
      "x": -35,
      "y": 5,
      "z": 8,
      "name": "Rock_Sandstone_Brick",
      "rotation": 7
    },
    {
      "x": -35,
      "y": 6,
      "z": 8,
      "name": "Rock_Sandstone_Brick",
      "rotation": 7
    },
    {
      "x": -35,
      "y": 1,
      "z": 9,
      "name": "Rock_Sandstone_Cobble",
      "rotation": 7
    },
    {
      "x": -35,
      "y": 2,
      "z": 9,
      "name": "Rock_Sandstone_Cobble",
      "rotation": 7
    },
    {
      "x": -35,
      "y": 3,
      "z": 9,
      "name": "Rock_Sandstone_Brick",
      "rotation": 7
    },
    {
      "x": -35,
      "y": 4,
      "z": 9,
      "name": "Rock_Sandstone_Brick",
      "rotation": 7
    },
    {
      "x": -35,
      "y": 5,
      "z": 9,
      "name": "Rock_Sandstone_Brick",
      "rotation": 7
    },
    {
      "x": -35,
      "y": 6,
      "z": 9,
      "name": "Rock_Sandstone_Brick",
      "rotation": 7
    },
    {
      "x": -35,
      "y": 1,
      "z": 10,
      "name": "Soil_Sand",
      "rotation": 16
    },
    {
      "x": -35,
      "y": 2,
      "z": 10,
      "name": "Soil_Sand",
      "rotation": 16
    },
    {
      "x": -35,
      "y": 3,
      "z": 10,
      "name": "Rock_Sandstone_Red_Brick",
      "rotation": 7
    },
    {
      "x": -35,
      "y": 4,
      "z": 10,
      "name": "Rock_Sandstone_Red_Brick",
      "rotation": 7
    },
    {
      "x": -35,
      "y": 3,
      "z": 11,
      "name": "Rock_Sandstone_Red_Brick",
      "rotation": 7
    },
    {
      "x": -35,
      "y": 4,
      "z": 11,
      "name": "Rock_Sandstone_Red_Brick",
      "rotation": 7
    },
    {
      "x": -34,
      "y": 3,
      "z": -10,
      "name": "Rock_Sandstone_Red_Brick",
      "rotation": 7
    },
    {
      "x": -34,
      "y": 4,
      "z": -10,
      "name": "Rock_Sandstone_Red_Cobble",
      "rotation": 7
    },
    {
      "x": -34,
      "y": 6,
      "z": -10,
      "name": "Rock_Sandstone_Cobble_Half",
      "rotation": 16
    },
    {
      "x": -34,
      "y": 1,
      "z": -9,
      "name": "Rock_Sandstone_Cobble_Half",
      "rotation": 16
    },
    {
      "x": -34,
      "y": 2,
      "z": -9,
      "name": "Rock_Sandstone",
      "rotation": 16
    },
    {
      "x": -34,
      "y": 3,
      "z": -9,
      "name": "Rock_Sandstone_Red_Brick",
      "rotation": 7
    },
    {
      "x": -34,
      "y": 4,
      "z": -9,
      "name": "Rock_Sandstone_Red_Brick",
      "rotation": 7
    },
    {
      "x": -34,
      "y": 5,
      "z": -9,
      "name": "Rock_Sandstone_Cobble_Half",
      "rotation": 16
    },
    {
      "x": -34,
      "y": 6,
      "z": -9,
      "name": "Rock_Sandstone_Brick",
      "rotation": 16
    },
    {
      "x": -34,
      "y": 1,
      "z": -8,
      "name": "Rock_Sandstone_Cobble",
      "rotation": 7
    },
    {
      "x": -34,
      "y": 2,
      "z": -8,
      "name": "Rock_Sandstone_Cobble",
      "rotation": 7
    },
    {
      "x": -34,
      "y": 3,
      "z": -8,
      "name": "Rock_Sandstone_Brick",
      "rotation": 7
    },
    {
      "x": -34,
      "y": 4,
      "z": -8,
      "name": "Rock_Sandstone_Brick",
      "rotation": 7
    },
    {
      "x": -34,
      "y": 5,
      "z": -8,
      "name": "Rock_Sandstone_Brick",
      "rotation": 7
    },
    {
      "x": -34,
      "y": 6,
      "z": -8,
      "name": "Rock_Sandstone_Brick",
      "rotation": 7
    },
    {
      "x": -34,
      "y": 1,
      "z": -7,
      "name": "Rock_Sandstone_Brick",
      "rotation": 7
    },
    {
      "x": -34,
      "y": 2,
      "z": -7,
      "name": "Rock_Sandstone_Brick",
      "rotation": 7
    },
    {
      "x": -34,
      "y": 3,
      "z": -7,
      "name": "Rock_Sandstone_Brick",
      "rotation": 7
    },
    {
      "x": -34,
      "y": 4,
      "z": -7,
      "name": "Rock_Sandstone_Brick",
      "rotation": 7
    },
    {
      "x": -34,
      "y": 5,
      "z": -7,
      "name": "Rock_Sandstone_Brick",
      "rotation": 7
    },
    {
      "x": -34,
      "y": 6,
      "z": -7,
      "name": "Rock_Sandstone_Brick",
      "rotation": 7
    },
    {
      "x": -34,
      "y": 1,
      "z": 8,
      "name": "Rock_Sandstone_Brick",
      "rotation": 7
    },
    {
      "x": -34,
      "y": 2,
      "z": 8,
      "name": "Rock_Sandstone_Brick",
      "rotation": 7
    },
    {
      "x": -34,
      "y": 3,
      "z": 8,
      "name": "Rock_Sandstone_Brick",
      "rotation": 7
    },
    {
      "x": -34,
      "y": 4,
      "z": 8,
      "name": "Rock_Sandstone_Brick",
      "rotation": 7
    },
    {
      "x": -34,
      "y": 5,
      "z": 8,
      "name": "Rock_Sandstone_Brick",
      "rotation": 7
    },
    {
      "x": -34,
      "y": 6,
      "z": 8,
      "name": "Rock_Sandstone_Brick",
      "rotation": 7
    },
    {
      "x": -34,
      "y": 1,
      "z": 9,
      "name": "Rock_Sandstone_Cobble",
      "rotation": 7
    },
    {
      "x": -34,
      "y": 2,
      "z": 9,
      "name": "Rock_Sandstone_Cobble",
      "rotation": 7
    },
    {
      "x": -34,
      "y": 3,
      "z": 9,
      "name": "Rock_Sandstone_Brick",
      "rotation": 7
    },
    {
      "x": -34,
      "y": 4,
      "z": 9,
      "name": "Rock_Sandstone_Brick",
      "rotation": 7
    },
    {
      "x": -34,
      "y": 5,
      "z": 9,
      "name": "Rock_Sandstone_Brick",
      "rotation": 7
    },
    {
      "x": -34,
      "y": 6,
      "z": 9,
      "name": "Rock_Sandstone_Cobble",
      "rotation": 7
    },
    {
      "x": -34,
      "y": 1,
      "z": 10,
      "name": "Soil_Sand",
      "rotation": 16
    },
    {
      "x": -34,
      "y": 2,
      "z": 10,
      "name": "Soil_Sand",
      "rotation": 16
    },
    {
      "x": -34,
      "y": 3,
      "z": 10,
      "name": "Rock_Sandstone_Red_Cobble",
      "rotation": 7
    },
    {
      "x": -34,
      "y": 4,
      "z": 10,
      "name": "Rock_Sandstone_Red_Brick",
      "rotation": 7
    },
    {
      "x": -34,
      "y": 5,
      "z": 10,
      "name": "Soil_Sand",
      "rotation": 16
    },
    {
      "x": -34,
      "y": 6,
      "z": 10,
      "name": "Soil_Sand",
      "rotation": 16
    },
    {
      "x": -34,
      "y": 2,
      "z": 11,
      "name": "Soil_Sand",
      "rotation": 16
    },
    {
      "x": -34,
      "y": 3,
      "z": 11,
      "name": "Rock_Sandstone_Red_Brick",
      "rotation": 7
    },
    {
      "x": -34,
      "y": 4,
      "z": 11,
      "name": "Rock_Sandstone_Red_Brick",
      "rotation": 7
    },
    {
      "x": -29,
      "y": 5,
      "z": -8,
      "name": "Rock_Sandstone_Brick_Half",
      "rotation": 7
    },
    {
      "x": -28,
      "y": 4,
      "z": -8,
      "name": "Rock_Sandstone_Brick_Half",
      "rotation": 8
    },
    {
      "x": -28,
      "y": 5,
      "z": -8,
      "name": "Rock_Sandstone_Brick"
    },
    {
      "x": -27,
      "y": 3,
      "z": -8,
      "name": "Rock_Sandstone_Brick_Half",
      "rotation": 7
    },
    {
      "x": -27,
      "y": 4,
      "z": -8,
      "name": "Rock_Sandstone_Brick"
    },
    {
      "x": -27,
      "y": 5,
      "z": -8,
      "name": "Rock_Sandstone_Brick"
    },
    {
      "x": -27,
      "y": 5,
      "z": -7,
      "name": "Rock_Sandstone_Brick_Half",
      "rotation": 4
    },
    {
      "x": -26,
      "y": 2,
      "z": -8,
      "name": "Rock_Sandstone_Brick_Half",
      "rotation": 8
    },
    {
      "x": -26,
      "y": 3,
      "z": -8,
      "name": "Rock_Sandstone_Brick"
    },
    {
      "x": -26,
      "y": 4,
      "z": -8,
      "name": "Rock_Sandstone_Brick"
    },
    {
      "x": -26,
      "y": 5,
      "z": -8,
      "name": "Rock_Sandstone_Brick"
    },
    {
      "x": -26,
      "y": 3,
      "z": -7,
      "name": "Rock_Sandstone_Brick_Half",
      "rotation": 7
    },
    {
      "x": -26,
      "y": 4,
      "z": -7,
      "name": "Rock_Sandstone_Brick"
    },
    {
      "x": -26,
      "y": 5,
      "z": -7,
      "name": "Rock_Sandstone_Brick"
    },
    {
      "x": -26,
      "y": 16,
      "z": -4,
      "name": "Wood_Drywood_Planks_Half",
      "rotation": 7
    },
    {
      "x": -26,
      "y": 17,
      "z": -4,
      "name": "Wood_Drywood_Planks_Half",
      "rotation": 7
    },
    {
      "x": -26,
      "y": 2,
      "z": 2,
      "name": "Rock_Sandstone_Brick_Half",
      "rotation": 7
    },
    {
      "x": -25,
      "y": 2,
      "z": -8,
      "name": "Rock_Sandstone_Brick_Half",
      "rotation": 8
    },
    {
      "x": -25,
      "y": 3,
      "z": -8,
      "name": "Rock_Sandstone_Brick"
    },
    {
      "x": -25,
      "y": 4,
      "z": -8,
      "name": "Rock_Sandstone_Brick"
    },
    {
      "x": -25,
      "y": 5,
      "z": -8,
      "name": "Rock_Sandstone_Brick"
    },
    {
      "x": -25,
      "y": 6,
      "z": -8,
      "name": "Rock_Sandstone_Brick_Ornate"
    },
    {
      "x": -25,
      "y": 2,
      "z": -7,
      "name": "Rock_Sandstone_Brick"
    },
    {
      "x": -25,
      "y": 3,
      "z": -7,
      "name": "Rock_Sandstone_Brick"
    },
    {
      "x": -25,
      "y": 4,
      "z": -7,
      "name": "Rock_Sandstone_Brick"
    },
    {
      "x": -25,
      "y": 5,
      "z": -7,
      "name": "Rock_Sandstone_Brick"
    },
    {
      "x": -25,
      "y": 15,
      "z": -4,
      "name": "Wood_Drywood_Planks_Half",
      "rotation": 8
    },
    {
      "x": -25,
      "y": 16,
      "z": -4,
      "name": "Wood_Drywood_Planks"
    },
    {
      "x": -25,
      "y": 17,
      "z": -4,
      "name": "Wood_Drywood_Planks"
    },
    {
      "x": -25,
      "y": 18,
      "z": -4,
      "name": "Wood_Drywood_Planks"
    },
    {
      "x": -25,
      "y": 19,
      "z": -4,
      "name": "Wood_Drywood_Planks_Half",
      "rotation": 7
    },
    {
      "x": -25,
      "y": 2,
      "z": 2,
      "name": "Rock_Sandstone_Brick"
    },
    {
      "x": -25,
      "y": 2,
      "z": 3,
      "name": "Rock_Sandstone_Brick"
    },
    {
      "x": -24,
      "y": 16,
      "z": -5,
      "name": "Wood_Drywood_Planks_Half",
      "rotation": 7
    },
    {
      "x": -24,
      "y": 17,
      "z": -5,
      "name": "Wood_Drywood_Planks"
    },
    {
      "x": -24,
      "y": 18,
      "z": -5,
      "name": "Wood_Drywood_Planks_Half",
      "rotation": 7
    },
    {
      "x": -24,
      "y": 19,
      "z": -5,
      "name": "Wood_Drywood_Planks_Half",
      "rotation": 7
    },
    {
      "x": -24,
      "y": 14,
      "z": -4,
      "name": "Rock_Sandstone_Brick"
    },
    {
      "x": -24,
      "y": 15,
      "z": -4,
      "name": "Wood_Drywood_Planks"
    },
    {
      "x": -24,
      "y": 16,
      "z": -4,
      "name": "Wood_Drywood_Planks"
    },
    {
      "x": -24,
      "y": 17,
      "z": -4,
      "name": "Wood_Drywood_Planks"
    },
    {
      "x": -24,
      "y": 18,
      "z": -4,
      "name": "Wood_Drywood_Planks"
    },
    {
      "x": -24,
      "y": 19,
      "z": -4,
      "name": "Wood_Drywood_Planks"
    },
    {
      "x": -24,
      "y": 20,
      "z": -4,
      "name": "Wood_Drywood_Planks"
    },
    {
      "x": -24,
      "y": 21,
      "z": -4,
      "name": "Rock_Sandstone_Brick"
    },
    {
      "x": -24,
      "y": 22,
      "z": -4,
      "name": "Rock_Sandstone_Brick"
    },
    {
      "x": -24,
      "y": 2,
      "z": 1,
      "name": "Rock_Sandstone_Brick_Half",
      "rotation": 6
    },
    {
      "x": -24,
      "y": 2,
      "z": 2,
      "name": "Rock_Sandstone_Brick"
    },
    {
      "x": -24,
      "y": 2,
      "z": 3,
      "name": "Rock_Sandstone_Brick"
    },
    {
      "x": -24,
      "y": 2,
      "z": 4,
      "name": "Rock_Sandstone_Brick_Half",
      "rotation": 4
    },
    {
      "x": -24,
      "y": 2,
      "z": 9,
      "name": "Rock_Sandstone_Brick_Half",
      "rotation": 7
    },
    {
      "x": -23,
      "y": 11,
      "z": -8,
      "name": "Rock_Sandstone_Brick_Stairs",
      "rotation": 8
    },
    {
      "x": -23,
      "y": 12,
      "z": -8,
      "name": "Rock_Sandstone_Brick",
      "rotation": 3
    },
    {
      "x": -23,
      "y": 13,
      "z": -8,
      "name": "Rock_Sandstone_Brick",
      "rotation": 3
    },
    {
      "x": -23,
      "y": 10,
      "z": -7,
      "name": "Rock_Sandstone_Cobble",
      "rotation": 3
    },
    {
      "x": -23,
      "y": 11,
      "z": -7,
      "name": "Rock_Sandstone_Cobble",
      "rotation": 3
    },
    {
      "x": -23,
      "y": 12,
      "z": -7,
      "name": "Rock_Sandstone_Brick",
      "rotation": 3
    },
    {
      "x": -23,
      "y": 13,
      "z": -7,
      "name": "Rock_Sandstone_Brick",
      "rotation": 3
    },
    {
      "x": -23,
      "y": 9,
      "z": -6,
      "name": "Rock_Sandstone_Brick_Stairs",
      "rotation": 10
    },
    {
      "x": -23,
      "y": 10,
      "z": -6,
      "name": "Rock_Sandstone_Red_Cobble",
      "rotation": 3
    },
    {
      "x": -23,
      "y": 11,
      "z": -6,
      "name": "Rock_Sandstone_Red_Brick",
      "rotation": 3
    },
    {
      "x": -23,
      "y": 12,
      "z": -6,
      "name": "Rock_Sandstone_Cobble",
      "rotation": 3
    },
    {
      "x": -23,
      "y": 13,
      "z": -6,
      "name": "Rock_Sandstone_Brick",
      "rotation": 1
    },
    {
      "x": -23,
      "y": 14,
      "z": -6,
      "name": "Rock_Sandstone_Brick_Smooth_Half",
      "rotation": 7
    },
    {
      "x": -23,
      "y": 15,
      "z": -6,
      "name": "Rock_Sandstone_Brick_Half",
      "rotation": 7
    },
    {
      "x": -23,
      "y": 16,
      "z": -6,
      "name": "Rock_Sandstone_Brick_Half",
      "rotation": 7
    },
    {
      "x": -23,
      "y": 17,
      "z": -6,
      "name": "Rock_Sandstone_Brick_Half",
      "rotation": 7
    },
    {
      "x": -23,
      "y": 18,
      "z": -6,
      "name": "Rock_Sandstone_Brick_Half",
      "rotation": 7
    },
    {
      "x": -23,
      "y": 19,
      "z": -6,
      "name": "Rock_Sandstone_Brick_Smooth_Half",
      "rotation": 7
    },
    {
      "x": -23,
      "y": 12,
      "z": -5,
      "name": "Rock_Sandstone_Cobble"
    },
    {
      "x": -23,
      "y": 13,
      "z": -5,
      "name": "Wood_Drywood_Planks",
      "rotation": 1
    },
    {
      "x": -23,
      "y": 14,
      "z": -5,
      "name": "Rock_Sandstone_Brick",
      "rotation": 1
    },
    {
      "x": -23,
      "y": 15,
      "z": -5,
      "name": "Wood_Drywood_Planks",
      "rotation": 1
    },
    {
      "x": -23,
      "y": 16,
      "z": -5,
      "name": "Wood_Drywood_Planks",
