{
  "version": 8,
  "blockIdVersion": 11,
  "anchorX": 0,
  "anchorY": 0,
  "anchorZ": 0,
  "blocks": [
    {
      "x": -3,
      "y": 0,
      "z": -4,
      "name": "Wood_Bamboo_Branch_Long_Deco",
      "support": 15
    },
    {
      "x": -3,
      "y": 1,
      "z": -4,
      "name": "Wood_Bamboo_Branch_Long_Deco",
      "support": 15
    },
    {
      "x": -3,
      "y": 2,
      "z": -4,
      "name": "Wood_Bamboo_Branch_Long_Deco",
      "support": 15
    },
    {
      "x": -3,
      "y": 3,
      "z": -4,
      "name": "Wood_Bamboo_Branch_Long_Deco",
      "support": 15
    },
    {
      "x": -3,
      "y": 4,
      "z": -4,
      "name": "Wood_Bamboo_Trunk_Deco",
      "support": 15
    },
    {
      "x": -3,
      "y": 7,
      "z": -4,
      "name": "*Wood_Tropicalwood_Roof_Steep_State_Definitions_Corner_Right",
      "rotation": 3
    },
    {
      "x": -3,
      "y": 8,
      "z": -4,
      "name": "*Wood_Tropicalwood_Roof_Steep_State_Definitions_Corner_Right",
      "filler": 1024,
      "rotation": 3
    },
    {
      "x": -3,
      "y": 4,
      "z": -3,
      "name": "Wood_Tropicalwood_Planks_Half",
      "rotation": 8
    },
    {
      "x": -3,
      "y": 7,
      "z": -3,
      "name": "Wood_Tropicalwood_Roof_Steep",
      "rotation": 3
    },
    {
      "x": -3,
      "y": 8,
      "z": -3,
      "name": "Wood_Tropicalwood_Roof_Steep",
      "filler": 1024,
      "rotation": 3
    },
    {
      "x": -3,
      "y": 4,
      "z": -2,
      "name": "Wood_Tropicalwood_Planks_Half",
      "rotation": 8
    },
    {
      "x": -3,
      "y": 7,
      "z": -2,
      "name": "Wood_Tropicalwood_Roof_Steep",
      "rotation": 3
    },
    {
      "x": -3,
      "y": 8,
      "z": -2,
      "name": "Wood_Tropicalwood_Roof_Steep",
      "filler": 1024,
      "rotation": 3
    },
    {
      "x": -3,
      "y": 4,
      "z": -1,
      "name": "Wood_Tropicalwood_Planks_Half",
      "rotation": 8
    },
    {
      "x": -3,
      "y": 7,
      "z": -1,
      "name": "Wood_Tropicalwood_Roof_Steep",
      "rotation": 3
    },
    {
      "x": -3,
      "y": 8,
      "z": -1,
      "name": "Wood_Tropicalwood_Roof_Steep",
      "filler": 1024,
      "rotation": 3
    },
    {
      "x": -3,
      "y": 4,
      "z": 0,
      "name": "Wood_Tropicalwood_Planks_Half",
      "rotation": 8
    },
    {
      "x": -3,
      "y": 7,
      "z": 0,
      "name": "Wood_Tropicalwood_Roof_Steep",
      "rotation": 3
    },
    {
      "x": -3,
      "y": 8,
      "z": 0,
      "name": "Wood_Tropicalwood_Roof_Steep",
      "filler": 1024,
      "rotation": 3
    },
    {
      "x": -3,
      "y": 4,
      "z": 1,
      "name": "Wood_Tropicalwood_Planks_Half",
      "rotation": 8
    },
    {
      "x": -3,
      "y": 7,
      "z": 1,
      "name": "Wood_Tropicalwood_Roof_Steep",
      "rotation": 3
    },
    {
      "x": -3,
      "y": 8,
      "z": 1,
      "name": "Wood_Tropicalwood_Roof_Steep",
      "filler": 1024,
      "rotation": 3
    },
    {
      "x": -3,
      "y": 4,
      "z": 2,
      "name": "Wood_Tropicalwood_Planks_Half",
      "rotation": 8
    },
    {
      "x": -3,
      "y": 7,
      "z": 2,
      "name": "Wood_Tropicalwood_Roof_Steep",
      "rotation": 3
    },
    {
      "x": -3,
      "y": 8,
      "z": 2,
      "name": "Wood_Tropicalwood_Roof_Steep",
      "filler": 1024,
      "rotation": 3
    },
    {
      "x": -3,
      "y": 4,
      "z": 3,
      "name": "Wood_Tropicalwood_Planks_Half",
      "rotation": 8
    },
    {
      "x": -3,
      "y": 7,
      "z": 3,
      "name": "*Wood_Tropicalwood_Roof_Steep_State_Definitions_Corner_Right"
    },
    {
      "x": -3,
      "y": 8,
      "z": 3,
      "name": "*Wood_Tropicalwood_Roof_Steep_State_Definitions_Corner_Right",
      "filler": 1024
    },
    {
      "x": -3,
      "y": 0,
      "z": 4,
      "name": "Wood_Bamboo_Branch_Long_Deco",
      "support": 15
    },
    {
      "x": -3,
      "y": 1,
      "z": 4,
      "name": "Wood_Bamboo_Branch_Long_Deco",
      "support": 15
    },
    {
      "x": -3,
      "y": 2,
      "z": 4,
      "name": "Wood_Bamboo_Branch_Long_Deco",
      "support": 15
    },
    {
      "x": -3,
      "y": 3,
      "z": 4,
      "name": "Wood_Bamboo_Branch_Long_Deco",
      "support": 15
    },
    {
      "x": -3,
      "y": 4,
      "z": 4,
      "name": "Wood_Bamboo_Trunk_Deco",
      "support": 15
    },
    {
      "x": -2,
      "y": 4,
      "z": -4,
      "name": "Wood_Tropicalwood_Planks_Half",
      "rotation": 8
    },
    {
      "x": -2,
      "y": 7,
      "z": -4,
      "name": "Wood_Tropicalwood_Roof_Steep",
      "rotation": 2
    },
    {
      "x": -2,
      "y": 8,
      "z": -4,
      "name": "Wood_Tropicalwood_Roof_Steep",
      "filler": 1024,
      "rotation": 2
    },
    {
      "x": -2,
      "y": 4,
      "z": -3,
      "name": "Wood_Tropicalwood_Planks_Half",
      "rotation": 8
    },
    {
      "x": -2,
      "y": 5,
      "z": -3,
      "name": "Wood_Bamboo_Trunk_Deco",
      "support": 15
    },
    {
      "x": -2,
      "y": 6,
      "z": -3,
      "name": "Wood_Bamboo_Trunk_Deco",
      "support": 15
    },
    {
      "x": -2,
      "y": 7,
      "z": -3,
      "name": "Wood_Bamboo_Trunk_Deco",
      "support": 15
    },
    {
      "x": -2,
      "y": 8,
      "z": -3,
      "name": "Wood_Bamboo_Trunk_Deco",
      "support": 15
    },
    {
      "x": -2,
      "y": 9,
      "z": -3,
      "name": "*Wood_Tropicalwood_Roof_State_Definitions_Corner_Left",
      "rotation": 2
    },
    {
      "x": -2,
      "y": 4,
      "z": -2,
      "name": "Wood_Tropicalwood_Planks_Half",
      "rotation": 8
    },
    {
      "x": -2,
      "y": 5,
      "z": -2,
      "name": "Wood_Tropicalwood_Planks_Half",
      "rotation": 5
    },
    {
      "x": -2,
      "y": 6,
      "z": -2,
      "name": "Wood_Tropicalwood_Planks_Half",
      "rotation": 5
    },
    {
      "x": -2,
      "y": 7,
      "z": -2,
      "name": "Wood_Tropicalwood_Planks_Half",
      "rotation": 5
    },
    {
      "x": -2,
      "y": 8,
      "z": -2,
      "name": "Wood_Tropicalwood_Decorative"
    },
    {
      "x": -2,
      "y": 9,
      "z": -2,
      "name": "Wood_Tropicalwood_Roof",
      "rotation": 3
    },
    {
      "x": -2,
      "y": 4,
      "z": -1,
      "name": "Wood_Tropicalwood_Planks_Half",
      "rotation": 8
    },
    {
      "x": -2,
      "y": 5,
      "z": -1,
      "name": "Wood_Tropicalwood_Planks_Half",
      "rotation": 5
    },
    {
      "x": -2,
      "y": 6,
      "z": -1,
      "name": "Wood_Tropicalwood_Fence",
      "rotation": 1
    },
    {
      "x": -2,
      "y": 7,
      "z": -1,
      "name": "Wood_Tropicalwood_Planks_Half",
      "rotation": 5
    },
    {
      "x": -2,
      "y": 8,
      "z": -1,
      "name": "Wood_Tropicalwood_Decorative"
    },
    {
      "x": -2,
      "y": 9,
      "z": -1,
      "name": "Wood_Tropicalwood_Roof",
      "rotation": 3
    },
    {
      "x": -2,
      "y": 4,
      "z": 0,
      "name": "Wood_Tropicalwood_Planks_Half",
      "rotation": 8
    },
    {
      "x": -2,
      "y": 5,
      "z": 0,
      "name": "Wood_Tropicalwood_Planks_Half",
      "rotation": 5
    },
    {
      "x": -2,
      "y": 6,
      "z": 0,
      "name": "Wood_Tropicalwood_Fence",
      "rotation": 1
    },
    {
      "x": -2,
      "y": 7,
      "z": 0,
      "name": "Wood_Tropicalwood_Planks_Half",
      "rotation": 5
    },
    {
      "x": -2,
      "y": 8,
      "z": 0,
      "name": "Wood_Tropicalwood_Decorative"
    },
    {
      "x": -2,
      "y": 9,
      "z": 0,
      "name": "Wood_Tropicalwood_Roof",
      "rotation": 3
    },
    {
      "x": -2,
      "y": 4,
      "z": 1,
      "name": "Wood_Tropicalwood_Planks_Half",
      "rotation": 8
    },
    {
      "x": -2,
      "y": 5,
      "z": 1,
      "name": "Wood_Tropicalwood_Planks_Half",
      "rotation": 5
    },
    {
      "x": -2,
      "y": 6,
      "z": 1,
      "name": "Wood_Tropicalwood_Planks_Half",
      "rotation": 5
    },
    {
      "x": -2,
      "y": 7,
      "z": 1,
      "name": "Wood_Tropicalwood_Planks_Half",
      "rotation": 5
    },
    {
      "x": -2,
      "y": 8,
      "z": 1,
      "name": "Wood_Tropicalwood_Decorative"
    },
    {
      "x": -2,
      "y": 9,
      "z": 1,
      "name": "Wood_Tropicalwood_Roof",
      "rotation": 3
    },
    {
      "x": -2,
      "y": 4,
      "z": 2,
      "name": "Wood_Tropicalwood_Planks_Half",
      "rotation": 8
    },
    {
      "x": -2,
      "y": 5,
      "z": 2,
      "name": "Wood_Bamboo_Trunk_Deco",
      "support": 15
    },
    {
      "x": -2,
      "y": 6,
      "z": 2,
      "name": "Wood_Bamboo_Trunk_Deco",
      "support": 15
    },
    {
      "x": -2,
      "y": 7,
      "z": 2,
      "name": "Wood_Bamboo_Trunk_Deco",
      "support": 15
    },
    {
      "x": -2,
      "y": 8,
      "z": 2,
      "name": "Wood_Bamboo_Trunk_Deco",
      "support": 15
    },
    {
      "x": -2,
      "y": 9,
      "z": 2,
      "name": "*Wood_Tropicalwood_Roof_State_Definitions_Corner_Right"
    },
    {
      "x": -2,
      "y": 4,
      "z": 3,
      "name": "Wood_Tropicalwood_Planks_Half",
      "rotation": 8
    },
    {
      "x": -2,
      "y": 7,
      "z": 3,
      "name": "Wood_Tropicalwood_Roof_Steep"
    },
    {
      "x": -2,
      "y": 8,
      "z": 3,
      "name": "Wood_Tropicalwood_Roof_Steep",
      "filler": 1024
    },
    {
      "x": -2,
      "y": 4,
      "z": 4,
      "name": "Wood_Tropicalwood_Planks_Half",
      "rotation": 8
    },
    {
      "x": -1,
      "y": 4,
      "z": -4,
      "name": "Wood_Tropicalwood_Planks_Half",
      "rotation": 8
    },
    {
      "x": -1,
      "y": 7,
      "z": -4,
      "name": "Wood_Tropicalwood_Roof_Steep",
      "rotation": 2
    },
    {
      "x": -1,
      "y": 8,
      "z": -4,
      "name": "Wood_Tropicalwood_Roof_Steep",
      "filler": 1024,
      "rotation": 2
    },
    {
      "x": -1,
      "y": 4,
      "z": -3,
      "name": "Wood_Tropicalwood_Planks_Half",
      "rotation": 8
    },
    {
      "x": -1,
      "y": 5,
      "z": -3,
      "name": "Wood_Tropicalwood_Planks_Half",
      "rotation": 4
    },
    {
      "x": -1,
      "y": 6,
      "z": -3,
      "name": "Wood_Tropicalwood_Planks_Half",
      "rotation": 4
    },
    {
      "x": -1,
      "y": 7,
      "z": -3,
      "name": "Wood_Tropicalwood_Planks_Half",
      "rotation": 4
    },
    {
      "x": -1,
      "y": 8,
      "z": -3,
      "name": "Wood_Tropicalwood_Decorative"
    },
    {
      "x": -1,
      "y": 9,
      "z": -3,
      "name": "Wood_Tropicalwood_Roof",
      "rotation": 2
    },
    {
      "x": -1,
      "y": 4,
      "z": -2,
      "name": "Wood_Tropicalwood_Planks_Half",
      "rotation": 8
    },
    {
      "x": -1,
      "y": 5,
      "z": -2,
      "name": "Furniture_Jungle_Pot"
    },
    {
      "x": -1,
      "y": 8,
      "z": -2,
      "name": "Furniture_Jungle_Shelf",
      "rotation": 1
    },
    {
      "x": -1,
      "y": 9,
      "z": -2,
      "name": "Wood_Tropicalwood_Planks_Half",
      "rotation": 8
    },
    {
      "x": -1,
      "y": 10,
      "z": -2,
      "name": "*Wood_Tropicalwood_Roof_Shallow_State_Definitions_Corner_Left",
      "rotation": 2
    },
    {
      "x": -1,
      "y": 4,
      "z": -1,
      "name": "Wood_Tropicalwood_Planks_Half",
      "rotation": 8
    },
    {
      "x": -1,
      "y": 8,
      "z": -1,
      "name": "Furniture_Jungle_Shelf",
      "rotation": 1
    },
    {
      "x": -1,
      "y": 10,
      "z": -1,
      "name": "*Wood_Tropicalwood_Roof_Shallow_State_Definitions_Corner_Left",
      "filler": 32,
      "rotation": 2
    },
    {
      "x": -1,
      "y": 4,
      "z": 0,
      "name": "Wood_Tropicalwood_Planks_Half",
      "rotation": 8
    },
    {
      "x": -1,
      "y": 8,
      "z": 0,
      "name": "Furniture_Jungle_Shelf",
      "rotation": 1
    },
    {
      "x": -1,
      "y": 10,
      "z": 0,
      "name": "*Wood_Tropicalwood_Roof_Shallow_State_Definitions_Corner_Left",
      "filler": 992,
      "rotation": 3
    },
    {
      "x": -1,
      "y": 4,
      "z": 1,
      "name": "Wood_Tropicalwood_Planks_Half",
      "rotation": 8
    },
    {
      "x": -1,
      "y": 5,
      "z": 1,
      "name": "*Furniture_Jungle_Candle_State_Definitions_Off"
    },
    {
      "x": -1,
      "y": 9,
      "z": 1,
      "name": "Wood_Tropicalwood_Planks_Half",
      "rotation": 8
    },
    {
      "x": -1,
      "y": 10,
      "z": 1,
      "name": "*Wood_Tropicalwood_Roof_Shallow_State_Definitions_Corner_Left",
      "rotation": 3
    },
    {
      "x": -1,
      "y": 4,
      "z": 2,
      "name": "Wood_Tropicalwood_Planks_Half",
      "rotation": 8
    },
    {
      "x": -1,
      "y": 5,
      "z": 2,
      "name": "Wood_Tropicalwood_Planks_Half",
      "rotation": 6
    },
    {
      "x": -1,
      "y": 6,
      "z": 2,
      "name": "Wood_Tropicalwood_Planks_Half",
      "rotation": 6
    },
    {
      "x": -1,
      "y": 7,
      "z": 2,
      "name": "Wood_Tropicalwood_Planks_Half",
      "rotation": 6
    },
    {
      "x": -1,
      "y": 8,
      "z": 2,
      "name": "Wood_Tropicalwood_Decorative"
    },
    {
      "x": -1,
      "y": 9,
      "z": 2,
      "name": "Wood_Tropicalwood_Roof"
    },
    {
      "x": -1,
      "y": 4,
      "z": 3,
      "name": "Wood_Tropicalwood_Planks_Half",
      "rotation": 8
    },
    {
      "x": -1,
      "y": 7,
      "z": 3,
      "name": "Wood_Tropicalwood_Roof_Steep"
    },
    {
      "x": -1,
      "y": 8,
      "z": 3,
      "name": "Wood_Tropicalwood_Roof_Steep",
      "filler": 1024
    },
    {
      "x": -1,
      "y": 4,
      "z": 4,
      "name": "Wood_Tropicalwood_Planks_Half",
      "rotation": 8
    },
    {
      "x": 0,
      "y": 4,
      "z": -4,
      "name": "Wood_Tropicalwood_Planks_Half",
      "rotation": 8
    },
    {
      "x": 0,
      "y": 7,
      "z": -4,
      "name": "Wood_Tropicalwood_Roof_Steep",
      "rotation": 2
    },
    {
      "x": 0,
      "y": 8,
      "z": -4,
      "name": "Wood_Tropicalwood_Roof_Steep",
      "filler": 1024,
      "rotation": 2
    },
    {
      "x": 0,
      "y": 4,
      "z": -3,
      "name": "Wood_Tropicalwood_Planks_Half",
      "rotation": 8
    },
    {
      "x": 0,
      "y": 5,
      "z": -3,
      "name": "Wood_Tropicalwood_Planks_Half",
      "rotation": 4
    },
    {
      "x": 0,
      "y": 6,
      "z": -3,
      "name": "Wood_Tropicalwood_Fence"
    },
    {
      "x": 0,
      "y": 7,
      "z": -3,
      "name": "Wood_Tropicalwood_Planks_Half",
      "rotation": 4
    },
    {
      "x": 0,
      "y": 8,
      "z": -3,
      "name": "Wood_Tropicalwood_Decorative"
    },
    {
      "x": 0,
      "y": 9,
      "z": -3,
      "name": "Wood_Tropicalwood_Roof",
      "rotation": 2
    },
    {
      "x": 0,
      "y": 4,
      "z": -2,
      "name": "Wood_Tropicalwood_Planks_Half",
      "rotation": 8
    },
    {
      "x": 0,
      "y": 10,
      "z": -2,
      "name": "*Wood_Tropicalwood_Roof_Shallow_State_Definitions_Corner_Left",
      "filler": 1,
      "rotation": 2
    },
    {
      "x": 0,
      "y": 4,
      "z": -1,
      "name": "Wood_Tropicalwood_Planks_Half",
      "rotation": 8
    },
    {
      "x": 0,
      "y": 10,
      "z": -1,
      "name": "*Wood_Tropicalwood_Roof_Shallow_State_Definitions_Corner_Left",
      "filler": 33,
      "rotation": 2
    },
    {
      "x": 0,
      "y": 4,
      "z": 0,
      "name": "Wood_Tropicalwood_Planks_Half",
      "rotation": 8
    },
    {
      "x": 0,
      "y": 10,
      "z": 0,
      "name": "*Wood_Tropicalwood_Roof_Shallow_State_Definitions_Corner_Left",
      "filler": 993,
      "rotation": 3
    },
    {
      "x": 0,
      "y": 4,
      "z": 1,
      "name": "Wood_Tropicalwood_Planks_Half",
      "rotation": 8
    },
    {
      "x": 0,
      "y": 10,
      "z": 1,
      "name": "*Wood_Tropicalwood_Roof_Shallow_State_Definitions_Corner_Left",
      "filler": 1,
      "rotation": 3
    },
    {
      "x": 0,
      "y": 4,
      "z": 2,
      "name": "Wood_Tropicalwood_Planks_Half",
      "rotation": 8
    },
    {
      "x": 0,
      "y": 5,
      "z": 2,
      "name": "*Furniture_Jungle_Door_State_Definitions_CloseDoorOut"
    },
    {
      "x": 0,
      "y": 6,
      "z": 2,
      "name": "*Furniture_Jungle_Door_State_Definitions_CloseDoorOut",
      "filler": 1024
    },
    {
      "x": 0,
      "y": 7,
      "z": 2,
      "name": "Wood_Tropicalwood_Planks_Half",
      "rotation": 6
    },
    {
      "x": 0,
      "y": 8,
      "z": 2,
      "name": "Wood_Tropicalwood_Decorative"
    },
    {
      "x": 0,
      "y": 9,
      "z": 2,
      "name": "Wood_Tropicalwood_Roof"
    },
    {
      "x": 0,
      "y": 4,
      "z": 3,
      "name": "Wood_Tropicalwood_Planks_Half",
      "rotation": 8
    },
    {
      "x": 0,
      "y": 7,
      "z": 3,
      "name": "Wood_Tropicalwood_Roof_Steep"
    },
    {
      "x": 0,
      "y": 8,
      "z": 3,
      "name": "Wood_Tropicalwood_Roof_Steep",
      "filler": 1024
    },
    {
      "x": 0,
      "y": 4,
      "z": 4,
      "name": "Wood_Tropicalwood_Planks_Half",
      "rotation": 8
    },
    {
      "x": 1,
      "y": 4,
      "z": -4,
      "name": "Wood_Tropicalwood_Planks_Half",
      "rotation": 8
    },
    {
      "x": 1,
      "y": 7,
      "z": -4,
      "name": "Wood_Tropicalwood_Roof_Steep",
      "rotation": 2
    },
    {
      "x": 1,
      "y": 8,
      "z": -4,
      "name": "Wood_Tropicalwood_Roof_Steep",
      "filler": 1024,
      "rotation": 2
    },
    {
      "x": 1,
      "y": 4,
      "z": -3,
      "name": "Wood_Tropicalwood_Planks_Half",
      "rotation": 8
    },
    {
      "x": 1,
      "y": 5,
      "z": -3,
      "name": "Wood_Tropicalwood_Planks_Half",
      "rotation": 4
    },
    {
      "x": 1,
      "y": 6,
      "z": -3,
      "name": "Wood_Tropicalwood_Fence"
    },
    {
      "x": 1,
      "y": 7,
      "z": -3,
      "name": "Wood_Tropicalwood_Planks_Half",
      "rotation": 4
    },
    {
      "x": 1,
      "y": 8,
      "z": -3,
      "name": "Wood_Tropicalwood_Decorative"
    },
    {
      "x": 1,
      "y": 9,
      "z": -3,
      "name": "Wood_Tropicalwood_Roof",
      "rotation": 2
    },
    {
      "x": 1,
      "y": 4,
      "z": -2,
      "name": "Wood_Tropicalwood_Planks_Half",
      "rotation": 8
    },
    {
      "x": 1,
      "y": 10,
      "z": -2,
      "name": "*Wood_Tropicalwood_Roof_Shallow_State_Definitions_Corner_Left",
      "filler": 31,
      "rotation": 1
    },
    {
      "x": 1,
      "y": 4,
      "z": -1,
      "name": "Wood_Tropicalwood_Planks_Half",
      "rotation": 8
    },
    {
      "x": 1,
      "y": 10,
      "z": -1,
      "name": "*Wood_Tropicalwood_Roof_Shallow_State_Definitions_Corner_Left",
      "filler": 63,
      "rotation": 1
    },
    {
      "x": 1,
      "y": 4,
      "z": 0,
      "name": "Wood_Tropicalwood_Planks_Half",
      "rotation": 8
    },
    {
      "x": 1,
      "y": 10,
      "z": 0,
      "name": "*Wood_Tropicalwood_Roof_Shallow_State_Definitions_Corner_Left",
      "filler": 1023
    },
    {
      "x": 1,
      "y": 4,
      "z": 1,
      "name": "Wood_Tropicalwood_Planks_Half",
      "rotation": 8
    },
    {
      "x": 1,
      "y": 10,
      "z": 1,
      "name": "*Wood_Tropicalwood_Roof_Shallow_State_Definitions_Corner_Left",
      "filler": 31
    },
    {
      "x": 1,
      "y": 4,
      "z": 2,
      "name": "Wood_Tropicalwood_Planks_Half",
      "rotation": 8
    },
    {
      "x": 1,
      "y": 5,
      "z": 2,
      "name": "Wood_Tropicalwood_Planks_Half",
      "rotation": 6
    },
    {
      "x": 1,
      "y": 6,
      "z": 2,
      "name": "Wood_Tropicalwood_Planks_Half",
      "rotation": 6
    },
    {
      "x": 1,
      "y": 7,
      "z": 2,
      "name": "Wood_Tropicalwood_Planks_Half",
      "rotation": 6
    },
    {
      "x": 1,
      "y": 8,
      "z": 2,
      "name": "Wood_Tropicalwood_Decorative"
    },
    {
      "x": 1,
      "y": 9,
      "z": 2,
      "name": "Wood_Tropicalwood_Roof"
    },
    {
      "x": 1,
      "y": 4,
      "z": 3,
      "name": "Wood_Tropicalwood_Planks_Half",
      "rotation": 8
    },
    {
      "x": 1,
      "y": 5,
      "z": 3,
      "name": "Furniture_Jungle_Bench",
      "filler": 31
    },
    {
      "x": 1,
      "y": 7,
      "z": 3,
      "name": "Wood_Tropicalwood_Roof_Steep"
    },
    {
      "x": 1,
      "y": 8,
      "z": 3,
      "name": "Wood_Tropicalwood_Roof_Steep",
      "filler": 1024
    },
    {
      "x": 1,
      "y": 4,
      "z": 4,
      "name": "Wood_Tropicalwood_Planks_Half",
      "rotation": 8
    },
    {
      "x": 2,
      "y": 4,
      "z": -4,
      "name": "Wood_Tropicalwood_Planks_Half",
      "rotation": 8
    },
    {
      "x": 2,
      "y": 7,
      "z": -4,
      "name": "Wood_Tropicalwood_Roof_Steep",
      "rotation": 2
    },
    {
      "x": 2,
      "y": 8,
      "z": -4,
      "name": "Wood_Tropicalwood_Roof_Steep",
      "filler": 1024,
      "rotation": 2
    },
    {
      "x": 2,
      "y": 4,
      "z": -3,
      "name": "Wood_Tropicalwood_Planks_Half",
      "rotation": 8
    },
    {
      "x": 2,
      "y": 5,
      "z": -3,
      "name": "Wood_Tropicalwood_Planks_Half",
      "rotation": 4
    },
    {
      "x": 2,
      "y": 6,
      "z": -3,
      "name": "Wood_Tropicalwood_Planks_Half",
      "rotation": 4
    },
    {
      "x": 2,
      "y": 7,
      "z": -3,
      "name": "Wood_Tropicalwood_Planks_Half",
      "rotation": 4
    },
    {
      "x": 2,
      "y": 8,
      "z": -3,
      "name": "Wood_Tropicalwood_Decorative"
    },
    {
      "x": 2,
      "y": 9,
      "z": -3,
      "name": "Wood_Tropicalwood_Roof",
      "rotation": 2
    },
    {
      "x": 2,
      "y": 4,
      "z": -2,
      "name": "Wood_Tropicalwood_Planks_Half",
      "rotation": 8
    },
    {
      "x": 2,
      "y": 9,
      "z": -2,
      "name": "Wood_Tropicalwood_Planks_Half",
      "rotation": 8
    },
    {
      "x": 2,
      "y": 10,
      "z": -2,
      "name": "*Wood_Tropicalwood_Roof_Shallow_State_Definitions_Corner_Left",
      "rotation": 1
    },
    {
      "x": 2,
      "y": 4,
      "z": -1,
      "name": "Wood_Tropicalwood_Planks_Half",
      "rotation": 8
    },
    {
      "x": 2,
      "y": 10,
      "z": -1,
      "name": "*Wood_Tropicalwood_Roof_Shallow_State_Definitions_Corner_Left",
      "filler": 32,
      "rotation": 1
    },
    {
      "x": 2,
      "y": 4,
      "z": 0,
      "name": "Wood_Tropicalwood_Planks_Half",
      "rotation": 8
    },
    {
      "x": 2,
      "y": 5,
      "z": 0,
      "name": "Furniture_Crude_Bed",
      "filler": 992,
      "rotation": 2
    },
    {
      "x": 2,
      "y": 10,
      "z": 0,
      "name": "*Wood_Tropicalwood_Roof_Shallow_State_Definitions_Corner_Left",
      "filler": 992
    },
    {
      "x": 2,
      "y": 4,
      "z": 1,
      "name": "Wood_Tropicalwood_Planks_Half",
      "rotation": 8
    },
    {
      "x": 2,
      "y": 5,
      "z": 1,
      "name": "Furniture_Crude_Bed",
      "components": {
        "Components": {
          "PlacedByInteraction": {
            "WhoPlacedUuid": {
              "$binary": "JMPNY5cWR9+IOfPEr8/h7w==",
              "$type": "04"
            }
          },
          "RespawnBlock": {}
        }
      },
      "rotation": 2
    },
    {
      "x": 2,
      "y": 9,
      "z": 1,
      "name": "Wood_Tropicalwood_Planks_Half",
      "rotation": 8
    },
    {
      "x": 2,
      "y": 10,
      "z": 1,
      "name": "*Wood_Tropicalwood_Roof_Shallow_State_Definitions_Corner_Left"
    },
    {
      "x": 2,
      "y": 4,
      "z": 2,
      "name": "Wood_Tropicalwood_Planks_Half",
      "rotation": 8
    },
    {
      "x": 2,
      "y": 5,
      "z": 2,
      "name": "Wood_Tropicalwood_Planks_Half",
      "rotation": 6
    },
    {
      "x": 2,
      "y": 6,
      "z": 2,
      "name": "Wood_Tropicalwood_Planks_Half",
      "rotation": 6
    },
    {
      "x": 2,
      "y": 7,
      "z": 2,
      "name": "Wood_Tropicalwood_Planks_Half",
      "rotation": 6
    },
    {
      "x": 2,
      "y": 8,
      "z": 2,
      "name": "Wood_Tropicalwood_Decorative"
    },
    {
      "x": 2,
      "y": 9,
      "z": 2,
      "name": "Wood_Tropicalwood_Roof"
    },
    {
      "x": 2,
      "y": 4,
      "z": 3,
      "name": "Wood_Tropicalwood_Planks_Half",
      "rotation": 8
    },
    {
      "x": 2,
      "y": 5,
      "z": 3,
      "name": "Furniture_Jungle_Bench",
      "components": {
        "Components": {}
      }
    },
    {
      "x": 2,
      "y": 7,
      "z": 3,
      "name": "Wood_Tropicalwood_Roof_Steep"
    },
    {
      "x": 2,
      "y": 8,
      "z": 3,
      "name": "Wood_Tropicalwood_Roof_Steep",
      "filler": 1024
    },
    {
      "x": 2,
      "y": 4,
      "z": 4,
      "name": "Wood_Tropicalwood_Planks_Half",
      "rotation": 8
    },
    {
      "x": 3,
      "y": 4,
      "z": -4,
      "name": "Wood_Tropicalwood_Planks_Half",
      "rotation": 8
    },
    {
      "x": 3,
      "y": 7,
      "z": -4,
      "name": "Wood_Tropicalwood_Roof_Steep",
      "rotation": 2
    },
    {
      "x": 3,
      "y": 8,
      "z": -4,
      "name": "Wood_Tropicalwood_Roof_Steep",
      "filler": 1024,
      "rotation": 2
    },
    {
      "x": 3,
      "y": 4,
      "z": -3,
      "name": "Wood_Tropicalwood_Planks_Half",
      "rotation": 8
    },
    {
      "x": 3,
      "y": 5,
      "z": -3,
      "name": "Wood_Bamboo_Trunk_Deco",
      "support": 15
    },
    {
      "x": 3,
      "y": 6,
      "z": -3,
      "name": "Wood_Bamboo_Trunk_Deco",
      "support": 15
    },
    {
      "x": 3,
      "y": 7,
      "z": -3,
      "name": "Wood_Bamboo_Trunk_Deco",
      "support": 15
    },
    {
      "x": 3,
      "y": 8,
      "z": -3,
      "name": "Wood_Bamboo_Trunk_Deco",
      "support": 15
    },
    {
      "x": 3,
      "y": 9,
      "z": -3,
      "name": "*Wood_Tropicalwood_Roof_State_Definitions_Corner_Left",
      "rotation": 1
    },
    {
      "x": 3,
      "y": 4,
      "z": -2,
      "name": "Wood_Tropicalwood_Planks_Half",
      "rotation": 8
    },
    {
      "x": 3,
      "y": 5,
      "z": -2,
      "name": "Wood_Tropicalwood_Planks_Half",
      "rotation": 7
    },
    {
      "x": 3,
      "y": 6,
      "z": -2,
      "name": "Wood_Tropicalwood_Planks_Half",
      "rotation": 7
    },
    {
      "x": 3,
      "y": 7,
      "z": -2,
      "name": "Wood_Tropicalwood_Planks_Half",
      "rotation": 7
    },
    {
      "x": 3,
      "y": 8,
      "z": -2,
      "name": "Wood_Tropicalwood_Decorative"
    },
    {
      "x": 3,
      "y": 9,
      "z": -2,
      "name": "Wood_Tropicalwood_Roof",
      "rotation": 1
    },
    {
      "x": 3,
      "y": 4,
      "z": -1,
      "name": "Wood_Tropicalwood_Planks_Half",
      "rotation": 8
    },
    {
      "x": 3,
      "y": 5,
      "z": -1,
      "name": "Wood_Tropicalwood_Planks_Half",
      "rotation": 7
    },
    {
      "x": 3,
      "y": 6,
      "z": -1,
      "name": "Wood_Tropicalwood_Fence",
      "rotation": 3
    },
    {
      "x": 3,
      "y": 7,
      "z": -1,
      "name": "Wood_Tropicalwood_Planks_Half",
      "rotation": 7
    },
    {
      "x": 3,
      "y": 8,
      "z": -1,
      "name": "Wood_Tropicalwood_Decorative"
    },
    {
      "x": 3,
      "y": 9,
      "z": -1,
      "name": "Wood_Tropicalwood_Roof",
      "rotation": 1
    },
    {
      "x": 3,
      "y": 4,
      "z": 0,
      "name": "Wood_Tropicalwood_Planks_Half",
      "rotation": 8
    },
    {
      "x": 3,
      "y": 5,
      "z": 0,
      "name": "Wood_Tropicalwood_Planks_Half",
      "rotation": 7
    },
    {
      "x": 3,
      "y": 6,
      "z": 0,
      "name": "Wood_Tropicalwood_Fence",
      "rotation": 3
    },
    {
      "x": 3,
      "y": 7,
      "z": 0,
      "name": "Wood_Tropicalwood_Planks_Half",
      "rotation": 7
    },
    {
      "x": 3,
      "y": 8,
      "z": 0,
      "name": "Wood_Tropicalwood_Decorative"
    },
    {
      "x": 3,
      "y": 9,
      "z": 0,
      "name": "Wood_Tropicalwood_Roof",
      "rotation": 1
    },
    {
      "x": 3,
      "y": 4,
      "z": 1,
      "name": "Wood_Tropicalwood_Planks_Half",
      "rotation": 8
    },
    {
      "x": 3,
      "y": 5,
      "z": 1,
      "name": "Wood_Tropicalwood_Planks_Half",
      "rotation": 7
    },
    {
      "x": 3,
      "y": 6,
      "z": 1,
      "name": "Wood_Tropicalwood_Planks_Half",
      "rotation": 7
    },
    {
      "x": 3,
      "y": 7,
      "z": 1,
      "name": "Wood_Tropicalwood_Planks_Half",
      "rotation": 7
    },
    {
      "x": 3,
      "y": 8,
      "z": 1,
      "name": "Wood_Tropicalwood_Decorative"
    },
    {
      "x": 3,
      "y": 9,
      "z": 1,
      "name": "Wood_Tropicalwood_Roof",
      "rotation": 1
    },
    {
      "x": 3,
      "y": 4,
      "z": 2,
      "name": "Wood_Tropicalwood_Planks_Half",
      "rotation": 8
    },
    {
      "x": 3,
      "y": 5,
      "z": 2,
      "name": "Wood_Bamboo_Trunk_Deco",
      "support": 15
    },
    {
      "x": 3,
      "y": 6,
      "z": 2,
      "name": "Wood_Bamboo_Trunk_Deco",
      "support": 15
    },
    {
      "x": 3,
      "y": 7,
      "z": 2,
      "name": "Wood_Bamboo_Trunk_Deco",
      "support": 15
    },
    {
      "x": 3,
      "y": 8,
      "z": 2,
      "name": "Wood_Bamboo_Trunk_Deco",
      "support": 15
    },
    {
      "x": 3,
      "y": 9,
      "z": 2,
      "name": "*Wood_Tropicalwood_Roof_State_Definitions_Corner_Right",
      "rotation": 1
    },
    {
      "x": 3,
      "y": 4,
      "z": 3,
      "name": "Wood_Tropicalwood_Planks_Half",
      "rotation": 8
    },
    {
      "x": 3,
      "y": 7,
      "z": 3,
      "name": "Wood_Tropicalwood_Roof_Steep"
    },
    {
      "x": 3,
      "y": 8,
      "z": 3,
      "name": "Wood_Tropicalwood_Roof_Steep",
      "filler": 1024
    },
    {
      "x": 3,
      "y": 4,
      "z": 4,
      "name": "Wood_Tropicalwood_Planks_Half",
      "rotation": 8
    },
    {
      "x": 4,
      "y": 0,
      "z": -4,
      "name": "Wood_Bamboo_Branch_Long_Deco",
      "support": 15
    },
    {
      "x": 4,
      "y": 1,
      "z": -4,
      "name": "Wood_Bamboo_Branch_Long_Deco",
      "support": 15
    },
    {
      "x": 4,
      "y": 2,
      "z": -4,
      "name": "Wood_Bamboo_Branch_Long_Deco",
      "support": 15
    },
    {
      "x": 4,
      "y": 3,
      "z": -4,
      "name": "Wood_Bamboo_Branch_Long_Deco",
      "support": 15
    },
    {
      "x": 4,
      "y": 4,
      "z": -4,
      "name": "Wood_Bamboo_Trunk_Deco",
      "support": 15
    },
    {
      "x": 4,
      "y": 7,
      "z": -4,
      "name": "*Wood_Tropicalwood_Roof_Steep_State_Definitions_Corner_Right",
      "rotation": 2
    },
    {
      "x": 4,
      "y": 8,
      "z": -4,
      "name": "*Wood_Tropicalwood_Roof_Steep_State_Definitions_Corner_Right",
      "filler": 1024,
      "rotation": 2
    },
    {
      "x": 4,
      "y": 4,
      "z": -3,
      "name": "Wood_Tropicalwood_Planks_Half",
      "rotation": 8
    },
    {
      "x": 4,
      "y": 7,
      "z": -3,
      "name": "Wood_Tropicalwood_Roof_Steep",
      "rotation": 1
    },
    {
      "x": 4,
      "y": 8,
      "z": -3,
      "name": "Wood_Tropicalwood_Roof_Steep",
      "filler": 1024,
      "rotation": 1
    },
    {
      "x": 4,
      "y": 4,
      "z": -2,
      "name": "Wood_Tropicalwood_Planks_Half",
      "rotation": 8
    },
    {
      "x": 4,
      "y": 7,
      "z": -2,
      "name": "Wood_Tropicalwood_Roof_Steep",
      "rotation": 1
    },
    {
      "x": 4,
      "y": 8,
      "z": -2,
      "name": "Wood_Tropicalwood_Roof_Steep",
      "filler": 1024,
      "rotation": 1
    },
    {
      "x": 4,
      "y": 4,
      "z": -1,
      "name": "Wood_Tropicalwood_Planks_Half",
      "rotation": 8
    },
    {
      "x": 4,
      "y": 7,
      "z": -1,
      "name": "Wood_Tropicalwood_Roof_Steep",
      "rotation": 1
    },
    {
      "x": 4,
      "y": 8,
      "z": -1,
      "name": "Wood_Tropicalwood_Roof_Steep",
      "filler": 1024,
      "rotation": 1
    },
    {
      "x": 4,
      "y": 4,
      "z": 0,
      "name": "Wood_Tropicalwood_Planks_Half",
      "rotation": 8
    },
    {
      "x": 4,
      "y": 7,
      "z": 0,
      "name": "Wood_Tropicalwood_Roof_Steep",
      "rotation": 1
    },
    {
      "x": 4,
      "y": 8,
      "z": 0,
      "name": "Wood_Tropicalwood_Roof_Steep",
      "filler": 1024,
      "rotation": 1
    },
    {
      "x": 4,
      "y": 4,
      "z": 1,
      "name": "Wood_Tropicalwood_Planks_Half",
      "rotation": 8
    },
    {
      "x": 4,
      "y": 7,
      "z": 1,
      "name": "Wood_Tropicalwood_Roof_Steep",
      "rotation": 1
    },
    {
      "x": 4,
      "y": 8,
      "z": 1,
      "name": "Wood_Tropicalwood_Roof_Steep",
      "filler": 1024,
      "rotation": 1
    },
    {
      "x": 4,
      "y": 4,
      "z": 2,
      "name": "Wood_Tropicalwood_Planks_Half",
      "rotation": 8
    },
    {
      "x": 4,
      "y": 7,
      "z": 2,
      "name": "Wood_Tropicalwood_Roof_Steep",
      "rotation": 1
    },
    {
      "x": 4,
      "y": 8,
      "z": 2,
      "name": "Wood_Tropicalwood_Roof_Steep",
      "filler": 1024,
      "rotation": 1
    },
    {
      "x": 4,
      "y": 4,
      "z": 3,
      "name": "Wood_Tropicalwood_Planks_Half",
      "rotation": 8
    },
    {
      "x": 4,
      "y": 7,
      "z": 3,
      "name": "*Wood_Tropicalwood_Roof_Steep_State_Definitions_Corner_Right",
      "rotation": 1
    },
    {
      "x": 4,
      "y": 8,
      "z": 3,
      "name": "*Wood_Tropicalwood_Roof_Steep_State_Definitions_Corner_Right",
      "filler": 1024,
      "rotation": 1
    },
    {
      "x": 4,
      "y": 0,
      "z": 4,
      "name": "Wood_Bamboo_Branch_Long_Deco",
      "support": 15
    },
    {
      "x": 4,
      "y": 1,
      "z": 4,
      "name": "Wood_Bamboo_Branch_Long_Deco",
      "support": 15
    },
    {
      "x": 4,
      "y": 2,
      "z": 4,
      "name": "Wood_Bamboo_Branch_Long_Deco",
      "support": 15
    },
    {
      "x": 4,
      "y": 3,
      "z": 4,
      "name": "Wood_Bamboo_Branch_Long_Deco",
      "support": 15
    },
    {
      "x": 4,
      "y": 4,
      "z": 4,
      "name": "Wood_Bamboo_Trunk_Deco",
      "support": 15
    },
    {
      "x": 4,
      "y": 0,
      "z": 5,
      "name": "Furniture_Jungle_Ladder"
    },
    {
      "x": 4,
      "y": 1,
      "z": 5,
      "name": "Furniture_Jungle_Ladder"
    },
    {
      "x": 4,
      "y": 2,
      "z": 5,
      "name": "Furniture_Jungle_Ladder"
    },
    {
      "x": 4,
      "y": 3,
      "z": 5,
      "name": "Furniture_Jungle_Ladder"
    },
    {
      "x": 4,
      "y": 4,
      "z": 5,
      "name": "Furniture_Jungle_Ladder"
    }
  ]
}