{
  "version": 8,
  "blockIdVersion": 11,
  "anchorX": 0,
  "anchorY": 0,
  "anchorZ": 0,
  "blocks": [
    {
      "x": -14,
      "y": -16,
      "z": -19,
      "name": "Rock_Sandstone_Brick_Smooth_Half",
      "rotation": 7
    },
    {
      "x": -14,
      "y": -13,
      "z": -19,
      "name": "Rock_Sandstone_Cobble_Roof_Hollow",
      "rotation": 3
    },
    {
      "x": -14,
      "y": -16,
      "z": -18,
      "name": "Rock_Sandstone_Brick_Smooth_Half",
      "rotation": 7
    },
    {
      "x": -14,
      "y": -13,
      "z": -18,
      "name": "Rock_Sandstone_Cobble_Roof_Hollow",
      "rotation": 3
    },
    {
      "x": -14,
      "y": -16,
      "z": -17,
      "name": "Rock_Sandstone_Brick_Smooth_Half",
      "rotation": 7
    },
    {
      "x": -14,
      "y": -13,
      "z": -17,
      "name": "Rock_Sandstone_Cobble_Roof_Hollow",
      "rotation": 3
    },
    {
      "x": -13,
      "y": -16,
      "z": -21,
      "name": "Rock_Sandstone_Brick_Half",
      "rotation": 6
    },
    {
      "x": -13,
      "y": -15,
      "z": -21,
      "name": "Rock_Sandstone_Brick_Half",
      "rotation": 6
    },
    {
      "x": -13,
      "y": -14,
      "z": -21,
      "name": "Rock_Sandstone_Brick"
    },
    {
      "x": -13,
      "y": -13,
      "z": -21,
      "name": "Rock_Sandstone_Brick"
    },
    {
      "x": -13,
      "y": -12,
      "z": -21,
      "name": "Rock_Sandstone_Brick"
    },
    {
      "x": -13,
      "y": -11,
      "z": -21,
      "name": "Rock_Sandstone_Brick_Ornate"
    },
    {
      "x": -13,
      "y": -10,
      "z": -21,
      "name": "Rock_Sandstone_Brick"
    },
    {
      "x": -13,
      "y": -9,
      "z": -21,
      "name": "Rock_Sandstone_Brick_Half"
    },
    {
      "x": -13,
      "y": -23,
      "z": -20,
      "name": "Rock_Sandstone_Cobble"
    },
    {
      "x": -13,
      "y": -22,
      "z": -20,
      "name": "Rock_Sandstone_Cobble"
    },
    {
      "x": -13,
      "y": -21,
      "z": -20,
      "name": "Rock_Sandstone_Cobble"
    },
    {
      "x": -13,
      "y": -20,
      "z": -20,
      "name": "Rock_Sandstone_Cobble"
    },
    {
      "x": -13,
      "y": -19,
      "z": -20,
      "name": "Rock_Sandstone_Cobble"
    },
    {
      "x": -13,
      "y": -18,
      "z": -20,
      "name": "Rock_Sandstone_Cobble"
    },
    {
      "x": -13,
      "y": -17,
      "z": -20,
      "name": "Rock_Sandstone_Brick"
    },
    {
      "x": -13,
      "y": -16,
      "z": -20,
      "name": "Rock_Sandstone_White_Brick"
    },
    {
      "x": -13,
      "y": -15,
      "z": -20,
      "name": "Rock_Sandstone_White_Brick"
    },
    {
      "x": -13,
      "y": -14,
      "z": -20,
      "name": "Rock_Sandstone_White_Brick"
    },
    {
      "x": -13,
      "y": -13,
      "z": -20,
      "name": "Rock_Sandstone_White_Brick"
    },
    {
      "x": -13,
      "y": -12,
      "z": -20,
      "name": "Rock_Sandstone_White_Brick"
    },
    {
      "x": -13,
      "y": -11,
      "z": -20,
      "name": "Rock_Sandstone_Brick_Ornate"
    },
    {
      "x": -13,
      "y": -10,
      "z": -20,
      "name": "Rock_Sandstone_White_Cobble"
    },
    {
      "x": -13,
      "y": -9,
      "z": -20,
      "name": "Rock_Sandstone_White_Cobble_Half"
    },
    {
      "x": -13,
      "y": -23,
      "z": -19,
      "name": "Rock_Sandstone_Cobble"
    },
    {
      "x": -13,
      "y": -22,
      "z": -19,
      "name": "Rock_Sandstone_Cobble"
    },
    {
      "x": -13,
      "y": -21,
      "z": -19,
      "name": "Rock_Sandstone_Cobble"
    },
    {
      "x": -13,
      "y": -20,
      "z": -19,
      "name": "Rock_Sandstone_Cobble"
    },
    {
      "x": -13,
      "y": -19,
      "z": -19,
      "name": "Rock_Sandstone_Cobble"
    },
    {
      "x": -13,
      "y": -18,
      "z": -19,
      "name": "Rock_Sandstone_Cobble"
    },
    {
      "x": -13,
      "y": -17,
      "z": -19,
      "name": "Rock_Sandstone_Brick"
    },
    {
      "x": -13,
      "y": -16,
      "z": -19,
      "name": "Rock_Sandstone_White_Brick"
    },
    {
      "x": -13,
      "y": -15,
      "z": -19,
      "name": "Furniture_Desert_Window",
      "rotation": 1
    },
    {
      "x": -13,
      "y": -14,
      "z": -19,
      "name": "Wood_Drywood_Beam"
    },
    {
      "x": -13,
      "y": -13,
      "z": -19,
      "name": "Wood_Dry_Trunk",
      "rotation": 4
    },
    {
      "x": -13,
      "y": -12,
      "z": -19,
      "name": "Rock_Sandstone_White_Brick"
    },
    {
      "x": -13,
      "y": -11,
      "z": -19,
      "name": "Rock_Sandstone_Brick_Ornate"
    },
    {
      "x": -13,
      "y": -10,
      "z": -19,
      "name": "Rock_Sandstone_White_Cobble"
    },
    {
      "x": -13,
      "y": -9,
      "z": -19,
      "name": "Rock_Sandstone_White_Cobble_Half"
    },
    {
      "x": -13,
      "y": -23,
      "z": -18,
      "name": "Rock_Sandstone_Cobble"
    },
    {
      "x": -13,
      "y": -22,
      "z": -18,
      "name": "Rock_Sandstone_Cobble"
    },
    {
      "x": -13,
      "y": -21,
      "z": -18,
      "name": "Rock_Sandstone_Cobble"
    },
    {
      "x": -13,
      "y": -20,
      "z": -18,
      "name": "Rock_Sandstone_Cobble"
    },
    {
      "x": -13,
      "y": -19,
      "z": -18,
      "name": "Rock_Sandstone_Cobble"
    },
    {
      "x": -13,
      "y": -18,
      "z": -18,
      "name": "Rock_Sandstone_Cobble"
    },
    {
      "x": -13,
      "y": -17,
      "z": -18,
      "name": "Rock_Sandstone_Brick"
    },
    {
      "x": -13,
      "y": -16,
      "z": -18,
      "name": "Rock_Sandstone_White_Brick"
    },
    {
      "x": -13,
      "y": -15,
      "z": -18,
      "name": "Furniture_Desert_Window",
      "rotation": 1
    },
    {
      "x": -13,
      "y": -14,
      "z": -18,
      "name": "Furniture_Desert_Window",
      "rotation": 1
    },
    {
      "x": -13,
      "y": -13,
      "z": -18,
      "name": "Wood_Dry_Trunk",
      "rotation": 4
    },
    {
      "x": -13,
      "y": -12,
      "z": -18,
      "name": "Rock_Sandstone_White_Brick"
    },
    {
      "x": -13,
      "y": -11,
      "z": -18,
      "name": "Rock_Sandstone_Brick_Ornate"
    },
    {
      "x": -13,
      "y": -10,
      "z": -18,
      "name": "Rock_Sandstone_White_Cobble"
    },
    {
      "x": -13,
      "y": -23,
      "z": -17,
      "name": "Rock_Sandstone_Cobble"
    },
    {
      "x": -13,
      "y": -22,
      "z": -17,
      "name": "Rock_Sandstone_Cobble"
    },
    {
      "x": -13,
      "y": -21,
      "z": -17,
      "name": "Rock_Sandstone_Cobble"
    },
    {
      "x": -13,
      "y": -20,
      "z": -17,
      "name": "Rock_Sandstone_Cobble"
    },
    {
      "x": -13,
      "y": -19,
      "z": -17,
      "name": "Rock_Sandstone_Cobble"
    },
    {
      "x": -13,
      "y": -18,
      "z": -17,
      "name": "Rock_Sandstone_Cobble"
    },
    {
      "x": -13,
      "y": -17,
      "z": -17,
      "name": "Rock_Sandstone_Brick"
    },
    {
      "x": -13,
      "y": -16,
      "z": -17,
      "name": "Rock_Sandstone_White_Brick"
    },
    {
      "x": -13,
      "y": -15,
      "z": -17,
      "name": "Furniture_Desert_Window",
      "rotation": 1
    },
    {
      "x": -13,
      "y": -14,
      "z": -17,
      "name": "Furniture_Desert_Window",
      "rotation": 1
    },
    {
      "x": -13,
      "y": -13,
      "z": -17,
      "name": "Wood_Dry_Trunk",
      "rotation": 4
    },
    {
      "x": -13,
      "y": -12,
      "z": -17,
      "name": "Rock_Sandstone_White_Brick"
    },
    {
      "x": -13,
      "y": -11,
      "z": -17,
      "name": "Rock_Sandstone_Brick_Ornate"
    },
    {
      "x": -13,
      "y": -10,
      "z": -17,
      "name": "Rock_Sandstone_White_Cobble"
    },
    {
      "x": -13,
      "y": -23,
      "z": -16,
      "name": "Rock_Sandstone_Cobble"
    },
    {
      "x": -13,
      "y": -22,
      "z": -16,
      "name": "Rock_Sandstone_Cobble"
    },
    {
      "x": -13,
      "y": -21,
      "z": -16,
      "name": "Rock_Sandstone_Cobble"
    },
    {
      "x": -13,
      "y": -20,
      "z": -16,
      "name": "Rock_Sandstone_Cobble"
    },
    {
      "x": -13,
      "y": -19,
      "z": -16,
      "name": "Rock_Sandstone_Cobble"
    },
    {
      "x": -13,
      "y": -18,
      "z": -16,
      "name": "Rock_Sandstone_Cobble"
    },
    {
      "x": -13,
      "y": -17,
      "z": -16,
      "name": "Rock_Sandstone_Brick"
    },
    {
      "x": -13,
      "y": -16,
      "z": -16,
      "name": "Rock_Sandstone_White_Brick"
    },
    {
      "x": -13,
      "y": -15,
      "z": -16,
      "name": "Rock_Sandstone_White_Brick"
    },
    {
      "x": -13,
      "y": -14,
      "z": -16,
      "name": "Rock_Sandstone_White_Brick"
    },
    {
      "x": -13,
      "y": -13,
      "z": -16,
      "name": "Rock_Sandstone_White_Brick"
    },
    {
      "x": -13,
      "y": -12,
      "z": -16,
      "name": "Rock_Sandstone_White_Brick"
    },
    {
      "x": -13,
      "y": -11,
      "z": -16,
      "name": "Rock_Sandstone_Brick_Ornate"
    },
    {
      "x": -13,
      "y": -23,
      "z": -15,
      "name": "Rock_Sandstone_Cobble"
    },
    {
      "x": -13,
      "y": -22,
      "z": -15,
      "name": "Rock_Sandstone_Cobble"
    },
    {
      "x": -13,
      "y": -21,
      "z": -15,
      "name": "Rock_Sandstone_Cobble"
    },
    {
      "x": -13,
      "y": -20,
      "z": -15,
      "name": "Rock_Sandstone_Cobble"
    },
    {
      "x": -13,
      "y": -19,
      "z": -15,
      "name": "Rock_Sandstone_Cobble"
    },
    {
      "x": -13,
      "y": -18,
      "z": -15,
      "name": "Rock_Sandstone_Cobble"
    },
    {
      "x": -13,
      "y": -17,
      "z": -15,
      "name": "Rock_Sandstone_Brick"
    },
    {
      "x": -13,
      "y": -16,
      "z": -15,
      "name": "Rock_Sandstone_Brick"
    },
    {
      "x": -13,
      "y": -15,
      "z": -15,
      "name": "Rock_Sandstone_Brick"
    },
    {
      "x": -13,
      "y": -14,
      "z": -15,
      "name": "Rock_Sandstone_Brick"
    },
    {
      "x": -13,
      "y": -13,
      "z": -15,
      "name": "Rock_Sandstone_Brick"
    },
    {
      "x": -13,
      "y": -12,
      "z": -15,
      "name": "Rock_Sandstone_Brick"
    },
    {
      "x": -12,
      "y": -23,
      "z": -27,
      "name": "Rock_Sandstone_Cobble"
    },
    {
      "x": -12,
      "y": -22,
      "z": -27,
      "name": "Rock_Sandstone_Cobble"
    },
    {
      "x": -12,
      "y": -21,
      "z": -27,
      "name": "Rock_Sandstone_Cobble"
    },
    {
      "x": -12,
      "y": -20,
      "z": -27,
      "name": "Rock_Sandstone_Cobble"
    },
    {
      "x": -12,
      "y": -19,
      "z": -27,
      "name": "Rock_Sandstone_Cobble"
    },
    {
      "x": -12,
      "y": -18,
      "z": -27,
      "name": "Rock_Sandstone_Cobble"
    },
    {
      "x": -12,
      "y": -17,
      "z": -27,
      "name": "Rock_Sandstone_Brick"
    },
    {
      "x": -12,
      "y": -16,
      "z": -27,
      "name": "Rock_Sandstone_Brick"
    },
    {
      "x": -12,
      "y": -15,
      "z": -27,
      "name": "Rock_Sandstone_White_Cobble"
    },
    {
      "x": -12,
      "y": -14,
      "z": -27,
      "name": "Rock_Sandstone_White_Cobble"
    },
    {
      "x": -12,
      "y": -13,
      "z": -27,
      "name": "Rock_Sandstone_White_Cobble_Half"
    },
    {
      "x": -12,
      "y": -23,
      "z": -26,
      "name": "Rock_Sandstone_Cobble"
    },
    {
      "x": -12,
      "y": -22,
      "z": -26,
      "name": "Rock_Sandstone_Cobble"
    },
    {
      "x": -12,
      "y": -21,
      "z": -26,
      "name": "Rock_Sandstone_Cobble"
    },
    {
      "x": -12,
      "y": -20,
      "z": -26,
      "name": "Rock_Sandstone_Cobble"
    },
    {
      "x": -12,
      "y": -19,
      "z": -26,
      "name": "Rock_Sandstone_Cobble"
    },
    {
      "x": -12,
      "y": -18,
      "z": -26,
      "name": "Rock_Sandstone_Cobble"
    },
    {
      "x": -12,
      "y": -17,
      "z": -26,
      "name": "Rock_Sandstone_Brick"
    },
    {
      "x": -12,
      "y": -16,
      "z": -26,
      "name": "Rock_Sandstone_Brick"
    },
    {
      "x": -12,
      "y": -15,
      "z": -26,
      "name": "Rock_Sandstone_White_Cobble"
    },
    {
      "x": -12,
      "y": -14,
      "z": -26,
      "name": "Rock_Sandstone_White_Cobble"
    },
    {
      "x": -12,
      "y": -13,
      "z": -26,
      "name": "Rock_Sandstone_White_Cobble_Half"
    },
    {
      "x": -12,
      "y": -23,
      "z": -25,
      "name": "Rock_Sandstone_Cobble"
    },
    {
      "x": -12,
      "y": -22,
      "z": -25,
      "name": "Rock_Sandstone_Cobble"
    },
    {
      "x": -12,
      "y": -21,
      "z": -25,
      "name": "Rock_Sandstone_Cobble"
    },
    {
      "x": -12,
      "y": -20,
      "z": -25,
      "name": "Rock_Sandstone_Cobble"
    },
    {
      "x": -12,
      "y": -19,
      "z": -25,
      "name": "Rock_Sandstone_Cobble"
    },
    {
      "x": -12,
      "y": -18,
      "z": -25,
      "name": "Rock_Sandstone_Cobble"
    },
    {
      "x": -12,
      "y": -17,
      "z": -25,
      "name": "Rock_Sandstone_Brick"
    },
    {
      "x": -12,
      "y": -16,
      "z": -25,
      "name": "Rock_Sandstone_Brick"
    },
    {
      "x": -12,
      "y": -15,
      "z": -25,
      "name": "Rock_Sandstone_White_Cobble"
    },
    {
      "x": -12,
      "y": -14,
      "z": -25,
      "name": "Rock_Sandstone_White_Cobble"
    },
    {
      "x": -12,
      "y": -13,
      "z": -25,
      "name": "Rock_Sandstone_White_Cobble"
    },
    {
      "x": -12,
      "y": -23,
      "z": -24,
      "name": "Rock_Sandstone_Cobble"
    },
    {
      "x": -12,
      "y": -22,
      "z": -24,
      "name": "Rock_Sandstone_Cobble"
    },
    {
      "x": -12,
      "y": -21,
      "z": -24,
      "name": "Rock_Sandstone_Cobble"
    },
    {
      "x": -12,
      "y": -20,
      "z": -24,
      "name": "Rock_Sandstone_Cobble"
    },
    {
      "x": -12,
      "y": -19,
      "z": -24,
      "name": "Rock_Sandstone_Cobble"
    },
    {
      "x": -12,
      "y": -18,
      "z": -24,
      "name": "Rock_Sandstone_Cobble"
    },
    {
      "x": -12,
      "y": -17,
      "z": -24,
      "name": "Rock_Sandstone_Brick"
    },
    {
      "x": -12,
      "y": -16,
      "z": -24,
      "name": "Rock_Sandstone_Brick"
    },
    {
      "x": -12,
      "y": -15,
      "z": -24,
      "name": "Rock_Sandstone_White_Cobble"
    },
    {
      "x": -12,
      "y": -14,
      "z": -24,
      "name": "Rock_Sandstone_White_Cobble"
    },
    {
      "x": -12,
      "y": -13,
      "z": -24,
      "name": "Rock_Sandstone_White_Cobble_Half",
      "rotation": 4
    },
    {
      "x": -12,
      "y": -23,
      "z": -23,
      "name": "Rock_Sandstone_Cobble"
    },
    {
      "x": -12,
      "y": -22,
      "z": -23,
      "name": "Rock_Sandstone_Cobble"
    },
    {
      "x": -12,
      "y": -21,
      "z": -23,
      "name": "Rock_Sandstone_Cobble"
    },
    {
      "x": -12,
      "y": -20,
      "z": -23,
      "name": "Rock_Sandstone_Cobble"
    },
    {
      "x": -12,
      "y": -19,
      "z": -23,
      "name": "Rock_Sandstone_Cobble"
    },
    {
      "x": -12,
      "y": -18,
      "z": -23,
      "name": "Rock_Sandstone_Cobble"
    },
    {
      "x": -12,
      "y": -17,
      "z": -23,
      "name": "Rock_Sandstone_Brick"
    },
    {
      "x": -12,
      "y": -16,
      "z": -23,
      "name": "Rock_Sandstone_Brick"
    },
    {
      "x": -12,
      "y": -15,
      "z": -23,
      "name": "Rock_Sandstone_White_Cobble"
    },
    {
      "x": -12,
      "y": -14,
      "z": -23,
      "name": "Rock_Sandstone_White_Cobble"
    },
    {
      "x": -12,
      "y": -13,
      "z": -23,
      "name": "Rock_Sandstone_White_Cobble"
    },
    {
      "x": -12,
      "y": -12,
      "z": -23,
      "name": "Rock_Sandstone_White_Cobble"
    },
    {
      "x": -12,
      "y": -11,
      "z": -23,
      "name": "Rock_Sandstone_White_Cobble_Half"
    },
    {
      "x": -12,
      "y": -23,
      "z": -22,
      "name": "Rock_Sandstone_Cobble"
    },
    {
      "x": -12,
      "y": -22,
      "z": -22,
      "name": "Rock_Sandstone_Cobble"
    },
    {
      "x": -12,
      "y": -21,
      "z": -22,
      "name": "Rock_Sandstone_Cobble"
    },
    {
      "x": -12,
      "y": -20,
      "z": -22,
      "name": "Rock_Sandstone_Cobble"
    },
    {
      "x": -12,
      "y": -19,
      "z": -22,
      "name": "Rock_Sandstone_Cobble"
    },
    {
      "x": -12,
      "y": -18,
      "z": -22,
      "name": "Rock_Sandstone_Cobble"
    },
    {
      "x": -12,
      "y": -17,
      "z": -22,
      "name": "Rock_Sandstone_Brick"
    },
    {
      "x": -12,
      "y": -16,
      "z": -22,
      "name": "Rock_Sandstone_Brick"
    },
    {
      "x": -12,
      "y": -15,
      "z": -22,
      "name": "Rock_Sandstone_White_Cobble"
    },
    {
      "x": -12,
      "y": -14,
      "z": -22,
      "name": "Rock_Sandstone_White_Cobble"
    },
    {
      "x": -12,
      "y": -13,
      "z": -22,
      "name": "Rock_Sandstone_White_Cobble"
    },
    {
      "x": -12,
      "y": -12,
      "z": -22,
      "name": "Rock_Sandstone_White_Cobble"
    },
    {
      "x": -12,
      "y": -11,
      "z": -22,
      "name": "Rock_Sandstone_White_Cobble"
    },
    {
      "x": -12,
      "y": -23,
      "z": -21,
      "name": "Rock_Sandstone_Cobble"
    },
    {
      "x": -12,
      "y": -22,
      "z": -21,
      "name": "Rock_Sandstone_Cobble"
    },
    {
      "x": -12,
      "y": -21,
      "z": -21,
      "name": "Rock_Sandstone_Cobble"
    },
    {
      "x": -12,
      "y": -20,
      "z": -21,
      "name": "Rock_Sandstone_Cobble"
    },
    {
      "x": -12,
      "y": -19,
      "z": -21,
      "name": "Rock_Sandstone_Cobble"
    },
    {
      "x": -12,
      "y": -18,
      "z": -21,
      "name": "Rock_Sandstone_Cobble"
    },
    {
      "x": -12,
      "y": -17,
      "z": -21,
      "name": "Rock_Sandstone_Brick"
    },
    {
      "x": -12,
      "y": -16,
      "z": -21,
      "name": "Rock_Sandstone_Brick"
    },
    {
      "x": -12,
      "y": -15,
      "z": -21,
      "name": "Rock_Sandstone_Brick"
    },
    {
      "x": -12,
      "y": -14,
      "z": -21,
      "name": "Rock_Sandstone_Brick"
    },
    {
      "x": -12,
      "y": -13,
      "z": -21,
      "name": "Rock_Sandstone_Brick"
    },
    {
      "x": -12,
      "y": -12,
      "z": -21,
      "name": "Rock_Sandstone_Brick"
    },
    {
      "x": -12,
      "y": -11,
      "z": -21,
      "name": "Rock_Sandstone_Brick_Ornate"
    },
    {
      "x": -12,
      "y": -10,
      "z": -21,
      "name": "Rock_Sandstone_Brick"
    },
    {
      "x": -12,
      "y": -23,
      "z": -20,
      "name": "Rock_Sandstone_Cobble"
    },
    {
      "x": -12,
      "y": -22,
      "z": -20,
      "name": "Rock_Sandstone_Cobble"
    },
    {
      "x": -12,
      "y": -21,
      "z": -20,
      "name": "Rock_Sandstone_Cobble"
    },
    {
      "x": -12,
      "y": -20,
      "z": -20,
      "name": "Rock_Sandstone_Cobble"
    },
    {
      "x": -12,
      "y": -19,
      "z": -20,
      "name": "Rock_Sandstone_Cobble"
    },
    {
      "x": -12,
      "y": -18,
      "z": -20,
      "name": "Rock_Sandstone_Cobble"
    },
    {
      "x": -12,
      "y": -17,
      "z": -20,
      "name": "Rock_Sandstone_Cobble"
    },
    {
      "x": -12,
      "y": -11,
      "z": -20,
      "name": "Wood_Drywood_Beam",
      "rotation": 4
    },
    {
      "x": -12,
      "y": -23,
      "z": -19,
      "name": "Rock_Sandstone_Cobble"
    },
    {
      "x": -12,
      "y": -22,
      "z": -19,
      "name": "Rock_Sandstone_Cobble"
    },
    {
      "x": -12,
      "y": -21,
      "z": -19,
      "name": "Rock_Sandstone_Cobble"
    },
    {
      "x": -12,
      "y": -20,
      "z": -19,
      "name": "Rock_Sandstone_Cobble"
    },
    {
      "x": -12,
      "y": -19,
      "z": -19,
      "name": "Rock_Sandstone_Cobble"
    },
    {
      "x": -12,
      "y": -18,
      "z": -19,
      "name": "Rock_Sandstone_Cobble"
    },
    {
      "x": -12,
      "y": -17,
      "z": -19,
      "name": "Rock_Sandstone_Cobble"
    },
    {
      "x": -12,
      "y": -14,
      "z": -19,
      "name": "Cloth_Roof_Hide_Flap",
      "rotation": 1
    },
    {
      "x": -12,
      "y": -13,
      "z": -19,
      "name": "Cloth_Roof_Hide_Vertical",
      "rotation": 1
    },
    {
      "x": -12,
      "y": -11,
      "z": -19,
      "name": "Wood_Drywood_Beam",
      "rotation": 4
    },
    {
      "x": -12,
      "y": -23,
      "z": -18,
      "name": "Rock_Sandstone_Cobble"
    },
    {
      "x": -12,
      "y": -22,
      "z": -18,
      "name": "Rock_Sandstone_Cobble"
    },
    {
      "x": -12,
      "y": -21,
      "z": -18,
      "name": "Rock_Sandstone_Cobble"
    },
    {
      "x": -12,
      "y": -20,
      "z": -18,
      "name": "Rock_Sandstone_Cobble"
    },
    {
      "x": -12,
      "y": -19,
      "z": -18,
      "name": "Rock_Sandstone_Cobble"
    },
    {
      "x": -12,
      "y": -18,
      "z": -18,
      "name": "Rock_Sandstone_Cobble"
    },
    {
      "x": -12,
      "y": -17,
      "z": -18,
      "name": "Rock_Sandstone_Cobble"
    },
    {
      "x": -12,
      "y": -16,
      "z": -18,
      "name": "Furniture_Desert_Chair",
      "rotation": 1
    },
    {
      "x": -12,
      "y": -14,
      "z": -18,
      "name": "Cloth_Roof_Hide_Flap",
      "rotation": 1
    },
    {
      "x": -12,
      "y": -13,
      "z": -18,
      "name": "Cloth_Roof_Hide_Vertical",
      "rotation": 1
    },
    {
      "x": -12,
      "y": -11,
      "z": -18,
      "name": "Wood_Drywood_Beam",
      "rotation": 4
    },
    {
      "x": -12,
      "y": -23,
      "z": -17,
      "name": "Rock_Sandstone_Cobble"
    },
    {
      "x": -12,
      "y": -22,
      "z": -17,
      "name": "Rock_Sandstone_Cobble"
    },
    {
      "x": -12,
      "y": -21,
      "z": -17,
      "name": "Rock_Sandstone_Cobble"
    },
    {
      "x": -12,
      "y": -20,
      "z": -17,
      "name": "Rock_Sandstone_Cobble"
    },
    {
      "x": -12,
      "y": -19,
      "z": -17,
      "name": "Rock_Sandstone_Cobble"
    },
    {
      "x": -12,
      "y": -18,
      "z": -17,
      "name": "Rock_Sandstone_Cobble"
    },
    {
      "x": -12,
      "y": -17,
      "z": -17,
      "name": "Rock_Sandstone_Cobble"
    },
    {
      "x": -12,
      "y": -14,
      "z": -17,
      "name": "Cloth_Roof_Hide_Flap",
      "rotation": 1
    },
    {
      "x": -12,
      "y": -13,
      "z": -17,
      "name": "Cloth_Roof_Hide_Vertical",
      "rotation": 1
    },
    {
      "x": -12,
      "y": -11,
      "z": -17,
      "name": "Wood_Drywood_Planks"
    },
    {
      "x": -12,
      "y": -23,
      "z": -16,
      "name": "Rock_Sandstone_Cobble"
    },
    {
      "x": -12,
      "y": -22,
      "z": -16,
      "name": "Rock_Sandstone_Cobble"
    },
    {
      "x": -12,
      "y": -21,
      "z": -16,
      "name": "Rock_Sandstone_Cobble"
    },
    {
      "x": -12,
      "y": -20,
      "z": -16,
      "name": "Rock_Sandstone_Cobble"
    },
    {
      "x": -12,
      "y": -19,
      "z": -16,
      "name": "Rock_Sandstone_Cobble"
    },
    {
      "x": -12,
      "y": -18,
      "z": -16,
      "name": "Rock_Sandstone_Cobble"
    },
    {
      "x": -12,
      "y": -17,
      "z": -16,
      "name": "Rock_Sandstone_Cobble"
    },
    {
      "x": -12,
      "y": -11,
      "z": -16,
      "name": "Wood_Drywood_Planks"
    },
    {
      "x": -12,
      "y": -23,
      "z": -15,
      "name": "Rock_Sandstone_Cobble"
    },
    {
      "x": -12,
      "y": -22,
      "z": -15,
      "name": "Rock_Sandstone_Cobble"
    },
    {
      "x": -12,
      "y": -21,
      "z": -15,
      "name": "Rock_Sandstone_Cobble"
    },
    {
      "x": -12,
      "y": -20,
      "z": -15,
      "name": "Rock_Sandstone_Cobble"
    },
    {
      "x": -12,
      "y": -19,
      "z": -15,
      "name": "Rock_Sandstone_Cobble"
    },
    {
      "x": -12,
      "y": -18,
      "z": -15,
      "name": "Rock_Sandstone_Cobble"
    },
    {
      "x": -12,
      "y": -17,
      "z": -15,
      "name": "Rock_Sandstone_Brick"
    },
    {
      "x": -12,
      "y": -16,
      "z": -15,
      "name": "Rock_Sandstone_White_Brick"
    },
    {
      "x": -12,
      "y": -15,
      "z": -15,
      "name": "Rock_Sandstone_White_Brick"
    },
    {
      "x": -12,
      "y": -14,
      "z": -15,
      "name": "Rock_Sandstone_White_Brick"
    },
    {
      "x": -12,
      "y": -13,
      "z": -15,
      "name": "Rock_Sandstone_White_Brick"
    },
    {
      "x": -12,
      "y": -12,
      "z": -15,
      "name": "Rock_Sandstone_White_Brick"
    },
    {
      "x": -12,
      "y": -11,
      "z": -15,
      "name": "Rock_Sandstone_Brick_Ornate"
    },
    {
      "x": -12,
      "y": -10,
      "z": -15,
      "name": "Rock_Sandstone_White_Cobble_Half"
    },
    {
      "x": -11,
      "y": -23,
      "z": -27,
      "name": "Rock_Sandstone_Cobble"
    },
    {
      "x": -11,
      "y": -22,
      "z": -27,
      "name": "Rock_Sandstone_Cobble"
    },
    {
      "x": -11,
      "y": -21,
      "z": -27,
      "name": "Rock_Sandstone_Cobble"
    },
    {
      "x": -11,
      "y": -20,
      "z": -27,
      "name": "Rock_Sandstone_Cobble"
    },
    {
      "x": -11,
      "y": -19,
      "z": -27,
      "name": "Rock_Sandstone_Cobble"
    },
    {
      "x": -11,
      "y": -18,
      "z": -27,
      "name": "Rock_Sandstone_Cobble"
    },
    {
      "x": -11,
      "y": -17,
      "z": -27,
      "name": "Rock_Sandstone_Brick"
    },
    {
      "x": -11,
      "y": -16,
      "z": -27,
      "name": "Rock_Sandstone_Brick"
    },
    {
      "x": -11,
      "y": -15,
      "z": -27,
      "name": "Rock_Sandstone_White_Cobble"
    },
    {
      "x": -11,
      "y": -14,
      "z": -27,
      "name": "Rock_Sandstone_White_Cobble"
    },
    {
      "x": -11,
      "y": -13,
      "z": -27,
      "name": "Rock_Sandstone_White_Cobble_Half"
    },
    {
      "x": -11,
      "y": -23,
      "z": -26,
      "name": "Soil_Dirt_Dry"
    },
    {
      "x": -11,
      "y": -22,
      "z": -26,
      "name": "Soil_Dirt_Dry"
    },
    {
      "x": -11,
      "y": -21,
      "z": -26,
      "name": "Soil_Dirt_Dry"
    },
    {
      "x": -11,
      "y": -20,
      "z": -26,
      "name": "Soil_Dirt_Dry"
    },
    {
      "x": -11,
      "y": -19,
      "z": -26,
      "name": "Soil_Dirt_Dry"
    },
    {
      "x": -11,
      "y": -18,
      "z": -26,
      "name": "Soil_Dirt_Dry"
    },
    {
      "x": -11,
      "y": -17,
      "z": -26,
      "name": "Plant_Bush_Arid"
    },
    {
      "x": -11,
      "y": -16,
      "z": -26,
      "name": "Plant_Bush_Arid"
    },
    {
      "x": -11,
      "y": -23,
      "z": -25,
      "name": "Soil_Dirt_Dry"
    },
    {
      "x": -11,
      "y": -22,
      "z": -25,
      "name": "Soil_Dirt_Dry"
    },
    {
      "x": -11,
      "y": -21,
      "z": -25,
      "name": "Soil_Dirt_Dry"
    },
    {
      "x": -11,
      "y": -20,
      "z": -25,
      "name": "Soil_Dirt_Dry"
    },
    {
      "x": -11,
      "y": -19,
      "z": -25,
      "name": "Soil_Dirt_Dry"
    },
    {
      "x": -11,
      "y": -18,
      "z": -25,
      "name": "Soil_Dirt_Dry"
    },
    {
      "x": -11,
      "y": -17,
      "z": -25,
      "name": "Plant_Bush_Arid"
    },
    {
      "x": -11,
      "y": -16,
      "z": -25,
      "name": "Plant_Bush_Arid"
    },
    {
      "x": -11,
      "y": -16,
      "z": -24,
      "name": "Plant_Vine_Wall_Dry",
      "rotation": 1
    },
    {
      "x": -11,
      "y": -15,
      "z": -24,
      "name": "Plant_Vine_Wall_Dry",
      "rotation": 1
    },
    {
      "x": -11,
      "y": -14,
      "z": -24,
      "name": "Plant_Vine_Wall_Dry",
      "rotation": 1
    },
    {
      "x": -11,
      "y": -23,
      "z": -22,
      "name": "Rock_Sandstone_Cobble"
    },
    {
      "x": -11,
      "y": -22,
      "z": -22,
      "name": "Rock_Sandstone_Cobble"
    },
    {
      "x": -11,
      "y": -21,
      "z": -22,
      "name": "Rock_Sandstone_Cobble"
    },
    {
      "x": -11,
      "y": -20,
      "z": -22,
      "name": "Rock_Sandstone_Cobble"
    },
    {
      "x": -11,
      "y": -19,
      "z": -22,
      "name": "Rock_Sandstone_Cobble"
    },
    {
      "x": -11,
      "y": -18,
      "z": -22,
      "name": "Rock_Sandstone_Cobble_Stairs",
      "rotation": 2
    },
    {
      "x": -11,
      "y": -23,
      "z": -21,
      "name": "Rock_Sandstone_Cobble"
    },
    {
      "x": -11,
      "y": -22,
      "z": -21,
      "name": "Rock_Sandstone_Cobble"
    },
    {
      "x": -11,
      "y": -21,
      "z": -21,
      "name": "Rock_Sandstone_Cobble"
    },
    {
      "x": -11,
      "y": -20,
      "z": -21,
      "name": "Rock_Sandstone_Cobble"
    },
    {
      "x": -11,
      "y": -19,
      "z": -21,
      "name": "Rock_Sandstone_Cobble"
    },
    {
      "x": -11,
      "y": -18,
      "z": -21,
      "name": "Rock_Sandstone_Cobble"
    },
    {
      "x": -11,
      "y": -17,
      "z": -21,
      "name": "Rock_Sandstone_Cobble_Stairs",
      "rotation": 2
    },
    {
      "x": -11,
      "y": -23,
      "z": -20,
      "name": "Rock_Sandstone_Cobble"
    },
    {
      "x": -11,
      "y": -22,
      "z": -20,
      "name": "Rock_Sandstone_Cobble"
    },
    {
      "x": -11,
      "y": -21,
      "z": -20,
      "name": "Rock_Sandstone_Cobble"
    },
    {
      "x": -11,
      "y": -20,
      "z": -20,
      "name": "Rock_Sandstone_Cobble"
    },
    {
      "x": -11,
      "y": -19,
      "z": -20,
      "name": "Rock_Sandstone_Cobble"
    },
    {
      "x": -11,
      "y": -18,
      "z": -20,
      "name": "Rock_Sandstone_Cobble"
    },
    {
      "x": -11,
      "y": -17,
      "z": -20,
      "name": "Rock_Sandstone_Cobble"
    },
    {
      "x": -11,
      "y": -23,
      "z": -19,
      "name": "Rock_Sandstone_Cobble"
    },
    {
      "x": -11,
      "y": -22,
      "z": -19,
      "name": "Rock_Sandstone_Cobble"
    },
    {
      "x": -11,
      "y": -21,
      "z": -19,
      "name": "Rock_Sandstone_Cobble"
    },
    {
      "x": -11,
      "y": -20,
      "z": -19,
      "name": "Rock_Sandstone_Cobble"
    },
    {
      "x": -11,
      "y": -19,
      "z": -19,
      "name": "Rock_Sandstone_Cobble"
    },
    {
      "x": -11,
      "y": -18,
      "z": -19,
      "name": "Rock_Sandstone_Cobble"
    },
    {
      "x": -11,
      "y": -17,
      "z": -19,
      "name": "Rock_Sandstone_Cobble"
    },
    {
      "x": -11,
      "y": -11,
      "z": -19,
      "name": "Wood_Drywood_Planks_Half",
      "rotation": 7
    },
    {
      "x": -11,
      "y": -23,
      "z": -18,
      "name": "Rock_Sandstone_Cobble"
    },
    {
      "x": -11,
      "y": -22,
      "z": -18,
      "name": "Rock_Sandstone_Cobble"
    },
    {
      "x": -11,
      "y": -21,
      "z": -18,
      "name": "Rock_Sandstone_Cobble"
    },
    {
      "x": -11,
      "y": -20,
      "z": -18,
      "name": "Rock_Sandstone_Cobble"
    },
    {
      "x": -11,
      "y": -19,
      "z": -18,
      "name": "Rock_Sandstone_Cobble"
    },
    {
      "x": -11,
      "y": -18,
      "z": -18,
      "name": "Rock_Sandstone_Cobble"
    },
    {
      "x": -11,
      "y": -17,
      "z": -18,
      "name": "Rock_Sandstone_Cobble"
    },
    {
      "x": -11,
      "y": -16,
      "z": -18,
      "name": "Furniture_Desert_Table"
    },
    {
      "x": -11,
      "y": -11,
      "z": -18,
      "name": "Wood_Drywood_Planks_Half",
      "rotation": 7
    },
    {
      "x": -11,
      "y": -23,
      "z": -17,
      "name": "Rock_Sandstone_Cobble"
    },
    {
      "x": -11,
      "y": -22,
      "z": -17,
      "name": "Rock_Sandstone_Cobble"
    },
    {
      "x": -11,
      "y": -21,
      "z": -17,
      "name": "Rock_Sandstone_Cobble"
    },
    {
      "x": -11,
      "y": -20,
      "z": -17,
      "name": "Rock_Sandstone_Cobble"
    },
    {
      "x": -11,
      "y": -19,
      "z": -17,
      "name": "Rock_Sandstone_Cobble"
    },
    {
      "x": -11,
      "y": -18,
      "z": -17,
      "name": "Rock_Sandstone_Cobble"
    },
    {
      "x": -11,
      "y": -17,
      "z": -17,
      "name": "Rock_Sandstone_Cobble"
    },
    {
      "x": -11,
      "y": -16,
      "z": -17,
      "name": "Furniture_Desert_Table",
      "filler": 32
    },
    {
      "x": -11,
      "y": -11,
      "z": -17,
      "name": "Wood_Drywood_Planks_Half",
      "rotation": 7
    },
    {
      "x": -11,
      "y": -23,
      "z": -16,
      "name": "Rock_Sandstone_Cobble"
    },
    {
      "x": -11,
      "y": -22,
      "z": -16,
      "name": "Rock_Sandstone_Cobble"
    },
    {
      "x": -11,
      "y": -21,
      "z": -16,
      "name": "Rock_Sandstone_Cobble"
    },
    {
      "x": -11,
      "y": -20,
      "z": -16,
      "name": "Rock_Sandstone_Cobble"
    },
    {
      "x": -11,
      "y": -19,
      "z": -16,
      "name": "Rock_Sandstone_Cobble"
    },
    {
      "x": -11,
      "y": -18,
      "z": -16,
      "name": "Rock_Sandstone_Cobble"
    },
    {
      "x": -11,
      "y": -17,
      "z": -16,
      "name": "Rock_Sandstone_Cobble"
    },
    {
      "x": -11,
      "y": -14,
      "z": -16,
      "name": "Cloth_Roof_Hide_Flap",
      "rotation": 2
    },
    {
      "x": -11,
      "y": -13,
      "z": -16,
      "name": "Cloth_Roof_Hide_Vertical",
      "rotation": 2
    },
    {
      "x": -11,
      "y": -23,
      "z": -15,
      "name": "Rock_Sandstone_Cobble"
    },
    {
      "x": -11,
      "y": -22,
      "z": -15,
      "name": "Rock_Sandstone_Cobble"
    },
    {
      "x": -11,
      "y": -21,
      "z": -15,
      "name": "Rock_Sandstone_Cobble"
    },
    {
      "x": -11,
      "y": -20,
      "z": -15,
      "name": "Rock_Sandstone_Cobble"
    },
    {
      "x": -11,
      "y": -19,
      "z": -15,
      "name": "Rock_Sandstone_Cobble"
    },
    {
      "x": -11,
      "y": -18,
      "z": -15,
      "name": "Rock_Sandstone_Cobble"
    },
    {
      "x": -11,
      "y": -17,
      "z": -15,
      "name": "Rock_Sandstone_Brick"
    },
    {
      "x": -11,
      "y": -16,
      "z": -15,
      "name": "Rock_Sandstone_White_Brick"
    },
    {
      "x": -11,
      "y": -15,
      "z": -15,
      "name": "Furniture_Desert_Window"
    },
    {
      "x": -11,
      "y": -14,
      "z": -15,
      "name": "Furniture_Desert_Window"
    },
    {
      "x": -11,
      "y": -13,
      "z": -15,
      "name": "Rock_Sandstone_White_Brick"
    },
    {
      "x": -11,
      "y": -12,
      "z": -15,
      "name": "Rock_Sandstone_White_Brick"
    },
    {
      "x": -11,
      "y": -11,
      "z": -15,
      "name": "Rock_Sandstone_Brick_Ornate"
    },
    {
      "x": -11,
      "y": -10,
      "z": -15,
      "name": "Rock_Sandstone_White_Cobble"
    },
    {
      "x": -11,
      "y": -9,
      "z": -15,
      "name": "Rock_Sandstone_White_Cobble_Half"
    },
    {
      "x": -11,
      "y": -16,
      "z": -14,
      "name": "Rock_Sandstone_Brick_Smooth_Half",
      "rotation": 4
    },
    {
      "x": -10,
      "y": -23,
      "z": -27,
      "name": "Rock_Sandstone_Cobble"
    },
    {
      "x": -10,
      "y": -22,
      "z": -27,
      "name": "Rock_Sandstone_Cobble"
    },
    {
      "x": -10,
      "y": -21,
      "z": -27,
      "name": "Rock_Sandstone_Cobble"
    },
    {
      "x": -10,
      "y": -20,
      "z": -27,
      "name": "Rock_Sandstone_Cobble"
    },
    {
      "x": -10,
      "y": -19,
      "z": -27,
      "name": "Rock_Sandstone_Cobble"
    },
    {
      "x": -10,
      "y": -18,
      "z": -27,
      "name": "Rock_Sandstone_Cobble"
    },
    {
      "x": -10,
      "y": -17,
      "z": -27,
      "name": "Rock_Sandstone_Brick"
    },
    {
      "x": -10,
      "y": -16,
      "z": -27,
      "name": "Rock_Sandstone_Brick"
    },
    {
      "x": -10,
      "y": -15,
      "z": -27,
      "name": "Rock_Sandstone_White_Cobble"
    },
    {
      "x": -10,
      "y": -14,
      "z": -27,
      "name": "Rock_Sandstone_White_Cobble"
    },
    {
      "x": -10,
      "y": -13,
      "z": -27,
      "name": "Rock_Sandstone_White_Cobble"
    },
    {
      "x": -10,
      "y": -23,
      "z": -26,
      "name": "Soil_Dirt_Dry"
    },
    {
      "x": -10,
      "y": -22,
      "z": -26,
      "name": "Soil_Dirt_Dry"
    },
    {
      "x": -10,
      "y": -21,
      "z": -26,
      "name": "Soil_Dirt_Dry"
    },
    {
      "x": -10,
      "y": -20,
      "z": -26,
      "name": "Soil_Dirt_Dry"
    },
    {
      "x": -10,
      "y": -19,
      "z": -26,
      "name": "Soil_Dirt_Dry"
    },
    {
      "x": -10,
      "y": -18,
      "z": -26,
      "name": "Soil_Dirt_Dry"
    },
    {
      "x": -10,
      "y": -17,
      "z": -26,
      "name": "Plant_Bush_Arid"
    },
    {
      "x": -10,
      "y": -15,
      "z": -26,
      "name": "Plant_Vine_Wall_Dry"
    },
    {
      "x": -10,
      "y": -14,
      "z": -26,
      "name": "Plant_Vine_Wall_Dry"
    },
    {
      "x": -10,
      "y": -23,
      "z": -25,
      "name": "Soil_Dirt_Dry"
    },
    {
      "x": -10,
      "y": -22,
      "z": -25,
      "name": "Soil_Dirt_Dry"
    },
    {
      "x": -10,
      "y": -21,
      "z": -25,
      "name": "Soil_Dirt_Dry"
    },
    {
      "x": -10,
      "y": -20,
      "z": -25,
      "name": "Soil_Dirt_Dry"
    },
    {
      "x": -10,
      "y": -19,
      "z": -25,
      "name": "Soil_Dirt_Dry"
    },
    {
      "x": -10,
      "y": -18,
      "z": -25,
      "name": "Soil_Dirt_Dry"
    },
    {
      "x": -10,
      "y": -23,
      "z": -22,
      "name": "Rock_Sandstone_Cobble"
    },
    {
      "x": -10,
      "y": -22,
      "z": -22,
      "name": "Rock_Sandstone_Cobble"
    },
    {
      "x": -10,
      "y": -21,
      "z": -22,
      "name": "Rock_Sandstone_Cobble"
    },
    {
      "x": -10,
      "y": -20,
      "z": -22,
      "name": "Rock_Sandstone_Cobble"
    },
    {
      "x": -10,
      "y": -19,
      "z": -22,
      "name": "Rock_Sandstone_Cobble"
    },
    {
      "x": -10,
      "y": -18,
      "z": -22,
      "name": "Rock_Sandstone_Cobble_Stairs",
      "rotation": 2
    },
    {
      "x": -10,
      "y": -23,
      "z": -21,
      "name": "Rock_Sandstone_Cobble"
    },
    {
      "x": -10,
      "y": -22,
      "z": -21,
      "name": "Rock_Sandstone_Cobble"
    },
    {
      "x": -10,
      "y": -21,
      "z": -21,
      "name": "Rock_Sandstone_Cobble"
    },
    {
      "x": -10,
      "y": -20,
      "z": -21,
      "name": "Rock_Sandstone_Cobble"
    },
    {
      "x": -10,
      "y": -19,
      "z": -21,
      "name": "Rock_Sandstone_Cobble"
    },
    {
      "x": -10,
      "y": -18,
      "z": -21,
      "name": "Rock_Sandstone_Cobble"
    },
    {
      "x": -10,
      "y": -17,
      "z": -21,
      "name": "Rock_Sandstone_Cobble_Stairs",
      "rotation": 2
    },
    {
      "x": -10,
      "y": -13,
      "z": -21,
      "name": "Rock_Sandstone_Brick"
    },
    {
      "x": -10,
      "y": -12,
      "z": -21,
      "name": "Rock_Sandstone_Brick"
    },
    {
      "x": -10,
      "y": -11,
      "z": -21,
      "name": "Rock_Sandstone_Brick_Ornate"
    },
    {
      "x": -10,
      "y": -10,
      "z": -21,
      "name": "Rock_Sandstone_Brick_Half"
    },
    {
      "x": -10,
      "y": -23,
      "z": -20,
      "name": "Rock_Sandstone_Cobble"
    },
    {
      "x": -10,
      "y": -22,
      "z": -20,
      "name": "Rock_Sandstone_Cobble"
    },
    {
      "x": -10,
      "y": -21,
      "z": -20,
      "name": "Rock_Sandstone_Cobble"
    },
    {
      "x": -10,
      "y": -20,
      "z": -20,
      "name": "Rock_Sandstone_Cobble"
    },
    {
      "x": -10,
      "y": -19,
      "z": -20,
      "name": "Rock_Sandstone_Cobble"
    },
    {
      "x": -10,
      "y": -18,
      "z": -20,
      "name": "Rock_Sandstone_Cobble"
    },
    {
      "x": -10,
      "y": -17,
      "z": -20,
      "name": "Rock_Sandstone_Cobble"
    },
    {
      "x": -10,
      "y": -11,
      "z": -20,
      "name": "Wood_Drywood_Beam",
      "rotation": 4
    },
    {
      "x": -10,
      "y": -23,
      "z": -19,
      "name": "Rock_Sandstone_Cobble"
    },
    {
      "x": -10,
      "y": -22,
      "z": -19,
      "name": "Rock_Sandstone_Cobble"
    },
    {
      "x": -10,
      "y": -21,
      "z": -19,
      "name": "Rock_Sandstone_Cobble"
    },
    {
      "x": -10,
      "y": -20,
      "z": -19,
      "name": "Rock_Sandstone_Cobble"
    },
    {
      "x": -10,
      "y": -19,
      "z": -19,
      "name": "Rock_Sandstone_Cobble"
    },
    {
      "x": -10,
      "y": -18,
      "z": -19,
      "name": "Rock_Sandstone_Cobble"
    },
    {
      "x": -10,
      "y": -17,
      "z": -19,
      "name": "Rock_Sandstone_Cobble"
    },
    {
      "x": -10,
      "y": -11,
      "z": -19,
      "name": "Wood_Drywood_Planks"
    },
    {
      "x": -10,
      "y": -10,
      "z": -19,
      "name": "Furniture_Ancient_Pot"
    },
    {
      "x": -10,
      "y": -23,
      "z": -18,
      "name": "Rock_Sandstone_Cobble"
    },
    {
      "x": -10,
      "y": -22,
      "z": -18,
      "name": "Rock_Sandstone_Cobble"
    },
    {
      "x": -10,
      "y": -21,
      "z": -18,
      "name": "Rock_Sandstone_Cobble"
    },
    {
      "x": -10,
      "y": -20,
      "z": -18,
      "name": "Rock_Sandstone_Cobble"
    },
    {
      "x": -10,
      "y": -19,
      "z": -18,
      "name": "Rock_Sandstone_Cobble"
    },
    {
      "x": -10,
      "y": -18,
      "z": -18,
      "name": "Rock_Sandstone_Cobble"
    },
    {
      "x": -10,
      "y": -17,
      "z": -18,
      "name": "Rock_Sandstone_Cobble"
    },
    {
      "x": -10,
      "y": -16,
      "z": -18,
      "name": "Furniture_Desert_Table",
      "filler": 1
    },
    {
      "x": -10,
      "y": -15,
      "z": -18,
      "name": "Deco_Pot_Clay_Broken"
    },
    {
      "x": -10,
      "y": -11,
      "z": -18,
      "name": "Wood_Drywood_Planks"
    },
    {
      "x": -10,
      "y": -23,
      "z": -17,
      "name": "Rock_Sandstone_Cobble"
    },
    {
      "x": -10,
      "y": -22,
      "z": -17,
      "name": "Rock_Sandstone_Cobble"
    },
    {
      "x": -10,
      "y": -21,
      "z": -17,
      "name": "Rock_Sandstone_Cobble"
    },
    {
      "x": -10,
      "y": -20,
      "z": -17,
      "name": "Rock_Sandstone_Cobble"
    },
    {
      "x": -10,
      "y": -19,
      "z": -17,
      "name": "Rock_Sandstone_Cobble"
    },
    {
      "x": -10,
      "y": -18,
      "z": -17,
      "name": "Rock_Sandstone_Cobble"
    },
    {
      "x": -10,
      "y": -17,
      "z": -17,
      "name": "Rock_Sandstone_Cobble"
    },
    {
      "x": -10,
      "y": -16,
      "z": -17,
      "name": "Furniture_Desert_Table",
      "filler": 33
    },
    {
      "x": -10,
      "y": -11,
      "z": -17,
      "name": "Wood_Drywood_Planks"
    },
    {
      "x": -10,
      "y": -23,
      "z": -16,
      "name": "Rock_Sandstone_Cobble"
    },
    {
      "x": -10,
      "y": -22,
      "z": -16,
      "name": "Rock_Sandstone_Cobble"
    },
    {
      "x": -10,
      "y": -21,
      "z": -16,
      "name": "Rock_Sandstone_Cobble"
    },
    {
      "x": -10,
      "y": -20,
      "z": -16,
      "name": "Rock_Sandstone_Cobble"
    },
    {
      "x": -10,
      "y": -19,
      "z": -16,
      "name": "Rock_Sandstone_Cobble"
    },
    {
      "x": -10,
      "y": -18,
      "z": -16,
      "name": "Rock_Sandstone_Cobble"
    },
    {
      "x": -10,
      "y": -17,
      "z": -16,
      "name": "Rock_Sandstone_Cobble"
    },
    {
      "x": -10,
      "y": -16,
      "z": -16,
      "name": "Furniture_Desert_Chair",
      "rotation": 2
    },
    {
      "x": -10,
      "y": -14,
      "z": -16,
      "name": "Cloth_Roof_Hide_Flap",
      "rotation": 2
    },
    {
      "x": -10,
      "y": -13,
      "z": -16,
      "name": "Cloth_Roof_Hide_Vertical",
      "rotation": 2
    },
    {
      "x": -10,
      "y": -11,
      "z": -16,
      "name": "Wood_Drywood_Planks"
    },
    {
      "x": -10,
      "y": -23,
      "z": -15,
      "name": "Rock_Sandstone_Cobble"
    },
    {
      "x": -10,
      "y": -22,
      "z": -15,
      "name": "Rock_Sandstone_Cobble"
    },
    {
      "x": -10,
      "y": -21,
      "z": -15,
      "name": "Rock_Sandstone_Cobble"
    },
    {
      "x": -10,
      "y": -20,
      "z": -15,
      "name": "Rock_Sandstone_Cobble"
    },
    {
      "x": -10,
      "y": -19,
      "z": -15,
      "name": "Rock_Sandstone_Cobble"
    },
    {
      "x": -10,
      "y": -18,
      "z": -15,
      "name": "Rock_Sandstone_Cobble"
    },
    {
      "x": -10,
      "y": -17,
      "z": -15,
      "name": "Rock_Sandstone_Brick"
    },
    {
      "x": -10,
      "y": -16,
      "z": -15,
      "name": "Rock_Sandstone_White_Brick"
    },
    {
      "x": -10,
      "y": -15,
      "z": -15,
      "name": "Furniture_Desert_Window"
    },
    {
      "x": -10,
      "y": -14,
      "z": -15,
      "name": "Furniture_Desert_Window"
    },
    {
      "x": -10,
      "y": -13,
      "z": -15,
      "name": "Rock_Sandstone_White_Brick"
    },
    {
      "x": -10,
      "y": -12,
      "z": -15,
      "name": "Rock_Sandstone_White_Brick"
    },
    {
      "x": -10,
      "y": -11,
      "z": -15,
      "name": "Rock_Sandstone_Brick_Ornate"
    },
    {
      "x": -10,
      "y": -10,
      "z": -15,
      "name": "Rock_Sandstone_White_Brick"
    },
    {
      "x": -10,
      "y": -9,
      "z": -15,
      "name": "Rock_Sandstone_White_Cobble_Half"
    },
    {
      "x": -10,
      "y": -16,
      "z": -14,
      "name": "Rock_Sandstone_Brick_Smooth_Half",
      "rotation": 4
    },
    {
      "x": -9,
      "y": -23,
      "z": -27,
      "name": "Rock_Sandstone_Cobble"
    },
    {
      "x": -9,
      "y": -22,
      "z": -27,
      "name": "Rock_Sandstone_Cobble"
    },
    {
      "x": -9,
      "y": -21,
      "z": -27,
      "name": "Rock_Sandstone_Cobble"
    },
    {
      "x": -9,
      "y": -20,
      "z": -27,
      "name": "Rock_Sandstone_Cobble"
    },
    {
      "x": -9,
      "y": -19,
      "z": -27,
      "name": "Rock_Sandstone_Cobble"
    },
    {
      "x": -9,
      "y": -18,
      "z": -27,
      "name": "Rock_Sandstone_Cobble"
    },
    {
      "x": -9,
      "y": -17,
      "z": -27,
      "name": "Rock_Sandstone_Brick"
    },
    {
      "x": -9,
      "y": -16,
      "z": -27,
      "name": "Wood_Drywood_Fence"
    },
    {
      "x": -9,
      "y": -15,
      "z": -27,
      "name": "Wood_Drywood_Fence",
      "rotation": 2
    },
    {
      "x": -9,
      "y": -14,
      "z": -27,
      "name": "Rock_Sandstone_White_Cobble"
    },
    {
      "x": -9,
      "y": -13,
      "z": -27,
      "name": "Rock_Sandstone_White_Cobble"
    },
    {
      "x": -9,
      "y": -23,
      "z": -26,
      "name": "Soil_Dirt_Dry"
    },
    {
      "x": -9,
      "y": -22,
      "z": -26,
      "name": "Soil_Dirt_Dry"
    },
    {
      "x": -9,
      "y": -21,
      "z": -26,
      "name": "Soil_Dirt_Dry"
    },
    {
      "x": -9,
      "y": -20,
      "z": -26,
      "name": "Soil_Dirt_Dry"
    },
    {
      "x": -9,
      "y": -19,
      "z": -26,
      "name": "Soil_Dirt_Dry"
    },
    {
      "x": -9,
      "y": -18,
      "z": -26,
      "name": "Soil_Dirt_Dry"
    },
    {
      "x": -9,
      "y": -14,
      "z": -26,
      "name": "Plant_Vine_Wall_Dry"
    },
    {
      "x": -9,
      "y": -13,
      "z": -26,
      "name": "Plant_Vine_Wall_Dry"
    },
    {
      "x": -9,
      "y": -23,
      "z": -22,
      "name": "Rock_Sandstone_Cobble"
    },
    {
      "x": -9,
      "y": -22,
      "z": -22,
      "name": "Rock_Sandstone_Cobble"
    },
    {
      "x": -9,
      "y": -21,
      "z": -22,
      "name": "Rock_Sandstone_Cobble"
    },
    {
      "x": -9,
      "y": -20,
      "z": -22,
      "name": "Rock_Sandstone_Cobble"
    },
    {
      "x": -9,
      "y": -19,
      "z": -22,
      "name": "Rock_Sandstone_Cobble"
    },
    {
      "x": -9,
      "y": -18,
      "z": -22,
      "name": "Rock_Sandstone_Cobble_Stairs",
      "rotation": 2
    },
    {
      "x": -9,
      "y": -23,
      "z": -21,
      "name": "Rock_Sandstone_Cobble"
    },
    {
      "x": -9,
      "y": -22,
      "z": -21,
      "name": "Rock_Sandstone_Cobble"
    },
    {
      "x": -9,
      "y": -21,
      "z": -21,
      "name": "Rock_Sandstone_Cobble"
    },
    {
      "x": -9,
      "y": -20,
      "z": -21,
      "name": "Rock_Sandstone_Cobble"
    },
    {
      "x": -9,
      "y": -19,
      "z": -21,
      "name": "Rock_Sandstone_Cobble"
    },
    {
      "x": -9,
      "y": -18,
      "z": -21,
      "name": "Rock_Sandstone_Cobble"
    },
    {
      "x": -9,
      "y": -17,
      "z": -21,
      "name": "Rock_Sandstone_Cobble_Stairs",
      "rotation": 2
    },
    {
      "x": -9,
      "y": -14,
      "z": -21,
      "name": "Rock_Sandstone_Brick_Stairs",
      "rotation": 9
    },
    {
      "x": -9,
      "y": -13,
      "z": -21,
      "name": "Rock_Sandstone_Brick"
    },
    {
      "x": -9,
      "y": -12,
      "z": -21,
      "name": "Rock_Sandstone_Brick"
    },
    {
      "x": -9,
      "y": -11,
      "z": -21,
      "name": "Rock_Sandstone_Brick_Ornate"
    },
    {
      "x": -9,
      "y": -10,
      "z": -21,
      "name": "Rock_Sandstone_Brick_Half"
    },
    {
      "x": -9,
      "y": -23,
      "z": -20,
      "name": "Rock_Sandstone_Cobble"
    },
    {
      "x": -9,
      "y": -22,
      "z": -20,
      "name": "Rock_Sandstone_Cobble"
    },
    {
      "x": -9,
      "y": -21,
      "z": -20,
      "name": "Rock_Sandstone_Cobble"
    },
    {
      "x": -9,
      "y": -20,
      "z": -20,
      "name": "Rock_Sandstone_Cobble"
    },
    {
      "x": -9,
      "y": -19,
      "z": -20,
      "name": "Rock_Sandstone_Cobble"
    },
    {
      "x": -9,
      "y": -18,
      "z": -20,
      "name": "Rock_Sandstone_Cobble"
    },
    {
      "x": -9,
      "y": -17,
      "z": -20,
      "name": "Rock_Sandstone_Cobble"
    },
    {
      "x": -9,
      "y": -11,
      "z": -20,
      "name": "Wood_Drywood_Planks"
    },
    {
      "x": -9,
      "y": -23,
      "z": -19,
      "name": "Rock_Sandstone_Cobble"
    },
    {
      "x": -9,
      "y": -22,
      "z": -19,
      "name": "Rock_Sandstone_Cobble"
    },
    {
      "x": -9,
      "y": -21,
      "z": -19,
      "name": "Rock_Sandstone_Cobble"
    },
    {
      "x": -9,
      "y": -20,
      "z": -19,
      "name": "Rock_Sandstone_Cobble"
    },
    {
      "x": -9,
      "y": -19,
      "z": -19,
      "name": "Rock_Sandstone_Cobble"
    },
    {
      "x": -9,
      "y": -18,
      "z": -19,
      "name": "Rock_Sandstone_Cobble"
    },
    {
      "x": -9,
      "y": -17,
      "z": -19,
      "name": "Rock_Sandstone_Cobble"
    },
    {
      "x": -9,
      "y": -11,
      "z": -19,
      "name": "Wood_Drywood_Planks"
    },
    {
      "x": -9,
      "y": -23,
      "z": -18,
      "name": "Rock_Sandstone_Cobble"
    },
    {
      "x": -9,
      "y": -22,
      "z": -18,
      "name": "Rock_Sandstone_Cobble"
    },
    {
      "x": -9,
      "y": -21,
      "z": -18,
      "name": "Rock_Sandstone_Cobble"
    },
    {
      "x": -9,
      "y": -20,
      "z": -18,
      "name": "Rock_Sandstone_Cobble"
    },
    {
      "x": -9,
      "y": -19,
      "z": -18,
      "name": "Rock_Sandstone_Cobble"
    },
    {
      "x": -9,
      "y": -18,
      "z": -18,
      "name": "Rock_Sandstone_Cobble"
    },
    {
      "x": -9,
      "y": -17,
      "z": -18,
      "name": "Rock_Sandstone_Cobble"
    },
    {
      "x": -9,
      "y": -11,
      "z": -18,
      "name": "Wood_Drywood_Planks"
    },
    {
      "x": -9,
      "y": -23,
      "z": -17,
      "name": "Rock_Sandstone_Cobble"
    },
    {
      "x": -9,
      "y": -22,
      "z": -17,
      "name": "Rock_Sandstone_Cobble"
    },
    {
      "x": -9,
      "y": -21,
      "z": -17,
      "name": "Rock_Sandstone_Cobble"
    },
    {
      "x": -9,
      "y": -20,
      "z": -17,
      "name": "Rock_Sandstone_Cobble"
    },
    {
      "x": -9,
      "y": -19,
      "z": -17,
      "name": "Rock_Sandstone_Cobble"
    },
    {
      "x": -9,
      "y": -18,
      "z": -17,
      "name": "Rock_Sandstone_Cobble"
    },
    {
      "x": -9,
      "y": -17,
      "z": -17,
      "name": "Rock_Sandstone_Cobble"
    },
    {
      "x": -9,
      "y": -11,
      "z": -17,
      "name": "Wood_Drywood_Planks"
    },
    {
      "x": -9,
      "y": -23,
      "z": -16,
      "name": "Rock_Sandstone_Cobble"
    },
    {
      "x": -9,
      "y": -22,
      "z": -16,
      "name": "Rock_Sandstone_Cobble"
    },
    {
      "x": -9,
      "y": -21,
      "z": -16,
      "name": "Rock_Sandstone_Cobble"
    },
    {
      "x": -9,
      "y": -20,
      "z": -16,
      "name": "Rock_Sandstone_Cobble"
    },
    {
      "x": -9,
      "y": -19,
      "z": -16,
      "name": "Rock_Sandstone_Cobble"
    },
    {
      "x": -9,
      "y": -18,
      "z": -16,
      "name": "Rock_Sandstone_Cobble"
    },
    {
      "x": -9,
      "y": -17,
      "z": -16,
      "name": "Rock_Sandstone_Cobble"
    },
    {
      "x": -9,
      "y": -13,
      "z": -16,
      "name": "Cloth_Roof_Hide_Vertical",
      "rotation": 2
    },
    {
      "x": -9,
      "y": -11,
      "z": -16,
      "name": "Wood_Drywood_Planks"
    },
    {
      "x": -9,
      "y": -10,
      "z": -16,
      "name": "Block_Spawner_Block",
      "components": {
        "Components": {
          "BlockSpawner": {
            "BlockSpawnerId": "Zone2_Undead_Tier3"
          }
        }
      },
      "rotation": 2
    },
    {
      "x": -9,
      "y": -23,
      "z": -15,
      "name": "Rock_Sandstone_Cobble"
    },
    {
      "x": -9,
      "y": -22,
      "z": -15,
      "name": "Rock_Sandstone_Cobble"
    },
    {
      "x": -9,
      "y": -21,
      "z": -15,
      "name": "Rock_Sandstone_Cobble"
    },
    {
      "x": -9,
      "y": -20,
      "z": -15,
      "name": "Rock_Sandstone_Cobble"
    },
    {
      "x": -9,
      "y": -19,
      "z": -15,
      "name": "Rock_Sandstone_Cobble"
    },
    {
      "x": -9,
      "y": -18,
      "z": -15,
      "name": "Rock_Sandstone_Cobble"
    },
    {
      "x": -9,
      "y": -17,
      "z": -15,
      "name": "Rock_Sandstone_Brick"
    },
    {
      "x": -9,
      "y": -16,
      "z": -15,
      "name": "Rock_Sandstone_White_Brick"
    },
    {
      "x": -9,
      "y": -15,
      "z": -15,
      "name": "Furniture_Desert_Window"
    },
    {
      "x": -9,
      "y": -13,
      "z": -15,
      "name": "Rock_Sandstone_White_Brick"
    },
    {
      "x": -9,
      "y": -12,
      "z": -15,
      "name": "Rock_Sandstone_White_Brick"
    },
    {
      "x": -9,
      "y": -11,
      "z": -15,
      "name": "Rock_Sandstone_Brick_Ornate"
    },
    {
      "x": -9,
      "y": -10,
      "z": -15,
      "name": "Rock_Sandstone_White_Brick"
    },
    {
      "x": -9,
      "y": -9,
      "z": -15,
      "name": "Rock_Sandstone_White_Brick"
    },
    {
      "x": -9,
      "y": -16,
      "z": -14,
      "name": "Rock_Sandstone_Brick_Smooth_Half",
      "rotation": 4
    },
    {
      "x": -8,
      "y": -23,
      "z": -27,
      "name": "Rock_Sandstone_Cobble"
    },
    {
      "x": -8,
      "y": -22,
      "z": -27,
      "name": "Rock_Sandstone_Cobble"
    },
    {
      "x": -8,
      "y": -21,
      "z": -27,
      "name": "Rock_Sandstone_Cobble"
    },
    {
      "x": -8,
      "y": -20,
      "z": -27,
      "name": "Rock_Sandstone_Cobble"
    },
    {
      "x": -8,
      "y": -19,
      "z": -27,
      "name": "Rock_Sandstone_Cobble"
    },
    {
      "x": -8,
      "y": -18,
      "z": -27,
      "name": "Rock_Sandstone_Cobble"
    },
    {
      "x": -8,
      "y": -17,
      "z": -27,
      "name": "Rock_Sandstone_Brick"
    },
    {
      "x": -8,
      "y": -16,
      "z": -27,
      "name": "Wood_Drywood_Fence"
    },
    {
      "x": -8,
      "y": -15,
      "z": -27,
      "name": "Wood_Drywood_Fence",
      "rotation": 2
    },
    {
      "x": -8,
      "y": -14,
      "z": -27,
      "name": "Rock_Sandstone_White_Cobble"
    },
    {
      "x": -8,
      "y": -13,
      "z": -27,
      "name": "Rock_Sandstone_White_Cobble"
    },
    {
      "x": -8,
      "y": -23,
      "z": -21,
      "name": "Rock_Sandstone_Cobble"
    },
    {
      "x": -8,
      "y": -22,
      "z": -21,
      "name": "Rock_Sandstone_Cobble"
    },
    {
      "x": -8,
      "y": -21,
      "z": -21,
      "name": "Rock_Sandstone_Cobble"
    },
    {
      "x": -8,
      "y": -20,
      "z": -21,
      "name": "Rock_Sandstone_Cobble"
    },
    {
      "x": -8,
      "y": -19,
      "z": -21,
      "name": "Rock_Sandstone_Cobble"
    },
    {
      "x": -8,
      "y": -18,
      "z": -21,
      "name": "Rock_Sandstone_Cobble"
    },
    {
      "x": -8,
      "y": -17,
      "z": -21,
      "name": "Rock_Sandstone_Brick"
    },
    {
      "x": -8,
      "y": -16,
      "z": -21,
      "name": "Rock_Sandstone_Brick"
    },
    {
      "x": -8,
      "y": -15,
      "z": -21,
      "name": "Rock_Sandstone_Brick"
    },
    {
      "x": -8,
      "y": -14,
      "z": -21,
      "name": "Rock_Sandstone_Brick"
    },
    {
      "x": -8,
      "y": -13,
      "z": -21,
      "name": "Rock_Sandstone_Brick"
    },
    {
      "x": -8,
      "y": -12,
      "z": -21,
      "name": "Rock_Sandstone_Brick"
    },
    {
      "x": -8,
      "y": -11,
      "z": -21,
      "name": "Rock_Sandstone_Brick_Ornate"
    },
    {
      "x": -8,
      "y": -23,
      "z": -20,
      "name": "Rock_Sandstone_Cobble"
    },
    {
      "x": -8,
      "y": -22,
      "z": -20,
      "name": "Rock_Sandstone_Cobble"
    },
    {
      "x": -8,
      "y": -21,
      "z": -20,
      "name": "Rock_Sandstone_Cobble"
    },
    {
      "x": -8,
      "y": -20,
      "z": -20,
      "name": "Rock_Sandstone_Cobble"
    },
    {
      "x": -8,
      "y": -19,
      "z": -20,
      "name": "Rock_Sandstone_Cobble"
    },
    {
      "x": -8,
      "y": -18,
      "z": -20,
      "name": "Rock_Sandstone_Cobble"
    },
    {
      "x": -8,
      "y": -17,
      "z": -20,
      "name": "Rock_Sandstone_Cobble"
    },
    {
      "x": -8,
      "y": -16,
      "z": -20,
      "name": "Rubble_Sandstone"
    },
    {
      "x": -8,
      "y": -11,
      "z": -20,
      "name": "Wood_Drywood_Planks"
    },
    {
      "x": -8,
      "y": -23,
      "z": -19,
      "name": "Rock_Sandstone_Cobble"
    },
    {
      "x": -8,
      "y": -22,
      "z": -19,
      "name": "Rock_Sandstone_Cobble"
    },
    {
      "x": -8,
      "y": -21,
      "z": -19,
      "name": "Rock_Sandstone_Cobble"
    },
    {
      "x": -8,
      "y": -20,
      "z": -19,
      "name": "Rock_Sandstone_Cobble"
    },
    {
      "x": -8,
      "y": -19,
      "z": -19,
      "name": "Rock_Sandstone_Cobble"
    },
    {
      "x": -8,
      "y": -18,
      "z": -19,
      "name": "Rock_Sandstone_Cobble"
    },
    {
      "x": -8,
      "y": -17,
      "z": -19,
      "name": "Rock_Sandstone_Cobble"
    },
    {
      "x": -8,
      "y": -11,
      "z": -19,
      "name": "Wood_Drywood_Planks"
    },
    {
      "x": -8,
      "y": -23,
      "z": -18,
      "name": "Rock_Sandstone_Cobble"
    },
    {
      "x": -8,
      "y": -22,
      "z": -18,
      "name": "Rock_Sandstone_Cobble"
    },
    {
      "x": -8,
      "y": -21,
      "z": -18,
      "name": "Rock_Sandstone_Cobble"
    },
    {
      "x": -8,
      "y": -20,
      "z": -18,
      "name": "Rock_Sandstone_Cobble"
    },
    {
      "x": -8,
      "y": -19,
      "z": -18,
      "name": "Rock_Sandstone_Cobble"
    },
    {
      "x": -8,
      "y": -18,
      "z": -18,
      "name": "Rock_Sandstone_Cobble"
    },
    {
      "x": -8,
      "y": -17,
      "z": -18,
      "name": "Rock_Sandstone_Cobble"
    },
    {
      "x": -8,
      "y": -11,
      "z": -18,
      "name": "Wood_Drywood_Planks"
    },
    {
      "x": -8,
      "y": -23,
      "z": -17,
      "name": "Rock_Sandstone_Cobble"
    },
    {
      "x": -8,
      "y": -22,
      "z": -17,
      "name": "Rock_Sandstone_Cobble"
    },
    {
      "x": -8,
      "y": -21,
      "z": -17,
      "name": "Rock_Sandstone_Cobble"
    },
    {
      "x": -8,
      "y": -20,
      "z": -17,
      "name": "Rock_Sandstone_Cobble"
    },
    {
      "x": -8,
      "y": -19,
      "z": -17,
      "name": "Rock_Sandstone_Cobble"
    },
    {
      "x": -8,
      "y": -18,
      "z": -17,
      "name": "Rock_Sandstone_Cobble"
    },
    {
      "x": -8,
      "y": -17,
      "z": -17,
      "name": "Rock_Sandstone_Cobble"
    },
    {
      "x": -8,
      "y": -11,
      "z": -17,
      "name": "Wood_Drywood_Planks"
    },
    {
      "x": -8,
      "y": -23,
      "z": -16,
      "name": "Rock_Sandstone_Cobble"
    },
    {
      "x": -8,
      "y": -22,
      "z": -16,
      "name": "Rock_Sandstone_Cobble"
    },
    {
      "x": -8,
      "y": -21,
      "z": -16,
      "name": "Rock_Sandstone_Cobble"
    },
    {
      "x": -8,
      "y": -20,
      "z": -16,
      "name": "Rock_Sandstone_Cobble"
    },
    {
      "x": -8,
      "y": -19,
      "z": -16,
      "name": "Rock_Sandstone_Cobble"
    },
    {
      "x": -8,
      "y": -18,
      "z": -16,
      "name": "Rock_Sandstone_Cobble"
    },
    {
      "x": -8,
      "y": -17,
      "z": -16,
      "name": "Rock_Sandstone_Cobble"
    },
    {
      "x": -8,
      "y": -16,
      "z": -16,
      "name": "Plant_Bush_Arid"
    },
    {
      "x": -8,
      "y": -11,
      "z": -16,
      "name": "Wood_Drywood_Planks"
    },
    {
      "x": -8,
      "y": -10,
      "z": -16,
      "name": "Deco_Pot_Clay_Broken"
    },
    {
      "x": -8,
      "y": -23,
      "z": -15,
      "name": "Rock_Sandstone_Cobble"
    },
    {
      "x": -8,
      "y": -22,
      "z": -15,
      "name": "Rock_Sandstone_Cobble"
    },
    {
      "x": -8,
      "y": -21,
      "z": -15,
      "name": "Rock_Sandstone_Cobble"
    },
    {
      "x": -8,
      "y": -20,
      "z": -15,
      "name": "Rock_Sandstone_Cobble"
    },
    {
      "x": -8,
      "y": -19,
      "z": -15,
      "name": "Rock_Sandstone_Cobble"
    },
    {
      "x": -8,
      "y": -18,
      "z": -15,
      "name": "Rock_Sandstone_Cobble"
    },
    {
      "x": -8,
      "y": -17,
      "z": -15,
      "name": "Rock_Sandstone_Brick"
    },
    {
      "x": -8,
      "y": -16,
      "z": -15,
      "name": "Rock_Sandstone_White_Brick"
    },
    {
      "x": -8,
      "y": -15,
      "z": -15,
      "name": "Rock_Sandstone_White_Brick"
    },
    {
      "x": -8,
      "y": -14,
      "z": -15,
      "name": "Rock_Sandstone_White_Brick"
    },
    {
      "x": -8,
      "y": -13,
      "z": -15,
      "name": "Rock_Sandstone_White_Brick"
    },
    {
      "x": -8,
      "y": -12,
      "z": -15,
      "name": "Rock_Sandstone_White_Brick"
    },
    {
      "x": -8,
      "y": -11,
      "z": -15,
      "name": "Rock_Sandstone_Brick_Ornate"
    },
    {
      "x": -8,
      "y": -10,
      "z": -15,
      "name": "Rock_Sandstone_White_Brick"
    },
    {
      "x": -8,
      "y": -9,
      "z": -15,
      "name": "Rock_Sandstone_White_Brick"
    },
    {
      "x": -7,
      "y": -14,
      "z": -27,
      "name": "Rock_Sandstone_White_Cobble_Half",
      "rotation": 5
    },
    {
      "x": -7,
      "y": -23,
      "z": -21,
      "name": "Rock_Sandstone_Cobble"
    },
    {
      "x": -7,
      "y": -22,
      "z": -21,
      "name": "Rock_Sandstone_Cobble"
    },
    {
      "x": -7,
      "y": -21,
      "z": -21,
      "name": "Rock_Sandstone_Cobble"
    },
    {
      "x": -7,
      "y": -20,
      "z": -21,
      "name": "Rock_Sandstone_Cobble"
    },
    {
      "x": -7,
      "y": -19,
      "z": -21,
      "name": "Rock_Sandstone_Cobble"
    },
    {
      "x": -7,
      "y": -18,
      "z": -21,
      "name": "Rock_Sandstone_Cobble"
    },
    {
      "x": -7,
      "y": -17,
      "z": -21,
      "name": "Rock_Sandstone_Brick"
    },
    {
      "x": -7,
      "y": -16,
      "z": -21,
      "name": "Rock_Sandstone_Brick"
    },
    {
      "x": -7,
      "y": -15,
      "z": -21,
      "name": "Rock_Sandstone_Brick"
    },
    {
      "x": -7,
      "y": -14,
      "z": -21,
      "name": "Rock_Sandstone_Brick"
    },
    {
      "x": -7,
      "y": -13,
      "z": -21,
      "name": "Rock_Sandstone_Brick"
    },
    {
      "x": -7,
      "y": -12,
      "z": -21,
      "name": "Rock_Sandstone_Brick"
    },
    {
      "x": -7,
      "y": -11,
      "z": -21,
      "name": "Rock_Sandstone_Brick"
    },
    {
      "x": -7,
      "y": -23,
      "z": -20,
      "name": "Rock_Sandstone_Cobble"
    },
    {
      "x": -7,
      "y": -22,
      "z": -20,
      "name": "Rock_Sandstone_Cobble"
    },
    {
      "x": -7,
      "y": -21,
      "z": -20,
      "name": "Rock_Sandstone_Cobble"
    },
    {
      "x": -7,
      "y": -20,
      "z": -20,
      "name": "Rock_Sandstone_Cobble"
    },
    {
      "x": -7,
      "y": -19,
      "z": -20,
      "name": "Rock_Sandstone_Cobble"
    },
    {
      "x": -7,
      "y": -18,
      "z": -20,
      "name": "Rock_Sandstone_Cobble"
    },
    {
      "x": -7,
      "y": -17,
      "z": -20,
      "name": "Soil_Dirt_Dry"
    },
    {
      "x": -7,
      "y": -12,
      "z": -20,
      "name": "Rock_Sandstone_Brick"
    },
    {
      "x": -7,
      "y": -11,
      "z": -20,
      "name": "Rock_Sandstone_Brick"
    },
    {
      "x": -7,
      "y": -23,
      "z": -19,
      "name": "Rock_Sandstone_Cobble"
    },
    {
      "x": -7,
      "y": -22,
      "z": -19,
      "name": "Rock_Sandstone_Cobble"
    },
    {
      "x": -7,
      "y": -21,
      "z": -19,
      "name": "Rock_Sandstone_Cobble"
    },
    {
      "x": -7,
      "y": -20,
      "z": -19,
      "name": "Rock_Sandstone_Cobble"
    },
    {
      "x": -7,
      "y": -19,
      "z": -19,
      "name": "Rock_Sandstone_Cobble"
    },
    {
      "x": -7,
      "y": -18,
      "z": -19,
      "name": "Rock_Sandstone_Cobble"
    },
    {
      "x": -7,
      "y": -17,
      "z": -19,
      "name": "Rock_Sandstone_Cobble"
    },
    {
      "x": -7,
      "y": -12,
      "z": -19,
      "name": "Rock_Sandstone_Brick"
    },
    {
      "x": -7,
      "y": -11,
      "z": -19,
      "name": "Rock_Sandstone_Brick"
    },
    {
      "x": -7,
      "y": -23,
      "z": -18,
      "name": "Rock_Sandstone_Cobble"
    },
    {
      "x": -7,
      "y": -22,
      "z": -18,
      "name": "Rock_Sandstone_Cobble"
    },
    {
      "x": -7,
      "y": -21,
      "z": -18,
      "name": "Rock_Sandstone_Cobble"
    },
    {
      "x": -7,
      "y": -20,
      "z": -18,
      "name": "Rock_Sandstone_Cobble"
    },
    {
      "x": -7,
      "y": -19,
      "z": -18,
      "name": "Rock_Sandstone_Cobble"
    },
    {
      "x": -7,
      "y": -18,
      "z": -18,
      "name": "Rock_Sandstone_Cobble"
    },
    {
      "x": -7,
      "y": -17,
      "z": -18,
      "name": "Rock_Sandstone_Cobble"
    },
    {
      "x": -7,
      "y": -12,
      "z": -18,
      "name": "Rock_Sandstone_Brick"
    },
    {
      "x": -7,
      "y": -11,
      "z": -18,
      "name": "Rock_Sandstone_Brick_Ornate"
    },
    {
      "x": -7,
      "y": -10,
      "z": -18,
      "name": "Rock_Sandstone_Brick"
    },
    {
      "x": -7,
      "y": -9,
      "z": -18,
      "name": "Rock_Sandstone_Brick_Half"
    },
    {
      "x": -7,
      "y": -23,
      "z": -17,
      "name": "Rock_Sandstone_Cobble"
    },
    {
      "x": -7,
      "y": -22,
      "z": -17,
      "name": "Rock_Sandstone_Cobble"
    },
    {
      "x": -7,
      "y": -21,
      "z": -17,
      "name": "Rock_Sandstone_Cobble"
    },
    {
      "x": -7,
      "y": -20,
      "z": -17,
      "name": "Rock_Sandstone_Cobble"
    },
    {
      "x": -7,
      "y": -19,
      "z": -17,
      "name": "Rock_Sandstone_Cobble"
    },
    {
      "x": -7,
      "y": -18,
      "z": -17,
      "name": "Rock_Sandstone_Cobble"
    },
    {
      "x": -7,
      "y": -17,
      "z": -17,
      "name": "Soil_Dirt_Dry"
    },
    {
      "x": -7,
      "y": -16,
      "z": -17,
      "name": "Plant_Grass_Arid"
    },
    {
      "x": -7,
      "y": -11,
      "z": -17,
      "name": "Rock_Sandstone_Brick_Ornate"
    },
    {
      "x": -7,
      "y": -10,
      "z": -17,
      "name": "Rock_Sandstone_Brick"
    },
    {
      "x": -7,
      "y": -23,
      "z": -16,
      "name": "Rock_Sandstone_Cobble"
    },
    {
      "x": -7,
      "y": -22,
      "z": -16,
      "name": "Rock_Sandstone_Cobble"
    },
    {
      "x": -7,
      "y": -21,
      "z": -16,
      "name": "Rock_Sandstone_Cobble"
    },
    {
      "x": -7,
      "y": -20,
      "z": -16,
      "name": "Rock_Sandstone_Cobble"
    },
    {
      "x": -7,
      "y": -19,
      "z": -16,
      "name": "Rock_Sandstone_Cobble"
    },
    {
      "x": -7,
      "y": -18,
      "z": -16,
      "name": "Rock_Sandstone_Cobble"
    },
    {
      "x": -7,
      "y": -17,
      "z": -16,
      "name": "Soil_Dirt_Dry"
    },
    {
      "x": -7,
      "y": -11,
      "z": -16,
      "name": "Rock_Sandstone_Brick_Ornate"
    },
    {
      "x": -7,
      "y": -10,
      "z": -16,
      "name": "Rock_Sandstone_Brick"
    },
    {
      "x": -7,
      "y": -9,
      "z": -16,
      "name": "Rock_Sandstone_Brick"
    },
    {
      "x": -7,
      "y": -15,
      "z": -15,
      "name": "Rock_Sandstone_Brick_Half",
      "rotation": 5
    },
    {
      "x": -7,
      "y": -14,
      "z": -15,
      "name": "Rock_Sandstone_Brick_Half",
      "rotation": 5
    },
    {
      "x": -7,
      "y": -13,
      "z": -15,
      "name": "Rock_Sandstone_Brick"
    },
    {
      "x": -7,
      "y": -12,
      "z": -15,
      "name": "Rock_Sandstone_Brick"
    },
    {
      "x": -7,
      "y": -11,
      "z": -15,
      "name": "Rock_Sandstone_Brick_Ornate"
    },
    {
      "x": -7,
      "y": -10,
      "z": -15,
      "name": "Rock_Sandstone_Brick"
    },
    {
      "x": -7,
      "y": -9,
      "z": -15,
      "name": "Rock_Sandstone_Brick"
    },
    {
      "x": -6,
      "y": -23,
      "z": -27,
      "name": "Rock_Sandstone_Cobble"
    },
    {
      "x": -6,
      "y": -22,
      "z": -27,
      "name": "Rock_Sandstone_Cobble"
    },
    {
      "x": -6,
      "y": -21,
      "z": -27,
      "name": "Rock_Sandstone_Cobble"
    },
    {
      "x": -6,
      "y": -20,
      "z": -27,
      "name": "Rock_Sandstone_Cobble"
    },
    {
      "x": -6,
      "y": -19,
      "z": -27,
      "name": "Rock_Sandstone_Cobble"
    },
    {
      "x": -6,
      "y": -18,
      "z": -27,
      "name": "Rock_Sandstone_Cobble"
    },
    {
      "x": -6,
      "y": -17,
      "z": -27,
      "name": "Rock_Sandstone_Brick"
    },
    {
      "x": -6,
      "y": -16,
      "z": -27,
      "name": "Rock_Sandstone_Brick"
    },
    {
      "x": -6,
      "y": -23,
      "z": -21,
      "name": "Rock_Sandstone_Cobble"
    },
    {
      "x": -6,
      "y": -22,
      "z": -21,
      "name": "Rock_Sandstone_Cobble"
    },
    {
      "x": -6,
      "y": -21,
      "z": -21,
      "name": "Rock_Sandstone_Cobble"
    },
    {
      "x": -6,
      "y": -20,
      "z": -21,
      "name": "Rock_Sandstone_Cobble"
    },
    {
      "x": -6,
      "y": -19,
      "z": -21,
      "name": "Rock_Sandstone_Cobble"
    },
    {
      "x": -6,
      "y": -18,
      "z": -21,
      "name": "Rock_Sandstone_Cobble"
    },
    {
      "x": -6,
      "y": -17,
      "z": -21,
      "name": "Rock_Sandstone_Brick"
    },
    {
      "x": -6,
      "y": -16,
      "z": -21,
      "name": "Rock_Sandstone_Brick"
    },
    {
      "x": -6,
      "y": -15,
      "z": -21,
      "name": "Rock_Sandstone_Brick"
    },
    {
      "x": -6,
      "y": -14,
      "z": -21,
      "name": "Rock_Sandstone_White_Cobble"
    },
    {
      "x": -6,
      "y": -13,
      "z": -21,
      "name": "Rock_Sandstone_White_Cobble"
    },
    {
      "x": -6,
      "y": -12,
      "z": -21,
      "name": "Rock_Sandstone_White_Cobble"
    },
    {
      "x": -6,
      "y": -11,
      "z": -21,
      "name": "Rock_Sandstone_Brick"
    },
    {
      "x": -6,
      "y": -23,
      "z": -20,
      "name": "Rock_Sandstone_Cobble"
    },
    {
      "x": -6,
      "y": -22,
      "z": -20,
      "name": "Rock_Sandstone_Cobble"
    },
    {
      "x": -6,
      "y": -21,
      "z": -20,
      "name": "Rock_Sandstone_Cobble"
    },
    {
      "x": -6,
      "y": -20,
      "z": -20,
      "name": "Rock_Sandstone_Cobble"
    },
    {
      "x": -6,
      "y": -19,
      "z": -20,
      "name": "Rock_Sandstone_Cobble"
    },
    {
      "x": -6,
      "y": -18,
      "z": -20,
      "name": "Rock_Sandstone_Cobble"
    },
    {
      "x": -6,
      "y": -17,
      "z": -20,
      "name": "Soil_Dirt_Dry"
    },
    {
      "x": -6,
      "y": -13,
      "z": -20,
      "name": "Rock_Sandstone_White_Cobble"
    },
    {
      "x": -6,
      "y": -12,
      "z": -20,
      "name": "Rock_Sandstone_White_Cobble"
    },
    {
      "x": -6,
      "y": -11,
      "z": -20,
      "name": "Rock_Sandstone_Cobble_Stairs",
      "rotation": 1
    },
    {
      "x": -6,
      "y": -23,
      "z": -19,
      "name": "Rock_Sandstone_Cobble"
    },
    {
      "x": -6,
      "y": -22,
      "z": -19,
      "name": "Rock_Sandstone_Cobble"
    },
    {
      "x": -6,
      "y": -21,
      "z": -19,
      "name": "Rock_Sandstone_Cobble"
    },
    {
      "x": -6,
      "y": -20,
      "z": -19,
      "name": "Rock_Sandstone_Cobble"
    },
    {
      "x": -6,
      "y": -19,
      "z": -19,
      "name": "Rock_Sandstone_Cobble"
    },
    {
      "x": -6,
      "y": -18,
      "z": -19,
      "name": "Rock_Sandstone_Cobble"
    },
    {
      "x": -6,
      "y": -17,
      "z": -19,
      "name": "Soil_Dirt_Dry"
    },
    {
      "x": -6,
      "y": -13,
      "z": -19,
      "name": "Rock_Sandstone_White_Cobble"
    },
    {
      "x": -6,
      "y": -12,
      "z": -19,
      "name": "Rock_Sandstone_White_Cobble"
    },
    {
      "x": -6,
      "y": -11,
      "z": -19,
      "name": "Rock_Sandstone_Cobble_Stairs",
      "rotation": 1
    },
    {
      "x": -6,
      "y": -23,
      "z": -18,
      "name": "Rock_Sandstone_Cobble"
    },
    {
      "x": -6,
      "y": -22,
      "z": -18,
      "name": "Rock_Sandstone_Cobble"
    },
    {
      "x": -6,
      "y": -21,
      "z": -18,
      "name": "Rock_Sandstone_Cobble"
    },
    {
      "x": -6,
      "y": -20,
      "z": -18,
      "name": "Rock_Sandstone_Cobble"
    },
    {
      "x": -6,
      "y": -19,
      "z": -18,
      "name": "Rock_Sandstone_Cobble"
    },
    {
      "x": -6,
      "y": -18,
      "z": -18,
      "name": "Rock_Sandstone_Cobble"
    },
    {
      "x": -6,
      "y": -17,
      "z": -18,
      "name": "Soil_Dirt_Dry"
    },
    {
      "x": -6,
      "y": -13,
      "z": -18,
      "name": "Rock_Sandstone_White_Cobble"
    },
    {
      "x": -6,
      "y": -12,
      "z": -18,
      "name": "Rock_Sandstone_White_Cobble"
    },
    {
      "x": -6,
      "y": -11,
      "z": -18,
      "name": "Rock_Sandstone_White_Cobble_Half"
    },
    {
      "x": -6,
      "y": -23,
      "z": -17,
      "name": "Rock_Sandstone_Cobble"
    },
    {
      "x": -6,
      "y": -22,
      "z": -17,
      "name": "Rock_Sandstone_Cobble"
    },
    {
      "x": -6,
      "y": -21,
      "z": -17,
      "name": "Rock_Sandstone_Cobble"
    },
    {
      "x": -6,
      "y": -20,
      "z": -17,
      "name": "Rock_Sandstone_Cobble"
    },
    {
      "x": -6,
      "y": -19,
      "z": -17,
      "name": "Rock_Sandstone_Cobble"
    },
    {
      "x": -6,
      "y": -18,
      "z": -17,
      "name": "Rock_Sandstone_Cobble"
    },
    {
      "x": -6,
      "y": -17,
      "z": -17,
      "name": "Soil_Dirt_Dry"
    },
    {
      "x": -6,
      "y": -12,
      "z": -17,
      "name": "Plant_Vine_Wall_Dry",
      "rotation": 1
    },
    {
      "x": -6,
      "y": -11,
      "z": -17,
      "name": "Plant_Vine_Wall_Dry",
      "rotation": 1
    },
    {
      "x": -6,
      "y": -10,
      "z": -17,
      "name": "Plant_Vine_Wall_Dry",
      "rotation": 1
    },
    {
      "x": -6,
      "y": -23,
      "z": -16,
      "name": "Rock_Sandstone_Cobble"
    },
    {
      "x": -6,
      "y": -22,
      "z": -16,
      "name": "Rock_Sandstone_Cobble"
    },
    {
      "x": -6,
      "y": -21,
      "z": -16,
      "name": "Rock_Sandstone_Cobble"
    },
    {
      "x": -6,
      "y": -20,
      "z": -16,
      "name": "Rock_Sandstone_Cobble"
    },
    {
      "x": -6,
      "y": -19,
      "z": -16,
      "name": "Rock_Sandstone_Cobble"
    },
    {
      "x": -6,
      "y": -18,
      "z": -16,
      "name": "Rock_Sandstone_Cobble"
    },
    {
      "x": -6,
      "y": -17,
      "z": -16,
      "name": "Soil_Dirt_Dry"
    },
    {
      "x": -6,
      "y": -10,
      "z": -16,
      "name": "Plant_Vine_Wall_Dry",
      "rotation": 1
    },
    {
      "x": -6,
      "y": -9,
      "z": -16,
      "name": "Plant_Vine_Wall_Dry",
      "rotation": 1
    },
    {
      "x": -6,
      "y": -14,
      "z": -15,
      "name": "Plant_Vine_Wall_Dry",
      "rotation": 1
    },
    {
      "x": -6,
      "y": -13,
      "z": -15,
      "name": "Plant_Vine_Wall_Dry",
      "rotation": 1
    },
    {
      "x": -5,
      "y": -23,
      "z": -27,
      "name": "Rock_Sandstone_Cobble"
    },
    {
      "x": -5,
      "y": -22,
      "z": -27,
      "name": "Rock_Sandstone_Cobble"
    },
    {
      "x": -5,
      "y": -21,
      "z": -27,
      "name": "Rock_Sandstone_Cobble"
    },
    {
      "x": -5,
      "y": -20,
      "z": -27,
      "name": "Rock_Sandstone_Cobble"
    },
    {
      "x": -5,
      "y": -19,
      "z": -27,
      "name": "Rock_Sandstone_Cobble"
    },
    {
      "x": -5,
      "y": -18,
      "z": -27,
      "name": "Rock_Sandstone_Cobble"
    },
    {
      "x": -5,
      "y": -17,
      "z": -27,
      "name": "Rock_Sandstone_Brick"
    },
    {
      "x": -5,
      "y": -16,
      "z": -27,
      "name": "Rock_Sandstone_Brick_Half"
    },
    {
      "x": -5,
      "y": -23,
      "z": -21,
      "name": "Rock_Sandstone_Cobble"
    },
    {
      "x": -5,
      "y": -22,
      "z": -21,
      "name": "Rock_Sandstone_Cobble"
    },
    {
      "x": -5,
      "y": -21,
      "z": -21,
      "name": "Rock_Sandstone_Cobble"
    },
    {
      "x": -5,
      "y": -20,
      "z": -21,
      "name": "Rock_Sandstone_Cobble"
    },
    {
      "x": -5,
      "y": -19,
      "z": -21,
      "name": "Rock_Sandstone_Cobble"
    },
    {
      "x": -5,
      "y": -18,
      "z": -21,
      "name": "Rock_Sandstone_Cobble"
    },
    {
      "x": -5,
      "y": -17,
      "z": -21,
      "name": "Rock_Sandstone_Brick"
    },
    {
      "x": -5,
      "y": -16,
      "z": -21,
      "name": "Rock_Sandstone_Brick"
    },
    {
      "x": -5,
      "y": -15,
      "z": -21,
      "name": "Rock_Sandstone_Brick"
    },
    {
      "x": -5,
      "y": -14,
      "z": -21,
      "name": "Rock_Sandstone_White_Cobble"
    },
    {
      "x": -5,
      "y": -13,
      "z": -21,
      "name": "Rock_Sandstone_White_Cobble"
    },
    {
      "x": -5,
      "y": -12,
      "z": -21,
      "name": "Rock_Sandstone_White_Cobble"
    },
    {
      "x": -5,
      "y": -11,
      "z": -21,
      "name": "Rock_Sandstone_White_Cobble"
    },
    {
      "x": -5,
      "y": -23,
      "z": -20,
      "name": "Rock_Sandstone_Cobble"
    },
    {
      "x": -5,
      "y": -22,
      "z": -20,
      "name": "Rock_Sandstone_Cobble"
    },
    {
      "x": -5,
      "y": -21,
      "z": -20,
      "name": "Rock_Sandstone_Cobble"
    },
    {
      "x": -5,
      "y": -20,
      "z": -20,
      "name": "Rock_Sandstone_Cobble"
    },
    {
      "x": -5,
      "y": -19,
      "z": -20,
      "name": "Rock_Sandstone_Cobble"
    },
    {
      "x": -5,
      "y": -18,
      "z": -20,
      "name": "Rock_Sandstone_Cobble"
    },
    {
      "x": -5,
      "y": -17,
      "z": -20,
      "name": "Soil_Dirt_Dry"
    },
    {
      "x": -5,
      "y": -14,
      "z": -20,
      "name": "Rock_Sandstone_White_Cobble"
    },
    {
      "x": -5,
      "y": -13,
      "z": -20,
      "name": "Rock_Sandstone_White_Cobble"
    },
    {
      "x": -5,
      "y": -12,
      "z": -20,
      "name": "Rock_Sandstone_Cobble_Stairs",
      "rotation": 1
    },
    {
      "x": -5,
      "y": -23,
      "z": -19,
      "name": "Rock_Sandstone_Cobble"
    },
    {
      "x": -5,
      "y": -22,
      "z": -19,
      "name": "Rock_Sandstone_Cobble"
    },
    {
      "x": -5,
      "y": -21,
      "z": -19,
      "name": "Rock_Sandstone_Cobble"
    },
    {
      "x": -5,
      "y": -20,
      "z": -19,
      "name": "Rock_Sandstone_Cobble"
    },
    {
      "x": -5,
      "y": -19,
      "z": -19,
      "name": "Rock_Sandstone_Cobble"
    },
    {
      "x": -5,
      "y": -18,
      "z": -19,
      "name": "Rock_Sandstone_Cobble"
    },
    {
      "x": -5,
      "y": -17,
      "z": -19,
      "name": "Soil_Dirt_Dry"
    },
    {
      "x": -5,
      "y": -16,
      "z": -19,
      "name": "Plant_Grass_Arid"
    },
    {
      "x": -5,
      "y": -14,
      "z": -19,
      "name": "Rock_Sandstone_White_Cobble"
    },
    {
      "x": -5,
      "y": -13,
      "z": -19,
      "name": "Rock_Sandstone_White_Cobble"
    },
    {
      "x": -5,
      "y": -12,
      "z": -19,
      "name": "Rock_Sandstone_Cobble_Stairs",
      "rotation": 1
    },
    {
      "x": -5,
      "y": -23,
      "z": -18,
      "name": "Rock_Sandstone_Cobble"
    },
    {
      "x": -5,
      "y": -22,
      "z": -18,
      "name": "Rock_Sandstone_Cobble"
    },
    {
      "x": -5,
      "y": -21,
      "z": -18,
      "name": "Rock_Sandstone_Cobble"
    },
    {
      "x": -5,
      "y": -20,
      "z": -18,
      "name": "Rock_Sandstone_Cobble"
    },
    {
      "x": -5,
      "y": -19,
      "z": -18,
      "name": "Rock_Sandstone_Cobble"
    },
    {
      "x": -5,
      "y": -18,
      "z": -18,
      "name": "Rock_Sandstone_Cobble"
    },
    {
      "x": -5,
      "y": -17,
      "z": -18,
      "name": "Soil_Dirt_Dry"
    },
    {
      "x": -5,
      "y": -14,
      "z": -18,
      "name": "Rock_Sandstone_White_Cobble"
    },
    {
      "x": -5,
      "y": -13,
      "z": -18,
      "name": "Rock_Sandstone_White_Cobble"
    },
    {
      "x": -5,
      "y": -12,
      "z": -18,
      "name": "Rock_Sandstone_White_Cobble"
    },
    {
      "x": -5,
      "y": -23,
      "z": -17,
      "name": "Rock_Sandstone_Cobble"
    },
    {
      "x": -5,
      "y": -22,
      "z": -17,
      "name": "Rock_Sandstone_Cobble"
    },
    {
      "x": -5,
      "y": -21,
      "z": -17,
      "name": "Rock_Sandstone_Cobble"
    },
    {
      "x": -5,
      "y": -20,
      "z": -17,
      "name": "Rock_Sandstone_Cobble"
    },
    {
      "x": -5,
      "y": -19,
      "z": -17,
      "name": "Rock_Sandstone_Cobble"
    },
    {
      "x": -5,
      "y": -18,
      "z": -17,
      "name": "Rock_Sandstone_Cobble"
    },
    {
      "x": -5,
      "y": -17,
      "z": -17,
      "name": "Soil_Dirt_Dry"
    },
    {
      "x": -5,
      "y": -16,
      "z": -17,
      "name": "Plant_Bush_Arid"
    },
    {
      "x": -5,
      "y": -14,
      "z": -17,
      "name": "Plant_Vine_Wall_Dry"
    },
    {
      "x": -5,
      "y": -13,
      "z": -17,
      "name": "Plant_Vine_Wall_Dry"
    },
    {
      "x": -5,
      "y": -12,
      "z": -17,
      "name": "Plant_Vine_Wall_Dry"
    },
    {
      "x": -5,
      "y": -23,
      "z": -16,
      "name": "Rock_Sandstone_Cobble"
    },
    {
      "x": -5,
      "y": -22,
      "z": -16,
      "name": "Rock_Sandstone_Cobble"
    },
    {
      "x": -5,
      "y": -21,
      "z": -16,
      "name": "Rock_Sandstone_Cobble"
    },
    {
      "x": -5,
      "y": -20,
      "z": -16,
      "name": "Rock_Sandstone_Cobble"
    },
    {
      "x": -5,
      "y": -19,
      "z": -16,
      "name": "Rock_Sandstone_Cobble"
    },
    {
      "x": -5,
      "y": -18,
      "z": -16,
      "name": "Rock_Sandstone_Cobble"
    },
    {
      "x": -5,
      "y": -17,
      "z": -16,
      "name": "Soil_Dirt_Dry"
    },
    {
      "x": -5,
      "y": -16,
      "z": -16,
      "name": "Rubble_Sandstone_Medium"
    },
    {
      "x": -5,
      "y": -23,
      "z": -15,
      "name": "Rock_Sandstone_Cobble"
    },
    {
      "x": -5,
      "y": -22,
      "z": -15,
      "name": "Rock_Sandstone_Cobble"
    },
    {
      "x": -5,
      "y": -21,
      "z": -15,
      "name": "Rock_Sandstone_Cobble"
    },
    {
      "x": -5,
      "y": -20,
      "z": -15,
      "name": "Rock_Sandstone_Cobble"
    },
    {
      "x": -5,
      "y": -19,
      "z": -15,
      "name": "Rock_Sandstone_Cobble"
    },
    {
      "x": -5,
      "y": -18,
      "z": -15,
      "name": "Rock_Sandstone_Cobble"
    },
    {
      "x": -5,
      "y": -17,
      "z": -15,
      "name": "Rock_Sandstone_Brick"
    },
    {
      "x": -5,
      "y": -16,
      "z": -15,
      "name": "Rock_Sandstone_Brick"
    },
    {
      "x": -4,
      "y": -23,
      "z": -27,
      "name": "Rock_Sandstone_Cobble"
    },
    {
      "x": -4,
      "y": -22,
      "z": -27,
      "name": "Rock_Sandstone_Cobble"
    },
    {
      "x": -4,
      "y": -21,
      "z": -27,
      "name": "Rock_Sandstone_Cobble"
    },
    {
      "x": -4,
      "y": -20,
      "z": -27,
      "name": "Rock_Sandstone_Cobble"
    },
    {
      "x": -4,
      "y": -19,
      "z": -27,
      "name": "Rock_Sandstone_Cobble"
    },
    {
      "x": -4,
      "y": -18,
      "z": -27,
      "name": "Rock_Sandstone_Cobble"
    },
    {
      "x": -4,
      "y": -17,
      "z": -27,
      "name": "Rock_Sandstone_Brick"
    },
    {
      "x": -4,
      "y": -16,
      "z": -27,
      "name": "Rock_Sandstone_Brick"
    },
    {
      "x": -4,
      "y": -15,
      "z": -27,
      "name": "Rock_Sandstone_White_Cobble"
    },
    {
      "x": -4,
      "y": -23,
      "z": -21,
      "name": "Rock_Sandstone_Cobble"
    },
    {
      "x": -4,
      "y": -22,
      "z": -21,
      "name": "Rock_Sandstone_Cobble"
    },
    {
      "x": -4,
      "y": -21,
      "z": -21,
      "name": "Rock_Sandstone_Cobble"
    },
    {
      "x": -4,
      "y": -20,
      "z": -21,
      "name": "Rock_Sandstone_Cobble"
    },
    {
      "x": -4,
      "y": -19,
      "z": -21,
      "name": "Rock_Sandstone_Cobble"
    },
    {
      "x": -4,
      "y": -18,
      "z": -21,
      "name": "Rock_Sandstone_Cobble"
    },
    {
      "x": -4,
      "y": -17,
      "z": -21,
      "name": "Rock_Sandstone_Brick"
    },
    {
      "x": -4,
      "y": -16,
      "z": -21,
      "name": "Rock_Sandstone_Brick"
    },
    {
      "x": -4,
      "y": -15,
      "z": -21,
      "name": "Rock_Sandstone_White_Cobble"
    },
    {
      "x": -4,
      "y": -14,
      "z": -21,
      "name": "Rock_Sandstone_White_Cobble"
    },
    {
      "x": -4,
      "y": -13,
      "z": -21,
      "name": "Rock_Sandstone_White_Cobble"
    },
    {
      "x": -4,
      "y": -12,
      "z": -21,
      "name": "Rock_Sandstone_White_Cobble"
    },
    {
      "x": -4,
      "y": -11,
      "z": -21,
      "name": "Rock_Sandstone_White_Cobble_Half"
    },
    {
      "x": -4,
      "y": -23,
      "z": -20,
      "name": "Rock_Sandstone_Cobble"
    },
    {
      "x": -4,
      "y": -22,
      "z": -20,
      "name": "Rock_Sandstone_Cobble"
    },
    {
      "x": -4,
      "y": -21,
      "z": -20,
      "name": "Rock_Sandstone_Cobble"
    },
    {
      "x": -4,
      "y": -20,
      "z": -20,
      "name": "Rock_Sandstone_Cobble"
    },
    {
      "x": -4,
      "y": -19,
      "z": -20,
      "name": "Rock_Sandstone_Cobble"
    },
    {
      "x": -4,
      "y": -18,
      "z": -20,
      "name": "Rock_Sandstone_Cobble"
    },
    {
      "x": -4,
      "y": -17,
      "z": -20,
      "name": "Rock_Sandstone_Brick"
    },
    {
      "x": -4,
      "y": -16,
      "z": -20,
      "name": "Rock_Sandstone_Brick"
    },
    {
      "x": -4,
      "y": -15,
      "z": -20,
      "name": "Rock_Sandstone_White_Cobble"
    },
    {
      "x": -4,
      "y": -14,
      "z": -20,
      "name": "Rock_Sandstone_White_Cobble"
    },
    {
      "x": -4,
      "y": -13,
      "z": -20,
      "name": "Rock_Sandstone_Cobble_Stairs",
      "rotation": 1
    },
    {
      "x": -4,
      "y": -23,
      "z": -19,
      "name": "Rock_Sandstone_Cobble"
    },
    {
      "x": -4,
      "y": -22,
      "z": -19,
      "name": "Rock_Sandstone_Cobble"
    },
    {
      "x": -4,
      "y": -21,
      "z": -19,
      "name": "Rock_Sandstone_Cobble"
    },
    {
      "x": -4,
      "y": -20,
      "z": -19,
      "name": "Rock_Sandstone_Cobble"
    },
    {
      "x": -4,
      "y": -19,
      "z": -19,
      "name": "Rock_Sandstone_Cobble"
    },
    {
      "x": -4,
      "y": -18,
      "z": -19,
      "name": "Rock_Sandstone_Cobble"
    },
    {
      "x": -4,
      "y": -17,
      "z": -19,
      "name": "Rock_Sandstone_Brick"
    },
    {
      "x": -4,
      "y": -16,
      "z": -19,
      "name": "Rock_Sandstone_Brick"
    },
    {
      "x": -4,
      "y": -15,
      "z": -19,
      "name": "Rock_Sandstone_White_Cobble"
    },
    {
      "x": -4,
      "y": -14,
      "z": -19,
      "name": "Rock_Sandstone_White_Cobble"
    },
    {
      "x": -4,
      "y": -13,
      "z": -19,
      "name": "Rock_Sandstone_Cobble_Stairs",
      "rotation": 1
    },
    {
      "x": -4,
      "y": -23,
      "z": -18,
      "name": "Rock_Sandstone_Cobble"
    },
    {
      "x": -4,
      "y": -22,
      "z": -18,
      "name": "Rock_Sandstone_Cobble"
    },
    {
      "x": -4,
      "y": -21,
      "z": -18,
      "name": "Rock_Sandstone_Cobble"
    },
    {
      "x": -4,
      "y": -20,
      "z": -18,
      "name": "Rock_Sandstone_Cobble"
    },
    {
      "x": -4,
      "y": -19,
      "z": -18,
      "name": "Rock_Sandstone_Cobble"
    },
    {
      "x": -4,
      "y": -18,
      "z": -18,
      "name": "Rock_Sandstone_Cobble"
    },
    {
      "x": -4,
      "y": -17,
      "z": -18,
      "name": "Rock_Sandstone_Brick"
    },
    {
      "x": -4,
      "y": -16,
      "z": -18,
      "name": "Rock_Sandstone_Brick"
    },
    {
      "x": -4,
      "y": -15,
      "z": -18,
      "name": "Rock_Sandstone_White_Cobble"
    },
    {
      "x": -4,
      "y": -14,
      "z": -18,
      "name": "Rock_Sandstone_White_Cobble"
    },
    {
      "x": -4,
      "y": -13,
      "z": -18,
      "name": "Rock_Sandstone_White_Cobble"
    },
    {
      "x": -4,
      "y": -23,
      "z": -17,
      "name": "Rock_Sandstone_Cobble"
    },
    {
      "x": -4,
      "y": -22,
      "z": -17,
      "name": "Rock_Sandstone_Cobble"
    },
    {
      "x": -4,
      "y": -21,
      "z": -17,
      "name": "Rock_Sandstone_Cobble"
    },
    {
      "x": -4,
      "y": -20,
      "z": -17,
      "name": "Rock_Sandstone_Cobble"
    },
    {
      "x": -4,
      "y": -19,
      "z": -17,
      "name": "Rock_Sandstone_Cobble"
    },
    {
      "x": -4,
      "y": -18,
      "z": -17,
      "name": "Rock_Sandstone_Cobble"
    },
    {
      "x": -4,
      "y": -17,
      "z": -17,
      "name": "Soil_Dirt_Dry"
    },
    {
      "x": -4,
      "y": -16,
      "z": -17,
      "name": "Plant_Bush_Arid"
    },
    {
      "x": -4,
      "y": -15,
      "z": -17,
      "name": "Plant_Bush_Arid"
    },
    {
      "x": -4,
      "y": -14,
      "z": -17,
      "name": "Plant_Vine_Wall_Dry"
    },
    {
      "x": -4,
      "y": -23,
      "z": -16,
      "name": "Rock_Sandstone_Cobble"
    },
    {
      "x": -4,
      "y": -22,
      "z": -16,
      "name": "Rock_Sandstone_Cobble"
    },
    {
      "x": -4,
      "y": -21,
      "z": -16,
      "name": "Rock_Sandstone_Cobble"
    },
    {
      "x": -4,
      "y": -20,
      "z": -16,
      "name": "Rock_Sandstone_Cobble"
    },
    {
      "x": -4,
      "y": -19,
      "z": -16,
      "name": "Rock_Sandstone_Cobble"
    },
    {
      "x": -4,
      "y": -18,
      "z": -16,
      "name": "Rock_Sandstone_Cobble"
    },
    {
      "x": -4,
      "y": -17,
      "z": -16,
      "name": "Soil_Dirt_Dry"
    },
    {
      "x": -4,
      "y": -16,
      "z": -16,
      "name": "Plant_Bush_Arid"
    },
    {
      "x": -4,
      "y": -23,
      "z": -15,
      "name": "Rock_Sandstone_Cobble"
    },
    {
      "x": -4,
      "y": -22,
      "z": -15,
      "name": "Rock_Sandstone_Cobble"
    },
    {
      "x": -4,
      "y": -21,
      "z": -15,
      "name": "Rock_Sandstone_Cobble"
    },
    {
      "x": -4,
      "y": -20,
      "z": -15,
      "name": "Rock_Sandstone_Cobble"
    },
    {
      "x": -4,
      "y": -19,
      "z": -15,
      "name": "Rock_Sandstone_Cobble"
    },
    {
      "x": -4,
      "y": -18,
      "z": -15,
      "name": "Rock_Sandstone_Cobble"
    },
    {
      "x": -4,
      "y": -17,
      "z": -15,
      "name": "Rock_Sandstone_Brick"
    },
    {
      "x": -4,
      "y": -16,
      "z": -15,
      "name": "Rock_Sandstone_Brick"
    },
    {
      "x": -4,
      "y": -15,
      "z": -15,
      "name": "Rock_Sandstone_White_Cobble"
    },
    {
      "x": -3,
      "y": -23,
      "z": -27,
      "name": "Rock_Sandstone_Cobble"
    },
    {
      "x": -3,
      "y": -22,
      "z": -27,
      "name": "Rock_Sandstone_Cobble"
    },
    {
      "x": -3,
      "y": -21,
      "z": -27,
      "name": "Rock_Sandstone_Cobble"
    },
    {
      "x": -3,
      "y": -20,
      "z": -27,
      "name": "Rock_Sandstone_Cobble"
    },
    {
      "x": -3,
      "y": -19,
      "z": -27,
      "name": "Rock_Sandstone_Cobble"
    },
    {
      "x": -3,
      "y": -18,
      "z": -27,
      "name": "Rock_Sandstone_Cobble"
    },
    {
      "x": -3,
      "y": -17,
      "z": -27,
      "name": "Rock_Sandstone_Brick"
    },
    {
      "x": -3,
      "y": -16,
      "z": -27,
      "name": "Rock_Sandstone_Brick"
    },
    {
      "x": -3,
      "y": -15,
      "z": -27,
      "name": "Rock_Sandstone_White_Cobble"
    },
    {
      "x": -3,
      "y": -14,
      "z": -27,
      "name": "Rock_Sandstone_White_Cobble_Half"
    },
    {
      "x": -3,
      "y": -23,
      "z": -26,
      "name": "Rock_Sandstone_Cobble"
    },
    {
      "x": -3,
      "y": -22,
      "z": -26,
      "name": "Rock_Sandstone_Cobble"
    },
    {
      "x": -3,
      "y": -21,
      "z": -26,
      "name": "Rock_Sandstone_Cobble"
    },
    {
      "x": -3,
      "y": -20,
      "z": -26,
      "name": "Rock_Sandstone_Cobble"
    },
    {
      "x": -3,
      "y": -19,
      "z": -26,
      "name": "Rock_Sandstone_Cobble"
    },
    {
      "x": -3,
      "y": -18,
      "z": -26,
      "name": "Rock_Sandstone_Cobble"
    },
    {
      "x": -3,
      "y": -17,
      "z": -26,
      "name": "Rock_Sandstone_Brick"
    },
    {
      "x": -3,
      "y": -16,
      "z": -26,
      "name": "Rock_Sandstone_Brick"
    },
    {
      "x": -3,
      "y": -15,
      "z": -26,
      "name": "Rock_Sandstone_White_Cobble"
    },
    {
      "x": -3,
      "y": -14,
      "z": -26,
      "name": "Rock_Sandstone_White_Cobble_Half"
    },
    {
      "x": -3,
      "y": -23,
      "z": -25,
      "name": "Rock_Sandstone_Cobble"
    },
    {
      "x": -3,
      "y": -22,
      "z": -25,
      "name": "Rock_Sandstone_Cobble"
    },
    {
      "x": -3,
      "y": -21,
      "z": -25,
      "name": "Rock_Sandstone_Cobble"
    },
    {
      "x": -3,
      "y": -20,
      "z": -25,
      "name": "Rock_Sandstone_Cobble"
    },
    {
      "x": -3,
      "y": -19,
      "z": -25,
      "name": "Rock_Sandstone_Cobble"
    },
    {
      "x": -3,
      "y": -18,
      "z": -25,
      "name": "Rock_Sandstone_Cobble"
    },
    {
      "x": -3,
      "y": -17,
      "z": -25,
      "name": "Rock_Sandstone_Brick"
    },
    {
      "x": -3,
      "y": -16,
      "z": -25,
      "name": "Rock_Sandstone_Brick"
    },
    {
      "x": -3,
      "y": -15,
      "z": -25,
      "name": "Rock_Sandstone_White_Cobble_Half"
    },
    {
      "x": -3,
      "y": -13,
      "z": -23,
      "name": "Rock_Sandstone_White_Cobble_Half",
      "rotation": 8
    },
    {
      "x": -3,
      "y": -12,
      "z": -23,
      "name": "Rock_Sandstone_White_Cobble"
    },
    {
      "x": -3,
      "y": -14,
      "z": -22,
      "name": "Rock_Sandstone_White_Cobble_Half",
      "rotation": 6
    },
    {
      "x": -3,
      "y": -13,
      "z": -22,
      "name": "Rock_Sandstone_White_Cobble"
    },
    {
      "x": -3,
      "y": -12,
      "z": -22,
      "name": "Rock_Sandstone_White_Cobble"
    },
    {
      "x": -3,
      "y": -23,
      "z": -21,
      "name": "Rock_Sandstone_Cobble"
    },
    {
      "x": -3,
      "y": -22,
      "z": -21,
      "name": "Rock_Sandstone_Cobble"
    },
    {
      "x": -3,
      "y": -21,
      "z": -21,
      "name": "Rock_Sandstone_Cobble"
    },
    {
      "x": -3,
      "y": -20,
      "z": -21,
      "name": "Rock_Sandstone_Cobble"
    },
    {
      "x": -3,
      "y": -19,
      "z": -21,
      "name": "Rock_Sandstone_Cobble"
    },
    {
      "x": -3,
      "y": -18,
      "z": -21,
      "name": "Rock_Sandstone_Cobble"
    },
    {
      "x": -3,
      "y": -17,
      "z": -21,
      "name": "Rock_Sandstone_Brick"
    },
    {
      "x": -3,
      "y": -16,
      "z": -21,
      "name": "Rock_Sandstone_Brick"
    },
    {
      "x": -3,
      "y": -15,
      "z": -21,
      "name": "Rock_Sandstone_White_Cobble"
    },
    {
      "x": -3,
      "y": -14,
      "z": -21,
      "name": "Rock_Sandstone_White_Cobble"
    },
    {
      "x": -3,
      "y": -13,
      "z": -21,
      "name": "Rock_Sandstone_White_Cobble"
    },
    {
      "x": -3,
      "y": -12,
      "z": -21,
      "name": "Rock_Sandstone_White_Cobble"
    },
    {
      "x": -3,
      "y": -11,
      "z": -21,
      "name": "Rock_Sandstone_White_Cobble_Half"
    },
    {
      "x": -3,
      "y": -23,
      "z": -20,
      "name": "Rock_Sandstone_Cobble"
    },
    {
      "x": -3,
      "y": -22,
      "z": -20,
      "name": "Rock_Sandstone_Cobble"
    },
    {
      "x": -3,
      "y": -21,
      "z": -20,
      "name": "Rock_Sandstone_Cobble"
    },
    {
      "x": -3,
      "y": -20,
      "z": -20,
      "name": "Rock_Sandstone_Cobble"
    },
    {
      "x": -3,
      "y": -19,
      "z": -20,
      "name": "Rock_Sandstone_Cobble"
    },
    {
      "x": -3,
      "y": -18,
      "z": -20,
      "name": "Rock_Sandstone_Cobble"
    },
    {
      "x": -3,
      "y": -17,
      "z": -20,
      "name": "Rock_Sandstone_Brick"
    },
    {
      "x": -3,
      "y": -16,
      "z": -20,
      "name": "Rock_Sandstone_Brick"
    },
    {
      "x": -3,
      "y": -15,
      "z": -20,
      "name": "Rock_Sandstone_White_Cobble"
    },
    {
      "x": -3,
      "y": -14,
      "z": -20,
      "name": "Rock_Sandstone_Cobble"
    },
    {
      "x": -3,
      "y": -23,
      "z": -19,
      "name": "Rock_Sandstone_Cobble"
    },
    {
      "x": -3,
      "y": -22,
      "z": -19,
      "name": "Rock_Sandstone_Cobble"
    },
    {
      "x": -3,
      "y": -21,
      "z": -19,
      "name": "Rock_Sandstone_Cobble"
    },
    {
      "x": -3,
      "y": -20,
      "z": -19,
      "name": "Rock_Sandstone_Cobble"
    },
    {
      "x": -3,
      "y": -19,
      "z": -19,
      "name": "Rock_Sandstone_Cobble"
    },
    {
      "x": -3,
      "y": -18,
      "z": -19,
      "name": "Rock_Sandstone_Cobble"
    },
    {
      "x": -3,
      "y": -17,
