{
  "version": 8,
  "blockIdVersion": 11,
  "anchorX": 0,
  "anchorY": 0,
  "anchorZ": 0,
  "blocks": [
    {
      "x": -9,
      "y": 11,
      "z": 5,
      "name": "Rock_Sandstone_Brick_Half",
      "rotation": 7
    },
    {
      "x": -9,
      "y": 11,
      "z": 6,
      "name": "Rock_Sandstone_Brick_Half",
      "rotation": 7
    },
    {
      "x": -9,
      "y": 15,
      "z": 6,
      "name": "Rock_Sandstone_Cobble_Beam",
      "rotation": 5
    },
    {
      "x": -9,
      "y": 11,
      "z": 7,
      "name": "Rock_Sandstone_Brick_Half",
      "rotation": 7
    },
    {
      "x": -9,
      "y": 15,
      "z": 10,
      "name": "Rock_Sandstone_Cobble_Beam",
      "rotation": 5
    },
    {
      "x": -8,
      "y": 9,
      "z": -6,
      "name": "Rock_Sandstone_Cobble_Stairs",
      "rotation": 8
    },
    {
      "x": -8,
      "y": 10,
      "z": -6,
      "name": "Rock_Sandstone_Brick"
    },
    {
      "x": -8,
      "y": 11,
      "z": -6,
      "name": "Soil_Clay_Ocean_Brick_Roof",
      "rotation": 3
    },
    {
      "x": -8,
      "y": 0,
      "z": -5,
      "name": "Soil_Dirt_Dry"
    },
    {
      "x": -8,
      "y": 1,
      "z": -5,
      "name": "Soil_Dirt_Dry"
    },
    {
      "x": -8,
      "y": 2,
      "z": -5,
      "name": "Soil_Dirt_Dry"
    },
    {
      "x": -8,
      "y": 3,
      "z": -5,
      "name": "Soil_Dirt_Dry"
    },
    {
      "x": -8,
      "y": 4,
      "z": -5,
      "name": "Soil_Dirt_Dry"
    },
    {
      "x": -8,
      "y": 5,
      "z": -5,
      "name": "Soil_Dirt_Dry"
    },
    {
      "x": -8,
      "y": 6,
      "z": -5,
      "name": "Rock_Sandstone_Cobble"
    },
    {
      "x": -8,
      "y": 7,
      "z": -5,
      "name": "Rock_Sandstone_Cobble"
    },
    {
      "x": -8,
      "y": 8,
      "z": -5,
      "name": "Rock_Sandstone_Cobble"
    },
    {
      "x": -8,
      "y": 9,
      "z": -5,
      "name": "Rock_Sandstone_Cobble"
    },
    {
      "x": -8,
      "y": 10,
      "z": -5,
      "name": "Rock_Sandstone_Brick"
    },
    {
      "x": -8,
      "y": 11,
      "z": -5,
      "name": "Soil_Clay_Ocean_Brick_Roof",
      "rotation": 3
    },
    {
      "x": -8,
      "y": 0,
      "z": -4,
      "name": "Soil_Dirt_Dry"
    },
    {
      "x": -8,
      "y": 1,
      "z": -4,
      "name": "Soil_Dirt_Dry"
    },
    {
      "x": -8,
      "y": 2,
      "z": -4,
      "name": "Soil_Dirt_Dry"
    },
    {
      "x": -8,
      "y": 3,
      "z": -4,
      "name": "Soil_Dirt_Dry"
    },
    {
      "x": -8,
      "y": 4,
      "z": -4,
      "name": "Soil_Dirt_Dry"
    },
    {
      "x": -8,
      "y": 5,
      "z": -4,
      "name": "Soil_Dirt_Dry"
    },
    {
      "x": -8,
      "y": 6,
      "z": -4,
      "name": "Rock_Sandstone_Cobble"
    },
    {
      "x": -8,
      "y": 7,
      "z": -4,
      "name": "Rock_Sandstone_Brick"
    },
    {
      "x": -8,
      "y": 8,
      "z": -4,
      "name": "Rock_Sandstone_Brick"
    },
    {
      "x": -8,
      "y": 9,
      "z": -4,
      "name": "Rock_Sandstone_Brick"
    },
    {
      "x": -8,
      "y": 10,
      "z": -4,
      "name": "Rock_Sandstone_Brick"
    },
    {
      "x": -8,
      "y": 11,
      "z": -4,
      "name": "Rock_Sandstone_Brick_Stairs",
      "rotation": 3
    },
    {
      "x": -8,
      "y": 8,
      "z": -3,
      "name": "Rock_Sandstone_Brick_Half",
      "rotation": 4
    },
    {
      "x": -8,
      "y": 9,
      "z": -3,
      "name": "Rock_Sandstone_Brick"
    },
    {
      "x": -8,
      "y": 10,
      "z": -3,
      "name": "Rock_Sandstone_Brick"
    },
    {
      "x": -8,
      "y": 11,
      "z": -3,
      "name": "Soil_Clay_Ocean_Brick_Roof",
      "rotation": 3
    },
    {
      "x": -8,
      "y": 9,
      "z": -2,
      "name": "Rock_Sandstone_Brick_Half",
      "rotation": 8
    },
    {
      "x": -8,
      "y": 10,
      "z": -2,
      "name": "Rock_Sandstone_Brick"
    },
    {
      "x": -8,
      "y": 11,
      "z": -2,
      "name": "Soil_Clay_Ocean_Brick_Roof",
      "rotation": 3
    },
    {
      "x": -8,
      "y": 8,
      "z": -1,
      "name": "Rock_Sandstone_Brick_Half",
      "rotation": 6
    },
    {
      "x": -8,
      "y": 9,
      "z": -1,
      "name": "Rock_Sandstone_Brick"
    },
    {
      "x": -8,
      "y": 10,
      "z": -1,
      "name": "Rock_Sandstone_Brick"
    },
    {
      "x": -8,
      "y": 11,
      "z": -1,
      "name": "Soil_Clay_Ocean_Brick_Roof",
      "rotation": 3
    },
    {
      "x": -8,
      "y": 0,
      "z": 0,
      "name": "Soil_Dirt_Dry"
    },
    {
      "x": -8,
      "y": 1,
      "z": 0,
      "name": "Soil_Dirt_Dry"
    },
    {
      "x": -8,
      "y": 2,
      "z": 0,
      "name": "Soil_Dirt_Dry"
    },
    {
      "x": -8,
      "y": 3,
      "z": 0,
      "name": "Soil_Dirt_Dry"
    },
    {
      "x": -8,
      "y": 4,
      "z": 0,
      "name": "Soil_Dirt_Dry"
    },
    {
      "x": -8,
      "y": 5,
      "z": 0,
      "name": "Soil_Dirt_Dry"
    },
    {
      "x": -8,
      "y": 6,
      "z": 0,
      "name": "Rock_Sandstone_Brick"
    },
    {
      "x": -8,
      "y": 7,
      "z": 0,
      "name": "Rock_Sandstone_Brick"
    },
    {
      "x": -8,
      "y": 8,
      "z": 0,
      "name": "Rock_Sandstone_Brick"
    },
    {
      "x": -8,
      "y": 9,
      "z": 0,
      "name": "Rock_Sandstone_Cobble"
    },
    {
      "x": -8,
      "y": 10,
      "z": 0,
      "name": "Rock_Sandstone_Brick"
    },
    {
      "x": -8,
      "y": 11,
      "z": 0,
      "name": "Soil_Clay_Ocean_Brick_Roof",
      "rotation": 3
    },
    {
      "x": -8,
      "y": 0,
      "z": 1,
      "name": "Soil_Dirt_Dry"
    },
    {
      "x": -8,
      "y": 1,
      "z": 1,
      "name": "Soil_Dirt_Dry"
    },
    {
      "x": -8,
      "y": 2,
      "z": 1,
      "name": "Soil_Dirt_Dry"
    },
    {
      "x": -8,
      "y": 3,
      "z": 1,
      "name": "Soil_Dirt_Dry"
    },
    {
      "x": -8,
      "y": 4,
      "z": 1,
      "name": "Soil_Dirt_Dry"
    },
    {
      "x": -8,
      "y": 5,
      "z": 1,
      "name": "Soil_Dirt_Dry"
    },
    {
      "x": -8,
      "y": 6,
      "z": 1,
      "name": "Rock_Sandstone_Brick"
    },
    {
      "x": -8,
      "y": 7,
      "z": 1,
      "name": "Rock_Sandstone_Cobble"
    },
    {
      "x": -8,
      "y": 8,
      "z": 1,
      "name": "Rock_Sandstone_Cobble"
    },
    {
      "x": -8,
      "y": 9,
      "z": 1,
      "name": "Rock_Sandstone_Cobble"
    },
    {
      "x": -8,
      "y": 10,
      "z": 1,
      "name": "Rock_Sandstone_Cobble"
    },
    {
      "x": -8,
      "y": 11,
      "z": 1,
      "name": "Soil_Clay_Ocean_Brick_Roof",
      "rotation": 3
    },
    {
      "x": -8,
      "y": 9,
      "z": 2,
      "name": "Rock_Sandstone_Cobble_Stairs",
      "rotation": 10
    },
    {
      "x": -8,
      "y": 10,
      "z": 2,
      "name": "Rock_Sandstone_Cobble"
    },
    {
      "x": -8,
      "y": 11,
      "z": 2,
      "name": "Rock_Sandstone_Cobble_Stairs",
      "rotation": 3
    },
    {
      "x": -8,
      "y": 11,
      "z": 4,
      "name": "Rock_Sandstone_Brick_Half",
      "rotation": 6
    },
    {
      "x": -8,
      "y": 0,
      "z": 5,
      "name": "Rock_Sandstone_Cobble"
    },
    {
      "x": -8,
      "y": 1,
      "z": 5,
      "name": "Rock_Sandstone_Cobble"
    },
    {
      "x": -8,
      "y": 2,
      "z": 5,
      "name": "Rock_Sandstone_Cobble"
    },
    {
      "x": -8,
      "y": 3,
      "z": 5,
      "name": "Rock_Sandstone_Cobble"
    },
    {
      "x": -8,
      "y": 4,
      "z": 5,
      "name": "Rock_Sandstone_Cobble"
    },
    {
      "x": -8,
      "y": 5,
      "z": 5,
      "name": "Rock_Sandstone_Cobble"
    },
    {
      "x": -8,
      "y": 6,
      "z": 5,
      "name": "Rock_Sandstone_Brick"
    },
    {
      "x": -8,
      "y": 7,
      "z": 5,
      "name": "Rock_Sandstone_Cobble"
    },
    {
      "x": -8,
      "y": 8,
      "z": 5,
      "name": "Rock_Sandstone_Cobble"
    },
    {
      "x": -8,
      "y": 9,
      "z": 5,
      "name": "Rock_Sandstone_Cobble"
    },
    {
      "x": -8,
      "y": 10,
      "z": 5,
      "name": "Rock_Sandstone_Cobble"
    },
    {
      "x": -8,
      "y": 11,
      "z": 5,
      "name": "Rock_Sandstone_White_Cobble"
    },
    {
      "x": -8,
      "y": 12,
      "z": 5,
      "name": "Rock_Sandstone_White_Cobble"
    },
    {
      "x": -8,
      "y": 13,
      "z": 5,
      "name": "Rock_Sandstone_White_Cobble"
    },
    {
      "x": -8,
      "y": 14,
      "z": 5,
      "name": "Rock_Sandstone_White_Cobble"
    },
    {
      "x": -8,
      "y": 15,
      "z": 5,
      "name": "Rock_Sandstone_Brick_Decorative"
    },
    {
      "x": -8,
      "y": 16,
      "z": 5,
      "name": "Rock_Sandstone_Brick_Smooth_Half"
    },
    {
      "x": -8,
      "y": 0,
      "z": 6,
      "name": "Rock_Sandstone_Cobble"
    },
    {
      "x": -8,
      "y": 1,
      "z": 6,
      "name": "Rock_Sandstone_Cobble"
    },
    {
      "x": -8,
      "y": 2,
      "z": 6,
      "name": "Rock_Sandstone_Cobble"
    },
    {
      "x": -8,
      "y": 3,
      "z": 6,
      "name": "Rock_Sandstone_Cobble"
    },
    {
      "x": -8,
      "y": 4,
      "z": 6,
      "name": "Rock_Sandstone_Cobble"
    },
    {
      "x": -8,
      "y": 5,
      "z": 6,
      "name": "Rock_Sandstone_Cobble"
    },
    {
      "x": -8,
      "y": 6,
      "z": 6,
      "name": "Rock_Sandstone_Brick"
    },
    {
      "x": -8,
      "y": 7,
      "z": 6,
      "name": "Rock_Sandstone_Brick"
    },
    {
      "x": -8,
      "y": 8,
      "z": 6,
      "name": "Rock_Sandstone_Cobble"
    },
    {
      "x": -8,
      "y": 9,
      "z": 6,
      "name": "Rock_Sandstone_Cobble"
    },
    {
      "x": -8,
      "y": 10,
      "z": 6,
      "name": "Rock_Sandstone_Cobble"
    },
    {
      "x": -8,
      "y": 11,
      "z": 6,
      "name": "Rock_Sandstone_White_Cobble"
    },
    {
      "x": -8,
      "y": 12,
      "z": 6,
      "name": "Rock_Sandstone_White_Cobble"
    },
    {
      "x": -8,
      "y": 13,
      "z": 6,
      "name": "Rock_Sandstone_White_Cobble"
    },
    {
      "x": -8,
      "y": 14,
      "z": 6,
      "name": "Rock_Sandstone_White_Cobble"
    },
    {
      "x": -8,
      "y": 15,
      "z": 6,
      "name": "Rock_Sandstone_Brick_Decorative"
    },
    {
      "x": -8,
      "y": 16,
      "z": 6,
      "name": "Rock_Sandstone_Brick_Smooth_Half"
    },
    {
      "x": -8,
      "y": 0,
      "z": 7,
      "name": "Rock_Sandstone_Cobble"
    },
    {
      "x": -8,
      "y": 1,
      "z": 7,
      "name": "Rock_Sandstone_Cobble"
    },
    {
      "x": -8,
      "y": 2,
      "z": 7,
      "name": "Rock_Sandstone_Cobble"
    },
    {
      "x": -8,
      "y": 3,
      "z": 7,
      "name": "Rock_Sandstone_Cobble"
    },
    {
      "x": -8,
      "y": 4,
      "z": 7,
      "name": "Rock_Sandstone_Cobble"
    },
    {
      "x": -8,
      "y": 5,
      "z": 7,
      "name": "Rock_Sandstone_Cobble"
    },
    {
      "x": -8,
      "y": 6,
      "z": 7,
      "name": "Rock_Sandstone_Brick"
    },
    {
      "x": -8,
      "y": 7,
      "z": 7,
      "name": "Rock_Sandstone_Brick"
    },
    {
      "x": -8,
      "y": 8,
      "z": 7,
      "name": "Rock_Sandstone_Brick"
    },
    {
      "x": -8,
      "y": 9,
      "z": 7,
      "name": "Rock_Sandstone_Brick"
    },
    {
      "x": -8,
      "y": 10,
      "z": 7,
      "name": "Rock_Sandstone_Cobble"
    },
    {
      "x": -8,
      "y": 11,
      "z": 7,
      "name": "Rock_Sandstone_White_Cobble"
    },
    {
      "x": -8,
      "y": 12,
      "z": 7,
      "name": "Rock_Sandstone_White_Cobble"
    },
    {
      "x": -8,
      "y": 13,
      "z": 7,
      "name": "Wood_Drywood_Fence",
      "rotation": 3
    },
    {
      "x": -8,
      "y": 14,
      "z": 7,
      "name": "Rock_Sandstone_White_Cobble"
    },
    {
      "x": -8,
      "y": 15,
      "z": 7,
      "name": "Rock_Sandstone_Brick_Decorative"
    },
    {
      "x": -8,
      "y": 16,
      "z": 7,
      "name": "Rock_Sandstone_Brick_Smooth_Half"
    },
    {
      "x": -8,
      "y": 0,
      "z": 8,
      "name": "Rock_Sandstone_Cobble"
    },
    {
      "x": -8,
      "y": 1,
      "z": 8,
      "name": "Rock_Sandstone_Cobble"
    },
    {
      "x": -8,
      "y": 2,
      "z": 8,
      "name": "Rock_Sandstone_Cobble"
    },
    {
      "x": -8,
      "y": 3,
      "z": 8,
      "name": "Rock_Sandstone_Cobble"
    },
    {
      "x": -8,
      "y": 4,
      "z": 8,
      "name": "Rock_Sandstone_Cobble"
    },
    {
      "x": -8,
      "y": 5,
      "z": 8,
      "name": "Rock_Sandstone_Cobble"
    },
    {
      "x": -8,
      "y": 6,
      "z": 8,
      "name": "Rock_Sandstone_Brick"
    },
    {
      "x": -8,
      "y": 7,
      "z": 8,
      "name": "Rock_Sandstone_Brick"
    },
    {
      "x": -8,
      "y": 8,
      "z": 8,
      "name": "Rock_Sandstone_Brick"
    },
    {
      "x": -8,
      "y": 9,
      "z": 8,
      "name": "Rock_Sandstone_Brick"
    },
    {
      "x": -8,
      "y": 10,
      "z": 8,
      "name": "Rock_Sandstone_Cobble"
    },
    {
      "x": -8,
      "y": 11,
      "z": 8,
      "name": "Rock_Sandstone_White_Cobble"
    },
    {
      "x": -8,
      "y": 12,
      "z": 8,
      "name": "Rock_Sandstone_White_Cobble"
    },
    {
      "x": -8,
      "y": 13,
      "z": 8,
      "name": "Rock_Sandstone_White_Cobble"
    },
    {
      "x": -8,
      "y": 14,
      "z": 8,
      "name": "Rock_Sandstone_White_Cobble"
    },
    {
      "x": -8,
      "y": 15,
      "z": 8,
      "name": "Rock_Sandstone_Brick_Decorative"
    },
    {
      "x": -8,
      "y": 16,
      "z": 8,
      "name": "Rock_Sandstone_Brick_Smooth_Half"
    },
    {
      "x": -8,
      "y": 0,
      "z": 9,
      "name": "Rock_Sandstone_Cobble"
    },
    {
      "x": -8,
      "y": 1,
      "z": 9,
      "name": "Rock_Sandstone_Cobble"
    },
    {
      "x": -8,
      "y": 2,
      "z": 9,
      "name": "Rock_Sandstone_Cobble"
    },
    {
      "x": -8,
      "y": 3,
      "z": 9,
      "name": "Rock_Sandstone_Cobble"
    },
    {
      "x": -8,
      "y": 4,
      "z": 9,
      "name": "Rock_Sandstone_Cobble"
    },
    {
      "x": -8,
      "y": 5,
      "z": 9,
      "name": "Rock_Sandstone_Cobble"
    },
    {
      "x": -8,
      "y": 6,
      "z": 9,
      "name": "Rock_Sandstone_Brick"
    },
    {
      "x": -8,
      "y": 7,
      "z": 9,
      "name": "Rock_Sandstone_Brick_Half",
      "rotation": 4
    },
    {
      "x": -8,
      "y": 8,
      "z": 9,
      "name": "Rock_Sandstone_Brick_Half",
      "rotation": 4
    },
    {
      "x": -8,
      "y": 9,
      "z": 9,
      "name": "Rock_Sandstone_Cobble"
    },
    {
      "x": -8,
      "y": 10,
      "z": 9,
      "name": "Rock_Sandstone_Cobble"
    },
    {
      "x": -8,
      "y": 11,
      "z": 9,
      "name": "Rock_Sandstone_White_Cobble"
    },
    {
      "x": -8,
      "y": 12,
      "z": 9,
      "name": "Rock_Sandstone_White_Cobble"
    },
    {
      "x": -8,
      "y": 13,
      "z": 9,
      "name": "Wood_Drywood_Fence",
      "rotation": 3
    },
    {
      "x": -8,
      "y": 14,
      "z": 9,
      "name": "Rock_Sandstone_White_Cobble"
    },
    {
      "x": -8,
      "y": 15,
      "z": 9,
      "name": "Rock_Sandstone_Brick_Decorative"
    },
    {
      "x": -8,
      "y": 16,
      "z": 9,
      "name": "Rock_Sandstone_Brick_Smooth_Half"
    },
    {
      "x": -8,
      "y": 11,
      "z": 10,
      "name": "Rock_Sandstone_White_Cobble_Half",
      "rotation": 8
    },
    {
      "x": -8,
      "y": 12,
      "z": 10,
      "name": "Rock_Sandstone_White_Cobble"
    },
    {
      "x": -8,
      "y": 13,
      "z": 10,
      "name": "Rock_Sandstone_White_Cobble"
    },
    {
      "x": -8,
      "y": 14,
      "z": 10,
      "name": "Rock_Sandstone_White_Cobble"
    },
    {
      "x": -8,
      "y": 15,
      "z": 10,
      "name": "Rock_Sandstone_Brick_Decorative"
    },
    {
      "x": -8,
      "y": 16,
      "z": 10,
      "name": "Rock_Sandstone_Brick_Smooth_Half"
    },
    {
      "x": -7,
      "y": 0,
      "z": -11,
      "name": "Rock_Sandstone_Brick"
    },
    {
      "x": -7,
      "y": 1,
      "z": -11,
      "name": "Rock_Sandstone_Brick"
    },
    {
      "x": -7,
      "y": 2,
      "z": -11,
      "name": "Rock_Sandstone_Brick"
    },
    {
      "x": -7,
      "y": 3,
      "z": -11,
      "name": "Rock_Sandstone_Brick"
    },
    {
      "x": -7,
      "y": 4,
      "z": -11,
      "name": "Rock_Sandstone_Brick"
    },
    {
      "x": -7,
      "y": 5,
      "z": -11,
      "name": "Rock_Sandstone_Brick"
    },
    {
      "x": -7,
      "y": 6,
      "z": -11,
      "name": "Rock_Sandstone_Brick"
    },
    {
      "x": -7,
      "y": 7,
      "z": -11,
      "name": "Rock_Sandstone_Brick"
    },
    {
      "x": -7,
      "y": 8,
      "z": -11,
      "name": "Rock_Sandstone_Brick_Half"
    },
    {
      "x": -7,
      "y": 0,
      "z": -10,
      "name": "Rock_Sandstone_Brick"
    },
    {
      "x": -7,
      "y": 1,
      "z": -10,
      "name": "Rock_Sandstone_Brick"
    },
    {
      "x": -7,
      "y": 2,
      "z": -10,
      "name": "Rock_Sandstone_Brick"
    },
    {
      "x": -7,
      "y": 3,
      "z": -10,
      "name": "Rock_Sandstone_Brick"
    },
    {
      "x": -7,
      "y": 4,
      "z": -10,
      "name": "Rock_Sandstone_Brick"
    },
    {
      "x": -7,
      "y": 5,
      "z": -10,
      "name": "Rock_Sandstone_Brick"
    },
    {
      "x": -7,
      "y": 6,
      "z": -10,
      "name": "Rock_Sandstone_Brick"
    },
    {
      "x": -7,
      "y": 7,
      "z": -10,
      "name": "Rock_Sandstone_Brick"
    },
    {
      "x": -7,
      "y": 8,
      "z": -10,
      "name": "Rock_Sandstone_Brick_Half"
    },
    {
      "x": -7,
      "y": 0,
      "z": -9,
      "name": "Rock_Sandstone_Brick"
    },
    {
      "x": -7,
      "y": 1,
      "z": -9,
      "name": "Rock_Sandstone_Brick"
    },
    {
      "x": -7,
      "y": 2,
      "z": -9,
      "name": "Rock_Sandstone_Brick"
    },
    {
      "x": -7,
      "y": 3,
      "z": -9,
      "name": "Rock_Sandstone_Brick"
    },
    {
      "x": -7,
      "y": 4,
      "z": -9,
      "name": "Rock_Sandstone_Brick"
    },
    {
      "x": -7,
      "y": 5,
      "z": -9,
      "name": "Rock_Sandstone_Brick"
    },
    {
      "x": -7,
      "y": 6,
      "z": -9,
      "name": "Rock_Sandstone_Brick"
    },
    {
      "x": -7,
      "y": 9,
      "z": -6,
      "name": "Rock_Sandstone_Cobble_Stairs",
      "rotation": 8
    },
    {
      "x": -7,
      "y": 10,
      "z": -6,
      "name": "Rock_Sandstone_Brick"
    },
    {
      "x": -7,
      "y": 11,
      "z": -6,
      "name": "Soil_Clay_Ocean_Brick_Roof",
      "rotation": 1
    },
    {
      "x": -7,
      "y": 0,
      "z": -5,
      "name": "Soil_Dirt_Dry"
    },
    {
      "x": -7,
      "y": 1,
      "z": -5,
      "name": "Soil_Dirt_Dry"
    },
    {
      "x": -7,
      "y": 2,
      "z": -5,
      "name": "Soil_Dirt_Dry"
    },
    {
      "x": -7,
      "y": 3,
      "z": -5,
      "name": "Soil_Dirt_Dry"
    },
    {
      "x": -7,
      "y": 4,
      "z": -5,
      "name": "Soil_Dirt_Dry"
    },
    {
      "x": -7,
      "y": 5,
      "z": -5,
      "name": "Soil_Dirt_Dry"
    },
    {
      "x": -7,
      "y": 6,
      "z": -5,
      "name": "Rock_Sandstone_Cobble"
    },
    {
      "x": -7,
      "y": 7,
      "z": -5,
      "name": "Rock_Sandstone_Cobble"
    },
    {
      "x": -7,
      "y": 8,
      "z": -5,
      "name": "Rock_Sandstone_Brick"
    },
    {
      "x": -7,
      "y": 9,
      "z": -5,
      "name": "Rock_Sandstone_Brick"
    },
    {
      "x": -7,
      "y": 10,
      "z": -5,
      "name": "Rock_Sandstone_Brick"
    },
    {
      "x": -7,
      "y": 11,
      "z": -5,
      "name": "Wood_Dry_Trunk",
      "rotation": 5
    },
    {
      "x": -7,
      "y": 0,
      "z": -4,
      "name": "Soil_Dirt_Dry"
    },
    {
      "x": -7,
      "y": 1,
      "z": -4,
      "name": "Soil_Dirt_Dry"
    },
    {
      "x": -7,
      "y": 2,
      "z": -4,
      "name": "Soil_Dirt_Dry"
    },
    {
      "x": -7,
      "y": 3,
      "z": -4,
      "name": "Soil_Dirt_Dry"
    },
    {
      "x": -7,
      "y": 4,
      "z": -4,
      "name": "Soil_Dirt_Dry"
    },
    {
      "x": -7,
      "y": 5,
      "z": -4,
      "name": "Soil_Dirt_Dry"
    },
    {
      "x": -7,
      "y": 6,
      "z": -4,
      "name": "Rock_Sandstone_Cobble"
    },
    {
      "x": -7,
      "y": 7,
      "z": -4,
      "name": "Rock_Sandstone_Brick"
    },
    {
      "x": -7,
      "y": 8,
      "z": -4,
      "name": "Rock_Sandstone_Brick"
    },
    {
      "x": -7,
      "y": 9,
      "z": -4,
      "name": "Rock_Sandstone_Brick"
    },
    {
      "x": -7,
      "y": 10,
      "z": -4,
      "name": "Rock_Sandstone_Brick"
    },
    {
      "x": -7,
      "y": 11,
      "z": -4,
      "name": "Soil_Clay_Ocean_Brick_Roof",
      "rotation": 1
    },
    {
      "x": -7,
      "y": 0,
      "z": -3,
      "name": "Soil_Dirt_Dry"
    },
    {
      "x": -7,
      "y": 1,
      "z": -3,
      "name": "Soil_Dirt_Dry"
    },
    {
      "x": -7,
      "y": 2,
      "z": -3,
      "name": "Soil_Dirt_Dry"
    },
    {
      "x": -7,
      "y": 3,
      "z": -3,
      "name": "Soil_Dirt_Dry"
    },
    {
      "x": -7,
      "y": 4,
      "z": -3,
      "name": "Soil_Dirt_Dry"
    },
    {
      "x": -7,
      "y": 5,
      "z": -3,
      "name": "Soil_Dirt_Dry"
    },
    {
      "x": -7,
      "y": 8,
      "z": -3,
      "name": "Rock_Sandstone_Brick_Half",
      "rotation": 4
    },
    {
      "x": -7,
      "y": 9,
      "z": -3,
      "name": "Rock_Sandstone_Brick"
    },
    {
      "x": -7,
      "y": 10,
      "z": -3,
      "name": "Rock_Sandstone_Brick"
    },
    {
      "x": -7,
      "y": 11,
      "z": -3,
      "name": "Soil_Clay_Ocean_Brick_Roof",
      "rotation": 1
    },
    {
      "x": -7,
      "y": 0,
      "z": -2,
      "name": "Soil_Dirt_Dry"
    },
    {
      "x": -7,
      "y": 1,
      "z": -2,
      "name": "Soil_Dirt_Dry"
    },
    {
      "x": -7,
      "y": 2,
      "z": -2,
      "name": "Soil_Dirt_Dry"
    },
    {
      "x": -7,
      "y": 3,
      "z": -2,
      "name": "Soil_Dirt_Dry"
    },
    {
      "x": -7,
      "y": 4,
      "z": -2,
      "name": "Soil_Dirt_Dry"
    },
    {
      "x": -7,
      "y": 5,
      "z": -2,
      "name": "Soil_Dirt_Dry"
    },
    {
      "x": -7,
      "y": 9,
      "z": -2,
      "name": "Rock_Sandstone_Brick_Half",
      "rotation": 8
    },
    {
      "x": -7,
      "y": 10,
      "z": -2,
      "name": "Rock_Sandstone_Brick"
    },
    {
      "x": -7,
      "y": 11,
      "z": -2,
      "name": "Wood_Dry_Trunk",
      "rotation": 5
    },
    {
      "x": -7,
      "y": 0,
      "z": -1,
      "name": "Soil_Dirt_Dry"
    },
    {
      "x": -7,
      "y": 1,
      "z": -1,
      "name": "Soil_Dirt_Dry"
    },
    {
      "x": -7,
      "y": 2,
      "z": -1,
      "name": "Soil_Dirt_Dry"
    },
    {
      "x": -7,
      "y": 3,
      "z": -1,
      "name": "Soil_Dirt_Dry"
    },
    {
      "x": -7,
      "y": 4,
      "z": -1,
      "name": "Soil_Dirt_Dry"
    },
    {
      "x": -7,
      "y": 5,
      "z": -1,
      "name": "Soil_Dirt_Dry"
    },
    {
      "x": -7,
      "y": 6,
      "z": -1,
      "name": "Plant_Vine_Wall_Dry",
      "rotation": 2
    },
    {
      "x": -7,
      "y": 7,
      "z": -1,
      "name": "Plant_Vine_Wall_Dry",
      "rotation": 2
    },
    {
      "x": -7,
      "y": 8,
      "z": -1,
      "name": "Rock_Sandstone_Brick_Half",
      "rotation": 6
    },
    {
      "x": -7,
      "y": 9,
      "z": -1,
      "name": "Rock_Sandstone_Brick"
    },
    {
      "x": -7,
      "y": 10,
      "z": -1,
      "name": "Rock_Sandstone_Brick"
    },
    {
      "x": -7,
      "y": 11,
      "z": -1,
      "name": "Soil_Clay_Ocean_Brick_Roof",
      "rotation": 1
    },
    {
      "x": -7,
      "y": 0,
      "z": 0,
      "name": "Soil_Dirt_Dry"
    },
    {
      "x": -7,
      "y": 1,
      "z": 0,
      "name": "Soil_Dirt_Dry"
    },
    {
      "x": -7,
      "y": 2,
      "z": 0,
      "name": "Soil_Dirt_Dry"
    },
    {
      "x": -7,
      "y": 3,
      "z": 0,
      "name": "Soil_Dirt_Dry"
    },
    {
      "x": -7,
      "y": 4,
      "z": 0,
      "name": "Soil_Dirt_Dry"
    },
    {
      "x": -7,
      "y": 5,
      "z": 0,
      "name": "Soil_Dirt_Dry"
    },
    {
      "x": -7,
      "y": 6,
      "z": 0,
      "name": "Rock_Sandstone_Cobble"
    },
    {
      "x": -7,
      "y": 7,
      "z": 0,
      "name": "Rock_Sandstone_Cobble"
    },
    {
      "x": -7,
      "y": 8,
      "z": 0,
      "name": "Rock_Sandstone_Brick"
    },
    {
      "x": -7,
      "y": 9,
      "z": 0,
      "name": "Rock_Sandstone_Brick"
    },
    {
      "x": -7,
      "y": 10,
      "z": 0,
      "name": "Rock_Sandstone_Brick"
    },
    {
      "x": -7,
      "y": 11,
      "z": 0,
      "name": "Soil_Clay_Ocean_Brick_Roof",
      "rotation": 1
    },
    {
      "x": -7,
      "y": 0,
      "z": 1,
      "name": "Soil_Dirt_Dry"
    },
    {
      "x": -7,
      "y": 1,
      "z": 1,
      "name": "Soil_Dirt_Dry"
    },
    {
      "x": -7,
      "y": 2,
      "z": 1,
      "name": "Soil_Dirt_Dry"
    },
    {
      "x": -7,
      "y": 3,
      "z": 1,
      "name": "Soil_Dirt_Dry"
    },
    {
      "x": -7,
      "y": 4,
      "z": 1,
      "name": "Soil_Dirt_Dry"
    },
    {
      "x": -7,
      "y": 5,
      "z": 1,
      "name": "Soil_Dirt_Dry"
    },
    {
      "x": -7,
      "y": 6,
      "z": 1,
      "name": "Rock_Sandstone_Cobble"
    },
    {
      "x": -7,
      "y": 7,
      "z": 1,
      "name": "Rock_Sandstone_Cobble"
    },
    {
      "x": -7,
      "y": 8,
      "z": 1,
      "name": "Rock_Sandstone_Cobble"
    },
    {
      "x": -7,
      "y": 9,
      "z": 1,
      "name": "Rock_Sandstone_Cobble"
    },
    {
      "x": -7,
      "y": 10,
      "z": 1,
      "name": "Rock_Sandstone_Brick"
    },
    {
      "x": -7,
      "y": 11,
      "z": 1,
      "name": "Soil_Clay_Ocean_Brick_Roof",
      "rotation": 1
    },
    {
      "x": -7,
      "y": 0,
      "z": 2,
      "name": "Rock_Sandstone_Cobble"
    },
    {
      "x": -7,
      "y": 1,
      "z": 2,
      "name": "Rock_Sandstone_Cobble"
    },
    {
      "x": -7,
      "y": 2,
      "z": 2,
      "name": "Rock_Sandstone_Cobble"
    },
    {
      "x": -7,
      "y": 3,
      "z": 2,
      "name": "Rock_Sandstone_Cobble"
    },
    {
      "x": -7,
      "y": 4,
      "z": 2,
      "name": "Rock_Sandstone_Cobble"
    },
    {
      "x": -7,
      "y": 5,
      "z": 2,
      "name": "Soil_Mud_Dry"
    },
    {
      "x": -7,
      "y": 6,
      "z": 2,
      "name": "Wood_Drywood_Beam"
    },
    {
      "x": -7,
      "y": 9,
      "z": 2,
      "name": "Rock_Sandstone_Cobble_Stairs",
      "rotation": 10
    },
    {
      "x": -7,
      "y": 10,
      "z": 2,
      "name": "Rock_Sandstone_Brick"
    },
    {
      "x": -7,
      "y": 11,
      "z": 2,
      "name": "Rock_Sandstone_Brick_Stairs",
      "rotation": 1
    },
    {
      "x": -7,
      "y": 0,
      "z": 3,
      "name": "Rock_Sandstone_Cobble"
    },
    {
      "x": -7,
      "y": 1,
      "z": 3,
      "name": "Rock_Sandstone_Cobble"
    },
    {
      "x": -7,
      "y": 2,
      "z": 3,
      "name": "Rock_Sandstone_Cobble"
    },
    {
      "x": -7,
      "y": 3,
      "z": 3,
      "name": "Rock_Sandstone_Cobble"
    },
    {
      "x": -7,
      "y": 4,
      "z": 3,
      "name": "Rock_Sandstone_Cobble"
    },
    {
      "x": -7,
      "y": 5,
      "z": 3,
      "name": "Soil_Mud_Dry"
    },
    {
      "x": -7,
      "y": 6,
      "z": 3,
      "name": "Wood_Drywood_Fence",
      "rotation": 3
    },
    {
      "x": -7,
      "y": 0,
      "z": 4,
      "name": "Rock_Sandstone_Cobble"
    },
    {
      "x": -7,
      "y": 1,
      "z": 4,
      "name": "Rock_Sandstone_Cobble"
    },
    {
      "x": -7,
      "y": 2,
      "z": 4,
      "name": "Rock_Sandstone_Cobble"
    },
    {
      "x": -7,
      "y": 3,
      "z": 4,
      "name": "Rock_Sandstone_Cobble"
    },
    {
      "x": -7,
      "y": 4,
      "z": 4,
      "name": "Rock_Sandstone_Cobble"
    },
    {
      "x": -7,
      "y": 5,
      "z": 4,
      "name": "Soil_Mud_Dry"
    },
    {
      "x": -7,
      "y": 6,
      "z": 4,
      "name": "Wood_Drywood_Fence",
      "rotation": 3
    },
    {
      "x": -7,
      "y": 11,
      "z": 4,
      "name": "Rock_Sandstone_Brick_Half",
      "rotation": 6
    },
    {
      "x": -7,
      "y": 15,
      "z": 4,
      "name": "Rock_Sandstone_Cobble_Beam",
      "rotation": 4
    },
    {
      "x": -7,
      "y": 0,
      "z": 5,
      "name": "Rock_Sandstone_Cobble"
    },
    {
      "x": -7,
      "y": 1,
      "z": 5,
      "name": "Rock_Sandstone_Cobble"
    },
    {
      "x": -7,
      "y": 2,
      "z": 5,
      "name": "Rock_Sandstone_Cobble"
    },
    {
      "x": -7,
      "y": 3,
      "z": 5,
      "name": "Rock_Sandstone_Cobble"
    },
    {
      "x": -7,
      "y": 4,
      "z": 5,
      "name": "Rock_Sandstone_Cobble"
    },
    {
      "x": -7,
      "y": 5,
      "z": 5,
      "name": "Rock_Sandstone_Cobble"
    },
    {
      "x": -7,
      "y": 6,
      "z": 5,
      "name": "Rock_Sandstone_Brick"
    },
    {
      "x": -7,
      "y": 7,
      "z": 5,
      "name": "Rock_Sandstone_Brick"
    },
    {
      "x": -7,
      "y": 8,
      "z": 5,
      "name": "Rock_Sandstone_Cobble"
    },
    {
      "x": -7,
      "y": 9,
      "z": 5,
      "name": "Rock_Sandstone_Cobble"
    },
    {
      "x": -7,
      "y": 10,
      "z": 5,
      "name": "Rock_Sandstone_Cobble"
    },
    {
      "x": -7,
      "y": 11,
      "z": 5,
      "name": "Rock_Sandstone_White_Cobble"
    },
    {
      "x": -7,
      "y": 12,
      "z": 5,
      "name": "Rock_Sandstone_White_Cobble"
    },
    {
      "x": -7,
      "y": 13,
      "z": 5,
      "name": "Rock_Sandstone_White_Cobble"
    },
    {
      "x": -7,
      "y": 14,
      "z": 5,
      "name": "Rock_Sandstone_White_Cobble"
    },
    {
      "x": -7,
      "y": 15,
      "z": 5,
      "name": "Rock_Sandstone_Brick_Decorative"
    },
    {
      "x": -7,
      "y": 16,
      "z": 5,
      "name": "Rock_Sandstone_Brick_Smooth_Half"
    },
    {
      "x": -7,
      "y": 10,
      "z": 6,
      "name": "Wood_Drywood_Planks"
    },
    {
      "x": -7,
      "y": 15,
      "z": 6,
      "name": "Wood_Dry_Trunk",
      "rotation": 4
    },
    {
      "x": -7,
      "y": 10,
      "z": 7,
      "name": "Wood_Drywood_Planks"
    },
    {
      "x": -7,
      "y": 15,
      "z": 7,
      "name": "Wood_Dry_Trunk",
      "rotation": 4
    },
    {
      "x": -7,
      "y": 10,
      "z": 8,
      "name": "Wood_Drywood_Beam",
      "rotation": 4
    },
    {
      "x": -7,
      "y": 15,
      "z": 8,
      "name": "Wood_Dry_Trunk",
      "rotation": 4
    },
    {
      "x": -7,
      "y": 15,
      "z": 9,
      "name": "Wood_Dry_Trunk",
      "rotation": 4
    },
    {
      "x": -7,
      "y": 15,
      "z": 10,
      "name": "Wood_Dry_Trunk",
      "rotation": 4
    },
    {
      "x": -7,
      "y": 13,
      "z": 11,
      "name": "Rock_Sandstone_White_Cobble_Half",
      "rotation": 7
    },
    {
      "x": -7,
      "y": 14,
      "z": 11,
      "name": "Rock_Sandstone_White_Cobble"
    },
    {
      "x": -7,
      "y": 15,
      "z": 11,
      "name": "Rock_Sandstone_Brick_Half"
    },
    {
      "x": -6,
      "y": 0,
      "z": -11,
      "name": "Rock_Sandstone_Brick"
    },
    {
      "x": -6,
      "y": 1,
      "z": -11,
      "name": "Rock_Sandstone_Brick"
    },
    {
      "x": -6,
      "y": 2,
      "z": -11,
      "name": "Rock_Sandstone_Brick"
    },
    {
      "x": -6,
      "y": 3,
      "z": -11,
      "name": "Rock_Sandstone_Brick"
    },
    {
      "x": -6,
      "y": 4,
      "z": -11,
      "name": "Rock_Sandstone_Brick"
    },
    {
      "x": -6,
      "y": 5,
      "z": -11,
      "name": "Rock_Sandstone_Brick"
    },
    {
      "x": -6,
      "y": 6,
      "z": -11,
      "name": "Rock_Sandstone_Brick"
    },
    {
      "x": -6,
      "y": 7,
      "z": -11,
      "name": "Rock_Sandstone_Brick_Stairs",
      "rotation": 1
    },
    {
      "x": -6,
      "y": 0,
      "z": -10,
      "name": "Soil_Dirt_Dry"
    },
    {
      "x": -6,
      "y": 1,
      "z": -10,
      "name": "Soil_Dirt_Dry"
    },
    {
      "x": -6,
      "y": 2,
      "z": -10,
      "name": "Soil_Dirt_Dry"
    },
    {
      "x": -6,
      "y": 3,
      "z": -10,
      "name": "Soil_Dirt_Dry"
    },
    {
      "x": -6,
      "y": 4,
      "z": -10,
      "name": "Soil_Dirt_Dry"
    },
    {
      "x": -6,
      "y": 5,
      "z": -10,
      "name": "Soil_Dirt_Dry"
    },
    {
      "x": -6,
      "y": 6,
      "z": -10,
      "name": "Wood_Softwood_Decorative"
    },
    {
      "x": -6,
      "y": 7,
      "z": -10,
      "name": "Wood_Softwood_Decorative"
    },
    {
      "x": -6,
      "y": 0,
      "z": -9,
      "name": "Soil_Dirt_Dry"
    },
    {
      "x": -6,
      "y": 1,
      "z": -9,
      "name": "Soil_Dirt_Dry"
    },
    {
      "x": -6,
      "y": 2,
      "z": -9,
      "name": "Soil_Dirt_Dry"
    },
    {
      "x": -6,
      "y": 3,
      "z": -9,
      "name": "Soil_Dirt_Dry"
    },
    {
      "x": -6,
      "y": 4,
      "z": -9,
      "name": "Soil_Dirt_Dry"
    },
    {
      "x": -6,
      "y": 5,
      "z": -9,
      "name": "Soil_Dirt_Dry"
    },
    {
      "x": -6,
      "y": 6,
      "z": -9,
      "name": "Wood_Softwood_Decorative"
    },
    {
      "x": -6,
      "y": 7,
      "z": -9,
      "name": "Wood_Softwood_Decorative"
    },
    {
      "x": -6,
      "y": 0,
      "z": -8,
      "name": "Soil_Dirt_Dry"
    },
    {
      "x": -6,
      "y": 1,
      "z": -8,
      "name": "Soil_Dirt_Dry"
    },
    {
      "x": -6,
      "y": 2,
      "z": -8,
      "name": "Soil_Dirt_Dry"
    },
    {
      "x": -6,
      "y": 3,
      "z": -8,
      "name": "Soil_Dirt_Dry"
    },
    {
      "x": -6,
      "y": 4,
      "z": -8,
      "name": "Soil_Dirt_Dry"
    },
    {
      "x": -6,
      "y": 5,
      "z": -8,
      "name": "Soil_Dirt_Dry"
    },
    {
      "x": -6,
      "y": 0,
      "z": -7,
      "name": "Soil_Dirt_Dry"
    },
    {
      "x": -6,
      "y": 1,
      "z": -7,
      "name": "Soil_Dirt_Dry"
    },
    {
      "x": -6,
      "y": 2,
      "z": -7,
      "name": "Soil_Dirt_Dry"
    },
    {
      "x": -6,
      "y": 3,
      "z": -7,
      "name": "Soil_Dirt_Dry"
    },
    {
      "x": -6,
      "y": 4,
      "z": -7,
      "name": "Soil_Dirt_Dry"
    },
    {
      "x": -6,
      "y": 5,
      "z": -7,
      "name": "Soil_Dirt_Dry"
    },
    {
      "x": -6,
      "y": 0,
      "z": -6,
      "name": "Soil_Dirt_Dry"
    },
    {
      "x": -6,
      "y": 1,
      "z": -6,
      "name": "Soil_Dirt_Dry"
    },
    {
      "x": -6,
      "y": 2,
      "z": -6,
      "name": "Soil_Dirt_Dry"
    },
    {
      "x": -6,
      "y": 3,
      "z": -6,
      "name": "Soil_Dirt_Dry"
    },
    {
      "x": -6,
      "y": 4,
      "z": -6,
      "name": "Soil_Dirt_Dry"
    },
    {
      "x": -6,
      "y": 5,
      "z": -6,
      "name": "Soil_Dirt_Dry"
    },
    {
      "x": -6,
      "y": 9,
      "z": -6,
      "name": "Cloth_Roof_Green_Flap",
      "rotation": 2
    },
    {
      "x": -6,
      "y": 10,
      "z": -6,
      "name": "Cloth_Roof_Green_Vertical",
      "rotation": 2
    },
    {
      "x": -6,
      "y": 11,
      "z": -6,
      "name": "Cloth_Roof_Green_Vertical",
      "rotation": 2
    },
    {
      "x": -6,
      "y": 0,
      "z": -5,
      "name": "Soil_Dirt_Dry"
    },
    {
      "x": -6,
      "y": 1,
      "z": -5,
      "name": "Soil_Dirt_Dry"
    },
    {
      "x": -6,
      "y": 2,
      "z": -5,
      "name": "Soil_Dirt_Dry"
    },
    {
      "x": -6,
      "y": 3,
      "z": -5,
      "name": "Soil_Dirt_Dry"
    },
    {
      "x": -6,
      "y": 4,
      "z": -5,
      "name": "Soil_Dirt_Dry"
    },
    {
      "x": -6,
      "y": 5,
      "z": -5,
      "name": "Soil_Dirt_Dry"
    },
    {
      "x": -6,
      "y": 9,
      "z": -5,
      "name": "Wood_Drywood_Beam",
      "rotation": 5
    },
    {
      "x": -6,
      "y": 11,
      "z": -5,
      "name": "Wood_Dry_Trunk",
      "rotation": 5
    },
    {
      "x": -6,
      "y": 12,
      "z": -5,
      "name": "Cloth_Roof_Green_Flat"
    },
    {
      "x": -6,
      "y": 0,
      "z": -4,
      "name": "Soil_Dirt_Dry"
    },
    {
      "x": -6,
      "y": 1,
      "z": -4,
      "name": "Soil_Dirt_Dry"
    },
    {
      "x": -6,
      "y": 2,
      "z": -4,
      "name": "Soil_Dirt_Dry"
    },
    {
      "x": -6,
      "y": 3,
      "z": -4,
      "name": "Soil_Dirt_Dry"
    },
    {
      "x": -6,
      "y": 4,
      "z": -4,
      "name": "Soil_Dirt_Dry"
    },
    {
      "x": -6,
      "y": 5,
      "z": -4,
      "name": "Soil_Dirt_Dry"
    },
    {
      "x": -6,
      "y": 7,
      "z": -4,
      "name": "Plant_Vine_Wall_Dry",
      "rotation": 1
    },
    {
      "x": -6,
      "y": 8,
      "z": -4,
      "name": "Plant_Vine_Wall_Dry",
      "rotation": 1
    },
    {
      "x": -6,
      "y": 9,
      "z": -4,
      "name": "Plant_Vine_Wall_Dry",
      "rotation": 1
    },
    {
      "x": -6,
      "y": 11,
      "z": -4,
      "name": "Wood_Dry_Branch_Long",
      "rotation": 4
    },
    {
      "x": -6,
      "y": 12,
      "z": -4,
      "name": "Cloth_Roof_Green_Flat"
    },
    {
      "x": -6,
      "y": 0,
      "z": -3,
      "name": "Soil_Dirt_Dry"
    },
    {
      "x": -6,
      "y": 1,
      "z": -3,
      "name": "Soil_Dirt_Dry"
    },
    {
      "x": -6,
      "y": 2,
      "z": -3,
      "name": "Soil_Dirt_Dry"
    },
    {
      "x": -6,
      "y": 3,
      "z": -3,
      "name": "Soil_Dirt_Dry"
    },
    {
      "x": -6,
      "y": 4,
      "z": -3,
      "name": "Soil_Dirt_Dry"
    },
    {
      "x": -6,
      "y": 5,
      "z": -3,
      "name": "Soil_Dirt_Dry"
    },
    {
      "x": -6,
      "y": 9,
      "z": -3,
      "name": "Plant_Vine_Wall_Dry",
      "rotation": 1
    },
    {
      "x": -6,
      "y": 10,
      "z": -3,
      "name": "Plant_Vine_Wall_Dry",
      "rotation": 1
    },
    {
      "x": -6,
      "y": 11,
      "z": -3,
      "name": "Wood_Dry_Branch_Long",
      "rotation": 4
    },
    {
      "x": -6,
      "y": 12,
      "z": -3,
      "name": "Cloth_Roof_Green_Flat"
    },
    {
      "x": -6,
      "y": 0,
      "z": -2,
      "name": "Soil_Dirt_Dry"
    },
    {
      "x": -6,
      "y": 1,
      "z": -2,
      "name": "Soil_Dirt_Dry"
    },
    {
      "x": -6,
      "y": 2,
      "z": -2,
      "name": "Soil_Dirt_Dry"
    },
    {
      "x": -6,
      "y": 3,
      "z": -2,
      "name": "Soil_Dirt_Dry"
    },
    {
      "x": -6,
      "y": 4,
      "z": -2,
      "name": "Soil_Dirt_Dry"
    },
    {
      "x": -6,
      "y": 5,
      "z": -2,
      "name": "Soil_Dirt_Dry"
    },
    {
      "x": -6,
      "y": 11,
      "z": -2,
      "name": "Wood_Dry_Trunk",
      "rotation": 5
    },
    {
      "x": -6,
      "y": 12,
      "z": -2,
      "name": "Cloth_Roof_Green_Flat"
    },
    {
      "x": -6,
      "y": 0,
      "z": -1,
      "name": "Soil_Dirt_Dry"
    },
    {
      "x": -6,
      "y": 1,
      "z": -1,
      "name": "Soil_Dirt_Dry"
    },
    {
      "x": -6,
      "y": 2,
      "z": -1,
      "name": "Soil_Dirt_Dry"
    },
    {
      "x": -6,
      "y": 3,
      "z": -1,
      "name": "Soil_Dirt_Dry"
    },
    {
      "x": -6,
      "y": 4,
      "z": -1,
      "name": "Soil_Dirt_Dry"
    },
    {
      "x": -6,
      "y": 5,
      "z": -1,
      "name": "Soil_Dirt_Dry"
    },
    {
      "x": -6,
      "y": 6,
      "z": -1,
      "name": "Plant_Grass_Arid"
    },
    {
      "x": -6,
      "y": 10,
      "z": -1,
      "name": "Cloth_Roof_Green_Vertical"
    },
    {
      "x": -6,
      "y": 11,
      "z": -1,
      "name": "Cloth_Roof_Green_Vertical"
    },
    {
      "x": -6,
      "y": 0,
      "z": 0,
      "name": "Soil_Dirt_Dry"
    },
    {
      "x": -6,
      "y": 1,
      "z": 0,
      "name": "Soil_Dirt_Dry"
    },
    {
      "x": -6,
      "y": 2,
      "z": 0,
      "name": "Soil_Dirt_Dry"
    },
    {
      "x": -6,
      "y": 3,
      "z": 0,
      "name": "Soil_Dirt_Dry"
    },
    {
      "x": -6,
      "y": 4,
      "z": 0,
      "name": "Soil_Dirt_Dry"
    },
    {
      "x": -6,
      "y": 5,
      "z": 0,
      "name": "Soil_Dirt_Dry"
    },
    {
      "x": -6,
      "y": 6,
      "z": 0,
      "name": "Plant_Bush_Arid"
    },
    {
      "x": -6,
      "y": 7,
      "z": 0,
      "name": "Plant_Vine_Wall_Dry",
      "rotation": 1
    },
    {
      "x": -6,
      "y": 8,
      "z": 0,
      "name": "Plant_Vine_Wall_Dry",
      "rotation": 1
    },
    {
      "x": -6,
      "y": 0,
      "z": 1,
      "name": "Rock_Sandstone_Cobble"
    },
    {
      "x": -6,
      "y": 1,
      "z": 1,
      "name": "Rock_Sandstone_Cobble"
    },
    {
      "x": -6,
      "y": 2,
      "z": 1,
      "name": "Rock_Sandstone_Cobble"
    },
    {
      "x": -6,
      "y": 3,
      "z": 1,
      "name": "Rock_Sandstone_Cobble"
    },
    {
      "x": -6,
      "y": 4,
      "z": 1,
      "name": "Rock_Sandstone_Cobble"
    },
    {
      "x": -6,
      "y": 5,
      "z": 1,
      "name": "Soil_Mud_Dry"
    },
    {
      "x": -6,
      "y": 6,
      "z": 1,
      "name": "Wood_Drywood_Fence",
      "rotation": 2
    },
    {
      "x": -6,
      "y": 7,
      "z": 1,
      "name": "Plant_Vine_Wall_Dry",
      "rotation": 1
    },
    {
      "x": -6,
      "y": 0,
      "z": 2,
      "name": "Rock_Sandstone_Cobble"
    },
    {
      "x": -6,
      "y": 1,
      "z": 2,
      "name": "Rock_Sandstone_Cobble"
    },
    {
      "x": -6,
      "y": 2,
      "z": 2,
      "name": "Rock_Sandstone_Cobble"
    },
    {
      "x": -6,
      "y": 3,
      "z": 2,
      "name": "Rock_Sandstone_Cobble"
    },
    {
      "x": -6,
      "y": 4,
      "z": 2,
      "name": "Rock_Sandstone_Cobble"
    },
    {
      "x": -6,
      "y": 5,
      "z": 2,
      "name": "Soil_Mud_Dry"
    },
    {
      "x": -6,
      "y": 6,
      "z": 2,
      "name": "Wood_Dry_Branch_Long"
    },
    {
      "x": -6,
      "y": 7,
      "z": 2,
      "name": "Wood_Dry_Branch_Long"
    },
    {
      "x": -6,
      "y": 8,
      "z": 2,
      "name": "Wood_Dry_Branch_Long"
    },
    {
      "x": -6,
      "y": 9,
      "z": 2,
      "name": "Wood_Dry_Trunk",
      "rotation": 4
    },
    {
      "x": -6,
      "y": 0,
      "z": 3,
      "name": "Rock_Sandstone_Cobble"
    },
    {
      "x": -6,
      "y": 1,
      "z": 3,
      "name": "Rock_Sandstone_Cobble"
    },
    {
      "x": -6,
      "y": 2,
      "z": 3,
      "name": "Rock_Sandstone_Cobble"
    },
    {
      "x": -6,
      "y": 3,
      "z": 3,
      "name": "Rock_Sandstone_Cobble"
    },
    {
      "x": -6,
      "y": 4,
      "z": 3,
      "name": "Rock_Sandstone_Cobble"
    },
    {
      "x": -6,
      "y": 5,
      "z": 3,
      "name": "Soil_Mud_Dry"
    },
    {
      "x": -6,
      "y": 9,
      "z": 3,
      "name": "Wood_Dry_Trunk",
      "rotation": 4
    },
    {
      "x": -6,
      "y": 10,
      "z": 3,
      "name": "Wood_Drywood_Roof_Flat",
      "rotation": 2
    },
    {
      "x": -6,
      "y": 0,
      "z": 4,
      "name": "Rock_Sandstone_Cobble"
    },
    {
      "x": -6,
      "y": 1,
      "z": 4,
      "name": "Rock_Sandstone_Cobble"
    },
    {
      "x": -6,
      "y": 2,
      "z": 4,
      "name": "Rock_Sandstone_Cobble"
    },
    {
      "x": -6,
      "y": 3,
      "z": 4,
      "name": "Rock_Sandstone_Cobble"
    },
    {
      "x": -6,
      "y": 4,
      "z": 4,
      "name": "Rock_Sandstone_Cobble"
    },
    {
      "x": -6,
      "y": 5,
      "z": 4,
      "name": "Soil_Mud_Dry"
    },
    {
      "x": -6,
      "y": 6,
      "z": 4,
      "name": "Container_Bucket"
    },
    {
      "x": -6,
      "y": 9,
      "z": 4,
      "name": "Wood_Dry_Trunk",
      "rotation": 4
    },
    {
      "x": -6,
      "y": 10,
      "z": 4,
      "name": "Wood_Drywood_Roof_Flat",
      "rotation": 2
    },
    {
      "x": -6,
      "y": 11,
      "z": 4,
      "name": "Rock_Sandstone_Brick_Half",
      "rotation": 6
    },
    {
      "x": -6,
      "y": 0,
      "z": 5,
      "name": "Rock_Sandstone_Cobble"
    },
    {
      "x": -6,
      "y": 1,
      "z": 5,
      "name": "Rock_Sandstone_Cobble"
    },
    {
      "x": -6,
      "y": 2,
      "z": 5,
      "name": "Rock_Sandstone_Cobble"
    },
    {
      "x": -6,
      "y": 3,
      "z": 5,
      "name": "Rock_Sandstone_Cobble"
    },
    {
      "x": -6,
      "y": 4,
      "z": 5,
      "name": "Rock_Sandstone_Cobble"
    },
    {
      "x": -6,
      "y": 5,
      "z": 5,
      "name": "Rock_Sandstone_Cobble"
    },
    {
      "x": -6,
      "y": 6,
      "z": 5,
      "name": "Rock_Sandstone_Brick"
    },
    {
      "x": -6,
      "y": 7,
      "z": 5,
      "name": "Rock_Sandstone_Cobble"
    },
    {
      "x": -6,
      "y": 8,
      "z": 5,
      "name": "Rock_Sandstone_Cobble"
    },
    {
      "x": -6,
      "y": 9,
      "z": 5,
      "name": "Rock_Sandstone_Cobble"
    },
    {
      "x": -6,
      "y": 10,
      "z": 5,
      "name": "Rock_Sandstone_Cobble"
    },
    {
      "x": -6,
      "y": 11,
      "z": 5,
      "name": "Rock_Sandstone_White_Cobble"
    },
    {
      "x": -6,
      "y": 12,
      "z": 5,
      "name": "Rock_Sandstone_White_Cobble"
    },
    {
      "x": -6,
      "y": 13,
      "z": 5,
      "name": "Rock_Sandstone_White_Cobble"
    },
    {
      "x": -6,
      "y": 14,
      "z": 5,
      "name": "Rock_Sandstone_White_Cobble"
    },
    {
      "x": -6,
      "y": 15,
      "z": 5,
      "name": "Rock_Sandstone_Brick_Decorative"
    },
    {
      "x": -6,
      "y": 16,
      "z": 5,
      "name": "Rock_Sandstone_Brick_Smooth_Half"
    },
    {
      "x": -6,
      "y": 10,
      "z": 6,
      "name": "Wood_Drywood_Planks"
    },
    {
      "x": -6,
      "y": 15,
      "z": 6,
      "name": "Wood_Dry_Trunk",
      "rotation": 5
    },
    {
      "x": -6,
      "y": 10,
      "z": 7,
      "name": "Wood_Drywood_Planks_Half"
    },
    {
      "x": -6,
      "y": 10,
      "z": 8,
      "name": "Wood_Drywood_Planks_Half"
    },
    {
      "x": -6,
      "y": 15,
      "z": 10,
      "name": "Wood_Dry_Trunk",
      "rotation": 5
    },
    {
      "x": -6,
      "y": 12,
      "z": 11,
      "name": "Rock_Sandstone_White_Cobble"
    },
    {
      "x": -6,
      "y": 13,
      "z": 11,
      "name": "Rock_Sandstone_White_Cobble"
    },
    {
      "x": -6,
      "y": 14,
      "z": 11,
      "name": "Rock_Sandstone_White_Cobble"
    },
    {
      "x": -6,
      "y": 15,
      "z": 11,
      "name": "Rock_Sandstone_Brick_Decorative"
    },
    {
      "x": -5,
      "y": 0,
      "z": -11,
      "name": "Rock_Sandstone_Brick"
    },
    {
      "x": -5,
      "y": 1,
      "z": -11,
      "name": "Rock_Sandstone_Brick"
    },
    {
      "x": -5,
      "y": 2,
      "z": -11,
      "name": "Rock_Sandstone_Brick"
    },
    {
      "x": -5,
      "y": 3,
      "z": -11,
      "name": "Rock_Sandstone_Brick"
    },
    {
      "x": -5,
      "y": 4,
      "z": -11,
      "name": "Rock_Sandstone_Brick"
    },
    {
      "x": -5,
      "y": 5,
      "z": -11,
      "name": "Rock_Sandstone_Brick"
    },
    {
      "x": -5,
      "y": 6,
      "z": -11,
      "name": "Rock_Sandstone_Brick_Stairs",
      "rotation": 1
    },
    {
      "x": -5,
      "y": 0,
      "z": -10,
      "name": "Soil_Dirt_Dry"
    },
    {
      "x": -5,
      "y": 1,
      "z": -10,
      "name": "Soil_Dirt_Dry"
    },
    {
      "x": -5,
      "y": 2,
      "z": -10,
      "name": "Soil_Dirt_Dry"
    },
    {
      "x": -5,
      "y": 3,
      "z": -10,
      "name": "Soil_Dirt_Dry"
    },
    {
      "x": -5,
      "y": 4,
      "z": -10,
      "name": "Soil_Dirt_Dry"
    },
    {
      "x": -5,
      "y": 5,
      "z": -10,
      "name": "Soil_Dirt_Dry"
    },
    {
      "x": -5,
      "y": 6,
      "z": -10,
      "name": "Wood_Softwood_Decorative"
    },
    {
      "x": -5,
      "y": 7,
      "z": -10,
      "name": "Wood_Softwood_Decorative"
    },
    {
      "x": -5,
      "y": 0,
      "z": -9,
      "name": "Soil_Dirt_Dry"
    },
    {
      "x": -5,
      "y": 1,
      "z": -9,
      "name": "Soil_Dirt_Dry"
    },
    {
      "x": -5,
      "y": 2,
      "z": -9,
      "name": "Soil_Dirt_Dry"
    },
    {
      "x": -5,
      "y": 3,
      "z": -9,
      "name": "Soil_Dirt_Dry"
    },
    {
      "x": -5,
      "y": 4,
      "z": -9,
      "name": "Soil_Dirt_Dry"
    },
    {
      "x": -5,
      "y": 5,
      "z": -9,
      "name": "Soil_Dirt_Dry"
    },
    {
      "x": -5,
      "y": 6,
      "z": -9,
      "name": "Wood_Softwood_Decorative"
    },
    {
      "x": -5,
      "y": 7,
      "z": -9,
      "name": "Wood_Softwood_Decorative"
    },
    {
      "x": -5,
      "y": 0,
      "z": -8,
      "name": "Soil_Dirt_Dry"
    },
    {
      "x": -5,
      "y": 1,
      "z": -8,
      "name": "Soil_Dirt_Dry"
    },
    {
      "x": -5,
      "y": 2,
      "z": -8,
      "name": "Soil_Dirt_Dry"
    },
    {
      "x": -5,
      "y": 3,
      "z": -8,
      "name": "Soil_Dirt_Dry"
    },
    {
      "x": -5,
      "y": 4,
      "z": -8,
      "name": "Soil_Dirt_Dry"
    },
    {
      "x": -5,
      "y": 5,
      "z": -8,
      "name": "Soil_Dirt_Dry"
    },
    {
      "x": -5,
      "y": 6,
      "z": -8,
      "name": "Rubble_Sandstone"
    },
    {
      "x": -5,
      "y": 0,
      "z": -7,
      "name": "Soil_Dirt_Dry"
    },
    {
      "x": -5,
      "y": 1,
      "z": -7,
      "name": "Soil_Dirt_Dry"
    },
    {
      "x": -5,
      "y": 2,
      "z": -7,
      "name": "Soil_Dirt_Dry"
    },
    {
      "x": -5,
      "y": 3,
      "z": -7,
      "name": "Soil_Dirt_Dry"
    },
    {
      "x": -5,
      "y": 4,
      "z": -7,
      "name": "Soil_Dirt_Dry"
    },
    {
      "x": -5,
      "y": 5,
      "z": -7,
      "name": "Soil_Dirt_Dry"
    },
    {
      "x": -5,
      "y": 0,
      "z": -6,
      "name": "Soil_Dirt_Dry"
    },
    {
      "x": -5,
      "y": 1,
      "z": -6,
      "name": "Soil_Dirt_Dry"
    },
    {
      "x": -5,
      "y": 2,
      "z": -6,
      "name": "Soil_Dirt_Dry"
    },
    {
      "x": -5,
      "y": 3,
      "z": -6,
      "name": "Soil_Dirt_Dry"
    },
    {
      "x": -5,
      "y": 4,
      "z": -6,
      "name": "Soil_Dirt_Dry"
    },
    {
      "x": -5,
      "y": 5,
      "z": -6,
      "name": "Soil_Dirt_Dry"
    },
    {
      "x": -5,
      "y": 9,
      "z": -6,
      "name": "Cloth_Roof_Green_Flap",
      "rotation": 2
    },
    {
      "x": -5,
      "y": 10,
      "z": -6,
      "name": "Cloth_Roof_Green_Vertical",
      "rotation": 2
    },
    {
      "x": -5,
      "y": 11,
      "z": -6,
      "name": "Cloth_Roof_Green_Vertical",
      "rotation": 2
    },
    {
      "x": -5,
      "y": 0,
      "z": -5,
      "name": "Soil_Dirt_Dry"
    },
    {
      "x": -5,
      "y": 1,
      "z": -5,
      "name": "Soil_Dirt_Dry"
    },
    {
      "x": -5,
      "y": 2,
      "z": -5,
      "name": "Soil_Dirt_Dry"
    },
    {
      "x": -5,
      "y": 3,
      "z": -5,
      "name": "Soil_Dirt_Dry"
    },
    {
      "x": -5,
      "y": 4,
      "z": -5,
      "name": "Soil_Dirt_Dry"
    },
    {
      "x": -5,
      "y": 5,
      "z": -5,
      "name": "Soil_Dirt_Dry"
    },
    {
      "x": -5,
      "y": 9,
      "z": -5,
      "name": "Wood_Drywood_Beam",
      "rotation": 5
    },
    {
      "x": -5,
      "y": 11,
      "z": -5,
      "name": "Wood_Dry_Trunk",
      "rotation": 5
    },
    {
      "x": -5,
      "y": 12,
      "z": -5,
      "name": "Cloth_Roof_Green_Flat"
    },
    {
      "x": -5,
      "y": 0,
      "z": -4,
      "name": "Soil_Dirt_Dry"
    },
    {
      "x": -5,
      "y": 1,
      "z": -4,
      "name": "Soil_Dirt_Dry"
    },
    {
      "x": -5,
      "y": 2,
      "z": -4,
      "name": "Soil_Dirt_Dry"
    },
    {
      "x": -5,
      "y": 3,
      "z": -4,
      "name": "Soil_Dirt_Dry"
    },
    {
      "x": -5,
      "y": 4,
      "z": -4,
      "name": "Soil_Dirt_Dry"
    },
    {
      "x": -5,
      "y": 5,
      "z": -4,
      "name": "Soil_Dirt_Dry"
    },
    {
      "x": -5,
      "y": 0,
      "z": -3,
      "name": "Soil_Dirt_Dry"
    },
    {
      "x": -5,
      "y": 1,
      "z": -3,
      "name": "Soil_Dirt_Dry"
    },
    {
      "x": -5,
      "y": 2,
      "z": -3,
      "name": "Soil_Dirt_Dry"
    },
    {
      "x": -5,
      "y": 3,
      "z": -3,
      "name": "Soil_Dirt_Dry"
    },
    {
      "x": -5,
      "y": 4,
      "z": -3,
      "name": "Soil_Dirt_Dry"
    },
    {
      "x": -5,
      "y": 5,
      "z": -3,
      "name": "Soil_Dirt_Dry"
    },
    {
      "x": -5,
      "y": 12,
      "z": -3,
      "name": "Cloth_Roof_Green_Flat"
    },
    {
      "x": -5,
      "y": 0,
      "z": -2,
      "name": "Soil_Dirt_Dry"
    },
    {
      "x": -5,
      "y": 1,
      "z": -2,
      "name": "Soil_Dirt_Dry"
    },
    {
      "x": -5,
      "y": 2,
      "z": -2,
      "name": "Soil_Dirt_Dry"
    },
    {
      "x": -5,
      "y": 3,
      "z": -2,
      "name": "Soil_Dirt_Dry"
    },
    {
      "x": -5,
      "y": 4,
      "z": -2,
      "name": "Soil_Dirt_Dry"
    },
    {
      "x": -5,
      "y": 5,
      "z": -2,
      "name": "Soil_Dirt_Dry"
    },
    {
      "x": -5,
      "y": 11,
      "z": -2,
      "name": "Wood_Dry_Trunk",
      "rotation": 5
    },
    {
      "x": -5,
      "y": 12,
      "z": -2,
      "name": "Cloth_Roof_Green_Flat"
    },
    {
      "x": -5,
      "y": 0,
      "z": -1,
      "name": "Soil_Dirt_Dry"
    },
    {
      "x": -5,
      "y": 1,
      "z": -1,
      "name": "Soil_Dirt_Dry"
    },
    {
      "x": -5,
      "y": 2,
      "z": -1,
      "name": "Soil_Dirt_Dry"
    },
    {
      "x": -5,
      "y": 3,
      "z": -1,
      "name": "Soil_Dirt_Dry"
    },
    {
      "x": -5,
      "y": 4,
      "z": -1,
      "name": "Soil_Dirt_Dry"
    },
    {
      "x": -5,
      "y": 5,
      "z": -1,
      "name": "Soil_Dirt_Dry"
    },
    {
      "x": -5,
      "y": 10,
      "z": -1,
      "name": "Cloth_Roof_Green_Vertical"
    },
    {
      "x": -5,
      "y": 11,
      "z": -1,
      "name": "Cloth_Roof_Green_Vertical"
    },
    {
      "x": -5,
      "y": 0,
      "z": 0,
      "name": "Soil_Dirt_Dry"
    },
    {
      "x": -5,
      "y": 1,
      "z": 0,
      "name": "Soil_Dirt_Dry"
    },
    {
      "x": -5,
      "y": 2,
      "z": 0,
      "name": "Soil_Dirt_Dry"
    },
    {
      "x": -5,
      "y": 3,
      "z": 0,
      "name": "Soil_Dirt_Dry"
    },
    {
      "x": -5,
      "y": 4,
      "z": 0,
      "name": "Soil_Dirt_Dry"
    },
    {
      "x": -5,
      "y": 5,
      "z": 0,
      "name": "Soil_Dirt_Dry"
    },
    {
      "x": -5,
      "y": 0,
      "z": 1,
      "name": "Rock_Sandstone_Cobble"
    },
    {
      "x": -5,
      "y": 1,
      "z": 1,
      "name": "Rock_Sandstone_Cobble"
    },
    {
      "x": -5,
      "y": 2,
      "z": 1,
      "name": "Rock_Sandstone_Cobble"
    },
    {
      "x": -5,
      "y": 3,
      "z": 1,
      "name": "Rock_Sandstone_Cobble"
    },
    {
      "x": -5,
      "y": 4,
      "z": 1,
      "name": "Rock_Sandstone_Cobble"
    },
    {
      "x": -5,
      "y": 5,
      "z": 1,
      "name": "Soil_Mud_Dry"
    },
    {
      "x": -5,
      "y": 6,
      "z": 1,
      "name": "Wood_Drywood_Fence",
      "rotation": 2
    },
    {
      "x": -5,
      "y": 0,
      "z": 2,
      "name": "Rock_Sandstone_Cobble"
    },
    {
      "x": -5,
      "y": 1,
      "z": 2,
      "name": "Rock_Sandstone_Cobble"
    },
    {
      "x": -5,
      "y": 2,
      "z": 2,
      "name": "Rock_Sandstone_Cobble"
    },
    {
      "x": -5,
      "y": 3,
      "z": 2,
      "name": "Rock_Sandstone_Cobble"
    },
    {
      "x": -5,
      "y": 4,
      "z": 2,
      "name": "Rock_Sandstone_Cobble"
    },
    {
      "x": -5,
      "y": 5,
      "z": 2,
      "name": "Soil_Mud_Dry"
    },
    {
      "x": -5,
      "y": 9,
      "z": 2,
      "name": "Wood_Drywood_Beam",
      "rotation": 5
    },
    {
      "x": -5,
      "y": 0,
      "z": 3,
      "name": "Rock_Sandstone_Cobble"
    },
    {
      "x": -5,
      "y": 1,
      "z": 3,
      "name": "Rock_Sandstone_Cobble"
    },
    {
      "x": -5,
      "y": 2,
      "z": 3,
      "name": "Rock_Sandstone_Cobble"
    },
    {
      "x": -5,
      "y": 3,
      "z": 3,
      "name": "Rock_Sandstone_Cobble"
    },
    {
      "x": -5,
      "y": 4,
      "z": 3,
      "name": "Rock_Sandstone_Cobble"
    },
    {
      "x": -5,
      "y": 5,
      "z": 3,
      "name": "Soil_Mud_Dry"
    },
    {
      "x": -5,
      "y": 10,
      "z": 3,
      "name": "Wood_Drywood_Roof_Flat",
      "rotation": 2
    },
    {
      "x": -5,
      "y": 0,
      "z": 4,
      "name": "Rock_Sandstone_Cobble"
    },
    {
      "x": -5,
      "y": 1,
      "z": 4,
      "name": "Rock_Sandstone_Cobble"
    },
    {
      "x": -5,
      "y": 2,
      "z": 4,
      "name": "Rock_Sandstone_Cobble"
    },
    {
      "x": -5,
      "y": 3,
      "z": 4,
      "name": "Rock_Sandstone_Cobble"
    },
    {
      "x": -5,
      "y": 4,
      "z": 4,
      "name": "Rock_Sandstone_Cobble"
    },
    {
      "x": -5,
      "y": 5,
      "z": 4,
      "name": "Soil_Mud_Dry"
    },
    {
      "x": -5,
      "y": 10,
      "z": 4,
      "name": "Wood_Drywood_Roof_Flat",
      "rotation": 2
    },
    {
      "x": -5,
      "y": 11,
      "z": 4,
      "name": "Rock_Sandstone_Brick_Half",
      "rotation": 6
    },
    {
      "x": -5,
      "y": 0,
      "z": 5,
      "name": "Rock_Sandstone_Cobble"
    },
    {
      "x": -5,
      "y": 1,
      "z": 5,
      "name": "Rock_Sandstone_Cobble"
    },
    {
      "x": -5,
      "y": 2,
      "z": 5,
      "name": "Rock_Sandstone_Cobble"
    },
    {
      "x": -5,
      "y": 3,
      "z": 5,
      "name": "Rock_Sandstone_Cobble"
    },
    {
      "x": -5,
      "y": 4,
      "z": 5,
      "name": "Rock_Sandstone_Cobble"
    },
    {
      "x": -5,
      "y": 5,
      "z": 5,
      "name": "Rock_Sandstone_Cobble"
    },
    {
      "x": -5,
      "y": 6,
      "z": 5,
      "name": "Rock_Sandstone_Brick"
    },
    {
      "x": -5,
      "y": 7,
      "z": 5,
      "name": "Rock_Sandstone_Brick"
    },
    {
      "x": -5,
      "y": 8,
      "z": 5,
      "name": "Rock_Sandstone_Cobble"
    },
    {
      "x": -5,
      "y": 9,
      "z": 5,
      "name": "Rock_Sandstone_Cobble"
    },
    {
      "x": -5,
      "y": 10,
      "z": 5,
      "name": "Rock_Sandstone_Cobble"
    },
    {
      "x": -5,
      "y": 11,
      "z": 5,
      "name": "Rock_Sandstone_White_Cobble"
    },
    {
      "x": -5,
      "y": 12,
      "z": 5,
      "name": "Rock_Sandstone_White_Cobble"
    },
    {
      "x": -5,
      "y": 13,
      "z": 5,
      "name": "Wood_Drywood_Fence"
    },
    {
      "x": -5,
      "y": 14,
      "z": 5,
      "name": "Rock_Sandstone_White_Cobble"
    },
    {
      "x": -5,
      "y": 15,
      "z": 5,
      "name": "Rock_Sandstone_Brick_Decorative"
    },
    {
      "x": -5,
      "y": 16,
      "z": 5,
      "name": "Rock_Sandstone_Brick_Smooth_Half"
    },
    {
      "x": -5,
      "y": 0,
      "z": 6,
      "name": "Rock_Sandstone_Cobble"
    },
    {
      "x": -5,
      "y": 1,
      "z": 6,
      "name": "Rock_Sandstone_Cobble"
    },
    {
      "x": -5,
      "y": 2,
      "z": 6,
      "name": "Rock_Sandstone_Cobble"
    },
    {
      "x": -5,
      "y": 3,
      "z": 6,
      "name": "Rock_Sandstone_Cobble"
    },
    {
      "x": -5,
      "y": 4,
      "z": 6,
      "name": "Rock_Sandstone_Cobble"
    },
    {
      "x": -5,
      "y": 5,
      "z": 6,
      "name": "Rock_Sandstone_Cobble"
    },
    {
      "x": -5,
      "y": 10,
      "z": 6,
      "name": "Wood_Drywood_Planks"
    },
    {
      "x": -5,
      "y": 11,
      "z": 6,
      "name": "Furniture_Ancient_Bed",
      "components": {
        "Components": {
          "RespawnBlock": {}
        }
      }
    },
    {
      "x": -5,
      "y": 12,
      "z": 6,
      "name": "Furniture_Ancient_Bed",
      "filler": 1024
    },
    {
      "x": -5,
      "y": 15,
      "z": 6,
      "name": "Wood_Dry_Trunk",
      "rotation": 5
    },
    {
      "x": -5,
      "y": 10,
      "z": 7,
      "name": "Wood_Drywood_Planks"
    },
    {
      "x": -5,
      "y": 11,
      "z": 7,
      "name": "Furniture_Ancient_Bed",
      "filler": 32
    },
    {
      "x": -5,
      "y": 12,
      "z": 7,
      "name": "Furniture_Ancient_Bed",
      "filler": 1056
    },
    {
      "x": -5,
      "y": 10,
      "z": 8,
      "name": "Wood_Drywood_Planks"
    },
    {
      "x": -5,
      "y": 11,
      "z": 8,
      "name": "Furniture_Ancient_Bed",
      "filler": 64
    },
    {
      "x": -5,
      "y": 12,
      "z": 8,
      "name": "Furniture_Ancient_Bed",
      "filler": 1088
    },
    {
      "x": -5,
      "y": 10,
      "z": 9,
      "name": "Wood_Drywood_Planks"
    },
    {
      "x": -5,
      "y": 10,
      "z": 10,
      "name": "Wood_Drywood_Planks_Half",
      "rotation": 7
    },
    {
      "x": -5,
      "y": 15,
      "z": 10,
      "name": "Wood_Dry_Trunk",
      "rotation": 5
    },
    {
      "x": -5,
      "y": 9,
      "z": 11,
      "name": "Rock_Sandstone_Brick_Half",
      "rotation": 8
    },
    {
      "x": -5,
      "y": 10,
      "z": 11,
      "name": "Rock_Sandstone_Cobble"
    },
    {
      "x": -5,
      "y": 11,
      "z": 11,
      "name": "Rock_Sandstone_White_Cobble"
    },
    {
      "x": -5,
      "y": 12,
      "z": 11,
      "name": "Rock_Sandstone_White_Cobble"
    },
    {
      "x": -5,
      "y": 13,
      "z": 11,
      "name": "Wood_Drywood_Fence",
      "rotation": 2
    },
    {
      "x": -5,
      "y": 14,
      "z": 11,
      "name": "Rock_Sandstone_White_Cobble"
    },
    {
      "x": -5,
      "y": 15,
      "z": 11,
      "name": "Rock_Sandstone_Brick_Decorative"
    },
    {
      "x": -5,
      "y": 16,
      "z": 11,
      "name": "Rock_Sandstone_Brick_Smooth_Half"
    },
    {
      "x": -5,
      "y": 11,
      "z": 12,
      "name": "Rock_Sandstone_Brick_Half",
      "rotation": 4
    },
    {
      "x": -4,
      "y": 0,
      "z": -10,
      "name": "Soil_Dirt_Dry"
    },
    {
      "x": -4,
      "y": 1,
      "z": -10,
      "name": "Soil_Dirt_Dry"
    },
    {
      "x": -4,
      "y": 2,
      "z": -10,
      "name": "Soil_Dirt_Dry"
    },
    {
      "x": -4,
      "y": 3,
      "z": -10,
      "name": "Soil_Dirt_Dry"
    },
    {
      "x": -4,
      "y": 4,
      "z": -10,
      "name": "Soil_Dirt_Dry"
    },
    {
      "x": -4,
      "y": 5,
      "z": -10,
      "name": "Soil_Dirt_Dry"
    },
    {
      "x": -4,
      "y": 6,
      "z": -10,
      "name": "Furniture_Village_Crate",
      "components": {
        "Components": {
          "ItemContainerBlock": {
            "ItemContainer": {
              "Capacity": 20,
              "Items": {}
            },
            "Capacity": 20
          }
        }
      }
    },
    {
      "x": -4,
      "y": 0,
      "z": -9,
      "name": "Soil_Dirt_Dry"
    },
    {
      "x": -4,
      "y": 1,
      "z": -9,
      "name": "Soil_Dirt_Dry"
    },
    {
      "x": -4,
      "y": 2,
      "z": -9,
      "name": "Soil_Dirt_Dry"
    },
    {
      "x": -4,
      "y": 3,
      "z": -9,
      "name": "Soil_Dirt_Dry"
    },
    {
      "x": -4,
      "y": 4,
      "z": -9,
      "name": "Soil_Dirt_Dry"
    },
    {
      "x": -4,
      "y": 5,
      "z": -9,
      "name": "Soil_Dirt_Dry"
    },
    {
      "x": -4,
      "y": 6,
      "z": -9,
      "name": "Furniture_Village_Crate",
      "components": {
        "Components": {
          "ItemContainerBlock": {
            "ItemContainer": {
              "Capacity": 20,
              "Items": {}
            },
            "Capacity": 20
          }
        }
      }
    },
    {
      "x": -4,
      "y": 7,
      "z": -9,
      "name": "Furniture_Village_Crate",
      "components": {
        "Components": {
          "ItemContainerBlock": {
            "ItemContainer": {
              "Capacity": 20,
              "Items": {}
            },
            "Capacity": 20
          }
        }
      }
    },
    {
      "x": -4,
      "y": 0,
      "z": -8,
      "name": "Soil_Dirt_Dry"
    },
    {
      "x": -4,
      "y": 1,
      "z": -8,
      "name": "Soil_Dirt_Dry"
    },
    {
      "x": -4,
      "y": 2,
      "z": -8,
      "name": "Soil_Dirt_Dry"
    },
    {
      "x": -4,
      "y": 3,
      "z": -8,
      "name": "Soil_Dirt_Dry"
    },
    {
      "x": -4,
      "y": 4,
      "z": -8,
      "name": "Soil_Dirt_Dry"
    },
    {
      "x": -4,
      "y": 5,
      "z": -8,
      "name": "Soil_Dirt_Dry"
    },
    {
      "x": -4,
      "y": 0,
      "z": -7,
      "name": "Soil_Dirt_Dry"
    },
    {
      "x": -4,
      "y": 1,
      "z": -7,
      "name": "Soil_Dirt_Dry"
    },
    {
      "x": -4,
      "y": 2,
      "z": -7,
      "name": "Soil_Dirt_Dry"
    },
    {
      "x": -4,
      "y": 3,
      "z": -7,
      "name": "Soil_Dirt_Dry"
    },
    {
      "x": -4,
      "y": 4,
      "z": -7,
      "name": "Soil_Dirt_Dry"
    },
    {
      "x": -4,
      "y": 5,
      "z": -7,
      "name": "Soil_Dirt_Dry"
    },
    {
      "x": -4,
      "y": 0,
      "z": -6,
      "name": "Soil_Dirt_Dry"
    },
    {
      "x": -4,
      "y": 1,
      "z": -6,
      "name": "Soil_Dirt_Dry"
    },
    {
      "x": -4,
      "y": 2,
      "z": -6,
      "name": "Soil_Dirt_Dry"
    },
    {
      "x": -4,
      "y": 3,
      "z": -6,
      "name": "Soil_Dirt_Dry"
    },
    {
      "x": -4,
      "y": 4,
      "z": -6,
      "name": "Soil_Dirt_Dry"
    },
    {
      "x": -4,
      "y": 5,
      "z": -6,
      "name": "Soil_Dirt_Dry"
    },
    {
      "x": -4,
      "y": 10,
      "z": -6,
      "name": "Cloth_Roof_Green_Flap",
      "rotation": 2
    },
    {
      "x": -4,
      "y": 11,
      "z": -6,
      "name": "Cloth_Roof_Green_Vertical",
      "rotation": 2
    },
    {
      "x": -4,
      "y": 0,
      "z": -5,
      "name": "Soil_Dirt_Dry"
    },
    {
      "x": -4,
      "y": 1,
      "z": -5,
      "name": "Soil_Dirt_Dry"
    },
    {
      "x": -4,
      "y": 2,
      "z": -5,
      "name": "Soil_Dirt_Dry"
    },
    {
      "x": -4,
      "y": 3,
      "z": -5,
      "name": "Soil_Dirt_Dry"
    },
    {
      "x": -4,
      "y": 4,
      "z": -5,
      "name": "Soil_Dirt_Dry"
    },
    {
      "x": -4,
      "y": 5,
      "z": -5,
      "name": "Soil_Dirt_Dry"
    },
    {
      "x": -4,
      "y": 9,
      "z": -5,
      "name": "Wood_Drywood_Beam",
      "rotation": 5
    },
    {
      "x": -4,
      "y": 11,
      "z": -5,
      "name": "Wood_Dry_Trunk",
      "rotation": 5
    },
    {
      "x": -4,
      "y": 12,
      "z": -5,
      "name": "Cloth_Roof_Green_Flat"
    },
    {
      "x": -4,
      "y": 0,
      "z": -4,
      "name": "Soil_Dirt_Dry"
    },
    {
      "x": -4,
      "y": 1,
      "z": -4,
      "name": "Soil_Dirt_Dry"
    },
    {
      "x": -4,
      "y": 2,
      "z": -4,
      "name": "Soil_Dirt_Dry"
    },
    {
      "x": -4,
      "y": 3,
      "z": -4,
      "name": "Soil_Dirt_Dry"
    },
    {
      "x": -4,
      "y": 4,
      "z": -4,
      "name": "Soil_Dirt_Dry"
    },
    {
      "x": -4,
      "y": 5,
      "z": -4,
      "name": "Soil_Dirt_Dry"
    },
    {
      "x": -4,
      "y": 12,
      "z": -4,
      "name": "Cloth_Roof_Green_Flat"
    },
    {
      "x": -4,
      "y": 0,
      "z": -3,
      "name": "Soil_Dirt_Dry"
    },
    {
      "x": -4,
      "y": 1,
      "z": -3,
      "name": "Soil_Dirt_Dry"
    },
    {
      "x": -4,
      "y": 2,
      "z": -3,
      "name": "Soil_Dirt_Dry"
    },
    {
      "x": -4,
      "y": 3,
      "z": -3,
      "name": "Soil_Dirt_Dry"
    },
    {
      "x": -4,
      "y": 4,
      "z": -3,
      "name": "Soil_Dirt_Dry"
    },
    {
      "x": -4,
      "y": 5,
      "z": -3,
      "name": "Soil_Dirt_Dry"
    },
    {
      "x": -4,
      "y": 12,
      "z": -3,
      "name": "Cloth_Roof_Green_Flat"
    },
    {
      "x": -4,
      "y": 0,
      "z": -2,
      "name": "Soil_Dirt_Dry"
    },
    {
      "x": -4,
      "y": 1,
      "z": -2,
      "name": "Soil_Dirt_Dry"
    },
    {
      "x": -4,
      "y": 2,
      "z": -2,
      "name": "Soil_Dirt_Dry"
    },
    {
      "x": -4,
      "y": 3,
      "z": -2,
      "name": "Soil_Dirt_Dry"
    },
    {
      "x": -4,
      "y": 4,
      "z": -2,
      "name": "Soil_Dirt_Dry"
    },
    {
      "x": -4,
      "y": 5,
      "z": -2,
      "name": "Soil_Dirt_Dry"
    },
    {
      "x": -4,
      "y": 11,
      "z": -2,
      "name": "Wood_Dry_Trunk",
      "rotation": 5
    },
    {
      "x": -4,
      "y": 12,
      "z": -2,
      "name": "Cloth_Roof_Green_Flat"
    },
    {
      "x": -4,
      "y": 0,
      "z": -1,
      "name": "Soil_Dirt_Dry"
    },
    {
      "x": -4,
      "y": 1,
      "z": -1,
      "name": "Soil_Dirt_Dry"
    },
    {
      "x": -4,
      "y": 2,
      "z": -1,
      "name": "Soil_Dirt_Dry"
    },
    {
      "x": -4,
      "y": 3,
      "z": -1,
      "name": "Soil_Dirt_Dry"
    },
    {
      "x": -4,
      "y": 4,
      "z": -1,
      "name": "Soil_Dirt_Dry"
    },
    {
      "x": -4,
      "y": 5,
      "z": -1,
      "name": "Soil_Dirt_Dry"
    },
    {
      "x": -4,
      "y": 10,
      "z": -1,
      "name": "Cloth_Roof_Green_Flap"
    },
    {
      "x": -4,
      "y": 11,
      "z": -1,
      "name": "Cloth_Roof_Green_Vertical"
    },
    {
      "x": -4,
      "y": 0,
      "z": 0,
      "name": "Soil_Dirt_Dry"
    },
    {
      "x": -4,
      "y": 1,
      "z": 0,
      "name": "Soil_Dirt_Dry"
    },
    {
      "x": -4,
      "y": 2,
      "z": 0,
      "name": "Soil_Dirt_Dry"
    },
    {
      "x": -4,
      "y": 3,
      "z": 0,
      "name": "Soil_Dirt_Dry"
    },
    {
      "x": -4,
      "y": 4,
      "z": 0,
      "name": "Soil_Dirt_Dry"
    },
    {
      "x": -4,
      "y": 5,
      "z": 0,
      "name": "Soil_Dirt_Dry"
    },
    {
      "x": -4,
      "y": 0,
      "z": 1,
      "name": "Soil_Dirt_Dry"
    },
    {
      "x": -4,
      "y": 1,
      "z": 1,
      "name": "Soil_Dirt_Dry"
    },
    {
      "x": -4,
      "y": 2,
      "z": 1,
      "name": "Soil_Dirt_Dry"
    },
    {
      "x": -4,
      "y": 3,
      "z": 1,
      "name": "Soil_Dirt_Dry"
    },
    {
      "x": -4,
      "y": 4,
      "z": 1,
      "name": "Soil_Dirt_Dry"
    },
    {
      "x": -4,
      "y": 5,
      "z": 1,
      "name": "Soil_Dirt_Dry"
    },
    {
      "x": -4,
      "y": 6,
      "z": 1,
      "name": "Wood_Drywood_Fence",
      "rotation": 2
    },
    {
      "x": -4,
      "y": 0,
      "z": 2,
      "name": "Rock_Sandstone_Cobble"
    },
    {
      "x": -4,
      "y": 1,
      "z": 2,
      "name": "Rock_Sandstone_Cobble"
    },
    {
      "x": -4,
      "y": 2,
      "z": 2,
      "name": "Rock_Sandstone_Cobble"
    },
    {
      "x": -4,
      "y": 3,
      "z": 2,
      "name": "Rock_Sandstone_Cobble"
    },
    {
      "x": -4,
      "y": 4,
      "z": 2,
      "name": "Rock_Sandstone_Cobble"
    },
    {
      "x": -4,
      "y": 5,
      "z": 2,
      "name": "Soil_Mud_Dry"
    },
    {
      "x": -4,
      "y": 9,
      "z": 2,
      "name": "Wood_Drywood_Beam",
      "rotation": 5
    },
    {
      "x": -4,
      "y": 10,
      "z": 2,
      "name": "Wood_Drywood_Roof_Flat",
      "rotation": 2
    },
    {
      "x": -4,
      "y": 0,
      "z": 3,
      "name": "Rock_Sandstone_Cobble"
    },
    {
      "x": -4,
      "y": 1,
      "z": 3,
      "name": "Rock_Sandstone_Cobble"
    },
    {
      "x": -4,
      "y": 2,
      "z": 3,
      "name": "Rock_Sandstone_Cobble"
    },
    {
      "x": -4,
      "y": 3,
      "z": 3,
      "name": "Rock_Sandstone_Cobble"
    },
    {
      "x": -4,
      "y": 4,
      "z": 3,
      "name": "Rock_Sandstone_Cobble"
    },
    {
      "x": -4,
      "y": 5,
      "z": 3,
      "name": "Soil_Mud_Dry"
    },
    {
      "x": -4,
      "y": 10,
      "z": 3,
      "name": "Wood_Drywood_Roof_Flat",
      "rotation": 2
    },
    {
      "x": -4,
      "y": 0,
      "z": 4,
      "name": "Rock_Sandstone_Cobble"
    },
    {
      "x": -4,
      "y": 1,
      "z": 4,
      "name": "Rock_Sandstone_Cobble"
    },
    {
      "x": -4,
      "y": 2,
      "z": 4,
      "name": "Rock_Sandstone_Cobble"
    },
    {
      "x": -4,
      "y": 3,
      "z": 4,
      "name": "Rock_Sandstone_Cobble"
    },
    {
      "x": -4,
      "y": 4,
      "z": 4,
      "name": "Rock_Sandstone_Cobble"
    },
    {
      "x": -4,
      "y": 5,
      "z": 4,
      "name": "Soil_Mud_Dry"
    },
    {
      "x": -4,
      "y": 10,
      "z": 4,
      "name": "Wood_Drywood_Roof_Flat",
      "rotation": 2
    },
    {
      "x": -4,
      "y": 11,
      "z": 4,
      "name": "Rock_Sandstone_Brick_Half",
      "rotation": 6
    },
    {
      "x": -4,
      "y": 0,
      "z": 5,
      "name": "Rock_Sandstone_Cobble"
    },
    {
      "x": -4,
      "y": 1,
      "z": 5,
      "name": "Rock_Sandstone_Cobble"
    },
    {
      "x": -4,
      "y": 2,
      "z": 5,
      "name": "Rock_Sandstone_Cobble"
    },
    {
      "x": -4,
      "y": 3,
      "z": 5,
      "name": "Rock_Sandstone_Cobble"
    },
    {
      "x": -4,
      "y": 4,
      "z": 5,
      "name": "Rock_Sandstone_Cobble"
    },
    {
      "x": -4,
      "y": 5,
      "z": 5,
      "name": "Rock_Sandstone_Cobble"
    },
    {
      "x": -4,
      "y": 6,
      "z": 5,
      "name": "*Furniture_Desert_Door_State_Definitions_CloseDoorOut"
    },
    {
      "x": -4,
      "y": 7,
      "z": 5,
      "name": "*Furniture_Desert_Door_State_Definitions_CloseDoorOut",
      "filler": 1024
    },
    {
      "x": -4,
      "y": 8,
      "z": 5,
      "name": "Rock_Sandstone_Brick"
    },
    {
      "x": -4,
      "y": 9,
      "z": 5,
      "name": "Rock_Sandstone_Cobble"
    },
    {
      "x": -4,
      "y": 10,
      "z": 5,
      "name": "Rock_Sandstone_Brick"
    },
    {
      "x": -4,
      "y": 11,
      "z": 5,
      "name": "Rock_Sandstone_White_Cobble"
    },
    {
      "x": -4,
      "y": 12,
      "z": 5,
      "name": "Rock_Sandstone_White_Cobble"
    },
    {
      "x": -4,
      "y": 13,
      "z": 5,
      "name": "Rock_Sandstone_White_Cobble"
    },
    {
      "x": -4,
      "y": 14,
      "z": 5,
      "name": "Rock_Sandstone_White_Cobble"
    },
    {
      "x": -4,
      "y": 15,
      "z": 5,
      "name": "Rock_Sandstone_Brick_Decorative"
    },
    {
      "x": -4,
      "y": 16,
      "z": 5,
      "name": "Rock_Sandstone_Brick_Smooth_Half"
    },
    {
      "x": -4,
      "y": 0,
      "z": 6,
      "name": "Rock_Sandstone_Cobble"
    },
    {
      "x": -4,
      "y": 1,
      "z": 6,
      "name": "Rock_Sandstone_Cobble"
    },
    {
      "x": -4,
      "y": 2,
      "z": 6,
      "name": "Rock_Sandstone_Cobble"
    },
    {
      "x": -4,
      "y": 3,
      "z": 6,
      "name": "Rock_Sandstone_Cobble"
    },
    {
      "x": -4,
      "y": 4,
      "z": 6,
      "name": "Rock_Sandstone_Cobble"
    },
    {
      "x": -4,
      "y": 5,
      "z": 6,
      "name": "Rock_Sandstone_Cobble"
    },
    {
      "x": -4,
      "y": 10,
      "z": 6,
      "name": "Wood_Drywood_Planks"
    },
    {
      "x": -4,
      "y": 11,
      "z": 6,
      "name": "Furniture_Ancient_Bed",
      "filler": 1
    },
    {
      "x": -4,
      "y": 12,
      "z": 6,
      "name": "Furniture_Ancient_Bed",
      "filler": 1025
    },
    {
      "x": -4,
      "y": 15,
      "z": 6,
      "name": "Wood_Dry_Trunk",
      "rotation": 5
    },
    {
      "x": -4,
      "y": 10,
      "z": 7,
      "name": "Wood_Drywood_Planks"
    },
    {
      "x": -4,
      "y": 11,
      "z": 7,
      "name": "Furniture_Ancient_Bed",
      "filler": 33
    },
    {
      "x": -4,
      "y": 12,
      "z": 7,
      "name": "Furniture_Ancient_Bed",
      "filler": 1057
    },
    {
      "x": -4,
      "y": 10,
      "z": 8,
      "name": "Wood_Drywood_Planks"
    },
    {
      "x": -4,
      "y": 11,
      "z": 8,
      "name": "Furniture_Ancient_Bed",
      "filler": 65
    },
    {
      "x": -4,
      "y": 12,
      "z": 8,
      "name": "Furniture_Ancient_Bed",
      "filler": 1089
    },
    {
      "x": -4,
      "y": 10,
      "z": 9,
      "name": "Wood_Drywood_Planks"
    },
    {
      "x": -4,
      "y": 10,
      "z": 10,
      "name": "Wood_Drywood_Planks"
    },
    {
      "x": -4,
      "y": 15,
      "z": 10,
      "name": "Wood_Dry_Trunk",
      "rotation": 5
    },
    {
      "x": -4,
      "y": 8,
      "z": 11,
      "name": "Rock_Sandstone_Brick_Half",
      "rotation": 7
    },
    {
      "x": -4,
      "y": 9,
      "z": 11,
      "name": "Rock_Sandstone_Brick"
    },
    {
      "x": -4,
      "y": 10,
      "z": 11,
      "name": "Rock_Sandstone_Cobble"
    },
    {
      "x": -4,
      "y": 11,
      "z": 11,
      "name": "Rock_Sandstone_White_Cobble"
    },
    {
      "x": -4,
      "y": 12,
      "z": 11,
      "name": "Rock_Sandstone_White_Cobble"
    },
    {
      "x": -4,
      "y": 13,
      "z": 11,
      "name": "Rock_Sandstone_White_Cobble"
    },
    {
      "x": -4,
      "y": 14,
      "z": 11,
      "name": "Rock_Sandstone_White_Cobble"
    },
    {
      "x": -4,
      "y": 15,
      "z": 11,
      "name": "Rock_Sandstone_Brick_Decorative"
    },
    {
      "x": -4,
      "y": 16,
      "z": 11,
      "name": "Rock_Sandstone_Brick_Smooth_Half"
    },
    {
      "x": -4,
      "y": 11,
      "z": 12,
      "name": "Rock_Sandstone_Brick_Half",
      "rotation": 4
    },
    {
      "x": -3,
      "y": 0,
      "z": -10,
      "name": "Soil_Dirt_Dry"
    },
    {
      "x": -3,
      "y": 1,
      "z": -10,
      "name": "Soil_Dirt_Dry"
    },
    {
      "x": -3,
      "y": 2,
      "z": -10,
      "name": "Soil_Dirt_Dry"
    },
    {
      "x": -3,
      "y": 3,
      "z": -10,
      "name": "Soil_Dirt_Dry"
    },
    {
      "x": -3,
      "y": 4,
      "z": -10,
      "name": "Soil_Dirt_Dry"
    },
    {
      "x": -3,
      "y": 5,
      "z": -10,
      "name": "Soil_Dirt_Dry"
    },
    {
      "x": -3,
      "y": 6,
      "z": -10,
      "name": "Plant_Grass_Arid"
    },
    {
      "x": -3,
      "y": 0,
      "z": -9,
      "name": "Soil_Dirt_Dry"
    },
    {
      "x": -3,
      "y": 1,
      "z": -9,
      "name": "Soil_Dirt_Dry"
    },
    {
      "x": -3,
      "y": 2,
      "z": -9,
      "name": "Soil_Dirt_Dry"
    },
    {
      "x": -3,
      "y": 3,
      "z": -9,
      "name": "Soil_Dirt_Dry"
    },
    {
      "x": -3,
      "y": 4,
      "z": -9,
      "name": "Soil_Dirt_Dry"
    },
    {
      "x": -3,
      "y": 5,
      "z": -9,
      "name": "Soil_Dirt_Dry"
    },
    {
      "x": -3,
      "y": 6,
      "z": -9,
      "name": "Plant_Bush_Arid"
    },
    {
      "x": -3,
      "y": 0,
      "z": -8,
      "name": "Soil_Dirt_Dry"
    },
    {
      "x": -3,
      "y": 1,
      "z": -8,
      "name": "Soil_Dirt_Dry"
    },
    {
      "x": -3,
      "y": 2,
      "z": -8,
      "name": "Soil_Dirt_Dry"
    },
    {
      "x": -3,
      "y": 3,
      "z": -8,
      "name": "Soil_Dirt_Dry"
    },
    {
      "x": -3,
      "y": 4,
      "z": -8,
      "name": "Soil_Dirt_Dry"
    },
    {
      "x": -3,
      "y": 5,
      "z": -8,
      "name": "Soil_Dirt_Dry"
    },
    {
      "x": -3,
      "y": 0,
      "z": -7,
      "name": "Soil_Dirt_Dry"
    },
    {
      "x": -3,
      "y": 1,
      "z": -7,
      "name": "Soil_Dirt_Dry"
    },
    {
      "x": -3,
      "y": 2,
      "z": -7,
      "name": "Soil_Dirt_Dry"
    },
    {
      "x": -3,
      "y": 3,
      "z": -7,
      "name": "Soil_Dirt_Dry"
    },
    {
      "x": -3,
      "y": 4,
      "z": -7,
      "name": "Soil_Dirt_Dry"
    },
    {
      "x": -3,
      "y": 5,
      "z": -7,
      "name": "Soil_Dirt_Dry"
    },
    {
      "x": -3,
      "y": 0,
      "z": -6,
      "name": "Soil_Dirt_Dry"
    },
    {
      "x": -3,
      "y": 1,
      "z": -6,
      "name": "Soil_Dirt_Dry"
    },
    {
      "x": -3,
      "y": 2,
      "z": -6,
      "name": "Soil_Dirt_Dry"
    },
    {
      "x": -3,
      "y": 3,
      "z": -6,
      "name": "Soil_Dirt_Dry"
    },
    {
      "x": -3,
      "y": 4,
      "z": -6,
      "name": "Soil_Dirt_Dry"
    },
    {
      "x": -3,
      "y": 5,
      "z": -6,
      "name": "Soil_Dirt_Dry"
    },
    {
      "x": -3,
      "y": 11,
      "z": -6,
      "name": "Cloth_Roof_Green_Flap",
      "rotation": 2
    },
    {
      "x": -3,
      "y": 0,
      "z": -5,
      "name": "Soil_Dirt_Dry"
    },
    {
      "x": -3,
      "y": 1,
      "z": -5,
      "name": "Soil_Dirt_Dry"
    },
    {
      "x": -3,
      "y": 2,
      "z": -5,
      "name": "Soil_Dirt_Dry"
    },
    {
      "x": -3,
      "y": 3,
      "z": -5,
      "name": "Soil_Dirt_Dry"
    },
    {
      "x": -3,
      "y": 4,
      "z": -5,
      "name": "Soil_Dirt_Dry"
    },
    {
      "x": -3,
      "y": 5,
      "z": -5,
      "name": "Soil_Dirt_Dry"
    },
    {
      "x": -3,
      "y": 9,
      "z": -5,
      "name": "Wood_Drywood_Beam",
      "rotation": 5
    },
    {
      "x": -3,
      "y": 11,
      "z": -5,
      "name": "Wood_Dry_Trunk",
      "rotation": 5
    },
    {
      "x": -3,
      "y": 12,
      "z": -5,
      "name": "Cloth_Roof_Green_Flat"
    },
    {
      "x": -3,
      "y": 0,
      "z": -4,
      "name": "Soil_Dirt_Dry"
    },
    {
      "x": -3,
      "y": 1,
      "z": -4,
      "name": "Soil_Dirt_Dry"
    },
    {
      "x": -3,
      "y": 2,
      "z": -4,
      "name": "Soil_Dirt_Dry"
    },
    {
      "x": -3,
      "y": 3,
      "z": -4,
      "name": "Soil_Dirt_Dry"
    },
    {
      "x": -3,
      "y": 4,
      "z": -4,
      "name": "Soil_Dirt_Dry"
    },
    {
      "x": -3,
      "y": 5,
      "z": -4,
      "name": "Soil_Dirt_Dry"
    },
    {
      "x": -3,
      "y": 11,
      "z": -4,
      "name": "Wood_Dry_Branch_Long",
      "rotation": 4
    },
    {
      "x": -3,
      "y": 12,
      "z": -4,
      "name": "Cloth_Roof_Green_Flat"
    },
    {
      "x": -3,
      "y": 0,
      "z": -3,
      "name": "Soil_Dirt_Dry"
    },
    {
      "x": -3,
      "y": 1,
      "z": -3,
      "name": "Soil_Dirt_Dry"
    },
    {
      "x": -3,
      "y": 2,
      "z": -3,
      "name": "Soil_Dirt_Dry"
    },
    {
      "x": -3,
      "y": 3,
      "z": -3,
      "name": "Soil_Dirt_Dry"
    },
    {
      "x": -3,
      "y": 4,
      "z": -3,
      "name": "Soil_Dirt_Dry"
    },
    {
      "x": -3,
      "y": 5,
      "z": -3,
      "name": "Soil_Dirt_Dry"
    },
    {
      "x": -3,
      "y": 11,
      "z": -3,
      "name": "Wood_Dry_Branch_Long",
      "rotation": 4
    },
    {
      "x": -3,
      "y": 12,
      "z": -3,
      "name": "Cloth_Roof_Green_Flat"
    },
    {
      "x": -3,
      "y": 0,
      "z": -2,
      "name": "Soil_Dirt_Dry"
    },
    {
      "x": -3,
      "y": 1,
      "z": -2,
      "name": "Soil_Dirt_Dry"
    },
    {
      "x": -3,
      "y": 2,
      "z": -2,
      "name": "Soil_Dirt_Dry"
    },
    {
      "x": -3,
      "y": 3,
      "z": -2,
      "name": "Soil_Dirt_Dry"
    },
    {
      "x": -3,
      "y": 4,
      "z": -2,
      "name": "Soil_Dirt_Dry"
    },
    {
      "x": -3,
      "y": 5,
      "z": -2,
      "name": "Soil_Dirt_Dry"
    },
    {
      "x": -3,
      "y": 11,
      "z": -2,
      "name": "Wood_Dry_Trunk",
      "rotation": 5
    },
    {
      "x": -3,
      "y": 12,
      "z": -2,
      "name": "Cloth_Roof_Green_Flat"
    },
    {
      "x": -3,
      "y": 0,
      "z": -1,
      "name": "Soil_Dirt_Dry"
    },
    {
      "x": -3,
      "y": 1,
      "z": -1,
      "name": "Soil_Dirt_Dry"
    },
    {
      "x": -3,
      "y": 2,
      "z": -1,
      "name": "Soil_Dirt_Dry"
    },
    {
      "x": -3,
      "y": 3,
      "z": -1,
      "name": "Soil_Dirt_Dry"
    },
    {
      "x": -3,
      "y": 4,
      "z": -1,
      "name": "Soil_Dirt_Dry"
    },
    {
      "x": -3,
      "y": 5,
      "z": -1,
      "name": "Soil_Dirt_Dry"
    },
    {
      "x": -3,
      "y": 11,
      "z": -1,
      "name": "Cloth_Roof_Green_Flap"
    },
    {
      "x": -3,
      "y": 0,
      "z": 0,
      "name": "Soil_Dirt_Dry"
    },
    {
      "x": -3,
      "y": 1,
      "z": 0,
      "name": "Soil_Dirt_Dry"
    },
    {
      "x": -3,
      "y": 2,
      "z": 0,
      "name": "Soil_Dirt_Dry"
    },
    {
      "x": -3,
      "y": 3,
      "z": 0,
      "name": "Soil_Dirt_Dry"
    },
    {
      "x": -3,
      "y": 4,
      "z": 0,
      "name": "Soil_Dirt_Dry"
    },
    {
      "x": -3,
      "y": 5,
      "z": 0,
      "name": "Soil_Dirt_Dry"
    },
    {
      "x": -3,
      "y": 0,
      "z": 1,
      "name": "Soil_Dirt_Dry"
    },
    {
      "x": -3,
      "y": 1,
      "z": 1,
      "name": "Soil_Dirt_Dry"
    },
    {
      "x": -3,
      "y": 2,
      "z": 1,
      "name": "Soil_Dirt_Dry"
    },
    {
      "x": -3,
      "y": 3,
      "z": 1,
      "name": "Soil_Dirt_Dry"
    },
    {
      "x": -3,
      "y": 4,
      "z": 1,
      "name": "Soil_Dirt_Dry"
    },
    {
      "x": -3,
      "y": 5,
      "z": 1,
      "name": "Soil_Dirt_Dry"
    },
    {
      "x": -3,
      "y": 6,
      "z": 1,
      "name": "Wood_Drywood_Beam"
    },
    {
      "x": -3,
      "y": 0,
      "z": 2,
      "name": "Rock_Sandstone_Cobble"
    },
    {
      "x": -3,
      "y": 1,
      "z": 2,
      "name": "Rock_Sandstone_Cobble"
    },
    {
      "x": -3,
      "y": 2,
      "z": 2,
      "name": "Rock_Sandstone_Cobble"
    },
    {
      "x": -3,
      "y": 3,
      "z": 2,
      "name": "Rock_Sandstone_Cobble"
    },
    {
      "x": -3,
      "y": 4,
      "z": 2,
      "name": "Rock_Sandstone_Cobble"
    },
    {
      "x": -3,
      "y": 5,
      "z": 2,
      "name": "Soil_Mud_Dry"
    },
    {
      "x": -3,
      "y": 9,
      "z": 2,
      "name": "Wood_Drywood_Beam",
      "rotation": 5
    },
    {
      "x": -3,
      "y": 10,
      "z": 2,
      "name": "Wood_Drywood_Roof_Flat",
      "rotation": 2
    },
    {
      "x": -3,
      "y": 0,
      "z": 3,
      "name": "Rock_Sandstone_Cobble"
    },
    {
      "x": -3,
      "y": 1,
      "z": 3,
      "name": "Rock_Sandstone_Cobble"
    },
    {
      "x": -3,
      "y": 2,
      "z": 3,
      "name": "Rock_Sandstone_Cobble"
    },
    {
      "x": -3,
      "y": 3,
      "z": 3,
      "name": "Rock_Sandstone_Cobble"
    },
    {
      "x": -3,
      "y": 4,
      "z": 3,
      "name": "Rock_Sandstone_Cobble"
    },
    {
      "x": -3,
      "y": 5,
      "z": 3,
      "name": "Soil_Mud_Dry"
    },
    {
      "x": -3,
      "y": 10,
      "z": 3,
      "name": "Wood_Drywood_Roof_Flat",
      "rotation": 2
    },
    {
      "x": -3,
      "y": 0,
      "z": 4,
      "name": "Rock_Sandstone_Cobble"
    },
    {
      "x": -3,
      "y": 1,
      "z": 4,
      "name": "Rock_Sandstone_Cobble"
    },
    {
      "x": -3,
      "y": 2,
      "z": 4,
      "name": "Rock_Sandstone_Cobble"
    },
    {
      "x": -3,
      "y": 3,
      "z": 4,
      "name": "Rock_Sandstone_Cobble"
    },
    {
      "x": -3,
      "y": 4,
      "z": 4,
      "name": "Rock_Sandstone_Cobble"
    },
    {
      "x": -3,
      "y": 5,
      "z": 4,
      "name": "Soil_Mud_Dry"
    },
    {
      "x": -3,
      "y": 9,
      "z": 4,
      "name": "Wood_Drywood_Beam",
      "rotation": 5
    },
    {
      "x": -3,
      "y": 10,
      "z": 4,
      "name": "Wood_Drywood_Roof_Flat",
      "rotation": 2
    },
    {
      "x": -3,
      "y": 11,
      "z": 4,
      "name": "Rock_Sandstone_Brick_Half",
      "rotation": 6
    },
    {
      "x": -3,
      "y": 15,
      "z": 4,
      "name": "Rock_Sandstone_Cobble_Beam",
      "rotation": 4
    },
    {
      "x": -3,
      "y": 0,
      "z": 5,
      "name": "Rock_Sandstone_Cobble"
    },
    {
      "x": -3,
      "y": 1,
      "z": 5,
      "name": "Rock_Sandstone_Cobble"
    },
    {
      "x": -3,
      "y": 2,
      "z": 5,
      "name": "Rock_Sandstone_Cobble"
    },
    {
      "x": -3,
      "y": 3,
      "z": 5,
      "name": "Rock_Sandstone_Cobble"
    },
    {
      "x": -3,
      "y": 4,
      "z": 5,
      "name": "Rock_Sandstone_Cobble"
    },
    {
      "x": -3,
      "y": 5,
      "z": 5,
      "name": "Rock_Sandstone_Cobble"
    },
    {
      "x": -3,
      "y": 6,
      "z": 5,
      "name": "Rock_Sandstone_Brick"
    },
    {
      "x": -3,
      "y": 7,
      "z": 5,
      "name": "Rock_Sandstone_Brick"
    },
    {
      "x": -3,
      "y": 8,
      "z": 5,
      "name": "Rock_Sandstone_Brick"
    },
    {
      "x": -3,
      "y": 9,
      "z": 5,
      "name": "Rock_Sandstone_Cobble"
    },
    {
      "x": -3,
      "y": 10,
      "z": 5,
      "name": "Rock_Sandstone_Brick"
    },
    {
      "x": -3,
      "y": 11,
      "z": 5,
      "name": "Rock_Sandstone_White_Cobble"
    },
    {
      "x": -3,
      "y": 12,
      "z": 5,
      "name": "Rock_Sandstone_White_Cobble"
    },
    {
      "x": -3,
      "y": 13,
      "z": 5,
      "name": "Rock_Sandstone_White_Cobble"
    },
    {
      "x": -3,
      "y": 14,
      "z": 5,
      "name": "Rock_Sandstone_White_Cobble"
    },
    {
      "x": -3,
      "y": 15,
      "z": 5,
      "name": "Rock_Sandstone_Brick_Decorative"
    },
    {
      "x": -3,
      "y": 16,
      "z": 5,
      "name": "Rock_Sandstone_Brick_Smooth_Half"
    },
    {
      "x": -3,
      "y": 0,
      "z": 6,
      "name": "Rock_Sandstone_Cobble"
    },
    {
      "x": -3,
      "y": 1,
      "z": 6,
      "name": "Rock_Sandstone_Cobble"
    },
    {
      "x": -3,
      "y": 2,
      "z": 6,
      "name": "Rock_Sandstone_Cobble"
    },
    {
      "x": -3,
      "y": 3,
      "z": 6,
      "name": "Rock_Sandstone_Cobble"
    },
    {
      "x": -3,
      "y": 4,
      "z": 6,
      "name": "Rock_Sandstone_Cobble"
    },
    {
      "x": -3,
      "y": 5,
      "z": 6,
      "name": "Rock_Sandstone_Cobble"
    },
    {
      "x": -3,
      "y": 10,
      "z": 6,
      "name": "Wood_Drywood_Planks"
    },
    {
      "x": -3,
      "y": 12,
      "z": 6,
      "name": "Furniture_Desert_Shelf"
    },
    {
      "x": -3,
      "y": 13,
      "z": 6,
      "name": "Furniture_Feran_Torch"
    },
    {
      "x": -3,
      "y": 15,
      "z": 6,
      "name": "Wood_Dry_Trunk",
      "rotation": 4
    },
    {
      "x": -3,
      "y": 10,
      "z": 7,
      "name": "Wood_Drywood_Planks"
    },
    {
      "x": -3,
      "y": 15,
      "z": 7,
      "name": "Wood_Dry_Trunk",
      "rotation": 4
    },
    {
      "x": -3,
      "y": 10,
      "z": 8,
      "name": "Wood_Drywood_Planks"
    },
    {
      "x": -3,
      "y": 15,
      "z": 8,
      "name": "Wood_Dry_Trunk",
      "rotation": 4
    },
    {
      "x": -3,
      "y": 10,
      "z": 9,
      "name": "Wood_Drywood_Planks"
    },
    {
      "x": -3,
      "y": 15,
      "z": 9,
      "name": "Wood_Dry_Trunk",
      "rotation": 4
    },
    {
      "x": -3,
      "y": 10,
      "z": 10,
      "name": "Wood_Drywood_Planks"
    },
    {
      "x": -3,
      "y": 11,
      "z": 10,
      "name": "Furniture_Temple_Wind_Pot"
    },
    {
      "x": -3,
      "y": 12,
      "z": 10,
      "name": "Furniture_Temple_Wind_Pot",
      "filler": 1024
    },
    {
      "x": -3,
      "y": 15,
      "z": 10,
      "name": "Wood_Dry_Trunk",
      "rotation": 4
    },
    {
      "x": -3,
      "y": 0,
      "z": 11,
      "name": "Rock_Sandstone_Cobble"
    },
    {
      "x": -3,
      "y": 1,
      "z": 11,
      "name": "Rock_Sandstone_Cobble"
    },
    {
      "x": -3,
      "y": 2,
      "z": 11,
      "name": "Rock_Sandstone_Cobble"
    },
    {
      "x": -3,
      "y": 3,
      "z": 11,
      "name": "Rock_Sandstone_Cobble"
    },
    {
      "x": -3,
      "y": 4,
      "z": 11,
      "name": "Rock_Sandstone_Cobble"
    },
    {
      "x": -3,
      "y": 5,
      "z": 11,
      "name": "Rock_Sandstone_Cobble"
    },
    {
      "x": -3,
      "y": 6,
      "z": 11,
      "name": "Rock_Sandstone_Brick"
    },
    {
      "x": -3,
      "y": 7,
      "z": 11,
      "name": "Rock_Sandstone_Brick"
    },
    {
      "x": -3,
      "y": 8,
      "z": 11,
      "name": "Rock_Sandstone_Brick"
    },
    {
      "x": -3,
      "y": 9,
      "z": 11,
      "name": "Rock_Sandstone_Brick"
    },
    {
      "x": -3,
      "y": 10,
      "z": 11,
      "name": "Rock_Sandstone_Cobble"
    },
    {
      "x": -3,
      "y": 11,
      "z": 11,
      "name": "Rock_Sandstone_White_Cobble"
    },
    {
      "x": -3,
      "y": 12,
      "z": 11,
      "name": "Rock_Sandstone_White_Cobble"
    },
    {
      "x": -3,
      "y": 13,
      "z": 11,
      "name": "Rock_Sandstone_White_Cobble"
    },
    {
      "x": -3,
      "y": 14,
      "z": 11,
      "name": "Rock_Sandstone_White_Cobble"
    },
    {
      "x": -3,
      "y": 15,
      "z": 11,
      "name": "Rock_Sandstone_Brick_Decorative"
    },
    {
      "x": -3,
      "y": 16,
      "z": 11,
      "name": "Rock_Sandstone_Brick_Smooth_Half"
    },
    {
      "x": -3,
      "y": 11,
      "z": 12,
      "name": "Rock_Sandstone_Brick_Half",
      "rotation": 4
    },
    {
      "x": -3,
      "y": 15,
      "z": 12,
      "name": "Rock_Sandstone_Cobble_Beam",
      "rotation": 4
    },
    {
      "x": -2,
      "y": 0,
      "z": -10,
      "name": "Soil_Dirt_Dry"
    },
    {
      "x": -2,
      "y": 1,
      "z": -10,
      "name": "Soil_Dirt_Dry"
    },
    {
      "x": -2,
      "y": 2,
      "z": -10,
      "name": "Soil_Dirt_Dry"
    },
    {
      "x": -2,
      "y": 3,
      "z": -10,
      "name": "Soil_Dirt_Dry"
    },
    {
      "x": -2,
      "y": 4,
      "z": -10,
      "name": "Soil_Dirt_Dry"
    },
    {
      "x": -2,
      "y": 5,
      "z": -10,
      "name": "Soil_Dirt_Dry"
    },
    {
      "x": -2,
      "y": 0,
      "z": -9,
      "name": "Soil_Dirt_Dry"
    },
    {
      "x": -2,
      "y": 1,
      "z": -9,
      "name": "Soil_Dirt_Dry"
    },
    {
      "x": -2,
      "y": 2,
      "z": -9,
      "name": "Soil_Dirt_Dry"
    },
    {
      "x": -2,
      "y": 3,
      "z": -9,
      "name": "Soil_Dirt_Dry"
    },
    {
      "x": -2,
      "y": 4,
      "z": -9,
      "name": "Soil_Dirt_Dry"
    },
    {
      "x": -2,
      "y": 5,
      "z": -9,
      "name": "Soil_Dirt_Dry"
    },
    {
      "x": -2,
      "y": 0,
      "z": -8,
      "name": "Soil_Dirt_Dry"
    },
    {
      "x": -2,
      "y": 1,
      "z": -8,
      "name": "Soil_Dirt_Dry"
    },
    {
      "x": -2,
      "y": 2,
      "z": -8,
      "name": "Soil_Dirt_Dry"
    },
    {
      "x": -2,
      "y": 3,
      "z": -8,
      "name": "Soil_Dirt_Dry"
    },
    {
      "x": -2,
      "y": 4,
      "z": -8,
      "name": "Soil_Dirt_Dry"
    },
    {
      "x": -2,
      "y": 5,
      "z": -8,
      "name": "Soil_Dirt_Dry"
    },
    {
      "x": -2,
      "y": 0,
      "z": -7,
      "name": "Soil_Dirt_Dry"
    },
    {
      "x": -2,
      "y": 1,
      "z": -7,
      "name": "Soil_Dirt_Dry"
    },
    {
      "x": -2,
      "y": 2,
      "z": -7,
      "name": "Soil_Dirt_Dry"
    },
    {
      "x": -2,
      "y": 3,
      "z": -7,
      "name": "Soil_Dirt_Dry"
    },
    {
      "x": -2,
      "y": 4,
      "z": -7,
      "name": "Soil_Dirt_Dry"
    },
    {
      "x": -2,
      "y": 5,
      "z": -7,
      "name": "Soil_Dirt_Dry"
    },
    {
      "x": -2,
      "y": 0,
      "z": -6,
      "name": "Soil_Dirt_Dry"
    },
    {
      "x": -2,
      "y": 1,
      "z": -6,
      "name": "Soil_Dirt_Dry"
    },
    {
      "x": -2,
      "y": 2,
      "z": -6,
      "name": "Soil_Dirt_Dry"
    },
    {
      "x": -2,
      "y": 3,
      "z": -6,
      "name": "Soil_Dirt_Dry"
    },
    {
      "x": -2,
      "y": 4,
      "z": -6,
      "name": "Soil_Dirt_Dry"
    },
    {
      "x": -2,
      "y": 5,
      "z": -6,
      "name": "Soil_Dirt_Dry"
    },
    {
      "x": -2,
      "y": 11,
      "z": -6,
      "name": "Cloth_Roof_Green_Flap",
      "rotation": 2
    },
    {
      "x": -2,
      "y": 0,
      "z": -5,
      "name": "Soil_Dirt_Dry"
    },
    {
      "x": -2,
      "y": 1,
      "z": -5,
      "name": "Soil_Dirt_Dry"
    },
    {
      "x": -2,
      "y": 2,
      "z": -5,
      "name": "Soil_Dirt_Dry"
    },
    {
      "x": -2,
      "y": 3,
      "z": -5,
      "name": "Soil_Dirt_Dry"
    },
    {
      "x": -2,
      "y": 4,
      "z": -5,
      "name": "Soil_Dirt_Dry"
    },
    {
      "x": -2,
      "y": 5,
      "z": -5,
      "name": "Soil_Dirt_Dry"
    },
    {
      "x": -2,
      "y": 6,
      "z": -5,
      "name": "Plant_Grass_Arid"
    },
    {
      "x": -2,
      "y": 9,
      "z": -5,
      "name": "Wood_Drywood_Beam",
      "rotation": 5
    },
    {
      "x": -2,
      "y": 11,
      "z": -5,
      "name": "Wood_Dry_Trunk",
      "rotation": 5
    },
    {
      "x": -2,
      "y": 12,
      "z": -5,
      "name": "Cloth_Roof_Green_Flat"
    },
    {
      "x": -2,
      "y": 0,
      "z": -4,
      "name": "Soil_Dirt_Dry"
    },
    {
      "x": -2,
      "y": 1,
      "z": -4,
      "name": "Soil_Dirt_Dry"
    },
    {
      "x": -2,
      "y": 2,
      "z": -4,
      "name": "Soil_Dirt_Dry"
    },
    {
      "x": -2,
      "y": 3,
      "z": -4,
      "name": "Soil_Dirt_Dry"
    },
    {
      "x": -2,
      "y": 4,
      "z": -4,
      "name": "Soil_Dirt_Dry"
    },
    {
      "x": -2,
      "y": 5,
      "z": -4,
      "name": "Soil_Dirt_Dry"
    },
    {
      "x": -2,
      "y": 12,
      "z": -4,
      "name": "Cloth_Roof_Green_Flat"
    },
    {
      "x": -2,
      "y": 0,
      "z": -3,
      "name": "Soil_Dirt_Dry"
    },
    {
      "x": -2,
      "y": 1,
      "z": -3,
      "name": "Soil_Dirt_Dry"
    },
    {
      "x": -2,
      "y": 2,
      "z": -3,
      "name": "Soil_Dirt_Dry"
    },
    {
      "x": -2,
      "y": 3,
      "z": -3,
      "name": "Soil_Dirt_Dry"
    },
    {
      "x": -2,
      "y": 4,
      "z": -3,
      "name": "Soil_Dirt_Dry"
    },
    {
      "x": -2,
      "y": 5,
      "z": -3,
      "name": "Soil_Dirt_Dry"
    },
    {
      "x": -2,
      "y": 0,
      "z": -2,
      "name": "Soil_Dirt_Dry"
    },
    {
      "x": -2,
      "y": 1,
      "z": -2,
      "name": "Soil_Dirt_Dry"
    },
    {
      "x": -2,
      "y": 2,
      "z": -2,
      "name": "Soil_Dirt_Dry"
    },
    {
      "x": -2,
      "y": 3,
      "z": -2,
      "name": "Soil_Dirt_Dry"
    },
    {
      "x": -2,
      "y": 4,
      "z": -2,
      "name": "Soil_Dirt_Dry"
    },
    {
      "x": -2,
      "y": 5,
      "z": -2,
      "name": "Soil_Dirt_Dry"
    },
    {
      "x": -2,
      "y": 11,
      "z": -2,
      "name": "Wood_Dry_Trunk",
      "rotation": 5
    },
    {
      "x": -2,
      "y": 0,
      "z": -1,
      "name": "Soil_Dirt_Dry"
    },
    {
      "x": -2,
      "y": 1,
      "z": -1,
      "name": "Soil_Dirt_Dry"
    },
    {
      "x": -2,
      "y": 2,
      "z": -1,
      "name": "Soil_Dirt_Dry"
    },
    {
      "x": -2,
      "y": 3,
      "z": -1,
      "name": "Soil_Dirt_Dry"
    },
    {
      "x": -2,
      "y": 4,
      "z": -1,
      "name": "Soil_Dirt_Dry"
    },
    {
      "x": -2,
      "y": 5,
      "z": -1,
      "name": "Soil_Dirt_Dry"
    },
    {
      "x": -2,
      "y": 0,
      "z": 0,
      "name": "Soil_Dirt_Dry"
    },
    {
      "x": -2,
      "y": 1,
      "z": 0,
      "name": "Soil_Dirt_Dry"
    },
    {
