{
  "version": 8,
  "blockIdVersion": 11,
  "anchorX": 0,
  "anchorY": 0,
  "anchorZ": 0,
  "blocks": [
    {
      "x": -5,
      "y": -2,
      "z": 0,
      "name": "Rock_Sandstone_Cobble"
    },
    {
      "x": -5,
      "y": -1,
      "z": 0,
      "name": "Rock_Sandstone_Cobble"
    },
    {
      "x": -5,
      "y": 0,
      "z": 0,
      "name": "Rock_Sandstone_Cobble"
    },
    {
      "x": -5,
      "y": 1,
      "z": 0,
      "name": "Rock_Sandstone_Cobble_Stairs",
      "rotation": 3
    },
    {
      "x": -5,
      "y": -2,
      "z": 1,
      "name": "Rock_Sandstone_Cobble"
    },
    {
      "x": -5,
      "y": -1,
      "z": 1,
      "name": "Rock_Sandstone_Cobble"
    },
    {
      "x": -5,
      "y": 0,
      "z": 1,
      "name": "Rock_Sandstone_Cobble"
    },
    {
      "x": -5,
      "y": 1,
      "z": 1,
      "name": "Rock_Sandstone_Cobble_Stairs",
      "rotation": 3
    },
    {
      "x": -5,
      "y": -2,
      "z": 2,
      "name": "Rock_Sandstone_Cobble"
    },
    {
      "x": -5,
      "y": -1,
      "z": 2,
      "name": "Rock_Sandstone_Cobble"
    },
    {
      "x": -5,
      "y": 0,
      "z": 2,
      "name": "Rock_Sandstone_Cobble"
    },
    {
      "x": -5,
      "y": 1,
      "z": 2,
      "name": "Rock_Sandstone_Cobble_Stairs",
      "rotation": 3
    },
    {
      "x": -4,
      "y": -3,
      "z": 0,
      "name": "Rock_Sandstone_Cobble"
    },
    {
      "x": -4,
      "y": -2,
      "z": 0,
      "name": "Rock_Sandstone_Cobble"
    },
    {
      "x": -4,
      "y": -1,
      "z": 0,
      "name": "Rock_Sandstone_Cobble"
    },
    {
      "x": -4,
      "y": 0,
      "z": 0,
      "name": "Rock_Sandstone_Cobble"
    },
    {
      "x": -4,
      "y": 1,
      "z": 0,
      "name": "Rock_Sandstone_Cobble"
    },
    {
      "x": -4,
      "y": 2,
      "z": 0,
      "name": "Rock_Sandstone_Cobble_Stairs",
      "rotation": 3
    },
    {
      "x": -4,
      "y": -3,
      "z": 1,
      "name": "Rock_Sandstone_Cobble"
    },
    {
      "x": -4,
      "y": -2,
      "z": 1,
      "name": "Rock_Sandstone_Cobble"
    },
    {
      "x": -4,
      "y": -1,
      "z": 1,
      "name": "Rock_Sandstone_Cobble"
    },
    {
      "x": -4,
      "y": 0,
      "z": 1,
      "name": "Rock_Sandstone_Cobble"
    },
    {
      "x": -4,
      "y": 1,
      "z": 1,
      "name": "Rock_Sandstone_Cobble"
    },
    {
      "x": -4,
      "y": 2,
      "z": 1,
      "name": "Rock_Sandstone_Cobble_Stairs",
      "rotation": 3
    },
    {
      "x": -4,
      "y": -3,
      "z": 2,
      "name": "Rock_Sandstone_Cobble"
    },
    {
      "x": -4,
      "y": -2,
      "z": 2,
      "name": "Rock_Sandstone_Cobble"
    },
    {
      "x": -4,
      "y": -1,
      "z": 2,
      "name": "Rock_Sandstone_Cobble"
    },
    {
      "x": -4,
      "y": 0,
      "z": 2,
      "name": "Rock_Sandstone_Cobble"
    },
    {
      "x": -4,
      "y": 1,
      "z": 2,
      "name": "Rock_Sandstone_Cobble"
    },
    {
      "x": -4,
      "y": 2,
      "z": 2,
      "name": "Rock_Sandstone_Cobble_Stairs",
      "rotation": 3
    },
    {
      "x": -3,
      "y": -4,
      "z": 0,
      "name": "Rock_Sandstone_Cobble"
    },
    {
      "x": -3,
      "y": -3,
      "z": 0,
      "name": "Rock_Sandstone_Cobble"
    },
    {
      "x": -3,
      "y": -2,
      "z": 0,
      "name": "Rock_Sandstone_Cobble"
    },
    {
      "x": -3,
      "y": -1,
      "z": 0,
      "name": "Rock_Sandstone_Cobble"
    },
    {
      "x": -3,
      "y": 0,
      "z": 0,
      "name": "Rock_Sandstone_Cobble"
    },
    {
      "x": -3,
      "y": 1,
      "z": 0,
      "name": "Rock_Sandstone_Cobble"
    },
    {
      "x": -3,
      "y": 2,
      "z": 0,
      "name": "Rock_Sandstone_Cobble"
    },
    {
      "x": -3,
      "y": 3,
      "z": 0,
      "name": "Rock_Sandstone_Cobble_Stairs",
      "rotation": 3
    },
    {
      "x": -3,
      "y": -4,
      "z": 1,
      "name": "Rock_Sandstone_Cobble"
    },
    {
      "x": -3,
      "y": -3,
      "z": 1,
      "name": "Rock_Sandstone_Cobble"
    },
    {
      "x": -3,
      "y": -2,
      "z": 1,
      "name": "Rock_Sandstone_Cobble"
    },
    {
      "x": -3,
      "y": -1,
      "z": 1,
      "name": "Rock_Sandstone_Cobble"
    },
    {
      "x": -3,
      "y": 0,
      "z": 1,
      "name": "Rock_Sandstone_Cobble"
    },
    {
      "x": -3,
      "y": 1,
      "z": 1,
      "name": "Rock_Sandstone_Cobble"
    },
    {
      "x": -3,
      "y": 2,
      "z": 1,
      "name": "Rock_Sandstone_Cobble"
    },
    {
      "x": -3,
      "y": 3,
      "z": 1,
      "name": "Rock_Sandstone_Cobble_Stairs",
      "rotation": 3
    },
    {
      "x": -3,
      "y": -4,
      "z": 2,
      "name": "Rock_Sandstone_Cobble"
    },
    {
      "x": -3,
      "y": -3,
      "z": 2,
      "name": "Rock_Sandstone_Cobble"
    },
    {
      "x": -3,
      "y": -2,
      "z": 2,
      "name": "Rock_Sandstone_Cobble"
    },
    {
      "x": -3,
      "y": -1,
      "z": 2,
      "name": "Rock_Sandstone_Cobble"
    },
    {
      "x": -3,
      "y": 0,
      "z": 2,
      "name": "Rock_Sandstone_Cobble"
    },
    {
      "x": -3,
      "y": 1,
      "z": 2,
      "name": "Rock_Sandstone_Cobble"
    },
    {
      "x": -3,
      "y": 2,
      "z": 2,
      "name": "Rock_Sandstone_Cobble"
    },
    {
      "x": -3,
      "y": 3,
      "z": 2,
      "name": "Rock_Sandstone_Cobble_Stairs",
      "rotation": 3
    },
    {
      "x": -2,
      "y": -4,
      "z": -2,
      "name": "Rock_Sandstone"
    },
    {
      "x": -2,
      "y": -3,
      "z": -2,
      "name": "Rock_Sandstone"
    },
    {
      "x": -2,
      "y": -2,
      "z": -2,
      "name": "Rock_Sandstone"
    },
    {
      "x": -2,
      "y": -1,
      "z": -2,
      "name": "Rock_Sandstone"
    },
    {
      "x": -2,
      "y": 0,
      "z": -2,
      "name": "Rock_Sandstone_Cobble"
    },
    {
      "x": -2,
      "y": 1,
      "z": -2,
      "name": "Rock_Sandstone_Cobble"
    },
    {
      "x": -2,
      "y": 2,
      "z": -2,
      "name": "Rock_Sandstone_Cobble"
    },
    {
      "x": -2,
      "y": 3,
      "z": -2,
      "name": "Rock_Sandstone_Cobble"
    },
    {
      "x": -2,
      "y": 4,
      "z": -2,
      "name": "Rock_Sandstone_Cobble"
    },
    {
      "x": -2,
      "y": 5,
      "z": -2,
      "name": "Rock_Sandstone_Cobble"
    },
    {
      "x": -2,
      "y": 6,
      "z": -2,
      "name": "Rock_Sandstone_Brick"
    },
    {
      "x": -2,
      "y": 7,
      "z": -2,
      "name": "Rock_Sandstone_Brick"
    },
    {
      "x": -2,
      "y": 8,
      "z": -2,
      "name": "Rock_Sandstone_Brick_Pillar_Base"
    },
    {
      "x": -2,
      "y": 9,
      "z": -2,
      "name": "Rock_Sandstone_Brick_Half"
    },
    {
      "x": -2,
      "y": -4,
      "z": -1,
      "name": "Rock_Sandstone"
    },
    {
      "x": -2,
      "y": -3,
      "z": -1,
      "name": "Rock_Sandstone"
    },
    {
      "x": -2,
      "y": -2,
      "z": -1,
      "name": "Rock_Sandstone"
    },
    {
      "x": -2,
      "y": -1,
      "z": -1,
      "name": "Rock_Sandstone"
    },
    {
      "x": -2,
      "y": 0,
      "z": -1,
      "name": "Rock_Sandstone"
    },
    {
      "x": -2,
      "y": 1,
      "z": -1,
      "name": "Rock_Sandstone_Cobble"
    },
    {
      "x": -2,
      "y": 2,
      "z": -1,
      "name": "Rock_Sandstone_Cobble"
    },
    {
      "x": -2,
      "y": 3,
      "z": -1,
      "name": "Rock_Sandstone_Cobble"
    },
    {
      "x": -2,
      "y": 4,
      "z": -1,
      "name": "Rock_Sandstone_Cobble"
    },
    {
      "x": -2,
      "y": 5,
      "z": -1,
      "name": "Rock_Sandstone_Brick"
    },
    {
      "x": -2,
      "y": 6,
      "z": -1,
      "name": "Rock_Sandstone_Brick"
    },
    {
      "x": -2,
      "y": 7,
      "z": -1,
      "name": "Rock_Sandstone_Brick_Half",
      "rotation": 4
    },
    {
      "x": -2,
      "y": -4,
      "z": 0,
      "name": "Rock_Sandstone_Cobble"
    },
    {
      "x": -2,
      "y": -3,
      "z": 0,
      "name": "Rock_Sandstone_Cobble"
    },
    {
      "x": -2,
      "y": -2,
      "z": 0,
      "name": "Rock_Sandstone_Cobble"
    },
    {
      "x": -2,
      "y": -1,
      "z": 0,
      "name": "Rock_Sandstone_Cobble"
    },
    {
      "x": -2,
      "y": 0,
      "z": 0,
      "name": "Rock_Sandstone_Cobble"
    },
    {
      "x": -2,
      "y": 1,
      "z": 0,
      "name": "Rock_Sandstone_Cobble"
    },
    {
      "x": -2,
      "y": 2,
      "z": 0,
      "name": "Rock_Sandstone_Cobble"
    },
    {
      "x": -2,
      "y": 3,
      "z": 0,
      "name": "Rock_Sandstone_Cobble"
    },
    {
      "x": -2,
      "y": 4,
      "z": 0,
      "name": "Wood_Drywood_Planks_Half",
      "rotation": 4
    },
    {
      "x": -2,
      "y": 5,
      "z": 0,
      "name": "Wood_Drywood_Planks_Half",
      "rotation": 4
    },
    {
      "x": -2,
      "y": 10,
      "z": 0,
      "name": "Rock_Sandstone_Cobble_Half",
      "rotation": 7
    },
    {
      "x": -2,
      "y": 11,
      "z": 0,
      "name": "Rock_Sandstone_Cobble_Half",
      "rotation": 7
    },
    {
      "x": -2,
      "y": 14,
      "z": 0,
      "name": "Rock_Sandstone_Brick_Smooth_Half",
      "rotation": 6
    },
    {
      "x": -2,
      "y": 15,
      "z": 0,
      "name": "Rock_Sandstone_Brick_Smooth_Half",
      "rotation": 6
    },
    {
      "x": -2,
      "y": -4,
      "z": 1,
      "name": "Rock_Sandstone_Cobble"
    },
    {
      "x": -2,
      "y": -3,
      "z": 1,
      "name": "Rock_Sandstone_Cobble"
    },
    {
      "x": -2,
      "y": -2,
      "z": 1,
      "name": "Rock_Sandstone_Cobble"
    },
    {
      "x": -2,
      "y": -1,
      "z": 1,
      "name": "Rock_Sandstone_Cobble"
    },
    {
      "x": -2,
      "y": 0,
      "z": 1,
      "name": "Rock_Sandstone_Cobble"
    },
    {
      "x": -2,
      "y": 1,
      "z": 1,
      "name": "Rock_Sandstone_Cobble"
    },
    {
      "x": -2,
      "y": 2,
      "z": 1,
      "name": "Rock_Sandstone_Cobble"
    },
    {
      "x": -2,
      "y": 3,
      "z": 1,
      "name": "Rock_Sandstone_Cobble"
    },
    {
      "x": -2,
      "y": 8,
      "z": 1,
      "name": "Rock_Sandstone_Brick_Half",
      "rotation": 8
    },
    {
      "x": -2,
      "y": 9,
      "z": 1,
      "name": "Rock_Sandstone_Brick"
    },
    {
      "x": -2,
      "y": 10,
      "z": 1,
      "name": "Rock_Sandstone_Cobble_Stairs",
      "rotation": 3
    },
    {
      "x": -2,
      "y": 11,
      "z": 1,
      "name": "Rock_Sandstone_Cobble_Half",
      "rotation": 7
    },
    {
      "x": -2,
      "y": 13,
      "z": 1,
      "name": "Rock_Sandstone_Brick_Smooth_Half",
      "rotation": 7
    },
    {
      "x": -2,
      "y": 16,
      "z": 1,
      "name": "Rock_Sandstone_Brick_Smooth_Half"
    },
    {
      "x": -2,
      "y": -4,
      "z": 2,
      "name": "Rock_Sandstone_Cobble"
    },
    {
      "x": -2,
      "y": -3,
      "z": 2,
      "name": "Rock_Sandstone_Cobble"
    },
    {
      "x": -2,
      "y": -2,
      "z": 2,
      "name": "Rock_Sandstone_Cobble"
    },
    {
      "x": -2,
      "y": -1,
      "z": 2,
      "name": "Rock_Sandstone_Cobble"
    },
    {
      "x": -2,
      "y": 0,
      "z": 2,
      "name": "Rock_Sandstone_Cobble"
    },
    {
      "x": -2,
      "y": 1,
      "z": 2,
      "name": "Rock_Sandstone_Cobble"
    },
    {
      "x": -2,
      "y": 2,
      "z": 2,
      "name": "Rock_Sandstone_Cobble"
    },
    {
      "x": -2,
      "y": 3,
      "z": 2,
      "name": "Rock_Sandstone_Cobble"
    },
    {
      "x": -2,
      "y": 4,
      "z": 2,
      "name": "Wood_Drywood_Planks_Half",
      "rotation": 6
    },
    {
      "x": -2,
      "y": 5,
      "z": 2,
      "name": "Wood_Drywood_Planks_Half",
      "rotation": 6
    },
    {
      "x": -2,
      "y": 6,
      "z": 2,
      "name": "Wood_Drywood_Stairs",
      "rotation": 8
    },
    {
      "x": -2,
      "y": 7,
      "z": 2,
      "name": "Rock_Sandstone_Brick"
    },
    {
      "x": -2,
      "y": 8,
      "z": 2,
      "name": "Rock_Sandstone_Brick_Pillar_Base"
    },
    {
      "x": -2,
      "y": 9,
      "z": 2,
      "name": "Rock_Sandstone_Brick"
    },
    {
      "x": -2,
      "y": 10,
      "z": 2,
      "name": "Rock_Sandstone_Cobble_Stairs",
      "rotation": 3
    },
    {
      "x": -2,
      "y": 11,
      "z": 2,
      "name": "Rock_Sandstone_Cobble_Half",
      "rotation": 7
    },
    {
      "x": -2,
      "y": 14,
      "z": 2,
      "name": "Rock_Sandstone_Brick_Smooth_Half",
      "rotation": 4
    },
    {
      "x": -2,
      "y": 15,
      "z": 2,
      "name": "Rock_Sandstone_Brick_Smooth_Half",
      "rotation": 4
    },
    {
      "x": -2,
      "y": -4,
      "z": 3,
      "name": "Rock_Sandstone"
    },
    {
      "x": -2,
      "y": -3,
      "z": 3,
      "name": "Rock_Sandstone"
    },
    {
      "x": -2,
      "y": -2,
      "z": 3,
      "name": "Rock_Sandstone"
    },
    {
      "x": -2,
      "y": -1,
      "z": 3,
      "name": "Rock_Sandstone"
    },
    {
      "x": -2,
      "y": 0,
      "z": 3,
      "name": "Rock_Sandstone_Cobble"
    },
    {
      "x": -2,
      "y": 1,
      "z": 3,
      "name": "Rock_Sandstone_Cobble"
    },
    {
      "x": -2,
      "y": 2,
      "z": 3,
      "name": "Rock_Sandstone_Cobble"
    },
    {
      "x": -2,
      "y": 3,
      "z": 3,
      "name": "Rock_Sandstone_Cobble"
    },
    {
      "x": -2,
      "y": 4,
      "z": 3,
      "name": "Rock_Sandstone_Cobble"
    },
    {
      "x": -2,
      "y": 5,
      "z": 3,
      "name": "Rock_Sandstone_Cobble"
    },
    {
      "x": -2,
      "y": 6,
      "z": 3,
      "name": "Rock_Sandstone_Brick"
    },
    {
      "x": -2,
      "y": 7,
      "z": 3,
      "name": "Rock_Sandstone_Brick"
    },
    {
      "x": -2,
      "y": 8,
      "z": 3,
      "name": "Rock_Sandstone_Brick_Pillar_Base"
    },
    {
      "x": -2,
      "y": 9,
      "z": 3,
      "name": "Rock_Sandstone_Brick"
    },
    {
      "x": -2,
      "y": -4,
      "z": 4,
      "name": "Rock_Sandstone"
    },
    {
      "x": -2,
      "y": -3,
      "z": 4,
      "name": "Rock_Sandstone"
    },
    {
      "x": -2,
      "y": -2,
      "z": 4,
      "name": "Rock_Sandstone"
    },
    {
      "x": -2,
      "y": -1,
      "z": 4,
      "name": "Rock_Sandstone"
    },
    {
      "x": -2,
      "y": 0,
      "z": 4,
      "name": "Rock_Sandstone_Cobble"
    },
    {
      "x": -2,
      "y": 1,
      "z": 4,
      "name": "Rock_Sandstone_Cobble"
    },
    {
      "x": -2,
      "y": 2,
      "z": 4,
      "name": "Rock_Sandstone_Cobble"
    },
    {
      "x": -2,
      "y": 3,
      "z": 4,
      "name": "Rock_Sandstone_Cobble"
    },
    {
      "x": -2,
      "y": 4,
      "z": 4,
      "name": "Rock_Sandstone_Cobble"
    },
    {
      "x": -2,
      "y": 5,
      "z": 4,
      "name": "Rock_Sandstone_Brick"
    },
    {
      "x": -2,
      "y": 6,
      "z": 4,
      "name": "Rock_Sandstone_Brick"
    },
    {
      "x": -2,
      "y": 7,
      "z": 4,
      "name": "Rock_Sandstone_Brick"
    },
    {
      "x": -2,
      "y": 8,
      "z": 4,
      "name": "Rock_Sandstone_Brick_Pillar_Base"
    },
    {
      "x": -2,
      "y": 9,
      "z": 4,
      "name": "Rock_Sandstone_Brick_Half"
    },
    {
      "x": -1,
      "y": -4,
      "z": -3,
      "name": "Rock_Sandstone"
    },
    {
      "x": -1,
      "y": -3,
      "z": -3,
      "name": "Rock_Sandstone"
    },
    {
      "x": -1,
      "y": -2,
      "z": -3,
      "name": "Rock_Sandstone"
    },
    {
      "x": -1,
      "y": -1,
      "z": -3,
      "name": "Rock_Sandstone"
    },
    {
      "x": -1,
      "y": 0,
      "z": -3,
      "name": "Rock_Sandstone_Cobble"
    },
    {
      "x": -1,
      "y": 1,
      "z": -3,
      "name": "Rock_Sandstone_Cobble"
    },
    {
      "x": -1,
      "y": 2,
      "z": -3,
      "name": "Rock_Sandstone_Cobble"
    },
    {
      "x": -1,
      "y": 3,
      "z": -3,
      "name": "Rock_Sandstone_Cobble"
    },
    {
      "x": -1,
      "y": 4,
      "z": -3,
      "name": "Rock_Sandstone_Cobble"
    },
    {
      "x": -1,
      "y": 5,
      "z": -3,
      "name": "Rock_Sandstone_Cobble"
    },
    {
      "x": -1,
      "y": 6,
      "z": -3,
      "name": "Rock_Sandstone_Cobble"
    },
    {
      "x": -1,
      "y": 7,
      "z": -3,
      "name": "Rock_Sandstone_Brick"
    },
    {
      "x": -1,
      "y": 8,
      "z": -3,
      "name": "Rock_Sandstone_Brick_Pillar_Base"
    },
    {
      "x": -1,
      "y": 9,
      "z": -3,
      "name": "Rock_Sandstone_Brick_Half"
    },
    {
      "x": -1,
      "y": -4,
      "z": -2,
      "name": "Rock_Sandstone_Cobble"
    },
    {
      "x": -1,
      "y": -3,
      "z": -2,
      "name": "Rock_Sandstone_Cobble"
    },
    {
      "x": -1,
      "y": -2,
      "z": -2,
      "name": "Rock_Sandstone_Cobble"
    },
    {
      "x": -1,
      "y": -1,
      "z": -2,
      "name": "Rock_Sandstone_Cobble"
    },
    {
      "x": -1,
      "y": 0,
      "z": -2,
      "name": "Rock_Sandstone_Cobble"
    },
    {
      "x": -1,
      "y": 1,
      "z": -2,
      "name": "Rock_Sandstone_Cobble"
    },
    {
      "x": -1,
      "y": 2,
      "z": -2,
      "name": "Rock_Sandstone_Cobble"
    },
    {
      "x": -1,
      "y": 3,
      "z": -2,
      "name": "Rock_Sandstone_Cobble"
    },
    {
      "x": -1,
      "y": 8,
      "z": -2,
      "name": "Rock_Sandstone_Brick"
    },
    {
      "x": -1,
      "y": 9,
      "z": -2,
      "name": "Rock_Sandstone_Brick"
    },
    {
      "x": -1,
      "y": 10,
      "z": -2,
      "name": "Plant_Bush_Arid_Sharp"
    },
    {
      "x": -1,
      "y": -4,
      "z": -1,
      "name": "Rock_Sandstone_Cobble"
    },
    {
      "x": -1,
      "y": -3,
      "z": -1,
      "name": "Rock_Sandstone_Cobble"
    },
    {
      "x": -1,
      "y": -2,
      "z": -1,
      "name": "Rock_Sandstone_Cobble"
    },
    {
      "x": -1,
      "y": -1,
      "z": -1,
      "name": "Rock_Sandstone_Cobble"
    },
    {
      "x": -1,
      "y": 0,
      "z": -1,
      "name": "Rock_Sandstone_Cobble"
    },
    {
      "x": -1,
      "y": 1,
      "z": -1,
      "name": "Rock_Sandstone_Cobble"
    },
    {
      "x": -1,
      "y": 2,
      "z": -1,
      "name": "Rock_Sandstone_Cobble"
    },
    {
      "x": -1,
      "y": 3,
      "z": -1,
      "name": "Rock_Sandstone_Cobble"
    },
    {
      "x": -1,
      "y": 8,
      "z": -1,
      "name": "Rock_Sandstone_Brick"
    },
    {
      "x": -1,
      "y": 9,
      "z": -1,
      "name": "Rock_Sandstone_Brick"
    },
    {
      "x": -1,
      "y": 10,
      "z": -1,
      "name": "Rock_Sandstone_Brick_Pillar_Base"
    },
    {
      "x": -1,
      "y": 11,
      "z": -1,
      "name": "Rock_Sandstone_Brick_Pillar_Middle"
    },
    {
      "x": -1,
      "y": 12,
      "z": -1,
      "name": "Rock_Sandstone_Brick_Pillar_Base",
      "rotation": 8
    },
    {
      "x": -1,
      "y": 13,
      "z": -1,
      "name": "Rock_Sandstone_Brick_Pillar_Middle"
    },
    {
      "x": -1,
      "y": 14,
      "z": -1,
      "name": "Rock_Sandstone_Brick_Pillar_Middle"
    },
    {
      "x": -1,
      "y": 15,
      "z": -1,
      "name": "Rock_Sandstone_Brick_Pillar_Middle"
    },
    {
      "x": -1,
      "y": 16,
      "z": -1,
      "name": "Rock_Sandstone_Brick_Pillar_Middle"
    },
    {
      "x": -1,
      "y": 17,
      "z": -1,
      "name": "Rock_Sandstone_Brick_Pillar_Base",
      "rotation": 8
    },
    {
      "x": -1,
      "y": 18,
      "z": -1,
      "name": "Rock_Sandstone_Brick_Stairs",
      "rotation": 3
    },
    {
      "x": -1,
      "y": 19,
      "z": -1,
      "name": "Rock_Sandstone_Brick_Ornate"
    },
    {
      "x": -1,
      "y": -4,
      "z": 0,
      "name": "Rock_Sandstone_Cobble"
    },
    {
      "x": -1,
      "y": -3,
      "z": 0,
      "name": "Rock_Sandstone_Cobble"
    },
    {
      "x": -1,
      "y": -2,
      "z": 0,
      "name": "Rock_Sandstone_Cobble"
    },
    {
      "x": -1,
      "y": -1,
      "z": 0,
      "name": "Rock_Sandstone_Cobble"
    },
    {
      "x": -1,
      "y": 0,
      "z": 0,
      "name": "Rock_Sandstone_Cobble"
    },
    {
      "x": -1,
      "y": 1,
      "z": 0,
      "name": "Rock_Sandstone_Cobble"
    },
    {
      "x": -1,
      "y": 2,
      "z": 0,
      "name": "Rock_Sandstone_Cobble"
    },
    {
      "x": -1,
      "y": 3,
      "z": 0,
      "name": "Rock_Sandstone_Cobble"
    },
    {
      "x": -1,
      "y": 8,
      "z": 0,
      "name": "Rock_Sandstone_Brick_Half",
      "rotation": 8
    },
    {
      "x": -1,
      "y": 9,
      "z": 0,
      "name": "Rock_Sandstone_Brick"
    },
    {
      "x": -1,
      "y": 10,
      "z": 0,
      "name": "Rock_Sandstone_Cobble"
    },
    {
      "x": -1,
      "y": 11,
      "z": 0,
      "name": "Rock_Sandstone_Cobble"
    },
    {
      "x": -1,
      "y": 12,
      "z": 0,
      "name": "Rock_Sandstone_Brick"
    },
    {
      "x": -1,
      "y": 13,
      "z": 0,
      "name": "Rock_Sandstone_Brick"
    },
    {
      "x": -1,
      "y": 14,
      "z": 0,
      "name": "Rock_Sandstone_Brick"
    },
    {
      "x": -1,
      "y": 15,
      "z": 0,
      "name": "Rock_Sandstone_Brick"
    },
    {
      "x": -1,
      "y": 16,
      "z": 0,
      "name": "Rock_Sandstone_Brick"
    },
    {
      "x": -1,
      "y": 17,
      "z": 0,
      "name": "Rock_Sandstone_Brick"
    },
    {
      "x": -1,
      "y": 18,
      "z": 0,
      "name": "Rock_Sandstone_Brick"
    },
    {
      "x": -1,
      "y": 19,
      "z": 0,
      "name": "Rock_Sandstone_Brick_Ornate"
    },
    {
      "x": -1,
      "y": 20,
      "z": 0,
      "name": "Rock_Sandstone_Brick_Pillar_Base"
    },
    {
      "x": -1,
      "y": 21,
      "z": 0,
      "name": "Rock_Sandstone_Brick_Pillar_Middle"
    },
    {
      "x": -1,
      "y": 22,
      "z": 0,
      "name": "Rock_Sandstone_Brick_Pillar_Base",
      "rotation": 8
    },
    {
      "x": -1,
      "y": 23,
      "z": 0,
      "name": "Rock_Sandstone_Brick_Ornate"
    },
    {
      "x": -1,
      "y": 24,
      "z": 0,
      "name": "Rock_Sandstone_Brick"
    },
    {
      "x": -1,
      "y": -4,
      "z": 1,
      "name": "Rock_Sandstone_Cobble"
    },
    {
      "x": -1,
      "y": -3,
      "z": 1,
      "name": "Rock_Sandstone_Cobble"
    },
    {
      "x": -1,
      "y": -2,
      "z": 1,
      "name": "Rock_Sandstone_Cobble"
    },
    {
      "x": -1,
      "y": -1,
      "z": 1,
      "name": "Rock_Sandstone_Cobble"
    },
    {
      "x": -1,
      "y": 0,
      "z": 1,
      "name": "Rock_Sandstone_Cobble"
    },
    {
      "x": -1,
      "y": 1,
      "z": 1,
      "name": "Rock_Sandstone_Cobble"
    },
    {
      "x": -1,
      "y": 2,
      "z": 1,
      "name": "Rock_Sandstone_Cobble"
    },
    {
      "x": -1,
      "y": 3,
      "z": 1,
      "name": "Rock_Sandstone_Cobble"
    },
    {
      "x": -1,
      "y": 8,
      "z": 1,
      "name": "Rock_Sandstone_Brick_Half",
      "rotation": 8
    },
    {
      "x": -1,
      "y": 9,
      "z": 1,
      "name": "Rock_Sandstone_Brick"
    },
    {
      "x": -1,
      "y": 10,
      "z": 1,
      "name": "Rock_Sandstone_Cobble"
    },
    {
      "x": -1,
      "y": 11,
      "z": 1,
      "name": "Rock_Sandstone_Cobble"
    },
    {
      "x": -1,
      "y": 12,
      "z": 1,
      "name": "Rock_Sandstone_Brick"
    },
    {
      "x": -1,
      "y": 13,
      "z": 1,
      "name": "Rock_Sandstone_Brick"
    },
    {
      "x": -1,
      "y": 14,
      "z": 1,
      "name": "Furniture_Desert_Window",
      "rotation": 1
    },
    {
      "x": -1,
      "y": 15,
      "z": 1,
      "name": "Furniture_Desert_Window",
      "rotation": 1
    },
    {
      "x": -1,
      "y": 16,
      "z": 1,
      "name": "Rock_Sandstone_Brick"
    },
    {
      "x": -1,
      "y": 17,
      "z": 1,
      "name": "Rock_Sandstone_Brick"
    },
    {
      "x": -1,
      "y": 18,
      "z": 1,
      "name": "Rock_Sandstone_Brick"
    },
    {
      "x": -1,
      "y": 19,
      "z": 1,
      "name": "Rock_Sandstone_Brick_Ornate"
    },
    {
      "x": -1,
      "y": 24,
      "z": 1,
      "name": "Rock_Sandstone_Brick_Half",
      "rotation": 7
    },
    {
      "x": -1,
      "y": -4,
      "z": 2,
      "name": "Rock_Sandstone_Cobble"
    },
    {
      "x": -1,
      "y": -3,
      "z": 2,
      "name": "Rock_Sandstone_Cobble"
    },
    {
      "x": -1,
      "y": -2,
      "z": 2,
      "name": "Rock_Sandstone_Cobble"
    },
    {
      "x": -1,
      "y": -1,
      "z": 2,
      "name": "Rock_Sandstone_Cobble"
    },
    {
      "x": -1,
      "y": 0,
      "z": 2,
      "name": "Rock_Sandstone_Cobble"
    },
    {
      "x": -1,
      "y": 1,
      "z": 2,
      "name": "Rock_Sandstone_Cobble"
    },
    {
      "x": -1,
      "y": 2,
      "z": 2,
      "name": "Rock_Sandstone_Cobble"
    },
    {
      "x": -1,
      "y": 3,
      "z": 2,
      "name": "Rock_Sandstone_Cobble"
    },
    {
      "x": -1,
      "y": 8,
      "z": 2,
      "name": "Rock_Sandstone_Brick"
    },
    {
      "x": -1,
      "y": 9,
      "z": 2,
      "name": "Rock_Sandstone_Cobble"
    },
    {
      "x": -1,
      "y": 10,
      "z": 2,
      "name": "Rock_Sandstone_Cobble"
    },
    {
      "x": -1,
      "y": 11,
      "z": 2,
      "name": "Rock_Sandstone_Cobble"
    },
    {
      "x": -1,
      "y": 12,
      "z": 2,
      "name": "Rock_Sandstone_Brick"
    },
    {
      "x": -1,
      "y": 13,
      "z": 2,
      "name": "Rock_Sandstone_Brick"
    },
    {
      "x": -1,
      "y": 14,
      "z": 2,
      "name": "Rock_Sandstone_Brick"
    },
    {
      "x": -1,
      "y": 15,
      "z": 2,
      "name": "Rock_Sandstone_Brick"
    },
    {
      "x": -1,
      "y": 16,
      "z": 2,
      "name": "Rock_Sandstone_Brick"
    },
    {
      "x": -1,
      "y": 18,
      "z": 2,
      "name": "Rock_Sandstone_Brick_Half",
      "rotation": 4
    },
    {
      "x": -1,
      "y": 19,
      "z": 2,
      "name": "Rock_Sandstone_Brick_Half",
      "rotation": 4
    },
    {
      "x": -1,
      "y": -4,
      "z": 3,
      "name": "Rock_Sandstone_Cobble"
    },
    {
      "x": -1,
      "y": -3,
      "z": 3,
      "name": "Rock_Sandstone_Cobble"
    },
    {
      "x": -1,
      "y": -2,
      "z": 3,
      "name": "Rock_Sandstone_Cobble"
    },
    {
      "x": -1,
      "y": -1,
      "z": 3,
      "name": "Rock_Sandstone_Cobble"
    },
    {
      "x": -1,
      "y": 0,
      "z": 3,
      "name": "Rock_Sandstone_Cobble"
    },
    {
      "x": -1,
      "y": 1,
      "z": 3,
      "name": "Rock_Sandstone_Cobble"
    },
    {
      "x": -1,
      "y": 2,
      "z": 3,
      "name": "Rock_Sandstone_Cobble"
    },
    {
      "x": -1,
      "y": 3,
      "z": 3,
      "name": "Rock_Sandstone_Cobble"
    },
    {
      "x": -1,
      "y": 8,
      "z": 3,
      "name": "Rock_Sandstone_Brick"
    },
    {
      "x": -1,
      "y": 9,
      "z": 3,
      "name": "Rock_Sandstone_Brick"
    },
    {
      "x": -1,
      "y": 10,
      "z": 3,
      "name": "Rock_Sandstone_Brick_Pillar_Base"
    },
    {
      "x": -1,
      "y": 11,
      "z": 3,
      "name": "Rock_Sandstone_Brick_Pillar_Middle"
    },
    {
      "x": -1,
      "y": 12,
      "z": 3,
      "name": "Rock_Sandstone_Brick_Pillar_Base",
      "rotation": 8
    },
    {
      "x": -1,
      "y": 13,
      "z": 3,
      "name": "Rock_Sandstone_Brick_Pillar_Middle"
    },
    {
      "x": -1,
      "y": 14,
      "z": 3,
      "name": "Rock_Sandstone_Brick_Pillar_Middle"
    },
    {
      "x": -1,
      "y": 15,
      "z": 3,
      "name": "Rock_Sandstone_Brick_Pillar_Middle"
    },
    {
      "x": -1,
      "y": -4,
      "z": 4,
      "name": "Rock_Sandstone"
    },
    {
      "x": -1,
      "y": -3,
      "z": 4,
      "name": "Rock_Sandstone"
    },
    {
      "x": -1,
      "y": -2,
      "z": 4,
      "name": "Rock_Sandstone"
    },
    {
      "x": -1,
      "y": -1,
      "z": 4,
      "name": "Rock_Sandstone"
    },
    {
      "x": -1,
      "y": 0,
      "z": 4,
      "name": "Rock_Sandstone"
    },
    {
      "x": -1,
      "y": 1,
      "z": 4,
      "name": "Rock_Sandstone_Cobble"
    },
    {
      "x": -1,
      "y": 2,
      "z": 4,
      "name": "Rock_Sandstone_Cobble"
    },
    {
      "x": -1,
      "y": 3,
      "z": 4,
      "name": "Rock_Sandstone_Cobble"
    },
    {
      "x": -1,
      "y": 4,
      "z": 4,
      "name": "Rock_Sandstone_Cobble"
    },
    {
      "x": -1,
      "y": 5,
      "z": 4,
      "name": "Rock_Sandstone_Brick"
    },
    {
      "x": -1,
      "y": 6,
      "z": 4,
      "name": "Rock_Sandstone_Brick"
    },
    {
      "x": -1,
      "y": 7,
      "z": 4,
      "name": "Rock_Sandstone_Brick"
    },
    {
      "x": -1,
      "y": 8,
      "z": 4,
      "name": "Rock_Sandstone_Brick"
    },
    {
      "x": -1,
      "y": 9,
      "z": 4,
      "name": "Rock_Sandstone_Brick"
    },
    {
      "x": -1,
      "y": -4,
      "z": 5,
      "name": "Rock_Sandstone"
    },
    {
      "x": -1,
      "y": -3,
      "z": 5,
      "name": "Rock_Sandstone"
    },
    {
      "x": -1,
      "y": -2,
      "z": 5,
      "name": "Rock_Sandstone"
    },
    {
      "x": -1,
      "y": -1,
      "z": 5,
      "name": "Rock_Sandstone"
    },
    {
      "x": -1,
      "y": 0,
      "z": 5,
      "name": "Rock_Sandstone"
    },
    {
      "x": -1,
      "y": 1,
      "z": 5,
      "name": "Rock_Sandstone_Cobble"
    },
    {
      "x": -1,
      "y": 2,
      "z": 5,
      "name": "Rock_Sandstone_Cobble"
    },
    {
      "x": -1,
      "y": 3,
      "z": 5,
      "name": "Rock_Sandstone_Cobble"
    },
    {
      "x": -1,
      "y": 4,
      "z": 5,
      "name": "Rock_Sandstone_Cobble"
    },
    {
      "x": -1,
      "y": 5,
      "z": 5,
      "name": "Rock_Sandstone_Cobble"
    },
    {
      "x": -1,
      "y": 6,
      "z": 5,
      "name": "Rock_Sandstone_Brick"
    },
    {
      "x": -1,
      "y": 7,
      "z": 5,
      "name": "Rock_Sandstone_Brick"
    },
    {
      "x": -1,
      "y": 8,
      "z": 5,
      "name": "Rock_Sandstone_Brick_Pillar_Base"
    },
    {
      "x": -1,
      "y": 9,
      "z": 5,
      "name": "Rock_Sandstone_Brick_Half"
    },
    {
      "x": 0,
      "y": -4,
      "z": -3,
      "name": "Rock_Sandstone"
    },
    {
      "x": 0,
      "y": -3,
      "z": -3,
      "name": "Rock_Sandstone"
    },
    {
      "x": 0,
      "y": -2,
      "z": -3,
      "name": "Rock_Sandstone"
    },
    {
      "x": 0,
      "y": -1,
      "z": -3,
      "name": "Rock_Sandstone"
    },
    {
      "x": 0,
      "y": 0,
      "z": -3,
      "name": "Rock_Sandstone"
    },
    {
      "x": 0,
      "y": 1,
      "z": -3,
      "name": "Rock_Sandstone_Cobble"
    },
    {
      "x": 0,
      "y": 2,
      "z": -3,
      "name": "Rock_Sandstone_Cobble"
    },
    {
      "x": 0,
      "y": 3,
      "z": -3,
      "name": "Rock_Sandstone_Cobble"
    },
    {
      "x": 0,
      "y": 4,
      "z": -3,
      "name": "Rock_Sandstone_Cobble"
    },
    {
      "x": 0,
      "y": 5,
      "z": -3,
      "name": "Rock_Sandstone_Cobble"
    },
    {
      "x": 0,
      "y": 6,
      "z": -3,
      "name": "Rock_Sandstone_Brick"
    },
    {
      "x": 0,
      "y": 7,
      "z": -3,
      "name": "Rock_Sandstone_Brick"
    },
    {
      "x": 0,
      "y": 8,
      "z": -3,
      "name": "Rock_Sandstone_Brick_Pillar_Base"
    },
    {
      "x": 0,
      "y": 9,
      "z": -3,
      "name": "Rock_Sandstone_Brick"
    },
    {
      "x": 0,
      "y": -4,
      "z": -2,
      "name": "Rock_Sandstone_Cobble"
    },
    {
      "x": 0,
      "y": -3,
      "z": -2,
      "name": "Rock_Sandstone_Cobble"
    },
    {
      "x": 0,
      "y": -2,
      "z": -2,
      "name": "Rock_Sandstone_Cobble"
    },
    {
      "x": 0,
      "y": -1,
      "z": -2,
      "name": "Rock_Sandstone_Cobble"
    },
    {
      "x": 0,
      "y": 0,
      "z": -2,
      "name": "Rock_Sandstone_Cobble"
    },
    {
      "x": 0,
      "y": 1,
      "z": -2,
      "name": "Rock_Sandstone_Cobble"
    },
    {
      "x": 0,
      "y": 2,
      "z": -2,
      "name": "Rock_Sandstone_Cobble"
    },
    {
      "x": 0,
      "y": 3,
      "z": -2,
      "name": "Rock_Sandstone_Cobble"
    },
    {
      "x": 0,
      "y": 8,
      "z": -2,
      "name": "Rock_Sandstone_Brick"
    },
    {
      "x": 0,
      "y": 9,
      "z": -2,
      "name": "Rock_Sandstone_Brick"
    },
    {
      "x": 0,
      "y": 10,
      "z": -2,
      "name": "Rock_Sandstone_Brick_Pillar_Base"
    },
    {
      "x": 0,
      "y": 11,
      "z": -2,
      "name": "Rock_Sandstone_Brick_Pillar_Middle"
    },
    {
      "x": 0,
      "y": 12,
      "z": -2,
      "name": "Rock_Sandstone_Brick_Pillar_Base",
      "rotation": 8
    },
    {
      "x": 0,
      "y": 13,
      "z": -2,
      "name": "Rock_Sandstone_Brick_Pillar_Middle"
    },
    {
      "x": 0,
      "y": 14,
      "z": -2,
      "name": "Rock_Sandstone_Brick_Pillar_Middle"
    },
    {
      "x": 0,
      "y": 15,
      "z": -2,
      "name": "Rock_Sandstone_Brick_Pillar_Middle"
    },
    {
      "x": 0,
      "y": 16,
      "z": -2,
      "name": "Rock_Sandstone_Brick_Pillar_Middle"
    },
    {
      "x": 0,
      "y": 17,
      "z": -2,
      "name": "Rock_Sandstone_Brick_Pillar_Base",
      "rotation": 8
    },
    {
      "x": 0,
      "y": 18,
      "z": -2,
      "name": "Rock_Sandstone_Brick_Half"
    },
    {
      "x": 0,
      "y": -4,
      "z": -1,
      "name": "Rock_Sandstone_Cobble"
    },
    {
      "x": 0,
      "y": -3,
      "z": -1,
      "name": "Rock_Sandstone_Cobble"
    },
    {
      "x": 0,
      "y": -2,
      "z": -1,
      "name": "Rock_Sandstone_Cobble"
    },
    {
      "x": 0,
      "y": -1,
      "z": -1,
      "name": "Rock_Sandstone_Cobble"
    },
    {
      "x": 0,
      "y": 0,
      "z": -1,
      "name": "Rock_Sandstone_Cobble"
    },
    {
      "x": 0,
      "y": 1,
      "z": -1,
      "name": "Rock_Sandstone_Cobble"
    },
    {
      "x": 0,
      "y": 2,
      "z": -1,
      "name": "Rock_Sandstone_Cobble"
    },
    {
      "x": 0,
      "y": 3,
      "z": -1,
      "name": "Rock_Sandstone_Cobble"
    },
    {
      "x": 0,
      "y": 8,
      "z": -1,
      "name": "Rock_Sandstone_Cobble"
    },
    {
      "x": 0,
      "y": 9,
      "z": -1,
      "name": "Rock_Sandstone_Brick"
    },
    {
      "x": 0,
      "y": 10,
      "z": -1,
      "name": "Rock_Sandstone_Cobble"
    },
    {
      "x": 0,
      "y": 11,
      "z": -1,
      "name": "Rock_Sandstone_Cobble"
    },
    {
      "x": 0,
      "y": 12,
      "z": -1,
      "name": "Rock_Sandstone_Brick"
    },
    {
      "x": 0,
      "y": 13,
      "z": -1,
      "name": "Rock_Sandstone_Brick"
    },
    {
      "x": 0,
      "y": 14,
      "z": -1,
      "name": "Rock_Sandstone_Brick"
    },
    {
      "x": 0,
      "y": 15,
      "z": -1,
      "name": "Rock_Sandstone_Brick"
    },
    {
      "x": 0,
      "y": 16,
      "z": -1,
      "name": "Rock_Sandstone_Brick"
    },
    {
      "x": 0,
      "y": 17,
      "z": -1,
      "name": "Rock_Sandstone_Brick"
    },
    {
      "x": 0,
      "y": 18,
      "z": -1,
      "name": "Rock_Sandstone_Brick"
    },
    {
      "x": 0,
      "y": 19,
      "z": -1,
      "name": "Rock_Sandstone_Brick_Ornate"
    },
    {
      "x": 0,
      "y": 20,
      "z": -1,
      "name": "Rock_Sandstone_Brick"
    },
    {
      "x": 0,
      "y": 21,
      "z": -1,
      "name": "Rock_Sandstone_Brick"
    },
    {
      "x": 0,
      "y": 22,
      "z": -1,
      "name": "Rock_Sandstone_Brick"
    },
    {
      "x": 0,
      "y": 23,
      "z": -1,
      "name": "Rock_Sandstone_Brick_Half",
      "rotation": 6
    },
    {
      "x": 0,
      "y": 24,
      "z": -1,
      "name": "Rock_Sandstone_Brick_Half",
      "rotation": 6
    },
    {
      "x": 0,
      "y": 25,
      "z": -1,
      "name": "Wood_Drywood_Beam",
      "rotation": 4
    },
    {
      "x": 0,
      "y": -4,
      "z": 0,
      "name": "Rock_Sandstone_Cobble"
    },
    {
      "x": 0,
      "y": -3,
      "z": 0,
      "name": "Rock_Sandstone_Cobble"
    },
    {
      "x": 0,
      "y": -2,
      "z": 0,
      "name": "Rock_Sandstone_Cobble"
    },
    {
      "x": 0,
      "y": -1,
      "z": 0,
      "name": "Rock_Sandstone_Cobble"
    },
    {
      "x": 0,
      "y": 0,
      "z": 0,
      "name": "Rock_Sandstone_Cobble"
    },
    {
      "x": 0,
      "y": 1,
      "z": 0,
      "name": "Rock_Sandstone_Cobble"
    },
    {
      "x": 0,
      "y": 2,
      "z": 0,
      "name": "Rock_Sandstone_Cobble"
    },
    {
      "x": 0,
      "y": 3,
      "z": 0,
      "name": "Rock_Sandstone_Cobble"
    },
    {
      "x": 0,
      "y": 8,
      "z": 0,
      "name": "Rock_Sandstone_Cobble"
    },
    {
      "x": 0,
      "y": 9,
      "z": 0,
      "name": "Rock_Sandstone_Cobble"
    },
    {
      "x": 0,
      "y": 10,
      "z": 0,
      "name": "Rock_Sandstone_Cobble_Half"
    },
    {
      "x": 0,
      "y": 19,
      "z": 0,
      "name": "Wood_Drywood_Planks"
    },
    {
      "x": 0,
      "y": 20,
      "z": 0,
      "name": "Rock_Sandstone_Brick_Smooth_Half",
      "rotation": 4
    },
    {
      "x": 0,
      "y": 21,
      "z": 0,
      "name": "Rock_Sandstone_Brick_Smooth_Half",
      "rotation": 4
    },
    {
      "x": 0,
      "y": 22,
      "z": 0,
      "name": "Rock_Sandstone_Brick_Smooth_Half",
      "rotation": 4
    },
    {
      "x": 0,
      "y": 23,
      "z": 0,
      "name": "Rock_Sandstone_Brick"
    },
    {
      "x": 0,
      "y": 24,
      "z": 0,
      "name": "Rock_Sandstone_Brick"
    },
    {
      "x": 0,
      "y": 25,
      "z": 0,
      "name": "Wood_Drywood_Planks"
    },
    {
      "x": 0,
      "y": -4,
      "z": 1,
      "name": "Rock_Sandstone_Cobble"
    },
    {
      "x": 0,
      "y": -3,
      "z": 1,
      "name": "Rock_Sandstone_Cobble"
    },
    {
      "x": 0,
      "y": -2,
      "z": 1,
      "name": "Rock_Sandstone_Cobble"
    },
    {
      "x": 0,
      "y": -1,
      "z": 1,
      "name": "Rock_Sandstone_Cobble"
    },
    {
      "x": 0,
      "y": 0,
      "z": 1,
      "name": "Rock_Sandstone_Cobble"
    },
    {
      "x": 0,
      "y": 1,
      "z": 1,
      "name": "Rock_Sandstone_Cobble"
    },
    {
      "x": 0,
      "y": 2,
      "z": 1,
      "name": "Rock_Sandstone_Cobble"
    },
    {
      "x": 0,
      "y": 3,
      "z": 1,
      "name": "Rock_Sandstone_Cobble"
    },
    {
      "x": 0,
      "y": 8,
      "z": 1,
      "name": "Rock_Sandstone_Brick"
    },
    {
      "x": 0,
      "y": 9,
      "z": 1,
      "name": "Rock_Sandstone_Cobble"
    },
    {
      "x": 0,
      "y": 10,
      "z": 1,
      "name": "Rock_Sandstone_Cobble"
    },
    {
      "x": 0,
      "y": 19,
      "z": 1,
      "name": "Wood_Drywood_Planks"
    },
    {
      "x": 0,
      "y": 24,
      "z": 1,
      "name": "Rock_Sandstone_Brick"
    },
    {
      "x": 0,
      "y": 25,
      "z": 1,
      "name": "Wood_Drywood_Planks"
    },
    {
      "x": 0,
      "y": -4,
      "z": 2,
      "name": "Rock_Sandstone_Cobble"
    },
    {
      "x": 0,
      "y": -3,
      "z": 2,
      "name": "Rock_Sandstone_Cobble"
    },
    {
      "x": 0,
      "y": -2,
      "z": 2,
      "name": "Rock_Sandstone_Cobble"
    },
    {
      "x": 0,
      "y": -1,
      "z": 2,
      "name": "Rock_Sandstone_Cobble"
    },
    {
      "x": 0,
      "y": 0,
      "z": 2,
      "name": "Rock_Sandstone_Cobble"
    },
    {
      "x": 0,
      "y": 1,
      "z": 2,
      "name": "Rock_Sandstone_Cobble"
    },
    {
      "x": 0,
      "y": 2,
      "z": 2,
      "name": "Rock_Sandstone_Cobble"
    },
    {
      "x": 0,
      "y": 3,
      "z": 2,
      "name": "Rock_Sandstone_Cobble"
    },
    {
      "x": 0,
      "y": 4,
      "z": 2,
      "name": "Rock_Sandstone_Cobble_Stairs",
      "rotation": 3
    },
    {
      "x": 0,
      "y": 8,
      "z": 2,
      "name": "Rock_Sandstone_Brick"
    },
    {
      "x": 0,
      "y": 9,
      "z": 2,
      "name": "Rock_Sandstone_Cobble"
    },
    {
      "x": 0,
      "y": 10,
      "z": 2,
      "name": "Rock_Sandstone_Cobble"
    },
    {
      "x": 0,
      "y": 11,
      "z": 2,
      "name": "Rock_Sandstone_Cobble_Half"
    },
    {
      "x": 0,
      "y": 19,
      "z": 2,
      "name": "Wood_Drywood_Beam",
      "rotation": 4
    },
    {
      "x": 0,
      "y": 25,
      "z": 2,
      "name": "Wood_Drywood_Planks"
    },
    {
      "x": 0,
      "y": -4,
      "z": 3,
      "name": "Rock_Sandstone_Cobble"
    },
    {
      "x": 0,
      "y": -3,
      "z": 3,
      "name": "Rock_Sandstone_Cobble"
    },
    {
      "x": 0,
      "y": -2,
      "z": 3,
      "name": "Rock_Sandstone_Cobble"
    },
    {
      "x": 0,
      "y": -1,
      "z": 3,
      "name": "Rock_Sandstone_Cobble"
    },
    {
      "x": 0,
      "y": 0,
      "z": 3,
      "name": "Rock_Sandstone_Cobble"
    },
    {
      "x": 0,
      "y": 1,
      "z": 3,
      "name": "Rock_Sandstone_Cobble"
    },
    {
      "x": 0,
      "y": 2,
      "z": 3,
      "name": "Rock_Sandstone_Cobble"
    },
    {
      "x": 0,
      "y": 3,
      "z": 3,
      "name": "Rock_Sandstone_Cobble"
    },
    {
      "x": 0,
      "y": 4,
      "z": 3,
      "name": "Rock_Sandstone_Cobble_Stairs",
      "rotation": 3
    },
    {
      "x": 0,
      "y": 8,
      "z": 3,
      "name": "Rock_Sandstone_Brick"
    },
    {
      "x": 0,
      "y": 9,
      "z": 3,
      "name": "Rock_Sandstone_Brick"
    },
    {
      "x": 0,
      "y": 10,
      "z": 3,
      "name": "Rock_Sandstone_Brick"
    },
    {
      "x": 0,
      "y": 11,
      "z": 3,
      "name": "Rock_Sandstone_Cobble"
    },
    {
      "x": 0,
      "y": 12,
      "z": 3,
      "name": "Rock_Sandstone_Brick"
    },
    {
      "x": 0,
      "y": 13,
      "z": 3,
      "name": "Rock_Sandstone_Brick"
    },
    {
      "x": 0,
      "y": 14,
      "z": 3,
      "name": "Rock_Sandstone_Brick"
    },
    {
      "x": 0,
      "y": 24,
      "z": 3,
      "name": "Rock_Sandstone_Brick_Half",
      "rotation": 7
    },
    {
      "x": 0,
      "y": 25,
      "z": 3,
      "name": "Wood_Drywood_Planks_Half",
      "rotation": 7
    },
    {
      "x": 0,
      "y": -4,
      "z": 4,
      "name": "Rock_Sandstone"
    },
    {
      "x": 0,
      "y": -3,
      "z": 4,
      "name": "Rock_Sandstone"
    },
    {
      "x": 0,
      "y": -2,
      "z": 4,
      "name": "Rock_Sandstone"
    },
    {
      "x": 0,
      "y": -1,
      "z": 4,
      "name": "Rock_Sandstone"
    },
    {
      "x": 0,
      "y": 0,
      "z": 4,
      "name": "Rock_Sandstone"
    },
    {
      "x": 0,
      "y": 1,
      "z": 4,
      "name": "Rock_Sandstone"
    },
    {
      "x": 0,
      "y": 2,
      "z": 4,
      "name": "Rock_Sandstone"
    },
    {
      "x": 0,
      "y": 3,
      "z": 4,
      "name": "Rock_Sandstone_Cobble"
    },
    {
      "x": 0,
      "y": 4,
      "z": 4,
      "name": "Rock_Sandstone_Brick"
    },
    {
      "x": 0,
      "y": 5,
      "z": 4,
      "name": "Rock_Sandstone_Brick"
    },
    {
      "x": 0,
      "y": 6,
      "z": 4,
      "name": "Rock_Sandstone_Brick"
    },
    {
      "x": 0,
      "y": 7,
      "z": 4,
      "name": "Rock_Sandstone_Brick"
    },
    {
      "x": 0,
      "y": 8,
      "z": 4,
      "name": "Rock_Sandstone_Brick"
    },
    {
      "x": 0,
      "y": 9,
      "z": 4,
      "name": "Rock_Sandstone_Brick"
    },
    {
      "x": 0,
      "y": 10,
      "z": 4,
      "name": "Rock_Sandstone_Brick_Pillar_Base"
    },
    {
      "x": 0,
      "y": 11,
      "z": 4,
      "name": "Rock_Sandstone_Brick_Pillar_Middle"
    },
    {
      "x": 0,
      "y": 12,
      "z": 4,
      "name": "Rock_Sandstone_Brick_Pillar_Base",
      "rotation": 8
    },
    {
      "x": 0,
      "y": 13,
      "z": 4,
      "name": "Rock_Sandstone_Brick_Pillar_Middle"
    },
    {
      "x": 0,
      "y": -4,
      "z": 5,
      "name": "Rock_Sandstone"
    },
    {
      "x": 0,
      "y": -3,
      "z": 5,
      "name": "Rock_Sandstone"
    },
    {
      "x": 0,
      "y": -2,
      "z": 5,
      "name": "Rock_Sandstone"
    },
    {
      "x": 0,
      "y": -1,
      "z": 5,
      "name": "Rock_Sandstone"
    },
    {
      "x": 0,
      "y": 0,
      "z": 5,
      "name": "Rock_Sandstone_Cobble"
    },
    {
      "x": 0,
      "y": 1,
      "z": 5,
      "name": "Rock_Sandstone"
    },
    {
      "x": 0,
      "y": 2,
      "z": 5,
      "name": "Rock_Sandstone_Cobble"
    },
    {
      "x": 0,
      "y": 3,
      "z": 5,
      "name": "Rock_Sandstone_Cobble"
    },
    {
      "x": 0,
      "y": 4,
      "z": 5,
      "name": "Rock_Sandstone_Cobble"
    },
    {
      "x": 0,
      "y": 5,
      "z": 5,
      "name": "Rock_Sandstone_Brick"
    },
    {
      "x": 0,
      "y": 6,
      "z": 5,
      "name": "Rock_Sandstone_Brick"
    },
    {
      "x": 0,
      "y": 7,
      "z": 5,
      "name": "Rock_Sandstone_Brick"
    },
    {
      "x": 0,
      "y": 8,
      "z": 5,
      "name": "Rock_Sandstone_Brick_Pillar_Base"
    },
    {
      "x": 0,
      "y": 9,
      "z": 5,
      "name": "Rock_Sandstone_Brick"
    },
    {
      "x": 1,
      "y": -2,
      "z": -6,
      "name": "Rock_Sandstone_Cobble"
    },
    {
      "x": 1,
      "y": -1,
      "z": -6,
      "name": "Rock_Sandstone_Cobble"
    },
    {
      "x": 1,
      "y": 0,
      "z": -6,
      "name": "Rock_Sandstone_Cobble"
    },
    {
      "x": 1,
      "y": 1,
      "z": -6,
      "name": "Rock_Sandstone_Cobble_Stairs",
      "rotation": 2
    },
    {
      "x": 1,
      "y": -3,
      "z": -5,
      "name": "Rock_Sandstone_Cobble"
    },
    {
      "x": 1,
      "y": -2,
      "z": -5,
      "name": "Rock_Sandstone_Cobble"
    },
    {
      "x": 1,
      "y": -1,
      "z": -5,
      "name": "Rock_Sandstone_Cobble"
    },
    {
      "x": 1,
      "y": 0,
      "z": -5,
      "name": "Rock_Sandstone_Cobble"
    },
    {
      "x": 1,
      "y": 1,
      "z": -5,
      "name": "Rock_Sandstone_Cobble"
    },
    {
      "x": 1,
      "y": 2,
      "z": -5,
      "name": "Rock_Sandstone_Cobble_Stairs",
      "rotation": 2
    },
    {
      "x": 1,
      "y": -4,
      "z": -4,
      "name": "Rock_Sandstone_Cobble"
    },
    {
      "x": 1,
      "y": -3,
      "z": -4,
      "name": "Rock_Sandstone_Cobble"
    },
    {
      "x": 1,
      "y": -2,
      "z": -4,
      "name": "Rock_Sandstone_Cobble"
    },
    {
      "x": 1,
      "y": -1,
      "z": -4,
      "name": "Rock_Sandstone_Cobble"
    },
    {
      "x": 1,
      "y": 0,
      "z": -4,
      "name": "Rock_Sandstone_Cobble"
    },
    {
      "x": 1,
      "y": 1,
      "z": -4,
      "name": "Rock_Sandstone_Cobble"
    },
    {
      "x": 1,
      "y": 2,
      "z": -4,
      "name": "Rock_Sandstone_Cobble"
    },
    {
      "x": 1,
      "y": 3,
      "z": -4,
      "name": "Rock_Sandstone_Cobble_Stairs",
      "rotation": 2
    },
    {
      "x": 1,
      "y": -4,
      "z": -3,
      "name": "Rock_Sandstone_Cobble"
    },
    {
      "x": 1,
      "y": -3,
      "z": -3,
      "name": "Rock_Sandstone_Cobble"
    },
    {
      "x": 1,
      "y": -2,
      "z": -3,
      "name": "Rock_Sandstone_Cobble"
    },
    {
      "x": 1,
      "y": -1,
      "z": -3,
      "name": "Rock_Sandstone_Cobble"
    },
    {
      "x": 1,
      "y": 0,
      "z": -3,
      "name": "Rock_Sandstone_Cobble"
    },
    {
      "x": 1,
      "y": 1,
      "z": -3,
      "name": "Rock_Sandstone_Cobble"
    },
    {
      "x": 1,
      "y": 2,
      "z": -3,
      "name": "Rock_Sandstone_Cobble"
    },
    {
      "x": 1,
      "y": 3,
      "z": -3,
      "name": "Rock_Sandstone_Cobble"
    },
    {
      "x": 1,
      "y": 4,
      "z": -3,
      "name": "Wood_Drywood_Planks_Half",
      "rotation": 5
    },
    {
      "x": 1,
      "y": 5,
      "z": -3,
      "name": "Wood_Drywood_Planks_Half",
      "rotation": 5
    },
    {
      "x": 1,
      "y": 6,
      "z": -3,
      "name": "Wood_Drywood_Stairs",
      "rotation": 11
    },
    {
      "x": 1,
      "y": 7,
      "z": -3,
      "name": "Rock_Sandstone_Brick"
    },
    {
      "x": 1,
      "y": 8,
      "z": -3,
      "name": "Rock_Sandstone_Brick_Pillar_Base"
    },
    {
      "x": 1,
      "y": 9,
      "z": -3,
      "name": "Rock_Sandstone_Brick"
    },
    {
      "x": 1,
      "y": 10,
      "z": -3,
      "name": "Rock_Sandstone_Cobble_Stairs",
      "rotation": 2
    },
    {
      "x": 1,
      "y": 11,
      "z": -3,
      "name": "Rock_Sandstone_Cobble_Half",
      "rotation": 6
    },
    {
      "x": 1,
      "y": 14,
      "z": -3,
      "name": "Rock_Sandstone_Brick_Smooth_Half",
      "rotation": 7
    },
    {
      "x": 1,
      "y": 15,
      "z": -3,
      "name": "Rock_Sandstone_Brick_Smooth_Half",
      "rotation": 7
    },
    {
      "x": 1,
      "y": -4,
      "z": -2,
      "name": "Rock_Sandstone_Cobble"
    },
    {
      "x": 1,
      "y": -3,
      "z": -2,
      "name": "Rock_Sandstone_Cobble"
    },
    {
      "x": 1,
      "y": -2,
      "z": -2,
      "name": "Rock_Sandstone_Cobble"
    },
    {
      "x": 1,
      "y": -1,
      "z": -2,
      "name": "Rock_Sandstone_Cobble"
    },
    {
      "x": 1,
      "y": 0,
      "z": -2,
      "name": "Rock_Sandstone_Cobble"
    },
    {
      "x": 1,
      "y": 1,
      "z": -2,
      "name": "Rock_Sandstone_Cobble"
    },
    {
      "x": 1,
      "y": 2,
      "z": -2,
      "name": "Rock_Sandstone_Cobble"
    },
    {
      "x": 1,
      "y": 3,
      "z": -2,
      "name": "Rock_Sandstone_Cobble"
    },
    {
      "x": 1,
      "y": 8,
      "z": -2,
      "name": "Rock_Sandstone_Brick"
    },
    {
      "x": 1,
      "y": 9,
      "z": -2,
      "name": "Rock_Sandstone_Brick"
    },
    {
      "x": 1,
      "y": 10,
      "z": -2,
      "name": "Rock_Sandstone_Cobble"
    },
    {
      "x": 1,
      "y": 11,
      "z": -2,
      "name": "Rock_Sandstone_Cobble"
    },
    {
      "x": 1,
      "y": 12,
      "z": -2,
      "name": "Rock_Sandstone_Brick"
    },
    {
      "x": 1,
      "y": 13,
      "z": -2,
      "name": "Rock_Sandstone_Brick"
    },
    {
      "x": 1,
      "y": 14,
      "z": -2,
      "name": "Rock_Sandstone_Brick"
    },
    {
      "x": 1,
      "y": 15,
      "z": -2,
      "name": "Rock_Sandstone_Brick"
    },
    {
      "x": 1,
      "y": 16,
      "z": -2,
      "name": "Rock_Sandstone_Brick"
    },
    {
      "x": 1,
      "y": 17,
      "z": -2,
      "name": "Rock_Sandstone_Brick"
    },
    {
      "x": 1,
      "y": 18,
      "z": -2,
      "name": "Rock_Sandstone_Brick"
    },
    {
      "x": 1,
      "y": 19,
      "z": -2,
      "name": "Rock_Sandstone_Brick_Ornate"
    },
    {
      "x": 1,
      "y": 20,
      "z": -2,
      "name": "Rock_Sandstone_Brick_Pillar_Base"
    },
    {
      "x": 1,
      "y": 21,
      "z": -2,
      "name": "Rock_Sandstone_Brick_Pillar_Middle"
    },
    {
      "x": 1,
      "y": -4,
      "z": -1,
      "name": "Rock_Sandstone_Cobble"
    },
    {
      "x": 1,
      "y": -3,
      "z": -1,
      "name": "Rock_Sandstone_Cobble"
    },
    {
      "x": 1,
      "y": -2,
      "z": -1,
      "name": "Rock_Sandstone_Cobble"
    },
    {
      "x": 1,
      "y": -1,
      "z": -1,
      "name": "Rock_Sandstone_Cobble"
    },
    {
      "x": 1,
      "y": 0,
      "z": -1,
      "name": "Rock_Sandstone_Cobble"
    },
    {
      "x": 1,
      "y": 1,
      "z": -1,
      "name": "Rock_Sandstone_Cobble"
    },
    {
      "x": 1,
      "y": 2,
      "z": -1,
      "name": "Rock_Sandstone_Cobble"
    },
    {
      "x": 1,
      "y": 3,
      "z": -1,
      "name": "Rock_Sandstone_Cobble"
    },
    {
      "x": 1,
      "y": 8,
      "z": -1,
      "name": "Rock_Sandstone_Cobble"
    },
    {
      "x": 1,
      "y": 9,
      "z": -1,
      "name": "Rock_Sandstone_Cobble"
    },
    {
      "x": 1,
      "y": 10,
      "z": -1,
      "name": "Rock_Sandstone_Cobble_Half"
    },
    {
      "x": 1,
      "y": 19,
      "z": -1,
      "name": "Wood_Drywood_Planks"
    },
    {
      "x": 1,
      "y": 20,
      "z": -1,
      "name": "Rock_Sandstone_Brick_Smooth_Half",
      "rotation": 5
    },
    {
      "x": 1,
      "y": 21,
      "z": -1,
      "name": "Rock_Sandstone_Brick_Smooth_Half",
      "rotation": 5
    },
    {
      "x": 1,
      "y": -4,
      "z": 0,
      "name": "Rock_Sandstone_Cobble"
    },
    {
      "x": 1,
      "y": -3,
      "z": 0,
      "name": "Rock_Sandstone_Cobble"
    },
    {
      "x": 1,
      "y": -2,
      "z": 0,
      "name": "Rock_Sandstone_Cobble"
    },
    {
      "x": 1,
      "y": -1,
      "z": 0,
      "name": "Rock_Sandstone_Cobble"
    },
    {
      "x": 1,
      "y": 0,
      "z": 0,
      "name": "Rock_Sandstone_Cobble"
    },
    {
      "x": 1,
      "y": 1,
      "z": 0,
      "name": "Rock_Sandstone_Cobble"
    },
    {
      "x": 1,
      "y": 2,
      "z": 0,
      "name": "Rock_Sandstone_Cobble"
    },
    {
      "x": 1,
      "y": 3,
      "z": 0,
      "name": "Rock_Sandstone_Cobble"
    },
    {
      "x": 1,
      "y": 8,
      "z": 0,
      "name": "Rock_Sandstone_Cobble"
    },
    {
      "x": 1,
      "y": 9,
      "z": 0,
      "name": "Rock_Sandstone_Cobble"
    },
    {
      "x": 1,
      "y": 10,
      "z": 0,
      "name": "Rock_Sandstone_Cobble_Half"
    },
    {
      "x": 1,
      "y": 19,
      "z": 0,
      "name": "Wood_Drywood_Planks"
    },
    {
      "x": 1,
      "y": 25,
      "z": 0,
      "name": "Wood_Drywood_Planks_Half",
      "rotation": 6
    },
    {
      "x": 1,
      "y": -4,
      "z": 1,
      "name": "Rock_Sandstone_Cobble"
    },
    {
      "x": 1,
      "y": -3,
      "z": 1,
      "name": "Rock_Sandstone_Cobble"
    },
    {
      "x": 1,
      "y": -2,
      "z": 1,
      "name": "Rock_Sandstone_Cobble"
    },
    {
      "x": 1,
      "y": -1,
      "z": 1,
      "name": "Rock_Sandstone_Cobble"
    },
    {
      "x": 1,
      "y": 0,
      "z": 1,
      "name": "Rock_Sandstone_Cobble"
    },
    {
      "x": 1,
      "y": 1,
      "z": 1,
      "name": "Rock_Sandstone_Cobble"
    },
    {
      "x": 1,
      "y": 2,
      "z": 1,
      "name": "Rock_Sandstone_Cobble"
    },
    {
      "x": 1,
      "y": 3,
      "z": 1,
      "name": "Rock_Sandstone_Cobble"
    },
    {
      "x": 1,
      "y": 8,
      "z": 1,
      "name": "Rock_Sandstone_Brick"
    },
    {
      "x": 1,
      "y": 9,
      "z": 1,
      "name": "Rock_Sandstone_Cobble"
    },
    {
      "x": 1,
      "y": 10,
      "z": 1,
      "name": "Rock_Sandstone_Cobble"
    },
    {
      "x": 1,
      "y": 19,
      "z": 1,
      "name": "Wood_Drywood_Planks"
    },
    {
      "x": 1,
      "y": 25,
      "z": 1,
      "name": "Wood_Drywood_Planks"
    },
    {
      "x": 1,
      "y": -4,
      "z": 2,
      "name": "Rock_Sandstone_Cobble"
    },
    {
      "x": 1,
      "y": -3,
      "z": 2,
      "name": "Rock_Sandstone_Cobble"
    },
    {
      "x": 1,
      "y": -2,
      "z": 2,
      "name": "Rock_Sandstone_Cobble"
    },
    {
      "x": 1,
      "y": -1,
      "z": 2,
      "name": "Rock_Sandstone_Cobble"
    },
    {
      "x": 1,
      "y": 0,
      "z": 2,
      "name": "Rock_Sandstone_Cobble"
    },
    {
      "x": 1,
      "y": 1,
      "z": 2,
      "name": "Rock_Sandstone_Cobble"
    },
    {
      "x": 1,
      "y": 2,
      "z": 2,
      "name": "Rock_Sandstone_Cobble"
    },
    {
      "x": 1,
      "y": 3,
      "z": 2,
      "name": "Rock_Sandstone_Cobble"
    },
    {
      "x": 1,
      "y": 4,
      "z": 2,
      "name": "Rock_Sandstone_Cobble"
    },
    {
      "x": 1,
      "y": 5,
      "z": 2,
      "name": "Rock_Sandstone_Cobble_Stairs",
      "rotation": 3
    },
    {
      "x": 1,
      "y": 9,
      "z": 2,
      "name": "Rock_Sandstone_Cobble_Half",
      "rotation": 5
    },
    {
      "x": 1,
      "y": 10,
      "z": 2,
      "name": "Rock_Sandstone_Cobble"
    },
    {
      "x": 1,
      "y": 11,
      "z": 2,
      "name": "Rock_Sandstone_Cobble_Half"
    },
    {
      "x": 1,
      "y": 19,
      "z": 2,
      "name": "Wood_Drywood_Planks"
    },
    {
      "x": 1,
      "y": 25,
      "z": 2,
      "name": "Wood_Drywood_Planks"
    },
    {
      "x": 1,
      "y": -4,
      "z": 3,
      "name": "Rock_Sandstone_Cobble"
    },
    {
      "x": 1,
      "y": -3,
      "z": 3,
      "name": "Rock_Sandstone_Cobble"
    },
    {
      "x": 1,
      "y": -2,
      "z": 3,
      "name": "Rock_Sandstone_Cobble"
    },
    {
      "x": 1,
      "y": -1,
      "z": 3,
      "name": "Rock_Sandstone_Cobble"
    },
    {
      "x": 1,
      "y": 0,
      "z": 3,
      "name": "Rock_Sandstone_Cobble"
    },
    {
      "x": 1,
      "y": 1,
      "z": 3,
      "name": "Rock_Sandstone_Cobble"
    },
    {
      "x": 1,
      "y": 2,
      "z": 3,
      "name": "Rock_Sandstone_Cobble"
    },
    {
      "x": 1,
      "y": 3,
      "z": 3,
      "name": "Rock_Sandstone_Cobble"
    },
    {
      "x": 1,
      "y": 4,
      "z": 3,
      "name": "Rock_Sandstone_Cobble"
    },
    {
      "x": 1,
      "y": 5,
      "z": 3,
      "name": "Rock_Sandstone_Cobble_Stairs",
      "rotation": 3
    },
    {
      "x": 1,
      "y": 9,
      "z": 3,
      "name": "Rock_Sandstone_Cobble_Half",
      "rotation": 5
    },
    {
      "x": 1,
      "y": 10,
      "z": 3,
      "name": "Rock_Sandstone_Cobble"
    },
    {
      "x": 1,
      "y": 11,
      "z": 3,
      "name": "Rock_Sandstone_Cobble"
    },
    {
      "x": 1,
      "y": 19,
      "z": 3,
      "name": "Wood_Drywood_Planks"
    },
    {
      "x": 1,
      "y": 23,
      "z": 3,
      "name": "Rock_Sandstone_Brick_Half",
      "rotation": 8
    },
    {
      "x": 1,
      "y": 24,
      "z": 3,
      "name": "Rock_Sandstone_Brick"
    },
    {
      "x": 1,
      "y": 25,
      "z": 3,
      "name": "Wood_Drywood_Planks"
    },
    {
      "x": 1,
      "y": -4,
      "z": 4,
      "name": "Rock_Sandstone"
    },
    {
      "x": 1,
      "y": -3,
      "z": 4,
      "name": "Rock_Sandstone"
    },
    {
      "x": 1,
      "y": -2,
      "z": 4,
      "name": "Rock_Sandstone"
    },
    {
      "x": 1,
      "y": -1,
      "z": 4,
      "name": "Rock_Sandstone"
    },
    {
      "x": 1,
      "y": 0,
      "z": 4,
      "name": "Rock_Sandstone_Cobble"
    },
    {
      "x": 1,
      "y": 1,
      "z": 4,
      "name": "Rock_Sandstone"
    },
    {
      "x": 1,
      "y": 2,
      "z": 4,
      "name": "Rock_Sandstone"
    },
    {
      "x": 1,
      "y": 3,
      "z": 4,
      "name": "Rock_Sandstone_Brick"
    },
    {
      "x": 1,
      "y": 4,
      "z": 4,
      "name": "Rock_Sandstone_Cobble"
    },
    {
      "x": 1,
      "y": 5,
      "z": 4,
      "name": "Rock_Sandstone_Brick"
    },
    {
      "x": 1,
      "y": 6,
      "z": 4,
      "name": "Rock_Sandstone_Brick"
    },
    {
      "x": 1,
      "y": 7,
      "z": 4,
      "name": "Rock_Sandstone_Brick"
    },
    {
      "x": 1,
      "y": 8,
      "z": 4,
      "name": "Rock_Sandstone_Brick"
    },
    {
      "x": 1,
      "y": 9,
      "z": 4,
      "name": "Rock_Sandstone_Cobble"
    },
    {
      "x": 1,
      "y": 10,
      "z": 4,
      "name": "Rock_Sandstone_Cobble"
    },
    {
      "x": 1,
      "y": 11,
      "z": 4,
      "name": "Rock_Sandstone_Cobble"
    },
    {
      "x": 1,
      "y": 12,
      "z": 4,
      "name": "Rock_Sandstone_Brick"
    },
    {
      "x": 1,
      "y": 13,
      "z": 4,
      "name": "Rock_Sandstone_Brick"
    },
    {
      "x": 1,
      "y": 14,
      "z": 4,
      "name": "Rock_Sandstone_Brick"
    },
    {
      "x": 1,
      "y": 15,
      "z": 4,
      "name": "Rock_Sandstone_Brick"
    },
    {
      "x": 1,
      "y": 16,
      "z": 4,
      "name": "Rock_Sandstone_Brick_Half",
      "rotation": 7
    },
    {
      "x": 1,
      "y": 17,
      "z": 4,
      "name": "Rock_Sandstone_Brick_Half",
      "rotation": 7
    },
    {
      "x": 1,
      "y": 22,
      "z": 4,
      "name": "Rock_Sandstone_Brick_Pillar_Base",
      "rotation": 8
    },
    {
      "x": 1,
      "y": 23,
      "z": 4,
      "name": "Rock_Sandstone_Brick_Ornate"
    },
    {
      "x": 1,
      "y": 24,
      "z": 4,
      "name": "Rock_Sandstone_Brick"
    },
    {
      "x": 1,
      "y": 25,
      "z": 4,
      "name": "Rock_Sandstone_Brick_Half",
      "rotation": 4
    },
    {
      "x": 1,
      "y": 26,
      "z": 4,
      "name": "Rock_Sandstone_Brick_Stairs",
      "rotation": 10
    },
    {
      "x": 1,
      "y": 27,
      "z": 4,
      "name": "Rock_Sandstone_White_Brick"
    },
    {
      "x": 1,
      "y": 28,
      "z": 4,
      "name": "Rock_Sandstone_White_Brick_Half"
    },
    {
      "x": 1,
      "y": -4,
      "z": 5,
      "name": "Rock_Sandstone"
    },
    {
      "x": 1,
      "y": -3,
      "z": 5,
      "name": "Rock_Sandstone"
    },
    {
      "x": 1,
      "y": -2,
      "z": 5,
      "name": "Rock_Sandstone"
    },
    {
      "x": 1,
      "y": -1,
      "z": 5,
      "name": "Rock_Sandstone_Cobble"
    },
    {
      "x": 1,
      "y": 0,
      "z": 5,
      "name": "Rock_Sandstone_Cobble"
    },
    {
      "x": 1,
      "y": 1,
      "z": 5,
      "name": "Rock_Sandstone_Cobble"
    },
    {
      "x": 1,
      "y": 2,
      "z": 5,
      "name": "Rock_Sandstone_Cobble"
    },
    {
      "x": 1,
      "y": 3,
      "z": 5,
      "name": "Rock_Sandstone_Cobble"
    },
    {
      "x": 1,
      "y": 4,
      "z": 5,
      "name": "Rock_Sandstone_Cobble"
    },
    {
      "x": 1,
      "y": 5,
      "z": 5,
      "name": "Rock_Sandstone_Cobble"
    },
    {
      "x": 1,
      "y": 6,
      "z": 5,
      "name": "Rock_Sandstone_Brick"
    },
    {
      "x": 1,
      "y": 7,
      "z": 5,
      "name": "Rock_Sandstone_Brick"
    },
    {
      "x": 1,
      "y": 8,
      "z": 5,
      "name": "Rock_Sandstone_Brick_Pillar_Base"
    },
    {
      "x": 1,
      "y": 9,
      "z": 5,
      "name": "Rock_Sandstone_Brick"
    },
    {
      "x": 1,
      "y": 10,
      "z": 5,
      "name": "Rock_Sandstone_Cobble_Stairs"
    },
    {
      "x": 1,
      "y": 11,
      "z": 5,
      "name": "Rock_Sandstone_Cobble_Half",
      "rotation": 4
    },
    {
      "x": 1,
      "y": 14,
      "z": 5,
      "name": "Rock_Sandstone_Brick_Smooth_Half",
      "rotation": 7
    },
    {
      "x": 1,
      "y": 15,
      "z": 5,
      "name": "Rock_Sandstone_Brick_Smooth_Half",
      "rotation": 7
    },
    {
      "x": 2,
      "y": -2,
      "z": -6,
      "name": "Rock_Sandstone_Cobble"
    },
    {
      "x": 2,
      "y": -1,
      "z": -6,
      "name": "Rock_Sandstone_Cobble"
    },
    {
      "x": 2,
      "y": 0,
      "z": -6,
      "name": "Rock_Sandstone_Cobble"
    },
    {
      "x": 2,
      "y": 1,
      "z": -6,
      "name": "Rock_Sandstone_Cobble_Stairs",
      "rotation": 2
    },
    {
      "x": 2,
      "y": -3,
      "z": -5,
      "name": "Rock_Sandstone_Cobble"
    },
    {
      "x": 2,
      "y": -2,
      "z": -5,
      "name": "Rock_Sandstone_Cobble"
    },
    {
      "x": 2,
      "y": -1,
      "z": -5,
      "name": "Rock_Sandstone_Cobble"
    },
    {
      "x": 2,
      "y": 0,
      "z": -5,
      "name": "Rock_Sandstone_Cobble"
    },
    {
      "x": 2,
      "y": 1,
      "z": -5,
      "name": "Rock_Sandstone_Cobble"
    },
    {
      "x": 2,
      "y": 2,
      "z": -5,
      "name": "Rock_Sandstone_Cobble_Stairs",
      "rotation": 2
    },
    {
      "x": 2,
      "y": -4,
      "z": -4,
      "name": "Rock_Sandstone_Cobble"
    },
    {
      "x": 2,
      "y": -3,
      "z": -4,
      "name": "Rock_Sandstone_Cobble"
    },
    {
      "x": 2,
      "y": -2,
      "z": -4,
      "name": "Rock_Sandstone_Cobble"
    },
    {
      "x": 2,
      "y": -1,
      "z": -4,
      "name": "Rock_Sandstone_Cobble"
    },
    {
      "x": 2,
      "y": 0,
      "z": -4,
      "name": "Rock_Sandstone_Cobble"
    },
    {
      "x": 2,
      "y": 1,
      "z": -4,
      "name": "Rock_Sandstone_Cobble"
    },
    {
      "x": 2,
      "y": 2,
      "z": -4,
      "name": "Rock_Sandstone_Cobble"
    },
    {
      "x": 2,
      "y": 3,
      "z": -4,
      "name": "Rock_Sandstone_Cobble_Stairs",
      "rotation": 2
    },
    {
      "x": 2,
      "y": -4,
      "z": -3,
      "name": "Rock_Sandstone_Cobble"
    },
    {
      "x": 2,
      "y": -3,
      "z": -3,
      "name": "Rock_Sandstone_Cobble"
    },
    {
      "x": 2,
      "y": -2,
      "z": -3,
      "name": "Rock_Sandstone_Cobble"
    },
    {
      "x": 2,
      "y": -1,
      "z": -3,
      "name": "Rock_Sandstone_Cobble"
    },
    {
      "x": 2,
      "y": 0,
      "z": -3,
      "name": "Rock_Sandstone_Cobble"
    },
    {
      "x": 2,
      "y": 1,
      "z": -3,
      "name": "Rock_Sandstone_Cobble"
    },
    {
      "x": 2,
      "y": 2,
      "z": -3,
      "name": "Rock_Sandstone_Cobble"
    },
    {
      "x": 2,
      "y": 3,
      "z": -3,
      "name": "Rock_Sandstone_Cobble"
    },
    {
      "x": 2,
      "y": 6,
      "z": -3,
      "name": "Wood_Drywood_Planks_Half",
      "rotation": 8
    },
    {
      "x": 2,
      "y": 7,
      "z": -3,
      "name": "Rock_Sandstone_Brick"
    },
    {
      "x": 2,
      "y": 8,
      "z": -3,
      "name": "Rock_Sandstone_Brick_Pillar_Base"
    },
    {
      "x": 2,
      "y": 9,
      "z": -3,
      "name": "Rock_Sandstone_Brick"
    },
    {
      "x": 2,
      "y": 10,
      "z": -3,
      "name": "Rock_Sandstone_Cobble_Stairs",
      "rotation": 2
    },
    {
      "x": 2,
      "y": 11,
      "z": -3,
      "name": "Rock_Sandstone_Cobble_Half",
      "rotation": 6
    },
    {
      "x": 2,
      "y": 13,
      "z": -3,
      "name": "Rock_Sandstone_Brick_Smooth_Half",
      "rotation": 6
    },
    {
      "x": 2,
      "y": 16,
      "z": -3,
      "name": "Rock_Sandstone_Brick_Smooth_Half"
    },
    {
      "x": 2,
      "y": -4,
      "z": -2,
      "name": "Rock_Sandstone_Cobble"
    },
    {
      "x": 2,
      "y": -3,
      "z": -2,
      "name": "Rock_Sandstone_Cobble"
    },
    {
      "x": 2,
      "y": -2,
      "z": -2,
      "name": "Rock_Sandstone_Cobble"
    },
    {
      "x": 2,
      "y": -1,
      "z": -2,
      "name": "Rock_Sandstone_Cobble"
    },
    {
      "x": 2,
      "y": 0,
      "z": -2,
      "name": "Rock_Sandstone_Cobble"
    },
    {
      "x": 2,
      "y": 1,
      "z": -2,
      "name": "Rock_Sandstone_Cobble"
    },
    {
      "x": 2,
      "y": 2,
      "z": -2,
      "name": "Rock_Sandstone_Cobble"
    },
    {
      "x": 2,
      "y": 3,
      "z": -2,
      "name": "Rock_Sandstone_Cobble"
    },
    {
      "x": 2,
      "y": 8,
      "z": -2,
      "name": "Rock_Sandstone_Brick"
    },
    {
      "x": 2,
      "y": 9,
      "z": -2,
      "name": "Rock_Sandstone_Cobble"
    },
    {
      "x": 2,
      "y": 10,
      "z": -2,
      "name": "Rock_Sandstone_Cobble"
    },
    {
      "x": 2,
      "y": 11,
      "z": -2,
      "name": "Rock_Sandstone_Cobble"
    },
    {
      "x": 2,
      "y": 12,
      "z": -2,
      "name": "Rock_Sandstone_Brick"
    },
    {
      "x": 2,
      "y": 13,
      "z": -2,
      "name": "Rock_Sandstone_Brick"
    },
    {
      "x": 2,
      "y": 14,
      "z": -2,
      "name": "Furniture_Desert_Window"
    },
    {
      "x": 2,
      "y": 15,
      "z": -2,
      "name": "Furniture_Desert_Window"
    },
    {
      "x": 2,
      "y": 16,
      "z": -2,
      "name": "Rock_Sandstone_Brick"
    },
    {
      "x": 2,
      "y": 17,
      "z": -2,
      "name": "Rock_Sandstone_Brick"
    },
    {
      "x": 2,
      "y": 18,
      "z": -2,
      "name": "Rock_Sandstone_Brick"
    },
    {
      "x": 2,
      "y": 19,
      "z": -2,
      "name": "Rock_Sandstone_Brick_Ornate"
    },
    {
      "x": 2,
      "y": 20,
      "z": -2,
      "name": "Rock_Sandstone_Brick_Wall"
    },
    {
      "x": 2,
      "y": -4,
      "z": -1,
      "name": "Rock_Sandstone_Cobble"
    },
    {
      "x": 2,
      "y": -3,
      "z": -1,
      "name": "Rock_Sandstone_Cobble"
    },
    {
      "x": 2,
      "y": -2,
      "z": -1,
      "name": "Rock_Sandstone_Cobble"
    },
    {
      "x": 2,
      "y": -1,
      "z": -1,
      "name": "Rock_Sandstone_Cobble"
    },
    {
      "x": 2,
      "y": 0,
      "z": -1,
      "name": "Rock_Sandstone_Cobble"
    },
    {
      "x": 2,
      "y": 1,
      "z": -1,
      "name": "Rock_Sandstone_Cobble"
    },
    {
      "x": 2,
      "y": 2,
      "z": -1,
      "name": "Rock_Sandstone_Cobble"
    },
    {
      "x": 2,
      "y": 3,
      "z": -1,
      "name": "Rock_Sandstone_Cobble"
    },
    {
      "x": 2,
      "y": 8,
      "z": -1,
      "name": "Rock_Sandstone_Cobble"
    },
    {
      "x": 2,
      "y": 9,
      "z": -1,
      "name": "Rock_Sandstone_Cobble"
    },
    {
      "x": 2,
      "y": 19,
      "z": -1,
      "name": "Wood_Drywood_Planks"
    },
    {
      "x": 2,
      "y": 25,
      "z": -1,
      "name": "Wood_Drywood_Beam",
      "rotation": 4
    },
    {
      "x": 2,
      "y": -4,
      "z": 0,
      "name": "Rock_Sandstone_Cobble"
    },
    {
      "x": 2,
      "y": -3,
      "z": 0,
      "name": "Rock_Sandstone_Cobble"
    },
    {
      "x": 2,
      "y": -2,
      "z": 0,
      "name": "Rock_Sandstone_Cobble"
    },
    {
      "x": 2,
      "y": -1,
      "z": 0,
      "name": "Rock_Sandstone_Cobble"
    },
    {
      "x": 2,
      "y": 0,
      "z": 0,
      "name": "Rock_Sandstone_Cobble"
    },
    {
      "x": 2,
      "y": 1,
      "z": 0,
      "name": "Rock_Sandstone_Cobble"
    },
    {
      "x": 2,
      "y": 2,
      "z": 0,
      "name": "Rock_Sandstone_Cobble"
    },
    {
      "x": 2,
      "y": 3,
      "z": 0,
      "name": "Rock_Sandstone_Cobble"
    },
    {
      "x": 2,
      "y": 8,
      "z": 0,
      "name": "Rock_Sandstone_Cobble"
    },
    {
      "x": 2,
      "y": 9,
      "z": 0,
      "name": "Rock_Sandstone_Cobble"
    },
    {
      "x": 2,
      "y": 19,
      "z": 0,
      "name": "Wood_Drywood_Planks"
    },
    {
      "x": 2,
      "y": 25,
      "z": 0,
      "name": "Wood_Drywood_Beam",
      "rotation": 4
    },
    {
      "x": 2,
      "y": -4,
      "z": 1,
      "name": "Rock_Sandstone"
    },
    {
      "x": 2,
      "y": -3,
      "z": 1,
      "name": "Rock_Sandstone"
    },
    {
      "x": 2,
      "y": -2,
      "z": 1,
      "name": "Rock_Sandstone"
    },
    {
      "x": 2,
      "y": -1,
      "z": 1,
      "name": "Rock_Sandstone"
    },
    {
      "x": 2,
      "y": 0,
      "z": 1,
      "name": "Rock_Sandstone"
    },
    {
      "x": 2,
      "y": 1,
      "z": 1,
      "name": "Rock_Sandstone"
    },
    {
      "x": 2,
      "y": 2,
      "z": 1,
      "name": "Rock_Sandstone"
    },
    {
      "x": 2,
      "y": 3,
      "z": 1,
      "name": "Rock_Sandstone_Brick"
    },
    {
      "x": 2,
      "y": 4,
      "z": 1,
      "name": "Rock_Sandstone_Brick"
    },
    {
      "x": 2,
      "y": 5,
      "z": 1,
      "name": "Rock_Sandstone_Brick"
    },
    {
      "x": 2,
      "y": 6,
      "z": 1,
      "name": "Rock_Sandstone_Brick"
    },
    {
      "x": 2,
      "y": 7,
      "z": 1,
      "name": "Rock_Sandstone_Brick"
    },
    {
      "x": 2,
      "y": 8,
      "z": 1,
      "name": "Rock_Sandstone_Brick"
    },
    {
      "x": 2,
      "y": 9,
      "z": 1,
      "name": "Rock_Sandstone_Brick"
    },
    {
      "x": 2,
      "y": 10,
      "z": 1,
      "name": "Rock_Sandstone_Brick"
    },
    {
      "x": 2,
      "y": 11,
      "z": 1,
      "name": "Rock_Sandstone_Brick"
    },
    {
      "x": 2,
      "y": 19,
      "z": 1,
      "name": "Wood_Drywood_Planks"
    },
    {
      "x": 2,
      "y": 25,
      "z": 1,
      "name": "Wood_Drywood_Planks"
    },
    {
      "x": 2,
      "y": -4,
      "z": 2,
      "name": "Rock_Sandstone"
    },
    {
      "x": 2,
      "y": -3,
      "z": 2,
      "name": "Rock_Sandstone"
    },
    {
      "x": 2,
      "y": -2,
      "z": 2,
      "name": "Rock_Sandstone"
    },
    {
      "x": 2,
      "y": -1,
      "z": 2,
      "name": "Rock_Sandstone"
    },
    {
      "x": 2,
      "y": 0,
      "z": 2,
      "name": "Rock_Sandstone"
    },
    {
      "x": 2,
      "y": 1,
      "z": 2,
      "name": "Rock_Sandstone"
    },
    {
      "x": 2,
      "y": 2,
      "z": 2,
      "name": "Rock_Sandstone"
    },
    {
      "x": 2,
      "y": 3,
      "z": 2,
      "name": "Rock_Sandstone_Brick"
    },
    {
      "x": 2,
      "y": 4,
      "z": 2,
      "name": "Rock_Sandstone_Cobble"
    },
    {
      "x": 2,
      "y": 5,
      "z": 2,
      "name": "Rock_Sandstone_Cobble"
    },
    {
      "x": 2,
      "y": 6,
      "z": 2,
      "name": "Rock_Sandstone_Cobble_Stairs",
      "rotation": 3
    },
    {
      "x": 2,
      "y": 11,
      "z": 2,
      "name": "Rock_Sandstone_Cobble"
    },
    {
      "x": 2,
      "y": 19,
      "z": 2,
      "name": "Wood_Drywood_Planks_Half",
      "rotation": 5
    },
    {
      "x": 2,
      "y": 25,
      "z": 2,
      "name": "Wood_Drywood_Planks_Half",
      "rotation": 5
    },
    {
      "x": 2,
      "y": -4,
      "z": 3,
      "name": "Rock_Sandstone"
    },
    {
      "x": 2,
      "y": -3,
      "z": 3,
      "name": "Rock_Sandstone"
    },
    {
      "x": 2,
      "y": -2,
      "z": 3,
      "name": "Rock_Sandstone"
    },
    {
      "x": 2,
      "y": -1,
      "z": 3,
      "name": "Rock_Sandstone"
    },
    {
      "x": 2,
      "y": 0,
      "z": 3,
      "name": "Rock_Sandstone"
    },
    {
      "x": 2,
      "y": 1,
      "z": 3,
      "name": "Rock_Sandstone"
    },
    {
      "x": 2,
      "y": 2,
      "z": 3,
      "name": "Rock_Sandstone"
    },
    {
      "x": 2,
      "y": 3,
      "z": 3,
      "name": "Rock_Sandstone_Brick"
    },
    {
      "x": 2,
      "y": 4,
      "z": 3,
      "name": "Rock_Sandstone_Cobble"
    },
    {
      "x": 2,
      "y": 5,
      "z": 3,
      "name": "Rock_Sandstone_Cobble"
    },
    {
      "x": 2,
      "y": 6,
      "z": 3,
      "name": "Rock_Sandstone_Cobble_Stairs",
      "rotation": 3
    },
    {
      "x": 2,
      "y": 11,
      "z": 3,
      "name": "Rock_Sandstone_Cobble"
    },
    {
      "x": 2,
      "y": 13,
      "z": 3,
      "name": "Wood_Torch_Wall",
      "rotation": 2
    },
    {
      "x": 2,
      "y": 19,
      "z": 3,
      "name": "Wood_Drywood_Planks"
    },
    {
      "x": 2,
      "y": 23,
      "z": 3,
      "name": "Rock_Sandstone_Brick_Half",
      "rotation": 8
    },
    {
      "x": 2,
      "y": 24,
      "z": 3,
      "name": "Rock_Sandstone_Brick"
    },
    {
      "x": 2,
      "y": 25,
      "z": 3,
      "name": "Wood_Drywood_Planks"
    },
    {
      "x": 2,
      "y": 26,
      "z": 3,
      "name": "Furniture_Village_Crate",
      "components": {
        "Components": {
          "ItemContainerBlock": {
            "ItemContainer": {
              "Capacity": 20,
              "Items": {
                "0": {
                  "Id": "Ingredient_Hide_Medium",
                  "Quantity": 2,
                  "Durability": 0.0,
                  "MaxDurability": 0.0,
                  "OverrideDroppedItemAnimation": false
                },
                "1": {
                  "Id": "Ingredient_Charcoal",
                  "Quantity": 5,
                  "Durability": 0.0,
                  "MaxDurability": 0.0,
                  "OverrideDroppedItemAnimation": false
                }
              }
            },
            "Capacity": 20
          }
        }
      }
    },
    {
      "x": 2,
      "y": -4,
      "z": 4,
      "name": "Rock_Sandstone"
    },
    {
      "x": 2,
      "y": -3,
      "z": 4,
      "name": "Rock_Sandstone"
    },
    {
      "x": 2,
      "y": -2,
      "z": 4,
      "name": "Rock_Sandstone"
    },
    {
      "x": 2,
      "y": -1,
      "z": 4,
      "name": "Rock_Sandstone"
    },
    {
      "x": 2,
      "y": 0,
      "z": 4,
      "name": "Rock_Sandstone"
    },
    {
      "x": 2,
      "y": 1,
      "z": 4,
      "name": "Rock_Sandstone"
    },
    {
      "x": 2,
      "y": 2,
      "z": 4,
      "name": "Rock_Sandstone"
    },
    {
      "x": 2,
      "y": 3,
      "z": 4,
      "name": "Rock_Sandstone_Cobble"
    },
    {
      "x": 2,
      "y": 4,
      "z": 4,
      "name": "Rock_Sandstone_Cobble"
    },
    {
      "x": 2,
      "y": 5,
      "z": 4,
      "name": "Rock_Sandstone_Cobble"
    },
    {
      "x": 2,
      "y": 6,
      "z": 4,
      "name": "Rock_Sandstone_Brick"
    },
    {
      "x": 2,
      "y": 7,
      "z": 4,
      "name": "Rock_Sandstone_Brick"
    },
    {
      "x": 2,
      "y": 8,
      "z": 4,
      "name": "Rock_Sandstone_Brick"
    },
    {
      "x": 2,
      "y": 9,
      "z": 4,
      "name": "Rock_Sandstone_Cobble"
    },
    {
      "x": 2,
      "y": 10,
      "z": 4,
      "name": "Rock_Sandstone_Cobble"
    },
    {
      "x": 2,
      "y": 11,
      "z": 4,
      "name": "Rock_Sandstone_Cobble"
    },
    {
      "x": 2,
      "y": 12,
      "z": 4,
      "name": "Rock_Sandstone_Brick"
    },
    {
      "x": 2,
      "y": 13,
      "z": 4,
      "name": "Rock_Sandstone_Brick"
    },
    {
      "x": 2,
      "y": 14,
      "z": 4,
      "name": "Furniture_Desert_Window"
    },
    {
      "x": 2,
      "y": 15,
      "z": 4,
      "name": "Furniture_Desert_Window"
    },
    {
      "x": 2,
      "y": 16,
      "z": 4,
      "name": "Rock_Sandstone_Brick"
    },
    {
      "x": 2,
      "y": 17,
      "z": 4,
      "name": "Rock_Sandstone_Brick"
    },
    {
      "x": 2,
      "y": 18,
      "z": 4,
      "name": "Rock_Sandstone_Brick"
    },
    {
      "x": 2,
      "y": 19,
      "z": 4,
      "name": "Rock_Sandstone_Brick_Ornate"
    },
    {
      "x": 2,
      "y": 23,
      "z": 4,
      "name": "Rock_Sandstone_Brick_Ornate"
    },
    {
      "x": 2,
      "y": 24,
      "z": 4,
      "name": "Rock_Sandstone_Brick"
    },
    {
      "x": 2,
      "y": 25,
      "z": 4,
      "name": "Rock_Sandstone_Brick_Stairs"
    },
    {
      "x": 2,
      "y": 26,
      "z": 4,
      "name": "Rock_Sandstone_Brick_Stairs",
      "rotation": 10
    },
    {
      "x": 2,
      "y": 27,
      "z": 4,
      "name": "Furniture_Desert_Window"
    },
    {
      "x": 2,
      "y": -4,
      "z": 5,
      "name": "Rock_Sandstone"
    },
    {
      "x": 2,
      "y": -3,
      "z": 5,
      "name": "Rock_Sandstone"
    },
    {
      "x": 2,
      "y": -2,
      "z": 5,
      "name": "Rock_Sandstone"
    },
    {
      "x": 2,
      "y": -1,
      "z": 5,
      "name": "Rock_Sandstone"
    },
    {
      "x": 2,
      "y": 0,
      "z": 5,
      "name": "Rock_Sandstone_Cobble"
    },
    {
      "x": 2,
      "y": 1,
      "z": 5,
      "name": "Rock_Sandstone_Cobble"
    },
    {
      "x": 2,
      "y": 2,
      "z": 5,
      "name": "Rock_Sandstone_Cobble"
    },
    {
      "x": 2,
      "y": 3,
      "z": 5,
      "name": "Rock_Sandstone_Cobble"
    },
    {
      "x": 2,
      "y": 4,
      "z": 5,
      "name": "Rock_Sandstone_Cobble"
    },
    {
      "x": 2,
      "y": 5,
      "z": 5,
      "name": "Rock_Sandstone_Cobble"
    },
    {
      "x": 2,
      "y": 6,
      "z": 5,
      "name": "Rock_Sandstone_Cobble"
    },
    {
      "x": 2,
      "y": 7,
      "z": 5,
      "name": "Rock_Sandstone_Brick"
    },
    {
      "x": 2,
      "y": 8,
      "z": 5,
      "name": "Rock_Sandstone_Brick_Pillar_Base"
    },
    {
      "x": 2,
      "y": 9,
      "z": 5,
      "name": "Rock_Sandstone_Brick"
    },
    {
      "x": 2,
      "y": 10,
      "z": 5,
      "name": "Rock_Sandstone_Cobble_Stairs"
    },
    {
      "x": 2,
      "y": 11,
      "z": 5,
      "name": "Rock_Sandstone_Cobble_Half",
      "rotation": 4
    },
    {
      "x": 2,
      "y": 13,
      "z": 5,
      "name": "Rock_Sandstone_Brick_Smooth_Half",
      "rotation": 4
    },
    {
      "x": 2,
      "y": 16,
      "z": 5,
      "name": "Rock_Sandstone_Brick_Smooth_Half"
    },
    {
      "x": 2,
      "y": 24,
      "z": 5,
      "name": "Rock_Sandstone_Brick_Smooth_Half",
      "rotation": 4
    },
    {
      "x": 3,
      "y": -2,
      "z": -6,
      "name": "Rock_Sandstone_Cobble"
    },
    {
      "x": 3,
      "y": -1,
      "z": -6,
      "name": "Rock_Sandstone_Cobble"
    },
    {
      "x": 3,
      "y": 0,
      "z": -6,
      "name": "Rock_Sandstone_Cobble"
    },
    {
      "x": 3,
      "y": 1,
      "z": -6,
      "name": "Rock_Sandstone_Cobble_Stairs",
      "rotation": 2
    },
    {
      "x": 3,
      "y": -3,
      "z": -5,
      "name": "Rock_Sandstone_Cobble"
    },
    {
      "x": 3,
      "y": -2,
      "z": -5,
      "name": "Rock_Sandstone_Cobble"
    },
    {
      "x": 3,
      "y": -1,
      "z": -5,
      "name": "Rock_Sandstone_Cobble"
    },
    {
      "x": 3,
      "y": 0,
      "z": -5,
      "name": "Rock_Sandstone_Cobble"
    },
    {
      "x": 3,
      "y": 1,
      "z": -5,
      "name": "Rock_Sandstone_Cobble"
    },
    {
      "x": 3,
      "y": 2,
      "z": -5,
      "name": "Rock_Sandstone_Cobble_Stairs",
      "rotation": 2
    },
    {
      "x": 3,
      "y": -4,
      "z": -4,
      "name": "Rock_Sandstone_Cobble"
    },
    {
      "x": 3,
      "y": -3,
      "z": -4,
      "name": "Rock_Sandstone_Cobble"
    },
    {
      "x": 3,
      "y": -2,
      "z": -4,
      "name": "Rock_Sandstone_Cobble"
    },
    {
      "x": 3,
      "y": -1,
      "z": -4,
      "name": "Rock_Sandstone_Cobble"
    },
    {
      "x": 3,
      "y": 0,
      "z": -4,
      "name": "Rock_Sandstone_Cobble"
    },
    {
      "x": 3,
      "y": 1,
      "z": -4,
      "name": "Rock_Sandstone_Cobble"
    },
    {
      "x": 3,
      "y": 2,
      "z": -4,
      "name": "Rock_Sandstone_Cobble"
    },
    {
      "x": 3,
      "y": 3,
      "z": -4,
      "name": "Rock_Sandstone_Cobble_Stairs",
      "rotation": 2
    },
    {
      "x": 3,
      "y": -4,
      "z": -3,
      "name": "Rock_Sandstone_Cobble"
    },
    {
      "x": 3,
      "y": -3,
      "z": -3,
      "name": "Rock_Sandstone_Cobble"
    },
    {
      "x": 3,
      "y": -2,
      "z": -3,
      "name": "Rock_Sandstone_Cobble"
    },
    {
      "x": 3,
      "y": -1,
      "z": -3,
      "name": "Rock_Sandstone_Cobble"
    },
    {
      "x": 3,
      "y": 0,
      "z": -3,
      "name": "Rock_Sandstone_Cobble"
    },
    {
      "x": 3,
      "y": 1,
      "z": -3,
      "name": "Rock_Sandstone_Cobble"
    },
    {
      "x": 3,
      "y": 2,
      "z": -3,
      "name": "Rock_Sandstone_Cobble"
    },
    {
      "x": 3,
      "y": 3,
      "z": -3,
      "name": "Rock_Sandstone_Cobble"
    },
    {
      "x": 3,
      "y": 4,
      "z": -3,
      "name": "Wood_Drywood_Planks_Half",
      "rotation": 7
    },
    {
      "x": 3,
      "y": 5,
      "z": -3,
      "name": "Wood_Drywood_Planks_Half",
      "rotation": 7
    },
    {
      "x": 3,
      "y": 6,
      "z": -3,
      "name": "Wood_Drywood_Stairs",
      "rotation": 9
    },
    {
      "x": 3,
      "y": 7,
      "z": -3,
      "name": "Rock_Sandstone_Brick"
    },
    {
      "x": 3,
      "y": 8,
      "z": -3,
      "name": "Rock_Sandstone_Brick_Pillar_Base"
    },
    {
      "x": 3,
      "y": 9,
      "z": -3,
      "name": "Rock_Sandstone_Brick"
    },
    {
      "x": 3,
      "y": 10,
      "z": -3,
      "name": "Rock_Sandstone_Cobble_Stairs",
      "rotation": 2
    },
    {
      "x": 3,
      "y": 11,
      "z": -3,
      "name": "Rock_Sandstone_Cobble_Half",
      "rotation": 6
    },
    {
      "x": 3,
      "y": 14,
      "z": -3,
      "name": "Rock_Sandstone_Brick_Smooth_Half",
      "rotation": 5
    },
    {
      "x": 3,
      "y": 15,
      "z": -3,
      "name": "Rock_Sandstone_Brick_Smooth_Half",
      "rotation": 5
    },
    {
      "x": 3,
      "y": -4,
      "z": -2,
      "name": "Rock_Sandstone_Cobble"
    },
    {
      "x": 3,
      "y": -3,
      "z": -2,
      "name": "Rock_Sandstone_Cobble"
    },
    {
      "x": 3,
      "y": -2,
      "z": -2,
      "name": "Rock_Sandstone_Cobble"
    },
    {
      "x": 3,
      "y": -1,
      "z": -2,
      "name": "Rock_Sandstone_Cobble"
    },
    {
      "x": 3,
      "y": 0,
      "z": -2,
      "name": "Rock_Sandstone_Cobble"
    },
    {
      "x": 3,
      "y": 1,
      "z": -2,
      "name": "Rock_Sandstone_Cobble"
    },
    {
      "x": 3,
      "y": 2,
      "z": -2,
      "name": "Rock_Sandstone_Cobble"
    },
    {
      "x": 3,
      "y": 3,
      "z": -2,
      "name": "Rock_Sandstone_Cobble"
    },
    {
      "x": 3,
      "y": 8,
      "z": -2,
      "name": "Rock_Sandstone_Brick"
    },
    {
      "x": 3,
      "y": 9,
      "z": -2,
      "name": "Rock_Sandstone_Brick"
    },
    {
      "x": 3,
      "y": 10,
      "z": -2,
      "name": "Rock_Sandstone_Cobble"
    },
    {
      "x": 3,
      "y": 11,
      "z": -2,
      "name": "Rock_Sandstone_Cobble"
    },
    {
      "x": 3,
      "y": 12,
      "z": -2,
      "name": "Rock_Sandstone_Brick"
    },
    {
      "x": 3,
      "y": 13,
      "z": -2,
      "name": "Rock_Sandstone_Brick"
    },
    {
      "x": 3,
      "y": 14,
      "z": -2,
      "name": "Rock_Sandstone_Brick"
    },
    {
      "x": 3,
      "y": 15,
      "z": -2,
      "name": "Rock_Sandstone_Brick"
    },
    {
      "x": 3,
      "y": 16,
      "z": -2,
      "name": "Rock_Sandstone_Brick"
    },
    {
      "x": 3,
      "y": 17,
      "z": -2,
      "name": "Rock_Sandstone_Brick"
    },
    {
      "x": 3,
      "y": 18,
      "z": -2,
      "name": "Rock_Sandstone_Brick"
    },
    {
      "x": 3,
      "y": 19,
      "z": -2,
      "name": "Rock_Sandstone_Brick_Ornate"
    },
    {
      "x": 3,
      "y": 20,
      "z": -2,
      "name": "Rock_Sandstone_Brick_Pillar_Base"
    },
    {
      "x": 3,
      "y": 21,
      "z": -2,
      "name": "Rock_Sandstone_Brick_Pillar_Middle"
    },
    {
      "x": 3,
      "y": 22,
      "z": -2,
      "name": "Rock_Sandstone_Brick_Pillar_Base",
      "rotation": 8
    },
    {
      "x": 3,
      "y": 23,
      "z": -2,
      "name": "Rock_Sandstone_Brick_Ornate"
    },
    {
      "x": 3,
      "y": 24,
      "z": -2,
      "name": "Rock_Sandstone_Brick"
    },
    {
      "x": 3,
      "y": 25,
      "z": -2,
      "name": "Rock_Sandstone_Brick_Half"
    },
    {
      "x": 3,
      "y": -4,
      "z": -1,
      "name": "Rock_Sandstone_Cobble"
    },
    {
      "x": 3,
      "y": -3,
      "z": -1,
      "name": "Rock_Sandstone_Cobble"
    },
    {
      "x": 3,
      "y": -2,
      "z": -1,
      "name": "Rock_Sandstone_Cobble"
    },
    {
      "x": 3,
      "y": -1,
      "z": -1,
      "name": "Rock_Sandstone_Cobble"
    },
    {
      "x": 3,
      "y": 0,
      "z": -1,
      "name": "Rock_Sandstone_Cobble"
    },
    {
      "x": 3,
      "y": 1,
      "z": -1,
      "name": "Rock_Sandstone_Cobble"
    },
    {
      "x": 3,
      "y": 2,
      "z": -1,
      "name": "Rock_Sandstone_Cobble"
    },
    {
      "x": 3,
      "y": 3,
      "z": -1,
      "name": "Rock_Sandstone_Cobble"
    },
    {
      "x": 3,
      "y": 8,
      "z": -1,
      "name": "Rock_Sandstone_Cobble"
    },
    {
      "x": 3,
      "y": 9,
      "z": -1,
      "name": "Rock_Sandstone_Cobble_Half"
    },
    {
      "x": 3,
      "y": 19,
      "z": -1,
      "name": "Wood_Drywood_Planks"
    },
    {
      "x": 3,
      "y": 20,
      "z": -1,
      "name": "Rock_Sandstone_Brick_Smooth_Half",
      "rotation": 7
    },
    {
      "x": 3,
      "y": 21,
      "z": -1,
      "name": "Rock_Sandstone_Brick_Smooth_Half",
      "rotation": 7
    },
    {
      "x": 3,
      "y": 22,
      "z": -1,
      "name": "Rock_Sandstone_Brick_Smooth_Half",
      "rotation": 7
    },
    {
      "x": 3,
      "y": 23,
      "z": -1,
      "name": "Rock_Sandstone_Brick"
    },
    {
      "x": 3,
      "y": 24,
      "z": -1,
      "name": "Rock_Sandstone_Brick"
    },
    {
      "x": 3,
      "y": 25,
      "z": -1,
      "name": "Wood_Drywood_Planks"
    },
    {
      "x": 3,
      "y": -4,
      "z": 0,
      "name": "Rock_Sandstone_Cobble"
    },
    {
      "x": 3,
      "y": -3,
      "z": 0,
      "name": "Rock_Sandstone_Cobble"
    },
    {
      "x": 3,
      "y": -2,
      "z": 0,
      "name": "Rock_Sandstone_Cobble"
    },
    {
      "x": 3,
      "y": -1,
      "z": 0,
      "name": "Rock_Sandstone_Cobble"
    },
    {
      "x": 3,
      "y": 0,
      "z": 0,
      "name": "Rock_Sandstone_Cobble"
    },
    {
      "x": 3,
      "y": 1,
      "z": 0,
      "name": "Rock_Sandstone_Cobble"
    },
    {
      "x": 3,
      "y": 2,
      "z": 0,
      "name": "Rock_Sandstone_Cobble"
    },
    {
      "x": 3,
      "y": 3,
      "z": 0,
      "name": "Rock_Sandstone_Cobble"
    },
    {
      "x": 3,
      "y": 4,
      "z": 0,
      "name": "Furniture_Desert_Chair",
      "rotation": 2
    },
    {
      "x": 3,
      "y": 6,
      "z": 0,
      "name": "Wood_Torch_Wall",
      "rotation": 2
    },
    {
      "x": 3,
      "y": 8,
      "z": 0,
      "name": "Rock_Sandstone_Cobble"
    },
    {
      "x": 3,
      "y": 9,
      "z": 0,
      "name": "Rock_Sandstone_Cobble_Half"
    },
    {
      "x": 3,
      "y": 19,
      "z": 0,
      "name": "Wood_Drywood_Planks"
    },
    {
      "x": 3,
      "y": 25,
      "z": 0,
      "name": "Wood_Drywood_Planks"
    },
    {
      "x": 3,
      "y": -4,
      "z": 1,
      "name": "Rock_Sandstone"
    },
    {
      "x": 3,
      "y": -3,
      "z": 1,
      "name": "Rock_Sandstone"
    },
    {
      "x": 3,
      "y": -2,
      "z": 1,
      "name": "Rock_Sandstone"
    },
    {
      "x": 3,
      "y": -1,
      "z": 1,
      "name": "Rock_Sandstone"
    },
    {
      "x": 3,
      "y": 0,
      "z": 1,
      "name": "Rock_Sandstone"
    },
    {
      "x": 3,
      "y": 1,
      "z": 1,
      "name": "Rock_Sandstone"
    },
    {
      "x": 3,
      "y": 2,
      "z": 1,
      "name": "Rock_Sandstone"
    },
    {
      "x": 3,
      "y": 3,
      "z": 1,
      "name": "Rock_Sandstone_Brick"
    },
    {
      "x": 3,
      "y": 4,
      "z": 1,
      "name": "Rock_Sandstone_Cobble"
    },
    {
      "x": 3,
      "y": 5,
      "z": 1,
      "name": "Rock_Sandstone_Cobble"
    },
    {
      "x": 3,
      "y": 6,
      "z": 1,
      "name": "Rock_Sandstone_Cobble"
    },
    {
      "x": 3,
      "y": 7,
      "z": 1,
      "name": "Rock_Sandstone_Cobble"
    },
    {
      "x": 3,
      "y": 8,
      "z": 1,
      "name": "Rock_Sandstone_Cobble_Stairs"
    },
    {
      "x": 3,
      "y": 11,
      "z": 1,
      "name": "Rock_Sandstone_Cobble_Half",
      "rotation": 8
    },
    {
      "x": 3,
      "y": 19,
      "z": 1,
      "name": "Wood_Drywood_Planks"
    },
    {
      "x": 3,
      "y": 25,
      "z": 1,
      "name": "Wood_Drywood_Planks"
    },
    {
      "x": 3,
      "y": -4,
      "z": 2,
      "name": "Rock_Sandstone"
    },
    {
      "x": 3,
      "y": -3,
      "z": 2,
      "name": "Rock_Sandstone"
    },
    {
      "x": 3,
      "y": -2,
      "z": 2,
      "name": "Rock_Sandstone"
    },
    {
      "x": 3,
      "y": -1,
      "z": 2,
      "name": "Rock_Sandstone"
    },
    {
      "x": 3,
      "y": 0,
      "z": 2,
      "name": "Rock_Sandstone"
    },
    {
      "x": 3,
      "y": 1,
      "z": 2,
      "name": "Rock_Sandstone"
    },
    {
      "x": 3,
      "y": 2,
      "z": 2,
      "name": "Rock_Sandstone"
    },
    {
      "x": 3,
      "y": 3,
      "z": 2,
      "name": "Rock_Sandstone_Brick"
    },
    {
      "x": 3,
      "y": 4,
      "z": 2,
      "name": "Rock_Sandstone_Cobble"
    },
    {
      "x": 3,
      "y": 5,
      "z": 2,
      "name": "Rock_Sandstone_Cobble"
    },
    {
      "x": 3,
      "y": 6,
      "z": 2,
      "name": "Rock_Sandstone_Cobble"
    },
    {
      "x": 3,
      "y": 7,
      "z": 2,
      "name": "Rock_Sandstone_Cobble_Stairs",
      "rotation": 3
    },
    {
      "x": 3,
      "y": 11,
      "z": 2,
      "name": "Rock_Sandstone_Cobble"
    },
    {
      "x": 3,
      "y": 12,
      "z": 2,
      "name": "Furniture_Desert_Ladder",
      "rotation": 3
    },
    {
      "x": 3,
      "y": 13,
      "z": 2,
      "name": "Furniture_Desert_Ladder",
      "rotation": 3
    },
    {
      "x": 3,
      "y": 14,
      "z": 2,
      "name": "Furniture_Desert_Ladder",
      "rotation": 3
    },
    {
      "x": 3,
      "y": 15,
      "z": 2,
      "name": "Furniture_Desert_Ladder",
      "rotation": 3
    },
    {
      "x": 3,
      "y": 16,
      "z": 2,
      "name": "Furniture_Desert_Ladder",
      "rotation": 3
    },
    {
      "x": 3,
      "y": 17,
      "z": 2,
      "name": "Furniture_Desert_Ladder",
      "rotation": 3
    },
    {
      "x": 3,
      "y": 18,
      "z": 2,
      "name": "Furniture_Desert_Ladder",
      "rotation": 3
    },
    {
      "x": 3,
      "y": 19,
      "z": 2,
      "name": "Furniture_Desert_Ladder",
      "rotation": 3
    },
    {
      "x": 3,
      "y": 20,
      "z": 2,
      "name": "Furniture_Desert_Ladder",
      "rotation": 3
    },
    {
      "x": 3,
      "y": 21,
      "z": 2,
      "name": "Furniture_Desert_Ladder",
      "rotation": 3
    },
    {
      "x": 3,
      "y": 22,
      "z": 2,
      "name": "Furniture_Desert_Ladder",
      "rotation": 3
    },
    {
      "x": 3,
      "y": 23,
      "z": 2,
      "name": "Furniture_Desert_Ladder",
      "rotation": 3
    },
    {
      "x": 3,
      "y": 24,
      "z": 2,
      "name": "Furniture_Desert_Ladder",
      "rotation": 3
    },
    {
      "x": 3,
      "y": 25,
      "z": 2,
      "name": "Furniture_Desert_Ladder",
      "rotation": 3
    },
    {
      "x": 3,
      "y": -4,
      "z": 3,
      "name": "Rock_Sandstone"
    },
    {
      "x": 3,
      "y": -3,
      "z": 3,
      "name": "Rock_Sandstone"
    },
    {
      "x": 3,
      "y": -2,
      "z": 3,
      "name": "Rock_Sandstone"
    },
    {
      "x": 3,
      "y": -1,
      "z": 3,
      "name": "Rock_Sandstone"
    },
    {
      "x": 3,
      "y": 0,
      "z": 3,
      "name": "Rock_Sandstone"
    },
    {
      "x": 3,
      "y": 1,
      "z": 3,
      "name": "Rock_Sandstone"
    },
    {
      "x": 3,
      "y": 2,
      "z": 3,
      "name": "Rock_Sandstone"
    },
    {
      "x": 3,
      "y": 3,
      "z": 3,
      "name": "Rock_Sandstone_Brick"
    },
    {
      "x": 3,
      "y": 4,
      "z": 3,
      "name": "Rock_Sandstone_Cobble"
    },
    {
      "x": 3,
      "y": 5,
      "z": 3,
      "name": "Rock_Sandstone_Cobble"
    },
    {
      "x": 3,
      "y": 6,
      "z": 3,
      "name": "Rock_Sandstone_Cobble"
    },
    {
      "x": 3,
      "y": 7,
      "z": 3,
      "name": "Rock_Sandstone_Cobble_Stairs",
      "rotation": 3
    },
    {
      "x": 3,
      "y": 11,
      "z": 3,
      "name": "Rock_Sandstone_Cobble"
    },
    {
      "x": 3,
      "y": 19,
      "z": 3,
      "name": "Wood_Drywood_Planks"
    },
    {
      "x": 3,
      "y": 20,
      "z": 3,
      "name": "Rock_Sandstone_Brick_Smooth_Half",
      "rotation": 7
    },
    {
      "x": 3,
      "y": 21,
      "z": 3,
      "name": "Rock_Sandstone_Brick_Smooth_Half",
      "rotation": 7
    },
    {
      "x": 3,
      "y": 22,
      "z": 3,
      "name": "Rock_Sandstone_Brick_Smooth_Half",
      "rotation": 7
    },
    {
      "x": 3,
      "y": 23,
      "z": 3,
      "name": "Rock_Sandstone_Brick"
    },
    {
      "x": 3,
      "y": 24,
      "z": 3,
      "name": "Rock_Sandstone_Brick"
    },
    {
      "x": 3,
      "y": 25,
      "z": 3,
      "name": "Wood_Drywood_Planks"
    },
    {
      "x": 3,
      "y": 26,
      "z": 3,
      "name": "Furniture_Temple_Wind_Pot"
    },
    {
      "x": 3,
      "y": 27,
      "z": 3,
      "name": "Furniture_Temple_Wind_Pot",
      "filler": 1024
    },
    {
      "x": 3,
      "y": -4,
      "z": 4,
      "name": "Rock_Sandstone"
    },
    {
      "x": 3,
      "y": -3,
      "z": 4,
      "name": "Rock_Sandstone"
    },
    {
      "x": 3,
      "y": -2,
      "z": 4,
      "name": "Rock_Sandstone"
    },
    {
      "x": 3,
      "y": -1,
      "z": 4,
      "name": "Rock_Sandstone"
    },
    {
      "x": 3,
      "y": 0,
      "z": 4,
      "name": "Rock_Sandstone"
    },
    {
      "x": 3,
      "y": 1,
      "z": 4,
      "name": "Rock_Sandstone"
    },
    {
      "x": 3,
      "y": 2,
      "z": 4,
      "name": "Rock_Sandstone"
    },
    {
      "x": 3,
      "y": 3,
      "z": 4,
      "name": "Rock_Sandstone_Cobble"
    },
    {
      "x": 3,
      "y": 4,
      "z": 4,
      "name": "Rock_Sandstone_Brick"
    },
    {
      "x": 3,
      "y": 5,
      "z": 4,
      "name": "Rock_Sandstone_Brick"
    },
    {
      "x": 3,
      "y": 6,
      "z": 4,
      "name": "Rock_Sandstone_Brick"
    },
    {
      "x": 3,
      "y": 7,
      "z": 4,
      "name": "Rock_Sandstone_Brick"
    },
    {
      "x": 3,
      "y": 8,
      "z": 4,
      "name": "Rock_Sandstone_Brick"
    },
    {
      "x": 3,
      "y": 9,
      "z": 4,
      "name": "Rock_Sandstone_Brick"
    },
    {
      "x": 3,
      "y": 10,
      "z": 4,
      "name": "Rock_Sandstone_Cobble"
    },
    {
      "x": 3,
      "y": 11,
      "z": 4,
      "name": "Rock_Sandstone_Cobble"
    },
    {
      "x": 3,
      "y": 12,
      "z": 4,
      "name": "Rock_Sandstone_Brick"
    },
    {
      "x": 3,
      "y": 13,
      "z": 4,
      "name": "Rock_Sandstone_Brick"
    },
    {
      "x": 3,
      "y": 14,
      "z": 4,
      "name": "Rock_Sandstone_Brick"
    },
    {
      "x": 3,
      "y": 15,
      "z": 4,
      "name": "Rock_Sandstone_Brick"
    },
    {
      "x": 3,
      "y": 16,
      "z": 4,
      "name": "Rock_Sandstone_Brick"
    },
    {
      "x": 3,
      "y": 17,
      "z": 4,
      "name": "Rock_Sandstone_Brick"
    },
    {
      "x": 3,
      "y": 18,
      "z": 4,
      "name": "Rock_Sandstone_Brick"
    },
    {
      "x": 3,
      "y": 19,
      "z": 4,
      "name": "Rock_Sandstone_Brick_Ornate"
    },
    {
      "x": 3,
      "y": 20,
      "z": 4,
      "name": "Rock_Sandstone_Brick_Pillar_Base"
    },
    {
      "x": 3,
      "y": 21,
      "z": 4,
      "name": "Rock_Sandstone_Brick_Pillar_Middle"
    },
    {
      "x": 3,
      "y": 22,
      "z": 4,
      "name": "Rock_Sandstone_Brick_Pillar_Base",
      "rotation": 8
    },
    {
      "x": 3,
      "y": 23,
      "z": 4,
      "name": "Rock_Sandstone_Brick_Ornate"
    },
    {
      "x": 3,
      "y": 24,
      "z": 4,
      "name": "Rock_Sandstone_Brick"
    },
    {
      "x": 3,
      "y": 25,
      "z": 4,
      "name": "Rock_Sandstone_Brick_Stairs"
    },
    {
      "x": 3,
      "y": 26,
      "z": 4,
      "name": "Rock_Sandstone_Brick_Stairs",
      "rotation": 10
    },
    {
      "x": 3,
      "y": 27,
      "z": 4,
      "name": "Rock_Sandstone_White_Brick"
    },
    {
      "x": 3,
      "y": 28,
      "z": 4,
      "name": "Rock_Sandstone_White_Brick"
    },
    {
      "x": 3,
      "y": 29,
      "z": 4,
      "name": "Rock_Sandstone_Brick_Smooth_Half"
    },
    {
      "x": 3,
      "y": -4,
      "z": 5,
      "name": "Rock_Sandstone"
    },
    {
      "x": 3,
      "y": -3,
      "z": 5,
      "name": "Rock_Sandstone"
    },
    {
      "x": 3,
      "y": -2,
      "z": 5,
      "name": "Rock_Sandstone"
    },
    {
      "x": 3,
      "y": -1,
      "z": 5,
      "name": "Rock_Sandstone"
    },
    {
      "x": 3,
      "y": 0,
      "z": 5,
      "name": "Rock_Sandstone"
    },
    {
      "x": 3,
      "y": 1,
      "z": 5,
      "name": "Rock_Sandstone"
    },
    {
      "x": 3,
      "y": 2,
      "z": 5,
      "name": "Rock_Sandstone_Cobble"
