{
  "version": 8,
  "blockIdVersion": 11,
  "anchorX": 0,
  "anchorY": 0,
  "anchorZ": 0,
  "blocks": [
    {
      "x": -2,
      "y": 0,
      "z": -2,
      "name": "*Rock_Calcite_Brick_Stairs_State_Definitions_Corner_Left",
      "rotation": 2
    },
    {
      "x": -2,
      "y": 4,
      "z": -2,
      "name": "*Rock_Calcite_Brick_Stairs_State_Definitions_Corner_Left",
      "rotation": 9
    },
    {
      "x": -2,
      "y": 5,
      "z": -2,
      "name": "Rock_Calcite_Brick_Smooth"
    },
    {
      "x": -2,
      "y": 6,
      "z": -2,
      "name": "Rock_Calcite_Brick"
    },
    {
      "x": -2,
      "y": 7,
      "z": -2,
      "name": "Rock_Calcite_Brick"
    },
    {
      "x": -2,
      "y": 8,
      "z": -2,
      "name": "Rock_Calcite_Brick_Smooth"
    },
    {
      "x": -2,
      "y": 9,
      "z": -2,
      "name": "*Rock_Shale_Brick_Roof_State_Definitions_Corner_Left",
      "rotation": 2
    },
    {
      "x": -2,
      "y": 0,
      "z": -1,
      "name": "Rock_Calcite_Brick_Stairs",
      "rotation": 3
    },
    {
      "x": -2,
      "y": 4,
      "z": -1,
      "name": "Rock_Calcite_Brick_Stairs",
      "rotation": 9
    },
    {
      "x": -2,
      "y": 5,
      "z": -1,
      "name": "Rock_Calcite_Brick"
    },
    {
      "x": -2,
      "y": 6,
      "z": -1,
      "name": "Rock_Calcite_Brick"
    },
    {
      "x": -2,
      "y": 7,
      "z": -1,
      "name": "Rock_Calcite_Brick_Stairs"
    },
    {
      "x": -2,
      "y": 8,
      "z": -1,
      "name": "Rock_Calcite_Brick_Stairs",
      "rotation": 10
    },
    {
      "x": -2,
      "y": 9,
      "z": -1,
      "name": "Rock_Shale_Brick_Roof",
      "rotation": 3
    },
    {
      "x": -2,
      "y": 0,
      "z": 0,
      "name": "*Rock_Calcite_Brick_Stairs_State_Definitions_Corner_Left",
      "rotation": 2
    },
    {
      "x": -2,
      "y": 4,
      "z": 0,
      "name": "Rock_Calcite_Brick_Stairs",
      "rotation": 9
    },
    {
      "x": -2,
      "y": 5,
      "z": 0,
      "name": "Rock_Calcite_Brick_Wall",
      "rotation": 1
    },
    {
      "x": -2,
      "y": 8,
      "z": 0,
      "name": "Rock_Calcite_Brick_Beam"
    },
    {
      "x": -2,
      "y": 9,
      "z": 0,
      "name": "Rock_Shale_Brick_Roof",
      "rotation": 3
    },
    {
      "x": -2,
      "y": 0,
      "z": 1,
      "name": "Rock_Calcite_Brick_Stairs",
      "rotation": 3
    },
    {
      "x": -2,
      "y": 4,
      "z": 1,
      "name": "Rock_Calcite_Brick_Stairs",
      "rotation": 9
    },
    {
      "x": -2,
      "y": 5,
      "z": 1,
      "name": "Rock_Calcite_Brick"
    },
    {
      "x": -2,
      "y": 6,
      "z": 1,
      "name": "Rock_Calcite_Brick_Smooth"
    },
    {
      "x": -2,
      "y": 7,
      "z": 1,
      "name": "Rock_Calcite_Brick_Stairs",
      "rotation": 2
    },
    {
      "x": -2,
      "y": 8,
      "z": 1,
      "name": "Rock_Calcite_Brick_Stairs",
      "rotation": 8
    },
    {
      "x": -2,
      "y": 9,
      "z": 1,
      "name": "Rock_Shale_Brick_Roof",
      "rotation": 3
    },
    {
      "x": -2,
      "y": 0,
      "z": 2,
      "name": "*Rock_Calcite_Brick_Stairs_State_Definitions_Corner_Right"
    },
    {
      "x": -2,
      "y": 4,
      "z": 2,
      "name": "*Rock_Calcite_Brick_Stairs_State_Definitions_Corner_Left",
      "rotation": 10
    },
    {
      "x": -2,
      "y": 5,
      "z": 2,
      "name": "Rock_Calcite_Brick"
    },
    {
      "x": -2,
      "y": 6,
      "z": 2,
      "name": "Rock_Calcite_Brick"
    },
    {
      "x": -2,
      "y": 7,
      "z": 2,
      "name": "Rock_Calcite_Brick_Smooth"
    },
    {
      "x": -2,
      "y": 8,
      "z": 2,
      "name": "Rock_Calcite_Brick_Smooth"
    },
    {
      "x": -2,
      "y": 9,
      "z": 2,
      "name": "*Rock_Shale_Brick_Roof_State_Definitions_Corner_Right"
    },
    {
      "x": -1,
      "y": 0,
      "z": -2,
      "name": "Rock_Calcite_Brick_Stairs",
      "rotation": 2
    },
    {
      "x": -1,
      "y": 4,
      "z": -2,
      "name": "Rock_Calcite_Brick_Stairs",
      "rotation": 8
    },
    {
      "x": -1,
      "y": 5,
      "z": -2,
      "name": "Rock_Calcite_Brick_Wall"
    },
    {
      "x": -1,
      "y": 8,
      "z": -2,
      "name": "Rock_Calcite_Brick_Stairs",
      "rotation": 11
    },
    {
      "x": -1,
      "y": 9,
      "z": -2,
      "name": "Rock_Shale_Brick_Roof",
      "rotation": 2
    },
    {
      "x": -1,
      "y": 0,
      "z": -1,
      "name": "Rock_Calcite_Brick"
    },
    {
      "x": -1,
      "y": 1,
      "z": -1,
      "name": "Rock_Calcite_Brick_Pillar_Base"
    },
    {
      "x": -1,
      "y": 2,
      "z": -1,
      "name": "Rock_Calcite_Brick_Pillar_Middle"
    },
    {
      "x": -1,
      "y": 3,
      "z": -1,
      "name": "Rock_Calcite_Brick_Pillar_Base",
      "rotation": 8
    },
    {
      "x": -1,
      "y": 4,
      "z": -1,
      "name": "Rock_Calcite_Brick"
    },
    {
      "x": -1,
      "y": 10,
      "z": -1,
      "name": "*Rock_Shale_Brick_Roof_Hollow_State_Definitions_Corner_Left",
      "rotation": 2
    },
    {
      "x": -1,
      "y": 0,
      "z": 0,
      "name": "Rock_Calcite_Brick_Stairs",
      "rotation": 2
    },
    {
      "x": -1,
      "y": 4,
      "z": 0,
      "name": "Rock_Calcite_Brick_Stairs",
      "rotation": 8
    },
    {
      "x": -1,
      "y": 10,
      "z": 0,
      "name": "Rock_Shale_Brick_Roof_Hollow",
      "rotation": 3
    },
    {
      "x": -1,
      "y": 0,
      "z": 1,
      "name": "Rock_Calcite_Brick"
    },
    {
      "x": -1,
      "y": 1,
      "z": 1,
      "name": "Rock_Calcite_Brick_Pillar_Base"
    },
    {
      "x": -1,
      "y": 2,
      "z": 1,
      "name": "Rock_Calcite_Brick_Pillar_Middle"
    },
    {
      "x": -1,
      "y": 3,
      "z": 1,
      "name": "Rock_Calcite_Brick_Pillar_Base",
      "rotation": 8
    },
    {
      "x": -1,
      "y": 4,
      "z": 1,
      "name": "Rock_Calcite_Brick"
    },
    {
      "x": -1,
      "y": 10,
      "z": 1,
      "name": "*Rock_Shale_Brick_Roof_Hollow_State_Definitions_Corner_Left",
      "rotation": 3
    },
    {
      "x": -1,
      "y": 0,
      "z": 2,
      "name": "Rock_Calcite_Brick_Stairs"
    },
    {
      "x": -1,
      "y": 4,
      "z": 2,
      "name": "Rock_Calcite_Brick_Stairs",
      "rotation": 10
    },
    {
      "x": -1,
      "y": 5,
      "z": 2,
      "name": "Rock_Calcite_Brick_Wall"
    },
    {
      "x": -1,
      "y": 8,
      "z": 2,
      "name": "Rock_Calcite_Brick_Stairs",
      "rotation": 11
    },
    {
      "x": -1,
      "y": 9,
      "z": 2,
      "name": "Rock_Shale_Brick_Roof"
    },
    {
      "x": 0,
      "y": 0,
      "z": -2,
      "name": "*Rock_Calcite_Brick_Stairs_State_Definitions_Corner_Right",
      "rotation": 2
    },
    {
      "x": 0,
      "y": 4,
      "z": -2,
      "name": "*Rock_Calcite_Brick_Stairs_State_Definitions_Corner_Right",
      "rotation": 11
    },
    {
      "x": 0,
      "y": 5,
      "z": -2,
      "name": "Rock_Calcite_Brick"
    },
    {
      "x": 0,
      "y": 6,
      "z": -2,
      "name": "Rock_Calcite_Brick"
    },
    {
      "x": 0,
      "y": 7,
      "z": -2,
      "name": "Rock_Calcite_Brick"
    },
    {
      "x": 0,
      "y": 8,
      "z": -2,
      "name": "Rock_Calcite_Brick"
    },
    {
      "x": 0,
      "y": 9,
      "z": -2,
      "name": "Rock_Shale_Brick_Roof",
      "rotation": 2
    },
    {
      "x": 0,
      "y": 0,
      "z": -1,
      "name": "Rock_Calcite_Brick_Stairs",
      "rotation": 1
    },
    {
      "x": 0,
      "y": 4,
      "z": -1,
      "name": "Rock_Calcite_Brick_Stairs",
      "rotation": 11
    },
    {
      "x": 0,
      "y": 10,
      "z": -1,
      "name": "Rock_Shale_Brick_Roof_Hollow",
      "rotation": 2
    },
    {
      "x": 0,
      "y": 0,
      "z": 0,
      "name": "*Rock_Calcite_Brick_Stairs_State_Definitions_Corner_Right",
      "rotation": 2
    },
    {
      "x": 0,
      "y": 4,
      "z": 0,
      "name": "*Rock_Calcite_Brick_Stairs_State_Definitions_Corner_Right",
      "rotation": 11
    },
    {
      "x": 0,
      "y": 11,
      "z": 0,
      "name": "Rock_Shale_Brick_Roof_Flat"
    },
    {
      "x": 0,
      "y": 0,
      "z": 1,
      "name": "Rock_Calcite_Brick_Stairs",
      "rotation": 1
    },
    {
      "x": 0,
      "y": 4,
      "z": 1,
      "name": "Rock_Calcite_Brick_Stairs",
      "rotation": 11
    },
    {
      "x": 0,
      "y": 10,
      "z": 1,
      "name": "Rock_Shale_Brick_Roof_Hollow"
    },
    {
      "x": 0,
      "y": 0,
      "z": 2,
      "name": "*Rock_Calcite_Brick_Stairs_State_Definitions_Corner_Right",
      "rotation": 1
    },
    {
      "x": 0,
      "y": 4,
      "z": 2,
      "name": "Rock_Calcite_Brick_Stairs",
      "rotation": 10
    },
    {
      "x": 0,
      "y": 5,
      "z": 2,
      "name": "Rock_Calcite_Brick_Smooth"
    },
    {
      "x": 0,
      "y": 6,
      "z": 2,
      "name": "Rock_Calcite_Brick_Smooth"
    },
    {
      "x": 0,
      "y": 7,
      "z": 2,
      "name": "Rock_Calcite_Brick_Smooth"
    },
    {
      "x": 0,
      "y": 8,
      "z": 2,
      "name": "Rock_Calcite_Brick"
    },
    {
      "x": 0,
      "y": 9,
      "z": 2,
      "name": "Rock_Shale_Brick_Roof"
    },
    {
      "x": 1,
      "y": 0,
      "z": -2,
      "name": "*Rock_Calcite_Brick_Stairs_State_Definitions_Corner_Left",
      "rotation": 2
    },
    {
      "x": 1,
      "y": 4,
      "z": -2,
      "name": "*Rock_Calcite_Brick_Stairs_State_Definitions_Corner_Left",
      "rotation": 9
    },
    {
      "x": 1,
      "y": 5,
      "z": -2,
      "name": "Rock_Calcite_Brick"
    },
    {
      "x": 1,
      "y": 6,
      "z": -2,
      "name": "Rock_Calcite_Brick_Smooth"
    },
    {
      "x": 1,
      "y": 7,
      "z": -2,
      "name": "Rock_Calcite_Brick_Smooth"
    },
    {
      "x": 1,
      "y": 8,
      "z": -2,
      "name": "Rock_Calcite_Brick"
    },
    {
      "x": 1,
      "y": 9,
      "z": -2,
      "name": "Rock_Shale_Brick_Roof",
      "rotation": 2
    },
    {
      "x": 1,
      "y": 0,
      "z": -1,
      "name": "Rock_Calcite_Brick_Stairs",
      "rotation": 3
    },
    {
      "x": 1,
      "y": 4,
      "z": -1,
      "name": "Rock_Calcite_Brick_Stairs",
      "rotation": 9
    },
    {
      "x": 1,
      "y": 10,
      "z": -1,
      "name": "Rock_Shale_Brick_Roof_Hollow",
      "rotation": 2
    },
    {
      "x": 1,
      "y": 0,
      "z": 0,
      "name": "*Rock_Calcite_Brick_Stairs_State_Definitions_Corner_Right"
    },
    {
      "x": 1,
      "y": 4,
      "z": 0,
      "name": "*Rock_Calcite_Brick_Stairs_State_Definitions_Corner_Left",
      "rotation": 10
    },
    {
      "x": 1,
      "y": 11,
      "z": 0,
      "name": "Rock_Shale_Brick_Roof_Flat",
      "rotation": 2
    },
    {
      "x": 1,
      "y": 0,
      "z": 1,
      "name": "Rock_Calcite_Brick_Stairs",
      "rotation": 3
    },
    {
      "x": 1,
      "y": 4,
      "z": 1,
      "name": "Rock_Calcite_Brick_Stairs",
      "rotation": 9
    },
    {
      "x": 1,
      "y": 10,
      "z": 1,
      "name": "Rock_Shale_Brick_Roof_Hollow"
    },
    {
      "x": 1,
      "y": 0,
      "z": 2,
      "name": "*Rock_Calcite_Brick_Stairs_State_Definitions_Corner_Right"
    },
    {
      "x": 1,
      "y": 4,
      "z": 2,
      "name": "Rock_Calcite_Brick_Stairs",
      "rotation": 10
    },
    {
      "x": 1,
      "y": 5,
      "z": 2,
      "name": "Rock_Calcite_Brick_Smooth"
    },
    {
      "x": 1,
      "y": 6,
      "z": 2,
      "name": "Rock_Calcite_Brick"
    },
    {
      "x": 1,
      "y": 7,
      "z": 2,
      "name": "Rock_Calcite_Brick_Smooth"
    },
    {
      "x": 1,
      "y": 8,
      "z": 2,
      "name": "Rock_Calcite_Brick_Smooth"
    },
    {
      "x": 1,
      "y": 9,
      "z": 2,
      "name": "Rock_Shale_Brick_Roof"
    },
    {
      "x": 2,
      "y": 0,
      "z": -2,
      "name": "Rock_Calcite_Brick_Stairs",
      "rotation": 2
    },
    {
      "x": 2,
      "y": 4,
      "z": -2,
      "name": "Rock_Calcite_Brick_Stairs",
      "rotation": 8
    },
    {
      "x": 2,
      "y": 5,
      "z": -2,
      "name": "Rock_Calcite_Brick_Wall"
    },
    {
      "x": 2,
      "y": 8,
      "z": -2,
      "name": "Rock_Calcite_Brick_Stairs",
      "rotation": 9
    },
    {
      "x": 2,
      "y": 9,
      "z": -2,
      "name": "Rock_Shale_Brick_Roof",
      "rotation": 2
    },
    {
      "x": 2,
      "y": 0,
      "z": -1,
      "name": "Rock_Calcite_Brick"
    },
    {
      "x": 2,
      "y": 1,
      "z": -1,
      "name": "Rock_Calcite_Brick_Pillar_Base"
    },
    {
      "x": 2,
      "y": 2,
      "z": -1,
      "name": "Rock_Calcite_Brick_Pillar_Middle"
    },
    {
      "x": 2,
      "y": 3,
      "z": -1,
      "name": "Rock_Calcite_Brick_Pillar_Base",
      "rotation": 8
    },
    {
      "x": 2,
      "y": 4,
      "z": -1,
      "name": "Rock_Calcite_Brick"
    },
    {
      "x": 2,
      "y": 10,
      "z": -1,
      "name": "*Rock_Shale_Brick_Roof_Hollow_State_Definitions_Corner_Left",
      "rotation": 1
    },
    {
      "x": 2,
      "y": 0,
      "z": 0,
      "name": "Rock_Calcite_Brick_Stairs"
    },
    {
      "x": 2,
      "y": 4,
      "z": 0,
      "name": "Rock_Calcite_Brick_Stairs",
      "rotation": 10
    },
    {
      "x": 2,
      "y": 10,
      "z": 0,
      "name": "Rock_Shale_Brick_Roof_Hollow",
      "rotation": 1
    },
    {
      "x": 2,
      "y": 0,
      "z": 1,
      "name": "Rock_Calcite_Brick"
    },
    {
      "x": 2,
      "y": 1,
      "z": 1,
      "name": "Rock_Calcite_Brick_Pillar_Base"
    },
    {
      "x": 2,
      "y": 2,
      "z": 1,
      "name": "Rock_Calcite_Brick_Pillar_Middle"
    },
    {
      "x": 2,
      "y": 3,
      "z": 1,
      "name": "Rock_Calcite_Brick_Pillar_Base",
      "rotation": 8
    },
    {
      "x": 2,
      "y": 4,
      "z": 1,
      "name": "Rock_Calcite_Brick"
    },
    {
      "x": 2,
      "y": 10,
      "z": 1,
      "name": "*Rock_Shale_Brick_Roof_Hollow_State_Definitions_Corner_Right",
      "rotation": 1
    },
    {
      "x": 2,
      "y": 0,
      "z": 2,
      "name": "Rock_Calcite_Brick_Stairs"
    },
    {
      "x": 2,
      "y": 4,
      "z": 2,
      "name": "Rock_Calcite_Brick_Stairs",
      "rotation": 10
    },
    {
      "x": 2,
      "y": 5,
      "z": 2,
      "name": "Rock_Calcite_Brick_Wall"
    },
    {
      "x": 2,
      "y": 8,
      "z": 2,
      "name": "Rock_Calcite_Brick_Stairs",
      "rotation": 9
    },
    {
      "x": 2,
      "y": 9,
      "z": 2,
      "name": "Rock_Shale_Brick_Roof"
    },
    {
      "x": 3,
      "y": 0,
      "z": -2,
      "name": "*Rock_Calcite_Brick_Stairs_State_Definitions_Corner_Right",
      "rotation": 2
    },
    {
      "x": 3,
      "y": 4,
      "z": -2,
      "name": "*Rock_Calcite_Brick_Stairs_State_Definitions_Corner_Right",
      "rotation": 11
    },
    {
      "x": 3,
      "y": 5,
      "z": -2,
      "name": "Rock_Calcite_Brick"
    },
    {
      "x": 3,
      "y": 6,
      "z": -2,
      "name": "Rock_Calcite_Brick_Smooth"
    },
    {
      "x": 3,
      "y": 7,
      "z": -2,
      "name": "Rock_Calcite_Brick"
    },
    {
      "x": 3,
      "y": 8,
      "z": -2,
      "name": "Rock_Calcite_Brick"
    },
    {
      "x": 3,
      "y": 9,
      "z": -2,
      "name": "*Rock_Shale_Brick_Roof_State_Definitions_Corner_Left",
      "rotation": 1
    },
    {
      "x": 3,
      "y": 0,
      "z": -1,
      "name": "Rock_Calcite_Brick_Stairs",
      "rotation": 1
    },
    {
      "x": 3,
      "y": 4,
      "z": -1,
      "name": "Rock_Calcite_Brick_Stairs",
      "rotation": 11
    },
    {
      "x": 3,
      "y": 5,
      "z": -1,
      "name": "Rock_Calcite_Brick"
    },
    {
      "x": 3,
      "y": 6,
      "z": -1,
      "name": "Rock_Calcite_Brick"
    },
    {
      "x": 3,
      "y": 7,
      "z": -1,
      "name": "Rock_Calcite_Brick_Stairs"
    },
    {
      "x": 3,
      "y": 8,
      "z": -1,
      "name": "Rock_Calcite_Brick_Stairs",
      "rotation": 10
    },
    {
      "x": 3,
      "y": 9,
      "z": -1,
      "name": "Rock_Shale_Brick_Roof",
      "rotation": 1
    },
    {
      "x": 3,
      "y": 0,
      "z": 0,
      "name": "*Rock_Calcite_Brick_Stairs_State_Definitions_Corner_Right",
      "rotation": 1
    },
    {
      "x": 3,
      "y": 4,
      "z": 0,
      "name": "*Rock_Calcite_Brick_Stairs_State_Definitions_Corner_Right",
      "rotation": 10
    },
    {
      "x": 3,
      "y": 5,
      "z": 0,
      "name": "Rock_Calcite_Brick_Wall",
      "rotation": 1
    },
    {
      "x": 3,
      "y": 8,
      "z": 0,
      "name": "Rock_Calcite_Brick_Beam"
    },
    {
      "x": 3,
      "y": 9,
      "z": 0,
      "name": "Rock_Shale_Brick_Roof",
      "rotation": 1
    },
    {
      "x": 3,
      "y": 0,
      "z": 1,
      "name": "Rock_Calcite_Brick_Stairs",
      "rotation": 1
    },
    {
      "x": 3,
      "y": 4,
      "z": 1,
      "name": "Rock_Calcite_Brick_Stairs",
      "rotation": 11
    },
    {
      "x": 3,
      "y": 5,
      "z": 1,
      "name": "Rock_Calcite_Brick"
    },
    {
      "x": 3,
      "y": 6,
      "z": 1,
      "name": "Rock_Calcite_Brick_Smooth"
    },
    {
      "x": 3,
      "y": 7,
      "z": 1,
      "name": "Rock_Calcite_Brick_Stairs",
      "rotation": 2
    },
    {
      "x": 3,
      "y": 8,
      "z": 1,
      "name": "Rock_Calcite_Brick_Stairs",
      "rotation": 8
    },
    {
      "x": 3,
      "y": 9,
      "z": 1,
      "name": "Rock_Shale_Brick_Roof",
      "rotation": 1
    },
    {
      "x": 3,
      "y": 0,
      "z": 2,
      "name": "*Rock_Calcite_Brick_Stairs_State_Definitions_Corner_Right",
      "rotation": 1
    },
    {
      "x": 3,
      "y": 4,
      "z": 2,
      "name": "*Rock_Calcite_Brick_Stairs_State_Definitions_Corner_Right",
      "rotation": 10
    },
    {
      "x": 3,
      "y": 5,
      "z": 2,
      "name": "Rock_Calcite_Brick"
    },
    {
      "x": 3,
      "y": 6,
      "z": 2,
      "name": "Rock_Calcite_Brick_Smooth"
    },
    {
      "x": 3,
      "y": 7,
      "z": 2,
      "name": "Rock_Calcite_Brick_Smooth"
    },
    {
      "x": 3,
      "y": 8,
      "z": 2,
      "name": "Rock_Calcite_Brick_Smooth"
    },
    {
      "x": 3,
      "y": 9,
      "z": 2,
      "name": "*Rock_Shale_Brick_Roof_State_Definitions_Corner_Right",
      "rotation": 1
    }
  ],
  "fluids": [
    {
      "x": -2,
      "y": 0,
      "z": -2,
      "name": "Empty",
      "level": 0
    },
    {
      "x": -2,
      "y": 4,
      "z": -2,
      "name": "Empty",
      "level": 0
    },
    {
      "x": -2,
      "y": 5,
      "z": -2,
      "name": "Empty",
      "level": 0
    },
    {
      "x": -2,
      "y": 6,
      "z": -2,
      "name": "Empty",
      "level": 0
    },
    {
      "x": -2,
      "y": 7,
      "z": -2,
      "name": "Empty",
      "level": 0
    },
    {
      "x": -2,
      "y": 8,
      "z": -2,
      "name": "Empty",
      "level": 0
    },
    {
      "x": -2,
      "y": 9,
      "z": -2,
      "name": "Empty",
      "level": 0
    },
    {
      "x": -2,
      "y": 0,
      "z": -1,
      "name": "Empty",
      "level": 0
    },
    {
      "x": -2,
      "y": 4,
      "z": -1,
      "name": "Empty",
      "level": 0
    },
    {
      "x": -2,
      "y": 5,
      "z": -1,
      "name": "Empty",
      "level": 0
    },
    {
      "x": -2,
      "y": 6,
      "z": -1,
      "name": "Empty",
      "level": 0
    },
    {
      "x": -2,
      "y": 7,
      "z": -1,
      "name": "Empty",
      "level": 0
    },
    {
      "x": -2,
      "y": 8,
      "z": -1,
      "name": "Empty",
      "level": 0
    },
    {
      "x": -2,
      "y": 9,
      "z": -1,
      "name": "Empty",
      "level": 0
    },
    {
      "x": -2,
      "y": 0,
      "z": 0,
      "name": "Empty",
      "level": 0
    },
    {
      "x": -2,
      "y": 4,
      "z": 0,
      "name": "Empty",
      "level": 0
    },
    {
      "x": -2,
      "y": 5,
      "z": 0,
      "name": "Empty",
      "level": 0
    },
    {
      "x": -2,
      "y": 8,
      "z": 0,
      "name": "Empty",
      "level": 0
    },
    {
      "x": -2,
      "y": 9,
      "z": 0,
      "name": "Empty",
      "level": 0
    },
    {
      "x": -2,
      "y": 0,
      "z": 1,
      "name": "Empty",
      "level": 0
    },
    {
      "x": -2,
      "y": 4,
      "z": 1,
      "name": "Empty",
      "level": 0
    },
    {
      "x": -2,
      "y": 5,
      "z": 1,
      "name": "Empty",
      "level": 0
    },
    {
      "x": -2,
      "y": 6,
      "z": 1,
      "name": "Empty",
      "level": 0
    },
    {
      "x": -2,
      "y": 7,
      "z": 1,
      "name": "Empty",
      "level": 0
    },
    {
      "x": -2,
      "y": 8,
      "z": 1,
      "name": "Empty",
      "level": 0
    },
    {
      "x": -2,
      "y": 9,
      "z": 1,
      "name": "Empty",
      "level": 0
    },
    {
      "x": -2,
      "y": 0,
      "z": 2,
      "name": "Empty",
      "level": 0
    },
    {
      "x": -2,
      "y": 4,
      "z": 2,
      "name": "Empty",
      "level": 0
    },
    {
      "x": -2,
      "y": 5,
      "z": 2,
      "name": "Empty",
      "level": 0
    },
    {
      "x": -2,
      "y": 6,
      "z": 2,
      "name": "Empty",
      "level": 0
    },
    {
      "x": -2,
      "y": 7,
      "z": 2,
      "name": "Empty",
      "level": 0
    },
    {
      "x": -2,
      "y": 8,
      "z": 2,
      "name": "Empty",
      "level": 0
    },
    {
      "x": -2,
      "y": 9,
      "z": 2,
      "name": "Empty",
      "level": 0
    },
    {
      "x": -1,
      "y": 0,
      "z": -2,
      "name": "Empty",
      "level": 0
    },
    {
      "x": -1,
      "y": 4,
      "z": -2,
      "name": "Empty",
      "level": 0
    },
    {
      "x": -1,
      "y": 5,
      "z": -2,
      "name": "Empty",
      "level": 0
    },
    {
      "x": -1,
      "y": 8,
      "z": -2,
      "name": "Empty",
      "level": 0
    },
    {
      "x": -1,
      "y": 9,
      "z": -2,
      "name": "Empty",
      "level": 0
    },
    {
      "x": -1,
      "y": 0,
      "z": -1,
      "name": "Empty",
      "level": 0
    },
    {
      "x": -1,
      "y": 1,
      "z": -1,
      "name": "Empty",
      "level": 0
    },
    {
      "x": -1,
      "y": 2,
      "z": -1,
      "name": "Empty",
      "level": 0
    },
    {
      "x": -1,
      "y": 3,
      "z": -1,
      "name": "Empty",
      "level": 0
    },
    {
      "x": -1,
      "y": 4,
      "z": -1,
      "name": "Empty",
      "level": 0
    },
    {
      "x": -1,
      "y": 10,
      "z": -1,
      "name": "Empty",
      "level": 0
    },
    {
      "x": -1,
      "y": 0,
      "z": 0,
      "name": "Empty",
      "level": 0
    },
    {
      "x": -1,
      "y": 4,
      "z": 0,
      "name": "Empty",
      "level": 0
    },
    {
      "x": -1,
      "y": 10,
      "z": 0,
      "name": "Empty",
      "level": 0
    },
    {
      "x": -1,
      "y": 0,
      "z": 1,
      "name": "Empty",
      "level": 0
    },
    {
      "x": -1,
      "y": 1,
      "z": 1,
      "name": "Empty",
      "level": 0
    },
    {
      "x": -1,
      "y": 2,
      "z": 1,
      "name": "Empty",
      "level": 0
    },
    {
      "x": -1,
      "y": 3,
      "z": 1,
      "name": "Empty",
      "level": 0
    },
    {
      "x": -1,
      "y": 4,
      "z": 1,
      "name": "Empty",
      "level": 0
    },
    {
      "x": -1,
      "y": 10,
      "z": 1,
      "name": "Empty",
      "level": 0
    },
    {
      "x": -1,
      "y": 0,
      "z": 2,
      "name": "Empty",
      "level": 0
    },
    {
      "x": -1,
      "y": 4,
      "z": 2,
      "name": "Empty",
      "level": 0
    },
    {
      "x": -1,
      "y": 5,
      "z": 2,
      "name": "Empty",
      "level": 0
    },
    {
      "x": -1,
      "y": 8,
      "z": 2,
      "name": "Empty",
      "level": 0
    },
    {
      "x": -1,
      "y": 9,
      "z": 2,
      "name": "Empty",
      "level": 0
    },
    {
      "x": 0,
      "y": 0,
      "z": -2,
      "name": "Empty",
      "level": 0
    },
    {
      "x": 0,
      "y": 4,
      "z": -2,
      "name": "Empty",
      "level": 0
    },
    {
      "x": 0,
      "y": 5,
      "z": -2,
      "name": "Empty",
      "level": 0
    },
    {
      "x": 0,
      "y": 6,
      "z": -2,
      "name": "Empty",
      "level": 0
    },
    {
      "x": 0,
      "y": 7,
      "z": -2,
      "name": "Empty",
      "level": 0
    },
    {
      "x": 0,
      "y": 8,
      "z": -2,
      "name": "Empty",
      "level": 0
    },
    {
      "x": 0,
      "y": 9,
      "z": -2,
      "name": "Empty",
      "level": 0
    },
    {
      "x": 0,
      "y": 0,
      "z": -1,
      "name": "Empty",
      "level": 0
    },
    {
      "x": 0,
      "y": 4,
      "z": -1,
      "name": "Empty",
      "level": 0
    },
    {
      "x": 0,
      "y": 10,
      "z": -1,
      "name": "Empty",
      "level": 0
    },
    {
      "x": 0,
      "y": 0,
      "z": 0,
      "name": "Empty",
      "level": 0
    },
    {
      "x": 0,
      "y": 4,
      "z": 0,
      "name": "Empty",
      "level": 0
    },
    {
      "x": 0,
      "y": 11,
      "z": 0,
      "name": "Empty",
      "level": 0
    },
    {
      "x": 0,
      "y": 0,
      "z": 1,
      "name": "Empty",
      "level": 0
    },
    {
      "x": 0,
      "y": 4,
      "z": 1,
      "name": "Empty",
      "level": 0
    },
    {
      "x": 0,
      "y": 10,
      "z": 1,
      "name": "Empty",
      "level": 0
    },
    {
      "x": 0,
      "y": 0,
      "z": 2,
      "name": "Empty",
      "level": 0
    },
    {
      "x": 0,
      "y": 4,
      "z": 2,
      "name": "Empty",
      "level": 0
    },
    {
      "x": 0,
      "y": 5,
      "z": 2,
      "name": "Empty",
      "level": 0
    },
    {
      "x": 0,
      "y": 6,
      "z": 2,
      "name": "Empty",
      "level": 0
    },
    {
      "x": 0,
      "y": 7,
      "z": 2,
      "name": "Empty",
      "level": 0
    },
    {
      "x": 0,
      "y": 8,
      "z": 2,
      "name": "Empty",
      "level": 0
    },
    {
      "x": 0,
      "y": 9,
      "z": 2,
      "name": "Empty",
      "level": 0
    },
    {
      "x": 1,
      "y": 0,
      "z": -2,
      "name": "Empty",
      "level": 0
    },
    {
      "x": 1,
      "y": 4,
      "z": -2,
      "name": "Empty",
      "level": 0
    },
    {
      "x": 1,
      "y": 5,
      "z": -2,
      "name": "Empty",
      "level": 0
    },
    {
      "x": 1,
      "y": 6,
      "z": -2,
      "name": "Empty",
      "level": 0
    },
    {
      "x": 1,
      "y": 7,
      "z": -2,
      "name": "Empty",
      "level": 0
    },
    {
      "x": 1,
      "y": 8,
      "z": -2,
      "name": "Empty",
      "level": 0
    },
    {
      "x": 1,
      "y": 9,
      "z": -2,
      "name": "Empty",
      "level": 0
    },
    {
      "x": 1,
      "y": 0,
      "z": -1,
      "name": "Empty",
      "level": 0
    },
    {
      "x": 1,
      "y": 4,
      "z": -1,
      "name": "Empty",
      "level": 0
    },
    {
      "x": 1,
      "y": 10,
      "z": -1,
      "name": "Empty",
      "level": 0
    },
    {
      "x": 1,
      "y": 0,
      "z": 0,
      "name": "Empty",
      "level": 0
    },
    {
      "x": 1,
      "y": 4,
      "z": 0,
      "name": "Empty",
      "level": 0
    },
    {
      "x": 1,
      "y": 11,
      "z": 0,
      "name": "Empty",
      "level": 0
    },
    {
      "x": 1,
      "y": 0,
      "z": 1,
      "name": "Empty",
      "level": 0
    },
    {
      "x": 1,
      "y": 4,
      "z": 1,
      "name": "Empty",
      "level": 0
    },
    {
      "x": 1,
      "y": 10,
      "z": 1,
      "name": "Empty",
      "level": 0
    },
    {
      "x": 1,
      "y": 0,
      "z": 2,
      "name": "Empty",
      "level": 0
    },
    {
      "x": 1,
      "y": 4,
      "z": 2,
      "name": "Empty",
      "level": 0
    },
    {
      "x": 1,
      "y": 5,
      "z": 2,
      "name": "Empty",
      "level": 0
    },
    {
      "x": 1,
      "y": 6,
      "z": 2,
      "name": "Empty",
      "level": 0
    },
    {
      "x": 1,
      "y": 7,
      "z": 2,
      "name": "Empty",
      "level": 0
    },
    {
      "x": 1,
      "y": 8,
      "z": 2,
      "name": "Empty",
      "level": 0
    },
    {
      "x": 1,
      "y": 9,
      "z": 2,
      "name": "Empty",
      "level": 0
    },
    {
      "x": 2,
      "y": 0,
      "z": -2,
      "name": "Empty",
      "level": 0
    },
    {
      "x": 2,
      "y": 4,
      "z": -2,
      "name": "Empty",
      "level": 0
    },
    {
      "x": 2,
      "y": 5,
      "z": -2,
      "name": "Empty",
      "level": 0
    },
    {
      "x": 2,
      "y": 8,
      "z": -2,
      "name": "Empty",
      "level": 0
    },
    {
      "x": 2,
      "y": 9,
      "z": -2,
      "name": "Empty",
      "level": 0
    },
    {
      "x": 2,
      "y": 0,
      "z": -1,
      "name": "Empty",
      "level": 0
    },
    {
      "x": 2,
      "y": 1,
      "z": -1,
      "name": "Empty",
      "level": 0
    },
    {
      "x": 2,
      "y": 2,
      "z": -1,
      "name": "Empty",
      "level": 0
    },
    {
      "x": 2,
      "y": 3,
      "z": -1,
      "name": "Empty",
      "level": 0
    },
    {
      "x": 2,
      "y": 4,
      "z": -1,
      "name": "Empty",
      "level": 0
    },
    {
      "x": 2,
      "y": 10,
      "z": -1,
      "name": "Empty",
      "level": 0
    },
    {
      "x": 2,
      "y": 0,
      "z": 0,
      "name": "Empty",
      "level": 0
    },
    {
      "x": 2,
      "y": 4,
      "z": 0,
      "name": "Empty",
      "level": 0
    },
    {
      "x": 2,
      "y": 10,
      "z": 0,
      "name": "Empty",
      "level": 0
    },
    {
      "x": 2,
      "y": 0,
      "z": 1,
      "name": "Empty",
      "level": 0
    },
    {
      "x": 2,
      "y": 1,
      "z": 1,
      "name": "Empty",
      "level": 0
    },
    {
      "x": 2,
      "y": 2,
      "z": 1,
      "name": "Empty",
      "level": 0
    },
    {
      "x": 2,
      "y": 3,
      "z": 1,
      "name": "Empty",
      "level": 0
    },
    {
      "x": 2,
      "y": 4,
      "z": 1,
      "name": "Empty",
      "level": 0
    },
    {
      "x": 2,
      "y": 10,
      "z": 1,
      "name": "Empty",
      "level": 0
    },
    {
      "x": 2,
      "y": 0,
      "z": 2,
      "name": "Empty",
      "level": 0
    },
    {
      "x": 2,
      "y": 4,
      "z": 2,
      "name": "Empty",
      "level": 0
    },
    {
      "x": 2,
      "y": 5,
      "z": 2,
      "name": "Empty",
      "level": 0
    },
    {
      "x": 2,
      "y": 8,
      "z": 2,
      "name": "Empty",
      "level": 0
    },
    {
      "x": 2,
      "y": 9,
      "z": 2,
      "name": "Empty",
      "level": 0
    },
    {
      "x": 3,
      "y": 0,
      "z": -2,
      "name": "Empty",
      "level": 0
    },
    {
      "x": 3,
      "y": 4,
      "z": -2,
      "name": "Empty",
      "level": 0
    },
    {
      "x": 3,
      "y": 5,
      "z": -2,
      "name": "Empty",
      "level": 0
    },
    {
      "x": 3,
      "y": 6,
      "z": -2,
      "name": "Empty",
      "level": 0
    },
    {
      "x": 3,
      "y": 7,
      "z": -2,
      "name": "Empty",
      "level": 0
    },
    {
      "x": 3,
      "y": 8,
      "z": -2,
      "name": "Empty",
      "level": 0
    },
    {
      "x": 3,
      "y": 9,
      "z": -2,
      "name": "Empty",
      "level": 0
    },
    {
      "x": 3,
      "y": 0,
      "z": -1,
      "name": "Empty",
      "level": 0
    },
    {
      "x": 3,
      "y": 4,
      "z": -1,
      "name": "Empty",
      "level": 0
    },
    {
      "x": 3,
      "y": 5,
      "z": -1,
      "name": "Empty",
      "level": 0
    },
    {
      "x": 3,
      "y": 6,
      "z": -1,
      "name": "Empty",
      "level": 0
    },
    {
      "x": 3,
      "y": 7,
      "z": -1,
      "name": "Empty",
      "level": 0
    },
    {
      "x": 3,
      "y": 8,
      "z": -1,
      "name": "Empty",
      "level": 0
    },
    {
      "x": 3,
      "y": 9,
      "z": -1,
      "name": "Empty",
      "level": 0
    },
    {
      "x": 3,
      "y": 0,
      "z": 0,
      "name": "Empty",
      "level": 0
    },
    {
      "x": 3,
      "y": 4,
      "z": 0,
      "name": "Empty",
      "level": 0
    },
    {
      "x": 3,
      "y": 5,
      "z": 0,
      "name": "Empty",
      "level": 0
    },
    {
      "x": 3,
      "y": 8,
      "z": 0,
      "name": "Empty",
      "level": 0
    },
    {
      "x": 3,
      "y": 9,
      "z": 0,
      "name": "Empty",
      "level": 0
    },
    {
      "x": 3,
      "y": 0,
      "z": 1,
      "name": "Empty",
      "level": 0
    },
    {
      "x": 3,
      "y": 4,
      "z": 1,
      "name": "Empty",
      "level": 0
    },
    {
      "x": 3,
      "y": 5,
      "z": 1,
      "name": "Empty",
      "level": 0
    },
    {
      "x": 3,
      "y": 6,
      "z": 1,
      "name": "Empty",
      "level": 0
    },
    {
      "x": 3,
      "y": 7,
      "z": 1,
      "name": "Empty",
      "level": 0
    },
    {
      "x": 3,
      "y": 8,
      "z": 1,
      "name": "Empty",
      "level": 0
    },
    {
      "x": 3,
      "y": 9,
      "z": 1,
      "name": "Empty",
      "level": 0
    },
    {
      "x": 3,
      "y": 0,
      "z": 2,
      "name": "Empty",
      "level": 0
    },
    {
      "x": 3,
      "y": 4,
      "z": 2,
      "name": "Empty",
      "level": 0
    },
    {
      "x": 3,
      "y": 5,
      "z": 2,
      "name": "Empty",
      "level": 0
    },
    {
      "x": 3,
      "y": 6,
      "z": 2,
      "name": "Empty",
      "level": 0
    },
    {
      "x": 3,
      "y": 7,
      "z": 2,
      "name": "Empty",
      "level": 0
    },
    {
      "x": 3,
      "y": 8,
      "z": 2,
      "name": "Empty",
      "level": 0
    },
    {
      "x": 3,
      "y": 9,
      "z": 2,
      "name": "Empty",
      "level": 0
    }
  ]
}