{
  "version": 8,
  "blockIdVersion": 11,
  "anchorX": 0,
  "anchorY": 9,
  "anchorZ": 0,
  "blocks": [
    {
      "x": -10,
      "y": 9,
      "z": 10,
      "name": "Wood_Oak_Trunk_Full",
      "support": 15,
      "rotation": 4
    },
    {
      "x": -10,
      "y": 10,
      "z": 10,
      "name": "Wood_Oak_Trunk_Full",
      "support": 15,
      "rotation": 4
    },
    {
      "x": -10,
      "y": 9,
      "z": 11,
      "name": "Wood_Oak_Trunk_Full",
      "support": 15,
      "rotation": 4
    },
    {
      "x": -10,
      "y": 10,
      "z": 11,
      "name": "Wood_Oak_Trunk_Full",
      "support": 15,
      "rotation": 4
    },
    {
      "x": -9,
      "y": 8,
      "z": -9,
      "name": "Wood_Oak_Trunk_Full",
      "support": 15,
      "rotation": 4
    },
    {
      "x": -9,
      "y": 8,
      "z": -8,
      "name": "Wood_Oak_Trunk_Full",
      "support": 15,
      "rotation": 4
    },
    {
      "x": -9,
      "y": 9,
      "z": -8,
      "name": "Wood_Oak_Trunk_Full",
      "support": 15,
      "rotation": 4
    },
    {
      "x": -9,
      "y": 8,
      "z": -7,
      "name": "Wood_Oak_Trunk_Full",
      "support": 15,
      "rotation": 4
    },
    {
      "x": -9,
      "y": 9,
      "z": -7,
      "name": "Wood_Oak_Trunk_Full",
      "support": 15,
      "rotation": 4
    },
    {
      "x": -9,
      "y": 8,
      "z": -6,
      "name": "Wood_Oak_Trunk_Full",
      "support": 15,
      "rotation": 4
    },
    {
      "x": -9,
      "y": 9,
      "z": -6,
      "name": "Wood_Oak_Trunk_Full",
      "support": 15,
      "rotation": 4
    },
    {
      "x": -9,
      "y": 8,
      "z": -5,
      "name": "Wood_Oak_Trunk_Full",
      "support": 15,
      "rotation": 4
    },
    {
      "x": -9,
      "y": 9,
      "z": -5,
      "name": "Wood_Oak_Trunk_Full",
      "support": 15,
      "rotation": 4
    },
    {
      "x": -9,
      "y": 9,
      "z": -4,
      "name": "Wood_Oak_Trunk_Full",
      "support": 15,
      "rotation": 4
    },
    {
      "x": -9,
      "y": 9,
      "z": 10,
      "name": "Wood_Oak_Trunk_Full",
      "support": 15,
      "rotation": 4
    },
    {
      "x": -9,
      "y": 10,
      "z": 10,
      "name": "Wood_Oak_Trunk_Full",
      "support": 15,
      "rotation": 4
    },
    {
      "x": -9,
      "y": 11,
      "z": 10,
      "name": "Wood_Oak_Trunk_Full",
      "support": 15,
      "rotation": 4
    },
    {
      "x": -9,
      "y": 9,
      "z": 11,
      "name": "Wood_Oak_Trunk_Full",
      "support": 15,
      "rotation": 4
    },
    {
      "x": -9,
      "y": 10,
      "z": 11,
      "name": "Wood_Oak_Trunk_Full",
      "support": 15,
      "rotation": 4
    },
    {
      "x": -9,
      "y": 11,
      "z": 11,
      "name": "Wood_Oak_Trunk_Full",
      "support": 15,
      "rotation": 4
    },
    {
      "x": -8,
      "y": 8,
      "z": -8,
      "name": "Wood_Oak_Trunk_Full",
      "support": 15,
      "rotation": 4
    },
    {
      "x": -8,
      "y": 8,
      "z": -7,
      "name": "Wood_Oak_Trunk_Full",
      "support": 15,
      "rotation": 4
    },
    {
      "x": -8,
      "y": 9,
      "z": -7,
      "name": "Wood_Oak_Trunk_Full",
      "support": 15,
      "rotation": 4
    },
    {
      "x": -8,
      "y": 8,
      "z": -6,
      "name": "Wood_Oak_Trunk_Full",
      "support": 15,
      "rotation": 4
    },
    {
      "x": -8,
      "y": 9,
      "z": -6,
      "name": "Wood_Oak_Trunk_Full",
      "support": 15,
      "rotation": 4
    },
    {
      "x": -8,
      "y": 8,
      "z": -5,
      "name": "Wood_Oak_Trunk_Full",
      "support": 15,
      "rotation": 4
    },
    {
      "x": -8,
      "y": 9,
      "z": -5,
      "name": "Wood_Oak_Trunk_Full",
      "support": 15,
      "rotation": 4
    },
    {
      "x": -8,
      "y": 10,
      "z": -5,
      "name": "Wood_Oak_Trunk_Full",
      "support": 15,
      "rotation": 4
    },
    {
      "x": -8,
      "y": 9,
      "z": -4,
      "name": "Wood_Oak_Trunk_Full",
      "support": 15,
      "rotation": 4
    },
    {
      "x": -8,
      "y": 10,
      "z": -4,
      "name": "Wood_Oak_Trunk_Full",
      "support": 15,
      "rotation": 4
    },
    {
      "x": -8,
      "y": 9,
      "z": -3,
      "name": "Wood_Oak_Trunk_Full",
      "support": 15,
      "rotation": 4
    },
    {
      "x": -8,
      "y": 10,
      "z": -3,
      "name": "Wood_Oak_Trunk",
      "rotation": 4
    },
    {
      "x": -8,
      "y": 9,
      "z": -2,
      "name": "Wood_Oak_Trunk_Full",
      "support": 15,
      "rotation": 4
    },
    {
      "x": -8,
      "y": 10,
      "z": -2,
      "name": "Wood_Oak_Trunk",
      "rotation": 4
    },
    {
      "x": -8,
      "y": 10,
      "z": -1,
      "name": "Wood_Oak_Trunk_Full",
      "support": 1,
      "rotation": 4
    },
    {
      "x": -8,
      "y": 10,
      "z": 10,
      "name": "Wood_Oak_Trunk_Full",
      "support": 15,
      "rotation": 4
    },
    {
      "x": -8,
      "y": 11,
      "z": 10,
      "name": "Wood_Oak_Trunk_Full",
      "support": 15,
      "rotation": 4
    },
    {
      "x": -8,
      "y": 10,
      "z": 11,
      "name": "Wood_Oak_Trunk_Full",
      "support": 15,
      "rotation": 4
    },
    {
      "x": -8,
      "y": 11,
      "z": 11,
      "name": "Wood_Oak_Trunk_Full",
      "support": 15,
      "rotation": 4
    },
    {
      "x": -7,
      "y": 8,
      "z": -5,
      "name": "Wood_Oak_Trunk_Full",
      "support": 15,
      "rotation": 4
    },
    {
      "x": -7,
      "y": 9,
      "z": -5,
      "name": "Wood_Oak_Trunk_Full",
      "support": 15,
      "rotation": 4
    },
    {
      "x": -7,
      "y": 9,
      "z": -4,
      "name": "Wood_Oak_Trunk_Full",
      "support": 15,
      "rotation": 4
    },
    {
      "x": -7,
      "y": 10,
      "z": -4,
      "name": "Wood_Oak_Trunk_Full",
      "support": 15,
      "rotation": 4
    },
    {
      "x": -7,
      "y": 9,
      "z": -3,
      "name": "Wood_Oak_Trunk_Full",
      "support": 15,
      "rotation": 4
    },
    {
      "x": -7,
      "y": 10,
      "z": -3,
      "name": "Wood_Oak_Trunk",
      "rotation": 4
    },
    {
      "x": -7,
      "y": 9,
      "z": -2,
      "name": "Wood_Oak_Trunk",
      "support": 2,
      "rotation": 4
    },
    {
      "x": -7,
      "y": 10,
      "z": -2,
      "name": "Wood_Oak_Trunk",
      "rotation": 4
    },
    {
      "x": -7,
      "y": 9,
      "z": -1,
      "name": "Wood_Oak_Trunk",
      "support": 3,
      "rotation": 4
    },
    {
      "x": -7,
      "y": 10,
      "z": -1,
      "name": "Wood_Oak_Trunk",
      "rotation": 4
    },
    {
      "x": -7,
      "y": 9,
      "z": 0,
      "name": "Wood_Oak_Trunk_Full",
      "support": 4,
      "rotation": 4
    },
    {
      "x": -7,
      "y": 10,
      "z": 0,
      "name": "Wood_Oak_Trunk_Full",
      "rotation": 4
    },
    {
      "x": -7,
      "y": 11,
      "z": 9,
      "name": "Wood_Oak_Trunk_Full",
      "support": 1,
      "rotation": 4
    },
    {
      "x": -7,
      "y": 12,
      "z": 9,
      "name": "Wood_Oak_Trunk_Full",
      "rotation": 4
    },
    {
      "x": -7,
      "y": 10,
      "z": 10,
      "name": "Wood_Oak_Trunk_Full",
      "support": 15,
      "rotation": 4
    },
    {
      "x": -7,
      "y": 11,
      "z": 10,
      "name": "Wood_Oak_Trunk_Full",
      "rotation": 4
    },
    {
      "x": -7,
      "y": 12,
      "z": 10,
      "name": "Wood_Oak_Trunk_Full",
      "support": 15,
      "rotation": 4
    },
    {
      "x": -7,
      "y": 10,
      "z": 11,
      "name": "Wood_Oak_Trunk_Full",
      "support": 15,
      "rotation": 4
    },
    {
      "x": -7,
      "y": 11,
      "z": 11,
      "name": "Wood_Oak_Trunk_Full",
      "support": 15,
      "rotation": 4
    },
    {
      "x": -6,
      "y": 9,
      "z": -4,
      "name": "Wood_Oak_Trunk_Full",
      "support": 15,
      "rotation": 4
    },
    {
      "x": -6,
      "y": 9,
      "z": -3,
      "name": "Wood_Oak_Trunk",
      "support": 2,
      "rotation": 4
    },
    {
      "x": -6,
      "y": 10,
      "z": -3,
      "name": "Wood_Oak_Trunk_Full",
      "rotation": 4
    },
    {
      "x": -6,
      "y": 14,
      "z": -3,
      "name": "Wood_Oak_Trunk_Full",
      "support": 2,
      "rotation": 4
    },
    {
      "x": -6,
      "y": 9,
      "z": -2,
      "name": "Wood_Oak_Trunk",
      "support": 3,
      "rotation": 4
    },
    {
      "x": -6,
      "y": 10,
      "z": -2,
      "name": "Wood_Oak_Trunk",
      "rotation": 4
    },
    {
      "x": -6,
      "y": 11,
      "z": -2,
      "name": "Wood_Oak_Trunk_Full",
      "rotation": 4
    },
    {
      "x": -6,
      "y": 14,
      "z": -2,
      "name": "Wood_Oak_Trunk_Full",
      "support": 15,
      "rotation": 4
    },
    {
      "x": -6,
      "y": 9,
      "z": -1,
      "name": "Wood_Oak_Trunk",
      "support": 4,
      "rotation": 4
    },
    {
      "x": -6,
      "y": 10,
      "z": -1,
      "name": "Wood_Oak_Trunk",
      "rotation": 4
    },
    {
      "x": -6,
      "y": 11,
      "z": -1,
      "name": "Wood_Oak_Trunk_Full",
      "rotation": 4
    },
    {
      "x": -6,
      "y": 14,
      "z": -1,
      "name": "Wood_Oak_Trunk_Full",
      "support": 2,
      "rotation": 4
    },
    {
      "x": -6,
      "y": 9,
      "z": 0,
      "name": "Wood_Oak_Trunk_Full",
      "support": 4,
      "rotation": 4
    },
    {
      "x": -6,
      "y": 10,
      "z": 0,
      "name": "Wood_Oak_Trunk_Full",
      "rotation": 4
    },
    {
      "x": -6,
      "y": 10,
      "z": 9,
      "name": "Wood_Oak_Trunk_Full",
      "support": 3,
      "rotation": 4
    },
    {
      "x": -6,
      "y": 11,
      "z": 9,
      "name": "Wood_Oak_Trunk_Full",
      "rotation": 4
    },
    {
      "x": -6,
      "y": 12,
      "z": 9,
      "name": "Wood_Oak_Trunk_Full",
      "rotation": 4
    },
    {
      "x": -6,
      "y": 10,
      "z": 10,
      "name": "Wood_Oak_Trunk_Full",
      "support": 2,
      "rotation": 4
    },
    {
      "x": -6,
      "y": 11,
      "z": 10,
      "name": "Wood_Oak_Trunk_Full",
      "rotation": 4
    },
    {
      "x": -6,
      "y": 12,
      "z": 10,
      "name": "Wood_Oak_Trunk_Full",
      "rotation": 4
    },
    {
      "x": -5,
      "y": 3,
      "z": -10,
      "name": "Wood_Oak_Trunk_Full",
      "rotation": 4
    },
    {
      "x": -5,
      "y": 3,
      "z": -9,
      "name": "Wood_Oak_Trunk",
      "rotation": 4
    },
    {
      "x": -5,
      "y": 3,
      "z": -8,
      "name": "Wood_Oak_Trunk_Full",
      "rotation": 4
    },
    {
      "x": -5,
      "y": 4,
      "z": -8,
      "name": "Wood_Oak_Trunk_Full",
      "rotation": 4
    },
    {
      "x": -5,
      "y": 9,
      "z": -3,
      "name": "Wood_Oak_Trunk_Full",
      "support": 3,
      "rotation": 4
    },
    {
      "x": -5,
      "y": 10,
      "z": -3,
      "name": "Wood_Oak_Trunk_Full",
      "rotation": 4
    },
    {
      "x": -5,
      "y": 14,
      "z": -3,
      "name": "Wood_Oak_Trunk_Full",
      "support": 1,
      "rotation": 4
    },
    {
      "x": -5,
      "y": 15,
      "z": -3,
      "name": "Wood_Oak_Trunk_Full",
      "support": 15,
      "rotation": 4
    },
    {
      "x": -5,
      "y": 9,
      "z": -2,
      "name": "Wood_Oak_Trunk",
      "support": 3,
      "rotation": 4
    },
    {
      "x": -5,
      "y": 10,
      "z": -2,
      "name": "Wood_Oak_Trunk",
      "rotation": 4
    },
    {
      "x": -5,
      "y": 11,
      "z": -2,
      "name": "Wood_Oak_Trunk_Full",
      "rotation": 4
    },
    {
      "x": -5,
      "y": 12,
      "z": -2,
      "name": "Wood_Oak_Trunk_Full",
      "rotation": 4
    },
    {
      "x": -5,
      "y": 13,
      "z": -2,
      "name": "Wood_Oak_Trunk_Full",
      "rotation": 4
    },
    {
      "x": -5,
      "y": 14,
      "z": -2,
      "name": "Wood_Oak_Trunk",
      "rotation": 4
    },
    {
      "x": -5,
      "y": 15,
      "z": -2,
      "name": "Wood_Oak_Trunk",
      "rotation": 4
    },
    {
      "x": -5,
      "y": 9,
      "z": -1,
      "name": "Wood_Oak_Trunk",
      "support": 3,
      "rotation": 4
    },
    {
      "x": -5,
      "y": 10,
      "z": -1,
      "name": "Wood_Oak_Trunk",
      "rotation": 4
    },
    {
      "x": -5,
      "y": 11,
      "z": -1,
      "name": "Wood_Oak_Trunk",
      "rotation": 4
    },
    {
      "x": -5,
      "y": 12,
      "z": -1,
      "name": "Wood_Oak_Trunk",
      "rotation": 4
    },
    {
      "x": -5,
      "y": 13,
      "z": -1,
      "name": "Wood_Oak_Trunk",
      "rotation": 4
    },
    {
      "x": -5,
      "y": 14,
      "z": -1,
      "name": "Wood_Oak_Trunk_Full",
      "rotation": 4
    },
    {
      "x": -5,
      "y": 15,
      "z": -1,
      "name": "Wood_Oak_Trunk_Full",
      "support": 15,
      "rotation": 4
    },
    {
      "x": -5,
      "y": 9,
      "z": 0,
      "name": "Wood_Oak_Trunk_Full",
      "support": 3,
      "rotation": 4
    },
    {
      "x": -5,
      "y": 10,
      "z": 0,
      "name": "Wood_Oak_Trunk",
      "rotation": 4
    },
    {
      "x": -5,
      "y": 11,
      "z": 0,
      "name": "Wood_Oak_Trunk_Full",
      "rotation": 4
    },
    {
      "x": -5,
      "y": 12,
      "z": 0,
      "name": "Wood_Oak_Trunk_Full",
      "rotation": 4
    },
    {
      "x": -5,
      "y": 13,
      "z": 0,
      "name": "Wood_Oak_Trunk_Full",
      "rotation": 4
    },
    {
      "x": -5,
      "y": 10,
      "z": 1,
      "name": "Wood_Oak_Trunk_Full",
      "support": 1,
      "rotation": 4
    },
    {
      "x": -5,
      "y": 10,
      "z": 8,
      "name": "Wood_Oak_Trunk_Full",
      "support": 2,
      "rotation": 4
    },
    {
      "x": -5,
      "y": 11,
      "z": 8,
      "name": "Wood_Oak_Trunk_Full",
      "rotation": 4
    },
    {
      "x": -5,
      "y": 10,
      "z": 9,
      "name": "Wood_Oak_Trunk",
      "support": 3,
      "rotation": 4
    },
    {
      "x": -5,
      "y": 11,
      "z": 9,
      "name": "Wood_Oak_Trunk",
      "rotation": 4
    },
    {
      "x": -5,
      "y": 12,
      "z": 9,
      "name": "Wood_Oak_Trunk_Full",
      "rotation": 4
    },
    {
      "x": -5,
      "y": 10,
      "z": 10,
      "name": "Wood_Oak_Trunk_Full",
      "support": 3,
      "rotation": 4
    },
    {
      "x": -5,
      "y": 11,
      "z": 10,
      "name": "Wood_Oak_Trunk_Full",
      "rotation": 4
    },
    {
      "x": -5,
      "y": 12,
      "z": 10,
      "name": "Wood_Oak_Trunk_Full",
      "rotation": 4
    },
    {
      "x": -4,
      "y": 3,
      "z": -11,
      "name": "Wood_Oak_Trunk_Full",
      "rotation": 4
    },
    {
      "x": -4,
      "y": 2,
      "z": -10,
      "name": "Wood_Oak_Trunk_Full",
      "rotation": 4
    },
    {
      "x": -4,
      "y": 3,
      "z": -10,
      "name": "Wood_Oak_Trunk",
      "rotation": 4
    },
    {
      "x": -4,
      "y": 4,
      "z": -10,
      "name": "Wood_Oak_Trunk_Full",
      "rotation": 4
    },
    {
      "x": -4,
      "y": 2,
      "z": -9,
      "name": "Wood_Oak_Trunk",
      "rotation": 4
    },
    {
      "x": -4,
      "y": 3,
      "z": -9,
      "name": "Wood_Oak_Trunk",
      "rotation": 4
    },
    {
      "x": -4,
      "y": 4,
      "z": -9,
      "name": "Wood_Oak_Trunk",
      "rotation": 4
    },
    {
      "x": -4,
      "y": 2,
      "z": -8,
      "name": "Wood_Oak_Trunk_Full",
      "rotation": 4
    },
    {
      "x": -4,
      "y": 3,
      "z": -8,
      "name": "Wood_Oak_Trunk",
      "rotation": 4
    },
    {
      "x": -4,
      "y": 4,
      "z": -8,
      "name": "Wood_Oak_Trunk",
      "rotation": 4
    },
    {
      "x": -4,
      "y": 5,
      "z": -8,
      "name": "Wood_Oak_Trunk_Full",
      "rotation": 4
    },
    {
      "x": -4,
      "y": 3,
      "z": -7,
      "name": "Wood_Oak_Trunk_Full",
      "rotation": 4
    },
    {
      "x": -4,
      "y": 4,
      "z": -7,
      "name": "Wood_Oak_Trunk_Full",
      "rotation": 4
    },
    {
      "x": -4,
      "y": 5,
      "z": -7,
      "name": "Wood_Oak_Trunk",
      "rotation": 4
    },
    {
      "x": -4,
      "y": 5,
      "z": -6,
      "name": "Wood_Oak_Trunk_Full",
      "rotation": 4
    },
    {
      "x": -4,
      "y": 14,
      "z": -3,
      "name": "Wood_Oak_Trunk_Full",
      "support": 15,
      "rotation": 4
    },
    {
      "x": -4,
      "y": 15,
      "z": -3,
      "name": "Wood_Oak_Trunk_Full",
      "rotation": 4
    },
    {
      "x": -4,
      "y": 9,
      "z": -2,
      "name": "Wood_Oak_Trunk_Full",
      "support": 2,
      "rotation": 4
    },
    {
      "x": -4,
      "y": 10,
      "z": -2,
      "name": "Wood_Oak_Trunk_Full",
      "rotation": 4
    },
    {
      "x": -4,
      "y": 11,
      "z": -2,
      "name": "Wood_Oak_Trunk_Full",
      "rotation": 4
    },
    {
      "x": -4,
      "y": 12,
      "z": -2,
      "name": "Wood_Oak_Trunk_Full",
      "rotation": 4
    },
    {
      "x": -4,
      "y": 13,
      "z": -2,
      "name": "Wood_Oak_Trunk_Full",
      "rotation": 4
    },
    {
      "x": -4,
      "y": 14,
      "z": -2,
      "name": "Wood_Oak_Trunk",
      "rotation": 4
    },
    {
      "x": -4,
      "y": 15,
      "z": -2,
      "name": "Wood_Oak_Trunk",
      "rotation": 4
    },
    {
      "x": -4,
      "y": 9,
      "z": -1,
      "name": "Wood_Oak_Trunk",
      "support": 2,
      "rotation": 4
    },
    {
      "x": -4,
      "y": 10,
      "z": -1,
      "name": "Wood_Oak_Trunk",
      "rotation": 4
    },
    {
      "x": -4,
      "y": 11,
      "z": -1,
      "name": "Wood_Oak_Trunk",
      "rotation": 4
    },
    {
      "x": -4,
      "y": 12,
      "z": -1,
      "name": "Wood_Oak_Trunk",
      "rotation": 4
    },
    {
      "x": -4,
      "y": 13,
      "z": -1,
      "name": "Wood_Oak_Trunk",
      "rotation": 4
    },
    {
      "x": -4,
      "y": 14,
      "z": -1,
      "name": "Wood_Oak_Trunk",
      "rotation": 4
    },
    {
      "x": -4,
      "y": 15,
      "z": -1,
      "name": "Wood_Oak_Trunk_Full",
      "rotation": 4
    },
    {
      "x": -4,
      "y": 9,
      "z": 0,
      "name": "Wood_Oak_Trunk",
      "support": 2,
      "rotation": 4
    },
    {
      "x": -4,
      "y": 10,
      "z": 0,
      "name": "Wood_Oak_Trunk",
      "rotation": 4
    },
    {
      "x": -4,
      "y": 11,
      "z": 0,
      "name": "Wood_Oak_Trunk",
      "rotation": 4
    },
    {
      "x": -4,
      "y": 12,
      "z": 0,
      "name": "Wood_Oak_Trunk",
      "rotation": 4
    },
    {
      "x": -4,
      "y": 13,
      "z": 0,
      "name": "Wood_Oak_Trunk",
      "rotation": 4
    },
    {
      "x": -4,
      "y": 14,
      "z": 0,
      "name": "Wood_Oak_Trunk_Full",
      "rotation": 4
    },
    {
      "x": -4,
      "y": 9,
      "z": 1,
      "name": "Wood_Oak_Trunk",
      "support": 2,
      "rotation": 4
    },
    {
      "x": -4,
      "y": 10,
      "z": 1,
      "name": "Wood_Oak_Trunk",
      "rotation": 4
    },
    {
      "x": -4,
      "y": 11,
      "z": 1,
      "name": "Wood_Oak_Trunk",
      "rotation": 4
    },
    {
      "x": -4,
      "y": 12,
      "z": 1,
      "name": "Wood_Oak_Trunk",
      "rotation": 4
    },
    {
      "x": -4,
      "y": 13,
      "z": 1,
      "name": "Wood_Oak_Trunk_Full",
      "rotation": 4
    },
    {
      "x": -4,
      "y": 9,
      "z": 2,
      "name": "Wood_Oak_Trunk_Full",
      "support": 2,
      "rotation": 4
    },
    {
      "x": -4,
      "y": 10,
      "z": 2,
      "name": "Wood_Oak_Trunk",
      "rotation": 4
    },
    {
      "x": -4,
      "y": 11,
      "z": 2,
      "name": "Wood_Oak_Trunk",
      "rotation": 4
    },
    {
      "x": -4,
      "y": 12,
      "z": 2,
      "name": "Wood_Oak_Trunk",
      "rotation": 4
    },
    {
      "x": -4,
      "y": 10,
      "z": 3,
      "name": "Wood_Oak_Trunk",
      "support": 1,
      "rotation": 4
    },
    {
      "x": -4,
      "y": 11,
      "z": 3,
      "name": "Wood_Oak_Trunk",
      "rotation": 4
    },
    {
      "x": -4,
      "y": 12,
      "z": 3,
      "name": "Wood_Oak_Trunk_Full",
      "rotation": 4
    },
    {
      "x": -4,
      "y": 10,
      "z": 4,
      "name": "Wood_Oak_Trunk",
      "support": 1,
      "rotation": 4
    },
    {
      "x": -4,
      "y": 11,
      "z": 4,
      "name": "Wood_Oak_Trunk",
      "rotation": 4
    },
    {
      "x": -4,
      "y": 10,
      "z": 5,
      "name": "Wood_Oak_Trunk",
      "support": 1,
      "rotation": 4
    },
    {
      "x": -4,
      "y": 11,
      "z": 5,
      "name": "Wood_Oak_Trunk",
      "rotation": 4
    },
    {
      "x": -4,
      "y": 9,
      "z": 6,
      "name": "Wood_Oak_Trunk_Full",
      "support": 4,
      "rotation": 4
    },
    {
      "x": -4,
      "y": 10,
      "z": 6,
      "name": "Wood_Oak_Trunk",
      "rotation": 4
    },
    {
      "x": -4,
      "y": 11,
      "z": 6,
      "name": "Wood_Oak_Trunk",
      "rotation": 4
    },
    {
      "x": -4,
      "y": 9,
      "z": 7,
      "name": "Wood_Oak_Trunk",
      "support": 5,
      "rotation": 4
    },
    {
      "x": -4,
      "y": 10,
      "z": 7,
      "name": "Wood_Oak_Trunk",
      "rotation": 4
    },
    {
      "x": -4,
      "y": 11,
      "z": 7,
      "name": "Wood_Oak_Trunk",
      "rotation": 4
    },
    {
      "x": -4,
      "y": 10,
      "z": 8,
      "name": "Wood_Oak_Trunk",
      "support": 1,
      "rotation": 4
    },
    {
      "x": -4,
      "y": 11,
      "z": 8,
      "name": "Wood_Oak_Trunk",
      "rotation": 4
    },
    {
      "x": -4,
      "y": 10,
      "z": 9,
      "name": "Wood_Oak_Trunk",
      "support": 2,
      "rotation": 4
    },
    {
      "x": -4,
      "y": 11,
      "z": 9,
      "name": "Wood_Oak_Trunk",
      "rotation": 4
    },
    {
      "x": -4,
      "y": 10,
      "z": 10,
      "name": "Wood_Oak_Trunk_Full",
      "support": 3,
      "rotation": 4
    },
    {
      "x": -4,
      "y": 11,
      "z": 10,
      "name": "Wood_Oak_Trunk_Full",
      "rotation": 4
    },
    {
      "x": -3,
      "y": 3,
      "z": -10,
      "name": "Wood_Oak_Trunk_Full",
      "rotation": 4
    },
    {
      "x": -3,
      "y": 3,
      "z": -9,
      "name": "Wood_Oak_Trunk",
      "rotation": 4
    },
    {
      "x": -3,
      "y": 3,
      "z": -8,
      "name": "Wood_Oak_Trunk_Full",
      "rotation": 4
    },
    {
      "x": -3,
      "y": 4,
      "z": -8,
      "name": "Wood_Oak_Trunk_Full",
      "rotation": 4
    },
    {
      "x": -3,
      "y": 5,
      "z": -8,
      "name": "Wood_Oak_Trunk_Full",
      "rotation": 4
    },
    {
      "x": -3,
      "y": 4,
      "z": -7,
      "name": "Wood_Oak_Trunk",
      "rotation": 4
    },
    {
      "x": -3,
      "y": 5,
      "z": -7,
      "name": "Wood_Oak_Trunk",
      "rotation": 4
    },
    {
      "x": -3,
      "y": 6,
      "z": -7,
      "name": "Wood_Oak_Trunk_Full",
      "rotation": 4
    },
    {
      "x": -3,
      "y": 4,
      "z": -6,
      "name": "Wood_Oak_Trunk_Full",
      "rotation": 4
    },
    {
      "x": -3,
      "y": 5,
      "z": -6,
      "name": "Wood_Oak_Trunk",
      "rotation": 4
    },
    {
      "x": -3,
      "y": 6,
      "z": -6,
      "name": "Wood_Oak_Trunk_Full",
      "rotation": 4
    },
    {
      "x": -3,
      "y": 5,
      "z": -5,
      "name": "Wood_Oak_Trunk",
      "rotation": 4
    },
    {
      "x": -3,
      "y": 5,
      "z": -4,
      "name": "Wood_Oak_Trunk",
      "rotation": 4
    },
    {
      "x": -3,
      "y": 5,
      "z": -3,
      "name": "Wood_Oak_Trunk_Full",
      "rotation": 4
    },
    {
      "x": -3,
      "y": 14,
      "z": -3,
      "name": "Wood_Oak_Trunk_Full",
      "support": 1,
      "rotation": 4
    },
    {
      "x": -3,
      "y": 15,
      "z": -3,
      "name": "Wood_Oak_Trunk_Full",
      "rotation": 4
    },
    {
      "x": -3,
      "y": 9,
      "z": -2,
      "name": "Wood_Oak_Trunk_Full",
      "support": 1,
      "rotation": 4
    },
    {
      "x": -3,
      "y": 10,
      "z": -2,
      "name": "Wood_Oak_Trunk_Full",
      "rotation": 4
    },
    {
      "x": -3,
      "y": 13,
      "z": -2,
      "name": "Wood_Oak_Trunk_Full",
      "support": 1,
      "rotation": 4
    },
    {
      "x": -3,
      "y": 14,
      "z": -2,
      "name": "Wood_Oak_Trunk",
      "rotation": 4
    },
    {
      "x": -3,
      "y": 15,
      "z": -2,
      "name": "Wood_Oak_Trunk",
      "rotation": 4
    },
    {
      "x": -3,
      "y": 9,
      "z": -1,
      "name": "Wood_Oak_Trunk",
      "support": 1,
      "rotation": 4
    },
    {
      "x": -3,
      "y": 10,
      "z": -1,
      "name": "Wood_Oak_Trunk",
      "rotation": 4
    },
    {
      "x": -3,
      "y": 11,
      "z": -1,
      "name": "Wood_Oak_Trunk_Full",
      "rotation": 4
    },
    {
      "x": -3,
      "y": 12,
      "z": -1,
      "name": "Wood_Oak_Trunk_Full",
      "rotation": 4
    },
    {
      "x": -3,
      "y": 13,
      "z": -1,
      "name": "Wood_Oak_Trunk",
      "rotation": 4
    },
    {
      "x": -3,
      "y": 14,
      "z": -1,
      "name": "Wood_Oak_Trunk",
      "rotation": 4
    },
    {
      "x": -3,
      "y": 15,
      "z": -1,
      "name": "Wood_Oak_Trunk",
      "rotation": 4
    },
    {
      "x": -3,
      "y": 9,
      "z": 0,
      "name": "Wood_Oak_Trunk",
      "support": 1,
      "rotation": 4
    },
    {
      "x": -3,
      "y": 10,
      "z": 0,
      "name": "Wood_Oak_Trunk",
      "rotation": 4
    },
    {
      "x": -3,
      "y": 11,
      "z": 0,
      "name": "Wood_Oak_Trunk",
      "rotation": 4
    },
    {
      "x": -3,
      "y": 12,
      "z": 0,
      "name": "Wood_Oak_Trunk",
      "rotation": 4
    },
    {
      "x": -3,
      "y": 13,
      "z": 0,
      "name": "Wood_Oak_Trunk",
      "rotation": 4
    },
    {
      "x": -3,
      "y": 14,
      "z": 0,
      "name": "Wood_Oak_Trunk",
      "rotation": 4
    },
    {
      "x": -3,
      "y": 15,
      "z": 0,
      "name": "Wood_Oak_Trunk_Full",
      "rotation": 4
    },
    {
      "x": -3,
      "y": 9,
      "z": 1,
      "name": "Wood_Oak_Trunk",
      "support": 1,
      "rotation": 4
    },
    {
      "x": -3,
      "y": 10,
      "z": 1,
      "name": "Wood_Oak_Trunk",
      "rotation": 4
    },
    {
      "x": -3,
      "y": 11,
      "z": 1,
      "name": "Wood_Oak_Trunk",
      "rotation": 4
    },
    {
      "x": -3,
      "y": 12,
      "z": 1,
      "name": "Wood_Oak_Trunk",
      "rotation": 4
    },
    {
      "x": -3,
      "y": 13,
      "z": 1,
      "name": "Wood_Oak_Trunk",
      "rotation": 4
    },
    {
      "x": -3,
      "y": 14,
      "z": 1,
      "name": "Wood_Oak_Trunk_Full",
      "rotation": 4
    },
    {
      "x": -3,
      "y": 9,
      "z": 2,
      "name": "Wood_Oak_Trunk",
      "support": 1,
      "rotation": 4
    },
    {
      "x": -3,
      "y": 10,
      "z": 2,
      "name": "Wood_Oak_Trunk",
      "rotation": 4
    },
    {
      "x": -3,
      "y": 11,
      "z": 2,
      "name": "Wood_Oak_Trunk",
      "rotation": 4
    },
    {
      "x": -3,
      "y": 12,
      "z": 2,
      "name": "Wood_Oak_Trunk",
      "rotation": 4
    },
    {
      "x": -3,
      "y": 13,
      "z": 2,
      "name": "Wood_Oak_Trunk",
      "rotation": 4
    },
    {
      "x": -3,
      "y": 9,
      "z": 3,
      "name": "Wood_Oak_Trunk",
      "support": 1,
      "rotation": 4
    },
    {
      "x": -3,
      "y": 10,
      "z": 3,
      "name": "Wood_Oak_Trunk",
      "rotation": 4
    },
    {
      "x": -3,
      "y": 11,
      "z": 3,
      "name": "Wood_Oak_Trunk",
      "rotation": 4
    },
    {
      "x": -3,
      "y": 12,
      "z": 3,
      "name": "Wood_Oak_Trunk",
      "rotation": 4
    },
    {
      "x": -3,
      "y": 13,
      "z": 3,
      "name": "Wood_Oak_Trunk",
      "rotation": 4
    },
    {
      "x": -3,
      "y": 9,
      "z": 4,
      "name": "Wood_Oak_Trunk",
      "support": 1,
      "rotation": 4
    },
    {
      "x": -3,
      "y": 10,
      "z": 4,
      "name": "Wood_Oak_Trunk",
      "rotation": 4
    },
    {
      "x": -3,
      "y": 11,
      "z": 4,
      "name": "Wood_Oak_Trunk",
      "rotation": 4
    },
    {
      "x": -3,
      "y": 12,
      "z": 4,
      "name": "Wood_Oak_Trunk",
      "rotation": 4
    },
    {
      "x": -3,
      "y": 13,
      "z": 4,
      "name": "Wood_Oak_Trunk",
      "rotation": 4
    },
    {
      "x": -3,
      "y": 9,
      "z": 5,
      "name": "Wood_Oak_Trunk",
      "support": 2,
      "rotation": 4
    },
    {
      "x": -3,
      "y": 10,
      "z": 5,
      "name": "Wood_Oak_Trunk",
      "rotation": 4
    },
    {
      "x": -3,
      "y": 11,
      "z": 5,
      "name": "Wood_Oak_Trunk",
      "rotation": 4
    },
    {
      "x": -3,
      "y": 12,
      "z": 5,
      "name": "Wood_Oak_Trunk",
      "rotation": 4
    },
    {
      "x": -3,
      "y": 13,
      "z": 5,
      "name": "Wood_Oak_Trunk_Full",
      "rotation": 4
    },
    {
      "x": -3,
      "y": 9,
      "z": 6,
      "name": "Wood_Oak_Trunk",
      "support": 3,
      "rotation": 4
    },
    {
      "x": -3,
      "y": 10,
      "z": 6,
      "name": "Wood_Oak_Trunk",
      "rotation": 4
    },
    {
      "x": -3,
      "y": 11,
      "z": 6,
      "name": "Wood_Oak_Trunk",
      "rotation": 4
    },
    {
      "x": -3,
      "y": 12,
      "z": 6,
      "name": "Wood_Oak_Trunk",
      "rotation": 4
    },
    {
      "x": -3,
      "y": 9,
      "z": 7,
      "name": "Wood_Oak_Trunk",
      "support": 4,
      "rotation": 4
    },
    {
      "x": -3,
      "y": 10,
      "z": 7,
      "name": "Wood_Oak_Trunk",
      "rotation": 4
    },
    {
      "x": -3,
      "y": 11,
      "z": 7,
      "name": "Wood_Oak_Trunk",
      "rotation": 4
    },
    {
      "x": -3,
      "y": 12,
      "z": 7,
      "name": "Wood_Oak_Trunk",
      "rotation": 4
    },
    {
      "x": -3,
      "y": 9,
      "z": 8,
      "name": "Wood_Oak_Trunk",
      "support": 5,
      "rotation": 4
    },
    {
      "x": -3,
      "y": 10,
      "z": 8,
      "name": "Wood_Oak_Trunk",
      "rotation": 4
    },
    {
      "x": -3,
      "y": 11,
      "z": 8,
      "name": "Wood_Oak_Trunk",
      "rotation": 4
    },
    {
      "x": -3,
      "y": 12,
      "z": 8,
      "name": "Wood_Oak_Trunk",
      "rotation": 4
    },
    {
      "x": -3,
      "y": 10,
      "z": 9,
      "name": "Wood_Oak_Trunk_Full",
      "support": 1,
      "rotation": 4
    },
    {
      "x": -3,
      "y": 11,
      "z": 9,
      "name": "Wood_Oak_Trunk",
      "rotation": 4
    },
    {
      "x": -3,
      "y": 12,
      "z": 9,
      "name": "Wood_Oak_Trunk",
      "rotation": 4
    },
    {
      "x": -3,
      "y": 13,
      "z": 9,
      "name": "Wood_Oak_Trunk_Full",
      "rotation": 4
    },
    {
      "x": -3,
      "y": 11,
      "z": 10,
      "name": "Wood_Oak_Trunk_Full",
      "support": 1,
      "rotation": 4
    },
    {
      "x": -3,
      "y": 12,
      "z": 10,
      "name": "Wood_Oak_Trunk",
      "rotation": 4
    },
    {
      "x": -3,
      "y": 13,
      "z": 10,
      "name": "Wood_Oak_Trunk",
      "rotation": 4
    },
    {
      "x": -3,
      "y": 12,
      "z": 11,
      "name": "Wood_Oak_Trunk",
      "support": 15,
      "rotation": 4
    },
    {
      "x": -3,
      "y": 13,
      "z": 11,
      "name": "Wood_Oak_Trunk",
      "support": 15,
      "rotation": 4
    },
    {
      "x": -3,
      "y": 12,
      "z": 12,
      "name": "Wood_Oak_Trunk_Full",
      "support": 15,
      "rotation": 4
    },
    {
      "x": -3,
      "y": 13,
      "z": 12,
      "name": "Wood_Oak_Trunk_Full",
      "support": 15,
      "rotation": 4
    },
    {
      "x": -2,
      "y": 5,
      "z": -7,
      "name": "Wood_Oak_Trunk_Full",
      "rotation": 4
    },
    {
      "x": -2,
      "y": 4,
      "z": -6,
      "name": "Wood_Oak_Trunk_Full",
      "rotation": 4
    },
    {
      "x": -2,
      "y": 5,
      "z": -6,
      "name": "Wood_Oak_Trunk",
      "rotation": 4
    },
    {
      "x": -2,
      "y": 6,
      "z": -6,
      "name": "Wood_Oak_Trunk_Full",
      "rotation": 4
    },
    {
      "x": -2,
      "y": 4,
      "z": -5,
      "name": "Wood_Oak_Trunk",
      "rotation": 4
    },
    {
      "x": -2,
      "y": 5,
      "z": -5,
      "name": "Wood_Oak_Trunk",
      "rotation": 4
    },
    {
      "x": -2,
      "y": 6,
      "z": -5,
      "name": "Wood_Oak_Trunk",
      "rotation": 4
    },
    {
      "x": -2,
      "y": 4,
      "z": -4,
      "name": "Wood_Oak_Trunk",
      "rotation": 4
    },
    {
      "x": -2,
      "y": 5,
      "z": -4,
      "name": "Wood_Oak_Trunk",
      "rotation": 4
    },
    {
      "x": -2,
      "y": 6,
      "z": -4,
      "name": "Wood_Oak_Trunk",
      "rotation": 4
    },
    {
      "x": -2,
      "y": 4,
      "z": -3,
      "name": "Wood_Oak_Trunk_Full",
      "rotation": 4
    },
    {
      "x": -2,
      "y": 5,
      "z": -3,
      "name": "Wood_Oak_Trunk",
      "rotation": 4
    },
    {
      "x": -2,
      "y": 6,
      "z": -3,
      "name": "Wood_Oak_Trunk",
      "rotation": 4
    },
    {
      "x": -2,
      "y": 8,
      "z": -3,
      "name": "Wood_Oak_Trunk_Full",
      "support": 1,
      "rotation": 4
    },
    {
      "x": -2,
      "y": 9,
      "z": -3,
      "name": "Wood_Oak_Trunk_Full",
      "rotation": 4
    },
    {
      "x": -2,
      "y": 14,
      "z": -3,
      "name": "Wood_Oak_Trunk_Full",
      "support": 1,
      "rotation": 4
    },
    {
      "x": -2,
      "y": 5,
      "z": -2,
      "name": "Wood_Oak_Trunk_Full",
      "rotation": 4
    },
    {
      "x": -2,
      "y": 6,
      "z": -2,
      "name": "Wood_Oak_Trunk_Full",
      "rotation": 4
    },
    {
      "x": -2,
      "y": 7,
      "z": -2,
      "name": "Wood_Oak_Trunk_Full",
      "support": 1,
      "rotation": 4
    },
    {
      "x": -2,
      "y": 8,
      "z": -2,
      "name": "Wood_Oak_Trunk",
      "rotation": 4
    },
    {
      "x": -2,
      "y": 9,
      "z": -2,
      "name": "Wood_Oak_Trunk",
      "rotation": 4
    },
    {
      "x": -2,
      "y": 10,
      "z": -2,
      "name": "Wood_Oak_Trunk_Full",
      "rotation": 4
    },
    {
      "x": -2,
      "y": 13,
      "z": -2,
      "name": "Wood_Oak_Trunk_Full",
      "support": 1,
      "rotation": 4
    },
    {
      "x": -2,
      "y": 14,
      "z": -2,
      "name": "Wood_Oak_Trunk",
      "rotation": 4
    },
    {
      "x": -2,
      "y": 15,
      "z": -2,
      "name": "Wood_Oak_Trunk_Full",
      "rotation": 4
    },
    {
      "x": -2,
      "y": 8,
      "z": -1,
      "name": "Wood_Oak_Trunk",
      "support": 1,
      "rotation": 4
    },
    {
      "x": -2,
      "y": 9,
      "z": -1,
      "name": "Wood_Oak_Trunk",
      "rotation": 4
    },
    {
      "x": -2,
      "y": 10,
      "z": -1,
      "name": "Wood_Oak_Trunk",
      "rotation": 4
    },
    {
      "x": -2,
      "y": 11,
      "z": -1,
      "name": "Wood_Oak_Trunk_Full",
      "rotation": 4
    },
    {
      "x": -2,
      "y": 12,
      "z": -1,
      "name": "Wood_Oak_Trunk_Full",
      "rotation": 4
    },
    {
      "x": -2,
      "y": 13,
      "z": -1,
      "name": "Wood_Oak_Trunk",
      "rotation": 4
    },
    {
      "x": -2,
      "y": 14,
      "z": -1,
      "name": "Wood_Oak_Trunk",
      "rotation": 4
    },
    {
      "x": -2,
      "y": 15,
      "z": -1,
      "name": "Wood_Oak_Trunk",
      "rotation": 4
    },
    {
      "x": -2,
      "y": 8,
      "z": 0,
      "name": "Wood_Oak_Trunk",
      "support": 2,
      "rotation": 4
    },
    {
      "x": -2,
      "y": 9,
      "z": 0,
      "name": "Wood_Oak_Trunk",
      "rotation": 4
    },
    {
      "x": -2,
      "y": 10,
      "z": 0,
      "name": "Wood_Oak_Trunk",
      "rotation": 4
    },
    {
      "x": -2,
      "y": 11,
      "z": 0,
      "name": "Wood_Oak_Trunk",
      "rotation": 4
    },
    {
      "x": -2,
      "y": 12,
      "z": 0,
      "name": "Wood_Oak_Trunk",
      "rotation": 4
    },
    {
      "x": -2,
      "y": 13,
      "z": 0,
      "name": "Wood_Oak_Trunk",
      "rotation": 4
    },
    {
      "x": -2,
      "y": 14,
      "z": 0,
      "name": "Wood_Oak_Trunk",
      "rotation": 4
    },
    {
      "x": -2,
      "y": 15,
      "z": 0,
      "name": "Wood_Oak_Trunk_Full",
      "rotation": 4
    },
    {
      "x": -2,
      "y": 8,
      "z": 1,
      "name": "Wood_Oak_Trunk",
      "support": 2,
      "rotation": 4
    },
    {
      "x": -2,
      "y": 9,
      "z": 1,
      "name": "Wood_Oak_Trunk",
      "rotation": 4
    },
    {
      "x": -2,
      "y": 10,
      "z": 1,
      "name": "Wood_Oak_Trunk",
      "rotation": 4
    },
    {
      "x": -2,
      "y": 11,
      "z": 1,
      "name": "Wood_Oak_Trunk",
      "rotation": 4
    },
    {
      "x": -2,
      "y": 12,
      "z": 1,
      "name": "Wood_Oak_Trunk",
      "rotation": 4
    },
    {
      "x": -2,
      "y": 13,
      "z": 1,
      "name": "Wood_Oak_Trunk",
      "rotation": 4
    },
    {
      "x": -2,
      "y": 14,
      "z": 1,
      "name": "Wood_Oak_Trunk",
      "rotation": 4
    },
    {
      "x": -2,
      "y": 8,
      "z": 2,
      "name": "Wood_Oak_Trunk",
      "support": 3,
      "rotation": 4
    },
    {
      "x": -2,
      "y": 9,
      "z": 2,
      "name": "Wood_Oak_Trunk",
      "rotation": 4
    },
    {
      "x": -2,
      "y": 10,
      "z": 2,
      "name": "Wood_Oak_Trunk",
      "rotation": 4
    },
    {
      "x": -2,
      "y": 11,
      "z": 2,
      "name": "Wood_Oak_Trunk",
      "rotation": 4
    },
    {
      "x": -2,
      "y": 12,
      "z": 2,
      "name": "Wood_Oak_Trunk",
      "rotation": 4
    },
    {
      "x": -2,
      "y": 13,
      "z": 2,
      "name": "Wood_Oak_Trunk",
      "rotation": 4
    },
    {
      "x": -2,
      "y": 14,
      "z": 2,
      "name": "Wood_Oak_Trunk",
      "rotation": 4
    },
    {
      "x": -2,
      "y": 8,
      "z": 3,
      "name": "Wood_Oak_Trunk",
      "support": 4,
      "rotation": 4
    },
    {
      "x": -2,
      "y": 9,
      "z": 3,
      "name": "Wood_Oak_Trunk",
      "rotation": 4
    },
    {
      "x": -2,
      "y": 10,
      "z": 3,
      "name": "Wood_Oak_Trunk",
      "rotation": 4
    },
    {
      "x": -2,
      "y": 11,
      "z": 3,
      "name": "Wood_Oak_Trunk",
      "rotation": 4
    },
    {
      "x": -2,
      "y": 12,
      "z": 3,
      "name": "Wood_Oak_Trunk",
      "rotation": 4
    },
    {
      "x": -2,
      "y": 13,
      "z": 3,
      "name": "Wood_Oak_Trunk",
      "rotation": 4
    },
    {
      "x": -2,
      "y": 14,
      "z": 3,
      "name": "Wood_Oak_Trunk",
      "rotation": 4
    },
    {
      "x": -2,
      "y": 8,
      "z": 4,
      "name": "Wood_Oak_Trunk",
      "support": 5,
      "rotation": 4
    },
    {
      "x": -2,
      "y": 9,
      "z": 4,
      "name": "Wood_Oak_Trunk",
      "rotation": 4
    },
    {
      "x": -2,
      "y": 10,
      "z": 4,
      "name": "Wood_Oak_Trunk",
      "rotation": 4
    },
    {
      "x": -2,
      "y": 11,
      "z": 4,
      "name": "Wood_Oak_Trunk",
      "rotation": 4
    },
    {
      "x": -2,
      "y": 12,
      "z": 4,
      "name": "Wood_Oak_Trunk",
      "rotation": 4
    },
    {
      "x": -2,
      "y": 13,
      "z": 4,
      "name": "Wood_Oak_Trunk",
      "rotation": 4
    },
    {
      "x": -2,
      "y": 14,
      "z": 4,
      "name": "Wood_Oak_Trunk",
      "rotation": 4
    },
    {
      "x": -2,
      "y": 9,
      "z": 5,
      "name": "Wood_Oak_Trunk",
      "support": 1,
      "rotation": 4
    },
    {
      "x": -2,
      "y": 10,
      "z": 5,
      "name": "Wood_Oak_Trunk",
      "rotation": 4
    },
    {
      "x": -2,
      "y": 11,
      "z": 5,
      "name": "Wood_Oak_Trunk",
      "rotation": 4
    },
    {
      "x": -2,
      "y": 12,
      "z": 5,
      "name": "Wood_Oak_Trunk",
      "rotation": 4
    },
    {
      "x": -2,
      "y": 13,
      "z": 5,
      "name": "Wood_Oak_Trunk",
      "rotation": 4
    },
    {
      "x": -2,
      "y": 14,
      "z": 5,
      "name": "Wood_Oak_Trunk_Full",
      "rotation": 4
    },
    {
      "x": -2,
      "y": 9,
      "z": 6,
      "name": "Wood_Oak_Trunk",
      "support": 2,
      "rotation": 4
    },
    {
      "x": -2,
      "y": 10,
      "z": 6,
      "name": "Wood_Oak_Trunk",
      "rotation": 4
    },
    {
      "x": -2,
      "y": 11,
      "z": 6,
      "name": "Wood_Oak_Trunk",
      "rotation": 4
    },
    {
      "x": -2,
      "y": 12,
      "z": 6,
      "name": "Wood_Oak_Trunk",
      "rotation": 4
    },
    {
      "x": -2,
      "y": 13,
      "z": 6,
      "name": "Wood_Oak_Trunk",
      "rotation": 4
    },
    {
      "x": -2,
      "y": 9,
      "z": 7,
      "name": "Wood_Oak_Trunk",
      "support": 3,
      "rotation": 4
    },
    {
      "x": -2,
      "y": 10,
      "z": 7,
      "name": "Wood_Oak_Trunk",
      "rotation": 4
    },
    {
      "x": -2,
      "y": 11,
      "z": 7,
      "name": "Wood_Oak_Trunk",
      "rotation": 4
    },
    {
      "x": -2,
      "y": 12,
      "z": 7,
      "name": "Wood_Oak_Trunk",
      "rotation": 4
    },
    {
      "x": -2,
      "y": 13,
      "z": 7,
      "name": "Wood_Oak_Trunk",
      "rotation": 4
    },
    {
      "x": -2,
      "y": 9,
      "z": 8,
      "name": "Wood_Oak_Trunk",
      "support": 4,
      "rotation": 4
    },
    {
      "x": -2,
      "y": 10,
      "z": 8,
      "name": "Wood_Oak_Trunk",
      "rotation": 4
    },
    {
      "x": -2,
      "y": 11,
      "z": 8,
      "name": "Wood_Oak_Trunk",
      "rotation": 4
    },
    {
      "x": -2,
      "y": 12,
      "z": 8,
      "name": "Wood_Oak_Trunk",
      "rotation": 4
    },
    {
      "x": -2,
      "y": 13,
      "z": 8,
      "name": "Wood_Oak_Trunk",
      "rotation": 4
    },
    {
      "x": -2,
      "y": 9,
      "z": 9,
      "name": "Wood_Oak_Trunk",
      "support": 4,
      "rotation": 4
    },
    {
      "x": -2,
      "y": 10,
      "z": 9,
      "name": "Wood_Oak_Trunk_Full",
      "rotation": 4
    },
    {
      "x": -2,
      "y": 11,
      "z": 9,
      "name": "Wood_Oak_Trunk",
      "rotation": 4
    },
    {
      "x": -2,
      "y": 12,
      "z": 9,
      "name": "Wood_Oak_Trunk",
      "rotation": 4
    },
    {
      "x": -2,
      "y": 13,
      "z": 9,
      "name": "Wood_Oak_Trunk",
      "rotation": 4
    },
    {
      "x": -2,
      "y": 11,
      "z": 10,
      "name": "Wood_Oak_Trunk",
      "support": 1,
      "rotation": 4
    },
    {
      "x": -2,
      "y": 12,
      "z": 10,
      "name": "Wood_Oak_Trunk",
      "rotation": 4
    },
    {
      "x": -2,
      "y": 13,
      "z": 10,
      "name": "Wood_Oak_Trunk",
      "rotation": 4
    },
    {
      "x": -2,
      "y": 14,
      "z": 10,
      "name": "Wood_Oak_Trunk_Full",
      "rotation": 4
    },
    {
      "x": -2,
      "y": 11,
      "z": 11,
      "name": "Wood_Oak_Trunk",
      "support": 15,
      "rotation": 4
    },
    {
      "x": -2,
      "y": 13,
      "z": 11,
      "name": "Wood_Oak_Trunk",
      "support": 15,
      "rotation": 4
    },
    {
      "x": -2,
      "y": 11,
      "z": 12,
      "name": "Wood_Oak_Trunk_Full",
      "support": 15,
      "rotation": 4
    },
    {
      "x": -2,
      "y": 13,
      "z": 12,
      "name": "Wood_Oak_Trunk_Full",
      "support": 15,
      "rotation": 4
    },
    {
      "x": -1,
      "y": 5,
      "z": -6,
      "name": "Wood_Oak_Trunk_Full",
      "rotation": 4
    },
    {
      "x": -1,
      "y": 5,
      "z": -5,
      "name": "Wood_Oak_Trunk",
      "rotation": 4
    },
    {
      "x": -1,
      "y": 5,
      "z": -4,
      "name": "Wood_Oak_Trunk",
      "rotation": 4
    },
    {
      "x": -1,
      "y": 6,
      "z": -4,
      "name": "Wood_Oak_Trunk_Full",
      "rotation": 4
    },
    {
      "x": -1,
      "y": 4,
      "z": -3,
      "name": "Wood_Oak_Trunk_Full",
      "rotation": 4
    },
    {
      "x": -1,
      "y": 5,
      "z": -3,
      "name": "Wood_Oak_Trunk",
      "rotation": 4
    },
    {
      "x": -1,
      "y": 6,
      "z": -3,
      "name": "Wood_Oak_Trunk",
      "rotation": 4
    },
    {
      "x": -1,
      "y": 7,
      "z": -3,
      "name": "Wood_Oak_Trunk_Full",
      "support": 1,
      "rotation": 4
    },
    {
      "x": -1,
      "y": 8,
      "z": -3,
      "name": "Wood_Oak_Trunk_Full",
      "rotation": 4
    },
    {
      "x": -1,
      "y": 9,
      "z": -3,
      "name": "Wood_Oak_Trunk_Full",
      "rotation": 4
    },
    {
      "x": -1,
      "y": 10,
      "z": -3,
      "name": "Wood_Oak_Trunk_Full",
      "rotation": 4
    },
    {
      "x": -1,
      "y": 5,
      "z": -2,
      "name": "Wood_Oak_Trunk_Full",
      "rotation": 4
    },
    {
      "x": -1,
      "y": 6,
      "z": -2,
      "name": "Wood_Oak_Trunk",
      "support": 5,
      "rotation": 4
    },
    {
      "x": -1,
      "y": 7,
      "z": -2,
      "name": "Wood_Oak_Trunk",
      "rotation": 4
    },
    {
      "x": -1,
      "y": 8,
      "z": -2,
      "name": "Wood_Oak_Trunk",
      "rotation": 4
    },
    {
      "x": -1,
      "y": 9,
      "z": -2,
      "name": "Wood_Oak_Trunk",
      "rotation": 4
    },
    {
      "x": -1,
      "y": 10,
      "z": -2,
      "name": "Wood_Oak_Trunk",
      "rotation": 4
    },
    {
      "x": -1,
      "y": 11,
      "z": -2,
      "name": "Wood_Oak_Trunk_Full",
      "rotation": 4
    },
    {
      "x": -1,
      "y": 13,
      "z": -2,
      "name": "Wood_Oak_Trunk_Full",
      "support": 1,
      "rotation": 4
    },
    {
      "x": -1,
      "y": 14,
      "z": -2,
      "name": "Wood_Oak_Trunk_Full",
      "rotation": 4
    },
    {
      "x": -1,
      "y": 15,
      "z": -2,
      "name": "Wood_Oak_Trunk_Full",
      "rotation": 4
    },
    {
      "x": -1,
      "y": 6,
      "z": -1,
      "name": "Wood_Oak_Trunk_Full",
      "rotation": 4
    },
    {
      "x": -1,
      "y": 7,
      "z": -1,
      "name": "Wood_Oak_Trunk_Full",
      "support": 1,
      "rotation": 4
    },
    {
      "x": -1,
      "y": 8,
      "z": -1,
      "name": "Wood_Oak_Trunk",
      "rotation": 4
    },
    {
      "x": -1,
      "y": 9,
      "z": -1,
      "name": "Wood_Oak_Trunk",
      "rotation": 4
    },
    {
      "x": -1,
      "y": 10,
      "z": -1,
      "name": "Wood_Oak_Trunk",
      "rotation": 4
    },
    {
      "x": -1,
      "y": 11,
      "z": -1,
      "name": "Wood_Oak_Trunk",
      "rotation": 4
    },
    {
      "x": -1,
      "y": 12,
      "z": -1,
      "name": "Wood_Oak_Trunk_Full",
      "rotation": 4
    },
    {
      "x": -1,
      "y": 13,
      "z": -1,
      "name": "Wood_Oak_Trunk",
      "rotation": 4
    },
    {
      "x": -1,
      "y": 14,
      "z": -1,
      "name": "Wood_Oak_Trunk",
      "rotation": 4
    },
    {
      "x": -1,
      "y": 15,
      "z": -1,
      "name": "Wood_Oak_Trunk",
      "rotation": 4
    },
    {
      "x": -1,
      "y": 8,
      "z": 0,
      "name": "Wood_Oak_Trunk",
      "support": 1,
      "rotation": 4
    },
    {
      "x": -1,
      "y": 9,
      "z": 0,
      "name": "Wood_Oak_Trunk",
      "rotation": 4
    },
    {
      "x": -1,
      "y": 10,
      "z": 0,
      "name": "Wood_Oak_Trunk",
      "rotation": 4
    },
    {
      "x": -1,
      "y": 11,
      "z": 0,
      "name": "Wood_Oak_Trunk",
      "rotation": 4
    },
    {
      "x": -1,
      "y": 12,
      "z": 0,
      "name": "Wood_Oak_Trunk",
      "rotation": 4
    },
    {
      "x": -1,
      "y": 13,
      "z": 0,
      "name": "Wood_Oak_Trunk",
      "rotation": 4
    },
    {
      "x": -1,
      "y": 14,
      "z": 0,
      "name": "Wood_Oak_Trunk",
      "rotation": 4
    },
    {
      "x": -1,
      "y": 15,
      "z": 0,
      "name": "Wood_Oak_Trunk",
      "rotation": 4
    },
    {
      "x": -1,
      "y": 8,
      "z": 1,
      "name": "Wood_Oak_Trunk",
      "support": 1,
      "rotation": 4
    },
    {
      "x": -1,
      "y": 9,
      "z": 1,
      "name": "Wood_Oak_Trunk",
      "rotation": 4
    },
    {
      "x": -1,
      "y": 10,
      "z": 1,
      "name": "Wood_Oak_Trunk",
      "rotation": 4
    },
    {
      "x": -1,
      "y": 11,
      "z": 1,
      "name": "Wood_Oak_Trunk",
      "rotation": 4
    },
    {
      "x": -1,
      "y": 12,
      "z": 1,
      "name": "Wood_Oak_Trunk",
      "rotation": 4
    },
    {
      "x": -1,
      "y": 13,
      "z": 1,
      "name": "Wood_Oak_Trunk",
      "rotation": 4
    },
    {
      "x": -1,
      "y": 14,
      "z": 1,
      "name": "Wood_Oak_Trunk",
      "rotation": 4
    },
    {
      "x": -1,
      "y": 15,
      "z": 1,
      "name": "Wood_Oak_Trunk_Full",
      "rotation": 4
    },
    {
      "x": -1,
      "y": 8,
      "z": 2,
      "name": "Wood_Oak_Trunk",
      "support": 2,
      "rotation": 4
    },
    {
      "x": -1,
      "y": 9,
      "z": 2,
      "name": "Wood_Oak_Trunk",
      "rotation": 4
    },
    {
      "x": -1,
      "y": 10,
      "z": 2,
      "name": "Wood_Oak_Trunk",
      "rotation": 4
    },
    {
      "x": -1,
      "y": 11,
      "z": 2,
      "name": "Wood_Oak_Trunk",
      "rotation": 4
    },
    {
      "x": -1,
      "y": 12,
      "z": 2,
      "name": "Wood_Oak_Trunk",
      "rotation": 4
    },
    {
      "x": -1,
      "y": 13,
      "z": 2,
      "name": "Wood_Oak_Trunk",
      "rotation": 4
    },
    {
      "x": -1,
      "y": 14,
      "z": 2,
      "name": "Wood_Oak_Trunk",
      "rotation": 4
    },
    {
      "x": -1,
      "y": 8,
      "z": 3,
      "name": "Wood_Oak_Trunk",
      "support": 3,
      "rotation": 4
    },
    {
      "x": -1,
      "y": 9,
      "z": 3,
      "name": "Wood_Oak_Trunk",
      "rotation": 4
    },
    {
      "x": -1,
      "y": 10,
      "z": 3,
      "name": "Wood_Oak_Trunk",
      "rotation": 4
    },
    {
      "x": -1,
      "y": 11,
      "z": 3,
      "name": "Wood_Oak_Trunk",
      "rotation": 4
    },
    {
      "x": -1,
      "y": 12,
      "z": 3,
      "name": "Wood_Oak_Trunk",
      "rotation": 4
    },
    {
      "x": -1,
      "y": 13,
      "z": 3,
      "name": "Wood_Oak_Trunk",
      "rotation": 4
    },
    {
      "x": -1,
      "y": 14,
      "z": 3,
      "name": "Wood_Oak_Trunk",
      "rotation": 4
    },
    {
      "x": -1,
      "y": 8,
      "z": 4,
      "name": "Wood_Oak_Trunk",
      "support": 4,
      "rotation": 4
    },
    {
      "x": -1,
      "y": 9,
      "z": 4,
      "name": "Wood_Oak_Trunk",
      "rotation": 4
    },
    {
      "x": -1,
      "y": 10,
      "z": 4,
      "name": "Wood_Oak_Trunk",
      "rotation": 4
    },
    {
      "x": -1,
      "y": 11,
      "z": 4,
      "name": "Wood_Oak_Trunk",
      "rotation": 4
    },
    {
      "x": -1,
      "y": 12,
      "z": 4,
      "name": "Wood_Oak_Trunk",
      "rotation": 4
    },
    {
      "x": -1,
      "y": 13,
      "z": 4,
      "name": "Wood_Oak_Trunk",
      "rotation": 4
    },
    {
      "x": -1,
      "y": 14,
      "z": 4,
      "name": "Wood_Oak_Trunk",
      "rotation": 4
    },
    {
      "x": -1,
      "y": 8,
      "z": 5,
      "name": "Wood_Oak_Trunk",
      "support": 5,
      "rotation": 4
    },
    {
      "x": -1,
      "y": 9,
      "z": 5,
      "name": "Wood_Oak_Trunk",
      "rotation": 4
    },
    {
      "x": -1,
      "y": 10,
      "z": 5,
      "name": "Wood_Oak_Trunk",
      "rotation": 4
    },
    {
      "x": -1,
      "y": 11,
      "z": 5,
      "name": "Wood_Oak_Trunk",
      "rotation": 4
    },
    {
      "x": -1,
      "y": 12,
      "z": 5,
      "name": "Wood_Oak_Trunk",
      "rotation": 4
    },
    {
      "x": -1,
      "y": 13,
      "z": 5,
      "name": "Wood_Oak_Trunk",
      "rotation": 4
    },
    {
      "x": -1,
      "y": 14,
      "z": 5,
      "name": "Wood_Oak_Trunk",
      "rotation": 4
    },
    {
      "x": -1,
      "y": 9,
      "z": 6,
      "name": "Wood_Oak_Trunk",
      "support": 1,
      "rotation": 4
    },
    {
      "x": -1,
      "y": 10,
      "z": 6,
      "name": "Wood_Oak_Trunk",
      "rotation": 4
    },
    {
      "x": -1,
      "y": 11,
      "z": 6,
      "name": "Wood_Oak_Trunk",
      "rotation": 4
    },
    {
      "x": -1,
      "y": 12,
      "z": 6,
      "name": "Wood_Oak_Trunk",
      "rotation": 4
    },
    {
      "x": -1,
      "y": 13,
      "z": 6,
      "name": "Wood_Oak_Trunk",
      "rotation": 4
    },
    {
      "x": -1,
      "y": 14,
      "z": 6,
      "name": "Wood_Oak_Trunk",
      "rotation": 4
    },
    {
      "x": -1,
      "y": 15,
      "z": 6,
      "name": "Wood_Oak_Trunk",
      "rotation": 34
    },
    {
      "x": -1,
      "y": 9,
      "z": 7,
      "name": "Wood_Oak_Trunk",
      "support": 2,
      "rotation": 4
    },
    {
      "x": -1,
      "y": 10,
      "z": 7,
      "name": "Wood_Oak_Trunk",
      "rotation": 4
    },
    {
      "x": -1,
      "y": 11,
      "z": 7,
      "name": "Wood_Oak_Trunk",
      "rotation": 4
    },
    {
      "x": -1,
      "y": 12,
      "z": 7,
      "name": "Wood_Oak_Trunk",
      "rotation": 4
    },
    {
      "x": -1,
      "y": 13,
      "z": 7,
      "name": "Wood_Oak_Trunk",
      "rotation": 4
    },
    {
      "x": -1,
      "y": 14,
      "z": 7,
      "name": "Wood_Oak_Trunk",
      "rotation": 4
    },
    {
      "x": -1,
      "y": 15,
      "z": 7,
      "name": "Wood_Oak_Trunk",
      "rotation": 34
    },
    {
      "x": -1,
      "y": 9,
      "z": 8,
      "name": "Wood_Oak_Trunk",
      "support": 3,
      "rotation": 4
    },
    {
      "x": -1,
      "y": 10,
      "z": 8,
      "name": "Wood_Oak_Trunk",
      "rotation": 4
    },
    {
      "x": -1,
      "y": 11,
      "z": 8,
      "name": "Wood_Oak_Trunk",
      "rotation": 4
    },
    {
      "x": -1,
      "y": 12,
      "z": 8,
      "name": "Wood_Oak_Trunk",
      "rotation": 4
    },
    {
      "x": -1,
      "y": 13,
      "z": 8,
      "name": "Wood_Oak_Trunk",
      "rotation": 4
    },
    {
      "x": -1,
      "y": 14,
      "z": 8,
      "name": "Wood_Oak_Trunk",
      "rotation": 4
    },
    {
      "x": -1,
      "y": 9,
      "z": 9,
      "name": "Wood_Oak_Trunk",
      "support": 3,
      "rotation": 4
    },
    {
      "x": -1,
      "y": 10,
      "z": 9,
      "name": "Wood_Oak_Trunk",
      "rotation": 4
    },
    {
      "x": -1,
      "y": 11,
      "z": 9,
      "name": "Wood_Oak_Trunk",
      "rotation": 4
    },
    {
      "x": -1,
      "y": 12,
      "z": 9,
      "name": "Wood_Oak_Trunk",
      "rotation": 4
    },
    {
      "x": -1,
      "y": 13,
      "z": 9,
      "name": "Wood_Oak_Trunk",
      "rotation": 4
    },
    {
      "x": -1,
      "y": 14,
      "z": 9,
      "name": "Wood_Oak_Trunk",
      "rotation": 4
    },
    {
      "x": -1,
      "y": 9,
      "z": 10,
      "name": "Wood_Oak_Trunk",
      "support": 2,
      "rotation": 4
    },
    {
      "x": -1,
      "y": 10,
      "z": 10,
      "name": "Wood_Oak_Trunk",
      "rotation": 4
    },
    {
      "x": -1,
      "y": 11,
      "z": 10,
      "name": "Wood_Oak_Trunk",
      "rotation": 4
    },
    {
      "x": -1,
      "y": 13,
      "z": 10,
      "name": "Wood_Oak_Trunk",
      "support": 1,
      "rotation": 4
    },
    {
      "x": -1,
      "y": 14,
      "z": 10,
      "name": "Wood_Oak_Trunk",
      "rotation": 4
    },
    {
      "x": -1,
      "y": 9,
      "z": 11,
      "name": "Wood_Oak_Trunk",
      "support": 15,
      "rotation": 4
    },
    {
      "x": -1,
      "y": 10,
      "z": 11,
      "name": "Wood_Oak_Trunk",
      "support": 15,
      "rotation": 4
    },
    {
      "x": -1,
      "y": 14,
      "z": 11,
      "name": "Wood_Oak_Trunk",
      "support": 15,
      "rotation": 4
    },
    {
      "x": -1,
      "y": 9,
      "z": 12,
      "name": "Wood_Oak_Trunk_Full",
      "support": 15,
      "rotation": 4
    },
    {
      "x": -1,
      "y": 10,
      "z": 12,
      "name": "Wood_Oak_Trunk_Full",
      "support": 15,
      "rotation": 4
    },
    {
      "x": -1,
      "y": 14,
      "z": 12,
      "name": "Wood_Oak_Trunk_Full",
      "support": 15,
      "rotation": 4
    },
    {
      "x": 0,
      "y": 5,
      "z": -3,
      "name": "Wood_Oak_Trunk_Full",
      "rotation": 4
    },
    {
      "x": 0,
      "y": 6,
      "z": -3,
      "name": "Wood_Oak_Trunk_Full",
      "support": 5,
      "rotation": 4
    },
    {
      "x": 0,
      "y": 7,
      "z": -3,
      "name": "Wood_Oak_Trunk_Full",
      "rotation": 4
    },
    {
      "x": 0,
      "y": 8,
      "z": -3,
      "name": "Wood_Oak_Trunk_Full",
      "rotation": 4
    },
    {
      "x": 0,
      "y": 9,
      "z": -3,
      "name": "Wood_Oak_Trunk_Full",
      "rotation": 4
    },
    {
      "x": 0,
      "y": 13,
      "z": -3,
      "name": "Wood_Oak_Trunk_Full",
      "support": 1,
      "rotation": 4
    },
    {
      "x": 0,
      "y": 14,
      "z": -3,
      "name": "Wood_Oak_Trunk_Full",
      "rotation": 4
    },
    {
      "x": 0,
      "y": 6,
      "z": -2,
      "name": "Wood_Oak_Trunk_Full",
      "support": 4,
      "rotation": 4
    },
    {
      "x": 0,
      "y": 7,
      "z": -2,
      "name": "Wood_Oak_Trunk",
      "rotation": 4
    },
    {
      "x": 0,
      "y": 8,
      "z": -2,
      "name": "Wood_Oak_Trunk",
      "rotation": 4
    },
    {
      "x": 0,
      "y": 9,
      "z": -2,
      "name": "Wood_Oak_Trunk",
      "rotation": 4
    },
    {
      "x": 0,
      "y": 10,
      "z": -2,
      "name": "Wood_Oak_Trunk_Full",
      "rotation": 4
    },
    {
      "x": 0,
      "y": 11,
      "z": -2,
      "name": "Wood_Oak_Trunk_Full",
      "rotation": 4
    },
    {
      "x": 0,
      "y": 12,
      "z": -2,
      "name": "Wood_Oak_Trunk_Full",
      "rotation": 4
    },
    {
      "x": 0,
      "y": 13,
      "z": -2,
      "name": "Wood_Oak_Trunk",
      "rotation": 4
    },
    {
      "x": 0,
      "y": 14,
      "z": -2,
      "name": "Wood_Oak_Trunk",
      "rotation": 4
    },
    {
      "x": 0,
      "y": 15,
      "z": -2,
      "name": "Wood_Oak_Trunk_Full",
      "rotation": 4
    },
    {
      "x": 0,
      "y": 7,
      "z": -1,
      "name": "Wood_Oak_Trunk",
      "support": 1,
      "rotation": 4
    },
    {
      "x": 0,
      "y": 8,
      "z": -1,
      "name": "Wood_Oak_Trunk",
      "rotation": 4
    },
    {
      "x": 0,
      "y": 9,
      "z": -1,
      "name": "Wood_Oak_Trunk",
      "rotation": 4
    },
    {
      "x": 0,
      "y": 10,
      "z": -1,
      "name": "Wood_Oak_Trunk",
      "rotation": 4
    },
    {
      "x": 0,
      "y": 11,
      "z": -1,
      "name": "Wood_Oak_Trunk",
      "rotation": 4
    },
    {
      "x": 0,
      "y": 12,
      "z": -1,
      "name": "Wood_Oak_Trunk",
      "rotation": 4
    },
    {
      "x": 0,
      "y": 13,
      "z": -1,
      "name": "Wood_Oak_Trunk",
      "rotation": 4
    },
    {
      "x": 0,
      "y": 14,
      "z": -1,
      "name": "Wood_Oak_Trunk",
      "rotation": 4
    },
    {
      "x": 0,
      "y": 15,
      "z": -1,
      "name": "Wood_Oak_Trunk",
      "rotation": 4
    },
    {
      "x": 0,
      "y": 7,
      "z": 0,
      "name": "Wood_Oak_Trunk",
      "support": 2,
      "rotation": 4
    },
    {
      "x": 0,
      "y": 8,
      "z": 0,
      "name": "Wood_Oak_Trunk",
      "rotation": 4
    },
    {
      "x": 0,
      "y": 9,
      "z": 0,
      "name": "Wood_Oak_Trunk",
      "rotation": 4
    },
    {
      "x": 0,
      "y": 10,
      "z": 0,
      "name": "Wood_Oak_Trunk",
      "rotation": 4
    },
    {
      "x": 0,
      "y": 11,
      "z": 0,
      "name": "Wood_Oak_Trunk",
      "rotation": 4
    },
    {
      "x": 0,
      "y": 12,
      "z": 0,
      "name": "Wood_Oak_Trunk",
      "rotation": 4
    },
    {
      "x": 0,
      "y": 13,
      "z": 0,
      "name": "Wood_Oak_Trunk",
      "rotation": 4
    },
    {
      "x": 0,
      "y": 14,
      "z": 0,
      "name": "Wood_Oak_Trunk",
      "rotation": 4
    },
    {
      "x": 0,
      "y": 15,
      "z": 0,
      "name": "Wood_Oak_Trunk",
      "rotation": 4
    },
    {
      "x": 0,
      "y": 7,
      "z": 1,
      "name": "Wood_Oak_Trunk_Full",
      "support": 3,
      "rotation": 4
    },
    {
      "x": 0,
      "y": 8,
      "z": 1,
      "name": "Wood_Oak_Trunk",
      "rotation": 4
    },
    {
      "x": 0,
      "y": 9,
      "z": 1,
      "name": "Wood_Oak_Trunk",
      "rotation": 4
    },
    {
      "x": 0,
      "y": 10,
      "z": 1,
      "name": "Wood_Oak_Trunk",
      "rotation": 4
    },
    {
      "x": 0,
      "y": 11,
      "z": 1,
      "name": "Wood_Oak_Trunk",
      "rotation": 4
    },
    {
      "x": 0,
      "y": 12,
      "z": 1,
      "name": "Wood_Oak_Trunk",
      "rotation": 4
    },
    {
      "x": 0,
      "y": 13,
      "z": 1,
      "name": "Wood_Oak_Trunk",
      "rotation": 4
    },
    {
      "x": 0,
      "y": 14,
      "z": 1,
      "name": "Wood_Oak_Trunk",
      "rotation": 4
    },
    {
      "x": 0,
      "y": 15,
      "z": 1,
      "name": "Wood_Oak_Trunk_Full",
      "rotation": 4
    },
    {
      "x": 0,
      "y": 8,
      "z": 2,
      "name": "Wood_Oak_Trunk",
      "support": 1,
      "rotation": 4
    },
    {
      "x": 0,
      "y": 9,
      "z": 2,
      "name": "Wood_Oak_Trunk",
      "rotation": 4
    },
    {
      "x": 0,
      "y": 10,
      "z": 2,
      "name": "Wood_Oak_Trunk",
      "rotation": 4
    },
    {
      "x": 0,
      "y": 11,
      "z": 2,
      "name": "Wood_Oak_Trunk",
      "rotation": 4
    },
    {
      "x": 0,
      "y": 12,
      "z": 2,
      "name": "Wood_Oak_Trunk",
      "rotation": 4
    },
    {
      "x": 0,
      "y": 13,
      "z": 2,
      "name": "Wood_Oak_Trunk",
      "rotation": 4
    },
    {
      "x": 0,
      "y": 14,
      "z": 2,
      "name": "Wood_Oak_Trunk",
      "rotation": 4
    },
    {
      "x": 0,
      "y": 8,
      "z": 3,
      "name": "Wood_Oak_Trunk",
      "support": 2,
      "rotation": 4
    },
    {
      "x": 0,
      "y": 9,
      "z": 3,
      "name": "Wood_Oak_Trunk",
      "rotation": 4
    },
    {
      "x": 0,
      "y": 10,
      "z": 3,
      "name": "Wood_Oak_Trunk",
      "rotation": 4
    },
    {
      "x": 0,
      "y": 11,
      "z": 3,
      "name": "Wood_Oak_Trunk",
      "rotation": 4
    },
    {
      "x": 0,
      "y": 12,
      "z": 3,
      "name": "Wood_Oak_Trunk",
      "rotation": 4
    },
    {
      "x": 0,
      "y": 13,
      "z": 3,
      "name": "Wood_Oak_Trunk",
      "rotation": 4
    },
    {
      "x": 0,
      "y": 14,
      "z": 3,
      "name": "Wood_Oak_Trunk",
      "rotation": 4
    },
    {
      "x": 0,
      "y": 8,
      "z": 4,
      "name": "Wood_Oak_Trunk",
      "support": 3,
      "rotation": 4
    },
    {
      "x": 0,
      "y": 9,
      "z": 4,
      "name": "Wood_Oak_Trunk",
      "rotation": 4
    },
    {
      "x": 0,
      "y": 10,
      "z": 4,
      "name": "Wood_Oak_Trunk",
      "rotation": 4
    },
    {
      "x": 0,
      "y": 11,
      "z": 4,
      "name": "Wood_Oak_Trunk",
      "rotation": 4
    },
    {
      "x": 0,
      "y": 12,
      "z": 4,
      "name": "Wood_Oak_Trunk",
      "rotation": 4
    },
    {
      "x": 0,
      "y": 13,
      "z": 4,
      "name": "Wood_Oak_Trunk",
      "rotation": 4
    },
    {
      "x": 0,
      "y": 14,
      "z": 4,
      "name": "Wood_Oak_Trunk",
      "rotation": 4
    },
    {
      "x": 0,
      "y": 8,
      "z": 5,
      "name": "Wood_Oak_Trunk",
      "support": 4,
      "rotation": 4
    },
    {
      "x": 0,
      "y": 9,
      "z": 5,
      "name": "Wood_Oak_Trunk",
      "rotation": 4
    },
    {
      "x": 0,
      "y": 10,
      "z": 5,
      "name": "Wood_Oak_Trunk",
      "rotation": 4
    },
    {
      "x": 0,
      "y": 11,
      "z": 5,
      "name": "Wood_Oak_Trunk",
      "rotation": 4
    },
    {
      "x": 0,
      "y": 12,
      "z": 5,
      "name": "Wood_Oak_Trunk",
      "rotation": 4
    },
    {
      "x": 0,
      "y": 13,
      "z": 5,
      "name": "Wood_Oak_Trunk",
      "rotation": 4
    },
    {
      "x": 0,
      "y": 14,
      "z": 5,
      "name": "Wood_Oak_Trunk",
      "rotation": 4
    },
    {
      "x": 0,
      "y": 8,
      "z": 6,
      "name": "Wood_Oak_Trunk",
      "support": 5,
      "rotation": 4
    },
    {
      "x": 0,
      "y": 9,
      "z": 6,
      "name": "Wood_Oak_Trunk",
      "rotation": 4
    },
    {
      "x": 0,
      "y": 10,
      "z": 6,
      "name": "Wood_Oak_Trunk",
      "rotation": 4
    },
    {
      "x": 0,
      "y": 11,
      "z": 6,
      "name": "Wood_Oak_Trunk",
      "rotation": 4
    },
    {
      "x": 0,
      "y": 12,
      "z": 6,
      "name": "Wood_Oak_Trunk",
      "rotation": 4
    },
    {
      "x": 0,
      "y": 13,
      "z": 6,
      "name": "Wood_Oak_Trunk",
      "rotation": 4
    },
    {
      "x": 0,
      "y": 14,
      "z": 6,
      "name": "Wood_Oak_Trunk",
      "rotation": 4
    },
    {
      "x": 0,
      "y": 15,
      "z": 6,
      "name": "Wood_Oak_Trunk",
      "rotation": 34
    },
    {
      "x": 0,
      "y": 9,
      "z": 7,
      "name": "Wood_Oak_Trunk",
      "support": 1,
      "rotation": 4
    },
    {
      "x": 0,
      "y": 10,
      "z": 7,
      "name": "Wood_Oak_Trunk",
      "rotation": 4
    },
    {
      "x": 0,
      "y": 11,
      "z": 7,
      "name": "Wood_Oak_Trunk",
      "rotation": 4
    },
    {
      "x": 0,
      "y": 12,
      "z": 7,
      "name": "Wood_Oak_Trunk",
      "rotation": 4
    },
    {
      "x": 0,
      "y": 13,
      "z": 7,
      "name": "Wood_Oak_Trunk",
      "rotation": 4
    },
    {
      "x": 0,
      "y": 14,
      "z": 7,
      "name": "Wood_Oak_Trunk",
      "rotation": 4
    },
    {
      "x": 0,
      "y": 15,
      "z": 7,
      "name": "Wood_Oak_Trunk",
      "rotation": 34
    },
    {
      "x": 0,
      "y": 9,
      "z": 8,
      "name": "Wood_Oak_Trunk",
      "support": 2,
      "rotation": 4
    },
    {
      "x": 0,
      "y": 10,
      "z": 8,
      "name": "Wood_Oak_Trunk",
      "rotation": 4
    },
    {
      "x": 0,
      "y": 11,
      "z": 8,
      "name": "Wood_Oak_Trunk",
      "rotation": 4
    },
    {
      "x": 0,
      "y": 12,
      "z": 8,
      "name": "Wood_Oak_Trunk",
      "rotation": 4
    },
    {
      "x": 0,
      "y": 13,
      "z": 8,
      "name": "Wood_Oak_Trunk",
      "rotation": 4
    },
    {
      "x": 0,
      "y": 14,
      "z": 8,
      "name": "Wood_Oak_Trunk",
      "rotation": 4
    },
    {
      "x": 0,
      "y": 9,
      "z": 9,
      "name": "Wood_Oak_Trunk",
      "support": 3,
      "rotation": 4
    },
    {
      "x": 0,
      "y": 10,
      "z": 9,
      "name": "Wood_Oak_Trunk",
      "rotation": 4
    },
    {
      "x": 0,
      "y": 11,
      "z": 9,
      "name": "Wood_Oak_Trunk",
      "rotation": 4
    },
    {
      "x": 0,
      "y": 12,
      "z": 9,
      "name": "Wood_Oak_Trunk",
      "rotation": 4
    },
    {
      "x": 0,
      "y": 13,
      "z": 9,
      "name": "Wood_Oak_Trunk",
      "rotation": 4
    },
    {
      "x": 0,
      "y": 14,
      "z": 9,
      "name": "Wood_Oak_Trunk",
      "rotation": 4
    },
    {
      "x": 0,
      "y": 9,
      "z": 10,
      "name": "Wood_Oak_Trunk",
      "support": 2,
      "rotation": 4
    },
    {
      "x": 0,
      "y": 10,
      "z": 10,
      "name": "Wood_Oak_Trunk",
      "rotation": 4
    },
    {
      "x": 0,
      "y": 13,
      "z": 10,
      "name": "Wood_Oak_Trunk",
      "support": 1,
      "rotation": 4
    },
    {
      "x": 0,
      "y": 14,
      "z": 10,
      "name": "Wood_Oak_Trunk",
      "rotation": 4
    },
    {
      "x": 0,
      "y": 9,
      "z": 11,
      "name": "Wood_Oak_Trunk",
      "support": 15,
      "rotation": 4
    },
    {
      "x": 0,
      "y": 14,
      "z": 11,
      "name": "Wood_Oak_Trunk",
      "support": 15,
      "rotation": 4
    },
    {
      "x": 0,
      "y": 9,
      "z": 12,
      "name": "Wood_Oak_Trunk",
      "support": 15,
      "rotation": 4
    },
    {
      "x": 0,
      "y": 14,
      "z": 12,
      "name": "Wood_Oak_Trunk",
      "support": 15,
      "rotation": 4
    },
    {
      "x": 0,
      "y": 9,
      "z": 13,
      "name": "Wood_Oak_Trunk_Full",
      "support": 15,
      "rotation": 4
    },
    {
      "x": 0,
      "y": 14,
      "z": 13,
      "name": "Wood_Oak_Trunk_Full",
      "support": 15,
      "rotation": 4
    },
    {
      "x": 1,
      "y": 7,
      "z": -3,
      "name": "Wood_Oak_Trunk_Full",
      "support": 1,
      "rotation": 4
    },
    {
      "x": 1,
      "y": 8,
      "z": -3,
      "name": "Wood_Oak_Trunk_Full",
      "rotation": 4
    },
    {
      "x": 1,
      "y": 9,
      "z": -3,
      "name": "Wood_Oak_Trunk_Full",
      "rotation": 4
    },
    {
      "x": 1,
      "y": 10,
      "z": -3,
      "name": "Wood_Oak_Trunk_Full",
      "rotation": 4
    },
    {
      "x": 1,
      "y": 12,
      "z": -3,
      "name": "Wood_Oak_Trunk_Full",
      "support": 1,
      "rotation": 4
    },
    {
      "x": 1,
      "y": 13,
      "z": -3,
      "name": "Wood_Oak_Trunk_Full",
      "rotation": 4
    },
    {
      "x": 1,
      "y": 14,
      "z": -3,
      "name": "Wood_Oak_Trunk_Full",
      "rotation": 4
    },
    {
      "x": 1,
      "y": 15,
      "z": -3,
      "name": "Wood_Oak_Trunk_Full",
      "rotation": 4
    },
    {
      "x": 1,
      "y": 6,
      "z": -2,
      "name": "Wood_Oak_Trunk_Full",
      "support": 3,
      "rotation": 4
    },
    {
      "x": 1,
      "y": 7,
      "z": -2,
      "name": "Wood_Oak_Trunk",
      "rotation": 4
    },
    {
      "x": 1,
      "y": 8,
      "z": -2,
      "name": "Wood_Oak_Trunk",
      "rotation": 4
    },
    {
      "x": 1,
      "y": 9,
      "z": -2,
      "name": "Wood_Oak_Trunk",
      "rotation": 4
    },
    {
      "x": 1,
      "y": 10,
      "z": -2,
      "name": "Wood_Oak_Trunk",
      "rotation": 4
    },
    {
      "x": 1,
      "y": 11,
      "z": -2,
      "name": "Wood_Oak_Trunk_Full",
      "rotation": 4
    },
    {
      "x": 1,
      "y": 12,
      "z": -2,
      "name": "Wood_Oak_Trunk",
      "rotation": 4
    },
    {
      "x": 1,
      "y": 13,
      "z": -2,
      "name": "Wood_Oak_Trunk",
      "rotation": 4
    },
    {
      "x": 1,
      "y": 14,
      "z": -2,
      "name": "Wood_Oak_Trunk",
      "rotation": 4
    },
    {
      "x": 1,
      "y": 15,
      "z": -2,
      "name": "Wood_Oak_Trunk",
      "rotation": 4
    },
    {
      "x": 1,
      "y": 6,
      "z": -1,
      "name": "Wood_Oak_Trunk_Full",
      "support": 3,
      "rotation": 4
    },
    {
      "x": 1,
      "y": 7,
      "z": -1,
      "name": "Wood_Oak_Trunk",
      "rotation": 4
    },
    {
      "x": 1,
      "y": 8,
      "z": -1,
      "name": "Wood_Oak_Trunk",
      "rotation": 4
    },
    {
      "x": 1,
      "y": 9,
      "z": -1,
      "name": "Wood_Oak_Trunk",
      "rotation": 4
    },
    {
      "x": 1,
      "y": 10,
      "z": -1,
      "name": "Wood_Oak_Trunk",
      "rotation": 4
    },
    {
      "x": 1,
      "y": 11,
      "z": -1,
      "name": "Wood_Oak_Trunk",
      "rotation": 4
    },
    {
      "x": 1,
      "y": 12,
      "z": -1,
      "name": "Wood_Oak_Trunk",
      "rotation": 4
    },
    {
      "x": 1,
      "y": 13,
      "z": -1,
      "name": "Wood_Oak_Trunk",
      "rotation": 4
    },
    {
      "x": 1,
      "y": 14,
      "z": -1,
      "name": "Wood_Oak_Trunk",
      "rotation": 4
    },
    {
      "x": 1,
      "y": 15,
      "z": -1,
      "name": "Wood_Oak_Trunk",
      "rotation": 4
    },
    {
      "x": 1,
      "y": 7,
      "z": 0,
      "name": "Wood_Oak_Trunk",
      "support": 1,
      "rotation": 4
    },
    {
      "x": 1,
      "y": 8,
      "z": 0,
      "name": "Wood_Oak_Trunk",
      "rotation": 4
    },
    {
      "x": 1,
      "y": 9,
      "z": 0,
      "name": "Wood_Oak_Trunk",
      "rotation": 4
    },
    {
      "x": 1,
      "y": 10,
      "z": 0,
      "name": "Wood_Oak_Trunk",
      "rotation": 4
    },
    {
      "x": 1,
      "y": 11,
      "z": 0,
      "name": "Wood_Oak_Trunk",
      "rotation": 4
    },
    {
      "x": 1,
      "y": 12,
      "z": 0,
      "name": "Wood_Oak_Trunk",
      "rotation": 4
    },
    {
      "x": 1,
      "y": 13,
      "z": 0,
      "name": "Wood_Oak_Trunk",
      "rotation": 4
    },
    {
      "x": 1,
      "y": 14,
      "z": 0,
      "name": "Wood_Oak_Trunk",
      "rotation": 4
    },
    {
      "x": 1,
      "y": 15,
      "z": 0,
      "name": "Wood_Oak_Trunk_Full",
      "rotation": 4
    },
    {
      "x": 1,
      "y": 7,
      "z": 1,
      "name": "Wood_Oak_Trunk_Full",
      "support": 2,
      "rotation": 4
    },
    {
      "x": 1,
      "y": 8,
      "z": 1,
      "name": "Wood_Oak_Trunk",
      "rotation": 4
    },
    {
      "x": 1,
      "y": 9,
      "z": 1,
      "name": "Wood_Oak_Trunk",
      "rotation": 4
    },
    {
      "x": 1,
      "y": 10,
      "z": 1,
      "name": "Wood_Oak_Trunk",
      "rotation": 4
    },
    {
      "x": 1,
      "y": 11,
      "z": 1,
      "name": "Wood_Oak_Trunk",
      "rotation": 4
    },
    {
      "x": 1,
      "y": 12,
      "z": 1,
      "name": "Wood_Oak_Trunk",
      "rotation": 4
    },
    {
      "x": 1,
      "y": 13,
      "z": 1,
      "name": "Wood_Oak_Trunk",
      "rotation": 4
    },
    {
      "x": 1,
      "y": 14,
      "z": 1,
      "name": "Wood_Oak_Trunk",
      "rotation": 4
    },
    {
      "x": 1,
      "y": 8,
      "z": 2,
      "name": "Wood_Oak_Trunk",
      "support": 1,
      "rotation": 4
    },
    {
      "x": 1,
      "y": 9,
      "z": 2,
      "name": "Wood_Oak_Trunk",
      "rotation": 4
    },
    {
      "x": 1,
      "y": 10,
      "z": 2,
      "name": "Wood_Oak_Trunk",
      "rotation": 4
    },
    {
      "x": 1,
      "y": 11,
      "z": 2,
      "name": "Wood_Oak_Trunk",
      "rotation": 4
    },
    {
      "x": 1,
      "y": 12,
      "z": 2,
      "name": "Wood_Oak_Trunk",
      "rotation": 4
    },
    {
      "x": 1,
      "y": 13,
      "z": 2,
      "name": "Wood_Oak_Trunk",
      "rotation": 4
    },
    {
      "x": 1,
      "y": 14,
      "z": 2,
      "name": "Wood_Oak_Trunk",
      "rotation": 4
    },
    {
      "x": 1,
      "y": 8,
      "z": 3,
      "name": "Wood_Oak_Trunk",
      "support": 2,
      "rotation": 4
    },
    {
      "x": 1,
      "y": 9,
      "z": 3,
      "name": "Wood_Oak_Trunk",
      "rotation": 4
    },
    {
      "x": 1,
      "y": 10,
      "z": 3,
      "name": "Wood_Oak_Trunk",
      "rotation": 4
    },
    {
      "x": 1,
      "y": 11,
      "z": 3,
      "name": "Wood_Oak_Trunk",
      "rotation": 4
    },
    {
      "x": 1,
      "y": 12,
      "z": 3,
      "name": "Wood_Oak_Trunk",
      "rotation": 4
    },
    {
      "x": 1,
      "y": 13,
      "z": 3,
      "name": "Wood_Oak_Trunk",
      "rotation": 4
    },
    {
      "x": 1,
      "y": 14,
      "z": 3,
      "name": "Wood_Oak_Trunk",
      "rotation": 4
    },
    {
      "x": 1,
      "y": 8,
      "z": 4,
      "name": "Wood_Oak_Trunk",
      "support": 3,
      "rotation": 4
    },
    {
      "x": 1,
      "y": 9,
      "z": 4,
      "name": "Wood_Oak_Trunk",
      "rotation": 4
    },
    {
      "x": 1,
      "y": 10,
      "z": 4,
      "name": "Wood_Oak_Trunk",
      "rotation": 4
    },
    {
      "x": 1,
      "y": 11,
      "z": 4,
      "name": "Wood_Oak_Trunk",
      "rotation": 4
    },
    {
      "x": 1,
      "y": 12,
      "z": 4,
      "name": "Wood_Oak_Trunk",
      "rotation": 4
    },
    {
      "x": 1,
      "y": 13,
      "z": 4,
      "name": "Wood_Oak_Trunk",
      "rotation": 4
    },
    {
      "x": 1,
      "y": 14,
      "z": 4,
      "name": "Wood_Oak_Trunk",
      "rotation": 4
    },
    {
      "x": 1,
      "y": 8,
      "z": 5,
      "name": "Wood_Oak_Trunk",
      "support": 4,
      "rotation": 4
    },
    {
      "x": 1,
      "y": 9,
      "z": 5,
      "name": "Wood_Oak_Trunk",
      "rotation": 4
    },
    {
      "x": 1,
      "y": 10,
      "z": 5,
      "name": "Wood_Oak_Trunk",
      "rotation": 4
    },
    {
      "x": 1,
      "y": 11,
      "z": 5,
      "name": "Wood_Oak_Trunk",
      "rotation": 4
    },
    {
      "x": 1,
      "y": 12,
      "z": 5,
      "name": "Wood_Oak_Trunk",
      "rotation": 4
    },
    {
      "x": 1,
      "y": 13,
      "z": 5,
      "name": "Wood_Oak_Trunk",
      "rotation": 4
    },
    {
      "x": 1,
      "y": 14,
      "z": 5,
      "name": "Wood_Oak_Trunk",
      "rotation": 4
    },
    {
      "x": 1,
      "y": 8,
      "z": 6,
      "name": "Wood_Oak_Trunk",
      "support": 5,
      "rotation": 4
    },
    {
      "x": 1,
      "y": 9,
      "z": 6,
      "name": "Wood_Oak_Trunk",
      "rotation": 4
    },
    {
      "x": 1,
      "y": 10,
      "z": 6,
      "name": "Wood_Oak_Trunk",
      "rotation": 4
    },
    {
      "x": 1,
      "y": 11,
      "z": 6,
      "name": "Wood_Oak_Trunk",
      "rotation": 4
    },
    {
      "x": 1,
      "y": 12,
      "z": 6,
      "name": "Wood_Oak_Trunk",
      "rotation": 4
    },
    {
      "x": 1,
      "y": 13,
      "z": 6,
      "name": "Wood_Oak_Trunk",
      "rotation": 4
    },
    {
      "x": 1,
      "y": 14,
      "z": 6,
      "name": "Wood_Oak_Trunk",
      "rotation": 4
    },
    {
      "x": 1,
      "y": 9,
      "z": 7,
      "name": "Wood_Oak_Trunk",
      "support": 1,
      "rotation": 4
    },
    {
      "x": 1,
      "y": 10,
      "z": 7,
      "name": "Wood_Oak_Trunk",
      "rotation": 4
    },
    {
      "x": 1,
      "y": 11,
      "z": 7,
      "name": "Wood_Oak_Trunk",
      "rotation": 4
    },
    {
      "x": 1,
      "y": 12,
      "z": 7,
      "name": "Wood_Oak_Trunk",
      "rotation": 4
    },
    {
      "x": 1,
      "y": 13,
      "z": 7,
      "name": "Wood_Oak_Trunk",
      "rotation": 4
    },
    {
      "x": 1,
      "y": 14,
      "z": 7,
      "name": "Wood_Oak_Trunk",
      "rotation": 4
    },
    {
      "x": 1,
      "y": 9,
      "z": 8,
      "name": "Wood_Oak_Trunk",
      "support": 2,
      "rotation": 4
    },
    {
      "x": 1,
      "y": 10,
      "z": 8,
      "name": "Wood_Oak_Trunk",
      "rotation": 4
    },
    {
      "x": 1,
      "y": 11,
      "z": 8,
      "name": "Wood_Oak_Trunk",
      "rotation": 4
    },
    {
      "x": 1,
      "y": 12,
      "z": 8,
      "name": "Wood_Oak_Trunk",
      "rotation": 4
    },
    {
      "x": 1,
      "y": 13,
      "z": 8,
      "name": "Wood_Oak_Trunk",
      "rotation": 4
    },
    {
      "x": 1,
      "y": 14,
      "z": 8,
      "name": "Wood_Oak_Trunk",
      "rotation": 4
    },
    {
      "x": 1,
      "y": 9,
      "z": 9,
      "name": "Wood_Oak_Trunk",
      "support": 3,
      "rotation": 4
    },
    {
      "x": 1,
      "y": 10,
      "z": 9,
      "name": "Wood_Oak_Trunk",
      "rotation": 4
    },
    {
      "x": 1,
      "y": 11,
      "z": 9,
      "name": "Wood_Oak_Trunk",
      "rotation": 4
    },
    {
      "x": 1,
      "y": 12,
      "z": 9,
      "name": "Wood_Oak_Trunk",
      "rotation": 4
    },
    {
      "x": 1,
      "y": 13,
      "z": 9,
      "name": "Wood_Oak_Trunk",
      "rotation": 4
    },
    {
      "x": 1,
      "y": 14,
      "z": 9,
      "name": "Wood_Oak_Trunk",
      "rotation": 4
    },
    {
      "x": 1,
      "y": 9,
      "z": 10,
      "name": "Wood_Oak_Trunk_Full",
      "support": 3,
      "rotation": 4
    },
    {
      "x": 1,
      "y": 10,
      "z": 10,
      "name": "Wood_Oak_Trunk",
      "rotation": 4
    },
    {
      "x": 1,
      "y": 13,
      "z": 10,
      "name": "Wood_Oak_Trunk",
      "support": 1,
      "rotation": 4
    },
    {
      "x": 1,
      "y": 14,
      "z": 10,
      "name": "Wood_Oak_Trunk",
      "rotation": 4
    },
    {
      "x": 1,
      "y": 10,
      "z": 11,
      "name": "Wood_Oak_Trunk",
      "support": 15,
      "rotation": 4
    },
    {
      "x": 1,
      "y": 14,
      "z": 11,
      "name": "Wood_Oak_Trunk",
      "support": 15,
      "rotation": 4
    },
    {
      "x": 1,
      "y": 10,
      "z": 12,
      "name": "Wood_Oak_Trunk",
      "support": 15,
      "rotation": 4
    },
    {
      "x": 1,
      "y": 14,
      "z": 12,
      "name": "Wood_Oak_Trunk",
      "support": 15,
      "rotation": 4
    },
    {
      "x": 1,
      "y": 10,
      "z": 13,
      "name": "Wood_Oak_Trunk_Full",
      "support": 15,
      "rotation": 4
    },
    {
      "x": 1,
      "y": 14,
      "z": 13,
      "name": "Wood_Oak_Trunk_Full",
      "support": 15,
      "rotation": 4
    },
    {
      "x": 2,
      "y": 2,
      "z": -11,
      "name": "Wood_Oak_Trunk_Full",
      "support": 1,
      "rotation": 4
    },
    {
      "x": 2,
      "y": 2,
      "z": -10,
      "name": "Wood_Oak_Trunk",
      "support": 1,
      "rotation": 4
    },
    {
      "x": 2,
      "y": 2,
      "z": -9,
      "name": "Wood_Oak_Trunk",
      "support": 1,
      "rotation": 4
    },
    {
      "x": 2,
      "y": 2,
      "z": -8,
      "name": "Wood_Oak_Trunk_Full",
      "support": 1,
      "rotation": 4
    },
    {
      "x": 2,
      "y": 7,
      "z": -3,
      "name": "Wood_Oak_Trunk_Full",
      "support": 1,
      "rotation": 4
    },
    {
      "x": 2,
      "y": 8,
      "z": -3,
      "name": "Wood_Oak_Trunk_Full",
      "rotation": 4
    },
    {
      "x": 2,
      "y": 9,
      "z": -3,
      "name": "Wood_Oak_Trunk_Full",
      "rotation": 4
    },
    {
      "x": 2,
      "y": 10,
      "z": -3,
      "name": "Wood_Oak_Trunk_Full",
      "rotation": 4
    },
    {
      "x": 2,
      "y": 11,
      "z": -3,
      "name": "Wood_Oak_Trunk_Full",
      "rotation": 4
    },
    {
      "x": 2,
      "y": 12,
      "z": -3,
      "name": "Wood_Oak_Trunk_Full",
      "rotation": 4
    },
    {
      "x": 2,
      "y": 13,
      "z": -3,
      "name": "Wood_Oak_Trunk_Full",
      "rotation": 4
    },
    {
      "x": 2,
      "y": 14,
      "z": -3,
      "name": "Wood_Oak_Trunk_Full",
      "rotation": 4
    },
    {
      "x": 2,
      "y": 6,
      "z": -2,
      "name": "Wood_Oak_Trunk_Full",
      "support": 2,
      "rotation": 4
    },
    {
      "x": 2,
      "y": 7,
      "z": -2,
      "name": "Wood_Oak_Trunk",
      "rotation": 4
    },
    {
      "x": 2,
      "y": 8,
      "z": -2,
      "name": "Wood_Oak_Trunk",
      "rotation": 4
    },
    {
      "x": 2,
      "y": 9,
      "z": -2,
      "name": "Wood_Oak_Trunk",
      "rotation": 4
    },
    {
      "x": 2,
      "y": 10,
      "z": -2,
      "name": "Wood_Oak_Trunk",
      "rotation": 4
    },
    {
      "x": 2,
      "y": 11,
      "z": -2,
      "name": "Wood_Oak_Trunk",
      "rotation": 4
    },
    {
      "x": 2,
      "y": 12,
      "z": -2,
      "name": "Wood_Oak_Trunk",
      "rotation": 4
    },
    {
      "x": 2,
      "y": 13,
      "z": -2,
      "name": "Wood_Oak_Trunk",
      "rotation": 4
    },
    {
      "x": 2,
      "y": 14,
      "z": -2,
      "name": "Wood_Oak_Trunk",
      "rotation": 4
    },
    {
      "x": 2,
      "y": 15,
      "z": -2,
      "name": "Wood_Oak_Trunk_Full",
      "rotation": 4
    },
    {
      "x": 2,
      "y": 6,
      "z": -1,
      "name": "Wood_Oak_Trunk_Full",
      "support": 2,
      "rotation": 4
    },
    {
      "x": 2,
      "y": 7,
      "z": -1,
      "name": "Wood_Oak_Trunk",
      "rotation": 4
    },
    {
      "x": 2,
      "y": 8,
      "z": -1,
      "name": "Wood_Oak_Trunk",
      "rotation": 4
    },
    {
      "x": 2,
      "y": 9,
      "z": -1,
      "name": "Wood_Oak_Trunk",
      "rotation": 4
    },
    {
      "x": 2,
      "y": 10,
      "z": -1,
      "name": "Wood_Oak_Trunk",
      "rotation": 4
    },
    {
      "x": 2,
      "y": 11,
      "z": -1,
      "name": "Wood_Oak_Trunk",
      "rotation": 4
    },
    {
      "x": 2,
      "y": 12,
      "z": -1,
      "name": "Wood_Oak_Trunk",
      "rotation": 4
    },
    {
      "x": 2,
      "y": 13,
      "z": -1,
      "name": "Wood_Oak_Trunk",
      "rotation": 4
    },
    {
      "x": 2,
      "y": 14,
      "z": -1,
      "name": "Wood_Oak_Trunk",
      "rotation": 4
    },
    {
      "x": 2,
      "y": 15,
      "z": -1,
      "name": "Wood_Oak_Trunk_Full",
      "rotation": 4
    },
    {
      "x": 2,
      "y": 7,
      "z": 0,
      "name": "Wood_Oak_Trunk",
      "support": 1,
      "rotation": 4
    },
    {
      "x": 2,
      "y": 8,
      "z": 0,
      "name": "Wood_Oak_Trunk",
      "rotation": 4
    },
    {
      "x": 2,
      "y": 9,
      "z": 0,
      "name": "Wood_Oak_Trunk",
      "rotation": 4
    },
    {
      "x": 2,
      "y": 10,
      "z": 0,
      "name": "Wood_Oak_Trunk",
      "rotation": 4
    },
    {
      "x": 2,
      "y": 11,
      "z": 0,
      "name": "Wood_Oak_Trunk",
      "rotation": 4
    },
    {
      "x": 2,
      "y": 12,
      "z": 0,
      "name": "Wood_Oak_Trunk",
      "rotation": 4
    },
    {
      "x": 2,
      "y": 13,
      "z": 0,
      "name": "Wood_Oak_Trunk",
      "rotation": 4
    },
    {
      "x": 2,
      "y": 14,
      "z": 0,
      "name": "Wood_Oak_Trunk",
      "rotation": 4
    },
    {
      "x": 2,
      "y": 7,
      "z": 1,
      "name": "Wood_Oak_Trunk_Full",
      "support": 2,
      "rotation": 4
    },
    {
      "x": 2,
      "y": 8,
      "z": 1,
      "name": "Wood_Oak_Trunk",
      "rotation": 4
    },
    {
      "x": 2,
      "y": 9,
      "z": 1,
      "name": "Wood_Oak_Trunk",
      "rotation": 4
    },
    {
      "x": 2,
      "y": 10,
      "z": 1,
      "name": "Wood_Oak_Trunk",
      "rotation": 4
    },
    {
      "x": 2,
      "y": 11,
      "z": 1,
      "name": "Wood_Oak_Trunk",
      "rotation": 4
    },
    {
      "x": 2,
      "y": 12,
      "z": 1,
      "name": "Wood_Oak_Trunk",
      "rotation": 4
    },
    {
      "x": 2,
      "y": 13,
      "z": 1,
      "name": "Wood_Oak_Trunk",
      "rotation": 4
    },
    {
      "x": 2,
      "y": 14,
      "z": 1,
      "name": "Wood_Oak_Trunk",
      "rotation": 4
    },
    {
      "x": 2,
      "y": 8,
      "z": 2,
      "name": "Wood_Oak_Trunk",
      "support": 1,
      "rotation": 4
    },
    {
      "x": 2,
      "y": 9,
      "z": 2,
      "name": "Wood_Oak_Trunk",
      "rotation": 4
    },
    {
      "x": 2,
      "y": 10,
      "z": 2,
      "name": "Wood_Oak_Trunk",
      "rotation": 4
    },
    {
      "x": 2,
      "y": 11,
      "z": 2,
      "name": "Wood_Oak_Trunk",
      "rotation": 4
    },
    {
      "x": 2,
      "y": 12,
      "z": 2,
      "name": "Wood_Oak_Trunk",
      "rotation": 4
    },
    {
      "x": 2,
      "y": 13,
      "z": 2,
      "name": "Wood_Oak_Trunk",
      "rotation": 4
    },
    {
      "x": 2,
      "y": 14,
      "z": 2,
      "name": "Wood_Oak_Trunk",
      "rotation": 4
    },
    {
      "x": 2,
      "y": 8,
      "z": 3,
      "name": "Wood_Oak_Trunk",
      "support": 2,
      "rotation": 4
    },
    {
      "x": 2,
      "y": 9,
      "z": 3,
      "name": "Wood_Oak_Trunk",
      "rotation": 4
    },
    {
      "x": 2,
      "y": 10,
      "z": 3,
      "name": "Wood_Oak_Trunk",
      "rotation": 4
    },
    {
      "x": 2,
      "y": 11,
      "z": 3,
      "name": "Wood_Oak_Trunk",
      "rotation": 4
    },
    {
      "x": 2,
      "y": 12,
      "z": 3,
      "name": "Wood_Oak_Trunk",
      "rotation": 4
    },
    {
      "x": 2,
      "y": 13,
      "z": 3,
      "name": "Wood_Oak_Trunk",
      "rotation": 4
    },
    {
      "x": 2,
      "y": 14,
      "z": 3,
      "name": "Wood_Oak_Trunk_Full",
      "rotation": 4
    },
    {
      "x": 2,
      "y": 8,
      "z": 4,
      "name": "Wood_Oak_Trunk",
      "support": 3,
      "rotation": 4
    },
    {
      "x": 2,
      "y": 9,
      "z": 4,
      "name": "Wood_Oak_Trunk",
      "rotation": 4
    },
    {
      "x": 2,
      "y": 10,
      "z": 4,
      "name": "Wood_Oak_Trunk",
      "rotation": 4
    },
    {
      "x": 2,
      "y": 11,
      "z": 4,
      "name": "Wood_Oak_Trunk",
      "rotation": 4
    },
    {
      "x": 2,
      "y": 12,
      "z": 4,
      "name": "Wood_Oak_Trunk",
      "rotation": 4
    },
    {
      "x": 2,
      "y": 13,
      "z": 4,
      "name": "Wood_Oak_Trunk",
      "rotation": 4
    },
    {
      "x": 2,
      "y": 8,
      "z": 5,
      "name": "Wood_Oak_Trunk",
      "support": 4,
      "rotation": 4
    },
    {
      "x": 2,
      "y": 9,
      "z": 5,
      "name": "Wood_Oak_Trunk",
      "rotation": 4
    },
    {
      "x": 2,
      "y": 10,
      "z": 5,
      "name": "Wood_Oak_Trunk",
      "rotation": 4
    },
    {
      "x": 2,
      "y": 11,
      "z": 5,
      "name": "Wood_Oak_Trunk",
      "rotation": 4
    },
    {
      "x": 2,
      "y": 12,
      "z": 5,
      "name": "Wood_Oak_Trunk",
      "rotation": 4
    },
    {
      "x": 2,
      "y": 13,
      "z": 5,
      "name": "Wood_Oak_Trunk",
      "rotation": 4
    },
    {
      "x": 2,
      "y": 8,
      "z": 6,
      "name": "Wood_Oak_Trunk",
      "support": 5,
      "rotation": 4
    },
    {
      "x": 2,
      "y": 9,
      "z": 6,
      "name": "Wood_Oak_Trunk",
      "rotation": 4
    },
    {
      "x": 2,
      "y": 10,
      "z": 6,
      "name": "Wood_Oak_Trunk",
      "rotation": 4
    },
    {
      "x": 2,
      "y": 11,
      "z": 6,
      "name": "Wood_Oak_Trunk",
      "rotation": 4
    },
    {
      "x": 2,
      "y": 12,
      "z": 6,
      "name": "Wood_Oak_Trunk",
      "rotation": 4
    },
    {
      "x": 2,
      "y": 13,
      "z": 6,
      "name": "Wood_Oak_Trunk",
      "rotation": 4
    },
    {
      "x": 2,
      "y": 9,
      "z": 7,
      "name": "Wood_Oak_Trunk",
      "support": 1,
      "rotation": 4
    },
    {
      "x": 2,
      "y": 10,
      "z": 7,
      "name": "Wood_Oak_Trunk",
      "rotation": 4
    },
    {
      "x": 2,
      "y": 11,
      "z": 7,
      "name": "Wood_Oak_Trunk",
      "rotation": 4
    },
    {
      "x": 2,
      "y": 12,
      "z": 7,
      "name": "Wood_Oak_Trunk",
      "rotation": 4
    },
    {
      "x": 2,
      "y": 13,
      "z": 7,
      "name": "Wood_Oak_Trunk",
      "rotation": 4
    },
    {
      "x": 2,
      "y": 9,
      "z": 8,
      "name": "Wood_Oak_Trunk",
      "support": 2,
      "rotation": 4
    },
    {
      "x": 2,
      "y": 10,
      "z": 8,
      "name": "Wood_Oak_Trunk",
      "rotation": 4
    },
    {
      "x": 2,
      "y": 11,
      "z": 8,
      "name": "Wood_Oak_Trunk",
      "rotation": 4
    },
    {
      "x": 2,
      "y": 12,
      "z": 8,
      "name": "Wood_Oak_Trunk",
      "rotation": 4
    },
    {
      "x": 2,
      "y": 13,
      "z": 8,
      "name": "Wood_Oak_Trunk",
      "rotation": 4
    },
    {
      "x": 2,
      "y": 9,
      "z": 9,
      "name": "Wood_Oak_Trunk",
      "support": 3,
      "rotation": 4
    },
    {
      "x": 2,
      "y": 10,
      "z": 9,
      "name": "Wood_Oak_Trunk",
      "rotation": 4
    },
    {
      "x": 2,
      "y": 11,
      "z": 9,
      "name": "Wood_Oak_Trunk",
      "rotation": 4
    },
    {
      "x": 2,
      "y": 12,
      "z": 9,
      "name": "Wood_Oak_Trunk",
      "rotation": 4
    },
    {
      "x": 2,
      "y": 13,
      "z": 9,
      "name": "Wood_Oak_Trunk",
      "rotation": 4
    },
    {
      "x": 2,
      "y": 9,
      "z": 10,
      "name": "Wood_Oak_Trunk_Full",
      "support": 4,
      "rotation": 4
    },
    {
      "x": 2,
      "y": 10,
      "z": 10,
      "name": "Wood_Oak_Trunk",
      "rotation": 4
    },
    {
      "x": 2,
      "y": 11,
      "z": 10,
      "name": "Wood_Oak_Trunk",
      "rotation": 4
    },
    {
      "x": 2,
      "y": 13,
      "z": 10,
      "name": "Wood_Oak_Trunk",
      "support": 1,
      "rotation": 4
    },
    {
      "x": 2,
      "y": 14,
      "z": 10,
      "name": "Wood_Oak_Trunk_Full",
      "rotation": 4
    },
    {
      "x": 2,
      "y": 10,
      "z": 11,
      "name": "Wood_Oak_Trunk",
      "support": 15,
      "rotation": 4
    },
    {
      "x": 2,
      "y": 13,
      "z": 11,
      "name": "Wood_Oak_Trunk",
      "support": 15,
      "rotation": 4
    },
    {
      "x": 2,
      "y": 10,
      "z": 12,
      "name": "Wood_Oak_Trunk_Full",
      "support": 15,
      "rotation": 4
    },
    {
      "x": 2,
      "y": 13,
      "z": 12,
      "name": "Wood_Oak_Trunk",
      "support": 15,
      "rotation": 4
    },
    {
      "x": 2,
      "y": 13,
      "z": 13,
      "name": "Wood_Oak_Trunk_Full",
      "support": 15,
      "rotation": 4
    },
    {
      "x": 3,
      "y": 2,
      "z": -12,
      "name": "Wood_Oak_Trunk_Full",
      "support": 1,
      "rotation": 4
    },
    {
      "x": 3,
      "y": 1,
      "z": -11,
      "name": "Wood_Oak_Trunk_Full",
      "rotation": 4
    },
    {
      "x": 3,
      "y": 2,
      "z": -11,
      "name": "Wood_Oak_Trunk",
      "rotation": 4
    },
    {
      "x": 3,
      "y": 3,
      "z": -11,
      "name": "Wood_Oak_Trunk_Full",
      "rotation": 4
    },
    {
      "x": 3,
      "y": 1,
      "z": -10,
      "name": "Wood_Oak_Trunk",
      "rotation": 4
    },
    {
      "x": 3,
      "y": 2,
      "z": -10,
      "name": "Wood_Oak_Trunk",
      "rotation": 4
    },
    {
      "x": 3,
      "y": 3,
      "z": -10,
      "name": "Wood_Oak_Trunk",
      "rotation": 4
    },
    {
      "x": 3,
      "y": 1,
      "z": -9,
      "name": "Wood_Oak_Trunk",
      "rotation": 4
    },
    {
      "x": 3,
      "y": 2,
      "z": -9,
      "name": "Wood_Oak_Trunk",
      "rotation": 4
    },
    {
      "x": 3,
      "y": 3,
      "z": -9,
      "name": "Wood_Oak_Trunk",
      "rotation": 4
    },
    {
      "x": 3,
      "y": 1,
      "z": -8,
      "name": "Wood_Oak_Trunk_Full",
      "rotation": 4
    },
    {
      "x": 3,
      "y": 2,
      "z": -8,
      "name": "Wood_Oak_Trunk",
      "rotation": 4
    },
    {
      "x": 3,
      "y": 3,
      "z": -8,
      "name": "Wood_Oak_Trunk_Full",
      "rotation": 4
    },
    {
      "x": 3,
      "y": 2,
      "z": -7,
      "name": "Wood_Oak_Trunk",
      "support": 1,
      "rotation": 4
    },
    {
      "x": 3,
      "y": 2,
      "z": -6,
      "name": "Wood_Oak_Trunk_Full",
      "support": 1,
      "rotation": 4
    },
    {
      "x": 3,
      "y": 3,
      "z": -6,
      "name": "Wood_Oak_Trunk_Full",
      "rotation": 4
    },
    {
      "x": 3,
      "y": 13,
      "z": -4,
      "name": "Wood_Oak_Trunk_Full",
      "support": 1,
      "rotation": 4
    },
    {
      "x": 3,
      "y": 7,
      "z": -3,
      "name": "Wood_Oak_Trunk_Full",
      "support": 1,
      "rotation": 4
    },
    {
      "x": 3,
      "y": 8,
      "z": -3,
      "name": "Wood_Oak_Trunk_Full",
      "rotation": 4
    },
    {
      "x": 3,
      "y": 9,
      "z": -3,
      "name": "Wood_Oak_Trunk_Full",
      "rotation": 4
    },
    {
      "x": 3,
      "y": 10,
      "z": -3,
      "name": "Wood_Oak_Trunk_Full",
      "rotation": 4
    },
    {
      "x": 3,
      "y": 11,
      "z": -3,
      "name": "Wood_Oak_Trunk_Full",
      "rotation": 4
    },
    {
      "x": 3,
      "y": 12,
      "z": -3,
      "name": "Wood_Oak_Trunk_Full",
      "rotation": 4
    },
    {
      "x": 3,
      "y": 13,
      "z": -3,
      "name": "Wood_Oak_Trunk",
      "rotation": 4
    },
    {
      "x": 3,
      "y": 14,
      "z": -3,
      "name": "Wood_Oak_Trunk_Full",
      "rotation": 4
    },
    {
      "x": 3,
      "y": 6,
      "z": -2,
      "name": "Wood_Oak_Trunk_Full",
      "support": 1,
      "rotation": 4
    },
    {
      "x": 3,
      "y": 7,
      "z": -2,
      "name": "Wood_Oak_Trunk",
      "rotation": 4
    },
    {
      "x": 3,
      "y": 8,
      "z": -2,
      "name": "Wood_Oak_Trunk",
      "rotation": 4
    },
    {
      "x": 3,
      "y": 9,
      "z": -2,
      "name": "Wood_Oak_Trunk",
      "rotation": 4
    },
    {
      "x": 3,
      "y": 10,
      "z": -2,
      "name": "Wood_Oak_Trunk",
      "rotation": 4
    },
    {
      "x": 3,
      "y": 11,
      "z": -2,
      "name": "Wood_Oak_Trunk",
      "rotation": 4
    },
    {
      "x": 3,
      "y": 12,
      "z": -2,
      "name": "Wood_Oak_Trunk",
      "rotation": 4
    },
    {
      "x": 3,
      "y": 13,
      "z": -2,
      "name": "Wood_Oak_Trunk",
      "rotation": 4
    },
    {
      "x": 3,
      "y": 14,
      "z": -2,
      "name": "Wood_Oak_Trunk",
      "rotation": 4
    },
    {
      "x": 3,
      "y": 6,
      "z": -1,
      "name": "Wood_Oak_Trunk_Full",
      "support": 1,
      "rotation": 4
    },
    {
      "x": 3,
      "y": 7,
      "z": -1,
      "name": "Wood_Oak_Trunk",
      "rotation": 4
    },
    {
      "x": 3,
      "y": 8,
      "z": -1,
      "name": "Wood_Oak_Trunk",
      "rotation": 4
    },
    {
      "x": 3,
      "y": 9,
      "z": -1,
      "name": "Wood_Oak_Trunk",
      "rotation": 4
    },
    {
      "x": 3,
      "y": 10,
      "z": -1,
      "name": "Wood_Oak_Trunk",
      "rotation": 4
    },
    {
      "x": 3,
      "y": 11,
      "z": -1,
      "name": "Wood_Oak_Trunk",
      "rotation": 4
    },
    {
      "x": 3,
      "y": 12,
      "z": -1,
      "name": "Wood_Oak_Trunk",
      "rotation": 4
    },
    {
      "x": 3,
      "y": 13,
      "z": -1,
      "name": "Wood_Oak_Trunk",
      "rotation": 4
    },
    {
      "x": 3,
      "y": 14,
      "z": -1,
      "name": "Wood_Oak_Trunk",
      "rotation": 4
    },
    {
      "x": 3,
      "y": 7,
      "z": 0,
      "name": "Wood_Oak_Trunk_Full",
      "support": 1,
      "rotation": 4
    },
    {
      "x": 3,
      "y": 8,
      "z": 0,
      "name": "Wood_Oak_Trunk",
      "rotation": 4
    },
    {
      "x": 3,
      "y": 9,
      "z": 0,
      "name": "Wood_Oak_Trunk",
      "rotation": 4
    },
    {
      "x": 3,
      "y": 10,
      "z": 0,
      "name": "Wood_Oak_Trunk",
      "rotation": 4
    },
    {
      "x": 3,
      "y": 11,
      "z": 0,
      "name": "Wood_Oak_Trunk",
      "rotation": 4
    },
    {
      "x": 3,
      "y": 12,
      "z": 0,
      "name": "Wood_Oak_Trunk",
      "rotation": 4
    },
    {
      "x": 3,
      "y": 13,
      "z": 0,
      "name": "Wood_Oak_Trunk",
      "rotation": 4
    },
    {
      "x": 3,
      "y": 14,
      "z": 0,
      "name": "Wood_Oak_Trunk",
      "rotation": 4
    },
    {
      "x": 3,
      "y": 8,
      "z": 1,
      "name": "Wood_Oak_Trunk",
      "support": 1,
      "rotation": 4
    },
    {
      "x": 3,
      "y": 9,
      "z": 1,
      "name": "Wood_Oak_Trunk",
      "rotation": 4
    },
    {
      "x": 3,
      "y": 10,
      "z": 1,
      "name": "Wood_Oak_Trunk",
      "rotation": 4
    },
    {
      "x": 3,
      "y": 11,
      "z": 1,
      "name": "Wood_Oak_Trunk",
      "rotation": 4
    },
    {
      "x": 3,
      "y": 12,
      "z": 1,
      "name": "Wood_Oak_Trunk",
      "rotation": 4
    },
    {
      "x": 3,
      "y": 13,
      "z": 1,
      "name": "Wood_Oak_Trunk",
      "rotation": 4
    },
    {
      "x": 3,
      "y": 14,
      "z": 1,
      "name": "Wood_Oak_Trunk",
      "rotation": 4
    },
    {
      "x": 3,
      "y": 8,
      "z": 2,
      "name": "Wood_Oak_Trunk",
      "support": 2,
      "rotation": 4
    },
    {
      "x": 3,
      "y": 9,
      "z": 2,
      "name": "Wood_Oak_Trunk",
      "rotation": 4
    },
    {
      "x": 3,
      "y": 10,
      "z": 2,
      "name": "Wood_Oak_Trunk",
      "rotation": 4
    },
    {
      "x": 3,
      "y": 11,
      "z": 2,
      "name": "Wood_Oak_Trunk",
      "rotation": 4
    },
    {
      "x": 3,
      "y": 12,
      "z": 2,
      "name": "Wood_Oak_Trunk",
      "rotation": 4
    },
    {
      "x": 3,
      "y": 13,
      "z": 2,
      "name": "Wood_Oak_Trunk",
      "rotation": 4
    },
    {
      "x": 3,
      "y": 14,
      "z": 2,
      "name": "Wood_Oak_Trunk",
      "rotation": 4
    },
    {
      "x": 3,
      "y": 8,
      "z": 3,
      "name": "Wood_Oak_Trunk",
