{
  "version": 8,
  "blockIdVersion": 11,
  "anchorX": -5,
  "anchorY": 0,
  "anchorZ": 0,
  "blocks": [
    {
      "x": -19,
      "y": 0,
      "z": -14,
      "name": "Rock_Basalt_Cobble"
    },
    {
      "x": -19,
      "y": 0,
      "z": -13,
      "name": "Rock_Basalt_Cobble"
    },
    {
      "x": -19,
      "y": 1,
      "z": -13,
      "name": "Wood_Hardwood_Planks_Half",
      "rotation": 7
    },
    {
      "x": -19,
      "y": 2,
      "z": -13,
      "name": "Wood_Hardwood_Planks_Half",
      "rotation": 7
    },
    {
      "x": -19,
      "y": 3,
      "z": -13,
      "name": "Wood_Hardwood_Planks_Half",
      "rotation": 7
    },
    {
      "x": -19,
      "y": 0,
      "z": -12,
      "name": "Rock_Basalt_Cobble"
    },
    {
      "x": -19,
      "y": 1,
      "z": -12,
      "name": "Wood_Hardwood_Planks_Half",
      "rotation": 7
    },
    {
      "x": -19,
      "y": 0,
      "z": -11,
      "name": "Rock_Basalt_Cobble"
    },
    {
      "x": -19,
      "y": 1,
      "z": -11,
      "name": "Wood_Hardwood_Planks_Half",
      "rotation": 7
    },
    {
      "x": -19,
      "y": 0,
      "z": -10,
      "name": "Rock_Basalt_Cobble"
    },
    {
      "x": -19,
      "y": 0,
      "z": 10,
      "name": "Rock_Basalt_Cobble"
    },
    {
      "x": -19,
      "y": 0,
      "z": 11,
      "name": "Rock_Basalt_Cobble"
    },
    {
      "x": -19,
      "y": 1,
      "z": 11,
      "name": "Wood_Hardwood_Planks_Half",
      "rotation": 7
    },
    {
      "x": -19,
      "y": 0,
      "z": 12,
      "name": "Rock_Basalt_Cobble"
    },
    {
      "x": -19,
      "y": 1,
      "z": 12,
      "name": "Wood_Hardwood_Planks_Half",
      "rotation": 7
    },
    {
      "x": -19,
      "y": 0,
      "z": 13,
      "name": "Rock_Basalt_Cobble"
    },
    {
      "x": -19,
      "y": 1,
      "z": 13,
      "name": "Wood_Hardwood_Planks_Half",
      "rotation": 7
    },
    {
      "x": -19,
      "y": 2,
      "z": 13,
      "name": "Wood_Hardwood_Planks_Half",
      "rotation": 7
    },
    {
      "x": -19,
      "y": 3,
      "z": 13,
      "name": "Wood_Hardwood_Planks_Half",
      "rotation": 7
    },
    {
      "x": -19,
      "y": 0,
      "z": 14,
      "name": "Rock_Basalt_Cobble"
    },
    {
      "x": -18,
      "y": 0,
      "z": -14,
      "name": "Rock_Basalt_Cobble"
    },
    {
      "x": -18,
      "y": 1,
      "z": -14,
      "name": "Wood_Hardwood_Planks_Half",
      "rotation": 6
    },
    {
      "x": -18,
      "y": 0,
      "z": -13,
      "name": "Rock_Basalt_Cobble"
    },
    {
      "x": -18,
      "y": 1,
      "z": -13,
      "name": "Wood_Oak_Trunk",
      "support": 15
    },
    {
      "x": -18,
      "y": 2,
      "z": -13,
      "name": "Wood_Oak_Trunk",
      "support": 15
    },
    {
      "x": -18,
      "y": 3,
      "z": -13,
      "name": "Wood_Oak_Trunk",
      "support": 15
    },
    {
      "x": -18,
      "y": 4,
      "z": -13,
      "name": "Wood_Oak_Trunk",
      "support": 15
    },
    {
      "x": -18,
      "y": 5,
      "z": -13,
      "name": "Wood_Oak_Trunk",
      "support": 15
    },
    {
      "x": -18,
      "y": 8,
      "z": -13,
      "name": "Wood_Softwood_Roof_Hollow",
      "rotation": 3
    },
    {
      "x": -18,
      "y": 0,
      "z": -12,
      "name": "Rock_Basalt_Cobble"
    },
    {
      "x": -18,
      "y": 1,
      "z": -12,
      "name": "Wood_Oak_Trunk",
      "support": 15
    },
    {
      "x": -18,
      "y": 2,
      "z": -12,
      "name": "Wood_Oak_Trunk",
      "support": 15
    },
    {
      "x": -18,
      "y": 3,
      "z": -12,
      "name": "Wood_Oak_Trunk",
      "support": 15
    },
    {
      "x": -18,
      "y": 4,
      "z": -12,
      "name": "Wood_Oak_Trunk",
      "support": 15
    },
    {
      "x": -18,
      "y": 5,
      "z": -12,
      "name": "Wood_Oak_Trunk",
      "support": 15
    },
    {
      "x": -18,
      "y": 6,
      "z": -12,
      "name": "Wood_Oak_Trunk",
      "support": 15
    },
    {
      "x": -18,
      "y": 8,
      "z": -12,
      "name": "Wood_Softwood_Roof_Hollow",
      "rotation": 3
    },
    {
      "x": -18,
      "y": 0,
      "z": -11,
      "name": "Rock_Basalt_Cobble"
    },
    {
      "x": -18,
      "y": 1,
      "z": -11,
      "name": "Wood_Oak_Trunk",
      "support": 15
    },
    {
      "x": -18,
      "y": 2,
      "z": -11,
      "name": "Wood_Oak_Trunk",
      "support": 15
    },
    {
      "x": -18,
      "y": 3,
      "z": -11,
      "name": "Wood_Oak_Trunk",
      "support": 15
    },
    {
      "x": -18,
      "y": 4,
      "z": -11,
      "name": "Wood_Oak_Trunk",
      "support": 15
    },
    {
      "x": -18,
      "y": 5,
      "z": -11,
      "name": "Wood_Oak_Trunk",
      "support": 15
    },
    {
      "x": -18,
      "y": 6,
      "z": -11,
      "name": "Wood_Oak_Trunk",
      "support": 15
    },
    {
      "x": -18,
      "y": 7,
      "z": -11,
      "name": "Wood_Oak_Trunk",
      "support": 15
    },
    {
      "x": -18,
      "y": 8,
      "z": -11,
      "name": "Wood_Softwood_Roof",
      "rotation": 3
    },
    {
      "x": -18,
      "y": 0,
      "z": -10,
      "name": "Rock_Basalt_Cobble"
    },
    {
      "x": -18,
      "y": 1,
      "z": -10,
      "name": "Wood_Hardwood_Planks_Half",
      "rotation": 4
    },
    {
      "x": -18,
      "y": 8,
      "z": -10,
      "name": "Wood_Softwood_Roof_Hollow",
      "rotation": 3
    },
    {
      "x": -18,
      "y": 0,
      "z": -9,
      "name": "Rock_Basalt_Cobble"
    },
    {
      "x": -18,
      "y": 8,
      "z": -9,
      "name": "Wood_Softwood_Roof_Hollow",
      "rotation": 3
    },
    {
      "x": -18,
      "y": 0,
      "z": -8,
      "name": "Rock_Basalt_Cobble"
    },
    {
      "x": -18,
      "y": 8,
      "z": -8,
      "name": "Wood_Softwood_Roof_Hollow",
      "rotation": 3
    },
    {
      "x": -18,
      "y": 0,
      "z": -7,
      "name": "Rock_Basalt_Cobble"
    },
    {
      "x": -18,
      "y": 8,
      "z": -7,
      "name": "Wood_Softwood_Roof_Hollow",
      "rotation": 3
    },
    {
      "x": -18,
      "y": 0,
      "z": -6,
      "name": "Rock_Basalt_Cobble"
    },
    {
      "x": -18,
      "y": 8,
      "z": -6,
      "name": "Wood_Softwood_Roof_Hollow",
      "rotation": 3
    },
    {
      "x": -18,
      "y": 0,
      "z": -5,
      "name": "Rock_Basalt_Cobble"
    },
    {
      "x": -18,
      "y": 8,
      "z": -5,
      "name": "Wood_Softwood_Roof_Hollow",
      "rotation": 3
    },
    {
      "x": -18,
      "y": 0,
      "z": -4,
      "name": "Rock_Basalt_Cobble"
    },
    {
      "x": -18,
      "y": 8,
      "z": -4,
      "name": "Wood_Softwood_Roof_Hollow",
      "rotation": 3
    },
    {
      "x": -18,
      "y": 0,
      "z": -3,
      "name": "Rock_Basalt_Cobble"
    },
    {
      "x": -18,
      "y": 8,
      "z": -3,
      "name": "Wood_Softwood_Roof_Hollow",
      "rotation": 3
    },
    {
      "x": -18,
      "y": 0,
      "z": -2,
      "name": "Rock_Basalt_Cobble"
    },
    {
      "x": -18,
      "y": 8,
      "z": -2,
      "name": "Wood_Softwood_Roof_Hollow",
      "rotation": 3
    },
    {
      "x": -18,
      "y": 0,
      "z": -1,
      "name": "Rock_Basalt_Cobble"
    },
    {
      "x": -18,
      "y": 8,
      "z": -1,
      "name": "Wood_Softwood_Roof_Hollow",
      "rotation": 3
    },
    {
      "x": -18,
      "y": 0,
      "z": 0,
      "name": "Rock_Basalt_Cobble"
    },
    {
      "x": -18,
      "y": 8,
      "z": 0,
      "name": "Wood_Softwood_Roof_Hollow",
      "rotation": 3
    },
    {
      "x": -18,
      "y": 0,
      "z": 1,
      "name": "Rock_Basalt_Cobble"
    },
    {
      "x": -18,
      "y": 8,
      "z": 1,
      "name": "Wood_Softwood_Roof_Hollow",
      "rotation": 3
    },
    {
      "x": -18,
      "y": 0,
      "z": 2,
      "name": "Rock_Basalt_Cobble"
    },
    {
      "x": -18,
      "y": 8,
      "z": 2,
      "name": "Wood_Softwood_Roof_Hollow",
      "rotation": 3
    },
    {
      "x": -18,
      "y": 0,
      "z": 3,
      "name": "Rock_Basalt_Cobble"
    },
    {
      "x": -18,
      "y": 8,
      "z": 3,
      "name": "Wood_Softwood_Roof_Hollow",
      "rotation": 3
    },
    {
      "x": -18,
      "y": 0,
      "z": 4,
      "name": "Rock_Basalt_Cobble"
    },
    {
      "x": -18,
      "y": 8,
      "z": 4,
      "name": "Wood_Softwood_Roof_Hollow",
      "rotation": 3
    },
    {
      "x": -18,
      "y": 0,
      "z": 5,
      "name": "Rock_Basalt_Cobble"
    },
    {
      "x": -18,
      "y": 8,
      "z": 5,
      "name": "Wood_Softwood_Roof_Hollow",
      "rotation": 3
    },
    {
      "x": -18,
      "y": 0,
      "z": 6,
      "name": "Rock_Basalt_Cobble"
    },
    {
      "x": -18,
      "y": 8,
      "z": 6,
      "name": "Wood_Softwood_Roof_Hollow",
      "rotation": 3
    },
    {
      "x": -18,
      "y": 0,
      "z": 7,
      "name": "Rock_Basalt_Cobble"
    },
    {
      "x": -18,
      "y": 8,
      "z": 7,
      "name": "Wood_Softwood_Roof_Hollow",
      "rotation": 3
    },
    {
      "x": -18,
      "y": 0,
      "z": 8,
      "name": "Rock_Basalt_Cobble"
    },
    {
      "x": -18,
      "y": 8,
      "z": 8,
      "name": "Wood_Softwood_Roof_Hollow",
      "rotation": 3
    },
    {
      "x": -18,
      "y": 0,
      "z": 9,
      "name": "Rock_Basalt_Cobble"
    },
    {
      "x": -18,
      "y": 8,
      "z": 9,
      "name": "Wood_Softwood_Roof_Hollow",
      "rotation": 3
    },
    {
      "x": -18,
      "y": 0,
      "z": 10,
      "name": "Rock_Basalt_Cobble"
    },
    {
      "x": -18,
      "y": 1,
      "z": 10,
      "name": "Wood_Hardwood_Planks_Half",
      "rotation": 6
    },
    {
      "x": -18,
      "y": 8,
      "z": 10,
      "name": "Wood_Softwood_Roof_Hollow",
      "rotation": 3
    },
    {
      "x": -18,
      "y": 0,
      "z": 11,
      "name": "Rock_Basalt_Cobble"
    },
    {
      "x": -18,
      "y": 1,
      "z": 11,
      "name": "Wood_Oak_Trunk",
      "support": 15
    },
    {
      "x": -18,
      "y": 2,
      "z": 11,
      "name": "Wood_Oak_Trunk",
      "support": 15
    },
    {
      "x": -18,
      "y": 3,
      "z": 11,
      "name": "Wood_Oak_Trunk",
      "support": 15
    },
    {
      "x": -18,
      "y": 4,
      "z": 11,
      "name": "Wood_Oak_Trunk",
      "support": 15
    },
    {
      "x": -18,
      "y": 5,
      "z": 11,
      "name": "Wood_Oak_Trunk",
      "support": 15
    },
    {
      "x": -18,
      "y": 6,
      "z": 11,
      "name": "Wood_Oak_Trunk",
      "support": 15
    },
    {
      "x": -18,
      "y": 7,
      "z": 11,
      "name": "Wood_Oak_Trunk",
      "support": 15
    },
    {
      "x": -18,
      "y": 8,
      "z": 11,
      "name": "Wood_Softwood_Roof",
      "rotation": 3
    },
    {
      "x": -18,
      "y": 0,
      "z": 12,
      "name": "Rock_Basalt_Cobble"
    },
    {
      "x": -18,
      "y": 1,
      "z": 12,
      "name": "Wood_Oak_Trunk",
      "support": 15
    },
    {
      "x": -18,
      "y": 2,
      "z": 12,
      "name": "Wood_Oak_Trunk",
      "support": 15
    },
    {
      "x": -18,
      "y": 3,
      "z": 12,
      "name": "Wood_Oak_Trunk",
      "support": 15
    },
    {
      "x": -18,
      "y": 4,
      "z": 12,
      "name": "Wood_Oak_Trunk",
      "support": 15
    },
    {
      "x": -18,
      "y": 5,
      "z": 12,
      "name": "Wood_Oak_Trunk",
      "support": 15
    },
    {
      "x": -18,
      "y": 6,
      "z": 12,
      "name": "Wood_Oak_Trunk",
      "support": 15
    },
    {
      "x": -18,
      "y": 8,
      "z": 12,
      "name": "Wood_Softwood_Roof_Hollow",
      "rotation": 3
    },
    {
      "x": -18,
      "y": 0,
      "z": 13,
      "name": "Rock_Basalt_Cobble"
    },
    {
      "x": -18,
      "y": 1,
      "z": 13,
      "name": "Wood_Oak_Trunk",
      "support": 15
    },
    {
      "x": -18,
      "y": 2,
      "z": 13,
      "name": "Wood_Oak_Trunk",
      "support": 15
    },
    {
      "x": -18,
      "y": 3,
      "z": 13,
      "name": "Wood_Oak_Trunk",
      "support": 15
    },
    {
      "x": -18,
      "y": 4,
      "z": 13,
      "name": "Wood_Oak_Trunk",
      "support": 15
    },
    {
      "x": -18,
      "y": 5,
      "z": 13,
      "name": "Wood_Oak_Trunk",
      "support": 15
    },
    {
      "x": -18,
      "y": 8,
      "z": 13,
      "name": "Wood_Softwood_Roof_Hollow",
      "rotation": 3
    },
    {
      "x": -18,
      "y": 0,
      "z": 14,
      "name": "Rock_Basalt_Cobble"
    },
    {
      "x": -18,
      "y": 1,
      "z": 14,
      "name": "Wood_Hardwood_Planks_Half",
      "rotation": 4
    },
    {
      "x": -17,
      "y": 0,
      "z": -14,
      "name": "Rock_Basalt_Cobble"
    },
    {
      "x": -17,
      "y": 1,
      "z": -14,
      "name": "Wood_Hardwood_Planks_Half",
      "rotation": 6
    },
    {
      "x": -17,
      "y": 0,
      "z": -13,
      "name": "Rock_Basalt_Cobble"
    },
    {
      "x": -17,
      "y": 1,
      "z": -13,
      "name": "Wood_Oak_Trunk",
      "support": 15
    },
    {
      "x": -17,
      "y": 2,
      "z": -13,
      "name": "Wood_Oak_Trunk",
      "support": 15
    },
    {
      "x": -17,
      "y": 3,
      "z": -13,
      "name": "Wood_Oak_Trunk",
      "support": 15
    },
    {
      "x": -17,
      "y": 4,
      "z": -13,
      "name": "Wood_Oak_Trunk",
      "support": 15
    },
    {
      "x": -17,
      "y": 5,
      "z": -13,
      "name": "Wood_Oak_Trunk",
      "support": 15
    },
    {
      "x": -17,
      "y": 6,
      "z": -13,
      "name": "Wood_Oak_Trunk",
      "support": 15
    },
    {
      "x": -17,
      "y": 9,
      "z": -13,
      "name": "Wood_Softwood_Roof_Shallow",
      "rotation": 3
    },
    {
      "x": -17,
      "y": 0,
      "z": -12,
      "name": "Rock_Basalt_Cobble"
    },
    {
      "x": -17,
      "y": 1,
      "z": -12,
      "name": "Wood_Oak_Trunk",
      "support": 15
    },
    {
      "x": -17,
      "y": 2,
      "z": -12,
      "name": "Wood_Oak_Trunk",
      "support": 15
    },
    {
      "x": -17,
      "y": 3,
      "z": -12,
      "name": "Wood_Oak_Trunk",
      "support": 15
    },
    {
      "x": -17,
      "y": 4,
      "z": -12,
      "name": "Wood_Oak_Trunk",
      "support": 15
    },
    {
      "x": -17,
      "y": 5,
      "z": -12,
      "name": "Wood_Oak_Trunk",
      "support": 15
    },
    {
      "x": -17,
      "y": 6,
      "z": -12,
      "name": "Wood_Oak_Trunk",
      "support": 15
    },
    {
      "x": -17,
      "y": 7,
      "z": -12,
      "name": "Wood_Oak_Trunk",
      "support": 15
    },
    {
      "x": -17,
      "y": 8,
      "z": -12,
      "name": "Wood_Oak_Trunk",
      "support": 15
    },
    {
      "x": -17,
      "y": 9,
      "z": -12,
      "name": "Wood_Softwood_Roof_Shallow",
      "rotation": 3
    },
    {
      "x": -17,
      "y": 0,
      "z": -11,
      "name": "Rock_Basalt_Cobble"
    },
    {
      "x": -17,
      "y": 1,
      "z": -11,
      "name": "Wood_Oak_Trunk",
      "support": 15
    },
    {
      "x": -17,
      "y": 2,
      "z": -11,
      "name": "Wood_Oak_Trunk",
      "support": 15
    },
    {
      "x": -17,
      "y": 3,
      "z": -11,
      "name": "Wood_Oak_Trunk",
      "support": 15
    },
    {
      "x": -17,
      "y": 4,
      "z": -11,
      "name": "Wood_Oak_Trunk",
      "support": 15
    },
    {
      "x": -17,
      "y": 5,
      "z": -11,
      "name": "Wood_Oak_Trunk",
      "support": 15
    },
    {
      "x": -17,
      "y": 6,
      "z": -11,
      "name": "Wood_Oak_Trunk",
      "support": 15
    },
    {
      "x": -17,
      "y": 7,
      "z": -11,
      "name": "Wood_Oak_Trunk",
      "support": 15
    },
    {
      "x": -17,
      "y": 8,
      "z": -11,
      "name": "Wood_Oak_Trunk",
      "support": 15
    },
    {
      "x": -17,
      "y": 9,
      "z": -11,
      "name": "Wood_Softwood_Roof_Shallow",
      "rotation": 3
    },
    {
      "x": -17,
      "y": 0,
      "z": -10,
      "name": "Rock_Basalt_Cobble"
    },
    {
      "x": -17,
      "y": 1,
      "z": -10,
      "name": "Wood_Softwood_Decorative"
    },
    {
      "x": -17,
      "y": 2,
      "z": -10,
      "name": "Wood_Softwood_Decorative"
    },
    {
      "x": -17,
      "y": 3,
      "z": -10,
      "name": "Wood_Softwood_Decorative"
    },
    {
      "x": -17,
      "y": 4,
      "z": -10,
      "name": "Wood_Softwood_Decorative"
    },
    {
      "x": -17,
      "y": 5,
      "z": -10,
      "name": "Wood_Softwood_Decorative"
    },
    {
      "x": -17,
      "y": 6,
      "z": -10,
      "name": "Wood_Oak_Trunk",
      "support": 15,
      "rotation": 4
    },
    {
      "x": -17,
      "y": 7,
      "z": -10,
      "name": "Wood_Softwood_Decorative"
    },
    {
      "x": -17,
      "y": 8,
      "z": -10,
      "name": "Wood_Softwood_Decorative"
    },
    {
      "x": -17,
      "y": 9,
      "z": -10,
      "name": "Wood_Softwood_Roof_Shallow",
      "rotation": 3
    },
    {
      "x": -17,
      "y": 0,
      "z": -9,
      "name": "Rock_Basalt_Cobble"
    },
    {
      "x": -17,
      "y": 1,
      "z": -9,
      "name": "Wood_Softwood_Planks"
    },
    {
      "x": -17,
      "y": 2,
      "z": -9,
      "name": "Wood_Softwood_Planks"
    },
    {
      "x": -17,
      "y": 3,
      "z": -9,
      "name": "Wood_Softwood_Planks"
    },
    {
      "x": -17,
      "y": 4,
      "z": -9,
      "name": "Wood_Softwood_Planks"
    },
    {
      "x": -17,
      "y": 5,
      "z": -9,
      "name": "Wood_Softwood_Stairs",
      "rotation": 3
    },
    {
      "x": -17,
      "y": 6,
      "z": -9,
      "name": "Wood_Oak_Trunk",
      "support": 15,
      "rotation": 4
    },
    {
      "x": -17,
      "y": 7,
      "z": -9,
      "name": "Wood_Softwood_Stairs",
      "rotation": 9
    },
    {
      "x": -17,
      "y": 8,
      "z": -9,
      "name": "Wood_Softwood_Planks"
    },
    {
      "x": -17,
      "y": 9,
      "z": -9,
      "name": "Wood_Softwood_Roof_Shallow",
      "rotation": 3
    },
    {
      "x": -17,
      "y": 0,
      "z": -8,
      "name": "Rock_Basalt_Cobble"
    },
    {
      "x": -17,
      "y": 1,
      "z": -8,
      "name": "Wood_Softwood_Planks_Half",
      "rotation": 7
    },
    {
      "x": -17,
      "y": 2,
      "z": -8,
      "name": "Wood_Softwood_Planks_Half",
      "rotation": 7
    },
    {
      "x": -17,
      "y": 3,
      "z": -8,
      "name": "Wood_Softwood_Planks_Half",
      "rotation": 7
    },
    {
      "x": -17,
      "y": 4,
      "z": -8,
      "name": "Wood_Softwood_Planks_Half",
      "rotation": 7
    },
    {
      "x": -17,
      "y": 5,
      "z": -8,
      "name": "Wood_Softwood_Planks_Half",
      "rotation": 7
    },
    {
      "x": -17,
      "y": 6,
      "z": -8,
      "name": "Wood_Oak_Trunk",
      "support": 15,
      "rotation": 4
    },
    {
      "x": -17,
      "y": 7,
      "z": -8,
      "name": "Wood_Softwood_Stairs",
      "rotation": 9
    },
    {
      "x": -17,
      "y": 8,
      "z": -8,
      "name": "Wood_Softwood_Planks"
    },
    {
      "x": -17,
      "y": 9,
      "z": -8,
      "name": "Wood_Softwood_Roof_Shallow",
      "rotation": 3
    },
    {
      "x": -17,
      "y": 0,
      "z": -7,
      "name": "Rock_Basalt_Cobble"
    },
    {
      "x": -17,
      "y": 1,
      "z": -7,
      "name": "Wood_Softwood_Planks"
    },
    {
      "x": -17,
      "y": 2,
      "z": -7,
      "name": "Wood_Softwood_Planks"
    },
    {
      "x": -17,
      "y": 3,
      "z": -7,
      "name": "Wood_Softwood_Planks"
    },
    {
      "x": -17,
      "y": 4,
      "z": -7,
      "name": "Wood_Softwood_Planks"
    },
    {
      "x": -17,
      "y": 5,
      "z": -7,
      "name": "Wood_Softwood_Stairs",
      "rotation": 3
    },
    {
      "x": -17,
      "y": 6,
      "z": -7,
      "name": "Wood_Oak_Trunk",
      "support": 15,
      "rotation": 4
    },
    {
      "x": -17,
      "y": 7,
      "z": -7,
      "name": "Wood_Softwood_Stairs",
      "rotation": 9
    },
    {
      "x": -17,
      "y": 8,
      "z": -7,
      "name": "Wood_Softwood_Planks"
    },
    {
      "x": -17,
      "y": 9,
      "z": -7,
      "name": "Wood_Softwood_Roof_Shallow",
      "rotation": 3
    },
    {
      "x": -17,
      "y": 0,
      "z": -6,
      "name": "Rock_Basalt_Cobble"
    },
    {
      "x": -17,
      "y": 1,
      "z": -6,
      "name": "Wood_Softwood_Planks"
    },
    {
      "x": -17,
      "y": 2,
      "z": -6,
      "name": "Wood_Softwood_Planks"
    },
    {
      "x": -17,
      "y": 3,
      "z": -6,
      "name": "Wood_Softwood_Planks"
    },
    {
      "x": -17,
      "y": 4,
      "z": -6,
      "name": "Wood_Softwood_Planks"
    },
    {
      "x": -17,
      "y": 5,
      "z": -6,
      "name": "Wood_Softwood_Stairs",
      "rotation": 3
    },
    {
      "x": -17,
      "y": 6,
      "z": -6,
      "name": "Wood_Oak_Trunk",
      "support": 15,
      "rotation": 4
    },
    {
      "x": -17,
      "y": 7,
      "z": -6,
      "name": "Wood_Softwood_Stairs",
      "rotation": 9
    },
    {
      "x": -17,
      "y": 8,
      "z": -6,
      "name": "Wood_Softwood_Planks"
    },
    {
      "x": -17,
      "y": 9,
      "z": -6,
      "name": "Wood_Softwood_Roof_Shallow",
      "rotation": 3
    },
    {
      "x": -17,
      "y": 0,
      "z": -5,
      "name": "Rock_Basalt_Cobble"
    },
    {
      "x": -17,
      "y": 1,
      "z": -5,
      "name": "Wood_Softwood_Planks_Half",
      "rotation": 7
    },
    {
      "x": -17,
      "y": 2,
      "z": -5,
      "name": "Wood_Softwood_Planks_Half",
      "rotation": 7
    },
    {
      "x": -17,
      "y": 3,
      "z": -5,
      "name": "Wood_Softwood_Planks_Half",
      "rotation": 7
    },
    {
      "x": -17,
      "y": 4,
      "z": -5,
      "name": "Wood_Softwood_Planks"
    },
    {
      "x": -17,
      "y": 5,
      "z": -5,
      "name": "Wood_Softwood_Stairs",
      "rotation": 3
    },
    {
      "x": -17,
      "y": 6,
      "z": -5,
      "name": "Wood_Oak_Trunk",
      "support": 15,
      "rotation": 4
    },
    {
      "x": -17,
      "y": 7,
      "z": -5,
      "name": "Wood_Softwood_Stairs",
      "rotation": 9
    },
    {
      "x": -17,
      "y": 8,
      "z": -5,
      "name": "Wood_Softwood_Planks"
    },
    {
      "x": -17,
      "y": 9,
      "z": -5,
      "name": "Wood_Softwood_Roof_Shallow",
      "rotation": 3
    },
    {
      "x": -17,
      "y": 0,
      "z": -4,
      "name": "Rock_Basalt_Cobble"
    },
    {
      "x": -17,
      "y": 1,
      "z": -4,
      "name": "Wood_Softwood_Planks"
    },
    {
      "x": -17,
      "y": 2,
      "z": -4,
      "name": "Wood_Softwood_Planks"
    },
    {
      "x": -17,
      "y": 3,
      "z": -4,
      "name": "Wood_Softwood_Planks"
    },
    {
      "x": -17,
      "y": 4,
      "z": -4,
      "name": "Wood_Softwood_Planks"
    },
    {
      "x": -17,
      "y": 5,
      "z": -4,
      "name": "Wood_Softwood_Stairs",
      "rotation": 3
    },
    {
      "x": -17,
      "y": 6,
      "z": -4,
      "name": "Wood_Oak_Trunk",
      "support": 15,
      "rotation": 4
    },
    {
      "x": -17,
      "y": 7,
      "z": -4,
      "name": "Wood_Softwood_Stairs",
      "rotation": 9
    },
    {
      "x": -17,
      "y": 8,
      "z": -4,
      "name": "Wood_Softwood_Planks"
    },
    {
      "x": -17,
      "y": 9,
      "z": -4,
      "name": "Wood_Softwood_Roof_Shallow",
      "rotation": 3
    },
    {
      "x": -17,
      "y": 0,
      "z": -3,
      "name": "Rock_Basalt_Cobble"
    },
    {
      "x": -17,
      "y": 1,
      "z": -3,
      "name": "Wood_Softwood_Planks"
    },
    {
      "x": -17,
      "y": 2,
      "z": -3,
      "name": "Wood_Softwood_Planks"
    },
    {
      "x": -17,
      "y": 3,
      "z": -3,
      "name": "Wood_Softwood_Planks"
    },
    {
      "x": -17,
      "y": 4,
      "z": -3,
      "name": "Wood_Softwood_Planks"
    },
    {
      "x": -17,
      "y": 5,
      "z": -3,
      "name": "Wood_Softwood_Stairs",
      "rotation": 3
    },
    {
      "x": -17,
      "y": 6,
      "z": -3,
      "name": "Wood_Oak_Trunk",
      "support": 15,
      "rotation": 4
    },
    {
      "x": -17,
      "y": 7,
      "z": -3,
      "name": "Wood_Softwood_Stairs",
      "rotation": 9
    },
    {
      "x": -17,
      "y": 8,
      "z": -3,
      "name": "Wood_Softwood_Planks"
    },
    {
      "x": -17,
      "y": 9,
      "z": -3,
      "name": "Wood_Softwood_Roof_Shallow",
      "rotation": 3
    },
    {
      "x": -17,
      "y": 0,
      "z": -2,
      "name": "Rock_Basalt_Cobble"
    },
    {
      "x": -17,
      "y": 1,
      "z": -2,
      "name": "Wood_Softwood_Planks_Half",
      "rotation": 7
    },
    {
      "x": -17,
      "y": 2,
      "z": -2,
      "name": "Wood_Softwood_Planks_Half",
      "rotation": 7
    },
    {
      "x": -17,
      "y": 3,
      "z": -2,
      "name": "Wood_Softwood_Planks_Half",
      "rotation": 7
    },
    {
      "x": -17,
      "y": 4,
      "z": -2,
      "name": "Wood_Softwood_Planks_Half",
      "rotation": 7
    },
    {
      "x": -17,
      "y": 5,
      "z": -2,
      "name": "Wood_Softwood_Planks_Half",
      "rotation": 7
    },
    {
      "x": -17,
      "y": 6,
      "z": -2,
      "name": "Wood_Oak_Trunk",
      "support": 15,
      "rotation": 4
    },
    {
      "x": -17,
      "y": 7,
      "z": -2,
      "name": "Wood_Softwood_Stairs",
      "rotation": 9
    },
    {
      "x": -17,
      "y": 8,
      "z": -2,
      "name": "Wood_Softwood_Planks"
    },
    {
      "x": -17,
      "y": 9,
      "z": -2,
      "name": "Wood_Softwood_Roof_Shallow",
      "rotation": 3
    },
    {
      "x": -17,
      "y": 0,
      "z": -1,
      "name": "Rock_Basalt_Cobble"
    },
    {
      "x": -17,
      "y": 1,
      "z": -1,
      "name": "Wood_Softwood_Planks"
    },
    {
      "x": -17,
      "y": 2,
      "z": -1,
      "name": "Wood_Softwood_Planks"
    },
    {
      "x": -17,
      "y": 3,
      "z": -1,
      "name": "Wood_Softwood_Planks"
    },
    {
      "x": -17,
      "y": 4,
      "z": -1,
      "name": "Wood_Softwood_Planks"
    },
    {
      "x": -17,
      "y": 5,
      "z": -1,
      "name": "Wood_Softwood_Stairs",
      "rotation": 3
    },
    {
      "x": -17,
      "y": 6,
      "z": -1,
      "name": "Wood_Oak_Trunk",
      "support": 15,
      "rotation": 4
    },
    {
      "x": -17,
      "y": 7,
      "z": -1,
      "name": "Wood_Softwood_Stairs",
      "rotation": 9
    },
    {
      "x": -17,
      "y": 8,
      "z": -1,
      "name": "Wood_Softwood_Planks"
    },
    {
      "x": -17,
      "y": 9,
      "z": -1,
      "name": "Wood_Softwood_Roof_Shallow",
      "rotation": 3
    },
    {
      "x": -17,
      "y": 0,
      "z": 0,
      "name": "Rock_Basalt_Cobble"
    },
    {
      "x": -17,
      "y": 1,
      "z": 0,
      "name": "Wood_Softwood_Decorative"
    },
    {
      "x": -17,
      "y": 2,
      "z": 0,
      "name": "Wood_Softwood_Decorative"
    },
    {
      "x": -17,
      "y": 3,
      "z": 0,
      "name": "Wood_Softwood_Decorative"
    },
    {
      "x": -17,
      "y": 4,
      "z": 0,
      "name": "Wood_Softwood_Decorative"
    },
    {
      "x": -17,
      "y": 5,
      "z": 0,
      "name": "Wood_Softwood_Decorative"
    },
    {
      "x": -17,
      "y": 6,
      "z": 0,
      "name": "Wood_Oak_Trunk",
      "support": 15,
      "rotation": 4
    },
    {
      "x": -17,
      "y": 7,
      "z": 0,
      "name": "Wood_Softwood_Decorative"
    },
    {
      "x": -17,
      "y": 8,
      "z": 0,
      "name": "Wood_Softwood_Decorative"
    },
    {
      "x": -17,
      "y": 9,
      "z": 0,
      "name": "Wood_Softwood_Roof_Shallow",
      "rotation": 3
    },
    {
      "x": -17,
      "y": 0,
      "z": 1,
      "name": "Rock_Basalt_Cobble"
    },
    {
      "x": -17,
      "y": 1,
      "z": 1,
      "name": "Wood_Softwood_Planks"
    },
    {
      "x": -17,
      "y": 2,
      "z": 1,
      "name": "Wood_Softwood_Planks"
    },
    {
      "x": -17,
      "y": 3,
      "z": 1,
      "name": "Wood_Softwood_Planks"
    },
    {
      "x": -17,
      "y": 4,
      "z": 1,
      "name": "Wood_Softwood_Planks"
    },
    {
      "x": -17,
      "y": 5,
      "z": 1,
      "name": "Wood_Softwood_Stairs",
      "rotation": 3
    },
    {
      "x": -17,
      "y": 6,
      "z": 1,
      "name": "Wood_Oak_Trunk",
      "support": 15,
      "rotation": 4
    },
    {
      "x": -17,
      "y": 7,
      "z": 1,
      "name": "Wood_Softwood_Stairs",
      "rotation": 9
    },
    {
      "x": -17,
      "y": 8,
      "z": 1,
      "name": "Wood_Softwood_Planks"
    },
    {
      "x": -17,
      "y": 9,
      "z": 1,
      "name": "Wood_Softwood_Roof_Shallow",
      "rotation": 3
    },
    {
      "x": -17,
      "y": 0,
      "z": 2,
      "name": "Rock_Basalt_Cobble"
    },
    {
      "x": -17,
      "y": 1,
      "z": 2,
      "name": "Wood_Softwood_Planks_Half",
      "rotation": 7
    },
    {
      "x": -17,
      "y": 2,
      "z": 2,
      "name": "Wood_Softwood_Planks_Half",
      "rotation": 7
    },
    {
      "x": -17,
      "y": 3,
      "z": 2,
      "name": "Wood_Softwood_Planks_Half",
      "rotation": 7
    },
    {
      "x": -17,
      "y": 4,
      "z": 2,
      "name": "Wood_Softwood_Planks_Half",
      "rotation": 7
    },
    {
      "x": -17,
      "y": 5,
      "z": 2,
      "name": "Wood_Softwood_Planks_Half",
      "rotation": 7
    },
    {
      "x": -17,
      "y": 6,
      "z": 2,
      "name": "Wood_Oak_Trunk",
      "support": 15,
      "rotation": 4
    },
    {
      "x": -17,
      "y": 7,
      "z": 2,
      "name": "Wood_Softwood_Stairs",
      "rotation": 9
    },
    {
      "x": -17,
      "y": 8,
      "z": 2,
      "name": "Wood_Softwood_Planks"
    },
    {
      "x": -17,
      "y": 9,
      "z": 2,
      "name": "Wood_Softwood_Roof_Shallow",
      "rotation": 3
    },
    {
      "x": -17,
      "y": 0,
      "z": 3,
      "name": "Rock_Basalt_Cobble"
    },
    {
      "x": -17,
      "y": 1,
      "z": 3,
      "name": "Wood_Softwood_Planks"
    },
    {
      "x": -17,
      "y": 2,
      "z": 3,
      "name": "Wood_Softwood_Planks"
    },
    {
      "x": -17,
      "y": 3,
      "z": 3,
      "name": "Wood_Softwood_Planks"
    },
    {
      "x": -17,
      "y": 4,
      "z": 3,
      "name": "Wood_Softwood_Planks"
    },
    {
      "x": -17,
      "y": 5,
      "z": 3,
      "name": "Wood_Softwood_Stairs",
      "rotation": 3
    },
    {
      "x": -17,
      "y": 6,
      "z": 3,
      "name": "Wood_Oak_Trunk",
      "support": 15,
      "rotation": 4
    },
    {
      "x": -17,
      "y": 7,
      "z": 3,
      "name": "Wood_Softwood_Stairs",
      "rotation": 9
    },
    {
      "x": -17,
      "y": 8,
      "z": 3,
      "name": "Wood_Softwood_Planks"
    },
    {
      "x": -17,
      "y": 9,
      "z": 3,
      "name": "Wood_Softwood_Roof_Shallow",
      "rotation": 3
    },
    {
      "x": -17,
      "y": 0,
      "z": 4,
      "name": "Rock_Basalt_Cobble"
    },
    {
      "x": -17,
      "y": 1,
      "z": 4,
      "name": "Wood_Softwood_Planks"
    },
    {
      "x": -17,
      "y": 2,
      "z": 4,
      "name": "Wood_Softwood_Planks"
    },
    {
      "x": -17,
      "y": 3,
      "z": 4,
      "name": "Wood_Softwood_Planks"
    },
    {
      "x": -17,
      "y": 4,
      "z": 4,
      "name": "Wood_Softwood_Planks"
    },
    {
      "x": -17,
      "y": 5,
      "z": 4,
      "name": "Wood_Softwood_Stairs",
      "rotation": 3
    },
    {
      "x": -17,
      "y": 6,
      "z": 4,
      "name": "Wood_Oak_Trunk",
      "support": 15,
      "rotation": 4
    },
    {
      "x": -17,
      "y": 7,
      "z": 4,
      "name": "Wood_Softwood_Stairs",
      "rotation": 9
    },
    {
      "x": -17,
      "y": 8,
      "z": 4,
      "name": "Wood_Softwood_Planks"
    },
    {
      "x": -17,
      "y": 9,
      "z": 4,
      "name": "Wood_Softwood_Roof_Shallow",
      "rotation": 3
    },
    {
      "x": -17,
      "y": 0,
      "z": 5,
      "name": "Rock_Basalt_Cobble"
    },
    {
      "x": -17,
      "y": 1,
      "z": 5,
      "name": "Wood_Softwood_Planks_Half",
      "rotation": 7
    },
    {
      "x": -17,
      "y": 2,
      "z": 5,
      "name": "Wood_Softwood_Planks_Half",
      "rotation": 7
    },
    {
      "x": -17,
      "y": 3,
      "z": 5,
      "name": "Wood_Softwood_Planks_Half",
      "rotation": 7
    },
    {
      "x": -17,
      "y": 4,
      "z": 5,
      "name": "Wood_Softwood_Planks"
    },
    {
      "x": -17,
      "y": 5,
      "z": 5,
      "name": "Wood_Softwood_Stairs",
      "rotation": 3
    },
    {
      "x": -17,
      "y": 6,
      "z": 5,
      "name": "Wood_Oak_Trunk",
      "support": 15,
      "rotation": 4
    },
    {
      "x": -17,
      "y": 7,
      "z": 5,
      "name": "Wood_Softwood_Stairs",
      "rotation": 9
    },
    {
      "x": -17,
      "y": 8,
      "z": 5,
      "name": "Wood_Softwood_Planks"
    },
    {
      "x": -17,
      "y": 9,
      "z": 5,
      "name": "Wood_Softwood_Roof_Shallow",
      "rotation": 3
    },
    {
      "x": -17,
      "y": 0,
      "z": 6,
      "name": "Rock_Basalt_Cobble"
    },
    {
      "x": -17,
      "y": 1,
      "z": 6,
      "name": "Wood_Softwood_Planks"
    },
    {
      "x": -17,
      "y": 2,
      "z": 6,
      "name": "Wood_Softwood_Planks"
    },
    {
      "x": -17,
      "y": 3,
      "z": 6,
      "name": "Wood_Softwood_Planks"
    },
    {
      "x": -17,
      "y": 4,
      "z": 6,
      "name": "Wood_Softwood_Planks"
    },
    {
      "x": -17,
      "y": 5,
      "z": 6,
      "name": "Wood_Softwood_Stairs",
      "rotation": 3
    },
    {
      "x": -17,
      "y": 6,
      "z": 6,
      "name": "Wood_Oak_Trunk",
      "support": 15,
      "rotation": 4
    },
    {
      "x": -17,
      "y": 7,
      "z": 6,
      "name": "Wood_Softwood_Stairs",
      "rotation": 9
    },
    {
      "x": -17,
      "y": 8,
      "z": 6,
      "name": "Wood_Softwood_Planks"
    },
    {
      "x": -17,
      "y": 9,
      "z": 6,
      "name": "Wood_Softwood_Roof_Shallow",
      "rotation": 3
    },
    {
      "x": -17,
      "y": 0,
      "z": 7,
      "name": "Rock_Basalt_Cobble"
    },
    {
      "x": -17,
      "y": 1,
      "z": 7,
      "name": "Wood_Softwood_Planks"
    },
    {
      "x": -17,
      "y": 2,
      "z": 7,
      "name": "Wood_Softwood_Planks"
    },
    {
      "x": -17,
      "y": 3,
      "z": 7,
      "name": "Wood_Softwood_Planks"
    },
    {
      "x": -17,
      "y": 4,
      "z": 7,
      "name": "Wood_Softwood_Planks"
    },
    {
      "x": -17,
      "y": 5,
      "z": 7,
      "name": "Wood_Softwood_Stairs",
      "rotation": 3
    },
    {
      "x": -17,
      "y": 6,
      "z": 7,
      "name": "Wood_Oak_Trunk",
      "support": 15,
      "rotation": 4
    },
    {
      "x": -17,
      "y": 7,
      "z": 7,
      "name": "Wood_Softwood_Stairs",
      "rotation": 9
    },
    {
      "x": -17,
      "y": 8,
      "z": 7,
      "name": "Wood_Softwood_Planks"
    },
    {
      "x": -17,
      "y": 9,
      "z": 7,
      "name": "Wood_Softwood_Roof_Shallow",
      "rotation": 3
    },
    {
      "x": -17,
      "y": 0,
      "z": 8,
      "name": "Rock_Basalt_Cobble"
    },
    {
      "x": -17,
      "y": 1,
      "z": 8,
      "name": "Wood_Softwood_Planks_Half",
      "rotation": 7
    },
    {
      "x": -17,
      "y": 2,
      "z": 8,
      "name": "Wood_Softwood_Planks_Half",
      "rotation": 7
    },
    {
      "x": -17,
      "y": 3,
      "z": 8,
      "name": "Wood_Softwood_Planks_Half",
      "rotation": 7
    },
    {
      "x": -17,
      "y": 4,
      "z": 8,
      "name": "Wood_Softwood_Planks_Half",
      "rotation": 7
    },
    {
      "x": -17,
      "y": 5,
      "z": 8,
      "name": "Wood_Softwood_Planks_Half",
      "rotation": 7
    },
    {
      "x": -17,
      "y": 6,
      "z": 8,
      "name": "Wood_Oak_Trunk",
      "support": 15,
      "rotation": 4
    },
    {
      "x": -17,
      "y": 7,
      "z": 8,
      "name": "Wood_Softwood_Stairs",
      "rotation": 9
    },
    {
      "x": -17,
      "y": 8,
      "z": 8,
      "name": "Wood_Softwood_Planks"
    },
    {
      "x": -17,
      "y": 9,
      "z": 8,
      "name": "Wood_Softwood_Roof_Shallow",
      "rotation": 3
    },
    {
      "x": -17,
      "y": 0,
      "z": 9,
      "name": "Rock_Basalt_Cobble"
    },
    {
      "x": -17,
      "y": 1,
      "z": 9,
      "name": "Wood_Softwood_Planks"
    },
    {
      "x": -17,
      "y": 2,
      "z": 9,
      "name": "Wood_Softwood_Planks"
    },
    {
      "x": -17,
      "y": 3,
      "z": 9,
      "name": "Wood_Softwood_Planks"
    },
    {
      "x": -17,
      "y": 4,
      "z": 9,
      "name": "Wood_Softwood_Planks"
    },
    {
      "x": -17,
      "y": 5,
      "z": 9,
      "name": "Wood_Softwood_Stairs",
      "rotation": 3
    },
    {
      "x": -17,
      "y": 6,
      "z": 9,
      "name": "Wood_Oak_Trunk",
      "support": 15,
      "rotation": 4
    },
    {
      "x": -17,
      "y": 7,
      "z": 9,
      "name": "Wood_Softwood_Stairs",
      "rotation": 9
    },
    {
      "x": -17,
      "y": 8,
      "z": 9,
      "name": "Wood_Softwood_Planks"
    },
    {
      "x": -17,
      "y": 9,
      "z": 9,
      "name": "Wood_Softwood_Roof_Shallow",
      "rotation": 3
    },
    {
      "x": -17,
      "y": 0,
      "z": 10,
      "name": "Rock_Basalt_Cobble"
    },
    {
      "x": -17,
      "y": 1,
      "z": 10,
      "name": "Wood_Softwood_Decorative"
    },
    {
      "x": -17,
      "y": 2,
      "z": 10,
      "name": "Wood_Softwood_Decorative"
    },
    {
      "x": -17,
      "y": 3,
      "z": 10,
      "name": "Wood_Softwood_Decorative"
    },
    {
      "x": -17,
      "y": 4,
      "z": 10,
      "name": "Wood_Softwood_Decorative"
    },
    {
      "x": -17,
      "y": 5,
      "z": 10,
      "name": "Wood_Softwood_Decorative"
    },
    {
      "x": -17,
      "y": 6,
      "z": 10,
      "name": "Wood_Oak_Trunk",
      "support": 15,
      "rotation": 4
    },
    {
      "x": -17,
      "y": 7,
      "z": 10,
      "name": "Wood_Softwood_Decorative"
    },
    {
      "x": -17,
      "y": 8,
      "z": 10,
      "name": "Wood_Softwood_Decorative"
    },
    {
      "x": -17,
      "y": 9,
      "z": 10,
      "name": "Wood_Softwood_Roof_Shallow",
      "rotation": 3
    },
    {
      "x": -17,
      "y": 0,
      "z": 11,
      "name": "Rock_Basalt_Cobble"
    },
    {
      "x": -17,
      "y": 1,
      "z": 11,
      "name": "Wood_Oak_Trunk",
      "support": 15
    },
    {
      "x": -17,
      "y": 2,
      "z": 11,
      "name": "Wood_Oak_Trunk",
      "support": 15
    },
    {
      "x": -17,
      "y": 3,
      "z": 11,
      "name": "Wood_Oak_Trunk",
      "support": 15
    },
    {
      "x": -17,
      "y": 4,
      "z": 11,
      "name": "Wood_Oak_Trunk",
      "support": 15
    },
    {
      "x": -17,
      "y": 5,
      "z": 11,
      "name": "Wood_Oak_Trunk",
      "support": 15
    },
    {
      "x": -17,
      "y": 6,
      "z": 11,
      "name": "Wood_Oak_Trunk",
      "support": 15
    },
    {
      "x": -17,
      "y": 7,
      "z": 11,
      "name": "Wood_Oak_Trunk",
      "support": 15
    },
    {
      "x": -17,
      "y": 8,
      "z": 11,
      "name": "Wood_Oak_Trunk",
      "support": 15
    },
    {
      "x": -17,
      "y": 9,
      "z": 11,
      "name": "Wood_Softwood_Roof_Shallow",
      "rotation": 3
    },
    {
      "x": -17,
      "y": 0,
      "z": 12,
      "name": "Rock_Basalt_Cobble"
    },
    {
      "x": -17,
      "y": 1,
      "z": 12,
      "name": "Wood_Oak_Trunk",
      "support": 15
    },
    {
      "x": -17,
      "y": 2,
      "z": 12,
      "name": "Wood_Oak_Trunk",
      "support": 15
    },
    {
      "x": -17,
      "y": 3,
      "z": 12,
      "name": "Wood_Oak_Trunk",
      "support": 15
    },
    {
      "x": -17,
      "y": 4,
      "z": 12,
      "name": "Wood_Oak_Trunk",
      "support": 15
    },
    {
      "x": -17,
      "y": 5,
      "z": 12,
      "name": "Wood_Oak_Trunk",
      "support": 15
    },
    {
      "x": -17,
      "y": 6,
      "z": 12,
      "name": "Wood_Oak_Trunk",
      "support": 15
    },
    {
      "x": -17,
      "y": 7,
      "z": 12,
      "name": "Wood_Oak_Trunk",
      "support": 15
    },
    {
      "x": -17,
      "y": 8,
      "z": 12,
      "name": "Wood_Oak_Trunk",
      "support": 15
    },
    {
      "x": -17,
      "y": 9,
      "z": 12,
      "name": "Wood_Softwood_Roof_Shallow",
      "rotation": 3
    },
    {
      "x": -17,
      "y": 0,
      "z": 13,
      "name": "Rock_Basalt_Cobble"
    },
    {
      "x": -17,
      "y": 1,
      "z": 13,
      "name": "Wood_Oak_Trunk",
      "support": 15
    },
    {
      "x": -17,
      "y": 2,
      "z": 13,
      "name": "Wood_Oak_Trunk",
      "support": 15
    },
    {
      "x": -17,
      "y": 3,
      "z": 13,
      "name": "Wood_Oak_Trunk",
      "support": 15
    },
    {
      "x": -17,
      "y": 4,
      "z": 13,
      "name": "Wood_Oak_Trunk",
      "support": 15
    },
    {
      "x": -17,
      "y": 5,
      "z": 13,
      "name": "Wood_Oak_Trunk",
      "support": 15
    },
    {
      "x": -17,
      "y": 6,
      "z": 13,
      "name": "Wood_Oak_Trunk",
      "support": 15
    },
    {
      "x": -17,
      "y": 9,
      "z": 13,
      "name": "Wood_Softwood_Roof_Shallow",
      "rotation": 3
    },
    {
      "x": -17,
      "y": 0,
      "z": 14,
      "name": "Rock_Basalt_Cobble"
    },
    {
      "x": -17,
      "y": 1,
      "z": 14,
      "name": "Wood_Hardwood_Planks_Half",
      "rotation": 4
    },
    {
      "x": -16,
      "y": 0,
      "z": -14,
      "name": "Rock_Basalt_Cobble"
    },
    {
      "x": -16,
      "y": 1,
      "z": -14,
      "name": "Wood_Hardwood_Planks_Half",
      "rotation": 6
    },
    {
      "x": -16,
      "y": 2,
      "z": -14,
      "name": "Wood_Hardwood_Planks_Half",
      "rotation": 6
    },
    {
      "x": -16,
      "y": 3,
      "z": -14,
      "name": "Wood_Hardwood_Planks_Half",
      "rotation": 6
    },
    {
      "x": -16,
      "y": 0,
      "z": -13,
      "name": "Rock_Basalt_Cobble"
    },
    {
      "x": -16,
      "y": 1,
      "z": -13,
      "name": "Wood_Oak_Trunk",
      "support": 15
    },
    {
      "x": -16,
      "y": 2,
      "z": -13,
      "name": "Wood_Oak_Trunk",
      "support": 15
    },
    {
      "x": -16,
      "y": 3,
      "z": -13,
      "name": "Wood_Oak_Trunk",
      "support": 15
    },
    {
      "x": -16,
      "y": 4,
      "z": -13,
      "name": "Wood_Oak_Trunk",
      "support": 15
    },
    {
      "x": -16,
      "y": 5,
      "z": -13,
      "name": "Wood_Oak_Trunk",
      "support": 15
    },
    {
      "x": -16,
      "y": 6,
      "z": -13,
      "name": "Wood_Oak_Trunk",
      "support": 15
    },
    {
      "x": -16,
      "y": 7,
      "z": -13,
      "name": "Wood_Oak_Trunk",
      "support": 15
    },
    {
      "x": -16,
      "y": 9,
      "z": -13,
      "name": "Wood_Softwood_Roof_Shallow",
      "filler": 1,
      "rotation": 3
    },
    {
      "x": -16,
      "y": 0,
      "z": -12,
      "name": "Rock_Basalt_Cobble"
    },
    {
      "x": -16,
      "y": 1,
      "z": -12,
      "name": "Wood_Oak_Trunk",
      "support": 15
    },
    {
      "x": -16,
      "y": 2,
      "z": -12,
      "name": "Wood_Oak_Trunk",
      "support": 15
    },
    {
      "x": -16,
      "y": 3,
      "z": -12,
      "name": "Wood_Oak_Trunk",
      "support": 15
    },
    {
      "x": -16,
      "y": 4,
      "z": -12,
      "name": "Wood_Oak_Trunk",
      "support": 15
    },
    {
      "x": -16,
      "y": 5,
      "z": -12,
      "name": "Wood_Oak_Trunk",
      "support": 15
    },
    {
      "x": -16,
      "y": 6,
      "z": -12,
      "name": "Wood_Oak_Trunk",
      "support": 15
    },
    {
      "x": -16,
      "y": 7,
      "z": -12,
      "name": "Wood_Oak_Trunk",
      "support": 15
    },
    {
      "x": -16,
      "y": 8,
      "z": -12,
      "name": "Wood_Oak_Trunk",
      "support": 15
    },
    {
      "x": -16,
      "y": 9,
      "z": -12,
      "name": "Wood_Softwood_Roof_Shallow",
      "filler": 1,
      "rotation": 3
    },
    {
      "x": -16,
      "y": 0,
      "z": -11,
      "name": "Rock_Basalt_Cobble"
    },
    {
      "x": -16,
      "y": 1,
      "z": -11,
      "name": "Wood_Oak_Trunk",
      "support": 15
    },
    {
      "x": -16,
      "y": 2,
      "z": -11,
      "name": "Wood_Oak_Trunk",
      "support": 15
    },
    {
      "x": -16,
      "y": 3,
      "z": -11,
      "name": "Wood_Oak_Trunk",
      "support": 15
    },
    {
      "x": -16,
      "y": 4,
      "z": -11,
      "name": "Wood_Oak_Trunk",
      "support": 15
    },
    {
      "x": -16,
      "y": 5,
      "z": -11,
      "name": "Wood_Oak_Trunk",
      "support": 15
    },
    {
      "x": -16,
      "y": 6,
      "z": -11,
      "name": "Wood_Oak_Trunk",
      "support": 15
    },
    {
      "x": -16,
      "y": 7,
      "z": -11,
      "name": "Wood_Oak_Trunk",
      "support": 15
    },
    {
      "x": -16,
      "y": 8,
      "z": -11,
      "name": "Wood_Oak_Trunk",
      "support": 15
    },
    {
      "x": -16,
      "y": 9,
      "z": -11,
      "name": "Wood_Softwood_Roof_Shallow",
      "filler": 1,
      "rotation": 3
    },
    {
      "x": -16,
      "y": 0,
      "z": -10,
      "name": "Wood_Softwood_Planks"
    },
    {
      "x": -16,
      "y": 1,
      "z": -10,
      "name": "Wood_Hardwood_Planks_Half",
      "rotation": 4
    },
    {
      "x": -16,
      "y": 6,
      "z": -10,
      "name": "Wood_Hardwood_Planks_Half",
      "rotation": 4
    },
    {
      "x": -16,
      "y": 8,
      "z": -10,
      "name": "Wood_Softwood_Planks_Half",
      "rotation": 8
    },
    {
      "x": -16,
      "y": 9,
      "z": -10,
      "name": "Wood_Softwood_Roof_Shallow",
      "filler": 1,
      "rotation": 3
    },
    {
      "x": -16,
      "y": 0,
      "z": -9,
      "name": "Wood_Softwood_Planks"
    },
    {
      "x": -16,
      "y": 8,
      "z": -9,
      "name": "Wood_Softwood_Planks_Half",
      "rotation": 8
    },
    {
      "x": -16,
      "y": 9,
      "z": -9,
      "name": "Wood_Softwood_Roof_Shallow",
      "filler": 1,
      "rotation": 3
    },
    {
      "x": -16,
      "y": 0,
      "z": -8,
      "name": "Wood_Softwood_Planks"
    },
    {
      "x": -16,
      "y": 8,
      "z": -8,
      "name": "Wood_Softwood_Planks_Half",
      "rotation": 8
    },
    {
      "x": -16,
      "y": 9,
      "z": -8,
      "name": "Wood_Softwood_Roof_Shallow",
      "filler": 1,
      "rotation": 3
    },
    {
      "x": -16,
      "y": 0,
      "z": -7,
      "name": "Wood_Softwood_Planks"
    },
    {
      "x": -16,
      "y": 8,
      "z": -7,
      "name": "Wood_Softwood_Planks_Half",
      "rotation": 8
    },
    {
      "x": -16,
      "y": 9,
      "z": -7,
      "name": "Wood_Softwood_Roof_Shallow",
      "filler": 1,
      "rotation": 3
    },
    {
      "x": -16,
      "y": 0,
      "z": -6,
      "name": "Wood_Softwood_Planks"
    },
    {
      "x": -16,
      "y": 1,
      "z": -6,
      "name": "Furniture_Lumberjack_Table",
      "filler": 992,
      "rotation": 1
    },
    {
      "x": -16,
      "y": 8,
      "z": -6,
      "name": "Wood_Softwood_Planks_Half",
      "rotation": 8
    },
    {
      "x": -16,
      "y": 9,
      "z": -6,
      "name": "Wood_Softwood_Roof_Shallow",
      "filler": 1,
      "rotation": 3
    },
    {
      "x": -16,
      "y": 0,
      "z": -5,
      "name": "Wood_Softwood_Planks"
    },
    {
      "x": -16,
      "y": 1,
      "z": -5,
      "name": "Furniture_Lumberjack_Table",
      "rotation": 1
    },
    {
      "x": -16,
      "y": 2,
      "z": -5,
      "name": "*Furniture_Lumberjack_Lantern_State_Definitions_Off"
    },
    {
      "x": -16,
      "y": 8,
      "z": -5,
      "name": "Wood_Softwood_Planks_Half",
      "rotation": 8
    },
    {
      "x": -16,
      "y": 9,
      "z": -5,
      "name": "Wood_Softwood_Roof_Shallow",
      "filler": 1,
      "rotation": 3
    },
    {
      "x": -16,
      "y": 0,
      "z": -4,
      "name": "Wood_Softwood_Planks"
    },
    {
      "x": -16,
      "y": 8,
      "z": -4,
      "name": "Wood_Softwood_Planks_Half",
      "rotation": 8
    },
    {
      "x": -16,
      "y": 9,
      "z": -4,
      "name": "Wood_Softwood_Roof_Shallow",
      "filler": 1,
      "rotation": 3
    },
    {
      "x": -16,
      "y": 0,
      "z": -3,
      "name": "Wood_Softwood_Planks"
    },
    {
      "x": -16,
      "y": 1,
      "z": -3,
      "name": "Furniture_Tavern_Barrel"
    },
    {
      "x": -16,
      "y": 8,
      "z": -3,
      "name": "Wood_Softwood_Planks_Half",
      "rotation": 8
    },
    {
      "x": -16,
      "y": 9,
      "z": -3,
      "name": "Wood_Softwood_Roof_Shallow",
      "filler": 1,
      "rotation": 3
    },
    {
      "x": -16,
      "y": 0,
      "z": -2,
      "name": "Wood_Softwood_Planks"
    },
    {
      "x": -16,
      "y": 1,
      "z": -2,
      "name": "Furniture_Village_Table",
      "filler": 992,
      "rotation": 1
    },
    {
      "x": -16,
      "y": 2,
      "z": -2,
      "name": "Deco_Scroll",
      "rotation": 1
    },
    {
      "x": -16,
      "y": 8,
      "z": -2,
      "name": "Wood_Softwood_Planks_Half",
      "rotation": 8
    },
    {
      "x": -16,
      "y": 9,
      "z": -2,
      "name": "Wood_Softwood_Roof_Shallow",
      "filler": 1,
      "rotation": 3
    },
    {
      "x": -16,
      "y": 0,
      "z": -1,
      "name": "Wood_Softwood_Planks"
    },
    {
      "x": -16,
      "y": 1,
      "z": -1,
      "name": "Furniture_Village_Table",
      "rotation": 1
    },
    {
      "x": -16,
      "y": 2,
      "z": -1,
      "name": "Deco_Scroll"
    },
    {
      "x": -16,
      "y": 8,
      "z": -1,
      "name": "Wood_Softwood_Planks_Half",
      "rotation": 8
    },
    {
      "x": -16,
      "y": 9,
      "z": -1,
      "name": "Wood_Softwood_Roof_Shallow",
      "filler": 1,
      "rotation": 3
    },
    {
      "x": -16,
      "y": 0,
      "z": 0,
      "name": "Wood_Softwood_Planks"
    },
    {
      "x": -16,
      "y": 8,
      "z": 0,
      "name": "Wood_Softwood_Planks_Half",
      "rotation": 8
    },
    {
      "x": -16,
      "y": 9,
      "z": 0,
      "name": "Wood_Softwood_Roof_Shallow",
      "filler": 1,
      "rotation": 3
    },
    {
      "x": -16,
      "y": 0,
      "z": 1,
      "name": "Wood_Softwood_Planks"
    },
    {
      "x": -16,
      "y": 1,
      "z": 1,
      "name": "Wood_Sticks",
      "support": 15
    },
    {
      "x": -16,
      "y": 8,
      "z": 1,
      "name": "Wood_Softwood_Planks_Half",
      "rotation": 8
    },
    {
      "x": -16,
      "y": 9,
      "z": 1,
      "name": "Wood_Softwood_Roof_Shallow",
      "filler": 1,
      "rotation": 3
    },
    {
      "x": -16,
      "y": 0,
      "z": 2,
      "name": "Wood_Softwood_Planks"
    },
    {
      "x": -16,
      "y": 1,
      "z": 2,
      "name": "Wood_Softwood_Ornate"
    },
    {
      "x": -16,
      "y": 2,
      "z": 2,
      "name": "Deco_Scroll",
      "rotation": 1
    },
    {
      "x": -16,
      "y": 8,
      "z": 2,
      "name": "Wood_Softwood_Planks_Half",
      "rotation": 8
    },
    {
      "x": -16,
      "y": 9,
      "z": 2,
      "name": "Wood_Softwood_Roof_Shallow",
      "filler": 1,
      "rotation": 3
    },
    {
      "x": -16,
      "y": 0,
      "z": 3,
      "name": "Wood_Softwood_Planks"
    },
    {
      "x": -16,
      "y": 1,
      "z": 3,
      "name": "Bench_WorkBench",
      "filler": 992,
      "rotation": 3
    },
    {
      "x": -16,
      "y": 3,
      "z": 3,
      "name": "Furniture_Village_Bookcase",
      "rotation": 1
    },
    {
      "x": -16,
      "y": 8,
      "z": 3,
      "name": "Wood_Softwood_Planks_Half",
      "rotation": 8
    },
    {
      "x": -16,
      "y": 9,
      "z": 3,
      "name": "Wood_Softwood_Roof_Shallow",
      "filler": 1,
      "rotation": 3
    },
    {
      "x": -16,
      "y": 0,
      "z": 4,
      "name": "Wood_Softwood_Planks"
    },
    {
      "x": -16,
      "y": 1,
      "z": 4,
      "name": "Bench_WorkBench",
      "components": {
        "Components": {
          "BenchBlock": {
            "TierLevel": 1,
            "UpgradeItems": []
          },
          "PlacedByInteraction": {
            "WhoPlacedUuid": {
              "$binary": "JMPNY5cWR9+IOfPEr8/h7w==",
              "$type": "04"
            }
          }
        }
      },
      "rotation": 3
    },
    {
      "x": -16,
      "y": 3,
      "z": 4,
      "name": "Furniture_Village_Shelf_Full",
      "rotation": 1
    },
    {
      "x": -16,
      "y": 8,
      "z": 4,
      "name": "Wood_Softwood_Planks_Half",
      "rotation": 8
    },
    {
      "x": -16,
      "y": 9,
      "z": 4,
      "name": "Wood_Softwood_Roof_Shallow",
      "filler": 1,
      "rotation": 3
    },
    {
      "x": -16,
      "y": 0,
      "z": 5,
      "name": "Wood_Softwood_Planks"
    },
    {
      "x": -16,
      "y": 1,
      "z": 5,
      "name": "Wood_Softwood_Ornate"
    },
    {
      "x": -16,
      "y": 2,
      "z": 5,
      "name": "Deco_Map",
      "rotation": 1
    },
    {
      "x": -16,
      "y": 3,
      "z": 5,
      "name": "Furniture_Village_Shelf_Full",
      "rotation": 1
    },
    {
      "x": -16,
      "y": 8,
      "z": 5,
      "name": "Wood_Softwood_Planks_Half",
      "rotation": 8
    },
    {
      "x": -16,
      "y": 9,
      "z": 5,
      "name": "Wood_Softwood_Roof_Shallow",
      "filler": 1,
      "rotation": 3
    },
    {
      "x": -16,
      "y": 0,
      "z": 6,
      "name": "Wood_Softwood_Planks"
    },
    {
      "x": -16,
      "y": 1,
      "z": 6,
      "name": "Bench_WorkBench",
      "components": {
        "Components": {
          "BenchBlock": {
            "TierLevel": 1,
            "UpgradeItems": []
          },
          "PlacedByInteraction": {
            "WhoPlacedUuid": {
              "$binary": "JMPNY5cWR9+IOfPEr8/h7w==",
              "$type": "04"
            }
          }
        }
      },
      "rotation": 1
    },
    {
      "x": -16,
      "y": 3,
      "z": 6,
      "name": "Furniture_Village_Shelf_Full",
      "rotation": 1
    },
    {
      "x": -16,
      "y": 8,
      "z": 6,
      "name": "Wood_Softwood_Planks_Half",
      "rotation": 8
    },
    {
      "x": -16,
      "y": 9,
      "z": 6,
      "name": "Wood_Softwood_Roof_Shallow",
      "filler": 1,
      "rotation": 3
    },
    {
      "x": -16,
      "y": 0,
      "z": 7,
      "name": "Wood_Softwood_Planks"
    },
    {
      "x": -16,
      "y": 1,
      "z": 7,
      "name": "Bench_WorkBench",
      "filler": 32,
      "rotation": 1
    },
    {
      "x": -16,
      "y": 3,
      "z": 7,
      "name": "Furniture_Village_Shelf_Full",
      "rotation": 1
    },
    {
      "x": -16,
      "y": 8,
      "z": 7,
      "name": "Wood_Softwood_Planks_Half",
      "rotation": 8
    },
    {
      "x": -16,
      "y": 9,
      "z": 7,
      "name": "Wood_Softwood_Roof_Shallow",
      "filler": 1,
      "rotation": 3
    },
    {
      "x": -16,
      "y": 0,
      "z": 8,
      "name": "Wood_Softwood_Planks"
    },
    {
      "x": -16,
      "y": 1,
      "z": 8,
      "name": "Bench_Builders",
      "components": {
        "Components": {
          "BenchBlock": {
            "TierLevel": 1,
            "UpgradeItems": []
          },
          "PlacedByInteraction": {
            "WhoPlacedUuid": {
              "$binary": "JMPNY5cWR9+IOfPEr8/h7w==",
              "$type": "04"
            }
          }
        }
      },
      "rotation": 1
    },
    {
      "x": -16,
      "y": 2,
      "z": 8,
      "name": "Bench_Builders",
      "filler": 1024,
      "rotation": 1
    },
    {
      "x": -16,
      "y": 3,
      "z": 8,
      "name": "Furniture_Village_Shelf_Full",
      "rotation": 1
    },
    {
      "x": -16,
      "y": 8,
      "z": 8,
      "name": "Wood_Softwood_Planks_Half",
      "rotation": 8
    },
    {
      "x": -16,
      "y": 9,
      "z": 8,
      "name": "Wood_Softwood_Roof_Shallow",
      "filler": 1,
      "rotation": 3
    },
    {
      "x": -16,
      "y": 0,
      "z": 9,
      "name": "Wood_Softwood_Planks"
    },
    {
      "x": -16,
      "y": 1,
      "z": 9,
      "name": "Bench_Builders",
      "filler": 32,
      "rotation": 1
    },
    {
      "x": -16,
      "y": 2,
      "z": 9,
      "name": "Bench_Builders",
      "filler": 1056,
      "rotation": 1
    },
    {
      "x": -16,
      "y": 8,
      "z": 9,
      "name": "Wood_Softwood_Planks_Half",
      "rotation": 8
    },
    {
      "x": -16,
      "y": 9,
      "z": 9,
      "name": "Wood_Softwood_Roof_Shallow",
      "filler": 1,
      "rotation": 3
    },
    {
      "x": -16,
      "y": 0,
      "z": 10,
      "name": "Wood_Softwood_Planks"
    },
    {
      "x": -16,
      "y": 1,
      "z": 10,
      "name": "Wood_Hardwood_Planks_Half",
      "rotation": 6
    },
    {
      "x": -16,
      "y": 6,
      "z": 10,
      "name": "Wood_Hardwood_Planks_Half",
      "rotation": 6
    },
    {
      "x": -16,
      "y": 8,
      "z": 10,
      "name": "Wood_Softwood_Planks_Half",
      "rotation": 8
    },
    {
      "x": -16,
      "y": 9,
      "z": 10,
      "name": "Wood_Softwood_Roof_Shallow",
      "filler": 1,
      "rotation": 3
    },
    {
      "x": -16,
      "y": 0,
      "z": 11,
      "name": "Rock_Basalt_Cobble"
    },
    {
      "x": -16,
      "y": 1,
      "z": 11,
      "name": "Wood_Oak_Trunk",
      "support": 15
    },
    {
      "x": -16,
      "y": 2,
      "z": 11,
      "name": "Wood_Oak_Trunk",
      "support": 15
    },
    {
      "x": -16,
      "y": 3,
      "z": 11,
      "name": "Wood_Oak_Trunk",
      "support": 15
    },
    {
      "x": -16,
      "y": 4,
      "z": 11,
      "name": "Wood_Oak_Trunk",
      "support": 15
    },
    {
      "x": -16,
      "y": 5,
      "z": 11,
      "name": "Wood_Oak_Trunk",
      "support": 15
    },
    {
      "x": -16,
      "y": 6,
      "z": 11,
      "name": "Wood_Oak_Trunk",
      "support": 15
    },
    {
      "x": -16,
      "y": 7,
      "z": 11,
      "name": "Wood_Oak_Trunk",
      "support": 15
    },
    {
      "x": -16,
      "y": 8,
      "z": 11,
      "name": "Wood_Oak_Trunk",
      "support": 15
    },
    {
      "x": -16,
      "y": 9,
      "z": 11,
      "name": "Wood_Softwood_Roof_Shallow",
      "filler": 1,
      "rotation": 3
    },
    {
      "x": -16,
      "y": 0,
      "z": 12,
      "name": "Rock_Basalt_Cobble"
    },
    {
      "x": -16,
      "y": 1,
      "z": 12,
      "name": "Wood_Oak_Trunk",
      "support": 15
    },
    {
      "x": -16,
      "y": 2,
      "z": 12,
      "name": "Wood_Oak_Trunk",
      "support": 15
    },
    {
      "x": -16,
      "y": 3,
      "z": 12,
      "name": "Wood_Oak_Trunk",
      "support": 15
    },
    {
      "x": -16,
      "y": 4,
      "z": 12,
      "name": "Wood_Oak_Trunk",
      "support": 15
    },
    {
      "x": -16,
      "y": 5,
      "z": 12,
      "name": "Wood_Oak_Trunk",
      "support": 15
    },
    {
      "x": -16,
      "y": 6,
      "z": 12,
      "name": "Wood_Oak_Trunk",
      "support": 15
    },
    {
      "x": -16,
      "y": 7,
      "z": 12,
      "name": "Wood_Oak_Trunk",
      "support": 15
    },
    {
      "x": -16,
      "y": 8,
      "z": 12,
      "name": "Wood_Oak_Trunk",
      "support": 15
    },
    {
      "x": -16,
      "y": 9,
      "z": 12,
      "name": "Wood_Softwood_Roof_Shallow",
      "filler": 1,
      "rotation": 3
    },
    {
      "x": -16,
      "y": 0,
      "z": 13,
      "name": "Rock_Basalt_Cobble"
    },
    {
      "x": -16,
      "y": 1,
      "z": 13,
      "name": "Wood_Oak_Trunk",
      "support": 15
    },
    {
      "x": -16,
      "y": 2,
      "z": 13,
      "name": "Wood_Oak_Trunk",
      "support": 15
    },
    {
      "x": -16,
      "y": 3,
      "z": 13,
      "name": "Wood_Oak_Trunk",
      "support": 15
    },
    {
      "x": -16,
      "y": 4,
      "z": 13,
      "name": "Wood_Oak_Trunk",
      "support": 15
    },
    {
      "x": -16,
      "y": 5,
      "z": 13,
      "name": "Wood_Oak_Trunk",
      "support": 15
    },
    {
      "x": -16,
      "y": 6,
      "z": 13,
      "name": "Wood_Oak_Trunk",
      "support": 15
    },
    {
      "x": -16,
      "y": 7,
      "z": 13,
      "name": "Wood_Oak_Trunk",
      "support": 15
    },
    {
      "x": -16,
      "y": 9,
      "z": 13,
      "name": "Wood_Softwood_Roof_Shallow",
      "filler": 1,
      "rotation": 3
    },
    {
      "x": -16,
      "y": 0,
      "z": 14,
      "name": "Rock_Basalt_Cobble"
    },
    {
      "x": -16,
      "y": 1,
      "z": 14,
      "name": "Wood_Hardwood_Planks_Half",
      "rotation": 4
    },
    {
      "x": -16,
      "y": 2,
      "z": 14,
      "name": "Wood_Hardwood_Planks_Half",
      "rotation": 4
    },
    {
      "x": -16,
      "y": 3,
      "z": 14,
      "name": "Wood_Hardwood_Planks_Half",
      "rotation": 4
    },
    {
      "x": -15,
      "y": 0,
      "z": -14,
      "name": "Rock_Basalt_Cobble"
    },
    {
      "x": -15,
      "y": 0,
      "z": -13,
      "name": "Rock_Basalt_Cobble"
    },
    {
      "x": -15,
      "y": 1,
      "z": -13,
      "name": "Wood_Hardwood_Planks_Half",
      "rotation": 5
    },
    {
      "x": -15,
      "y": 10,
      "z": -13,
      "name": "Wood_Softwood_Roof_Shallow",
      "rotation": 3
    },
    {
      "x": -15,
      "y": 0,
      "z": -12,
      "name": "Rock_Basalt_Cobble"
    },
    {
      "x": -15,
      "y": 1,
      "z": -12,
      "name": "Wood_Softwood_Decorative"
    },
    {
      "x": -15,
      "y": 2,
      "z": -12,
      "name": "Wood_Softwood_Decorative"
    },
    {
      "x": -15,
      "y": 3,
      "z": -12,
      "name": "Wood_Softwood_Decorative"
    },
    {
      "x": -15,
      "y": 4,
      "z": -12,
      "name": "Wood_Softwood_Decorative"
    },
    {
      "x": -15,
      "y": 5,
      "z": -12,
      "name": "Wood_Softwood_Decorative"
    },
    {
      "x": -15,
      "y": 6,
      "z": -12,
      "name": "Wood_Oak_Trunk",
      "support": 15,
      "rotation": 5
    },
    {
      "x": -15,
      "y": 7,
      "z": -12,
      "name": "Wood_Softwood_Decorative"
    },
    {
      "x": -15,
      "y": 8,
      "z": -12,
      "name": "Wood_Softwood_Decorative"
    },
    {
      "x": -15,
      "y": 9,
      "z": -12,
      "name": "Wood_Softwood_Decorative"
    },
    {
      "x": -15,
      "y": 10,
      "z": -12,
      "name": "Wood_Softwood_Roof_Shallow",
      "rotation": 3
    },
    {
      "x": -15,
      "y": 0,
      "z": -11,
      "name": "Wood_Softwood_Planks"
    },
    {
      "x": -15,
      "y": 1,
      "z": -11,
      "name": "Wood_Hardwood_Planks_Half",
      "rotation": 5
    },
    {
      "x": -15,
      "y": 6,
      "z": -11,
      "name": "Wood_Hardwood_Planks_Half",
      "rotation": 5
    },
    {
      "x": -15,
      "y": 9,
      "z": -11,
      "name": "Wood_Softwood_Planks"
    },
    {
      "x": -15,
      "y": 10,
      "z": -11,
      "name": "Wood_Softwood_Roof_Shallow",
      "rotation": 3
    },
    {
      "x": -15,
      "y": 0,
      "z": -10,
      "name": "Wood_Softwood_Planks"
    },
    {
      "x": -15,
      "y": 1,
      "z": -10,
      "name": "Furniture_Tavern_Barrel"
    },
    {
      "x": -15,
      "y": 9,
      "z": -10,
      "name": "Wood_Softwood_Planks"
    },
    {
      "x": -15,
      "y": 10,
      "z": -10,
      "name": "Wood_Softwood_Roof_Shallow",
      "rotation": 3
    },
    {
      "x": -15,
      "y": 0,
      "z": -9,
      "name": "Wood_Softwood_Planks"
    },
    {
      "x": -15,
      "y": 1,
      "z": -9,
      "name": "Furniture_Village_Crate"
    },
    {
      "x": -15,
      "y": 2,
      "z": -9,
      "name": "Furniture_Village_Crate"
    },
    {
      "x": -15,
      "y": 9,
      "z": -9,
      "name": "Wood_Softwood_Planks"
    },
    {
      "x": -15,
      "y": 10,
      "z": -9,
      "name": "Wood_Softwood_Roof_Shallow",
      "rotation": 3
    },
    {
      "x": -15,
      "y": 0,
      "z": -8,
      "name": "Wood_Softwood_Planks"
    },
    {
      "x": -15,
      "y": 1,
      "z": -8,
      "name": "Furniture_Village_Crate"
    },
    {
      "x": -15,
      "y": 2,
      "z": -8,
      "name": "Deco_Scroll"
    },
    {
      "x": -15,
      "y": 9,
      "z": -8,
      "name": "Wood_Softwood_Planks"
    },
    {
      "x": -15,
      "y": 10,
      "z": -8,
      "name": "Wood_Softwood_Roof_Shallow",
      "rotation": 3
    },
    {
      "x": -15,
      "y": 0,
      "z": -7,
      "name": "Wood_Softwood_Planks"
    },
    {
      "x": -15,
      "y": 9,
      "z": -7,
      "name": "Wood_Softwood_Planks"
    },
    {
      "x": -15,
      "y": 10,
      "z": -7,
      "name": "Wood_Softwood_Roof_Shallow",
      "rotation": 3
    },
    {
      "x": -15,
      "y": 0,
      "z": -6,
      "name": "Wood_Softwood_Planks"
    },
    {
      "x": -15,
      "y": 1,
      "z": -6,
      "name": "Furniture_Lumberjack_Table",
      "filler": 993,
      "rotation": 1
    },
    {
      "x": -15,
      "y": 2,
      "z": -6,
      "name": "Wood_Sticks",
      "support": 15
    },
    {
      "x": -15,
      "y": 9,
      "z": -6,
      "name": "Wood_Softwood_Planks"
    },
    {
      "x": -15,
      "y": 10,
      "z": -6,
      "name": "Wood_Softwood_Roof_Shallow",
      "rotation": 3
    },
    {
      "x": -15,
      "y": 0,
      "z": -5,
      "name": "Wood_Softwood_Planks"
    },
    {
      "x": -15,
      "y": 1,
      "z": -5,
      "name": "Furniture_Lumberjack_Table",
      "filler": 1,
      "rotation": 1
    },
    {
      "x": -15,
      "y": 9,
      "z": -5,
      "name": "Wood_Softwood_Planks"
    },
    {
      "x": -15,
      "y": 10,
      "z": -5,
      "name": "Wood_Softwood_Roof_Shallow",
      "rotation": 3
    },
    {
      "x": -15,
      "y": 0,
      "z": -4,
      "name": "Wood_Softwood_Planks"
    },
    {
      "x": -15,
      "y": 9,
      "z": -4,
      "name": "Wood_Softwood_Planks"
    },
    {
      "x": -15,
      "y": 10,
      "z": -4,
      "name": "Wood_Softwood_Roof_Shallow",
      "rotation": 3
    },
    {
      "x": -15,
      "y": 0,
      "z": -3,
      "name": "Wood_Softwood_Planks"
    },
    {
      "x": -15,
      "y": 9,
      "z": -3,
      "name": "Wood_Softwood_Planks"
    },
    {
      "x": -15,
      "y": 10,
      "z": -3,
      "name": "Wood_Softwood_Roof_Shallow",
      "rotation": 3
    },
    {
      "x": -15,
      "y": 0,
      "z": -2,
      "name": "Wood_Softwood_Planks"
    },
    {
      "x": -15,
      "y": 1,
      "z": -2,
      "name": "Furniture_Village_Table",
      "filler": 993,
      "rotation": 1
    },
    {
      "x": -15,
      "y": 2,
      "z": -2,
      "name": "Deco_Potion",
      "rotation": 1
    },
    {
      "x": -15,
      "y": 9,
      "z": -2,
      "name": "Wood_Softwood_Planks"
    },
    {
      "x": -15,
      "y": 10,
      "z": -2,
      "name": "Wood_Softwood_Roof_Shallow",
      "rotation": 3
    },
    {
      "x": -15,
      "y": 0,
      "z": -1,
      "name": "Wood_Softwood_Planks"
    },
    {
      "x": -15,
      "y": 1,
      "z": -1,
      "name": "Furniture_Village_Table",
      "filler": 1,
      "rotation": 1
    },
    {
      "x": -15,
      "y": 2,
      "z": -1,
      "name": "Deco_Map",
      "rotation": 1
    },
    {
      "x": -15,
      "y": 9,
      "z": -1,
      "name": "Wood_Softwood_Planks"
    },
    {
      "x": -15,
      "y": 10,
      "z": -1,
      "name": "Wood_Softwood_Roof_Shallow",
      "rotation": 3
    },
    {
      "x": -15,
      "y": 0,
      "z": 0,
      "name": "Wood_Softwood_Planks"
    },
    {
      "x": -15,
      "y": 9,
      "z": 0,
      "name": "Wood_Softwood_Planks"
    },
    {
      "x": -15,
      "y": 10,
      "z": 0,
      "name": "Wood_Softwood_Roof_Shallow",
      "rotation": 3
    },
    {
      "x": -15,
      "y": 0,
      "z": 1,
      "name": "Wood_Softwood_Planks"
    },
    {
      "x": -15,
      "y": 9,
      "z": 1,
      "name": "Wood_Softwood_Planks"
    },
    {
      "x": -15,
      "y": 10,
      "z": 1,
      "name": "Wood_Softwood_Roof_Shallow",
      "rotation": 3
    },
    {
      "x": -15,
      "y": 0,
      "z": 2,
      "name": "Wood_Softwood_Planks"
    },
    {
      "x": -15,
      "y": 9,
      "z": 2,
      "name": "Wood_Softwood_Planks"
    },
    {
      "x": -15,
      "y": 10,
      "z": 2,
      "name": "Wood_Softwood_Roof_Shallow",
      "rotation": 3
    },
    {
      "x": -15,
      "y": 0,
      "z": 3,
      "name": "Wood_Softwood_Planks"
    },
    {
      "x": -15,
      "y": 9,
      "z": 3,
      "name": "Wood_Softwood_Planks"
    },
    {
      "x": -15,
      "y": 10,
      "z": 3,
      "name": "Wood_Softwood_Roof_Shallow",
      "rotation": 3
    },
    {
      "x": -15,
      "y": 0,
      "z": 4,
      "name": "Wood_Softwood_Planks"
    },
    {
      "x": -15,
      "y": 9,
      "z": 4,
      "name": "Wood_Softwood_Planks"
    },
    {
      "x": -15,
      "y": 10,
      "z": 4,
      "name": "Wood_Softwood_Roof_Shallow",
      "rotation": 3
    },
    {
      "x": -15,
      "y": 0,
      "z": 5,
      "name": "Wood_Softwood_Planks"
    },
    {
      "x": -15,
      "y": 9,
      "z": 5,
      "name": "Wood_Softwood_Planks"
    },
    {
      "x": -15,
      "y": 10,
      "z": 5,
      "name": "Wood_Softwood_Roof_Shallow",
      "rotation": 3
    },
    {
      "x": -15,
      "y": 0,
      "z": 6,
      "name": "Wood_Softwood_Planks"
    },
    {
      "x": -15,
      "y": 9,
      "z": 6,
      "name": "Wood_Softwood_Planks"
    },
    {
      "x": -15,
      "y": 10,
      "z": 6,
      "name": "Wood_Softwood_Roof_Shallow",
      "rotation": 3
    },
    {
      "x": -15,
      "y": 0,
      "z": 7,
      "name": "Wood_Softwood_Planks"
    },
    {
      "x": -15,
      "y": 9,
      "z": 7,
      "name": "Wood_Softwood_Planks"
    },
    {
      "x": -15,
      "y": 10,
      "z": 7,
      "name": "Wood_Softwood_Roof_Shallow",
      "rotation": 3
    },
    {
      "x": -15,
      "y": 0,
      "z": 8,
      "name": "Wood_Softwood_Planks"
    },
    {
      "x": -15,
      "y": 9,
      "z": 8,
      "name": "Wood_Softwood_Planks"
    },
    {
      "x": -15,
      "y": 10,
      "z": 8,
      "name": "Wood_Softwood_Roof_Shallow",
      "rotation": 3
    },
    {
      "x": -15,
      "y": 0,
      "z": 9,
      "name": "Wood_Softwood_Planks"
    },
    {
      "x": -15,
      "y": 9,
      "z": 9,
      "name": "Wood_Softwood_Planks"
    },
    {
      "x": -15,
      "y": 10,
      "z": 9,
      "name": "Wood_Softwood_Roof_Shallow",
      "rotation": 3
    },
    {
      "x": -15,
      "y": 0,
      "z": 10,
      "name": "Wood_Softwood_Planks"
    },
    {
      "x": -15,
      "y": 1,
      "z": 10,
      "name": "Furniture_Village_Pot"
    },
    {
      "x": -15,
      "y": 9,
      "z": 10,
      "name": "Wood_Softwood_Planks"
    },
    {
      "x": -15,
      "y": 10,
      "z": 10,
      "name": "Wood_Softwood_Roof_Shallow",
      "rotation": 3
    },
    {
      "x": -15,
      "y": 0,
      "z": 11,
      "name": "Wood_Softwood_Planks"
    },
    {
      "x": -15,
      "y": 1,
      "z": 11,
      "name": "Wood_Hardwood_Planks_Half",
      "rotation": 5
    },
    {
      "x": -15,
      "y": 6,
      "z": 11,
      "name": "Wood_Hardwood_Planks_Half",
      "rotation": 5
    },
    {
      "x": -15,
      "y": 9,
      "z": 11,
      "name": "Wood_Softwood_Planks"
    },
    {
      "x": -15,
      "y": 10,
      "z": 11,
      "name": "Wood_Softwood_Roof_Shallow",
      "rotation": 3
    },
    {
      "x": -15,
      "y": 0,
      "z": 12,
      "name": "Rock_Basalt_Cobble"
    },
    {
      "x": -15,
      "y": 1,
      "z": 12,
      "name": "Wood_Softwood_Decorative"
    },
    {
      "x": -15,
      "y": 2,
      "z": 12,
      "name": "Wood_Softwood_Decorative"
    },
    {
      "x": -15,
      "y": 3,
      "z": 12,
      "name": "Wood_Softwood_Decorative"
    },
    {
      "x": -15,
      "y": 4,
      "z": 12,
      "name": "Wood_Softwood_Decorative"
    },
    {
      "x": -15,
      "y": 5,
      "z": 12,
      "name": "Wood_Softwood_Decorative"
    },
    {
      "x": -15,
      "y": 6,
      "z": 12,
      "name": "Wood_Oak_Trunk",
      "support": 15,
      "rotation": 5
    },
    {
      "x": -15,
      "y": 7,
      "z": 12,
      "name": "Wood_Softwood_Decorative"
    },
    {
      "x": -15,
      "y": 8,
      "z": 12,
      "name": "Wood_Softwood_Decorative"
    },
    {
      "x": -15,
      "y": 9,
      "z": 12,
      "name": "Wood_Softwood_Decorative"
    },
    {
      "x": -15,
      "y": 10,
      "z": 12,
      "name": "Wood_Softwood_Roof_Shallow",
      "rotation": 3
    },
    {
      "x": -15,
      "y": 0,
      "z": 13,
      "name": "Rock_Basalt_Cobble"
    },
    {
      "x": -15,
      "y": 1,
      "z": 13,
      "name": "Wood_Hardwood_Planks_Half",
      "rotation": 5
    },
    {
      "x": -15,
      "y": 10,
      "z": 13,
      "name": "Wood_Softwood_Roof_Shallow",
      "rotation": 3
    },
    {
      "x": -15,
      "y": 0,
      "z": 14,
      "name": "Rock_Basalt_Cobble"
    },
    {
      "x": -14,
      "y": 0,
      "z": -13,
      "name": "Rock_Basalt_Cobble"
    },
    {
      "x": -14,
      "y": 10,
      "z": -13,
      "name": "Wood_Softwood_Roof_Shallow",
      "filler": 1,
      "rotation": 3
    },
    {
      "x": -14,
      "y": 0,
      "z": -12,
      "name": "Rock_Basalt_Cobble"
    },
    {
      "x": -14,
      "y": 1,
      "z": -12,
      "name": "Wood_Softwood_Planks"
    },
    {
      "x": -14,
      "y": 2,
      "z": -12,
      "name": "Wood_Softwood_Planks"
    },
    {
      "x": -14,
      "y": 3,
      "z": -12,
      "name": "Wood_Softwood_Planks_Half",
      "rotation": 6
    },
    {
      "x": -14,
      "y": 4,
      "z": -12,
      "name": "Wood_Softwood_Planks_Half",
      "rotation": 6
    },
    {
      "x": -14,
      "y": 5,
      "z": -12,
      "name": "Wood_Softwood_Planks_Half",
      "rotation": 6
    },
    {
      "x": -14,
      "y": 6,
      "z": -12,
      "name": "Wood_Oak_Trunk",
      "support": 15,
      "rotation": 5
    },
    {
      "x": -14,
      "y": 7,
      "z": -12,
      "name": "Wood_Softwood_Stairs",
      "rotation": 8
    },
    {
      "x": -14,
      "y": 8,
      "z": -12,
      "name": "Wood_Softwood_Planks"
    },
    {
      "x": -14,
      "y": 9,
      "z": -12,
      "name": "Wood_Softwood_Planks"
    },
    {
      "x": -14,
      "y": 10,
      "z": -12,
      "name": "Wood_Softwood_Roof_Shallow",
      "filler": 1,
      "rotation": 3
    },
    {
      "x": -14,
      "y": 0,
      "z": -11,
      "name": "Wood_Softwood_Planks"
    },
    {
      "x": -14,
      "y": 1,
      "z": -11,
      "name": "Furniture_Village_Ladder"
    },
    {
      "x": -14,
      "y": 2,
      "z": -11,
      "name": "Furniture_Village_Ladder"
    },
    {
      "x": -14,
      "y": 3,
      "z": -11,
      "name": "Furniture_Village_Ladder"
    },
    {
      "x": -14,
      "y": 4,
      "z": -11,
      "name": "Furniture_Village_Ladder"
    },
    {
      "x": -14,
      "y": 5,
      "z": -11,
      "name": "Furniture_Village_Ladder"
    },
    {
      "x": -14,
      "y": 9,
      "z": -11,
      "name": "Wood_Softwood_Planks_Half",
      "rotation": 8
    },
    {
      "x": -14,
      "y": 10,
      "z": -11,
      "name": "Wood_Softwood_Roof_Shallow",
      "filler": 1,
      "rotation": 3
    },
    {
      "x": -14,
      "y": 0,
      "z": -10,
      "name": "Wood_Softwood_Planks"
    },
    {
      "x": -14,
      "y": 1,
      "z": -10,
      "name": "Furniture_Tavern_Barrel"
    },
    {
      "x": -14,
      "y": 9,
      "z": -10,
      "name": "Wood_Softwood_Planks_Half",
      "rotation": 8
    },
    {
      "x": -14,
      "y": 10,
      "z": -10,
      "name": "Wood_Softwood_Roof_Shallow",
      "filler": 1,
      "rotation": 3
    },
    {
      "x": -14,
      "y": 0,
      "z": -9,
      "name": "Wood_Softwood_Planks"
    },
    {
      "x": -14,
      "y": 1,
      "z": -9,
      "name": "Furniture_Village_Crate"
    },
    {
      "x": -14,
      "y": 9,
      "z": -9,
      "name": "Wood_Softwood_Planks_Half",
      "rotation": 8
    },
    {
      "x": -14,
      "y": 10,
      "z": -9,
      "name": "Wood_Softwood_Roof_Shallow",
      "filler": 1,
      "rotation": 3
    },
    {
      "x": -14,
      "y": 0,
      "z": -8,
      "name": "Wood_Softwood_Planks"
    },
    {
      "x": -14,
      "y": 9,
      "z": -8,
      "name": "Wood_Softwood_Planks_Half",
      "rotation": 8
    },
    {
      "x": -14,
      "y": 10,
      "z": -8,
      "name": "Wood_Softwood_Roof_Shallow",
      "filler": 1,
      "rotation": 3
    },
    {
      "x": -14,
      "y": 0,
      "z": -7,
      "name": "Wood_Softwood_Planks"
    },
    {
      "x": -14,
      "y": 9,
      "z": -7,
      "name": "Wood_Softwood_Planks_Half",
      "rotation": 8
    },
    {
      "x": -14,
      "y": 10,
      "z": -7,
      "name": "Wood_Softwood_Roof_Shallow",
      "filler": 1,
      "rotation": 3
    },
    {
      "x": -14,
      "y": 0,
      "z": -6,
      "name": "Wood_Softwood_Planks"
    },
    {
      "x": -14,
      "y": 1,
      "z": -6,
      "name": "Furniture_Crude_Stool",
      "rotation": 1
    },
    {
      "x": -14,
      "y": 9,
      "z": -6,
      "name": "Wood_Softwood_Planks_Half",
      "rotation": 8
    },
    {
      "x": -14,
      "y": 10,
      "z": -6,
      "name": "Wood_Softwood_Roof_Shallow",
      "filler": 1,
      "rotation": 3
    },
    {
      "x": -14,
      "y": 0,
      "z": -5,
      "name": "Wood_Softwood_Planks"
    },
    {
      "x": -14,
      "y": 9,
      "z": -5,
      "name": "Wood_Softwood_Planks_Half",
      "rotation": 8
    },
    {
      "x": -14,
      "y": 10,
      "z": -5,
      "name": "Wood_Softwood_Roof_Shallow",
      "filler": 1,
      "rotation": 3
    },
    {
      "x": -14,
      "y": 0,
      "z": -4,
      "name": "Wood_Softwood_Planks"
    },
    {
      "x": -14,
      "y": 9,
      "z": -4,
      "name": "Wood_Softwood_Planks_Half",
      "rotation": 8
    },
    {
      "x": -14,
      "y": 10,
      "z": -4,
      "name": "Wood_Softwood_Roof_Shallow",
      "filler": 1,
      "rotation": 3
    },
    {
      "x": -14,
      "y": 0,
      "z": -3,
      "name": "Wood_Softwood_Planks"
    },
    {
      "x": -14,
      "y": 9,
      "z": -3,
      "name": "Wood_Softwood_Planks_Half",
      "rotation": 8
    },
    {
      "x": -14,
      "y": 10,
      "z": -3,
      "name": "Wood_Softwood_Roof_Shallow",
      "filler": 1,
      "rotation": 3
    },
    {
      "x": -14,
      "y": 0,
      "z": -2,
      "name": "Wood_Softwood_Planks"
    },
    {
      "x": -14,
      "y": 9,
      "z": -2,
      "name": "Wood_Softwood_Planks_Half",
      "rotation": 8
    },
    {
      "x": -14,
      "y": 10,
      "z": -2,
      "name": "Wood_Softwood_Roof_Shallow",
      "filler": 1,
      "rotation": 3
    },
    {
      "x": -14,
      "y": 0,
      "z": -1,
      "name": "Wood_Softwood_Planks"
    },
    {
      "x": -14,
      "y": 9,
      "z": -1,
      "name": "Wood_Softwood_Planks_Half",
      "rotation": 8
    },
    {
      "x": -14,
      "y": 10,
      "z": -1,
      "name": "Wood_Softwood_Roof_Shallow",
      "filler": 1,
      "rotation": 3
    },
    {
      "x": -14,
      "y": 0,
      "z": 0,
      "name": "Wood_Softwood_Planks"
    },
    {
      "x": -14,
      "y": 9,
      "z": 0,
      "name": "Wood_Softwood_Planks_Half",
      "rotation": 8
    },
    {
      "x": -14,
      "y": 10,
      "z": 0,
      "name": "Wood_Softwood_Roof_Shallow",
      "filler": 1,
      "rotation": 3
    },
    {
      "x": -14,
      "y": 0,
      "z": 1,
      "name": "Wood_Softwood_Planks"
    },
    {
      "x": -14,
      "y": 9,
      "z": 1,
      "name": "Wood_Softwood_Planks_Half",
      "rotation": 8
    },
    {
      "x": -14,
      "y": 10,
      "z": 1,
      "name": "Wood_Softwood_Roof_Shallow",
      "filler": 1,
      "rotation": 3
    },
    {
      "x": -14,
      "y": 0,
      "z": 2,
      "name": "Wood_Softwood_Planks"
    },
    {
      "x": -14,
      "y": 9,
      "z": 2,
      "name": "Wood_Softwood_Planks_Half",
      "rotation": 8
    },
    {
      "x": -14,
      "y": 10,
      "z": 2,
      "name": "Wood_Softwood_Roof_Shallow",
      "filler": 1,
      "rotation": 3
    },
    {
      "x": -14,
      "y": 0,
      "z": 3,
      "name": "Wood_Softwood_Planks"
    },
    {
      "x": -14,
      "y": 9,
      "z": 3,
      "name": "Wood_Softwood_Planks_Half",
      "rotation": 8
    },
    {
      "x": -14,
      "y": 10,
      "z": 3,
      "name": "Wood_Softwood_Roof_Shallow",
      "filler": 1,
      "rotation": 3
    },
    {
      "x": -14,
      "y": 0,
      "z": 4,
      "name": "Wood_Softwood_Planks"
    },
    {
      "x": -14,
      "y": 9,
      "z": 4,
      "name": "Wood_Softwood_Planks_Half",
      "rotation": 8
    },
    {
      "x": -14,
      "y": 10,
      "z": 4,
      "name": "Wood_Softwood_Roof_Shallow",
      "filler": 1,
      "rotation": 3
    },
    {
      "x": -14,
      "y": 0,
      "z": 5,
      "name": "Wood_Softwood_Planks"
    },
    {
      "x": -14,
      "y": 9,
      "z": 5,
      "name": "Wood_Softwood_Planks_Half",
      "rotation": 8
    },
    {
      "x": -14,
      "y": 10,
      "z": 5,
      "name": "Wood_Softwood_Roof_Shallow",
      "filler": 1,
      "rotation": 3
    },
    {
      "x": -14,
      "y": 0,
      "z": 6,
      "name": "Wood_Softwood_Planks"
    },
    {
      "x": -14,
      "y": 9,
      "z": 6,
      "name": "Wood_Softwood_Planks_Half",
      "rotation": 8
    },
    {
      "x": -14,
      "y": 10,
      "z": 6,
      "name": "Wood_Softwood_Roof_Shallow",
      "filler": 1,
      "rotation": 3
    },
    {
      "x": -14,
      "y": 0,
      "z": 7,
      "name": "Wood_Softwood_Planks"
    },
    {
      "x": -14,
      "y": 9,
      "z": 7,
      "name": "Wood_Softwood_Planks_Half",
      "rotation": 8
    },
    {
      "x": -14,
      "y": 10,
      "z": 7,
      "name": "Wood_Softwood_Roof_Shallow",
      "filler": 1,
      "rotation": 3
    },
    {
      "x": -14,
      "y": 0,
      "z": 8,
      "name": "Wood_Softwood_Planks"
    },
    {
      "x": -14,
      "y": 9,
      "z": 8,
      "name": "Wood_Softwood_Planks_Half",
      "rotation": 8
    },
    {
      "x": -14,
      "y": 10,
      "z": 8,
      "name": "Wood_Softwood_Roof_Shallow",
      "filler": 1,
      "rotation": 3
    },
    {
      "x": -14,
      "y": 0,
      "z": 9,
      "name": "Wood_Softwood_Planks"
    },
    {
      "x": -14,
      "y": 9,
      "z": 9,
      "name": "Wood_Softwood_Planks_Half",
      "rotation": 8
    },
    {
      "x": -14,
      "y": 10,
      "z": 9,
      "name": "Wood_Softwood_Roof_Shallow",
      "filler": 1,
      "rotation": 3
    },
    {
      "x": -14,
      "y": 0,
      "z": 10,
      "name": "Wood_Softwood_Planks"
    },
    {
      "x": -14,
      "y": 9,
      "z": 10,
      "name": "Wood_Softwood_Planks_Half",
      "rotation": 8
    },
    {
      "x": -14,
      "y": 10,
      "z": 10,
      "name": "Wood_Softwood_Roof_Shallow",
      "filler": 1,
      "rotation": 3
    },
    {
      "x": -14,
      "y": 0,
      "z": 11,
      "name": "Wood_Softwood_Planks"
    },
    {
      "x": -14,
      "y": 1,
      "z": 11,
      "name": "Wood_Softwood_Ornate"
    },
    {
      "x": -14,
      "y": 9,
      "z": 11,
      "name": "Wood_Softwood_Planks_Half",
      "rotation": 8
    },
    {
      "x": -14,
      "y": 10,
      "z": 11,
      "name": "Wood_Softwood_Roof_Shallow",
      "filler": 1,
      "rotation": 3
    },
    {
      "x": -14,
      "y": 0,
      "z": 12,
      "name": "Rock_Basalt_Cobble"
    },
    {
      "x": -14,
      "y": 1,
      "z": 12,
      "name": "Wood_Softwood_Planks"
    },
    {
      "x": -14,
      "y": 2,
      "z": 12,
      "name": "Wood_Softwood_Planks"
    },
    {
      "x": -14,
      "y": 3,
      "z": 12,
      "name": "Wood_Softwood_Planks_Half",
      "rotation": 4
    },
    {
      "x": -14,
      "y": 4,
      "z": 12,
      "name": "Wood_Softwood_Planks_Half",
      "rotation": 4
    },
    {
      "x": -14,
      "y": 5,
      "z": 12,
      "name": "Wood_Softwood_Planks_Half",
      "rotation": 4
    },
    {
      "x": -14,
      "y": 6,
      "z": 12,
      "name": "Wood_Oak_Trunk",
      "support": 15,
      "rotation": 5
    },
    {
      "x": -14,
      "y": 7,
      "z": 12,
      "name": "Wood_Softwood_Stairs",
      "rotation": 10
    },
    {
      "x": -14,
      "y": 8,
      "z": 12,
      "name": "Wood_Softwood_Planks"
    },
    {
      "x": -14,
      "y": 9,
      "z": 12,
      "name": "Wood_Softwood_Planks"
    },
    {
      "x": -14,
      "y": 10,
      "z": 12,
      "name": "Wood_Softwood_Roof_Shallow",
      "filler": 1,
      "rotation": 3
    },
    {
      "x": -14,
      "y": 0,
      "z": 13,
      "name": "Rock_Basalt_Cobble"
    },
    {
      "x": -14,
      "y": 10,
      "z": 13,
      "name": "Wood_Softwood_Roof_Shallow",
      "filler": 1,
      "rotation": 3
    },
    {
      "x": -13,
      "y": 0,
      "z": -13,
      "name": "Rock_Basalt_Cobble"
    },
    {
      "x": -13,
      "y": 6,
      "z": -13,
      "name": "Wood_Oak_Trunk",
      "support": 15,
      "rotation": 4
    },
    {
      "x": -13,
      "y": 11,
      "z": -13,
      "name": "Wood_Softwood_Roof_Shallow",
      "rotation": 3
    },
    {
      "x": -13,
      "y": 0,
      "z": -12,
      "name": "Rock_Basalt_Cobble"
    },
    {
      "x": -13,
      "y": 1,
      "z": -12,
      "name": "Wood_Softwood_Planks"
    },
    {
      "x": -13,
      "y": 2,
      "z": -12,
      "name": "Wood_Softwood_Planks"
    },
    {
      "x": -13,
      "y": 3,
      "z": -12,
      "name": "Wood_Softwood_Planks"
    },
    {
      "x": -13,
      "y": 4,
      "z": -12,
      "name": "Wood_Softwood_Planks"
    },
    {
      "x": -13,
      "y": 5,
      "z": -12,
      "name": "Wood_Softwood_Stairs",
      "rotation": 2
    },
    {
      "x": -13,
      "y": 6,
      "z": -12,
      "name": "Wood_Oak_Trunk",
      "support": 15,
      "rotation": 5
    },
    {
      "x": -13,
      "y": 7,
      "z": -12,
      "name": "Wood_Softwood_Stairs",
      "rotation": 8
    },
    {
      "x": -13,
      "y": 8,
      "z": -12,
      "name": "Wood_Softwood_Planks"
    },
    {
      "x": -13,
      "y": 9,
      "z": -12,
      "name": "Wood_Softwood_Planks"
    },
    {
      "x": -13,
      "y": 10,
      "z": -12,
      "name": "Wood_Softwood_Planks"
    },
    {
      "x": -13,
      "y": 11,
      "z": -12,
      "name": "Wood_Softwood_Roof_Shallow",
      "rotation": 3
    },
    {
      "x": -13,
      "y": 0,
      "z": -11,
      "name": "Wood_Softwood_Planks"
    },
    {
      "x": -13,
      "y": 1,
      "z": -11,
      "name": "Furniture_Village_Counter",
      "filler": 31
    },
    {
      "x": -13,
      "y": 2,
      "z": -11,
      "name": "Furniture_Village_Counter",
      "filler": 31
    },
    {
      "x": -13,
      "y": 3,
      "z": -11,
      "name": "Furniture_Village_Counter",
      "filler": 31
    },
    {
      "x": -13,
      "y": 6,
      "z": -11,
      "name": "Wood_Oak_Trunk",
      "support": 15,
      "rotation": 4
    },
    {
      "x": -13,
      "y": 10,
      "z": -11,
      "name": "Wood_Softwood_Planks"
    },
    {
      "x": -13,
      "y": 11,
      "z": -11,
      "name": "Wood_Softwood_Roof_Shallow",
      "rotation": 3
    },
    {
      "x": -13,
      "y": 0,
      "z": -10,
      "name": "Wood_Softwood_Planks"
    },
    {
      "x": -13,
      "y": 6,
      "z": -10,
      "name": "Wood_Oak_Trunk",
      "support": 15,
      "rotation": 4
    },
    {
      "x": -13,
      "y": 10,
      "z": -10,
      "name": "Wood_Softwood_Planks"
    },
    {
      "x": -13,
      "y": 11,
      "z": -10,
      "name": "Wood_Softwood_Roof_Shallow",
      "rotation": 3
    },
    {
      "x": -13,
      "y": 0,
      "z": -9,
      "name": "Wood_Softwood_Planks"
    },
    {
      "x": -13,
      "y": 6,
      "z": -9,
      "name": "Wood_Oak_Trunk",
      "support": 15,
      "rotation": 4
    },
    {
      "x": -13,
      "y": 7,
      "z": -9,
      "name": "Furniture_Tavern_Barrel"
    },
    {
      "x": -13,
      "y": 10,
      "z": -9,
      "name": "Wood_Softwood_Planks"
    },
    {
      "x": -13,
      "y": 11,
      "z": -9,
      "name": "Wood_Softwood_Roof_Shallow",
      "rotation": 3
    },
    {
      "x": -13,
      "y": 0,
      "z": -8,
      "name": "Wood_Softwood_Planks"
    },
    {
      "x": -13,
      "y": 6,
      "z": -8,
      "name": "Wood_Oak_Trunk",
      "support": 15,
      "rotation": 4
    },
    {
      "x": -13,
      "y": 7,
      "z": -8,
      "name": "Furniture_Tavern_Barrel"
    },
    {
      "x": -13,
      "y": 10,
      "z": -8,
      "name": "Wood_Softwood_Planks"
    },
    {
      "x": -13,
      "y": 11,
      "z": -8,
      "name": "Wood_Softwood_Roof_Shallow",
      "rotation": 3
    },
    {
      "x": -13,
      "y": 0,
      "z": -7,
      "name": "Wood_Softwood_Planks"
    },
    {
      "x": -13,
      "y": 6,
      "z": -7,
      "name": "Wood_Oak_Trunk",
      "support": 15,
      "rotation": 4
    },
    {
      "x": -13,
      "y": 10,
      "z": -7,
      "name": "Wood_Softwood_Planks"
    },
    {
      "x": -13,
      "y": 11,
      "z": -7,
      "name": "Wood_Softwood_Roof_Shallow",
      "rotation": 3
    },
    {
      "x": -13,
      "y": 0,
      "z": -6,
      "name": "Wood_Softwood_Planks"
    },
    {
      "x": -13,
      "y": 6,
      "z": -6,
      "name": "Wood_Oak_Trunk",
      "support": 15,
      "rotation": 4
    },
    {
      "x": -13,
      "y": 10,
      "z": -6,
      "name": "Wood_Softwood_Planks"
    },
    {
      "x": -13,
      "y": 11,
      "z": -6,
      "name": "Wood_Softwood_Roof_Shallow",
      "rotation": 3
    },
    {
      "x": -13,
      "y": 0,
      "z": -5,
      "name": "Wood_Softwood_Planks"
    },
    {
      "x": -13,
      "y": 6,
      "z": -5,
      "name": "Wood_Oak_Trunk",
      "support": 15,
      "rotation": 4
    },
    {
      "x": -13,
      "y": 10,
      "z": -5,
      "name": "Wood_Softwood_Planks"
    },
    {
      "x": -13,
      "y": 11,
      "z": -5,
      "name": "Wood_Softwood_Roof_Shallow",
      "rotation": 3
    },
    {
      "x": -13,
      "y": 0,
      "z": -4,
      "name": "Wood_Softwood_Planks"
    },
    {
      "x": -13,
      "y": 6,
      "z": -4,
      "name": "Wood_Oak_Trunk",
      "support": 15,
      "rotation": 4
    },
    {
      "x": -13,
      "y": 10,
      "z": -4,
      "name": "Wood_Softwood_Planks"
    },
    {
      "x": -13,
      "y": 11,
      "z": -4,
      "name": "Wood_Softwood_Roof_Shallow",
      "rotation": 3
    },
    {
      "x": -13,
      "y": 0,
      "z": -3,
      "name": "Wood_Softwood_Planks"
    },
    {
      "x": -13,
      "y": 6,
      "z": -3,
      "name": "Wood_Oak_Trunk",
      "support": 15,
      "rotation": 4
    },
    {
      "x": -13,
      "y": 10,
      "z": -3,
      "name": "Wood_Softwood_Planks"
    },
    {
      "x": -13,
      "y": 11,
      "z": -3,
      "name": "Wood_Softwood_Roof_Shallow",
      "rotation": 3
    },
    {
      "x": -13,
      "y": 0,
      "z": -2,
      "name": "Wood_Softwood_Planks"
    },
    {
      "x": -13,
      "y": 6,
      "z": -2,
      "name": "Wood_Oak_Trunk",
      "support": 15,
      "rotation": 4
    },
    {
      "x": -13,
      "y": 10,
      "z": -2,
      "name": "Wood_Softwood_Planks"
    },
    {
      "x": -13,
      "y": 11,
      "z": -2,
      "name": "Wood_Softwood_Roof_Shallow",
      "rotation": 3
    },
    {
      "x": -13,
      "y": 0,
      "z": -1,
      "name": "Wood_Softwood_Planks"
    },
    {
      "x": -13,
      "y": 6,
      "z": -1,
      "name": "Wood_Oak_Trunk",
      "support": 15,
      "rotation": 4
    },
    {
      "x": -13,
      "y": 10,
      "z": -1,
      "name": "Wood_Softwood_Planks"
    },
    {
      "x": -13,
      "y": 11,
      "z": -1,
      "name": "Wood_Softwood_Roof_Shallow",
      "rotation": 3
    },
    {
      "x": -13,
      "y": 0,
      "z": 0,
      "name": "Wood_Softwood_Planks"
    },
    {
      "x": -13,
      "y": 1,
      "z": 0,
      "name": "Wood_Oak_Trunk",
      "support": 15,
      "rotation": 5
    },
    {
      "x": -13,
      "y": 6,
      "z": 0,
      "name": "Wood_Oak_Trunk",
      "support": 15,
      "rotation": 4
    },
    {
      "x": -13,
      "y": 10,
      "z": 0,
      "name": "Wood_Softwood_Planks"
    },
    {
      "x": -13,
      "y": 11,
      "z": 0,
      "name": "Wood_Softwood_Roof_Shallow",
      "rotation": 3
    },
    {
      "x": -13,
      "y": 0,
      "z": 1,
      "name": "Wood_Softwood_Planks"
    },
    {
      "x": -13,
      "y": 6,
      "z": 1,
      "name": "Wood_Oak_Trunk",
      "support": 15,
      "rotation": 4
    },
    {
      "x": -13,
      "y": 10,
      "z": 1,
      "name": "Wood_Softwood_Planks"
    },
    {
      "x": -13,
      "y": 11,
      "z": 1,
      "name": "Wood_Softwood_Roof_Shallow",
      "rotation": 3
    },
    {
      "x": -13,
      "y": 0,
      "z": 2,
      "name": "Wood_Softwood_Planks"
    },
    {
      "x": -13,
      "y": 6,
      "z": 2,
      "name": "Wood_Oak_Trunk",
      "support": 15,
      "rotation": 4
    },
    {
      "x": -13,
      "y": 10,
      "z": 2,
      "name": "Wood_Softwood_Planks"
    },
    {
      "x": -13,
      "y": 11,
      "z": 2,
      "name": "Wood_Softwood_Roof_Shallow",
      "rotation": 3
    },
    {
      "x": -13,
      "y": 0,
      "z": 3,
      "name": "Wood_Softwood_Planks"
    },
    {
      "x": -13,
      "y": 6,
      "z": 3,
      "name": "Wood_Oak_Trunk",
      "support": 15,
      "rotation": 4
    },
    {
      "x": -13,
      "y": 10,
      "z": 3,
      "name": "Wood_Softwood_Planks"
    },
    {
      "x": -13,
      "y": 11,
      "z": 3,
      "name": "Wood_Softwood_Roof_Shallow",
      "rotation": 3
    },
    {
      "x": -13,
      "y": 0,
      "z": 4,
      "name": "Wood_Softwood_Planks"
    },
    {
      "x": -13,
      "y": 6,
      "z": 4,
      "name": "Wood_Oak_Trunk",
      "support": 15,
      "rotation": 4
    },
    {
      "x": -13,
      "y": 10,
      "z": 4,
      "name": "Wood_Softwood_Planks"
    },
    {
      "x": -13,
      "y": 11,
      "z": 4,
      "name": "Wood_Softwood_Roof_Shallow",
      "rotation": 3
    },
    {
      "x": -13,
      "y": 0,
      "z": 5,
      "name": "Wood_Softwood_Planks"
    },
    {
      "x": -13,
      "y": 6,
      "z": 5,
      "name": "Wood_Oak_Trunk",
      "support": 15,
      "rotation": 4
    },
    {
      "x": -13,
      "y": 10,
      "z": 5,
      "name": "Wood_Softwood_Planks"
    },
    {
      "x": -13,
      "y": 11,
      "z": 5,
      "name": "Wood_Softwood_Roof_Shallow",
      "rotation": 3
    },
    {
      "x": -13,
      "y": 0,
      "z": 6,
      "name": "Wood_Softwood_Planks"
    },
    {
      "x": -13,
      "y": 6,
      "z": 6,
      "name": "Wood_Oak_Trunk",
      "support": 15,
      "rotation": 4
    },
    {
      "x": -13,
      "y": 10,
      "z": 6,
      "name": "Wood_Softwood_Planks"
    },
    {
      "x": -13,
      "y": 11,
      "z": 6,
      "name": "Wood_Softwood_Roof_Shallow",
      "rotation": 3
    },
    {
      "x": -13,
      "y": 0,
      "z": 7,
      "name": "Wood_Softwood_Planks"
    },
    {
      "x": -13,
      "y": 6,
      "z": 7,
      "name": "Wood_Oak_Trunk",
      "support": 15,
      "rotation": 4
    },
    {
      "x": -13,
      "y": 10,
      "z": 7,
      "name": "Wood_Softwood_Planks"
    },
    {
      "x": -13,
      "y": 11,
      "z": 7,
      "name": "Wood_Softwood_Roof_Shallow",
      "rotation": 3
    },
    {
      "x": -13,
      "y": 0,
      "z": 8,
      "name": "Wood_Softwood_Planks"
    },
    {
      "x": -13,
      "y": 6,
      "z": 8,
      "name": "Wood_Oak_Trunk",
      "support": 15,
      "rotation": 4
    },
    {
      "x": -13,
      "y": 7,
      "z": 8,
      "name": "Furniture_Village_Crate"
    },
    {
      "x": -13,
      "y": 10,
      "z": 8,
      "name": "Wood_Softwood_Planks"
    },
    {
      "x": -13,
      "y": 11,
      "z": 8,
      "name": "Wood_Softwood_Roof_Shallow",
      "rotation": 3
    },
    {
      "x": -13,
      "y": 0,
      "z": 9,
      "name": "Wood_Softwood_Planks"
    },
    {
      "x": -13,
      "y": 6,
      "z": 9,
      "name": "Wood_Oak_Trunk",
      "support": 15,
      "rotation": 4
    },
    {
      "x": -13,
      "y": 10,
      "z": 9,
      "name": "Wood_Softwood_Planks"
    },
    {
      "x": -13,
      "y": 11,
      "z": 9,
      "name": "Wood_Softwood_Roof_Shallow",
      "rotation": 3
    },
    {
      "x": -13,
      "y": 0,
      "z": 10,
      "name": "Wood_Softwood_Planks"
    },
    {
      "x": -13,
      "y": 6,
      "z": 10,
      "name": "Wood_Oak_Trunk",
      "support": 15,
      "rotation": 4
    },
    {
      "x": -13,
      "y": 10,
      "z": 10,
      "name": "Wood_Softwood_Planks"
    },
    {
      "x": -13,
      "y": 11,
      "z": 10,
      "name": "Wood_Softwood_Roof_Shallow",
      "rotation": 3
    },
    {
      "x": -13,
      "y": 0,
      "z": 11,
      "name": "Wood_Softwood_Planks"
    },
    {
      "x": -13,
      "y": 1,
      "z": 11,
      "name": "Wood_Softwood_Ornate"
    },
    {
      "x": -13,
      "y": 2,
      "z": 11,
      "name": "Deco_Map"
    },
    {
      "x": -13,
      "y": 6,
      "z": 11,
      "name": "Wood_Oak_Trunk",
      "support": 15,
      "rotation": 4
    },
    {
      "x": -13,
      "y": 10,
      "z": 11,
      "name": "Wood_Softwood_Planks"
    },
    {
      "x": -13,
      "y": 11,
      "z": 11,
      "name": "Wood_Softwood_Roof_Shallow",
      "rotation": 3
    },
    {
      "x": -13,
      "y": 0,
      "z": 12,
      "name": "Rock_Basalt_Cobble"
    },
    {
      "x": -13,
      "y": 1,
      "z": 12,
      "name": "Wood_Softwood_Planks"
    },
    {
      "x": -13,
      "y": 2,
      "z": 12,
      "name": "Wood_Softwood_Planks"
    },
    {
      "x": -13,
      "y": 3,
      "z": 12,
      "name": "Wood_Softwood_Planks"
    },
    {
      "x": -13,
      "y": 4,
      "z": 12,
      "name": "Wood_Softwood_Planks"
    },
    {
      "x": -13,
      "y": 5,
      "z": 12,
      "name": "Wood_Softwood_Stairs"
    },
    {
      "x": -13,
      "y": 6,
      "z": 12,
      "name": "Wood_Oak_Trunk",
      "support": 15,
      "rotation": 5
    },
    {
      "x": -13,
      "y": 7,
      "z": 12,
      "name": "Wood_Softwood_Stairs",
      "rotation": 10
    },
    {
      "x": -13,
      "y": 8,
      "z": 12,
      "name": "Wood_Softwood_Planks"
    },
    {
      "x": -13,
      "y": 9,
      "z": 12,
      "name": "Wood_Softwood_Planks"
    },
    {
      "x": -13,
      "y": 10,
      "z": 12,
      "name": "Wood_Softwood_Planks"
    },
    {
      "x": -13,
      "y": 11,
      "z": 12,
      "name": "Wood_Softwood_Roof_Shallow",
      "rotation": 3
    },
    {
      "x": -13,
      "y": 0,
      "z": 13,
      "name": "Rock_Basalt_Cobble"
    },
    {
      "x": -13,
      "y": 6,
      "z": 13,
      "name": "Wood_Oak_Trunk",
      "support": 15,
      "rotation": 4
    },
    {
      "x": -13,
      "y": 11,
      "z": 13,
      "name": "Wood_Softwood_Roof_Shallow",
