{
  "anchorX": 0,
  "anchorY": 1,
  "anchorZ": 0,
  "blockIdVersion": 11,
  "blocks": [
    {
      "name": "Soil_Dirt",
      "x": -3,
      "y": 0,
      "z": -2
    },
    {
      "name": "Wood_Softwood_Planks_Half",
      "rotation": 6,
      "x": -3,
      "y": 1,
      "z": -2
    },
    {
      "name": "Wood_Softwood_Planks_Half",
      "rotation": 6,
      "x": -3,
      "y": 2,
      "z": -2
    },
    {
      "name": "Wood_Softwood_Roof_Shallow",
      "rotation": 2,
      "x": -3,
      "y": 3,
      "z": -2
    },
    {
      "name": "Wood_Softwood_Planks",
      "x": -3,
      "y": 0,
      "z": -1
    },
    {
      "name": "Wood_Softwood_Planks_Half",
      "rotation": 5,
      "x": -3,
      "y": 1,
      "z": -1
    },
    {
      "name": "Wood_Softwood_Planks_Half",
      "rotation": 5,
      "x": -3,
      "y": 2,
      "z": -1
    },
    {
      "name": "Empty",
      "rotation": 2,
      "x": -3,
      "y": 3,
      "z": -1
    },
    {
      "name": "Wood_Softwood_Planks",
      "x": -3,
      "y": 0,
      "z": 0
    },
    {
      "name": "Wood_Softwood_Planks_Half",
      "rotation": 5,
      "x": -3,
      "y": 1,
      "z": 0
    },
    {
      "name": "Wood_Softwood_Planks_Half",
      "rotation": 5,
      "x": -3,
      "y": 2,
      "z": 0
    },
    {
      "name": "Wood_Softwood_Planks_Half",
      "rotation": 5,
      "x": -3,
      "y": 3,
      "z": 0
    },
    {
      "name": "Wood_Softwood_Roof_Flat",
      "x": -3,
      "y": 4,
      "z": 0
    },
    {
      "name": "Wood_Softwood_Planks",
      "x": -3,
      "y": 0,
      "z": 1
    },
    {
      "name": "Wood_Softwood_Planks_Half",
      "rotation": 5,
      "x": -3,
      "y": 1,
      "z": 1
    },
    {
      "name": "Wood_Softwood_Planks_Half",
      "rotation": 5,
      "x": -3,
      "y": 2,
      "z": 1
    },
    {
      "name": "Empty",
      "x": -3,
      "y": 3,
      "z": 1
    },
    {
      "name": "Soil_Dirt",
      "x": -3,
      "y": 0,
      "z": 2
    },
    {
      "name": "Wood_Softwood_Planks_Half",
      "rotation": 4,
      "x": -3,
      "y": 1,
      "z": 2
    },
    {
      "name": "Wood_Softwood_Planks_Half",
      "rotation": 4,
      "x": -3,
      "y": 2,
      "z": 2
    },
    {
      "name": "Wood_Softwood_Roof_Shallow",
      "x": -3,
      "y": 3,
      "z": 2
    },
    {
      "name": "Soil_Dirt",
      "x": -2,
      "y": 0,
      "z": -2
    },
    {
      "name": "Wood_Softwood_Planks_Half",
      "rotation": 6,
      "x": -2,
      "y": 1,
      "z": -2
    },
    {
      "name": "Wood_Softwood_Planks_Half",
      "rotation": 6,
      "x": -2,
      "y": 2,
      "z": -2
    },
    {
      "name": "Wood_Softwood_Roof_Shallow",
      "rotation": 2,
      "x": -2,
      "y": 3,
      "z": -2
    },
    {
      "name": "Wood_Softwood_Planks",
      "x": -2,
      "y": 0,
      "z": -1
    },
    {
      "name": "Furniture_Village_Crate",
      "x": -2,
      "y": 1,
      "z": -1
    },
    {
      "name": "Furniture_Village_Crate",
      "x": -2,
      "y": 2,
      "z": -1
    },
    {
      "name": "Empty",
      "rotation": 2,
      "x": -2,
      "y": 3,
      "z": -1
    },
    {
      "name": "Wood_Softwood_Planks",
      "x": -2,
      "y": 0,
      "z": 0
    },
    {
      "name": "Furniture_Village_Crate",
      "x": -2,
      "y": 1,
      "z": 0
    },
    {
      "name": "Empty",
      "x": -2,
      "y": 2,
      "z": 0
    },
    {
      "name": "Empty",
      "x": -2,
      "y": 3,
      "z": 0
    },
    {
      "name": "Wood_Softwood_Roof_Flat",
      "x": -2,
      "y": 4,
      "z": 0
    },
    {
      "name": "Wood_Softwood_Planks",
      "x": -2,
      "y": 0,
      "z": 1
    },
    {
      "name": "Furniture_Tavern_Barrel",
      "x": -2,
      "y": 1,
      "z": 1
    },
    {
      "name": "Empty",
      "x": -2,
      "y": 2,
      "z": 1
    },
    {
      "name": "Empty",
      "x": -2,
      "y": 3,
      "z": 1
    },
    {
      "name": "Soil_Dirt",
      "x": -2,
      "y": 0,
      "z": 2
    },
    {
      "name": "Wood_Softwood_Planks_Half",
      "rotation": 4,
      "x": -2,
      "y": 1,
      "z": 2
    },
    {
      "name": "Wood_Softwood_Planks_Half",
      "rotation": 4,
      "x": -2,
      "y": 2,
      "z": 2
    },
    {
      "name": "Wood_Softwood_Roof_Shallow",
      "x": -2,
      "y": 3,
      "z": 2
    },
    {
      "name": "Soil_Dirt",
      "x": -1,
      "y": 0,
      "z": -2
    },
    {
      "name": "Wood_Softwood_Planks_Half",
      "rotation": 6,
      "x": -1,
      "y": 1,
      "z": -2
    },
    {
      "name": "Wood_Softwood_Planks_Half",
      "rotation": 6,
      "x": -1,
      "y": 2,
      "z": -2
    },
    {
      "name": "Wood_Softwood_Roof_Shallow",
      "rotation": 2,
      "x": -1,
      "y": 3,
      "z": -2
    },
    {
      "name": "Wood_Softwood_Planks",
      "x": -1,
      "y": 0,
      "z": -1
    },
    {
      "name": "Furniture_Village_Crate",
      "x": -1,
      "y": 1,
      "z": -1
    },
    {
      "name": "Furniture_Crude_Stool",
      "rotation": 1,
      "x": -1,
      "y": 2,
      "z": -1
    },
    {
      "name": "Empty",
      "rotation": 2,
      "x": -1,
      "y": 3,
      "z": -1
    },
    {
      "name": "Wood_Softwood_Planks",
      "x": -1,
      "y": 0,
      "z": 0
    },
    {
      "name": "Empty",
      "x": -1,
      "y": 1,
      "z": 0
    },
    {
      "name": "Empty",
      "x": -1,
      "y": 2,
      "z": 0
    },
    {
      "name": "Empty",
      "x": -1,
      "y": 3,
      "z": 0
    },
    {
      "name": "Wood_Softwood_Roof_Flat",
      "x": -1,
      "y": 4,
      "z": 0
    },
    {
      "name": "Wood_Softwood_Planks",
      "x": -1,
      "y": 0,
      "z": 1
    },
    {
      "name": "Furniture_Tavern_Barrel",
      "x": -1,
      "y": 1,
      "z": 1
    },
    {
      "name": "Empty",
      "x": -1,
      "y": 2,
      "z": 1
    },
    {
      "name": "Empty",
      "x": -1,
      "y": 3,
      "z": 1
    },
    {
      "name": "Soil_Dirt",
      "x": -1,
      "y": 0,
      "z": 2
    },
    {
      "name": "Wood_Softwood_Planks_Half",
      "rotation": 4,
      "x": -1,
      "y": 1,
      "z": 2
    },
    {
      "name": "Wood_Softwood_Planks_Half",
      "rotation": 4,
      "x": -1,
      "y": 2,
      "z": 2
    },
    {
      "name": "Wood_Softwood_Roof_Shallow",
      "x": -1,
      "y": 3,
      "z": 2
    },
    {
      "name": "Soil_Dirt",
      "x": 0,
      "y": 0,
      "z": -2
    },
    {
      "name": "Wood_Softwood_Planks_Half",
      "rotation": 6,
      "x": 0,
      "y": 1,
      "z": -2
    },
    {
      "name": "Wood_Softwood_Planks_Half",
      "rotation": 6,
      "x": 0,
      "y": 2,
      "z": -2
    },
    {
      "name": "Wood_Softwood_Roof_Shallow",
      "rotation": 2,
      "x": 0,
      "y": 3,
      "z": -2
    },
    {
      "name": "Wood_Softwood_Planks",
      "x": 0,
      "y": 0,
      "z": -1
    },
    {
      "name": "Furniture_Crude_Stool",
      "rotation": 1,
      "x": 0,
      "y": 1,
      "z": -1
    },
    {
      "name": "Empty",
      "x": 0,
      "y": 2,
      "z": -1
    },
    {
      "name": "Empty",
      "rotation": 2,
      "x": 0,
      "y": 3,
      "z": -1
    },
    {
      "name": "Wood_Softwood_Planks",
      "x": 0,
      "y": 0,
      "z": 0
    },
    {
      "name": "Empty",
      "x": 0,
      "y": 1,
      "z": 0
    },
    {
      "name": "Empty",
      "x": 0,
      "y": 3,
      "z": 0
    },
    {
      "name": "Wood_Softwood_Roof_Flat",
      "x": 0,
      "y": 4,
      "z": 0
    },
    {
      "name": "Wood_Softwood_Planks",
      "x": 0,
      "y": 0,
      "z": 1
    },
    {
      "name": "Empty",
      "x": 0,
      "y": 1,
      "z": 1
    },
    {
      "name": "Empty",
      "x": 0,
      "y": 2,
      "z": 1
    },
    {
      "name": "Empty",
      "x": 0,
      "y": 3,
      "z": 1
    },
    {
      "name": "Soil_Dirt",
      "x": 0,
      "y": 0,
      "z": 2
    },
    {
      "name": "Wood_Softwood_Planks_Half",
      "rotation": 4,
      "x": 0,
      "y": 1,
      "z": 2
    },
    {
      "name": "Wood_Softwood_Planks_Half",
      "rotation": 4,
      "x": 0,
      "y": 2,
      "z": 2
    },
    {
      "name": "Wood_Softwood_Roof_Shallow",
      "x": 0,
      "y": 3,
      "z": 2
    },
    {
      "name": "Soil_Dirt",
      "x": 1,
      "y": 0,
      "z": -2
    },
    {
      "name": "Wood_Softwood_Planks_Half",
      "rotation": 6,
      "x": 1,
      "y": 1,
      "z": -2
    },
    {
      "name": "Wood_Softwood_Planks_Half",
      "rotation": 6,
      "x": 1,
      "y": 2,
      "z": -2
    },
    {
      "name": "Wood_Softwood_Roof_Shallow",
      "rotation": 2,
      "x": 1,
      "y": 3,
      "z": -2
    },
    {
      "name": "Wood_Softwood_Planks",
      "x": 1,
      "y": 0,
      "z": -1
    },
    {
      "name": "Furniture_Crude_Shelf",
      "x": 1,
      "y": 1,
      "z": -1
    },
    {
      "name": "Empty",
      "x": 1,
      "y": 2,
      "z": -1
    },
    {
      "name": "Empty",
      "rotation": 2,
      "x": 1,
      "y": 3,
      "z": -1
    },
    {
      "name": "Wood_Softwood_Planks",
      "x": 1,
      "y": 0,
      "z": 0
    },
    {
      "name": "Empty",
      "x": 1,
      "y": 1,
      "z": 0
    },
    {
      "name": "Empty",
      "x": 1,
      "y": 3,
      "z": 0
    },
    {
      "name": "Wood_Softwood_Roof_Flat",
      "x": 1,
      "y": 4,
      "z": 0
    },
    {
      "name": "Wood_Softwood_Planks",
      "x": 1,
      "y": 0,
      "z": 1
    },
    {
      "name": "Empty",
      "x": 1,
      "y": 1,
      "z": 1
    },
    {
      "name": "Empty",
      "x": 1,
      "y": 2,
      "z": 1
    },
    {
      "name": "Empty",
      "x": 1,
      "y": 3,
      "z": 1
    },
    {
      "name": "Soil_Dirt",
      "x": 1,
      "y": 0,
      "z": 2
    },
    {
      "name": "Wood_Softwood_Planks_Half",
      "rotation": 4,
      "x": 1,
      "y": 1,
      "z": 2
    },
    {
      "name": "Wood_Softwood_Planks_Half",
      "rotation": 4,
      "x": 1,
      "y": 2,
      "z": 2
    },
    {
      "name": "Wood_Softwood_Roof_Shallow",
      "x": 1,
      "y": 3,
      "z": 2
    },
    {
      "name": "Soil_Dirt",
      "x": 2,
      "y": 0,
      "z": -2
    },
    {
      "name": "Wood_Softwood_Planks_Half",
      "rotation": 6,
      "x": 2,
      "y": 1,
      "z": -2
    },
    {
      "name": "Wood_Softwood_Planks_Half",
      "rotation": 6,
      "x": 2,
      "y": 2,
      "z": -2
    },
    {
      "name": "Wood_Softwood_Roof_Shallow",
      "rotation": 2,
      "x": 2,
      "y": 3,
      "z": -2
    },
    {
      "name": "Wood_Softwood_Planks",
      "x": 2,
      "y": 0,
      "z": -1
    },
    {
      "name": "Furniture_Crude_Shelf",
      "x": 2,
      "y": 1,
      "z": -1
    },
    {
      "name": "Empty",
      "x": 2,
      "y": 2,
      "z": -1
    },
    {
      "name": "Empty",
      "rotation": 2,
      "x": 2,
      "y": 3,
      "z": -1
    },
    {
      "name": "Wood_Softwood_Planks",
      "x": 2,
      "y": 0,
      "z": 0
    },
    {
      "name": "Empty",
      "x": 2,
      "y": 1,
      "z": 0
    },
    {
      "name": "Empty",
      "x": 2,
      "y": 3,
      "z": 0
    },
    {
      "name": "Wood_Softwood_Roof_Flat",
      "x": 2,
      "y": 4,
      "z": 0
    },
    {
      "name": "Wood_Softwood_Planks",
      "x": 2,
      "y": 0,
      "z": 1
    },
    {
      "name": "Furniture_Village_Crate",
      "x": 2,
      "y": 1,
      "z": 1
    },
    {
      "name": "Empty",
      "x": 2,
      "y": 2,
      "z": 1
    },
    {
      "name": "Empty",
      "x": 2,
      "y": 3,
      "z": 1
    },
    {
      "name": "Soil_Dirt",
      "x": 2,
      "y": 0,
      "z": 2
    },
    {
      "name": "Wood_Softwood_Planks_Half",
      "rotation": 4,
      "x": 2,
      "y": 1,
      "z": 2
    },
    {
      "name": "Wood_Softwood_Planks_Half",
      "rotation": 4,
      "x": 2,
      "y": 2,
      "z": 2
    },
    {
      "name": "Wood_Softwood_Roof_Shallow",
      "x": 2,
      "y": 3,
      "z": 2
    },
    {
      "name": "Soil_Dirt",
      "x": 3,
      "y": 0,
      "z": -2
    },
    {
      "name": "Wood_Softwood_Planks_Half",
      "rotation": 6,
      "x": 3,
      "y": 1,
      "z": -2
    },
    {
      "name": "Wood_Softwood_Planks_Half",
      "rotation": 6,
      "x": 3,
      "y": 2,
      "z": -2
    },
    {
      "name": "Wood_Softwood_Roof_Shallow",
      "rotation": 2,
      "x": 3,
      "y": 3,
      "z": -2
    },
    {
      "name": "Wood_Softwood_Planks",
      "x": 3,
      "y": 0,
      "z": -1
    },
    {
      "name": "Wood_Softwood_Planks_Half",
      "rotation": 7,
      "x": 3,
      "y": 1,
      "z": -1
    },
    {
      "name": "Wood_Softwood_Planks_Half",
      "rotation": 7,
      "x": 3,
      "y": 2,
      "z": -1
    },
    {
      "name": "Empty",
      "rotation": 2,
      "x": 3,
      "y": 3,
      "z": -1
    },
    {
      "name": "Wood_Softwood_Planks",
      "x": 3,
      "y": 0,
      "z": 0
    },
    {
      "name": "*Furniture_Crude_Door_State_Definitions_CloseDoorIn",
      "rotation": 1,
      "x": 3,
      "y": 1,
      "z": 0
    },
    {
      "name": "Empty",
      "rotation": 1,
      "x": 3,
      "y": 2,
      "z": 0
    },
    {
      "name": "Wood_Softwood_Planks_Half",
      "rotation": 7,
      "x": 3,
      "y": 3,
      "z": 0
    },
    {
      "name": "Wood_Softwood_Roof_Flat",
      "x": 3,
      "y": 4,
      "z": 0
    },
    {
      "name": "Wood_Softwood_Planks",
      "x": 3,
      "y": 0,
      "z": 1
    },
    {
      "name": "Wood_Softwood_Planks_Half",
      "rotation": 7,
      "x": 3,
      "y": 1,
      "z": 1
    },
    {
      "name": "Wood_Softwood_Planks_Half",
      "rotation": 7,
      "x": 3,
      "y": 2,
      "z": 1
    },
    {
      "name": "Empty",
      "x": 3,
      "y": 3,
      "z": 1
    },
    {
      "name": "Soil_Dirt",
      "x": 3,
      "y": 0,
      "z": 2
    },
    {
      "name": "Wood_Softwood_Planks_Half",
      "rotation": 4,
      "x": 3,
      "y": 1,
      "z": 2
    },
    {
      "name": "Wood_Softwood_Planks_Half",
      "rotation": 4,
      "x": 3,
      "y": 2,
      "z": 2
    },
    {
      "name": "Wood_Softwood_Roof_Shallow",
      "x": 3,
      "y": 3,
      "z": 2
    }
  ],
  "entities": [
    {
      "Components": {
        "EntityScale": {
          "Scale": 1.0
        },
        "HeadRotation": {
          "Rotation": {
            "Pitch": -0.48027873039245605,
            "Roll": 3.1363744735717773,
            "Yaw": 2.8856468200683594
          }
        },
        "Item": {
          "Item": {
            "Durability": 150.0,
            "Id": "Tool_Shovel_Crude",
            "MaxDurability": 150.0,
            "OverrideDroppedItemAnimation": true,
            "Quantity": 1
          },
          "PickupDelay": 0.5,
          "PickupThrottle": 0.0,
          "RemovedByPlayerPickup": false,
          "StackDelay": 1.5
        },
        "PrefabCopyable": {},
        "PreventItemMerging": {},
        "PreventPickup": {},
        "Prop": {},
        "Transform": {
          "Position": {
            "X": 0.29701805114746094,
            "Y": 2.3299598693847656,
            "Z": 1.996833324432373
          },
          "Rotation": {
            "Pitch": -0.48027873039245605,
            "Roll": 3.1363744735717773,
            "Yaw": 2.885646343231201
          }
        }
      }
    },
    {
      "Components": {
        "EntityScale": {
          "Scale": 1.0
        },
        "HeadRotation": {
          "Rotation": {
            "Pitch": 0.0,
            "Roll": -0.6859027147293091,
            "Yaw": -1.7273190021514893
          }
        },
        "Item": {
          "Item": {
            "Durability": 300.0,
            "Id": "Tool_Hoe_Iron",
            "MaxDurability": 300.0,
            "OverrideDroppedItemAnimation": true,
            "Quantity": 1
          },
          "PickupDelay": 0.5,
          "PickupThrottle": 0.0,
          "RemovedByPlayerPickup": false,
          "StackDelay": 1.5
        },
        "PrefabCopyable": {},
        "PreventItemMerging": {},
        "PreventPickup": {},
        "Prop": {},
        "Transform": {
          "Position": {
            "X": 1.1640963554382324,
            "Y": 1.0200424194335938,
            "Z": 1.2196590900421145
          },
          "Rotation": {
            "Pitch": 0.0,
            "Roll": -0.6859027147293091,
            "Yaw": -1.7273190021514893
          }
        }
      }
    },
    {
      "Components": {
        "EntityScale": {
          "Scale": 1.0
        },
        "HeadRotation": {
          "Rotation": {
            "Pitch": 0.0,
            "Roll": 1.5148988962173462,
            "Yaw": -3.1188368797302246
          }
        },
        "Item": {
          "Item": {
            "Durability": 100.0,
            "Id": "Tool_Hammer_Crude",
            "MaxDurability": 100.0,
            "OverrideDroppedItemAnimation": true,
            "Quantity": 1
          },
          "PickupDelay": 0.5,
          "PickupThrottle": 0.0,
          "RemovedByPlayerPickup": false,
          "StackDelay": 1.5
        },
        "PrefabCopyable": {},
        "PreventItemMerging": {},
        "PreventPickup": {},
        "Prop": {},
        "Transform": {
          "Position": {
            "X": 2.015869140625,
            "Y": 2.03900146484375,
            "Z": -0.7161865234375
          },
          "Rotation": {
            "Pitch": 0.0,
            "Roll": 1.5148988962173462,
            "Yaw": -3.1188368797302246
          }
        }
      }
    }
  ],
  "version": 8
}