{
  "version": 8,
  "blockIdVersion": 11,
  "anchorX": 0,
  "anchorY": 0,
  "anchorZ": 0,
  "blocks": [
    {
      "x": -15,
      "y": 0,
      "z": -6,
      "name": "Soil_Grass"
    },
    {
      "x": -15,
      "y": 1,
      "z": -6,
      "name": "*Rock_Stone_Cobble_Wall_State_Definitions_Corner",
      "rotation": 1
    },
    {
      "x": -15,
      "y": 2,
      "z": -6,
      "name": "*Rock_Stone_Cobble_Wall_State_Definitions_Corner",
      "rotation": 1
    },
    {
      "x": -15,
      "y": 3,
      "z": -6,
      "name": "*Rock_Stone_Cobble_Wall_State_Definitions_Corner",
      "rotation": 1
    },
    {
      "x": -15,
      "y": 4,
      "z": -6,
      "name": "*Rock_Stone_Cobble_Wall_State_Definitions_Corner",
      "rotation": 1
    },
    {
      "x": -15,
      "y": 5,
      "z": -6,
      "name": "*Rock_Stone_Cobble_Wall_State_Definitions_Corner",
      "rotation": 1
    },
    {
      "x": -15,
      "y": 6,
      "z": -6,
      "name": "*Rock_Stone_Cobble_Wall_State_Definitions_Corner",
      "rotation": 1
    },
    {
      "x": -15,
      "y": 7,
      "z": -6,
      "name": "Rock_Marble_Brick_Half"
    },
    {
      "x": -15,
      "y": 0,
      "z": -5,
      "name": "Soil_Grass"
    },
    {
      "x": -15,
      "y": 1,
      "z": -5,
      "name": "Rock_Stone_Cobble_Wall",
      "rotation": 3
    },
    {
      "x": -15,
      "y": 2,
      "z": -5,
      "name": "Rock_Stone_Cobble_Wall",
      "rotation": 3
    },
    {
      "x": -15,
      "y": 3,
      "z": -5,
      "name": "Rock_Stone_Cobble_Wall",
      "rotation": 3
    },
    {
      "x": -15,
      "y": 4,
      "z": -5,
      "name": "Rock_Stone_Cobble_Wall",
      "rotation": 3
    },
    {
      "x": -15,
      "y": 5,
      "z": -5,
      "name": "Rock_Stone_Cobble_Wall",
      "rotation": 3
    },
    {
      "x": -15,
      "y": 6,
      "z": -5,
      "name": "Rock_Stone_Cobble_Wall",
      "rotation": 3
    },
    {
      "x": -15,
      "y": 7,
      "z": -5,
      "name": "Rock_Marble_Brick_Half"
    },
    {
      "x": -15,
      "y": 0,
      "z": -4,
      "name": "Soil_Dirt"
    },
    {
      "x": -15,
      "y": 1,
      "z": -4,
      "name": "Rock_Marble_Brick",
      "rotation": 3
    },
    {
      "x": -15,
      "y": 2,
      "z": -4,
      "name": "Rock_Marble_Brick",
      "rotation": 3
    },
    {
      "x": -15,
      "y": 3,
      "z": -4,
      "name": "Rock_Marble_Brick",
      "rotation": 3
    },
    {
      "x": -15,
      "y": 4,
      "z": -4,
      "name": "Rock_Marble_Brick",
      "rotation": 3
    },
    {
      "x": -15,
      "y": 5,
      "z": -4,
      "name": "Rock_Marble_Brick",
      "rotation": 3
    },
    {
      "x": -15,
      "y": 6,
      "z": -4,
      "name": "Rock_Marble_Brick",
      "rotation": 3
    },
    {
      "x": -15,
      "y": 7,
      "z": -4,
      "name": "Rock_Marble_Brick_Half"
    },
    {
      "x": -15,
      "y": 0,
      "z": -3,
      "name": "Soil_Grass"
    },
    {
      "x": -15,
      "y": 1,
      "z": -3,
      "name": "Rock_Stone_Cobble_Wall",
      "rotation": 3
    },
    {
      "x": -15,
      "y": 2,
      "z": -3,
      "name": "Rock_Stone_Cobble_Wall",
      "rotation": 3
    },
    {
      "x": -15,
      "y": 3,
      "z": -3,
      "name": "Rock_Stone_Cobble_Wall",
      "rotation": 3
    },
    {
      "x": -15,
      "y": 4,
      "z": -3,
      "name": "Rock_Stone_Cobble_Wall",
      "rotation": 3
    },
    {
      "x": -15,
      "y": 5,
      "z": -3,
      "name": "Rock_Stone_Cobble_Wall",
      "rotation": 3
    },
    {
      "x": -15,
      "y": 6,
      "z": -3,
      "name": "Rock_Stone_Cobble_Wall",
      "rotation": 3
    },
    {
      "x": -15,
      "y": 7,
      "z": -3,
      "name": "Rock_Marble_Brick_Half"
    },
    {
      "x": -15,
      "y": 0,
      "z": -2,
      "name": "Soil_Dirt"
    },
    {
      "x": -15,
      "y": 1,
      "z": -2,
      "name": "Rock_Marble_Brick"
    },
    {
      "x": -15,
      "y": 2,
      "z": -2,
      "name": "Rock_Marble_Brick"
    },
    {
      "x": -15,
      "y": 3,
      "z": -2,
      "name": "Rock_Marble_Brick"
    },
    {
      "x": -15,
      "y": 4,
      "z": -2,
      "name": "Rock_Marble_Brick"
    },
    {
      "x": -15,
      "y": 5,
      "z": -2,
      "name": "Rock_Stone_Cobble_Wall",
      "rotation": 3
    },
    {
      "x": -15,
      "y": 6,
      "z": -2,
      "name": "Rock_Stone_Cobble_Wall",
      "rotation": 3
    },
    {
      "x": -15,
      "y": 7,
      "z": -2,
      "name": "Rock_Marble_Brick_Half"
    },
    {
      "x": -15,
      "y": 0,
      "z": -1,
      "name": "Soil_Gravel",
      "support": 15
    },
    {
      "x": -15,
      "y": 4,
      "z": -1,
      "name": "Rock_Marble_Brick_Half",
      "rotation": 4
    },
    {
      "x": -15,
      "y": 5,
      "z": -1,
      "name": "Rock_Marble_Brick"
    },
    {
      "x": -15,
      "y": 6,
      "z": -1,
      "name": "Rock_Stone_Cobble_Wall",
      "rotation": 3
    },
    {
      "x": -15,
      "y": 7,
      "z": -1,
      "name": "Rock_Marble_Brick_Half"
    },
    {
      "x": -15,
      "y": 0,
      "z": 0,
      "name": "Soil_Gravel",
      "support": 15
    },
    {
      "x": -15,
      "y": 5,
      "z": 0,
      "name": "Rock_Marble_Brick_Half",
      "rotation": 8
    },
    {
      "x": -15,
      "y": 6,
      "z": 0,
      "name": "Rock_Stone_Cobble_Wall",
      "rotation": 3
    },
    {
      "x": -15,
      "y": 7,
      "z": 0,
      "name": "Rock_Marble_Brick_Half"
    },
    {
      "x": -15,
      "y": 0,
      "z": 1,
      "name": "Soil_Gravel",
      "support": 15
    },
    {
      "x": -15,
      "y": 4,
      "z": 1,
      "name": "Rock_Marble_Brick_Half",
      "rotation": 6
    },
    {
      "x": -15,
      "y": 5,
      "z": 1,
      "name": "Rock_Marble_Brick"
    },
    {
      "x": -15,
      "y": 6,
      "z": 1,
      "name": "Rock_Stone_Cobble_Wall",
      "rotation": 3
    },
    {
      "x": -15,
      "y": 7,
      "z": 1,
      "name": "Rock_Marble_Brick_Half"
    },
    {
      "x": -15,
      "y": 0,
      "z": 2,
      "name": "Soil_Dirt"
    },
    {
      "x": -15,
      "y": 1,
      "z": 2,
      "name": "Rock_Marble_Brick"
    },
    {
      "x": -15,
      "y": 2,
      "z": 2,
      "name": "Rock_Marble_Brick"
    },
    {
      "x": -15,
      "y": 3,
      "z": 2,
      "name": "Rock_Marble_Brick"
    },
    {
      "x": -15,
      "y": 4,
      "z": 2,
      "name": "Rock_Marble_Brick"
    },
    {
      "x": -15,
      "y": 5,
      "z": 2,
      "name": "Rock_Stone_Cobble_Wall",
      "rotation": 3
    },
    {
      "x": -15,
      "y": 6,
      "z": 2,
      "name": "Rock_Stone_Cobble_Wall",
      "rotation": 3
    },
    {
      "x": -15,
      "y": 7,
      "z": 2,
      "name": "Rock_Marble_Brick_Half"
    },
    {
      "x": -15,
      "y": 0,
      "z": 3,
      "name": "Soil_Grass"
    },
    {
      "x": -15,
      "y": 1,
      "z": 3,
      "name": "Rock_Stone_Cobble_Wall",
      "rotation": 3
    },
    {
      "x": -15,
      "y": 2,
      "z": 3,
      "name": "Rock_Stone_Cobble_Wall",
      "rotation": 3
    },
    {
      "x": -15,
      "y": 3,
      "z": 3,
      "name": "Rock_Stone_Cobble_Wall",
      "rotation": 3
    },
    {
      "x": -15,
      "y": 4,
      "z": 3,
      "name": "Rock_Stone_Cobble_Wall",
      "rotation": 3
    },
    {
      "x": -15,
      "y": 5,
      "z": 3,
      "name": "Rock_Stone_Cobble_Wall",
      "rotation": 3
    },
    {
      "x": -15,
      "y": 6,
      "z": 3,
      "name": "Rock_Stone_Cobble_Wall",
      "rotation": 3
    },
    {
      "x": -15,
      "y": 7,
      "z": 3,
      "name": "Rock_Marble_Brick_Half"
    },
    {
      "x": -15,
      "y": 0,
      "z": 4,
      "name": "Soil_Dirt"
    },
    {
      "x": -15,
      "y": 1,
      "z": 4,
      "name": "Rock_Marble_Brick",
      "rotation": 3
    },
    {
      "x": -15,
      "y": 2,
      "z": 4,
      "name": "Rock_Marble_Brick",
      "rotation": 3
    },
    {
      "x": -15,
      "y": 3,
      "z": 4,
      "name": "Rock_Marble_Brick",
      "rotation": 3
    },
    {
      "x": -15,
      "y": 4,
      "z": 4,
      "name": "Rock_Marble_Brick",
      "rotation": 3
    },
    {
      "x": -15,
      "y": 5,
      "z": 4,
      "name": "Rock_Marble_Brick",
      "rotation": 3
    },
    {
      "x": -15,
      "y": 6,
      "z": 4,
      "name": "Rock_Marble_Brick",
      "rotation": 3
    },
    {
      "x": -15,
      "y": 7,
      "z": 4,
      "name": "Rock_Marble_Brick_Half"
    },
    {
      "x": -15,
      "y": 0,
      "z": 5,
      "name": "Soil_Grass"
    },
    {
      "x": -15,
      "y": 1,
      "z": 5,
      "name": "Rock_Stone_Cobble_Wall",
      "rotation": 1
    },
    {
      "x": -15,
      "y": 2,
      "z": 5,
      "name": "Rock_Stone_Cobble_Wall",
      "rotation": 1
    },
    {
      "x": -15,
      "y": 3,
      "z": 5,
      "name": "Rock_Stone_Cobble_Wall",
      "rotation": 1
    },
    {
      "x": -15,
      "y": 4,
      "z": 5,
      "name": "Rock_Stone_Cobble_Wall",
      "rotation": 1
    },
    {
      "x": -15,
      "y": 5,
      "z": 5,
      "name": "Rock_Stone_Cobble_Wall",
      "rotation": 1
    },
    {
      "x": -15,
      "y": 6,
      "z": 5,
      "name": "Rock_Stone_Cobble_Wall",
      "rotation": 1
    },
    {
      "x": -15,
      "y": 7,
      "z": 5,
      "name": "Rock_Marble_Brick_Half"
    },
    {
      "x": -15,
      "y": 0,
      "z": 6,
      "name": "Soil_Grass"
    },
    {
      "x": -15,
      "y": 1,
      "z": 6,
      "name": "*Rock_Stone_Cobble_Wall_State_Definitions_Corner",
      "rotation": 2
    },
    {
      "x": -15,
      "y": 2,
      "z": 6,
      "name": "*Rock_Stone_Cobble_Wall_State_Definitions_Corner",
      "rotation": 2
    },
    {
      "x": -15,
      "y": 3,
      "z": 6,
      "name": "*Rock_Stone_Cobble_Wall_State_Definitions_Corner",
      "rotation": 2
    },
    {
      "x": -15,
      "y": 4,
      "z": 6,
      "name": "*Rock_Stone_Cobble_Wall_State_Definitions_Corner",
      "rotation": 2
    },
    {
      "x": -15,
      "y": 5,
      "z": 6,
      "name": "*Rock_Stone_Cobble_Wall_State_Definitions_Corner",
      "rotation": 2
    },
    {
      "x": -15,
      "y": 6,
      "z": 6,
      "name": "*Rock_Stone_Cobble_Wall_State_Definitions_Corner",
      "rotation": 2
    },
    {
      "x": -15,
      "y": 7,
      "z": 6,
      "name": "Rock_Marble_Brick_Half"
    },
    {
      "x": -14,
      "y": 0,
      "z": -8,
      "name": "Soil_Grass"
    },
    {
      "x": -14,
      "y": 1,
      "z": -8,
      "name": "*Rock_Stone_Cobble_Wall_State_Definitions_Corner",
      "rotation": 1
    },
    {
      "x": -14,
      "y": 2,
      "z": -8,
      "name": "*Rock_Stone_Cobble_Wall_State_Definitions_Corner",
      "rotation": 1
    },
    {
      "x": -14,
      "y": 3,
      "z": -8,
      "name": "*Rock_Stone_Cobble_Wall_State_Definitions_Corner",
      "rotation": 1
    },
    {
      "x": -14,
      "y": 4,
      "z": -8,
      "name": "*Rock_Stone_Cobble_Wall_State_Definitions_Corner",
      "rotation": 1
    },
    {
      "x": -14,
      "y": 5,
      "z": -8,
      "name": "*Rock_Stone_Cobble_Wall_State_Definitions_Corner",
      "rotation": 1
    },
    {
      "x": -14,
      "y": 6,
      "z": -8,
      "name": "*Rock_Stone_Cobble_Wall_State_Definitions_Corner",
      "rotation": 1
    },
    {
      "x": -14,
      "y": 7,
      "z": -8,
      "name": "Rock_Marble_Brick_Half"
    },
    {
      "x": -14,
      "y": 0,
      "z": -7,
      "name": "Soil_Grass"
    },
    {
      "x": -14,
      "y": 1,
      "z": -7,
      "name": "Rock_Stone_Cobble_Wall",
      "rotation": 3
    },
    {
      "x": -14,
      "y": 2,
      "z": -7,
      "name": "Rock_Stone_Cobble_Wall",
      "rotation": 3
    },
    {
      "x": -14,
      "y": 3,
      "z": -7,
      "name": "Rock_Stone_Cobble_Wall",
      "rotation": 3
    },
    {
      "x": -14,
      "y": 4,
      "z": -7,
      "name": "Rock_Stone_Cobble_Wall",
      "rotation": 3
    },
    {
      "x": -14,
      "y": 5,
      "z": -7,
      "name": "Rock_Stone_Cobble_Wall",
      "rotation": 3
    },
    {
      "x": -14,
      "y": 6,
      "z": -7,
      "name": "Rock_Stone_Cobble_Wall",
      "rotation": 3
    },
    {
      "x": -14,
      "y": 7,
      "z": -7,
      "name": "Rock_Marble_Brick_Half"
    },
    {
      "x": -14,
      "y": 0,
      "z": -6,
      "name": "Soil_Grass"
    },
    {
      "x": -14,
      "y": 1,
      "z": -6,
      "name": "*Rock_Stone_Cobble_Wall_State_Definitions_Corner",
      "rotation": 3
    },
    {
      "x": -14,
      "y": 2,
      "z": -6,
      "name": "*Rock_Stone_Cobble_Wall_State_Definitions_Corner",
      "rotation": 3
    },
    {
      "x": -14,
      "y": 3,
      "z": -6,
      "name": "*Rock_Stone_Cobble_Wall_State_Definitions_Corner",
      "rotation": 3
    },
    {
      "x": -14,
      "y": 4,
      "z": -6,
      "name": "*Rock_Stone_Cobble_Wall_State_Definitions_Corner",
      "rotation": 3
    },
    {
      "x": -14,
      "y": 5,
      "z": -6,
      "name": "*Rock_Stone_Cobble_Wall_State_Definitions_Corner",
      "rotation": 3
    },
    {
      "x": -14,
      "y": 6,
      "z": -6,
      "name": "*Rock_Stone_Cobble_Wall_State_Definitions_Corner",
      "rotation": 3
    },
    {
      "x": -14,
      "y": 7,
      "z": -6,
      "name": "Rock_Marble_Brick_Half"
    },
    {
      "x": -14,
      "y": 0,
      "z": -5,
      "name": "Soil_Grass"
    },
    {
      "x": -14,
      "y": 0,
      "z": -4,
      "name": "Soil_Grass"
    },
    {
      "x": -14,
      "y": 1,
      "z": -4,
      "name": "Plant_Grass_Jungle",
      "support": 15
    },
    {
      "x": -14,
      "y": 4,
      "z": -4,
      "name": "Plant_Vine_Wall",
      "support": 15,
      "rotation": 1
    },
    {
      "x": -14,
      "y": 5,
      "z": -4,
      "name": "Plant_Vine_Wall",
      "support": 15,
      "rotation": 1
    },
    {
      "x": -14,
      "y": 6,
      "z": -4,
      "name": "Plant_Vine",
      "support": 15,
      "rotation": 1
    },
    {
      "x": -14,
      "y": 0,
      "z": -3,
      "name": "Soil_Grass"
    },
    {
      "x": -14,
      "y": 1,
      "z": -3,
      "name": "Plant_Grass_Jungle",
      "support": 15
    },
    {
      "x": -14,
      "y": 0,
      "z": -2,
      "name": "Soil_Grass"
    },
    {
      "x": -14,
      "y": 1,
      "z": -2,
      "name": "Plant_Grass_Jungle",
      "support": 15
    },
    {
      "x": -14,
      "y": 0,
      "z": -1,
      "name": "Soil_Gravel",
      "support": 15
    },
    {
      "x": -14,
      "y": 0,
      "z": 0,
      "name": "Soil_Gravel",
      "support": 15
    },
    {
      "x": -14,
      "y": 0,
      "z": 1,
      "name": "Soil_Gravel",
      "support": 15
    },
    {
      "x": -14,
      "y": 4,
      "z": 1,
      "name": "Plant_Vine_Wall",
      "support": 15,
      "rotation": 1
    },
    {
      "x": -14,
      "y": 5,
      "z": 1,
      "name": "Plant_Vine_Wall",
      "support": 15,
      "rotation": 1
    },
    {
      "x": -14,
      "y": 0,
      "z": 2,
      "name": "Soil_Grass"
    },
    {
      "x": -14,
      "y": 3,
      "z": 2,
      "name": "Plant_Vine_Wall",
      "support": 15,
      "rotation": 1
    },
    {
      "x": -14,
      "y": 4,
      "z": 2,
      "name": "Plant_Vine",
      "support": 15,
      "rotation": 1
    },
    {
      "x": -14,
      "y": 0,
      "z": 3,
      "name": "Soil_Grass"
    },
    {
      "x": -14,
      "y": 1,
      "z": 3,
      "name": "Plant_Grass_Jungle",
      "support": 15
    },
    {
      "x": -14,
      "y": 0,
      "z": 4,
      "name": "Soil_Grass"
    },
    {
      "x": -14,
      "y": 6,
      "z": 4,
      "name": "Plant_Vine_Wall_Dead",
      "support": 15,
      "rotation": 1
    },
    {
      "x": -14,
      "y": 0,
      "z": 5,
      "name": "Soil_Grass"
    },
    {
      "x": -14,
      "y": 1,
      "z": 5,
      "name": "Plant_Grass_Jungle_Tall",
      "support": 15
    },
    {
      "x": -14,
      "y": 0,
      "z": 6,
      "name": "Soil_Grass"
    },
    {
      "x": -14,
      "y": 1,
      "z": 6,
      "name": "*Rock_Stone_Cobble_Wall_State_Definitions_Corner"
    },
    {
      "x": -14,
      "y": 2,
      "z": 6,
      "name": "*Rock_Stone_Cobble_Wall_State_Definitions_Corner"
    },
    {
      "x": -14,
      "y": 3,
      "z": 6,
      "name": "*Rock_Stone_Cobble_Wall_State_Definitions_Corner"
    },
    {
      "x": -14,
      "y": 4,
      "z": 6,
      "name": "*Rock_Stone_Cobble_Wall_State_Definitions_Corner"
    },
    {
      "x": -14,
      "y": 5,
      "z": 6,
      "name": "*Rock_Stone_Cobble_Wall_State_Definitions_Corner"
    },
    {
      "x": -14,
      "y": 6,
      "z": 6,
      "name": "*Rock_Stone_Cobble_Wall_State_Definitions_Corner"
    },
    {
      "x": -14,
      "y": 7,
      "z": 6,
      "name": "Rock_Marble_Brick_Half"
    },
    {
      "x": -14,
      "y": 0,
      "z": 7,
      "name": "Soil_Grass"
    },
    {
      "x": -14,
      "y": 1,
      "z": 7,
      "name": "Rock_Stone_Cobble_Wall",
      "rotation": 1
    },
    {
      "x": -14,
      "y": 2,
      "z": 7,
      "name": "Rock_Stone_Cobble_Wall",
      "rotation": 1
    },
    {
      "x": -14,
      "y": 3,
      "z": 7,
      "name": "Rock_Stone_Cobble_Wall",
      "rotation": 1
    },
    {
      "x": -14,
      "y": 4,
      "z": 7,
      "name": "Rock_Stone_Cobble_Wall",
      "rotation": 1
    },
    {
      "x": -14,
      "y": 5,
      "z": 7,
      "name": "Rock_Stone_Cobble_Wall",
      "rotation": 1
    },
    {
      "x": -14,
      "y": 6,
      "z": 7,
      "name": "Rock_Stone_Cobble_Wall",
      "rotation": 1
    },
    {
      "x": -14,
      "y": 7,
      "z": 7,
      "name": "Rock_Marble_Brick_Half"
    },
    {
      "x": -14,
      "y": 0,
      "z": 8,
      "name": "Soil_Grass"
    },
    {
      "x": -14,
      "y": 1,
      "z": 8,
      "name": "*Rock_Stone_Cobble_Wall_State_Definitions_Corner",
      "rotation": 2
    },
    {
      "x": -14,
      "y": 2,
      "z": 8,
      "name": "*Rock_Stone_Cobble_Wall_State_Definitions_Corner",
      "rotation": 2
    },
    {
      "x": -14,
      "y": 3,
      "z": 8,
      "name": "*Rock_Stone_Cobble_Wall_State_Definitions_Corner",
      "rotation": 2
    },
    {
      "x": -14,
      "y": 4,
      "z": 8,
      "name": "*Rock_Stone_Cobble_Wall_State_Definitions_Corner",
      "rotation": 2
    },
    {
      "x": -14,
      "y": 5,
      "z": 8,
      "name": "*Rock_Stone_Cobble_Wall_State_Definitions_Corner",
      "rotation": 2
    },
    {
      "x": -14,
      "y": 6,
      "z": 8,
      "name": "*Rock_Stone_Cobble_Wall_State_Definitions_Corner",
      "rotation": 2
    },
    {
      "x": -14,
      "y": 7,
      "z": 8,
      "name": "Rock_Marble_Brick_Half"
    },
    {
      "x": -13,
      "y": 4,
      "z": -12,
      "name": "Plant_Vine_Wall",
      "support": 15,
      "rotation": 3
    },
    {
      "x": -13,
      "y": 5,
      "z": -12,
      "name": "Plant_Vine_Wall",
      "support": 15,
      "rotation": 3
    },
    {
      "x": -13,
      "y": 6,
      "z": -12,
      "name": "Plant_Vine_Wall",
      "support": 15,
      "rotation": 3
    },
    {
      "x": -13,
      "y": 0,
      "z": -11,
      "name": "Soil_Grass"
    },
    {
      "x": -13,
      "y": 1,
      "z": -11,
      "name": "*Rock_Stone_Cobble_Wall_State_Definitions_Corner",
      "rotation": 1
    },
    {
      "x": -13,
      "y": 2,
      "z": -11,
      "name": "*Rock_Stone_Cobble_Wall_State_Definitions_Corner",
      "rotation": 1
    },
    {
      "x": -13,
      "y": 3,
      "z": -11,
      "name": "*Rock_Stone_Cobble_Wall_State_Definitions_Corner",
      "rotation": 1
    },
    {
      "x": -13,
      "y": 4,
      "z": -11,
      "name": "*Rock_Stone_Cobble_Wall_State_Definitions_Corner",
      "rotation": 1
    },
    {
      "x": -13,
      "y": 5,
      "z": -11,
      "name": "*Rock_Stone_Cobble_Wall_State_Definitions_Corner",
      "rotation": 1
    },
    {
      "x": -13,
      "y": 6,
      "z": -11,
      "name": "*Rock_Stone_Cobble_Wall_State_Definitions_Corner",
      "rotation": 1
    },
    {
      "x": -13,
      "y": 7,
      "z": -11,
      "name": "Rock_Marble_Brick_Half"
    },
    {
      "x": -13,
      "y": 0,
      "z": -10,
      "name": "Soil_Grass"
    },
    {
      "x": -13,
      "y": 1,
      "z": -10,
      "name": "Rock_Stone_Cobble_Wall",
      "rotation": 3
    },
    {
      "x": -13,
      "y": 2,
      "z": -10,
      "name": "Rock_Stone_Cobble_Wall",
      "rotation": 3
    },
    {
      "x": -13,
      "y": 3,
      "z": -10,
      "name": "Rock_Stone_Cobble_Wall",
      "rotation": 3
    },
    {
      "x": -13,
      "y": 4,
      "z": -10,
      "name": "Rock_Stone_Cobble_Wall",
      "rotation": 3
    },
    {
      "x": -13,
      "y": 5,
      "z": -10,
      "name": "Rock_Stone_Cobble_Wall",
      "rotation": 3
    },
    {
      "x": -13,
      "y": 6,
      "z": -10,
      "name": "Rock_Stone_Cobble_Wall",
      "rotation": 3
    },
    {
      "x": -13,
      "y": 7,
      "z": -10,
      "name": "Rock_Marble_Brick_Half"
    },
    {
      "x": -13,
      "y": 0,
      "z": -9,
      "name": "Soil_Grass"
    },
    {
      "x": -13,
      "y": 1,
      "z": -9,
      "name": "Rock_Stone_Cobble_Wall",
      "rotation": 3
    },
    {
      "x": -13,
      "y": 2,
      "z": -9,
      "name": "Rock_Stone_Cobble_Wall",
      "rotation": 3
    },
    {
      "x": -13,
      "y": 3,
      "z": -9,
      "name": "Rock_Stone_Cobble_Wall",
      "rotation": 3
    },
    {
      "x": -13,
      "y": 4,
      "z": -9,
      "name": "Rock_Stone_Cobble_Wall",
      "rotation": 3
    },
    {
      "x": -13,
      "y": 5,
      "z": -9,
      "name": "Rock_Stone_Cobble_Wall",
      "rotation": 3
    },
    {
      "x": -13,
      "y": 6,
      "z": -9,
      "name": "Rock_Stone_Cobble_Wall",
      "rotation": 3
    },
    {
      "x": -13,
      "y": 7,
      "z": -9,
      "name": "Rock_Marble_Brick_Half"
    },
    {
      "x": -13,
      "y": 0,
      "z": -8,
      "name": "Soil_Grass"
    },
    {
      "x": -13,
      "y": 1,
      "z": -8,
      "name": "*Rock_Stone_Cobble_Wall_State_Definitions_Corner",
      "rotation": 3
    },
    {
      "x": -13,
      "y": 2,
      "z": -8,
      "name": "*Rock_Stone_Cobble_Wall_State_Definitions_Corner",
      "rotation": 3
    },
    {
      "x": -13,
      "y": 3,
      "z": -8,
      "name": "*Rock_Stone_Cobble_Wall_State_Definitions_Corner",
      "rotation": 3
    },
    {
      "x": -13,
      "y": 4,
      "z": -8,
      "name": "*Rock_Stone_Cobble_Wall_State_Definitions_Corner",
      "rotation": 3
    },
    {
      "x": -13,
      "y": 5,
      "z": -8,
      "name": "*Rock_Stone_Cobble_Wall_State_Definitions_Corner",
      "rotation": 3
    },
    {
      "x": -13,
      "y": 6,
      "z": -8,
      "name": "*Rock_Stone_Cobble_Wall_State_Definitions_Corner",
      "rotation": 3
    },
    {
      "x": -13,
      "y": 7,
      "z": -8,
      "name": "Rock_Marble_Brick_Half"
    },
    {
      "x": -13,
      "y": 0,
      "z": -7,
      "name": "Soil_Grass"
    },
    {
      "x": -13,
      "y": 1,
      "z": -7,
      "name": "Plant_Grass_Jungle",
      "support": 15
    },
    {
      "x": -13,
      "y": 0,
      "z": -6,
      "name": "Soil_Grass"
    },
    {
      "x": -13,
      "y": 1,
      "z": -6,
      "name": "Plant_Grass_Jungle",
      "support": 15
    },
    {
      "x": -13,
      "y": 0,
      "z": -5,
      "name": "Soil_Grass"
    },
    {
      "x": -13,
      "y": 1,
      "z": -5,
      "name": "Plant_Grass_Jungle_Tall",
      "support": 15
    },
    {
      "x": -13,
      "y": 0,
      "z": -4,
      "name": "Soil_Grass"
    },
    {
      "x": -13,
      "y": 1,
      "z": -4,
      "name": "Plant_Grass_Jungle",
      "support": 15
    },
    {
      "x": -13,
      "y": 0,
      "z": -3,
      "name": "Soil_Grass"
    },
    {
      "x": -13,
      "y": 1,
      "z": -3,
      "name": "Plant_Grass_Jungle_Tall",
      "support": 15
    },
    {
      "x": -13,
      "y": 0,
      "z": -2,
      "name": "Soil_Grass"
    },
    {
      "x": -13,
      "y": 1,
      "z": -2,
      "name": "Plant_Grass_Jungle_Tall",
      "support": 15
    },
    {
      "x": -13,
      "y": 0,
      "z": -1,
      "name": "Soil_Gravel",
      "support": 15
    },
    {
      "x": -13,
      "y": 0,
      "z": 0,
      "name": "Soil_Gravel",
      "support": 15
    },
    {
      "x": -13,
      "y": 0,
      "z": 1,
      "name": "Soil_Gravel",
      "support": 15
    },
    {
      "x": -13,
      "y": 0,
      "z": 2,
      "name": "Soil_Grass"
    },
    {
      "x": -13,
      "y": 0,
      "z": 3,
      "name": "Soil_Grass"
    },
    {
      "x": -13,
      "y": 1,
      "z": 3,
      "name": "Plant_Grass_Jungle_Tall",
      "support": 15
    },
    {
      "x": -13,
      "y": 0,
      "z": 4,
      "name": "Soil_Grass"
    },
    {
      "x": -13,
      "y": 1,
      "z": 4,
      "name": "Plant_Grass_Jungle",
      "support": 15
    },
    {
      "x": -13,
      "y": 0,
      "z": 5,
      "name": "Soil_Grass"
    },
    {
      "x": -13,
      "y": 1,
      "z": 5,
      "name": "Plant_Grass_Jungle",
      "support": 15
    },
    {
      "x": -13,
      "y": 0,
      "z": 6,
      "name": "Soil_Grass"
    },
    {
      "x": -13,
      "y": 1,
      "z": 6,
      "name": "Plant_Grass_Jungle_Tall",
      "support": 15
    },
    {
      "x": -13,
      "y": 0,
      "z": 7,
      "name": "Soil_Grass"
    },
    {
      "x": -13,
      "y": 1,
      "z": 7,
      "name": "Plant_Grass_Jungle",
      "support": 15
    },
    {
      "x": -13,
      "y": 0,
      "z": 8,
      "name": "Soil_Grass"
    },
    {
      "x": -13,
      "y": 1,
      "z": 8,
      "name": "*Rock_Stone_Cobble_Wall_State_Definitions_Corner"
    },
    {
      "x": -13,
      "y": 2,
      "z": 8,
      "name": "*Rock_Stone_Cobble_Wall_State_Definitions_Corner"
    },
    {
      "x": -13,
      "y": 3,
      "z": 8,
      "name": "*Rock_Stone_Cobble_Wall_State_Definitions_Corner"
    },
    {
      "x": -13,
      "y": 4,
      "z": 8,
      "name": "*Rock_Stone_Cobble_Wall_State_Definitions_Corner"
    },
    {
      "x": -13,
      "y": 5,
      "z": 8,
      "name": "*Rock_Stone_Cobble_Wall_State_Definitions_Corner"
    },
    {
      "x": -13,
      "y": 6,
      "z": 8,
      "name": "*Rock_Stone_Cobble_Wall_State_Definitions_Corner"
    },
    {
      "x": -13,
      "y": 7,
      "z": 8,
      "name": "Rock_Marble_Brick_Half"
    },
    {
      "x": -13,
      "y": 0,
      "z": 9,
      "name": "Soil_Grass"
    },
    {
      "x": -13,
      "y": 1,
      "z": 9,
      "name": "Rock_Stone_Cobble_Wall",
      "rotation": 1
    },
    {
      "x": -13,
      "y": 2,
      "z": 9,
      "name": "Rock_Stone_Cobble_Wall",
      "rotation": 1
    },
    {
      "x": -13,
      "y": 3,
      "z": 9,
      "name": "Rock_Stone_Cobble_Wall",
      "rotation": 1
    },
    {
      "x": -13,
      "y": 4,
      "z": 9,
      "name": "Rock_Stone_Cobble_Wall",
      "rotation": 1
    },
    {
      "x": -13,
      "y": 5,
      "z": 9,
      "name": "Rock_Stone_Cobble_Wall",
      "rotation": 1
    },
    {
      "x": -13,
      "y": 6,
      "z": 9,
      "name": "Rock_Stone_Cobble_Wall",
      "rotation": 1
    },
    {
      "x": -13,
      "y": 7,
      "z": 9,
      "name": "Rock_Marble_Brick_Half"
    },
    {
      "x": -13,
      "y": 0,
      "z": 10,
      "name": "Soil_Grass"
    },
    {
      "x": -13,
      "y": 1,
      "z": 10,
      "name": "Rock_Stone_Cobble_Wall",
      "rotation": 1
    },
    {
      "x": -13,
      "y": 2,
      "z": 10,
      "name": "Rock_Stone_Cobble_Wall",
      "rotation": 1
    },
    {
      "x": -13,
      "y": 3,
      "z": 10,
      "name": "Rock_Stone_Cobble_Wall",
      "rotation": 1
    },
    {
      "x": -13,
      "y": 4,
      "z": 10,
      "name": "Rock_Stone_Cobble_Wall",
      "rotation": 1
    },
    {
      "x": -13,
      "y": 5,
      "z": 10,
      "name": "Rock_Stone_Cobble_Wall",
      "rotation": 1
    },
    {
      "x": -13,
      "y": 6,
      "z": 10,
      "name": "Rock_Stone_Cobble_Wall",
      "rotation": 1
    },
    {
      "x": -13,
      "y": 7,
      "z": 10,
      "name": "Rock_Marble_Brick_Half"
    },
    {
      "x": -13,
      "y": 0,
      "z": 11,
      "name": "Soil_Grass"
    },
    {
      "x": -13,
      "y": 1,
      "z": 11,
      "name": "*Rock_Stone_Cobble_Wall_State_Definitions_Corner",
      "rotation": 2
    },
    {
      "x": -13,
      "y": 2,
      "z": 11,
      "name": "*Rock_Stone_Cobble_Wall_State_Definitions_Corner",
      "rotation": 2
    },
    {
      "x": -13,
      "y": 3,
      "z": 11,
      "name": "*Rock_Stone_Cobble_Wall_State_Definitions_Corner",
      "rotation": 2
    },
    {
      "x": -13,
      "y": 4,
      "z": 11,
      "name": "*Rock_Stone_Cobble_Wall_State_Definitions_Corner",
      "rotation": 2
    },
    {
      "x": -13,
      "y": 5,
      "z": 11,
      "name": "*Rock_Stone_Cobble_Wall_State_Definitions_Corner",
      "rotation": 2
    },
    {
      "x": -13,
      "y": 6,
      "z": 11,
      "name": "*Rock_Stone_Cobble_Wall_State_Definitions_Corner",
      "rotation": 2
    },
    {
      "x": -13,
      "y": 7,
      "z": 11,
      "name": "Rock_Marble_Brick_Half"
    },
    {
      "x": -13,
      "y": 5,
      "z": 12,
      "name": "Plant_Vine_Wall",
      "support": 15,
      "rotation": 3
    },
    {
      "x": -13,
      "y": 6,
      "z": 12,
      "name": "Plant_Vine_Wall",
      "support": 15,
      "rotation": 3
    },
    {
      "x": -12,
      "y": 0,
      "z": -12,
      "name": "Soil_Dirt"
    },
    {
      "x": -12,
      "y": 1,
      "z": -12,
      "name": "Rock_Marble_Brick",
      "rotation": 3
    },
    {
      "x": -12,
      "y": 2,
      "z": -12,
      "name": "Rock_Marble_Brick",
      "rotation": 3
    },
    {
      "x": -12,
      "y": 3,
      "z": -12,
      "name": "Rock_Marble_Brick",
      "rotation": 3
    },
    {
      "x": -12,
      "y": 4,
      "z": -12,
      "name": "Rock_Marble_Brick",
      "rotation": 3
    },
    {
      "x": -12,
      "y": 5,
      "z": -12,
      "name": "Rock_Marble_Brick",
      "rotation": 3
    },
    {
      "x": -12,
      "y": 6,
      "z": -12,
      "name": "Rock_Marble_Brick",
      "rotation": 3
    },
    {
      "x": -12,
      "y": 7,
      "z": -12,
      "name": "Rock_Marble_Brick_Half"
    },
    {
      "x": -12,
      "y": 0,
      "z": -11,
      "name": "Soil_Grass"
    },
    {
      "x": -12,
      "y": 1,
      "z": -11,
      "name": "Rock_Stone_Cobble_Wall"
    },
    {
      "x": -12,
      "y": 2,
      "z": -11,
      "name": "Rock_Stone_Cobble_Wall"
    },
    {
      "x": -12,
      "y": 3,
      "z": -11,
      "name": "Rock_Stone_Cobble_Wall"
    },
    {
      "x": -12,
      "y": 4,
      "z": -11,
      "name": "Rock_Stone_Cobble_Wall"
    },
    {
      "x": -12,
      "y": 5,
      "z": -11,
      "name": "Rock_Stone_Cobble_Wall"
    },
    {
      "x": -12,
      "y": 6,
      "z": -11,
      "name": "Rock_Stone_Cobble_Wall"
    },
    {
      "x": -12,
      "y": 7,
      "z": -11,
      "name": "Rock_Marble_Brick_Half"
    },
    {
      "x": -12,
      "y": 0,
      "z": -10,
      "name": "Soil_Grass"
    },
    {
      "x": -12,
      "y": 0,
      "z": -9,
      "name": "Soil_Grass"
    },
    {
      "x": -12,
      "y": 1,
      "z": -9,
      "name": "Plant_Grass_Jungle_Tall",
      "support": 15
    },
    {
      "x": -12,
      "y": 0,
      "z": -8,
      "name": "Soil_Grass"
    },
    {
      "x": -12,
      "y": 1,
      "z": -8,
      "name": "Plant_Grass_Jungle",
      "support": 15
    },
    {
      "x": -12,
      "y": 0,
      "z": -7,
      "name": "Soil_Grass"
    },
    {
      "x": -12,
      "y": 1,
      "z": -7,
      "name": "Plant_Grass_Jungle",
      "support": 15
    },
    {
      "x": -12,
      "y": 0,
      "z": -6,
      "name": "Soil_Grass"
    },
    {
      "x": -12,
      "y": 1,
      "z": -6,
      "name": "Plant_Grass_Jungle_Tall",
      "support": 15
    },
    {
      "x": -12,
      "y": 0,
      "z": -5,
      "name": "Soil_Grass"
    },
    {
      "x": -12,
      "y": 1,
      "z": -5,
      "name": "Plant_Grass_Jungle_Tall",
      "support": 15
    },
    {
      "x": -12,
      "y": 0,
      "z": -4,
      "name": "Soil_Grass"
    },
    {
      "x": -12,
      "y": 1,
      "z": -4,
      "name": "Plant_Grass_Jungle",
      "support": 15
    },
    {
      "x": -12,
      "y": 0,
      "z": -3,
      "name": "Soil_Grass"
    },
    {
      "x": -12,
      "y": 1,
      "z": -3,
      "name": "Plant_Grass_Jungle_Tall",
      "support": 15
    },
    {
      "x": -12,
      "y": 0,
      "z": -2,
      "name": "Soil_Grass"
    },
    {
      "x": -12,
      "y": 1,
      "z": -2,
      "name": "Plant_Grass_Jungle",
      "support": 15
    },
    {
      "x": -12,
      "y": 0,
      "z": -1,
      "name": "Soil_Gravel",
      "support": 15
    },
    {
      "x": -12,
      "y": 0,
      "z": 0,
      "name": "Soil_Gravel",
      "support": 15
    },
    {
      "x": -12,
      "y": 0,
      "z": 1,
      "name": "Soil_Gravel",
      "support": 15
    },
    {
      "x": -12,
      "y": 0,
      "z": 2,
      "name": "Soil_Grass"
    },
    {
      "x": -12,
      "y": 0,
      "z": 3,
      "name": "Soil_Grass"
    },
    {
      "x": -12,
      "y": 1,
      "z": 3,
      "name": "Plant_Grass_Jungle_Tall",
      "support": 15
    },
    {
      "x": -12,
      "y": 0,
      "z": 4,
      "name": "Soil_Grass"
    },
    {
      "x": -12,
      "y": 1,
      "z": 4,
      "name": "Plant_Grass_Jungle_Tall",
      "support": 15
    },
    {
      "x": -12,
      "y": 0,
      "z": 5,
      "name": "Soil_Grass"
    },
    {
      "x": -12,
      "y": 1,
      "z": 5,
      "name": "Plant_Grass_Jungle_Tall",
      "support": 15
    },
    {
      "x": -12,
      "y": 0,
      "z": 6,
      "name": "Soil_Grass"
    },
    {
      "x": -12,
      "y": 1,
      "z": 6,
      "name": "Plant_Grass_Jungle",
      "support": 15
    },
    {
      "x": -12,
      "y": 0,
      "z": 7,
      "name": "Soil_Grass"
    },
    {
      "x": -12,
      "y": 1,
      "z": 7,
      "name": "Plant_Grass_Jungle",
      "support": 15
    },
    {
      "x": -12,
      "y": 0,
      "z": 8,
      "name": "Soil_Grass"
    },
    {
      "x": -12,
      "y": 0,
      "z": 9,
      "name": "Soil_Grass"
    },
    {
      "x": -12,
      "y": 1,
      "z": 9,
      "name": "Plant_Grass_Jungle_Tall",
      "support": 15
    },
    {
      "x": -12,
      "y": 0,
      "z": 10,
      "name": "Soil_Grass"
    },
    {
      "x": -12,
      "y": 1,
      "z": 10,
      "name": "Plant_Grass_Jungle",
      "support": 15
    },
    {
      "x": -12,
      "y": 0,
      "z": 11,
      "name": "Soil_Grass"
    },
    {
      "x": -12,
      "y": 1,
      "z": 11,
      "name": "Rock_Stone_Cobble_Wall"
    },
    {
      "x": -12,
      "y": 2,
      "z": 11,
      "name": "Rock_Stone_Cobble_Wall"
    },
    {
      "x": -12,
      "y": 3,
      "z": 11,
      "name": "Rock_Stone_Cobble_Wall"
    },
    {
      "x": -12,
      "y": 4,
      "z": 11,
      "name": "Rock_Stone_Cobble_Wall"
    },
    {
      "x": -12,
      "y": 5,
      "z": 11,
      "name": "Rock_Stone_Cobble_Wall"
    },
    {
      "x": -12,
      "y": 6,
      "z": 11,
      "name": "Rock_Stone_Cobble_Wall"
    },
    {
      "x": -12,
      "y": 7,
      "z": 11,
      "name": "Rock_Marble_Brick_Half"
    },
    {
      "x": -12,
      "y": 0,
      "z": 12,
      "name": "Soil_Dirt"
    },
    {
      "x": -12,
      "y": 1,
      "z": 12,
      "name": "Rock_Marble_Brick"
    },
    {
      "x": -12,
      "y": 2,
      "z": 12,
      "name": "Rock_Marble_Brick"
    },
    {
      "x": -12,
      "y": 3,
      "z": 12,
      "name": "Rock_Marble_Brick"
    },
    {
      "x": -12,
      "y": 4,
      "z": 12,
      "name": "Rock_Marble_Brick"
    },
    {
      "x": -12,
      "y": 5,
      "z": 12,
      "name": "Rock_Marble_Brick"
    },
    {
      "x": -12,
      "y": 6,
      "z": 12,
      "name": "Rock_Marble_Brick"
    },
    {
      "x": -12,
      "y": 7,
      "z": 12,
      "name": "Rock_Marble_Brick_Half"
    },
    {
      "x": -12,
      "y": 6,
      "z": 13,
      "name": "Plant_Vine_Wall",
      "support": 15
    },
    {
      "x": -11,
      "y": 0,
      "z": -13,
      "name": "Soil_Grass"
    },
    {
      "x": -11,
      "y": 1,
      "z": -13,
      "name": "*Rock_Stone_Cobble_Wall_State_Definitions_Corner",
      "rotation": 1
    },
    {
      "x": -11,
      "y": 2,
      "z": -13,
      "name": "*Rock_Stone_Cobble_Wall_State_Definitions_Corner",
      "rotation": 1
    },
    {
      "x": -11,
      "y": 3,
      "z": -13,
      "name": "*Rock_Stone_Cobble_Wall_State_Definitions_Corner",
      "rotation": 1
    },
    {
      "x": -11,
      "y": 4,
      "z": -13,
      "name": "*Rock_Stone_Cobble_Wall_State_Definitions_Corner",
      "rotation": 1
    },
    {
      "x": -11,
      "y": 5,
      "z": -13,
      "name": "*Rock_Stone_Cobble_Wall_State_Definitions_Corner",
      "rotation": 1
    },
    {
      "x": -11,
      "y": 6,
      "z": -13,
      "name": "*Rock_Stone_Cobble_Wall_State_Definitions_Corner",
      "rotation": 1
    },
    {
      "x": -11,
      "y": 7,
      "z": -13,
      "name": "Rock_Marble_Brick_Half"
    },
    {
      "x": -11,
      "y": 0,
      "z": -12,
      "name": "Soil_Grass"
    },
    {
      "x": -11,
      "y": 1,
      "z": -12,
      "name": "Rock_Stone_Cobble_Wall",
      "rotation": 3
    },
    {
      "x": -11,
      "y": 2,
      "z": -12,
      "name": "Rock_Stone_Cobble_Wall",
      "rotation": 3
    },
    {
      "x": -11,
      "y": 3,
      "z": -12,
      "name": "Rock_Stone_Cobble_Wall",
      "rotation": 3
    },
    {
      "x": -11,
      "y": 4,
      "z": -12,
      "name": "Rock_Stone_Cobble_Wall",
      "rotation": 3
    },
    {
      "x": -11,
      "y": 5,
      "z": -12,
      "name": "Rock_Stone_Cobble_Wall",
      "rotation": 3
    },
    {
      "x": -11,
      "y": 6,
      "z": -12,
      "name": "Rock_Stone_Cobble_Wall",
      "rotation": 3
    },
    {
      "x": -11,
      "y": 7,
      "z": -12,
      "name": "Rock_Marble_Brick_Half"
    },
    {
      "x": -11,
      "y": 0,
      "z": -11,
      "name": "Soil_Dirt"
    },
    {
      "x": -11,
      "y": 1,
      "z": -11,
      "name": "Rock_Marble_Brick",
      "rotation": 3
    },
    {
      "x": -11,
      "y": 2,
      "z": -11,
      "name": "Rock_Marble_Brick",
      "rotation": 3
    },
    {
      "x": -11,
      "y": 3,
      "z": -11,
      "name": "Rock_Marble_Brick",
      "rotation": 3
    },
    {
      "x": -11,
      "y": 4,
      "z": -11,
      "name": "Rock_Marble_Brick",
      "rotation": 3
    },
    {
      "x": -11,
      "y": 5,
      "z": -11,
      "name": "Rock_Marble_Brick",
      "rotation": 3
    },
    {
      "x": -11,
      "y": 6,
      "z": -11,
      "name": "Rock_Marble_Brick",
      "rotation": 3
    },
    {
      "x": -11,
      "y": 7,
      "z": -11,
      "name": "Rock_Marble_Brick_Half"
    },
    {
      "x": -11,
      "y": 0,
      "z": -10,
      "name": "Soil_Grass"
    },
    {
      "x": -11,
      "y": 1,
      "z": -10,
      "name": "Plant_Grass_Jungle",
      "support": 15
    },
    {
      "x": -11,
      "y": 0,
      "z": -9,
      "name": "Soil_Grass"
    },
    {
      "x": -11,
      "y": 1,
      "z": -9,
      "name": "Plant_Grass_Jungle",
      "support": 15
    },
    {
      "x": -11,
      "y": 0,
      "z": -8,
      "name": "Soil_Grass"
    },
    {
      "x": -11,
      "y": 1,
      "z": -8,
      "name": "Plant_Grass_Jungle_Tall",
      "support": 15
    },
    {
      "x": -11,
      "y": 0,
      "z": -7,
      "name": "Soil_Grass"
    },
    {
      "x": -11,
      "y": 1,
      "z": -7,
      "name": "Plant_Grass_Jungle",
      "support": 15
    },
    {
      "x": -11,
      "y": 0,
      "z": -6,
      "name": "Soil_Grass"
    },
    {
      "x": -11,
      "y": 1,
      "z": -6,
      "name": "Plant_Grass_Jungle",
      "support": 15
    },
    {
      "x": -11,
      "y": 0,
      "z": -5,
      "name": "Soil_Grass"
    },
    {
      "x": -11,
      "y": 0,
      "z": -4,
      "name": "Soil_Grass"
    },
    {
      "x": -11,
      "y": 1,
      "z": -4,
      "name": "Plant_Grass_Jungle",
      "support": 15
    },
    {
      "x": -11,
      "y": 0,
      "z": -3,
      "name": "Soil_Grass"
    },
    {
      "x": -11,
      "y": 1,
      "z": -3,
      "name": "Rock_Marble_Brick_Pillar_Base",
      "rotation": 3
    },
    {
      "x": -11,
      "y": 2,
      "z": -3,
      "name": "Rock_Marble_Brick_Pillar_Middle",
      "rotation": 3
    },
    {
      "x": -11,
      "y": 3,
      "z": -3,
      "name": "Rock_Marble_Brick_Pillar_Middle",
      "rotation": 3
    },
    {
      "x": -11,
      "y": 4,
      "z": -3,
      "name": "Rubble_Marble_Medium",
      "support": 15
    },
    {
      "x": -11,
      "y": 0,
      "z": -2,
      "name": "Soil_Grass"
    },
    {
      "x": -11,
      "y": 1,
      "z": -2,
      "name": "Plant_Grass_Jungle",
      "support": 15
    },
    {
      "x": -11,
      "y": 0,
      "z": -1,
      "name": "Soil_Gravel",
      "support": 15
    },
    {
      "x": -11,
      "y": 0,
      "z": 0,
      "name": "Soil_Gravel",
      "support": 15
    },
    {
      "x": -11,
      "y": 0,
      "z": 1,
      "name": "Soil_Gravel",
      "support": 15
    },
    {
      "x": -11,
      "y": 0,
      "z": 2,
      "name": "Soil_Grass"
    },
    {
      "x": -11,
      "y": 7,
      "z": 2,
      "name": "Plant_Vine_Wall",
      "support": 15,
      "rotation": 2
    },
    {
      "x": -11,
      "y": 8,
      "z": 2,
      "name": "Plant_Vine",
      "support": 15,
      "rotation": 2
    },
    {
      "x": -11,
      "y": 9,
      "z": 2,
      "name": "Rock_Marble_Brick_Half",
      "rotation": 33
    },
    {
      "x": -11,
      "y": 10,
      "z": 2,
      "name": "Rock_Marble_Brick_Half",
      "rotation": 3
    },
    {
      "x": -11,
      "y": 0,
      "z": 3,
      "name": "Soil_Grass"
    },
    {
      "x": -11,
      "y": 1,
      "z": 3,
      "name": "Rock_Marble_Brick_Pillar_Base",
      "rotation": 3
    },
    {
      "x": -11,
      "y": 2,
      "z": 3,
      "name": "Rock_Marble_Brick_Pillar_Middle",
      "rotation": 3
    },
    {
      "x": -11,
      "y": 3,
      "z": 3,
      "name": "Rock_Marble_Brick_Pillar_Middle",
      "rotation": 3
    },
    {
      "x": -11,
      "y": 4,
      "z": 3,
      "name": "Rock_Marble_Brick_Pillar_Middle",
      "rotation": 3
    },
    {
      "x": -11,
      "y": 5,
      "z": 3,
      "name": "Rock_Marble_Brick_Pillar_Middle",
      "rotation": 3
    },
    {
      "x": -11,
      "y": 6,
      "z": 3,
      "name": "Rock_Marble_Brick_Pillar_Middle",
      "rotation": 3
    },
    {
      "x": -11,
      "y": 7,
      "z": 3,
      "name": "Rock_Marble_Brick_Pillar_Base",
      "rotation": 33
    },
    {
      "x": -11,
      "y": 8,
      "z": 3,
      "name": "Rock_Marble_Brick",
      "rotation": 3
    },
    {
      "x": -11,
      "y": 9,
      "z": 3,
      "name": "Rock_Marble_Brick_Stairs"
    },
    {
      "x": -11,
      "y": 0,
      "z": 4,
      "name": "Soil_Grass"
    },
    {
      "x": -11,
      "y": 1,
      "z": 4,
      "name": "Plant_Grass_Jungle",
      "support": 15
    },
    {
      "x": -11,
      "y": 0,
      "z": 5,
      "name": "Soil_Grass"
    },
    {
      "x": -11,
      "y": 1,
      "z": 5,
      "name": "Plant_Grass_Jungle",
      "support": 15
    },
    {
      "x": -11,
      "y": 0,
      "z": 6,
      "name": "Soil_Grass"
    },
    {
      "x": -11,
      "y": 0,
      "z": 7,
      "name": "Soil_Grass"
    },
    {
      "x": -11,
      "y": 1,
      "z": 7,
      "name": "Plant_Grass_Jungle_Tall",
      "support": 15
    },
    {
      "x": -11,
      "y": 0,
      "z": 8,
      "name": "Soil_Grass"
    },
    {
      "x": -11,
      "y": 1,
      "z": 8,
      "name": "Plant_Grass_Jungle",
      "support": 15
    },
    {
      "x": -11,
      "y": 0,
      "z": 9,
      "name": "Soil_Grass"
    },
    {
      "x": -11,
      "y": 1,
      "z": 9,
      "name": "Plant_Grass_Jungle_Tall",
      "support": 15
    },
    {
      "x": -11,
      "y": 0,
      "z": 10,
      "name": "Soil_Grass"
    },
    {
      "x": -11,
      "y": 1,
      "z": 10,
      "name": "Plant_Grass_Jungle_Tall",
      "support": 15
    },
    {
      "x": -11,
      "y": 5,
      "z": 10,
      "name": "Plant_Vine_Wall",
      "support": 15,
      "rotation": 2
    },
    {
      "x": -11,
      "y": 6,
      "z": 10,
      "name": "Plant_Vine_Wall",
      "support": 15,
      "rotation": 2
    },
    {
      "x": -11,
      "y": 0,
      "z": 11,
      "name": "Soil_Dirt"
    },
    {
      "x": -11,
      "y": 1,
      "z": 11,
      "name": "Rock_Marble_Brick"
    },
    {
      "x": -11,
      "y": 2,
      "z": 11,
      "name": "Rock_Marble_Brick"
    },
    {
      "x": -11,
      "y": 3,
      "z": 11,
      "name": "Rock_Marble_Brick"
    },
    {
      "x": -11,
      "y": 4,
      "z": 11,
      "name": "Rock_Marble_Brick"
    },
    {
      "x": -11,
      "y": 5,
      "z": 11,
      "name": "Rock_Marble_Brick"
    },
    {
      "x": -11,
      "y": 6,
      "z": 11,
      "name": "Rock_Marble_Brick"
    },
    {
      "x": -11,
      "y": 7,
      "z": 11,
      "name": "Rock_Marble_Brick_Half"
    },
    {
      "x": -11,
      "y": 0,
      "z": 12,
      "name": "Soil_Grass"
    },
    {
      "x": -11,
      "y": 1,
      "z": 12,
      "name": "Rock_Stone_Cobble_Wall",
      "rotation": 1
    },
    {
      "x": -11,
      "y": 2,
      "z": 12,
      "name": "Rock_Stone_Cobble_Wall",
      "rotation": 1
    },
    {
      "x": -11,
      "y": 3,
      "z": 12,
      "name": "Rock_Stone_Cobble_Wall",
      "rotation": 1
    },
    {
      "x": -11,
      "y": 4,
      "z": 12,
      "name": "Rock_Stone_Cobble_Wall",
      "rotation": 1
    },
    {
      "x": -11,
      "y": 5,
      "z": 12,
      "name": "Rock_Stone_Cobble_Wall",
      "rotation": 1
    },
    {
      "x": -11,
      "y": 6,
      "z": 12,
      "name": "Rock_Stone_Cobble_Wall",
      "rotation": 1
    },
    {
      "x": -11,
      "y": 7,
      "z": 12,
      "name": "Rock_Marble_Brick_Half"
    },
    {
      "x": -11,
      "y": 0,
      "z": 13,
      "name": "Soil_Grass"
    },
    {
      "x": -11,
      "y": 1,
      "z": 13,
      "name": "*Rock_Stone_Cobble_Wall_State_Definitions_Corner",
      "rotation": 2
    },
    {
      "x": -11,
      "y": 2,
      "z": 13,
      "name": "*Rock_Stone_Cobble_Wall_State_Definitions_Corner",
      "rotation": 2
    },
    {
      "x": -11,
      "y": 3,
      "z": 13,
      "name": "*Rock_Stone_Cobble_Wall_State_Definitions_Corner",
      "rotation": 2
    },
    {
      "x": -11,
      "y": 4,
      "z": 13,
      "name": "*Rock_Stone_Cobble_Wall_State_Definitions_Corner",
      "rotation": 2
    },
    {
      "x": -11,
      "y": 5,
      "z": 13,
      "name": "*Rock_Stone_Cobble_Wall_State_Definitions_Corner",
      "rotation": 2
    },
    {
      "x": -11,
      "y": 6,
      "z": 13,
      "name": "*Rock_Stone_Cobble_Wall_State_Definitions_Corner",
      "rotation": 2
    },
    {
      "x": -11,
      "y": 7,
      "z": 13,
      "name": "Rock_Marble_Brick_Half"
    },
    {
      "x": -10,
      "y": 0,
      "z": -13,
      "name": "Soil_Grass"
    },
    {
      "x": -10,
      "y": 1,
      "z": -13,
      "name": "Rock_Stone_Cobble_Wall"
    },
    {
      "x": -10,
      "y": 2,
      "z": -13,
      "name": "Rock_Stone_Cobble_Wall"
    },
    {
      "x": -10,
      "y": 3,
      "z": -13,
      "name": "Rock_Stone_Cobble_Wall"
    },
    {
      "x": -10,
      "y": 4,
      "z": -13,
      "name": "Rock_Stone_Cobble_Wall"
    },
    {
      "x": -10,
      "y": 5,
      "z": -13,
      "name": "Rock_Stone_Cobble_Wall"
    },
    {
      "x": -10,
      "y": 6,
      "z": -13,
      "name": "Rock_Stone_Cobble_Wall"
    },
    {
      "x": -10,
      "y": 7,
      "z": -13,
      "name": "Rock_Marble_Brick_Half"
    },
    {
      "x": -10,
      "y": 0,
      "z": -12,
      "name": "Soil_Grass"
    },
    {
      "x": -10,
      "y": 1,
      "z": -12,
      "name": "Plant_Grass_Jungle",
      "support": 15
    },
    {
      "x": -10,
      "y": 0,
      "z": -11,
      "name": "Soil_Grass"
    },
    {
      "x": -10,
      "y": 1,
      "z": -11,
      "name": "Plant_Grass_Jungle",
      "support": 15
    },
    {
      "x": -10,
      "y": 0,
      "z": -10,
      "name": "Soil_Grass"
    },
    {
      "x": -10,
      "y": 1,
      "z": -10,
      "name": "Plant_Grass_Jungle_Tall",
      "support": 15
    },
    {
      "x": -10,
      "y": 0,
      "z": -9,
      "name": "Soil_Grass"
    },
    {
      "x": -10,
      "y": 1,
      "z": -9,
      "name": "Plant_Grass_Jungle_Tall",
      "support": 15
    },
    {
      "x": -10,
      "y": 0,
      "z": -8,
      "name": "Soil_Grass"
    },
    {
      "x": -10,
      "y": 1,
      "z": -8,
      "name": "Plant_Grass_Jungle",
      "support": 15
    },
    {
      "x": -10,
      "y": 0,
      "z": -7,
      "name": "Soil_Grass"
    },
    {
      "x": -10,
      "y": 0,
      "z": -6,
      "name": "Soil_Grass"
    },
    {
      "x": -10,
      "y": 1,
      "z": -6,
      "name": "Plant_Leaves_Wisteria_Wild",
      "support": 15
    },
    {
      "x": -10,
      "y": 2,
      "z": -6,
      "name": "Plant_Leaves_Wisteria_Wild",
      "support": 15
    },
    {
      "x": -10,
      "y": 0,
      "z": -5,
      "name": "Soil_Grass"
    },
    {
      "x": -10,
      "y": 1,
      "z": -5,
      "name": "Plant_Leaves_Wisteria_Wild",
      "support": 15
    },
    {
      "x": -10,
      "y": 2,
      "z": -5,
      "name": "Plant_Leaves_Wisteria_Wild",
      "support": 15
    },
    {
      "x": -10,
      "y": 0,
      "z": -4,
      "name": "Soil_Grass"
    },
    {
      "x": -10,
      "y": 0,
      "z": -3,
      "name": "Soil_Grass"
    },
    {
      "x": -10,
      "y": 1,
      "z": -3,
      "name": "Rubble_Marble_Medium",
      "support": 15
    },
    {
      "x": -10,
      "y": 0,
      "z": -2,
      "name": "Soil_Grass"
    },
    {
      "x": -10,
      "y": 1,
      "z": -2,
      "name": "Plant_Grass_Jungle_Tall",
      "support": 15
    },
    {
      "x": -10,
      "y": 0,
      "z": -1,
      "name": "Soil_Gravel",
      "support": 15
    },
    {
      "x": -10,
      "y": 0,
      "z": 0,
      "name": "Soil_Gravel_Mossy",
      "support": 15
    },
    {
      "x": -10,
      "y": 0,
      "z": 1,
      "name": "Soil_Gravel",
      "support": 15
    },
    {
      "x": -10,
      "y": 0,
      "z": 2,
      "name": "Soil_Grass"
    },
    {
      "x": -10,
      "y": 1,
      "z": 2,
      "name": "Plant_Grass_Jungle",
      "support": 15
    },
    {
      "x": -10,
      "y": 0,
      "z": 3,
      "name": "Soil_Grass"
    },
    {
      "x": -10,
      "y": 1,
      "z": 3,
      "name": "Plant_Grass_Jungle_Tall",
      "support": 15
    },
    {
      "x": -10,
      "y": 4,
      "z": 3,
      "name": "Plant_Vine_Wall",
      "support": 15,
      "rotation": 1
    },
    {
      "x": -10,
      "y": 5,
      "z": 3,
      "name": "Plant_Vine_Wall",
      "support": 15,
      "rotation": 1
    },
    {
      "x": -10,
      "y": 6,
      "z": 3,
      "name": "Plant_Vine_Wall",
      "support": 15,
      "rotation": 1
    },
    {
      "x": -10,
      "y": 7,
      "z": 3,
      "name": "Plant_Vine_Wall",
      "support": 15,
      "rotation": 1
    },
    {
      "x": -10,
      "y": 8,
      "z": 3,
      "name": "Plant_Vine",
      "support": 15,
      "rotation": 1
    },
    {
      "x": -10,
      "y": 0,
      "z": 4,
      "name": "Soil_Grass"
    },
    {
      "x": -10,
      "y": 1,
      "z": 4,
      "name": "Plant_Leaves_Wisteria_Wild",
      "support": 15,
      "rotation": 1
    },
    {
      "x": -10,
      "y": 2,
      "z": 4,
      "name": "Plant_Leaves_Wisteria_Wild",
      "support": 15,
      "rotation": 1
    },
    {
      "x": -10,
      "y": 0,
      "z": 5,
      "name": "Soil_Grass"
    },
    {
      "x": -10,
      "y": 1,
      "z": 5,
      "name": "Plant_Leaves_Wisteria_Wild",
      "support": 15,
      "rotation": 1
    },
    {
      "x": -10,
      "y": 2,
      "z": 5,
      "name": "Plant_Leaves_Wisteria_Wild",
      "support": 15,
      "rotation": 1
    },
    {
      "x": -10,
      "y": 0,
      "z": 6,
      "name": "Soil_Grass"
    },
    {
      "x": -10,
      "y": 1,
      "z": 6,
      "name": "Plant_Leaves_Wisteria_Wild",
      "support": 15,
      "rotation": 1
    },
    {
      "x": -10,
      "y": 2,
      "z": 6,
      "name": "Plant_Leaves_Wisteria_Wild",
      "support": 15,
      "rotation": 1
    },
    {
      "x": -10,
      "y": 0,
      "z": 7,
      "name": "Soil_Grass"
    },
    {
      "x": -10,
      "y": 1,
      "z": 7,
      "name": "Plant_Grass_Jungle",
      "support": 15
    },
    {
      "x": -10,
      "y": 0,
      "z": 8,
      "name": "Soil_Grass"
    },
    {
      "x": -10,
      "y": 0,
      "z": 9,
      "name": "Soil_Grass"
    },
    {
      "x": -10,
      "y": 1,
      "z": 9,
      "name": "Plant_Grass_Jungle",
      "support": 15
    },
    {
      "x": -10,
      "y": 0,
      "z": 10,
      "name": "Soil_Grass"
    },
    {
      "x": -10,
      "y": 0,
      "z": 11,
      "name": "Soil_Grass"
    },
    {
      "x": -10,
      "y": 1,
      "z": 11,
      "name": "Plant_Grass_Jungle",
      "support": 15
    },
    {
      "x": -10,
      "y": 6,
      "z": 11,
      "name": "Plant_Vine_Wall",
      "support": 15,
      "rotation": 1
    },
    {
      "x": -10,
      "y": 0,
      "z": 12,
      "name": "Soil_Grass"
    },
    {
      "x": -10,
      "y": 1,
      "z": 12,
      "name": "Plant_Grass_Jungle_Tall",
      "support": 15
    },
    {
      "x": -10,
      "y": 0,
      "z": 13,
      "name": "Soil_Grass"
    },
    {
      "x": -10,
      "y": 1,
      "z": 13,
      "name": "Rock_Stone_Cobble_Wall"
    },
    {
      "x": -10,
      "y": 2,
      "z": 13,
      "name": "Rock_Stone_Cobble_Wall"
    },
    {
      "x": -10,
      "y": 3,
      "z": 13,
      "name": "Rock_Stone_Cobble_Wall"
    },
    {
      "x": -10,
      "y": 4,
      "z": 13,
      "name": "Rock_Stone_Cobble_Wall"
    },
    {
      "x": -10,
      "y": 5,
      "z": 13,
      "name": "Rock_Stone_Cobble_Wall"
    },
    {
      "x": -10,
      "y": 6,
      "z": 13,
      "name": "Rock_Stone_Cobble_Wall"
    },
    {
      "x": -10,
      "y": 7,
      "z": 13,
      "name": "Rock_Marble_Brick_Half"
    },
    {
      "x": -9,
      "y": 0,
      "z": -13,
      "name": "Soil_Grass"
    },
    {
      "x": -9,
      "y": 1,
      "z": -13,
      "name": "Rock_Stone_Cobble_Wall"
    },
    {
      "x": -9,
      "y": 2,
      "z": -13,
      "name": "Rock_Stone_Cobble_Wall"
    },
    {
      "x": -9,
      "y": 3,
      "z": -13,
      "name": "Rock_Stone_Cobble_Wall"
    },
    {
      "x": -9,
      "y": 4,
      "z": -13,
      "name": "Rock_Stone_Cobble_Wall"
    },
    {
      "x": -9,
      "y": 5,
      "z": -13,
      "name": "Rock_Stone_Cobble_Wall"
    },
    {
      "x": -9,
      "y": 6,
      "z": -13,
      "name": "Rock_Stone_Cobble_Wall"
    },
    {
      "x": -9,
      "y": 7,
      "z": -13,
      "name": "Rock_Marble_Brick_Half"
    },
    {
      "x": -9,
      "y": 0,
      "z": -12,
      "name": "Soil_Grass"
    },
    {
      "x": -9,
      "y": 1,
      "z": -12,
      "name": "Plant_Grass_Jungle_Tall",
      "support": 15
    },
    {
      "x": -9,
      "y": 0,
      "z": -11,
      "name": "Soil_Grass"
    },
    {
      "x": -9,
      "y": 1,
      "z": -11,
      "name": "Plant_Grass_Jungle_Tall",
      "support": 15
    },
    {
      "x": -9,
      "y": 0,
      "z": -10,
      "name": "Soil_Grass"
    },
    {
      "x": -9,
      "y": 1,
      "z": -10,
      "name": "Plant_Grass_Jungle_Tall",
      "support": 15
    },
    {
      "x": -9,
      "y": 0,
      "z": -9,
      "name": "Soil_Grass"
    },
    {
      "x": -9,
      "y": 0,
      "z": -8,
      "name": "Soil_Grass"
    },
    {
      "x": -9,
      "y": 1,
      "z": -8,
      "name": "Plant_Leaves_Wisteria_Wild",
      "support": 15
    },
    {
      "x": -9,
      "y": 2,
      "z": -8,
      "name": "Plant_Leaves_Wisteria_Wild",
      "support": 15
    },
    {
      "x": -9,
      "y": 0,
      "z": -7,
      "name": "Soil_Grass"
    },
    {
      "x": -9,
      "y": 1,
      "z": -7,
      "name": "Plant_Leaves_Wisteria_Wild",
      "support": 15
    },
    {
      "x": -9,
      "y": 2,
      "z": -7,
      "name": "Plant_Leaves_Wisteria_Wild",
      "support": 15
    },
    {
      "x": -9,
      "y": 0,
      "z": -6,
      "name": "Soil_Grass"
    },
    {
      "x": -9,
      "y": 1,
      "z": -6,
      "name": "Plant_Leaves_Wisteria_Wild",
      "support": 15
    },
    {
      "x": -9,
      "y": 2,
      "z": -6,
      "name": "Plant_Leaves_Wisteria_Wild",
      "support": 15
    },
    {
      "x": -9,
      "y": 0,
      "z": -5,
      "name": "Soil_Grass"
    },
    {
      "x": -9,
      "y": 1,
      "z": -5,
      "name": "Plant_Grass_Jungle",
      "support": 15
    },
    {
      "x": -9,
      "y": 0,
      "z": -4,
      "name": "Soil_Grass"
    },
    {
      "x": -9,
      "y": 1,
      "z": -4,
      "name": "Plant_Grass_Jungle",
      "support": 15
    },
    {
      "x": -9,
      "y": 0,
      "z": -3,
      "name": "Soil_Grass"
    },
    {
      "x": -9,
      "y": 1,
      "z": -3,
      "name": "Rock_Marble_Brick_Pillar_Middle",
      "rotation": 15
    },
    {
      "x": -9,
      "y": 0,
      "z": -2,
      "name": "Soil_Grass"
    },
    {
      "x": -9,
      "y": 1,
      "z": -2,
      "name": "Plant_Grass_Jungle_Tall",
      "support": 15
    },
    {
      "x": -9,
      "y": 0,
      "z": -1,
      "name": "Soil_Gravel_Mossy",
      "support": 15
    },
    {
      "x": -9,
      "y": 0,
      "z": 0,
      "name": "Soil_Gravel",
      "support": 15
    },
    {
      "x": -9,
      "y": 0,
      "z": 1,
      "name": "Soil_Gravel",
      "support": 15
    },
    {
      "x": -9,
      "y": 0,
      "z": 2,
      "name": "Soil_Grass"
    },
    {
      "x": -9,
      "y": 1,
      "z": 2,
      "name": "Plant_Grass_Jungle_Tall",
      "support": 15
    },
    {
      "x": -9,
      "y": 0,
      "z": 3,
      "name": "Soil_Grass"
    },
    {
      "x": -9,
      "y": 1,
      "z": 3,
      "name": "Plant_Grass_Jungle_Tall",
      "support": 15
    },
    {
      "x": -9,
      "y": 0,
      "z": 4,
      "name": "Soil_Grass"
    },
    {
      "x": -9,
      "y": 1,
      "z": 4,
      "name": "Plant_Flower_Tall_Pink"
    },
    {
      "x": -9,
      "y": 0,
      "z": 5,
      "name": "Soil_Grass"
    },
    {
      "x": -9,
      "y": 0,
      "z": 6,
      "name": "Soil_Grass"
    },
    {
      "x": -9,
      "y": 1,
      "z": 6,
      "name": "Plant_Leaves_Wisteria_Wild",
      "support": 15,
      "rotation": 1
    },
    {
      "x": -9,
      "y": 2,
      "z": 6,
      "name": "Plant_Leaves_Wisteria_Wild",
      "support": 15,
      "rotation": 1
    },
    {
      "x": -9,
      "y": 0,
      "z": 7,
      "name": "Soil_Grass"
    },
    {
      "x": -9,
      "y": 1,
      "z": 7,
      "name": "Plant_Leaves_Wisteria_Wild",
      "support": 15,
      "rotation": 1
    },
    {
      "x": -9,
      "y": 2,
      "z": 7,
      "name": "Plant_Leaves_Wisteria_Wild",
      "support": 15,
      "rotation": 1
    },
    {
      "x": -9,
      "y": 0,
      "z": 8,
      "name": "Soil_Grass"
    },
    {
      "x": -9,
      "y": 1,
      "z": 8,
      "name": "Plant_Leaves_Wisteria_Wild",
      "support": 15,
      "rotation": 1
    },
    {
      "x": -9,
      "y": 2,
      "z": 8,
      "name": "Plant_Leaves_Wisteria_Wild",
      "support": 15,
      "rotation": 1
    },
    {
      "x": -9,
      "y": 0,
      "z": 9,
      "name": "Soil_Grass"
    },
    {
      "x": -9,
      "y": 0,
      "z": 10,
      "name": "Soil_Grass"
    },
    {
      "x": -9,
      "y": 1,
      "z": 10,
      "name": "Plant_Grass_Jungle",
      "support": 15
    },
    {
      "x": -9,
      "y": 0,
      "z": 11,
      "name": "Soil_Grass"
    },
    {
      "x": -9,
      "y": 1,
      "z": 11,
      "name": "Plant_Grass_Jungle",
      "support": 15
    },
    {
      "x": -9,
      "y": 0,
      "z": 12,
      "name": "Soil_Grass"
    },
    {
      "x": -9,
      "y": 0,
      "z": 13,
      "name": "Soil_Grass"
    },
    {
      "x": -9,
      "y": 1,
      "z": 13,
      "name": "Rock_Stone_Cobble_Wall"
    },
    {
      "x": -9,
      "y": 2,
      "z": 13,
      "name": "Rock_Stone_Cobble_Wall"
    },
    {
      "x": -9,
      "y": 3,
      "z": 13,
      "name": "Rock_Stone_Cobble_Wall"
    },
    {
      "x": -9,
      "y": 4,
      "z": 13,
      "name": "Rock_Stone_Cobble_Wall"
    },
    {
      "x": -9,
      "y": 5,
      "z": 13,
      "name": "Rock_Stone_Cobble_Wall"
    },
    {
      "x": -9,
      "y": 6,
      "z": 13,
      "name": "Rock_Stone_Cobble_Wall"
    },
    {
      "x": -9,
      "y": 7,
      "z": 13,
      "name": "Rock_Marble_Brick_Half"
    },
    {
      "x": -8,
      "y": 0,
      "z": -14,
      "name": "Soil_Grass"
    },
    {
      "x": -8,
      "y": 1,
      "z": -14,
      "name": "*Rock_Stone_Cobble_Wall_State_Definitions_Corner",
      "rotation": 1
    },
    {
      "x": -8,
      "y": 2,
      "z": -14,
      "name": "*Rock_Stone_Cobble_Wall_State_Definitions_Corner",
      "rotation": 1
    },
    {
      "x": -8,
      "y": 3,
      "z": -14,
      "name": "*Rock_Stone_Cobble_Wall_State_Definitions_Corner",
      "rotation": 1
    },
    {
      "x": -8,
      "y": 4,
      "z": -14,
      "name": "*Rock_Stone_Cobble_Wall_State_Definitions_Corner",
      "rotation": 1
    },
    {
      "x": -8,
      "y": 5,
      "z": -14,
      "name": "*Rock_Stone_Cobble_Wall_State_Definitions_Corner",
      "rotation": 1
    },
    {
      "x": -8,
      "y": 6,
      "z": -14,
      "name": "*Rock_Stone_Cobble_Wall_State_Definitions_Corner",
      "rotation": 1
    },
    {
      "x": -8,
      "y": 7,
      "z": -14,
      "name": "Rock_Marble_Brick_Half"
    },
    {
      "x": -8,
      "y": 0,
      "z": -13,
      "name": "Soil_Grass"
    },
    {
      "x": -8,
      "y": 1,
      "z": -13,
      "name": "*Rock_Stone_Cobble_Wall_State_Definitions_Corner",
      "rotation": 3
    },
    {
      "x": -8,
      "y": 2,
      "z": -13,
      "name": "*Rock_Stone_Cobble_Wall_State_Definitions_Corner",
      "rotation": 3
    },
    {
      "x": -8,
      "y": 3,
      "z": -13,
      "name": "*Rock_Stone_Cobble_Wall_State_Definitions_Corner",
      "rotation": 3
    },
    {
      "x": -8,
      "y": 4,
      "z": -13,
      "name": "*Rock_Stone_Cobble_Wall_State_Definitions_Corner",
      "rotation": 3
    },
    {
      "x": -8,
      "y": 5,
      "z": -13,
      "name": "*Rock_Stone_Cobble_Wall_State_Definitions_Corner",
      "rotation": 3
    },
    {
      "x": -8,
      "y": 6,
      "z": -13,
      "name": "*Rock_Stone_Cobble_Wall_State_Definitions_Corner",
      "rotation": 3
    },
    {
      "x": -8,
      "y": 7,
      "z": -13,
      "name": "Rock_Marble_Brick_Half"
    },
    {
      "x": -8,
      "y": 0,
      "z": -12,
      "name": "Soil_Grass"
    },
    {
      "x": -8,
      "y": 1,
      "z": -12,
      "name": "Plant_Grass_Jungle",
      "support": 15
    },
    {
      "x": -8,
      "y": 0,
      "z": -11,
      "name": "Soil_Grass"
    },
    {
      "x": -8,
      "y": 1,
      "z": -11,
      "name": "Plant_Grass_Jungle_Tall",
      "support": 15
    },
    {
      "x": -8,
      "y": 0,
      "z": -10,
      "name": "Soil_Grass"
    },
    {
      "x": -8,
      "y": 1,
      "z": -10,
      "name": "Plant_Grass_Jungle",
      "support": 15
    },
    {
      "x": -8,
      "y": 0,
      "z": -9,
      "name": "Soil_Grass"
    },
    {
      "x": -8,
      "y": 1,
      "z": -9,
      "name": "Plant_Leaves_Wisteria_Wild",
      "support": 15
    },
    {
      "x": -8,
      "y": 2,
      "z": -9,
      "name": "Plant_Leaves_Wisteria_Wild",
      "support": 15
    },
    {
      "x": -8,
      "y": 0,
      "z": -8,
      "name": "Soil_Grass"
    },
    {
      "x": -8,
      "y": 1,
      "z": -8,
      "name": "Plant_Leaves_Wisteria_Wild",
      "support": 15
    },
    {
      "x": -8,
      "y": 2,
      "z": -8,
      "name": "Plant_Leaves_Wisteria_Wild",
      "support": 15
    },
    {
      "x": -8,
      "y": 0,
      "z": -7,
      "name": "Soil_Grass"
    },
    {
      "x": -8,
      "y": 1,
      "z": -7,
      "name": "Plant_Flower_Tall_Pink"
    },
    {
      "x": -8,
      "y": 0,
      "z": -6,
      "name": "Soil_Grass"
    },
    {
      "x": -8,
      "y": 1,
      "z": -6,
      "name": "Plant_Flower_Tall_Pink"
    },
    {
      "x": -8,
      "y": 0,
      "z": -5,
      "name": "Soil_Grass"
    },
    {
      "x": -8,
      "y": 1,
      "z": -5,
      "name": "Plant_Grass_Jungle_Tall",
      "support": 15
    },
    {
      "x": -8,
      "y": 0,
      "z": -4,
      "name": "Soil_Grass"
    },
    {
      "x": -8,
      "y": 1,
      "z": -4,
      "name": "Plant_Grass_Jungle_Tall",
      "support": 15
    },
    {
      "x": -8,
      "y": 0,
      "z": -3,
      "name": "Soil_Grass"
    },
    {
      "x": -8,
      "y": 1,
      "z": -3,
      "name": "Rock_Marble_Brick_Pillar_Middle",
      "rotation": 15
    },
    {
      "x": -8,
      "y": 0,
      "z": -2,
      "name": "Soil_Grass"
    },
    {
      "x": -8,
      "y": 1,
      "z": -2,
      "name": "Plant_Grass_Jungle",
      "support": 15
    },
    {
      "x": -8,
      "y": 0,
      "z": -1,
      "name": "Soil_Gravel_Mossy",
      "support": 15
    },
    {
      "x": -8,
      "y": 0,
      "z": 0,
      "name": "Soil_Gravel",
      "support": 15
    },
    {
      "x": -8,
      "y": 0,
      "z": 1,
      "name": "Soil_Gravel_Mossy",
      "support": 15
    },
    {
      "x": -8,
      "y": 0,
      "z": 2,
      "name": "Soil_Grass"
    },
    {
      "x": -8,
      "y": 1,
      "z": 2,
      "name": "Plant_Grass_Jungle_Tall",
      "support": 15
    },
    {
      "x": -8,
      "y": 0,
      "z": 3,
      "name": "Soil_Grass"
    },
    {
      "x": -8,
      "y": 1,
      "z": 3,
      "name": "Plant_Grass_Jungle",
      "support": 15
    },
    {
      "x": -8,
      "y": 0,
      "z": 4,
      "name": "Soil_Grass"
    },
    {
      "x": -8,
      "y": 1,
      "z": 4,
      "name": "Plant_Grass_Jungle_Tall",
      "support": 15
    },
    {
      "x": -8,
      "y": 0,
      "z": 5,
      "name": "Soil_Grass"
    },
    {
      "x": -8,
      "y": 1,
      "z": 5,
      "name": "Plant_Flower_Tall_Pink"
    },
    {
      "x": -8,
      "y": 0,
      "z": 6,
      "name": "Soil_Grass"
    },
    {
      "x": -8,
      "y": 1,
      "z": 6,
      "name": "Plant_Flower_Tall_Pink"
    },
    {
      "x": -8,
      "y": 0,
      "z": 7,
      "name": "Soil_Grass"
    },
    {
      "x": -8,
      "y": 1,
      "z": 7,
      "name": "Plant_Flower_Tall_Pink"
    },
    {
      "x": -8,
      "y": 0,
      "z": 8,
      "name": "Soil_Grass"
    },
    {
      "x": -8,
      "y": 1,
      "z": 8,
      "name": "Plant_Leaves_Wisteria_Wild",
      "support": 15,
      "rotation": 1
    },
    {
      "x": -8,
      "y": 2,
      "z": 8,
      "name": "Plant_Leaves_Wisteria_Wild",
      "support": 15,
      "rotation": 1
    },
    {
      "x": -8,
      "y": 0,
      "z": 9,
      "name": "Soil_Grass"
    },
    {
      "x": -8,
      "y": 1,
      "z": 9,
      "name": "Plant_Leaves_Wisteria_Wild",
      "support": 15,
      "rotation": 1
    },
    {
      "x": -8,
      "y": 2,
      "z": 9,
      "name": "Plant_Leaves_Wisteria_Wild",
      "support": 15,
      "rotation": 1
    },
    {
      "x": -8,
      "y": 0,
      "z": 10,
      "name": "Soil_Grass"
    },
    {
      "x": -8,
      "y": 1,
      "z": 10,
      "name": "Plant_Grass_Jungle",
      "support": 15
    },
    {
      "x": -8,
      "y": 0,
      "z": 11,
      "name": "Soil_Grass"
    },
    {
      "x": -8,
      "y": 1,
      "z": 11,
      "name": "Plant_Grass_Jungle_Tall",
      "support": 15
    },
    {
      "x": -8,
      "y": 0,
      "z": 12,
      "name": "Soil_Grass"
    },
    {
      "x": -8,
      "y": 1,
      "z": 12,
      "name": "Plant_Grass_Jungle",
      "support": 15
    },
    {
      "x": -8,
      "y": 0,
      "z": 13,
      "name": "Soil_Grass"
    },
    {
      "x": -8,
      "y": 1,
      "z": 13,
      "name": "*Rock_Stone_Cobble_Wall_State_Definitions_Corner"
    },
    {
      "x": -8,
      "y": 2,
      "z": 13,
      "name": "*Rock_Stone_Cobble_Wall_State_Definitions_Corner"
    },
    {
      "x": -8,
      "y": 3,
      "z": 13,
      "name": "*Rock_Stone_Cobble_Wall_State_Definitions_Corner"
    },
    {
      "x": -8,
      "y": 4,
      "z": 13,
      "name": "*Rock_Stone_Cobble_Wall_State_Definitions_Corner"
    },
    {
      "x": -8,
      "y": 5,
      "z": 13,
      "name": "*Rock_Stone_Cobble_Wall_State_Definitions_Corner"
    },
    {
      "x": -8,
      "y": 6,
      "z": 13,
      "name": "*Rock_Stone_Cobble_Wall_State_Definitions_Corner"
    },
    {
      "x": -8,
      "y": 7,
      "z": 13,
      "name": "Rock_Marble_Brick_Half"
    },
    {
      "x": -8,
      "y": 0,
      "z": 14,
      "name": "Soil_Grass"
    },
    {
      "x": -8,
      "y": 1,
      "z": 14,
      "name": "*Rock_Stone_Cobble_Wall_State_Definitions_Corner",
      "rotation": 2
    },
    {
      "x": -8,
      "y": 2,
      "z": 14,
      "name": "*Rock_Stone_Cobble_Wall_State_Definitions_Corner",
      "rotation": 2
    },
    {
      "x": -8,
      "y": 3,
      "z": 14,
      "name": "*Rock_Stone_Cobble_Wall_State_Definitions_Corner",
      "rotation": 2
    },
    {
      "x": -8,
      "y": 4,
      "z": 14,
      "name": "*Rock_Stone_Cobble_Wall_State_Definitions_Corner",
      "rotation": 2
    },
    {
      "x": -8,
      "y": 5,
      "z": 14,
      "name": "*Rock_Stone_Cobble_Wall_State_Definitions_Corner",
      "rotation": 2
    },
    {
      "x": -8,
      "y": 6,
      "z": 14,
      "name": "*Rock_Stone_Cobble_Wall_State_Definitions_Corner",
      "rotation": 2
    },
    {
      "x": -8,
      "y": 7,
      "z": 14,
      "name": "Rock_Marble_Brick_Half"
    },
    {
      "x": -7,
      "y": 0,
      "z": -14,
      "name": "Soil_Grass"
    },
    {
      "x": -7,
      "y": 1,
      "z": -14,
      "name": "Rock_Stone_Cobble_Wall"
    },
    {
      "x": -7,
      "y": 2,
      "z": -14,
      "name": "Rock_Stone_Cobble_Wall"
    },
    {
      "x": -7,
      "y": 3,
      "z": -14,
      "name": "Rock_Stone_Cobble_Wall"
    },
    {
      "x": -7,
      "y": 4,
      "z": -14,
      "name": "Rock_Stone_Cobble_Wall"
    },
    {
      "x": -7,
      "y": 5,
      "z": -14,
      "name": "Rock_Stone_Cobble_Wall"
    },
    {
      "x": -7,
      "y": 6,
      "z": -14,
      "name": "Rock_Stone_Cobble_Wall"
    },
    {
      "x": -7,
      "y": 7,
      "z": -14,
      "name": "Rock_Marble_Brick_Half"
    },
    {
      "x": -7,
      "y": 0,
      "z": -13,
      "name": "Soil_Grass"
    },
    {
      "x": -7,
      "y": 1,
      "z": -13,
      "name": "Plant_Grass_Jungle_Tall",
      "support": 15
    },
    {
      "x": -7,
      "y": 0,
      "z": -12,
      "name": "Soil_Grass"
    },
    {
      "x": -7,
      "y": 1,
      "z": -12,
      "name": "Plant_Grass_Jungle_Tall",
      "support": 15
    },
    {
      "x": -7,
      "y": 0,
      "z": -11,
      "name": "Soil_Grass"
    },
    {
      "x": -7,
      "y": 1,
      "z": -11,
      "name": "Plant_Grass_Jungle",
      "support": 15
    },
    {
      "x": -7,
      "y": 0,
      "z": -10,
      "name": "Soil_Grass"
    },
    {
      "x": -7,
      "y": 1,
      "z": -10,
      "name": "Plant_Grass_Jungle",
      "support": 15
    },
    {
      "x": -7,
      "y": 0,
      "z": -9,
      "name": "Soil_Grass"
    },
    {
      "x": -7,
      "y": 1,
      "z": -9,
      "name": "Plant_Leaves_Wisteria_Wild",
      "support": 15
    },
    {
      "x": -7,
      "y": 2,
      "z": -9,
      "name": "Plant_Leaves_Wisteria_Wild",
      "support": 15
    },
    {
      "x": -7,
      "y": 0,
      "z": -8,
      "name": "Soil_Grass"
    },
    {
      "x": -7,
      "y": 1,
      "z": -8,
      "name": "Plant_Flower_Tall_Pink"
    },
    {
      "x": -7,
      "y": 0,
      "z": -7,
      "name": "Soil_Grass"
    },
    {
      "x": -7,
      "y": 1,
      "z": -7,
      "name": "Plant_Flower_Tall_Pink"
    },
    {
      "x": -7,
      "y": 0,
      "z": -6,
      "name": "Soil_Grass"
    },
    {
      "x": -7,
      "y": 0,
      "z": -5,
      "name": "Soil_Grass"
    },
    {
      "x": -7,
      "y": 1,
      "z": -5,
      "name": "Plant_Flower_Tall_Pink"
    },
    {
      "x": -7,
      "y": 0,
      "z": -4,
      "name": "Soil_Grass"
    },
    {
      "x": -7,
      "y": 1,
      "z": -4,
      "name": "Plant_Grass_Jungle_Tall",
      "support": 15
    },
    {
      "x": -7,
      "y": 0,
      "z": -3,
      "name": "Soil_Grass"
    },
    {
      "x": -7,
      "y": 1,
      "z": -3,
      "name": "Rock_Marble_Brick_Pillar_Base",
      "rotation": 7
    },
    {
      "x": -7,
      "y": 0,
      "z": -2,
      "name": "Soil_Grass"
    },
    {
      "x": -7,
      "y": 1,
      "z": -2,
      "name": "Plant_Grass_Jungle_Tall",
      "support": 15
    },
    {
      "x": -7,
      "y": 0,
      "z": -1,
      "name": "Soil_Gravel_Mossy",
      "support": 15
    },
    {
      "x": -7,
      "y": 0,
      "z": 0,
      "name": "Soil_Gravel_Mossy",
      "support": 15
    },
    {
      "x": -7,
      "y": 0,
      "z": 1,
      "name": "Soil_Gravel_Mossy",
      "support": 15
    },
    {
      "x": -7,
      "y": 0,
      "z": 2,
      "name": "Soil_Grass"
    },
    {
      "x": -7,
      "y": 1,
      "z": 2,
      "name": "Plant_Grass_Jungle",
      "support": 15
    },
    {
      "x": -7,
      "y": 0,
      "z": 3,
      "name": "Soil_Grass"
    },
    {
      "x": -7,
      "y": 1,
      "z": 3,
      "name": "Plant_Grass_Jungle_Tall",
      "support": 15
    },
    {
      "x": -7,
      "y": 0,
      "z": 4,
      "name": "Soil_Grass"
    },
    {
      "x": -7,
      "y": 1,
      "z": 4,
      "name": "Plant_Flower_Tall_Pink"
    },
    {
      "x": -7,
      "y": 0,
      "z": 5,
      "name": "Soil_Grass"
    },
    {
      "x": -7,
      "y": 1,
      "z": 5,
      "name": "Plant_Grass_Jungle_Tall",
      "support": 15
    },
    {
      "x": -7,
      "y": 0,
      "z": 6,
      "name": "Soil_Grass"
    },
    {
      "x": -7,
      "y": 1,
      "z": 6,
      "name": "Plant_Grass_Jungle_Tall",
      "support": 15
    },
    {
      "x": -7,
      "y": 0,
      "z": 7,
      "name": "Soil_Grass"
    },
    {
      "x": -7,
      "y": 1,
      "z": 7,
      "name": "Plant_Flower_Tall_Pink"
    },
    {
      "x": -7,
      "y": 0,
      "z": 8,
      "name": "Soil_Grass"
    },
    {
      "x": -7,
      "y": 1,
      "z": 8,
      "name": "Plant_Flower_Tall_Pink"
    },
    {
      "x": -7,
      "y": 0,
      "z": 9,
      "name": "Soil_Grass"
    },
    {
      "x": -7,
      "y": 1,
      "z": 9,
      "name": "Plant_Leaves_Wisteria_Wild",
      "support": 15,
      "rotation": 1
    },
    {
      "x": -7,
      "y": 2,
      "z": 9,
      "name": "Plant_Leaves_Wisteria_Wild",
      "support": 15,
      "rotation": 1
    },
    {
      "x": -7,
      "y": 0,
      "z": 10,
      "name": "Soil_Grass"
    },
    {
      "x": -7,
      "y": 0,
      "z": 11,
      "name": "Soil_Grass"
    },
    {
      "x": -7,
      "y": 1,
      "z": 11,
      "name": "Plant_Grass_Jungle_Tall",
      "support": 15
    },
    {
      "x": -7,
      "y": 0,
      "z": 12,
      "name": "Soil_Grass"
    },
    {
      "x": -7,
      "y": 1,
      "z": 12,
      "name": "Plant_Grass_Jungle",
      "support": 15
    },
    {
      "x": -7,
      "y": 0,
      "z": 13,
      "name": "Soil_Grass"
    },
    {
      "x": -7,
      "y": 1,
      "z": 13,
      "name": "Plant_Grass_Jungle_Tall",
      "support": 15
    },
    {
      "x": -7,
      "y": 0,
      "z": 14,
      "name": "Soil_Grass"
    },
    {
      "x": -7,
      "y": 1,
      "z": 14,
      "name": "Rock_Stone_Cobble_Wall"
    },
    {
      "x": -7,
      "y": 2,
      "z": 14,
      "name": "Rock_Stone_Cobble_Wall"
    },
    {
      "x": -7,
      "y": 3,
      "z": 14,
      "name": "Rock_Stone_Cobble_Wall"
    },
    {
      "x": -7,
      "y": 4,
      "z": 14,
      "name": "Rock_Stone_Cobble_Wall"
    },
    {
      "x": -7,
      "y": 5,
      "z": 14,
      "name": "Rock_Stone_Cobble_Wall"
    },
    {
      "x": -7,
      "y": 6,
      "z": 14,
      "name": "Rock_Stone_Cobble_Wall"
    },
    {
      "x": -7,
      "y": 7,
      "z": 14,
      "name": "Rock_Marble_Brick_Half"
    },
    {
      "x": -6,
      "y": 0,
      "z": -15,
      "name": "Soil_Grass"
    },
    {
      "x": -6,
      "y": 1,
      "z": -15,
      "name": "*Rock_Stone_Cobble_Wall_State_Definitions_Corner",
      "rotation": 1
    },
    {
      "x": -6,
      "y": 2,
      "z": -15,
      "name": "*Rock_Stone_Cobble_Wall_State_Definitions_Corner",
      "rotation": 1
    },
    {
      "x": -6,
      "y": 3,
      "z": -15,
      "name": "*Rock_Stone_Cobble_Wall_State_Definitions_Corner",
      "rotation": 1
    },
    {
      "x": -6,
      "y": 4,
      "z": -15,
      "name": "*Rock_Stone_Cobble_Wall_State_Definitions_Corner",
      "rotation": 1
    },
    {
      "x": -6,
      "y": 5,
      "z": -15,
      "name": "*Rock_Stone_Cobble_Wall_State_Definitions_Corner",
      "rotation": 1
    },
    {
      "x": -6,
      "y": 6,
      "z": -15,
      "name": "*Rock_Stone_Cobble_Wall_State_Definitions_Corner",
      "rotation": 1
    },
    {
      "x": -6,
      "y": 7,
      "z": -15,
      "name": "Rock_Marble_Brick_Half"
    },
    {
      "x": -6,
      "y": 0,
      "z": -14,
      "name": "Soil_Grass"
    },
    {
      "x": -6,
      "y": 1,
      "z": -14,
      "name": "*Rock_Stone_Cobble_Wall_State_Definitions_Corner",
      "rotation": 3
    },
    {
      "x": -6,
      "y": 2,
      "z": -14,
      "name": "*Rock_Stone_Cobble_Wall_State_Definitions_Corner",
      "rotation": 3
    },
    {
      "x": -6,
      "y": 3,
      "z": -14,
      "name": "*Rock_Stone_Cobble_Wall_State_Definitions_Corner",
      "rotation": 3
    },
    {
      "x": -6,
      "y": 4,
      "z": -14,
      "name": "*Rock_Stone_Cobble_Wall_State_Definitions_Corner",
      "rotation": 3
    },
    {
      "x": -6,
      "y": 5,
      "z": -14,
      "name": "*Rock_Stone_Cobble_Wall_State_Definitions_Corner",
      "rotation": 3
    },
    {
      "x": -6,
      "y": 6,
      "z": -14,
      "name": "*Rock_Stone_Cobble_Wall_State_Definitions_Corner",
      "rotation": 3
    },
    {
      "x": -6,
      "y": 7,
      "z": -14,
      "name": "Rock_Marble_Brick_Half"
    },
    {
      "x": -6,
      "y": 0,
      "z": -13,
      "name": "Soil_Grass"
    },
    {
      "x": -6,
      "y": 1,
      "z": -13,
      "name": "Plant_Grass_Jungle",
      "support": 15
    },
    {
      "x": -6,
      "y": 0,
      "z": -12,
      "name": "Soil_Grass"
    },
    {
      "x": -6,
      "y": 1,
      "z": -12,
      "name": "Plant_Grass_Jungle",
      "support": 15
    },
    {
      "x": -6,
      "y": 0,
      "z": -11,
      "name": "Soil_Grass"
    },
    {
      "x": -6,
      "y": 0,
      "z": -10,
      "name": "Soil_Grass"
    },
    {
      "x": -6,
      "y": 1,
      "z": -10,
      "name": "Plant_Leaves_Wisteria_Wild",
      "support": 15
    },
    {
      "x": -6,
      "y": 2,
      "z": -10,
      "name": "Plant_Leaves_Wisteria_Wild",
      "support": 15
    },
    {
      "x": -6,
      "y": 0,
      "z": -9,
      "name": "Soil_Grass"
    },
    {
      "x": -6,
      "y": 1,
      "z": -9,
      "name": "Plant_Leaves_Wisteria_Wild",
      "support": 15
    },
    {
      "x": -6,
      "y": 2,
      "z": -9,
      "name": "Plant_Leaves_Wisteria_Wild",
      "support": 15
    },
    {
      "x": -6,
      "y": 0,
      "z": -8,
      "name": "Soil_Grass"
    },
    {
      "x": -6,
      "y": 1,
      "z": -8,
      "name": "Plant_Flower_Tall_Pink"
    },
    {
      "x": -6,
      "y": 0,
      "z": -7,
      "name": "Soil_Grass"
    },
    {
      "x": -6,
      "y": 1,
      "z": -7,
      "name": "Plant_Grass_Jungle_Tall",
      "support": 15
    },
    {
      "x": -6,
      "y": 0,
      "z": -6,
      "name": "Soil_Grass"
    },
    {
      "x": -6,
      "y": 1,
      "z": -6,
      "name": "Plant_Grass_Jungle_Tall",
      "support": 15
    },
    {
      "x": -6,
      "y": 0,
      "z": -5,
      "name": "Soil_Grass"
    },
    {
      "x": -6,
      "y": 1,
      "z": -5,
      "name": "Plant_Grass_Jungle_Tall",
      "support": 15
    },
    {
      "x": -6,
      "y": 0,
      "z": -4,
      "name": "Soil_Grass"
    },
    {
      "x": -6,
      "y": 1,
      "z": -4,
      "name": "Plant_Grass_Jungle",
      "support": 15
    },
    {
      "x": -6,
      "y": 0,
      "z": -3,
      "name": "Soil_Grass"
    },
    {
      "x": -6,
      "y": 1,
      "z": -3,
      "name": "Rubble_Marble_Medium",
      "support": 15
    },
    {
      "x": -6,
      "y": 0,
      "z": -2,
      "name": "Rock_Marble_Brick"
    },
    {
      "x": -6,
      "y": 0,
      "z": -1,
      "name": "Rock_Marble_Brick"
    },
    {
      "x": -6,
      "y": 0,
      "z": 0,
      "name": "Rock_Marble_Brick"
    },
    {
      "x": -6,
      "y": 0,
      "z": 1,
      "name": "Rock_Marble_Brick"
    },
    {
      "x": -6,
      "y": 0,
      "z": 2,
      "name": "Rock_Marble_Brick"
    },
    {
      "x": -6,
      "y": 0,
      "z": 3,
      "name": "Soil_Grass"
    },
    {
      "x": -6,
      "y": 1,
      "z": 3,
      "name": "Plant_Grass_Jungle",
      "support": 15
    },
    {
      "x": -6,
      "y": 0,
      "z": 4,
      "name": "Soil_Grass"
    },
    {
      "x": -6,
      "y": 0,
      "z": 5,
      "name": "Soil_Grass"
    },
    {
      "x": -6,
      "y": 1,
      "z": 5,
      "name": "Plant_Grass_Jungle",
      "support": 15
    },
    {
      "x": -6,
      "y": 0,
      "z": 6,
      "name": "Soil_Grass"
    },
    {
      "x": -6,
      "y": 1,
      "z": 6,
      "name": "Plant_Grass_Jungle",
      "support": 15
    },
    {
      "x": -6,
      "y": 0,
      "z": 7,
      "name": "Soil_Grass"
    },
    {
      "x": -6,
      "y": 1,
      "z": 7,
      "name": "Plant_Grass_Jungle",
      "support": 15
    },
    {
      "x": -6,
      "y": 0,
      "z": 8,
      "name": "Soil_Grass"
    },
    {
      "x": -6,
      "y": 1,
      "z": 8,
      "name": "Plant_Flower_Tall_Pink"
    },
    {
      "x": -6,
      "y": 0,
      "z": 9,
      "name": "Soil_Grass"
    },
    {
      "x": -6,
      "y": 1,
      "z": 9,
      "name": "Plant_Leaves_Wisteria_Wild",
      "support": 15,
      "rotation": 1
    },
    {
      "x": -6,
      "y": 2,
      "z": 9,
      "name": "Plant_Leaves_Wisteria_Wild",
      "support": 15,
      "rotation": 1
    },
    {
      "x": -6,
      "y": 0,
      "z": 10,
      "name": "Soil_Grass"
    },
    {
      "x": -6,
      "y": 1,
      "z": 10,
      "name": "Plant_Leaves_Wisteria_Wild",
      "support": 15,
      "rotation": 1
    },
    {
      "x": -6,
      "y": 2,
      "z": 10,
      "name": "Plant_Leaves_Wisteria_Wild",
      "support": 15,
      "rotation": 1
    },
    {
      "x": -6,
      "y": 0,
      "z": 11,
      "name": "Soil_Grass"
    },
    {
      "x": -6,
      "y": 1,
      "z": 11,
      "name": "Plant_Grass_Jungle",
      "support": 15
    },
    {
      "x": -6,
      "y": 0,
      "z": 12,
      "name": "Soil_Grass"
    },
    {
      "x": -6,
      "y": 1,
      "z": 12,
      "name": "Plant_Grass_Jungle_Tall",
      "support": 15
    },
    {
      "x": -6,
      "y": 0,
      "z": 13,
      "name": "Soil_Grass"
    },
    {
      "x": -6,
      "y": 1,
      "z": 13,
      "name": "Plant_Grass_Jungle",
      "support": 15
    },
    {
      "x": -6,
      "y": 0,
      "z": 14,
      "name": "Soil_Grass"
    },
    {
      "x": -6,
      "y": 1,
      "z": 14,
      "name": "*Rock_Stone_Cobble_Wall_State_Definitions_Corner"
    },
    {
      "x": -6,
      "y": 2,
      "z": 14,
      "name": "*Rock_Stone_Cobble_Wall_State_Definitions_Corner"
    },
    {
      "x": -6,
      "y": 3,
      "z": 14,
      "name": "*Rock_Stone_Cobble_Wall_State_Definitions_Corner"
    },
    {
      "x": -6,
      "y": 4,
      "z": 14,
      "name": "*Rock_Stone_Cobble_Wall_State_Definitions_Corner"
    },
    {
      "x": -6,
      "y": 5,
      "z": 14,
      "name": "*Rock_Stone_Cobble_Wall_State_Definitions_Corner"
    },
    {
      "x": -6,
      "y": 6,
      "z": 14,
      "name": "*Rock_Stone_Cobble_Wall_State_Definitions_Corner"
    },
    {
      "x": -6,
      "y": 7,
      "z": 14,
      "name": "Rock_Marble_Brick_Half"
    },
    {
      "x": -6,
      "y": 0,
      "z": 15,
      "name": "Soil_Grass"
    },
    {
      "x": -6,
      "y": 1,
      "z": 15,
      "name": "*Rock_Stone_Cobble_Wall_State_Definitions_Corner",
      "rotation": 2
    },
    {
      "x": -6,
      "y": 2,
      "z": 15,
      "name": "*Rock_Stone_Cobble_Wall_State_Definitions_Corner",
      "rotation": 2
    },
    {
      "x": -6,
      "y": 3,
      "z": 15,
      "name": "*Rock_Stone_Cobble_Wall_State_Definitions_Corner",
      "rotation": 2
    },
    {
      "x": -6,
      "y": 4,
      "z": 15,
      "name": "*Rock_Stone_Cobble_Wall_State_Definitions_Corner",
      "rotation": 2
    },
    {
      "x": -6,
      "y": 5,
      "z": 15,
      "name": "*Rock_Stone_Cobble_Wall_State_Definitions_Corner",
      "rotation": 2
    },
    {
      "x": -6,
      "y": 6,
      "z": 15,
      "name": "*Rock_Stone_Cobble_Wall_State_Definitions_Corner",
      "rotation": 2
    },
    {
      "x": -6,
      "y": 7,
      "z": 15,
      "name": "Rock_Marble_Brick_Half"
    },
    {
      "x": -5,
      "y": 0,
      "z": -15,
      "name": "Soil_Grass"
    },
    {
      "x": -5,
      "y": 1,
      "z": -15,
      "name": "Rock_Stone_Cobble_Wall"
    },
    {
      "x": -5,
      "y": 2,
      "z": -15,
      "name": "Rock_Stone_Cobble_Wall"
    },
    {
      "x": -5,
      "y": 3,
      "z": -15,
      "name": "Rock_Stone_Cobble_Wall"
    },
    {
      "x": -5,
      "y": 4,
      "z": -15,
      "name": "Rock_Stone_Cobble_Wall"
    },
    {
      "x": -5,
      "y": 5,
      "z": -15,
      "name": "Rock_Stone_Cobble_Wall"
    },
    {
      "x": -5,
      "y": 6,
      "z": -15,
      "name": "Rock_Stone_Cobble_Wall"
    },
    {
      "x": -5,
      "y": 7,
      "z": -15,
      "name": "Rock_Marble_Brick_Half"
    },
    {
      "x": -5,
      "y": 0,
      "z": -14,
      "name": "Soil_Grass"
    },
    {
      "x": -5,
      "y": 1,
      "z": -14,
      "name": "Plant_Grass_Jungle",
      "support": 15
    },
    {
      "x": -5,
      "y": 0,
      "z": -13,
      "name": "Soil_Grass"
    },
    {
      "x": -5,
      "y": 1,
      "z": -13,
      "name": "Plant_Grass_Jungle_Tall",
      "support": 15
    },
    {
      "x": -5,
      "y": 0,
      "z": -12,
      "name": "Soil_Grass"
    },
    {
      "x": -5,
      "y": 1,
      "z": -12,
      "name": "Plant_Grass_Jungle_Tall",
      "support": 15
    },
    {
      "x": -5,
      "y": 0,
      "z": -11,
      "name": "Soil_Grass"
    },
    {
      "x": -5,
      "y": 0,
      "z": -10,
      "name": "Soil_Grass"
    },
    {
      "x": -5,
      "y": 1,
      "z": -10,
      "name": "Plant_Leaves_Wisteria_Wild",
      "support": 15
    },
    {
      "x": -5,
      "y": 2,
      "z": -10,
      "name": "Plant_Leaves_Wisteria_Wild",
      "support": 15
    },
    {
      "x": -5,
      "y": 0,
      "z": -9,
      "name": "Soil_Grass"
    },
    {
      "x": -5,
      "y": 1,
      "z": -9,
      "name": "Plant_Flower_Tall_Pink"
    },
    {
      "x": -5,
      "y": 0,
      "z": -8,
      "name": "Soil_Grass"
    },
    {
      "x": -5,
      "y": 1,
      "z": -8,
      "name": "Plant_Grass_Jungle_Tall",
      "support": 15
    },
    {
      "x": -5,
      "y": 0,
      "z": -7,
      "name": "Soil_Grass"
    },
    {
      "x": -5,
      "y": 1,
      "z": -7,
      "name": "Plant_Grass_Jungle_Tall",
      "support": 15
    },
    {
      "x": -5,
      "y": 0,
      "z": -6,
      "name": "Soil_Grass"
    },
    {
      "x": -5,
      "y": 1,
      "z": -6,
      "name": "Plant_Grass_Jungle",
      "support": 15
    },
    {
      "x": -5,
      "y": 0,
      "z": -5,
      "name": "Soil_Grass"
    },
    {
      "x": -5,
      "y": 1,
      "z": -5,
      "name": "Plant_Flower_Tall_Pink"
    },
    {
      "x": -5,
      "y": 0,
      "z": -4,
      "name": "Rock_Marble_Brick"
    },
    {
      "x": -5,
      "y": 0,
      "z": -3,
      "name": "Rock_Marble_Brick"
    },
    {
      "x": -5,
      "y": 1,
      "z": -3,
      "name": "Rock_Marble_Brick_Stairs",
      "rotation": 18
    },
    {
      "x": -5,
      "y": 0,
      "z": -2,
      "name": "Rock_Marble_Brick"
    },
    {
      "x": -5,
      "y": 1,
      "z": -2,
      "name": "Rock_Marble_Brick_Half",
      "rotation": 7
    },
    {
      "x": -5,
      "y": 0,
      "z": -1,
      "name": "Rock_Marble_Brick"
    },
    {
      "x": -5,
      "y": 0,
      "z": 0,
      "name": "Rock_Marble_Brick"
    },
    {
      "x": -5,
      "y": 1,
      "z": 0,
      "name": "Rubble_Marble_Medium",
      "support": 15
    },
    {
      "x": -5,
      "y": 0,
      "z": 1,
      "name": "Rock_Marble_Brick"
    },
    {
      "x": -5,
      "y": 1,
      "z": 1,
      "name": "Rock_Marble_Brick",
      "rotation": 15
    },
    {
      "x": -5,
      "y": 0,
      "z": 2,
      "name": "Rock_Marble_Brick"
    },
    {
      "x": -5,
      "y": 1,
      "z": 2,
      "name": "Rock_Marble_Brick",
      "rotation": 15
    },
    {
      "x": -5,
      "y": 0,
      "z": 3,
      "name": "Rock_Marble_Brick"
    },
    {
      "x": -5,
      "y": 0,
      "z": 4,
      "name": "Rock_Marble_Brick"
    },
    {
      "x": -5,
      "y": 0,
      "z": 5,
      "name": "Soil_Grass"
    },
    {
      "x": -5,
      "y": 1,
      "z": 5,
      "name": "Plant_Grass_Jungle_Tall",
      "support": 15
    },
    {
      "x": -5,
      "y": 0,
      "z": 6,
      "name": "Soil_Grass"
    },
    {
      "x": -5,
      "y": 1,
      "z": 6,
      "name": "Plant_Flower_Tall_Pink"
    },
    {
      "x": -5,
      "y": 0,
      "z": 7,
      "name": "Soil_Grass"
    },
    {
      "x": -5,
      "y": 0,
      "z": 8,
      "name": "Soil_Grass"
    },
    {
      "x": -5,
      "y": 1,
      "z": 8,
      "name": "Plant_Flower_Tall_Pink"
    },
    {
      "x": -5,
      "y": 0,
      "z": 9,
      "name": "Soil_Grass"
    },
    {
      "x": -5,
      "y": 0,
      "z": 10,
      "name": "Soil_Grass"
    },
    {
      "x": -5,
      "y": 1,
      "z": 10,
      "name": "Plant_Leaves_Wisteria_Wild",
      "support": 15,
      "rotation": 1
    },
    {
      "x": -5,
      "y": 2,
      "z": 10,
      "name": "Plant_Leaves_Wisteria_Wild",
      "support": 15,
      "rotation": 1
    },
    {
      "x": -5,
      "y": 0,
      "z": 11,
      "name": "Soil_Grass"
    },
    {
      "x": -5,
      "y": 1,
      "z": 11,
      "name": "Plant_Grass_Jungle",
      "support": 15
    },
    {
      "x": -5,
      "y": 0,
      "z": 12,
      "name": "Soil_Grass"
    },
    {
      "x": -5,
      "y": 1,
      "z": 12,
      "name": "Plant_Grass_Jungle",
      "support": 15
    },
    {
      "x": -5,
      "y": 0,
      "z": 13,
      "name": "Soil_Grass"
    },
    {
      "x": -5,
      "y": 1,
      "z": 13,
      "name": "Plant_Grass_Jungle",
      "support": 15
    },
    {
      "x": -5,
      "y": 0,
      "z": 14,
      "name": "Soil_Grass"
    },
    {
      "x": -5,
      "y": 0,
      "z": 15,
      "name": "Soil_Grass"
    },
    {
      "x": -5,
      "y": 1,
      "z": 15,
      "name": "Rock_Stone_Cobble_Wall"
    },
    {
      "x": -5,
      "y": 2,
      "z": 15,
      "name": "Rock_Stone_Cobble_Wall"
    },
    {
      "x": -5,
      "y": 3,
      "z": 15,
      "name": "Rock_Stone_Cobble_Wall"
    },
    {
      "x": -5,
      "y": 4,
      "z": 15,
      "name": "Rock_Stone_Cobble_Wall"
    },
    {
      "x": -5,
      "y": 5,
      "z": 15,
      "name": "Rock_Stone_Cobble_Wall"
    },
    {
      "x": -5,
      "y": 6,
      "z": 15,
      "name": "Rock_Stone_Cobble_Wall"
    },
    {
      "x": -5,
      "y": 7,
      "z": 15,
      "name": "Rock_Marble_Brick_Half"
    },
    {
      "x": -4,
      "y": 0,
      "z": -15,
      "name": "Soil_Dirt"
    },
    {
      "x": -4,
      "y": 1,
      "z": -15,
      "name": "Rock_Marble_Brick",
      "rotation": 2
    },
    {
      "x": -4,
      "y": 2,
      "z": -15,
      "name": "Rock_Marble_Brick",
      "rotation": 2
    },
    {
      "x": -4,
      "y": 3,
      "z": -15,
      "name": "Rock_Marble_Brick",
      "rotation": 2
    },
    {
      "x": -4,
      "y": 4,
      "z": -15,
      "name": "Rock_Marble_Brick",
      "rotation": 2
    },
    {
      "x": -4,
      "y": 5,
      "z": -15,
      "name": "Rock_Marble_Brick",
      "rotation": 2
    },
    {
      "x": -4,
      "y": 6,
      "z": -15,
      "name": "Rock_Marble_Brick",
      "rotation": 2
    },
    {
      "x": -4,
      "y": 7,
      "z": -15,
      "name": "Rock_Marble_Brick_Half"
    },
    {
      "x": -4,
      "y": 0,
      "z": -14,
      "name": "Soil_Grass"
    },
    {
      "x": -4,
      "y": 1,
      "z": -14,
      "name": "Plant_Grass_Jungle",
      "support": 15
    },
    {
      "x": -4,
      "y": 3,
      "z": -14,
      "name": "Plant_Vine_Wall",
      "support": 15
    },
    {
      "x": -4,
      "y": 4,
      "z": -14,
      "name": "Plant_Vine_Wall",
      "support": 15
    },
    {
      "x": -4,
      "y": 5,
      "z": -14,
      "name": "Plant_Vine_Wall",
      "support": 15
    },
    {
      "x": -4,
      "y": 6,
      "z": -14,
      "name": "Plant_Vine_Wall",
      "support": 15
    },
    {
      "x": -4,
      "y": 0,
      "z": -13,
      "name": "Soil_Grass"
    },
    {
      "x": -4,
      "y": 1,
      "z": -13,
      "name": "Plant_Grass_Jungle_Tall",
      "support": 15
    },
    {
      "x": -4,
      "y": 0,
      "z": -12,
      "name": "Soil_Grass"
    },
    {
      "x": -4,
      "y": 1,
      "z": -12,
      "name": "Plant_Grass_Jungle",
      "support": 15
    },
    {
      "x": -4,
      "y": 0,
      "z": -11,
      "name": "Soil_Grass"
    },
    {
      "x": -4,
      "y": 1,
      "z": -11,
      "name": "Plant_Grass_Jungle",
      "support": 15
    },
    {
      "x": -4,
      "y": 8,
      "z": -11,
      "name": "Plant_Vine_Wall",
      "support": 15,
      "rotation": 3
    },
    {
      "x": -4,
      "y": 0,
      "z": -10,
      "name": "Soil_Grass"
    },
    {
      "x": -4,
      "y": 1,
      "z": -10,
      "name": "Plant_Leaves_Wisteria_Wild",
      "support": 15
    },
    {
      "x": -4,
      "y": 2,
      "z": -10,
      "name": "Plant_Leaves_Wisteria_Wild",
      "support": 15
    },
    {
      "x": -4,
      "y": 0,
      "z": -9,
      "name": "Soil_Grass"
    },
    {
      "x": -4,
      "y": 0,
      "z": -8,
      "name": "Soil_Grass"
    },
    {
      "x": -4,
      "y": 1,
      "z": -8,
      "name": "Plant_Grass_Jungle_Tall",
      "support": 15
    },
    {
      "x": -4,
      "y": 0,
      "z": -7,
      "name": "Soil_Grass"
    },
    {
      "x": -4,
      "y": 1,
      "z": -7,
      "name": "Plant_Flower_Tall_Pink"
    },
    {
      "x": -4,
      "y": 0,
      "z": -6,
      "name": "Soil_Grass"
    },
    {
      "x": -4,
      "y": 1,
      "z": -6,
      "name": "Plant_Grass_Jungle_Tall",
      "support": 15
    },
    {
      "x": -4,
      "y": 0,
      "z": -5,
      "name": "Rock_Marble_Brick"
    },
    {
      "x": -4,
      "y": 0,
      "z": -4,
      "name": "Rock_Marble_Brick"
    },
    {
      "x": -4,
      "y": 0,
      "z": -3,
      "name": "Rock_Marble_Brick"
    },
    {
      "x": -4,
      "y": 0,
      "z": -2,
      "name": "Rock_Marble_Brick"
    },
    {
      "x": -4,
      "y": 1,
      "z": -2,
      "name": "Rock_Marble_Brick_Half",
      "rotation": 15
    },
    {
      "x": -4,
      "y": 0,
      "z": -1,
      "name": "Rock_Marble_Brick"
    },
    {
      "x": -4,
      "y": 1,
      "z": -1,
      "name": "Rock_Marble_Brick",
      "rotation": 15
    },
    {
      "x": -4,
      "y": 0,
      "z": 0,
      "name": "Rock_Marble_Brick"
    },
    {
      "x": -4,
      "y": 1,
      "z": 0,
      "name": "Rubble_Marble",
      "support": 15
    },
    {
      "x": -4,
      "y": 0,
      "z": 1,
      "name": "Rock_Marble_Brick"
    },
    {
      "x": -4,
      "y": 0,
      "z": 2,
      "name": "Rock_Marble_Brick"
    },
    {
      "x": -4,
      "y": 0,
      "z": 3,
      "name": "Rock_Marble_Brick"
    },
    {
      "x": -4,
      "y": 0,
      "z": 4,
      "name": "Rock_Marble_Brick"
    },
    {
      "x": -4,
      "y": 0,
      "z": 5,
      "name": "Rock_Marble_Brick"
    },
    {
      "x": -4,
      "y": 0,
      "z": 6,
      "name": "Soil_Grass"
    },
    {
      "x": -4,
      "y": 0,
      "z": 7,
      "name": "Soil_Grass"
    },
    {
      "x": -4,
      "y": 1,
      "z": 7,
      "name": "Plant_Grass_Jungle_Tall",
      "support": 15
    },
    {
      "x": -4,
      "y": 0,
      "z": 8,
      "name": "Soil_Grass"
    },
    {
      "x": -4,
      "y": 1,
      "z": 8,
      "name": "Plant_Grass_Jungle_Tall",
      "support": 15
    },
    {
      "x": -4,
      "y": 0,
      "z": 9,
      "name": "Soil_Grass"
    },
    {
      "x": -4,
      "y": 1,
      "z": 9,
      "name": "Plant_Flower_Tall_Pink"
    },
    {
      "x": -4,
      "y": 0,
      "z": 10,
      "name": "Soil_Grass"
    },
    {
      "x": -4,
      "y": 1,
      "z": 10,
      "name": "Plant_Leaves_Wisteria_Wild",
      "support": 15,
      "rotation": 1
    },
    {
      "x": -4,
      "y": 2,
      "z": 10,
      "name": "Plant_Leaves_Wisteria_Wild",
      "support": 15,
      "rotation": 1
    },
    {
      "x": -4,
      "y": 0,
      "z": 11,
      "name": "Soil_Grass"
    },
    {
      "x": -4,
      "y": 0,
      "z": 12,
      "name": "Soil_Grass"
    },
    {
      "x": -4,
      "y": 1,
      "z": 12,
      "name": "Plant_Grass_Jungle_Tall",
      "support": 15
    },
    {
      "x": -4,
      "y": 0,
      "z": 13,
      "name": "Soil_Grass"
    },
    {
      "x": -4,
      "y": 1,
      "z": 13,
      "name": "Plant_Grass_Jungle",
      "support": 15
    },
    {
      "x": -4,
      "y": 0,
      "z": 14,
      "name": "Soil_Grass"
    },
    {
      "x": -4,
      "y": 1,
      "z": 14,
      "name": "Plant_Grass_Jungle",
      "support": 15
    },
    {
      "x": -4,
      "y": 0,
      "z": 15,
      "name": "Soil_Dirt"
    },
    {
      "x": -4,
      "y": 1,
      "z": 15,
      "name": "Rock_Marble_Brick"
    },
    {
      "x": -4,
      "y": 2,
