{
  "version": 8,
  "blockIdVersion": 11,
  "anchorX": 0,
  "anchorY": 0,
  "anchorZ": -1,
  "blocks": [
    {
      "x": -5,
      "y": 0,
      "z": -1,
      "name": "Soil_Grass"
    },
    {
      "x": -5,
      "y": 0,
      "z": 0,
      "name": "Soil_Grass"
    },
    {
      "x": -5,
      "y": -1,
      "z": 1,
      "name": "Soil_Dirt"
    },
    {
      "x": -5,
      "y": 0,
      "z": 1,
      "name": "Soil_Grass"
    },
    {
      "x": -5,
      "y": 0,
      "z": 2,
      "name": "Soil_Grass"
    },
    {
      "x": -5,
      "y": -1,
      "z": 3,
      "name": "Soil_Dirt"
    },
    {
      "x": -5,
      "y": 0,
      "z": 3,
      "name": "Soil_Grass"
    },
    {
      "x": -5,
      "y": -1,
      "z": 4,
      "name": "Soil_Dirt"
    },
    {
      "x": -5,
      "y": 0,
      "z": 4,
      "name": "Soil_Grass"
    },
    {
      "x": -5,
      "y": 0,
      "z": 5,
      "name": "Soil_Grass"
    },
    {
      "x": -5,
      "y": 0,
      "z": 6,
      "name": "Soil_Grass"
    },
    {
      "x": -4,
      "y": 0,
      "z": -3,
      "name": "Soil_Grass"
    },
    {
      "x": -4,
      "y": 0,
      "z": -2,
      "name": "Soil_Grass"
    },
    {
      "x": -4,
      "y": 1,
      "z": -2,
      "name": "Empty"
    },
    {
      "x": -4,
      "y": 2,
      "z": -2,
      "name": "Empty"
    },
    {
      "x": -4,
      "y": 0,
      "z": -1,
      "name": "Soil_Grass"
    },
    {
      "x": -4,
      "y": 1,
      "z": -1,
      "name": "Empty"
    },
    {
      "x": -4,
      "y": 2,
      "z": -1,
      "name": "Empty"
    },
    {
      "x": -4,
      "y": -1,
      "z": 0,
      "name": "Soil_Dirt"
    },
    {
      "x": -4,
      "y": 0,
      "z": 0,
      "name": "Soil_Grass"
    },
    {
      "x": -4,
      "y": -2,
      "z": 1,
      "name": "Soil_Dirt"
    },
    {
      "x": -4,
      "y": -1,
      "z": 1,
      "name": "Soil_Dirt"
    },
    {
      "x": -4,
      "y": 0,
      "z": 1,
      "name": "Rock_Quartzite_Brick"
    },
    {
      "x": -4,
      "y": 1,
      "z": 1,
      "name": "Empty"
    },
    {
      "x": -4,
      "y": 2,
      "z": 1,
      "name": "Empty"
    },
    {
      "x": -4,
      "y": -2,
      "z": 2,
      "name": "Soil_Dirt"
    },
    {
      "x": -4,
      "y": -1,
      "z": 2,
      "name": "Soil_Dirt"
    },
    {
      "x": -4,
      "y": 0,
      "z": 2,
      "name": "Rock_Quartzite_Brick"
    },
    {
      "x": -4,
      "y": 1,
      "z": 2,
      "name": "Empty"
    },
    {
      "x": -4,
      "y": 2,
      "z": 2,
      "name": "Empty"
    },
    {
      "x": -4,
      "y": -2,
      "z": 3,
      "name": "Soil_Dirt"
    },
    {
      "x": -4,
      "y": -1,
      "z": 3,
      "name": "Soil_Dirt"
    },
    {
      "x": -4,
      "y": 0,
      "z": 3,
      "name": "Rock_Quartzite_Brick"
    },
    {
      "x": -4,
      "y": 1,
      "z": 3,
      "name": "Plant_Moss_Rug_Green",
      "support": 15
    },
    {
      "x": -4,
      "y": 2,
      "z": 3,
      "name": "Empty"
    },
    {
      "x": -4,
      "y": -2,
      "z": 4,
      "name": "Soil_Dirt"
    },
    {
      "x": -4,
      "y": -1,
      "z": 4,
      "name": "Soil_Dirt"
    },
    {
      "x": -4,
      "y": 0,
      "z": 4,
      "name": "Rock_Quartzite_Brick"
    },
    {
      "x": -4,
      "y": 1,
      "z": 4,
      "name": "Plant_Moss_Rug_Green",
      "support": 15
    },
    {
      "x": -4,
      "y": 2,
      "z": 4,
      "name": "Empty"
    },
    {
      "x": -4,
      "y": -1,
      "z": 5,
      "name": "Soil_Dirt"
    },
    {
      "x": -4,
      "y": 0,
      "z": 5,
      "name": "Rock_Quartzite_Brick"
    },
    {
      "x": -4,
      "y": 1,
      "z": 5,
      "name": "Empty"
    },
    {
      "x": -4,
      "y": 2,
      "z": 5,
      "name": "Empty"
    },
    {
      "x": -4,
      "y": -1,
      "z": 6,
      "name": "Soil_Dirt"
    },
    {
      "x": -4,
      "y": 0,
      "z": 6,
      "name": "Soil_Grass"
    },
    {
      "x": -4,
      "y": 1,
      "z": 6,
      "name": "Empty"
    },
    {
      "x": -4,
      "y": 2,
      "z": 6,
      "name": "Empty"
    },
    {
      "x": -4,
      "y": -1,
      "z": 7,
      "name": "Soil_Dirt"
    },
    {
      "x": -4,
      "y": 0,
      "z": 7,
      "name": "Soil_Grass"
    },
    {
      "x": -4,
      "y": 1,
      "z": 7,
      "name": "Empty"
    },
    {
      "x": -4,
      "y": 2,
      "z": 7,
      "name": "Empty"
    },
    {
      "x": -4,
      "y": 0,
      "z": 8,
      "name": "Soil_Grass"
    },
    {
      "x": -3,
      "y": 0,
      "z": -5,
      "name": "Soil_Grass"
    },
    {
      "x": -3,
      "y": 1,
      "z": -5,
      "name": "Rock_Quartzite_Brick_Pillar_Base",
      "rotation": 4
    },
    {
      "x": -3,
      "y": 2,
      "z": -5,
      "name": "Empty"
    },
    {
      "x": -3,
      "y": 0,
      "z": -4,
      "name": "Soil_Grass"
    },
    {
      "x": -3,
      "y": 1,
      "z": -4,
      "name": "Rubble_Quartzite_Medium",
      "support": 15
    },
    {
      "x": -3,
      "y": 2,
      "z": -4,
      "name": "Empty"
    },
    {
      "x": -3,
      "y": 0,
      "z": -3,
      "name": "Soil_Grass"
    },
    {
      "x": -3,
      "y": 1,
      "z": -3,
      "name": "Rock_Quartzite_Brick_Pillar_Middle",
      "rotation": 6
    },
    {
      "x": -3,
      "y": 2,
      "z": -3,
      "name": "Empty"
    },
    {
      "x": -3,
      "y": 0,
      "z": -2,
      "name": "Soil_Grass"
    },
    {
      "x": -3,
      "y": 1,
      "z": -2,
      "name": "Rock_Quartzite_Brick_Pillar_Middle",
      "rotation": 6
    },
    {
      "x": -3,
      "y": 2,
      "z": -2,
      "name": "Empty"
    },
    {
      "x": -3,
      "y": -1,
      "z": -1,
      "name": "Soil_Dirt"
    },
    {
      "x": -3,
      "y": 0,
      "z": -1,
      "name": "Soil_Grass"
    },
    {
      "x": -3,
      "y": 1,
      "z": -1,
      "name": "Rock_Quartzite_Brick_Pillar_Base",
      "rotation": 6
    },
    {
      "x": -3,
      "y": 2,
      "z": -1,
      "name": "Empty"
    },
    {
      "x": -3,
      "y": -2,
      "z": 0,
      "name": "Soil_Dirt"
    },
    {
      "x": -3,
      "y": -1,
      "z": 0,
      "name": "Soil_Dirt"
    },
    {
      "x": -3,
      "y": 0,
      "z": 0,
      "name": "Rock_Quartzite_Brick"
    },
    {
      "x": -3,
      "y": 1,
      "z": 0,
      "name": "Empty"
    },
    {
      "x": -3,
      "y": 2,
      "z": 0,
      "name": "Empty"
    },
    {
      "x": -3,
      "y": -2,
      "z": 1,
      "name": "Soil_Dirt"
    },
    {
      "x": -3,
      "y": -1,
      "z": 1,
      "name": "Soil_Dirt"
    },
    {
      "x": -3,
      "y": 0,
      "z": 1,
      "name": "Rock_Quartzite_Brick"
    },
    {
      "x": -3,
      "y": 1,
      "z": 1,
      "name": "Empty"
    },
    {
      "x": -3,
      "y": 2,
      "z": 1,
      "name": "Empty"
    },
    {
      "x": -3,
      "y": -2,
      "z": 2,
      "name": "Soil_Dirt"
    },
    {
      "x": -3,
      "y": -1,
      "z": 2,
      "name": "Soil_Dirt"
    },
    {
      "x": -3,
      "y": 0,
      "z": 2,
      "name": "Rock_Quartzite_Brick_Ornate"
    },
    {
      "x": -3,
      "y": 1,
      "z": 2,
      "name": "Rock_Quartzite_Brick_Wall",
      "rotation": 1
    },
    {
      "x": -3,
      "y": 2,
      "z": 2,
      "name": "Empty"
    },
    {
      "x": -3,
      "y": -2,
      "z": 3,
      "name": "Soil_Dirt"
    },
    {
      "x": -3,
      "y": -1,
      "z": 3,
      "name": "Soil_Dirt"
    },
    {
      "x": -3,
      "y": 0,
      "z": 3,
      "name": "Rock_Quartzite_Brick_Ornate"
    },
    {
      "x": -3,
      "y": 1,
      "z": 3,
      "name": "Rock_Quartzite_Brick_Wall",
      "rotation": 3
    },
    {
      "x": -3,
      "y": 2,
      "z": 3,
      "name": "Deco_Lantern"
    },
    {
      "x": -3,
      "y": -2,
      "z": 4,
      "name": "Soil_Dirt"
    },
    {
      "x": -3,
      "y": -1,
      "z": 4,
      "name": "Soil_Dirt"
    },
    {
      "x": -3,
      "y": 0,
      "z": 4,
      "name": "Rock_Quartzite_Brick_Ornate"
    },
    {
      "x": -3,
      "y": 1,
      "z": 4,
      "name": "Rubble_Quartzite",
      "support": 15
    },
    {
      "x": -3,
      "y": 2,
      "z": 4,
      "name": "Empty"
    },
    {
      "x": -3,
      "y": -2,
      "z": 5,
      "name": "Soil_Dirt"
    },
    {
      "x": -3,
      "y": -1,
      "z": 5,
      "name": "Soil_Dirt"
    },
    {
      "x": -3,
      "y": 0,
      "z": 5,
      "name": "Rock_Quartzite_Brick"
    },
    {
      "x": -3,
      "y": 1,
      "z": 5,
      "name": "Empty"
    },
    {
      "x": -3,
      "y": 2,
      "z": 5,
      "name": "Empty"
    },
    {
      "x": -3,
      "y": -2,
      "z": 6,
      "name": "Soil_Dirt"
    },
    {
      "x": -3,
      "y": -1,
      "z": 6,
      "name": "Soil_Dirt"
    },
    {
      "x": -3,
      "y": 0,
      "z": 6,
      "name": "Rock_Quartzite_Brick"
    },
    {
      "x": -3,
      "y": 1,
      "z": 6,
      "name": "Rock_Quartzite_Brick_Pillar_Base"
    },
    {
      "x": -3,
      "y": 2,
      "z": 6,
      "name": "Rock_Quartzite_Brick_Pillar_Middle"
    },
    {
      "x": -3,
      "y": 3,
      "z": 6,
      "name": "Rubble_Quartzite_Medium",
      "support": 15
    },
    {
      "x": -3,
      "y": -1,
      "z": 7,
      "name": "Soil_Dirt"
    },
    {
      "x": -3,
      "y": 0,
      "z": 7,
      "name": "Soil_Grass"
    },
    {
      "x": -3,
      "y": 1,
      "z": 7,
      "name": "Empty"
    },
    {
      "x": -3,
      "y": 2,
      "z": 7,
      "name": "Empty"
    },
    {
      "x": -3,
      "y": -1,
      "z": 8,
      "name": "Soil_Dirt"
    },
    {
      "x": -3,
      "y": 0,
      "z": 8,
      "name": "Soil_Grass"
    },
    {
      "x": -3,
      "y": 0,
      "z": 9,
      "name": "Soil_Grass"
    },
    {
      "x": -2,
      "y": 0,
      "z": -6,
      "name": "Soil_Grass"
    },
    {
      "x": -2,
      "y": 0,
      "z": -5,
      "name": "Soil_Grass"
    },
    {
      "x": -2,
      "y": 1,
      "z": -5,
      "name": "Empty"
    },
    {
      "x": -2,
      "y": 2,
      "z": -5,
      "name": "Empty"
    },
    {
      "x": -2,
      "y": -1,
      "z": -4,
      "name": "Soil_Dirt"
    },
    {
      "x": -2,
      "y": 0,
      "z": -4,
      "name": "Soil_Grass"
    },
    {
      "x": -2,
      "y": 1,
      "z": -4,
      "name": "Empty"
    },
    {
      "x": -2,
      "y": 2,
      "z": -4,
      "name": "Empty"
    },
    {
      "x": -2,
      "y": -2,
      "z": -3,
      "name": "Soil_Dirt"
    },
    {
      "x": -2,
      "y": -1,
      "z": -3,
      "name": "Soil_Dirt"
    },
    {
      "x": -2,
      "y": 0,
      "z": -3,
      "name": "Soil_Grass"
    },
    {
      "x": -2,
      "y": 1,
      "z": -3,
      "name": "Empty"
    },
    {
      "x": -2,
      "y": 2,
      "z": -3,
      "name": "Empty"
    },
    {
      "x": -2,
      "y": -2,
      "z": -2,
      "name": "Soil_Dirt"
    },
    {
      "x": -2,
      "y": -1,
      "z": -2,
      "name": "Soil_Dirt"
    },
    {
      "x": -2,
      "y": 0,
      "z": -2,
      "name": "Soil_Grass"
    },
    {
      "x": -2,
      "y": 1,
      "z": -2,
      "name": "Empty"
    },
    {
      "x": -2,
      "y": 2,
      "z": -2,
      "name": "Empty"
    },
    {
      "x": -2,
      "y": -2,
      "z": -1,
      "name": "Soil_Dirt"
    },
    {
      "x": -2,
      "y": -1,
      "z": -1,
      "name": "Soil_Dirt"
    },
    {
      "x": -2,
      "y": 0,
      "z": -1,
      "name": "Soil_Grass"
    },
    {
      "x": -2,
      "y": 1,
      "z": -1,
      "name": "Empty"
    },
    {
      "x": -2,
      "y": 2,
      "z": -1,
      "name": "Empty"
    },
    {
      "x": -2,
      "y": -2,
      "z": 0,
      "name": "Soil_Dirt"
    },
    {
      "x": -2,
      "y": -1,
      "z": 0,
      "name": "Soil_Dirt"
    },
    {
      "x": -2,
      "y": 0,
      "z": 0,
      "name": "Rock_Quartzite_Brick"
    },
    {
      "x": -2,
      "y": 1,
      "z": 0,
      "name": "Plant_Moss_Rug_Green",
      "support": 15
    },
    {
      "x": -2,
      "y": 2,
      "z": 0,
      "name": "Empty"
    },
    {
      "x": -2,
      "y": -2,
      "z": 1,
      "name": "Soil_Dirt"
    },
    {
      "x": -2,
      "y": -1,
      "z": 1,
      "name": "Soil_Dirt"
    },
    {
      "x": -2,
      "y": 0,
      "z": 1,
      "name": "Rock_Quartzite_Brick_Ornate"
    },
    {
      "x": -2,
      "y": 1,
      "z": 1,
      "name": "Rubble_Quartzite",
      "support": 15
    },
    {
      "x": -2,
      "y": 2,
      "z": 1,
      "name": "Empty"
    },
    {
      "x": -2,
      "y": -2,
      "z": 2,
      "name": "Soil_Dirt"
    },
    {
      "x": -2,
      "y": -1,
      "z": 2,
      "name": "Soil_Dirt"
    },
    {
      "x": -2,
      "y": 0,
      "z": 2,
      "name": "Rock_Quartzite_Brick_Smooth"
    },
    {
      "x": -2,
      "y": 1,
      "z": 2,
      "name": "Empty"
    },
    {
      "x": -2,
      "y": 2,
      "z": 2,
      "name": "Empty"
    },
    {
      "x": -2,
      "y": -2,
      "z": 3,
      "name": "Soil_Dirt"
    },
    {
      "x": -2,
      "y": -1,
      "z": 3,
      "name": "Soil_Dirt"
    },
    {
      "x": -2,
      "y": 0,
      "z": 3,
      "name": "Rock_Quartzite_Brick_Smooth"
    },
    {
      "x": -2,
      "y": 1,
      "z": 3,
      "name": "Empty"
    },
    {
      "x": -2,
      "y": 2,
      "z": 3,
      "name": "Empty"
    },
    {
      "x": -2,
      "y": -2,
      "z": 4,
      "name": "Soil_Dirt"
    },
    {
      "x": -2,
      "y": -1,
      "z": 4,
      "name": "Soil_Dirt"
    },
    {
      "x": -2,
      "y": 0,
      "z": 4,
      "name": "Rock_Quartzite_Brick_Smooth"
    },
    {
      "x": -2,
      "y": 1,
      "z": 4,
      "name": "Empty"
    },
    {
      "x": -2,
      "y": 2,
      "z": 4,
      "name": "Empty"
    },
    {
      "x": -2,
      "y": -2,
      "z": 5,
      "name": "Soil_Dirt"
    },
    {
      "x": -2,
      "y": -1,
      "z": 5,
      "name": "Soil_Dirt"
    },
    {
      "x": -2,
      "y": 0,
      "z": 5,
      "name": "Rock_Quartzite_Brick_Ornate"
    },
    {
      "x": -2,
      "y": 1,
      "z": 5,
      "name": "Rubble_Quartzite",
      "support": 15
    },
    {
      "x": -2,
      "y": 2,
      "z": 5,
      "name": "Empty"
    },
    {
      "x": -2,
      "y": -2,
      "z": 6,
      "name": "Soil_Dirt"
    },
    {
      "x": -2,
      "y": -1,
      "z": 6,
      "name": "Soil_Dirt"
    },
    {
      "x": -2,
      "y": 0,
      "z": 6,
      "name": "Rock_Quartzite_Brick"
    },
    {
      "x": -2,
      "y": 1,
      "z": 6,
      "name": "Empty"
    },
    {
      "x": -2,
      "y": 2,
      "z": 6,
      "name": "Empty"
    },
    {
      "x": -2,
      "y": -2,
      "z": 7,
      "name": "Soil_Dirt"
    },
    {
      "x": -2,
      "y": -1,
      "z": 7,
      "name": "Soil_Dirt"
    },
    {
      "x": -2,
      "y": 0,
      "z": 7,
      "name": "Rock_Quartzite_Brick"
    },
    {
      "x": -2,
      "y": 1,
      "z": 7,
      "name": "Empty"
    },
    {
      "x": -2,
      "y": 2,
      "z": 7,
      "name": "Empty"
    },
    {
      "x": -2,
      "y": -1,
      "z": 8,
      "name": "Soil_Dirt"
    },
    {
      "x": -2,
      "y": 0,
      "z": 8,
      "name": "Soil_Grass"
    },
    {
      "x": -2,
      "y": 0,
      "z": 9,
      "name": "Soil_Grass"
    },
    {
      "x": -1,
      "y": -1,
      "z": -7,
      "name": "Soil_Dirt"
    },
    {
      "x": -1,
      "y": 0,
      "z": -7,
      "name": "Rock_Quartzite_Brick"
    },
    {
      "x": -1,
      "y": 1,
      "z": -7,
      "name": "Plant_Moss_Rug_Green",
      "support": 15
    },
    {
      "x": -1,
      "y": 2,
      "z": -7,
      "name": "Empty"
    },
    {
      "x": -1,
      "y": -1,
      "z": -6,
      "name": "Soil_Dirt"
    },
    {
      "x": -1,
      "y": 0,
      "z": -6,
      "name": "Rock_Quartzite_Brick"
    },
    {
      "x": -1,
      "y": 1,
      "z": -6,
      "name": "Empty"
    },
    {
      "x": -1,
      "y": 2,
      "z": -6,
      "name": "Empty"
    },
    {
      "x": -1,
      "y": -1,
      "z": -5,
      "name": "Soil_Dirt"
    },
    {
      "x": -1,
      "y": 0,
      "z": -5,
      "name": "Rock_Quartzite_Brick"
    },
    {
      "x": -1,
      "y": 1,
      "z": -5,
      "name": "Empty"
    },
    {
      "x": -1,
      "y": 2,
      "z": -5,
      "name": "Empty"
    },
    {
      "x": -1,
      "y": -2,
      "z": -4,
      "name": "Soil_Dirt"
    },
    {
      "x": -1,
      "y": -1,
      "z": -4,
      "name": "Soil_Dirt"
    },
    {
      "x": -1,
      "y": 0,
      "z": -4,
      "name": "Rock_Quartzite_Brick"
    },
    {
      "x": -1,
      "y": 1,
      "z": -4,
      "name": "Plant_Moss_Rug_Green",
      "support": 15
    },
    {
      "x": -1,
      "y": 2,
      "z": -4,
      "name": "Empty"
    },
    {
      "x": -1,
      "y": -2,
      "z": -3,
      "name": "Soil_Dirt"
    },
    {
      "x": -1,
      "y": -1,
      "z": -3,
      "name": "Soil_Dirt"
    },
    {
      "x": -1,
      "y": 0,
      "z": -3,
      "name": "Rock_Quartzite_Brick"
    },
    {
      "x": -1,
      "y": 1,
      "z": -3,
      "name": "Empty"
    },
    {
      "x": -1,
      "y": 2,
      "z": -3,
      "name": "Empty"
    },
    {
      "x": -1,
      "y": -2,
      "z": -2,
      "name": "Soil_Dirt"
    },
    {
      "x": -1,
      "y": -1,
      "z": -2,
      "name": "Soil_Dirt"
    },
    {
      "x": -1,
      "y": 0,
      "z": -2,
      "name": "Rock_Quartzite_Brick"
    },
    {
      "x": -1,
      "y": 1,
      "z": -2,
      "name": "Empty"
    },
    {
      "x": -1,
      "y": 2,
      "z": -2,
      "name": "Empty"
    },
    {
      "x": -1,
      "y": -2,
      "z": -1,
      "name": "Soil_Dirt"
    },
    {
      "x": -1,
      "y": -1,
      "z": -1,
      "name": "Soil_Dirt"
    },
    {
      "x": -1,
      "y": 0,
      "z": -1,
      "name": "Rock_Quartzite_Brick"
    },
    {
      "x": -1,
      "y": 1,
      "z": -1,
      "name": "Empty"
    },
    {
      "x": -1,
      "y": 2,
      "z": -1,
      "name": "Empty"
    },
    {
      "x": -1,
      "y": -2,
      "z": 0,
      "name": "Soil_Dirt"
    },
    {
      "x": -1,
      "y": -1,
      "z": 0,
      "name": "Soil_Dirt"
    },
    {
      "x": -1,
      "y": 0,
      "z": 0,
      "name": "Rock_Quartzite_Brick_Ornate"
    },
    {
      "x": -1,
      "y": 1,
      "z": 0,
      "name": "Empty"
    },
    {
      "x": -1,
      "y": 2,
      "z": 0,
      "name": "Empty"
    },
    {
      "x": -1,
      "y": -2,
      "z": 1,
      "name": "Soil_Dirt"
    },
    {
      "x": -1,
      "y": -1,
      "z": 1,
      "name": "Soil_Dirt"
    },
    {
      "x": -1,
      "y": 0,
      "z": 1,
      "name": "Rock_Quartzite_Brick_Smooth"
    },
    {
      "x": -1,
      "y": 1,
      "z": 1,
      "name": "Empty"
    },
    {
      "x": -1,
      "y": 2,
      "z": 1,
      "name": "Empty"
    },
    {
      "x": -1,
      "y": -2,
      "z": 2,
      "name": "Soil_Dirt"
    },
    {
      "x": -1,
      "y": -1,
      "z": 2,
      "name": "Soil_Dirt"
    },
    {
      "x": -1,
      "y": 0,
      "z": 2,
      "name": "Rock_Quartzite_Brick_Smooth"
    },
    {
      "x": -1,
      "y": 1,
      "z": 2,
      "name": "Leave_Instance",
      "filler": 1023,
      "rotation": 2
    },
    {
      "x": -1,
      "y": 2,
      "z": 2,
      "name": "Empty"
    },
    {
      "x": -1,
      "y": -2,
      "z": 3,
      "name": "Soil_Dirt"
    },
    {
      "x": -1,
      "y": -1,
      "z": 3,
      "name": "Soil_Dirt"
    },
    {
      "x": -1,
      "y": 0,
      "z": 3,
      "name": "Rock_Quartzite_Brick_Smooth"
    },
    {
      "x": -1,
      "y": 1,
      "z": 3,
      "name": "Leave_Instance",
      "filler": 31,
      "rotation": 2
    },
    {
      "x": -1,
      "y": 2,
      "z": 3,
      "name": "Empty"
    },
    {
      "x": -1,
      "y": -2,
      "z": 4,
      "name": "Soil_Dirt"
    },
    {
      "x": -1,
      "y": -1,
      "z": 4,
      "name": "Soil_Dirt"
    },
    {
      "x": -1,
      "y": 0,
      "z": 4,
      "name": "Rock_Quartzite_Brick_Smooth"
    },
    {
      "x": -1,
      "y": 1,
      "z": 4,
      "name": "Leave_Instance",
      "filler": 63,
      "rotation": 2
    },
    {
      "x": -1,
      "y": 2,
      "z": 4,
      "name": "Empty"
    },
    {
      "x": -1,
      "y": -2,
      "z": 5,
      "name": "Soil_Dirt"
    },
    {
      "x": -1,
      "y": -1,
      "z": 5,
      "name": "Soil_Dirt"
    },
    {
      "x": -1,
      "y": 0,
      "z": 5,
      "name": "Rock_Quartzite_Brick_Smooth"
    },
    {
      "x": -1,
      "y": 1,
      "z": 5,
      "name": "Empty"
    },
    {
      "x": -1,
      "y": 2,
      "z": 5,
      "name": "Empty"
    },
    {
      "x": -1,
      "y": -2,
      "z": 6,
      "name": "Soil_Dirt"
    },
    {
      "x": -1,
      "y": -1,
      "z": 6,
      "name": "Soil_Dirt"
    },
    {
      "x": -1,
      "y": 0,
      "z": 6,
      "name": "Rock_Quartzite_Brick_Ornate"
    },
    {
      "x": -1,
      "y": 1,
      "z": 6,
      "name": "Rock_Quartzite_Brick_Wall",
      "rotation": 2
    },
    {
      "x": -1,
      "y": 2,
      "z": 6,
      "name": "Empty"
    },
    {
      "x": -1,
      "y": -2,
      "z": 7,
      "name": "Soil_Dirt"
    },
    {
      "x": -1,
      "y": -1,
      "z": 7,
      "name": "Soil_Dirt"
    },
    {
      "x": -1,
      "y": 0,
      "z": 7,
      "name": "Rock_Quartzite_Brick"
    },
    {
      "x": -1,
      "y": 1,
      "z": 7,
      "name": "Empty"
    },
    {
      "x": -1,
      "y": 2,
      "z": 7,
      "name": "Empty"
    },
    {
      "x": -1,
      "y": -2,
      "z": 8,
      "name": "Soil_Dirt"
    },
    {
      "x": -1,
      "y": -1,
      "z": 8,
      "name": "Soil_Dirt"
    },
    {
      "x": -1,
      "y": 0,
      "z": 8,
      "name": "Soil_Grass"
    },
    {
      "x": -1,
      "y": -1,
      "z": 9,
      "name": "Soil_Dirt"
    },
    {
      "x": -1,
      "y": 0,
      "z": 9,
      "name": "Soil_Grass"
    },
    {
      "x": 0,
      "y": -1,
      "z": -7,
      "name": "Soil_Dirt"
    },
    {
      "x": 0,
      "y": 0,
      "z": -7,
      "name": "Rock_Quartzite_Brick"
    },
    {
      "x": 0,
      "y": 1,
      "z": -7,
      "name": "Empty"
    },
    {
      "x": 0,
      "y": 2,
      "z": -7,
      "name": "Empty"
    },
    {
      "x": 0,
      "y": -2,
      "z": -6,
      "name": "Soil_Dirt"
    },
    {
      "x": 0,
      "y": -1,
      "z": -6,
      "name": "Soil_Dirt"
    },
    {
      "x": 0,
      "y": 0,
      "z": -6,
      "name": "Rock_Quartzite_Brick"
    },
    {
      "x": 0,
      "y": 1,
      "z": -6,
      "name": "Plant_Moss_Rug_Green",
      "support": 15
    },
    {
      "x": 0,
      "y": 2,
      "z": -6,
      "name": "Empty"
    },
    {
      "x": 0,
      "y": -2,
      "z": -5,
      "name": "Soil_Dirt"
    },
    {
      "x": 0,
      "y": -1,
      "z": -5,
      "name": "Soil_Dirt"
    },
    {
      "x": 0,
      "y": 0,
      "z": -5,
      "name": "Rock_Quartzite_Brick"
    },
    {
      "x": 0,
      "y": 1,
      "z": -5,
      "name": "Empty"
    },
    {
      "x": 0,
      "y": 2,
      "z": -5,
      "name": "Empty"
    },
    {
      "x": 0,
      "y": -2,
      "z": -4,
      "name": "Soil_Dirt"
    },
    {
      "x": 0,
      "y": -1,
      "z": -4,
      "name": "Soil_Dirt"
    },
    {
      "x": 0,
      "y": 0,
      "z": -4,
      "name": "Rock_Quartzite_Brick"
    },
    {
      "x": 0,
      "y": 1,
      "z": -4,
      "name": "Plant_Moss_Rug_Green",
      "support": 15
    },
    {
      "x": 0,
      "y": 2,
      "z": -4,
      "name": "Empty"
    },
    {
      "x": 0,
      "y": -2,
      "z": -3,
      "name": "Soil_Dirt"
    },
    {
      "x": 0,
      "y": -1,
      "z": -3,
      "name": "Soil_Dirt"
    },
    {
      "x": 0,
      "y": 0,
      "z": -3,
      "name": "Rock_Quartzite_Brick"
    },
    {
      "x": 0,
      "y": 1,
      "z": -3,
      "name": "Plant_Moss_Rug_Green",
      "support": 15
    },
    {
      "x": 0,
      "y": 2,
      "z": -3,
      "name": "Empty"
    },
    {
      "x": 0,
      "y": -2,
      "z": -2,
      "name": "Soil_Dirt"
    },
    {
      "x": 0,
      "y": -1,
      "z": -2,
      "name": "Soil_Dirt"
    },
    {
      "x": 0,
      "y": 0,
      "z": -2,
      "name": "Rock_Quartzite_Brick"
    },
    {
      "x": 0,
      "y": 1,
      "z": -2,
      "name": "Empty"
    },
    {
      "x": 0,
      "y": 2,
      "z": -2,
      "name": "Empty"
    },
    {
      "x": 0,
      "y": -2,
      "z": -1,
      "name": "Soil_Dirt"
    },
    {
      "x": 0,
      "y": -1,
      "z": -1,
      "name": "Soil_Dirt"
    },
    {
      "x": 0,
      "y": 0,
      "z": -1,
      "name": "Rock_Quartzite_Brick_Smooth"
    },
    {
      "x": 0,
      "y": 1,
      "z": -1,
      "name": "Empty"
    },
    {
      "x": 0,
      "y": 2,
      "z": -1,
      "name": "Empty"
    },
    {
      "x": 0,
      "y": -2,
      "z": 0,
      "name": "Soil_Dirt"
    },
    {
      "x": 0,
      "y": -1,
      "z": 0,
      "name": "Soil_Dirt"
    },
    {
      "x": 0,
      "y": 0,
      "z": 0,
      "name": "Rock_Quartzite_Brick_Smooth"
    },
    {
      "x": 0,
      "y": 1,
      "z": 0,
      "name": "Empty"
    },
    {
      "x": 0,
      "y": 2,
      "z": 0,
      "name": "Empty"
    },
    {
      "x": 0,
      "y": -2,
      "z": 1,
      "name": "Soil_Dirt"
    },
    {
      "x": 0,
      "y": -1,
      "z": 1,
      "name": "Soil_Dirt"
    },
    {
      "x": 0,
      "y": 0,
      "z": 1,
      "name": "Rock_Quartzite_Brick_Smooth"
    },
    {
      "x": 0,
      "y": 1,
      "z": 1,
      "name": "Empty"
    },
    {
      "x": 0,
      "y": 2,
      "z": 1,
      "name": "Empty"
    },
    {
      "x": 0,
      "y": -2,
      "z": 2,
      "name": "Soil_Dirt"
    },
    {
      "x": 0,
      "y": -1,
      "z": 2,
      "name": "Soil_Dirt"
    },
    {
      "x": 0,
      "y": 0,
      "z": 2,
      "name": "Rock_Quartzite_Brick_Smooth"
    },
    {
      "x": 0,
      "y": 1,
      "z": 2,
      "name": "Leave_Instance",
      "filler": 992,
      "rotation": 2
    },
    {
      "x": 0,
      "y": 2,
      "z": 2,
      "name": "Empty"
    },
    {
      "x": 0,
      "y": -2,
      "z": 3,
      "name": "Soil_Dirt"
    },
    {
      "x": 0,
      "y": -1,
      "z": 3,
      "name": "Soil_Dirt"
    },
    {
      "x": 0,
      "y": 0,
      "z": 3,
      "name": "Rock_Quartzite_Brick"
    },
    {
      "x": 0,
      "y": 1,
      "z": 3,
      "name": "Leave_Instance",
      "rotation": 2
    },
    {
      "x": 0,
      "y": 2,
      "z": 3,
      "name": "Empty"
    },
    {
      "x": 0,
      "y": -2,
      "z": 4,
      "name": "Soil_Dirt"
    },
    {
      "x": 0,
      "y": -1,
      "z": 4,
      "name": "Soil_Dirt"
    },
    {
      "x": 0,
      "y": 0,
      "z": 4,
      "name": "Rock_Quartzite_Brick_Smooth"
    },
    {
      "x": 0,
      "y": 1,
      "z": 4,
      "name": "Leave_Instance",
      "filler": 32,
      "rotation": 2
    },
    {
      "x": 0,
      "y": 2,
      "z": 4,
      "name": "Empty"
    },
    {
      "x": 0,
      "y": -2,
      "z": 5,
      "name": "Soil_Dirt"
    },
    {
      "x": 0,
      "y": -1,
      "z": 5,
      "name": "Soil_Dirt"
    },
    {
      "x": 0,
      "y": 0,
      "z": 5,
      "name": "Rock_Quartzite_Brick_Smooth"
    },
    {
      "x": 0,
      "y": 1,
      "z": 5,
      "name": "Empty"
    },
    {
      "x": 0,
      "y": 2,
      "z": 5,
      "name": "Empty"
    },
    {
      "x": 0,
      "y": -2,
      "z": 6,
      "name": "Soil_Dirt"
    },
    {
      "x": 0,
      "y": -1,
      "z": 6,
      "name": "Soil_Dirt"
    },
    {
      "x": 0,
      "y": 0,
      "z": 6,
      "name": "Rock_Quartzite_Brick_Ornate"
    },
    {
      "x": 0,
      "y": 1,
      "z": 6,
      "name": "Rock_Quartzite_Brick_Wall",
      "rotation": 2
    },
    {
      "x": 0,
      "y": 2,
      "z": 6,
      "name": "Empty"
    },
    {
      "x": 0,
      "y": -2,
      "z": 7,
      "name": "Soil_Dirt"
    },
    {
      "x": 0,
      "y": -1,
      "z": 7,
      "name": "Soil_Dirt"
    },
    {
      "x": 0,
      "y": 0,
      "z": 7,
      "name": "Rock_Quartzite_Brick"
    },
    {
      "x": 0,
      "y": 1,
      "z": 7,
      "name": "Plant_Moss_Rug_Green",
      "support": 15
    },
    {
      "x": 0,
      "y": 2,
      "z": 7,
      "name": "Empty"
    },
    {
      "x": 0,
      "y": -2,
      "z": 8,
      "name": "Soil_Dirt"
    },
    {
      "x": 0,
      "y": -1,
      "z": 8,
      "name": "Soil_Dirt"
    },
    {
      "x": 0,
      "y": 0,
      "z": 8,
      "name": "Soil_Grass"
    },
    {
      "x": 0,
      "y": -1,
      "z": 9,
      "name": "Soil_Dirt"
    },
    {
      "x": 0,
      "y": 0,
      "z": 9,
      "name": "Soil_Grass"
    },
    {
      "x": 1,
      "y": -1,
      "z": -7,
      "name": "Soil_Dirt"
    },
    {
      "x": 1,
      "y": 0,
      "z": -7,
      "name": "Rock_Quartzite_Brick"
    },
    {
      "x": 1,
      "y": 1,
      "z": -7,
      "name": "Plant_Moss_Rug_Green",
      "support": 15
    },
    {
      "x": 1,
      "y": 2,
      "z": -7,
      "name": "Empty"
    },
    {
      "x": 1,
      "y": -1,
      "z": -6,
      "name": "Soil_Dirt"
    },
    {
      "x": 1,
      "y": 0,
      "z": -6,
      "name": "Rock_Quartzite_Brick"
    },
    {
      "x": 1,
      "y": 1,
      "z": -6,
      "name": "Plant_Moss_Rug_Green",
      "support": 15
    },
    {
      "x": 1,
      "y": 2,
      "z": -6,
      "name": "Empty"
    },
    {
      "x": 1,
      "y": -2,
      "z": -5,
      "name": "Soil_Dirt"
    },
    {
      "x": 1,
      "y": -1,
      "z": -5,
      "name": "Soil_Dirt"
    },
    {
      "x": 1,
      "y": 0,
      "z": -5,
      "name": "Rock_Quartzite_Brick"
    },
    {
      "x": 1,
      "y": 1,
      "z": -5,
      "name": "Plant_Moss_Rug_Green",
      "support": 15
    },
    {
      "x": 1,
      "y": 2,
      "z": -5,
      "name": "Empty"
    },
    {
      "x": 1,
      "y": -2,
      "z": -4,
      "name": "Soil_Dirt"
    },
    {
      "x": 1,
      "y": -1,
      "z": -4,
      "name": "Soil_Dirt"
    },
    {
      "x": 1,
      "y": 0,
      "z": -4,
      "name": "Rock_Quartzite_Brick"
    },
    {
      "x": 1,
      "y": 1,
      "z": -4,
      "name": "Empty"
    },
    {
      "x": 1,
      "y": 2,
      "z": -4,
      "name": "Empty"
    },
    {
      "x": 1,
      "y": -2,
      "z": -3,
      "name": "Soil_Dirt"
    },
    {
      "x": 1,
      "y": -1,
      "z": -3,
      "name": "Soil_Dirt"
    },
    {
      "x": 1,
      "y": 0,
      "z": -3,
      "name": "Rock_Quartzite_Brick"
    },
    {
      "x": 1,
      "y": 1,
      "z": -3,
      "name": "Empty"
    },
    {
      "x": 1,
      "y": 2,
      "z": -3,
      "name": "Empty"
    },
    {
      "x": 1,
      "y": -2,
      "z": -2,
      "name": "Soil_Dirt"
    },
    {
      "x": 1,
      "y": -1,
      "z": -2,
      "name": "Soil_Dirt"
    },
    {
      "x": 1,
      "y": 0,
      "z": -2,
      "name": "Rock_Quartzite_Brick"
    },
    {
      "x": 1,
      "y": 1,
      "z": -2,
      "name": "Empty"
    },
    {
      "x": 1,
      "y": 2,
      "z": -2,
      "name": "Empty"
    },
    {
      "x": 1,
      "y": -2,
      "z": -1,
      "name": "Soil_Dirt"
    },
    {
      "x": 1,
      "y": -1,
      "z": -1,
      "name": "Soil_Dirt"
    },
    {
      "x": 1,
      "y": 0,
      "z": -1,
      "name": "Rock_Quartzite_Brick"
    },
    {
      "x": 1,
      "y": 1,
      "z": -1,
      "name": "Empty"
    },
    {
      "x": 1,
      "y": 2,
      "z": -1,
      "name": "Empty"
    },
    {
      "x": 1,
      "y": -2,
      "z": 0,
      "name": "Soil_Dirt"
    },
    {
      "x": 1,
      "y": -1,
      "z": 0,
      "name": "Soil_Dirt"
    },
    {
      "x": 1,
      "y": 0,
      "z": 0,
      "name": "Rock_Quartzite_Brick_Ornate"
    },
    {
      "x": 1,
      "y": 1,
      "z": 0,
      "name": "Empty"
    },
    {
      "x": 1,
      "y": 2,
      "z": 0,
      "name": "Empty"
    },
    {
      "x": 1,
      "y": -2,
      "z": 1,
      "name": "Soil_Dirt"
    },
    {
      "x": 1,
      "y": -1,
      "z": 1,
      "name": "Soil_Dirt"
    },
    {
      "x": 1,
      "y": 0,
      "z": 1,
      "name": "Rock_Quartzite_Brick_Smooth"
    },
    {
      "x": 1,
      "y": 1,
      "z": 1,
      "name": "Empty"
    },
    {
      "x": 1,
      "y": 2,
      "z": 1,
      "name": "Empty"
    },
    {
      "x": 1,
      "y": -2,
      "z": 2,
      "name": "Soil_Dirt"
    },
    {
      "x": 1,
      "y": -1,
      "z": 2,
      "name": "Soil_Dirt"
    },
    {
      "x": 1,
      "y": 0,
      "z": 2,
      "name": "Rock_Quartzite_Brick_Smooth"
    },
    {
      "x": 1,
      "y": 1,
      "z": 2,
      "name": "Leave_Instance",
      "filler": 993,
      "rotation": 2
    },
    {
      "x": 1,
      "y": 2,
      "z": 2,
      "name": "Empty"
    },
    {
      "x": 1,
      "y": -2,
      "z": 3,
      "name": "Soil_Dirt"
    },
    {
      "x": 1,
      "y": -1,
      "z": 3,
      "name": "Soil_Dirt"
    },
    {
      "x": 1,
      "y": 0,
      "z": 3,
      "name": "Rock_Quartzite_Brick_Smooth"
    },
    {
      "x": 1,
      "y": 1,
      "z": 3,
      "name": "Leave_Instance",
      "filler": 1,
      "rotation": 2
    },
    {
      "x": 1,
      "y": 2,
      "z": 3,
      "name": "Empty"
    },
    {
      "x": 1,
      "y": -2,
      "z": 4,
      "name": "Soil_Dirt"
    },
    {
      "x": 1,
      "y": -1,
      "z": 4,
      "name": "Soil_Dirt"
    },
    {
      "x": 1,
      "y": 0,
      "z": 4,
      "name": "Rock_Quartzite_Brick_Smooth"
    },
    {
      "x": 1,
      "y": 1,
      "z": 4,
      "name": "Leave_Instance",
      "filler": 33,
      "rotation": 2
    },
    {
      "x": 1,
      "y": 2,
      "z": 4,
      "name": "Empty"
    },
    {
      "x": 1,
      "y": -2,
      "z": 5,
      "name": "Soil_Dirt"
    },
    {
      "x": 1,
      "y": -1,
      "z": 5,
      "name": "Soil_Dirt"
    },
    {
      "x": 1,
      "y": 0,
      "z": 5,
      "name": "Rock_Quartzite_Brick_Smooth"
    },
    {
      "x": 1,
      "y": 1,
      "z": 5,
      "name": "Empty"
    },
    {
      "x": 1,
      "y": 2,
      "z": 5,
      "name": "Empty"
    },
    {
      "x": 1,
      "y": -2,
      "z": 6,
      "name": "Soil_Dirt"
    },
    {
      "x": 1,
      "y": -1,
      "z": 6,
      "name": "Soil_Dirt"
    },
    {
      "x": 1,
      "y": 0,
      "z": 6,
      "name": "Rock_Quartzite_Brick_Ornate"
    },
    {
      "x": 1,
      "y": 1,
      "z": 6,
      "name": "Rock_Quartzite_Brick_Wall",
      "rotation": 2
    },
    {
      "x": 1,
      "y": 2,
      "z": 6,
      "name": "Empty"
    },
    {
      "x": 1,
      "y": -2,
      "z": 7,
      "name": "Soil_Dirt"
    },
    {
      "x": 1,
      "y": -1,
      "z": 7,
      "name": "Soil_Dirt"
    },
    {
      "x": 1,
      "y": 0,
      "z": 7,
      "name": "Rock_Quartzite_Brick"
    },
    {
      "x": 1,
      "y": 1,
      "z": 7,
      "name": "Empty"
    },
    {
      "x": 1,
      "y": 2,
      "z": 7,
      "name": "Empty"
    },
    {
      "x": 1,
      "y": -2,
      "z": 8,
      "name": "Soil_Dirt"
    },
    {
      "x": 1,
      "y": -1,
      "z": 8,
      "name": "Soil_Dirt"
    },
    {
      "x": 1,
      "y": 0,
      "z": 8,
      "name": "Soil_Grass"
    },
    {
      "x": 1,
      "y": 0,
      "z": 9,
      "name": "Soil_Grass"
    },
    {
      "x": 2,
      "y": 0,
      "z": -7,
      "name": "Soil_Grass"
    },
    {
      "x": 2,
      "y": 0,
      "z": -6,
      "name": "Soil_Grass"
    },
    {
      "x": 2,
      "y": -1,
      "z": -5,
      "name": "Soil_Dirt"
    },
    {
      "x": 2,
      "y": 0,
      "z": -5,
      "name": "Soil_Grass"
    },
    {
      "x": 2,
      "y": -1,
      "z": -4,
      "name": "Soil_Dirt"
    },
    {
      "x": 2,
      "y": 0,
      "z": -4,
      "name": "Soil_Grass"
    },
    {
      "x": 2,
      "y": -2,
      "z": -3,
      "name": "Soil_Dirt"
    },
    {
      "x": 2,
      "y": -1,
      "z": -3,
      "name": "Soil_Dirt"
    },
    {
      "x": 2,
      "y": 0,
      "z": -3,
      "name": "Soil_Grass"
    },
    {
      "x": 2,
      "y": -2,
      "z": -2,
      "name": "Soil_Dirt"
    },
    {
      "x": 2,
      "y": -1,
      "z": -2,
      "name": "Soil_Dirt"
    },
    {
      "x": 2,
      "y": 0,
      "z": -2,
      "name": "Soil_Grass"
    },
    {
      "x": 2,
      "y": -2,
      "z": -1,
      "name": "Soil_Dirt"
    },
    {
      "x": 2,
      "y": -1,
      "z": -1,
      "name": "Soil_Dirt"
    },
    {
      "x": 2,
      "y": 0,
      "z": -1,
      "name": "Rock_Quartzite_Brick"
    },
    {
      "x": 2,
      "y": 1,
      "z": -1,
      "name": "Rubble_Quartzite_Medium",
      "support": 15
    },
    {
      "x": 2,
      "y": 2,
      "z": -1,
      "name": "Empty"
    },
    {
      "x": 2,
      "y": -2,
      "z": 0,
      "name": "Soil_Dirt"
    },
    {
      "x": 2,
      "y": -1,
      "z": 0,
      "name": "Soil_Dirt"
    },
    {
      "x": 2,
      "y": 0,
      "z": 0,
      "name": "Rock_Quartzite_Brick"
    },
    {
      "x": 2,
      "y": 1,
      "z": 0,
      "name": "Empty"
    },
    {
      "x": 2,
      "y": 2,
      "z": 0,
      "name": "Empty"
    },
    {
      "x": 2,
      "y": -2,
      "z": 1,
      "name": "Soil_Dirt"
    },
    {
      "x": 2,
      "y": -1,
      "z": 1,
      "name": "Soil_Dirt"
    },
    {
      "x": 2,
      "y": 0,
      "z": 1,
      "name": "Rock_Quartzite_Brick_Ornate"
    },
    {
      "x": 2,
      "y": 1,
      "z": 1,
      "name": "Empty"
    },
    {
      "x": 2,
      "y": 2,
      "z": 1,
      "name": "Empty"
    },
    {
      "x": 2,
      "y": -2,
      "z": 2,
      "name": "Soil_Dirt"
    },
    {
      "x": 2,
      "y": -1,
      "z": 2,
      "name": "Soil_Dirt"
    },
    {
      "x": 2,
      "y": 0,
      "z": 2,
      "name": "Rock_Quartzite_Brick_Smooth"
    },
    {
      "x": 2,
      "y": 1,
      "z": 2,
      "name": "Empty"
    },
    {
      "x": 2,
      "y": 2,
      "z": 2,
      "name": "Empty"
    },
    {
      "x": 2,
      "y": -2,
      "z": 3,
      "name": "Soil_Dirt"
    },
    {
      "x": 2,
      "y": -1,
      "z": 3,
      "name": "Soil_Dirt"
    },
    {
      "x": 2,
      "y": 0,
      "z": 3,
      "name": "Rock_Quartzite_Brick_Smooth"
    },
    {
      "x": 2,
      "y": 1,
      "z": 3,
      "name": "Empty"
    },
    {
      "x": 2,
      "y": 2,
      "z": 3,
      "name": "Empty"
    },
    {
      "x": 2,
      "y": -2,
      "z": 4,
      "name": "Soil_Dirt"
    },
    {
      "x": 2,
      "y": -1,
      "z": 4,
      "name": "Soil_Dirt"
    },
    {
      "x": 2,
      "y": 0,
      "z": 4,
      "name": "Rock_Quartzite_Brick_Smooth"
    },
    {
      "x": 2,
      "y": 1,
      "z": 4,
      "name": "Empty"
    },
    {
      "x": 2,
      "y": 2,
      "z": 4,
      "name": "Empty"
    },
    {
      "x": 2,
      "y": -2,
      "z": 5,
      "name": "Soil_Dirt"
    },
    {
      "x": 2,
      "y": -1,
      "z": 5,
      "name": "Soil_Dirt"
    },
    {
      "x": 2,
      "y": 0,
      "z": 5,
      "name": "Rock_Quartzite_Brick_Ornate"
    },
    {
      "x": 2,
      "y": 1,
      "z": 5,
      "name": "Empty"
    },
    {
      "x": 2,
      "y": 2,
      "z": 5,
      "name": "Empty"
    },
    {
      "x": 2,
      "y": -2,
      "z": 6,
      "name": "Soil_Dirt"
    },
    {
      "x": 2,
      "y": -1,
      "z": 6,
      "name": "Soil_Dirt"
    },
    {
      "x": 2,
      "y": 0,
      "z": 6,
      "name": "Rock_Quartzite_Brick"
    },
    {
      "x": 2,
      "y": 1,
      "z": 6,
      "name": "Rubble_Quartzite_Medium",
      "support": 15
    },
    {
      "x": 2,
      "y": 2,
      "z": 6,
      "name": "Empty"
    },
    {
      "x": 2,
      "y": -2,
      "z": 7,
      "name": "Soil_Dirt"
    },
    {
      "x": 2,
      "y": -1,
      "z": 7,
      "name": "Soil_Dirt"
    },
    {
      "x": 2,
      "y": 0,
      "z": 7,
      "name": "Rock_Quartzite_Brick"
    },
    {
      "x": 2,
      "y": 1,
      "z": 7,
      "name": "Empty"
    },
    {
      "x": 2,
      "y": 2,
      "z": 7,
      "name": "Empty"
    },
    {
      "x": 2,
      "y": -1,
      "z": 8,
      "name": "Soil_Dirt"
    },
    {
      "x": 2,
      "y": 0,
      "z": 8,
      "name": "Soil_Grass"
    },
    {
      "x": 3,
      "y": 0,
      "z": -5,
      "name": "Soil_Grass"
    },
    {
      "x": 3,
      "y": 0,
      "z": -4,
      "name": "Soil_Grass"
    },
    {
      "x": 3,
      "y": 0,
      "z": -3,
      "name": "Soil_Grass"
    },
    {
      "x": 3,
      "y": -1,
      "z": -2,
      "name": "Soil_Dirt"
    },
    {
      "x": 3,
      "y": 0,
      "z": -2,
      "name": "Soil_Grass"
    },
    {
      "x": 3,
      "y": -1,
      "z": -1,
      "name": "Soil_Dirt"
    },
    {
      "x": 3,
      "y": 0,
      "z": -1,
      "name": "Soil_Grass"
    },
    {
      "x": 3,
      "y": 1,
      "z": -1,
      "name": "Empty"
    },
    {
      "x": 3,
      "y": 2,
      "z": -1,
      "name": "Empty"
    },
    {
      "x": 3,
      "y": -2,
      "z": 0,
      "name": "Soil_Dirt"
    },
    {
      "x": 3,
      "y": -1,
      "z": 0,
      "name": "Soil_Dirt"
    },
    {
      "x": 3,
      "y": 0,
      "z": 0,
      "name": "Rock_Quartzite_Brick"
    },
    {
      "x": 3,
      "y": 1,
      "z": 0,
      "name": "Rock_Quartzite_Brick_Pillar_Base"
    },
    {
      "x": 3,
      "y": 2,
      "z": 0,
      "name": "Rock_Quartzite_Brick_Pillar_Middle"
    },
    {
      "x": 3,
      "y": 3,
      "z": 0,
      "name": "Rock_Quartzite_Brick_Pillar_Middle"
    },
    {
      "x": 3,
      "y": 4,
      "z": 0,
      "name": "Plant_Moss_Rug_Green",
      "support": 15
    },
    {
      "x": 3,
      "y": -2,
      "z": 1,
      "name": "Soil_Dirt"
    },
    {
      "x": 3,
      "y": -1,
      "z": 1,
      "name": "Soil_Dirt"
    },
    {
      "x": 3,
      "y": 0,
      "z": 1,
      "name": "Rock_Quartzite_Brick"
    },
    {
      "x": 3,
      "y": 1,
      "z": 1,
      "name": "Empty"
    },
    {
      "x": 3,
      "y": 2,
      "z": 1,
      "name": "Empty"
    },
    {
      "x": 3,
      "y": -2,
      "z": 2,
      "name": "Soil_Dirt"
    },
    {
      "x": 3,
      "y": -1,
      "z": 2,
      "name": "Soil_Dirt"
    },
    {
      "x": 3,
      "y": 0,
      "z": 2,
      "name": "Rock_Quartzite_Brick_Ornate"
    },
    {
      "x": 3,
      "y": 1,
      "z": 2,
      "name": "Rock_Quartzite_Brick_Wall",
      "rotation": 1
    },
    {
      "x": 3,
      "y": 2,
      "z": 2,
      "name": "Empty"
    },
    {
      "x": 3,
      "y": -2,
      "z": 3,
      "name": "Soil_Dirt"
    },
    {
      "x": 3,
      "y": -1,
      "z": 3,
      "name": "Soil_Dirt"
    },
    {
      "x": 3,
      "y": 0,
      "z": 3,
      "name": "Rock_Quartzite_Brick_Ornate"
    },
    {
      "x": 3,
      "y": 1,
      "z": 3,
      "name": "Rock_Quartzite_Brick_Wall",
      "rotation": 1
    },
    {
      "x": 3,
      "y": 2,
      "z": 3,
      "name": "Empty"
    },
    {
      "x": 3,
      "y": -2,
      "z": 4,
      "name": "Soil_Dirt"
    },
    {
      "x": 3,
      "y": -1,
      "z": 4,
      "name": "Soil_Dirt"
    },
    {
      "x": 3,
      "y": 0,
      "z": 4,
      "name": "Rock_Quartzite_Brick_Ornate"
    },
    {
      "x": 3,
      "y": 1,
      "z": 4,
      "name": "Rock_Quartzite_Brick_Wall",
      "rotation": 1
    },
    {
      "x": 3,
      "y": 2,
      "z": 4,
      "name": "Empty"
    },
    {
      "x": 3,
      "y": -2,
      "z": 5,
      "name": "Soil_Dirt"
    },
    {
      "x": 3,
      "y": -1,
      "z": 5,
      "name": "Soil_Dirt"
    },
    {
      "x": 3,
      "y": 0,
      "z": 5,
      "name": "Rock_Quartzite_Brick"
    },
    {
      "x": 3,
      "y": 1,
      "z": 5,
      "name": "Rubble_Quartzite",
      "support": 15
    },
    {
      "x": 3,
      "y": 2,
      "z": 5,
      "name": "Empty"
    },
    {
      "x": 3,
      "y": -2,
      "z": 6,
      "name": "Soil_Dirt"
    },
    {
      "x": 3,
      "y": -1,
      "z": 6,
      "name": "Soil_Dirt"
    },
    {
      "x": 3,
      "y": 0,
      "z": 6,
      "name": "Rock_Quartzite_Brick"
    },
    {
      "x": 3,
      "y": 1,
      "z": 6,
      "name": "Rock_Quartzite_Brick_Pillar_Base"
    },
    {
      "x": 3,
      "y": 2,
      "z": 6,
      "name": "Rock_Quartzite_Brick_Pillar_Middle"
    },
    {
      "x": 3,
      "y": -2,
      "z": 7,
      "name": "Soil_Dirt"
    },
    {
      "x": 3,
      "y": -1,
      "z": 7,
      "name": "Soil_Dirt"
    },
    {
      "x": 3,
      "y": 0,
      "z": 7,
      "name": "Soil_Grass"
    },
    {
      "x": 3,
      "y": 1,
      "z": 7,
      "name": "Empty"
    },
    {
      "x": 3,
      "y": 2,
      "z": 7,
      "name": "Empty"
    },
    {
      "x": 3,
      "y": 0,
      "z": 8,
      "name": "Soil_Grass"
    },
    {
      "x": 4,
      "y": 0,
      "z": -3,
      "name": "Soil_Grass"
    },
    {
      "x": 4,
      "y": 0,
      "z": -2,
      "name": "Soil_Grass"
    },
    {
      "x": 4,
      "y": -1,
      "z": -1,
      "name": "Soil_Dirt"
    },
    {
      "x": 4,
      "y": 0,
      "z": -1,
      "name": "Soil_Grass"
    },
    {
      "x": 4,
      "y": 1,
      "z": -1,
      "name": "Empty"
    },
    {
      "x": 4,
      "y": 2,
      "z": -1,
      "name": "Empty"
    },
    {
      "x": 4,
      "y": -1,
      "z": 0,
      "name": "Soil_Dirt"
    },
    {
      "x": 4,
      "y": 0,
      "z": 0,
      "name": "Soil_Grass"
    },
    {
      "x": 4,
      "y": 1,
      "z": 0,
      "name": "Empty"
    },
    {
      "x": 4,
      "y": 2,
      "z": 0,
      "name": "Empty"
    },
    {
      "x": 4,
      "y": -2,
      "z": 1,
      "name": "Soil_Dirt"
    },
    {
      "x": 4,
      "y": -1,
      "z": 1,
      "name": "Soil_Dirt"
    },
    {
      "x": 4,
      "y": 0,
      "z": 1,
      "name": "Rock_Quartzite_Brick"
    },
    {
      "x": 4,
      "y": 1,
      "z": 1,
      "name": "Rubble_Quartzite_Medium",
      "support": 15
    },
    {
      "x": 4,
      "y": 2,
      "z": 1,
      "name": "Empty"
    },
    {
      "x": 4,
      "y": -1,
      "z": 2,
      "name": "Soil_Dirt"
    },
    {
      "x": 4,
      "y": 0,
      "z": 2,
      "name": "Rock_Quartzite_Brick"
    },
    {
      "x": 4,
      "y": 1,
      "z": 2,
      "name": "Rock_Quartzite_Brick_Pillar_Base",
      "rotation": 4
    },
    {
      "x": 4,
      "y": 2,
      "z": 2,
      "name": "Empty"
    },
    {
      "x": 4,
      "y": -2,
      "z": 3,
      "name": "Soil_Dirt"
    },
    {
      "x": 4,
      "y": -1,
      "z": 3,
      "name": "Soil_Dirt"
    },
    {
      "x": 4,
      "y": 0,
      "z": 3,
      "name": "Rock_Quartzite_Brick"
    },
    {
      "x": 4,
      "y": 1,
      "z": 3,
      "name": "Rock_Quartzite_Brick_Pillar_Middle",
      "rotation": 4
    },
    {
      "x": 4,
      "y": 2,
      "z": 3,
      "name": "Empty"
    },
    {
      "x": 4,
      "y": -2,
      "z": 4,
      "name": "Soil_Dirt"
    },
    {
      "x": 4,
      "y": -1,
      "z": 4,
      "name": "Soil_Dirt"
    },
    {
      "x": 4,
      "y": 0,
      "z": 4,
      "name": "Rock_Quartzite_Brick"
    },
    {
      "x": 4,
      "y": 1,
      "z": 4,
      "name": "Rubble_Quartzite_Medium",
      "support": 15
    },
    {
      "x": 4,
      "y": 2,
      "z": 4,
      "name": "Empty"
    },
    {
      "x": 4,
      "y": -2,
      "z": 5,
      "name": "Soil_Dirt"
    },
    {
      "x": 4,
      "y": -1,
      "z": 5,
      "name": "Soil_Dirt"
    },
    {
      "x": 4,
      "y": 0,
      "z": 5,
      "name": "Rock_Quartzite_Brick"
    },
    {
      "x": 4,
      "y": 1,
      "z": 5,
      "name": "Empty"
    },
    {
      "x": 4,
      "y": 2,
      "z": 5,
      "name": "Empty"
    },
    {
      "x": 4,
      "y": -2,
      "z": 6,
      "name": "Soil_Dirt"
    },
    {
      "x": 4,
      "y": -1,
      "z": 6,
      "name": "Soil_Dirt"
    },
    {
      "x": 4,
      "y": 0,
      "z": 6,
      "name": "Soil_Grass"
    },
    {
      "x": 4,
      "y": 1,
      "z": 6,
      "name": "Empty"
    },
    {
      "x": 4,
      "y": 2,
      "z": 6,
      "name": "Empty"
    },
    {
      "x": 4,
      "y": -1,
      "z": 7,
      "name": "Soil_Dirt"
    },
    {
      "x": 4,
      "y": 0,
      "z": 7,
      "name": "Soil_Grass"
    },
    {
      "x": 4,
      "y": 1,
      "z": 7,
      "name": "Empty"
    },
    {
      "x": 4,
      "y": 2,
      "z": 7,
      "name": "Empty"
    },
    {
      "x": 5,
      "y": 0,
      "z": -1,
      "name": "Soil_Grass"
    },
    {
      "x": 5,
      "y": 0,
      "z": 0,
      "name": "Soil_Grass"
    },
    {
      "x": 5,
      "y": -1,
      "z": 1,
      "name": "Soil_Dirt"
    },
    {
      "x": 5,
      "y": 0,
      "z": 1,
      "name": "Soil_Grass"
    },
    {
      "x": 5,
      "y": 0,
      "z": 2,
      "name": "Soil_Grass"
    },
    {
      "x": 5,
      "y": -1,
      "z": 3,
      "name": "Soil_Dirt"
    },
    {
      "x": 5,
      "y": 0,
      "z": 3,
      "name": "Soil_Grass"
    },
    {
      "x": 5,
      "y": -2,
      "z": 4,
      "name": "Soil_Dirt"
    },
    {
      "x": 5,
      "y": -1,
      "z": 4,
      "name": "Soil_Dirt"
    },
    {
      "x": 5,
      "y": 0,
      "z": 4,
      "name": "Soil_Grass"
    },
    {
      "x": 5,
      "y": -1,
      "z": 5,
      "name": "Soil_Dirt"
    },
    {
      "x": 5,
      "y": 0,
      "z": 5,
      "name": "Soil_Grass"
    },
    {
      "x": 5,
      "y": 0,
      "z": 6,
      "name": "Soil_Grass"
    }
  ]
}