{
  "version": 8,
  "blockIdVersion": 11,
  "anchorX": 0,
  "anchorY": 0,
  "anchorZ": 0,
  "blocks": [
    {
      "x": -1,
      "y": -2,
      "z": -1,
      "name": "Rock_Slate_Stalactite_Large",
      "filler": 31744,
      "rotation": 8
    },
    {
      "x": -1,
      "y": -1,
      "z": -1,
      "name": "Rock_Slate_Stalactite_Large",
      "rotation": 8
    },
    {
      "x": -1,
      "y": 0,
      "z": -1,
      "name": "Rock_Slate",
      "rotation": 3
    },
    {
      "x": -1,
      "y": 1,
      "z": -1,
      "name": "Rock_Slate",
      "rotation": 3
    },
    {
      "x": -1,
      "y": 2,
      "z": -1,
      "name": "Rock_Slate_Cobble",
      "rotation": 3
    },
    {
      "x": -1,
      "y": -4,
      "z": 0,
      "name": "Rock_Slate_Stalactite_Large",
      "filler": 31744,
      "rotation": 8
    },
    {
      "x": -1,
      "y": -3,
      "z": 0,
      "name": "Rock_Slate_Stalactite_Large",
      "rotation": 8
    },
    {
      "x": -1,
      "y": -2,
      "z": 0,
      "name": "Rock_Slate_Cobble",
      "rotation": 3
    },
    {
      "x": -1,
      "y": -1,
      "z": 0,
      "name": "Rock_Slate",
      "rotation": 3
    },
    {
      "x": -1,
      "y": 0,
      "z": 0,
      "name": "Rock_Slate",
      "rotation": 3
    },
    {
      "x": -1,
      "y": 1,
      "z": 0,
      "name": "Rock_Slate",
      "rotation": 3
    },
    {
      "x": -1,
      "y": 2,
      "z": 0,
      "name": "Rock_Slate_Cobble",
      "rotation": 3
    },
    {
      "x": -1,
      "y": -2,
      "z": 1,
      "name": "Rock_Slate_Stalactite_Small",
      "rotation": 8
    },
    {
      "x": -1,
      "y": -1,
      "z": 1,
      "name": "Rock_Slate",
      "rotation": 3
    },
    {
      "x": -1,
      "y": 0,
      "z": 1,
      "name": "Rock_Slate",
      "rotation": 3
    },
    {
      "x": -1,
      "y": 1,
      "z": 1,
      "name": "Rock_Slate",
      "rotation": 3
    },
    {
      "x": -1,
      "y": 2,
      "z": 1,
      "name": "Rock_Slate_Cobble",
      "rotation": 3
    },
    {
      "x": 0,
      "y": -4,
      "z": -1,
      "name": "Rock_Slate_Stalactite_Large",
      "filler": 31744,
      "rotation": 8
    },
    {
      "x": 0,
      "y": -3,
      "z": -1,
      "name": "Rock_Slate_Stalactite_Large",
      "rotation": 8
    },
    {
      "x": 0,
      "y": -2,
      "z": -1,
      "name": "Rock_Slate_Cobble",
      "rotation": 3
    },
    {
      "x": 0,
      "y": -1,
      "z": -1,
      "name": "Rock_Slate",
      "rotation": 3
    },
    {
      "x": 0,
      "y": 0,
      "z": -1,
      "name": "Rock_Slate",
      "rotation": 3
    },
    {
      "x": 0,
      "y": 1,
      "z": -1,
      "name": "Rock_Slate",
      "rotation": 3
    },
    {
      "x": 0,
      "y": 2,
      "z": -1,
      "name": "Rock_Slate_Cobble",
      "rotation": 3
    },
    {
      "x": 0,
      "y": -7,
      "z": 0,
      "name": "Rock_Slate_Stalactite_Large",
      "filler": 31744,
      "rotation": 8
    },
    {
      "x": 0,
      "y": -6,
      "z": 0,
      "name": "Rock_Slate_Stalactite_Large",
      "rotation": 8
    },
    {
      "x": 0,
      "y": -5,
      "z": 0,
      "name": "Rock_Slate_Cobble",
      "rotation": 3
    },
    {
      "x": 0,
      "y": -4,
      "z": 0,
      "name": "Rock_Slate_Cobble",
      "rotation": 3
    },
    {
      "x": 0,
      "y": -3,
      "z": 0,
      "name": "Rock_Slate_Cobble",
      "rotation": 3
    },
    {
      "x": 0,
      "y": -2,
      "z": 0,
      "name": "Rock_Slate_Cobble",
      "rotation": 3
    },
    {
      "x": 0,
      "y": -1,
      "z": 0,
      "name": "Rock_Slate",
      "rotation": 3
    },
    {
      "x": 0,
      "y": 0,
      "z": 0,
      "name": "Rock_Slate",
      "rotation": 3
    },
    {
      "x": 0,
      "y": 1,
      "z": 0,
      "name": "Rock_Slate",
      "rotation": 3
    },
    {
      "x": 0,
      "y": 2,
      "z": 0,
      "name": "Rock_Slate_Cobble",
      "rotation": 3
    },
    {
      "x": 0,
      "y": -4,
      "z": 1,
      "name": "Rock_Slate_Stalactite_Small",
      "rotation": 8
    },
    {
      "x": 0,
      "y": -3,
      "z": 1,
      "name": "Rock_Slate_Cobble",
      "rotation": 3
    },
    {
      "x": 0,
      "y": -2,
      "z": 1,
      "name": "Rock_Slate_Cobble",
      "rotation": 3
    },
    {
      "x": 0,
      "y": -1,
      "z": 1,
      "name": "Rock_Slate",
      "rotation": 3
    },
    {
      "x": 0,
      "y": 0,
      "z": 1,
      "name": "Rock_Slate",
      "rotation": 3
    },
    {
      "x": 0,
      "y": 1,
      "z": 1,
      "name": "Rock_Slate",
      "rotation": 3
    },
    {
      "x": 0,
      "y": 2,
      "z": 1,
      "name": "Rock_Slate_Cobble",
      "rotation": 3
    },
    {
      "x": 1,
      "y": -2,
      "z": -1,
      "name": "Rock_Slate_Stalactite_Small",
      "rotation": 8
    },
    {
      "x": 1,
      "y": -1,
      "z": -1,
      "name": "Rock_Slate",
      "rotation": 3
    },
    {
      "x": 1,
      "y": 0,
      "z": -1,
      "name": "Rock_Slate",
      "rotation": 3
    },
    {
      "x": 1,
      "y": 1,
      "z": -1,
      "name": "Rock_Slate",
      "rotation": 3
    },
    {
      "x": 1,
      "y": 2,
      "z": -1,
      "name": "Rock_Slate_Cobble",
      "rotation": 3
    },
    {
      "x": 1,
      "y": -5,
      "z": 0,
      "name": "Rock_Slate_Stalactite_Large",
      "filler": 31744,
      "rotation": 8
    },
    {
      "x": 1,
      "y": -4,
      "z": 0,
      "name": "Rock_Slate_Stalactite_Large",
      "rotation": 8
    },
    {
      "x": 1,
      "y": -3,
      "z": 0,
      "name": "Rock_Slate_Cobble",
      "rotation": 3
    },
    {
      "x": 1,
      "y": -2,
      "z": 0,
      "name": "Rock_Slate_Cobble",
      "rotation": 3
    },
    {
      "x": 1,
      "y": -1,
      "z": 0,
      "name": "Rock_Slate",
      "rotation": 3
    },
    {
      "x": 1,
      "y": 0,
      "z": 0,
      "name": "Rock_Slate",
      "rotation": 3
    },
    {
      "x": 1,
      "y": 1,
      "z": 0,
      "name": "Rock_Slate",
      "rotation": 3
    },
    {
      "x": 1,
      "y": 2,
      "z": 0,
      "name": "Rock_Slate_Cobble",
      "rotation": 3
    },
    {
      "x": 1,
      "y": -3,
      "z": 1,
      "name": "Rock_Slate_Stalactite_Small",
      "rotation": 8
    },
    {
      "x": 1,
      "y": -2,
      "z": 1,
      "name": "Rock_Slate_Cobble",
      "rotation": 3
    },
    {
      "x": 1,
      "y": -1,
      "z": 1,
      "name": "Rock_Slate",
      "rotation": 3
    },
    {
      "x": 1,
      "y": 0,
      "z": 1,
      "name": "Rock_Slate",
      "rotation": 3
    },
    {
      "x": 1,
      "y": 1,
      "z": 1,
      "name": "Rock_Slate",
      "rotation": 3
    },
    {
      "x": 1,
      "y": 2,
      "z": 1,
      "name": "Rock_Slate_Cobble",
      "rotation": 3
    }
  ]
}