{
  "version": 8,
  "blockIdVersion": 11,
  "anchorX": 1,
  "anchorY": 7,
  "anchorZ": -7,
  "blocks": [
    {
      "x": -5,
      "y": 6,
      "z": -13,
      "name": "Soil_Pathway"
    },
    {
      "x": -5,
      "y": 7,
      "z": -13,
      "name": "Soil_Pathway"
    },
    {
      "x": -5,
      "y": 8,
      "z": -13,
      "name": "Soil_Pathway"
    },
    {
      "x": -5,
      "y": 6,
      "z": -12,
      "name": "Soil_Pathway"
    },
    {
      "x": -5,
      "y": 7,
      "z": -12,
      "name": "Soil_Pathway"
    },
    {
      "x": -5,
      "y": 8,
      "z": -12,
      "name": "Soil_Pathway"
    },
    {
      "x": -4,
      "y": 6,
      "z": -14,
      "name": "Soil_Pathway"
    },
    {
      "x": -4,
      "y": 7,
      "z": -14,
      "name": "Soil_Pathway"
    },
    {
      "x": -4,
      "y": 8,
      "z": -14,
      "name": "Soil_Pathway"
    },
    {
      "x": -4,
      "y": 6,
      "z": -13,
      "name": "Soil_Pathway"
    },
    {
      "x": -4,
      "y": 7,
      "z": -13,
      "name": "Soil_Pathway"
    },
    {
      "x": -4,
      "y": 8,
      "z": -13,
      "name": "Soil_Pathway"
    },
    {
      "x": -4,
      "y": 6,
      "z": -12,
      "name": "Soil_Pathway"
    },
    {
      "x": -4,
      "y": 7,
      "z": -12,
      "name": "Soil_Pathway"
    },
    {
      "x": -4,
      "y": 8,
      "z": -12,
      "name": "Soil_Pathway"
    },
    {
      "x": -4,
      "y": 6,
      "z": -11,
      "name": "Soil_Pathway"
    },
    {
      "x": -4,
      "y": 7,
      "z": -11,
      "name": "Soil_Pathway"
    },
    {
      "x": -4,
      "y": 8,
      "z": -11,
      "name": "Soil_Pathway"
    },
    {
      "x": -4,
      "y": 6,
      "z": -10,
      "name": "Soil_Pathway"
    },
    {
      "x": -4,
      "y": 7,
      "z": -10,
      "name": "Soil_Pathway"
    },
    {
      "x": -4,
      "y": 8,
      "z": -10,
      "name": "Soil_Pathway"
    },
    {
      "x": -3,
      "y": 6,
      "z": -16,
      "name": "Soil_Pathway"
    },
    {
      "x": -3,
      "y": 7,
      "z": -16,
      "name": "Soil_Pathway"
    },
    {
      "x": -3,
      "y": 8,
      "z": -16,
      "name": "Wood_Bamboo_Branch_Long_Deco",
      "support": 15
    },
    {
      "x": -3,
      "y": 9,
      "z": -16,
      "name": "Wood_Bamboo_Branch_Long_Deco",
      "support": 15
    },
    {
      "x": -3,
      "y": 10,
      "z": -16,
      "name": "Wood_Bamboo_Branch_Long_Deco",
      "support": 15
    },
    {
      "x": -3,
      "y": 11,
      "z": -16,
      "name": "Wood_Bamboo_Branch_Long_Deco",
      "support": 15
    },
    {
      "x": -3,
      "y": 12,
      "z": -16,
      "name": "Wood_Bamboo_Trunk_Deco",
      "support": 15
    },
    {
      "x": -3,
      "y": 15,
      "z": -16,
      "name": "*Wood_Tropicalwood_Roof_Steep_State_Definitions_Corner_Right",
      "rotation": 3
    },
    {
      "x": -3,
      "y": 16,
      "z": -16,
      "name": "*Wood_Tropicalwood_Roof_Steep_State_Definitions_Corner_Right",
      "filler": 1024,
      "rotation": 3
    },
    {
      "x": -3,
      "y": 6,
      "z": -15,
      "name": "Soil_Pathway"
    },
    {
      "x": -3,
      "y": 7,
      "z": -15,
      "name": "Soil_Pathway"
    },
    {
      "x": -3,
      "y": 8,
      "z": -15,
      "name": "Soil_Pathway"
    },
    {
      "x": -3,
      "y": 12,
      "z": -15,
      "name": "Wood_Tropicalwood_Planks_Half",
      "rotation": 8
    },
    {
      "x": -3,
      "y": 15,
      "z": -15,
      "name": "Wood_Tropicalwood_Roof_Steep",
      "rotation": 3
    },
    {
      "x": -3,
      "y": 16,
      "z": -15,
      "name": "Wood_Tropicalwood_Roof_Steep",
      "filler": 1024,
      "rotation": 3
    },
    {
      "x": -3,
      "y": 6,
      "z": -14,
      "name": "Soil_Pathway"
    },
    {
      "x": -3,
      "y": 7,
      "z": -14,
      "name": "Soil_Pathway"
    },
    {
      "x": -3,
      "y": 8,
      "z": -14,
      "name": "Soil_Pathway"
    },
    {
      "x": -3,
      "y": 12,
      "z": -14,
      "name": "Wood_Tropicalwood_Planks_Half",
      "rotation": 8
    },
    {
      "x": -3,
      "y": 15,
      "z": -14,
      "name": "Wood_Tropicalwood_Roof_Steep",
      "rotation": 3
    },
    {
      "x": -3,
      "y": 16,
      "z": -14,
      "name": "Wood_Tropicalwood_Roof_Steep",
      "filler": 1024,
      "rotation": 3
    },
    {
      "x": -3,
      "y": 6,
      "z": -13,
      "name": "Soil_Pathway"
    },
    {
      "x": -3,
      "y": 7,
      "z": -13,
      "name": "Soil_Pathway"
    },
    {
      "x": -3,
      "y": 8,
      "z": -13,
      "name": "Soil_Pathway"
    },
    {
      "x": -3,
      "y": 12,
      "z": -13,
      "name": "Wood_Tropicalwood_Planks_Half",
      "rotation": 8
    },
    {
      "x": -3,
      "y": 15,
      "z": -13,
      "name": "Wood_Tropicalwood_Roof_Steep",
      "rotation": 3
    },
    {
      "x": -3,
      "y": 16,
      "z": -13,
      "name": "Wood_Tropicalwood_Roof_Steep",
      "filler": 1024,
      "rotation": 3
    },
    {
      "x": -3,
      "y": 6,
      "z": -12,
      "name": "Soil_Pathway"
    },
    {
      "x": -3,
      "y": 7,
      "z": -12,
      "name": "Soil_Pathway"
    },
    {
      "x": -3,
      "y": 8,
      "z": -12,
      "name": "Soil_Pathway"
    },
    {
      "x": -3,
      "y": 12,
      "z": -12,
      "name": "Wood_Tropicalwood_Planks_Half",
      "rotation": 8
    },
    {
      "x": -3,
      "y": 15,
      "z": -12,
      "name": "Wood_Tropicalwood_Roof_Steep",
      "rotation": 3
    },
    {
      "x": -3,
      "y": 16,
      "z": -12,
      "name": "Wood_Tropicalwood_Roof_Steep",
      "filler": 1024,
      "rotation": 3
    },
    {
      "x": -3,
      "y": 6,
      "z": -11,
      "name": "Soil_Pathway"
    },
    {
      "x": -3,
      "y": 7,
      "z": -11,
      "name": "Soil_Pathway"
    },
    {
      "x": -3,
      "y": 8,
      "z": -11,
      "name": "Soil_Pathway"
    },
    {
      "x": -3,
      "y": 12,
      "z": -11,
      "name": "Wood_Tropicalwood_Planks_Half",
      "rotation": 8
    },
    {
      "x": -3,
      "y": 15,
      "z": -11,
      "name": "Wood_Tropicalwood_Roof_Steep",
      "rotation": 3
    },
    {
      "x": -3,
      "y": 16,
      "z": -11,
      "name": "Wood_Tropicalwood_Roof_Steep",
      "filler": 1024,
      "rotation": 3
    },
    {
      "x": -3,
      "y": 6,
      "z": -10,
      "name": "Soil_Pathway"
    },
    {
      "x": -3,
      "y": 7,
      "z": -10,
      "name": "Soil_Pathway"
    },
    {
      "x": -3,
      "y": 8,
      "z": -10,
      "name": "Soil_Pathway"
    },
    {
      "x": -3,
      "y": 12,
      "z": -10,
      "name": "Wood_Tropicalwood_Planks_Half",
      "rotation": 8
    },
    {
      "x": -3,
      "y": 15,
      "z": -10,
      "name": "Wood_Tropicalwood_Roof_Steep",
      "rotation": 3
    },
    {
      "x": -3,
      "y": 16,
      "z": -10,
      "name": "Wood_Tropicalwood_Roof_Steep",
      "filler": 1024,
      "rotation": 3
    },
    {
      "x": -3,
      "y": 6,
      "z": -9,
      "name": "Soil_Pathway"
    },
    {
      "x": -3,
      "y": 7,
      "z": -9,
      "name": "Soil_Pathway"
    },
    {
      "x": -3,
      "y": 8,
      "z": -9,
      "name": "Soil_Pathway"
    },
    {
      "x": -3,
      "y": 12,
      "z": -9,
      "name": "Wood_Tropicalwood_Planks_Half",
      "rotation": 8
    },
    {
      "x": -3,
      "y": 15,
      "z": -9,
      "name": "*Wood_Tropicalwood_Roof_Steep_State_Definitions_Corner_Right"
    },
    {
      "x": -3,
      "y": 16,
      "z": -9,
      "name": "*Wood_Tropicalwood_Roof_Steep_State_Definitions_Corner_Right",
      "filler": 1024
    },
    {
      "x": -3,
      "y": 6,
      "z": -8,
      "name": "Soil_Pathway"
    },
    {
      "x": -3,
      "y": 7,
      "z": -8,
      "name": "Soil_Pathway"
    },
    {
      "x": -3,
      "y": 8,
      "z": -8,
      "name": "Wood_Bamboo_Branch_Long_Deco",
      "support": 15
    },
    {
      "x": -3,
      "y": 9,
      "z": -8,
      "name": "Wood_Bamboo_Branch_Long_Deco",
      "support": 15
    },
    {
      "x": -3,
      "y": 10,
      "z": -8,
      "name": "Wood_Bamboo_Branch_Long_Deco",
      "support": 15
    },
    {
      "x": -3,
      "y": 11,
      "z": -8,
      "name": "Wood_Bamboo_Branch_Long_Deco",
      "support": 15
    },
    {
      "x": -3,
      "y": 12,
      "z": -8,
      "name": "Wood_Bamboo_Trunk_Deco",
      "support": 15
    },
    {
      "x": -2,
      "y": 6,
      "z": -16,
      "name": "Soil_Pathway"
    },
    {
      "x": -2,
      "y": 7,
      "z": -16,
      "name": "Soil_Pathway"
    },
    {
      "x": -2,
      "y": 8,
      "z": -16,
      "name": "Soil_Pathway"
    },
    {
      "x": -2,
      "y": 12,
      "z": -16,
      "name": "Wood_Tropicalwood_Planks_Half",
      "rotation": 8
    },
    {
      "x": -2,
      "y": 15,
      "z": -16,
      "name": "Wood_Tropicalwood_Roof_Steep",
      "rotation": 2
    },
    {
      "x": -2,
      "y": 16,
      "z": -16,
      "name": "Wood_Tropicalwood_Roof_Steep",
      "filler": 1024,
      "rotation": 2
    },
    {
      "x": -2,
      "y": 6,
      "z": -15,
      "name": "Soil_Pathway"
    },
    {
      "x": -2,
      "y": 7,
      "z": -15,
      "name": "Soil_Pathway"
    },
    {
      "x": -2,
      "y": 8,
      "z": -15,
      "name": "Soil_Pathway"
    },
    {
      "x": -2,
      "y": 12,
      "z": -15,
      "name": "Wood_Tropicalwood_Planks_Half",
      "rotation": 8
    },
    {
      "x": -2,
      "y": 13,
      "z": -15,
      "name": "Wood_Bamboo_Trunk_Deco",
      "support": 15
    },
    {
      "x": -2,
      "y": 14,
      "z": -15,
      "name": "Wood_Bamboo_Trunk_Deco",
      "support": 15
    },
    {
      "x": -2,
      "y": 15,
      "z": -15,
      "name": "Wood_Bamboo_Trunk_Deco",
      "support": 15
    },
    {
      "x": -2,
      "y": 16,
      "z": -15,
      "name": "Wood_Bamboo_Trunk_Deco",
      "support": 15
    },
    {
      "x": -2,
      "y": 17,
      "z": -15,
      "name": "*Wood_Tropicalwood_Roof_State_Definitions_Corner_Left",
      "rotation": 2
    },
    {
      "x": -2,
      "y": 6,
      "z": -14,
      "name": "Soil_Pathway"
    },
    {
      "x": -2,
      "y": 7,
      "z": -14,
      "name": "Soil_Pathway"
    },
    {
      "x": -2,
      "y": 8,
      "z": -14,
      "name": "Soil_Pathway"
    },
    {
      "x": -2,
      "y": 12,
      "z": -14,
      "name": "Wood_Tropicalwood_Planks_Half",
      "rotation": 8
    },
    {
      "x": -2,
      "y": 13,
      "z": -14,
      "name": "Wood_Tropicalwood_Planks_Half",
      "rotation": 5
    },
    {
      "x": -2,
      "y": 14,
      "z": -14,
      "name": "Wood_Tropicalwood_Planks_Half",
      "rotation": 5
    },
    {
      "x": -2,
      "y": 15,
      "z": -14,
      "name": "Wood_Tropicalwood_Planks_Half",
      "rotation": 5
    },
    {
      "x": -2,
      "y": 16,
      "z": -14,
      "name": "Wood_Tropicalwood_Decorative"
    },
    {
      "x": -2,
      "y": 17,
      "z": -14,
      "name": "Wood_Tropicalwood_Roof",
      "rotation": 3
    },
    {
      "x": -2,
      "y": 6,
      "z": -13,
      "name": "Soil_Pathway"
    },
    {
      "x": -2,
      "y": 7,
      "z": -13,
      "name": "Soil_Pathway"
    },
    {
      "x": -2,
      "y": 8,
      "z": -13,
      "name": "Soil_Pathway"
    },
    {
      "x": -2,
      "y": 12,
      "z": -13,
      "name": "Wood_Tropicalwood_Planks_Half",
      "rotation": 8
    },
    {
      "x": -2,
      "y": 13,
      "z": -13,
      "name": "Wood_Tropicalwood_Planks_Half",
      "rotation": 5
    },
    {
      "x": -2,
      "y": 14,
      "z": -13,
      "name": "Wood_Tropicalwood_Fence",
      "rotation": 1
    },
    {
      "x": -2,
      "y": 15,
      "z": -13,
      "name": "Wood_Tropicalwood_Planks_Half",
      "rotation": 5
    },
    {
      "x": -2,
      "y": 16,
      "z": -13,
      "name": "Wood_Tropicalwood_Decorative"
    },
    {
      "x": -2,
      "y": 17,
      "z": -13,
      "name": "Wood_Tropicalwood_Roof",
      "rotation": 3
    },
    {
      "x": -2,
      "y": 6,
      "z": -12,
      "name": "Soil_Pathway"
    },
    {
      "x": -2,
      "y": 7,
      "z": -12,
      "name": "Soil_Pathway"
    },
    {
      "x": -2,
      "y": 8,
      "z": -12,
      "name": "Soil_Pathway"
    },
    {
      "x": -2,
      "y": 12,
      "z": -12,
      "name": "Wood_Tropicalwood_Planks_Half",
      "rotation": 8
    },
    {
      "x": -2,
      "y": 13,
      "z": -12,
      "name": "Wood_Tropicalwood_Planks_Half",
      "rotation": 5
    },
    {
      "x": -2,
      "y": 14,
      "z": -12,
      "name": "Wood_Tropicalwood_Fence",
      "rotation": 1
    },
    {
      "x": -2,
      "y": 15,
      "z": -12,
      "name": "Wood_Tropicalwood_Planks_Half",
      "rotation": 5
    },
    {
      "x": -2,
      "y": 16,
      "z": -12,
      "name": "Wood_Tropicalwood_Decorative"
    },
    {
      "x": -2,
      "y": 17,
      "z": -12,
      "name": "Wood_Tropicalwood_Roof",
      "rotation": 3
    },
    {
      "x": -2,
      "y": 6,
      "z": -11,
      "name": "Soil_Pathway"
    },
    {
      "x": -2,
      "y": 7,
      "z": -11,
      "name": "Soil_Pathway"
    },
    {
      "x": -2,
      "y": 8,
      "z": -11,
      "name": "Soil_Pathway"
    },
    {
      "x": -2,
      "y": 12,
      "z": -11,
      "name": "Wood_Tropicalwood_Planks_Half",
      "rotation": 8
    },
    {
      "x": -2,
      "y": 13,
      "z": -11,
      "name": "Wood_Tropicalwood_Planks_Half",
      "rotation": 5
    },
    {
      "x": -2,
      "y": 14,
      "z": -11,
      "name": "Wood_Tropicalwood_Planks_Half",
      "rotation": 5
    },
    {
      "x": -2,
      "y": 15,
      "z": -11,
      "name": "Wood_Tropicalwood_Planks_Half",
      "rotation": 5
    },
    {
      "x": -2,
      "y": 16,
      "z": -11,
      "name": "Wood_Tropicalwood_Decorative"
    },
    {
      "x": -2,
      "y": 17,
      "z": -11,
      "name": "Wood_Tropicalwood_Roof",
      "rotation": 3
    },
    {
      "x": -2,
      "y": 6,
      "z": -10,
      "name": "Soil_Pathway"
    },
    {
      "x": -2,
      "y": 7,
      "z": -10,
      "name": "Soil_Pathway"
    },
    {
      "x": -2,
      "y": 8,
      "z": -10,
      "name": "Soil_Pathway"
    },
    {
      "x": -2,
      "y": 12,
      "z": -10,
      "name": "Wood_Tropicalwood_Planks_Half",
      "rotation": 8
    },
    {
      "x": -2,
      "y": 13,
      "z": -10,
      "name": "Wood_Bamboo_Trunk_Deco",
      "support": 15
    },
    {
      "x": -2,
      "y": 14,
      "z": -10,
      "name": "Wood_Bamboo_Trunk_Deco",
      "support": 15
    },
    {
      "x": -2,
      "y": 15,
      "z": -10,
      "name": "Wood_Bamboo_Trunk_Deco",
      "support": 15
    },
    {
      "x": -2,
      "y": 16,
      "z": -10,
      "name": "Wood_Bamboo_Trunk_Deco",
      "support": 15
    },
    {
      "x": -2,
      "y": 17,
      "z": -10,
      "name": "*Wood_Tropicalwood_Roof_State_Definitions_Corner_Right"
    },
    {
      "x": -2,
      "y": 6,
      "z": -9,
      "name": "Soil_Pathway"
    },
    {
      "x": -2,
      "y": 7,
      "z": -9,
      "name": "Soil_Pathway"
    },
    {
      "x": -2,
      "y": 8,
      "z": -9,
      "name": "Soil_Pathway"
    },
    {
      "x": -2,
      "y": 12,
      "z": -9,
      "name": "Wood_Tropicalwood_Planks_Half",
      "rotation": 8
    },
    {
      "x": -2,
      "y": 15,
      "z": -9,
      "name": "Wood_Tropicalwood_Roof_Steep"
    },
    {
      "x": -2,
      "y": 16,
      "z": -9,
      "name": "Wood_Tropicalwood_Roof_Steep",
      "filler": 1024
    },
    {
      "x": -2,
      "y": 6,
      "z": -8,
      "name": "Soil_Pathway"
    },
    {
      "x": -2,
      "y": 7,
      "z": -8,
      "name": "Soil_Pathway"
    },
    {
      "x": -2,
      "y": 8,
      "z": -8,
      "name": "Soil_Pathway"
    },
    {
      "x": -2,
      "y": 12,
      "z": -8,
      "name": "Wood_Tropicalwood_Planks_Half",
      "rotation": 8
    },
    {
      "x": -1,
      "y": 6,
      "z": -17,
      "name": "Soil_Pathway"
    },
    {
      "x": -1,
      "y": 7,
      "z": -17,
      "name": "Soil_Pathway"
    },
    {
      "x": -1,
      "y": 8,
      "z": -17,
      "name": "Soil_Pathway"
    },
    {
      "x": -1,
      "y": 6,
      "z": -16,
      "name": "Soil_Pathway"
    },
    {
      "x": -1,
      "y": 7,
      "z": -16,
      "name": "Soil_Pathway"
    },
    {
      "x": -1,
      "y": 8,
      "z": -16,
      "name": "Soil_Pathway"
    },
    {
      "x": -1,
      "y": 12,
      "z": -16,
      "name": "Wood_Tropicalwood_Planks_Half",
      "rotation": 8
    },
    {
      "x": -1,
      "y": 15,
      "z": -16,
      "name": "Wood_Tropicalwood_Roof_Steep",
      "rotation": 2
    },
    {
      "x": -1,
      "y": 16,
      "z": -16,
      "name": "Wood_Tropicalwood_Roof_Steep",
      "filler": 1024,
      "rotation": 2
    },
    {
      "x": -1,
      "y": 6,
      "z": -15,
      "name": "Soil_Pathway"
    },
    {
      "x": -1,
      "y": 7,
      "z": -15,
      "name": "Soil_Pathway"
    },
    {
      "x": -1,
      "y": 8,
      "z": -15,
      "name": "Soil_Pathway"
    },
    {
      "x": -1,
      "y": 12,
      "z": -15,
      "name": "Wood_Tropicalwood_Planks_Half",
      "rotation": 8
    },
    {
      "x": -1,
      "y": 13,
      "z": -15,
      "name": "Wood_Tropicalwood_Planks_Half",
      "rotation": 4
    },
    {
      "x": -1,
      "y": 14,
      "z": -15,
      "name": "Wood_Tropicalwood_Planks_Half",
      "rotation": 4
    },
    {
      "x": -1,
      "y": 15,
      "z": -15,
      "name": "Wood_Tropicalwood_Planks_Half",
      "rotation": 4
    },
    {
      "x": -1,
      "y": 16,
      "z": -15,
      "name": "Wood_Tropicalwood_Decorative"
    },
    {
      "x": -1,
      "y": 17,
      "z": -15,
      "name": "Wood_Tropicalwood_Roof",
      "rotation": 2
    },
    {
      "x": -1,
      "y": 6,
      "z": -14,
      "name": "Soil_Pathway"
    },
    {
      "x": -1,
      "y": 7,
      "z": -14,
      "name": "Soil_Pathway"
    },
    {
      "x": -1,
      "y": 8,
      "z": -14,
      "name": "Soil_Pathway"
    },
    {
      "x": -1,
      "y": 12,
      "z": -14,
      "name": "Wood_Tropicalwood_Planks_Half",
      "rotation": 8
    },
    {
      "x": -1,
      "y": 13,
      "z": -14,
      "name": "Furniture_Jungle_Pot"
    },
    {
      "x": -1,
      "y": 16,
      "z": -14,
      "name": "Furniture_Jungle_Shelf",
      "rotation": 1
    },
    {
      "x": -1,
      "y": 17,
      "z": -14,
      "name": "Wood_Tropicalwood_Planks_Half",
      "rotation": 8
    },
    {
      "x": -1,
      "y": 18,
      "z": -14,
      "name": "*Wood_Tropicalwood_Roof_Shallow_State_Definitions_Corner_Left",
      "rotation": 2
    },
    {
      "x": -1,
      "y": 6,
      "z": -13,
      "name": "Soil_Pathway"
    },
    {
      "x": -1,
      "y": 7,
      "z": -13,
      "name": "Soil_Pathway"
    },
    {
      "x": -1,
      "y": 8,
      "z": -13,
      "name": "Soil_Pathway"
    },
    {
      "x": -1,
      "y": 12,
      "z": -13,
      "name": "Wood_Tropicalwood_Planks_Half",
      "rotation": 8
    },
    {
      "x": -1,
      "y": 16,
      "z": -13,
      "name": "Furniture_Jungle_Shelf",
      "rotation": 1
    },
    {
      "x": -1,
      "y": 18,
      "z": -13,
      "name": "*Wood_Tropicalwood_Roof_Shallow_State_Definitions_Corner_Left",
      "filler": 32,
      "rotation": 2
    },
    {
      "x": -1,
      "y": 6,
      "z": -12,
      "name": "Soil_Pathway"
    },
    {
      "x": -1,
      "y": 7,
      "z": -12,
      "name": "Soil_Pathway"
    },
    {
      "x": -1,
      "y": 8,
      "z": -12,
      "name": "Soil_Pathway"
    },
    {
      "x": -1,
      "y": 12,
      "z": -12,
      "name": "Wood_Tropicalwood_Planks_Half",
      "rotation": 8
    },
    {
      "x": -1,
      "y": 16,
      "z": -12,
      "name": "Furniture_Jungle_Shelf",
      "rotation": 1
    },
    {
      "x": -1,
      "y": 18,
      "z": -12,
      "name": "*Wood_Tropicalwood_Roof_Shallow_State_Definitions_Corner_Left",
      "filler": 992,
      "rotation": 3
    },
    {
      "x": -1,
      "y": 6,
      "z": -11,
      "name": "Soil_Pathway"
    },
    {
      "x": -1,
      "y": 7,
      "z": -11,
      "name": "Soil_Pathway"
    },
    {
      "x": -1,
      "y": 8,
      "z": -11,
      "name": "Soil_Pathway"
    },
    {
      "x": -1,
      "y": 12,
      "z": -11,
      "name": "Wood_Tropicalwood_Planks_Half",
      "rotation": 8
    },
    {
      "x": -1,
      "y": 13,
      "z": -11,
      "name": "*Furniture_Jungle_Candle_State_Definitions_Off"
    },
    {
      "x": -1,
      "y": 17,
      "z": -11,
      "name": "Wood_Tropicalwood_Planks_Half",
      "rotation": 8
    },
    {
      "x": -1,
      "y": 18,
      "z": -11,
      "name": "*Wood_Tropicalwood_Roof_Shallow_State_Definitions_Corner_Left",
      "rotation": 3
    },
    {
      "x": -1,
      "y": 6,
      "z": -10,
      "name": "Soil_Pathway"
    },
    {
      "x": -1,
      "y": 7,
      "z": -10,
      "name": "Soil_Pathway"
    },
    {
      "x": -1,
      "y": 8,
      "z": -10,
      "name": "Soil_Pathway"
    },
    {
      "x": -1,
      "y": 12,
      "z": -10,
      "name": "Wood_Tropicalwood_Planks_Half",
      "rotation": 8
    },
    {
      "x": -1,
      "y": 13,
      "z": -10,
      "name": "Wood_Tropicalwood_Planks_Half",
      "rotation": 6
    },
    {
      "x": -1,
      "y": 14,
      "z": -10,
      "name": "Wood_Tropicalwood_Planks_Half",
      "rotation": 6
    },
    {
      "x": -1,
      "y": 15,
      "z": -10,
      "name": "Wood_Tropicalwood_Planks_Half",
      "rotation": 6
    },
    {
      "x": -1,
      "y": 16,
      "z": -10,
      "name": "Wood_Tropicalwood_Decorative"
    },
    {
      "x": -1,
      "y": 17,
      "z": -10,
      "name": "Wood_Tropicalwood_Roof"
    },
    {
      "x": -1,
      "y": 6,
      "z": -9,
      "name": "Soil_Pathway"
    },
    {
      "x": -1,
      "y": 7,
      "z": -9,
      "name": "Soil_Pathway"
    },
    {
      "x": -1,
      "y": 8,
      "z": -9,
      "name": "Soil_Pathway"
    },
    {
      "x": -1,
      "y": 12,
      "z": -9,
      "name": "Wood_Tropicalwood_Planks_Half",
      "rotation": 8
    },
    {
      "x": -1,
      "y": 15,
      "z": -9,
      "name": "Wood_Tropicalwood_Roof_Steep"
    },
    {
      "x": -1,
      "y": 16,
      "z": -9,
      "name": "Wood_Tropicalwood_Roof_Steep",
      "filler": 1024
    },
    {
      "x": -1,
      "y": 6,
      "z": -8,
      "name": "Soil_Pathway"
    },
    {
      "x": -1,
      "y": 7,
      "z": -8,
      "name": "Soil_Pathway"
    },
    {
      "x": -1,
      "y": 8,
      "z": -8,
      "name": "Soil_Pathway"
    },
    {
      "x": -1,
      "y": 12,
      "z": -8,
      "name": "Wood_Tropicalwood_Planks_Half",
      "rotation": 8
    },
    {
      "x": -1,
      "y": 6,
      "z": -7,
      "name": "Soil_Pathway"
    },
    {
      "x": -1,
      "y": 7,
      "z": -7,
      "name": "Soil_Pathway"
    },
    {
      "x": -1,
      "y": 8,
      "z": -7,
      "name": "Soil_Pathway"
    },
    {
      "x": 0,
      "y": 6,
      "z": -17,
      "name": "Soil_Pathway"
    },
    {
      "x": 0,
      "y": 7,
      "z": -17,
      "name": "Soil_Pathway"
    },
    {
      "x": 0,
      "y": 8,
      "z": -17,
      "name": "Soil_Pathway"
    },
    {
      "x": 0,
      "y": 6,
      "z": -16,
      "name": "Soil_Pathway"
    },
    {
      "x": 0,
      "y": 7,
      "z": -16,
      "name": "Soil_Pathway"
    },
    {
      "x": 0,
      "y": 8,
      "z": -16,
      "name": "Soil_Pathway"
    },
    {
      "x": 0,
      "y": 12,
      "z": -16,
      "name": "Wood_Tropicalwood_Planks_Half",
      "rotation": 8
    },
    {
      "x": 0,
      "y": 15,
      "z": -16,
      "name": "Wood_Tropicalwood_Roof_Steep",
      "rotation": 2
    },
    {
      "x": 0,
      "y": 16,
      "z": -16,
      "name": "Wood_Tropicalwood_Roof_Steep",
      "filler": 1024,
      "rotation": 2
    },
    {
      "x": 0,
      "y": 6,
      "z": -15,
      "name": "Soil_Pathway"
    },
    {
      "x": 0,
      "y": 7,
      "z": -15,
      "name": "Soil_Pathway"
    },
    {
      "x": 0,
      "y": 8,
      "z": -15,
      "name": "Soil_Pathway"
    },
    {
      "x": 0,
      "y": 12,
      "z": -15,
      "name": "Wood_Tropicalwood_Planks_Half",
      "rotation": 8
    },
    {
      "x": 0,
      "y": 13,
      "z": -15,
      "name": "Wood_Tropicalwood_Planks_Half",
      "rotation": 4
    },
    {
      "x": 0,
      "y": 14,
      "z": -15,
      "name": "Wood_Tropicalwood_Fence"
    },
    {
      "x": 0,
      "y": 15,
      "z": -15,
      "name": "Wood_Tropicalwood_Planks_Half",
      "rotation": 4
    },
    {
      "x": 0,
      "y": 16,
      "z": -15,
      "name": "Wood_Tropicalwood_Decorative"
    },
    {
      "x": 0,
      "y": 17,
      "z": -15,
      "name": "Wood_Tropicalwood_Roof",
      "rotation": 2
    },
    {
      "x": 0,
      "y": 6,
      "z": -14,
      "name": "Soil_Pathway"
    },
    {
      "x": 0,
      "y": 7,
      "z": -14,
      "name": "Soil_Pathway"
    },
    {
      "x": 0,
      "y": 8,
      "z": -14,
      "name": "Soil_Pathway"
    },
    {
      "x": 0,
      "y": 12,
      "z": -14,
      "name": "Wood_Tropicalwood_Planks_Half",
      "rotation": 8
    },
    {
      "x": 0,
      "y": 18,
      "z": -14,
      "name": "*Wood_Tropicalwood_Roof_Shallow_State_Definitions_Corner_Left",
      "filler": 1,
      "rotation": 2
    },
    {
      "x": 0,
      "y": 6,
      "z": -13,
      "name": "Soil_Pathway"
    },
    {
      "x": 0,
      "y": 7,
      "z": -13,
      "name": "Soil_Pathway"
    },
    {
      "x": 0,
      "y": 8,
      "z": -13,
      "name": "Soil_Pathway"
    },
    {
      "x": 0,
      "y": 12,
      "z": -13,
      "name": "Wood_Tropicalwood_Planks_Half",
      "rotation": 8
    },
    {
      "x": 0,
      "y": 18,
      "z": -13,
      "name": "*Wood_Tropicalwood_Roof_Shallow_State_Definitions_Corner_Left",
      "filler": 33,
      "rotation": 2
    },
    {
      "x": 0,
      "y": 6,
      "z": -12,
      "name": "Soil_Pathway"
    },
    {
      "x": 0,
      "y": 7,
      "z": -12,
      "name": "Soil_Pathway"
    },
    {
      "x": 0,
      "y": 8,
      "z": -12,
      "name": "Soil_Pathway"
    },
    {
      "x": 0,
      "y": 12,
      "z": -12,
      "name": "Wood_Tropicalwood_Planks_Half",
      "rotation": 8
    },
    {
      "x": 0,
      "y": 18,
      "z": -12,
      "name": "*Wood_Tropicalwood_Roof_Shallow_State_Definitions_Corner_Left",
      "filler": 993,
      "rotation": 3
    },
    {
      "x": 0,
      "y": 6,
      "z": -11,
      "name": "Soil_Pathway"
    },
    {
      "x": 0,
      "y": 7,
      "z": -11,
      "name": "Soil_Pathway"
    },
    {
      "x": 0,
      "y": 8,
      "z": -11,
      "name": "Soil_Pathway"
    },
    {
      "x": 0,
      "y": 12,
      "z": -11,
      "name": "Wood_Tropicalwood_Planks_Half",
      "rotation": 8
    },
    {
      "x": 0,
      "y": 18,
      "z": -11,
      "name": "*Wood_Tropicalwood_Roof_Shallow_State_Definitions_Corner_Left",
      "filler": 1,
      "rotation": 3
    },
    {
      "x": 0,
      "y": 6,
      "z": -10,
      "name": "Soil_Pathway"
    },
    {
      "x": 0,
      "y": 7,
      "z": -10,
      "name": "Soil_Pathway"
    },
    {
      "x": 0,
      "y": 8,
      "z": -10,
      "name": "Soil_Pathway"
    },
    {
      "x": 0,
      "y": 12,
      "z": -10,
      "name": "Wood_Tropicalwood_Planks_Half",
      "rotation": 8
    },
    {
      "x": 0,
      "y": 13,
      "z": -10,
      "name": "*Furniture_Jungle_Door_State_Definitions_CloseDoorOut"
    },
    {
      "x": 0,
      "y": 14,
      "z": -10,
      "name": "*Furniture_Jungle_Door_State_Definitions_CloseDoorOut",
      "filler": 1024
    },
    {
      "x": 0,
      "y": 15,
      "z": -10,
      "name": "Wood_Tropicalwood_Planks_Half",
      "rotation": 6
    },
    {
      "x": 0,
      "y": 16,
      "z": -10,
      "name": "Wood_Tropicalwood_Decorative"
    },
    {
      "x": 0,
      "y": 17,
      "z": -10,
      "name": "Wood_Tropicalwood_Roof"
    },
    {
      "x": 0,
      "y": 6,
      "z": -9,
      "name": "Soil_Pathway"
    },
    {
      "x": 0,
      "y": 7,
      "z": -9,
      "name": "Soil_Pathway"
    },
    {
      "x": 0,
      "y": 8,
      "z": -9,
      "name": "Soil_Pathway"
    },
    {
      "x": 0,
      "y": 12,
      "z": -9,
      "name": "Wood_Tropicalwood_Planks_Half",
      "rotation": 8
    },
    {
      "x": 0,
      "y": 15,
      "z": -9,
      "name": "Wood_Tropicalwood_Roof_Steep"
    },
    {
      "x": 0,
      "y": 16,
      "z": -9,
      "name": "Wood_Tropicalwood_Roof_Steep",
      "filler": 1024
    },
    {
      "x": 0,
      "y": 6,
      "z": -8,
      "name": "Soil_Pathway"
    },
    {
      "x": 0,
      "y": 7,
      "z": -8,
      "name": "Soil_Pathway"
    },
    {
      "x": 0,
      "y": 8,
      "z": -8,
      "name": "Soil_Pathway"
    },
    {
      "x": 0,
      "y": 12,
      "z": -8,
      "name": "Wood_Tropicalwood_Planks_Half",
      "rotation": 8
    },
    {
      "x": 0,
      "y": 6,
      "z": -7,
      "name": "Soil_Pathway"
    },
    {
      "x": 0,
      "y": 7,
      "z": -7,
      "name": "Soil_Pathway"
    },
    {
      "x": 0,
      "y": 8,
      "z": -7,
      "name": "Soil_Pathway"
    },
    {
      "x": 0,
      "y": 6,
      "z": 3,
      "name": "Soil_Pathway"
    },
    {
      "x": 0,
      "y": 7,
      "z": 3,
      "name": "Soil_Pathway"
    },
    {
      "x": 0,
      "y": 8,
      "z": 3,
      "name": "Soil_Pathway"
    },
    {
      "x": 0,
      "y": 6,
      "z": 4,
      "name": "Soil_Pathway"
    },
    {
      "x": 0,
      "y": 7,
      "z": 4,
      "name": "Soil_Pathway"
    },
    {
      "x": 0,
      "y": 8,
      "z": 4,
      "name": "Soil_Pathway"
    },
    {
      "x": 0,
      "y": 6,
      "z": 6,
      "name": "Soil_Pathway"
    },
    {
      "x": 0,
      "y": 7,
      "z": 6,
      "name": "Soil_Pathway"
    },
    {
      "x": 0,
      "y": 8,
      "z": 6,
      "name": "Soil_Pathway"
    },
    {
      "x": 0,
      "y": 6,
      "z": 7,
      "name": "Soil_Pathway"
    },
    {
      "x": 0,
      "y": 7,
      "z": 7,
      "name": "Soil_Pathway"
    },
    {
      "x": 0,
      "y": 8,
      "z": 7,
      "name": "Soil_Pathway"
    },
    {
      "x": 0,
      "y": 6,
      "z": 8,
      "name": "Soil_Pathway"
    },
    {
      "x": 0,
      "y": 7,
      "z": 8,
      "name": "Soil_Pathway"
    },
    {
      "x": 0,
      "y": 8,
      "z": 8,
      "name": "Soil_Pathway"
    },
    {
      "x": 0,
      "y": 7,
      "z": 9,
      "name": "Wood_Tropicalwood_Planks_Half",
      "rotation": 8
    },
    {
      "x": 0,
      "y": 7,
      "z": 10,
      "name": "Wood_Tropicalwood_Planks_Half",
      "rotation": 8
    },
    {
      "x": 0,
      "y": 8,
      "z": 10,
      "name": "Wood_Tropicalwood_Fence",
      "rotation": 1
    },
    {
      "x": 0,
      "y": 7,
      "z": 11,
      "name": "Wood_Tropicalwood_Planks_Half",
      "rotation": 8
    },
    {
      "x": 0,
      "y": 8,
      "z": 11,
      "name": "Wood_Tropicalwood_Fence",
      "rotation": 3
    },
    {
      "x": 0,
      "y": 7,
      "z": 12,
      "name": "Wood_Tropicalwood_Planks_Half",
      "rotation": 8
    },
    {
      "x": 0,
      "y": 8,
      "z": 12,
      "name": "Wood_Tropicalwood_Fence",
      "rotation": 1
    },
    {
      "x": 0,
      "y": 7,
      "z": 13,
      "name": "Wood_Tropicalwood_Planks_Half",
      "rotation": 8
    },
    {
      "x": 0,
      "y": 8,
      "z": 13,
      "name": "Wood_Tropicalwood_Fence",
      "rotation": 3
    },
    {
      "x": 0,
      "y": 7,
      "z": 14,
      "name": "Wood_Tropicalwood_Planks_Half",
      "rotation": 8
    },
    {
      "x": 0,
      "y": 8,
      "z": 14,
      "name": "Wood_Tropicalwood_Fence",
      "rotation": 3
    },
    {
      "x": 0,
      "y": 7,
      "z": 15,
      "name": "Wood_Tropicalwood_Planks_Half",
      "rotation": 8
    },
    {
      "x": 0,
      "y": 8,
      "z": 15,
      "name": "Wood_Tropicalwood_Fence",
      "rotation": 3
    },
    {
      "x": 0,
      "y": 0,
      "z": 16,
      "name": "Wood_Bamboo_Branch_Long_Deco",
      "support": 15
    },
    {
      "x": 0,
      "y": 1,
      "z": 16,
      "name": "Wood_Bamboo_Branch_Long_Deco",
      "support": 15
    },
    {
      "x": 0,
      "y": 2,
      "z": 16,
      "name": "Wood_Bamboo_Branch_Long_Deco",
      "support": 15
    },
    {
      "x": 0,
      "y": 3,
      "z": 16,
      "name": "Wood_Bamboo_Branch_Long_Deco",
      "support": 15
    },
    {
      "x": 0,
      "y": 4,
      "z": 16,
      "name": "Wood_Bamboo_Branch_Long_Deco",
      "support": 15
    },
    {
      "x": 0,
      "y": 5,
      "z": 16,
      "name": "Wood_Bamboo_Branch_Long_Deco",
      "support": 15
    },
    {
      "x": 0,
      "y": 6,
      "z": 16,
      "name": "Wood_Bamboo_Branch_Long_Deco",
      "support": 15
    },
    {
      "x": 0,
      "y": 7,
      "z": 16,
      "name": "Wood_Bamboo_Trunk_Deco",
      "support": 15
    },
    {
      "x": 0,
      "y": 8,
      "z": 16,
      "name": "*Wood_Tropicalwood_Fence_State_Definitions_Corner",
      "rotation": 2
    },
    {
      "x": 1,
      "y": 6,
      "z": -17,
      "name": "Soil_Pathway"
    },
    {
      "x": 1,
      "y": 7,
      "z": -17,
      "name": "Soil_Pathway"
    },
    {
      "x": 1,
      "y": 8,
      "z": -17,
      "name": "Soil_Pathway"
    },
    {
      "x": 1,
      "y": 6,
      "z": -16,
      "name": "Soil_Pathway"
    },
    {
      "x": 1,
      "y": 7,
      "z": -16,
      "name": "Soil_Pathway"
    },
    {
      "x": 1,
      "y": 8,
      "z": -16,
      "name": "Soil_Pathway"
    },
    {
      "x": 1,
      "y": 12,
      "z": -16,
      "name": "Wood_Tropicalwood_Planks_Half",
      "rotation": 8
    },
    {
      "x": 1,
      "y": 15,
      "z": -16,
      "name": "Wood_Tropicalwood_Roof_Steep",
      "rotation": 2
    },
    {
      "x": 1,
      "y": 16,
      "z": -16,
      "name": "Wood_Tropicalwood_Roof_Steep",
      "filler": 1024,
      "rotation": 2
    },
    {
      "x": 1,
      "y": 6,
      "z": -15,
      "name": "Soil_Pathway"
    },
    {
      "x": 1,
      "y": 7,
      "z": -15,
      "name": "Soil_Pathway"
    },
    {
      "x": 1,
      "y": 8,
      "z": -15,
      "name": "Soil_Pathway"
    },
    {
      "x": 1,
      "y": 12,
      "z": -15,
      "name": "Wood_Tropicalwood_Planks_Half",
      "rotation": 8
    },
    {
      "x": 1,
      "y": 13,
      "z": -15,
      "name": "Wood_Tropicalwood_Planks_Half",
      "rotation": 4
    },
    {
      "x": 1,
      "y": 14,
      "z": -15,
      "name": "Wood_Tropicalwood_Fence"
    },
    {
      "x": 1,
      "y": 15,
      "z": -15,
      "name": "Wood_Tropicalwood_Planks_Half",
      "rotation": 4
    },
    {
      "x": 1,
      "y": 16,
      "z": -15,
      "name": "Wood_Tropicalwood_Decorative"
    },
    {
      "x": 1,
      "y": 17,
      "z": -15,
      "name": "Wood_Tropicalwood_Roof",
      "rotation": 2
    },
    {
      "x": 1,
      "y": 6,
      "z": -14,
      "name": "Soil_Pathway"
    },
    {
      "x": 1,
      "y": 7,
      "z": -14,
      "name": "Soil_Pathway"
    },
    {
      "x": 1,
      "y": 8,
      "z": -14,
      "name": "Soil_Pathway"
    },
    {
      "x": 1,
      "y": 12,
      "z": -14,
      "name": "Wood_Tropicalwood_Planks_Half",
      "rotation": 8
    },
    {
      "x": 1,
      "y": 18,
      "z": -14,
      "name": "*Wood_Tropicalwood_Roof_Shallow_State_Definitions_Corner_Left",
      "filler": 31,
      "rotation": 1
    },
    {
      "x": 1,
      "y": 6,
      "z": -13,
      "name": "Soil_Pathway"
    },
    {
      "x": 1,
      "y": 7,
      "z": -13,
      "name": "Soil_Pathway"
    },
    {
      "x": 1,
      "y": 8,
      "z": -13,
      "name": "Soil_Pathway"
    },
    {
      "x": 1,
      "y": 12,
      "z": -13,
      "name": "Wood_Tropicalwood_Planks_Half",
      "rotation": 8
    },
    {
      "x": 1,
      "y": 18,
      "z": -13,
      "name": "*Wood_Tropicalwood_Roof_Shallow_State_Definitions_Corner_Left",
      "filler": 63,
      "rotation": 1
    },
    {
      "x": 1,
      "y": 6,
      "z": -12,
      "name": "Soil_Pathway"
    },
    {
      "x": 1,
      "y": 7,
      "z": -12,
      "name": "Soil_Pathway"
    },
    {
      "x": 1,
      "y": 8,
      "z": -12,
      "name": "Soil_Pathway"
    },
    {
      "x": 1,
      "y": 12,
      "z": -12,
      "name": "Wood_Tropicalwood_Planks_Half",
      "rotation": 8
    },
    {
      "x": 1,
      "y": 18,
      "z": -12,
      "name": "*Wood_Tropicalwood_Roof_Shallow_State_Definitions_Corner_Left",
      "filler": 1023
    },
    {
      "x": 1,
      "y": 6,
      "z": -11,
      "name": "Soil_Pathway"
    },
    {
      "x": 1,
      "y": 7,
      "z": -11,
      "name": "Soil_Pathway"
    },
    {
      "x": 1,
      "y": 8,
      "z": -11,
      "name": "Soil_Pathway"
    },
    {
      "x": 1,
      "y": 12,
      "z": -11,
      "name": "Wood_Tropicalwood_Planks_Half",
      "rotation": 8
    },
    {
      "x": 1,
      "y": 18,
      "z": -11,
      "name": "*Wood_Tropicalwood_Roof_Shallow_State_Definitions_Corner_Left",
      "filler": 31
    },
    {
      "x": 1,
      "y": 6,
      "z": -10,
      "name": "Soil_Pathway"
    },
    {
      "x": 1,
      "y": 7,
      "z": -10,
      "name": "Soil_Pathway"
    },
    {
      "x": 1,
      "y": 8,
      "z": -10,
      "name": "Soil_Pathway"
    },
    {
      "x": 1,
      "y": 12,
      "z": -10,
      "name": "Wood_Tropicalwood_Planks_Half",
      "rotation": 8
    },
    {
      "x": 1,
      "y": 13,
      "z": -10,
      "name": "Wood_Tropicalwood_Planks_Half",
      "rotation": 6
    },
    {
      "x": 1,
      "y": 14,
      "z": -10,
      "name": "Wood_Tropicalwood_Planks_Half",
      "rotation": 6
    },
    {
      "x": 1,
      "y": 15,
      "z": -10,
      "name": "Wood_Tropicalwood_Planks_Half",
      "rotation": 6
    },
    {
      "x": 1,
      "y": 16,
      "z": -10,
      "name": "Wood_Tropicalwood_Decorative"
    },
    {
      "x": 1,
      "y": 17,
      "z": -10,
      "name": "Wood_Tropicalwood_Roof"
    },
    {
      "x": 1,
      "y": 6,
      "z": -9,
      "name": "Soil_Pathway"
    },
    {
      "x": 1,
      "y": 7,
      "z": -9,
      "name": "Soil_Pathway"
    },
    {
      "x": 1,
      "y": 8,
      "z": -9,
      "name": "Soil_Pathway"
    },
    {
      "x": 1,
      "y": 12,
      "z": -9,
      "name": "Wood_Tropicalwood_Planks_Half",
      "rotation": 8
    },
    {
      "x": 1,
      "y": 13,
      "z": -9,
      "name": "Furniture_Jungle_Bench",
      "filler": 31
    },
    {
      "x": 1,
      "y": 15,
      "z": -9,
      "name": "Wood_Tropicalwood_Roof_Steep"
    },
    {
      "x": 1,
      "y": 16,
      "z": -9,
      "name": "Wood_Tropicalwood_Roof_Steep",
      "filler": 1024
    },
    {
      "x": 1,
      "y": 6,
      "z": -8,
      "name": "Soil_Pathway"
    },
    {
      "x": 1,
      "y": 7,
      "z": -8,
      "name": "Soil_Pathway"
    },
    {
      "x": 1,
      "y": 8,
      "z": -8,
      "name": "Soil_Pathway"
    },
    {
      "x": 1,
      "y": 12,
      "z": -8,
      "name": "Wood_Tropicalwood_Planks_Half",
      "rotation": 8
    },
    {
      "x": 1,
      "y": 6,
      "z": -7,
      "name": "Soil_Pathway"
    },
    {
      "x": 1,
      "y": 7,
      "z": -7,
      "name": "Soil_Pathway"
    },
    {
      "x": 1,
      "y": 8,
      "z": -7,
      "name": "Soil_Pathway"
    },
    {
      "x": 1,
      "y": 6,
      "z": -2,
      "name": "Soil_Pathway"
    },
    {
      "x": 1,
      "y": 7,
      "z": -2,
      "name": "Soil_Pathway"
    },
    {
      "x": 1,
      "y": 8,
      "z": -2,
      "name": "Soil_Pathway"
    },
    {
      "x": 1,
      "y": 6,
      "z": -1,
      "name": "Soil_Pathway"
    },
    {
      "x": 1,
      "y": 7,
      "z": -1,
      "name": "Soil_Pathway"
    },
    {
      "x": 1,
      "y": 8,
      "z": -1,
      "name": "Soil_Pathway"
    },
    {
      "x": 1,
      "y": 6,
      "z": 2,
      "name": "Soil_Pathway"
    },
    {
      "x": 1,
      "y": 7,
      "z": 2,
      "name": "Soil_Pathway"
    },
    {
      "x": 1,
      "y": 8,
      "z": 2,
      "name": "Soil_Pathway"
    },
    {
      "x": 1,
      "y": 6,
      "z": 4,
      "name": "Soil_Pathway"
    },
    {
      "x": 1,
      "y": 7,
      "z": 4,
      "name": "Soil_Pathway"
    },
    {
      "x": 1,
      "y": 8,
      "z": 4,
      "name": "Soil_Pathway"
    },
    {
      "x": 1,
      "y": 6,
      "z": 5,
      "name": "Soil_Pathway"
    },
    {
      "x": 1,
      "y": 7,
      "z": 5,
      "name": "Soil_Pathway"
    },
    {
      "x": 1,
      "y": 8,
      "z": 5,
      "name": "Soil_Pathway"
    },
    {
      "x": 1,
      "y": 6,
      "z": 7,
      "name": "Soil_Pathway"
    },
    {
      "x": 1,
      "y": 7,
      "z": 7,
      "name": "Soil_Pathway"
    },
    {
      "x": 1,
      "y": 8,
      "z": 7,
      "name": "Soil_Pathway"
    },
    {
      "x": 1,
      "y": 7,
      "z": 9,
      "name": "Wood_Tropicalwood_Planks_Half",
      "rotation": 8
    },
    {
      "x": 1,
      "y": 7,
      "z": 10,
      "name": "Wood_Tropicalwood_Planks_Half",
      "rotation": 8
    },
    {
      "x": 1,
      "y": 7,
      "z": 11,
      "name": "Wood_Tropicalwood_Planks_Half",
      "rotation": 8
    },
    {
      "x": 1,
      "y": 7,
      "z": 12,
      "name": "Wood_Tropicalwood_Planks_Half",
      "rotation": 8
    },
    {
      "x": 1,
      "y": 7,
      "z": 13,
      "name": "Wood_Tropicalwood_Planks_Half",
      "rotation": 8
    },
    {
      "x": 1,
      "y": 7,
      "z": 14,
      "name": "Wood_Tropicalwood_Planks_Half",
      "rotation": 8
    },
    {
      "x": 1,
      "y": 7,
      "z": 15,
      "name": "Wood_Tropicalwood_Planks_Half",
      "rotation": 8
    },
    {
      "x": 1,
      "y": 7,
      "z": 16,
      "name": "Wood_Tropicalwood_Planks_Half",
      "rotation": 8
    },
    {
      "x": 1,
      "y": 8,
      "z": 16,
      "name": "Wood_Tropicalwood_Fence"
    },
    {
      "x": 2,
      "y": 6,
      "z": -16,
      "name": "Soil_Pathway"
    },
    {
      "x": 2,
      "y": 7,
      "z": -16,
      "name": "Soil_Pathway"
    },
    {
      "x": 2,
      "y": 8,
      "z": -16,
      "name": "Soil_Pathway"
    },
    {
      "x": 2,
      "y": 12,
      "z": -16,
      "name": "Wood_Tropicalwood_Planks_Half",
      "rotation": 8
    },
    {
      "x": 2,
      "y": 15,
      "z": -16,
      "name": "Wood_Tropicalwood_Roof_Steep",
      "rotation": 2
    },
    {
      "x": 2,
      "y": 16,
      "z": -16,
      "name": "Wood_Tropicalwood_Roof_Steep",
      "filler": 1024,
      "rotation": 2
    },
    {
      "x": 2,
      "y": 6,
      "z": -15,
      "name": "Soil_Pathway"
    },
    {
      "x": 2,
      "y": 7,
      "z": -15,
      "name": "Soil_Pathway"
    },
    {
      "x": 2,
      "y": 8,
      "z": -15,
      "name": "Soil_Pathway"
    },
    {
      "x": 2,
      "y": 12,
      "z": -15,
      "name": "Wood_Tropicalwood_Planks_Half",
      "rotation": 8
    },
    {
      "x": 2,
      "y": 13,
      "z": -15,
      "name": "Wood_Tropicalwood_Planks_Half",
      "rotation": 4
    },
    {
      "x": 2,
      "y": 14,
      "z": -15,
      "name": "Wood_Tropicalwood_Planks_Half",
      "rotation": 4
    },
    {
      "x": 2,
      "y": 15,
      "z": -15,
      "name": "Wood_Tropicalwood_Planks_Half",
      "rotation": 4
    },
    {
      "x": 2,
      "y": 16,
      "z": -15,
      "name": "Wood_Tropicalwood_Decorative"
    },
    {
      "x": 2,
      "y": 17,
      "z": -15,
      "name": "Wood_Tropicalwood_Roof",
      "rotation": 2
    },
    {
      "x": 2,
      "y": 6,
      "z": -14,
      "name": "Soil_Pathway"
    },
    {
      "x": 2,
      "y": 7,
      "z": -14,
      "name": "Soil_Pathway"
    },
    {
      "x": 2,
      "y": 8,
      "z": -14,
      "name": "Soil_Pathway"
    },
    {
      "x": 2,
      "y": 12,
      "z": -14,
      "name": "Wood_Tropicalwood_Planks_Half",
      "rotation": 8
    },
    {
      "x": 2,
      "y": 17,
      "z": -14,
      "name": "Wood_Tropicalwood_Planks_Half",
      "rotation": 8
    },
    {
      "x": 2,
      "y": 18,
      "z": -14,
      "name": "*Wood_Tropicalwood_Roof_Shallow_State_Definitions_Corner_Left",
      "rotation": 1
    },
    {
      "x": 2,
      "y": 6,
      "z": -13,
      "name": "Soil_Pathway"
    },
    {
      "x": 2,
      "y": 7,
      "z": -13,
      "name": "Soil_Pathway"
    },
    {
      "x": 2,
      "y": 8,
      "z": -13,
      "name": "Soil_Pathway"
    },
    {
      "x": 2,
      "y": 12,
      "z": -13,
      "name": "Wood_Tropicalwood_Planks_Half",
      "rotation": 8
    },
    {
      "x": 2,
      "y": 18,
      "z": -13,
      "name": "*Wood_Tropicalwood_Roof_Shallow_State_Definitions_Corner_Left",
      "filler": 32,
      "rotation": 1
    },
    {
      "x": 2,
      "y": 6,
      "z": -12,
      "name": "Soil_Pathway"
    },
    {
      "x": 2,
      "y": 7,
      "z": -12,
      "name": "Soil_Pathway"
    },
    {
      "x": 2,
      "y": 8,
      "z": -12,
      "name": "Soil_Pathway"
    },
    {
      "x": 2,
      "y": 12,
      "z": -12,
      "name": "Wood_Tropicalwood_Planks_Half",
      "rotation": 8
    },
    {
      "x": 2,
      "y": 13,
      "z": -12,
      "name": "Furniture_Crude_Bed",
      "filler": 992,
      "rotation": 2
    },
    {
      "x": 2,
      "y": 18,
      "z": -12,
      "name": "*Wood_Tropicalwood_Roof_Shallow_State_Definitions_Corner_Left",
      "filler": 992
    },
    {
      "x": 2,
      "y": 6,
      "z": -11,
      "name": "Soil_Pathway"
    },
    {
      "x": 2,
      "y": 7,
      "z": -11,
      "name": "Soil_Pathway"
    },
    {
      "x": 2,
      "y": 8,
      "z": -11,
      "name": "Soil_Pathway"
    },
    {
      "x": 2,
      "y": 12,
      "z": -11,
      "name": "Wood_Tropicalwood_Planks_Half",
      "rotation": 8
    },
    {
      "x": 2,
      "y": 13,
      "z": -11,
      "name": "Furniture_Crude_Bed",
      "components": {
        "Components": {
          "PlacedByInteraction": {
            "WhoPlacedUuid": {
              "$binary": "JMPNY5cWR9+IOfPEr8/h7w==",
              "$type": "04"
            }
          },
          "RespawnBlock": {}
        }
      },
      "rotation": 2
    },
    {
      "x": 2,
      "y": 17,
      "z": -11,
      "name": "Wood_Tropicalwood_Planks_Half",
      "rotation": 8
    },
    {
      "x": 2,
      "y": 18,
      "z": -11,
      "name": "*Wood_Tropicalwood_Roof_Shallow_State_Definitions_Corner_Left"
    },
    {
      "x": 2,
      "y": 6,
      "z": -10,
      "name": "Soil_Pathway"
    },
    {
      "x": 2,
      "y": 7,
      "z": -10,
      "name": "Soil_Pathway"
    },
    {
      "x": 2,
      "y": 8,
      "z": -10,
      "name": "Soil_Pathway"
    },
    {
      "x": 2,
      "y": 12,
      "z": -10,
      "name": "Wood_Tropicalwood_Planks_Half",
      "rotation": 8
    },
    {
      "x": 2,
      "y": 13,
      "z": -10,
      "name": "Wood_Tropicalwood_Planks_Half",
      "rotation": 6
    },
    {
      "x": 2,
      "y": 14,
      "z": -10,
      "name": "Wood_Tropicalwood_Planks_Half",
      "rotation": 6
    },
    {
      "x": 2,
      "y": 15,
      "z": -10,
      "name": "Wood_Tropicalwood_Planks_Half",
      "rotation": 6
    },
    {
      "x": 2,
      "y": 16,
      "z": -10,
      "name": "Wood_Tropicalwood_Decorative"
    },
    {
      "x": 2,
      "y": 17,
      "z": -10,
      "name": "Wood_Tropicalwood_Roof"
    },
    {
      "x": 2,
      "y": 6,
      "z": -9,
      "name": "Soil_Pathway"
    },
    {
      "x": 2,
      "y": 7,
      "z": -9,
      "name": "Soil_Pathway"
    },
    {
      "x": 2,
      "y": 8,
      "z": -9,
      "name": "Soil_Pathway"
    },
    {
      "x": 2,
      "y": 12,
      "z": -9,
      "name": "Wood_Tropicalwood_Planks_Half",
      "rotation": 8
    },
    {
      "x": 2,
      "y": 13,
      "z": -9,
      "name": "Furniture_Jungle_Bench",
      "components": {
        "Components": {}
      }
    },
    {
      "x": 2,
      "y": 15,
      "z": -9,
      "name": "Wood_Tropicalwood_Roof_Steep"
    },
    {
      "x": 2,
      "y": 16,
      "z": -9,
      "name": "Wood_Tropicalwood_Roof_Steep",
      "filler": 1024
    },
    {
      "x": 2,
      "y": 6,
      "z": -8,
      "name": "Soil_Pathway"
    },
    {
      "x": 2,
      "y": 7,
      "z": -8,
      "name": "Soil_Pathway"
    },
    {
      "x": 2,
      "y": 8,
      "z": -8,
      "name": "Soil_Pathway"
    },
    {
      "x": 2,
      "y": 12,
      "z": -8,
      "name": "Wood_Tropicalwood_Planks_Half",
      "rotation": 8
    },
    {
      "x": 2,
      "y": 6,
      "z": -4,
      "name": "Soil_Pathway"
    },
    {
      "x": 2,
      "y": 7,
      "z": -4,
      "name": "Soil_Pathway"
    },
    {
      "x": 2,
      "y": 8,
      "z": -4,
      "name": "Soil_Pathway"
    },
    {
      "x": 2,
      "y": 6,
      "z": -3,
      "name": "Soil_Pathway"
    },
    {
      "x": 2,
      "y": 7,
      "z": -3,
      "name": "Soil_Pathway"
    },
    {
      "x": 2,
      "y": 8,
      "z": -3,
      "name": "Soil_Pathway"
    },
    {
      "x": 2,
      "y": 6,
      "z": -2,
      "name": "Soil_Pathway"
    },
    {
      "x": 2,
      "y": 7,
      "z": -2,
      "name": "Soil_Pathway"
    },
    {
      "x": 2,
      "y": 8,
      "z": -2,
      "name": "Soil_Pathway"
    },
    {
      "x": 2,
      "y": 6,
      "z": -1,
      "name": "Soil_Pathway"
    },
    {
      "x": 2,
      "y": 7,
      "z": -1,
      "name": "Soil_Pathway"
    },
    {
      "x": 2,
      "y": 8,
      "z": -1,
      "name": "Soil_Pathway"
    },
    {
      "x": 2,
      "y": 6,
      "z": 1,
      "name": "Soil_Pathway"
    },
    {
      "x": 2,
      "y": 7,
      "z": 1,
      "name": "Soil_Pathway"
    },
    {
      "x": 2,
      "y": 8,
      "z": 1,
      "name": "Soil_Pathway"
    },
    {
      "x": 2,
      "y": 6,
      "z": 2,
      "name": "Soil_Pathway"
    },
    {
      "x": 2,
      "y": 7,
      "z": 2,
      "name": "Soil_Pathway"
    },
    {
      "x": 2,
      "y": 8,
      "z": 2,
      "name": "Soil_Pathway"
    },
    {
      "x": 2,
      "y": 6,
      "z": 3,
      "name": "Soil_Pathway"
    },
    {
      "x": 2,
      "y": 7,
      "z": 3,
      "name": "Soil_Pathway"
    },
    {
      "x": 2,
      "y": 8,
      "z": 3,
      "name": "Soil_Pathway"
    },
    {
      "x": 2,
      "y": 6,
      "z": 8,
      "name": "Soil_Pathway"
    },
    {
      "x": 2,
      "y": 7,
      "z": 8,
      "name": "Soil_Pathway"
    },
    {
      "x": 2,
      "y": 8,
      "z": 8,
      "name": "Soil_Pathway"
    },
    {
      "x": 2,
      "y": 7,
      "z": 9,
      "name": "Wood_Tropicalwood_Planks_Half",
      "rotation": 8
    },
    {
      "x": 2,
      "y": 7,
      "z": 10,
      "name": "Wood_Tropicalwood_Planks_Half",
      "rotation": 8
    },
    {
      "x": 2,
      "y": 8,
      "z": 10,
      "name": "Wood_Tropicalwood_Fence",
      "rotation": 1
    },
    {
      "x": 2,
      "y": 7,
      "z": 11,
      "name": "Wood_Tropicalwood_Planks_Half",
      "rotation": 8
    },
    {
      "x": 2,
      "y": 8,
      "z": 11,
      "name": "Wood_Tropicalwood_Fence",
      "rotation": 1
    },
    {
      "x": 2,
      "y": 7,
      "z": 12,
      "name": "Wood_Tropicalwood_Planks_Half",
      "rotation": 8
    },
    {
      "x": 2,
      "y": 8,
      "z": 12,
      "name": "Wood_Tropicalwood_Fence",
      "rotation": 1
    },
    {
      "x": 2,
      "y": 7,
      "z": 13,
      "name": "Wood_Tropicalwood_Planks_Half",
      "rotation": 8
    },
    {
      "x": 2,
      "y": 7,
      "z": 14,
      "name": "Wood_Tropicalwood_Planks_Half",
      "rotation": 8
    },
    {
      "x": 2,
      "y": 7,
      "z": 15,
      "name": "Wood_Tropicalwood_Planks_Half",
      "rotation": 8
    },
    {
      "x": 2,
      "y": 8,
      "z": 15,
      "name": "Wood_Tropicalwood_Fence",
      "rotation": 1
    },
    {
      "x": 2,
      "y": 0,
      "z": 16,
      "name": "Wood_Bamboo_Branch_Long_Deco",
      "support": 15
    },
    {
      "x": 2,
      "y": 1,
      "z": 16,
      "name": "Wood_Bamboo_Branch_Long_Deco",
      "support": 15
    },
    {
      "x": 2,
      "y": 2,
      "z": 16,
      "name": "Wood_Bamboo_Branch_Long_Deco",
      "support": 15
    },
    {
      "x": 2,
      "y": 3,
      "z": 16,
      "name": "Wood_Bamboo_Branch_Long_Deco",
      "support": 15
    },
    {
      "x": 2,
      "y": 4,
      "z": 16,
      "name": "Wood_Bamboo_Branch_Long_Deco",
      "support": 15
    },
    {
      "x": 2,
      "y": 5,
      "z": 16,
      "name": "Wood_Bamboo_Branch_Long_Deco",
      "support": 15
    },
    {
      "x": 2,
      "y": 6,
      "z": 16,
      "name": "Wood_Bamboo_Branch_Long_Deco",
      "support": 15
    },
    {
      "x": 2,
      "y": 7,
      "z": 16,
      "name": "Wood_Bamboo_Trunk_Deco",
      "support": 15
    },
    {
      "x": 2,
      "y": 8,
      "z": 16,
      "name": "*Wood_Tropicalwood_Fence_State_Definitions_Corner",
      "rotation": 3
    },
    {
      "x": 3,
      "y": 6,
      "z": -16,
      "name": "Soil_Pathway"
    },
    {
      "x": 3,
      "y": 7,
      "z": -16,
      "name": "Soil_Pathway"
    },
    {
      "x": 3,
      "y": 8,
      "z": -16,
      "name": "Soil_Pathway"
    },
    {
      "x": 3,
      "y": 12,
      "z": -16,
      "name": "Wood_Tropicalwood_Planks_Half",
      "rotation": 8
    },
    {
      "x": 3,
      "y": 15,
      "z": -16,
      "name": "Wood_Tropicalwood_Roof_Steep",
      "rotation": 2
    },
    {
      "x": 3,
      "y": 16,
      "z": -16,
      "name": "Wood_Tropicalwood_Roof_Steep",
      "filler": 1024,
      "rotation": 2
    },
    {
      "x": 3,
      "y": 6,
      "z": -15,
      "name": "Soil_Pathway"
    },
    {
      "x": 3,
      "y": 7,
      "z": -15,
      "name": "Soil_Pathway"
    },
    {
      "x": 3,
      "y": 8,
      "z": -15,
      "name": "Soil_Pathway"
    },
    {
      "x": 3,
      "y": 12,
      "z": -15,
      "name": "Wood_Tropicalwood_Planks_Half",
      "rotation": 8
    },
    {
      "x": 3,
      "y": 13,
      "z": -15,
      "name": "Wood_Bamboo_Trunk_Deco",
      "support": 15
    },
    {
      "x": 3,
      "y": 14,
      "z": -15,
      "name": "Wood_Bamboo_Trunk_Deco",
      "support": 15
    },
    {
      "x": 3,
      "y": 15,
      "z": -15,
      "name": "Wood_Bamboo_Trunk_Deco",
      "support": 15
    },
    {
      "x": 3,
      "y": 16,
      "z": -15,
      "name": "Wood_Bamboo_Trunk_Deco",
      "support": 15
    },
    {
      "x": 3,
      "y": 17,
      "z": -15,
      "name": "*Wood_Tropicalwood_Roof_State_Definitions_Corner_Left",
      "rotation": 1
    },
    {
      "x": 3,
      "y": 6,
      "z": -14,
      "name": "Soil_Pathway"
    },
    {
      "x": 3,
      "y": 7,
      "z": -14,
      "name": "Soil_Pathway"
    },
    {
      "x": 3,
      "y": 8,
      "z": -14,
      "name": "Soil_Pathway"
    },
    {
      "x": 3,
      "y": 12,
      "z": -14,
      "name": "Wood_Tropicalwood_Planks_Half",
      "rotation": 8
    },
    {
      "x": 3,
      "y": 13,
      "z": -14,
      "name": "Wood_Tropicalwood_Planks_Half",
      "rotation": 7
    },
    {
      "x": 3,
      "y": 14,
      "z": -14,
      "name": "Wood_Tropicalwood_Planks_Half",
      "rotation": 7
    },
    {
      "x": 3,
      "y": 15,
      "z": -14,
      "name": "Wood_Tropicalwood_Planks_Half",
      "rotation": 7
    },
    {
      "x": 3,
      "y": 16,
      "z": -14,
      "name": "Wood_Tropicalwood_Decorative"
    },
    {
      "x": 3,
      "y": 17,
      "z": -14,
      "name": "Wood_Tropicalwood_Roof",
      "rotation": 1
    },
    {
      "x": 3,
      "y": 6,
      "z": -13,
      "name": "Soil_Pathway"
    },
    {
      "x": 3,
      "y": 7,
      "z": -13,
      "name": "Soil_Pathway"
    },
    {
      "x": 3,
      "y": 8,
      "z": -13,
      "name": "Soil_Pathway"
    },
    {
      "x": 3,
      "y": 12,
      "z": -13,
      "name": "Wood_Tropicalwood_Planks_Half",
      "rotation": 8
    },
    {
      "x": 3,
      "y": 13,
      "z": -13,
      "name": "Wood_Tropicalwood_Planks_Half",
      "rotation": 7
    },
    {
      "x": 3,
      "y": 14,
      "z": -13,
      "name": "Wood_Tropicalwood_Fence",
      "rotation": 3
    },
    {
      "x": 3,
      "y": 15,
      "z": -13,
      "name": "Wood_Tropicalwood_Planks_Half",
      "rotation": 7
    },
    {
      "x": 3,
      "y": 16,
      "z": -13,
      "name": "Wood_Tropicalwood_Decorative"
    },
    {
      "x": 3,
      "y": 17,
      "z": -13,
      "name": "Wood_Tropicalwood_Roof",
      "rotation": 1
    },
    {
      "x": 3,
      "y": 6,
      "z": -12,
      "name": "Soil_Pathway"
    },
    {
      "x": 3,
      "y": 7,
      "z": -12,
      "name": "Soil_Pathway"
    },
    {
      "x": 3,
      "y": 8,
      "z": -12,
      "name": "Soil_Pathway"
    },
    {
      "x": 3,
      "y": 12,
      "z": -12,
      "name": "Wood_Tropicalwood_Planks_Half",
      "rotation": 8
    },
    {
      "x": 3,
      "y": 13,
      "z": -12,
      "name": "Wood_Tropicalwood_Planks_Half",
      "rotation": 7
    },
    {
      "x": 3,
      "y": 14,
      "z": -12,
      "name": "Wood_Tropicalwood_Fence",
      "rotation": 3
    },
    {
      "x": 3,
      "y": 15,
      "z": -12,
      "name": "Wood_Tropicalwood_Planks_Half",
      "rotation": 7
    },
    {
      "x": 3,
      "y": 16,
      "z": -12,
      "name": "Wood_Tropicalwood_Decorative"
    },
    {
      "x": 3,
      "y": 17,
      "z": -12,
      "name": "Wood_Tropicalwood_Roof",
      "rotation": 1
    },
    {
      "x": 3,
      "y": 6,
      "z": -11,
      "name": "Soil_Pathway"
    },
    {
      "x": 3,
      "y": 7,
      "z": -11,
      "name": "Soil_Pathway"
    },
    {
      "x": 3,
      "y": 8,
      "z": -11,
      "name": "Soil_Pathway"
    },
    {
      "x": 3,
      "y": 12,
      "z": -11,
      "name": "Wood_Tropicalwood_Planks_Half",
      "rotation": 8
    },
    {
      "x": 3,
      "y": 13,
      "z": -11,
      "name": "Wood_Tropicalwood_Planks_Half",
      "rotation": 7
    },
    {
      "x": 3,
      "y": 14,
      "z": -11,
      "name": "Wood_Tropicalwood_Planks_Half",
      "rotation": 7
    },
    {
      "x": 3,
      "y": 15,
      "z": -11,
      "name": "Wood_Tropicalwood_Planks_Half",
      "rotation": 7
    },
    {
      "x": 3,
      "y": 16,
      "z": -11,
      "name": "Wood_Tropicalwood_Decorative"
    },
    {
      "x": 3,
      "y": 17,
      "z": -11,
      "name": "Wood_Tropicalwood_Roof",
      "rotation": 1
    },
    {
      "x": 3,
      "y": 6,
      "z": -10,
      "name": "Soil_Pathway"
    },
    {
      "x": 3,
      "y": 7,
      "z": -10,
      "name": "Soil_Pathway"
    },
    {
      "x": 3,
      "y": 8,
      "z": -10,
      "name": "Soil_Pathway"
    },
    {
      "x": 3,
      "y": 12,
      "z": -10,
      "name": "Wood_Tropicalwood_Planks_Half",
      "rotation": 8
    },
    {
      "x": 3,
      "y": 13,
      "z": -10,
      "name": "Wood_Bamboo_Trunk_Deco",
      "support": 15
    },
    {
      "x": 3,
      "y": 14,
      "z": -10,
      "name": "Wood_Bamboo_Trunk_Deco",
      "support": 15
    },
    {
      "x": 3,
      "y": 15,
      "z": -10,
      "name": "Wood_Bamboo_Trunk_Deco",
      "support": 15
    },
    {
      "x": 3,
      "y": 16,
      "z": -10,
      "name": "Wood_Bamboo_Trunk_Deco",
      "support": 15
    },
    {
      "x": 3,
      "y": 17,
      "z": -10,
      "name": "*Wood_Tropicalwood_Roof_State_Definitions_Corner_Right",
      "rotation": 1
    },
    {
      "x": 3,
      "y": 6,
      "z": -9,
      "name": "Soil_Pathway"
    },
    {
      "x": 3,
      "y": 7,
      "z": -9,
      "name": "Soil_Pathway"
    },
    {
      "x": 3,
      "y": 8,
      "z": -9,
      "name": "Soil_Pathway"
    },
    {
      "x": 3,
      "y": 12,
      "z": -9,
      "name": "Wood_Tropicalwood_Planks_Half",
      "rotation": 8
    },
    {
      "x": 3,
      "y": 15,
      "z": -9,
      "name": "Wood_Tropicalwood_Roof_Steep"
    },
    {
      "x": 3,
      "y": 16,
      "z": -9,
      "name": "Wood_Tropicalwood_Roof_Steep",
      "filler": 1024
    },
    {
      "x": 3,
      "y": 6,
      "z": -8,
      "name": "Soil_Pathway"
    },
    {
      "x": 3,
      "y": 7,
      "z": -8,
      "name": "Soil_Pathway"
    },
    {
      "x": 3,
      "y": 8,
      "z": -8,
      "name": "Soil_Pathway"
    },
    {
      "x": 3,
      "y": 12,
      "z": -8,
      "name": "Wood_Tropicalwood_Planks_Half",
      "rotation": 8
    },
    {
      "x": 3,
      "y": 6,
      "z": -6,
      "name": "Soil_Pathway"
    },
    {
      "x": 3,
      "y": 7,
      "z": -6,
      "name": "Soil_Pathway"
    },
    {
      "x": 3,
      "y": 8,
      "z": -6,
      "name": "Soil_Pathway"
    },
    {
      "x": 3,
      "y": 6,
      "z": -5,
      "name": "Soil_Pathway"
    },
    {
      "x": 3,
      "y": 7,
      "z": -5,
      "name": "Soil_Pathway"
    },
    {
      "x": 3,
      "y": 8,
      "z": -5,
      "name": "Soil_Pathway"
    },
    {
      "x": 3,
      "y": 6,
      "z": -3,
      "name": "Soil_Pathway"
    },
    {
      "x": 3,
      "y": 7,
      "z": -3,
      "name": "Soil_Pathway"
    },
    {
      "x": 3,
      "y": 8,
      "z": -3,
      "name": "Soil_Pathway"
    },
    {
      "x": 3,
      "y": 3,
      "z": 14,
      "name": "Furniture_Jungle_Ladder",
      "rotation": 1
    },
    {
      "x": 3,
      "y": 4,
      "z": 14,
      "name": "Furniture_Jungle_Ladder",
      "rotation": 1
    },
    {
      "x": 3,
      "y": 5,
      "z": 14,
      "name": "Furniture_Jungle_Ladder",
      "rotation": 1
    },
    {
      "x": 3,
      "y": 6,
      "z": 14,
      "name": "Furniture_Jungle_Ladder",
      "rotation": 1
    },
    {
      "x": 3,
      "y": 7,
      "z": 14,
      "name": "Furniture_Jungle_Ladder",
      "rotation": 1
    },
    {
      "x": 4,
      "y": 6,
      "z": -16,
      "name": "Soil_Pathway"
    },
    {
      "x": 4,
      "y": 7,
      "z": -16,
      "name": "Soil_Pathway"
    },
    {
      "x": 4,
      "y": 8,
      "z": -16,
      "name": "Wood_Bamboo_Branch_Long_Deco",
      "support": 15
    },
    {
      "x": 4,
      "y": 9,
      "z": -16,
      "name": "Wood_Bamboo_Branch_Long_Deco",
      "support": 15
    },
    {
      "x": 4,
      "y": 10,
      "z": -16,
      "name": "Wood_Bamboo_Branch_Long_Deco",
      "support": 15
    },
    {
      "x": 4,
      "y": 11,
      "z": -16,
      "name": "Wood_Bamboo_Branch_Long_Deco",
      "support": 15
    },
    {
      "x": 4,
      "y": 12,
      "z": -16,
      "name": "Wood_Bamboo_Trunk_Deco",
      "support": 15
    },
    {
      "x": 4,
      "y": 15,
      "z": -16,
      "name": "*Wood_Tropicalwood_Roof_Steep_State_Definitions_Corner_Right",
      "rotation": 2
    },
    {
      "x": 4,
      "y": 16,
      "z": -16,
      "name": "*Wood_Tropicalwood_Roof_Steep_State_Definitions_Corner_Right",
      "filler": 1024,
      "rotation": 2
    },
    {
      "x": 4,
      "y": 6,
      "z": -15,
      "name": "Soil_Pathway"
    },
    {
      "x": 4,
      "y": 7,
      "z": -15,
      "name": "Soil_Pathway"
    },
    {
      "x": 4,
      "y": 8,
      "z": -15,
      "name": "Soil_Pathway"
    },
    {
      "x": 4,
      "y": 12,
      "z": -15,
      "name": "Wood_Tropicalwood_Planks_Half",
      "rotation": 8
    },
    {
      "x": 4,
      "y": 15,
      "z": -15,
      "name": "Wood_Tropicalwood_Roof_Steep",
      "rotation": 1
    },
    {
      "x": 4,
      "y": 16,
      "z": -15,
      "name": "Wood_Tropicalwood_Roof_Steep",
      "filler": 1024,
      "rotation": 1
    },
    {
      "x": 4,
      "y": 6,
      "z": -14,
      "name": "Soil_Pathway"
    },
    {
      "x": 4,
      "y": 7,
      "z": -14,
      "name": "Soil_Pathway"
    },
    {
      "x": 4,
      "y": 8,
      "z": -14,
      "name": "Soil_Pathway"
    },
    {
      "x": 4,
      "y": 12,
      "z": -14,
      "name": "Wood_Tropicalwood_Planks_Half",
      "rotation": 8
    },
    {
      "x": 4,
      "y": 15,
      "z": -14,
      "name": "Wood_Tropicalwood_Roof_Steep",
      "rotation": 1
    },
    {
      "x": 4,
      "y": 16,
      "z": -14,
      "name": "Wood_Tropicalwood_Roof_Steep",
      "filler": 1024,
      "rotation": 1
    },
    {
      "x": 4,
      "y": 6,
      "z": -13,
      "name": "Soil_Pathway"
    },
    {
      "x": 4,
      "y": 7,
      "z": -13,
      "name": "Soil_Pathway"
    },
    {
      "x": 4,
      "y": 8,
      "z": -13,
      "name": "Soil_Pathway"
    },
    {
      "x": 4,
      "y": 12,
      "z": -13,
      "name": "Wood_Tropicalwood_Planks_Half",
      "rotation": 8
    },
    {
      "x": 4,
      "y": 15,
      "z": -13,
      "name": "Wood_Tropicalwood_Roof_Steep",
      "rotation": 1
    },
    {
      "x": 4,
      "y": 16,
      "z": -13,
      "name": "Wood_Tropicalwood_Roof_Steep",
      "filler": 1024,
      "rotation": 1
    },
    {
      "x": 4,
      "y": 6,
      "z": -12,
      "name": "Soil_Pathway"
    },
    {
      "x": 4,
      "y": 7,
      "z": -12,
      "name": "Soil_Pathway"
    },
    {
      "x": 4,
      "y": 8,
      "z": -12,
      "name": "Soil_Pathway"
    },
    {
      "x": 4,
      "y": 12,
      "z": -12,
      "name": "Wood_Tropicalwood_Planks_Half",
      "rotation": 8
    },
    {
      "x": 4,
      "y": 15,
      "z": -12,
      "name": "Wood_Tropicalwood_Roof_Steep",
      "rotation": 1
    },
    {
      "x": 4,
      "y": 16,
      "z": -12,
      "name": "Wood_Tropicalwood_Roof_Steep",
      "filler": 1024,
      "rotation": 1
    },
    {
      "x": 4,
      "y": 6,
      "z": -11,
      "name": "Soil_Pathway"
    },
    {
      "x": 4,
      "y": 7,
      "z": -11,
      "name": "Soil_Pathway"
    },
    {
      "x": 4,
      "y": 8,
      "z": -11,
      "name": "Soil_Pathway"
    },
    {
      "x": 4,
      "y": 12,
      "z": -11,
      "name": "Wood_Tropicalwood_Planks_Half",
      "rotation": 8
    },
    {
      "x": 4,
      "y": 15,
      "z": -11,
      "name": "Wood_Tropicalwood_Roof_Steep",
      "rotation": 1
    },
    {
      "x": 4,
      "y": 16,
      "z": -11,
      "name": "Wood_Tropicalwood_Roof_Steep",
      "filler": 1024,
      "rotation": 1
    },
    {
      "x": 4,
      "y": 6,
      "z": -10,
      "name": "Soil_Pathway"
    },
    {
      "x": 4,
      "y": 7,
      "z": -10,
      "name": "Soil_Pathway"
    },
    {
      "x": 4,
      "y": 8,
      "z": -10,
      "name": "Soil_Pathway"
    },
    {
      "x": 4,
      "y": 12,
      "z": -10,
      "name": "Wood_Tropicalwood_Planks_Half",
      "rotation": 8
    },
    {
      "x": 4,
      "y": 15,
      "z": -10,
      "name": "Wood_Tropicalwood_Roof_Steep",
      "rotation": 1
    },
    {
      "x": 4,
      "y": 16,
      "z": -10,
      "name": "Wood_Tropicalwood_Roof_Steep",
      "filler": 1024,
      "rotation": 1
    },
    {
      "x": 4,
      "y": 6,
      "z": -9,
      "name": "Soil_Pathway"
    },
    {
      "x": 4,
      "y": 7,
      "z": -9,
      "name": "Soil_Pathway"
    },
    {
      "x": 4,
      "y": 8,
      "z": -9,
      "name": "Soil_Pathway"
    },
    {
      "x": 4,
      "y": 12,
      "z": -9,
      "name": "Wood_Tropicalwood_Planks_Half",
      "rotation": 8
    },
    {
      "x": 4,
      "y": 15,
      "z": -9,
      "name": "*Wood_Tropicalwood_Roof_Steep_State_Definitions_Corner_Right",
      "rotation": 1
    },
    {
      "x": 4,
      "y": 16,
      "z": -9,
      "name": "*Wood_Tropicalwood_Roof_Steep_State_Definitions_Corner_Right",
      "filler": 1024,
      "rotation": 1
    },
    {
      "x": 4,
      "y": 6,
      "z": -8,
      "name": "Soil_Pathway"
    },
    {
      "x": 4,
      "y": 7,
      "z": -8,
      "name": "Soil_Pathway"
    },
    {
      "x": 4,
      "y": 8,
      "z": -8,
      "name": "Wood_Bamboo_Branch_Long_Deco",
      "support": 15
    },
    {
      "x": 4,
      "y": 9,
      "z": -8,
      "name": "Wood_Bamboo_Branch_Long_Deco",
      "support": 15
    },
    {
      "x": 4,
      "y": 10,
      "z": -8,
      "name": "Wood_Bamboo_Branch_Long_Deco",
      "support": 15
    },
    {
      "x": 4,
      "y": 11,
      "z": -8,
      "name": "Wood_Bamboo_Branch_Long_Deco",
      "support": 15
    },
    {
      "x": 4,
      "y": 12,
      "z": -8,
      "name": "Wood_Bamboo_Trunk_Deco",
      "support": 15
    },
    {
      "x": 4,
      "y": 6,
      "z": -7,
      "name": "Soil_Pathway"
    },
    {
      "x": 4,
      "y": 7,
      "z": -7,
      "name": "Soil_Pathway"
    },
    {
      "x": 4,
      "y": 8,
      "z": -7,
      "name": "Furniture_Jungle_Ladder"
    },
    {
      "x": 4,
      "y": 9,
      "z": -7,
      "name": "Furniture_Jungle_Ladder"
    },
    {
      "x": 4,
      "y": 10,
      "z": -7,
      "name": "Furniture_Jungle_Ladder"
    },
    {
      "x": 4,
      "y": 11,
      "z": -7,
      "name": "Furniture_Jungle_Ladder"
    },
    {
      "x": 4,
      "y": 12,
      "z": -7,
      "name": "Furniture_Jungle_Ladder"
    },
    {
      "x": 5,
      "y": 6,
      "z": -13,
      "name": "Soil_Pathway"
    },
    {
      "x": 5,
      "y": 7,
      "z": -13,
      "name": "Soil_Pathway"
    },
    {
      "x": 5,
      "y": 8,
      "z": -13,
      "name": "Soil_Pathway"
    },
    {
      "x": 5,
      "y": 6,
      "z": -12,
      "name": "Soil_Pathway"
    },
    {
      "x": 5,
      "y": 7,
      "z": -12,
      "name": "Soil_Pathway"
    },
    {
      "x": 5,
      "y": 8,
      "z": -12,
      "name": "Soil_Pathway"
    },
    {
      "x": 5,
      "y": 6,
      "z": -11,
      "name": "Soil_Pathway"
    },
    {
      "x": 5,
      "y": 7,
      "z": -11,
      "name": "Soil_Pathway"
    },
    {
      "x": 5,
      "y": 8,
      "z": -11,
      "name": "Soil_Pathway"
    }
  ]
}