{
  "version": 8,
  "blockIdVersion": 11,
  "anchorX": 0,
  "anchorY": 0,
  "anchorZ": 0,
  "blocks": [
    {
      "x": -11,
      "y": 24,
      "z": 0,
      "name": "Plant_Leaves_Bottle"
    },
    {
      "x": -11,
      "y": 22,
      "z": 1,
      "name": "Plant_Leaves_Bottle"
    },
    {
      "x": -11,
      "y": 23,
      "z": 1,
      "name": "Plant_Leaves_Bottle"
    },
    {
      "x": -11,
      "y": 24,
      "z": 1,
      "name": "Plant_Leaves_Bottle"
    },
    {
      "x": -11,
      "y": 25,
      "z": 1,
      "name": "Plant_Leaves_Bottle"
    },
    {
      "x": -11,
      "y": 23,
      "z": 2,
      "name": "Plant_Leaves_Bottle"
    },
    {
      "x": -11,
      "y": 24,
      "z": 2,
      "name": "Plant_Leaves_Bottle"
    },
    {
      "x": -10,
      "y": 22,
      "z": -1,
      "name": "Plant_Leaves_Bottle"
    },
    {
      "x": -10,
      "y": 23,
      "z": -1,
      "name": "Plant_Leaves_Bottle"
    },
    {
      "x": -10,
      "y": 24,
      "z": -1,
      "name": "Plant_Leaves_Bottle"
    },
    {
      "x": -10,
      "y": 25,
      "z": -1,
      "name": "Plant_Leaves_Bottle"
    },
    {
      "x": -10,
      "y": 23,
      "z": 0,
      "name": "Plant_Leaves_Bottle"
    },
    {
      "x": -10,
      "y": 24,
      "z": 0,
      "name": "Plant_Leaves_Bottle"
    },
    {
      "x": -10,
      "y": 25,
      "z": 0,
      "name": "Plant_Leaves_Bottle"
    },
    {
      "x": -10,
      "y": 26,
      "z": 0,
      "name": "Plant_Leaves_Bottle"
    },
    {
      "x": -10,
      "y": 23,
      "z": 1,
      "name": "Plant_Leaves_Bottle"
    },
    {
      "x": -10,
      "y": 26,
      "z": 1,
      "name": "Plant_Leaves_Bottle"
    },
    {
      "x": -10,
      "y": 21,
      "z": 2,
      "name": "Plant_Leaves_Bottle"
    },
    {
      "x": -10,
      "y": 22,
      "z": 2,
      "name": "Plant_Leaves_Bottle"
    },
    {
      "x": -10,
      "y": 23,
      "z": 2,
      "name": "Plant_Leaves_Bottle"
    },
    {
      "x": -10,
      "y": 24,
      "z": 2,
      "name": "Plant_Leaves_Bottle"
    },
    {
      "x": -10,
      "y": 25,
      "z": 2,
      "name": "Plant_Leaves_Bottle"
    },
    {
      "x": -10,
      "y": 26,
      "z": 2,
      "name": "Plant_Leaves_Bottle"
    },
    {
      "x": -10,
      "y": 22,
      "z": 3,
      "name": "Plant_Leaves_Bottle"
    },
    {
      "x": -10,
      "y": 23,
      "z": 3,
      "name": "Plant_Leaves_Bottle"
    },
    {
      "x": -10,
      "y": 24,
      "z": 3,
      "name": "Plant_Leaves_Bottle"
    },
    {
      "x": -9,
      "y": 22,
      "z": -2,
      "name": "Plant_Leaves_Bottle"
    },
    {
      "x": -9,
      "y": 23,
      "z": -2,
      "name": "Plant_Leaves_Bottle"
    },
    {
      "x": -9,
      "y": 24,
      "z": -2,
      "name": "Plant_Leaves_Bottle"
    },
    {
      "x": -9,
      "y": 25,
      "z": -1,
      "name": "Plant_Leaves_Bottle"
    },
    {
      "x": -9,
      "y": 23,
      "z": 0,
      "name": "Plant_Leaves_Bottle"
    },
    {
      "x": -9,
      "y": 24,
      "z": 0,
      "name": "Plant_Leaves_Bottle"
    },
    {
      "x": -9,
      "y": 25,
      "z": 0,
      "name": "Plant_Leaves_Bottle"
    },
    {
      "x": -9,
      "y": 26,
      "z": 0,
      "name": "Plant_Leaves_Bottle"
    },
    {
      "x": -9,
      "y": 24,
      "z": 1,
      "name": "Plant_Leaves_Bottle"
    },
    {
      "x": -9,
      "y": 25,
      "z": 1,
      "name": "Plant_Leaves_Bottle"
    },
    {
      "x": -9,
      "y": 23,
      "z": 2,
      "name": "Plant_Leaves_Bottle"
    },
    {
      "x": -9,
      "y": 24,
      "z": 2,
      "name": "Plant_Leaves_Bottle"
    },
    {
      "x": -9,
      "y": 25,
      "z": 2,
      "name": "Plant_Leaves_Bottle"
    },
    {
      "x": -9,
      "y": 26,
      "z": 2,
      "name": "Plant_Leaves_Bottle"
    },
    {
      "x": -9,
      "y": 26,
      "z": 3,
      "name": "Plant_Leaves_Bottle"
    },
    {
      "x": -9,
      "y": 22,
      "z": 4,
      "name": "Plant_Leaves_Bottle"
    },
    {
      "x": -9,
      "y": 23,
      "z": 4,
      "name": "Plant_Leaves_Bottle"
    },
    {
      "x": -9,
      "y": 24,
      "z": 4,
      "name": "Plant_Leaves_Bottle"
    },
    {
      "x": -8,
      "y": 21,
      "z": -2,
      "name": "Plant_Leaves_Bottle"
    },
    {
      "x": -8,
      "y": 22,
      "z": -2,
      "name": "Plant_Leaves_Bottle"
    },
    {
      "x": -8,
      "y": 23,
      "z": -2,
      "name": "Plant_Leaves_Bottle"
    },
    {
      "x": -8,
      "y": 24,
      "z": -2,
      "name": "Plant_Leaves_Bottle"
    },
    {
      "x": -8,
      "y": 23,
      "z": -1,
      "name": "Plant_Leaves_Bottle"
    },
    {
      "x": -8,
      "y": 24,
      "z": -1,
      "name": "Plant_Leaves_Bottle"
    },
    {
      "x": -8,
      "y": 23,
      "z": 0,
      "name": "Plant_Leaves_Bottle"
    },
    {
      "x": -8,
      "y": 24,
      "z": 0,
      "name": "Plant_Leaves_Bottle"
    },
    {
      "x": -8,
      "y": 25,
      "z": 0,
      "name": "Plant_Leaves_Bottle"
    },
    {
      "x": -8,
      "y": 26,
      "z": 0,
      "name": "Plant_Leaves_Bottle"
    },
    {
      "x": -8,
      "y": 21,
      "z": 1,
      "name": "Soil_Plant_Vine_Block"
    },
    {
      "x": -8,
      "y": 22,
      "z": 1,
      "name": "Soil_Plant_Vine_Block"
    },
    {
      "x": -8,
      "y": 23,
      "z": 1,
      "name": "Vine_Branch_Long"
    },
    {
      "x": -8,
      "y": 24,
      "z": 1,
      "name": "Vine_Branch_Long"
    },
    {
      "x": -8,
      "y": 25,
      "z": 1,
      "name": "Plant_Leaves_Bottle"
    },
    {
      "x": -8,
      "y": 26,
      "z": 1,
      "name": "Plant_Leaves_Bottle"
    },
    {
      "x": -8,
      "y": 22,
      "z": 2,
      "name": "Vine_Branch_Long",
      "rotation": 4
    },
    {
      "x": -8,
      "y": 22,
      "z": 3,
      "name": "Vine_Branch_Long",
      "rotation": 4
    },
    {
      "x": -8,
      "y": 24,
      "z": 3,
      "name": "Plant_Leaves_Bottle"
    },
    {
      "x": -8,
      "y": 25,
      "z": 3,
      "name": "Plant_Leaves_Bottle"
    },
    {
      "x": -8,
      "y": 26,
      "z": 3,
      "name": "Plant_Leaves_Bottle"
    },
    {
      "x": -8,
      "y": 23,
      "z": 4,
      "name": "Plant_Leaves_Bottle"
    },
    {
      "x": -8,
      "y": 24,
      "z": 4,
      "name": "Plant_Leaves_Bottle"
    },
    {
      "x": -7,
      "y": 24,
      "z": -5,
      "name": "Plant_Leaves_Bottle"
    },
    {
      "x": -7,
      "y": 23,
      "z": -4,
      "name": "Plant_Leaves_Bottle"
    },
    {
      "x": -7,
      "y": 24,
      "z": -4,
      "name": "Plant_Leaves_Bottle"
    },
    {
      "x": -7,
      "y": 25,
      "z": -4,
      "name": "Plant_Leaves_Bottle"
    },
    {
      "x": -7,
      "y": 24,
      "z": -3,
      "name": "Plant_Leaves_Bottle"
    },
    {
      "x": -7,
      "y": 25,
      "z": -3,
      "name": "Plant_Leaves_Bottle"
    },
    {
      "x": -7,
      "y": 26,
      "z": -3,
      "name": "Plant_Leaves_Bottle"
    },
    {
      "x": -7,
      "y": 25,
      "z": -2,
      "name": "Plant_Leaves_Bottle"
    },
    {
      "x": -7,
      "y": 23,
      "z": -1,
      "name": "Plant_Leaves_Bottle"
    },
    {
      "x": -7,
      "y": 24,
      "z": -1,
      "name": "Plant_Leaves_Bottle"
    },
    {
      "x": -7,
      "y": 21,
      "z": 0,
      "name": "Vine_Branch_Corner",
      "rotation": 2
    },
    {
      "x": -7,
      "y": 22,
      "z": 0,
      "name": "Vine_Branch_Long"
    },
    {
      "x": -7,
      "y": 23,
      "z": 0,
      "name": "Vine_Branch_Long"
    },
    {
      "x": -7,
      "y": 24,
      "z": 0,
      "name": "Plant_Leaves_Bottle"
    },
    {
      "x": -7,
      "y": 25,
      "z": 0,
      "name": "Plant_Leaves_Bottle"
    },
    {
      "x": -7,
      "y": 19,
      "z": 1,
      "name": "Soil_Plant_Vine_Block"
    },
    {
      "x": -7,
      "y": 20,
      "z": 1,
      "name": "Soil_Plant_Vine_Block"
    },
    {
      "x": -7,
      "y": 21,
      "z": 1,
      "name": "Soil_Plant_Vine_Block"
    },
    {
      "x": -7,
      "y": 23,
      "z": 1,
      "name": "Plant_Leaves_Bottle"
    },
    {
      "x": -7,
      "y": 24,
      "z": 1,
      "name": "Plant_Leaves_Bottle"
    },
    {
      "x": -7,
      "y": 25,
      "z": 1,
      "name": "Plant_Leaves_Bottle"
    },
    {
      "x": -7,
      "y": 26,
      "z": 1,
      "name": "Plant_Leaves_Bottle"
    },
    {
      "x": -7,
      "y": 19,
      "z": 2,
      "name": "Soil_Plant_Vine_Block"
    },
    {
      "x": -7,
      "y": 24,
      "z": 2,
      "name": "Plant_Leaves_Bottle"
    },
    {
      "x": -7,
      "y": 25,
      "z": 2,
      "name": "Plant_Leaves_Bottle"
    },
    {
      "x": -7,
      "y": 26,
      "z": 2,
      "name": "Plant_Leaves_Bottle"
    },
    {
      "x": -7,
      "y": 24,
      "z": 3,
      "name": "Plant_Leaves_Bottle"
    },
    {
      "x": -7,
      "y": 25,
      "z": 3,
      "name": "Plant_Leaves_Bottle"
    },
    {
      "x": -7,
      "y": 26,
      "z": 3,
      "name": "Plant_Leaves_Bottle"
    },
    {
      "x": -7,
      "y": 23,
      "z": 4,
      "name": "Plant_Leaves_Bottle"
    },
    {
      "x": -7,
      "y": 24,
      "z": 4,
      "name": "Plant_Leaves_Bottle"
    },
    {
      "x": -7,
      "y": 25,
      "z": 4,
      "name": "Plant_Leaves_Bottle"
    },
    {
      "x": -6,
      "y": 24,
      "z": -6,
      "name": "Plant_Leaves_Bottle"
    },
    {
      "x": -6,
      "y": 23,
      "z": -5,
      "name": "Plant_Leaves_Bottle"
    },
    {
      "x": -6,
      "y": 24,
      "z": -5,
      "name": "Plant_Leaves_Bottle"
    },
    {
      "x": -6,
      "y": 25,
      "z": -5,
      "name": "Plant_Leaves_Bottle"
    },
    {
      "x": -6,
      "y": 25,
      "z": -4,
      "name": "Plant_Leaves_Bottle"
    },
    {
      "x": -6,
      "y": 26,
      "z": -4,
      "name": "Plant_Leaves_Bottle"
    },
    {
      "x": -6,
      "y": 25,
      "z": -3,
      "name": "Plant_Leaves_Bottle"
    },
    {
      "x": -6,
      "y": 26,
      "z": -3,
      "name": "Plant_Leaves_Bottle"
    },
    {
      "x": -6,
      "y": 27,
      "z": -3,
      "name": "Plant_Leaves_Bottle"
    },
    {
      "x": -6,
      "y": 24,
      "z": -2,
      "name": "Plant_Leaves_Bottle"
    },
    {
      "x": -6,
      "y": 26,
      "z": -2,
      "name": "Plant_Leaves_Bottle"
    },
    {
      "x": -6,
      "y": 23,
      "z": -1,
      "name": "Plant_Leaves_Bottle"
    },
    {
      "x": -6,
      "y": 24,
      "z": -1,
      "name": "Plant_Leaves_Bottle"
    },
    {
      "x": -6,
      "y": 26,
      "z": -1,
      "name": "Plant_Leaves_Bottle"
    },
    {
      "x": -6,
      "y": 23,
      "z": 0,
      "name": "Plant_Leaves_Bottle"
    },
    {
      "x": -6,
      "y": 18,
      "z": 2,
      "name": "Soil_Plant_Vine_Block"
    },
    {
      "x": -6,
      "y": 19,
      "z": 2,
      "name": "Soil_Plant_Vine_Block"
    },
    {
      "x": -6,
      "y": 24,
      "z": 2,
      "name": "Plant_Leaves_Bottle"
    },
    {
      "x": -6,
      "y": 19,
      "z": 3,
      "name": "Vine_Branch_Corner"
    },
    {
      "x": -6,
      "y": 20,
      "z": 3,
      "name": "Vine_Branch_Long"
    },
    {
      "x": -6,
      "y": 21,
      "z": 3,
      "name": "Vine_Branch_Long"
    },
    {
      "x": -6,
      "y": 22,
      "z": 3,
      "name": "Vine_Branch_Long"
    },
    {
      "x": -6,
      "y": 23,
      "z": 3,
      "name": "Plant_Leaves_Bottle"
    },
    {
      "x": -6,
      "y": 24,
      "z": 3,
      "name": "Plant_Leaves_Bottle"
    },
    {
      "x": -6,
      "y": 25,
      "z": 3,
      "name": "Plant_Leaves_Bottle"
    },
    {
      "x": -6,
      "y": 22,
      "z": 4,
      "name": "Plant_Leaves_Bottle"
    },
    {
      "x": -6,
      "y": 23,
      "z": 4,
      "name": "Plant_Leaves_Bottle"
    },
    {
      "x": -6,
      "y": 24,
      "z": 4,
      "name": "Plant_Leaves_Bottle"
    },
    {
      "x": -5,
      "y": 23,
      "z": -6,
      "name": "Plant_Leaves_Bottle"
    },
    {
      "x": -5,
      "y": 22,
      "z": -5,
      "name": "Plant_Leaves_Bottle"
    },
    {
      "x": -5,
      "y": 23,
      "z": -5,
      "name": "Plant_Leaves_Bottle"
    },
    {
      "x": -5,
      "y": 24,
      "z": -5,
      "name": "Plant_Leaves_Bottle"
    },
    {
      "x": -5,
      "y": 25,
      "z": -5,
      "name": "Plant_Leaves_Bottle"
    },
    {
      "x": -5,
      "y": 26,
      "z": -5,
      "name": "Plant_Leaves_Bottle"
    },
    {
      "x": -5,
      "y": 26,
      "z": -4,
      "name": "Plant_Leaves_Bottle"
    },
    {
      "x": -5,
      "y": 26,
      "z": -3,
      "name": "Plant_Leaves_Bottle"
    },
    {
      "x": -5,
      "y": 27,
      "z": -3,
      "name": "Plant_Leaves_Bottle"
    },
    {
      "x": -5,
      "y": 26,
      "z": -2,
      "name": "Plant_Leaves_Bottle"
    },
    {
      "x": -5,
      "y": 27,
      "z": -2,
      "name": "Plant_Leaves_Bottle"
    },
    {
      "x": -5,
      "y": 24,
      "z": -1,
      "name": "Plant_Leaves_Bottle"
    },
    {
      "x": -5,
      "y": 26,
      "z": -1,
      "name": "Plant_Leaves_Bottle"
    },
    {
      "x": -5,
      "y": 24,
      "z": 0,
      "name": "Plant_Leaves_Bottle"
    },
    {
      "x": -5,
      "y": 25,
      "z": 0,
      "name": "Plant_Leaves_Bottle"
    },
    {
      "x": -5,
      "y": 26,
      "z": 0,
      "name": "Plant_Leaves_Bottle"
    },
    {
      "x": -5,
      "y": 24,
      "z": 1,
      "name": "Plant_Leaves_Bottle"
    },
    {
      "x": -5,
      "y": 18,
      "z": 2,
      "name": "Soil_Plant_Vine_Block"
    },
    {
      "x": -5,
      "y": 22,
      "z": 3,
      "name": "Plant_Leaves_Bottle"
    },
    {
      "x": -5,
      "y": 23,
      "z": 3,
      "name": "Plant_Leaves_Bottle"
    },
    {
      "x": -5,
      "y": 24,
      "z": 3,
      "name": "Plant_Leaves_Bottle"
    },
    {
      "x": -5,
      "y": 22,
      "z": 4,
      "name": "Plant_Leaves_Bottle"
    },
    {
      "x": -5,
      "y": 23,
      "z": 4,
      "name": "Plant_Leaves_Bottle"
    },
    {
      "x": -5,
      "y": 24,
      "z": 4,
      "name": "Plant_Leaves_Bottle"
    },
    {
      "x": -5,
      "y": 23,
      "z": 5,
      "name": "Plant_Leaves_Bottle"
    },
    {
      "x": -4,
      "y": 24,
      "z": -6,
      "name": "Plant_Leaves_Bottle"
    },
    {
      "x": -4,
      "y": 25,
      "z": -6,
      "name": "Plant_Leaves_Bottle"
    },
    {
      "x": -4,
      "y": 22,
      "z": -5,
      "name": "Plant_Leaves_Bottle"
    },
    {
      "x": -4,
      "y": 23,
      "z": -5,
      "name": "Plant_Leaves_Bottle"
    },
    {
      "x": -4,
      "y": 24,
      "z": -5,
      "name": "Plant_Leaves_Bottle"
    },
    {
      "x": -4,
      "y": 25,
      "z": -5,
      "name": "Plant_Leaves_Bottle"
    },
    {
      "x": -4,
      "y": 26,
      "z": -5,
      "name": "Plant_Leaves_Bottle"
    },
    {
      "x": -4,
      "y": 25,
      "z": -4,
      "name": "Vine_Branch_Corner",
      "rotation": 2
    },
    {
      "x": -4,
      "y": 26,
      "z": -4,
      "name": "Plant_Leaves_Bottle"
    },
    {
      "x": -4,
      "y": 27,
      "z": -4,
      "name": "Plant_Leaves_Bottle"
    },
    {
      "x": -4,
      "y": 23,
      "z": -3,
      "name": "Soil_Plant_Vine_Block"
    },
    {
      "x": -4,
      "y": 24,
      "z": -3,
      "name": "Soil_Plant_Vine_Block"
    },
    {
      "x": -4,
      "y": 25,
      "z": -3,
      "name": "Soil_Plant_Vine_Block"
    },
    {
      "x": -4,
      "y": 26,
      "z": -3,
      "name": "Vine_Branch_Long"
    },
    {
      "x": -4,
      "y": 27,
      "z": -3,
      "name": "Plant_Leaves_Bottle"
    },
    {
      "x": -4,
      "y": 22,
      "z": -2,
      "name": "Soil_Plant_Vine_Block"
    },
    {
      "x": -4,
      "y": 23,
      "z": -2,
      "name": "Soil_Plant_Vine_Block"
    },
    {
      "x": -4,
      "y": 27,
      "z": -2,
      "name": "Plant_Leaves_Bottle"
    },
    {
      "x": -4,
      "y": 22,
      "z": -1,
      "name": "Soil_Plant_Vine_Block"
    },
    {
      "x": -4,
      "y": 25,
      "z": -1,
      "name": "Plant_Leaves_Bottle"
    },
    {
      "x": -4,
      "y": 26,
      "z": -1,
      "name": "Plant_Leaves_Bottle"
    },
    {
      "x": -4,
      "y": 27,
      "z": -1,
      "name": "Plant_Leaves_Bottle"
    },
    {
      "x": -4,
      "y": 25,
      "z": 0,
      "name": "Plant_Leaves_Bottle"
    },
    {
      "x": -4,
      "y": 17,
      "z": 2,
      "name": "Soil_Plant_Vine_Block"
    },
    {
      "x": -4,
      "y": 18,
      "z": 2,
      "name": "Soil_Plant_Vine_Block"
    },
    {
      "x": -4,
      "y": 21,
      "z": 3,
      "name": "Plant_Leaves_Bottle"
    },
    {
      "x": -4,
      "y": 22,
      "z": 3,
      "name": "Plant_Leaves_Bottle"
    },
    {
      "x": -4,
      "y": 23,
      "z": 3,
      "name": "Plant_Leaves_Bottle"
    },
    {
      "x": -4,
      "y": 22,
      "z": 4,
      "name": "Plant_Leaves_Bottle"
    },
    {
      "x": -4,
      "y": 23,
      "z": 4,
      "name": "Plant_Leaves_Bottle"
    },
    {
      "x": -4,
      "y": 24,
      "z": 4,
      "name": "Plant_Leaves_Bottle"
    },
    {
      "x": -4,
      "y": 22,
      "z": 5,
      "name": "Plant_Leaves_Bottle"
    },
    {
      "x": -4,
      "y": 23,
      "z": 5,
      "name": "Plant_Leaves_Bottle"
    },
    {
      "x": -3,
      "y": 24,
      "z": -6,
      "name": "Plant_Leaves_Bottle"
    },
    {
      "x": -3,
      "y": 24,
      "z": -5,
      "name": "Plant_Leaves_Bottle"
    },
    {
      "x": -3,
      "y": 25,
      "z": -5,
      "name": "Plant_Leaves_Bottle"
    },
    {
      "x": -3,
      "y": 26,
      "z": -4,
      "name": "Plant_Leaves_Bottle"
    },
    {
      "x": -3,
      "y": 25,
      "z": -3,
      "name": "Vine_Branch_Long",
      "rotation": 5
    },
    {
      "x": -3,
      "y": 26,
      "z": -3,
      "name": "Plant_Leaves_Bottle"
    },
    {
      "x": -3,
      "y": 27,
      "z": -3,
      "name": "Plant_Leaves_Bottle"
    },
    {
      "x": -3,
      "y": 27,
      "z": -2,
      "name": "Plant_Leaves_Bottle"
    },
    {
      "x": -3,
      "y": 22,
      "z": -1,
      "name": "Soil_Plant_Vine_Block"
    },
    {
      "x": -3,
      "y": 23,
      "z": -1,
      "name": "Vine_Branch_Long"
    },
    {
      "x": -3,
      "y": 24,
      "z": -1,
      "name": "Vine_Branch_Long"
    },
    {
      "x": -3,
      "y": 25,
      "z": -1,
      "name": "Vine_Branch_Long"
    },
    {
      "x": -3,
      "y": 26,
      "z": -1,
      "name": "Plant_Leaves_Bottle"
    },
    {
      "x": -3,
      "y": 21,
      "z": 0,
      "name": "Soil_Plant_Vine_Block"
    },
    {
      "x": -3,
      "y": 22,
      "z": 0,
      "name": "Soil_Plant_Vine_Block"
    },
    {
      "x": -3,
      "y": 25,
      "z": 0,
      "name": "Plant_Leaves_Bottle"
    },
    {
      "x": -3,
      "y": 26,
      "z": 0,
      "name": "Plant_Leaves_Bottle"
    },
    {
      "x": -3,
      "y": 14,
      "z": 2,
      "name": "Soil_Plant_Vine_Block"
    },
    {
      "x": -3,
      "y": 15,
      "z": 2,
      "name": "Soil_Plant_Vine_Block"
    },
    {
      "x": -3,
      "y": 16,
      "z": 2,
      "name": "Soil_Plant_Vine_Block"
    },
    {
      "x": -3,
      "y": 17,
      "z": 2,
      "name": "Soil_Plant_Vine_Block"
    },
    {
      "x": -3,
      "y": 17,
      "z": 3,
      "name": "Vine_Branch_Corner"
    },
    {
      "x": -3,
      "y": 18,
      "z": 3,
      "name": "Vine_Branch_Long"
    },
    {
      "x": -3,
      "y": 19,
      "z": 3,
      "name": "Vine_Branch_Long"
    },
    {
      "x": -3,
      "y": 20,
      "z": 3,
      "name": "Vine_Branch_Long"
    },
    {
      "x": -3,
      "y": 21,
      "z": 3,
      "name": "Plant_Leaves_Bottle"
    },
    {
      "x": -3,
      "y": 22,
      "z": 3,
      "name": "Plant_Leaves_Bottle"
    },
    {
      "x": -3,
      "y": 23,
      "z": 3,
      "name": "Plant_Leaves_Bottle"
    },
    {
      "x": -3,
      "y": 20,
      "z": 4,
      "name": "Plant_Leaves_Bottle"
    },
    {
      "x": -3,
      "y": 21,
      "z": 4,
      "name": "Plant_Leaves_Bottle"
    },
    {
      "x": -3,
      "y": 22,
      "z": 4,
      "name": "Plant_Leaves_Bottle"
    },
    {
      "x": -3,
      "y": 21,
      "z": 5,
      "name": "Plant_Leaves_Bottle"
    },
    {
      "x": -2,
      "y": 23,
      "z": -6,
      "name": "Plant_Leaves_Bottle"
    },
    {
      "x": -2,
      "y": 24,
      "z": -5,
      "name": "Plant_Leaves_Bottle"
    },
    {
      "x": -2,
      "y": 25,
      "z": -5,
      "name": "Plant_Leaves_Bottle"
    },
    {
      "x": -2,
      "y": 25,
      "z": -4,
      "name": "Plant_Leaves_Bottle"
    },
    {
      "x": -2,
      "y": 26,
      "z": -4,
      "name": "Plant_Leaves_Bottle"
    },
    {
      "x": -2,
      "y": 25,
      "z": -3,
      "name": "Vine_Branch_Long",
      "rotation": 5
    },
    {
      "x": -2,
      "y": 26,
      "z": -3,
      "name": "Plant_Leaves_Bottle"
    },
    {
      "x": -2,
      "y": 25,
      "z": -2,
      "name": "Plant_Leaves_Bottle"
    },
    {
      "x": -2,
      "y": 25,
      "z": -1,
      "name": "Plant_Leaves_Bottle"
    },
    {
      "x": -2,
      "y": 26,
      "z": -1,
      "name": "Plant_Leaves_Bottle"
    },
    {
      "x": -2,
      "y": 18,
      "z": 0,
      "name": "Soil_Plant_Vine_Block"
    },
    {
      "x": -2,
      "y": 19,
      "z": 0,
      "name": "Soil_Plant_Vine_Block"
    },
    {
      "x": -2,
      "y": 20,
      "z": 0,
      "name": "Soil_Plant_Vine_Block"
    },
    {
      "x": -2,
      "y": 21,
      "z": 0,
      "name": "Soil_Plant_Vine_Block"
    },
    {
      "x": -2,
      "y": 25,
      "z": 0,
      "name": "Plant_Leaves_Bottle"
    },
    {
      "x": -2,
      "y": 10,
      "z": 2,
      "name": "Soil_Plant_Vine_Block"
    },
    {
      "x": -2,
      "y": 11,
      "z": 2,
      "name": "Soil_Plant_Vine_Block"
    },
    {
      "x": -2,
      "y": 12,
      "z": 2,
      "name": "Soil_Plant_Vine_Block"
    },
    {
      "x": -2,
      "y": 13,
      "z": 2,
      "name": "Soil_Plant_Vine_Block"
    },
    {
      "x": -2,
      "y": 14,
      "z": 2,
      "name": "Soil_Plant_Vine_Block"
    },
    {
      "x": -2,
      "y": 20,
      "z": 3,
      "name": "Plant_Leaves_Bottle"
    },
    {
      "x": -2,
      "y": 21,
      "z": 3,
      "name": "Plant_Leaves_Bottle"
    },
    {
      "x": -2,
      "y": 22,
      "z": 3,
      "name": "Plant_Leaves_Bottle"
    },
    {
      "x": -2,
      "y": 20,
      "z": 4,
      "name": "Plant_Leaves_Bottle"
    },
    {
      "x": -2,
      "y": 21,
      "z": 4,
      "name": "Plant_Leaves_Bottle"
    },
    {
      "x": -2,
      "y": 22,
      "z": 4,
      "name": "Plant_Leaves_Bottle"
    },
    {
      "x": -1,
      "y": 22,
      "z": -6,
      "name": "Plant_Leaves_Bottle"
    },
    {
      "x": -1,
      "y": 23,
      "z": -6,
      "name": "Plant_Leaves_Bottle"
    },
    {
      "x": -1,
      "y": 24,
      "z": -6,
      "name": "Plant_Leaves_Bottle"
    },
    {
      "x": -1,
      "y": 25,
      "z": -6,
      "name": "Plant_Leaves_Bottle"
    },
    {
      "x": -1,
      "y": 24,
      "z": -5,
      "name": "Plant_Leaves_Bottle"
    },
    {
      "x": -1,
      "y": 25,
      "z": -5,
      "name": "Plant_Leaves_Bottle"
    },
    {
      "x": -1,
      "y": 24,
      "z": -4,
      "name": "Plant_Leaves_Bottle"
    },
    {
      "x": -1,
      "y": 25,
      "z": -4,
      "name": "Plant_Leaves_Bottle"
    },
    {
      "x": -1,
      "y": 25,
      "z": -3,
      "name": "Plant_Leaves_Bottle"
    },
    {
      "x": -1,
      "y": 25,
      "z": -2,
      "name": "Plant_Leaves_Bottle"
    },
    {
      "x": -1,
      "y": 18,
      "z": 0,
      "name": "Soil_Plant_Vine_Block"
    },
    {
      "x": -1,
      "y": 0,
      "z": 1,
      "name": "Soil_Plant_Vine_Block"
    },
    {
      "x": -1,
      "y": 1,
      "z": 1,
      "name": "Soil_Plant_Vine_Block"
    },
    {
      "x": -1,
      "y": 2,
      "z": 1,
      "name": "Soil_Plant_Vine_Block"
    },
    {
      "x": -1,
      "y": 3,
      "z": 1,
      "name": "Soil_Plant_Vine_Block"
    },
    {
      "x": -1,
      "y": 4,
      "z": 1,
      "name": "Soil_Plant_Vine_Block"
    },
    {
      "x": -1,
      "y": 5,
      "z": 1,
      "name": "Soil_Plant_Vine_Block"
    },
    {
      "x": -1,
      "y": 6,
      "z": 1,
      "name": "Soil_Plant_Vine_Block"
    },
    {
      "x": -1,
      "y": 15,
      "z": 1,
      "name": "Soil_Plant_Vine_Block"
    },
    {
      "x": -1,
      "y": 16,
      "z": 1,
      "name": "Soil_Plant_Vine_Block"
    },
    {
      "x": -1,
      "y": 17,
      "z": 1,
      "name": "Soil_Plant_Vine_Block"
    },
    {
      "x": -1,
      "y": 18,
      "z": 1,
      "name": "Soil_Plant_Vine_Block"
    },
    {
      "x": -1,
      "y": 0,
      "z": 2,
      "name": "Soil_Plant_Vine_Block"
    },
    {
      "x": -1,
      "y": 1,
      "z": 2,
      "name": "Soil_Plant_Vine_Block"
    },
    {
      "x": -1,
      "y": 2,
      "z": 2,
      "name": "Soil_Plant_Vine_Block"
    },
    {
      "x": -1,
      "y": 3,
      "z": 2,
      "name": "Soil_Plant_Vine_Block"
    },
    {
      "x": -1,
      "y": 4,
      "z": 2,
      "name": "Soil_Plant_Vine_Block"
    },
    {
      "x": -1,
      "y": 5,
      "z": 2,
      "name": "Soil_Plant_Vine_Block"
    },
    {
      "x": -1,
      "y": 6,
      "z": 2,
      "name": "Soil_Plant_Vine_Block"
    },
    {
      "x": -1,
      "y": 7,
      "z": 2,
      "name": "Soil_Plant_Vine_Block"
    },
    {
      "x": -1,
      "y": 8,
      "z": 2,
      "name": "Soil_Plant_Vine_Block"
    },
    {
      "x": -1,
      "y": 9,
      "z": 2,
      "name": "Soil_Plant_Vine_Block"
    },
    {
      "x": -1,
      "y": 10,
      "z": 2,
      "name": "Soil_Plant_Vine_Block"
    },
    {
      "x": 0,
      "y": 22,
      "z": -7,
      "name": "Plant_Leaves_Bottle"
    },
    {
      "x": 0,
      "y": 23,
      "z": -7,
      "name": "Plant_Leaves_Bottle"
    },
    {
      "x": 0,
      "y": 24,
      "z": -7,
      "name": "Plant_Leaves_Bottle"
    },
    {
      "x": 0,
      "y": 24,
      "z": -6,
      "name": "Plant_Leaves_Bottle"
    },
    {
      "x": 0,
      "y": 25,
      "z": -6,
      "name": "Plant_Leaves_Bottle"
    },
    {
      "x": 0,
      "y": 24,
      "z": -5,
      "name": "Plant_Leaves_Bottle"
    },
    {
      "x": 0,
      "y": 26,
      "z": -5,
      "name": "Plant_Leaves_Bottle"
    },
    {
      "x": 0,
      "y": 25,
      "z": -4,
      "name": "Plant_Leaves_Bottle"
    },
    {
      "x": 0,
      "y": 26,
      "z": -4,
      "name": "Plant_Leaves_Bottle"
    },
    {
      "x": 0,
      "y": 25,
      "z": -3,
      "name": "Plant_Leaves_Bottle"
    },
    {
      "x": 0,
      "y": 25,
      "z": -2,
      "name": "Plant_Leaves_Bottle"
    },
    {
      "x": 0,
      "y": 27,
      "z": -2,
      "name": "Plant_Leaves_Bottle"
    },
    {
      "x": 0,
      "y": 25,
      "z": -1,
      "name": "Plant_Leaves_Bottle"
    },
    {
      "x": 0,
      "y": 27,
      "z": -1,
      "name": "Plant_Leaves_Bottle"
    },
    {
      "x": 0,
      "y": 26,
      "z": 0,
      "name": "Plant_Leaves_Bottle"
    },
    {
      "x": 0,
      "y": 27,
      "z": 0,
      "name": "Plant_Leaves_Bottle"
    },
    {
      "x": 0,
      "y": 0,
      "z": 1,
      "name": "Soil_Plant_Vine_Block"
    },
    {
      "x": 0,
      "y": 1,
      "z": 1,
      "name": "Soil_Plant_Vine_Block"
    },
    {
      "x": 0,
      "y": 2,
      "z": 1,
      "name": "Soil_Plant_Vine_Block"
    },
    {
      "x": 0,
      "y": 3,
      "z": 1,
      "name": "Soil_Plant_Vine_Block"
    },
    {
      "x": 0,
      "y": 4,
      "z": 1,
      "name": "Soil_Plant_Vine_Block"
    },
    {
      "x": 0,
      "y": 5,
      "z": 1,
      "name": "Soil_Plant_Vine_Block"
    },
    {
      "x": 0,
      "y": 6,
      "z": 1,
      "name": "Soil_Plant_Vine_Block"
    },
    {
      "x": 0,
      "y": 7,
      "z": 1,
      "name": "Soil_Plant_Vine_Block"
    },
    {
      "x": 0,
      "y": 8,
      "z": 1,
      "name": "Soil_Plant_Vine_Block"
    },
    {
      "x": 0,
      "y": 9,
      "z": 1,
      "name": "Soil_Plant_Vine_Block"
    },
    {
      "x": 0,
      "y": 10,
      "z": 1,
      "name": "Soil_Plant_Vine_Block"
    },
    {
      "x": 0,
      "y": 11,
      "z": 1,
      "name": "Soil_Plant_Vine_Block"
    },
    {
      "x": 0,
      "y": 12,
      "z": 1,
      "name": "Soil_Plant_Vine_Block"
    },
    {
      "x": 0,
      "y": 13,
      "z": 1,
      "name": "Soil_Plant_Vine_Block"
    },
    {
      "x": 0,
      "y": 14,
      "z": 1,
      "name": "Soil_Plant_Vine_Block"
    },
    {
      "x": 0,
      "y": 15,
      "z": 1,
      "name": "Soil_Plant_Vine_Block"
    },
    {
      "x": 0,
      "y": 25,
      "z": 1,
      "name": "Plant_Leaves_Bottle"
    },
    {
      "x": 0,
      "y": 26,
      "z": 1,
      "name": "Plant_Leaves_Bottle"
    },
    {
      "x": 0,
      "y": 27,
      "z": 1,
      "name": "Plant_Leaves_Bottle"
    },
    {
      "x": 0,
      "y": 0,
      "z": 2,
      "name": "Soil_Plant_Vine_Block"
    },
    {
      "x": 0,
      "y": 1,
      "z": 2,
      "name": "Soil_Plant_Vine_Block"
    },
    {
      "x": 0,
      "y": 2,
      "z": 2,
      "name": "Soil_Plant_Vine_Block"
    },
    {
      "x": 0,
      "y": 3,
      "z": 2,
      "name": "Soil_Plant_Vine_Block"
    },
    {
      "x": 0,
      "y": 4,
      "z": 2,
      "name": "Soil_Plant_Vine_Block"
    },
    {
      "x": 0,
      "y": 5,
      "z": 2,
      "name": "Soil_Plant_Vine_Block"
    },
    {
      "x": 0,
      "y": 6,
      "z": 2,
      "name": "Soil_Plant_Vine_Block"
    },
    {
      "x": 0,
      "y": 7,
      "z": 2,
      "name": "Soil_Plant_Vine_Block"
    },
    {
      "x": 0,
      "y": 8,
      "z": 2,
      "name": "Soil_Plant_Vine_Block"
    },
    {
      "x": 0,
      "y": 9,
      "z": 2,
      "name": "Soil_Plant_Vine_Block"
    },
    {
      "x": 0,
      "y": 25,
      "z": 2,
      "name": "Plant_Leaves_Bottle"
    },
    {
      "x": 0,
      "y": 8,
      "z": 3,
      "name": "Soil_Plant_Vine_Block"
    },
    {
      "x": 0,
      "y": 9,
      "z": 3,
      "name": "Soil_Plant_Vine_Block"
    },
    {
      "x": 0,
      "y": 10,
      "z": 3,
      "name": "Soil_Plant_Vine_Block"
    },
    {
      "x": 0,
      "y": 11,
      "z": 3,
      "name": "Soil_Plant_Vine_Block"
    },
    {
      "x": 0,
      "y": 12,
      "z": 3,
      "name": "Soil_Plant_Vine_Block"
    },
    {
      "x": 0,
      "y": 13,
      "z": 3,
      "name": "Soil_Plant_Vine_Block"
    },
    {
      "x": 0,
      "y": 13,
      "z": 4,
      "name": "Soil_Plant_Vine_Block"
    },
    {
      "x": 0,
      "y": 14,
      "z": 4,
      "name": "Soil_Plant_Vine_Block"
    },
    {
      "x": 0,
      "y": 15,
      "z": 4,
      "name": "Soil_Plant_Vine_Block"
    },
    {
      "x": 0,
      "y": 16,
      "z": 4,
      "name": "Soil_Plant_Vine_Block"
    },
    {
      "x": 1,
      "y": 22,
      "z": -7,
      "name": "Plant_Leaves_Bottle"
    },
    {
      "x": 1,
      "y": 23,
      "z": -7,
      "name": "Plant_Leaves_Bottle"
    },
    {
      "x": 1,
      "y": 24,
      "z": -7,
      "name": "Plant_Leaves_Bottle"
    },
    {
      "x": 1,
      "y": 25,
      "z": -7,
      "name": "Plant_Leaves_Bottle"
    },
    {
      "x": 1,
      "y": 24,
      "z": -6,
      "name": "Plant_Leaves_Bottle"
    },
    {
      "x": 1,
      "y": 25,
      "z": -6,
      "name": "Plant_Leaves_Bottle"
    },
    {
      "x": 1,
      "y": 26,
      "z": -6,
      "name": "Plant_Leaves_Bottle"
    },
    {
      "x": 1,
      "y": 22,
      "z": -5,
      "name": "Soil_Plant_Vine_Block"
    },
    {
      "x": 1,
      "y": 23,
      "z": -5,
      "name": "Soil_Plant_Vine_Block"
    },
    {
      "x": 1,
      "y": 24,
      "z": -5,
      "name": "Vine_Branch_Long"
    },
    {
      "x": 1,
      "y": 25,
      "z": -5,
      "name": "Plant_Leaves_Bottle"
    },
    {
      "x": 1,
      "y": 26,
      "z": -5,
      "name": "Plant_Leaves_Bottle"
    },
    {
      "x": 1,
      "y": 22,
      "z": -4,
      "name": "Soil_Plant_Vine_Block"
    },
    {
      "x": 1,
      "y": 25,
      "z": -4,
      "name": "Plant_Leaves_Bottle"
    },
    {
      "x": 1,
      "y": 26,
      "z": -4,
      "name": "Plant_Leaves_Bottle"
    },
    {
      "x": 1,
      "y": 21,
      "z": -3,
      "name": "Soil_Plant_Vine_Block"
    },
    {
      "x": 1,
      "y": 22,
      "z": -3,
      "name": "Soil_Plant_Vine_Block"
    },
    {
      "x": 1,
      "y": 23,
      "z": -3,
      "name": "Vine_Branch_Long"
    },
    {
      "x": 1,
      "y": 24,
      "z": -3,
      "name": "Vine_Branch_Long"
    },
    {
      "x": 1,
      "y": 25,
      "z": -3,
      "name": "Plant_Leaves_Bottle"
    },
    {
      "x": 1,
      "y": 26,
      "z": -3,
      "name": "Plant_Leaves_Bottle"
    },
    {
      "x": 1,
      "y": 19,
      "z": -2,
      "name": "Soil_Plant_Vine_Block"
    },
    {
      "x": 1,
      "y": 20,
      "z": -2,
      "name": "Soil_Plant_Vine_Block"
    },
    {
      "x": 1,
      "y": 21,
      "z": -2,
      "name": "Soil_Plant_Vine_Block"
    },
    {
      "x": 1,
      "y": 26,
      "z": -2,
      "name": "Plant_Leaves_Bottle"
    },
    {
      "x": 1,
      "y": 27,
      "z": -2,
      "name": "Plant_Leaves_Bottle"
    },
    {
      "x": 1,
      "y": 16,
      "z": -1,
      "name": "Soil_Plant_Vine_Block"
    },
    {
      "x": 1,
      "y": 17,
      "z": -1,
      "name": "Soil_Plant_Vine_Block"
    },
    {
      "x": 1,
      "y": 18,
      "z": -1,
      "name": "Soil_Plant_Vine_Block"
    },
    {
      "x": 1,
      "y": 19,
      "z": -1,
      "name": "Soil_Plant_Vine_Block"
    },
    {
      "x": 1,
      "y": 28,
      "z": -1,
      "name": "Plant_Leaves_Bottle"
    },
    {
      "x": 1,
      "y": 13,
      "z": 0,
      "name": "Soil_Plant_Vine_Block"
    },
    {
      "x": 1,
      "y": 14,
      "z": 0,
      "name": "Soil_Plant_Vine_Block"
    },
    {
      "x": 1,
      "y": 15,
      "z": 0,
      "name": "Soil_Plant_Vine_Block"
    },
    {
      "x": 1,
      "y": 16,
      "z": 0,
      "name": "Soil_Plant_Vine_Block"
    },
    {
      "x": 1,
      "y": 28,
      "z": 0,
      "name": "Plant_Leaves_Bottle"
    },
    {
      "x": 1,
      "y": 10,
      "z": 1,
      "name": "Soil_Plant_Vine_Block"
    },
    {
      "x": 1,
      "y": 11,
      "z": 1,
      "name": "Soil_Plant_Vine_Block"
    },
    {
      "x": 1,
      "y": 12,
      "z": 1,
      "name": "Soil_Plant_Vine_Block"
    },
    {
      "x": 1,
      "y": 13,
      "z": 1,
      "name": "Soil_Plant_Vine_Block"
    },
    {
      "x": 1,
      "y": 27,
      "z": 1,
      "name": "Plant_Leaves_Bottle"
    },
    {
      "x": 1,
      "y": 28,
      "z": 1,
      "name": "Plant_Leaves_Bottle"
    },
    {
      "x": 1,
      "y": 27,
      "z": 2,
      "name": "Plant_Leaves_Bottle"
    },
    {
      "x": 1,
      "y": 21,
      "z": 3,
      "name": "Plant_Leaves_Bottle"
    },
    {
      "x": 1,
      "y": 25,
      "z": 3,
      "name": "Plant_Leaves_Bottle"
    },
    {
      "x": 1,
      "y": 26,
      "z": 3,
      "name": "Plant_Leaves_Bottle"
    },
    {
      "x": 1,
      "y": 27,
      "z": 3,
      "name": "Plant_Leaves_Bottle"
    },
    {
      "x": 1,
      "y": 16,
      "z": 4,
      "name": "Soil_Plant_Vine_Block"
    },
    {
      "x": 1,
      "y": 17,
      "z": 4,
      "name": "Soil_Plant_Vine_Block"
    },
    {
      "x": 1,
      "y": 18,
      "z": 4,
      "name": "Soil_Plant_Vine_Block"
    },
    {
      "x": 1,
      "y": 20,
      "z": 4,
      "name": "Plant_Leaves_Bottle"
    },
    {
      "x": 1,
      "y": 21,
      "z": 4,
      "name": "Plant_Leaves_Bottle"
    },
    {
      "x": 1,
      "y": 22,
      "z": 4,
      "name": "Plant_Leaves_Bottle"
    },
    {
      "x": 1,
      "y": 20,
      "z": 5,
      "name": "Plant_Leaves_Bottle"
    },
    {
      "x": 1,
      "y": 21,
      "z": 5,
      "name": "Plant_Leaves_Bottle"
    },
    {
      "x": 1,
      "y": 22,
      "z": 5,
      "name": "Plant_Leaves_Bottle"
    },
    {
      "x": 2,
      "y": 23,
      "z": -7,
      "name": "Plant_Leaves_Bottle"
    },
    {
      "x": 2,
      "y": 24,
      "z": -7,
      "name": "Plant_Leaves_Bottle"
    },
    {
      "x": 2,
      "y": 25,
      "z": -7,
      "name": "Plant_Leaves_Bottle"
    },
    {
      "x": 2,
      "y": 24,
      "z": -6,
      "name": "Plant_Leaves_Bottle"
    },
    {
      "x": 2,
      "y": 25,
      "z": -6,
      "name": "Plant_Leaves_Bottle"
    },
    {
      "x": 2,
      "y": 25,
      "z": -5,
      "name": "Plant_Leaves_Bottle"
    },
    {
      "x": 2,
      "y": 26,
      "z": -5,
      "name": "Plant_Leaves_Bottle"
    },
    {
      "x": 2,
      "y": 25,
      "z": -4,
      "name": "Plant_Leaves_Bottle"
    },
    {
      "x": 2,
      "y": 24,
      "z": -3,
      "name": "Plant_Leaves_Bottle"
    },
    {
      "x": 2,
      "y": 25,
      "z": -3,
      "name": "Plant_Leaves_Bottle"
    },
    {
      "x": 2,
      "y": 26,
      "z": -3,
      "name": "Plant_Leaves_Bottle"
    },
    {
      "x": 2,
      "y": 27,
      "z": -3,
      "name": "Plant_Leaves_Bottle"
    },
    {
      "x": 2,
      "y": 25,
      "z": -2,
      "name": "Plant_Leaves_Bottle"
    },
    {
      "x": 2,
      "y": 28,
      "z": -2,
      "name": "Plant_Leaves_Bottle"
    },
    {
      "x": 2,
      "y": 19,
      "z": -1,
      "name": "Soil_Plant_Vine_Block"
    },
    {
      "x": 2,
      "y": 20,
      "z": -1,
      "name": "Soil_Plant_Vine_Block"
    },
    {
      "x": 2,
      "y": 21,
      "z": -1,
      "name": "Soil_Plant_Vine_Block"
    },
    {
      "x": 2,
      "y": 28,
      "z": -1,
      "name": "Plant_Leaves_Bottle"
    },
    {
      "x": 2,
      "y": 16,
      "z": 0,
      "name": "Plant_Leaves_Bottle"
    },
    {
      "x": 2,
      "y": 28,
      "z": 0,
      "name": "Plant_Leaves_Bottle"
    },
    {
      "x": 2,
      "y": 29,
      "z": 0,
      "name": "Plant_Leaves_Bottle"
    },
    {
      "x": 2,
      "y": 12,
      "z": 1,
      "name": "Soil_Plant_Vine_Block"
    },
    {
      "x": 2,
      "y": 13,
      "z": 1,
      "name": "Soil_Plant_Vine_Block"
    },
    {
      "x": 2,
      "y": 16,
      "z": 1,
      "name": "Plant_Leaves_Bottle"
    },
    {
      "x": 2,
      "y": 17,
      "z": 1,
      "name": "Plant_Leaves_Bottle"
    },
    {
      "x": 2,
      "y": 28,
      "z": 1,
      "name": "Plant_Leaves_Bottle"
    },
    {
      "x": 2,
      "y": 29,
      "z": 1,
      "name": "Plant_Leaves_Bottle"
    },
    {
      "x": 2,
      "y": 21,
      "z": 3,
      "name": "Plant_Leaves_Bottle"
    },
    {
      "x": 2,
      "y": 22,
      "z": 3,
      "name": "Plant_Leaves_Bottle"
    },
    {
      "x": 2,
      "y": 26,
      "z": 3,
      "name": "Plant_Leaves_Bottle"
    },
    {
      "x": 2,
      "y": 27,
      "z": 3,
      "name": "Plant_Leaves_Bottle"
    },
    {
      "x": 2,
      "y": 18,
      "z": 4,
      "name": "Soil_Plant_Vine_Block"
    },
    {
      "x": 2,
      "y": 19,
      "z": 4,
      "name": "Soil_Plant_Vine_Block"
    },
    {
      "x": 2,
      "y": 20,
      "z": 4,
      "name": "Vine_Branch_Long"
    },
    {
      "x": 2,
      "y": 21,
      "z": 4,
      "name": "Vine_Branch_Long"
    },
    {
      "x": 2,
      "y": 22,
      "z": 4,
      "name": "Plant_Leaves_Bottle"
    },
    {
      "x": 2,
      "y": 23,
      "z": 4,
      "name": "Plant_Leaves_Bottle"
    },
    {
      "x": 2,
      "y": 19,
      "z": 5,
      "name": "Soil_Plant_Vine_Block"
    },
    {
      "x": 2,
      "y": 22,
      "z": 5,
      "name": "Plant_Leaves_Bottle"
    },
    {
      "x": 2,
      "y": 23,
      "z": 5,
      "name": "Plant_Leaves_Bottle"
    },
    {
      "x": 2,
      "y": 21,
      "z": 6,
      "name": "Plant_Leaves_Bottle"
    },
    {
      "x": 2,
      "y": 22,
      "z": 6,
      "name": "Plant_Leaves_Bottle"
    },
    {
      "x": 3,
      "y": 23,
      "z": -7,
      "name": "Plant_Leaves_Bottle"
    },
    {
      "x": 3,
      "y": 24,
      "z": -7,
      "name": "Plant_Leaves_Bottle"
    },
    {
      "x": 3,
      "y": 22,
      "z": -6,
      "name": "Plant_Leaves_Bottle"
    },
    {
      "x": 3,
      "y": 23,
      "z": -6,
      "name": "Plant_Leaves_Bottle"
    },
    {
      "x": 3,
      "y": 24,
      "z": -6,
      "name": "Plant_Leaves_Bottle"
    },
    {
      "x": 3,
      "y": 25,
      "z": -6,
      "name": "Plant_Leaves_Bottle"
    },
    {
      "x": 3,
      "y": 23,
      "z": -5,
      "name": "Plant_Leaves_Bottle"
    },
    {
      "x": 3,
      "y": 24,
      "z": -5,
      "name": "Plant_Leaves_Bottle"
    },
    {
      "x": 3,
      "y": 25,
      "z": -5,
      "name": "Plant_Leaves_Bottle"
    },
    {
      "x": 3,
      "y": 26,
      "z": -5,
      "name": "Plant_Leaves_Bottle"
    },
    {
      "x": 3,
      "y": 24,
      "z": -4,
      "name": "Plant_Leaves_Bottle"
    },
    {
      "x": 3,
      "y": 23,
      "z": -3,
      "name": "Plant_Leaves_Bottle"
    },
    {
      "x": 3,
      "y": 24,
      "z": -3,
      "name": "Plant_Leaves_Bottle"
    },
    {
      "x": 3,
      "y": 25,
      "z": -3,
      "name": "Plant_Leaves_Bottle"
    },
    {
      "x": 3,
      "y": 27,
      "z": -3,
      "name": "Plant_Leaves_Bottle"
    },
    {
      "x": 3,
      "y": 23,
      "z": -2,
      "name": "Plant_Leaves_Bottle"
    },
    {
      "x": 3,
      "y": 24,
      "z": -2,
      "name": "Plant_Leaves_Bottle"
    },
    {
      "x": 3,
      "y": 25,
      "z": -2,
      "name": "Plant_Leaves_Bottle"
    },
    {
      "x": 3,
      "y": 28,
      "z": -2,
      "name": "Plant_Leaves_Bottle"
    },
    {
      "x": 3,
      "y": 16,
      "z": -1,
      "name": "Plant_Leaves_Bottle"
    },
    {
      "x": 3,
      "y": 21,
      "z": -1,
      "name": "Soil_Plant_Vine_Block"
    },
    {
      "x": 3,
      "y": 28,
      "z": -1,
      "name": "Plant_Leaves_Bottle"
    },
    {
      "x": 3,
      "y": 29,
      "z": -1,
      "name": "Plant_Leaves_Bottle"
    },
    {
      "x": 3,
      "y": 17,
      "z": 0,
      "name": "Plant_Leaves_Bottle"
    },
    {
      "x": 3,
      "y": 21,
      "z": 0,
      "name": "Soil_Plant_Vine_Block"
    },
    {
      "x": 3,
      "y": 22,
      "z": 0,
      "name": "Soil_Plant_Vine_Block"
    },
    {
      "x": 3,
      "y": 23,
      "z": 0,
      "name": "Soil_Plant_Vine_Block"
    },
    {
      "x": 3,
      "y": 24,
      "z": 0,
      "name": "Soil_Plant_Vine_Block"
    },
    {
      "x": 3,
      "y": 28,
      "z": 0,
      "name": "Plant_Leaves_Bottle"
    },
    {
      "x": 3,
      "y": 29,
      "z": 0,
      "name": "Plant_Leaves_Bottle"
    },
    {
      "x": 3,
      "y": 13,
      "z": 1,
      "name": "Soil_Plant_Vine_Block"
    },
    {
      "x": 3,
      "y": 14,
      "z": 1,
      "name": "Soil_Plant_Vine_Block"
    },
    {
      "x": 3,
      "y": 17,
      "z": 1,
      "name": "Plant_Leaves_Bottle"
    },
    {
      "x": 3,
      "y": 18,
      "z": 1,
      "name": "Plant_Leaves_Bottle"
    },
    {
      "x": 3,
      "y": 24,
      "z": 1,
      "name": "Soil_Plant_Vine_Block"
    },
    {
      "x": 3,
      "y": 25,
      "z": 1,
      "name": "Soil_Plant_Vine_Block"
    },
    {
      "x": 3,
      "y": 26,
      "z": 1,
      "name": "Vine_Branch_Long"
    },
    {
      "x": 3,
      "y": 27,
      "z": 1,
      "name": "Vine_Branch_Long"
    },
    {
      "x": 3,
      "y": 28,
      "z": 1,
      "name": "Plant_Leaves_Bottle"
    },
    {
      "x": 3,
      "y": 29,
      "z": 1,
      "name": "Plant_Leaves_Bottle"
    },
    {
      "x": 3,
      "y": 28,
      "z": 2,
      "name": "Plant_Leaves_Bottle"
    },
    {
      "x": 3,
      "y": 26,
      "z": 3,
      "name": "Plant_Leaves_Bottle"
    },
    {
      "x": 3,
      "y": 27,
      "z": 3,
      "name": "Plant_Leaves_Bottle"
    },
    {
      "x": 3,
      "y": 28,
      "z": 3,
      "name": "Plant_Leaves_Bottle"
    },
    {
      "x": 3,
      "y": 23,
      "z": 4,
      "name": "Plant_Leaves_Bottle"
    },
    {
      "x": 3,
      "y": 19,
      "z": 5,
      "name": "Soil_Plant_Vine_Block"
    },
    {
      "x": 3,
      "y": 20,
      "z": 5,
      "name": "Soil_Plant_Vine_Block"
    },
    {
      "x": 3,
      "y": 23,
      "z": 5,
      "name": "Plant_Leaves_Bottle"
    },
    {
      "x": 3,
      "y": 24,
      "z": 5,
      "name": "Plant_Leaves_Bottle"
    },
    {
      "x": 3,
      "y": 20,
      "z": 6,
      "name": "Vine_Branch_Corner"
    },
    {
      "x": 3,
      "y": 21,
      "z": 6,
      "name": "Vine_Branch_Long"
    },
    {
      "x": 3,
      "y": 22,
      "z": 6,
      "name": "Plant_Leaves_Bottle"
    },
    {
      "x": 3,
      "y": 24,
      "z": 6,
      "name": "Plant_Leaves_Bottle"
    },
    {
      "x": 4,
      "y": 23,
      "z": -6,
      "name": "Plant_Leaves_Bottle"
    },
    {
      "x": 4,
      "y": 24,
      "z": -6,
      "name": "Plant_Leaves_Bottle"
    },
    {
      "x": 4,
      "y": 22,
      "z": -5,
      "name": "Plant_Leaves_Bottle"
    },
    {
      "x": 4,
      "y": 23,
      "z": -5,
      "name": "Plant_Leaves_Bottle"
    },
    {
      "x": 4,
      "y": 24,
      "z": -5,
      "name": "Plant_Leaves_Bottle"
    },
    {
      "x": 4,
      "y": 25,
      "z": -5,
      "name": "Plant_Leaves_Bottle"
    },
    {
      "x": 4,
      "y": 24,
      "z": -4,
      "name": "Plant_Leaves_Bottle"
    },
    {
      "x": 4,
      "y": 27,
      "z": -3,
      "name": "Plant_Leaves_Bottle"
    },
    {
      "x": 4,
      "y": 27,
      "z": -2,
      "name": "Plant_Leaves_Bottle"
    },
    {
      "x": 4,
      "y": 28,
      "z": -2,
      "name": "Plant_Leaves_Bottle"
    },
    {
      "x": 4,
      "y": 16,
      "z": -1,
      "name": "Plant_Leaves_Bottle"
    },
    {
      "x": 4,
      "y": 17,
      "z": -1,
      "name": "Plant_Leaves_Bottle"
    },
    {
      "x": 4,
      "y": 28,
      "z": -1,
      "name": "Plant_Leaves_Bottle"
    },
    {
      "x": 4,
      "y": 29,
      "z": -1,
      "name": "Plant_Leaves_Bottle"
    },
    {
      "x": 4,
      "y": 14,
      "z": 0,
      "name": "Vine_Branch_Corner",
      "rotation": 2
    },
    {
      "x": 4,
      "y": 15,
      "z": 0,
      "name": "Vine_Branch_Long"
    },
    {
      "x": 4,
      "y": 16,
      "z": 0,
      "name": "Vine_Branch_Long"
    },
    {
      "x": 4,
      "y": 17,
      "z": 0,
      "name": "Plant_Leaves_Bottle"
    },
    {
      "x": 4,
      "y": 18,
      "z": 0,
      "name": "Plant_Leaves_Bottle"
    },
    {
      "x": 4,
      "y": 24,
      "z": 0,
      "name": "Vine_Branch_Corner",
      "rotation": 1
    },
    {
      "x": 4,
      "y": 25,
      "z": 0,
      "name": "Vine_Branch_Long"
    },
    {
      "x": 4,
      "y": 26,
      "z": 0,
      "name": "Vine_Branch_Long"
    },
    {
      "x": 4,
      "y": 27,
      "z": 0,
      "name": "Vine_Branch_Long"
    },
    {
      "x": 4,
      "y": 28,
      "z": 0,
      "name": "Plant_Leaves_Bottle"
    },
    {
      "x": 4,
      "y": 29,
      "z": 0,
      "name": "Plant_Leaves_Bottle"
    },
    {
      "x": 4,
      "y": 14,
      "z": 1,
      "name": "Soil_Plant_Vine_Block"
    },
    {
      "x": 4,
      "y": 17,
      "z": 1,
      "name": "Plant_Leaves_Bottle"
    },
    {
      "x": 4,
      "y": 28,
      "z": 1,
      "name": "Plant_Leaves_Bottle"
    },
    {
      "x": 4,
      "y": 29,
      "z": 1,
      "name": "Plant_Leaves_Bottle"
    },
    {
      "x": 4,
      "y": 14,
      "z": 2,
      "name": "Soil_Plant_Vine_Block"
    },
    {
      "x": 4,
      "y": 17,
      "z": 2,
      "name": "Plant_Leaves_Bottle"
    },
    {
      "x": 4,
      "y": 18,
      "z": 2,
      "name": "Plant_Leaves_Bottle"
    },
    {
      "x": 4,
      "y": 27,
      "z": 2,
      "name": "Plant_Leaves_Bottle"
    },
    {
      "x": 4,
      "y": 17,
      "z": 3,
      "name": "Plant_Leaves_Bottle"
    },
    {
      "x": 4,
      "y": 22,
      "z": 3,
      "name": "Plant_Leaves_Bottle"
    },
    {
      "x": 4,
      "y": 23,
      "z": 3,
      "name": "Plant_Leaves_Bottle"
    },
    {
      "x": 4,
      "y": 27,
      "z": 3,
      "name": "Plant_Leaves_Bottle"
    },
    {
      "x": 4,
      "y": 23,
      "z": 4,
      "name": "Plant_Leaves_Bottle"
    },
    {
      "x": 4,
      "y": 24,
      "z": 4,
      "name": "Plant_Leaves_Bottle"
    },
    {
      "x": 4,
      "y": 25,
      "z": 4,
      "name": "Plant_Leaves_Bottle"
    },
    {
      "x": 4,
      "y": 20,
      "z": 5,
      "name": "Soil_Plant_Vine_Block"
    },
    {
      "x": 4,
      "y": 25,
      "z": 5,
      "name": "Plant_Leaves_Bottle"
    },
    {
      "x": 4,
      "y": 23,
      "z": 6,
      "name": "Plant_Leaves_Bottle"
    },
    {
      "x": 4,
      "y": 24,
      "z": 6,
      "name": "Plant_Leaves_Bottle"
    },
    {
      "x": 4,
      "y": 25,
      "z": 6,
      "name": "Plant_Leaves_Bottle"
    },
    {
      "x": 5,
      "y": 27,
      "z": -2,
      "name": "Plant_Leaves_Bottle"
    },
    {
      "x": 5,
      "y": 28,
      "z": -2,
      "name": "Plant_Leaves_Bottle"
    },
    {
      "x": 5,
      "y": 17,
      "z": -1,
      "name": "Plant_Leaves_Bottle"
    },
    {
      "x": 5,
      "y": 28,
      "z": -1,
      "name": "Plant_Leaves_Bottle"
    },
    {
      "x": 5,
      "y": 17,
      "z": 0,
      "name": "Plant_Leaves_Bottle"
    },
    {
      "x": 5,
      "y": 26,
      "z": 0,
      "name": "Plant_Leaves_Bottle"
    },
    {
      "x": 5,
      "y": 27,
      "z": 0,
      "name": "Plant_Leaves_Bottle"
    },
    {
      "x": 5,
      "y": 28,
      "z": 0,
      "name": "Plant_Leaves_Bottle"
    },
    {
      "x": 5,
      "y": 29,
      "z": 0,
      "name": "Plant_Leaves_Bottle"
    },
    {
      "x": 5,
      "y": 17,
      "z": 1,
      "name": "Plant_Leaves_Bottle"
    },
    {
      "x": 5,
      "y": 18,
      "z": 1,
      "name": "Plant_Leaves_Bottle"
    },
    {
      "x": 5,
      "y": 19,
      "z": 1,
      "name": "Plant_Leaves_Bottle"
    },
    {
      "x": 5,
      "y": 27,
      "z": 1,
      "name": "Plant_Leaves_Bottle"
    },
    {
      "x": 5,
      "y": 28,
      "z": 1,
      "name": "Plant_Leaves_Bottle"
    },
    {
      "x": 5,
      "y": 14,
      "z": 2,
      "name": "Soil_Plant_Vine_Block"
    },
    {
      "x": 5,
      "y": 15,
      "z": 2,
      "name": "Vine_Branch_Long"
    },
    {
      "x": 5,
      "y": 16,
      "z": 2,
      "name": "Vine_Branch_Long"
    },
    {
      "x": 5,
      "y": 17,
      "z": 2,
      "name": "Vine_Branch_Long"
    },
    {
      "x": 5,
      "y": 18,
      "z": 2,
      "name": "Plant_Leaves_Bottle"
    },
    {
      "x": 5,
      "y": 26,
      "z": 2,
      "name": "Plant_Leaves_Bottle"
    },
    {
      "x": 5,
      "y": 27,
      "z": 2,
      "name": "Plant_Leaves_Bottle"
    },
    {
      "x": 5,
      "y": 17,
      "z": 3,
      "name": "Plant_Leaves_Bottle"
    },
    {
      "x": 5,
      "y": 18,
      "z": 3,
      "name": "Plant_Leaves_Bottle"
    },
    {
      "x": 5,
      "y": 22,
      "z": 3,
      "name": "Plant_Leaves_Bottle"
    },
    {
      "x": 5,
      "y": 23,
      "z": 3,
      "name": "Plant_Leaves_Bottle"
    },
    {
      "x": 5,
      "y": 24,
      "z": 3,
      "name": "Plant_Leaves_Bottle"
    },
    {
      "x": 5,
      "y": 21,
      "z": 4,
      "name": "Vine_Branch_Corner",
      "rotation": 2
    },
    {
      "x": 5,
      "y": 22,
      "z": 4,
      "name": "Vine_Branch_Long"
    },
    {
      "x": 5,
      "y": 23,
      "z": 4,
      "name": "Vine_Branch_Long"
    },
    {
      "x": 5,
      "y": 24,
      "z": 4,
      "name": "Vine_Branch_Long"
    },
    {
      "x": 5,
      "y": 25,
      "z": 4,
      "name": "Plant_Leaves_Bottle"
    },
    {
      "x": 5,
      "y": 20,
      "z": 5,
      "name": "Soil_Plant_Vine_Block"
    },
    {
      "x": 5,
      "y": 21,
      "z": 5,
      "name": "Soil_Plant_Vine_Block"
    },
    {
      "x": 5,
      "y": 25,
      "z": 5,
      "name": "Plant_Leaves_Bottle"
    },
    {
      "x": 5,
      "y": 24,
      "z": 6,
      "name": "Plant_Leaves_Bottle"
    },
    {
      "x": 5,
      "y": 25,
      "z": 6,
      "name": "Plant_Leaves_Bottle"
    },
    {
      "x": 5,
      "y": 22,
      "z": 7,
      "name": "Plant_Leaves_Bottle"
    },
    {
      "x": 5,
      "y": 23,
      "z": 7,
      "name": "Plant_Leaves_Bottle"
    },
    {
      "x": 5,
      "y": 24,
      "z": 7,
      "name": "Plant_Leaves_Bottle"
    },
    {
      "x": 6,
      "y": 25,
      "z": -2,
      "name": "Plant_Leaves_Bottle"
    },
    {
      "x": 6,
      "y": 26,
      "z": -2,
      "name": "Plant_Leaves_Bottle"
    },
    {
      "x": 6,
      "y": 27,
      "z": -2,
      "name": "Plant_Leaves_Bottle"
    },
    {
      "x": 6,
      "y": 17,
      "z": -1,
      "name": "Plant_Leaves_Bottle"
    },
    {
      "x": 6,
      "y": 26,
      "z": -1,
      "name": "Plant_Leaves_Bottle"
    },
    {
      "x": 6,
      "y": 27,
      "z": -1,
      "name": "Plant_Leaves_Bottle"
    },
    {
      "x": 6,
      "y": 18,
      "z": 0,
      "name": "Plant_Leaves_Bottle"
    },
    {
      "x": 6,
      "y": 19,
      "z": 0,
      "name": "Plant_Leaves_Bottle"
    },
    {
      "x": 6,
      "y": 24,
      "z": 0,
      "name": "Plant_Leaves_Bottle"
    },
    {
      "x": 6,
      "y": 25,
      "z": 0,
      "name": "Plant_Leaves_Bottle"
    },
    {
      "x": 6,
      "y": 26,
      "z": 0,
      "name": "Plant_Leaves_Bottle"
    },
    {
      "x": 6,
      "y": 27,
      "z": 0,
      "name": "Plant_Leaves_Bottle"
    },
    {
      "x": 6,
      "y": 28,
      "z": 0,
      "name": "Plant_Leaves_Bottle"
    },
    {
      "x": 6,
      "y": 18,
      "z": 1,
      "name": "Plant_Leaves_Bottle"
    },
    {
      "x": 6,
      "y": 19,
      "z": 1,
      "name": "Plant_Leaves_Bottle"
    },
    {
      "x": 6,
      "y": 26,
      "z": 1,
      "name": "Plant_Leaves_Bottle"
    },
    {
      "x": 6,
      "y": 27,
      "z": 1,
      "name": "Plant_Leaves_Bottle"
    },
    {
      "x": 6,
      "y": 14,
      "z": 2,
      "name": "Soil_Plant_Vine_Block"
    },
    {
      "x": 6,
      "y": 15,
      "z": 2,
      "name": "Soil_Plant_Vine_Block"
    },
    {
      "x": 6,
      "y": 17,
      "z": 2,
      "name": "Plant_Leaves_Bottle"
    },
    {
      "x": 6,
      "y": 18,
      "z": 2,
      "name": "Plant_Leaves_Bottle"
    },
    {
      "x": 6,
      "y": 19,
      "z": 2,
      "name": "Plant_Leaves_Bottle"
    },
    {
      "x": 6,
      "y": 17,
      "z": 3,
      "name": "Plant_Leaves_Bottle"
    },
    {
      "x": 6,
      "y": 18,
      "z": 3,
      "name": "Plant_Leaves_Bottle"
    },
    {
      "x": 6,
      "y": 19,
      "z": 3,
      "name": "Plant_Leaves_Bottle"
    },
    {
      "x": 6,
      "y": 22,
      "z": 3,
      "name": "Plant_Leaves_Bottle"
    },
    {
      "x": 6,
      "y": 23,
      "z": 3,
      "name": "Plant_Leaves_Bottle"
    },
    {
      "x": 6,
      "y": 24,
      "z": 3,
      "name": "Plant_Leaves_Bottle"
    },
    {
      "x": 6,
      "y": 18,
      "z": 4,
      "name": "Plant_Leaves_Bottle"
    },
    {
      "x": 6,
      "y": 19,
      "z": 4,
      "name": "Plant_Leaves_Bottle"
    },
    {
      "x": 6,
      "y": 25,
      "z": 4,
      "name": "Plant_Leaves_Bottle"
    },
    {
      "x": 6,
      "y": 18,
      "z": 5,
      "name": "Plant_Leaves_Bottle"
    },
    {
      "x": 6,
      "y": 21,
      "z": 5,
      "name": "Soil_Plant_Vine_Block"
    },
    {
      "x": 6,
      "y": 22,
      "z": 5,
      "name": "Soil_Plant_Vine_Block"
    },
    {
      "x": 6,
      "y": 23,
      "z": 5,
      "name": "Soil_Plant_Vine_Block"
    },
    {
      "x": 6,
      "y": 24,
      "z": 5,
      "name": "Vine_Branch_Long"
    },
    {
      "x": 6,
      "y": 25,
      "z": 5,
      "name": "Plant_Leaves_Bottle"
    },
    {
      "x": 6,
      "y": 26,
      "z": 5,
      "name": "Plant_Leaves_Bottle"
    },
    {
      "x": 6,
      "y": 25,
      "z": 6,
      "name": "Plant_Leaves_Bottle"
    },
    {
      "x": 6,
      "y": 26,
      "z": 6,
      "name": "Plant_Leaves_Bottle"
    },
    {
      "x": 6,
      "y": 22,
      "z": 7,
      "name": "Plant_Leaves_Bottle"
    },
    {
      "x": 6,
      "y": 23,
      "z": 7,
      "name": "Plant_Leaves_Bottle"
    },
    {
      "x": 6,
      "y": 24,
      "z": 7,
      "name": "Plant_Leaves_Bottle"
    },
    {
      "x": 6,
      "y": 25,
      "z": 7,
      "name": "Plant_Leaves_Bottle"
    },
    {
      "x": 7,
      "y": 18,
      "z": -1,
      "name": "Plant_Leaves_Bottle"
    },
    {
      "x": 7,
      "y": 25,
      "z": 0,
      "name": "Plant_Leaves_Bottle"
    },
    {
      "x": 7,
      "y": 26,
      "z": 0,
      "name": "Plant_Leaves_Bottle"
    },
    {
      "x": 7,
      "y": 19,
      "z": 1,
      "name": "Plant_Leaves_Bottle"
    },
    {
      "x": 7,
      "y": 20,
      "z": 1,
      "name": "Plant_Leaves_Bottle"
    },
    {
      "x": 7,
      "y": 15,
      "z": 2,
      "name": "Soil_Plant_Vine_Block"
    },
    {
      "x": 7,
      "y": 16,
      "z": 2,
      "name": "Soil_Plant_Vine_Block"
    },
    {
      "x": 7,
      "y": 20,
      "z": 2,
      "name": "Plant_Leaves_Bottle"
    },
    {
      "x": 7,
      "y": 16,
      "z": 3,
      "name": "Vine_Branch_Corner"
    },
    {
      "x": 7,
      "y": 17,
      "z": 3,
      "name": "Vine_Branch_Long"
    },
    {
      "x": 7,
      "y": 18,
      "z": 3,
      "name": "Vine_Branch_Long"
    },
    {
      "x": 7,
      "y": 19,
      "z": 3,
      "name": "Vine_Branch_Long"
    },
    {
      "x": 7,
      "y": 20,
      "z": 3,
      "name": "Plant_Leaves_Bottle"
    },
    {
      "x": 7,
      "y": 23,
      "z": 3,
      "name": "Plant_Leaves_Bottle"
    },
    {
      "x": 7,
      "y": 24,
      "z": 3,
      "name": "Plant_Leaves_Bottle"
    },
    {
      "x": 7,
      "y": 24,
      "z": 4,
      "name": "Plant_Leaves_Bottle"
    },
    {
      "x": 7,
      "y": 25,
      "z": 4,
      "name": "Plant_Leaves_Bottle"
    },
    {
      "x": 7,
      "y": 17,
      "z": 5,
      "name": "Plant_Leaves_Bottle"
    },
    {
      "x": 7,
      "y": 18,
      "z": 5,
      "name": "Plant_Leaves_Bottle"
    },
    {
      "x": 7,
      "y": 19,
      "z": 5,
      "name": "Plant_Leaves_Bottle"
    },
    {
      "x": 7,
      "y": 23,
      "z": 5,
      "name": "Vine_Branch_Long",
      "rotation": 5
    },
    {
      "x": 7,
      "y": 25,
      "z": 5,
      "name": "Plant_Leaves_Bottle"
    },
    {
      "x": 7,
      "y": 26,
      "z": 5,
      "name": "Plant_Leaves_Bottle"
    },
    {
      "x": 7,
      "y": 25,
      "z": 6,
      "name": "Plant_Leaves_Bottle"
    },
    {
      "x": 7,
      "y": 23,
      "z": 7,
      "name": "Plant_Leaves_Bottle"
    },
    {
      "x": 7,
      "y": 24,
      "z": 7,
      "name": "Plant_Leaves_Bottle"
    },
    {
      "x": 8,
      "y": 17,
      "z": -1,
      "name": "Plant_Leaves_Bottle"
    },
    {
      "x": 8,
      "y": 18,
      "z": -1,
      "name": "Plant_Leaves_Bottle"
    },
    {
      "x": 8,
      "y": 18,
      "z": 0,
      "name": "Plant_Leaves_Bottle"
    },
    {
      "x": 8,
      "y": 19,
      "z": 0,
      "name": "Plant_Leaves_Bottle"
    },
    {
      "x": 8,
      "y": 20,
      "z": 1,
      "name": "Plant_Leaves_Bottle"
    },
    {
      "x": 8,
      "y": 16,
      "z": 2,
      "name": "Soil_Plant_Vine_Block"
    },
    {
      "x": 8,
      "y": 17,
      "z": 2,
      "name": "Soil_Plant_Vine_Block"
    },
    {
      "x": 8,
      "y": 18,
      "z": 2,
      "name": "Vine_Branch_Long"
    },
    {
      "x": 8,
      "y": 19,
      "z": 2,
      "name": "Vine_Branch_Long"
    },
    {
      "x": 8,
      "y": 20,
      "z": 2,
      "name": "Plant_Leaves_Bottle"
    },
    {
      "x": 8,
      "y": 17,
      "z": 3,
      "name": "Vine_Branch_Long",
      "rotation": 4
    },
    {
      "x": 8,
      "y": 20,
      "z": 3,
      "name": "Plant_Leaves_Bottle"
    },
    {
      "x": 8,
      "y": 23,
      "z": 3,
      "name": "Plant_Leaves_Bottle"
    },
    {
      "x": 8,
      "y": 17,
      "z": 4,
      "name": "Vine_Branch_Long",
      "rotation": 4
    },
    {
      "x": 8,
      "y": 20,
      "z": 4,
      "name": "Plant_Leaves_Bottle"
    },
    {
      "x": 8,
      "y": 23,
      "z": 4,
      "name": "Plant_Leaves_Bottle"
    },
    {
      "x": 8,
      "y": 24,
      "z": 4,
      "name": "Plant_Leaves_Bottle"
    },
    {
      "x": 8,
      "y": 16,
      "z": 5,
      "name": "Plant_Leaves_Bottle"
    },
    {
      "x": 8,
      "y": 17,
      "z": 5,
      "name": "Plant_Leaves_Bottle"
    },
    {
      "x": 8,
      "y": 18,
      "z": 5,
      "name": "Plant_Leaves_Bottle"
    },
    {
      "x": 8,
      "y": 19,
      "z": 5,
      "name": "Plant_Leaves_Bottle"
    },
    {
      "x": 8,
      "y": 20,
      "z": 5,
      "name": "Plant_Leaves_Bottle"
    },
    {
      "x": 8,
      "y": 23,
      "z": 5,
      "name": "Vine_Branch_Corner",
      "rotation": 1
    },
    {
      "x": 8,
      "y": 24,
      "z": 5,
      "name": "Plant_Leaves_Bottle"
    },
    {
      "x": 8,
      "y": 25,
      "z": 5,
      "name": "Plant_Leaves_Bottle"
    },
    {
      "x": 8,
      "y": 17,
      "z": 6,
      "name": "Plant_Leaves_Bottle"
    },
    {
      "x": 8,
      "y": 18,
      "z": 6,
      "name": "Plant_Leaves_Bottle"
    },
    {
      "x": 8,
      "y": 19,
      "z": 6,
      "name": "Plant_Leaves_Bottle"
    },
    {
      "x": 8,
      "y": 22,
      "z": 6,
      "name": "Plant_Leaves_Bottle"
    },
    {
      "x": 8,
      "y": 23,
      "z": 6,
      "name": "Plant_Leaves_Bottle"
    },
    {
      "x": 8,
      "y": 24,
      "z": 6,
      "name": "Plant_Leaves_Bottle"
    },
    {
      "x": 8,
      "y": 25,
      "z": 6,
      "name": "Plant_Leaves_Bottle"
    },
    {
      "x": 8,
      "y": 23,
      "z": 7,
      "name": "Plant_Leaves_Bottle"
    },
    {
      "x": 9,
      "y": 18,
      "z": -1,
      "name": "Plant_Leaves_Bottle"
    },
    {
      "x": 9,
      "y": 18,
      "z": 0,
      "name": "Plant_Leaves_Bottle"
    },
    {
      "x": 9,
      "y": 19,
      "z": 0,
      "name": "Plant_Leaves_Bottle"
    },
    {
      "x": 9,
      "y": 20,
      "z": 1,
      "name": "Plant_Leaves_Bottle"
    },
    {
      "x": 9,
      "y": 17,
      "z": 2,
      "name": "Vine_Branch_Long",
      "rotation": 5
    },
    {
      "x": 9,
      "y": 20,
      "z": 2,
      "name": "Plant_Leaves_Bottle"
    },
    {
      "x": 9,
      "y": 19,
      "z": 4,
      "name": "Plant_Leaves_Bottle"
    },
    {
      "x": 9,
      "y": 20,
      "z": 4,
      "name": "Plant_Leaves_Bottle"
    },
    {
      "x": 9,
      "y": 16,
      "z": 5,
      "name": "Plant_Leaves_Bottle"
    },
    {
      "x": 9,
      "y": 17,
      "z": 5,
      "name": "Plant_Leaves_Bottle"
    },
    {
      "x": 9,
      "y": 18,
      "z": 5,
      "name": "Plant_Leaves_Bottle"
    },
    {
      "x": 9,
      "y": 19,
      "z": 5,
      "name": "Plant_Leaves_Bottle"
    },
    {
      "x": 9,
      "y": 23,
      "z": 5,
      "name": "Plant_Leaves_Bottle"
    },
    {
      "x": 9,
      "y": 24,
      "z": 5,
      "name": "Plant_Leaves_Bottle"
    },
    {
      "x": 9,
      "y": 18,
      "z": 6,
      "name": "Plant_Leaves_Bottle"
    },
    {
      "x": 9,
      "y": 23,
      "z": 6,
      "name": "Plant_Leaves_Bottle"
    },
    {
      "x": 10,
      "y": 16,
      "z": 0,
      "name": "Plant_Leaves_Bottle"
    },
    {
      "x": 10,
      "y": 17,
      "z": 0,
      "name": "Plant_Leaves_Bottle"
    },
    {
      "x": 10,
      "y": 18,
      "z": 0,
      "name": "Plant_Leaves_Bottle"
    },
    {
      "x": 10,
      "y": 19,
      "z": 0,
      "name": "Plant_Leaves_Bottle"
    },
    {
      "x": 10,
      "y": 17,
      "z": 1,
      "name": "Plant_Leaves_Bottle"
    },
    {
      "x": 10,
      "y": 18,
      "z": 1,
      "name": "Plant_Leaves_Bottle"
    },
    {
      "x": 10,
      "y": 19,
      "z": 1,
      "name": "Plant_Leaves_Bottle"
    },
    {
      "x": 10,
      "y": 17,
      "z": 2,
      "name": "Vine_Branch_Long",
      "rotation": 5
    },
    {
      "x": 10,
      "y": 18,
      "z": 2,
      "name": "Plant_Leaves_Bottle"
    },
    {
      "x": 10,
      "y": 19,
      "z": 2,
      "name": "Plant_Leaves_Bottle"
    },
    {
      "x": 10,
      "y": 20,
      "z": 2,
      "name": "Plant_Leaves_Bottle"
    },
    {
      "x": 10,
      "y": 18,
      "z": 3,
      "name": "Plant_Leaves_Bottle"
    },
    {
      "x": 10,
      "y": 19,
      "z": 3,
      "name": "Plant_Leaves_Bottle"
    },
    {
      "x": 10,
      "y": 20,
      "z": 3,
      "name": "Plant_Leaves_Bottle"
    },
    {
      "x": 10,
      "y": 17,
      "z": 4,
      "name": "Plant_Leaves_Bottle"
    },
    {
      "x": 10,
      "y": 18,
      "z": 4,
      "name": "Plant_Leaves_Bottle"
    },
    {
      "x": 10,
      "y": 19,
      "z": 4,
      "name": "Plant_Leaves_Bottle"
    },
    {
      "x": 10,
      "y": 17,
      "z": 5,
      "name": "Plant_Leaves_Bottle"
    },
    {
      "x": 11,
      "y": 17,
      "z": 0,
      "name": "Plant_Leaves_Bottle"
    },
    {
      "x": 11,
      "y": 16,
      "z": 1,
      "name": "Plant_Leaves_Bottle"
    },
    {
      "x": 11,
      "y": 17,
      "z": 1,
      "name": "Plant_Leaves_Bottle"
    },
    {
      "x": 11,
      "y": 18,
      "z": 1,
      "name": "Plant_Leaves_Bottle"
    },
    {
      "x": 11,
      "y": 16,
      "z": 2,
      "name": "Plant_Leaves_Bottle"
    },
    {
      "x": 11,
      "y": 17,
      "z": 2,
      "name": "Plant_Leaves_Bottle"
    },
    {
      "x": 11,
      "y": 18,
      "z": 2,
      "name": "Plant_Leaves_Bottle"
    },
    {
      "x": 11,
      "y": 19,
      "z": 2,
      "name": "Plant_Leaves_Bottle"
    },
    {
      "x": 11,
      "y": 17,
      "z": 3,
      "name": "Plant_Leaves_Bottle"
    },
    {
      "x": 11,
      "y": 18,
      "z": 3,
      "name": "Plant_Leaves_Bottle"
    }
  ],
  "fluids": [
    {
      "x": -11,
      "y": 24,
      "z": 0,
      "name": "Empty",
      "level": 0
    },
    {
      "x": -11,
      "y": 22,
      "z": 1,
      "name": "Empty",
      "level": 0
    },
    {
      "x": -11,
      "y": 23,
      "z": 1,
      "name": "Empty",
      "level": 0
    },
    {
      "x": -11,
      "y": 24,
      "z": 1,
      "name": "Empty",
      "level": 0
    },
    {
      "x": -11,
      "y": 25,
      "z": 1,
      "name": "Empty",
      "level": 0
    },
    {
      "x": -11,
      "y": 23,
      "z": 2,
      "name": "Empty",
      "level": 0
    },
    {
      "x": -11,
      "y": 24,
      "z": 2,
      "name": "Empty",
      "level": 0
    },
    {
      "x": -10,
      "y": 22,
      "z": -1,
      "name": "Empty",
      "level": 0
    },
    {
      "x": -10,
      "y": 23,
      "z": -1,
      "name": "Empty",
      "level": 0
    },
    {
      "x": -10,
      "y": 24,
      "z": -1,
      "name": "Empty",
      "level": 0
    },
    {
      "x": -10,
      "y": 25,
      "z": -1,
      "name": "Empty",
      "level": 0
    },
    {
      "x": -10,
      "y": 23,
      "z": 0,
      "name": "Empty",
      "level": 0
    },
    {
      "x": -10,
      "y": 24,
      "z": 0,
      "name": "Empty",
      "level": 0
    },
    {
      "x": -10,
      "y": 25,
      "z": 0,
      "name": "Empty",
      "level": 0
    },
    {
      "x": -10,
      "y": 26,
      "z": 0,
      "name": "Empty",
      "level": 0
    },
    {
      "x": -10,
      "y": 23,
      "z": 1,
      "name": "Empty",
      "level": 0
    },
    {
      "x": -10,
      "y": 26,
      "z": 1,
      "name": "Empty",
      "level": 0
    },
    {
      "x": -10,
      "y": 21,
      "z": 2,
      "name": "Empty",
      "level": 0
    },
    {
      "x": -10,
      "y": 22,
      "z": 2,
      "name": "Empty",
      "level": 0
    },
    {
      "x": -10,
      "y": 23,
      "z": 2,
      "name": "Empty",
      "level": 0
    },
    {
      "x": -10,
      "y": 24,
      "z": 2,
      "name": "Empty",
      "level": 0
    },
    {
      "x": -10,
      "y": 25,
      "z": 2,
      "name": "Empty",
      "level": 0
    },
    {
      "x": -10,
      "y": 26,
      "z": 2,
      "name": "Empty",
      "level": 0
    },
    {
      "x": -10,
      "y": 22,
      "z": 3,
      "name": "Empty",
      "level": 0
    },
    {
      "x": -10,
      "y": 23,
      "z": 3,
      "name": "Empty",
      "level": 0
    },
    {
      "x": -10,
      "y": 24,
      "z": 3,
      "name": "Empty",
      "level": 0
    },
    {
      "x": -9,
      "y": 22,
      "z": -2,
      "name": "Empty",
      "level": 0
    },
    {
      "x": -9,
      "y": 23,
      "z": -2,
      "name": "Empty",
      "level": 0
    },
    {
      "x": -9,
      "y": 24,
      "z": -2,
      "name": "Empty",
      "level": 0
    },
    {
      "x": -9,
      "y": 25,
      "z": -1,
      "name": "Empty",
      "level": 0
    },
    {
      "x": -9,
      "y": 23,
      "z": 0,
      "name": "Empty",
      "level": 0
    },
    {
      "x": -9,
      "y": 24,
      "z": 0,
      "name": "Empty",
      "level": 0
    },
    {
      "x": -9,
      "y": 25,
      "z": 0,
      "name": "Empty",
      "level": 0
    },
    {
      "x": -9,
      "y": 26,
      "z": 0,
      "name": "Empty",
      "level": 0
    },
    {
      "x": -9,
      "y": 24,
      "z": 1,
      "name": "Empty",
      "level": 0
    },
    {
      "x": -9,
      "y": 25,
      "z": 1,
      "name": "Empty",
      "level": 0
    },
    {
      "x": -9,
      "y": 23,
      "z": 2,
      "name": "Empty",
      "level": 0
    },
    {
      "x": -9,
      "y": 24,
      "z": 2,
      "name": "Empty",
      "level": 0
    },
    {
      "x": -9,
      "y": 25,
      "z": 2,
      "name": "Empty",
      "level": 0
    },
    {
      "x": -9,
      "y": 26,
      "z": 2,
      "name": "Empty",
      "level": 0
    },
    {
      "x": -9,
      "y": 26,
      "z": 3,
      "name": "Empty",
      "level": 0
    },
    {
      "x": -9,
      "y": 22,
      "z": 4,
      "name": "Empty",
      "level": 0
    },
    {
      "x": -9,
      "y": 23,
      "z": 4,
      "name": "Empty",
      "level": 0
    },
    {
      "x": -9,
      "y": 24,
      "z": 4,
      "name": "Empty",
      "level": 0
    },
    {
      "x": -8,
      "y": 21,
      "z": -2,
      "name": "Empty",
      "level": 0
    },
    {
      "x": -8,
      "y": 22,
      "z": -2,
      "name": "Empty",
      "level": 0
    },
    {
      "x": -8,
      "y": 23,
      "z": -2,
      "name": "Empty",
      "level": 0
    },
    {
      "x": -8,
      "y": 24,
      "z": -2,
      "name": "Empty",
      "level": 0
    },
    {
      "x": -8,
      "y": 23,
      "z": -1,
      "name": "Empty",
      "level": 0
    },
    {
      "x": -8,
      "y": 24,
      "z": -1,
      "name": "Empty",
      "level": 0
    },
    {
      "x": -8,
      "y": 23,
      "z": 0,
      "name": "Empty",
      "level": 0
    },
    {
      "x": -8,
      "y": 24,
      "z": 0,
      "name": "Empty",
      "level": 0
    },
    {
      "x": -8,
      "y": 25,
      "z": 0,
      "name": "Empty",
      "level": 0
    },
    {
      "x": -8,
      "y": 26,
      "z": 0,
      "name": "Empty",
      "level": 0
    },
    {
      "x": -8,
      "y": 21,
      "z": 1,
      "name": "Empty",
      "level": 0
    },
    {
      "x": -8,
      "y": 22,
      "z": 1,
      "name": "Empty",
      "level": 0
    },
    {
      "x": -8,
      "y": 23,
      "z": 1,
      "name": "Empty",
      "level": 0
    },
    {
      "x": -8,
      "y": 24,
      "z": 1,
      "name": "Empty",
      "level": 0
    },
    {
      "x": -8,
      "y": 25,
      "z": 1,
      "name": "Empty",
      "level": 0
    },
    {
      "x": -8,
      "y": 26,
      "z": 1,
      "name": "Empty",
      "level": 0
    },
    {
      "x": -8,
      "y": 22,
      "z": 2,
      "name": "Empty",
      "level": 0
    },
    {
      "x": -8,
      "y": 22,
      "z": 3,
      "name": "Empty",
      "level": 0
    },
    {
      "x": -8,
      "y": 24,
      "z": 3,
      "name": "Empty",
      "level": 0
    },
    {
      "x": -8,
      "y": 25,
      "z": 3,
      "name": "Empty",
      "level": 0
    },
    {
      "x": -8,
      "y": 26,
      "z": 3,
      "name": "Empty",
      "level": 0
    },
    {
      "x": -8,
      "y": 23,
      "z": 4,
      "name": "Empty",
      "level": 0
    },
    {
      "x": -8,
      "y": 24,
      "z": 4,
      "name": "Empty",
      "level": 0
    },
    {
      "x": -7,
      "y": 24,
      "z": -5,
      "name": "Empty",
      "level": 0
    },
    {
      "x": -7,
      "y": 23,
      "z": -4,
      "name": "Empty",
      "level": 0
    },
    {
      "x": -7,
      "y": 24,
      "z": -4,
      "name": "Empty",
      "level": 0
    },
    {
      "x": -7,
      "y": 25,
      "z": -4,
      "name": "Empty",
      "level": 0
    },
    {
      "x": -7,
      "y": 24,
      "z": -3,
      "name": "Empty",
      "level": 0
    },
    {
      "x": -7,
      "y": 25,
      "z": -3,
      "name": "Empty",
      "level": 0
    },
    {
      "x": -7,
      "y": 26,
      "z": -3,
      "name": "Empty",
      "level": 0
    },
    {
      "x": -7,
      "y": 25,
      "z": -2,
      "name": "Empty",
      "level": 0
    },
    {
      "x": -7,
      "y": 23,
      "z": -1,
      "name": "Empty",
      "level": 0
    },
    {
      "x": -7,
      "y": 24,
      "z": -1,
      "name": "Empty",
      "level": 0
    },
    {
      "x": -7,
      "y": 21,
      "z": 0,
      "name": "Empty",
      "level": 0
    },
    {
      "x": -7,
      "y": 22,
      "z": 0,
      "name": "Empty",
      "level": 0
    },
    {
      "x": -7,
      "y": 23,
      "z": 0,
      "name": "Empty",
      "level": 0
    },
    {
      "x": -7,
      "y": 24,
      "z": 0,
      "name": "Empty",
      "level": 0
    },
    {
      "x": -7,
      "y": 25,
      "z": 0,
      "name": "Empty",
      "level": 0
    },
    {
      "x": -7,
      "y": 19,
      "z": 1,
      "name": "Empty",
      "level": 0
    },
    {
      "x": -7,
      "y": 20,
      "z": 1,
      "name": "Empty",
      "level": 0
    },
    {
      "x": -7,
      "y": 21,
      "z": 1,
      "name": "Empty",
      "level": 0
    },
    {
      "x": -7,
      "y": 23,
      "z": 1,
      "name": "Empty",
      "level": 0
    },
    {
      "x": -7,
      "y": 24,
      "z": 1,
      "name": "Empty",
      "level": 0
    },
    {
      "x": -7,
      "y": 25,
      "z": 1,
      "name": "Empty",
      "level": 0
    },
    {
      "x": -7,
      "y": 26,
      "z": 1,
      "name": "Empty",
      "level": 0
    },
    {
      "x": -7,
      "y": 19,
      "z": 2,
      "name": "Empty",
      "level": 0
    },
    {
      "x": -7,
      "y": 24,
      "z": 2,
      "name": "Empty",
      "level": 0
    },
    {
      "x": -7,
      "y": 25,
      "z": 2,
      "name": "Empty",
      "level": 0
    },
    {
      "x": -7,
      "y": 26,
      "z": 2,
      "name": "Empty",
      "level": 0
    },
    {
      "x": -7,
      "y": 24,
      "z": 3,
      "name": "Empty",
      "level": 0
    },
    {
      "x": -7,
      "y": 25,
      "z": 3,
      "name": "Empty",
      "level": 0
    },
    {
      "x": -7,
      "y": 26,
      "z": 3,
      "name": "Empty",
      "level": 0
    },
    {
      "x": -7,
      "y": 23,
      "z": 4,
      "name": "Empty",
      "level": 0
    },
    {
      "x": -7,
      "y": 24,
      "z": 4,
      "name": "Empty",
      "level": 0
    },
    {
      "x": -7,
      "y": 25,
      "z": 4,
      "name": "Empty",
      "level": 0
    },
    {
      "x": -6,
      "y": 24,
      "z": -6,
      "name": "Empty",
      "level": 0
    },
    {
      "x": -6,
      "y": 23,
      "z": -5,
      "name": "Empty",
      "level": 0
    },
    {
      "x": -6,
      "y": 24,
      "z": -5,
      "name": "Empty",
      "level": 0
    },
    {
      "x": -6,
      "y": 25,
      "z": -5,
      "name": "Empty",
      "level": 0
    },
    {
      "x": -6,
      "y": 25,
      "z": -4,
      "name": "Empty",
      "level": 0
    },
    {
      "x": -6,
      "y": 26,
      "z": -4,
      "name": "Empty",
      "level": 0
    },
    {
      "x": -6,
      "y": 25,
      "z": -3,
      "name": "Empty",
      "level": 0
    },
    {
      "x": -6,
      "y": 26,
      "z": -3,
      "name": "Empty",
      "level": 0
    },
    {
      "x": -6,
      "y": 27,
      "z": -3,
      "name": "Empty",
      "level": 0
    },
    {
      "x": -6,
      "y": 24,
      "z": -2,
      "name": "Empty",
      "level": 0
    },
    {
      "x": -6,
      "y": 26,
      "z": -2,
      "name": "Empty",
      "level": 0
    },
    {
      "x": -6,
      "y": 23,
      "z": -1,
      "name": "Empty",
      "level": 0
    },
    {
      "x": -6,
      "y": 24,
      "z": -1,
      "name": "Empty",
      "level": 0
    },
    {
      "x": -6,
      "y": 26,
      "z": -1,
      "name": "Empty",
      "level": 0
    },
    {
      "x": -6,
      "y": 23,
      "z": 0,
      "name": "Empty",
      "level": 0
    },
    {
      "x": -6,
      "y": 18,
      "z": 2,
      "name": "Empty",
      "level": 0
    },
    {
      "x": -6,
      "y": 19,
      "z": 2,
      "name": "Empty",
      "level": 0
    },
    {
      "x": -6,
      "y": 24,
      "z": 2,
      "name": "Empty",
      "level": 0
    },
    {
      "x": -6,
      "y": 19,
      "z": 3,
      "name": "Empty",
      "level": 0
    },
    {
      "x": -6,
      "y": 20,
      "z": 3,
      "name": "Empty",
      "level": 0
    },
    {
      "x": -6,
      "y": 21,
      "z": 3,
      "name": "Empty",
      "level": 0
    },
    {
      "x": -6,
      "y": 22,
      "z": 3,
      "name": "Empty",
      "level": 0
    },
    {
      "x": -6,
      "y": 23,
      "z": 3,
      "name": "Empty",
      "level": 0
    },
    {
      "x": -6,
      "y": 24,
      "z": 3,
      "name": "Empty",
      "level": 0
    },
    {
      "x": -6,
      "y": 25,
      "z": 3,
      "name": "Empty",
      "level": 0
    },
    {
      "x": -6,
      "y": 22,
      "z": 4,
      "name": "Empty",
      "level": 0
    },
    {
      "x": -6,
      "y": 23,
      "z": 4,
      "name": "Empty",
      "level": 0
    },
    {
      "x": -6,
      "y": 24,
      "z": 4,
      "name": "Empty",
      "level": 0
    },
    {
      "x": -5,
      "y": 23,
      "z": -6,
      "name": "Empty",
      "level": 0
    },
    {
      "x": -5,
      "y": 22,
      "z": -5,
      "name": "Empty",
      "level": 0
    },
    {
      "x": -5,
      "y": 23,
      "z": -5,
      "name": "Empty",
      "level": 0
    },
    {
      "x": -5,
      "y": 24,
      "z": -5,
      "name": "Empty",
      "level": 0
    },
    {
      "x": -5,
      "y": 25,
      "z": -5,
      "name": "Empty",
      "level": 0
    },
    {
      "x": -5,
      "y": 26,
      "z": -5,
      "name": "Empty",
      "level": 0
    },
    {
      "x": -5,
      "y": 26,
      "z": -4,
      "name": "Empty",
      "level": 0
    },
    {
      "x": -5,
      "y": 26,
      "z": -3,
      "name": "Empty",
      "level": 0
    },
    {
      "x": -5,
      "y": 27,
      "z": -3,
      "name": "Empty",
      "level": 0
    },
    {
      "x": -5,
      "y": 26,
      "z": -2,
      "name": "Empty",
      "level": 0
    },
    {
      "x": -5,
      "y": 27,
      "z": -2,
      "name": "Empty",
      "level": 0
    },
    {
      "x": -5,
      "y": 24,
      "z": -1,
      "name": "Empty",
      "level": 0
    },
    {
      "x": -5,
      "y": 26,
      "z": -1,
      "name": "Empty",
      "level": 0
    },
    {
      "x": -5,
      "y": 24,
      "z": 0,
      "name": "Empty",
      "level": 0
    },
    {
      "x": -5,
      "y": 25,
      "z": 0,
      "name": "Empty",
      "level": 0
    },
    {
      "x": -5,
      "y": 26,
      "z": 0,
      "name": "Empty",
      "level": 0
    },
    {
      "x": -5,
      "y": 24,
      "z": 1,
      "name": "Empty",
      "level": 0
    },
    {
      "x": -5,
      "y": 18,
      "z": 2,
      "name": "Empty",
      "level": 0
    },
    {
      "x": -5,
      "y": 22,
      "z": 3,
      "name": "Empty",
      "level": 0
    },
    {
      "x": -5,
      "y": 23,
      "z": 3,
      "name": "Empty",
      "level": 0
    },
    {
      "x": -5,
      "y": 24,
      "z": 3,
      "name": "Empty",
      "level": 0
    },
    {
      "x": -5,
      "y": 22,
      "z": 4,
      "name": "Empty",
      "level": 0
    },
    {
      "x": -5,
      "y": 23,
      "z": 4,
      "name": "Empty",
      "level": 0
    },
    {
      "x": -5,
      "y": 24,
      "z": 4,
      "name": "Empty",
      "level": 0
    },
    {
      "x": -5,
      "y": 23,
      "z": 5,
      "name": "Empty",
      "level": 0
    },
    {
      "x": -4,
      "y": 24,
      "z": -6,
      "name": "Empty",
      "level": 0
    },
    {
      "x": -4,
      "y": 25,
      "z": -6,
      "name": "Empty",
      "level": 0
    },
    {
      "x": -4,
      "y": 22,
      "z": -5,
      "name": "Empty",
      "level": 0
    },
    {
      "x": -4,
      "y": 23,
      "z": -5,
      "name": "Empty",
      "level": 0
    },
    {
      "x": -4,
      "y": 24,
      "z": -5,
      "name": "Empty",
      "level": 0
    },
    {
      "x": -4,
      "y": 25,
      "z": -5,
      "name": "Empty",
      "level": 0
    },
    {
      "x": -4,
      "y": 26,
      "z": -5,
      "name": "Empty",
      "level": 0
    },
    {
      "x": -4,
      "y": 25,
      "z": -4,
      "name": "Empty",
      "level": 0
    },
    {
      "x": -4,
      "y": 26,
      "z": -4,
      "name": "Empty",
      "level": 0
    },
    {
      "x": -4,
      "y": 27,
      "z": -4,
      "name": "Empty",
      "level": 0
    },
    {
      "x": -4,
      "y": 23,
      "z": -3,
      "name": "Empty",
      "level": 0
    },
    {
      "x": -4,
      "y": 24,
      "z": -3,
      "name": "Empty",
      "level": 0
    },
    {
      "x": -4,
      "y": 25,
      "z": -3,
      "name": "Empty",
      "level": 0
    },
    {
      "x": -4,
      "y": 26,
      "z": -3,
      "name": "Empty",
      "level": 0
    },
    {
      "x": -4,
      "y": 27,
      "z": -3,
      "name": "Empty",
      "level": 0
    },
    {
      "x": -4,
      "y": 22,
      "z": -2,
      "name": "Empty",
      "level": 0
    },
    {
      "x": -4,
      "y": 23,
      "z": -2,
      "name": "Empty",
      "level": 0
    },
    {
      "x": -4,
      "y": 27,
      "z": -2,
      "name": "Empty",
      "level": 0
    },
    {
      "x": -4,
      "y": 22,
      "z": -1,
      "name": "Empty",
      "level": 0
    },
    {
      "x": -4,
      "y": 25,
      "z": -1,
      "name": "Empty",
      "level": 0
    },
    {
      "x": -4,
      "y": 26,
      "z": -1,
      "name": "Empty",
      "level": 0
    },
    {
      "x": -4,
      "y": 27,
      "z": -1,
      "name": "Empty",
      "level": 0
    },
    {
      "x": -4,
      "y": 25,
      "z": 0,
      "name": "Empty",
      "level": 0
    },
    {
      "x": -4,
      "y": 17,
      "z": 2,
      "name": "Empty",
      "level": 0
    },
    {
      "x": -4,
      "y": 18,
      "z": 2,
      "name": "Empty",
      "level": 0
    },
    {
      "x": -4,
      "y": 21,
      "z": 3,
      "name": "Empty",
      "level": 0
    },
    {
      "x": -4,
      "y": 22,
      "z": 3,
      "name": "Empty",
      "level": 0
    },
    {
      "x": -4,
      "y": 23,
      "z": 3,
      "name": "Empty",
      "level": 0
    },
    {
      "x": -4,
      "y": 22,
      "z": 4,
      "name": "Empty",
      "level": 0
    },
    {
      "x": -4,
      "y": 23,
      "z": 4,
      "name": "Empty",
      "level": 0
    },
    {
      "x": -4,
      "y": 24,
      "z": 4,
      "name": "Empty",
      "level": 0
    },
    {
      "x": -4,
      "y": 22,
      "z": 5,
      "name": "Empty",
      "level": 0
    },
    {
      "x": -4,
      "y": 23,
      "z": 5,
      "name": "Empty",
      "level": 0
    },
    {
      "x": -3,
      "y": 24,
      "z": -6,
      "name": "Empty",
      "level": 0
    },
    {
      "x": -3,
      "y": 24,
      "z": -5,
      "name": "Empty",
      "level": 0
    },
    {
      "x": -3,
      "y": 25,
      "z": -5,
      "name": "Empty",
      "level": 0
    },
    {
      "x": -3,
      "y": 26,
      "z": -4,
      "name": "Empty",
      "level": 0
    },
    {
      "x": -3,
      "y": 25,
      "z": -3,
      "name": "Empty",
      "level": 0
    },
    {
      "x": -3,
      "y": 26,
      "z": -3,
      "name": "Empty",
      "level": 0
    },
    {
      "x": -3,
      "y": 27,
      "z": -3,
      "name": "Empty",
      "level": 0
    },
    {
      "x": -3,
      "y": 27,
      "z": -2,
      "name": "Empty",
      "level": 0
    },
    {
      "x": -3,
      "y": 22,
      "z": -1,
      "name": "Empty",
      "level": 0
    },
    {
      "x": -3,
      "y": 23,
      "z": -1,
      "name": "Empty",
      "level": 0
    },
    {
      "x": -3,
      "y": 24,
      "z": -1,
      "name": "Empty",
      "level": 0
    },
    {
      "x": -3,
      "y": 25,
      "z": -1,
      "name": "Empty",
      "level": 0
    },
    {
      "x": -3,
      "y": 26,
      "z": -1,
      "name": "Empty",
      "level": 0
    },
    {
      "x": -3,
      "y": 21,
      "z": 0,
      "name": "Empty",
      "level": 0
    },
    {
      "x": -3,
      "y": 22,
      "z": 0,
      "name": "Empty",
      "level": 0
    },
    {
      "x": -3,
      "y": 25,
      "z": 0,
      "name": "Empty",
      "level": 0
    },
    {
      "x": -3,
      "y": 26,
      "z": 0,
      "name": "Empty",
      "level": 0
    },
    {
      "x": -3,
      "y": 14,
      "z": 2,
      "name": "Empty",
      "level": 0
    },
    {
      "x": -3,
      "y": 15,
      "z": 2,
      "name": "Empty",
      "level": 0
    },
    {
      "x": -3,
      "y": 16,
      "z": 2,
      "name": "Empty",
      "level": 0
    },
    {
      "x": -3,
      "y": 17,
      "z": 2,
      "name": "Empty",
      "level": 0
    },
    {
      "x": -3,
      "y": 17,
      "z": 3,
      "name": "Empty",
      "level": 0
    },
    {
      "x": -3,
      "y": 18,
      "z": 3,
      "name": "Empty",
      "level": 0
    },
    {
      "x": -3,
      "y": 19,
      "z": 3,
      "name": "Empty",
      "level": 0
    },
    {
      "x": -3,
      "y": 20,
      "z": 3,
      "name": "Empty",
      "level": 0
    },
    {
      "x": -3,
      "y": 21,
      "z": 3,
      "name": "Empty",
      "level": 0
    },
    {
      "x": -3,
      "y": 22,
      "z": 3,
      "name": "Empty",
      "level": 0
    },
    {
      "x": -3,
      "y": 23,
      "z": 3,
      "name": "Empty",
      "level": 0
    },
    {
      "x": -3,
      "y": 20,
      "z": 4,
      "name": "Empty",
      "level": 0
    },
    {
      "x": -3,
      "y": 21,
      "z": 4,
      "name": "Empty",
      "level": 0
    },
    {
      "x": -3,
      "y": 22,
      "z": 4,
      "name": "Empty",
      "level": 0
    },
    {
      "x": -3,
      "y": 21,
      "z": 5,
      "name": "Empty",
      "level": 0
    },
    {
      "x": -2,
      "y": 23,
      "z": -6,
      "name": "Empty",
      "level": 0
    },
    {
      "x": -2,
      "y": 24,
      "z": -5,
      "name": "Empty",
      "level": 0
    },
    {
      "x": -2,
      "y": 25,
      "z": -5,
      "name": "Empty",
      "level": 0
    },
    {
      "x": -2,
      "y": 25,
      "z": -4,
      "name": "Empty",
      "level": 0
    },
    {
      "x": -2,
      "y": 26,
      "z": -4,
      "name": "Empty",
      "level": 0
    },
    {
      "x": -2,
      "y": 25,
      "z": -3,
      "name": "Empty",
      "level": 0
    },
    {
      "x": -2,
      "y": 26,
      "z": -3,
      "name": "Empty",
      "level": 0
    },
    {
      "x": -2,
      "y": 25,
      "z": -2,
      "name": "Empty",
      "level": 0
    },
    {
      "x": -2,
      "y": 25,
      "z": -1,
      "name": "Empty",
      "level": 0
    },
    {
      "x": -2,
      "y": 26,
      "z": -1,
      "name": "Empty",
      "level": 0
    },
    {
      "x": -2,
      "y": 18,
      "z": 0,
      "name": "Empty",
      "level": 0
    },
    {
      "x": -2,
      "y": 19,
      "z": 0,
      "name": "Empty",
      "level": 0
    },
    {
      "x": -2,
      "y": 20,
      "z": 0,
      "name": "Empty",
      "level": 0
    },
    {
      "x": -2,
      "y": 21,
      "z": 0,
      "name": "Empty",
      "level": 0
    },
    {
      "x": -2,
      "y": 25,
      "z": 0,
      "name": "Empty",
      "level": 0
    },
    {
      "x": -2,
      "y": 10,
      "z": 2,
      "name": "Empty",
      "level": 0
    },
    {
      "x": -2,
      "y": 11,
      "z": 2,
      "name": "Empty",
      "level": 0
    },
    {
      "x": -2,
      "y": 12,
      "z": 2,
      "name": "Empty",
      "level": 0
    },
    {
      "x": -2,
      "y": 13,
      "z": 2,
      "name": "Empty",
      "level": 0
    },
    {
      "x": -2,
      "y": 14,
      "z": 2,
      "name": "Empty",
      "level": 0
    },
    {
      "x": -2,
      "y": 20,
      "z": 3,
      "name": "Empty",
      "level": 0
    },
    {
      "x": -2,
      "y": 21,
      "z": 3,
      "name": "Empty",
      "level": 0
    },
    {
      "x": -2,
      "y": 22,
      "z": 3,
      "name": "Empty",
      "level": 0
    },
    {
      "x": -2,
      "y": 20,
      "z": 4,
      "name": "Empty",
      "level": 0
    },
    {
      "x": -2,
      "y": 21,
      "z": 4,
      "name": "Empty",
      "level": 0
    },
    {
      "x": -2,
      "y": 22,
      "z": 4,
      "name": "Empty",
      "level": 0
    },
    {
      "x": -1,
      "y": 22,
      "z": -6,
      "name": "Empty",
      "level": 0
    },
    {
      "x": -1,
      "y": 23,
      "z": -6,
      "name": "Empty",
      "level": 0
    },
    {
      "x": -1,
      "y": 24,
      "z": -6,
      "name": "Empty",
      "level": 0
    },
    {
      "x": -1,
      "y": 25,
      "z": -6,
      "name": "Empty",
      "level": 0
    },
    {
      "x": -1,
      "y": 24,
      "z": -5,
      "name": "Empty",
      "level": 0
    },
    {
      "x": -1,
      "y": 25,
      "z": -5,
      "name": "Empty",
      "level": 0
    },
    {
      "x": -1,
      "y": 24,
      "z": -4,
      "name": "Empty",
      "level": 0
    },
    {
      "x": -1,
      "y": 25,
      "z": -4,
      "name": "Empty",
      "level": 0
    },
    {
      "x": -1,
      "y": 25,
      "z": -3,
      "name": "Empty",
      "level": 0
    },
    {
      "x": -1,
      "y": 25,
      "z": -2,
      "name": "Empty",
      "level": 0
    },
    {
      "x": -1,
      "y": 18,
      "z": 0,
      "name": "Empty",
      "level": 0
    },
    {
      "x": -1,
      "y": 0,
      "z": 1,
      "name": "Empty",
      "level": 0
    },
    {
      "x": -1,
      "y": 1,
      "z": 1,
      "name": "Empty",
      "level": 0
    },
    {
      "x": -1,
      "y": 2,
      "z": 1,
      "name": "Empty",
      "level": 0
    },
    {
      "x": -1,
      "y": 3,
      "z": 1,
      "name": "Empty",
      "level": 0
    },
    {
      "x": -1,
      "y": 4,
      "z": 1,
      "name": "Empty",
      "level": 0
    },
    {
      "x": -1,
      "y": 5,
      "z": 1,
      "name": "Empty",
      "level": 0
    },
    {
      "x": -1,
      "y": 6,
      "z": 1,
      "name": "Empty",
      "level": 0
    },
    {
      "x": -1,
      "y": 15,
      "z": 1,
      "name": "Empty",
      "level": 0
    },
    {
      "x": -1,
      "y": 16,
      "z": 1,
      "name": "Empty",
      "level": 0
    },
    {
      "x": -1,
      "y": 17,
      "z": 1,
      "name": "Empty",
      "level": 0
    },
    {
      "x": -1,
      "y": 18,
      "z": 1,
      "name": "Empty",
      "level": 0
    },
    {
      "x": -1,
      "y": 0,
      "z": 2,
      "name": "Empty",
      "level": 0
    },
    {
      "x": -1,
      "y": 1,
      "z": 2,
      "name": "Empty",
      "level": 0
    },
    {
      "x": -1,
      "y": 2,
      "z": 2,
      "name": "Empty",
      "level": 0
    },
    {
      "x": -1,
      "y": 3,
      "z": 2,
      "name": "Empty",
      "level": 0
    },
    {
      "x": -1,
      "y": 4,
      "z": 2,
      "name": "Empty",
      "level": 0
    },
    {
      "x": -1,
      "y": 5,
      "z": 2,
      "name": "Empty",
      "level": 0
    },
    {
      "x": -1,
      "y": 6,
      "z": 2,
      "name": "Empty",
      "level": 0
    },
    {
      "x": -1,
      "y": 7,
      "z": 2,
      "name": "Empty",
      "level": 0
    },
    {
      "x": -1,
      "y": 8,
      "z": 2,
      "name": "Empty",
      "level": 0
    },
    {
      "x": -1,
      "y": 9,
      "z": 2,
      "name": "Empty",
      "level": 0
    },
    {
      "x": -1,
      "y": 10,
      "z": 2,
      "name": "Empty",
      "level": 0
    },
    {
      "x": 0,
      "y": 22,
      "z": -7,
      "name": "Empty",
      "level": 0
    },
    {
      "x": 0,
      "y": 23,
      "z": -7,
      "name": "Empty",
      "level": 0
    },
    {
      "x": 0,
      "y": 24,
      "z": -7,
      "name": "Empty",
      "level": 0
    },
    {
      "x": 0,
      "y": 24,
      "z": -6,
      "name": "Empty",
      "level": 0
    },
    {
      "x": 0,
      "y": 25,
      "z": -6,
      "name": "Empty",
      "level": 0
    },
    {
      "x": 0,
      "y": 24,
      "z": -5,
      "name": "Empty",
      "level": 0
    },
    {
      "x": 0,
      "y": 26,
      "z": -5,
      "name": "Empty",
      "level": 0
    },
    {
      "x": 0,
      "y": 25,
      "z": -4,
      "name": "Empty",
      "level": 0
    },
    {
      "x": 0,
      "y": 26,
      "z": -4,
      "name": "Empty",
      "level": 0
    },
    {
      "x": 0,
      "y": 25,
      "z": -3,
      "name": "Empty",
      "level": 0
    },
    {
      "x": 0,
      "y": 25,
      "z": -2,
      "name": "Empty",
      "level": 0
    },
    {
      "x": 0,
      "y": 27,
      "z": -2,
      "name": "Empty",
      "level": 0
    },
    {
      "x": 0,
      "y": 25,
      "z": -1,
      "name": "Empty",
      "level": 0
    },
    {
      "x": 0,
      "y": 27,
      "z": -1,
      "name": "Empty",
      "level": 0
    },
    {
      "x": 0,
      "y": 26,
      "z": 0,
      "name": "Empty",
      "level": 0
    },
    {
      "x": 0,
      "y": 27,
      "z": 0,
      "name": "Empty",
      "level": 0
    },
    {
      "x": 0,
      "y": 0,
      "z": 1,
      "name": "Empty",
      "level": 0
    },
    {
      "x": 0,
      "y": 1,
      "z": 1,
      "name": "Empty",
      "level": 0
    },
    {
      "x": 0,
      "y": 2,
      "z": 1,
      "name": "Empty",
      "level": 0
    },
    {
      "x": 0,
      "y": 3,
      "z": 1,
      "name": "Empty",
      "level": 0
    },
    {
      "x": 0,
      "y": 4,
      "z": 1,
      "name": "Empty",
      "level": 0
    },
    {
      "x": 0,
      "y": 5,
      "z": 1,
      "name": "Empty",
      "level": 0
    },
    {
      "x": 0,
      "y": 6,
      "z": 1,
      "name": "Empty",
      "level": 0
    },
    {
      "x": 0,
      "y": 7,
      "z": 1,
      "name": "Empty",
      "level": 0
    },
    {
      "x": 0,
      "y": 8,
      "z": 1,
      "name": "Empty",
      "level": 0
    },
    {
      "x": 0,
      "y": 9,
      "z": 1,
      "name": "Empty",
      "level": 0
    },
    {
      "x": 0,
      "y": 10,
      "z": 1,
      "name": "Empty",
      "level": 0
    },
    {
      "x": 0,
      "y": 11,
      "z": 1,
      "name": "Empty",
      "level": 0
    },
    {
      "x": 0,
      "y": 12,
      "z": 1,
      "name": "Empty",
      "level": 0
    },
    {
      "x": 0,
      "y": 13,
      "z": 1,
      "name": "Empty",
      "level": 0
    },
    {
      "x": 0,
      "y": 14,
      "z": 1,
      "name": "Empty",
      "level": 0
    },
    {
      "x": 0,
      "y": 15,
      "z": 1,
      "name": "Empty",
      "level": 0
    },
    {
      "x": 0,
      "y": 25,
      "z": 1,
      "name": "Empty",
      "level": 0
    },
    {
      "x": 0,
      "y": 26,
      "z": 1,
      "name": "Empty",
      "level": 0
    },
    {
      "x": 0,
      "y": 27,
      "z": 1,
      "name": "Empty",
      "level": 0
    },
    {
      "x": 0,
      "y": 0,
      "z": 2,
      "name": "Empty",
      "level": 0
    },
    {
      "x": 0,
      "y": 1,
      "z": 2,
      "name": "Empty",
      "level": 0
    },
    {
      "x": 0,
      "y": 2,
      "z": 2,
      "name": "Empty",
      "level": 0
    },
    {
      "x": 0,
      "y": 3,
      "z": 2,
      "name": "Empty",
      "level": 0
    },
    {
      "x": 0,
      "y": 4,
      "z": 2,
      "name": "Empty",
      "level": 0
    },
    {
      "x": 0,
      "y": 5,
      "z": 2,
      "name": "Empty",
      "level": 0
    },
    {
      "x": 0,
      "y": 6,
      "z": 2,
      "name": "Empty",
      "level": 0
    },
    {
      "x": 0,
      "y": 7,
      "z": 2,
      "name": "Empty",
      "level": 0
    },
    {
      "x": 0,
      "y": 8,
      "z": 2,
      "name": "Empty",
      "level": 0
    },
    {
      "x": 0,
      "y": 9,
      "z": 2,
      "name": "Empty",
      "level": 0
    },
    {
      "x": 0,
      "y": 25,
      "z": 2,
      "name": "Empty",
      "level": 0
    },
    {
      "x": 0,
      "y": 8,
      "z": 3,
      "name": "Empty",
      "level": 0
    },
    {
      "x": 0,
      "y": 9,
      "z": 3,
      "name": "Empty",
      "level": 0
    },
    {
      "x": 0,
      "y": 10,
      "z": 3,
      "name": "Empty",
      "level": 0
    },
    {
      "x": 0,
      "y": 11,
      "z": 3,
      "name": "Empty",
      "level": 0
    },
    {
      "x": 0,
      "y": 12,
      "z": 3,
      "name": "Empty",
      "level": 0
    },
    {
      "x": 0,
      "y": 13,
      "z": 3,
      "name": "Empty",
      "level": 0
    },
    {
      "x": 0,
      "y": 13,
      "z": 4,
      "name": "Empty",
      "level": 0
    },
    {
      "x": 0,
      "y": 14,
      "z": 4,
      "name": "Empty",
      "level": 0
    },
    {
      "x": 0,
      "y": 15,
      "z": 4,
      "name": "Empty",
      "level": 0
    },
    {
      "x": 0,
      "y": 16,
      "z": 4,
      "name": "Empty",
      "level": 0
    },
    {
      "x": 1,
      "y": 22,
      "z": -7,
      "name": "Empty",
      "level": 0
    },
    {
      "x": 1,
      "y": 23,
      "z": -7,
      "name": "Empty",
      "level": 0
    },
    {
      "x": 1,
      "y": 24,
      "z": -7,
      "name": "Empty",
      "level": 0
    },
    {
      "x": 1,
      "y": 25,
      "z": -7,
      "name": "Empty",
      "level": 0
    },
    {
      "x": 1,
      "y": 24,
      "z": -6,
      "name": "Empty",
      "level": 0
    },
    {
      "x": 1,
      "y": 25,
      "z": -6,
      "name": "Empty",
      "level": 0
    },
    {
      "x": 1,
      "y": 26,
      "z": -6,
      "name": "Empty",
      "level": 0
    },
    {
      "x": 1,
      "y": 22,
      "z": -5,
      "name": "Empty",
      "level": 0
    },
    {
      "x": 1,
      "y": 23,
      "z": -5,
      "name": "Empty",
      "level": 0
    },
    {
      "x": 1,
      "y": 24,
      "z": -5,
      "name": "Empty",
      "level": 0
