{
  "version": 8,
  "blockIdVersion": 11,
  "anchorX": 0,
  "anchorY": 1,
  "anchorZ": 0,
  "blocks": [
    {
      "x": -22,
      "y": 1,
      "z": -22,
      "name": "Cloth_Block_Wool_Purple"
    },
    {
      "x": -22,
      "y": 2,
      "z": -22,
      "name": "Cloth_Block_Wool_Purple"
    },
    {
      "x": -22,
      "y": 3,
      "z": -22,
      "name": "Cloth_Block_Wool_Purple"
    },
    {
      "x": -22,
      "y": 4,
      "z": -22,
      "name": "Cloth_Block_Wool_Purple"
    },
    {
      "x": -22,
      "y": 5,
      "z": -22,
      "name": "Cloth_Block_Wool_Purple"
    },
    {
      "x": -22,
      "y": 6,
      "z": -22,
      "name": "Cloth_Block_Wool_Purple"
    },
    {
      "x": -22,
      "y": 7,
      "z": -22,
      "name": "Cloth_Block_Wool_Purple"
    },
    {
      "x": -22,
      "y": 8,
      "z": -22,
      "name": "Cloth_Block_Wool_Purple"
    },
    {
      "x": -22,
      "y": 1,
      "z": -21,
      "name": "Cloth_Block_Wool_Purple"
    },
    {
      "x": -22,
      "y": 2,
      "z": -21,
      "name": "Cloth_Block_Wool_Purple"
    },
    {
      "x": -22,
      "y": 3,
      "z": -21,
      "name": "Cloth_Block_Wool_Purple"
    },
    {
      "x": -22,
      "y": 4,
      "z": -21,
      "name": "Cloth_Block_Wool_Purple"
    },
    {
      "x": -22,
      "y": 5,
      "z": -21,
      "name": "Cloth_Block_Wool_Purple"
    },
    {
      "x": -22,
      "y": 6,
      "z": -21,
      "name": "Cloth_Block_Wool_Purple"
    },
    {
      "x": -22,
      "y": 7,
      "z": -21,
      "name": "Cloth_Block_Wool_Purple"
    },
    {
      "x": -22,
      "y": 8,
      "z": -21,
      "name": "Cloth_Block_Wool_Purple"
    },
    {
      "x": -22,
      "y": 1,
      "z": -20,
      "name": "Cloth_Block_Wool_Purple"
    },
    {
      "x": -22,
      "y": 2,
      "z": -20,
      "name": "Cloth_Block_Wool_Purple"
    },
    {
      "x": -22,
      "y": 3,
      "z": -20,
      "name": "Cloth_Block_Wool_Purple"
    },
    {
      "x": -22,
      "y": 4,
      "z": -20,
      "name": "Cloth_Block_Wool_Purple"
    },
    {
      "x": -22,
      "y": 5,
      "z": -20,
      "name": "Cloth_Block_Wool_Purple"
    },
    {
      "x": -22,
      "y": 6,
      "z": -20,
      "name": "Cloth_Block_Wool_Purple"
    },
    {
      "x": -22,
      "y": 7,
      "z": -20,
      "name": "Cloth_Block_Wool_Purple"
    },
    {
      "x": -22,
      "y": 8,
      "z": -20,
      "name": "Cloth_Block_Wool_Purple"
    },
    {
      "x": -22,
      "y": 1,
      "z": -19,
      "name": "Cloth_Block_Wool_Purple"
    },
    {
      "x": -22,
      "y": 2,
      "z": -19,
      "name": "Cloth_Block_Wool_Purple"
    },
    {
      "x": -22,
      "y": 3,
      "z": -19,
      "name": "Cloth_Block_Wool_Purple"
    },
    {
      "x": -22,
      "y": 4,
      "z": -19,
      "name": "Cloth_Block_Wool_Purple"
    },
    {
      "x": -22,
      "y": 5,
      "z": -19,
      "name": "Cloth_Block_Wool_Purple"
    },
    {
      "x": -22,
      "y": 6,
      "z": -19,
      "name": "Cloth_Block_Wool_Purple"
    },
    {
      "x": -22,
      "y": 7,
      "z": -19,
      "name": "Cloth_Block_Wool_Purple"
    },
    {
      "x": -22,
      "y": 8,
      "z": -19,
      "name": "Cloth_Block_Wool_Purple"
    },
    {
      "x": -22,
      "y": 1,
      "z": -18,
      "name": "Cloth_Block_Wool_Purple"
    },
    {
      "x": -22,
      "y": 2,
      "z": -18,
      "name": "Cloth_Block_Wool_Purple"
    },
    {
      "x": -22,
      "y": 3,
      "z": -18,
      "name": "Cloth_Block_Wool_Purple"
    },
    {
      "x": -22,
      "y": 4,
      "z": -18,
      "name": "Cloth_Block_Wool_Purple"
    },
    {
      "x": -22,
      "y": 5,
      "z": -18,
      "name": "Cloth_Block_Wool_Purple"
    },
    {
      "x": -22,
      "y": 6,
      "z": -18,
      "name": "Cloth_Block_Wool_Purple"
    },
    {
      "x": -22,
      "y": 7,
      "z": -18,
      "name": "Cloth_Block_Wool_Purple"
    },
    {
      "x": -22,
      "y": 8,
      "z": -18,
      "name": "Cloth_Block_Wool_Purple"
    },
    {
      "x": -22,
      "y": 1,
      "z": -17,
      "name": "Cloth_Block_Wool_Purple"
    },
    {
      "x": -22,
      "y": 2,
      "z": -17,
      "name": "Cloth_Block_Wool_Purple"
    },
    {
      "x": -22,
      "y": 3,
      "z": -17,
      "name": "Cloth_Block_Wool_Purple"
    },
    {
      "x": -22,
      "y": 4,
      "z": -17,
      "name": "Cloth_Block_Wool_Purple"
    },
    {
      "x": -22,
      "y": 5,
      "z": -17,
      "name": "Cloth_Block_Wool_Purple"
    },
    {
      "x": -22,
      "y": 6,
      "z": -17,
      "name": "Cloth_Block_Wool_Purple"
    },
    {
      "x": -22,
      "y": 7,
      "z": -17,
      "name": "Cloth_Block_Wool_Purple"
    },
    {
      "x": -22,
      "y": 8,
      "z": -17,
      "name": "Cloth_Block_Wool_Purple"
    },
    {
      "x": -22,
      "y": 1,
      "z": -16,
      "name": "Cloth_Block_Wool_Purple"
    },
    {
      "x": -22,
      "y": 2,
      "z": -16,
      "name": "Cloth_Block_Wool_Purple"
    },
    {
      "x": -22,
      "y": 3,
      "z": -16,
      "name": "Cloth_Block_Wool_Purple"
    },
    {
      "x": -22,
      "y": 4,
      "z": -16,
      "name": "Cloth_Block_Wool_Purple"
    },
    {
      "x": -22,
      "y": 5,
      "z": -16,
      "name": "Cloth_Block_Wool_Purple"
    },
    {
      "x": -22,
      "y": 6,
      "z": -16,
      "name": "Cloth_Block_Wool_Purple"
    },
    {
      "x": -22,
      "y": 7,
      "z": -16,
      "name": "Cloth_Block_Wool_Purple"
    },
    {
      "x": -22,
      "y": 8,
      "z": -16,
      "name": "Cloth_Block_Wool_Purple"
    },
    {
      "x": -22,
      "y": 1,
      "z": -15,
      "name": "Cloth_Block_Wool_Purple"
    },
    {
      "x": -22,
      "y": 2,
      "z": -15,
      "name": "Cloth_Block_Wool_Purple"
    },
    {
      "x": -22,
      "y": 3,
      "z": -15,
      "name": "Cloth_Block_Wool_Purple"
    },
    {
      "x": -22,
      "y": 4,
      "z": -15,
      "name": "Cloth_Block_Wool_Purple"
    },
    {
      "x": -22,
      "y": 5,
      "z": -15,
      "name": "Cloth_Block_Wool_Purple"
    },
    {
      "x": -22,
      "y": 6,
      "z": -15,
      "name": "Cloth_Block_Wool_Purple"
    },
    {
      "x": -22,
      "y": 7,
      "z": -15,
      "name": "Cloth_Block_Wool_Purple"
    },
    {
      "x": -22,
      "y": 8,
      "z": -15,
      "name": "Cloth_Block_Wool_Purple"
    },
    {
      "x": -22,
      "y": 1,
      "z": -14,
      "name": "Cloth_Block_Wool_Purple"
    },
    {
      "x": -22,
      "y": 2,
      "z": -14,
      "name": "Cloth_Block_Wool_Purple"
    },
    {
      "x": -22,
      "y": 3,
      "z": -14,
      "name": "Cloth_Block_Wool_Purple"
    },
    {
      "x": -22,
      "y": 4,
      "z": -14,
      "name": "Cloth_Block_Wool_Purple"
    },
    {
      "x": -22,
      "y": 5,
      "z": -14,
      "name": "Cloth_Block_Wool_Purple"
    },
    {
      "x": -22,
      "y": 6,
      "z": -14,
      "name": "Cloth_Block_Wool_Purple"
    },
    {
      "x": -22,
      "y": 7,
      "z": -14,
      "name": "Cloth_Block_Wool_Purple"
    },
    {
      "x": -22,
      "y": 8,
      "z": -14,
      "name": "Cloth_Block_Wool_Purple"
    },
    {
      "x": -22,
      "y": 1,
      "z": -13,
      "name": "Cloth_Block_Wool_Purple"
    },
    {
      "x": -22,
      "y": 2,
      "z": -13,
      "name": "Cloth_Block_Wool_Purple"
    },
    {
      "x": -22,
      "y": 3,
      "z": -13,
      "name": "Cloth_Block_Wool_Purple"
    },
    {
      "x": -22,
      "y": 4,
      "z": -13,
      "name": "Cloth_Block_Wool_Purple"
    },
    {
      "x": -22,
      "y": 5,
      "z": -13,
      "name": "Cloth_Block_Wool_Purple"
    },
    {
      "x": -22,
      "y": 6,
      "z": -13,
      "name": "Cloth_Block_Wool_Purple"
    },
    {
      "x": -22,
      "y": 7,
      "z": -13,
      "name": "Cloth_Block_Wool_Purple"
    },
    {
      "x": -22,
      "y": 8,
      "z": -13,
      "name": "Cloth_Block_Wool_Purple"
    },
    {
      "x": -22,
      "y": 1,
      "z": -12,
      "name": "Cloth_Block_Wool_Purple"
    },
    {
      "x": -22,
      "y": 2,
      "z": -12,
      "name": "Cloth_Block_Wool_Purple"
    },
    {
      "x": -22,
      "y": 3,
      "z": -12,
      "name": "Cloth_Block_Wool_Purple"
    },
    {
      "x": -22,
      "y": 4,
      "z": -12,
      "name": "Cloth_Block_Wool_Purple"
    },
    {
      "x": -22,
      "y": 5,
      "z": -12,
      "name": "Cloth_Block_Wool_Purple"
    },
    {
      "x": -22,
      "y": 6,
      "z": -12,
      "name": "Cloth_Block_Wool_Purple"
    },
    {
      "x": -22,
      "y": 7,
      "z": -12,
      "name": "Cloth_Block_Wool_Purple"
    },
    {
      "x": -22,
      "y": 8,
      "z": -12,
      "name": "Cloth_Block_Wool_Purple"
    },
    {
      "x": -22,
      "y": 1,
      "z": -11,
      "name": "Cloth_Block_Wool_Purple"
    },
    {
      "x": -22,
      "y": 2,
      "z": -11,
      "name": "Cloth_Block_Wool_Purple"
    },
    {
      "x": -22,
      "y": 3,
      "z": -11,
      "name": "Cloth_Block_Wool_Purple"
    },
    {
      "x": -22,
      "y": 4,
      "z": -11,
      "name": "Cloth_Block_Wool_Purple"
    },
    {
      "x": -22,
      "y": 5,
      "z": -11,
      "name": "Cloth_Block_Wool_Purple"
    },
    {
      "x": -22,
      "y": 6,
      "z": -11,
      "name": "Cloth_Block_Wool_Purple"
    },
    {
      "x": -22,
      "y": 7,
      "z": -11,
      "name": "Cloth_Block_Wool_Purple"
    },
    {
      "x": -22,
      "y": 8,
      "z": -11,
      "name": "Cloth_Block_Wool_Purple"
    },
    {
      "x": -22,
      "y": 1,
      "z": -10,
      "name": "Cloth_Block_Wool_Purple"
    },
    {
      "x": -22,
      "y": 2,
      "z": -10,
      "name": "Cloth_Block_Wool_Purple"
    },
    {
      "x": -22,
      "y": 3,
      "z": -10,
      "name": "Cloth_Block_Wool_Purple"
    },
    {
      "x": -22,
      "y": 4,
      "z": -10,
      "name": "Cloth_Block_Wool_Purple"
    },
    {
      "x": -22,
      "y": 5,
      "z": -10,
      "name": "Cloth_Block_Wool_Purple"
    },
    {
      "x": -22,
      "y": 6,
      "z": -10,
      "name": "Cloth_Block_Wool_Purple"
    },
    {
      "x": -22,
      "y": 7,
      "z": -10,
      "name": "Cloth_Block_Wool_Purple"
    },
    {
      "x": -22,
      "y": 8,
      "z": -10,
      "name": "Cloth_Block_Wool_Purple"
    },
    {
      "x": -22,
      "y": 1,
      "z": -9,
      "name": "Cloth_Block_Wool_Purple"
    },
    {
      "x": -22,
      "y": 2,
      "z": -9,
      "name": "Cloth_Block_Wool_Purple"
    },
    {
      "x": -22,
      "y": 3,
      "z": -9,
      "name": "Cloth_Block_Wool_Purple"
    },
    {
      "x": -22,
      "y": 4,
      "z": -9,
      "name": "Cloth_Block_Wool_Purple"
    },
    {
      "x": -22,
      "y": 5,
      "z": -9,
      "name": "Cloth_Block_Wool_Purple"
    },
    {
      "x": -22,
      "y": 6,
      "z": -9,
      "name": "Cloth_Block_Wool_Purple"
    },
    {
      "x": -22,
      "y": 7,
      "z": -9,
      "name": "Cloth_Block_Wool_Purple"
    },
    {
      "x": -22,
      "y": 8,
      "z": -9,
      "name": "Cloth_Block_Wool_Purple"
    },
    {
      "x": -22,
      "y": 1,
      "z": -8,
      "name": "Cloth_Block_Wool_Purple"
    },
    {
      "x": -22,
      "y": 2,
      "z": -8,
      "name": "Cloth_Block_Wool_Purple"
    },
    {
      "x": -22,
      "y": 3,
      "z": -8,
      "name": "Cloth_Block_Wool_Purple"
    },
    {
      "x": -22,
      "y": 4,
      "z": -8,
      "name": "Cloth_Block_Wool_Purple"
    },
    {
      "x": -22,
      "y": 5,
      "z": -8,
      "name": "Cloth_Block_Wool_Purple"
    },
    {
      "x": -22,
      "y": 6,
      "z": -8,
      "name": "Cloth_Block_Wool_Purple"
    },
    {
      "x": -22,
      "y": 7,
      "z": -8,
      "name": "Cloth_Block_Wool_Purple"
    },
    {
      "x": -22,
      "y": 8,
      "z": -8,
      "name": "Cloth_Block_Wool_Purple"
    },
    {
      "x": -22,
      "y": 1,
      "z": -7,
      "name": "Cloth_Block_Wool_Purple"
    },
    {
      "x": -22,
      "y": 2,
      "z": -7,
      "name": "Cloth_Block_Wool_Purple"
    },
    {
      "x": -22,
      "y": 3,
      "z": -7,
      "name": "Cloth_Block_Wool_Purple"
    },
    {
      "x": -22,
      "y": 4,
      "z": -7,
      "name": "Cloth_Block_Wool_Purple"
    },
    {
      "x": -22,
      "y": 5,
      "z": -7,
      "name": "Cloth_Block_Wool_Purple"
    },
    {
      "x": -22,
      "y": 6,
      "z": -7,
      "name": "Cloth_Block_Wool_Purple"
    },
    {
      "x": -22,
      "y": 7,
      "z": -7,
      "name": "Cloth_Block_Wool_Purple"
    },
    {
      "x": -22,
      "y": 8,
      "z": -7,
      "name": "Cloth_Block_Wool_Purple"
    },
    {
      "x": -22,
      "y": 1,
      "z": -6,
      "name": "Cloth_Block_Wool_Purple"
    },
    {
      "x": -22,
      "y": 2,
      "z": -6,
      "name": "Cloth_Block_Wool_Purple"
    },
    {
      "x": -22,
      "y": 3,
      "z": -6,
      "name": "Cloth_Block_Wool_Purple"
    },
    {
      "x": -22,
      "y": 4,
      "z": -6,
      "name": "Cloth_Block_Wool_Purple"
    },
    {
      "x": -22,
      "y": 5,
      "z": -6,
      "name": "Cloth_Block_Wool_Purple"
    },
    {
      "x": -22,
      "y": 6,
      "z": -6,
      "name": "Cloth_Block_Wool_Purple"
    },
    {
      "x": -22,
      "y": 7,
      "z": -6,
      "name": "Cloth_Block_Wool_Purple"
    },
    {
      "x": -22,
      "y": 8,
      "z": -6,
      "name": "Cloth_Block_Wool_Purple"
    },
    {
      "x": -22,
      "y": 1,
      "z": -5,
      "name": "Cloth_Block_Wool_Purple"
    },
    {
      "x": -22,
      "y": 2,
      "z": -5,
      "name": "Cloth_Block_Wool_Purple"
    },
    {
      "x": -22,
      "y": 3,
      "z": -5,
      "name": "Cloth_Block_Wool_Purple"
    },
    {
      "x": -22,
      "y": 4,
      "z": -5,
      "name": "Cloth_Block_Wool_Purple"
    },
    {
      "x": -22,
      "y": 5,
      "z": -5,
      "name": "Cloth_Block_Wool_Purple"
    },
    {
      "x": -22,
      "y": 6,
      "z": -5,
      "name": "Cloth_Block_Wool_Purple"
    },
    {
      "x": -22,
      "y": 7,
      "z": -5,
      "name": "Cloth_Block_Wool_Purple"
    },
    {
      "x": -22,
      "y": 8,
      "z": -5,
      "name": "Cloth_Block_Wool_Purple"
    },
    {
      "x": -22,
      "y": 1,
      "z": -4,
      "name": "Cloth_Block_Wool_Purple"
    },
    {
      "x": -22,
      "y": 2,
      "z": -4,
      "name": "Cloth_Block_Wool_Purple"
    },
    {
      "x": -22,
      "y": 3,
      "z": -4,
      "name": "Cloth_Block_Wool_Purple"
    },
    {
      "x": -22,
      "y": 4,
      "z": -4,
      "name": "Cloth_Block_Wool_Purple"
    },
    {
      "x": -22,
      "y": 5,
      "z": -4,
      "name": "Cloth_Block_Wool_Purple"
    },
    {
      "x": -22,
      "y": 6,
      "z": -4,
      "name": "Cloth_Block_Wool_Purple"
    },
    {
      "x": -22,
      "y": 7,
      "z": -4,
      "name": "Cloth_Block_Wool_Purple"
    },
    {
      "x": -22,
      "y": 8,
      "z": -4,
      "name": "Cloth_Block_Wool_Purple"
    },
    {
      "x": -22,
      "y": 1,
      "z": -3,
      "name": "Cloth_Block_Wool_Purple"
    },
    {
      "x": -22,
      "y": 2,
      "z": -3,
      "name": "Cloth_Block_Wool_Purple"
    },
    {
      "x": -22,
      "y": 3,
      "z": -3,
      "name": "Cloth_Block_Wool_Purple"
    },
    {
      "x": -22,
      "y": 4,
      "z": -3,
      "name": "Cloth_Block_Wool_Purple"
    },
    {
      "x": -22,
      "y": 5,
      "z": -3,
      "name": "Cloth_Block_Wool_Purple"
    },
    {
      "x": -22,
      "y": 6,
      "z": -3,
      "name": "Cloth_Block_Wool_Purple"
    },
    {
      "x": -22,
      "y": 7,
      "z": -3,
      "name": "Cloth_Block_Wool_Purple"
    },
    {
      "x": -22,
      "y": 8,
      "z": -3,
      "name": "Cloth_Block_Wool_Purple"
    },
    {
      "x": -22,
      "y": 1,
      "z": -2,
      "name": "Cloth_Block_Wool_Purple"
    },
    {
      "x": -22,
      "y": 2,
      "z": -2,
      "name": "Cloth_Block_Wool_Purple"
    },
    {
      "x": -22,
      "y": 3,
      "z": -2,
      "name": "Cloth_Block_Wool_Purple"
    },
    {
      "x": -22,
      "y": 4,
      "z": -2,
      "name": "Cloth_Block_Wool_Purple"
    },
    {
      "x": -22,
      "y": 5,
      "z": -2,
      "name": "Cloth_Block_Wool_Purple"
    },
    {
      "x": -22,
      "y": 6,
      "z": -2,
      "name": "Cloth_Block_Wool_Purple"
    },
    {
      "x": -22,
      "y": 7,
      "z": -2,
      "name": "Cloth_Block_Wool_Purple"
    },
    {
      "x": -22,
      "y": 8,
      "z": -2,
      "name": "Cloth_Block_Wool_Purple"
    },
    {
      "x": -22,
      "y": 1,
      "z": -1,
      "name": "Cloth_Block_Wool_Purple"
    },
    {
      "x": -22,
      "y": 2,
      "z": -1,
      "name": "Cloth_Block_Wool_Purple"
    },
    {
      "x": -22,
      "y": 3,
      "z": -1,
      "name": "Cloth_Block_Wool_Purple"
    },
    {
      "x": -22,
      "y": 4,
      "z": -1,
      "name": "Cloth_Block_Wool_Purple"
    },
    {
      "x": -22,
      "y": 5,
      "z": -1,
      "name": "Cloth_Block_Wool_Purple"
    },
    {
      "x": -22,
      "y": 6,
      "z": -1,
      "name": "Cloth_Block_Wool_Purple"
    },
    {
      "x": -22,
      "y": 7,
      "z": -1,
      "name": "Cloth_Block_Wool_Purple"
    },
    {
      "x": -22,
      "y": 8,
      "z": -1,
      "name": "Cloth_Block_Wool_Purple"
    },
    {
      "x": -22,
      "y": 1,
      "z": 0,
      "name": "Cloth_Block_Wool_Purple"
    },
    {
      "x": -22,
      "y": 2,
      "z": 0,
      "name": "Cloth_Block_Wool_Purple"
    },
    {
      "x": -22,
      "y": 3,
      "z": 0,
      "name": "Cloth_Block_Wool_Purple"
    },
    {
      "x": -22,
      "y": 4,
      "z": 0,
      "name": "Cloth_Block_Wool_Purple"
    },
    {
      "x": -22,
      "y": 5,
      "z": 0,
      "name": "Cloth_Block_Wool_Purple"
    },
    {
      "x": -22,
      "y": 6,
      "z": 0,
      "name": "Cloth_Block_Wool_Purple"
    },
    {
      "x": -22,
      "y": 7,
      "z": 0,
      "name": "Cloth_Block_Wool_Purple"
    },
    {
      "x": -22,
      "y": 8,
      "z": 0,
      "name": "Cloth_Block_Wool_Purple"
    },
    {
      "x": -21,
      "y": 1,
      "z": -22,
      "name": "Cloth_Block_Wool_Purple"
    },
    {
      "x": -21,
      "y": 2,
      "z": -22,
      "name": "Cloth_Block_Wool_Purple"
    },
    {
      "x": -21,
      "y": 3,
      "z": -22,
      "name": "Cloth_Block_Wool_Purple"
    },
    {
      "x": -21,
      "y": 4,
      "z": -22,
      "name": "Cloth_Block_Wool_Purple"
    },
    {
      "x": -21,
      "y": 5,
      "z": -22,
      "name": "Cloth_Block_Wool_Purple"
    },
    {
      "x": -21,
      "y": 6,
      "z": -22,
      "name": "Cloth_Block_Wool_Purple"
    },
    {
      "x": -21,
      "y": 7,
      "z": -22,
      "name": "Cloth_Block_Wool_Purple"
    },
    {
      "x": -21,
      "y": 8,
      "z": -22,
      "name": "Cloth_Block_Wool_Purple"
    },
    {
      "x": -21,
      "y": 1,
      "z": -21,
      "name": "Cloth_Block_Wool_Purple"
    },
    {
      "x": -21,
      "y": 2,
      "z": -21,
      "name": "Cloth_Block_Wool_Purple"
    },
    {
      "x": -21,
      "y": 3,
      "z": -21,
      "name": "Cloth_Block_Wool_Purple"
    },
    {
      "x": -21,
      "y": 4,
      "z": -21,
      "name": "Cloth_Block_Wool_Purple"
    },
    {
      "x": -21,
      "y": 5,
      "z": -21,
      "name": "Cloth_Block_Wool_Purple"
    },
    {
      "x": -21,
      "y": 6,
      "z": -21,
      "name": "Cloth_Block_Wool_Purple"
    },
    {
      "x": -21,
      "y": 7,
      "z": -21,
      "name": "Cloth_Block_Wool_Purple"
    },
    {
      "x": -21,
      "y": 8,
      "z": -21,
      "name": "Cloth_Block_Wool_Purple"
    },
    {
      "x": -21,
      "y": 1,
      "z": -20,
      "name": "Cloth_Block_Wool_Purple"
    },
    {
      "x": -21,
      "y": 2,
      "z": -20,
      "name": "Cloth_Block_Wool_Purple"
    },
    {
      "x": -21,
      "y": 3,
      "z": -20,
      "name": "Cloth_Block_Wool_Purple"
    },
    {
      "x": -21,
      "y": 4,
      "z": -20,
      "name": "Cloth_Block_Wool_Purple"
    },
    {
      "x": -21,
      "y": 5,
      "z": -20,
      "name": "Cloth_Block_Wool_Purple"
    },
    {
      "x": -21,
      "y": 6,
      "z": -20,
      "name": "Cloth_Block_Wool_Purple"
    },
    {
      "x": -21,
      "y": 7,
      "z": -20,
      "name": "Cloth_Block_Wool_Purple"
    },
    {
      "x": -21,
      "y": 8,
      "z": -20,
      "name": "Cloth_Block_Wool_Purple"
    },
    {
      "x": -21,
      "y": 1,
      "z": -19,
      "name": "Cloth_Block_Wool_Purple"
    },
    {
      "x": -21,
      "y": 2,
      "z": -19,
      "name": "Cloth_Block_Wool_Purple"
    },
    {
      "x": -21,
      "y": 3,
      "z": -19,
      "name": "Cloth_Block_Wool_Purple"
    },
    {
      "x": -21,
      "y": 4,
      "z": -19,
      "name": "Cloth_Block_Wool_Purple"
    },
    {
      "x": -21,
      "y": 5,
      "z": -19,
      "name": "Cloth_Block_Wool_Purple"
    },
    {
      "x": -21,
      "y": 6,
      "z": -19,
      "name": "Cloth_Block_Wool_Purple"
    },
    {
      "x": -21,
      "y": 7,
      "z": -19,
      "name": "Cloth_Block_Wool_Purple"
    },
    {
      "x": -21,
      "y": 8,
      "z": -19,
      "name": "Cloth_Block_Wool_Purple"
    },
    {
      "x": -21,
      "y": 1,
      "z": -18,
      "name": "Cloth_Block_Wool_Purple"
    },
    {
      "x": -21,
      "y": 2,
      "z": -18,
      "name": "Cloth_Block_Wool_Purple"
    },
    {
      "x": -21,
      "y": 3,
      "z": -18,
      "name": "Cloth_Block_Wool_Purple"
    },
    {
      "x": -21,
      "y": 4,
      "z": -18,
      "name": "Cloth_Block_Wool_Purple"
    },
    {
      "x": -21,
      "y": 5,
      "z": -18,
      "name": "Cloth_Block_Wool_Purple"
    },
    {
      "x": -21,
      "y": 6,
      "z": -18,
      "name": "Cloth_Block_Wool_Purple"
    },
    {
      "x": -21,
      "y": 7,
      "z": -18,
      "name": "Cloth_Block_Wool_Purple"
    },
    {
      "x": -21,
      "y": 8,
      "z": -18,
      "name": "Cloth_Block_Wool_Purple"
    },
    {
      "x": -21,
      "y": 1,
      "z": -17,
      "name": "Cloth_Block_Wool_Purple"
    },
    {
      "x": -21,
      "y": 2,
      "z": -17,
      "name": "Cloth_Block_Wool_Purple"
    },
    {
      "x": -21,
      "y": 3,
      "z": -17,
      "name": "Cloth_Block_Wool_Purple"
    },
    {
      "x": -21,
      "y": 4,
      "z": -17,
      "name": "Cloth_Block_Wool_Purple"
    },
    {
      "x": -21,
      "y": 5,
      "z": -17,
      "name": "Cloth_Block_Wool_Purple"
    },
    {
      "x": -21,
      "y": 6,
      "z": -17,
      "name": "Cloth_Block_Wool_Purple"
    },
    {
      "x": -21,
      "y": 7,
      "z": -17,
      "name": "Cloth_Block_Wool_Purple"
    },
    {
      "x": -21,
      "y": 8,
      "z": -17,
      "name": "Cloth_Block_Wool_Purple"
    },
    {
      "x": -21,
      "y": 1,
      "z": -16,
      "name": "Cloth_Block_Wool_Purple"
    },
    {
      "x": -21,
      "y": 2,
      "z": -16,
      "name": "Cloth_Block_Wool_Purple"
    },
    {
      "x": -21,
      "y": 3,
      "z": -16,
      "name": "Cloth_Block_Wool_Purple"
    },
    {
      "x": -21,
      "y": 4,
      "z": -16,
      "name": "Cloth_Block_Wool_Purple"
    },
    {
      "x": -21,
      "y": 5,
      "z": -16,
      "name": "Cloth_Block_Wool_Purple"
    },
    {
      "x": -21,
      "y": 6,
      "z": -16,
      "name": "Cloth_Block_Wool_Purple"
    },
    {
      "x": -21,
      "y": 7,
      "z": -16,
      "name": "Cloth_Block_Wool_Purple"
    },
    {
      "x": -21,
      "y": 8,
      "z": -16,
      "name": "Cloth_Block_Wool_Purple"
    },
    {
      "x": -21,
      "y": 1,
      "z": -15,
      "name": "Cloth_Block_Wool_Purple"
    },
    {
      "x": -21,
      "y": 2,
      "z": -15,
      "name": "Cloth_Block_Wool_Purple"
    },
    {
      "x": -21,
      "y": 3,
      "z": -15,
      "name": "Cloth_Block_Wool_Purple"
    },
    {
      "x": -21,
      "y": 4,
      "z": -15,
      "name": "Cloth_Block_Wool_Purple"
    },
    {
      "x": -21,
      "y": 5,
      "z": -15,
      "name": "Cloth_Block_Wool_Purple"
    },
    {
      "x": -21,
      "y": 6,
      "z": -15,
      "name": "Cloth_Block_Wool_Purple"
    },
    {
      "x": -21,
      "y": 7,
      "z": -15,
      "name": "Cloth_Block_Wool_Purple"
    },
    {
      "x": -21,
      "y": 8,
      "z": -15,
      "name": "Cloth_Block_Wool_Purple"
    },
    {
      "x": -21,
      "y": 1,
      "z": -14,
      "name": "Cloth_Block_Wool_Purple"
    },
    {
      "x": -21,
      "y": 2,
      "z": -14,
      "name": "Cloth_Block_Wool_Purple"
    },
    {
      "x": -21,
      "y": 3,
      "z": -14,
      "name": "Cloth_Block_Wool_Purple"
    },
    {
      "x": -21,
      "y": 4,
      "z": -14,
      "name": "Cloth_Block_Wool_Purple"
    },
    {
      "x": -21,
      "y": 5,
      "z": -14,
      "name": "Cloth_Block_Wool_Purple"
    },
    {
      "x": -21,
      "y": 6,
      "z": -14,
      "name": "Cloth_Block_Wool_Purple"
    },
    {
      "x": -21,
      "y": 7,
      "z": -14,
      "name": "Cloth_Block_Wool_Purple"
    },
    {
      "x": -21,
      "y": 8,
      "z": -14,
      "name": "Cloth_Block_Wool_Purple"
    },
    {
      "x": -21,
      "y": 1,
      "z": -13,
      "name": "Cloth_Block_Wool_Purple"
    },
    {
      "x": -21,
      "y": 2,
      "z": -13,
      "name": "Cloth_Block_Wool_Purple"
    },
    {
      "x": -21,
      "y": 3,
      "z": -13,
      "name": "Cloth_Block_Wool_Purple"
    },
    {
      "x": -21,
      "y": 4,
      "z": -13,
      "name": "Cloth_Block_Wool_Purple"
    },
    {
      "x": -21,
      "y": 5,
      "z": -13,
      "name": "Cloth_Block_Wool_Purple"
    },
    {
      "x": -21,
      "y": 6,
      "z": -13,
      "name": "Cloth_Block_Wool_Purple"
    },
    {
      "x": -21,
      "y": 7,
      "z": -13,
      "name": "Cloth_Block_Wool_Purple"
    },
    {
      "x": -21,
      "y": 8,
      "z": -13,
      "name": "Cloth_Block_Wool_Purple"
    },
    {
      "x": -21,
      "y": 1,
      "z": -12,
      "name": "Cloth_Block_Wool_Purple"
    },
    {
      "x": -21,
      "y": 2,
      "z": -12,
      "name": "Cloth_Block_Wool_Purple"
    },
    {
      "x": -21,
      "y": 3,
      "z": -12,
      "name": "Cloth_Block_Wool_Purple"
    },
    {
      "x": -21,
      "y": 4,
      "z": -12,
      "name": "Cloth_Block_Wool_Purple"
    },
    {
      "x": -21,
      "y": 5,
      "z": -12,
      "name": "Cloth_Block_Wool_Purple"
    },
    {
      "x": -21,
      "y": 6,
      "z": -12,
      "name": "Cloth_Block_Wool_Purple"
    },
    {
      "x": -21,
      "y": 7,
      "z": -12,
      "name": "Cloth_Block_Wool_Purple"
    },
    {
      "x": -21,
      "y": 8,
      "z": -12,
      "name": "Cloth_Block_Wool_Purple"
    },
    {
      "x": -21,
      "y": 1,
      "z": -11,
      "name": "Cloth_Block_Wool_Purple"
    },
    {
      "x": -21,
      "y": 2,
      "z": -11,
      "name": "Cloth_Block_Wool_Purple"
    },
    {
      "x": -21,
      "y": 3,
      "z": -11,
      "name": "Cloth_Block_Wool_Purple"
    },
    {
      "x": -21,
      "y": 4,
      "z": -11,
      "name": "Cloth_Block_Wool_Purple"
    },
    {
      "x": -21,
      "y": 5,
      "z": -11,
      "name": "Cloth_Block_Wool_Purple"
    },
    {
      "x": -21,
      "y": 6,
      "z": -11,
      "name": "Cloth_Block_Wool_Purple"
    },
    {
      "x": -21,
      "y": 7,
      "z": -11,
      "name": "Cloth_Block_Wool_Purple"
    },
    {
      "x": -21,
      "y": 8,
      "z": -11,
      "name": "Cloth_Block_Wool_Purple"
    },
    {
      "x": -21,
      "y": 1,
      "z": -10,
      "name": "Cloth_Block_Wool_Purple"
    },
    {
      "x": -21,
      "y": 2,
      "z": -10,
      "name": "Cloth_Block_Wool_Purple"
    },
    {
      "x": -21,
      "y": 3,
      "z": -10,
      "name": "Cloth_Block_Wool_Purple"
    },
    {
      "x": -21,
      "y": 4,
      "z": -10,
      "name": "Cloth_Block_Wool_Purple"
    },
    {
      "x": -21,
      "y": 5,
      "z": -10,
      "name": "Cloth_Block_Wool_Purple"
    },
    {
      "x": -21,
      "y": 6,
      "z": -10,
      "name": "Cloth_Block_Wool_Purple"
    },
    {
      "x": -21,
      "y": 7,
      "z": -10,
      "name": "Cloth_Block_Wool_Purple"
    },
    {
      "x": -21,
      "y": 8,
      "z": -10,
      "name": "Cloth_Block_Wool_Purple"
    },
    {
      "x": -21,
      "y": 1,
      "z": -9,
      "name": "Cloth_Block_Wool_Purple"
    },
    {
      "x": -21,
      "y": 2,
      "z": -9,
      "name": "Cloth_Block_Wool_Purple"
    },
    {
      "x": -21,
      "y": 3,
      "z": -9,
      "name": "Cloth_Block_Wool_Purple"
    },
    {
      "x": -21,
      "y": 4,
      "z": -9,
      "name": "Cloth_Block_Wool_Purple"
    },
    {
      "x": -21,
      "y": 5,
      "z": -9,
      "name": "Cloth_Block_Wool_Purple"
    },
    {
      "x": -21,
      "y": 6,
      "z": -9,
      "name": "Cloth_Block_Wool_Purple"
    },
    {
      "x": -21,
      "y": 7,
      "z": -9,
      "name": "Cloth_Block_Wool_Purple"
    },
    {
      "x": -21,
      "y": 8,
      "z": -9,
      "name": "Cloth_Block_Wool_Purple"
    },
    {
      "x": -21,
      "y": 1,
      "z": -8,
      "name": "Cloth_Block_Wool_Purple"
    },
    {
      "x": -21,
      "y": 2,
      "z": -8,
      "name": "Cloth_Block_Wool_Purple"
    },
    {
      "x": -21,
      "y": 3,
      "z": -8,
      "name": "Cloth_Block_Wool_Purple"
    },
    {
      "x": -21,
      "y": 4,
      "z": -8,
      "name": "Cloth_Block_Wool_Purple"
    },
    {
      "x": -21,
      "y": 5,
      "z": -8,
      "name": "Cloth_Block_Wool_Purple"
    },
    {
      "x": -21,
      "y": 6,
      "z": -8,
      "name": "Cloth_Block_Wool_Purple"
    },
    {
      "x": -21,
      "y": 7,
      "z": -8,
      "name": "Cloth_Block_Wool_Purple"
    },
    {
      "x": -21,
      "y": 8,
      "z": -8,
      "name": "Cloth_Block_Wool_Purple"
    },
    {
      "x": -21,
      "y": 1,
      "z": -7,
      "name": "Cloth_Block_Wool_Purple"
    },
    {
      "x": -21,
      "y": 2,
      "z": -7,
      "name": "Cloth_Block_Wool_Purple"
    },
    {
      "x": -21,
      "y": 3,
      "z": -7,
      "name": "Cloth_Block_Wool_Purple"
    },
    {
      "x": -21,
      "y": 4,
      "z": -7,
      "name": "Cloth_Block_Wool_Purple"
    },
    {
      "x": -21,
      "y": 5,
      "z": -7,
      "name": "Cloth_Block_Wool_Purple"
    },
    {
      "x": -21,
      "y": 6,
      "z": -7,
      "name": "Cloth_Block_Wool_Purple"
    },
    {
      "x": -21,
      "y": 7,
      "z": -7,
      "name": "Cloth_Block_Wool_Purple"
    },
    {
      "x": -21,
      "y": 8,
      "z": -7,
      "name": "Cloth_Block_Wool_Purple"
    },
    {
      "x": -21,
      "y": 1,
      "z": -6,
      "name": "Cloth_Block_Wool_Purple"
    },
    {
      "x": -21,
      "y": 2,
      "z": -6,
      "name": "Cloth_Block_Wool_Purple"
    },
    {
      "x": -21,
      "y": 3,
      "z": -6,
      "name": "Cloth_Block_Wool_Purple"
    },
    {
      "x": -21,
      "y": 4,
      "z": -6,
      "name": "Cloth_Block_Wool_Purple"
    },
    {
      "x": -21,
      "y": 5,
      "z": -6,
      "name": "Cloth_Block_Wool_Purple"
    },
    {
      "x": -21,
      "y": 6,
      "z": -6,
      "name": "Cloth_Block_Wool_Purple"
    },
    {
      "x": -21,
      "y": 7,
      "z": -6,
      "name": "Cloth_Block_Wool_Purple"
    },
    {
      "x": -21,
      "y": 8,
      "z": -6,
      "name": "Cloth_Block_Wool_Purple"
    },
    {
      "x": -21,
      "y": 1,
      "z": -5,
      "name": "Cloth_Block_Wool_Purple"
    },
    {
      "x": -21,
      "y": 2,
      "z": -5,
      "name": "Cloth_Block_Wool_Purple"
    },
    {
      "x": -21,
      "y": 3,
      "z": -5,
      "name": "Cloth_Block_Wool_Purple"
    },
    {
      "x": -21,
      "y": 4,
      "z": -5,
      "name": "Cloth_Block_Wool_Purple"
    },
    {
      "x": -21,
      "y": 5,
      "z": -5,
      "name": "Cloth_Block_Wool_Purple"
    },
    {
      "x": -21,
      "y": 6,
      "z": -5,
      "name": "Cloth_Block_Wool_Purple"
    },
    {
      "x": -21,
      "y": 7,
      "z": -5,
      "name": "Cloth_Block_Wool_Purple"
    },
    {
      "x": -21,
      "y": 8,
      "z": -5,
      "name": "Cloth_Block_Wool_Purple"
    },
    {
      "x": -21,
      "y": 1,
      "z": -4,
      "name": "Cloth_Block_Wool_Purple"
    },
    {
      "x": -21,
      "y": 2,
      "z": -4,
      "name": "Cloth_Block_Wool_Purple"
    },
    {
      "x": -21,
      "y": 3,
      "z": -4,
      "name": "Cloth_Block_Wool_Purple"
    },
    {
      "x": -21,
      "y": 4,
      "z": -4,
      "name": "Cloth_Block_Wool_Purple"
    },
    {
      "x": -21,
      "y": 5,
      "z": -4,
      "name": "Cloth_Block_Wool_Purple"
    },
    {
      "x": -21,
      "y": 6,
      "z": -4,
      "name": "Cloth_Block_Wool_Purple"
    },
    {
      "x": -21,
      "y": 7,
      "z": -4,
      "name": "Cloth_Block_Wool_Purple"
    },
    {
      "x": -21,
      "y": 8,
      "z": -4,
      "name": "Cloth_Block_Wool_Purple"
    },
    {
      "x": -21,
      "y": 1,
      "z": -3,
      "name": "Cloth_Block_Wool_Purple"
    },
    {
      "x": -21,
      "y": 2,
      "z": -3,
      "name": "Cloth_Block_Wool_Purple"
    },
    {
      "x": -21,
      "y": 3,
      "z": -3,
      "name": "Cloth_Block_Wool_Purple"
    },
    {
      "x": -21,
      "y": 4,
      "z": -3,
      "name": "Cloth_Block_Wool_Purple"
    },
    {
      "x": -21,
      "y": 5,
      "z": -3,
      "name": "Cloth_Block_Wool_Purple"
    },
    {
      "x": -21,
      "y": 6,
      "z": -3,
      "name": "Cloth_Block_Wool_Purple"
    },
    {
      "x": -21,
      "y": 7,
      "z": -3,
      "name": "Cloth_Block_Wool_Purple"
    },
    {
      "x": -21,
      "y": 8,
      "z": -3,
      "name": "Cloth_Block_Wool_Purple"
    },
    {
      "x": -21,
      "y": 1,
      "z": -2,
      "name": "Cloth_Block_Wool_Purple"
    },
    {
      "x": -21,
      "y": 2,
      "z": -2,
      "name": "Cloth_Block_Wool_Purple"
    },
    {
      "x": -21,
      "y": 3,
      "z": -2,
      "name": "Cloth_Block_Wool_Purple"
    },
    {
      "x": -21,
      "y": 4,
      "z": -2,
      "name": "Cloth_Block_Wool_Purple"
    },
    {
      "x": -21,
      "y": 5,
      "z": -2,
      "name": "Cloth_Block_Wool_Purple"
    },
    {
      "x": -21,
      "y": 6,
      "z": -2,
      "name": "Cloth_Block_Wool_Purple"
    },
    {
      "x": -21,
      "y": 7,
      "z": -2,
      "name": "Cloth_Block_Wool_Purple"
    },
    {
      "x": -21,
      "y": 8,
      "z": -2,
      "name": "Cloth_Block_Wool_Purple"
    },
    {
      "x": -21,
      "y": 1,
      "z": -1,
      "name": "Cloth_Block_Wool_Purple"
    },
    {
      "x": -21,
      "y": 2,
      "z": -1,
      "name": "Cloth_Block_Wool_Purple"
    },
    {
      "x": -21,
      "y": 3,
      "z": -1,
      "name": "Cloth_Block_Wool_Purple"
    },
    {
      "x": -21,
      "y": 4,
      "z": -1,
      "name": "Cloth_Block_Wool_Purple"
    },
    {
      "x": -21,
      "y": 5,
      "z": -1,
      "name": "Cloth_Block_Wool_Purple"
    },
    {
      "x": -21,
      "y": 6,
      "z": -1,
      "name": "Cloth_Block_Wool_Purple"
    },
    {
      "x": -21,
      "y": 7,
      "z": -1,
      "name": "Cloth_Block_Wool_Purple"
    },
    {
      "x": -21,
      "y": 8,
      "z": -1,
      "name": "Cloth_Block_Wool_Purple"
    },
    {
      "x": -21,
      "y": 1,
      "z": 0,
      "name": "Cloth_Block_Wool_Purple"
    },
    {
      "x": -21,
      "y": 2,
      "z": 0,
      "name": "Cloth_Block_Wool_Purple"
    },
    {
      "x": -21,
      "y": 3,
      "z": 0,
      "name": "Cloth_Block_Wool_Purple"
    },
    {
      "x": -21,
      "y": 4,
      "z": 0,
      "name": "Cloth_Block_Wool_Purple"
    },
    {
      "x": -21,
      "y": 5,
      "z": 0,
      "name": "Cloth_Block_Wool_Purple"
    },
    {
      "x": -21,
      "y": 6,
      "z": 0,
      "name": "Cloth_Block_Wool_Purple"
    },
    {
      "x": -21,
      "y": 7,
      "z": 0,
      "name": "Cloth_Block_Wool_Purple"
    },
    {
      "x": -21,
      "y": 8,
      "z": 0,
      "name": "Cloth_Block_Wool_Purple"
    },
    {
      "x": -20,
      "y": 1,
      "z": -22,
      "name": "Cloth_Block_Wool_Purple"
    },
    {
      "x": -20,
      "y": 2,
      "z": -22,
      "name": "Cloth_Block_Wool_Purple"
    },
    {
      "x": -20,
      "y": 3,
      "z": -22,
      "name": "Cloth_Block_Wool_Purple"
    },
    {
      "x": -20,
      "y": 4,
      "z": -22,
      "name": "Cloth_Block_Wool_Purple"
    },
    {
      "x": -20,
      "y": 5,
      "z": -22,
      "name": "Cloth_Block_Wool_Purple"
    },
    {
      "x": -20,
      "y": 6,
      "z": -22,
      "name": "Cloth_Block_Wool_Purple"
    },
    {
      "x": -20,
      "y": 7,
      "z": -22,
      "name": "Cloth_Block_Wool_Purple"
    },
    {
      "x": -20,
      "y": 8,
      "z": -22,
      "name": "Cloth_Block_Wool_Purple"
    },
    {
      "x": -20,
      "y": 1,
      "z": -21,
      "name": "Cloth_Block_Wool_Purple"
    },
    {
      "x": -20,
      "y": 2,
      "z": -21,
      "name": "Cloth_Block_Wool_Purple"
    },
    {
      "x": -20,
      "y": 3,
      "z": -21,
      "name": "Cloth_Block_Wool_Purple"
    },
    {
      "x": -20,
      "y": 4,
      "z": -21,
      "name": "Cloth_Block_Wool_Purple"
    },
    {
      "x": -20,
      "y": 5,
      "z": -21,
      "name": "Cloth_Block_Wool_Purple"
    },
    {
      "x": -20,
      "y": 6,
      "z": -21,
      "name": "Cloth_Block_Wool_Purple"
    },
    {
      "x": -20,
      "y": 7,
      "z": -21,
      "name": "Cloth_Block_Wool_Purple"
    },
    {
      "x": -20,
      "y": 8,
      "z": -21,
      "name": "Cloth_Block_Wool_Purple"
    },
    {
      "x": -20,
      "y": 1,
      "z": -20,
      "name": "Cloth_Block_Wool_Purple"
    },
    {
      "x": -20,
      "y": 2,
      "z": -20,
      "name": "Cloth_Block_Wool_Purple"
    },
    {
      "x": -20,
      "y": 3,
      "z": -20,
      "name": "Cloth_Block_Wool_Purple"
    },
    {
      "x": -20,
      "y": 4,
      "z": -20,
      "name": "Cloth_Block_Wool_Purple"
    },
    {
      "x": -20,
      "y": 5,
      "z": -20,
      "name": "Cloth_Block_Wool_Purple"
    },
    {
      "x": -20,
      "y": 6,
      "z": -20,
      "name": "Cloth_Block_Wool_Purple"
    },
    {
      "x": -20,
      "y": 7,
      "z": -20,
      "name": "Cloth_Block_Wool_Purple"
    },
    {
      "x": -20,
      "y": 8,
      "z": -20,
      "name": "Cloth_Block_Wool_Purple"
    },
    {
      "x": -20,
      "y": 1,
      "z": -19,
      "name": "Cloth_Block_Wool_Purple"
    },
    {
      "x": -20,
      "y": 2,
      "z": -19,
      "name": "Cloth_Block_Wool_Purple"
    },
    {
      "x": -20,
      "y": 3,
      "z": -19,
      "name": "Cloth_Block_Wool_Purple"
    },
    {
      "x": -20,
      "y": 4,
      "z": -19,
      "name": "Cloth_Block_Wool_Purple"
    },
    {
      "x": -20,
      "y": 5,
      "z": -19,
      "name": "Cloth_Block_Wool_Purple"
    },
    {
      "x": -20,
      "y": 6,
      "z": -19,
      "name": "Cloth_Block_Wool_Purple"
    },
    {
      "x": -20,
      "y": 7,
      "z": -19,
      "name": "Cloth_Block_Wool_Purple"
    },
    {
      "x": -20,
      "y": 8,
      "z": -19,
      "name": "Cloth_Block_Wool_Purple"
    },
    {
      "x": -20,
      "y": 1,
      "z": -18,
      "name": "Cloth_Block_Wool_Purple"
    },
    {
      "x": -20,
      "y": 2,
      "z": -18,
      "name": "Cloth_Block_Wool_Purple"
    },
    {
      "x": -20,
      "y": 3,
      "z": -18,
      "name": "Cloth_Block_Wool_Purple"
    },
    {
      "x": -20,
      "y": 4,
      "z": -18,
      "name": "Cloth_Block_Wool_Purple"
    },
    {
      "x": -20,
      "y": 5,
      "z": -18,
      "name": "Cloth_Block_Wool_Purple"
    },
    {
      "x": -20,
      "y": 6,
      "z": -18,
      "name": "Cloth_Block_Wool_Purple"
    },
    {
      "x": -20,
      "y": 7,
      "z": -18,
      "name": "Cloth_Block_Wool_Purple"
    },
    {
      "x": -20,
      "y": 8,
      "z": -18,
      "name": "Cloth_Block_Wool_Purple"
    },
    {
      "x": -20,
      "y": 1,
      "z": -17,
      "name": "Cloth_Block_Wool_Purple"
    },
    {
      "x": -20,
      "y": 2,
      "z": -17,
      "name": "Cloth_Block_Wool_Purple"
    },
    {
      "x": -20,
      "y": 3,
      "z": -17,
      "name": "Cloth_Block_Wool_Purple"
    },
    {
      "x": -20,
      "y": 4,
      "z": -17,
      "name": "Cloth_Block_Wool_Purple"
    },
    {
      "x": -20,
      "y": 5,
      "z": -17,
      "name": "Cloth_Block_Wool_Purple"
    },
    {
      "x": -20,
      "y": 6,
      "z": -17,
      "name": "Cloth_Block_Wool_Purple"
    },
    {
      "x": -20,
      "y": 7,
      "z": -17,
      "name": "Cloth_Block_Wool_Purple"
    },
    {
      "x": -20,
      "y": 8,
      "z": -17,
      "name": "Cloth_Block_Wool_Purple"
    },
    {
      "x": -20,
      "y": 1,
      "z": -16,
      "name": "Cloth_Block_Wool_Purple"
    },
    {
      "x": -20,
      "y": 2,
      "z": -16,
      "name": "Cloth_Block_Wool_Purple"
    },
    {
      "x": -20,
      "y": 3,
      "z": -16,
      "name": "Cloth_Block_Wool_Purple"
    },
    {
      "x": -20,
      "y": 4,
      "z": -16,
      "name": "Cloth_Block_Wool_Purple"
    },
    {
      "x": -20,
      "y": 5,
      "z": -16,
      "name": "Cloth_Block_Wool_Purple"
    },
    {
      "x": -20,
      "y": 6,
      "z": -16,
      "name": "Cloth_Block_Wool_Purple"
    },
    {
      "x": -20,
      "y": 7,
      "z": -16,
      "name": "Cloth_Block_Wool_Purple"
    },
    {
      "x": -20,
      "y": 8,
      "z": -16,
      "name": "Cloth_Block_Wool_Purple"
    },
    {
      "x": -20,
      "y": 1,
      "z": -15,
      "name": "Cloth_Block_Wool_Purple"
    },
    {
      "x": -20,
      "y": 2,
      "z": -15,
      "name": "Cloth_Block_Wool_Purple"
    },
    {
      "x": -20,
      "y": 3,
      "z": -15,
      "name": "Cloth_Block_Wool_Purple"
    },
    {
      "x": -20,
      "y": 4,
      "z": -15,
      "name": "Cloth_Block_Wool_Purple"
    },
    {
      "x": -20,
      "y": 5,
      "z": -15,
      "name": "Cloth_Block_Wool_Purple"
    },
    {
      "x": -20,
      "y": 6,
      "z": -15,
      "name": "Cloth_Block_Wool_Purple"
    },
    {
      "x": -20,
      "y": 7,
      "z": -15,
      "name": "Cloth_Block_Wool_Purple"
    },
    {
      "x": -20,
      "y": 8,
      "z": -15,
      "name": "Cloth_Block_Wool_Purple"
    },
    {
      "x": -20,
      "y": 1,
      "z": -14,
      "name": "Cloth_Block_Wool_Purple"
    },
    {
      "x": -20,
      "y": 2,
      "z": -14,
      "name": "Cloth_Block_Wool_Purple"
    },
    {
      "x": -20,
      "y": 3,
      "z": -14,
      "name": "Cloth_Block_Wool_Purple"
    },
    {
      "x": -20,
      "y": 4,
      "z": -14,
      "name": "Cloth_Block_Wool_Purple"
    },
    {
      "x": -20,
      "y": 5,
      "z": -14,
      "name": "Cloth_Block_Wool_Purple"
    },
    {
      "x": -20,
      "y": 6,
      "z": -14,
      "name": "Cloth_Block_Wool_Purple"
    },
    {
      "x": -20,
      "y": 7,
      "z": -14,
      "name": "Cloth_Block_Wool_Purple"
    },
    {
      "x": -20,
      "y": 8,
      "z": -14,
      "name": "Cloth_Block_Wool_Purple"
    },
    {
      "x": -20,
      "y": 1,
      "z": -13,
      "name": "Cloth_Block_Wool_Purple"
    },
    {
      "x": -20,
      "y": 2,
      "z": -13,
      "name": "Cloth_Block_Wool_Purple"
    },
    {
      "x": -20,
      "y": 3,
      "z": -13,
      "name": "Cloth_Block_Wool_Purple"
    },
    {
      "x": -20,
      "y": 4,
      "z": -13,
      "name": "Cloth_Block_Wool_Purple"
    },
    {
      "x": -20,
      "y": 5,
      "z": -13,
      "name": "Cloth_Block_Wool_Purple"
    },
    {
      "x": -20,
      "y": 6,
      "z": -13,
      "name": "Cloth_Block_Wool_Purple"
    },
    {
      "x": -20,
      "y": 7,
      "z": -13,
      "name": "Cloth_Block_Wool_Purple"
    },
    {
      "x": -20,
      "y": 8,
      "z": -13,
      "name": "Cloth_Block_Wool_Purple"
    },
    {
      "x": -20,
      "y": 1,
      "z": -12,
      "name": "Cloth_Block_Wool_Purple"
    },
    {
      "x": -20,
      "y": 2,
      "z": -12,
      "name": "Cloth_Block_Wool_Purple"
    },
    {
      "x": -20,
      "y": 3,
      "z": -12,
      "name": "Cloth_Block_Wool_Purple"
    },
    {
      "x": -20,
      "y": 4,
      "z": -12,
      "name": "Cloth_Block_Wool_Purple"
    },
    {
      "x": -20,
      "y": 5,
      "z": -12,
      "name": "Cloth_Block_Wool_Purple"
    },
    {
      "x": -20,
      "y": 6,
      "z": -12,
      "name": "Cloth_Block_Wool_Purple"
    },
    {
      "x": -20,
      "y": 7,
      "z": -12,
      "name": "Cloth_Block_Wool_Purple"
    },
    {
      "x": -20,
      "y": 8,
      "z": -12,
      "name": "Cloth_Block_Wool_Purple"
    },
    {
      "x": -20,
      "y": 1,
      "z": -11,
      "name": "Cloth_Block_Wool_Purple"
    },
    {
      "x": -20,
      "y": 2,
      "z": -11,
      "name": "Cloth_Block_Wool_Purple"
    },
    {
      "x": -20,
      "y": 3,
      "z": -11,
      "name": "Cloth_Block_Wool_Purple"
    },
    {
      "x": -20,
      "y": 4,
      "z": -11,
      "name": "Cloth_Block_Wool_Purple"
    },
    {
      "x": -20,
      "y": 5,
      "z": -11,
      "name": "Cloth_Block_Wool_Purple"
    },
    {
      "x": -20,
      "y": 6,
      "z": -11,
      "name": "Cloth_Block_Wool_Purple"
    },
    {
      "x": -20,
      "y": 7,
      "z": -11,
      "name": "Cloth_Block_Wool_Purple"
    },
    {
      "x": -20,
      "y": 8,
      "z": -11,
      "name": "Cloth_Block_Wool_Purple"
    },
    {
      "x": -20,
      "y": 1,
      "z": -10,
      "name": "Cloth_Block_Wool_Purple"
    },
    {
      "x": -20,
      "y": 2,
      "z": -10,
      "name": "Cloth_Block_Wool_Purple"
    },
    {
      "x": -20,
      "y": 3,
      "z": -10,
      "name": "Cloth_Block_Wool_Purple"
    },
    {
      "x": -20,
      "y": 4,
      "z": -10,
      "name": "Cloth_Block_Wool_Purple"
    },
    {
      "x": -20,
      "y": 5,
      "z": -10,
      "name": "Cloth_Block_Wool_Purple"
    },
    {
      "x": -20,
      "y": 6,
      "z": -10,
      "name": "Cloth_Block_Wool_Purple"
    },
    {
      "x": -20,
      "y": 7,
      "z": -10,
      "name": "Cloth_Block_Wool_Purple"
    },
    {
      "x": -20,
      "y": 8,
      "z": -10,
      "name": "Cloth_Block_Wool_Purple"
    },
    {
      "x": -20,
      "y": 1,
      "z": -9,
      "name": "Cloth_Block_Wool_Purple"
    },
    {
      "x": -20,
      "y": 2,
      "z": -9,
      "name": "Cloth_Block_Wool_Purple"
    },
    {
      "x": -20,
      "y": 3,
      "z": -9,
      "name": "Cloth_Block_Wool_Purple"
    },
    {
      "x": -20,
      "y": 4,
      "z": -9,
      "name": "Cloth_Block_Wool_Purple"
    },
    {
      "x": -20,
      "y": 5,
      "z": -9,
      "name": "Cloth_Block_Wool_Purple"
    },
    {
      "x": -20,
      "y": 6,
      "z": -9,
      "name": "Cloth_Block_Wool_Purple"
    },
    {
      "x": -20,
      "y": 7,
      "z": -9,
      "name": "Cloth_Block_Wool_Purple"
    },
    {
      "x": -20,
      "y": 8,
      "z": -9,
      "name": "Cloth_Block_Wool_Purple"
    },
    {
      "x": -20,
      "y": 1,
      "z": -8,
      "name": "Cloth_Block_Wool_Purple"
    },
    {
      "x": -20,
      "y": 2,
      "z": -8,
      "name": "Cloth_Block_Wool_Purple"
    },
    {
      "x": -20,
      "y": 3,
      "z": -8,
      "name": "Cloth_Block_Wool_Purple"
    },
    {
      "x": -20,
      "y": 4,
      "z": -8,
      "name": "Cloth_Block_Wool_Purple"
    },
    {
      "x": -20,
      "y": 5,
      "z": -8,
      "name": "Cloth_Block_Wool_Purple"
    },
    {
      "x": -20,
      "y": 6,
      "z": -8,
      "name": "Cloth_Block_Wool_Purple"
    },
    {
      "x": -20,
      "y": 7,
      "z": -8,
      "name": "Cloth_Block_Wool_Purple"
    },
    {
      "x": -20,
      "y": 8,
      "z": -8,
      "name": "Cloth_Block_Wool_Purple"
    },
    {
      "x": -20,
      "y": 1,
      "z": -7,
      "name": "Cloth_Block_Wool_Purple"
    },
    {
      "x": -20,
      "y": 2,
      "z": -7,
      "name": "Cloth_Block_Wool_Purple"
    },
    {
      "x": -20,
      "y": 3,
      "z": -7,
      "name": "Cloth_Block_Wool_Purple"
    },
    {
      "x": -20,
      "y": 4,
      "z": -7,
      "name": "Cloth_Block_Wool_Purple"
    },
    {
      "x": -20,
      "y": 5,
      "z": -7,
      "name": "Cloth_Block_Wool_Purple"
    },
    {
      "x": -20,
      "y": 6,
      "z": -7,
      "name": "Cloth_Block_Wool_Purple"
    },
    {
      "x": -20,
      "y": 7,
      "z": -7,
      "name": "Cloth_Block_Wool_Purple"
    },
    {
      "x": -20,
      "y": 8,
      "z": -7,
      "name": "Cloth_Block_Wool_Purple"
    },
    {
      "x": -20,
      "y": 1,
      "z": -6,
      "name": "Cloth_Block_Wool_Purple"
    },
    {
      "x": -20,
      "y": 2,
      "z": -6,
      "name": "Cloth_Block_Wool_Purple"
    },
    {
      "x": -20,
      "y": 3,
      "z": -6,
      "name": "Cloth_Block_Wool_Purple"
    },
    {
      "x": -20,
      "y": 4,
      "z": -6,
      "name": "Cloth_Block_Wool_Purple"
    },
    {
      "x": -20,
      "y": 5,
      "z": -6,
      "name": "Cloth_Block_Wool_Purple"
    },
    {
      "x": -20,
      "y": 6,
      "z": -6,
      "name": "Cloth_Block_Wool_Purple"
    },
    {
      "x": -20,
      "y": 7,
      "z": -6,
      "name": "Cloth_Block_Wool_Purple"
    },
    {
      "x": -20,
      "y": 8,
      "z": -6,
      "name": "Cloth_Block_Wool_Purple"
    },
    {
      "x": -20,
      "y": 1,
      "z": -5,
      "name": "Cloth_Block_Wool_Purple"
    },
    {
      "x": -20,
      "y": 2,
      "z": -5,
      "name": "Cloth_Block_Wool_Purple"
    },
    {
      "x": -20,
      "y": 3,
      "z": -5,
      "name": "Cloth_Block_Wool_Purple"
    },
    {
      "x": -20,
      "y": 4,
      "z": -5,
      "name": "Cloth_Block_Wool_Purple"
    },
    {
      "x": -20,
      "y": 5,
      "z": -5,
      "name": "Cloth_Block_Wool_Purple"
    },
    {
      "x": -20,
      "y": 6,
      "z": -5,
      "name": "Cloth_Block_Wool_Purple"
    },
    {
      "x": -20,
      "y": 7,
      "z": -5,
      "name": "Cloth_Block_Wool_Purple"
    },
    {
      "x": -20,
      "y": 8,
      "z": -5,
      "name": "Cloth_Block_Wool_Purple"
    },
    {
      "x": -20,
      "y": 1,
      "z": -4,
      "name": "Cloth_Block_Wool_Purple"
    },
    {
      "x": -20,
      "y": 2,
      "z": -4,
      "name": "Cloth_Block_Wool_Purple"
    },
    {
      "x": -20,
      "y": 3,
      "z": -4,
      "name": "Cloth_Block_Wool_Purple"
    },
    {
      "x": -20,
      "y": 4,
      "z": -4,
      "name": "Cloth_Block_Wool_Purple"
    },
    {
      "x": -20,
      "y": 5,
      "z": -4,
      "name": "Cloth_Block_Wool_Purple"
    },
    {
      "x": -20,
      "y": 6,
      "z": -4,
      "name": "Cloth_Block_Wool_Purple"
    },
    {
      "x": -20,
      "y": 7,
      "z": -4,
      "name": "Cloth_Block_Wool_Purple"
    },
    {
      "x": -20,
      "y": 8,
      "z": -4,
      "name": "Cloth_Block_Wool_Purple"
    },
    {
      "x": -20,
      "y": 1,
      "z": -3,
      "name": "Cloth_Block_Wool_Purple"
    },
    {
      "x": -20,
      "y": 2,
      "z": -3,
      "name": "Cloth_Block_Wool_Purple"
    },
    {
      "x": -20,
      "y": 3,
      "z": -3,
      "name": "Cloth_Block_Wool_Purple"
    },
    {
      "x": -20,
      "y": 4,
      "z": -3,
      "name": "Cloth_Block_Wool_Purple"
    },
    {
      "x": -20,
      "y": 5,
      "z": -3,
      "name": "Cloth_Block_Wool_Purple"
    },
    {
      "x": -20,
      "y": 6,
      "z": -3,
      "name": "Cloth_Block_Wool_Purple"
    },
    {
      "x": -20,
      "y": 7,
      "z": -3,
      "name": "Cloth_Block_Wool_Purple"
    },
    {
      "x": -20,
      "y": 8,
      "z": -3,
      "name": "Cloth_Block_Wool_Purple"
    },
    {
      "x": -20,
      "y": 1,
      "z": -2,
      "name": "Cloth_Block_Wool_Purple"
    },
    {
      "x": -20,
      "y": 2,
      "z": -2,
      "name": "Cloth_Block_Wool_Purple"
    },
    {
      "x": -20,
      "y": 3,
      "z": -2,
      "name": "Cloth_Block_Wool_Purple"
    },
    {
      "x": -20,
      "y": 4,
      "z": -2,
      "name": "Cloth_Block_Wool_Purple"
    },
    {
      "x": -20,
      "y": 5,
      "z": -2,
      "name": "Cloth_Block_Wool_Purple"
    },
    {
      "x": -20,
      "y": 6,
      "z": -2,
      "name": "Cloth_Block_Wool_Purple"
    },
    {
      "x": -20,
      "y": 7,
      "z": -2,
      "name": "Cloth_Block_Wool_Purple"
    },
    {
      "x": -20,
      "y": 8,
      "z": -2,
      "name": "Cloth_Block_Wool_Purple"
    },
    {
      "x": -20,
      "y": 1,
      "z": -1,
      "name": "Cloth_Block_Wool_Purple"
    },
    {
      "x": -20,
      "y": 2,
      "z": -1,
      "name": "Cloth_Block_Wool_Purple"
    },
    {
      "x": -20,
      "y": 3,
      "z": -1,
      "name": "Cloth_Block_Wool_Purple"
    },
    {
      "x": -20,
      "y": 4,
      "z": -1,
      "name": "Cloth_Block_Wool_Purple"
    },
    {
      "x": -20,
      "y": 5,
      "z": -1,
      "name": "Cloth_Block_Wool_Purple"
    },
    {
      "x": -20,
      "y": 6,
      "z": -1,
      "name": "Cloth_Block_Wool_Purple"
    },
    {
      "x": -20,
      "y": 7,
      "z": -1,
      "name": "Cloth_Block_Wool_Purple"
    },
    {
      "x": -20,
      "y": 8,
      "z": -1,
      "name": "Cloth_Block_Wool_Purple"
    },
    {
      "x": -20,
      "y": 1,
      "z": 0,
      "name": "Cloth_Block_Wool_Purple"
    },
    {
      "x": -20,
      "y": 2,
      "z": 0,
      "name": "Cloth_Block_Wool_Purple"
    },
    {
      "x": -20,
      "y": 3,
      "z": 0,
      "name": "Cloth_Block_Wool_Purple"
    },
    {
      "x": -20,
      "y": 4,
      "z": 0,
      "name": "Cloth_Block_Wool_Purple"
    },
    {
      "x": -20,
      "y": 5,
      "z": 0,
      "name": "Cloth_Block_Wool_Purple"
    },
    {
      "x": -20,
      "y": 6,
      "z": 0,
      "name": "Cloth_Block_Wool_Purple"
    },
    {
      "x": -20,
      "y": 7,
      "z": 0,
      "name": "Cloth_Block_Wool_Purple"
    },
    {
      "x": -20,
      "y": 8,
      "z": 0,
      "name": "Cloth_Block_Wool_Purple"
    },
    {
      "x": -19,
      "y": 1,
      "z": -22,
      "name": "Cloth_Block_Wool_Purple"
    },
    {
      "x": -19,
      "y": 2,
      "z": -22,
      "name": "Cloth_Block_Wool_Purple"
    },
    {
      "x": -19,
      "y": 3,
      "z": -22,
      "name": "Cloth_Block_Wool_Purple"
    },
    {
      "x": -19,
      "y": 4,
      "z": -22,
      "name": "Cloth_Block_Wool_Purple"
    },
    {
      "x": -19,
      "y": 5,
      "z": -22,
      "name": "Cloth_Block_Wool_Purple"
    },
    {
      "x": -19,
      "y": 6,
      "z": -22,
      "name": "Cloth_Block_Wool_Purple"
    },
    {
      "x": -19,
      "y": 7,
      "z": -22,
      "name": "Cloth_Block_Wool_Purple"
    },
    {
      "x": -19,
      "y": 8,
      "z": -22,
      "name": "Cloth_Block_Wool_Purple"
    },
    {
      "x": -19,
      "y": 1,
      "z": -21,
      "name": "Cloth_Block_Wool_Purple"
    },
    {
      "x": -19,
      "y": 2,
      "z": -21,
      "name": "Cloth_Block_Wool_Purple"
    },
    {
      "x": -19,
      "y": 3,
      "z": -21,
      "name": "Cloth_Block_Wool_Purple"
    },
    {
      "x": -19,
      "y": 4,
      "z": -21,
      "name": "Cloth_Block_Wool_Purple"
    },
    {
      "x": -19,
      "y": 5,
      "z": -21,
      "name": "Cloth_Block_Wool_Purple"
    },
    {
      "x": -19,
      "y": 6,
      "z": -21,
      "name": "Cloth_Block_Wool_Purple"
    },
    {
      "x": -19,
      "y": 7,
      "z": -21,
      "name": "Cloth_Block_Wool_Purple"
    },
    {
      "x": -19,
      "y": 8,
      "z": -21,
      "name": "Cloth_Block_Wool_Purple"
    },
    {
      "x": -19,
      "y": 1,
      "z": -20,
      "name": "Cloth_Block_Wool_Purple"
    },
    {
      "x": -19,
      "y": 2,
      "z": -20,
      "name": "Cloth_Block_Wool_Purple"
    },
    {
      "x": -19,
      "y": 3,
      "z": -20,
      "name": "Cloth_Block_Wool_Purple"
    },
    {
      "x": -19,
      "y": 4,
      "z": -20,
      "name": "Cloth_Block_Wool_Purple"
    },
    {
      "x": -19,
      "y": 5,
      "z": -20,
      "name": "Cloth_Block_Wool_Purple"
    },
    {
      "x": -19,
      "y": 6,
      "z": -20,
      "name": "Cloth_Block_Wool_Purple"
    },
    {
      "x": -19,
      "y": 7,
      "z": -20,
      "name": "Cloth_Block_Wool_Purple"
    },
    {
      "x": -19,
      "y": 8,
      "z": -20,
      "name": "Cloth_Block_Wool_Purple"
    },
    {
      "x": -19,
      "y": 1,
      "z": -19,
      "name": "Cloth_Block_Wool_Purple"
    },
    {
      "x": -19,
      "y": 2,
      "z": -19,
      "name": "Cloth_Block_Wool_Purple"
    },
    {
      "x": -19,
      "y": 3,
      "z": -19,
      "name": "Cloth_Block_Wool_Purple"
    },
    {
      "x": -19,
      "y": 4,
      "z": -19,
      "name": "Cloth_Block_Wool_Purple"
    },
    {
      "x": -19,
      "y": 5,
      "z": -19,
      "name": "Cloth_Block_Wool_Purple"
    },
    {
      "x": -19,
      "y": 6,
      "z": -19,
      "name": "Cloth_Block_Wool_Purple"
    },
    {
      "x": -19,
      "y": 7,
      "z": -19,
      "name": "Cloth_Block_Wool_Purple"
    },
    {
      "x": -19,
      "y": 8,
      "z": -19,
      "name": "Cloth_Block_Wool_Purple"
    },
    {
      "x": -19,
      "y": 1,
      "z": -18,
      "name": "Cloth_Block_Wool_Purple"
    },
    {
      "x": -19,
      "y": 2,
      "z": -18,
      "name": "Cloth_Block_Wool_Purple"
    },
    {
      "x": -19,
      "y": 3,
      "z": -18,
      "name": "Cloth_Block_Wool_Purple"
    },
    {
      "x": -19,
      "y": 4,
      "z": -18,
      "name": "Cloth_Block_Wool_Purple"
    },
    {
      "x": -19,
      "y": 5,
      "z": -18,
      "name": "Cloth_Block_Wool_Purple"
    },
    {
      "x": -19,
      "y": 6,
      "z": -18,
      "name": "Cloth_Block_Wool_Purple"
    },
    {
      "x": -19,
      "y": 7,
      "z": -18,
      "name": "Cloth_Block_Wool_Purple"
    },
    {
      "x": -19,
      "y": 8,
      "z": -18,
      "name": "Cloth_Block_Wool_Purple"
    },
    {
      "x": -19,
      "y": 1,
      "z": -17,
      "name": "Cloth_Block_Wool_Purple"
    },
    {
      "x": -19,
      "y": 2,
      "z": -17,
      "name": "Cloth_Block_Wool_Purple"
    },
    {
      "x": -19,
      "y": 3,
      "z": -17,
      "name": "Cloth_Block_Wool_Purple"
    },
    {
      "x": -19,
      "y": 4,
      "z": -17,
      "name": "Cloth_Block_Wool_Purple"
    },
    {
      "x": -19,
      "y": 5,
      "z": -17,
      "name": "Cloth_Block_Wool_Purple"
    },
    {
      "x": -19,
      "y": 6,
      "z": -17,
      "name": "Cloth_Block_Wool_Purple"
    },
    {
      "x": -19,
      "y": 7,
      "z": -17,
      "name": "Cloth_Block_Wool_Purple"
    },
    {
      "x": -19,
      "y": 8,
      "z": -17,
      "name": "Cloth_Block_Wool_Purple"
    },
    {
      "x": -19,
      "y": 1,
      "z": -16,
      "name": "Cloth_Block_Wool_Purple"
    },
    {
      "x": -19,
      "y": 2,
      "z": -16,
      "name": "Cloth_Block_Wool_Purple"
    },
    {
      "x": -19,
      "y": 3,
      "z": -16,
      "name": "Cloth_Block_Wool_Purple"
    },
    {
      "x": -19,
      "y": 4,
      "z": -16,
      "name": "Cloth_Block_Wool_Purple"
    },
    {
      "x": -19,
      "y": 5,
      "z": -16,
      "name": "Cloth_Block_Wool_Purple"
    },
    {
      "x": -19,
      "y": 6,
      "z": -16,
      "name": "Cloth_Block_Wool_Purple"
    },
    {
      "x": -19,
      "y": 7,
      "z": -16,
      "name": "Cloth_Block_Wool_Purple"
    },
    {
      "x": -19,
      "y": 8,
      "z": -16,
      "name": "Cloth_Block_Wool_Purple"
    },
    {
      "x": -19,
      "y": 1,
      "z": -15,
      "name": "Cloth_Block_Wool_Purple"
    },
    {
      "x": -19,
      "y": 2,
      "z": -15,
      "name": "Cloth_Block_Wool_Purple"
    },
    {
      "x": -19,
      "y": 3,
      "z": -15,
      "name": "Cloth_Block_Wool_Purple"
    },
    {
      "x": -19,
      "y": 4,
      "z": -15,
      "name": "Cloth_Block_Wool_Purple"
    },
    {
      "x": -19,
      "y": 5,
      "z": -15,
      "name": "Cloth_Block_Wool_Purple"
    },
    {
      "x": -19,
      "y": 6,
      "z": -15,
      "name": "Cloth_Block_Wool_Purple"
    },
    {
      "x": -19,
      "y": 7,
      "z": -15,
      "name": "Cloth_Block_Wool_Purple"
    },
    {
      "x": -19,
      "y": 8,
      "z": -15,
      "name": "Cloth_Block_Wool_Purple"
    },
    {
      "x": -19,
      "y": 1,
      "z": -14,
      "name": "Cloth_Block_Wool_Purple"
    },
    {
      "x": -19,
      "y": 2,
      "z": -14,
      "name": "Cloth_Block_Wool_Purple"
    },
    {
      "x": -19,
      "y": 3,
      "z": -14,
      "name": "Cloth_Block_Wool_Purple"
    },
    {
      "x": -19,
      "y": 4,
      "z": -14,
      "name": "Cloth_Block_Wool_Purple"
    },
    {
      "x": -19,
      "y": 5,
      "z": -14,
      "name": "Cloth_Block_Wool_Purple"
    },
    {
      "x": -19,
      "y": 6,
      "z": -14,
      "name": "Cloth_Block_Wool_Purple"
    },
    {
      "x": -19,
      "y": 7,
      "z": -14,
      "name": "Cloth_Block_Wool_Purple"
    },
    {
      "x": -19,
      "y": 8,
      "z": -14,
      "name": "Cloth_Block_Wool_Purple"
    },
    {
      "x": -19,
      "y": 1,
      "z": -13,
      "name": "Cloth_Block_Wool_Purple"
    },
    {
      "x": -19,
      "y": 2,
      "z": -13,
      "name": "Cloth_Block_Wool_Purple"
    },
    {
      "x": -19,
      "y": 3,
      "z": -13,
      "name": "Cloth_Block_Wool_Purple"
    },
    {
      "x": -19,
      "y": 4,
      "z": -13,
      "name": "Cloth_Block_Wool_Purple"
    },
    {
      "x": -19,
      "y": 5,
      "z": -13,
      "name": "Cloth_Block_Wool_Purple"
    },
    {
      "x": -19,
      "y": 6,
      "z": -13,
      "name": "Cloth_Block_Wool_Purple"
    },
    {
      "x": -19,
      "y": 7,
      "z": -13,
      "name": "Cloth_Block_Wool_Purple"
    },
    {
      "x": -19,
      "y": 8,
      "z": -13,
      "name": "Cloth_Block_Wool_Purple"
    },
    {
      "x": -19,
      "y": 1,
      "z": -12,
      "name": "Cloth_Block_Wool_Purple"
    },
    {
      "x": -19,
      "y": 2,
      "z": -12,
      "name": "Cloth_Block_Wool_Purple"
    },
    {
      "x": -19,
      "y": 3,
      "z": -12,
      "name": "Cloth_Block_Wool_Purple"
    },
    {
      "x": -19,
      "y": 4,
      "z": -12,
      "name": "Cloth_Block_Wool_Purple"
    },
    {
      "x": -19,
      "y": 5,
      "z": -12,
      "name": "Cloth_Block_Wool_Purple"
    },
    {
      "x": -19,
      "y": 6,
      "z": -12,
      "name": "Cloth_Block_Wool_Purple"
    },
    {
      "x": -19,
      "y": 7,
      "z": -12,
      "name": "Cloth_Block_Wool_Purple"
    },
    {
      "x": -19,
      "y": 8,
      "z": -12,
      "name": "Cloth_Block_Wool_Purple"
    },
    {
      "x": -19,
      "y": 1,
      "z": -11,
      "name": "Cloth_Block_Wool_Purple"
    },
    {
      "x": -19,
      "y": 2,
      "z": -11,
      "name": "Cloth_Block_Wool_Purple"
    },
    {
      "x": -19,
      "y": 3,
      "z": -11,
      "name": "Cloth_Block_Wool_Purple"
    },
    {
      "x": -19,
      "y": 4,
      "z": -11,
      "name": "Cloth_Block_Wool_Purple"
    },
    {
      "x": -19,
      "y": 5,
      "z": -11,
      "name": "Cloth_Block_Wool_Purple"
    },
    {
      "x": -19,
      "y": 6,
      "z": -11,
      "name": "Cloth_Block_Wool_Purple"
    },
    {
      "x": -19,
      "y": 7,
      "z": -11,
      "name": "Cloth_Block_Wool_Purple"
    },
    {
      "x": -19,
      "y": 8,
      "z": -11,
      "name": "Cloth_Block_Wool_Purple"
    },
    {
      "x": -19,
      "y": 1,
      "z": -10,
      "name": "Cloth_Block_Wool_Purple"
    },
    {
      "x": -19,
      "y": 2,
      "z": -10,
      "name": "Cloth_Block_Wool_Purple"
    },
    {
      "x": -19,
      "y": 3,
      "z": -10,
      "name": "Cloth_Block_Wool_Purple"
    },
    {
      "x": -19,
      "y": 4,
      "z": -10,
      "name": "Cloth_Block_Wool_Purple"
    },
    {
      "x": -19,
      "y": 5,
      "z": -10,
      "name": "Cloth_Block_Wool_Purple"
    },
    {
      "x": -19,
      "y": 6,
      "z": -10,
      "name": "Cloth_Block_Wool_Purple"
    },
    {
      "x": -19,
      "y": 7,
      "z": -10,
      "name": "Cloth_Block_Wool_Purple"
    },
    {
      "x": -19,
      "y": 8,
      "z": -10,
      "name": "Cloth_Block_Wool_Purple"
    },
    {
      "x": -19,
      "y": 1,
      "z": -9,
      "name": "Cloth_Block_Wool_Purple"
    },
    {
      "x": -19,
      "y": 2,
      "z": -9,
      "name": "Cloth_Block_Wool_Purple"
    },
    {
      "x": -19,
      "y": 3,
      "z": -9,
      "name": "Cloth_Block_Wool_Purple"
    },
    {
      "x": -19,
      "y": 4,
      "z": -9,
      "name": "Cloth_Block_Wool_Purple"
    },
    {
      "x": -19,
      "y": 5,
      "z": -9,
      "name": "Cloth_Block_Wool_Purple"
    },
    {
      "x": -19,
      "y": 6,
      "z": -9,
      "name": "Cloth_Block_Wool_Purple"
    },
    {
      "x": -19,
      "y": 7,
      "z": -9,
      "name": "Cloth_Block_Wool_Purple"
    },
    {
      "x": -19,
      "y": 8,
      "z": -9,
      "name": "Cloth_Block_Wool_Purple"
    },
    {
      "x": -19,
      "y": 1,
      "z": -8,
      "name": "Cloth_Block_Wool_Purple"
    },
    {
      "x": -19,
      "y": 2,
      "z": -8,
      "name": "Cloth_Block_Wool_Purple"
    },
    {
      "x": -19,
      "y": 3,
      "z": -8,
      "name": "Cloth_Block_Wool_Purple"
    },
    {
      "x": -19,
      "y": 4,
      "z": -8,
      "name": "Cloth_Block_Wool_Purple"
    },
    {
      "x": -19,
      "y": 5,
      "z": -8,
      "name": "Cloth_Block_Wool_Purple"
    },
    {
      "x": -19,
      "y": 6,
      "z": -8,
      "name": "Cloth_Block_Wool_Purple"
    },
    {
      "x": -19,
      "y": 7,
      "z": -8,
      "name": "Cloth_Block_Wool_Purple"
    },
    {
      "x": -19,
      "y": 8,
      "z": -8,
      "name": "Cloth_Block_Wool_Purple"
    },
    {
      "x": -19,
      "y": 1,
      "z": -7,
      "name": "Cloth_Block_Wool_Purple"
    },
    {
      "x": -19,
      "y": 2,
      "z": -7,
      "name": "Cloth_Block_Wool_Purple"
    },
    {
      "x": -19,
      "y": 3,
      "z": -7,
      "name": "Cloth_Block_Wool_Purple"
    },
    {
      "x": -19,
      "y": 4,
      "z": -7,
      "name": "Cloth_Block_Wool_Purple"
    },
    {
      "x": -19,
      "y": 5,
      "z": -7,
      "name": "Cloth_Block_Wool_Purple"
    },
    {
      "x": -19,
      "y": 6,
      "z": -7,
      "name": "Cloth_Block_Wool_Purple"
    },
    {
      "x": -19,
      "y": 7,
      "z": -7,
      "name": "Cloth_Block_Wool_Purple"
    },
    {
      "x": -19,
      "y": 8,
      "z": -7,
      "name": "Cloth_Block_Wool_Purple"
    },
    {
      "x": -19,
      "y": 1,
      "z": -6,
      "name": "Cloth_Block_Wool_Purple"
    },
    {
      "x": -19,
      "y": 2,
      "z": -6,
      "name": "Cloth_Block_Wool_Purple"
    },
    {
      "x": -19,
      "y": 3,
      "z": -6,
      "name": "Cloth_Block_Wool_Purple"
    },
    {
      "x": -19,
      "y": 4,
      "z": -6,
      "name": "Cloth_Block_Wool_Purple"
    },
    {
      "x": -19,
      "y": 5,
      "z": -6,
      "name": "Cloth_Block_Wool_Purple"
    },
    {
      "x": -19,
      "y": 6,
      "z": -6,
      "name": "Cloth_Block_Wool_Purple"
    },
    {
      "x": -19,
      "y": 7,
      "z": -6,
      "name": "Cloth_Block_Wool_Purple"
    },
    {
      "x": -19,
      "y": 8,
      "z": -6,
      "name": "Cloth_Block_Wool_Purple"
    },
    {
      "x": -19,
      "y": 1,
      "z": -5,
      "name": "Cloth_Block_Wool_Purple"
    },
    {
      "x": -19,
      "y": 2,
      "z": -5,
      "name": "Cloth_Block_Wool_Purple"
    },
    {
      "x": -19,
      "y": 3,
      "z": -5,
      "name": "Cloth_Block_Wool_Purple"
    },
    {
      "x": -19,
      "y": 4,
      "z": -5,
      "name": "Cloth_Block_Wool_Purple"
    },
    {
      "x": -19,
      "y": 5,
      "z": -5,
      "name": "Cloth_Block_Wool_Purple"
    },
    {
      "x": -19,
      "y": 6,
      "z": -5,
      "name": "Cloth_Block_Wool_Purple"
    },
    {
      "x": -19,
      "y": 7,
      "z": -5,
      "name": "Cloth_Block_Wool_Purple"
    },
    {
      "x": -19,
      "y": 8,
      "z": -5,
      "name": "Cloth_Block_Wool_Purple"
    },
    {
      "x": -19,
      "y": 1,
      "z": -4,
      "name": "Cloth_Block_Wool_Purple"
    },
    {
      "x": -19,
      "y": 2,
      "z": -4,
      "name": "Cloth_Block_Wool_Purple"
    },
    {
      "x": -19,
      "y": 3,
      "z": -4,
      "name": "Cloth_Block_Wool_Purple"
    },
    {
      "x": -19,
      "y": 4,
      "z": -4,
      "name": "Cloth_Block_Wool_Purple"
    },
    {
      "x": -19,
      "y": 5,
      "z": -4,
      "name": "Cloth_Block_Wool_Purple"
    },
    {
      "x": -19,
      "y": 6,
      "z": -4,
      "name": "Cloth_Block_Wool_Purple"
    },
    {
      "x": -19,
      "y": 7,
      "z": -4,
      "name": "Cloth_Block_Wool_Purple"
    },
    {
      "x": -19,
      "y": 8,
      "z": -4,
      "name": "Cloth_Block_Wool_Purple"
    },
    {
      "x": -19,
      "y": 1,
      "z": -3,
      "name": "Cloth_Block_Wool_Purple"
    },
    {
      "x": -19,
      "y": 2,
      "z": -3,
      "name": "Cloth_Block_Wool_Purple"
    },
    {
      "x": -19,
      "y": 3,
      "z": -3,
      "name": "Cloth_Block_Wool_Purple"
    },
    {
      "x": -19,
      "y": 4,
      "z": -3,
      "name": "Cloth_Block_Wool_Purple"
    },
    {
      "x": -19,
      "y": 5,
      "z": -3,
      "name": "Cloth_Block_Wool_Purple"
    },
    {
      "x": -19,
      "y": 6,
      "z": -3,
      "name": "Cloth_Block_Wool_Purple"
    },
    {
      "x": -19,
      "y": 7,
      "z": -3,
      "name": "Cloth_Block_Wool_Purple"
    },
    {
      "x": -19,
      "y": 8,
      "z": -3,
      "name": "Cloth_Block_Wool_Purple"
    },
    {
      "x": -19,
      "y": 1,
      "z": -2,
      "name": "Cloth_Block_Wool_Purple"
    },
    {
      "x": -19,
      "y": 2,
      "z": -2,
      "name": "Cloth_Block_Wool_Purple"
    },
    {
      "x": -19,
      "y": 3,
      "z": -2,
      "name": "Cloth_Block_Wool_Purple"
    },
    {
      "x": -19,
      "y": 4,
      "z": -2,
      "name": "Cloth_Block_Wool_Purple"
    },
    {
      "x": -19,
      "y": 5,
      "z": -2,
      "name": "Cloth_Block_Wool_Purple"
    },
    {
      "x": -19,
      "y": 6,
      "z": -2,
      "name": "Cloth_Block_Wool_Purple"
    },
    {
      "x": -19,
      "y": 7,
      "z": -2,
      "name": "Cloth_Block_Wool_Purple"
    },
    {
      "x": -19,
      "y": 8,
      "z": -2,
      "name": "Cloth_Block_Wool_Purple"
    },
    {
      "x": -19,
      "y": 1,
      "z": -1,
      "name": "Cloth_Block_Wool_Purple"
    },
    {
      "x": -19,
      "y": 2,
      "z": -1,
      "name": "Cloth_Block_Wool_Purple"
    },
    {
      "x": -19,
      "y": 3,
      "z": -1,
      "name": "Cloth_Block_Wool_Purple"
    },
    {
      "x": -19,
      "y": 4,
      "z": -1,
      "name": "Cloth_Block_Wool_Purple"
    },
    {
      "x": -19,
      "y": 5,
      "z": -1,
      "name": "Cloth_Block_Wool_Purple"
    },
    {
      "x": -19,
      "y": 6,
      "z": -1,
      "name": "Cloth_Block_Wool_Purple"
    },
    {
      "x": -19,
      "y": 7,
      "z": -1,
      "name": "Cloth_Block_Wool_Purple"
    },
    {
      "x": -19,
      "y": 8,
      "z": -1,
      "name": "Cloth_Block_Wool_Purple"
    },
    {
      "x": -19,
      "y": 1,
      "z": 0,
      "name": "Cloth_Block_Wool_Purple"
    },
    {
      "x": -19,
      "y": 2,
      "z": 0,
      "name": "Cloth_Block_Wool_Purple"
    },
    {
      "x": -19,
      "y": 3,
      "z": 0,
      "name": "Cloth_Block_Wool_Purple"
    },
    {
      "x": -19,
      "y": 4,
      "z": 0,
      "name": "Cloth_Block_Wool_Purple"
    },
    {
      "x": -19,
      "y": 5,
      "z": 0,
      "name": "Cloth_Block_Wool_Purple"
    },
    {
      "x": -19,
      "y": 6,
      "z": 0,
      "name": "Cloth_Block_Wool_Purple"
    },
    {
      "x": -19,
      "y": 7,
      "z": 0,
      "name": "Cloth_Block_Wool_Purple"
    },
    {
      "x": -19,
      "y": 8,
      "z": 0,
      "name": "Cloth_Block_Wool_Purple"
    },
    {
      "x": -18,
      "y": 1,
      "z": -22,
      "name": "Cloth_Block_Wool_Purple"
    },
    {
      "x": -18,
      "y": 2,
      "z": -22,
      "name": "Cloth_Block_Wool_Purple"
    },
    {
      "x": -18,
      "y": 3,
      "z": -22,
      "name": "Cloth_Block_Wool_Purple"
    },
    {
      "x": -18,
      "y": 4,
      "z": -22,
      "name": "Cloth_Block_Wool_Purple"
    },
    {
      "x": -18,
      "y": 5,
      "z": -22,
      "name": "Cloth_Block_Wool_Purple"
    },
    {
      "x": -18,
      "y": 6,
      "z": -22,
      "name": "Cloth_Block_Wool_Purple"
    },
    {
      "x": -18,
      "y": 7,
      "z": -22,
      "name": "Cloth_Block_Wool_Purple"
    },
    {
      "x": -18,
      "y": 8,
      "z": -22,
      "name": "Cloth_Block_Wool_Purple"
    },
    {
      "x": -18,
      "y": 1,
      "z": -21,
      "name": "Cloth_Block_Wool_Purple"
    },
    {
      "x": -18,
      "y": 2,
      "z": -21,
      "name": "Cloth_Block_Wool_Purple"
    },
    {
      "x": -18,
      "y": 3,
      "z": -21,
      "name": "Cloth_Block_Wool_Purple"
    },
    {
      "x": -18,
      "y": 4,
      "z": -21,
      "name": "Cloth_Block_Wool_Purple"
    },
    {
      "x": -18,
      "y": 5,
      "z": -21,
      "name": "Cloth_Block_Wool_Purple"
    },
    {
      "x": -18,
      "y": 6,
      "z": -21,
      "name": "Cloth_Block_Wool_Purple"
    },
    {
      "x": -18,
      "y": 7,
      "z": -21,
      "name": "Cloth_Block_Wool_Purple"
    },
    {
      "x": -18,
      "y": 8,
      "z": -21,
      "name": "Cloth_Block_Wool_Purple"
    },
    {
      "x": -18,
      "y": 1,
      "z": -20,
      "name": "Cloth_Block_Wool_Purple"
    },
    {
      "x": -18,
      "y": 2,
      "z": -20,
      "name": "Cloth_Block_Wool_Purple"
    },
    {
      "x": -18,
      "y": 3,
      "z": -20,
      "name": "Cloth_Block_Wool_Purple"
    },
    {
      "x": -18,
      "y": 4,
      "z": -20,
      "name": "Cloth_Block_Wool_Purple"
    },
    {
      "x": -18,
      "y": 5,
      "z": -20,
      "name": "Cloth_Block_Wool_Purple"
    },
    {
      "x": -18,
      "y": 6,
      "z": -20,
      "name": "Cloth_Block_Wool_Purple"
    },
    {
      "x": -18,
      "y": 7,
      "z": -20,
      "name": "Cloth_Block_Wool_Purple"
    },
    {
      "x": -18,
      "y": 8,
      "z": -20,
      "name": "Cloth_Block_Wool_Purple"
    },
    {
      "x": -18,
      "y": 1,
      "z": -19,
      "name": "Cloth_Block_Wool_Purple"
    },
    {
      "x": -18,
      "y": 2,
      "z": -19,
      "name": "Cloth_Block_Wool_Purple"
    },
    {
      "x": -18,
      "y": 3,
      "z": -19,
      "name": "Cloth_Block_Wool_Purple"
    },
    {
      "x": -18,
      "y": 4,
      "z": -19,
      "name": "Cloth_Block_Wool_Purple"
    },
    {
      "x": -18,
      "y": 5,
      "z": -19,
      "name": "Cloth_Block_Wool_Purple"
    },
    {
      "x": -18,
      "y": 6,
      "z": -19,
      "name": "Cloth_Block_Wool_Purple"
    },
    {
      "x": -18,
      "y": 7,
      "z": -19,
      "name": "Cloth_Block_Wool_Purple"
    },
    {
      "x": -18,
      "y": 8,
      "z": -19,
      "name": "Cloth_Block_Wool_Purple"
    },
    {
      "x": -18,
      "y": 1,
      "z": -18,
      "name": "Cloth_Block_Wool_Purple"
    },
    {
      "x": -18,
      "y": 2,
      "z": -18,
      "name": "Cloth_Block_Wool_Purple"
    },
    {
      "x": -18,
      "y": 3,
      "z": -18,
      "name": "Cloth_Block_Wool_Purple"
    },
    {
      "x": -18,
      "y": 4,
      "z": -18,
      "name": "Cloth_Block_Wool_Purple"
    },
    {
      "x": -18,
      "y": 5,
      "z": -18,
      "name": "Cloth_Block_Wool_Purple"
    },
    {
      "x": -18,
      "y": 6,
      "z": -18,
      "name": "Cloth_Block_Wool_Purple"
    },
    {
      "x": -18,
      "y": 7,
      "z": -18,
      "name": "Cloth_Block_Wool_Purple"
    },
    {
      "x": -18,
      "y": 8,
      "z": -18,
      "name": "Cloth_Block_Wool_Purple"
    },
    {
      "x": -18,
      "y": 1,
      "z": -17,
      "name": "Cloth_Block_Wool_Purple"
    },
    {
      "x": -18,
      "y": 2,
      "z": -17,
      "name": "Cloth_Block_Wool_Purple"
    },
    {
      "x": -18,
      "y": 3,
      "z": -17,
      "name": "Cloth_Block_Wool_Purple"
    },
    {
      "x": -18,
      "y": 4,
      "z": -17,
      "name": "Cloth_Block_Wool_Purple"
    },
    {
      "x": -18,
      "y": 5,
      "z": -17,
      "name": "Cloth_Block_Wool_Purple"
    },
    {
      "x": -18,
      "y": 6,
      "z": -17,
      "name": "Cloth_Block_Wool_Purple"
    },
    {
      "x": -18,
      "y": 7,
      "z": -17,
      "name": "Cloth_Block_Wool_Purple"
    },
    {
      "x": -18,
      "y": 8,
      "z": -17,
      "name": "Cloth_Block_Wool_Purple"
    },
    {
      "x": -18,
      "y": 1,
      "z": -16,
      "name": "Cloth_Block_Wool_Purple"
    },
    {
      "x": -18,
      "y": 2,
      "z": -16,
      "name": "Cloth_Block_Wool_Purple"
    },
    {
      "x": -18,
      "y": 3,
      "z": -16,
      "name": "Cloth_Block_Wool_Purple"
    },
    {
      "x": -18,
      "y": 4,
      "z": -16,
      "name": "Cloth_Block_Wool_Purple"
    },
    {
      "x": -18,
      "y": 5,
      "z": -16,
      "name": "Cloth_Block_Wool_Purple"
    },
    {
      "x": -18,
      "y": 6,
      "z": -16,
      "name": "Cloth_Block_Wool_Purple"
    },
    {
      "x": -18,
      "y": 7,
      "z": -16,
      "name": "Cloth_Block_Wool_Purple"
    },
    {
      "x": -18,
      "y": 8,
      "z": -16,
      "name": "Cloth_Block_Wool_Purple"
    },
    {
      "x": -18,
      "y": 1,
      "z": -15,
      "name": "Cloth_Block_Wool_Purple"
    },
    {
      "x": -18,
      "y": 2,
      "z": -15,
      "name": "Cloth_Block_Wool_Purple"
    },
    {
      "x": -18,
      "y": 3,
      "z": -15,
      "name": "Cloth_Block_Wool_Purple"
    },
    {
      "x": -18,
      "y": 4,
      "z": -15,
      "name": "Cloth_Block_Wool_Purple"
    },
    {
      "x": -18,
      "y": 5,
      "z": -15,
      "name": "Cloth_Block_Wool_Purple"
    },
    {
      "x": -18,
      "y": 6,
      "z": -15,
      "name": "Cloth_Block_Wool_Purple"
    },
    {
      "x": -18,
      "y": 7,
      "z": -15,
      "name": "Cloth_Block_Wool_Purple"
    },
    {
      "x": -18,
      "y": 8,
      "z": -15,
      "name": "Cloth_Block_Wool_Purple"
    },
    {
      "x": -18,
      "y": 1,
      "z": -14,
      "name": "Cloth_Block_Wool_Purple"
    },
    {
      "x": -18,
      "y": 2,
      "z": -14,
      "name": "Cloth_Block_Wool_Purple"
    },
    {
      "x": -18,
      "y": 3,
      "z": -14,
      "name": "Cloth_Block_Wool_Purple"
    },
    {
      "x": -18,
      "y": 4,
      "z": -14,
      "name": "Cloth_Block_Wool_Purple"
    },
    {
      "x": -18,
      "y": 5,
      "z": -14,
      "name": "Cloth_Block_Wool_Purple"
    },
    {
      "x": -18,
      "y": 6,
      "z": -14,
      "name": "Cloth_Block_Wool_Purple"
    },
    {
      "x": -18,
      "y": 7,
      "z": -14,
      "name": "Cloth_Block_Wool_Purple"
    },
    {
      "x": -18,
      "y": 8,
      "z": -14,
      "name": "Cloth_Block_Wool_Purple"
    },
    {
      "x": -18,
      "y": 1,
      "z": -13,
      "name": "Cloth_Block_Wool_Purple"
    },
    {
      "x": -18,
      "y": 2,
      "z": -13,
      "name": "Cloth_Block_Wool_Purple"
    },
    {
      "x": -18,
      "y": 3,
      "z": -13,
      "name": "Cloth_Block_Wool_Purple"
    },
    {
      "x": -18,
      "y": 4,
      "z": -13,
      "name": "Cloth_Block_Wool_Purple"
    },
    {
      "x": -18,
      "y": 5,
      "z": -13,
      "name": "Cloth_Block_Wool_Purple"
    },
    {
      "x": -18,
      "y": 6,
      "z": -13,
      "name": "Cloth_Block_Wool_Purple"
    },
    {
      "x": -18,
      "y": 7,
      "z": -13,
      "name": "Cloth_Block_Wool_Purple"
    },
    {
      "x": -18,
      "y": 8,
      "z": -13,
      "name": "Cloth_Block_Wool_Purple"
    },
    {
      "x": -18,
      "y": 1,
      "z": -12,
      "name": "Cloth_Block_Wool_Purple"
    },
    {
      "x": -18,
      "y": 2,
      "z": -12,
      "name": "Cloth_Block_Wool_Purple"
    },
    {
      "x": -18,
      "y": 3,
      "z": -12,
      "name": "Cloth_Block_Wool_Purple"
    },
    {
      "x": -18,
      "y": 4,
      "z": -12,
      "name": "Cloth_Block_Wool_Purple"
    },
    {
      "x": -18,
      "y": 5,
      "z": -12,
      "name": "Cloth_Block_Wool_Purple"
    },
    {
      "x": -18,
      "y": 6,
      "z": -12,
      "name": "Cloth_Block_Wool_Purple"
    },
    {
      "x": -18,
      "y": 7,
      "z": -12,
      "name": "Cloth_Block_Wool_Purple"
    },
    {
      "x": -18,
      "y": 8,
      "z": -12,
      "name": "Cloth_Block_Wool_Purple"
    },
    {
      "x": -18,
      "y": 1,
      "z": -11,
      "name": "Cloth_Block_Wool_Purple"
    },
    {
      "x": -18,
      "y": 2,
      "z": -11,
      "name": "Cloth_Block_Wool_Purple"
    },
    {
      "x": -18,
      "y": 3,
      "z": -11,
      "name": "Cloth_Block_Wool_Purple"
    },
    {
      "x": -18,
      "y": 4,
      "z": -11,
      "name": "Cloth_Block_Wool_Purple"
    },
    {
      "x": -18,
      "y": 5,
      "z": -11,
      "name": "Cloth_Block_Wool_Purple"
    },
    {
      "x": -18,
      "y": 6,
      "z": -11,
      "name": "Cloth_Block_Wool_Purple"
    },
    {
      "x": -18,
      "y": 7,
      "z": -11,
      "name": "Cloth_Block_Wool_Purple"
    },
    {
      "x": -18,
      "y": 8,
      "z": -11,
      "name": "Cloth_Block_Wool_Purple"
    },
    {
      "x": -18,
      "y": 1,
      "z": -10,
      "name": "Cloth_Block_Wool_Purple"
    },
    {
      "x": -18,
      "y": 2,
      "z": -10,
      "name": "Cloth_Block_Wool_Purple"
    },
    {
      "x": -18,
      "y": 3,
      "z": -10,
      "name": "Cloth_Block_Wool_Purple"
    },
    {
      "x": -18,
      "y": 4,
      "z": -10,
      "name": "Cloth_Block_Wool_Purple"
    },
    {
      "x": -18,
      "y": 5,
      "z": -10,
      "name": "Cloth_Block_Wool_Purple"
    },
    {
      "x": -18,
      "y": 6,
      "z": -10,
      "name": "Cloth_Block_Wool_Purple"
    },
    {
      "x": -18,
      "y": 7,
      "z": -10,
      "name": "Cloth_Block_Wool_Purple"
    },
    {
      "x": -18,
      "y": 8,
      "z": -10,
      "name": "Cloth_Block_Wool_Purple"
    },
    {
      "x": -18,
      "y": 1,
      "z": -9,
      "name": "Cloth_Block_Wool_Purple"
    },
    {
      "x": -18,
      "y": 2,
      "z": -9,
      "name": "Cloth_Block_Wool_Purple"
    },
    {
      "x": -18,
      "y": 3,
      "z": -9,
      "name": "Cloth_Block_Wool_Purple"
    },
    {
      "x": -18,
      "y": 4,
      "z": -9,
      "name": "Cloth_Block_Wool_Purple"
    },
    {
      "x": -18,
      "y": 5,
      "z": -9,
      "name": "Cloth_Block_Wool_Purple"
    },
    {
      "x": -18,
      "y": 6,
      "z": -9,
      "name": "Cloth_Block_Wool_Purple"
    },
    {
      "x": -18,
      "y": 7,
      "z": -9,
      "name": "Cloth_Block_Wool_Purple"
    },
    {
      "x": -18,
      "y": 8,
      "z": -9,
      "name": "Cloth_Block_Wool_Purple"
    },
    {
      "x": -18,
      "y": 1,
      "z": -8,
      "name": "Cloth_Block_Wool_Purple"
    },
    {
      "x": -18,
      "y": 2,
      "z": -8,
      "name": "Cloth_Block_Wool_Purple"
    },
    {
      "x": -18,
      "y": 3,
      "z": -8,
      "name": "Cloth_Block_Wool_Purple"
    },
    {
      "x": -18,
      "y": 4,
      "z": -8,
      "name": "Cloth_Block_Wool_Purple"
    },
    {
      "x": -18,
      "y": 5,
      "z": -8,
      "name": "Cloth_Block_Wool_Purple"
    },
    {
      "x": -18,
      "y": 6,
      "z": -8,
      "name": "Cloth_Block_Wool_Purple"
    },
    {
      "x": -18,
      "y": 7,
      "z": -8,
      "name": "Cloth_Block_Wool_Purple"
    },
    {
      "x": -18,
      "y": 8,
      "z": -8,
      "name": "Cloth_Block_Wool_Purple"
    },
    {
      "x": -18,
      "y": 1,
      "z": -7,
      "name": "Cloth_Block_Wool_Purple"
    },
    {
      "x": -18,
      "y": 2,
      "z": -7,
      "name": "Cloth_Block_Wool_Purple"
    },
    {
      "x": -18,
      "y": 3,
      "z": -7,
      "name": "Cloth_Block_Wool_Purple"
    },
    {
      "x": -18,
      "y": 4,
      "z": -7,
      "name": "Cloth_Block_Wool_Purple"
    },
    {
      "x": -18,
      "y": 5,
      "z": -7,
      "name": "Cloth_Block_Wool_Purple"
    },
    {
      "x": -18,
      "y": 6,
      "z": -7,
      "name": "Cloth_Block_Wool_Purple"
    },
    {
      "x": -18,
      "y": 7,
      "z": -7,
      "name": "Cloth_Block_Wool_Purple"
    },
    {
      "x": -18,
      "y": 8,
      "z": -7,
      "name": "Cloth_Block_Wool_Purple"
    },
    {
      "x": -18,
      "y": 1,
      "z": -6,
      "name": "Cloth_Block_Wool_Purple"
    },
    {
      "x": -18,
      "y": 2,
      "z": -6,
      "name": "Cloth_Block_Wool_Purple"
    },
    {
      "x": -18,
      "y": 3,
      "z": -6,
      "name": "Cloth_Block_Wool_Purple"
    },
    {
      "x": -18,
      "y": 4,
      "z": -6,
      "name": "Cloth_Block_Wool_Purple"
    },
    {
      "x": -18,
      "y": 5,
      "z": -6,
      "name": "Cloth_Block_Wool_Purple"
    },
    {
      "x": -18,
      "y": 6,
      "z": -6,
      "name": "Cloth_Block_Wool_Purple"
    },
    {
      "x": -18,
      "y": 7,
      "z": -6,
      "name": "Cloth_Block_Wool_Purple"
    },
    {
      "x": -18,
      "y": 8,
      "z": -6,
      "name": "Cloth_Block_Wool_Purple"
    },
    {
      "x": -18,
      "y": 1,
      "z": -5,
      "name": "Cloth_Block_Wool_Purple"
    },
    {
      "x": -18,
      "y": 2,
      "z": -5,
      "name": "Cloth_Block_Wool_Purple"
    },
    {
      "x": -18,
      "y": 3,
      "z": -5,
      "name": "Cloth_Block_Wool_Purple"
    },
    {
      "x": -18,
      "y": 4,
      "z": -5,
      "name": "Cloth_Block_Wool_Purple"
    },
    {
      "x": -18,
      "y": 5,
      "z": -5,
      "name": "Cloth_Block_Wool_Purple"
    },
    {
      "x": -18,
      "y": 6,
      "z": -5,
      "name": "Cloth_Block_Wool_Purple"
    },
    {
      "x": -18,
      "y": 7,
      "z": -5,
      "name": "Cloth_Block_Wool_Purple"
    },
    {
      "x": -18,
      "y": 8,
      "z": -5,
      "name": "Cloth_Block_Wool_Purple"
    },
    {
      "x": -18,
      "y": 1,
      "z": -4,
      "name": "Cloth_Block_Wool_Purple"
    },
    {
      "x": -18,
      "y": 2,
      "z": -4,
      "name": "Cloth_Block_Wool_Purple"
    },
    {
      "x": -18,
      "y": 3,
      "z": -4,
      "name": "Cloth_Block_Wool_Purple"
    },
    {
      "x": -18,
      "y": 4,
      "z": -4,
      "name": "Cloth_Block_Wool_Purple"
    },
    {
      "x": -18,
      "y": 5,
      "z": -4,
      "name": "Cloth_Block_Wool_Purple"
    },
    {
      "x": -18,
      "y": 6,
      "z": -4,
      "name": "Cloth_Block_Wool_Purple"
    },
    {
      "x": -18,
      "y": 7,
      "z": -4,
      "name": "Cloth_Block_Wool_Purple"
    },
    {
      "x": -18,
      "y": 8,
      "z": -4,
      "name": "Cloth_Block_Wool_Purple"
    },
    {
      "x": -18,
      "y": 1,
      "z": -3,
      "name": "Cloth_Block_Wool_Purple"
    },
    {
      "x": -18,
      "y": 2,
      "z": -3,
      "name": "Cloth_Block_Wool_Purple"
    },
    {
      "x": -18,
      "y": 3,
      "z": -3,
      "name": "Cloth_Block_Wool_Purple"
    },
    {
      "x": -18,
      "y": 4,
      "z": -3,
      "name": "Cloth_Block_Wool_Purple"
    },
    {
      "x": -18,
      "y": 5,
      "z": -3,
      "name": "Cloth_Block_Wool_Purple"
    },
    {
      "x": -18,
      "y": 6,
      "z": -3,
      "name": "Cloth_Block_Wool_Purple"
    },
    {
      "x": -18,
      "y": 7,
      "z": -3,
      "name": "Cloth_Block_Wool_Purple"
    },
    {
      "x": -18,
      "y": 8,
      "z": -3,
      "name": "Cloth_Block_Wool_Purple"
    },
    {
      "x": -18,
      "y": 1,
      "z": -2,
      "name": "Cloth_Block_Wool_Purple"
    },
    {
      "x": -18,
      "y": 2,
      "z": -2,
      "name": "Cloth_Block_Wool_Purple"
    },
    {
      "x": -18,
      "y": 3,
      "z": -2,
      "name": "Cloth_Block_Wool_Purple"
    },
    {
      "x": -18,
      "y": 4,
      "z": -2,
      "name": "Cloth_Block_Wool_Purple"
    },
    {
      "x": -18,
      "y": 5,
      "z": -2,
      "name": "Cloth_Block_Wool_Purple"
    },
    {
      "x": -18,
      "y": 6,
      "z": -2,
      "name": "Cloth_Block_Wool_Purple"
    },
    {
      "x": -18,
      "y": 7,
      "z": -2,
      "name": "Cloth_Block_Wool_Purple"
    },
    {
      "x": -18,
      "y": 8,
      "z": -2,
      "name": "Cloth_Block_Wool_Purple"
    },
    {
      "x": -18,
      "y": 1,
      "z": -1,
      "name": "Cloth_Block_Wool_Purple"
    },
    {
      "x": -18,
      "y": 2,
      "z": -1,
      "name": "Cloth_Block_Wool_Purple"
    },
    {
      "x": -18,
      "y": 3,
      "z": -1,
      "name": "Cloth_Block_Wool_Purple"
    },
    {
      "x": -18,
      "y": 4,
      "z": -1,
      "name": "Cloth_Block_Wool_Purple"
    },
    {
      "x": -18,
      "y": 5,
      "z": -1,
      "name": "Cloth_Block_Wool_Purple"
    },
    {
      "x": -18,
      "y": 6,
      "z": -1,
      "name": "Cloth_Block_Wool_Purple"
    },
    {
      "x": -18,
      "y": 7,
      "z": -1,
      "name": "Cloth_Block_Wool_Purple"
    },
    {
      "x": -18,
      "y": 8,
      "z": -1,
      "name": "Cloth_Block_Wool_Purple"
    },
    {
      "x": -18,
      "y": 1,
      "z": 0,
      "name": "Cloth_Block_Wool_Purple"
    },
    {
      "x": -18,
      "y": 2,
      "z": 0,
      "name": "Cloth_Block_Wool_Purple"
    },
    {
      "x": -18,
      "y": 3,
      "z": 0,
      "name": "Cloth_Block_Wool_Purple"
    },
    {
      "x": -18,
      "y": 4,
      "z": 0,
      "name": "Cloth_Block_Wool_Purple"
    },
    {
      "x": -18,
      "y": 5,
      "z": 0,
      "name": "Cloth_Block_Wool_Purple"
    },
    {
      "x": -18,
      "y": 6,
      "z": 0,
      "name": "Cloth_Block_Wool_Purple"
    },
    {
      "x": -18,
      "y": 7,
      "z": 0,
      "name": "Cloth_Block_Wool_Purple"
    },
    {
      "x": -18,
      "y": 8,
      "z": 0,
      "name": "Cloth_Block_Wool_Purple"
    },
    {
      "x": -17,
      "y": 1,
      "z": -22,
      "name": "Cloth_Block_Wool_Purple"
    },
    {
      "x": -17,
      "y": 2,
      "z": -22,
      "name": "Cloth_Block_Wool_Purple"
    },
    {
      "x": -17,
      "y": 3,
      "z": -22,
      "name": "Cloth_Block_Wool_Purple"
    },
    {
      "x": -17,
      "y": 4,
      "z": -22,
      "name": "Cloth_Block_Wool_Purple"
    },
    {
      "x": -17,
      "y": 5,
      "z": -22,
      "name": "Cloth_Block_Wool_Purple"
    },
    {
      "x": -17,
      "y": 6,
      "z": -22,
      "name": "Cloth_Block_Wool_Purple"
    },
    {
      "x": -17,
      "y": 7,
      "z": -22,
      "name": "Cloth_Block_Wool_Purple"
    },
    {
      "x": -17,
      "y": 8,
      "z": -22,
      "name": "Cloth_Block_Wool_Purple"
    },
    {
      "x": -17,
      "y": 1,
      "z": -21,
      "name": "Cloth_Block_Wool_Purple"
    },
    {
      "x": -17,
      "y": 2,
      "z": -21,
      "name": "Cloth_Block_Wool_Purple"
    },
    {
      "x": -17,
      "y": 3,
      "z": -21,
      "name": "Cloth_Block_Wool_Purple"
    },
    {
      "x": -17,
      "y": 4,
      "z": -21,
      "name": "Cloth_Block_Wool_Purple"
    },
    {
      "x": -17,
      "y": 5,
      "z": -21,
      "name": "Cloth_Block_Wool_Purple"
    },
    {
      "x": -17,
      "y": 6,
      "z": -21,
      "name": "Cloth_Block_Wool_Purple"
    },
    {
      "x": -17,
      "y": 7,
      "z": -21,
      "name": "Cloth_Block_Wool_Purple"
    },
    {
      "x": -17,
      "y": 8,
      "z": -21,
      "name": "Cloth_Block_Wool_Purple"
    },
    {
      "x": -17,
      "y": 1,
      "z": -20,
      "name": "Cloth_Block_Wool_Purple"
    },
    {
      "x": -17,
      "y": 2,
      "z": -20,
      "name": "Cloth_Block_Wool_Purple"
    },
    {
      "x": -17,
      "y": 3,
      "z": -20,
      "name": "Cloth_Block_Wool_Purple"
    },
    {
      "x": -17,
      "y": 4,
      "z": -20,
      "name": "Cloth_Block_Wool_Purple"
    },
    {
      "x": -17,
      "y": 5,
      "z": -20,
      "name": "Cloth_Block_Wool_Purple"
    },
    {
      "x": -17,
      "y": 6,
      "z": -20,
      "name": "Cloth_Block_Wool_Purple"
    },
    {
      "x": -17,
      "y": 7,
      "z": -20,
      "name": "Cloth_Block_Wool_Purple"
    },
    {
      "x": -17,
      "y": 8,
      "z": -20,
      "name": "Cloth_Block_Wool_Purple"
    },
    {
      "x": -17,
      "y": 1,
      "z": -19,
      "name": "Cloth_Block_Wool_Purple"
    },
    {
      "x": -17,
      "y": 2,
      "z": -19,
      "name": "Cloth_Block_Wool_Purple"
    },
    {
      "x": -17,
      "y": 3,
      "z": -19,
      "name": "Cloth_Block_Wool_Purple"
    },
    {
      "x": -17,
      "y": 4,
      "z": -19,
      "name": "Cloth_Block_Wool_Purple"
    },
    {
      "x": -17,
      "y": 5,
      "z": -19,
      "name": "Cloth_Block_Wool_Purple"
    },
    {
      "x": -17,
      "y": 6,
      "z": -19,
      "name": "Cloth_Block_Wool_Purple"
    },
    {
      "x": -17,
      "y": 7,
      "z": -19,
      "name": "Cloth_Block_Wool_Purple"
    },
    {
      "x": -17,
      "y": 8,
      "z": -19,
      "name": "Cloth_Block_Wool_Purple"
    },
    {
      "x": -17,
      "y": 1,
      "z": -18,
      "name": "Cloth_Block_Wool_Purple"
    },
    {
      "x": -17,
      "y": 2,
      "z": -18,
      "name": "Cloth_Block_Wool_Purple"
    },
    {
      "x": -17,
      "y": 3,
      "z": -18,
      "name": "Cloth_Block_Wool_Purple"
    },
    {
      "x": -17,
      "y": 4,
      "z": -18,
      "name": "Cloth_Block_Wool_Purple"
    },
    {
      "x": -17,
      "y": 5,
      "z": -18,
      "name": "Cloth_Block_Wool_Purple"
    },
    {
      "x": -17,
      "y": 6,
      "z": -18,
      "name": "Cloth_Block_Wool_Purple"
    },
    {
      "x": -17,
      "y": 7,
      "z": -18,
      "name": "Cloth_Block_Wool_Purple"
    },
    {
      "x": -17,
      "y": 8,
      "z": -18,
      "name": "Cloth_Block_Wool_Purple"
    },
    {
      "x": -17,
      "y": 1,
      "z": -17,
      "name": "Cloth_Block_Wool_Purple"
    },
    {
      "x": -17,
      "y": 2,
      "z": -17,
      "name": "Cloth_Block_Wool_Purple"
    },
    {
      "x": -17,
      "y": 3,
      "z": -17,
      "name": "Cloth_Block_Wool_Purple"
    },
    {
      "x": -17,
      "y": 4,
      "z": -17,
      "name": "Cloth_Block_Wool_Purple"
    },
    {
      "x": -17,
      "y": 5,
      "z": -17,
      "name": "Cloth_Block_Wool_Purple"
    },
    {
      "x": -17,
      "y": 6,
      "z": -17,
      "name": "Cloth_Block_Wool_Purple"
    },
    {
      "x": -17,
      "y": 7,
      "z": -17,
      "name": "Cloth_Block_Wool_Purple"
    },
    {
      "x": -17,
      "y": 8,
      "z": -17,
      "name": "Cloth_Block_Wool_Purple"
    },
    {
      "x": -17,
      "y": 1,
      "z": -16,
      "name": "Cloth_Block_Wool_Purple"
    },
    {
      "x": -17,
      "y": 2,
      "z": -16,
      "name": "Cloth_Block_Wool_Purple"
    },
    {
      "x": -17,
      "y": 3,
      "z": -16,
      "name": "Cloth_Block_Wool_Purple"
    },
    {
      "x": -17,
      "y": 4,
      "z": -16,
      "name": "Cloth_Block_Wool_Purple"
    },
    {
      "x": -17,
      "y": 5,
      "z": -16,
      "name": "Cloth_Block_Wool_Purple"
    },
    {
      "x": -17,
      "y": 6,
      "z": -16,
      "name": "Cloth_Block_Wool_Purple"
    },
    {
      "x": -17,
      "y": 7,
      "z": -16,
      "name": "Cloth_Block_Wool_Purple"
    },
    {
      "x": -17,
      "y": 8,
      "z": -16,
      "name": "Cloth_Block_Wool_Purple"
    },
    {
      "x": -17,
      "y": 1,
      "z": -15,
      "name": "Cloth_Block_Wool_Purple"
    },
    {
      "x": -17,
      "y": 2,
      "z": -15,
      "name": "Cloth_Block_Wool_Purple"
    },
    {
      "x": -17,
      "y": 3,
      "z": -15,
      "name": "Cloth_Block_Wool_Purple"
    },
    {
      "x": -17,
      "y": 4,
      "z": -15,
      "name": "Cloth_Block_Wool_Purple"
    },
    {
      "x": -17,
      "y": 5,
      "z": -15,
      "name": "Cloth_Block_Wool_Purple"
    },
    {
      "x": -17,
      "y": 6,
      "z": -15,
      "name": "Cloth_Block_Wool_Purple"
    },
    {
      "x": -17,
      "y": 7,
      "z": -15,
      "name": "Cloth_Block_Wool_Purple"
    },
    {
      "x": -17,
      "y": 8,
      "z": -15,
      "name": "Cloth_Block_Wool_Purple"
    },
    {
      "x": -17,
      "y": 1,
      "z": -14,
      "name": "Cloth_Block_Wool_Purple"
    },
    {
      "x": -17,
      "y": 2,
      "z": -14,
      "name": "Cloth_Block_Wool_Purple"
    },
    {
      "x": -17,
      "y": 3,
      "z": -14,
      "name": "Cloth_Block_Wool_Purple"
    },
    {
      "x": -17,
      "y": 4,
      "z": -14,
      "name": "Cloth_Block_Wool_Purple"
    },
    {
      "x": -17,
      "y": 5,
      "z": -14,
      "name": "Cloth_Block_Wool_Purple"
    },
    {
      "x": -17,
      "y": 6,
      "z": -14,
      "name": "Cloth_Block_Wool_Purple"
    },
    {
      "x": -17,
      "y": 7,
      "z": -14,
      "name": "Cloth_Block_Wool_Purple"
    },
    {
      "x": -17,
      "y": 8,
      "z": -14,
      "name": "Cloth_Block_Wool_Purple"
    },
    {
      "x": -17,
      "y": 1,
      "z": -13,
      "name": "Cloth_Block_Wool_Purple"
    },
    {
      "x": -17,
      "y": 2,
      "z": -13,
      "name": "Cloth_Block_Wool_Purple"
    },
    {
      "x": -17,
      "y": 3,
      "z": -13,
      "name": "Cloth_Block_Wool_Purple"
    },
    {
      "x": -17,
      "y": 4,
      "z": -13,
      "name": "Cloth_Block_Wool_Purple"
    },
    {
      "x": -17,
      "y": 5,
      "z": -13,
      "name": "Cloth_Block_Wool_Purple"
    },
    {
      "x": -17,
      "y": 6,
      "z": -13,
      "name": "Cloth_Block_Wool_Purple"
    },
    {
      "x": -17,
      "y": 7,
      "z": -13,
      "name": "Cloth_Block_Wool_Purple"
    },
    {
      "x": -17,
      "y": 8,
      "z": -13,
      "name": "Cloth_Block_Wool_Purple"
    },
    {
      "x": -17,
      "y": 1,
      "z": -12,
      "name": "Cloth_Block_Wool_Purple"
    },
    {
      "x": -17,
      "y": 2,
      "z": -12,
      "name": "Cloth_Block_Wool_Purple"
    },
    {
      "x": -17,
      "y": 3,
      "z": -12,
      "name": "Cloth_Block_Wool_Purple"
    },
    {
      "x": -17,
      "y": 4,
      "z": -12,
      "name": "Cloth_Block_Wool_Purple"
    },
    {
      "x": -17,
      "y": 5,
      "z": -12,
      "name": "Cloth_Block_Wool_Purple"
    },
    {
      "x": -17,
      "y": 6,
      "z": -12,
      "name": "Cloth_Block_Wool_Purple"
    },
    {
      "x": -17,
      "y": 7,
      "z": -12,
      "name": "Cloth_Block_Wool_Purple"
    },
    {
      "x": -17,
      "y": 8,
      "z": -12,
      "name": "Cloth_Block_Wool_Purple"
    },
    {
      "x": -17,
      "y": 1,
      "z": -11,
      "name": "Cloth_Block_Wool_Purple"
    },
    {
      "x": -17,
      "y": 2,
      "z": -11,
      "name": "Cloth_Block_Wool_Purple"
    },
    {
      "x": -17,
      "y": 3,
      "z": -11,
      "name": "Cloth_Block_Wool_Purple"
    },
    {
      "x": -17,
      "y": 4,
      "z": -11,
      "name": "Cloth_Block_Wool_Purple"
    },
    {
      "x": -17,
      "y": 5,
      "z": -11,
      "name": "Cloth_Block_Wool_Purple"
    },
    {
      "x": -17,
      "y": 6,
