{
  "version": 8,
  "blockIdVersion": 11,
  "anchorX": 12,
  "anchorY": 0,
  "anchorZ": -11,
  "blocks": [
    {
      "x": -10,
      "y": 0,
      "z": -11,
      "name": "Cloth_Block_Wool_Purple"
    },
    {
      "x": -10,
      "y": 1,
      "z": -11,
      "name": "Cloth_Block_Wool_Purple"
    },
    {
      "x": -10,
      "y": 2,
      "z": -11,
      "name": "Cloth_Block_Wool_Purple"
    },
    {
      "x": -10,
      "y": 3,
      "z": -11,
      "name": "Cloth_Block_Wool_Purple"
    },
    {
      "x": -10,
      "y": 4,
      "z": -11,
      "name": "Cloth_Block_Wool_Purple"
    },
    {
      "x": -10,
      "y": 5,
      "z": -11,
      "name": "Cloth_Block_Wool_Purple"
    },
    {
      "x": -10,
      "y": 6,
      "z": -11,
      "name": "Cloth_Block_Wool_Purple"
    },
    {
      "x": -10,
      "y": 7,
      "z": -11,
      "name": "Cloth_Block_Wool_Purple"
    },
    {
      "x": -10,
      "y": 0,
      "z": -10,
      "name": "Cloth_Block_Wool_Purple"
    },
    {
      "x": -10,
      "y": 1,
      "z": -10,
      "name": "Cloth_Block_Wool_Purple"
    },
    {
      "x": -10,
      "y": 2,
      "z": -10,
      "name": "Cloth_Block_Wool_Purple"
    },
    {
      "x": -10,
      "y": 3,
      "z": -10,
      "name": "Cloth_Block_Wool_Purple"
    },
    {
      "x": -10,
      "y": 4,
      "z": -10,
      "name": "Cloth_Block_Wool_Purple"
    },
    {
      "x": -10,
      "y": 5,
      "z": -10,
      "name": "Cloth_Block_Wool_Purple"
    },
    {
      "x": -10,
      "y": 6,
      "z": -10,
      "name": "Cloth_Block_Wool_Purple"
    },
    {
      "x": -10,
      "y": 7,
      "z": -10,
      "name": "Cloth_Block_Wool_Purple"
    },
    {
      "x": -10,
      "y": 0,
      "z": -9,
      "name": "Cloth_Block_Wool_Purple"
    },
    {
      "x": -10,
      "y": 1,
      "z": -9,
      "name": "Cloth_Block_Wool_Purple"
    },
    {
      "x": -10,
      "y": 2,
      "z": -9,
      "name": "Cloth_Block_Wool_Purple"
    },
    {
      "x": -10,
      "y": 3,
      "z": -9,
      "name": "Cloth_Block_Wool_Purple"
    },
    {
      "x": -10,
      "y": 4,
      "z": -9,
      "name": "Cloth_Block_Wool_Purple"
    },
    {
      "x": -10,
      "y": 5,
      "z": -9,
      "name": "Cloth_Block_Wool_Purple"
    },
    {
      "x": -10,
      "y": 6,
      "z": -9,
      "name": "Cloth_Block_Wool_Purple"
    },
    {
      "x": -10,
      "y": 7,
      "z": -9,
      "name": "Cloth_Block_Wool_Purple"
    },
    {
      "x": -10,
      "y": 0,
      "z": -8,
      "name": "Cloth_Block_Wool_Purple"
    },
    {
      "x": -10,
      "y": 1,
      "z": -8,
      "name": "Cloth_Block_Wool_Purple"
    },
    {
      "x": -10,
      "y": 2,
      "z": -8,
      "name": "Cloth_Block_Wool_Purple"
    },
    {
      "x": -10,
      "y": 3,
      "z": -8,
      "name": "Cloth_Block_Wool_Purple"
    },
    {
      "x": -10,
      "y": 4,
      "z": -8,
      "name": "Cloth_Block_Wool_Purple"
    },
    {
      "x": -10,
      "y": 5,
      "z": -8,
      "name": "Cloth_Block_Wool_Purple"
    },
    {
      "x": -10,
      "y": 6,
      "z": -8,
      "name": "Cloth_Block_Wool_Purple"
    },
    {
      "x": -10,
      "y": 7,
      "z": -8,
      "name": "Cloth_Block_Wool_Purple"
    },
    {
      "x": -10,
      "y": 0,
      "z": -7,
      "name": "Cloth_Block_Wool_Purple"
    },
    {
      "x": -10,
      "y": 1,
      "z": -7,
      "name": "Cloth_Block_Wool_Purple"
    },
    {
      "x": -10,
      "y": 2,
      "z": -7,
      "name": "Cloth_Block_Wool_Purple"
    },
    {
      "x": -10,
      "y": 3,
      "z": -7,
      "name": "Cloth_Block_Wool_Purple"
    },
    {
      "x": -10,
      "y": 4,
      "z": -7,
      "name": "Cloth_Block_Wool_Purple"
    },
    {
      "x": -10,
      "y": 5,
      "z": -7,
      "name": "Cloth_Block_Wool_Purple"
    },
    {
      "x": -10,
      "y": 6,
      "z": -7,
      "name": "Cloth_Block_Wool_Purple"
    },
    {
      "x": -10,
      "y": 7,
      "z": -7,
      "name": "Cloth_Block_Wool_Purple"
    },
    {
      "x": -10,
      "y": 0,
      "z": -6,
      "name": "Cloth_Block_Wool_Purple"
    },
    {
      "x": -10,
      "y": 1,
      "z": -6,
      "name": "Cloth_Block_Wool_Purple"
    },
    {
      "x": -10,
      "y": 2,
      "z": -6,
      "name": "Cloth_Block_Wool_Purple"
    },
    {
      "x": -10,
      "y": 3,
      "z": -6,
      "name": "Cloth_Block_Wool_Purple"
    },
    {
      "x": -10,
      "y": 4,
      "z": -6,
      "name": "Cloth_Block_Wool_Purple"
    },
    {
      "x": -10,
      "y": 5,
      "z": -6,
      "name": "Cloth_Block_Wool_Purple"
    },
    {
      "x": -10,
      "y": 6,
      "z": -6,
      "name": "Cloth_Block_Wool_Purple"
    },
    {
      "x": -10,
      "y": 7,
      "z": -6,
      "name": "Cloth_Block_Wool_Purple"
    },
    {
      "x": -10,
      "y": 0,
      "z": -5,
      "name": "Cloth_Block_Wool_Purple"
    },
    {
      "x": -10,
      "y": 1,
      "z": -5,
      "name": "Cloth_Block_Wool_Purple"
    },
    {
      "x": -10,
      "y": 2,
      "z": -5,
      "name": "Cloth_Block_Wool_Purple"
    },
    {
      "x": -10,
      "y": 3,
      "z": -5,
      "name": "Cloth_Block_Wool_Purple"
    },
    {
      "x": -10,
      "y": 4,
      "z": -5,
      "name": "Cloth_Block_Wool_Purple"
    },
    {
      "x": -10,
      "y": 5,
      "z": -5,
      "name": "Cloth_Block_Wool_Purple"
    },
    {
      "x": -10,
      "y": 6,
      "z": -5,
      "name": "Cloth_Block_Wool_Purple"
    },
    {
      "x": -10,
      "y": 7,
      "z": -5,
      "name": "Cloth_Block_Wool_Purple"
    },
    {
      "x": -10,
      "y": 0,
      "z": -4,
      "name": "Cloth_Block_Wool_Purple"
    },
    {
      "x": -10,
      "y": 1,
      "z": -4,
      "name": "Cloth_Block_Wool_Purple"
    },
    {
      "x": -10,
      "y": 2,
      "z": -4,
      "name": "Cloth_Block_Wool_Purple"
    },
    {
      "x": -10,
      "y": 3,
      "z": -4,
      "name": "Cloth_Block_Wool_Purple"
    },
    {
      "x": -10,
      "y": 4,
      "z": -4,
      "name": "Cloth_Block_Wool_Purple"
    },
    {
      "x": -10,
      "y": 5,
      "z": -4,
      "name": "Cloth_Block_Wool_Purple"
    },
    {
      "x": -10,
      "y": 6,
      "z": -4,
      "name": "Cloth_Block_Wool_Purple"
    },
    {
      "x": -10,
      "y": 7,
      "z": -4,
      "name": "Cloth_Block_Wool_Purple"
    },
    {
      "x": -10,
      "y": 0,
      "z": -3,
      "name": "Cloth_Block_Wool_Purple"
    },
    {
      "x": -10,
      "y": 1,
      "z": -3,
      "name": "Cloth_Block_Wool_Purple"
    },
    {
      "x": -10,
      "y": 2,
      "z": -3,
      "name": "Cloth_Block_Wool_Purple"
    },
    {
      "x": -10,
      "y": 3,
      "z": -3,
      "name": "Cloth_Block_Wool_Purple"
    },
    {
      "x": -10,
      "y": 4,
      "z": -3,
      "name": "Cloth_Block_Wool_Purple"
    },
    {
      "x": -10,
      "y": 5,
      "z": -3,
      "name": "Cloth_Block_Wool_Purple"
    },
    {
      "x": -10,
      "y": 6,
      "z": -3,
      "name": "Cloth_Block_Wool_Purple"
    },
    {
      "x": -10,
      "y": 7,
      "z": -3,
      "name": "Cloth_Block_Wool_Purple"
    },
    {
      "x": -10,
      "y": 0,
      "z": -2,
      "name": "Cloth_Block_Wool_Purple"
    },
    {
      "x": -10,
      "y": 1,
      "z": -2,
      "name": "Cloth_Block_Wool_Purple"
    },
    {
      "x": -10,
      "y": 2,
      "z": -2,
      "name": "Cloth_Block_Wool_Purple"
    },
    {
      "x": -10,
      "y": 3,
      "z": -2,
      "name": "Cloth_Block_Wool_Purple"
    },
    {
      "x": -10,
      "y": 4,
      "z": -2,
      "name": "Cloth_Block_Wool_Purple"
    },
    {
      "x": -10,
      "y": 5,
      "z": -2,
      "name": "Cloth_Block_Wool_Purple"
    },
    {
      "x": -10,
      "y": 6,
      "z": -2,
      "name": "Cloth_Block_Wool_Purple"
    },
    {
      "x": -10,
      "y": 7,
      "z": -2,
      "name": "Cloth_Block_Wool_Purple"
    },
    {
      "x": -10,
      "y": 0,
      "z": -1,
      "name": "Cloth_Block_Wool_Purple"
    },
    {
      "x": -10,
      "y": 1,
      "z": -1,
      "name": "Cloth_Block_Wool_Purple"
    },
    {
      "x": -10,
      "y": 2,
      "z": -1,
      "name": "Cloth_Block_Wool_Purple"
    },
    {
      "x": -10,
      "y": 3,
      "z": -1,
      "name": "Cloth_Block_Wool_Purple"
    },
    {
      "x": -10,
      "y": 4,
      "z": -1,
      "name": "Cloth_Block_Wool_Purple"
    },
    {
      "x": -10,
      "y": 5,
      "z": -1,
      "name": "Cloth_Block_Wool_Purple"
    },
    {
      "x": -10,
      "y": 6,
      "z": -1,
      "name": "Cloth_Block_Wool_Purple"
    },
    {
      "x": -10,
      "y": 7,
      "z": -1,
      "name": "Cloth_Block_Wool_Purple"
    },
    {
      "x": -10,
      "y": 0,
      "z": 0,
      "name": "Cloth_Block_Wool_Purple"
    },
    {
      "x": -10,
      "y": 1,
      "z": 0,
      "name": "Cloth_Block_Wool_Purple"
    },
    {
      "x": -10,
      "y": 2,
      "z": 0,
      "name": "Cloth_Block_Wool_Purple"
    },
    {
      "x": -10,
      "y": 3,
      "z": 0,
      "name": "Cloth_Block_Wool_Purple"
    },
    {
      "x": -10,
      "y": 4,
      "z": 0,
      "name": "Cloth_Block_Wool_Purple"
    },
    {
      "x": -10,
      "y": 5,
      "z": 0,
      "name": "Cloth_Block_Wool_Purple"
    },
    {
      "x": -10,
      "y": 6,
      "z": 0,
      "name": "Cloth_Block_Wool_Purple"
    },
    {
      "x": -10,
      "y": 7,
      "z": 0,
      "name": "Cloth_Block_Wool_Purple"
    },
    {
      "x": -10,
      "y": 0,
      "z": 1,
      "name": "Cloth_Block_Wool_Purple"
    },
    {
      "x": -10,
      "y": 1,
      "z": 1,
      "name": "Cloth_Block_Wool_Purple"
    },
    {
      "x": -10,
      "y": 2,
      "z": 1,
      "name": "Cloth_Block_Wool_Purple"
    },
    {
      "x": -10,
      "y": 3,
      "z": 1,
      "name": "Cloth_Block_Wool_Purple"
    },
    {
      "x": -10,
      "y": 4,
      "z": 1,
      "name": "Cloth_Block_Wool_Purple"
    },
    {
      "x": -10,
      "y": 5,
      "z": 1,
      "name": "Cloth_Block_Wool_Purple"
    },
    {
      "x": -10,
      "y": 6,
      "z": 1,
      "name": "Cloth_Block_Wool_Purple"
    },
    {
      "x": -10,
      "y": 7,
      "z": 1,
      "name": "Cloth_Block_Wool_Purple"
    },
    {
      "x": -10,
      "y": 0,
      "z": 2,
      "name": "Cloth_Block_Wool_Purple"
    },
    {
      "x": -10,
      "y": 1,
      "z": 2,
      "name": "Cloth_Block_Wool_Purple"
    },
    {
      "x": -10,
      "y": 2,
      "z": 2,
      "name": "Cloth_Block_Wool_Purple"
    },
    {
      "x": -10,
      "y": 3,
      "z": 2,
      "name": "Cloth_Block_Wool_Purple"
    },
    {
      "x": -10,
      "y": 4,
      "z": 2,
      "name": "Cloth_Block_Wool_Purple"
    },
    {
      "x": -10,
      "y": 5,
      "z": 2,
      "name": "Cloth_Block_Wool_Purple"
    },
    {
      "x": -10,
      "y": 6,
      "z": 2,
      "name": "Cloth_Block_Wool_Purple"
    },
    {
      "x": -10,
      "y": 7,
      "z": 2,
      "name": "Cloth_Block_Wool_Purple"
    },
    {
      "x": -10,
      "y": 0,
      "z": 3,
      "name": "Cloth_Block_Wool_Purple"
    },
    {
      "x": -10,
      "y": 1,
      "z": 3,
      "name": "Cloth_Block_Wool_Purple"
    },
    {
      "x": -10,
      "y": 2,
      "z": 3,
      "name": "Cloth_Block_Wool_Purple"
    },
    {
      "x": -10,
      "y": 3,
      "z": 3,
      "name": "Cloth_Block_Wool_Purple"
    },
    {
      "x": -10,
      "y": 4,
      "z": 3,
      "name": "Cloth_Block_Wool_Purple"
    },
    {
      "x": -10,
      "y": 5,
      "z": 3,
      "name": "Cloth_Block_Wool_Purple"
    },
    {
      "x": -10,
      "y": 6,
      "z": 3,
      "name": "Cloth_Block_Wool_Purple"
    },
    {
      "x": -10,
      "y": 7,
      "z": 3,
      "name": "Cloth_Block_Wool_Purple"
    },
    {
      "x": -10,
      "y": 0,
      "z": 4,
      "name": "Cloth_Block_Wool_Purple"
    },
    {
      "x": -10,
      "y": 1,
      "z": 4,
      "name": "Cloth_Block_Wool_Purple"
    },
    {
      "x": -10,
      "y": 2,
      "z": 4,
      "name": "Cloth_Block_Wool_Purple"
    },
    {
      "x": -10,
      "y": 3,
      "z": 4,
      "name": "Cloth_Block_Wool_Purple"
    },
    {
      "x": -10,
      "y": 4,
      "z": 4,
      "name": "Cloth_Block_Wool_Purple"
    },
    {
      "x": -10,
      "y": 5,
      "z": 4,
      "name": "Cloth_Block_Wool_Purple"
    },
    {
      "x": -10,
      "y": 6,
      "z": 4,
      "name": "Cloth_Block_Wool_Purple"
    },
    {
      "x": -10,
      "y": 7,
      "z": 4,
      "name": "Cloth_Block_Wool_Purple"
    },
    {
      "x": -10,
      "y": 0,
      "z": 5,
      "name": "Cloth_Block_Wool_Purple"
    },
    {
      "x": -10,
      "y": 1,
      "z": 5,
      "name": "Cloth_Block_Wool_Purple"
    },
    {
      "x": -10,
      "y": 2,
      "z": 5,
      "name": "Cloth_Block_Wool_Purple"
    },
    {
      "x": -10,
      "y": 3,
      "z": 5,
      "name": "Cloth_Block_Wool_Purple"
    },
    {
      "x": -10,
      "y": 4,
      "z": 5,
      "name": "Cloth_Block_Wool_Purple"
    },
    {
      "x": -10,
      "y": 5,
      "z": 5,
      "name": "Cloth_Block_Wool_Purple"
    },
    {
      "x": -10,
      "y": 6,
      "z": 5,
      "name": "Cloth_Block_Wool_Purple"
    },
    {
      "x": -10,
      "y": 7,
      "z": 5,
      "name": "Cloth_Block_Wool_Purple"
    },
    {
      "x": -10,
      "y": 0,
      "z": 6,
      "name": "Cloth_Block_Wool_Purple"
    },
    {
      "x": -10,
      "y": 1,
      "z": 6,
      "name": "Cloth_Block_Wool_Purple"
    },
    {
      "x": -10,
      "y": 2,
      "z": 6,
      "name": "Cloth_Block_Wool_Purple"
    },
    {
      "x": -10,
      "y": 3,
      "z": 6,
      "name": "Cloth_Block_Wool_Purple"
    },
    {
      "x": -10,
      "y": 4,
      "z": 6,
      "name": "Cloth_Block_Wool_Purple"
    },
    {
      "x": -10,
      "y": 5,
      "z": 6,
      "name": "Cloth_Block_Wool_Purple"
    },
    {
      "x": -10,
      "y": 6,
      "z": 6,
      "name": "Cloth_Block_Wool_Purple"
    },
    {
      "x": -10,
      "y": 7,
      "z": 6,
      "name": "Cloth_Block_Wool_Purple"
    },
    {
      "x": -10,
      "y": 0,
      "z": 7,
      "name": "Cloth_Block_Wool_Purple"
    },
    {
      "x": -10,
      "y": 1,
      "z": 7,
      "name": "Cloth_Block_Wool_Purple"
    },
    {
      "x": -10,
      "y": 2,
      "z": 7,
      "name": "Cloth_Block_Wool_Purple"
    },
    {
      "x": -10,
      "y": 3,
      "z": 7,
      "name": "Cloth_Block_Wool_Purple"
    },
    {
      "x": -10,
      "y": 4,
      "z": 7,
      "name": "Cloth_Block_Wool_Purple"
    },
    {
      "x": -10,
      "y": 5,
      "z": 7,
      "name": "Cloth_Block_Wool_Purple"
    },
    {
      "x": -10,
      "y": 6,
      "z": 7,
      "name": "Cloth_Block_Wool_Purple"
    },
    {
      "x": -10,
      "y": 7,
      "z": 7,
      "name": "Cloth_Block_Wool_Purple"
    },
    {
      "x": -10,
      "y": 0,
      "z": 8,
      "name": "Cloth_Block_Wool_Purple"
    },
    {
      "x": -10,
      "y": 1,
      "z": 8,
      "name": "Cloth_Block_Wool_Purple"
    },
    {
      "x": -10,
      "y": 2,
      "z": 8,
      "name": "Cloth_Block_Wool_Purple"
    },
    {
      "x": -10,
      "y": 3,
      "z": 8,
      "name": "Cloth_Block_Wool_Purple"
    },
    {
      "x": -10,
      "y": 4,
      "z": 8,
      "name": "Cloth_Block_Wool_Purple"
    },
    {
      "x": -10,
      "y": 5,
      "z": 8,
      "name": "Cloth_Block_Wool_Purple"
    },
    {
      "x": -10,
      "y": 6,
      "z": 8,
      "name": "Cloth_Block_Wool_Purple"
    },
    {
      "x": -10,
      "y": 7,
      "z": 8,
      "name": "Cloth_Block_Wool_Purple"
    },
    {
      "x": -10,
      "y": 0,
      "z": 9,
      "name": "Cloth_Block_Wool_Purple"
    },
    {
      "x": -10,
      "y": 1,
      "z": 9,
      "name": "Cloth_Block_Wool_Purple"
    },
    {
      "x": -10,
      "y": 2,
      "z": 9,
      "name": "Cloth_Block_Wool_Purple"
    },
    {
      "x": -10,
      "y": 3,
      "z": 9,
      "name": "Cloth_Block_Wool_Purple"
    },
    {
      "x": -10,
      "y": 4,
      "z": 9,
      "name": "Cloth_Block_Wool_Purple"
    },
    {
      "x": -10,
      "y": 5,
      "z": 9,
      "name": "Cloth_Block_Wool_Purple"
    },
    {
      "x": -10,
      "y": 6,
      "z": 9,
      "name": "Cloth_Block_Wool_Purple"
    },
    {
      "x": -10,
      "y": 7,
      "z": 9,
      "name": "Cloth_Block_Wool_Purple"
    },
    {
      "x": -10,
      "y": 0,
      "z": 10,
      "name": "Cloth_Block_Wool_Purple"
    },
    {
      "x": -10,
      "y": 1,
      "z": 10,
      "name": "Cloth_Block_Wool_Purple"
    },
    {
      "x": -10,
      "y": 2,
      "z": 10,
      "name": "Cloth_Block_Wool_Purple"
    },
    {
      "x": -10,
      "y": 3,
      "z": 10,
      "name": "Cloth_Block_Wool_Purple"
    },
    {
      "x": -10,
      "y": 4,
      "z": 10,
      "name": "Cloth_Block_Wool_Purple"
    },
    {
      "x": -10,
      "y": 5,
      "z": 10,
      "name": "Cloth_Block_Wool_Purple"
    },
    {
      "x": -10,
      "y": 6,
      "z": 10,
      "name": "Cloth_Block_Wool_Purple"
    },
    {
      "x": -10,
      "y": 7,
      "z": 10,
      "name": "Cloth_Block_Wool_Purple"
    },
    {
      "x": -10,
      "y": 0,
      "z": 11,
      "name": "Cloth_Block_Wool_Purple"
    },
    {
      "x": -10,
      "y": 1,
      "z": 11,
      "name": "Cloth_Block_Wool_Purple"
    },
    {
      "x": -10,
      "y": 2,
      "z": 11,
      "name": "Cloth_Block_Wool_Purple"
    },
    {
      "x": -10,
      "y": 3,
      "z": 11,
      "name": "Cloth_Block_Wool_Purple"
    },
    {
      "x": -10,
      "y": 4,
      "z": 11,
      "name": "Cloth_Block_Wool_Purple"
    },
    {
      "x": -10,
      "y": 5,
      "z": 11,
      "name": "Cloth_Block_Wool_Purple"
    },
    {
      "x": -10,
      "y": 6,
      "z": 11,
      "name": "Cloth_Block_Wool_Purple"
    },
    {
      "x": -10,
      "y": 7,
      "z": 11,
      "name": "Cloth_Block_Wool_Purple"
    },
    {
      "x": -9,
      "y": 0,
      "z": -11,
      "name": "Cloth_Block_Wool_Purple"
    },
    {
      "x": -9,
      "y": 1,
      "z": -11,
      "name": "Cloth_Block_Wool_Purple"
    },
    {
      "x": -9,
      "y": 2,
      "z": -11,
      "name": "Cloth_Block_Wool_Purple"
    },
    {
      "x": -9,
      "y": 3,
      "z": -11,
      "name": "Cloth_Block_Wool_Purple"
    },
    {
      "x": -9,
      "y": 4,
      "z": -11,
      "name": "Cloth_Block_Wool_Purple"
    },
    {
      "x": -9,
      "y": 5,
      "z": -11,
      "name": "Cloth_Block_Wool_Purple"
    },
    {
      "x": -9,
      "y": 6,
      "z": -11,
      "name": "Cloth_Block_Wool_Purple"
    },
    {
      "x": -9,
      "y": 7,
      "z": -11,
      "name": "Cloth_Block_Wool_Purple"
    },
    {
      "x": -9,
      "y": 0,
      "z": -10,
      "name": "Cloth_Block_Wool_Purple"
    },
    {
      "x": -9,
      "y": 1,
      "z": -10,
      "name": "Cloth_Block_Wool_Purple"
    },
    {
      "x": -9,
      "y": 2,
      "z": -10,
      "name": "Cloth_Block_Wool_Purple"
    },
    {
      "x": -9,
      "y": 3,
      "z": -10,
      "name": "Cloth_Block_Wool_Purple"
    },
    {
      "x": -9,
      "y": 4,
      "z": -10,
      "name": "Cloth_Block_Wool_Purple"
    },
    {
      "x": -9,
      "y": 5,
      "z": -10,
      "name": "Cloth_Block_Wool_Purple"
    },
    {
      "x": -9,
      "y": 6,
      "z": -10,
      "name": "Cloth_Block_Wool_Purple"
    },
    {
      "x": -9,
      "y": 7,
      "z": -10,
      "name": "Cloth_Block_Wool_Purple"
    },
    {
      "x": -9,
      "y": 0,
      "z": -9,
      "name": "Cloth_Block_Wool_Purple"
    },
    {
      "x": -9,
      "y": 1,
      "z": -9,
      "name": "Cloth_Block_Wool_Purple"
    },
    {
      "x": -9,
      "y": 2,
      "z": -9,
      "name": "Cloth_Block_Wool_Purple"
    },
    {
      "x": -9,
      "y": 3,
      "z": -9,
      "name": "Cloth_Block_Wool_Purple"
    },
    {
      "x": -9,
      "y": 4,
      "z": -9,
      "name": "Cloth_Block_Wool_Purple"
    },
    {
      "x": -9,
      "y": 5,
      "z": -9,
      "name": "Cloth_Block_Wool_Purple"
    },
    {
      "x": -9,
      "y": 6,
      "z": -9,
      "name": "Cloth_Block_Wool_Purple"
    },
    {
      "x": -9,
      "y": 7,
      "z": -9,
      "name": "Cloth_Block_Wool_Purple"
    },
    {
      "x": -9,
      "y": 0,
      "z": -8,
      "name": "Cloth_Block_Wool_Purple"
    },
    {
      "x": -9,
      "y": 1,
      "z": -8,
      "name": "Cloth_Block_Wool_Purple"
    },
    {
      "x": -9,
      "y": 2,
      "z": -8,
      "name": "Cloth_Block_Wool_Purple"
    },
    {
      "x": -9,
      "y": 3,
      "z": -8,
      "name": "Cloth_Block_Wool_Purple"
    },
    {
      "x": -9,
      "y": 4,
      "z": -8,
      "name": "Cloth_Block_Wool_Purple"
    },
    {
      "x": -9,
      "y": 5,
      "z": -8,
      "name": "Cloth_Block_Wool_Purple"
    },
    {
      "x": -9,
      "y": 6,
      "z": -8,
      "name": "Cloth_Block_Wool_Purple"
    },
    {
      "x": -9,
      "y": 7,
      "z": -8,
      "name": "Cloth_Block_Wool_Purple"
    },
    {
      "x": -9,
      "y": 0,
      "z": -7,
      "name": "Cloth_Block_Wool_Purple"
    },
    {
      "x": -9,
      "y": 1,
      "z": -7,
      "name": "Cloth_Block_Wool_Purple"
    },
    {
      "x": -9,
      "y": 2,
      "z": -7,
      "name": "Cloth_Block_Wool_Purple"
    },
    {
      "x": -9,
      "y": 3,
      "z": -7,
      "name": "Cloth_Block_Wool_Purple"
    },
    {
      "x": -9,
      "y": 4,
      "z": -7,
      "name": "Cloth_Block_Wool_Purple"
    },
    {
      "x": -9,
      "y": 5,
      "z": -7,
      "name": "Cloth_Block_Wool_Purple"
    },
    {
      "x": -9,
      "y": 6,
      "z": -7,
      "name": "Cloth_Block_Wool_Purple"
    },
    {
      "x": -9,
      "y": 7,
      "z": -7,
      "name": "Cloth_Block_Wool_Purple"
    },
    {
      "x": -9,
      "y": 0,
      "z": -6,
      "name": "Cloth_Block_Wool_Purple"
    },
    {
      "x": -9,
      "y": 1,
      "z": -6,
      "name": "Cloth_Block_Wool_Purple"
    },
    {
      "x": -9,
      "y": 2,
      "z": -6,
      "name": "Cloth_Block_Wool_Purple"
    },
    {
      "x": -9,
      "y": 3,
      "z": -6,
      "name": "Cloth_Block_Wool_Purple"
    },
    {
      "x": -9,
      "y": 4,
      "z": -6,
      "name": "Cloth_Block_Wool_Purple"
    },
    {
      "x": -9,
      "y": 5,
      "z": -6,
      "name": "Cloth_Block_Wool_Purple"
    },
    {
      "x": -9,
      "y": 6,
      "z": -6,
      "name": "Cloth_Block_Wool_Purple"
    },
    {
      "x": -9,
      "y": 7,
      "z": -6,
      "name": "Cloth_Block_Wool_Purple"
    },
    {
      "x": -9,
      "y": 0,
      "z": -5,
      "name": "Cloth_Block_Wool_Purple"
    },
    {
      "x": -9,
      "y": 1,
      "z": -5,
      "name": "Cloth_Block_Wool_Purple"
    },
    {
      "x": -9,
      "y": 2,
      "z": -5,
      "name": "Cloth_Block_Wool_Purple"
    },
    {
      "x": -9,
      "y": 3,
      "z": -5,
      "name": "Cloth_Block_Wool_Purple"
    },
    {
      "x": -9,
      "y": 4,
      "z": -5,
      "name": "Cloth_Block_Wool_Purple"
    },
    {
      "x": -9,
      "y": 5,
      "z": -5,
      "name": "Cloth_Block_Wool_Purple"
    },
    {
      "x": -9,
      "y": 6,
      "z": -5,
      "name": "Cloth_Block_Wool_Purple"
    },
    {
      "x": -9,
      "y": 7,
      "z": -5,
      "name": "Cloth_Block_Wool_Purple"
    },
    {
      "x": -9,
      "y": 0,
      "z": -4,
      "name": "Cloth_Block_Wool_Purple"
    },
    {
      "x": -9,
      "y": 1,
      "z": -4,
      "name": "Cloth_Block_Wool_Purple"
    },
    {
      "x": -9,
      "y": 2,
      "z": -4,
      "name": "Cloth_Block_Wool_Purple"
    },
    {
      "x": -9,
      "y": 3,
      "z": -4,
      "name": "Cloth_Block_Wool_Purple"
    },
    {
      "x": -9,
      "y": 4,
      "z": -4,
      "name": "Cloth_Block_Wool_Purple"
    },
    {
      "x": -9,
      "y": 5,
      "z": -4,
      "name": "Cloth_Block_Wool_Purple"
    },
    {
      "x": -9,
      "y": 6,
      "z": -4,
      "name": "Cloth_Block_Wool_Purple"
    },
    {
      "x": -9,
      "y": 7,
      "z": -4,
      "name": "Cloth_Block_Wool_Purple"
    },
    {
      "x": -9,
      "y": 0,
      "z": -3,
      "name": "Cloth_Block_Wool_Purple"
    },
    {
      "x": -9,
      "y": 1,
      "z": -3,
      "name": "Cloth_Block_Wool_Purple"
    },
    {
      "x": -9,
      "y": 2,
      "z": -3,
      "name": "Cloth_Block_Wool_Purple"
    },
    {
      "x": -9,
      "y": 3,
      "z": -3,
      "name": "Cloth_Block_Wool_Purple"
    },
    {
      "x": -9,
      "y": 4,
      "z": -3,
      "name": "Cloth_Block_Wool_Purple"
    },
    {
      "x": -9,
      "y": 5,
      "z": -3,
      "name": "Cloth_Block_Wool_Purple"
    },
    {
      "x": -9,
      "y": 6,
      "z": -3,
      "name": "Cloth_Block_Wool_Purple"
    },
    {
      "x": -9,
      "y": 7,
      "z": -3,
      "name": "Cloth_Block_Wool_Purple"
    },
    {
      "x": -9,
      "y": 0,
      "z": -2,
      "name": "Cloth_Block_Wool_Purple"
    },
    {
      "x": -9,
      "y": 1,
      "z": -2,
      "name": "Cloth_Block_Wool_Purple"
    },
    {
      "x": -9,
      "y": 2,
      "z": -2,
      "name": "Cloth_Block_Wool_Purple"
    },
    {
      "x": -9,
      "y": 3,
      "z": -2,
      "name": "Cloth_Block_Wool_Purple"
    },
    {
      "x": -9,
      "y": 4,
      "z": -2,
      "name": "Cloth_Block_Wool_Purple"
    },
    {
      "x": -9,
      "y": 5,
      "z": -2,
      "name": "Cloth_Block_Wool_Purple"
    },
    {
      "x": -9,
      "y": 6,
      "z": -2,
      "name": "Cloth_Block_Wool_Purple"
    },
    {
      "x": -9,
      "y": 7,
      "z": -2,
      "name": "Cloth_Block_Wool_Purple"
    },
    {
      "x": -9,
      "y": 0,
      "z": -1,
      "name": "Cloth_Block_Wool_Purple"
    },
    {
      "x": -9,
      "y": 1,
      "z": -1,
      "name": "Cloth_Block_Wool_Purple"
    },
    {
      "x": -9,
      "y": 2,
      "z": -1,
      "name": "Cloth_Block_Wool_Purple"
    },
    {
      "x": -9,
      "y": 3,
      "z": -1,
      "name": "Cloth_Block_Wool_Purple"
    },
    {
      "x": -9,
      "y": 4,
      "z": -1,
      "name": "Cloth_Block_Wool_Purple"
    },
    {
      "x": -9,
      "y": 5,
      "z": -1,
      "name": "Cloth_Block_Wool_Purple"
    },
    {
      "x": -9,
      "y": 6,
      "z": -1,
      "name": "Cloth_Block_Wool_Purple"
    },
    {
      "x": -9,
      "y": 7,
      "z": -1,
      "name": "Cloth_Block_Wool_Purple"
    },
    {
      "x": -9,
      "y": 0,
      "z": 0,
      "name": "Cloth_Block_Wool_Purple"
    },
    {
      "x": -9,
      "y": 1,
      "z": 0,
      "name": "Cloth_Block_Wool_Purple"
    },
    {
      "x": -9,
      "y": 2,
      "z": 0,
      "name": "Cloth_Block_Wool_Purple"
    },
    {
      "x": -9,
      "y": 3,
      "z": 0,
      "name": "Cloth_Block_Wool_Purple"
    },
    {
      "x": -9,
      "y": 4,
      "z": 0,
      "name": "Cloth_Block_Wool_Purple"
    },
    {
      "x": -9,
      "y": 5,
      "z": 0,
      "name": "Cloth_Block_Wool_Purple"
    },
    {
      "x": -9,
      "y": 6,
      "z": 0,
      "name": "Cloth_Block_Wool_Purple"
    },
    {
      "x": -9,
      "y": 7,
      "z": 0,
      "name": "Cloth_Block_Wool_Purple"
    },
    {
      "x": -9,
      "y": 0,
      "z": 1,
      "name": "Cloth_Block_Wool_Purple"
    },
    {
      "x": -9,
      "y": 1,
      "z": 1,
      "name": "Cloth_Block_Wool_Purple"
    },
    {
      "x": -9,
      "y": 2,
      "z": 1,
      "name": "Cloth_Block_Wool_Purple"
    },
    {
      "x": -9,
      "y": 3,
      "z": 1,
      "name": "Cloth_Block_Wool_Purple"
    },
    {
      "x": -9,
      "y": 4,
      "z": 1,
      "name": "Cloth_Block_Wool_Purple"
    },
    {
      "x": -9,
      "y": 5,
      "z": 1,
      "name": "Cloth_Block_Wool_Purple"
    },
    {
      "x": -9,
      "y": 6,
      "z": 1,
      "name": "Cloth_Block_Wool_Purple"
    },
    {
      "x": -9,
      "y": 7,
      "z": 1,
      "name": "Cloth_Block_Wool_Purple"
    },
    {
      "x": -9,
      "y": 0,
      "z": 2,
      "name": "Cloth_Block_Wool_Purple"
    },
    {
      "x": -9,
      "y": 1,
      "z": 2,
      "name": "Cloth_Block_Wool_Purple"
    },
    {
      "x": -9,
      "y": 2,
      "z": 2,
      "name": "Cloth_Block_Wool_Purple"
    },
    {
      "x": -9,
      "y": 3,
      "z": 2,
      "name": "Cloth_Block_Wool_Purple"
    },
    {
      "x": -9,
      "y": 4,
      "z": 2,
      "name": "Cloth_Block_Wool_Purple"
    },
    {
      "x": -9,
      "y": 5,
      "z": 2,
      "name": "Cloth_Block_Wool_Purple"
    },
    {
      "x": -9,
      "y": 6,
      "z": 2,
      "name": "Cloth_Block_Wool_Purple"
    },
    {
      "x": -9,
      "y": 7,
      "z": 2,
      "name": "Cloth_Block_Wool_Purple"
    },
    {
      "x": -9,
      "y": 0,
      "z": 3,
      "name": "Cloth_Block_Wool_Purple"
    },
    {
      "x": -9,
      "y": 1,
      "z": 3,
      "name": "Cloth_Block_Wool_Purple"
    },
    {
      "x": -9,
      "y": 2,
      "z": 3,
      "name": "Cloth_Block_Wool_Purple"
    },
    {
      "x": -9,
      "y": 3,
      "z": 3,
      "name": "Cloth_Block_Wool_Purple"
    },
    {
      "x": -9,
      "y": 4,
      "z": 3,
      "name": "Cloth_Block_Wool_Purple"
    },
    {
      "x": -9,
      "y": 5,
      "z": 3,
      "name": "Cloth_Block_Wool_Purple"
    },
    {
      "x": -9,
      "y": 6,
      "z": 3,
      "name": "Cloth_Block_Wool_Purple"
    },
    {
      "x": -9,
      "y": 7,
      "z": 3,
      "name": "Cloth_Block_Wool_Purple"
    },
    {
      "x": -9,
      "y": 0,
      "z": 4,
      "name": "Cloth_Block_Wool_Purple"
    },
    {
      "x": -9,
      "y": 1,
      "z": 4,
      "name": "Cloth_Block_Wool_Purple"
    },
    {
      "x": -9,
      "y": 2,
      "z": 4,
      "name": "Cloth_Block_Wool_Purple"
    },
    {
      "x": -9,
      "y": 3,
      "z": 4,
      "name": "Cloth_Block_Wool_Purple"
    },
    {
      "x": -9,
      "y": 4,
      "z": 4,
      "name": "Cloth_Block_Wool_Purple"
    },
    {
      "x": -9,
      "y": 5,
      "z": 4,
      "name": "Cloth_Block_Wool_Purple"
    },
    {
      "x": -9,
      "y": 6,
      "z": 4,
      "name": "Cloth_Block_Wool_Purple"
    },
    {
      "x": -9,
      "y": 7,
      "z": 4,
      "name": "Cloth_Block_Wool_Purple"
    },
    {
      "x": -9,
      "y": 0,
      "z": 5,
      "name": "Cloth_Block_Wool_Purple"
    },
    {
      "x": -9,
      "y": 1,
      "z": 5,
      "name": "Cloth_Block_Wool_Purple"
    },
    {
      "x": -9,
      "y": 2,
      "z": 5,
      "name": "Cloth_Block_Wool_Purple"
    },
    {
      "x": -9,
      "y": 3,
      "z": 5,
      "name": "Cloth_Block_Wool_Purple"
    },
    {
      "x": -9,
      "y": 4,
      "z": 5,
      "name": "Cloth_Block_Wool_Purple"
    },
    {
      "x": -9,
      "y": 5,
      "z": 5,
      "name": "Cloth_Block_Wool_Purple"
    },
    {
      "x": -9,
      "y": 6,
      "z": 5,
      "name": "Cloth_Block_Wool_Purple"
    },
    {
      "x": -9,
      "y": 7,
      "z": 5,
      "name": "Cloth_Block_Wool_Purple"
    },
    {
      "x": -9,
      "y": 0,
      "z": 6,
      "name": "Cloth_Block_Wool_Purple"
    },
    {
      "x": -9,
      "y": 1,
      "z": 6,
      "name": "Cloth_Block_Wool_Purple"
    },
    {
      "x": -9,
      "y": 2,
      "z": 6,
      "name": "Cloth_Block_Wool_Purple"
    },
    {
      "x": -9,
      "y": 3,
      "z": 6,
      "name": "Cloth_Block_Wool_Purple"
    },
    {
      "x": -9,
      "y": 4,
      "z": 6,
      "name": "Cloth_Block_Wool_Purple"
    },
    {
      "x": -9,
      "y": 5,
      "z": 6,
      "name": "Cloth_Block_Wool_Purple"
    },
    {
      "x": -9,
      "y": 6,
      "z": 6,
      "name": "Cloth_Block_Wool_Purple"
    },
    {
      "x": -9,
      "y": 7,
      "z": 6,
      "name": "Cloth_Block_Wool_Purple"
    },
    {
      "x": -9,
      "y": 0,
      "z": 7,
      "name": "Cloth_Block_Wool_Purple"
    },
    {
      "x": -9,
      "y": 1,
      "z": 7,
      "name": "Cloth_Block_Wool_Purple"
    },
    {
      "x": -9,
      "y": 2,
      "z": 7,
      "name": "Cloth_Block_Wool_Purple"
    },
    {
      "x": -9,
      "y": 3,
      "z": 7,
      "name": "Cloth_Block_Wool_Purple"
    },
    {
      "x": -9,
      "y": 4,
      "z": 7,
      "name": "Cloth_Block_Wool_Purple"
    },
    {
      "x": -9,
      "y": 5,
      "z": 7,
      "name": "Cloth_Block_Wool_Purple"
    },
    {
      "x": -9,
      "y": 6,
      "z": 7,
      "name": "Cloth_Block_Wool_Purple"
    },
    {
      "x": -9,
      "y": 7,
      "z": 7,
      "name": "Cloth_Block_Wool_Purple"
    },
    {
      "x": -9,
      "y": 0,
      "z": 8,
      "name": "Cloth_Block_Wool_Purple"
    },
    {
      "x": -9,
      "y": 1,
      "z": 8,
      "name": "Cloth_Block_Wool_Purple"
    },
    {
      "x": -9,
      "y": 2,
      "z": 8,
      "name": "Cloth_Block_Wool_Purple"
    },
    {
      "x": -9,
      "y": 3,
      "z": 8,
      "name": "Cloth_Block_Wool_Purple"
    },
    {
      "x": -9,
      "y": 4,
      "z": 8,
      "name": "Cloth_Block_Wool_Purple"
    },
    {
      "x": -9,
      "y": 5,
      "z": 8,
      "name": "Cloth_Block_Wool_Purple"
    },
    {
      "x": -9,
      "y": 6,
      "z": 8,
      "name": "Cloth_Block_Wool_Purple"
    },
    {
      "x": -9,
      "y": 7,
      "z": 8,
      "name": "Cloth_Block_Wool_Purple"
    },
    {
      "x": -9,
      "y": 0,
      "z": 9,
      "name": "Cloth_Block_Wool_Purple"
    },
    {
      "x": -9,
      "y": 1,
      "z": 9,
      "name": "Cloth_Block_Wool_Purple"
    },
    {
      "x": -9,
      "y": 2,
      "z": 9,
      "name": "Cloth_Block_Wool_Purple"
    },
    {
      "x": -9,
      "y": 3,
      "z": 9,
      "name": "Cloth_Block_Wool_Purple"
    },
    {
      "x": -9,
      "y": 4,
      "z": 9,
      "name": "Cloth_Block_Wool_Purple"
    },
    {
      "x": -9,
      "y": 5,
      "z": 9,
      "name": "Cloth_Block_Wool_Purple"
    },
    {
      "x": -9,
      "y": 6,
      "z": 9,
      "name": "Cloth_Block_Wool_Purple"
    },
    {
      "x": -9,
      "y": 7,
      "z": 9,
      "name": "Cloth_Block_Wool_Purple"
    },
    {
      "x": -9,
      "y": 0,
      "z": 10,
      "name": "Cloth_Block_Wool_Purple"
    },
    {
      "x": -9,
      "y": 1,
      "z": 10,
      "name": "Cloth_Block_Wool_Purple"
    },
    {
      "x": -9,
      "y": 2,
      "z": 10,
      "name": "Cloth_Block_Wool_Purple"
    },
    {
      "x": -9,
      "y": 3,
      "z": 10,
      "name": "Cloth_Block_Wool_Purple"
    },
    {
      "x": -9,
      "y": 4,
      "z": 10,
      "name": "Cloth_Block_Wool_Purple"
    },
    {
      "x": -9,
      "y": 5,
      "z": 10,
      "name": "Cloth_Block_Wool_Purple"
    },
    {
      "x": -9,
      "y": 6,
      "z": 10,
      "name": "Cloth_Block_Wool_Purple"
    },
    {
      "x": -9,
      "y": 7,
      "z": 10,
      "name": "Cloth_Block_Wool_Purple"
    },
    {
      "x": -9,
      "y": 0,
      "z": 11,
      "name": "Cloth_Block_Wool_Purple"
    },
    {
      "x": -9,
      "y": 1,
      "z": 11,
      "name": "Cloth_Block_Wool_Purple"
    },
    {
      "x": -9,
      "y": 2,
      "z": 11,
      "name": "Cloth_Block_Wool_Purple"
    },
    {
      "x": -9,
      "y": 3,
      "z": 11,
      "name": "Cloth_Block_Wool_Purple"
    },
    {
      "x": -9,
      "y": 4,
      "z": 11,
      "name": "Cloth_Block_Wool_Purple"
    },
    {
      "x": -9,
      "y": 5,
      "z": 11,
      "name": "Cloth_Block_Wool_Purple"
    },
    {
      "x": -9,
      "y": 6,
      "z": 11,
      "name": "Cloth_Block_Wool_Purple"
    },
    {
      "x": -9,
      "y": 7,
      "z": 11,
      "name": "Cloth_Block_Wool_Purple"
    },
    {
      "x": -8,
      "y": 0,
      "z": -11,
      "name": "Cloth_Block_Wool_Purple"
    },
    {
      "x": -8,
      "y": 1,
      "z": -11,
      "name": "Cloth_Block_Wool_Purple"
    },
    {
      "x": -8,
      "y": 2,
      "z": -11,
      "name": "Cloth_Block_Wool_Purple"
    },
    {
      "x": -8,
      "y": 3,
      "z": -11,
      "name": "Cloth_Block_Wool_Purple"
    },
    {
      "x": -8,
      "y": 4,
      "z": -11,
      "name": "Cloth_Block_Wool_Purple"
    },
    {
      "x": -8,
      "y": 5,
      "z": -11,
      "name": "Cloth_Block_Wool_Purple"
    },
    {
      "x": -8,
      "y": 6,
      "z": -11,
      "name": "Cloth_Block_Wool_Purple"
    },
    {
      "x": -8,
      "y": 7,
      "z": -11,
      "name": "Cloth_Block_Wool_Purple"
    },
    {
      "x": -8,
      "y": 0,
      "z": -10,
      "name": "Cloth_Block_Wool_Purple"
    },
    {
      "x": -8,
      "y": 1,
      "z": -10,
      "name": "Cloth_Block_Wool_Purple"
    },
    {
      "x": -8,
      "y": 2,
      "z": -10,
      "name": "Cloth_Block_Wool_Purple"
    },
    {
      "x": -8,
      "y": 3,
      "z": -10,
      "name": "Cloth_Block_Wool_Purple"
    },
    {
      "x": -8,
      "y": 4,
      "z": -10,
      "name": "Cloth_Block_Wool_Purple"
    },
    {
      "x": -8,
      "y": 5,
      "z": -10,
      "name": "Cloth_Block_Wool_Purple"
    },
    {
      "x": -8,
      "y": 6,
      "z": -10,
      "name": "Cloth_Block_Wool_Purple"
    },
    {
      "x": -8,
      "y": 7,
      "z": -10,
      "name": "Cloth_Block_Wool_Purple"
    },
    {
      "x": -8,
      "y": 0,
      "z": -9,
      "name": "Cloth_Block_Wool_Purple"
    },
    {
      "x": -8,
      "y": 1,
      "z": -9,
      "name": "Cloth_Block_Wool_Purple"
    },
    {
      "x": -8,
      "y": 2,
      "z": -9,
      "name": "Cloth_Block_Wool_Purple"
    },
    {
      "x": -8,
      "y": 3,
      "z": -9,
      "name": "Cloth_Block_Wool_Purple"
    },
    {
      "x": -8,
      "y": 4,
      "z": -9,
      "name": "Cloth_Block_Wool_Purple"
    },
    {
      "x": -8,
      "y": 5,
      "z": -9,
      "name": "Cloth_Block_Wool_Purple"
    },
    {
      "x": -8,
      "y": 6,
      "z": -9,
      "name": "Cloth_Block_Wool_Purple"
    },
    {
      "x": -8,
      "y": 7,
      "z": -9,
      "name": "Cloth_Block_Wool_Purple"
    },
    {
      "x": -8,
      "y": 0,
      "z": -8,
      "name": "Cloth_Block_Wool_Purple"
    },
    {
      "x": -8,
      "y": 1,
      "z": -8,
      "name": "Cloth_Block_Wool_Purple"
    },
    {
      "x": -8,
      "y": 2,
      "z": -8,
      "name": "Cloth_Block_Wool_Purple"
    },
    {
      "x": -8,
      "y": 3,
      "z": -8,
      "name": "Cloth_Block_Wool_Purple"
    },
    {
      "x": -8,
      "y": 4,
      "z": -8,
      "name": "Cloth_Block_Wool_Purple"
    },
    {
      "x": -8,
      "y": 5,
      "z": -8,
      "name": "Cloth_Block_Wool_Purple"
    },
    {
      "x": -8,
      "y": 6,
      "z": -8,
      "name": "Cloth_Block_Wool_Purple"
    },
    {
      "x": -8,
      "y": 7,
      "z": -8,
      "name": "Cloth_Block_Wool_Purple"
    },
    {
      "x": -8,
      "y": 0,
      "z": -7,
      "name": "Cloth_Block_Wool_Purple"
    },
    {
      "x": -8,
      "y": 1,
      "z": -7,
      "name": "Cloth_Block_Wool_Purple"
    },
    {
      "x": -8,
      "y": 2,
      "z": -7,
      "name": "Cloth_Block_Wool_Purple"
    },
    {
      "x": -8,
      "y": 3,
      "z": -7,
      "name": "Cloth_Block_Wool_Purple"
    },
    {
      "x": -8,
      "y": 4,
      "z": -7,
      "name": "Cloth_Block_Wool_Purple"
    },
    {
      "x": -8,
      "y": 5,
      "z": -7,
      "name": "Cloth_Block_Wool_Purple"
    },
    {
      "x": -8,
      "y": 6,
      "z": -7,
      "name": "Cloth_Block_Wool_Purple"
    },
    {
      "x": -8,
      "y": 7,
      "z": -7,
      "name": "Cloth_Block_Wool_Purple"
    },
    {
      "x": -8,
      "y": 0,
      "z": -6,
      "name": "Cloth_Block_Wool_Purple"
    },
    {
      "x": -8,
      "y": 1,
      "z": -6,
      "name": "Cloth_Block_Wool_Purple"
    },
    {
      "x": -8,
      "y": 2,
      "z": -6,
      "name": "Cloth_Block_Wool_Purple"
    },
    {
      "x": -8,
      "y": 3,
      "z": -6,
      "name": "Cloth_Block_Wool_Purple"
    },
    {
      "x": -8,
      "y": 4,
      "z": -6,
      "name": "Cloth_Block_Wool_Purple"
    },
    {
      "x": -8,
      "y": 5,
      "z": -6,
      "name": "Cloth_Block_Wool_Purple"
    },
    {
      "x": -8,
      "y": 6,
      "z": -6,
      "name": "Cloth_Block_Wool_Purple"
    },
    {
      "x": -8,
      "y": 7,
      "z": -6,
      "name": "Cloth_Block_Wool_Purple"
    },
    {
      "x": -8,
      "y": 0,
      "z": -5,
      "name": "Cloth_Block_Wool_Purple"
    },
    {
      "x": -8,
      "y": 1,
      "z": -5,
      "name": "Cloth_Block_Wool_Purple"
    },
    {
      "x": -8,
      "y": 2,
      "z": -5,
      "name": "Cloth_Block_Wool_Purple"
    },
    {
      "x": -8,
      "y": 3,
      "z": -5,
      "name": "Cloth_Block_Wool_Purple"
    },
    {
      "x": -8,
      "y": 4,
      "z": -5,
      "name": "Cloth_Block_Wool_Purple"
    },
    {
      "x": -8,
      "y": 5,
      "z": -5,
      "name": "Cloth_Block_Wool_Purple"
    },
    {
      "x": -8,
      "y": 6,
      "z": -5,
      "name": "Cloth_Block_Wool_Purple"
    },
    {
      "x": -8,
      "y": 7,
      "z": -5,
      "name": "Cloth_Block_Wool_Purple"
    },
    {
      "x": -8,
      "y": 0,
      "z": -4,
      "name": "Cloth_Block_Wool_Purple"
    },
    {
      "x": -8,
      "y": 1,
      "z": -4,
      "name": "Cloth_Block_Wool_Purple"
    },
    {
      "x": -8,
      "y": 2,
      "z": -4,
      "name": "Cloth_Block_Wool_Purple"
    },
    {
      "x": -8,
      "y": 3,
      "z": -4,
      "name": "Cloth_Block_Wool_Purple"
    },
    {
      "x": -8,
      "y": 4,
      "z": -4,
      "name": "Cloth_Block_Wool_Purple"
    },
    {
      "x": -8,
      "y": 5,
      "z": -4,
      "name": "Cloth_Block_Wool_Purple"
    },
    {
      "x": -8,
      "y": 6,
      "z": -4,
      "name": "Cloth_Block_Wool_Purple"
    },
    {
      "x": -8,
      "y": 7,
      "z": -4,
      "name": "Cloth_Block_Wool_Purple"
    },
    {
      "x": -8,
      "y": 0,
      "z": -3,
      "name": "Cloth_Block_Wool_Purple"
    },
    {
      "x": -8,
      "y": 1,
      "z": -3,
      "name": "Cloth_Block_Wool_Purple"
    },
    {
      "x": -8,
      "y": 2,
      "z": -3,
      "name": "Cloth_Block_Wool_Purple"
    },
    {
      "x": -8,
      "y": 3,
      "z": -3,
      "name": "Cloth_Block_Wool_Purple"
    },
    {
      "x": -8,
      "y": 4,
      "z": -3,
      "name": "Cloth_Block_Wool_Purple"
    },
    {
      "x": -8,
      "y": 5,
      "z": -3,
      "name": "Cloth_Block_Wool_Purple"
    },
    {
      "x": -8,
      "y": 6,
      "z": -3,
      "name": "Cloth_Block_Wool_Purple"
    },
    {
      "x": -8,
      "y": 7,
      "z": -3,
      "name": "Cloth_Block_Wool_Purple"
    },
    {
      "x": -8,
      "y": 0,
      "z": -2,
      "name": "Cloth_Block_Wool_Purple"
    },
    {
      "x": -8,
      "y": 1,
      "z": -2,
      "name": "Cloth_Block_Wool_Purple"
    },
    {
      "x": -8,
      "y": 2,
      "z": -2,
      "name": "Cloth_Block_Wool_Purple"
    },
    {
      "x": -8,
      "y": 3,
      "z": -2,
      "name": "Cloth_Block_Wool_Purple"
    },
    {
      "x": -8,
      "y": 4,
      "z": -2,
      "name": "Cloth_Block_Wool_Purple"
    },
    {
      "x": -8,
      "y": 5,
      "z": -2,
      "name": "Cloth_Block_Wool_Purple"
    },
    {
      "x": -8,
      "y": 6,
      "z": -2,
      "name": "Cloth_Block_Wool_Purple"
    },
    {
      "x": -8,
      "y": 7,
      "z": -2,
      "name": "Cloth_Block_Wool_Purple"
    },
    {
      "x": -8,
      "y": 0,
      "z": -1,
      "name": "Cloth_Block_Wool_Purple"
    },
    {
      "x": -8,
      "y": 1,
      "z": -1,
      "name": "Cloth_Block_Wool_Purple"
    },
    {
      "x": -8,
      "y": 2,
      "z": -1,
      "name": "Cloth_Block_Wool_Purple"
    },
    {
      "x": -8,
      "y": 3,
      "z": -1,
      "name": "Cloth_Block_Wool_Purple"
    },
    {
      "x": -8,
      "y": 4,
      "z": -1,
      "name": "Cloth_Block_Wool_Purple"
    },
    {
      "x": -8,
      "y": 5,
      "z": -1,
      "name": "Cloth_Block_Wool_Purple"
    },
    {
      "x": -8,
      "y": 6,
      "z": -1,
      "name": "Cloth_Block_Wool_Purple"
    },
    {
      "x": -8,
      "y": 7,
      "z": -1,
      "name": "Cloth_Block_Wool_Purple"
    },
    {
      "x": -8,
      "y": 0,
      "z": 0,
      "name": "Cloth_Block_Wool_Purple"
    },
    {
      "x": -8,
      "y": 1,
      "z": 0,
      "name": "Cloth_Block_Wool_Purple"
    },
    {
      "x": -8,
      "y": 2,
      "z": 0,
      "name": "Cloth_Block_Wool_Purple"
    },
    {
      "x": -8,
      "y": 3,
      "z": 0,
      "name": "Cloth_Block_Wool_Purple"
    },
    {
      "x": -8,
      "y": 4,
      "z": 0,
      "name": "Cloth_Block_Wool_Purple"
    },
    {
      "x": -8,
      "y": 5,
      "z": 0,
      "name": "Cloth_Block_Wool_Purple"
    },
    {
      "x": -8,
      "y": 6,
      "z": 0,
      "name": "Cloth_Block_Wool_Purple"
    },
    {
      "x": -8,
      "y": 7,
      "z": 0,
      "name": "Cloth_Block_Wool_Purple"
    },
    {
      "x": -8,
      "y": 0,
      "z": 1,
      "name": "Cloth_Block_Wool_Purple"
    },
    {
      "x": -8,
      "y": 1,
      "z": 1,
      "name": "Cloth_Block_Wool_Purple"
    },
    {
      "x": -8,
      "y": 2,
      "z": 1,
      "name": "Cloth_Block_Wool_Purple"
    },
    {
      "x": -8,
      "y": 3,
      "z": 1,
      "name": "Cloth_Block_Wool_Purple"
    },
    {
      "x": -8,
      "y": 4,
      "z": 1,
      "name": "Cloth_Block_Wool_Purple"
    },
    {
      "x": -8,
      "y": 5,
      "z": 1,
      "name": "Cloth_Block_Wool_Purple"
    },
    {
      "x": -8,
      "y": 6,
      "z": 1,
      "name": "Cloth_Block_Wool_Purple"
    },
    {
      "x": -8,
      "y": 7,
      "z": 1,
      "name": "Cloth_Block_Wool_Purple"
    },
    {
      "x": -8,
      "y": 0,
      "z": 2,
      "name": "Cloth_Block_Wool_Purple"
    },
    {
      "x": -8,
      "y": 1,
      "z": 2,
      "name": "Cloth_Block_Wool_Purple"
    },
    {
      "x": -8,
      "y": 2,
      "z": 2,
      "name": "Cloth_Block_Wool_Purple"
    },
    {
      "x": -8,
      "y": 3,
      "z": 2,
      "name": "Cloth_Block_Wool_Purple"
    },
    {
      "x": -8,
      "y": 4,
      "z": 2,
      "name": "Cloth_Block_Wool_Purple"
    },
    {
      "x": -8,
      "y": 5,
      "z": 2,
      "name": "Cloth_Block_Wool_Purple"
    },
    {
      "x": -8,
      "y": 6,
      "z": 2,
      "name": "Cloth_Block_Wool_Purple"
    },
    {
      "x": -8,
      "y": 7,
      "z": 2,
      "name": "Cloth_Block_Wool_Purple"
    },
    {
      "x": -8,
      "y": 0,
      "z": 3,
      "name": "Cloth_Block_Wool_Purple"
    },
    {
      "x": -8,
      "y": 1,
      "z": 3,
      "name": "Cloth_Block_Wool_Purple"
    },
    {
      "x": -8,
      "y": 2,
      "z": 3,
      "name": "Cloth_Block_Wool_Purple"
    },
    {
      "x": -8,
      "y": 3,
      "z": 3,
      "name": "Cloth_Block_Wool_Purple"
    },
    {
      "x": -8,
      "y": 4,
      "z": 3,
      "name": "Cloth_Block_Wool_Purple"
    },
    {
      "x": -8,
      "y": 5,
      "z": 3,
      "name": "Cloth_Block_Wool_Purple"
    },
    {
      "x": -8,
      "y": 6,
      "z": 3,
      "name": "Cloth_Block_Wool_Purple"
    },
    {
      "x": -8,
      "y": 7,
      "z": 3,
      "name": "Cloth_Block_Wool_Purple"
    },
    {
      "x": -8,
      "y": 0,
      "z": 4,
      "name": "Cloth_Block_Wool_Purple"
    },
    {
      "x": -8,
      "y": 1,
      "z": 4,
      "name": "Cloth_Block_Wool_Purple"
    },
    {
      "x": -8,
      "y": 2,
      "z": 4,
      "name": "Cloth_Block_Wool_Purple"
    },
    {
      "x": -8,
      "y": 3,
      "z": 4,
      "name": "Cloth_Block_Wool_Purple"
    },
    {
      "x": -8,
      "y": 4,
      "z": 4,
      "name": "Cloth_Block_Wool_Purple"
    },
    {
      "x": -8,
      "y": 5,
      "z": 4,
      "name": "Cloth_Block_Wool_Purple"
    },
    {
      "x": -8,
      "y": 6,
      "z": 4,
      "name": "Cloth_Block_Wool_Purple"
    },
    {
      "x": -8,
      "y": 7,
      "z": 4,
      "name": "Cloth_Block_Wool_Purple"
    },
    {
      "x": -8,
      "y": 0,
      "z": 5,
      "name": "Cloth_Block_Wool_Purple"
    },
    {
      "x": -8,
      "y": 1,
      "z": 5,
      "name": "Cloth_Block_Wool_Purple"
    },
    {
      "x": -8,
      "y": 2,
      "z": 5,
      "name": "Cloth_Block_Wool_Purple"
    },
    {
      "x": -8,
      "y": 3,
      "z": 5,
      "name": "Cloth_Block_Wool_Purple"
    },
    {
      "x": -8,
      "y": 4,
      "z": 5,
      "name": "Cloth_Block_Wool_Purple"
    },
    {
      "x": -8,
      "y": 5,
      "z": 5,
      "name": "Cloth_Block_Wool_Purple"
    },
    {
      "x": -8,
      "y": 6,
      "z": 5,
      "name": "Cloth_Block_Wool_Purple"
    },
    {
      "x": -8,
      "y": 7,
      "z": 5,
      "name": "Cloth_Block_Wool_Purple"
    },
    {
      "x": -8,
      "y": 0,
      "z": 6,
      "name": "Cloth_Block_Wool_Purple"
    },
    {
      "x": -8,
      "y": 1,
      "z": 6,
      "name": "Cloth_Block_Wool_Purple"
    },
    {
      "x": -8,
      "y": 2,
      "z": 6,
      "name": "Cloth_Block_Wool_Purple"
    },
    {
      "x": -8,
      "y": 3,
      "z": 6,
      "name": "Cloth_Block_Wool_Purple"
    },
    {
      "x": -8,
      "y": 4,
      "z": 6,
      "name": "Cloth_Block_Wool_Purple"
    },
    {
      "x": -8,
      "y": 5,
      "z": 6,
      "name": "Cloth_Block_Wool_Purple"
    },
    {
      "x": -8,
      "y": 6,
      "z": 6,
      "name": "Cloth_Block_Wool_Purple"
    },
    {
      "x": -8,
      "y": 7,
      "z": 6,
      "name": "Cloth_Block_Wool_Purple"
    },
    {
      "x": -8,
      "y": 0,
      "z": 7,
      "name": "Cloth_Block_Wool_Purple"
    },
    {
      "x": -8,
      "y": 1,
      "z": 7,
      "name": "Cloth_Block_Wool_Purple"
    },
    {
      "x": -8,
      "y": 2,
      "z": 7,
      "name": "Cloth_Block_Wool_Purple"
    },
    {
      "x": -8,
      "y": 3,
      "z": 7,
      "name": "Cloth_Block_Wool_Purple"
    },
    {
      "x": -8,
      "y": 4,
      "z": 7,
      "name": "Cloth_Block_Wool_Purple"
    },
    {
      "x": -8,
      "y": 5,
      "z": 7,
      "name": "Cloth_Block_Wool_Purple"
    },
    {
      "x": -8,
      "y": 6,
      "z": 7,
      "name": "Cloth_Block_Wool_Purple"
    },
    {
      "x": -8,
      "y": 7,
      "z": 7,
      "name": "Cloth_Block_Wool_Purple"
    },
    {
      "x": -8,
      "y": 0,
      "z": 8,
      "name": "Cloth_Block_Wool_Purple"
    },
    {
      "x": -8,
      "y": 1,
      "z": 8,
      "name": "Cloth_Block_Wool_Purple"
    },
    {
      "x": -8,
      "y": 2,
      "z": 8,
      "name": "Cloth_Block_Wool_Purple"
    },
    {
      "x": -8,
      "y": 3,
      "z": 8,
      "name": "Cloth_Block_Wool_Purple"
    },
    {
      "x": -8,
      "y": 4,
      "z": 8,
      "name": "Cloth_Block_Wool_Purple"
    },
    {
      "x": -8,
      "y": 5,
      "z": 8,
      "name": "Cloth_Block_Wool_Purple"
    },
    {
      "x": -8,
      "y": 6,
      "z": 8,
      "name": "Cloth_Block_Wool_Purple"
    },
    {
      "x": -8,
      "y": 7,
      "z": 8,
      "name": "Cloth_Block_Wool_Purple"
    },
    {
      "x": -8,
      "y": 0,
      "z": 9,
      "name": "Cloth_Block_Wool_Purple"
    },
    {
      "x": -8,
      "y": 1,
      "z": 9,
      "name": "Cloth_Block_Wool_Purple"
    },
    {
      "x": -8,
      "y": 2,
      "z": 9,
      "name": "Cloth_Block_Wool_Purple"
    },
    {
      "x": -8,
      "y": 3,
      "z": 9,
      "name": "Cloth_Block_Wool_Purple"
    },
    {
      "x": -8,
      "y": 4,
      "z": 9,
      "name": "Cloth_Block_Wool_Purple"
    },
    {
      "x": -8,
      "y": 5,
      "z": 9,
      "name": "Cloth_Block_Wool_Purple"
    },
    {
      "x": -8,
      "y": 6,
      "z": 9,
      "name": "Cloth_Block_Wool_Purple"
    },
    {
      "x": -8,
      "y": 7,
      "z": 9,
      "name": "Cloth_Block_Wool_Purple"
    },
    {
      "x": -8,
      "y": 0,
      "z": 10,
      "name": "Cloth_Block_Wool_Purple"
    },
    {
      "x": -8,
      "y": 1,
      "z": 10,
      "name": "Cloth_Block_Wool_Purple"
    },
    {
      "x": -8,
      "y": 2,
      "z": 10,
      "name": "Cloth_Block_Wool_Purple"
    },
    {
      "x": -8,
      "y": 3,
      "z": 10,
      "name": "Cloth_Block_Wool_Purple"
    },
    {
      "x": -8,
      "y": 4,
      "z": 10,
      "name": "Cloth_Block_Wool_Purple"
    },
    {
      "x": -8,
      "y": 5,
      "z": 10,
      "name": "Cloth_Block_Wool_Purple"
    },
    {
      "x": -8,
      "y": 6,
      "z": 10,
      "name": "Cloth_Block_Wool_Purple"
    },
    {
      "x": -8,
      "y": 7,
      "z": 10,
      "name": "Cloth_Block_Wool_Purple"
    },
    {
      "x": -8,
      "y": 0,
      "z": 11,
      "name": "Cloth_Block_Wool_Purple"
    },
    {
      "x": -8,
      "y": 1,
      "z": 11,
      "name": "Cloth_Block_Wool_Purple"
    },
    {
      "x": -8,
      "y": 2,
      "z": 11,
      "name": "Cloth_Block_Wool_Purple"
    },
    {
      "x": -8,
      "y": 3,
      "z": 11,
      "name": "Cloth_Block_Wool_Purple"
    },
    {
      "x": -8,
      "y": 4,
      "z": 11,
      "name": "Cloth_Block_Wool_Purple"
    },
    {
      "x": -8,
      "y": 5,
      "z": 11,
      "name": "Cloth_Block_Wool_Purple"
    },
    {
      "x": -8,
      "y": 6,
      "z": 11,
      "name": "Cloth_Block_Wool_Purple"
    },
    {
      "x": -8,
      "y": 7,
      "z": 11,
      "name": "Cloth_Block_Wool_Purple"
    },
    {
      "x": -7,
      "y": 0,
      "z": -11,
      "name": "Cloth_Block_Wool_Purple"
    },
    {
      "x": -7,
      "y": 1,
      "z": -11,
      "name": "Cloth_Block_Wool_Purple"
    },
    {
      "x": -7,
      "y": 2,
      "z": -11,
      "name": "Cloth_Block_Wool_Purple"
    },
    {
      "x": -7,
      "y": 3,
      "z": -11,
      "name": "Cloth_Block_Wool_Purple"
    },
    {
      "x": -7,
      "y": 4,
      "z": -11,
      "name": "Cloth_Block_Wool_Purple"
    },
    {
      "x": -7,
      "y": 5,
      "z": -11,
      "name": "Cloth_Block_Wool_Purple"
    },
    {
      "x": -7,
      "y": 6,
      "z": -11,
      "name": "Cloth_Block_Wool_Purple"
    },
    {
      "x": -7,
      "y": 7,
      "z": -11,
      "name": "Cloth_Block_Wool_Purple"
    },
    {
      "x": -7,
      "y": 0,
      "z": -10,
      "name": "Cloth_Block_Wool_Purple"
    },
    {
      "x": -7,
      "y": 1,
      "z": -10,
      "name": "Cloth_Block_Wool_Purple"
    },
    {
      "x": -7,
      "y": 2,
      "z": -10,
      "name": "Cloth_Block_Wool_Purple"
    },
    {
      "x": -7,
      "y": 3,
      "z": -10,
      "name": "Cloth_Block_Wool_Purple"
    },
    {
      "x": -7,
      "y": 4,
      "z": -10,
      "name": "Cloth_Block_Wool_Purple"
    },
    {
      "x": -7,
      "y": 5,
      "z": -10,
      "name": "Cloth_Block_Wool_Purple"
    },
    {
      "x": -7,
      "y": 6,
      "z": -10,
      "name": "Cloth_Block_Wool_Purple"
    },
    {
      "x": -7,
      "y": 7,
      "z": -10,
      "name": "Cloth_Block_Wool_Purple"
    },
    {
      "x": -7,
      "y": 0,
      "z": -9,
      "name": "Cloth_Block_Wool_Purple"
    },
    {
      "x": -7,
      "y": 1,
      "z": -9,
      "name": "Cloth_Block_Wool_Purple"
    },
    {
      "x": -7,
      "y": 2,
      "z": -9,
      "name": "Cloth_Block_Wool_Purple"
    },
    {
      "x": -7,
      "y": 3,
      "z": -9,
      "name": "Cloth_Block_Wool_Purple"
    },
    {
      "x": -7,
      "y": 4,
      "z": -9,
      "name": "Cloth_Block_Wool_Purple"
    },
    {
      "x": -7,
      "y": 5,
      "z": -9,
      "name": "Cloth_Block_Wool_Purple"
    },
    {
      "x": -7,
      "y": 6,
      "z": -9,
      "name": "Cloth_Block_Wool_Purple"
    },
    {
      "x": -7,
      "y": 7,
      "z": -9,
      "name": "Cloth_Block_Wool_Purple"
    },
    {
      "x": -7,
      "y": 0,
      "z": -8,
      "name": "Cloth_Block_Wool_Purple"
    },
    {
      "x": -7,
      "y": 1,
      "z": -8,
      "name": "Cloth_Block_Wool_Purple"
    },
    {
      "x": -7,
      "y": 2,
      "z": -8,
      "name": "Cloth_Block_Wool_Purple"
    },
    {
      "x": -7,
      "y": 3,
      "z": -8,
      "name": "Cloth_Block_Wool_Purple"
    },
    {
      "x": -7,
      "y": 4,
      "z": -8,
      "name": "Cloth_Block_Wool_Purple"
    },
    {
      "x": -7,
      "y": 5,
      "z": -8,
      "name": "Cloth_Block_Wool_Purple"
    },
    {
      "x": -7,
      "y": 6,
      "z": -8,
      "name": "Cloth_Block_Wool_Purple"
    },
    {
      "x": -7,
      "y": 7,
      "z": -8,
      "name": "Cloth_Block_Wool_Purple"
    },
    {
      "x": -7,
      "y": 0,
      "z": -7,
      "name": "Cloth_Block_Wool_Purple"
    },
    {
      "x": -7,
      "y": 1,
      "z": -7,
      "name": "Cloth_Block_Wool_Purple"
    },
    {
      "x": -7,
      "y": 2,
      "z": -7,
      "name": "Cloth_Block_Wool_Purple"
    },
    {
      "x": -7,
      "y": 3,
      "z": -7,
      "name": "Cloth_Block_Wool_Purple"
    },
    {
      "x": -7,
      "y": 4,
      "z": -7,
      "name": "Cloth_Block_Wool_Purple"
    },
    {
      "x": -7,
      "y": 5,
      "z": -7,
      "name": "Cloth_Block_Wool_Purple"
    },
    {
      "x": -7,
      "y": 6,
      "z": -7,
      "name": "Cloth_Block_Wool_Purple"
    },
    {
      "x": -7,
      "y": 7,
      "z": -7,
      "name": "Cloth_Block_Wool_Purple"
    },
    {
      "x": -7,
      "y": 0,
      "z": -6,
      "name": "Cloth_Block_Wool_Purple"
    },
    {
      "x": -7,
      "y": 1,
      "z": -6,
      "name": "Cloth_Block_Wool_Purple"
    },
    {
      "x": -7,
      "y": 2,
      "z": -6,
      "name": "Cloth_Block_Wool_Purple"
    },
    {
      "x": -7,
      "y": 3,
      "z": -6,
      "name": "Cloth_Block_Wool_Purple"
    },
    {
      "x": -7,
      "y": 4,
      "z": -6,
      "name": "Cloth_Block_Wool_Purple"
    },
    {
      "x": -7,
      "y": 5,
      "z": -6,
      "name": "Cloth_Block_Wool_Purple"
    },
    {
      "x": -7,
      "y": 6,
      "z": -6,
      "name": "Cloth_Block_Wool_Purple"
    },
    {
      "x": -7,
      "y": 7,
      "z": -6,
      "name": "Cloth_Block_Wool_Purple"
    },
    {
      "x": -7,
      "y": 0,
      "z": -5,
      "name": "Cloth_Block_Wool_Purple"
    },
    {
      "x": -7,
      "y": 1,
      "z": -5,
      "name": "Cloth_Block_Wool_Purple"
    },
    {
      "x": -7,
      "y": 2,
      "z": -5,
      "name": "Cloth_Block_Wool_Purple"
    },
    {
      "x": -7,
      "y": 3,
      "z": -5,
      "name": "Cloth_Block_Wool_Purple"
    },
    {
      "x": -7,
      "y": 4,
      "z": -5,
      "name": "Cloth_Block_Wool_Purple"
    },
    {
      "x": -7,
      "y": 5,
      "z": -5,
      "name": "Cloth_Block_Wool_Purple"
    },
    {
      "x": -7,
      "y": 6,
      "z": -5,
      "name": "Cloth_Block_Wool_Purple"
    },
    {
      "x": -7,
      "y": 7,
      "z": -5,
      "name": "Cloth_Block_Wool_Purple"
    },
    {
      "x": -7,
      "y": 0,
      "z": -4,
      "name": "Cloth_Block_Wool_Purple"
    },
    {
      "x": -7,
      "y": 1,
      "z": -4,
      "name": "Cloth_Block_Wool_Purple"
    },
    {
      "x": -7,
      "y": 2,
      "z": -4,
      "name": "Cloth_Block_Wool_Purple"
    },
    {
      "x": -7,
      "y": 3,
      "z": -4,
      "name": "Cloth_Block_Wool_Purple"
    },
    {
      "x": -7,
      "y": 4,
      "z": -4,
      "name": "Cloth_Block_Wool_Purple"
    },
    {
      "x": -7,
      "y": 5,
      "z": -4,
      "name": "Cloth_Block_Wool_Purple"
    },
    {
      "x": -7,
      "y": 6,
      "z": -4,
      "name": "Cloth_Block_Wool_Purple"
    },
    {
      "x": -7,
      "y": 7,
      "z": -4,
      "name": "Cloth_Block_Wool_Purple"
    },
    {
      "x": -7,
      "y": 0,
      "z": -3,
      "name": "Cloth_Block_Wool_Purple"
    },
    {
      "x": -7,
      "y": 1,
      "z": -3,
      "name": "Cloth_Block_Wool_Purple"
    },
    {
      "x": -7,
      "y": 2,
      "z": -3,
      "name": "Cloth_Block_Wool_Purple"
    },
    {
      "x": -7,
      "y": 3,
      "z": -3,
      "name": "Cloth_Block_Wool_Purple"
    },
    {
      "x": -7,
      "y": 4,
      "z": -3,
      "name": "Cloth_Block_Wool_Purple"
    },
    {
      "x": -7,
      "y": 5,
      "z": -3,
      "name": "Cloth_Block_Wool_Purple"
    },
    {
      "x": -7,
      "y": 6,
      "z": -3,
      "name": "Cloth_Block_Wool_Purple"
    },
    {
      "x": -7,
      "y": 7,
      "z": -3,
      "name": "Cloth_Block_Wool_Purple"
    },
    {
      "x": -7,
      "y": 0,
      "z": -2,
      "name": "Cloth_Block_Wool_Purple"
    },
    {
      "x": -7,
      "y": 1,
      "z": -2,
      "name": "Cloth_Block_Wool_Purple"
    },
    {
      "x": -7,
      "y": 2,
      "z": -2,
      "name": "Cloth_Block_Wool_Purple"
    },
    {
      "x": -7,
      "y": 3,
      "z": -2,
      "name": "Cloth_Block_Wool_Purple"
    },
    {
      "x": -7,
      "y": 4,
      "z": -2,
      "name": "Cloth_Block_Wool_Purple"
    },
    {
      "x": -7,
      "y": 5,
      "z": -2,
      "name": "Cloth_Block_Wool_Purple"
    },
    {
      "x": -7,
      "y": 6,
      "z": -2,
      "name": "Cloth_Block_Wool_Purple"
    },
    {
      "x": -7,
      "y": 7,
      "z": -2,
      "name": "Cloth_Block_Wool_Purple"
    },
    {
      "x": -7,
      "y": 0,
      "z": -1,
      "name": "Cloth_Block_Wool_Purple"
    },
    {
      "x": -7,
      "y": 1,
      "z": -1,
      "name": "Cloth_Block_Wool_Purple"
    },
    {
      "x": -7,
      "y": 2,
      "z": -1,
      "name": "Cloth_Block_Wool_Purple"
    },
    {
      "x": -7,
      "y": 3,
      "z": -1,
      "name": "Cloth_Block_Wool_Purple"
    },
    {
      "x": -7,
      "y": 4,
      "z": -1,
      "name": "Cloth_Block_Wool_Purple"
    },
    {
      "x": -7,
      "y": 5,
      "z": -1,
      "name": "Cloth_Block_Wool_Purple"
    },
    {
      "x": -7,
      "y": 6,
      "z": -1,
      "name": "Cloth_Block_Wool_Purple"
    },
    {
      "x": -7,
      "y": 7,
      "z": -1,
      "name": "Cloth_Block_Wool_Purple"
    },
    {
      "x": -7,
      "y": 0,
      "z": 0,
      "name": "Cloth_Block_Wool_Purple"
    },
    {
      "x": -7,
      "y": 1,
      "z": 0,
      "name": "Cloth_Block_Wool_Purple"
    },
    {
      "x": -7,
      "y": 2,
      "z": 0,
      "name": "Cloth_Block_Wool_Purple"
    },
    {
      "x": -7,
      "y": 3,
      "z": 0,
      "name": "Cloth_Block_Wool_Purple"
    },
    {
      "x": -7,
      "y": 4,
      "z": 0,
      "name": "Cloth_Block_Wool_Purple"
    },
    {
      "x": -7,
      "y": 5,
      "z": 0,
      "name": "Cloth_Block_Wool_Purple"
    },
    {
      "x": -7,
      "y": 6,
      "z": 0,
      "name": "Cloth_Block_Wool_Purple"
    },
    {
      "x": -7,
      "y": 7,
      "z": 0,
      "name": "Cloth_Block_Wool_Purple"
    },
    {
      "x": -7,
      "y": 0,
      "z": 1,
      "name": "Cloth_Block_Wool_Purple"
    },
    {
      "x": -7,
      "y": 1,
      "z": 1,
      "name": "Cloth_Block_Wool_Purple"
    },
    {
      "x": -7,
      "y": 2,
      "z": 1,
      "name": "Cloth_Block_Wool_Purple"
    },
    {
      "x": -7,
      "y": 3,
      "z": 1,
      "name": "Cloth_Block_Wool_Purple"
    },
    {
      "x": -7,
      "y": 4,
      "z": 1,
      "name": "Cloth_Block_Wool_Purple"
    },
    {
      "x": -7,
      "y": 5,
      "z": 1,
      "name": "Cloth_Block_Wool_Purple"
    },
    {
      "x": -7,
      "y": 6,
      "z": 1,
      "name": "Cloth_Block_Wool_Purple"
    },
    {
      "x": -7,
      "y": 7,
      "z": 1,
      "name": "Cloth_Block_Wool_Purple"
    },
    {
      "x": -7,
      "y": 0,
      "z": 2,
      "name": "Cloth_Block_Wool_Purple"
    },
    {
      "x": -7,
      "y": 1,
      "z": 2,
      "name": "Cloth_Block_Wool_Purple"
    },
    {
      "x": -7,
      "y": 2,
      "z": 2,
      "name": "Cloth_Block_Wool_Purple"
    },
    {
      "x": -7,
      "y": 3,
      "z": 2,
      "name": "Cloth_Block_Wool_Purple"
    },
    {
      "x": -7,
      "y": 4,
      "z": 2,
      "name": "Cloth_Block_Wool_Purple"
    },
    {
      "x": -7,
      "y": 5,
      "z": 2,
      "name": "Cloth_Block_Wool_Purple"
    },
    {
      "x": -7,
      "y": 6,
      "z": 2,
      "name": "Cloth_Block_Wool_Purple"
    },
    {
      "x": -7,
      "y": 7,
      "z": 2,
      "name": "Cloth_Block_Wool_Purple"
    },
    {
      "x": -7,
      "y": 0,
      "z": 3,
      "name": "Cloth_Block_Wool_Purple"
    },
    {
      "x": -7,
      "y": 1,
      "z": 3,
      "name": "Cloth_Block_Wool_Purple"
    },
    {
      "x": -7,
      "y": 2,
      "z": 3,
      "name": "Cloth_Block_Wool_Purple"
    },
    {
      "x": -7,
      "y": 3,
      "z": 3,
      "name": "Cloth_Block_Wool_Purple"
    },
    {
      "x": -7,
      "y": 4,
      "z": 3,
      "name": "Cloth_Block_Wool_Purple"
    },
    {
      "x": -7,
      "y": 5,
      "z": 3,
      "name": "Cloth_Block_Wool_Purple"
    },
    {
      "x": -7,
      "y": 6,
      "z": 3,
      "name": "Cloth_Block_Wool_Purple"
    },
    {
      "x": -7,
      "y": 7,
      "z": 3,
      "name": "Cloth_Block_Wool_Purple"
    },
    {
      "x": -7,
      "y": 0,
      "z": 4,
      "name": "Cloth_Block_Wool_Purple"
    },
    {
      "x": -7,
      "y": 1,
      "z": 4,
      "name": "Cloth_Block_Wool_Purple"
    },
    {
      "x": -7,
      "y": 2,
      "z": 4,
      "name": "Cloth_Block_Wool_Purple"
    },
    {
      "x": -7,
      "y": 3,
      "z": 4,
      "name": "Cloth_Block_Wool_Purple"
    },
    {
      "x": -7,
      "y": 4,
      "z": 4,
      "name": "Cloth_Block_Wool_Purple"
    },
    {
      "x": -7,
      "y": 5,
      "z": 4,
      "name": "Cloth_Block_Wool_Purple"
    },
    {
      "x": -7,
      "y": 6,
      "z": 4,
      "name": "Cloth_Block_Wool_Purple"
    },
    {
      "x": -7,
      "y": 7,
      "z": 4,
      "name": "Cloth_Block_Wool_Purple"
    },
    {
      "x": -7,
      "y": 0,
      "z": 5,
      "name": "Cloth_Block_Wool_Purple"
    },
    {
      "x": -7,
      "y": 1,
      "z": 5,
      "name": "Cloth_Block_Wool_Purple"
    },
    {
      "x": -7,
      "y": 2,
      "z": 5,
      "name": "Cloth_Block_Wool_Purple"
    },
    {
      "x": -7,
      "y": 3,
      "z": 5,
      "name": "Cloth_Block_Wool_Purple"
    },
    {
      "x": -7,
      "y": 4,
      "z": 5,
      "name": "Cloth_Block_Wool_Purple"
    },
    {
      "x": -7,
      "y": 5,
      "z": 5,
      "name": "Cloth_Block_Wool_Purple"
    },
    {
      "x": -7,
      "y": 6,
      "z": 5,
      "name": "Cloth_Block_Wool_Purple"
    },
    {
      "x": -7,
      "y": 7,
      "z": 5,
      "name": "Cloth_Block_Wool_Purple"
    },
    {
      "x": -7,
      "y": 0,
      "z": 6,
      "name": "Cloth_Block_Wool_Purple"
    },
    {
      "x": -7,
      "y": 1,
      "z": 6,
      "name": "Cloth_Block_Wool_Purple"
    },
    {
      "x": -7,
      "y": 2,
      "z": 6,
      "name": "Cloth_Block_Wool_Purple"
    },
    {
      "x": -7,
      "y": 3,
      "z": 6,
      "name": "Cloth_Block_Wool_Purple"
    },
    {
      "x": -7,
      "y": 4,
      "z": 6,
      "name": "Cloth_Block_Wool_Purple"
    },
    {
      "x": -7,
      "y": 5,
      "z": 6,
      "name": "Cloth_Block_Wool_Purple"
    },
    {
      "x": -7,
      "y": 6,
      "z": 6,
      "name": "Cloth_Block_Wool_Purple"
    },
    {
      "x": -7,
      "y": 7,
      "z": 6,
      "name": "Cloth_Block_Wool_Purple"
    },
    {
      "x": -7,
      "y": 0,
      "z": 7,
      "name": "Cloth_Block_Wool_Purple"
    },
    {
      "x": -7,
      "y": 1,
      "z": 7,
      "name": "Cloth_Block_Wool_Purple"
    },
    {
      "x": -7,
      "y": 2,
      "z": 7,
      "name": "Cloth_Block_Wool_Purple"
    },
    {
      "x": -7,
      "y": 3,
      "z": 7,
      "name": "Cloth_Block_Wool_Purple"
    },
    {
      "x": -7,
      "y": 4,
      "z": 7,
      "name": "Cloth_Block_Wool_Purple"
    },
    {
      "x": -7,
      "y": 5,
      "z": 7,
      "name": "Cloth_Block_Wool_Purple"
    },
    {
      "x": -7,
      "y": 6,
      "z": 7,
      "name": "Cloth_Block_Wool_Purple"
    },
    {
      "x": -7,
      "y": 7,
      "z": 7,
      "name": "Cloth_Block_Wool_Purple"
    },
    {
      "x": -7,
      "y": 0,
      "z": 8,
      "name": "Cloth_Block_Wool_Purple"
    },
    {
      "x": -7,
      "y": 1,
      "z": 8,
      "name": "Cloth_Block_Wool_Purple"
    },
    {
      "x": -7,
      "y": 2,
      "z": 8,
      "name": "Cloth_Block_Wool_Purple"
    },
    {
      "x": -7,
      "y": 3,
      "z": 8,
      "name": "Cloth_Block_Wool_Purple"
    },
    {
      "x": -7,
      "y": 4,
      "z": 8,
      "name": "Cloth_Block_Wool_Purple"
    },
    {
      "x": -7,
      "y": 5,
      "z": 8,
      "name": "Cloth_Block_Wool_Purple"
    },
    {
      "x": -7,
      "y": 6,
      "z": 8,
      "name": "Cloth_Block_Wool_Purple"
    },
    {
      "x": -7,
      "y": 7,
      "z": 8,
      "name": "Cloth_Block_Wool_Purple"
    },
    {
      "x": -7,
      "y": 0,
      "z": 9,
      "name": "Cloth_Block_Wool_Purple"
    },
    {
      "x": -7,
      "y": 1,
      "z": 9,
      "name": "Cloth_Block_Wool_Purple"
    },
    {
      "x": -7,
      "y": 2,
      "z": 9,
      "name": "Cloth_Block_Wool_Purple"
    },
    {
      "x": -7,
      "y": 3,
      "z": 9,
      "name": "Cloth_Block_Wool_Purple"
    },
    {
      "x": -7,
      "y": 4,
      "z": 9,
      "name": "Cloth_Block_Wool_Purple"
    },
    {
      "x": -7,
      "y": 5,
      "z": 9,
      "name": "Cloth_Block_Wool_Purple"
    },
    {
      "x": -7,
      "y": 6,
      "z": 9,
      "name": "Cloth_Block_Wool_Purple"
    },
    {
      "x": -7,
      "y": 7,
      "z": 9,
      "name": "Cloth_Block_Wool_Purple"
    },
    {
      "x": -7,
      "y": 0,
      "z": 10,
      "name": "Cloth_Block_Wool_Purple"
    },
    {
      "x": -7,
      "y": 1,
      "z": 10,
      "name": "Cloth_Block_Wool_Purple"
    },
    {
      "x": -7,
      "y": 2,
      "z": 10,
      "name": "Cloth_Block_Wool_Purple"
    },
    {
      "x": -7,
      "y": 3,
      "z": 10,
      "name": "Cloth_Block_Wool_Purple"
    },
    {
      "x": -7,
      "y": 4,
      "z": 10,
      "name": "Cloth_Block_Wool_Purple"
    },
    {
      "x": -7,
      "y": 5,
      "z": 10,
      "name": "Cloth_Block_Wool_Purple"
    },
    {
      "x": -7,
      "y": 6,
      "z": 10,
      "name": "Cloth_Block_Wool_Purple"
    },
    {
      "x": -7,
      "y": 7,
      "z": 10,
      "name": "Cloth_Block_Wool_Purple"
    },
    {
      "x": -7,
      "y": 0,
      "z": 11,
      "name": "Cloth_Block_Wool_Purple"
    },
    {
      "x": -7,
      "y": 1,
      "z": 11,
      "name": "Cloth_Block_Wool_Purple"
    },
    {
      "x": -7,
      "y": 2,
      "z": 11,
      "name": "Cloth_Block_Wool_Purple"
    },
    {
      "x": -7,
      "y": 3,
      "z": 11,
      "name": "Cloth_Block_Wool_Purple"
    },
    {
      "x": -7,
      "y": 4,
      "z": 11,
      "name": "Cloth_Block_Wool_Purple"
    },
    {
      "x": -7,
      "y": 5,
      "z": 11,
      "name": "Cloth_Block_Wool_Purple"
    },
    {
      "x": -7,
      "y": 6,
      "z": 11,
      "name": "Cloth_Block_Wool_Purple"
    },
    {
      "x": -7,
      "y": 7,
      "z": 11,
      "name": "Cloth_Block_Wool_Purple"
    },
    {
      "x": -6,
      "y": 0,
      "z": -11,
      "name": "Cloth_Block_Wool_Purple"
    },
    {
      "x": -6,
      "y": 1,
      "z": -11,
      "name": "Cloth_Block_Wool_Purple"
    },
    {
      "x": -6,
      "y": 2,
      "z": -11,
      "name": "Cloth_Block_Wool_Purple"
    },
    {
      "x": -6,
      "y": 3,
      "z": -11,
      "name": "Cloth_Block_Wool_Purple"
    },
    {
      "x": -6,
      "y": 4,
      "z": -11,
      "name": "Cloth_Block_Wool_Purple"
    },
    {
      "x": -6,
      "y": 5,
      "z": -11,
      "name": "Cloth_Block_Wool_Purple"
    },
    {
      "x": -6,
      "y": 6,
      "z": -11,
      "name": "Cloth_Block_Wool_Purple"
    },
    {
      "x": -6,
      "y": 7,
      "z": -11,
      "name": "Cloth_Block_Wool_Purple"
    },
    {
      "x": -6,
      "y": 0,
      "z": -10,
      "name": "Cloth_Block_Wool_Purple"
    },
    {
      "x": -6,
      "y": 1,
      "z": -10,
      "name": "Cloth_Block_Wool_Purple"
    },
    {
      "x": -6,
      "y": 2,
      "z": -10,
      "name": "Cloth_Block_Wool_Purple"
    },
    {
      "x": -6,
      "y": 3,
      "z": -10,
      "name": "Cloth_Block_Wool_Purple"
    },
    {
      "x": -6,
      "y": 4,
      "z": -10,
      "name": "Cloth_Block_Wool_Purple"
    },
    {
      "x": -6,
      "y": 5,
      "z": -10,
      "name": "Cloth_Block_Wool_Purple"
    },
    {
      "x": -6,
      "y": 6,
      "z": -10,
      "name": "Cloth_Block_Wool_Purple"
    },
    {
      "x": -6,
      "y": 7,
      "z": -10,
      "name": "Cloth_Block_Wool_Purple"
    },
    {
      "x": -6,
      "y": 0,
      "z": -9,
      "name": "Cloth_Block_Wool_Purple"
    },
    {
      "x": -6,
      "y": 1,
      "z": -9,
      "name": "Cloth_Block_Wool_Purple"
    },
    {
      "x": -6,
      "y": 2,
      "z": -9,
      "name": "Cloth_Block_Wool_Purple"
    },
    {
      "x": -6,
      "y": 3,
      "z": -9,
      "name": "Cloth_Block_Wool_Purple"
    },
    {
      "x": -6,
      "y": 4,
      "z": -9,
      "name": "Cloth_Block_Wool_Purple"
    },
    {
      "x": -6,
      "y": 5,
      "z": -9,
      "name": "Cloth_Block_Wool_Purple"
    },
    {
      "x": -6,
      "y": 6,
      "z": -9,
      "name": "Cloth_Block_Wool_Purple"
    },
    {
      "x": -6,
      "y": 7,
      "z": -9,
      "name": "Cloth_Block_Wool_Purple"
    },
    {
      "x": -6,
      "y": 0,
      "z": -8,
      "name": "Cloth_Block_Wool_Purple"
    },
    {
      "x": -6,
      "y": 1,
      "z": -8,
      "name": "Cloth_Block_Wool_Purple"
    },
    {
      "x": -6,
      "y": 2,
      "z": -8,
      "name": "Cloth_Block_Wool_Purple"
    },
    {
      "x": -6,
      "y": 3,
      "z": -8,
      "name": "Cloth_Block_Wool_Purple"
    },
    {
      "x": -6,
      "y": 4,
      "z": -8,
      "name": "Cloth_Block_Wool_Purple"
    },
    {
      "x": -6,
      "y": 5,
      "z": -8,
      "name": "Cloth_Block_Wool_Purple"
    },
    {
      "x": -6,
      "y": 6,
      "z": -8,
      "name": "Cloth_Block_Wool_Purple"
    },
    {
      "x": -6,
      "y": 7,
      "z": -8,
      "name": "Cloth_Block_Wool_Purple"
    },
    {
      "x": -6,
      "y": 0,
      "z": -7,
      "name": "Cloth_Block_Wool_Purple"
    },
    {
      "x": -6,
      "y": 1,
      "z": -7,
      "name": "Cloth_Block_Wool_Purple"
    },
    {
      "x": -6,
      "y": 2,
      "z": -7,
      "name": "Cloth_Block_Wool_Purple"
    },
    {
      "x": -6,
      "y": 3,
      "z": -7,
      "name": "Cloth_Block_Wool_Purple"
    },
    {
      "x": -6,
      "y": 4,
      "z": -7,
      "name": "Cloth_Block_Wool_Purple"
    },
    {
      "x": -6,
      "y": 5,
      "z": -7,
      "name": "Cloth_Block_Wool_Purple"
    },
    {
      "x": -6,
      "y": 6,
      "z": -7,
      "name": "Cloth_Block_Wool_Purple"
    },
    {
      "x": -6,
      "y": 7,
      "z": -7,
      "name": "Cloth_Block_Wool_Purple"
    },
    {
      "x": -6,
      "y": 0,
      "z": -6,
      "name": "Cloth_Block_Wool_Purple"
    },
    {
      "x": -6,
      "y": 1,
      "z": -6,
      "name": "Cloth_Block_Wool_Purple"
    },
    {
      "x": -6,
      "y": 2,
      "z": -6,
      "name": "Cloth_Block_Wool_Purple"
    },
    {
      "x": -6,
      "y": 3,
      "z": -6,
      "name": "Cloth_Block_Wool_Purple"
    },
    {
      "x": -6,
      "y": 4,
      "z": -6,
      "name": "Cloth_Block_Wool_Purple"
    },
    {
      "x": -6,
      "y": 5,
      "z": -6,
      "name": "Cloth_Block_Wool_Purple"
    },
    {
      "x": -6,
      "y": 6,
      "z": -6,
      "name": "Cloth_Block_Wool_Purple"
    },
    {
      "x": -6,
      "y": 7,
      "z": -6,
      "name": "Cloth_Block_Wool_Purple"
    },
    {
      "x": -6,
      "y": 0,
      "z": -5,
      "name": "Cloth_Block_Wool_Purple"
    },
    {
      "x": -6,
      "y": 1,
      "z": -5,
      "name": "Cloth_Block_Wool_Purple"
    },
    {
      "x": -6,
      "y": 2,
      "z": -5,
      "name": "Cloth_Block_Wool_Purple"
    },
    {
      "x": -6,
      "y": 3,
      "z": -5,
      "name": "Cloth_Block_Wool_Purple"
    },
    {
      "x": -6,
      "y": 4,
      "z": -5,
      "name": "Cloth_Block_Wool_Purple"
    },
    {
      "x": -6,
      "y": 5,
      "z": -5,
      "name": "Cloth_Block_Wool_Purple"
    },
    {
      "x": -6,
      "y": 6,
      "z": -5,
      "name": "Cloth_Block_Wool_Purple"
    },
    {
      "x": -6,
      "y": 7,
      "z": -5,
      "name": "Cloth_Block_Wool_Purple"
    },
    {
      "x": -6,
      "y": 0,
      "z": -4,
      "name": "Cloth_Block_Wool_Purple"
    },
    {
      "x": -6,
      "y": 1,
      "z": -4,
      "name": "Cloth_Block_Wool_Purple"
    },
    {
      "x": -6,
      "y": 2,
      "z": -4,
      "name": "Cloth_Block_Wool_Purple"
    },
    {
      "x": -6,
      "y": 3,
      "z": -4,
      "name": "Cloth_Block_Wool_Purple"
    },
    {
      "x": -6,
      "y": 4,
      "z": -4,
      "name": "Cloth_Block_Wool_Purple"
    },
    {
      "x": -6,
      "y": 5,
      "z": -4,
      "name": "Cloth_Block_Wool_Purple"
    },
    {
      "x": -6,
      "y": 6,
      "z": -4,
      "name": "Cloth_Block_Wool_Purple"
    },
    {
      "x": -6,
      "y": 7,
      "z": -4,
      "name": "Cloth_Block_Wool_Purple"
    },
    {
      "x": -6,
      "y": 0,
      "z": -3,
      "name": "Cloth_Block_Wool_Purple"
    },
    {
      "x": -6,
      "y": 1,
      "z": -3,
      "name": "Cloth_Block_Wool_Purple"
    },
    {
      "x": -6,
      "y": 2,
      "z": -3,
      "name": "Cloth_Block_Wool_Purple"
    },
    {
      "x": -6,
      "y": 3,
      "z": -3,
      "name": "Cloth_Block_Wool_Purple"
    },
    {
      "x": -6,
      "y": 4,
      "z": -3,
      "name": "Cloth_Block_Wool_Purple"
    },
    {
      "x": -6,
      "y": 5,
      "z": -3,
      "name": "Cloth_Block_Wool_Purple"
    },
    {
      "x": -6,
      "y": 6,
      "z": -3,
      "name": "Cloth_Block_Wool_Purple"
    },
    {
      "x": -6,
      "y": 7,
      "z": -3,
      "name": "Cloth_Block_Wool_Purple"
    },
    {
      "x": -6,
      "y": 0,
      "z": -2,
      "name": "Cloth_Block_Wool_Purple"
    },
    {
      "x": -6,
      "y": 1,
      "z": -2,
      "name": "Cloth_Block_Wool_Purple"
    },
    {
      "x": -6,
      "y": 2,
      "z": -2,
      "name": "Cloth_Block_Wool_Purple"
    },
    {
      "x": -6,
      "y": 3,
      "z": -2,
      "name": "Cloth_Block_Wool_Purple"
    },
    {
      "x": -6,
      "y": 4,
      "z": -2,
      "name": "Cloth_Block_Wool_Purple"
    },
    {
      "x": -6,
      "y": 5,
      "z": -2,
      "name": "Cloth_Block_Wool_Purple"
    },
    {
      "x": -6,
      "y": 6,
      "z": -2,
      "name": "Cloth_Block_Wool_Purple"
    },
    {
      "x": -6,
      "y": 7,
      "z": -2,
      "name": "Cloth_Block_Wool_Purple"
    },
    {
      "x": -6,
      "y": 0,
      "z": -1,
      "name": "Cloth_Block_Wool_Purple"
    },
    {
      "x": -6,
      "y": 1,
      "z": -1,
      "name": "Cloth_Block_Wool_Purple"
    },
    {
      "x": -6,
      "y": 2,
      "z": -1,
      "name": "Cloth_Block_Wool_Purple"
    },
    {
      "x": -6,
      "y": 3,
      "z": -1,
      "name": "Cloth_Block_Wool_Purple"
    },
    {
      "x": -6,
      "y": 4,
      "z": -1,
      "name": "Cloth_Block_Wool_Purple"
    },
    {
      "x": -6,
      "y": 5,
      "z": -1,
      "name": "Cloth_Block_Wool_Purple"
    },
    {
      "x": -6,
      "y": 6,
      "z": -1,
      "name": "Cloth_Block_Wool_Purple"
    },
    {
      "x": -6,
      "y": 7,
      "z": -1,
      "name": "Cloth_Block_Wool_Purple"
    },
    {
      "x": -6,
      "y": 0,
      "z": 0,
      "name": "Cloth_Block_Wool_Purple"
    },
    {
      "x": -6,
      "y": 1,
      "z": 0,
      "name": "Cloth_Block_Wool_Purple"
    },
    {
      "x": -6,
      "y": 2,
      "z": 0,
      "name": "Cloth_Block_Wool_Purple"
    },
    {
      "x": -6,
      "y": 3,
      "z": 0,
      "name": "Cloth_Block_Wool_Purple"
    },
    {
      "x": -6,
      "y": 4,
      "z": 0,
      "name": "Cloth_Block_Wool_Purple"
    },
    {
      "x": -6,
      "y": 5,
      "z": 0,
      "name": "Cloth_Block_Wool_Purple"
    },
    {
      "x": -6,
      "y": 6,
      "z": 0,
      "name": "Cloth_Block_Wool_Purple"
    },
    {
      "x": -6,
      "y": 7,
      "z": 0,
      "name": "Cloth_Block_Wool_Purple"
    },
    {
      "x": -6,
      "y": 0,
      "z": 1,
      "name": "Cloth_Block_Wool_Purple"
    },
    {
      "x": -6,
      "y": 1,
      "z": 1,
      "name": "Cloth_Block_Wool_Purple"
    },
    {
      "x": -6,
      "y": 2,
      "z": 1,
      "name": "Cloth_Block_Wool_Purple"
    },
    {
      "x": -6,
      "y": 3,
      "z": 1,
      "name": "Cloth_Block_Wool_Purple"
    },
    {
      "x": -6,
      "y": 4,
      "z": 1,
      "name": "Cloth_Block_Wool_Purple"
    },
    {
      "x": -6,
      "y": 5,
      "z": 1,
      "name": "Cloth_Block_Wool_Purple"
    },
    {
      "x": -6,
      "y": 6,
      "z": 1,
      "name": "Cloth_Block_Wool_Purple"
    },
    {
      "x": -6,
      "y": 7,
      "z": 1,
      "name": "Cloth_Block_Wool_Purple"
    },
    {
      "x": -6,
      "y": 0,
      "z": 2,
      "name": "Cloth_Block_Wool_Purple"
    },
    {
      "x": -6,
      "y": 1,
      "z": 2,
      "name": "Cloth_Block_Wool_Purple"
    },
    {
      "x": -6,
      "y": 2,
      "z": 2,
      "name": "Cloth_Block_Wool_Purple"
    },
    {
      "x": -6,
      "y": 3,
      "z": 2,
      "name": "Cloth_Block_Wool_Purple"
    },
    {
      "x": -6,
      "y": 4,
      "z": 2,
      "name": "Cloth_Block_Wool_Purple"
    },
    {
      "x": -6,
      "y": 5,
      "z": 2,
      "name": "Cloth_Block_Wool_Purple"
    },
    {
      "x": -6,
      "y": 6,
      "z": 2,
      "name": "Cloth_Block_Wool_Purple"
    },
    {
      "x": -6,
      "y": 7,
      "z": 2,
      "name": "Cloth_Block_Wool_Purple"
    },
    {
      "x": -6,
      "y": 0,
      "z": 3,
      "name": "Cloth_Block_Wool_Purple"
    },
    {
      "x": -6,
      "y": 1,
      "z": 3,
      "name": "Cloth_Block_Wool_Purple"
    },
    {
      "x": -6,
      "y": 2,
      "z": 3,
      "name": "Cloth_Block_Wool_Purple"
    },
    {
      "x": -6,
      "y": 3,
      "z": 3,
      "name": "Cloth_Block_Wool_Purple"
    },
    {
      "x": -6,
      "y": 4,
      "z": 3,
      "name": "Cloth_Block_Wool_Purple"
    },
    {
      "x": -6,
      "y": 5,
      "z": 3,
      "name": "Cloth_Block_Wool_Purple"
    },
    {
      "x": -6,
      "y": 6,
      "z": 3,
      "name": "Cloth_Block_Wool_Purple"
    },
    {
      "x": -6,
      "y": 7,
      "z": 3,
      "name": "Cloth_Block_Wool_Purple"
    },
    {
      "x": -6,
      "y": 0,
      "z": 4,
      "name": "Cloth_Block_Wool_Purple"
    },
    {
      "x": -6,
      "y": 1,
      "z": 4,
      "name": "Cloth_Block_Wool_Purple"
    },
    {
      "x": -6,
      "y": 2,
      "z": 4,
      "name": "Cloth_Block_Wool_Purple"
    },
    {
      "x": -6,
      "y": 3,
      "z": 4,
      "name": "Cloth_Block_Wool_Purple"
    },
    {
      "x": -6,
      "y": 4,
      "z": 4,
      "name": "Cloth_Block_Wool_Purple"
    },
    {
      "x": -6,
      "y": 5,
      "z": 4,
      "name": "Cloth_Block_Wool_Purple"
    },
    {
      "x": -6,
      "y": 6,
      "z": 4,
      "name": "Cloth_Block_Wool_Purple"
    },
    {
      "x": -6,
      "y": 7,
      "z": 4,
      "name": "Cloth_Block_Wool_Purple"
    },
    {
      "x": -6,
      "y": 0,
      "z": 5,
      "name": "Cloth_Block_Wool_Purple"
    },
    {
      "x": -6,
      "y": 1,
      "z": 5,
      "name": "Cloth_Block_Wool_Purple"
    },
    {
      "x": -6,
      "y": 2,
      "z": 5,
      "name": "Cloth_Block_Wool_Purple"
    },
    {
      "x": -6,
      "y": 3,
      "z": 5,
      "name": "Cloth_Block_Wool_Purple"
    },
    {
      "x": -6,
      "y": 4,
      "z": 5,
      "name": "Cloth_Block_Wool_Purple"
    },
    {
      "x": -6,
      "y": 5,
      "z": 5,
      "name": "Cloth_Block_Wool_Purple"
    },
    {
      "x": -6,
      "y": 6,
      "z": 5,
      "name": "Cloth_Block_Wool_Purple"
    },
    {
      "x": -6,
      "y": 7,
      "z": 5,
      "name": "Cloth_Block_Wool_Purple"
    },
    {
      "x": -6,
      "y": 0,
      "z": 6,
      "name": "Cloth_Block_Wool_Purple"
    },
    {
      "x": -6,
      "y": 1,
      "z": 6,
      "name": "Cloth_Block_Wool_Purple"
    },
    {
      "x": -6,
      "y": 2,
      "z": 6,
      "name": "Cloth_Block_Wool_Purple"
    },
    {
      "x": -6,
      "y": 3,
      "z": 6,
      "name": "Cloth_Block_Wool_Purple"
    },
    {
      "x": -6,
      "y": 4,
      "z": 6,
      "name": "Cloth_Block_Wool_Purple"
    },
    {
      "x": -6,
      "y": 5,
      "z": 6,
      "name": "Cloth_Block_Wool_Purple"
    },
    {
      "x": -6,
      "y": 6,
      "z": 6,
      "name": "Cloth_Block_Wool_Purple"
    },
    {
      "x": -6,
      "y": 7,
      "z": 6,
      "name": "Cloth_Block_Wool_Purple"
    },
    {
      "x": -6,
      "y": 0,
      "z": 7,
      "name": "Cloth_Block_Wool_Purple"
    },
    {
      "x": -6,
      "y": 1,
      "z": 7,
      "name": "Cloth_Block_Wool_Purple"
    },
    {
      "x": -6,
      "y": 2,
      "z": 7,
      "name": "Cloth_Block_Wool_Purple"
    },
    {
      "x": -6,
      "y": 3,
      "z": 7,
      "name": "Cloth_Block_Wool_Purple"
    },
    {
      "x": -6,
      "y": 4,
      "z": 7,
      "name": "Cloth_Block_Wool_Purple"
    },
    {
      "x": -6,
      "y": 5,
      "z": 7,
      "name": "Cloth_Block_Wool_Purple"
    },
    {
      "x": -6,
      "y": 6,
      "z": 7,
      "name": "Cloth_Block_Wool_Purple"
    },
    {
      "x": -6,
      "y": 7,
      "z": 7,
      "name": "Cloth_Block_Wool_Purple"
    },
    {
      "x": -6,
      "y": 0,
      "z": 8,
      "name": "Cloth_Block_Wool_Purple"
    },
    {
      "x": -6,
      "y": 1,
      "z": 8,
      "name": "Cloth_Block_Wool_Purple"
    },
    {
      "x": -6,
      "y": 2,
      "z": 8,
      "name": "Cloth_Block_Wool_Purple"
    },
    {
      "x": -6,
      "y": 3,
      "z": 8,
      "name": "Cloth_Block_Wool_Purple"
    },
    {
      "x": -6,
      "y": 4,
      "z": 8,
      "name": "Cloth_Block_Wool_Purple"
    },
    {
      "x": -6,
      "y": 5,
      "z": 8,
      "name": "Cloth_Block_Wool_Purple"
    },
    {
      "x": -6,
      "y": 6,
      "z": 8,
      "name": "Cloth_Block_Wool_Purple"
    },
    {
      "x": -6,
      "y": 7,
      "z": 8,
      "name": "Cloth_Block_Wool_Purple"
    },
    {
      "x": -6,
      "y": 0,
      "z": 9,
      "name": "Cloth_Block_Wool_Purple"
    },
    {
      "x": -6,
      "y": 1,
      "z": 9,
      "name": "Cloth_Block_Wool_Purple"
    },
    {
      "x": -6,
      "y": 2,
      "z": 9,
      "name": "Cloth_Block_Wool_Purple"
    },
    {
      "x": -6,
      "y": 3,
      "z": 9,
      "name": "Cloth_Block_Wool_Purple"
    },
    {
      "x": -6,
      "y": 4,
      "z": 9,
      "name": "Cloth_Block_Wool_Purple"
    },
    {
      "x": -6,
      "y": 5,
      "z": 9,
      "name": "Cloth_Block_Wool_Purple"
    },
    {
      "x": -6,
      "y": 6,
      "z": 9,
      "name": "Cloth_Block_Wool_Purple"
    },
    {
      "x": -6,
      "y": 7,
      "z": 9,
      "name": "Cloth_Block_Wool_Purple"
    },
    {
      "x": -6,
      "y": 0,
      "z": 10,
      "name": "Cloth_Block_Wool_Purple"
    },
    {
      "x": -6,
      "y": 1,
      "z": 10,
      "name": "Cloth_Block_Wool_Purple"
    },
    {
      "x": -6,
      "y": 2,
      "z": 10,
      "name": "Cloth_Block_Wool_Purple"
    },
    {
      "x": -6,
      "y": 3,
      "z": 10,
      "name": "Cloth_Block_Wool_Purple"
    },
    {
      "x": -6,
      "y": 4,
      "z": 10,
      "name": "Cloth_Block_Wool_Purple"
    },
    {
      "x": -6,
      "y": 5,
      "z": 10,
      "name": "Cloth_Block_Wool_Purple"
    },
    {
      "x": -6,
      "y": 6,
      "z": 10,
      "name": "Cloth_Block_Wool_Purple"
    },
    {
      "x": -6,
      "y": 7,
      "z": 10,
      "name": "Cloth_Block_Wool_Purple"
    },
    {
      "x": -6,
      "y": 0,
      "z": 11,
      "name": "Cloth_Block_Wool_Purple"
    },
    {
      "x": -6,
      "y": 1,
      "z": 11,
      "name": "Cloth_Block_Wool_Purple"
    },
    {
      "x": -6,
      "y": 2,
      "z": 11,
      "name": "Cloth_Block_Wool_Purple"
    },
    {
      "x": -6,
      "y": 3,
      "z": 11,
      "name": "Cloth_Block_Wool_Purple"
    },
    {
      "x": -6,
      "y": 4,
      "z": 11,
      "name": "Cloth_Block_Wool_Purple"
    },
    {
      "x": -6,
      "y": 5,
      "z": 11,
      "name": "Cloth_Block_Wool_Purple"
    },
    {
      "x": -6,
      "y": 6,
      "z": 11,
      "name": "Cloth_Block_Wool_Purple"
    },
    {
      "x": -6,
      "y": 7,
      "z": 11,
      "name": "Cloth_Block_Wool_Purple"
    },
    {
      "x": -5,
      "y": 0,
      "z": -11,
      "name": "Cloth_Block_Wool_Purple"
    },
    {
      "x": -5,
      "y": 1,
      "z": -11,
      "name": "Cloth_Block_Wool_Purple"
    },
    {
      "x": -5,
      "y": 2,
      "z": -11,
      "name": "Cloth_Block_Wool_Purple"
    },
    {
      "x": -5,
      "y": 3,
      "z": -11,
      "name": "Cloth_Block_Wool_Purple"
    },
    {
      "x": -5,
      "y": 4,
      "z": -11,
      "name": "Cloth_Block_Wool_Purple"
    },
    {
      "x": -5,
      "y": 5,
      "z": -11,
      "name": "Cloth_Block_Wool_Purple"
    },
    {
      "x": -5,
      "y": 6,
      "z": -11,
      "name": "Cloth_Block_Wool_Purple"
    },
    {
      "x": -5,
      "y": 7,
      "z": -11,
      "name": "Cloth_Block_Wool_Purple"
    },
    {
      "x": -5,
      "y": 0,
      "z": -10,
      "name": "Cloth_Block_Wool_Purple"
    },
    {
      "x": -5,
      "y": 1,
      "z": -10,
      "name": "Cloth_Block_Wool_Purple"
    },
    {
      "x": -5,
      "y": 2,
      "z": -10,
      "name": "Cloth_Block_Wool_Purple"
    },
    {
      "x": -5,
      "y": 3,
      "z": -10,
      "name": "Cloth_Block_Wool_Purple"
    },
    {
      "x": -5,
      "y": 4,
      "z": -10,
      "name": "Cloth_Block_Wool_Purple"
    },
    {
      "x": -5,
      "y": 5,
      "z": -10,
      "name": "Cloth_Block_Wool_Purple"
    },
    {
      "x": -5,
      "y": 6,
      "z": -10,
      "name": "Cloth_Block_Wool_Purple"
    },
    {
      "x": -5,
      "y": 7,
      "z": -10,
      "name": "Cloth_Block_Wool_Purple"
    },
    {
      "x": -5,
      "y": 0,
      "z": -9,
      "name": "Cloth_Block_Wool_Purple"
    },
    {
      "x": -5,
      "y": 1,
      "z": -9,
      "name": "Cloth_Block_Wool_Purple"
    },
    {
      "x": -5,
      "y": 2,
      "z": -9,
      "name": "Cloth_Block_Wool_Purple"
    },
    {
      "x": -5,
      "y": 3,
      "z": -9,
      "name": "Cloth_Block_Wool_Purple"
    },
    {
      "x": -5,
      "y": 4,
      "z": -9,
      "name": "Cloth_Block_Wool_Purple"
    },
    {
      "x": -5,
      "y": 5,
      "z": -9,
      "name": "Cloth_Block_Wool_Purple"
    },
    {
      "x": -5,
      "y": 6,
      "z": -9,
      "name": "Cloth_Block_Wool_Purple"
    },
    {
      "x": -5,
      "y": 7,
      "z": -9,
      "name": "Cloth_Block_Wool_Purple"
    },
    {
      "x": -5,
      "y": 0,
      "z": -8,
      "name": "Cloth_Block_Wool_Purple"
    },
    {
      "x": -5,
      "y": 1,
      "z": -8,
      "name": "Cloth_Block_Wool_Purple"
    },
    {
      "x": -5,
      "y": 2,
      "z": -8,
      "name": "Cloth_Block_Wool_Purple"
    },
    {
      "x": -5,
      "y": 3,
      "z": -8,
      "name": "Cloth_Block_Wool_Purple"
    },
    {
      "x": -5,
      "y": 4,
      "z": -8,
      "name": "Cloth_Block_Wool_Purple"
    },
    {
      "x": -5,
      "y": 5,
      "z": -8,
      "name": "Cloth_Block_Wool_Purple"
    },
    {
      "x": -5,
      "y": 6,
      "z": -8,
      "name": "Cloth_Block_Wool_Purple"
    },
    {
      "x": -5,
      "y": 7,
      "z": -8,
      "name": "Cloth_Block_Wool_Purple"
    },
    {
      "x": -5,
      "y": 0,
      "z": -7,
      "name": "Cloth_Block_Wool_Purple"
    },
    {
      "x": -5,
      "y": 1,
      "z": -7,
      "name": "Cloth_Block_Wool_Purple"
    },
    {
      "x": -5,
      "y": 2,
      "z": -7,
      "name": "Cloth_Block_Wool_Purple"
    },
    {
      "x": -5,
      "y": 3,
      "z": -7,
      "name": "Cloth_Block_Wool_Purple"
    },
    {
      "x": -5,
      "y": 4,
      "z": -7,
      "name": "Cloth_Block_Wool_Purple"
    },
    {
      "x": -5,
      "y": 5,
      "z": -7,
      "name": "Cloth_Block_Wool_Purple"
    },
    {
      "x": -5,
      "y": 6,
      "z": -7,
      "name": "Cloth_Block_Wool_Purple"
    },
    {
      "x": -5,
      "y": 7,
      "z": -7,
      "name": "Cloth_Block_Wool_Purple"
    },
    {
      "x": -5,
      "y": 0,
      "z": -6,
      "name": "Cloth_Block_Wool_Purple"
    },
    {
      "x": -5,
      "y": 1,
      "z": -6,
      "name": "Cloth_Block_Wool_Purple"
    },
    {
      "x": -5,
      "y": 2,
      "z": -6,
      "name": "Cloth_Block_Wool_Purple"
    },
    {
      "x": -5,
      "y": 3,
      "z": -6,
      "name": "Cloth_Block_Wool_Purple"
    },
    {
      "x": -5,
      "y": 4,
      "z": -6,
      "name": "Cloth_Block_Wool_Purple"
    },
    {
      "x": -5,
      "y": 5,
      "z": -6,
      "name": "Cloth_Block_Wool_Purple"
    },
    {
      "x": -5,
      "y": 6,
      "z": -6,
      "name": "Cloth_Block_Wool_Purple"
    },
    {
      "x": -5,
      "y": 7,
      "z": -6,
      "name": "Cloth_Block_Wool_Purple"
    },
    {
      "x": -5,
      "y": 0,
      "z": -5,
      "name": "Cloth_Block_Wool_Purple"
    },
    {
      "x": -5,
      "y": 1,
      "z": -5,
      "name": "Cloth_Block_Wool_Purple"
    },
    {
      "x": -5,
      "y": 2,
      "z": -5,
      "name": "Cloth_Block_Wool_Purple"
    },
    {
      "x": -5,
      "y": 3,
      "z": -5,
      "name": "Cloth_Block_Wool_Purple"
    },
    {
      "x": -5,
      "y": 4,
      "z": -5,
      "name": "Cloth_Block_Wool_Purple"
    },
    {
      "x": -5,
      "y": 5,
      "z": -5,
      "name": "Cloth_Block_Wool_Purple"
    },
    {
      "x": -5,
      "y": 6,
      "z": -5,
      "name": "Cloth_Block_Wool_Purple"
    },
    {
      "x": -5,
      "y": 7,
      "z": -5,
      "name": "Cloth_Block_Wool_Purple"
    },
    {
      "x": -5,
      "y": 0,
      "z": -4,
      "name": "Cloth_Block_Wool_Purple"
    },
    {
      "x": -5,
      "y": 1,
      "z": -4,
      "name": "Cloth_Block_Wool_Purple"
    },
    {
      "x": -5,
      "y": 2,
      "z": -4,
      "name": "Cloth_Block_Wool_Purple"
    },
    {
      "x": -5,
      "y": 3,
      "z": -4,
      "name": "Cloth_Block_Wool_Purple"
    },
    {
      "x": -5,
      "y": 4,
      "z": -4,
      "name": "Cloth_Block_Wool_Purple"
    },
    {
      "x": -5,
      "y": 5,
      "z": -4,
      "name": "Cloth_Block_Wool_Purple"
    },
    {
      "x": -5,
      "y": 6,
      "z": -4,
      "name": "Cloth_Block_Wool_Purple"
    },
    {
      "x": -5,
      "y": 7,
      "z": -4,
      "name": "Cloth_Block_Wool_Purple"
    },
    {
      "x": -5,
      "y": 0,
      "z": -3,
      "name": "Cloth_Block_Wool_Purple"
    },
    {
      "x": -5,
      "y": 1,
      "z": -3,
      "name": "Cloth_Block_Wool_Purple"
    },
    {
      "x": -5,
      "y": 2,
      "z": -3,
      "name": "Cloth_Block_Wool_Purple"
    },
    {
      "x": -5,
      "y": 3,
      "z": -3,
      "name": "Cloth_Block_Wool_Purple"
    },
    {
      "x": -5,
      "y": 4,
      "z": -3,
      "name": "Cloth_Block_Wool_Purple"
    },
    {
      "x": -5,
      "y": 5,
      "z": -3,
      "name": "Cloth_Block_Wool_Purple"
    },
    {
      "x": -5,
      "y": 6,
      "z": -3,
      "name": "Cloth_Block_Wool_Purple"
    },
    {
      "x": -5,
      "y": 7,
      "z": -3,
      "name": "Cloth_Block_Wool_Purple"
    },
    {
      "x": -5,
      "y": 0,
      "z": -2,
      "name": "Cloth_Block_Wool_Purple"
    },
    {
      "x": -5,
      "y": 1,
      "z": -2,
      "name": "Cloth_Block_Wool_Purple"
    },
    {
      "x": -5,
      "y": 2,
      "z": -2,
      "name": "Cloth_Block_Wool_Purple"
    },
    {
      "x": -5,
      "y": 3,
      "z": -2,
      "name": "Cloth_Block_Wool_Purple"
    },
    {
      "x": -5,
      "y": 4,
      "z": -2,
      "name": "Cloth_Block_Wool_Purple"
    },
    {
      "x": -5,
      "y": 5,
      "z": -2,
      "name": "Cloth_Block_Wool_Purple"
    },
    {
      "x": -5,
      "y": 6,
      "z": -2,
      "name": "Cloth_Block_Wool_Purple"
    },
    {
      "x": -5,
      "y": 7,
      "z": -2,
      "name": "Cloth_Block_Wool_Purple"
    },
    {
      "x": -5,
      "y": 0,
      "z": -1,
      "name": "Cloth_Block_Wool_Purple"
    },
    {
      "x": -5,
      "y": 1,
      "z": -1,
      "name": "Cloth_Block_Wool_Purple"
    },
    {
      "x": -5,
      "y": 2,
      "z": -1,
      "name": "Cloth_Block_Wool_Purple"
    },
    {
      "x": -5,
      "y": 3,
      "z": -1,
      "name": "Cloth_Block_Wool_Purple"
    },
    {
      "x": -5,
      "y": 4,
      "z": -1,
      "name": "Cloth_Block_Wool_Purple"
    },
    {
      "x": -5,
      "y": 5,
      "z": -1,
      "name": "Cloth_Block_Wool_Purple"
    },
    {
      "x": -5,
      "y": 6,
      "z": -1,
      "name": "Cloth_Block_Wool_Purple"
    },
    {
      "x": -5,
      "y": 7,
      "z": -1,
      "name": "Cloth_Block_Wool_Purple"
    },
    {
      "x": -5,
      "y": 0,
      "z": 0,
      "name": "Cloth_Block_Wool_Purple"
    },
    {
      "x": -5,
      "y": 1,
      "z": 0,
      "name": "Cloth_Block_Wool_Purple"
    },
    {
      "x": -5,
      "y": 2,
      "z": 0,
      "name": "Cloth_Block_Wool_Purple"
    },
    {
      "x": -5,
      "y": 3,
      "z": 0,
      "name": "Cloth_Block_Wool_Purple"
    },
    {
      "x": -5,
      "y": 4,
      "z": 0,
      "name": "Cloth_Block_Wool_Purple"
    },
    {
      "x": -5,
      "y": 5,
      "z": 0,
      "name": "Cloth_Block_Wool_Purple"
    },
    {
      "x": -5,
      "y": 6,
      "z": 0,
      "name": "Cloth_Block_Wool_Purple"
    },
    {
      "x": -5,
      "y": 7,
      "z": 0,
      "name": "Cloth_Block_Wool_Purple"
    },
    {
      "x": -5,
      "y": 0,
      "z": 1,
      "name": "Cloth_Block_Wool_Purple"
    },
    {
      "x": -5,
      "y": 1,
      "z": 1,
      "name": "Cloth_Block_Wool_Purple"
    },
    {
      "x": -5,
      "y": 2,
      "z": 1,
      "name": "Cloth_Block_Wool_Purple"
    },
    {
      "x": -5,
      "y": 3,
      "z": 1,
      "name": "Cloth_Block_Wool_Purple"
    },
    {
      "x": -5,
      "y": 4,
      "z": 1,
      "name": "Cloth_Block_Wool_Purple"
    },
    {
      "x": -5,
      "y": 5,
      "z": 1,
      "name": "Cloth_Block_Wool_Purple"
    },
    {
      "x": -5,
      "y": 6,
      "z": 1,
      "name": "Cloth_Block_Wool_Purple"
    },
    {
      "x": -5,
      "y": 7,
      "z": 1,
      "name": "Cloth_Block_Wool_Purple"
    },
    {
      "x": -5,
      "y": 0,
      "z": 2,
      "name": "Cloth_Block_Wool_Purple"
    },
    {
      "x": -5,
      "y": 1,
      "z": 2,
      "name": "Cloth_Block_Wool_Purple"
    },
    {
      "x": -5,
      "y": 2,
      "z": 2,
      "name": "Cloth_Block_Wool_Purple"
    },
    {
      "x": -5,
      "y": 3,
      "z": 2,
      "name": "Cloth_Block_Wool_Purple"
    },
    {
      "x": -5,
      "y": 4,
      "z": 2,
      "name": "Cloth_Block_Wool_Purple"
    },
    {
      "x": -5,
      "y": 5,
      "z": 2,
      "name": "Cloth_Block_Wool_Purple"
    },
    {
      "x": -5,
      "y": 6,
      "z": 2,
      "name": "Cloth_Block_Wool_Purple"
    },
    {
      "x": -5,
