{"anchorX":0,"anchorY":0,"anchorZ":0,"blockIdVersion":11,"blocks":[{"name":"Plant_Moss_Block_Green_Dark","support":15,"x":-5,"y":21,"z":1},{"name":"Plant_Coral_Bush_Green","x":-5,"y":22,"z":1},{"name":"Plant_Moss_Block_Green_Dark","support":15,"x":-5,"y":21,"z":2},{"name":"Plant_Coral_Bush_Green","x":-5,"y":22,"z":2},{"name":"Rock_Sandstone_Brick_Half","rotation":6,"x":-4,"y":3,"z":-3},{"name":"Rock_Sandstone_Brick","rotation":3,"x":-4,"y":4,"z":-3},{"name":"Rock_Sandstone_Brick_Pillar_Base","rotation":3,"x":-4,"y":5,"z":-3},{"name":"Soil_Grass_Full","x":-4,"y":6,"z":-3},{"name":"Plant_Coral_Bush_Green","x":-4,"y":7,"z":-3},{"name":"Rock_Sandstone_Brick","rotation":3,"x":-4,"y":2,"z":-2},{"name":"Rock_Sandstone_Brick","rotation":3,"x":-4,"y":3,"z":-2},{"name":"Rock_Sandstone_Brick","rotation":3,"x":-4,"y":4,"z":-2},{"name":"Rock_Sandstone_Brick_Pillar_Base","rotation":3,"x":-4,"y":5,"z":-2},{"name":"Plant_Moss_Block_Green_Dark","support":15,"x":-4,"y":6,"z":-2},{"name":"Plant_Coral_Bush_Green","x":-4,"y":7,"z":-2},{"name":"Rock_Sandstone_Brick_Half","rotation":8,"x":-4,"y":2,"z":-1},{"name":"Rock_Sandstone_Brick","rotation":3,"x":-4,"y":3,"z":-1},{"name":"Rock_Sandstone_Brick","rotation":3,"x":-4,"y":4,"z":-1},{"name":"Rock_Sandstone_Brick_Pillar_Base","rotation":3,"x":-4,"y":5,"z":-1},{"name":"Rock_Sandstone_Brick","rotation":3,"x":-4,"y":6,"z":-1},{"name":"Rock_Sandstone_Cobble_Stairs","rotation":3,"x":-4,"y":7,"z":-1},{"name":"Rock_Sandstone_Cobble_Half","rotation":7,"x":-4,"y":8,"z":-1},{"name":"Plant_Moss_Block_Green_Dark","support":15,"x":-4,"y":11,"z":-1},{"name":"Soil_Grass_Full","x":-4,"y":12,"z":-1},{"name":"Plant_Coral_Bush_Green","x":-4,"y":13,"z":-1},{"name":"Plant_Kelp_Bubble","rotation":2,"x":-4,"y":21,"z":-1},{"filler":1024,"name":"Plant_Kelp_Bubble","rotation":2,"x":-4,"y":22,"z":-1},{"name":"Rock_Sandstone_Brick","rotation":3,"x":-4,"y":4,"z":0},{"name":"Rock_Sandstone_Brick_Pillar_Base","rotation":3,"x":-4,"y":5,"z":0},{"name":"Rock_Sandstone_Brick","rotation":3,"x":-4,"y":6,"z":0},{"name":"Rock_Sandstone_Cobble_Stairs","rotation":3,"x":-4,"y":7,"z":0},{"name":"Rock_Sandstone_Cobble_Half","rotation":7,"x":-4,"y":8,"z":0},{"name":"Rock_Sandstone_Brick_Smooth_Half","rotation":7,"x":-4,"y":10,"z":0},{"name":"Rock_Sandstone_Brick_Smooth_Half","rotation":8,"x":-4,"y":12,"z":0},{"name":"Plant_Coral_Bush_Green","x":-4,"y":13,"z":0},{"name":"Plant_Moss_Block_Green_Dark","support":15,"x":-4,"y":21,"z":0},{"name":"Plant_Coral_Bush_Green","x":-4,"y":22,"z":0},{"name":"Rock_Sandstone_Brick_Half","rotation":8,"x":-4,"y":3,"z":1},{"name":"Rock_Sandstone_Brick","rotation":3,"x":-4,"y":4,"z":1},{"name":"Rock_Sandstone_Brick_Pillar_Base","rotation":3,"x":-4,"y":5,"z":1},{"name":"Rock_Sandstone_Brick","rotation":3,"x":-4,"y":6,"z":1},{"name":"Rock_Sandstone_Cobble_Stairs","rotation":3,"x":-4,"y":7,"z":1},{"name":"Rock_Sandstone_Brick_Smooth_Half","rotation":4,"x":-4,"y":11,"z":1},{"name":"Rock_Sandstone_Brick_Smooth_Half","rotation":4,"x":-4,"y":12,"z":1},{"name":"Plant_Moss_Block_Green_Dark","support":15,"x":-4,"y":20,"z":1},{"name":"Plant_Moss_Block_Green_Dark","support":15,"x":-4,"y":21,"z":1},{"name":"Plant_Coral_Bush_Green","x":-4,"y":22,"z":1},{"name":"Rock_Sandstone_Brick_Half","rotation":6,"x":-4,"y":2,"z":2},{"name":"Rock_Sandstone_Brick","rotation":3,"x":-4,"y":3,"z":2},{"name":"Rock_Sandstone_Brick","rotation":3,"x":-4,"y":4,"z":2},{"name":"Rock_Sandstone_Brick_Pillar_Base","rotation":3,"x":-4,"y":5,"z":2},{"name":"Rock_Sandstone_Brick","rotation":3,"x":-4,"y":6,"z":2},{"name":"Plant_Seaweed_Grass","support":15,"x":-4,"y":7,"z":2},{"name":"Plant_Kelp_Bubble","rotation":2,"x":-4,"y":16,"z":2},{"filler":1024,"name":"Plant_Kelp_Bubble","rotation":2,"x":-4,"y":17,"z":2},{"name":"Plant_Moss_Block_Green_Dark","support":15,"x":-4,"y":21,"z":2},{"name":"Rock_Sandstone_Brick_Half","rotation":8,"x":-4,"y":1,"z":3},{"name":"Rock_Sandstone_Brick","rotation":3,"x":-4,"y":2,"z":3},{"name":"Rock_Sandstone_Brick","rotation":3,"x":-4,"y":3,"z":3},{"name":"Rock_Sandstone_Brick","rotation":3,"x":-4,"y":4,"z":3},{"name":"Rock_Sandstone_Brick_Pillar_Base","rotation":3,"x":-4,"y":5,"z":3},{"name":"Rock_Sandstone_Brick_Half","rotation":3,"x":-4,"y":6,"z":3},{"name":"Plant_Moss_Block_Green_Dark","support":15,"x":-4,"y":21,"z":3},{"name":"Plant_Coral_Bush_Green","x":-4,"y":22,"z":3},{"name":"Rock_Sandstone_Brick_Half","rotation":7,"x":-4,"y":2,"z":4},{"name":"Rock_Sandstone_Brick_Half","rotation":7,"x":-4,"y":3,"z":4},{"name":"Plant_Kelp_Bubble","rotation":1,"x":-3,"y":5,"z":-5},{"filler":1024,"name":"Plant_Kelp_Bubble","rotation":1,"x":-3,"y":6,"z":-5},{"name":"Rock_Sandstone_Brick_Half","rotation":8,"x":-3,"y":3,"z":-4},{"name":"Rock_Sandstone_Brick","rotation":3,"x":-3,"y":4,"z":-4},{"name":"Rock_Sandstone_Brick_Pillar_Base","rotation":3,"x":-3,"y":5,"z":-4},{"name":"Soil_Grass_Full","x":-3,"y":6,"z":-4},{"name":"Plant_Coral_Model_Green","x":-3,"y":7,"z":-4},{"name":"Rock_Sandstone_Brick","rotation":3,"x":-3,"y":2,"z":-3},{"name":"Rock_Sandstone_Brick","rotation":3,"x":-3,"y":3,"z":-3},{"name":"Rock_Sandstone_Brick","rotation":3,"x":-3,"y":4,"z":-3},{"name":"Rock_Sandstone_Brick","rotation":3,"x":-3,"y":5,"z":-3},{"name":"Plant_Moss_Block_Green_Dark","support":15,"x":-3,"y":6,"z":-3},{"name":"Plant_Moss_Block_Green_Dark","support":15,"x":-3,"y":7,"z":-3},{"name":"Plant_Moss_Block_Green_Dark","support":15,"x":-3,"y":8,"z":-3},{"name":"Plant_Coral_Bush_Green","x":-3,"y":9,"z":-3},{"name":"Rock_Sandstone_Brick_Half","rotation":8,"x":-3,"y":1,"z":-2},{"name":"Rock_Sandstone_Brick","rotation":3,"x":-3,"y":2,"z":-2},{"name":"Rock_Sandstone_Brick","rotation":3,"x":-3,"y":3,"z":-2},{"name":"Rock_Sandstone_Brick","rotation":3,"x":-3,"y":4,"z":-2},{"name":"Rock_Sandstone_Brick","rotation":3,"x":-3,"y":5,"z":-2},{"name":"Rock_Sandstone_Brick","rotation":3,"x":-3,"y":6,"z":-2},{"name":"Plant_Moss_Block_Green_Dark","support":15,"x":-3,"y":7,"z":-2},{"name":"Plant_Moss_Block_Green_Dark","support":15,"x":-3,"y":8,"z":-2},{"name":"Plant_Moss_Block_Green_Dark","support":15,"x":-3,"y":9,"z":-2},{"name":"Soil_Grass_Full","x":-3,"y":10,"z":-2},{"name":"Plant_Coral_Bush_Green","x":-3,"y":11,"z":-2},{"name":"Plant_Kelp_Bubble","rotation":1,"x":-3,"y":22,"z":-2},{"filler":1024,"name":"Plant_Kelp_Bubble","rotation":1,"x":-3,"y":23,"z":-2},{"name":"Rock_Sandstone_Brick_Half","rotation":8,"x":-3,"y":1,"z":-1},{"name":"Rock_Sandstone_Brick","rotation":3,"x":-3,"y":2,"z":-1},{"name":"Rock_Sandstone_Brick","rotation":3,"x":-3,"y":3,"z":-1},{"name":"Rock_Sandstone_Brick","rotation":3,"x":-3,"y":4,"z":-1},{"name":"Rock_Sandstone_Brick","rotation":3,"x":-3,"y":5,"z":-1},{"name":"Rock_Sandstone_Cobble","rotation":3,"x":-3,"y":6,"z":-1},{"name":"Rock_Sandstone_Cobble","rotation":3,"x":-3,"y":7,"z":-1},{"name":"Rock_Sandstone_Cobble","rotation":3,"x":-3,"y":8,"z":-1},{"name":"Plant_Moss_Block_Green_Dark","support":15,"x":-3,"y":9,"z":-1},{"name":"Plant_Moss_Block_Green_Dark","support":15,"x":-3,"y":10,"z":-1},{"name":"Plant_Moss_Block_Green_Dark","support":15,"x":-3,"y":11,"z":-1},{"name":"Soil_Grass_Full","x":-3,"y":12,"z":-1},{"name":"Plant_Coral_Model_Green","x":-3,"y":13,"z":-1},{"name":"Rock_Sandstone_Brick_Pillar_Base","rotation":33,"x":-3,"y":19,"z":-1},{"name":"Rock_Sandstone_Brick_Ornate","rotation":3,"x":-3,"y":20,"z":-1},{"name":"Rock_Sandstone_Brick","rotation":3,"x":-3,"y":21,"z":-1},{"name":"Soil_Grass_Full","x":-3,"y":22,"z":-1},{"name":"Plant_Seaweed_Grass","support":15,"x":-3,"y":23,"z":-1},{"name":"Rock_Sandstone_Brick","rotation":3,"x":-3,"y":3,"z":0},{"name":"Rock_Sandstone_Brick","rotation":3,"x":-3,"y":4,"z":0},{"name":"Rock_Sandstone_Brick","rotation":3,"x":-3,"y":5,"z":0},{"name":"Rock_Sandstone_Cobble","rotation":3,"x":-3,"y":6,"z":0},{"name":"Rock_Sandstone_Cobble","rotation":3,"x":-3,"y":7,"z":0},{"name":"Rock_Sandstone_Cobble","rotation":3,"x":-3,"y":8,"z":0},{"name":"Rock_Sandstone_Brick","rotation":3,"x":-3,"y":9,"z":0},{"name":"Rock_Sandstone_Brick","rotation":3,"x":-3,"y":10,"z":0},{"name":"Plant_Seaweed_Grass","support":15,"x":-3,"y":11,"z":0},{"name":"Furniture_Desert_Window","rotation":3,"x":-3,"y":12,"z":0},{"name":"Rock_Sandstone_Brick","rotation":3,"x":-3,"y":13,"z":0},{"name":"Rock_Sandstone_Brick","rotation":3,"x":-3,"y":14,"z":0},{"name":"Rock_Sandstone_Brick","rotation":3,"x":-3,"y":15,"z":0},{"name":"Rock_Sandstone_Brick_Ornate","rotation":3,"x":-3,"y":16,"z":0},{"name":"Rubble_Sandstone","support":15,"x":-3,"y":17,"z":0},{"name":"Rock_Sandstone_Brick_Ornate","rotation":3,"x":-3,"y":20,"z":0},{"name":"Rock_Sandstone_Brick","rotation":3,"x":-3,"y":21,"z":0},{"name":"Plant_Moss_Block_Green_Dark","support":15,"x":-3,"y":22,"z":0},{"name":"Plant_Coral_Bush_Green","x":-3,"y":23,"z":0},{"name":"Rock_Sandstone_Brick","rotation":3,"x":-3,"y":1,"z":1},{"name":"Rock_Sandstone_Brick","rotation":3,"x":-3,"y":2,"z":1},{"name":"Rock_Sandstone_Brick","rotation":3,"x":-3,"y":3,"z":1},{"name":"Rock_Sandstone_Brick","rotation":3,"x":-3,"y":4,"z":1},{"name":"Rock_Sandstone_Brick","rotation":3,"x":-3,"y":5,"z":1},{"name":"Rock_Sandstone_Brick","rotation":3,"x":-3,"y":6,"z":1},{"name":"Rock_Sandstone_Cobble","rotation":3,"x":-3,"y":7,"z":1},{"name":"Rock_Sandstone_Cobble","rotation":3,"x":-3,"y":8,"z":1},{"name":"Rock_Sandstone_Brick","rotation":3,"x":-3,"y":9,"z":1},{"name":"Rock_Sandstone_Brick","rotation":3,"x":-3,"y":10,"z":1},{"name":"Rock_Sandstone_Brick","rotation":3,"x":-3,"y":11,"z":1},{"name":"Rock_Sandstone_Brick","rotation":3,"x":-3,"y":12,"z":1},{"name":"Rock_Sandstone_Brick","rotation":3,"x":-3,"y":13,"z":1},{"name":"Rock_Sandstone_Brick","rotation":3,"x":-3,"y":14,"z":1},{"name":"Rock_Sandstone_Brick","rotation":3,"x":-3,"y":15,"z":1},{"name":"Rock_Sandstone_Brick_Ornate","rotation":3,"x":-3,"y":16,"z":1},{"name":"Rock_Sandstone_Brick_Pillar_Base","rotation":3,"x":-3,"y":17,"z":1},{"name":"Rock_Sandstone_Brick_Pillar_Middle","rotation":3,"x":-3,"y":18,"z":1},{"name":"Rock_Sandstone_Brick_Pillar_Base","rotation":33,"x":-3,"y":19,"z":1},{"name":"Rock_Sandstone_Brick_Ornate","rotation":3,"x":-3,"y":20,"z":1},{"name":"Rock_Sandstone_Brick","rotation":3,"x":-3,"y":21,"z":1},{"name":"Plant_Moss_Block_Green_Dark","support":15,"x":-3,"y":22,"z":1},{"name":"Plant_Coral_Bush_Green","x":-3,"y":23,"z":1},{"name":"Rock_Sandstone_Brick","rotation":3,"x":-3,"y":1,"z":2},{"name":"Rock_Sandstone_Brick","rotation":3,"x":-3,"y":2,"z":2},{"name":"Rock_Sandstone_Brick","rotation":3,"x":-3,"y":3,"z":2},{"name":"Rock_Sandstone_Brick","rotation":3,"x":-3,"y":4,"z":2},{"name":"Rock_Sandstone_Brick","rotation":3,"x":-3,"y":5,"z":2},{"name":"Rock_Sandstone_Brick","rotation":3,"x":-3,"y":6,"z":2},{"name":"Rock_Sandstone_Brick_Pillar_Base","rotation":3,"x":-3,"y":7,"z":2},{"name":"Rock_Sandstone_Brick_Pillar_Middle","rotation":3,"x":-3,"y":8,"z":2},{"name":"Rock_Sandstone_Brick_Pillar_Base","rotation":33,"x":-3,"y":9,"z":2},{"name":"Rock_Sandstone_Brick_Pillar_Middle","rotation":3,"x":-3,"y":10,"z":2},{"name":"Rock_Sandstone_Brick_Pillar_Middle","rotation":3,"x":-3,"y":11,"z":2},{"name":"Rock_Sandstone_Brick_Pillar_Middle","rotation":3,"x":-3,"y":12,"z":2},{"name":"Rock_Sandstone_Brick_Pillar_Middle","rotation":3,"x":-3,"y":13,"z":2},{"name":"Rock_Sandstone_Brick_Pillar_Base","rotation":33,"x":-3,"y":14,"z":2},{"name":"Plant_Moss_Block_Green_Dark","support":15,"x":-3,"y":15,"z":2},{"name":"Soil_Grass_Full","x":-3,"y":16,"z":2},{"name":"Plant_Coral_Bush_Green","x":-3,"y":17,"z":2},{"name":"Plant_Moss_Block_Green_Dark","support":15,"x":-3,"y":19,"z":2},{"name":"Plant_Moss_Block_Green_Dark","support":15,"x":-3,"y":20,"z":2},{"name":"Plant_Moss_Block_Green_Dark","support":15,"x":-3,"y":21,"z":2},{"name":"Plant_Coral_Bush_Green","x":-3,"y":22,"z":2},{"name":"Rock_Sandstone_Brick","rotation":3,"x":-3,"y":1,"z":3},{"name":"Rock_Sandstone_Brick","rotation":3,"x":-3,"y":2,"z":3},{"name":"Rock_Sandstone_Brick","rotation":3,"x":-3,"y":3,"z":3},{"name":"Rock_Sandstone_Brick","rotation":3,"x":-3,"y":4,"z":3},{"name":"Rock_Sandstone_Brick","rotation":3,"x":-3,"y":5,"z":3},{"name":"Rock_Sandstone_Brick","rotation":3,"x":-3,"y":6,"z":3},{"name":"Plant_Seaweed_Grass_Tall","support":15,"x":-3,"y":7,"z":3},{"filler":1024,"name":"Plant_Seaweed_Grass_Tall","x":-3,"y":8,"z":3},{"name":"Plant_Moss_Block_Green_Dark","support":15,"x":-3,"y":16,"z":3},{"name":"Plant_Coral_Bush_Green","x":-3,"y":17,"z":3},{"name":"Plant_Moss_Block_Green_Dark","support":15,"x":-3,"y":20,"z":3},{"name":"Plant_Moss_Block_Green_Dark","support":15,"x":-3,"y":21,"z":3},{"name":"Rock_Sandstone_Brick_Half","rotation":8,"x":-3,"y":1,"z":4},{"name":"Rock_Sandstone_Brick","rotation":3,"x":-3,"y":2,"z":4},{"name":"Rock_Sandstone_Brick","rotation":3,"x":-3,"y":3,"z":4},{"name":"Rock_Sandstone_Brick","rotation":3,"x":-3,"y":4,"z":4},{"name":"Rock_Sandstone_Brick_Pillar_Base","rotation":3,"x":-3,"y":5,"z":4},{"name":"Rock_Sandstone_Brick_Half","rotation":3,"x":-3,"y":6,"z":4},{"name":"Plant_Moss_Block_Green_Dark","support":15,"x":-3,"y":20,"z":4},{"name":"Plant_Moss_Block_Green_Dark","support":15,"x":-3,"y":21,"z":4},{"name":"Plant_Coral_Bush_Green","x":-3,"y":22,"z":4},{"name":"Plant_Kelp_Bubble","rotation":3,"x":-3,"y":21,"z":5},{"filler":1024,"name":"Plant_Kelp_Bubble","rotation":3,"x":-3,"y":22,"z":5},{"name":"Plant_Kelp_Bubble","rotation":1,"x":-2,"y":4,"z":-5},{"filler":1024,"name":"Plant_Kelp_Bubble","rotation":1,"x":-2,"y":5,"z":-5},{"name":"Rock_Sandstone_Brick_Half","rotation":7,"x":-2,"y":2,"z":-4},{"name":"Rock_Sandstone_Brick","rotation":3,"x":-2,"y":3,"z":-4},{"name":"Rock_Sandstone_Brick","rotation":3,"x":-2,"y":4,"z":-4},{"name":"Rock_Sandstone_Brick_Pillar_Base","rotation":3,"x":-2,"y":5,"z":-4},{"name":"Plant_Moss_Block_Green_Dark","support":15,"x":-2,"y":6,"z":-4},{"name":"Plant_Moss_Block_Green_Dark","support":15,"x":-2,"y":7,"z":-4},{"name":"Plant_Moss_Block_Green_Dark","support":15,"x":-2,"y":8,"z":-4},{"name":"Plant_Moss_Block_Green_Dark","support":15,"x":-2,"y":9,"z":-4},{"name":"Plant_Coral_Bush_Green","x":-2,"y":10,"z":-4},{"name":"Rock_Sandstone_Brick","rotation":3,"x":-2,"y":5,"z":-3},{"name":"Rock_Sandstone_Brick","rotation":3,"x":-2,"y":6,"z":-3},{"name":"Plant_Moss_Block_Green_Dark","support":15,"x":-2,"y":7,"z":-3},{"name":"Plant_Moss_Block_Green_Dark","support":15,"x":-2,"y":8,"z":-3},{"name":"Plant_Moss_Block_Green_Dark","support":15,"x":-2,"y":9,"z":-3},{"name":"Plant_Moss_Block_Green_Dark","support":15,"x":-2,"y":10,"z":-3},{"name":"Plant_Moss_Block_Green_Dark","support":15,"x":-2,"y":11,"z":-3},{"name":"Soil_Grass_Full","x":-2,"y":12,"z":-3},{"name":"Plant_Coral_Bush_Green","x":-2,"y":13,"z":-3},{"name":"Rock_Sandstone_Brick","rotation":3,"x":-2,"y":5,"z":-2},{"name":"Rock_Sandstone_Brick","rotation":3,"x":-2,"y":6,"z":-2},{"name":"Rock_Sandstone_Brick","rotation":3,"x":-2,"y":7,"z":-2},{"name":"Rock_Sandstone_Cobble","rotation":3,"x":-2,"y":8,"z":-2},{"name":"Rock_Sandstone_Brick","rotation":3,"x":-2,"y":9,"z":-2},{"name":"Rock_Sandstone_Brick","rotation":3,"x":-2,"y":10,"z":-2},{"name":"Soil_Grass_Full","x":-2,"y":11,"z":-2},{"name":"Plant_Coral_Bush_Green","x":-2,"y":12,"z":-2},{"name":"Rock_Sandstone_Brick_Half","rotation":6,"x":-2,"y":21,"z":-2},{"name":"Soil_Grass_Full","x":-2,"y":22,"z":-2},{"name":"Plant_Seaweed_Grass","support":15,"x":-2,"y":23,"z":-2},{"name":"Rock_Sandstone_Cobble_Stairs","rotation":2,"x":-2,"y":2,"z":-1},{"name":"Rock_Sandstone_Cobble_Half","rotation":4,"x":-2,"y":6,"z":-1},{"name":"Rock_Sandstone_Cobble","rotation":3,"x":-2,"y":7,"z":-1},{"name":"Rock_Sandstone_Cobble","rotation":3,"x":-2,"y":8,"z":-1},{"name":"Plant_Kelp_Bubble","x":-2,"y":9,"z":-1},{"filler":1024,"name":"Plant_Kelp_Bubble","x":-2,"y":10,"z":-1},{"name":"Rock_Sandstone_Brick_Half","rotation":33,"x":-2,"y":20,"z":-1},{"name":"Rock_Sandstone_Brick","rotation":3,"x":-2,"y":21,"z":-1},{"name":"Soil_Grass_Full","x":-2,"y":22,"z":-1},{"name":"Deco_Pot_Clay_Broken","x":-2,"y":23,"z":-1},{"name":"Rock_Sandstone_Brick","rotation":3,"x":-2,"y":0,"z":0},{"name":"Rock_Sandstone_Cobble_Stairs","rotation":2,"x":-2,"y":3,"z":0},{"name":"Rock_Sandstone_Cobble","rotation":3,"x":-2,"y":8,"z":0},{"name":"*Wood_Torch_Wall_State_Definitions_Off","rotation":1,"x":-2,"y":10,"z":0},{"name":"Wood_Drywood_Planks","rotation":3,"x":-2,"y":16,"z":0},{"name":"Deco_Pot_Clay_Broken","x":-2,"y":17,"z":0},{"name":"Rock_Sandstone_Brick_Half","rotation":33,"x":-2,"y":20,"z":0},{"name":"Rock_Sandstone_Brick","rotation":3,"x":-2,"y":21,"z":0},{"name":"Soil_Grass_Full","x":-2,"y":22,"z":0},{"name":"Furniture_Ancient_Pot","rotation":1,"x":-2,"y":23,"z":0},{"name":"Rock_Sandstone_Brick","rotation":3,"x":-2,"y":0,"z":1},{"name":"Rock_Sandstone_Cobble","rotation":3,"x":-2,"y":1,"z":1},{"name":"Rock_Sandstone_Cobble","rotation":3,"x":-2,"y":2,"z":1},{"name":"Rock_Sandstone_Cobble","rotation":3,"x":-2,"y":3,"z":1},{"name":"Rock_Sandstone_Cobble_Stairs","rotation":2,"x":-2,"y":4,"z":1},{"name":"Rock_Sandstone_Cobble","rotation":3,"x":-2,"y":8,"z":1},{"name":"Wood_Drywood_Planks","rotation":3,"x":-2,"y":16,"z":1},{"name":"Rock_Sandstone_Brick_Smooth_Half","rotation":6,"x":-2,"y":17,"z":1},{"name":"Rock_Sandstone_Brick_Smooth_Half","rotation":6,"x":-2,"y":18,"z":1},{"name":"Rock_Sandstone_Brick_Smooth_Half","rotation":6,"x":-2,"y":19,"z":1},{"name":"Rock_Sandstone_Brick","rotation":3,"x":-2,"y":20,"z":1},{"name":"Rock_Sandstone_Brick","rotation":3,"x":-2,"y":21,"z":1},{"name":"Plant_Moss_Block_Green_Dark","support":15,"x":-2,"y":22,"z":1},{"name":"Furniture_Temple_Wind_Pot","rotation":3,"x":-2,"y":23,"z":1},{"filler":1024,"name":"Furniture_Temple_Wind_Pot","rotation":3,"x":-2,"y":24,"z":1},{"name":"Rock_Sandstone_Brick","rotation":3,"x":-2,"y":0,"z":2},{"name":"Rock_Sandstone_Cobble","rotation":3,"x":-2,"y":1,"z":2},{"name":"Rock_Sandstone_Cobble","rotation":3,"x":-2,"y":2,"z":2},{"name":"Rock_Sandstone_Cobble","rotation":3,"x":-2,"y":3,"z":2},{"name":"Rock_Sandstone_Brick","rotation":3,"x":-2,"y":4,"z":2},{"name":"Rock_Sandstone_Brick","rotation":3,"x":-2,"y":5,"z":2},{"name":"Rock_Sandstone_Cobble","rotation":3,"x":-2,"y":6,"z":2},{"name":"Rock_Sandstone_Cobble","rotation":3,"x":-2,"y":7,"z":2},{"name":"Rock_Sandstone_Cobble","rotation":3,"x":-2,"y":8,"z":2},{"name":"Rock_Sandstone_Brick","rotation":3,"x":-2,"y":9,"z":2},{"name":"Rock_Sandstone_Brick","rotation":3,"x":-2,"y":10,"z":2},{"name":"Rock_Sandstone_Brick","rotation":3,"x":-2,"y":11,"z":2},{"name":"Rock_Sandstone_Brick","rotation":3,"x":-2,"y":12,"z":2},{"name":"Rock_Sandstone_Brick","rotation":3,"x":-2,"y":13,"z":2},{"name":"Rock_Sandstone_Brick","rotation":3,"x":-2,"y":14,"z":2},{"name":"Rock_Sandstone_Brick","rotation":3,"x":-2,"y":15,"z":2},{"name":"Rock_Sandstone_Brick_Ornate","rotation":3,"x":-2,"y":16,"z":2},{"name":"Plant_Moss_Block_Green_Dark","support":15,"x":-2,"y":17,"z":2},{"name":"Plant_Moss_Block_Green_Dark","support":15,"x":-2,"y":18,"z":2},{"name":"Plant_Moss_Block_Green_Dark","support":15,"x":-2,"y":19,"z":2},{"name":"Plant_Moss_Block_Green_Dark","support":15,"x":-2,"y":20,"z":2},{"name":"Rock_Sandstone_Brick","rotation":3,"x":-2,"y":21,"z":2},{"name":"Plant_Moss_Block_Green_Dark","support":15,"x":-2,"y":22,"z":2},{"name":"Plant_Coral_Bush_Green","x":-2,"y":23,"z":2},{"name":"Rock_Sandstone_Cobble","rotation":3,"x":-2,"y":0,"z":3},{"name":"Rock_Sandstone_Cobble","rotation":3,"x":-2,"y":1,"z":3},{"name":"Rock_Sandstone_Brick","rotation":3,"x":-2,"y":2,"z":3},{"name":"Rock_Sandstone_Brick","rotation":3,"x":-2,"y":3,"z":3},{"name":"Rock_Sandstone_Brick","rotation":3,"x":-2,"y":4,"z":3},{"name":"Rock_Sandstone_Brick","rotation":3,"x":-2,"y":5,"z":3},{"name":"Rock_Sandstone_Brick","rotation":3,"x":-2,"y":6,"z":3},{"name":"Rock_Sandstone_Brick_Pillar_Base","rotation":3,"x":-2,"y":7,"z":3},{"name":"Rock_Sandstone_Brick_Pillar_Middle","rotation":3,"x":-2,"y":8,"z":3},{"name":"Rock_Sandstone_Brick_Pillar_Base","rotation":33,"x":-2,"y":9,"z":3},{"name":"Rock_Sandstone_Brick_Pillar_Middle","rotation":3,"x":-2,"y":10,"z":3},{"name":"Rock_Sandstone_Brick_Pillar_Middle","rotation":3,"x":-2,"y":11,"z":3},{"name":"Rock_Sandstone_Brick_Pillar_Middle","rotation":3,"x":-2,"y":12,"z":3},{"name":"Rock_Sandstone_Brick_Pillar_Middle","rotation":3,"x":-2,"y":13,"z":3},{"name":"Rock_Sandstone_Brick_Pillar_Base","rotation":33,"x":-2,"y":14,"z":3},{"name":"Plant_Moss_Block_Green_Dark","support":15,"x":-2,"y":15,"z":3},{"name":"Plant_Moss_Block_Green_Dark","support":15,"x":-2,"y":16,"z":3},{"name":"Plant_Coral_Bush_Green","x":-2,"y":17,"z":3},{"name":"Plant_Moss_Block_Green_Dark","support":15,"x":-2,"y":20,"z":3},{"name":"Plant_Moss_Block_Green_Dark","support":15,"x":-2,"y":21,"z":3},{"name":"Plant_Coral_Bush_Green","x":-2,"y":22,"z":3},{"name":"Rock_Sandstone_Brick_Half","rotation":5,"x":-2,"y":2,"z":4},{"name":"Rock_Sandstone_Brick","rotation":3,"x":-2,"y":3,"z":4},{"name":"Rock_Sandstone_Brick","rotation":3,"x":-2,"y":4,"z":4},{"name":"Rock_Sandstone_Brick_Pillar_Base","rotation":3,"x":-2,"y":5,"z":4},{"name":"Rock_Sandstone_Brick","rotation":3,"x":-2,"y":6,"z":4},{"name":"Plant_Seaweed_Grass","support":15,"x":-2,"y":7,"z":4},{"name":"Plant_Kelp_Bubble","rotation":3,"x":-2,"y":16,"z":4},{"filler":1024,"name":"Plant_Kelp_Bubble","rotation":3,"x":-2,"y":17,"z":4},{"name":"Plant_Moss_Block_Green_Dark","support":15,"x":-2,"y":20,"z":4},{"name":"Plant_Seaweed_Grass","support":15,"x":-2,"y":21,"z":4},{"name":"Wood_Drywood_Planks_Half","rotation":5,"x":-1,"y":1,"z":-4},{"name":"Wood_Drywood_Planks_Half","rotation":5,"x":-1,"y":2,"z":-4},{"name":"Wood_Drywood_Stairs","rotation":33,"x":-1,"y":3,"z":-4},{"name":"Rock_Sandstone_Brick","rotation":3,"x":-1,"y":4,"z":-4},{"name":"Rock_Sandstone_Brick_Pillar_Base","rotation":3,"x":-1,"y":5,"z":-4},{"name":"Rock_Sandstone_Brick","rotation":3,"x":-1,"y":6,"z":-4},{"name":"Rock_Sandstone_Cobble_Stairs","rotation":2,"x":-1,"y":7,"z":-4},{"name":"Rock_Sandstone_Cobble_Half","rotation":6,"x":-1,"y":8,"z":-4},{"name":"Rock_Sandstone_Brick_Smooth_Half","rotation":7,"x":-1,"y":11,"z":-4},{"name":"Rock_Sandstone_Brick_Smooth_Half","rotation":7,"x":-1,"y":12,"z":-4},{"name":"Plant_Coral_Bush_Green","x":-1,"y":13,"z":-4},{"name":"Rock_Sandstone_Brick","rotation":3,"x":-1,"y":5,"z":-3},{"name":"Rock_Sandstone_Cobble","rotation":3,"x":-1,"y":6,"z":-3},{"name":"Rock_Sandstone_Cobble","rotation":3,"x":-1,"y":7,"z":-3},{"name":"Rock_Sandstone_Cobble","rotation":3,"x":-1,"y":8,"z":-3},{"name":"Rock_Sandstone_Brick","rotation":3,"x":-1,"y":9,"z":-3},{"name":"Rock_Sandstone_Brick","rotation":3,"x":-1,"y":10,"z":-3},{"name":"Rock_Sandstone_Brick","rotation":3,"x":-1,"y":11,"z":-3},{"name":"Rock_Sandstone_Brick","rotation":3,"x":-1,"y":12,"z":-3},{"name":"Soil_Grass_Full","x":-1,"y":13,"z":-3},{"name":"Rubble_Sandstone","support":15,"x":-1,"y":14,"z":-3},{"name":"Rock_Sandstone_Brick_Half","rotation":7,"x":-1,"y":15,"z":-3},{"name":"Rock_Sandstone_Brick_Half","rotation":7,"x":-1,"y":16,"z":-3},{"name":"Rock_Sandstone_Cobble","rotation":3,"x":-1,"y":0,"z":-2},{"name":"Rock_Sandstone_Cobble_Stairs","rotation":2,"x":-1,"y":1,"z":-2},{"name":"Rock_Sandstone_Brick","rotation":3,"x":-1,"y":5,"z":-2},{"name":"Rock_Sandstone_Cobble","rotation":3,"x":-1,"y":6,"z":-2},{"name":"Rock_Sandstone_Cobble","rotation":3,"x":-1,"y":7,"z":-2},{"name":"Rock_Sandstone_Cobble_Half","rotation":3,"x":-1,"y":8,"z":-2},{"name":"Wood_Drywood_Beam","rotation":7,"x":-1,"y":16,"z":-2},{"name":"Soil_Grass_Full","x":-1,"y":22,"z":-2},{"name":"Plant_Seaweed_Grass","support":15,"x":-1,"y":23,"z":-2},{"name":"Rock_Sandstone_Cobble","rotation":3,"x":-1,"y":0,"z":-1},{"name":"Rock_Sandstone_Cobble","rotation":3,"x":-1,"y":1,"z":-1},{"name":"Rock_Sandstone_Cobble_Stairs","rotation":2,"x":-1,"y":2,"z":-1},{"name":"Rock_Sandstone_Cobble_Half","rotation":4,"x":-1,"y":6,"z":-1},{"name":"Rock_Sandstone_Cobble","rotation":3,"x":-1,"y":7,"z":-1},{"name":"Rock_Sandstone_Cobble_Half","rotation":3,"x":-1,"y":8,"z":-1},{"name":"Soil_Grass_Full","x":-1,"y":16,"z":-1},{"name":"Plant_Coral_Model_Green","x":-1,"y":17,"z":-1},{"name":"Soil_Grass_Full","x":-1,"y":22,"z":-1},{"name":"Plant_Seaweed_Grass","support":15,"x":-1,"y":23,"z":-1},{"name":"Rock_Sandstone_Brick","rotation":3,"x":-1,"y":0,"z":0},{"name":"Rock_Sandstone_Cobble","rotation":3,"x":-1,"y":1,"z":0},{"name":"Rock_Sandstone_Cobble","rotation":3,"x":-1,"y":2,"z":0},{"name":"Rock_Sandstone_Cobble_Stairs","rotation":2,"x":-1,"y":3,"z":0},{"name":"Rock_Sandstone_Cobble","rotation":3,"x":-1,"y":8,"z":0},{"name":"Soil_Grass_Full","x":-1,"y":16,"z":0},{"name":"Plant_Seaweed_Grass","support":15,"x":-1,"y":17,"z":0},{"name":"Plant_Moss_Block_Green_Dark","support":15,"x":-1,"y":22,"z":0},{"name":"Plant_Seaweed_Grass","support":15,"x":-1,"y":23,"z":0},{"name":"Rock_Sandstone_Brick","rotation":3,"x":-1,"y":0,"z":1},{"name":"Rock_Sandstone_Cobble","rotation":3,"x":-1,"y":1,"z":1},{"name":"Rock_Sandstone_Cobble","rotation":3,"x":-1,"y":2,"z":1},{"name":"Rock_Sandstone_Cobble","rotation":3,"x":-1,"y":3,"z":1},{"name":"Rock_Sandstone_Cobble_Stairs","rotation":2,"x":-1,"y":4,"z":1},{"name":"Rock_Sandstone_Cobble","rotation":3,"x":-1,"y":8,"z":1},{"name":"Furniture_Desert_Ladder","rotation":2,"x":-1,"y":11,"z":1},{"name":"Furniture_Desert_Ladder","rotation":2,"x":-1,"y":12,"z":1},{"name":"Furniture_Desert_Ladder","rotation":2,"x":-1,"y":13,"z":1},{"name":"Furniture_Desert_Ladder","rotation":2,"x":-1,"y":14,"z":1},{"name":"Furniture_Desert_Ladder","rotation":2,"x":-1,"y":15,"z":1},{"name":"Furniture_Desert_Ladder","rotation":2,"x":-1,"y":16,"z":1},{"name":"Furniture_Desert_Ladder","rotation":2,"x":-1,"y":18,"z":1},{"name":"Furniture_Desert_Ladder","rotation":2,"x":-1,"y":22,"z":1},{"name":"Rock_Sandstone_Brick","rotation":3,"x":-1,"y":0,"z":2},{"name":"Rock_Sandstone_Cobble","rotation":3,"x":-1,"y":1,"z":2},{"name":"Rock_Sandstone_Cobble","rotation":3,"x":-1,"y":2,"z":2},{"name":"Rock_Sandstone_Cobble","rotation":3,"x":-1,"y":3,"z":2},{"name":"Rock_Sandstone_Cobble","rotation":3,"x":-1,"y":4,"z":2},{"name":"Rock_Sandstone_Cobble","rotation":3,"x":-1,"y":8,"z":2},{"name":"Wood_Dry_Trunk","rotation":3,"x":-1,"y":9,"z":2},{"name":"Wood_Dry_Trunk","rotation":3,"x":-1,"y":10,"z":2},{"name":"Wood_Dry_Trunk","rotation":3,"x":-1,"y":11,"z":2},{"name":"Wood_Dry_Trunk","rotation":3,"x":-1,"y":12,"z":2},{"name":"Wood_Dry_Trunk","rotation":3,"x":-1,"y":13,"z":2},{"name":"Wood_Dry_Trunk","rotation":3,"x":-1,"y":14,"z":2},{"name":"Wood_Dry_Trunk","rotation":3,"x":-1,"y":15,"z":2},{"name":"Wood_Dry_Trunk","rotation":3,"x":-1,"y":16,"z":2},{"name":"Wood_Dry_Trunk","rotation":3,"x":-1,"y":17,"z":2},{"name":"Wood_Dry_Trunk","rotation":3,"x":-1,"y":18,"z":2},{"name":"Wood_Dry_Trunk","rotation":3,"x":-1,"y":19,"z":2},{"name":"Wood_Dry_Trunk","rotation":3,"x":-1,"y":20,"z":2},{"name":"Wood_Dry_Trunk","rotation":3,"x":-1,"y":21,"z":2},{"name":"Soil_Grass_Full","x":-1,"y":22,"z":2},{"name":"Plant_Seaweed_Grass","support":15,"x":-1,"y":23,"z":2},{"name":"Rock_Sandstone_Brick","rotation":3,"x":-1,"y":0,"z":3},{"name":"Rock_Sandstone_Brick","rotation":3,"x":-1,"y":1,"z":3},{"name":"Rock_Sandstone_Cobble","rotation":3,"x":-1,"y":2,"z":3},{"name":"Rock_Sandstone_Brick","rotation":3,"x":-1,"y":3,"z":3},{"name":"Rock_Sandstone_Brick","rotation":3,"x":-1,"y":4,"z":3},{"name":"Rock_Sandstone_Brick","rotation":3,"x":-1,"y":5,"z":3},{"name":"Rock_Sandstone_Brick","rotation":3,"x":-1,"y":6,"z":3},{"name":"Rock_Sandstone_Cobble","rotation":3,"x":-1,"y":7,"z":3},{"name":"Rock_Sandstone_Cobble","rotation":3,"x":-1,"y":8,"z":3},{"name":"Rock_Sandstone_Brick","rotation":3,"x":-1,"y":9,"z":3},{"name":"Rock_Sandstone_Brick","rotation":3,"x":-1,"y":10,"z":3},{"name":"Rock_Sandstone_Brick","rotation":3,"x":-1,"y":11,"z":3},{"name":"Rock_Sandstone_Brick","rotation":3,"x":-1,"y":12,"z":3},{"name":"Rock_Sandstone_Brick","rotation":3,"x":-1,"y":13,"z":3},{"name":"Plant_Moss_Block_Green_Dark","support":15,"x":-1,"y":14,"z":3},{"name":"Plant_Moss_Block_Green_Dark","support":15,"x":-1,"y":15,"z":3},{"name":"Plant_Moss_Block_Green_Dark","support":15,"x":-1,"y":16,"z":3},{"name":"Plant_Coral_Bush_Green","x":-1,"y":17,"z":3},{"name":"Plant_Moss_Block_Green_Dark","support":15,"x":-1,"y":20,"z":3},{"name":"Rock_Sandstone_Brick","rotation":3,"x":-1,"y":21,"z":3},{"name":"Soil_Grass_Full","x":-1,"y":22,"z":3},{"name":"Plant_Seaweed_Grass","support":15,"x":-1,"y":23,"z":3},{"name":"Rock_Sandstone_Brick_Half","rotation":7,"x":-1,"y":3,"z":4},{"name":"Rock_Sandstone_Brick","rotation":3,"x":-1,"y":4,"z":4},{"name":"Rock_Sandstone_Brick_Pillar_Base","rotation":3,"x":-1,"y":5,"z":4},{"name":"Rock_Sandstone_Brick","rotation":3,"x":-1,"y":6,"z":4},{"name":"Rock_Sandstone_Cobble_Stairs","x":-1,"y":7,"z":4},{"name":"Rock_Sandstone_Brick_Smooth_Half","rotation":7,"x":-1,"y":11,"z":4},{"name":"Rock_Sandstone_Brick_Smooth_Half","rotation":7,"x":-1,"y":12,"z":4},{"name":"Plant_Moss_Block_Green_Dark","support":15,"x":-1,"y":14,"z":4},{"name":"Plant_Moss_Block_Green_Dark","support":15,"x":-1,"y":15,"z":4},{"name":"Plant_Coral_Bush_Green","x":-1,"y":16,"z":4},{"name":"Plant_Moss_Block_Green_Dark","support":15,"x":-1,"y":21,"z":4},{"name":"Plant_Seaweed_Grass","support":15,"x":-1,"y":22,"z":4},{"name":"Plant_Kelp_Bubble","rotation":3,"x":-1,"y":15,"z":5},{"filler":1024,"name":"Plant_Kelp_Bubble","rotation":3,"x":-1,"y":16,"z":5},{"name":"Rock_Sandstone_Brick_Half","rotation":33,"x":0,"y":5,"z":-4},{"name":"Rock_Sandstone_Brick","rotation":3,"x":0,"y":6,"z":-4},{"name":"Rock_Sandstone_Cobble_Stairs","rotation":2,"x":0,"y":7,"z":-4},{"name":"Rock_Sandstone_Cobble_Half","rotation":6,"x":0,"y":8,"z":-4},{"name":"Rock_Sandstone_Brick_Smooth_Half","rotation":6,"x":0,"y":10,"z":-4},{"name":"Rock_Sandstone_Brick_Smooth_Half","rotation":3,"x":0,"y":13,"z":-4},{"name":"Plant_Kelp_Bubble","rotation":1,"x":0,"y":14,"z":-4},{"filler":1024,"name":"Plant_Kelp_Bubble","rotation":1,"x":0,"y":15,"z":-4},{"name":"Rock_Sandstone_Cobble","rotation":3,"x":0,"y":0,"z":-3},{"name":"Rock_Sandstone_Brick_Half","rotation":33,"x":0,"y":5,"z":-3},{"name":"Rock_Sandstone_Brick","rotation":3,"x":0,"y":6,"z":-3},{"name":"Rock_Sandstone_Cobble","rotation":3,"x":0,"y":7,"z":-3},{"name":"Rock_Sandstone_Cobble","rotation":3,"x":0,"y":8,"z":-3},{"name":"Rock_Sandstone_Brick","rotation":3,"x":0,"y":9,"z":-3},{"name":"Rock_Sandstone_Brick","rotation":3,"x":0,"y":10,"z":-3},{"name":"Rock_Sandstone_Brick","rotation":3,"x":0,"y":13,"z":-3},{"name":"Rock_Sandstone_Brick","rotation":3,"x":0,"y":14,"z":-3},{"name":"Rock_Sandstone_Brick","rotation":3,"x":0,"y":15,"z":-3},{"name":"Plant_Moss_Block_Green_Dark","support":15,"x":0,"y":16,"z":-3},{"name":"Plant_Seaweed_Grass","support":15,"x":0,"y":17,"z":-3},{"name":"Rock_Sandstone_Brick_Half","rotation":6,"x":0,"y":21,"z":-3},{"name":"Rock_Sandstone_Cobble","rotation":3,"x":0,"y":0,"z":-2},{"name":"Rock_Sandstone_Brick","rotation":3,"x":0,"y":5,"z":-2},{"name":"Rock_Sandstone_Cobble","rotation":3,"x":0,"y":6,"z":-2},{"name":"Rock_Sandstone_Cobble","rotation":3,"x":0,"y":7,"z":-2},{"name":"Wood_Drywood_Planks","rotation":3,"x":0,"y":16,"z":-2},{"name":"Rubble_Sandstone","support":15,"x":0,"y":17,"z":-2},{"name":"Rock_Sandstone_Brick","rotation":3,"x":0,"y":21,"z":-2},{"name":"Plant_Moss_Block_Green_Dark","support":15,"x":0,"y":22,"z":-2},{"name":"Plant_Seaweed_Grass","support":15,"x":0,"y":23,"z":-2},{"name":"Rock_Sandstone_Cobble","rotation":1,"x":0,"y":0,"z":-1},{"name":"Rock_Sandstone_Brick","rotation":3,"x":0,"y":5,"z":-1},{"name":"Rock_Sandstone_Cobble","rotation":3,"x":0,"y":6,"z":-1},{"name":"Rock_Sandstone_Cobble","rotation":3,"x":0,"y":7,"z":-1},{"name":"Wood_Drywood_Planks","rotation":3,"x":0,"y":16,"z":-1},{"name":"Plant_Seaweed_Grass","support":15,"x":0,"y":17,"z":-1},{"name":"Soil_Grass_Full","x":0,"y":22,"z":-1},{"name":"Plant_Seaweed_Grass","support":15,"x":0,"y":23,"z":-1},{"name":"Rock_Sandstone_Brick","rotation":3,"x":0,"y":0,"z":0},{"name":"Rock_Sandstone_Brick","rotation":3,"x":0,"y":1,"z":0},{"name":"Rock_Sandstone_Brick","rotation":3,"x":0,"y":2,"z":0},{"name":"Rock_Sandstone_Brick","rotation":3,"x":0,"y":3,"z":0},{"name":"Rock_Sandstone_Brick","rotation":3,"x":0,"y":4,"z":0},{"name":"Rock_Sandstone_Brick","rotation":3,"x":0,"y":5,"z":0},{"name":"Rock_Sandstone_Brick","rotation":3,"x":0,"y":6,"z":0},{"name":"Rock_Sandstone_Brick","rotation":3,"x":0,"y":7,"z":0},{"name":"Rock_Sandstone_Brick","rotation":3,"x":0,"y":8,"z":0},{"name":"Soil_Grass_Full","x":0,"y":16,"z":0},{"name":"Plant_Seaweed_Grass","support":15,"x":0,"y":17,"z":0},{"name":"Soil_Grass_Full","x":0,"y":22,"z":0},{"name":"Plant_Seaweed_Grass","support":15,"x":0,"y":23,"z":0},{"name":"Rock_Sandstone_Brick","rotation":3,"x":0,"y":0,"z":1},{"name":"Rock_Sandstone_Cobble","rotation":3,"x":0,"y":1,"z":1},{"name":"Rock_Sandstone_Cobble","rotation":3,"x":0,"y":2,"z":1},{"name":"Rock_Sandstone_Cobble","rotation":3,"x":0,"y":3,"z":1},{"name":"Rock_Sandstone_Cobble","rotation":3,"x":0,"y":4,"z":1},{"name":"Rock_Sandstone_Cobble_Stairs","rotation":3,"x":0,"y":5,"z":1},{"name":"Rock_Sandstone_Cobble_Half","rotation":33,"x":0,"y":8,"z":1},{"name":"Soil_Grass_Full","x":0,"y":16,"z":1},{"name":"Plant_Coral_Bush_Green","x":0,"y":17,"z":1},{"name":"Soil_Grass_Full","x":0,"y":22,"z":1},{"name":"Plant_Coral_Model_Green","x":0,"y":23,"z":1},{"name":"Rock_Sandstone_Brick","rotation":3,"x":0,"y":0,"z":2},{"name":"Rock_Sandstone_Cobble","rotation":3,"x":0,"y":1,"z":2},{"name":"Rock_Sandstone_Cobble","rotation":3,"x":0,"y":2,"z":2},{"name":"Rock_Sandstone_Cobble","rotation":3,"x":0,"y":3,"z":2},{"name":"Rock_Sandstone_Cobble","rotation":3,"x":0,"y":4,"z":2},{"name":"Rock_Sandstone_Cobble_Stairs","rotation":3,"x":0,"y":5,"z":2},{"name":"Rock_Sandstone_Cobble_Half","rotation":33,"x":0,"y":8,"z":2},{"name":"Furniture_Village_Crate","rotation":3,"x":0,"y":9,"z":2},{"name":"Furniture_Ancient_Barrel","rotation":3,"x":0,"y":10,"z":2},{"name":"Plant_Kelp_Bubble","rotation":1,"x":0,"y":14,"z":2},{"filler":1024,"name":"Plant_Kelp_Bubble","rotation":1,"x":0,"y":15,"z":2},{"name":"Soil_Grass_Full","x":0,"y":16,"z":2},{"name":"Plant_Coral_Bush_Green","x":0,"y":17,"z":2},{"name":"Rock_Sandstone_Brick","rotation":3,"x":0,"y":20,"z":2},{"name":"Rock_Sandstone_Brick","rotation":3,"x":0,"y":21,"z":2},{"name":"Soil_Grass_Full","x":0,"y":22,"z":2},{"name":"Plant_Seaweed_Grass","support":15,"x":0,"y":23,"z":2},{"name":"Rock_Sandstone_Brick","rotation":3,"x":0,"y":0,"z":3},{"name":"Rock_Sandstone_Cobble","rotation":3,"x":0,"y":1,"z":3},{"name":"Rock_Sandstone_Brick","rotation":3,"x":0,"y":2,"z":3},{"name":"Rock_Sandstone_Brick","rotation":3,"x":0,"y":3,"z":3},{"name":"Rock_Sandstone_Brick","rotation":3,"x":0,"y":4,"z":3},{"name":"Rock_Sandstone_Brick","rotation":3,"x":0,"y":5,"z":3},{"name":"Rock_Sandstone_Brick","rotation":3,"x":0,"y":6,"z":3},{"name":"Rock_Sandstone_Cobble","rotation":3,"x":0,"y":7,"z":3},{"name":"Rock_Sandstone_Cobble","rotation":3,"x":0,"y":8,"z":3},{"name":"Rock_Sandstone_Brick","rotation":3,"x":0,"y":9,"z":3},{"name":"Rock_Sandstone_Brick","rotation":3,"x":0,"y":10,"z":3},{"name":"Furniture_Desert_Window","x":0,"y":11,"z":3},{"name":"Furniture_Desert_Window","x":0,"y":12,"z":3},{"name":"Plant_Moss_Block_Green_Dark","support":15,"x":0,"y":13,"z":3},{"name":"Plant_Moss_Block_Green_Dark","support":15,"x":0,"y":14,"z":3},{"name":"Plant_Moss_Block_Green_Dark","support":15,"x":0,"y":15,"z":3},{"name":"Rock_Sandstone_Brick_Ornate","rotation":3,"x":0,"y":16,"z":3},{"name":"Plant_Coral_Bush_Green","x":0,"y":17,"z":3},{"name":"Rock_Sandstone_Brick_Ornate","rotation":3,"x":0,"y":20,"z":3},{"name":"Rock_Sandstone_Brick","rotation":3,"x":0,"y":21,"z":3},{"name":"Plant_Moss_Block_Green_Dark","support":15,"x":0,"y":22,"z":3},{"name":"Plant_Seaweed_Grass","support":15,"x":0,"y":23,"z":3},{"name":"Rock_Sandstone_Brick_Half","rotation":8,"x":0,"y":2,"z":4},{"name":"Rock_Sandstone_Brick","rotation":3,"x":0,"y":3,"z":4},{"name":"Rock_Sandstone_Brick","rotation":3,"x":0,"y":4,"z":4},{"name":"Rock_Sandstone_Brick_Pillar_Base","rotation":3,"x":0,"y":5,"z":4},{"name":"Rock_Sandstone_Brick","rotation":3,"x":0,"y":6,"z":4},{"name":"Rock_Sandstone_Cobble_Stairs","x":0,"y":7,"z":4},{"name":"Rock_Sandstone_Cobble_Half","rotation":4,"x":0,"y":8,"z":4},{"name":"Rock_Sandstone_Brick_Smooth_Half","rotation":4,"x":0,"y":10,"z":4},{"name":"Rock_Sandstone_Brick_Smooth_Half","rotation":8,"x":0,"y":12,"z":4},{"name":"Plant_Seaweed_Grass","support":15,"x":0,"y":13,"z":4},{"name":"Plant_Moss_Block_Green_Dark","support":15,"x":0,"y":14,"z":4},{"name":"Plant_Moss_Block_Green_Dark","support":15,"x":0,"y":15,"z":4},{"name":"Plant_Coral_Bush_Green","x":0,"y":16,"z":4},{"name":"Plant_Moss_Block_Green_Dark","support":15,"x":0,"y":21,"z":4},{"name":"Plant_Seaweed_Grass","support":15,"x":0,"y":22,"z":4},{"name":"Plant_Moss_Block_Green_Dark","support":15,"x":0,"y":14,"z":5},{"name":"Plant_Seaweed_Grass","support":15,"x":0,"y":15,"z":5},{"name":"Wood_Drywood_Planks_Half","rotation":7,"x":1,"y":1,"z":-4},{"name":"Wood_Drywood_Planks_Half","rotation":7,"x":1,"y":2,"z":-4},{"name":"Rock_Sandstone_Cobble_Half","rotation":6,"x":1,"y":7,"z":-4},{"name":"Rock_Sandstone_Cobble_Half","rotation":6,"x":1,"y":8,"z":-4},{"name":"Plant_Kelp_Bubble","rotation":1,"x":1,"y":12,"z":-4},{"filler":1024,"name":"Plant_Kelp_Bubble","rotation":1,"x":1,"y":13,"z":-4},{"name":"Rock_Sandstone_Cobble","rotation":3,"x":1,"y":0,"z":-3},{"name":"Rock_Sandstone_Brick_Half","rotation":33,"x":1,"y":5,"z":-3},{"name":"Rock_Sandstone_Brick","rotation":3,"x":1,"y":6,"z":-3},{"name":"Rock_Sandstone_Cobble","rotation":3,"x":1,"y":7,"z":-3},{"name":"Rock_Sandstone_Cobble","rotation":3,"x":1,"y":8,"z":-3},{"name":"Rock_Sandstone_Brick","rotation":3,"x":1,"y":9,"z":-3},{"name":"Rock_Sandstone_Brick","rotation":3,"x":1,"y":10,"z":-3},{"name":"Rock_Sandstone_Brick","rotation":3,"x":1,"y":11,"z":-3},{"name":"Rock_Sandstone_Brick","rotation":3,"x":1,"y":12,"z":-3},{"name":"Rock_Sandstone_Brick","rotation":3,"x":1,"y":13,"z":-3},{"name":"Rock_Sandstone_Brick","rotation":3,"x":1,"y":14,"z":-3},{"name":"Rock_Sandstone_Brick","rotation":3,"x":1,"y":15,"z":-3},{"name":"Plant_Moss_Block_Green_Dark","support":15,"x":1,"y":16,"z":-3},{"name":"Rock_Sandstone_Brick_Pillar_Base","rotation":3,"x":1,"y":17,"z":-3},{"name":"Rock_Sandstone_Brick_Pillar_Middle","rotation":3,"x":1,"y":18,"z":-3},{"name":"Rock_Sandstone_Brick_Pillar_Base","rotation":33,"x":1,"y":19,"z":-3},{"name":"Rock_Sandstone_Brick_Ornate","rotation":3,"x":1,"y":20,"z":-3},{"name":"Rock_Sandstone_Brick","rotation":3,"x":1,"y":21,"z":-3},{"name":"Rubble_Sandstone","support":15,"x":1,"y":22,"z":-3},{"name":"Rock_Sandstone_Cobble","rotation":3,"x":1,"y":0,"z":-2},{"name":"Rock_Sandstone_Cobble","rotation":3,"x":1,"y":5,"z":-2},{"name":"Rock_Sandstone_Cobble","rotation":3,"x":1,"y":6,"z":-2},{"name":"Rock_Sandstone_Cobble_Half","rotation":3,"x":1,"y":7,"z":-2},{"name":"Plant_Moss_Block_Green_Dark","support":15,"x":1,"y":16,"z":-2},{"name":"Rock_Sandstone_Brick_Smooth_Half","rotation":7,"x":1,"y":17,"z":-2},{"name":"Rock_Sandstone_Brick_Smooth_Half","rotation":7,"x":1,"y":18,"z":-2},{"name":"Rock_Sandstone_Brick_Smooth_Half","rotation":7,"x":1,"y":19,"z":-2},{"name":"Rock_Sandstone_Brick","rotation":3,"x":1,"y":20,"z":-2},{"name":"Rock_Sandstone_Brick","rotation":3,"x":1,"y":21,"z":-2},{"name":"Plant_Moss_Block_Green_Dark","support":15,"x":1,"y":22,"z":-2},{"name":"Plant_Seaweed_Grass","support":15,"x":1,"y":23,"z":-2},{"name":"Rock_Sandstone_Cobble","rotation":3,"x":1,"y":0,"z":-1},{"name":"Rock_Sandstone_Cobble","rotation":3,"x":1,"y":5,"z":-1},{"name":"Rock_Sandstone_Cobble","rotation":3,"x":1,"y":6,"z":-1},{"name":"Rock_Sandstone_Cobble_Half","rotation":3,"x":1,"y":7,"z":-1},{"name":"Plant_Moss_Block_Green_Dark","support":15,"x":1,"y":16,"z":-1},{"name":"Plant_Seaweed_Grass","support":15,"x":1,"y":17,"z":-1},{"name":"Plant_Moss_Block_Green_Dark","support":15,"x":1,"y":22,"z":-1},{"name":"Plant_Seaweed_Grass","support":15,"x":1,"y":23,"z":-1},{"name":"Rock_Sandstone_Cobble","rotation":3,"x":1,"y":0,"z":0},{"name":"Rock_Sandstone_Cobble","rotation":3,"x":1,"y":5,"z":0},{"name":"Rock_Sandstone_Cobble","rotation":3,"x":1,"y":6,"z":0},{"name":"Wood_Drywood_Planks","rotation":3,"x":1,"y":16,"z":0},{"name":"Plant_Seaweed_Grass","support":15,"x":1,"y":17,"z":0},{"name":"Wood_Drywood_Beam","rotation":7,"x":1,"y":22,"z":0},{"name":"Rock_Sandstone_Cobble","rotation":3,"x":1,"y":0,"z":1},{"name":"Furniture_Desert_Chair","rotation":1,"x":1,"y":1,"z":1},{"name":"Rock_Sandstone_Cobble","rotation":3,"x":1,"y":5,"z":1},{"name":"Rock_Sandstone_Cobble_Half","rotation":3,"x":1,"y":6,"z":1},{"name":"Soil_Grass_Full","x":1,"y":16,"z":1},{"name":"Plant_Seaweed_Grass","support":15,"x":1,"y":17,"z":1},{"name":"Soil_Grass_Full","x":1,"y":22,"z":1},{"name":"Plant_Seaweed_Grass","support":15,"x":1,"y":23,"z":1},{"name":"Rock_Sandstone_Cobble","rotation":3,"x":1,"y":0,"z":2},{"filler":31,"name":"Furniture_Desert_Table","rotation":3,"x":1,"y":1,"z":2},{"name":"Rock_Sandstone_Cobble","rotation":3,"x":1,"y":5,"z":2},{"name":"Plant_Kelp_Bubble","rotation":1,"x":1,"y":13,"z":2},{"filler":1024,"name":"Plant_Kelp_Bubble","rotation":1,"x":1,"y":14,"z":2},{"name":"Soil_Grass_Full","x":1,"y":16,"z":2},{"name":"Rock_Sandstone_Brick_Smooth_Half","rotation":7,"x":1,"y":17,"z":2},{"name":"Rock_Sandstone_Brick_Smooth_Half","rotation":7,"x":1,"y":18,"z":2},{"name":"Rock_Sandstone_Brick_Smooth_Half","rotation":7,"x":1,"y":19,"z":2},{"name":"Rock_Sandstone_Brick","rotation":3,"x":1,"y":20,"z":2},{"name":"Rock_Sandstone_Brick","rotation":3,"x":1,"y":21,"z":2},{"name":"Plant_Moss_Block_Green_Dark","support":15,"x":1,"y":22,"z":2},{"name":"Plant_Coral_Bush_Green","x":1,"y":23,"z":2},{"name":"Rock_Sandstone_Cobble","rotation":3,"x":1,"y":0,"z":3},{"filler":63,"name":"Furniture_Desert_Table","rotation":3,"x":1,"y":1,"z":3},{"name":"Rock_Sandstone_Brick","rotation":3,"x":1,"y":5,"z":3},{"name":"Rock_Sandstone_Cobble","rotation":3,"x":1,"y":6,"z":3},{"name":"Rock_Sandstone_Cobble","rotation":3,"x":1,"y":7,"z":3},{"name":"Rock_Sandstone_Cobble","rotation":3,"x":1,"y":8,"z":3},{"name":"Rock_Sandstone_Brick","rotation":3,"x":1,"y":9,"z":3},{"name":"Rock_Sandstone_Brick","rotation":3,"x":1,"y":10,"z":3},{"name":"Rock_Sandstone_Brick","rotation":3,"x":1,"y":11,"z":3},{"name":"Plant_Moss_Block_Green_Dark","support":15,"x":1,"y":12,"z":3},{"name":"Plant_Moss_Block_Green_Dark","support":15,"x":1,"y":13,"z":3},{"name":"Plant_Moss_Block_Green_Dark","support":15,"x":1,"y":14,"z":3},{"name":"Rock_Sandstone_Brick","rotation":3,"x":1,"y":15,"z":3},{"name":"Rock_Sandstone_Brick_Ornate","rotation":3,"x":1,"y":16,"z":3},{"name":"Plant_Coral_Bush_Green","x":1,"y":17,"z":3},{"name":"Rock_Sandstone_Brick_Ornate","rotation":3,"x":1,"y":20,"z":3},{"name":"Rock_Sandstone_Brick","rotation":3,"x":1,"y":21,"z":3},{"name":"Plant_Moss_Block_Green_Dark","support":15,"x":1,"y":22,"z":3},{"name":"Plant_Coral_Bush_Green","x":1,"y":23,"z":3},{"name":"Rock_Sandstone_Brick","rotation":3,"x":1,"y":2,"z":4},{"name":"Rock_Sandstone_Brick","rotation":3,"x":1,"y":3,"z":4},{"name":"Rock_Sandstone_Brick","rotation":3,"x":1,"y":4,"z":4},{"name":"Rock_Sandstone_Brick_Pillar_Base","rotation":3,"x":1,"y":5,"z":4},{"name":"Rock_Sandstone_Brick","rotation":3,"x":1,"y":6,"z":4},{"name":"Rock_Sandstone_Cobble_Stairs","x":1,"y":7,"z":4},{"name":"Rock_Sandstone_Brick_Smooth_Half","rotation":5,"x":1,"y":11,"z":4},{"name":"Rock_Sandstone_Brick_Smooth_Half","rotation":5,"x":1,"y":12,"z":4},{"name":"Plant_Moss_Block_Green_Dark","support":15,"x":1,"y":21,"z":4},{"name":"Plant_Coral_Bush_Green","x":1,"y":22,"z":4},{"name":"Rock_Sandstone_Brick_Half","rotation":8,"x":2,"y":1,"z":-4},{"name":"Rock_Sandstone_Brick","rotation":3,"x":2,"y":2,"z":-4},{"name":"Rock_Sandstone_Brick","rotation":3,"x":2,"y":3,"z":-4},{"name":"Rock_Sandstone_Brick_Half","rotation":7,"x":2,"y":4,"z":-4},{"name":"Plant_Moss_Block_Green_Dark","support":15,"x":2,"y":14,"z":-4},{"name":"Soil_Grass_Full","x":2,"y":15,"z":-4},{"name":"Plant_Seaweed_Grass","support":15,"x":2,"y":16,"z":-4},{"name":"Rock_Sandstone_Cobble","rotation":3,"x":2,"y":0,"z":-3},{"name":"Rubble_Sandstone","support":15,"x":2,"y":1,"z":-3},{"name":"Rock_Sandstone_Brick","rotation":3,"x":2,"y":5,"z":-3},{"name":"Rock_Sandstone_Brick","rotation":3,"x":2,"y":6,"z":-3},{"name":"Rock_Sandstone_Brick_Pillar_Base","rotation":3,"x":2,"y":7,"z":-3},{"name":"Rock_Sandstone_Brick_Pillar_Middle","rotation":3,"x":2,"y":8,"z":-3},{"name":"Rock_Sandstone_Brick_Pillar_Base","rotation":33,"x":2,"y":9,"z":-3},{"name":"Rock_Sandstone_Brick_Pillar_Middle","rotation":3,"x":2,"y":10,"z":-3},{"name":"Rock_Sandstone_Brick_Pillar_Middle","rotation":3,"x":2,"y":11,"z":-3},{"name":"Rock_Sandstone_Brick_Pillar_Middle","rotation":3,"x":2,"y":12,"z":-3},{"name":"Rock_Sandstone_Brick_Pillar_Middle","rotation":3,"x":2,"y":13,"z":-3},{"name":"Rock_Sandstone_Brick_Pillar_Base","rotation":33,"x":2,"y":14,"z":-3},{"name":"Soil_Grass_Full","x":2,"y":15,"z":-3},{"name":"Plant_Coral_Bush_Green","x":2,"y":16,"z":-3},{"name":"Rock_Sandstone_Cobble","rotation":3,"x":2,"y":0,"z":-2},{"name":"Rock_Sandstone_Cobble","rotation":3,"x":2,"y":5,"z":-2},{"name":"Rock_Sandstone_Brick","rotation":3,"x":2,"y":6,"z":-2},{"name":"Rock_Sandstone_Cobble","rotation":3,"x":2,"y":7,"z":-2},{"name":"Rock_Sandstone_Cobble","rotation":3,"x":2,"y":8,"z":-2},{"name":"Rock_Sandstone_Brick","rotation":3,"x":2,"y":9,"z":-2},{"name":"Rock_Sandstone_Brick","rotation":3,"x":2,"y":10,"z":-2},{"name":"Rock_Sandstone_Brick","rotation":3,"x":2,"y":11,"z":-2},{"name":"Rock_Sandstone_Brick","rotation":3,"x":2,"y":12,"z":-2},{"name":"Rock_Sandstone_Brick","rotation":3,"x":2,"y":13,"z":-2},{"name":"Rock_Sandstone_Brick","rotation":3,"x":2,"y":14,"z":-2},{"name":"Rock_Sandstone_Brick","rotation":3,"x":2,"y":15,"z":-2},{"name":"Plant_Moss_Block_Green_Dark","support":15,"x":2,"y":16,"z":-2},{"name":"Rock_Sandstone_Brick","rotation":3,"x":2,"y":17,"z":-2},{"name":"Rock_Sandstone_Brick","rotation":3,"x":2,"y":18,"z":-2},{"name":"Rock_Sandstone_Brick","rotation":3,"x":2,"y":19,"z":-2},{"name":"Rock_Sandstone_Brick_Half","rotation":5,"x":2,"y":20,"z":-2},{"name":"Rock_Sandstone_Brick_Half","rotation":5,"x":2,"y":21,"z":-2},{"name":"Wood_Drywood_Beam","rotation":7,"x":2,"y":22,"z":-2},{"name":"Rock_Sandstone_Cobble","rotation":3,"x":2,"y":0,"z":-1},{"name":"Rock_Sandstone_Cobble","rotation":3,"x":2,"y":5,"z":-1},{"name":"Rock_Sandstone_Cobble","rotation":3,"x":2,"y":6,"z":-1},{"name":"Rock_Sandstone_Cobble_Half","rotation":3,"x":2,"y":7,"z":-1},{"name":"Plant_Moss_Block_Green_Dark","support":15,"x":2,"y":16,"z":-1},{"name":"Rock_Sandstone_Brick_Smooth_Half","rotation":4,"x":2,"y":17,"z":-1},{"name":"Rock_Sandstone_Brick_Smooth_Half","rotation":4,"x":2,"y":18,"z":-1},{"name":"Rock_Sandstone_Cobble","rotation":3,"x":2,"y":0,"z":0},{"name":"Rock_Sandstone_Cobble","rotation":3,"x":2,"y":5,"z":0},{"name":"Rock_Sandstone_Cobble","rotation":3,"x":2,"y":6,"z":0},{"name":"Plant_Kelp_Bubble","rotation":2,"x":2,"y":8,"z":0},{"filler":1024,"name":"Plant_Kelp_Bubble","rotation":2,"x":2,"y":9,"z":0},{"name":"Plant_Moss_Block_Green_Dark","support":15,"x":2,"y":16,"z":0},{"name":"Plant_Seaweed_Grass","support":15,"x":2,"y":17,"z":0},{"name":"Wood_Drywood_Beam","rotation":7,"x":2,"y":22,"z":0},{"name":"Rock_Sandstone_Cobble","rotation":3,"x":2,"y":0,"z":1},{"name":"Rock_Sandstone_Cobble","rotation":3,"x":2,"y":5,"z":1},{"name":"Rock_Sandstone_Cobble_Half","rotation":3,"x":2,"y":6,"z":1},{"name":"Plant_Kelp_Bubble","rotation":2,"x":2,"y":7,"z":1},{"filler":1024,"name":"Plant_Kelp_Bubble","rotation":2,"x":2,"y":8,"z":1},{"name":"Plant_Kelp_Bubble","rotation":2,"x":2,"y":10,"z":1},{"filler":1024,"name":"Plant_Kelp_Bubble","rotation":2,"x":2,"y":11,"z":1},{"name":"Wood_Drywood_Planks","rotation":3,"x":2,"y":16,"z":1},{"name":"Rock_Sandstone_Brick_Smooth_Half","rotation":6,"x":2,"y":17,"z":1},{"name":"Rock_Sandstone_Brick_Smooth_Half","rotation":6,"x":2,"y":18,"z":1},{"name":"Rock_Sandstone_Brick_Smooth_Half","rotation":6,"x":2,"y":19,"z":1},{"name":"Rock_Sandstone_Brick","rotation":3,"x":2,"y":20,"z":1},{"name":"Rock_Sandstone_Brick","rotation":3,"x":2,"y":21,"z":1},{"name":"Soil_Grass_Full","x":2,"y":22,"z":1},{"name":"Deco_Pot_Clay_Broken","x":2,"y":23,"z":1},{"name":"Rock_Sandstone_Cobble","rotation":3,"x":2,"y":0,"z":2},{"name":"Furniture_Desert_Table","rotation":3,"x":2,"y":1,"z":2},{"name":"Rock_Sandstone_Cobble","rotation":3,"x":2,"y":5,"z":2},{"name":"Rock_Sandstone_Brick","rotation":3,"x":2,"y":6,"z":2},{"name":"Rock_Sandstone_Cobble","rotation":3,"x":2,"y":7,"z":2},{"name":"Rock_Sandstone_Cobble","rotation":3,"x":2,"y":8,"z":2},{"name":"Rock_Sandstone_Brick","rotation":3,"x":2,"y":9,"z":2},{"name":"Rock_Sandstone_Brick","rotation":3,"x":2,"y":10,"z":2},{"name":"Rock_Sandstone_Brick","rotation":3,"x":2,"y":11,"z":2},{"name":"Rock_Sandstone_Brick","rotation":3,"x":2,"y":12,"z":2},{"name":"Rock_Sandstone_Brick","rotation":3,"x":2,"y":13,"z":2},{"name":"Rock_Sandstone_Brick","rotation":3,"x":2,"y":14,"z":2},{"name":"Rock_Sandstone_Brick","rotation":3,"x":2,"y":15,"z":2},{"name":"Rock_Sandstone_Brick_Ornate","rotation":3,"x":2,"y":16,"z":2},{"name":"Rock_Sandstone_Brick","rotation":3,"x":2,"y":17,"z":2},{"name":"Rock_Sandstone_Brick","rotation":3,"x":2,"y":18,"z":2},{"name":"Rock_Sandstone_Brick","rotation":3,"x":2,"y":19,"z":2},{"name":"Rock_Sandstone_Brick_Ornate","rotation":3,"x":2,"y":20,"z":2},{"name":"Rock_Sandstone_Brick","rotation":3,"x":2,"y":21,"z":2},{"name":"Plant_Moss_Block_Green_Dark","support":15,"x":2,"y":22,"z":2},{"name":"Plant_Coral_Bush_Green","x":2,"y":23,"z":2},{"name":"Rock_Sandstone_Cobble","rotation":3,"x":2,"y":0,"z":3},{"filler":32,"name":"Furniture_Desert_Table","rotation":3,"x":2,"y":1,"z":3},{"name":"Rock_Sandstone_Brick","rotation":3,"x":2,"y":5,"z":3},{"name":"Rock_Sandstone_Brick","rotation":3,"x":2,"y":6,"z":3},{"name":"Rock_Sandstone_Brick_Pillar_Base","rotation":3,"x":2,"y":7,"z":3},{"name":"Rock_Sandstone_Brick_Pillar_Middle","rotation":3,"x":2,"y":8,"z":3},{"name":"Rock_Sandstone_Brick_Pillar_Base","rotation":33,"x":2,"y":9,"z":3},{"name":"Rock_Sandstone_Brick_Pillar_Middle","rotation":3,"x":2,"y":10,"z":3},{"name":"Rock_Sandstone_Brick_Pillar_Middle","rotation":3,"x":2,"y":11,"z":3},{"name":"Rock_Sandstone_Brick_Pillar_Middle","rotation":3,"x":2,"y":12,"z":3},{"name":"Rock_Sandstone_Brick_Pillar_Middle","rotation":3,"x":2,"y":13,"z":3},{"name":"Rock_Sandstone_Brick_Pillar_Base","rotation":33,"x":2,"y":14,"z":3},{"name":"Rock_Sandstone_Brick_Stairs","x":2,"y":15,"z":3},{"name":"Rock_Sandstone_Brick_Ornate","rotation":3,"x":2,"y":16,"z":3},{"name":"Plant_Coral_Bush_Green","x":2,"y":17,"z":3},{"name":"Plant_Moss_Block_Green_Dark","support":15,"x":2,"y":21,"z":3},{"name":"Plant_Coral_Bush_Green","x":2,"y":22,"z":3},{"name":"Rock_Sandstone_Brick_Half","rotation":8,"x":2,"y":1,"z":4},{"name":"Rock_Sandstone_Brick","rotation":3,"x":2,"y":2,"z":4},{"name":"Rock_Sandstone_Brick","rotation":3,"x":2,"y":3,"z":4},{"name":"Rock_Sandstone_Brick","rotation":3,"x":2,"y":4,"z":4},{"name":"Plant_Moss_Block_Green_Dark","support":15,"x":2,"y":5,"z":4},{"name":"Plant_Moss_Block_Green_Dark","support":15,"x":2,"y":6,"z":4},{"name":"Plant_Coral_Bush_Green","x":2,"y":7,"z":4},{"name":"Plant_Moss_Block_Green_Dark","support":15,"x":2,"y":6,"z":5},{"name":"Plant_Seaweed_Grass","support":15,"x":2,"y":7,"z":5},{"name":"Rock_Sandstone_Brick_Half","rotation":5,"x":3,"y":2,"z":-4},{"name":"Rock_Sandstone_Brick","rotation":3,"x":3,"y":3,"z":-4},{"name":"Rock_Sandstone_Brick","rotation":3,"x":3,"y":4,"z":-4},{"name":"Rock_Sandstone_Brick_Pillar_Base","rotation":3,"x":3,"y":5,"z":-4},{"name":"Rock_Sandstone_Brick_Half","rotation":3,"x":3,"y":6,"z":-4},{"name":"Plant_Moss_Block_Green_Dark","support":15,"x":3,"y":13,"z":-4},{"name":"Plant_Moss_Block_Green_Dark","support":15,"x":3,"y":14,"z":-4},{"name":"Soil_Grass_Full","x":3,"y":15,"z":-4},{"name":"Plant_Seaweed_Grass","support":15,"x":3,"y":16,"z":-4},{"name":"Rock_Sandstone_Cobble","rotation":3,"x":3,"y":0,"z":-3},{"name":"Rubble_Sandstone_Medium","support":15,"x":3,"y":1,"z":-3},{"name":"Rock_Sandstone_Brick","rotation":3,"x":3,"y":5,"z":-3},{"name":"Rock_Sandstone_Brick","rotation":3,"x":3,"y":6,"z":-3},{"name":"Rubble_Sandstone","support":15,"x":3,"y":7,"z":-3},{"name":"Plant_Moss_Block_Green_Dark","support":15,"x":3,"y":12,"z":-3},{"name":"Plant_Moss_Block_Green_Dark","support":15,"x":3,"y":13,"z":-3},{"name":"Plant_Moss_Block_Green_Dark","support":15,"x":3,"y":14,"z":-3},{"name":"Soil_Grass_Full","x":3,"y":15,"z":-3},{"name":"Plant_Seaweed_Grass","support":15,"x":3,"y":16,"z":-3},{"name":"Rock_Sandstone_Cobble","rotation":3,"x":3,"y":0,"z":-2},{"name":"Rubble_Sandstone","support":15,"x":3,"y":1,"z":-2},{"name":"Rock_Sandstone_Brick","rotation":3,"x":3,"y":5,"z":-2},{"name":"Rock_Sandstone_Brick","rotation":3,"x":3,"y":6,"z":-2},{"name":"Rock_Sandstone_Brick_Pillar_Base","rotation":3,"x":3,"y":7,"z":-2},{"name":"Rock_Sandstone_Brick_Pillar_Middle","rotation":3,"x":3,"y":8,"z":-2},{"name":"Rock_Sandstone_Brick_Pillar_Base","rotation":33,"x":3,"y":9,"z":-2},{"name":"Rock_Sandstone_Brick_Pillar_Middle","rotation":3,"x":3,"y":10,"z":-2},{"name":"Rock_Sandstone_Brick_Pillar_Middle","rotation":3,"x":3,"y":11,"z":-2},{"name":"Rock_Sandstone_Brick_Pillar_Middle","rotation":3,"x":3,"y":12,"z":-2},{"name":"Rock_Sandstone_Brick_Pillar_Middle","rotation":3,"x":3,"y":13,"z":-2},{"name":"Rock_Sandstone_Brick_Pillar_Base","rotation":33,"x":3,"y":14,"z":-2},{"name":"Soil_Grass_Full","x":3,"y":15,"z":-2},{"name":"Plant_Coral_Bush_Green","x":3,"y":16,"z":-2},{"name":"Rock_Sandstone_Cobble","rotation":3,"x":3,"y":0,"z":-1},{"name":"Rock_Sandstone_Brick","rotation":3,"x":3,"y":5,"z":-1},{"name":"Rock_Sandstone_Brick","rotation":3,"x":3,"y":6,"z":-1},{"name":"Rock_Sandstone_Cobble","rotation":3,"x":3,"y":7,"z":-1},{"name":"Rock_Sandstone_Cobble","rotation":3,"x":3,"y":8,"z":-1},{"name":"Rock_Sandstone_Brick","rotation":3,"x":3,"y":9,"z":-1},{"name":"Rock_Sandstone_Brick","rotation":3,"x":3,"y":10,"z":-1},{"name":"Rock_Sandstone_Brick","rotation":3,"x":3,"y":11,"z":-1},{"name":"Rock_Sandstone_Brick","rotation":3,"x":3,"y":12,"z":-1},{"name":"Rock_Sandstone_Brick","rotation":3,"x":3,"y":13,"z":-1},{"name":"Rock_Sandstone_Brick","rotation":3,"x":3,"y":14,"z":-1},{"name":"Rock_Sandstone_Brick","rotation":3,"x":3,"y":15,"z":-1},{"name":"Soil_Grass_Full","x":3,"y":16,"z":-1},{"name":"Plant_Coral_Bush_Green","x":3,"y":17,"z":-1},{"name":"Rock_Sandstone_Cobble","rotation":3,"x":3,"y":0,"z":0},{"name":"Rock_Sandstone_Brick","rotation":3,"x":3,"y":5,"z":0},{"name":"Rock_Sandstone_Cobble","rotation":3,"x":3,"y":6,"z":0},{"name":"Rock_Sandstone_Cobble","rotation":3,"x":3,"y":7,"z":0},{"name":"Rock_Sandstone_Cobble","rotation":3,"x":3,"y":8,"z":0},{"name":"Rock_Sandstone_Brick","rotation":3,"x":3,"y":9,"z":0},{"name":"Rock_Sandstone_Brick","rotation":3,"x":3,"y":10,"z":0},{"name":"Furniture_Desert_Window","rotation":3,"x":3,"y":12,"z":0},{"name":"Rock_Sandstone_Brick","rotation":3,"x":3,"y":13,"z":0},{"name":"Rock_Sandstone_Brick","rotation":3,"x":3,"y":14,"z":0},{"name":"Rock_Sandstone_Brick","rotation":3,"x":3,"y":15,"z":0},{"name":"Plant_Moss_Block_Green_Dark","support":15,"x":3,"y":16,"z":0},{"name":"Rock_Sandstone_Brick_Wall","rotation":3,"x":3,"y":17,"z":0},{"name":"Rock_Sandstone_Cobble","rotation":3,"x":3,"y":0,"z":1},{"name":"Rock_Sandstone_Brick","rotation":3,"x":3,"y":5,"z":1},{"name":"Rock_Sandstone_Brick","rotation":3,"x":3,"y":6,"z":1},{"name":"Rock_Sandstone_Cobble","rotation":3,"x":3,"y":7,"z":1},{"name":"Rock_Sandstone_Cobble","rotation":3,"x":3,"y":8,"z":1},{"name":"Rock_Sandstone_Brick","rotation":3,"x":3,"y":9,"z":1},{"name":"Rock_Sandstone_Brick","rotation":3,"x":3,"y":10,"z":1},{"name":"Rock_Sandstone_Brick","rotation":3,"x":3,"y":11,"z":1},{"name":"Rock_Sandstone_Brick","rotation":3,"x":3,"y":12,"z":1},{"name":"Rock_Sandstone_Brick","rotation":3,"x":3,"y":13,"z":1},{"name":"Rock_Sandstone_Brick","rotation":3,"x":3,"y":14,"z":1},{"name":"Rock_Sandstone_Brick","rotation":3,"x":3,"y":15,"z":1},{"name":"Rock_Sandstone_Brick_Ornate","rotation":3,"x":3,"y":16,"z":1},{"name":"Rock_Sandstone_Brick_Pillar_Base","rotation":3,"x":3,"y":17,"z":1},{"name":"Rock_Sandstone_Brick_Pillar_Middle","rotation":3,"x":3,"y":18,"z":1},{"name":"Rock_Sandstone_Brick_Pillar_Base","rotation":33,"x":3,"y":19,"z":1},{"name":"Rock_Sandstone_Brick_Ornate","rotation":3,"x":3,"y":20,"z":1},{"name":"Rock_Sandstone_Brick","rotation":3,"x":3,"y":21,"z":1},{"name":"Plant_Moss_Block_Green_Dark","support":15,"x":3,"y":22,"z":1},{"name":"Plant_Seaweed_Grass","support":15,"x":3,"y":23,"z":1},{"name":"Rock_Sandstone_Cobble","rotation":3,"x":3,"y":0,"z":2},{"name":"Rock_Sandstone_Brick","rotation":3,"x":3,"y":5,"z":2},{"name":"Rock_Sandstone_Brick","rotation":3,"x":3,"y":6,"z":2},{"name":"Rock_Sandstone_Brick_Pillar_Base","rotation":3,"x":3,"y":7,"z":2},{"name":"Rock_Sandstone_Brick_Pillar_Middle","rotation":3,"x":3,"y":8,"z":2},{"name":"Rock_Sandstone_Brick_Pillar_Base","rotation":33,"x":3,"y":9,"z":2},{"name":"Rock_Sandstone_Brick_Pillar_Middle","rotation":3,"x":3,"y":10,"z":2},{"name":"Rock_Sandstone_Brick_Pillar_Middle","rotation":3,"x":3,"y":11,"z":2},{"name":"Rock_Sandstone_Brick_Pillar_Middle","rotation":3,"x":3,"y":12,"z":2},{"name":"Rock_Sandstone_Brick_Pillar_Middle","rotation":3,"x":3,"y":13,"z":2},{"name":"Rock_Sandstone_Brick_Pillar_Base","rotation":33,"x":3,"y":14,"z":2},{"name":"Rock_Sandstone_Brick_Stairs","rotation":1,"x":3,"y":15,"z":2},{"name":"Rock_Sandstone_Brick_Ornate","rotation":3,"x":3,"y":16,"z":2},{"name":"Plant_Coral_Bush_Green","x":3,"y":17,"z":2},{"name":"Plant_Moss_Block_Green_Dark","support":15,"x":3,"y":21,"z":2},{"name":"Rubble_Sandstone_Medium","support":15,"x":3,"y":22,"z":2},{"name":"Rock_Sandstone_Brick","rotation":3,"x":3,"y":5,"z":3},{"name":"Plant_Moss_Block_Green_Dark","support":15,"x":3,"y":6,"z":3},{"name":"Plant_Coral_Bush_Green","x":3,"y":7,"z":3},{"name":"Rock_Sandstone_Brick_Half","rotation":8,"x":3,"y":1,"z":4},{"name":"Rock_Sandstone_Brick","rotation":3,"x":3,"y":2,"z":4},{"name":"Rock_Sandstone_Brick","rotation":3,"x":3,"y":3,"z":4},{"name":"Plant_Moss_Block_Green_Dark","support":15,"x":3,"y":4,"z":4},{"name":"Plant_Moss_Block_Green_Dark","support":15,"x":3,"y":5,"z":4},{"name":"Plant_Moss_Block_Green_Dark","support":15,"x":3,"y":6,"z":4},{"name":"Plant_Coral_Bush_Green","x":3,"y":7,"z":4},{"name":"Plant_Moss_Block_Green_Dark","support":15,"x":3,"y":5,"z":5},{"name":"Plant_Moss_Block_Green_Dark","support":15,"x":3,"y":6,"z":5},{"name":"Plant_Seaweed_Grass","support":15,"x":3,"y":7,"z":5},{"name":"Rock_Sandstone_Brick_Half","rotation":6,"x":4,"y":3,"z":-3},{"name":"Rock_Sandstone_Brick","rotation":3,"x":4,"y":4,"z":-3},{"name":"Rock_Sandstone_Brick_Pillar_Base","rotation":3,"x":4,"y":5,"z":-3},{"name":"Rock_Sandstone_Brick_Half","rotation":3,"x":4,"y":6,"z":-3},{"name":"Plant_Moss_Block_Green_Dark","support":15,"x":4,"y":14,"z":-3},{"name":"Soil_Grass_Full","x":4,"y":15,"z":-3},{"name":"Plant_Seaweed_Grass","support":15,"x":4,"y":16,"z":-3},{"name":"Rock_Sandstone_Brick_Half","rotation":8,"x":4,"y":2,"z":-2},{"name":"Rock_Sandstone_Brick","rotation":3,"x":4,"y":3,"z":-2},{"name":"Rock_Sandstone_Brick","rotation":3,"x":4,"y":4,"z":-2},{"name":"Rock_Sandstone_Brick_Pillar_Base","rotation":3,"x":4,"y":5,"z":-2},{"name":"Rock_Sandstone_Brick","rotation":3,"x":4,"y":6,"z":-2},{"name":"Rock_Sandstone_Cobble","rotation":3,"x":4,"y":0,"z":-1},{"name":"Wood_Drywood_Planks_Half","rotation":4,"x":4,"y":1,"z":-1},{"name":"Wood_Drywood_Planks_Half","rotation":4,"x":4,"y":2,"z":-1},{"name":"Wood_Drywood_Stairs","rotation":32,"x":4,"y":3,"z":-1},{"name":"Rock_Sandstone_Brick","rotation":3,"x":4,"y":4,"z":-1},{"name":"Rock_Sandstone_Brick_Pillar_Base","rotation":3,"x":4,"y":5,"z":-1},{"name":"Rock_Sandstone_Brick","rotation":3,"x":4,"y":6,"z":-1},{"name":"Rock_Sandstone_Cobble_Stairs","rotation":1,"x":4,"y":7,"z":-1},{"name":"Rock_Sandstone_Cobble_Half","rotation":5,"x":4,"y":8,"z":-1},{"name":"Rock_Sandstone_Brick_Smooth_Half","rotation":6,"x":4,"y":11,"z":-1},{"name":"Rock_Sandstone_Brick_Smooth_Half","rotation":6,"x":4,"y":12,"z":-1},{"name":"Plant_Coral_Bush_Green","x":4,"y":13,"z":-1},{"name":"Rock_Sandstone_Cobble","rotation":3,"x":4,"y":0,"z":0},{"name":"Wood_Drywood_Planks_Half","rotation":33,"x":4,"y":3,"z":0},{"name":"Rock_Sandstone_Brick","rotation":3,"x":4,"y":4,"z":0},{"name":"Rock_Sandstone_Brick_Pillar_Base","rotation":3,"x":4,"y":5,"z":0},{"name":"Rock_Sandstone_Brick","rotation":3,"x":4,"y":6,"z":0},{"name":"Rock_Sandstone_Cobble_Stairs","rotation":1,"x":4,"y":7,"z":0},{"name":"Rock_Sandstone_Brick_Smooth_Half","rotation":8,"x":4,"y":12,"z":0},{"name":"Plant_Coral_Bush_Green","x":4,"y":13,"z":0},{"name":"Plant_Moss_Block_Green_Dark","support":15,"x":4,"y":15,"z":0},{"name":"Plant_Coral_Bush_Green","x":4,"y":16,"z":0},{"name":"Rock_Sandstone_Cobble","rotation":3,"x":4,"y":0,"z":1},{"name":"Wood_Drywood_Planks_Half","rotation":6,"x":4,"y":1,"z":1},{"name":"Wood_Drywood_Planks_Half","rotation":6,"x":4,"y":2,"z":1},{"name":"Wood_Drywood_Stairs","rotation":34,"x":4,"y":3,"z":1},{"name":"Rock_Sandstone_Brick","rotation":3,"x":4,"y":4,"z":1},{"name":"Rock_Sandstone_Brick_Pillar_Base","rotation":3,"x":4,"y":5,"z":1},{"name":"Plant_Moss_Block_Green_Dark","support":15,"x":4,"y":6,"z":1},{"name":"Plant_Coral_Bush_Green","x":4,"y":7,"z":1},{"name":"Rock_Sandstone_Brick_Smooth_Half","rotation":4,"x":4,"y":11,"z":1},{"name":"Rock_Sandstone_Brick_Smooth_Half","rotation":4,"x":4,"y":12,"z":1},{"name":"Plant_Moss_Block_Green_Dark","support":15,"x":4,"y":15,"z":1},{"name":"Plant_Seaweed_Grass","support":15,"x":4,"y":16,"z":1},{"name":"Rock_Sandstone_Brick_Half","rotation":8,"x":4,"y":1,"z":2},{"name":"Rock_Sandstone_Brick","rotation":3,"x":4,"y":2,"z":2},{"name":"Rock_Sandstone_Brick","rotation":3,"x":4,"y":3,"z":2},{"name":"Rock_Sandstone_Brick","rotation":3,"x":4,"y":4,"z":2},{"name":"Plant_Moss_Block_Green_Dark","support":15,"x":4,"y":5,"z":2},{"name":"Plant_Moss_Block_Green_Dark","support":15,"x":4,"y":6,"z":2},{"name":"Plant_Coral_Bush_Green","x":4,"y":7,"z":2},{"name":"Rock_Sandstone_Brick_Half","rotation":4,"x":4,"y":2,"z":3},{"name":"Rock_Sandstone_Brick","rotation":3,"x":4,"y":3,"z":3},{"name":"Rock_Sandstone_Brick","rotation":3,"x":4,"y":4,"z":3},{"name":"Plant_Moss_Block_Green_Dark","support":15,"x":4,"y":5,"z":3},{"name":"Plant_Moss_Block_Green_Dark","support":15,"x":4,"y":6,"z":3},{"name":"Plant_Coral_Bush_Green","x":4,"y":7,"z":3},{"name":"Rock_Sandstone_Brick_Half","rotation":5,"x":4,"y":2,"z":4},{"name":"Rock_Sandstone_Brick_Half","rotation":5,"x":4,"y":3,"z":4},{"name":"Plant_Moss_Block_Green_Dark","support":15,"x":4,"y":6,"z":4},{"name":"Plant_Seaweed_Grass","support":15,"x":4,"y":7,"z":4},{"name":"Plant_Moss_Block_Green_Dark","support":15,"x":5,"y":5,"z":2},{"name":"Plant_Moss_Block_Green_Dark","support":15,"x":5,"y":6,"z":2},{"name":"Plant_Coral_Bush_Green","x":5,"y":7,"z":2},{"name":"Plant_Moss_Block_Green_Dark","support":15,"x":5,"y":6,"z":3},{"name":"Plant_Seaweed_Grass","support":15,"x":5,"y":7,"z":3}],"fluids":[{"level":1,"name":"Water_Source","x":-5,"y":21,"z":1},{"level":1,"name":"Water_Source","x":-5,"y":22,"z":1},{"level":1,"name":"Water_Source","x":-5,"y":21,"z":2},{"level":1,"name":"Water_Source","x":-5,"y":22,"z":2},{"level":1,"name":"Water_Source","x":-4,"y":3,"z":-3},{"level":1,"name":"Water_Source","x":-4,"y":4,"z":-3},{"level":1,"name":"Water_Source","x":-4,"y":5,"z":-3},{"level":1,"name":"Water_Source","x":-4,"y":6,"z":-3},{"level":1,"name":"Water_Source","x":-4,"y":7,"z":-3},{"level":1,"name":"Water_Source","x":-4,"y":2,"z":-2},{"level":1,"name":"Water_Source","x":-4,"y":3,"z":-2},{"level":1,"name":"Water_Source","x":-4,"y":4,"z":-2},{"level":1,"name":"Water_Source","x":-4,"y":5,"z":-2},{"level":1,"name":"Water_Source","x":-4,"y":6,"z":-2},{"level":1,"name":"Water_Source","x":-4,"y":7,"z":-2},{"level":1,"name":"Water_Source","x":-4,"y":2,"z":-1},{"level":1,"name":"Water_Source","x":-4,"y":3,"z":-1},{"level":1,"name":"Water_Source","x":-4,"y":4,"z":-1},{"level":1,"name":"Water_Source","x":-4,"y":5,"z":-1},{"level":1,"name":"Water_Source","x":-4,"y":6,"z":-1},{"level":1,"name":"Water_Source","x":-4,"y":7,"z":-1},{"level":1,"name":"Water_Source","x":-4,"y":8,"z":-1},{"level":1,"name":"Water_Source","x":-4,"y":11,"z":-1},{"level":1,"name":"Water_Source","x":-4,"y":12,"z":-1},{"level":1,"name":"Water_Source","x":-4,"y":13,"z":-1},{"level":1,"name":"Water_Source","x":-4,"y":21,"z":-1},{"level":1,"name":"Water_Source","x":-4,"y":22,"z":-1},{"level":1,"name":"Water_Source","x":-4,"y":4,"z":0},{"level":1,"name":"Water_Source","x":-4,"y":5,"z":0},{"level":1,"name":"Water_Source","x":-4,"y":6,"z":0},{"level":1,"name":"Water_Source","x":-4,"y":7,"z":0},{"level":1,"name":"Water_Source","x":-4,"y":8,"z":0},{"level":1,"name":"Water_Source","x":-4,"y":10,"z":0},{"level":1,"name":"Water_Source","x":-4,"y":12,"z":0},{"level":1,"name":"Water_Source","x":-4,"y":13,"z":0},{"level":1,"name":"Water_Source","x":-4,"y":21,"z":0},{"level":1,"name":"Water_Source","x":-4,"y":22,"z":0},{"level":1,"name":"Water_Source","x":-4,"y":3,"z":1},{"level":1,"name":"Water_Source","x":-4,"y":4,"z":1},{"level":1,"name":"Water_Source","x":-4,"y":5,"z":1},{"level":1,"name":"Water_Source","x":-4,"y":6,"z":1},{"level":1,"name":"Water_Source","x":-4,"y":7,"z":1},{"level":1,"name":"Water_Source","x":-4,"y":11,"z":1},{"level":1,"name":"Water_Source","x":-4,"y":12,"z":1},{"level":1,"name":"Water_Source","x":-4,"y":20,"z":1},{"level":1,"name":"Water_Source","x":-4,"y":21,"z":1},{"level":1,"name":"Water_Source","x":-4,"y":22,"z":1},{"level":1,"name":"Water_Source","x":-4,"y":2,"z":2},{"level":1,"name":"Water_Source","x":-4,"y":3,"z":2},{"level":1,"name":"Water_Source","x":-4,"y":4,"z":2},{"level":1,"name":"Water_Source","x":-4,"y":5,"z":2},{"level":1,"name":"Water_Source","x":-4,"y":6,"z":2},{"level":1,"name":"Water_Source","x":-4,"y":7,"z":2},{"level":1,"name":"Water_Source","x":-4,"y":16,"z":2},{"level":1,"name":"Water_Source","x":-4,"y":17,"z":2},{"level":1,"name":"Water_Source","x":-4,"y":21,"z":2},{"level":1,"name":"Water_Source","x":-4,"y":1,"z":3},{"level":1,"name":"Water_Source","x":-4,"y":2,"z":3},{"level":1,"name":"Water_Source","x":-4,"y":3,"z":3},{"level":1,"name":"Water_Source","x":-4,"y":4,"z":3},{"level":1,"name":"Water_Source","x":-4,"y":5,"z":3},{"level":1,"name":"Water_Source","x":-4,"y":6,"z":3},{"level":1,"name":"Water_Source","x":-4,"y":21,"z":3},{"level":1,"name":"Water_Source","x":-4,"y":22,"z":3},{"level":1,"name":"Water_Source","x":-4,"y":2,"z":4},{"level":1,"name":"Water_Source","x":-4,"y":3,"z":4},{"level":1,"name":"Water_Source","x":-3,"y":5,"z":-5},{"level":1,"name":"Water_Source","x":-3,"y":6,"z":-5},{"level":1,"name":"Water_Source","x":-3,"y":3,"z":-4},{"level":1,"name":"Water_Source","x":-3,"y":4,"z":-4},{"level":1,"name":"Water_Source","x":-3,"y":5,"z":-4},{"level":1,"name":"Water_Source","x":-3,"y":6,"z":-4},{"level":1,"name":"Water_Source","x":-3,"y":7,"z":-4},{"level":1,"name":"Water_Source","x":-3,"y":2,"z":-3},{"level":1,"name":"Water_Source","x":-3,"y":3,"z":-3},{"level":1,"name":"Water_Source","x":-3,"y":4,"z":-3},{"level":1,"name":"Water_Source","x":-3,"y":5,"z":-3},{"level":1,"name":"Water_Source","x":-3,"y":6,"z":-3},{"level":1,"name":"Water_Source","x":-3,"y":7,"z":-3},{"level":1,"name":"Water_Source","x":-3,"y":8,"z":-3},{"level":1,"name":"Water_Source","x":-3,"y":9,"z":-3},{"level":1,"name":"Water_Source","x":-3,"y":1,"z":-2},{"level":1,"name":"Water_Source","x":-3,"y":2,"z":-2},{"level":1,"name":"Water_Source","x":-3,"y":3,"z":-2},{"level":1,"name":"Water_Source","x":-3,"y":4,"z":-2},{"level":1,"name":"Water_Source","x":-3,"y":5,"z":-2},{"level":1,"name":"Water_Source","x":-3,"y":6,"z":-2},{"level":1,"name":"Water_Source","x":-3,"y":7,"z":-2},{"level":1,"name":"Water_Source","x":-3,"y":8,"z":-2},{"level":1,"name":"Water_Source","x":-3,"y":9,"z":-2},{"level":1,"name":"Water_Source","x":-3,"y":10,"z":-2},{"level":1,"name":"Water_Source","x":-3,"y":11,"z":-2},{"level":1,"name":"Water_Source","x":-3,"y":22,"z":-2},{"level":1,"name":"Water_Source","x":-3,"y":23,"z":-2},{"level":1,"name":"Water_Source","x":-3,"y":1,"z":-1},{"level":1,"name":"Water_Source","x":-3,"y":2,"z":-1},{"level":1,"name":"Water_Source","x":-3,"y":3,"z":-1},{"level":1,"name":"Water_Source","x":-3,"y":4,"z":-1},{"level":1,"name":"Water_Source","x":-3,"y":5,"z":-1},{"level":1,"name":"Water_Source","x":-3,"y":6,"z":-1},{"level":1,"name":"Water_Source","x":-3,"y":7,"z":-1},{"level":1,"name":"Water_Source","x":-3,"y":8,"z":-1},{"level":1,"name":"Water_Source","x":-3,"y":9,"z":-1},{"level":1,"name":"Water_Source","x":-3,"y":10,"z":-1},{"level":1,"name":"Water_Source","x":-3,"y":11,"z":-1},{"level":1,"name":"Water_Source","x":-3,"y":12,"z":-1},{"level":1,"name":"Water_Source","x":-3,"y":13,"z":-1},{"level":1,"name":"Water_Source","x":-3,"y":19,"z":-1},{"level":1,"name":"Water_Source","x":-3,"y":20,"z":-1},{"level":1,"name":"Water_Source","x":-3,"y":21,"z":-1},{"level":1,"name":"Water_Source","x":-3,"y":22,"z":-1},{"level":1,"name":"Water_Source","x":-3,"y":23,"z":-1},{"level":1,"name":"Water_Source","x":-3,"y":3,"z":0},{"level":1,"name":"Water_Source","x":-3,"y":4,"z":0},{"level":1,"name":"Water_Source","x":-3,"y":5,"z":0},{"level":1,"name":"Water_Source","x":-3,"y":6,"z":0},{"level":1,"name":"Water_Source","x":-3,"y":7,"z":0},{"level":1,"name":"Water_Source","x":-3,"y":8,"z":0},{"level":1,"name":"Water_Source","x":-3,"y":9,"z":0},{"level":1,"name":"Water_Source","x":-3,"y":10,"z":0},{"level":1,"name":"Water_Source","x":-3,"y":11,"z":0},{"level":1,"name":"Water_Source","x":-3,"y":12,"z":0},{"level":1,"name":"Water_Source","x":-3,"y":13,"z":0},{"level":1,"name":"Water_Source","x":-3,"y":14,"z":0},{"level":1,"name":"Water_Source","x":-3,"y":15,"z":0},{"level":1,"name":"Water_Source","x":-3,"y":16,"z":0},{"level":1,"name":"Water_Source","x":-3,"y":17,"z":0},{"level":1,"name":"Water_Source","x":-3,"y":20,"z":0},{"level":1,"name":"Water_Source","x":-3,"y":21,"z":0},{"level":1,"name":"Water_Source","x":-3,"y":22,"z":0},{"level":1,"name":"Water_Source","x":-3,"y":23,"z":0},{"level":1,"name":"Water_Source","x":-3,"y":1,"z":1},{"level":1,"name":"Water_Source","x":-3,"y":2,"z":1},{"level":1,"name":"Water_Source","x":-3,"y":3,"z":1},{"level":1,"name":"Water_Source","x":-3,"y":4,"z":1},{"level":1,"name":"Water_Source","x":-3,"y":5,"z":1},{"level":1,"name":"Water_Source","x":-3,"y":6,"z":1},{"level":1,"name":"Water_Source","x":-3,"y":7,"z":1},{"level":1,"name":"Water_Source","x":-3,"y":8,"z":1},{"level":1,"name":"Water_Source","x":-3,"y":9,"z":1},{"level":1,"name":"Water_Source","x":-3,"y":10,"z":1},{"level":1,"name":"Water_Source","x":-3,"y":11,"z":1},{"level":1,"name":"Water_Source","x":-3,"y":12,"z":1},{"level":1,"name":"Water_Source","x":-3,"y":13,"z":1},{"level":1,"name":"Water_Source","x":-3,"y":14,"z":1},{"level":1,"name":"Water_Source","x":-3,"y":15,"z":1},{"level":1,"name":"Water_Source","x":-3,"y":16,"z":1},{"level":1,"name":"Water_Source","x":-3,"y":17,"z":1},{"level":1,"name":"Water_Source","x":-3,"y":18,"z":1},{"level":1,"name":"Water_Source","x":-3,"y":19,"z":1},{"level":1,"name":"Water_Source","x":-3,"y":20,"z":1},{"level":1,"name":"Water_Source","x":-3,"y":21,"z":1},{"level":1,"name":"Water_Source","x":-3,"y":22,"z":1},{"level":1,"name":"Water_Source","x":-3,"y":23,"z":1},{"level":1,"name":"Water_Source","x":-3,"y":1,"z":2},{"level":1,"name":"Water_Source","x":-3,"y":2,"z":2},{"level":1,"name":"Water_Source","x":-3,"y":3,"z":2},{"level":1,"name":"Water_Source","x":-3,"y":4,"z":2},{"level":1,"name":"Water_Source","x":-3,"y":5,"z":2},{"level":1,"name":"Water_Source","x":-3,"y":6,"z":2},{"level":1,"name":"Water_Source","x":-3,"y":7,"z":2},{"level":1,"name":"Water_Source","x":-3,"y":8,"z":2},{"level":1,"name":"Water_Source","x":-3,"y":9,"z":2},{"level":1,"name":"Water_Source","x":-3,"y":10,"z":2},{"level":1,"name":"Water_Source","x":-3,"y":11,"z":2},{"level":1,"name":"Water_Source","x":-3,"y":12,"z":2},{"level":1,"name":"Water_Source","x":-3,"y":13,"z":2},{"level":1,"name":"Water_Source","x":-3,"y":14,"z":2},{"level":1,"name":"Water_Source","x":-3,"y":15,"z":2},{"level":1,"name":"Water_Source","x":-3,"y":16,"z":2},{"level":1,"name":"Water_Source","x":-3,"y":17,"z":2},{"level":1,"name":"Water_Source","x":-3,"y":19,"z":2},{"level":1,"name":"Water_Source","x":-3,"y":20,"z":2},{"level":1,"name":"Water_Source","x":-3,"y":21,"z":2},{"level":1,"name":"Water_Source","x":-3,"y":22,"z":2},{"level":1,"name":"Water_Source","x":-3,"y":1,"z":3},{"level":1,"name":"Water_Source","x":-3,"y":2,"z":3},{"level":1,"name":"Water_Source","x":-3,"y":3,"z":3},{"level":1,"name":"Water_Source","x":-3,"y":4,"z":3},{"level":1,"name":"Water_Source","x":-3,"y":5,"z":3},{"level":1,"name":"Water_Source","x":-3,"y":6,"z":3},{"level":1,"name":"Water_Source","x":-3,"y":7,"z":3},{"level":1,"name":"Water_Source","x":-3,"y":8,"z":3},{"level":1,"name":"Water_Source","x":-3,"y":16,"z":3},{"level":1,"name":"Water_Source","x":-3,"y":17,"z":3},{"level":1,"name":"Water_Source","x":-3,"y":20,"z":3},{"level":1,"name":"Water_Source","x":-3,"y":21,"z":3},{"level":1,"name":"Water_Source","x":-3,"y":1,"z":4},{"level":1,"name":"Water_Source","x":-3,"y":2,"z":4},{"level":1,"name":"Water_Source","x":-3,"y":3,"z":4},{"level":1,"name":"Water_Source","x":-3,"y":4,"z":4},{"level":1,"name":"Water_Source","x":-3,"y":5,"z":4},{"level":1,"name":"Water_Source","x":-3,"y":6,"z":4},{"level":1,"name":"Water_Source","x":-3,"y":20,"z":4},{"level":1,"name":"Water_Source","x":-3,"y":21,"z":4},{"level":1,"name":"Water_Source","x":-3,"y":22,"z":4},{"level":1,"name":"Water_Source","x":-3,"y":21,"z":5},{"level":1,"name":"Water_Source","x":-3,"y":22,"z":5},{"level":1,"name":"Water_Source","x":-2,"y":4,"z":-5},{"level":1,"name":"Water_Source","x":-2,"y":5,"z":-5},{"level":1,"name":"Water_Source","x":-2,"y":2,"z":-4},{"level":1,"name":"Water_Source","x":-2,"y":3,"z":-4},{"level":1,"name":"Water_Source","x":-2,"y":4,"z":-4},{"level":1,"name":"Water_Source","x":-2,"y":5,"z":-4},{"level":1,"name":"Water_Source","x":-2,"y":6,"z":-4},{"level":1,"name":"Water_Source","x":-2,"y":7,"z":-4},{"level":1,"name":"Water_Source","x":-2,"y":8,"z":-4},{"level":1,"name":"Water_Source","x":-2,"y":9,"z":-4},{"level":1,"name":"Water_Source","x":-2,"y":10,"z":-4},{"level":1,"name":"Water_Source","x":-2,"y":5,"z":-3},{"level":1,"name":"Water_Source","x":-2,"y":6,"z":-3},{"level":1,"name":"Water_Source","x":-2,"y":7,"z":-3},{"level":1,"name":"Water_Source","x":-2,"y":8,"z":-3},{"level":1,"name":"Water_Source","x":-2,"y":9,"z":-3},{"level":1,"name":"Water_Source","x":-2,"y":10,"z":-3},{"level":1,"name":"Water_Source","x":-2,"y":11,"z":-3},{"level":1,"name":"Water_Source","x":-2,"y":12,"z":-3},{"level":1,"name":"Water_Source","x":-2,"y":13,"z":-3},{"level":1,"name":"Water_Source","x":-2,"y":5,"z":-2},{"level":1,"name":"Water_Source","x":-2,"y":6,"z":-2},{"level":1,"name":"Water_Source","x":-2,"y":7,"z":-2},{"level":1,"name":"Water_Source","x":-2,"y":8,"z":-2},{"level":1,"name":"Water_Source","x":-2,"y":9,"z":-2},{"level":1,"name":"Water_Source","x":-2,"y":10,"z":-2},{"level":1,"name":"Water_Source","x":-2,"y":11,"z":-2},{"level":1,"name":"Water_Source","x":-2,"y":12,"z":-2},{"level":1,"name":"Water_Source","x":-2,"y":21,"z":-2},{"level":1,"name":"Water_Source","x":-2,"y":22,"z":-2},{"level":1,"name":"Water_Source","x":-2,"y":23,"z":-2},{"level":1,"name":"Water_Source","x":-2,"y":2,"z":-1},{"level":1,"name":"Water_Source","x":-2,"y":6,"z":-1},{"level":1,"name":"Water_Source","x":-2,"y":7,"z":-1},{"level":1,"name":"Water_Source","x":-2,"y":8,"z":-1},{"level":1,"name":"Water_Source","x":-2,"y":9,"z":-1},{"level":1,"name":"Water_Source","x":-2,"y":10,"z":-1},{"level":1,"name":"Water_Source","x":-2,"y":20,"z":-1},{"level":1,"name":"Water_Source","x":-2,"y":21,"z":-1},{"level":1,"name":"Water_Source","x":-2,"y":22,"z":-1},{"level":1,"name":"Water_Source","x":-2,"y":23,"z":-1},{"level":1,"name":"Water_Source","x":-2,"y":0,"z":0},{"level":1,"name":"Water_Source","x":-2,"y":3,"z":0},{"level":1,"name":"Water_Source","x":-2,"y":8,"z":0},{"level":1,"name":"Water_Source","x":-2,"y":10,"z":0},{"level":1,"name":"Water_Source","x":-2,"y":16,"z":0},{"level":1,"name":"Water_Source","x":-2,"y":17,"z":0},{"level":1,"name":"Water_Source","x":-2,"y":20,"z":0},{"level":1,"name":"Water_Source","x":-2,"y":21,"z":0},{"level":1,"name":"Water_Source","x":-2,"y":22,"z":0},{"level":1,"name":"Water_Source","x":-2,"y":23,"z":0},{"level":1,"name":"Water_Source","x":-2,"y":0,"z":1},{"level":1,"name":"Water_Source","x":-2,"y":1,"z":1},{"level":1,"name":"Water_Source","x":-2,"y":2,"z":1},{"level":1,"name":"Water_Source","x":-2,"y":3,"z":1},{"level":1,"name":"Water_Source","x":-2,"y":4,"z":1},{"level":1,"name":"Water_Source","x":-2,"y":8,"z":1},{"level":1,"name":"Water_Source","x":-2,"y":16,"z":1},{"level":1,"name":"Water_Source","x":-2,"y":17,"z":1},{"level":1,"name":"Water_Source","x":-2,"y":18,"z":1},{"level":1,"name":"Water_Source","x":-2,"y":19,"z":1},{"level":1,"name":"Water_Source","x":-2,"y":20,"z":1},{"level":1,"name":"Water_Source","x":-2,"y":21,"z":1},{"level":1,"name":"Water_Source","x":-2,"y":22,"z":1},{"level":1,"name":"Water_Source","x":-2,"y":23,"z":1},{"level":1,"name":"Water_Source","x":-2,"y":24,"z":1},{"level":1,"name":"Water_Source","x":-2,"y":0,"z":2},{"level":1,"name":"Water_Source","x":-2,"y":1,"z":2},{"level":1,"name":"Water_Source","x":-2,"y":2,"z":2},{"level":1,"name":"Water_Source","x":-2,"y":3,"z":2},{"level":1,"name":"Water_Source","x":-2,"y":4,"z":2},{"level":1,"name":"Water_Source","x":-2,"y":5,"z":2},{"level":1,"name":"Water_Source","x":-2,"y":6,"z":2},{"level":1,"name":"Water_Source","x":-2,"y":7,"z":2},{"level":1,"name":"Water_Source","x":-2,"y":8,"z":2},{"level":1,"name":"Water_Source","x":-2,"y":9,"z":2},{"level":1,"name":"Water_Source","x":-2,"y":10,"z":2},{"level":1,"name":"Water_Source","x":-2,"y":11,"z":2},{"level":1,"name":"Water_Source","x":-2,"y":12,"z":2},{"level":1,"name":"Water_Source","x":-2,"y":13,"z":2},{"level":1,"name":"Water_Source","x":-2,"y":14,"z":2},{"level":1,"name":"Water_Source","x":-2,"y":15,"z":2},{"level":1,"name":"Water_Source","x":-2,"y":16,"z":2},{"level":1,"name":"Water_Source","x":-2,"y":17,"z":2},{"level":1,"name":"Water_Source","x":-2,"y":18,"z":2},{"level":1,"name":"Water_Source","x":-2,"y":19,"z":2},{"level":1,"name":"Water_Source","x":-2,"y":20,"z":2},{"level":1,"name":"Water_Source","x":-2,"y":21,"z":2},{"level":1,"name":"Water_Source","x":-2,"y":22,"z":2},{"level":1,"name":"Water_Source","x":-2,"y":23,"z":2},{"level":1,"name":"Water_Source","x":-2,"y":0,"z":3},{"level":1,"name":"Water_Source","x":-2,"y":1,"z":3},{"level":1,"name":"Water_Source","x":-2,"y":2,"z":3},{"level":1,"name":"Water_Source","x":-2,"y":3,"z":3},{"level":1,"name":"Water_Source","x":-2,"y":4,"z":3},{"level":1,"name":"Water_Source","x":-2,"y":5,"z":3},{"level":1,"name":"Water_Source","x":-2,"y":6,"z":3},{"level":1,"name":"Water_Source","x":-2,"y":7,"z":3},{"level":1,"name":"Water_Source","x":-2,"y":8,"z":3},{"level":1,"name":"Water_Source","x":-2,"y":9,"z":3},{"level":1,"name":"Water_Source","x":-2,"y":10,"z":3},{"level":1,"name":"Water_Source","x":-2,"y":11,"z":3},{"level":1,"name":"Water_Source","x":-2,"y":12,"z":3},{"level":1,"name":"Water_Source","x":-2,"y":13,"z":3},{"level":1,"name":"Water_Source","x":-2,"y":14,"z":3},{"level":1,"name":"Water_Source","x":-2,"y":15,"z":3},{"level":1,"name":"Water_Source","x":-2,"y":16,"z":3},{"level":1,"name":"Water_Source","x":-2,"y":17,"z":3},{"level":1,"name":"Water_Source","x":-2,"y":20,"z":3},{"level":1,"name":"Water_Source","x":-2,"y":21,"z":3},{"level":1,"name":"Water_Source","x":-2,"y":22,"z":3},{"level":1,"name":"Water_Source","x":-2,"y":2,"z":4},{"level":1,"name":"Water_Source","x":-2,"y":3,"z":4},{"level":1,"name":"Water_Source","x":-2,"y":4,"z":4},{"level":1,"name":"Water_Source","x":-2,"y":5,"z":4},{"level":1,"name":"Water_Source","x":-2,"y":6,"z":4},{"level":1,"name":"Water_Source","x":-2,"y":7,"z":4},{"level":1,"name":"Water_Source","x":-2,"y":16,"z":4},{"level":1,"name":"Water_Source","x":-2,"y":17,"z":4},{"level":1,"name":"Water_Source","x":-2,"y":20,"z":4},{"level":1,"name":"Water_Source","x":-2,"y":21,"z":4},{"level":1,"name":"Water_Source","x":-1,"y":1,"z":-4},{"level":1,"name":"Water_Source","x":-1,"y":2,"z":-4},{"level":1,"name":"Water_Source","x":-1,"y":3,"z":-4},{"level":1,"name":"Water_Source","x":-1,"y":4,"z":-4},{"level":1,"name":"Water_Source","x":-1,"y":5,"z":-4},{"level":1,"name":"Water_Source","x":-1,"y":6,"z":-4},{"level":1,"name":"Water_Source","x":-1,"y":7,"z":-4},{"level":1,"name":"Water_Source","x":-1,"y":8,"z":-4},{"level":1,"name":"Water_Source","x":-1,"y":11,"z":-4},{"level":1,"name":"Water_Source","x":-1,"y":12,"z":-4},{"level":1,"name":"Water_Source","x":-1,"y":13,"z":-4},{"level":1,"name":"Water_Source","x":-1,"y":5,"z":-3},{"level":1,"name":"Water_Source","x":-1,"y":6,"z":-3},{"level":1,"name":"Water_Source","x":-1,"y":7,"z":-3},{"level":1,"name":"Water_Source","x":-1,"y":8,"z":-3},{"level":1,"name":"Water_Source","x":-1,"y":9,"z":-3},{"level":1,"name":"Water_Source","x":-1,"y":10,"z":-3},{"level":1,"name":"Water_Source","x":-1,"y":11,"z":-3},{"level":1,"name":"Water_Source","x":-1,"y":12,"z":-3},{"level":1,"name":"Water_Source","x":-1,"y":13,"z":-3},{"level":1,"name":"Water_Source","x":-1,"y":14,"z":-3},{"level":1,"name":"Water_Source","x":-1,"y":15,"z":-3},{"level":1,"name":"Water_Source","x":-1,"y":16,"z":-3},{"level":1,"name":"Water_Source","x":-1,"y":0,"z":-2},{"level":1,"name":"Water_Source","x":-1,"y":1,"z":-2},{"level":1,"name":"Water_Source","x":-1,"y":5,"z":-2},{"level":1,"name":"Water_Source","x":-1,"y":6,"z":-2},{"level":1,"name":"Water_Source","x":-1,"y":7,"z":-2},{"level":1,"name":"Water_Source","x":-1,"y":8,"z":-2},{"level":1,"name":"Water_Source","x":-1,"y":16,"z":-2},{"level":1,"name":"Water_Source","x":-1,"y":22,"z":-2},{"level":1,"name":"Water_Source","x":-1,"y":23,"z":-2},{"level":1,"name":"Water_Source","x":-1,"y":0,"z":-1},{"level":1,"name":"Water_Source","x":-1,"y":1,"z":-1},{"level":1,"name":"Water_Source","x":-1,"y":2,"z":-1},{"level":1,"name":"Water_Source","x":-1,"y":6,"z":-1},{"level":1,"name":"Water_Source","x":-1,"y":7,"z":-1},{"level":1,"name":"Water_Source","x":-1,"y":8,"z":-1},{"level":1,"name":"Water_Source","x":-1,"y":16,"z":-1},{"level":1,"name":"Water_Source","x":-1,"y":17,"z":-1},{"level":1,"name":"Water_Source","x":-1,"y":22,"z":-1},{"level":1,"name":"Water_Source","x":-1,"y":23,"z":-1},{"level":1,"name":"Water_Source","x":-1,"y":0,"z":0},{"level":1,"name":"Water_Source","x":-1,"y":1,"z":0},{"level":1,"name":"Water_Source","x":-1,"y":2,"z":0},{"level":1,"name":"Water_Source","x":-1,"y":3,"z":0},{"level":1,"name":"Water_Source","x":-1,"y":8,"z":0},{"level":1,"name":"Water_Source","x":-1,"y":16,"z":0},{"level":1,"name":"Water_Source","x":-1,"y":17,"z":0},{"level":1,"name":"Water_Source","x":-1,"y":22,"z":0},{"level":1,"name":"Water_Source","x":-1,"y":23,"z":0},{"level":1,"name":"Water_Source","x":-1,"y":0,"z":1},{"level":1,"name":"Water_Source","x":-1,"y":1,"z":1},{"level":1,"name":"Water_Source","x":-1,"y":2,"z":1},{"level":1,"name":"Water_Source","x":-1,"y":3,"z":1},{"level":1,"name":"Water_Source","x":-1,"y":4,"z":1},{"level":1,"name":"Water_Source","x":-1,"y":8,"z":1},{"level":1,"name":"Water_Source","x":-1,"y":11,"z":1},{"level":1,"name":"Water_Source","x":-1,"y":12,"z":1},{"level":1,"name":"Water_Source","x":-1,"y":13,"z":1},{"level":1,"name":"Water_Source","x":-1,"y":14,"z":1},{"level":1,"name":"Water_Source","x":-1,"y":15,"z":1},{"level":1,"name":"Water_Source","x":-1,"y":16,"z":1},{"level":1,"name":"Water_Source","x":-1,"y":18,"z":1},{"level":1,"name":"Water_Source","x":-1,"y":22,"z":1},{"level":1,"name":"Water_Source","x":-1,"y":0,"z":2},{"level":1,"name":"Water_Source","x":-1,"y":1,"z":2},{"level":1,"name":"Water_Source","x":-1,"y":2,"z":2},{"level":1,"name":"Water_Source","x":-1,"y":3,"z":2},{"level":1,"name":"Water_Source","x":-1,"y":4,"z":2},{"level":1,"name":"Water_Source","x":-1,"y":8,"z":2},{"level":1,"name":"Water_Source","x":-1,"y":9,"z":2},{"level":1,"name":"Water_Source","x":-1,"y":10,"z":2},{"level":1,"name":"Water_Source","x":-1,"y":11,"z":2},{"level":1,"name":"Water_Source","x":-1,"y":12,"z":2},{"level":1,"name":"Water_Source","x":-1,"y":13,"z":2},{"level":1,"name":"Water_Source","x":-1,"y":14,"z":2},{"level":1,"name":"Water_Source","x":-1,"y":15,"z":2},{"level":1,"name":"Water_Source","x":-1,"y":16,"z":2},{"level":1,"name":"Water_Source","x":-1,"y":17,"z":2},{"level":1,"name":"Water_Source","x":-1,"y":18,"z":2},{"level":1,"name":"Water_Source","x":-1,"y":19,"z":2},{"level":1,"name":"Water_Source","x":-1,"y":20,"z":2},{"level":1,"name":"Water_Source","x":-1,"y":21,"z":2},{"level":1,"name":"Water_Source","x":-1,"y":22,"z":2},{"level":1,"name":"Water_Source","x":-1,"y":23,"z":2},{"level":1,"name":"Water_Source","x":-1,"y":0,"z":3},{"level":1,"name":"Water_Source","x":-1,"y":1,"z":3},{"level":1,"name":"Water_Source","x":-1,"y":2,"z":3},{"level":1,"name":"Water_Source","x":-1,"y":3,"z":3},{"level":1,"name":"Water_Source","x":-1,"y":4,"z":3},{"level":1,"name":"Water_Source","x":-1,"y":5,"z":3},{"level":1,"name":"Water_Source","x":-1,"y":6,"z":3},{"level":1,"name":"Water_Source","x":-1,"y":7,"z":3},{"level":1,"name":"Water_Source","x":-1,"y":8,"z":3},{"level":1,"name":"Water_Source","x":-1,"y":9,"z":3},{"level":1,"name":"Water_Source","x":-1,"y":10,"z":3},{"level":1,"name":"Water_Source","x":-1,"y":11,"z":3},{"level":1,"name":"Water_Source","x":-1,"y":12,"z":3},{"level":1,"name":"Water_Source","x":-1,"y":13,"z":3},{"level":1,"name":"Water_Source","x":-1,"y":14,"z":3},{"level":1,"name":"Water_Source","x":-1,"y":15,"z":3},{"level":1,"name":"Water_Source","x":-1,"y":16,"z":3},{"level":1,"name":"Water_Source","x":-1,"y":17,"z":3},{"level":1,"name":"Water_Source","x":-1,"y":20,"z":3},{"level":1,"name":"Water_Source","x":-1,"y":21,"z":3},{"level":1,"name":"Water_Source","x":-1,"y":22,"z":3},{"level":1,"name":"Water_Source","x":-1,"y":23,"z":3},{"level":1,"name":"Water_Source","x":-1,"y":3,"z":4},{"level":1,"name":"Water_Source","x":-1,"y":4,"z":4},{"level":1,"name":"Water_Source","x":-1,"y":5,"z":4},{"level":1,"name":"Water_Source","x":-1,"y":6,"z":4},{"level":1,"name":"Water_Source","x":-1,"y":7,"z":4},{"level":1,"name":"Water_Source","x":-1,"y":11,"z":4},{"level":1,"name":"Water_Source","x":-1,"y":12,"z":4},{"level":1,"name":"Water_Source","x":-1,"y":14,"z":4},{"level":1,"name":"Water_Source","x":-1,"y":15,"z":4},{"level":1,"name":"Water_Source","x":-1,"y":16,"z":4},{"level":1,"name":"Water_Source","x":-1,"y":21,"z":4},{"level":1,"name":"Water_Source","x":-1,"y":22,"z":4},{"level":1,"name":"Water_Source","x":-1,"y":15,"z":5},{"level":1,"name":"Water_Source","x":-1,"y":16,"z":5},{"level":1,"name":"Water_Source","x":0,"y":5,"z":-4},{"level":1,"name":"Water_Source","x":0,"y":6,"z":-4},{"level":1,"name":"Water_Source","x":0,"y":7,"z":-4},{"level":1,"name":"Water_Source","x":0,"y":8,"z":-4},{"level":1,"name":"Water_Source","x":0,"y":10,"z":-4},{"level":1,"name":"Water_Source","x":0,"y":13,"z":-4},{"level":1,"name":"Water_Source","x":0,"y":14,"z":-4},{"level":1,"name":"Water_Source","x":0,"y":15,"z":-4},{"level":1,"name":"Water_Source","x":0,"y":0,"z":-3},{"level":1,"name":"Water_Source","x":0,"y":5,"z":-3},{"level":1,"name":"Water_Source","x":0,"y":6,"z":-3},{"level":1,"name":"Water_Source","x":0,"y":7,"z":-3},{"level":1,"name":"Water_Source","x":0,"y":8,"z":-3},{"level":1,"name":"Water_Source","x":0,"y":9,"z":-3},{"level":1,"name":"Water_Source","x":0,"y":10,"z":-3},{"level":1,"name":"Water_Source","x":0,"y":13,"z":-3},{"level":1,"name":"Water_Source","x":0,"y":14,"z":-3},{"level":1,"name":"Water_Source","x":0,"y":15,"z":-3},{"level":1,"name":"Water_Source","x":0,"y":16,"z":-3},{"level":1,"name":"Water_Source","x":0,"y":17,"z":-3},{"level":1,"name":"Water_Source","x":0,"y":21,"z":-3},{"level":1,"name":"Water_Source","x":0,"y":0,"z":-2},{"level":1,"name":"Water_Source","x":0,"y":5,"z":-2},{"level":1,"name":"Water_Source","x":0,"y":6,"z":-2},{"level":1,"name":"Water_Source","x":0,"y":7,"z":-2},{"level":1,"name":"Water_Source","x":0,"y":16,"z":-2},{"level":1,"name":"Water_Source","x":0,"y":17,"z":-2},{"level":1,"name":"Water_Source","x":0,"y":21,"z":-2},{"level":1,"name":"Water_Source","x":0,"y":22,"z":-2},{"level":1,"name":"Water_Source","x":0,"y":23,"z":-2},{"level":1,"name":"Water_Source","x":0,"y":0,"z":-1},{"level":1,"name":"Water_Source","x":0,"y":5,"z":-1},{"level":1,"name":"Water_Source","x":0,"y":6,"z":-1},{"level":1,"name":"Water_Source","x":0,"y":7,"z":-1},{"level":1,"name":"Water_Source","x":0,"y":16,"z":-1},{"level":1,"name":"Water_Source","x":0,"y":17,"z":-1},{"level":1,"name":"Water_Source","x":0,"y":22,"z":-1},{"level":1,"name":"Water_Source","x":0,"y":23,"z":-1},{"level":1,"name":"Water_Source","x":0,"y":0,"z":0},{"level":1,"name":"Water_Source","x":0,"y":1,"z":0},{"level":1,"name":"Water_Source","x":0,"y":2,"z":0},{"level":1,"name":"Water_Source","x":0,"y":3,"z":0},{"level":1,"name":"Water_Source","x":0,"y":4,"z":0},{"level":1,"name":"Water_Source","x":0,"y":5,"z":0},{"level":1,"name":"Water_Source","x":0,"y":6,"z":0},{"level":1,"name":"Water_Source","x":0,"y":7,"z":0},{"level":1,"name":"Water_Source","x":0,"y":8,"z":0},{"level":1,"name":"Water_Source","x":0,"y":16,"z":0},{"level":1,"name":"Water_Source","x":0,"y":17,"z":0},{"level":1,"name":"Water_Source","x":0,"y":22,"z":0},{"level":1,"name":"Water_Source","x":0,"y":23,"z":0},{"level":1,"name":"Water_Source","x":0,"y":0,"z":1},{"level":1,"name":"Water_Source","x":0,"y":1,"z":1},{"level":1,"name":"Water_Source","x":0,"y":2,"z":1},{"level":1,"name":"Water_Source","x":0,"y":3,"z":1},{"level":1,"name":"Water_Source","x":0,"y":4,"z":1},{"level":1,"name":"Water_Source","x":0,"y":5,"z":1},{"level":1,"name":"Water_Source","x":0,"y":8,"z":1},{"level":1,"name":"Water_Source","x":0,"y":16,"z":1},{"level":1,"name":"Water_Source","x":0,"y":17,"z":1},{"level":1,"name":"Water_Source","x":0,"y":22,"z":1},{"level":1,"name":"Water_Source","x":0,"y":23,"z":1},{"level":1,"name":"Water_Source","x":0,"y":0,"z":2},{"level":1,"name":"Water_Source","x":0,"y":1,"z":2},{"level":1,"name":"Water_Source","x":0,"y":2,"z":2},{"level":1,"name":"Water_Source","x":0,"y":3,"z":2},{"level":1,"name":"Water_Source","x":0,"y":4,"z":2},{"level":1,"name":"Water_Source","x":0,"y":5,"z":2},{"level":1,"name":"Water_Source","x":0,"y":8,"z":2},{"level":1,"name":"Water_Source","x":0,"y":9,"z":2},{"level":1,"name":"Water_Source","x":0,"y":10,"z":2},{"level":1,"name":"Water_Source","x":0,"y":14,"z":2},{"level":1,"name":"Water_Source","x":0,"y":15,"z":2},{"level":1,"name":"Water_Source","x":0,"y":16,"z":2},{"level":1,"name":"Water_Source","x":0,"y":17,"z":2},{"level":1,"name":"Water_Source","x":0,"y":20,"z":2},{"level":1,"name":"Water_Source","x":0,"y":21,"z":2},{"level":1,"name":"Water_Source","x":0,"y":22,"z":2},{"level":1,"name":"Water_Source","x":0,"y":23,"z":2},{"level":1,"name":"Water_Source","x":0,"y":0,"z":3},{"level":1,"name":"Water_Source","x":0,"y":1,"z":3},{"level":1,"name":"Water_Source","x":0,"y":2,"z":3},{"level":1,"name":"Water_Source","x":0,"y":3,"z":3},{"level":1,"name":"Water_Source","x":0,"y":4,"z":3},{"level":1,"name":"Water_Source","x":0,"y":5,"z":3},{"level":1,"name":"Water_Source","x":0,"y":6,"z":3},{"level":1,"name":"Water_Source","x":0,"y":7,"z":3},{"level":1,"name":"Water_Source","x":0,"y":8,"z":3},{"level":1,"name":"Water_Source","x":0,"y":9,"z":3},{"level":1,"name":"Water_Source","x":0,"y":10,"z":3},{"level":1,"name":"Water_Source","x":0,"y":11,"z":3},{"level":1,"name":"Water_Source","x":0,"y":12,"z":3},{"level":1,"name":"Water_Source","x":0,"y":13,"z":3},{"level":1,"name":"Water_Source","x":0,"y":14,"z":3},{"level":1,"name":"Water_Source","x":0,"y":15,"z":3},{"level":1,"name":"Water_Source","x":0,"y":16,"z":3},{"level":1,"name":"Water_Source","x":0,"y":17,"z":3},{"level":1,"name":"Water_Source","x":0,"y":20,"z":3},{"level":1,"name":"Water_Source","x":0,"y":21,"z":3},{"level":1,"name":"Water_Source","x":0,"y":22,"z":3},{"level":1,"name":"Water_Source","x":0,"y":23,"z":3},{"level":1,"name":"Water_Source","x":0,"y":2,"z":4},{"level":1,"name":"Water_Source","x":0,"y":3,"z":4},{"level":1,"name":"Water_Source","x":0,"y":4,"z":4},{"level":1,"name":"Water_Source","x":0,"y":5,"z":4},{"level":1,"name":"Water_Source","x":0,"y":6,"z":4},{"level":1,"name":"Water_Source","x":0,"y":7,"z":4},{"level":1,"name":"Water_Source","x":0,"y":8,"z":4},{"level":1,"name":"Water_Source","x":0,"y":10,"z":4},{"level":1,"name":"Water_Source","x":0,"y":12,"z":4},{"level":1,"name":"Water_Source","x":0,"y":13,"z":4},{"level":1,"name":"Water_Source","x":0,"y":14,"z":4},{"level":1,"name":"Water_Source","x":0,"y":15,"z":4},{"level":1,"name":"Water_Source","x":0,"y":16,"z":4},{"level":1,"name":"Water_Source","x":0,"y":21,"z":4},{"level":1,"name":"Water_Source","x":0,"y":22,"z":4},{"level":1,"name":"Water_Source","x":0,"y":14,"z":5},{"level":1,"name":"Water_Source","x":0,"y":15,"z":5},{"level":1,"name":"Water_Source","x":1,"y":1,"z":-4},{"level":1,"name":"Water_Source","x":1,"y":2,"z":-4},{"level":1,"name":"Water_Source","x":1,"y":7,"z":-4},{"level":1,"name":"Water_Source","x":1,"y":8,"z":-4},{"level":1,"name":"Water_Source","x":1,"y":12,"z":-4},{"level":1,"name":"Water_Source","x":1,"y":13,"z":-4},{"level":1,"name":"Water_Source","x":1,"y":0,"z":-3},{"level":1,"name":"Water_Source","x":1,"y":5,"z":-3},{"level":1,"name":"Water_Source","x":1,"y":6,"z":-3},{"level":1,"name":"Water_Source","x":1,"y":7,"z":-3},{"level":1,"name":"Water_Source","x":1,"y":8,"z":-3},{"level":1,"name":"Water_Source","x":1,"y":9,"z":-3},{"level":1,"name":"Water_Source","x":1,"y":10,"z":-3},{"level":1,"name":"Water_Source","x":1,"y":11,"z":-3},{"level":1,"name":"Water_Source","x":1,"y":12,"z":-3},{"level":1,"name":"Water_Source","x":1,"y":13,"z":-3},{"level":1,"name":"Water_Source","x":1,"y":14,"z":-3},{"level":1,"name":"Water_Source","x":1,"y":15,"z":-3},{"level":1,"name":"Water_Source","x":1,"y":16,"z":-3},{"level":1,"name":"Water_Source","x":1,"y":17,"z":-3},{"level":1,"name":"Water_Source","x":1,"y":18,"z":-3},{"level":1,"name":"Water_Source","x":1,"y":19,"z":-3},{"level":1,"name":"Water_Source","x":1,"y":20,"z":-3},{"level":1,"name":"Water_Source","x":1,"y":21,"z":-3},{"level":1,"name":"Water_Source","x":1,"y":22,"z":-3},{"level":1,"name":"Water_Source","x":1,"y":0,"z":-2},{"level":1,"name":"Water_Source","x":1,"y":5,"z":-2},{"level":1,"name":"Water_Source","x":1,"y":6,"z":-2},{"level":1,"name":"Water_Source","x":1,"y":7,"z":-2},{"level":1,"name":"Water_Source","x":1,"y":16,"z":-2},{"level":1,"name":"Water_Source","x":1,"y":17,"z":-2},{"level":1,"name":"Water_Source","x":1,"y":18,"z":-2},{"level":1,"name":"Water_Source","x":1,"y":19,"z":-2},{"level":1,"name":"Water_Source","x":1,"y":20,"z":-2},{"level":1,"name":"Water_Source","x":1,"y":21,"z":-2},{"level":1,"name":"Water_Source","x":1,"y":22,"z":-2},{"level":1,"name":"Water_Source","x":1,"y":23,"z":-2},{"level":1,"name":"Water_Source","x":1,"y":0,"z":-1},{"level":1,"name":"Water_Source","x":1,"y":5,"z":-1},{"level":1,"name":"Water_Source","x":1,"y":6,"z":-1},{"level":1,"name":"Water_Source","x":1,"y":7,"z":-1},{"level":1,"name":"Water_Source","x":1,"y":16,"z":-1},{"level":1,"name":"Water_Source","x":1,"y":17,"z":-1},{"level":1,"name":"Water_Source","x":1,"y":22,"z":-1},{"level":1,"name":"Water_Source","x":1,"y":23,"z":-1},{"level":1,"name":"Water_Source","x":1,"y":0,"z":0},{"level":1,"name":"Water_Source","x":1,"y":5,"z":0},{"level":1,"name":"Water_Source","x":1,"y":6,"z":0},{"level":1,"name":"Water_Source","x":1,"y":16,"z":0},{"level":1,"name":"Water_Source","x":1,"y":17,"z":0},{"level":1,"name":"Water_Source","x":1,"y":22,"z":0},{"level":1,"name":"Water_Source","x":1,"y":0,"z":1},{"level":1,"name":"Water_Source","x":1,"y":1,"z":1},{"level":1,"name":"Water_Source","x":1,"y":5,"z":1},{"level":1,"name":"Water_Source","x":1,"y":6,"z":1},{"level":1,"name":"Water_Source","x":1,"y":16,"z":1},{"level":1,"name":"Water_Source","x":1,"y":17,"z":1},{"level":1,"name":"Water_Source","x":1,"y":22,"z":1},{"level":1,"name":"Water_Source","x":1,"y":23,"z":1},{"level":1,"name":"Water_Source","x":1,"y":0,"z":2},{"level":1,"name":"Water_Source","x":1,"y":1,"z":2},{"level":1,"name":"Water_Source","x":1,"y":5,"z":2},{"level":1,"name":"Water_Source","x":1,"y":13,"z":2},{"level":1,"name":"Water_Source","x":1,"y":14,"z":2},{"level":1,"name":"Water_Source","x":1,"y":16,"z":2},{"level":1,"name":"Water_Source","x":1,"y":17,"z":2},{"level":1,"name":"Water_Source","x":1,"y":18,"z":2},{"level":1,"name":"Water_Source","x":1,"y":19,"z":2},{"level":1,"name":"Water_Source","x":1,"y":20,"z":2},{"level":1,"name":"Water_Source","x":1,"y":21,"z":2},{"level":1,"name":"Water_Source","x":1,"y":22,"z":2},{"level":1,"name":"Water_Source","x":1,"y":23,"z":2},{"level":1,"name":"Water_Source","x":1,"y":0,"z":3},{"level":1,"name":"Water_Source","x":1,"y":1,"z":3},{"level":1,"name":"Water_Source","x":1,"y":5,"z":3},{"level":1,"name":"Water_Source","x":1,"y":6,"z":3},{"level":1,"name":"Water_Source","x":1,"y":7,"z":3},{"level":1,"name":"Water_Source","x":1,"y":8,"z":3},{"level":1,"name":"Water_Source","x":1,"y":9,"z":3},{"level":1,"name":"Water_Source","x":1,"y":10,"z":3},{"level":1,"name":"Water_Source","x":1,"y":11,"z":3},{"level":1,"name":"Water_Source","x":1,"y":12,"z":3},{"level":1,"name":"Water_Source","x":1,"y":13,"z":3},{"level":1,"name":"Water_Source","x":1,"y":14,"z":3},{"level":1,"name":"Water_Source","x":1,"y":15,"z":3},{"level":1,"name":"Water_Source","x":1,"y":16,"z":3},{"level":1,"name":"Water_Source","x":1,"y":17,"z":3},{"level":1,"name":"Water_Source","x":1,"y":20,"z":3},{"level":1,"name":"Water_Source","x":1,"y":21,"z":3},{"level":1,"name":"Water_Source","x":1,"y":22,"z":3},{"level":1,"name":"Water_Source","x":1,"y":23,"z":3},{"level":1,"name":"Water_Source","x":1,"y":2,"z":4},{"level":1,"name":"Water_Source","x":1,"y":3,"z":4},{"level":1,"name":"Water_Source","x":1,"y":4,"z":4},{"level":1,"name":"Water_Source","x":1,"y":5,"z":4},{"level":1,"name":"Water_Source","x":1,"y":6,"z":4},{"level":1,"name":"Water_Source","x":1,"y":7,"z":4},{"level":1,"name":"Water_Source","x":1,"y":11,"z":4},{"level":1,"name":"Water_Source","x":1,"y":12,"z":4},{"level":1,"name":"Water_Source","x":1,"y":21,"z":4},{"level":1,"name":"Water_Source","x":1,"y":22,"z":4},{"level":1,"name":"Water_Source","x":2,"y":1,"z":-4},{"level":1,"name":"Water_Source","x":2,"y":2,"z":-4},{"level":1,"name":"Water_Source","x":2,"y":3,"z":-4},{"level":1,"name":"Water_Source","x":2,"y":4,"z":-4},{"level":1,"name":"Water_Source","x":2,"y":14,"z":-4},{"level":1,"name":"Water_Source","x":2,"y":15,"z":-4},{"level":1,"name":"Water_Source","x":2,"y":16,"z":-4},{"level":1,"name":"Water_Source","x":2,"y":0,"z":-3},{"level":1,"name":"Water_Source","x":2,"y":1,"z":-3},{"level":1,"name":"Water_Source","x":2,"y":5,"z":-3},{"level":1,"name":"Water_Source","x":2,"y":6,"z":-3},{"level":1,"name":"Water_Source","x":2,"y":7,"z":-3},{"level":1,"name":"Water_Source","x":2,"y":8,"z":-3},{"level":1,"name":"Water_Source","x":2,"y":9,"z":-3},{"level":1,"name":"Water_Source","x":2,"y":10,"z":-3},{"level":1,"name":"Water_Source","x":2,"y":11,"z":-3},{"level":1,"name":"Water_Source","x":2,"y":12,"z":-3},{"level":1,"name":"Water_Source","x":2,"y":13,"z":-3},{"level":1,"name":"Water_Source","x":2,"y":14,"z":-3},{"level":1,"name":"Water_Source","x":2,"y":15,"z":-3},{"level":1,"name":"Water_Source","x":2,"y":16,"z":-3},{"level":1,"name":"Water_Source","x":2,"y":0,"z":-2},{"level":1,"name":"Water_Source","x":2,"y":5,"z":-2},{"level":1,"name":"Water_Source","x":2,"y":6,"z":-2},{"level":1,"name":"Water_Source","x":2,"y":7,"z":-2},{"level":1,"name":"Water_Source","x":2,"y":8,"z":-2},{"level":1,"name":"Water_Source","x":2,"y":9,"z":-2},{"level":1,"name":"Water_Source","x":2,"y":10,"z":-2},{"level":1,"name":"Water_Source","x":2,"y":11,"z":-2},