{
  "version": 8,
  "blockIdVersion": 11,
  "anchorX": 0,
  "anchorY": 0,
  "anchorZ": 0,
  "blocks": [
    {
      "x": -10,
      "y": 1,
      "z": -3,
      "name": "Rock_Stone_Brick_Mossy",
      "rotation": 2
    },
    {
      "x": -10,
      "y": 2,
      "z": -3,
      "name": "Rock_Quartzite_Brick",
      "rotation": 2
    },
    {
      "x": -10,
      "y": 3,
      "z": -3,
      "name": "Soil_Quartzite_Gravel",
      "rotation": 2
    },
    {
      "x": -10,
      "y": 4,
      "z": -3,
      "name": "Rock_Quartzite_Brick",
      "rotation": 2
    },
    {
      "x": -10,
      "y": 1,
      "z": -2,
      "name": "Rock_Stone_Brick",
      "rotation": 2
    },
    {
      "x": -10,
      "y": 2,
      "z": -2,
      "name": "Rubble_Stone_Mossy_Medium",
      "support": 15,
      "rotation": 2
    },
    {
      "x": -10,
      "y": 5,
      "z": -2,
      "name": "Rock_Quartzite_Brick_Stairs",
      "rotation": 32
    },
    {
      "x": -10,
      "y": 6,
      "z": -2,
      "name": "Rock_Quartzite_Brick",
      "rotation": 2
    },
    {
      "x": -10,
      "y": 0,
      "z": -1,
      "name": "Rock_Stone_Brick",
      "rotation": 2
    },
    {
      "x": -10,
      "y": 1,
      "z": -1,
      "name": "Soil_Clay_Brick",
      "rotation": 2
    },
    {
      "x": -10,
      "y": 2,
      "z": -1,
      "name": "Soil_Clay_Brick_Wall",
      "rotation": 2
    },
    {
      "x": -10,
      "y": 6,
      "z": -1,
      "name": "Rock_Quartzite_Brick_Half",
      "rotation": 4
    },
    {
      "x": -10,
      "y": 7,
      "z": -1,
      "name": "Rock_Quartzite_Brick",
      "rotation": 2
    },
    {
      "x": -10,
      "y": 0,
      "z": 0,
      "name": "Rock_Stone_Brick_Mossy",
      "rotation": 2
    },
    {
      "x": -10,
      "y": 1,
      "z": 0,
      "name": "Soil_Mud",
      "rotation": 2
    },
    {
      "x": -10,
      "y": 7,
      "z": 0,
      "name": "Build_Lightsource_YellowLight",
      "rotation": 6
    },
    {
      "x": -10,
      "y": 8,
      "z": 0,
      "name": "Rock_Quartzite_Brick",
      "rotation": 2
    },
    {
      "x": -10,
      "y": 0,
      "z": 1,
      "name": "Rock_Stone_Brick_Mossy",
      "rotation": 2
    },
    {
      "x": -10,
      "y": 1,
      "z": 1,
      "name": "Soil_Clay_Brick",
      "rotation": 2
    },
    {
      "x": -10,
      "y": 2,
      "z": 1,
      "name": "Soil_Clay_Brick_Wall",
      "rotation": 2
    },
    {
      "x": -10,
      "y": 6,
      "z": 1,
      "name": "Rock_Quartzite_Brick_Half",
      "rotation": 6
    },
    {
      "x": -10,
      "y": 7,
      "z": 1,
      "name": "Rock_Quartzite_Brick",
      "rotation": 2
    },
    {
      "x": -10,
      "y": 1,
      "z": 2,
      "name": "Rock_Stone_Brick_Mossy",
      "rotation": 2
    },
    {
      "x": -10,
      "y": 2,
      "z": 2,
      "name": "Rubble_Stone_Mossy",
      "support": 15,
      "rotation": 2
    },
    {
      "x": -10,
      "y": 5,
      "z": 2,
      "name": "Rock_Quartzite_Brick_Stairs",
      "rotation": 34
    },
    {
      "x": -10,
      "y": 6,
      "z": 2,
      "name": "Rock_Quartzite_Brick",
      "rotation": 2
    },
    {
      "x": -10,
      "y": 1,
      "z": 3,
      "name": "Rock_Stone_Brick_Mossy",
      "rotation": 2
    },
    {
      "x": -10,
      "y": 2,
      "z": 3,
      "name": "Soil_Quartzite_Gravel",
      "rotation": 2
    },
    {
      "x": -10,
      "y": 3,
      "z": 3,
      "name": "Rock_Quartzite_Brick",
      "rotation": 2
    },
    {
      "x": -10,
      "y": 4,
      "z": 3,
      "name": "Rock_Quartzite_Brick",
      "rotation": 2
    },
    {
      "x": -9,
      "y": 1,
      "z": -3,
      "name": "Rock_Stone_Brick_Mossy",
      "rotation": 2
    },
    {
      "x": -9,
      "y": 2,
      "z": -3,
      "name": "Rock_Quartzite_Brick",
      "rotation": 2
    },
    {
      "x": -9,
      "y": 3,
      "z": -3,
      "name": "Soil_Quartzite_Gravel",
      "rotation": 2
    },
    {
      "x": -9,
      "y": 4,
      "z": -3,
      "name": "Rock_Quartzite_Brick",
      "rotation": 2
    },
    {
      "x": -9,
      "y": 1,
      "z": -2,
      "name": "Rock_Stone_Brick",
      "rotation": 2
    },
    {
      "x": -9,
      "y": 2,
      "z": -2,
      "name": "Rubble_Stone_Mossy_Medium",
      "support": 15,
      "rotation": 2
    },
    {
      "x": -9,
      "y": 5,
      "z": -2,
      "name": "Rock_Quartzite_Brick_Stairs",
      "rotation": 32
    },
    {
      "x": -9,
      "y": 6,
      "z": -2,
      "name": "Rock_Quartzite_Brick",
      "rotation": 2
    },
    {
      "x": -9,
      "y": 0,
      "z": -1,
      "name": "Rock_Stone_Brick",
      "rotation": 2
    },
    {
      "x": -9,
      "y": 1,
      "z": -1,
      "name": "Soil_Clay_Brick",
      "rotation": 2
    },
    {
      "x": -9,
      "y": 2,
      "z": -1,
      "name": "Soil_Clay_Brick_Wall",
      "rotation": 2
    },
    {
      "x": -9,
      "y": 6,
      "z": -1,
      "name": "Rock_Quartzite_Brick_Half",
      "rotation": 4
    },
    {
      "x": -9,
      "y": 7,
      "z": -1,
      "name": "Rock_Quartzite_Brick",
      "rotation": 2
    },
    {
      "x": -9,
      "y": 0,
      "z": 0,
      "name": "Rock_Stone_Brick_Mossy",
      "rotation": 2
    },
    {
      "x": -9,
      "y": 1,
      "z": 0,
      "name": "Soil_Mud",
      "rotation": 2
    },
    {
      "x": -9,
      "y": 7,
      "z": 0,
      "name": "Build_Lightsource_YellowLight",
      "rotation": 6
    },
    {
      "x": -9,
      "y": 8,
      "z": 0,
      "name": "Rock_Quartzite_Brick",
      "rotation": 2
    },
    {
      "x": -9,
      "y": 0,
      "z": 1,
      "name": "Rock_Stone_Brick_Mossy",
      "rotation": 2
    },
    {
      "x": -9,
      "y": 1,
      "z": 1,
      "name": "Soil_Clay_Brick",
      "rotation": 2
    },
    {
      "x": -9,
      "y": 2,
      "z": 1,
      "name": "Soil_Clay_Brick_Wall",
      "rotation": 2
    },
    {
      "x": -9,
      "y": 6,
      "z": 1,
      "name": "Rock_Quartzite_Brick_Half",
      "rotation": 6
    },
    {
      "x": -9,
      "y": 7,
      "z": 1,
      "name": "Rock_Quartzite_Brick",
      "rotation": 2
    },
    {
      "x": -9,
      "y": 1,
      "z": 2,
      "name": "Rock_Stone_Brick_Mossy",
      "rotation": 2
    },
    {
      "x": -9,
      "y": 2,
      "z": 2,
      "name": "Rubble_Stone_Mossy",
      "support": 15,
      "rotation": 2
    },
    {
      "x": -9,
      "y": 5,
      "z": 2,
      "name": "Rock_Quartzite_Brick_Stairs",
      "rotation": 34
    },
    {
      "x": -9,
      "y": 6,
      "z": 2,
      "name": "Rock_Quartzite_Brick",
      "rotation": 2
    },
    {
      "x": -9,
      "y": 1,
      "z": 3,
      "name": "Rock_Stone_Brick_Mossy",
      "rotation": 2
    },
    {
      "x": -9,
      "y": 2,
      "z": 3,
      "name": "Soil_Quartzite_Gravel",
      "rotation": 2
    },
    {
      "x": -9,
      "y": 3,
      "z": 3,
      "name": "Rock_Quartzite_Brick",
      "rotation": 2
    },
    {
      "x": -9,
      "y": 4,
      "z": 3,
      "name": "Rock_Quartzite_Brick",
      "rotation": 2
    },
    {
      "x": -8,
      "y": 1,
      "z": -3,
      "name": "Rock_Stone_Brick_Mossy",
      "rotation": 2
    },
    {
      "x": -8,
      "y": 2,
      "z": -3,
      "name": "Rock_Quartzite_Brick",
      "rotation": 2
    },
    {
      "x": -8,
      "y": 3,
      "z": -3,
      "name": "Soil_Quartzite_Gravel",
      "rotation": 2
    },
    {
      "x": -8,
      "y": 4,
      "z": -3,
      "name": "Rock_Quartzite_Brick",
      "rotation": 2
    },
    {
      "x": -8,
      "y": 1,
      "z": -2,
      "name": "Rock_Stone_Brick",
      "rotation": 2
    },
    {
      "x": -8,
      "y": 2,
      "z": -2,
      "name": "Rubble_Stone_Mossy_Medium",
      "support": 15,
      "rotation": 2
    },
    {
      "x": -8,
      "y": 5,
      "z": -2,
      "name": "Rock_Quartzite_Brick_Stairs",
      "rotation": 32
    },
    {
      "x": -8,
      "y": 6,
      "z": -2,
      "name": "Rock_Quartzite_Brick",
      "rotation": 2
    },
    {
      "x": -8,
      "y": 0,
      "z": -1,
      "name": "Rock_Stone_Brick",
      "rotation": 2
    },
    {
      "x": -8,
      "y": 1,
      "z": -1,
      "name": "Soil_Clay_Brick",
      "rotation": 2
    },
    {
      "x": -8,
      "y": 2,
      "z": -1,
      "name": "Soil_Clay_Brick_Wall",
      "rotation": 2
    },
    {
      "x": -8,
      "y": 6,
      "z": -1,
      "name": "Rock_Quartzite_Brick_Half",
      "rotation": 4
    },
    {
      "x": -8,
      "y": 7,
      "z": -1,
      "name": "Rock_Quartzite_Brick",
      "rotation": 2
    },
    {
      "x": -8,
      "y": 0,
      "z": 0,
      "name": "Rock_Stone_Brick_Mossy",
      "rotation": 2
    },
    {
      "x": -8,
      "y": 1,
      "z": 0,
      "name": "Soil_Mud",
      "rotation": 2
    },
    {
      "x": -8,
      "y": 7,
      "z": 0,
      "name": "Build_Lightsource_YellowLight",
      "rotation": 6
    },
    {
      "x": -8,
      "y": 8,
      "z": 0,
      "name": "Rock_Quartzite_Brick",
      "rotation": 2
    },
    {
      "x": -8,
      "y": 0,
      "z": 1,
      "name": "Rock_Stone_Brick_Mossy",
      "rotation": 2
    },
    {
      "x": -8,
      "y": 1,
      "z": 1,
      "name": "Soil_Clay_Brick",
      "rotation": 2
    },
    {
      "x": -8,
      "y": 2,
      "z": 1,
      "name": "Soil_Clay_Brick_Wall",
      "rotation": 2
    },
    {
      "x": -8,
      "y": 6,
      "z": 1,
      "name": "Rock_Quartzite_Brick_Half",
      "rotation": 6
    },
    {
      "x": -8,
      "y": 7,
      "z": 1,
      "name": "Rock_Quartzite_Brick",
      "rotation": 2
    },
    {
      "x": -8,
      "y": 1,
      "z": 2,
      "name": "Rock_Stone_Brick_Mossy",
      "rotation": 2
    },
    {
      "x": -8,
      "y": 2,
      "z": 2,
      "name": "Rubble_Stone_Mossy",
      "support": 15,
      "rotation": 2
    },
    {
      "x": -8,
      "y": 5,
      "z": 2,
      "name": "Rock_Quartzite_Brick_Stairs",
      "rotation": 34
    },
    {
      "x": -8,
      "y": 6,
      "z": 2,
      "name": "Rock_Quartzite_Brick",
      "rotation": 2
    },
    {
      "x": -8,
      "y": 1,
      "z": 3,
      "name": "Rock_Stone_Brick_Mossy",
      "rotation": 2
    },
    {
      "x": -8,
      "y": 2,
      "z": 3,
      "name": "Soil_Quartzite_Gravel",
      "rotation": 2
    },
    {
      "x": -8,
      "y": 3,
      "z": 3,
      "name": "Rock_Quartzite_Brick",
      "rotation": 2
    },
    {
      "x": -8,
      "y": 4,
      "z": 3,
      "name": "Rock_Quartzite_Brick",
      "rotation": 2
    },
    {
      "x": -7,
      "y": 1,
      "z": -3,
      "name": "Rock_Stone_Brick_Mossy"
    },
    {
      "x": -7,
      "y": 2,
      "z": -3,
      "name": "Rock_Quartzite_Brick"
    },
    {
      "x": -7,
      "y": 3,
      "z": -3,
      "name": "Rock_Quartzite_Brick"
    },
    {
      "x": -7,
      "y": 4,
      "z": -3,
      "name": "Rock_Quartzite_Brick"
    },
    {
      "x": -7,
      "y": 5,
      "z": -3,
      "name": "Rock_Quartzite_Brick"
    },
    {
      "x": -7,
      "y": 1,
      "z": -2,
      "name": "Rock_Stone_Brick_Mossy"
    },
    {
      "x": -7,
      "y": 5,
      "z": -2,
      "name": "Rock_Quartzite_Brick_Stairs",
      "rotation": 10
    },
    {
      "x": -7,
      "y": 6,
      "z": -2,
      "name": "Rock_Quartzite_Brick"
    },
    {
      "x": -7,
      "y": 0,
      "z": -1,
      "name": "Rock_Stone_Brick_Mossy"
    },
    {
      "x": -7,
      "y": 1,
      "z": -1,
      "name": "Soil_Clay_Brick"
    },
    {
      "x": -7,
      "y": 2,
      "z": -1,
      "name": "Soil_Clay_Brick_Wall"
    },
    {
      "x": -7,
      "y": 6,
      "z": -1,
      "name": "Rock_Quartzite_Brick_Half",
      "rotation": 4
    },
    {
      "x": -7,
      "y": 7,
      "z": -1,
      "name": "Rock_Quartzite_Brick"
    },
    {
      "x": -7,
      "y": 0,
      "z": 0,
      "name": "Rock_Stone_Brick_Mossy"
    },
    {
      "x": -7,
      "y": 1,
      "z": 0,
      "name": "Soil_Mud"
    },
    {
      "x": -7,
      "y": 7,
      "z": 0,
      "name": "Build_Lightsource_YellowLight",
      "rotation": 4
    },
    {
      "x": -7,
      "y": 8,
      "z": 0,
      "name": "Rock_Quartzite_Brick"
    },
    {
      "x": -7,
      "y": 0,
      "z": 1,
      "name": "Rock_Stone_Brick_Mossy"
    },
    {
      "x": -7,
      "y": 1,
      "z": 1,
      "name": "Soil_Clay_Brick"
    },
    {
      "x": -7,
      "y": 2,
      "z": 1,
      "name": "Soil_Clay_Brick_Wall"
    },
    {
      "x": -7,
      "y": 6,
      "z": 1,
      "name": "Rock_Quartzite_Brick_Half",
      "rotation": 6
    },
    {
      "x": -7,
      "y": 7,
      "z": 1,
      "name": "Rock_Quartzite_Brick"
    },
    {
      "x": -7,
      "y": 1,
      "z": 2,
      "name": "Rock_Stone_Brick_Mossy"
    },
    {
      "x": -7,
      "y": 2,
      "z": 2,
      "name": "Rubble_Stone",
      "support": 15
    },
    {
      "x": -7,
      "y": 5,
      "z": 2,
      "name": "Rock_Quartzite_Brick_Stairs",
      "rotation": 8
    },
    {
      "x": -7,
      "y": 6,
      "z": 2,
      "name": "Rock_Quartzite_Brick"
    },
    {
      "x": -7,
      "y": 1,
      "z": 3,
      "name": "Rock_Stone_Brick_Mossy"
    },
    {
      "x": -7,
      "y": 2,
      "z": 3,
      "name": "Rock_Quartzite_Brick"
    },
    {
      "x": -7,
      "y": 3,
      "z": 3,
      "name": "Soil_Quartzite_Gravel"
    },
    {
      "x": -7,
      "y": 4,
      "z": 3,
      "name": "Rock_Quartzite_Brick"
    },
    {
      "x": -6,
      "y": 1,
      "z": -3,
      "name": "Rock_Stone_Brick"
    },
    {
      "x": -6,
      "y": 2,
      "z": -3,
      "name": "Rock_Quartzite_Brick"
    },
    {
      "x": -6,
      "y": 3,
      "z": -3,
      "name": "Rock_Quartzite_Brick"
    },
    {
      "x": -6,
      "y": 4,
      "z": -3,
      "name": "Rock_Quartzite_Brick"
    },
    {
      "x": -6,
      "y": 1,
      "z": -2,
      "name": "Rock_Stone_Brick_Mossy"
    },
    {
      "x": -6,
      "y": 5,
      "z": -2,
      "name": "Rock_Quartzite_Brick_Stairs",
      "rotation": 10
    },
    {
      "x": -6,
      "y": 6,
      "z": -2,
      "name": "Soil_Quartzite_Gravel"
    },
    {
      "x": -6,
      "y": 0,
      "z": -1,
      "name": "Rock_Stone_Brick_Mossy"
    },
    {
      "x": -6,
      "y": 1,
      "z": -1,
      "name": "Soil_Clay_Brick"
    },
    {
      "x": -6,
      "y": 2,
      "z": -1,
      "name": "Soil_Clay_Brick_Wall"
    },
    {
      "x": -6,
      "y": 6,
      "z": -1,
      "name": "Rock_Quartzite_Brick_Half",
      "rotation": 4
    },
    {
      "x": -6,
      "y": 7,
      "z": -1,
      "name": "Rock_Quartzite_Brick"
    },
    {
      "x": -6,
      "y": 0,
      "z": 0,
      "name": "Rock_Stone_Brick_Mossy"
    },
    {
      "x": -6,
      "y": 1,
      "z": 0,
      "name": "Soil_Mud"
    },
    {
      "x": -6,
      "y": 7,
      "z": 0,
      "name": "Rock_Quartzite_Brick"
    },
    {
      "x": -6,
      "y": 0,
      "z": 1,
      "name": "Rock_Stone_Brick_Mossy"
    },
    {
      "x": -6,
      "y": 1,
      "z": 1,
      "name": "Soil_Clay_Brick"
    },
    {
      "x": -6,
      "y": 2,
      "z": 1,
      "name": "Soil_Clay_Brick_Wall"
    },
    {
      "x": -6,
      "y": 6,
      "z": 1,
      "name": "Rock_Quartzite_Brick_Half",
      "rotation": 6
    },
    {
      "x": -6,
      "y": 7,
      "z": 1,
      "name": "Rock_Quartzite_Brick"
    },
    {
      "x": -6,
      "y": 1,
      "z": 2,
      "name": "Rock_Stone_Brick"
    },
    {
      "x": -6,
      "y": 5,
      "z": 2,
      "name": "Rock_Quartzite_Brick_Stairs",
      "rotation": 8
    },
    {
      "x": -6,
      "y": 6,
      "z": 2,
      "name": "Rock_Quartzite_Brick"
    },
    {
      "x": -6,
      "y": 1,
      "z": 3,
      "name": "Rock_Stone_Brick_Mossy"
    },
    {
      "x": -6,
      "y": 2,
      "z": 3,
      "name": "Soil_Quartzite_Gravel"
    },
    {
      "x": -6,
      "y": 3,
      "z": 3,
      "name": "Deco_Bone_Skulls_Feran_Wall",
      "rotation": 2
    },
    {
      "x": -6,
      "y": 4,
      "z": 3,
      "name": "Rock_Quartzite_Brick"
    },
    {
      "x": -5,
      "y": 1,
      "z": -3,
      "name": "Rock_Stone_Brick"
    },
    {
      "x": -5,
      "y": 2,
      "z": -3,
      "name": "Rock_Quartzite_Brick"
    },
    {
      "x": -5,
      "y": 3,
      "z": -3,
      "name": "Rock_Quartzite_Brick"
    },
    {
      "x": -5,
      "y": 4,
      "z": -3,
      "name": "Soil_Quartzite_Gravel"
    },
    {
      "x": -5,
      "y": 1,
      "z": -2,
      "name": "Rock_Stone_Brick_Mossy"
    },
    {
      "x": -5,
      "y": 2,
      "z": -2,
      "name": "Rubble_Stone_Mossy_Medium",
      "support": 15
    },
    {
      "x": -5,
      "y": 5,
      "z": -2,
      "name": "Rock_Quartzite_Brick_Stairs",
      "rotation": 10
    },
    {
      "x": -5,
      "y": 6,
      "z": -2,
      "name": "Rock_Quartzite_Brick"
    },
    {
      "x": -5,
      "y": 0,
      "z": -1,
      "name": "Rock_Stone_Brick"
    },
    {
      "x": -5,
      "y": 1,
      "z": -1,
      "name": "Soil_Clay_Brick"
    },
    {
      "x": -5,
      "y": 2,
      "z": -1,
      "name": "Soil_Clay_Brick_Wall"
    },
    {
      "x": -5,
      "y": 6,
      "z": -1,
      "name": "Rock_Quartzite_Brick_Half",
      "rotation": 4
    },
    {
      "x": -5,
      "y": 7,
      "z": -1,
      "name": "Rock_Quartzite_Brick"
    },
    {
      "x": -5,
      "y": 0,
      "z": 0,
      "name": "Rock_Stone_Brick_Mossy"
    },
    {
      "x": -5,
      "y": 1,
      "z": 0,
      "name": "Soil_Mud"
    },
    {
      "x": -5,
      "y": 2,
      "z": 0,
      "name": "Ingredient_Poop"
    },
    {
      "x": -5,
      "y": 7,
      "z": 0,
      "name": "Rock_Quartzite_Brick"
    },
    {
      "x": -5,
      "y": 0,
      "z": 1,
      "name": "Rock_Stone_Brick_Mossy"
    },
    {
      "x": -5,
      "y": 1,
      "z": 1,
      "name": "Soil_Clay_Brick"
    },
    {
      "x": -5,
      "y": 2,
      "z": 1,
      "name": "Soil_Clay_Brick_Wall"
    },
    {
      "x": -5,
      "y": 6,
      "z": 1,
      "name": "Rock_Quartzite_Brick_Half",
      "rotation": 6
    },
    {
      "x": -5,
      "y": 7,
      "z": 1,
      "name": "Rock_Quartzite_Brick"
    },
    {
      "x": -5,
      "y": 1,
      "z": 2,
      "name": "Rock_Stone_Brick_Mossy"
    },
    {
      "x": -5,
      "y": 5,
      "z": 2,
      "name": "Rock_Quartzite_Brick_Stairs",
      "rotation": 8
    },
    {
      "x": -5,
      "y": 6,
      "z": 2,
      "name": "Rock_Quartzite_Brick"
    },
    {
      "x": -5,
      "y": 1,
      "z": 3,
      "name": "Rock_Stone_Brick"
    },
    {
      "x": -5,
      "y": 2,
      "z": 3,
      "name": "Rock_Quartzite_Brick"
    },
    {
      "x": -5,
      "y": 3,
      "z": 3,
      "name": "Deco_Bone_Skulls_Feran_Wall",
      "rotation": 2
    },
    {
      "x": -5,
      "y": 4,
      "z": 3,
      "name": "Rock_Quartzite_Brick"
    },
    {
      "x": -4,
      "y": 1,
      "z": -3,
      "name": "Rock_Stone_Brick_Mossy"
    },
    {
      "x": -4,
      "y": 2,
      "z": -3,
      "name": "Rock_Quartzite_Brick"
    },
    {
      "x": -4,
      "y": 3,
      "z": -3,
      "name": "Rock_Quartzite_Brick"
    },
    {
      "x": -4,
      "y": 4,
      "z": -3,
      "name": "Rock_Quartzite_Brick"
    },
    {
      "x": -4,
      "y": 1,
      "z": -2,
      "name": "Rock_Stone_Brick_Mossy"
    },
    {
      "x": -4,
      "y": 2,
      "z": -2,
      "name": "Rubble_Stone",
      "support": 15
    },
    {
      "x": -4,
      "y": 5,
      "z": -2,
      "name": "Rock_Quartzite_Brick_Stairs",
      "rotation": 10
    },
    {
      "x": -4,
      "y": 6,
      "z": -2,
      "name": "Rock_Quartzite_Brick"
    },
    {
      "x": -4,
      "y": 0,
      "z": -1,
      "name": "Rock_Stone_Brick_Mossy"
    },
    {
      "x": -4,
      "y": 1,
      "z": -1,
      "name": "Soil_Clay_Brick"
    },
    {
      "x": -4,
      "y": 2,
      "z": -1,
      "name": "Soil_Clay_Brick_Wall"
    },
    {
      "x": -4,
      "y": 6,
      "z": -1,
      "name": "Rock_Quartzite_Brick_Half",
      "rotation": 4
    },
    {
      "x": -4,
      "y": 7,
      "z": -1,
      "name": "Rock_Quartzite_Brick"
    },
    {
      "x": -4,
      "y": 0,
      "z": 0,
      "name": "Rock_Stone_Brick_Mossy"
    },
    {
      "x": -4,
      "y": 1,
      "z": 0,
      "name": "Soil_Mud"
    },
    {
      "x": -4,
      "y": 2,
      "z": 0,
      "name": "Plant_Crop_Mushroom_Flatcap_Green",
      "components": {
        "Components": {
          "FarmingBlock": {
            "LastTickGameTime": "0001-01-01T12:00:00Z"
          },
          "PlacedByInteraction": {
            "WhoPlacedUuid": {
              "$binary": "HCpUQzdeSaiDYHpoRePv+w==",
              "$type": "04"
            }
          }
        }
      }
    },
    {
      "x": -4,
      "y": 7,
      "z": 0,
      "name": "Rock_Quartzite_Brick"
    },
    {
      "x": -4,
      "y": 0,
      "z": 1,
      "name": "Rock_Stone_Brick_Mossy"
    },
    {
      "x": -4,
      "y": 1,
      "z": 1,
      "name": "Soil_Clay_Brick"
    },
    {
      "x": -4,
      "y": 2,
      "z": 1,
      "name": "Soil_Clay_Brick_Wall"
    },
    {
      "x": -4,
      "y": 6,
      "z": 1,
      "name": "Rock_Quartzite_Brick_Half",
      "rotation": 6
    },
    {
      "x": -4,
      "y": 7,
      "z": 1,
      "name": "Rock_Quartzite_Brick"
    },
    {
      "x": -4,
      "y": 1,
      "z": 2,
      "name": "Rock_Stone_Brick"
    },
    {
      "x": -4,
      "y": 2,
      "z": 2,
      "name": "Rubble_Stone_Mossy_Medium",
      "support": 15
    },
    {
      "x": -4,
      "y": 5,
      "z": 2,
      "name": "Rock_Quartzite_Brick_Stairs",
      "rotation": 8
    },
    {
      "x": -4,
      "y": 6,
      "z": 2,
      "name": "Soil_Quartzite_Gravel"
    },
    {
      "x": -4,
      "y": 1,
      "z": 3,
      "name": "Rock_Stone_Brick_Mossy"
    },
    {
      "x": -4,
      "y": 2,
      "z": 3,
      "name": "Rock_Quartzite_Brick"
    },
    {
      "x": -4,
      "y": 3,
      "z": 3,
      "name": "Rock_Quartzite_Brick"
    },
    {
      "x": -4,
      "y": 4,
      "z": 3,
      "name": "Soil_Quartzite_Gravel"
    },
    {
      "x": -3,
      "y": 1,
      "z": -10,
      "name": "Rock_Stone_Brick_Mossy",
      "rotation": 3
    },
    {
      "x": -3,
      "y": 2,
      "z": -10,
      "name": "Rock_Quartzite_Brick",
      "rotation": 3
    },
    {
      "x": -3,
      "y": 3,
      "z": -10,
      "name": "Soil_Quartzite_Gravel",
      "rotation": 3
    },
    {
      "x": -3,
      "y": 4,
      "z": -10,
      "name": "Rock_Quartzite_Brick",
      "rotation": 3
    },
    {
      "x": -3,
      "y": 1,
      "z": -9,
      "name": "Rock_Stone_Brick_Mossy",
      "rotation": 3
    },
    {
      "x": -3,
      "y": 2,
      "z": -9,
      "name": "Rock_Quartzite_Brick",
      "rotation": 3
    },
    {
      "x": -3,
      "y": 3,
      "z": -9,
      "name": "Soil_Quartzite_Gravel",
      "rotation": 3
    },
    {
      "x": -3,
      "y": 4,
      "z": -9,
      "name": "Rock_Quartzite_Brick",
      "rotation": 3
    },
    {
      "x": -3,
      "y": 1,
      "z": -8,
      "name": "Rock_Stone_Brick_Mossy",
      "rotation": 3
    },
    {
      "x": -3,
      "y": 2,
      "z": -8,
      "name": "Rock_Quartzite_Brick",
      "rotation": 3
    },
    {
      "x": -3,
      "y": 3,
      "z": -8,
      "name": "Soil_Quartzite_Gravel",
      "rotation": 3
    },
    {
      "x": -3,
      "y": 4,
      "z": -8,
      "name": "Rock_Quartzite_Brick",
      "rotation": 3
    },
    {
      "x": -3,
      "y": 1,
      "z": -7,
      "name": "Rock_Stone_Brick_Mossy",
      "rotation": 1
    },
    {
      "x": -3,
      "y": 2,
      "z": -7,
      "name": "Soil_Quartzite_Gravel",
      "rotation": 1
    },
    {
      "x": -3,
      "y": 3,
      "z": -7,
      "name": "Rock_Quartzite_Brick",
      "rotation": 1
    },
    {
      "x": -3,
      "y": 4,
      "z": -7,
      "name": "Rock_Quartzite_Brick",
      "rotation": 1
    },
    {
      "x": -3,
      "y": 1,
      "z": -6,
      "name": "Rock_Stone_Brick_Mossy",
      "rotation": 1
    },
    {
      "x": -3,
      "y": 2,
      "z": -6,
      "name": "Rock_Quartzite_Brick",
      "rotation": 1
    },
    {
      "x": -3,
      "y": 3,
      "z": -6,
      "name": "Rock_Quartzite_Brick",
      "rotation": 1
    },
    {
      "x": -3,
      "y": 4,
      "z": -6,
      "name": "Rock_Quartzite_Brick",
      "rotation": 1
    },
    {
      "x": -3,
      "y": 1,
      "z": -5,
      "name": "Rock_Stone_Brick_Mossy",
      "rotation": 1
    },
    {
      "x": -3,
      "y": 2,
      "z": -5,
      "name": "Soil_Quartzite_Gravel",
      "rotation": 1
    },
    {
      "x": -3,
      "y": 3,
      "z": -5,
      "name": "Soil_Quartzite_Gravel",
      "rotation": 1
    },
    {
      "x": -3,
      "y": 4,
      "z": -5,
      "name": "Rock_Quartzite_Brick",
      "rotation": 1
    },
    {
      "x": -3,
      "y": 1,
      "z": -4,
      "name": "Rock_Stone_Brick_Mossy",
      "rotation": 1
    },
    {
      "x": -3,
      "y": 2,
      "z": -4,
      "name": "Rock_Quartzite_Brick",
      "rotation": 1
    },
    {
      "x": -3,
      "y": 3,
      "z": -4,
      "name": "Rock_Quartzite_Brick",
      "rotation": 1
    },
    {
      "x": -3,
      "y": 4,
      "z": -4,
      "name": "Rock_Quartzite_Brick",
      "rotation": 1
    },
    {
      "x": -3,
      "y": 1,
      "z": -3,
      "name": "Rock_Stone_Brick_Mossy",
      "rotation": 1
    },
    {
      "x": -3,
      "y": 2,
      "z": -3,
      "name": "Rock_Quartzite_Brick",
      "rotation": 1
    },
    {
      "x": -3,
      "y": 3,
      "z": -3,
      "name": "Rock_Quartzite_Brick",
      "rotation": 1
    },
    {
      "x": -3,
      "y": 4,
      "z": -3,
      "name": "Rock_Quartzite_Brick",
      "rotation": 1
    },
    {
      "x": -3,
      "y": 5,
      "z": -3,
      "name": "Rock_Quartzite_Brick"
    },
    {
      "x": -3,
      "y": 1,
      "z": -2,
      "name": "Rock_Stone_Brick_Mossy",
      "rotation": 1
    },
    {
      "x": -3,
      "y": 5,
      "z": -2,
      "name": "Rock_Quartzite_Brick_Stairs",
      "rotation": 10
    },
    {
      "x": -3,
      "y": 6,
      "z": -2,
      "name": "Rock_Quartzite_Brick"
    },
    {
      "x": -3,
      "y": 0,
      "z": -1,
      "name": "Rock_Stone_Brick_Mossy"
    },
    {
      "x": -3,
      "y": 1,
      "z": -1,
      "name": "Soil_Clay_Brick"
    },
    {
      "x": -3,
      "y": 2,
      "z": -1,
      "name": "Soil_Clay_Brick_Wall"
    },
    {
      "x": -3,
      "y": 6,
      "z": -1,
      "name": "Rock_Quartzite_Brick_Half",
      "rotation": 4
    },
    {
      "x": -3,
      "y": 7,
      "z": -1,
      "name": "Rock_Quartzite_Brick"
    },
    {
      "x": -3,
      "y": 0,
      "z": 0,
      "name": "Rock_Stone_Brick"
    },
    {
      "x": -3,
      "y": 1,
      "z": 0,
      "name": "Soil_Mud"
    },
    {
      "x": -3,
      "y": 7,
      "z": 0,
      "name": "Rock_Quartzite_Brick"
    },
    {
      "x": -3,
      "y": 0,
      "z": 1,
      "name": "Rock_Stone_Brick_Mossy"
    },
    {
      "x": -3,
      "y": 1,
      "z": 1,
      "name": "Soil_Clay_Brick"
    },
    {
      "x": -3,
      "y": 2,
      "z": 1,
      "name": "Soil_Clay_Brick_Wall"
    },
    {
      "x": -3,
      "y": 6,
      "z": 1,
      "name": "Rock_Quartzite_Brick_Half",
      "rotation": 6
    },
    {
      "x": -3,
      "y": 7,
      "z": 1,
      "name": "Rock_Quartzite_Brick"
    },
    {
      "x": -3,
      "y": 1,
      "z": 2,
      "name": "Rock_Stone_Brick_Mossy",
      "rotation": 1
    },
    {
      "x": -3,
      "y": 2,
      "z": 2,
      "name": "Plant_Crop_Mushroom_Glowing_Green"
    },
    {
      "x": -3,
      "y": 5,
      "z": 2,
      "name": "Rock_Quartzite_Brick_Stairs",
      "rotation": 8
    },
    {
      "x": -3,
      "y": 6,
      "z": 2,
      "name": "Rock_Quartzite_Brick"
    },
    {
      "x": -3,
      "y": 1,
      "z": 3,
      "name": "Rock_Stone_Brick_Mossy",
      "rotation": 1
    },
    {
      "x": -3,
      "y": 2,
      "z": 3,
      "name": "Rock_Quartzite_Brick",
      "rotation": 1
    },
    {
      "x": -3,
      "y": 3,
      "z": 3,
      "name": "Rock_Quartzite_Brick",
      "rotation": 1
    },
    {
      "x": -3,
      "y": 4,
      "z": 3,
      "name": "Rock_Quartzite_Brick",
      "rotation": 1
    },
    {
      "x": -3,
      "y": 5,
      "z": 3,
      "name": "Rock_Quartzite_Brick"
    },
    {
      "x": -3,
      "y": 1,
      "z": 4,
      "name": "Rock_Stone_Brick_Mossy",
      "rotation": 1
    },
    {
      "x": -3,
      "y": 2,
      "z": 4,
      "name": "Rock_Quartzite_Brick",
      "rotation": 1
    },
    {
      "x": -3,
      "y": 3,
      "z": 4,
      "name": "Deco_Bone_Skulls_Feran_Wall",
      "rotation": 1
    },
    {
      "x": -3,
      "y": 4,
      "z": 4,
      "name": "Rock_Quartzite_Brick",
      "rotation": 1
    },
    {
      "x": -3,
      "y": 1,
      "z": 5,
      "name": "Rock_Stone_Brick",
      "rotation": 1
    },
    {
      "x": -3,
      "y": 2,
      "z": 5,
      "name": "Rock_Quartzite_Brick",
      "rotation": 1
    },
    {
      "x": -3,
      "y": 3,
      "z": 5,
      "name": "Rock_Quartzite_Brick",
      "rotation": 1
    },
    {
      "x": -3,
      "y": 4,
      "z": 5,
      "name": "Soil_Quartzite_Gravel",
      "rotation": 1
    },
    {
      "x": -3,
      "y": 1,
      "z": 6,
      "name": "Rock_Stone_Brick",
      "rotation": 1
    },
    {
      "x": -3,
      "y": 2,
      "z": 6,
      "name": "Rock_Quartzite_Brick",
      "rotation": 1
    },
    {
      "x": -3,
      "y": 3,
      "z": 6,
      "name": "Rock_Quartzite_Brick",
      "rotation": 1
    },
    {
      "x": -3,
      "y": 4,
      "z": 6,
      "name": "Rock_Quartzite_Brick",
      "rotation": 1
    },
    {
      "x": -3,
      "y": 1,
      "z": 7,
      "name": "Rock_Stone_Brick_Mossy",
      "rotation": 1
    },
    {
      "x": -3,
      "y": 2,
      "z": 7,
      "name": "Rock_Quartzite_Brick",
      "rotation": 1
    },
    {
      "x": -3,
      "y": 3,
      "z": 7,
      "name": "Rock_Quartzite_Brick",
      "rotation": 1
    },
    {
      "x": -3,
      "y": 4,
      "z": 7,
      "name": "Rock_Quartzite_Brick",
      "rotation": 1
    },
    {
      "x": -3,
      "y": 1,
      "z": 8,
      "name": "Rock_Stone_Brick_Mossy",
      "rotation": 1
    },
    {
      "x": -3,
      "y": 2,
      "z": 8,
      "name": "Soil_Quartzite_Gravel",
      "rotation": 1
    },
    {
      "x": -3,
      "y": 3,
      "z": 8,
      "name": "Rock_Quartzite_Brick",
      "rotation": 1
    },
    {
      "x": -3,
      "y": 4,
      "z": 8,
      "name": "Rock_Quartzite_Brick",
      "rotation": 1
    },
    {
      "x": -3,
      "y": 1,
      "z": 9,
      "name": "Rock_Stone_Brick_Mossy",
      "rotation": 1
    },
    {
      "x": -3,
      "y": 2,
      "z": 9,
      "name": "Soil_Quartzite_Gravel",
      "rotation": 1
    },
    {
      "x": -3,
      "y": 3,
      "z": 9,
      "name": "Rock_Quartzite_Brick",
      "rotation": 1
    },
    {
      "x": -3,
      "y": 4,
      "z": 9,
      "name": "Rock_Quartzite_Brick",
      "rotation": 1
    },
    {
      "x": -3,
      "y": 1,
      "z": 10,
      "name": "Rock_Stone_Brick_Mossy",
      "rotation": 1
    },
    {
      "x": -3,
      "y": 2,
      "z": 10,
      "name": "Soil_Quartzite_Gravel",
      "rotation": 1
    },
    {
      "x": -3,
      "y": 3,
      "z": 10,
      "name": "Rock_Quartzite_Brick",
      "rotation": 1
    },
    {
      "x": -3,
      "y": 4,
      "z": 10,
      "name": "Rock_Quartzite_Brick",
      "rotation": 1
    },
    {
      "x": -2,
      "y": 1,
      "z": -10,
      "name": "Rock_Stone_Brick",
      "rotation": 3
    },
    {
      "x": -2,
      "y": 2,
      "z": -10,
      "name": "Rubble_Stone_Mossy_Medium",
      "support": 15,
      "rotation": 3
    },
    {
      "x": -2,
      "y": 5,
      "z": -10,
      "name": "Rock_Quartzite_Brick_Stairs",
      "rotation": 33
    },
    {
      "x": -2,
      "y": 6,
      "z": -10,
      "name": "Rock_Quartzite_Brick",
      "rotation": 3
    },
    {
      "x": -2,
      "y": 1,
      "z": -9,
      "name": "Rock_Stone_Brick",
      "rotation": 3
    },
    {
      "x": -2,
      "y": 2,
      "z": -9,
      "name": "Rubble_Stone_Mossy_Medium",
      "support": 15,
      "rotation": 3
    },
    {
      "x": -2,
      "y": 5,
      "z": -9,
      "name": "Rock_Quartzite_Brick_Stairs",
      "rotation": 33
    },
    {
      "x": -2,
      "y": 6,
      "z": -9,
      "name": "Rock_Quartzite_Brick",
      "rotation": 3
    },
    {
      "x": -2,
      "y": 1,
      "z": -8,
      "name": "Rock_Stone_Brick",
      "rotation": 3
    },
    {
      "x": -2,
      "y": 2,
      "z": -8,
      "name": "Rubble_Stone_Mossy_Medium",
      "support": 15,
      "rotation": 3
    },
    {
      "x": -2,
      "y": 5,
      "z": -8,
      "name": "Rock_Quartzite_Brick_Stairs",
      "rotation": 33
    },
    {
      "x": -2,
      "y": 6,
      "z": -8,
      "name": "Rock_Quartzite_Brick",
      "rotation": 3
    },
    {
      "x": -2,
      "y": 1,
      "z": -7,
      "name": "Rock_Stone_Brick_Mossy",
      "rotation": 1
    },
    {
      "x": -2,
      "y": 5,
      "z": -7,
      "name": "Rock_Quartzite_Brick_Stairs",
      "rotation": 11
    },
    {
      "x": -2,
      "y": 6,
      "z": -7,
      "name": "Rock_Quartzite_Brick",
      "rotation": 1
    },
    {
      "x": -2,
      "y": 1,
      "z": -6,
      "name": "Rock_Stone_Brick_Mossy",
      "rotation": 1
    },
    {
      "x": -2,
      "y": 2,
      "z": -6,
      "name": "Rubble_Stone_Mossy",
      "support": 15
    },
    {
      "x": -2,
      "y": 5,
      "z": -6,
      "name": "Rock_Quartzite_Brick_Stairs",
      "rotation": 11
    },
    {
      "x": -2,
      "y": 6,
      "z": -6,
      "name": "Rock_Quartzite_Brick",
      "rotation": 1
    },
    {
      "x": -2,
      "y": 1,
      "z": -5,
      "name": "Rock_Stone_Brick",
      "rotation": 1
    },
    {
      "x": -2,
      "y": 5,
      "z": -5,
      "name": "Rock_Quartzite_Brick_Stairs",
      "rotation": 11
    },
    {
      "x": -2,
      "y": 6,
      "z": -5,
      "name": "Rock_Quartzite_Brick",
      "rotation": 1
    },
    {
      "x": -2,
      "y": 1,
      "z": -4,
      "name": "Rock_Stone_Brick",
      "rotation": 1
    },
    {
      "x": -2,
      "y": 5,
      "z": -4,
      "name": "Rock_Quartzite_Brick_Stairs",
      "rotation": 11
    },
    {
      "x": -2,
      "y": 6,
      "z": -4,
      "name": "Soil_Quartzite_Gravel",
      "rotation": 1
    },
    {
      "x": -2,
      "y": 1,
      "z": -3,
      "name": "Rock_Stone_Brick_Mossy",
      "rotation": 1
    },
    {
      "x": -2,
      "y": 5,
      "z": -3,
      "name": "Rock_Quartzite_Brick_Stairs",
      "rotation": 11
    },
    {
      "x": -2,
      "y": 6,
      "z": -3,
      "name": "Rock_Quartzite_Brick",
      "rotation": 1
    },
    {
      "x": -2,
      "y": 1,
      "z": -2,
      "name": "Rock_Stone_Brick_Mossy",
      "rotation": 1
    },
    {
      "x": -2,
      "y": 5,
      "z": -2,
      "name": "*Rock_Quartzite_Brick_Stairs_State_Definitions_Corner_Left",
      "rotation": 11
    },
    {
      "x": -2,
      "y": 6,
      "z": -2,
      "name": "Rock_Quartzite_Brick",
      "rotation": 1
    },
    {
      "x": -2,
      "y": 7,
      "z": -2,
      "name": "Rock_Quartzite_Brick"
    },
    {
      "x": -2,
      "y": 0,
      "z": -1,
      "name": "Rock_Stone_Brick"
    },
    {
      "x": -2,
      "y": 1,
      "z": -1,
      "name": "Soil_Clay_Brick"
    },
    {
      "x": -2,
      "y": 2,
      "z": -1,
      "name": "Soil_Clay_Brick_Wall"
    },
    {
      "x": -2,
      "y": 6,
      "z": -1,
      "name": "Rock_Quartzite_Stalactite_Small",
      "rotation": 8
    },
    {
      "x": -2,
      "y": 7,
      "z": -1,
      "name": "Rock_Quartzite_Brick"
    },
    {
      "x": -2,
      "y": 0,
      "z": 0,
      "name": "Rock_Stone_Brick_Mossy"
    },
    {
      "x": -2,
      "y": 1,
      "z": 0,
      "name": "Soil_Mud"
    },
    {
      "x": -2,
      "y": 7,
      "z": 0,
      "name": "Rock_Quartzite_Brick"
    },
    {
      "x": -2,
      "y": 0,
      "z": 1,
      "name": "Rock_Stone_Brick_Mossy"
    },
    {
      "x": -2,
      "y": 1,
      "z": 1,
      "name": "Soil_Clay_Brick"
    },
    {
      "x": -2,
      "y": 2,
      "z": 1,
      "name": "Soil_Clay_Brick_Wall"
    },
    {
      "x": -2,
      "y": 7,
      "z": 1,
      "name": "Rock_Quartzite_Brick"
    },
    {
      "x": -2,
      "y": 1,
      "z": 2,
      "name": "Rock_Stone_Brick_Mossy",
      "rotation": 1
    },
    {
      "x": -2,
      "y": 5,
      "z": 2,
      "name": "*Rock_Quartzite_Brick_Stairs_State_Definitions_Corner_Left",
      "rotation": 8
    },
    {
      "x": -2,
      "y": 6,
      "z": 2,
      "name": "Rock_Quartzite_Brick",
      "rotation": 1
    },
    {
      "x": -2,
      "y": 7,
      "z": 2,
      "name": "Rock_Quartzite_Brick"
    },
    {
      "x": -2,
      "y": 1,
      "z": 3,
      "name": "Rock_Stone_Brick_Mossy",
      "rotation": 1
    },
    {
      "x": -2,
      "y": 5,
      "z": 3,
      "name": "Rock_Quartzite_Brick_Stairs",
      "rotation": 11
    },
    {
      "x": -2,
      "y": 6,
      "z": 3,
      "name": "Rock_Quartzite_Brick",
      "rotation": 1
    },
    {
      "x": -2,
      "y": 1,
      "z": 4,
      "name": "Rock_Stone_Brick_Mossy",
      "rotation": 1
    },
    {
      "x": -2,
      "y": 5,
      "z": 4,
      "name": "Rock_Quartzite_Brick_Stairs",
      "rotation": 11
    },
    {
      "x": -2,
      "y": 6,
      "z": 4,
      "name": "Rock_Quartzite_Brick",
      "rotation": 1
    },
    {
      "x": -2,
      "y": 1,
      "z": 5,
      "name": "Rock_Stone_Brick_Mossy",
      "rotation": 1
    },
    {
      "x": -2,
      "y": 5,
      "z": 5,
      "name": "Rock_Quartzite_Brick_Stairs",
      "rotation": 11
    },
    {
      "x": -2,
      "y": 6,
      "z": 5,
      "name": "Rock_Quartzite_Brick",
      "rotation": 1
    },
    {
      "x": -2,
      "y": 1,
      "z": 6,
      "name": "Rock_Stone_Brick_Mossy",
      "rotation": 1
    },
    {
      "x": -2,
      "y": 5,
      "z": 6,
      "name": "Rock_Quartzite_Brick_Stairs",
      "rotation": 11
    },
    {
      "x": -2,
      "y": 6,
      "z": 6,
      "name": "Soil_Quartzite_Gravel",
      "rotation": 1
    },
    {
      "x": -2,
      "y": 1,
      "z": 7,
      "name": "Rock_Stone_Brick_Mossy",
      "rotation": 1
    },
    {
      "x": -2,
      "y": 5,
      "z": 7,
      "name": "Rock_Quartzite_Brick_Stairs",
      "rotation": 11
    },
    {
      "x": -2,
      "y": 6,
      "z": 7,
      "name": "Rock_Quartzite_Brick",
      "rotation": 1
    },
    {
      "x": -2,
      "y": 1,
      "z": 8,
      "name": "Rock_Stone_Brick_Mossy",
      "rotation": 1
    },
    {
      "x": -2,
      "y": 2,
      "z": 8,
      "name": "Rubble_Stone_Mossy",
      "support": 15,
      "rotation": 1
    },
    {
      "x": -2,
      "y": 5,
      "z": 8,
      "name": "Rock_Quartzite_Brick_Stairs",
      "rotation": 33
    },
    {
      "x": -2,
      "y": 6,
      "z": 8,
      "name": "Rock_Quartzite_Brick",
      "rotation": 1
    },
    {
      "x": -2,
      "y": 1,
      "z": 9,
      "name": "Rock_Stone_Brick_Mossy",
      "rotation": 1
    },
    {
      "x": -2,
      "y": 2,
      "z": 9,
      "name": "Rubble_Stone_Mossy",
      "support": 15,
      "rotation": 1
    },
    {
      "x": -2,
      "y": 5,
      "z": 9,
      "name": "Rock_Quartzite_Brick_Stairs",
      "rotation": 33
    },
    {
      "x": -2,
      "y": 6,
      "z": 9,
      "name": "Rock_Quartzite_Brick",
      "rotation": 1
    },
    {
      "x": -2,
      "y": 1,
      "z": 10,
      "name": "Rock_Stone_Brick_Mossy",
      "rotation": 1
    },
    {
      "x": -2,
      "y": 2,
      "z": 10,
      "name": "Rubble_Stone_Mossy",
      "support": 15,
      "rotation": 1
    },
    {
      "x": -2,
      "y": 5,
      "z": 10,
      "name": "Rock_Quartzite_Brick_Stairs",
      "rotation": 33
    },
    {
      "x": -2,
      "y": 6,
      "z": 10,
      "name": "Rock_Quartzite_Brick",
      "rotation": 1
    },
    {
      "x": -1,
      "y": 0,
      "z": -10,
      "name": "Rock_Stone_Brick",
      "rotation": 3
    },
    {
      "x": -1,
      "y": 1,
      "z": -10,
      "name": "Soil_Clay_Brick",
      "rotation": 3
    },
    {
      "x": -1,
      "y": 2,
      "z": -10,
      "name": "Soil_Clay_Brick_Wall",
      "rotation": 3
    },
    {
      "x": -1,
      "y": 6,
      "z": -10,
      "name": "Rock_Quartzite_Brick_Half",
      "rotation": 5
    },
    {
      "x": -1,
      "y": 7,
      "z": -10,
      "name": "Rock_Quartzite_Brick",
      "rotation": 3
    },
    {
      "x": -1,
      "y": 0,
      "z": -9,
      "name": "Rock_Stone_Brick",
      "rotation": 3
    },
    {
      "x": -1,
      "y": 1,
      "z": -9,
      "name": "Soil_Clay_Brick",
      "rotation": 3
    },
    {
      "x": -1,
      "y": 2,
      "z": -9,
      "name": "Soil_Clay_Brick_Wall",
      "rotation": 3
    },
    {
      "x": -1,
      "y": 6,
      "z": -9,
      "name": "Rock_Quartzite_Brick_Half",
      "rotation": 5
    },
    {
      "x": -1,
      "y": 7,
      "z": -9,
      "name": "Rock_Quartzite_Brick",
      "rotation": 3
    },
    {
      "x": -1,
      "y": 0,
      "z": -8,
      "name": "Rock_Stone_Brick",
      "rotation": 3
    },
    {
      "x": -1,
      "y": 1,
      "z": -8,
      "name": "Soil_Clay_Brick",
      "rotation": 3
    },
    {
      "x": -1,
      "y": 2,
      "z": -8,
      "name": "Soil_Clay_Brick_Wall",
      "rotation": 3
    },
    {
      "x": -1,
      "y": 6,
      "z": -8,
      "name": "Rock_Quartzite_Brick_Half",
      "rotation": 5
    },
    {
      "x": -1,
      "y": 7,
      "z": -8,
      "name": "Rock_Quartzite_Brick",
      "rotation": 3
    },
    {
      "x": -1,
      "y": 0,
      "z": -7,
      "name": "Rock_Stone_Brick_Mossy",
      "rotation": 1
    },
    {
      "x": -1,
      "y": 1,
      "z": -7,
      "name": "Soil_Clay_Brick"
    },
    {
      "x": -1,
      "y": 2,
      "z": -7,
      "name": "Soil_Clay_Brick_Wall",
      "rotation": 1
    },
    {
      "x": -1,
      "y": 6,
      "z": -7,
      "name": "Rock_Quartzite_Brick_Half",
      "rotation": 5
    },
    {
      "x": -1,
      "y": 7,
      "z": -7,
      "name": "Rock_Quartzite_Brick",
      "rotation": 1
    },
    {
      "x": -1,
      "y": 0,
      "z": -6,
      "name": "Rock_Stone_Brick_Mossy",
      "rotation": 1
    },
    {
      "x": -1,
      "y": 1,
      "z": -6,
      "name": "Soil_Clay_Brick"
    },
    {
      "x": -1,
      "y": 2,
      "z": -6,
      "name": "Soil_Clay_Brick_Wall",
      "rotation": 1
    },
    {
      "x": -1,
      "y": 6,
      "z": -6,
      "name": "Rock_Quartzite_Brick_Half",
      "rotation": 5
    },
    {
      "x": -1,
      "y": 7,
      "z": -6,
      "name": "Rock_Quartzite_Brick",
      "rotation": 1
    },
    {
      "x": -1,
      "y": 0,
      "z": -5,
      "name": "Rock_Stone_Brick_Mossy",
      "rotation": 1
    },
    {
      "x": -1,
      "y": 1,
      "z": -5,
      "name": "Soil_Clay_Brick"
    },
    {
      "x": -1,
      "y": 2,
      "z": -5,
      "name": "Soil_Clay_Brick_Wall",
      "rotation": 1
    },
    {
      "x": -1,
      "y": 6,
      "z": -5,
      "name": "Rock_Quartzite_Brick_Half",
      "rotation": 5
    },
    {
      "x": -1,
      "y": 7,
      "z": -5,
      "name": "Rock_Quartzite_Brick",
      "rotation": 1
    },
    {
      "x": -1,
      "y": 0,
      "z": -4,
      "name": "Rock_Stone_Brick_Mossy",
      "rotation": 1
    },
    {
      "x": -1,
      "y": 1,
      "z": -4,
      "name": "Soil_Clay_Brick"
    },
    {
      "x": -1,
      "y": 2,
      "z": -4,
      "name": "Soil_Clay_Brick_Wall",
      "rotation": 1
    },
    {
      "x": -1,
      "y": 6,
      "z": -4,
      "name": "Rock_Quartzite_Brick_Half",
      "rotation": 5
    },
    {
      "x": -1,
      "y": 7,
      "z": -4,
      "name": "Rock_Quartzite_Brick",
      "rotation": 1
    },
    {
      "x": -1,
      "y": 0,
      "z": -3,
      "name": "Rock_Stone_Brick_Mossy",
      "rotation": 1
    },
    {
      "x": -1,
      "y": 1,
      "z": -3,
      "name": "Soil_Clay_Brick"
    },
    {
      "x": -1,
      "y": 2,
      "z": -3,
      "name": "Soil_Clay_Brick_Wall",
      "rotation": 1
    },
    {
      "x": -1,
      "y": 6,
      "z": -3,
      "name": "Rock_Quartzite_Brick_Half",
      "rotation": 5
    },
    {
      "x": -1,
      "y": 7,
      "z": -3,
      "name": "Rock_Quartzite_Brick",
      "rotation": 1
    },
    {
      "x": -1,
      "y": 0,
      "z": -2,
      "name": "Rock_Stone_Brick_Mossy",
      "rotation": 1
    },
    {
      "x": -1,
      "y": 1,
      "z": -2,
      "name": "Soil_Clay_Brick"
    },
    {
      "x": -1,
      "y": 2,
      "z": -2,
      "name": "Soil_Clay_Brick_Wall",
      "rotation": 1
    },
    {
      "x": -1,
      "y": 7,
      "z": -2,
      "name": "Rock_Quartzite_Brick",
      "rotation": 1
    },
    {
      "x": -1,
      "y": 0,
      "z": -1,
      "name": "Rock_Stone_Brick",
      "rotation": 1
    },
    {
      "x": -1,
      "y": 1,
      "z": -1,
      "name": "Soil_Clay_Brick"
    },
    {
      "x": -1,
      "y": 2,
      "z": -1,
      "name": "*Soil_Clay_Brick_Wall_State_Definitions_Corner",
      "rotation": 3
    },
    {
      "x": -1,
      "y": 8,
      "z": -1,
      "name": "Soil_Clay_Brick"
    },
    {
      "x": -1,
      "y": 9,
      "z": -1,
      "name": "Soil_Clay_Brick"
    },
    {
      "x": -1,
      "y": 10,
      "z": -1,
      "name": "Soil_Clay_Brick_Stairs",
      "rotation": 17
    },
    {
      "x": -1,
      "y": 11,
      "z": -1,
      "name": "Soil_Clay_Brick_Stairs",
      "rotation": 17
    },
    {
      "x": -1,
      "y": 12,
      "z": -1,
      "name": "Soil_Clay_Brick_Stairs",
      "rotation": 17
    },
    {
      "x": -1,
      "y": 13,
      "z": -1,
      "name": "Soil_Clay_Brick_Stairs",
      "rotation": 17
    },
    {
      "x": -1,
      "y": 14,
      "z": -1,
      "name": "Soil_Clay_Brick_Stairs",
      "rotation": 17
    },
    {
      "x": -1,
      "y": 15,
      "z": -1,
      "name": "Soil_Clay_Brick_Stairs",
      "rotation": 17
    },
    {
      "x": -1,
      "y": 16,
      "z": -1,
      "name": "Soil_Clay_Brick_Stairs",
      "rotation": 17
    },
    {
      "x": -1,
      "y": 17,
      "z": -1,
      "name": "Soil_Clay_Brick_Stairs",
      "rotation": 17
    },
    {
      "x": -1,
      "y": 18,
      "z": -1,
      "name": "Soil_Clay_Brick"
    },
    {
      "x": -1,
      "y": 19,
      "z": -1,
      "name": "Soil_Clay_Brick"
    },
    {
      "x": -1,
      "y": 20,
      "z": -1,
      "name": "Soil_Clay_Brick_Stairs",
      "rotation": 17
    },
    {
      "x": -1,
      "y": 21,
      "z": -1,
      "name": "Soil_Clay_Brick_Stairs",
      "rotation": 17
    },
    {
      "x": -1,
      "y": 22,
      "z": -1,
      "name": "Soil_Clay_Brick_Stairs",
      "rotation": 17
    },
    {
      "x": -1,
      "y": 23,
      "z": -1,
      "name": "Soil_Clay_Brick_Stairs",
      "rotation": 17
    },
    {
      "x": -1,
      "y": 24,
      "z": -1,
      "name": "Soil_Clay_Brick_Stairs",
      "rotation": 17
    },
    {
      "x": -1,
      "y": 25,
      "z": -1,
      "name": "Soil_Clay_Brick_Stairs",
      "rotation": 17
    },
    {
      "x": -1,
      "y": 26,
      "z": -1,
      "name": "Soil_Clay_Brick_Stairs",
      "rotation": 17
    },
    {
      "x": -1,
      "y": 27,
      "z": -1,
      "name": "Soil_Clay_Brick_Stairs",
      "rotation": 17
    },
    {
      "x": -1,
      "y": 28,
      "z": -1,
      "name": "Soil_Clay_Brick"
    },
    {
      "x": -1,
      "y": 0,
      "z": 0,
      "name": "Rock_Stone_Brick_Mossy",
      "rotation": 1
    },
    {
      "x": -1,
      "y": 1,
      "z": 0,
      "name": "Soil_Mud"
    },
    {
      "x": -1,
      "y": 8,
      "z": 0,
      "name": "Soil_Clay_Brick_Stairs",
      "rotation": 1
    },
    {
      "x": -1,
      "y": 9,
      "z": 0,
      "name": "Soil_Clay_Brick_Half",
      "rotation": 5
    },
    {
      "x": -1,
      "y": 10,
      "z": 0,
      "name": "Soil_Clay_Brick_Half",
      "rotation": 5
    },
    {
      "x": -1,
      "y": 11,
      "z": 0,
      "name": "Soil_Clay_Brick_Half",
      "rotation": 5
    },
    {
      "x": -1,
      "y": 12,
      "z": 0,
      "name": "Soil_Clay_Brick_Half",
      "rotation": 5
    },
    {
      "x": -1,
      "y": 13,
      "z": 0,
      "name": "Soil_Clay_Brick_Half",
      "rotation": 5
    },
    {
      "x": -1,
      "y": 14,
      "z": 0,
      "name": "Soil_Clay_Brick_Half",
      "rotation": 5
    },
    {
      "x": -1,
      "y": 15,
      "z": 0,
      "name": "Soil_Clay_Brick_Half",
      "rotation": 5
    },
    {
      "x": -1,
      "y": 16,
      "z": 0,
      "name": "Soil_Clay_Brick_Half",
      "rotation": 5
    },
    {
      "x": -1,
      "y": 17,
      "z": 0,
      "name": "Soil_Clay_Brick_Half",
      "rotation": 5
    },
    {
      "x": -1,
      "y": 18,
      "z": 0,
      "name": "Soil_Clay_Brick_Stairs",
      "rotation": 1
    },
    {
      "x": -1,
      "y": 19,
      "z": 0,
      "name": "Soil_Clay_Brick_Half",
      "rotation": 5
    },
    {
      "x": -1,
      "y": 20,
      "z": 0,
      "name": "Soil_Clay_Brick_Half",
      "rotation": 5
    },
    {
      "x": -1,
      "y": 21,
      "z": 0,
      "name": "Soil_Clay_Brick_Half",
      "rotation": 5
    },
    {
      "x": -1,
      "y": 22,
      "z": 0,
      "name": "Soil_Clay_Brick_Half",
      "rotation": 5
    },
    {
      "x": -1,
      "y": 23,
      "z": 0,
      "name": "Soil_Clay_Brick_Half",
      "rotation": 5
    },
    {
      "x": -1,
      "y": 24,
      "z": 0,
      "name": "Soil_Clay_Brick_Half",
      "rotation": 5
    },
    {
      "x": -1,
      "y": 25,
      "z": 0,
      "name": "Soil_Clay_Brick_Half",
      "rotation": 5
    },
    {
      "x": -1,
      "y": 26,
      "z": 0,
      "name": "Soil_Clay_Brick_Half",
      "rotation": 5
    },
    {
      "x": -1,
      "y": 27,
      "z": 0,
      "name": "Soil_Clay_Brick_Half",
      "rotation": 5
    },
    {
      "x": -1,
      "y": 28,
      "z": 0,
      "name": "Soil_Clay_Brick_Stairs",
      "rotation": 1
    },
    {
      "x": -1,
      "y": 0,
      "z": 1,
      "name": "Rock_Stone_Brick_Mossy",
      "rotation": 1
    },
    {
      "x": -1,
      "y": 1,
      "z": 1,
      "name": "Soil_Clay_Brick"
    },
    {
      "x": -1,
      "y": 2,
      "z": 1,
      "name": "*Soil_Clay_Brick_Wall_State_Definitions_Corner"
    },
    {
      "x": -1,
      "y": 8,
      "z": 1,
      "name": "Soil_Clay_Brick"
    },
    {
      "x": -1,
      "y": 9,
      "z": 1,
      "name": "Soil_Clay_Brick"
    },
    {
      "x": -1,
      "y": 10,
      "z": 1,
      "name": "Soil_Clay_Brick_Stairs",
      "rotation": 18
    },
    {
      "x": -1,
      "y": 11,
      "z": 1,
      "name": "Soil_Clay_Brick_Stairs",
      "rotation": 18
    },
    {
      "x": -1,
      "y": 12,
      "z": 1,
      "name": "Soil_Clay_Brick_Stairs",
      "rotation": 18
    },
    {
      "x": -1,
      "y": 13,
      "z": 1,
      "name": "Soil_Clay_Brick_Stairs",
      "rotation": 18
    },
    {
      "x": -1,
      "y": 14,
      "z": 1,
      "name": "Soil_Clay_Brick_Stairs",
      "rotation": 18
    },
    {
      "x": -1,
      "y": 15,
      "z": 1,
      "name": "Soil_Clay_Brick_Stairs",
      "rotation": 18
    },
    {
      "x": -1,
      "y": 16,
      "z": 1,
      "name": "Soil_Clay_Brick_Stairs",
      "rotation": 18
    },
    {
      "x": -1,
      "y": 17,
      "z": 1,
      "name": "Soil_Clay_Brick_Stairs",
      "rotation": 18
    },
    {
      "x": -1,
      "y": 18,
      "z": 1,
      "name": "Soil_Clay_Brick"
    },
    {
      "x": -1,
      "y": 19,
      "z": 1,
      "name": "Soil_Clay_Brick"
    },
    {
      "x": -1,
      "y": 20,
      "z": 1,
      "name": "Soil_Clay_Brick_Stairs",
      "rotation": 18
    },
    {
      "x": -1,
      "y": 21,
      "z": 1,
      "name": "Soil_Clay_Brick_Stairs",
      "rotation": 18
    },
    {
      "x": -1,
      "y": 22,
      "z": 1,
      "name": "Soil_Clay_Brick_Stairs",
      "rotation": 18
    },
    {
      "x": -1,
      "y": 23,
      "z": 1,
      "name": "Soil_Clay_Brick_Stairs",
      "rotation": 18
    },
    {
      "x": -1,
      "y": 24,
      "z": 1,
      "name": "Soil_Clay_Brick_Stairs",
      "rotation": 18
    },
    {
      "x": -1,
      "y": 25,
      "z": 1,
      "name": "Soil_Clay_Brick_Stairs",
      "rotation": 18
    },
    {
      "x": -1,
      "y": 26,
      "z": 1,
      "name": "Soil_Clay_Brick_Stairs",
      "rotation": 18
    },
    {
      "x": -1,
      "y": 27,
      "z": 1,
      "name": "Soil_Clay_Brick_Stairs",
      "rotation": 18
    },
    {
      "x": -1,
      "y": 28,
      "z": 1,
      "name": "Soil_Clay_Brick"
    },
    {
      "x": -1,
      "y": 0,
      "z": 2,
      "name": "Rock_Stone_Brick",
      "rotation": 1
    },
    {
      "x": -1,
      "y": 1,
      "z": 2,
      "name": "Soil_Clay_Brick"
    },
    {
      "x": -1,
      "y": 2,
      "z": 2,
      "name": "Soil_Clay_Brick_Wall",
      "rotation": 1
    },
    {
      "x": -1,
      "y": 7,
      "z": 2,
      "name": "Rock_Quartzite_Brick"
    },
    {
      "x": -1,
      "y": 0,
      "z": 3,
      "name": "Rock_Stone_Brick_Mossy",
      "rotation": 1
    },
    {
      "x": -1,
      "y": 1,
      "z": 3,
      "name": "Soil_Clay_Brick"
    },
    {
      "x": -1,
      "y": 2,
      "z": 3,
      "name": "Soil_Clay_Brick_Wall",
      "rotation": 1
    },
    {
      "x": -1,
      "y": 6,
      "z": 3,
      "name": "Rock_Quartzite_Brick_Half",
      "rotation": 5
    },
    {
      "x": -1,
      "y": 7,
      "z": 3,
      "name": "Rock_Quartzite_Brick",
      "rotation": 1
    },
    {
      "x": -1,
      "y": 0,
      "z": 4,
      "name": "Rock_Stone_Brick_Mossy",
      "rotation": 1
    },
    {
      "x": -1,
      "y": 1,
      "z": 4,
      "name": "Soil_Clay_Brick"
    },
    {
      "x": -1,
      "y": 2,
      "z": 4,
      "name": "Soil_Clay_Brick_Wall",
      "rotation": 1
    },
    {
      "x": -1,
      "y": 6,
      "z": 4,
      "name": "Rock_Quartzite_Brick_Half",
      "rotation": 5
    },
    {
      "x": -1,
      "y": 7,
      "z": 4,
      "name": "Rock_Quartzite_Brick"
    },
    {
      "x": -1,
      "y": 0,
      "z": 5,
      "name": "Rock_Stone_Brick",
      "rotation": 1
    },
    {
      "x": -1,
      "y": 1,
      "z": 5,
      "name": "Soil_Clay_Brick"
    },
    {
      "x": -1,
      "y": 2,
      "z": 5,
      "name": "Soil_Clay_Brick_Wall",
      "rotation": 1
    },
    {
      "x": -1,
      "y": 6,
      "z": 5,
      "name": "Rock_Quartzite_Brick_Half",
      "rotation": 5
    },
    {
      "x": -1,
      "y": 7,
      "z": 5,
      "name": "Rock_Quartzite_Brick",
      "rotation": 1
    },
    {
      "x": -1,
      "y": 0,
      "z": 6,
      "name": "Rock_Stone_Brick_Mossy",
      "rotation": 1
    },
    {
      "x": -1,
      "y": 1,
      "z": 6,
      "name": "Soil_Clay_Brick"
    },
    {
      "x": -1,
      "y": 2,
      "z": 6,
      "name": "Soil_Clay_Brick_Wall",
      "rotation": 1
    },
    {
      "x": -1,
      "y": 6,
      "z": 6,
      "name": "Rock_Quartzite_Brick_Half",
      "rotation": 5
    },
    {
      "x": -1,
      "y": 7,
      "z": 6,
      "name": "Rock_Quartzite_Brick"
    },
    {
      "x": -1,
      "y": 0,
      "z": 7,
      "name": "Rock_Stone_Brick_Mossy",
      "rotation": 1
    },
    {
      "x": -1,
      "y": 1,
      "z": 7,
      "name": "Soil_Clay_Brick"
    },
    {
      "x": -1,
      "y": 2,
      "z": 7,
      "name": "Soil_Clay_Brick_Wall",
      "rotation": 1
    },
    {
      "x": -1,
      "y": 6,
      "z": 7,
      "name": "Rock_Quartzite_Brick_Half",
      "rotation": 5
    },
    {
      "x": -1,
      "y": 7,
      "z": 7,
      "name": "Rock_Quartzite_Brick",
      "rotation": 1
    },
    {
      "x": -1,
      "y": 0,
      "z": 8,
      "name": "Rock_Stone_Brick_Mossy",
      "rotation": 1
    },
    {
      "x": -1,
      "y": 1,
      "z": 8,
      "name": "Soil_Clay_Brick",
      "rotation": 1
    },
    {
      "x": -1,
      "y": 2,
      "z": 8,
      "name": "Soil_Clay_Brick_Wall",
      "rotation": 1
    },
    {
      "x": -1,
      "y": 6,
      "z": 8,
      "name": "Rock_Quartzite_Brick_Half",
      "rotation": 5
    },
    {
      "x": -1,
      "y": 7,
      "z": 8,
      "name": "Rock_Quartzite_Brick",
      "rotation": 1
    },
    {
      "x": -1,
      "y": 0,
      "z": 9,
      "name": "Rock_Stone_Brick_Mossy",
      "rotation": 1
    },
    {
      "x": -1,
      "y": 1,
      "z": 9,
      "name": "Soil_Clay_Brick",
      "rotation": 1
    },
    {
      "x": -1,
      "y": 2,
      "z": 9,
      "name": "Soil_Clay_Brick_Wall",
      "rotation": 1
    },
    {
      "x": -1,
      "y": 6,
      "z": 9,
      "name": "Rock_Quartzite_Brick_Half",
      "rotation": 5
    },
    {
      "x": -1,
      "y": 7,
      "z": 9,
      "name": "Rock_Quartzite_Brick",
      "rotation": 1
    },
    {
      "x": -1,
      "y": 0,
      "z": 10,
      "name": "Rock_Stone_Brick_Mossy",
      "rotation": 1
    },
    {
      "x": -1,
      "y": 1,
      "z": 10,
      "name": "Soil_Clay_Brick",
      "rotation": 1
    },
    {
      "x": -1,
      "y": 2,
      "z": 10,
      "name": "Soil_Clay_Brick_Wall",
      "rotation": 1
    },
    {
      "x": -1,
      "y": 6,
      "z": 10,
      "name": "Rock_Quartzite_Brick_Half",
      "rotation": 5
    },
    {
      "x": -1,
      "y": 7,
      "z": 10,
      "name": "Rock_Quartzite_Brick",
      "rotation": 1
    },
    {
      "x": 0,
      "y": 0,
      "z": -10,
      "name": "Rock_Stone_Brick_Mossy",
      "rotation": 3
    },
    {
      "x": 0,
      "y": 1,
      "z": -10,
      "name": "Soil_Mud",
      "rotation": 3
    },
    {
      "x": 0,
      "y": 7,
      "z": -10,
      "name": "Build_Lightsource_YellowLight",
      "rotation": 7
    },
    {
      "x": 0,
      "y": 8,
      "z": -10,
      "name": "Rock_Quartzite_Brick",
      "rotation": 3
    },
    {
      "x": 0,
      "y": 0,
      "z": -9,
      "name": "Rock_Stone_Brick_Mossy",
      "rotation": 3
    },
    {
      "x": 0,
      "y": 1,
      "z": -9,
      "name": "Soil_Mud",
      "rotation": 3
    },
    {
      "x": 0,
      "y": 7,
      "z": -9,
      "name": "Build_Lightsource_YellowLight",
      "rotation": 7
    },
    {
      "x": 0,
      "y": 8,
      "z": -9,
      "name": "Rock_Quartzite_Brick",
      "rotation": 3
    },
    {
      "x": 0,
      "y": 0,
      "z": -8,
      "name": "Rock_Stone_Brick_Mossy",
      "rotation": 3
    },
    {
      "x": 0,
      "y": 1,
      "z": -8,
      "name": "Soil_Mud",
      "rotation": 3
    },
    {
      "x": 0,
      "y": 7,
      "z": -8,
      "name": "Build_Lightsource_YellowLight",
      "rotation": 7
    },
    {
      "x": 0,
      "y": 8,
      "z": -8,
      "name": "Rock_Quartzite_Brick",
      "rotation": 3
    },
    {
      "x": 0,
      "y": 0,
      "z": -7,
      "name": "Rock_Stone_Brick_Mossy",
      "rotation": 1
    },
    {
      "x": 0,
      "y": 1,
      "z": -7,
      "name": "Soil_Mud",
      "rotation": 1
    },
    {
      "x": 0,
      "y": 7,
      "z": -7,
      "name": "Build_Lightsource_YellowLight",
      "rotation": 5
    },
    {
      "x": 0,
      "y": 8,
      "z": -7,
      "name": "Rock_Quartzite_Brick"
    },
    {
      "x": 0,
      "y": 0,
      "z": -6,
      "name": "Rock_Stone_Brick",
      "rotation": 1
    },
    {
      "x": 0,
      "y": 1,
      "z": -6,
      "name": "Soil_Mud",
      "rotation": 1
    },
    {
      "x": 0,
      "y": 5,
      "z": -6,
      "name": "Rock_Quartzite_Stalactite_Large",
      "filler": 31744,
      "rotation": 8
    },
    {
      "x": 0,
      "y": 6,
      "z": -6,
      "name": "Rock_Quartzite_Stalactite_Large",
      "rotation": 8
    },
    {
      "x": 0,
      "y": 7,
      "z": -6,
      "name": "Rock_Quartzite_Brick",
      "rotation": 1
    },
    {
      "x": 0,
      "y": 0,
      "z": -5,
      "name": "Rock_Stone_Brick",
      "rotation": 1
    },
    {
      "x": 0,
      "y": 1,
      "z": -5,
      "name": "Soil_Mud",
      "rotation": 1
    },
    {
      "x": 0,
      "y": 7,
      "z": -5,
      "name": "Rock_Quartzite_Brick"
    },
    {
      "x": 0,
      "y": 0,
      "z": -4,
      "name": "Rock_Stone_Brick",
      "rotation": 1
    },
    {
      "x": 0,
      "y": 1,
      "z": -4,
      "name": "Soil_Mud",
      "rotation": 1
    },
    {
      "x": 0,
      "y": 2,
      "z": -4,
      "name": "Plant_Crop_Mushroom_Flatcap_Green",
      "components": {
        "Components": {
          "FarmingBlock": {
            "LastTickGameTime": "0001-01-01T12:00:00Z"
          },
          "PlacedByInteraction": {
            "WhoPlacedUuid": {
              "$binary": "HCpUQzdeSaiDYHpoRePv+w==",
              "$type": "04"
            }
          }
        }
      }
    },
    {
      "x": 0,
      "y": 7,
      "z": -4,
      "name": "Rock_Quartzite_Brick"
    },
    {
      "x": 0,
      "y": 0,
      "z": -3,
      "name": "Rock_Stone_Brick",
      "rotation": 1
    },
    {
      "x": 0,
      "y": 1,
      "z": -3,
      "name": "Soil_Mud",
      "rotation": 1
    },
    {
      "x": 0,
      "y": 2,
      "z": -3,
      "name": "Deco_Bone_Ribs_Feran"
    },
    {
      "x": 0,
      "y": 7,
      "z": -3,
      "name": "Rock_Quartzite_Brick"
    },
    {
      "x": 0,
      "y": 0,
      "z": -2,
      "name": "Rock_Stone_Brick_Mossy",
      "rotation": 1
    },
    {
      "x": 0,
      "y": 1,
      "z": -2,
      "name": "Soil_Mud",
      "rotation": 1
    },
    {
      "x": 0,
      "y": 7,
      "z": -2,
      "name": "Rock_Quartzite_Brick",
      "rotation": 1
    },
    {
      "x": 0,
      "y": 0,
      "z": -1,
      "name": "Rock_Stone_Brick_Mossy",
      "rotation": 1
    },
    {
      "x": 0,
      "y": 1,
      "z": -1,
      "name": "Soil_Mud",
      "rotation": 1
    },
    {
      "x": 0,
      "y": 8,
      "z": -1,
      "name": "Soil_Clay_Brick_Stairs"
    },
    {
      "x": 0,
      "y": 9,
      "z": -1,
      "name": "Soil_Clay_Brick_Half",
      "rotation": 4
    },
    {
      "x": 0,
      "y": 10,
      "z": -1,
      "name": "Soil_Clay_Brick_Half",
      "rotation": 4
    },
    {
      "x": 0,
      "y": 11,
      "z": -1,
      "name": "Soil_Clay_Brick_Half",
      "rotation": 4
    },
    {
      "x": 0,
      "y": 12,
      "z": -1,
      "name": "Soil_Clay_Brick_Half",
      "rotation": 4
    },
    {
      "x": 0,
      "y": 13,
      "z": -1,
      "name": "Soil_Clay_Brick_Half",
      "rotation": 4
    },
    {
      "x": 0,
      "y": 14,
      "z": -1,
      "name": "Soil_Clay_Brick_Half",
      "rotation": 4
    },
    {
      "x": 0,
      "y": 15,
      "z": -1,
      "name": "Soil_Clay_Brick_Half",
      "rotation": 4
    },
    {
      "x": 0,
      "y": 16,
      "z": -1,
      "name": "Soil_Clay_Brick_Half",
      "rotation": 4
    },
    {
      "x": 0,
      "y": 17,
      "z": -1,
      "name": "Soil_Clay_Brick_Half",
      "rotation": 4
    },
    {
      "x": 0,
      "y": 18,
      "z": -1,
      "name": "Soil_Clay_Brick_Stairs"
    },
    {
      "x": 0,
      "y": 19,
      "z": -1,
      "name": "Soil_Clay_Brick_Half",
      "rotation": 4
    },
    {
      "x": 0,
      "y": 20,
      "z": -1,
      "name": "Soil_Clay_Brick_Half",
      "rotation": 4
    },
    {
      "x": 0,
      "y": 21,
      "z": -1,
      "name": "Soil_Clay_Brick_Half",
      "rotation": 4
    },
    {
      "x": 0,
      "y": 22,
      "z": -1,
      "name": "Soil_Clay_Brick_Half",
      "rotation": 4
    },
    {
      "x": 0,
      "y": 23,
      "z": -1,
      "name": "Soil_Clay_Brick_Half",
      "rotation": 4
    },
    {
      "x": 0,
      "y": 24,
      "z": -1,
      "name": "Soil_Clay_Brick_Half",
      "rotation": 4
    },
    {
      "x": 0,
      "y": 25,
      "z": -1,
      "name": "Soil_Clay_Brick_Half",
      "rotation": 4
    },
    {
      "x": 0,
      "y": 26,
      "z": -1,
      "name": "Soil_Clay_Brick_Half",
      "rotation": 4
    },
    {
      "x": 0,
      "y": 27,
      "z": -1,
      "name": "Soil_Clay_Brick_Half",
      "rotation": 4
    },
    {
      "x": 0,
      "y": 28,
      "z": -1,
      "name": "Soil_Clay_Brick_Stairs"
    },
    {
      "x": 0,
      "y": 0,
      "z": 0,
      "name": "Rock_Stone_Brick",
      "rotation": 1
    },
    {
      "x": 0,
      "y": 1,
      "z": 0,
      "name": "Soil_Mud",
      "rotation": 1
    },
    {
      "x": 0,
      "y": 0,
      "z": 1,
      "name": "Rock_Stone_Brick_Mossy",
      "rotation": 1
    },
    {
      "x": 0,
      "y": 1,
      "z": 1,
      "name": "Soil_Mud",
      "rotation": 1
    },
    {
      "x": 0,
      "y": 8,
      "z": 1,
      "name": "Soil_Clay_Brick_Stairs",
      "rotation": 2
    },
    {
      "x": 0,
      "y": 9,
      "z": 1,
      "name": "Soil_Clay_Brick_Half",
      "rotation": 6
    },
    {
      "x": 0,
      "y": 10,
      "z": 1,
      "name": "Soil_Clay_Brick_Half",
      "rotation": 6
    },
    {
      "x": 0,
      "y": 11,
      "z": 1,
      "name": "Soil_Clay_Brick_Half",
      "rotation": 6
    },
    {
      "x": 0,
      "y": 12,
      "z": 1,
      "name": "Soil_Clay_Brick_Half",
      "rotation": 6
    },
    {
      "x": 0,
      "y": 13,
      "z": 1,
      "name": "Soil_Clay_Brick_Half",
      "rotation": 6
    },
    {
      "x": 0,
      "y": 14,
      "z": 1,
      "name": "Soil_Clay_Brick_Half",
      "rotation": 6
    },
    {
      "x": 0,
      "y": 15,
      "z": 1,
      "name": "Soil_Clay_Brick_Half",
      "rotation": 6
    },
    {
      "x": 0,
      "y": 16,
      "z": 1,
      "name": "Soil_Clay_Brick_Half",
      "rotation": 6
    },
    {
      "x": 0,
      "y": 17,
      "z": 1,
      "name": "Soil_Clay_Brick_Half",
      "rotation": 6
    },
    {
      "x": 0,
      "y": 18,
      "z": 1,
      "name": "Soil_Clay_Brick_Stairs",
      "rotation": 2
    },
    {
      "x": 0,
      "y": 19,
      "z": 1,
      "name": "Soil_Clay_Brick_Half",
      "rotation": 6
    },
    {
      "x": 0,
      "y": 20,
      "z": 1,
      "name": "Soil_Clay_Brick_Half",
      "rotation": 6
    },
    {
      "x": 0,
      "y": 21,
      "z": 1,
      "name": "Soil_Clay_Brick_Half",
      "rotation": 6
    },
    {
      "x": 0,
      "y": 22,
      "z": 1,
      "name": "Soil_Clay_Brick_Half",
      "rotation": 6
    },
    {
      "x": 0,
      "y": 23,
      "z": 1,
      "name": "Soil_Clay_Brick_Half",
      "rotation": 6
    },
    {
      "x": 0,
      "y": 24,
      "z": 1,
      "name": "Soil_Clay_Brick_Half",
      "rotation": 6
    },
    {
      "x": 0,
      "y": 25,
      "z": 1,
      "name": "Soil_Clay_Brick_Half",
      "rotation": 6
    },
    {
      "x": 0,
      "y": 26,
      "z": 1,
      "name": "Soil_Clay_Brick_Half",
      "rotation": 6
    },
    {
      "x": 0,
      "y": 27,
      "z": 1,
      "name": "Soil_Clay_Brick_Half",
      "rotation": 6
    },
    {
      "x": 0,
      "y": 28,
      "z": 1,
      "name": "Soil_Clay_Brick_Stairs",
      "rotation": 2
    },
    {
      "x": 0,
      "y": 0,
      "z": 2,
      "name": "Rock_Stone_Brick_Mossy",
      "rotation": 1
    },
    {
      "x": 0,
      "y": 1,
      "z": 2,
      "name": "Soil_Mud",
      "rotation": 1
    },
    {
      "x": 0,
      "y": 6,
      "z": 2,
      "name": "Rock_Quartzite_Stalactite_Small",
      "rotation": 8
    },
    {
      "x": 0,
      "y": 7,
      "z": 2,
      "name": "Rock_Quartzite_Brick",
      "rotation": 1
    },
    {
      "x": 0,
      "y": 0,
      "z": 3,
      "name": "Rock_Stone_Brick",
      "rotation": 1
    },
    {
      "x": 0,
      "y": 1,
      "z": 3,
      "name": "Soil_Mud",
      "rotation": 1
    },
    {
      "x": 0,
      "y": 2,
      "z": 3,
      "name": "Ingredient_Poop"
    },
    {
      "x": 0,
      "y": 7,
      "z": 3,
      "name": "Rock_Quartzite_Brick",
      "rotation": 1
    },
    {
      "x": 0,
      "y": 0,
      "z": 4,
      "name": "Rock_Stone_Brick_Mossy",
      "rotation": 1
    },
    {
      "x": 0,
      "y": 1,
      "z": 4,
      "name": "Soil_Mud",
      "rotation": 1
    },
    {
      "x": 0,
      "y": 7,
      "z": 4,
      "name": "Rock_Quartzite_Brick"
    },
    {
      "x": 0,
      "y": 0,
      "z": 5,
      "name": "Rock_Stone_Brick_Mossy",
      "rotation": 1
    },
    {
      "x": 0,
      "y": 1,
      "z": 5,
      "name": "Soil_Mud",
      "rotation": 1
    },
    {
      "x": 0,
      "y": 5,
      "z": 5,
      "name": "Rock_Quartzite_Stalactite_Large",
      "filler": 31744,
      "rotation": 8
    },
    {
      "x": 0,
      "y": 6,
      "z": 5,
      "name": "Rock_Quartzite_Stalactite_Large",
      "rotation": 8
    },
    {
      "x": 0,
      "y": 7,
      "z": 5,
      "name": "Rock_Quartzite_Brick"
    },
    {
      "x": 0,
      "y": 0,
      "z": 6,
      "name": "Rock_Stone_Brick_Mossy",
      "rotation": 1
    },
    {
      "x": 0,
      "y": 1,
      "z": 6,
      "name": "Soil_Mud",
      "rotation": 1
    },
    {
      "x": 0,
      "y": 6,
      "z": 6,
      "name": "Rock_Quartzite_Stalactite_Small",
      "rotation": 8
    },
    {
      "x": 0,
      "y": 7,
      "z": 6,
      "name": "Rock_Quartzite_Brick",
      "rotation": 1
    },
    {
      "x": 0,
      "y": 0,
      "z": 7,
      "name": "Rock_Stone_Brick_Mossy",
      "rotation": 1
    },
    {
      "x": 0,
      "y": 1,
      "z": 7,
      "name": "Soil_Mud",
      "rotation": 1
    },
    {
      "x": 0,
      "y": 2,
      "z": 7,
      "name": "Ingredient_Poop"
    },
    {
      "x": 0,
      "y": 7,
      "z": 7,
      "name": "Build_Lightsource_YellowLight",
      "rotation": 5
    },
    {
      "x": 0,
      "y": 8,
      "z": 7,
      "name": "Rock_Quartzite_Brick"
    },
    {
      "x": 0,
      "y": 0,
      "z": 8,
      "name": "Rock_Stone_Brick_Mossy",
      "rotation": 1
    },
    {
      "x": 0,
      "y": 1,
      "z": 8,
      "name": "Soil_Mud",
      "rotation": 1
    },
    {
      "x": 0,
      "y": 7,
      "z": 8,
      "name": "Build_Lightsource_YellowLight",
      "rotation": 5
    },
    {
      "x": 0,
      "y": 8,
      "z": 8,
      "name": "Rock_Quartzite_Brick",
      "rotation": 1
    },
    {
      "x": 0,
      "y": 0,
      "z": 9,
      "name": "Rock_Stone_Brick_Mossy",
      "rotation": 1
    },
    {
      "x": 0,
      "y": 1,
      "z": 9,
      "name": "Soil_Mud",
      "rotation": 1
    },
    {
      "x": 0,
      "y": 7,
      "z": 9,
      "name": "Build_Lightsource_YellowLight",
      "rotation": 5
    },
    {
      "x": 0,
      "y": 8,
      "z": 9,
      "name": "Rock_Quartzite_Brick",
      "rotation": 1
    },
    {
      "x": 0,
      "y": 0,
      "z": 10,
      "name": "Rock_Stone_Brick_Mossy",
      "rotation": 1
    },
    {
      "x": 0,
      "y": 1,
      "z": 10,
      "name": "Soil_Mud",
      "rotation": 1
    },
    {
      "x": 0,
      "y": 7,
      "z": 10,
      "name": "Build_Lightsource_YellowLight",
      "rotation": 5
    },
    {
      "x": 0,
      "y": 8,
      "z": 10,
      "name": "Rock_Quartzite_Brick",
      "rotation": 1
    },
    {
      "x": 1,
      "y": 0,
      "z": -10,
      "name": "Rock_Stone_Brick_Mossy",
      "rotation": 3
    },
    {
      "x": 1,
      "y": 1,
      "z": -10,
      "name": "Soil_Clay_Brick",
      "rotation": 3
    },
    {
      "x": 1,
      "y": 2,
      "z": -10,
      "name": "Soil_Clay_Brick_Wall",
      "rotation": 3
    },
    {
      "x": 1,
      "y": 6,
      "z": -10,
      "name": "Rock_Quartzite_Brick_Half",
      "rotation": 7
    },
    {
      "x": 1,
      "y": 7,
      "z": -10,
      "name": "Rock_Quartzite_Brick",
      "rotation": 3
    },
    {
      "x": 1,
      "y": 0,
      "z": -9,
      "name": "Rock_Stone_Brick_Mossy",
      "rotation": 3
    },
    {
      "x": 1,
      "y": 1,
      "z": -9,
      "name": "Soil_Clay_Brick",
      "rotation": 3
    },
    {
      "x": 1,
      "y": 2,
      "z": -9,
      "name": "Soil_Clay_Brick_Wall",
      "rotation": 3
    },
    {
      "x": 1,
      "y": 6,
      "z": -9,
      "name": "Rock_Quartzite_Brick_Half",
      "rotation": 7
    },
    {
      "x": 1,
      "y": 7,
      "z": -9,
      "name": "Rock_Quartzite_Brick",
      "rotation": 3
    },
    {
      "x": 1,
      "y": 0,
      "z": -8,
      "name": "Rock_Stone_Brick_Mossy",
      "rotation": 3
    },
    {
      "x": 1,
      "y": 1,
      "z": -8,
      "name": "Soil_Clay_Brick",
      "rotation": 3
    },
    {
      "x": 1,
      "y": 2,
      "z": -8,
      "name": "Soil_Clay_Brick_Wall",
      "rotation": 3
    },
    {
      "x": 1,
      "y": 6,
      "z": -8,
      "name": "Rock_Quartzite_Brick_Half",
      "rotation": 7
    },
    {
      "x": 1,
      "y": 7,
      "z": -8,
      "name": "Rock_Quartzite_Brick",
      "rotation": 3
    },
    {
      "x": 1,
      "y": 0,
      "z": -7,
      "name": "Rock_Stone_Brick",
      "rotation": 1
    },
    {
      "x": 1,
      "y": 1,
      "z": -7,
      "name": "Soil_Clay_Brick"
    },
    {
      "x": 1,
      "y": 2,
      "z": -7,
      "name": "Soil_Clay_Brick_Wall",
      "rotation": 1
    },
    {
      "x": 1,
      "y": 6,
      "z": -7,
      "name": "Rock_Quartzite_Brick_Half",
      "rotation": 7
    },
    {
      "x": 1,
      "y": 7,
      "z": -7,
      "name": "Rock_Quartzite_Brick",
      "rotation": 1
    },
    {
      "x": 1,
      "y": 0,
      "z": -6,
      "name": "Rock_Stone_Brick_Mossy",
      "rotation": 1
    },
    {
      "x": 1,
      "y": 1,
      "z": -6,
      "name": "Soil_Clay_Brick"
    },
    {
      "x": 1,
      "y": 2,
      "z": -6,
      "name": "Soil_Clay_Brick_Wall",
      "rotation": 1
    },
    {
      "x": 1,
      "y": 6,
      "z": -6,
      "name": "Rock_Quartzite_Brick_Half",
      "rotation": 7
    },
    {
      "x": 1,
      "y": 7,
      "z": -6,
      "name": "Rock_Quartzite_Brick"
    },
    {
      "x": 1,
      "y": 0,
      "z": -5,
      "name": "Rock_Stone_Brick",
      "rotation": 1
    },
    {
      "x": 1,
      "y": 1,
      "z": -5,
      "name": "Soil_Clay_Brick"
    },
    {
      "x": 1,
      "y": 2,
      "z": -5,
      "name": "Soil_Clay_Brick_Wall",
      "rotation": 1
    },
    {
      "x": 1,
      "y": 6,
      "z": -5,
      "name": "Rock_Quartzite_Brick_Half",
      "rotation": 7
    },
    {
      "x": 1,
      "y": 7,
      "z": -5,
      "name": "Rock_Quartzite_Brick"
    },
    {
      "x": 1,
      "y": 0,
      "z": -4,
      "name": "Rock_Stone_Brick_Mossy",
      "rotation": 1
    },
    {
      "x": 1,
      "y": 1,
      "z": -4,
      "name": "Soil_Clay_Brick"
    },
    {
      "x": 1,
      "y": 2,
      "z": -4,
      "name": "Soil_Clay_Brick_Wall",
      "rotation": 1
    },
    {
      "x": 1,
      "y": 6,
      "z": -4,
      "name": "Rock_Quartzite_Brick_Half",
      "rotation": 7
    },
    {
      "x": 1,
      "y": 7,
      "z": -4,
      "name": "Rock_Quartzite_Brick"
    },
    {
      "x": 1,
      "y": 0,
      "z": -3,
      "name": "Rock_Stone_Brick_Mossy",
      "rotation": 1
    },
    {
      "x": 1,
      "y": 1,
      "z": -3,
      "name": "Soil_Clay_Brick"
    },
    {
      "x": 1,
      "y": 2,
      "z": -3,
      "name": "Soil_Clay_Brick_Wall",
      "rotation": 1
    },
    {
      "x": 1,
      "y": 6,
      "z": -3,
      "name": "Rock_Quartzite_Brick_Half",
      "rotation": 7
    },
    {
      "x": 1,
      "y": 7,
      "z": -3,
      "name": "Rock_Quartzite_Brick",
      "rotation": 1
    },
    {
      "x": 1,
      "y": 0,
      "z": -2,
      "name": "Rock_Stone_Brick_Mossy",
      "rotation": 1
    },
    {
      "x": 1,
      "y": 1,
      "z": -2,
      "name": "Soil_Clay_Brick"
    },
    {
      "x": 1,
      "y": 2,
      "z": -2,
      "name": "Soil_Clay_Brick_Wall",
      "rotation": 1
    },
    {
      "x": 1,
      "y": 7,
      "z": -2,
      "name": "Rock_Quartzite_Brick",
      "rotation": 1
    },
    {
      "x": 1,
      "y": 0,
      "z": -1,
      "name": "Rock_Stone_Brick",
      "rotation": 1
    },
    {
      "x": 1,
      "y": 1,
      "z": -1,
      "name": "Soil_Clay_Brick"
    },
    {
      "x": 1,
      "y": 2,
      "z": -1,
      "name": "*Soil_Clay_Brick_Wall_State_Definitions_Corner",
      "rotation": 2
    },
    {
      "x": 1,
      "y": 8,
      "z": -1,
      "name": "Soil_Clay_Brick"
    },
    {
      "x": 1,
      "y": 9,
      "z": -1,
      "name": "Soil_Clay_Brick"
    },
    {
      "x": 1,
      "y": 10,
      "z": -1,
      "name": "Soil_Clay_Brick_Stairs",
      "rotation": 16
    },
    {
      "x": 1,
      "y": 11,
      "z": -1,
      "name": "Soil_Clay_Brick_Stairs",
      "rotation": 16
    },
    {
      "x": 1,
      "y": 12,
      "z": -1,
      "name": "Soil_Clay_Brick_Stairs",
      "rotation": 16
    },
    {
      "x": 1,
      "y": 13,
      "z": -1,
      "name": "Soil_Clay_Brick_Stairs",
      "rotation": 16
    },
    {
      "x": 1,
      "y": 14,
      "z": -1,
      "name": "Soil_Clay_Brick_Stairs",
      "rotation": 16
    },
    {
      "x": 1,
      "y": 15,
      "z": -1,
      "name": "Soil_Clay_Brick_Stairs",
      "rotation": 16
    },
    {
      "x": 1,
      "y": 16,
      "z": -1,
      "name": "Soil_Clay_Brick_Stairs",
      "rotation": 16
    },
    {
      "x": 1,
      "y": 17,
      "z": -1,
      "name": "Soil_Clay_Brick_Stairs",
      "rotation": 16
    },
    {
      "x": 1,
      "y": 18,
      "z": -1,
      "name": "Soil_Clay_Brick"
    },
    {
      "x": 1,
      "y": 19,
      "z": -1,
      "name": "Soil_Clay_Brick"
    },
    {
      "x": 1,
      "y": 20,
      "z": -1,
      "name": "Soil_Clay_Brick_Stairs",
      "rotation": 16
    },
    {
      "x": 1,
      "y": 21,
      "z": -1,
      "name": "Soil_Clay_Brick_Stairs",
      "rotation": 16
    },
    {
      "x": 1,
      "y": 22,
      "z": -1,
      "name": "Soil_Clay_Brick_Stairs",
      "rotation": 16
    },
    {
      "x": 1,
      "y": 23,
      "z": -1,
      "name": "Soil_Clay_Brick_Stairs",
      "rotation": 16
    },
    {
      "x": 1,
      "y": 24,
      "z": -1,
      "name": "Soil_Clay_Brick_Stairs",
      "rotation": 16
    },
    {
      "x": 1,
      "y": 25,
      "z": -1,
      "name": "Soil_Clay_Brick_Stairs",
      "rotation": 16
    },
    {
      "x": 1,
      "y": 26,
      "z": -1,
      "name": "Soil_Clay_Brick_Stairs",
      "rotation": 16
    },
    {
      "x": 1,
      "y": 27,
      "z": -1,
      "name": "Soil_Clay_Brick_Stairs",
      "rotation": 16
    },
    {
      "x": 1,
      "y": 28,
      "z": -1,
      "name": "Soil_Clay_Brick"
    },
    {
      "x": 1,
      "y": 0,
      "z": 0,
      "name": "Rock_Stone_Brick_Mossy",
      "rotation": 1
    },
    {
      "x": 1,
      "y": 1,
      "z": 0,
      "name": "Soil_Mud"
    },
    {
      "x": 1,
      "y": 2,
      "z": 0,
      "name": "Deco_Bone_Skulls_Feran"
    },
    {
      "x": 1,
      "y": 8,
      "z": 0,
      "name": "Soil_Clay_Brick_Stairs",
      "rotation": 3
    },
    {
      "x": 1,
      "y": 9,
      "z": 0,
      "name": "Soil_Clay_Brick_Half",
      "rotation": 7
    },
    {
      "x": 1,
      "y": 10,
      "z": 0,
      "name": "Soil_Clay_Brick_Half",
      "rotation": 7
    },
    {
      "x": 1,
      "y": 11,
      "z": 0,
      "name": "Soil_Clay_Brick_Half",
      "rotation": 7
    },
    {
      "x": 1,
      "y": 12,
      "z": 0,
      "name": "Soil_Clay_Brick_Half",
      "rotation": 7
    },
    {
      "x": 1,
      "y": 13,
      "z": 0,
      "name": "Soil_Clay_Brick_Half",
      "rotation": 7
    },
    {
      "x": 1,
      "y": 14,
      "z": 0,
      "name": "Soil_Clay_Brick_Half",
      "rotation": 7
    },
    {
      "x": 1,
      "y": 15,
      "z": 0,
      "name": "Soil_Clay_Brick_Half",
      "rotation": 7
    },
    {
      "x": 1,
      "y": 16,
      "z": 0,
      "name": "Soil_Clay_Brick_Half",
      "rotation": 7
    },
    {
      "x": 1,
      "y": 17,
      "z": 0,
      "name": "Soil_Clay_Brick_Half",
      "rotation": 7
    },
    {
      "x": 1,
      "y": 18,
      "z": 0,
      "name": "Soil_Clay_Brick_Stairs",
      "rotation": 3
    },
    {
      "x": 1,
      "y": 19,
      "z": 0,
      "name": "Soil_Clay_Brick_Half",
      "rotation": 7
    },
    {
      "x": 1,
      "y": 20,
      "z": 0,
      "name": "Soil_Clay_Brick_Half",
      "rotation": 7
    },
    {
      "x": 1,
      "y": 21,
      "z": 0,
      "name": "Soil_Clay_Brick_Half",
      "rotation": 7
    },
    {
      "x": 1,
      "y": 22,
      "z": 0,
      "name": "Soil_Clay_Brick_Half",
      "rotation": 7
    },
    {
      "x": 1,
      "y": 23,
      "z": 0,
      "name": "Soil_Clay_Brick_Half",
      "rotation": 7
    },
    {
      "x": 1,
      "y": 24,
      "z": 0,
      "name": "Soil_Clay_Brick_Half",
      "rotation": 7
    },
    {
      "x": 1,
      "y": 25,
      "z": 0,
      "name": "Soil_Clay_Brick_Half",
      "rotation": 7
    },
    {
      "x": 1,
      "y": 26,
      "z": 0,
      "name": "Soil_Clay_Brick_Half",
      "rotation": 7
    },
    {
      "x": 1,
      "y": 27,
      "z": 0,
      "name": "Soil_Clay_Brick_Half",
      "rotation": 7
    },
    {
      "x": 1,
      "y": 28,
      "z": 0,
      "name": "Soil_Clay_Brick_Stairs",
      "rotation": 3
    },
    {
      "x": 1,
      "y": 0,
      "z": 1,
      "name": "Rock_Stone_Brick_Mossy",
      "rotation": 1
    },
    {
      "x": 1,
      "y": 1,
      "z": 1,
      "name": "Soil_Clay_Brick"
    },
    {
      "x": 1,
      "y": 2,
      "z": 1,
      "name": "*Soil_Clay_Brick_Wall_State_Definitions_Corner",
      "rotation": 1
    },
    {
      "x": 1,
      "y": 8,
      "z": 1,
      "name": "Soil_Clay_Brick"
    },
    {
      "x": 1,
      "y": 9,
      "z": 1,
      "name": "Soil_Clay_Brick"
    },
    {
      "x": 1,
      "y": 10,
      "z": 1,
      "name": "Soil_Clay_Brick_Stairs",
      "rotation": 19
    },
    {
      "x": 1,
      "y": 11,
      "z": 1,
      "name": "Soil_Clay_Brick_Stairs",
      "rotation": 19
    },
    {
      "x": 1,
      "y": 12,
      "z": 1,
      "name": "Soil_Clay_Brick_Stairs",
      "rotation": 19
    },
    {
      "x": 1,
      "y": 13,
      "z": 1,
      "name": "Soil_Clay_Brick_Stairs",
      "rotation": 19
    },
    {
      "x": 1,
      "y": 14,
      "z": 1,
      "name": "Soil_Clay_Brick_Stairs",
      "rotation": 19
    },
    {
      "x": 1,
      "y": 15,
      "z": 1,
      "name": "Soil_Clay_Brick_Stairs",
      "rotation": 19
    },
    {
      "x": 1,
      "y": 16,
      "z": 1,
      "name": "Soil_Clay_Brick_Stairs",
      "rotation": 19
    },
    {
      "x": 1,
      "y": 17,
      "z": 1,
      "name": "Soil_Clay_Brick_Stairs",
      "rotation": 19
    },
    {
      "x": 1,
      "y": 18,
      "z": 1,
      "name": "Soil_Clay_Brick"
    },
    {
      "x": 1,
      "y": 19,
      "z": 1,
      "name": "Soil_Clay_Brick"
    },
    {
      "x": 1,
      "y": 20,
      "z": 1,
      "name": "Soil_Clay_Brick_Stairs",
      "rotation": 19
    },
    {
      "x": 1,
      "y": 21,
      "z": 1,
      "name": "Soil_Clay_Brick_Stairs",
      "rotation": 19
    },
    {
      "x": 1,
      "y": 22,
      "z": 1,
      "name": "Soil_Clay_Brick_Stairs",
      "rotation": 19
    },
    {
      "x": 1,
      "y": 23,
      "z": 1,
      "name": "Soil_Clay_Brick_Stairs",
      "rotation": 19
    },
    {
      "x": 1,
      "y": 24,
      "z": 1,
      "name": "Soil_Clay_Brick_Stairs",
      "rotation": 19
    },
    {
      "x": 1,
      "y": 25,
      "z": 1,
      "name": "Soil_Clay_Brick_Stairs",
      "rotation": 19
    },
    {
      "x": 1,
      "y": 26,
      "z": 1,
      "name": "Soil_Clay_Brick_Stairs",
      "rotation": 19
    },
    {
      "x": 1,
      "y": 27,
      "z": 1,
      "name": "Soil_Clay_Brick_Stairs",
      "rotation": 19
    },
    {
      "x": 1,
      "y": 28,
      "z": 1,
      "name": "Soil_Clay_Brick"
    },
    {
      "x": 1,
      "y": 0,
      "z": 2,
      "name": "Rock_Stone_Brick_Mossy",
      "rotation": 1
    },
    {
      "x": 1,
      "y": 1,
      "z": 2,
      "name": "Soil_Clay_Brick"
    },
    {
      "x": 1,
      "y": 2,
      "z": 2,
      "name": "Soil_Clay_Brick_Wall",
      "rotation": 1
    },
    {
      "x": 1,
      "y": 7,
      "z": 2,
      "name": "Rock_Quartzite_Brick",
      "rotation": 1
    },
    {
      "x": 1,
      "y": 0,
      "z": 3,
      "name": "Rock_Stone_Brick_Mossy",
      "rotation": 1
    },
    {
      "x": 1,
      "y": 1,
      "z": 3,
      "name": "Soil_Clay_Brick"
    },
    {
      "x": 1,
      "y": 2,
      "z": 3,
      "name": "Soil_Clay_Brick_Wall",
      "rotation": 1
    },
    {
      "x": 1,
      "y": 6,
      "z": 3,
      "name": "Rock_Quartzite_Brick_Half",
      "rotation": 7
    },
    {
      "x": 1,
      "y": 7,
      "z": 3,
      "name": "Rock_Quartzite_Brick",
      "rotation": 1
    },
    {
      "x": 1,
      "y": 0,
      "z": 4,
      "name": "Rock_Stone_Brick_Mossy",
      "rotation": 1
    },
    {
      "x": 1,
      "y": 1,
      "z": 4,
      "name": "Soil_Clay_Brick"
    },
    {
      "x": 1,
      "y": 2,
      "z": 4,
      "name": "Soil_Clay_Brick_Wall",
      "rotation": 1
    },
    {
      "x": 1,
      "y": 6,
      "z": 4,
      "name": "Rock_Quartzite_Brick_Half",
      "rotation": 7
    },
    {
      "x": 1,
      "y": 7,
      "z": 4,
      "name": "Rock_Quartzite_Brick",
      "rotation": 1
    },
    {
      "x": 1,
      "y": 0,
      "z": 5,
      "name": "Rock_Stone_Brick_Mossy",
      "rotation": 1
    },
    {
      "x": 1,
      "y": 1,
      "z": 5,
      "name": "Soil_Clay_Brick"
    },
    {
      "x": 1,
      "y": 2,
      "z": 5,
      "name": "Soil_Clay_Brick_Wall",
      "rotation": 1
    },
    {
      "x": 1,
      "y": 6,
      "z": 5,
      "name": "Rock_Quartzite_Brick_Half",
      "rotation": 7
    },
    {
      "x": 1,
      "y": 7,
      "z": 5,
      "name": "Rock_Quartzite_Brick"
    },
    {
      "x": 1,
      "y": 0,
      "z": 6,
      "name": "Rock_Stone_Brick_Mossy",
      "rotation": 1
    },
    {
      "x": 1,
      "y": 1,
      "z": 6,
      "name": "Soil_Clay_Brick"
    },
    {
      "x": 1,
      "y": 2,
      "z": 6,
      "name": "Soil_Clay_Brick_Wall",
      "rotation": 1
    },
    {
      "x": 1,
      "y": 6,
      "z": 6,
      "name": "Rock_Quartzite_Brick_Half",
      "rotation": 7
    },
    {
      "x": 1,
      "y": 7,
      "z": 6,
      "name": "Rock_Quartzite_Brick"
    },
    {
      "x": 1,
      "y": 0,
      "z": 7,
      "name": "Rock_Stone_Brick_Mossy",
      "rotation": 1
    },
    {
      "x": 1,
      "y": 1,
      "z": 7,
      "name": "Soil_Clay_Brick"
    },
    {
      "x": 1,
      "y": 2,
      "z": 7,
      "name": "Soil_Clay_Brick_Wall",
      "rotation": 1
    },
    {
      "x": 1,
      "y": 6,
      "z": 7,
      "name": "Rock_Quartzite_Brick_Half",
      "rotation": 7
    },
    {
      "x": 1,
      "y": 7,
      "z": 7,
      "name": "Rock_Quartzite_Brick"
    },
    {
      "x": 1,
      "y": 0,
      "z": 8,
      "name": "Rock_Stone_Brick",
      "rotation": 1
    },
    {
      "x": 1,
      "y": 1,
      "z": 8,
      "name": "Soil_Clay_Brick",
      "rotation": 1
    },
    {
      "x": 1,
      "y": 2,
      "z": 8,
      "name": "Soil_Clay_Brick_Wall",
      "rotation": 1
    },
    {
      "x": 1,
      "y": 6,
      "z": 8,
      "name": "Rock_Quartzite_Brick_Half",
      "rotation": 7
    },
    {
      "x": 1,
      "y": 7,
      "z": 8,
      "name": "Rock_Quartzite_Brick",
      "rotation": 1
    },
    {
      "x": 1,
      "y": 0,
      "z": 9,
      "name": "Rock_Stone_Brick",
      "rotation": 1
    },
    {
      "x": 1,
      "y": 1,
      "z": 9,
      "name": "Soil_Clay_Brick",
      "rotation": 1
    },
    {
      "x": 1,
      "y": 2,
      "z": 9,
      "name": "Soil_Clay_Brick_Wall",
      "rotation": 1
    },
    {
      "x": 1,
      "y": 6,
      "z": 9,
      "name": "Rock_Quartzite_Brick_Half",
      "rotation": 7
    },
    {
      "x": 1,
      "y": 7,
      "z": 9,
      "name": "Rock_Quartzite_Brick",
      "rotation": 1
    },
    {
      "x": 1,
      "y": 0,
      "z": 10,
      "name": "Rock_Stone_Brick",
      "rotation": 1
    },
    {
      "x": 1,
      "y": 1,
      "z": 10,
      "name": "Soil_Clay_Brick",
      "rotation": 1
    },
    {
      "x": 1,
      "y": 2,
      "z": 10,
      "name": "Soil_Clay_Brick_Wall",
      "rotation": 1
    },
    {
      "x": 1,
      "y": 6,
      "z": 10,
      "name": "Rock_Quartzite_Brick_Half",
      "rotation": 7
    },
    {
      "x": 1,
      "y": 7,
      "z": 10,
      "name": "Rock_Quartzite_Brick",
      "rotation": 1
    },
    {
      "x": 2,
      "y": 1,
      "z": -10,
      "name": "Rock_Stone_Brick_Mossy",
      "rotation": 3
    },
    {
      "x": 2,
      "y": 2,
      "z": -10,
      "name": "Rubble_Stone_Mossy",
      "support": 15,
      "rotation": 3
    },
    {
      "x": 2,
      "y": 5,
      "z": -10,
      "name": "Rock_Quartzite_Brick_Stairs",
      "rotation": 35
    },
    {
      "x": 2,
      "y": 6,
      "z": -10,
      "name": "Rock_Quartzite_Brick",
      "rotation": 3
    },
    {
      "x": 2,
      "y": 1,
      "z": -9,
      "name": "Rock_Stone_Brick_Mossy",
      "rotation": 3
    },
    {
      "x": 2,
      "y": 2,
      "z": -9,
      "name": "Rubble_Stone_Mossy",
      "support": 15,
      "rotation": 3
    },
    {
      "x": 2,
      "y": 5,
      "z": -9,
      "name": "Rock_Quartzite_Brick_Stairs",
      "rotation": 35
    },
    {
      "x": 2,
      "y": 6,
      "z": -9,
      "name": "Rock_Quartzite_Brick",
      "rotation": 3
    },
    {
      "x": 2,
      "y": 1,
      "z": -8,
      "name": "Rock_Stone_Brick_Mossy",
      "rotation": 3
    },
    {
      "x": 2,
      "y": 2,
      "z": -8,
      "name": "Rubble_Stone_Mossy",
      "support": 15,
      "rotation": 3
    },
    {
      "x": 2,
      "y": 5,
      "z": -8,
      "name": "Rock_Quartzite_Brick_Stairs",
      "rotation": 35
    },
    {
      "x": 2,
      "y": 6,
      "z": -8,
      "name": "Rock_Quartzite_Brick",
      "rotation": 3
    },
    {
      "x": 2,
      "y": 1,
      "z": -7,
      "name": "Rock_Stone_Brick",
      "rotation": 1
    },
    {
      "x": 2,
      "y": 5,
      "z": -7,
      "name": "Rock_Quartzite_Brick_Stairs",
      "rotation": 9
    },
    {
      "x": 2,
      "y": 6,
      "z": -7,
      "name": "Rock_Quartzite_Brick",
      "rotation": 1
    },
    {
      "x": 2,
      "y": 1,
      "z": -6,
      "name": "Rock_Stone_Brick_Mossy",
      "rotation": 1
    },
    {
      "x": 2,
      "y": 2,
      "z": -6,
      "name": "Rubble_Stone_Mossy",
      "support": 15
    },
    {
      "x": 2,
      "y": 5,
      "z": -6,
      "name": "Rock_Quartzite_Brick_Stairs",
      "rotation": 9
    },
    {
      "x": 2,
      "y": 6,
      "z": -6,
      "name": "Rock_Quartzite_Brick",
      "rotation": 1
    },
    {
      "x": 2,
      "y": 1,
      "z": -5,
      "name": "Rock_Stone_Brick_Mossy",
      "rotation": 1
    },
    {
      "x": 2,
      "y": 5,
      "z": -5,
      "name": "Rock_Quartzite_Brick_Stairs",
      "rotation": 9
    },
    {
      "x": 2,
      "y": 6,
      "z": -5,
      "name": "Soil_Quartzite_Gravel",
      "rotation": 1
    },
    {
      "x": 2,
      "y": 1,
      "z": -4,
      "name": "Rock_Stone_Brick_Mossy",
      "rotation": 1
    },
    {
      "x": 2,
      "y": 5,
      "z": -4,
      "name": "Rock_Quartzite_Brick_Stairs",
      "rotation": 9
    },
    {
      "x": 2,
      "y": 6,
      "z": -4,
      "name": "Rock_Quartzite_Brick",
      "rotation": 1
    },
    {
      "x": 2,
      "y": 1,
      "z": -3,
      "name": "Rock_Stone_Brick_Mossy",
      "rotation": 1
    },
    {
      "x": 2,
      "y": 5,
      "z": -3,
      "name": "Rock_Quartzite_Brick_Stairs",
      "rotation": 9
    },
    {
      "x": 2,
      "y": 6,
      "z": -3,
      "name": "Rock_Quartzite_Brick",
      "rotation": 1
    },
    {
      "x": 2,
      "y": 1,
      "z": -2,
      "name": "Rock_Stone_Brick",
      "rotation": 1
    },
    {
      "x": 2,
      "y": 2,
      "z": -2,
      "name": "Rubble_Stone_Mossy_Medium",
      "support": 15
    },
    {
      "x": 2,
      "y": 5,
      "z": -2,
      "name": "*Rock_Quartzite_Brick_Stairs_State_Definitions_Corner_Right",
      "rotation": 9
    },
    {
      "x": 2,
      "y": 6,
      "z": -2,
      "name": "Rock_Quartzite_Brick",
      "rotation": 1
    },
    {
      "x": 2,
      "y": 7,
      "z": -2,
      "name": "Rock_Quartzite_Brick"
    },
    {
      "x": 2,
      "y": 0,
      "z": -1,
      "name": "Rock_Stone_Brick_Mossy"
    },
    {
      "x": 2,
      "y": 1,
      "z": -1,
      "name": "Soil_Clay_Brick"
    },
    {
      "x": 2,
      "y": 2,
      "z": -1,
      "name": "Soil_Clay_Brick_Wall"
    },
    {
      "x": 2,
      "y": 5,
      "z": -1,
      "name": "Rock_Quartzite_Stalactite_Large",
      "filler": 31744,
      "rotation": 8
    },
    {
      "x": 2,
      "y": 6,
      "z": -1,
      "name": "Rock_Quartzite_Stalactite_Large",
      "rotation": 8
    },
    {
      "x": 2,
      "y": 7,
      "z": -1,
      "name": "Rock_Quartzite_Brick"
    },
    {
      "x": 2,
      "y": 0,
      "z": 0,
      "name": "Rock_Stone_Brick_Mossy"
    },
    {
      "x": 2,
      "y": 1,
      "z": 0,
      "name": "Soil_Mud"
    },
    {
      "x": 2,
      "y": 7,
      "z": 0,
      "name": "Rock_Quartzite_Brick"
    },
    {
      "x": 2,
      "y": 0,
      "z": 1,
      "name": "Rock_Stone_Brick_Mossy"
    },
    {
      "x": 2,
      "y": 1,
      "z": 1,
      "name": "Soil_Clay_Brick"
    },
    {
      "x": 2,
      "y": 2,
      "z": 1,
      "name": "Soil_Clay_Brick_Wall"
    },
    {
      "x": 2,
      "y": 7,
      "z": 1,
      "name": "Rock_Quartzite_Brick"
    },
    {
      "x": 2,
      "y": 1,
      "z": 2,
      "name": "Rock_Stone_Brick_Mossy",
      "rotation": 1
    },
    {
      "x": 2,
      "y": 2,
      "z": 2,
      "name": "Rubble_Stone_Mossy_Medium",
      "support": 15
    },
    {
      "x": 2,
      "y": 5,
      "z": 2,
      "name": "*Rock_Quartzite_Brick_Stairs_State_Definitions_Corner_Left",
      "rotation": 9
    },
    {
      "x": 2,
      "y": 6,
      "z": 2,
      "name": "Rock_Quartzite_Brick",
      "rotation": 1
    },
    {
      "x": 2,
      "y": 7,
      "z": 2,
      "name": "Rock_Quartzite_Brick"
    },
    {
      "x": 2,
      "y": 1,
      "z": 3,
      "name": "Rock_Stone_Brick_Mossy",
      "rotation": 1
    },
    {
      "x": 2,
      "y": 2,
      "z": 3,
      "name": "Rubble_Stone_Mossy",
      "support": 15
    },
    {
      "x": 2,
      "y": 5,
      "z": 3,
      "name": "Rock_Quartzite_Brick_Stairs",
      "rotation": 9
    },
    {
      "x": 2,
      "y": 6,
      "z": 3,
      "name": "Rock_Quartzite_Brick",
      "rotation": 1
    },
    {
      "x": 2,
      "y": 1,
      "z": 4,
      "name": "Rock_Stone_Brick",
      "rotation": 1
    },
    {
      "x": 2,
      "y": 5,
      "z": 4,
      "name": "Rock_Quartzite_Brick_Stairs",
      "rotation": 9
    },
    {
      "x": 2,
      "y": 6,
      "z": 4,
      "name": "Soil_Quartzite_Gravel",
      "rotation": 1
    },
    {
      "x": 2,
      "y": 1,
      "z": 5,
      "name": "Rock_Stone_Brick_Mossy",
      "rotation": 1
    },
    {
      "x": 2,
      "y": 5,
      "z": 5,
      "name": "Rock_Quartzite_Brick_Stairs",
      "rotation": 9
    },
    {
      "x": 2,
      "y": 6,
      "z": 5,
      "name": "Rock_Quartzite_Brick",
      "rotation": 1
    },
    {
      "x": 2,
      "y": 1,
      "z": 6,
      "name": "Rock_Stone_Brick",
      "rotation": 1
    },
    {
      "x": 2,
      "y": 2,
      "z": 6,
      "name": "Plant_Crop_Mushroom_Glowing_Green"
    },
    {
      "x": 2,
      "y": 5,
      "z": 6,
      "name": "Rock_Quartzite_Brick_Stairs",
      "rotation": 9
    },
    {
      "x": 2,
      "y": 6,
      "z": 6,
      "name": "Rock_Quartzite_Brick",
      "rotation": 1
    },
    {
      "x": 2,
      "y": 1,
      "z": 7,
      "name": "Rock_Stone_Brick_Mossy",
      "rotation": 1
    },
    {
      "x": 2,
      "y": 5,
      "z": 7,
      "name": "Rock_Quartzite_Brick_Stairs",
      "rotation": 9
    },
    {
      "x": 2,
      "y": 6,
      "z": 7,
      "name": "Rock_Quartzite_Brick",
      "rotation": 1
    },
    {
      "x": 2,
      "y": 1,
      "z": 8,
      "name": "Rock_Stone_Brick",
      "rotation": 1
    },
    {
      "x": 2,
      "y": 2,
      "z": 8,
      "name": "Rubble_Stone_Mossy_Medium",
      "support": 15,
      "rotation": 1
    },
    {
      "x": 2,
      "y": 5,
      "z": 8,
      "name": "Rock_Quartzite_Brick_Stairs",
      "rotation": 35
    },
    {
      "x": 2,
      "y": 6,
      "z": 8,
      "name": "Rock_Quartzite_Brick",
      "rotation": 1
    },
    {
      "x": 2,
      "y": 1,
      "z": 9,
      "name": "Rock_Stone_Brick",
      "rotation": 1
    },
    {
      "x": 2,
      "y": 2,
      "z": 9,
      "name": "Rubble_Stone_Mossy_Medium",
      "support": 15,
      "rotation": 1
    },
    {
      "x": 2,
      "y": 5,
      "z": 9,
      "name": "Rock_Quartzite_Brick_Stairs",
      "rotation": 35
    },
    {
      "x": 2,
      "y": 6,
      "z": 9,
      "name": "Rock_Quartzite_Brick",
      "rotation": 1
    },
    {
      "x": 2,
      "y": 1,
      "z": 10,
      "name": "Rock_Stone_Brick",
      "rotation": 1
    },
    {
      "x": 2,
      "y": 2,
      "z": 10,
      "name": "Rubble_Stone_Mossy_Medium",
      "support": 15,
      "rotation": 1
    },
    {
      "x": 2,
      "y": 5,
      "z": 10,
      "name": "Rock_Quartzite_Brick_Stairs",
      "rotation": 35
    },
    {
      "x": 2,
      "y": 6,
      "z": 10,
      "name": "Rock_Quartzite_Brick",
      "rotation": 1
    },
    {
      "x": 3,
      "y": 1,
      "z": -10,
      "name": "Rock_Stone_Brick_Mossy",
      "rotation": 3
    },
    {
      "x": 3,
      "y": 2,
      "z": -10,
      "name": "Soil_Quartzite_Gravel",
      "rotation": 3
    },
    {
      "x": 3,
      "y": 3,
      "z": -10,
      "name": "Rock_Quartzite_Brick",
      "rotation": 3
    },
    {
      "x": 3,
      "y": 4,
      "z": -10,
      "name": "Rock_Quartzite_Brick",
      "rotation": 3
    },
    {
      "x": 3,
      "y": 1,
      "z": -9,
      "name": "Rock_Stone_Brick_Mossy",
      "rotation": 3
    },
    {
      "x": 3,
      "y": 2,
      "z": -9,
      "name": "Soil_Quartzite_Gravel",
      "rotation": 3
    },
    {
      "x": 3,
      "y": 3,
      "z": -9,
      "name": "Rock_Quartzite_Brick",
      "rotation": 3
    },
    {
      "x": 3,
      "y": 4,
      "z": -9,
      "name": "Rock_Quartzite_Brick",
      "rotation": 3
    },
    {
      "x": 3,
      "y": 1,
      "z": -8,
      "name": "Rock_Stone_Brick_Mossy",
      "rotation": 3
    },
    {
      "x": 3,
      "y": 2,
      "z": -8,
      "name": "Soil_Quartzite_Gravel",
      "rotation": 3
    },
    {
      "x": 3,
      "y": 3,
      "z": -8,
      "name": "Rock_Quartzite_Brick",
