{
  "version": 8,
  "blockIdVersion": 11,
  "anchorX": 0,
  "anchorY": 0,
  "anchorZ": 0,
  "blocks": [
    {
      "x": -4,
      "y": 0,
      "z": 4,
      "name": "Rock_Sandstone_Brick_Pillar_Base"
    },
    {
      "x": -4,
      "y": 1,
      "z": 4,
      "name": "Rock_Sandstone_Brick_Pillar_Middle"
    },
    {
      "x": -4,
      "y": 2,
      "z": 4,
      "name": "Rock_Sandstone_Brick_Pillar_Base",
      "rotation": 8
    },
    {
      "x": -4,
      "y": 3,
      "z": 5,
      "name": "Rock_Sandstone_Cobble_Stairs",
      "rotation": 10
    },
    {
      "x": -4,
      "y": 4,
      "z": 5,
      "name": "Rock_Sandstone_Cobble"
    },
    {
      "x": -4,
      "y": 5,
      "z": 5,
      "name": "Rock_Sandstone_Cobble_Stairs",
      "rotation": 3
    },
    {
      "x": -3,
      "y": 0,
      "z": -2,
      "name": "Rock_Sandstone_Cobble"
    },
    {
      "x": -3,
      "y": 0,
      "z": 3,
      "name": "Rock_Sandstone_Brick"
    },
    {
      "x": -3,
      "y": 0,
      "z": 4,
      "name": "Rock_Sandstone_Brick",
      "rotation": 2
    },
    {
      "x": -3,
      "y": 1,
      "z": 4,
      "name": "Rock_Sandstone_Cobble",
      "rotation": 2
    },
    {
      "x": -3,
      "y": 2,
      "z": 4,
      "name": "Rock_Sandstone_Cobble",
      "rotation": 2
    },
    {
      "x": -3,
      "y": 3,
      "z": 5,
      "name": "Rock_Sandstone_Brick_Stairs",
      "rotation": 10
    },
    {
      "x": -3,
      "y": 4,
      "z": 5,
      "name": "Rock_Sandstone_Brick",
      "rotation": 2
    },
    {
      "x": -3,
      "y": 5,
      "z": 5,
      "name": "Rock_Sandstone_Brick_Stairs",
      "rotation": 1
    },
    {
      "x": -2,
      "y": 0,
      "z": -3,
      "name": "Rock_Sandstone_Cobble"
    },
    {
      "x": -2,
      "y": 0,
      "z": -1,
      "name": "Deco_Pot_Clay_Broken"
    },
    {
      "x": -2,
      "y": 0,
      "z": 0,
      "name": "Wood_Dry_Trunk",
      "support": 15,
      "rotation": 5
    },
    {
      "x": -2,
      "y": 0,
      "z": 4,
      "name": "Rock_Sandstone_Brick_Stairs",
      "rotation": 2
    },
    {
      "x": -2,
      "y": 1,
      "z": 4,
      "name": "Rock_Sandstone_Brick_Stairs",
      "rotation": 11
    },
    {
      "x": -2,
      "y": 2,
      "z": 4,
      "name": "Rock_Sandstone_Cobble",
      "rotation": 2
    },
    {
      "x": -2,
      "y": 3,
      "z": 4,
      "name": "Rock_Sandstone_Cobble"
    },
    {
      "x": -2,
      "y": 4,
      "z": 4,
      "name": "Rock_Sandstone_White_Cobble",
      "support": 15
    },
    {
      "x": -2,
      "y": 5,
      "z": 4,
      "name": "Wood_Dry_Trunk",
      "rotation": 5
    },
    {
      "x": -2,
      "y": 1,
      "z": 5,
      "name": "Rock_Sandstone_Brick_Smooth_Half",
      "rotation": 7
    },
    {
      "x": -2,
      "y": 2,
      "z": 5,
      "name": "Rock_Sandstone_Brick_Smooth_Half",
      "rotation": 7
    },
    {
      "x": -2,
      "y": 4,
      "z": 5,
      "name": "Rock_Sandstone_Brick",
      "rotation": 2
    },
    {
      "x": -2,
      "y": 5,
      "z": 5,
      "name": "Soil_Clay_Ocean_Brick_Roof"
    },
    {
      "x": -1,
      "y": 0,
      "z": -4,
      "name": "Rock_Sandstone_Brick_Smooth_Half",
      "rotation": 6
    },
    {
      "x": -1,
      "y": 0,
      "z": -3,
      "name": "Rock_Sandstone_Brick",
      "support": 15
    },
    {
      "x": -1,
      "y": 1,
      "z": -3,
      "name": "Rubble_Sandstone"
    },
    {
      "x": -1,
      "y": 0,
      "z": 0,
      "name": "Wood_Dry_Trunk",
      "support": 15,
      "rotation": 5
    },
    {
      "x": -1,
      "y": 0,
      "z": 4,
      "name": "*Rock_Sandstone_Brick_Stairs_State_Definitions_Corner_Left",
      "rotation": 1
    },
    {
      "x": -1,
      "y": 3,
      "z": 4,
      "name": "Rock_Sandstone_Cobble",
      "rotation": 2
    },
    {
      "x": -1,
      "y": 4,
      "z": 4,
      "name": "Rock_Sandstone_White_Cobble",
      "support": 15
    },
    {
      "x": -1,
      "y": 5,
      "z": 4,
      "name": "Wood_Dry_Trunk",
      "rotation": 5
    },
    {
      "x": -1,
      "y": 0,
      "z": 5,
      "name": "Rock_Sandstone_Brick_Smooth_Half",
      "rotation": 4
    },
    {
      "x": -1,
      "y": 3,
      "z": 5,
      "name": "Rock_Sandstone_Brick_Smooth_Half"
    },
    {
      "x": -1,
      "y": 4,
      "z": 5,
      "name": "Rock_Sandstone_Brick",
      "rotation": 2
    },
    {
      "x": -1,
      "y": 5,
      "z": 5,
      "name": "Soil_Clay_Ocean_Brick_Roof"
    },
    {
      "x": 0,
      "y": 1,
      "z": -4,
      "name": "Rock_Sandstone_Brick_Smooth_Half",
      "rotation": 5
    },
    {
      "x": 0,
      "y": 2,
      "z": -4,
      "name": "Rock_Sandstone_Brick_Smooth_Half",
      "rotation": 5
    },
    {
      "x": 0,
      "y": 4,
      "z": -4,
      "name": "Rock_Sandstone_Brick"
    },
    {
      "x": 0,
      "y": 0,
      "z": -3,
      "name": "Rock_Sandstone_Brick"
    },
    {
      "x": 0,
      "y": 1,
      "z": -3,
      "name": "Rock_Sandstone_Brick"
    },
    {
      "x": 0,
      "y": 2,
      "z": -3,
      "name": "Rock_Sandstone_Brick"
    },
    {
      "x": 0,
      "y": 3,
      "z": -3,
      "name": "Rock_Sandstone_Cobble"
    },
    {
      "x": 0,
      "y": 4,
      "z": -3,
      "name": "Rock_Sandstone_White_Cobble",
      "support": 15
    },
    {
      "x": 0,
      "y": 5,
      "z": -3,
      "name": "Wood_Dry_Branch_Long",
      "rotation": 5
    },
    {
      "x": 0,
      "y": 0,
      "z": 0,
      "name": "Wood_Dry_Branch_Long",
      "support": 15,
      "rotation": 5
    },
    {
      "x": 0,
      "y": 0,
      "z": 4,
      "name": "Rock_Sandstone_Brick"
    },
    {
      "x": 0,
      "y": 1,
      "z": 4,
      "name": "Rock_Sandstone_Brick_Stairs",
      "rotation": 9
    },
    {
      "x": 0,
      "y": 2,
      "z": 4,
      "name": "Rock_Sandstone_Brick_Stairs",
      "rotation": 3
    },
    {
      "x": 0,
      "y": 3,
      "z": 4,
      "name": "Rock_Sandstone_Cobble",
      "rotation": 2
    },
    {
      "x": 0,
      "y": 4,
      "z": 4,
      "name": "Rock_Sandstone_White_Cobble",
      "support": 15
    },
    {
      "x": 0,
      "y": 5,
      "z": 4,
      "name": "Wood_Dry_Trunk",
      "rotation": 5
    },
    {
      "x": 0,
      "y": 1,
      "z": 5,
      "name": "Rock_Sandstone_Brick_Smooth_Half",
      "rotation": 5
    },
    {
      "x": 0,
      "y": 2,
      "z": 5,
      "name": "Rock_Sandstone_Brick_Smooth_Half",
      "rotation": 5
    },
    {
      "x": 0,
      "y": 4,
      "z": 5,
      "name": "Rock_Sandstone_Brick",
      "rotation": 2
    },
    {
      "x": 0,
      "y": 5,
      "z": 5,
      "name": "Soil_Clay_Ocean_Brick_Roof"
    },
    {
      "x": 1,
      "y": 1,
      "z": -4,
      "name": "Rock_Sandstone_Brick_Smooth_Half",
      "rotation": 7
    },
    {
      "x": 1,
      "y": 2,
      "z": -4,
      "name": "Rock_Sandstone_Brick_Smooth_Half",
      "rotation": 7
    },
    {
      "x": 1,
      "y": 4,
      "z": -4,
      "name": "Rock_Sandstone_Brick"
    },
    {
      "x": 1,
      "y": 5,
      "z": -4,
      "name": "Soil_Clay_Ocean_Brick_Roof",
      "rotation": 2
    },
    {
      "x": 1,
      "y": 0,
      "z": -3,
      "name": "Rock_Sandstone_Brick"
    },
    {
      "x": 1,
      "y": 1,
      "z": -3,
      "name": "Rock_Sandstone_Brick"
    },
    {
      "x": 1,
      "y": 2,
      "z": -3,
      "name": "Rock_Sandstone_Brick"
    },
    {
      "x": 1,
      "y": 3,
      "z": -3,
      "name": "Rock_Sandstone_Cobble"
    },
    {
      "x": 1,
      "y": 4,
      "z": -3,
      "name": "Rock_Sandstone_White_Cobble",
      "support": 15
    },
    {
      "x": 1,
      "y": 5,
      "z": -3,
      "name": "Wood_Dry_Trunk",
      "rotation": 5
    },
    {
      "x": 1,
      "y": 5,
      "z": -2,
      "name": "Cloth_Roof_Leather_Flap"
    },
    {
      "x": 1,
      "y": 0,
      "z": 4,
      "name": "Rock_Sandstone_Brick"
    },
    {
      "x": 1,
      "y": 1,
      "z": 4,
      "name": "Rock_Sandstone_Brick_Stairs",
      "rotation": 1
    },
    {
      "x": 1,
      "y": 2,
      "z": 4,
      "name": "Rock_Sandstone_Brick_Stairs",
      "rotation": 8
    },
    {
      "x": 1,
      "y": 3,
      "z": 4,
      "name": "Rock_Sandstone_Cobble",
      "rotation": 2
    },
    {
      "x": 1,
      "y": 4,
      "z": 4,
      "name": "Rock_Sandstone_White_Cobble",
      "support": 15
    },
    {
      "x": 1,
      "y": 5,
      "z": 4,
      "name": "Wood_Dry_Trunk",
      "rotation": 5
    },
    {
      "x": 1,
      "y": 1,
      "z": 5,
      "name": "Rock_Sandstone_Brick_Smooth_Half",
      "rotation": 7
    },
    {
      "x": 1,
      "y": 2,
      "z": 5,
      "name": "Rock_Sandstone_Brick_Smooth_Half",
      "rotation": 7
    },
    {
      "x": 1,
      "y": 4,
      "z": 5,
      "name": "Rock_Sandstone_Brick",
      "rotation": 2
    },
    {
      "x": 2,
      "y": 0,
      "z": -4,
      "name": "Rock_Sandstone_Brick_Smooth_Half",
      "rotation": 6
    },
    {
      "x": 2,
      "y": 3,
      "z": -4,
      "name": "Rock_Sandstone_Brick_Smooth_Half"
    },
    {
      "x": 2,
      "y": 4,
      "z": -4,
      "name": "Rock_Sandstone_Brick"
    },
    {
      "x": 2,
      "y": 5,
      "z": -4,
      "name": "Soil_Clay_Ocean_Brick_Roof",
      "rotation": 2
    },
    {
      "x": 2,
      "y": 0,
      "z": -3,
      "name": "Rock_Sandstone_Brick"
    },
    {
      "x": 2,
      "y": 3,
      "z": -3,
      "name": "Rock_Sandstone_Cobble"
    },
    {
      "x": 2,
      "y": 4,
      "z": -3,
      "name": "Rock_Sandstone_White_Cobble",
      "support": 15
    },
    {
      "x": 2,
      "y": 5,
      "z": -3,
      "name": "Wood_Dry_Trunk",
      "rotation": 5
    },
    {
      "x": 2,
      "y": 5,
      "z": -2,
      "name": "Cloth_Roof_Leather_Flap"
    },
    {
      "x": 2,
      "y": 0,
      "z": 3,
      "name": "Wood_Sticks"
    },
    {
      "x": 2,
      "y": 5,
      "z": 3,
      "name": "Cloth_Roof_Leather_Flap",
      "rotation": 2
    },
    {
      "x": 2,
      "y": 0,
      "z": 4,
      "name": "Rock_Sandstone_Brick_Stairs",
      "rotation": 3
    },
    {
      "x": 2,
      "y": 3,
      "z": 4,
      "name": "Rock_Sandstone_Brick",
      "rotation": 2
    },
    {
      "x": 2,
      "y": 4,
      "z": 4,
      "name": "Rock_Sandstone_White_Cobble",
      "support": 15
    },
    {
      "x": 2,
      "y": 5,
      "z": 4,
      "name": "Wood_Dry_Trunk",
      "rotation": 5
    },
    {
      "x": 2,
      "y": 0,
      "z": 5,
      "name": "Rock_Sandstone_Brick_Smooth_Half",
      "rotation": 4
    },
    {
      "x": 2,
      "y": 3,
      "z": 5,
      "name": "Rock_Sandstone_Brick_Smooth_Half"
    },
    {
      "x": 2,
      "y": 4,
      "z": 5,
      "name": "Rock_Sandstone_Brick",
      "rotation": 2
    },
    {
      "x": 2,
      "y": 5,
      "z": 5,
      "name": "Soil_Clay_Ocean_Brick_Roof"
    },
    {
      "x": 3,
      "y": 1,
      "z": -4,
      "name": "Rock_Sandstone_Brick_Smooth_Half",
      "rotation": 5
    },
    {
      "x": 3,
      "y": 2,
      "z": -4,
      "name": "Rock_Sandstone_Brick_Smooth_Half",
      "rotation": 5
    },
    {
      "x": 3,
      "y": 4,
      "z": -4,
      "name": "Rock_Sandstone_Brick"
    },
    {
      "x": 3,
      "y": 5,
      "z": -4,
      "name": "Soil_Clay_Ocean_Brick_Roof",
      "rotation": 2
    },
    {
      "x": 3,
      "y": 0,
      "z": -3,
      "name": "Rock_Sandstone_Brick"
    },
    {
      "x": 3,
      "y": 1,
      "z": -3,
      "name": "Rock_Sandstone_Brick"
    },
    {
      "x": 3,
      "y": 2,
      "z": -3,
      "name": "Rock_Sandstone_Cobble"
    },
    {
      "x": 3,
      "y": 3,
      "z": -3,
      "name": "Rock_Sandstone_Cobble"
    },
    {
      "x": 3,
      "y": 4,
      "z": -3,
      "name": "Rock_Sandstone_White_Cobble",
      "support": 15
    },
    {
      "x": 3,
      "y": 5,
      "z": -3,
      "name": "Wood_Dry_Trunk",
      "rotation": 5
    },
    {
      "x": 3,
      "y": 5,
      "z": -2,
      "name": "Cloth_Roof_Leather_Flap"
    },
    {
      "x": 3,
      "y": 0,
      "z": 4,
      "name": "Rock_Sandstone_Cobble",
      "rotation": 2
    },
    {
      "x": 3,
      "y": 1,
      "z": 4,
      "name": "Rock_Sandstone_Cobble",
      "rotation": 2
    },
    {
      "x": 3,
      "y": 2,
      "z": 4,
      "name": "Rock_Sandstone_Brick",
      "rotation": 2
    },
    {
      "x": 3,
      "y": 3,
      "z": 4,
      "name": "Rock_Sandstone_Brick",
      "support": 15,
      "rotation": 2
    },
    {
      "x": 3,
      "y": 4,
      "z": 4,
      "name": "Rubble_Sandstone",
      "support": 15
    },
    {
      "x": 3,
      "y": 1,
      "z": 5,
      "name": "Rock_Sandstone_Brick_Smooth_Half",
      "rotation": 5
    },
    {
      "x": 3,
      "y": 2,
      "z": 5,
      "name": "Rock_Sandstone_Brick_Smooth_Half",
      "rotation": 5
    },
    {
      "x": 3,
      "y": 4,
      "z": 5,
      "name": "Rock_Sandstone_Brick",
      "rotation": 2
    },
    {
      "x": 4,
      "y": 3,
      "z": -4,
      "name": "Rock_Sandstone_Cobble_Stairs",
      "rotation": 8
    },
    {
      "x": 4,
      "y": 4,
      "z": -4,
      "name": "Rock_Sandstone_Brick"
    },
    {
      "x": 4,
      "y": 5,
      "z": -4,
      "name": "Rock_Sandstone_Brick_Stairs",
      "rotation": 3
    },
    {
      "x": 4,
      "y": 0,
      "z": -3,
      "name": "Rock_Sandstone_Brick"
    },
    {
      "x": 4,
      "y": 1,
      "z": -3,
      "name": "Rock_Sandstone_Cobble"
    },
    {
      "x": 4,
      "y": 2,
      "z": -3,
      "name": "Rock_Sandstone_Cobble"
    },
    {
      "x": 4,
      "y": 3,
      "z": -3,
      "name": "Rock_Sandstone_Cobble"
    },
    {
      "x": 4,
      "y": 4,
      "z": -3,
      "name": "Rock_Sandstone_Cobble",
      "support": 15
    },
    {
      "x": 4,
      "y": 5,
      "z": -3,
      "name": "Wood_Dry_Trunk",
      "rotation": 7
    },
    {
      "x": 4,
      "y": 0,
      "z": -2,
      "name": "Rock_Sandstone_Cobble",
      "rotation": 2
    },
    {
      "x": 4,
      "y": 1,
      "z": -2,
      "name": "Rock_Sandstone_Cobble",
      "rotation": 2
    },
    {
      "x": 4,
      "y": 2,
      "z": -2,
      "name": "Rock_Sandstone_Brick",
      "rotation": 2
    },
    {
      "x": 4,
      "y": 3,
      "z": -2,
      "name": "Rock_Sandstone_Brick",
      "rotation": 2
    },
    {
      "x": 4,
      "y": 4,
      "z": -2,
      "name": "Rock_Sandstone_White_Cobble"
    },
    {
      "x": 4,
      "y": 5,
      "z": -2,
      "name": "Soil_Clay_Ocean_Brick_Roof",
      "rotation": 3
    },
    {
      "x": 4,
      "y": 2,
      "z": -1,
      "name": "Rock_Sandstone_Brick_Stairs",
      "rotation": 10
    },
    {
      "x": 4,
      "y": 3,
      "z": -1,
      "name": "Rock_Sandstone_Brick",
      "rotation": 2
    },
    {
      "x": 4,
      "y": 4,
      "z": -1,
      "name": "Rock_Sandstone_White_Cobble",
      "support": 15
    },
    {
      "x": 4,
      "y": 3,
      "z": 0,
      "name": "*Rock_Sandstone_Brick_Half_State_Definitions_Block",
      "rotation": 10
    },
    {
      "x": 4,
      "y": 4,
      "z": 0,
      "name": "Rock_Sandstone_White_Cobble"
    },
    {
      "x": 4,
      "y": 3,
      "z": 1,
      "name": "Rock_Sandstone_Brick",
      "rotation": 2
    },
    {
      "x": 4,
      "y": 0,
      "z": 3,
      "name": "Rock_Sandstone_Cobble",
      "support": 15,
      "rotation": 2
    },
    {
      "x": 4,
      "y": 1,
      "z": 3,
      "name": "Rubble_Sandstone_Medium"
    },
    {
      "x": 4,
      "y": 0,
      "z": 4,
      "name": "Rock_Sandstone_Cobble",
      "rotation": 2
    },
    {
      "x": 4,
      "y": 1,
      "z": 4,
      "name": "Rock_Sandstone_Cobble",
      "rotation": 2
    },
    {
      "x": 4,
      "y": 3,
      "z": 5,
      "name": "Rock_Sandstone_Brick_Stairs",
      "rotation": 10
    },
    {
      "x": 5,
      "y": 3,
      "z": -4,
      "name": "Rock_Sandstone_Cobble_Stairs",
      "rotation": 8
    },
    {
      "x": 5,
      "y": 4,
      "z": -4,
      "name": "Rock_Sandstone_Cobble",
      "rotation": 2
    },
    {
      "x": 5,
      "y": 5,
      "z": -4,
      "name": "Rock_Sandstone_Cobble_Stairs",
      "rotation": 1
    },
    {
      "x": 5,
      "y": 0,
      "z": -3,
      "name": "Rock_Sandstone_Brick_Pillar_Base"
    },
    {
      "x": 5,
      "y": 1,
      "z": -3,
      "name": "Rock_Sandstone_Brick_Pillar_Middle"
    },
    {
      "x": 5,
      "y": 2,
      "z": -3,
      "name": "Rock_Sandstone_Brick_Pillar_Base",
      "rotation": 8
    },
    {
      "x": 5,
      "y": 3,
      "z": -3,
      "name": "Rock_Sandstone_Cobble"
    },
    {
      "x": 5,
      "y": 4,
      "z": -3,
      "name": "Rock_Sandstone_Cobble"
    },
    {
      "x": 5,
      "y": 5,
      "z": -3,
      "name": "Soil_Clay_Ocean_Brick_Roof",
      "rotation": 1
    },
    {
      "x": 5,
      "y": 0,
      "z": -2,
      "name": "Rock_Sandstone_Brick",
      "rotation": 2
    },
    {
      "x": 5,
      "y": 1,
      "z": -2,
      "name": "Rock_Sandstone_Brick",
      "rotation": 2
    },
    {
      "x": 5,
      "y": 2,
      "z": -2,
      "name": "Rock_Sandstone_Brick",
      "rotation": 2
    },
    {
      "x": 5,
      "y": 3,
      "z": -2,
      "name": "Rock_Sandstone_Cobble",
      "rotation": 2
    },
    {
      "x": 5,
      "y": 4,
      "z": -2,
      "name": "Rock_Sandstone_Brick",
      "rotation": 2
    },
    {
      "x": 5,
      "y": 5,
      "z": -2,
      "name": "Soil_Clay_Ocean_Brick_Roof",
      "rotation": 1
    },
    {
      "x": 5,
      "y": 3,
      "z": -1,
      "name": "Rock_Sandstone_Brick_Stairs",
      "rotation": 10
    },
    {
      "x": 5,
      "y": 4,
      "z": -1,
      "name": "Rock_Sandstone_Brick",
      "rotation": 2
    },
    {
      "x": 5,
      "y": 4,
      "z": 0,
      "name": "Rock_Sandstone_Brick",
      "rotation": 2
    },
    {
      "x": 5,
      "y": 0,
      "z": 3,
      "name": "Rock_Sandstone_Cobble",
      "rotation": 2
    },
    {
      "x": 5,
      "y": 0,
      "z": 4,
      "name": "Rock_Sandstone_Brick_Pillar_Base"
    }
  ],
  "fluids": [
    {
      "x": -4,
      "y": 0,
      "z": 4,
      "name": "Empty",
      "level": 0
    },
    {
      "x": -4,
      "y": 1,
      "z": 4,
      "name": "Empty",
      "level": 0
    },
    {
      "x": -4,
      "y": 2,
      "z": 4,
      "name": "Empty",
      "level": 0
    },
    {
      "x": -4,
      "y": 3,
      "z": 5,
      "name": "Empty",
      "level": 0
    },
    {
      "x": -4,
      "y": 4,
      "z": 5,
      "name": "Empty",
      "level": 0
    },
    {
      "x": -4,
      "y": 5,
      "z": 5,
      "name": "Empty",
      "level": 0
    },
    {
      "x": -3,
      "y": 0,
      "z": -2,
      "name": "Empty",
      "level": 0
    },
    {
      "x": -3,
      "y": 0,
      "z": 3,
      "name": "Empty",
      "level": 0
    },
    {
      "x": -3,
      "y": 0,
      "z": 4,
      "name": "Empty",
      "level": 0
    },
    {
      "x": -3,
      "y": 1,
      "z": 4,
      "name": "Empty",
      "level": 0
    },
    {
      "x": -3,
      "y": 2,
      "z": 4,
      "name": "Empty",
      "level": 0
    },
    {
      "x": -3,
      "y": 3,
      "z": 5,
      "name": "Empty",
      "level": 0
    },
    {
      "x": -3,
      "y": 4,
      "z": 5,
      "name": "Empty",
      "level": 0
    },
    {
      "x": -3,
      "y": 5,
      "z": 5,
      "name": "Empty",
      "level": 0
    },
    {
      "x": -2,
      "y": 0,
      "z": -3,
      "name": "Empty",
      "level": 0
    },
    {
      "x": -2,
      "y": 0,
      "z": -1,
      "name": "Empty",
      "level": 0
    },
    {
      "x": -2,
      "y": 0,
      "z": 0,
      "name": "Empty",
      "level": 0
    },
    {
      "x": -2,
      "y": 0,
      "z": 4,
      "name": "Empty",
      "level": 0
    },
    {
      "x": -2,
      "y": 1,
      "z": 4,
      "name": "Empty",
      "level": 0
    },
    {
      "x": -2,
      "y": 2,
      "z": 4,
      "name": "Empty",
      "level": 0
    },
    {
      "x": -2,
      "y": 3,
      "z": 4,
      "name": "Empty",
      "level": 0
    },
    {
      "x": -2,
      "y": 4,
      "z": 4,
      "name": "Empty",
      "level": 0
    },
    {
      "x": -2,
      "y": 5,
      "z": 4,
      "name": "Empty",
      "level": 0
    },
    {
      "x": -2,
      "y": 1,
      "z": 5,
      "name": "Empty",
      "level": 0
    },
    {
      "x": -2,
      "y": 2,
      "z": 5,
      "name": "Empty",
      "level": 0
    },
    {
      "x": -2,
      "y": 4,
      "z": 5,
      "name": "Empty",
      "level": 0
    },
    {
      "x": -2,
      "y": 5,
      "z": 5,
      "name": "Empty",
      "level": 0
    },
    {
      "x": -1,
      "y": 0,
      "z": -4,
      "name": "Empty",
      "level": 0
    },
    {
      "x": -1,
      "y": 0,
      "z": -3,
      "name": "Empty",
      "level": 0
    },
    {
      "x": -1,
      "y": 1,
      "z": -3,
      "name": "Empty",
      "level": 0
    },
    {
      "x": -1,
      "y": 0,
      "z": 0,
      "name": "Empty",
      "level": 0
    },
    {
      "x": -1,
      "y": 0,
      "z": 4,
      "name": "Empty",
      "level": 0
    },
    {
      "x": -1,
      "y": 3,
      "z": 4,
      "name": "Empty",
      "level": 0
    },
    {
      "x": -1,
      "y": 4,
      "z": 4,
      "name": "Empty",
      "level": 0
    },
    {
      "x": -1,
      "y": 5,
      "z": 4,
      "name": "Empty",
      "level": 0
    },
    {
      "x": -1,
      "y": 0,
      "z": 5,
      "name": "Empty",
      "level": 0
    },
    {
      "x": -1,
      "y": 3,
      "z": 5,
      "name": "Empty",
      "level": 0
    },
    {
      "x": -1,
      "y": 4,
      "z": 5,
      "name": "Empty",
      "level": 0
    },
    {
      "x": -1,
      "y": 5,
      "z": 5,
      "name": "Empty",
      "level": 0
    },
    {
      "x": 0,
      "y": 1,
      "z": -4,
      "name": "Empty",
      "level": 0
    },
    {
      "x": 0,
      "y": 2,
      "z": -4,
      "name": "Empty",
      "level": 0
    },
    {
      "x": 0,
      "y": 4,
      "z": -4,
      "name": "Empty",
      "level": 0
    },
    {
      "x": 0,
      "y": 0,
      "z": -3,
      "name": "Empty",
      "level": 0
    },
    {
      "x": 0,
      "y": 1,
      "z": -3,
      "name": "Empty",
      "level": 0
    },
    {
      "x": 0,
      "y": 2,
      "z": -3,
      "name": "Empty",
      "level": 0
    },
    {
      "x": 0,
      "y": 3,
      "z": -3,
      "name": "Empty",
      "level": 0
    },
    {
      "x": 0,
      "y": 4,
      "z": -3,
      "name": "Empty",
      "level": 0
    },
    {
      "x": 0,
      "y": 5,
      "z": -3,
      "name": "Empty",
      "level": 0
    },
    {
      "x": 0,
      "y": 0,
      "z": 0,
      "name": "Empty",
      "level": 0
    },
    {
      "x": 0,
      "y": 0,
      "z": 4,
      "name": "Empty",
      "level": 0
    },
    {
      "x": 0,
      "y": 1,
      "z": 4,
      "name": "Empty",
      "level": 0
    },
    {
      "x": 0,
      "y": 2,
      "z": 4,
      "name": "Empty",
      "level": 0
    },
    {
      "x": 0,
      "y": 3,
      "z": 4,
      "name": "Empty",
      "level": 0
    },
    {
      "x": 0,
      "y": 4,
      "z": 4,
      "name": "Empty",
      "level": 0
    },
    {
      "x": 0,
      "y": 5,
      "z": 4,
      "name": "Empty",
      "level": 0
    },
    {
      "x": 0,
      "y": 1,
      "z": 5,
      "name": "Empty",
      "level": 0
    },
    {
      "x": 0,
      "y": 2,
      "z": 5,
      "name": "Empty",
      "level": 0
    },
    {
      "x": 0,
      "y": 4,
      "z": 5,
      "name": "Empty",
      "level": 0
    },
    {
      "x": 0,
      "y": 5,
      "z": 5,
      "name": "Empty",
      "level": 0
    },
    {
      "x": 1,
      "y": 1,
      "z": -4,
      "name": "Empty",
      "level": 0
    },
    {
      "x": 1,
      "y": 2,
      "z": -4,
      "name": "Empty",
      "level": 0
    },
    {
      "x": 1,
      "y": 4,
      "z": -4,
      "name": "Empty",
      "level": 0
    },
    {
      "x": 1,
      "y": 5,
      "z": -4,
      "name": "Empty",
      "level": 0
    },
    {
      "x": 1,
      "y": 0,
      "z": -3,
      "name": "Empty",
      "level": 0
    },
    {
      "x": 1,
      "y": 1,
      "z": -3,
      "name": "Empty",
      "level": 0
    },
    {
      "x": 1,
      "y": 2,
      "z": -3,
      "name": "Empty",
      "level": 0
    },
    {
      "x": 1,
      "y": 3,
      "z": -3,
      "name": "Empty",
      "level": 0
    },
    {
      "x": 1,
      "y": 4,
      "z": -3,
      "name": "Empty",
      "level": 0
    },
    {
      "x": 1,
      "y": 5,
      "z": -3,
      "name": "Empty",
      "level": 0
    },
    {
      "x": 1,
      "y": 5,
      "z": -2,
      "name": "Empty",
      "level": 0
    },
    {
      "x": 1,
      "y": 0,
      "z": 4,
      "name": "Empty",
      "level": 0
    },
    {
      "x": 1,
      "y": 1,
      "z": 4,
      "name": "Empty",
      "level": 0
    },
    {
      "x": 1,
      "y": 2,
      "z": 4,
      "name": "Empty",
      "level": 0
    },
    {
      "x": 1,
      "y": 3,
      "z": 4,
      "name": "Empty",
      "level": 0
    },
    {
      "x": 1,
      "y": 4,
      "z": 4,
      "name": "Empty",
      "level": 0
    },
    {
      "x": 1,
      "y": 5,
      "z": 4,
      "name": "Empty",
      "level": 0
    },
    {
      "x": 1,
      "y": 1,
      "z": 5,
      "name": "Empty",
      "level": 0
    },
    {
      "x": 1,
      "y": 2,
      "z": 5,
      "name": "Empty",
      "level": 0
    },
    {
      "x": 1,
      "y": 4,
      "z": 5,
      "name": "Empty",
      "level": 0
    },
    {
      "x": 2,
      "y": 0,
      "z": -4,
      "name": "Empty",
      "level": 0
    },
    {
      "x": 2,
      "y": 3,
      "z": -4,
      "name": "Empty",
      "level": 0
    },
    {
      "x": 2,
      "y": 4,
      "z": -4,
      "name": "Empty",
      "level": 0
    },
    {
      "x": 2,
      "y": 5,
      "z": -4,
      "name": "Empty",
      "level": 0
    },
    {
      "x": 2,
      "y": 0,
      "z": -3,
      "name": "Empty",
      "level": 0
    },
    {
      "x": 2,
      "y": 3,
      "z": -3,
      "name": "Empty",
      "level": 0
    },
    {
      "x": 2,
      "y": 4,
      "z": -3,
      "name": "Empty",
      "level": 0
    },
    {
      "x": 2,
      "y": 5,
      "z": -3,
      "name": "Empty",
      "level": 0
    },
    {
      "x": 2,
      "y": 5,
      "z": -2,
      "name": "Empty",
      "level": 0
    },
    {
      "x": 2,
      "y": 0,
      "z": 3,
      "name": "Empty",
      "level": 0
    },
    {
      "x": 2,
      "y": 5,
      "z": 3,
      "name": "Empty",
      "level": 0
    },
    {
      "x": 2,
      "y": 0,
      "z": 4,
      "name": "Empty",
      "level": 0
    },
    {
      "x": 2,
      "y": 3,
      "z": 4,
      "name": "Empty",
      "level": 0
    },
    {
      "x": 2,
      "y": 4,
      "z": 4,
      "name": "Empty",
      "level": 0
    },
    {
      "x": 2,
      "y": 5,
      "z": 4,
      "name": "Empty",
      "level": 0
    },
    {
      "x": 2,
      "y": 0,
      "z": 5,
      "name": "Empty",
      "level": 0
    },
    {
      "x": 2,
      "y": 3,
      "z": 5,
      "name": "Empty",
      "level": 0
    },
    {
      "x": 2,
      "y": 4,
      "z": 5,
      "name": "Empty",
      "level": 0
    },
    {
      "x": 2,
      "y": 5,
      "z": 5,
      "name": "Empty",
      "level": 0
    },
    {
      "x": 3,
      "y": 1,
      "z": -4,
      "name": "Empty",
      "level": 0
    },
    {
      "x": 3,
      "y": 2,
      "z": -4,
      "name": "Empty",
      "level": 0
    },
    {
      "x": 3,
      "y": 4,
      "z": -4,
      "name": "Empty",
      "level": 0
    },
    {
      "x": 3,
      "y": 5,
      "z": -4,
      "name": "Empty",
      "level": 0
    },
    {
      "x": 3,
      "y": 0,
      "z": -3,
      "name": "Empty",
      "level": 0
    },
    {
      "x": 3,
      "y": 1,
      "z": -3,
      "name": "Empty",
      "level": 0
    },
    {
      "x": 3,
      "y": 2,
      "z": -3,
      "name": "Empty",
      "level": 0
    },
    {
      "x": 3,
      "y": 3,
      "z": -3,
      "name": "Empty",
      "level": 0
    },
    {
      "x": 3,
      "y": 4,
      "z": -3,
      "name": "Empty",
      "level": 0
    },
    {
      "x": 3,
      "y": 5,
      "z": -3,
      "name": "Empty",
      "level": 0
    },
    {
      "x": 3,
      "y": 5,
      "z": -2,
      "name": "Empty",
      "level": 0
    },
    {
      "x": 3,
      "y": 0,
      "z": 4,
      "name": "Empty",
      "level": 0
    },
    {
      "x": 3,
      "y": 1,
      "z": 4,
      "name": "Empty",
      "level": 0
    },
    {
      "x": 3,
      "y": 2,
      "z": 4,
      "name": "Empty",
      "level": 0
    },
    {
      "x": 3,
      "y": 3,
      "z": 4,
      "name": "Empty",
      "level": 0
    },
    {
      "x": 3,
      "y": 4,
      "z": 4,
      "name": "Empty",
      "level": 0
    },
    {
      "x": 3,
      "y": 1,
      "z": 5,
      "name": "Empty",
      "level": 0
    },
    {
      "x": 3,
      "y": 2,
      "z": 5,
      "name": "Empty",
      "level": 0
    },
    {
      "x": 3,
      "y": 4,
      "z": 5,
      "name": "Empty",
      "level": 0
    },
    {
      "x": 4,
      "y": 3,
      "z": -4,
      "name": "Empty",
      "level": 0
    },
    {
      "x": 4,
      "y": 4,
      "z": -4,
      "name": "Empty",
      "level": 0
    },
    {
      "x": 4,
      "y": 5,
      "z": -4,
      "name": "Empty",
      "level": 0
    },
    {
      "x": 4,
      "y": 0,
      "z": -3,
      "name": "Empty",
      "level": 0
    },
    {
      "x": 4,
      "y": 1,
      "z": -3,
      "name": "Empty",
      "level": 0
    },
    {
      "x": 4,
      "y": 2,
      "z": -3,
      "name": "Empty",
      "level": 0
    },
    {
      "x": 4,
      "y": 3,
      "z": -3,
      "name": "Empty",
      "level": 0
    },
    {
      "x": 4,
      "y": 4,
      "z": -3,
      "name": "Empty",
      "level": 0
    },
    {
      "x": 4,
      "y": 5,
      "z": -3,
      "name": "Empty",
      "level": 0
    },
    {
      "x": 4,
      "y": 0,
      "z": -2,
      "name": "Empty",
      "level": 0
    },
    {
      "x": 4,
      "y": 1,
      "z": -2,
      "name": "Empty",
      "level": 0
    },
    {
      "x": 4,
      "y": 2,
      "z": -2,
      "name": "Empty",
      "level": 0
    },
    {
      "x": 4,
      "y": 3,
      "z": -2,
      "name": "Empty",
      "level": 0
    },
    {
      "x": 4,
      "y": 4,
      "z": -2,
      "name": "Empty",
      "level": 0
    },
    {
      "x": 4,
      "y": 5,
      "z": -2,
      "name": "Empty",
      "level": 0
    },
    {
      "x": 4,
      "y": 2,
      "z": -1,
      "name": "Empty",
      "level": 0
    },
    {
      "x": 4,
      "y": 3,
      "z": -1,
      "name": "Empty",
      "level": 0
    },
    {
      "x": 4,
      "y": 4,
      "z": -1,
      "name": "Empty",
      "level": 0
    },
    {
      "x": 4,
      "y": 3,
      "z": 0,
      "name": "Empty",
      "level": 0
    },
    {
      "x": 4,
      "y": 4,
      "z": 0,
      "name": "Empty",
      "level": 0
    },
    {
      "x": 4,
      "y": 3,
      "z": 1,
      "name": "Empty",
      "level": 0
    },
    {
      "x": 4,
      "y": 0,
      "z": 3,
      "name": "Empty",
      "level": 0
    },
    {
      "x": 4,
      "y": 1,
      "z": 3,
      "name": "Empty",
      "level": 0
    },
    {
      "x": 4,
      "y": 0,
      "z": 4,
      "name": "Empty",
      "level": 0
    },
    {
      "x": 4,
      "y": 1,
      "z": 4,
      "name": "Empty",
      "level": 0
    },
    {
      "x": 4,
      "y": 3,
      "z": 5,
      "name": "Empty",
      "level": 0
    },
    {
      "x": 5,
      "y": 3,
      "z": -4,
      "name": "Empty",
      "level": 0
    },
    {
      "x": 5,
      "y": 4,
      "z": -4,
      "name": "Empty",
      "level": 0
    },
    {
      "x": 5,
      "y": 5,
      "z": -4,
      "name": "Empty",
      "level": 0
    },
    {
      "x": 5,
      "y": 0,
      "z": -3,
      "name": "Empty",
      "level": 0
    },
    {
      "x": 5,
      "y": 1,
      "z": -3,
      "name": "Empty",
      "level": 0
    },
    {
      "x": 5,
      "y": 2,
      "z": -3,
      "name": "Empty",
      "level": 0
    },
    {
      "x": 5,
      "y": 3,
      "z": -3,
      "name": "Empty",
      "level": 0
    },
    {
      "x": 5,
      "y": 4,
      "z": -3,
      "name": "Empty",
      "level": 0
    },
    {
      "x": 5,
      "y": 5,
      "z": -3,
      "name": "Empty",
      "level": 0
    },
    {
      "x": 5,
      "y": 0,
      "z": -2,
      "name": "Empty",
      "level": 0
    },
    {
      "x": 5,
      "y": 1,
      "z": -2,
      "name": "Empty",
      "level": 0
    },
    {
      "x": 5,
      "y": 2,
      "z": -2,
      "name": "Empty",
      "level": 0
    },
    {
      "x": 5,
      "y": 3,
      "z": -2,
      "name": "Empty",
      "level": 0
    },
    {
      "x": 5,
      "y": 4,
      "z": -2,
      "name": "Empty",
      "level": 0
    },
    {
      "x": 5,
      "y": 5,
      "z": -2,
      "name": "Empty",
      "level": 0
    },
    {
      "x": 5,
      "y": 3,
      "z": -1,
      "name": "Empty",
      "level": 0
    },
    {
      "x": 5,
      "y": 4,
      "z": -1,
      "name": "Empty",
      "level": 0
    },
    {
      "x": 5,
      "y": 4,
      "z": 0,
      "name": "Empty",
      "level": 0
    },
    {
      "x": 5,
      "y": 0,
      "z": 3,
      "name": "Empty",
      "level": 0
    },
    {
      "x": 5,
      "y": 0,
      "z": 4,
      "name": "Empty",
      "level": 0
    }
  ]
}