{
  "version": 8,
  "blockIdVersion": 11,
  "anchorX": 4,
  "anchorY": 1,
  "anchorZ": -5,
  "blocks": [
    {
      "x": 0,
      "y": 1,
      "z": -8,
      "name": "Rock_Sandstone_Brick"
    },
    {
      "x": 0,
      "y": 2,
      "z": -8,
      "name": "Rock_Sandstone_Brick",
      "rotation": 3
    },
    {
      "x": 0,
      "y": 3,
      "z": -8,
      "name": "Rock_Sandstone_Brick",
      "rotation": 3
    },
    {
      "x": 0,
      "y": 1,
      "z": -7,
      "name": "Rock_Sandstone_Brick"
    },
    {
      "x": 0,
      "y": 2,
      "z": -7,
      "name": "Rock_Sandstone_Brick",
      "rotation": 3
    },
    {
      "x": 0,
      "y": 3,
      "z": -7,
      "name": "Rubble_Sandstone",
      "support": 15
    },
    {
      "x": 0,
      "y": 1,
      "z": -6,
      "name": "Rock_Sandstone_Cobble_Stairs",
      "rotation": 3
    },
    {
      "x": 0,
      "y": 7,
      "z": -6,
      "name": "Rock_Sandstone_White_Cobble",
      "support": 15,
      "rotation": 3
    },
    {
      "x": 0,
      "y": 8,
      "z": -6,
      "name": "Rubble_Sandstone"
    },
    {
      "x": 0,
      "y": 1,
      "z": -5,
      "name": "Rock_Sandstone_Cobble_Stairs",
      "rotation": 3
    },
    {
      "x": 0,
      "y": 5,
      "z": -5,
      "name": "Rock_Sandstone_Brick_Half",
      "rotation": 11
    },
    {
      "x": 0,
      "y": 6,
      "z": -5,
      "name": "Rock_Sandstone_Cobble",
      "rotation": 3
    },
    {
      "x": 0,
      "y": 7,
      "z": -5,
      "name": "Rock_Sandstone_White_Cobble",
      "rotation": 3
    },
    {
      "x": 0,
      "y": 8,
      "z": -5,
      "name": "Rock_Sandstone_Brick_Pillar_Base"
    },
    {
      "x": 0,
      "y": 9,
      "z": -5,
      "name": "Rock_Sandstone_Brick_Ornate"
    },
    {
      "x": 0,
      "y": 1,
      "z": -4,
      "name": "Rock_Sandstone_Cobble_Stairs",
      "rotation": 3
    },
    {
      "x": 0,
      "y": 5,
      "z": -4,
      "name": "Rock_Sandstone_Brick_Half",
      "rotation": 11
    },
    {
      "x": 0,
      "y": 6,
      "z": -4,
      "name": "Rock_Sandstone_Cobble",
      "rotation": 3
    },
    {
      "x": 0,
      "y": 7,
      "z": -4,
      "name": "Rock_Sandstone_White_Cobble",
      "rotation": 3
    },
    {
      "x": 0,
      "y": 8,
      "z": -4,
      "name": "Rock_Sandstone_Brick_Pillar_Base"
    },
    {
      "x": 0,
      "y": 9,
      "z": -4,
      "name": "Rock_Sandstone_Brick_Ornate"
    },
    {
      "x": 0,
      "y": 13,
      "z": -4,
      "name": "Soil_Clay_Ocean_Brick_Roof_Hollow",
      "rotation": 3
    },
    {
      "x": 0,
      "y": 1,
      "z": -3,
      "name": "Rock_Sandstone_Cobble_Stairs",
      "rotation": 3
    },
    {
      "x": 0,
      "y": 4,
      "z": -3,
      "name": "Rock_Sandstone_Cobble_Half",
      "rotation": 6
    },
    {
      "x": 0,
      "y": 5,
      "z": -3,
      "name": "Rock_Sandstone_Cobble",
      "rotation": 3
    },
    {
      "x": 0,
      "y": 6,
      "z": -3,
      "name": "Rock_Sandstone_Cobble",
      "rotation": 3
    },
    {
      "x": 0,
      "y": 7,
      "z": -3,
      "name": "Rock_Sandstone_White_Cobble",
      "rotation": 3
    },
    {
      "x": 0,
      "y": 8,
      "z": -3,
      "name": "Rock_Sandstone_Brick_Pillar_Base"
    },
    {
      "x": 0,
      "y": 9,
      "z": -3,
      "name": "Rock_Sandstone_Brick_Ornate"
    },
    {
      "x": 0,
      "y": 10,
      "z": -3,
      "name": "Rock_Sandstone_Brick_Wall",
      "rotation": 1
    },
    {
      "x": 0,
      "y": 13,
      "z": -3,
      "name": "Soil_Clay_Ocean_Brick_Roof_Hollow",
      "rotation": 3
    },
    {
      "x": 0,
      "y": 1,
      "z": -2,
      "name": "Rock_Sandstone_Cobble"
    },
    {
      "x": 0,
      "y": 2,
      "z": -2,
      "name": "Rock_Sandstone_Cobble"
    },
    {
      "x": 0,
      "y": 3,
      "z": -2,
      "name": "Rock_Sandstone_Cobble"
    },
    {
      "x": 0,
      "y": 4,
      "z": -2,
      "name": "Rock_Sandstone_Cobble"
    },
    {
      "x": 0,
      "y": 5,
      "z": -2,
      "name": "Rock_Sandstone_Cobble",
      "rotation": 3
    },
    {
      "x": 0,
      "y": 6,
      "z": -2,
      "name": "Rock_Sandstone_Cobble",
      "rotation": 3
    },
    {
      "x": 0,
      "y": 7,
      "z": -2,
      "name": "Rock_Sandstone_White_Cobble",
      "rotation": 3
    },
    {
      "x": 0,
      "y": 8,
      "z": -2,
      "name": "Rock_Sandstone_Brick_Pillar_Base"
    },
    {
      "x": 0,
      "y": 9,
      "z": -2,
      "name": "Rock_Sandstone_Brick_Ornate"
    },
    {
      "x": 0,
      "y": 10,
      "z": -2,
      "name": "Rock_Sandstone_Brick_Wall",
      "rotation": 1
    },
    {
      "x": 0,
      "y": 13,
      "z": -2,
      "name": "Soil_Clay_Ocean_Brick_Roof_Hollow",
      "rotation": 3
    },
    {
      "x": 0,
      "y": 1,
      "z": -1,
      "name": "Rock_Sandstone_Brick"
    },
    {
      "x": 0,
      "y": 2,
      "z": -1,
      "name": "Rock_Sandstone_Brick",
      "rotation": 3
    },
    {
      "x": 0,
      "y": 3,
      "z": -1,
      "name": "Rock_Sandstone_Brick",
      "rotation": 3
    },
    {
      "x": 0,
      "y": 4,
      "z": -1,
      "name": "Rock_Sandstone_Cobble"
    },
    {
      "x": 0,
      "y": 5,
      "z": -1,
      "name": "Rock_Sandstone_Cobble"
    },
    {
      "x": 0,
      "y": 6,
      "z": -1,
      "name": "Rock_Sandstone_Cobble"
    },
    {
      "x": 0,
      "y": 7,
      "z": -1,
      "name": "Rock_Sandstone_White_Cobble",
      "rotation": 3
    },
    {
      "x": 0,
      "y": 8,
      "z": -1,
      "name": "Rock_Sandstone_Brick_Pillar_Base"
    },
    {
      "x": 0,
      "y": 9,
      "z": -1,
      "name": "Rock_Sandstone_Brick_Half"
    },
    {
      "x": 0,
      "y": 13,
      "z": -1,
      "name": "Soil_Clay_Ocean_Brick_Roof_Hollow",
      "rotation": 3
    },
    {
      "x": 0,
      "y": 13,
      "z": 0,
      "name": "*Soil_Clay_Ocean_Brick_Roof_Hollow_State_Definitions_Corner_Right"
    },
    {
      "x": 1,
      "y": 1,
      "z": -9,
      "name": "Rock_Sandstone_Brick"
    },
    {
      "x": 1,
      "y": 2,
      "z": -9,
      "name": "Rock_Sandstone_Brick",
      "rotation": 2
    },
    {
      "x": 1,
      "y": 3,
      "z": -9,
      "name": "Rock_Sandstone_Brick",
      "rotation": 2
    },
    {
      "x": 1,
      "y": 4,
      "z": -9,
      "name": "Rock_Sandstone_Brick",
      "rotation": 2
    },
    {
      "x": 1,
      "y": 5,
      "z": -9,
      "name": "Rock_Sandstone_Brick",
      "rotation": 2
    },
    {
      "x": 1,
      "y": 6,
      "z": -9,
      "name": "Rock_Sandstone_Brick",
      "rotation": 2
    },
    {
      "x": 1,
      "y": 7,
      "z": -9,
      "name": "Rock_Sandstone_White_Cobble",
      "rotation": 2
    },
    {
      "x": 1,
      "y": 8,
      "z": -9,
      "name": "Rock_Sandstone_Brick_Pillar_Base"
    },
    {
      "x": 1,
      "y": 9,
      "z": -9,
      "name": "Rock_Sandstone_Brick_Half"
    },
    {
      "x": 1,
      "y": 1,
      "z": -8,
      "name": "Rock_Sandstone_Cobble"
    },
    {
      "x": 1,
      "y": 2,
      "z": -8,
      "name": "Rock_Sandstone_Brick",
      "rotation": 3
    },
    {
      "x": 1,
      "y": 3,
      "z": -8,
      "name": "Rock_Sandstone_Brick",
      "rotation": 3
    },
    {
      "x": 1,
      "y": 4,
      "z": -8,
      "name": "Rock_Sandstone_Brick",
      "rotation": 3
    },
    {
      "x": 1,
      "y": 5,
      "z": -8,
      "name": "Rock_Sandstone_Brick",
      "rotation": 3
    },
    {
      "x": 1,
      "y": 6,
      "z": -8,
      "name": "Rock_Sandstone_Cobble",
      "rotation": 3
    },
    {
      "x": 1,
      "y": 7,
      "z": -8,
      "name": "Rock_Sandstone_White_Cobble",
      "rotation": 3
    },
    {
      "x": 1,
      "y": 8,
      "z": -8,
      "name": "Rock_Sandstone_Brick_Pillar_Base"
    },
    {
      "x": 1,
      "y": 9,
      "z": -8,
      "name": "Rock_Sandstone_Brick_Pillar_Middle"
    },
    {
      "x": 1,
      "y": 1,
      "z": -7,
      "name": "Rock_Sandstone_Cobble"
    },
    {
      "x": 1,
      "y": 2,
      "z": -7,
      "name": "Rubble_Sandstone_Medium",
      "support": 15
    },
    {
      "x": 1,
      "y": 6,
      "z": -7,
      "name": "Wood_Drywood_Planks",
      "rotation": 3
    },
    {
      "x": 1,
      "y": 7,
      "z": -7,
      "name": "Soil_Clay_Ocean_Brick_Ornate"
    },
    {
      "x": 1,
      "y": 1,
      "z": -6,
      "name": "Rock_Sandstone_Cobble"
    },
    {
      "x": 1,
      "y": 2,
      "z": -6,
      "name": "Rubble_Sandstone",
      "support": 15
    },
    {
      "x": 1,
      "y": 6,
      "z": -6,
      "name": "Wood_Drywood_Planks",
      "rotation": 3
    },
    {
      "x": 1,
      "y": 7,
      "z": -6,
      "name": "Rubble_Sandstone_Medium",
      "support": 15
    },
    {
      "x": 1,
      "y": 1,
      "z": -5,
      "name": "Rock_Sandstone_Cobble"
    },
    {
      "x": 1,
      "y": 6,
      "z": -5,
      "name": "Wood_Drywood_Beam",
      "rotation": 4
    },
    {
      "x": 1,
      "y": 1,
      "z": -4,
      "name": "Rock_Sandstone_Cobble"
    },
    {
      "x": 1,
      "y": 6,
      "z": -4,
      "name": "Wood_Drywood_Beam",
      "rotation": 4
    },
    {
      "x": 1,
      "y": 13,
      "z": -4,
      "name": "*Rock_Sandstone_Brick_Smooth_Half_State_Definitions_Block",
      "rotation": 3
    },
    {
      "x": 1,
      "y": 1,
      "z": -3,
      "name": "Rock_Sandstone_Cobble"
    },
    {
      "x": 1,
      "y": 6,
      "z": -3,
      "name": "Wood_Drywood_Planks",
      "rotation": 3
    },
    {
      "x": 1,
      "y": 12,
      "z": -3,
      "name": "Rock_Sandstone_Brick_Smooth_Half",
      "rotation": 8
    },
    {
      "x": 1,
      "y": 13,
      "z": -3,
      "name": "*Rock_Sandstone_Brick_Smooth_Half_State_Definitions_Block"
    },
    {
      "x": 1,
      "y": 14,
      "z": -3,
      "name": "Soil_Clay_Ocean_Brick_Ornate"
    },
    {
      "x": 1,
      "y": 1,
      "z": -2,
      "name": "Rock_Sandstone_Cobble"
    },
    {
      "x": 1,
      "y": 6,
      "z": -2,
      "name": "Wood_Drywood_Planks",
      "support": 15,
      "rotation": 3
    },
    {
      "x": 1,
      "y": 7,
      "z": -2,
      "name": "Rubble_Sandstone"
    },
    {
      "x": 1,
      "y": 12,
      "z": -2,
      "name": "Rock_Sandstone_Brick_Stairs",
      "rotation": 8
    },
    {
      "x": 1,
      "y": 13,
      "z": -2,
      "name": "Rock_Sandstone_Brick_Ornate",
      "rotation": 3
    },
    {
      "x": 1,
      "y": 14,
      "z": -2,
      "name": "Soil_Clay_Ocean_Brick_Roof",
      "rotation": 3
    },
    {
      "x": 1,
      "y": 1,
      "z": -1,
      "name": "Rock_Sandstone_Cobble"
    },
    {
      "x": 1,
      "y": 2,
      "z": -1,
      "name": "Rock_Sandstone_Brick",
      "rotation": 3
    },
    {
      "x": 1,
      "y": 3,
      "z": -1,
      "name": "Rock_Sandstone_Brick",
      "rotation": 3
    },
    {
      "x": 1,
      "y": 4,
      "z": -1,
      "name": "Rock_Sandstone_Brick",
      "rotation": 3
    },
    {
      "x": 1,
      "y": 5,
      "z": -1,
      "name": "Rock_Sandstone_Cobble",
      "rotation": 3
    },
    {
      "x": 1,
      "y": 6,
      "z": -1,
      "name": "Rock_Sandstone_Cobble",
      "rotation": 3
    },
    {
      "x": 1,
      "y": 7,
      "z": -1,
      "name": "Rock_Sandstone_White_Cobble",
      "rotation": 3
    },
    {
      "x": 1,
      "y": 8,
      "z": -1,
      "name": "Rock_Sandstone_Brick_Pillar_Base"
    },
    {
      "x": 1,
      "y": 9,
      "z": -1,
      "name": "Rock_Sandstone_Brick_Pillar_Middle"
    },
    {
      "x": 1,
      "y": 10,
      "z": -1,
      "name": "Rock_Sandstone_Brick_Pillar_Middle"
    },
    {
      "x": 1,
      "y": 11,
      "z": -1,
      "name": "Rock_Sandstone_Brick_Pillar_Middle"
    },
    {
      "x": 1,
      "y": 12,
      "z": -1,
      "name": "Rock_Sandstone_Brick_Ornate"
    },
    {
      "x": 1,
      "y": 13,
      "z": -1,
      "name": "Rock_Sandstone_Brick_Ornate",
      "rotation": 3
    },
    {
      "x": 1,
      "y": 14,
      "z": -1,
      "name": "*Soil_Clay_Ocean_Brick_Roof_State_Definitions_Corner_Right"
    },
    {
      "x": 1,
      "y": 1,
      "z": 0,
      "name": "Rock_Sandstone_Brick"
    },
    {
      "x": 1,
      "y": 2,
      "z": 0,
      "name": "Rock_Sandstone_Brick"
    },
    {
      "x": 1,
      "y": 3,
      "z": 0,
      "name": "Rock_Sandstone_Brick"
    },
    {
      "x": 1,
      "y": 4,
      "z": 0,
      "name": "Rock_Sandstone_Brick"
    },
    {
      "x": 1,
      "y": 5,
      "z": 0,
      "name": "Rock_Sandstone_Brick"
    },
    {
      "x": 1,
      "y": 6,
      "z": 0,
      "name": "Rock_Sandstone_Cobble"
    },
    {
      "x": 1,
      "y": 7,
      "z": 0,
      "name": "Rock_Sandstone_White_Cobble"
    },
    {
      "x": 1,
      "y": 8,
      "z": 0,
      "name": "Rock_Sandstone_Brick_Pillar_Base"
    },
    {
      "x": 1,
      "y": 9,
      "z": 0,
      "name": "Rock_Sandstone_Brick_Half"
    },
    {
      "x": 1,
      "y": 13,
      "z": 0,
      "name": "Soil_Clay_Ocean_Brick_Roof_Hollow"
    },
    {
      "x": 2,
      "y": 1,
      "z": -9,
      "name": "Rock_Sandstone_Brick"
    },
    {
      "x": 2,
      "y": 2,
      "z": -9,
      "name": "Rock_Sandstone_Brick",
      "rotation": 2
    },
    {
      "x": 2,
      "y": 3,
      "z": -9,
      "name": "Rock_Sandstone_Cobble"
    },
    {
      "x": 2,
      "y": 4,
      "z": -9,
      "name": "Rock_Sandstone_Cobble"
    },
    {
      "x": 2,
      "y": 5,
      "z": -9,
      "name": "Rock_Sandstone_Cobble",
      "rotation": 2
    },
    {
      "x": 2,
      "y": 6,
      "z": -9,
      "name": "Rock_Sandstone_Cobble",
      "rotation": 2
    },
    {
      "x": 2,
      "y": 7,
      "z": -9,
      "name": "Rock_Sandstone_White_Cobble",
      "rotation": 2
    },
    {
      "x": 2,
      "y": 8,
      "z": -9,
      "name": "Rock_Sandstone_Brick_Pillar_Base"
    },
    {
      "x": 2,
      "y": 9,
      "z": -9,
      "name": "Rock_Sandstone_Brick_Ornate"
    },
    {
      "x": 2,
      "y": 10,
      "z": -9,
      "name": "Rock_Sandstone_Brick_Wall"
    },
    {
      "x": 2,
      "y": 1,
      "z": -8,
      "name": "Rock_Sandstone_Cobble"
    },
    {
      "x": 2,
      "y": 2,
      "z": -8,
      "name": "Rubble_Sandstone_Medium",
      "support": 15
    },
    {
      "x": 2,
      "y": 6,
      "z": -8,
      "name": "Wood_Drywood_Planks",
      "rotation": 2
    },
    {
      "x": 2,
      "y": 7,
      "z": -8,
      "name": "Soil_Clay_Ocean_Brick_Half",
      "rotation": 4
    },
    {
      "x": 2,
      "y": 1,
      "z": -7,
      "name": "Rock_Sandstone_Cobble"
    },
    {
      "x": 2,
      "y": 2,
      "z": -7,
      "name": "Rubble_Sandstone",
      "support": 15
    },
    {
      "x": 2,
      "y": 6,
      "z": -7,
      "name": "Wood_Drywood_Planks"
    },
    {
      "x": 2,
      "y": 1,
      "z": -6,
      "name": "Rock_Sandstone_Cobble"
    },
    {
      "x": 2,
      "y": 6,
      "z": -6,
      "name": "Wood_Drywood_Planks"
    },
    {
      "x": 2,
      "y": 1,
      "z": -5,
      "name": "Rock_Sandstone_Cobble"
    },
    {
      "x": 2,
      "y": 1,
      "z": -4,
      "name": "Rock_Sandstone_Cobble"
    },
    {
      "x": 2,
      "y": 6,
      "z": -4,
      "name": "Wood_Drywood_Beam",
      "rotation": 4
    },
    {
      "x": 2,
      "y": 1,
      "z": -3,
      "name": "Rock_Sandstone_Cobble"
    },
    {
      "x": 2,
      "y": 6,
      "z": -3,
      "name": "Wood_Drywood_Planks"
    },
    {
      "x": 2,
      "y": 1,
      "z": -2,
      "name": "Rock_Sandstone_Cobble"
    },
    {
      "x": 2,
      "y": 6,
      "z": -2,
      "name": "Wood_Drywood_Planks"
    },
    {
      "x": 2,
      "y": 13,
      "z": -2,
      "name": "Rock_Sandstone_Brick",
      "rotation": 3
    },
    {
      "x": 2,
      "y": 14,
      "z": -2,
      "name": "Soil_Clay_Ocean_Brick_Ornate",
      "rotation": 3
    },
    {
      "x": 2,
      "y": 15,
      "z": -2,
      "name": "Soil_Clay_Ocean_Brick_Half"
    },
    {
      "x": 2,
      "y": 1,
      "z": -1,
      "name": "Rock_Sandstone_Cobble"
    },
    {
      "x": 2,
      "y": 2,
      "z": -1,
      "name": "Deco_Pot_Clay_Broken"
    },
    {
      "x": 2,
      "y": 6,
      "z": -1,
      "name": "Wood_Drywood_Planks"
    },
    {
      "x": 2,
      "y": 12,
      "z": -1,
      "name": "Rock_Sandstone_Brick_Stairs",
      "rotation": 11
    },
    {
      "x": 2,
      "y": 13,
      "z": -1,
      "name": "Rock_Sandstone_Brick_Ornate",
      "rotation": 3
    },
    {
      "x": 2,
      "y": 14,
      "z": -1,
      "name": "Soil_Clay_Ocean_Brick_Roof"
    },
    {
      "x": 2,
      "y": 1,
      "z": 0,
      "name": "Rock_Sandstone_Brick"
    },
    {
      "x": 2,
      "y": 2,
      "z": 0,
      "name": "Rock_Sandstone_Brick"
    },
    {
      "x": 2,
      "y": 3,
      "z": 0,
      "name": "Rock_Sandstone_Brick"
    },
    {
      "x": 2,
      "y": 4,
      "z": 0,
      "name": "Rock_Sandstone_Brick"
    },
    {
      "x": 2,
      "y": 5,
      "z": 0,
      "name": "Rock_Sandstone_Brick"
    },
    {
      "x": 2,
      "y": 6,
      "z": 0,
      "name": "Rock_Sandstone_Brick"
    },
    {
      "x": 2,
      "y": 7,
      "z": 0,
      "name": "Rock_Sandstone_White_Cobble"
    },
    {
      "x": 2,
      "y": 8,
      "z": 0,
      "name": "Rock_Sandstone_Brick_Pillar_Base"
    },
    {
      "x": 2,
      "y": 9,
      "z": 0,
      "name": "Rock_Sandstone_Brick_Ornate"
    },
    {
      "x": 2,
      "y": 10,
      "z": 0,
      "name": "Rock_Sandstone_Brick_Wall"
    },
    {
      "x": 2,
      "y": 13,
      "z": 0,
      "name": "Soil_Clay_Ocean_Brick_Roof_Hollow"
    },
    {
      "x": 3,
      "y": 1,
      "z": -9,
      "name": "Rock_Sandstone_Cobble_Stairs",
      "rotation": 2
    },
    {
      "x": 3,
      "y": 4,
      "z": -9,
      "name": "Rock_Sandstone_Cobble_Half",
      "rotation": 5
    },
    {
      "x": 3,
      "y": 5,
      "z": -9,
      "name": "Rock_Sandstone_Cobble",
      "rotation": 2
    },
    {
      "x": 3,
      "y": 6,
      "z": -9,
      "name": "Rock_Sandstone_Cobble",
      "rotation": 2
    },
    {
      "x": 3,
      "y": 7,
      "z": -9,
      "name": "Rock_Sandstone_White_Cobble",
      "rotation": 2
    },
    {
      "x": 3,
      "y": 8,
      "z": -9,
      "name": "Rock_Sandstone_Brick_Pillar_Base"
    },
    {
      "x": 3,
      "y": 9,
      "z": -9,
      "name": "Rock_Sandstone_Brick_Ornate"
    },
    {
      "x": 3,
      "y": 10,
      "z": -9,
      "name": "Rock_Sandstone_Brick_Wall"
    },
    {
      "x": 3,
      "y": 1,
      "z": -8,
      "name": "Rock_Sandstone_Cobble"
    },
    {
      "x": 3,
      "y": 6,
      "z": -8,
      "name": "Wood_Drywood_Planks",
      "rotation": 2
    },
    {
      "x": 3,
      "y": 13,
      "z": -8,
      "name": "*Rock_Sandstone_Brick_Smooth_Half_State_Definitions_Block",
      "rotation": 8
    },
    {
      "x": 3,
      "y": 1,
      "z": -7,
      "name": "Rock_Sandstone_Cobble"
    },
    {
      "x": 3,
      "y": 2,
      "z": -7,
      "name": "Wood_Sticks",
      "support": 15
    },
    {
      "x": 3,
      "y": 6,
      "z": -7,
      "name": "Wood_Drywood_Planks"
    },
    {
      "x": 3,
      "y": 13,
      "z": -7,
      "name": "Soil_Clay_Ocean_Stalactite_Small",
      "rotation": 8
    },
    {
      "x": 3,
      "y": 14,
      "z": -7,
      "name": "Soil_Clay_Ocean_Brick_Ornate"
    },
    {
      "x": 3,
      "y": 15,
      "z": -7,
      "name": "Soil_Clay_Ocean_Brick_Half",
      "rotation": 6
    },
    {
      "x": 3,
      "y": 1,
      "z": -6,
      "name": "Rock_Sandstone_Cobble"
    },
    {
      "x": 3,
      "y": 2,
      "z": -6,
      "name": "Wood_Dry_Branch_Long",
      "support": 15
    },
    {
      "x": 3,
      "y": 3,
      "z": -6,
      "name": "Wood_Drywood_Beam"
    },
    {
      "x": 3,
      "y": 4,
      "z": -6,
      "name": "Wood_Drywood_Beam"
    },
    {
      "x": 3,
      "y": 6,
      "z": -6,
      "name": "Wood_Drywood_Beam",
      "rotation": 4
    },
    {
      "x": 3,
      "y": 15,
      "z": -6,
      "name": "Soil_Clay_Ocean_Brick_Ornate"
    },
    {
      "x": 3,
      "y": 16,
      "z": -6,
      "name": "Soil_Clay_Ocean_Brick_Half"
    },
    {
      "x": 3,
      "y": 1,
      "z": -5,
      "name": "Rock_Sandstone_Cobble"
    },
    {
      "x": 3,
      "y": 15,
      "z": -5,
      "name": "Soil_Clay_Ocean_Brick_Ornate"
    },
    {
      "x": 3,
      "y": 16,
      "z": -5,
      "name": "Soil_Clay_Ocean_Brick_Smooth"
    },
    {
      "x": 3,
      "y": 17,
      "z": -5,
      "name": "Soil_Clay_Ocean_Brick_Half",
      "rotation": 7
    },
    {
      "x": 3,
      "y": 1,
      "z": -4,
      "name": "Rock_Sandstone_Cobble"
    },
    {
      "x": 3,
      "y": 6,
      "z": -4,
      "name": "Wood_Drywood_Beam",
      "rotation": 4
    },
    {
      "x": 3,
      "y": 15,
      "z": -4,
      "name": "Soil_Clay_Ocean_Brick_Ornate"
    },
    {
      "x": 3,
      "y": 16,
      "z": -4,
      "name": "Soil_Clay_Ocean_Brick_Smooth"
    },
    {
      "x": 3,
      "y": 17,
      "z": -4,
      "name": "Soil_Clay_Ocean_Brick_Half",
      "rotation": 7
    },
    {
      "x": 3,
      "y": 1,
      "z": -3,
      "name": "Rock_Sandstone_Cobble"
    },
    {
      "x": 3,
      "y": 2,
      "z": -3,
      "name": "Wood_Dry_Branch_Long",
      "support": 15
    },
    {
      "x": 3,
      "y": 3,
      "z": -3,
      "name": "Wood_Drywood_Beam"
    },
    {
      "x": 3,
      "y": 4,
      "z": -3,
      "name": "Wood_Drywood_Beam",
      "support": 15
    },
    {
      "x": 3,
      "y": 5,
      "z": -3,
      "name": "Wood_Dry_Branch_Long"
    },
    {
      "x": 3,
      "y": 6,
      "z": -3,
      "name": "Wood_Drywood_Planks"
    },
    {
      "x": 3,
      "y": 15,
      "z": -3,
      "name": "Soil_Clay_Ocean_Brick_Ornate"
    },
    {
      "x": 3,
      "y": 16,
      "z": -3,
      "name": "Soil_Clay_Ocean_Brick_Half"
    },
    {
      "x": 3,
      "y": 1,
      "z": -2,
      "name": "Rock_Sandstone_Cobble"
    },
    {
      "x": 3,
      "y": 6,
      "z": -2,
      "name": "Wood_Drywood_Planks"
    },
    {
      "x": 3,
      "y": 13,
      "z": -2,
      "name": "*Rock_Sandstone_Brick_Smooth_Half_State_Definitions_Block"
    },
    {
      "x": 3,
      "y": 14,
      "z": -2,
      "name": "Soil_Clay_Ocean_Brick_Ornate"
    },
    {
      "x": 3,
      "y": 15,
      "z": -2,
      "name": "Soil_Clay_Ocean_Brick_Half",
      "rotation": 4
    },
    {
      "x": 3,
      "y": 1,
      "z": -1,
      "name": "Rock_Sandstone_Cobble"
    },
    {
      "x": 3,
      "y": 6,
      "z": -1,
      "name": "Wood_Drywood_Planks"
    },
    {
      "x": 3,
      "y": 7,
      "z": -1,
      "name": "Furniture_Ancient_Pot"
    },
    {
      "x": 3,
      "y": 12,
      "z": -1,
      "name": "Rock_Sandstone_Brick_Smooth_Half",
      "rotation": 8
    },
    {
      "x": 3,
      "y": 13,
      "z": -1,
      "name": "Rock_Sandstone_Brick_Ornate"
    },
    {
      "x": 3,
      "y": 14,
      "z": -1,
      "name": "Soil_Clay_Ocean_Brick_Ornate"
    },
    {
      "x": 3,
      "y": 1,
      "z": 0,
      "name": "Rock_Sandstone_Brick"
    },
    {
      "x": 3,
      "y": 2,
      "z": 0,
      "name": "Rubble_Sandstone",
      "support": 15
    },
    {
      "x": 3,
      "y": 5,
      "z": 0,
      "name": "Rock_Sandstone_Cobble"
    },
    {
      "x": 3,
      "y": 6,
      "z": 0,
      "name": "Rock_Sandstone_Brick"
    },
    {
      "x": 3,
      "y": 7,
      "z": 0,
      "name": "Rock_Sandstone_White_Cobble"
    },
    {
      "x": 3,
      "y": 8,
      "z": 0,
      "name": "Rock_Sandstone_Brick_Pillar_Base"
    },
    {
      "x": 3,
      "y": 9,
      "z": 0,
      "name": "Rock_Sandstone_Brick_Ornate"
    },
    {
      "x": 3,
      "y": 10,
      "z": 0,
      "name": "Rock_Sandstone_Brick_Wall"
    },
    {
      "x": 3,
      "y": 13,
      "z": 0,
      "name": "Soil_Clay_Ocean_Brick_Roof_Hollow"
    },
    {
      "x": 4,
      "y": 1,
      "z": -9,
      "name": "Rock_Sandstone_Cobble_Stairs",
      "rotation": 2
    },
    {
      "x": 4,
      "y": 5,
      "z": -9,
      "name": "Rock_Sandstone_Brick_Half",
      "rotation": 10
    },
    {
      "x": 4,
      "y": 6,
      "z": -9,
      "name": "Rock_Sandstone_Cobble",
      "rotation": 2
    },
    {
      "x": 4,
      "y": 7,
      "z": -9,
      "name": "Rock_Sandstone_White_Cobble",
      "rotation": 2
    },
    {
      "x": 4,
      "y": 8,
      "z": -9,
      "name": "Rock_Sandstone_Brick_Pillar_Base"
    },
    {
      "x": 4,
      "y": 9,
      "z": -9,
      "name": "Rock_Sandstone_Brick_Ornate"
    },
    {
      "x": 4,
      "y": 10,
      "z": -9,
      "name": "Rock_Sandstone_Brick_Wall"
    },
    {
      "x": 4,
      "y": 13,
      "z": -9,
      "name": "Soil_Clay_Ocean_Brick_Roof_Hollow",
      "rotation": 2
    },
    {
      "x": 4,
      "y": 1,
      "z": -8,
      "name": "Rock_Sandstone_Cobble"
    },
    {
      "x": 4,
      "y": 6,
      "z": -8,
      "name": "Wood_Drywood_Planks",
      "rotation": 2
    },
    {
      "x": 4,
      "y": 13,
      "z": -8,
      "name": "*Rock_Sandstone_Brick_Smooth_Half_State_Definitions_Block",
      "rotation": 2
    },
    {
      "x": 4,
      "y": 14,
      "z": -8,
      "name": "Soil_Clay_Ocean_Brick_Ornate"
    },
    {
      "x": 4,
      "y": 1,
      "z": -7,
      "name": "Rock_Sandstone_Cobble"
    },
    {
      "x": 4,
      "y": 6,
      "z": -7,
      "name": "Wood_Drywood_Planks"
    },
    {
      "x": 4,
      "y": 14,
      "z": -7,
      "name": "Soil_Clay_Ocean_Brick_Ornate"
    },
    {
      "x": 4,
      "y": 15,
      "z": -7,
      "name": "Soil_Clay_Ocean_Brick_Smooth"
    },
    {
      "x": 4,
      "y": 1,
      "z": -6,
      "name": "Rock_Sandstone_Cobble"
    },
    {
      "x": 4,
      "y": 15,
      "z": -6,
      "name": "Soil_Clay_Ocean_Brick_Ornate"
    },
    {
      "x": 4,
      "y": 16,
      "z": -6,
      "name": "Soil_Clay_Ocean_Brick_Smooth"
    },
    {
      "x": 4,
      "y": 17,
      "z": -6,
      "name": "Soil_Clay_Ocean_Brick_Half",
      "rotation": 6
    },
    {
      "x": 4,
      "y": 1,
      "z": -5,
      "name": "Rock_Sandstone_Cobble"
    },
    {
      "x": 4,
      "y": 17,
      "z": -5,
      "name": "Soil_Clay_Ocean_Brick_Smooth"
    },
    {
      "x": 4,
      "y": 18,
      "z": -5,
      "name": "Soil_Clay_Ocean_Brick_Half"
    },
    {
      "x": 4,
      "y": 1,
      "z": -4,
      "name": "Rock_Sandstone_Cobble"
    },
    {
      "x": 4,
      "y": 17,
      "z": -4,
      "name": "Soil_Clay_Ocean_Brick_Smooth"
    },
    {
      "x": 4,
      "y": 18,
      "z": -4,
      "name": "Soil_Clay_Ocean_Brick_Half"
    },
    {
      "x": 4,
      "y": 1,
      "z": -3,
      "name": "Rock_Sandstone_Cobble"
    },
    {
      "x": 4,
      "y": 14,
      "z": -3,
      "name": "Soil_Clay_Ocean_Stalactite_Small",
      "rotation": 8
    },
    {
      "x": 4,
      "y": 15,
      "z": -3,
      "name": "Soil_Clay_Ocean_Brick_Ornate"
    },
    {
      "x": 4,
      "y": 16,
      "z": -3,
      "name": "Soil_Clay_Ocean_Brick_Smooth"
    },
    {
      "x": 4,
      "y": 17,
      "z": -3,
      "name": "Soil_Clay_Ocean_Brick_Half",
      "rotation": 4
    },
    {
      "x": 4,
      "y": 1,
      "z": -2,
      "name": "Rock_Sandstone_Cobble"
    },
    {
      "x": 4,
      "y": 6,
      "z": -2,
      "name": "Wood_Drywood_Planks"
    },
    {
      "x": 4,
      "y": 13,
      "z": -2,
      "name": "*Rock_Sandstone_Brick_Smooth_Half_State_Definitions_Block"
    },
    {
      "x": 4,
      "y": 14,
      "z": -2,
      "name": "Soil_Clay_Ocean_Brick_Ornate"
    },
    {
      "x": 4,
      "y": 15,
      "z": -2,
      "name": "Soil_Clay_Ocean_Brick_Smooth"
    },
    {
      "x": 4,
      "y": 1,
      "z": -1,
      "name": "Rock_Sandstone_Cobble"
    },
    {
      "x": 4,
      "y": 6,
      "z": -1,
      "name": "Wood_Drywood_Planks"
    },
    {
      "x": 4,
      "y": 7,
      "z": -1,
      "name": "Deco_Pot_Clay_Broken"
    },
    {
      "x": 4,
      "y": 13,
      "z": -1,
      "name": "Rock_Sandstone_Brick_Ornate"
    },
    {
      "x": 4,
      "y": 14,
      "z": -1,
      "name": "Soil_Clay_Ocean_Brick_Ornate"
    },
    {
      "x": 4,
      "y": 1,
      "z": 0,
      "name": "Rubble_Sandstone_Medium",
      "support": 15
    },
    {
      "x": 4,
      "y": 4,
      "z": 0,
      "name": "Rock_Sandstone_Brick"
    },
    {
      "x": 4,
      "y": 5,
      "z": 0,
      "name": "Rock_Sandstone_Cobble"
    },
    {
      "x": 4,
      "y": 6,
      "z": 0,
      "name": "Rock_Sandstone_Cobble"
    },
    {
      "x": 4,
      "y": 7,
      "z": 0,
      "name": "Rock_Sandstone_White_Cobble"
    },
    {
      "x": 4,
      "y": 8,
      "z": 0,
      "name": "Rock_Sandstone_Brick_Pillar_Base"
    },
    {
      "x": 4,
      "y": 9,
      "z": 0,
      "name": "Rock_Sandstone_Brick_Ornate"
    },
    {
      "x": 4,
      "y": 10,
      "z": 0,
      "name": "Rock_Sandstone_Brick_Wall"
    },
    {
      "x": 4,
      "y": 13,
      "z": 0,
      "name": "Soil_Clay_Ocean_Brick_Roof_Hollow"
    },
    {
      "x": 5,
      "y": 1,
      "z": -9,
      "name": "Rock_Sandstone_Cobble_Stairs",
      "rotation": 2
    },
    {
      "x": 5,
      "y": 5,
      "z": -9,
      "name": "Rock_Sandstone_Brick_Half",
      "rotation": 10
    },
    {
      "x": 5,
      "y": 6,
      "z": -9,
      "name": "Rock_Sandstone_Cobble",
      "rotation": 2
    },
    {
      "x": 5,
      "y": 7,
      "z": -9,
      "name": "Rock_Sandstone_White_Cobble",
      "rotation": 2
    },
    {
      "x": 5,
      "y": 8,
      "z": -9,
      "name": "Rock_Sandstone_Brick_Pillar_Base"
    },
    {
      "x": 5,
      "y": 13,
      "z": -9,
      "name": "Soil_Clay_Ocean_Brick_Roof_Hollow",
      "rotation": 2
    },
    {
      "x": 5,
      "y": 1,
      "z": -8,
      "name": "Rock_Sandstone_Cobble"
    },
    {
      "x": 5,
      "y": 6,
      "z": -8,
      "name": "Wood_Drywood_Planks"
    },
    {
      "x": 5,
      "y": 7,
      "z": -8,
      "name": "Rubble_Sandstone",
      "support": 15
    },
    {
      "x": 5,
      "y": 13,
      "z": -8,
      "name": "*Rock_Sandstone_Brick_Smooth_Half_State_Definitions_Block",
      "rotation": 2
    },
    {
      "x": 5,
      "y": 14,
      "z": -8,
      "name": "Soil_Clay_Ocean_Brick_Ornate"
    },
    {
      "x": 5,
      "y": 1,
      "z": -7,
      "name": "Rock_Sandstone_Cobble"
    },
    {
      "x": 5,
      "y": 6,
      "z": -7,
      "name": "Wood_Drywood_Planks"
    },
    {
      "x": 5,
      "y": 14,
      "z": -7,
      "name": "Soil_Clay_Ocean_Brick_Ornate"
    },
    {
      "x": 5,
      "y": 15,
      "z": -7,
      "name": "Soil_Clay_Ocean_Brick_Smooth"
    },
    {
      "x": 5,
      "y": 1,
      "z": -6,
      "name": "Rock_Sandstone_Cobble"
    },
    {
      "x": 5,
      "y": 15,
      "z": -6,
      "name": "Soil_Clay_Ocean_Brick_Ornate"
    },
    {
      "x": 5,
      "y": 16,
      "z": -6,
      "name": "Soil_Clay_Ocean_Brick_Smooth"
    },
    {
      "x": 5,
      "y": 17,
      "z": -6,
      "name": "Soil_Clay_Ocean_Brick_Half",
      "rotation": 6
    },
    {
      "x": 5,
      "y": 1,
      "z": -5,
      "name": "Rock_Sandstone_Cobble"
    },
    {
      "x": 5,
      "y": 2,
      "z": -5,
      "name": "Wood_Sticks",
      "support": 15
    },
    {
      "x": 5,
      "y": 17,
      "z": -5,
      "name": "Soil_Clay_Ocean_Brick_Smooth"
    },
    {
      "x": 5,
      "y": 18,
      "z": -5,
      "name": "Soil_Clay_Ocean_Brick_Half"
    },
    {
      "x": 5,
      "y": 1,
      "z": -4,
      "name": "Rock_Sandstone_Cobble"
    },
    {
      "x": 5,
      "y": 17,
      "z": -4,
      "name": "Soil_Clay_Ocean_Brick_Smooth"
    },
    {
      "x": 5,
      "y": 18,
      "z": -4,
      "name": "Soil_Clay_Ocean_Brick_Half"
    },
    {
      "x": 5,
      "y": 1,
      "z": -3,
      "name": "Rock_Sandstone_Cobble"
    },
    {
      "x": 5,
      "y": 15,
      "z": -3,
      "name": "Soil_Clay_Ocean_Brick_Ornate"
    },
    {
      "x": 5,
      "y": 16,
      "z": -3,
      "name": "Soil_Clay_Ocean_Brick_Smooth"
    },
    {
      "x": 5,
      "y": 17,
      "z": -3,
      "name": "Soil_Clay_Ocean_Brick_Half",
      "rotation": 4
    },
    {
      "x": 5,
      "y": 1,
      "z": -2,
      "name": "Rock_Sandstone_Cobble"
    },
    {
      "x": 5,
      "y": 6,
      "z": -2,
      "name": "Wood_Drywood_Stairs",
      "rotation": 11
    },
    {
      "x": 5,
      "y": 13,
      "z": -2,
      "name": "*Rock_Sandstone_Brick_Smooth_Half_State_Definitions_Block"
    },
    {
      "x": 5,
      "y": 14,
      "z": -2,
      "name": "Soil_Clay_Ocean_Brick_Ornate"
    },
    {
      "x": 5,
      "y": 15,
      "z": -2,
      "name": "Soil_Clay_Ocean_Brick_Smooth"
    },
    {
      "x": 5,
      "y": 1,
      "z": -1,
      "name": "Rock_Sandstone_Cobble"
    },
    {
      "x": 5,
      "y": 2,
      "z": -1,
      "name": "Wood_Drywood_Stairs",
      "rotation": 3
    },
    {
      "x": 5,
      "y": 6,
      "z": -1,
      "name": "Wood_Drywood_Stairs",
      "rotation": 11
    },
    {
      "x": 5,
      "y": 13,
      "z": -1,
      "name": "Rock_Sandstone_Brick_Ornate"
    },
    {
      "x": 5,
      "y": 14,
      "z": -1,
      "name": "Soil_Clay_Ocean_Brick_Ornate"
    },
    {
      "x": 5,
      "y": 1,
      "z": 0,
      "name": "Rock_Sandstone_Brick"
    },
    {
      "x": 5,
      "y": 2,
      "z": 0,
      "name": "Rock_Sandstone_Brick"
    },
    {
      "x": 5,
      "y": 3,
      "z": 0,
      "name": "Rock_Sandstone_Brick"
    },
    {
      "x": 5,
      "y": 4,
      "z": 0,
      "name": "Rock_Sandstone_Brick"
    },
    {
      "x": 5,
      "y": 5,
      "z": 0,
      "name": "Rock_Sandstone_Cobble"
    },
    {
      "x": 5,
      "y": 6,
      "z": 0,
      "name": "Rock_Sandstone_Cobble"
    },
    {
      "x": 5,
      "y": 7,
      "z": 0,
      "name": "Rock_Sandstone_White_Cobble"
    },
    {
      "x": 5,
      "y": 8,
      "z": 0,
      "name": "Rock_Sandstone_Brick_Pillar_Base"
    },
    {
      "x": 5,
      "y": 9,
      "z": 0,
      "name": "Rock_Sandstone_Brick_Ornate"
    },
    {
      "x": 5,
      "y": 10,
      "z": 0,
      "name": "Rock_Sandstone_Brick_Wall"
    },
    {
      "x": 5,
      "y": 13,
      "z": 0,
      "name": "Soil_Clay_Ocean_Brick_Roof_Hollow"
    },
    {
      "x": 6,
      "y": 1,
      "z": -9,
      "name": "Rock_Sandstone_Cobble_Stairs",
      "rotation": 2
    },
    {
      "x": 6,
      "y": 4,
      "z": -9,
      "name": "Rock_Sandstone_Brick_Half",
      "rotation": 7
    },
    {
      "x": 6,
      "y": 5,
      "z": -9,
      "name": "Rock_Sandstone_Brick",
      "rotation": 2
    },
    {
      "x": 6,
      "y": 6,
      "z": -9,
      "name": "Rock_Sandstone_Brick",
      "rotation": 2
    },
    {
      "x": 6,
      "y": 7,
      "z": -9,
      "name": "Rock_Sandstone_White_Cobble",
      "rotation": 2
    },
    {
      "x": 6,
      "y": 8,
      "z": -9,
      "name": "Rock_Sandstone_Brick_Pillar_Base"
    },
    {
      "x": 6,
      "y": 13,
      "z": -9,
      "name": "Soil_Clay_Ocean_Brick_Roof_Hollow",
      "rotation": 2
    },
    {
      "x": 6,
      "y": 1,
      "z": -8,
      "name": "Rock_Sandstone_Cobble"
    },
    {
      "x": 6,
      "y": 2,
      "z": -8,
      "name": "Rubble_Sandstone",
      "support": 15
    },
    {
      "x": 6,
      "y": 6,
      "z": -8,
      "name": "Wood_Drywood_Planks",
      "rotation": 2
    },
    {
      "x": 6,
      "y": 7,
      "z": -8,
      "name": "Furniture_Ancient_Pot",
      "rotation": 2
    },
    {
      "x": 6,
      "y": 12,
      "z": -8,
      "name": "Rock_Sandstone_Brick_Smooth_Half",
      "rotation": 8
    },
    {
      "x": 6,
      "y": 13,
      "z": -8,
      "name": "*Rock_Sandstone_Brick_Smooth_Half_State_Definitions_Block",
      "rotation": 8
    },
    {
      "x": 6,
      "y": 14,
      "z": -8,
      "name": "Soil_Clay_Ocean_Brick_Ornate"
    },
    {
      "x": 6,
      "y": 1,
      "z": -7,
      "name": "Rock_Sandstone_Cobble"
    },
    {
      "x": 6,
      "y": 6,
      "z": -7,
      "name": "Wood_Drywood_Planks"
    },
    {
      "x": 6,
      "y": 14,
      "z": -7,
      "name": "Soil_Clay_Ocean_Brick_Ornate"
    },
    {
      "x": 6,
      "y": 15,
      "z": -7,
      "name": "Soil_Clay_Ocean_Brick_Half",
      "rotation": 6
    },
    {
      "x": 6,
      "y": 1,
      "z": -6,
      "name": "Rock_Sandstone_Cobble"
    },
    {
      "x": 6,
      "y": 2,
      "z": -6,
      "name": "Wood_Dry_Branch_Long",
      "support": 15
    },
    {
      "x": 6,
      "y": 3,
      "z": -6,
      "name": "Wood_Drywood_Beam"
    },
    {
      "x": 6,
      "y": 5,
      "z": -6,
      "name": "Wood_Drywood_Beam"
    },
    {
      "x": 6,
      "y": 6,
      "z": -6,
      "name": "Wood_Drywood_Planks"
    },
    {
      "x": 6,
      "y": 15,
      "z": -6,
      "name": "Soil_Clay_Ocean_Brick_Ornate"
    },
    {
      "x": 6,
      "y": 16,
      "z": -6,
      "name": "Soil_Clay_Ocean_Brick_Half"
    },
    {
      "x": 6,
      "y": 1,
      "z": -5,
      "name": "Rock_Sandstone_Cobble"
    },
    {
      "x": 6,
      "y": 2,
      "z": -5,
      "name": "Wood_Sticks",
      "support": 15
    },
    {
      "x": 6,
      "y": 15,
      "z": -5,
      "name": "Soil_Clay_Ocean_Brick_Ornate"
    },
    {
      "x": 6,
      "y": 16,
      "z": -5,
      "name": "Soil_Clay_Ocean_Brick_Smooth"
    },
    {
      "x": 6,
      "y": 17,
      "z": -5,
      "name": "Soil_Clay_Ocean_Brick_Half",
      "rotation": 5
    },
    {
      "x": 6,
      "y": 1,
      "z": -4,
      "name": "Rock_Sandstone_Cobble"
    },
    {
      "x": 6,
      "y": 15,
      "z": -4,
      "name": "Soil_Clay_Ocean_Brick_Ornate"
    },
    {
      "x": 6,
      "y": 16,
      "z": -4,
      "name": "Soil_Clay_Ocean_Brick_Smooth"
    },
    {
      "x": 6,
      "y": 17,
      "z": -4,
      "name": "Soil_Clay_Ocean_Brick_Half",
      "rotation": 5
    },
    {
      "x": 6,
      "y": 1,
      "z": -3,
      "name": "Rock_Sandstone_Cobble"
    },
    {
      "x": 6,
      "y": 2,
      "z": -3,
      "name": "Deco_Pot_Clay_Broken"
    },
    {
      "x": 6,
      "y": 15,
      "z": -3,
      "name": "Soil_Clay_Ocean_Brick_Ornate"
    },
    {
      "x": 6,
      "y": 16,
      "z": -3,
      "name": "Soil_Clay_Ocean_Brick_Half"
    },
    {
      "x": 6,
      "y": 1,
      "z": -2,
      "name": "Rock_Sandstone_Cobble"
    },
    {
      "x": 6,
      "y": 3,
      "z": -2,
      "name": "Wood_Drywood_Beam",
      "rotation": 4
    },
    {
      "x": 6,
      "y": 13,
      "z": -2,
      "name": "*Rock_Sandstone_Brick_Smooth_Half_State_Definitions_Block"
    },
    {
      "x": 6,
      "y": 14,
      "z": -2,
      "name": "Soil_Clay_Ocean_Brick_Ornate",
      "rotation": 3
    },
    {
      "x": 6,
      "y": 15,
      "z": -2,
      "name": "Soil_Clay_Ocean_Brick_Half",
      "rotation": 4
    },
    {
      "x": 6,
      "y": 1,
      "z": -1,
      "name": "Rock_Sandstone_Cobble"
    },
    {
      "x": 6,
      "y": 3,
      "z": -1,
      "name": "Wood_Drywood_Stairs",
      "rotation": 3
    },
    {
      "x": 6,
      "y": 12,
      "z": -1,
      "name": "Rock_Sandstone_Brick_Smooth_Half",
      "rotation": 8
    },
    {
      "x": 6,
      "y": 13,
      "z": -1,
      "name": "Rock_Sandstone_Brick_Ornate",
      "rotation": 3
    },
    {
      "x": 6,
      "y": 14,
      "z": -1,
      "name": "Soil_Clay_Ocean_Brick_Ornate",
      "rotation": 3
    },
    {
      "x": 6,
      "y": 1,
      "z": 0,
      "name": "Rock_Sandstone_Brick"
    },
    {
      "x": 6,
      "y": 2,
      "z": 0,
      "name": "Rock_Sandstone_Brick"
    },
    {
      "x": 6,
      "y": 3,
      "z": 0,
      "name": "Rock_Sandstone_Brick"
    },
    {
      "x": 6,
      "y": 4,
      "z": 0,
      "name": "Rock_Sandstone_Cobble"
    },
    {
      "x": 6,
      "y": 5,
      "z": 0,
      "name": "Rock_Sandstone_Cobble"
    },
    {
      "x": 6,
      "y": 6,
      "z": 0,
      "name": "Rock_Sandstone_Cobble"
    },
    {
      "x": 6,
      "y": 7,
      "z": 0,
      "name": "Rock_Sandstone_White_Cobble"
    },
    {
      "x": 6,
      "y": 8,
      "z": 0,
      "name": "Rock_Sandstone_Brick_Pillar_Base"
    },
    {
      "x": 6,
      "y": 9,
      "z": 0,
      "name": "Rock_Sandstone_Brick_Ornate"
    },
    {
      "x": 6,
      "y": 10,
      "z": 0,
      "name": "Rock_Sandstone_Brick_Wall"
    },
    {
      "x": 6,
      "y": 13,
      "z": 0,
      "name": "Soil_Clay_Ocean_Brick_Roof_Hollow"
    },
    {
      "x": 7,
      "y": 1,
      "z": -9,
      "name": "Rock_Sandstone_Brick"
    },
    {
      "x": 7,
      "y": 2,
      "z": -9,
      "name": "Rock_Sandstone_Brick",
      "rotation": 2
    },
    {
      "x": 7,
      "y": 3,
      "z": -9,
      "name": "Rock_Sandstone_Brick",
      "rotation": 2
    },
    {
      "x": 7,
      "y": 4,
      "z": -9,
      "name": "Rock_Sandstone_Brick",
      "rotation": 2
    },
    {
      "x": 7,
      "y": 5,
      "z": -9,
      "name": "Rock_Sandstone_Brick",
      "rotation": 2
    },
    {
      "x": 7,
      "y": 6,
      "z": -9,
      "name": "Rock_Sandstone_Brick",
      "rotation": 2
    },
    {
      "x": 7,
      "y": 7,
      "z": -9,
      "name": "Rock_Sandstone_White_Cobble",
      "rotation": 2
    },
    {
      "x": 7,
      "y": 8,
      "z": -9,
      "name": "Rock_Sandstone_Brick_Pillar_Base"
    },
    {
      "x": 7,
      "y": 9,
      "z": -9,
      "name": "Rock_Sandstone_Brick_Ornate"
    },
    {
      "x": 7,
      "y": 10,
      "z": -9,
      "name": "Rock_Sandstone_Brick_Wall"
    },
    {
      "x": 7,
      "y": 13,
      "z": -9,
      "name": "Soil_Clay_Ocean_Brick_Roof_Hollow",
      "rotation": 2
    },
    {
      "x": 7,
      "y": 1,
      "z": -8,
      "name": "Rock_Sandstone_Cobble"
    },
    {
      "x": 7,
      "y": 2,
      "z": -8,
      "name": "Rubble_Sandstone_Medium"
    },
    {
      "x": 7,
      "y": 6,
      "z": -8,
      "name": "Wood_Drywood_Planks",
      "rotation": 2
    },
    {
      "x": 7,
      "y": 7,
      "z": -8,
      "name": "Rubble_Sandstone_Medium",
      "support": 15
    },
    {
      "x": 7,
      "y": 12,
      "z": -8,
      "name": "Rock_Sandstone_Brick_Stairs",
      "rotation": 9
    },
    {
      "x": 7,
      "y": 13,
      "z": -8,
      "name": "Rock_Sandstone_Brick"
    },
    {
      "x": 7,
      "y": 14,
      "z": -8,
      "name": "Soil_Clay_Ocean_Brick_Roof",
      "rotation": 2
    },
    {
      "x": 7,
      "y": 1,
      "z": -7,
      "name": "Rock_Sandstone_Cobble"
    },
    {
      "x": 7,
      "y": 6,
      "z": -7,
      "name": "Wood_Drywood_Planks"
    },
    {
      "x": 7,
      "y": 7,
      "z": -7,
      "name": "Deco_Pot_Clay_Broken"
    },
    {
      "x": 7,
      "y": 14,
      "z": -7,
      "name": "Soil_Clay_Ocean_Brick_Ornate"
    },
    {
      "x": 7,
      "y": 15,
      "z": -7,
      "name": "Soil_Clay_Ocean_Brick_Half"
    },
    {
      "x": 7,
      "y": 1,
      "z": -6,
      "name": "Rock_Sandstone_Cobble"
    },
    {
      "x": 7,
      "y": 6,
      "z": -6,
      "name": "Wood_Drywood_Planks"
    },
    {
      "x": 7,
      "y": 14,
      "z": -6,
      "name": "Soil_Clay_Ocean_Brick_Ornate"
    },
    {
      "x": 7,
      "y": 15,
      "z": -6,
      "name": "Soil_Clay_Ocean_Brick_Half",
      "rotation": 5
    },
    {
      "x": 7,
      "y": 1,
      "z": -5,
      "name": "Rock_Sandstone_Cobble"
    },
    {
      "x": 7,
      "y": 6,
      "z": -5,
      "name": "Wood_Drywood_Planks"
    },
    {
      "x": 7,
      "y": 14,
      "z": -5,
      "name": "Soil_Clay_Ocean_Brick_Ornate"
    },
    {
      "x": 7,
      "y": 15,
      "z": -5,
      "name": "Soil_Clay_Ocean_Brick_Smooth"
    },
    {
      "x": 7,
      "y": 1,
      "z": -4,
      "name": "Rock_Sandstone_Cobble"
    },
    {
      "x": 7,
      "y": 6,
      "z": -4,
      "name": "Wood_Drywood_Stairs"
    },
    {
      "x": 7,
      "y": 14,
      "z": -4,
      "name": "Soil_Clay_Ocean_Brick_Ornate"
    },
    {
      "x": 7,
      "y": 15,
      "z": -4,
      "name": "Soil_Clay_Ocean_Brick_Smooth"
    },
    {
      "x": 7,
      "y": 1,
      "z": -3,
      "name": "Rock_Sandstone_Cobble"
    },
    {
      "x": 7,
      "y": 2,
      "z": -3,
      "name": "Wood_Dry_Trunk",
      "support": 15
    },
    {
      "x": 7,
      "y": 3,
      "z": -3,
      "name": "Wood_Dry_Trunk",
      "support": 15
    },
    {
      "x": 7,
      "y": 4,
      "z": -3,
      "name": "Wood_Dry_Trunk"
    },
    {
      "x": 7,
      "y": 5,
      "z": -3,
      "name": "Wood_Drywood_Stairs"
    },
    {
      "x": 7,
      "y": 14,
      "z": -3,
      "name": "Soil_Clay_Ocean_Brick_Ornate"
    },
    {
      "x": 7,
      "y": 15,
      "z": -3,
      "name": "Soil_Clay_Ocean_Brick_Half",
      "rotation": 5
    },
    {
      "x": 7,
      "y": 1,
      "z": -2,
      "name": "Rock_Sandstone_Cobble"
    },
    {
      "x": 7,
      "y": 4,
      "z": -2,
      "name": "Wood_Drywood_Stairs",
      "rotation": 3
    },
    {
      "x": 7,
      "y": 13,
      "z": -2,
      "name": "Rock_Sandstone_Brick",
      "rotation": 3
    },
    {
      "x": 7,
      "y": 14,
      "z": -2,
      "name": "Soil_Clay_Ocean_Brick_Ornate",
      "rotation": 3
    },
    {
      "x": 7,
      "y": 15,
      "z": -2,
      "name": "Soil_Clay_Ocean_Brick_Half"
    },
    {
      "x": 7,
      "y": 1,
      "z": -1,
      "name": "Rock_Sandstone_Cobble"
    },
    {
      "x": 7,
      "y": 4,
      "z": -1,
      "name": "Wood_Drywood_Stairs",
      "rotation": 3
    },
    {
      "x": 7,
      "y": 12,
      "z": -1,
      "name": "Rock_Sandstone_Brick_Stairs",
      "rotation": 9
    },
    {
      "x": 7,
      "y": 13,
      "z": -1,
      "name": "Rock_Sandstone_Brick_Ornate",
      "rotation": 3
    },
    {
      "x": 7,
      "y": 14,
      "z": -1,
      "name": "Soil_Clay_Ocean_Brick_Roof"
    },
    {
      "x": 7,
      "y": 1,
      "z": 0,
      "name": "Rock_Sandstone_Brick"
    },
    {
      "x": 7,
      "y": 2,
      "z": 0,
      "name": "Rock_Sandstone_Brick"
    },
    {
      "x": 7,
      "y": 3,
      "z": 0,
      "name": "Rock_Sandstone_Brick"
    },
    {
      "x": 7,
      "y": 4,
      "z": 0,
      "name": "Rock_Sandstone_Brick"
    },
    {
      "x": 7,
      "y": 5,
      "z": 0,
      "name": "Rock_Sandstone_Cobble"
    },
    {
      "x": 7,
      "y": 6,
      "z": 0,
      "name": "Rock_Sandstone_Cobble"
    },
    {
      "x": 7,
      "y": 7,
      "z": 0,
      "name": "Rock_Sandstone_White_Cobble"
    },
    {
      "x": 7,
      "y": 8,
      "z": 0,
      "name": "Rock_Sandstone_Brick_Pillar_Base"
    },
    {
      "x": 7,
      "y": 9,
      "z": 0,
      "name": "Rock_Sandstone_Brick_Ornate"
    },
    {
      "x": 7,
      "y": 10,
      "z": 0,
      "name": "Rock_Sandstone_Brick_Wall"
    },
    {
      "x": 7,
      "y": 13,
      "z": 0,
      "name": "Soil_Clay_Ocean_Brick_Roof_Hollow"
    },
    {
      "x": 8,
      "y": 1,
      "z": -9,
      "name": "Rock_Sandstone_Brick"
    },
    {
      "x": 8,
      "y": 2,
      "z": -9,
      "name": "Rock_Sandstone_Brick",
      "rotation": 2
    },
    {
      "x": 8,
      "y": 3,
      "z": -9,
      "name": "Rock_Sandstone_Brick",
      "rotation": 2
    },
    {
      "x": 8,
      "y": 4,
      "z": -9,
      "name": "Rock_Sandstone_Brick",
      "rotation": 2
    },
    {
      "x": 8,
      "y": 5,
      "z": -9,
      "name": "Rock_Sandstone_Brick",
      "rotation": 2
    },
    {
      "x": 8,
      "y": 6,
      "z": -9,
      "name": "Rock_Sandstone_Cobble",
      "rotation": 2
    },
    {
      "x": 8,
      "y": 7,
      "z": -9,
      "name": "Rock_Sandstone_White_Cobble",
      "rotation": 2
    },
    {
      "x": 8,
      "y": 8,
      "z": -9,
      "name": "Rock_Sandstone_Brick_Pillar_Base"
    },
    {
      "x": 8,
      "y": 9,
      "z": -9,
      "name": "Rock_Sandstone_Brick_Half"
    },
    {
      "x": 8,
      "y": 12,
      "z": -9,
      "name": "Rock_Sandstone_Brick_Wall"
    },
    {
      "x": 8,
      "y": 13,
      "z": -9,
      "name": "Soil_Clay_Ocean_Brick_Roof",
      "rotation": 2
    },
    {
      "x": 8,
      "y": 1,
      "z": -8,
      "name": "Rock_Sandstone_Brick"
    },
    {
      "x": 8,
      "y": 2,
      "z": -8,
      "name": "Rock_Sandstone_Brick",
      "rotation": 1
    },
    {
      "x": 8,
      "y": 3,
      "z": -8,
      "name": "Rock_Sandstone_Brick",
      "rotation": 1
    },
    {
      "x": 8,
      "y": 4,
      "z": -8,
      "name": "Rock_Sandstone_Brick",
      "rotation": 1
    },
    {
      "x": 8,
      "y": 5,
      "z": -8,
      "name": "Rock_Sandstone_Cobble",
      "rotation": 1
    },
    {
      "x": 8,
      "y": 6,
      "z": -8,
      "name": "Rock_Sandstone_Cobble",
      "rotation": 1
    },
    {
      "x": 8,
      "y": 7,
      "z": -8,
      "name": "Rock_Sandstone_White_Cobble",
      "rotation": 1
    },
    {
      "x": 8,
      "y": 8,
      "z": -8,
      "name": "Rock_Sandstone_Brick_Pillar_Base"
    },
    {
      "x": 8,
      "y": 9,
      "z": -8,
      "name": "Rock_Sandstone_Brick_Pillar_Middle"
    },
    {
      "x": 8,
      "y": 10,
      "z": -8,
      "name": "Rock_Sandstone_Brick_Beam"
    },
    {
      "x": 8,
      "y": 11,
      "z": -8,
      "name": "Rock_Sandstone_Brick_Pillar_Middle"
    },
    {
      "x": 8,
      "y": 12,
      "z": -8,
      "name": "Rock_Sandstone_Brick_Ornate"
    },
    {
      "x": 8,
      "y": 13,
      "z": -8,
      "name": "Rock_Sandstone_Brick_Ornate"
    },
    {
      "x": 8,
      "y": 1,
      "z": -7,
      "name": "Rock_Sandstone_Cobble"
    },
    {
      "x": 8,
      "y": 2,
      "z": -7,
      "name": "Rubble_Sandstone",
      "support": 15
    },
    {
      "x": 8,
      "y": 6,
      "z": -7,
      "name": "Wood_Drywood_Planks",
      "support": 15,
      "rotation": 1
    },
    {
      "x": 8,
      "y": 7,
      "z": -7,
      "name": "Rubble_Sandstone"
    },
    {
      "x": 8,
      "y": 12,
      "z": -7,
      "name": "Rock_Sandstone_Brick_Stairs",
      "rotation": 10
    },
    {
      "x": 8,
      "y": 13,
      "z": -7,
      "name": "Rock_Sandstone_Brick"
    },
    {
      "x": 8,
      "y": 14,
      "z": -7,
      "name": "Soil_Clay_Ocean_Brick_Roof",
      "rotation": 1
    },
    {
      "x": 8,
      "y": 1,
      "z": -6,
      "name": "Rock_Sandstone_Cobble"
    },
    {
      "x": 8,
      "y": 6,
      "z": -6,
      "name": "Wood_Drywood_Planks",
      "rotation": 1
    },
    {
      "x": 8,
      "y": 12,
      "z": -6,
      "name": "Rock_Sandstone_Brick_Smooth_Half",
      "rotation": 8
    },
    {
      "x": 8,
      "y": 13,
      "z": -6,
      "name": "*Rock_Sandstone_Brick_Smooth_Half_State_Definitions_Block",
      "rotation": 8
    },
    {
      "x": 8,
      "y": 14,
      "z": -6,
      "name": "Soil_Clay_Ocean_Brick_Ornate"
    },
    {
      "x": 8,
      "y": 1,
      "z": -5,
      "name": "Rock_Sandstone_Cobble"
    },
    {
      "x": 8,
      "y": 6,
      "z": -5,
      "name": "Wood_Drywood_Beam",
      "rotation": 4
    },
    {
      "x": 8,
      "y": 13,
      "z": -5,
      "name": "*Rock_Sandstone_Brick_Smooth_Half_State_Definitions_Block"
    },
    {
      "x": 8,
      "y": 14,
      "z": -5,
      "name": "Soil_Clay_Ocean_Brick_Ornate"
    },
    {
      "x": 8,
      "y": 1,
      "z": -4,
      "name": "Rock_Sandstone_Cobble"
    },
    {
      "x": 8,
      "y": 13,
      "z": -4,
      "name": "*Rock_Sandstone_Brick_Smooth_Half_State_Definitions_Block",
      "rotation": 1
    },
    {
      "x": 8,
      "y": 14,
      "z": -4,
      "name": "Soil_Clay_Ocean_Brick_Ornate"
    },
    {
      "x": 8,
      "y": 1,
      "z": -3,
      "name": "Rock_Sandstone_Cobble"
    },
    {
      "x": 8,
      "y": 4,
      "z": -3,
      "name": "Wood_Drywood_Planks"
    },
    {
      "x": 8,
      "y": 12,
      "z": -3,
      "name": "Rock_Sandstone_Brick_Smooth_Half",
      "rotation": 8
    },
    {
      "x": 8,
      "y": 13,
      "z": -3,
      "name": "*Rock_Sandstone_Brick_Smooth_Half_State_Definitions_Block"
    },
    {
      "x": 8,
      "y": 14,
      "z": -3,
      "name": "Soil_Clay_Ocean_Brick_Ornate"
    },
    {
      "x": 8,
      "y": 1,
      "z": -2,
      "name": "Rock_Sandstone_Cobble"
    },
    {
      "x": 8,
      "y": 4,
      "z": -2,
      "name": "Wood_Drywood_Planks"
    },
    {
      "x": 8,
      "y": 12,
      "z": -2,
      "name": "Rock_Sandstone_Brick_Stairs",
      "rotation": 8
    },
    {
      "x": 8,
      "y": 13,
      "z": -2,
      "name": "Rock_Sandstone_Brick_Ornate",
      "rotation": 3
    },
    {
      "x": 8,
      "y": 14,
      "z": -2,
      "name": "Soil_Clay_Ocean_Brick_Roof",
      "rotation": 1
    },
    {
      "x": 8,
      "y": 1,
      "z": -1,
      "name": "Rock_Sandstone_Cobble"
    },
    {
      "x": 8,
      "y": 2,
      "z": -1,
      "name": "Rock_Sandstone_Brick",
      "rotation": 1
    },
    {
      "x": 8,
      "y": 3,
      "z": -1,
      "name": "Rock_Sandstone_Brick",
      "rotation": 1
    },
    {
      "x": 8,
      "y": 4,
      "z": -1,
      "name": "Rock_Sandstone_Brick",
      "rotation": 1
    },
    {
      "x": 8,
      "y": 5,
      "z": -1,
      "name": "Rock_Sandstone_Brick",
      "rotation": 1
    },
    {
      "x": 8,
      "y": 6,
      "z": -1,
      "name": "Rock_Sandstone_Cobble",
      "rotation": 1
    },
    {
      "x": 8,
      "y": 7,
      "z": -1,
      "name": "Rock_Sandstone_White_Cobble",
      "rotation": 1
    },
    {
      "x": 8,
      "y": 8,
      "z": -1,
      "name": "Rock_Sandstone_Brick_Pillar_Base"
    },
    {
      "x": 8,
      "y": 9,
      "z": -1,
      "name": "Rock_Sandstone_Brick_Pillar_Middle"
    },
    {
      "x": 8,
      "y": 10,
      "z": -1,
      "name": "Rock_Sandstone_Brick_Pillar_Middle"
    },
    {
      "x": 8,
      "y": 11,
      "z": -1,
      "name": "Rock_Sandstone_Brick_Pillar_Middle"
    },
    {
      "x": 8,
      "y": 12,
      "z": -1,
      "name": "Rock_Sandstone_Brick_Ornate"
    },
    {
      "x": 8,
      "y": 13,
      "z": -1,
      "name": "Rock_Sandstone_Brick_Ornate",
      "rotation": 3
    },
    {
      "x": 8,
      "y": 14,
      "z": -1,
      "name": "*Soil_Clay_Ocean_Brick_Roof_State_Definitions_Corner_Right",
      "rotation": 1
    },
    {
      "x": 8,
      "y": 1,
      "z": 0,
      "name": "Rock_Sandstone_Brick"
    },
    {
      "x": 8,
      "y": 2,
      "z": 0,
      "name": "Rock_Sandstone_Brick"
    },
    {
      "x": 8,
      "y": 3,
      "z": 0,
      "name": "Rock_Sandstone_Brick"
    },
    {
      "x": 8,
      "y": 4,
      "z": 0,
      "name": "Rock_Sandstone_Brick"
    },
    {
      "x": 8,
      "y": 5,
      "z": 0,
      "name": "Rock_Sandstone_Brick"
    },
    {
      "x": 8,
      "y": 6,
      "z": 0,
      "name": "Rock_Sandstone_Brick"
    },
    {
      "x": 8,
      "y": 7,
      "z": 0,
      "name": "Rock_Sandstone_White_Cobble"
    },
    {
      "x": 8,
      "y": 8,
      "z": 0,
      "name": "Rock_Sandstone_Brick_Pillar_Base"
    },
    {
      "x": 8,
      "y": 9,
      "z": 0,
      "name": "Rock_Sandstone_Brick_Half"
    },
    {
      "x": 8,
      "y": 13,
      "z": 0,
      "name": "Soil_Clay_Ocean_Brick_Roof_Hollow"
    },
    {
      "x": 9,
      "y": 1,
      "z": -8,
      "name": "Rock_Sandstone_Brick"
    },
    {
      "x": 9,
      "y": 2,
      "z": -8,
      "name": "Rock_Sandstone_Brick",
      "rotation": 1
    },
    {
      "x": 9,
      "y": 3,
      "z": -8,
      "name": "Rock_Sandstone_Brick",
      "rotation": 1
    },
    {
      "x": 9,
      "y": 4,
      "z": -8,
      "name": "Rock_Sandstone_Brick",
      "rotation": 1
    },
    {
      "x": 9,
      "y": 5,
      "z": -8,
      "name": "Rock_Sandstone_Brick",
      "rotation": 1
    },
    {
      "x": 9,
      "y": 6,
      "z": -8,
      "name": "Rock_Sandstone_Brick",
      "rotation": 1
    },
    {
      "x": 9,
      "y": 7,
      "z": -8,
      "name": "Rock_Sandstone_White_Cobble",
      "rotation": 1
    },
    {
      "x": 9,
      "y": 8,
      "z": -8,
      "name": "Rock_Sandstone_Brick_Pillar_Base"
    },
    {
      "x": 9,
      "y": 1,
      "z": -7,
      "name": "Rock_Sandstone_Cobble_Stairs",
      "rotation": 1
    },
    {
      "x": 9,
      "y": 4,
      "z": -7,
      "name": "Rock_Sandstone_Brick_Half",
      "rotation": 4
    },
    {
      "x": 9,
      "y": 5,
      "z": -7,
      "name": "Rock_Sandstone_Brick"
    },
    {
      "x": 9,
      "y": 6,
      "z": -7,
      "name": "Rock_Sandstone_Cobble",
      "rotation": 1
    },
    {
      "x": 9,
      "y": 7,
      "z": -7,
      "name": "Rock_Sandstone_White_Cobble",
      "rotation": 1
    },
    {
      "x": 9,
      "y": 8,
      "z": -7,
      "name": "Rock_Sandstone_Brick_Pillar_Base"
    },
    {
      "x": 9,
      "y": 13,
      "z": -7,
      "name": "Soil_Clay_Ocean_Brick_Roof_Hollow",
      "rotation": 1
    },
    {
      "x": 9,
      "y": 1,
      "z": -6,
      "name": "Rock_Sandstone_Cobble_Stairs",
      "rotation": 1
    },
    {
      "x": 9,
      "y": 5,
      "z": -6,
      "name": "Rock_Sandstone_Brick_Half",
      "rotation": 8
    },
    {
      "x": 9,
      "y": 6,
      "z": -6,
      "name": "Rock_Sandstone_Cobble",
      "rotation": 1
    },
    {
      "x": 9,
      "y": 7,
      "z": -6,
      "name": "Rock_Sandstone_White_Cobble",
      "rotation": 1
    },
    {
      "x": 9,
      "y": 8,
      "z": -6,
      "name": "Rubble_Sandstone_Medium",
      "support": 15
    },
    {
      "x": 9,
      "y": 13,
      "z": -6,
      "name": "Soil_Clay_Ocean_Brick_Roof_Hollow",
      "rotation": 1
    },
    {
      "x": 9,
      "y": 1,
      "z": -5,
      "name": "Rock_Sandstone_Cobble_Stairs",
      "rotation": 1
    },
    {
      "x": 9,
      "y": 4,
      "z": -5,
      "name": "Rock_Sandstone_Cobble_Half",
      "rotation": 6
    },
    {
      "x": 9,
      "y": 5,
      "z": -5,
      "name": "Rock_Sandstone_Cobble"
    },
    {
      "x": 9,
      "y": 6,
      "z": -5,
      "name": "Rock_Sandstone_Cobble",
      "rotation": 1
    },
    {
      "x": 9,
      "y": 7,
      "z": -5,
      "name": "Rock_Sandstone_White_Cobble",
      "rotation": 1
    },
    {
      "x": 9,
      "y": 8,
      "z": -5,
      "name": "Rock_Sandstone_Brick_Pillar_Base"
    },
    {
      "x": 9,
      "y": 13,
      "z": -5,
      "name": "Soil_Clay_Ocean_Brick_Roof_Hollow",
      "rotation": 1
    },
    {
      "x": 9,
      "y": 1,
      "z": -4,
      "name": "Rock_Sandstone_Brick"
    },
    {
      "x": 9,
      "y": 2,
      "z": -4,
      "name": "Rock_Sandstone_Brick"
    },
    {
      "x": 9,
      "y": 3,
      "z": -4,
      "name": "Rock_Sandstone_Cobble"
    },
    {
      "x": 9,
      "y": 4,
      "z": -4,
      "name": "Rock_Sandstone_Cobble"
    },
    {
      "x": 9,
      "y": 5,
      "z": -4,
      "name": "Rock_Sandstone_Cobble"
    },
    {
      "x": 9,
      "y": 6,
      "z": -4,
      "name": "Rock_Sandstone_Cobble",
      "rotation": 1
    },
    {
      "x": 9,
      "y": 7,
      "z": -4,
      "name": "Rock_Sandstone_White_Cobble",
      "rotation": 1
    },
    {
      "x": 9,
      "y": 8,
      "z": -4,
      "name": "Rock_Sandstone_Brick_Pillar_Base"
    },
    {
      "x": 9,
      "y": 9,
      "z": -4,
      "name": "Rock_Sandstone_Brick_Ornate"
    },
    {
      "x": 9,
      "y": 13,
      "z": -4,
      "name": "Soil_Clay_Ocean_Brick_Roof_Hollow",
      "rotation": 1
    },
    {
      "x": 9,
      "y": 1,
      "z": -3,
      "name": "Rock_Sandstone_Brick"
    },
    {
      "x": 9,
      "y": 2,
      "z": -3,
      "name": "Rock_Sandstone_Brick"
    },
    {
      "x": 9,
      "y": 3,
      "z": -3,
      "name": "Rock_Sandstone_Brick"
    },
    {
      "x": 9,
      "y": 4,
      "z": -3,
      "name": "Rock_Sandstone_Cobble"
    },
    {
      "x": 9,
      "y": 5,
      "z": -3,
      "name": "Rock_Sandstone_Cobble"
    },
    {
      "x": 9,
      "y": 6,
      "z": -3,
      "name": "Rock_Sandstone_Brick",
      "rotation": 1
    },
    {
      "x": 9,
      "y": 7,
      "z": -3,
      "name": "Rock_Sandstone_White_Cobble",
      "rotation": 1
    },
    {
      "x": 9,
      "y": 8,
      "z": -3,
      "name": "Rock_Sandstone_Brick_Pillar_Base"
    },
    {
      "x": 9,
      "y": 9,
      "z": -3,
      "name": "Rock_Sandstone_Brick_Ornate"
    },
    {
      "x": 9,
      "y": 13,
      "z": -3,
      "name": "Soil_Clay_Ocean_Brick_Roof_Hollow",
      "rotation": 1
    },
    {
      "x": 9,
      "y": 1,
      "z": -2,
      "name": "Rock_Sandstone_Brick"
    },
    {
      "x": 9,
      "y": 2,
      "z": -2,
      "name": "Rock_Sandstone_Brick",
      "rotation": 1
    },
    {
      "x": 9,
      "y": 3,
      "z": -2,
      "name": "Rock_Sandstone_Brick",
      "rotation": 1
    },
    {
      "x": 9,
      "y": 4,
      "z": -2,
      "name": "Rock_Sandstone_Brick",
      "rotation": 1
    },
    {
      "x": 9,
      "y": 5,
      "z": -2,
      "name": "Rock_Sandstone_Brick",
      "rotation": 1
    },
    {
      "x": 9,
      "y": 6,
      "z": -2,
      "name": "Rock_Sandstone_Brick",
      "rotation": 1
    },
    {
      "x": 9,
      "y": 7,
      "z": -2,
      "name": "Rock_Sandstone_White_Cobble",
      "rotation": 1
    },
    {
      "x": 9,
      "y": 8,
      "z": -2,
      "name": "Rock_Sandstone_Brick_Pillar_Base"
    },
    {
      "x": 9,
      "y": 9,
      "z": -2,
      "name": "Rock_Sandstone_Brick_Ornate"
    },
    {
      "x": 9,
      "y": 10,
      "z": -2,
      "name": "Rock_Sandstone_Brick_Wall",
      "rotation": 1
    },
    {
      "x": 9,
      "y": 13,
      "z": -2,
      "name": "Soil_Clay_Ocean_Brick_Roof_Hollow",
      "rotation": 1
    },
    {
      "x": 9,
      "y": 1,
      "z": -1,
      "name": "Rock_Sandstone_Brick"
    },
    {
      "x": 9,
      "y": 2,
      "z": -1,
      "name": "Rock_Sandstone_Brick",
      "rotation": 1
    },
    {
      "x": 9,
      "y": 3,
      "z": -1,
      "name": "Rock_Sandstone_Brick",
      "rotation": 1
    },
    {
      "x": 9,
      "y": 4,
      "z": -1,
      "name": "Rock_Sandstone_Brick",
      "rotation": 1
    },
    {
      "x": 9,
      "y": 5,
      "z": -1,
      "name": "Rock_Sandstone_Brick",
      "rotation": 1
    },
    {
      "x": 9,
      "y": 6,
      "z": -1,
      "name": "Rock_Sandstone_Cobble",
      "rotation": 1
    },
    {
      "x": 9,
      "y": 7,
      "z": -1,
      "name": "Rock_Sandstone_White_Cobble",
      "rotation": 1
    },
    {
      "x": 9,
      "y": 8,
      "z": -1,
      "name": "Rock_Sandstone_Brick_Pillar_Base"
    },
    {
      "x": 9,
      "y": 9,
      "z": -1,
      "name": "Rock_Sandstone_Brick_Half"
    },
    {
      "x": 9,
      "y": 13,
      "z": -1,
      "name": "Soil_Clay_Ocean_Brick_Roof_Hollow",
      "rotation": 1
    },
    {
      "x": 9,
      "y": 13,
      "z": 0,
      "name": "*Soil_Clay_Ocean_Brick_Roof_Hollow_State_Definitions_Corner_Right",
      "rotation": 1
    }
  ],
  "fluids": [
    {
      "x": 0,
      "y": 1,
      "z": -9,
      "name": "Water_Source",
      "level": 1
    },
    {
      "x": 0,
      "y": 2,
      "z": -9,
      "name": "Water_Source",
      "level": 1
    },
    {
      "x": 0,
      "y": 3,
      "z": -9,
      "name": "Water_Source",
      "level": 1
    },
    {
      "x": 0,
      "y": 4,
      "z": -9,
      "name": "Water_Source",
      "level": 1
    },
    {
      "x": 0,
      "y": 5,
      "z": -9,
      "name": "Water_Source",
      "level": 1
    },
    {
      "x": 0,
      "y": 6,
      "z": -9,
      "name": "Water_Source",
      "level": 1
    },
    {
      "x": 0,
      "y": 7,
      "z": -9,
      "name": "Water_Source",
      "level": 1
    },
    {
      "x": 0,
      "y": 8,
      "z": -9,
      "name": "Water_Source",
      "level": 1
    },
    {
      "x": 0,
      "y": 9,
      "z": -9,
      "name": "Water_Source",
      "level": 1
    },
    {
      "x": 0,
      "y": 10,
      "z": -9,
      "name": "Water_Source",
      "level": 1
    },
    {
      "x": 0,
      "y": 11,
      "z": -9,
      "name": "Water_Source",
      "level": 1
    },
    {
      "x": 0,
      "y": 12,
      "z": -9,
      "name": "Water_Source",
      "level": 1
    },
    {
      "x": 0,
      "y": 13,
      "z": -9,
      "name": "Water_Source",
      "level": 1
    },
    {
      "x": 0,
      "y": 14,
      "z": -9,
      "name": "Water_Source",
      "level": 1
    },
    {
      "x": 0,
      "y": 1,
      "z": -8,
      "name": "Water_Source",
      "level": 1
    },
    {
      "x": 0,
      "y": 2,
      "z": -8,
      "name": "Water_Source",
      "level": 1
    },
    {
      "x": 0,
      "y": 3,
      "z": -8,
      "name": "Water_Source",
      "level": 1
    },
    {
      "x": 0,
      "y": 4,
      "z": -8,
      "name": "Water_Source",
      "level": 1
    },
    {
      "x": 0,
      "y": 5,
      "z": -8,
      "name": "Water_Source",
      "level": 1
    },
    {
      "x": 0,
      "y": 6,
      "z": -8,
      "name": "Water_Source",
      "level": 1
    },
    {
      "x": 0,
      "y": 7,
      "z": -8,
      "name": "Water_Source",
      "level": 1
    },
    {
      "x": 0,
      "y": 8,
      "z": -8,
      "name": "Water_Source",
      "level": 1
    },
    {
      "x": 0,
      "y": 9,
      "z": -8,
      "name": "Water_Source",
      "level": 1
    },
    {
      "x": 0,
      "y": 10,
      "z": -8,
      "name": "Water_Source",
      "level": 1
    },
    {
      "x": 0,
      "y": 11,
      "z": -8,
      "name": "Water_Source",
      "level": 1
    },
    {
      "x": 0,
      "y": 12,
      "z": -8,
      "name": "Water_Source",
      "level": 1
    },
    {
      "x": 0,
      "y": 13,
      "z": -8,
      "name": "Water_Source",
      "level": 1
    },
    {
      "x": 0,
      "y": 14,
      "z": -8,
      "name": "Water_Source",
      "level": 1
    },
    {
      "x": 0,
      "y": 1,
      "z": -7,
      "name": "Water_Source",
      "level": 1
    },
    {
      "x": 0,
      "y": 2,
      "z": -7,
      "name": "Water_Source",
      "level": 1
    },
    {
      "x": 0,
      "y": 3,
      "z": -7,
      "name": "Water_Source",
      "level": 1
    },
    {
      "x": 0,
      "y": 4,
      "z": -7,
      "name": "Water_Source",
      "level": 1
    },
    {
      "x": 0,
      "y": 5,
      "z": -7,
      "name": "Water_Source",
      "level": 1
    },
    {
      "x": 0,
      "y": 6,
      "z": -7,
      "name": "Water_Source",
      "level": 1
    },
    {
      "x": 0,
      "y": 7,
      "z": -7,
      "name": "Water_Source",
      "level": 1
    },
    {
      "x": 0,
      "y": 8,
      "z": -7,
      "name": "Water_Source",
      "level": 1
    },
    {
      "x": 0,
      "y": 9,
      "z": -7,
      "name": "Water_Source",
      "level": 1
    },
    {
      "x": 0,
      "y": 10,
      "z": -7,
      "name": "Water_Source",
      "level": 1
    },
    {
      "x": 0,
      "y": 11,
      "z": -7,
      "name": "Water_Source",
      "level": 1
    },
    {
      "x": 0,
      "y": 12,
      "z": -7,
      "name": "Water_Source",
      "level": 1
    },
    {
      "x": 0,
      "y": 13,
      "z": -7,
      "name": "Water_Source",
      "level": 1
    },
    {
      "x": 0,
      "y": 14,
      "z": -7,
      "name": "Water_Source",
      "level": 1
    },
    {
      "x": 0,
      "y": 1,
      "z": -6,
      "name": "Water_Source",
      "level": 1
    },
    {
      "x": 0,
      "y": 2,
      "z": -6,
      "name": "Water_Source",
      "level": 1
    },
    {
      "x": 0,
      "y": 3,
      "z": -6,
      "name": "Water_Source",
      "level": 1
    },
    {
      "x": 0,
      "y": 4,
      "z": -6,
      "name": "Water_Source",
      "level": 1
    },
    {
      "x": 0,
      "y": 5,
      "z": -6,
      "name": "Water_Source",
      "level": 1
    },
    {
      "x": 0,
      "y": 6,
      "z": -6,
      "name": "Water_Source",
      "level": 1
    },
    {
      "x": 0,
      "y": 7,
      "z": -6,
      "name": "Water_Source",
      "level": 1
    },
    {
      "x": 0,
      "y": 8,
      "z": -6,
      "name": "Water_Source",
      "level": 1
    },
    {
      "x": 0,
      "y": 9,
      "z": -6,
      "name": "Water_Source",
      "level": 1
    },
    {
      "x": 0,
      "y": 10,
      "z": -6,
      "name": "Water_Source",
      "level": 1
    },
    {
      "x": 0,
      "y": 11,
      "z": -6,
      "name": "Water_Source",
      "level": 1
    },
    {
      "x": 0,
      "y": 12,
      "z": -6,
      "name": "Water_Source",
      "level": 1
    },
    {
      "x": 0,
      "y": 13,
      "z": -6,
      "name": "Water_Source",
      "level": 1
    },
    {
      "x": 0,
      "y": 14,
      "z": -6,
      "name": "Water_Source",
      "level": 1
    },
    {
      "x": 0,
      "y": 1,
      "z": -5,
      "name": "Water_Source",
      "level": 1
    },
    {
      "x": 0,
      "y": 2,
      "z": -5,
      "name": "Water_Source",
      "level": 1
    },
    {
      "x": 0,
      "y": 3,
      "z": -5,
      "name": "Water_Source",
      "level": 1
    },
    {
      "x": 0,
      "y": 4,
      "z": -5,
      "name": "Water_Source",
      "level": 1
    },
    {
      "x": 0,
      "y": 5,
      "z": -5,
      "name": "Water_Source",
      "level": 1
    },
    {
      "x": 0,
      "y": 6,
      "z": -5,
      "name": "Water_Source",
      "level": 1
    },
    {
      "x": 0,
      "y": 7,
      "z": -5,
      "name": "Water_Source",
      "level": 1
    },
    {
      "x": 0,
      "y": 8,
      "z": -5,
      "name": "Water_Source",
      "level": 1
    },
    {
      "x": 0,
      "y": 9,
      "z": -5,
      "name": "Water_Source",
      "level": 1
    },
    {
      "x": 0,
      "y": 10,
      "z": -5,
      "name": "Water_Source",
      "level": 1
    },
    {
      "x": 0,
      "y": 11,
      "z": -5,
      "name": "Water_Source",
      "level": 1
    },
    {
      "x": 0,
      "y": 12,
      "z": -5,
      "name": "Water_Source",
      "level": 1
    },
    {
      "x": 0,
      "y": 13,
      "z": -5,
      "name": "Water_Source",
      "level": 1
    },
    {
      "x": 0,
      "y": 14,
      "z": -5,
      "name": "Water_Source",
      "level": 1
    },
    {
      "x": 0,
      "y": 1,
      "z": -4,
      "name": "Water_Source",
      "level": 1
    },
    {
      "x": 0,
      "y": 2,
      "z": -4,
      "name": "Water_Source",
      "level": 1
    },
    {
      "x": 0,
      "y": 3,
      "z": -4,
      "name": "Water_Source",
      "level": 1
    },
    {
      "x": 0,
      "y": 4,
      "z": -4,
      "name": "Water_Source",
      "level": 1
    },
    {
      "x": 0,
      "y": 5,
      "z": -4,
      "name": "Water_Source",
      "level": 1
    },
    {
      "x": 0,
      "y": 6,
      "z": -4,
      "name": "Water_Source",
      "level": 1
    },
    {
      "x": 0,
      "y": 7,
      "z": -4,
      "name": "Water_Source",
      "level": 1
    },
    {
      "x": 0,
      "y": 8,
      "z": -4,
      "name": "Water_Source",
      "level": 1
    },
    {
      "x": 0,
      "y": 9,
      "z": -4,
      "name": "Water_Source",
      "level": 1
    },
    {
      "x": 0,
      "y": 10,
      "z": -4,
      "name": "Water_Source",
      "level": 1
    },
    {
      "x": 0,
      "y": 11,
      "z": -4,
      "name": "Water_Source",
      "level": 1
    },
    {
      "x": 0,
      "y": 12,
      "z": -4,
      "name": "Water_Source",
      "level": 1
    },
    {
      "x": 0,
      "y": 13,
      "z": -4,
      "name": "Water_Source",
      "level": 1
    },
    {
      "x": 0,
      "y": 14,
      "z": -4,
      "name": "Water_Source",
      "level": 1
    },
    {
      "x": 0,
      "y": 1,
      "z": -3,
      "name": "Water_Source",
      "level": 1
    },
    {
      "x": 0,
      "y": 2,
      "z": -3,
      "name": "Water_Source",
      "level": 1
    },
    {
      "x": 0,
      "y": 3,
      "z": -3,
      "name": "Water_Source",
      "level": 1
    },
    {
      "x": 0,
      "y": 4,
      "z": -3,
      "name": "Water_Source",
      "level": 1
    },
    {
      "x": 0,
      "y": 5,
      "z": -3,
      "name": "Water_Source",
      "level": 1
    },
    {
      "x": 0,
      "y": 6,
      "z": -3,
      "name": "Water_Source",
      "level": 1
    },
    {
      "x": 0,
      "y": 7,
      "z": -3,
      "name": "Water_Source",
      "level": 1
    },
    {
      "x": 0,
      "y": 8,
      "z": -3,
      "name": "Water_Source",
      "level": 1
    },
    {
      "x": 0,
      "y": 9,
      "z": -3,
      "name": "Water_Source",
      "level": 1
    },
    {
      "x": 0,
      "y": 10,
      "z": -3,
      "name": "Water_Source",
      "level": 1
    },
    {
      "x": 0,
      "y": 11,
      "z": -3,
      "name": "Water_Source",
      "level": 1
    },
    {
      "x": 0,
      "y": 12,
      "z": -3,
      "name": "Water_Source",
      "level": 1
    },
    {
      "x": 0,
      "y": 13,
      "z": -3,
      "name": "Water_Source",
      "level": 1
    },
    {
      "x": 0,
      "y": 14,
      "z": -3,
      "name": "Water_Source",
      "level": 1
    },
    {
      "x": 0,
      "y": 1,
      "z": -2,
      "name": "Water_Source",
      "level": 1
    },
    {
      "x": 0,
      "y": 2,
      "z": -2,
      "name": "Water_Source",
      "level": 1
    },
    {
      "x": 0,
      "y": 3,
      "z": -2,
      "name": "Water_Source",
      "level": 1
    },
    {
      "x": 0,
      "y": 4,
      "z": -2,
      "name": "Water_Source",
      "level": 1
    },
    {
      "x": 0,
      "y": 5,
      "z": -2,
      "name": "Water_Source",
      "level": 1
    },
    {
      "x": 0,
      "y": 6,
      "z": -2,
      "name": "Water_Source",
      "level": 1
    },
    {
      "x": 0,
      "y": 7,
      "z": -2,
      "name": "Water_Source",
      "level": 1
    },
    {
      "x": 0,
      "y": 8,
      "z": -2,
      "name": "Water_Source",
      "level": 1
    },
    {
      "x": 0,
      "y": 9,
      "z": -2,
      "name": "Water_Source",
      "level": 1
    },
    {
      "x": 0,
      "y": 10,
      "z": -2,
      "name": "Water_Source",
      "level": 1
    },
    {
      "x": 0,
      "y": 11,
      "z": -2,
      "name": "Water_Source",
      "level": 1
    },
    {
      "x": 0,
      "y": 12,
      "z": -2,
      "name": "Water_Source",
      "level": 1
    },
    {
      "x": 0,
      "y": 13,
      "z": -2,
      "name": "Water_Source",
      "level": 1
    },
    {
      "x": 0,
      "y": 14,
      "z": -2,
      "name": "Water_Source",
      "level": 1
    },
    {
      "x": 0,
      "y": 1,
      "z": -1,
      "name": "Water_Source",
      "level": 1
    },
    {
      "x": 0,
      "y": 2,
      "z": -1,
      "name": "Water_Source",
      "level": 1
    },
    {
      "x": 0,
      "y": 3,
      "z": -1,
      "name": "Water_Source",
      "level": 1
    },
    {
      "x": 0,
      "y": 4,
      "z": -1,
      "name": "Water_Source",
      "level": 1
    },
    {
      "x": 0,
      "y": 5,
      "z": -1,
      "name": "Water_Source",
      "level": 1
    },
    {
      "x": 0,
      "y": 6,
      "z": -1,
      "name": "Water_Source",
      "level": 1
    },
    {
      "x": 0,
      "y": 7,
      "z": -1,
      "name": "Water_Source",
      "level": 1
    },
    {
      "x": 0,
      "y": 8,
      "z": -1,
      "name": "Water_Source",
      "level": 1
    },
    {
      "x": 0,
      "y": 9,
      "z": -1,
      "name": "Water_Source",
      "level": 1
    },
    {
      "x": 0,
      "y": 10,
      "z": -1,
      "name": "Water_Source",
      "level": 1
    },
    {
      "x": 0,
      "y": 11,
      "z": -1,
      "name": "Water_Source",
      "level": 1
    },
    {
      "x": 0,
      "y": 12,
      "z": -1,
      "name": "Water_Source",
      "level": 1
    },
    {
      "x": 0,
      "y": 13,
      "z": -1,
      "name": "Water_Source",
      "level": 1
    },
    {
      "x": 0,
      "y": 14,
      "z": -1,
      "name": "Water_Source",
      "level": 1
    },
    {
      "x": 0,
      "y": 1,
      "z": 0,
      "name": "Water_Source",
      "level": 1
    },
    {
      "x": 0,
      "y": 2,
      "z": 0,
      "name": "Water_Source",
      "level": 1
    },
    {
      "x": 0,
      "y": 3,
      "z": 0,
      "name": "Water_Source",
      "level": 1
    },
    {
      "x": 0,
      "y": 4,
      "z": 0,
      "name": "Water_Source",
      "level": 1
    },
    {
      "x": 0,
      "y": 5,
      "z": 0,
      "name": "Water_Source",
      "level": 1
    },
    {
      "x": 0,
      "y": 6,
      "z": 0,
      "name": "Water_Source",
      "level": 1
    },
    {
      "x": 0,
      "y": 7,
      "z": 0,
      "name": "Water_Source",
      "level": 1
    },
    {
      "x": 0,
      "y": 8,
      "z": 0,
      "name": "Water_Source",
      "level": 1
    },
    {
      "x": 0,
      "y": 9,
      "z": 0,
      "name": "Water_Source",
      "level": 1
    },
    {
      "x": 0,
      "y": 10,
      "z": 0,
      "name": "Water_Source",
      "level": 1
    },
    {
      "x": 0,
      "y": 11,
      "z": 0,
      "name": "Water_Source",
      "level": 1
    },
    {
      "x": 0,
      "y": 12,
      "z": 0,
      "name": "Water_Source",
      "level": 1
    },
    {
      "x": 0,
      "y": 13,
      "z": 0,
      "name": "Water_Source",
      "level": 1
    },
    {
      "x": 0,
      "y": 14,
      "z": 0,
      "name": "Water_Source",
      "level": 1
    },
    {
      "x": 1,
      "y": 1,
      "z": -9,
      "name": "Water_Source",
      "level": 1
    },
    {
      "x": 1,
      "y": 2,
      "z": -9,
      "name": "Water_Source",
      "level": 1
    },
    {
      "x": 1,
      "y": 3,
      "z": -9,
      "name": "Water_Source",
      "level": 1
    },
    {
      "x": 1,
      "y": 4,
      "z": -9,
      "name": "Water_Source",
      "level": 1
    },
    {
      "x": 1,
      "y": 5,
      "z": -9,
      "name": "Water_Source",
      "level": 1
    },
    {
      "x": 1,
      "y": 6,
      "z": -9,
      "name": "Water_Source",
      "level": 1
    },
    {
      "x": 1,
      "y": 7,
      "z": -9,
      "name": "Water_Source",
      "level": 1
    },
    {
      "x": 1,
      "y": 8,
      "z": -9,
      "name": "Water_Source",
      "level": 1
    },
    {
      "x": 1,
      "y": 9,
      "z": -9,
      "name": "Water_Source",
      "level": 1
    },
    {
      "x": 1,
      "y": 10,
      "z": -9,
      "name": "Water_Source",
      "level": 1
    },
    {
      "x": 1,
      "y": 11,
      "z": -9,
      "name": "Water_Source",
      "level": 1
    },
    {
      "x": 1,
      "y": 12,
      "z": -9,
      "name": "Water_Source",
      "level": 1
    },
    {
      "x": 1,
      "y": 13,
      "z": -9,
      "name": "Water_Source",
      "level": 1
    },
    {
      "x": 1,
      "y": 14,
      "z": -9,
      "name": "Water_Source",
      "level": 1
    },
    {
      "x": 1,
      "y": 1,
      "z": -8,
      "name": "Water_Source",
      "level": 1
    },
    {
      "x": 1,
      "y": 2,
      "z": -8,
      "name": "Water_Source",
      "level": 1
    },
    {
      "x": 1,
      "y": 3,
      "z": -8,
      "name": "Water_Source",
      "level": 1
    },
    {
      "x": 1,
      "y": 4,
      "z": -8,
      "name": "Water_Source",
      "level": 1
    },
    {
      "x": 1,
      "y": 5,
      "z": -8,
      "name": "Water_Source",
      "level": 1
    },
    {
      "x": 1,
      "y": 6,
      "z": -8,
      "name": "Water_Source",
      "level": 1
    },
    {
      "x": 1,
      "y": 7,
      "z": -8,
      "name": "Water_Source",
      "level": 1
    },
    {
      "x": 1,
      "y": 8,
      "z": -8,
      "name": "Water_Source",
      "level": 1
    },
    {
      "x": 1,
      "y": 9,
      "z": -8,
      "name": "Water_Source",
      "level": 1
    },
    {
      "x": 1,
      "y": 10,
      "z": -8,
      "name": "Water_Source",
      "level": 1
    },
    {
      "x": 1,
      "y": 11,
      "z": -8,
      "name": "Water_Source",
      "level": 1
    },
    {
      "x": 1,
      "y": 12,
      "z": -8,
      "name": "Water_Source",
      "level": 1
    },
    {
      "x": 1,
      "y": 13,
      "z": -8,
      "name": "Water_Source",
      "level": 1
    },
    {
      "x": 1,
      "y": 14,
      "z": -8,
      "name": "Water_Source",
      "level": 1
    },
    {
      "x": 1,
      "y": 1,
      "z": -7,
      "name": "Water_Source",
      "level": 1
    },
    {
      "x": 1,
      "y": 2,
      "z": -7,
      "name": "Water_Source",
      "level": 1
    },
    {
      "x": 1,
      "y": 3,
      "z": -7,
      "name": "Water_Source",
      "level": 1
    },
    {
      "x": 1,
      "y": 4,
      "z": -7,
      "name": "Water_Source",
      "level": 1
    },
    {
      "x": 1,
      "y": 5,
      "z": -7,
      "name": "Water_Source",
      "level": 1
    },
    {
      "x": 1,
      "y": 6,
      "z": -7,
      "name": "Water_Source",
      "level": 1
    },
    {
      "x": 1,
      "y": 7,
      "z": -7,
      "name": "Water_Source",
      "level": 1
    },
    {
      "x": 1,
      "y": 8,
      "z": -7,
      "name": "Water_Source",
      "level": 1
    },
    {
      "x": 1,
      "y": 9,
      "z": -7,
      "name": "Water_Source",
      "level": 1
    },
    {
      "x": 1,
      "y": 10,
      "z": -7,
      "name": "Water_Source",
      "level": 1
    },
    {
      "x": 1,
      "y": 11,
      "z": -7,
      "name": "Water_Source",
      "level": 1
    },
    {
      "x": 1,
      "y": 12,
      "z": -7,
      "name": "Water_Source",
      "level": 1
    },
    {
      "x": 1,
      "y": 13,
      "z": -7,
      "name": "Water_Source",
      "level": 1
    },
    {
      "x": 1,
      "y": 14,
      "z": -7,
      "name": "Water_Source",
      "level": 1
    },
    {
      "x": 1,
      "y": 1,
      "z": -6,
      "name": "Water_Source",
      "level": 1
    },
    {
      "x": 1,
      "y": 2,
      "z": -6,
      "name": "Water_Source",
      "level": 1
    },
    {
      "x": 1,
      "y": 3,
      "z": -6,
      "name": "Water_Source",
      "level": 1
    },
    {
      "x": 1,
      "y": 4,
      "z": -6,
      "name": "Water_Source",
      "level": 1
    },
    {
      "x": 1,
      "y": 5,
      "z": -6,
      "name": "Water_Source",
      "level": 1
    },
    {
      "x": 1,
      "y": 6,
      "z": -6,
      "name": "Water_Source",
      "level": 1
    },
    {
      "x": 1,
      "y": 7,
      "z": -6,
      "name": "Water_Source",
      "level": 1
    },
    {
      "x": 1,
      "y": 8,
      "z": -6,
      "name": "Water_Source",
      "level": 1
    },
    {
      "x": 1,
      "y": 9,
      "z": -6,
      "name": "Water_Source",
      "level": 1
    },
    {
      "x": 1,
      "y": 10,
      "z": -6,
      "name": "Water_Source",
      "level": 1
    },
    {
      "x": 1,
      "y": 11,
      "z": -6,
      "name": "Water_Source",
      "level": 1
    },
    {
      "x": 1,
      "y": 12,
      "z": -6,
      "name": "Water_Source",
      "level": 1
    },
    {
      "x": 1,
      "y": 13,
      "z": -6,
      "name": "Water_Source",
      "level": 1
    },
    {
      "x": 1,
      "y": 14,
      "z": -6,
      "name": "Water_Source",
      "level": 1
    },
    {
      "x": 1,
      "y": 1,
      "z": -5,
      "name": "Water_Source",
      "level": 1
    },
    {
      "x": 1,
      "y": 2,
      "z": -5,
      "name": "Water_Source",
      "level": 1
    },
    {
      "x": 1,
      "y": 3,
      "z": -5,
      "name": "Water_Source",
      "level": 1
    },
    {
      "x": 1,
      "y": 4,
      "z": -5,
      "name": "Water_Source",
      "level": 1
    },
    {
      "x": 1,
      "y": 5,
      "z": -5,
      "name": "Water_Source",
      "level": 1
    },
    {
      "x": 1,
      "y": 6,
      "z": -5,
      "name": "Water_Source",
      "level": 1
    },
    {
      "x": 1,
      "y": 7,
      "z": -5,
      "name": "Water_Source",
      "level": 1
    },
    {
      "x": 1,
      "y": 8,
      "z": -5,
      "name": "Water_Source",
      "level": 1
    },
    {
      "x": 1,
      "y": 9,
      "z": -5,
      "name": "Water_Source",
      "level": 1
    },
    {
      "x": 1,
      "y": 10,
      "z": -5,
      "name": "Water_Source",
      "level": 1
    },
    {
      "x": 1,
      "y": 11,
      "z": -5,
      "name": "Water_Source",
      "level": 1
    },
    {
      "x": 1,
      "y": 12,
      "z": -5,
      "name": "Water_Source",
      "level": 1
    },
    {
      "x": 1,
      "y": 13,
      "z": -5,
      "name": "Water_Source",
      "level": 1
    },
    {
      "x": 1,
      "y": 14,
      "z": -5,
      "name": "Water_Source",
      "level": 1
    },
    {
      "x": 1,
      "y": 1,
      "z": -4,
      "name": "Water_Source",
      "level": 1
    },
    {
      "x": 1,
      "y": 2,
      "z": -4,
      "name": "Water_Source",
      "level": 1
    },
    {
      "x": 1,
      "y": 3,
      "z": -4,
      "name": "Water_Source",
      "level": 1
    },
    {
      "x": 1,
      "y": 4,
      "z": -4,
      "name": "Water_Source",
      "level": 1
    },
    {
      "x": 1,
      "y": 5,
      "z": -4,
      "name": "Water_Source",
      "level": 1
    },
    {
      "x": 1,
      "y": 6,
      "z": -4,
      "name": "Water_Source",
      "level": 1
    },
    {
      "x": 1,
      "y": 7,
      "z": -4,
      "name": "Water_Source",
      "level": 1
    },
    {
      "x": 1,
      "y": 8,
      "z": -4,
      "name": "Water_Source",
      "level": 1
    },
    {
      "x": 1,
      "y": 9,
      "z": -4,
      "name": "Water_Source",
      "level": 1
    },
    {
      "x": 1,
      "y": 10,
      "z": -4,
      "name": "Water_Source",
      "level": 1
    },
    {
      "x": 1,
      "y": 11,
      "z": -4,
      "name": "Water_Source",
      "level": 1
    },
    {
      "x": 1,
      "y": 12,
      "z": -4,
      "name": "Water_Source",
      "level": 1
    },
    {
      "x": 1,
      "y": 13,
      "z": -4,
      "name": "Water_Source",
      "level": 1
    },
    {
      "x": 1,
      "y": 14,
      "z": -4,
      "name": "Water_Source",
      "level": 1
    },
    {
      "x": 1,
      "y": 1,
      "z": -3,
      "name": "Water_Source",
      "level": 1
    },
    {
      "x": 1,
      "y": 2,
      "z": -3,
      "name": "Water_Source",
      "level": 1
    },
    {
      "x": 1,
      "y": 3,
      "z": -3,
      "name": "Water_Source",
      "level": 1
    },
    {
      "x": 1,
      "y": 4,
      "z": -3,
      "name": "Water_Source",
      "level": 1
    },
    {
      "x": 1,
      "y": 5,
      "z": -3,
      "name": "Water_Source",
      "level": 1
    },
    {
      "x": 1,
      "y": 6,
      "z": -3,
      "name": "Water_Source",
      "level": 1
    },
    {
      "x": 1,
      "y": 7,
      "z": -3,
      "name": "Water_Source",
      "level": 1
    },
    {
      "x": 1,
      "y": 8,
      "z": -3,
      "name": "Water_Source",
      "level": 1
    },
    {
      "x": 1,
      "y": 9,
      "z": -3,
      "name": "Water_Source",
      "level": 1
    },
    {
      "x": 1,
      "y": 10,
      "z": -3,
      "name": "Water_Source",
      "level": 1
    },
    {
      "x": 1,
      "y": 11,
      "z": -3,
      "name": "Water_Source",
      "level": 1
    },
    {
      "x": 1,
      "y": 12,
      "z": -3,
      "name": "Water_Source",
      "level": 1
    },
    {
      "x": 1,
      "y": 13,
      "z": -3,
      "name": "Water_Source",
      "level": 1
    },
    {
      "x": 1,
      "y": 14,
      "z": -3,
      "name": "Water_Source",
      "level": 1
    },
    {
      "x": 1,
      "y": 1,
      "z": -2,
      "name": "Water_Source",
      "level": 1
    },
    {
      "x": 1,
      "y": 2,
      "z": -2,
      "name": "Water_Source",
      "level": 1
    },
    {
      "x": 1,
      "y": 3,
      "z": -2,
      "name": "Water_Source",
      "level": 1
    },
    {
      "x": 1,
      "y": 4,
      "z": -2,
      "name": "Water_Source",
      "level": 1
    },
    {
      "x": 1,
      "y": 5,
      "z": -2,
      "name": "Water_Source",
      "level": 1
    },
    {
      "x": 1,
      "y": 6,
      "z": -2,
      "name": "Water_Source",
      "level": 1
    },
    {
      "x": 1,
      "y": 7,
      "z": -2,
      "name": "Water_Source",
      "level": 1
    },
    {
      "x": 1,
      "y": 8,
      "z": -2,
      "name": "Water_Source",
      "level": 1
    },
    {
      "x": 1,
      "y": 9,
      "z": -2,
      "name": "Water_Source",
      "level": 1
    },
    {
      "x": 1,
      "y": 10,
      "z": -2,
      "name": "Water_Source",
      "level": 1
    },
    {
      "x": 1,
      "y": 11,
      "z": -2,
      "name": "Water_Source",
      "level": 1
    },
    {
      "x": 1,
      "y": 12,
      "z": -2,
      "name": "Water_Source",
      "level": 1
    },
    {
      "x": 1,
      "y": 13,
      "z": -2,
      "name": "Water_Source",
      "level": 1
    },
    {
      "x": 1,
      "y": 14,
      "z": -2,
      "name": "Water_Source",
      "level": 1
    },
    {
      "x": 1,
      "y": 1,
      "z": -1,
      "name": "Water_Source",
      "level": 1
    },
    {
      "x": 1,
      "y": 2,
      "z": -1,
      "name": "Water_Source",
      "level": 1
    },
    {
      "x": 1,
      "y": 3,
      "z": -1,
      "name": "Water_Source",
      "level": 1
    },
    {
      "x": 1,
      "y": 4,
      "z": -1,
      "name": "Water_Source",
      "level": 1
    },
    {
      "x": 1,
      "y": 5,
      "z": -1,
      "name": "Water_Source",
      "level": 1
    },
    {
      "x": 1,
      "y": 6,
      "z": -1,
      "name": "Water_Source",
      "level": 1
    },
    {
      "x": 1,
      "y": 7,
      "z": -1,
      "name": "Water_Source",
      "level": 1
    },
    {
      "x": 1,
      "y": 8,
      "z": -1,
      "name": "Water_Source",
      "level": 1
    },
    {
      "x": 1,
      "y": 9,
      "z": -1,
      "name": "Water_Source",
      "level": 1
    },
    {
      "x": 1,
      "y": 10,
      "z": -1,
      "name": "Water_Source",
      "level": 1
    },
    {
      "x": 1,
      "y": 11,
      "z": -1,
      "name": "Water_Source",
      "level": 1
    },
    {
      "x": 1,
      "y": 12,
      "z": -1,
      "name": "Water_Source",
      "level": 1
    },
    {
      "x": 1,
      "y": 13,
      "z": -1,
      "name": "Water_Source",
      "level": 1
    },
    {
      "x": 1,
      "y": 14,
      "z": -1,
      "name": "Water_Source",
      "level": 1
    },
    {
      "x": 1,
      "y": 1,
      "z": 0,
      "name": "Water_Source",
      "level": 1
    },
    {
      "x": 1,
      "y": 2,
      "z": 0,
      "name": "Water_Source",
      "level": 1
    },
    {
      "x": 1,
      "y": 3,
      "z": 0,
      "name": "Water_Source",
      "level": 1
    },
    {
      "x": 1,
      "y": 4,
      "z": 0,
      "name": "Water_Source",
      "level": 1
    },
    {
      "x": 1,
      "y": 5,
      "z": 0,
      "name": "Water_Source",
      "level": 1
    },
    {
      "x": 1,
      "y": 6,
      "z": 0,
      "name": "Water_Source",
      "level": 1
    },
    {
      "x": 1,
      "y": 7,
      "z": 0,
      "name": "Water_Source",
      "level": 1
    },
    {
      "x": 1,
      "y": 8,
      "z": 0,
      "name": "Water_Source",
      "level": 1
    },
    {
      "x": 1,
      "y": 9,
      "z": 0,
      "name": "Water_Source",
      "level": 1
    },
    {
      "x": 1,
      "y": 10,
      "z": 0,
      "name": "Water_Source",
      "level": 1
    },
    {
      "x": 1,
      "y": 11,
      "z": 0,
      "name": "Water_Source",
      "level": 1
    },
    {
      "x": 1,
      "y": 12,
      "z": 0,
      "name": "Water_Source",
      "level": 1
    },
    {
      "x": 1,
      "y": 13,
      "z": 0,
      "name": "Water_Source",
      "level": 1
    },
    {
      "x": 1,
      "y": 14,
      "z": 0,
      "name": "Water_Source",
      "level": 1
    },
    {
      "x": 2,
      "y": 1,
      "z": -9,
      "name": "Water_Source",
      "level": 1
    },
    {
      "x": 2,
      "y": 2,
      "z": -9,
      "name": "Water_Source",
      "level": 1
    },
    {
      "x": 2,
      "y": 3,
      "z": -9,
      "name": "Water_Source",
      "level": 1
    },
    {
      "x": 2,
      "y": 4,
      "z": -9,
      "name": "Water_Source",
      "level": 1
    },
    {
      "x": 2,
      "y": 5,
      "z": -9,
      "name": "Water_Source",
      "level": 1
    },
    {
      "x": 2,
      "y": 6,
      "z": -9,
      "name": "Water_Source",
      "level": 1
    },
    {
      "x": 2,
      "y": 7,
      "z": -9,
      "name": "Water_Source",
      "level": 1
    },
    {
      "x": 2,
      "y": 8,
      "z": -9,
      "name": "Water_Source",
      "level": 1
    },
    {
      "x": 2,
      "y": 9,
      "z": -9,
      "name": "Water_Source",
      "level": 1
    },
    {
      "x": 2,
      "y": 10,
      "z": -9,
      "name": "Water_Source",
      "level": 1
    },
    {
      "x": 2,
      "y": 11,
      "z": -9,
      "name": "Water_Source",
      "level": 1
    },
    {
      "x": 2,
      "y": 12,
      "z": -9,
      "name": "Water_Source",
      "level": 1
    },
    {
      "x": 2,
      "y": 13,
      "z": -9,
      "name": "Water_Source",
      "level": 1
    },
    {
      "x": 2,
      "y": 14,
      "z": -9,
      "name": "Water_Source",
      "level": 1
    },
    {
      "x": 2,
      "y": 1,
      "z": -8,
      "name": "Water_Source",
      "level": 1
    },
    {
      "x": 2,
      "y": 2,
      "z": -8,
      "name": "Water_Source",
      "level": 1
    },
    {
      "x": 2,
      "y": 3,
      "z": -8,
      "name": "Water_Source",
      "level": 1
    },
    {
      "x": 2,
      "y": 4,
      "z": -8,
      "name": "Water_Source",
      "level": 1
    },
    {
      "x": 2,
      "y": 5,
      "z": -8,
      "name": "Water_Source",
      "level": 1
    },
    {
      "x": 2,
      "y": 6,
      "z": -8,
      "name": "Water_Source",
      "level": 1
    },
    {
      "x": 2,
      "y": 7,
      "z": -8,
      "name": "Water_Source",
      "level": 1
    },
    {
      "x": 2,
      "y": 8,
      "z": -8,
      "name": "Water_Source",
      "level": 1
    },
    {
      "x": 2,
      "y": 9,
      "z": -8,
      "name": "Water_Source",
      "level": 1
    },
    {
      "x": 2,
      "y": 10,
      "z": -8,
      "name": "Water_Source",
      "level": 1
    },
    {
      "x": 2,
      "y": 11,
      "z": -8,
      "name": "Water_Source",
      "level": 1
    },
    {
      "x": 2,
      "y": 12,
      "z": -8,
      "name": "Water_Source",
      "level": 1
    },
    {
      "x": 2,
      "y": 13,
      "z": -8,
      "name": "Water_Source",
      "level": 1
    },
    {
      "x": 2,
      "y": 14,
      "z": -8,
      "name": "Water_Source",
      "level": 1
    },
    {
      "x": 2,
      "y": 1,
      "z": -7,
      "name": "Water_Source",
      "level": 1
    },
    {
      "x": 2,
      "y": 2,
      "z": -7,
      "name": "Water_Source",
      "level": 1
    },
    {
      "x": 2,
      "y": 3,
      "z": -7,
      "name": "Water_Source",
      "level": 1
    },
    {
      "x": 2,
      "y": 4,
      "z": -7,
      "name": "Water_Source",
      "level": 1
    },
    {
      "x": 2,
      "y": 5,
      "z": -7,
      "name": "Water_Source",
      "level": 1
    },
    {
      "x": 2,
      "y": 6,
      "z": -7,
      "name": "Water_Source",
      "level": 1
    },
    {
      "x": 2,
      "y": 7,
      "z": -7,
      "name": "Water_Source",
      "level": 1
    },
    {
      "x": 2,
      "y": 8,
      "z": -7,
      "name": "Water_Source",
      "level": 1
    },
    {
      "x": 2,
      "y": 9,
      "z": -7,
      "name": "Water_Source",
      "level": 1
    },
    {
      "x": 2,
      "y": 10,
      "z": -7,
      "name": "Water_Source",
      "level": 1
    },
    {
      "x": 2,
      "y": 11,
      "z": -7,
      "name": "Water_Source",
      "level": 1
    },
    {
      "x": 2,
      "y": 12,
      "z": -7,
      "name": "Water_Source",
      "level": 1
    },
    {
      "x": 2,
      "y": 13,
      "z": -7,
      "name": "Water_Source",
      "level": 1
    },
    {
      "x": 2,
      "y": 14,
      "z": -7,
      "name": "Water_Source",
      "level": 1
    },
    {
      "x": 2,
      "y": 1,
      "z": -6,
      "name": "Water_Source",
      "level": 1
    },
    {
      "x": 2,
      "y": 2,
      "z": -6,
      "name": "Water_Source",
      "level": 1
    },
    {
      "x": 2,
      "y": 3,
      "z": -6,
      "name": "Water_Source",
      "level": 1
    },
    {
      "x": 2,
      "y": 4,
      "z": -6,
      "name": "Water_Source",
      "level": 1
    },
    {
      "x": 2,
      "y": 5,
      "z": -6,
      "name": "Water_Source",
      "level": 1
    },
    {
      "x": 2,
      "y": 6,
      "z": -6,
      "name": "Water_Source",
      "level": 1
    },
    {
      "x": 2,
      "y": 7,
      "z": -6,
      "name": "Water_Source",
      "level": 1
    },
    {
      "x": 2,
      "y": 8,
      "z": -6,
      "name": "Water_Source",
      "level": 1
    },
    {
      "x": 2,
      "y": 9,
      "z": -6,
      "name": "Water_Source",
      "level": 1
    },
    {
      "x": 2,
      "y": 10,
      "z": -6,
      "name": "Water_Source",
      "level": 1
    },
    {
      "x": 2,
      "y": 11,
      "z": -6,
      "name": "Water_Source",
      "level": 1
    },
    {
      "x": 2,
      "y": 12,
      "z": -6,
      "name": "Water_Source",
      "level": 1
    },
    {
      "x": 2,
      "y": 13,
      "z": -6,
      "name": "Water_Source",
      "level": 1
    },
    {
      "x": 2,
      "y": 14,
      "z": -6,
      "name": "Water_Source",
      "level": 1
    },
    {
      "x": 2,
      "y": 1,
      "z": -5,
      "name": "Water_Source",
      "level": 1
    },
    {
      "x": 2,
      "y": 2,
      "z": -5,
      "name": "Water_Source",
      "level": 1
    },
    {
      "x": 2,
      "y": 3,
      "z": -5,
      "name": "Water_Source",
      "level": 1
    },
    {
      "x": 2,
      "y": 4,
      "z": -5,
      "name": "Water_Source",
      "level": 1
    },
    {
      "x": 2,
      "y": 5,
      "z": -5,
      "name": "Water_Source",
      "level": 1
    },
    {
      "x": 2,
      "y": 6,
      "z": -5,
      "name": "Water_Source",
      "level": 1
    },
    {
      "x": 2,
      "y": 7,
      "z": -5,
      "name": "Water_Source",
      "level": 1
    },
    {
      "x": 2,
      "y": 8,
      "z": -5,
      "name": "Water_Source",
      "level": 1
    },
    {
      "x": 2,
      "y": 9,
      "z": -5,
      "name": "Water_Source",
      "level": 1
    },
    {
      "x": 2,
      "y": 10,
      "z": -5,
      "name": "Water_Source",
      "level": 1
    },
    {
      "x": 2,
      "y": 11,
      "z": -5,
      "name": "Water_Source",
      "level": 1
    },
    {
      "x": 2,
      "y": 12,
      "z": -5,
      "name": "Water_Source",
      "level": 1
    },
    {
      "x": 2,
      "y": 13,
      "z": -5,
      "name": "Water_Source",
      "level": 1
    },
    {
      "x": 2,
      "y": 14,
      "z": -5,
      "name": "Water_Source",
      "level": 1
    },
    {
      "x": 2,
      "y": 1,
      "z": -4,
