{
  "version": 8,
  "blockIdVersion": 11,
  "anchorX": 0,
  "anchorY": 0,
  "anchorZ": 0,
  "blocks": [
    {
      "x": -4,
      "y": 0,
      "z": -3,
      "name": "Rock_Sandstone_Cobble_Stairs",
      "rotation": 3
    },
    {
      "x": -4,
      "y": 0,
      "z": -2,
      "name": "Rock_Sandstone_Brick_Pillar_Base"
    },
    {
      "x": -4,
      "y": 3,
      "z": -2,
      "name": "Rock_Sandstone_Brick"
    },
    {
      "x": -4,
      "y": 4,
      "z": -2,
      "name": "Soil_Clay_Ocean_Brick_Smooth_Half"
    },
    {
      "x": -4,
      "y": 0,
      "z": -1,
      "name": "Rock_Sandstone_Cobble"
    },
    {
      "x": -4,
      "y": 1,
      "z": -1,
      "name": "Rock_Sandstone_Brick"
    },
    {
      "x": -4,
      "y": 2,
      "z": -1,
      "name": "Rock_Sandstone_Brick"
    },
    {
      "x": -4,
      "y": 3,
      "z": -1,
      "name": "Rock_Sandstone_Brick"
    },
    {
      "x": -4,
      "y": 4,
      "z": -1,
      "name": "Rock_Sandstone_Brick"
    },
    {
      "x": -4,
      "y": 5,
      "z": -1,
      "name": "Soil_Clay_Ocean_Brick_Roof",
      "rotation": 3
    },
    {
      "x": -4,
      "y": 0,
      "z": 0,
      "name": "Rock_Sandstone_Brick"
    },
    {
      "x": -4,
      "y": 4,
      "z": 0,
      "name": "Rock_Sandstone_Brick"
    },
    {
      "x": -4,
      "y": 5,
      "z": 0,
      "name": "Soil_Clay_Ocean_Brick_Roof",
      "rotation": 3
    },
    {
      "x": -4,
      "y": 0,
      "z": 1,
      "name": "Rock_Sandstone_Brick"
    },
    {
      "x": -4,
      "y": 1,
      "z": 1,
      "name": "Rock_Sandstone_Brick"
    },
    {
      "x": -4,
      "y": 4,
      "z": 1,
      "name": "Rock_Sandstone_Brick"
    },
    {
      "x": -4,
      "y": 5,
      "z": 1,
      "name": "Soil_Clay_Ocean_Brick_Roof",
      "rotation": 3
    },
    {
      "x": -4,
      "y": 0,
      "z": 2,
      "name": "Rock_Sandstone_Brick"
    },
    {
      "x": -4,
      "y": 1,
      "z": 2,
      "name": "Rock_Sandstone_Brick"
    },
    {
      "x": -4,
      "y": 2,
      "z": 2,
      "name": "Rock_Sandstone_Brick"
    },
    {
      "x": -4,
      "y": 3,
      "z": 2,
      "name": "Rock_Sandstone_Brick"
    },
    {
      "x": -4,
      "y": 4,
      "z": 2,
      "name": "Rock_Sandstone_Brick"
    },
    {
      "x": -4,
      "y": 5,
      "z": 2,
      "name": "Soil_Clay_Ocean_Brick_Roof",
      "rotation": 3
    },
    {
      "x": -4,
      "y": 0,
      "z": 3,
      "name": "Rock_Sandstone_Brick_Pillar_Base"
    },
    {
      "x": -4,
      "y": 1,
      "z": 3,
      "name": "Rock_Sandstone_Brick_Pillar_Middle"
    },
    {
      "x": -4,
      "y": 4,
      "z": 3,
      "name": "Rock_Sandstone_Brick"
    },
    {
      "x": -4,
      "y": 5,
      "z": 3,
      "name": "Soil_Clay_Ocean_Brick_Roof",
      "rotation": 3
    },
    {
      "x": -4,
      "y": 0,
      "z": 4,
      "name": "Rock_Sandstone_Cobble_Stairs",
      "rotation": 3
    },
    {
      "x": -4,
      "y": 4,
      "z": 4,
      "name": "Rock_Sandstone_Brick"
    },
    {
      "x": -4,
      "y": 5,
      "z": 4,
      "name": "Soil_Clay_Ocean_Brick_Roof",
      "rotation": 3
    },
    {
      "x": -4,
      "y": 4,
      "z": 5,
      "name": "Rock_Sandstone_Brick_Half",
      "rotation": 8
    },
    {
      "x": -4,
      "y": 5,
      "z": 5,
      "name": "*Soil_Clay_Ocean_Brick_Roof_State_Definitions_Corner_Left",
      "rotation": 3
    },
    {
      "x": -3,
      "y": 0,
      "z": -4,
      "name": "Rock_Sandstone_Brick_Stairs",
      "rotation": 2
    },
    {
      "x": -3,
      "y": 0,
      "z": -3,
      "name": "Rock_Sandstone_Brick"
    },
    {
      "x": -3,
      "y": 1,
      "z": -3,
      "name": "Rock_Sandstone_Cobble"
    },
    {
      "x": -3,
      "y": 2,
      "z": -3,
      "name": "Rock_Sandstone_Cobble"
    },
    {
      "x": -3,
      "y": 3,
      "z": -3,
      "name": "Rock_Sandstone_Brick"
    },
    {
      "x": -3,
      "y": 0,
      "z": -2,
      "name": "Soil_Clay_Ocean_Brick_Ornate"
    },
    {
      "x": -3,
      "y": 1,
      "z": -2,
      "name": "Soil_Clay_Ocean_Brick_Roof"
    },
    {
      "x": -3,
      "y": 0,
      "z": -1,
      "name": "Soil_Clay_Ocean_Brick_Stairs"
    },
    {
      "x": -3,
      "y": 6,
      "z": 0,
      "name": "Soil_Clay_Ocean_Brick_Ornate"
    },
    {
      "x": -3,
      "y": 6,
      "z": 2,
      "name": "Soil_Clay_Ocean_Brick_Ornate"
    },
    {
      "x": -3,
      "y": 6,
      "z": 3,
      "name": "Soil_Clay_Ocean_Brick_Ornate"
    },
    {
      "x": -3,
      "y": 0,
      "z": 4,
      "name": "Rock_Sandstone_Brick"
    },
    {
      "x": -3,
      "y": 1,
      "z": 4,
      "name": "Rock_Sandstone_Brick_Stairs",
      "rotation": 1
    },
    {
      "x": -3,
      "y": 2,
      "z": 4,
      "name": "Rock_Sandstone_Brick_Stairs",
      "rotation": 2
    },
    {
      "x": -3,
      "y": 3,
      "z": 4,
      "name": "Rock_Sandstone_Brick_Stairs",
      "rotation": 9
    },
    {
      "x": -3,
      "y": 5,
      "z": 4,
      "name": "Soil_Clay_Ocean_Brick_Smooth_Half",
      "rotation": 8
    },
    {
      "x": -3,
      "y": 0,
      "z": 5,
      "name": "Rock_Sandstone_Brick_Stairs"
    },
    {
      "x": -3,
      "y": 4,
      "z": 5,
      "name": "Rock_Sandstone_Brick"
    },
    {
      "x": -3,
      "y": 5,
      "z": 5,
      "name": "Soil_Clay_Ocean_Brick_Roof"
    },
    {
      "x": -2,
      "y": 0,
      "z": -4,
      "name": "Rock_Sandstone_Brick_Pillar_Base"
    },
    {
      "x": -2,
      "y": 1,
      "z": -4,
      "name": "Rock_Sandstone_Brick_Pillar_Middle"
    },
    {
      "x": -2,
      "y": 2,
      "z": -4,
      "name": "Rock_Sandstone_Brick_Pillar_Base",
      "rotation": 8
    },
    {
      "x": -2,
      "y": 3,
      "z": -4,
      "name": "Rock_Sandstone_Brick"
    },
    {
      "x": -2,
      "y": 4,
      "z": -4,
      "name": "Rock_Sandstone_Brick"
    },
    {
      "x": -2,
      "y": 0,
      "z": -3,
      "name": "Soil_Clay_Ocean_Brick_Smooth_Half",
      "rotation": 4
    },
    {
      "x": -2,
      "y": 0,
      "z": 0,
      "name": "Soil_Clay_Ocean_Brick_Smooth_Half"
    },
    {
      "x": -2,
      "y": 6,
      "z": 4,
      "name": "Soil_Clay_Ocean_Brick_Ornate"
    },
    {
      "x": -2,
      "y": 0,
      "z": 5,
      "name": "Rock_Sandstone_Brick_Pillar_Base"
    },
    {
      "x": -2,
      "y": 1,
      "z": 5,
      "name": "Rock_Sandstone_Brick_Pillar_Middle"
    },
    {
      "x": -2,
      "y": 2,
      "z": 5,
      "name": "Rock_Sandstone_Brick_Pillar_Base",
      "rotation": 8
    },
    {
      "x": -2,
      "y": 3,
      "z": 5,
      "name": "Rock_Sandstone_Brick"
    },
    {
      "x": -2,
      "y": 4,
      "z": 5,
      "name": "Rock_Sandstone_Brick"
    },
    {
      "x": -2,
      "y": 5,
      "z": 5,
      "name": "Soil_Clay_Ocean_Brick_Roof"
    },
    {
      "x": -1,
      "y": 0,
      "z": -4,
      "name": "Rock_Sandstone_Cobble_Half",
      "rotation": 5
    },
    {
      "x": -1,
      "y": 1,
      "z": -4,
      "name": "Rock_Sandstone_Cobble_Stairs",
      "rotation": 11
    },
    {
      "x": -1,
      "y": 2,
      "z": -4,
      "name": "Rock_Sandstone_Brick"
    },
    {
      "x": -1,
      "y": 3,
      "z": -4,
      "name": "Rock_Sandstone_Brick"
    },
    {
      "x": -1,
      "y": 4,
      "z": -4,
      "name": "Rock_Sandstone_Brick"
    },
    {
      "x": -1,
      "y": 5,
      "z": -4,
      "name": "Soil_Clay_Ocean_Brick_Roof",
      "rotation": 2
    },
    {
      "x": -1,
      "y": 0,
      "z": 1,
      "name": "Soil_Clay_Ocean_Brick_Roof_Flat",
      "rotation": 3
    },
    {
      "x": -1,
      "y": 0,
      "z": 2,
      "name": "Soil_Clay_Ocean_Brick_Roof_Flat"
    },
    {
      "x": -1,
      "y": 6,
      "z": 4,
      "name": "Soil_Clay_Ocean_Brick_Ornate"
    },
    {
      "x": -1,
      "y": 0,
      "z": 5,
      "name": "Rock_Sandstone_Brick"
    },
    {
      "x": -1,
      "y": 1,
      "z": 5,
      "name": "Rock_Sandstone_Brick"
    },
    {
      "x": -1,
      "y": 2,
      "z": 5,
      "name": "Rock_Sandstone_Cobble"
    },
    {
      "x": -1,
      "y": 3,
      "z": 5,
      "name": "Rock_Sandstone_Brick"
    },
    {
      "x": -1,
      "y": 4,
      "z": 5,
      "name": "Rock_Sandstone_Brick"
    },
    {
      "x": -1,
      "y": 5,
      "z": 5,
      "name": "Soil_Clay_Ocean_Brick_Roof"
    },
    {
      "x": 0,
      "y": 0,
      "z": -4,
      "name": "Rubble_Sandstone",
      "support": 15
    },
    {
      "x": 0,
      "y": 2,
      "z": -4,
      "name": "Rock_Sandstone_Brick"
    },
    {
      "x": 0,
      "y": 3,
      "z": -4,
      "name": "Rock_Sandstone_Brick"
    },
    {
      "x": 0,
      "y": 4,
      "z": -4,
      "name": "Rock_Sandstone_Brick"
    },
    {
      "x": 0,
      "y": 5,
      "z": -4,
      "name": "Soil_Clay_Ocean_Brick_Roof",
      "rotation": 2
    },
    {
      "x": 0,
      "y": 0,
      "z": -3,
      "name": "Rubble_Sandstone",
      "support": 15
    },
    {
      "x": 0,
      "y": 6,
      "z": -3,
      "name": "Soil_Clay_Ocean_Brick_Ornate"
    },
    {
      "x": 0,
      "y": 0,
      "z": 5,
      "name": "Rock_Sandstone_Brick"
    },
    {
      "x": 0,
      "y": 1,
      "z": 5,
      "name": "Rock_Sandstone_Brick"
    },
    {
      "x": 0,
      "y": 2,
      "z": 5,
      "name": "Rock_Sandstone_Cobble"
    },
    {
      "x": 0,
      "y": 3,
      "z": 5,
      "name": "Rock_Sandstone_Brick"
    },
    {
      "x": 0,
      "y": 4,
      "z": 5,
      "name": "Rock_Sandstone_Brick"
    },
    {
      "x": 0,
      "y": 5,
      "z": 5,
      "name": "Soil_Clay_Ocean_Brick_Roof"
    },
    {
      "x": 1,
      "y": 0,
      "z": -4,
      "name": "Rubble_Sandstone",
      "support": 15
    },
    {
      "x": 1,
      "y": 2,
      "z": -4,
      "name": "Rock_Sandstone_Cobble"
    },
    {
      "x": 1,
      "y": 3,
      "z": -4,
      "name": "Rock_Sandstone_Brick"
    },
    {
      "x": 1,
      "y": 4,
      "z": -4,
      "name": "Rock_Sandstone_Brick"
    },
    {
      "x": 1,
      "y": 5,
      "z": -4,
      "name": "Soil_Clay_Ocean_Brick_Roof",
      "rotation": 2
    },
    {
      "x": 1,
      "y": 6,
      "z": -3,
      "name": "Soil_Clay_Ocean_Brick_Ornate"
    },
    {
      "x": 1,
      "y": 0,
      "z": 0,
      "name": "Soil_Clay_Ocean_Brick_Roof_Flat",
      "rotation": 2
    },
    {
      "x": 1,
      "y": 0,
      "z": 1,
      "name": "Soil_Clay_Ocean_Brick_Stairs",
      "rotation": 2
    },
    {
      "x": 1,
      "y": 0,
      "z": 2,
      "name": "Soil_Clay_Ocean_Brick_Ornate"
    },
    {
      "x": 1,
      "y": 6,
      "z": 4,
      "name": "Soil_Clay_Ocean_Brick_Ornate"
    },
    {
      "x": 1,
      "y": 0,
      "z": 5,
      "name": "Rock_Sandstone_Cobble"
    },
    {
      "x": 1,
      "y": 1,
      "z": 5,
      "name": "Rock_Sandstone_Brick"
    },
    {
      "x": 1,
      "y": 2,
      "z": 5,
      "name": "Rock_Sandstone_Brick"
    },
    {
      "x": 1,
      "y": 3,
      "z": 5,
      "name": "Rock_Sandstone_Brick"
    },
    {
      "x": 1,
      "y": 4,
      "z": 5,
      "name": "Rock_Sandstone_Brick"
    },
    {
      "x": 1,
      "y": 5,
      "z": 5,
      "name": "Soil_Clay_Ocean_Brick_Roof"
    },
    {
      "x": 2,
      "y": 3,
      "z": -4,
      "name": "Rock_Sandstone_Brick"
    },
    {
      "x": 2,
      "y": 4,
      "z": -4,
      "name": "Rock_Sandstone_Brick"
    },
    {
      "x": 2,
      "y": 5,
      "z": -4,
      "name": "Soil_Clay_Ocean_Brick_Roof",
      "rotation": 2
    },
    {
      "x": 2,
      "y": 5,
      "z": -3,
      "name": "Soil_Clay_Ocean_Stalactite_Small",
      "rotation": 8
    },
    {
      "x": 2,
      "y": 6,
      "z": -3,
      "name": "Soil_Clay_Ocean_Brick_Ornate"
    },
    {
      "x": 2,
      "y": 0,
      "z": -2,
      "name": "Soil_Clay_Ocean_Brick_Smooth_Half"
    },
    {
      "x": 2,
      "y": 7,
      "z": -2,
      "name": "Soil_Clay_Ocean_Brick_Stairs",
      "rotation": 2
    },
    {
      "x": 2,
      "y": 6,
      "z": 4,
      "name": "Soil_Clay_Ocean_Brick_Ornate"
    },
    {
      "x": 2,
      "y": 0,
      "z": 5,
      "name": "Rock_Sandstone_Brick"
    },
    {
      "x": 2,
      "y": 1,
      "z": 5,
      "name": "Rock_Sandstone_Brick"
    },
    {
      "x": 2,
      "y": 2,
      "z": 5,
      "name": "Rock_Sandstone_Brick"
    },
    {
      "x": 2,
      "y": 3,
      "z": 5,
      "name": "Rock_Sandstone_Brick"
    },
    {
      "x": 2,
      "y": 4,
      "z": 5,
      "name": "Rock_Sandstone_Brick"
    },
    {
      "x": 2,
      "y": 5,
      "z": 5,
      "name": "Soil_Clay_Ocean_Brick_Roof"
    },
    {
      "x": 3,
      "y": 0,
      "z": -4,
      "name": "Rock_Sandstone_Brick_Pillar_Base"
    },
    {
      "x": 3,
      "y": 1,
      "z": -4,
      "name": "Rock_Sandstone_Brick_Pillar_Middle"
    },
    {
      "x": 3,
      "y": 2,
      "z": -4,
      "name": "Rock_Sandstone_Brick_Pillar_Base",
      "rotation": 8
    },
    {
      "x": 3,
      "y": 3,
      "z": -4,
      "name": "Rock_Sandstone_Brick"
    },
    {
      "x": 3,
      "y": 4,
      "z": -4,
      "name": "Rock_Sandstone_Brick"
    },
    {
      "x": 3,
      "y": 5,
      "z": -4,
      "name": "Soil_Clay_Ocean_Brick_Roof",
      "rotation": 2
    },
    {
      "x": 3,
      "y": 6,
      "z": -3,
      "name": "Soil_Clay_Ocean_Brick_Ornate"
    },
    {
      "x": 3,
      "y": 0,
      "z": -2,
      "name": "Soil_Clay_Ocean_Brick_Roof_Flat",
      "rotation": 3
    },
    {
      "x": 3,
      "y": 6,
      "z": -2,
      "name": "Soil_Clay_Ocean_Brick_Ornate"
    },
    {
      "x": 3,
      "y": 7,
      "z": -1,
      "name": "Soil_Clay_Ocean_Brick_Stairs",
      "rotation": 1
    },
    {
      "x": 3,
      "y": 6,
      "z": 3,
      "name": "Soil_Clay_Ocean_Brick_Ornate"
    },
    {
      "x": 3,
      "y": 6,
      "z": 4,
      "name": "Soil_Clay_Ocean_Brick_Ornate"
    },
    {
      "x": 3,
      "y": 0,
      "z": 5,
      "name": "Rock_Sandstone_Brick_Pillar_Base"
    },
    {
      "x": 3,
      "y": 1,
      "z": 5,
      "name": "Rock_Sandstone_Brick_Pillar_Middle"
    },
    {
      "x": 3,
      "y": 2,
      "z": 5,
      "name": "Rock_Sandstone_Brick_Pillar_Base",
      "rotation": 8
    },
    {
      "x": 3,
      "y": 3,
      "z": 5,
      "name": "Rock_Sandstone_Brick"
    },
    {
      "x": 3,
      "y": 4,
      "z": 5,
      "name": "Rock_Sandstone_Brick"
    },
    {
      "x": 3,
      "y": 5,
      "z": 5,
      "name": "Soil_Clay_Ocean_Brick_Roof"
    },
    {
      "x": 4,
      "y": 0,
      "z": -4,
      "name": "Rock_Sandstone_Brick_Stairs",
      "rotation": 2
    },
    {
      "x": 4,
      "y": 4,
      "z": -4,
      "name": "Rock_Sandstone_Brick"
    },
    {
      "x": 4,
      "y": 5,
      "z": -4,
      "name": "Soil_Clay_Ocean_Brick_Roof",
      "rotation": 2
    },
    {
      "x": 4,
      "y": 0,
      "z": -3,
      "name": "Rock_Sandstone_Brick"
    },
    {
      "x": 4,
      "y": 1,
      "z": -3,
      "name": "Rock_Sandstone_Brick"
    },
    {
      "x": 4,
      "y": 2,
      "z": -3,
      "name": "Rubble_Sandstone",
      "support": 15
    },
    {
      "x": 4,
      "y": 5,
      "z": -3,
      "name": "Soil_Clay_Ocean_Brick_Smooth_Half",
      "rotation": 8
    },
    {
      "x": 4,
      "y": 6,
      "z": -2,
      "name": "Soil_Clay_Ocean_Brick_Ornate"
    },
    {
      "x": 4,
      "y": 6,
      "z": -1,
      "name": "Soil_Clay_Ocean_Brick_Ornate"
    },
    {
      "x": 4,
      "y": 6,
      "z": 0,
      "name": "Soil_Clay_Ocean_Brick_Ornate"
    },
    {
      "x": 4,
      "y": 6,
      "z": 1,
      "name": "Soil_Clay_Ocean_Brick_Ornate"
    },
    {
      "x": 4,
      "y": 6,
      "z": 2,
      "name": "Soil_Clay_Ocean_Brick_Ornate"
    },
    {
      "x": 4,
      "y": 6,
      "z": 3,
      "name": "Soil_Clay_Ocean_Brick_Ornate"
    },
    {
      "x": 4,
      "y": 0,
      "z": 4,
      "name": "Rubble_Sandstone",
      "support": 15
    },
    {
      "x": 4,
      "y": 5,
      "z": 4,
      "name": "Soil_Clay_Ocean_Brick_Smooth_Half",
      "rotation": 8
    },
    {
      "x": 4,
      "y": 4,
      "z": 5,
      "name": "Rock_Sandstone_Brick"
    },
    {
      "x": 4,
      "y": 5,
      "z": 5,
      "name": "Soil_Clay_Ocean_Brick_Roof"
    },
    {
      "x": 5,
      "y": 4,
      "z": -4,
      "name": "Rock_Sandstone_Brick_Half",
      "rotation": 8
    },
    {
      "x": 5,
      "y": 5,
      "z": -4,
      "name": "*Soil_Clay_Ocean_Brick_Roof_State_Definitions_Corner_Left",
      "rotation": 1
    },
    {
      "x": 5,
      "y": 0,
      "z": -3,
      "name": "Rock_Sandstone_Brick_Stairs",
      "rotation": 1
    },
    {
      "x": 5,
      "y": 4,
      "z": -3,
      "name": "Rock_Sandstone_Brick"
    },
    {
      "x": 5,
      "y": 5,
      "z": -3,
      "name": "Soil_Clay_Ocean_Brick_Roof",
      "rotation": 1
    },
    {
      "x": 5,
      "y": 0,
      "z": -2,
      "name": "Rock_Sandstone_Brick_Pillar_Base"
    },
    {
      "x": 5,
      "y": 1,
      "z": -2,
      "name": "Rock_Sandstone_Brick_Pillar_Middle"
    },
    {
      "x": 5,
      "y": 3,
      "z": -2,
      "name": "Rock_Sandstone_Brick"
    },
    {
      "x": 5,
      "y": 4,
      "z": -2,
      "name": "Rock_Sandstone_Brick"
    },
    {
      "x": 5,
      "y": 5,
      "z": -2,
      "name": "Soil_Clay_Ocean_Brick_Roof",
      "rotation": 1
    },
    {
      "x": 5,
      "y": 0,
      "z": -1,
      "name": "Rock_Sandstone_Cobble"
    },
    {
      "x": 5,
      "y": 1,
      "z": -1,
      "name": "Rock_Sandstone_Cobble"
    },
    {
      "x": 5,
      "y": 2,
      "z": -1,
      "name": "Rock_Sandstone_Cobble"
    },
    {
      "x": 5,
      "y": 3,
      "z": -1,
      "name": "Rock_Sandstone_Brick"
    },
    {
      "x": 5,
      "y": 4,
      "z": -1,
      "name": "Rock_Sandstone_Brick"
    },
    {
      "x": 5,
      "y": 5,
      "z": -1,
      "name": "Soil_Clay_Ocean_Brick_Roof",
      "rotation": 1
    },
    {
      "x": 5,
      "y": 0,
      "z": 0,
      "name": "Rock_Sandstone_Brick"
    },
    {
      "x": 5,
      "y": 1,
      "z": 0,
      "name": "Rock_Sandstone_Cobble"
    },
    {
      "x": 5,
      "y": 2,
      "z": 0,
      "name": "Rock_Sandstone_Brick"
    },
    {
      "x": 5,
      "y": 3,
      "z": 0,
      "name": "Rock_Sandstone_Brick"
    },
    {
      "x": 5,
      "y": 4,
      "z": 0,
      "name": "Rock_Sandstone_Brick"
    },
    {
      "x": 5,
      "y": 5,
      "z": 0,
      "name": "Soil_Clay_Ocean_Brick_Roof",
      "rotation": 1
    },
    {
      "x": 5,
      "y": 0,
      "z": 1,
      "name": "Rock_Sandstone_Brick"
    },
    {
      "x": 5,
      "y": 1,
      "z": 1,
      "name": "Rock_Sandstone_Brick"
    },
    {
      "x": 5,
      "y": 2,
      "z": 1,
      "name": "Rock_Sandstone_Cobble"
    },
    {
      "x": 5,
      "y": 3,
      "z": 1,
      "name": "Rock_Sandstone_Brick"
    },
    {
      "x": 5,
      "y": 4,
      "z": 1,
      "name": "Rock_Sandstone_Brick"
    },
    {
      "x": 5,
      "y": 5,
      "z": 1,
      "name": "Soil_Clay_Ocean_Brick_Roof",
      "rotation": 1
    },
    {
      "x": 5,
      "y": 0,
      "z": 2,
      "name": "Rock_Sandstone_Brick"
    },
    {
      "x": 5,
      "y": 1,
      "z": 2,
      "name": "Rock_Sandstone_Brick"
    },
    {
      "x": 5,
      "y": 2,
      "z": 2,
      "name": "Rock_Sandstone_Brick"
    },
    {
      "x": 5,
      "y": 3,
      "z": 2,
      "name": "Rock_Sandstone_Brick"
    },
    {
      "x": 5,
      "y": 4,
      "z": 2,
      "name": "Rock_Sandstone_Brick"
    },
    {
      "x": 5,
      "y": 5,
      "z": 2,
      "name": "Soil_Clay_Ocean_Brick_Roof",
      "rotation": 1
    },
    {
      "x": 5,
      "y": 0,
      "z": 3,
      "name": "Rock_Sandstone_Brick_Pillar_Base",
      "rotation": 4
    },
    {
      "x": 5,
      "y": 3,
      "z": 3,
      "name": "Rock_Sandstone_Brick"
    },
    {
      "x": 5,
      "y": 4,
      "z": 3,
      "name": "Rock_Sandstone_Brick"
    },
    {
      "x": 5,
      "y": 5,
      "z": 3,
      "name": "Soil_Clay_Ocean_Brick_Roof",
      "rotation": 1
    },
    {
      "x": 5,
      "y": 0,
      "z": 4,
      "name": "Rock_Sandstone_Brick_Pillar_Middle",
      "rotation": 4
    },
    {
      "x": 5,
      "y": 4,
      "z": 4,
      "name": "Rock_Sandstone_Brick"
    },
    {
      "x": 5,
      "y": 5,
      "z": 4,
      "name": "Soil_Clay_Ocean_Brick_Roof",
      "rotation": 1
    },
    {
      "x": 5,
      "y": 0,
      "z": 5,
      "name": "Rubble_Sandstone",
      "support": 15
    },
    {
      "x": 5,
      "y": 4,
      "z": 5,
      "name": "Rock_Sandstone_Brick_Half",
      "rotation": 8
    },
    {
      "x": 5,
      "y": 5,
      "z": 5,
      "name": "*Soil_Clay_Ocean_Brick_Roof_State_Definitions_Corner_Left"
    }
  ]
}