{
  "version": 8,
  "blockIdVersion": 11,
  "anchorX": 0,
  "anchorY": 1,
  "anchorZ": 0,
  "blocks": [
    {
      "x": 0,
      "y": 17,
      "z": -8,
      "name": "*Rock_Sandstone_Brick_Stairs_State_Definitions_Corner_Right",
      "rotation": 34
    },
    {
      "x": 0,
      "y": 18,
      "z": -8,
      "name": "*Rock_Sandstone_Brick_Wall_State_Definitions_Corner",
      "rotation": 1
    },
    {
      "x": 0,
      "y": 22,
      "z": -8,
      "name": "*Soil_Clay_Ocean_Brick_Roof_State_Definitions_Corner_Right",
      "rotation": 3
    },
    {
      "x": 0,
      "y": 1,
      "z": -7,
      "name": "Rock_Sandstone_Cobble",
      "rotation": 3
    },
    {
      "x": 0,
      "y": 2,
      "z": -7,
      "name": "Rock_Sandstone_Cobble",
      "rotation": 3
    },
    {
      "x": 0,
      "y": 3,
      "z": -7,
      "name": "Rock_Sandstone_Cobble",
      "rotation": 3
    },
    {
      "x": 0,
      "y": 4,
      "z": -7,
      "name": "Rock_Sandstone_Brick",
      "rotation": 3
    },
    {
      "x": 0,
      "y": 5,
      "z": -7,
      "name": "Rock_Sandstone_Brick",
      "rotation": 3
    },
    {
      "x": 0,
      "y": 6,
      "z": -7,
      "name": "Rock_Sandstone_Brick_Pillar_Base",
      "rotation": 3
    },
    {
      "x": 0,
      "y": 7,
      "z": -7,
      "name": "Rock_Sandstone_Brick_Half",
      "rotation": 3
    },
    {
      "x": 0,
      "y": 17,
      "z": -7,
      "name": "Rock_Sandstone_Brick_Stairs",
      "rotation": 35
    },
    {
      "x": 0,
      "y": 18,
      "z": -7,
      "name": "Rock_Sandstone_Brick_Wall",
      "rotation": 3
    },
    {
      "x": 0,
      "y": 22,
      "z": -7,
      "name": "Soil_Clay_Ocean_Brick_Roof",
      "rotation": 3
    },
    {
      "x": 0,
      "y": 1,
      "z": -6,
      "name": "Rock_Sandstone_Cobble",
      "rotation": 3
    },
    {
      "x": 0,
      "y": 2,
      "z": -6,
      "name": "Rock_Sandstone_Cobble",
      "rotation": 3
    },
    {
      "x": 0,
      "y": 3,
      "z": -6,
      "name": "Rock_Sandstone_Brick",
      "rotation": 3
    },
    {
      "x": 0,
      "y": 4,
      "z": -6,
      "name": "Rock_Sandstone_Brick",
      "rotation": 3
    },
    {
      "x": 0,
      "y": 5,
      "z": -6,
      "name": "Rock_Sandstone_Brick",
      "rotation": 3
    },
    {
      "x": 0,
      "y": 6,
      "z": -6,
      "name": "Rock_Sandstone_Brick_Pillar_Base",
      "rotation": 3
    },
    {
      "x": 0,
      "y": 7,
      "z": -6,
      "name": "Rock_Sandstone_Brick",
      "rotation": 3
    },
    {
      "x": 0,
      "y": 17,
      "z": -6,
      "name": "Rock_Sandstone_Brick_Stairs",
      "rotation": 35
    },
    {
      "x": 0,
      "y": 18,
      "z": -6,
      "name": "Rock_Sandstone_Brick_Wall",
      "rotation": 3
    },
    {
      "x": 0,
      "y": 22,
      "z": -6,
      "name": "Soil_Clay_Ocean_Brick_Roof",
      "rotation": 3
    },
    {
      "x": 0,
      "y": 1,
      "z": -5,
      "name": "Rock_Sandstone_Cobble",
      "rotation": 3
    },
    {
      "x": 0,
      "y": 2,
      "z": -5,
      "name": "Rock_Sandstone_Cobble",
      "rotation": 3
    },
    {
      "x": 0,
      "y": 3,
      "z": -5,
      "name": "Rock_Sandstone_Cobble",
      "rotation": 3
    },
    {
      "x": 0,
      "y": 4,
      "z": -5,
      "name": "Rock_Sandstone_Brick",
      "rotation": 3
    },
    {
      "x": 0,
      "y": 5,
      "z": -5,
      "name": "Rock_Sandstone_Brick",
      "rotation": 3
    },
    {
      "x": 0,
      "y": 6,
      "z": -5,
      "name": "Rock_Sandstone_Brick_Pillar_Base",
      "rotation": 3
    },
    {
      "x": 0,
      "y": 7,
      "z": -5,
      "name": "Rock_Sandstone_Brick",
      "rotation": 3
    },
    {
      "x": 0,
      "y": 8,
      "z": -5,
      "name": "Rock_Sandstone_Cobble_Stairs",
      "rotation": 3
    },
    {
      "x": 0,
      "y": 9,
      "z": -5,
      "name": "Rock_Sandstone_Cobble_Half",
      "rotation": 7
    },
    {
      "x": 0,
      "y": 17,
      "z": -5,
      "name": "Rock_Sandstone_Brick_Stairs",
      "rotation": 35
    },
    {
      "x": 0,
      "y": 18,
      "z": -5,
      "name": "Rock_Sandstone_Brick_Wall",
      "rotation": 3
    },
    {
      "x": 0,
      "y": 22,
      "z": -5,
      "name": "Soil_Clay_Ocean_Brick_Roof",
      "rotation": 3
    },
    {
      "x": 0,
      "y": 1,
      "z": -4,
      "name": "Rock_Sandstone_Cobble",
      "rotation": 3
    },
    {
      "x": 0,
      "y": 2,
      "z": -4,
      "name": "Rock_Sandstone_Cobble",
      "rotation": 3
    },
    {
      "x": 0,
      "y": 3,
      "z": -4,
      "name": "Rock_Sandstone_Cobble",
      "rotation": 3
    },
    {
      "x": 0,
      "y": 4,
      "z": -4,
      "name": "Rock_Sandstone_Cobble",
      "rotation": 3
    },
    {
      "x": 0,
      "y": 5,
      "z": -4,
      "name": "Rock_Sandstone_Brick",
      "rotation": 3
    },
    {
      "x": 0,
      "y": 6,
      "z": -4,
      "name": "Rock_Sandstone_Brick_Pillar_Base",
      "rotation": 3
    },
    {
      "x": 0,
      "y": 7,
      "z": -4,
      "name": "Rock_Sandstone_Brick",
      "rotation": 3
    },
    {
      "x": 0,
      "y": 8,
      "z": -4,
      "name": "Rock_Sandstone_Cobble_Stairs",
      "rotation": 3
    },
    {
      "x": 0,
      "y": 9,
      "z": -4,
      "name": "Rock_Sandstone_Cobble_Half",
      "rotation": 7
    },
    {
      "x": 0,
      "y": 14,
      "z": -4,
      "name": "Rock_Sandstone_Brick_Smooth_Half",
      "rotation": 3
    },
    {
      "x": 0,
      "y": 17,
      "z": -4,
      "name": "Rock_Sandstone_Brick_Stairs",
      "rotation": 35
    },
    {
      "x": 0,
      "y": 18,
      "z": -4,
      "name": "Rock_Sandstone_Brick_Wall",
      "rotation": 3
    },
    {
      "x": 0,
      "y": 22,
      "z": -4,
      "name": "Soil_Clay_Ocean_Brick_Roof",
      "rotation": 3
    },
    {
      "x": 0,
      "y": 1,
      "z": -3,
      "name": "Rock_Sandstone_Cobble",
      "rotation": 3
    },
    {
      "x": 0,
      "y": 2,
      "z": -3,
      "name": "Rock_Sandstone_Cobble",
      "rotation": 3
    },
    {
      "x": 0,
      "y": 3,
      "z": -3,
      "name": "Rock_Sandstone_Cobble",
      "rotation": 3
    },
    {
      "x": 0,
      "y": 4,
      "z": -3,
      "name": "Rock_Sandstone_Cobble",
      "rotation": 3
    },
    {
      "x": 0,
      "y": 5,
      "z": -3,
      "name": "Rock_Sandstone_Brick",
      "rotation": 3
    },
    {
      "x": 0,
      "y": 6,
      "z": -3,
      "name": "Rock_Sandstone_Brick_Pillar_Base",
      "rotation": 3
    },
    {
      "x": 0,
      "y": 7,
      "z": -3,
      "name": "Rock_Sandstone_Brick",
      "rotation": 3
    },
    {
      "x": 0,
      "y": 8,
      "z": -3,
      "name": "Rock_Sandstone_Cobble_Stairs",
      "rotation": 3
    },
    {
      "x": 0,
      "y": 9,
      "z": -3,
      "name": "Rock_Sandstone_Cobble_Half",
      "rotation": 7
    },
    {
      "x": 0,
      "y": 13,
      "z": -3,
      "name": "Rock_Sandstone_Brick_Smooth_Half",
      "rotation": 4
    },
    {
      "x": 0,
      "y": 17,
      "z": -3,
      "name": "Rock_Sandstone_Brick_Stairs",
      "rotation": 35
    },
    {
      "x": 0,
      "y": 18,
      "z": -3,
      "name": "Rock_Sandstone_Brick_Wall",
      "rotation": 3
    },
    {
      "x": 0,
      "y": 22,
      "z": -3,
      "name": "Soil_Clay_Ocean_Brick_Half",
      "rotation": 7
    },
    {
      "x": 0,
      "y": 1,
      "z": -2,
      "name": "Rock_Sandstone_Cobble",
      "rotation": 3
    },
    {
      "x": 0,
      "y": 2,
      "z": -2,
      "name": "Rock_Sandstone_Cobble",
      "rotation": 3
    },
    {
      "x": 0,
      "y": 3,
      "z": -2,
      "name": "Rock_Sandstone_Cobble",
      "rotation": 3
    },
    {
      "x": 0,
      "y": 4,
      "z": -2,
      "name": "Rock_Sandstone_Brick",
      "rotation": 3
    },
    {
      "x": 0,
      "y": 5,
      "z": -2,
      "name": "Rock_Sandstone_Brick",
      "rotation": 3
    },
    {
      "x": 0,
      "y": 6,
      "z": -2,
      "name": "Rock_Sandstone_Brick_Pillar_Base",
      "rotation": 3
    },
    {
      "x": 0,
      "y": 7,
      "z": -2,
      "name": "Rock_Sandstone_Brick",
      "rotation": 3
    },
    {
      "x": 0,
      "y": 17,
      "z": -2,
      "name": "Rock_Sandstone_Brick_Stairs",
      "rotation": 35
    },
    {
      "x": 0,
      "y": 1,
      "z": -1,
      "name": "Rock_Sandstone_Cobble",
      "rotation": 3
    },
    {
      "x": 0,
      "y": 2,
      "z": -1,
      "name": "Rock_Sandstone_Cobble",
      "rotation": 3
    },
    {
      "x": 0,
      "y": 3,
      "z": -1,
      "name": "Rock_Sandstone_Brick",
      "rotation": 3
    },
    {
      "x": 0,
      "y": 4,
      "z": -1,
      "name": "Rock_Sandstone_Brick",
      "rotation": 3
    },
    {
      "x": 0,
      "y": 5,
      "z": -1,
      "name": "Rock_Sandstone_Brick",
      "rotation": 3
    },
    {
      "x": 0,
      "y": 6,
      "z": -1,
      "name": "Rock_Sandstone_Brick_Pillar_Base",
      "rotation": 3
    },
    {
      "x": 0,
      "y": 7,
      "z": -1,
      "name": "Rock_Sandstone_Brick_Half",
      "rotation": 3
    },
    {
      "x": 0,
      "y": 17,
      "z": -1,
      "name": "Rock_Sandstone_Brick_Half",
      "rotation": 7
    },
    {
      "x": 1,
      "y": 1,
      "z": -9,
      "name": "Rock_Sandstone_Brick_Half"
    },
    {
      "x": 1,
      "y": 1,
      "z": -8,
      "name": "Rock_Sandstone_Cobble",
      "rotation": 3
    },
    {
      "x": 1,
      "y": 2,
      "z": -8,
      "name": "Rock_Sandstone_Cobble",
      "rotation": 3
    },
    {
      "x": 1,
      "y": 3,
      "z": -8,
      "name": "Rock_Sandstone_Brick",
      "rotation": 3
    },
    {
      "x": 1,
      "y": 4,
      "z": -8,
      "name": "Rock_Sandstone_Brick",
      "rotation": 3
    },
    {
      "x": 1,
      "y": 5,
      "z": -8,
      "name": "Rock_Sandstone_Brick",
      "rotation": 3
    },
    {
      "x": 1,
      "y": 6,
      "z": -8,
      "name": "Rock_Sandstone_Brick_Pillar_Base",
      "rotation": 3
    },
    {
      "x": 1,
      "y": 7,
      "z": -8,
      "name": "Rock_Sandstone_Brick_Half",
      "rotation": 3
    },
    {
      "x": 1,
      "y": 17,
      "z": -8,
      "name": "Rock_Sandstone_Brick_Stairs",
      "rotation": 34
    },
    {
      "x": 1,
      "y": 18,
      "z": -8,
      "name": "Rock_Sandstone_Brick_Wall"
    },
    {
      "x": 1,
      "y": 22,
      "z": -8,
      "name": "Soil_Clay_Ocean_Brick_Roof",
      "rotation": 2
    },
    {
      "x": 1,
      "y": 1,
      "z": -7,
      "name": "Rock_Sandstone_Cobble",
      "rotation": 3
    },
    {
      "x": 1,
      "y": 2,
      "z": -7,
      "name": "Rock_Sandstone_Cobble",
      "rotation": 3
    },
    {
      "x": 1,
      "y": 3,
      "z": -7,
      "name": "Rock_Sandstone_Brick",
      "rotation": 3
    },
    {
      "x": 1,
      "y": 4,
      "z": -7,
      "name": "Rock_Sandstone_Brick",
      "rotation": 3
    },
    {
      "x": 1,
      "y": 5,
      "z": -7,
      "name": "Rock_Sandstone_Brick",
      "rotation": 3
    },
    {
      "x": 1,
      "y": 6,
      "z": -7,
      "name": "Rock_Sandstone_Brick",
      "rotation": 3
    },
    {
      "x": 1,
      "y": 7,
      "z": -7,
      "name": "Rock_Sandstone_Brick",
      "rotation": 3
    },
    {
      "x": 1,
      "y": 16,
      "z": -7,
      "name": "Rock_Sandstone_Brick_Ornate",
      "rotation": 3
    },
    {
      "x": 1,
      "y": 17,
      "z": -7,
      "name": "Rock_Sandstone_Brick",
      "rotation": 3
    },
    {
      "x": 1,
      "y": 21,
      "z": -7,
      "name": "Rock_Sandstone_Brick_Ornate",
      "rotation": 3
    },
    {
      "x": 1,
      "y": 22,
      "z": -7,
      "name": "Soil_Clay_Ocean_Brick_Smooth",
      "rotation": 3
    },
    {
      "x": 1,
      "y": 23,
      "z": -7,
      "name": "*Soil_Clay_Ocean_Brick_Roof_State_Definitions_Corner_Right",
      "rotation": 3
    },
    {
      "x": 1,
      "y": 28,
      "z": -7,
      "name": "*Soil_Clay_Ocean_Brick_Roof_State_Definitions_Corner_Right",
      "rotation": 3
    },
    {
      "x": 1,
      "y": 1,
      "z": -6,
      "name": "Rock_Sandstone_Cobble",
      "rotation": 3
    },
    {
      "x": 1,
      "y": 2,
      "z": -6,
      "name": "Rock_Sandstone_Brick",
      "rotation": 3
    },
    {
      "x": 1,
      "y": 3,
      "z": -6,
      "name": "Rock_Sandstone_Brick",
      "rotation": 3
    },
    {
      "x": 1,
      "y": 4,
      "z": -6,
      "name": "Rock_Sandstone_Brick",
      "rotation": 3
    },
    {
      "x": 1,
      "y": 5,
      "z": -6,
      "name": "Rock_Sandstone_Brick",
      "rotation": 3
    },
    {
      "x": 1,
      "y": 6,
      "z": -6,
      "name": "Rock_Sandstone_Brick",
      "rotation": 3
    },
    {
      "x": 1,
      "y": 7,
      "z": -6,
      "name": "Rock_Sandstone_Brick",
      "rotation": 3
    },
    {
      "x": 1,
      "y": 8,
      "z": -6,
      "name": "Rock_Sandstone_Brick_Pillar_Base",
      "rotation": 3
    },
    {
      "x": 1,
      "y": 9,
      "z": -6,
      "name": "Rock_Sandstone_Brick_Pillar_Middle",
      "rotation": 3
    },
    {
      "x": 1,
      "y": 10,
      "z": -6,
      "name": "Rock_Sandstone_Brick_Pillar_Base",
      "rotation": 33
    },
    {
      "x": 1,
      "y": 11,
      "z": -6,
      "name": "Rock_Sandstone_Brick_Pillar_Middle",
      "rotation": 3
    },
    {
      "x": 1,
      "y": 12,
      "z": -6,
      "name": "Rock_Sandstone_Brick_Pillar_Middle",
      "rotation": 3
    },
    {
      "x": 1,
      "y": 13,
      "z": -6,
      "name": "Rock_Sandstone_Brick_Pillar_Middle",
      "rotation": 3
    },
    {
      "x": 1,
      "y": 14,
      "z": -6,
      "name": "Rock_Sandstone_Brick_Pillar_Middle",
      "rotation": 3
    },
    {
      "x": 1,
      "y": 15,
      "z": -6,
      "name": "Rock_Sandstone_Brick_Pillar_Base",
      "rotation": 33
    },
    {
      "x": 1,
      "y": 16,
      "z": -6,
      "name": "Rock_Sandstone_Brick_Ornate",
      "rotation": 3
    },
    {
      "x": 1,
      "y": 17,
      "z": -6,
      "name": "Rock_Sandstone_Brick",
      "rotation": 3
    },
    {
      "x": 1,
      "y": 18,
      "z": -6,
      "name": "Rock_Sandstone_Brick",
      "rotation": 3
    },
    {
      "x": 1,
      "y": 19,
      "z": -6,
      "name": "Rock_Sandstone_Brick",
      "rotation": 3
    },
    {
      "x": 1,
      "y": 20,
      "z": -6,
      "name": "Rock_Sandstone_Brick",
      "rotation": 3
    },
    {
      "x": 1,
      "y": 21,
      "z": -6,
      "name": "Rock_Sandstone_Brick_Ornate",
      "rotation": 3
    },
    {
      "x": 1,
      "y": 22,
      "z": -6,
      "name": "Soil_Clay_Ocean_Brick_Smooth",
      "rotation": 3
    },
    {
      "x": 1,
      "y": 23,
      "z": -6,
      "name": "Soil_Clay_Ocean_Brick_Roof",
      "rotation": 3
    },
    {
      "x": 1,
      "y": 24,
      "z": -6,
      "name": "Rock_Sandstone_Brick_Smooth_Half",
      "rotation": 7
    },
    {
      "x": 1,
      "y": 28,
      "z": -6,
      "name": "Soil_Clay_Ocean_Brick_Roof",
      "rotation": 3
    },
    {
      "x": 1,
      "y": 1,
      "z": -5,
      "name": "Rock_Sandstone_Brick",
      "rotation": 3
    },
    {
      "x": 1,
      "y": 2,
      "z": -5,
      "name": "Rock_Sandstone_Cobble",
      "rotation": 3
    },
    {
      "x": 1,
      "y": 3,
      "z": -5,
      "name": "Rock_Sandstone_Brick",
      "rotation": 3
    },
    {
      "x": 1,
      "y": 4,
      "z": -5,
      "name": "Rock_Sandstone_Brick",
      "rotation": 3
    },
    {
      "x": 1,
      "y": 5,
      "z": -5,
      "name": "Rock_Sandstone_Brick",
      "rotation": 3
    },
    {
      "x": 1,
      "y": 6,
      "z": -5,
      "name": "Rock_Sandstone_Brick",
      "rotation": 3
    },
    {
      "x": 1,
      "y": 7,
      "z": -5,
      "name": "Rock_Sandstone_Cobble",
      "rotation": 3
    },
    {
      "x": 1,
      "y": 8,
      "z": -5,
      "name": "Rock_Sandstone_Cobble",
      "rotation": 3
    },
    {
      "x": 1,
      "y": 9,
      "z": -5,
      "name": "Rock_Sandstone_Cobble",
      "rotation": 3
    },
    {
      "x": 1,
      "y": 10,
      "z": -5,
      "name": "Rock_Sandstone_Brick",
      "rotation": 3
    },
    {
      "x": 1,
      "y": 11,
      "z": -5,
      "name": "Rock_Sandstone_Brick",
      "rotation": 3
    },
    {
      "x": 1,
      "y": 12,
      "z": -5,
      "name": "Rock_Sandstone_Brick",
      "rotation": 3
    },
    {
      "x": 1,
      "y": 13,
      "z": -5,
      "name": "Rock_Sandstone_Brick",
      "rotation": 3
    },
    {
      "x": 1,
      "y": 14,
      "z": -5,
      "name": "Rock_Sandstone_Brick",
      "rotation": 3
    },
    {
      "x": 1,
      "y": 15,
      "z": -5,
      "name": "Rock_Sandstone_Brick",
      "rotation": 3
    },
    {
      "x": 1,
      "y": 16,
      "z": -5,
      "name": "Rock_Sandstone_Brick_Ornate",
      "rotation": 3
    },
    {
      "x": 1,
      "y": 17,
      "z": -5,
      "name": "Rock_Sandstone_Brick",
      "rotation": 3
    },
    {
      "x": 1,
      "y": 21,
      "z": -5,
      "name": "Rock_Sandstone_Brick_Stairs",
      "rotation": 32
    },
    {
      "x": 1,
      "y": 22,
      "z": -5,
      "name": "Rock_Sandstone_Brick",
      "rotation": 3
    },
    {
      "x": 1,
      "y": 23,
      "z": -5,
      "name": "Soil_Clay_Ocean_Brick_Roof",
      "rotation": 3
    },
    {
      "x": 1,
      "y": 24,
      "z": -5,
      "name": "Rock_Sandstone_Brick_Smooth",
      "rotation": 3
    },
    {
      "x": 1,
      "y": 27,
      "z": -5,
      "name": "Rock_Sandstone_Brick_Smooth_Half",
      "rotation": 7
    },
    {
      "x": 1,
      "y": 28,
      "z": -5,
      "name": "Soil_Clay_Ocean_Brick_Roof",
      "rotation": 3
    },
    {
      "x": 1,
      "y": 1,
      "z": -4,
      "name": "Rock_Sandstone_Cobble",
      "rotation": 3
    },
    {
      "x": 1,
      "y": 2,
      "z": -4,
      "name": "Rock_Sandstone_Cobble",
      "rotation": 3
    },
    {
      "x": 1,
      "y": 3,
      "z": -4,
      "name": "Rock_Sandstone_Cobble",
      "rotation": 3
    },
    {
      "x": 1,
      "y": 4,
      "z": -4,
      "name": "Rock_Sandstone_Brick",
      "rotation": 3
    },
    {
      "x": 1,
      "y": 5,
      "z": -4,
      "name": "Rock_Sandstone_Brick",
      "rotation": 3
    },
    {
      "x": 1,
      "y": 6,
      "z": -4,
      "name": "Rock_Sandstone_Brick",
      "rotation": 3
    },
    {
      "x": 1,
      "y": 7,
      "z": -4,
      "name": "Rock_Sandstone_Cobble",
      "rotation": 3
    },
    {
      "x": 1,
      "y": 8,
      "z": -4,
      "name": "Rock_Sandstone_Cobble",
      "rotation": 3
    },
    {
      "x": 1,
      "y": 9,
      "z": -4,
      "name": "Rock_Sandstone_Cobble",
      "rotation": 3
    },
    {
      "x": 1,
      "y": 10,
      "z": -4,
      "name": "Rock_Sandstone_Brick",
      "rotation": 3
    },
    {
      "x": 1,
      "y": 11,
      "z": -4,
      "name": "Rock_Sandstone_Brick",
      "rotation": 3
    },
    {
      "x": 1,
      "y": 14,
      "z": -4,
      "name": "Rock_Sandstone_Brick",
      "rotation": 3
    },
    {
      "x": 1,
      "y": 15,
      "z": -4,
      "name": "Rock_Sandstone_Brick",
      "rotation": 3
    },
    {
      "x": 1,
      "y": 16,
      "z": -4,
      "name": "Rock_Sandstone_Brick_Ornate",
      "rotation": 3
    },
    {
      "x": 1,
      "y": 17,
      "z": -4,
      "name": "Rock_Sandstone_Brick",
      "rotation": 3
    },
    {
      "x": 1,
      "y": 21,
      "z": -4,
      "name": "Rock_Sandstone_Brick_Smooth_Half",
      "rotation": 33
    },
    {
      "x": 1,
      "y": 22,
      "z": -4,
      "name": "Rock_Sandstone_Brick",
      "rotation": 3
    },
    {
      "x": 1,
      "y": 23,
      "z": -4,
      "name": "Soil_Clay_Ocean_Brick_Roof",
      "rotation": 3
    },
    {
      "x": 1,
      "y": 24,
      "z": -4,
      "name": "Rock_Sandstone_Brick_Smooth",
      "rotation": 3
    },
    {
      "x": 1,
      "y": 27,
      "z": -4,
      "name": "Rock_Sandstone_Brick_Smooth_Half",
      "rotation": 7
    },
    {
      "x": 1,
      "y": 28,
      "z": -4,
      "name": "Soil_Clay_Ocean_Brick_Roof",
      "rotation": 3
    },
    {
      "x": 1,
      "y": 1,
      "z": -3,
      "name": "Rock_Sandstone_Cobble",
      "rotation": 3
    },
    {
      "x": 1,
      "y": 2,
      "z": -3,
      "name": "Rock_Sandstone_Brick",
      "rotation": 3
    },
    {
      "x": 1,
      "y": 3,
      "z": -3,
      "name": "Rock_Sandstone_Brick",
      "rotation": 3
    },
    {
      "x": 1,
      "y": 4,
      "z": -3,
      "name": "Rock_Sandstone_Brick",
      "rotation": 3
    },
    {
      "x": 1,
      "y": 5,
      "z": -3,
      "name": "Rock_Sandstone_Brick",
      "rotation": 3
    },
    {
      "x": 1,
      "y": 6,
      "z": -3,
      "name": "Rock_Sandstone_Brick",
      "rotation": 3
    },
    {
      "x": 1,
      "y": 7,
      "z": -3,
      "name": "Rock_Sandstone_Brick",
      "rotation": 3
    },
    {
      "x": 1,
      "y": 8,
      "z": -3,
      "name": "Rock_Sandstone_Cobble",
      "rotation": 3
    },
    {
      "x": 1,
      "y": 9,
      "z": -3,
      "name": "Rock_Sandstone_Cobble",
      "rotation": 3
    },
    {
      "x": 1,
      "y": 10,
      "z": -3,
      "name": "Rock_Sandstone_Brick",
      "rotation": 3
    },
    {
      "x": 1,
      "y": 11,
      "z": -3,
      "name": "Rock_Sandstone_Brick",
      "rotation": 3
    },
    {
      "x": 1,
      "y": 12,
      "z": -3,
      "name": "Rock_Sandstone_Brick",
      "rotation": 3
    },
    {
      "x": 1,
      "y": 13,
      "z": -3,
      "name": "Rock_Sandstone_Brick",
      "rotation": 3
    },
    {
      "x": 1,
      "y": 14,
      "z": -3,
      "name": "Rock_Sandstone_Brick",
      "rotation": 3
    },
    {
      "x": 1,
      "y": 15,
      "z": -3,
      "name": "Rock_Sandstone_Brick",
      "rotation": 3
    },
    {
      "x": 1,
      "y": 16,
      "z": -3,
      "name": "Rock_Sandstone_Brick_Ornate",
      "rotation": 3
    },
    {
      "x": 1,
      "y": 17,
      "z": -3,
      "name": "Rock_Sandstone_Brick",
      "rotation": 3
    },
    {
      "x": 1,
      "y": 21,
      "z": -3,
      "name": "Rock_Sandstone_Brick_Stairs",
      "rotation": 34
    },
    {
      "x": 1,
      "y": 22,
      "z": -3,
      "name": "Rock_Sandstone_Brick",
      "rotation": 3
    },
    {
      "x": 1,
      "y": 23,
      "z": -3,
      "name": "Soil_Clay_Ocean_Brick_Roof",
      "rotation": 3
    },
    {
      "x": 1,
      "y": 24,
      "z": -3,
      "name": "Rock_Sandstone_Brick_Smooth",
      "rotation": 3
    },
    {
      "x": 1,
      "y": 27,
      "z": -3,
      "name": "Rock_Sandstone_Brick_Smooth_Half",
      "rotation": 7
    },
    {
      "x": 1,
      "y": 28,
      "z": -3,
      "name": "Soil_Clay_Ocean_Brick_Roof",
      "rotation": 3
    },
    {
      "x": 1,
      "y": 1,
      "z": -2,
      "name": "Rock_Sandstone_Cobble",
      "rotation": 3
    },
    {
      "x": 1,
      "y": 2,
      "z": -2,
      "name": "Rock_Sandstone_Brick",
      "rotation": 3
    },
    {
      "x": 1,
      "y": 3,
      "z": -2,
      "name": "Rock_Sandstone_Brick",
      "rotation": 3
    },
    {
      "x": 1,
      "y": 4,
      "z": -2,
      "name": "Rock_Sandstone_Brick",
      "rotation": 3
    },
    {
      "x": 1,
      "y": 5,
      "z": -2,
      "name": "Rock_Sandstone_Brick",
      "rotation": 3
    },
    {
      "x": 1,
      "y": 6,
      "z": -2,
      "name": "Rock_Sandstone_Brick",
      "rotation": 3
    },
    {
      "x": 1,
      "y": 7,
      "z": -2,
      "name": "Rock_Sandstone_Brick",
      "rotation": 3
    },
    {
      "x": 1,
      "y": 8,
      "z": -2,
      "name": "Rock_Sandstone_Brick_Pillar_Base",
      "rotation": 3
    },
    {
      "x": 1,
      "y": 9,
      "z": -2,
      "name": "Rock_Sandstone_Brick_Pillar_Middle",
      "rotation": 3
    },
    {
      "x": 1,
      "y": 10,
      "z": -2,
      "name": "Rock_Sandstone_Brick_Pillar_Base",
      "rotation": 33
    },
    {
      "x": 1,
      "y": 11,
      "z": -2,
      "name": "Rock_Sandstone_Brick_Pillar_Middle",
      "rotation": 3
    },
    {
      "x": 1,
      "y": 12,
      "z": -2,
      "name": "Rock_Sandstone_Brick_Pillar_Middle",
      "rotation": 3
    },
    {
      "x": 1,
      "y": 13,
      "z": -2,
      "name": "Rock_Sandstone_Brick_Pillar_Middle",
      "rotation": 3
    },
    {
      "x": 1,
      "y": 14,
      "z": -2,
      "name": "Rock_Sandstone_Brick_Pillar_Middle",
      "rotation": 3
    },
    {
      "x": 1,
      "y": 15,
      "z": -2,
      "name": "Rock_Sandstone_Brick_Pillar_Base",
      "rotation": 33
    },
    {
      "x": 1,
      "y": 16,
      "z": -2,
      "name": "Rock_Sandstone_Brick_Ornate",
      "rotation": 3
    },
    {
      "x": 1,
      "y": 17,
      "z": -2,
      "name": "Rock_Sandstone_Brick",
      "rotation": 3
    },
    {
      "x": 1,
      "y": 18,
      "z": -2,
      "name": "Rock_Sandstone_Brick",
      "rotation": 3
    },
    {
      "x": 1,
      "y": 19,
      "z": -2,
      "name": "Rock_Sandstone_Brick",
      "rotation": 3
    },
    {
      "x": 1,
      "y": 20,
      "z": -2,
      "name": "Rock_Sandstone_Brick",
      "rotation": 3
    },
    {
      "x": 1,
      "y": 21,
      "z": -2,
      "name": "Rock_Sandstone_Brick_Ornate",
      "rotation": 3
    },
    {
      "x": 1,
      "y": 22,
      "z": -2,
      "name": "Soil_Clay_Ocean_Brick_Smooth",
      "rotation": 3
    },
    {
      "x": 1,
      "y": 23,
      "z": -2,
      "name": "Soil_Clay_Ocean_Brick_Roof",
      "rotation": 3
    },
    {
      "x": 1,
      "y": 24,
      "z": -2,
      "name": "Rock_Sandstone_Brick_Smooth_Half",
      "rotation": 7
    },
    {
      "x": 1,
      "y": 28,
      "z": -2,
      "name": "Soil_Clay_Ocean_Brick_Roof",
      "rotation": 3
    },
    {
      "x": 1,
      "y": 1,
      "z": -1,
      "name": "Rock_Sandstone_Cobble",
      "rotation": 3
    },
    {
      "x": 1,
      "y": 2,
      "z": -1,
      "name": "Rock_Sandstone_Brick",
      "rotation": 3
    },
    {
      "x": 1,
      "y": 3,
      "z": -1,
      "name": "Rock_Sandstone_Brick",
      "rotation": 3
    },
    {
      "x": 1,
      "y": 4,
      "z": -1,
      "name": "Rock_Sandstone_Brick",
      "rotation": 3
    },
    {
      "x": 1,
      "y": 5,
      "z": -1,
      "name": "Rock_Sandstone_Brick",
      "rotation": 3
    },
    {
      "x": 1,
      "y": 6,
      "z": -1,
      "name": "Rock_Sandstone_Brick",
      "rotation": 3
    },
    {
      "x": 1,
      "y": 7,
      "z": -1,
      "name": "Rock_Sandstone_Brick",
      "rotation": 3
    },
    {
      "x": 1,
      "y": 16,
      "z": -1,
      "name": "Rock_Sandstone_Brick_Ornate",
      "rotation": 3
    },
    {
      "x": 1,
      "y": 17,
      "z": -1,
      "name": "Rock_Sandstone_Brick",
      "rotation": 3
    },
    {
      "x": 1,
      "y": 21,
      "z": -1,
      "name": "Rock_Sandstone_Brick_Ornate",
      "rotation": 3
    },
    {
      "x": 1,
      "y": 22,
      "z": -1,
      "name": "Soil_Clay_Ocean_Brick_Half",
      "rotation": 3
    },
    {
      "x": 1,
      "y": 28,
      "z": -1,
      "name": "*Soil_Clay_Ocean_Brick_Roof_State_Definitions_Corner_Right"
    },
    {
      "x": 1,
      "y": 1,
      "z": 0,
      "name": "Rock_Sandstone_Cobble",
      "rotation": 3
    },
    {
      "x": 1,
      "y": 2,
      "z": 0,
      "name": "Rock_Sandstone_Cobble",
      "rotation": 3
    },
    {
      "x": 1,
      "y": 3,
      "z": 0,
      "name": "Rock_Sandstone_Brick",
      "rotation": 3
    },
    {
      "x": 1,
      "y": 4,
      "z": 0,
      "name": "Rock_Sandstone_Brick",
      "rotation": 3
    },
    {
      "x": 1,
      "y": 5,
      "z": 0,
      "name": "Rock_Sandstone_Brick",
      "rotation": 3
    },
    {
      "x": 1,
      "y": 6,
      "z": 0,
      "name": "Rock_Sandstone_Brick_Pillar_Base",
      "rotation": 3
    },
    {
      "x": 1,
      "y": 7,
      "z": 0,
      "name": "Rock_Sandstone_Brick_Half",
      "rotation": 3
    },
    {
      "x": 1,
      "y": 17,
      "z": 0,
      "name": "Rock_Sandstone_Brick_Stairs",
      "rotation": 32
    },
    {
      "x": 2,
      "y": 1,
      "z": -9,
      "name": "Wood_Dry_Trunk",
      "support": 15,
      "rotation": 4
    },
    {
      "x": 2,
      "y": 1,
      "z": -8,
      "name": "Rock_Sandstone_Cobble",
      "rotation": 3
    },
    {
      "x": 2,
      "y": 2,
      "z": -8,
      "name": "Rock_Sandstone_Cobble",
      "rotation": 3
    },
    {
      "x": 2,
      "y": 3,
      "z": -8,
      "name": "Rock_Sandstone_Cobble",
      "rotation": 3
    },
    {
      "x": 2,
      "y": 4,
      "z": -8,
      "name": "Rock_Sandstone_Brick",
      "rotation": 3
    },
    {
      "x": 2,
      "y": 5,
      "z": -8,
      "name": "Rock_Sandstone_Brick",
      "rotation": 3
    },
    {
      "x": 2,
      "y": 6,
      "z": -8,
      "name": "Rock_Sandstone_Brick_Pillar_Base",
      "rotation": 3
    },
    {
      "x": 2,
      "y": 7,
      "z": -8,
      "name": "Rock_Sandstone_Brick",
      "rotation": 3
    },
    {
      "x": 2,
      "y": 17,
      "z": -8,
      "name": "Rock_Sandstone_Brick_Stairs",
      "rotation": 34
    },
    {
      "x": 2,
      "y": 18,
      "z": -8,
      "name": "Rock_Sandstone_Brick_Wall"
    },
    {
      "x": 2,
      "y": 22,
      "z": -8,
      "name": "Soil_Clay_Ocean_Brick_Roof",
      "rotation": 2
    },
    {
      "x": 2,
      "y": 1,
      "z": -7,
      "name": "Rock_Sandstone_Cobble",
      "rotation": 3
    },
    {
      "x": 2,
      "y": 6,
      "z": -7,
      "name": "Rock_Sandstone_Brick",
      "rotation": 3
    },
    {
      "x": 2,
      "y": 7,
      "z": -7,
      "name": "Rock_Sandstone_Brick",
      "rotation": 3
    },
    {
      "x": 2,
      "y": 8,
      "z": -7,
      "name": "Rock_Sandstone_Brick_Pillar_Base",
      "rotation": 3
    },
    {
      "x": 2,
      "y": 9,
      "z": -7,
      "name": "Rock_Sandstone_Brick_Pillar_Middle",
      "rotation": 3
    },
    {
      "x": 2,
      "y": 10,
      "z": -7,
      "name": "Rock_Sandstone_Brick_Pillar_Base",
      "rotation": 33
    },
    {
      "x": 2,
      "y": 11,
      "z": -7,
      "name": "Rock_Sandstone_Brick_Pillar_Middle",
      "rotation": 3
    },
    {
      "x": 2,
      "y": 12,
      "z": -7,
      "name": "Rock_Sandstone_Brick_Pillar_Middle",
      "rotation": 3
    },
    {
      "x": 2,
      "y": 13,
      "z": -7,
      "name": "Rock_Sandstone_Brick_Pillar_Middle",
      "rotation": 3
    },
    {
      "x": 2,
      "y": 14,
      "z": -7,
      "name": "Rock_Sandstone_Brick_Pillar_Middle",
      "rotation": 3
    },
    {
      "x": 2,
      "y": 15,
      "z": -7,
      "name": "Rock_Sandstone_Brick_Pillar_Base",
      "rotation": 33
    },
    {
      "x": 2,
      "y": 16,
      "z": -7,
      "name": "Rock_Sandstone_Brick_Ornate",
      "rotation": 3
    },
    {
      "x": 2,
      "y": 17,
      "z": -7,
      "name": "Rock_Sandstone_Brick",
      "rotation": 3
    },
    {
      "x": 2,
      "y": 18,
      "z": -7,
      "name": "Rock_Sandstone_Brick",
      "rotation": 3
    },
    {
      "x": 2,
      "y": 19,
      "z": -7,
      "name": "Rock_Sandstone_Brick",
      "rotation": 3
    },
    {
      "x": 2,
      "y": 20,
      "z": -7,
      "name": "Rock_Sandstone_Brick",
      "rotation": 3
    },
    {
      "x": 2,
      "y": 21,
      "z": -7,
      "name": "Rock_Sandstone_Brick_Ornate",
      "rotation": 3
    },
    {
      "x": 2,
      "y": 22,
      "z": -7,
      "name": "Soil_Clay_Ocean_Brick_Smooth",
      "rotation": 3
    },
    {
      "x": 2,
      "y": 23,
      "z": -7,
      "name": "Soil_Clay_Ocean_Brick_Roof",
      "rotation": 2
    },
    {
      "x": 2,
      "y": 24,
      "z": -7,
      "name": "Rock_Sandstone_Brick_Smooth_Half",
      "rotation": 6
    },
    {
      "x": 2,
      "y": 28,
      "z": -7,
      "name": "Soil_Clay_Ocean_Brick_Roof",
      "rotation": 2
    },
    {
      "x": 2,
      "y": 1,
      "z": -6,
      "name": "Rock_Sandstone_Cobble",
      "rotation": 3
    },
    {
      "x": 2,
      "y": 2,
      "z": -6,
      "name": "Rock_Sandstone_Cobble_Stairs",
      "rotation": 2
    },
    {
      "x": 2,
      "y": 6,
      "z": -6,
      "name": "Rock_Sandstone_Brick",
      "rotation": 3
    },
    {
      "x": 2,
      "y": 7,
      "z": -6,
      "name": "Rock_Sandstone_Brick",
      "rotation": 3
    },
    {
      "x": 2,
      "y": 8,
      "z": -6,
      "name": "Rock_Sandstone_Brick",
      "rotation": 3
    },
    {
      "x": 2,
      "y": 9,
      "z": -6,
      "name": "Rock_Sandstone_Cobble",
      "rotation": 3
    },
    {
      "x": 2,
      "y": 10,
      "z": -6,
      "name": "Rock_Sandstone_Brick",
      "rotation": 3
    },
    {
      "x": 2,
      "y": 11,
      "z": -6,
      "name": "Rock_Sandstone_Brick",
      "rotation": 3
    },
    {
      "x": 2,
      "y": 12,
      "z": -6,
      "name": "Rock_Sandstone_Brick",
      "rotation": 3
    },
    {
      "x": 2,
      "y": 13,
      "z": -6,
      "name": "Rock_Sandstone_Brick",
      "rotation": 3
    },
    {
      "x": 2,
      "y": 14,
      "z": -6,
      "name": "Rock_Sandstone_Brick",
      "rotation": 3
    },
    {
      "x": 2,
      "y": 15,
      "z": -6,
      "name": "Rock_Sandstone_Brick",
      "rotation": 3
    },
    {
      "x": 2,
      "y": 16,
      "z": -6,
      "name": "Rock_Sandstone_Brick_Ornate",
      "rotation": 3
    },
    {
      "x": 2,
      "y": 17,
      "z": -6,
      "name": "Rock_Sandstone_Brick",
      "rotation": 3
    },
    {
      "x": 2,
      "y": 18,
      "z": -6,
      "name": "Rock_Sandstone_Brick",
      "rotation": 3
    },
    {
      "x": 2,
      "y": 19,
      "z": -6,
      "name": "Rock_Sandstone_Brick",
      "rotation": 3
    },
    {
      "x": 2,
      "y": 20,
      "z": -6,
      "name": "Rock_Sandstone_Brick",
      "rotation": 3
    },
    {
      "x": 2,
      "y": 21,
      "z": -6,
      "name": "Rock_Sandstone_Brick_Ornate",
      "rotation": 3
    },
    {
      "x": 2,
      "y": 22,
      "z": -6,
      "name": "Rock_Sandstone_Brick",
      "rotation": 3
    },
    {
      "x": 2,
      "y": 23,
      "z": -6,
      "name": "Rock_Sandstone_Brick_Smooth",
      "rotation": 3
    },
    {
      "x": 2,
      "y": 24,
      "z": -6,
      "name": "Rock_Sandstone_Brick_Smooth",
      "rotation": 3
    },
    {
      "x": 2,
      "y": 27,
      "z": -6,
      "name": "Rock_Sandstone_Brick_Smooth",
      "rotation": 3
    },
    {
      "x": 2,
      "y": 28,
      "z": -6,
      "name": "Rock_Sandstone_Brick_Ornate",
      "rotation": 3
    },
    {
      "x": 2,
      "y": 29,
      "z": -6,
      "name": "*Soil_Clay_Ocean_Brick_Roof_State_Definitions_Corner_Right",
      "rotation": 3
    },
    {
      "x": 2,
      "y": 1,
      "z": -5,
      "name": "Rock_Sandstone_Cobble",
      "rotation": 3
    },
    {
      "x": 2,
      "y": 2,
      "z": -5,
      "name": "Rock_Sandstone_Cobble",
      "rotation": 3
    },
    {
      "x": 2,
      "y": 3,
      "z": -5,
      "name": "Rock_Sandstone_Cobble_Stairs",
      "rotation": 2
    },
    {
      "x": 2,
      "y": 7,
      "z": -5,
      "name": "Rock_Sandstone_Cobble_Half",
      "rotation": 4
    },
    {
      "x": 2,
      "y": 8,
      "z": -5,
      "name": "Rock_Sandstone_Cobble",
      "rotation": 3
    },
    {
      "x": 2,
      "y": 9,
      "z": -5,
      "name": "Rock_Sandstone_Cobble",
      "rotation": 3
    },
    {
      "x": 2,
      "y": 17,
      "z": -5,
      "name": "Wood_Drywood_Planks",
      "rotation": 3
    },
    {
      "x": 2,
      "y": 22,
      "z": -5,
      "name": "Rock_Sandstone_Brick",
      "rotation": 3
    },
    {
      "x": 2,
      "y": 23,
      "z": -5,
      "name": "Rock_Sandstone_Brick_Smooth",
      "rotation": 3
    },
    {
      "x": 2,
      "y": 24,
      "z": -5,
      "name": "Rock_Sandstone_Brick_Smooth",
      "rotation": 3
    },
    {
      "x": 2,
      "y": 25,
      "z": -5,
      "name": "Rock_Sandstone_White_Brick",
      "rotation": 3
    },
    {
      "x": 2,
      "y": 26,
      "z": -5,
      "name": "Rock_Sandstone_White_Brick",
      "rotation": 3
    },
    {
      "x": 2,
      "y": 27,
      "z": -5,
      "name": "Rock_Sandstone_Brick_Smooth",
      "rotation": 3
    },
    {
      "x": 2,
      "y": 28,
      "z": -5,
      "name": "Rock_Sandstone_Brick_Ornate",
      "rotation": 3
    },
    {
      "x": 2,
      "y": 29,
      "z": -5,
      "name": "Soil_Clay_Ocean_Brick_Ornate",
      "rotation": 3
    },
    {
      "x": 2,
      "y": 30,
      "z": -5,
      "name": "Soil_Clay_Ocean_Brick_Half",
      "rotation": 7
    },
    {
      "x": 2,
      "y": 31,
      "z": -5,
      "name": "Soil_Clay_Ocean_Brick_Half",
      "rotation": 7
    },
    {
      "x": 2,
      "y": 1,
      "z": -4,
      "name": "Rock_Sandstone_Brick",
      "rotation": 3
    },
    {
      "x": 2,
      "y": 2,
      "z": -4,
      "name": "Rock_Sandstone_Cobble",
      "rotation": 3
    },
    {
      "x": 2,
      "y": 3,
      "z": -4,
      "name": "Rock_Sandstone_Cobble",
      "rotation": 3
    },
    {
      "x": 2,
      "y": 4,
      "z": -4,
      "name": "Rock_Sandstone_Cobble_Stairs",
      "rotation": 2
    },
    {
      "x": 2,
      "y": 9,
      "z": -4,
      "name": "Rock_Sandstone_Cobble",
      "rotation": 3
    },
    {
      "x": 2,
      "y": 17,
      "z": -4,
      "name": "Wood_Drywood_Planks",
      "rotation": 3
    },
    {
      "x": 2,
      "y": 22,
      "z": -4,
      "name": "Rock_Sandstone_Brick",
      "rotation": 3
    },
    {
      "x": 2,
      "y": 23,
      "z": -4,
      "name": "Rock_Sandstone_Brick_Smooth",
      "rotation": 3
    },
    {
      "x": 2,
      "y": 24,
      "z": -4,
      "name": "Rock_Sandstone_Brick_Smooth",
      "rotation": 3
    },
    {
      "x": 2,
      "y": 25,
      "z": -4,
      "name": "Furniture_Desert_Window",
      "rotation": 3
    },
    {
      "x": 2,
      "y": 26,
      "z": -4,
      "name": "Furniture_Desert_Window",
      "rotation": 3
    },
    {
      "x": 2,
      "y": 27,
      "z": -4,
      "name": "Rock_Sandstone_Brick_Smooth",
      "rotation": 3
    },
    {
      "x": 2,
      "y": 28,
      "z": -4,
      "name": "Rock_Sandstone_Brick_Ornate",
      "rotation": 3
    },
    {
      "x": 2,
      "y": 29,
      "z": -4,
      "name": "Soil_Clay_Ocean_Brick_Ornate",
      "rotation": 3
    },
    {
      "x": 2,
      "y": 30,
      "z": -4,
      "name": "Soil_Clay_Ocean_Brick_Smooth",
      "rotation": 3
    },
    {
      "x": 2,
      "y": 31,
      "z": -4,
      "name": "Soil_Clay_Ocean_Brick_Half",
      "rotation": 7
    },
    {
      "x": 2,
      "y": 1,
      "z": -3,
      "name": "Rock_Sandstone_Brick",
      "rotation": 3
    },
    {
      "x": 2,
      "y": 2,
      "z": -3,
      "name": "Rock_Sandstone_Cobble",
      "rotation": 3
    },
    {
      "x": 2,
      "y": 3,
      "z": -3,
      "name": "Rock_Sandstone_Cobble",
      "rotation": 3
    },
    {
      "x": 2,
      "y": 4,
      "z": -3,
      "name": "Rock_Sandstone_Cobble",
      "rotation": 3
    },
    {
      "x": 2,
      "y": 5,
      "z": -3,
      "name": "Rock_Sandstone_Cobble_Stairs",
      "rotation": 2
    },
    {
      "x": 2,
      "y": 9,
      "z": -3,
      "name": "Rock_Sandstone_Cobble",
      "rotation": 3
    },
    {
      "x": 2,
      "y": 10,
      "z": -3,
      "name": "Furniture_Village_Pot",
      "rotation": 3
    },
    {
      "x": 2,
      "y": 17,
      "z": -3,
      "name": "Wood_Drywood_Planks",
      "rotation": 3
    },
    {
      "x": 2,
      "y": 19,
      "z": -3,
      "name": "*Wood_Torch_Wall_State_Definitions_Off",
      "rotation": 2
    },
    {
      "x": 2,
      "y": 22,
      "z": -3,
      "name": "Rock_Sandstone_Brick",
      "rotation": 3
    },
    {
      "x": 2,
      "y": 23,
      "z": -3,
      "name": "Rock_Sandstone_Brick_Smooth",
      "rotation": 3
    },
    {
      "x": 2,
      "y": 24,
      "z": -3,
      "name": "Rock_Sandstone_Brick_Smooth",
      "rotation": 3
    },
    {
      "x": 2,
      "y": 25,
      "z": -3,
      "name": "Rock_Sandstone_White_Brick",
      "rotation": 3
    },
    {
      "x": 2,
      "y": 26,
      "z": -3,
      "name": "Rock_Sandstone_White_Brick",
      "rotation": 3
    },
    {
      "x": 2,
      "y": 27,
      "z": -3,
      "name": "Rock_Sandstone_Brick_Smooth",
      "rotation": 3
    },
    {
      "x": 2,
      "y": 28,
      "z": -3,
      "name": "Rock_Sandstone_Brick_Ornate",
      "rotation": 3
    },
    {
      "x": 2,
      "y": 29,
      "z": -3,
      "name": "Soil_Clay_Ocean_Brick_Ornate",
      "rotation": 3
    },
    {
      "x": 2,
      "y": 30,
      "z": -3,
      "name": "Soil_Clay_Ocean_Brick_Half",
      "rotation": 7
    },
    {
      "x": 2,
      "y": 31,
      "z": -3,
      "name": "Soil_Clay_Ocean_Brick_Half",
      "rotation": 7
    },
    {
      "x": 2,
      "y": 1,
      "z": -2,
      "name": "Rock_Sandstone_Brick",
      "rotation": 3
    },
    {
      "x": 2,
      "y": 2,
      "z": -2,
      "name": "Rock_Sandstone_Cobble",
      "rotation": 3
    },
    {
      "x": 2,
      "y": 3,
      "z": -2,
      "name": "Rock_Sandstone_Cobble",
      "rotation": 3
    },
    {
      "x": 2,
      "y": 4,
      "z": -2,
      "name": "Rock_Sandstone_Cobble",
      "rotation": 3
    },
    {
      "x": 2,
      "y": 5,
      "z": -2,
      "name": "Rock_Sandstone_Brick",
      "rotation": 3
    },
    {
      "x": 2,
      "y": 6,
      "z": -2,
      "name": "Rock_Sandstone_Brick",
      "rotation": 3
    },
    {
      "x": 2,
      "y": 7,
      "z": -2,
      "name": "Rock_Sandstone_Cobble",
      "rotation": 3
    },
    {
      "x": 2,
      "y": 8,
      "z": -2,
      "name": "Rock_Sandstone_Cobble",
      "rotation": 3
    },
    {
      "x": 2,
      "y": 9,
      "z": -2,
      "name": "Rock_Sandstone_Cobble",
      "rotation": 3
    },
    {
      "x": 2,
      "y": 10,
      "z": -2,
      "name": "Rock_Sandstone_Brick",
      "rotation": 3
    },
    {
      "x": 2,
      "y": 11,
      "z": -2,
      "name": "Rock_Sandstone_Brick",
      "rotation": 3
    },
    {
      "x": 2,
      "y": 12,
      "z": -2,
      "name": "Rock_Sandstone_Brick",
      "rotation": 3
    },
    {
      "x": 2,
      "y": 13,
      "z": -2,
      "name": "Rock_Sandstone_Brick",
      "rotation": 3
    },
    {
      "x": 2,
      "y": 14,
      "z": -2,
      "name": "Rock_Sandstone_Brick",
      "rotation": 3
    },
    {
      "x": 2,
      "y": 15,
      "z": -2,
      "name": "Rock_Sandstone_Brick",
      "rotation": 3
    },
    {
      "x": 2,
      "y": 16,
      "z": -2,
      "name": "Rock_Sandstone_Brick_Ornate",
      "rotation": 3
    },
    {
      "x": 2,
      "y": 17,
      "z": -2,
      "name": "Rock_Sandstone_Brick",
      "rotation": 3
    },
    {
      "x": 2,
      "y": 18,
      "z": -2,
      "name": "Rock_Sandstone_Brick",
      "rotation": 3
    },
    {
      "x": 2,
      "y": 19,
      "z": -2,
      "name": "Rock_Sandstone_Brick",
      "rotation": 3
    },
    {
      "x": 2,
      "y": 20,
      "z": -2,
      "name": "Rock_Sandstone_Brick",
      "rotation": 3
    },
    {
      "x": 2,
      "y": 21,
      "z": -2,
      "name": "Rock_Sandstone_Brick_Ornate",
      "rotation": 3
    },
    {
      "x": 2,
      "y": 22,
      "z": -2,
      "name": "Rock_Sandstone_Brick",
      "rotation": 3
    },
    {
      "x": 2,
      "y": 23,
      "z": -2,
      "name": "Rock_Sandstone_Brick_Smooth",
      "rotation": 3
    },
    {
      "x": 2,
      "y": 24,
      "z": -2,
      "name": "Rock_Sandstone_Brick_Smooth",
      "rotation": 3
    },
    {
      "x": 2,
      "y": 27,
      "z": -2,
      "name": "Rock_Sandstone_Brick_Smooth",
      "rotation": 3
    },
    {
      "x": 2,
      "y": 28,
      "z": -2,
      "name": "Rock_Sandstone_Brick_Ornate",
      "rotation": 3
    },
    {
      "x": 2,
      "y": 29,
      "z": -2,
      "name": "*Soil_Clay_Ocean_Brick_Roof_State_Definitions_Corner_Right"
    },
    {
      "x": 2,
      "y": 1,
      "z": -1,
      "name": "Rock_Sandstone_Cobble",
      "rotation": 3
    },
    {
      "x": 2,
      "y": 2,
      "z": -1,
      "name": "Rock_Sandstone_Cobble",
      "rotation": 3
    },
    {
      "x": 2,
      "y": 3,
      "z": -1,
      "name": "Rock_Sandstone_Brick",
      "rotation": 3
    },
    {
      "x": 2,
      "y": 4,
      "z": -1,
      "name": "Rock_Sandstone_Brick",
      "rotation": 3
    },
    {
      "x": 2,
      "y": 5,
      "z": -1,
      "name": "Rock_Sandstone_Brick",
      "rotation": 3
    },
    {
      "x": 2,
      "y": 6,
      "z": -1,
      "name": "Rock_Sandstone_Brick",
      "rotation": 3
    },
    {
      "x": 2,
      "y": 7,
      "z": -1,
      "name": "Rock_Sandstone_Brick",
      "rotation": 3
    },
    {
      "x": 2,
      "y": 8,
      "z": -1,
      "name": "Rock_Sandstone_Brick_Pillar_Base",
      "rotation": 3
    },
    {
      "x": 2,
      "y": 9,
      "z": -1,
      "name": "Rock_Sandstone_Brick_Pillar_Middle",
      "rotation": 3
    },
    {
      "x": 2,
      "y": 10,
      "z": -1,
      "name": "Rock_Sandstone_Brick_Pillar_Base",
      "rotation": 33
    },
    {
      "x": 2,
      "y": 11,
      "z": -1,
      "name": "Rock_Sandstone_Brick_Pillar_Middle",
      "rotation": 3
    },
    {
      "x": 2,
      "y": 12,
      "z": -1,
      "name": "Rock_Sandstone_Brick_Pillar_Middle",
      "rotation": 3
    },
    {
      "x": 2,
      "y": 13,
      "z": -1,
      "name": "Rock_Sandstone_Brick_Pillar_Middle",
      "rotation": 3
    },
    {
      "x": 2,
      "y": 14,
      "z": -1,
      "name": "Rock_Sandstone_Brick_Pillar_Middle",
      "rotation": 3
    },
    {
      "x": 2,
      "y": 15,
      "z": -1,
      "name": "Rock_Sandstone_Brick_Pillar_Base",
      "rotation": 33
    },
    {
      "x": 2,
      "y": 16,
      "z": -1,
      "name": "Rock_Sandstone_Brick_Ornate",
      "rotation": 3
    },
    {
      "x": 2,
      "y": 17,
      "z": -1,
      "name": "Rock_Sandstone_Brick",
      "rotation": 3
    },
    {
      "x": 2,
      "y": 18,
      "z": -1,
      "name": "Rock_Sandstone_Brick",
      "rotation": 3
    },
    {
      "x": 2,
      "y": 19,
      "z": -1,
      "name": "Rock_Sandstone_Brick",
      "rotation": 3
    },
    {
      "x": 2,
      "y": 20,
      "z": -1,
      "name": "Rock_Sandstone_Brick",
      "rotation": 3
    },
    {
      "x": 2,
      "y": 21,
      "z": -1,
      "name": "Rock_Sandstone_Brick_Ornate",
      "rotation": 3
    },
    {
      "x": 2,
      "y": 22,
      "z": -1,
      "name": "Soil_Clay_Ocean_Brick_Smooth",
      "rotation": 3
    },
    {
      "x": 2,
      "y": 23,
      "z": -1,
      "name": "Soil_Clay_Ocean_Brick_Half",
      "rotation": 4
    },
    {
      "x": 2,
      "y": 24,
      "z": -1,
      "name": "Rock_Sandstone_Brick_Smooth_Half",
      "rotation": 4
    },
    {
      "x": 2,
      "y": 28,
      "z": -1,
      "name": "Soil_Clay_Ocean_Brick_Roof"
    },
    {
      "x": 2,
      "y": 1,
      "z": 0,
      "name": "Rock_Sandstone_Cobble",
      "rotation": 3
    },
    {
      "x": 2,
      "y": 2,
      "z": 0,
      "name": "Rock_Sandstone_Cobble",
      "rotation": 3
    },
    {
      "x": 2,
      "y": 3,
      "z": 0,
      "name": "Rock_Sandstone_Cobble",
      "rotation": 3
    },
    {
      "x": 2,
      "y": 4,
      "z": 0,
      "name": "Rock_Sandstone_Brick",
      "rotation": 3
    },
    {
      "x": 2,
      "y": 5,
      "z": 0,
      "name": "Rock_Sandstone_Brick",
      "rotation": 3
    },
    {
      "x": 2,
      "y": 6,
      "z": 0,
      "name": "Rock_Sandstone_Brick_Pillar_Base",
      "rotation": 3
    },
    {
      "x": 2,
      "y": 7,
      "z": 0,
      "name": "Rock_Sandstone_Brick",
      "rotation": 3
    },
    {
      "x": 2,
      "y": 8,
      "z": 0,
      "name": "Plant_Bush_Arid_Sharp",
      "rotation": 3
    },
    {
      "x": 2,
      "y": 17,
      "z": 0,
      "name": "Rock_Sandstone_Brick_Stairs",
      "rotation": 32
    },
    {
      "x": 2,
      "y": 18,
      "z": 0,
      "name": "Rock_Sandstone_Brick_Wall"
    },
    {
      "x": 2,
      "y": 22,
      "z": 0,
      "name": "Soil_Clay_Ocean_Brick_Roof"
    },
    {
      "x": 3,
      "y": 1,
      "z": -9,
      "name": "Wood_Dry_Trunk",
      "support": 15,
      "rotation": 5
    },
    {
      "x": 3,
      "y": 1,
      "z": -8,
      "name": "Rock_Sandstone_Cobble",
      "rotation": 3
    },
    {
      "x": 3,
      "y": 2,
      "z": -8,
      "name": "Wood_Drywood_Planks_Half",
      "rotation": 5
    },
    {
      "x": 3,
      "y": 3,
      "z": -8,
      "name": "Wood_Drywood_Planks_Half",
      "rotation": 5
    },
    {
      "x": 3,
      "y": 4,
      "z": -8,
      "name": "Wood_Drywood_Stairs",
      "rotation": 33
    },
    {
      "x": 3,
      "y": 5,
      "z": -8,
      "name": "Rock_Sandstone_Brick",
      "rotation": 3
    },
    {
      "x": 3,
      "y": 6,
      "z": -8,
      "name": "Rock_Sandstone_Brick_Pillar_Base",
      "rotation": 3
    },
    {
      "x": 3,
      "y": 7,
      "z": -8,
      "name": "Rock_Sandstone_Brick",
      "rotation": 3
    },
    {
      "x": 3,
      "y": 8,
      "z": -8,
      "name": "Rock_Sandstone_Cobble_Stairs",
      "rotation": 2
    },
    {
      "x": 3,
      "y": 9,
      "z": -8,
      "name": "Rock_Sandstone_Cobble_Half",
      "rotation": 6
    },
    {
      "x": 3,
      "y": 12,
      "z": -8,
      "name": "Rock_Sandstone_Brick_Smooth_Half",
      "rotation": 7
    },
    {
      "x": 3,
      "y": 13,
      "z": -8,
      "name": "Rock_Sandstone_Brick_Smooth_Half",
      "rotation": 7
    },
    {
      "x": 3,
      "y": 17,
      "z": -8,
      "name": "Rock_Sandstone_Brick_Stairs",
      "rotation": 34
    },
    {
      "x": 3,
      "y": 18,
      "z": -8,
      "name": "Rock_Sandstone_Brick_Wall"
    },
    {
      "x": 3,
      "y": 22,
      "z": -8,
      "name": "Soil_Clay_Ocean_Brick_Roof",
      "rotation": 2
    },
    {
      "x": 3,
      "y": 1,
      "z": -7,
      "name": "Rock_Sandstone_Cobble",
      "rotation": 3
    },
    {
      "x": 3,
      "y": 6,
      "z": -7,
      "name": "Rock_Sandstone_Brick",
      "rotation": 3
    },
    {
      "x": 3,
      "y": 7,
      "z": -7,
      "name": "Rock_Sandstone_Cobble",
      "rotation": 3
    },
    {
      "x": 3,
      "y": 8,
      "z": -7,
      "name": "Rock_Sandstone_Cobble",
      "rotation": 3
    },
    {
      "x": 3,
      "y": 9,
      "z": -7,
      "name": "Rock_Sandstone_Cobble",
      "rotation": 3
    },
    {
      "x": 3,
      "y": 10,
      "z": -7,
      "name": "Rock_Sandstone_Brick",
      "rotation": 3
    },
    {
      "x": 3,
      "y": 11,
      "z": -7,
      "name": "Rock_Sandstone_Brick",
      "rotation": 3
    },
    {
      "x": 3,
      "y": 12,
      "z": -7,
      "name": "Rock_Sandstone_Brick",
      "rotation": 3
    },
    {
      "x": 3,
      "y": 13,
      "z": -7,
      "name": "Rock_Sandstone_Brick",
      "rotation": 3
    },
    {
      "x": 3,
      "y": 14,
      "z": -7,
      "name": "Rock_Sandstone_Brick",
      "rotation": 3
    },
    {
      "x": 3,
      "y": 15,
      "z": -7,
      "name": "Rock_Sandstone_Brick",
      "rotation": 3
    },
    {
      "x": 3,
      "y": 16,
      "z": -7,
      "name": "Rock_Sandstone_Brick_Ornate",
      "rotation": 3
    },
    {
      "x": 3,
      "y": 17,
      "z": -7,
      "name": "Rock_Sandstone_Brick",
      "rotation": 3
    },
    {
      "x": 3,
      "y": 18,
      "z": -7,
      "name": "Furniture_Village_Pot",
      "rotation": 3
    },
    {
      "x": 3,
      "y": 21,
      "z": -7,
      "name": "Rock_Sandstone_Brick_Stairs",
      "rotation": 33
    },
    {
      "x": 3,
      "y": 22,
      "z": -7,
      "name": "Rock_Sandstone_Brick",
      "rotation": 3
    },
    {
      "x": 3,
      "y": 23,
      "z": -7,
      "name": "Soil_Clay_Ocean_Brick_Roof",
      "rotation": 2
    },
    {
      "x": 3,
      "y": 24,
      "z": -7,
      "name": "Rock_Sandstone_Brick_Smooth",
      "rotation": 3
    },
    {
      "x": 3,
      "y": 27,
      "z": -7,
      "name": "Rock_Sandstone_Brick_Smooth_Half",
      "rotation": 6
    },
    {
      "x": 3,
      "y": 28,
      "z": -7,
      "name": "Soil_Clay_Ocean_Brick_Roof",
      "rotation": 2
    },
    {
      "x": 3,
      "y": 1,
      "z": -6,
      "name": "Rock_Sandstone_Cobble",
      "rotation": 3
    },
    {
      "x": 3,
      "y": 2,
      "z": -6,
      "name": "Rock_Sandstone_Cobble_Stairs",
      "rotation": 2
    },
    {
      "x": 3,
      "y": 6,
      "z": -6,
      "name": "Rock_Sandstone_Brick",
      "rotation": 3
    },
    {
      "x": 3,
      "y": 7,
      "z": -6,
      "name": "Rock_Sandstone_Cobble",
      "rotation": 3
    },
    {
      "x": 3,
      "y": 8,
      "z": -6,
      "name": "Rock_Sandstone_Cobble",
      "rotation": 3
    },
    {
      "x": 3,
      "y": 9,
      "z": -6,
      "name": "Rock_Sandstone_Cobble_Half",
      "rotation": 3
    },
    {
      "x": 3,
      "y": 14,
      "z": -6,
      "name": "Wood_Dry_Trunk",
      "rotation": 7
    },
    {
      "x": 3,
      "y": 17,
      "z": -6,
      "name": "Wood_Drywood_Planks",
      "rotation": 3
    },
    {
      "x": 3,
      "y": 22,
      "z": -6,
      "name": "Rock_Sandstone_Brick",
      "rotation": 3
    },
    {
      "x": 3,
      "y": 23,
      "z": -6,
      "name": "Rock_Sandstone_Brick_Smooth",
      "rotation": 3
    },
    {
      "x": 3,
      "y": 24,
      "z": -6,
      "name": "Rock_Sandstone_Brick_Smooth",
      "rotation": 3
    },
    {
      "x": 3,
      "y": 25,
      "z": -6,
      "name": "Rock_Sandstone_White_Brick",
      "rotation": 3
    },
    {
      "x": 3,
      "y": 26,
      "z": -6,
      "name": "Rock_Sandstone_White_Brick",
      "rotation": 3
    },
    {
      "x": 3,
      "y": 27,
      "z": -6,
      "name": "Rock_Sandstone_Brick_Smooth",
      "rotation": 3
    },
    {
      "x": 3,
      "y": 28,
      "z": -6,
      "name": "Rock_Sandstone_Brick_Ornate",
      "rotation": 3
    },
    {
      "x": 3,
      "y": 29,
      "z": -6,
      "name": "Soil_Clay_Ocean_Brick_Ornate",
      "rotation": 3
    },
    {
      "x": 3,
      "y": 30,
      "z": -6,
      "name": "Soil_Clay_Ocean_Brick_Half",
      "rotation": 6
    },
    {
      "x": 3,
      "y": 31,
      "z": -6,
      "name": "Soil_Clay_Ocean_Brick_Half",
      "rotation": 6
    },
    {
      "x": 3,
      "y": 1,
      "z": -5,
      "name": "Rock_Sandstone_Cobble",
      "rotation": 3
    },
    {
      "x": 3,
      "y": 2,
      "z": -5,
      "name": "Rock_Sandstone_Cobble",
      "rotation": 3
    },
    {
      "x": 3,
      "y": 3,
      "z": -5,
      "name": "Rock_Sandstone_Cobble_Stairs",
      "rotation": 2
    },
    {
      "x": 3,
      "y": 7,
      "z": -5,
      "name": "Rock_Sandstone_Cobble_Half",
      "rotation": 4
    },
    {
      "x": 3,
      "y": 8,
      "z": -5,
      "name": "Rock_Sandstone_Cobble",
      "rotation": 3
    },
    {
      "x": 3,
      "y": 9,
      "z": -5,
      "name": "Rock_Sandstone_Cobble_Half",
      "rotation": 3
    },
    {
      "x": 3,
      "y": 17,
      "z": -5,
      "name": "Wood_Drywood_Planks",
      "rotation": 3
    },
    {
      "x": 3,
      "y": 23,
      "z": -5,
      "name": "Wood_Drywood_Planks",
      "rotation": 3
    },
    {
      "x": 3,
      "y": 24,
      "z": -5,
      "name": "Block_Spawner_Block",
      "components": {
        "Components": {
          "BlockSpawner": {}
        }
      },
      "rotation": 1
    },
    {
      "x": 3,
      "y": 28,
      "z": -5,
      "name": "Rock_Sandstone_Brick_Half",
      "rotation": 33
    },
    {
      "x": 3,
      "y": 29,
      "z": -5,
      "name": "Soil_Clay_Ocean_Brick_Ornate",
      "rotation": 3
    },
    {
      "x": 3,
      "y": 30,
      "z": -5,
      "name": "Soil_Clay_Ocean_Brick_Smooth",
      "rotation": 3
    },
    {
      "x": 3,
      "y": 31,
      "z": -5,
      "name": "Soil_Clay_Ocean_Brick_Smooth",
      "rotation": 3
    },
    {
      "x": 3,
      "y": 32,
      "z": -5,
      "name": "Soil_Clay_Ocean_Brick_Half",
      "rotation": 3
    },
    {
      "x": 3,
      "y": 1,
      "z": -4,
      "name": "Rock_Sandstone_Brick",
      "rotation": 3
    },
    {
      "x": 3,
      "y": 2,
      "z": -4,
      "name": "Rock_Sandstone_Cobble",
      "rotation": 3
    },
    {
      "x": 3,
      "y": 3,
      "z": -4,
      "name": "Rock_Sandstone_Cobble",
      "rotation": 3
    },
    {
      "x": 3,
      "y": 4,
      "z": -4,
      "name": "Rock_Sandstone_Cobble_Stairs",
      "rotation": 2
    },
    {
      "x": 3,
      "y": 9,
      "z": -4,
      "name": "Rock_Sandstone_Cobble",
      "rotation": 3
    },
    {
      "x": 3,
      "y": 17,
      "z": -4,
      "name": "Wood_Drywood_Planks_Half",
      "rotation": 4
    },
    {
      "x": 3,
      "y": 23,
      "z": -4,
      "name": "Wood_Drywood_Planks_Half",
      "rotation": 4
    },
    {
      "x": 3,
      "y": 28,
      "z": -4,
      "name": "Rock_Sandstone_Brick",
      "rotation": 3
    },
    {
      "x": 3,
      "y": 29,
      "z": -4,
      "name": "Soil_Clay_Ocean_Brick_Ornate",
      "rotation": 3
    },
    {
      "x": 3,
      "y": 30,
      "z": -4,
      "name": "Soil_Clay_Ocean_Brick_Smooth",
      "rotation": 3
    },
    {
      "x": 3,
      "y": 31,
      "z": -4,
      "name": "Soil_Clay_Ocean_Brick_Smooth",
      "rotation": 3
    },
    {
      "x": 3,
      "y": 32,
      "z": -4,
      "name": "Soil_Clay_Ocean_Brick_Smooth",
      "rotation": 3
    },
    {
      "x": 3,
      "y": 1,
      "z": -3,
      "name": "Rock_Sandstone_Brick",
      "rotation": 3
    },
    {
      "x": 3,
      "y": 2,
      "z": -3,
      "name": "Rock_Sandstone_Cobble",
      "rotation": 3
    },
    {
      "x": 3,
      "y": 3,
      "z": -3,
      "name": "Rock_Sandstone_Cobble",
      "rotation": 3
    },
    {
      "x": 3,
      "y": 4,
      "z": -3,
      "name": "Rock_Sandstone_Cobble",
      "rotation": 3
    },
    {
      "x": 3,
      "y": 5,
      "z": -3,
      "name": "Rock_Sandstone_Cobble_Stairs",
      "rotation": 2
    },
    {
      "x": 3,
      "y": 9,
      "z": -3,
      "name": "Rock_Sandstone_Cobble",
      "rotation": 3
    },
    {
      "x": 3,
      "y": 11,
      "z": -3,
      "name": "Furniture_Desert_Ladder",
      "rotation": 2
    },
    {
      "x": 3,
      "y": 12,
      "z": -3,
      "name": "Furniture_Desert_Ladder",
      "rotation": 2
    },
    {
      "x": 3,
      "y": 13,
      "z": -3,
      "name": "Furniture_Desert_Ladder",
      "rotation": 2
    },
    {
      "x": 3,
      "y": 15,
      "z": -3,
      "name": "Furniture_Desert_Ladder",
      "rotation": 2
    },
    {
      "x": 3,
      "y": 16,
      "z": -3,
      "name": "Furniture_Desert_Ladder",
      "rotation": 2
    },
    {
      "x": 3,
      "y": 17,
      "z": -3,
      "name": "Furniture_Desert_Ladder",
      "rotation": 2
    },
    {
      "x": 3,
      "y": 18,
      "z": -3,
      "name": "Furniture_Desert_Ladder",
      "rotation": 2
    },
    {
      "x": 3,
      "y": 19,
      "z": -3,
      "name": "Furniture_Desert_Ladder",
      "rotation": 2
    },
    {
      "x": 3,
      "y": 21,
      "z": -3,
      "name": "Furniture_Desert_Ladder",
      "rotation": 2
    },
    {
      "x": 3,
      "y": 22,
      "z": -3,
      "name": "Furniture_Desert_Ladder",
      "rotation": 2
    },
    {
      "x": 3,
      "y": 23,
      "z": -3,
      "name": "Furniture_Desert_Ladder",
      "rotation": 2
    },
    {
      "x": 3,
      "y": 28,
      "z": -3,
      "name": "Rock_Sandstone_Brick",
      "rotation": 3
    },
    {
      "x": 3,
      "y": 29,
      "z": -3,
      "name": "Soil_Clay_Ocean_Brick_Ornate",
      "rotation": 3
    },
    {
      "x": 3,
      "y": 30,
      "z": -3,
      "name": "Soil_Clay_Ocean_Brick_Smooth",
      "rotation": 3
    },
    {
      "x": 3,
      "y": 31,
      "z": -3,
      "name": "Soil_Clay_Ocean_Brick_Smooth",
      "rotation": 3
    },
    {
      "x": 3,
      "y": 32,
      "z": -3,
      "name": "Soil_Clay_Ocean_Brick_Half",
      "rotation": 3
    },
    {
      "x": 3,
      "y": 1,
      "z": -2,
      "name": "Rock_Sandstone_Brick",
      "rotation": 3
    },
    {
      "x": 3,
      "y": 2,
      "z": -2,
      "name": "Rock_Sandstone_Cobble",
      "rotation": 3
    },
    {
      "x": 3,
      "y": 3,
      "z": -2,
      "name": "Rock_Sandstone_Cobble",
      "rotation": 3
    },
    {
      "x": 3,
      "y": 4,
      "z": -2,
      "name": "Rock_Sandstone_Cobble",
      "rotation": 3
    },
    {
      "x": 3,
      "y": 5,
      "z": -2,
      "name": "Rock_Sandstone_Cobble",
      "rotation": 3
    },
    {
      "x": 3,
      "y": 9,
      "z": -2,
      "name": "Rock_Sandstone_Cobble",
      "rotation": 3
    },
    {
      "x": 3,
      "y": 10,
      "z": -2,
      "name": "Wood_Dry_Trunk",
      "rotation": 3
    },
    {
      "x": 3,
      "y": 11,
      "z": -2,
      "name": "Wood_Dry_Trunk",
      "rotation": 3
    },
    {
      "x": 3,
      "y": 12,
      "z": -2,
      "name": "Wood_Dry_Trunk",
      "rotation": 3
    },
    {
      "x": 3,
      "y": 13,
      "z": -2,
      "name": "Wood_Dry_Trunk",
      "rotation": 3
    },
    {
      "x": 3,
      "y": 14,
      "z": -2,
      "name": "Wood_Dry_Trunk",
      "rotation": 3
    },
    {
      "x": 3,
      "y": 15,
      "z": -2,
      "name": "Wood_Dry_Trunk",
      "rotation": 3
    },
    {
      "x": 3,
      "y": 16,
      "z": -2,
      "name": "Wood_Dry_Trunk",
      "rotation": 3
    },
    {
      "x": 3,
      "y": 17,
      "z": -2,
      "name": "Wood_Dry_Trunk",
      "rotation": 3
    },
    {
      "x": 3,
      "y": 18,
      "z": -2,
      "name": "Wood_Dry_Trunk",
      "rotation": 3
    },
    {
      "x": 3,
      "y": 19,
      "z": -2,
      "name": "Wood_Dry_Trunk",
      "rotation": 3
    },
    {
      "x": 3,
      "y": 20,
      "z": -2,
      "name": "Wood_Dry_Trunk",
      "rotation": 3
    },
    {
      "x": 3,
      "y": 21,
      "z": -2,
      "name": "Wood_Dry_Trunk",
      "rotation": 3
    },
    {
      "x": 3,
      "y": 22,
      "z": -2,
      "name": "Wood_Dry_Trunk",
      "rotation": 3
    },
    {
      "x": 3,
      "y": 23,
      "z": -2,
      "name": "Rock_Sandstone_Brick_Smooth",
      "rotation": 3
    },
    {
      "x": 3,
      "y": 24,
      "z": -2,
      "name": "Rock_Sandstone_Brick_Smooth",
      "rotation": 3
    },
    {
      "x": 3,
      "y": 25,
      "z": -2,
      "name": "Rock_Sandstone_White_Brick",
      "rotation": 3
    },
    {
      "x": 3,
      "y": 26,
      "z": -2,
      "name": "Rock_Sandstone_White_Brick",
      "rotation": 3
    },
    {
      "x": 3,
      "y": 27,
      "z": -2,
      "name": "Rock_Sandstone_Brick_Smooth",
      "rotation": 3
    },
    {
      "x": 3,
      "y": 28,
      "z": -2,
      "name": "Rock_Sandstone_Brick_Ornate",
      "rotation": 3
    },
    {
      "x": 3,
      "y": 29,
      "z": -2,
      "name": "Soil_Clay_Ocean_Brick_Ornate",
      "rotation": 3
    },
    {
      "x": 3,
      "y": 30,
      "z": -2,
      "name": "Soil_Clay_Ocean_Brick_Half",
      "rotation": 4
    },
    {
      "x": 3,
      "y": 31,
      "z": -2,
      "name": "Soil_Clay_Ocean_Brick_Half",
      "rotation": 4
    },
    {
      "x": 3,
      "y": 1,
      "z": -1,
      "name": "Rock_Sandstone_Brick",
      "rotation": 3
    },
    {
      "x": 3,
      "y": 2,
      "z": -1,
      "name": "Rock_Sandstone_Brick",
      "rotation": 3
    },
    {
      "x": 3,
      "y": 3,
      "z": -1,
      "name": "Rock_Sandstone_Cobble",
      "rotation": 3
    },
    {
      "x": 3,
      "y": 4,
      "z": -1,
      "name": "Rock_Sandstone_Brick",
      "rotation": 3
    },
    {
      "x": 3,
      "y": 5,
      "z": -1,
      "name": "Rock_Sandstone_Brick",
      "rotation": 3
    },
    {
      "x": 3,
      "y": 6,
      "z": -1,
      "name": "Rock_Sandstone_Brick",
      "rotation": 3
    },
    {
      "x": 3,
      "y": 7,
      "z": -1,
      "name": "Rock_Sandstone_Brick",
      "rotation": 3
    },
    {
      "x": 3,
      "y": 8,
      "z": -1,
      "name": "Rock_Sandstone_Cobble",
      "rotation": 3
    },
    {
      "x": 3,
      "y": 9,
      "z": -1,
      "name": "Rock_Sandstone_Cobble",
      "rotation": 3
    },
    {
      "x": 3,
      "y": 10,
      "z": -1,
      "name": "Rock_Sandstone_Brick",
      "rotation": 3
    },
    {
      "x": 3,
      "y": 11,
      "z": -1,
      "name": "Rock_Sandstone_Brick",
      "rotation": 3
    },
    {
      "x": 3,
      "y": 12,
      "z": -1,
      "name": "Rock_Sandstone_Brick",
      "rotation": 3
    },
    {
      "x": 3,
      "y": 13,
      "z": -1,
      "name": "Rock_Sandstone_Brick",
      "rotation": 3
    },
    {
      "x": 3,
      "y": 14,
      "z": -1,
      "name": "Rock_Sandstone_Brick",
      "rotation": 3
    },
    {
      "x": 3,
      "y": 15,
      "z": -1,
      "name": "Rock_Sandstone_Brick",
      "rotation": 3
    },
    {
      "x": 3,
      "y": 16,
      "z": -1,
      "name": "Rock_Sandstone_Brick_Ornate",
      "rotation": 3
    },
    {
      "x": 3,
      "y": 17,
      "z": -1,
      "name": "Rock_Sandstone_Brick",
      "rotation": 3
    },
    {
      "x": 3,
      "y": 21,
      "z": -1,
      "name": "Rock_Sandstone_Brick_Stairs",
      "rotation": 33
    },
    {
      "x": 3,
      "y": 22,
      "z": -1,
      "name": "Rock_Sandstone_Brick",
      "rotation": 3
    },
    {
      "x": 3,
      "y": 23,
      "z": -1,
      "name": "Soil_Clay_Ocean_Brick_Roof"
    },
    {
      "x": 3,
      "y": 24,
      "z": -1,
      "name": "Rock_Sandstone_Brick_Smooth",
      "rotation": 3
    },
    {
      "x": 3,
      "y": 27,
      "z": -1,
      "name": "Rock_Sandstone_Brick_Smooth_Half",
      "rotation": 4
    },
    {
      "x": 3,
      "y": 28,
      "z": -1,
      "name": "Soil_Clay_Ocean_Brick_Roof"
    },
    {
      "x": 3,
      "y": 1,
      "z": 0,
      "name": "Rock_Sandstone_Cobble",
      "rotation": 3
    },
    {
      "x": 3,
      "y": 2,
      "z": 0,
      "name": "Rock_Sandstone_Cobble",
      "rotation": 3
    },
    {
      "x": 3,
      "y": 3,
      "z": 0,
      "name": "Rock_Sandstone_Cobble",
      "rotation": 3
    },
    {
      "x": 3,
      "y": 4,
      "z": 0,
      "name": "Rock_Sandstone_Cobble",
      "rotation": 3
    },
    {
      "x": 3,
      "y": 5,
      "z": 0,
      "name": "Rock_Sandstone_Brick",
      "rotation": 3
    },
    {
      "x": 3,
      "y": 6,
      "z": 0,
      "name": "Rock_Sandstone_Brick_Pillar_Base",
      "rotation": 3
    },
    {
      "x": 3,
      "y": 7,
      "z": 0,
      "name": "Rock_Sandstone_Brick",
      "rotation": 3
    },
    {
      "x": 3,
      "y": 8,
      "z": 0,
      "name": "Rock_Sandstone_Cobble_Stairs"
    },
    {
      "x": 3,
      "y": 9,
      "z": 0,
      "name": "Rock_Sandstone_Cobble_Half",
      "rotation": 4
    },
    {
      "x": 3,
      "y": 12,
      "z": 0,
      "name": "Rock_Sandstone_Brick_Smooth_Half",
      "rotation": 7
    },
    {
      "x": 3,
      "y": 13,
      "z": 0,
      "name": "Rock_Sandstone_Brick_Smooth_Half",
      "rotation": 7
    },
    {
      "x": 3,
      "y": 17,
      "z": 0,
      "name": "Rock_Sandstone_Brick_Half",
      "rotation": 4
    },
    {
      "x": 3,
      "y": 22,
      "z": 0,
      "name": "Soil_Clay_Ocean_Brick_Roof"
    },
    {
      "x": 4,
      "y": 1,
      "z": -9,
      "name": "Wood_Dry_Trunk",
      "support": 15,
      "rotation": 5
    },
    {
      "x": 4,
      "y": 1,
      "z": -8,
      "name": "Rock_Sandstone_Cobble",
      "rotation": 3
    },
    {
      "x": 4,
      "y": 4,
      "z": -8,
      "name": "Wood_Drywood_Planks_Half",
      "rotation": 33
    },
    {
      "x": 4,
      "y": 5,
      "z": -8,
      "name": "Rock_Sandstone_Brick",
      "rotation": 3
    },
    {
      "x": 4,
      "y": 6,
      "z": -8,
      "name": "Rock_Sandstone_Brick_Pillar_Base",
      "rotation": 3
    },
    {
      "x": 4,
      "y": 7,
      "z": -8,
      "name": "Rock_Sandstone_Brick",
      "rotation": 3
    },
    {
      "x": 4,
      "y": 8,
      "z": -8,
      "name": "Rock_Sandstone_Cobble_Stairs",
      "rotation": 2
    },
    {
      "x": 4,
      "y": 9,
      "z": -8,
      "name": "Rock_Sandstone_Cobble_Half",
      "rotation": 6
    },
    {
      "x": 4,
      "y": 14,
      "z": -8,
      "name": "Rock_Sandstone_Brick_Smooth_Half",
      "rotation": 3
    },
    {
      "x": 4,
      "y": 17,
      "z": -8,
      "name": "Rock_Sandstone_Brick_Stairs",
      "rotation": 34
    },
    {
      "x": 4,
      "y": 22,
      "z": -8,
      "name": "Soil_Clay_Ocean_Brick_Roof",
      "rotation": 2
    },
    {
      "x": 4,
      "y": 1,
      "z": -7,
      "name": "Rock_Sandstone_Cobble",
      "rotation": 3
    },
    {
      "x": 4,
      "y": 6,
      "z": -7,
      "name": "Rock_Sandstone_Brick",
      "rotation": 3
    },
    {
      "x": 4,
      "y": 7,
      "z": -7,
      "name": "Rock_Sandstone_Brick",
      "rotation": 3
    },
    {
      "x": 4,
      "y": 8,
      "z": -7,
      "name": "Rock_Sandstone_Cobble",
      "rotation": 3
    },
    {
      "x": 4,
      "y": 9,
      "z": -7,
      "name": "Rock_Sandstone_Cobble",
      "rotation": 3
    },
    {
      "x": 4,
      "y": 10,
      "z": -7,
      "name": "Rock_Sandstone_Brick",
      "rotation": 3
    },
    {
      "x": 4,
      "y": 11,
      "z": -7,
      "name": "Rock_Sandstone_Brick",
      "rotation": 3
    },
    {
      "x": 4,
      "y": 12,
      "z": -7,
      "name": "Furniture_Desert_Window"
    },
    {
      "x": 4,
      "y": 13,
      "z": -7,
      "name": "Furniture_Desert_Window"
    },
    {
      "x": 4,
      "y": 14,
      "z": -7,
      "name": "Rock_Sandstone_Brick",
      "rotation": 3
    },
    {
      "x": 4,
      "y": 15,
      "z": -7,
      "name": "Rock_Sandstone_Brick",
      "rotation": 3
    },
    {
      "x": 4,
      "y": 16,
      "z": -7,
      "name": "Rock_Sandstone_Brick_Ornate",
      "rotation": 3
    },
    {
      "x": 4,
      "y": 17,
      "z": -7,
      "name": "Rock_Sandstone_Brick",
      "rotation": 3
    },
    {
      "x": 4,
      "y": 21,
      "z": -7,
      "name": "Rock_Sandstone_Brick_Smooth_Half",
      "rotation": 33
    },
    {
      "x": 4,
      "y": 22,
      "z": -7,
      "name": "Rock_Sandstone_Brick",
      "rotation": 3
    },
    {
      "x": 4,
      "y": 23,
      "z": -7,
      "name": "Wood_Dry_Trunk",
      "rotation": 7
    },
    {
      "x": 4,
      "y": 24,
      "z": -7,
      "name": "Rock_Sandstone_Brick_Smooth",
      "rotation": 3
    },
    {
      "x": 4,
      "y": 27,
      "z": -7,
      "name": "Rock_Sandstone_Brick_Smooth_Half",
      "rotation": 6
    },
    {
      "x": 4,
      "y": 28,
      "z": -7,
      "name": "Soil_Clay_Ocean_Brick_Roof",
      "rotation": 2
    },
    {
      "x": 4,
      "y": 1,
      "z": -6,
      "name": "Rock_Sandstone_Cobble",
      "rotation": 3
    },
    {
      "x": 4,
      "y": 6,
      "z": -6,
      "name": "Rock_Sandstone_Brick",
      "rotation": 3
    },
    {
      "x": 4,
      "y": 7,
      "z": -6,
      "name": "Rock_Sandstone_Cobble",
      "rotation": 3
    },
    {
      "x": 4,
      "y": 8,
      "z": -6,
      "name": "Rock_Sandstone_Cobble",
      "rotation": 3
    },
    {
      "x": 4,
      "y": 14,
      "z": -6,
      "name": "Wood_Dry_Trunk",
      "rotation": 7
    },
    {
      "x": 4,
      "y": 17,
      "z": -6,
      "name": "Wood_Drywood_Planks",
      "rotation": 3
    },
    {
      "x": 4,
      "y": 22,
      "z": -6,
      "name": "Rock_Sandstone_Brick",
      "rotation": 3
    },
    {
      "x": 4,
      "y": 23,
      "z": -6,
      "name": "Rock_Sandstone_Brick_Smooth",
      "rotation": 3
    },
    {
      "x": 4,
      "y": 24,
      "z": -6,
      "name": "Rock_Sandstone_Brick_Smooth",
      "rotation": 3
    },
    {
      "x": 4,
      "y": 25,
      "z": -6,
      "name": "Rock_Sandstone_Brick_Smooth_Half",
      "rotation": 3
    },
    {
      "x": 4,
      "y": 27,
      "z": -6,
      "name": "Rock_Sandstone_Brick_Smooth",
      "rotation": 3
    },
    {
      "x": 4,
      "y": 28,
      "z": -6,
      "name": "Rock_Sandstone_Brick_Ornate",
      "rotation": 3
    },
    {
      "x": 4,
      "y": 29,
      "z": -6,
      "name": "Soil_Clay_Ocean_Brick_Ornate",
      "rotation": 3
    },
    {
      "x": 4,
      "y": 30,
      "z": -6,
      "name": "Soil_Clay_Ocean_Brick_Half",
      "rotation": 3
    },
    {
      "x": 4,
      "y": 1,
      "z": -5,
      "name": "Rock_Sandstone_Cobble",
      "rotation": 1
    },
    {
      "x": 4,
      "y": 2,
      "z": -5,
      "name": "Deco_Pot_Clay_Broken"
    },
    {
      "x": 4,
      "y": 6,
      "z": -5,
      "name": "Rock_Sandstone_Brick",
      "rotation": 3
    },
    {
      "x": 4,
      "y": 7,
      "z": -5,
      "name": "Rock_Sandstone_Cobble",
      "rotation": 3
    },
    {
      "x": 4,
      "y": 8,
      "z": -5,
      "name": "Rock_Sandstone_Cobble",
      "rotation": 3
    },
    {
      "x": 4,
      "y": 17,
      "z": -5,
      "name": "Wood_Drywood_Planks",
      "rotation": 3
    },
    {
      "x": 4,
      "y": 23,
      "z": -5,
      "name": "Wood_Drywood_Planks",
      "rotation": 3
    },
    {
      "x": 4,
      "y": 28,
      "z": -5,
      "name": "Rock_Sandstone_Brick_Half",
      "rotation": 33
    },
    {
      "x": 4,
      "y": 29,
      "z": -5,
      "name": "Wood_Dry_Trunk",
      "rotation": 7
    },
    {
      "x": 4,
      "y": 30,
      "z": -5,
      "name": "Block_Spawner_Block",
      "components": {
        "Components": {
          "BlockSpawner": {}
        }
      },
      "rotation": 1
    },
    {
      "x": 4,
      "y": 1,
      "z": -4,
      "name": "Rock_Sandstone_Brick",
      "rotation": 3
    },
    {
      "x": 4,
      "y": 2,
      "z": -4,
      "name": "Rock_Sandstone_Brick",
      "rotation": 3
    },
    {
      "x": 4,
      "y": 3,
      "z": -4,
      "name": "Rock_Sandstone_Brick",
      "rotation": 3
    },
    {
      "x": 4,
      "y": 4,
      "z": -4,
      "name": "Rock_Sandstone_Brick",
      "rotation": 3
    },
    {
      "x": 4,
      "y": 5,
      "z": -4,
      "name": "Rock_Sandstone_Brick",
      "rotation": 3
    },
    {
      "x": 4,
      "y": 6,
      "z": -4,
      "name": "Rock_Sandstone_Brick",
      "rotation": 3
    },
    {
      "x": 4,
      "y": 7,
      "z": -4,
      "name": "Rock_Sandstone_Brick",
      "rotation": 3
    },
    {
      "x": 4,
      "y": 8,
      "z": -4,
      "name": "Rock_Sandstone_Brick",
      "rotation": 3
    },
    {
      "x": 4,
      "y": 9,
      "z": -4,
      "name": "Rock_Sandstone_Brick",
      "rotation": 3
    },
    {
      "x": 4,
      "y": 17,
      "z": -4,
      "name": "Wood_Drywood_Planks",
      "rotation": 3
    },
    {
      "x": 4,
      "y": 23,
      "z": -4,
      "name": "Wood_Drywood_Planks",
      "rotation": 3
    },
    {
      "x": 4,
      "y": 28,
      "z": -4,
      "name": "Rock_Sandstone_Brick_Half",
      "rotation": 33
    },
    {
      "x": 4,
      "y": 29,
      "z": -4,
      "name": "Wood_Dry_Trunk",
      "rotation": 4
    },
    {
      "x": 4,
      "y": 32,
      "z": -4,
      "name": "Soil_Clay_Ocean_Brick_Smooth",
      "rotation": 3
    },
    {
      "x": 4,
      "y": 1,
      "z": -3,
      "name": "Rock_Sandstone_Brick",
      "rotation": 3
    },
    {
      "x": 4,
      "y": 2,
      "z": -3,
      "name": "Rock_Sandstone_Cobble",
      "rotation": 3
    },
    {
      "x": 4,
      "y": 3,
      "z": -3,
      "name": "Rock_Sandstone_Cobble",
      "rotation": 3
    },
    {
      "x": 4,
      "y": 4,
      "z": -3,
      "name": "Rock_Sandstone_Cobble",
      "rotation": 3
    },
    {
      "x": 4,
      "y": 5,
      "z": -3,
      "name": "Rock_Sandstone_Cobble",
      "rotation": 3
    },
    {
      "x": 4,
      "y": 6,
      "z": -3,
      "name": "Rock_Sandstone_Cobble_Stairs",
      "rotation": 3
    },
    {
      "x": 4,
      "y": 9,
      "z": -3,
      "name": "Rock_Sandstone_Cobble_Half",
      "rotation": 33
    },
    {
      "x": 4,
      "y": 17,
      "z": -3,
      "name": "Wood_Drywood_Planks",
      "rotation": 3
    },
    {
      "x": 4,
      "y": 23,
      "z": -3,
      "name": "Wood_Drywood_Planks",
      "rotation": 3
    },
    {
      "x": 4,
      "y": 28,
      "z": -3,
      "name": "Rock_Sandstone_Brick",
      "rotation": 3
    },
    {
      "x": 4,
      "y": 29,
      "z": -3,
      "name": "Soil_Clay_Ocean_Brick_Ornate",
      "rotation": 3
    },
    {
      "x": 4,
      "y": 30,
      "z": -3,
      "name": "Soil_Clay_Ocean_Brick_Smooth",
      "rotation": 3
    },
    {
      "x": 4,
      "y": 31,
      "z": -3,
      "name": "Soil_Clay_Ocean_Brick_Smooth",
      "rotation": 3
    },
    {
      "x": 4,
      "y": 32,
      "z": -3,
      "name": "Soil_Clay_Ocean_Brick_Smooth",
      "rotation": 3
    },
    {
      "x": 4,
      "y": 1,
      "z": -2,
      "name": "Rock_Sandstone_Brick",
      "rotation": 3
    },
    {
      "x": 4,
      "y": 2,
      "z": -2,
      "name": "Rock_Sandstone_Cobble",
      "rotation": 3
    },
    {
      "x": 4,
      "y": 3,
      "z": -2,
      "name": "Rock_Sandstone_Cobble",
      "rotation": 3
    },
    {
      "x": 4,
      "y": 4,
      "z": -2,
      "name": "Rock_Sandstone_Cobble",
      "rotation": 3
    },
    {
      "x": 4,
      "y": 5,
      "z": -2,
      "name": "Rock_Sandstone_Cobble",
      "rotation": 3
    },
    {
      "x": 4,
      "y": 6,
      "z": -2,
      "name": "Rock_Sandstone_Cobble_Stairs",
      "rotation": 3
    },
    {
      "x": 4,
      "y": 9,
      "z": -2,
      "name": "Rock_Sandstone_Cobble_Half",
      "rotation": 33
    },
    {
      "x": 4,
      "y": 10,
      "z": -2,
      "name": "Deco_Pot_Clay_Broken"
    },
    {
      "x": 4,
      "y": 16,
      "z": -2,
      "name": "Wood_Dry_Trunk",
      "rotation": 7
    },
    {
      "x": 4,
      "y": 17,
      "z": -2,
      "name": "Wood_Drywood_Planks",
      "rotation": 3
    },
    {
      "x": 4,
      "y": 18,
      "z": -2,
      "name": "Deco_Pot_Clay_Broken"
    },
    {
      "x": 4,
      "y": 22,
      "z": -2,
      "name": "Rock_Sandstone_Brick",
      "rotation": 3
    },
    {
      "x": 4,
      "y": 23,
      "z": -2,
      "name": "Rock_Sandstone_Brick_Smooth",
      "rotation": 3
    },
    {
      "x": 4,
      "y": 24,
      "z": -2,
      "name": "Rock_Sandstone_Brick_Smooth",
      "rotation": 3
    },
    {
      "x": 4,
      "y": 25,
      "z": -2,
      "name": "Furniture_Desert_Window"
    },
    {
      "x": 4,
      "y": 26,
      "z": -2,
      "name": "Furniture_Desert_Window"
    },
    {
      "x": 4,
      "y": 27,
      "z": -2,
      "name": "Rock_Sandstone_Brick_Smooth",
      "rotation": 3
    },
    {
      "x": 4,
      "y": 28,
      "z": -2,
      "name": "Rock_Sandstone_Brick_Ornate",
      "rotation": 3
    },
    {
      "x": 4,
      "y": 29,
      "z": -2,
      "name": "Soil_Clay_Ocean_Brick_Ornate",
      "rotation": 3
    },
    {
      "x": 4,
      "y": 30,
      "z": -2,
      "name": "Soil_Clay_Ocean_Brick_Smooth",
      "rotation": 3
    },
    {
      "x": 4,
      "y": 31,
      "z": -2,
      "name": "Soil_Clay_Ocean_Brick_Half",
      "rotation": 4
    },
    {
      "x": 4,
      "y": 1,
      "z": -1,
      "name": "Rock_Sandstone_Brick",
      "rotation": 3
    },
    {
      "x": 4,
      "y": 2,
      "z": -1,
      "name": "Rock_Sandstone_Cobble",
      "rotation": 3
    },
    {
      "x": 4,
      "y": 3,
      "z": -1,
      "name": "Rock_Sandstone_Brick",
      "rotation": 3
    },
    {
      "x": 4,
      "y": 4,
      "z": -1,
      "name": "Rock_Sandstone_Brick",
      "rotation": 3
    },
    {
      "x": 4,
      "y": 5,
      "z": -1,
      "name": "Rock_Sandstone_Brick",
      "rotation": 3
    },
    {
      "x": 4,
      "y": 6,
      "z": -1,
      "name": "Rock_Sandstone_Brick",
      "rotation": 3
    },
    {
      "x": 4,
      "y": 7,
      "z": -1,
      "name": "Rock_Sandstone_Brick",
      "rotation": 3
    },
    {
      "x": 4,
      "y": 8,
      "z": -1,
      "name": "Rock_Sandstone_Cobble",
      "rotation": 3
    },
    {
      "x": 4,
      "y": 9,
      "z": -1,
      "name": "Rock_Sandstone_Cobble",
      "rotation": 3
    },
    {
      "x": 4,
      "y": 10,
      "z": -1,
      "name": "Rock_Sandstone_Brick",
      "rotation": 3
    },
    {
      "x": 4,
      "y": 11,
      "z": -1,
      "name": "Rock_Sandstone_Brick",
      "rotation": 3
    },
    {
      "x": 4,
      "y": 13,
      "z": -1,
      "name": "Furniture_Desert_Window"
    },
    {
      "x": 4,
      "y": 14,
      "z": -1,
      "name": "Rock_Sandstone_Brick",
      "rotation": 3
    },
    {
      "x": 4,
      "y": 15,
      "z": -1,
      "name": "Rock_Sandstone_Brick",
      "rotation": 3
    },
    {
      "x": 4,
      "y": 16,
      "z": -1,
      "name": "Rock_Sandstone_Brick_Ornate",
      "rotation": 3
    },
    {
      "x": 4,
      "y": 17,
      "z": -1,
      "name": "Rock_Sandstone_Brick",
      "rotation": 3
    },
    {
      "x": 4,
      "y": 21,
      "z": -1,
      "name": "Rock_Sandstone_Brick_Smooth_Half",
      "rotation": 33
    },
    {
      "x": 4,
      "y": 22,
      "z": -1,
      "name": "Rock_Sandstone_Brick",
      "rotation": 3
    },
    {
      "x": 4,
      "y": 23,
      "z": -1,
      "name": "Soil_Clay_Ocean_Brick_Roof"
    },
    {
      "x": 4,
      "y": 24,
      "z": -1,
      "name": "Rock_Sandstone_Brick_Smooth",
      "rotation": 3
    },
    {
      "x": 4,
      "y": 27,
      "z": -1,
      "name": "Rock_Sandstone_Brick_Smooth_Half",
      "rotation": 4
    },
    {
      "x": 4,
      "y": 28,
      "z": -1,
      "name": "Soil_Clay_Ocean_Brick_Roof"
    },
    {
      "x": 4,
      "y": 1,
      "z": 0,
      "name": "Rock_Sandstone_Cobble",
      "rotation": 3
    },
    {
      "x": 4,
      "y": 2,
      "z": 0,
      "name": "Rock_Sandstone_Cobble",
      "rotation": 3
    },
    {
      "x": 4,
      "y": 3,
      "z": 0,
      "name": "Rock_Sandstone_Cobble",
      "rotation": 3
    },
    {
      "x": 4,
      "y": 4,
      "z": 0,
      "name": "Rock_Sandstone_Brick",
      "rotation": 3
    },
    {
      "x": 4,
      "y": 5,
      "z": 0,
      "name": "Rock_Sandstone_Brick",
      "rotation": 3
    },
    {
      "x": 4,
      "y": 6,
      "z": 0,
      "name": "Rock_Sandstone_Brick_Pillar_Base",
      "rotation": 3
    },
    {
      "x": 4,
      "y": 7,
      "z": 0,
      "name": "Rock_Sandstone_Brick",
      "rotation": 3
    },
    {
      "x": 4,
      "y": 8,
      "z": 0,
      "name": "Rock_Sandstone_Cobble_Stairs"
    },
    {
      "x": 4,
      "y": 9,
      "z": 0,
      "name": "Rock_Sandstone_Cobble_Half",
      "rotation": 4
    },
    {
      "x": 4,
      "y": 11,
      "z": 0,
      "name": "Rock_Sandstone_Brick_Smooth_Half",
      "rotation": 4
    },
    {
      "x": 4,
      "y": 14,
      "z": 0,
      "name": "Rock_Sandstone_Brick_Smooth_Half",
      "rotation": 3
    },
    {
      "x": 4,
      "y": 17,
      "z": 0,
      "name": "Rock_Sandstone_Brick_Half",
      "rotation": 4
    },
    {
      "x": 4,
      "y": 22,
      "z": 0,
      "name": "Soil_Clay_Ocean_Brick_Roof"
    },
    {
      "x": 5,
      "y": 1,
      "z": -9,
      "name": "Wood_Dry_Trunk",
      "support": 15,
      "rotation": 5
    },
    {
      "x": 5,
      "y": 1,
      "z": -8,
      "name": "Rock_Sandstone_Cobble"
    },
    {
      "x": 5,
      "y": 2,
      "z": -8,
      "name": "Wood_Drywood_Planks_Half",
      "rotation": 7
    },
    {
      "x": 5,
      "y": 3,
      "z": -8,
      "name": "Wood_Drywood_Planks_Half",
      "rotation": 7
    },
    {
      "x": 5,
      "y": 4,
      "z": -8,
      "name": "Wood_Drywood_Stairs",
      "rotation": 35
    },
    {
      "x": 5,
      "y": 5,
      "z": -8,
      "name": "Rock_Sandstone_Brick",
      "rotation": 3
    },
    {
      "x": 5,
      "y": 6,
      "z": -8,
      "name": "Rock_Sandstone_Brick_Pillar_Base",
      "rotation": 3
    },
    {
      "x": 5,
      "y": 7,
      "z": -8,
      "name": "Rock_Sandstone_Brick",
      "rotation": 3
    },
    {
      "x": 5,
      "y": 8,
      "z": -8,
      "name": "Rock_Sandstone_Cobble_Stairs",
      "rotation": 2
    },
    {
      "x": 5,
      "y": 9,
      "z": -8,
      "name": "Rock_Sandstone_Cobble_Half",
      "rotation": 6
    },
    {
      "x": 5,
      "y": 13,
      "z": -8,
      "name": "Rock_Sandstone_Brick_Smooth_Half",
      "rotation": 5
    },
    {
      "x": 5,
      "y": 17,
      "z": -8,
      "name": "Rock_Sandstone_Brick_Half",
      "rotation": 6
    },
    {
      "x": 5,
      "y": 22,
      "z": -8,
      "name": "Soil_Clay_Ocean_Brick_Roof",
      "rotation": 2
    },
    {
      "x": 5,
      "y": 1,
      "z": -7,
      "name": "Rock_Sandstone_Cobble",
      "rotation": 3
    },
    {
      "x": 5,
      "y": 6,
      "z": -7,
      "name": "Rock_Sandstone_Brick",
      "rotation": 3
    },
    {
      "x": 5,
      "y": 7,
      "z": -7,
      "name": "Rock_Sandstone_Brick",
      "rotation": 3
    },
    {
      "x": 5,
      "y": 8,
      "z": -7,
      "name": "Rock_Sandstone_Cobble",
      "rotation": 3
    },
    {
      "x": 5,
      "y": 9,
      "z": -7,
      "name": "Rock_Sandstone_Cobble",
      "rotation": 3
    },
    {
      "x": 5,
      "y": 10,
      "z": -7,
      "name": "Rock_Sandstone_Brick",
      "rotation": 3
    },
    {
      "x": 5,
      "y": 11,
      "z": -7,
      "name": "Rock_Sandstone_Brick",
      "rotation": 3
    },
    {
      "x": 5,
      "y": 12,
      "z": -7,
      "name": "Rock_Sandstone_Brick",
      "rotation": 3
    },
    {
      "x": 5,
      "y": 13,
      "z": -7,
      "name": "Rock_Sandstone_Brick",
      "rotation": 3
    },
    {
      "x": 5,
      "y": 14,
      "z": -7,
      "name": "Rock_Sandstone_Brick",
      "rotation": 3
    },
    {
      "x": 5,
      "y": 15,
      "z": -7,
      "name": "Rock_Sandstone_Brick",
      "rotation": 3
    },
    {
      "x": 5,
      "y": 16,
      "z": -7,
      "name": "Rock_Sandstone_Brick_Ornate",
      "rotation": 3
    },
    {
      "x": 5,
      "y": 17,
      "z": -7,
      "name": "Rock_Sandstone_Brick",
      "rotation": 3
    },
    {
      "x": 5,
      "y": 18,
      "z": -7,
      "name": "Furniture_Ancient_Pot",
      "rotation": 3
    },
    {
      "x": 5,
      "y": 21,
      "z": -7,
      "name": "Rock_Sandstone_Brick_Stairs",
      "rotation": 35
    },
    {
      "x": 5,
      "y": 22,
      "z": -7,
      "name": "Rock_Sandstone_Brick",
      "rotation": 3
    },
    {
      "x": 5,
      "y": 23,
      "z": -7,
      "name": "Wood_Dry_Trunk",
      "rotation": 7
    },
    {
      "x": 5,
      "y": 1,
      "z": -6,
      "name": "Rock_Sandstone_Cobble",
      "rotation": 3
    },
    {
      "x": 5,
      "y": 6,
      "z": -6,
      "name": "Rock_Sandstone_Cobble",
      "rotation": 3
    },
    {
      "x": 5,
      "y": 7,
      "z": -6,
      "name": "Rock_Sandstone_Cobble",
      "rotation": 3
    },
    {
      "x": 5,
      "y": 8,
      "z": -6,
      "name": "Rock_Sandstone_Cobble",
      "rotation": 3
    },
    {
      "x": 5,
      "y": 13,
      "z": -6,
      "name": "Wood_Dry_Branch_Long",
      "rotation": 3
    },
    {
      "x": 5,
      "y": 14,
      "z": -6,
      "name": "Wood_Dry_Trunk",
      "rotation": 7
    },
    {
      "x": 5,
      "y": 15,
      "z": -6,
      "name": "Wood_Dry_Branch_Long",
      "rotation": 3
    },
    {
      "x": 5,
      "y": 16,
      "z": -6,
      "name": "Wood_Dry_Trunk",
      "rotation": 4
    },
    {
      "x": 5,
      "y": 17,
      "z": -6,
      "name": "Wood_Drywood_Planks",
      "rotation": 3
    },
    {
      "x": 5,
      "y": 18,
      "z": -6,
      "name": "Deco_Pot_Clay_Broken",
      "rotation": 3
    },
    {
      "x": 5,
      "y": 22,
      "z": -6,
      "name": "Rock_Sandstone_Brick",
      "rotation": 3
    },
    {
      "x": 5,
      "y": 23,
      "z": -6,
      "name": "Rock_Sandstone_Brick_Smooth",
      "rotation": 3
    },
    {
      "x": 5,
      "y": 24,
      "z": -6,
      "name": "Rock_Sandstone_Brick_Smooth_Half",
      "rotation": 3
    },
    {
      "x": 5,
      "y": 1,
      "z": -5,
      "name": "Rock_Sandstone_Cobble",
      "rotation": 3
    },
    {
      "x": 5,
      "y": 6,
      "z": -5,
      "name": "Rock_Sandstone_Cobble",
      "rotation": 3
    },
    {
      "x": 5,
      "y": 7,
      "z": -5,
      "name": "Rock_Sandstone_Cobble",
      "rotation": 3
    },
    {
      "x": 5,
      "y": 8,
      "z": -5,
      "name": "Rock_Sandstone_Cobble_Half",
      "rotation": 3
    },
    {
      "x": 5,
      "y": 16,
      "z": -5,
      "name": "Wood_Dry_Trunk",
      "rotation": 4
    },
    {
      "x": 5,
      "y": 17,
      "z": -5,
      "name": "Wood_Drywood_Planks",
      "rotation": 3
    },
    {
      "x": 5,
      "y": 23,
      "z": -5,
      "name": "Wood_Drywood_Planks",
      "rotation": 3
    },
    {
      "x": 5,
      "y": 29,
      "z": -5,
      "name": "Wood_Dry_Trunk",
      "rotation": 7
    },
    {
      "x": 5,
      "y": 1,
      "z": -4,
      "name": "Rock_Sandstone_Cobble",
      "rotation": 3
    },
    {
      "x": 5,
      "y": 6,
      "z": -4,
      "name": "Rock_Sandstone_Cobble",
      "rotation": 3
    },
    {
      "x": 5,
      "y": 7,
      "z": -4,
      "name": "Rock_Sandstone_Cobble",
      "rotation": 3
    },
    {
      "x": 5,
      "y": 16,
      "z": -4,
      "name": "Wood_Dry_Trunk",
      "rotation": 4
    },
    {
      "x": 5,
      "y": 17,
      "z": -4,
      "name": "Wood_Drywood_Planks",
      "rotation": 3
    },
    {
      "x": 5,
      "y": 23,
      "z": -4,
      "name": "Wood_Drywood_Planks",
      "rotation": 3
    },
    {
      "x": 5,
      "y": 1,
      "z": -3,
      "name": "Rock_Sandstone_Cobble",
      "rotation": 3
    },
    {
      "x": 5,
      "y": 2,
      "z": -3,
      "name": "Deco_Pot_Clay_Broken"
    },
    {
      "x": 5,
      "y": 6,
      "z": -3,
      "name": "Rock_Sandstone_Cobble",
      "rotation": 3
    },
    {
      "x": 5,
      "y": 7,
      "z": -3,
      "name": "Rock_Sandstone_Cobble_Half",
      "rotation": 3
    },
    {
      "x": 5,
      "y": 16,
      "z": -3,
      "name": "Wood_Dry_Trunk",
      "rotation": 4
    },
    {
      "x": 5,
      "y": 17,
      "z": -3,
      "name": "Wood_Drywood_Planks",
      "rotation": 3
    },
    {
      "x": 5,
      "y": 23,
      "z": -3,
      "name": "Wood_Drywood_Planks",
      "rotation": 3
    },
    {
      "x": 5,
      "y": 24,
      "z": -3,
      "name": "Furniture_Temple_Dark_Pot",
      "rotation": 3
    },
    {
      "x": 5,
      "y": 28,
      "z": -3,
      "name": "Rock_Sandstone_Brick",
      "rotation": 3
    },
    {
      "x": 5,
      "y": 29,
      "z": -3,
      "name": "Soil_Clay_Ocean_Brick_Ornate",
      "rotation": 3
    },
    {
      "x": 5,
      "y": 30,
      "z": -3,
      "name": "Soil_Clay_Ocean_Brick_Smooth",
      "rotation": 3
    },
    {
      "x": 5,
      "y": 31,
      "z": -3,
      "name": "Soil_Clay_Ocean_Brick_Smooth",
      "rotation": 3
    },
    {
      "x": 5,
      "y": 32,
      "z": -3,
      "name": "Soil_Clay_Ocean_Brick_Half",
      "rotation": 3
    },
    {
      "x": 5,
      "y": 1,
      "z": -2,
      "name": "Rock_Sandstone_Cobble",
      "rotation": 3
    },
    {
      "x": 5,
      "y": 2,
      "z": -2,
      "name": "Furniture_Ancient_Crate",
      "rotation": 2
    },
    {
      "x": 5,
      "y": 3,
      "z": -2,
      "name": "Furniture_Ancient_Barrel",
      "rotation": 3
    },
    {
      "x": 5,
      "y": 6,
      "z": -2,
      "name": "Rock_Sandstone_Cobble",
      "rotation": 3
    },
    {
      "x": 5,
      "y": 16,
      "z": -2,
      "name": "Wood_Dry_Trunk",
      "rotation": 7
    },
    {
      "x": 5,
      "y": 17,
      "z": -2,
      "name": "Wood_Drywood_Planks",
      "rotation": 3
    },
    {
      "x": 5,
      "y": 22,
      "z": -2,
      "name": "Rock_Sandstone_Brick",
      "rotation": 3
    },
    {
      "x": 5,
      "y": 23,
      "z": -2,
      "name": "Rock_Sandstone_Brick_Smooth",
      "rotation": 3
    },
    {
      "x": 5,
      "y": 24,
      "z": -2,
      "name": "Rock_Sandstone_Brick_Smooth",
      "rotation": 3
    },
    {
      "x": 5,
      "y": 25,
      "z": -2,
      "name": "Rock_Sandstone_White_Brick",
      "rotation": 3
    },
    {
      "x": 5,
      "y": 26,
      "z": -2,
      "name": "Rock_Sandstone_White_Brick",
      "rotation": 3
    },
    {
      "x": 5,
      "y": 27,
      "z": -2,
      "name": "Rock_Sandstone_Brick_Smooth",
      "rotation": 3
    },
    {
      "x": 5,
      "y": 28,
      "z": -2,
      "name": "Rock_Sandstone_Brick_Ornate",
      "rotation": 3
    },
    {
      "x": 5,
      "y": 29,
      "z": -2,
      "name": "Soil_Clay_Ocean_Brick_Ornate",
      "rotation": 3
    },
    {
      "x": 5,
      "y": 30,
      "z": -2,
      "name": "Soil_Clay_Ocean_Brick_Half",
      "rotation": 4
    },
    {
      "x": 5,
      "y": 31,
      "z": -2,
      "name": "Soil_Clay_Ocean_Brick_Half",
      "rotation": 4
    },
    {
      "x": 5,
      "y": 1,
      "z": -1,
      "name": "Rock_Sandstone_Cobble",
      "rotation": 3
    },
    {
      "x": 5,
      "y": 2,
      "z": -1,
      "name": "Furniture_Ancient_Crate",
      "rotation": 2
    },
    {
      "x": 5,
      "y": 3,
      "z": -1,
      "name": "Furniture_Ancient_Crate",
      "rotation": 2
    },
    {
      "x": 5,
      "y": 6,
      "z": -1,
      "name": "Rock_Sandstone_Brick",
      "rotation": 3
    },
    {
      "x": 5,
      "y": 7,
      "z": -1,
      "name": "Rock_Sandstone_Cobble",
      "rotation": 3
    },
    {
      "x": 5,
      "y": 8,
      "z": -1,
      "name": "Rock_Sandstone_Cobble",
      "rotation": 3
    },
    {
      "x": 5,
      "y": 9,
      "z": -1,
      "name": "Rock_Sandstone_Cobble",
      "rotation": 3
    },
    {
      "x": 5,
      "y": 10,
      "z": -1,
      "name": "Rock_Sandstone_Brick",
      "rotation": 3
    },
    {
      "x": 5,
      "y": 11,
      "z": -1,
      "name": "Rock_Sandstone_Brick",
      "rotation": 3
    },
    {
      "x": 5,
      "y": 12,
      "z": -1,
      "name": "Rock_Sandstone_Brick",
      "rotation": 3
    },
    {
      "x": 5,
      "y": 13,
      "z": -1,
      "name": "Rock_Sandstone_Brick",
      "rotation": 3
    },
    {
      "x": 5,
      "y": 14,
      "z": -1,
      "name": "Rock_Sandstone_Brick",
      "rotation": 3
    },
    {
      "x": 5,
      "y": 15,
      "z": -1,
      "name": "Rock_Sandstone_Brick",
      "rotation": 3
    },
    {
      "x": 5,
      "y": 16,
      "z": -1,
      "name": "Rock_Sandstone_Brick_Half",
      "rotation": 3
    },
    {
      "x": 5,
      "y": 21,
      "z": -1,
      "name": "Rock_Sandstone_Brick_Stairs",
      "rotation": 35
    },
    {
      "x": 5,
      "y": 22,
      "z": -1,
      "name": "Rock_Sandstone_Brick",
      "rotation": 3
    },
    {
      "x": 5,
      "y": 23,
      "z": -1,
      "name": "Soil_Clay_Ocean_Brick_Roof"
    },
    {
      "x": 5,
      "y": 24,
      "z": -1,
      "name": "Rock_Sandstone_Brick_Smooth",
      "rotation": 3
    },
    {
      "x": 5,
      "y": 27,
      "z": -1,
      "name": "Rock_Sandstone_Brick_Smooth_Half",
      "rotation": 4
    },
    {
      "x": 5,
      "y": 28,
      "z": -1,
      "name": "Soil_Clay_Ocean_Brick_Roof"
    },
    {
      "x": 5,
      "y": 1,
      "z": 0,
      "name": "Rock_Sandstone_Cobble",
      "rotation": 3
    },
    {
      "x": 5,
      "y": 2,
      "z": 0,
      "name": "Rock_Sandstone_Cobble",
      "rotation": 3
    },
    {
      "x": 5,
      "y": 3,
      "z": 0,
      "name": "Rock_Sandstone_Brick",
      "rotation": 3
    },
    {
      "x": 5,
      "y": 4,
      "z": 0,
      "name": "Rock_Sandstone_Brick",
      "rotation": 3
    },
    {
      "x": 5,
      "y": 5,
      "z": 0,
      "name": "Rock_Sandstone_Brick",
      "rotation": 3
    },
    {
      "x": 5,
      "y": 6,
      "z": 0,
      "name": "Rock_Sandstone_Brick_Pillar_Base",
      "rotation": 3
    },
    {
      "x": 5,
      "y": 7,
      "z": 0,
      "name": "Rock_Sandstone_Brick",
      "rotation": 3
    },
    {
      "x": 5,
      "y": 8,
      "z": 0,
      "name": "Rock_Sandstone_Cobble_Stairs"
    },
    {
      "x": 5,
      "y": 9,
      "z": 0,
      "name": "Rock_Sandstone_Cobble_Half",
      "rotation": 4
    },
    {
      "x": 5,
      "y": 12,
      "z": 0,
      "name": "Rock_Sandstone_Brick_Smooth_Half",
      "rotation": 5
    },
    {
      "x": 5,
      "y": 13,
      "z": 0,
      "name": "Rock_Sandstone_Brick_Smooth_Half",
      "rotation": 5
    },
    {
      "x": 5,
      "y": 22,
      "z": 0,
      "name": "Soil_Clay_Ocean_Brick_Roof"
    },
    {
      "x": 6,
      "y": 1,
      "z": -9,
      "name": "Wood_Dry_Trunk",
      "support": 15,
      "rotation": 4
    },
    {
      "x": 6,
      "y": 1,
      "z": -8,
      "name": "Rock_Sandstone_Cobble",
      "rotation": 3
    },
    {
      "x": 6,
      "y": 2,
      "z": -8,
      "name": "Rock_Sandstone_Cobble",
      "rotation": 3
    },
    {
      "x": 6,
      "y": 3,
      "z": -8,
      "name": "Rock_Sandstone_Brick",
      "rotation": 3
    },
    {
      "x": 6,
      "y": 4,
      "z": -8,
      "name": "Rock_Sandstone_Brick",
      "rotation": 3
    },
    {
      "x": 6,
      "y": 5,
      "z": -8,
      "name": "Rock_Sandstone_Brick",
      "rotation": 3
    },
    {
      "x": 6,
      "y": 6,
      "z": -8,
      "name": "Rock_Sandstone_Brick_Pillar_Base",
      "rotation": 3
    },
    {
      "x": 6,
      "y": 7,
      "z": -8,
      "name": "Rock_Sandstone_Brick",
      "rotation": 3
    },
    {
      "x": 6,
      "y": 17,
      "z": -8,
      "name": "Rock_Sandstone_Brick_Half",
      "rotation": 6
    },
    {
      "x": 6,
      "y": 1,
      "z": -7,
      "name": "Rock_Sandstone_Cobble",
      "rotation": 3
    },
    {
      "x": 6,
      "y": 2,
      "z": -7,
      "name": "Furniture_Temple_Wind_Pot",
      "rotation": 3
    },
    {
      "x": 6,
      "y": 3,
      "z": -7,
      "name": "Furniture_Temple_Wind_Pot",
      "filler": 1024,
      "rotation": 3
    },
    {
      "x": 6,
      "y": 6,
      "z": -7,
      "name": "Rock_Sandstone_Brick",
      "rotation": 3
    },
    {
      "x": 6,
      "y": 7,
      "z": -7,
      "name": "Rock_Sandstone_Brick",
      "rotation": 3
    },
    {
      "x": 6,
      "y": 8,
      "z": -7,
      "name": "Rock_Sandstone_Brick_Pillar_Base",
      "rotation": 3
    },
    {
      "x": 6,
      "y": 9,
      "z": -7,
      "name": "Rock_Sandstone_Brick_Pillar_Middle",
      "rotation": 3
    },
    {
      "x": 6,
      "y": 10,
      "z": -7,
      "name": "Rock_Sandstone_Brick_Pillar_Base",
      "rotation": 33
    },
    {
      "x": 6,
      "y": 11,
      "z": -7,
      "name": "Rock_Sandstone_Brick_Pillar_Middle",
      "rotation": 3
    },
    {
      "x": 6,
      "y": 12,
      "z": -7,
