{
  "version": 8,
  "blockIdVersion": 11,
  "anchorX": 0,
  "anchorY": 0,
  "anchorZ": 0,
  "blocks": [
    {
      "x": -4,
      "y": 0,
      "z": -2,
      "name": "Rock_Sandstone_Cobble",
      "rotation": 3
    },
    {
      "x": -4,
      "y": 1,
      "z": -2,
      "name": "Rock_Sandstone_Cobble",
      "rotation": 3
    },
    {
      "x": -4,
      "y": 2,
      "z": -2,
      "name": "Rock_Sandstone_Cobble",
      "rotation": 3
    },
    {
      "x": -4,
      "y": 3,
      "z": -2,
      "name": "Rock_Sandstone_Brick",
      "rotation": 3
    },
    {
      "x": -4,
      "y": 4,
      "z": -2,
      "name": "Rock_Sandstone_Brick",
      "rotation": 3
    },
    {
      "x": -4,
      "y": 5,
      "z": -2,
      "name": "Rock_Sandstone_Brick_Pillar_Base",
      "rotation": 3
    },
    {
      "x": -4,
      "y": 6,
      "z": -2,
      "name": "Rock_Sandstone_Brick_Half",
      "rotation": 3
    },
    {
      "x": -4,
      "y": 0,
      "z": -1,
      "name": "Rock_Sandstone_Cobble",
      "rotation": 3
    },
    {
      "x": -4,
      "y": 1,
      "z": -1,
      "name": "Rock_Sandstone_Cobble",
      "rotation": 3
    },
    {
      "x": -4,
      "y": 2,
      "z": -1,
      "name": "Rock_Sandstone_Brick",
      "rotation": 3
    },
    {
      "x": -4,
      "y": 3,
      "z": -1,
      "name": "Rock_Sandstone_Brick",
      "rotation": 3
    },
    {
      "x": -4,
      "y": 4,
      "z": -1,
      "name": "Rock_Sandstone_Brick",
      "rotation": 3
    },
    {
      "x": -4,
      "y": 5,
      "z": -1,
      "name": "Rock_Sandstone_Brick_Pillar_Base",
      "rotation": 3
    },
    {
      "x": -4,
      "y": 6,
      "z": -1,
      "name": "Rock_Sandstone_Brick",
      "rotation": 3
    },
    {
      "x": -4,
      "y": 0,
      "z": 0,
      "name": "Rock_Sandstone_Cobble",
      "rotation": 3
    },
    {
      "x": -4,
      "y": 1,
      "z": 0,
      "name": "Rock_Sandstone_Cobble",
      "rotation": 3
    },
    {
      "x": -4,
      "y": 2,
      "z": 0,
      "name": "Rock_Sandstone_Cobble",
      "rotation": 3
    },
    {
      "x": -4,
      "y": 3,
      "z": 0,
      "name": "Rock_Sandstone_Brick",
      "rotation": 3
    },
    {
      "x": -4,
      "y": 4,
      "z": 0,
      "name": "Rock_Sandstone_Brick",
      "rotation": 3
    },
    {
      "x": -4,
      "y": 5,
      "z": 0,
      "name": "Rock_Sandstone_Brick_Pillar_Base",
      "rotation": 3
    },
    {
      "x": -4,
      "y": 6,
      "z": 0,
      "name": "Rock_Sandstone_Brick",
      "rotation": 3
    },
    {
      "x": -4,
      "y": 7,
      "z": 0,
      "name": "Rock_Sandstone_Cobble_Stairs",
      "rotation": 3
    },
    {
      "x": -4,
      "y": 8,
      "z": 0,
      "name": "Rock_Sandstone_Cobble_Half",
      "rotation": 7
    },
    {
      "x": -4,
      "y": 0,
      "z": 1,
      "name": "Rock_Sandstone_Cobble",
      "rotation": 3
    },
    {
      "x": -4,
      "y": 1,
      "z": 1,
      "name": "Rock_Sandstone_Cobble",
      "rotation": 3
    },
    {
      "x": -4,
      "y": 2,
      "z": 1,
      "name": "Rock_Sandstone_Cobble",
      "rotation": 3
    },
    {
      "x": -4,
      "y": 3,
      "z": 1,
      "name": "Rock_Sandstone_Cobble",
      "rotation": 3
    },
    {
      "x": -4,
      "y": 4,
      "z": 1,
      "name": "Rock_Sandstone_Brick",
      "rotation": 3
    },
    {
      "x": -4,
      "y": 5,
      "z": 1,
      "name": "Rock_Sandstone_Brick_Pillar_Base",
      "rotation": 3
    },
    {
      "x": -4,
      "y": 6,
      "z": 1,
      "name": "Rock_Sandstone_Brick",
      "rotation": 3
    },
    {
      "x": -4,
      "y": 7,
      "z": 1,
      "name": "Rock_Sandstone_Cobble_Stairs",
      "rotation": 3
    },
    {
      "x": -4,
      "y": 8,
      "z": 1,
      "name": "Rock_Sandstone_Cobble_Half",
      "rotation": 7
    },
    {
      "x": -4,
      "y": 10,
      "z": 1,
      "name": "Rock_Sandstone_Brick_Smooth_Half",
      "rotation": 7
    },
    {
      "x": -4,
      "y": 0,
      "z": 2,
      "name": "Rock_Sandstone_Cobble",
      "rotation": 3
    },
    {
      "x": -4,
      "y": 1,
      "z": 2,
      "name": "Rock_Sandstone_Cobble",
      "rotation": 3
    },
    {
      "x": -4,
      "y": 2,
      "z": 2,
      "name": "Rock_Sandstone_Cobble",
      "rotation": 3
    },
    {
      "x": -4,
      "y": 3,
      "z": 2,
      "name": "Rock_Sandstone_Cobble",
      "rotation": 3
    },
    {
      "x": -4,
      "y": 4,
      "z": 2,
      "name": "Rock_Sandstone_Brick",
      "rotation": 3
    },
    {
      "x": -4,
      "y": 5,
      "z": 2,
      "name": "Rock_Sandstone_Brick_Pillar_Base",
      "rotation": 3
    },
    {
      "x": -4,
      "y": 6,
      "z": 2,
      "name": "Rock_Sandstone_Brick",
      "rotation": 3
    },
    {
      "x": -4,
      "y": 7,
      "z": 2,
      "name": "Rock_Sandstone_Cobble_Stairs",
      "rotation": 3
    },
    {
      "x": -4,
      "y": 8,
      "z": 2,
      "name": "Rock_Sandstone_Cobble_Half",
      "rotation": 7
    },
    {
      "x": -4,
      "y": 0,
      "z": 3,
      "name": "Rock_Sandstone_Cobble",
      "rotation": 3
    },
    {
      "x": -4,
      "y": 1,
      "z": 3,
      "name": "Rock_Sandstone_Cobble",
      "rotation": 3
    },
    {
      "x": -4,
      "y": 2,
      "z": 3,
      "name": "Rock_Sandstone_Cobble",
      "rotation": 3
    },
    {
      "x": -4,
      "y": 3,
      "z": 3,
      "name": "Rock_Sandstone_Brick",
      "rotation": 3
    },
    {
      "x": -4,
      "y": 4,
      "z": 3,
      "name": "Rock_Sandstone_Brick",
      "rotation": 3
    },
    {
      "x": -4,
      "y": 5,
      "z": 3,
      "name": "Rock_Sandstone_Brick_Pillar_Base",
      "rotation": 3
    },
    {
      "x": -4,
      "y": 6,
      "z": 3,
      "name": "Rock_Sandstone_Brick",
      "rotation": 3
    },
    {
      "x": -4,
      "y": 0,
      "z": 4,
      "name": "Rock_Sandstone_Cobble",
      "rotation": 3
    },
    {
      "x": -4,
      "y": 1,
      "z": 4,
      "name": "Rock_Sandstone_Cobble",
      "rotation": 3
    },
    {
      "x": -4,
      "y": 2,
      "z": 4,
      "name": "Rock_Sandstone_Brick",
      "rotation": 3
    },
    {
      "x": -4,
      "y": 3,
      "z": 4,
      "name": "Rock_Sandstone_Brick",
      "rotation": 3
    },
    {
      "x": -4,
      "y": 4,
      "z": 4,
      "name": "Rock_Sandstone_Brick",
      "rotation": 3
    },
    {
      "x": -4,
      "y": 5,
      "z": 4,
      "name": "Rock_Sandstone_Brick_Pillar_Base",
      "rotation": 3
    },
    {
      "x": -4,
      "y": 6,
      "z": 4,
      "name": "Rock_Sandstone_Brick_Half",
      "rotation": 3
    },
    {
      "x": -3,
      "y": 0,
      "z": -3,
      "name": "Rock_Sandstone_Cobble",
      "rotation": 3
    },
    {
      "x": -3,
      "y": 1,
      "z": -3,
      "name": "Rock_Sandstone_Cobble",
      "rotation": 3
    },
    {
      "x": -3,
      "y": 2,
      "z": -3,
      "name": "Rock_Sandstone_Brick",
      "rotation": 3
    },
    {
      "x": -3,
      "y": 3,
      "z": -3,
      "name": "Rock_Sandstone_Brick",
      "rotation": 3
    },
    {
      "x": -3,
      "y": 4,
      "z": -3,
      "name": "Rock_Sandstone_Brick",
      "rotation": 3
    },
    {
      "x": -3,
      "y": 5,
      "z": -3,
      "name": "Rock_Sandstone_Brick_Pillar_Base",
      "rotation": 3
    },
    {
      "x": -3,
      "y": 6,
      "z": -3,
      "name": "Rock_Sandstone_Brick_Half",
      "rotation": 3
    },
    {
      "x": -3,
      "y": 0,
      "z": -2,
      "name": "Rock_Sandstone_Cobble",
      "rotation": 3
    },
    {
      "x": -3,
      "y": 1,
      "z": -2,
      "name": "Rock_Sandstone_Cobble",
      "rotation": 3
    },
    {
      "x": -3,
      "y": 2,
      "z": -2,
      "name": "Rock_Sandstone_Brick",
      "rotation": 3
    },
    {
      "x": -3,
      "y": 3,
      "z": -2,
      "name": "Rock_Sandstone_Brick",
      "rotation": 3
    },
    {
      "x": -3,
      "y": 4,
      "z": -2,
      "name": "Rock_Sandstone_Brick",
      "rotation": 3
    },
    {
      "x": -3,
      "y": 5,
      "z": -2,
      "name": "Rock_Sandstone_Brick",
      "rotation": 3
    },
    {
      "x": -3,
      "y": 6,
      "z": -2,
      "name": "Rock_Sandstone_Brick",
      "rotation": 3
    },
    {
      "x": -3,
      "y": 0,
      "z": -1,
      "name": "Rock_Sandstone_Cobble",
      "rotation": 3
    },
    {
      "x": -3,
      "y": 1,
      "z": -1,
      "name": "Rock_Sandstone_Brick",
      "rotation": 3
    },
    {
      "x": -3,
      "y": 2,
      "z": -1,
      "name": "Rock_Sandstone_Brick",
      "rotation": 3
    },
    {
      "x": -3,
      "y": 3,
      "z": -1,
      "name": "Rock_Sandstone_Brick",
      "rotation": 3
    },
    {
      "x": -3,
      "y": 4,
      "z": -1,
      "name": "Rock_Sandstone_Brick",
      "rotation": 3
    },
    {
      "x": -3,
      "y": 5,
      "z": -1,
      "name": "Rock_Sandstone_Brick",
      "rotation": 3
    },
    {
      "x": -3,
      "y": 6,
      "z": -1,
      "name": "Rock_Sandstone_Brick",
      "rotation": 3
    },
    {
      "x": -3,
      "y": 7,
      "z": -1,
      "name": "Rock_Sandstone_Brick_Pillar_Base",
      "rotation": 3
    },
    {
      "x": -3,
      "y": 8,
      "z": -1,
      "name": "Rock_Sandstone_Brick_Pillar_Middle",
      "rotation": 3
    },
    {
      "x": -3,
      "y": 9,
      "z": -1,
      "name": "Rock_Sandstone_Brick_Pillar_Base",
      "rotation": 33
    },
    {
      "x": -3,
      "y": 10,
      "z": -1,
      "name": "Rock_Sandstone_Brick_Pillar_Middle",
      "rotation": 3
    },
    {
      "x": -3,
      "y": 0,
      "z": 0,
      "name": "Rock_Sandstone_Brick",
      "rotation": 3
    },
    {
      "x": -3,
      "y": 1,
      "z": 0,
      "name": "Rock_Sandstone_Cobble",
      "rotation": 3
    },
    {
      "x": -3,
      "y": 2,
      "z": 0,
      "name": "Rock_Sandstone_Brick",
      "rotation": 3
    },
    {
      "x": -3,
      "y": 3,
      "z": 0,
      "name": "Rock_Sandstone_Brick",
      "rotation": 3
    },
    {
      "x": -3,
      "y": 4,
      "z": 0,
      "name": "Rock_Sandstone_Brick",
      "rotation": 3
    },
    {
      "x": -3,
      "y": 5,
      "z": 0,
      "name": "Rock_Sandstone_Brick",
      "rotation": 3
    },
    {
      "x": -3,
      "y": 6,
      "z": 0,
      "name": "Rock_Sandstone_Cobble",
      "rotation": 3
    },
    {
      "x": -3,
      "y": 7,
      "z": 0,
      "name": "Rock_Sandstone_Cobble",
      "rotation": 3
    },
    {
      "x": -3,
      "y": 8,
      "z": 0,
      "name": "Rock_Sandstone_Cobble",
      "rotation": 3
    },
    {
      "x": -3,
      "y": 9,
      "z": 0,
      "name": "Rock_Sandstone_Brick",
      "rotation": 3
    },
    {
      "x": -3,
      "y": 10,
      "z": 0,
      "name": "Rock_Sandstone_Brick",
      "rotation": 3
    },
    {
      "x": -3,
      "y": 11,
      "z": 0,
      "name": "Rock_Sandstone_Brick",
      "rotation": 3
    },
    {
      "x": -3,
      "y": 12,
      "z": 0,
      "name": "Rock_Sandstone_Brick",
      "rotation": 3
    },
    {
      "x": -3,
      "y": 13,
      "z": 0,
      "name": "Rock_Sandstone_Brick_Half",
      "rotation": 6
    },
    {
      "x": -3,
      "y": 0,
      "z": 1,
      "name": "Rock_Sandstone_Cobble",
      "rotation": 3
    },
    {
      "x": -3,
      "y": 1,
      "z": 1,
      "name": "Rock_Sandstone_Cobble",
      "rotation": 3
    },
    {
      "x": -3,
      "y": 2,
      "z": 1,
      "name": "Rock_Sandstone_Cobble",
      "rotation": 3
    },
    {
      "x": -3,
      "y": 3,
      "z": 1,
      "name": "Rock_Sandstone_Brick",
      "rotation": 3
    },
    {
      "x": -3,
      "y": 4,
      "z": 1,
      "name": "Rock_Sandstone_Brick",
      "rotation": 3
    },
    {
      "x": -3,
      "y": 5,
      "z": 1,
      "name": "Rock_Sandstone_Brick",
      "rotation": 3
    },
    {
      "x": -3,
      "y": 6,
      "z": 1,
      "name": "Rock_Sandstone_Cobble",
      "rotation": 3
    },
    {
      "x": -3,
      "y": 7,
      "z": 1,
      "name": "Rock_Sandstone_Cobble",
      "rotation": 3
    },
    {
      "x": -3,
      "y": 8,
      "z": 1,
      "name": "Rock_Sandstone_Cobble",
      "rotation": 3
    },
    {
      "x": -3,
      "y": 9,
      "z": 1,
      "name": "Rock_Sandstone_Brick",
      "rotation": 3
    },
    {
      "x": -3,
      "y": 10,
      "z": 1,
      "name": "Rock_Sandstone_Brick",
      "rotation": 3
    },
    {
      "x": -3,
      "y": 12,
      "z": 1,
      "name": "Furniture_Desert_Window",
      "rotation": 3
    },
    {
      "x": -3,
      "y": 13,
      "z": 1,
      "name": "Rock_Sandstone_Brick",
      "rotation": 3
    },
    {
      "x": -3,
      "y": 0,
      "z": 2,
      "name": "Rock_Sandstone_Cobble",
      "rotation": 3
    },
    {
      "x": -3,
      "y": 1,
      "z": 2,
      "name": "Rock_Sandstone_Brick",
      "rotation": 3
    },
    {
      "x": -3,
      "y": 2,
      "z": 2,
      "name": "Rock_Sandstone_Brick",
      "rotation": 3
    },
    {
      "x": -3,
      "y": 3,
      "z": 2,
      "name": "Rock_Sandstone_Brick",
      "rotation": 3
    },
    {
      "x": -3,
      "y": 4,
      "z": 2,
      "name": "Rock_Sandstone_Brick",
      "rotation": 3
    },
    {
      "x": -3,
      "y": 5,
      "z": 2,
      "name": "Rock_Sandstone_Brick",
      "rotation": 3
    },
    {
      "x": -3,
      "y": 6,
      "z": 2,
      "name": "Rock_Sandstone_Brick",
      "rotation": 3
    },
    {
      "x": -3,
      "y": 7,
      "z": 2,
      "name": "Rock_Sandstone_Cobble",
      "rotation": 3
    },
    {
      "x": -3,
      "y": 8,
      "z": 2,
      "name": "Rock_Sandstone_Cobble",
      "rotation": 3
    },
    {
      "x": -3,
      "y": 9,
      "z": 2,
      "name": "Rock_Sandstone_Brick",
      "rotation": 3
    },
    {
      "x": -3,
      "y": 10,
      "z": 2,
      "name": "Rock_Sandstone_Brick",
      "rotation": 3
    },
    {
      "x": -3,
      "y": 11,
      "z": 2,
      "name": "Rock_Sandstone_Brick",
      "rotation": 3
    },
    {
      "x": -3,
      "y": 12,
      "z": 2,
      "name": "Rock_Sandstone_Brick",
      "rotation": 3
    },
    {
      "x": -3,
      "y": 13,
      "z": 2,
      "name": "Rock_Sandstone_Brick",
      "rotation": 3
    },
    {
      "x": -3,
      "y": 14,
      "z": 2,
      "name": "Rock_Sandstone_Brick",
      "rotation": 3
    },
    {
      "x": -3,
      "y": 15,
      "z": 2,
      "name": "Rock_Sandstone_Brick",
      "rotation": 3
    },
    {
      "x": -3,
      "y": 0,
      "z": 3,
      "name": "Rock_Sandstone_Cobble",
      "rotation": 3
    },
    {
      "x": -3,
      "y": 1,
      "z": 3,
      "name": "Rock_Sandstone_Brick",
      "rotation": 3
    },
    {
      "x": -3,
      "y": 2,
      "z": 3,
      "name": "Rock_Sandstone_Brick",
      "rotation": 3
    },
    {
      "x": -3,
      "y": 3,
      "z": 3,
      "name": "Rock_Sandstone_Brick",
      "rotation": 3
    },
    {
      "x": -3,
      "y": 4,
      "z": 3,
      "name": "Rock_Sandstone_Brick",
      "rotation": 3
    },
    {
      "x": -3,
      "y": 5,
      "z": 3,
      "name": "Rock_Sandstone_Brick",
      "rotation": 3
    },
    {
      "x": -3,
      "y": 6,
      "z": 3,
      "name": "Rock_Sandstone_Brick",
      "rotation": 3
    },
    {
      "x": -3,
      "y": 7,
      "z": 3,
      "name": "Rock_Sandstone_Brick_Pillar_Base",
      "rotation": 3
    },
    {
      "x": -3,
      "y": 8,
      "z": 3,
      "name": "Rock_Sandstone_Brick_Pillar_Middle",
      "rotation": 3
    },
    {
      "x": -3,
      "y": 9,
      "z": 3,
      "name": "Rock_Sandstone_Brick_Pillar_Base",
      "rotation": 33
    },
    {
      "x": -3,
      "y": 10,
      "z": 3,
      "name": "Rock_Sandstone_Brick_Pillar_Middle",
      "rotation": 3
    },
    {
      "x": -3,
      "y": 11,
      "z": 3,
      "name": "Rock_Sandstone_Brick_Pillar_Middle",
      "rotation": 3
    },
    {
      "x": -3,
      "y": 12,
      "z": 3,
      "name": "Rock_Sandstone_Brick_Pillar_Middle",
      "rotation": 3
    },
    {
      "x": -3,
      "y": 13,
      "z": 3,
      "name": "Rock_Sandstone_Brick_Pillar_Middle",
      "rotation": 3
    },
    {
      "x": -3,
      "y": 14,
      "z": 3,
      "name": "Rock_Sandstone_Brick_Pillar_Base",
      "rotation": 33
    },
    {
      "x": -3,
      "y": 15,
      "z": 3,
      "name": "Rock_Sandstone_Brick_Stairs",
      "rotation": 3
    },
    {
      "x": -3,
      "y": 0,
      "z": 4,
      "name": "Rock_Sandstone_Cobble",
      "rotation": 3
    },
    {
      "x": -3,
      "y": 1,
      "z": 4,
      "name": "Rock_Sandstone_Brick",
      "rotation": 3
    },
    {
      "x": -3,
      "y": 2,
      "z": 4,
      "name": "Rock_Sandstone_Brick",
      "rotation": 3
    },
    {
      "x": -3,
      "y": 3,
      "z": 4,
      "name": "Rock_Sandstone_Brick",
      "rotation": 3
    },
    {
      "x": -3,
      "y": 4,
      "z": 4,
      "name": "Rock_Sandstone_Brick",
      "rotation": 3
    },
    {
      "x": -3,
      "y": 5,
      "z": 4,
      "name": "Rock_Sandstone_Brick",
      "rotation": 3
    },
    {
      "x": -3,
      "y": 6,
      "z": 4,
      "name": "Rock_Sandstone_Brick",
      "rotation": 3
    },
    {
      "x": -3,
      "y": 0,
      "z": 5,
      "name": "Rock_Sandstone_Cobble",
      "rotation": 3
    },
    {
      "x": -3,
      "y": 1,
      "z": 5,
      "name": "Rock_Sandstone_Cobble",
      "rotation": 3
    },
    {
      "x": -3,
      "y": 2,
      "z": 5,
      "name": "Rock_Sandstone_Brick",
      "rotation": 3
    },
    {
      "x": -3,
      "y": 3,
      "z": 5,
      "name": "Rock_Sandstone_Brick",
      "rotation": 3
    },
    {
      "x": -3,
      "y": 4,
      "z": 5,
      "name": "Rock_Sandstone_Brick",
      "rotation": 3
    },
    {
      "x": -3,
      "y": 5,
      "z": 5,
      "name": "Rock_Sandstone_Brick_Pillar_Base",
      "rotation": 3
    },
    {
      "x": -3,
      "y": 6,
      "z": 5,
      "name": "Rock_Sandstone_Brick_Half",
      "rotation": 3
    },
    {
      "x": -2,
      "y": 0,
      "z": -3,
      "name": "Rock_Sandstone_Cobble",
      "rotation": 3
    },
    {
      "x": -2,
      "y": 1,
      "z": -3,
      "name": "Rock_Sandstone_Cobble",
      "rotation": 3
    },
    {
      "x": -2,
      "y": 2,
      "z": -3,
      "name": "Rock_Sandstone_Cobble",
      "rotation": 3
    },
    {
      "x": -2,
      "y": 3,
      "z": -3,
      "name": "Rock_Sandstone_Brick",
      "rotation": 3
    },
    {
      "x": -2,
      "y": 4,
      "z": -3,
      "name": "Rock_Sandstone_Brick",
      "rotation": 3
    },
    {
      "x": -2,
      "y": 5,
      "z": -3,
      "name": "Rock_Sandstone_Brick_Pillar_Base",
      "rotation": 3
    },
    {
      "x": -2,
      "y": 6,
      "z": -3,
      "name": "Rock_Sandstone_Brick",
      "rotation": 3
    },
    {
      "x": -2,
      "y": 0,
      "z": -2,
      "name": "Rock_Sandstone_Cobble",
      "rotation": 3
    },
    {
      "x": -2,
      "y": 5,
      "z": -2,
      "name": "Rock_Sandstone_Brick",
      "rotation": 3
    },
    {
      "x": -2,
      "y": 6,
      "z": -2,
      "name": "Rock_Sandstone_Brick",
      "rotation": 3
    },
    {
      "x": -2,
      "y": 7,
      "z": -2,
      "name": "Rock_Sandstone_Brick_Pillar_Base",
      "rotation": 3
    },
    {
      "x": -2,
      "y": 8,
      "z": -2,
      "name": "Rock_Sandstone_Brick_Pillar_Middle",
      "rotation": 3
    },
    {
      "x": -2,
      "y": 0,
      "z": -1,
      "name": "Rock_Sandstone_Cobble",
      "rotation": 3
    },
    {
      "x": -2,
      "y": 1,
      "z": -1,
      "name": "Rock_Sandstone_Cobble_Stairs",
      "rotation": 2
    },
    {
      "x": -2,
      "y": 5,
      "z": -1,
      "name": "Rock_Sandstone_Brick",
      "rotation": 3
    },
    {
      "x": -2,
      "y": 6,
      "z": -1,
      "name": "Rock_Sandstone_Brick",
      "rotation": 3
    },
    {
      "x": -2,
      "y": 7,
      "z": -1,
      "name": "Rock_Sandstone_Brick",
      "rotation": 3
    },
    {
      "x": -2,
      "y": 8,
      "z": -1,
      "name": "Rock_Sandstone_Cobble",
      "rotation": 3
    },
    {
      "x": -2,
      "y": 9,
      "z": -1,
      "name": "Rock_Sandstone_Brick",
      "rotation": 3
    },
    {
      "x": -2,
      "y": 10,
      "z": -1,
      "name": "Rock_Sandstone_Brick",
      "rotation": 3
    },
    {
      "x": -2,
      "y": 0,
      "z": 0,
      "name": "Rock_Sandstone_Cobble",
      "rotation": 3
    },
    {
      "x": -2,
      "y": 1,
      "z": 0,
      "name": "Rock_Sandstone_Cobble",
      "rotation": 3
    },
    {
      "x": -2,
      "y": 2,
      "z": 0,
      "name": "Rock_Sandstone_Cobble_Stairs",
      "rotation": 2
    },
    {
      "x": -2,
      "y": 6,
      "z": 0,
      "name": "Rock_Sandstone_Cobble_Half",
      "rotation": 4
    },
    {
      "x": -2,
      "y": 7,
      "z": 0,
      "name": "Rock_Sandstone_Cobble",
      "rotation": 3
    },
    {
      "x": -2,
      "y": 8,
      "z": 0,
      "name": "Rock_Sandstone_Cobble",
      "rotation": 3
    },
    {
      "x": -2,
      "y": 0,
      "z": 1,
      "name": "Rock_Sandstone_Brick",
      "rotation": 3
    },
    {
      "x": -2,
      "y": 1,
      "z": 1,
      "name": "Rock_Sandstone_Cobble",
      "rotation": 3
    },
    {
      "x": -2,
      "y": 2,
      "z": 1,
      "name": "Rock_Sandstone_Cobble",
      "rotation": 3
    },
    {
      "x": -2,
      "y": 3,
      "z": 1,
      "name": "Rock_Sandstone_Cobble_Stairs",
      "rotation": 2
    },
    {
      "x": -2,
      "y": 8,
      "z": 1,
      "name": "Rock_Sandstone_Cobble",
      "rotation": 3
    },
    {
      "x": -2,
      "y": 10,
      "z": 1,
      "name": "*Wood_Torch_Wall_State_Definitions_Off",
      "rotation": 1
    },
    {
      "x": -2,
      "y": 0,
      "z": 2,
      "name": "Rock_Sandstone_Brick",
      "rotation": 3
    },
    {
      "x": -2,
      "y": 1,
      "z": 2,
      "name": "Rock_Sandstone_Cobble",
      "rotation": 3
    },
    {
      "x": -2,
      "y": 2,
      "z": 2,
      "name": "Rock_Sandstone_Cobble",
      "rotation": 3
    },
    {
      "x": -2,
      "y": 3,
      "z": 2,
      "name": "Rock_Sandstone_Cobble",
      "rotation": 3
    },
    {
      "x": -2,
      "y": 4,
      "z": 2,
      "name": "Rock_Sandstone_Cobble_Stairs",
      "rotation": 2
    },
    {
      "x": -2,
      "y": 8,
      "z": 2,
      "name": "Rock_Sandstone_Cobble",
      "rotation": 3
    },
    {
      "x": -2,
      "y": 0,
      "z": 3,
      "name": "Rock_Sandstone_Brick",
      "rotation": 3
    },
    {
      "x": -2,
      "y": 1,
      "z": 3,
      "name": "Rock_Sandstone_Cobble",
      "rotation": 3
    },
    {
      "x": -2,
      "y": 2,
      "z": 3,
      "name": "Rock_Sandstone_Cobble",
      "rotation": 3
    },
    {
      "x": -2,
      "y": 3,
      "z": 3,
      "name": "Rock_Sandstone_Cobble",
      "rotation": 3
    },
    {
      "x": -2,
      "y": 4,
      "z": 3,
      "name": "Rock_Sandstone_Brick",
      "rotation": 3
    },
    {
      "x": -2,
      "y": 5,
      "z": 3,
      "name": "Rock_Sandstone_Brick",
      "rotation": 3
    },
    {
      "x": -2,
      "y": 6,
      "z": 3,
      "name": "Rock_Sandstone_Cobble",
      "rotation": 3
    },
    {
      "x": -2,
      "y": 7,
      "z": 3,
      "name": "Rock_Sandstone_Cobble",
      "rotation": 3
    },
    {
      "x": -2,
      "y": 8,
      "z": 3,
      "name": "Rock_Sandstone_Cobble",
      "rotation": 3
    },
    {
      "x": -2,
      "y": 9,
      "z": 3,
      "name": "Rock_Sandstone_Brick",
      "rotation": 3
    },
    {
      "x": -2,
      "y": 10,
      "z": 3,
      "name": "Rock_Sandstone_Brick",
      "rotation": 3
    },
    {
      "x": -2,
      "y": 11,
      "z": 3,
      "name": "Rock_Sandstone_Brick",
      "rotation": 3
    },
    {
      "x": -2,
      "y": 12,
      "z": 3,
      "name": "Rock_Sandstone_Brick",
      "rotation": 3
    },
    {
      "x": -2,
      "y": 13,
      "z": 3,
      "name": "Rock_Sandstone_Brick",
      "rotation": 3
    },
    {
      "x": -2,
      "y": 14,
      "z": 3,
      "name": "Rock_Sandstone_Brick",
      "rotation": 3
    },
    {
      "x": -2,
      "y": 15,
      "z": 3,
      "name": "Rock_Sandstone_Brick",
      "rotation": 3
    },
    {
      "x": -2,
      "y": 16,
      "z": 3,
      "name": "Rock_Sandstone_Brick_Ornate",
      "rotation": 3
    },
    {
      "x": -2,
      "y": 0,
      "z": 4,
      "name": "Rock_Sandstone_Cobble",
      "rotation": 3
    },
    {
      "x": -2,
      "y": 1,
      "z": 4,
      "name": "Rock_Sandstone_Cobble",
      "rotation": 3
    },
    {
      "x": -2,
      "y": 2,
      "z": 4,
      "name": "Rock_Sandstone_Brick",
      "rotation": 3
    },
    {
      "x": -2,
      "y": 3,
      "z": 4,
      "name": "Rock_Sandstone_Brick",
      "rotation": 3
    },
    {
      "x": -2,
      "y": 4,
      "z": 4,
      "name": "Rock_Sandstone_Brick",
      "rotation": 3
    },
    {
      "x": -2,
      "y": 5,
      "z": 4,
      "name": "Rock_Sandstone_Brick",
      "rotation": 3
    },
    {
      "x": -2,
      "y": 6,
      "z": 4,
      "name": "Rock_Sandstone_Brick",
      "rotation": 3
    },
    {
      "x": -2,
      "y": 7,
      "z": 4,
      "name": "Rock_Sandstone_Brick_Pillar_Base",
      "rotation": 3
    },
    {
      "x": -2,
      "y": 8,
      "z": 4,
      "name": "Rock_Sandstone_Brick_Pillar_Middle",
      "rotation": 3
    },
    {
      "x": -2,
      "y": 9,
      "z": 4,
      "name": "Rock_Sandstone_Brick_Pillar_Base",
      "rotation": 33
    },
    {
      "x": -2,
      "y": 10,
      "z": 4,
      "name": "Rock_Sandstone_Brick_Pillar_Middle",
      "rotation": 3
    },
    {
      "x": -2,
      "y": 11,
      "z": 4,
      "name": "Rock_Sandstone_Brick_Pillar_Middle",
      "rotation": 3
    },
    {
      "x": -2,
      "y": 12,
      "z": 4,
      "name": "Rock_Sandstone_Brick_Pillar_Middle",
      "rotation": 3
    },
    {
      "x": -2,
      "y": 13,
      "z": 4,
      "name": "Rock_Sandstone_Brick_Pillar_Middle",
      "rotation": 3
    },
    {
      "x": -2,
      "y": 14,
      "z": 4,
      "name": "Rock_Sandstone_Brick_Pillar_Base",
      "rotation": 33
    },
    {
      "x": -2,
      "y": 15,
      "z": 4,
      "name": "Rock_Sandstone_Brick_Stairs"
    },
    {
      "x": -2,
      "y": 0,
      "z": 5,
      "name": "Rock_Sandstone_Cobble",
      "rotation": 3
    },
    {
      "x": -2,
      "y": 1,
      "z": 5,
      "name": "Rock_Sandstone_Cobble",
      "rotation": 3
    },
    {
      "x": -2,
      "y": 2,
      "z": 5,
      "name": "Rock_Sandstone_Cobble",
      "rotation": 3
    },
    {
      "x": -2,
      "y": 3,
      "z": 5,
      "name": "Rock_Sandstone_Brick",
      "rotation": 3
    },
    {
      "x": -2,
      "y": 4,
      "z": 5,
      "name": "Rock_Sandstone_Brick",
      "rotation": 3
    },
    {
      "x": -2,
      "y": 5,
      "z": 5,
      "name": "Rock_Sandstone_Brick_Pillar_Base",
      "rotation": 3
    },
    {
      "x": -2,
      "y": 6,
      "z": 5,
      "name": "Rock_Sandstone_Brick",
      "rotation": 3
    },
    {
      "x": -1,
      "y": 0,
      "z": -4,
      "name": "Rock_Sandstone_Cobble_Stairs",
      "rotation": 2
    },
    {
      "x": -1,
      "y": 0,
      "z": -3,
      "name": "Rock_Sandstone_Cobble",
      "rotation": 3
    },
    {
      "x": -1,
      "y": 1,
      "z": -3,
      "name": "Wood_Drywood_Planks_Half",
      "rotation": 5
    },
    {
      "x": -1,
      "y": 5,
      "z": -3,
      "name": "Rock_Sandstone_Brick_Pillar_Base",
      "rotation": 3
    },
    {
      "x": -1,
      "y": 6,
      "z": -3,
      "name": "Rock_Sandstone_Brick",
      "rotation": 3
    },
    {
      "x": -1,
      "y": 7,
      "z": -3,
      "name": "Rock_Sandstone_Cobble_Stairs",
      "rotation": 2
    },
    {
      "x": -1,
      "y": 8,
      "z": -3,
      "name": "Rock_Sandstone_Cobble_Half",
      "rotation": 6
    },
    {
      "x": -1,
      "y": 0,
      "z": -2,
      "name": "Rock_Sandstone_Cobble",
      "rotation": 3
    },
    {
      "x": -1,
      "y": 5,
      "z": -2,
      "name": "Rock_Sandstone_Brick",
      "rotation": 3
    },
    {
      "x": -1,
      "y": 6,
      "z": -2,
      "name": "Rock_Sandstone_Cobble",
      "rotation": 3
    },
    {
      "x": -1,
      "y": 7,
      "z": -2,
      "name": "Rock_Sandstone_Cobble",
      "rotation": 3
    },
    {
      "x": -1,
      "y": 8,
      "z": -2,
      "name": "Rock_Sandstone_Cobble",
      "rotation": 3
    },
    {
      "x": -1,
      "y": 9,
      "z": -2,
      "name": "Rock_Sandstone_Brick",
      "rotation": 3
    },
    {
      "x": -1,
      "y": 0,
      "z": -1,
      "name": "Rock_Sandstone_Cobble",
      "rotation": 3
    },
    {
      "x": -1,
      "y": 1,
      "z": -1,
      "name": "Rock_Sandstone_Cobble_Stairs",
      "rotation": 2
    },
    {
      "x": -1,
      "y": 5,
      "z": -1,
      "name": "Rock_Sandstone_Brick",
      "rotation": 3
    },
    {
      "x": -1,
      "y": 6,
      "z": -1,
      "name": "Rock_Sandstone_Cobble",
      "rotation": 3
    },
    {
      "x": -1,
      "y": 7,
      "z": -1,
      "name": "Rock_Sandstone_Cobble",
      "rotation": 3
    },
    {
      "x": -1,
      "y": 8,
      "z": -1,
      "name": "Rock_Sandstone_Cobble_Half",
      "rotation": 3
    },
    {
      "x": -1,
      "y": 0,
      "z": 0,
      "name": "Rock_Sandstone_Cobble",
      "rotation": 3
    },
    {
      "x": -1,
      "y": 1,
      "z": 0,
      "name": "Rock_Sandstone_Cobble",
      "rotation": 3
    },
    {
      "x": -1,
      "y": 2,
      "z": 0,
      "name": "Rock_Sandstone_Cobble_Stairs",
      "rotation": 2
    },
    {
      "x": -1,
      "y": 6,
      "z": 0,
      "name": "Rock_Sandstone_Cobble_Half",
      "rotation": 4
    },
    {
      "x": -1,
      "y": 7,
      "z": 0,
      "name": "Rock_Sandstone_Cobble",
      "rotation": 3
    },
    {
      "x": -1,
      "y": 8,
      "z": 0,
      "name": "Rock_Sandstone_Cobble_Half",
      "rotation": 3
    },
    {
      "x": -1,
      "y": 0,
      "z": 1,
      "name": "Rock_Sandstone_Brick",
      "rotation": 3
    },
    {
      "x": -1,
      "y": 1,
      "z": 1,
      "name": "Rock_Sandstone_Cobble",
      "rotation": 3
    },
    {
      "x": -1,
      "y": 2,
      "z": 1,
      "name": "Rock_Sandstone_Cobble",
      "rotation": 3
    },
    {
      "x": -1,
      "y": 3,
      "z": 1,
      "name": "Rock_Sandstone_Cobble_Stairs",
      "rotation": 2
    },
    {
      "x": -1,
      "y": 8,
      "z": 1,
      "name": "Rock_Sandstone_Cobble",
      "rotation": 3
    },
    {
      "x": -1,
      "y": 0,
      "z": 2,
      "name": "Rock_Sandstone_Brick",
      "rotation": 3
    },
    {
      "x": -1,
      "y": 1,
      "z": 2,
      "name": "Rock_Sandstone_Cobble",
      "rotation": 3
    },
    {
      "x": -1,
      "y": 2,
      "z": 2,
      "name": "Rock_Sandstone_Cobble",
      "rotation": 3
    },
    {
      "x": -1,
      "y": 3,
      "z": 2,
      "name": "Rock_Sandstone_Cobble",
      "rotation": 3
    },
    {
      "x": -1,
      "y": 4,
      "z": 2,
      "name": "Rock_Sandstone_Cobble_Stairs",
      "rotation": 2
    },
    {
      "x": -1,
      "y": 8,
      "z": 2,
      "name": "Rock_Sandstone_Cobble",
      "rotation": 3
    },
    {
      "x": -1,
      "y": 11,
      "z": 2,
      "name": "Furniture_Desert_Ladder",
      "rotation": 2
    },
    {
      "x": -1,
      "y": 12,
      "z": 2,
      "name": "Furniture_Desert_Ladder",
      "rotation": 2
    },
    {
      "x": -1,
      "y": 0,
      "z": 3,
      "name": "Rock_Sandstone_Brick",
      "rotation": 3
    },
    {
      "x": -1,
      "y": 1,
      "z": 3,
      "name": "Rock_Sandstone_Cobble",
      "rotation": 3
    },
    {
      "x": -1,
      "y": 2,
      "z": 3,
      "name": "Rock_Sandstone_Cobble",
      "rotation": 3
    },
    {
      "x": -1,
      "y": 3,
      "z": 3,
      "name": "Rock_Sandstone_Cobble",
      "rotation": 3
    },
    {
      "x": -1,
      "y": 4,
      "z": 3,
      "name": "Rock_Sandstone_Cobble",
      "rotation": 3
    },
    {
      "x": -1,
      "y": 8,
      "z": 3,
      "name": "Rock_Sandstone_Cobble",
      "rotation": 3
    },
    {
      "x": -1,
      "y": 9,
      "z": 3,
      "name": "Wood_Dry_Trunk",
      "rotation": 3
    },
    {
      "x": -1,
      "y": 10,
      "z": 3,
      "name": "Wood_Dry_Trunk",
      "rotation": 3
    },
    {
      "x": -1,
      "y": 11,
      "z": 3,
      "name": "Wood_Dry_Trunk",
      "rotation": 3
    },
    {
      "x": -1,
      "y": 12,
      "z": 3,
      "name": "Wood_Dry_Trunk",
      "rotation": 3
    },
    {
      "x": -1,
      "y": 13,
      "z": 3,
      "name": "Wood_Dry_Trunk",
      "rotation": 3
    },
    {
      "x": -1,
      "y": 14,
      "z": 3,
      "name": "Wood_Dry_Trunk",
      "rotation": 3
    },
    {
      "x": -1,
      "y": 15,
      "z": 3,
      "name": "Wood_Dry_Trunk",
      "rotation": 3
    },
    {
      "x": -1,
      "y": 0,
      "z": 4,
      "name": "Rock_Sandstone_Brick",
      "rotation": 3
    },
    {
      "x": -1,
      "y": 1,
      "z": 4,
      "name": "Rock_Sandstone_Brick",
      "rotation": 3
    },
    {
      "x": -1,
      "y": 2,
      "z": 4,
      "name": "Rock_Sandstone_Cobble",
      "rotation": 3
    },
    {
      "x": -1,
      "y": 3,
      "z": 4,
      "name": "Rock_Sandstone_Brick",
      "rotation": 3
    },
    {
      "x": -1,
      "y": 4,
      "z": 4,
      "name": "Rock_Sandstone_Brick",
      "rotation": 3
    },
    {
      "x": -1,
      "y": 5,
      "z": 4,
      "name": "Rock_Sandstone_Brick",
      "rotation": 3
    },
    {
      "x": -1,
      "y": 6,
      "z": 4,
      "name": "Rock_Sandstone_Brick",
      "rotation": 3
    },
    {
      "x": -1,
      "y": 7,
      "z": 4,
      "name": "Rock_Sandstone_Cobble",
      "rotation": 3
    },
    {
      "x": -1,
      "y": 8,
      "z": 4,
      "name": "Rock_Sandstone_Cobble",
      "rotation": 3
    },
    {
      "x": -1,
      "y": 9,
      "z": 4,
      "name": "Rock_Sandstone_Brick",
      "rotation": 3
    },
    {
      "x": -1,
      "y": 10,
      "z": 4,
      "name": "Rock_Sandstone_Brick",
      "rotation": 3
    },
    {
      "x": -1,
      "y": 11,
      "z": 4,
      "name": "Rock_Sandstone_Brick",
      "rotation": 3
    },
    {
      "x": -1,
      "y": 12,
      "z": 4,
      "name": "Rock_Sandstone_Brick",
      "rotation": 3
    },
    {
      "x": -1,
      "y": 13,
      "z": 4,
      "name": "Rock_Sandstone_Brick",
      "rotation": 3
    },
    {
      "x": -1,
      "y": 14,
      "z": 4,
      "name": "Rock_Sandstone_Brick",
      "rotation": 3
    },
    {
      "x": -1,
      "y": 15,
      "z": 4,
      "name": "Rock_Sandstone_Brick",
      "rotation": 3
    },
    {
      "x": -1,
      "y": 0,
      "z": 5,
      "name": "Rock_Sandstone_Cobble",
      "rotation": 3
    },
    {
      "x": -1,
      "y": 1,
      "z": 5,
      "name": "Rock_Sandstone_Cobble",
      "rotation": 3
    },
    {
      "x": -1,
      "y": 2,
      "z": 5,
      "name": "Rock_Sandstone_Cobble",
      "rotation": 3
    },
    {
      "x": -1,
      "y": 3,
      "z": 5,
      "name": "Rock_Sandstone_Cobble",
      "rotation": 3
    },
    {
      "x": -1,
      "y": 4,
      "z": 5,
      "name": "Rock_Sandstone_Brick",
      "rotation": 3
    },
    {
      "x": -1,
      "y": 5,
      "z": 5,
      "name": "Rock_Sandstone_Brick_Pillar_Base",
      "rotation": 3
    },
    {
      "x": -1,
      "y": 6,
      "z": 5,
      "name": "Rock_Sandstone_Brick",
      "rotation": 3
    },
    {
      "x": -1,
      "y": 7,
      "z": 5,
      "name": "Rock_Sandstone_Cobble_Stairs"
    },
    {
      "x": -1,
      "y": 8,
      "z": 5,
      "name": "Rock_Sandstone_Cobble_Half",
      "rotation": 4
    },
    {
      "x": -1,
      "y": 11,
      "z": 5,
      "name": "Rock_Sandstone_Brick_Smooth_Half",
      "rotation": 7
    },
    {
      "x": -1,
      "y": 12,
      "z": 5,
      "name": "Rock_Sandstone_Brick_Smooth_Half",
      "rotation": 7
    },
    {
      "x": 0,
      "y": 0,
      "z": -4,
      "name": "Rock_Sandstone_Cobble_Stairs",
      "rotation": 2
    },
    {
      "x": 0,
      "y": 0,
      "z": -3,
      "name": "Rock_Sandstone_Cobble",
      "rotation": 3
    },
    {
      "x": 0,
      "y": 6,
      "z": -3,
      "name": "Rock_Sandstone_Brick",
      "rotation": 3
    },
    {
      "x": 0,
      "y": 7,
      "z": -3,
      "name": "Rock_Sandstone_Cobble_Stairs",
      "rotation": 2
    },
    {
      "x": 0,
      "y": 8,
      "z": -3,
      "name": "Rock_Sandstone_Cobble_Half",
      "rotation": 6
    },
    {
      "x": 0,
      "y": 0,
      "z": -2,
      "name": "Rock_Sandstone_Cobble",
      "rotation": 3
    },
    {
      "x": 0,
      "y": 6,
      "z": -2,
      "name": "Rock_Sandstone_Brick",
      "rotation": 3
    },
    {
      "x": 0,
      "y": 7,
      "z": -2,
      "name": "Rock_Sandstone_Cobble",
      "rotation": 3
    },
    {
      "x": 0,
      "y": 8,
      "z": -2,
      "name": "Rock_Sandstone_Cobble",
      "rotation": 3
    },
    {
      "x": 0,
      "y": 9,
      "z": -2,
      "name": "Rock_Sandstone_Brick",
      "rotation": 3
    },
    {
      "x": 0,
      "y": 13,
      "z": -2,
      "name": "Rock_Sandstone_Brick",
      "rotation": 3
    },
    {
      "x": 0,
      "y": 14,
      "z": -2,
      "name": "Rock_Sandstone_Brick",
      "rotation": 3
    },
    {
      "x": 0,
      "y": 0,
      "z": -1,
      "name": "Rock_Sandstone_Cobble",
      "rotation": 3
    },
    {
      "x": 0,
      "y": 5,
      "z": -1,
      "name": "Rock_Sandstone_Brick",
      "rotation": 3
    },
    {
      "x": 0,
      "y": 6,
      "z": -1,
      "name": "Rock_Sandstone_Cobble",
      "rotation": 3
    },
    {
      "x": 0,
      "y": 7,
      "z": -1,
      "name": "Rock_Sandstone_Cobble",
      "rotation": 3
    },
    {
      "x": 0,
      "y": 0,
      "z": 0,
      "name": "Rock_Sandstone_Cobble",
      "rotation": 1
    },
    {
      "x": 0,
      "y": 5,
      "z": 0,
      "name": "Rock_Sandstone_Brick",
      "rotation": 3
    },
    {
      "x": 0,
      "y": 6,
      "z": 0,
      "name": "Rock_Sandstone_Cobble",
      "rotation": 3
    },
    {
      "x": 0,
      "y": 7,
      "z": 0,
      "name": "Rock_Sandstone_Cobble",
      "rotation": 3
    },
    {
      "x": 0,
      "y": 0,
      "z": 1,
      "name": "Rock_Sandstone_Brick",
      "rotation": 3
    },
    {
      "x": 0,
      "y": 1,
      "z": 1,
      "name": "Rock_Sandstone_Brick",
      "rotation": 3
    },
    {
      "x": 0,
      "y": 2,
      "z": 1,
      "name": "Rock_Sandstone_Brick",
      "rotation": 3
    },
    {
      "x": 0,
      "y": 3,
      "z": 1,
      "name": "Rock_Sandstone_Brick",
      "rotation": 3
    },
    {
      "x": 0,
      "y": 4,
      "z": 1,
      "name": "Rock_Sandstone_Brick",
      "rotation": 3
    },
    {
      "x": 0,
      "y": 5,
      "z": 1,
      "name": "Rock_Sandstone_Brick",
      "rotation": 3
    },
    {
      "x": 0,
      "y": 6,
      "z": 1,
      "name": "Rock_Sandstone_Brick",
      "rotation": 3
    },
    {
      "x": 0,
      "y": 7,
      "z": 1,
      "name": "Rock_Sandstone_Brick",
      "rotation": 3
    },
    {
      "x": 0,
      "y": 8,
      "z": 1,
      "name": "Rock_Sandstone_Brick",
      "rotation": 3
    },
    {
      "x": 0,
      "y": 0,
      "z": 2,
      "name": "Rock_Sandstone_Brick",
      "rotation": 3
    },
    {
      "x": 0,
      "y": 1,
      "z": 2,
      "name": "Rock_Sandstone_Cobble",
      "rotation": 3
    },
    {
      "x": 0,
      "y": 2,
      "z": 2,
      "name": "Rock_Sandstone_Cobble",
      "rotation": 3
    },
    {
      "x": 0,
      "y": 3,
      "z": 2,
      "name": "Rock_Sandstone_Cobble",
      "rotation": 3
    },
    {
      "x": 0,
      "y": 4,
      "z": 2,
      "name": "Rock_Sandstone_Cobble",
      "rotation": 3
    },
    {
      "x": 0,
      "y": 5,
      "z": 2,
      "name": "Rock_Sandstone_Cobble_Stairs",
      "rotation": 3
    },
    {
      "x": 0,
      "y": 8,
      "z": 2,
      "name": "Rock_Sandstone_Cobble_Half",
      "rotation": 33
    },
    {
      "x": 0,
      "y": 0,
      "z": 3,
      "name": "Rock_Sandstone_Brick",
      "rotation": 3
    },
    {
      "x": 0,
      "y": 1,
      "z": 3,
      "name": "Rock_Sandstone_Cobble",
      "rotation": 3
    },
    {
      "x": 0,
      "y": 2,
      "z": 3,
      "name": "Rock_Sandstone_Cobble",
      "rotation": 3
    },
    {
      "x": 0,
      "y": 3,
      "z": 3,
      "name": "Rock_Sandstone_Cobble",
      "rotation": 3
    },
    {
      "x": 0,
      "y": 4,
      "z": 3,
      "name": "Rock_Sandstone_Cobble",
      "rotation": 3
    },
    {
      "x": 0,
      "y": 5,
      "z": 3,
      "name": "Rock_Sandstone_Cobble_Stairs",
      "rotation": 3
    },
    {
      "x": 0,
      "y": 8,
      "z": 3,
      "name": "Rock_Sandstone_Cobble_Half",
      "rotation": 33
    },
    {
      "x": 0,
      "y": 9,
      "z": 3,
      "name": "Furniture_Village_Crate",
      "rotation": 3
    },
    {
      "x": 0,
      "y": 10,
      "z": 3,
      "name": "Furniture_Ancient_Barrel",
      "rotation": 3
    },
    {
      "x": 0,
      "y": 0,
      "z": 4,
      "name": "Rock_Sandstone_Brick",
      "rotation": 3
    },
    {
      "x": 0,
      "y": 1,
      "z": 4,
      "name": "Rock_Sandstone_Cobble",
      "rotation": 3
    },
    {
      "x": 0,
      "y": 2,
      "z": 4,
      "name": "Rock_Sandstone_Brick",
      "rotation": 3
    },
    {
      "x": 0,
      "y": 3,
      "z": 4,
      "name": "Rock_Sandstone_Brick",
      "rotation": 3
    },
    {
      "x": 0,
      "y": 4,
      "z": 4,
      "name": "Rock_Sandstone_Brick",
      "rotation": 3
    },
    {
      "x": 0,
      "y": 5,
      "z": 4,
      "name": "Rock_Sandstone_Brick",
      "rotation": 3
    },
    {
      "x": 0,
      "y": 6,
      "z": 4,
      "name": "Rock_Sandstone_Brick",
      "rotation": 3
    },
    {
      "x": 0,
      "y": 7,
      "z": 4,
      "name": "Rock_Sandstone_Cobble",
      "rotation": 3
    },
    {
      "x": 0,
      "y": 8,
      "z": 4,
      "name": "Rock_Sandstone_Cobble",
      "rotation": 3
    },
    {
      "x": 0,
      "y": 9,
      "z": 4,
      "name": "Rock_Sandstone_Brick",
      "rotation": 3
    },
    {
      "x": 0,
      "y": 10,
      "z": 4,
      "name": "Rock_Sandstone_Brick",
      "rotation": 3
    },
    {
      "x": 0,
      "y": 11,
      "z": 4,
      "name": "Furniture_Desert_Window"
    },
    {
      "x": 0,
      "y": 12,
      "z": 4,
      "name": "Furniture_Desert_Window"
    },
    {
      "x": 0,
      "y": 13,
      "z": 4,
      "name": "Rock_Sandstone_Brick",
      "rotation": 3
    },
    {
      "x": 0,
      "y": 14,
      "z": 4,
      "name": "Rock_Sandstone_Brick",
      "rotation": 3
    },
    {
      "x": 0,
      "y": 15,
      "z": 4,
      "name": "Rock_Sandstone_Brick",
      "rotation": 3
    },
    {
      "x": 0,
      "y": 0,
      "z": 5,
      "name": "Rock_Sandstone_Cobble",
      "rotation": 3
    },
    {
      "x": 0,
      "y": 1,
      "z": 5,
      "name": "Rock_Sandstone_Cobble",
      "rotation": 3
    },
    {
      "x": 0,
      "y": 2,
      "z": 5,
      "name": "Rock_Sandstone_Cobble",
      "rotation": 3
    },
    {
      "x": 0,
      "y": 3,
      "z": 5,
      "name": "Rock_Sandstone_Brick",
      "rotation": 3
    },
    {
      "x": 0,
      "y": 4,
      "z": 5,
      "name": "Rock_Sandstone_Brick",
      "rotation": 3
    },
    {
      "x": 0,
      "y": 5,
      "z": 5,
      "name": "Rock_Sandstone_Brick_Pillar_Base",
      "rotation": 3
    },
    {
      "x": 0,
      "y": 6,
      "z": 5,
      "name": "Rock_Sandstone_Brick",
      "rotation": 3
    },
    {
      "x": 0,
      "y": 7,
      "z": 5,
      "name": "Rock_Sandstone_Cobble_Stairs"
    },
    {
      "x": 0,
      "y": 8,
      "z": 5,
      "name": "Rock_Sandstone_Cobble_Half",
      "rotation": 4
    },
    {
      "x": 0,
      "y": 10,
      "z": 5,
      "name": "Rock_Sandstone_Brick_Smooth_Half",
      "rotation": 4
    },
    {
      "x": 0,
      "y": 13,
      "z": 5,
      "name": "Rock_Sandstone_Brick_Smooth_Half",
      "rotation": 3
    },
    {
      "x": 1,
      "y": 0,
      "z": -4,
      "name": "Rock_Sandstone_Cobble_Stairs",
      "rotation": 2
    },
    {
      "x": 1,
      "y": 7,
      "z": -3,
      "name": "Rock_Sandstone_Cobble_Half",
      "rotation": 6
    },
    {
      "x": 1,
      "y": 8,
      "z": -3,
      "name": "Rock_Sandstone_Cobble_Half",
      "rotation": 6
    },
    {
      "x": 1,
      "y": 6,
      "z": -2,
      "name": "Rock_Sandstone_Brick",
      "rotation": 3
    },
    {
      "x": 1,
      "y": 7,
      "z": -2,
      "name": "Rock_Sandstone_Cobble",
      "rotation": 3
    },
    {
      "x": 1,
      "y": 8,
      "z": -2,
      "name": "Rock_Sandstone_Cobble",
      "rotation": 3
    },
    {
      "x": 1,
      "y": 9,
      "z": -2,
      "name": "Rock_Sandstone_Brick",
      "rotation": 3
    },
    {
      "x": 1,
      "y": 10,
      "z": -2,
      "name": "Rock_Sandstone_Brick",
      "rotation": 3
    },
    {
      "x": 1,
      "y": 11,
      "z": -2,
      "name": "Rock_Sandstone_Brick",
      "rotation": 3
    },
    {
      "x": 1,
      "y": 12,
      "z": -2,
      "name": "Rock_Sandstone_Brick",
      "rotation": 3
    },
    {
      "x": 1,
      "y": 13,
      "z": -2,
      "name": "Rock_Sandstone_Brick",
      "rotation": 3
    },
    {
      "x": 1,
      "y": 14,
      "z": -2,
      "name": "Rock_Sandstone_Brick",
      "rotation": 3
    },
    {
      "x": 1,
      "y": 15,
      "z": -2,
      "name": "Rock_Sandstone_Brick",
      "rotation": 3
    },
    {
      "x": 1,
      "y": 0,
      "z": -1,
      "name": "Rock_Sandstone_Cobble",
      "rotation": 3
    },
    {
      "x": 1,
      "y": 6,
      "z": -1,
      "name": "Rock_Sandstone_Cobble",
      "rotation": 3
    },
    {
      "x": 1,
      "y": 7,
      "z": -1,
      "name": "Rock_Sandstone_Cobble_Half",
      "rotation": 3
    },
    {
      "x": 1,
      "y": 0,
      "z": 0,
      "name": "Rock_Sandstone_Cobble",
      "rotation": 3
    },
    {
      "x": 1,
      "y": 5,
      "z": 0,
      "name": "Rock_Sandstone_Cobble",
      "rotation": 3
    },
    {
      "x": 1,
      "y": 6,
      "z": 0,
      "name": "Rock_Sandstone_Cobble",
      "rotation": 3
    },
    {
      "x": 1,
      "y": 7,
      "z": 0,
      "name": "Rock_Sandstone_Cobble_Half",
      "rotation": 3
    },
    {
      "x": 1,
      "y": 0,
      "z": 1,
      "name": "Rock_Sandstone_Cobble",
      "rotation": 3
    },
    {
      "x": 1,
      "y": 5,
      "z": 1,
      "name": "Rock_Sandstone_Cobble",
      "rotation": 3
    },
    {
      "x": 1,
      "y": 6,
      "z": 1,
      "name": "Rock_Sandstone_Cobble",
      "rotation": 3
    },
    {
      "x": 1,
      "y": 0,
      "z": 2,
      "name": "Rock_Sandstone_Cobble",
      "rotation": 3
    },
    {
      "x": 1,
      "y": 1,
      "z": 2,
      "name": "Furniture_Desert_Chair",
      "rotation": 1
    },
    {
      "x": 1,
      "y": 5,
      "z": 2,
      "name": "Rock_Sandstone_Cobble",
      "rotation": 3
    },
    {
      "x": 1,
      "y": 6,
      "z": 2,
      "name": "Rock_Sandstone_Cobble_Half",
      "rotation": 3
    },
    {
      "x": 1,
      "y": 0,
      "z": 3,
      "name": "Rock_Sandstone_Cobble",
      "rotation": 3
    },
    {
      "x": 1,
      "y": 1,
      "z": 3,
      "name": "Furniture_Desert_Table",
      "filler": 31,
      "rotation": 3
    },
    {
      "x": 1,
      "y": 5,
      "z": 3,
      "name": "Rock_Sandstone_Cobble",
      "rotation": 3
    },
    {
      "x": 1,
      "y": 0,
      "z": 4,
      "name": "Rock_Sandstone_Cobble",
      "rotation": 3
    },
    {
      "x": 1,
      "y": 1,
      "z": 4,
      "name": "Furniture_Desert_Table",
      "filler": 63,
      "rotation": 3
    },
    {
      "x": 1,
      "y": 5,
      "z": 4,
      "name": "Rock_Sandstone_Brick",
      "rotation": 3
    },
    {
      "x": 1,
      "y": 6,
      "z": 4,
      "name": "Rock_Sandstone_Cobble",
      "rotation": 3
    },
    {
      "x": 1,
      "y": 7,
      "z": 4,
      "name": "Rock_Sandstone_Cobble",
      "rotation": 3
    },
    {
      "x": 1,
      "y": 8,
      "z": 4,
      "name": "Rock_Sandstone_Cobble",
      "rotation": 3
    },
    {
      "x": 1,
      "y": 9,
      "z": 4,
      "name": "Rock_Sandstone_Brick",
      "rotation": 3
    },
    {
      "x": 1,
      "y": 10,
      "z": 4,
      "name": "Rock_Sandstone_Brick",
      "rotation": 3
    },
    {
      "x": 1,
      "y": 11,
      "z": 4,
      "name": "Rock_Sandstone_Brick",
      "rotation": 3
    },
    {
      "x": 1,
      "y": 12,
      "z": 4,
      "name": "Rock_Sandstone_Brick",
      "rotation": 3
    },
    {
      "x": 1,
      "y": 13,
      "z": 4,
      "name": "Rock_Sandstone_Brick",
      "rotation": 3
    },
    {
      "x": 1,
      "y": 14,
      "z": 4,
      "name": "Rock_Sandstone_Brick",
      "rotation": 3
    },
    {
      "x": 1,
      "y": 0,
      "z": 5,
      "name": "Rock_Sandstone_Cobble",
      "rotation": 3
    },
    {
      "x": 1,
      "y": 1,
      "z": 5,
      "name": "Rock_Sandstone_Cobble",
      "rotation": 3
    },
    {
      "x": 1,
      "y": 2,
      "z": 5,
      "name": "Rock_Sandstone_Brick",
      "rotation": 3
    },
    {
      "x": 1,
      "y": 3,
      "z": 5,
      "name": "Rock_Sandstone_Brick",
      "rotation": 3
    },
    {
      "x": 1,
      "y": 4,
      "z": 5,
      "name": "Rock_Sandstone_Brick",
      "rotation": 3
    },
    {
      "x": 1,
      "y": 5,
      "z": 5,
      "name": "Rock_Sandstone_Brick_Pillar_Base",
      "rotation": 3
    },
    {
      "x": 1,
      "y": 6,
      "z": 5,
      "name": "Rock_Sandstone_Brick",
      "rotation": 3
    },
    {
      "x": 1,
      "y": 7,
      "z": 5,
      "name": "Rock_Sandstone_Cobble_Stairs"
    },
    {
      "x": 1,
      "y": 8,
      "z": 5,
      "name": "Rock_Sandstone_Cobble_Half",
      "rotation": 4
    },
    {
      "x": 1,
      "y": 11,
      "z": 5,
      "name": "Rock_Sandstone_Brick_Smooth_Half",
      "rotation": 5
    },
    {
      "x": 1,
      "y": 12,
      "z": 5,
      "name": "Rock_Sandstone_Brick_Smooth_Half",
      "rotation": 5
    },
    {
      "x": 2,
      "y": 6,
      "z": -1,
      "name": "Rock_Sandstone_Brick",
      "rotation": 3
    },
    {
      "x": 2,
      "y": 7,
      "z": -1,
      "name": "Rock_Sandstone_Cobble",
      "rotation": 3
    },
    {
      "x": 2,
      "y": 8,
      "z": -1,
      "name": "Rock_Sandstone_Cobble",
      "rotation": 3
    },
    {
      "x": 2,
      "y": 9,
      "z": -1,
      "name": "Rock_Sandstone_Brick",
      "rotation": 3
    },
    {
      "x": 2,
      "y": 10,
      "z": -1,
      "name": "Rock_Sandstone_Brick",
      "rotation": 3
    },
    {
      "x": 2,
      "y": 11,
      "z": -1,
      "name": "Rock_Sandstone_Brick",
      "rotation": 3
    },
    {
      "x": 2,
      "y": 12,
      "z": -1,
      "name": "Rock_Sandstone_Brick",
      "rotation": 3
    },
    {
      "x": 2,
      "y": 13,
      "z": -1,
      "name": "Rock_Sandstone_Brick",
      "rotation": 3
    },
    {
      "x": 2,
      "y": 14,
      "z": -1,
      "name": "Rock_Sandstone_Brick",
      "rotation": 3
    },
    {
      "x": 2,
      "y": 0,
      "z": 0,
      "name": "Rock_Sandstone_Cobble",
      "rotation": 3
    },
    {
      "x": 2,
      "y": 6,
      "z": 0,
      "name": "Rock_Sandstone_Cobble",
      "rotation": 3
    },
    {
      "x": 2,
      "y": 7,
      "z": 0,
      "name": "Rock_Sandstone_Cobble_Half",
      "rotation": 3
    },
    {
      "x": 2,
      "y": 0,
      "z": 1,
      "name": "Rock_Sandstone_Cobble",
      "rotation": 3
    },
    {
      "x": 2,
      "y": 5,
      "z": 1,
      "name": "Rock_Sandstone_Cobble",
      "rotation": 3
    },
    {
      "x": 2,
      "y": 6,
      "z": 1,
      "name": "Rock_Sandstone_Cobble",
      "rotation": 3
    },
    {
      "x": 2,
      "y": 0,
      "z": 2,
      "name": "Rock_Sandstone_Cobble",
      "rotation": 3
    },
    {
      "x": 2,
      "y": 5,
      "z": 2,
      "name": "Rock_Sandstone_Cobble",
      "rotation": 3
    },
    {
      "x": 2,
      "y": 6,
      "z": 2,
      "name": "Rock_Sandstone_Cobble_Half",
      "rotation": 3
    },
    {
      "x": 2,
      "y": 0,
      "z": 3,
      "name": "Rock_Sandstone_Cobble",
      "rotation": 3
    },
    {
      "x": 2,
      "y": 1,
      "z": 3,
      "name": "Furniture_Desert_Table",
      "rotation": 3
    },
    {
      "x": 2,
      "y": 5,
      "z": 3,
      "name": "Rock_Sandstone_Cobble",
      "rotation": 3
    },
    {
      "x": 2,
      "y": 6,
      "z": 3,
      "name": "Rock_Sandstone_Brick",
      "rotation": 3
    },
    {
      "x": 2,
      "y": 7,
      "z": 3,
      "name": "Rock_Sandstone_Cobble",
      "rotation": 3
    },
    {
      "x": 2,
      "y": 8,
      "z": 3,
      "name": "Rock_Sandstone_Cobble",
      "rotation": 3
    },
    {
      "x": 2,
      "y": 9,
      "z": 3,
      "name": "Rock_Sandstone_Brick",
      "rotation": 3
    },
    {
      "x": 2,
      "y": 10,
      "z": 3,
      "name": "Rock_Sandstone_Brick",
      "rotation": 3
    },
    {
      "x": 2,
      "y": 11,
      "z": 3,
      "name": "Rock_Sandstone_Brick",
      "rotation": 3
    },
    {
      "x": 2,
      "y": 12,
      "z": 3,
      "name": "Rock_Sandstone_Brick",
      "rotation": 3
    },
    {
      "x": 2,
      "y": 13,
      "z": 3,
      "name": "Rock_Sandstone_Brick",
      "rotation": 3
    },
    {
      "x": 2,
      "y": 14,
      "z": 3,
      "name": "Rock_Sandstone_Brick",
      "rotation": 3
    },
    {
      "x": 2,
      "y": 15,
      "z": 3,
      "name": "Rock_Sandstone_Brick",
      "rotation": 3
    },
    {
      "x": 2,
      "y": 0,
      "z": 4,
      "name": "Rock_Sandstone_Cobble",
      "rotation": 3
    },
    {
      "x": 2,
      "y": 1,
      "z": 4,
      "name": "Furniture_Desert_Table",
      "filler": 32,
      "rotation": 3
    },
    {
      "x": 2,
      "y": 5,
      "z": 4,
      "name": "Rock_Sandstone_Brick",
      "rotation": 3
    },
    {
      "x": 2,
      "y": 6,
      "z": 4,
      "name": "Rock_Sandstone_Brick",
      "rotation": 3
    },
    {
      "x": 2,
      "y": 7,
      "z": 4,
      "name": "Rock_Sandstone_Brick_Pillar_Base",
      "rotation": 3
    },
    {
      "x": 2,
      "y": 8,
      "z": 4,
      "name": "Rock_Sandstone_Brick_Pillar_Middle",
      "rotation": 3
    },
    {
      "x": 2,
      "y": 9,
      "z": 4,
      "name": "Rock_Sandstone_Brick_Pillar_Base",
      "rotation": 33
    },
    {
      "x": 2,
      "y": 10,
      "z": 4,
      "name": "Rock_Sandstone_Brick_Pillar_Middle",
      "rotation": 3
    },
    {
      "x": 2,
      "y": 11,
      "z": 4,
      "name": "Rock_Sandstone_Brick_Pillar_Middle",
      "rotation": 3
    },
    {
      "x": 2,
      "y": 12,
      "z": 4,
      "name": "Rock_Sandstone_Brick_Pillar_Middle",
      "rotation": 3
    },
    {
      "x": 2,
      "y": 13,
      "z": 4,
      "name": "Rock_Sandstone_Brick_Pillar_Middle",
      "rotation": 3
    },
    {
      "x": 2,
      "y": 14,
      "z": 4,
      "name": "Rock_Sandstone_Brick_Pillar_Base",
      "rotation": 33
    },
    {
      "x": 2,
      "y": 15,
      "z": 4,
      "name": "Rock_Sandstone_Brick_Stairs"
    },
    {
      "x": 2,
      "y": 0,
      "z": 5,
      "name": "Rock_Sandstone_Cobble",
      "rotation": 3
    },
    {
      "x": 2,
      "y": 1,
      "z": 5,
      "name": "Rock_Sandstone_Cobble",
      "rotation": 3
    },
    {
      "x": 2,
      "y": 2,
      "z": 5,
      "name": "Rock_Sandstone_Brick",
      "rotation": 3
    },
    {
      "x": 2,
      "y": 3,
      "z": 5,
      "name": "Rock_Sandstone_Brick",
      "rotation": 3
    },
    {
      "x": 2,
      "y": 4,
      "z": 5,
      "name": "Rock_Sandstone_Brick",
      "rotation": 3
    },
    {
      "x": 2,
      "y": 5,
      "z": 5,
      "name": "Rock_Sandstone_Brick_Pillar_Base",
      "rotation": 3
    },
    {
      "x": 2,
      "y": 6,
      "z": 5,
      "name": "Rock_Sandstone_Brick",
      "rotation": 3
    },
    {
      "x": 3,
      "y": 0,
      "z": 0,
      "name": "Rock_Sandstone_Cobble",
      "rotation": 3
    },
    {
      "x": 3,
      "y": 6,
      "z": 0,
      "name": "Rock_Sandstone_Brick",
      "rotation": 3
    },
    {
      "x": 3,
      "y": 7,
      "z": 0,
      "name": "Rock_Sandstone_Cobble",
      "rotation": 3
    },
    {
      "x": 3,
      "y": 8,
      "z": 0,
      "name": "Rock_Sandstone_Cobble",
      "rotation": 3
    },
    {
      "x": 3,
      "y": 9,
      "z": 0,
      "name": "Rock_Sandstone_Brick",
      "rotation": 3
    },
    {
      "x": 3,
      "y": 10,
      "z": 0,
      "name": "Rock_Sandstone_Brick",
      "rotation": 3
    },
    {
      "x": 3,
      "y": 11,
      "z": 0,
      "name": "Rock_Sandstone_Brick",
      "rotation": 3
    },
    {
      "x": 3,
      "y": 0,
      "z": 1,
      "name": "Rock_Sandstone_Cobble",
      "rotation": 3
    },
    {
      "x": 3,
      "y": 5,
      "z": 1,
      "name": "Rock_Sandstone_Brick",
      "rotation": 3
    },
    {
      "x": 3,
      "y": 6,
      "z": 1,
      "name": "Rock_Sandstone_Cobble",
      "rotation": 3
    },
    {
      "x": 3,
      "y": 7,
      "z": 1,
      "name": "Rock_Sandstone_Cobble",
      "rotation": 3
    },
    {
      "x": 3,
      "y": 8,
      "z": 1,
      "name": "Rock_Sandstone_Cobble",
      "rotation": 3
    },
    {
      "x": 3,
      "y": 9,
      "z": 1,
      "name": "Rock_Sandstone_Brick",
      "rotation": 3
    },
    {
      "x": 3,
      "y": 10,
      "z": 1,
      "name": "Rock_Sandstone_Brick",
      "rotation": 3
    },
    {
      "x": 3,
      "y": 13,
      "z": 1,
      "name": "Rock_Sandstone_Brick",
      "rotation": 3
    },
    {
      "x": 3,
      "y": 14,
      "z": 1,
      "name": "Rock_Sandstone_Brick",
      "rotation": 3
    },
    {
      "x": 3,
      "y": 0,
      "z": 2,
      "name": "Rock_Sandstone_Cobble",
      "rotation": 3
    },
    {
      "x": 3,
      "y": 5,
      "z": 2,
      "name": "Rock_Sandstone_Brick",
      "rotation": 3
    },
    {
      "x": 3,
      "y": 6,
      "z": 2,
      "name": "Rock_Sandstone_Brick",
      "rotation": 3
    },
    {
      "x": 3,
      "y": 7,
      "z": 2,
      "name": "Rock_Sandstone_Cobble",
      "rotation": 3
    },
    {
      "x": 3,
      "y": 8,
      "z": 2,
      "name": "Rock_Sandstone_Cobble",
      "rotation": 3
    },
    {
      "x": 3,
      "y": 9,
      "z": 2,
      "name": "Rock_Sandstone_Brick",
      "rotation": 3
    },
    {
      "x": 3,
      "y": 10,
      "z": 2,
      "name": "Rock_Sandstone_Brick",
      "rotation": 3
    },
    {
      "x": 3,
      "y": 11,
      "z": 2,
      "name": "Rock_Sandstone_Brick",
      "rotation": 3
    },
    {
      "x": 3,
      "y": 12,
      "z": 2,
      "name": "Rock_Sandstone_Brick",
      "rotation": 3
    },
    {
      "x": 3,
      "y": 13,
      "z": 2,
      "name": "Rock_Sandstone_Brick",
      "rotation": 3
    },
    {
      "x": 3,
      "y": 14,
      "z": 2,
      "name": "Rock_Sandstone_Brick",
      "rotation": 3
    },
    {
      "x": 3,
      "y": 15,
      "z": 2,
      "name": "Rock_Sandstone_Brick",
      "rotation": 3
    },
    {
      "x": 3,
      "y": 0,
      "z": 3,
      "name": "Rock_Sandstone_Cobble",
      "rotation": 3
    },
    {
      "x": 3,
      "y": 5,
      "z": 3,
      "name": "Rock_Sandstone_Brick",
      "rotation": 3
    },
    {
      "x": 3,
      "y": 6,
      "z": 3,
      "name": "Rock_Sandstone_Brick",
      "rotation": 3
    },
    {
      "x": 3,
      "y": 7,
      "z": 3,
      "name": "Rock_Sandstone_Brick_Pillar_Base",
      "rotation": 3
    },
    {
      "x": 3,
      "y": 8,
      "z": 3,
      "name": "Rock_Sandstone_Brick_Pillar_Middle",
      "rotation": 3
    },
    {
      "x": 3,
      "y": 9,
      "z": 3,
      "name": "Rock_Sandstone_Brick_Pillar_Base",
      "rotation": 33
    },
    {
      "x": 3,
      "y": 10,
      "z": 3,
      "name": "Rock_Sandstone_Brick_Pillar_Middle",
      "rotation": 3
    },
    {
      "x": 3,
      "y": 11,
      "z": 3,
      "name": "Rock_Sandstone_Brick_Pillar_Middle",
      "rotation": 3
    },
    {
      "x": 3,
      "y": 12,
      "z": 3,
      "name": "Rock_Sandstone_Brick_Pillar_Middle",
      "rotation": 3
    },
    {
      "x": 3,
      "y": 13,
      "z": 3,
      "name": "Rock_Sandstone_Brick_Pillar_Middle",
      "rotation": 3
    },
    {
      "x": 3,
      "y": 14,
      "z": 3,
      "name": "Rock_Sandstone_Brick_Pillar_Base",
      "rotation": 33
    },
    {
      "x": 3,
      "y": 15,
      "z": 3,
      "name": "Rock_Sandstone_Brick_Stairs",
      "rotation": 1
    },
    {
      "x": 3,
      "y": 0,
      "z": 4,
      "name": "Rock_Sandstone_Cobble",
      "rotation": 3
    },
    {
      "x": 3,
      "y": 5,
      "z": 4,
      "name": "Rock_Sandstone_Brick",
      "rotation": 3
    },
    {
      "x": 3,
      "y": 6,
      "z": 4,
      "name": "Rock_Sandstone_Brick",
      "rotation": 3
    },
    {
      "x": 3,
      "y": 0,
      "z": 5,
      "name": "Rock_Sandstone_Cobble",
      "rotation": 3
    },
    {
      "x": 3,
      "y": 1,
      "z": 5,
      "name": "Rock_Sandstone_Cobble",
      "rotation": 3
    },
    {
      "x": 3,
      "y": 2,
      "z": 5,
      "name": "Rock_Sandstone_Brick",
      "rotation": 3
    },
    {
      "x": 3,
      "y": 3,
      "z": 5,
      "name": "Rock_Sandstone_Brick",
      "rotation": 3
    },
    {
      "x": 3,
      "y": 4,
      "z": 5,
      "name": "Rock_Sandstone_Brick",
      "rotation": 3
    },
    {
      "x": 3,
      "y": 5,
      "z": 5,
      "name": "Rock_Sandstone_Brick_Pillar_Base",
      "rotation": 3
    },
    {
      "x": 3,
      "y": 6,
      "z": 5,
      "name": "Rock_Sandstone_Brick_Half",
      "rotation": 3
    },
    {
      "x": 4,
      "y": 6,
      "z": -1,
      "name": "Rock_Sandstone_Brick",
      "rotation": 3
    },
    {
      "x": 4,
      "y": 6,
      "z": 0,
      "name": "Rock_Sandstone_Brick",
      "rotation": 3
    },
    {
      "x": 4,
      "y": 7,
      "z": 0,
      "name": "Rock_Sandstone_Cobble_Stairs",
      "rotation": 1
    },
    {
      "x": 4,
      "y": 8,
      "z": 0,
      "name": "Rock_Sandstone_Cobble_Half",
      "rotation": 5
    },
    {
      "x": 4,
      "y": 0,
      "z": 1,
      "name": "Rock_Sandstone_Cobble",
      "rotation": 3
    },
    {
      "x": 4,
      "y": 5,
      "z": 1,
      "name": "Rock_Sandstone_Brick_Pillar_Base",
      "rotation": 3
    },
    {
      "x": 4,
      "y": 6,
      "z": 1,
      "name": "Rock_Sandstone_Brick",
      "rotation": 3
    },
    {
      "x": 4,
      "y": 7,
      "z": 1,
      "name": "Rock_Sandstone_Cobble_Stairs",
      "rotation": 1
    },
    {
      "x": 4,
      "y": 8,
      "z": 1,
      "name": "Rock_Sandstone_Cobble_Half",
      "rotation": 5
    },
    {
      "x": 4,
      "y": 0,
      "z": 2,
      "name": "Rock_Sandstone_Cobble",
      "rotation": 3
    },
    {
      "x": 4,
      "y": 1,
      "z": 2,
      "name": "Wood_Drywood_Planks_Half",
      "rotation": 6
    },
    {
      "x": 4,
      "y": 2,
      "z": 2,
      "name": "Wood_Drywood_Planks_Half",
      "rotation": 6
    },
    {
      "x": 4,
      "y": 3,
      "z": 2,
      "name": "Wood_Drywood_Stairs",
      "rotation": 34
    },
    {
      "x": 4,
      "y": 4,
      "z": 2,
      "name": "Rock_Sandstone_Brick",
      "rotation": 3
    },
    {
      "x": 4,
      "y": 5,
      "z": 2,
      "name": "Rock_Sandstone_Brick_Pillar_Base",
      "rotation": 3
    },
    {
      "x": 4,
      "y": 6,
      "z": 2,
      "name": "Rock_Sandstone_Brick",
      "rotation": 3
    },
    {
      "x": 4,
      "y": 7,
      "z": 2,
      "name": "Rock_Sandstone_Cobble_Stairs",
      "rotation": 1
    },
    {
      "x": 4,
      "y": 8,
      "z": 2,
      "name": "Rock_Sandstone_Cobble_Half",
      "rotation": 5
    },
    {
      "x": 4,
      "y": 11,
      "z": 2,
      "name": "Rock_Sandstone_Brick_Smooth_Half",
      "rotation": 4
    },
    {
      "x": 4,
      "y": 12,
      "z": 2,
      "name": "Rock_Sandstone_Brick_Smooth_Half",
      "rotation": 4
    },
    {
      "x": 4,
      "y": 0,
      "z": 3,
      "name": "Rock_Sandstone_Cobble",
      "rotation": 3
    },
    {
      "x": 4,
      "y": 1,
      "z": 3,
      "name": "Rock_Sandstone_Cobble",
      "rotation": 3
    },
    {
      "x": 4,
      "y": 2,
      "z": 3,
      "name": "Rock_Sandstone_Brick",
      "rotation": 3
    },
    {
      "x": 4,
      "y": 3,
      "z": 3,
      "name": "Rock_Sandstone_Brick",
      "rotation": 3
    },
    {
      "x": 4,
      "y": 4,
      "z": 3,
      "name": "Rock_Sandstone_Brick",
      "rotation": 3
    },
    {
      "x": 4,
      "y": 5,
      "z": 3,
      "name": "Rock_Sandstone_Brick_Pillar_Base",
      "rotation": 3
    },
    {
      "x": 4,
      "y": 6,
      "z": 3,
      "name": "Rock_Sandstone_Brick",
      "rotation": 3
    },
    {
      "x": 4,
      "y": 0,
      "z": 4,
      "name": "Rock_Sandstone_Cobble",
      "rotation": 3
    },
    {
      "x": 4,
      "y": 1,
      "z": 4,
      "name": "Rock_Sandstone_Cobble",
      "rotation": 3
    },
    {
      "x": 4,
      "y": 2,
      "z": 4,
      "name": "Rock_Sandstone_Cobble",
      "rotation": 3
    },
    {
      "x": 4,
      "y": 3,
      "z": 4,
      "name": "Rock_Sandstone_Brick",
      "rotation": 3
    },
    {
      "x": 4,
      "y": 4,
      "z": 4,
      "name": "Rock_Sandstone_Brick",
      "rotation": 3
    },
    {
      "x": 4,
      "y": 5,
      "z": 4,
      "name": "Rock_Sandstone_Brick_Pillar_Base",
      "rotation": 3
    },
    {
      "x": 4,
      "y": 6,
      "z": 4,
      "name": "Rock_Sandstone_Brick_Half",
      "rotation": 3
    }
  ],
  "fluids": [
    {
      "x": -4,
      "y": 0,
      "z": -4,
      "name": "Water_Source",
      "level": 1
    },
    {
      "x": -4,
      "y": 1,
      "z": -4,
      "name": "Water_Source",
      "level": 1
    },
    {
      "x": -4,
      "y": 2,
      "z": -4,
      "name": "Water_Source",
      "level": 1
    },
    {
      "x": -4,
      "y": 3,
      "z": -4,
      "name": "Water_Source",
      "level": 1
    },
    {
      "x": -4,
      "y": 4,
      "z": -4,
      "name": "Water_Source",
      "level": 1
    },
    {
      "x": -4,
      "y": 5,
      "z": -4,
      "name": "Water_Source",
      "level": 1
    },
    {
      "x": -4,
      "y": 6,
      "z": -4,
      "name": "Water_Source",
      "level": 1
    },
    {
      "x": -4,
      "y": 7,
      "z": -4,
      "name": "Water_Source",
      "level": 1
    },
    {
      "x": -4,
      "y": 8,
      "z": -4,
      "name": "Water_Source",
      "level": 1
    },
    {
      "x": -4,
      "y": 9,
      "z": -4,
      "name": "Water_Source",
      "level": 1
    },
    {
      "x": -4,
      "y": 10,
      "z": -4,
      "name": "Water_Source",
      "level": 1
    },
    {
      "x": -4,
      "y": 11,
      "z": -4,
      "name": "Water_Source",
      "level": 1
    },
    {
      "x": -4,
      "y": 12,
      "z": -4,
      "name": "Water_Source",
      "level": 1
    },
    {
      "x": -4,
      "y": 13,
      "z": -4,
      "name": "Water_Source",
      "level": 1
    },
    {
      "x": -4,
      "y": 0,
      "z": -3,
      "name": "Water_Source",
      "level": 1
    },
    {
      "x": -4,
      "y": 1,
      "z": -3,
      "name": "Water_Source",
      "level": 1
    },
    {
      "x": -4,
      "y": 2,
      "z": -3,
      "name": "Water_Source",
      "level": 1
    },
    {
      "x": -4,
      "y": 3,
      "z": -3,
      "name": "Water_Source",
      "level": 1
    },
    {
      "x": -4,
      "y": 4,
      "z": -3,
      "name": "Water_Source",
      "level": 1
    },
    {
      "x": -4,
      "y": 5,
      "z": -3,
      "name": "Water_Source",
      "level": 1
    },
    {
      "x": -4,
      "y": 6,
      "z": -3,
      "name": "Water_Source",
      "level": 1
    },
    {
      "x": -4,
      "y": 7,
      "z": -3,
      "name": "Water_Source",
      "level": 1
    },
    {
      "x": -4,
      "y": 8,
      "z": -3,
      "name": "Water_Source",
      "level": 1
    },
    {
      "x": -4,
      "y": 9,
      "z": -3,
      "name": "Water_Source",
      "level": 1
    },
    {
      "x": -4,
      "y": 10,
      "z": -3,
      "name": "Water_Source",
      "level": 1
    },
    {
      "x": -4,
      "y": 11,
      "z": -3,
      "name": "Water_Source",
      "level": 1
    },
    {
      "x": -4,
      "y": 12,
      "z": -3,
      "name": "Water_Source",
      "level": 1
    },
    {
      "x": -4,
      "y": 13,
      "z": -3,
      "name": "Water_Source",
      "level": 1
    },
    {
      "x": -4,
      "y": 0,
      "z": -2,
      "name": "Water_Source",
      "level": 1
    },
    {
      "x": -4,
      "y": 1,
      "z": -2,
      "name": "Water_Source",
      "level": 1
    },
    {
      "x": -4,
      "y": 2,
      "z": -2,
      "name": "Water_Source",
      "level": 1
    },
    {
      "x": -4,
      "y": 3,
      "z": -2,
      "name": "Water_Source",
      "level": 1
    },
    {
      "x": -4,
      "y": 4,
      "z": -2,
      "name": "Water_Source",
      "level": 1
    },
    {
      "x": -4,
      "y": 5,
      "z": -2,
      "name": "Water_Source",
      "level": 1
    },
    {
      "x": -4,
      "y": 6,
      "z": -2,
      "name": "Water_Source",
      "level": 1
    },
    {
      "x": -4,
      "y": 7,
      "z": -2,
      "name": "Water_Source",
      "level": 1
    },
    {
      "x": -4,
      "y": 8,
      "z": -2,
      "name": "Water_Source",
      "level": 1
    },
    {
      "x": -4,
      "y": 9,
      "z": -2,
      "name": "Water_Source",
      "level": 1
    },
    {
      "x": -4,
      "y": 10,
      "z": -2,
      "name": "Water_Source",
      "level": 1
    },
    {
      "x": -4,
      "y": 11,
      "z": -2,
      "name": "Water_Source",
      "level": 1
    },
    {
      "x": -4,
      "y": 12,
      "z": -2,
      "name": "Water_Source",
      "level": 1
    },
    {
      "x": -4,
      "y": 13,
      "z": -2,
      "name": "Water_Source",
      "level": 1
    },
    {
      "x": -4,
      "y": 0,
      "z": -1,
      "name": "Water_Source",
      "level": 1
    },
    {
      "x": -4,
      "y": 1,
      "z": -1,
      "name": "Water_Source",
      "level": 1
    },
    {
      "x": -4,
      "y": 2,
      "z": -1,
      "name": "Water_Source",
      "level": 1
    },
    {
      "x": -4,
      "y": 3,
      "z": -1,
      "name": "Water_Source",
      "level": 1
    },
    {
      "x": -4,
      "y": 4,
      "z": -1,
      "name": "Water_Source",
      "level": 1
    },
    {
      "x": -4,
      "y": 5,
      "z": -1,
      "name": "Water_Source",
      "level": 1
    },
    {
      "x": -4,
      "y": 6,
      "z": -1,
      "name": "Water_Source",
      "level": 1
    },
    {
      "x": -4,
      "y": 7,
      "z": -1,
      "name": "Water_Source",
      "level": 1
    },
    {
      "x": -4,
      "y": 8,
      "z": -1,
      "name": "Water_Source",
      "level": 1
    },
    {
      "x": -4,
      "y": 9,
      "z": -1,
      "name": "Water_Source",
      "level": 1
    },
    {
      "x": -4,
      "y": 10,
      "z": -1,
      "name": "Water_Source",
      "level": 1
    },
    {
      "x": -4,
      "y": 11,
      "z": -1,
      "name": "Water_Source",
      "level": 1
    },
    {
      "x": -4,
      "y": 12,
      "z": -1,
      "name": "Water_Source",
      "level": 1
    },
    {
      "x": -4,
      "y": 13,
      "z": -1,
      "name": "Water_Source",
      "level": 1
    },
    {
      "x": -4,
      "y": 0,
      "z": 0,
      "name": "Water_Source",
      "level": 1
    },
    {
      "x": -4,
      "y": 1,
      "z": 0,
      "name": "Water_Source",
      "level": 1
    },
    {
      "x": -4,
      "y": 2,
      "z": 0,
      "name": "Water_Source",
      "level": 1
    },
    {
      "x": -4,
      "y": 3,
      "z": 0,
      "name": "Water_Source",
      "level": 1
    },
    {
      "x": -4,
      "y": 4,
      "z": 0,
      "name": "Water_Source",
      "level": 1
    },
    {
      "x": -4,
      "y": 5,
      "z": 0,
      "name": "Water_Source",
      "level": 1
    },
    {
      "x": -4,
      "y": 6,
      "z": 0,
      "name": "Water_Source",
      "level": 1
    },
    {
      "x": -4,
      "y": 7,
      "z": 0,
      "name": "Water_Source",
      "level": 1
    },
    {
      "x": -4,
      "y": 8,
      "z": 0,
      "name": "Water_Source",
      "level": 1
    },
    {
      "x": -4,
      "y": 9,
      "z": 0,
      "name": "Water_Source",
      "level": 1
    },
    {
      "x": -4,
      "y": 10,
      "z": 0,
      "name": "Water_Source",
      "level": 1
    },
    {
      "x": -4,
      "y": 11,
      "z": 0,
      "name": "Water_Source",
      "level": 1
    },
    {
      "x": -4,
      "y": 12,
      "z": 0,
      "name": "Water_Source",
      "level": 1
    },
    {
      "x": -4,
      "y": 13,
      "z": 0,
      "name": "Water_Source",
      "level": 1
    },
    {
      "x": -4,
      "y": 0,
      "z": 1,
      "name": "Water_Source",
      "level": 1
    },
    {
      "x": -4,
      "y": 1,
      "z": 1,
      "name": "Water_Source",
      "level": 1
    },
    {
      "x": -4,
      "y": 2,
      "z": 1,
      "name": "Water_Source",
      "level": 1
    },
    {
      "x": -4,
      "y": 3,
      "z": 1,
      "name": "Water_Source",
      "level": 1
    },
    {
      "x": -4,
      "y": 4,
      "z": 1,
      "name": "Water_Source",
      "level": 1
    },
    {
      "x": -4,
      "y": 5,
      "z": 1,
      "name": "Water_Source",
      "level": 1
    },
    {
      "x": -4,
      "y": 6,
      "z": 1,
      "name": "Water_Source",
      "level": 1
    },
    {
      "x": -4,
      "y": 7,
      "z": 1,
      "name": "Water_Source",
      "level": 1
    },
    {
      "x": -4,
      "y": 8,
      "z": 1,
      "name": "Water_Source",
      "level": 1
    },
    {
      "x": -4,
      "y": 9,
      "z": 1,
      "name": "Water_Source",
      "level": 1
    },
    {
      "x": -4,
      "y": 10,
      "z": 1,
      "name": "Water_Source",
      "level": 1
    },
    {
      "x": -4,
      "y": 11,
      "z": 1,
      "name": "Water_Source",
      "level": 1
    },
    {
      "x": -4,
      "y": 12,
      "z": 1,
      "name": "Water_Source",
      "level": 1
    },
    {
      "x": -4,
      "y": 13,
      "z": 1,
      "name": "Water_Source",
      "level": 1
    },
    {
      "x": -4,
      "y": 0,
      "z": 2,
      "name": "Water_Source",
      "level": 1
    },
    {
      "x": -4,
      "y": 1,
      "z": 2,
      "name": "Water_Source",
      "level": 1
    },
    {
      "x": -4,
      "y": 2,
      "z": 2,
      "name": "Water_Source",
      "level": 1
    },
    {
      "x": -4,
      "y": 3,
      "z": 2,
      "name": "Water_Source",
      "level": 1
    },
    {
      "x": -4,
      "y": 4,
      "z": 2,
      "name": "Water_Source",
      "level": 1
    },
    {
      "x": -4,
      "y": 5,
      "z": 2,
      "name": "Water_Source",
      "level": 1
    },
    {
      "x": -4,
      "y": 6,
      "z": 2,
      "name": "Water_Source",
      "level": 1
    },
    {
      "x": -4,
      "y": 7,
      "z": 2,
      "name": "Water_Source",
      "level": 1
    },
    {
      "x": -4,
      "y": 8,
      "z": 2,
      "name": "Water_Source",
      "level": 1
    },
    {
      "x": -4,
      "y": 9,
      "z": 2,
      "name": "Water_Source",
      "level": 1
    },
    {
      "x": -4,
      "y": 10,
      "z": 2,
      "name": "Water_Source",
      "level": 1
    },
    {
      "x": -4,
      "y": 11,
      "z": 2,
      "name": "Water_Source",
      "level": 1
    },
    {
      "x": -4,
      "y": 12,
      "z": 2,
      "name": "Water_Source",
      "level": 1
    },
    {
      "x": -4,
      "y": 13,
      "z": 2,
      "name": "Water_Source",
      "level": 1
    },
    {
      "x": -4,
      "y": 0,
      "z": 3,
      "name": "Water_Source",
      "level": 1
    },
    {
      "x": -4,
      "y": 1,
      "z": 3,
      "name": "Water_Source",
      "level": 1
    },
    {
      "x": -4,
      "y": 2,
      "z": 3,
      "name": "Water_Source",
      "level": 1
    },
    {
      "x": -4,
      "y": 3,
      "z": 3,
      "name": "Water_Source",
      "level": 1
    },
    {
      "x": -4,
      "y": 4,
      "z": 3,
      "name": "Water_Source",
      "level": 1
    },
    {
      "x": -4,
      "y": 5,
      "z": 3,
      "name": "Water_Source",
      "level": 1
    },
    {
      "x": -4,
      "y": 6,
      "z": 3,
      "name": "Water_Source",
      "level": 1
    },
    {
      "x": -4,
      "y": 7,
      "z": 3,
      "name": "Water_Source",
      "level": 1
    },
    {
      "x": -4,
      "y": 8,
      "z": 3,
      "name": "Water_Source",
      "level": 1
    },
    {
      "x": -4,
      "y": 9,
      "z": 3,
      "name": "Water_Source",
      "level": 1
    },
    {
      "x": -4,
      "y": 10,
      "z": 3,
      "name": "Water_Source",
      "level": 1
    },
    {
      "x": -4,
      "y": 11,
      "z": 3,
      "name": "Water_Source",
      "level": 1
    },
    {
      "x": -4,
      "y": 12,
      "z": 3,
      "name": "Water_Source",
      "level": 1
    },
    {
      "x": -4,
      "y": 13,
      "z": 3,
      "name": "Water_Source",
      "level": 1
    },
    {
      "x": -4,
      "y": 0,
      "z": 4,
      "name": "Water_Source",
      "level": 1
    },
    {
      "x": -4,
      "y": 1,
      "z": 4,
      "name": "Water_Source",
      "level": 1
    },
    {
      "x": -4,
      "y": 2,
      "z": 4,
      "name": "Water_Source",
      "level": 1
    },
    {
      "x": -4,
      "y": 3,
      "z": 4,
      "name": "Water_Source",
      "level": 1
    },
    {
      "x": -4,
      "y": 4,
      "z": 4,
      "name": "Water_Source",
      "level": 1
    },
    {
      "x": -4,
      "y": 5,
      "z": 4,
      "name": "Water_Source",
      "level": 1
    },
    {
      "x": -4,
      "y": 6,
      "z": 4,
      "name": "Water_Source",
      "level": 1
    },
    {
      "x": -4,
      "y": 7,
      "z": 4,
      "name": "Water_Source",
      "level": 1
    },
    {
      "x": -4,
      "y": 8,
      "z": 4,
      "name": "Water_Source",
      "level": 1
    },
    {
      "x": -4,
      "y": 9,
      "z": 4,
      "name": "Water_Source",
      "level": 1
    },
    {
      "x": -4,
      "y": 10,
      "z": 4,
      "name": "Water_Source",
      "level": 1
    },
    {
      "x": -4,
      "y": 11,
      "z": 4,
      "name": "Water_Source",
      "level": 1
    },
    {
      "x": -4,
      "y": 12,
      "z": 4,
      "name": "Water_Source",
      "level": 1
    },
    {
      "x": -4,
      "y": 13,
      "z": 4,
      "name": "Water_Source",
      "level": 1
    },
    {
      "x": -4,
      "y": 0,
      "z": 5,
      "name": "Water_Source",
      "level": 1
    },
    {
      "x": -4,
      "y": 1,
      "z": 5,
      "name": "Water_Source",
      "level": 1
    },
    {
      "x": -4,
      "y": 2,
      "z": 5,
      "name": "Water_Source",
      "level": 1
    },
    {
      "x": -4,
      "y": 3,
      "z": 5,
      "name": "Water_Source",
      "level": 1
    },
    {
      "x": -4,
      "y": 4,
      "z": 5,
      "name": "Water_Source",
      "level": 1
    },
    {
      "x": -4,
      "y": 5,
      "z": 5,
      "name": "Water_Source",
      "level": 1
    },
    {
      "x": -4,
      "y": 6,
      "z": 5,
      "name": "Water_Source",
      "level": 1
    },
    {
      "x": -4,
      "y": 7,
      "z": 5,
      "name": "Water_Source",
      "level": 1
    },
    {
      "x": -4,
      "y": 8,
      "z": 5,
      "name": "Water_Source",
      "level": 1
    },
    {
      "x": -4,
      "y": 9,
      "z": 5,
      "name": "Water_Source",
      "level": 1
    },
    {
      "x": -4,
      "y": 10,
      "z": 5,
      "name": "Water_Source",
      "level": 1
    },
    {
      "x": -4,
      "y": 11,
      "z": 5,
      "name": "Water_Source",
      "level": 1
    },
    {
      "x": -4,
      "y": 12,
      "z": 5,
      "name": "Water_Source",
      "level": 1
    },
    {
      "x": -4,
      "y": 13,
      "z": 5,
      "name": "Water_Source",
      "level": 1
    },
    {
      "x": -3,
      "y": 0,
      "z": -4,
      "name": "Water_Source",
      "level": 1
    },
    {
      "x": -3,
      "y": 1,
      "z": -4,
      "name": "Water_Source",
      "level": 1
    },
    {
      "x": -3,
      "y": 2,
      "z": -4,
      "name": "Water_Source",
      "level": 1
    },
    {
      "x": -3,
      "y": 3,
      "z": -4,
      "name": "Water_Source",
      "level": 1
    },
    {
      "x": -3,
      "y": 4,
      "z": -4,
      "name": "Water_Source",
      "level": 1
    },
    {
      "x": -3,
      "y": 5,
      "z": -4,
      "name": "Water_Source",
      "level": 1
    },
    {
      "x": -3,
      "y": 6,
      "z": -4,
      "name": "Water_Source",
      "level": 1
    },
    {
      "x": -3,
      "y": 7,
      "z": -4,
      "name": "Water_Source",
      "level": 1
    },
    {
      "x": -3,
      "y": 8,
      "z": -4,
      "name": "Water_Source",
      "level": 1
    },
    {
      "x": -3,
      "y": 9,
      "z": -4,
      "name": "Water_Source",
      "level": 1
    },
    {
      "x": -3,
      "y": 10,
      "z": -4,
      "name": "Water_Source",
      "level": 1
    },
    {
      "x": -3,
      "y": 11,
      "z": -4,
      "name": "Water_Source",
      "level": 1
    },
    {
      "x": -3,
      "y": 12,
      "z": -4,
      "name": "Water_Source",
      "level": 1
    },
    {
      "x": -3,
      "y": 13,
      "z": -4,
      "name": "Water_Source",
      "level": 1
    },
    {
      "x": -3,
      "y": 0,
      "z": -3,
      "name": "Water_Source",
      "level": 1
    },
    {
      "x": -3,
      "y": 1,
      "z": -3,
      "name": "Water_Source",
      "level": 1
    },
    {
      "x": -3,
      "y": 2,
      "z": -3,
      "name": "Water_Source",
      "level": 1
    },
    {
      "x": -3,
      "y": 3,
      "z": -3,
      "name": "Water_Source",
      "level": 1
    },
    {
      "x": -3,
      "y": 4,
      "z": -3,
      "name": "Water_Source",
      "level": 1
    },
    {
      "x": -3,
      "y": 5,
      "z": -3,
      "name": "Water_Source",
      "level": 1
    },
    {
      "x": -3,
      "y": 6,
      "z": -3,
      "name": "Water_Source",
      "level": 1
    },
    {
      "x": -3,
      "y": 7,
      "z": -3,
      "name": "Water_Source",
      "level": 1
    },
    {
      "x": -3,
      "y": 8,
      "z": -3,
      "name": "Water_Source",
      "level": 1
    },
    {
      "x": -3,
      "y": 9,
      "z": -3,
      "name": "Water_Source",
      "level": 1
    },
    {
      "x": -3,
      "y": 10,
      "z": -3,
      "name": "Water_Source",
      "level": 1
    },
    {
      "x": -3,
      "y": 11,
      "z": -3,
      "name": "Water_Source",
      "level": 1
    },
    {
      "x": -3,
      "y": 12,
      "z": -3,
      "name": "Water_Source",
      "level": 1
    },
    {
      "x": -3,
      "y": 13,
      "z": -3,
      "name": "Water_Source",
      "level": 1
    },
    {
      "x": -3,
      "y": 0,
      "z": -2,
      "name": "Water_Source",
      "level": 1
    },
    {
      "x": -3,
      "y": 1,
      "z": -2,
      "name": "Water_Source",
      "level": 1
    },
    {
      "x": -3,
      "y": 2,
      "z": -2,
      "name": "Water_Source",
      "level": 1
    },
    {
      "x": -3,
      "y": 3,
      "z": -2,
      "name": "Water_Source",
      "level": 1
    },
    {
      "x": -3,
      "y": 4,
      "z": -2,
      "name": "Water_Source",
      "level": 1
    },
    {
      "x": -3,
      "y": 5,
      "z": -2,
      "name": "Water_Source",
      "level": 1
    },
    {
      "x": -3,
      "y": 6,
      "z": -2,
      "name": "Water_Source",
      "level": 1
    },
    {
      "x": -3,
      "y": 7,
      "z": -2,
      "name": "Water_Source",
      "level": 1
    },
    {
      "x": -3,
      "y": 8,
      "z": -2,
      "name": "Water_Source",
      "level": 1
    },
    {
      "x": -3,
      "y": 9,
      "z": -2,
      "name": "Water_Source",
      "level": 1
    },
    {
      "x": -3,
      "y": 10,
      "z": -2,
      "name": "Water_Source",
      "level": 1
    },
    {
      "x": -3,
      "y": 11,
      "z": -2,
      "name": "Water_Source",
      "level": 1
    },
    {
      "x": -3,
      "y": 12,
      "z": -2,
      "name": "Water_Source",
      "level": 1
    },
    {
      "x": -3,
      "y": 13,
      "z": -2,
      "name": "Water_Source",
      "level": 1
    },
    {
      "x": -3,
      "y": 0,
      "z": -1,
      "name": "Water_Source",
      "level": 1
    },
    {
      "x": -3,
      "y": 1,
      "z": -1,
      "name": "Water_Source",
      "level": 1
    },
    {
      "x": -3,
      "y": 2,
      "z": -1,
      "name": "Water_Source",
      "level": 1
    },
    {
      "x": -3,
      "y": 3,
      "z": -1,
      "name": "Water_Source",
      "level": 1
    },
    {
      "x": -3,
      "y": 4,
      "z": -1,
      "name": "Water_Source",
      "level": 1
    },
    {
      "x": -3,
      "y": 5,
      "z": -1,
      "name": "Water_Source",
      "level": 1
    },
    {
      "x": -3,
      "y": 6,
      "z": -1,
      "name": "Water_Source",
      "level": 1
    },
    {
      "x": -3,
      "y": 7,
      "z": -1,
      "name": "Water_Source",
      "level": 1
    },
    {
      "x": -3,
      "y": 8,
      "z": -1,
      "name": "Water_Source",
      "level": 1
    },
    {
      "x": -3,
      "y": 9,
      "z": -1,
      "name": "Water_Source",
      "level": 1
    },
    {
      "x": -3,
      "y": 10,
      "z": -1,
      "name": "Water_Source",
      "level": 1
    },
    {
      "x": -3,
      "y": 11,
      "z": -1,
      "name": "Water_Source",
      "level": 1
    },
    {
      "x": -3,
      "y": 12,
      "z": -1,
      "name": "Water_Source",
      "level": 1
    },
    {
      "x": -3,
      "y": 13,
      "z": -1,
      "name": "Water_Source",
      "level": 1
    },
    {
      "x": -3,
      "y": 0,
      "z": 0,
      "name": "Water_Source",
      "level": 1
    },
    {
      "x": -3,
      "y": 1,
      "z": 0,
      "name": "Water_Source",
      "level": 1
    },
    {
      "x": -3,
      "y": 2,
      "z": 0,
      "name": "Water_Source",
      "level": 1
    },
    {
      "x": -3,
      "y": 3,
      "z": 0,
      "name": "Water_Source",
      "level": 1
    },
    {
      "x": -3,
      "y": 4,
      "z": 0,
      "name": "Water_Source",
      "level": 1
    },
    {
      "x": -3,
      "y": 5,
      "z": 0,
      "name": "Water_Source",
      "level": 1
    },
    {
      "x": -3,
      "y": 6,
      "z": 0,
      "name": "Water_Source",
      "level": 1
    },
    {
      "x": -3,
      "y": 7,
      "z": 0,
      "name": "Water_Source",
      "level": 1
    },
    {
      "x": -3,
      "y": 8,
      "z": 0,
      "name": "Water_Source",
      "level": 1
    },
    {
      "x": -3,
      "y": 9,
      "z": 0,
      "name": "Water_Source",
      "level": 1
    },
    {
      "x": -3,
      "y": 10,
      "z": 0,
      "name": "Water_Source",
      "level": 1
    },
    {
      "x": -3,
      "y": 11,
      "z": 0,
      "name": "Water_Source",
      "level": 1
    },
    {
      "x": -3,
      "y": 12,
      "z": 0,
      "name": "Water_Source",
      "level": 1
    },
    {
      "x": -3,
      "y": 13,
      "z": 0,
      "name": "Water_Source",
      "level": 1
    },
    {
      "x": -3,
      "y": 0,
      "z": 1,
      "name": "Water_Source",
      "level": 1
    },
    {
      "x": -3,
      "y": 1,
      "z": 1,
      "name": "Water_Source",
      "level": 1
    },
    {
      "x": -3,
      "y": 2,
      "z": 1,
      "name": "Water_Source",
      "level": 1
    },
    {
      "x": -3,
      "y": 3,
      "z": 1,
      "name": "Water_Source",
      "level": 1
    },
    {
      "x": -3,
      "y": 4,
      "z": 1,
      "name": "Water_Source",
      "level": 1
    },
    {
      "x": -3,
      "y": 5,
      "z": 1,
      "name": "Water_Source",
      "level": 1
    },
    {
      "x": -3,
      "y": 6,
      "z": 1,
      "name": "Water_Source",
      "level": 1
    },
    {
      "x": -3,
      "y": 7,
      "z": 1,
      "name": "Water_Source",
      "level": 1
    },
    {
      "x": -3,
      "y": 8,
      "z": 1,
      "name": "Water_Source",
      "level": 1
    },
    {
      "x": -3,
      "y": 9,
      "z": 1,
      "name": "Water_Source",
      "level": 1
    },
    {
      "x": -3,
      "y": 10,
      "z": 1,
      "name": "Water_Source",
      "level": 1
    },
    {
      "x": -3,
      "y": 11,
      "z": 1,
      "name": "Water_Source",
      "level": 1
    },
    {
      "x": -3,
      "y": 12,
      "z": 1,
      "name": "Water_Source",
      "level": 1
    },
    {
      "x": -3,
      "y": 13,
      "z": 1,
      "name": "Water_Source",
      "level": 1
    },
    {
      "x": -3,
      "y": 0,
      "z": 2,
      "name": "Water_Source",
      "level": 1
    },
    {
      "x": -3,
      "y": 1,
      "z": 2,
      "name": "Water_Source",
      "level": 1
    },
    {
      "x": -3,
      "y": 2,
      "z": 2,
      "name": "Water_Source",
      "level": 1
    },
    {
      "x": -3,
      "y": 3,
      "z": 2,
      "name": "Water_Source",
      "level": 1
    },
    {
      "x": -3,
      "y": 4,
      "z": 2,
      "name": "Water_Source",
      "level": 1
    },
    {
      "x": -3,
      "y": 5,
      "z": 2,
      "name": "Water_Source",
      "level": 1
    },
    {
      "x": -3,
      "y": 6,
      "z": 2,
      "name": "Water_Source",
      "level": 1
    },
    {
      "x": -3,
      "y": 7,
      "z": 2,
      "name": "Water_Source",
      "level": 1
    },
    {
      "x": -3,
      "y": 8,
      "z": 2,
      "name": "Water_Source",
      "level": 1
    },
    {
      "x": -3,
      "y": 9,
      "z": 2,
      "name": "Water_Source",
      "level": 1
    },
    {
      "x": -3,
      "y": 10,
      "z": 2,
      "name": "Water_Source",
      "level": 1
    },
    {
      "x": -3,
      "y": 11,
      "z": 2,
      "name": "Water_Source",
      "level": 1
    },
    {
      "x": -3,
      "y": 12,
      "z": 2,
      "name": "Water_Source",
      "level": 1
    },
    {
      "x": -3,
      "y": 13,
      "z": 2,
      "name": "Water_Source",
      "level": 1
    },
    {
      "x": -3,
      "y": 0,
      "z": 3,
      "name": "Water_Source",
      "level": 1
    },
    {
      "x": -3,
      "y": 1,
      "z": 3,
      "name": "Water_Source",
      "level": 1
    },
    {
      "x": -3,
      "y": 2,
      "z": 3,
      "name": "Water_Source",
      "level": 1
    },
    {
      "x": -3,
      "y": 3,
      "z": 3,
      "name": "Water_Source",
      "level": 1
    },
    {
      "x": -3,
      "y": 4,
      "z": 3,
      "name": "Water_Source",
      "level": 1
    },
    {
      "x": -3,
      "y": 5,
      "z": 3,
      "name": "Water_Source",
      "level": 1
    },
    {
      "x": -3,
      "y": 6,
      "z": 3,
      "name": "Water_Source",
      "level": 1
    },
    {
      "x": -3,
      "y": 7,
      "z": 3,
      "name": "Water_Source",
      "level": 1
    },
    {
      "x": -3,
      "y": 8,
      "z": 3,
      "name": "Water_Source",
      "level": 1
    },
    {
      "x": -3,
      "y": 9,
      "z": 3,
      "name": "Water_Source",
      "level": 1
    },
    {
      "x": -3,
      "y": 10,
      "z": 3,
      "name": "Water_Source",
      "level": 1
    },
    {
      "x": -3,
      "y": 11,
      "z": 3,
      "name": "Water_Source",
      "level": 1
    },
    {
      "x": -3,
      "y": 12,
      "z": 3,
      "name": "Water_Source",
      "level": 1
    },
    {
      "x": -3,
      "y": 13,
      "z": 3,
      "name": "Water_Source",
      "level": 1
    },
    {
      "x": -3,
      "y": 0,
      "z": 4,
      "name": "Water_Source",
      "level": 1
    },
    {
      "x": -3,
      "y": 1,
      "z": 4,
      "name": "Water_Source",
      "level": 1
    },
    {
      "x": -3,
      "y": 2,
      "z": 4,
      "name": "Water_Source",
      "level": 1
    },
    {
      "x": -3,
      "y": 3,
      "z": 4,
      "name": "Water_Source",
      "level": 1
    },
    {
      "x": -3,
      "y": 4,
      "z": 4,
      "name": "Water_Source",
      "level": 1
    },
    {
      "x": -3,
      "y": 5,
      "z": 4,
      "name": "Water_Source",
      "level": 1
    },
    {
      "x": -3,
      "y": 6,
      "z": 4,
      "name": "Water_Source",
      "level": 1
    },
    {
      "x": -3,
      "y": 7,
      "z": 4,
      "name": "Water_Source",
      "level": 1
    },
    {
      "x": -3,
      "y": 8,
      "z": 4,
      "name": "Water_Source",
      "level": 1
    },
    {
      "x": -3,
      "y": 9,
      "z": 4,
      "name": "Water_Source",
      "level": 1
    },
    {
      "x": -3,
      "y": 10,
      "z": 4,
      "name": "Water_Source",
      "level": 1
    },
    {
      "x": -3,
      "y": 11,
      "z": 4,
      "name": "Water_Source",
      "level": 1
    },
    {
      "x": -3,
      "y": 12,
      "z": 4,
      "name": "Water_Source",
      "level": 1
    },
    {
      "x": -3,
      "y": 13,
      "z": 4,
      "name": "Water_Source",
      "level": 1
    },
    {
      "x": -3,
      "y": 0,
      "z": 5,
      "name": "Water_Source",
      "level": 1
    },
    {
      "x": -3,
      "y": 1,
      "z": 5,
      "name": "Water_Source",
      "level": 1
    },
    {
      "x": -3,
      "y": 2,
      "z": 5,
      "name": "Water_Source",
      "level": 1
    },
    {
      "x": -3,
      "y": 3,
      "z": 5,
      "name": "Water_Source",
      "level": 1
    },
    {
      "x": -3,
      "y": 4,
      "z": 5,
      "name": "Water_Source",
      "level": 1
    },
    {
      "x": -3,
      "y": 5,
      "z": 5,
      "name": "Water_Source",
      "level": 1
    },
    {
      "x": -3,
      "y": 6,
      "z": 5,
      "name": "Water_Source",
      "level": 1
    },
    {
      "x": -3,
      "y": 7,
      "z": 5,
      "name": "Water_Source",
      "level": 1
    },
    {
      "x": -3,
      "y": 8,
      "z": 5,
      "name": "Water_Source",
      "level": 1
    },
    {
      "x": -3,
      "y": 9,
      "z": 5,
      "name": "Water_Source",
      "level": 1
    },
    {
      "x": -3,
      "y": 10,
      "z": 5,
      "name": "Water_Source",
      "level": 1
    },
    {
      "x": -3,
      "y": 11,
      "z": 5,
      "name": "Water_Source",
      "level": 1
    },
    {
      "x": -3,
      "y": 12,
      "z": 5,
      "name": "Water_Source",
      "level": 1
    },
    {
      "x": -3,
      "y": 13,
      "z": 5,
      "name": "Water_Source",
      "level": 1
    },
    {
      "x": -2,
      "y": 0,
      "z": -4,
      "name": "Water_Source",
      "level": 1
    },
    {
      "x": -2,
      "y": 1,
      "z": -4,
      "name": "Water_Source",
      "level": 1
    },
    {
      "x": -2,
      "y": 2,
      "z": -4,
      "name": "Water_Source",
      "level": 1
    },
    {
      "x": -2,
      "y": 3,
      "z": -4,
      "name": "Water_Source",
      "level": 1
    },
    {
      "x": -2,
      "y": 4,
      "z": -4,
      "name": "Water_Source",
      "level": 1
    },
    {
      "x": -2,
      "y": 5,
      "z": -4,
      "name": "Water_Source",
      "level": 1
    },
    {
      "x": -2,
      "y": 6,
      "z": -4,
      "name": "Water_Source",
      "level": 1
    },
    {
      "x": -2,
      "y": 7,
      "z": -4,
      "name": "Water_Source",
      "level": 1
    },
    {
      "x": -2,
      "y": 8,
      "z": -4,
      "name": "Water_Source",
      "level": 1
    },
    {
      "x": -2,
      "y": 9,
      "z": -4,
      "name": "Water_Source",
      "level": 1
    },
    {
      "x": -2,
      "y": 10,
      "z": -4,
      "name": "Water_Source",
      "level": 1
    },
    {
      "x": -2,
      "y": 11,
      "z": -4,
      "name": "Water_Source",
      "level": 1
    },
    {
      "x": -2,
      "y": 12,
      "z": -4,
      "name": "Water_Source",
      "level": 1
    },
    {
      "x": -2,
      "y": 13,
      "z": -4,
      "name": "Water_Source",
      "level": 1
    },
    {
      "x": -2,
      "y": 0,
      "z": -3,
      "name": "Water_Source",
      "level": 1
    },
    {
      "x": -2,
      "y": 1,
      "z": -3,
      "name": "Water_Source",
      "level": 1
    },
    {
      "x": -2,
      "y": 2,
      "z": -3,
      "name": "Water_Source",
      "level": 1
    },
    {
      "x": -2,
      "y": 3,
      "z": -3,
      "name": "Water_Source",
      "level": 1
    },
    {
      "x": -2,
      "y": 4,
      "z": -3,
      "name": "Water_Source",
      "level": 1
    },
    {
      "x": -2,
      "y": 5,
      "z": -3,
      "name": "Water_Source",
      "level": 1
    },
    {
      "x": -2,
      "y": 6,
      "z": -3,
      "name": "Water_Source",
      "level": 1
    },
    {
      "x": -2,
      "y": 7,
      "z": -3,
      "name": "Water_Source",
      "level": 1
    },
    {
      "x": -2,
      "y": 8,
      "z": -3,
      "name": "Water_Source",
      "level": 1
    },
    {
      "x": -2,
      "y": 9,
      "z": -3,
      "name": "Water_Source",
      "level": 1
    },
    {
      "x": -2,
      "y": 10,
      "z": -3,
      "name": "Water_Source",
      "level": 1
    },
    {
      "x": -2,
      "y": 11,
      "z": -3,
      "name": "Water_Source",
      "level": 1
    },
    {
      "x": -2,
      "y": 12,
      "z": -3,
      "name": "Water_Source",
      "level": 1
    },
    {
      "x": -2,
      "y": 13,
      "z": -3,
      "name": "Water_Source",
      "level": 1
    },
    {
      "x": -2,
      "y": 0,
      "z": -2,
      "name": "Water_Source",
      "level": 1
    },
    {
      "x": -2,
      "y": 1,
      "z": -2,
      "name": "Water_Source",
      "level": 1
    },
    {
      "x": -2,
      "y": 2,
      "z": -2,
      "name": "Water_Source",
      "level": 1
    },
    {
      "x": -2,
      "y": 3,
      "z": -2,
      "name": "Water_Source",
      "level": 1
    },
    {
      "x": -2,
      "y": 4,
      "z": -2,
      "name": "Water_Source",
      "level": 1
    },
    {
      "x": -2,
      "y": 5,
      "z": -2,
      "name": "Water_Source",
      "level": 1
    },
    {
      "x": -2,
      "y": 6,
      "z": -2,
      "name": "Water_Source",
      "level": 1
    },
    {
      "x": -2,
      "y": 7,
      "z": -2,
      "name": "Water_Source",
      "level": 1
    },
    {
      "x": -2,
      "y": 8,
      "z": -2,
      "name": "Water_Source",
      "level": 1
    },
    {
      "x": -2,
      "y": 9,
      "z": -2,
      "name": "Water_Source",
      "level": 1
    },
    {
      "x": -2,
      "y": 10,
      "z": -2,
      "name": "Water_Source",
      "level": 1
    },
    {
      "x": -2,
      "y": 11,
      "z": -2,
      "name": "Water_Source",
      "level": 1
    },
    {
      "x": -2,
      "y": 12,
      "z": -2,
      "name": "Water_Source",
      "level": 1
    },
    {
      "x": -2,
      "y": 13,
      "z": -2,
      "name": "Water_Source",
      "level": 1
    },
    {
      "x": -2,
      "y": 0,
      "z": -1,
      "name": "Water_Source",
      "level": 1
    },
    {
