{
  "version": 8,
  "blockIdVersion": 11,
  "anchorX": 0,
  "anchorY": 25,
  "anchorZ": 0,
  "blocks": [
    {
      "x": -12,
      "y": 20,
      "z": -12,
      "name": "*Rock_Sandstone_Brick_Stairs_State_Definitions_Corner_Left",
      "rotation": 9
    },
    {
      "x": -12,
      "y": 22,
      "z": -12,
      "name": "*Rock_Sandstone_Brick_Stairs_State_Definitions_Corner_Left",
      "rotation": 9
    },
    {
      "x": -12,
      "y": 25,
      "z": -12,
      "name": "*Rock_Sandstone_Brick_Stairs_State_Definitions_Corner_Right",
      "rotation": 8
    },
    {
      "x": -12,
      "y": -10,
      "z": -11,
      "name": "Rock_Sandstone_Brick_Half",
      "rotation": 7
    },
    {
      "x": -12,
      "y": -9,
      "z": -11,
      "name": "Rock_Sandstone_Brick_Half",
      "rotation": 7
    },
    {
      "x": -12,
      "y": -8,
      "z": -11,
      "name": "Rock_Sandstone_Brick_Half",
      "rotation": 7
    },
    {
      "x": -12,
      "y": -7,
      "z": -11,
      "name": "Rock_Sandstone_Brick_Half",
      "rotation": 7
    },
    {
      "x": -12,
      "y": -6,
      "z": -11,
      "name": "Rock_Sandstone_Brick_Half",
      "rotation": 7
    },
    {
      "x": -12,
      "y": -5,
      "z": -11,
      "name": "Rock_Sandstone_Brick_Half",
      "rotation": 7
    },
    {
      "x": -12,
      "y": -4,
      "z": -11,
      "name": "Rock_Sandstone_Brick_Half",
      "rotation": 7
    },
    {
      "x": -12,
      "y": -3,
      "z": -11,
      "name": "Rock_Sandstone_Brick_Half",
      "rotation": 7
    },
    {
      "x": -12,
      "y": -2,
      "z": -11,
      "name": "Rock_Sandstone_Brick_Half",
      "rotation": 7
    },
    {
      "x": -12,
      "y": -1,
      "z": -11,
      "name": "Rock_Sandstone_Brick_Half",
      "rotation": 7
    },
    {
      "x": -12,
      "y": 0,
      "z": -11,
      "name": "Rock_Sandstone_Brick_Half",
      "rotation": 7
    },
    {
      "x": -12,
      "y": 1,
      "z": -11,
      "name": "Rock_Sandstone_Brick_Half",
      "rotation": 7
    },
    {
      "x": -12,
      "y": 2,
      "z": -11,
      "name": "Rock_Sandstone_Brick_Half",
      "rotation": 7
    },
    {
      "x": -12,
      "y": 3,
      "z": -11,
      "name": "Rock_Sandstone_Brick_Half",
      "rotation": 7
    },
    {
      "x": -12,
      "y": 4,
      "z": -11,
      "name": "Rock_Sandstone_Brick_Half",
      "rotation": 7
    },
    {
      "x": -12,
      "y": 5,
      "z": -11,
      "name": "Rock_Sandstone_Brick_Half",
      "rotation": 7
    },
    {
      "x": -12,
      "y": 6,
      "z": -11,
      "name": "Rock_Sandstone_Brick_Half",
      "rotation": 7
    },
    {
      "x": -12,
      "y": 7,
      "z": -11,
      "name": "Rock_Sandstone_Brick_Half",
      "rotation": 7
    },
    {
      "x": -12,
      "y": 8,
      "z": -11,
      "name": "Rock_Sandstone_Brick_Half",
      "rotation": 7
    },
    {
      "x": -12,
      "y": 9,
      "z": -11,
      "name": "Rock_Sandstone_Brick_Half",
      "rotation": 7
    },
    {
      "x": -12,
      "y": 10,
      "z": -11,
      "name": "Rock_Sandstone_Brick_Half",
      "rotation": 7
    },
    {
      "x": -12,
      "y": 11,
      "z": -11,
      "name": "Rock_Sandstone_Brick_Half",
      "rotation": 7
    },
    {
      "x": -12,
      "y": 12,
      "z": -11,
      "name": "Rock_Sandstone_Brick_Half",
      "rotation": 7
    },
    {
      "x": -12,
      "y": 13,
      "z": -11,
      "name": "Rock_Sandstone_Brick_Half",
      "rotation": 7
    },
    {
      "x": -12,
      "y": 14,
      "z": -11,
      "name": "Rock_Sandstone_Brick_Half",
      "rotation": 7
    },
    {
      "x": -12,
      "y": 15,
      "z": -11,
      "name": "Rock_Sandstone_Brick_Half",
      "rotation": 7
    },
    {
      "x": -12,
      "y": 16,
      "z": -11,
      "name": "Rock_Sandstone_Brick_Half",
      "rotation": 7
    },
    {
      "x": -12,
      "y": 17,
      "z": -11,
      "name": "Rock_Sandstone_Brick_Half",
      "rotation": 7
    },
    {
      "x": -12,
      "y": 18,
      "z": -11,
      "name": "Rock_Sandstone_Brick_Half",
      "rotation": 7
    },
    {
      "x": -12,
      "y": 19,
      "z": -11,
      "name": "Rock_Sandstone_Brick_Half",
      "rotation": 7
    },
    {
      "x": -12,
      "y": 20,
      "z": -11,
      "name": "Rock_Sandstone_Brick_Stairs",
      "rotation": 9
    },
    {
      "x": -12,
      "y": 21,
      "z": -11,
      "name": "Rock_Sandstone_Brick_Half",
      "rotation": 7
    },
    {
      "x": -12,
      "y": 22,
      "z": -11,
      "name": "Rock_Sandstone_Brick_Stairs",
      "rotation": 9
    },
    {
      "x": -12,
      "y": 23,
      "z": -11,
      "name": "Rock_Sandstone_Brick_Half",
      "rotation": 7
    },
    {
      "x": -12,
      "y": 24,
      "z": -11,
      "name": "Rock_Sandstone_Brick_Half",
      "rotation": 7
    },
    {
      "x": -12,
      "y": 25,
      "z": -11,
      "name": "Rock_Sandstone_Brick_Stairs",
      "rotation": 9
    },
    {
      "x": -12,
      "y": 20,
      "z": -10,
      "name": "Rock_Sandstone_Brick_Half",
      "rotation": 8
    },
    {
      "x": -12,
      "y": 22,
      "z": -10,
      "name": "Rock_Sandstone_Brick_Stairs",
      "rotation": 9
    },
    {
      "x": -12,
      "y": 25,
      "z": -10,
      "name": "Rock_Sandstone_Brick_Stairs",
      "rotation": 9
    },
    {
      "x": -12,
      "y": -10,
      "z": -9,
      "name": "Rock_Sandstone_Brick_Half",
      "rotation": 7
    },
    {
      "x": -12,
      "y": -9,
      "z": -9,
      "name": "Rock_Sandstone_Brick_Half",
      "rotation": 7
    },
    {
      "x": -12,
      "y": -8,
      "z": -9,
      "name": "Rock_Sandstone_Brick_Half",
      "rotation": 7
    },
    {
      "x": -12,
      "y": -7,
      "z": -9,
      "name": "Rock_Sandstone_Brick_Half",
      "rotation": 7
    },
    {
      "x": -12,
      "y": -6,
      "z": -9,
      "name": "Rock_Sandstone_Brick_Half",
      "rotation": 7
    },
    {
      "x": -12,
      "y": -5,
      "z": -9,
      "name": "Rock_Sandstone_Brick_Half",
      "rotation": 7
    },
    {
      "x": -12,
      "y": -4,
      "z": -9,
      "name": "Rock_Sandstone_Brick_Half",
      "rotation": 7
    },
    {
      "x": -12,
      "y": -3,
      "z": -9,
      "name": "Rock_Sandstone_Brick_Half",
      "rotation": 7
    },
    {
      "x": -12,
      "y": -2,
      "z": -9,
      "name": "Rock_Sandstone_Brick_Half",
      "rotation": 7
    },
    {
      "x": -12,
      "y": -1,
      "z": -9,
      "name": "Rock_Sandstone_Brick_Half",
      "rotation": 7
    },
    {
      "x": -12,
      "y": 0,
      "z": -9,
      "name": "Rock_Sandstone_Brick_Half",
      "rotation": 7
    },
    {
      "x": -12,
      "y": 1,
      "z": -9,
      "name": "Rock_Sandstone_Brick_Half",
      "rotation": 7
    },
    {
      "x": -12,
      "y": 2,
      "z": -9,
      "name": "Rock_Sandstone_Brick_Half",
      "rotation": 7
    },
    {
      "x": -12,
      "y": 3,
      "z": -9,
      "name": "Rock_Sandstone_Brick_Half",
      "rotation": 7
    },
    {
      "x": -12,
      "y": 4,
      "z": -9,
      "name": "Rock_Sandstone_Brick_Half",
      "rotation": 7
    },
    {
      "x": -12,
      "y": 5,
      "z": -9,
      "name": "Rock_Sandstone_Brick_Half",
      "rotation": 7
    },
    {
      "x": -12,
      "y": 6,
      "z": -9,
      "name": "Rock_Sandstone_Brick_Half",
      "rotation": 7
    },
    {
      "x": -12,
      "y": 7,
      "z": -9,
      "name": "Rock_Sandstone_Brick_Half",
      "rotation": 7
    },
    {
      "x": -12,
      "y": 8,
      "z": -9,
      "name": "Rock_Sandstone_Brick_Half",
      "rotation": 7
    },
    {
      "x": -12,
      "y": 9,
      "z": -9,
      "name": "Rock_Sandstone_Brick_Half",
      "rotation": 7
    },
    {
      "x": -12,
      "y": 10,
      "z": -9,
      "name": "Rock_Sandstone_Brick_Half",
      "rotation": 7
    },
    {
      "x": -12,
      "y": 11,
      "z": -9,
      "name": "Rock_Sandstone_Brick_Half",
      "rotation": 7
    },
    {
      "x": -12,
      "y": 12,
      "z": -9,
      "name": "Rock_Sandstone_Brick_Half",
      "rotation": 7
    },
    {
      "x": -12,
      "y": 13,
      "z": -9,
      "name": "Rock_Sandstone_Brick_Half",
      "rotation": 7
    },
    {
      "x": -12,
      "y": 14,
      "z": -9,
      "name": "Rock_Sandstone_Brick_Half",
      "rotation": 7
    },
    {
      "x": -12,
      "y": 15,
      "z": -9,
      "name": "Rock_Sandstone_Brick_Half",
      "rotation": 7
    },
    {
      "x": -12,
      "y": 16,
      "z": -9,
      "name": "Rock_Sandstone_Brick_Half",
      "rotation": 7
    },
    {
      "x": -12,
      "y": 17,
      "z": -9,
      "name": "Rock_Sandstone_Brick_Half",
      "rotation": 7
    },
    {
      "x": -12,
      "y": 18,
      "z": -9,
      "name": "Rock_Sandstone_Brick_Half",
      "rotation": 7
    },
    {
      "x": -12,
      "y": 19,
      "z": -9,
      "name": "Rock_Sandstone_Brick_Half",
      "rotation": 7
    },
    {
      "x": -12,
      "y": 20,
      "z": -9,
      "name": "Rock_Sandstone_Brick_Stairs",
      "rotation": 9
    },
    {
      "x": -12,
      "y": 21,
      "z": -9,
      "name": "Rock_Sandstone_Brick_Half",
      "rotation": 7
    },
    {
      "x": -12,
      "y": 22,
      "z": -9,
      "name": "Rock_Sandstone_Brick_Stairs",
      "rotation": 9
    },
    {
      "x": -12,
      "y": 23,
      "z": -9,
      "name": "Rock_Sandstone_Brick_Half",
      "rotation": 7
    },
    {
      "x": -12,
      "y": 24,
      "z": -9,
      "name": "Rock_Sandstone_Brick_Half",
      "rotation": 7
    },
    {
      "x": -12,
      "y": 25,
      "z": -9,
      "name": "Rock_Sandstone_Brick_Stairs",
      "rotation": 9
    },
    {
      "x": -12,
      "y": 20,
      "z": -8,
      "name": "*Rock_Sandstone_Brick_Stairs_State_Definitions_Corner_Left",
      "rotation": 10
    },
    {
      "x": -12,
      "y": 22,
      "z": -8,
      "name": "*Rock_Sandstone_Brick_Stairs_State_Definitions_Corner_Left",
      "rotation": 10
    },
    {
      "x": -12,
      "y": 25,
      "z": -8,
      "name": "Rock_Sandstone_Brick_Stairs",
      "rotation": 9
    },
    {
      "x": -12,
      "y": 25,
      "z": -7,
      "name": "Rock_Sandstone_Brick_Stairs",
      "rotation": 9
    },
    {
      "x": -12,
      "y": 25,
      "z": -6,
      "name": "Rock_Sandstone_Brick_Stairs",
      "rotation": 9
    },
    {
      "x": -12,
      "y": 25,
      "z": -5,
      "name": "Rock_Sandstone_Brick_Stairs",
      "rotation": 9
    },
    {
      "x": -12,
      "y": 25,
      "z": -4,
      "name": "Rock_Sandstone_Brick_Stairs",
      "rotation": 9
    },
    {
      "x": -12,
      "y": 25,
      "z": -3,
      "name": "Rock_Sandstone_Brick_Stairs",
      "rotation": 9
    },
    {
      "x": -12,
      "y": 25,
      "z": -2,
      "name": "Rock_Sandstone_Brick_Stairs",
      "rotation": 9
    },
    {
      "x": -12,
      "y": 25,
      "z": -1,
      "name": "Rock_Sandstone_Brick_Stairs",
      "rotation": 9
    },
    {
      "x": -12,
      "y": 25,
      "z": 0,
      "name": "Rock_Sandstone_Brick_Stairs",
      "rotation": 9
    },
    {
      "x": -12,
      "y": 25,
      "z": 1,
      "name": "Rock_Sandstone_Brick_Stairs",
      "rotation": 9
    },
    {
      "x": -12,
      "y": 25,
      "z": 2,
      "name": "Rock_Sandstone_Brick_Stairs",
      "rotation": 9
    },
    {
      "x": -12,
      "y": 25,
      "z": 3,
      "name": "Rock_Sandstone_Brick_Stairs",
      "rotation": 9
    },
    {
      "x": -12,
      "y": 25,
      "z": 4,
      "name": "Rock_Sandstone_Brick_Stairs",
      "rotation": 9
    },
    {
      "x": -12,
      "y": 25,
      "z": 5,
      "name": "Rock_Sandstone_Brick_Stairs",
      "rotation": 9
    },
    {
      "x": -12,
      "y": 25,
      "z": 6,
      "name": "Rock_Sandstone_Brick_Stairs",
      "rotation": 9
    },
    {
      "x": -12,
      "y": 25,
      "z": 7,
      "name": "Rock_Sandstone_Brick_Stairs",
      "rotation": 9
    },
    {
      "x": -12,
      "y": 25,
      "z": 8,
      "name": "Rock_Sandstone_Brick_Stairs",
      "rotation": 9
    },
    {
      "x": -12,
      "y": 20,
      "z": 9,
      "name": "*Rock_Sandstone_Brick_Stairs_State_Definitions_Corner_Right",
      "rotation": 8
    },
    {
      "x": -12,
      "y": 22,
      "z": 9,
      "name": "*Rock_Sandstone_Brick_Stairs_State_Definitions_Corner_Right",
      "rotation": 8
    },
    {
      "x": -12,
      "y": 25,
      "z": 9,
      "name": "Rock_Sandstone_Brick_Stairs",
      "rotation": 9
    },
    {
      "x": -12,
      "y": -10,
      "z": 10,
      "name": "Rock_Sandstone_Brick_Half",
      "rotation": 7
    },
    {
      "x": -12,
      "y": -9,
      "z": 10,
      "name": "Rock_Sandstone_Brick_Half",
      "rotation": 7
    },
    {
      "x": -12,
      "y": -8,
      "z": 10,
      "name": "Rock_Sandstone_Brick_Half",
      "rotation": 7
    },
    {
      "x": -12,
      "y": -7,
      "z": 10,
      "name": "Rock_Sandstone_Brick_Half",
      "rotation": 7
    },
    {
      "x": -12,
      "y": -6,
      "z": 10,
      "name": "Rock_Sandstone_Brick_Half",
      "rotation": 7
    },
    {
      "x": -12,
      "y": -5,
      "z": 10,
      "name": "Rock_Sandstone_Brick_Half",
      "rotation": 7
    },
    {
      "x": -12,
      "y": -4,
      "z": 10,
      "name": "Rock_Sandstone_Brick_Half",
      "rotation": 7
    },
    {
      "x": -12,
      "y": -3,
      "z": 10,
      "name": "Rock_Sandstone_Brick_Half",
      "rotation": 7
    },
    {
      "x": -12,
      "y": -2,
      "z": 10,
      "name": "Rock_Sandstone_Brick_Half",
      "rotation": 7
    },
    {
      "x": -12,
      "y": -1,
      "z": 10,
      "name": "Rock_Sandstone_Brick_Half",
      "rotation": 7
    },
    {
      "x": -12,
      "y": 0,
      "z": 10,
      "name": "Rock_Sandstone_Brick_Half",
      "rotation": 7
    },
    {
      "x": -12,
      "y": 1,
      "z": 10,
      "name": "Rock_Sandstone_Brick_Half",
      "rotation": 7
    },
    {
      "x": -12,
      "y": 2,
      "z": 10,
      "name": "Rock_Sandstone_Brick_Half",
      "rotation": 7
    },
    {
      "x": -12,
      "y": 3,
      "z": 10,
      "name": "Rock_Sandstone_Brick_Half",
      "rotation": 7
    },
    {
      "x": -12,
      "y": 4,
      "z": 10,
      "name": "Rock_Sandstone_Brick_Half",
      "rotation": 7
    },
    {
      "x": -12,
      "y": 5,
      "z": 10,
      "name": "Rock_Sandstone_Brick_Half",
      "rotation": 7
    },
    {
      "x": -12,
      "y": 6,
      "z": 10,
      "name": "Rock_Sandstone_Brick_Half",
      "rotation": 7
    },
    {
      "x": -12,
      "y": 7,
      "z": 10,
      "name": "Rock_Sandstone_Brick_Half",
      "rotation": 7
    },
    {
      "x": -12,
      "y": 8,
      "z": 10,
      "name": "Rock_Sandstone_Brick_Half",
      "rotation": 7
    },
    {
      "x": -12,
      "y": 9,
      "z": 10,
      "name": "Rock_Sandstone_Brick_Half",
      "rotation": 7
    },
    {
      "x": -12,
      "y": 10,
      "z": 10,
      "name": "Rock_Sandstone_Brick_Half",
      "rotation": 7
    },
    {
      "x": -12,
      "y": 11,
      "z": 10,
      "name": "Rock_Sandstone_Brick_Half",
      "rotation": 7
    },
    {
      "x": -12,
      "y": 12,
      "z": 10,
      "name": "Rock_Sandstone_Brick_Half",
      "rotation": 7
    },
    {
      "x": -12,
      "y": 13,
      "z": 10,
      "name": "Rock_Sandstone_Brick_Half",
      "rotation": 7
    },
    {
      "x": -12,
      "y": 14,
      "z": 10,
      "name": "Rock_Sandstone_Brick_Half",
      "rotation": 7
    },
    {
      "x": -12,
      "y": 15,
      "z": 10,
      "name": "Rock_Sandstone_Brick_Half",
      "rotation": 7
    },
    {
      "x": -12,
      "y": 16,
      "z": 10,
      "name": "Rock_Sandstone_Brick_Half",
      "rotation": 7
    },
    {
      "x": -12,
      "y": 17,
      "z": 10,
      "name": "Rock_Sandstone_Brick_Half",
      "rotation": 7
    },
    {
      "x": -12,
      "y": 18,
      "z": 10,
      "name": "Rock_Sandstone_Brick_Half",
      "rotation": 7
    },
    {
      "x": -12,
      "y": 19,
      "z": 10,
      "name": "Rock_Sandstone_Brick_Half",
      "rotation": 7
    },
    {
      "x": -12,
      "y": 20,
      "z": 10,
      "name": "Rock_Sandstone_Brick_Stairs",
      "rotation": 9
    },
    {
      "x": -12,
      "y": 21,
      "z": 10,
      "name": "Rock_Sandstone_Brick_Half",
      "rotation": 7
    },
    {
      "x": -12,
      "y": 22,
      "z": 10,
      "name": "Rock_Sandstone_Brick_Stairs",
      "rotation": 9
    },
    {
      "x": -12,
      "y": 23,
      "z": 10,
      "name": "Rock_Sandstone_Brick_Half",
      "rotation": 7
    },
    {
      "x": -12,
      "y": 24,
      "z": 10,
      "name": "Rock_Sandstone_Brick_Half",
      "rotation": 7
    },
    {
      "x": -12,
      "y": 25,
      "z": 10,
      "name": "Rock_Sandstone_Brick_Stairs",
      "rotation": 9
    },
    {
      "x": -12,
      "y": 20,
      "z": 11,
      "name": "Rock_Sandstone_Brick_Half",
      "rotation": 9
    },
    {
      "x": -12,
      "y": 22,
      "z": 11,
      "name": "Rock_Sandstone_Brick_Stairs",
      "rotation": 9
    },
    {
      "x": -12,
      "y": 25,
      "z": 11,
      "name": "Rock_Sandstone_Brick_Stairs",
      "rotation": 9
    },
    {
      "x": -12,
      "y": -10,
      "z": 12,
      "name": "Rock_Sandstone_Brick_Half",
      "rotation": 7
    },
    {
      "x": -12,
      "y": -9,
      "z": 12,
      "name": "Rock_Sandstone_Brick_Half",
      "rotation": 7
    },
    {
      "x": -12,
      "y": -8,
      "z": 12,
      "name": "Rock_Sandstone_Brick_Half",
      "rotation": 7
    },
    {
      "x": -12,
      "y": -7,
      "z": 12,
      "name": "Rock_Sandstone_Brick_Half",
      "rotation": 7
    },
    {
      "x": -12,
      "y": -6,
      "z": 12,
      "name": "Rock_Sandstone_Brick_Half",
      "rotation": 7
    },
    {
      "x": -12,
      "y": -5,
      "z": 12,
      "name": "Rock_Sandstone_Brick_Half",
      "rotation": 7
    },
    {
      "x": -12,
      "y": -4,
      "z": 12,
      "name": "Rock_Sandstone_Brick_Half",
      "rotation": 7
    },
    {
      "x": -12,
      "y": -3,
      "z": 12,
      "name": "Rock_Sandstone_Brick_Half",
      "rotation": 7
    },
    {
      "x": -12,
      "y": -2,
      "z": 12,
      "name": "Rock_Sandstone_Brick_Half",
      "rotation": 7
    },
    {
      "x": -12,
      "y": -1,
      "z": 12,
      "name": "Rock_Sandstone_Brick_Half",
      "rotation": 7
    },
    {
      "x": -12,
      "y": 0,
      "z": 12,
      "name": "Rock_Sandstone_Brick_Half",
      "rotation": 7
    },
    {
      "x": -12,
      "y": 1,
      "z": 12,
      "name": "Rock_Sandstone_Brick_Half",
      "rotation": 7
    },
    {
      "x": -12,
      "y": 2,
      "z": 12,
      "name": "Rock_Sandstone_Brick_Half",
      "rotation": 7
    },
    {
      "x": -12,
      "y": 3,
      "z": 12,
      "name": "Rock_Sandstone_Brick_Half",
      "rotation": 7
    },
    {
      "x": -12,
      "y": 4,
      "z": 12,
      "name": "Rock_Sandstone_Brick_Half",
      "rotation": 7
    },
    {
      "x": -12,
      "y": 5,
      "z": 12,
      "name": "Rock_Sandstone_Brick_Half",
      "rotation": 7
    },
    {
      "x": -12,
      "y": 6,
      "z": 12,
      "name": "Rock_Sandstone_Brick_Half",
      "rotation": 7
    },
    {
      "x": -12,
      "y": 7,
      "z": 12,
      "name": "Rock_Sandstone_Brick_Half",
      "rotation": 7
    },
    {
      "x": -12,
      "y": 8,
      "z": 12,
      "name": "Rock_Sandstone_Brick_Half",
      "rotation": 7
    },
    {
      "x": -12,
      "y": 9,
      "z": 12,
      "name": "Rock_Sandstone_Brick_Half",
      "rotation": 7
    },
    {
      "x": -12,
      "y": 10,
      "z": 12,
      "name": "Rock_Sandstone_Brick_Half",
      "rotation": 7
    },
    {
      "x": -12,
      "y": 11,
      "z": 12,
      "name": "Rock_Sandstone_Brick_Half",
      "rotation": 7
    },
    {
      "x": -12,
      "y": 12,
      "z": 12,
      "name": "Rock_Sandstone_Brick_Half",
      "rotation": 7
    },
    {
      "x": -12,
      "y": 13,
      "z": 12,
      "name": "Rock_Sandstone_Brick_Half",
      "rotation": 7
    },
    {
      "x": -12,
      "y": 14,
      "z": 12,
      "name": "Rock_Sandstone_Brick_Half",
      "rotation": 7
    },
    {
      "x": -12,
      "y": 15,
      "z": 12,
      "name": "Rock_Sandstone_Brick_Half",
      "rotation": 7
    },
    {
      "x": -12,
      "y": 16,
      "z": 12,
      "name": "Rock_Sandstone_Brick_Half",
      "rotation": 7
    },
    {
      "x": -12,
      "y": 17,
      "z": 12,
      "name": "Rock_Sandstone_Brick_Half",
      "rotation": 7
    },
    {
      "x": -12,
      "y": 18,
      "z": 12,
      "name": "Rock_Sandstone_Brick_Half",
      "rotation": 7
    },
    {
      "x": -12,
      "y": 19,
      "z": 12,
      "name": "Rock_Sandstone_Brick_Half",
      "rotation": 7
    },
    {
      "x": -12,
      "y": 20,
      "z": 12,
      "name": "Rock_Sandstone_Brick_Stairs",
      "rotation": 9
    },
    {
      "x": -12,
      "y": 21,
      "z": 12,
      "name": "Rock_Sandstone_Brick_Half",
      "rotation": 7
    },
    {
      "x": -12,
      "y": 22,
      "z": 12,
      "name": "Rock_Sandstone_Brick_Stairs",
      "rotation": 9
    },
    {
      "x": -12,
      "y": 23,
      "z": 12,
      "name": "Rock_Sandstone_Brick_Half",
      "rotation": 7
    },
    {
      "x": -12,
      "y": 24,
      "z": 12,
      "name": "Rock_Sandstone_Brick_Half",
      "rotation": 7
    },
    {
      "x": -12,
      "y": 25,
      "z": 12,
      "name": "Rock_Sandstone_Brick_Stairs",
      "rotation": 9
    },
    {
      "x": -12,
      "y": 20,
      "z": 13,
      "name": "*Rock_Sandstone_Brick_Stairs_State_Definitions_Corner_Left",
      "rotation": 10
    },
    {
      "x": -12,
      "y": 22,
      "z": 13,
      "name": "*Rock_Sandstone_Brick_Stairs_State_Definitions_Corner_Left",
      "rotation": 10
    },
    {
      "x": -12,
      "y": 25,
      "z": 13,
      "name": "*Rock_Sandstone_Brick_Stairs_State_Definitions_Corner_Right",
      "rotation": 9
    },
    {
      "x": -11,
      "y": -10,
      "z": -12,
      "name": "Rock_Sandstone_Brick_Half",
      "rotation": 6
    },
    {
      "x": -11,
      "y": -9,
      "z": -12,
      "name": "Rock_Sandstone_Brick_Half",
      "rotation": 6
    },
    {
      "x": -11,
      "y": -8,
      "z": -12,
      "name": "Rock_Sandstone_Brick_Half",
      "rotation": 6
    },
    {
      "x": -11,
      "y": -7,
      "z": -12,
      "name": "Rock_Sandstone_Brick_Half",
      "rotation": 6
    },
    {
      "x": -11,
      "y": -6,
      "z": -12,
      "name": "Rock_Sandstone_Brick_Half",
      "rotation": 6
    },
    {
      "x": -11,
      "y": -5,
      "z": -12,
      "name": "Rock_Sandstone_Brick_Half",
      "rotation": 6
    },
    {
      "x": -11,
      "y": -4,
      "z": -12,
      "name": "Rock_Sandstone_Brick_Half",
      "rotation": 6
    },
    {
      "x": -11,
      "y": -3,
      "z": -12,
      "name": "Rock_Sandstone_Brick_Half",
      "rotation": 6
    },
    {
      "x": -11,
      "y": -2,
      "z": -12,
      "name": "Rock_Sandstone_Brick_Half",
      "rotation": 6
    },
    {
      "x": -11,
      "y": -1,
      "z": -12,
      "name": "Rock_Sandstone_Brick_Half",
      "rotation": 6
    },
    {
      "x": -11,
      "y": 0,
      "z": -12,
      "name": "Rock_Sandstone_Brick_Half",
      "rotation": 6
    },
    {
      "x": -11,
      "y": 1,
      "z": -12,
      "name": "Rock_Sandstone_Brick_Half",
      "rotation": 6
    },
    {
      "x": -11,
      "y": 2,
      "z": -12,
      "name": "Rock_Sandstone_Brick_Half",
      "rotation": 6
    },
    {
      "x": -11,
      "y": 3,
      "z": -12,
      "name": "Rock_Sandstone_Brick_Half",
      "rotation": 6
    },
    {
      "x": -11,
      "y": 4,
      "z": -12,
      "name": "Rock_Sandstone_Brick_Half",
      "rotation": 6
    },
    {
      "x": -11,
      "y": 5,
      "z": -12,
      "name": "Rock_Sandstone_Brick_Half",
      "rotation": 6
    },
    {
      "x": -11,
      "y": 6,
      "z": -12,
      "name": "Rock_Sandstone_Brick_Half",
      "rotation": 6
    },
    {
      "x": -11,
      "y": 7,
      "z": -12,
      "name": "Rock_Sandstone_Brick_Half",
      "rotation": 6
    },
    {
      "x": -11,
      "y": 8,
      "z": -12,
      "name": "Rock_Sandstone_Brick_Half",
      "rotation": 6
    },
    {
      "x": -11,
      "y": 9,
      "z": -12,
      "name": "Rock_Sandstone_Brick_Half",
      "rotation": 6
    },
    {
      "x": -11,
      "y": 10,
      "z": -12,
      "name": "Rock_Sandstone_Brick_Half",
      "rotation": 6
    },
    {
      "x": -11,
      "y": 11,
      "z": -12,
      "name": "Rock_Sandstone_Brick_Half",
      "rotation": 6
    },
    {
      "x": -11,
      "y": 12,
      "z": -12,
      "name": "Rock_Sandstone_Brick_Half",
      "rotation": 6
    },
    {
      "x": -11,
      "y": 13,
      "z": -12,
      "name": "Rock_Sandstone_Brick_Half",
      "rotation": 6
    },
    {
      "x": -11,
      "y": 14,
      "z": -12,
      "name": "Rock_Sandstone_Brick_Half",
      "rotation": 6
    },
    {
      "x": -11,
      "y": 15,
      "z": -12,
      "name": "Rock_Sandstone_Brick_Half",
      "rotation": 6
    },
    {
      "x": -11,
      "y": 16,
      "z": -12,
      "name": "Rock_Sandstone_Brick_Half",
      "rotation": 6
    },
    {
      "x": -11,
      "y": 17,
      "z": -12,
      "name": "Rock_Sandstone_Brick_Half",
      "rotation": 6
    },
    {
      "x": -11,
      "y": 18,
      "z": -12,
      "name": "Rock_Sandstone_Brick_Half",
      "rotation": 6
    },
    {
      "x": -11,
      "y": 19,
      "z": -12,
      "name": "Rock_Sandstone_Brick_Half",
      "rotation": 6
    },
    {
      "x": -11,
      "y": 20,
      "z": -12,
      "name": "Rock_Sandstone_Brick_Stairs",
      "rotation": 8
    },
    {
      "x": -11,
      "y": 21,
      "z": -12,
      "name": "Rock_Sandstone_Brick_Half",
      "rotation": 6
    },
    {
      "x": -11,
      "y": 22,
      "z": -12,
      "name": "Rock_Sandstone_Brick_Stairs",
      "rotation": 8
    },
    {
      "x": -11,
      "y": 23,
      "z": -12,
      "name": "Rock_Sandstone_Brick_Half",
      "rotation": 6
    },
    {
      "x": -11,
      "y": 24,
      "z": -12,
      "name": "Rock_Sandstone_Brick_Half",
      "rotation": 6
    },
    {
      "x": -11,
      "y": 25,
      "z": -12,
      "name": "Rock_Sandstone_Brick_Stairs",
      "rotation": 8
    },
    {
      "x": -11,
      "y": -10,
      "z": -11,
      "name": "Rock_Sandstone_Brick"
    },
    {
      "x": -11,
      "y": -9,
      "z": -11,
      "name": "Rock_Sandstone_Brick"
    },
    {
      "x": -11,
      "y": -8,
      "z": -11,
      "name": "Rock_Sandstone_Cobble"
    },
    {
      "x": -11,
      "y": -7,
      "z": -11,
      "name": "Rock_Sandstone_Brick"
    },
    {
      "x": -11,
      "y": -6,
      "z": -11,
      "name": "Rock_Sandstone_Brick"
    },
    {
      "x": -11,
      "y": -5,
      "z": -11,
      "name": "Rock_Sandstone_Brick"
    },
    {
      "x": -11,
      "y": -4,
      "z": -11,
      "name": "Rock_Sandstone_Brick"
    },
    {
      "x": -11,
      "y": -3,
      "z": -11,
      "name": "Rock_Sandstone"
    },
    {
      "x": -11,
      "y": -2,
      "z": -11,
      "name": "Rock_Sandstone_Cobble"
    },
    {
      "x": -11,
      "y": -1,
      "z": -11,
      "name": "Rock_Sandstone_Brick"
    },
    {
      "x": -11,
      "y": 0,
      "z": -11,
      "name": "Rock_Sandstone_Brick"
    },
    {
      "x": -11,
      "y": 1,
      "z": -11,
      "name": "Rock_Sandstone",
      "rotation": 3
    },
    {
      "x": -11,
      "y": 2,
      "z": -11,
      "name": "Rock_Sandstone",
      "rotation": 3
    },
    {
      "x": -11,
      "y": 3,
      "z": -11,
      "name": "Rock_Sandstone_Cobble",
      "rotation": 3
    },
    {
      "x": -11,
      "y": 4,
      "z": -11,
      "name": "Rock_Sandstone",
      "rotation": 3
    },
    {
      "x": -11,
      "y": 5,
      "z": -11,
      "name": "Rock_Sandstone_Brick",
      "rotation": 3
    },
    {
      "x": -11,
      "y": 6,
      "z": -11,
      "name": "Rock_Sandstone",
      "rotation": 3
    },
    {
      "x": -11,
      "y": 7,
      "z": -11,
      "name": "Rock_Sandstone_Brick",
      "rotation": 3
    },
    {
      "x": -11,
      "y": 8,
      "z": -11,
      "name": "Rock_Sandstone",
      "rotation": 3
    },
    {
      "x": -11,
      "y": 9,
      "z": -11,
      "name": "Rock_Sandstone_Brick",
      "rotation": 3
    },
    {
      "x": -11,
      "y": 10,
      "z": -11,
      "name": "Rock_Sandstone_Brick",
      "rotation": 3
    },
    {
      "x": -11,
      "y": 11,
      "z": -11,
      "name": "Rock_Sandstone_Brick",
      "rotation": 3
    },
    {
      "x": -11,
      "y": 12,
      "z": -11,
      "name": "Rock_Sandstone_Brick",
      "rotation": 3
    },
    {
      "x": -11,
      "y": 13,
      "z": -11,
      "name": "Rock_Sandstone_Cobble",
      "rotation": 3
    },
    {
      "x": -11,
      "y": 14,
      "z": -11,
      "name": "Rock_Sandstone",
      "rotation": 3
    },
    {
      "x": -11,
      "y": 15,
      "z": -11,
      "name": "Rock_Sandstone_Cobble",
      "rotation": 3
    },
    {
      "x": -11,
      "y": 16,
      "z": -11,
      "name": "Rock_Sandstone",
      "rotation": 3
    },
    {
      "x": -11,
      "y": 17,
      "z": -11,
      "name": "Rock_Sandstone_Brick",
      "rotation": 3
    },
    {
      "x": -11,
      "y": 18,
      "z": -11,
      "name": "Rock_Sandstone_Brick",
      "rotation": 3
    },
    {
      "x": -11,
      "y": 19,
      "z": -11,
      "name": "Rock_Sandstone_Brick",
      "rotation": 3
    },
    {
      "x": -11,
      "y": 20,
      "z": -11,
      "name": "Rock_Sandstone_Brick",
      "rotation": 3
    },
    {
      "x": -11,
      "y": 21,
      "z": -11,
      "name": "Rock_Sandstone_Brick",
      "rotation": 3
    },
    {
      "x": -11,
      "y": 22,
      "z": -11,
      "name": "Rock_Sandstone_Brick",
      "rotation": 3
    },
    {
      "x": -11,
      "y": 23,
      "z": -11,
      "name": "Rock_Sandstone_Brick",
      "rotation": 3
    },
    {
      "x": -11,
      "y": 24,
      "z": -11,
      "name": "Rock_Sandstone_Brick",
      "rotation": 3
    },
    {
      "x": -11,
      "y": 25,
      "z": -11,
      "name": "Rock_Sandstone_Brick"
    },
    {
      "x": -11,
      "y": -10,
      "z": -10,
      "name": "Rock_Sandstone_Cobble"
    },
    {
      "x": -11,
      "y": -9,
      "z": -10,
      "name": "Rock_Sandstone_Cobble"
    },
    {
      "x": -11,
      "y": -8,
      "z": -10,
      "name": "Rock_Sandstone_Cobble"
    },
    {
      "x": -11,
      "y": -7,
      "z": -10,
      "name": "Rock_Sandstone_Cobble"
    },
    {
      "x": -11,
      "y": -6,
      "z": -10,
      "name": "Rock_Sandstone_Cobble"
    },
    {
      "x": -11,
      "y": -5,
      "z": -10,
      "name": "Rock_Sandstone_Cobble"
    },
    {
      "x": -11,
      "y": -4,
      "z": -10,
      "name": "Rock_Sandstone_Cobble"
    },
    {
      "x": -11,
      "y": -3,
      "z": -10,
      "name": "Rock_Sandstone_Cobble"
    },
    {
      "x": -11,
      "y": -2,
      "z": -10,
      "name": "Rock_Sandstone_Cobble"
    },
    {
      "x": -11,
      "y": -1,
      "z": -10,
      "name": "Rock_Sandstone_Cobble"
    },
    {
      "x": -11,
      "y": 0,
      "z": -10,
      "name": "Rock_Sandstone_Cobble"
    },
    {
      "x": -11,
      "y": 1,
      "z": -10,
      "name": "Rock_Sandstone_Cobble"
    },
    {
      "x": -11,
      "y": 2,
      "z": -10,
      "name": "Rock_Sandstone_Cobble"
    },
    {
      "x": -11,
      "y": 3,
      "z": -10,
      "name": "Rock_Sandstone_Cobble"
    },
    {
      "x": -11,
      "y": 4,
      "z": -10,
      "name": "Rock_Sandstone_Cobble"
    },
    {
      "x": -11,
      "y": 5,
      "z": -10,
      "name": "Rock_Sandstone_Cobble"
    },
    {
      "x": -11,
      "y": 6,
      "z": -10,
      "name": "Rock_Sandstone_Cobble"
    },
    {
      "x": -11,
      "y": 7,
      "z": -10,
      "name": "Rock_Sandstone_Cobble"
    },
    {
      "x": -11,
      "y": 8,
      "z": -10,
      "name": "Rock_Sandstone_Cobble"
    },
    {
      "x": -11,
      "y": 9,
      "z": -10,
      "name": "Rock_Sandstone_Cobble"
    },
    {
      "x": -11,
      "y": 10,
      "z": -10,
      "name": "Rock_Sandstone_Cobble"
    },
    {
      "x": -11,
      "y": 11,
      "z": -10,
      "name": "Rock_Sandstone_Cobble"
    },
    {
      "x": -11,
      "y": 12,
      "z": -10,
      "name": "Rock_Sandstone_Cobble"
    },
    {
      "x": -11,
      "y": 13,
      "z": -10,
      "name": "Rock_Sandstone_Cobble"
    },
    {
      "x": -11,
      "y": 14,
      "z": -10,
      "name": "Rock_Sandstone_Cobble"
    },
    {
      "x": -11,
      "y": 15,
      "z": -10,
      "name": "Rock_Sandstone_Cobble"
    },
    {
      "x": -11,
      "y": 16,
      "z": -10,
      "name": "Rock_Sandstone_Cobble"
    },
    {
      "x": -11,
      "y": 17,
      "z": -10,
      "name": "Rock_Sandstone_Cobble"
    },
    {
      "x": -11,
      "y": 18,
      "z": -10,
      "name": "Rock_Sandstone_Cobble"
    },
    {
      "x": -11,
      "y": 19,
      "z": -10,
      "name": "Rock_Sandstone_Cobble"
    },
    {
      "x": -11,
      "y": 20,
      "z": -10,
      "name": "Rock_Sandstone_Cobble"
    },
    {
      "x": -11,
      "y": 21,
      "z": -10,
      "name": "Rock_Sandstone_Cobble"
    },
    {
      "x": -11,
      "y": 22,
      "z": -10,
      "name": "Rock_Sandstone_Cobble"
    },
    {
      "x": -11,
      "y": 23,
      "z": -10,
      "name": "Rock_Sandstone_Cobble"
    },
    {
      "x": -11,
      "y": 24,
      "z": -10,
      "name": "Rock_Sandstone_Cobble"
    },
    {
      "x": -11,
      "y": 25,
      "z": -10,
      "name": "Rock_Sandstone_Brick"
    },
    {
      "x": -11,
      "y": -10,
      "z": -9,
      "name": "Rock_Sandstone_Brick"
    },
    {
      "x": -11,
      "y": -9,
      "z": -9,
      "name": "Rock_Sandstone_Brick"
    },
    {
      "x": -11,
      "y": -8,
      "z": -9,
      "name": "Rock_Sandstone_Cobble"
    },
    {
      "x": -11,
      "y": -7,
      "z": -9,
      "name": "Rock_Sandstone"
    },
    {
      "x": -11,
      "y": -6,
      "z": -9,
      "name": "Rock_Sandstone_Brick"
    },
    {
      "x": -11,
      "y": -5,
      "z": -9,
      "name": "Rock_Sandstone_Cobble"
    },
    {
      "x": -11,
      "y": -4,
      "z": -9,
      "name": "Rock_Sandstone"
    },
    {
      "x": -11,
      "y": -3,
      "z": -9,
      "name": "Rock_Sandstone"
    },
    {
      "x": -11,
      "y": -2,
      "z": -9,
      "name": "Rock_Sandstone"
    },
    {
      "x": -11,
      "y": -1,
      "z": -9,
      "name": "Rock_Sandstone_Brick"
    },
    {
      "x": -11,
      "y": 0,
      "z": -9,
      "name": "Rock_Sandstone"
    },
    {
      "x": -11,
      "y": 1,
      "z": -9,
      "name": "Rock_Sandstone_Brick",
      "rotation": 3
    },
    {
      "x": -11,
      "y": 2,
      "z": -9,
      "name": "Rock_Sandstone_Brick",
      "rotation": 3
    },
    {
      "x": -11,
      "y": 3,
      "z": -9,
      "name": "Rock_Sandstone_Brick",
      "rotation": 3
    },
    {
      "x": -11,
      "y": 4,
      "z": -9,
      "name": "Rock_Sandstone_Cobble",
      "rotation": 3
    },
    {
      "x": -11,
      "y": 5,
      "z": -9,
      "name": "Rock_Sandstone_Brick",
      "rotation": 3
    },
    {
      "x": -11,
      "y": 6,
      "z": -9,
      "name": "Rock_Sandstone_Brick",
      "rotation": 3
    },
    {
      "x": -11,
      "y": 7,
      "z": -9,
      "name": "Rock_Sandstone",
      "rotation": 3
    },
    {
      "x": -11,
      "y": 8,
      "z": -9,
      "name": "Rock_Sandstone_Brick",
      "rotation": 3
    },
    {
      "x": -11,
      "y": 9,
      "z": -9,
      "name": "Rock_Sandstone_Brick",
      "rotation": 3
    },
    {
      "x": -11,
      "y": 10,
      "z": -9,
      "name": "Rock_Sandstone",
      "rotation": 3
    },
    {
      "x": -11,
      "y": 11,
      "z": -9,
      "name": "Rock_Sandstone_Brick",
      "rotation": 3
    },
    {
      "x": -11,
      "y": 12,
      "z": -9,
      "name": "Rock_Sandstone_Brick",
      "rotation": 3
    },
    {
      "x": -11,
      "y": 13,
      "z": -9,
      "name": "Rock_Sandstone_Brick",
      "rotation": 3
    },
    {
      "x": -11,
      "y": 14,
      "z": -9,
      "name": "Rock_Sandstone_Brick",
      "rotation": 3
    },
    {
      "x": -11,
      "y": 15,
      "z": -9,
      "name": "Rock_Sandstone_Brick",
      "rotation": 3
    },
    {
      "x": -11,
      "y": 16,
      "z": -9,
      "name": "Rock_Sandstone_Brick",
      "rotation": 3
    },
    {
      "x": -11,
      "y": 17,
      "z": -9,
      "name": "Rock_Sandstone_Brick",
      "rotation": 3
    },
    {
      "x": -11,
      "y": 18,
      "z": -9,
      "name": "Rock_Sandstone_Brick",
      "rotation": 3
    },
    {
      "x": -11,
      "y": 19,
      "z": -9,
      "name": "Rock_Sandstone_Brick",
      "rotation": 3
    },
    {
      "x": -11,
      "y": 20,
      "z": -9,
      "name": "Rock_Sandstone",
      "rotation": 3
    },
    {
      "x": -11,
      "y": 21,
      "z": -9,
      "name": "Rock_Sandstone_Cobble",
      "rotation": 3
    },
    {
      "x": -11,
      "y": 22,
      "z": -9,
      "name": "Rock_Sandstone_Brick",
      "rotation": 3
    },
    {
      "x": -11,
      "y": 23,
      "z": -9,
      "name": "Rock_Sandstone_Brick"
    },
    {
      "x": -11,
      "y": 24,
      "z": -9,
      "name": "Rock_Sandstone_Brick",
      "rotation": 3
    },
    {
      "x": -11,
      "y": 25,
      "z": -9,
      "name": "Rock_Sandstone_Brick"
    },
    {
      "x": -11,
      "y": 20,
      "z": -8,
      "name": "Rock_Sandstone_Brick_Stairs",
      "rotation": 10
    },
    {
      "x": -11,
      "y": 21,
      "z": -8,
      "name": "Rock_Sandstone_Brick"
    },
    {
      "x": -11,
      "y": 22,
      "z": -8,
      "name": "Rock_Sandstone_Brick"
    },
    {
      "x": -11,
      "y": 23,
      "z": -8,
      "name": "Rock_Sandstone_Brick",
      "rotation": 2
    },
    {
      "x": -11,
      "y": 24,
      "z": -8,
      "name": "Rock_Sandstone_Brick"
    },
    {
      "x": -11,
      "y": 25,
      "z": -8,
      "name": "Rock_Sandstone_Brick"
    },
    {
      "x": -11,
      "y": 21,
      "z": -7,
      "name": "Rock_Sandstone_Brick_Stairs",
      "rotation": 10
    },
    {
      "x": -11,
      "y": 22,
      "z": -7,
      "name": "Rock_Sandstone"
    },
    {
      "x": -11,
      "y": 23,
      "z": -7,
      "name": "Rock_Sandstone_Brick",
      "rotation": 2
    },
    {
      "x": -11,
      "y": 24,
      "z": -7,
      "name": "Rock_Sandstone_Brick"
    },
    {
      "x": -11,
      "y": 25,
      "z": -7,
      "name": "Rock_Sandstone_Brick"
    },
    {
      "x": -11,
      "y": 22,
      "z": -6,
      "name": "Rock_Sandstone_Brick"
    },
    {
      "x": -11,
      "y": 23,
      "z": -6,
      "name": "Rock_Sandstone_Brick"
    },
    {
      "x": -11,
      "y": 24,
      "z": -6,
      "name": "Rock_Sandstone_Brick"
    },
    {
      "x": -11,
      "y": 25,
      "z": -6,
      "name": "Rock_Sandstone_Brick"
    },
    {
      "x": -11,
      "y": 22,
      "z": -5,
      "name": "Rock_Sandstone_Brick_Half",
      "rotation": 8
    },
    {
      "x": -11,
      "y": 23,
      "z": -5,
      "name": "Rock_Sandstone_Brick"
    },
    {
      "x": -11,
      "y": 24,
      "z": -5,
      "name": "Rock_Sandstone_Brick"
    },
    {
      "x": -11,
      "y": 25,
      "z": -5,
      "name": "Rock_Sandstone_Brick"
    },
    {
      "x": -11,
      "y": 23,
      "z": -4,
      "name": "Rock_Sandstone_Brick"
    },
    {
      "x": -11,
      "y": 24,
      "z": -4,
      "name": "Rock_Sandstone_Brick"
    },
    {
      "x": -11,
      "y": 25,
      "z": -4,
      "name": "Rock_Sandstone_Brick"
    },
    {
      "x": -11,
      "y": 23,
      "z": -3,
      "name": "Rock_Sandstone_Brick_Stairs",
      "rotation": 10
    },
    {
      "x": -11,
      "y": 24,
      "z": -3,
      "name": "Rock_Sandstone_Brick",
      "rotation": 3
    },
    {
      "x": -11,
      "y": 25,
      "z": -3,
      "name": "Rock_Sandstone_Brick",
      "rotation": 3
    },
    {
      "x": -11,
      "y": 23,
      "z": -2,
      "name": "Rock_Sandstone_Brick_Half",
      "rotation": 11
    },
    {
      "x": -11,
      "y": 24,
      "z": -2,
      "name": "Rock_Sandstone_Brick",
      "rotation": 3
    },
    {
      "x": -11,
      "y": 25,
      "z": -2,
      "name": "Rock_Sandstone_Brick",
      "rotation": 3
    },
    {
      "x": -11,
      "y": 24,
      "z": -1,
      "name": "Rock_Sandstone_Brick"
    },
    {
      "x": -11,
      "y": 25,
      "z": -1,
      "name": "Rock_Sandstone_Brick",
      "rotation": 3
    },
    {
      "x": -11,
      "y": 24,
      "z": 0,
      "name": "Rock_Sandstone_Brick"
    },
    {
      "x": -11,
      "y": 25,
      "z": 0,
      "name": "Rock_Sandstone_Brick",
      "rotation": 3
    },
    {
      "x": -11,
      "y": 24,
      "z": 1,
      "name": "Rock_Sandstone_Brick"
    },
    {
      "x": -11,
      "y": 25,
      "z": 1,
      "name": "Rock_Sandstone_Brick",
      "rotation": 3
    },
    {
      "x": -11,
      "y": 24,
      "z": 2,
      "name": "Rock_Sandstone_Brick",
      "rotation": 3
    },
    {
      "x": -11,
      "y": 25,
      "z": 2,
      "name": "Rock_Sandstone_Brick",
      "rotation": 3
    },
    {
      "x": -11,
      "y": 23,
      "z": 3,
      "name": "Rock_Sandstone_Brick_Half",
      "rotation": 11
    },
    {
      "x": -11,
      "y": 24,
      "z": 3,
      "name": "Rock_Sandstone_Brick",
      "rotation": 3
    },
    {
      "x": -11,
      "y": 25,
      "z": 3,
      "name": "Rock_Sandstone_Brick",
      "rotation": 3
    },
    {
      "x": -11,
      "y": 23,
      "z": 4,
      "name": "Rock_Sandstone_Brick_Stairs",
      "rotation": 8
    },
    {
      "x": -11,
      "y": 24,
      "z": 4,
      "name": "Rock_Sandstone_Brick",
      "rotation": 3
    },
    {
      "x": -11,
      "y": 25,
      "z": 4,
      "name": "Rock_Sandstone_Brick",
      "rotation": 3
    },
    {
      "x": -11,
      "y": 23,
      "z": 5,
      "name": "Rock_Sandstone_Brick"
    },
    {
      "x": -11,
      "y": 24,
      "z": 5,
      "name": "Rock_Sandstone_Brick"
    },
    {
      "x": -11,
      "y": 25,
      "z": 5,
      "name": "Rock_Sandstone_Brick"
    },
    {
      "x": -11,
      "y": 22,
      "z": 6,
      "name": "Rock_Sandstone_Brick_Half",
      "rotation": 8
    },
    {
      "x": -11,
      "y": 23,
      "z": 6,
      "name": "Rock_Sandstone_Brick"
    },
    {
      "x": -11,
      "y": 24,
      "z": 6,
      "name": "Rock_Sandstone_Brick"
    },
    {
      "x": -11,
      "y": 25,
      "z": 6,
      "name": "Rock_Sandstone_Brick"
    },
    {
      "x": -11,
      "y": 22,
      "z": 7,
      "name": "Rock_Sandstone_Brick"
    },
    {
      "x": -11,
      "y": 23,
      "z": 7,
      "name": "Rock_Sandstone_Brick"
    },
    {
      "x": -11,
      "y": 24,
      "z": 7,
      "name": "Rock_Sandstone_Brick"
    },
    {
      "x": -11,
      "y": 25,
      "z": 7,
      "name": "Rock_Sandstone_Brick"
    },
    {
      "x": -11,
      "y": 21,
      "z": 8,
      "name": "Rock_Sandstone_Brick_Stairs",
      "rotation": 8
    },
    {
      "x": -11,
      "y": 22,
      "z": 8,
      "name": "Rock_Sandstone_Cobble"
    },
    {
      "x": -11,
      "y": 23,
      "z": 8,
      "name": "Rock_Sandstone_Brick"
    },
    {
      "x": -11,
      "y": 24,
      "z": 8,
      "name": "Rock_Sandstone_Brick"
    },
    {
      "x": -11,
      "y": 25,
      "z": 8,
      "name": "Rock_Sandstone_Brick"
    },
    {
      "x": -11,
      "y": 20,
      "z": 9,
      "name": "Rock_Sandstone_Brick_Stairs",
      "rotation": 8
    },
    {
      "x": -11,
      "y": 21,
      "z": 9,
      "name": "Rock_Sandstone_Brick"
    },
    {
      "x": -11,
      "y": 22,
      "z": 9,
      "name": "Rock_Sandstone_Brick"
    },
    {
      "x": -11,
      "y": 23,
      "z": 9,
      "name": "Rock_Sandstone_Brick"
    },
    {
      "x": -11,
      "y": 24,
      "z": 9,
      "name": "Rock_Sandstone_Brick"
    },
    {
      "x": -11,
      "y": 25,
      "z": 9,
      "name": "Rock_Sandstone_Brick"
    },
    {
      "x": -11,
      "y": -10,
      "z": 10,
      "name": "Rock_Sandstone_Brick"
    },
    {
      "x": -11,
      "y": -9,
      "z": 10,
      "name": "Rock_Sandstone_Brick"
    },
    {
      "x": -11,
      "y": -8,
      "z": 10,
      "name": "Rock_Sandstone_Brick"
    },
    {
      "x": -11,
      "y": -7,
      "z": 10,
      "name": "Rock_Sandstone_Cobble"
    },
    {
      "x": -11,
      "y": -6,
      "z": 10,
      "name": "Rock_Sandstone"
    },
    {
      "x": -11,
      "y": -5,
      "z": 10,
      "name": "Rock_Sandstone_Brick"
    },
    {
      "x": -11,
      "y": -4,
      "z": 10,
      "name": "Rock_Sandstone"
    },
    {
      "x": -11,
      "y": -3,
      "z": 10,
      "name": "Rock_Sandstone_Brick"
    },
    {
      "x": -11,
      "y": -2,
      "z": 10,
      "name": "Rock_Sandstone_Brick"
    },
    {
      "x": -11,
      "y": -1,
      "z": 10,
      "name": "Rock_Sandstone"
    },
    {
      "x": -11,
      "y": 0,
      "z": 10,
      "name": "Rock_Sandstone_Brick"
    },
    {
      "x": -11,
      "y": 1,
      "z": 10,
      "name": "Rock_Sandstone"
    },
    {
      "x": -11,
      "y": 2,
      "z": 10,
      "name": "Rock_Sandstone_Brick"
    },
    {
      "x": -11,
      "y": 3,
      "z": 10,
      "name": "Rock_Sandstone_Brick"
    },
    {
      "x": -11,
      "y": 4,
      "z": 10,
      "name": "Rock_Sandstone_Brick"
    },
    {
      "x": -11,
      "y": 5,
      "z": 10,
      "name": "Rock_Sandstone_Cobble"
    },
    {
      "x": -11,
      "y": 6,
      "z": 10,
      "name": "Rock_Sandstone"
    },
    {
      "x": -11,
      "y": 7,
      "z": 10,
      "name": "Rock_Sandstone"
    },
    {
      "x": -11,
      "y": 8,
      "z": 10,
      "name": "Rock_Sandstone_Brick"
    },
    {
      "x": -11,
      "y": 9,
      "z": 10,
      "name": "Rock_Sandstone"
    },
    {
      "x": -11,
      "y": 10,
      "z": 10,
      "name": "Rock_Sandstone_Brick"
    },
    {
      "x": -11,
      "y": 11,
      "z": 10,
      "name": "Rock_Sandstone"
    },
    {
      "x": -11,
      "y": 12,
      "z": 10,
      "name": "Rock_Sandstone_Brick"
    },
    {
      "x": -11,
      "y": 13,
      "z": 10,
      "name": "Rock_Sandstone_Brick"
    },
    {
      "x": -11,
      "y": 14,
      "z": 10,
      "name": "Rock_Sandstone_Brick"
    },
    {
      "x": -11,
      "y": 15,
      "z": 10,
      "name": "Rock_Sandstone_Brick"
    },
    {
      "x": -11,
      "y": 16,
      "z": 10,
      "name": "Rock_Sandstone_Brick"
    },
    {
      "x": -11,
      "y": 17,
      "z": 10,
      "name": "Rock_Sandstone_Brick"
    },
    {
      "x": -11,
      "y": 18,
      "z": 10,
      "name": "Rock_Sandstone_Cobble"
    },
    {
      "x": -11,
      "y": 19,
      "z": 10,
      "name": "Rock_Sandstone_Brick"
    },
    {
      "x": -11,
      "y": 20,
      "z": 10,
      "name": "Rock_Sandstone_Brick"
    },
    {
      "x": -11,
      "y": 21,
      "z": 10,
      "name": "Rock_Sandstone_Brick"
    },
    {
      "x": -11,
      "y": 22,
      "z": 10,
      "name": "Rock_Sandstone_Brick"
    },
    {
      "x": -11,
      "y": 23,
      "z": 10,
      "name": "Rock_Sandstone_Brick"
    },
    {
      "x": -11,
      "y": 24,
      "z": 10,
      "name": "Rock_Sandstone_Brick",
      "rotation": 1
    },
    {
      "x": -11,
      "y": 25,
      "z": 10,
      "name": "Rock_Sandstone_Brick"
    },
    {
      "x": -11,
      "y": -10,
      "z": 11,
      "name": "Rock_Sandstone_Cobble"
    },
    {
      "x": -11,
      "y": -9,
      "z": 11,
      "name": "Rock_Sandstone_Cobble"
    },
    {
      "x": -11,
      "y": -8,
      "z": 11,
      "name": "Rock_Sandstone_Cobble"
    },
    {
      "x": -11,
      "y": -7,
      "z": 11,
      "name": "Rock_Sandstone_Cobble"
    },
    {
      "x": -11,
      "y": -6,
      "z": 11,
      "name": "Rock_Sandstone_Cobble"
    },
    {
      "x": -11,
      "y": -5,
      "z": 11,
      "name": "Rock_Sandstone_Cobble"
    },
    {
      "x": -11,
      "y": -4,
      "z": 11,
      "name": "Rock_Sandstone_Cobble"
    },
    {
      "x": -11,
      "y": -3,
      "z": 11,
      "name": "Rock_Sandstone_Cobble"
    },
    {
      "x": -11,
      "y": -2,
      "z": 11,
      "name": "Rock_Sandstone_Cobble"
    },
    {
      "x": -11,
      "y": -1,
      "z": 11,
      "name": "Rock_Sandstone_Cobble"
    },
    {
      "x": -11,
      "y": 0,
      "z": 11,
      "name": "Rock_Sandstone_Cobble"
    },
    {
      "x": -11,
      "y": 1,
      "z": 11,
      "name": "Rock_Sandstone_Cobble",
      "rotation": 1
    },
    {
      "x": -11,
      "y": 2,
      "z": 11,
      "name": "Rock_Sandstone_Cobble",
      "rotation": 1
    },
    {
      "x": -11,
      "y": 3,
      "z": 11,
      "name": "Rock_Sandstone_Cobble",
      "rotation": 1
    },
    {
      "x": -11,
      "y": 4,
      "z": 11,
      "name": "Rock_Sandstone_Cobble",
      "rotation": 1
    },
    {
      "x": -11,
      "y": 5,
      "z": 11,
      "name": "Rock_Sandstone_Cobble",
      "rotation": 1
    },
    {
      "x": -11,
      "y": 6,
      "z": 11,
      "name": "Rock_Sandstone_Cobble",
      "rotation": 1
    },
    {
      "x": -11,
      "y": 7,
      "z": 11,
      "name": "Rock_Sandstone_Cobble",
      "rotation": 1
    },
    {
      "x": -11,
      "y": 8,
      "z": 11,
      "name": "Rock_Sandstone_Cobble",
      "rotation": 1
    },
    {
      "x": -11,
      "y": 9,
      "z": 11,
      "name": "Rock_Sandstone_Cobble",
      "rotation": 1
    },
    {
      "x": -11,
      "y": 10,
      "z": 11,
      "name": "Rock_Sandstone_Cobble",
      "rotation": 1
    },
    {
      "x": -11,
      "y": 11,
      "z": 11,
      "name": "Rock_Sandstone_Cobble",
      "rotation": 1
    },
    {
      "x": -11,
      "y": 12,
      "z": 11,
      "name": "Rock_Sandstone_Cobble",
      "rotation": 1
    },
    {
      "x": -11,
      "y": 13,
      "z": 11,
      "name": "Rock_Sandstone_Cobble",
      "rotation": 1
    },
    {
      "x": -11,
      "y": 14,
      "z": 11,
      "name": "Rock_Sandstone_Cobble",
      "rotation": 1
    },
    {
      "x": -11,
      "y": 15,
      "z": 11,
      "name": "Rock_Sandstone_Cobble",
      "rotation": 1
    },
    {
      "x": -11,
      "y": 16,
      "z": 11,
      "name": "Rock_Sandstone_Cobble",
      "rotation": 1
    },
    {
      "x": -11,
      "y": 17,
      "z": 11,
      "name": "Rock_Sandstone_Cobble",
      "rotation": 1
    },
    {
      "x": -11,
      "y": 18,
      "z": 11,
      "name": "Rock_Sandstone_Cobble",
      "rotation": 1
    },
    {
      "x": -11,
      "y": 19,
      "z": 11,
      "name": "Rock_Sandstone_Cobble",
      "rotation": 1
    },
    {
      "x": -11,
      "y": 20,
      "z": 11,
      "name": "Rock_Sandstone_Cobble",
      "rotation": 1
    },
    {
      "x": -11,
      "y": 21,
      "z": 11,
      "name": "Rock_Sandstone_Cobble",
      "rotation": 1
    },
    {
      "x": -11,
      "y": 22,
      "z": 11,
      "name": "Rock_Sandstone_Cobble",
      "rotation": 1
    },
    {
      "x": -11,
      "y": 23,
      "z": 11,
      "name": "Rock_Sandstone_Cobble",
      "rotation": 1
    },
    {
      "x": -11,
      "y": 24,
      "z": 11,
      "name": "Rock_Sandstone_Cobble",
      "rotation": 1
    },
    {
      "x": -11,
      "y": 25,
      "z": 11,
      "name": "Rock_Sandstone_Brick"
    },
    {
      "x": -11,
      "y": -10,
      "z": 12,
      "name": "Rock_Sandstone_Brick"
    },
    {
      "x": -11,
      "y": -9,
      "z": 12,
      "name": "Rock_Sandstone_Cobble"
    },
    {
      "x": -11,
      "y": -8,
      "z": 12,
      "name": "Rock_Sandstone_Brick"
    },
    {
      "x": -11,
      "y": -7,
      "z": 12,
      "name": "Rock_Sandstone_Cobble"
    },
    {
      "x": -11,
      "y": -6,
      "z": 12,
      "name": "Rock_Sandstone_Brick"
    },
    {
      "x": -11,
      "y": -5,
      "z": 12,
      "name": "Rock_Sandstone_Brick"
    },
    {
      "x": -11,
      "y": -4,
      "z": 12,
      "name": "Rock_Sandstone_Brick"
    },
    {
      "x": -11,
      "y": -3,
      "z": 12,
      "name": "Rock_Sandstone_Brick"
    },
    {
      "x": -11,
      "y": -2,
      "z": 12,
      "name": "Rock_Sandstone_Brick"
    },
    {
      "x": -11,
      "y": -1,
      "z": 12,
      "name": "Rock_Sandstone_Brick"
    },
    {
      "x": -11,
      "y": 0,
      "z": 12,
      "name": "Rock_Sandstone"
    },
    {
      "x": -11,
      "y": 1,
      "z": 12,
      "name": "Rock_Sandstone"
    },
    {
      "x": -11,
      "y": 2,
      "z": 12,
      "name": "Rock_Sandstone_Brick"
    },
    {
      "x": -11,
      "y": 3,
      "z": 12,
      "name": "Rock_Sandstone_Brick"
    },
    {
      "x": -11,
      "y": 4,
      "z": 12,
      "name": "Rock_Sandstone_Brick"
    },
    {
      "x": -11,
      "y": 5,
      "z": 12,
      "name": "Rock_Sandstone_Brick"
    },
    {
      "x": -11,
      "y": 6,
      "z": 12,
      "name": "Rock_Sandstone"
    },
    {
      "x": -11,
      "y": 7,
      "z": 12,
      "name": "Rock_Sandstone_Brick"
    },
    {
      "x": -11,
      "y": 8,
      "z": 12,
      "name": "Rock_Sandstone_Cobble"
    },
    {
      "x": -11,
      "y": 9,
      "z": 12,
      "name": "Rock_Sandstone"
    },
    {
      "x": -11,
      "y": 10,
      "z": 12,
      "name": "Rock_Sandstone_Brick"
    },
    {
      "x": -11,
      "y": 11,
      "z": 12,
      "name": "Rock_Sandstone_Brick"
    },
    {
      "x": -11,
      "y": 12,
      "z": 12,
      "name": "Rock_Sandstone_Brick"
    },
    {
      "x": -11,
      "y": 13,
      "z": 12,
      "name": "Rock_Sandstone_Brick"
    },
    {
      "x": -11,
      "y": 14,
      "z": 12,
      "name": "Rock_Sandstone"
    },
    {
      "x": -11,
      "y": 15,
      "z": 12,
      "name": "Rock_Sandstone_Brick"
    },
    {
      "x": -11,
      "y": 16,
      "z": 12,
      "name": "Rock_Sandstone_Brick"
    },
    {
      "x": -11,
      "y": 17,
      "z": 12,
      "name": "Rock_Sandstone_Brick"
    },
    {
      "x": -11,
      "y": 18,
      "z": 12,
      "name": "Rock_Sandstone_Brick"
    },
    {
      "x": -11,
      "y": 19,
      "z": 12,
      "name": "Rock_Sandstone_Cobble"
    },
    {
      "x": -11,
      "y": 20,
      "z": 12,
      "name": "Rock_Sandstone"
    },
    {
      "x": -11,
      "y": 21,
      "z": 12,
      "name": "Rock_Sandstone_Brick"
    },
    {
      "x": -11,
      "y": 22,
      "z": 12,
      "name": "Rock_Sandstone_Cobble"
    },
    {
      "x": -11,
      "y": 23,
      "z": 12,
      "name": "Rock_Sandstone_Brick"
    },
    {
      "x": -11,
      "y": 24,
      "z": 12,
      "name": "Rock_Sandstone_Brick"
    },
    {
      "x": -11,
      "y": 25,
      "z": 12,
      "name": "Rock_Sandstone_Brick"
    },
    {
      "x": -11,
      "y": -10,
      "z": 13,
      "name": "Rock_Sandstone_Brick_Half",
      "rotation": 4
    },
    {
      "x": -11,
      "y": -9,
      "z": 13,
      "name": "Rock_Sandstone_Brick_Half",
      "rotation": 4
    },
    {
      "x": -11,
      "y": -8,
      "z": 13,
      "name": "Rock_Sandstone_Brick_Half",
      "rotation": 4
    },
    {
      "x": -11,
      "y": -7,
      "z": 13,
      "name": "Rock_Sandstone_Brick_Half",
      "rotation": 4
    },
    {
      "x": -11,
      "y": -6,
      "z": 13,
      "name": "Rock_Sandstone_Brick_Half",
      "rotation": 4
    },
    {
      "x": -11,
      "y": -5,
      "z": 13,
      "name": "Rock_Sandstone_Brick_Half",
      "rotation": 4
    },
    {
      "x": -11,
      "y": -4,
      "z": 13,
      "name": "Rock_Sandstone_Brick_Half",
      "rotation": 4
    },
    {
      "x": -11,
      "y": -3,
      "z": 13,
      "name": "Rock_Sandstone_Brick_Half",
      "rotation": 4
    },
    {
      "x": -11,
      "y": -2,
      "z": 13,
      "name": "Rock_Sandstone_Brick_Half",
      "rotation": 4
    },
    {
      "x": -11,
      "y": -1,
      "z": 13,
      "name": "Rock_Sandstone_Brick_Half",
      "rotation": 4
    },
    {
      "x": -11,
      "y": 0,
      "z": 13,
      "name": "Rock_Sandstone_Brick_Half",
      "rotation": 4
    },
    {
      "x": -11,
      "y": 1,
      "z": 13,
      "name": "Rock_Sandstone_Brick_Half",
      "rotation": 4
    },
    {
      "x": -11,
      "y": 2,
      "z": 13,
      "name": "Rock_Sandstone_Brick_Half",
      "rotation": 4
    },
    {
      "x": -11,
      "y": 3,
      "z": 13,
      "name": "Rock_Sandstone_Brick_Half",
      "rotation": 4
    },
    {
      "x": -11,
      "y": 4,
      "z": 13,
      "name": "Rock_Sandstone_Brick_Half",
      "rotation": 4
    },
    {
      "x": -11,
      "y": 5,
      "z": 13,
      "name": "Rock_Sandstone_Brick_Half",
      "rotation": 4
    },
    {
      "x": -11,
      "y": 6,
      "z": 13,
      "name": "Rock_Sandstone_Brick_Half",
      "rotation": 4
    },
    {
      "x": -11,
      "y": 7,
      "z": 13,
      "name": "Rock_Sandstone_Brick_Half",
      "rotation": 4
    },
    {
      "x": -11,
      "y": 8,
      "z": 13,
      "name": "Rock_Sandstone_Brick_Half",
      "rotation": 4
    },
    {
      "x": -11,
      "y": 9,
      "z": 13,
      "name": "Rock_Sandstone_Brick_Half",
      "rotation": 4
    },
    {
      "x": -11,
      "y": 10,
      "z": 13,
      "name": "Rock_Sandstone_Brick_Half",
      "rotation": 4
    },
    {
      "x": -11,
      "y": 11,
      "z": 13,
      "name": "Rock_Sandstone_Brick_Half",
      "rotation": 4
    },
    {
      "x": -11,
      "y": 12,
      "z": 13,
      "name": "Rock_Sandstone_Brick_Half",
      "rotation": 4
    },
    {
      "x": -11,
      "y": 13,
      "z": 13,
      "name": "Rock_Sandstone_Brick_Half",
      "rotation": 4
    },
    {
      "x": -11,
      "y": 14,
      "z": 13,
      "name": "Rock_Sandstone_Brick_Half",
      "rotation": 4
    },
    {
      "x": -11,
      "y": 15,
      "z": 13,
      "name": "Rock_Sandstone_Brick_Half",
      "rotation": 4
    },
    {
      "x": -11,
      "y": 16,
      "z": 13,
      "name": "Rock_Sandstone_Brick_Half",
      "rotation": 4
    },
    {
      "x": -11,
      "y": 17,
      "z": 13,
      "name": "Rock_Sandstone_Brick_Half",
      "rotation": 4
    },
    {
      "x": -11,
      "y": 18,
      "z": 13,
      "name": "Rock_Sandstone_Brick_Half",
      "rotation": 4
    },
    {
      "x": -11,
      "y": 19,
      "z": 13,
      "name": "Rock_Sandstone_Brick_Half",
      "rotation": 4
    },
    {
      "x": -11,
      "y": 20,
      "z": 13,
      "name": "Rock_Sandstone_Brick_Stairs",
      "rotation": 10
    },
    {
      "x": -11,
      "y": 21,
      "z": 13,
      "name": "Rock_Sandstone_Brick_Half",
      "rotation": 4
    },
    {
      "x": -11,
      "y": 22,
      "z": 13,
      "name": "Rock_Sandstone_Brick_Stairs",
      "rotation": 10
    },
    {
      "x": -11,
      "y": 23,
      "z": 13,
      "name": "Rock_Sandstone_Brick_Half",
      "rotation": 4
    },
    {
      "x": -11,
      "y": 24,
      "z": 13,
      "name": "Rock_Sandstone_Brick_Half",
      "rotation": 4
    },
    {
      "x": -11,
      "y": 25,
      "z": 13,
      "name": "Rock_Sandstone_Brick_Stairs",
      "rotation": 10
    },
    {
      "x": -10,
      "y": 20,
      "z": -12,
      "name": "Rock_Sandstone_Brick_Half",
      "rotation": 8
    },
    {
      "x": -10,
      "y": 22,
      "z": -12,
      "name": "Rock_Sandstone_Brick_Stairs",
      "rotation": 8
    },
    {
      "x": -10,
      "y": 25,
      "z": -12,
      "name": "Rock_Sandstone_Brick_Stairs",
      "rotation": 8
    },
    {
      "x": -10,
      "y": -10,
      "z": -11,
      "name": "Rock_Sandstone_Cobble"
    },
    {
      "x": -10,
      "y": -9,
      "z": -11,
      "name": "Rock_Sandstone_Cobble"
    },
    {
      "x": -10,
      "y": -8,
      "z": -11,
      "name": "Rock_Sandstone_Cobble"
    },
    {
      "x": -10,
      "y": -7,
      "z": -11,
      "name": "Rock_Sandstone_Cobble"
    },
    {
      "x": -10,
      "y": -6,
      "z": -11,
      "name": "Rock_Sandstone_Cobble"
    },
    {
      "x": -10,
      "y": -5,
      "z": -11,
      "name": "Rock_Sandstone_Cobble"
    },
    {
      "x": -10,
      "y": -4,
      "z": -11,
      "name": "Rock_Sandstone_Cobble"
    },
    {
      "x": -10,
      "y": -3,
      "z": -11,
      "name": "Rock_Sandstone_Cobble"
    },
    {
      "x": -10,
      "y": -2,
      "z": -11,
      "name": "Rock_Sandstone_Cobble"
    },
    {
      "x": -10,
      "y": -1,
      "z": -11,
      "name": "Rock_Sandstone_Cobble"
    },
    {
      "x": -10,
      "y": 0,
      "z": -11,
      "name": "Rock_Sandstone_Cobble"
    },
    {
      "x": -10,
      "y": 1,
      "z": -11,
      "name": "Rock_Sandstone_Cobble"
    },
    {
      "x": -10,
      "y": 2,
      "z": -11,
      "name": "Rock_Sandstone_Cobble"
    },
    {
      "x": -10,
      "y": 3,
      "z": -11,
      "name": "Rock_Sandstone_Cobble"
    },
    {
      "x": -10,
      "y": 4,
      "z": -11,
      "name": "Rock_Sandstone_Cobble"
    },
    {
      "x": -10,
      "y": 5,
      "z": -11,
      "name": "Rock_Sandstone_Cobble"
    },
    {
      "x": -10,
      "y": 6,
      "z": -11,
      "name": "Rock_Sandstone_Cobble"
    },
    {
      "x": -10,
      "y": 7,
      "z": -11,
      "name": "Rock_Sandstone_Cobble"
    },
    {
      "x": -10,
      "y": 8,
      "z": -11,
      "name": "Rock_Sandstone_Cobble"
    },
    {
      "x": -10,
      "y": 9,
      "z": -11,
      "name": "Rock_Sandstone_Cobble"
    },
    {
      "x": -10,
      "y": 10,
      "z": -11,
      "name": "Rock_Sandstone_Cobble"
    },
    {
      "x": -10,
      "y": 11,
      "z": -11,
      "name": "Rock_Sandstone_Cobble"
    },
    {
      "x": -10,
      "y": 12,
      "z": -11,
      "name": "Rock_Sandstone_Cobble"
    },
    {
      "x": -10,
      "y": 13,
      "z": -11,
      "name": "Rock_Sandstone_Cobble"
    },
    {
      "x": -10,
      "y": 14,
      "z": -11,
      "name": "Rock_Sandstone_Cobble"
    },
    {
      "x": -10,
      "y": 15,
      "z": -11,
      "name": "Rock_Sandstone_Cobble"
    },
    {
      "x": -10,
      "y": 16,
      "z": -11,
      "name": "Rock_Sandstone_Cobble"
    },
    {
      "x": -10,
      "y": 17,
      "z": -11,
      "name": "Rock_Sandstone_Cobble"
    },
    {
      "x": -10,
      "y": 18,
      "z": -11,
      "name": "Rock_Sandstone_Cobble"
    },
    {
      "x": -10,
      "y": 19,
      "z": -11,
      "name": "Rock_Sandstone_Cobble"
    },
    {
      "x": -10,
      "y": 20,
      "z": -11,
      "name": "Rock_Sandstone_Cobble"
    },
    {
      "x": -10,
      "y": 21,
      "z": -11,
      "name": "Rock_Sandstone_Cobble"
    },
    {
      "x": -10,
      "y": 22,
      "z": -11,
      "name": "Rock_Sandstone_Cobble"
    },
    {
      "x": -10,
      "y": 23,
      "z": -11,
      "name": "Rock_Sandstone_Cobble"
    },
    {
      "x": -10,
      "y": 24,
      "z": -11,
      "name": "Rock_Sandstone_Cobble"
    },
    {
      "x": -10,
      "y": 25,
      "z": -11,
      "name": "Rock_Sandstone_Brick"
    },
    {
      "x": -10,
      "y": -10,
      "z": -10,
      "name": "Rock_Sandstone_Brick"
    },
    {
      "x": -10,
      "y": -9,
      "z": -10,
      "name": "Rock_Sandstone"
    },
    {
      "x": -10,
      "y": -8,
      "z": -10,
      "name": "Rock_Sandstone_Cobble"
    },
    {
      "x": -10,
      "y": -7,
      "z": -10,
      "name": "Rock_Sandstone_Brick"
    },
    {
      "x": -10,
      "y": -6,
      "z": -10,
      "name": "Rock_Sandstone"
    },
    {
      "x": -10,
      "y": -5,
      "z": -10,
      "name": "Rock_Sandstone"
    },
    {
      "x": -10,
      "y": -4,
      "z": -10,
      "name": "Rock_Sandstone_Brick"
    },
    {
      "x": -10,
      "y": -3,
      "z": -10,
      "name": "Rock_Sandstone_Brick"
    },
    {
      "x": -10,
      "y": -2,
      "z": -10,
      "name": "Rock_Sandstone_Brick"
    },
    {
      "x": -10,
      "y": -1,
      "z": -10,
      "name": "Rock_Sandstone"
    },
    {
      "x": -10,
      "y": 0,
      "z": -10,
      "name": "Rock_Sandstone_Brick"
    },
    {
      "x": -10,
      "y": 1,
      "z": -10,
      "name": "Rock_Sandstone_Brick",
      "rotation": 3
    },
    {
      "x": -10,
      "y": 2,
      "z": -10,
      "name": "Rock_Sandstone",
      "rotation": 3
    },
    {
      "x": -10,
      "y": 3,
      "z": -10,
      "name": "Rock_Sandstone_Brick",
      "rotation": 3
    },
    {
      "x": -10,
      "y": 4,
      "z": -10,
      "name": "Rock_Sandstone_Brick",
      "rotation": 3
    },
    {
      "x": -10,
      "y": 5,
      "z": -10,
      "name": "Rock_Sandstone_Cobble",
      "rotation": 3
    },
    {
      "x": -10,
      "y": 6,
      "z": -10,
      "name": "Rock_Sandstone_Brick",
      "rotation": 3
    },
    {
      "x": -10,
      "y": 7,
      "z": -10,
      "name": "Rock_Sandstone_Brick",
      "rotation": 3
    },
    {
      "x": -10,
      "y": 8,
      "z": -10,
      "name": "Rock_Sandstone_Brick",
      "rotation": 3
    },
    {
      "x": -10,
      "y": 9,
      "z": -10,
      "name": "Rock_Sandstone",
      "rotation": 3
    },
    {
      "x": -10,
      "y": 10,
      "z": -10,
      "name": "Rock_Sandstone_Cobble",
      "rotation": 3
    },
    {
      "x": -10,
      "y": 11,
      "z": -10,
      "name": "Rock_Sandstone_Brick",
      "rotation": 3
    },
    {
      "x": -10,
      "y": 12,
      "z": -10,
      "name": "Rock_Sandstone_Brick",
      "rotation": 3
    },
    {
      "x": -10,
      "y": 13,
      "z": -10,
      "name": "Rock_Sandstone_Brick"
    },
    {
      "x": -10,
      "y": 14,
      "z": -10,
      "name": "Rock_Sandstone_Brick",
      "rotation": 3
    },
    {
      "x": -10,
      "y": 15,
      "z": -10,
      "name": "Rock_Sandstone_Brick",
      "rotation": 3
    },
    {
      "x": -10,
      "y": 16,
      "z": -10,
      "name": "Rock_Sandstone_Brick",
      "rotation": 3
    },
    {
      "x": -10,
      "y": 17,
      "z": -10,
      "name": "Rock_Sandstone_Brick",
      "rotation": 3
    },
    {
      "x": -10,
      "y": 18,
      "z": -10,
      "name": "Rock_Sandstone_Brick",
      "rotation": 3
    },
    {
      "x": -10,
      "y": 19,
      "z": -10,
      "name": "Rock_Sandstone_Brick",
      "rotation": 3
    },
    {
      "x": -10,
      "y": 20,
      "z": -10,
      "name": "Rock_Sandstone_Brick",
      "rotation": 3
    },
    {
      "x": -10,
      "y": 21,
      "z": -10,
      "name": "Rock_Sandstone_Cobble",
      "rotation": 3
    },
    {
      "x": -10,
      "y": 22,
      "z": -10,
      "name": "Rock_Sandstone",
      "rotation": 3
    },
    {
      "x": -10,
      "y": 23,
      "z": -10,
      "name": "Rock_Sandstone_Brick",
      "rotation": 3
    },
    {
      "x": -10,
      "y": 24,
      "z": -10,
      "name": "Rock_Sandstone_Brick",
      "rotation": 3
    },
    {
      "x": -10,
      "y": 25,
      "z": -10,
      "name": "Rock_Sandstone_Brick"
    },
    {
      "x": -10,
      "y": -10,
      "z": -9,
      "name": "Rock_Sandstone_Brick"
    },
    {
      "x": -10,
      "y": -9,
      "z": -9,
      "name": "Rock_Sandstone_Brick"
    },
    {
      "x": -10,
      "y": -8,
      "z": -9,
      "name": "Rock_Sandstone"
    },
    {
      "x": -10,
      "y": -7,
      "z": -9,
      "name": "Rock_Sandstone_Brick"
    },
    {
      "x": -10,
      "y": -6,
      "z": -9,
      "name": "Rock_Sandstone"
    },
    {
      "x": -10,
      "y": -5,
      "z": -9,
      "name": "Rock_Sandstone_Brick"
    },
    {
      "x": -10,
      "y": -4,
      "z": -9,
      "name": "Rock_Sandstone"
    },
    {
      "x": -10,
      "y": -3,
      "z": -9,
      "name": "Rock_Sandstone_Brick"
    },
    {
      "x": -10,
      "y": -2,
      "z": -9,
      "name": "Rock_Sandstone_Cobble"
    },
    {
      "x": -10,
      "y": -1,
      "z": -9,
      "name": "Rock_Sandstone_Brick"
    },
    {
      "x": -10,
      "y": 0,
      "z": -9,
      "name": "Rock_Sandstone_Brick"
    },
    {
      "x": -10,
      "y": 1,
      "z": -9,
      "name": "Rock_Sandstone_Cobble",
      "rotation": 3
    },
    {
      "x": -10,
      "y": 2,
      "z": -9,
      "name": "Rock_Sandstone_Brick",
      "rotation": 3
    },
    {
      "x": -10,
      "y": 3,
      "z": -9,
      "name": "Rock_Sandstone_Brick",
      "rotation": 3
    },
    {
      "x": -10,
      "y": 4,
      "z": -9,
      "name": "Rock_Sandstone_Brick",
      "rotation": 3
    },
    {
      "x": -10,
      "y": 5,
      "z": -9,
      "name": "Rock_Sandstone_Cobble",
      "rotation": 3
    },
    {
      "x": -10,
      "y": 6,
      "z": -9,
      "name": "Rock_Sandstone_Brick",
      "rotation": 3
    },
    {
      "x": -10,
      "y": 7,
      "z": -9,
      "name": "Rock_Sandstone",
      "rotation": 3
    },
    {
      "x": -10,
      "y": 8,
      "z": -9,
      "name": "Rock_Sandstone_Brick",
      "rotation": 3
    },
    {
      "x": -10,
      "y": 9,
      "z": -9,
      "name": "Rock_Sandstone_Brick",
      "rotation": 3
    },
    {
      "x": -10,
      "y": 10,
      "z": -9,
      "name": "Rock_Sandstone_Brick",
      "rotation": 3
    },
    {
      "x": -10,
      "y": 11,
      "z": -9,
      "name": "Rock_Sandstone_Brick",
      "rotation": 3
    },
    {
      "x": -10,
      "y": 12,
      "z": -9,
      "name": "Rock_Sandstone_Brick",
      "rotation": 3
    },
    {
      "x": -10,
      "y": 13,
      "z": -9,
      "name": "Rock_Sandstone",
      "rotation": 3
    },
    {
      "x": -10,
      "y": 14,
      "z": -9,
      "name": "Rock_Sandstone_Brick",
      "rotation": 3
    },
    {
      "x": -10,
      "y": 15,
      "z": -9,
      "name": "Rock_Sandstone",
      "rotation": 3
    },
    {
      "x": -10,
      "y": 16,
      "z": -9,
      "name": "Rock_Sandstone_Brick",
      "rotation": 3
    },
    {
      "x": -10,
      "y": 17,
      "z": -9,
      "name": "Rock_Sandstone",
      "rotation": 3
    },
    {
      "x": -10,
      "y": 18,
      "z": -9,
      "name": "Rock_Sandstone_Brick",
      "rotation": 3
    },
    {
      "x": -10,
      "y": 19,
      "z": -9,
      "name": "Rock_Sandstone_Brick",
      "rotation": 3
    },
    {
      "x": -10,
      "y": 20,
      "z": -9,
      "name": "Rock_Sandstone_Brick",
      "rotation": 3
    },
    {
      "x": -10,
      "y": 21,
      "z": -9,
      "name": "Rock_Sandstone",
      "rotation": 3
    },
    {
      "x": -10,
      "y": 22,
      "z": -9,
      "name": "Rock_Sandstone_Cobble",
      "rotation": 3
    },
    {
      "x": -10,
      "y": 23,
      "z": -9,
      "name": "Rock_Sandstone_Brick",
      "rotation": 3
    },
    {
      "x": -10,
      "y": 24,
      "z": -9,
      "name": "Rock_Sandstone_Brick",
      "rotation": 3
    },
    {
      "x": -10,
      "y": 25,
      "z": -9,
      "name": "Rock_Sandstone_Brick"
    },
    {
      "x": -10,
      "y": -10,
      "z": -8,
      "name": "Rock_Sandstone_Brick"
    },
    {
      "x": -10,
      "y": -9,
      "z": -8,
      "name": "Rock_Sandstone_Cobble"
    },
    {
      "x": -10,
      "y": -8,
      "z": -8,
      "name": "Rock_Sandstone_Brick"
    },
    {
      "x": -10,
      "y": -7,
      "z": -8,
      "name": "Rock_Sandstone_Brick"
    },
    {
      "x": -10,
      "y": -6,
      "z": -8,
      "name": "Rock_Sandstone"
    },
    {
      "x": -10,
      "y": -5,
      "z": -8,
      "name": "Rock_Sandstone_Brick"
    },
    {
      "x": -10,
      "y": -4,
      "z": -8,
      "name": "Rock_Sandstone"
    },
    {
      "x": -10,
      "y": -3,
      "z": -8,
      "name": "Rock_Sandstone_Brick"
    },
    {
      "x": -10,
      "y": -2,
      "z": -8,
      "name": "Rock_Sandstone_Cobble"
    },
    {
      "x": -10,
      "y": -1,
      "z": -8,
      "name": "Rock_Sandstone_Brick"
    },
    {
      "x": -10,
      "y": 0,
      "z": -8,
      "name": "Rock_Sandstone_Cobble"
    },
    {
      "x": -10,
      "y": 1,
      "z": -8,
      "name": "Rock_Sandstone_Brick"
    },
    {
      "x": -10,
      "y": 2,
      "z": -8,
      "name": "Rock_Sandstone_Brick"
    },
    {
      "x": -10,
      "y": 3,
      "z": -8,
      "name": "Rock_Sandstone_Brick"
    },
    {
      "x": -10,
      "y": 4,
      "z": -8,
      "name": "Rock_Sandstone_Brick"
    },
    {
      "x": -10,
      "y": 5,
      "z": -8,
      "name": "Rock_Sandstone_Brick"
    },
    {
      "x": -10,
      "y": 6,
      "z": -8,
      "name": "Rock_Sandstone_Cobble"
    },
    {
      "x": -10,
      "y": 7,
      "z": -8,
      "name": "Rock_Sandstone"
    },
    {
      "x": -10,
      "y": 8,
      "z": -8,
      "name": "Rock_Sandstone_Brick"
    },
    {
      "x": -10,
      "y": 9,
      "z": -8,
      "name": "Rock_Sandstone"
    },
    {
      "x": -10,
      "y": 10,
      "z": -8,
      "name": "Rock_Sandstone_Brick"
    },
    {
      "x": -10,
      "y": 11,
      "z": -8,
      "name": "Rock_Sandstone_Brick"
    },
    {
      "x": -10,
      "y": 12,
      "z": -8,
      "name": "Rock_Sandstone_Brick"
    },
    {
      "x": -10,
      "y": 13,
      "z": -8,
      "name": "Rock_Sandstone_Cobble"
    },
    {
      "x": -10,
      "y": 14,
      "z": -8,
      "name": "Rock_Sandstone_Brick"
    },
    {
      "x": -10,
      "y": 15,
      "z": -8,
      "name": "Rock_Sandstone_Brick"
    },
    {
      "x": -10,
      "y": 16,
      "z": -8,
      "name": "Rock_Sandstone_Brick"
    },
    {
      "x": -10,
      "y": 17,
      "z": -8,
      "name": "Rock_Sandstone"
    },
    {
      "x": -10,
      "y": 18,
      "z": -8,
      "name": "Rock_Sandstone_Brick"
    },
    {
      "x": -10,
      "y": 19,
      "z": -8,
      "name": "Rock_Sandstone_Cobble"
    },
    {
      "x": -10,
      "y": 20,
      "z": -8,
      "name": "Rock_Sandstone"
    },
    {
      "x": -10,
      "y": 21,
      "z": -8,
      "name": "Rock_Sandstone_Brick"
    },
    {
      "x": -10,
      "y": 22,
      "z": -8,
      "name": "Rock_Sandstone"
    },
    {
      "x": -10,
      "y": 23,
      "z": -8,
      "name": "Rock_Sandstone_Brick",
      "rotation": 2
    },
    {
      "x": -10,
      "y": 24,
      "z": -8,
      "name": "Rock_Sandstone_Brick"
    },
    {
      "x": -10,
      "y": 25,
      "z": -8,
      "name": "Rock_Sandstone_Brick"
    },
    {
      "x": -10,
      "y": -10,
      "z": -7,
      "name": "Rock_Sandstone"
    },
    {
      "x": -10,
      "y": -9,
      "z": -7,
      "name": "Rock_Sandstone_Brick"
    },
    {
      "x": -10,
      "y": -8,
      "z": -7,
      "name": "Rock_Sandstone"
    },
    {
      "x": -10,
      "y": -7,
      "z": -7,
      "name": "Rock_Sandstone_Brick"
    },
    {
      "x": -10,
      "y": -6,
      "z": -7,
      "name": "Rock_Sandstone_Cobble"
    },
    {
      "x": -10,
      "y": -5,
      "z": -7,
      "name": "Rock_Sandstone_Brick"
    },
    {
      "x": -10,
      "y": -4,
      "z": -7,
      "name": "Rock_Sandstone_Cobble"
    },
    {
      "x": -10,
      "y": -3,
      "z": -7,
      "name": "Rock_Sandstone_Cobble"
    },
    {
      "x": -10,
      "y": -2,
      "z": -7,
      "name": "Rock_Sandstone_Brick"
    },
    {
      "x": -10,
      "y": -1,
      "z": -7,
      "name": "Rock_Sandstone_Brick"
    },
    {
      "x": -10,
      "y": 0,
      "z": -7,
      "name": "Rock_Sandstone_Brick"
    },
    {
      "x": -10,
      "y": 1,
      "z": -7,
      "name": "Rock_Sandstone_Brick"
    },
    {
      "x": -10,
      "y": 2,
      "z": -7,
      "name": "Rock_Sandstone_Brick"
    },
    {
      "x": -10,
      "y": 3,
      "z": -7,
      "name": "Rock_Sandstone_Cobble"
    },
    {
      "x": -10,
      "y": 4,
      "z": -7,
      "name": "Rock_Sandstone_Brick"
    },
    {
      "x": -10,
      "y": 5,
      "z": -7,
      "name": "Rock_Sandstone_Brick"
    },
    {
      "x": -10,
      "y": 6,
      "z": -7,
      "name": "Rock_Sandstone_Brick"
    },
    {
      "x": -10,
      "y": 7,
      "z": -7,
      "name": "Rock_Sandstone"
    },
    {
      "x": -10,
      "y": 8,
      "z": -7,
      "name": "Rock_Sandstone_Brick"
    },
    {
      "x": -10,
      "y": 9,
      "z": -7,
      "name": "Rock_Sandstone_Cobble"
    },
    {
      "x": -10,
      "y": 10,
      "z": -7,
      "name": "Rock_Sandstone_Cobble"
    },
    {
      "x": -10,
      "y": 11,
      "z": -7,
      "name": "Rock_Sandstone_Brick"
    },
    {
      "x": -10,
      "y": 12,
      "z": -7,
      "name": "Rock_Sandstone_Cobble"
    },
    {
      "x": -10,
      "y": 13,
      "z": -7,
      "name": "Rock_Sandstone_Brick"
    },
    {
      "x": -10,
      "y": 14,
      "z": -7,
      "name": "Rock_Sandstone_Brick"
    },
    {
      "x": -10,
      "y": 15,
      "z": -7,
      "name": "Rock_Sandstone_Cobble"
    },
    {
      "x": -10,
      "y": 16,
      "z": -7,
      "name": "Rock_Sandstone_Brick"
    },
    {
      "x": -10,
      "y": 17,
      "z": -7,
      "name": "Rock_Sandstone"
    },
    {
      "x": -10,
      "y": 18,
      "z": -7,
      "name": "Rock_Sandstone_Cobble"
    },
    {
      "x": -10,
      "y": 19,
      "z": -7,
      "name": "Rock_Sandstone_Brick"
    },
    {
      "x": -10,
      "y": 20,
      "z": -7,
      "name": "Rock_Sandstone_Cobble"
    },
    {
      "x": -10,
      "y": 21,
      "z": -7,
      "name": "Rock_Sandstone_Brick"
    },
    {
      "x": -10,
      "y": 22,
      "z": -7,
      "name": "Rock_Sandstone_Cobble"
    },
    {
      "x": -10,
      "y": 23,
      "z": -7,
      "name": "Rock_Sandstone_Brick",
      "rotation": 2
    },
    {
      "x": -10,
      "y": 24,
      "z": -7,
      "name": "Rock_Sandstone_Brick"
    },
    {
      "x": -10,
      "y": 25,
      "z": -7,
      "name": "Rock_Sandstone_Brick"
    },
    {
      "x": -10,
      "y": 17,
      "z": -6,
      "name": "Rock_Sandstone_Brick_Stairs",
      "rotation": 10
    },
    {
      "x": -10,
      "y": 18,
      "z": -6,
      "name": "Rock_Sandstone_Brick"
    },
    {
      "x": -10,
      "y": 19,
      "z": -6,
      "name": "Rock_Sandstone_Brick"
    },
    {
      "x": -10,
      "y": 20,
      "z": -6,
      "name": "Rock_Sandstone_Brick"
    },
    {
      "x": -10,
      "y": 21,
      "z": -6,
      "name": "Rock_Sandstone"
    },
    {
      "x": -10,
      "y": 22,
      "z": -6,
      "name": "Rock_Sandstone"
    },
    {
      "x": -10,
      "y": 23,
      "z": -6,
      "name": "Rock_Sandstone_Brick"
    },
    {
      "x": -10,
      "y": 24,
      "z": -6,
      "name": "Rock_Sandstone_Brick"
    },
    {
      "x": -10,
      "y": 25,
      "z": -6,
      "name": "Rock_Sandstone_Brick"
    },
    {
      "x": -10,
      "y": 20,
      "z": -5,
      "name": "Rock_Sandstone_Brick_Stairs",
      "rotation": 10
    },
    {
      "x": -10,
      "y": 21,
      "z": -5,
      "name": "Rock_Sandstone_Brick"
    },
    {
      "x": -10,
      "y": 22,
      "z": -5,
      "name": "Rock_Sandstone_Cobble"
    },
    {
      "x": -10,
      "y": 23,
      "z": -5,
      "name": "Rock_Sandstone_Brick"
    },
    {
      "x": -10,
      "y": 24,
      "z": -5,
      "name": "Rock_Sandstone_Brick"
    },
    {
      "x": -10,
      "y": 25,
      "z": -5,
      "name": "Rock_Sandstone_Brick"
    },
    {
      "x": -10,
      "y": 21,
      "z": -4,
      "name": "Rock_Sandstone_Brick"
    },
    {
      "x": -10,
      "y": 22,
      "z": -4,
      "name": "Rock_Sandstone_Brick"
    },
    {
      "x": -10,
      "y": 23,
      "z": -4,
      "name": "Rock_Sandstone_Brick"
    },
    {
      "x": -10,
      "y": 24,
      "z": -4,
      "name": "Rock_Sandstone_Brick"
    },
    {
      "x": -10,
      "y": 25,
      "z": -4,
      "name": "Rock_Sandstone_Brick"
    },
    {
      "x": -10,
      "y": 21,
      "z": -3,
      "name": "Rock_Sandstone_Brick_Stairs",
      "rotation": 10
    },
    {
      "x": -10,
      "y": 22,
      "z": -3,
      "name": "Rock_Sandstone_Brick",
      "rotation": 3
    },
    {
      "x": -10,
      "y": 23,
      "z": -3,
      "name": "Rock_Sandstone_Brick",
      "rotation": 3
    },
    {
      "x": -10,
      "y": 24,
      "z": -3,
      "name": "Rock_Sandstone_Brick",
      "rotation": 3
    },
    {
      "x": -10,
      "y": 25,
      "z": -3,
      "name": "Rock_Sandstone_Brick",
      "rotation": 3
    },
    {
      "x": -10,
      "y": 22,
      "z": -2,
      "name": "Rock_Sandstone_Brick",
      "rotation": 3
    },
    {
      "x": -10,
      "y": 23,
      "z": -2,
      "name": "Rock_Sandstone_Brick",
      "rotation": 3
    },
    {
      "x": -10,
      "y": 24,
      "z": -2,
      "name": "Rock_Sandstone_Brick",
      "rotation": 3
    },
    {
      "x": -10,
      "y": 25,
      "z": -2,
      "name": "Rock_Sandstone_Brick",
      "rotation": 3
    },
    {
      "x": -10,
      "y": 22,
      "z": -1,
      "name": "Rock_Sandstone_Brick"
    },
    {
      "x": -10,
      "y": 23,
      "z": -1,
      "name": "Rock_Sandstone_Brick"
    },
    {
      "x": -10,
      "y": 24,
      "z": -1,
      "name": "Rock_Sandstone_Brick"
    },
    {
      "x": -10,
      "y": 25,
      "z": -1,
      "name": "Rock_Sandstone_Brick",
      "rotation": 3
    },
    {
      "x": -10,
      "y": 22,
      "z": 0,
      "name": "Rock_Sandstone_Brick_Stairs",
      "rotation": 9
    },
    {
      "x": -10,
      "y": 23,
      "z": 0,
      "name": "Rock_Sandstone_Brick"
    },
    {
      "x": -10,
      "y": 24,
      "z": 0,
      "name": "Rock_Sandstone_Brick"
    },
    {
      "x": -10,
      "y": 25,
      "z": 0,
      "name": "Rock_Sandstone_Brick",
      "rotation": 3
    },
    {
      "x": -10,
      "y": 22,
      "z": 1,
      "name": "Rock_Sandstone_Brick_Stairs",
      "rotation": 9
    },
    {
      "x": -10,
      "y": 23,
      "z": 1,
      "name": "Rock_Sandstone_Brick"
    },
    {
      "x": -10,
      "y": 24,
      "z": 1,
      "name": "Rock_Sandstone_Brick"
    },
    {
      "x": -10,
      "y": 25,
      "z": 1,
      "name": "Rock_Sandstone_Brick",
      "rotation": 3
    },
    {
      "x": -10,
      "y": 22,
      "z": 2,
      "name": "Rock_Sandstone_Cobble"
    },
    {
      "x": -10,
      "y": 23,
      "z": 2,
      "name": "Rock_Sandstone_Brick"
    },
    {
      "x": -10,
      "y": 24,
      "z": 2,
      "name": "Rock_Sandstone_Brick_Stairs",
      "rotation": 9
    },
    {
      "x": -10,
      "y": 25,
      "z": 2,
      "name": "Rock_Sandstone_Brick",
      "rotation": 3
    },
    {
      "x": -10,
      "y": 22,
      "z": 3,
      "name": "Rock_Sandstone_Brick",
      "rotation": 3
    },
    {
      "x": -10,
      "y": 23,
      "z": 3,
      "name": "Rock_Sandstone_Brick",
      "rotation": 3
    },
    {
      "x": -10,
      "y": 24,
      "z": 3,
      "name": "Rock_Sandstone_Brick",
      "rotation": 3
    },
    {
      "x": -10,
      "y": 25,
      "z": 3,
      "name": "Rock_Sandstone_Brick",
      "rotation": 3
    },
    {
      "x": -10,
      "y": 21,
      "z": 4,
      "name": "Rock_Sandstone_Brick_Stairs",
      "rotation": 8
    },
    {
      "x": -10,
      "y": 22,
      "z": 4,
      "name": "Rock_Sandstone_Brick",
      "rotation": 3
    },
    {
      "x": -10,
      "y": 23,
      "z": 4,
      "name": "Rock_Sandstone_Brick",
      "rotation": 3
    },
    {
      "x": -10,
      "y": 24,
      "z": 4,
      "name": "Rock_Sandstone_Brick",
      "rotation": 3
    },
    {
      "x": -10,
      "y": 25,
      "z": 4,
      "name": "Rock_Sandstone_Brick",
      "rotation": 3
    },
    {
      "x": -10,
      "y": 21,
      "z": 5,
      "name": "Rock_Sandstone_Brick"
    },
    {
      "x": -10,
      "y": 22,
      "z": 5,
      "name": "Rock_Sandstone_Brick"
    },
    {
      "x": -10,
      "y": 23,
      "z": 5,
      "name": "Rock_Sandstone_Brick"
    },
    {
      "x": -10,
      "y": 24,
      "z": 5,
      "name": "Rock_Sandstone_Brick"
    },
    {
      "x": -10,
      "y": 25,
      "z": 5,
      "name": "Rock_Sandstone_Brick"
    },
    {
      "x": -10,
      "y": 20,
      "z": 6,
      "name": "Rock_Sandstone_Brick_Stairs",
      "rotation": 8
    },
    {
      "x": -10,
      "y": 21,
      "z": 6,
      "name": "Rock_Sandstone_Brick"
    },
    {
      "x": -10,
      "y": 22,
      "z": 6,
      "name": "Rock_Sandstone_Brick"
    },
    {
      "x": -10,
      "y": 23,
      "z": 6,
      "name": "Rock_Sandstone_Brick"
    },
    {
      "x": -10,
      "y": 24,
      "z": 6,
      "name": "Rock_Sandstone_Brick"
    },
    {
      "x": -10,
      "y": 25,
      "z": 6,
      "name": "Rock_Sandstone_Brick"
    },
    {
      "x": -10,
      "y": 17,
      "z": 7,
      "name": "Rock_Sandstone_Brick_Stairs",
      "rotation": 8
    },
    {
      "x": -10,
      "y": 18,
      "z": 7,
      "name": "Rock_Sandstone_Brick"
    },
    {
      "x": -10,
      "y": 19,
      "z": 7,
      "name": "Rock_Sandstone_Brick"
    },
    {
      "x": -10,
      "y": 20,
      "z": 7,
      "name": "Rock_Sandstone_Brick"
    },
    {
      "x": -10,
      "y": 21,
      "z": 7,
      "name": "Rock_Sandstone"
    },
    {
      "x": -10,
      "y": 22,
      "z": 7,
      "name": "Rock_Sandstone_Cobble"
    },
    {
      "x": -10,
      "y": 23,
      "z": 7,
      "name": "Rock_Sandstone_Brick"
    },
    {
      "x": -10,
      "y": 24,
      "z": 7,
      "name": "Rock_Sandstone_Brick"
    },
    {
      "x": -10,
      "y": 25,
      "z": 7,
      "name": "Rock_Sandstone_Brick"
    },
    {
      "x": -10,
      "y": -10,
      "z": 8,
      "name": "Rock_Sandstone_Brick"
    },
    {
      "x": -10,
      "y": -9,
      "z": 8,
      "name": "Rock_Sandstone_Brick"
    },
    {
      "x": -10,
      "y": -8,
      "z": 8,
      "name": "Rock_Sandstone_Brick"
    },
    {
      "x": -10,
      "y": -7,
      "z": 8,
      "name": "Rock_Sandstone_Brick"
    },
    {
      "x": -10,
      "y": -6,
      "z": 8,
      "name": "Rock_Sandstone_Cobble"
    },
    {
      "x": -10,
      "y": -5,
      "z": 8,
      "name": "Rock_Sandstone_Brick"
    },
    {
      "x": -10,
      "y": -4,
      "z": 8,
      "name": "Rock_Sandstone_Brick"
    },
    {
      "x": -10,
      "y": -3,
      "z": 8,
      "name": "Rock_Sandstone_Brick"
    },
    {
      "x": -10,
      "y": -2,
      "z": 8,
      "name": "Rock_Sandstone_Brick"
    },
    {
      "x": -10,
      "y": -1,
      "z": 8,
      "name": "Rock_Sandstone_Brick"
    },
    {
      "x": -10,
      "y": 0,
      "z": 8,
      "name": "Rock_Sandstone_Brick"
    },
    {
      "x": -10,
      "y": 1,
      "z": 8,
      "name": "Rock_Sandstone_Brick"
    },
    {
      "x": -10,
      "y": 2,
      "z": 8,
      "name": "Rock_Sandstone_Cobble"
    },
    {
      "x": -10,
      "y": 3,
      "z": 8,
      "name": "Rock_Sandstone_Brick"
    },
    {
      "x": -10,
      "y": 4,
      "z": 8,
      "name": "Rock_Sandstone_Cobble"
    },
    {
      "x": -10,
      "y": 5,
      "z": 8,
      "name": "Rock_Sandstone"
    },
    {
      "x": -10,
      "y": 6,
      "z": 8,
      "name": "Rock_Sandstone_Cobble"
    },
    {
      "x": -10,
      "y": 7,
      "z": 8,
      "name": "Rock_Sandstone_Brick"
    },
    {
      "x": -10,
      "y": 8,
      "z": 8,
      "name": "Rock_Sandstone_Brick"
    },
    {
      "x": -10,
      "y": 9,
      "z": 8,
      "name": "Rock_Sandstone_Brick"
    },
    {
      "x": -10,
      "y": 10,
      "z": 8,
      "name": "Rock_Sandstone_Brick"
    },
    {
      "x": -10,
      "y": 11,
      "z": 8,
      "name": "Rock_Sandstone"
    },
    {
      "x": -10,
      "y": 12,
      "z": 8,
      "name": "Rock_Sandstone_Brick"
    },
    {
      "x": -10,
      "y": 13,
      "z": 8,
      "name": "Rock_Sandstone_Brick"
    },
    {
      "x": -10,
      "y": 14,
      "z": 8,
      "name": "Rock_Sandstone_Brick"
    },
    {
      "x": -10,
      "y": 15,
      "z": 8,
      "name": "Rock_Sandstone"
    },
    {
      "x": -10,
      "y": 16,
      "z": 8,
      "name": "Rock_Sandstone_Brick"
    },
    {
      "x": -10,
      "y": 17,
      "z": 8,
      "name": "Rock_Sandstone_Brick"
    },
    {
      "x": -10,
      "y": 18,
      "z": 8,
      "name": "Rock_Sandstone_Brick"
    },
    {
      "x": -10,
      "y": 19,
      "z": 8,
      "name": "Rock_Sandstone_Brick"
    },
    {
      "x": -10,
      "y": 20,
      "z": 8,
      "name": "Rock_Sandstone_Cobble"
    },
    {
      "x": -10,
      "y": 21,
      "z": 8,
      "name": "Rock_Sandstone_Brick"
    },
    {
      "x": -10,
      "y": 22,
      "z": 8,
      "name": "Rock_Sandstone"
    },
    {
      "x": -10,
      "y": 23,
      "z": 8,
      "name": "Rock_Sandstone_Brick"
    },
    {
      "x": -10,
      "y": 24,
      "z": 8,
      "name": "Rock_Sandstone_Brick"
    },
    {
      "x": -10,
      "y": 25,
      "z": 8,
      "name": "Rock_Sandstone_Brick"
    },
    {
      "x": -10,
      "y": -10,
      "z": 9,
      "name": "Rock_Sandstone_Brick"
    },
    {
      "x": -10,
      "y": -9,
      "z": 9,
      "name": "Rock_Sandstone_Cobble"
    },
    {
      "x": -10,
      "y": -8,
      "z": 9,
      "name": "Rock_Sandstone_Brick"
    },
    {
      "x": -10,
      "y": -7,
      "z": 9,
      "name": "Rock_Sandstone"
    },
    {
      "x": -10,
      "y": -6,
      "z": 9,
      "name": "Rock_Sandstone_Brick"
    },
    {
      "x": -10,
      "y": -5,
      "z": 9,
      "name": "Rock_Sandstone_Cobble"
    },
    {
      "x": -10,
      "y": -4,
      "z": 9,
      "name": "Rock_Sandstone_Brick"
    },
    {
      "x": -10,
      "y": -3,
      "z": 9,
      "name": "Rock_Sandstone_Brick"
    },
    {
      "x": -10,
      "y": -2,
      "z": 9,
      "name": "Rock_Sandstone"
    },
    {
      "x": -10,
      "y": -1,
      "z": 9,
      "name": "Rock_Sandstone_Brick"
    },
    {
      "x": -10,
      "y": 0,
      "z": 9,
      "name": "Rock_Sandstone_Brick"
    },
    {
      "x": -10,
      "y": 1,
      "z": 9,
      "name": "Rock_Sandstone_Brick"
    },
    {
      "x": -10,
      "y": 2,
      "z": 9,
      "name": "Rock_Sandstone_Brick"
    },
    {
      "x": -10,
      "y": 3,
      "z": 9,
      "name": "Rock_Sandstone_Brick"
    },
    {
      "x": -10,
      "y": 4,
      "z": 9,
      "name": "Rock_Sandstone_Brick"
    },
    {
      "x": -10,
      "y": 5,
      "z": 9,
      "name": "Rock_Sandstone"
    },
    {
      "x": -10,
      "y": 6,
      "z": 9,
      "name": "Rock_Sandstone"
    },
    {
      "x": -10,
      "y": 7,
      "z": 9,
      "name": "Rock_Sandstone_Brick"
    },
    {
      "x": -10,
      "y": 8,
      "z": 9,
      "name": "Rock_Sandstone"
    },
    {
      "x": -10,
      "y": 9,
      "z": 9,
      "name": "Rock_Sandstone_Brick"
    },
    {
      "x": -10,
      "y": 10,
      "z": 9,
      "name": "Rock_Sandstone_Brick"
    },
    {
      "x": -10,
      "y": 11,
      "z": 9,
      "name": "Rock_Sandstone"
    },
    {
      "x": -10,
      "y": 12,
      "z": 9,
      "name": "Rock_Sandstone_Cobble"
    },
    {
      "x": -10,
      "y": 13,
      "z": 9,
      "name": "Rock_Sandstone_Cobble"
    },
    {
      "x": -10,
      "y": 14,
      "z": 9,
      "name": "Rock_Sandstone_Brick"
    },
    {
      "x": -10,
      "y": 15,
      "z": 9,
      "name": "Rock_Sandstone_Brick"
    },
    {
      "x": -10,
      "y": 16,
      "z": 9,
      "name": "Rock_Sandstone_Brick"
    },
    {
      "x": -10,
      "y": 17,
      "z": 9,
      "name": "Rock_Sandstone_Brick"
    },
    {
      "x": -10,
      "y": 18,
      "z": 9,
      "name": "Rock_Sandstone_Brick"
    },
    {
      "x": -10,
      "y": 19,
      "z": 9,
      "name": "Rock_Sandstone_Brick"
    },
    {
      "x": -10,
      "y": 20,
      "z": 9,
      "name": "Rock_Sandstone"
    },
    {
      "x": -10,
      "y": 21,
      "z": 9,
      "name": "Rock_Sandstone"
    },
    {
      "x": -10,
      "y": 22,
      "z": 9,
      "name": "Rock_Sandstone"
    },
    {
      "x": -10,
      "y": 23,
      "z": 9,
      "name": "Rock_Sandstone_Brick"
    },
    {
      "x": -10,
      "y": 24,
      "z": 9,
      "name": "Rock_Sandstone_Brick"
    },
    {
      "x": -10,
      "y": 25,
      "z": 9,
      "name": "Rock_Sandstone_Brick"
    },
    {
      "x": -10,
      "y": -10,
      "z": 10,
      "name": "Rock_Sandstone_Brick"
    },
    {
      "x": -10,
      "y": -9,
      "z": 10,
      "name": "Rock_Sandstone_Brick"
    },
    {
      "x": -10,
      "y": -8,
      "z": 10,
      "name": "Rock_Sandstone_Brick"
    },
    {
      "x": -10,
      "y": -7,
      "z": 10,
      "name": "Rock_Sandstone_Cobble"
    },
    {
      "x": -10,
      "y": -6,
      "z": 10,
      "name": "Rock_Sandstone_Brick"
    },
    {
      "x": -10,
      "y": -5,
      "z": 10,
      "name": "Rock_Sandstone_Brick"
    },
    {
      "x": -10,
      "y": -4,
      "z": 10,
      "name": "Rock_Sandstone_Brick"
    },
    {
      "x": -10,
      "y": -3,
      "z": 10,
      "name": "Rock_Sandstone"
    },
    {
      "x": -10,
      "y": -2,
      "z": 10,
      "name": "Rock_Sandstone_Brick"
    },
    {
      "x": -10,
      "y": -1,
      "z": 10,
      "name": "Rock_Sandstone_Cobble"
    },
    {
      "x": -10,
      "y": 0,
      "z": 10,
      "name": "Rock_Sandstone"
    },
    {
      "x": -10,
      "y": 1,
      "z": 10,
      "name": "Rock_Sandstone_Brick"
    },
    {
      "x": -10,
      "y": 2,
      "z": 10,
      "name": "Rock_Sandstone_Brick"
    },
    {
      "x": -10,
      "y": 3,
      "z": 10,
      "name": "Rock_Sandstone_Cobble"
    },
    {
      "x": -10,
      "y": 4,
      "z": 10,
      "name": "Rock_Sandstone_Cobble"
    },
    {
      "x": -10,
      "y": 5,
      "z": 10,
      "name": "Rock_Sandstone_Brick"
    },
    {
      "x": -10,
      "y": 6,
      "z": 10,
      "name": "Rock_Sandstone"
    },
    {
      "x": -10,
      "y": 7,
      "z": 10,
      "name": "Rock_Sandstone_Brick"
    },
    {
      "x": -10,
      "y": 8,
      "z": 10,
      "name": "Rock_Sandstone_Brick"
    },
    {
      "x": -10,
      "y": 9,
      "z": 10,
      "name": "Rock_Sandstone"
    },
    {
      "x": -10,
      "y": 10,
      "z": 10,
      "name": "Rock_Sandstone_Brick"
    },
    {
      "x": -10,
      "y": 11,
      "z": 10,
      "name": "Rock_Sandstone_Brick"
    },
    {
      "x": -10,
      "y": 12,
      "z": 10,
      "name": "Rock_Sandstone_Cobble"
    },
    {
      "x": -10,
      "y": 13,
      "z": 10,
      "name": "Rock_Sandstone"
    },
    {
      "x": -10,
      "y": 14,
      "z": 10,
      "name": "Rock_Sandstone_Brick"
    },
    {
      "x": -10,
      "y": 15,
      "z": 10,
      "name": "Rock_Sandstone_Brick"
    },
    {
      "x": -10,
      "y": 16,
      "z": 10,
      "name": "Rock_Sandstone_Cobble"
    },
    {
      "x": -10,
      "y": 17,
      "z": 10,
      "name": "Rock_Sandstone_Cobble"
    },
    {
      "x": -10,
      "y": 18,
      "z": 10,
      "name": "Rock_Sandstone_Brick"
    },
    {
      "x": -10,
      "y": 19,
      "z": 10,
      "name": "Rock_Sandstone_Cobble"
    },
    {
      "x": -10,
      "y": 20,
      "z": 10,
      "name": "Rock_Sandstone_Brick"
    },
    {
      "x": -10,
      "y": 21,
      "z": 10,
      "name": "Rock_Sandstone"
    },
    {
      "x": -10,
      "y": 22,
      "z": 10,
      "name": "Rock_Sandstone_Brick"
    },
    {
      "x": -10,
      "y": 23,
      "z": 10,
      "name": "Rock_Sandstone_Brick"
    },
    {
      "x": -10,
      "y": 24,
      "z": 10,
      "name": "Rock_Sandstone_Brick"
    },
    {
      "x": -10,
      "y": 25,
      "z": 10,
      "name": "Rock_Sandstone_Brick"
    },
    {
      "x": -10,
      "y": -10,
      "z": 11,
      "name": "Rock_Sandstone"
    },
    {
      "x": -10,
      "y": -9,
      "z": 11,
      "name": "Rock_Sandstone"
    },
    {
      "x": -10,
      "y": -8,
      "z": 11,
      "name": "Rock_Sandstone_Brick"
    },
    {
      "x": -10,
      "y": -7,
      "z": 11,
      "name": "Rock_Sandstone_Brick"
    },
    {
      "x": -10,
      "y": -6,
      "z": 11,
      "name": "Rock_Sandstone_Brick"
    },
    {
      "x": -10,
      "y": -5,
      "z": 11,
      "name": "Rock_Sandstone_Brick"
    },
    {
      "x": -10,
      "y": -4,
      "z": 11,
      "name": "Rock_Sandstone"
    },
    {
      "x": -10,
      "y": -3,
      "z": 11,
      "name": "Rock_Sandstone_Brick"
    },
    {
      "x": -10,
      "y": -2,
      "z": 11,
      "name": "Rock_Sandstone_Cobble"
    },
    {
      "x": -10,
      "y": -1,
      "z": 11,
      "name": "Rock_Sandstone"
    },
    {
      "x": -10,
      "y": 0,
      "z": 11,
      "name": "Rock_Sandstone"
    },
    {
      "x": -10,
      "y": 1,
      "z": 11,
      "name": "Rock_Sandstone_Brick"
    },
    {
      "x": -10,
      "y": 2,
      "z": 11,
      "name": "Rock_Sandstone_Cobble"
    },
    {
      "x": -10,
      "y": 3,
      "z": 11,
      "name": "Rock_Sandstone_Brick"
    },
    {
      "x": -10,
      "y": 4,
      "z": 11,
      "name": "Rock_Sandstone"
    },
    {
      "x": -10,
      "y": 5,
      "z": 11,
      "name": "Rock_Sandstone_Brick"
    },
    {
      "x": -10,
      "y": 6,
      "z": 11,
      "name": "Rock_Sandstone_Brick"
    },
    {
      "x": -10,
      "y": 7,
      "z": 11,
      "name": "Rock_Sandstone"
    },
    {
      "x": -10,
      "y": 8,
      "z": 11,
      "name": "Rock_Sandstone"
    },
    {
      "x": -10,
      "y": 9,
      "z": 11,
      "name": "Rock_Sandstone_Brick"
    },
    {
      "x": -10,
      "y": 10,
      "z": 11,
      "name": "Rock_Sandstone_Brick"
    },
    {
      "x": -10,
      "y": 11,
      "z": 11,
      "name": "Rock_Sandstone_Brick"
    },
    {
      "x": -10,
      "y": 12,
      "z": 11,
      "name": "Rock_Sandstone_Brick"
    },
    {
      "x": -10,
      "y": 13,
      "z": 11,
      "name": "Rock_Sandstone_Brick",
      "rotation": 1
    },
    {
      "x": -10,
      "y": 14,
      "z": 11,
      "name": "Rock_Sandstone_Brick"
    },
    {
      "x": -10,
      "y": 15,
      "z": 11,
      "name": "Rock_Sandstone_Brick"
    },
    {
      "x": -10,
      "y": 16,
      "z": 11,
      "name": "Rock_Sandstone_Brick"
    },
    {
      "x": -10,
      "y": 17,
      "z": 11,
      "name": "Rock_Sandstone_Cobble"
    },
    {
      "x": -10,
      "y": 18,
      "z": 11,
      "name": "Rock_Sandstone_Brick"
    },
    {
      "x": -10,
      "y": 19,
      "z": 11,
      "name": "Rock_Sandstone"
    },
    {
      "x": -10,
      "y": 20,
      "z": 11,
      "name": "Rock_Sandstone_Brick"
    },
    {
      "x": -10,
      "y": 21,
      "z": 11,
      "name": "Rock_Sandstone"
    },
    {
      "x": -10,
      "y": 22,
      "z": 11,
      "name": "Rock_Sandstone"
    },
    {
      "x": -10,
      "y": 23,
      "z": 11,
      "name": "Rock_Sandstone_Brick"
    },
    {
      "x": -10,
      "y": 24,
      "z": 11,
      "name": "Rock_Sandstone_Brick"
    },
    {
      "x": -10,
      "y": 25,
      "z": 11,
      "name": "Rock_Sandstone_Brick"
    },
    {
      "x": -10,
      "y": -10,
      "z": 12,
      "name": "Rock_Sandstone_Cobble"
    },
    {
      "x": -10,
      "y": -9,
      "z": 12,
