{
  "version": 8,
  "blockIdVersion": 11,
  "anchorX": 0,
  "anchorY": 1,
  "anchorZ": 1,
  "blocks": [
    {
      "x": -1,
      "y": 5,
      "z": 0,
      "name": "Plant_Leaves_Rubber"
    },
    {
      "x": -1,
      "y": -1,
      "z": 1,
      "name": "Rubber_Branch_Long",
      "support": 15
    },
    {
      "x": -1,
      "y": 0,
      "z": 1,
      "name": "Rubber_Branch_Long"
    },
    {
      "x": -1,
      "y": 1,
      "z": 1,
      "name": "Rubber_Branch_Corner",
      "rotation": 9
    },
    {
      "x": -1,
      "y": 7,
      "z": 1,
      "name": "Plant_Leaves_Rubber"
    },
    {
      "x": -1,
      "y": 9,
      "z": 1,
      "name": "Plant_Leaves_Rubber"
    },
    {
      "x": -1,
      "y": 10,
      "z": 1,
      "name": "Plant_Leaves_Rubber"
    },
    {
      "x": -1,
      "y": 5,
      "z": 2,
      "name": "Plant_Leaves_Rubber"
    },
    {
      "x": -1,
      "y": 6,
      "z": 2,
      "name": "Plant_Leaves_Rubber"
    },
    {
      "x": -1,
      "y": 7,
      "z": 2,
      "name": "Plant_Leaves_Rubber"
    },
    {
      "x": 0,
      "y": 5,
      "z": -1,
      "name": "Plant_Leaves_Rubber"
    },
    {
      "x": 0,
      "y": 6,
      "z": -1,
      "name": "Plant_Leaves_Rubber"
    },
    {
      "x": 0,
      "y": 4,
      "z": 0,
      "name": "Plant_Leaves_Rubber"
    },
    {
      "x": 0,
      "y": 5,
      "z": 0,
      "name": "Rubber_Branch_Corner",
      "rotation": 2
    },
    {
      "x": 0,
      "y": 6,
      "z": 0,
      "name": "Plant_Leaves_Rubber"
    },
    {
      "x": 0,
      "y": 7,
      "z": 0,
      "name": "Plant_Leaves_Rubber"
    },
    {
      "x": 0,
      "y": 8,
      "z": 0,
      "name": "Plant_Leaves_Rubber"
    },
    {
      "x": 0,
      "y": 10,
      "z": 0,
      "name": "Plant_Leaves_Rubber"
    },
    {
      "x": 0,
      "y": -1,
      "z": 1,
      "name": "Rubber_Branch_Long",
      "support": 15
    },
    {
      "x": 0,
      "y": 0,
      "z": 1,
      "name": "Rubber_Branch_Long"
    },
    {
      "x": 0,
      "y": 1,
      "z": 1,
      "name": "Rubber_Branch_T_Sideways",
      "rotation": 2
    },
    {
      "x": 0,
      "y": 2,
      "z": 1,
      "name": "Rubber_Branch_Corner",
      "rotation": 8
    },
    {
      "x": 0,
      "y": 3,
      "z": 1,
      "name": "Rubber_Branch_Corner",
      "rotation": 2
    },
    {
      "x": 0,
      "y": 4,
      "z": 1,
      "name": "Rubber_Branch_T_Sideways"
    },
    {
      "x": 0,
      "y": 5,
      "z": 1,
      "name": "Rubber_Branch_T_Sideways",
      "rotation": 1
    },
    {
      "x": 0,
      "y": 6,
      "z": 1,
      "name": "Rubber_Branch_Long"
    },
    {
      "x": 0,
      "y": 7,
      "z": 1,
      "name": "Rubber_Branch_Long"
    },
    {
      "x": 0,
      "y": 8,
      "z": 1,
      "name": "Plant_Leaves_Rubber"
    },
    {
      "x": 0,
      "y": 9,
      "z": 1,
      "name": "Plant_Leaves_Rubber"
    },
    {
      "x": 0,
      "y": 10,
      "z": 1,
      "name": "Plant_Leaves_Rubber"
    },
    {
      "x": 0,
      "y": 11,
      "z": 1,
      "name": "Plant_Leaves_Rubber"
    },
    {
      "x": 0,
      "y": -1,
      "z": 2,
      "name": "Rubber_Branch_Long",
      "support": 15
    },
    {
      "x": 0,
      "y": 0,
      "z": 2,
      "name": "Rubber_Branch_Long"
    },
    {
      "x": 0,
      "y": 1,
      "z": 2,
      "name": "Rubber_Branch_Long"
    },
    {
      "x": 0,
      "y": 2,
      "z": 2,
      "name": "Rubber_Branch_T_Sideways",
      "rotation": 1
    },
    {
      "x": 0,
      "y": 3,
      "z": 2,
      "name": "Rubber_Branch_Corner",
      "rotation": 10
    },
    {
      "x": 0,
      "y": 6,
      "z": 2,
      "name": "Plant_Leaves_Rubber"
    },
    {
      "x": 0,
      "y": 7,
      "z": 2,
      "name": "Plant_Leaves_Rubber"
    },
    {
      "x": 0,
      "y": 9,
      "z": 2,
      "name": "Plant_Leaves_Rubber"
    },
    {
      "x": 1,
      "y": 5,
      "z": 0,
      "name": "Plant_Leaves_Rubber"
    },
    {
      "x": 1,
      "y": 6,
      "z": 0,
      "name": "Plant_Leaves_Rubber"
    },
    {
      "x": 1,
      "y": 7,
      "z": 0,
      "name": "Plant_Leaves_Rubber"
    },
    {
      "x": 1,
      "y": 4,
      "z": 1,
      "name": "Rubber_Branch_Corner",
      "rotation": 1
    },
    {
      "x": 1,
      "y": 5,
      "z": 1,
      "name": "Rubber_Branch_Long"
    },
    {
      "x": 1,
      "y": 6,
      "z": 1,
      "name": "Rubber_Branch_Long"
    },
    {
      "x": 1,
      "y": 7,
      "z": 1,
      "name": "Plant_Leaves_Rubber"
    },
    {
      "x": 1,
      "y": 8,
      "z": 1,
      "name": "Plant_Leaves_Rubber"
    },
    {
      "x": 1,
      "y": 6,
      "z": 2,
      "name": "Plant_Leaves_Rubber"
    },
    {
      "x": 1,
      "y": 7,
      "z": 2,
      "name": "Plant_Leaves_Rubber"
    },
    {
      "x": 2,
      "y": 6,
      "z": 1,
      "name": "Plant_Leaves_Rubber"
    }
  ]
}