{
  "version": 8,
  "blockIdVersion": 11,
  "anchorX": 0,
  "anchorY": 1,
  "anchorZ": 0,
  "blocks": [
    {
      "x": -3,
      "y": 8,
      "z": -4,
      "name": "Plant_Leaves_Rubber"
    },
    {
      "x": -3,
      "y": 9,
      "z": -4,
      "name": "Plant_Leaves_Rubber"
    },
    {
      "x": -3,
      "y": 7,
      "z": -3,
      "name": "Plant_Leaves_Rubber"
    },
    {
      "x": -3,
      "y": 8,
      "z": -3,
      "name": "Plant_Leaves_Rubber"
    },
    {
      "x": -3,
      "y": 9,
      "z": -3,
      "name": "Plant_Leaves_Rubber"
    },
    {
      "x": -3,
      "y": 10,
      "z": -3,
      "name": "Plant_Leaves_Rubber"
    },
    {
      "x": -3,
      "y": 9,
      "z": -2,
      "name": "Plant_Leaves_Rubber"
    },
    {
      "x": -3,
      "y": -1,
      "z": 0,
      "name": "Rubber_Branch_Long",
      "support": 15
    },
    {
      "x": -3,
      "y": 0,
      "z": 0,
      "name": "Rubber_Branch_Long"
    },
    {
      "x": -3,
      "y": 1,
      "z": 0,
      "name": "Rubber_Branch_Long"
    },
    {
      "x": -3,
      "y": 2,
      "z": 0,
      "name": "Rubber_Branch_Corner",
      "rotation": 9
    },
    {
      "x": -2,
      "y": 8,
      "z": -4,
      "name": "Plant_Leaves_Rubber"
    },
    {
      "x": -2,
      "y": 9,
      "z": -4,
      "name": "Plant_Leaves_Rubber"
    },
    {
      "x": -2,
      "y": 10,
      "z": -4,
      "name": "Plant_Leaves_Rubber"
    },
    {
      "x": -2,
      "y": 11,
      "z": -4,
      "name": "Plant_Leaves_Rubber"
    },
    {
      "x": -2,
      "y": 4,
      "z": -3,
      "name": "Plant_Leaves_Rubber"
    },
    {
      "x": -2,
      "y": 5,
      "z": -3,
      "name": "Plant_Leaves_Rubber"
    },
    {
      "x": -2,
      "y": 6,
      "z": -3,
      "name": "Rubber_Branch_Corner",
      "rotation": 2
    },
    {
      "x": -2,
      "y": 7,
      "z": -3,
      "name": "Rubber_Branch_Long"
    },
    {
      "x": -2,
      "y": 8,
      "z": -3,
      "name": "Rubber_Branch_Long"
    },
    {
      "x": -2,
      "y": 9,
      "z": -3,
      "name": "Rubber_Branch_Long"
    },
    {
      "x": -2,
      "y": 10,
      "z": -3,
      "name": "Plant_Leaves_Rubber"
    },
    {
      "x": -2,
      "y": 11,
      "z": -3,
      "name": "Plant_Leaves_Rubber"
    },
    {
      "x": -2,
      "y": 12,
      "z": -3,
      "name": "Plant_Leaves_Rubber"
    },
    {
      "x": -2,
      "y": 13,
      "z": -3,
      "name": "Plant_Leaves_Rubber"
    },
    {
      "x": -2,
      "y": 14,
      "z": -3,
      "name": "Plant_Leaves_Rubber"
    },
    {
      "x": -2,
      "y": 15,
      "z": -3,
      "name": "Plant_Leaves_Rubber"
    },
    {
      "x": -2,
      "y": 5,
      "z": -2,
      "name": "Rubber_Branch_Corner",
      "rotation": 3
    },
    {
      "x": -2,
      "y": 6,
      "z": -2,
      "name": "Rubber_Branch_T_Sideways",
      "rotation": 1
    },
    {
      "x": -2,
      "y": 7,
      "z": -2,
      "name": "Rubber_Branch_Long"
    },
    {
      "x": -2,
      "y": 8,
      "z": -2,
      "name": "Rubber_Branch_Corner",
      "rotation": 8
    },
    {
      "x": -2,
      "y": 9,
      "z": -2,
      "name": "Plant_Leaves_Rubber"
    },
    {
      "x": -2,
      "y": 10,
      "z": -2,
      "name": "Plant_Leaves_Rubber"
    },
    {
      "x": -2,
      "y": 8,
      "z": -1,
      "name": "Rubber_Branch_Corner",
      "rotation": 19
    },
    {
      "x": -2,
      "y": 11,
      "z": -1,
      "name": "Plant_Leaves_Rubber"
    },
    {
      "x": -2,
      "y": 13,
      "z": -1,
      "name": "Plant_Leaves_Rubber"
    },
    {
      "x": -2,
      "y": -1,
      "z": 0,
      "name": "Rubber_Branch_Long",
      "support": 15
    },
    {
      "x": -2,
      "y": 0,
      "z": 0,
      "name": "Rubber_Branch_Long"
    },
    {
      "x": -2,
      "y": 1,
      "z": 0,
      "name": "Rubber_Branch_Long"
    },
    {
      "x": -2,
      "y": 2,
      "z": 0,
      "name": "Rubber_Branch_T_Sideways",
      "rotation": 2
    },
    {
      "x": -2,
      "y": 3,
      "z": 0,
      "name": "Rubber_Branch_Corner",
      "rotation": 8
    },
    {
      "x": -2,
      "y": 10,
      "z": 0,
      "name": "Plant_Leaves_Rubber"
    },
    {
      "x": -2,
      "y": 11,
      "z": 0,
      "name": "Plant_Leaves_Rubber"
    },
    {
      "x": -2,
      "y": 12,
      "z": 0,
      "name": "Plant_Leaves_Rubber"
    },
    {
      "x": -2,
      "y": 13,
      "z": 0,
      "name": "Plant_Leaves_Rubber"
    },
    {
      "x": -2,
      "y": 14,
      "z": 0,
      "name": "Plant_Leaves_Rubber"
    },
    {
      "x": -2,
      "y": -1,
      "z": 1,
      "name": "Rubber_Branch_Long",
      "support": 15
    },
    {
      "x": -2,
      "y": 0,
      "z": 1,
      "name": "Rubber_Branch_Long"
    },
    {
      "x": -2,
      "y": 1,
      "z": 1,
      "name": "Rubber_Branch_Corner",
      "rotation": 9
    },
    {
      "x": -2,
      "y": 3,
      "z": 1,
      "name": "Rubber_Branch_Corner",
      "rotation": 19
    },
    {
      "x": -2,
      "y": 13,
      "z": 1,
      "name": "Plant_Leaves_Rubber"
    },
    {
      "x": -2,
      "y": 14,
      "z": 1,
      "name": "Plant_Leaves_Rubber"
    },
    {
      "x": -2,
      "y": 2,
      "z": 2,
      "name": "Rubber_Branch_Corner",
      "rotation": 3
    },
    {
      "x": -2,
      "y": 3,
      "z": 2,
      "name": "Rubber_Branch_Corner",
      "rotation": 9
    },
    {
      "x": -1,
      "y": 8,
      "z": -4,
      "name": "Plant_Leaves_Rubber"
    },
    {
      "x": -1,
      "y": 9,
      "z": -4,
      "name": "Plant_Leaves_Rubber"
    },
    {
      "x": -1,
      "y": 10,
      "z": -4,
      "name": "Plant_Leaves_Rubber"
    },
    {
      "x": -1,
      "y": 6,
      "z": -3,
      "name": "Plant_Leaves_Rubber"
    },
    {
      "x": -1,
      "y": 7,
      "z": -3,
      "name": "Plant_Leaves_Rubber"
    },
    {
      "x": -1,
      "y": 9,
      "z": -3,
      "name": "Plant_Leaves_Rubber"
    },
    {
      "x": -1,
      "y": 10,
      "z": -3,
      "name": "Plant_Leaves_Rubber"
    },
    {
      "x": -1,
      "y": 5,
      "z": -2,
      "name": "Rubber_Branch_Corner",
      "rotation": 17
    },
    {
      "x": -1,
      "y": 13,
      "z": -2,
      "name": "Plant_Leaves_Rubber"
    },
    {
      "x": -1,
      "y": 3,
      "z": -1,
      "name": "Rubber_Branch_Corner",
      "rotation": 3
    },
    {
      "x": -1,
      "y": 4,
      "z": -1,
      "name": "Rubber_Branch_Corner",
      "rotation": 9
    },
    {
      "x": -1,
      "y": 5,
      "z": -1,
      "name": "Rubber_Branch_Long",
      "rotation": 4
    },
    {
      "x": -1,
      "y": 8,
      "z": -1,
      "name": "Rubber_Branch_Long",
      "rotation": 5
    },
    {
      "x": -1,
      "y": 10,
      "z": -1,
      "name": "Plant_Leaves_Rubber"
    },
    {
      "x": -1,
      "y": 11,
      "z": -1,
      "name": "Plant_Leaves_Rubber"
    },
    {
      "x": -1,
      "y": 12,
      "z": -1,
      "name": "Plant_Leaves_Rubber"
    },
    {
      "x": -1,
      "y": 13,
      "z": -1,
      "name": "Plant_Leaves_Rubber"
    },
    {
      "x": -1,
      "y": 14,
      "z": -1,
      "name": "Plant_Leaves_Rubber"
    },
    {
      "x": -1,
      "y": -1,
      "z": 0,
      "name": "Rubber_Branch_Long",
      "support": 15
    },
    {
      "x": -1,
      "y": 0,
      "z": 0,
      "name": "Rubber_Branch_Long"
    },
    {
      "x": -1,
      "y": 1,
      "z": 0,
      "name": "Rubber_Branch_Corner",
      "rotation": 8
    },
    {
      "x": -1,
      "y": 5,
      "z": 0,
      "name": "Rubber_Branch_Long",
      "rotation": 4
    },
    {
      "x": -1,
      "y": 10,
      "z": 0,
      "name": "Rubber_Branch_Corner",
      "rotation": 3
    },
    {
      "x": -1,
      "y": 11,
      "z": 0,
      "name": "Rubber_Branch_Long"
    },
    {
      "x": -1,
      "y": 12,
      "z": 0,
      "name": "Rubber_Branch_Long"
    },
    {
      "x": -1,
      "y": 13,
      "z": 0,
      "name": "Rubber_Branch_Long"
    },
    {
      "x": -1,
      "y": 14,
      "z": 0,
      "name": "Plant_Leaves_Rubber"
    },
    {
      "x": -1,
      "y": 15,
      "z": 0,
      "name": "Plant_Leaves_Rubber"
    },
    {
      "x": -1,
      "y": 16,
      "z": 0,
      "name": "Plant_Leaves_Rubber"
    },
    {
      "x": -1,
      "y": 17,
      "z": 0,
      "name": "Plant_Leaves_Rubber"
    },
    {
      "x": -1,
      "y": 18,
      "z": 0,
      "name": "Plant_Leaves_Rubber"
    },
    {
      "x": -1,
      "y": 1,
      "z": 1,
      "name": "Rubber_Branch_X",
      "rotation": 6
    },
    {
      "x": -1,
      "y": 3,
      "z": 1,
      "name": "Rubber_Branch_Corner",
      "rotation": 17
    },
    {
      "x": -1,
      "y": 5,
      "z": 1,
      "name": "Rubber_Branch_Corner",
      "rotation": 19
    },
    {
      "x": -1,
      "y": 10,
      "z": 1,
      "name": "Plant_Leaves_Rubber"
    },
    {
      "x": -1,
      "y": 11,
      "z": 1,
      "name": "Plant_Leaves_Rubber"
    },
    {
      "x": -1,
      "y": 12,
      "z": 1,
      "name": "Plant_Leaves_Rubber"
    },
    {
      "x": -1,
      "y": 13,
      "z": 1,
      "name": "Plant_Leaves_Rubber"
    },
    {
      "x": -1,
      "y": 14,
      "z": 1,
      "name": "Plant_Leaves_Rubber"
    },
    {
      "x": -1,
      "y": 15,
      "z": 1,
      "name": "Plant_Leaves_Rubber"
    },
    {
      "x": -1,
      "y": -1,
      "z": 2,
      "name": "Rubber_Branch_Long",
      "support": 15
    },
    {
      "x": -1,
      "y": 0,
      "z": 2,
      "name": "Rubber_Branch_Long"
    },
    {
      "x": -1,
      "y": 1,
      "z": 2,
      "name": "Rubber_Branch_T_Sideways",
      "rotation": 1
    },
    {
      "x": -1,
      "y": 2,
      "z": 2,
      "name": "Rubber_Branch_Corner",
      "rotation": 11
    },
    {
      "x": -1,
      "y": 3,
      "z": 2,
      "name": "Rubber_Branch_X",
      "rotation": 6
    },
    {
      "x": -1,
      "y": 5,
      "z": 2,
      "name": "Plant_Leaves_Rubber"
    },
    {
      "x": -1,
      "y": 12,
      "z": 2,
      "name": "Plant_Leaves_Rubber"
    },
    {
      "x": -1,
      "y": 13,
      "z": 2,
      "name": "Plant_Leaves_Rubber"
    },
    {
      "x": -1,
      "y": 3,
      "z": 3,
      "name": "Rubber_Branch_T",
      "rotation": 3
    },
    {
      "x": -1,
      "y": 4,
      "z": 3,
      "name": "Rubber_Branch_Corner",
      "rotation": 9
    },
    {
      "x": -1,
      "y": 5,
      "z": 3,
      "name": "Plant_Leaves_Rubber"
    },
    {
      "x": -1,
      "y": 6,
      "z": 3,
      "name": "Plant_Leaves_Rubber"
    },
    {
      "x": -1,
      "y": -1,
      "z": 4,
      "name": "Rubber_Branch_Long",
      "support": 15
    },
    {
      "x": -1,
      "y": 0,
      "z": 4,
      "name": "Rubber_Branch_Long"
    },
    {
      "x": -1,
      "y": 1,
      "z": 4,
      "name": "Rubber_Branch_Long"
    },
    {
      "x": -1,
      "y": 2,
      "z": 4,
      "name": "Rubber_Branch_Long"
    },
    {
      "x": -1,
      "y": 3,
      "z": 4,
      "name": "Rubber_Branch_Corner",
      "rotation": 10
    },
    {
      "x": -1,
      "y": 5,
      "z": 4,
      "name": "Plant_Leaves_Rubber"
    },
    {
      "x": 0,
      "y": -1,
      "z": -3,
      "name": "Rubber_Branch_Long",
      "support": 15
    },
    {
      "x": 0,
      "y": 0,
      "z": -3,
      "name": "Rubber_Branch_Long"
    },
    {
      "x": 0,
      "y": 1,
      "z": -3,
      "name": "Rubber_Branch_Long"
    },
    {
      "x": 0,
      "y": 2,
      "z": -3,
      "name": "Rubber_Branch_Corner",
      "rotation": 8
    },
    {
      "x": 0,
      "y": 13,
      "z": -3,
      "name": "Plant_Leaves_Rubber"
    },
    {
      "x": 0,
      "y": -1,
      "z": -2,
      "name": "Rubber_Branch_Long",
      "support": 15
    },
    {
      "x": 0,
      "y": 0,
      "z": -2,
      "name": "Rubber_Branch_Long"
    },
    {
      "x": 0,
      "y": 1,
      "z": -2,
      "name": "Rubber_Branch_Long"
    },
    {
      "x": 0,
      "y": 2,
      "z": -2,
      "name": "Rubber_Branch_T_Sideways",
      "rotation": 1
    },
    {
      "x": 0,
      "y": 3,
      "z": -2,
      "name": "Rubber_Branch_T_Sideways",
      "rotation": 3
    },
    {
      "x": 0,
      "y": 4,
      "z": -2,
      "name": "Rubber_Branch_T_Sideways",
      "rotation": 3
    },
    {
      "x": 0,
      "y": 5,
      "z": -2,
      "name": "Rubber_Branch_Long"
    },
    {
      "x": 0,
      "y": 6,
      "z": -2,
      "name": "Rubber_Branch_Corner",
      "rotation": 8
    },
    {
      "x": 0,
      "y": 11,
      "z": -2,
      "name": "Plant_Leaves_Rubber"
    },
    {
      "x": 0,
      "y": 12,
      "z": -2,
      "name": "Plant_Leaves_Rubber"
    },
    {
      "x": 0,
      "y": 13,
      "z": -2,
      "name": "Plant_Leaves_Rubber"
    },
    {
      "x": 0,
      "y": 14,
      "z": -2,
      "name": "Plant_Leaves_Rubber"
    },
    {
      "x": 0,
      "y": 3,
      "z": -1,
      "name": "Rubber_Branch_X",
      "rotation": 6
    },
    {
      "x": 0,
      "y": 4,
      "z": -1,
      "name": "Rubber_Branch_X",
      "rotation": 6
    },
    {
      "x": 0,
      "y": 5,
      "z": -1,
      "name": "Rubber_Branch_Corner",
      "rotation": 2
    },
    {
      "x": 0,
      "y": 6,
      "z": -1,
      "name": "Rubber_Branch_T_Sideways",
      "rotation": 1
    },
    {
      "x": 0,
      "y": 7,
      "z": -1,
      "name": "Rubber_Branch_Corner",
      "rotation": 8
    },
    {
      "x": 0,
      "y": 8,
      "z": -1,
      "name": "Rubber_Branch_Corner",
      "rotation": 17
    },
    {
      "x": 0,
      "y": 11,
      "z": -1,
      "name": "Rubber_Branch_Corner",
      "rotation": 2
    },
    {
      "x": 0,
      "y": 12,
      "z": -1,
      "name": "Plant_Leaves_Rubber"
    },
    {
      "x": 0,
      "y": 13,
      "z": -1,
      "name": "Plant_Leaves_Rubber"
    },
    {
      "x": 0,
      "y": 14,
      "z": -1,
      "name": "Plant_Leaves_Rubber"
    },
    {
      "x": 0,
      "y": 15,
      "z": -1,
      "name": "Plant_Leaves_Rubber"
    },
    {
      "x": 0,
      "y": 16,
      "z": -1,
      "name": "Plant_Leaves_Rubber"
    },
    {
      "x": 0,
      "y": 18,
      "z": -1,
      "name": "Plant_Leaves_Rubber"
    },
    {
      "x": 0,
      "y": 19,
      "z": -1,
      "name": "Plant_Leaves_Rubber"
    },
    {
      "x": 0,
      "y": 3,
      "z": 0,
      "name": "Rubber_Branch_Long",
      "rotation": 4
    },
    {
      "x": 0,
      "y": 4,
      "z": 0,
      "name": "Rubber_Branch_T",
      "rotation": 1
    },
    {
      "x": 0,
      "y": 5,
      "z": 0,
      "name": "Rubber_Branch_X",
      "rotation": 3
    },
    {
      "x": 0,
      "y": 6,
      "z": 0,
      "name": "Rubber_Branch_Long"
    },
    {
      "x": 0,
      "y": 7,
      "z": 0,
      "name": "Rubber_Branch_T_Sideways",
      "rotation": 1
    },
    {
      "x": 0,
      "y": 8,
      "z": 0,
      "name": "Rubber_Branch_T_Sideways",
      "rotation": 1
    },
    {
      "x": 0,
      "y": 9,
      "z": 0,
      "name": "Rubber_Branch_Long"
    },
    {
      "x": 0,
      "y": 10,
      "z": 0,
      "name": "Rubber_Branch_X"
    },
    {
      "x": 0,
      "y": 11,
      "z": 0,
      "name": "Rubber_Branch_X",
      "rotation": 1
    },
    {
      "x": 0,
      "y": 12,
      "z": 0,
      "name": "Rubber_Branch_Long"
    },
    {
      "x": 0,
      "y": 13,
      "z": 0,
      "name": "Rubber_Branch_Long"
    },
    {
      "x": 0,
      "y": 14,
      "z": 0,
      "name": "Rubber_Branch_Long"
    },
    {
      "x": 0,
      "y": 15,
      "z": 0,
      "name": "Plant_Leaves_Rubber"
    },
    {
      "x": 0,
      "y": 16,
      "z": 0,
      "name": "Plant_Leaves_Rubber"
    },
    {
      "x": 0,
      "y": 17,
      "z": 0,
      "name": "Plant_Leaves_Rubber"
    },
    {
      "x": 0,
      "y": 18,
      "z": 0,
      "name": "Plant_Leaves_Rubber"
    },
    {
      "x": 0,
      "y": 19,
      "z": 0,
      "name": "Plant_Leaves_Rubber"
    },
    {
      "x": 0,
      "y": 20,
      "z": 0,
      "name": "Plant_Leaves_Rubber"
    },
    {
      "x": 0,
      "y": 21,
      "z": 0,
      "name": "Plant_Leaves_Rubber"
    },
    {
      "x": 0,
      "y": 22,
      "z": 0,
      "name": "Plant_Leaves_Rubber"
    },
    {
      "x": 0,
      "y": 23,
      "z": 0,
      "name": "Plant_Leaves_Rubber"
    },
    {
      "x": 0,
      "y": 24,
      "z": 0,
      "name": "Plant_Leaves_Rubber"
    },
    {
      "x": 0,
      "y": -1,
      "z": 1,
      "name": "Rubber_Branch_Long",
      "support": 15
    },
    {
      "x": 0,
      "y": 0,
      "z": 1,
      "name": "Rubber_Branch_Long"
    },
    {
      "x": 0,
      "y": 1,
      "z": 1,
      "name": "Rubber_Branch_T_Sideways",
      "rotation": 2
    },
    {
      "x": 0,
      "y": 2,
      "z": 1,
      "name": "Rubber_Branch_Long"
    },
    {
      "x": 0,
      "y": 3,
      "z": 1,
      "name": "Rubber_Branch_X",
      "rotation": 3
    },
    {
      "x": 0,
      "y": 4,
      "z": 1,
      "name": "Rubber_Branch_Corner",
      "rotation": 10
    },
    {
      "x": 0,
      "y": 5,
      "z": 1,
      "name": "Rubber_Branch_Corner",
      "rotation": 16
    },
    {
      "x": 0,
      "y": 10,
      "z": 1,
      "name": "Plant_Leaves_Rubber"
    },
    {
      "x": 0,
      "y": 11,
      "z": 1,
      "name": "Rubber_Branch_Corner"
    },
    {
      "x": 0,
      "y": 12,
      "z": 1,
      "name": "Rubber_Branch_Long"
    },
    {
      "x": 0,
      "y": 13,
      "z": 1,
      "name": "Rubber_Branch_Long"
    },
    {
      "x": 0,
      "y": 14,
      "z": 1,
      "name": "Plant_Leaves_Rubber"
    },
    {
      "x": 0,
      "y": 15,
      "z": 1,
      "name": "Plant_Leaves_Rubber"
    },
    {
      "x": 0,
      "y": 16,
      "z": 1,
      "name": "Plant_Leaves_Rubber"
    },
    {
      "x": 0,
      "y": 17,
      "z": 1,
      "name": "Plant_Leaves_Rubber"
    },
    {
      "x": 0,
      "y": 19,
      "z": 1,
      "name": "Plant_Leaves_Rubber"
    },
    {
      "x": 0,
      "y": 20,
      "z": 1,
      "name": "Plant_Leaves_Rubber"
    },
    {
      "x": 0,
      "y": 22,
      "z": 1,
      "name": "Plant_Leaves_Rubber"
    },
    {
      "x": 0,
      "y": 3,
      "z": 2,
      "name": "Rubber_Branch_Corner",
      "rotation": 16
    },
    {
      "x": 0,
      "y": 5,
      "z": 2,
      "name": "Plant_Leaves_Rubber"
    },
    {
      "x": 0,
      "y": 6,
      "z": 2,
      "name": "Plant_Leaves_Rubber"
    },
    {
      "x": 0,
      "y": 11,
      "z": 2,
      "name": "Plant_Leaves_Rubber"
    },
    {
      "x": 0,
      "y": 12,
      "z": 2,
      "name": "Plant_Leaves_Rubber"
    },
    {
      "x": 0,
      "y": 13,
      "z": 2,
      "name": "Plant_Leaves_Rubber"
    },
    {
      "x": 0,
      "y": 14,
      "z": 2,
      "name": "Plant_Leaves_Rubber"
    },
    {
      "x": 0,
      "y": 3,
      "z": 3,
      "name": "Rubber_Branch_Corner",
      "rotation": 3
    },
    {
      "x": 0,
      "y": 4,
      "z": 3,
      "name": "Rubber_Branch_T_Sideways",
      "rotation": 2
    },
    {
      "x": 0,
      "y": 5,
      "z": 3,
      "name": "Rubber_Branch_Long"
    },
    {
      "x": 0,
      "y": 6,
      "z": 3,
      "name": "Plant_Leaves_Rubber"
    },
    {
      "x": 0,
      "y": 7,
      "z": 3,
      "name": "Plant_Leaves_Rubber"
    },
    {
      "x": 0,
      "y": 8,
      "z": 3,
      "name": "Plant_Leaves_Rubber"
    },
    {
      "x": 0,
      "y": 5,
      "z": 4,
      "name": "Plant_Leaves_Rubber"
    },
    {
      "x": 0,
      "y": 6,
      "z": 4,
      "name": "Plant_Leaves_Rubber"
    },
    {
      "x": 1,
      "y": 13,
      "z": -3,
      "name": "Plant_Leaves_Rubber"
    },
    {
      "x": 1,
      "y": 11,
      "z": -2,
      "name": "Plant_Leaves_Rubber"
    },
    {
      "x": 1,
      "y": 12,
      "z": -2,
      "name": "Plant_Leaves_Rubber"
    },
    {
      "x": 1,
      "y": 13,
      "z": -2,
      "name": "Plant_Leaves_Rubber"
    },
    {
      "x": 1,
      "y": 14,
      "z": -2,
      "name": "Plant_Leaves_Rubber"
    },
    {
      "x": 1,
      "y": -1,
      "z": -1,
      "name": "Rubber_Branch_Long",
      "support": 15
    },
    {
      "x": 1,
      "y": 0,
      "z": -1,
      "name": "Rubber_Branch_Long"
    },
    {
      "x": 1,
      "y": 1,
      "z": -1,
      "name": "Rubber_Branch_Long"
    },
    {
      "x": 1,
      "y": 2,
      "z": -1,
      "name": "Rubber_Branch_T_Sideways"
    },
    {
      "x": 1,
      "y": 3,
      "z": -1,
      "name": "Rubber_Branch_T_Sideways",
      "rotation": 2
    },
    {
      "x": 1,
      "y": 4,
      "z": -1,
      "name": "Rubber_Branch_Corner",
      "rotation": 11
    },
    {
      "x": 1,
      "y": 11,
      "z": -1,
      "name": "Rubber_Branch_Corner",
      "rotation": 2
    },
    {
      "x": 1,
      "y": 12,
      "z": -1,
      "name": "Rubber_Branch_Long"
    },
    {
      "x": 1,
      "y": 13,
      "z": -1,
      "name": "Plant_Leaves_Rubber"
    },
    {
      "x": 1,
      "y": 14,
      "z": -1,
      "name": "Plant_Leaves_Rubber"
    },
    {
      "x": 1,
      "y": 15,
      "z": -1,
      "name": "Plant_Leaves_Rubber"
    },
    {
      "x": 1,
      "y": 16,
      "z": -1,
      "name": "Plant_Leaves_Rubber"
    },
    {
      "x": 1,
      "y": 7,
      "z": 0,
      "name": "Plant_Leaves_Rubber"
    },
    {
      "x": 1,
      "y": 8,
      "z": 0,
      "name": "Plant_Leaves_Rubber"
    },
    {
      "x": 1,
      "y": 10,
      "z": 0,
      "name": "Rubber_Branch_Corner",
      "rotation": 1
    },
    {
      "x": 1,
      "y": 11,
      "z": 0,
      "name": "Rubber_Branch_T_Sideways",
      "rotation": 1
    },
    {
      "x": 1,
      "y": 12,
      "z": 0,
      "name": "Rubber_Branch_Long"
    },
    {
      "x": 1,
      "y": 13,
      "z": 0,
      "name": "Rubber_Branch_Long"
    },
    {
      "x": 1,
      "y": 14,
      "z": 0,
      "name": "Plant_Leaves_Rubber"
    },
    {
      "x": 1,
      "y": 15,
      "z": 0,
      "name": "Plant_Leaves_Rubber"
    },
    {
      "x": 1,
      "y": 16,
      "z": 0,
      "name": "Plant_Leaves_Rubber"
    },
    {
      "x": 1,
      "y": 17,
      "z": 0,
      "name": "Plant_Leaves_Rubber"
    },
    {
      "x": 1,
      "y": 18,
      "z": 0,
      "name": "Plant_Leaves_Rubber"
    },
    {
      "x": 1,
      "y": 19,
      "z": 0,
      "name": "Plant_Leaves_Rubber"
    },
    {
      "x": 1,
      "y": 21,
      "z": 0,
      "name": "Plant_Leaves_Rubber"
    },
    {
      "x": 1,
      "y": 22,
      "z": 0,
      "name": "Plant_Leaves_Rubber"
    },
    {
      "x": 1,
      "y": 23,
      "z": 0,
      "name": "Plant_Leaves_Rubber"
    },
    {
      "x": 1,
      "y": 8,
      "z": 1,
      "name": "Plant_Leaves_Rubber"
    },
    {
      "x": 1,
      "y": 9,
      "z": 1,
      "name": "Plant_Leaves_Rubber"
    },
    {
      "x": 1,
      "y": 10,
      "z": 1,
      "name": "Plant_Leaves_Rubber"
    },
    {
      "x": 1,
      "y": 11,
      "z": 1,
      "name": "Plant_Leaves_Rubber"
    },
    {
      "x": 1,
      "y": 12,
      "z": 1,
      "name": "Plant_Leaves_Rubber"
    },
    {
      "x": 1,
      "y": 13,
      "z": 1,
      "name": "Plant_Leaves_Rubber"
    },
    {
      "x": 1,
      "y": 14,
      "z": 1,
      "name": "Plant_Leaves_Rubber"
    },
    {
      "x": 1,
      "y": 15,
      "z": 1,
      "name": "Plant_Leaves_Rubber"
    },
    {
      "x": 1,
      "y": 16,
      "z": 1,
      "name": "Plant_Leaves_Rubber"
    },
    {
      "x": 1,
      "y": 17,
      "z": 1,
      "name": "Plant_Leaves_Rubber"
    },
    {
      "x": 1,
      "y": 18,
      "z": 1,
      "name": "Plant_Leaves_Rubber"
    },
    {
      "x": 1,
      "y": 5,
      "z": 2,
      "name": "Plant_Leaves_Rubber"
    },
    {
      "x": 1,
      "y": 13,
      "z": 2,
      "name": "Plant_Leaves_Rubber"
    },
    {
      "x": 1,
      "y": 14,
      "z": 2,
      "name": "Plant_Leaves_Rubber"
    },
    {
      "x": 1,
      "y": 17,
      "z": 2,
      "name": "Plant_Leaves_Rubber"
    },
    {
      "x": 1,
      "y": -1,
      "z": 3,
      "name": "Rubber_Branch_Long",
      "support": 15
    },
    {
      "x": 1,
      "y": 0,
      "z": 3,
      "name": "Rubber_Branch_Long"
    },
    {
      "x": 1,
      "y": 1,
      "z": 3,
      "name": "Rubber_Branch_Long"
    },
    {
      "x": 1,
      "y": 2,
      "z": 3,
      "name": "Rubber_Branch_Long"
    },
    {
      "x": 1,
      "y": 3,
      "z": 3,
      "name": "Rubber_Branch_Corner",
      "rotation": 11
    },
    {
      "x": 1,
      "y": 5,
      "z": 3,
      "name": "Plant_Leaves_Rubber"
    },
    {
      "x": 1,
      "y": 6,
      "z": 3,
      "name": "Plant_Leaves_Rubber"
    },
    {
      "x": 1,
      "y": 5,
      "z": 4,
      "name": "Plant_Leaves_Rubber"
    },
    {
      "x": 2,
      "y": 12,
      "z": -2,
      "name": "Plant_Leaves_Rubber"
    },
    {
      "x": 2,
      "y": 13,
      "z": -2,
      "name": "Plant_Leaves_Rubber"
    },
    {
      "x": 2,
      "y": -1,
      "z": -1,
      "name": "Rubber_Branch_Long",
      "support": 15
    },
    {
      "x": 2,
      "y": 0,
      "z": -1,
      "name": "Rubber_Branch_Long"
    },
    {
      "x": 2,
      "y": 1,
      "z": -1,
      "name": "Rubber_Branch_Long"
    },
    {
      "x": 2,
      "y": 2,
      "z": -1,
      "name": "Rubber_Branch_Corner",
      "rotation": 11
    },
    {
      "x": 2,
      "y": 12,
      "z": -1,
      "name": "Plant_Leaves_Rubber"
    },
    {
      "x": 2,
      "y": 13,
      "z": -1,
      "name": "Plant_Leaves_Rubber"
    },
    {
      "x": 2,
      "y": 14,
      "z": -1,
      "name": "Plant_Leaves_Rubber"
    },
    {
      "x": 2,
      "y": 11,
      "z": 0,
      "name": "Plant_Leaves_Rubber"
    },
    {
      "x": 2,
      "y": 12,
      "z": 0,
      "name": "Plant_Leaves_Rubber"
    },
    {
      "x": 2,
      "y": 13,
      "z": 0,
      "name": "Plant_Leaves_Rubber"
    },
    {
      "x": 2,
      "y": 14,
      "z": 0,
      "name": "Plant_Leaves_Rubber"
    },
    {
      "x": 2,
      "y": 15,
      "z": 0,
      "name": "Plant_Leaves_Rubber"
    },
    {
      "x": 2,
      "y": 16,
      "z": 0,
      "name": "Plant_Leaves_Rubber"
    },
    {
      "x": 2,
      "y": 17,
      "z": 0,
      "name": "Plant_Leaves_Rubber"
    },
    {
      "x": 2,
      "y": 12,
      "z": 1,
      "name": "Plant_Leaves_Rubber"
    },
    {
      "x": 2,
      "y": 13,
      "z": 1,
      "name": "Plant_Leaves_Rubber"
    },
    {
      "x": 2,
      "y": 15,
      "z": 1,
      "name": "Plant_Leaves_Rubber"
    },
    {
      "x": 2,
      "y": 17,
      "z": 1,
      "name": "Plant_Leaves_Rubber"
    },
    {
      "x": 3,
      "y": 12,
      "z": -1,
      "name": "Plant_Leaves_Rubber"
    },
    {
      "x": 3,
      "y": 13,
      "z": -1,
      "name": "Plant_Leaves_Rubber"
    },
    {
      "x": 3,
      "y": 12,
      "z": 0,
      "name": "Plant_Leaves_Rubber"
    },
    {
      "x": 3,
      "y": 13,
      "z": 0,
      "name": "Plant_Leaves_Rubber"
    },
    {
      "x": 3,
      "y": 12,
      "z": 1,
      "name": "Plant_Leaves_Rubber"
    }
  ]
}