{
  "version": 8,
  "blockIdVersion": 11,
  "anchorX": 0,
  "anchorY": 0,
  "anchorZ": 0,
  "blocks": [
    {
      "x": -3,
      "y": 10,
      "z": -1,
      "name": "Plant_Leaves_Rubber",
      "support": 15
    },
    {
      "x": -3,
      "y": 9,
      "z": 0,
      "name": "Plant_Leaves_Rubber",
      "support": 15
    },
    {
      "x": -3,
      "y": 10,
      "z": 0,
      "name": "Plant_Leaves_Rubber",
      "support": 15
    },
    {
      "x": -3,
      "y": 10,
      "z": 1,
      "name": "Plant_Leaves_Rubber",
      "support": 15
    },
    {
      "x": -2,
      "y": 7,
      "z": -2,
      "name": "Plant_Leaves_Rubber",
      "support": 15
    },
    {
      "x": -2,
      "y": 9,
      "z": -2,
      "name": "Plant_Leaves_Rubber",
      "support": 15
    },
    {
      "x": -2,
      "y": 10,
      "z": -2,
      "name": "Plant_Leaves_Rubber",
      "support": 15
    },
    {
      "x": -2,
      "y": 9,
      "z": -1,
      "name": "Plant_Leaves_Rubber",
      "support": 15
    },
    {
      "x": -2,
      "y": 10,
      "z": -1,
      "name": "Plant_Leaves_Rubber",
      "support": 15
    },
    {
      "x": -2,
      "y": 8,
      "z": 0,
      "name": "Rubber_Branch_Corner",
      "support": 15,
      "rotation": 3
    },
    {
      "x": -2,
      "y": 9,
      "z": 0,
      "name": "Rubber_Branch_X",
      "support": 15,
      "rotation": 1
    },
    {
      "x": -2,
      "y": 10,
      "z": 0,
      "name": "Rubber_Branch_Corner",
      "support": 15,
      "rotation": 11
    },
    {
      "x": -2,
      "y": 11,
      "z": 0,
      "name": "Plant_Leaves_Rubber",
      "support": 15
    },
    {
      "x": -2,
      "y": 9,
      "z": 1,
      "name": "Plant_Leaves_Rubber",
      "support": 15
    },
    {
      "x": -2,
      "y": 10,
      "z": 1,
      "name": "Plant_Leaves_Rubber",
      "support": 15
    },
    {
      "x": -2,
      "y": 9,
      "z": 2,
      "name": "Plant_Leaves_Rubber",
      "support": 15
    },
    {
      "x": -2,
      "y": 10,
      "z": 2,
      "name": "Plant_Leaves_Rubber",
      "support": 15
    },
    {
      "x": -2,
      "y": 10,
      "z": 3,
      "name": "Plant_Leaves_Rubber",
      "support": 15
    },
    {
      "x": -1,
      "y": 9,
      "z": -4,
      "name": "Plant_Leaves_Rubber",
      "support": 15
    },
    {
      "x": -1,
      "y": 7,
      "z": -3,
      "name": "Plant_Leaves_Rubber",
      "support": 15
    },
    {
      "x": -1,
      "y": 8,
      "z": -3,
      "name": "Plant_Leaves_Rubber",
      "support": 15
    },
    {
      "x": -1,
      "y": 9,
      "z": -3,
      "name": "Plant_Leaves_Rubber",
      "support": 15
    },
    {
      "x": -1,
      "y": 10,
      "z": -3,
      "name": "Plant_Leaves_Rubber",
      "support": 15
    },
    {
      "x": -1,
      "y": 7,
      "z": -2,
      "name": "Rubber_Branch_Long",
      "support": 15,
      "rotation": 5
    },
    {
      "x": -1,
      "y": 10,
      "z": -1,
      "name": "Plant_Leaves_Rubber",
      "support": 15
    },
    {
      "x": -1,
      "y": 11,
      "z": -1,
      "name": "Plant_Leaves_Rubber",
      "support": 15
    },
    {
      "x": -1,
      "y": 7,
      "z": 0,
      "name": "Rubber_Branch_Corner",
      "support": 15,
      "rotation": 3
    },
    {
      "x": -1,
      "y": 8,
      "z": 0,
      "name": "Rubber_Branch_Corner",
      "support": 15,
      "rotation": 11
    },
    {
      "x": -1,
      "y": 11,
      "z": 0,
      "name": "Plant_Leaves_Rubber",
      "support": 15
    },
    {
      "x": -1,
      "y": 12,
      "z": 0,
      "name": "Plant_Leaves_Rubber",
      "support": 15
    },
    {
      "x": -1,
      "y": 9,
      "z": 1,
      "name": "Plant_Leaves_Rubber",
      "support": 15
    },
    {
      "x": -1,
      "y": 10,
      "z": 1,
      "name": "Plant_Leaves_Rubber",
      "support": 15
    },
    {
      "x": -1,
      "y": 11,
      "z": 1,
      "name": "Plant_Leaves_Rubber",
      "support": 15
    },
    {
      "x": -1,
      "y": 12,
      "z": 1,
      "name": "Plant_Leaves_Rubber",
      "support": 15
    },
    {
      "x": -1,
      "y": 9,
      "z": 3,
      "name": "Plant_Leaves_Rubber",
      "support": 15
    },
    {
      "x": -1,
      "y": 10,
      "z": 3,
      "name": "Plant_Leaves_Rubber",
      "support": 15
    },
    {
      "x": 0,
      "y": 8,
      "z": -4,
      "name": "Plant_Leaves_Rubber",
      "support": 15
    },
    {
      "x": 0,
      "y": 9,
      "z": -4,
      "name": "Plant_Leaves_Rubber",
      "support": 15
    },
    {
      "x": 0,
      "y": 10,
      "z": -4,
      "name": "Plant_Leaves_Rubber",
      "support": 15
    },
    {
      "x": 0,
      "y": 8,
      "z": -3,
      "name": "Rubber_Branch_Corner",
      "support": 15,
      "rotation": 2
    },
    {
      "x": 0,
      "y": 9,
      "z": -3,
      "name": "Rubber_Branch_Long",
      "support": 15
    },
    {
      "x": 0,
      "y": 10,
      "z": -3,
      "name": "Plant_Leaves_Rubber",
      "support": 15
    },
    {
      "x": 0,
      "y": 6,
      "z": -2,
      "name": "Rubber_Branch_Corner",
      "support": 15,
      "rotation": 2
    },
    {
      "x": 0,
      "y": 7,
      "z": -2,
      "name": "Rubber_Branch_X",
      "support": 15,
      "rotation": 2
    },
    {
      "x": 0,
      "y": 8,
      "z": -2,
      "name": "Rubber_Branch_Corner",
      "support": 15,
      "rotation": 10
    },
    {
      "x": 0,
      "y": 9,
      "z": -2,
      "name": "Plant_Leaves_Rubber",
      "support": 15
    },
    {
      "x": 0,
      "y": 11,
      "z": -2,
      "name": "Plant_Leaves_Rubber",
      "support": 15
    },
    {
      "x": 0,
      "y": 5,
      "z": -1,
      "name": "Rubber_Branch_Corner",
      "support": 15,
      "rotation": 2
    },
    {
      "x": 0,
      "y": 6,
      "z": -1,
      "name": "Rubber_Branch_Corner",
      "support": 15,
      "rotation": 10
    },
    {
      "x": 0,
      "y": 9,
      "z": -1,
      "name": "Rubber_Branch_Corner",
      "support": 15,
      "rotation": 2
    },
    {
      "x": 0,
      "y": 10,
      "z": -1,
      "name": "Rubber_Branch_Long",
      "support": 15
    },
    {
      "x": 0,
      "y": 11,
      "z": -1,
      "name": "Rubber_Branch_Long",
      "support": 15
    },
    {
      "x": 0,
      "y": 12,
      "z": -1,
      "name": "Plant_Leaves_Rubber",
      "support": 15
    },
    {
      "x": 0,
      "y": 0,
      "z": 0,
      "name": "Rubber_Branch_Long",
      "support": 15
    },
    {
      "x": 0,
      "y": 1,
      "z": 0,
      "name": "Rubber_Branch_Long",
      "support": 15
    },
    {
      "x": 0,
      "y": 2,
      "z": 0,
      "name": "Rubber_Branch_Long",
      "support": 15
    },
    {
      "x": 0,
      "y": 3,
      "z": 0,
      "name": "Rubber_Branch_Long",
      "support": 15
    },
    {
      "x": 0,
      "y": 4,
      "z": 0,
      "name": "Rubber_Branch_Long",
      "support": 15
    },
    {
      "x": 0,
      "y": 5,
      "z": 0,
      "name": "Rubber_Branch_T_Sideways",
      "support": 15,
      "rotation": 1
    },
    {
      "x": 0,
      "y": 6,
      "z": 0,
      "name": "Rubber_Branch_T_Sideways",
      "support": 15,
      "rotation": 3
    },
    {
      "x": 0,
      "y": 7,
      "z": 0,
      "name": "Rubber_Branch_X",
      "support": 15,
      "rotation": 2
    },
    {
      "x": 0,
      "y": 8,
      "z": 0,
      "name": "Rubber_Branch_Long",
      "support": 15
    },
    {
      "x": 0,
      "y": 9,
      "z": 0,
      "name": "Rubber_Branch_T",
      "support": 15,
      "rotation": 9
    },
    {
      "x": 0,
      "y": 10,
      "z": 0,
      "name": "Plant_Leaves_Rubber",
      "support": 15
    },
    {
      "x": 0,
      "y": 11,
      "z": 0,
      "name": "Plant_Leaves_Rubber",
      "support": 15
    },
    {
      "x": 0,
      "y": 12,
      "z": 0,
      "name": "Plant_Leaves_Rubber",
      "support": 15
    },
    {
      "x": 0,
      "y": 6,
      "z": 1,
      "name": "Rubber_Branch_Corner",
      "support": 15
    },
    {
      "x": 0,
      "y": 7,
      "z": 1,
      "name": "Rubber_Branch_Corner",
      "support": 15,
      "rotation": 8
    },
    {
      "x": 0,
      "y": 9,
      "z": 1,
      "name": "Rubber_Branch_Corner",
      "support": 15
    },
    {
      "x": 0,
      "y": 10,
      "z": 1,
      "name": "Rubber_Branch_Long",
      "support": 15
    },
    {
      "x": 0,
      "y": 11,
      "z": 1,
      "name": "Rubber_Branch_Long",
      "support": 15
    },
    {
      "x": 0,
      "y": 12,
      "z": 1,
      "name": "Plant_Leaves_Rubber",
      "support": 15
    },
    {
      "x": 0,
      "y": 7,
      "z": 2,
      "name": "Rubber_Branch_Corner",
      "support": 15
    },
    {
      "x": 0,
      "y": 8,
      "z": 2,
      "name": "Rubber_Branch_Corner",
      "support": 15,
      "rotation": 8
    },
    {
      "x": 0,
      "y": 9,
      "z": 2,
      "name": "Plant_Leaves_Rubber",
      "support": 15
    },
    {
      "x": 0,
      "y": 11,
      "z": 2,
      "name": "Plant_Leaves_Rubber",
      "support": 15
    },
    {
      "x": 0,
      "y": 8,
      "z": 3,
      "name": "Rubber_Branch_Corner",
      "support": 15
    },
    {
      "x": 0,
      "y": 9,
      "z": 3,
      "name": "Rubber_Branch_Long",
      "support": 15
    },
    {
      "x": 0,
      "y": 10,
      "z": 3,
      "name": "Plant_Leaves_Rubber",
      "support": 15
    },
    {
      "x": 0,
      "y": 9,
      "z": 4,
      "name": "Plant_Leaves_Rubber",
      "support": 15
    },
    {
      "x": 1,
      "y": 9,
      "z": -4,
      "name": "Plant_Leaves_Rubber",
      "support": 15
    },
    {
      "x": 1,
      "y": 7,
      "z": -3,
      "name": "Plant_Leaves_Rubber",
      "support": 15
    },
    {
      "x": 1,
      "y": 8,
      "z": -3,
      "name": "Plant_Leaves_Rubber",
      "support": 15
    },
    {
      "x": 1,
      "y": 9,
      "z": -3,
      "name": "Plant_Leaves_Rubber",
      "support": 15
    },
    {
      "x": 1,
      "y": 7,
      "z": -2,
      "name": "Rubber_Branch_Long",
      "support": 15,
      "rotation": 5
    },
    {
      "x": 1,
      "y": 9,
      "z": -2,
      "name": "Plant_Leaves_Rubber",
      "support": 15
    },
    {
      "x": 1,
      "y": 10,
      "z": -2,
      "name": "Plant_Leaves_Rubber",
      "support": 15
    },
    {
      "x": 1,
      "y": 10,
      "z": -1,
      "name": "Plant_Leaves_Rubber",
      "support": 15
    },
    {
      "x": 1,
      "y": 11,
      "z": -1,
      "name": "Plant_Leaves_Rubber",
      "support": 15
    },
    {
      "x": 1,
      "y": 12,
      "z": -1,
      "name": "Plant_Leaves_Rubber",
      "support": 15
    },
    {
      "x": 1,
      "y": 7,
      "z": 0,
      "name": "Rubber_Branch_Long",
      "support": 15,
      "rotation": 5
    },
    {
      "x": 1,
      "y": 9,
      "z": 0,
      "name": "Plant_Leaves_Rubber",
      "support": 15
    },
    {
      "x": 1,
      "y": 10,
      "z": 1,
      "name": "Plant_Leaves_Rubber",
      "support": 15
    },
    {
      "x": 1,
      "y": 11,
      "z": 1,
      "name": "Plant_Leaves_Rubber",
      "support": 15
    },
    {
      "x": 1,
      "y": 10,
      "z": 2,
      "name": "Plant_Leaves_Rubber",
      "support": 15
    },
    {
      "x": 1,
      "y": 11,
      "z": 2,
      "name": "Plant_Leaves_Rubber",
      "support": 15
    },
    {
      "x": 1,
      "y": 9,
      "z": 3,
      "name": "Plant_Leaves_Rubber",
      "support": 15
    },
    {
      "x": 1,
      "y": 10,
      "z": 3,
      "name": "Plant_Leaves_Rubber",
      "support": 15
    },
    {
      "x": 1,
      "y": 9,
      "z": 4,
      "name": "Plant_Leaves_Rubber",
      "support": 15
    },
    {
      "x": 1,
      "y": 10,
      "z": 4,
      "name": "Plant_Leaves_Rubber",
      "support": 15
    },
    {
      "x": 2,
      "y": 9,
      "z": -3,
      "name": "Plant_Leaves_Rubber",
      "support": 15
    },
    {
      "x": 2,
      "y": 7,
      "z": -2,
      "name": "Plant_Leaves_Rubber",
      "support": 15
    },
    {
      "x": 2,
      "y": 8,
      "z": -1,
      "name": "Plant_Leaves_Rubber",
      "support": 15
    },
    {
      "x": 2,
      "y": 9,
      "z": -1,
      "name": "Plant_Leaves_Rubber",
      "support": 15
    },
    {
      "x": 2,
      "y": 10,
      "z": -1,
      "name": "Plant_Leaves_Rubber",
      "support": 15
    },
    {
      "x": 2,
      "y": 11,
      "z": -1,
      "name": "Plant_Leaves_Rubber",
      "support": 15
    },
    {
      "x": 2,
      "y": 7,
      "z": 0,
      "name": "Rubber_Branch_Corner",
      "support": 15,
      "rotation": 1
    },
    {
      "x": 2,
      "y": 8,
      "z": 0,
      "name": "Rubber_Branch_Long",
      "support": 15
    },
    {
      "x": 2,
      "y": 9,
      "z": 0,
      "name": "Rubber_Branch_Corner",
      "support": 15,
      "rotation": 9
    },
    {
      "x": 2,
      "y": 10,
      "z": 0,
      "name": "Plant_Leaves_Rubber",
      "support": 15
    },
    {
      "x": 2,
      "y": 9,
      "z": 1,
      "name": "Plant_Leaves_Rubber",
      "support": 15
    },
    {
      "x": 2,
      "y": 10,
      "z": 1,
      "name": "Plant_Leaves_Rubber",
      "support": 15
    },
    {
      "x": 2,
      "y": 9,
      "z": 2,
      "name": "Plant_Leaves_Rubber",
      "support": 15
    },
    {
      "x": 2,
      "y": 10,
      "z": 2,
      "name": "Plant_Leaves_Rubber",
      "support": 15
    },
    {
      "x": 2,
      "y": 9,
      "z": 3,
      "name": "Plant_Leaves_Rubber",
      "support": 15
    },
    {
      "x": 3,
      "y": 9,
      "z": -1,
      "name": "Plant_Leaves_Rubber",
      "support": 15
    },
    {
      "x": 3,
      "y": 8,
      "z": 0,
      "name": "Plant_Leaves_Rubber",
      "support": 15
    },
    {
      "x": 3,
      "y": 9,
      "z": 0,
      "name": "Plant_Leaves_Rubber",
      "support": 15
    },
    {
      "x": 3,
      "y": 9,
      "z": 1,
      "name": "Plant_Leaves_Rubber",
      "support": 15
    }
  ]
}