{
  "version": 8,
  "blockIdVersion": 11,
  "anchorX": 0,
  "anchorY": 12,
  "anchorZ": 0,
  "blocks": [
    {
      "x": -7,
      "y": 8,
      "z": 0,
      "name": "Plant_Leaves_Oak",
      "rotation": 10
    },
    {
      "x": -6,
      "y": 8,
      "z": -2,
      "name": "Plant_Leaves_Oak",
      "rotation": 10
    },
    {
      "x": -6,
      "y": 7,
      "z": -1,
      "name": "Plant_Leaves_Oak",
      "rotation": 10
    },
    {
      "x": -6,
      "y": 8,
      "z": -1,
      "name": "Plant_Leaves_Oak",
      "rotation": 10
    },
    {
      "x": -6,
      "y": 7,
      "z": 0,
      "name": "Plant_Leaves_Oak",
      "rotation": 10
    },
    {
      "x": -6,
      "y": 8,
      "z": 0,
      "name": "Plant_Leaves_Oak",
      "rotation": 10
    },
    {
      "x": -6,
      "y": 8,
      "z": 1,
      "name": "Plant_Leaves_Oak",
      "rotation": 10
    },
    {
      "x": -5,
      "y": 7,
      "z": -2,
      "name": "Plant_Leaves_Oak",
      "rotation": 10
    },
    {
      "x": -5,
      "y": 8,
      "z": -2,
      "name": "Plant_Leaves_Oak",
      "rotation": 10
    },
    {
      "x": -5,
      "y": 7,
      "z": -1,
      "name": "Plant_Leaves_Oak",
      "rotation": 10
    },
    {
      "x": -5,
      "y": 8,
      "z": -1,
      "name": "Wood_Oak_Branch_Corner",
      "rotation": 9
    },
    {
      "x": -5,
      "y": 7,
      "z": 0,
      "name": "Plant_Leaves_Oak",
      "rotation": 10
    },
    {
      "x": -5,
      "y": 8,
      "z": 0,
      "name": "Plant_Leaves_Oak",
      "rotation": 10
    },
    {
      "x": -4,
      "y": 8,
      "z": -2,
      "name": "Plant_Leaves_Oak",
      "rotation": 10
    },
    {
      "x": -4,
      "y": 7,
      "z": -1,
      "name": "Plant_Leaves_Oak",
      "rotation": 10
    },
    {
      "x": -4,
      "y": 8,
      "z": -1,
      "name": "Wood_Oak_Branch_Long",
      "rotation": 13
    },
    {
      "x": -4,
      "y": 8,
      "z": 0,
      "name": "Plant_Leaves_Oak",
      "rotation": 10
    },
    {
      "x": -3,
      "y": 8,
      "z": -1,
      "name": "Wood_Oak_Branch_Long",
      "rotation": 13
    },
    {
      "x": -2,
      "y": 6,
      "z": -3,
      "name": "Wood_Oak_Branch_Short",
      "rotation": 2
    },
    {
      "x": -2,
      "y": 3,
      "z": -2,
      "name": "Furniture_Kweebec_Candle",
      "rotation": 10
    },
    {
      "x": -2,
      "y": 4,
      "z": -2,
      "name": "Wood_Oak_Branch_Corner",
      "rotation": 9
    },
    {
      "x": -2,
      "y": 5,
      "z": -2,
      "name": "Wood_Oak_Trunk_Half",
      "rotation": 13
    },
    {
      "x": -2,
      "y": 6,
      "z": -2,
      "name": "Wood_Oak_Trunk_Full",
      "rotation": 10
    },
    {
      "x": -2,
      "y": 7,
      "z": -2,
      "name": "Wood_Oak_Trunk_Half",
      "rotation": 12
    },
    {
      "x": -2,
      "y": 6,
      "z": -1,
      "name": "Wood_Oak_Trunk_Half",
      "rotation": 14
    },
    {
      "x": -2,
      "y": 7,
      "z": -1,
      "name": "Wood_Oak_Trunk_Full",
      "rotation": 10
    },
    {
      "x": -2,
      "y": 8,
      "z": -1,
      "name": "Wood_Oak_Trunk_Full",
      "rotation": 10
    },
    {
      "x": -2,
      "y": 7,
      "z": 0,
      "name": "Wood_Oak_Branch_Short"
    },
    {
      "x": -2,
      "y": 8,
      "z": 0,
      "name": "Wood_Oak_Trunk_Half",
      "rotation": 14
    },
    {
      "x": -2,
      "y": 9,
      "z": 0,
      "name": "Wood_Oak_Trunk_Half",
      "rotation": 13
    },
    {
      "x": -2,
      "y": 10,
      "z": 0,
      "name": "Wood_Oak_Branch_Short",
      "rotation": 3
    },
    {
      "x": -2,
      "y": 10,
      "z": 1,
      "name": "Plant_Leaves_Oak",
      "rotation": 10
    },
    {
      "x": -2,
      "y": 9,
      "z": 2,
      "name": "Plant_Leaves_Oak",
      "rotation": 10
    },
    {
      "x": -2,
      "y": 10,
      "z": 2,
      "name": "Plant_Leaves_Oak",
      "rotation": 10
    },
    {
      "x": -2,
      "y": 10,
      "z": 3,
      "name": "Plant_Leaves_Oak",
      "rotation": 10
    },
    {
      "x": -1,
      "y": 3,
      "z": -3,
      "name": "Wood_Oak_Branch_Short",
      "rotation": 3
    },
    {
      "x": -1,
      "y": 4,
      "z": -3,
      "name": "Wood_Oak_Trunk_Half",
      "rotation": 6
    },
    {
      "x": -1,
      "y": 3,
      "z": -2,
      "name": "Wood_Oak_Roots",
      "rotation": 2
    },
    {
      "x": -1,
      "y": 4,
      "z": -2,
      "name": "Wood_Oak_Trunk_Full",
      "rotation": 10
    },
    {
      "x": -1,
      "y": 5,
      "z": -2,
      "name": "Wood_Oak_Trunk_Full",
      "rotation": 10
    },
    {
      "x": -1,
      "y": 6,
      "z": -2,
      "name": "Wood_Oak_Trunk_Half",
      "rotation": 5
    },
    {
      "x": -1,
      "y": 8,
      "z": -1,
      "name": "Wood_Oak_Trunk_Half",
      "rotation": 15
    },
    {
      "x": -1,
      "y": 9,
      "z": -1,
      "name": "Wood_Oak_Trunk_Half",
      "rotation": 12
    },
    {
      "x": -1,
      "y": 13,
      "z": -1,
      "name": "Wood_Oak_Trunk_Full"
    },
    {
      "x": -1,
      "y": 14,
      "z": -1,
      "name": "Wood_Oak_Trunk_Full"
    },
    {
      "x": -1,
      "y": 9,
      "z": 0,
      "name": "Wood_Oak_Trunk_Full",
      "rotation": 10
    },
    {
      "x": -1,
      "y": 10,
      "z": 0,
      "name": "Wood_Oak_Trunk_Full",
      "rotation": 10
    },
    {
      "x": -1,
      "y": 11,
      "z": 0,
      "name": "Wood_Oak_Trunk_Half",
      "rotation": 13
    },
    {
      "x": -1,
      "y": 12,
      "z": 0,
      "name": "Wood_Oak_Trunk_Full",
      "rotation": 10
    },
    {
      "x": -1,
      "y": 13,
      "z": 0,
      "name": "Wood_Oak_Trunk_Full"
    },
    {
      "x": -1,
      "y": 14,
      "z": 0,
      "name": "Wood_Oak_Trunk_Full"
    },
    {
      "x": -1,
      "y": 9,
      "z": 1,
      "name": "Plant_Leaves_Oak",
      "rotation": 10
    },
    {
      "x": -1,
      "y": 10,
      "z": 1,
      "name": "Wood_Oak_Branch_Long",
      "rotation": 14
    },
    {
      "x": -1,
      "y": 13,
      "z": 1,
      "name": "Wood_Oak_Trunk_Full"
    },
    {
      "x": -1,
      "y": 14,
      "z": 1,
      "name": "Wood_Oak_Trunk_Full"
    },
    {
      "x": -1,
      "y": 9,
      "z": 2,
      "name": "Plant_Leaves_Oak",
      "rotation": 10
    },
    {
      "x": -1,
      "y": 10,
      "z": 2,
      "name": "Wood_Oak_Branch_Corner",
      "rotation": 10
    },
    {
      "x": -1,
      "y": 9,
      "z": 3,
      "name": "Plant_Leaves_Oak",
      "rotation": 10
    },
    {
      "x": -1,
      "y": 10,
      "z": 3,
      "name": "Plant_Leaves_Oak",
      "rotation": 10
    },
    {
      "x": -1,
      "y": 10,
      "z": 4,
      "name": "Plant_Leaves_Oak",
      "rotation": 10
    },
    {
      "x": 0,
      "y": 2,
      "z": -3,
      "name": "Wood_Oak_Roots",
      "rotation": 2
    },
    {
      "x": 0,
      "y": 3,
      "z": -3,
      "name": "Wood_Oak_Trunk_Full",
      "rotation": 10
    },
    {
      "x": 0,
      "y": 4,
      "z": -3,
      "name": "Wood_Oak_Trunk_Full"
    },
    {
      "x": 0,
      "y": 8,
      "z": -3,
      "name": "Plant_Leaves_Oak",
      "rotation": 10
    },
    {
      "x": 0,
      "y": 4,
      "z": -2,
      "name": "Wood_Oak_Trunk_Half",
      "rotation": 4
    },
    {
      "x": 0,
      "y": 7,
      "z": -2,
      "name": "Plant_Leaves_Oak",
      "rotation": 10
    },
    {
      "x": 0,
      "y": 8,
      "z": -2,
      "name": "Wood_Oak_Branch_Corner",
      "rotation": 3
    },
    {
      "x": 0,
      "y": 9,
      "z": -2,
      "name": "Wood_Oak_Branch_Corner",
      "rotation": 8
    },
    {
      "x": 0,
      "y": 8,
      "z": -1,
      "name": "Plant_Leaves_Oak",
      "rotation": 10
    },
    {
      "x": 0,
      "y": 9,
      "z": -1,
      "name": "Wood_Oak_Branch_Corner"
    },
    {
      "x": 0,
      "y": 10,
      "z": -1,
      "name": "Wood_Oak_Branch_Corner",
      "rotation": 8
    },
    {
      "x": 0,
      "y": 12,
      "z": -1,
      "name": "Wood_Oak_Trunk_Full",
      "rotation": 10
    },
    {
      "x": 0,
      "y": 13,
      "z": -1,
      "name": "Wood_Oak_Trunk_Full"
    },
    {
      "x": 0,
      "y": 14,
      "z": -1,
      "name": "Wood_Oak_Trunk_Full"
    },
    {
      "x": 0,
      "y": 10,
      "z": 0,
      "name": "Wood_Oak_Trunk_Full",
      "rotation": 10
    },
    {
      "x": 0,
      "y": 11,
      "z": 0,
      "name": "Wood_Oak_Trunk_Full",
      "rotation": 10
    },
    {
      "x": 0,
      "y": 12,
      "z": 0,
      "name": "Wood_Oak_Trunk_Full",
      "rotation": 10
    },
    {
      "x": 0,
      "y": 13,
      "z": 0,
      "name": "Wood_Oak_Trunk_Full"
    },
    {
      "x": 0,
      "y": 14,
      "z": 0,
      "name": "Wood_Oak_Trunk_Full"
    },
    {
      "x": 0,
      "y": 10,
      "z": 1,
      "name": "Plant_Leaves_Oak",
      "rotation": 10
    },
    {
      "x": 0,
      "y": 11,
      "z": 1,
      "name": "Wood_Oak_Trunk_Half",
      "rotation": 14
    },
    {
      "x": 0,
      "y": 12,
      "z": 1,
      "name": "Wood_Oak_Trunk_Full",
      "rotation": 10
    },
    {
      "x": 0,
      "y": 13,
      "z": 1,
      "name": "Wood_Oak_Trunk_Full"
    },
    {
      "x": 0,
      "y": 14,
      "z": 1,
      "name": "Wood_Oak_Trunk_Full"
    },
    {
      "x": 0,
      "y": 9,
      "z": 2,
      "name": "Plant_Leaves_Oak",
      "rotation": 10
    },
    {
      "x": 0,
      "y": 10,
      "z": 2,
      "name": "Plant_Leaves_Oak",
      "rotation": 10
    },
    {
      "x": 0,
      "y": 10,
      "z": 3,
      "name": "Plant_Leaves_Oak",
      "rotation": 10
    },
    {
      "x": 0,
      "y": 10,
      "z": 4,
      "name": "Plant_Leaves_Oak",
      "rotation": 10
    },
    {
      "x": 1,
      "y": 3,
      "z": -4,
      "name": "Wood_Oak_Trunk_Half",
      "rotation": 12
    },
    {
      "x": 1,
      "y": 2,
      "z": -3,
      "name": "Wood_Oak_Trunk_Half",
      "rotation": 10
    },
    {
      "x": 1,
      "y": 3,
      "z": -3,
      "name": "Wood_Oak_Trunk_Full",
      "rotation": 10
    },
    {
      "x": 1,
      "y": 7,
      "z": -3,
      "name": "Plant_Leaves_Oak",
      "rotation": 10
    },
    {
      "x": 1,
      "y": 8,
      "z": -3,
      "name": "Plant_Leaves_Oak",
      "rotation": 10
    },
    {
      "x": 1,
      "y": 3,
      "z": -2,
      "name": "Wood_Oak_Branch_Short"
    },
    {
      "x": 1,
      "y": 7,
      "z": -2,
      "name": "Plant_Leaves_Oak",
      "rotation": 10
    },
    {
      "x": 1,
      "y": 8,
      "z": -2,
      "name": "Wood_Oak_Branch_Corner",
      "rotation": 11
    },
    {
      "x": 1,
      "y": 7,
      "z": -1,
      "name": "Plant_Leaves_Oak",
      "rotation": 10
    },
    {
      "x": 1,
      "y": 8,
      "z": -1,
      "name": "Plant_Leaves_Oak",
      "rotation": 10
    },
    {
      "x": 1,
      "y": 12,
      "z": -1,
      "name": "Wood_Oak_Trunk_Full",
      "rotation": 10
    },
    {
      "x": 1,
      "y": 13,
      "z": -1,
      "name": "Wood_Oak_Trunk_Full"
    },
    {
      "x": 1,
      "y": 14,
      "z": -1,
      "name": "Wood_Oak_Trunk_Full"
    },
    {
      "x": 1,
      "y": 10,
      "z": 0,
      "name": "Wood_Oak_Roots"
    },
    {
      "x": 1,
      "y": 11,
      "z": 0,
      "name": "Wood_Oak_Trunk_Full",
      "rotation": 10
    },
    {
      "x": 1,
      "y": 12,
      "z": 0,
      "name": "Wood_Oak_Trunk_Full",
      "rotation": 10
    },
    {
      "x": 1,
      "y": 13,
      "z": 0,
      "name": "Wood_Oak_Trunk_Full"
    },
    {
      "x": 1,
      "y": 14,
      "z": 0,
      "name": "Wood_Oak_Trunk_Full"
    },
    {
      "x": 1,
      "y": 12,
      "z": 1,
      "name": "Wood_Oak_Trunk_Full",
      "rotation": 10
    },
    {
      "x": 1,
      "y": 13,
      "z": 1,
      "name": "Wood_Oak_Trunk_Full"
    },
    {
      "x": 1,
      "y": 14,
      "z": 1,
      "name": "Wood_Oak_Trunk_Full"
    },
    {
      "x": 1,
      "y": 10,
      "z": 2,
      "name": "Plant_Leaves_Oak",
      "rotation": 10
    },
    {
      "x": 1,
      "y": 10,
      "z": 3,
      "name": "Plant_Leaves_Oak",
      "rotation": 10
    },
    {
      "x": 2,
      "y": 2,
      "z": -4,
      "name": "Wood_Oak_Trunk_Half",
      "rotation": 12
    },
    {
      "x": 2,
      "y": 2,
      "z": -3,
      "name": "Wood_Oak_Trunk_Full",
      "rotation": 10
    },
    {
      "x": 2,
      "y": 3,
      "z": -3,
      "name": "Wood_Oak_Trunk_Half",
      "rotation": 2
    },
    {
      "x": 2,
      "y": 8,
      "z": -3,
      "name": "Plant_Leaves_Oak",
      "rotation": 10
    },
    {
      "x": 2,
      "y": 7,
      "z": -2,
      "name": "Plant_Leaves_Oak",
      "rotation": 10
    },
    {
      "x": 2,
      "y": 8,
      "z": -2,
      "name": "Plant_Leaves_Oak",
      "rotation": 10
    },
    {
      "x": 2,
      "y": 8,
      "z": -1,
      "name": "Plant_Leaves_Oak",
      "rotation": 10
    },
    {
      "x": 2,
      "y": 13,
      "z": -1,
      "name": "Wood_Oak_Trunk_Full"
    },
    {
      "x": 2,
      "y": 14,
      "z": -1,
      "name": "Wood_Oak_Trunk_Full"
    },
    {
      "x": 2,
      "y": 12,
      "z": 0,
      "name": "Wood_Oak_Trunk_Full",
      "rotation": 10
    },
    {
      "x": 2,
      "y": 13,
      "z": 0,
      "name": "Wood_Oak_Trunk_Full"
    },
    {
      "x": 2,
      "y": 14,
      "z": 0,
      "name": "Wood_Oak_Trunk_Full"
    },
    {
      "x": 2,
      "y": 13,
      "z": 1,
      "name": "Wood_Oak_Trunk_Full"
    },
    {
      "x": 2,
      "y": 14,
      "z": 1,
      "name": "Wood_Oak_Trunk_Full"
    },
    {
      "x": 3,
      "y": 2,
      "z": -4,
      "name": "Wood_Oak_Trunk_Half",
      "rotation": 12
    },
    {
      "x": 3,
      "y": 1,
      "z": -3,
      "name": "Wood_Oak_Roots",
      "rotation": 2
    },
    {
      "x": 3,
      "y": 2,
      "z": -3,
      "name": "Wood_Oak_Trunk_Full",
      "rotation": 10
    },
    {
      "x": 3,
      "y": 3,
      "z": -3,
      "name": "Wood_Oak_Trunk_Half",
      "rotation": 2
    },
    {
      "x": 3,
      "y": 5,
      "z": -3,
      "name": "Furniture_Kweebec_Candle",
      "rotation": 10
    },
    {
      "x": 3,
      "y": 6,
      "z": -3,
      "name": "Wood_Oak_Branch_Corner",
      "rotation": 9
    },
    {
      "x": 4,
      "y": 2,
      "z": -3,
      "name": "Wood_Oak_Trunk_Half",
      "rotation": 10
    },
    {
      "x": 4,
      "y": 3,
      "z": -3,
      "name": "Wood_Oak_Trunk_Full",
      "rotation": 10
    },
    {
      "x": 4,
      "y": 4,
      "z": -3,
      "name": "Wood_Oak_Branch_Long"
    },
    {
      "x": 4,
      "y": 5,
      "z": -3,
      "name": "Wood_Oak_Branch_Long"
    },
    {
      "x": 4,
      "y": 6,
      "z": -3,
      "name": "Wood_Oak_Branch_Corner",
      "rotation": 11
    },
    {
      "x": 4,
      "y": 3,
      "z": -2,
      "name": "Wood_Oak_Trunk_Half",
      "rotation": 14
    },
    {
      "x": 5,
      "y": 3,
      "z": -3,
      "name": "Wood_Oak_Trunk_Half",
      "rotation": 12
    },
    {
      "x": 5,
      "y": 1,
      "z": -2,
      "name": "Furniture_Kweebec_Candle",
      "rotation": 10
    },
    {
      "x": 5,
      "y": 2,
      "z": -2,
      "name": "Wood_Oak_Branch_Long",
      "rotation": 10
    },
    {
      "x": 5,
      "y": 3,
      "z": -2,
      "name": "Wood_Oak_Trunk_Full",
      "rotation": 10
    },
    {
      "x": 5,
      "y": 4,
      "z": -2,
      "name": "Wood_Oak_Trunk_Half",
      "rotation": 2
    },
    {
      "x": 5,
      "y": 3,
      "z": -1,
      "name": "Wood_Oak_Branch_Short"
    },
    {
      "x": 5,
      "y": 7,
      "z": 1,
      "name": "Rock_Crystal_Shroomlight_Block",
      "rotation": 10
    },
    {
      "x": 5,
      "y": 8,
      "z": 1,
      "name": "Rock_Crystal_Shroomlight_Block",
      "rotation": 13
    },
    {
      "x": 5,
      "y": 9,
      "z": 1,
      "name": "Wood_Oak_Trunk_Half",
      "rotation": 2
    },
    {
      "x": 5,
      "y": 7,
      "z": 2,
      "name": "Rock_Crystal_Shroomlight_Block",
      "rotation": 10
    },
    {
      "x": 5,
      "y": 8,
      "z": 2,
      "name": "Rock_Crystal_Shroomlight_Block",
      "rotation": 14
    },
    {
      "x": 6,
      "y": 4,
      "z": -3,
      "name": "Wood_Oak_Branch_Short",
      "rotation": 2
    },
    {
      "x": 6,
      "y": 3,
      "z": -2,
      "name": "Wood_Oak_Trunk_Half",
      "rotation": 10
    },
    {
      "x": 6,
      "y": 4,
      "z": -2,
      "name": "Wood_Oak_Trunk_Full",
      "rotation": 10
    },
    {
      "x": 6,
      "y": 4,
      "z": -1,
      "name": "Wood_Oak_Trunk_Half",
      "rotation": 14
    },
    {
      "x": 6,
      "y": 5,
      "z": -1,
      "name": "Wood_Oak_Trunk_Half",
      "rotation": 13
    },
    {
      "x": 6,
      "y": 6,
      "z": -1,
      "name": "Wood_Oak_Branch_Short",
      "rotation": 3
    },
    {
      "x": 6,
      "y": 7,
      "z": 0,
      "name": "Wood_Oak_Trunk_Full",
      "rotation": 10
    },
    {
      "x": 6,
      "y": 8,
      "z": 0,
      "name": "Wood_Oak_Trunk_Half",
      "rotation": 12
    },
    {
      "x": 6,
      "y": 6,
      "z": 1,
      "name": "Wood_Oak_Trunk_Half",
      "rotation": 10
    },
    {
      "x": 6,
      "y": 7,
      "z": 1,
      "name": "Rock_Crystal_Shroomlight_Block",
      "rotation": 10
    },
    {
      "x": 6,
      "y": 8,
      "z": 1,
      "name": "Rock_Crystal_Shroomlight_Block",
      "rotation": 10
    },
    {
      "x": 6,
      "y": 9,
      "z": 1,
      "name": "Wood_Oak_Trunk_Full",
      "rotation": 10
    },
    {
      "x": 6,
      "y": 7,
      "z": 2,
      "name": "Rock_Crystal_Shroomlight_Block",
      "rotation": 10
    },
    {
      "x": 6,
      "y": 8,
      "z": 2,
      "name": "Rock_Crystal_Shroomlight_Block",
      "rotation": 14
    },
    {
      "x": 6,
      "y": 9,
      "z": 2,
      "name": "Wood_Oak_Trunk_Half",
      "rotation": 2
    },
    {
      "x": 7,
      "y": 4,
      "z": -2,
      "name": "Wood_Oak_Trunk_Half",
      "rotation": 15
    },
    {
      "x": 7,
      "y": 5,
      "z": -2,
      "name": "Wood_Oak_Trunk_Half",
      "rotation": 12
    },
    {
      "x": 7,
      "y": 4,
      "z": -1,
      "name": "Wood_Oak_Roots",
      "rotation": 2
    },
    {
      "x": 7,
      "y": 5,
      "z": -1,
      "name": "Wood_Oak_Trunk_Full",
      "rotation": 10
    },
    {
      "x": 7,
      "y": 6,
      "z": -1,
      "name": "Wood_Oak_Trunk_Full",
      "rotation": 10
    },
    {
      "x": 7,
      "y": 7,
      "z": -1,
      "name": "Wood_Oak_Trunk_Half",
      "rotation": 12
    },
    {
      "x": 7,
      "y": 6,
      "z": 0,
      "name": "Wood_Oak_Trunk_Stairs",
      "rotation": 10
    },
    {
      "x": 7,
      "y": 7,
      "z": 0,
      "name": "Wood_Oak_Trunk_Full",
      "rotation": 10
    },
    {
      "x": 7,
      "y": 8,
      "z": 0,
      "name": "Wood_Oak_Trunk_Full",
      "rotation": 10
    },
    {
      "x": 7,
      "y": 7,
      "z": 1,
      "name": "Wood_Oak_Trunk_Full",
      "rotation": 10
    },
    {
      "x": 7,
      "y": 8,
      "z": 1,
      "name": "Wood_Oak_Trunk_Half",
      "rotation": 15
    }
  ]
}