{
  "version": 8,
  "blockIdVersion": 11,
  "anchorX": 1,
  "anchorY": 11,
  "anchorZ": 0,
  "blocks": [
    {
      "x": -5,
      "y": 7,
      "z": 0,
      "name": "Plant_Leaves_Oak",
      "rotation": 8
    },
    {
      "x": -5,
      "y": 6,
      "z": 1,
      "name": "Plant_Leaves_Oak",
      "rotation": 8
    },
    {
      "x": -5,
      "y": 7,
      "z": 1,
      "name": "Plant_Leaves_Oak",
      "rotation": 8
    },
    {
      "x": -5,
      "y": 7,
      "z": 2,
      "name": "Plant_Leaves_Oak",
      "rotation": 8
    },
    {
      "x": -4,
      "y": 7,
      "z": -1,
      "name": "Plant_Leaves_Oak",
      "rotation": 8
    },
    {
      "x": -4,
      "y": 6,
      "z": 0,
      "name": "Plant_Leaves_Oak",
      "rotation": 8
    },
    {
      "x": -4,
      "y": 7,
      "z": 0,
      "name": "Plant_Leaves_Oak",
      "rotation": 8
    },
    {
      "x": -4,
      "y": 6,
      "z": 1,
      "name": "Plant_Leaves_Oak",
      "rotation": 8
    },
    {
      "x": -4,
      "y": 7,
      "z": 1,
      "name": "Wood_Oak_Branch_Corner",
      "rotation": 9
    },
    {
      "x": -4,
      "y": 6,
      "z": 2,
      "name": "Plant_Leaves_Oak",
      "rotation": 8
    },
    {
      "x": -4,
      "y": 7,
      "z": 2,
      "name": "Plant_Leaves_Oak",
      "rotation": 8
    },
    {
      "x": -4,
      "y": 7,
      "z": 3,
      "name": "Plant_Leaves_Oak",
      "rotation": 8
    },
    {
      "x": -3,
      "y": 7,
      "z": -1,
      "name": "Plant_Leaves_Oak",
      "rotation": 8
    },
    {
      "x": -3,
      "y": 7,
      "z": 0,
      "name": "Plant_Leaves_Oak",
      "rotation": 8
    },
    {
      "x": -3,
      "y": 6,
      "z": 1,
      "name": "Plant_Leaves_Oak",
      "rotation": 8
    },
    {
      "x": -3,
      "y": 7,
      "z": 1,
      "name": "Wood_Oak_Branch_Long",
      "rotation": 15
    },
    {
      "x": -3,
      "y": 7,
      "z": 2,
      "name": "Plant_Leaves_Oak",
      "rotation": 8
    },
    {
      "x": -3,
      "y": 4,
      "z": 3,
      "name": "Furniture_Kweebec_Candle",
      "rotation": 11
    },
    {
      "x": -3,
      "y": 5,
      "z": 3,
      "name": "Wood_Oak_Branch_Corner",
      "rotation": 9
    },
    {
      "x": -2,
      "y": 7,
      "z": 1,
      "name": "Wood_Oak_Trunk_Full",
      "rotation": 8
    },
    {
      "x": -2,
      "y": 8,
      "z": 1,
      "name": "Wood_Oak_Trunk_Full",
      "rotation": 8
    },
    {
      "x": -2,
      "y": 5,
      "z": 2,
      "name": "Wood_Oak_Roots",
      "rotation": 1
    },
    {
      "x": -2,
      "y": 6,
      "z": 2,
      "name": "Wood_Oak_Trunk_Full",
      "rotation": 8
    },
    {
      "x": -2,
      "y": 7,
      "z": 2,
      "name": "Wood_Oak_Trunk_Full",
      "rotation": 8
    },
    {
      "x": -2,
      "y": 5,
      "z": 3,
      "name": "Wood_Oak_Trunk_Full",
      "rotation": 8
    },
    {
      "x": -2,
      "y": 6,
      "z": 3,
      "name": "Wood_Oak_Trunk_Full",
      "rotation": 8
    },
    {
      "x": -2,
      "y": 4,
      "z": 4,
      "name": "Wood_Oak_Trunk_Half",
      "rotation": 13
    },
    {
      "x": -2,
      "y": 5,
      "z": 4,
      "name": "Wood_Oak_Trunk_Half",
      "rotation": 14
    },
    {
      "x": -1,
      "y": 8,
      "z": 0,
      "name": "Wood_Oak_Trunk_Full",
      "rotation": 8
    },
    {
      "x": -1,
      "y": 9,
      "z": 0,
      "name": "Wood_Oak_Trunk_Full",
      "rotation": 8
    },
    {
      "x": -1,
      "y": 10,
      "z": 0,
      "name": "Wood_Oak_Trunk_Stairs",
      "rotation": 3
    },
    {
      "x": -1,
      "y": 11,
      "z": 0,
      "name": "Wood_Oak_Trunk_Full",
      "rotation": 8
    },
    {
      "x": -1,
      "y": 12,
      "z": 0,
      "name": "Wood_Oak_Trunk_Full"
    },
    {
      "x": -1,
      "y": 13,
      "z": 0,
      "name": "Wood_Oak_Trunk_Full"
    },
    {
      "x": -1,
      "y": 7,
      "z": 1,
      "name": "Wood_Oak_Trunk_Half",
      "rotation": 8
    },
    {
      "x": -1,
      "y": 8,
      "z": 1,
      "name": "Wood_Oak_Trunk_Full",
      "rotation": 8
    },
    {
      "x": -1,
      "y": 9,
      "z": 1,
      "name": "Wood_Oak_Trunk_Stairs"
    },
    {
      "x": -1,
      "y": 8,
      "z": 2,
      "name": "Wood_Oak_Branch_Short",
      "rotation": 10
    },
    {
      "x": -1,
      "y": 3,
      "z": 3,
      "name": "Wood_Oak_Branch_Short",
      "rotation": 8
    },
    {
      "x": -1,
      "y": 5,
      "z": 3,
      "name": "Wood_Oak_Trunk_Half",
      "rotation": 15
    },
    {
      "x": -1,
      "y": 2,
      "z": 4,
      "name": "Wood_Oak_Roots",
      "rotation": 1
    },
    {
      "x": -1,
      "y": 3,
      "z": 4,
      "name": "Wood_Oak_Trunk_Full",
      "rotation": 8
    },
    {
      "x": -1,
      "y": 4,
      "z": 4,
      "name": "Wood_Oak_Trunk_Full",
      "rotation": 8
    },
    {
      "x": 0,
      "y": 11,
      "z": -2,
      "name": "Wood_Oak_Trunk_Half",
      "rotation": 12
    },
    {
      "x": 0,
      "y": 12,
      "z": -2,
      "name": "Wood_Oak_Trunk_Full"
    },
    {
      "x": 0,
      "y": 13,
      "z": -2,
      "name": "Wood_Oak_Trunk_Full"
    },
    {
      "x": 0,
      "y": 9,
      "z": -1,
      "name": "Wood_Oak_Trunk_Half",
      "rotation": 12
    },
    {
      "x": 0,
      "y": 10,
      "z": -1,
      "name": "Wood_Oak_Trunk_Full",
      "rotation": 8
    },
    {
      "x": 0,
      "y": 11,
      "z": -1,
      "name": "Wood_Oak_Trunk_Full",
      "rotation": 8
    },
    {
      "x": 0,
      "y": 12,
      "z": -1,
      "name": "Wood_Oak_Trunk_Full"
    },
    {
      "x": 0,
      "y": 13,
      "z": -1,
      "name": "Wood_Oak_Trunk_Full"
    },
    {
      "x": 0,
      "y": 8,
      "z": 0,
      "name": "Wood_Oak_Trunk_Half",
      "rotation": 8
    },
    {
      "x": 0,
      "y": 9,
      "z": 0,
      "name": "Wood_Oak_Trunk_Full",
      "rotation": 8
    },
    {
      "x": 0,
      "y": 10,
      "z": 0,
      "name": "Wood_Oak_Trunk_Full",
      "rotation": 8
    },
    {
      "x": 0,
      "y": 11,
      "z": 0,
      "name": "Wood_Oak_Trunk_Full",
      "rotation": 8
    },
    {
      "x": 0,
      "y": 12,
      "z": 0,
      "name": "Wood_Oak_Trunk_Full"
    },
    {
      "x": 0,
      "y": 13,
      "z": 0,
      "name": "Wood_Oak_Trunk_Full"
    },
    {
      "x": 0,
      "y": 8,
      "z": 1,
      "name": "Plant_Leaves_Oak",
      "rotation": 9
    },
    {
      "x": 0,
      "y": 9,
      "z": 1,
      "name": "Wood_Oak_Branch_Long",
      "rotation": 12
    },
    {
      "x": 0,
      "y": 10,
      "z": 1,
      "name": "Wood_Oak_Trunk_Half",
      "rotation": 14
    },
    {
      "x": 0,
      "y": 11,
      "z": 1,
      "name": "Wood_Oak_Trunk_Full",
      "rotation": 8
    },
    {
      "x": 0,
      "y": 12,
      "z": 1,
      "name": "Wood_Oak_Trunk_Full"
    },
    {
      "x": 0,
      "y": 13,
      "z": 1,
      "name": "Wood_Oak_Trunk_Full"
    },
    {
      "x": 0,
      "y": 7,
      "z": 2,
      "name": "Plant_Leaves_Oak",
      "rotation": 9
    },
    {
      "x": 0,
      "y": 8,
      "z": 2,
      "name": "Wood_Oak_Branch_Corner",
      "rotation": 3
    },
    {
      "x": 0,
      "y": 9,
      "z": 2,
      "name": "Wood_Oak_Branch_Corner",
      "rotation": 10
    },
    {
      "x": 0,
      "y": 8,
      "z": 3,
      "name": "Plant_Leaves_Oak",
      "rotation": 9
    },
    {
      "x": 0,
      "y": 2,
      "z": 4,
      "name": "Wood_Oak_Trunk_Half",
      "rotation": 8
    },
    {
      "x": 0,
      "y": 3,
      "z": 4,
      "name": "Wood_Oak_Trunk_Full",
      "rotation": 8
    },
    {
      "x": 1,
      "y": 7,
      "z": -1,
      "name": "Wood_Oak_Trunk_Half",
      "rotation": 13
    },
    {
      "x": 1,
      "y": 11,
      "z": -1,
      "name": "Wood_Oak_Trunk_Half",
      "rotation": 12
    },
    {
      "x": 1,
      "y": 12,
      "z": -1,
      "name": "Wood_Oak_Trunk_Full"
    },
    {
      "x": 1,
      "y": 13,
      "z": -1,
      "name": "Wood_Oak_Trunk_Full"
    },
    {
      "x": 1,
      "y": 9,
      "z": 0,
      "name": "Wood_Oak_Trunk_Half",
      "rotation": 15
    },
    {
      "x": 1,
      "y": 10,
      "z": 0,
      "name": "Wood_Oak_Trunk_Full",
      "rotation": 8
    },
    {
      "x": 1,
      "y": 11,
      "z": 0,
      "name": "Wood_Oak_Trunk_Full",
      "rotation": 8
    },
    {
      "x": 1,
      "y": 12,
      "z": 0,
      "name": "Wood_Oak_Trunk_Full"
    },
    {
      "x": 1,
      "y": 13,
      "z": 0,
      "name": "Wood_Oak_Trunk_Full"
    },
    {
      "x": 1,
      "y": 7,
      "z": 1,
      "name": "Plant_Leaves_Oak",
      "rotation": 9
    },
    {
      "x": 1,
      "y": 8,
      "z": 1,
      "name": "Plant_Leaves_Oak",
      "rotation": 9
    },
    {
      "x": 1,
      "y": 11,
      "z": 1,
      "name": "Wood_Oak_Trunk_Half",
      "rotation": 14
    },
    {
      "x": 1,
      "y": 12,
      "z": 1,
      "name": "Wood_Oak_Trunk_Full"
    },
    {
      "x": 1,
      "y": 13,
      "z": 1,
      "name": "Wood_Oak_Trunk_Full"
    },
    {
      "x": 1,
      "y": 7,
      "z": 2,
      "name": "Plant_Leaves_Oak",
      "rotation": 9
    },
    {
      "x": 1,
      "y": 8,
      "z": 2,
      "name": "Wood_Oak_Branch_Corner",
      "rotation": 11
    },
    {
      "x": 1,
      "y": 1,
      "z": 3,
      "name": "Wood_Oak_Roots",
      "rotation": 1
    },
    {
      "x": 1,
      "y": 2,
      "z": 3,
      "name": "Wood_Oak_Trunk_Full",
      "rotation": 8
    },
    {
      "x": 1,
      "y": 3,
      "z": 3,
      "name": "Wood_Oak_Trunk_Half"
    },
    {
      "x": 1,
      "y": 7,
      "z": 3,
      "name": "Plant_Leaves_Oak",
      "rotation": 9
    },
    {
      "x": 1,
      "y": 8,
      "z": 3,
      "name": "Plant_Leaves_Oak",
      "rotation": 9
    },
    {
      "x": 1,
      "y": 2,
      "z": 4,
      "name": "Wood_Oak_Trunk_Half",
      "rotation": 8
    },
    {
      "x": 1,
      "y": 3,
      "z": 4,
      "name": "Wood_Oak_Trunk_Half"
    },
    {
      "x": 2,
      "y": 6,
      "z": -2,
      "name": "Wood_Oak_Trunk_Half",
      "rotation": 8
    },
    {
      "x": 2,
      "y": 7,
      "z": -2,
      "name": "Rock_Crystal_Shroomlight_Block",
      "rotation": 8
    },
    {
      "x": 2,
      "y": 8,
      "z": -2,
      "name": "Rock_Crystal_Shroomlight_Block",
      "rotation": 12
    },
    {
      "x": 2,
      "y": 6,
      "z": -1,
      "name": "Wood_Oak_Trunk_Stairs",
      "rotation": 9
    },
    {
      "x": 2,
      "y": 7,
      "z": -1,
      "name": "Rock_Crystal_Shroomlight_Block",
      "rotation": 8
    },
    {
      "x": 2,
      "y": 8,
      "z": -1,
      "name": "Rock_Crystal_Shroomlight_Block",
      "rotation": 12
    },
    {
      "x": 2,
      "y": 7,
      "z": 0,
      "name": "Wood_Oak_Trunk_Half",
      "rotation": 14
    },
    {
      "x": 2,
      "y": 11,
      "z": 0,
      "name": "Wood_Oak_Trunk_Half",
      "rotation": 15
    },
    {
      "x": 2,
      "y": 12,
      "z": 0,
      "name": "Wood_Oak_Trunk_Full"
    },
    {
      "x": 2,
      "y": 13,
      "z": 0,
      "name": "Wood_Oak_Trunk_Full"
    },
    {
      "x": 2,
      "y": 8,
      "z": 1,
      "name": "Plant_Leaves_Oak",
      "rotation": 9
    },
    {
      "x": 2,
      "y": 2,
      "z": 2,
      "name": "Wood_Oak_Trunk_Full",
      "rotation": 8
    },
    {
      "x": 2,
      "y": 7,
      "z": 2,
      "name": "Plant_Leaves_Oak",
      "rotation": 9
    },
    {
      "x": 2,
      "y": 8,
      "z": 2,
      "name": "Plant_Leaves_Oak",
      "rotation": 9
    },
    {
      "x": 2,
      "y": 0,
      "z": 3,
      "name": "Furniture_Kweebec_Candle",
      "rotation": 9
    },
    {
      "x": 2,
      "y": 1,
      "z": 3,
      "name": "Wood_Oak_Branch_Long",
      "rotation": 9
    },
    {
      "x": 2,
      "y": 2,
      "z": 3,
      "name": "Wood_Oak_Trunk_Full",
      "rotation": 8
    },
    {
      "x": 2,
      "y": 8,
      "z": 3,
      "name": "Plant_Leaves_Oak",
      "rotation": 9
    },
    {
      "x": 2,
      "y": 2,
      "z": 4,
      "name": "Wood_Oak_Branch_Short",
      "rotation": 10
    },
    {
      "x": 3,
      "y": 7,
      "z": -3,
      "name": "Wood_Oak_Trunk_Half",
      "rotation": 12
    },
    {
      "x": 3,
      "y": 6,
      "z": -2,
      "name": "Wood_Oak_Trunk_Stairs",
      "rotation": 8
    },
    {
      "x": 3,
      "y": 7,
      "z": -2,
      "name": "Rock_Crystal_Shroomlight_Block",
      "rotation": 8
    },
    {
      "x": 3,
      "y": 8,
      "z": -2,
      "name": "Rock_Crystal_Shroomlight_Block",
      "rotation": 15
    },
    {
      "x": 3,
      "y": 4,
      "z": -1,
      "name": "Wood_Oak_Branch_Short",
      "rotation": 9
    },
    {
      "x": 3,
      "y": 5,
      "z": -1,
      "name": "Wood_Oak_Trunk_Stairs",
      "rotation": 9
    },
    {
      "x": 3,
      "y": 6,
      "z": -1,
      "name": "Wood_Oak_Trunk_Full",
      "rotation": 8
    },
    {
      "x": 3,
      "y": 7,
      "z": -1,
      "name": "Rock_Crystal_Shroomlight_Block",
      "rotation": 8
    },
    {
      "x": 3,
      "y": 8,
      "z": -1,
      "name": "Rock_Crystal_Shroomlight_Block",
      "rotation": 12
    },
    {
      "x": 3,
      "y": 6,
      "z": 0,
      "name": "Wood_Oak_Trunk_Half",
      "rotation": 14
    },
    {
      "x": 3,
      "y": 7,
      "z": 0,
      "name": "Wood_Oak_Trunk_Half",
      "rotation": 14
    },
    {
      "x": 3,
      "y": 1,
      "z": 1,
      "name": "Wood_Oak_Roots",
      "rotation": 1
    },
    {
      "x": 3,
      "y": 2,
      "z": 1,
      "name": "Wood_Oak_Trunk_Full",
      "rotation": 8
    },
    {
      "x": 3,
      "y": 3,
      "z": 1,
      "name": "Wood_Oak_Trunk_Half"
    },
    {
      "x": 3,
      "y": 2,
      "z": 2,
      "name": "Wood_Oak_Trunk_Full",
      "rotation": 8
    },
    {
      "x": 4,
      "y": 7,
      "z": -2,
      "name": "Wood_Oak_Trunk_Half",
      "rotation": 15
    },
    {
      "x": 4,
      "y": 3,
      "z": -1,
      "name": "Wood_Oak_Roots",
      "rotation": 1
    },
    {
      "x": 4,
      "y": 4,
      "z": -1,
      "name": "Wood_Oak_Trunk_Full",
      "rotation": 8
    },
    {
      "x": 4,
      "y": 5,
      "z": -1,
      "name": "Wood_Oak_Trunk_Full",
      "rotation": 8
    },
    {
      "x": 4,
      "y": 6,
      "z": -1,
      "name": "Wood_Oak_Trunk_Half",
      "rotation": 15
    },
    {
      "x": 4,
      "y": 7,
      "z": -1,
      "name": "Wood_Oak_Trunk_Half",
      "rotation": 15
    },
    {
      "x": 4,
      "y": 3,
      "z": 0,
      "name": "Wood_Oak_Trunk_Full",
      "rotation": 8
    },
    {
      "x": 4,
      "y": 4,
      "z": 0,
      "name": "Wood_Oak_Trunk_Stairs"
    },
    {
      "x": 4,
      "y": 2,
      "z": 1,
      "name": "Wood_Oak_Trunk_Half",
      "rotation": 8
    },
    {
      "x": 4,
      "y": 3,
      "z": 1,
      "name": "Wood_Oak_Trunk_Stairs"
    },
    {
      "x": 5,
      "y": 4,
      "z": -1,
      "name": "Furniture_Kweebec_Candle",
      "rotation": 8
    },
    {
      "x": 5,
      "y": 5,
      "z": -1,
      "name": "Wood_Oak_Branch_Corner",
      "rotation": 11
    }
  ]
}