{
  "version": 8,
  "blockIdVersion": 11,
  "anchorX": -1,
  "anchorY": 0,
  "anchorZ": 0,
  "blocks": [
    {
      "x": -3,
      "y": -3,
      "z": -4,
      "name": "Soil_Pathway"
    },
    {
      "x": -3,
      "y": -2,
      "z": -4,
      "name": "Soil_Pathway"
    },
    {
      "x": -3,
      "y": -1,
      "z": -4,
      "name": "Soil_Pathway"
    },
    {
      "x": -3,
      "y": 0,
      "z": -4,
      "name": "Empty"
    },
    {
      "x": -3,
      "y": 1,
      "z": -4,
      "name": "Empty"
    },
    {
      "x": -3,
      "y": -3,
      "z": -3,
      "name": "Soil_Pathway"
    },
    {
      "x": -3,
      "y": -2,
      "z": -3,
      "name": "Soil_Pathway"
    },
    {
      "x": -3,
      "y": -1,
      "z": -3,
      "name": "Soil_Pathway"
    },
    {
      "x": -3,
      "y": 0,
      "z": -3,
      "name": "Empty"
    },
    {
      "x": -3,
      "y": 1,
      "z": -3,
      "name": "Empty"
    },
    {
      "x": -3,
      "y": -3,
      "z": -2,
      "name": "Soil_Pathway"
    },
    {
      "x": -3,
      "y": -2,
      "z": -2,
      "name": "Soil_Pathway"
    },
    {
      "x": -3,
      "y": -1,
      "z": -2,
      "name": "Soil_Pathway"
    },
    {
      "x": -3,
      "y": 0,
      "z": -2,
      "name": "Empty"
    },
    {
      "x": -3,
      "y": 1,
      "z": -2,
      "name": "Empty"
    },
    {
      "x": -3,
      "y": -3,
      "z": -1,
      "name": "Soil_Pathway"
    },
    {
      "x": -3,
      "y": -2,
      "z": -1,
      "name": "Soil_Pathway"
    },
    {
      "x": -3,
      "y": -1,
      "z": -1,
      "name": "Soil_Pathway"
    },
    {
      "x": -3,
      "y": 0,
      "z": -1,
      "name": "Soil_Pathway"
    },
    {
      "x": -3,
      "y": -3,
      "z": 0,
      "name": "Soil_Pathway"
    },
    {
      "x": -3,
      "y": -2,
      "z": 0,
      "name": "Soil_Pathway"
    },
    {
      "x": -3,
      "y": -1,
      "z": 0,
      "name": "Soil_Pathway"
    },
    {
      "x": -3,
      "y": 0,
      "z": 0,
      "name": "Soil_Pathway"
    },
    {
      "x": -2,
      "y": -3,
      "z": -4,
      "name": "Soil_Pathway"
    },
    {
      "x": -2,
      "y": -2,
      "z": -4,
      "name": "Soil_Pathway"
    },
    {
      "x": -2,
      "y": -1,
      "z": -4,
      "name": "Soil_Pathway"
    },
    {
      "x": -2,
      "y": 0,
      "z": -4,
      "name": "Empty"
    },
    {
      "x": -2,
      "y": 1,
      "z": -4,
      "name": "Empty"
    },
    {
      "x": -2,
      "y": -3,
      "z": -3,
      "name": "Soil_Pathway"
    },
    {
      "x": -2,
      "y": -2,
      "z": -3,
      "name": "Soil_Dirt"
    },
    {
      "x": -2,
      "y": -1,
      "z": -3,
      "name": "Soil_Dirt"
    },
    {
      "x": -2,
      "y": 0,
      "z": -3,
      "name": "Wood_Oak_Trunk",
      "support": 15,
      "rotation": 5
    },
    {
      "x": -2,
      "y": 1,
      "z": -3,
      "name": "Empty"
    },
    {
      "x": -2,
      "y": -3,
      "z": -2,
      "name": "Soil_Pathway"
    },
    {
      "x": -2,
      "y": -2,
      "z": -2,
      "name": "Soil_Pathway"
    },
    {
      "x": -2,
      "y": -1,
      "z": -2,
      "name": "Soil_Pathway"
    },
    {
      "x": -2,
      "y": 0,
      "z": -2,
      "name": "Empty"
    },
    {
      "x": -2,
      "y": 1,
      "z": -2,
      "name": "Empty"
    },
    {
      "x": -2,
      "y": -3,
      "z": -1,
      "name": "Soil_Pathway"
    },
    {
      "x": -2,
      "y": -2,
      "z": -1,
      "name": "Soil_Pathway"
    },
    {
      "x": -2,
      "y": -1,
      "z": -1,
      "name": "Soil_Pathway"
    },
    {
      "x": -2,
      "y": 0,
      "z": -1,
      "name": "Empty"
    },
    {
      "x": -2,
      "y": 1,
      "z": -1,
      "name": "Empty"
    },
    {
      "x": -2,
      "y": -3,
      "z": 0,
      "name": "Soil_Pathway"
    },
    {
      "x": -2,
      "y": -2,
      "z": 0,
      "name": "Soil_Pathway"
    },
    {
      "x": -2,
      "y": -1,
      "z": 0,
      "name": "Soil_Pathway"
    },
    {
      "x": -2,
      "y": 0,
      "z": 0,
      "name": "Empty"
    },
    {
      "x": -2,
      "y": 1,
      "z": 0,
      "name": "Empty"
    },
    {
      "x": -2,
      "y": -3,
      "z": 1,
      "name": "Soil_Pathway"
    },
    {
      "x": -2,
      "y": -2,
      "z": 1,
      "name": "Soil_Pathway"
    },
    {
      "x": -2,
      "y": -1,
      "z": 1,
      "name": "Soil_Pathway"
    },
    {
      "x": -2,
      "y": 0,
      "z": 1,
      "name": "Empty"
    },
    {
      "x": -2,
      "y": 1,
      "z": 1,
      "name": "Empty"
    },
    {
      "x": -2,
      "y": -3,
      "z": 2,
      "name": "Soil_Pathway"
    },
    {
      "x": -2,
      "y": -2,
      "z": 2,
      "name": "Soil_Pathway"
    },
    {
      "x": -2,
      "y": -1,
      "z": 2,
      "name": "Soil_Pathway"
    },
    {
      "x": -2,
      "y": 0,
      "z": 2,
      "name": "Soil_Pathway"
    },
    {
      "x": -1,
      "y": 0,
      "z": -4,
      "name": "Empty"
    },
    {
      "x": -1,
      "y": 1,
      "z": -4,
      "name": "Empty"
    },
    {
      "x": -1,
      "y": -3,
      "z": -3,
      "name": "Soil_Pathway"
    },
    {
      "x": -1,
      "y": -2,
      "z": -3,
      "name": "Soil_Dirt"
    },
    {
      "x": -1,
      "y": -1,
      "z": -3,
      "name": "Soil_Dirt"
    },
    {
      "x": -1,
      "y": 0,
      "z": -3,
      "name": "Wood_Oak_Trunk",
      "support": 15,
      "rotation": 5
    },
    {
      "x": -1,
      "y": 1,
      "z": -3,
      "name": "Empty"
    },
    {
      "x": -1,
      "y": -3,
      "z": -2,
      "name": "Soil_Pathway"
    },
    {
      "x": -1,
      "y": -2,
      "z": -2,
      "name": "Soil_Pathway"
    },
    {
      "x": -1,
      "y": -1,
      "z": -2,
      "name": "Soil_Pathway"
    },
    {
      "x": -1,
      "y": 0,
      "z": -2,
      "name": "Empty"
    },
    {
      "x": -1,
      "y": 1,
      "z": -2,
      "name": "Empty"
    },
    {
      "x": -1,
      "y": -3,
      "z": -1,
      "name": "Soil_Pathway"
    },
    {
      "x": -1,
      "y": -2,
      "z": -1,
      "name": "Soil_Pathway"
    },
    {
      "x": -1,
      "y": -1,
      "z": -1,
      "name": "Soil_Pathway"
    },
    {
      "x": -1,
      "y": 0,
      "z": -1,
      "name": "Empty"
    },
    {
      "x": -1,
      "y": 1,
      "z": -1,
      "name": "Empty"
    },
    {
      "x": -1,
      "y": -3,
      "z": 0,
      "name": "Soil_Pathway"
    },
    {
      "x": -1,
      "y": -2,
      "z": 0,
      "name": "Soil_Dirt"
    },
    {
      "x": -1,
      "y": -1,
      "z": 0,
      "name": "Soil_Dirt"
    },
    {
      "x": -1,
      "y": 0,
      "z": 0,
      "name": "Deco_Campfire_Off"
    },
    {
      "x": -1,
      "y": 1,
      "z": 0,
      "name": "Empty"
    },
    {
      "x": -1,
      "y": -3,
      "z": 1,
      "name": "Soil_Pathway"
    },
    {
      "x": -1,
      "y": -2,
      "z": 1,
      "name": "Soil_Pathway"
    },
    {
      "x": -1,
      "y": -1,
      "z": 1,
      "name": "Soil_Pathway"
    },
    {
      "x": -1,
      "y": 0,
      "z": 1,
      "name": "Empty"
    },
    {
      "x": -1,
      "y": 1,
      "z": 1,
      "name": "Empty"
    },
    {
      "x": -1,
      "y": -3,
      "z": 2,
      "name": "Soil_Pathway"
    },
    {
      "x": -1,
      "y": -2,
      "z": 2,
      "name": "Soil_Pathway"
    },
    {
      "x": -1,
      "y": -1,
      "z": 2,
      "name": "Soil_Pathway"
    },
    {
      "x": -1,
      "y": 0,
      "z": 2,
      "name": "Soil_Pathway"
    },
    {
      "x": 0,
      "y": 0,
      "z": -4,
      "name": "Empty"
    },
    {
      "x": 0,
      "y": 1,
      "z": -4,
      "name": "Empty"
    },
    {
      "x": 0,
      "y": -3,
      "z": -3,
      "name": "Soil_Pathway"
    },
    {
      "x": 0,
      "y": -2,
      "z": -3,
      "name": "Soil_Dirt"
    },
    {
      "x": 0,
      "y": -1,
      "z": -3,
      "name": "Soil_Dirt"
    },
    {
      "x": 0,
      "y": 0,
      "z": -3,
      "name": "Wood_Oak_Trunk",
      "support": 15,
      "rotation": 5
    },
    {
      "x": 0,
      "y": 1,
      "z": -3,
      "name": "Empty"
    },
    {
      "x": 0,
      "y": -3,
      "z": -2,
      "name": "Soil_Pathway"
    },
    {
      "x": 0,
      "y": -2,
      "z": -2,
      "name": "Soil_Pathway"
    },
    {
      "x": 0,
      "y": -1,
      "z": -2,
      "name": "Soil_Pathway"
    },
    {
      "x": 0,
      "y": 0,
      "z": -2,
      "name": "Empty"
    },
    {
      "x": 0,
      "y": 1,
      "z": -2,
      "name": "Empty"
    },
    {
      "x": 0,
      "y": -3,
      "z": -1,
      "name": "Soil_Pathway"
    },
    {
      "x": 0,
      "y": -2,
      "z": -1,
      "name": "Soil_Pathway"
    },
    {
      "x": 0,
      "y": -1,
      "z": -1,
      "name": "Soil_Pathway"
    },
    {
      "x": 0,
      "y": 0,
      "z": -1,
      "name": "Empty"
    },
    {
      "x": 0,
      "y": 1,
      "z": -1,
      "name": "Empty"
    },
    {
      "x": 0,
      "y": -3,
      "z": 0,
      "name": "Soil_Pathway"
    },
    {
      "x": 0,
      "y": -2,
      "z": 0,
      "name": "Soil_Pathway"
    },
    {
      "x": 0,
      "y": -1,
      "z": 0,
      "name": "Soil_Pathway"
    },
    {
      "x": 0,
      "y": 0,
      "z": 0,
      "name": "Empty"
    },
    {
      "x": 0,
      "y": 1,
      "z": 0,
      "name": "Empty"
    },
    {
      "x": 0,
      "y": -3,
      "z": 1,
      "name": "Soil_Pathway"
    },
    {
      "x": 0,
      "y": -2,
      "z": 1,
      "name": "Soil_Pathway"
    },
    {
      "x": 0,
      "y": -1,
      "z": 1,
      "name": "Soil_Pathway"
    },
    {
      "x": 0,
      "y": 0,
      "z": 1,
      "name": "Empty"
    },
    {
      "x": 0,
      "y": 1,
      "z": 1,
      "name": "Empty"
    },
    {
      "x": 0,
      "y": -3,
      "z": 2,
      "name": "Soil_Pathway"
    },
    {
      "x": 0,
      "y": -2,
      "z": 2,
      "name": "Soil_Pathway"
    },
    {
      "x": 0,
      "y": -1,
      "z": 2,
      "name": "Soil_Pathway"
    },
    {
      "x": 0,
      "y": 0,
      "z": 2,
      "name": "Soil_Pathway"
    },
    {
      "x": 1,
      "y": 0,
      "z": -4,
      "name": "Empty"
    },
    {
      "x": 1,
      "y": 1,
      "z": -4,
      "name": "Empty"
    },
    {
      "x": 1,
      "y": -3,
      "z": -3,
      "name": "Soil_Pathway"
    },
    {
      "x": 1,
      "y": -2,
      "z": -3,
      "name": "Soil_Pathway"
    },
    {
      "x": 1,
      "y": -1,
      "z": -3,
      "name": "Soil_Pathway"
    },
    {
      "x": 1,
      "y": 0,
      "z": -3,
      "name": "Empty"
    },
    {
      "x": 1,
      "y": 1,
      "z": -3,
      "name": "Empty"
    },
    {
      "x": 1,
      "y": -3,
      "z": -2,
      "name": "Soil_Pathway"
    },
    {
      "x": 1,
      "y": -2,
      "z": -2,
      "name": "Soil_Pathway"
    },
    {
      "x": 1,
      "y": -1,
      "z": -2,
      "name": "Soil_Pathway"
    },
    {
      "x": 1,
      "y": 0,
      "z": -2,
      "name": "Empty"
    },
    {
      "x": 1,
      "y": 1,
      "z": -2,
      "name": "Empty"
    },
    {
      "x": 1,
      "y": -3,
      "z": -1,
      "name": "Soil_Pathway"
    },
    {
      "x": 1,
      "y": -2,
      "z": -1,
      "name": "Soil_Pathway"
    },
    {
      "x": 1,
      "y": -1,
      "z": -1,
      "name": "Soil_Pathway"
    },
    {
      "x": 1,
      "y": 0,
      "z": -1,
      "name": "Empty"
    },
    {
      "x": 1,
      "y": 1,
      "z": -1,
      "name": "Empty"
    },
    {
      "x": 1,
      "y": -3,
      "z": 0,
      "name": "Soil_Pathway"
    },
    {
      "x": 1,
      "y": -2,
      "z": 0,
      "name": "Soil_Pathway"
    },
    {
      "x": 1,
      "y": -1,
      "z": 0,
      "name": "Soil_Pathway"
    },
    {
      "x": 1,
      "y": 0,
      "z": 0,
      "name": "Empty"
    },
    {
      "x": 1,
      "y": 1,
      "z": 0,
      "name": "Empty"
    },
    {
      "x": 1,
      "y": -3,
      "z": 1,
      "name": "Soil_Pathway"
    },
    {
      "x": 1,
      "y": -2,
      "z": 1,
      "name": "Soil_Pathway"
    },
    {
      "x": 1,
      "y": -1,
      "z": 1,
      "name": "Soil_Pathway"
    },
    {
      "x": 1,
      "y": 0,
      "z": 1,
      "name": "Empty"
    },
    {
      "x": 1,
      "y": 1,
      "z": 1,
      "name": "Empty"
    },
    {
      "x": 1,
      "y": -3,
      "z": 2,
      "name": "Soil_Pathway"
    },
    {
      "x": 1,
      "y": -2,
      "z": 2,
      "name": "Soil_Pathway"
    },
    {
      "x": 1,
      "y": -1,
      "z": 2,
      "name": "Soil_Pathway"
    },
    {
      "x": 1,
      "y": 0,
      "z": 2,
      "name": "Soil_Pathway"
    },
    {
      "x": 2,
      "y": -3,
      "z": -4,
      "name": "Soil_Pathway"
    },
    {
      "x": 2,
      "y": -2,
      "z": -4,
      "name": "Soil_Pathway"
    },
    {
      "x": 2,
      "y": -1,
      "z": -4,
      "name": "Soil_Pathway"
    },
    {
      "x": 2,
      "y": 0,
      "z": -4,
      "name": "Soil_Pathway"
    },
    {
      "x": 2,
      "y": -3,
      "z": -3,
      "name": "Soil_Pathway"
    },
    {
      "x": 2,
      "y": -2,
      "z": -3,
      "name": "Soil_Pathway"
    },
    {
      "x": 2,
      "y": -1,
      "z": -3,
      "name": "Soil_Pathway"
    },
    {
      "x": 2,
      "y": 0,
      "z": -3,
      "name": "Empty"
    },
    {
      "x": 2,
      "y": 1,
      "z": -3,
      "name": "Empty"
    },
    {
      "x": 2,
      "y": -3,
      "z": -2,
      "name": "Soil_Pathway"
    },
    {
      "x": 2,
      "y": -2,
      "z": -2,
      "name": "Soil_Pathway"
    },
    {
      "x": 2,
      "y": -1,
      "z": -2,
      "name": "Soil_Pathway"
    },
    {
      "x": 2,
      "y": 0,
      "z": -2,
      "name": "Empty"
    },
    {
      "x": 2,
      "y": 1,
      "z": -2,
      "name": "Empty"
    },
    {
      "x": 2,
      "y": -3,
      "z": -1,
      "name": "Soil_Pathway"
    },
    {
      "x": 2,
      "y": -2,
      "z": -1,
      "name": "Soil_Pathway"
    },
    {
      "x": 2,
      "y": -1,
      "z": -1,
      "name": "Soil_Pathway"
    },
    {
      "x": 2,
      "y": 0,
      "z": -1,
      "name": "Empty"
    },
    {
      "x": 2,
      "y": 1,
      "z": -1,
      "name": "Empty"
    },
    {
      "x": 2,
      "y": -3,
      "z": 0,
      "name": "Soil_Pathway"
    },
    {
      "x": 2,
      "y": -2,
      "z": 0,
      "name": "Soil_Dirt"
    },
    {
      "x": 2,
      "y": -1,
      "z": 0,
      "name": "Soil_Dirt"
    },
    {
      "x": 2,
      "y": 0,
      "z": 0,
      "name": "Wood_Oak_Trunk",
      "support": 15
    },
    {
      "x": 2,
      "y": 1,
      "z": 0,
      "name": "Empty"
    },
    {
      "x": 2,
      "y": -3,
      "z": 1,
      "name": "Soil_Pathway"
    },
    {
      "x": 2,
      "y": -2,
      "z": 1,
      "name": "Soil_Pathway"
    },
    {
      "x": 2,
      "y": -1,
      "z": 1,
      "name": "Soil_Pathway"
    },
    {
      "x": 2,
      "y": 0,
      "z": 1,
      "name": "Empty"
    },
    {
      "x": 2,
      "y": 1,
      "z": 1,
      "name": "Empty"
    },
    {
      "x": 3,
      "y": -3,
      "z": -4,
      "name": "Soil_Pathway"
    },
    {
      "x": 3,
      "y": -2,
      "z": -4,
      "name": "Soil_Pathway"
    },
    {
      "x": 3,
      "y": -1,
      "z": -4,
      "name": "Soil_Pathway"
    },
    {
      "x": 3,
      "y": 0,
      "z": -4,
      "name": "Soil_Pathway"
    },
    {
      "x": 3,
      "y": -3,
      "z": -3,
      "name": "Soil_Pathway"
    },
    {
      "x": 3,
      "y": -2,
      "z": -3,
      "name": "Soil_Pathway"
    },
    {
      "x": 3,
      "y": -1,
      "z": -3,
      "name": "Soil_Pathway"
    },
    {
      "x": 3,
      "y": 0,
      "z": -3,
      "name": "Soil_Pathway"
    },
    {
      "x": 3,
      "y": -3,
      "z": -2,
      "name": "Soil_Pathway"
    },
    {
      "x": 3,
      "y": -2,
      "z": -2,
      "name": "Soil_Pathway"
    },
    {
      "x": 3,
      "y": -1,
      "z": -2,
      "name": "Soil_Pathway"
    },
    {
      "x": 3,
      "y": 0,
      "z": -2,
      "name": "Soil_Pathway"
    },
    {
      "x": 3,
      "y": -3,
      "z": -1,
      "name": "Soil_Pathway"
    },
    {
      "x": 3,
      "y": -2,
      "z": -1,
      "name": "Soil_Pathway"
    },
    {
      "x": 3,
      "y": -1,
      "z": -1,
      "name": "Soil_Pathway"
    },
    {
      "x": 3,
      "y": 0,
      "z": -1,
      "name": "Empty"
    },
    {
      "x": 3,
      "y": 1,
      "z": -1,
      "name": "Empty"
    },
    {
      "x": 3,
      "y": 0,
      "z": 0,
      "name": "Empty"
    },
    {
      "x": 3,
      "y": 1,
      "z": 0,
      "name": "Empty"
    },
    {
      "x": 3,
      "y": 0,
      "z": 1,
      "name": "Empty"
    },
    {
      "x": 3,
      "y": 1,
      "z": 1,
      "name": "Empty"
    }
  ]
}