{
  "version": 8,
  "blockIdVersion": 11,
  "anchorX": 0,
  "anchorY": 0,
  "anchorZ": 0,
  "blocks": [
    {
      "x": -2,
      "y": -3,
      "z": -1,
      "name": "Rock_Slate_Stalactite_Large",
      "filler": 31744,
      "rotation": 8
    },
    {
      "x": -2,
      "y": -2,
      "z": -1,
      "name": "Rock_Slate_Stalactite_Large",
      "rotation": 8
    },
    {
      "x": -2,
      "y": -1,
      "z": -1,
      "name": "Rock_Slate"
    },
    {
      "x": -2,
      "y": 0,
      "z": -1,
      "name": "Rock_Slate_Cobble"
    },
    {
      "x": -2,
      "y": 1,
      "z": -1,
      "name": "Rock_Slate"
    },
    {
      "x": -2,
      "y": 2,
      "z": -1,
      "name": "Rock_Slate"
    },
    {
      "x": -2,
      "y": -6,
      "z": 0,
      "name": "Rock_Slate_Stalactite_Large",
      "filler": 31744,
      "rotation": 8
    },
    {
      "x": -2,
      "y": -5,
      "z": 0,
      "name": "Rock_Slate_Stalactite_Large",
      "rotation": 8
    },
    {
      "x": -2,
      "y": -4,
      "z": 0,
      "name": "Rock_Slate"
    },
    {
      "x": -2,
      "y": -3,
      "z": 0,
      "name": "Rock_Slate_Cobble"
    },
    {
      "x": -2,
      "y": -2,
      "z": 0,
      "name": "Rock_Slate"
    },
    {
      "x": -2,
      "y": -1,
      "z": 0,
      "name": "Rock_Slate"
    },
    {
      "x": -2,
      "y": 0,
      "z": 0,
      "name": "Rock_Slate_Cobble"
    },
    {
      "x": -2,
      "y": 1,
      "z": 0,
      "name": "Rock_Slate"
    },
    {
      "x": -2,
      "y": 2,
      "z": 0,
      "name": "Rock_Slate"
    },
    {
      "x": -2,
      "y": -4,
      "z": 1,
      "name": "Rock_Slate_Stalactite_Large",
      "filler": 31744,
      "rotation": 8
    },
    {
      "x": -2,
      "y": -3,
      "z": 1,
      "name": "Rock_Slate_Stalactite_Large",
      "rotation": 8
    },
    {
      "x": -2,
      "y": -2,
      "z": 1,
      "name": "Rock_Slate"
    },
    {
      "x": -2,
      "y": -1,
      "z": 1,
      "name": "Rock_Slate"
    },
    {
      "x": -2,
      "y": 0,
      "z": 1,
      "name": "Rock_Slate_Cobble"
    },
    {
      "x": -2,
      "y": 1,
      "z": 1,
      "name": "Rock_Slate"
    },
    {
      "x": -2,
      "y": 2,
      "z": 1,
      "name": "Rock_Slate"
    },
    {
      "x": -1,
      "y": -2,
      "z": -2,
      "name": "Rock_Slate_Stalactite_Small",
      "rotation": 8
    },
    {
      "x": -1,
      "y": -1,
      "z": -2,
      "name": "Rock_Slate"
    },
    {
      "x": -1,
      "y": 0,
      "z": -2,
      "name": "Rock_Slate_Cobble"
    },
    {
      "x": -1,
      "y": 1,
      "z": -2,
      "name": "Rock_Slate"
    },
    {
      "x": -1,
      "y": 2,
      "z": -2,
      "name": "Rock_Slate"
    },
    {
      "x": -1,
      "y": -7,
      "z": -1,
      "name": "Rock_Slate_Stalactite_Large",
      "filler": 31744,
      "rotation": 8
    },
    {
      "x": -1,
      "y": -6,
      "z": -1,
      "name": "Rock_Slate_Stalactite_Large",
      "rotation": 8
    },
    {
      "x": -1,
      "y": -5,
      "z": -1,
      "name": "Rock_Slate"
    },
    {
      "x": -1,
      "y": -4,
      "z": -1,
      "name": "Rock_Slate"
    },
    {
      "x": -1,
      "y": -3,
      "z": -1,
      "name": "Rock_Slate_Cobble"
    },
    {
      "x": -1,
      "y": -2,
      "z": -1,
      "name": "Rock_Slate"
    },
    {
      "x": -1,
      "y": -1,
      "z": -1,
      "name": "Rock_Slate"
    },
    {
      "x": -1,
      "y": 0,
      "z": -1,
      "name": "Rock_Slate_Cobble"
    },
    {
      "x": -1,
      "y": 1,
      "z": -1,
      "name": "Rock_Slate"
    },
    {
      "x": -1,
      "y": 2,
      "z": -1,
      "name": "Rock_Slate"
    },
    {
      "x": -1,
      "y": -10,
      "z": 0,
      "name": "Rock_Slate_Stalactite_Large",
      "filler": 31744,
      "rotation": 8
    },
    {
      "x": -1,
      "y": -9,
      "z": 0,
      "name": "Rock_Slate_Stalactite_Large",
      "rotation": 8
    },
    {
      "x": -1,
      "y": -8,
      "z": 0,
      "name": "Rock_Slate_Cobble"
    },
    {
      "x": -1,
      "y": -7,
      "z": 0,
      "name": "Rock_Slate"
    },
    {
      "x": -1,
      "y": -6,
      "z": 0,
      "name": "Rock_Slate"
    },
    {
      "x": -1,
      "y": -5,
      "z": 0,
      "name": "Rock_Slate"
    },
    {
      "x": -1,
      "y": -4,
      "z": 0,
      "name": "Rock_Slate"
    },
    {
      "x": -1,
      "y": -3,
      "z": 0,
      "name": "Rock_Slate_Cobble"
    },
    {
      "x": -1,
      "y": -2,
      "z": 0,
      "name": "Rock_Slate"
    },
    {
      "x": -1,
      "y": -1,
      "z": 0,
      "name": "Rock_Slate"
    },
    {
      "x": -1,
      "y": 0,
      "z": 0,
      "name": "Rock_Slate_Cobble"
    },
    {
      "x": -1,
      "y": 1,
      "z": 0,
      "name": "Rock_Slate"
    },
    {
      "x": -1,
      "y": 2,
      "z": 0,
      "name": "Rock_Slate"
    },
    {
      "x": -1,
      "y": -6,
      "z": 1,
      "name": "Rock_Slate_Stalactite_Large",
      "filler": 31744,
      "rotation": 8
    },
    {
      "x": -1,
      "y": -5,
      "z": 1,
      "name": "Rock_Slate_Stalactite_Large",
      "rotation": 8
    },
    {
      "x": -1,
      "y": -4,
      "z": 1,
      "name": "Rock_Slate"
    },
    {
      "x": -1,
      "y": -3,
      "z": 1,
      "name": "Rock_Slate_Cobble"
    },
    {
      "x": -1,
      "y": -2,
      "z": 1,
      "name": "Rock_Slate"
    },
    {
      "x": -1,
      "y": -1,
      "z": 1,
      "name": "Rock_Slate"
    },
    {
      "x": -1,
      "y": 0,
      "z": 1,
      "name": "Rock_Slate_Cobble"
    },
    {
      "x": -1,
      "y": 1,
      "z": 1,
      "name": "Rock_Slate"
    },
    {
      "x": -1,
      "y": 2,
      "z": 1,
      "name": "Rock_Slate"
    },
    {
      "x": -1,
      "y": -3,
      "z": 2,
      "name": "Rock_Slate_Stalactite_Small",
      "rotation": 8
    },
    {
      "x": -1,
      "y": -2,
      "z": 2,
      "name": "Rock_Slate"
    },
    {
      "x": -1,
      "y": -1,
      "z": 2,
      "name": "Rock_Slate"
    },
    {
      "x": -1,
      "y": 0,
      "z": 2,
      "name": "Rock_Slate_Cobble"
    },
    {
      "x": -1,
      "y": 1,
      "z": 2,
      "name": "Rock_Slate"
    },
    {
      "x": -1,
      "y": 2,
      "z": 2,
      "name": "Rock_Slate"
    },
    {
      "x": 0,
      "y": -4,
      "z": -2,
      "name": "Rock_Slate_Stalactite_Large",
      "filler": 31744,
      "rotation": 8
    },
    {
      "x": 0,
      "y": -3,
      "z": -2,
      "name": "Rock_Slate_Stalactite_Large",
      "rotation": 8
    },
    {
      "x": 0,
      "y": -2,
      "z": -2,
      "name": "Rock_Slate"
    },
    {
      "x": 0,
      "y": -1,
      "z": -2,
      "name": "Rock_Slate"
    },
    {
      "x": 0,
      "y": 0,
      "z": -2,
      "name": "Rock_Slate_Cobble"
    },
    {
      "x": 0,
      "y": 1,
      "z": -2,
      "name": "Rock_Slate"
    },
    {
      "x": 0,
      "y": 2,
      "z": -2,
      "name": "Rock_Slate"
    },
    {
      "x": 0,
      "y": -10,
      "z": -1,
      "name": "Rock_Slate_Stalactite_Large",
      "filler": 31744,
      "rotation": 8
    },
    {
      "x": 0,
      "y": -9,
      "z": -1,
      "name": "Rock_Slate_Stalactite_Large",
      "rotation": 8
    },
    {
      "x": 0,
      "y": -8,
      "z": -1,
      "name": "Rock_Slate_Cobble"
    },
    {
      "x": 0,
      "y": -7,
      "z": -1,
      "name": "Rock_Slate"
    },
    {
      "x": 0,
      "y": -6,
      "z": -1,
      "name": "Rock_Slate"
    },
    {
      "x": 0,
      "y": -5,
      "z": -1,
      "name": "Rock_Slate"
    },
    {
      "x": 0,
      "y": -4,
      "z": -1,
      "name": "Rock_Slate"
    },
    {
      "x": 0,
      "y": -3,
      "z": -1,
      "name": "Rock_Slate_Cobble"
    },
    {
      "x": 0,
      "y": -2,
      "z": -1,
      "name": "Rock_Slate"
    },
    {
      "x": 0,
      "y": -1,
      "z": -1,
      "name": "Rock_Slate"
    },
    {
      "x": 0,
      "y": 0,
      "z": -1,
      "name": "Rock_Slate_Cobble"
    },
    {
      "x": 0,
      "y": 1,
      "z": -1,
      "name": "Rock_Slate"
    },
    {
      "x": 0,
      "y": 2,
      "z": -1,
      "name": "Rock_Slate"
    },
    {
      "x": 0,
      "y": -13,
      "z": 0,
      "name": "Rock_Slate_Stalactite_Large",
      "filler": 31744,
      "rotation": 8
    },
    {
      "x": 0,
      "y": -12,
      "z": 0,
      "name": "Rock_Slate_Stalactite_Large",
      "rotation": 8
    },
    {
      "x": 0,
      "y": -11,
      "z": 0,
      "name": "Rock_Slate"
    },
    {
      "x": 0,
      "y": -10,
      "z": 0,
      "name": "Rock_Slate"
    },
    {
      "x": 0,
      "y": -9,
      "z": 0,
      "name": "Rock_Slate_Cobble"
    },
    {
      "x": 0,
      "y": -8,
      "z": 0,
      "name": "Rock_Slate_Cobble"
    },
    {
      "x": 0,
      "y": -7,
      "z": 0,
      "name": "Rock_Slate"
    },
    {
      "x": 0,
      "y": -6,
      "z": 0,
      "name": "Rock_Slate"
    },
    {
      "x": 0,
      "y": -5,
      "z": 0,
      "name": "Rock_Slate"
    },
    {
      "x": 0,
      "y": -4,
      "z": 0,
      "name": "Rock_Slate"
    },
    {
      "x": 0,
      "y": -3,
      "z": 0,
      "name": "Rock_Slate_Cobble"
    },
    {
      "x": 0,
      "y": -2,
      "z": 0,
      "name": "Rock_Slate"
    },
    {
      "x": 0,
      "y": -1,
      "z": 0,
      "name": "Rock_Slate"
    },
    {
      "x": 0,
      "y": 0,
      "z": 0,
      "name": "Rock_Slate_Cobble"
    },
    {
      "x": 0,
      "y": 1,
      "z": 0,
      "name": "Rock_Slate"
    },
    {
      "x": 0,
      "y": 2,
      "z": 0,
      "name": "Rock_Slate"
    },
    {
      "x": 0,
      "y": -8,
      "z": 1,
      "name": "Rock_Slate_Stalactite_Large",
      "filler": 31744,
      "rotation": 8
    },
    {
      "x": 0,
      "y": -7,
      "z": 1,
      "name": "Rock_Slate_Stalactite_Large",
      "rotation": 8
    },
    {
      "x": 0,
      "y": -6,
      "z": 1,
      "name": "Rock_Slate"
    },
    {
      "x": 0,
      "y": -5,
      "z": 1,
      "name": "Rock_Slate"
    },
    {
      "x": 0,
      "y": -4,
      "z": 1,
      "name": "Rock_Slate"
    },
    {
      "x": 0,
      "y": -3,
      "z": 1,
      "name": "Rock_Slate_Cobble"
    },
    {
      "x": 0,
      "y": -2,
      "z": 1,
      "name": "Rock_Slate"
    },
    {
      "x": 0,
      "y": -1,
      "z": 1,
      "name": "Rock_Slate"
    },
    {
      "x": 0,
      "y": 0,
      "z": 1,
      "name": "Rock_Slate_Cobble"
    },
    {
      "x": 0,
      "y": 1,
      "z": 1,
      "name": "Rock_Slate"
    },
    {
      "x": 0,
      "y": 2,
      "z": 1,
      "name": "Rock_Slate"
    },
    {
      "x": 0,
      "y": -5,
      "z": 2,
      "name": "Rock_Slate_Stalactite_Large",
      "filler": 31744,
      "rotation": 8
    },
    {
      "x": 0,
      "y": -4,
      "z": 2,
      "name": "Rock_Slate_Stalactite_Large",
      "rotation": 8
    },
    {
      "x": 0,
      "y": -3,
      "z": 2,
      "name": "Rock_Slate_Cobble"
    },
    {
      "x": 0,
      "y": -2,
      "z": 2,
      "name": "Rock_Slate"
    },
    {
      "x": 0,
      "y": -1,
      "z": 2,
      "name": "Rock_Slate"
    },
    {
      "x": 0,
      "y": 0,
      "z": 2,
      "name": "Rock_Slate_Cobble"
    },
    {
      "x": 0,
      "y": 1,
      "z": 2,
      "name": "Rock_Slate"
    },
    {
      "x": 0,
      "y": 2,
      "z": 2,
      "name": "Rock_Slate"
    },
    {
      "x": 1,
      "y": -2,
      "z": -2,
      "name": "Rock_Slate_Stalactite_Large",
      "filler": 31744,
      "rotation": 8
    },
    {
      "x": 1,
      "y": -1,
      "z": -2,
      "name": "Rock_Slate_Stalactite_Large",
      "rotation": 8
    },
    {
      "x": 1,
      "y": 0,
      "z": -2,
      "name": "Rock_Slate_Cobble"
    },
    {
      "x": 1,
      "y": 1,
      "z": -2,
      "name": "Rock_Slate"
    },
    {
      "x": 1,
      "y": 2,
      "z": -2,
      "name": "Rock_Slate"
    },
    {
      "x": 1,
      "y": -6,
      "z": -1,
      "name": "Rock_Slate_Stalactite_Large",
      "filler": 31744,
      "rotation": 8
    },
    {
      "x": 1,
      "y": -5,
      "z": -1,
      "name": "Rock_Slate_Stalactite_Large",
      "rotation": 8
    },
    {
      "x": 1,
      "y": -4,
      "z": -1,
      "name": "Rock_Slate"
    },
    {
      "x": 1,
      "y": -3,
      "z": -1,
      "name": "Rock_Slate_Cobble"
    },
    {
      "x": 1,
      "y": -2,
      "z": -1,
      "name": "Rock_Slate"
    },
    {
      "x": 1,
      "y": -1,
      "z": -1,
      "name": "Rock_Slate"
    },
    {
      "x": 1,
      "y": 0,
      "z": -1,
      "name": "Rock_Slate_Cobble"
    },
    {
      "x": 1,
      "y": 1,
      "z": -1,
      "name": "Rock_Slate"
    },
    {
      "x": 1,
      "y": 2,
      "z": -1,
      "name": "Rock_Slate"
    },
    {
      "x": 1,
      "y": -9,
      "z": 0,
      "name": "Rock_Slate_Stalactite_Large",
      "filler": 31744,
      "rotation": 8
    },
    {
      "x": 1,
      "y": -8,
      "z": 0,
      "name": "Rock_Slate_Stalactite_Large",
      "rotation": 8
    },
    {
      "x": 1,
      "y": -7,
      "z": 0,
      "name": "Rock_Slate"
    },
    {
      "x": 1,
      "y": -6,
      "z": 0,
      "name": "Rock_Slate"
    },
    {
      "x": 1,
      "y": -5,
      "z": 0,
      "name": "Rock_Slate"
    },
    {
      "x": 1,
      "y": -4,
      "z": 0,
      "name": "Rock_Slate"
    },
    {
      "x": 1,
      "y": -3,
      "z": 0,
      "name": "Rock_Slate_Cobble"
    },
    {
      "x": 1,
      "y": -2,
      "z": 0,
      "name": "Rock_Slate"
    },
    {
      "x": 1,
      "y": -1,
      "z": 0,
      "name": "Rock_Slate"
    },
    {
      "x": 1,
      "y": 0,
      "z": 0,
      "name": "Rock_Slate_Cobble"
    },
    {
      "x": 1,
      "y": 1,
      "z": 0,
      "name": "Rock_Slate"
    },
    {
      "x": 1,
      "y": 2,
      "z": 0,
      "name": "Rock_Slate"
    },
    {
      "x": 1,
      "y": -6,
      "z": 1,
      "name": "Rock_Slate_Stalactite_Large",
      "filler": 31744,
      "rotation": 8
    },
    {
      "x": 1,
      "y": -5,
      "z": 1,
      "name": "Rock_Slate_Stalactite_Large",
      "rotation": 8
    },
    {
      "x": 1,
      "y": -4,
      "z": 1,
      "name": "Rock_Slate"
    },
    {
      "x": 1,
      "y": -3,
      "z": 1,
      "name": "Rock_Slate_Cobble"
    },
    {
      "x": 1,
      "y": -2,
      "z": 1,
      "name": "Rock_Slate"
    },
    {
      "x": 1,
      "y": -1,
      "z": 1,
      "name": "Rock_Slate"
    },
    {
      "x": 1,
      "y": 0,
      "z": 1,
      "name": "Rock_Slate_Cobble"
    },
    {
      "x": 1,
      "y": 1,
      "z": 1,
      "name": "Rock_Slate"
    },
    {
      "x": 1,
      "y": 2,
      "z": 1,
      "name": "Rock_Slate"
    },
    {
      "x": 1,
      "y": -4,
      "z": 2,
      "name": "Rock_Slate_Stalactite_Small",
      "rotation": 8
    },
    {
      "x": 1,
      "y": -3,
      "z": 2,
      "name": "Rock_Slate_Cobble"
    },
    {
      "x": 1,
      "y": -2,
      "z": 2,
      "name": "Rock_Slate"
    },
    {
      "x": 1,
      "y": -1,
      "z": 2,
      "name": "Rock_Slate"
    },
    {
      "x": 1,
      "y": 0,
      "z": 2,
      "name": "Rock_Slate_Cobble"
    },
    {
      "x": 1,
      "y": 1,
      "z": 2,
      "name": "Rock_Slate"
    },
    {
      "x": 1,
      "y": 2,
      "z": 2,
      "name": "Rock_Slate"
    },
    {
      "x": 2,
      "y": -3,
      "z": -1,
      "name": "Rock_Slate_Stalactite_Large",
      "filler": 31744,
      "rotation": 8
    },
    {
      "x": 2,
      "y": -2,
      "z": -1,
      "name": "Rock_Slate_Stalactite_Large",
      "rotation": 8
    },
    {
      "x": 2,
      "y": -1,
      "z": -1,
      "name": "Rock_Slate"
    },
    {
      "x": 2,
      "y": 0,
      "z": -1,
      "name": "Rock_Slate_Cobble"
    },
    {
      "x": 2,
      "y": 1,
      "z": -1,
      "name": "Rock_Slate"
    },
    {
      "x": 2,
      "y": 2,
      "z": -1,
      "name": "Rock_Slate"
    },
    {
      "x": 2,
      "y": -5,
      "z": 0,
      "name": "Rock_Slate_Stalactite_Large",
      "filler": 31744,
      "rotation": 8
    },
    {
      "x": 2,
      "y": -4,
      "z": 0,
      "name": "Rock_Slate_Stalactite_Large",
      "rotation": 8
    },
    {
      "x": 2,
      "y": -3,
      "z": 0,
      "name": "Rock_Slate_Cobble"
    },
    {
      "x": 2,
      "y": -2,
      "z": 0,
      "name": "Rock_Slate"
    },
    {
      "x": 2,
      "y": -1,
      "z": 0,
      "name": "Rock_Slate"
    },
    {
      "x": 2,
      "y": 0,
      "z": 0,
      "name": "Rock_Slate_Cobble"
    },
    {
      "x": 2,
      "y": 1,
      "z": 0,
      "name": "Rock_Slate"
    },
    {
      "x": 2,
      "y": 2,
      "z": 0,
      "name": "Rock_Slate"
    },
    {
      "x": 2,
      "y": -4,
      "z": 1,
      "name": "Rock_Slate_Stalactite_Large",
      "filler": 31744,
      "rotation": 8
    },
    {
      "x": 2,
      "y": -3,
      "z": 1,
      "name": "Rock_Slate_Stalactite_Large",
      "rotation": 8
    },
    {
      "x": 2,
      "y": -2,
      "z": 1,
      "name": "Rock_Slate"
    },
    {
      "x": 2,
      "y": -1,
      "z": 1,
      "name": "Rock_Slate"
    },
    {
      "x": 2,
      "y": 0,
      "z": 1,
      "name": "Rock_Slate_Cobble"
    },
    {
      "x": 2,
      "y": 1,
      "z": 1,
      "name": "Rock_Slate"
    },
    {
      "x": 2,
      "y": 2,
      "z": 1,
      "name": "Rock_Slate"
    }
  ],
  "fluids": [
    {
      "x": -2,
      "y": -3,
      "z": -1,
      "name": "Water_Source",
      "level": 1
    },
    {
      "x": -2,
      "y": -2,
      "z": -1,
      "name": "Water_Source",
      "level": 1
    },
    {
      "x": -2,
      "y": -6,
      "z": 0,
      "name": "Water_Source",
      "level": 1
    },
    {
      "x": -2,
      "y": -5,
      "z": 0,
      "name": "Water_Source",
      "level": 1
    },
    {
      "x": -2,
      "y": -4,
      "z": 1,
      "name": "Water_Source",
      "level": 1
    },
    {
      "x": -2,
      "y": -3,
      "z": 1,
      "name": "Water_Source",
      "level": 1
    },
    {
      "x": -1,
      "y": -2,
      "z": -2,
      "name": "Water_Source",
      "level": 1
    },
    {
      "x": -1,
      "y": -7,
      "z": -1,
      "name": "Water_Source",
      "level": 1
    },
    {
      "x": -1,
      "y": -6,
      "z": -1,
      "name": "Water_Source",
      "level": 1
    },
    {
      "x": -1,
      "y": -10,
      "z": 0,
      "name": "Water_Source",
      "level": 1
    },
    {
      "x": -1,
      "y": -9,
      "z": 0,
      "name": "Water_Source",
      "level": 1
    },
    {
      "x": -1,
      "y": -6,
      "z": 1,
      "name": "Water_Source",
      "level": 1
    },
    {
      "x": -1,
      "y": -5,
      "z": 1,
      "name": "Water_Source",
      "level": 1
    },
    {
      "x": -1,
      "y": -3,
      "z": 2,
      "name": "Water_Source",
      "level": 1
    },
    {
      "x": 0,
      "y": -4,
      "z": -2,
      "name": "Water_Source",
      "level": 1
    },
    {
      "x": 0,
      "y": -3,
      "z": -2,
      "name": "Water_Source",
      "level": 1
    },
    {
      "x": 0,
      "y": -10,
      "z": -1,
      "name": "Water_Source",
      "level": 1
    },
    {
      "x": 0,
      "y": -9,
      "z": -1,
      "name": "Water_Source",
      "level": 1
    },
    {
      "x": 0,
      "y": -13,
      "z": 0,
      "name": "Water_Source",
      "level": 1
    },
    {
      "x": 0,
      "y": -12,
      "z": 0,
      "name": "Water_Source",
      "level": 1
    },
    {
      "x": 0,
      "y": -8,
      "z": 1,
      "name": "Water_Source",
      "level": 1
    },
    {
      "x": 0,
      "y": -7,
      "z": 1,
      "name": "Water_Source",
      "level": 1
    },
    {
      "x": 0,
      "y": -5,
      "z": 2,
      "name": "Water_Source",
      "level": 1
    },
    {
      "x": 0,
      "y": -4,
      "z": 2,
      "name": "Water_Source",
      "level": 1
    },
    {
      "x": 1,
      "y": -2,
      "z": -2,
      "name": "Water_Source",
      "level": 1
    },
    {
      "x": 1,
      "y": -1,
      "z": -2,
      "name": "Water_Source",
      "level": 1
    },
    {
      "x": 1,
      "y": -6,
      "z": -1,
      "name": "Water_Source",
      "level": 1
    },
    {
      "x": 1,
      "y": -5,
      "z": -1,
      "name": "Water_Source",
      "level": 1
    },
    {
      "x": 1,
      "y": -9,
      "z": 0,
      "name": "Water_Source",
      "level": 1
    },
    {
      "x": 1,
      "y": -8,
      "z": 0,
      "name": "Water_Source",
      "level": 1
    },
    {
      "x": 1,
      "y": -6,
      "z": 1,
      "name": "Water_Source",
      "level": 1
    },
    {
      "x": 1,
      "y": -5,
      "z": 1,
      "name": "Water_Source",
      "level": 1
    },
    {
      "x": 1,
      "y": -4,
      "z": 2,
      "name": "Water_Source",
      "level": 1
    },
    {
      "x": 2,
      "y": -3,
      "z": -1,
      "name": "Water_Source",
      "level": 1
    },
    {
      "x": 2,
      "y": -2,
      "z": -1,
      "name": "Water_Source",
      "level": 1
    },
    {
      "x": 2,
      "y": -5,
      "z": 0,
      "name": "Water_Source",
      "level": 1
    },
    {
      "x": 2,
      "y": -4,
      "z": 0,
      "name": "Water_Source",
      "level": 1
    },
    {
      "x": 2,
      "y": -4,
      "z": 1,
      "name": "Water_Source",
      "level": 1
    },
    {
      "x": 2,
      "y": -3,
      "z": 1,
      "name": "Water_Source",
      "level": 1
    }
  ]
}