{
  "version": 8,
  "blockIdVersion": 11,
  "anchorX": 0,
  "anchorY": 8,
  "anchorZ": 0,
  "blocks": [
    {
      "x": -9,
      "y": 8,
      "z": -9,
      "name": "Soil_Gravel_Sand"
    },
    {
      "x": -9,
      "y": 8,
      "z": -8,
      "name": "Soil_Gravel_Sand"
    },
    {
      "x": -9,
      "y": 8,
      "z": -7,
      "name": "Soil_Gravel_Sand"
    },
    {
      "x": -9,
      "y": 8,
      "z": -6,
      "name": "Soil_Gravel_Sand"
    },
    {
      "x": -9,
      "y": 8,
      "z": -5,
      "name": "Soil_Gravel_Sand"
    },
    {
      "x": -9,
      "y": 8,
      "z": -4,
      "name": "Soil_Gravel_Sand"
    },
    {
      "x": -9,
      "y": 8,
      "z": -3,
      "name": "Soil_Gravel_Sand"
    },
    {
      "x": -9,
      "y": 8,
      "z": -2,
      "name": "Soil_Gravel_Sand"
    },
    {
      "x": -9,
      "y": 8,
      "z": -1,
      "name": "Soil_Gravel_Sand"
    },
    {
      "x": -9,
      "y": 8,
      "z": 0,
      "name": "Soil_Gravel_Sand"
    },
    {
      "x": -9,
      "y": 8,
      "z": 1,
      "name": "Soil_Gravel_Sand"
    },
    {
      "x": -9,
      "y": 8,
      "z": 2,
      "name": "Soil_Gravel_Sand"
    },
    {
      "x": -9,
      "y": 8,
      "z": 3,
      "name": "Soil_Gravel_Sand"
    },
    {
      "x": -9,
      "y": 8,
      "z": 4,
      "name": "Soil_Gravel_Sand"
    },
    {
      "x": -9,
      "y": 8,
      "z": 5,
      "name": "Soil_Gravel_Sand"
    },
    {
      "x": -9,
      "y": 8,
      "z": 6,
      "name": "Soil_Gravel_Sand"
    },
    {
      "x": -9,
      "y": 8,
      "z": 7,
      "name": "Soil_Gravel_Sand"
    },
    {
      "x": -9,
      "y": 8,
      "z": 8,
      "name": "Soil_Gravel_Sand"
    },
    {
      "x": -9,
      "y": 8,
      "z": 9,
      "name": "Soil_Gravel_Sand"
    },
    {
      "x": -9,
      "y": 8,
      "z": 10,
      "name": "Soil_Gravel_Sand"
    },
    {
      "x": -8,
      "y": 8,
      "z": -9,
      "name": "Soil_Gravel_Sand"
    },
    {
      "x": -8,
      "y": 8,
      "z": -8,
      "name": "Soil_Gravel_Sand"
    },
    {
      "x": -8,
      "y": 8,
      "z": -7,
      "name": "Soil_Gravel_Sand"
    },
    {
      "x": -8,
      "y": 8,
      "z": -6,
      "name": "Soil_Gravel_Sand"
    },
    {
      "x": -8,
      "y": 8,
      "z": -5,
      "name": "Soil_Gravel_Sand"
    },
    {
      "x": -8,
      "y": 8,
      "z": -4,
      "name": "Soil_Gravel_Sand"
    },
    {
      "x": -8,
      "y": 8,
      "z": -3,
      "name": "Soil_Gravel_Sand"
    },
    {
      "x": -8,
      "y": 8,
      "z": -2,
      "name": "Soil_Gravel_Sand"
    },
    {
      "x": -8,
      "y": 9,
      "z": -2,
      "name": "*Rock_Sandstone_Brick_Stairs_State_Definitions_Corner_Right",
      "rotation": 3
    },
    {
      "x": -8,
      "y": 8,
      "z": -1,
      "name": "Soil_Gravel_Sand"
    },
    {
      "x": -8,
      "y": 9,
      "z": -1,
      "name": "Rock_Sandstone_Brick_Stairs",
      "rotation": 3
    },
    {
      "x": -8,
      "y": 14,
      "z": -1,
      "name": "Rock_Sandstone_Brick_Stairs",
      "rotation": 9
    },
    {
      "x": -8,
      "y": 15,
      "z": -1,
      "name": "Soil_Clay_Ocean_Brick_Smooth",
      "rotation": 3
    },
    {
      "x": -8,
      "y": 8,
      "z": 0,
      "name": "Soil_Gravel_Sand"
    },
    {
      "x": -8,
      "y": 9,
      "z": 0,
      "name": "Rock_Sandstone_Brick_Stairs",
      "rotation": 3
    },
    {
      "x": -8,
      "y": 14,
      "z": 0,
      "name": "Rock_Sandstone_Brick_Stairs",
      "rotation": 9
    },
    {
      "x": -8,
      "y": 15,
      "z": 0,
      "name": "Soil_Clay_Ocean_Brick_Smooth",
      "rotation": 3
    },
    {
      "x": -8,
      "y": 8,
      "z": 1,
      "name": "Soil_Gravel_Sand"
    },
    {
      "x": -8,
      "y": 9,
      "z": 1,
      "name": "Rock_Sandstone_Brick_Stairs",
      "rotation": 3
    },
    {
      "x": -8,
      "y": 14,
      "z": 1,
      "name": "Rock_Sandstone_Brick_Stairs",
      "rotation": 9
    },
    {
      "x": -8,
      "y": 15,
      "z": 1,
      "name": "Soil_Clay_Ocean_Brick_Smooth",
      "rotation": 3
    },
    {
      "x": -8,
      "y": 8,
      "z": 2,
      "name": "Soil_Gravel_Sand"
    },
    {
      "x": -8,
      "y": 9,
      "z": 2,
      "name": "Rock_Sandstone_Brick_Stairs",
      "rotation": 3
    },
    {
      "x": -8,
      "y": 14,
      "z": 2,
      "name": "Rock_Sandstone_Brick_Stairs",
      "rotation": 9
    },
    {
      "x": -8,
      "y": 15,
      "z": 2,
      "name": "Soil_Clay_Ocean_Brick_Smooth",
      "rotation": 3
    },
    {
      "x": -8,
      "y": 8,
      "z": 3,
      "name": "Soil_Gravel_Sand"
    },
    {
      "x": -8,
      "y": 9,
      "z": 3,
      "name": "Rock_Sandstone_Brick_Stairs",
      "rotation": 3
    },
    {
      "x": -8,
      "y": 14,
      "z": 3,
      "name": "Rock_Sandstone_Brick_Stairs",
      "rotation": 9
    },
    {
      "x": -8,
      "y": 15,
      "z": 3,
      "name": "Soil_Clay_Ocean_Brick_Smooth",
      "rotation": 3
    },
    {
      "x": -8,
      "y": 8,
      "z": 4,
      "name": "Soil_Gravel_Sand"
    },
    {
      "x": -8,
      "y": 9,
      "z": 4,
      "name": "Rock_Sandstone_Brick_Stairs",
      "rotation": 3
    },
    {
      "x": -8,
      "y": 14,
      "z": 4,
      "name": "Rock_Sandstone_Brick_Stairs",
      "rotation": 9
    },
    {
      "x": -8,
      "y": 15,
      "z": 4,
      "name": "Soil_Clay_Ocean_Brick_Smooth",
      "rotation": 3
    },
    {
      "x": -8,
      "y": 8,
      "z": 5,
      "name": "Soil_Gravel_Sand"
    },
    {
      "x": -8,
      "y": 9,
      "z": 5,
      "name": "Rock_Sandstone_Brick_Stairs",
      "rotation": 3
    },
    {
      "x": -8,
      "y": 8,
      "z": 6,
      "name": "Soil_Gravel_Sand"
    },
    {
      "x": -8,
      "y": 9,
      "z": 6,
      "name": "*Rock_Sandstone_Brick_Stairs_State_Definitions_Corner_Right"
    },
    {
      "x": -8,
      "y": 8,
      "z": 7,
      "name": "Soil_Gravel_Sand"
    },
    {
      "x": -8,
      "y": 9,
      "z": 7,
      "name": "Rock_Sandstone_Brick_Half"
    },
    {
      "x": -8,
      "y": 8,
      "z": 8,
      "name": "Soil_Gravel_Sand"
    },
    {
      "x": -8,
      "y": 8,
      "z": 9,
      "name": "Soil_Gravel_Sand"
    },
    {
      "x": -8,
      "y": 8,
      "z": 10,
      "name": "Soil_Gravel_Sand"
    },
    {
      "x": -7,
      "y": 8,
      "z": -9,
      "name": "Soil_Gravel_Sand"
    },
    {
      "x": -7,
      "y": 8,
      "z": -8,
      "name": "Soil_Gravel_Sand"
    },
    {
      "x": -7,
      "y": 8,
      "z": -7,
      "name": "Soil_Gravel_Sand"
    },
    {
      "x": -7,
      "y": 8,
      "z": -6,
      "name": "Soil_Gravel_Sand"
    },
    {
      "x": -7,
      "y": 8,
      "z": -5,
      "name": "Soil_Gravel_Sand"
    },
    {
      "x": -7,
      "y": 8,
      "z": -4,
      "name": "Soil_Gravel_Sand"
    },
    {
      "x": -7,
      "y": 9,
      "z": -4,
      "name": "*Rock_Sandstone_Brick_Stairs_State_Definitions_Corner_Left",
      "rotation": 2
    },
    {
      "x": -7,
      "y": 8,
      "z": -3,
      "name": "Soil_Gravel_Sand"
    },
    {
      "x": -7,
      "y": 9,
      "z": -3,
      "name": "Rock_Sandstone_Brick_Stairs",
      "rotation": 3
    },
    {
      "x": -7,
      "y": 14,
      "z": -3,
      "name": "Rock_Sandstone_Brick_Stairs",
      "rotation": 9
    },
    {
      "x": -7,
      "y": 15,
      "z": -3,
      "name": "Soil_Clay_Ocean_Brick_Smooth",
      "rotation": 3
    },
    {
      "x": -7,
      "y": 8,
      "z": -2,
      "name": "Soil_Gravel_Sand"
    },
    {
      "x": -7,
      "y": 9,
      "z": -2,
      "name": "*Rock_Sandstone_Brick_Stairs_State_Definitions_Inverted_Corner_Left",
      "rotation": 2
    },
    {
      "x": -7,
      "y": 14,
      "z": -2,
      "name": "Rock_Sandstone_Brick_Stairs",
      "rotation": 9
    },
    {
      "x": -7,
      "y": 15,
      "z": -2,
      "name": "Soil_Clay_Ocean_Brick_Smooth",
      "rotation": 3
    },
    {
      "x": -7,
      "y": 8,
      "z": -1,
      "name": "Soil_Gravel_Sand"
    },
    {
      "x": -7,
      "y": 9,
      "z": -1,
      "name": "Rock_Sandstone_Brick"
    },
    {
      "x": -7,
      "y": 10,
      "z": -1,
      "name": "Rock_Sandstone_Brick",
      "rotation": 3
    },
    {
      "x": -7,
      "y": 11,
      "z": -1,
      "name": "Rock_Sandstone_Brick",
      "rotation": 3
    },
    {
      "x": -7,
      "y": 12,
      "z": -1,
      "name": "Rock_Sandstone_Brick",
      "rotation": 3
    },
    {
      "x": -7,
      "y": 13,
      "z": -1,
      "name": "Rock_Sandstone_Brick",
      "rotation": 3
    },
    {
      "x": -7,
      "y": 14,
      "z": -1,
      "name": "Rock_Sandstone_Brick",
      "rotation": 3
    },
    {
      "x": -7,
      "y": 15,
      "z": -1,
      "name": "Soil_Clay_Ocean_Brick_Smooth",
      "rotation": 3
    },
    {
      "x": -7,
      "y": 8,
      "z": 0,
      "name": "Soil_Gravel_Sand"
    },
    {
      "x": -7,
      "y": 9,
      "z": 0,
      "name": "Rock_Sandstone_Brick"
    },
    {
      "x": -7,
      "y": 10,
      "z": 0,
      "name": "Rock_Sandstone_Brick",
      "rotation": 3
    },
    {
      "x": -7,
      "y": 11,
      "z": 0,
      "name": "Rock_Sandstone_Brick",
      "rotation": 3
    },
    {
      "x": -7,
      "y": 12,
      "z": 0,
      "name": "Furniture_Desert_Window",
      "rotation": 3
    },
    {
      "x": -7,
      "y": 13,
      "z": 0,
      "name": "Furniture_Desert_Window",
      "rotation": 3
    },
    {
      "x": -7,
      "y": 14,
      "z": 0,
      "name": "Rock_Sandstone_Brick",
      "rotation": 3
    },
    {
      "x": -7,
      "y": 15,
      "z": 0,
      "name": "Soil_Clay_Ocean_Brick_Smooth",
      "rotation": 3
    },
    {
      "x": -7,
      "y": 16,
      "z": 0,
      "name": "Soil_Clay_Ocean_Brick_Half",
      "rotation": 3
    },
    {
      "x": -7,
      "y": 8,
      "z": 1,
      "name": "Soil_Gravel_Sand"
    },
    {
      "x": -7,
      "y": 9,
      "z": 1,
      "name": "Rock_Sandstone_Brick"
    },
    {
      "x": -7,
      "y": 10,
      "z": 1,
      "name": "Rock_Sandstone_Brick",
      "rotation": 3
    },
    {
      "x": -7,
      "y": 11,
      "z": 1,
      "name": "Rock_Sandstone_Brick",
      "rotation": 3
    },
    {
      "x": -7,
      "y": 12,
      "z": 1,
      "name": "Rock_Sandstone_Brick",
      "rotation": 3
    },
    {
      "x": -7,
      "y": 13,
      "z": 1,
      "name": "Rock_Sandstone_Brick",
      "rotation": 3
    },
    {
      "x": -7,
      "y": 14,
      "z": 1,
      "name": "Rock_Sandstone_Brick",
      "rotation": 3
    },
    {
      "x": -7,
      "y": 15,
      "z": 1,
      "name": "Soil_Clay_Ocean_Brick_Smooth",
      "rotation": 3
    },
    {
      "x": -7,
      "y": 16,
      "z": 1,
      "name": "Soil_Clay_Ocean_Brick_Half",
      "rotation": 3
    },
    {
      "x": -7,
      "y": 8,
      "z": 2,
      "name": "Soil_Gravel_Sand"
    },
    {
      "x": -7,
      "y": 9,
      "z": 2,
      "name": "Rock_Sandstone_Brick"
    },
    {
      "x": -7,
      "y": 10,
      "z": 2,
      "name": "Rock_Sandstone_Brick",
      "rotation": 3
    },
    {
      "x": -7,
      "y": 11,
      "z": 2,
      "name": "Rock_Sandstone_Brick",
      "rotation": 3
    },
    {
      "x": -7,
      "y": 12,
      "z": 2,
      "name": "Rock_Sandstone_Brick",
      "rotation": 3
    },
    {
      "x": -7,
      "y": 13,
      "z": 2,
      "name": "Rock_Sandstone_Brick",
      "rotation": 3
    },
    {
      "x": -7,
      "y": 14,
      "z": 2,
      "name": "Rock_Sandstone_Brick",
      "rotation": 3
    },
    {
      "x": -7,
      "y": 15,
      "z": 2,
      "name": "Soil_Clay_Ocean_Brick_Smooth",
      "rotation": 3
    },
    {
      "x": -7,
      "y": 16,
      "z": 2,
      "name": "Soil_Clay_Ocean_Brick_Half",
      "rotation": 3
    },
    {
      "x": -7,
      "y": 8,
      "z": 3,
      "name": "Soil_Gravel_Sand"
    },
    {
      "x": -7,
      "y": 9,
      "z": 3,
      "name": "Rock_Sandstone_Brick"
    },
    {
      "x": -7,
      "y": 10,
      "z": 3,
      "name": "Rock_Sandstone_Brick",
      "rotation": 3
    },
    {
      "x": -7,
      "y": 11,
      "z": 3,
      "name": "Rock_Sandstone_Brick",
      "rotation": 3
    },
    {
      "x": -7,
      "y": 12,
      "z": 3,
      "name": "Furniture_Desert_Window",
      "rotation": 3
    },
    {
      "x": -7,
      "y": 13,
      "z": 3,
      "name": "Furniture_Desert_Window",
      "rotation": 3
    },
    {
      "x": -7,
      "y": 14,
      "z": 3,
      "name": "Rock_Sandstone_Brick",
      "rotation": 3
    },
    {
      "x": -7,
      "y": 15,
      "z": 3,
      "name": "Soil_Clay_Ocean_Brick_Smooth",
      "rotation": 3
    },
    {
      "x": -7,
      "y": 16,
      "z": 3,
      "name": "Soil_Clay_Ocean_Brick_Half",
      "rotation": 3
    },
    {
      "x": -7,
      "y": 8,
      "z": 4,
      "name": "Soil_Gravel_Sand"
    },
    {
      "x": -7,
      "y": 9,
      "z": 4,
      "name": "Rock_Sandstone_Brick"
    },
    {
      "x": -7,
      "y": 10,
      "z": 4,
      "name": "Rock_Sandstone_Brick",
      "rotation": 3
    },
    {
      "x": -7,
      "y": 11,
      "z": 4,
      "name": "Rock_Sandstone_Brick",
      "rotation": 3
    },
    {
      "x": -7,
      "y": 12,
      "z": 4,
      "name": "Rock_Sandstone_Brick",
      "rotation": 3
    },
    {
      "x": -7,
      "y": 13,
      "z": 4,
      "name": "Rock_Sandstone_Brick",
      "rotation": 3
    },
    {
      "x": -7,
      "y": 14,
      "z": 4,
      "name": "Rock_Sandstone_Brick",
      "rotation": 3
    },
    {
      "x": -7,
      "y": 15,
      "z": 4,
      "name": "Soil_Clay_Ocean_Brick_Smooth",
      "rotation": 3
    },
    {
      "x": -7,
      "y": 8,
      "z": 5,
      "name": "Soil_Gravel_Sand"
    },
    {
      "x": -7,
      "y": 9,
      "z": 5,
      "name": "Rock_Sandstone_Brick"
    },
    {
      "x": -7,
      "y": 14,
      "z": 5,
      "name": "Rock_Sandstone_Brick_Stairs",
      "rotation": 9
    },
    {
      "x": -7,
      "y": 15,
      "z": 5,
      "name": "Soil_Clay_Ocean_Brick_Smooth",
      "rotation": 3
    },
    {
      "x": -7,
      "y": 8,
      "z": 6,
      "name": "Soil_Gravel_Sand"
    },
    {
      "x": -7,
      "y": 9,
      "z": 6,
      "name": "*Rock_Sandstone_Brick_Stairs_State_Definitions_Inverted_Corner_Right"
    },
    {
      "x": -7,
      "y": 14,
      "z": 6,
      "name": "Rock_Sandstone_Brick_Stairs",
      "rotation": 9
    },
    {
      "x": -7,
      "y": 15,
      "z": 6,
      "name": "Soil_Clay_Ocean_Brick_Smooth",
      "rotation": 3
    },
    {
      "x": -7,
      "y": 8,
      "z": 7,
      "name": "Soil_Gravel_Sand"
    },
    {
      "x": -7,
      "y": 9,
      "z": 7,
      "name": "*Rock_Sandstone_Brick_Stairs_State_Definitions_Corner_Left",
      "rotation": 3
    },
    {
      "x": -7,
      "y": 8,
      "z": 8,
      "name": "Soil_Gravel_Sand"
    },
    {
      "x": -7,
      "y": 8,
      "z": 9,
      "name": "Soil_Gravel_Sand"
    },
    {
      "x": -7,
      "y": 8,
      "z": 10,
      "name": "Soil_Gravel_Sand"
    },
    {
      "x": -6,
      "y": 8,
      "z": -9,
      "name": "Soil_Gravel_Sand"
    },
    {
      "x": -6,
      "y": 8,
      "z": -8,
      "name": "Soil_Gravel_Sand"
    },
    {
      "x": -6,
      "y": 8,
      "z": -7,
      "name": "Soil_Gravel_Sand"
    },
    {
      "x": -6,
      "y": 8,
      "z": -6,
      "name": "Soil_Gravel_Sand"
    },
    {
      "x": -6,
      "y": 8,
      "z": -5,
      "name": "Soil_Gravel_Sand"
    },
    {
      "x": -6,
      "y": 8,
      "z": -4,
      "name": "Soil_Gravel_Sand"
    },
    {
      "x": -6,
      "y": 9,
      "z": -4,
      "name": "Rock_Sandstone_Brick_Stairs",
      "rotation": 2
    },
    {
      "x": -6,
      "y": 14,
      "z": -4,
      "name": "Rock_Sandstone_Brick_Stairs",
      "rotation": 9
    },
    {
      "x": -6,
      "y": 15,
      "z": -4,
      "name": "Soil_Clay_Ocean_Brick_Smooth",
      "rotation": 3
    },
    {
      "x": -6,
      "y": 8,
      "z": -3,
      "name": "Soil_Gravel_Sand"
    },
    {
      "x": -6,
      "y": 9,
      "z": -3,
      "name": "Rock_Sandstone_Brick"
    },
    {
      "x": -6,
      "y": 10,
      "z": -3,
      "name": "Rock_Sandstone_Brick",
      "rotation": 3
    },
    {
      "x": -6,
      "y": 11,
      "z": -3,
      "name": "Rock_Sandstone_Brick",
      "rotation": 3
    },
    {
      "x": -6,
      "y": 12,
      "z": -3,
      "name": "Rock_Sandstone_Brick",
      "rotation": 3
    },
    {
      "x": -6,
      "y": 13,
      "z": -3,
      "name": "Rock_Sandstone_Brick",
      "rotation": 3
    },
    {
      "x": -6,
      "y": 14,
      "z": -3,
      "name": "Rock_Sandstone_Brick",
      "rotation": 3
    },
    {
      "x": -6,
      "y": 15,
      "z": -3,
      "name": "Soil_Clay_Ocean_Brick_Smooth",
      "rotation": 3
    },
    {
      "x": -6,
      "y": 8,
      "z": -2,
      "name": "Soil_Gravel_Sand"
    },
    {
      "x": -6,
      "y": 9,
      "z": -2,
      "name": "Rock_Sandstone_Brick"
    },
    {
      "x": -6,
      "y": 10,
      "z": -2,
      "name": "Rock_Sandstone_Brick",
      "rotation": 3
    },
    {
      "x": -6,
      "y": 11,
      "z": -2,
      "name": "Rock_Sandstone_Brick",
      "rotation": 3
    },
    {
      "x": -6,
      "y": 12,
      "z": -2,
      "name": "Rock_Sandstone_Brick",
      "rotation": 3
    },
    {
      "x": -6,
      "y": 13,
      "z": -2,
      "name": "Rock_Sandstone_Brick",
      "rotation": 3
    },
    {
      "x": -6,
      "y": 14,
      "z": -2,
      "name": "Rock_Sandstone_Brick",
      "rotation": 3
    },
    {
      "x": -6,
      "y": 15,
      "z": -2,
      "name": "Soil_Clay_Ocean_Brick_Smooth",
      "rotation": 3
    },
    {
      "x": -6,
      "y": 16,
      "z": -2,
      "name": "Soil_Clay_Ocean_Brick_Half",
      "rotation": 3
    },
    {
      "x": -6,
      "y": 8,
      "z": -1,
      "name": "Soil_Gravel_Sand"
    },
    {
      "x": -6,
      "y": 9,
      "z": -1,
      "name": "Rock_Sandstone_Brick"
    },
    {
      "x": -6,
      "y": 10,
      "z": -1,
      "name": "Rock_Sandstone_Brick",
      "rotation": 3
    },
    {
      "x": -6,
      "y": 15,
      "z": -1,
      "name": "Soil_Clay_Ocean_Brick_Smooth",
      "rotation": 3
    },
    {
      "x": -6,
      "y": 16,
      "z": -1,
      "name": "Soil_Clay_Ocean_Brick_Half",
      "rotation": 3
    },
    {
      "x": -6,
      "y": 8,
      "z": 0,
      "name": "Soil_Gravel_Sand"
    },
    {
      "x": -6,
      "y": 10,
      "z": 0,
      "name": "Rock_Sandstone_Brick",
      "rotation": 3
    },
    {
      "x": -6,
      "y": 15,
      "z": 0,
      "name": "Soil_Clay_Ocean_Brick_Smooth",
      "rotation": 3
    },
    {
      "x": -6,
      "y": 16,
      "z": 0,
      "name": "Rock_Sandstone_Brick_Smooth",
      "rotation": 3
    },
    {
      "x": -6,
      "y": 8,
      "z": 1,
      "name": "Soil_Gravel_Sand"
    },
    {
      "x": -6,
      "y": 15,
      "z": 1,
      "name": "Soil_Clay_Ocean_Brick_Smooth",
      "rotation": 3
    },
    {
      "x": -6,
      "y": 16,
      "z": 1,
      "name": "Rock_Sandstone_Brick_Smooth",
      "rotation": 3
    },
    {
      "x": -6,
      "y": 8,
      "z": 2,
      "name": "Soil_Gravel_Sand"
    },
    {
      "x": -6,
      "y": 15,
      "z": 2,
      "name": "Soil_Clay_Ocean_Brick_Smooth",
      "rotation": 3
    },
    {
      "x": -6,
      "y": 16,
      "z": 2,
      "name": "Rock_Sandstone_Brick_Smooth",
      "rotation": 3
    },
    {
      "x": -6,
      "y": 8,
      "z": 3,
      "name": "Soil_Gravel_Sand"
    },
    {
      "x": -6,
      "y": 15,
      "z": 3,
      "name": "Soil_Clay_Ocean_Brick_Smooth",
      "rotation": 3
    },
    {
      "x": -6,
      "y": 16,
      "z": 3,
      "name": "Rock_Sandstone_Brick_Smooth",
      "rotation": 3
    },
    {
      "x": -6,
      "y": 8,
      "z": 4,
      "name": "Soil_Gravel_Sand"
    },
    {
      "x": -6,
      "y": 10,
      "z": 4,
      "name": "Rock_Sandstone_Brick",
      "rotation": 3
    },
    {
      "x": -6,
      "y": 15,
      "z": 4,
      "name": "Soil_Clay_Ocean_Brick_Smooth",
      "rotation": 3
    },
    {
      "x": -6,
      "y": 16,
      "z": 4,
      "name": "Soil_Clay_Ocean_Brick_Half",
      "rotation": 3
    },
    {
      "x": -6,
      "y": 8,
      "z": 5,
      "name": "Soil_Gravel_Sand"
    },
    {
      "x": -6,
      "y": 9,
      "z": 5,
      "name": "Rock_Sandstone_Brick"
    },
    {
      "x": -6,
      "y": 10,
      "z": 5,
      "name": "Rock_Sandstone_Brick",
      "rotation": 3
    },
    {
      "x": -6,
      "y": 11,
      "z": 5,
      "name": "Rock_Sandstone_Brick",
      "rotation": 3
    },
    {
      "x": -6,
      "y": 12,
      "z": 5,
      "name": "Rock_Sandstone_Brick",
      "rotation": 3
    },
    {
      "x": -6,
      "y": 13,
      "z": 5,
      "name": "Rock_Sandstone_Brick",
      "rotation": 3
    },
    {
      "x": -6,
      "y": 14,
      "z": 5,
      "name": "Rock_Sandstone_Brick",
      "rotation": 3
    },
    {
      "x": -6,
      "y": 15,
      "z": 5,
      "name": "Soil_Clay_Ocean_Brick_Smooth",
      "rotation": 3
    },
    {
      "x": -6,
      "y": 16,
      "z": 5,
      "name": "Soil_Clay_Ocean_Brick_Half",
      "rotation": 3
    },
    {
      "x": -6,
      "y": 8,
      "z": 6,
      "name": "Soil_Gravel_Sand"
    },
    {
      "x": -6,
      "y": 9,
      "z": 6,
      "name": "Rock_Sandstone_Brick"
    },
    {
      "x": -6,
      "y": 10,
      "z": 6,
      "name": "Rock_Sandstone_Brick",
      "rotation": 3
    },
    {
      "x": -6,
      "y": 11,
      "z": 6,
      "name": "Rock_Sandstone_Brick",
      "rotation": 3
    },
    {
      "x": -6,
      "y": 12,
      "z": 6,
      "name": "Rock_Sandstone_Brick",
      "rotation": 3
    },
    {
      "x": -6,
      "y": 13,
      "z": 6,
      "name": "Rock_Sandstone_Brick",
      "rotation": 3
    },
    {
      "x": -6,
      "y": 14,
      "z": 6,
      "name": "Rock_Sandstone_Brick",
      "rotation": 3
    },
    {
      "x": -6,
      "y": 15,
      "z": 6,
      "name": "Soil_Clay_Ocean_Brick_Smooth",
      "rotation": 3
    },
    {
      "x": -6,
      "y": 8,
      "z": 7,
      "name": "Soil_Gravel_Sand"
    },
    {
      "x": -6,
      "y": 9,
      "z": 7,
      "name": "Rock_Sandstone_Brick_Stairs"
    },
    {
      "x": -6,
      "y": 14,
      "z": 7,
      "name": "Rock_Sandstone_Brick_Stairs",
      "rotation": 9
    },
    {
      "x": -6,
      "y": 15,
      "z": 7,
      "name": "Soil_Clay_Ocean_Brick_Smooth",
      "rotation": 3
    },
    {
      "x": -6,
      "y": 8,
      "z": 8,
      "name": "Soil_Gravel_Sand"
    },
    {
      "x": -6,
      "y": 8,
      "z": 9,
      "name": "Soil_Gravel_Sand"
    },
    {
      "x": -6,
      "y": 8,
      "z": 10,
      "name": "Soil_Gravel_Sand"
    },
    {
      "x": -5,
      "y": 8,
      "z": -9,
      "name": "Soil_Gravel_Sand"
    },
    {
      "x": -5,
      "y": 8,
      "z": -8,
      "name": "Soil_Gravel_Sand"
    },
    {
      "x": -5,
      "y": 8,
      "z": -7,
      "name": "Soil_Gravel_Sand"
    },
    {
      "x": -5,
      "y": 8,
      "z": -6,
      "name": "Soil_Gravel_Sand"
    },
    {
      "x": -5,
      "y": 8,
      "z": -5,
      "name": "Soil_Gravel_Sand"
    },
    {
      "x": -5,
      "y": 9,
      "z": -5,
      "name": "Rock_Sandstone_Brick_Stairs",
      "rotation": 2
    },
    {
      "x": -5,
      "y": 14,
      "z": -5,
      "name": "Rock_Sandstone_Brick_Stairs",
      "rotation": 8
    },
    {
      "x": -5,
      "y": 15,
      "z": -5,
      "name": "Soil_Clay_Ocean_Brick_Smooth",
      "rotation": 3
    },
    {
      "x": -5,
      "y": 8,
      "z": -4,
      "name": "Soil_Gravel_Sand"
    },
    {
      "x": -5,
      "y": 9,
      "z": -4,
      "name": "Rock_Sandstone_Brick"
    },
    {
      "x": -5,
      "y": 10,
      "z": -4,
      "name": "Rock_Sandstone_Brick",
      "rotation": 3
    },
    {
      "x": -5,
      "y": 11,
      "z": -4,
      "name": "Rock_Sandstone_Brick",
      "rotation": 3
    },
    {
      "x": -5,
      "y": 12,
      "z": -4,
      "name": "Rock_Sandstone_Brick",
      "rotation": 3
    },
    {
      "x": -5,
      "y": 13,
      "z": -4,
      "name": "Rock_Sandstone_Brick",
      "rotation": 3
    },
    {
      "x": -5,
      "y": 14,
      "z": -4,
      "name": "Rock_Sandstone_Brick",
      "rotation": 3
    },
    {
      "x": -5,
      "y": 15,
      "z": -4,
      "name": "Soil_Clay_Ocean_Brick_Smooth",
      "rotation": 3
    },
    {
      "x": -5,
      "y": 8,
      "z": -3,
      "name": "Soil_Gravel_Sand"
    },
    {
      "x": -5,
      "y": 9,
      "z": -3,
      "name": "Rock_Sandstone_Brick"
    },
    {
      "x": -5,
      "y": 10,
      "z": -3,
      "name": "Rock_Sandstone_Brick",
      "rotation": 3
    },
    {
      "x": -5,
      "y": 15,
      "z": -3,
      "name": "Soil_Clay_Ocean_Brick_Smooth",
      "rotation": 3
    },
    {
      "x": -5,
      "y": 16,
      "z": -3,
      "name": "Soil_Clay_Ocean_Brick_Half",
      "rotation": 3
    },
    {
      "x": -5,
      "y": 8,
      "z": -2,
      "name": "Soil_Gravel_Sand"
    },
    {
      "x": -5,
      "y": 10,
      "z": -2,
      "name": "Rock_Sandstone_Brick",
      "rotation": 3
    },
    {
      "x": -5,
      "y": 15,
      "z": -2,
      "name": "Soil_Clay_Ocean_Brick_Smooth",
      "rotation": 3
    },
    {
      "x": -5,
      "y": 16,
      "z": -2,
      "name": "Rock_Sandstone_Brick_Smooth",
      "rotation": 3
    },
    {
      "x": -5,
      "y": 8,
      "z": -1,
      "name": "Soil_Gravel_Sand"
    },
    {
      "x": -5,
      "y": 10,
      "z": -1,
      "name": "Rock_Sandstone_Brick",
      "rotation": 3
    },
    {
      "x": -5,
      "y": 15,
      "z": -1,
      "name": "Soil_Clay_Ocean_Brick_Smooth",
      "rotation": 3
    },
    {
      "x": -5,
      "y": 16,
      "z": -1,
      "name": "Rock_Sandstone_Brick_Smooth",
      "rotation": 3
    },
    {
      "x": -5,
      "y": 8,
      "z": 0,
      "name": "Soil_Gravel_Sand"
    },
    {
      "x": -5,
      "y": 9,
      "z": 0,
      "name": "Rock_Sandstone_Cobble",
      "rotation": 3
    },
    {
      "x": -5,
      "y": 10,
      "z": 0,
      "name": "Rock_Sandstone_Brick",
      "rotation": 3
    },
    {
      "x": -5,
      "y": 15,
      "z": 0,
      "name": "Rock_Sandstone_Brick",
      "rotation": 3
    },
    {
      "x": -5,
      "y": 16,
      "z": 0,
      "name": "Rock_Sandstone_Brick",
      "rotation": 3
    },
    {
      "x": -5,
      "y": 17,
      "z": 0,
      "name": "Soil_Clay_Ocean_Brick_Smooth",
      "rotation": 3
    },
    {
      "x": -5,
      "y": 8,
      "z": 1,
      "name": "Soil_Gravel_Sand"
    },
    {
      "x": -5,
      "y": 9,
      "z": 1,
      "name": "Rock_Sandstone_Cobble",
      "rotation": 3
    },
    {
      "x": -5,
      "y": 10,
      "z": 1,
      "name": "Rock_Sandstone_Brick",
      "rotation": 3
    },
    {
      "x": -5,
      "y": 15,
      "z": 1,
      "name": "Rock_Sandstone_Brick",
      "rotation": 3
    },
    {
      "x": -5,
      "y": 16,
      "z": 1,
      "name": "Rock_Sandstone_Brick_Half",
      "rotation": 3
    },
    {
      "x": -5,
      "y": 18,
      "z": 1,
      "name": "Soil_Clay_Ocean_Brick_Smooth",
      "rotation": 3
    },
    {
      "x": -5,
      "y": 8,
      "z": 2,
      "name": "Soil_Gravel_Sand"
    },
    {
      "x": -5,
      "y": 9,
      "z": 2,
      "name": "Rock_Sandstone_Cobble",
      "rotation": 3
    },
    {
      "x": -5,
      "y": 10,
      "z": 2,
      "name": "Rock_Sandstone_Brick",
      "rotation": 3
    },
    {
      "x": -5,
      "y": 15,
      "z": 2,
      "name": "Rock_Sandstone_Brick",
      "rotation": 3
    },
    {
      "x": -5,
      "y": 16,
      "z": 2,
      "name": "Rock_Sandstone_Brick_Half",
      "rotation": 3
    },
    {
      "x": -5,
      "y": 18,
      "z": 2,
      "name": "Soil_Clay_Ocean_Brick_Smooth",
      "rotation": 3
    },
    {
      "x": -5,
      "y": 8,
      "z": 3,
      "name": "Soil_Gravel_Sand"
    },
    {
      "x": -5,
      "y": 9,
      "z": 3,
      "name": "Rock_Sandstone_Cobble",
      "rotation": 3
    },
    {
      "x": -5,
      "y": 10,
      "z": 3,
      "name": "Rock_Sandstone_Brick",
      "rotation": 3
    },
    {
      "x": -5,
      "y": 15,
      "z": 3,
      "name": "Rock_Sandstone_Brick",
      "rotation": 3
    },
    {
      "x": -5,
      "y": 16,
      "z": 3,
      "name": "Rock_Sandstone_Brick",
      "rotation": 3
    },
    {
      "x": -5,
      "y": 17,
      "z": 3,
      "name": "Soil_Clay_Ocean_Brick_Smooth",
      "rotation": 3
    },
    {
      "x": -5,
      "y": 8,
      "z": 4,
      "name": "Soil_Gravel_Sand"
    },
    {
      "x": -5,
      "y": 10,
      "z": 4,
      "name": "Rock_Sandstone_Brick",
      "rotation": 3
    },
    {
      "x": -5,
      "y": 15,
      "z": 4,
      "name": "Soil_Clay_Ocean_Brick_Smooth",
      "rotation": 3
    },
    {
      "x": -5,
      "y": 16,
      "z": 4,
      "name": "Rock_Sandstone_Brick_Smooth",
      "rotation": 3
    },
    {
      "x": -5,
      "y": 8,
      "z": 5,
      "name": "Soil_Gravel_Sand"
    },
    {
      "x": -5,
      "y": 9,
      "z": 5,
      "name": "Rock_Sandstone_Brick"
    },
    {
      "x": -5,
      "y": 10,
      "z": 5,
      "name": "Rock_Sandstone_Brick",
      "rotation": 3
    },
    {
      "x": -5,
      "y": 15,
      "z": 5,
      "name": "Soil_Clay_Ocean_Brick_Smooth",
      "rotation": 3
    },
    {
      "x": -5,
      "y": 16,
      "z": 5,
      "name": "Rock_Sandstone_Brick_Smooth",
      "rotation": 3
    },
    {
      "x": -5,
      "y": 8,
      "z": 6,
      "name": "Soil_Gravel_Sand"
    },
    {
      "x": -5,
      "y": 9,
      "z": 6,
      "name": "Rock_Sandstone_Brick"
    },
    {
      "x": -5,
      "y": 10,
      "z": 6,
      "name": "Rock_Sandstone_Brick",
      "rotation": 3
    },
    {
      "x": -5,
      "y": 11,
      "z": 6,
      "name": "Rock_Sandstone_Brick"
    },
    {
      "x": -5,
      "y": 12,
      "z": 6,
      "name": "Rock_Sandstone_Brick"
    },
    {
      "x": -5,
      "y": 13,
      "z": 6,
      "name": "Rock_Sandstone_Brick"
    },
    {
      "x": -5,
      "y": 14,
      "z": 6,
      "name": "Rock_Sandstone_Brick"
    },
    {
      "x": -5,
      "y": 15,
      "z": 6,
      "name": "Soil_Clay_Ocean_Brick_Smooth",
      "rotation": 3
    },
    {
      "x": -5,
      "y": 16,
      "z": 6,
      "name": "Soil_Clay_Ocean_Brick_Half",
      "rotation": 3
    },
    {
      "x": -5,
      "y": 8,
      "z": 7,
      "name": "Soil_Gravel_Sand"
    },
    {
      "x": -5,
      "y": 9,
      "z": 7,
      "name": "Rock_Sandstone_Brick_Stairs"
    },
    {
      "x": -5,
      "y": 13,
      "z": 7,
      "name": "Rock_Sandstone_Brick_Stairs",
      "rotation": 9
    },
    {
      "x": -5,
      "y": 14,
      "z": 7,
      "name": "Rock_Sandstone_Brick"
    },
    {
      "x": -5,
      "y": 15,
      "z": 7,
      "name": "Soil_Clay_Ocean_Brick_Smooth",
      "rotation": 3
    },
    {
      "x": -5,
      "y": 8,
      "z": 8,
      "name": "Soil_Gravel_Sand"
    },
    {
      "x": -5,
      "y": 13,
      "z": 8,
      "name": "*Rock_Sandstone_Brick_Stairs_State_Definitions_Corner_Right",
      "rotation": 9
    },
    {
      "x": -5,
      "y": 14,
      "z": 8,
      "name": "Rock_Sandstone_Brick"
    },
    {
      "x": -5,
      "y": 15,
      "z": 8,
      "name": "Soil_Clay_Ocean_Brick_Smooth",
      "rotation": 3
    },
    {
      "x": -5,
      "y": 8,
      "z": 9,
      "name": "Soil_Gravel_Sand"
    },
    {
      "x": -5,
      "y": 8,
      "z": 10,
      "name": "Soil_Gravel_Sand"
    },
    {
      "x": -4,
      "y": 8,
      "z": -9,
      "name": "Soil_Gravel_Sand"
    },
    {
      "x": -4,
      "y": 8,
      "z": -8,
      "name": "Soil_Gravel_Sand"
    },
    {
      "x": -4,
      "y": 8,
      "z": -7,
      "name": "Soil_Gravel_Sand"
    },
    {
      "x": -4,
      "y": 8,
      "z": -6,
      "name": "Soil_Gravel_Sand"
    },
    {
      "x": -4,
      "y": 14,
      "z": -6,
      "name": "Rock_Sandstone_Brick_Stairs",
      "rotation": 8
    },
    {
      "x": -4,
      "y": 15,
      "z": -6,
      "name": "Soil_Clay_Ocean_Brick_Smooth",
      "rotation": 3
    },
    {
      "x": -4,
      "y": 8,
      "z": -5,
      "name": "Soil_Gravel_Sand"
    },
    {
      "x": -4,
      "y": 9,
      "z": -5,
      "name": "Rock_Sandstone_Brick"
    },
    {
      "x": -4,
      "y": 10,
      "z": -5,
      "name": "Rock_Sandstone_Brick",
      "rotation": 3
    },
    {
      "x": -4,
      "y": 11,
      "z": -5,
      "name": "Rock_Sandstone_Brick",
      "rotation": 3
    },
    {
      "x": -4,
      "y": 12,
      "z": -5,
      "name": "Rock_Sandstone_Brick",
      "rotation": 3
    },
    {
      "x": -4,
      "y": 13,
      "z": -5,
      "name": "Rock_Sandstone_Brick",
      "rotation": 3
    },
    {
      "x": -4,
      "y": 14,
      "z": -5,
      "name": "Rock_Sandstone_Brick",
      "rotation": 3
    },
    {
      "x": -4,
      "y": 15,
      "z": -5,
      "name": "Soil_Clay_Ocean_Brick_Smooth",
      "rotation": 3
    },
    {
      "x": -4,
      "y": 8,
      "z": -4,
      "name": "Soil_Gravel_Sand"
    },
    {
      "x": -4,
      "y": 9,
      "z": -4,
      "name": "Rock_Sandstone_Brick"
    },
    {
      "x": -4,
      "y": 10,
      "z": -4,
      "name": "Rock_Sandstone_Brick",
      "rotation": 3
    },
    {
      "x": -4,
      "y": 15,
      "z": -4,
      "name": "Soil_Clay_Ocean_Brick_Smooth",
      "rotation": 3
    },
    {
      "x": -4,
      "y": 16,
      "z": -4,
      "name": "Soil_Clay_Ocean_Brick_Half",
      "rotation": 3
    },
    {
      "x": -4,
      "y": 8,
      "z": -3,
      "name": "Soil_Gravel_Sand"
    },
    {
      "x": -4,
      "y": 9,
      "z": -3,
      "name": "Rock_Sandstone_Brick"
    },
    {
      "x": -4,
      "y": 10,
      "z": -3,
      "name": "Rock_Sandstone_Brick",
      "rotation": 3
    },
    {
      "x": -4,
      "y": 15,
      "z": -3,
      "name": "Soil_Clay_Ocean_Brick_Smooth",
      "rotation": 3
    },
    {
      "x": -4,
      "y": 16,
      "z": -3,
      "name": "Rock_Sandstone_Brick_Smooth",
      "rotation": 3
    },
    {
      "x": -4,
      "y": 8,
      "z": -2,
      "name": "Soil_Gravel_Sand"
    },
    {
      "x": -4,
      "y": 9,
      "z": -2,
      "name": "Rock_Sandstone_Cobble",
      "rotation": 3
    },
    {
      "x": -4,
      "y": 10,
      "z": -2,
      "name": "Rock_Sandstone_Brick",
      "rotation": 3
    },
    {
      "x": -4,
      "y": 15,
      "z": -2,
      "name": "Rock_Sandstone_Brick",
      "rotation": 3
    },
    {
      "x": -4,
      "y": 16,
      "z": -2,
      "name": "Rock_Sandstone_Brick",
      "rotation": 3
    },
    {
      "x": -4,
      "y": 17,
      "z": -2,
      "name": "Soil_Clay_Ocean_Brick_Smooth",
      "rotation": 3
    },
    {
      "x": -4,
      "y": 21,
      "z": -2,
      "name": "Rock_Sandstone_Brick_Stairs",
      "rotation": 8
    },
    {
      "x": -4,
      "y": 22,
      "z": -2,
      "name": "Rock_Sandstone_Brick_Wall",
      "rotation": 2
    },
    {
      "x": -4,
      "y": 8,
      "z": -1,
      "name": "Soil_Gravel_Sand"
    },
    {
      "x": -4,
      "y": 9,
      "z": -1,
      "name": "Rock_Sandstone_Cobble",
      "rotation": 3
    },
    {
      "x": -4,
      "y": 10,
      "z": -1,
      "name": "Rock_Sandstone_Brick",
      "rotation": 3
    },
    {
      "x": -4,
      "y": 15,
      "z": -1,
      "name": "Rock_Sandstone_Brick",
      "rotation": 3
    },
    {
      "x": -4,
      "y": 16,
      "z": -1,
      "name": "Rock_Sandstone_Brick",
      "rotation": 3
    },
    {
      "x": -4,
      "y": 17,
      "z": -1,
      "name": "Soil_Clay_Ocean_Brick_Smooth",
      "rotation": 3
    },
    {
      "x": -4,
      "y": 18,
      "z": -1,
      "name": "Soil_Clay_Ocean_Brick_Smooth",
      "rotation": 3
    },
    {
      "x": -4,
      "y": 20,
      "z": -1,
      "name": "Rock_Sandstone_Brick_Stairs",
      "rotation": 9
    },
    {
      "x": -4,
      "y": 8,
      "z": 0,
      "name": "Soil_Gravel_Sand"
    },
    {
      "x": -4,
      "y": 10,
      "z": 0,
      "name": "Rock_Sandstone_Brick",
      "rotation": 3
    },
    {
      "x": -4,
      "y": 18,
      "z": 0,
      "name": "Soil_Clay_Ocean_Brick_Smooth",
      "rotation": 3
    },
    {
      "x": -4,
      "y": 20,
      "z": 0,
      "name": "Rock_Sandstone_Brick_Stairs",
      "rotation": 9
    },
    {
      "x": -4,
      "y": 8,
      "z": 1,
      "name": "Soil_Gravel_Sand"
    },
    {
      "x": -4,
      "y": 10,
      "z": 1,
      "name": "Rock_Sandstone_Brick",
      "rotation": 3
    },
    {
      "x": -4,
      "y": 18,
      "z": 1,
      "name": "Soil_Clay_Ocean_Brick_Smooth",
      "rotation": 3
    },
    {
      "x": -4,
      "y": 19,
      "z": 1,
      "name": "Soil_Clay_Ocean_Brick_Smooth",
      "rotation": 3
    },
    {
      "x": -4,
      "y": 20,
      "z": 1,
      "name": "Rock_Sandstone_Brick_Half",
      "rotation": 7
    },
    {
      "x": -4,
      "y": 8,
      "z": 2,
      "name": "Soil_Gravel_Sand"
    },
    {
      "x": -4,
      "y": 10,
      "z": 2,
      "name": "Rock_Sandstone_Brick",
      "rotation": 3
    },
    {
      "x": -4,
      "y": 18,
      "z": 2,
      "name": "Soil_Clay_Ocean_Brick_Smooth",
      "rotation": 3
    },
    {
      "x": -4,
      "y": 19,
      "z": 2,
      "name": "Soil_Clay_Ocean_Brick_Smooth",
      "rotation": 3
    },
    {
      "x": -4,
      "y": 20,
      "z": 2,
      "name": "Rock_Sandstone_Brick_Half",
      "rotation": 7
    },
    {
      "x": -4,
      "y": 8,
      "z": 3,
      "name": "Soil_Gravel_Sand"
    },
    {
      "x": -4,
      "y": 10,
      "z": 3,
      "name": "Rock_Sandstone_Brick",
      "rotation": 3
    },
    {
      "x": -4,
      "y": 18,
      "z": 3,
      "name": "Soil_Clay_Ocean_Brick_Smooth",
      "rotation": 3
    },
    {
      "x": -4,
      "y": 8,
      "z": 4,
      "name": "Soil_Gravel_Sand"
    },
    {
      "x": -4,
      "y": 9,
      "z": 4,
      "name": "Rock_Sandstone_Cobble",
      "rotation": 3
    },
    {
      "x": -4,
      "y": 10,
      "z": 4,
      "name": "Rock_Sandstone_Brick",
      "rotation": 3
    },
    {
      "x": -4,
      "y": 17,
      "z": 4,
      "name": "Soil_Clay_Ocean_Brick_Smooth",
      "rotation": 3
    },
    {
      "x": -4,
      "y": 18,
      "z": 4,
      "name": "Soil_Clay_Ocean_Brick_Smooth",
      "rotation": 3
    },
    {
      "x": -4,
      "y": 8,
      "z": 5,
      "name": "Soil_Gravel_Sand"
    },
    {
      "x": -4,
      "y": 9,
      "z": 5,
      "name": "Rock_Sandstone_Cobble",
      "rotation": 3
    },
    {
      "x": -4,
      "y": 10,
      "z": 5,
      "name": "Rock_Sandstone_Brick",
      "rotation": 3
    },
    {
      "x": -4,
      "y": 17,
      "z": 5,
      "name": "Soil_Clay_Ocean_Brick_Smooth",
      "rotation": 3
    },
    {
      "x": -4,
      "y": 8,
      "z": 6,
      "name": "Soil_Gravel_Sand"
    },
    {
      "x": -4,
      "y": 9,
      "z": 6,
      "name": "Rock_Sandstone_Brick"
    },
    {
      "x": -4,
      "y": 10,
      "z": 6,
      "name": "Rock_Sandstone_Brick",
      "rotation": 3
    },
    {
      "x": -4,
      "y": 11,
      "z": 6,
      "name": "Rock_Sandstone_Brick"
    },
    {
      "x": -4,
      "y": 12,
      "z": 6,
      "name": "Rock_Sandstone_Brick"
    },
    {
      "x": -4,
      "y": 13,
      "z": 6,
      "name": "Rock_Sandstone_Brick"
    },
    {
      "x": -4,
      "y": 14,
      "z": 6,
      "name": "Rock_Sandstone_Brick"
    },
    {
      "x": -4,
      "y": 15,
      "z": 6,
      "name": "Soil_Clay_Ocean_Brick_Smooth",
      "rotation": 3
    },
    {
      "x": -4,
      "y": 16,
      "z": 6,
      "name": "Rock_Sandstone_Brick_Smooth",
      "rotation": 3
    },
    {
      "x": -4,
      "y": 8,
      "z": 7,
      "name": "Soil_Gravel_Sand"
    },
    {
      "x": -4,
      "y": 9,
      "z": 7,
      "name": "Rock_Sandstone_Brick_Stairs"
    },
    {
      "x": -4,
      "y": 12,
      "z": 7,
      "name": "Rock_Sandstone_Brick_Stairs",
      "rotation": 10
    },
    {
      "x": -4,
      "y": 13,
      "z": 7,
      "name": "Rock_Sandstone_Brick"
    },
    {
      "x": -4,
      "y": 14,
      "z": 7,
      "name": "Rock_Sandstone_Brick"
    },
    {
      "x": -4,
      "y": 15,
      "z": 7,
      "name": "Soil_Clay_Ocean_Brick_Smooth",
      "rotation": 3
    },
    {
      "x": -4,
      "y": 16,
      "z": 7,
      "name": "Soil_Clay_Ocean_Brick_Half",
      "rotation": 3
    },
    {
      "x": -4,
      "y": 8,
      "z": 8,
      "name": "Soil_Gravel_Sand"
    },
    {
      "x": -4,
      "y": 13,
      "z": 8,
      "name": "Rock_Sandstone_Brick_Stairs",
      "rotation": 10
    },
    {
      "x": -4,
      "y": 14,
      "z": 8,
      "name": "Rock_Sandstone_Brick"
    },
    {
      "x": -4,
      "y": 15,
      "z": 8,
      "name": "Soil_Clay_Ocean_Brick_Smooth",
      "rotation": 3
    },
    {
      "x": -4,
      "y": 8,
      "z": 9,
      "name": "Soil_Gravel_Sand"
    },
    {
      "x": -4,
      "y": 14,
      "z": 9,
      "name": "Rock_Sandstone_Brick_Stairs",
      "rotation": 10
    },
    {
      "x": -4,
      "y": 15,
      "z": 9,
      "name": "Soil_Clay_Ocean_Brick_Smooth",
      "rotation": 3
    },
    {
      "x": -4,
      "y": 8,
      "z": 10,
      "name": "Soil_Gravel_Sand"
    },
    {
      "x": -3,
      "y": 8,
      "z": -9,
      "name": "Soil_Gravel_Sand"
    },
    {
      "x": -3,
      "y": 8,
      "z": -8,
      "name": "Soil_Gravel_Sand"
    },
    {
      "x": -3,
      "y": 8,
      "z": -7,
      "name": "Soil_Gravel_Sand"
    },
    {
      "x": -3,
      "y": 9,
      "z": -7,
      "name": "*Rock_Sandstone_Brick_Stairs_State_Definitions_Corner_Left",
      "rotation": 2
    },
    {
      "x": -3,
      "y": 8,
      "z": -6,
      "name": "Soil_Gravel_Sand"
    },
    {
      "x": -3,
      "y": 9,
      "z": -6,
      "name": "Rock_Sandstone_Brick_Stairs",
      "rotation": 3
    },
    {
      "x": -3,
      "y": 14,
      "z": -6,
      "name": "Rock_Sandstone_Brick_Stairs",
      "rotation": 8
    },
    {
      "x": -3,
      "y": 15,
      "z": -6,
      "name": "Soil_Clay_Ocean_Brick_Smooth",
      "rotation": 3
    },
    {
      "x": -3,
      "y": 8,
      "z": -5,
      "name": "Soil_Gravel_Sand"
    },
    {
      "x": -3,
      "y": 9,
      "z": -5,
      "name": "Rock_Sandstone_Brick"
    },
    {
      "x": -3,
      "y": 10,
      "z": -5,
      "name": "Rock_Sandstone_Brick",
      "rotation": 3
    },
    {
      "x": -3,
      "y": 11,
      "z": -5,
      "name": "Rock_Sandstone_Brick",
      "rotation": 3
    },
    {
      "x": -3,
      "y": 12,
      "z": -5,
      "name": "Rock_Sandstone_Brick",
      "rotation": 3
    },
    {
      "x": -3,
      "y": 13,
      "z": -5,
      "name": "Rock_Sandstone_Brick",
      "rotation": 3
    },
    {
      "x": -3,
      "y": 14,
      "z": -5,
      "name": "Rock_Sandstone_Brick",
      "rotation": 3
    },
    {
      "x": -3,
      "y": 15,
      "z": -5,
      "name": "Soil_Clay_Ocean_Brick_Smooth",
      "rotation": 3
    },
    {
      "x": -3,
      "y": 16,
      "z": -5,
      "name": "Soil_Clay_Ocean_Brick_Half",
      "rotation": 3
    },
    {
      "x": -3,
      "y": 8,
      "z": -4,
      "name": "Soil_Gravel_Sand"
    },
    {
      "x": -3,
      "y": 9,
      "z": -4,
      "name": "Wood_Dry_Trunk",
      "rotation": 4
    },
    {
      "x": -3,
      "y": 10,
      "z": -4,
      "name": "Rock_Sandstone_Brick",
      "rotation": 3
    },
    {
      "x": -3,
      "y": 15,
      "z": -4,
      "name": "Soil_Clay_Ocean_Brick_Smooth",
      "rotation": 3
    },
    {
      "x": -3,
      "y": 16,
      "z": -4,
      "name": "Rock_Sandstone_Brick_Smooth",
      "rotation": 3
    },
    {
      "x": -3,
      "y": 8,
      "z": -3,
      "name": "Soil_Gravel_Sand"
    },
    {
      "x": -3,
      "y": 9,
      "z": -3,
      "name": "Rock_Sandstone_Cobble",
      "rotation": 3
    },
    {
      "x": -3,
      "y": 10,
      "z": -3,
      "name": "Rock_Sandstone_Brick",
      "rotation": 3
    },
    {
      "x": -3,
      "y": 15,
      "z": -3,
      "name": "Rock_Sandstone_Brick",
      "rotation": 3
    },
    {
      "x": -3,
      "y": 16,
      "z": -3,
      "name": "Rock_Sandstone_Brick",
      "rotation": 3
    },
    {
      "x": -3,
      "y": 17,
      "z": -3,
      "name": "Soil_Clay_Ocean_Brick_Smooth",
      "rotation": 3
    },
    {
      "x": -3,
      "y": 8,
      "z": -2,
      "name": "Soil_Gravel_Sand"
    },
    {
      "x": -3,
      "y": 10,
      "z": -2,
      "name": "Rock_Sandstone_Brick",
      "rotation": 3
    },
    {
      "x": -3,
      "y": 18,
      "z": -2,
      "name": "Soil_Clay_Ocean_Brick_Smooth",
      "rotation": 3
    },
    {
      "x": -3,
      "y": 20,
      "z": -2,
      "name": "Rock_Sandstone_Brick_Half",
      "rotation": 6
    },
    {
      "x": -3,
      "y": 21,
      "z": -2,
      "name": "Rock_Sandstone_Brick_Stairs",
      "rotation": 8
    },
    {
      "x": -3,
      "y": 22,
      "z": -2,
      "name": "Rock_Sandstone_Brick_Wall",
      "rotation": 2
    },
    {
      "x": -3,
      "y": 26,
      "z": -2,
      "name": "Soil_Clay_Ocean_Brick_Roof_Hollow",
      "rotation": 2
    },
    {
      "x": -3,
      "y": 8,
      "z": -1,
      "name": "Soil_Gravel_Sand"
    },
    {
      "x": -3,
      "y": 10,
      "z": -1,
      "name": "Rock_Sandstone_Brick",
      "rotation": 3
    },
    {
      "x": -3,
      "y": 18,
      "z": -1,
      "name": "Soil_Clay_Ocean_Brick_Smooth",
      "rotation": 3
    },
    {
      "x": -3,
      "y": 19,
      "z": -1,
      "name": "Soil_Clay_Ocean_Brick_Smooth",
      "rotation": 3
    },
    {
      "x": -3,
      "y": 20,
      "z": -1,
      "name": "Rock_Sandstone_Brick",
      "rotation": 2
    },
    {
      "x": -3,
      "y": 21,
      "z": -1,
      "name": "Rock_Sandstone_Brick",
      "rotation": 2
    },
    {
      "x": -3,
      "y": 24,
      "z": -1,
      "name": "Rock_Sandstone_Brick_Ornate",
      "rotation": 2
    },
    {
      "x": -3,
      "y": 25,
      "z": -1,
      "name": "Rock_Sandstone_Brick_Smooth_Half",
      "rotation": 10
    },
    {
      "x": -3,
      "y": 26,
      "z": -1,
      "name": "Rock_Sandstone_Brick",
      "rotation": 2
    },
    {
      "x": -3,
      "y": 27,
      "z": -1,
      "name": "Soil_Clay_Ocean_Brick_Roof",
      "rotation": 2
    },
    {
      "x": -3,
      "y": 8,
      "z": 0,
      "name": "Soil_Gravel_Sand"
    },
    {
      "x": -3,
      "y": 10,
      "z": 0,
      "name": "Rock_Sandstone_Brick",
      "rotation": 3
    },
    {
      "x": -3,
      "y": 18,
      "z": 0,
      "name": "Soil_Clay_Ocean_Brick_Smooth",
      "rotation": 3
    },
    {
      "x": -3,
      "y": 19,
      "z": 0,
      "name": "Soil_Clay_Ocean_Brick_Smooth",
      "rotation": 3
    },
    {
      "x": -3,
      "y": 20,
      "z": 0,
      "name": "Rock_Sandstone_Brick",
      "rotation": 2
    },
    {
      "x": -3,
      "y": 22,
      "z": 0,
      "name": "Rock_Sandstone_Brick",
      "rotation": 2
    },
    {
      "x": -3,
      "y": 23,
      "z": 0,
      "name": "Rock_Sandstone_Brick",
      "rotation": 2
    },
    {
      "x": -3,
      "y": 24,
      "z": 0,
      "name": "Rock_Sandstone_Brick_Ornate",
      "rotation": 2
    },
    {
      "x": -3,
      "y": 25,
      "z": 0,
      "name": "Soil_Clay_Ocean_Brick_Smooth",
      "rotation": 2
    },
    {
      "x": -3,
      "y": 26,
      "z": 0,
      "name": "Rock_Sandstone_Brick",
      "rotation": 2
    },
    {
      "x": -3,
      "y": 27,
      "z": 0,
      "name": "Rock_Sandstone_Brick_Smooth",
      "rotation": 2
    },
    {
      "x": -3,
      "y": 28,
      "z": 0,
      "name": "Rock_Sandstone_Brick"
    },
    {
      "x": -3,
      "y": 8,
      "z": 1,
      "name": "Soil_Gravel_Sand"
    },
    {
      "x": -3,
      "y": 10,
      "z": 1,
      "name": "Rock_Sandstone_Brick",
      "rotation": 3
    },
    {
      "x": -3,
      "y": 19,
      "z": 1,
      "name": "Soil_Clay_Ocean_Brick_Smooth",
      "rotation": 3
    },
    {
      "x": -3,
      "y": 20,
      "z": 1,
      "name": "Rock_Sandstone_Brick",
      "rotation": 2
    },
    {
      "x": -3,
      "y": 24,
      "z": 1,
      "name": "Rock_Sandstone_Brick_Stairs",
      "rotation": 10
    },
    {
      "x": -3,
      "y": 25,
      "z": 1,
      "name": "Rock_Sandstone_Brick",
      "rotation": 2
    },
    {
      "x": -3,
      "y": 26,
      "z": 1,
      "name": "Soil_Clay_Ocean_Brick_Roof",
      "rotation": 3
    },
    {
      "x": -3,
      "y": 30,
      "z": 1,
      "name": "Rock_Sandstone_Brick_Smooth_Half",
      "rotation": 7
    },
    {
      "x": -3,
      "y": 8,
      "z": 2,
      "name": "Soil_Gravel_Sand"
    },
    {
      "x": -3,
      "y": 10,
      "z": 2,
      "name": "Rock_Sandstone_Brick",
      "rotation": 3
    },
    {
      "x": -3,
      "y": 19,
      "z": 2,
      "name": "Soil_Clay_Ocean_Brick_Smooth",
      "rotation": 3
    },
    {
      "x": -3,
      "y": 20,
      "z": 2,
      "name": "Rock_Sandstone_Brick",
      "rotation": 2
    },
    {
      "x": -3,
      "y": 24,
      "z": 2,
      "name": "Rock_Sandstone_Brick_Smooth_Half",
      "rotation": 10
    },
    {
      "x": -3,
      "y": 25,
      "z": 2,
      "name": "Rock_Sandstone_Brick",
      "rotation": 2
    },
    {
      "x": -3,
      "y": 26,
      "z": 2,
      "name": "Soil_Clay_Ocean_Brick_Roof",
      "rotation": 3
    },
    {
      "x": -3,
      "y": 8,
      "z": 3,
      "name": "Soil_Gravel_Sand"
    },
    {
      "x": -3,
      "y": 10,
      "z": 3,
      "name": "Rock_Sandstone_Brick",
      "rotation": 3
    },
    {
      "x": -3,
      "y": 18,
      "z": 3,
      "name": "Soil_Clay_Ocean_Brick_Smooth",
      "rotation": 3
    },
    {
      "x": -3,
      "y": 19,
      "z": 3,
      "name": "Soil_Clay_Ocean_Brick_Smooth",
      "rotation": 3
    },
    {
      "x": -3,
      "y": 24,
      "z": 3,
      "name": "Rock_Sandstone_Brick_Stairs",
      "rotation": 8
    },
    {
      "x": -3,
      "y": 25,
      "z": 3,
      "name": "Rock_Sandstone_Brick",
      "rotation": 2
    },
    {
      "x": -3,
      "y": 26,
      "z": 3,
      "name": "Soil_Clay_Ocean_Brick_Roof",
      "rotation": 3
    },
    {
      "x": -3,
      "y": 8,
      "z": 4,
      "name": "Soil_Gravel_Sand"
    },
    {
      "x": -3,
      "y": 10,
      "z": 4,
      "name": "Rock_Sandstone_Brick",
      "rotation": 3
    },
    {
      "x": -3,
      "y": 18,
      "z": 4,
      "name": "Soil_Clay_Ocean_Brick_Smooth",
      "rotation": 3
    },
    {
      "x": -3,
      "y": 19,
      "z": 4,
      "name": "Soil_Clay_Ocean_Brick_Smooth",
      "rotation": 3
    },
    {
      "x": -3,
      "y": 22,
      "z": 4,
      "name": "Rock_Sandstone_Brick_Half",
      "rotation": 10
    },
    {
      "x": -3,
      "y": 23,
      "z": 4,
      "name": "Rock_Sandstone_Brick",
      "rotation": 2
    },
    {
      "x": -3,
      "y": 24,
      "z": 4,
      "name": "Rock_Sandstone_Brick_Ornate",
      "rotation": 2
    },
    {
      "x": -3,
      "y": 25,
      "z": 4,
      "name": "Soil_Clay_Ocean_Brick_Smooth",
      "rotation": 2
    },
    {
      "x": -3,
      "y": 26,
      "z": 4,
      "name": "Rock_Sandstone_Brick",
      "rotation": 2
    },
    {
      "x": -3,
      "y": 27,
      "z": 4,
      "name": "Rock_Sandstone_Brick_Smooth",
      "rotation": 2
    },
    {
      "x": -3,
      "y": 8,
      "z": 5,
      "name": "Soil_Gravel_Sand"
    },
    {
      "x": -3,
      "y": 10,
      "z": 5,
      "name": "Rock_Sandstone_Brick",
      "rotation": 3
    },
    {
      "x": -3,
      "y": 18,
      "z": 5,
      "name": "Soil_Clay_Ocean_Brick_Smooth",
      "rotation": 3
    },
    {
      "x": -3,
      "y": 24,
      "z": 5,
      "name": "Rock_Sandstone_Brick_Ornate",
      "rotation": 2
    },
    {
      "x": -3,
      "y": 25,
      "z": 5,
      "name": "Rock_Sandstone_Brick_Smooth_Half",
      "rotation": 10
    },
    {
      "x": -3,
      "y": 26,
      "z": 5,
      "name": "Rock_Sandstone_Brick",
      "rotation": 2
    },
    {
      "x": -3,
      "y": 8,
      "z": 6,
      "name": "Soil_Gravel_Sand"
    },
    {
      "x": -3,
      "y": 9,
      "z": 6,
      "name": "Rock_Sandstone_Cobble",
      "rotation": 3
    },
    {
      "x": -3,
      "y": 10,
      "z": 6,
      "name": "Rock_Sandstone_Brick",
      "rotation": 3
    },
    {
      "x": -3,
      "y": 11,
      "z": 6,
      "name": "Rock_Sandstone_Brick"
    },
    {
      "x": -3,
      "y": 12,
      "z": 6,
      "name": "Rock_Sandstone_Brick"
    },
    {
      "x": -3,
      "y": 13,
      "z": 6,
      "name": "Rock_Sandstone_Brick"
    },
    {
      "x": -3,
      "y": 14,
      "z": 6,
      "name": "Rock_Sandstone_Brick"
    },
    {
      "x": -3,
      "y": 15,
      "z": 6,
      "name": "Rock_Sandstone_Brick",
      "rotation": 3
    },
    {
      "x": -3,
      "y": 16,
      "z": 6,
      "name": "Rock_Sandstone_Brick",
      "rotation": 3
    },
    {
      "x": -3,
      "y": 17,
      "z": 6,
      "name": "Soil_Clay_Ocean_Brick_Smooth",
      "rotation": 3
    },
    {
      "x": -3,
      "y": 25,
      "z": 6,
      "name": "Soil_Clay_Ocean_Brick_Roof_Hollow"
    },
    {
      "x": -3,
      "y": 26,
      "z": 6,
      "name": "Soil_Clay_Ocean_Brick_Half",
      "rotation": 4
    },
    {
      "x": -3,
      "y": 8,
      "z": 7,
      "name": "Soil_Gravel_Sand"
    },
    {
      "x": -3,
      "y": 9,
      "z": 7,
      "name": "Rock_Sandstone_Brick_Stairs"
    },
    {
      "x": -3,
      "y": 12,
      "z": 7,
      "name": "Rock_Sandstone_Brick_Stairs",
      "rotation": 10
    },
    {
      "x": -3,
      "y": 13,
      "z": 7,
      "name": "Rock_Sandstone_Brick"
    },
    {
      "x": -3,
      "y": 14,
      "z": 7,
      "name": "Rock_Sandstone_Brick"
    },
    {
      "x": -3,
      "y": 15,
      "z": 7,
      "name": "Soil_Clay_Ocean_Brick_Smooth",
      "rotation": 3
    },
    {
      "x": -3,
      "y": 16,
      "z": 7,
      "name": "Rock_Sandstone_Brick_Smooth",
      "rotation": 3
    },
    {
      "x": -3,
      "y": 8,
      "z": 8,
      "name": "Soil_Gravel_Sand"
    },
    {
      "x": -3,
      "y": 13,
      "z": 8,
      "name": "Rock_Sandstone_Brick_Stairs",
      "rotation": 10
    },
    {
      "x": -3,
      "y": 14,
      "z": 8,
      "name": "Rock_Sandstone_Brick"
    },
    {
      "x": -3,
      "y": 15,
      "z": 8,
      "name": "Soil_Clay_Ocean_Brick_Smooth",
      "rotation": 3
    },
    {
      "x": -3,
      "y": 16,
      "z": 8,
      "name": "Soil_Clay_Ocean_Brick_Half",
      "rotation": 3
    },
    {
      "x": -3,
      "y": 8,
      "z": 9,
      "name": "Soil_Gravel_Sand"
    },
    {
      "x": -3,
      "y": 14,
      "z": 9,
      "name": "Rock_Sandstone_Brick_Stairs",
      "rotation": 10
    },
    {
      "x": -3,
      "y": 15,
      "z": 9,
      "name": "Soil_Clay_Ocean_Brick_Smooth",
      "rotation": 3
    },
    {
      "x": -3,
      "y": 8,
      "z": 10,
      "name": "Soil_Gravel_Sand"
    },
    {
      "x": -2,
      "y": 8,
      "z": -9,
      "name": "Soil_Gravel_Sand"
    },
    {
      "x": -2,
      "y": 8,
      "z": -8,
      "name": "Soil_Gravel_Sand"
    },
    {
      "x": -2,
      "y": 8,
      "z": -7,
      "name": "Soil_Gravel_Sand"
    },
    {
      "x": -2,
      "y": 9,
      "z": -7,
      "name": "Rock_Sandstone_Brick_Stairs",
      "rotation": 2
    },
    {
      "x": -2,
      "y": 8,
      "z": -6,
      "name": "Soil_Gravel_Sand"
    },
    {
      "x": -2,
      "y": 9,
      "z": -6,
      "name": "Rock_Sandstone_Brick"
    },
    {
      "x": -2,
      "y": 10,
      "z": -6,
      "name": "Rock_Sandstone_Brick",
      "rotation": 3
    },
    {
      "x": -2,
      "y": 11,
      "z": -6,
      "name": "Rock_Sandstone_Brick",
      "rotation": 3
    },
    {
      "x": -2,
      "y": 12,
      "z": -6,
      "name": "Rock_Sandstone_Brick",
      "rotation": 3
    },
    {
      "x": -2,
      "y": 13,
      "z": -6,
      "name": "Rock_Sandstone_Brick",
      "rotation": 3
    },
    {
      "x": -2,
      "y": 14,
      "z": -6,
      "name": "Rock_Sandstone_Brick",
      "rotation": 3
    },
    {
      "x": -2,
      "y": 15,
      "z": -6,
      "name": "Soil_Clay_Ocean_Brick_Smooth",
      "rotation": 3
    },
    {
      "x": -2,
      "y": 8,
      "z": -5,
      "name": "Soil_Gravel_Sand"
    },
    {
      "x": -2,
      "y": 9,
      "z": -5,
      "name": "Wood_Dry_Trunk",
      "rotation": 7
    },
    {
      "x": -2,
      "y": 10,
      "z": -5,
      "name": "Rock_Sandstone_Brick",
      "rotation": 3
    },
    {
      "x": -2,
      "y": 15,
      "z": -5,
      "name": "Soil_Clay_Ocean_Brick_Smooth",
      "rotation": 3
    },
    {
      "x": -2,
      "y": 16,
      "z": -5,
      "name": "Soil_Clay_Ocean_Brick_Half",
      "rotation": 3
    },
    {
      "x": -2,
      "y": 8,
      "z": -4,
      "name": "Soil_Gravel_Sand"
    },
    {
      "x": -2,
      "y": 9,
      "z": -4,
      "name": "Rock_Sandstone_Cobble",
      "rotation": 3
    },
    {
      "x": -2,
      "y": 10,
      "z": -4,
      "name": "Rock_Sandstone_Brick",
      "rotation": 3
    },
    {
      "x": -2,
      "y": 15,
      "z": -4,
      "name": "Soil_Clay_Ocean_Brick_Smooth",
      "rotation": 3
    },
    {
      "x": -2,
      "y": 16,
      "z": -4,
      "name": "Rock_Sandstone_Brick_Smooth",
      "rotation": 3
    },
    {
      "x": -2,
      "y": 8,
      "z": -3,
      "name": "Soil_Gravel_Sand"
    },
    {
      "x": -2,
      "y": 9,
      "z": -3,
      "name": "Rock_Sandstone_Cobble",
      "rotation": 3
    },
    {
      "x": -2,
      "y": 10,
      "z": -3,
      "name": "Rock_Sandstone_Brick",
      "rotation": 3
    },
    {
      "x": -2,
      "y": 15,
      "z": -3,
      "name": "Rock_Sandstone_Brick",
      "rotation": 3
    },
    {
      "x": -2,
      "y": 16,
      "z": -3,
      "name": "Rock_Sandstone_Brick",
      "rotation": 3
    },
    {
      "x": -2,
      "y": 17,
      "z": -3,
      "name": "Soil_Clay_Ocean_Brick_Smooth",
      "rotation": 3
    },
    {
      "x": -2,
      "y": 18,
      "z": -3,
      "name": "Soil_Clay_Ocean_Brick_Smooth",
      "rotation": 3
    },
    {
      "x": -2,
      "y": 8,
      "z": -2,
      "name": "Soil_Gravel_Sand"
    },
    {
      "x": -2,
      "y": 10,
      "z": -2,
      "name": "Rock_Sandstone_Brick",
      "rotation": 3
    },
    {
      "x": -2,
      "y": 18,
      "z": -2,
      "name": "Soil_Clay_Ocean_Brick_Smooth",
      "rotation": 3
    },
    {
      "x": -2,
      "y": 19,
      "z": -2,
      "name": "Soil_Clay_Ocean_Brick_Smooth",
      "rotation": 3
    },
    {
      "x": -2,
      "y": 20,
      "z": -2,
      "name": "Rock_Sandstone_Brick_Stairs",
      "rotation": 8
    },
    {
      "x": -2,
      "y": 21,
      "z": -2,
      "name": "Rock_Sandstone_Brick_Stairs",
      "rotation": 8
    },
    {
      "x": -2,
      "y": 22,
      "z": -2,
      "name": "Rock_Sandstone_Brick_Wall",
      "rotation": 2
    },
    {
      "x": -2,
      "y": 26,
      "z": -2,
      "name": "Soil_Clay_Ocean_Brick_Roof_Hollow",
      "rotation": 2
    },
    {
      "x": -2,
      "y": 8,
      "z": -1,
      "name": "Soil_Gravel_Sand"
    },
    {
      "x": -2,
      "y": 10,
      "z": -1,
      "name": "Rock_Sandstone_Brick",
      "rotation": 3
    },
    {
      "x": -2,
      "y": 19,
      "z": -1,
      "name": "Soil_Clay_Ocean_Brick_Smooth",
      "rotation": 3
    },
    {
      "x": -2,
      "y": 20,
      "z": -1,
      "name": "Rock_Sandstone_Brick",
      "rotation": 2
    },
    {
      "x": -2,
      "y": 21,
      "z": -1,
      "name": "Rock_Sandstone_Brick",
      "rotation": 2
    },
    {
      "x": -2,
      "y": 22,
      "z": -1,
      "name": "Rock_Sandstone_Brick",
      "rotation": 2
    },
    {
      "x": -2,
      "y": 23,
      "z": -1,
      "name": "Rock_Sandstone_Brick",
      "rotation": 2
    },
    {
      "x": -2,
      "y": 24,
      "z": -1,
      "name": "Rock_Sandstone_Brick_Ornate",
      "rotation": 2
    },
    {
      "x": -2,
      "y": 25,
      "z": -1,
      "name": "Rock_Sandstone_Brick_Stairs",
      "rotation": 9
    },
    {
      "x": -2,
      "y": 26,
      "z": -1,
      "name": "Rock_Sandstone_Brick",
      "rotation": 2
    },
    {
      "x": -2,
      "y": 27,
      "z": -1,
      "name": "Soil_Clay_Ocean_Brick_Roof",
      "rotation": 2
    },
    {
      "x": -2,
      "y": 31,
      "z": -1,
      "name": "Rock_Sandstone_Brick_Smooth_Half",
      "rotation": 6
    },
    {
      "x": -2,
      "y": 32,
      "z": -1,
      "name": "Soil_Clay_Ocean_Brick_Roof_Hollow",
      "rotation": 2
    },
    {
      "x": -2,
      "y": 8,
      "z": 0,
      "name": "Soil_Gravel_Sand"
    },
    {
      "x": -2,
      "y": 10,
      "z": 0,
      "name": "Rock_Sandstone_Brick",
      "rotation": 3
    },
    {
      "x": -2,
      "y": 19,
      "z": 0,
      "name": "Soil_Clay_Ocean_Brick_Smooth",
      "rotation": 3
    },
    {
      "x": -2,
      "y": 20,
      "z": 0,
      "name": "Rock_Sandstone_Brick",
      "rotation": 2
    },
    {
      "x": -2,
      "y": 22,
      "z": 0,
      "name": "Rock_Sandstone_Brick",
      "rotation": 2
    },
    {
      "x": -2,
      "y": 23,
      "z": 0,
      "name": "Rock_Sandstone_Brick",
      "rotation": 2
    },
    {
      "x": -2,
      "y": 24,
      "z": 0,
      "name": "Rock_Sandstone_Brick_Ornate",
      "rotation": 2
    },
    {
      "x": -2,
      "y": 25,
      "z": 0,
      "name": "Rock_Sandstone_Brick",
      "rotation": 2
    },
    {
      "x": -2,
      "y": 26,
      "z": 0,
      "name": "Rock_Sandstone_Brick"
    },
    {
      "x": -2,
      "y": 27,
      "z": 0,
      "name": "Rock_Sandstone_Brick"
    },
    {
      "x": -2,
      "y": 28,
      "z": 0,
      "name": "Rock_Sandstone_Brick"
    },
    {
      "x": -2,
      "y": 29,
      "z": 0,
      "name": "Rock_Sandstone_White_Brick",
      "rotation": 2
    },
    {
      "x": -2,
      "y": 30,
      "z": 0,
      "name": "Rock_Sandstone_White_Brick",
      "rotation": 2
    },
    {
      "x": -2,
      "y": 31,
      "z": 0,
      "name": "Rock_Sandstone_Brick_Smooth",
      "rotation": 2
    },
    {
      "x": -2,
      "y": 32,
      "z": 0,
      "name": "Rock_Sandstone_Brick_Ornate",
      "rotation": 2
    },
    {
      "x": -2,
      "y": 33,
      "z": 0,
      "name": "Soil_Clay_Ocean_Brick_Ornate",
      "rotation": 2
    },
    {
      "x": -2,
      "y": 34,
      "z": 0,
      "name": "Soil_Clay_Ocean_Brick_Half",
      "rotation": 6
    },
    {
      "x": -2,
      "y": 8,
      "z": 1,
      "name": "Soil_Gravel_Sand"
    },
    {
      "x": -2,
      "y": 10,
      "z": 1,
      "name": "Rock_Sandstone_Brick",
      "rotation": 3
    },
    {
      "x": -2,
      "y": 30,
      "z": 1,
      "name": "Rock_Sandstone_Brick_Smooth",
      "rotation": 2
    },
    {
      "x": -2,
      "y": 31,
      "z": 1,
      "name": "Rock_Sandstone_Brick_Ornate",
      "rotation": 2
    },
    {
      "x": -2,
      "y": 32,
      "z": 1,
      "name": "Rock_Sandstone_Brick_Half",
      "rotation": 10
    },
    {
      "x": -2,
      "y": 33,
      "z": 1,
      "name": "Soil_Clay_Ocean_Brick_Ornate",
      "rotation": 2
    },
    {
      "x": -2,
      "y": 34,
      "z": 1,
      "name": "Soil_Clay_Ocean_Brick_Smooth",
      "rotation": 2
    },
    {
      "x": -2,
      "y": 35,
      "z": 1,
      "name": "Soil_Clay_Ocean_Brick_Smooth",
      "rotation": 2
    },
    {
      "x": -2,
      "y": 8,
      "z": 2,
      "name": "Soil_Gravel_Sand"
    },
    {
      "x": -2,
      "y": 10,
      "z": 2,
      "name": "Rock_Sandstone_Brick",
      "rotation": 3
    },
    {
      "x": -2,
      "y": 25,
      "z": 2,
      "name": "Rock_Sandstone_Brick",
      "rotation": 2
    },
    {
      "x": -2,
      "y": 26,
      "z": 2,
      "name": "Rock_Sandstone_Brick_Smooth",
      "rotation": 2
    },
    {
      "x": -2,
      "y": 8,
      "z": 3,
      "name": "Soil_Gravel_Sand"
    },
    {
      "x": -2,
      "y": 10,
      "z": 3,
      "name": "Rock_Sandstone_Brick",
      "rotation": 3
    },
    {
      "x": -2,
      "y": 19,
      "z": 3,
      "name": "Soil_Clay_Ocean_Brick_Smooth",
      "rotation": 3
    },
    {
      "x": -2,
      "y": 25,
      "z": 3,
      "name": "Rock_Sandstone_Brick",
      "rotation": 2
    },
    {
      "x": -2,
      "y": 26,
      "z": 3,
      "name": "Rock_Sandstone_Brick_Smooth",
      "rotation": 2
    },
    {
      "x": -2,
      "y": 8,
      "z": 4,
      "name": "Soil_Gravel_Sand"
    },
    {
      "x": -2,
      "y": 10,
      "z": 4,
      "name": "Rock_Sandstone_Brick",
      "rotation": 3
    },
    {
      "x": -2,
      "y": 19,
      "z": 4,
      "name": "Soil_Clay_Ocean_Brick_Smooth",
      "rotation": 3
    },
    {
      "x": -2,
      "y": 23,
      "z": 4,
      "name": "Rock_Sandstone_Brick",
      "rotation": 2
    },
    {
      "x": -2,
      "y": 24,
      "z": 4,
      "name": "Rock_Sandstone_Brick_Ornate",
      "rotation": 2
    },
    {
      "x": -2,
      "y": 25,
      "z": 4,
      "name": "Rock_Sandstone_Brick",
      "rotation": 2
    },
    {
      "x": -2,
      "y": 26,
      "z": 4,
      "name": "Rock_Sandstone_Brick",
      "rotation": 2
    },
    {
      "x": -2,
      "y": 27,
      "z": 4,
      "name": "Rock_Sandstone_Brick_Smooth",
      "rotation": 2
    },
    {
      "x": -2,
      "y": 8,
      "z": 5,
      "name": "Soil_Gravel_Sand"
    },
    {
      "x": -2,
      "y": 10,
      "z": 5,
      "name": "Rock_Sandstone_Brick",
      "rotation": 3
    },
    {
      "x": -2,
      "y": 18,
      "z": 5,
      "name": "Soil_Clay_Ocean_Brick_Smooth",
      "rotation": 3
    },
    {
      "x": -2,
      "y": 19,
      "z": 5,
      "name": "Soil_Clay_Ocean_Brick_Smooth",
      "rotation": 3
    },
    {
      "x": -2,
      "y": 23,
      "z": 5,
      "name": "Rock_Sandstone_Brick_Half",
      "rotation": 4
    },
    {
      "x": -2,
      "y": 24,
      "z": 5,
      "name": "Rock_Sandstone_Brick_Ornate",
      "rotation": 2
    },
    {
      "x": -2,
      "y": 25,
      "z": 5,
      "name": "Soil_Clay_Ocean_Brick_Smooth",
      "rotation": 2
    },
    {
      "x": -2,
      "y": 8,
      "z": 6,
      "name": "Soil_Gravel_Sand"
    },
    {
      "x": -2,
      "y": 9,
      "z": 6,
      "name": "Rock_Sandstone_Cobble",
      "rotation": 3
    },
    {
      "x": -2,
      "y": 10,
      "z": 6,
      "name": "Rock_Sandstone_Brick",
      "rotation": 3
    },
    {
      "x": -2,
      "y": 11,
      "z": 6,
      "name": "Rock_Sandstone_Brick"
    },
    {
      "x": -2,
      "y": 12,
      "z": 6,
      "name": "Rock_Sandstone_Brick"
    },
    {
      "x": -2,
      "y": 13,
      "z": 6,
      "name": "Rock_Sandstone_Brick"
    },
    {
      "x": -2,
      "y": 14,
      "z": 6,
      "name": "Rock_Sandstone_Brick"
    },
    {
      "x": -2,
      "y": 15,
      "z": 6,
      "name": "Rock_Sandstone_Brick",
      "rotation": 3
    },
    {
      "x": -2,
      "y": 16,
      "z": 6,
      "name": "Rock_Sandstone_Brick",
      "rotation": 3
    },
    {
      "x": -2,
      "y": 17,
      "z": 6,
      "name": "Soil_Clay_Ocean_Brick_Smooth",
      "rotation": 3
    },
    {
      "x": -2,
      "y": 18,
      "z": 6,
      "name": "Soil_Clay_Ocean_Brick_Smooth",
      "rotation": 3
    },
    {
      "x": -2,
      "y": 25,
      "z": 6,
      "name": "Soil_Clay_Ocean_Brick_Roof_Hollow"
    },
    {
      "x": -2,
      "y": 8,
      "z": 7,
      "name": "Soil_Gravel_Sand"
    },
    {
      "x": -2,
      "y": 9,
      "z": 7,
      "name": "Rock_Sandstone_Brick_Stairs"
    },
    {
      "x": -2,
      "y": 12,
      "z": 7,
      "name": "Rock_Sandstone_Brick_Stairs",
      "rotation": 10
    },
    {
      "x": -2,
      "y": 13,
      "z": 7,
      "name": "Rock_Sandstone_Brick"
    },
    {
      "x": -2,
      "y": 14,
      "z": 7,
      "name": "Rock_Sandstone_Brick"
    },
    {
      "x": -2,
      "y": 15,
      "z": 7,
      "name": "Soil_Clay_Ocean_Brick_Smooth",
      "rotation": 3
    },
    {
      "x": -2,
      "y": 16,
      "z": 7,
      "name": "Rock_Sandstone_Brick_Smooth",
      "rotation": 3
    },
    {
      "x": -2,
      "y": 8,
      "z": 8,
      "name": "Soil_Gravel_Sand"
    },
    {
      "x": -2,
      "y": 13,
      "z": 8,
      "name": "Rock_Sandstone_Brick_Stairs",
      "rotation": 10
    },
    {
      "x": -2,
      "y": 14,
      "z": 8,
      "name": "Rock_Sandstone_Brick"
    },
    {
      "x": -2,
      "y": 15,
      "z": 8,
      "name": "Soil_Clay_Ocean_Brick_Smooth",
      "rotation": 3
    },
    {
      "x": -2,
      "y": 16,
      "z": 8,
      "name": "Soil_Clay_Ocean_Brick_Half",
      "rotation": 3
    },
    {
      "x": -2,
      "y": 8,
      "z": 9,
      "name": "Soil_Gravel_Sand"
    },
    {
      "x": -2,
      "y": 14,
      "z": 9,
      "name": "Rock_Sandstone_Brick_Stairs",
      "rotation": 10
    },
    {
      "x": -2,
      "y": 15,
      "z": 9,
      "name": "Soil_Clay_Ocean_Brick_Smooth",
      "rotation": 3
    },
    {
      "x": -2,
      "y": 8,
      "z": 10,
      "name": "Soil_Gravel_Sand"
    },
    {
      "x": -1,
      "y": 8,
      "z": -9,
      "name": "Soil_Gravel_Sand"
    },
    {
      "x": -1,
      "y": 8,
      "z": -8,
      "name": "Soil_Gravel_Sand"
    },
    {
      "x": -1,
      "y": 8,
      "z": -7,
      "name": "Soil_Gravel_Sand"
    },
    {
      "x": -1,
      "y": 9,
      "z": -7,
      "name": "Rock_Sandstone_Brick_Stairs",
      "rotation": 2
    },
    {
      "x": -1,
      "y": 8,
      "z": -6,
      "name": "Soil_Gravel_Sand"
    },
    {
      "x": -1,
      "y": 9,
      "z": -6,
      "name": "Rock_Sandstone_Brick"
    },
    {
      "x": -1,
      "y": 10,
      "z": -6,
      "name": "Rock_Sandstone_Brick",
      "rotation": 3
    },
    {
      "x": -1,
      "y": 11,
      "z": -6,
      "name": "Rock_Sandstone_Brick",
      "rotation": 3
    },
    {
      "x": -1,
      "y": 12,
      "z": -6,
      "name": "Rock_Sandstone_Brick",
      "rotation": 3
    },
    {
      "x": -1,
      "y": 13,
      "z": -6,
      "name": "Rock_Sandstone_Brick",
      "rotation": 3
    },
    {
      "x": -1,
      "y": 14,
      "z": -6,
      "name": "Rock_Sandstone_Brick",
      "rotation": 3
    },
    {
      "x": -1,
      "y": 15,
      "z": -6,
      "name": "Soil_Clay_Ocean_Brick_Smooth",
      "rotation": 3
    },
    {
      "x": -1,
      "y": 16,
      "z": -6,
      "name": "Soil_Clay_Ocean_Brick_Half",
      "rotation": 3
    },
    {
      "x": -1,
      "y": 8,
      "z": -5,
      "name": "Soil_Gravel_Sand"
    },
    {
      "x": -1,
      "y": 9,
      "z": -5,
      "name": "Wood_Dry_Trunk",
      "rotation": 7
    },
    {
      "x": -1,
      "y": 10,
      "z": -5,
      "name": "Rock_Sandstone_Brick",
      "rotation": 3
    },
    {
      "x": -1,
      "y": 15,
      "z": -5,
      "name": "Soil_Clay_Ocean_Brick_Smooth",
      "rotation": 3
    },
    {
      "x": -1,
      "y": 16,
      "z": -5,
      "name": "Rock_Sandstone_Brick_Smooth",
      "rotation": 3
    },
    {
      "x": -1,
      "y": 8,
      "z": -4,
      "name": "Soil_Gravel_Sand"
    },
    {
      "x": -1,
      "y": 9,
      "z": -4,
      "name": "Rock_Sandstone_Cobble",
      "rotation": 3
    },
    {
      "x": -1,
      "y": 10,
      "z": -4,
      "name": "Rock_Sandstone_Brick",
      "rotation": 3
    },
    {
      "x": -1,
      "y": 15,
      "z": -4,
      "name": "Rock_Sandstone_Brick",
      "rotation": 3
    },
    {
      "x": -1,
      "y": 16,
      "z": -4,
      "name": "Rock_Sandstone_Brick",
      "rotation": 3
    },
    {
      "x": -1,
      "y": 17,
      "z": -4,
      "name": "Soil_Clay_Ocean_Brick_Smooth",
      "rotation": 3
    },
    {
      "x": -1,
      "y": 8,
      "z": -3,
      "name": "Soil_Gravel_Sand"
    },
    {
      "x": -1,
      "y": 10,
      "z": -3,
      "name": "Rock_Sandstone_Brick",
      "rotation": 3
    },
    {
      "x": -1,
      "y": 18,
      "z": -3,
      "name": "Soil_Clay_Ocean_Brick_Smooth",
      "rotation": 3
    },
    {
      "x": -1,
      "y": 8,
      "z": -2,
      "name": "Soil_Gravel_Sand"
    },
    {
      "x": -1,
      "y": 10,
      "z": -2,
      "name": "Rock_Sandstone_Brick",
      "rotation": 3
    },
    {
      "x": -1,
      "y": 18,
      "z": -2,
      "name": "Soil_Clay_Ocean_Brick_Smooth",
      "rotation": 3
    },
    {
      "x": -1,
      "y": 19,
      "z": -2,
      "name": "Soil_Clay_Ocean_Brick_Smooth",
      "rotation": 3
    },
    {
      "x": -1,
      "y": 20,
      "z": -2,
      "name": "Rock_Sandstone_Brick_Stairs",
      "rotation": 8
    },
    {
      "x": -1,
      "y": 21,
      "z": -2,
      "name": "Rock_Sandstone_Brick_Stairs",
      "rotation": 8
    },
    {
      "x": -1,
      "y": 22,
      "z": -2,
      "name": "Rock_Sandstone_Brick_Wall",
      "rotation": 2
    },
    {
      "x": -1,
      "y": 25,
      "z": -2,
      "name": "Soil_Clay_Ocean_Brick_Half",
      "rotation": 6
    },
    {
      "x": -1,
      "y": 26,
      "z": -2,
      "name": "Soil_Clay_Ocean_Brick_Roof_Hollow",
      "rotation": 2
    },
    {
      "x": -1,
      "y": 8,
      "z": -1,
      "name": "Soil_Gravel_Sand"
    },
    {
      "x": -1,
      "y": 10,
      "z": -1,
      "name": "Rock_Sandstone_Brick",
      "rotation": 3
    },
    {
      "x": -1,
      "y": 19,
      "z": -1,
      "name": "Soil_Clay_Ocean_Brick_Smooth",
      "rotation": 3
    },
    {
      "x": -1,
      "y": 20,
      "z": -1,
      "name": "Rock_Sandstone_Brick",
      "rotation": 2
    },
    {
      "x": -1,
      "y": 21,
      "z": -1,
      "name": "Rock_Sandstone_Brick",
      "rotation": 2
    },
    {
      "x": -1,
      "y": 22,
      "z": -1,
      "name": "Rock_Sandstone_Brick",
      "rotation": 2
    },
    {
      "x": -1,
      "y": 23,
      "z": -1,
      "name": "Rock_Sandstone_Brick",
      "rotation": 2
    },
    {
      "x": -1,
      "y": 24,
      "z": -1,
      "name": "Rock_Sandstone_Brick",
      "rotation": 2
    },
    {
      "x": -1,
      "y": 25,
      "z": -1,
      "name": "Rock_Sandstone_Brick_Ornate",
      "rotation": 2
    },
    {
      "x": -1,
      "y": 26,
      "z": -1,
      "name": "Soil_Clay_Ocean_Brick_Smooth",
      "rotation": 2
    },
    {
      "x": -1,
      "y": 27,
      "z": -1,
      "name": "Soil_Clay_Ocean_Brick_Roof",
      "rotation": 2
    },
    {
      "x": -1,
      "y": 30,
      "z": -1,
      "name": "Rock_Sandstone_Brick_Smooth_Half",
      "rotation": 6
    },
    {
      "x": -1,
      "y": 31,
      "z": -1,
      "name": "Soil_Clay_Ocean_Brick_Roof_Hollow",
      "rotation": 2
    },
    {
      "x": -1,
      "y": 32,
      "z": -1,
      "name": "Soil_Clay_Ocean_Brick_Roof_Hollow",
      "rotation": 2
    },
    {
      "x": -1,
      "y": 8,
      "z": 0,
      "name": "Soil_Gravel_Sand"
    },
    {
      "x": -1,
      "y": 10,
      "z": 0,
      "name": "Rock_Sandstone_Brick",
      "rotation": 3
    },
    {
      "x": -1,
      "y": 21,
      "z": 0,
      "name": "Rock_Sandstone_Brick",
      "rotation": 2
    },
    {
      "x": -1,
      "y": 22,
      "z": 0,
      "name": "Rock_Sandstone_Brick",
      "rotation": 2
    },
    {
      "x": -1,
      "y": 23,
      "z": 0,
      "name": "Rock_Sandstone_Brick",
      "rotation": 2
    },
    {
      "x": -1,
      "y": 24,
      "z": 0,
      "name": "Rock_Sandstone_Brick",
      "rotation": 2
    },
    {
      "x": -1,
      "y": 25,
      "z": 0,
      "name": "Rock_Sandstone_Brick_Ornate",
      "rotation": 2
    },
    {
      "x": -1,
      "y": 28,
      "z": 0,
      "name": "Rock_Sandstone_Brick"
    },
    {
      "x": -1,
      "y": 29,
      "z": 0,
      "name": "Rock_Sandstone_White_Brick",
      "rotation": 2
    },
    {
      "x": -1,
      "y": 30,
      "z": 0,
      "name": "Rock_Sandstone_Brick_Smooth",
      "rotation": 2
    },
    {
      "x": -1,
      "y": 31,
      "z": 0,
      "name": "Rock_Sandstone_Brick_Smooth",
      "rotation": 2
    },
    {
      "x": -1,
      "y": 32,
      "z": 0,
      "name": "Rock_Sandstone_Brick_Ornate",
      "rotation": 2
    },
    {
      "x": -1,
      "y": 33,
      "z": 0,
      "name": "*Soil_Clay_Ocean_Brick_Roof_State_Definitions_Corner_Right",
      "rotation": 2
    },
    {
      "x": -1,
      "y": 34,
      "z": 0,
      "name": "Soil_Clay_Ocean_Brick_Half",
      "rotation": 6
    },
    {
      "x": -1,
      "y": 8,
      "z": 1,
      "name": "Soil_Gravel_Sand"
    },
    {
      "x": -1,
      "y": 10,
      "z": 1,
      "name": "Rock_Sandstone_Brick",
      "rotation": 3
    },
    {
      "x": -1,
      "y": 30,
      "z": 1,
      "name": "Rock_Sandstone_White_Brick",
      "rotation": 2
    },
    {
      "x": -1,
      "y": 31,
      "z": 1,
      "name": "Rock_Sandstone_Brick_Smooth",
      "rotation": 2
    },
    {
      "x": -1,
      "y": 32,
      "z": 1,
      "name": "Rock_Sandstone_Brick_Ornate",
      "rotation": 2
    },
    {
      "x": -1,
      "y": 33,
      "z": 1,
      "name": "Soil_Clay_Ocean_Brick_Ornate",
      "rotation": 2
    },
    {
      "x": -1,
      "y": 34,
      "z": 1,
      "name": "Soil_Clay_Ocean_Brick_Half",
      "rotation": 5
    },
    {
      "x": -1,
      "y": 35,
      "z": 1,
      "name": "Soil_Clay_Ocean_Brick_Half",
      "rotation": 5
    },
    {
      "x": -1,
      "y": 8,
      "z": 2,
      "name": "Soil_Gravel_Sand"
    },
    {
      "x": -1,
      "y": 10,
      "z": 2,
      "name": "Rock_Sandstone_Brick",
      "rotation": 3
    },
    {
      "x": -1,
      "y": 8,
      "z": 3,
      "name": "Soil_Gravel_Sand"
    },
    {
      "x": -1,
      "y": 10,
      "z": 3,
      "name": "Rock_Sandstone_Brick",
      "rotation": 3
    },
    {
      "x": -1,
      "y": 8,
      "z": 4,
      "name": "Soil_Gravel_Sand"
    },
    {
      "x": -1,
      "y": 9,
      "z": 4,
      "name": "Rock_Sandstone_Brick"
    },
    {
      "x": -1,
      "y": 10,
      "z": 4,
      "name": "Rock_Sandstone_Brick",
      "rotation": 3
    },
    {
      "x": -1,
      "y": 19,
      "z": 4,
      "name": "Soil_Clay_Ocean_Brick_Smooth",
      "rotation": 3
    },
    {
      "x": -1,
      "y": 21,
      "z": 4,
      "name": "Rock_Sandstone_Brick",
      "rotation": 2
    },
    {
      "x": -1,
      "y": 22,
      "z": 4,
      "name": "Rock_Sandstone_Brick",
      "rotation": 2
    },
    {
      "x": -1,
      "y": 23,
      "z": 4,
      "name": "Rock_Sandstone_Brick",
      "rotation": 2
    },
    {
      "x": -1,
      "y": 24,
      "z": 4,
      "name": "Rock_Sandstone_Brick",
      "rotation": 2
    },
    {
      "x": -1,
      "y": 25,
      "z": 4,
      "name": "Rock_Sandstone_Brick_Ornate",
      "rotation": 2
    },
    {
      "x": -1,
      "y": 26,
      "z": 4,
      "name": "Rock_Sandstone_Brick",
      "rotation": 2
    },
    {
      "x": -1,
      "y": 27,
      "z": 4,
      "name": "Rock_Sandstone_Brick_Smooth",
      "rotation": 2
    },
    {
      "x": -1,
      "y": 28,
      "z": 4,
      "name": "Rock_Sandstone_Brick_Smooth_Half",
      "rotation": 2
    },
    {
      "x": -1,
      "y": 8,
      "z": 5,
      "name": "Soil_Gravel_Sand"
    },
    {
      "x": -1,
      "y": 10,
      "z": 5,
      "name": "Rock_Sandstone_Brick",
      "rotation": 3
    },
    {
      "x": -1,
      "y": 18,
      "z": 5,
      "name": "Soil_Clay_Ocean_Brick_Smooth",
      "rotation": 3
    },
    {
      "x": -1,
      "y": 19,
      "z": 5,
      "name": "Soil_Clay_Ocean_Brick_Smooth",
      "rotation": 3
    },
    {
      "x": -1,
      "y": 22,
      "z": 5,
      "name": "Rock_Sandstone_Brick_Half",
      "rotation": 4
    },
    {
      "x": -1,
      "y": 23,
      "z": 5,
      "name": "Rock_Sandstone_Brick",
      "rotation": 2
    },
    {
      "x": -1,
      "y": 24,
      "z": 5,
      "name": "Rock_Sandstone_Brick",
      "rotation": 2
    },
    {
      "x": -1,
      "y": 25,
      "z": 5,
      "name": "Rock_Sandstone_Brick_Ornate",
      "rotation": 2
    },
    {
      "x": -1,
      "y": 26,
      "z": 5,
      "name": "Soil_Clay_Ocean_Brick_Smooth",
      "rotation": 2
    },
    {
      "x": -1,
      "y": 8,
      "z": 6,
      "name": "Soil_Gravel_Sand"
    },
    {
      "x": -1,
      "y": 9,
      "z": 6,
      "name": "Rock_Sandstone_Brick"
    },
    {
      "x": -1,
      "y": 10,
      "z": 6,
      "name": "Rock_Sandstone_Brick"
    },
    {
      "x": -1,
      "y": 11,
      "z": 6,
      "name": "Rock_Sandstone_Brick"
    },
    {
      "x": -1,
      "y": 12,
      "z": 6,
      "name": "Rock_Sandstone_Brick"
    },
    {
      "x": -1,
      "y": 13,
      "z": 6,
      "name": "Rock_Sandstone_Brick"
    },
    {
      "x": -1,
      "y": 14,
      "z": 6,
      "name": "Rock_Sandstone_Brick"
    },
    {
      "x": -1,
      "y": 18,
      "z": 6,
      "name": "Soil_Clay_Ocean_Brick_Smooth",
      "rotation": 3
    },
    {
      "x": -1,
      "y": 25,
      "z": 6,
      "name": "Soil_Clay_Ocean_Brick_Roof_Hollow"
    },
    {
      "x": -1,
      "y": 8,
      "z": 7,
      "name": "Soil_Gravel_Sand"
    },
    {
      "x": -1,
      "y": 9,
      "z": 7,
      "name": "Rock_Sandstone_Brick_Stairs"
    },
    {
      "x": -1,
      "y": 12,
      "z": 7,
      "name": "Rock_Sandstone_Brick_Stairs",
      "rotation": 10
    },
    {
      "x": -1,
      "y": 13,
      "z": 7,
      "name": "Rock_Sandstone_Brick"
    },
    {
      "x": -1,
      "y": 14,
      "z": 7,
      "name": "Rock_Sandstone_Brick"
    },
    {
      "x": -1,
      "y": 15,
      "z": 7,
      "name": "Rock_Sandstone_Brick",
      "rotation": 3
    },
    {
      "x": -1,
      "y": 16,
      "z": 7,
      "name": "Rock_Sandstone_Brick",
      "rotation": 3
    },
    {
      "x": -1,
      "y": 17,
      "z": 7,
      "name": "Soil_Clay_Ocean_Brick_Smooth",
      "rotation": 3
    },
    {
      "x": -1,
      "y": 8,
      "z": 8,
      "name": "Soil_Gravel_Sand"
    },
    {
      "x": -1,
      "y": 13,
      "z": 8,
      "name": "Rock_Sandstone_Brick_Stairs",
      "rotation": 10
    },
    {
      "x": -1,
      "y": 14,
      "z": 8,
      "name": "Rock_Sandstone_Brick"
    },
    {
      "x": -1,
      "y": 15,
      "z": 8,
      "name": "Soil_Clay_Ocean_Brick_Smooth",
      "rotation": 3
    },
    {
      "x": -1,
      "y": 16,
      "z": 8,
      "name": "Rock_Sandstone_Brick_Smooth",
      "rotation": 3
    },
    {
      "x": -1,
      "y": 8,
      "z": 9,
      "name": "Soil_Gravel_Sand"
    },
    {
      "x": -1,
      "y": 14,
      "z": 9,
      "name": "Rock_Sandstone_Brick_Stairs",
      "rotation": 10
    },
    {
      "x": -1,
      "y": 15,
      "z": 9,
      "name": "Soil_Clay_Ocean_Brick_Smooth",
      "rotation": 3
    },
    {
      "x": -1,
      "y": 16,
      "z": 9,
      "name": "Soil_Clay_Ocean_Brick_Half",
      "rotation": 3
    },
    {
      "x": -1,
      "y": 8,
      "z": 10,
      "name": "Soil_Gravel_Sand"
    },
    {
      "x": 0,
      "y": 8,
      "z": -9,
      "name": "Soil_Gravel_Sand"
    },
    {
      "x": 0,
      "y": 8,
      "z": -8,
      "name": "Soil_Gravel_Sand"
    },
    {
      "x": 0,
      "y": 8,
      "z": -7,
      "name": "Soil_Gravel_Sand"
    },
    {
      "x": 0,
      "y": 9,
      "z": -7,
      "name": "Rock_Sandstone_Brick_Stairs",
      "rotation": 2
    },
    {
      "x": 0,
      "y": 8,
      "z": -6,
      "name": "Soil_Gravel_Sand"
    },
    {
      "x": 0,
      "y": 9,
      "z": -6,
      "name": "Rock_Sandstone_Brick"
    },
    {
      "x": 0,
      "y": 10,
      "z": -6,
      "name": "Rock_Sandstone_Brick_Stairs",
      "rotation": 2
    },
    {
      "x": 0,
      "y": 13,
      "z": -6,
      "name": "Rock_Sandstone_Brick_Stairs",
      "rotation": 11
    },
    {
      "x": 0,
      "y": 14,
      "z": -6,
      "name": "Rock_Sandstone_Brick",
      "rotation": 3
    },
    {
      "x": 0,
      "y": 15,
      "z": -6,
      "name": "Soil_Clay_Ocean_Brick_Smooth",
      "rotation": 3
    },
    {
      "x": 0,
      "y": 16,
      "z": -6,
      "name": "Soil_Clay_Ocean_Brick_Half",
      "rotation": 3
    },
    {
      "x": 0,
      "y": 8,
      "z": -5,
      "name": "Soil_Gravel_Sand"
    },
    {
      "x": 0,
      "y": 9,
      "z": -5,
      "name": "Wood_Dry_Trunk",
      "rotation": 7
    },
    {
      "x": 0,
      "y": 10,
      "z": -5,
      "name": "Rock_Sandstone_Brick"
    },
    {
      "x": 0,
      "y": 15,
      "z": -5,
      "name": "Soil_Clay_Ocean_Brick_Smooth",
      "rotation": 3
    },
    {
      "x": 0,
      "y": 16,
      "z": -5,
      "name": "Rock_Sandstone_Brick_Smooth",
      "rotation": 3
    },
    {
      "x": 0,
      "y": 8,
      "z": -4,
      "name": "Soil_Gravel_Sand"
    },
    {
      "x": 0,
      "y": 9,
      "z": -4,
      "name": "Rock_Sandstone_Cobble",
      "rotation": 3
    },
    {
      "x": 0,
      "y": 10,
      "z": -4,
      "name": "Rock_Sandstone_Brick",
      "rotation": 3
    },
    {
      "x": 0,
      "y": 15,
      "z": -4,
      "name": "Rock_Sandstone_Brick",
      "rotation": 3
    },
    {
      "x": 0,
      "y": 16,
      "z": -4,
      "name": "Rock_Sandstone_Brick",
      "rotation": 3
    },
    {
      "x": 0,
      "y": 17,
      "z": -4,
      "name": "Soil_Clay_Ocean_Brick_Smooth",
      "rotation": 3
    },
    {
      "x": 0,
      "y": 18,
      "z": -4,
      "name": "Soil_Clay_Ocean_Brick_Smooth",
      "rotation": 3
    },
    {
      "x": 0,
      "y": 8,
      "z": -3,
      "name": "Soil_Gravel_Sand"
    },
    {
      "x": 0,
      "y": 10,
      "z": -3,
      "name": "Rock_Sandstone_Brick",
      "rotation": 3
    },
    {
      "x": 0,
      "y": 18,
      "z": -3,
      "name": "Soil_Clay_Ocean_Brick_Smooth",
      "rotation": 3
    },
    {
      "x": 0,
      "y": 19,
      "z": -3,
      "name": "Soil_Clay_Ocean_Brick_Smooth",
      "rotation": 3
    },
    {
      "x": 0,
      "y": 8,
      "z": -2,
      "name": "Soil_Gravel_Sand"
    },
    {
      "x": 0,
      "y": 10,
      "z": -2,
      "name": "Rock_Sandstone_Brick",
      "rotation": 3
    },
    {
      "x": 0,
      "y": 19,
      "z": -2,
      "name": "Soil_Clay_Ocean_Brick_Smooth",
      "rotation": 3
    },
    {
      "x": 0,
      "y": 20,
      "z": -2,
      "name": "Rock_Sandstone_Brick_Stairs",
      "rotation": 8
    },
    {
      "x": 0,
      "y": 21,
      "z": -2,
      "name": "Rock_Sandstone_Brick_Stairs",
      "rotation": 8
    },
    {
      "x": 0,
      "y": 22,
      "z": -2,
      "name": "Rock_Sandstone_Brick_Wall",
      "rotation": 2
    },
    {
      "x": 0,
      "y": 25,
      "z": -2,
      "name": "Soil_Clay_Ocean_Brick_Roof_Hollow",
      "rotation": 2
    },
    {
      "x": 0,
      "y": 8,
      "z": -1,
      "name": "Soil_Gravel_Sand"
    },
    {
      "x": 0,
      "y": 10,
      "z": -1,
      "name": "Rock_Sandstone_Brick",
      "rotation": 3
    },
    {
      "x": 0,
      "y": 19,
      "z": -1,
      "name": "Rock_Sandstone_Brick"
    },
    {
      "x": 0,
      "y": 20,
      "z": -1,
      "name": "Rock_Sandstone_Brick",
      "rotation": 2
    },
    {
      "x": 0,
      "y": 21,
      "z": -1,
      "name": "Rock_Sandstone_Brick",
      "rotation": 2
    },
    {
      "x": 0,
      "y": 24,
      "z": -1,
      "name": "Rock_Sandstone_Brick_Smooth_Half",
      "rotation": 10
    },
    {
      "x": 0,
      "y": 25,
      "z": -1,
      "name": "Rock_Sandstone_Brick_Ornate",
      "rotation": 2
    },
    {
      "x": 0,
      "y": 26,
      "z": -1,
      "name": "Rock_Sandstone_Brick"
    },
    {
      "x": 0,
      "y": 27,
      "z": -1,
      "name": "Rock_Sandstone_Brick"
    },
    {
      "x": 0,
      "y": 28,
      "z": -1,
      "name": "Rock_Sandstone_Brick"
    },
    {
      "x": 0,
      "y": 30,
      "z": -1,
      "name": "Rock_Sandstone_Brick_Smooth_Half",
      "rotation": 6
    },
    {
      "x": 0,
      "y": 31,
      "z": -1,
      "name": "Soil_Clay_Ocean_Brick_Roof_Hollow",
      "rotation": 2
    },
    {
      "x": 0,
      "y": 32,
      "z": -1,
      "name": "*Soil_Clay_Ocean_Brick_Roof_Hollow_State_Definitions_Corner_Right",
      "rotation": 2
    },
    {
      "x": 0,
      "y": 8,
      "z": 0,
      "name": "Soil_Gravel_Sand"
    },
    {
      "x": 0,
      "y": 10,
      "z": 0,
      "name": "Rock_Sandstone_Brick",
      "rotation": 3
    },
    {
      "x": 0,
      "y": 19,
      "z": 0,
      "name": "Rock_Sandstone_Brick"
    },
    {
      "x": 0,
      "y": 21,
      "z": 0,
      "name": "Rock_Sandstone_Brick",
      "rotation": 2
    },
    {
      "x": 0,
      "y": 22,
      "z": 0,
      "name": "Rock_Sandstone_Brick",
      "rotation": 2
    },
    {
      "x": 0,
      "y": 23,
      "z": 0,
      "name": "Rock_Sandstone_Brick",
      "rotation": 2
    },
    {
      "x": 0,
      "y": 24,
      "z": 0,
      "name": "Rock_Sandstone_Brick",
      "rotation": 2
    },
    {
      "x": 0,
      "y": 25,
      "z": 0,
      "name": "Rock_Sandstone_Brick_Ornate",
      "rotation": 2
    },
    {
      "x": 0,
      "y": 29,
      "z": 0,
      "name": "Furniture_Desert_Window",
      "rotation": 2
    },
    {
      "x": 0,
      "y": 30,
      "z": 0,
      "name": "Rock_Sandstone_Brick_Smooth",
      "rotation": 2
    },
    {
      "x": 0,
      "y": 31,
      "z": 0,
      "name": "Rock_Sandstone_Brick_Ornate",
      "rotation": 2
    },
    {
      "x": 0,
      "y": 32,
      "z": 0,
      "name": "Soil_Clay_Ocean_Brick_Roof",
      "rotation": 1
    },
    {
      "x": 0,
      "y": 33,
      "z": 0,
      "name": "Soil_Clay_Ocean_Brick_Smooth",
      "rotation": 2
    },
    {
      "x": 0,
      "y": 34,
      "z": 0,
      "name": "Soil_Clay_Ocean_Brick_Half",
      "rotation": 6
    },
    {
      "x": 0,
      "y": 8,
      "z": 1,
      "name": "Soil_Gravel_Sand"
    },
    {
      "x": 0,
      "y": 10,
      "z": 1,
      "name": "Rock_Sandstone_Brick",
      "rotation": 3
    },
    {
      "x": 0,
      "y": 19,
      "z": 1,
      "name": "Rock_Sandstone_Brick"
    },
    {
      "x": 0,
      "y": 21,
      "z": 1,
      "name": "Rock_Sandstone_Brick",
      "rotation": 2
    },
    {
      "x": 0,
      "y": 22,
      "z": 1,
      "name": "Furniture_Village_Pot",
      "rotation": 2
    },
    {
      "x": 0,
      "y": 31,
      "z": 1,
      "name": "Rock_Sandstone_Brick_Smooth_Half",
      "rotation": 5
    },
    {
      "x": 0,
      "y": 8,
      "z": 2,
      "name": "Soil_Gravel_Sand"
    },
    {
      "x": 0,
      "y": 10,
      "z": 2,
      "name": "Rock_Sandstone_Brick",
      "rotation": 3
    },
    {
      "x": 0,
      "y": 19,
      "z": 2,
      "name": "Rock_Sandstone_Brick"
    },
    {
      "x": 0,
      "y": 21,
      "z": 2,
      "name": "Rock_Sandstone_Brick",
      "rotation": 2
    },
    {
      "x": 0,
      "y": 8,
      "z": 3,
      "name": "Soil_Gravel_Sand"
    },
    {
      "x": 0,
      "y": 10,
      "z": 3,
      "name": "Rock_Sandstone_Brick",
      "rotation": 3
    },
    {
      "x": 0,
      "y": 19,
      "z": 3,
      "name": "Rock_Sandstone_Brick"
    },
    {
      "x": 0,
      "y": 21,
      "z": 3,
      "name": "Rock_Sandstone_Brick",
      "rotation": 2
    },
    {
      "x": 0,
      "y": 22,
      "z": 3,
      "name": "Furniture_Ancient_Pot",
      "rotation": 2
    },
    {
      "x": 0,
      "y": 8,
      "z": 4,
      "name": "Soil_Gravel_Sand"
    },
    {
      "x": 0,
      "y": 10,
      "z": 4,
      "name": "Rock_Sandstone_Brick",
      "rotation": 3
    },
    {
      "x": 0,
      "y": 19,
      "z": 4,
      "name": "Rock_Sandstone_Brick"
    },
    {
      "x": 0,
      "y": 21,
      "z": 4,
      "name": "Rock_Sandstone_Brick",
      "rotation": 2
    },
    {
      "x": 0,
      "y": 22,
      "z": 4,
      "name": "Rock_Sandstone_Brick",
      "rotation": 2
    },
    {
      "x": 0,
      "y": 23,
      "z": 4,
      "name": "Rock_Sandstone_Brick",
      "rotation": 2
    },
    {
      "x": 0,
      "y": 24,
      "z": 4,
      "name": "Rock_Sandstone_Brick",
      "rotation": 2
    },
    {
      "x": 0,
      "y": 25,
      "z": 4,
      "name": "Rock_Sandstone_Brick_Ornate",
      "rotation": 2
    },
    {
      "x": 0,
      "y": 26,
      "z": 4,
      "name": "Soil_Clay_Ocean_Brick_Smooth",
      "rotation": 2
    },
    {
      "x": 0,
      "y": 8,
      "z": 5,
      "name": "Soil_Gravel_Sand"
    },
    {
      "x": 0,
      "y": 10,
      "z": 5,
      "name": "Rock_Sandstone_Brick",
      "rotation": 3
    },
    {
      "x": 0,
      "y": 19,
      "z": 5,
      "name": "Soil_Clay_Ocean_Brick_Smooth",
      "rotation": 3
    },
    {
      "x": 0,
      "y": 24,
      "z": 5,
      "name": "Rock_Sandstone_Brick_Smooth_Half",
      "rotation": 10
    },
    {
      "x": 0,
      "y": 25,
      "z": 5,
      "name": "Rock_Sandstone_Brick_Ornate",
      "rotation": 2
    },
    {
      "x": 0,
      "y": 26,
      "z": 5,
      "name": "Soil_Clay_Ocean_Brick_Half",
      "rotation": 4
    },
    {
      "x": 0,
      "y": 8,
      "z": 6,
      "name": "Soil_Gravel_Sand"
    },
    {
      "x": 0,
      "y": 9,
      "z": 6,
      "name": "Rock_Sandstone_Brick"
    },
    {
      "x": 0,
      "y": 10,
      "z": 6,
      "name": "Rock_Sandstone_Brick",
      "rotation": 3
    },
    {
      "x": 0,
      "y": 11,
      "z": 6,
      "name": "Rock_Sandstone_Brick"
    },
    {
      "x": 0,
      "y": 12,
      "z": 6,
      "name": "Rock_Sandstone_Brick"
    },
    {
      "x": 0,
      "y": 13,
      "z": 6,
      "name": "Rock_Sandstone_Brick"
    },
    {
      "x": 0,
      "y": 14,
      "z": 6,
      "name": "Rock_Sandstone_Brick"
    },
    {
      "x": 0,
      "y": 18,
      "z": 6,
      "name": "Soil_Clay_Ocean_Brick_Smooth",
      "rotation": 3
    },
    {
      "x": 0,
      "y": 19,
      "z": 6,
      "name": "Soil_Clay_Ocean_Brick_Smooth",
      "rotation": 3
    },
    {
      "x": 0,
      "y": 25,
      "z": 6,
      "name": "Soil_Clay_Ocean_Brick_Half",
      "rotation": 4
    },
    {
      "x": 0,
      "y": 8,
      "z": 7,
      "name": "Soil_Gravel_Sand"
    },
    {
      "x": 0,
      "y": 9,
      "z": 7,
      "name": "Rock_Sandstone_Brick_Stairs"
    },
    {
      "x": 0,
      "y": 12,
      "z": 7,
      "name": "Rock_Sandstone_Brick_Stairs",
      "rotation": 10
    },
    {
      "x": 0,
      "y": 13,
      "z": 7,
      "name": "Rock_Sandstone_Brick"
    },
    {
      "x": 0,
      "y": 14,
      "z": 7,
      "name": "Rock_Sandstone_Brick"
    },
    {
      "x": 0,
      "y": 15,
      "z": 7,
      "name": "Rock_Sandstone_Brick",
      "rotation": 3
    },
    {
      "x": 0,
      "y": 16,
      "z": 7,
      "name": "Rock_Sandstone_Brick_Half",
      "rotation": 3
    },
    {
      "x": 0,
      "y": 18,
      "z": 7,
      "name": "Soil_Clay_Ocean_Brick_Smooth",
      "rotation": 3
    },
    {
      "x": 0,
      "y": 8,
      "z": 8,
      "name": "Soil_Gravel_Sand"
    },
    {
      "x": 0,
      "y": 13,
      "z": 8,
      "name": "Rock_Sandstone_Brick_Stairs",
      "rotation": 10
    },
    {
      "x": 0,
      "y": 14,
      "z": 8,
      "name": "Rock_Sandstone_Brick"
    },
    {
      "x": 0,
      "y": 15,
      "z": 8,
      "name": "Soil_Clay_Ocean_Brick_Smooth",
      "rotation": 3
    },
    {
      "x": 0,
      "y": 16,
      "z": 8,
      "name": "Rock_Sandstone_Brick_Smooth",
      "rotation": 3
    },
    {
      "x": 0,
      "y": 8,
      "z": 9,
      "name": "Soil_Gravel_Sand"
    },
    {
      "x": 0,
      "y": 14,
      "z": 9,
      "name": "Rock_Sandstone_Brick_Stairs",
      "rotation": 10
    },
    {
      "x": 0,
      "y": 15,
      "z": 9,
      "name": "Soil_Clay_Ocean_Brick_Smooth",
      "rotation": 3
    },
    {
      "x": 0,
      "y": 16,
      "z": 9,
      "name": "Soil_Clay_Ocean_Brick_Half",
      "rotation": 3
    },
    {
      "x": 0,
      "y": 8,
      "z": 10,
      "name": "Soil_Gravel_Sand"
    },
    {
      "x": 1,
      "y": 8,
      "z": -9,
      "name": "Soil_Gravel_Sand"
    },
    {
      "x": 1,
      "y": 8,
      "z": -8,
      "name": "Soil_Gravel_Sand"
    },
    {
      "x": 1,
      "y": 8,
      "z": -7,
      "name": "Soil_Gravel_Sand"
    },
    {
      "x": 1,
      "y": 9,
      "z": -7,
      "name": "Rock_Sandstone_Brick_Stairs",
      "rotation": 2
    },
    {
      "x": 1,
      "y": 8,
      "z": -6,
      "name": "Soil_Gravel_Sand"
    },
    {
      "x": 1,
      "y": 9,
      "z": -6,
      "name": "Rock_Sandstone_Brick"
    },
    {
      "x": 1,
      "y": 10,
      "z": -6,
      "name": "Rock_Sandstone_Brick_Stairs",
      "rotation": 2
    },
    {
      "x": 1,
      "y": 13,
      "z": -6,
      "name": "Rock_Sandstone_Brick_Stairs",
      "rotation": 9
    },
    {
      "x": 1,
      "y": 14,
      "z": -6,
      "name": "Rock_Sandstone_Brick",
      "rotation": 3
    },
    {
      "x": 1,
      "y": 15,
      "z": -6,
      "name": "Soil_Clay_Ocean_Brick_Smooth",
      "rotation": 3
    },
    {
      "x": 1,
      "y": 16,
      "z": -6,
      "name": "Soil_Clay_Ocean_Brick_Half",
      "rotation": 3
    },
    {
      "x": 1,
      "y": 8,
      "z": -5,
      "name": "Soil_Gravel_Sand"
    },
    {
      "x": 1,
      "y": 9,
      "z": -5,
      "name": "Wood_Dry_Trunk",
      "rotation": 7
    },
    {
      "x": 1,
      "y": 10,
      "z": -5,
      "name": "Rock_Sandstone_Brick"
    },
    {
      "x": 1,
      "y": 15,
      "z": -5,
      "name": "Soil_Clay_Ocean_Brick_Smooth",
      "rotation": 3
    },
    {
      "x": 1,
      "y": 16,
      "z": -5,
      "name": "Rock_Sandstone_Brick_Smooth",
      "rotation": 3
    },
    {
      "x": 1,
      "y": 8,
      "z": -4,
      "name": "Soil_Gravel_Sand"
    },
    {
      "x": 1,
      "y": 9,
      "z": -4,
      "name": "Rock_Sandstone_Cobble",
      "rotation": 3
    },
    {
      "x": 1,
      "y": 10,
      "z": -4,
      "name": "Rock_Sandstone_Brick",
      "rotation": 3
    },
    {
      "x": 1,
      "y": 15,
      "z": -4,
      "name": "Rock_Sandstone_Brick",
      "rotation": 3
    },
    {
      "x": 1,
      "y": 16,
      "z": -4,
      "name": "Rock_Sandstone_Brick",
      "rotation": 3
    },
    {
      "x": 1,
      "y": 17,
      "z": -4,
      "name": "Soil_Clay_Ocean_Brick_Smooth",
      "rotation": 3
    },
    {
      "x": 1,
      "y": 18,
      "z": -4,
      "name": "Soil_Clay_Ocean_Brick_Smooth",
      "rotation": 3
    },
    {
      "x": 1,
      "y": 8,
      "z": -3,
      "name": "Soil_Gravel_Sand"
    },
    {
      "x": 1,
      "y": 10,
      "z": -3,
      "name": "Rock_Sandstone_Brick",
      "rotation": 3
    },
    {
      "x": 1,
      "y": 18,
      "z": -3,
      "name": "Soil_Clay_Ocean_Brick_Smooth",
      "rotation": 3
    },
    {
      "x": 1,
      "y": 19,
      "z": -3,
