{
  "version": 8,
  "blockIdVersion": 11,
  "anchorX": 0,
  "anchorY": 8,
  "anchorZ": 0,
  "blocks": [
    {
      "x": -10,
      "y": 8,
      "z": -8,
      "name": "Rock_Sandstone_Red_Brick",
      "rotation": 3
    },
    {
      "x": -10,
      "y": 9,
      "z": -8,
      "name": "Rock_Sandstone_Red_Brick",
      "rotation": 3
    },
    {
      "x": -10,
      "y": 10,
      "z": -8,
      "name": "Rock_Sandstone_Red_Brick_Stairs",
      "rotation": 3
    },
    {
      "x": -10,
      "y": 8,
      "z": -7,
      "name": "Rock_Sandstone_Red_Cobble",
      "rotation": 3
    },
    {
      "x": -10,
      "y": 9,
      "z": -7,
      "name": "Rock_Sandstone_Red_Brick",
      "rotation": 3
    },
    {
      "x": -10,
      "y": 10,
      "z": -7,
      "name": "Rock_Sandstone_Red_Brick_Stairs",
      "rotation": 3
    },
    {
      "x": -10,
      "y": 8,
      "z": -5,
      "name": "Rock_Sandstone"
    },
    {
      "x": -10,
      "y": 8,
      "z": -4,
      "name": "Rock_Sandstone_Red_Brick",
      "rotation": 3
    },
    {
      "x": -10,
      "y": 9,
      "z": -4,
      "name": "Rock_Sandstone_Red_Brick",
      "rotation": 3
    },
    {
      "x": -10,
      "y": 10,
      "z": -4,
      "name": "Rock_Sandstone_Red_Brick_Stairs",
      "rotation": 3
    },
    {
      "x": -10,
      "y": 8,
      "z": -3,
      "name": "Rock_Sandstone_Red_Cobble",
      "rotation": 3
    },
    {
      "x": -10,
      "y": 9,
      "z": -3,
      "name": "Rock_Sandstone_Red_Brick",
      "rotation": 3
    },
    {
      "x": -10,
      "y": 10,
      "z": -3,
      "name": "Rock_Sandstone_Red_Brick_Stairs",
      "rotation": 3
    },
    {
      "x": -10,
      "y": 8,
      "z": 0,
      "name": "Rock_Sandstone_Red_Cobble",
      "rotation": 3
    },
    {
      "x": -10,
      "y": 9,
      "z": 0,
      "name": "Rock_Sandstone_Red_Brick",
      "rotation": 3
    },
    {
      "x": -10,
      "y": 10,
      "z": 0,
      "name": "Rock_Sandstone_Red_Brick_Stairs",
      "rotation": 3
    },
    {
      "x": -10,
      "y": 8,
      "z": 1,
      "name": "Rock_Sandstone_Red_Brick",
      "rotation": 3
    },
    {
      "x": -10,
      "y": 9,
      "z": 1,
      "name": "Rock_Sandstone_Red_Brick",
      "rotation": 3
    },
    {
      "x": -10,
      "y": 10,
      "z": 1,
      "name": "Rock_Sandstone_Red_Brick_Stairs",
      "rotation": 3
    },
    {
      "x": -10,
      "y": 8,
      "z": 4,
      "name": "Rock_Sandstone_Red_Brick",
      "rotation": 3
    },
    {
      "x": -10,
      "y": 9,
      "z": 4,
      "name": "Rock_Sandstone_Red_Brick",
      "rotation": 3
    },
    {
      "x": -10,
      "y": 10,
      "z": 4,
      "name": "Rock_Sandstone_Red_Brick_Stairs",
      "rotation": 3
    },
    {
      "x": -10,
      "y": 8,
      "z": 5,
      "name": "Rock_Sandstone_Red_Brick",
      "rotation": 3
    },
    {
      "x": -10,
      "y": 9,
      "z": 5,
      "name": "Rock_Sandstone_Red_Brick",
      "rotation": 3
    },
    {
      "x": -10,
      "y": 10,
      "z": 5,
      "name": "Rock_Sandstone_Red_Brick_Stairs",
      "rotation": 3
    },
    {
      "x": -10,
      "y": 8,
      "z": 6,
      "name": "Rock_Sandstone",
      "rotation": 3
    },
    {
      "x": -10,
      "y": 8,
      "z": 8,
      "name": "Rock_Sandstone_Red_Cobble",
      "rotation": 3
    },
    {
      "x": -10,
      "y": 9,
      "z": 8,
      "name": "Rock_Sandstone_Red_Brick",
      "rotation": 3
    },
    {
      "x": -10,
      "y": 10,
      "z": 8,
      "name": "Rock_Sandstone_Red_Brick_Stairs",
      "rotation": 3
    },
    {
      "x": -10,
      "y": 8,
      "z": 9,
      "name": "Rock_Sandstone_Red_Brick",
      "rotation": 3
    },
    {
      "x": -10,
      "y": 9,
      "z": 9,
      "name": "Rock_Sandstone_Red_Brick",
      "rotation": 3
    },
    {
      "x": -10,
      "y": 10,
      "z": 9,
      "name": "Rock_Sandstone_Red_Brick_Stairs",
      "rotation": 3
    },
    {
      "x": -9,
      "y": 8,
      "z": -8,
      "name": "Rock_Sandstone_Red_Brick",
      "rotation": 3
    },
    {
      "x": -9,
      "y": 9,
      "z": -8,
      "name": "Rock_Sandstone_Red_Brick",
      "rotation": 3
    },
    {
      "x": -9,
      "y": 10,
      "z": -8,
      "name": "Rock_Sandstone_Red_Brick",
      "rotation": 3
    },
    {
      "x": -9,
      "y": 11,
      "z": -8,
      "name": "Rock_Sandstone_Red_Brick_Stairs",
      "rotation": 3
    },
    {
      "x": -9,
      "y": 8,
      "z": -7,
      "name": "Rock_Sandstone_Red_Cobble",
      "rotation": 3
    },
    {
      "x": -9,
      "y": 9,
      "z": -7,
      "name": "Rock_Sandstone_Red_Brick",
      "rotation": 3
    },
    {
      "x": -9,
      "y": 10,
      "z": -7,
      "name": "Rock_Sandstone_Red_Brick",
      "rotation": 3
    },
    {
      "x": -9,
      "y": 11,
      "z": -7,
      "name": "Rock_Sandstone_Red_Brick_Stairs",
      "rotation": 3
    },
    {
      "x": -9,
      "y": 8,
      "z": -6,
      "name": "Rock_Sandstone"
    },
    {
      "x": -9,
      "y": 8,
      "z": -5,
      "name": "Rock_Sandstone"
    },
    {
      "x": -9,
      "y": 8,
      "z": -4,
      "name": "Rock_Sandstone_Red_Brick",
      "rotation": 3
    },
    {
      "x": -9,
      "y": 9,
      "z": -4,
      "name": "Rock_Sandstone_Red_Brick",
      "rotation": 3
    },
    {
      "x": -9,
      "y": 10,
      "z": -4,
      "name": "Rock_Sandstone_Red_Brick",
      "rotation": 3
    },
    {
      "x": -9,
      "y": 11,
      "z": -4,
      "name": "Rock_Sandstone_Red_Brick_Stairs",
      "rotation": 3
    },
    {
      "x": -9,
      "y": 8,
      "z": -3,
      "name": "Rock_Sandstone_Red_Brick",
      "rotation": 3
    },
    {
      "x": -9,
      "y": 9,
      "z": -3,
      "name": "Rock_Sandstone_Red_Brick",
      "rotation": 3
    },
    {
      "x": -9,
      "y": 10,
      "z": -3,
      "name": "Rock_Sandstone_Red_Brick",
      "rotation": 3
    },
    {
      "x": -9,
      "y": 11,
      "z": -3,
      "name": "Rock_Sandstone_Red_Brick_Stairs",
      "rotation": 3
    },
    {
      "x": -9,
      "y": 8,
      "z": -2,
      "name": "Rock_Sandstone"
    },
    {
      "x": -9,
      "y": 9,
      "z": -2,
      "name": "Rock_Sandstone"
    },
    {
      "x": -9,
      "y": 8,
      "z": -1,
      "name": "Rock_Sandstone"
    },
    {
      "x": -9,
      "y": 8,
      "z": 0,
      "name": "Rock_Sandstone_Red_Cobble",
      "rotation": 3
    },
    {
      "x": -9,
      "y": 9,
      "z": 0,
      "name": "Rock_Sandstone_Red_Cobble",
      "rotation": 3
    },
    {
      "x": -9,
      "y": 10,
      "z": 0,
      "name": "Rock_Sandstone_Red_Brick",
      "rotation": 3
    },
    {
      "x": -9,
      "y": 11,
      "z": 0,
      "name": "Rock_Sandstone_Red_Brick_Stairs",
      "rotation": 3
    },
    {
      "x": -9,
      "y": 8,
      "z": 1,
      "name": "Rock_Sandstone_Red_Brick",
      "rotation": 3
    },
    {
      "x": -9,
      "y": 9,
      "z": 1,
      "name": "Rock_Sandstone_Red_Brick",
      "rotation": 3
    },
    {
      "x": -9,
      "y": 10,
      "z": 1,
      "name": "Rock_Sandstone_Red_Brick",
      "rotation": 3
    },
    {
      "x": -9,
      "y": 11,
      "z": 1,
      "name": "Rock_Sandstone_Red_Brick_Stairs",
      "rotation": 3
    },
    {
      "x": -9,
      "y": 8,
      "z": 2,
      "name": "Rock_Sandstone_Cobble",
      "rotation": 3
    },
    {
      "x": -9,
      "y": 8,
      "z": 4,
      "name": "Rock_Sandstone_Red_Brick",
      "rotation": 3
    },
    {
      "x": -9,
      "y": 9,
      "z": 4,
      "name": "Rock_Sandstone_Red_Brick",
      "rotation": 3
    },
    {
      "x": -9,
      "y": 10,
      "z": 4,
      "name": "Rock_Sandstone_Red_Brick",
      "rotation": 3
    },
    {
      "x": -9,
      "y": 11,
      "z": 4,
      "name": "Rock_Sandstone_Red_Brick_Stairs",
      "rotation": 3
    },
    {
      "x": -9,
      "y": 8,
      "z": 5,
      "name": "Rock_Sandstone_Red_Brick",
      "rotation": 3
    },
    {
      "x": -9,
      "y": 9,
      "z": 5,
      "name": "Rock_Sandstone_Red_Brick",
      "rotation": 3
    },
    {
      "x": -9,
      "y": 10,
      "z": 5,
      "name": "Rock_Sandstone_Red_Brick",
      "rotation": 3
    },
    {
      "x": -9,
      "y": 11,
      "z": 5,
      "name": "Rock_Sandstone_Red_Brick_Stairs",
      "rotation": 3
    },
    {
      "x": -9,
      "y": 8,
      "z": 6,
      "name": "Rock_Sandstone",
      "rotation": 3
    },
    {
      "x": -9,
      "y": 8,
      "z": 7,
      "name": "Rock_Sandstone",
      "rotation": 3
    },
    {
      "x": -9,
      "y": 8,
      "z": 8,
      "name": "Rock_Sandstone_Red_Brick",
      "rotation": 3
    },
    {
      "x": -9,
      "y": 9,
      "z": 8,
      "name": "Rock_Sandstone_Red_Brick",
      "rotation": 3
    },
    {
      "x": -9,
      "y": 10,
      "z": 8,
      "name": "Rock_Sandstone_Red_Brick",
      "rotation": 3
    },
    {
      "x": -9,
      "y": 11,
      "z": 8,
      "name": "Rock_Sandstone_Red_Brick_Stairs",
      "rotation": 3
    },
    {
      "x": -9,
      "y": 8,
      "z": 9,
      "name": "Rock_Sandstone_Red_Brick",
      "rotation": 3
    },
    {
      "x": -9,
      "y": 9,
      "z": 9,
      "name": "Rock_Sandstone_Red_Brick",
      "rotation": 3
    },
    {
      "x": -9,
      "y": 10,
      "z": 9,
      "name": "Rock_Sandstone_Red_Brick",
      "rotation": 3
    },
    {
      "x": -9,
      "y": 11,
      "z": 9,
      "name": "Rock_Sandstone_Red_Brick_Stairs",
      "rotation": 3
    },
    {
      "x": -8,
      "y": 8,
      "z": -10,
      "name": "Rock_Sandstone_Red_Cobble",
      "rotation": 3
    },
    {
      "x": -8,
      "y": 9,
      "z": -10,
      "name": "Rock_Sandstone_Red_Brick",
      "rotation": 3
    },
    {
      "x": -8,
      "y": 10,
      "z": -10,
      "name": "Rock_Sandstone_Red_Brick_Stairs",
      "rotation": 2
    },
    {
      "x": -8,
      "y": 8,
      "z": -9,
      "name": "Rock_Sandstone_Red_Brick",
      "rotation": 3
    },
    {
      "x": -8,
      "y": 9,
      "z": -9,
      "name": "Rock_Sandstone_Red_Brick",
      "rotation": 3
    },
    {
      "x": -8,
      "y": 10,
      "z": -9,
      "name": "Rock_Sandstone_Red_Brick",
      "rotation": 3
    },
    {
      "x": -8,
      "y": 11,
      "z": -9,
      "name": "Rock_Sandstone_Red_Brick_Stairs",
      "rotation": 2
    },
    {
      "x": -8,
      "y": 8,
      "z": -8,
      "name": "Rock_Sandstone_Brick",
      "rotation": 3
    },
    {
      "x": -8,
      "y": 9,
      "z": -8,
      "name": "Rock_Sandstone_Brick",
      "rotation": 3
    },
    {
      "x": -8,
      "y": 10,
      "z": -8,
      "name": "Rock_Sandstone_Brick",
      "rotation": 3
    },
    {
      "x": -8,
      "y": 11,
      "z": -8,
      "name": "Rock_Sandstone_Brick",
      "rotation": 3
    },
    {
      "x": -8,
      "y": 12,
      "z": -8,
      "name": "Rock_Sandstone_Brick_Ornate",
      "rotation": 3
    },
    {
      "x": -8,
      "y": 13,
      "z": -8,
      "name": "*Rock_Sandstone_Brick_Stairs_State_Definitions_Corner_Right",
      "rotation": 3
    },
    {
      "x": -8,
      "y": 8,
      "z": -7,
      "name": "Rock_Sandstone_Brick",
      "rotation": 3
    },
    {
      "x": -8,
      "y": 9,
      "z": -7,
      "name": "Rock_Sandstone_Brick",
      "rotation": 3
    },
    {
      "x": -8,
      "y": 10,
      "z": -7,
      "name": "Rock_Sandstone_Brick",
      "rotation": 3
    },
    {
      "x": -8,
      "y": 11,
      "z": -7,
      "name": "Rock_Sandstone_Brick",
      "rotation": 3
    },
    {
      "x": -8,
      "y": 12,
      "z": -7,
      "name": "Rock_Sandstone_Brick_Ornate",
      "rotation": 3
    },
    {
      "x": -8,
      "y": 13,
      "z": -7,
      "name": "Rock_Sandstone_Brick_Stairs",
      "rotation": 3
    },
    {
      "x": -8,
      "y": 8,
      "z": -6,
      "name": "Rock_Sandstone_Brick",
      "rotation": 3
    },
    {
      "x": -8,
      "y": 9,
      "z": -6,
      "name": "Rock_Sandstone_Cobble",
      "rotation": 3
    },
    {
      "x": -8,
      "y": 10,
      "z": -6,
      "name": "Rock_Sandstone_Brick",
      "rotation": 3
    },
    {
      "x": -8,
      "y": 11,
      "z": -6,
      "name": "Rock_Sandstone_Cobble",
      "rotation": 3
    },
    {
      "x": -8,
      "y": 12,
      "z": -6,
      "name": "Rock_Sandstone_Brick_Ornate",
      "rotation": 3
    },
    {
      "x": -8,
      "y": 13,
      "z": -6,
      "name": "Rock_Sandstone_Brick_Stairs",
      "rotation": 3
    },
    {
      "x": -8,
      "y": 8,
      "z": -5,
      "name": "Rock_Sandstone_Brick",
      "rotation": 3
    },
    {
      "x": -8,
      "y": 9,
      "z": -5,
      "name": "Rock_Sandstone_Brick",
      "rotation": 3
    },
    {
      "x": -8,
      "y": 10,
      "z": -5,
      "name": "Rock_Sandstone_Cobble",
      "rotation": 3
    },
    {
      "x": -8,
      "y": 11,
      "z": -5,
      "name": "Rock_Sandstone_Cobble",
      "rotation": 3
    },
    {
      "x": -8,
      "y": 12,
      "z": -5,
      "name": "Rock_Sandstone_Brick_Ornate",
      "rotation": 3
    },
    {
      "x": -8,
      "y": 13,
      "z": -5,
      "name": "Rock_Sandstone_Brick_Stairs",
      "rotation": 3
    },
    {
      "x": -8,
      "y": 8,
      "z": -4,
      "name": "Rock_Sandstone_Brick",
      "rotation": 3
    },
    {
      "x": -8,
      "y": 9,
      "z": -4,
      "name": "Rock_Sandstone_Brick",
      "rotation": 3
    },
    {
      "x": -8,
      "y": 10,
      "z": -4,
      "name": "Rock_Sandstone_Brick",
      "rotation": 3
    },
    {
      "x": -8,
      "y": 11,
      "z": -4,
      "name": "Rock_Sandstone_Brick",
      "rotation": 3
    },
    {
      "x": -8,
      "y": 12,
      "z": -4,
      "name": "Rock_Sandstone_Brick_Ornate",
      "rotation": 3
    },
    {
      "x": -8,
      "y": 13,
      "z": -4,
      "name": "Rock_Sandstone_Brick_Stairs",
      "rotation": 3
    },
    {
      "x": -8,
      "y": 8,
      "z": -3,
      "name": "Rock_Sandstone_Brick",
      "rotation": 3
    },
    {
      "x": -8,
      "y": 9,
      "z": -3,
      "name": "Rock_Sandstone_Brick",
      "rotation": 3
    },
    {
      "x": -8,
      "y": 10,
      "z": -3,
      "name": "Rock_Sandstone_Brick",
      "rotation": 3
    },
    {
      "x": -8,
      "y": 11,
      "z": -3,
      "name": "Rock_Sandstone_Brick",
      "rotation": 3
    },
    {
      "x": -8,
      "y": 12,
      "z": -3,
      "name": "Rock_Sandstone_Brick_Ornate",
      "rotation": 3
    },
    {
      "x": -8,
      "y": 13,
      "z": -3,
      "name": "Rock_Sandstone_Brick_Stairs",
      "rotation": 3
    },
    {
      "x": -8,
      "y": 8,
      "z": -2,
      "name": "Rock_Sandstone_Cobble",
      "rotation": 3
    },
    {
      "x": -8,
      "y": 9,
      "z": -2,
      "name": "Rock_Sandstone_Cobble",
      "rotation": 3
    },
    {
      "x": -8,
      "y": 10,
      "z": -2,
      "name": "Rock_Sandstone_Cobble",
      "rotation": 3
    },
    {
      "x": -8,
      "y": 11,
      "z": -2,
      "name": "Rock_Sandstone_Cobble",
      "rotation": 3
    },
    {
      "x": -8,
      "y": 12,
      "z": -2,
      "name": "Rock_Sandstone_Brick_Ornate",
      "rotation": 3
    },
    {
      "x": -8,
      "y": 13,
      "z": -2,
      "name": "Rock_Sandstone_Brick_Stairs",
      "rotation": 3
    },
    {
      "x": -8,
      "y": 8,
      "z": -1,
      "name": "Rock_Sandstone_Brick",
      "rotation": 3
    },
    {
      "x": -8,
      "y": 9,
      "z": -1,
      "name": "Rock_Sandstone_Cobble",
      "rotation": 3
    },
    {
      "x": -8,
      "y": 10,
      "z": -1,
      "name": "Rock_Sandstone_Cobble",
      "rotation": 3
    },
    {
      "x": -8,
      "y": 11,
      "z": -1,
      "name": "Rock_Sandstone_Cobble",
      "rotation": 3
    },
    {
      "x": -8,
      "y": 12,
      "z": -1,
      "name": "Rock_Sandstone_Brick_Ornate",
      "rotation": 3
    },
    {
      "x": -8,
      "y": 13,
      "z": -1,
      "name": "Rock_Sandstone_Brick_Stairs",
      "rotation": 3
    },
    {
      "x": -8,
      "y": 17,
      "z": -1,
      "name": "Rock_Sandstone_Brick_Stairs",
      "rotation": 9
    },
    {
      "x": -8,
      "y": 18,
      "z": -1,
      "name": "Rock_Sandstone_Brick",
      "rotation": 3
    },
    {
      "x": -8,
      "y": 8,
      "z": 0,
      "name": "Rock_Sandstone_Brick",
      "rotation": 3
    },
    {
      "x": -8,
      "y": 9,
      "z": 0,
      "name": "Rock_Sandstone_Brick",
      "rotation": 3
    },
    {
      "x": -8,
      "y": 10,
      "z": 0,
      "name": "Rock_Sandstone_Brick",
      "rotation": 3
    },
    {
      "x": -8,
      "y": 11,
      "z": 0,
      "name": "Rock_Sandstone_Brick",
      "rotation": 3
    },
    {
      "x": -8,
      "y": 12,
      "z": 0,
      "name": "Rock_Sandstone_Brick_Ornate",
      "rotation": 3
    },
    {
      "x": -8,
      "y": 13,
      "z": 0,
      "name": "Rock_Sandstone_Brick_Stairs",
      "rotation": 3
    },
    {
      "x": -8,
      "y": 17,
      "z": 0,
      "name": "Rock_Sandstone_Brick_Stairs",
      "rotation": 9
    },
    {
      "x": -8,
      "y": 18,
      "z": 0,
      "name": "Rock_Sandstone_Brick",
      "rotation": 3
    },
    {
      "x": -8,
      "y": 19,
      "z": 0,
      "name": "Rock_Sandstone_Brick",
      "rotation": 3
    },
    {
      "x": -8,
      "y": 8,
      "z": 1,
      "name": "Rock_Sandstone_Brick",
      "rotation": 3
    },
    {
      "x": -8,
      "y": 9,
      "z": 1,
      "name": "Rock_Sandstone_Brick",
      "rotation": 3
    },
    {
      "x": -8,
      "y": 10,
      "z": 1,
      "name": "Rock_Sandstone_Brick",
      "rotation": 3
    },
    {
      "x": -8,
      "y": 11,
      "z": 1,
      "name": "Rock_Sandstone_Brick",
      "rotation": 3
    },
    {
      "x": -8,
      "y": 12,
      "z": 1,
      "name": "Rock_Sandstone_Brick_Ornate",
      "rotation": 3
    },
    {
      "x": -8,
      "y": 13,
      "z": 1,
      "name": "Rock_Sandstone_Brick_Stairs",
      "rotation": 3
    },
    {
      "x": -8,
      "y": 17,
      "z": 1,
      "name": "Rock_Sandstone_Brick_Stairs",
      "rotation": 9
    },
    {
      "x": -8,
      "y": 18,
      "z": 1,
      "name": "Rock_Sandstone_Brick",
      "rotation": 3
    },
    {
      "x": -8,
      "y": 19,
      "z": 1,
      "name": "Rock_Sandstone_Brick",
      "rotation": 3
    },
    {
      "x": -8,
      "y": 8,
      "z": 2,
      "name": "Rock_Sandstone_Brick",
      "rotation": 3
    },
    {
      "x": -8,
      "y": 9,
      "z": 2,
      "name": "Rock_Sandstone_Cobble",
      "rotation": 3
    },
    {
      "x": -8,
      "y": 10,
      "z": 2,
      "name": "Rock_Sandstone_Brick",
      "rotation": 3
    },
    {
      "x": -8,
      "y": 11,
      "z": 2,
      "name": "Rock_Sandstone_Cobble",
      "rotation": 3
    },
    {
      "x": -8,
      "y": 12,
      "z": 2,
      "name": "Rock_Sandstone_Brick_Ornate",
      "rotation": 3
    },
    {
      "x": -8,
      "y": 13,
      "z": 2,
      "name": "Rock_Sandstone_Brick_Stairs",
      "rotation": 3
    },
    {
      "x": -8,
      "y": 17,
      "z": 2,
      "name": "Rock_Sandstone_Brick_Stairs",
      "rotation": 9
    },
    {
      "x": -8,
      "y": 18,
      "z": 2,
      "name": "Rock_Sandstone_Brick",
      "rotation": 3
    },
    {
      "x": -8,
      "y": 19,
      "z": 2,
      "name": "Rock_Sandstone_Brick",
      "rotation": 3
    },
    {
      "x": -8,
      "y": 8,
      "z": 3,
      "name": "Rock_Sandstone_Brick",
      "rotation": 3
    },
    {
      "x": -8,
      "y": 9,
      "z": 3,
      "name": "Rock_Sandstone_Brick",
      "rotation": 3
    },
    {
      "x": -8,
      "y": 10,
      "z": 3,
      "name": "Rock_Sandstone_Cobble",
      "rotation": 3
    },
    {
      "x": -8,
      "y": 11,
      "z": 3,
      "name": "Rock_Sandstone_Cobble",
      "rotation": 3
    },
    {
      "x": -8,
      "y": 12,
      "z": 3,
      "name": "Rock_Sandstone_Brick_Ornate",
      "rotation": 3
    },
    {
      "x": -8,
      "y": 13,
      "z": 3,
      "name": "Rock_Sandstone_Brick_Stairs",
      "rotation": 3
    },
    {
      "x": -8,
      "y": 17,
      "z": 3,
      "name": "Rock_Sandstone_Brick_Stairs",
      "rotation": 9
    },
    {
      "x": -8,
      "y": 18,
      "z": 3,
      "name": "Rock_Sandstone_Brick",
      "rotation": 3
    },
    {
      "x": -8,
      "y": 19,
      "z": 3,
      "name": "Rock_Sandstone_Brick",
      "rotation": 3
    },
    {
      "x": -8,
      "y": 8,
      "z": 4,
      "name": "Rock_Sandstone_Brick",
      "rotation": 3
    },
    {
      "x": -8,
      "y": 9,
      "z": 4,
      "name": "Rock_Sandstone_Brick",
      "rotation": 3
    },
    {
      "x": -8,
      "y": 10,
      "z": 4,
      "name": "Rock_Sandstone_Brick",
      "rotation": 3
    },
    {
      "x": -8,
      "y": 11,
      "z": 4,
      "name": "Rock_Sandstone_Brick",
      "rotation": 3
    },
    {
      "x": -8,
      "y": 12,
      "z": 4,
      "name": "Rock_Sandstone_Brick_Ornate",
      "rotation": 3
    },
    {
      "x": -8,
      "y": 13,
      "z": 4,
      "name": "Rock_Sandstone_Brick_Stairs",
      "rotation": 3
    },
    {
      "x": -8,
      "y": 17,
      "z": 4,
      "name": "Rock_Sandstone_Brick_Stairs",
      "rotation": 9
    },
    {
      "x": -8,
      "y": 18,
      "z": 4,
      "name": "Rock_Sandstone_Brick",
      "rotation": 3
    },
    {
      "x": -8,
      "y": 19,
      "z": 4,
      "name": "Rock_Sandstone_Brick",
      "rotation": 3
    },
    {
      "x": -8,
      "y": 20,
      "z": 4,
      "name": "Rock_Sandstone_Brick_Half",
      "rotation": 3
    },
    {
      "x": -8,
      "y": 8,
      "z": 5,
      "name": "Rock_Sandstone_Brick",
      "rotation": 3
    },
    {
      "x": -8,
      "y": 9,
      "z": 5,
      "name": "Rock_Sandstone_Brick",
      "rotation": 3
    },
    {
      "x": -8,
      "y": 10,
      "z": 5,
      "name": "Rock_Sandstone_Brick",
      "rotation": 3
    },
    {
      "x": -8,
      "y": 11,
      "z": 5,
      "name": "Rock_Sandstone_Brick",
      "rotation": 3
    },
    {
      "x": -8,
      "y": 12,
      "z": 5,
      "name": "Rock_Sandstone_Brick_Ornate",
      "rotation": 3
    },
    {
      "x": -8,
      "y": 13,
      "z": 5,
      "name": "Rock_Sandstone_Brick_Stairs",
      "rotation": 3
    },
    {
      "x": -8,
      "y": 17,
      "z": 5,
      "name": "Rock_Sandstone_Brick_Half",
      "rotation": 7
    },
    {
      "x": -8,
      "y": 18,
      "z": 5,
      "name": "Rock_Sandstone_Brick",
      "rotation": 3
    },
    {
      "x": -8,
      "y": 19,
      "z": 5,
      "name": "Rock_Sandstone_Brick",
      "rotation": 3
    },
    {
      "x": -8,
      "y": 20,
      "z": 5,
      "name": "Rock_Sandstone_Brick_Half",
      "rotation": 3
    },
    {
      "x": -8,
      "y": 8,
      "z": 6,
      "name": "Rock_Sandstone_Cobble",
      "rotation": 3
    },
    {
      "x": -8,
      "y": 9,
      "z": 6,
      "name": "Rock_Sandstone_Cobble",
      "rotation": 3
    },
    {
      "x": -8,
      "y": 10,
      "z": 6,
      "name": "Rock_Sandstone_Cobble",
      "rotation": 3
    },
    {
      "x": -8,
      "y": 11,
      "z": 6,
      "name": "Rock_Sandstone_Cobble",
      "rotation": 3
    },
    {
      "x": -8,
      "y": 12,
      "z": 6,
      "name": "Rock_Sandstone_Brick_Ornate",
      "rotation": 3
    },
    {
      "x": -8,
      "y": 13,
      "z": 6,
      "name": "Rock_Sandstone_Brick_Stairs",
      "rotation": 3
    },
    {
      "x": -8,
      "y": 18,
      "z": 6,
      "name": "Rock_Sandstone_Brick",
      "rotation": 3
    },
    {
      "x": -8,
      "y": 19,
      "z": 6,
      "name": "Rock_Sandstone_Brick",
      "rotation": 3
    },
    {
      "x": -8,
      "y": 8,
      "z": 7,
      "name": "Rock_Sandstone_Brick",
      "rotation": 3
    },
    {
      "x": -8,
      "y": 9,
      "z": 7,
      "name": "Rock_Sandstone_Cobble",
      "rotation": 3
    },
    {
      "x": -8,
      "y": 10,
      "z": 7,
      "name": "Rock_Sandstone_Cobble",
      "rotation": 3
    },
    {
      "x": -8,
      "y": 11,
      "z": 7,
      "name": "Rock_Sandstone_Cobble",
      "rotation": 3
    },
    {
      "x": -8,
      "y": 12,
      "z": 7,
      "name": "Rock_Sandstone_Brick_Ornate",
      "rotation": 3
    },
    {
      "x": -8,
      "y": 13,
      "z": 7,
      "name": "Rock_Sandstone_Brick_Stairs",
      "rotation": 3
    },
    {
      "x": -8,
      "y": 8,
      "z": 8,
      "name": "Rock_Sandstone_Brick",
      "rotation": 3
    },
    {
      "x": -8,
      "y": 9,
      "z": 8,
      "name": "Rock_Sandstone_Brick",
      "rotation": 3
    },
    {
      "x": -8,
      "y": 10,
      "z": 8,
      "name": "Rock_Sandstone_Brick",
      "rotation": 3
    },
    {
      "x": -8,
      "y": 11,
      "z": 8,
      "name": "Rock_Sandstone_Brick",
      "rotation": 3
    },
    {
      "x": -8,
      "y": 12,
      "z": 8,
      "name": "Rock_Sandstone_Brick_Ornate",
      "rotation": 3
    },
    {
      "x": -8,
      "y": 8,
      "z": 9,
      "name": "Rock_Sandstone_Brick",
      "rotation": 3
    },
    {
      "x": -8,
      "y": 9,
      "z": 9,
      "name": "Rock_Sandstone_Brick",
      "rotation": 3
    },
    {
      "x": -8,
      "y": 10,
      "z": 9,
      "name": "Rock_Sandstone_Brick",
      "rotation": 3
    },
    {
      "x": -8,
      "y": 11,
      "z": 9,
      "name": "Rock_Sandstone_Brick",
      "rotation": 3
    },
    {
      "x": -8,
      "y": 12,
      "z": 9,
      "name": "Rock_Sandstone_Brick_Ornate",
      "rotation": 3
    },
    {
      "x": -8,
      "y": 8,
      "z": 10,
      "name": "Rock_Sandstone_Red_Brick",
      "rotation": 3
    },
    {
      "x": -8,
      "y": 9,
      "z": 10,
      "name": "Rock_Sandstone_Red_Brick",
      "rotation": 3
    },
    {
      "x": -8,
      "y": 10,
      "z": 10,
      "name": "Rock_Sandstone_Red_Brick",
      "rotation": 3
    },
    {
      "x": -8,
      "y": 11,
      "z": 10,
      "name": "Rock_Sandstone_Red_Brick_Stairs"
    },
    {
      "x": -8,
      "y": 8,
      "z": 11,
      "name": "Rock_Sandstone_Red_Cobble",
      "rotation": 3
    },
    {
      "x": -8,
      "y": 9,
      "z": 11,
      "name": "Rock_Sandstone_Red_Brick",
      "rotation": 3
    },
    {
      "x": -8,
      "y": 10,
      "z": 11,
      "name": "Rock_Sandstone_Red_Brick_Stairs"
    },
    {
      "x": -7,
      "y": 8,
      "z": -10,
      "name": "Rock_Sandstone_Red_Brick",
      "rotation": 3
    },
    {
      "x": -7,
      "y": 9,
      "z": -10,
      "name": "Rock_Sandstone_Red_Brick",
      "rotation": 3
    },
    {
      "x": -7,
      "y": 10,
      "z": -10,
      "name": "Rock_Sandstone_Red_Brick_Stairs",
      "rotation": 2
    },
    {
      "x": -7,
      "y": 8,
      "z": -9,
      "name": "Rock_Sandstone_Red_Brick",
      "rotation": 3
    },
    {
      "x": -7,
      "y": 9,
      "z": -9,
      "name": "Rock_Sandstone_Red_Brick",
      "rotation": 3
    },
    {
      "x": -7,
      "y": 10,
      "z": -9,
      "name": "Rock_Sandstone_Red_Brick",
      "rotation": 3
    },
    {
      "x": -7,
      "y": 11,
      "z": -9,
      "name": "Rock_Sandstone_Red_Brick_Stairs",
      "rotation": 2
    },
    {
      "x": -7,
      "y": 8,
      "z": -8,
      "name": "Rock_Sandstone_Brick",
      "rotation": 3
    },
    {
      "x": -7,
      "y": 9,
      "z": -8,
      "name": "Rock_Sandstone_Brick",
      "rotation": 3
    },
    {
      "x": -7,
      "y": 10,
      "z": -8,
      "name": "Rock_Sandstone_Brick",
      "rotation": 3
    },
    {
      "x": -7,
      "y": 11,
      "z": -8,
      "name": "Rock_Sandstone_Brick",
      "rotation": 3
    },
    {
      "x": -7,
      "y": 12,
      "z": -8,
      "name": "Rock_Sandstone_Brick_Ornate",
      "rotation": 3
    },
    {
      "x": -7,
      "y": 13,
      "z": -8,
      "name": "Rock_Sandstone_Brick_Stairs",
      "rotation": 2
    },
    {
      "x": -7,
      "y": 8,
      "z": -7,
      "name": "Rock_Sandstone_Brick",
      "rotation": 3
    },
    {
      "x": -7,
      "y": 9,
      "z": -7,
      "name": "Rock_Sandstone_Brick",
      "rotation": 3
    },
    {
      "x": -7,
      "y": 10,
      "z": -7,
      "name": "Rock_Sandstone_Brick",
      "rotation": 3
    },
    {
      "x": -7,
      "y": 11,
      "z": -7,
      "name": "Rock_Sandstone_Brick",
      "rotation": 3
    },
    {
      "x": -7,
      "y": 12,
      "z": -7,
      "name": "Rock_Sandstone_Brick",
      "rotation": 3
    },
    {
      "x": -7,
      "y": 13,
      "z": -7,
      "name": "Rock_Sandstone_Cobble",
      "rotation": 3
    },
    {
      "x": -7,
      "y": 14,
      "z": -7,
      "name": "Rock_Sandstone_Cobble",
      "rotation": 3
    },
    {
      "x": -7,
      "y": 15,
      "z": -7,
      "name": "Rock_Sandstone_Cobble"
    },
    {
      "x": -7,
      "y": 8,
      "z": -6,
      "name": "Rock_Sandstone_Brick",
      "rotation": 3
    },
    {
      "x": -7,
      "y": 9,
      "z": -6,
      "name": "Rock_Sandstone_Brick",
      "rotation": 3
    },
    {
      "x": -7,
      "y": 10,
      "z": -6,
      "name": "Rock_Sandstone_Brick",
      "rotation": 3
    },
    {
      "x": -7,
      "y": 11,
      "z": -6,
      "name": "Rock_Sandstone_Red_Brick",
      "rotation": 3
    },
    {
      "x": -7,
      "y": 12,
      "z": -6,
      "name": "Rock_Sandstone_Brick",
      "rotation": 3
    },
    {
      "x": -7,
      "y": 13,
      "z": -6,
      "name": "Rock_Sandstone_Cobble",
      "rotation": 3
    },
    {
      "x": -7,
      "y": 14,
      "z": -6,
      "name": "Rock_Sandstone_Cobble",
      "rotation": 3
    },
    {
      "x": -7,
      "y": 15,
      "z": -6,
      "name": "Rock_Sandstone_Cobble",
      "rotation": 3
    },
    {
      "x": -7,
      "y": 8,
      "z": -5,
      "name": "Rock_Sandstone_Brick",
      "rotation": 3
    },
    {
      "x": -7,
      "y": 9,
      "z": -5,
      "name": "Rock_Sandstone_Brick",
      "rotation": 3
    },
    {
      "x": -7,
      "y": 10,
      "z": -5,
      "name": "Rock_Sandstone_Brick",
      "rotation": 3
    },
    {
      "x": -7,
      "y": 11,
      "z": -5,
      "name": "Rock_Sandstone_Red_Brick",
      "rotation": 3
    },
    {
      "x": -7,
      "y": 12,
      "z": -5,
      "name": "Rock_Sandstone_Brick",
      "rotation": 3
    },
    {
      "x": -7,
      "y": 13,
      "z": -5,
      "name": "Rock_Sandstone_Cobble",
      "rotation": 3
    },
    {
      "x": -7,
      "y": 14,
      "z": -5,
      "name": "Rock_Sandstone_Cobble",
      "rotation": 3
    },
    {
      "x": -7,
      "y": 15,
      "z": -5,
      "name": "Rock_Sandstone_Cobble",
      "rotation": 3
    },
    {
      "x": -7,
      "y": 8,
      "z": -4,
      "name": "Rock_Sandstone_Brick",
      "rotation": 3
    },
    {
      "x": -7,
      "y": 9,
      "z": -4,
      "name": "Rock_Sandstone_Brick",
      "rotation": 3
    },
    {
      "x": -7,
      "y": 10,
      "z": -4,
      "name": "Rock_Sandstone_Brick",
      "rotation": 3
    },
    {
      "x": -7,
      "y": 11,
      "z": -4,
      "name": "Rock_Sandstone_Red_Brick",
      "rotation": 3
    },
    {
      "x": -7,
      "y": 12,
      "z": -4,
      "name": "Rock_Sandstone_Brick",
      "rotation": 3
    },
    {
      "x": -7,
      "y": 13,
      "z": -4,
      "name": "Rock_Sandstone_Cobble",
      "rotation": 3
    },
    {
      "x": -7,
      "y": 14,
      "z": -4,
      "name": "Rock_Sandstone_Cobble",
      "rotation": 3
    },
    {
      "x": -7,
      "y": 15,
      "z": -4,
      "name": "Rock_Sandstone_Cobble"
    },
    {
      "x": -7,
      "y": 8,
      "z": -3,
      "name": "Rock_Sandstone_Brick",
      "rotation": 3
    },
    {
      "x": -7,
      "y": 9,
      "z": -3,
      "name": "Rock_Sandstone_Brick",
      "rotation": 3
    },
    {
      "x": -7,
      "y": 10,
      "z": -3,
      "name": "Rock_Sandstone_Brick",
      "rotation": 3
    },
    {
      "x": -7,
      "y": 11,
      "z": -3,
      "name": "Rock_Sandstone_Red_Brick",
      "rotation": 3
    },
    {
      "x": -7,
      "y": 12,
      "z": -3,
      "name": "Rock_Sandstone_Brick",
      "rotation": 3
    },
    {
      "x": -7,
      "y": 13,
      "z": -3,
      "name": "Rock_Sandstone_Cobble",
      "rotation": 3
    },
    {
      "x": -7,
      "y": 14,
      "z": -3,
      "name": "Rock_Sandstone_Cobble",
      "rotation": 3
    },
    {
      "x": -7,
      "y": 15,
      "z": -3,
      "name": "Rock_Sandstone_Cobble",
      "rotation": 3
    },
    {
      "x": -7,
      "y": 16,
      "z": -3,
      "name": "Rock_Sandstone_Cobble"
    },
    {
      "x": -7,
      "y": 8,
      "z": -2,
      "name": "Rock_Sandstone_Brick",
      "rotation": 3
    },
    {
      "x": -7,
      "y": 9,
      "z": -2,
      "name": "Rock_Sandstone_Brick",
      "rotation": 3
    },
    {
      "x": -7,
      "y": 10,
      "z": -2,
      "name": "Rock_Sandstone_Brick",
      "rotation": 3
    },
    {
      "x": -7,
      "y": 11,
      "z": -2,
      "name": "Rock_Sandstone_Red_Brick",
      "rotation": 3
    },
    {
      "x": -7,
      "y": 12,
      "z": -2,
      "name": "Rock_Sandstone_Brick",
      "rotation": 3
    },
    {
      "x": -7,
      "y": 13,
      "z": -2,
      "name": "Rock_Sandstone_Cobble",
      "rotation": 3
    },
    {
      "x": -7,
      "y": 14,
      "z": -2,
      "name": "Rock_Sandstone_Cobble",
      "rotation": 3
    },
    {
      "x": -7,
      "y": 15,
      "z": -2,
      "name": "Rock_Sandstone_Cobble",
      "rotation": 3
    },
    {
      "x": -7,
      "y": 16,
      "z": -2,
      "name": "Rock_Sandstone_Cobble",
      "rotation": 3
    },
    {
      "x": -7,
      "y": 17,
      "z": -2,
      "name": "Rock_Sandstone_Cobble"
    },
    {
      "x": -7,
      "y": 18,
      "z": -2,
      "name": "Rock_Sandstone_Cobble"
    },
    {
      "x": -7,
      "y": 8,
      "z": -1,
      "name": "Rock_Sandstone_Brick",
      "rotation": 3
    },
    {
      "x": -7,
      "y": 9,
      "z": -1,
      "name": "Rock_Sandstone_Brick",
      "rotation": 3
    },
    {
      "x": -7,
      "y": 10,
      "z": -1,
      "name": "Rock_Sandstone_Brick",
      "rotation": 3
    },
    {
      "x": -7,
      "y": 11,
      "z": -1,
      "name": "Rock_Sandstone_Red_Brick",
      "rotation": 3
    },
    {
      "x": -7,
      "y": 12,
      "z": -1,
      "name": "Rock_Sandstone_Brick",
      "rotation": 3
    },
    {
      "x": -7,
      "y": 13,
      "z": -1,
      "name": "Rock_Sandstone_Cobble",
      "rotation": 3
    },
    {
      "x": -7,
      "y": 14,
      "z": -1,
      "name": "Rock_Sandstone_Cobble",
      "rotation": 3
    },
    {
      "x": -7,
      "y": 15,
      "z": -1,
      "name": "Rock_Sandstone_Cobble",
      "rotation": 3
    },
    {
      "x": -7,
      "y": 16,
      "z": -1,
      "name": "Rock_Sandstone_Cobble",
      "rotation": 3
    },
    {
      "x": -7,
      "y": 17,
      "z": -1,
      "name": "Rock_Sandstone_Cobble",
      "rotation": 3
    },
    {
      "x": -7,
      "y": 18,
      "z": -1,
      "name": "Rock_Sandstone_Cobble"
    },
    {
      "x": -7,
      "y": 8,
      "z": 0,
      "name": "Rock_Sandstone_Red_Brick",
      "rotation": 3
    },
    {
      "x": -7,
      "y": 9,
      "z": 0,
      "name": "Rock_Sandstone_Red_Brick",
      "rotation": 3
    },
    {
      "x": -7,
      "y": 10,
      "z": 0,
      "name": "Rock_Sandstone_Red_Brick",
      "rotation": 3
    },
    {
      "x": -7,
      "y": 11,
      "z": 0,
      "name": "Rock_Sandstone_Red_Brick",
      "rotation": 3
    },
    {
      "x": -7,
      "y": 12,
      "z": 0,
      "name": "Rock_Sandstone_Brick",
      "rotation": 3
    },
    {
      "x": -7,
      "y": 13,
      "z": 0,
      "name": "Rock_Sandstone_Cobble",
      "rotation": 3
    },
    {
      "x": -7,
      "y": 14,
      "z": 0,
      "name": "Rock_Sandstone_Cobble",
      "rotation": 3
    },
    {
      "x": -7,
      "y": 15,
      "z": 0,
      "name": "Rock_Sandstone_Cobble",
      "rotation": 3
    },
    {
      "x": -7,
      "y": 16,
      "z": 0,
      "name": "Rock_Sandstone_Cobble",
      "rotation": 3
    },
    {
      "x": -7,
      "y": 17,
      "z": 0,
      "name": "Rock_Sandstone_Cobble",
      "rotation": 3
    },
    {
      "x": -7,
      "y": 18,
      "z": 0,
      "name": "Rock_Sandstone_Brick",
      "rotation": 3
    },
    {
      "x": -7,
      "y": 19,
      "z": 0,
      "name": "Rock_Sandstone_Brick"
    },
    {
      "x": -7,
      "y": 8,
      "z": 1,
      "name": "Rock_Sandstone_Brick",
      "rotation": 3
    },
    {
      "x": -7,
      "y": 9,
      "z": 1,
      "name": "Rock_Sandstone_Brick",
      "rotation": 3
    },
    {
      "x": -7,
      "y": 10,
      "z": 1,
      "name": "Rock_Sandstone_Brick",
      "rotation": 3
    },
    {
      "x": -7,
      "y": 11,
      "z": 1,
      "name": "Rock_Sandstone_Brick",
      "rotation": 3
    },
    {
      "x": -7,
      "y": 12,
      "z": 1,
      "name": "Rock_Sandstone_Brick",
      "rotation": 3
    },
    {
      "x": -7,
      "y": 13,
      "z": 1,
      "name": "Rock_Sandstone_Cobble",
      "rotation": 3
    },
    {
      "x": -7,
      "y": 14,
      "z": 1,
      "name": "Rock_Sandstone_Cobble",
      "rotation": 3
    },
    {
      "x": -7,
      "y": 15,
      "z": 1,
      "name": "Rock_Sandstone_Cobble",
      "rotation": 3
    },
    {
      "x": -7,
      "y": 16,
      "z": 1,
      "name": "Rock_Sandstone_Cobble",
      "rotation": 3
    },
    {
      "x": -7,
      "y": 17,
      "z": 1,
      "name": "Rock_Sandstone_Cobble",
      "rotation": 3
    },
    {
      "x": -7,
      "y": 18,
      "z": 1,
      "name": "Rock_Sandstone_Brick",
      "rotation": 3
    },
    {
      "x": -7,
      "y": 19,
      "z": 1,
      "name": "Rock_Sandstone_Brick",
      "rotation": 3
    },
    {
      "x": -7,
      "y": 8,
      "z": 2,
      "name": "Rock_Sandstone_Brick",
      "rotation": 3
    },
    {
      "x": -7,
      "y": 9,
      "z": 2,
      "name": "Rock_Sandstone_Brick",
      "rotation": 3
    },
    {
      "x": -7,
      "y": 10,
      "z": 2,
      "name": "Rock_Sandstone_Brick",
      "rotation": 3
    },
    {
      "x": -7,
      "y": 11,
      "z": 2,
      "name": "Rock_Sandstone_Red_Brick",
      "rotation": 3
    },
    {
      "x": -7,
      "y": 12,
      "z": 2,
      "name": "Rock_Sandstone_Brick",
      "rotation": 3
    },
    {
      "x": -7,
      "y": 13,
      "z": 2,
      "name": "Rock_Sandstone_Cobble",
      "rotation": 3
    },
    {
      "x": -7,
      "y": 14,
      "z": 2,
      "name": "Rock_Sandstone_Cobble",
      "rotation": 3
    },
    {
      "x": -7,
      "y": 15,
      "z": 2,
      "name": "Rock_Sandstone_Cobble",
      "rotation": 3
    },
    {
      "x": -7,
      "y": 16,
      "z": 2,
      "name": "Rock_Sandstone_Cobble",
      "rotation": 3
    },
    {
      "x": -7,
      "y": 17,
      "z": 2,
      "name": "Rock_Sandstone_Cobble",
      "rotation": 3
    },
    {
      "x": -7,
      "y": 18,
      "z": 2,
      "name": "Rock_Sandstone_Brick",
      "rotation": 3
    },
    {
      "x": -7,
      "y": 19,
      "z": 2,
      "name": "Rock_Sandstone_Brick",
      "rotation": 3
    },
    {
      "x": -7,
      "y": 8,
      "z": 3,
      "name": "Rock_Sandstone_Brick",
      "rotation": 3
    },
    {
      "x": -7,
      "y": 9,
      "z": 3,
      "name": "Rock_Sandstone_Brick",
      "rotation": 3
    },
    {
      "x": -7,
      "y": 10,
      "z": 3,
      "name": "Rock_Sandstone_Brick",
      "rotation": 3
    },
    {
      "x": -7,
      "y": 11,
      "z": 3,
      "name": "Rock_Sandstone_Red_Brick",
      "rotation": 3
    },
    {
      "x": -7,
      "y": 12,
      "z": 3,
      "name": "Rock_Sandstone_Brick",
      "rotation": 3
    },
    {
      "x": -7,
      "y": 13,
      "z": 3,
      "name": "Rock_Sandstone_Cobble",
      "rotation": 3
    },
    {
      "x": -7,
      "y": 14,
      "z": 3,
      "name": "Rock_Sandstone_Cobble",
      "rotation": 3
    },
    {
      "x": -7,
      "y": 15,
      "z": 3,
      "name": "Rock_Sandstone_Cobble",
      "rotation": 3
    },
    {
      "x": -7,
      "y": 16,
      "z": 3,
      "name": "Rock_Sandstone_Cobble",
      "rotation": 3
    },
    {
      "x": -7,
      "y": 17,
      "z": 3,
      "name": "Rock_Sandstone_Cobble",
      "rotation": 3
    },
    {
      "x": -7,
      "y": 18,
      "z": 3,
      "name": "Rock_Sandstone_Brick",
      "rotation": 3
    },
    {
      "x": -7,
      "y": 19,
      "z": 3,
      "name": "Rock_Sandstone_Brick",
      "rotation": 3
    },
    {
      "x": -7,
      "y": 8,
      "z": 4,
      "name": "Rock_Sandstone_Brick"
    },
    {
      "x": -7,
      "y": 9,
      "z": 4,
      "name": "Rock_Sandstone_Brick",
      "rotation": 3
    },
    {
      "x": -7,
      "y": 10,
      "z": 4,
      "name": "Rock_Sandstone_Brick",
      "rotation": 3
    },
    {
      "x": -7,
      "y": 11,
      "z": 4,
      "name": "Rock_Sandstone_Red_Brick",
      "rotation": 3
    },
    {
      "x": -7,
      "y": 12,
      "z": 4,
      "name": "Rock_Sandstone_Brick",
      "rotation": 3
    },
    {
      "x": -7,
      "y": 13,
      "z": 4,
      "name": "Rock_Sandstone_Cobble",
      "rotation": 3
    },
    {
      "x": -7,
      "y": 14,
      "z": 4,
      "name": "Rock_Sandstone_Cobble",
      "rotation": 3
    },
    {
      "x": -7,
      "y": 15,
      "z": 4,
      "name": "Rock_Sandstone_Cobble",
      "rotation": 3
    },
    {
      "x": -7,
      "y": 16,
      "z": 4,
      "name": "Rock_Sandstone_Cobble",
      "rotation": 3
    },
    {
      "x": -7,
      "y": 17,
      "z": 4,
      "name": "Rock_Sandstone_Cobble",
      "rotation": 3
    },
    {
      "x": -7,
      "y": 18,
      "z": 4,
      "name": "Rock_Sandstone_Brick",
      "rotation": 3
    },
    {
      "x": -7,
      "y": 19,
      "z": 4,
      "name": "Rock_Sandstone_Brick",
      "rotation": 3
    },
    {
      "x": -7,
      "y": 20,
      "z": 4,
      "name": "Rock_Sandstone_Brick_Half",
      "rotation": 3
    },
    {
      "x": -7,
      "y": 8,
      "z": 5,
      "name": "Rock_Sandstone_Brick",
      "rotation": 3
    },
    {
      "x": -7,
      "y": 9,
      "z": 5,
      "name": "Rock_Sandstone_Brick",
      "rotation": 3
    },
    {
      "x": -7,
      "y": 10,
      "z": 5,
      "name": "Rock_Sandstone_Brick",
      "rotation": 3
    },
    {
      "x": -7,
      "y": 11,
      "z": 5,
      "name": "Rock_Sandstone_Red_Brick",
      "rotation": 3
    },
    {
      "x": -7,
      "y": 12,
      "z": 5,
      "name": "Rock_Sandstone_Brick",
      "rotation": 3
    },
    {
      "x": -7,
      "y": 13,
      "z": 5,
      "name": "Rock_Sandstone_Cobble",
      "rotation": 3
    },
    {
      "x": -7,
      "y": 14,
      "z": 5,
      "name": "Rock_Sandstone_Cobble",
      "rotation": 3
    },
    {
      "x": -7,
      "y": 15,
      "z": 5,
      "name": "Rock_Sandstone_Cobble",
      "rotation": 3
    },
    {
      "x": -7,
      "y": 16,
      "z": 5,
      "name": "Rock_Sandstone_Cobble",
      "rotation": 3
    },
    {
      "x": -7,
      "y": 17,
      "z": 5,
      "name": "Rock_Sandstone_Cobble",
      "rotation": 3
    },
    {
      "x": -7,
      "y": 18,
      "z": 5,
      "name": "Rock_Sandstone_Brick",
      "rotation": 3
    },
    {
      "x": -7,
      "y": 19,
      "z": 5,
      "name": "Rock_Sandstone_Brick",
      "rotation": 3
    },
    {
      "x": -7,
      "y": 20,
      "z": 5,
      "name": "Rock_Sandstone_Brick_Half",
      "rotation": 3
    },
    {
      "x": -7,
      "y": 8,
      "z": 6,
      "name": "Rock_Sandstone_Brick",
      "rotation": 3
    },
    {
      "x": -7,
      "y": 9,
      "z": 6,
      "name": "Rock_Sandstone_Brick",
      "rotation": 3
    },
    {
      "x": -7,
      "y": 10,
      "z": 6,
      "name": "Rock_Sandstone_Brick",
      "rotation": 3
    },
    {
      "x": -7,
      "y": 11,
      "z": 6,
      "name": "Rock_Sandstone_Red_Brick",
      "rotation": 3
    },
    {
      "x": -7,
      "y": 12,
      "z": 6,
      "name": "Rock_Sandstone_Brick",
      "rotation": 3
    },
    {
      "x": -7,
      "y": 13,
      "z": 6,
      "name": "Rock_Sandstone_Cobble",
      "rotation": 3
    },
    {
      "x": -7,
      "y": 14,
      "z": 6,
      "name": "Rock_Sandstone_Cobble",
      "rotation": 3
    },
    {
      "x": -7,
      "y": 15,
      "z": 6,
      "name": "Rock_Sandstone_Cobble",
      "rotation": 3
    },
    {
      "x": -7,
      "y": 16,
      "z": 6,
      "name": "Rock_Sandstone_Cobble",
      "rotation": 3
    },
    {
      "x": -7,
      "y": 17,
      "z": 6,
      "name": "Rock_Sandstone_Cobble",
      "rotation": 3
    },
    {
      "x": -7,
      "y": 18,
      "z": 6,
      "name": "Rock_Sandstone_Brick",
      "rotation": 3
    },
    {
      "x": -7,
      "y": 19,
      "z": 6,
      "name": "Rock_Sandstone_Brick",
      "rotation": 3
    },
    {
      "x": -7,
      "y": 8,
      "z": 7,
      "name": "Rock_Sandstone_Brick",
      "rotation": 3
    },
    {
      "x": -7,
      "y": 9,
      "z": 7,
      "name": "Rock_Sandstone_Brick",
      "rotation": 3
    },
    {
      "x": -7,
      "y": 10,
      "z": 7,
      "name": "Rock_Sandstone_Brick",
      "rotation": 3
    },
    {
      "x": -7,
      "y": 11,
      "z": 7,
      "name": "Rock_Sandstone_Red_Brick",
      "rotation": 3
    },
    {
      "x": -7,
      "y": 12,
      "z": 7,
      "name": "Rock_Sandstone_Brick",
      "rotation": 3
    },
    {
      "x": -7,
      "y": 13,
      "z": 7,
      "name": "Rock_Sandstone_Cobble",
      "rotation": 3
    },
    {
      "x": -7,
      "y": 14,
      "z": 7,
      "name": "Rock_Sandstone_Cobble",
      "rotation": 3
    },
    {
      "x": -7,
      "y": 15,
      "z": 7,
      "name": "Rock_Sandstone_Cobble",
      "rotation": 3
    },
    {
      "x": -7,
      "y": 16,
      "z": 7,
      "name": "Rock_Sandstone_Cobble",
      "rotation": 3
    },
    {
      "x": -7,
      "y": 17,
      "z": 7,
      "name": "Rock_Sandstone_Cobble",
      "rotation": 3
    },
    {
      "x": -7,
      "y": 18,
      "z": 7,
      "name": "Rock_Sandstone_Brick",
      "rotation": 3
    },
    {
      "x": -7,
      "y": 19,
      "z": 7,
      "name": "Rock_Sandstone_Brick",
      "rotation": 3
    },
    {
      "x": -7,
      "y": 8,
      "z": 8,
      "name": "Rock_Sandstone_Brick",
      "rotation": 3
    },
    {
      "x": -7,
      "y": 9,
      "z": 8,
      "name": "Rock_Sandstone_Brick",
      "rotation": 3
    },
    {
      "x": -7,
      "y": 10,
      "z": 8,
      "name": "Rock_Sandstone_Brick",
      "rotation": 3
    },
    {
      "x": -7,
      "y": 11,
      "z": 8,
      "name": "Rock_Sandstone_Brick",
      "rotation": 3
    },
    {
      "x": -7,
      "y": 12,
      "z": 8,
      "name": "Rock_Sandstone_Brick",
      "rotation": 3
    },
    {
      "x": -7,
      "y": 13,
      "z": 8,
      "name": "Rock_Sandstone_Cobble",
      "rotation": 3
    },
    {
      "x": -7,
      "y": 15,
      "z": 8,
      "name": "Rock_Sandstone_Brick",
      "rotation": 3
    },
    {
      "x": -7,
      "y": 16,
      "z": 8,
      "name": "Rock_Sandstone_Brick",
      "rotation": 3
    },
    {
      "x": -7,
      "y": 17,
      "z": 8,
      "name": "Rock_Sandstone_Brick",
      "rotation": 3
    },
    {
      "x": -7,
      "y": 18,
      "z": 8,
      "name": "Rock_Sandstone_Brick",
      "rotation": 3
    },
    {
      "x": -7,
      "y": 8,
      "z": 9,
      "name": "Rock_Sandstone_Brick",
      "rotation": 3
    },
    {
      "x": -7,
      "y": 9,
      "z": 9,
      "name": "Rock_Sandstone_Brick",
      "rotation": 3
    },
    {
      "x": -7,
      "y": 10,
      "z": 9,
      "name": "Rock_Sandstone_Brick",
      "rotation": 3
    },
    {
      "x": -7,
      "y": 11,
      "z": 9,
      "name": "Rock_Sandstone_Brick",
      "rotation": 3
    },
    {
      "x": -7,
      "y": 12,
      "z": 9,
      "name": "Rock_Sandstone_Brick_Ornate",
      "rotation": 3
    },
    {
      "x": -7,
      "y": 8,
      "z": 10,
      "name": "Rock_Sandstone_Red_Brick",
      "rotation": 3
    },
    {
      "x": -7,
      "y": 9,
      "z": 10,
      "name": "Rock_Sandstone_Red_Brick",
      "rotation": 3
    },
    {
      "x": -7,
      "y": 10,
      "z": 10,
      "name": "Rock_Sandstone_Red_Brick",
      "rotation": 3
    },
    {
      "x": -7,
      "y": 11,
      "z": 10,
      "name": "Rock_Sandstone_Red_Brick_Stairs"
    },
    {
      "x": -7,
      "y": 8,
      "z": 11,
      "name": "Rock_Sandstone_Red_Cobble",
      "rotation": 3
    },
    {
      "x": -7,
      "y": 9,
      "z": 11,
      "name": "Rock_Sandstone_Red_Brick",
      "rotation": 3
    },
    {
      "x": -7,
      "y": 10,
      "z": 11,
      "name": "Rock_Sandstone_Red_Brick_Stairs"
    },
    {
      "x": -6,
      "y": 8,
      "z": -9,
      "name": "Rock_Sandstone_Cobble_Half"
    },
    {
      "x": -6,
      "y": 8,
      "z": -8,
      "name": "Rock_Sandstone_Cobble",
      "rotation": 3
    },
    {
      "x": -6,
      "y": 9,
      "z": -8,
      "name": "Rock_Sandstone_Cobble",
      "rotation": 3
    },
    {
      "x": -6,
      "y": 10,
      "z": -8,
      "name": "Rock_Sandstone_Cobble",
      "rotation": 3
    },
    {
      "x": -6,
      "y": 11,
      "z": -8,
      "name": "Rock_Sandstone_Cobble",
      "rotation": 3
    },
    {
      "x": -6,
      "y": 12,
      "z": -8,
      "name": "Rock_Sandstone_Brick_Ornate",
      "rotation": 3
    },
    {
      "x": -6,
      "y": 13,
      "z": -8,
      "name": "Rock_Sandstone_Brick_Stairs",
      "rotation": 2
    },
    {
      "x": -6,
      "y": 8,
      "z": -7,
      "name": "Rock_Sandstone_Brick",
      "rotation": 3
    },
    {
      "x": -6,
      "y": 9,
      "z": -7,
      "name": "Rock_Sandstone_Brick",
      "rotation": 3
    },
    {
      "x": -6,
      "y": 10,
      "z": -7,
      "name": "Rock_Sandstone_Brick",
      "rotation": 3
    },
    {
      "x": -6,
      "y": 11,
      "z": -7,
      "name": "Rock_Sandstone_Brick",
      "rotation": 3
    },
    {
      "x": -6,
      "y": 12,
      "z": -7,
      "name": "Rock_Sandstone_Brick",
      "rotation": 3
    },
    {
      "x": -6,
      "y": 13,
      "z": -7,
      "name": "Rock_Sandstone_Cobble",
      "rotation": 3
    },
    {
      "x": -6,
      "y": 14,
      "z": -7,
      "name": "Rock_Sandstone_Cobble"
    },
    {
      "x": -6,
      "y": 15,
      "z": -7,
      "name": "Rock_Sandstone_Cobble"
    },
    {
      "x": -6,
      "y": 8,
      "z": -6,
      "name": "Rock_Sandstone_Brick"
    },
    {
      "x": -6,
      "y": 9,
      "z": -6,
      "name": "Rock_Sandstone_Brick",
      "rotation": 3
    },
    {
      "x": -6,
      "y": 10,
      "z": -6,
      "name": "Rock_Sandstone_Brick",
      "rotation": 3
    },
    {
      "x": -6,
      "y": 11,
      "z": -6,
      "name": "Soil_Sand",
      "rotation": 3
    },
    {
      "x": -6,
      "y": 12,
      "z": -6,
      "name": "Soil_Sand",
      "rotation": 3
    },
    {
      "x": -6,
      "y": 13,
      "z": -6,
      "name": "Rubble_Sandstone"
    },
    {
      "x": -6,
      "y": 16,
      "z": -6,
      "name": "Rock_Sandstone_Red_Brick"
    },
    {
      "x": -6,
      "y": 8,
      "z": -5,
      "name": "Rock_Sandstone_Brick"
    },
    {
      "x": -6,
      "y": 9,
      "z": -5,
      "name": "Rock_Sandstone_Brick",
      "rotation": 3
    },
    {
      "x": -6,
      "y": 10,
      "z": -5,
      "name": "Soil_Sand",
      "rotation": 3
    },
    {
      "x": -6,
      "y": 11,
      "z": -5,
      "name": "Soil_Sand",
      "rotation": 3
    },
    {
      "x": -6,
      "y": 16,
      "z": -5,
      "name": "Rock_Sandstone_Red_Brick"
    },
    {
      "x": -6,
      "y": 17,
      "z": -5,
      "name": "Rock_Sandstone_Red_Brick"
    },
    {
      "x": -6,
      "y": 8,
      "z": -4,
      "name": "Rock_Sandstone_Brick"
    },
    {
      "x": -6,
      "y": 9,
      "z": -4,
      "name": "Rock_Sandstone_Brick",
      "rotation": 3
    },
    {
      "x": -6,
      "y": 10,
      "z": -4,
      "name": "Soil_Sand",
      "rotation": 3
    },
    {
      "x": -6,
      "y": 16,
      "z": -4,
      "name": "Rock_Sandstone_Red_Brick"
    },
    {
      "x": -6,
      "y": 17,
      "z": -4,
      "name": "Rock_Sandstone_Red_Brick"
    },
    {
      "x": -6,
      "y": 18,
      "z": -4,
      "name": "Rock_Sandstone_Cobble"
    },
    {
      "x": -6,
      "y": 8,
      "z": -3,
      "name": "Rock_Sandstone_Brick"
    },
    {
      "x": -6,
      "y": 9,
      "z": -3,
      "name": "Rock_Sandstone_Brick",
      "rotation": 3
    },
    {
      "x": -6,
      "y": 10,
      "z": -3,
      "name": "Soil_Sand",
      "rotation": 3
    },
    {
      "x": -6,
      "y": 11,
      "z": -3,
      "name": "Rubble_Sandstone",
      "rotation": 3
    },
    {
      "x": -6,
      "y": 16,
      "z": -3,
      "name": "Rock_Sandstone_Red_Brick"
    },
    {
      "x": -6,
      "y": 17,
      "z": -3,
      "name": "Rock_Sandstone_Red_Brick"
    },
    {
      "x": -6,
      "y": 18,
      "z": -3,
      "name": "Rock_Sandstone_Cobble"
    },
    {
      "x": -6,
      "y": 8,
      "z": -2,
      "name": "Rock_Sandstone_Brick"
    },
    {
      "x": -6,
      "y": 9,
      "z": -2,
      "name": "Rock_Sandstone_Brick",
      "rotation": 3
    },
    {
      "x": -6,
      "y": 10,
      "z": -2,
      "name": "Rock_Sandstone_Brick",
      "rotation": 3
    },
    {
      "x": -6,
      "y": 16,
      "z": -2,
      "name": "Rock_Sandstone_Red_Brick"
    },
    {
      "x": -6,
      "y": 17,
      "z": -2,
      "name": "Rock_Sandstone_Red_Brick"
    },
    {
      "x": -6,
      "y": 18,
      "z": -2,
      "name": "Rock_Sandstone_Cobble"
    },
    {
      "x": -6,
      "y": 19,
      "z": -2,
      "name": "Rock_Sandstone_Brick"
    },
    {
      "x": -6,
      "y": 8,
      "z": -1,
      "name": "Rock_Sandstone_Brick"
    },
    {
      "x": -6,
      "y": 16,
      "z": -1,
      "name": "Rock_Sandstone_Red_Brick"
    },
    {
      "x": -6,
      "y": 17,
      "z": -1,
      "name": "Rock_Sandstone_Red_Brick",
      "rotation": 3
    },
    {
      "x": -6,
      "y": 18,
      "z": -1,
      "name": "Rock_Sandstone_Cobble"
    },
    {
      "x": -6,
      "y": 19,
      "z": -1,
      "name": "Rock_Sandstone_Brick"
    },
    {
      "x": -6,
      "y": 20,
      "z": -1,
      "name": "Rock_Sandstone_Brick_Smooth_Half",
      "rotation": 6
    },
    {
      "x": -6,
      "y": 21,
      "z": -1,
      "name": "Rock_Sandstone_Brick_Half",
      "rotation": 6
    },
    {
      "x": -6,
      "y": 22,
      "z": -1,
      "name": "Rock_Sandstone_Brick_Half",
      "rotation": 6
    },
    {
      "x": -6,
      "y": 23,
      "z": -1,
      "name": "Rock_Sandstone_Brick_Half",
      "rotation": 6
    },
    {
      "x": -6,
      "y": 24,
      "z": -1,
      "name": "Rock_Sandstone_Brick_Half",
      "rotation": 6
    },
    {
      "x": -6,
      "y": 25,
      "z": -1,
      "name": "Rock_Sandstone_Brick_Smooth_Half",
      "rotation": 6
    },
    {
      "x": -6,
      "y": 8,
      "z": 0,
      "name": "Rock_Sandstone_Brick"
    },
    {
      "x": -6,
      "y": 16,
      "z": 0,
      "name": "Rock_Sandstone_Red_Cobble",
      "rotation": 3
    },
    {
      "x": -6,
      "y": 17,
      "z": 0,
      "name": "Rock_Sandstone_Red_Brick",
      "rotation": 3
    },
    {
      "x": -6,
      "y": 18,
      "z": 0,
      "name": "Rock_Sandstone_Cobble"
    },
    {
      "x": -6,
      "y": 19,
      "z": 0,
      "name": "Rock_Sandstone_Brick"
    },
    {
      "x": -6,
      "y": 25,
      "z": 0,
      "name": "Rock_Sandstone_Brick_Smooth_Half",
      "rotation": 4
    },
    {
      "x": -6,
      "y": 26,
      "z": 0,
      "name": "Rock_Sandstone_Brick_Stairs",
      "rotation": 2
    },
    {
      "x": -6,
      "y": 27,
      "z": 0,
      "name": "Rock_Gold_Brick_Smooth_Half",
      "rotation": 7
    },
    {
      "x": -6,
      "y": 8,
      "z": 1,
      "name": "Rock_Sandstone_Brick"
    },
    {
      "x": -6,
      "y": 15,
      "z": 1,
      "name": "Rock_Sandstone_Brick_Stairs",
      "rotation": 11
    },
    {
      "x": -6,
      "y": 16,
      "z": 1,
      "name": "Rock_Sandstone_Red_Brick",
      "rotation": 3
    },
    {
      "x": -6,
      "y": 17,
      "z": 1,
      "name": "Rock_Sandstone_Red_Brick",
      "rotation": 3
    },
    {
      "x": -6,
      "y": 18,
      "z": 1,
      "name": "Rock_Sandstone_Cobble"
    },
    {
      "x": -6,
      "y": 19,
      "z": 1,
      "name": "Rock_Sandstone_Brick"
    },
    {
      "x": -6,
      "y": 26,
      "z": 1,
      "name": "Rock_Sandstone_Brick_Smooth_Half",
      "rotation": 9
    },
    {
      "x": -6,
      "y": 27,
      "z": 1,
      "name": "Rock_Sandstone_Brick_Smooth_Half",
      "rotation": 1
    },
    {
      "x": -6,
      "y": 8,
      "z": 2,
      "name": "Rock_Sandstone_Brick"
    },
    {
      "x": -6,
      "y": 15,
      "z": 2,
      "name": "Rock_Sandstone_Brick_Stairs",
      "rotation": 11
    },
    {
      "x": -6,
      "y": 16,
      "z": 2,
      "name": "Rock_Sandstone_Red_Brick",
      "rotation": 3
    },
    {
      "x": -6,
      "y": 17,
      "z": 2,
      "name": "Rock_Sandstone_Red_Brick",
      "rotation": 3
    },
    {
      "x": -6,
      "y": 18,
      "z": 2,
      "name": "Rock_Sandstone_Cobble",
      "rotation": 3
    },
    {
      "x": -6,
      "y": 19,
      "z": 2,
      "name": "Rock_Sandstone_Brick"
    },
    {
      "x": -6,
      "y": 25,
      "z": 2,
      "name": "Rock_Sandstone_Brick_Smooth_Half",
      "rotation": 6
    },
    {
      "x": -6,
      "y": 26,
      "z": 2,
      "name": "Rock_Sandstone_Brick_Stairs"
    },
    {
      "x": -6,
      "y": 27,
      "z": 2,
      "name": "Rock_Gold_Brick_Smooth_Half",
      "rotation": 7
    },
    {
      "x": -6,
      "y": 8,
      "z": 3,
      "name": "Rock_Sandstone_Brick",
      "rotation": 3
    },
    {
      "x": -6,
      "y": 9,
      "z": 3,
      "name": "Rock_Sandstone_Brick",
      "rotation": 3
    },
    {
      "x": -6,
      "y": 10,
      "z": 3,
      "name": "Rock_Sandstone_Brick",
      "rotation": 3
    },
    {
      "x": -6,
      "y": 15,
      "z": 3,
      "name": "Rock_Sandstone_Brick_Stairs",
      "rotation": 11
    },
    {
      "x": -6,
      "y": 16,
      "z": 3,
      "name": "Rock_Sandstone_Red_Brick",
      "rotation": 3
    },
    {
      "x": -6,
      "y": 17,
      "z": 3,
      "name": "Rock_Sandstone_Red_Brick",
      "rotation": 3
    },
    {
      "x": -6,
      "y": 18,
      "z": 3,
      "name": "Rock_Sandstone_Cobble",
      "rotation": 3
    },
    {
      "x": -6,
      "y": 19,
      "z": 3,
      "name": "Rock_Sandstone_Brick"
    },
    {
      "x": -6,
      "y": 20,
      "z": 3,
      "name": "Rock_Sandstone_Brick_Smooth_Half",
      "rotation": 4
    },
    {
      "x": -6,
      "y": 21,
      "z": 3,
      "name": "Rock_Sandstone_Brick_Half",
      "rotation": 4
    },
    {
      "x": -6,
      "y": 22,
      "z": 3,
      "name": "Rock_Sandstone_Brick_Half",
      "rotation": 4
    },
    {
      "x": -6,
      "y": 23,
      "z": 3,
      "name": "Rock_Sandstone_Brick_Half",
      "rotation": 4
    },
    {
      "x": -6,
      "y": 24,
      "z": 3,
      "name": "Rock_Sandstone_Brick_Half",
      "rotation": 4
    },
    {
      "x": -6,
      "y": 25,
      "z": 3,
      "name": "Rock_Sandstone_Brick_Smooth_Half",
      "rotation": 4
    },
    {
      "x": -6,
      "y": 8,
      "z": 4,
      "name": "Rock_Sandstone_Brick"
    },
    {
      "x": -6,
      "y": 9,
      "z": 4,
      "name": "Rock_Sandstone_Brick",
      "rotation": 3
    },
    {
      "x": -6,
      "y": 10,
      "z": 4,
      "name": "Soil_Sand"
    },
    {
      "x": -6,
      "y": 15,
      "z": 4,
      "name": "Rock_Sandstone_Brick_Stairs",
      "rotation": 11
    },
    {
      "x": -6,
      "y": 16,
      "z": 4,
      "name": "Rock_Sandstone_Red_Brick",
      "rotation": 3
    },
    {
      "x": -6,
      "y": 17,
      "z": 4,
      "name": "Rock_Sandstone_Red_Brick",
      "rotation": 3
    },
    {
      "x": -6,
      "y": 18,
      "z": 4,
      "name": "Rock_Sandstone_Cobble",
      "rotation": 3
    },
    {
      "x": -6,
      "y": 19,
      "z": 4,
      "name": "Rock_Sandstone_Brick"
    },
    {
      "x": -6,
      "y": 8,
      "z": 5,
      "name": "Rock_Sandstone_Brick"
    },
    {
      "x": -6,
      "y": 9,
      "z": 5,
      "name": "Rock_Sandstone_Brick",
      "rotation": 3
    },
    {
      "x": -6,
      "y": 10,
      "z": 5,
      "name": "Soil_Sand"
    },
    {
      "x": -6,
      "y": 15,
      "z": 5,
      "name": "Rock_Sandstone_Brick_Stairs",
      "rotation": 11
    },
    {
      "x": -6,
      "y": 16,
      "z": 5,
      "name": "Rock_Sandstone_Red_Brick",
      "rotation": 3
    },
    {
      "x": -6,
      "y": 17,
      "z": 5,
      "name": "Rock_Sandstone_Red_Brick",
      "rotation": 3
    },
    {
      "x": -6,
      "y": 18,
      "z": 5,
      "name": "Rock_Sandstone",
      "rotation": 3
    },
    {
      "x": -6,
      "y": 19,
      "z": 5,
      "name": "Rock_Sandstone_Brick"
    },
    {
      "x": -6,
      "y": 8,
      "z": 6,
      "name": "Rock_Sandstone_Brick"
    },
    {
      "x": -6,
      "y": 9,
      "z": 6,
      "name": "Rock_Sandstone_Brick",
      "rotation": 3
    },
    {
      "x": -6,
      "y": 10,
      "z": 6,
      "name": "Soil_Sand"
    },
    {
      "x": -6,
      "y": 11,
      "z": 6,
      "name": "Soil_Sand"
    },
    {
      "x": -6,
      "y": 15,
      "z": 6,
      "name": "Rock_Sandstone_Brick_Stairs",
      "rotation": 11
    },
    {
      "x": -6,
      "y": 16,
      "z": 6,
      "name": "Rock_Sandstone_Red_Brick",
      "rotation": 3
    },
    {
      "x": -6,
      "y": 17,
      "z": 6,
      "name": "Rock_Sandstone_Red_Brick",
      "rotation": 3
    },
    {
      "x": -6,
      "y": 18,
      "z": 6,
      "name": "Rock_Sandstone",
      "rotation": 3
    },
    {
      "x": -6,
      "y": 19,
      "z": 6,
      "name": "Rock_Sandstone_Brick"
    },
    {
      "x": -6,
      "y": 8,
      "z": 7,
      "name": "Rock_Sandstone_Brick"
    },
    {
      "x": -6,
      "y": 9,
      "z": 7,
      "name": "Rock_Sandstone_Brick",
      "rotation": 3
    },
    {
      "x": -6,
      "y": 10,
      "z": 7,
      "name": "Rock_Sandstone_Brick",
      "rotation": 3
    },
    {
      "x": -6,
      "y": 11,
      "z": 7,
      "name": "Soil_Sand"
    },
    {
      "x": -6,
      "y": 12,
      "z": 7,
      "name": "Soil_Sand"
    },
    {
      "x": -6,
      "y": 15,
      "z": 7,
      "name": "*Rock_Sandstone_Brick_Stairs_State_Definitions_Inverted_Corner_Right",
      "rotation": 11
    },
    {
      "x": -6,
      "y": 16,
      "z": 7,
      "name": "Rock_Sandstone_Red_Brick",
      "rotation": 3
    },
    {
      "x": -6,
      "y": 17,
      "z": 7,
      "name": "Rock_Sandstone_Red_Brick",
      "rotation": 3
    },
    {
      "x": -6,
      "y": 18,
      "z": 7,
      "name": "Rock_Sandstone",
      "rotation": 3
    },
    {
      "x": -6,
      "y": 19,
      "z": 7,
      "name": "Rock_Sandstone_Brick"
    },
    {
      "x": -6,
      "y": 8,
      "z": 8,
      "name": "Rock_Sandstone_Brick",
      "rotation": 3
    },
    {
      "x": -6,
      "y": 9,
      "z": 8,
      "name": "Rock_Sandstone_Brick",
      "rotation": 3
    },
    {
      "x": -6,
      "y": 10,
      "z": 8,
      "name": "Rock_Sandstone_Brick",
      "rotation": 3
    },
    {
      "x": -6,
      "y": 11,
      "z": 8,
      "name": "Rock_Sandstone_Brick",
      "rotation": 3
    },
    {
      "x": -6,
      "y": 12,
      "z": 8,
      "name": "Rock_Sandstone_Brick",
      "rotation": 3
    },
    {
      "x": -6,
      "y": 13,
      "z": 8,
      "name": "Rock_Sandstone_Cobble",
      "rotation": 3
    },
    {
      "x": -6,
      "y": 14,
      "z": 8,
      "name": "Rock_Sandstone_Cobble",
      "rotation": 3
    },
    {
      "x": -6,
      "y": 15,
      "z": 8,
      "name": "Rock_Sandstone_Cobble",
      "rotation": 3
    },
    {
      "x": -6,
      "y": 16,
      "z": 8,
      "name": "Rock_Sandstone_Brick",
      "rotation": 3
    },
    {
      "x": -6,
      "y": 17,
      "z": 8,
      "name": "Rock_Sandstone_Brick",
      "rotation": 3
    },
    {
      "x": -6,
      "y": 18,
      "z": 8,
      "name": "Rock_Sandstone_Brick",
      "rotation": 3
    },
    {
      "x": -6,
      "y": 19,
      "z": 8,
      "name": "Rock_Sandstone_Brick",
      "rotation": 3
    },
    {
      "x": -6,
      "y": 8,
      "z": 9,
      "name": "Rock_Sandstone_Cobble",
      "rotation": 3
    },
    {
      "x": -6,
      "y": 9,
      "z": 9,
      "name": "Rock_Sandstone_Cobble",
      "rotation": 3
    },
    {
      "x": -6,
      "y": 10,
      "z": 9,
      "name": "Rock_Sandstone_Cobble",
      "rotation": 3
    },
    {
      "x": -6,
      "y": 11,
      "z": 9,
      "name": "Rock_Sandstone_Cobble",
      "rotation": 3
    },
    {
      "x": -6,
      "y": 12,
      "z": 9,
      "name": "Rock_Sandstone_Brick_Ornate",
      "rotation": 3
    },
    {
      "x": -6,
      "y": 13,
      "z": 9,
      "name": "Rock_Sandstone_Brick_Stairs"
    },
    {
      "x": -6,
      "y": 8,
      "z": 10,
      "name": "Soil_Sand"
    },
    {
      "x": -6,
      "y": 9,
      "z": 10,
      "name": "Soil_Sand"
    },
    {
      "x": -5,
      "y": 8,
      "z": -9,
      "name": "Rock_Sandstone"
    },
    {
      "x": -5,
      "y": 8,
      "z": -8,
      "name": "Rock_Sandstone_Cobble",
      "rotation": 3
    },
    {
      "x": -5,
      "y": 9,
      "z": -8,
      "name": "Rock_Sandstone_Cobble",
      "rotation": 3
    },
    {
      "x": -5,
      "y": 10,
      "z": -8,
      "name": "Rock_Sandstone_Cobble",
      "rotation": 3
    },
    {
      "x": -5,
      "y": 11,
      "z": -8,
      "name": "Rock_Sandstone_Cobble",
      "rotation": 3
    },
    {
      "x": -5,
      "y": 12,
      "z": -8,
      "name": "Rock_Sandstone_Brick_Ornate",
      "rotation": 3
    },
    {
      "x": -5,
      "y": 13,
      "z": -8,
      "name": "Rock_Sandstone_Brick_Stairs",
      "rotation": 2
    },
    {
      "x": -5,
      "y": 8,
      "z": -7,
      "name": "Rock_Sandstone_Brick",
      "rotation": 3
    },
    {
      "x": -5,
      "y": 9,
      "z": -7,
      "name": "Rock_Sandstone_Brick",
      "rotation": 3
    },
    {
      "x": -5,
      "y": 10,
      "z": -7,
      "name": "Rock_Sandstone_Brick",
      "rotation": 3
    },
    {
      "x": -5,
      "y": 11,
      "z": -7,
      "name": "Rock_Sandstone_Brick",
      "rotation": 3
    },
    {
      "x": -5,
      "y": 12,
      "z": -7,
      "name": "Rock_Sandstone_Brick",
      "rotation": 3
    },
    {
      "x": -5,
      "y": 13,
      "z": -7,
      "name": "Rock_Sandstone_Cobble",
      "rotation": 3
    },
    {
      "x": -5,
      "y": 14,
      "z": -7,
      "name": "Rock_Sandstone_Cobble",
      "rotation": 3
    },
    {
      "x": -5,
      "y": 15,
      "z": -7,
      "name": "Rock_Sandstone_Cobble",
      "rotation": 3
    },
    {
      "x": -5,
      "y": 16,
      "z": -7,
      "name": "Rock_Sandstone_Cobble"
    },
    {
      "x": -5,
      "y": 8,
      "z": -6,
      "name": "Rock_Sandstone_Brick"
    },
    {
      "x": -5,
      "y": 9,
      "z": -6,
      "name": "Rock_Sandstone_Brick_Stairs",
      "rotation": 11
    },
    {
      "x": -5,
      "y": 10,
      "z": -6,
      "name": "Rock_Sandstone_Brick",
      "rotation": 3
    },
    {
      "x": -5,
      "y": 11,
      "z": -6,
      "name": "Soil_Sand",
      "rotation": 3
    },
    {
      "x": -5,
      "y": 16,
      "z": -6,
      "name": "Rock_Sandstone_Red_Brick"
    },
    {
      "x": -5,
      "y": 17,
      "z": -6,
      "name": "Rock_Sandstone_Red_Brick"
    },
    {
      "x": -5,
      "y": 8,
      "z": -5,
      "name": "Rock_Sandstone_Brick"
    },
    {
      "x": -5,
      "y": 9,
      "z": -5,
      "name": "Rock_Sandstone_Brick_Stairs",
      "rotation": 11
    },
    {
      "x": -5,
      "y": 10,
      "z": -5,
      "name": "Rock_Sandstone_Brick",
      "rotation": 3
    },
    {
      "x": -5,
      "y": 8,
      "z": -4,
      "name": "Rock_Sandstone_Brick"
    },
    {
      "x": -5,
      "y": 9,
      "z": -4,
      "name": "Rock_Sandstone_Brick_Stairs",
      "rotation": 11
    },
    {
      "x": -5,
      "y": 10,
      "z": -4,
      "name": "Rock_Sandstone_Brick",
      "rotation": 3
    },
    {
      "x": -5,
      "y": 18,
      "z": -4,
      "name": "Rock_Sandstone_Cobble"
    },
    {
      "x": -5,
      "y": 8,
      "z": -3,
      "name": "Rock_Sandstone_Brick"
    },
    {
      "x": -5,
      "y": 9,
      "z": -3,
      "name": "Rock_Sandstone_Brick_Stairs",
      "rotation": 11
    },
    {
      "x": -5,
      "y": 10,
      "z": -3,
      "name": "Rock_Sandstone_Brick",
      "rotation": 3
    },
    {
      "x": -5,
      "y": 18,
      "z": -3,
      "name": "Rock_Sandstone_Cobble"
    },
    {
      "x": -5,
      "y": 19,
      "z": -3,
      "name": "Rock_Sandstone_Brick"
    },
    {
      "x": -5,
      "y": 20,
      "z": -3,
      "name": "Rock_Sandstone_Brick_Pillar_Base",
      "rotation": 1
    },
    {
      "x": -5,
      "y": 21,
      "z": -3,
      "name": "Rock_Sandstone_Brick_Pillar_Middle",
      "rotation": 1
    },
    {
      "x": -5,
      "y": 22,
      "z": -3,
      "name": "Rock_Sandstone_Brick_Pillar_Middle",
      "rotation": 1
    },
    {
      "x": -5,
      "y": 23,
      "z": -3,
      "name": "Rock_Sandstone_Brick_Pillar_Middle",
      "rotation": 1
    },
    {
      "x": -5,
      "y": 24,
      "z": -3,
      "name": "Rock_Sandstone_Brick_Pillar_Middle",
      "rotation": 1
    },
    {
      "x": -5,
      "y": 25,
      "z": -3,
      "name": "Rock_Sandstone_Brick_Pillar_Middle",
      "rotation": 1
    },
    {
      "x": -5,
      "y": 26,
      "z": -3,
      "name": "Rock_Sandstone_Brick_Pillar_Middle",
      "rotation": 1
    },
    {
      "x": -5,
      "y": 27,
      "z": -3,
      "name": "Rock_Sandstone_Brick_Pillar_Base",
      "rotation": 9
    },
    {
      "x": -5,
      "y": 8,
      "z": -2,
      "name": "Rock_Sandstone_Brick"
    },
    {
      "x": -5,
      "y": 9,
      "z": -2,
      "name": "Rock_Sandstone_Brick_Stairs",
      "rotation": 11
    },
    {
      "x": -5,
      "y": 10,
      "z": -2,
      "name": "Rock_Sandstone_Brick",
      "rotation": 3
    },
    {
      "x": -5,
      "y": 18,
      "z": -2,
      "name": "Rock_Sandstone_Cobble"
    },
    {
      "x": -5,
      "y": 19,
      "z": -2,
      "name": "Rock_Sandstone_Brick"
    },
    {
      "x": -5,
      "y": 27,
      "z": -2,
      "name": "Rock_Gold_Brick_Smooth_Half",
      "rotation": 7
    },
    {
      "x": -5,
      "y": 8,
      "z": -1,
      "name": "Rock_Sandstone_Brick"
    },
    {
      "x": -5,
      "y": 18,
      "z": -1,
      "name": "Rock_Sandstone_Cobble"
    },
    {
      "x": -5,
      "y": 19,
      "z": -1,
      "name": "Rock_Sandstone_Brick",
      "rotation": 1
    },
    {
      "x": -5,
      "y": 20,
      "z": -1,
      "name": "Rock_Sandstone_Brick",
      "rotation": 1
    },
    {
      "x": -5,
      "y": 21,
      "z": -1,
      "name": "Wood_Drywood_Planks",
      "rotation": 1
    },
    {
      "x": -5,
      "y": 22,
      "z": -1,
      "name": "Wood_Drywood_Planks",
      "rotation": 1
    },
    {
      "x": -5,
      "y": 23,
      "z": -1,
      "name": "Wood_Drywood_Planks",
      "rotation": 1
    },
    {
      "x": -5,
      "y": 24,
      "z": -1,
      "name": "Wood_Drywood_Planks",
      "rotation": 1
    },
    {
      "x": -5,
      "y": 25,
      "z": -1,
      "name": "Wood_Drywood_Planks",
      "rotation": 1
    },
    {
      "x": -5,
      "y": 26,
      "z": -1,
      "name": "Wood_Drywood_Planks",
      "rotation": 1
    },
    {
      "x": -5,
      "y": 27,
      "z": -1,
      "name": "Rock_Sandstone_Brick"
    },
    {
      "x": -5,
      "y": 28,
      "z": -1,
      "name": "Rock_Sandstone_Brick",
      "rotation": 1
    },
    {
      "x": -5,
      "y": 29,
      "z": -1,
      "name": "Rock_Sandstone_Brick",
      "rotation": 1
    },
    {
      "x": -5,
      "y": 30,
      "z": -1,
      "name": "Rock_Sandstone_Brick_Beam",
      "rotation": 1
    },
    {
      "x": -5,
      "y": 31,
      "z": -1,
      "name": "Rock_Sandstone_Brick_Beam",
      "rotation": 1
    },
    {
      "x": -5,
      "y": 8,
      "z": 0,
      "name": "Rock_Sandstone_Brick"
    },
    {
      "x": -5,
      "y": 18,
      "z": 0,
      "name": "Rock_Sandstone_Cobble"
    },
    {
      "x": -5,
      "y": 19,
      "z": 0,
      "name": "Rock_Sandstone_Brick",
      "rotation": 1
    },
    {
      "x": -5,
      "y": 23,
      "z": 0,
      "name": "Furniture_Desert_Window",
      "rotation": 1
    },
    {
      "x": -5,
      "y": 24,
      "z": 0,
      "name": "Furniture_Desert_Window",
      "rotation": 1
    },
    {
      "x": -5,
      "y": 25,
      "z": 0,
      "name": "Furniture_Desert_Window",
      "rotation": 1
    },
    {
      "x": -5,
      "y": 26,
      "z": 0,
      "name": "Wood_Drywood_Planks",
      "rotation": 1
    },
    {
      "x": -5,
      "y": 27,
      "z": 0,
      "name": "Rock_Sandstone_Brick",
      "rotation": 1
    },
    {
      "x": -5,
      "y": 28,
      "z": 0,
      "name": "Rock_Sandstone_Brick_Smooth",
      "rotation": 1
    },
    {
      "x": -5,
      "y": 8,
      "z": 1,
      "name": "Soil_Sand"
    },
    {
      "x": -5,
      "y": 18,
      "z": 1,
      "name": "Rock_Sandstone_Cobble",
      "rotation": 3
    },
    {
      "x": -5,
      "y": 19,
      "z": 1,
      "name": "Rock_Sandstone_Brick",
      "rotation": 1
    },
    {
      "x": -5,
      "y": 23,
      "z": 1,
      "name": "Wood_Drywood_Beam"
    },
    {
      "x": -5,
      "y": 24,
      "z": 1,
      "name": "Furniture_Desert_Window",
      "rotation": 1
    },
    {
      "x": -5,
      "y": 25,
      "z": 1,
      "name": "Furniture_Desert_Window",
      "rotation": 1
    },
    {
      "x": -5,
      "y": 26,
      "z": 1,
      "name": "Furniture_Desert_Window",
      "rotation": 1
    },
    {
      "x": -5,
      "y": 27,
      "z": 1,
      "name": "Rock_Sandstone_Brick",
      "rotation": 1
    },
    {
      "x": -5,
      "y": 28,
      "z": 1,
      "name": "Rock_Sandstone_Brick_Smooth",
      "rotation": 1
    },
    {
      "x": -5,
      "y": 8,
      "z": 2,
      "name": "Rock_Sandstone_Brick"
    },
    {
      "x": -5,
      "y": 18,
      "z": 2,
      "name": "Rock_Sandstone_Cobble",
      "rotation": 3
    },
    {
      "x": -5,
      "y": 19,
      "z": 2,
      "name": "Rock_Sandstone_Brick",
      "rotation": 1
    },
    {
      "x": -5,
      "y": 21,
      "z": 2,
      "name": "Wood_Drywood_Beam"
    },
    {
      "x": -5,
      "y": 22,
      "z": 2,
      "name": "Furniture_Desert_Window",
      "rotation": 1
    },
    {
      "x": -5,
      "y": 23,
      "z": 2,
      "name": "Furniture_Desert_Window",
      "rotation": 1
    },
    {
      "x": -5,
      "y": 24,
      "z": 2,
      "name": "Furniture_Desert_Window",
      "rotation": 1
    },
    {
      "x": -5,
      "y": 25,
      "z": 2,
      "name": "Furniture_Desert_Window",
      "rotation": 1
    },
    {
      "x": -5,
      "y": 26,
      "z": 2,
      "name": "Wood_Drywood_Planks",
      "rotation": 1
    },
    {
      "x": -5,
      "y": 27,
      "z": 2,
      "name": "Rock_Gold_Brick_Smooth_Half",
      "rotation": 7
    },
    {
      "x": -5,
      "y": 28,
      "z": 2,
      "name": "Rock_Sandstone_Brick",
      "rotation": 1
    },
    {
      "x": -5,
      "y": 29,
      "z": 2,
      "name": "Rock_Sandstone_Brick",
      "rotation": 1
    },
    {
      "x": -5,
      "y": 30,
      "z": 2,
      "name": "Rock_Sandstone_Brick_Beam",
      "rotation": 1
    },
    {
      "x": -5,
      "y": 31,
      "z": 2,
      "name": "Rock_Sandstone_Brick_Beam",
      "rotation": 1
    },
    {
      "x": -5,
      "y": 8,
      "z": 3,
      "name": "Rock_Sandstone_Brick"
    },
    {
      "x": -5,
      "y": 9,
      "z": 3,
      "name": "Rock_Sandstone_Brick_Stairs",
      "rotation": 11
    },
    {
      "x": -5,
      "y": 10,
      "z": 3,
      "name": "Rock_Sandstone_Brick",
      "rotation": 3
    },
    {
      "x": -5,
      "y": 18,
      "z": 3,
      "name": "Rock_Sandstone_Cobble",
      "rotation": 3
    },
    {
      "x": -5,
      "y": 19,
      "z": 3,
      "name": "Rock_Sandstone_Brick",
      "rotation": 1
    },
    {
      "x": -5,
      "y": 20,
      "z": 3,
      "name": "Rock_Sandstone_Brick",
      "rotation": 1
    },
    {
      "x": -5,
      "y": 21,
      "z": 3,
      "name": "Wood_Drywood_Planks",
      "rotation": 1
    },
    {
      "x": -5,
      "y": 22,
      "z": 3,
      "name": "Wood_Drywood_Planks",
      "rotation": 1
    },
    {
      "x": -5,
      "y": 23,
      "z": 3,
      "name": "Wood_Drywood_Planks",
      "rotation": 1
    },
    {
      "x": -5,
      "y": 24,
      "z": 3,
      "name": "Wood_Drywood_Planks",
      "rotation": 1
    },
    {
      "x": -5,
      "y": 25,
      "z": 3,
      "name": "Wood_Drywood_Planks",
      "rotation": 1
    },
    {
      "x": -5,
      "y": 26,
      "z": 3,
      "name": "Wood_Drywood_Planks",
      "rotation": 1
    },
    {
      "x": -5,
      "y": 27,
      "z": 3,
      "name": "Rock_Sandstone_Brick"
    },
    {
      "x": -5,
      "y": 8,
      "z": 4,
      "name": "Rock_Sandstone_Brick"
    },
    {
      "x": -5,
      "y": 9,
      "z": 4,
      "name": "Rock_Sandstone_Brick_Stairs",
      "rotation": 11
    },
    {
      "x": -5,
      "y": 10,
      "z": 4,
      "name": "Rock_Sandstone_Brick",
      "rotation": 3
    },
    {
      "x": -5,
      "y": 17,
      "z": 4,
      "name": "Rock_Sandstone_Cobble_Half",
      "rotation": 11
    },
    {
      "x": -5,
      "y": 18,
      "z": 4,
      "name": "Rock_Sandstone_Cobble",
      "rotation": 3
    },
    {
      "x": -5,
      "y": 19,
      "z": 4,
      "name": "Rock_Sandstone_Brick"
    },
    {
      "x": -5,
      "y": 27,
      "z": 4,
      "name": "Rock_Gold_Brick_Smooth_Half",
      "rotation": 7
    },
    {
      "x": -5,
      "y": 8,
      "z": 5,
      "name": "Rock_Sandstone_Brick"
    },
    {
      "x": -5,
      "y": 9,
      "z": 5,
      "name": "Rock_Sandstone_Brick_Stairs",
      "rotation": 11
    },
    {
      "x": -5,
      "y": 10,
      "z": 5,
      "name": "Rock_Sandstone_Brick",
      "rotation": 3
    },
    {
      "x": -5,
      "y": 17,
      "z": 5,
      "name": "Rock_Sandstone_Cobble_Half",
      "rotation": 11
    },
    {
      "x": -5,
      "y": 18,
      "z": 5,
      "name": "Rock_Sandstone",
      "rotation": 3
    },
    {
      "x": -5,
      "y": 19,
      "z": 5,
      "name": "Rock_Sandstone_Brick"
    },
    {
      "x": -5,
      "y": 20,
      "z": 5,
      "name": "Rock_Sandstone_Brick",
      "rotation": 1
    },
    {
      "x": -5,
      "y": 21,
      "z": 5,
      "name": "Rock_Sandstone_Brick_Beam",
      "rotation": 1
    },
    {
      "x": -5,
      "y": 22,
      "z": 5,
      "name": "Rock_Sandstone_Brick_Beam",
      "rotation": 1
    },
    {
      "x": -5,
      "y": 23,
      "z": 5,
      "name": "Rock_Sandstone_Brick_Pillar_Middle",
      "rotation": 1
    },
    {
      "x": -5,
      "y": 24,
      "z": 5,
      "name": "Rock_Sandstone_Brick_Pillar_Middle",
      "rotation": 1
    },
    {
      "x": -5,
      "y": 25,
      "z": 5,
      "name": "Rock_Sandstone_Brick_Pillar_Middle",
      "rotation": 1
    },
    {
      "x": -5,
      "y": 26,
      "z": 5,
      "name": "Rock_Sandstone_Brick_Pillar_Middle",
      "rotation": 1
    },
    {
      "x": -5,
      "y": 27,
      "z": 5,
      "name": "Rock_Sandstone_Brick_Pillar_Base",
      "rotation": 9
    },
    {
      "x": -5,
      "y": 8,
      "z": 6,
      "name": "Rock_Sandstone_Brick"
    },
    {
      "x": -5,
      "y": 9,
      "z": 6,
      "name": "Rock_Sandstone_Brick_Stairs",
      "rotation": 11
    },
    {
      "x": -5,
      "y": 10,
      "z": 6,
      "name": "Rock_Sandstone_Brick",
      "rotation": 3
    },
    {
      "x": -5,
      "y": 17,
      "z": 6,
      "name": "Rock_Sandstone_Cobble_Half",
      "rotation": 11
    },
    {
      "x": -5,
      "y": 18,
      "z": 6,
      "name": "Rock_Sandstone",
      "rotation": 3
    },
    {
      "x": -5,
      "y": 19,
      "z": 6,
      "name": "Rock_Sandstone_Brick"
    },
    {
      "x": -5,
      "y": 8,
      "z": 7,
      "name": "Rock_Sandstone_Brick"
    },
    {
      "x": -5,
      "y": 9,
      "z": 7,
      "name": "Rock_Sandstone_Brick_Stairs",
      "rotation": 11
    },
    {
      "x": -5,
      "y": 10,
      "z": 7,
      "name": "Rock_Sandstone_Brick",
      "rotation": 3
    },
    {
      "x": -5,
      "y": 11,
      "z": 7,
      "name": "Rock_Sandstone_Red_Brick_Half",
      "rotation": 6
    },
    {
      "x": -5,
      "y": 15,
      "z": 7,
      "name": "Rock_Sandstone_Brick_Stairs",
      "rotation": 8
    },
    {
      "x": -5,
      "y": 16,
      "z": 7,
      "name": "Rock_Sandstone_Red_Brick",
      "rotation": 3
    },
    {
      "x": -5,
      "y": 17,
      "z": 7,
      "name": "Rock_Sandstone_Red_Brick",
      "rotation": 3
    },
    {
      "x": -5,
      "y": 18,
      "z": 7,
      "name": "Rock_Sandstone",
      "rotation": 3
    },
    {
      "x": -5,
      "y": 19,
      "z": 7,
      "name": "Rock_Sandstone_Brick"
    },
    {
      "x": -5,
      "y": 8,
      "z": 8,
      "name": "Rock_Sandstone_Brick",
      "rotation": 3
    },
    {
      "x": -5,
      "y": 9,
      "z": 8,
      "name": "Rock_Sandstone_Brick",
      "rotation": 3
    },
    {
      "x": -5,
      "y": 10,
      "z": 8,
      "name": "Rock_Sandstone_Brick",
      "rotation": 3
    },
    {
      "x": -5,
      "y": 11,
      "z": 8,
      "name": "Rock_Sandstone_Brick",
      "rotation": 3
    },
    {
      "x": -5,
      "y": 12,
      "z": 8,
      "name": "Rock_Sandstone_Brick",
      "rotation": 3
    },
    {
      "x": -5,
      "y": 13,
      "z": 8,
      "name": "Rock_Sandstone_Cobble",
      "rotation": 3
    },
    {
      "x": -5,
      "y": 14,
      "z": 8,
      "name": "Rock_Sandstone_Cobble",
      "rotation": 3
    },
    {
      "x": -5,
      "y": 15,
      "z": 8,
      "name": "Rock_Sandstone_Cobble",
      "rotation": 3
    },
    {
      "x": -5,
      "y": 16,
      "z": 8,
      "name": "Rock_Sandstone_Cobble",
      "rotation": 3
    },
    {
      "x": -5,
      "y": 17,
      "z": 8,
      "name": "Rock_Sandstone_Cobble",
      "rotation": 3
    },
    {
      "x": -5,
      "y": 18,
      "z": 8,
      "name": "Rock_Sandstone_Brick",
      "rotation": 3
    },
    {
      "x": -5,
      "y": 19,
      "z": 8,
      "name": "Rock_Sandstone_Brick",
      "rotation": 3
    },
    {
      "x": -5,
      "y": 8,
      "z": 9,
      "name": "Rock_Sandstone_Cobble",
      "rotation": 3
    },
    {
      "x": -5,
      "y": 9,
      "z": 9,
      "name": "Rock_Sandstone_Cobble",
      "rotation": 3
    },
    {
      "x": -5,
      "y": 10,
      "z": 9,
      "name": "Rock_Sandstone_Cobble",
      "rotation": 3
    },
    {
      "x": -5,
      "y": 11,
      "z": 9,
      "name": "Rock_Sandstone_Cobble",
      "rotation": 3
    },
    {
      "x": -5,
      "y": 12,
      "z": 9,
      "name": "Rock_Sandstone_Brick_Ornate",
      "rotation": 3
    },
    {
      "x": -5,
      "y": 13,
      "z": 9,
      "name": "Rock_Sandstone_Brick_Stairs"
    },
    {
      "x": -5,
      "y": 17,
      "z": 9,
      "name": "Rock_Sandstone_Brick_Stairs",
      "rotation": 10
    },
    {
      "x": -5,
      "y": 18,
      "z": 9,
      "name": "Rock_Sandstone_Brick",
      "rotation": 3
    },
    {
      "x": -5,
      "y": 19,
      "z": 9,
      "name": "Rock_Sandstone_Brick",
      "rotation": 3
    },
    {
      "x": -5,
      "y": 8,
      "z": 10,
      "name": "Soil_Sand"
    },
    {
      "x": -5,
      "y": 9,
      "z": 10,
      "name": "Soil_Sand"
    },
    {
      "x": -5,
      "y": 10,
      "z": 10,
      "name": "Soil_Sand"
    },
    {
      "x": -5,
      "y": 8,
      "z": 11,
      "name": "Soil_Sand"
    },
    {
      "x": -4,
      "y": 8,
      "z": -10,
      "name": "Rock_Sandstone_Red_Brick",
      "rotation": 3
    },
    {
      "x": -4,
      "y": 9,
      "z": -10,
      "name": "Rock_Sandstone_Red_Brick",
      "rotation": 3
    },
    {
      "x": -4,
      "y": 10,
      "z": -10,
      "name": "Rock_Sandstone_Red_Brick_Stairs",
      "rotation": 2
    },
    {
      "x": -4,
      "y": 8,
      "z": -9,
      "name": "Rock_Sandstone_Red_Brick",
      "rotation": 3
    },
    {
      "x": -4,
      "y": 9,
      "z": -9,
      "name": "Rock_Sandstone_Red_Brick",
      "rotation": 3
    },
    {
      "x": -4,
      "y": 10,
      "z": -9,
      "name": "Rock_Sandstone_Red_Brick",
      "rotation": 3
    },
    {
      "x": -4,
      "y": 11,
      "z": -9,
      "name": "Rock_Sandstone_Red_Brick_Stairs",
      "rotation": 2
    },
    {
      "x": -4,
      "y": 8,
      "z": -8,
      "name": "Rock_Sandstone_Brick",
      "rotation": 3
    },
    {
      "x": -4,
      "y": 9,
      "z": -8,
      "name": "Rock_Sandstone_Brick",
      "rotation": 3
    },
    {
      "x": -4,
      "y": 10,
      "z": -8,
      "name": "Rock_Sandstone_Brick",
      "rotation": 3
    },
    {
      "x": -4,
      "y": 11,
      "z": -8,
      "name": "Rock_Sandstone_Brick",
      "rotation": 3
    },
    {
      "x": -4,
      "y": 12,
      "z": -8,
      "name": "Rock_Sandstone_Brick_Ornate",
      "rotation": 3
    },
    {
      "x": -4,
      "y": 13,
      "z": -8,
      "name": "Rock_Sandstone_Brick_Stairs",
      "rotation": 2
    },
    {
      "x": -4,
      "y": 8,
      "z": -7,
      "name": "Rock_Sandstone_Brick",
      "rotation": 3
    },
    {
      "x": -4,
      "y": 9,
      "z": -7,
      "name": "Rock_Sandstone_Brick",
      "rotation": 3
    },
    {
      "x": -4,
      "y": 10,
      "z": -7,
      "name": "Rock_Sandstone_Brick",
      "rotation": 3
    },
    {
      "x": -4,
      "y": 11,
      "z": -7,
      "name": "Rock_Sandstone_Brick",
      "rotation": 3
    },
    {
      "x": -4,
      "y": 12,
      "z": -7,
      "name": "Rock_Sandstone_Brick",
      "rotation": 3
    },
    {
      "x": -4,
      "y": 13,
      "z": -7,
      "name": "Rock_Sandstone_Cobble",
      "rotation": 3
    },
    {
      "x": -4,
      "y": 14,
      "z": -7,
      "name": "Rock_Sandstone_Cobble",
      "rotation": 3
    },
    {
      "x": -4,
      "y": 15,
      "z": -7,
      "name": "Rock_Sandstone_Cobble",
      "rotation": 3
    },
    {
      "x": -4,
      "y": 16,
      "z": -7,
      "name": "Rock_Sandstone_Cobble"
    },
    {
      "x": -4,
      "y": 8,
      "z": -6,
      "name": "Rock_Sandstone_Brick"
    },
    {
      "x": -4,
      "y": 11,
      "z": -6,
      "name": "Rock_Sandstone_Red_Brick_Half",
      "rotation": 4
    },
    {
      "x": -4,
      "y": 16,
      "z": -6,
      "name": "Rock_Sandstone_Red_Brick"
    },
    {
      "x": -4,
      "y": 17,
      "z": -6,
      "name": "Rock_Sandstone_Red_Cobble"
    },
    {
      "x": -4,
      "y": 8,
      "z": -5,
      "name": "Rock_Sandstone_Brick"
    },
    {
      "x": -4,
      "y": 18,
      "z": -5,
      "name": "Rock_Sandstone_Cobble"
    },
    {
      "x": -4,
      "y": 8,
      "z": -4,
      "name": "Rock_Sandstone_Brick"
    },
    {
      "x": -4,
      "y": 18,
      "z": -4,
      "name": "Rock_Sandstone_Cobble"
    },
    {
      "x": -4,
      "y": 27,
      "z": -4,
      "name": "Rock_Gold_Brick_Smooth_Half",
      "rotation": 6
    },
    {
      "x": -4,
      "y": 8,
      "z": -3,
      "name": "Rock_Sandstone_Brick"
    },
    {
      "x": -4,
      "y": 18,
      "z": -3,
      "name": "Rock_Sandstone_Cobble_Half",
      "rotation": 8
    },
    {
      "x": -4,
      "y": 19,
      "z": -3,
      "name": "Rock_Sandstone_Brick"
    },
    {
      "x": -4,
      "y": 20,
      "z": -3,
      "name": "Rock_Sandstone_Brick",
      "rotation": 1
    },
    {
      "x": -4,
      "y": 21,
      "z": -3,
      "name": "Wood_Drywood_Planks",
      "rotation": 1
    },
    {
      "x": -4,
      "y": 22,
      "z": -3,
      "name": "Wood_Drywood_Planks",
      "rotation": 1
    },
    {
      "x": -4,
      "y": 23,
      "z": -3,
      "name": "Wood_Drywood_Planks",
      "rotation": 1
    },
    {
      "x": -4,
      "y": 24,
      "z": -3,
      "name": "Wood_Drywood_Planks",
      "rotation": 1
    },
    {
      "x": -4,
      "y": 25,
      "z": -3,
      "name": "Wood_Drywood_Planks",
      "rotation": 1
    },
    {
      "x": -4,
      "y": 26,
      "z": -3,
      "name": "Wood_Drywood_Planks",
      "rotation": 1
    },
    {
      "x": -4,
      "y": 27,
      "z": -3,
      "name": "*Rock_Gold_Brick_Smooth_Half_State_Definitions_Block",
      "rotation": 6
    },
    {
      "x": -4,
      "y": 28,
      "z": -3,
      "name": "Rock_Sandstone_Brick_Smooth",
      "rotation": 1
    },
    {
      "x": -4,
      "y": 8,
      "z": -2,
      "name": "Rock_Sandstone_Brick"
    },
    {
      "x": -4,
      "y": 18,
      "z": -2,
      "name": "Rock_Sandstone_Cobble"
    },
    {
      "x": -4,
      "y": 19,
      "z": -2,
      "name": "Rock_Sandstone_Brick_Smooth",
      "rotation": 1
    },
    {
      "x": -4,
      "y": 20,
      "z": -2,
      "name": "Rock_Sandstone_Brick",
      "rotation": 1
    },
    {
      "x": -4,
      "y": 21,
      "z": -2,
      "name": "Wood_Drywood_Planks",
      "rotation": 1
    },
    {
      "x": -4,
      "y": 22,
      "z": -2,
      "name": "Wood_Drywood_Planks",
      "rotation": 1
    },
    {
      "x": -4,
      "y": 23,
      "z": -2,
      "name": "Wood_Drywood_Planks",
      "rotation": 1
    },
    {
      "x": -4,
      "y": 24,
      "z": -2,
      "name": "Wood_Drywood_Planks",
      "rotation": 1
    },
    {
      "x": -4,
      "y": 25,
      "z": -2,
      "name": "Wood_Drywood_Planks",
      "rotation": 1
    },
    {
      "x": -4,
      "y": 26,
      "z": -2,
      "name": "Wood_Drywood_Planks",
      "rotation": 1
    },
    {
      "x": -4,
      "y": 27,
      "z": -2,
      "name": "Rock_Sandstone_Brick",
      "rotation": 1
    },
    {
      "x": -4,
      "y": 28,
      "z": -2,
      "name": "Rock_Sandstone_Brick_Smooth",
      "rotation": 1
    },
    {
      "x": -4,
      "y": 8,
      "z": -1,
      "name": "Rock_Sandstone_Brick"
    },
    {
      "x": -4,
      "y": 18,
      "z": -1,
      "name": "Rock_Sandstone_Cobble"
    },
    {
      "x": -4,
      "y": 19,
      "z": -1,
      "name": "Wood_Drywood_Planks",
      "rotation": 1
    },
    {
      "x": -4,
      "y": 27,
      "z": -1,
      "name": "Rock_Sandstone_Brick",
      "rotation": 1
    },
    {
      "x": -4,
      "y": 28,
      "z": -1,
      "name": "Rock_Sandstone_Brick",
      "rotation": 1
    },
    {
      "x": -4,
      "y": 29,
      "z": -1,
      "name": "Soil_Clay_Ocean_Brick_Smooth",
      "rotation": 1
    },
    {
      "x": -4,
      "y": 8,
      "z": 0,
      "name": "Soil_Sand"
    },
    {
      "x": -4,
      "y": 18,
      "z": 0,
      "name": "Rock_Sandstone_Cobble"
    },
    {
      "x": -4,
      "y": 19,
      "z": 0,
      "name": "Wood_Drywood_Planks",
      "rotation": 1
    },
    {
      "x": -4,
      "y": 27,
      "z": 0,
      "name": "Rock_Sandstone_Brick",
      "rotation": 1
    },
    {
      "x": -4,
      "y": 28,
      "z": 0,
      "name": "Rock_Sandstone_Brick",
      "rotation": 1
    },
    {
      "x": -4,
      "y": 29,
      "z": 0,
      "name": "Soil_Clay_Ocean_Brick_Smooth",
      "rotation": 1
    },
    {
      "x": -4,
      "y": 30,
      "z": 0,
      "name": "Soil_Clay_Ocean_Brick_Smooth",
      "rotation": 1
    },
    {
      "x": -4,
      "y": 8,
      "z": 1,
      "name": "Soil_Sand"
    },
    {
      "x": -4,
      "y": 18,
      "z": 1,
      "name": "Rock_Sandstone_Cobble"
    },
    {
      "x": -4,
      "y": 19,
      "z": 1,
      "name": "Wood_Drywood_Planks",
      "rotation": 1
    },
    {
      "x": -4,
      "y": 27,
      "z": 1,
      "name": "Rock_Sandstone_Brick",
      "rotation": 1
    },
    {
      "x": -4,
      "y": 28,
      "z": 1,
      "name": "Rock_Sandstone_Brick",
      "rotation": 1
    },
    {
      "x": -4,
      "y": 29,
      "z": 1,
      "name": "Soil_Clay_Ocean_Brick_Smooth",
      "rotation": 1
    },
    {
      "x": -4,
      "y": 30,
      "z": 1,
      "name": "Soil_Clay_Ocean_Brick_Smooth",
      "rotation": 1
    },
    {
      "x": -4,
      "y": 8,
      "z": 2,
      "name": "Rock_Sandstone_Brick"
    },
    {
      "x": -4,
      "y": 18,
      "z": 2,
      "name": "Rock_Sandstone_Cobble",
      "rotation": 3
    },
    {
      "x": -4,
      "y": 19,
      "z": 2,
      "name": "Wood_Drywood_Planks",
      "rotation": 1
    },
    {
      "x": -4,
      "y": 27,
      "z": 2,
      "name": "Rock_Sandstone_Brick",
      "rotation": 1
    },
    {
      "x": -4,
      "y": 28,
      "z": 2,
      "name": "Rock_Sandstone_Brick",
      "rotation": 1
    },
    {
      "x": -4,
      "y": 29,
      "z": 2,
      "name": "Soil_Clay_Ocean_Brick_Smooth",
      "rotation": 1
    },
    {
      "x": -4,
      "y": 8,
      "z": 3,
      "name": "Rock_Sandstone_Brick"
    },
    {
      "x": -4,
      "y": 18,
      "z": 3,
      "name": "Rock_Sandstone_Cobble",
      "rotation": 3
    },
    {
      "x": -4,
      "y": 19,
      "z": 3,
      "name": "Wood_Drywood_Planks",
      "rotation": 1
    },
    {
      "x": -4,
      "y": 27,
      "z": 3,
      "name": "Rock_Sandstone_Brick"
    },
    {
      "x": -4,
      "y": 28,
      "z": 3,
      "name": "Rock_Sandstone_Brick_Smooth",
      "rotation": 1
    },
    {
      "x": -4,
      "y": 8,
      "z": 4,
      "name": "Rock_Sandstone_Brick"
    },
    {
      "x": -4,
      "y": 18,
      "z": 4,
      "name": "Rock_Sandstone_Cobble",
      "rotation": 3
    },
    {
      "x": -4,
      "y": 19,
      "z": 4,
      "name": "Rock_Sandstone_Brick"
    },
    {
      "x": -4,
      "y": 20,
      "z": 4,
      "name": "Rock_Sandstone_Brick",
      "rotation": 1
    },
    {
      "x": -4,
      "y": 21,
      "z": 4,
      "name": "Wood_Drywood_Planks",
      "rotation": 1
    },
    {
      "x": -4,
      "y": 22,
      "z": 4,
      "name": "Wood_Drywood_Planks",
      "rotation": 1
    },
    {
      "x": -4,
      "y": 23,
      "z": 4,
      "name": "Wood_Drywood_Planks",
      "rotation": 1
    },
    {
      "x": -4,
      "y": 24,
      "z": 4,
      "name": "Wood_Drywood_Planks",
      "rotation": 1
    },
    {
      "x": -4,
      "y": 25,
      "z": 4,
      "name": "Wood_Drywood_Planks",
      "rotation": 1
    },
    {
      "x": -4,
      "y": 26,
      "z": 4,
      "name": "Wood_Drywood_Planks",
      "rotation": 1
    },
    {
      "x": -4,
      "y": 27,
      "z": 4,
      "name": "Rock_Gold_Brick_Smooth_Half",
      "rotation": 7
    },
    {
      "x": -4,
      "y": 28,
      "z": 4,
      "name": "Rock_Sandstone_Brick_Smooth",
      "rotation": 1
    },
    {
      "x": -4,
      "y": 8,
      "z": 5,
      "name": "Rock_Sandstone_Brick"
    },
    {
      "x": -4,
      "y": 17,
      "z": 5,
      "name": "Rock_Sandstone_Cobble_Half",
      "rotation": 11
    },
    {
      "x": -4,
      "y": 18,
      "z": 5,
      "name": "Rock_Sandstone_Cobble",
      "rotation": 3
    },
    {
      "x": -4,
      "y": 19,
      "z": 5,
      "name": "Rock_Sandstone_Brick",
      "rotation": 1
    },
    {
      "x": -4,
      "y": 20,
      "z": 5,
      "name": "Rock_Sandstone_Brick",
      "rotation": 1
    },
    {
      "x": -4,
      "y": 21,
      "z": 5,
      "name": "Wood_Drywood_Planks",
      "rotation": 1
    },
    {
      "x": -4,
      "y": 22,
      "z": 5,
      "name": "Wood_Drywood_Planks",
      "rotation": 1
    },
    {
      "x": -4,
      "y": 23,
      "z": 5,
      "name": "Wood_Drywood_Planks",
      "rotation": 1
    },
    {
      "x": -4,
      "y": 24,
      "z": 5,
      "name": "Wood_Drywood_Planks",
      "rotation": 1
    },
    {
      "x": -4,
      "y": 25,
      "z": 5,
      "name": "Wood_Drywood_Planks",
      "rotation": 1
    },
    {
      "x": -4,
      "y": 26,
      "z": 5,
      "name": "Wood_Drywood_Planks",
      "rotation": 1
    },
    {
      "x": -4,
      "y": 27,
      "z": 5,
      "name": "Rock_Sandstone_Brick",
      "rotation": 1
    },
    {
      "x": -4,
      "y": 8,
      "z": 6,
      "name": "Rock_Sandstone_Brick"
    },
    {
      "x": -4,
      "y": 17,
      "z": 6,
      "name": "Rock_Sandstone_Cobble_Half",
      "rotation": 11
    },
    {
      "x": -4,
      "y": 18,
      "z": 6,
      "name": "Rock_Sandstone",
      "rotation": 3
    },
    {
      "x": -4,
      "y": 19,
      "z": 6,
      "name": "Rock_Sandstone_Brick"
    },
    {
      "x": -4,
      "y": 27,
      "z": 6,
      "name": "Rock_Gold_Brick_Smooth_Half",
      "rotation": 4
    },
    {
      "x": -4,
      "y": 8,
      "z": 7,
      "name": "Rock_Sandstone_Brick"
    },
    {
      "x": -4,
      "y": 11,
      "z": 7,
      "name": "Rock_Sandstone_Red_Brick_Half",
      "rotation": 6
    },
    {
      "x": -4,
      "y": 15,
      "z": 7,
      "name": "Rock_Sandstone_Brick_Stairs",
      "rotation": 8
    },
    {
      "x": -4,
      "y": 16,
      "z": 7,
      "name": "Rock_Sandstone_Red_Brick",
      "rotation": 3
    },
    {
      "x": -4,
      "y": 17,
      "z": 7,
      "name": "Rock_Sandstone_Red_Cobble",
      "rotation": 3
    },
    {
      "x": -4,
      "y": 18,
      "z": 7,
      "name": "Rock_Sandstone",
      "rotation": 3
    },
    {
      "x": -4,
      "y": 19,
      "z": 7,
      "name": "Rock_Sandstone_Brick"
    },
    {
      "x": -4,
      "y": 20,
      "z": 7,
      "name": "Rock_Sandstone_Brick",
      "rotation": 1
    },
    {
      "x": -4,
      "y": 21,
      "z": 7,
      "name": "Rock_Sandstone_Brick_Beam",
      "rotation": 1
    },
    {
      "x": -4,
      "y": 22,
      "z": 7,
      "name": "Rock_Sandstone_Brick_Beam",
      "rotation": 1
    },
    {
      "x": -4,
      "y": 8,
      "z": 8,
      "name": "Rock_Sandstone_Brick",
      "rotation": 3
    },
    {
      "x": -4,
      "y": 9,
      "z": 8,
      "name": "Rock_Sandstone_Brick",
      "rotation": 3
    },
    {
      "x": -4,
      "y": 10,
      "z": 8,
      "name": "Rock_Sandstone_Brick",
      "rotation": 3
    },
    {
      "x": -4,
      "y": 11,
      "z": 8,
      "name": "Rock_Sandstone_Brick",
      "rotation": 3
    },
    {
      "x": -4,
      "y": 12,
      "z": 8,
      "name": "Rock_Sandstone_Brick",
      "rotation": 3
    },
    {
      "x": -4,
      "y": 13,
      "z": 8,
      "name": "Rock_Sandstone_Cobble",
      "rotation": 3
    },
    {
      "x": -4,
      "y": 14,
      "z": 8,
      "name": "Rock_Sandstone_Cobble",
      "rotation": 3
    },
    {
      "x": -4,
      "y": 15,
      "z": 8,
      "name": "Rock_Sandstone_Cobble",
      "rotation": 3
    },
    {
      "x": -4,
      "y": 16,
      "z": 8,
      "name": "Rock_Sandstone_Cobble",
