{
  "version": 8,
  "blockIdVersion": 11,
  "anchorX": -7,
  "anchorY": 5,
  "anchorZ": -6,
  "blocks": [
    {
      "x": -7,
      "y": 10,
      "z": -3,
      "name": "Rock_Sandstone_Cobble_Beam",
      "rotation": 5
    },
    {
      "x": -7,
      "y": 11,
      "z": -2,
      "name": "Rock_Sandstone_Brick_Smooth_Half",
      "rotation": 7
    },
    {
      "x": -7,
      "y": 13,
      "z": -2,
      "name": "*Wood_Drywood_Roof_State_Definitions_Corner_Right",
      "rotation": 3
    },
    {
      "x": -7,
      "y": 11,
      "z": -1,
      "name": "Rock_Sandstone_Brick_Smooth_Half",
      "rotation": 7
    },
    {
      "x": -7,
      "y": 13,
      "z": -1,
      "name": "Wood_Drywood_Roof_Hollow",
      "rotation": 3
    },
    {
      "x": -7,
      "y": 11,
      "z": 0,
      "name": "Rock_Sandstone_Brick_Smooth_Half",
      "rotation": 7
    },
    {
      "x": -7,
      "y": 13,
      "z": 0,
      "name": "*Wood_Drywood_Roof_State_Definitions_Corner_Right"
    },
    {
      "x": -7,
      "y": 10,
      "z": 1,
      "name": "Rock_Sandstone_Cobble_Beam",
      "rotation": 5
    },
    {
      "x": -6,
      "y": 10,
      "z": -5,
      "name": "Wood_Dry_Trunk",
      "rotation": 5
    },
    {
      "x": -6,
      "y": 6,
      "z": -4,
      "name": "Rock_Sandstone_Brick_Half",
      "rotation": 6
    },
    {
      "x": -6,
      "y": 7,
      "z": -4,
      "name": "Rock_Sandstone_Brick_Half",
      "rotation": 6
    },
    {
      "x": -6,
      "y": 8,
      "z": -4,
      "name": "Rock_Sandstone_Brick"
    },
    {
      "x": -6,
      "y": 9,
      "z": -4,
      "name": "Rock_Sandstone_Brick"
    },
    {
      "x": -6,
      "y": 10,
      "z": -4,
      "name": "Rock_Sandstone_Brick_Ornate"
    },
    {
      "x": -6,
      "y": 11,
      "z": -4,
      "name": "Rock_Sandstone_Cobble"
    },
    {
      "x": -6,
      "y": 12,
      "z": -4,
      "name": "Rock_Sandstone_Cobble"
    },
    {
      "x": -6,
      "y": 13,
      "z": -4,
      "name": "Rock_Sandstone_Cobble"
    },
    {
      "x": -6,
      "y": 14,
      "z": -4,
      "name": "Rock_Sandstone_Cobble"
    },
    {
      "x": -6,
      "y": 5,
      "z": -3,
      "name": "Rock_Sandstone"
    },
    {
      "x": -6,
      "y": 6,
      "z": -3,
      "name": "Rock_Sandstone"
    },
    {
      "x": -6,
      "y": 7,
      "z": -3,
      "name": "Rock_Sandstone"
    },
    {
      "x": -6,
      "y": 8,
      "z": -3,
      "name": "Rock_Sandstone_Brick"
    },
    {
      "x": -6,
      "y": 9,
      "z": -3,
      "name": "Rock_Sandstone_Cobble"
    },
    {
      "x": -6,
      "y": 10,
      "z": -3,
      "name": "Rock_Sandstone_Brick_Decorative"
    },
    {
      "x": -6,
      "y": 11,
      "z": -3,
      "name": "Rock_Sandstone_Cobble"
    },
    {
      "x": -6,
      "y": 12,
      "z": -3,
      "name": "Rock_Sandstone_Cobble"
    },
    {
      "x": -6,
      "y": 13,
      "z": -3,
      "name": "Rock_Sandstone_Cobble"
    },
    {
      "x": -6,
      "y": 14,
      "z": -3,
      "name": "Rock_Sandstone_Cobble"
    },
    {
      "x": -6,
      "y": 5,
      "z": -2,
      "name": "Rock_Sandstone"
    },
    {
      "x": -6,
      "y": 6,
      "z": -2,
      "name": "Rock_Sandstone"
    },
    {
      "x": -6,
      "y": 7,
      "z": -2,
      "name": "Rock_Sandstone"
    },
    {
      "x": -6,
      "y": 8,
      "z": -2,
      "name": "Rock_Sandstone"
    },
    {
      "x": -6,
      "y": 9,
      "z": -2,
      "name": "Rock_Sandstone_Cobble"
    },
    {
      "x": -6,
      "y": 10,
      "z": -2,
      "name": "Rock_Sandstone_Cobble"
    },
    {
      "x": -6,
      "y": 11,
      "z": -2,
      "name": "Rock_Sandstone_Brick"
    },
    {
      "x": -6,
      "y": 12,
      "z": -2,
      "name": "Rock_Sandstone_Cobble"
    },
    {
      "x": -6,
      "y": 13,
      "z": -2,
      "name": "Rock_Sandstone_Cobble"
    },
    {
      "x": -6,
      "y": 14,
      "z": -2,
      "name": "Rock_Sandstone_Cobble"
    },
    {
      "x": -6,
      "y": 5,
      "z": -1,
      "name": "Rock_Sandstone"
    },
    {
      "x": -6,
      "y": 6,
      "z": -1,
      "name": "Rock_Sandstone"
    },
    {
      "x": -6,
      "y": 7,
      "z": -1,
      "name": "Rock_Sandstone"
    },
    {
      "x": -6,
      "y": 8,
      "z": -1,
      "name": "Rock_Sandstone"
    },
    {
      "x": -6,
      "y": 9,
      "z": -1,
      "name": "Rock_Sandstone_Cobble"
    },
    {
      "x": -6,
      "y": 10,
      "z": -1,
      "name": "Rock_Sandstone_Brick_Ornate"
    },
    {
      "x": -6,
      "y": 11,
      "z": -1,
      "name": "Rock_Sandstone_Brick"
    },
    {
      "x": -6,
      "y": 12,
      "z": -1,
      "name": "Wood_Drywood_Fence",
      "rotation": 3
    },
    {
      "x": -6,
      "y": 13,
      "z": -1,
      "name": "Wood_Drywood_Fence",
      "rotation": 1
    },
    {
      "x": -6,
      "y": 14,
      "z": -1,
      "name": "Rock_Sandstone_Cobble"
    },
    {
      "x": -6,
      "y": 5,
      "z": 0,
      "name": "Rock_Sandstone"
    },
    {
      "x": -6,
      "y": 6,
      "z": 0,
      "name": "Rock_Sandstone"
    },
    {
      "x": -6,
      "y": 7,
      "z": 0,
      "name": "Rock_Sandstone"
    },
    {
      "x": -6,
      "y": 8,
      "z": 0,
      "name": "Rock_Sandstone_Cobble"
    },
    {
      "x": -6,
      "y": 9,
      "z": 0,
      "name": "Rock_Sandstone_Cobble"
    },
    {
      "x": -6,
      "y": 10,
      "z": 0,
      "name": "Rock_Sandstone_Brick_Ornate"
    },
    {
      "x": -6,
      "y": 11,
      "z": 0,
      "name": "Rock_Sandstone_Brick"
    },
    {
      "x": -6,
      "y": 12,
      "z": 0,
      "name": "Rock_Sandstone_Cobble"
    },
    {
      "x": -6,
      "y": 13,
      "z": 0,
      "name": "Rock_Sandstone_Cobble"
    },
    {
      "x": -6,
      "y": 14,
      "z": 0,
      "name": "Rock_Sandstone_Brick"
    },
    {
      "x": -6,
      "y": 5,
      "z": 1,
      "name": "Rock_Sandstone"
    },
    {
      "x": -6,
      "y": 6,
      "z": 1,
      "name": "Rock_Sandstone"
    },
    {
      "x": -6,
      "y": 7,
      "z": 1,
      "name": "Rock_Sandstone"
    },
    {
      "x": -6,
      "y": 8,
      "z": 1,
      "name": "Rock_Sandstone"
    },
    {
      "x": -6,
      "y": 9,
      "z": 1,
      "name": "Rock_Sandstone_Cobble"
    },
    {
      "x": -6,
      "y": 10,
      "z": 1,
      "name": "Rock_Sandstone_Brick_Decorative"
    },
    {
      "x": -6,
      "y": 11,
      "z": 1,
      "name": "Rock_Sandstone_Cobble"
    },
    {
      "x": -6,
      "y": 12,
      "z": 1,
      "name": "Rock_Sandstone_Cobble"
    },
    {
      "x": -6,
      "y": 13,
      "z": 1,
      "name": "Rock_Sandstone_Cobble"
    },
    {
      "x": -6,
      "y": 14,
      "z": 1,
      "name": "Rock_Sandstone_Brick"
    },
    {
      "x": -6,
      "y": 5,
      "z": 2,
      "name": "Rock_Sandstone"
    },
    {
      "x": -6,
      "y": 6,
      "z": 2,
      "name": "Rock_Sandstone"
    },
    {
      "x": -6,
      "y": 7,
      "z": 2,
      "name": "Rock_Sandstone"
    },
    {
      "x": -6,
      "y": 8,
      "z": 2,
      "name": "Rock_Sandstone"
    },
    {
      "x": -6,
      "y": 9,
      "z": 2,
      "name": "Rock_Sandstone_Brick"
    },
    {
      "x": -6,
      "y": 10,
      "z": 2,
      "name": "Rock_Sandstone_Brick_Ornate"
    },
    {
      "x": -6,
      "y": 11,
      "z": 2,
      "name": "Rock_Sandstone_Cobble"
    },
    {
      "x": -6,
      "y": 12,
      "z": 2,
      "name": "Rock_Sandstone_Cobble"
    },
    {
      "x": -6,
      "y": 13,
      "z": 2,
      "name": "Rock_Sandstone_Brick"
    },
    {
      "x": -6,
      "y": 14,
      "z": 2,
      "name": "Rock_Sandstone_Brick"
    },
    {
      "x": -5,
      "y": 5,
      "z": -5,
      "name": "Soil_Dirt_Dry"
    },
    {
      "x": -5,
      "y": 10,
      "z": -5,
      "name": "Wood_Dry_Trunk",
      "rotation": 5
    },
    {
      "x": -5,
      "y": 5,
      "z": -4,
      "name": "Rock_Sandstone_Cobble"
    },
    {
      "x": -5,
      "y": 6,
      "z": -4,
      "name": "Wood_Dry_Trunk"
    },
    {
      "x": -5,
      "y": 7,
      "z": -4,
      "name": "Wood_Dry_Trunk"
    },
    {
      "x": -5,
      "y": 8,
      "z": -4,
      "name": "Wood_Dry_Trunk"
    },
    {
      "x": -5,
      "y": 9,
      "z": -4,
      "name": "Wood_Dry_Trunk"
    },
    {
      "x": -5,
      "y": 10,
      "z": -4,
      "name": "Rock_Sandstone_Brick_Ornate"
    },
    {
      "x": -5,
      "y": 11,
      "z": -4,
      "name": "Rock_Sandstone_Brick"
    },
    {
      "x": -5,
      "y": 12,
      "z": -4,
      "name": "Rock_Sandstone_Cobble"
    },
    {
      "x": -5,
      "y": 13,
      "z": -4,
      "name": "Rock_Sandstone_Cobble"
    },
    {
      "x": -5,
      "y": 14,
      "z": -4,
      "name": "Rock_Sandstone_Cobble"
    },
    {
      "x": -5,
      "y": 5,
      "z": -3,
      "name": "Rock_Sandstone_White_Cobble"
    },
    {
      "x": -5,
      "y": 10,
      "z": -3,
      "name": "Wood_Dry_Trunk",
      "rotation": 4
    },
    {
      "x": -5,
      "y": 11,
      "z": -3,
      "name": "Furniture_Village_Crate",
      "components": {
        "Components": {
          "ItemContainerBlock": {
            "ItemContainer": {
              "Capacity": 20,
              "Items": {
                "0": {
                  "Id": "Ingredient_Hide_Medium",
                  "Quantity": 2,
                  "Durability": 0.0,
                  "MaxDurability": 0.0,
                  "OverrideDroppedItemAnimation": false
                },
                "1": {
                  "Id": "Ingredient_Charcoal",
                  "Quantity": 5,
                  "Durability": 0.0,
                  "MaxDurability": 0.0,
                  "OverrideDroppedItemAnimation": false
                }
              }
            },
            "Capacity": 20
          }
        }
      }
    },
    {
      "x": -5,
      "y": 12,
      "z": -3,
      "name": "Furniture_Ancient_Barrel"
    },
    {
      "x": -5,
      "y": 5,
      "z": -2,
      "name": "Rock_Sandstone_White_Cobble"
    },
    {
      "x": -5,
      "y": 10,
      "z": -2,
      "name": "Wood_Dry_Trunk",
      "rotation": 4
    },
    {
      "x": -5,
      "y": 11,
      "z": -2,
      "name": "Furniture_Village_Crate",
      "components": {
        "Components": {
          "ItemContainerBlock": {
            "ItemContainer": {
              "Capacity": 20,
              "Items": {
                "0": {
                  "Id": "Ingredient_Hide_Medium",
                  "Quantity": 2,
                  "Durability": 0.0,
                  "MaxDurability": 0.0,
                  "OverrideDroppedItemAnimation": false
                },
                "1": {
                  "Id": "Ingredient_Charcoal",
                  "Quantity": 5,
                  "Durability": 0.0,
                  "MaxDurability": 0.0,
                  "OverrideDroppedItemAnimation": false
                }
              }
            },
            "Capacity": 20
          }
        }
      }
    },
    {
      "x": -5,
      "y": 5,
      "z": -1,
      "name": "Rock_Sandstone_White_Cobble"
    },
    {
      "x": -5,
      "y": 13,
      "z": -1,
      "name": "Cloth_Roof_Hide_Flap",
      "rotation": 1
    },
    {
      "x": -5,
      "y": 5,
      "z": 0,
      "name": "Rock_Sandstone_White_Cobble"
    },
    {
      "x": -5,
      "y": 5,
      "z": 1,
      "name": "Rock_Sandstone_White_Cobble"
    },
    {
      "x": -5,
      "y": 10,
      "z": 1,
      "name": "Wood_Drywood_Beam",
      "rotation": 5
    },
    {
      "x": -5,
      "y": 5,
      "z": 2,
      "name": "Rock_Sandstone"
    },
    {
      "x": -5,
      "y": 6,
      "z": 2,
      "name": "Rock_Sandstone"
    },
    {
      "x": -5,
      "y": 7,
      "z": 2,
      "name": "Rock_Sandstone"
    },
    {
      "x": -5,
      "y": 8,
      "z": 2,
      "name": "Rock_Sandstone_Brick"
    },
    {
      "x": -5,
      "y": 9,
      "z": 2,
      "name": "Rock_Sandstone_Brick"
    },
    {
      "x": -5,
      "y": 10,
      "z": 2,
      "name": "Rock_Sandstone_Cobble"
    },
    {
      "x": -5,
      "y": 11,
      "z": 2,
      "name": "Rock_Sandstone_Cobble"
    },
    {
      "x": -5,
      "y": 12,
      "z": 2,
      "name": "Rock_Sandstone_Cobble"
    },
    {
      "x": -5,
      "y": 13,
      "z": 2,
      "name": "Rock_Sandstone_Cobble"
    },
    {
      "x": -5,
      "y": 14,
      "z": 2,
      "name": "Rock_Sandstone_Brick"
    },
    {
      "x": -4,
      "y": 5,
      "z": -6,
      "name": "Soil_Dirt_Dry"
    },
    {
      "x": -4,
      "y": 5,
      "z": -5,
      "name": "Soil_Dirt_Dry"
    },
    {
      "x": -4,
      "y": 10,
      "z": -5,
      "name": "Wood_Dry_Trunk",
      "rotation": 5
    },
    {
      "x": -4,
      "y": 5,
      "z": -4,
      "name": "Soil_Dirt_Dry"
    },
    {
      "x": -4,
      "y": 9,
      "z": -4,
      "name": "Wood_Drywood_Planks_Half",
      "rotation": 8
    },
    {
      "x": -4,
      "y": 10,
      "z": -4,
      "name": "Rock_Sandstone_Brick_Ornate"
    },
    {
      "x": -4,
      "y": 11,
      "z": -4,
      "name": "Rock_Sandstone_Brick"
    },
    {
      "x": -4,
      "y": 12,
      "z": -4,
      "name": "Rock_Sandstone_Brick"
    },
    {
      "x": -4,
      "y": 13,
      "z": -4,
      "name": "Rock_Sandstone_Cobble"
    },
    {
      "x": -4,
      "y": 14,
      "z": -4,
      "name": "Rock_Sandstone_Cobble"
    },
    {
      "x": -4,
      "y": 5,
      "z": -3,
      "name": "Rock_Sandstone_White_Cobble"
    },
    {
      "x": -4,
      "y": 10,
      "z": -3,
      "name": "Wood_Drywood_Planks"
    },
    {
      "x": -4,
      "y": 11,
      "z": -3,
      "name": "Furniture_Ancient_Crate",
      "components": {
        "Components": {
          "ItemContainerBlock": {
            "ItemContainer": {
              "Capacity": 20,
              "Items": {
                "0": {
                  "Id": "Ingredient_Hide_Medium",
                  "Quantity": 2,
                  "Durability": 0.0,
                  "MaxDurability": 0.0,
                  "OverrideDroppedItemAnimation": false
                }
              }
            },
            "Capacity": 20
          }
        }
      },
      "rotation": 1
    },
    {
      "x": -4,
      "y": 5,
      "z": -2,
      "name": "Rock_Sandstone_White_Cobble"
    },
    {
      "x": -4,
      "y": 10,
      "z": -2,
      "name": "Wood_Drywood_Planks"
    },
    {
      "x": -4,
      "y": 5,
      "z": -1,
      "name": "Rock_Sandstone_White_Cobble"
    },
    {
      "x": -4,
      "y": 10,
      "z": -1,
      "name": "Wood_Drywood_Beam",
      "rotation": 4
    },
    {
      "x": -4,
      "y": 5,
      "z": 0,
      "name": "Rock_Sandstone_White_Cobble"
    },
    {
      "x": -4,
      "y": 5,
      "z": 1,
      "name": "Rock_Sandstone_White_Cobble"
    },
    {
      "x": -4,
      "y": 10,
      "z": 1,
      "name": "Wood_Drywood_Beam",
      "rotation": 5
    },
    {
      "x": -4,
      "y": 9,
      "z": 2,
      "name": "Rock_Sandstone_Brick"
    },
    {
      "x": -4,
      "y": 10,
      "z": 2,
      "name": "Rock_Sandstone_Cobble"
    },
    {
      "x": -4,
      "y": 11,
      "z": 2,
      "name": "Rock_Sandstone_Brick"
    },
    {
      "x": -4,
      "y": 12,
      "z": 2,
      "name": "Rock_Sandstone_Cobble"
    },
    {
      "x": -4,
      "y": 13,
      "z": 2,
      "name": "Rock_Sandstone_Cobble"
    },
    {
      "x": -4,
      "y": 14,
      "z": 2,
      "name": "Rock_Sandstone_Cobble"
    },
    {
      "x": -3,
      "y": 5,
      "z": -6,
      "name": "Soil_Dirt_Dry"
    },
    {
      "x": -3,
      "y": 5,
      "z": -5,
      "name": "Soil_Dirt_Dry"
    },
    {
      "x": -3,
      "y": 10,
      "z": -5,
      "name": "Wood_Dry_Trunk",
      "rotation": 5
    },
    {
      "x": -3,
      "y": 5,
      "z": -4,
      "name": "Soil_Dirt_Dry"
    },
    {
      "x": -3,
      "y": 9,
      "z": -4,
      "name": "Wood_Drywood_Planks_Half",
      "rotation": 8
    },
    {
      "x": -3,
      "y": 10,
      "z": -4,
      "name": "Rock_Sandstone_Brick_Ornate"
    },
    {
      "x": -3,
      "y": 11,
      "z": -4,
      "name": "Rock_Sandstone_Cobble_Half"
    },
    {
      "x": -3,
      "y": 13,
      "z": -4,
      "name": "Rock_Sandstone_Cobble_Half",
      "rotation": 5
    },
    {
      "x": -3,
      "y": 14,
      "z": -4,
      "name": "Rock_Sandstone_Cobble"
    },
    {
      "x": -3,
      "y": 5,
      "z": -3,
      "name": "Soil_Dirt_Dry"
    },
    {
      "x": -3,
      "y": 10,
      "z": -3,
      "name": "Wood_Drywood_Planks"
    },
    {
      "x": -3,
      "y": 5,
      "z": -2,
      "name": "Rock_Sandstone_White_Cobble"
    },
    {
      "x": -3,
      "y": 10,
      "z": -2,
      "name": "Wood_Drywood_Planks"
    },
    {
      "x": -3,
      "y": 5,
      "z": -1,
      "name": "Rock_Sandstone_White_Cobble"
    },
    {
      "x": -3,
      "y": 10,
      "z": -1,
      "name": "Wood_Drywood_Planks"
    },
    {
      "x": -3,
      "y": 10,
      "z": 0,
      "name": "Wood_Drywood_Planks"
    },
    {
      "x": -3,
      "y": 10,
      "z": 1,
      "name": "Wood_Drywood_Beam",
      "rotation": 5
    },
    {
      "x": -3,
      "y": 13,
      "z": 1,
      "name": "Cloth_Roof_Hide_Flap",
      "rotation": 2
    },
    {
      "x": -3,
      "y": 9,
      "z": 2,
      "name": "Rock_Sandstone_Brick"
    },
    {
      "x": -3,
      "y": 10,
      "z": 2,
      "name": "Rock_Sandstone_Cobble"
    },
    {
      "x": -3,
      "y": 11,
      "z": 2,
      "name": "Rock_Sandstone_Brick"
    },
    {
      "x": -3,
      "y": 12,
      "z": 2,
      "name": "Wood_Drywood_Fence"
    },
    {
      "x": -3,
      "y": 13,
      "z": 2,
      "name": "Wood_Drywood_Fence",
      "rotation": 2
    },
    {
      "x": -3,
      "y": 14,
      "z": 2,
      "name": "Rock_Sandstone_Cobble"
    },
    {
      "x": -2,
      "y": 5,
      "z": -6,
      "name": "Soil_Dirt_Dry"
    },
    {
      "x": -2,
      "y": 5,
      "z": -5,
      "name": "Soil_Dirt_Dry"
    },
    {
      "x": -2,
      "y": 10,
      "z": -5,
      "name": "Wood_Dry_Trunk",
      "rotation": 5
    },
    {
      "x": -2,
      "y": 5,
      "z": -4,
      "name": "Soil_Dirt_Dry"
    },
    {
      "x": -2,
      "y": 9,
      "z": -4,
      "name": "Wood_Drywood_Planks_Half",
      "rotation": 8
    },
    {
      "x": -2,
      "y": 10,
      "z": -4,
      "name": "Rock_Sandstone_Brick_Ornate"
    },
    {
      "x": -2,
      "y": 11,
      "z": -4,
      "name": "Rock_Sandstone_Cobble_Half"
    },
    {
      "x": -2,
      "y": 5,
      "z": -3,
      "name": "Soil_Dirt_Dry"
    },
    {
      "x": -2,
      "y": 10,
      "z": -3,
      "name": "Wood_Dry_Trunk",
      "rotation": 4
    },
    {
      "x": -2,
      "y": 5,
      "z": -2,
      "name": "Rock_Sandstone_White_Cobble"
    },
    {
      "x": -2,
      "y": 10,
      "z": -2,
      "name": "Wood_Dry_Trunk",
      "rotation": 4
    },
    {
      "x": -2,
      "y": 10,
      "z": -1,
      "name": "Wood_Dry_Trunk",
      "rotation": 4
    },
    {
      "x": -2,
      "y": 10,
      "z": 0,
      "name": "Wood_Dry_Trunk",
      "rotation": 4
    },
    {
      "x": -2,
      "y": 10,
      "z": 1,
      "name": "Wood_Drywood_Beam",
      "rotation": 5
    },
    {
      "x": -2,
      "y": 8,
      "z": 2,
      "name": "Rock_Sandstone_Brick_Stairs",
      "rotation": 9
    },
    {
      "x": -2,
      "y": 9,
      "z": 2,
      "name": "Rock_Sandstone_Cobble"
    },
    {
      "x": -2,
      "y": 10,
      "z": 2,
      "name": "Rock_Sandstone_Cobble"
    },
    {
      "x": -2,
      "y": 11,
      "z": 2,
      "name": "Rock_Sandstone_Brick"
    },
    {
      "x": -2,
      "y": 12,
      "z": 2,
      "name": "Rock_Sandstone_Cobble"
    },
    {
      "x": -2,
      "y": 13,
      "z": 2,
      "name": "Rock_Sandstone_Cobble"
    },
    {
      "x": -2,
      "y": 14,
      "z": 2,
      "name": "Rock_Sandstone_Cobble_Half",
      "rotation": 5
    },
    {
      "x": -1,
      "y": 5,
      "z": -6,
      "name": "Soil_Dirt_Dry"
    },
    {
      "x": -1,
      "y": 5,
      "z": -5,
      "name": "Soil_Dirt_Dry"
    },
    {
      "x": -1,
      "y": 10,
      "z": -5,
      "name": "Wood_Dry_Trunk",
      "rotation": 5
    },
    {
      "x": -1,
      "y": 5,
      "z": -4,
      "name": "Rock_Sandstone_Cobble"
    },
    {
      "x": -1,
      "y": 6,
      "z": -4,
      "name": "Wood_Dry_Trunk"
    },
    {
      "x": -1,
      "y": 7,
      "z": -4,
      "name": "Wood_Dry_Trunk"
    },
    {
      "x": -1,
      "y": 8,
      "z": -4,
      "name": "Wood_Dry_Trunk"
    },
    {
      "x": -1,
      "y": 9,
      "z": -4,
      "name": "Wood_Dry_Trunk"
    },
    {
      "x": -1,
      "y": 10,
      "z": -4,
      "name": "Rock_Sandstone_Brick_Ornate"
    },
    {
      "x": -1,
      "y": 11,
      "z": -4,
      "name": "Rock_Sandstone_Cobble"
    },
    {
      "x": -1,
      "y": 5,
      "z": -3,
      "name": "Rock_Sandstone_White_Cobble"
    },
    {
      "x": -1,
      "y": 10,
      "z": -3,
      "name": "Wood_Drywood_Planks"
    },
    {
      "x": -1,
      "y": 11,
      "z": -3,
      "name": "Furniture_Ancient_Barrel"
    },
    {
      "x": -1,
      "y": 5,
      "z": -2,
      "name": "Rock_Sandstone_White_Cobble"
    },
    {
      "x": -1,
      "y": 10,
      "z": -2,
      "name": "Wood_Drywood_Planks"
    },
    {
      "x": -1,
      "y": 10,
      "z": -1,
      "name": "Wood_Drywood_Planks"
    },
    {
      "x": -1,
      "y": 10,
      "z": 0,
      "name": "Wood_Drywood_Planks"
    },
    {
      "x": -1,
      "y": 10,
      "z": 1,
      "name": "Wood_Drywood_Planks"
    },
    {
      "x": -1,
      "y": 5,
      "z": 2,
      "name": "Rock_Sandstone_Brick"
    },
    {
      "x": -1,
      "y": 6,
      "z": 2,
      "name": "Rock_Sandstone_Brick"
    },
    {
      "x": -1,
      "y": 7,
      "z": 2,
      "name": "Rock_Sandstone_Brick"
    },
    {
      "x": -1,
      "y": 8,
      "z": 2,
      "name": "Rock_Sandstone_Brick"
    },
    {
      "x": -1,
      "y": 9,
      "z": 2,
      "name": "Rock_Sandstone_Cobble"
    },
    {
      "x": -1,
      "y": 10,
      "z": 2,
      "name": "Rock_Sandstone_Cobble"
    },
    {
      "x": -1,
      "y": 11,
      "z": 2,
      "name": "Rock_Sandstone_Cobble"
    },
    {
      "x": -1,
      "y": 12,
      "z": 2,
      "name": "Rock_Sandstone_Cobble"
    },
    {
      "x": 0,
      "y": 5,
      "z": -5,
      "name": "Soil_Dirt_Dry"
    },
    {
      "x": 0,
      "y": 10,
      "z": -5,
      "name": "Wood_Dry_Trunk",
      "rotation": 5
    },
    {
      "x": 0,
      "y": 5,
      "z": -4,
      "name": "Rock_Sandstone_Cobble"
    },
    {
      "x": 0,
      "y": 6,
      "z": -4,
      "name": "Rock_Sandstone_Cobble"
    },
    {
      "x": 0,
      "y": 7,
      "z": -4,
      "name": "Rock_Sandstone_Cobble"
    },
    {
      "x": 0,
      "y": 8,
      "z": -4,
      "name": "Rock_Sandstone_Brick"
    },
    {
      "x": 0,
      "y": 9,
      "z": -4,
      "name": "Rock_Sandstone_Brick"
    },
    {
      "x": 0,
      "y": 10,
      "z": -4,
      "name": "Rock_Sandstone_Brick_Ornate"
    },
    {
      "x": 0,
      "y": 11,
      "z": -4,
      "name": "Rock_Sandstone_Cobble"
    },
    {
      "x": 0,
      "y": 5,
      "z": -3,
      "name": "Rock_Sandstone_Cobble"
    },
    {
      "x": 0,
      "y": 6,
      "z": -3,
      "name": "Rock_Sandstone_Cobble"
    },
    {
      "x": 0,
      "y": 7,
      "z": -3,
      "name": "Rock_Sandstone_Cobble"
    },
    {
      "x": 0,
      "y": 8,
      "z": -3,
      "name": "Rock_Sandstone_Brick"
    },
    {
      "x": 0,
      "y": 9,
      "z": -3,
      "name": "Rock_Sandstone_Brick"
    },
    {
      "x": 0,
      "y": 10,
      "z": -3,
      "name": "Rock_Sandstone_Cobble"
    },
    {
      "x": 0,
      "y": 11,
      "z": -3,
      "name": "Rock_Sandstone_Cobble"
    },
    {
      "x": 0,
      "y": 12,
      "z": -3,
      "name": "Rock_Sandstone_Cobble_Half"
    },
    {
      "x": 0,
      "y": 5,
      "z": -2,
      "name": "Rock_Sandstone_White_Cobble"
    },
    {
      "x": 0,
      "y": 8,
      "z": -2,
      "name": "Rock_Sandstone_Brick_Stairs",
      "rotation": 10
    },
    {
      "x": 0,
      "y": 9,
      "z": -2,
      "name": "Rock_Sandstone_Brick"
    },
    {
      "x": 0,
      "y": 10,
      "z": -2,
      "name": "Wood_Dry_Trunk",
      "rotation": 4
    },
    {
      "x": 0,
      "y": 5,
      "z": -1,
      "name": "Rock_Sandstone_White_Cobble"
    },
    {
      "x": 0,
      "y": 9,
      "z": -1,
      "name": "Rock_Sandstone_Brick"
    },
    {
      "x": 0,
      "y": 10,
      "z": -1,
      "name": "Wood_Dry_Trunk",
      "rotation": 4
    },
    {
      "x": 0,
      "y": 5,
      "z": 0,
      "name": "Rock_Sandstone_Brick"
    },
    {
      "x": 0,
      "y": 8,
      "z": 0,
      "name": "Rock_Sandstone_Brick_Stairs",
      "rotation": 8
    },
    {
      "x": 0,
      "y": 9,
      "z": 0,
      "name": "Rock_Sandstone_Brick"
    },
    {
      "x": 0,
      "y": 10,
      "z": 0,
      "name": "Wood_Dry_Trunk",
      "rotation": 4
    },
    {
      "x": 0,
      "y": 5,
      "z": 1,
      "name": "Rock_Sandstone_Brick"
    },
    {
      "x": 0,
      "y": 6,
      "z": 1,
      "name": "Rock_Sandstone_Brick"
    },
    {
      "x": 0,
      "y": 7,
      "z": 1,
      "name": "Rock_Sandstone_Brick"
    },
    {
      "x": 0,
      "y": 8,
      "z": 1,
      "name": "Rock_Sandstone_Brick"
    },
    {
      "x": 0,
      "y": 9,
      "z": 1,
      "name": "Rock_Sandstone_Brick"
    },
    {
      "x": 0,
      "y": 10,
      "z": 1,
      "name": "Wood_Dry_Trunk",
      "rotation": 4
    },
    {
      "x": 0,
      "y": 5,
      "z": 2,
      "name": "Rock_Sandstone_Brick"
    },
    {
      "x": 0,
      "y": 6,
      "z": 2,
      "name": "Rock_Sandstone_Brick"
    },
    {
      "x": 0,
      "y": 7,
      "z": 2,
      "name": "Rock_Sandstone_Brick"
    },
    {
      "x": 0,
      "y": 8,
      "z": 2,
      "name": "Rock_Sandstone_Brick"
    },
    {
      "x": 0,
      "y": 9,
      "z": 2,
      "name": "Rock_Sandstone_Cobble"
    },
    {
      "x": 0,
      "y": 10,
      "z": 2,
      "name": "Rock_Sandstone_Cobble_Half",
      "rotation": 5
    },
    {
      "x": 0,
      "y": 11,
      "z": 2,
      "name": "Rock_Sandstone_Cobble_Half",
      "rotation": 5
    },
    {
      "x": 1,
      "y": 5,
      "z": -6,
      "name": "Rock_Sandstone_Cobble"
    },
    {
      "x": 1,
      "y": 6,
      "z": -6,
      "name": "Rock_Sandstone_Cobble"
    },
    {
      "x": 1,
      "y": 7,
      "z": -6,
      "name": "Rock_Sandstone_Cobble"
    },
    {
      "x": 1,
      "y": 8,
      "z": -6,
      "name": "Rock_Sandstone_Brick"
    },
    {
      "x": 1,
      "y": 9,
      "z": -6,
      "name": "Rock_Sandstone_Brick"
    },
    {
      "x": 1,
      "y": 5,
      "z": -5,
      "name": "Rock_Sandstone_Cobble"
    },
    {
      "x": 1,
      "y": 6,
      "z": -5,
      "name": "Rock_Sandstone_Cobble"
    },
    {
      "x": 1,
      "y": 7,
      "z": -5,
      "name": "Rock_Sandstone_Brick"
    },
    {
      "x": 1,
      "y": 8,
      "z": -5,
      "name": "Rock_Sandstone_Brick"
    },
    {
      "x": 1,
      "y": 9,
      "z": -5,
      "name": "Rock_Sandstone_Brick"
    },
    {
      "x": 1,
      "y": 5,
      "z": -4,
      "name": "Rock_Sandstone_Cobble"
    },
    {
      "x": 1,
      "y": 6,
      "z": -4,
      "name": "Rock_Sandstone_Cobble"
    },
    {
      "x": 1,
      "y": 7,
      "z": -4,
      "name": "Rock_Sandstone_Brick"
    },
    {
      "x": 1,
      "y": 8,
      "z": -4,
      "name": "Rock_Sandstone_Brick"
    },
    {
      "x": 1,
      "y": 9,
      "z": -4,
      "name": "Rock_Sandstone_Brick"
    },
    {
      "x": 1,
      "y": 10,
      "z": -4,
      "name": "Rock_Sandstone_Brick_Stairs",
      "rotation": 2
    },
    {
      "x": 1,
      "y": 5,
      "z": -3,
      "name": "Rock_Sandstone_White_Cobble"
    },
    {
      "x": 1,
      "y": 10,
      "z": -3,
      "name": "Wood_Dry_Trunk",
      "rotation": 5
    },
    {
      "x": 1,
      "y": 5,
      "z": -2,
      "name": "Rock_Sandstone_White_Cobble"
    },
    {
      "x": 1,
      "y": 10,
      "z": -2,
      "name": "Wood_Drywood_Planks"
    },
    {
      "x": 1,
      "y": 5,
      "z": -1,
      "name": "Rock_Sandstone_White_Cobble"
    },
    {
      "x": 1,
      "y": 10,
      "z": -1,
      "name": "Wood_Drywood_Planks"
    },
    {
      "x": 1,
      "y": 5,
      "z": 0,
      "name": "Rock_Sandstone_White_Cobble"
    },
    {
      "x": 1,
      "y": 10,
      "z": 0,
      "name": "Wood_Drywood_Planks"
    },
    {
      "x": 1,
      "y": 5,
      "z": 1,
      "name": "Rock_Sandstone_White_Cobble"
    },
    {
      "x": 1,
      "y": 6,
      "z": 1,
      "name": "Furniture_Temple_Dark_Pot"
    },
    {
      "x": 1,
      "y": 5,
      "z": 2,
      "name": "Rock_Sandstone_Brick"
    },
    {
      "x": 1,
      "y": 6,
      "z": 2,
      "name": "Rock_Sandstone_Brick"
    },
    {
      "x": 1,
      "y": 7,
      "z": 2,
      "name": "Rock_Sandstone_Brick_Stairs",
      "rotation": 1
    },
    {
      "x": 2,
      "y": 5,
      "z": -6,
      "name": "Rock_Sandstone_Cobble"
    },
    {
      "x": 2,
      "y": 6,
      "z": -6,
      "name": "Rock_Sandstone_Cobble"
    },
    {
      "x": 2,
      "y": 7,
      "z": -6,
      "name": "Rock_Sandstone_Brick"
    },
    {
      "x": 2,
      "y": 8,
      "z": -6,
      "name": "Rock_Sandstone_Brick"
    },
    {
      "x": 2,
      "y": 9,
      "z": -6,
      "name": "Rock_Sandstone_Brick"
    },
    {
      "x": 2,
      "y": 5,
      "z": -5,
      "name": "Rock_Sandstone_Brick"
    },
    {
      "x": 2,
      "y": 6,
      "z": -5,
      "name": "Rock_Sandstone_Brick"
    },
    {
      "x": 2,
      "y": 7,
      "z": -5,
      "name": "Rock_Sandstone_Brick"
    },
    {
      "x": 2,
      "y": 8,
      "z": -5,
      "name": "Rock_Sandstone_Brick"
    },
    {
      "x": 2,
      "y": 9,
      "z": -5,
      "name": "Rock_Sandstone_Brick"
    },
    {
      "x": 2,
      "y": 5,
      "z": -4,
      "name": "Rock_Sandstone_Brick"
    },
    {
      "x": 2,
      "y": 6,
      "z": -4,
      "name": "Rock_Sandstone_Brick"
    },
    {
      "x": 2,
      "y": 7,
      "z": -4,
      "name": "Rock_Sandstone_Brick"
    },
    {
      "x": 2,
      "y": 8,
      "z": -4,
      "name": "Rock_Sandstone_Brick"
    },
    {
      "x": 2,
      "y": 9,
      "z": -4,
      "name": "Rock_Sandstone_Brick"
    },
    {
      "x": 2,
      "y": 10,
      "z": -4,
      "name": "Rock_Sandstone_Brick_Stairs",
      "rotation": 2
    },
    {
      "x": 2,
      "y": 5,
      "z": -3,
      "name": "Rock_Sandstone_White_Cobble"
    },
    {
      "x": 2,
      "y": 10,
      "z": -3,
      "name": "Wood_Dry_Trunk",
      "rotation": 5
    },
    {
      "x": 2,
      "y": 5,
      "z": -2,
      "name": "Rock_Sandstone_White_Cobble"
    },
    {
      "x": 2,
      "y": 10,
      "z": -2,
      "name": "Wood_Drywood_Planks"
    },
    {
      "x": 2,
      "y": 5,
      "z": -1,
      "name": "Rock_Sandstone_White_Cobble"
    },
    {
      "x": 2,
      "y": 10,
      "z": -1,
      "name": "Wood_Drywood_Planks"
    },
    {
      "x": 2,
      "y": 5,
      "z": 0,
      "name": "Rock_Sandstone_White_Cobble"
    },
    {
      "x": 2,
      "y": 10,
      "z": 0,
      "name": "Wood_Drywood_Beam",
      "rotation": 5
    },
    {
      "x": 2,
      "y": 5,
      "z": 1,
      "name": "Rock_Sandstone_White_Cobble"
    },
    {
      "x": 2,
      "y": 5,
      "z": 2,
      "name": "Rock_Sandstone_Brick"
    },
    {
      "x": 2,
      "y": 6,
      "z": 2,
      "name": "Rock_Sandstone_Brick_Stairs",
      "rotation": 1
    },
    {
      "x": 3,
      "y": 5,
      "z": -6,
      "name": "Rock_Sandstone_Cobble"
    },
    {
      "x": 3,
      "y": 6,
      "z": -6,
      "name": "Rock_Sandstone_Cobble"
    },
    {
      "x": 3,
      "y": 7,
      "z": -6,
      "name": "Rock_Sandstone_Cobble"
    },
    {
      "x": 3,
      "y": 5,
      "z": -5,
      "name": "Rock_Sandstone_Brick"
    },
    {
      "x": 3,
      "y": 6,
      "z": -5,
      "name": "Rock_Sandstone_Cobble"
    },
    {
      "x": 3,
      "y": 5,
      "z": -4,
      "name": "Rock_Sandstone_Brick"
    },
    {
      "x": 3,
      "y": 6,
      "z": -4,
      "name": "Rock_Sandstone_Brick"
    },
    {
      "x": 3,
      "y": 10,
      "z": -3,
      "name": "Wood_Dry_Trunk",
      "support": 15,
      "rotation": 5
    },
    {
      "x": 3,
      "y": 10,
      "z": -2,
      "name": "Wood_Drywood_Planks"
    },
    {
      "x": 3,
      "y": 10,
      "z": -1,
      "name": "Wood_Drywood_Planks"
    },
    {
      "x": 3,
      "y": 10,
      "z": 0,
      "name": "Wood_Drywood_Beam",
      "rotation": 5
    },
    {
      "x": 3,
      "y": 5,
      "z": 2,
      "name": "Rock_Sandstone_Brick_Stairs",
      "rotation": 1
    }
  ],
  "entities": [
    {
      "Components": {
        "Nameplate": {
          "Text": "Zombie_Sand"
        },
        "HiddenFromAdventurePlayer": {},
        "SpawnMarkerComponent": {
          "SpawnMarker": "Zombie_Sand",
          "RespawnTime": 0.0,
          "SpawnCount": 0,
          "NPCReferences": [],
          "PersistedFlock": {},
          "SpawnPosition": {
            "X": 0.0,
            "Y": 0.0,
            "Z": 0.0
          }
        },
        "Transform": {
          "Position": {
            "X": -1.812857031249223,
            "Y": 11.0,
            "Z": -0.4887355957030195
          },
          "Rotation": {
            "Pitch": 0.0,
            "Yaw": 4.680466651916504,
            "Roll": 0.0
          }
        },
        "Intangible": {},
        "PrefabCopyable": {},
        "Model": {
          "Model": {
            "Id": "NPC_Spawn_Marker",
            "Scale": 1.0,
            "Static": false
          }
        },
        "UUID": {
          "UUID": {
            "$binary": "pSf8pL93OVqadklD7N4y1A==",
            "$type": "04"
          }
        },
        "HeadRotation": {
          "Rotation": {
            "Pitch": 0.0,
            "Yaw": 1.5388737916946411,
            "Roll": 0.0
          }
        }
      }
    }
  ]
}