{
  "version": 8,
  "blockIdVersion": 11,
  "anchorX": -14,
  "anchorY": -17,
  "anchorZ": -23,
  "blocks": [
    {
      "x": -14,
      "y": -16,
      "z": -19,
      "name": "Rock_Sandstone_Brick_Smooth_Half",
      "rotation": 7
    },
    {
      "x": -14,
      "y": -13,
      "z": -19,
      "name": "Rock_Sandstone_Cobble_Roof_Hollow",
      "rotation": 3
    },
    {
      "x": -14,
      "y": -16,
      "z": -18,
      "name": "Rock_Sandstone_Brick_Smooth_Half",
      "rotation": 7
    },
    {
      "x": -14,
      "y": -13,
      "z": -18,
      "name": "Rock_Sandstone_Cobble_Roof_Hollow",
      "rotation": 3
    },
    {
      "x": -14,
      "y": -16,
      "z": -17,
      "name": "Rock_Sandstone_Brick_Smooth_Half",
      "rotation": 7
    },
    {
      "x": -13,
      "y": -16,
      "z": -21,
      "name": "Rock_Sandstone_Brick_Half",
      "rotation": 6
    },
    {
      "x": -13,
      "y": -15,
      "z": -21,
      "name": "Rock_Sandstone_Brick_Half",
      "rotation": 6
    },
    {
      "x": -13,
      "y": -14,
      "z": -21,
      "name": "Rock_Sandstone_Brick"
    },
    {
      "x": -13,
      "y": -13,
      "z": -21,
      "name": "Rock_Sandstone_Brick"
    },
    {
      "x": -13,
      "y": -12,
      "z": -21,
      "name": "Rock_Sandstone_Brick"
    },
    {
      "x": -13,
      "y": -11,
      "z": -21,
      "name": "Rock_Sandstone_Brick_Ornate"
    },
    {
      "x": -13,
      "y": -10,
      "z": -21,
      "name": "Rock_Sandstone_Brick"
    },
    {
      "x": -13,
      "y": -9,
      "z": -21,
      "name": "Rock_Sandstone_Brick_Half"
    },
    {
      "x": -13,
      "y": -17,
      "z": -20,
      "name": "Rock_Sandstone_Brick"
    },
    {
      "x": -13,
      "y": -16,
      "z": -20,
      "name": "Rock_Sandstone_White_Brick"
    },
    {
      "x": -13,
      "y": -15,
      "z": -20,
      "name": "Rock_Sandstone_White_Brick"
    },
    {
      "x": -13,
      "y": -14,
      "z": -20,
      "name": "Rock_Sandstone_White_Brick"
    },
    {
      "x": -13,
      "y": -13,
      "z": -20,
      "name": "Rock_Sandstone_White_Brick"
    },
    {
      "x": -13,
      "y": -12,
      "z": -20,
      "name": "Rock_Sandstone_White_Brick"
    },
    {
      "x": -13,
      "y": -11,
      "z": -20,
      "name": "Rock_Sandstone_Brick_Ornate"
    },
    {
      "x": -13,
      "y": -10,
      "z": -20,
      "name": "Rock_Sandstone_White_Cobble"
    },
    {
      "x": -13,
      "y": -9,
      "z": -20,
      "name": "Rock_Sandstone_White_Cobble_Half"
    },
    {
      "x": -13,
      "y": -17,
      "z": -19,
      "name": "Rock_Sandstone_Brick"
    },
    {
      "x": -13,
      "y": -16,
      "z": -19,
      "name": "Rock_Sandstone_White_Brick"
    },
    {
      "x": -13,
      "y": -15,
      "z": -19,
      "name": "Furniture_Desert_Window",
      "rotation": 1
    },
    {
      "x": -13,
      "y": -14,
      "z": -19,
      "name": "Wood_Drywood_Beam"
    },
    {
      "x": -13,
      "y": -13,
      "z": -19,
      "name": "Wood_Dry_Trunk",
      "rotation": 4
    },
    {
      "x": -13,
      "y": -12,
      "z": -19,
      "name": "Rock_Sandstone_White_Brick"
    },
    {
      "x": -13,
      "y": -11,
      "z": -19,
      "name": "Rock_Sandstone_Brick_Ornate"
    },
    {
      "x": -13,
      "y": -10,
      "z": -19,
      "name": "Rock_Sandstone_White_Cobble"
    },
    {
      "x": -13,
      "y": -9,
      "z": -19,
      "name": "Rock_Sandstone_White_Cobble_Half"
    },
    {
      "x": -13,
      "y": -17,
      "z": -18,
      "name": "Rock_Sandstone_Brick"
    },
    {
      "x": -13,
      "y": -16,
      "z": -18,
      "name": "Rock_Sandstone_White_Brick"
    },
    {
      "x": -13,
      "y": -15,
      "z": -18,
      "name": "Furniture_Desert_Window",
      "rotation": 1
    },
    {
      "x": -13,
      "y": -14,
      "z": -18,
      "name": "Furniture_Desert_Window",
      "rotation": 1
    },
    {
      "x": -13,
      "y": -13,
      "z": -18,
      "name": "Wood_Dry_Trunk",
      "rotation": 4
    },
    {
      "x": -13,
      "y": -12,
      "z": -18,
      "name": "Rock_Sandstone_White_Brick"
    },
    {
      "x": -13,
      "y": -11,
      "z": -18,
      "name": "Rock_Sandstone_Brick_Ornate"
    },
    {
      "x": -13,
      "y": -10,
      "z": -18,
      "name": "Rock_Sandstone_White_Cobble"
    },
    {
      "x": -13,
      "y": -17,
      "z": -17,
      "name": "Rock_Sandstone_Brick"
    },
    {
      "x": -13,
      "y": -16,
      "z": -17,
      "name": "Rock_Sandstone_White_Brick"
    },
    {
      "x": -13,
      "y": -15,
      "z": -17,
      "name": "Furniture_Desert_Window",
      "rotation": 1
    },
    {
      "x": -13,
      "y": -14,
      "z": -17,
      "name": "Furniture_Desert_Window",
      "rotation": 1
    },
    {
      "x": -13,
      "y": -13,
      "z": -17,
      "name": "Wood_Dry_Trunk",
      "rotation": 4
    },
    {
      "x": -13,
      "y": -12,
      "z": -17,
      "name": "Rock_Sandstone_White_Brick"
    },
    {
      "x": -13,
      "y": -11,
      "z": -17,
      "name": "Rock_Sandstone_Brick_Ornate"
    },
    {
      "x": -13,
      "y": -10,
      "z": -17,
      "name": "Rock_Sandstone_White_Cobble"
    },
    {
      "x": -13,
      "y": -17,
      "z": -16,
      "name": "Rock_Sandstone_Brick"
    },
    {
      "x": -13,
      "y": -16,
      "z": -16,
      "name": "Rock_Sandstone_White_Brick"
    },
    {
      "x": -13,
      "y": -15,
      "z": -16,
      "name": "Rock_Sandstone_White_Brick"
    },
    {
      "x": -13,
      "y": -14,
      "z": -16,
      "name": "Rock_Sandstone_White_Brick"
    },
    {
      "x": -13,
      "y": -13,
      "z": -16,
      "name": "Rock_Sandstone_White_Brick"
    },
    {
      "x": -13,
      "y": -12,
      "z": -16,
      "name": "Rock_Sandstone_White_Brick"
    },
    {
      "x": -13,
      "y": -11,
      "z": -16,
      "name": "Rock_Sandstone_Brick_Ornate"
    },
    {
      "x": -13,
      "y": -17,
      "z": -15,
      "name": "Rock_Sandstone_Brick"
    },
    {
      "x": -13,
      "y": -16,
      "z": -15,
      "name": "Rock_Sandstone_Brick"
    },
    {
      "x": -13,
      "y": -15,
      "z": -15,
      "name": "Rock_Sandstone_Brick"
    },
    {
      "x": -13,
      "y": -14,
      "z": -15,
      "name": "Rock_Sandstone_Brick"
    },
    {
      "x": -13,
      "y": -13,
      "z": -15,
      "name": "Rock_Sandstone_Brick"
    },
    {
      "x": -13,
      "y": -12,
      "z": -15,
      "name": "Rock_Sandstone_Brick"
    },
    {
      "x": -12,
      "y": -17,
      "z": -23,
      "name": "Rock_Sandstone_Brick"
    },
    {
      "x": -12,
      "y": -16,
      "z": -23,
      "name": "Rock_Sandstone_Brick"
    },
    {
      "x": -12,
      "y": -15,
      "z": -23,
      "name": "Rock_Sandstone_White_Cobble"
    },
    {
      "x": -12,
      "y": -14,
      "z": -23,
      "name": "Rock_Sandstone_White_Cobble"
    },
    {
      "x": -12,
      "y": -13,
      "z": -23,
      "name": "Rock_Sandstone_White_Cobble"
    },
    {
      "x": -12,
      "y": -12,
      "z": -23,
      "name": "Rock_Sandstone_White_Cobble_Half",
      "rotation": 6
    },
    {
      "x": -12,
      "y": -17,
      "z": -22,
      "name": "Rock_Sandstone_Brick"
    },
    {
      "x": -12,
      "y": -16,
      "z": -22,
      "name": "Rock_Sandstone_Brick"
    },
    {
      "x": -12,
      "y": -15,
      "z": -22,
      "name": "Rock_Sandstone_White_Cobble"
    },
    {
      "x": -12,
      "y": -14,
      "z": -22,
      "name": "Rock_Sandstone_White_Cobble"
    },
    {
      "x": -12,
      "y": -13,
      "z": -22,
      "name": "Rock_Sandstone_White_Cobble"
    },
    {
      "x": -12,
      "y": -12,
      "z": -22,
      "name": "Rock_Sandstone_White_Cobble"
    },
    {
      "x": -12,
      "y": -17,
      "z": -21,
      "name": "Rock_Sandstone_Brick"
    },
    {
      "x": -12,
      "y": -16,
      "z": -21,
      "name": "Rock_Sandstone_Brick"
    },
    {
      "x": -12,
      "y": -15,
      "z": -21,
      "name": "Rock_Sandstone_Brick"
    },
    {
      "x": -12,
      "y": -14,
      "z": -21,
      "name": "Rock_Sandstone_Brick"
    },
    {
      "x": -12,
      "y": -13,
      "z": -21,
      "name": "Rock_Sandstone_Brick"
    },
    {
      "x": -12,
      "y": -12,
      "z": -21,
      "name": "Rock_Sandstone_Brick"
    },
    {
      "x": -12,
      "y": -11,
      "z": -21,
      "name": "Rock_Sandstone_Brick_Ornate"
    },
    {
      "x": -12,
      "y": -10,
      "z": -21,
      "name": "Rock_Sandstone_Brick"
    },
    {
      "x": -12,
      "y": -17,
      "z": -20,
      "name": "Rock_Sandstone_Cobble"
    },
    {
      "x": -12,
      "y": -11,
      "z": -20,
      "name": "Wood_Drywood_Beam",
      "rotation": 4
    },
    {
      "x": -12,
      "y": -17,
      "z": -19,
      "name": "Rock_Sandstone_Cobble"
    },
    {
      "x": -12,
      "y": -14,
      "z": -19,
      "name": "Cloth_Roof_Hide_Flap",
      "rotation": 1
    },
    {
      "x": -12,
      "y": -13,
      "z": -19,
      "name": "Cloth_Roof_Hide_Vertical",
      "rotation": 1
    },
    {
      "x": -12,
      "y": -11,
      "z": -19,
      "name": "Wood_Drywood_Beam",
      "rotation": 4
    },
    {
      "x": -12,
      "y": -17,
      "z": -18,
      "name": "Rock_Sandstone_Cobble"
    },
    {
      "x": -12,
      "y": -16,
      "z": -18,
      "name": "Furniture_Desert_Chair",
      "rotation": 1
    },
    {
      "x": -12,
      "y": -14,
      "z": -18,
      "name": "Cloth_Roof_Hide_Flap",
      "rotation": 1
    },
    {
      "x": -12,
      "y": -13,
      "z": -18,
      "name": "Cloth_Roof_Hide_Vertical",
      "rotation": 1
    },
    {
      "x": -12,
      "y": -11,
      "z": -18,
      "name": "Wood_Drywood_Beam",
      "rotation": 4
    },
    {
      "x": -12,
      "y": -17,
      "z": -17,
      "name": "Rock_Sandstone_Cobble"
    },
    {
      "x": -12,
      "y": -14,
      "z": -17,
      "name": "Cloth_Roof_Hide_Flap",
      "rotation": 1
    },
    {
      "x": -12,
      "y": -13,
      "z": -17,
      "name": "Cloth_Roof_Hide_Vertical",
      "rotation": 1
    },
    {
      "x": -12,
      "y": -11,
      "z": -17,
      "name": "Wood_Drywood_Planks"
    },
    {
      "x": -12,
      "y": -17,
      "z": -16,
      "name": "Rock_Sandstone_Cobble"
    },
    {
      "x": -12,
      "y": -11,
      "z": -16,
      "name": "Wood_Drywood_Planks"
    },
    {
      "x": -12,
      "y": -17,
      "z": -15,
      "name": "Rock_Sandstone_Brick"
    },
    {
      "x": -12,
      "y": -16,
      "z": -15,
      "name": "Rock_Sandstone_White_Brick"
    },
    {
      "x": -12,
      "y": -15,
      "z": -15,
      "name": "Rock_Sandstone_White_Brick"
    },
    {
      "x": -12,
      "y": -14,
      "z": -15,
      "name": "Rock_Sandstone_White_Brick"
    },
    {
      "x": -12,
      "y": -13,
      "z": -15,
      "name": "Rock_Sandstone_White_Brick"
    },
    {
      "x": -12,
      "y": -12,
      "z": -15,
      "name": "Rock_Sandstone_White_Brick"
    },
    {
      "x": -12,
      "y": -11,
      "z": -15,
      "name": "Rock_Sandstone_Brick_Ornate"
    },
    {
      "x": -12,
      "y": -10,
      "z": -15,
      "name": "Rock_Sandstone_White_Cobble_Half"
    },
    {
      "x": -11,
      "y": -17,
      "z": -21,
      "name": "Rock_Sandstone_Cobble_Stairs",
      "rotation": 2
    },
    {
      "x": -11,
      "y": -17,
      "z": -20,
      "name": "Rock_Sandstone_Cobble"
    },
    {
      "x": -11,
      "y": -17,
      "z": -19,
      "name": "Rock_Sandstone_Cobble"
    },
    {
      "x": -11,
      "y": -11,
      "z": -19,
      "name": "Wood_Drywood_Planks_Half",
      "rotation": 7
    },
    {
      "x": -11,
      "y": -17,
      "z": -18,
      "name": "Rock_Sandstone_Cobble"
    },
    {
      "x": -11,
      "y": -16,
      "z": -18,
      "name": "Furniture_Desert_Table"
    },
    {
      "x": -11,
      "y": -11,
      "z": -18,
      "name": "Wood_Drywood_Planks_Half",
      "rotation": 7
    },
    {
      "x": -11,
      "y": -17,
      "z": -17,
      "name": "Rock_Sandstone_Cobble"
    },
    {
      "x": -11,
      "y": -16,
      "z": -17,
      "name": "Furniture_Desert_Table",
      "filler": 32
    },
    {
      "x": -11,
      "y": -11,
      "z": -17,
      "name": "Wood_Drywood_Planks_Half",
      "rotation": 7
    },
    {
      "x": -11,
      "y": -17,
      "z": -16,
      "name": "Rock_Sandstone_Cobble"
    },
    {
      "x": -11,
      "y": -14,
      "z": -16,
      "name": "Cloth_Roof_Hide_Flap",
      "rotation": 2
    },
    {
      "x": -11,
      "y": -13,
      "z": -16,
      "name": "Cloth_Roof_Hide_Vertical",
      "rotation": 2
    },
    {
      "x": -11,
      "y": -17,
      "z": -15,
      "name": "Rock_Sandstone_Brick"
    },
    {
      "x": -11,
      "y": -16,
      "z": -15,
      "name": "Rock_Sandstone_White_Brick"
    },
    {
      "x": -11,
      "y": -15,
      "z": -15,
      "name": "Furniture_Desert_Window"
    },
    {
      "x": -11,
      "y": -14,
      "z": -15,
      "name": "Furniture_Desert_Window"
    },
    {
      "x": -11,
      "y": -13,
      "z": -15,
      "name": "Rock_Sandstone_White_Brick"
    },
    {
      "x": -11,
      "y": -12,
      "z": -15,
      "name": "Rock_Sandstone_White_Brick"
    },
    {
      "x": -11,
      "y": -11,
      "z": -15,
      "name": "Rock_Sandstone_Brick_Ornate"
    },
    {
      "x": -11,
      "y": -10,
      "z": -15,
      "name": "Rock_Sandstone_White_Cobble"
    },
    {
      "x": -11,
      "y": -9,
      "z": -15,
      "name": "Rock_Sandstone_White_Cobble_Half"
    },
    {
      "x": -11,
      "y": -13,
      "z": -14,
      "name": "Rock_Sandstone_Cobble_Roof_Hollow"
    },
    {
      "x": -10,
      "y": -17,
      "z": -21,
      "name": "Rock_Sandstone_Cobble_Stairs",
      "rotation": 2
    },
    {
      "x": -10,
      "y": -13,
      "z": -21,
      "name": "Rock_Sandstone_Brick"
    },
    {
      "x": -10,
      "y": -12,
      "z": -21,
      "name": "Rock_Sandstone_Brick"
    },
    {
      "x": -10,
      "y": -11,
      "z": -21,
      "name": "Rock_Sandstone_Brick_Ornate"
    },
    {
      "x": -10,
      "y": -10,
      "z": -21,
      "name": "Rock_Sandstone_Brick_Half"
    },
    {
      "x": -10,
      "y": -17,
      "z": -20,
      "name": "Rock_Sandstone_Cobble"
    },
    {
      "x": -10,
      "y": -11,
      "z": -20,
      "name": "Wood_Drywood_Beam",
      "rotation": 4
    },
    {
      "x": -10,
      "y": -17,
      "z": -19,
      "name": "Rock_Sandstone_Cobble"
    },
    {
      "x": -10,
      "y": -11,
      "z": -19,
      "name": "Wood_Drywood_Planks"
    },
    {
      "x": -10,
      "y": -10,
      "z": -19,
      "name": "Furniture_Ancient_Pot"
    },
    {
      "x": -10,
      "y": -17,
      "z": -18,
      "name": "Rock_Sandstone_Cobble"
    },
    {
      "x": -10,
      "y": -16,
      "z": -18,
      "name": "Furniture_Desert_Table",
      "filler": 1
    },
    {
      "x": -10,
      "y": -15,
      "z": -18,
      "name": "Deco_Pot_Clay_Broken"
    },
    {
      "x": -10,
      "y": -11,
      "z": -18,
      "name": "Wood_Drywood_Planks"
    },
    {
      "x": -10,
      "y": -17,
      "z": -17,
      "name": "Rock_Sandstone_Cobble"
    },
    {
      "x": -10,
      "y": -16,
      "z": -17,
      "name": "Furniture_Desert_Table",
      "filler": 33
    },
    {
      "x": -10,
      "y": -11,
      "z": -17,
      "name": "Wood_Drywood_Planks"
    },
    {
      "x": -10,
      "y": -17,
      "z": -16,
      "name": "Rock_Sandstone_Cobble"
    },
    {
      "x": -10,
      "y": -16,
      "z": -16,
      "name": "Furniture_Desert_Chair",
      "rotation": 2
    },
    {
      "x": -10,
      "y": -14,
      "z": -16,
      "name": "Cloth_Roof_Hide_Flap",
      "rotation": 2
    },
    {
      "x": -10,
      "y": -13,
      "z": -16,
      "name": "Cloth_Roof_Hide_Vertical",
      "rotation": 2
    },
    {
      "x": -10,
      "y": -11,
      "z": -16,
      "name": "Wood_Drywood_Planks"
    },
    {
      "x": -10,
      "y": -17,
      "z": -15,
      "name": "Rock_Sandstone_Brick"
    },
    {
      "x": -10,
      "y": -16,
      "z": -15,
      "name": "Rock_Sandstone_White_Brick"
    },
    {
      "x": -10,
      "y": -15,
      "z": -15,
      "name": "Furniture_Desert_Window"
    },
    {
      "x": -10,
      "y": -14,
      "z": -15,
      "name": "Furniture_Desert_Window"
    },
    {
      "x": -10,
      "y": -13,
      "z": -15,
      "name": "Rock_Sandstone_White_Brick"
    },
    {
      "x": -10,
      "y": -12,
      "z": -15,
      "name": "Rock_Sandstone_White_Brick"
    },
    {
      "x": -10,
      "y": -11,
      "z": -15,
      "name": "Rock_Sandstone_Brick_Ornate"
    },
    {
      "x": -10,
      "y": -10,
      "z": -15,
      "name": "Rock_Sandstone_White_Brick"
    },
    {
      "x": -10,
      "y": -9,
      "z": -15,
      "name": "Rock_Sandstone_White_Cobble_Half"
    },
    {
      "x": -9,
      "y": -17,
      "z": -21,
      "name": "Rock_Sandstone_Cobble_Stairs",
      "rotation": 2
    },
    {
      "x": -9,
      "y": -14,
      "z": -21,
      "name": "Rock_Sandstone_Brick_Stairs",
      "rotation": 9
    },
    {
      "x": -9,
      "y": -13,
      "z": -21,
      "name": "Rock_Sandstone_Brick"
    },
    {
      "x": -9,
      "y": -12,
      "z": -21,
      "name": "Rock_Sandstone_Brick"
    },
    {
      "x": -9,
      "y": -11,
      "z": -21,
      "name": "Rock_Sandstone_Brick_Ornate"
    },
    {
      "x": -9,
      "y": -10,
      "z": -21,
      "name": "Rock_Sandstone_Brick_Half"
    },
    {
      "x": -9,
      "y": -17,
      "z": -20,
      "name": "Rock_Sandstone_Cobble"
    },
    {
      "x": -9,
      "y": -11,
      "z": -20,
      "name": "Wood_Drywood_Planks"
    },
    {
      "x": -9,
      "y": -17,
      "z": -19,
      "name": "Rock_Sandstone_Cobble"
    },
    {
      "x": -9,
      "y": -11,
      "z": -19,
      "name": "Wood_Drywood_Planks"
    },
    {
      "x": -9,
      "y": -17,
      "z": -18,
      "name": "Rock_Sandstone_Cobble"
    },
    {
      "x": -9,
      "y": -11,
      "z": -18,
      "name": "Wood_Drywood_Planks"
    },
    {
      "x": -9,
      "y": -17,
      "z": -17,
      "name": "Rock_Sandstone_Cobble"
    },
    {
      "x": -9,
      "y": -11,
      "z": -17,
      "name": "Wood_Drywood_Planks"
    },
    {
      "x": -9,
      "y": -17,
      "z": -16,
      "name": "Rock_Sandstone_Cobble"
    },
    {
      "x": -9,
      "y": -13,
      "z": -16,
      "name": "Cloth_Roof_Hide_Vertical",
      "rotation": 2
    },
    {
      "x": -9,
      "y": -11,
      "z": -16,
      "name": "Wood_Drywood_Planks"
    },
    {
      "x": -9,
      "y": -17,
      "z": -15,
      "name": "Rock_Sandstone_Brick"
    },
    {
      "x": -9,
      "y": -16,
      "z": -15,
      "name": "Rock_Sandstone_White_Brick"
    },
    {
      "x": -9,
      "y": -15,
      "z": -15,
      "name": "Furniture_Desert_Window"
    },
    {
      "x": -9,
      "y": -13,
      "z": -15,
      "name": "Rock_Sandstone_White_Brick"
    },
    {
      "x": -9,
      "y": -12,
      "z": -15,
      "name": "Rock_Sandstone_White_Brick"
    },
    {
      "x": -9,
      "y": -11,
      "z": -15,
      "name": "Rock_Sandstone_Brick_Ornate"
    },
    {
      "x": -9,
      "y": -10,
      "z": -15,
      "name": "Rock_Sandstone_White_Brick"
    },
    {
      "x": -9,
      "y": -9,
      "z": -15,
      "name": "Rock_Sandstone_White_Brick"
    },
    {
      "x": -9,
      "y": -13,
      "z": -14,
      "name": "Rock_Sandstone_Cobble_Roof_Hollow"
    },
    {
      "x": -8,
      "y": -17,
      "z": -23,
      "name": "Rock_Sandstone_Brick"
    },
    {
      "x": -8,
      "y": -16,
      "z": -23,
      "name": "Rock_Sandstone_Brick"
    },
    {
      "x": -8,
      "y": -15,
      "z": -23,
      "name": "Rock_Sandstone_White_Cobble"
    },
    {
      "x": -8,
      "y": -14,
      "z": -23,
      "name": "Rock_Sandstone_White_Cobble"
    },
    {
      "x": -8,
      "y": -13,
      "z": -23,
      "name": "Rock_Sandstone_White_Cobble_Half"
    },
    {
      "x": -8,
      "y": -17,
      "z": -22,
      "name": "Rock_Sandstone_Brick"
    },
    {
      "x": -8,
      "y": -16,
      "z": -22,
      "name": "Rock_Sandstone_Brick"
    },
    {
      "x": -8,
      "y": -15,
      "z": -22,
      "name": "Rock_Sandstone_White_Cobble"
    },
    {
      "x": -8,
      "y": -14,
      "z": -22,
      "name": "Rock_Sandstone_White_Cobble"
    },
    {
      "x": -8,
      "y": -13,
      "z": -22,
      "name": "Rock_Sandstone_White_Cobble"
    },
    {
      "x": -8,
      "y": -17,
      "z": -21,
      "name": "Rock_Sandstone_Brick"
    },
    {
      "x": -8,
      "y": -16,
      "z": -21,
      "name": "Rock_Sandstone_Brick"
    },
    {
      "x": -8,
      "y": -15,
      "z": -21,
      "name": "Rock_Sandstone_Brick"
    },
    {
      "x": -8,
      "y": -14,
      "z": -21,
      "name": "Rock_Sandstone_Brick"
    },
    {
      "x": -8,
      "y": -13,
      "z": -21,
      "name": "Rock_Sandstone_Brick"
    },
    {
      "x": -8,
      "y": -12,
      "z": -21,
      "name": "Rock_Sandstone_Brick"
    },
    {
      "x": -8,
      "y": -11,
      "z": -21,
      "name": "Rock_Sandstone_Brick_Ornate"
    },
    {
      "x": -8,
      "y": -17,
      "z": -20,
      "name": "Rock_Sandstone_Cobble"
    },
    {
      "x": -8,
      "y": -16,
      "z": -20,
      "name": "Rubble_Sandstone"
    },
    {
      "x": -8,
      "y": -11,
      "z": -20,
      "name": "Wood_Drywood_Planks"
    },
    {
      "x": -8,
      "y": -17,
      "z": -19,
      "name": "Rock_Sandstone_Cobble"
    },
    {
      "x": -8,
      "y": -11,
      "z": -19,
      "name": "Wood_Drywood_Planks"
    },
    {
      "x": -8,
      "y": -17,
      "z": -18,
      "name": "Rock_Sandstone_Cobble"
    },
    {
      "x": -8,
      "y": -11,
      "z": -18,
      "name": "Wood_Drywood_Planks"
    },
    {
      "x": -8,
      "y": -17,
      "z": -17,
      "name": "Rock_Sandstone_Cobble"
    },
    {
      "x": -8,
      "y": -11,
      "z": -17,
      "name": "Wood_Drywood_Planks"
    },
    {
      "x": -8,
      "y": -17,
      "z": -16,
      "name": "Rock_Sandstone_Cobble"
    },
    {
      "x": -8,
      "y": -11,
      "z": -16,
      "name": "Wood_Drywood_Planks"
    },
    {
      "x": -8,
      "y": -10,
      "z": -16,
      "name": "Deco_Pot_Clay_Broken"
    },
    {
      "x": -8,
      "y": -17,
      "z": -15,
      "name": "Rock_Sandstone_Brick"
    },
    {
      "x": -8,
      "y": -16,
      "z": -15,
      "name": "Rock_Sandstone_White_Brick"
    },
    {
      "x": -8,
      "y": -15,
      "z": -15,
      "name": "Rock_Sandstone_White_Brick"
    },
    {
      "x": -8,
      "y": -14,
      "z": -15,
      "name": "Rock_Sandstone_White_Brick"
    },
    {
      "x": -8,
      "y": -13,
      "z": -15,
      "name": "Rock_Sandstone_White_Brick"
    },
    {
      "x": -8,
      "y": -12,
      "z": -15,
      "name": "Rock_Sandstone_White_Brick"
    },
    {
      "x": -8,
      "y": -11,
      "z": -15,
      "name": "Rock_Sandstone_Brick_Ornate"
    },
    {
      "x": -8,
      "y": -10,
      "z": -15,
      "name": "Rock_Sandstone_White_Brick"
    },
    {
      "x": -8,
      "y": -9,
      "z": -15,
      "name": "Rock_Sandstone_White_Brick"
    },
    {
      "x": -7,
      "y": -17,
      "z": -21,
      "name": "Rock_Sandstone_Brick"
    },
    {
      "x": -7,
      "y": -16,
      "z": -21,
      "name": "Rock_Sandstone_Brick"
    },
    {
      "x": -7,
      "y": -15,
      "z": -21,
      "name": "Rock_Sandstone_Brick"
    },
    {
      "x": -7,
      "y": -14,
      "z": -21,
      "name": "Rock_Sandstone_Brick"
    },
    {
      "x": -7,
      "y": -13,
      "z": -21,
      "name": "Rock_Sandstone_Brick"
    },
    {
      "x": -7,
      "y": -12,
      "z": -21,
      "name": "Rock_Sandstone_Brick"
    },
    {
      "x": -7,
      "y": -11,
      "z": -21,
      "name": "Rock_Sandstone_Brick"
    },
    {
      "x": -7,
      "y": -17,
      "z": -20,
      "name": "Soil_Dirt_Dry"
    },
    {
      "x": -7,
      "y": -12,
      "z": -20,
      "name": "Rock_Sandstone_Brick"
    },
    {
      "x": -7,
      "y": -11,
      "z": -20,
      "name": "Rock_Sandstone_Brick"
    },
    {
      "x": -7,
      "y": -17,
      "z": -19,
      "name": "Rock_Sandstone_Cobble"
    },
    {
      "x": -7,
      "y": -12,
      "z": -19,
      "name": "Rock_Sandstone_Brick"
    },
    {
      "x": -7,
      "y": -11,
      "z": -19,
      "name": "Rock_Sandstone_Brick"
    },
    {
      "x": -7,
      "y": -17,
      "z": -18,
      "name": "Rock_Sandstone_Cobble"
    },
    {
      "x": -7,
      "y": -12,
      "z": -18,
      "name": "Rock_Sandstone_Brick"
    },
    {
      "x": -7,
      "y": -11,
      "z": -18,
      "name": "Rock_Sandstone_Brick_Ornate"
    },
    {
      "x": -7,
      "y": -10,
      "z": -18,
      "name": "Rock_Sandstone_Brick"
    },
    {
      "x": -7,
      "y": -9,
      "z": -18,
      "name": "Rock_Sandstone_Brick_Half"
    },
    {
      "x": -7,
      "y": -17,
      "z": -17,
      "name": "Soil_Dirt_Dry"
    },
    {
      "x": -7,
      "y": -11,
      "z": -17,
      "name": "Rock_Sandstone_Brick_Ornate"
    },
    {
      "x": -7,
      "y": -10,
      "z": -17,
      "name": "Rock_Sandstone_Brick"
    },
    {
      "x": -7,
      "y": -17,
      "z": -16,
      "name": "Soil_Dirt_Dry"
    },
    {
      "x": -7,
      "y": -11,
      "z": -16,
      "name": "Rock_Sandstone_Brick_Ornate"
    },
    {
      "x": -7,
      "y": -10,
      "z": -16,
      "name": "Rock_Sandstone_Brick"
    },
    {
      "x": -7,
      "y": -9,
      "z": -16,
      "name": "Rock_Sandstone_Brick"
    },
    {
      "x": -7,
      "y": -15,
      "z": -15,
      "name": "Rock_Sandstone_Brick_Half",
      "rotation": 5
    },
    {
      "x": -7,
      "y": -14,
      "z": -15,
      "name": "Rock_Sandstone_Brick_Half",
      "rotation": 5
    },
    {
      "x": -7,
      "y": -13,
      "z": -15,
      "name": "Rock_Sandstone_Brick"
    },
    {
      "x": -7,
      "y": -12,
      "z": -15,
      "name": "Rock_Sandstone_Brick"
    },
    {
      "x": -7,
      "y": -11,
      "z": -15,
      "name": "Rock_Sandstone_Brick_Ornate"
    },
    {
      "x": -7,
      "y": -10,
      "z": -15,
      "name": "Rock_Sandstone_Brick"
    },
    {
      "x": -7,
      "y": -9,
      "z": -15,
      "name": "Rock_Sandstone_Brick"
    },
    {
      "x": -6,
      "y": -17,
      "z": -21,
      "name": "Rock_Sandstone_Brick"
    },
    {
      "x": -6,
      "y": -16,
      "z": -21,
      "name": "Rock_Sandstone_Brick"
    },
    {
      "x": -6,
      "y": -15,
      "z": -21,
      "name": "Rock_Sandstone_Brick"
    },
    {
      "x": -6,
      "y": -14,
      "z": -21,
      "name": "Rock_Sandstone_White_Cobble"
    },
    {
      "x": -6,
      "y": -13,
      "z": -21,
      "name": "Rock_Sandstone_White_Cobble"
    },
    {
      "x": -6,
      "y": -12,
      "z": -21,
      "name": "Rock_Sandstone_White_Cobble"
    },
    {
      "x": -6,
      "y": -11,
      "z": -21,
      "name": "Rock_Sandstone_White_Cobble"
    },
    {
      "x": -6,
      "y": -17,
      "z": -20,
      "name": "Soil_Dirt_Dry"
    },
    {
      "x": -6,
      "y": -16,
      "z": -20,
      "name": "Rock_Sandstone_White_Cobble_Half"
    },
    {
      "x": -6,
      "y": -15,
      "z": -20,
      "name": "Furniture_Temple_Emerald_Ladder"
    },
    {
      "x": -6,
      "y": -14,
      "z": -20,
      "name": "Furniture_Temple_Emerald_Ladder"
    },
    {
      "x": -6,
      "y": -13,
      "z": -20,
      "name": "Furniture_Temple_Emerald_Ladder"
    },
    {
      "x": -6,
      "y": -12,
      "z": -20,
      "name": "Furniture_Temple_Emerald_Ladder"
    },
    {
      "x": -6,
      "y": -11,
      "z": -20,
      "name": "Furniture_Temple_Emerald_Ladder"
    },
    {
      "x": -6,
      "y": -17,
      "z": -19,
      "name": "Soil_Dirt_Dry"
    },
    {
      "x": -6,
      "y": -16,
      "z": -19,
      "name": "Rock_Sandstone_White_Cobble_Half"
    },
    {
      "x": -6,
      "y": -17,
      "z": -18,
      "name": "Soil_Dirt_Dry"
    },
    {
      "x": -6,
      "y": -17,
      "z": -17,
      "name": "Soil_Dirt_Dry"
    },
    {
      "x": -6,
      "y": -17,
      "z": -16,
      "name": "Soil_Dirt_Dry"
    },
    {
      "x": -5,
      "y": -17,
      "z": -21,
      "name": "Rock_Sandstone_Brick"
    },
    {
      "x": -5,
      "y": -16,
      "z": -21,
      "name": "Rock_Sandstone_Brick"
    },
    {
      "x": -5,
      "y": -15,
      "z": -21,
      "name": "Rock_Sandstone_Brick"
    },
    {
      "x": -5,
      "y": -14,
      "z": -21,
      "name": "Rock_Sandstone_White_Cobble"
    },
    {
      "x": -5,
      "y": -13,
      "z": -21,
      "name": "Rock_Sandstone_White_Cobble"
    },
    {
      "x": -5,
      "y": -12,
      "z": -21,
      "name": "Rock_Sandstone_White_Cobble"
    },
    {
      "x": -5,
      "y": -11,
      "z": -21,
      "name": "Rock_Sandstone_White_Cobble"
    },
    {
      "x": -5,
      "y": -17,
      "z": -20,
      "name": "Soil_Dirt_Dry"
    },
    {
      "x": -5,
      "y": -16,
      "z": -20,
      "name": "Rock_Sandstone_White_Cobble_Half"
    },
    {
      "x": -5,
      "y": -15,
      "z": -20,
      "name": "Furniture_Temple_Emerald_Ladder"
    },
    {
      "x": -5,
      "y": -14,
      "z": -20,
      "name": "Furniture_Temple_Emerald_Ladder"
    },
    {
      "x": -5,
      "y": -13,
      "z": -20,
      "name": "Furniture_Temple_Emerald_Ladder"
    },
    {
      "x": -5,
      "y": -12,
      "z": -20,
      "name": "Furniture_Temple_Emerald_Ladder"
    },
    {
      "x": -5,
      "y": -11,
      "z": -20,
      "name": "Furniture_Temple_Emerald_Ladder"
    },
    {
      "x": -5,
      "y": -17,
      "z": -19,
      "name": "Soil_Dirt_Dry"
    },
    {
      "x": -5,
      "y": -16,
      "z": -19,
      "name": "Rock_Sandstone_White_Cobble_Half"
    },
    {
      "x": -5,
      "y": -17,
      "z": -18,
      "name": "Soil_Dirt_Dry"
    },
    {
      "x": -5,
      "y": -17,
      "z": -17,
      "name": "Soil_Dirt_Dry"
    },
    {
      "x": -5,
      "y": -17,
      "z": -16,
      "name": "Soil_Dirt_Dry"
    },
    {
      "x": -5,
      "y": -16,
      "z": -16,
      "name": "Rubble_Sandstone_Medium"
    }
  ],
  "entities": [
    {
      "Components": {
        "Nameplate": {
          "Text": "Zombie_Sand"
        },
        "HiddenFromAdventurePlayer": {},
        "SpawnMarkerComponent": {
          "SpawnMarker": "Zombie_Sand",
          "RespawnTime": 0.0,
          "SpawnCount": 0,
          "NPCReferences": [],
          "PersistedFlock": {},
          "SpawnPosition": {
            "X": 0.0,
            "Y": 0.0,
            "Z": 0.0
          }
        },
        "Transform": {
          "Position": {
            "X": -9.479741992186973,
            "Y": -10.0,
            "Z": -17.091001318359304
          },
          "Rotation": {
            "Pitch": 0.0,
            "Yaw": 5.28664493560791,
            "Roll": 0.0
          }
        },
        "Intangible": {},
        "PrefabCopyable": {},
        "Model": {
          "Model": {
            "Id": "NPC_Spawn_Marker",
            "Scale": 1.0,
            "Static": false
          }
        },
        "UUID": {
          "UUID": {
            "$binary": "rVsDahKhMeCe0mAIaQXW7w==",
            "$type": "04"
          }
        },
        "HeadRotation": {
          "Rotation": {
            "Pitch": 0.0,
            "Yaw": 2.145051956176758,
            "Roll": 0.0
          }
        }
      }
    }
  ]
}