{
  "version": 8,
  "blockIdVersion": 11,
  "anchorX": 0,
  "anchorY": 0,
  "anchorZ": 0,
  "blocks": [
    {
      "x": -3,
      "y": 1,
      "z": 1,
      "name": "Soil_Clay_White",
      "rotation": 34
    },
    {
      "x": -3,
      "y": 2,
      "z": 1,
      "name": "Soil_Clay_White",
      "rotation": 34
    },
    {
      "x": -3,
      "y": 2,
      "z": 2,
      "name": "Soil_Clay_White",
      "rotation": 34
    },
    {
      "x": -2,
      "y": 2,
      "z": -1,
      "name": "Soil_Clay_White",
      "rotation": 34
    },
    {
      "x": -2,
      "y": 1,
      "z": 0,
      "name": "Soil_Clay_White",
      "rotation": 34
    },
    {
      "x": -2,
      "y": 2,
      "z": 0,
      "name": "Soil_Clay_White",
      "rotation": 34
    },
    {
      "x": -2,
      "y": 3,
      "z": 0,
      "name": "Rock_Marble_Cobble",
      "rotation": 34
    },
    {
      "x": -2,
      "y": 0,
      "z": 1,
      "name": "Rock_Chalk",
      "rotation": 34
    },
    {
      "x": -2,
      "y": 1,
      "z": 1,
      "name": "Soil_Clay_White",
      "rotation": 34
    },
    {
      "x": -2,
      "y": 2,
      "z": 1,
      "name": "Soil_Clay_White",
      "rotation": 34
    },
    {
      "x": -2,
      "y": 3,
      "z": 1,
      "name": "Rock_Marble_Cobble",
      "rotation": 34
    },
    {
      "x": -2,
      "y": 1,
      "z": 2,
      "name": "Soil_Clay_White",
      "rotation": 34
    },
    {
      "x": -2,
      "y": 2,
      "z": 2,
      "name": "Soil_Clay_White",
      "rotation": 34
    },
    {
      "x": -2,
      "y": 3,
      "z": 2,
      "name": "Rock_Marble_Cobble",
      "rotation": 34
    },
    {
      "x": -2,
      "y": 2,
      "z": 3,
      "name": "Soil_Clay_White",
      "rotation": 34
    },
    {
      "x": -1,
      "y": 1,
      "z": -1,
      "name": "Soil_Clay_White",
      "rotation": 34
    },
    {
      "x": -1,
      "y": 2,
      "z": -1,
      "name": "Soil_Clay_White",
      "rotation": 34
    },
    {
      "x": -1,
      "y": 3,
      "z": -1,
      "name": "Rock_Marble_Cobble",
      "rotation": 34
    },
    {
      "x": -1,
      "y": 0,
      "z": 0,
      "name": "Rock_Chalk",
      "rotation": 34
    },
    {
      "x": -1,
      "y": 1,
      "z": 0,
      "name": "Soil_Clay_White",
      "rotation": 34
    },
    {
      "x": -1,
      "y": 2,
      "z": 0,
      "name": "Soil_Clay_White",
      "rotation": 34
    },
    {
      "x": -1,
      "y": 3,
      "z": 0,
      "name": "Rock_Marble_Cobble",
      "rotation": 34
    },
    {
      "x": -1,
      "y": 4,
      "z": 0,
      "name": "Rock_Marble_Cobble",
      "rotation": 34
    },
    {
      "x": -1,
      "y": 0,
      "z": 1,
      "name": "Rock_Chalk",
      "rotation": 34
    },
    {
      "x": -1,
      "y": 1,
      "z": 1,
      "name": "Soil_Clay_White",
      "rotation": 34
    },
    {
      "x": -1,
      "y": 2,
      "z": 1,
      "name": "Soil_Clay_White",
      "rotation": 34
    },
    {
      "x": -1,
      "y": 3,
      "z": 1,
      "name": "Rock_Marble_Cobble",
      "rotation": 34
    },
    {
      "x": -1,
      "y": 4,
      "z": 1,
      "name": "Rock_Marble_Cobble",
      "rotation": 34
    },
    {
      "x": -1,
      "y": 0,
      "z": 2,
      "name": "Rock_Chalk",
      "rotation": 34
    },
    {
      "x": -1,
      "y": 1,
      "z": 2,
      "name": "Soil_Clay_White",
      "rotation": 34
    },
    {
      "x": -1,
      "y": 2,
      "z": 2,
      "name": "Soil_Clay_White",
      "rotation": 34
    },
    {
      "x": -1,
      "y": 3,
      "z": 2,
      "name": "Rock_Marble_Cobble",
      "rotation": 34
    },
    {
      "x": -1,
      "y": 1,
      "z": 3,
      "name": "Soil_Clay_White",
      "rotation": 34
    },
    {
      "x": -1,
      "y": 2,
      "z": 3,
      "name": "Soil_Clay_White",
      "rotation": 34
    },
    {
      "x": -1,
      "y": 3,
      "z": 3,
      "name": "Rock_Marble_Cobble",
      "rotation": 34
    },
    {
      "x": 0,
      "y": 3,
      "z": -2,
      "name": "Rock_Marble_Cobble",
      "rotation": 34
    },
    {
      "x": 0,
      "y": 1,
      "z": -1,
      "name": "Soil_Clay_White",
      "rotation": 34
    },
    {
      "x": 0,
      "y": 2,
      "z": -1,
      "name": "Soil_Clay_White",
      "rotation": 34
    },
    {
      "x": 0,
      "y": 3,
      "z": -1,
      "name": "Rock_Marble_Cobble",
      "rotation": 34
    },
    {
      "x": 0,
      "y": 4,
      "z": -1,
      "name": "Rock_Marble_Cobble",
      "rotation": 34
    },
    {
      "x": 0,
      "y": 1,
      "z": 0,
      "name": "Soil_Clay_White",
      "rotation": 34
    },
    {
      "x": 0,
      "y": 2,
      "z": 0,
      "name": "Soil_Clay_White",
      "rotation": 34
    },
    {
      "x": 0,
      "y": 3,
      "z": 0,
      "name": "Rock_Marble_Cobble",
      "rotation": 34
    },
    {
      "x": 0,
      "y": 4,
      "z": 0,
      "name": "Rock_Marble_Cobble",
      "rotation": 34
    },
    {
      "x": 0,
      "y": 5,
      "z": 0,
      "name": "Rock_Marble",
      "rotation": 34
    },
    {
      "x": 0,
      "y": 0,
      "z": 1,
      "name": "Rock_Chalk",
      "rotation": 34
    },
    {
      "x": 0,
      "y": 1,
      "z": 1,
      "name": "Soil_Clay_White",
      "rotation": 34
    },
    {
      "x": 0,
      "y": 2,
      "z": 1,
      "name": "Soil_Clay_White",
      "rotation": 34
    },
    {
      "x": 0,
      "y": 3,
      "z": 1,
      "name": "Rock_Marble_Cobble",
      "rotation": 34
    },
    {
      "x": 0,
      "y": 4,
      "z": 1,
      "name": "Rock_Marble_Cobble",
      "rotation": 34
    },
    {
      "x": 0,
      "y": 5,
      "z": 1,
      "name": "Rock_Marble",
      "rotation": 34
    },
    {
      "x": 0,
      "y": 1,
      "z": 2,
      "name": "Soil_Clay_White",
      "rotation": 34
    },
    {
      "x": 0,
      "y": 2,
      "z": 2,
      "name": "Soil_Clay_White",
      "rotation": 34
    },
    {
      "x": 0,
      "y": 3,
      "z": 2,
      "name": "Rock_Marble_Cobble",
      "rotation": 34
    },
    {
      "x": 0,
      "y": 4,
      "z": 2,
      "name": "Rock_Marble_Cobble",
      "rotation": 34
    },
    {
      "x": 0,
      "y": 1,
      "z": 3,
      "name": "Rock_Marble",
      "rotation": 34
    },
    {
      "x": 0,
      "y": 2,
      "z": 3,
      "name": "Soil_Clay_White",
      "rotation": 34
    },
    {
      "x": 0,
      "y": 3,
      "z": 3,
      "name": "Rock_Marble_Cobble",
      "rotation": 34
    },
    {
      "x": 0,
      "y": 4,
      "z": 3,
      "name": "Rock_Marble_Cobble",
      "rotation": 34
    },
    {
      "x": 1,
      "y": 3,
      "z": -2,
      "name": "Rock_Marble_Cobble",
      "rotation": 34
    },
    {
      "x": 1,
      "y": 2,
      "z": -1,
      "name": "Soil_Clay_White",
      "rotation": 34
    },
    {
      "x": 1,
      "y": 3,
      "z": -1,
      "name": "Rock_Marble_Cobble",
      "rotation": 34
    },
    {
      "x": 1,
      "y": 4,
      "z": -1,
      "name": "Rock_Marble_Cobble",
      "rotation": 34
    },
    {
      "x": 1,
      "y": 1,
      "z": 0,
      "name": "Soil_Clay_White",
      "rotation": 34
    },
    {
      "x": 1,
      "y": 2,
      "z": 0,
      "name": "Soil_Clay_White",
      "rotation": 34
    },
    {
      "x": 1,
      "y": 3,
      "z": 0,
      "name": "Rock_Marble_Cobble",
      "rotation": 34
    },
    {
      "x": 1,
      "y": 4,
      "z": 0,
      "name": "Rock_Marble_Cobble",
      "rotation": 34
    },
    {
      "x": 1,
      "y": 5,
      "z": 0,
      "name": "Rock_Marble",
      "rotation": 34
    },
    {
      "x": 1,
      "y": 1,
      "z": 1,
      "name": "Soil_Clay_White",
      "rotation": 34
    },
    {
      "x": 1,
      "y": 2,
      "z": 1,
      "name": "Soil_Clay_White",
      "rotation": 34
    },
    {
      "x": 1,
      "y": 3,
      "z": 1,
      "name": "Rock_Marble_Cobble",
      "rotation": 34
    },
    {
      "x": 1,
      "y": 4,
      "z": 1,
      "name": "Rock_Marble_Cobble",
      "rotation": 34
    },
    {
      "x": 1,
      "y": 5,
      "z": 1,
      "name": "Rock_Marble",
      "rotation": 34
    },
    {
      "x": 1,
      "y": 1,
      "z": 2,
      "name": "Soil_Clay_White",
      "rotation": 34
    },
    {
      "x": 1,
      "y": 2,
      "z": 2,
      "name": "Soil_Clay_White",
      "rotation": 34
    },
    {
      "x": 1,
      "y": 3,
      "z": 2,
      "name": "Rock_Marble_Cobble",
      "rotation": 34
    },
    {
      "x": 1,
      "y": 4,
      "z": 2,
      "name": "Rock_Marble_Cobble",
      "rotation": 34
    },
    {
      "x": 1,
      "y": 5,
      "z": 2,
      "name": "Rock_Marble",
      "rotation": 34
    },
    {
      "x": 1,
      "y": 2,
      "z": 3,
      "name": "Soil_Clay_White",
      "rotation": 34
    },
    {
      "x": 1,
      "y": 3,
      "z": 3,
      "name": "Rock_Marble_Cobble",
      "rotation": 34
    },
    {
      "x": 1,
      "y": 4,
      "z": 3,
      "name": "Rock_Marble_Cobble",
      "rotation": 34
    },
    {
      "x": 2,
      "y": 3,
      "z": -1,
      "name": "Rock_Marble_Cobble",
      "rotation": 34
    },
    {
      "x": 2,
      "y": 4,
      "z": -1,
      "name": "Rock_Marble_Cobble",
      "rotation": 34
    },
    {
      "x": 2,
      "y": 2,
      "z": 0,
      "name": "Soil_Clay_White",
      "rotation": 34
    },
    {
      "x": 2,
      "y": 3,
      "z": 0,
      "name": "Rock_Marble_Cobble",
      "rotation": 34
    },
    {
      "x": 2,
      "y": 4,
      "z": 0,
      "name": "Rock_Marble_Cobble",
      "rotation": 34
    },
    {
      "x": 2,
      "y": 2,
      "z": 1,
      "name": "Soil_Clay_White",
      "rotation": 34
    },
    {
      "x": 2,
      "y": 3,
      "z": 1,
      "name": "Rock_Marble_Cobble",
      "rotation": 34
    },
    {
      "x": 2,
      "y": 4,
      "z": 1,
      "name": "Rock_Marble_Cobble",
      "rotation": 34
    },
    {
      "x": 2,
      "y": 5,
      "z": 1,
      "name": "Rock_Marble",
      "rotation": 34
    },
    {
      "x": 2,
      "y": 2,
      "z": 2,
      "name": "Soil_Clay_White",
      "rotation": 34
    },
    {
      "x": 2,
      "y": 3,
      "z": 2,
      "name": "Rock_Marble_Cobble",
      "rotation": 34
    },
    {
      "x": 2,
      "y": 4,
      "z": 2,
      "name": "Rock_Marble_Cobble",
      "rotation": 34
    },
    {
      "x": 2,
      "y": 3,
      "z": 3,
      "name": "Rock_Marble_Cobble",
      "rotation": 34
    },
    {
      "x": 3,
      "y": 4,
      "z": 0,
      "name": "Rock_Marble_Cobble",
      "rotation": 34
    },
    {
      "x": 3,
      "y": 3,
      "z": 1,
      "name": "Rock_Marble_Cobble",
      "rotation": 34
    },
    {
      "x": 3,
      "y": 4,
      "z": 1,
      "name": "Rock_Marble_Cobble",
      "rotation": 34
    },
    {
      "x": 3,
      "y": 3,
      "z": 2,
      "name": "Rock_Marble_Cobble",
      "rotation": 34
    }
  ]
}