{
  "version": 8,
  "blockIdVersion": 11,
  "anchorX": 0,
  "anchorY": 0,
  "anchorZ": 0,
  "blocks": [
    {
      "x": 0,
      "y": -34,
      "z": 1,
      "name": "Rock_Sandstone_Brick"
    },
    {
      "x": 0,
      "y": -33,
      "z": 1,
      "name": "Rock_Sandstone_Brick"
    },
    {
      "x": 0,
      "y": -32,
      "z": 1,
      "name": "Rock_Sandstone_Brick"
    },
    {
      "x": 0,
      "y": -31,
      "z": 1,
      "name": "Rock_Sandstone_Brick"
    },
    {
      "x": 0,
      "y": -30,
      "z": 1,
      "name": "Rock_Sandstone"
    },
    {
      "x": 0,
      "y": -29,
      "z": 1,
      "name": "Rock_Sandstone_Brick"
    },
    {
      "x": 0,
      "y": -28,
      "z": 1,
      "name": "Rock_Sandstone_Brick"
    },
    {
      "x": 0,
      "y": -27,
      "z": 1,
      "name": "Rock_Sandstone_Brick"
    },
    {
      "x": 0,
      "y": -26,
      "z": 1,
      "name": "Rock_Sandstone"
    },
    {
      "x": 0,
      "y": -25,
      "z": 1,
      "name": "Rock_Sandstone_Brick"
    },
    {
      "x": 0,
      "y": -24,
      "z": 1,
      "name": "Rock_Sandstone_Brick",
      "rotation": 3
    },
    {
      "x": 0,
      "y": -23,
      "z": 1,
      "name": "Rock_Sandstone_Brick",
      "rotation": 3
    },
    {
      "x": 0,
      "y": -22,
      "z": 1,
      "name": "Rock_Sandstone_Brick",
      "rotation": 3
    },
    {
      "x": 0,
      "y": -34,
      "z": 2,
      "name": "Rock_Sandstone_Cobble"
    },
    {
      "x": 0,
      "y": -33,
      "z": 2,
      "name": "Rock_Sandstone_Brick"
    },
    {
      "x": 0,
      "y": -32,
      "z": 2,
      "name": "Rock_Sandstone_Brick"
    },
    {
      "x": 0,
      "y": -31,
      "z": 2,
      "name": "Rock_Sandstone_Brick"
    },
    {
      "x": 0,
      "y": -30,
      "z": 2,
      "name": "Rock_Sandstone_Brick"
    },
    {
      "x": 0,
      "y": -29,
      "z": 2,
      "name": "Rock_Sandstone_Brick"
    },
    {
      "x": 0,
      "y": -28,
      "z": 2,
      "name": "Rock_Sandstone"
    },
    {
      "x": 0,
      "y": -27,
      "z": 2,
      "name": "Rock_Sandstone_Cobble"
    },
    {
      "x": 0,
      "y": -26,
      "z": 2,
      "name": "Rock_Sandstone_Brick"
    },
    {
      "x": 0,
      "y": -25,
      "z": 2,
      "name": "Rock_Sandstone_Cobble"
    },
    {
      "x": 0,
      "y": -24,
      "z": 2,
      "name": "Rock_Sandstone_Brick",
      "rotation": 3
    },
    {
      "x": 0,
      "y": -23,
      "z": 2,
      "name": "Rock_Sandstone_Brick",
      "rotation": 3
    },
    {
      "x": 0,
      "y": -22,
      "z": 2,
      "name": "Rock_Sandstone_Brick",
      "rotation": 3
    },
    {
      "x": 0,
      "y": -34,
      "z": 3,
      "name": "Rock_Sandstone_Brick"
    },
    {
      "x": 0,
      "y": -33,
      "z": 3,
      "name": "Rock_Sandstone_Brick"
    },
    {
      "x": 0,
      "y": -32,
      "z": 3,
      "name": "Rock_Sandstone_Brick"
    },
    {
      "x": 0,
      "y": -31,
      "z": 3,
      "name": "Rock_Sandstone"
    },
    {
      "x": 0,
      "y": -30,
      "z": 3,
      "name": "Rock_Sandstone_Cobble"
    },
    {
      "x": 0,
      "y": -29,
      "z": 3,
      "name": "Rock_Sandstone_Brick"
    },
    {
      "x": 0,
      "y": -28,
      "z": 3,
      "name": "Rock_Sandstone_Brick"
    },
    {
      "x": 0,
      "y": -27,
      "z": 3,
      "name": "Rock_Sandstone"
    },
    {
      "x": 0,
      "y": -26,
      "z": 3,
      "name": "Rock_Sandstone_Brick"
    },
    {
      "x": 0,
      "y": -25,
      "z": 3,
      "name": "Rock_Sandstone_Cobble"
    },
    {
      "x": 0,
      "y": -24,
      "z": 3,
      "name": "Rock_Sandstone",
      "rotation": 3
    },
    {
      "x": 0,
      "y": -23,
      "z": 3,
      "name": "Rock_Sandstone_Brick",
      "rotation": 3
    },
    {
      "x": 0,
      "y": -22,
      "z": 3,
      "name": "Rock_Sandstone_Brick",
      "rotation": 3
    },
    {
      "x": 0,
      "y": -34,
      "z": 18,
      "name": "Rock_Sandstone_Brick"
    },
    {
      "x": 0,
      "y": -33,
      "z": 18,
      "name": "Rock_Sandstone_Brick"
    },
    {
      "x": 0,
      "y": -32,
      "z": 18,
      "name": "Rock_Sandstone_Cobble"
    },
    {
      "x": 0,
      "y": -31,
      "z": 18,
      "name": "Rock_Sandstone_Brick"
    },
    {
      "x": 0,
      "y": -30,
      "z": 18,
      "name": "Rock_Sandstone_Brick"
    },
    {
      "x": 0,
      "y": -29,
      "z": 18,
      "name": "Rock_Sandstone_Brick"
    },
    {
      "x": 0,
      "y": -28,
      "z": 18,
      "name": "Rock_Sandstone_Brick"
    },
    {
      "x": 0,
      "y": -27,
      "z": 18,
      "name": "Rock_Sandstone_Brick"
    },
    {
      "x": 0,
      "y": -26,
      "z": 18,
      "name": "Rock_Sandstone_Cobble"
    },
    {
      "x": 0,
      "y": -25,
      "z": 18,
      "name": "Rock_Sandstone_Brick"
    },
    {
      "x": 0,
      "y": -24,
      "z": 18,
      "name": "Rock_Sandstone_Brick"
    },
    {
      "x": 0,
      "y": -23,
      "z": 18,
      "name": "Rock_Sandstone",
      "rotation": 1
    },
    {
      "x": 0,
      "y": -22,
      "z": 18,
      "name": "Rock_Sandstone_Brick",
      "rotation": 1
    },
    {
      "x": 0,
      "y": -21,
      "z": 18,
      "name": "Rock_Sandstone",
      "rotation": 1
    },
    {
      "x": 0,
      "y": -20,
      "z": 18,
      "name": "Rock_Sandstone_Brick",
      "rotation": 1
    },
    {
      "x": 0,
      "y": -19,
      "z": 18,
      "name": "Rock_Sandstone",
      "rotation": 1
    },
    {
      "x": 0,
      "y": -18,
      "z": 18,
      "name": "Rock_Sandstone",
      "rotation": 1
    },
    {
      "x": 0,
      "y": -34,
      "z": 19,
      "name": "Rock_Sandstone_Brick"
    },
    {
      "x": 0,
      "y": -33,
      "z": 19,
      "name": "Rock_Sandstone_Brick"
    },
    {
      "x": 0,
      "y": -32,
      "z": 19,
      "name": "Rock_Sandstone_Brick"
    },
    {
      "x": 0,
      "y": -31,
      "z": 19,
      "name": "Rock_Sandstone_Brick"
    },
    {
      "x": 0,
      "y": -30,
      "z": 19,
      "name": "Rock_Sandstone_Brick"
    },
    {
      "x": 0,
      "y": -29,
      "z": 19,
      "name": "Rock_Sandstone_Brick"
    },
    {
      "x": 0,
      "y": -28,
      "z": 19,
      "name": "Rock_Sandstone_Brick"
    },
    {
      "x": 0,
      "y": -27,
      "z": 19,
      "name": "Rock_Sandstone"
    },
    {
      "x": 0,
      "y": -26,
      "z": 19,
      "name": "Rock_Sandstone_Brick"
    },
    {
      "x": 0,
      "y": -25,
      "z": 19,
      "name": "Rock_Sandstone_Cobble"
    },
    {
      "x": 0,
      "y": -24,
      "z": 19,
      "name": "Rock_Sandstone_Brick"
    },
    {
      "x": 0,
      "y": -23,
      "z": 19,
      "name": "Rock_Sandstone_Brick",
      "rotation": 1
    },
    {
      "x": 0,
      "y": -22,
      "z": 19,
      "name": "Rock_Sandstone_Brick",
      "rotation": 1
    },
    {
      "x": 0,
      "y": -21,
      "z": 19,
      "name": "Rock_Sandstone_Brick",
      "rotation": 1
    },
    {
      "x": 0,
      "y": -20,
      "z": 19,
      "name": "Rock_Sandstone_Brick",
      "rotation": 1
    },
    {
      "x": 0,
      "y": -19,
      "z": 19,
      "name": "Rock_Sandstone_Brick",
      "rotation": 1
    },
    {
      "x": 0,
      "y": -18,
      "z": 19,
      "name": "Rock_Sandstone",
      "rotation": 1
    },
    {
      "x": 0,
      "y": -34,
      "z": 20,
      "name": "Rock_Sandstone"
    },
    {
      "x": 0,
      "y": -33,
      "z": 20,
      "name": "Rock_Sandstone_Cobble"
    },
    {
      "x": 0,
      "y": -32,
      "z": 20,
      "name": "Rock_Sandstone_Brick"
    },
    {
      "x": 0,
      "y": -31,
      "z": 20,
      "name": "Rock_Sandstone_Brick"
    },
    {
      "x": 0,
      "y": -30,
      "z": 20,
      "name": "Rock_Sandstone_Brick"
    },
    {
      "x": 0,
      "y": -29,
      "z": 20,
      "name": "Rock_Sandstone_Brick"
    },
    {
      "x": 0,
      "y": -28,
      "z": 20,
      "name": "Rock_Sandstone_Brick"
    },
    {
      "x": 0,
      "y": -27,
      "z": 20,
      "name": "Rock_Sandstone_Cobble"
    },
    {
      "x": 0,
      "y": -26,
      "z": 20,
      "name": "Rock_Sandstone_Brick"
    },
    {
      "x": 0,
      "y": -25,
      "z": 20,
      "name": "Rock_Sandstone_Brick"
    },
    {
      "x": 0,
      "y": -24,
      "z": 20,
      "name": "Rock_Sandstone_Cobble"
    },
    {
      "x": 0,
      "y": -23,
      "z": 20,
      "name": "Rock_Sandstone_Brick",
      "rotation": 1
    },
    {
      "x": 0,
      "y": -22,
      "z": 20,
      "name": "Rock_Sandstone_Brick",
      "rotation": 1
    },
    {
      "x": 0,
      "y": -21,
      "z": 20,
      "name": "Rock_Sandstone_Brick",
      "rotation": 1
    },
    {
      "x": 0,
      "y": -20,
      "z": 20,
      "name": "Rock_Sandstone",
      "rotation": 1
    },
    {
      "x": 0,
      "y": -19,
      "z": 20,
      "name": "Rock_Sandstone_Brick",
      "rotation": 1
    },
    {
      "x": 0,
      "y": -18,
      "z": 20,
      "name": "Rock_Sandstone_Brick",
      "rotation": 1
    },
    {
      "x": 0,
      "y": -17,
      "z": 20,
      "name": "Rock_Sandstone",
      "rotation": 1
    },
    {
      "x": 1,
      "y": -34,
      "z": 0,
      "name": "Rock_Sandstone_Cobble"
    },
    {
      "x": 1,
      "y": -33,
      "z": 0,
      "name": "Rock_Sandstone"
    },
    {
      "x": 1,
      "y": -32,
      "z": 0,
      "name": "Rock_Sandstone_Brick"
    },
    {
      "x": 1,
      "y": -31,
      "z": 0,
      "name": "Rock_Sandstone_Brick"
    },
    {
      "x": 1,
      "y": -30,
      "z": 0,
      "name": "Rock_Sandstone"
    },
    {
      "x": 1,
      "y": -29,
      "z": 0,
      "name": "Rock_Sandstone_Brick"
    },
    {
      "x": 1,
      "y": -28,
      "z": 0,
      "name": "Rock_Sandstone_Brick"
    },
    {
      "x": 1,
      "y": -27,
      "z": 0,
      "name": "Rock_Sandstone_Brick"
    },
    {
      "x": 1,
      "y": -26,
      "z": 0,
      "name": "Rock_Sandstone"
    },
    {
      "x": 1,
      "y": -25,
      "z": 0,
      "name": "Rock_Sandstone_Cobble"
    },
    {
      "x": 1,
      "y": -24,
      "z": 0,
      "name": "Rock_Sandstone_Brick"
    },
    {
      "x": 1,
      "y": -23,
      "z": 0,
      "name": "Rock_Sandstone_Brick"
    },
    {
      "x": 1,
      "y": -22,
      "z": 0,
      "name": "Rock_Sandstone_Brick"
    },
    {
      "x": 1,
      "y": -34,
      "z": 1,
      "name": "Rock_Sandstone_Brick"
    },
    {
      "x": 1,
      "y": -33,
      "z": 1,
      "name": "Rock_Sandstone_Brick"
    },
    {
      "x": 1,
      "y": -32,
      "z": 1,
      "name": "Rock_Sandstone_Brick"
    },
    {
      "x": 1,
      "y": -31,
      "z": 1,
      "name": "Rock_Sandstone_Cobble"
    },
    {
      "x": 1,
      "y": -30,
      "z": 1,
      "name": "Rock_Sandstone"
    },
    {
      "x": 1,
      "y": -29,
      "z": 1,
      "name": "Rock_Sandstone_Brick"
    },
    {
      "x": 1,
      "y": -28,
      "z": 1,
      "name": "Rock_Sandstone"
    },
    {
      "x": 1,
      "y": -27,
      "z": 1,
      "name": "Rock_Sandstone_Brick"
    },
    {
      "x": 1,
      "y": -26,
      "z": 1,
      "name": "Rock_Sandstone_Brick"
    },
    {
      "x": 1,
      "y": -25,
      "z": 1,
      "name": "Rock_Sandstone"
    },
    {
      "x": 1,
      "y": -24,
      "z": 1,
      "name": "Rock_Sandstone_Brick",
      "rotation": 3
    },
    {
      "x": 1,
      "y": -23,
      "z": 1,
      "name": "Rock_Sandstone_Brick",
      "rotation": 3
    },
    {
      "x": 1,
      "y": -22,
      "z": 1,
      "name": "Rock_Sandstone_Cobble",
      "rotation": 3
    },
    {
      "x": 1,
      "y": -34,
      "z": 2,
      "name": "Rock_Sandstone_Cobble"
    },
    {
      "x": 1,
      "y": -33,
      "z": 2,
      "name": "Rock_Sandstone"
    },
    {
      "x": 1,
      "y": -32,
      "z": 2,
      "name": "Rock_Sandstone_Brick"
    },
    {
      "x": 1,
      "y": -31,
      "z": 2,
      "name": "Rock_Sandstone_Brick"
    },
    {
      "x": 1,
      "y": -30,
      "z": 2,
      "name": "Rock_Sandstone_Brick"
    },
    {
      "x": 1,
      "y": -29,
      "z": 2,
      "name": "Rock_Sandstone_Brick"
    },
    {
      "x": 1,
      "y": -28,
      "z": 2,
      "name": "Rock_Sandstone"
    },
    {
      "x": 1,
      "y": -27,
      "z": 2,
      "name": "Rock_Sandstone"
    },
    {
      "x": 1,
      "y": -26,
      "z": 2,
      "name": "Rock_Sandstone_Cobble"
    },
    {
      "x": 1,
      "y": -25,
      "z": 2,
      "name": "Rock_Sandstone"
    },
    {
      "x": 1,
      "y": -24,
      "z": 2,
      "name": "Rock_Sandstone_Brick",
      "rotation": 3
    },
    {
      "x": 1,
      "y": -23,
      "z": 2,
      "name": "Rock_Sandstone_Cobble",
      "rotation": 3
    },
    {
      "x": 1,
      "y": -22,
      "z": 2,
      "name": "Rock_Sandstone_Brick",
      "rotation": 3
    },
    {
      "x": 1,
      "y": -34,
      "z": 3,
      "name": "Rock_Sandstone_Brick"
    },
    {
      "x": 1,
      "y": -33,
      "z": 3,
      "name": "Rock_Sandstone_Brick"
    },
    {
      "x": 1,
      "y": -32,
      "z": 3,
      "name": "Rock_Sandstone_Brick"
    },
    {
      "x": 1,
      "y": -31,
      "z": 3,
      "name": "Rock_Sandstone_Brick"
    },
    {
      "x": 1,
      "y": -30,
      "z": 3,
      "name": "Rock_Sandstone_Brick"
    },
    {
      "x": 1,
      "y": -29,
      "z": 3,
      "name": "Rock_Sandstone"
    },
    {
      "x": 1,
      "y": -28,
      "z": 3,
      "name": "Rock_Sandstone_Brick"
    },
    {
      "x": 1,
      "y": -27,
      "z": 3,
      "name": "Rock_Sandstone"
    },
    {
      "x": 1,
      "y": -26,
      "z": 3,
      "name": "Rock_Sandstone"
    },
    {
      "x": 1,
      "y": -25,
      "z": 3,
      "name": "Rock_Sandstone_Brick"
    },
    {
      "x": 1,
      "y": -24,
      "z": 3,
      "name": "Rock_Sandstone_Cobble",
      "rotation": 3
    },
    {
      "x": 1,
      "y": -23,
      "z": 3,
      "name": "Rock_Sandstone_Brick",
      "rotation": 3
    },
    {
      "x": 1,
      "y": -22,
      "z": 3,
      "name": "Rock_Sandstone_Brick",
      "rotation": 3
    },
    {
      "x": 1,
      "y": -34,
      "z": 18,
      "name": "Rock_Sandstone_Brick"
    },
    {
      "x": 1,
      "y": -33,
      "z": 18,
      "name": "Rock_Sandstone"
    },
    {
      "x": 1,
      "y": -32,
      "z": 18,
      "name": "Rock_Sandstone_Brick"
    },
    {
      "x": 1,
      "y": -31,
      "z": 18,
      "name": "Rock_Sandstone_Brick"
    },
    {
      "x": 1,
      "y": -30,
      "z": 18,
      "name": "Rock_Sandstone_Brick"
    },
    {
      "x": 1,
      "y": -29,
      "z": 18,
      "name": "Rock_Sandstone_Brick"
    },
    {
      "x": 1,
      "y": -28,
      "z": 18,
      "name": "Rock_Sandstone_Brick"
    },
    {
      "x": 1,
      "y": -27,
      "z": 18,
      "name": "Rock_Sandstone_Cobble"
    },
    {
      "x": 1,
      "y": -26,
      "z": 18,
      "name": "Rock_Sandstone_Brick"
    },
    {
      "x": 1,
      "y": -25,
      "z": 18,
      "name": "Rock_Sandstone_Brick"
    },
    {
      "x": 1,
      "y": -24,
      "z": 18,
      "name": "Rock_Sandstone"
    },
    {
      "x": 1,
      "y": -23,
      "z": 18,
      "name": "Rock_Sandstone_Brick",
      "rotation": 1
    },
    {
      "x": 1,
      "y": -22,
      "z": 18,
      "name": "Rock_Sandstone_Brick",
      "rotation": 1
    },
    {
      "x": 1,
      "y": -21,
      "z": 18,
      "name": "Rock_Sandstone_Brick",
      "rotation": 1
    },
    {
      "x": 1,
      "y": -20,
      "z": 18,
      "name": "Rock_Sandstone_Cobble",
      "rotation": 1
    },
    {
      "x": 1,
      "y": -19,
      "z": 18,
      "name": "Rock_Sandstone_Brick",
      "rotation": 1
    },
    {
      "x": 1,
      "y": -34,
      "z": 19,
      "name": "Rock_Sandstone_Brick"
    },
    {
      "x": 1,
      "y": -33,
      "z": 19,
      "name": "Rock_Sandstone"
    },
    {
      "x": 1,
      "y": -32,
      "z": 19,
      "name": "Rock_Sandstone_Brick"
    },
    {
      "x": 1,
      "y": -31,
      "z": 19,
      "name": "Rock_Sandstone_Brick"
    },
    {
      "x": 1,
      "y": -30,
      "z": 19,
      "name": "Rock_Sandstone"
    },
    {
      "x": 1,
      "y": -29,
      "z": 19,
      "name": "Rock_Sandstone_Brick"
    },
    {
      "x": 1,
      "y": -28,
      "z": 19,
      "name": "Rock_Sandstone_Cobble"
    },
    {
      "x": 1,
      "y": -27,
      "z": 19,
      "name": "Rock_Sandstone_Brick"
    },
    {
      "x": 1,
      "y": -26,
      "z": 19,
      "name": "Rock_Sandstone_Brick"
    },
    {
      "x": 1,
      "y": -25,
      "z": 19,
      "name": "Rock_Sandstone_Brick"
    },
    {
      "x": 1,
      "y": -24,
      "z": 19,
      "name": "Rock_Sandstone_Cobble"
    },
    {
      "x": 1,
      "y": -23,
      "z": 19,
      "name": "Rock_Sandstone_Brick",
      "rotation": 1
    },
    {
      "x": 1,
      "y": -22,
      "z": 19,
      "name": "Rock_Sandstone_Brick",
      "rotation": 1
    },
    {
      "x": 1,
      "y": -21,
      "z": 19,
      "name": "Rock_Sandstone_Brick",
      "rotation": 1
    },
    {
      "x": 1,
      "y": -20,
      "z": 19,
      "name": "Rock_Sandstone",
      "rotation": 1
    },
    {
      "x": 1,
      "y": -19,
      "z": 19,
      "name": "Rock_Sandstone_Brick",
      "rotation": 1
    },
    {
      "x": 1,
      "y": -34,
      "z": 20,
      "name": "Rock_Sandstone_Cobble"
    },
    {
      "x": 1,
      "y": -33,
      "z": 20,
      "name": "Rock_Sandstone_Brick"
    },
    {
      "x": 1,
      "y": -32,
      "z": 20,
      "name": "Rock_Sandstone_Brick"
    },
    {
      "x": 1,
      "y": -31,
      "z": 20,
      "name": "Rock_Sandstone"
    },
    {
      "x": 1,
      "y": -30,
      "z": 20,
      "name": "Rock_Sandstone_Brick"
    },
    {
      "x": 1,
      "y": -29,
      "z": 20,
      "name": "Rock_Sandstone_Brick"
    },
    {
      "x": 1,
      "y": -28,
      "z": 20,
      "name": "Rock_Sandstone_Brick"
    },
    {
      "x": 1,
      "y": -27,
      "z": 20,
      "name": "Rock_Sandstone"
    },
    {
      "x": 1,
      "y": -26,
      "z": 20,
      "name": "Rock_Sandstone_Brick"
    },
    {
      "x": 1,
      "y": -25,
      "z": 20,
      "name": "Rock_Sandstone_Brick"
    },
    {
      "x": 1,
      "y": -24,
      "z": 20,
      "name": "Rock_Sandstone"
    },
    {
      "x": 1,
      "y": -23,
      "z": 20,
      "name": "Rock_Sandstone_Brick",
      "rotation": 1
    },
    {
      "x": 1,
      "y": -22,
      "z": 20,
      "name": "Rock_Sandstone_Brick",
      "rotation": 1
    },
    {
      "x": 1,
      "y": -21,
      "z": 20,
      "name": "Rock_Sandstone_Brick",
      "rotation": 1
    },
    {
      "x": 1,
      "y": -20,
      "z": 20,
      "name": "Rock_Sandstone",
      "rotation": 1
    },
    {
      "x": 1,
      "y": -19,
      "z": 20,
      "name": "Rock_Sandstone_Brick",
      "rotation": 1
    },
    {
      "x": 1,
      "y": -18,
      "z": 20,
      "name": "Rock_Sandstone_Brick",
      "rotation": 1
    },
    {
      "x": 1,
      "y": -34,
      "z": 21,
      "name": "Rock_Sandstone_Brick"
    },
    {
      "x": 1,
      "y": -33,
      "z": 21,
      "name": "Rock_Sandstone_Brick"
    },
    {
      "x": 1,
      "y": -32,
      "z": 21,
      "name": "Rock_Sandstone_Brick"
    },
    {
      "x": 1,
      "y": -31,
      "z": 21,
      "name": "Rock_Sandstone_Brick"
    },
    {
      "x": 1,
      "y": -30,
      "z": 21,
      "name": "Rock_Sandstone_Cobble"
    },
    {
      "x": 1,
      "y": -29,
      "z": 21,
      "name": "Rock_Sandstone_Brick"
    },
    {
      "x": 1,
      "y": -28,
      "z": 21,
      "name": "Rock_Sandstone"
    },
    {
      "x": 1,
      "y": -27,
      "z": 21,
      "name": "Rock_Sandstone_Brick"
    },
    {
      "x": 1,
      "y": -26,
      "z": 21,
      "name": "Rock_Sandstone"
    },
    {
      "x": 1,
      "y": -25,
      "z": 21,
      "name": "Rock_Sandstone"
    },
    {
      "x": 1,
      "y": -24,
      "z": 21,
      "name": "Rock_Sandstone_Brick"
    },
    {
      "x": 1,
      "y": -23,
      "z": 21,
      "name": "Rock_Sandstone"
    },
    {
      "x": 1,
      "y": -22,
      "z": 21,
      "name": "Rock_Sandstone_Brick"
    },
    {
      "x": 1,
      "y": -21,
      "z": 21,
      "name": "Rock_Sandstone_Brick"
    },
    {
      "x": 1,
      "y": -20,
      "z": 21,
      "name": "Rock_Sandstone_Brick"
    },
    {
      "x": 1,
      "y": -19,
      "z": 21,
      "name": "Rock_Sandstone_Brick"
    },
    {
      "x": 1,
      "y": -18,
      "z": 21,
      "name": "Rock_Sandstone_Cobble"
    },
    {
      "x": 1,
      "y": -17,
      "z": 21,
      "name": "Rock_Sandstone"
    },
    {
      "x": 2,
      "y": -34,
      "z": 0,
      "name": "Rock_Sandstone_Brick"
    },
    {
      "x": 2,
      "y": -33,
      "z": 0,
      "name": "Rock_Sandstone_Brick"
    },
    {
      "x": 2,
      "y": -32,
      "z": 0,
      "name": "Rock_Sandstone"
    },
    {
      "x": 2,
      "y": -31,
      "z": 0,
      "name": "Rock_Sandstone"
    },
    {
      "x": 2,
      "y": -30,
      "z": 0,
      "name": "Rock_Sandstone_Brick"
    },
    {
      "x": 2,
      "y": -29,
      "z": 0,
      "name": "Rock_Sandstone_Brick"
    },
    {
      "x": 2,
      "y": -28,
      "z": 0,
      "name": "Rock_Sandstone"
    },
    {
      "x": 2,
      "y": -27,
      "z": 0,
      "name": "Rock_Sandstone_Brick"
    },
    {
      "x": 2,
      "y": -26,
      "z": 0,
      "name": "Rock_Sandstone"
    },
    {
      "x": 2,
      "y": -25,
      "z": 0,
      "name": "Rock_Sandstone_Cobble"
    },
    {
      "x": 2,
      "y": -24,
      "z": 0,
      "name": "Rock_Sandstone_Brick"
    },
    {
      "x": 2,
      "y": -23,
      "z": 0,
      "name": "Rock_Sandstone"
    },
    {
      "x": 2,
      "y": -22,
      "z": 0,
      "name": "Rock_Sandstone_Brick"
    },
    {
      "x": 2,
      "y": -34,
      "z": 1,
      "name": "Rock_Sandstone_Cobble"
    },
    {
      "x": 2,
      "y": -33,
      "z": 1,
      "name": "Rock_Sandstone_Brick"
    },
    {
      "x": 2,
      "y": -32,
      "z": 1,
      "name": "Rock_Sandstone_Brick"
    },
    {
      "x": 2,
      "y": -31,
      "z": 1,
      "name": "Rock_Sandstone_Brick"
    },
    {
      "x": 2,
      "y": -30,
      "z": 1,
      "name": "Rock_Sandstone_Brick"
    },
    {
      "x": 2,
      "y": -29,
      "z": 1,
      "name": "Rock_Sandstone_Brick"
    },
    {
      "x": 2,
      "y": -28,
      "z": 1,
      "name": "Rock_Sandstone_Brick"
    },
    {
      "x": 2,
      "y": -27,
      "z": 1,
      "name": "Rock_Sandstone_Brick"
    },
    {
      "x": 2,
      "y": -26,
      "z": 1,
      "name": "Rock_Sandstone_Brick"
    },
    {
      "x": 2,
      "y": -25,
      "z": 1,
      "name": "Rock_Sandstone_Brick"
    },
    {
      "x": 2,
      "y": -24,
      "z": 1,
      "name": "Rock_Sandstone_Brick",
      "rotation": 3
    },
    {
      "x": 2,
      "y": -23,
      "z": 1,
      "name": "Rock_Sandstone_Brick",
      "rotation": 3
    },
    {
      "x": 2,
      "y": -22,
      "z": 1,
      "name": "Rock_Sandstone_Brick",
      "rotation": 3
    },
    {
      "x": 2,
      "y": -34,
      "z": 2,
      "name": "Rock_Sandstone_Brick"
    },
    {
      "x": 2,
      "y": -33,
      "z": 2,
      "name": "Rock_Sandstone_Brick"
    },
    {
      "x": 2,
      "y": -32,
      "z": 2,
      "name": "Rock_Sandstone_Brick"
    },
    {
      "x": 2,
      "y": -31,
      "z": 2,
      "name": "Rock_Sandstone_Brick"
    },
    {
      "x": 2,
      "y": -30,
      "z": 2,
      "name": "Rock_Sandstone_Brick"
    },
    {
      "x": 2,
      "y": -29,
      "z": 2,
      "name": "Rock_Sandstone_Brick"
    },
    {
      "x": 2,
      "y": -28,
      "z": 2,
      "name": "Rock_Sandstone_Brick"
    },
    {
      "x": 2,
      "y": -27,
      "z": 2,
      "name": "Rock_Sandstone_Brick"
    },
    {
      "x": 2,
      "y": -26,
      "z": 2,
      "name": "Rock_Sandstone_Cobble"
    },
    {
      "x": 2,
      "y": -25,
      "z": 2,
      "name": "Rock_Sandstone_Brick"
    },
    {
      "x": 2,
      "y": -24,
      "z": 2,
      "name": "Rock_Sandstone_Cobble",
      "rotation": 3
    },
    {
      "x": 2,
      "y": -23,
      "z": 2,
      "name": "Rock_Sandstone_Brick",
      "rotation": 3
    },
    {
      "x": 2,
      "y": -22,
      "z": 2,
      "name": "Rock_Sandstone_Cobble",
      "rotation": 3
    },
    {
      "x": 2,
      "y": -34,
      "z": 3,
      "name": "Rock_Sandstone"
    },
    {
      "x": 2,
      "y": -33,
      "z": 3,
      "name": "Rock_Sandstone"
    },
    {
      "x": 2,
      "y": -32,
      "z": 3,
      "name": "Rock_Sandstone_Brick"
    },
    {
      "x": 2,
      "y": -31,
      "z": 3,
      "name": "Rock_Sandstone_Brick"
    },
    {
      "x": 2,
      "y": -30,
      "z": 3,
      "name": "Rock_Sandstone_Brick"
    },
    {
      "x": 2,
      "y": -29,
      "z": 3,
      "name": "Rock_Sandstone_Brick"
    },
    {
      "x": 2,
      "y": -28,
      "z": 3,
      "name": "Rock_Sandstone_Brick"
    },
    {
      "x": 2,
      "y": -27,
      "z": 3,
      "name": "Rock_Sandstone_Brick"
    },
    {
      "x": 2,
      "y": -26,
      "z": 3,
      "name": "Rock_Sandstone_Brick"
    },
    {
      "x": 2,
      "y": -25,
      "z": 3,
      "name": "Rock_Sandstone_Cobble"
    },
    {
      "x": 2,
      "y": -24,
      "z": 3,
      "name": "Rock_Sandstone_Brick",
      "rotation": 3
    },
    {
      "x": 2,
      "y": -23,
      "z": 3,
      "name": "Rock_Sandstone",
      "rotation": 3
    },
    {
      "x": 2,
      "y": -22,
      "z": 3,
      "name": "Rock_Sandstone_Brick",
      "rotation": 3
    },
    {
      "x": 2,
      "y": -34,
      "z": 4,
      "name": "Rock_Sandstone_Brick"
    },
    {
      "x": 2,
      "y": -33,
      "z": 4,
      "name": "Rock_Sandstone_Brick"
    },
    {
      "x": 2,
      "y": -32,
      "z": 4,
      "name": "Rock_Sandstone_Brick"
    },
    {
      "x": 2,
      "y": -31,
      "z": 4,
      "name": "Rock_Sandstone_Brick"
    },
    {
      "x": 2,
      "y": -30,
      "z": 4,
      "name": "Rock_Sandstone_Brick"
    },
    {
      "x": 2,
      "y": -29,
      "z": 4,
      "name": "Rock_Sandstone_Brick"
    },
    {
      "x": 2,
      "y": -28,
      "z": 4,
      "name": "Rock_Sandstone_Brick"
    },
    {
      "x": 2,
      "y": -27,
      "z": 4,
      "name": "Rock_Sandstone_Brick"
    },
    {
      "x": 2,
      "y": -26,
      "z": 4,
      "name": "Rock_Sandstone_Brick"
    },
    {
      "x": 2,
      "y": -25,
      "z": 4,
      "name": "Rock_Sandstone_Brick"
    },
    {
      "x": 2,
      "y": -24,
      "z": 4,
      "name": "Rock_Sandstone_Cobble"
    },
    {
      "x": 2,
      "y": -23,
      "z": 4,
      "name": "Rock_Sandstone_Cobble"
    },
    {
      "x": 2,
      "y": -22,
      "z": 4,
      "name": "Rock_Sandstone_Brick"
    },
    {
      "x": 2,
      "y": -34,
      "z": 5,
      "name": "Rock_Sandstone_Brick"
    },
    {
      "x": 2,
      "y": -33,
      "z": 5,
      "name": "Rock_Sandstone_Brick"
    },
    {
      "x": 2,
      "y": -32,
      "z": 5,
      "name": "Rock_Sandstone_Cobble"
    },
    {
      "x": 2,
      "y": -31,
      "z": 5,
      "name": "Rock_Sandstone"
    },
    {
      "x": 2,
      "y": -30,
      "z": 5,
      "name": "Rock_Sandstone"
    },
    {
      "x": 2,
      "y": -29,
      "z": 5,
      "name": "Rock_Sandstone_Brick"
    },
    {
      "x": 2,
      "y": -28,
      "z": 5,
      "name": "Rock_Sandstone"
    },
    {
      "x": 2,
      "y": -27,
      "z": 5,
      "name": "Rock_Sandstone"
    },
    {
      "x": 2,
      "y": -26,
      "z": 5,
      "name": "Rock_Sandstone"
    },
    {
      "x": 2,
      "y": -25,
      "z": 5,
      "name": "Rock_Sandstone_Cobble"
    },
    {
      "x": 2,
      "y": -24,
      "z": 5,
      "name": "Rock_Sandstone_Brick"
    },
    {
      "x": 2,
      "y": -34,
      "z": 16,
      "name": "Rock_Sandstone_Brick"
    },
    {
      "x": 2,
      "y": -33,
      "z": 16,
      "name": "Rock_Sandstone_Brick"
    },
    {
      "x": 2,
      "y": -32,
      "z": 16,
      "name": "Rock_Sandstone"
    },
    {
      "x": 2,
      "y": -31,
      "z": 16,
      "name": "Rock_Sandstone_Brick"
    },
    {
      "x": 2,
      "y": -30,
      "z": 16,
      "name": "Rock_Sandstone_Brick"
    },
    {
      "x": 2,
      "y": -29,
      "z": 16,
      "name": "Rock_Sandstone_Cobble"
    },
    {
      "x": 2,
      "y": -28,
      "z": 16,
      "name": "Rock_Sandstone_Brick"
    },
    {
      "x": 2,
      "y": -27,
      "z": 16,
      "name": "Rock_Sandstone_Cobble"
    },
    {
      "x": 2,
      "y": -26,
      "z": 16,
      "name": "Rock_Sandstone_Brick"
    },
    {
      "x": 2,
      "y": -25,
      "z": 16,
      "name": "Rock_Sandstone"
    },
    {
      "x": 2,
      "y": -24,
      "z": 16,
      "name": "Rock_Sandstone"
    },
    {
      "x": 2,
      "y": -23,
      "z": 16,
      "name": "Rock_Sandstone_Brick"
    },
    {
      "x": 2,
      "y": -22,
      "z": 16,
      "name": "Rock_Sandstone"
    },
    {
      "x": 2,
      "y": -21,
      "z": 16,
      "name": "Rock_Sandstone_Brick"
    },
    {
      "x": 2,
      "y": -20,
      "z": 16,
      "name": "Rock_Sandstone"
    },
    {
      "x": 2,
      "y": -34,
      "z": 17,
      "name": "Rock_Sandstone_Brick"
    },
    {
      "x": 2,
      "y": -33,
      "z": 17,
      "name": "Rock_Sandstone_Brick"
    },
    {
      "x": 2,
      "y": -32,
      "z": 17,
      "name": "Rock_Sandstone"
    },
    {
      "x": 2,
      "y": -31,
      "z": 17,
      "name": "Rock_Sandstone_Brick"
    },
    {
      "x": 2,
      "y": -30,
      "z": 17,
      "name": "Rock_Sandstone_Cobble"
    },
    {
      "x": 2,
      "y": -29,
      "z": 17,
      "name": "Rock_Sandstone_Brick"
    },
    {
      "x": 2,
      "y": -28,
      "z": 17,
      "name": "Rock_Sandstone"
    },
    {
      "x": 2,
      "y": -27,
      "z": 17,
      "name": "Rock_Sandstone_Brick"
    },
    {
      "x": 2,
      "y": -26,
      "z": 17,
      "name": "Rock_Sandstone_Brick"
    },
    {
      "x": 2,
      "y": -25,
      "z": 17,
      "name": "Rock_Sandstone"
    },
    {
      "x": 2,
      "y": -24,
      "z": 17,
      "name": "Rock_Sandstone_Cobble"
    },
    {
      "x": 2,
      "y": -23,
      "z": 17,
      "name": "Rock_Sandstone_Cobble"
    },
    {
      "x": 2,
      "y": -22,
      "z": 17,
      "name": "Rock_Sandstone"
    },
    {
      "x": 2,
      "y": -21,
      "z": 17,
      "name": "Rock_Sandstone_Brick"
    },
    {
      "x": 2,
      "y": -20,
      "z": 17,
      "name": "Rock_Sandstone_Brick"
    },
    {
      "x": 2,
      "y": -34,
      "z": 18,
      "name": "Rock_Sandstone_Brick"
    },
    {
      "x": 2,
      "y": -33,
      "z": 18,
      "name": "Rock_Sandstone"
    },
    {
      "x": 2,
      "y": -32,
      "z": 18,
      "name": "Rock_Sandstone"
    },
    {
      "x": 2,
      "y": -31,
      "z": 18,
      "name": "Rock_Sandstone_Cobble"
    },
    {
      "x": 2,
      "y": -30,
      "z": 18,
      "name": "Rock_Sandstone_Brick"
    },
    {
      "x": 2,
      "y": -29,
      "z": 18,
      "name": "Rock_Sandstone_Brick"
    },
    {
      "x": 2,
      "y": -28,
      "z": 18,
      "name": "Rock_Sandstone_Brick"
    },
    {
      "x": 2,
      "y": -27,
      "z": 18,
      "name": "Rock_Sandstone_Brick"
    },
    {
      "x": 2,
      "y": -26,
      "z": 18,
      "name": "Rock_Sandstone_Brick"
    },
    {
      "x": 2,
      "y": -25,
      "z": 18,
      "name": "Rock_Sandstone"
    },
    {
      "x": 2,
      "y": -24,
      "z": 18,
      "name": "Rock_Sandstone_Brick"
    },
    {
      "x": 2,
      "y": -23,
      "z": 18,
      "name": "Rock_Sandstone_Brick",
      "rotation": 1
    },
    {
      "x": 2,
      "y": -22,
      "z": 18,
      "name": "Rock_Sandstone_Cobble",
      "rotation": 1
    },
    {
      "x": 2,
      "y": -21,
      "z": 18,
      "name": "Rock_Sandstone",
      "rotation": 1
    },
    {
      "x": 2,
      "y": -20,
      "z": 18,
      "name": "Rock_Sandstone_Brick",
      "rotation": 1
    },
    {
      "x": 2,
      "y": -34,
      "z": 19,
      "name": "Rock_Sandstone_Brick"
    },
    {
      "x": 2,
      "y": -33,
      "z": 19,
      "name": "Rock_Sandstone_Brick"
    },
    {
      "x": 2,
      "y": -32,
      "z": 19,
      "name": "Rock_Sandstone_Cobble"
    },
    {
      "x": 2,
      "y": -31,
      "z": 19,
      "name": "Rock_Sandstone_Brick"
    },
    {
      "x": 2,
      "y": -30,
      "z": 19,
      "name": "Rock_Sandstone_Brick"
    },
    {
      "x": 2,
      "y": -29,
      "z": 19,
      "name": "Rock_Sandstone"
    },
    {
      "x": 2,
      "y": -28,
      "z": 19,
      "name": "Rock_Sandstone"
    },
    {
      "x": 2,
      "y": -27,
      "z": 19,
      "name": "Rock_Sandstone_Brick"
    },
    {
      "x": 2,
      "y": -26,
      "z": 19,
      "name": "Rock_Sandstone_Cobble"
    },
    {
      "x": 2,
      "y": -25,
      "z": 19,
      "name": "Rock_Sandstone_Brick"
    },
    {
      "x": 2,
      "y": -24,
      "z": 19,
      "name": "Rock_Sandstone_Brick"
    },
    {
      "x": 2,
      "y": -23,
      "z": 19,
      "name": "Rock_Sandstone_Brick",
      "rotation": 1
    },
    {
      "x": 2,
      "y": -22,
      "z": 19,
      "name": "Rock_Sandstone_Brick",
      "rotation": 1
    },
    {
      "x": 2,
      "y": -21,
      "z": 19,
      "name": "Rock_Sandstone_Brick",
      "rotation": 1
    },
    {
      "x": 2,
      "y": -20,
      "z": 19,
      "name": "Rock_Sandstone_Brick",
      "rotation": 1
    },
    {
      "x": 2,
      "y": -19,
      "z": 19,
      "name": "Rock_Sandstone_Cobble",
      "rotation": 1
    },
    {
      "x": 2,
      "y": -34,
      "z": 20,
      "name": "Rock_Sandstone_Brick"
    },
    {
      "x": 2,
      "y": -33,
      "z": 20,
      "name": "Rock_Sandstone"
    },
    {
      "x": 2,
      "y": -32,
      "z": 20,
      "name": "Rock_Sandstone_Brick"
    },
    {
      "x": 2,
      "y": -31,
      "z": 20,
      "name": "Rock_Sandstone_Brick"
    },
    {
      "x": 2,
      "y": -30,
      "z": 20,
      "name": "Rock_Sandstone_Brick"
    },
    {
      "x": 2,
      "y": -29,
      "z": 20,
      "name": "Rock_Sandstone_Brick"
    },
    {
      "x": 2,
      "y": -28,
      "z": 20,
      "name": "Rock_Sandstone_Brick"
    },
    {
      "x": 2,
      "y": -27,
      "z": 20,
      "name": "Rock_Sandstone_Brick"
    },
    {
      "x": 2,
      "y": -26,
      "z": 20,
      "name": "Rock_Sandstone_Cobble"
    },
    {
      "x": 2,
      "y": -25,
      "z": 20,
      "name": "Rock_Sandstone_Brick"
    },
    {
      "x": 2,
      "y": -24,
      "z": 20,
      "name": "Rock_Sandstone_Brick"
    },
    {
      "x": 2,
      "y": -23,
      "z": 20,
      "name": "Rock_Sandstone",
      "rotation": 1
    },
    {
      "x": 2,
      "y": -22,
      "z": 20,
      "name": "Rock_Sandstone_Brick",
      "rotation": 1
    },
    {
      "x": 2,
      "y": -21,
      "z": 20,
      "name": "Rock_Sandstone",
      "rotation": 1
    },
    {
      "x": 2,
      "y": -20,
      "z": 20,
      "name": "Rock_Sandstone",
      "rotation": 1
    },
    {
      "x": 2,
      "y": -19,
      "z": 20,
      "name": "Rock_Sandstone_Brick",
      "rotation": 1
    },
    {
      "x": 2,
      "y": -34,
      "z": 21,
      "name": "Rock_Sandstone_Brick"
    },
    {
      "x": 2,
      "y": -33,
      "z": 21,
      "name": "Rock_Sandstone_Cobble"
    },
    {
      "x": 2,
      "y": -32,
      "z": 21,
      "name": "Rock_Sandstone_Cobble"
    },
    {
      "x": 2,
      "y": -31,
      "z": 21,
      "name": "Rock_Sandstone_Brick"
    },
    {
      "x": 2,
      "y": -30,
      "z": 21,
      "name": "Rock_Sandstone_Brick"
    },
    {
      "x": 2,
      "y": -29,
      "z": 21,
      "name": "Rock_Sandstone"
    },
    {
      "x": 2,
      "y": -28,
      "z": 21,
      "name": "Rock_Sandstone_Cobble"
    },
    {
      "x": 2,
      "y": -27,
      "z": 21,
      "name": "Rock_Sandstone_Brick"
    },
    {
      "x": 2,
      "y": -26,
      "z": 21,
      "name": "Rock_Sandstone"
    },
    {
      "x": 2,
      "y": -25,
      "z": 21,
      "name": "Rock_Sandstone_Brick"
    },
    {
      "x": 2,
      "y": -24,
      "z": 21,
      "name": "Rock_Sandstone_Brick"
    },
    {
      "x": 2,
      "y": -23,
      "z": 21,
      "name": "Rock_Sandstone"
    },
    {
      "x": 2,
      "y": -22,
      "z": 21,
      "name": "Rock_Sandstone_Brick"
    },
    {
      "x": 2,
      "y": -21,
      "z": 21,
      "name": "Rock_Sandstone_Brick"
    },
    {
      "x": 2,
      "y": -20,
      "z": 21,
      "name": "Rock_Sandstone_Brick"
    },
    {
      "x": 2,
      "y": -19,
      "z": 21,
      "name": "Rock_Sandstone_Brick"
    },
    {
      "x": 2,
      "y": -18,
      "z": 21,
      "name": "Rock_Sandstone_Cobble"
    },
    {
      "x": 3,
      "y": -34,
      "z": 0,
      "name": "Rock_Sandstone_Brick"
    },
    {
      "x": 3,
      "y": -33,
      "z": 0,
      "name": "Rock_Sandstone_Brick"
    },
    {
      "x": 3,
      "y": -32,
      "z": 0,
      "name": "Rock_Sandstone_Brick"
    },
    {
      "x": 3,
      "y": -31,
      "z": 0,
      "name": "Rock_Sandstone"
    },
    {
      "x": 3,
      "y": -30,
      "z": 0,
      "name": "Rock_Sandstone_Brick"
    },
    {
      "x": 3,
      "y": -29,
      "z": 0,
      "name": "Rock_Sandstone_Brick"
    },
    {
      "x": 3,
      "y": -28,
      "z": 0,
      "name": "Rock_Sandstone"
    },
    {
      "x": 3,
      "y": -27,
      "z": 0,
      "name": "Rock_Sandstone_Cobble"
    },
    {
      "x": 3,
      "y": -26,
      "z": 0,
      "name": "Rock_Sandstone_Brick"
    },
    {
      "x": 3,
      "y": -25,
      "z": 0,
      "name": "Rock_Sandstone"
    },
    {
      "x": 3,
      "y": -24,
      "z": 0,
      "name": "Rock_Sandstone_Brick"
    },
    {
      "x": 3,
      "y": -23,
      "z": 0,
      "name": "Rock_Sandstone_Brick"
    },
    {
      "x": 3,
      "y": -22,
      "z": 0,
      "name": "Rock_Sandstone_Brick"
    },
    {
      "x": 3,
      "y": -34,
      "z": 1,
      "name": "Rock_Sandstone_Brick"
    },
    {
      "x": 3,
      "y": -33,
      "z": 1,
      "name": "Rock_Sandstone_Cobble"
    },
    {
      "x": 3,
      "y": -32,
      "z": 1,
      "name": "Rock_Sandstone"
    },
    {
      "x": 3,
      "y": -31,
      "z": 1,
      "name": "Rock_Sandstone_Brick"
    },
    {
      "x": 3,
      "y": -30,
      "z": 1,
      "name": "Rock_Sandstone_Brick"
    },
    {
      "x": 3,
      "y": -29,
      "z": 1,
      "name": "Rock_Sandstone_Cobble"
    },
    {
      "x": 3,
      "y": -28,
      "z": 1,
      "name": "Rock_Sandstone_Brick"
    },
    {
      "x": 3,
      "y": -27,
      "z": 1,
      "name": "Rock_Sandstone_Cobble"
    },
    {
      "x": 3,
      "y": -26,
      "z": 1,
      "name": "Rock_Sandstone_Brick"
    },
    {
      "x": 3,
      "y": -25,
      "z": 1,
      "name": "Rock_Sandstone_Brick"
    },
    {
      "x": 3,
      "y": -24,
      "z": 1,
      "name": "Rock_Sandstone_Brick",
      "rotation": 3
    },
    {
      "x": 3,
      "y": -23,
      "z": 1,
      "name": "Rock_Sandstone_Cobble",
      "rotation": 3
    },
    {
      "x": 3,
      "y": -22,
      "z": 1,
      "name": "Rock_Sandstone_Cobble",
      "rotation": 3
    },
    {
      "x": 3,
      "y": -34,
      "z": 2,
      "name": "Rock_Sandstone_Brick"
    },
    {
      "x": 3,
      "y": -33,
      "z": 2,
      "name": "Rock_Sandstone_Cobble"
    },
    {
      "x": 3,
      "y": -32,
      "z": 2,
      "name": "Rock_Sandstone"
    },
    {
      "x": 3,
      "y": -31,
      "z": 2,
      "name": "Rock_Sandstone_Brick"
    },
    {
      "x": 3,
      "y": -30,
      "z": 2,
      "name": "Rock_Sandstone_Brick"
    },
    {
      "x": 3,
      "y": -29,
      "z": 2,
      "name": "Rock_Sandstone_Brick"
    },
    {
      "x": 3,
      "y": -28,
      "z": 2,
      "name": "Rock_Sandstone_Brick"
    },
    {
      "x": 3,
      "y": -27,
      "z": 2,
      "name": "Rock_Sandstone_Cobble"
    },
    {
      "x": 3,
      "y": -26,
      "z": 2,
      "name": "Rock_Sandstone_Brick"
    },
    {
      "x": 3,
      "y": -25,
      "z": 2,
      "name": "Rock_Sandstone_Cobble"
    },
    {
      "x": 3,
      "y": -24,
      "z": 2,
      "name": "Rock_Sandstone_Brick",
      "rotation": 3
    },
    {
      "x": 3,
      "y": -23,
      "z": 2,
      "name": "Rock_Sandstone_Brick",
      "rotation": 3
    },
    {
      "x": 3,
      "y": -22,
      "z": 2,
      "name": "Rock_Sandstone",
      "rotation": 3
    },
    {
      "x": 3,
      "y": -34,
      "z": 3,
      "name": "Rock_Sandstone_Brick"
    },
    {
      "x": 3,
      "y": -33,
      "z": 3,
      "name": "Rock_Sandstone_Brick"
    },
    {
      "x": 3,
      "y": -32,
      "z": 3,
      "name": "Rock_Sandstone_Brick"
    },
    {
      "x": 3,
      "y": -31,
      "z": 3,
      "name": "Rock_Sandstone_Brick"
    },
    {
      "x": 3,
      "y": -30,
      "z": 3,
      "name": "Rock_Sandstone_Brick"
    },
    {
      "x": 3,
      "y": -29,
      "z": 3,
      "name": "Rock_Sandstone_Brick"
    },
    {
      "x": 3,
      "y": -28,
      "z": 3,
      "name": "Rock_Sandstone_Brick"
    },
    {
      "x": 3,
      "y": -27,
      "z": 3,
      "name": "Rock_Sandstone_Brick"
    },
    {
      "x": 3,
      "y": -26,
      "z": 3,
      "name": "Rock_Sandstone"
    },
    {
      "x": 3,
      "y": -25,
      "z": 3,
      "name": "Rock_Sandstone_Brick"
    },
    {
      "x": 3,
      "y": -24,
      "z": 3,
      "name": "Rock_Sandstone",
      "rotation": 3
    },
    {
      "x": 3,
      "y": -23,
      "z": 3,
      "name": "Rock_Sandstone_Brick",
      "rotation": 3
    },
    {
      "x": 3,
      "y": -22,
      "z": 3,
      "name": "Rock_Sandstone",
      "rotation": 3
    },
    {
      "x": 3,
      "y": -34,
      "z": 4,
      "name": "Rock_Sandstone_Brick"
    },
    {
      "x": 3,
      "y": -33,
      "z": 4,
      "name": "Rock_Sandstone_Brick"
    },
    {
      "x": 3,
      "y": -32,
      "z": 4,
      "name": "Rock_Sandstone_Brick"
    },
    {
      "x": 3,
      "y": -31,
      "z": 4,
      "name": "Rock_Sandstone_Cobble"
    },
    {
      "x": 3,
      "y": -30,
      "z": 4,
      "name": "Rock_Sandstone_Brick"
    },
    {
      "x": 3,
      "y": -29,
      "z": 4,
      "name": "Rock_Sandstone"
    },
    {
      "x": 3,
      "y": -28,
      "z": 4,
      "name": "Rock_Sandstone_Brick"
    },
    {
      "x": 3,
      "y": -27,
      "z": 4,
      "name": "Rock_Sandstone"
    },
    {
      "x": 3,
      "y": -26,
      "z": 4,
      "name": "Rock_Sandstone_Brick"
    },
    {
      "x": 3,
      "y": -25,
      "z": 4,
      "name": "Rock_Sandstone_Brick"
    },
    {
      "x": 3,
      "y": -24,
      "z": 4,
      "name": "Rock_Sandstone_Cobble"
    },
    {
      "x": 3,
      "y": -23,
      "z": 4,
      "name": "Rock_Sandstone_Brick"
    },
    {
      "x": 3,
      "y": -34,
      "z": 5,
      "name": "Rock_Sandstone_Brick"
    },
    {
      "x": 3,
      "y": -33,
      "z": 5,
      "name": "Rock_Sandstone_Brick"
    },
    {
      "x": 3,
      "y": -32,
      "z": 5,
      "name": "Rock_Sandstone_Brick"
    },
    {
      "x": 3,
      "y": -31,
      "z": 5,
      "name": "Rock_Sandstone_Brick"
    },
    {
      "x": 3,
      "y": -30,
      "z": 5,
      "name": "Rock_Sandstone"
    },
    {
      "x": 3,
      "y": -29,
      "z": 5,
      "name": "Rock_Sandstone_Brick"
    },
    {
      "x": 3,
      "y": -28,
      "z": 5,
      "name": "Rock_Sandstone_Cobble"
    },
    {
      "x": 3,
      "y": -27,
      "z": 5,
      "name": "Rock_Sandstone_Brick"
    },
    {
      "x": 3,
      "y": -26,
      "z": 5,
      "name": "Rock_Sandstone_Cobble"
    },
    {
      "x": 3,
      "y": -25,
      "z": 5,
      "name": "Rock_Sandstone_Cobble"
    },
    {
      "x": 3,
      "y": -24,
      "z": 5,
      "name": "Rock_Sandstone_Brick"
    },
    {
      "x": 3,
      "y": -23,
      "z": 5,
      "name": "Rock_Sandstone_Brick"
    },
    {
      "x": 3,
      "y": -34,
      "z": 16,
      "name": "Rock_Sandstone_Cobble"
    },
    {
      "x": 3,
      "y": -33,
      "z": 16,
      "name": "Rock_Sandstone_Cobble"
    },
    {
      "x": 3,
      "y": -32,
      "z": 16,
      "name": "Rock_Sandstone_Brick"
    },
    {
      "x": 3,
      "y": -31,
      "z": 16,
      "name": "Rock_Sandstone_Brick"
    },
    {
      "x": 3,
      "y": -30,
      "z": 16,
      "name": "Rock_Sandstone_Brick"
    },
    {
      "x": 3,
      "y": -29,
      "z": 16,
      "name": "Rock_Sandstone_Brick"
    },
    {
      "x": 3,
      "y": -28,
      "z": 16,
      "name": "Rock_Sandstone_Cobble"
    },
    {
      "x": 3,
      "y": -27,
      "z": 16,
      "name": "Rock_Sandstone_Brick"
    },
    {
      "x": 3,
      "y": -26,
      "z": 16,
      "name": "Rock_Sandstone"
    },
    {
      "x": 3,
      "y": -25,
      "z": 16,
      "name": "Rock_Sandstone_Brick"
    },
    {
      "x": 3,
      "y": -24,
      "z": 16,
      "name": "Rock_Sandstone_Brick"
    },
    {
      "x": 3,
      "y": -23,
      "z": 16,
      "name": "Rock_Sandstone"
    },
    {
      "x": 3,
      "y": -22,
      "z": 16,
      "name": "Rock_Sandstone"
    },
    {
      "x": 3,
      "y": -21,
      "z": 16,
      "name": "Rock_Sandstone"
    },
    {
      "x": 3,
      "y": -34,
      "z": 17,
      "name": "Rock_Sandstone_Brick"
    },
    {
      "x": 3,
      "y": -33,
      "z": 17,
      "name": "Rock_Sandstone_Brick"
    },
    {
      "x": 3,
      "y": -32,
      "z": 17,
      "name": "Rock_Sandstone"
    },
    {
      "x": 3,
      "y": -31,
      "z": 17,
      "name": "Rock_Sandstone_Brick"
    },
    {
      "x": 3,
      "y": -30,
      "z": 17,
      "name": "Rock_Sandstone_Brick"
    },
    {
      "x": 3,
      "y": -29,
      "z": 17,
      "name": "Rock_Sandstone"
    },
    {
      "x": 3,
      "y": -28,
      "z": 17,
      "name": "Rock_Sandstone_Brick"
    },
    {
      "x": 3,
      "y": -27,
      "z": 17,
      "name": "Rock_Sandstone_Brick"
    },
    {
      "x": 3,
      "y": -26,
      "z": 17,
      "name": "Rock_Sandstone_Brick"
    },
    {
      "x": 3,
      "y": -25,
      "z": 17,
      "name": "Rock_Sandstone_Brick"
    },
    {
      "x": 3,
      "y": -24,
      "z": 17,
      "name": "Rock_Sandstone"
    },
    {
      "x": 3,
      "y": -23,
      "z": 17,
      "name": "Rock_Sandstone_Brick"
    },
    {
      "x": 3,
      "y": -22,
      "z": 17,
      "name": "Rock_Sandstone"
    },
    {
      "x": 3,
      "y": -21,
      "z": 17,
      "name": "Rock_Sandstone_Brick"
    },
    {
      "x": 3,
      "y": -34,
      "z": 18,
      "name": "Rock_Sandstone_Brick"
    },
    {
      "x": 3,
      "y": -33,
      "z": 18,
      "name": "Rock_Sandstone_Brick"
    },
    {
      "x": 3,
      "y": -32,
      "z": 18,
      "name": "Rock_Sandstone_Cobble"
    },
    {
      "x": 3,
      "y": -31,
      "z": 18,
      "name": "Rock_Sandstone"
    },
    {
      "x": 3,
      "y": -30,
      "z": 18,
      "name": "Rock_Sandstone_Brick"
    },
    {
      "x": 3,
      "y": -29,
      "z": 18,
      "name": "Rock_Sandstone_Brick"
    },
    {
      "x": 3,
      "y": -28,
      "z": 18,
      "name": "Rock_Sandstone_Brick"
    },
    {
      "x": 3,
      "y": -27,
      "z": 18,
      "name": "Rock_Sandstone"
    },
    {
      "x": 3,
      "y": -26,
      "z": 18,
      "name": "Rock_Sandstone"
    },
    {
      "x": 3,
      "y": -25,
      "z": 18,
      "name": "Rock_Sandstone_Brick"
    },
    {
      "x": 3,
      "y": -24,
      "z": 18,
      "name": "Rock_Sandstone_Brick"
    },
    {
      "x": 3,
      "y": -23,
      "z": 18,
      "name": "Rock_Sandstone_Brick",
      "rotation": 1
    },
    {
      "x": 3,
      "y": -22,
      "z": 18,
      "name": "Rock_Sandstone_Brick",
      "rotation": 1
    },
    {
      "x": 3,
      "y": -21,
      "z": 18,
      "name": "Rock_Sandstone",
      "rotation": 1
    },
    {
      "x": 3,
      "y": -34,
      "z": 19,
      "name": "Rock_Sandstone_Cobble"
    },
    {
      "x": 3,
      "y": -33,
      "z": 19,
      "name": "Rock_Sandstone_Cobble"
    },
    {
      "x": 3,
      "y": -32,
      "z": 19,
      "name": "Rock_Sandstone_Brick"
    },
    {
      "x": 3,
      "y": -31,
      "z": 19,
      "name": "Rock_Sandstone"
    },
    {
      "x": 3,
      "y": -30,
      "z": 19,
      "name": "Rock_Sandstone_Brick"
    },
    {
      "x": 3,
      "y": -29,
      "z": 19,
      "name": "Rock_Sandstone_Brick"
    },
    {
      "x": 3,
      "y": -28,
      "z": 19,
      "name": "Rock_Sandstone_Cobble"
    },
    {
      "x": 3,
      "y": -27,
      "z": 19,
      "name": "Rock_Sandstone_Cobble"
    },
    {
      "x": 3,
      "y": -26,
      "z": 19,
      "name": "Rock_Sandstone_Brick"
    },
    {
      "x": 3,
      "y": -25,
      "z": 19,
      "name": "Rock_Sandstone_Brick"
    },
    {
      "x": 3,
      "y": -24,
      "z": 19,
      "name": "Rock_Sandstone_Brick"
    },
    {
      "x": 3,
      "y": -23,
      "z": 19,
      "name": "Rock_Sandstone_Brick",
      "rotation": 1
    },
    {
      "x": 3,
      "y": -22,
      "z": 19,
      "name": "Rock_Sandstone_Brick",
      "rotation": 1
    },
    {
      "x": 3,
      "y": -21,
      "z": 19,
      "name": "Rock_Sandstone",
      "rotation": 1
    },
    {
      "x": 3,
      "y": -20,
      "z": 19,
      "name": "Rock_Sandstone",
      "rotation": 1
    },
    {
      "x": 3,
      "y": -34,
      "z": 20,
      "name": "Rock_Sandstone_Brick"
    },
    {
      "x": 3,
      "y": -33,
      "z": 20,
      "name": "Rock_Sandstone_Brick"
    },
    {
      "x": 3,
      "y": -32,
      "z": 20,
      "name": "Rock_Sandstone"
    },
    {
      "x": 3,
      "y": -31,
      "z": 20,
      "name": "Rock_Sandstone_Brick"
    },
    {
      "x": 3,
      "y": -30,
      "z": 20,
      "name": "Rock_Sandstone_Brick"
    },
    {
      "x": 3,
      "y": -29,
      "z": 20,
      "name": "Rock_Sandstone_Cobble"
    },
    {
      "x": 3,
      "y": -28,
      "z": 20,
      "name": "Rock_Sandstone_Brick"
    },
    {
      "x": 3,
      "y": -27,
      "z": 20,
      "name": "Rock_Sandstone"
    },
    {
      "x": 3,
      "y": -26,
      "z": 20,
      "name": "Rock_Sandstone_Brick"
    },
    {
      "x": 3,
      "y": -25,
      "z": 20,
      "name": "Rock_Sandstone"
    },
    {
      "x": 3,
      "y": -24,
      "z": 20,
      "name": "Rock_Sandstone_Brick"
    },
    {
      "x": 3,
      "y": -23,
      "z": 20,
      "name": "Rock_Sandstone_Brick",
      "rotation": 1
    },
    {
      "x": 3,
      "y": -22,
      "z": 20,
      "name": "Rock_Sandstone",
      "rotation": 1
    },
    {
      "x": 3,
      "y": -21,
      "z": 20,
      "name": "Rock_Sandstone_Brick",
      "rotation": 1
    },
    {
      "x": 3,
      "y": -20,
      "z": 20,
      "name": "Rock_Sandstone_Brick",
      "rotation": 1
    },
    {
      "x": 3,
      "y": -34,
      "z": 21,
      "name": "Rock_Sandstone_Brick"
    },
    {
      "x": 3,
      "y": -33,
      "z": 21,
      "name": "Rock_Sandstone"
    },
    {
      "x": 3,
      "y": -32,
      "z": 21,
      "name": "Rock_Sandstone"
    },
    {
      "x": 3,
      "y": -31,
      "z": 21,
      "name": "Rock_Sandstone_Cobble"
    },
    {
      "x": 3,
      "y": -30,
      "z": 21,
      "name": "Rock_Sandstone_Brick"
    },
    {
      "x": 3,
      "y": -29,
      "z": 21,
      "name": "Rock_Sandstone_Brick"
    },
    {
      "x": 3,
      "y": -28,
      "z": 21,
      "name": "Rock_Sandstone_Brick"
    },
    {
      "x": 3,
      "y": -27,
      "z": 21,
      "name": "Rock_Sandstone"
    },
    {
      "x": 3,
      "y": -26,
      "z": 21,
      "name": "Rock_Sandstone"
    },
    {
      "x": 3,
      "y": -25,
      "z": 21,
      "name": "Rock_Sandstone_Cobble"
    },
    {
      "x": 3,
      "y": -24,
      "z": 21,
      "name": "Rock_Sandstone_Brick"
    },
    {
      "x": 3,
      "y": -23,
      "z": 21,
      "name": "Rock_Sandstone_Brick"
    },
    {
      "x": 3,
      "y": -22,
      "z": 21,
      "name": "Rock_Sandstone_Brick"
    },
    {
      "x": 3,
      "y": -21,
      "z": 21,
      "name": "Rock_Sandstone_Brick"
    },
    {
      "x": 3,
      "y": -20,
      "z": 21,
      "name": "Rock_Sandstone_Brick"
    },
    {
      "x": 3,
      "y": -19,
      "z": 21,
      "name": "Rock_Sandstone_Brick"
    },
    {
      "x": 4,
      "y": -34,
      "z": 2,
      "name": "Rock_Sandstone_Brick"
    },
    {
      "x": 4,
      "y": -33,
      "z": 2,
      "name": "Rock_Sandstone_Brick"
    },
    {
      "x": 4,
      "y": -32,
      "z": 2,
      "name": "Rock_Sandstone_Brick"
    },
    {
      "x": 4,
      "y": -31,
      "z": 2,
      "name": "Rock_Sandstone_Brick"
    },
    {
      "x": 4,
      "y": -30,
      "z": 2,
      "name": "Rock_Sandstone_Brick"
    },
    {
      "x": 4,
      "y": -29,
      "z": 2,
      "name": "Rock_Sandstone_Brick"
    },
    {
      "x": 4,
      "y": -28,
      "z": 2,
      "name": "Rock_Sandstone_Brick"
    },
    {
      "x": 4,
      "y": -27,
      "z": 2,
      "name": "Rock_Sandstone"
    },
    {
      "x": 4,
      "y": -26,
      "z": 2,
      "name": "Rock_Sandstone_Brick"
    },
    {
      "x": 4,
      "y": -25,
      "z": 2,
      "name": "Rock_Sandstone_Cobble"
    },
    {
      "x": 4,
      "y": -24,
      "z": 2,
      "name": "Rock_Sandstone_Cobble",
      "rotation": 3
    },
    {
      "x": 4,
      "y": -23,
      "z": 2,
      "name": "Rock_Sandstone_Brick",
      "rotation": 3
    },
    {
      "x": 4,
      "y": -22,
      "z": 2,
      "name": "Rock_Sandstone_Cobble",
      "rotation": 3
    },
    {
      "x": 4,
      "y": -34,
      "z": 3,
      "name": "Rock_Sandstone_Brick"
    },
    {
      "x": 4,
      "y": -33,
      "z": 3,
      "name": "Rock_Sandstone"
    },
    {
      "x": 4,
      "y": -32,
      "z": 3,
      "name": "Rock_Sandstone_Brick"
    },
    {
      "x": 4,
      "y": -31,
      "z": 3,
      "name": "Rock_Sandstone_Brick"
    },
    {
      "x": 4,
      "y": -30,
      "z": 3,
      "name": "Rock_Sandstone_Brick"
    },
    {
      "x": 4,
      "y": -29,
      "z": 3,
      "name": "Rock_Sandstone_Brick"
    },
    {
      "x": 4,
      "y": -28,
      "z": 3,
      "name": "Rock_Sandstone_Brick"
    },
    {
      "x": 4,
      "y": -27,
      "z": 3,
      "name": "Rock_Sandstone_Brick"
    },
    {
      "x": 4,
      "y": -26,
      "z": 3,
      "name": "Rock_Sandstone_Brick"
    },
    {
      "x": 4,
      "y": -25,
      "z": 3,
      "name": "Rock_Sandstone_Brick"
    },
    {
      "x": 4,
      "y": -24,
      "z": 3,
      "name": "Rock_Sandstone_Brick",
      "rotation": 3
    },
    {
      "x": 4,
      "y": -23,
      "z": 3,
      "name": "Rock_Sandstone_Brick",
      "rotation": 3
    },
    {
      "x": 4,
      "y": -34,
      "z": 18,
      "name": "Rock_Sandstone_Brick"
    },
    {
      "x": 4,
      "y": -33,
      "z": 18,
      "name": "Rock_Sandstone"
    },
    {
      "x": 4,
      "y": -32,
      "z": 18,
      "name": "Rock_Sandstone_Brick"
    },
    {
      "x": 4,
      "y": -31,
      "z": 18,
      "name": "Rock_Sandstone_Brick"
    },
    {
      "x": 4,
      "y": -30,
      "z": 18,
      "name": "Rock_Sandstone_Brick"
    },
    {
      "x": 4,
      "y": -29,
      "z": 18,
      "name": "Rock_Sandstone_Brick"
    },
    {
      "x": 4,
      "y": -28,
      "z": 18,
      "name": "Rock_Sandstone_Brick"
    },
    {
      "x": 4,
      "y": -27,
      "z": 18,
      "name": "Rock_Sandstone"
    },
    {
      "x": 4,
      "y": -26,
      "z": 18,
      "name": "Rock_Sandstone_Brick"
    },
    {
      "x": 4,
      "y": -25,
      "z": 18,
      "name": "Rock_Sandstone_Brick"
    },
    {
      "x": 4,
      "y": -24,
      "z": 18,
      "name": "Rock_Sandstone_Brick"
    },
    {
      "x": 4,
      "y": -23,
      "z": 18,
      "name": "Rock_Sandstone_Brick",
      "rotation": 1
    },
    {
      "x": 4,
      "y": -22,
      "z": 18,
      "name": "Rock_Sandstone_Brick",
      "rotation": 1
    },
    {
      "x": 4,
      "y": -21,
      "z": 18,
      "name": "Rock_Sandstone_Brick",
      "rotation": 1
    },
    {
      "x": 4,
      "y": -34,
      "z": 19,
      "name": "Rock_Sandstone"
    },
    {
      "x": 4,
      "y": -33,
      "z": 19,
      "name": "Rock_Sandstone_Cobble"
    },
    {
      "x": 4,
      "y": -32,
      "z": 19,
      "name": "Rock_Sandstone_Brick"
    },
    {
      "x": 4,
      "y": -31,
      "z": 19,
      "name": "Rock_Sandstone_Brick"
    },
    {
      "x": 4,
      "y": -30,
      "z": 19,
      "name": "Rock_Sandstone_Brick"
    },
    {
      "x": 4,
      "y": -29,
      "z": 19,
      "name": "Rock_Sandstone_Cobble"
    },
    {
      "x": 4,
      "y": -28,
      "z": 19,
      "name": "Rock_Sandstone_Brick"
    },
    {
      "x": 4,
      "y": -27,
      "z": 19,
      "name": "Rock_Sandstone"
    },
    {
      "x": 4,
      "y": -26,
      "z": 19,
      "name": "Rock_Sandstone"
    },
    {
      "x": 4,
      "y": -25,
      "z": 19,
      "name": "Rock_Sandstone"
    },
    {
      "x": 4,
      "y": -24,
      "z": 19,
      "name": "Rock_Sandstone_Brick"
    },
    {
      "x": 4,
      "y": -23,
      "z": 19,
      "name": "Rock_Sandstone_Brick",
      "rotation": 1
    },
    {
      "x": 4,
      "y": -22,
      "z": 19,
      "name": "Rock_Sandstone_Brick",
      "rotation": 1
    },
    {
      "x": 4,
      "y": -21,
      "z": 19,
      "name": "Rock_Sandstone_Brick",
      "rotation": 1
    },
    {
      "x": 5,
      "y": -34,
      "z": 2,
      "name": "Rock_Sandstone_Brick"
    },
    {
      "x": 5,
      "y": -33,
      "z": 2,
      "name": "Rock_Sandstone_Brick"
    },
    {
      "x": 5,
      "y": -32,
      "z": 2,
      "name": "Rock_Sandstone_Brick"
    },
    {
      "x": 5,
      "y": -31,
      "z": 2,
      "name": "Rock_Sandstone_Brick"
    },
    {
      "x": 5,
      "y": -30,
      "z": 2,
      "name": "Rock_Sandstone"
    },
    {
      "x": 5,
      "y": -29,
      "z": 2,
      "name": "Rock_Sandstone_Brick"
    },
    {
      "x": 5,
      "y": -28,
      "z": 2,
      "name": "Rock_Sandstone_Brick"
    },
    {
      "x": 5,
      "y": -27,
      "z": 2,
      "name": "Rock_Sandstone_Brick"
    },
    {
      "x": 5,
      "y": -26,
      "z": 2,
      "name": "Rock_Sandstone_Brick"
    },
    {
      "x": 5,
      "y": -25,
      "z": 2,
      "name": "Rock_Sandstone_Brick"
    },
    {
      "x": 5,
      "y": -24,
      "z": 2,
      "name": "Rock_Sandstone_Brick",
      "rotation": 3
    },
    {
      "x": 5,
      "y": -23,
      "z": 2,
      "name": "Rock_Sandstone_Brick",
      "rotation": 3
    },
    {
      "x": 5,
      "y": -22,
      "z": 2,
      "name": "Rock_Sandstone",
      "rotation": 3
    },
    {
      "x": 5,
      "y": -34,
      "z": 3,
      "name": "Rock_Sandstone_Brick"
    },
    {
      "x": 5,
      "y": -33,
      "z": 3,
      "name": "Rock_Sandstone"
    },
    {
      "x": 5,
      "y": -32,
      "z": 3,
      "name": "Rock_Sandstone_Brick"
    },
    {
      "x": 5,
      "y": -31,
      "z": 3,
      "name": "Rock_Sandstone_Brick"
    },
    {
      "x": 5,
      "y": -30,
      "z": 3,
      "name": "Rock_Sandstone"
    },
    {
      "x": 5,
      "y": -29,
      "z": 3,
      "name": "Rock_Sandstone_Brick"
    },
    {
      "x": 5,
      "y": -28,
      "z": 3,
      "name": "Rock_Sandstone_Cobble"
    },
    {
      "x": 5,
      "y": -27,
      "z": 3,
      "name": "Rock_Sandstone_Brick"
    },
    {
      "x": 5,
      "y": -26,
      "z": 3,
      "name": "Rock_Sandstone_Brick"
    },
    {
      "x": 5,
      "y": -25,
      "z": 3,
      "name": "Rock_Sandstone_Brick"
    },
    {
      "x": 5,
      "y": -24,
      "z": 3,
      "name": "Rock_Sandstone_Brick",
      "rotation": 3
    },
    {
      "x": 5,
      "y": -34,
      "z": 18,
      "name": "Rock_Sandstone_Brick"
    },
    {
      "x": 5,
      "y": -33,
      "z": 18,
      "name": "Rock_Sandstone_Brick"
    },
    {
      "x": 5,
      "y": -32,
      "z": 18,
      "name": "Rock_Sandstone_Brick"
    },
    {
      "x": 5,
      "y": -31,
      "z": 18,
      "name": "Rock_Sandstone_Cobble"
    },
    {
      "x": 5,
      "y": -30,
      "z": 18,
      "name": "Rock_Sandstone"
    },
    {
      "x": 5,
      "y": -29,
      "z": 18,
      "name": "Rock_Sandstone_Cobble"
    },
    {
      "x": 5,
      "y": -28,
      "z": 18,
      "name": "Rock_Sandstone_Cobble"
    },
    {
      "x": 5,
      "y": -27,
      "z": 18,
      "name": "Rock_Sandstone_Brick"
    },
    {
      "x": 5,
      "y": -26,
      "z": 18,
      "name": "Rock_Sandstone_Brick"
    },
    {
      "x": 5,
      "y": -25,
      "z": 18,
      "name": "Rock_Sandstone_Brick"
    },
    {
      "x": 5,
      "y": -24,
      "z": 18,
      "name": "Rock_Sandstone_Brick"
    },
    {
      "x": 5,
      "y": -23,
      "z": 18,
      "name": "Rock_Sandstone_Cobble",
      "rotation": 1
    },
    {
      "x": 5,
      "y": -22,
      "z": 18,
      "name": "Rock_Sandstone_Brick",
      "rotation": 1
    },
    {
      "x": 5,
      "y": -34,
      "z": 19,
      "name": "Rock_Sandstone_Cobble"
    },
    {
      "x": 5,
      "y": -33,
      "z": 19,
      "name": "Rock_Sandstone_Brick"
    },
    {
      "x": 5,
      "y": -32,
      "z": 19,
      "name": "Rock_Sandstone_Brick"
    },
    {
      "x": 5,
      "y": -31,
      "z": 19,
      "name": "Rock_Sandstone_Brick"
    },
    {
      "x": 5,
      "y": -30,
      "z": 19,
      "name": "Rock_Sandstone"
    },
    {
      "x": 5,
      "y": -29,
      "z": 19,
      "name": "Rock_Sandstone_Cobble"
    },
    {
      "x": 5,
      "y": -28,
      "z": 19,
      "name": "Rock_Sandstone_Cobble"
    },
    {
      "x": 5,
      "y": -27,
      "z": 19,
      "name": "Rock_Sandstone_Cobble"
    },
    {
      "x": 5,
      "y": -26,
      "z": 19,
      "name": "Rock_Sandstone_Brick"
    },
    {
      "x": 5,
      "y": -25,
      "z": 19,
      "name": "Rock_Sandstone_Brick"
    },
    {
      "x": 5,
      "y": -24,
      "z": 19,
      "name": "Rock_Sandstone"
    },
    {
      "x": 5,
      "y": -23,
      "z": 19,
      "name": "Rock_Sandstone",
      "rotation": 1
    },
    {
      "x": 5,
      "y": -22,
      "z": 19,
      "name": "Rock_Sandstone_Cobble",
      "rotation": 1
    },
    {
      "x": 5,
      "y": -21,
      "z": 19,
      "name": "Rock_Sandstone_Brick",
      "rotation": 1
    },
    {
      "x": 7,
      "y": -34,
      "z": 10,
      "name": "Rock_Sandstone_Brick"
    },
    {
      "x": 7,
      "y": -33,
      "z": 10,
      "name": "Rock_Sandstone_Brick"
    },
    {
      "x": 7,
      "y": -32,
      "z": 10,
      "name": "Rock_Sandstone_Cobble"
    },
    {
      "x": 7,
      "y": -31,
      "z": 10,
      "name": "Rock_Sandstone_Brick"
    },
    {
      "x": 7,
      "y": -30,
      "z": 10,
      "name": "Rock_Sandstone_Brick"
    },
    {
      "x": 7,
      "y": -29,
      "z": 10,
      "name": "Rock_Sandstone"
    },
    {
      "x": 7,
      "y": -28,
      "z": 10,
      "name": "Rock_Sandstone_Brick"
    },
    {
      "x": 7,
      "y": -27,
      "z": 10,
      "name": "Rock_Sandstone_Brick"
    },
    {
      "x": 7,
      "y": -26,
      "z": 10,
      "name": "Rock_Sandstone_Brick"
    },
    {
      "x": 7,
      "y": -25,
      "z": 10,
      "name": "Rock_Sandstone_Cobble"
    },
    {
      "x": 7,
      "y": -24,
      "z": 10,
      "name": "Rock_Sandstone"
    },
    {
      "x": 7,
      "y": -23,
      "z": 10,
      "name": "Rock_Sandstone_Brick",
      "rotation": 1
    },
    {
      "x": 7,
      "y": -22,
      "z": 10,
      "name": "Rock_Sandstone",
      "rotation": 1
    },
    {
      "x": 7,
      "y": -34,
      "z": 11,
      "name": "Rock_Sandstone"
    },
    {
      "x": 7,
      "y": -33,
      "z": 11,
      "name": "Rock_Sandstone"
    },
    {
      "x": 7,
      "y": -32,
      "z": 11,
      "name": "Rock_Sandstone"
    },
    {
      "x": 7,
      "y": -31,
      "z": 11,
      "name": "Rock_Sandstone_Brick"
    },
    {
      "x": 7,
      "y": -30,
      "z": 11,
      "name": "Rock_Sandstone_Brick"
    },
    {
      "x": 7,
      "y": -29,
      "z": 11,
      "name": "Rock_Sandstone_Brick"
    },
    {
      "x": 7,
      "y": -28,
      "z": 11,
      "name": "Rock_Sandstone_Brick"
    },
    {
      "x": 7,
      "y": -27,
      "z": 11,
      "name": "Rock_Sandstone_Brick"
    },
    {
      "x": 7,
      "y": -26,
      "z": 11,
      "name": "Rock_Sandstone_Brick"
    },
    {
      "x": 7,
      "y": -25,
      "z": 11,
      "name": "Rock_Sandstone_Brick"
    },
    {
      "x": 7,
      "y": -24,
      "z": 11,
      "name": "Rock_Sandstone"
    },
    {
      "x": 7,
      "y": -23,
      "z": 11,
      "name": "Rock_Sandstone_Brick",
      "rotation": 1
    },
    {
      "x": 7,
      "y": -22,
      "z": 11,
      "name": "Rock_Sandstone_Brick",
      "rotation": 1
    },
    {
      "x": 8,
      "y": -34,
      "z": 9,
      "name": "Rock_Sandstone"
    },
    {
      "x": 8,
      "y": -33,
      "z": 9,
      "name": "Rock_Sandstone_Brick"
    },
    {
      "x": 8,
      "y": -32,
      "z": 9,
      "name": "Rock_Sandstone_Brick"
    },
    {
      "x": 8,
      "y": -31,
      "z": 9,
      "name": "Rock_Sandstone_Brick"
    },
    {
      "x": 8,
      "y": -30,
      "z": 9,
      "name": "Rock_Sandstone"
    },
    {
      "x": 8,
      "y": -29,
      "z": 9,
      "name": "Rock_Sandstone_Cobble"
    },
    {
      "x": 8,
      "y": -28,
      "z": 9,
      "name": "Rock_Sandstone"
    },
    {
      "x": 8,
      "y": -27,
      "z": 9,
      "name": "Rock_Sandstone_Brick"
    },
    {
      "x": 8,
      "y": -26,
      "z": 9,
      "name": "Rock_Sandstone"
    },
    {
      "x": 8,
      "y": -25,
      "z": 9,
      "name": "Rock_Sandstone_Brick"
    },
    {
      "x": 8,
      "y": -24,
      "z": 9,
      "name": "Rock_Sandstone"
    },
    {
      "x": 8,
      "y": -23,
      "z": 9,
      "name": "Rock_Sandstone"
    },
    {
      "x": 8,
      "y": -22,
      "z": 9,
      "name": "Rock_Sandstone_Brick"
    },
    {
      "x": 8,
      "y": -34,
      "z": 10,
      "name": "Rock_Sandstone_Brick"
    },
    {
      "x": 8,
      "y": -33,
      "z": 10,
      "name": "Rock_Sandstone_Cobble"
    },
    {
      "x": 8,
      "y": -32,
      "z": 10,
      "name": "Rock_Sandstone_Brick"
    },
    {
      "x": 8,
      "y": -31,
      "z": 10,
      "name": "Rock_Sandstone_Brick"
    },
    {
      "x": 8,
      "y": -30,
      "z": 10,
      "name": "Rock_Sandstone_Brick"
    },
    {
      "x": 8,
      "y": -29,
      "z": 10,
      "name": "Rock_Sandstone_Cobble"
    },
    {
      "x": 8,
      "y": -28,
      "z": 10,
      "name": "Rock_Sandstone_Brick"
    },
    {
      "x": 8,
      "y": -27,
      "z": 10,
      "name": "Rock_Sandstone_Brick"
    },
    {
      "x": 8,
      "y": -26,
      "z": 10,
      "name": "Rock_Sandstone_Brick"
    },
    {
      "x": 8,
      "y": -25,
      "z": 10,
      "name": "Rock_Sandstone_Brick"
    },
    {
      "x": 8,
      "y": -24,
      "z": 10,
      "name": "Rock_Sandstone_Cobble"
    },
    {
      "x": 8,
      "y": -23,
      "z": 10,
      "name": "Rock_Sandstone",
      "rotation": 1
    },
    {
      "x": 8,
      "y": -22,
      "z": 10,
      "name": "Rock_Sandstone_Brick",
      "rotation": 1
    },
    {
      "x": 8,
      "y": -34,
      "z": 11,
      "name": "Rock_Sandstone_Brick"
    },
    {
      "x": 8,
      "y": -33,
      "z": 11,
      "name": "Rock_Sandstone"
    },
    {
      "x": 8,
      "y": -32,
      "z": 11,
      "name": "Rock_Sandstone_Brick"
    },
    {
      "x": 8,
      "y": -31,
      "z": 11,
      "name": "Rock_Sandstone"
    },
    {
      "x": 8,
      "y": -30,
      "z": 11,
      "name": "Rock_Sandstone_Brick"
    },
    {
      "x": 8,
      "y": -29,
      "z": 11,
      "name": "Rock_Sandstone"
    },
    {
      "x": 8,
      "y": -28,
      "z": 11,
      "name": "Rock_Sandstone_Cobble"
    },
    {
      "x": 8,
      "y": -27,
      "z": 11,
      "name": "Rock_Sandstone"
    },
    {
      "x": 8,
      "y": -26,
      "z": 11,
      "name": "Rock_Sandstone"
    },
    {
      "x": 8,
      "y": -25,
      "z": 11,
      "name": "Rock_Sandstone_Cobble"
    },
    {
      "x": 8,
      "y": -24,
      "z": 11,
      "name": "Rock_Sandstone_Brick"
    },
    {
      "x": 8,
      "y": -23,
      "z": 11,
      "name": "Rock_Sandstone_Brick",
      "rotation": 1
    },
    {
      "x": 8,
      "y": -22,
      "z": 11,
      "name": "Rock_Sandstone",
      "rotation": 1
    },
    {
      "x": 8,
      "y": -34,
      "z": 12,
      "name": "Rock_Sandstone_Brick"
    },
    {
      "x": 8,
      "y": -33,
      "z": 12,
      "name": "Rock_Sandstone_Brick"
    },
    {
      "x": 8,
      "y": -32,
      "z": 12,
      "name": "Rock_Sandstone_Brick"
    },
    {
      "x": 8,
      "y": -31,
      "z": 12,
      "name": "Rock_Sandstone_Cobble"
    },
    {
      "x": 8,
      "y": -30,
      "z": 12,
      "name": "Rock_Sandstone_Brick"
    },
    {
      "x": 8,
      "y": -29,
      "z": 12,
      "name": "Rock_Sandstone_Brick"
    },
    {
      "x": 8,
      "y": -28,
      "z": 12,
      "name": "Rock_Sandstone_Cobble"
    },
    {
      "x": 8,
      "y": -27,
      "z": 12,
      "name": "Rock_Sandstone"
    },
    {
      "x": 8,
      "y": -26,
      "z": 12,
      "name": "Rock_Sandstone_Brick"
    },
    {
      "x": 8,
      "y": -25,
      "z": 12,
      "name": "Rock_Sandstone_Cobble"
    },
    {
      "x": 8,
      "y": -24,
      "z": 12,
      "name": "Rock_Sandstone_Brick"
    },
    {
      "x": 8,
      "y": -23,
      "z": 12,
      "name": "Rock_Sandstone_Brick"
    },
    {
      "x": 8,
      "y": -22,
      "z": 12,
      "name": "Rock_Sandstone_Brick"
    },
    {
      "x": 9,
      "y": -34,
      "z": 8,
      "name": "Rock_Sandstone_Brick"
    },
    {
      "x": 9,
      "y": -33,
      "z": 8,
      "name": "Rock_Sandstone_Brick"
    },
    {
      "x": 9,
      "y": -32,
      "z": 8,
      "name": "Rock_Sandstone_Brick"
    },
    {
      "x": 9,
      "y": -31,
      "z": 8,
      "name": "Rock_Sandstone_Cobble"
    },
    {
      "x": 9,
      "y": -30,
      "z": 8,
      "name": "Rock_Sandstone_Brick"
    },
    {
      "x": 9,
      "y": -29,
      "z": 8,
      "name": "Rock_Sandstone_Brick"
    },
    {
      "x": 9,
      "y": -28,
      "z": 8,
      "name": "Rock_Sandstone_Brick"
    },
    {
      "x": 9,
      "y": -27,
      "z": 8,
      "name": "Rock_Sandstone_Brick"
    },
    {
      "x": 9,
      "y": -26,
      "z": 8,
      "name": "Rock_Sandstone_Cobble"
    },
    {
      "x": 9,
      "y": -25,
      "z": 8,
      "name": "Rock_Sandstone_Brick"
    },
    {
      "x": 9,
      "y": -24,
      "z": 8,
      "name": "Rock_Sandstone"
    },
    {
      "x": 9,
      "y": -23,
      "z": 8,
      "name": "Rock_Sandstone_Cobble"
    },
    {
      "x": 9,
      "y": -22,
      "z": 8,
      "name": "Rock_Sandstone_Brick"
    },
    {
      "x": 9,
      "y": -34,
      "z": 9,
      "name": "Rock_Sandstone_Brick"
    },
    {
      "x": 9,
      "y": -33,
      "z": 9,
      "name": "Rock_Sandstone_Brick"
    },
    {
      "x": 9,
      "y": -32,
      "z": 9,
      "name": "Rock_Sandstone_Brick"
    },
    {
      "x": 9,
      "y": -31,
      "z": 9,
      "name": "Rock_Sandstone_Brick"
    },
    {
      "x": 9,
      "y": -30,
      "z": 9,
      "name": "Rock_Sandstone_Cobble"
    },
    {
      "x": 9,
      "y": -29,
      "z": 9,
      "name": "Rock_Sandstone_Brick"
    },
    {
      "x": 9,
      "y": -28,
      "z": 9,
      "name": "Rock_Sandstone_Brick"
    },
    {
      "x": 9,
      "y": -27,
      "z": 9,
      "name": "Rock_Sandstone_Cobble"
    },
    {
      "x": 9,
      "y": -26,
      "z": 9,
      "name": "Rock_Sandstone_Brick"
    },
    {
      "x": 9,
      "y": -25,
      "z": 9,
      "name": "Rock_Sandstone_Brick"
    },
    {
      "x": 9,
      "y": -24,
      "z": 9,
      "name": "Rock_Sandstone_Brick"
    },
    {
      "x": 9,
      "y": -23,
      "z": 9,
      "name": "Rock_Sandstone"
    },
    {
      "x": 9,
      "y": -22,
      "z": 9,
      "name": "Rock_Sandstone_Brick"
    },
    {
      "x": 9,
      "y": -21,
      "z": 9,
      "name": "Rock_Sandstone_Cobble"
    },
    {
      "x": 9,
      "y": -34,
      "z": 10,
      "name": "Rock_Sandstone"
    },
    {
      "x": 9,
      "y": -33,
      "z": 10,
      "name": "Rock_Sandstone_Cobble"
    },
    {
      "x": 9,
      "y": -32,
      "z": 10,
      "name": "Rock_Sandstone_Brick"
    },
    {
      "x": 9,
      "y": -31,
      "z": 10,
      "name": "Rock_Sandstone_Brick"
    },
    {
      "x": 9,
      "y": -30,
      "z": 10,
      "name": "Rock_Sandstone_Brick"
    },
    {
      "x": 9,
      "y": -29,
      "z": 10,
      "name": "Rock_Sandstone_Cobble"
    },
    {
      "x": 9,
      "y": -28,
      "z": 10,
      "name": "Rock_Sandstone"
    },
    {
      "x": 9,
      "y": -27,
      "z": 10,
      "name": "Rock_Sandstone_Brick"
    },
    {
      "x": 9,
      "y": -26,
      "z": 10,
      "name": "Rock_Sandstone_Brick"
    },
    {
      "x": 9,
      "y": -25,
      "z": 10,
      "name": "Rock_Sandstone_Brick"
    },
    {
      "x": 9,
      "y": -24,
      "z": 10,
      "name": "Rock_Sandstone_Brick"
    },
    {
      "x": 9,
      "y": -23,
      "z": 10,
      "name": "Rock_Sandstone_Cobble"
    },
    {
      "x": 9,
      "y": -22,
      "z": 10,
      "name": "Rock_Sandstone_Brick"
    },
    {
      "x": 9,
      "y": -34,
      "z": 11,
      "name": "Rock_Sandstone_Brick"
    },
    {
      "x": 9,
      "y": -33,
      "z": 11,
      "name": "Rock_Sandstone_Cobble"
    },
    {
      "x": 9,
      "y": -32,
      "z": 11,
      "name": "Rock_Sandstone_Brick"
    },
    {
      "x": 9,
      "y": -31,
      "z": 11,
      "name": "Rock_Sandstone_Cobble"
    },
    {
      "x": 9,
      "y": -30,
      "z": 11,
      "name": "Rock_Sandstone"
    },
    {
      "x": 9,
      "y": -29,
      "z": 11,
      "name": "Rock_Sandstone_Brick"
    },
    {
      "x": 9,
      "y": -28,
      "z": 11,
      "name": "Rock_Sandstone_Brick"
    },
    {
      "x": 9,
      "y": -27,
      "z": 11,
      "name": "Rock_Sandstone"
    },
    {
      "x": 9,
      "y": -26,
      "z": 11,
      "name": "Rock_Sandstone_Cobble"
    },
    {
      "x": 9,
      "y": -25,
      "z": 11,
      "name": "Rock_Sandstone_Brick"
    },
    {
      "x": 9,
      "y": -24,
      "z": 11,
      "name": "Rock_Sandstone"
    },
    {
      "x": 9,
      "y": -23,
      "z": 11,
      "name": "Rock_Sandstone_Cobble"
    },
    {
      "x": 9,
      "y": -22,
      "z": 11,
      "name": "Rock_Sandstone"
    },
    {
      "x": 9,
      "y": -34,
      "z": 12,
      "name": "Rock_Sandstone_Brick"
    },
    {
      "x": 9,
      "y": -33,
      "z": 12,
      "name": "Rock_Sandstone"
    },
    {
      "x": 9,
      "y": -32,
      "z": 12,
      "name": "Rock_Sandstone_Brick"
    },
    {
      "x": 9,
      "y": -31,
      "z": 12,
      "name": "Rock_Sandstone_Cobble"
    },
    {
      "x": 9,
      "y": -30,
      "z": 12,
      "name": "Rock_Sandstone_Brick"
    },
    {
      "x": 9,
      "y": -29,
      "z": 12,
      "name": "Rock_Sandstone"
    },
    {
      "x": 9,
      "y": -28,
      "z": 12,
      "name": "Rock_Sandstone_Brick"
    },
    {
      "x": 9,
      "y": -27,
      "z": 12,
      "name": "Rock_Sandstone_Brick"
    },
    {
      "x": 9,
      "y": -26,
      "z": 12,
      "name": "Rock_Sandstone_Brick"
    },
    {
      "x": 9,
      "y": -25,
      "z": 12,
      "name": "Rock_Sandstone_Brick"
    },
    {
      "x": 9,
      "y": -24,
      "z": 12,
      "name": "Rock_Sandstone_Cobble"
    },
    {
      "x": 9,
      "y": -23,
      "z": 12,
      "name": "Rock_Sandstone_Cobble"
    },
    {
      "x": 9,
      "y": -22,
      "z": 12,
      "name": "Rock_Sandstone"
    },
    {
      "x": 9,
      "y": -34,
      "z": 13,
      "name": "Rock_Sandstone"
    },
    {
      "x": 9,
      "y": -33,
      "z": 13,
      "name": "Rock_Sandstone"
    },
    {
      "x": 9,
      "y": -32,
      "z": 13,
      "name": "Rock_Sandstone_Brick"
    },
    {
      "x": 9,
      "y": -31,
      "z": 13,
      "name": "Rock_Sandstone"
    },
    {
      "x": 9,
      "y": -30,
      "z": 13,
      "name": "Rock_Sandstone_Brick"
    },
    {
      "x": 9,
      "y": -29,
      "z": 13,
      "name": "Rock_Sandstone_Cobble"
    },
    {
      "x": 9,
      "y": -28,
      "z": 13,
      "name": "Rock_Sandstone_Brick"
    },
    {
      "x": 9,
      "y": -27,
      "z": 13,
      "name": "Rock_Sandstone"
    },
    {
      "x": 9,
      "y": -26,
      "z": 13,
      "name": "Rock_Sandstone_Brick"
    },
    {
      "x": 9,
      "y": -25,
      "z": 13,
      "name": "Rock_Sandstone_Brick"
    },
    {
      "x": 9,
      "y": -24,
      "z": 13,
      "name": "Rock_Sandstone_Brick"
    },
    {
      "x": 9,
      "y": -23,
      "z": 13,
      "name": "Rock_Sandstone_Brick"
    },
    {
      "x": 9,
      "y": -22,
      "z": 13,
      "name": "Rock_Sandstone_Cobble"
    },
    {
      "x": 10,
      "y": -34,
      "z": 7,
      "name": "Rock_Sandstone_Brick"
    },
    {
      "x": 10,
      "y": -33,
      "z": 7,
      "name": "Rock_Sandstone_Brick"
    },
    {
      "x": 10,
      "y": -32,
      "z": 7,
      "name": "Rock_Sandstone_Brick"
    },
    {
      "x": 10,
      "y": -31,
      "z": 7,
      "name": "Rock_Sandstone_Cobble"
    },
    {
      "x": 10,
      "y": -30,
      "z": 7,
      "name": "Rock_Sandstone_Brick"
    },
    {
      "x": 10,
      "y": -29,
      "z": 7,
      "name": "Rock_Sandstone"
    },
    {
      "x": 10,
      "y": -28,
      "z": 7,
      "name": "Rock_Sandstone_Brick"
    },
    {
      "x": 10,
      "y": -27,
      "z": 7,
      "name": "Rock_Sandstone_Brick"
    },
    {
      "x": 10,
      "y": -26,
      "z": 7,
      "name": "Rock_Sandstone_Brick"
    },
    {
      "x": 10,
      "y": -25,
      "z": 7,
      "name": "Rock_Sandstone_Brick"
    },
    {
      "x": 10,
      "y": -24,
      "z": 7,
      "name": "Rock_Sandstone_Brick"
    },
    {
      "x": 10,
      "y": -23,
      "z": 7,
      "name": "Rock_Sandstone_Cobble"
    },
    {
      "x": 10,
      "y": -34,
      "z": 8,
      "name": "Rock_Sandstone"
    },
    {
      "x": 10,
      "y": -33,
      "z": 8,
      "name": "Rock_Sandstone_Brick"
    },
    {
      "x": 10,
      "y": -32,
      "z": 8,
      "name": "Rock_Sandstone_Cobble"
    },
    {
      "x": 10,
      "y": -31,
      "z": 8,
      "name": "Rock_Sandstone"
    },
    {
      "x": 10,
      "y": -30,
      "z": 8,
      "name": "Rock_Sandstone"
    },
    {
      "x": 10,
      "y": -29,
      "z": 8,
      "name": "Rock_Sandstone_Brick"
    },
    {
      "x": 10,
      "y": -28,
      "z": 8,
      "name": "Rock_Sandstone_Brick"
    },
    {
      "x": 10,
      "y": -27,
      "z": 8,
      "name": "Rock_Sandstone_Brick"
    },
    {
      "x": 10,
      "y": -26,
      "z": 8,
      "name": "Rock_Sandstone"
    },
    {
      "x": 10,
      "y": -25,
      "z": 8,
      "name": "Rock_Sandstone_Brick"
    },
    {
      "x": 10,
      "y": -24,
      "z": 8,
      "name": "Rock_Sandstone_Brick"
    },
    {
      "x": 10,
      "y": -23,
      "z": 8,
      "name": "Rock_Sandstone_Cobble"
    },
    {
      "x": 10,
      "y": -22,
      "z": 8,
      "name": "Rock_Sandstone_Brick"
    },
    {
      "x": 10,
      "y": -34,
      "z": 9,
      "name": "Rock_Sandstone"
    },
    {
      "x": 10,
      "y": -33,
      "z": 9,
      "name": "Rock_Sandstone_Cobble"
    },
    {
      "x": 10,
      "y": -32,
      "z": 9,
      "name": "Rock_Sandstone"
    },
    {
      "x": 10,
      "y": -31,
      "z": 9,
      "name": "Rock_Sandstone"
    },
    {
      "x": 10,
      "y": -30,
      "z": 9,
      "name": "Rock_Sandstone_Brick"
    },
    {
      "x": 10,
      "y": -29,
      "z": 9,
      "name": "Rock_Sandstone"
    },
    {
      "x": 10,
      "y": -28,
      "z": 9,
      "name": "Rock_Sandstone_Cobble"
    },
    {
      "x": 10,
      "y": -27,
      "z": 9,
      "name": "Rock_Sandstone"
    },
    {
      "x": 10,
      "y": -26,
      "z": 9,
      "name": "Rock_Sandstone_Brick"
    },
    {
      "x": 10,
      "y": -25,
      "z": 9,
      "name": "Rock_Sandstone"
    },
    {
      "x": 10,
      "y": -24,
      "z": 9,
      "name": "Rock_Sandstone"
    },
    {
      "x": 10,
      "y": -23,
      "z": 9,
      "name": "Rock_Sandstone"
    },
    {
      "x": 10,
      "y": -22,
      "z": 9,
      "name": "Rock_Sandstone_Brick"
    },
    {
      "x": 10,
      "y": -34,
      "z": 10,
      "name": "Rock_Sandstone_Brick"
    },
    {
      "x": 10,
      "y": -33,
      "z": 10,
      "name": "Rock_Sandstone_Brick"
    },
    {
      "x": 10,
      "y": -32,
      "z": 10,
      "name": "Rock_Sandstone_Brick"
    },
    {
      "x": 10,
      "y": -31,
      "z": 10,
      "name": "Rock_Sandstone_Cobble"
    },
    {
      "x": 10,
      "y": -30,
      "z": 10,
      "name": "Rock_Sandstone_Brick"
    },
    {
      "x": 10,
      "y": -29,
      "z": 10,
      "name": "Rock_Sandstone_Brick"
    },
    {
      "x": 10,
      "y": -28,
      "z": 10,
      "name": "Rock_Sandstone_Brick"
    },
    {
      "x": 10,
      "y": -27,
      "z": 10,
      "name": "Rock_Sandstone"
    },
    {
      "x": 10,
      "y": -26,
      "z": 10,
      "name": "Rock_Sandstone"
    },
    {
      "x": 10,
      "y": -25,
      "z": 10,
      "name": "Rock_Sandstone_Cobble"
    },
    {
      "x": 10,
      "y": -24,
      "z": 10,
      "name": "Rock_Sandstone"
    },
    {
      "x": 10,
      "y": -23,
      "z": 10,
      "name": "Rock_Sandstone"
    },
    {
      "x": 10,
      "y": -22,
      "z": 10,
      "name": "Rock_Sandstone"
    },
    {
      "x": 10,
      "y": -34,
      "z": 11,
      "name": "Rock_Sandstone_Brick"
    },
    {
      "x": 10,
      "y": -33,
      "z": 11,
      "name": "Rock_Sandstone_Brick"
    },
    {
      "x": 10,
      "y": -32,
      "z": 11,
      "name": "Rock_Sandstone"
    },
    {
      "x": 10,
      "y": -31,
      "z": 11,
      "name": "Rock_Sandstone_Cobble"
    },
    {
      "x": 10,
      "y": -30,
      "z": 11,
      "name": "Rock_Sandstone_Cobble"
    },
    {
      "x": 10,
      "y": -29,
      "z": 11,
      "name": "Rock_Sandstone_Cobble"
    },
    {
      "x": 10,
      "y": -28,
      "z": 11,
      "name": "Rock_Sandstone_Cobble"
    },
    {
      "x": 10,
      "y": -27,
      "z": 11,
      "name": "Rock_Sandstone"
    },
    {
      "x": 10,
      "y": -26,
      "z": 11,
      "name": "Rock_Sandstone_Brick"
    },
    {
      "x": 10,
      "y": -25,
      "z": 11,
      "name": "Rock_Sandstone_Brick"
    },
    {
      "x": 10,
      "y": -24,
      "z": 11,
      "name": "Rock_Sandstone_Brick"
    },
    {
      "x": 10,
      "y": -23,
      "z": 11,
      "name": "Rock_Sandstone_Brick"
    },
    {
      "x": 10,
      "y": -22,
      "z": 11,
      "name": "Rock_Sandstone_Cobble"
    },
    {
      "x": 10,
      "y": -34,
      "z": 12,
      "name": "Rock_Sandstone"
    },
    {
      "x": 10,
      "y": -33,
      "z": 12,
      "name": "Rock_Sandstone_Brick"
    },
    {
      "x": 10,
      "y": -32,
      "z": 12,
      "name": "Rock_Sandstone_Cobble"
    },
    {
      "x": 10,
      "y": -31,
      "z": 12,
      "name": "Rock_Sandstone_Brick"
    },
    {
      "x": 10,
      "y": -30,
      "z": 12,
      "name": "Rock_Sandstone_Brick"
    },
    {
      "x": 10,
      "y": -29,
      "z": 12,
      "name": "Rock_Sandstone_Brick"
    },
    {
      "x": 10,
      "y": -28,
      "z": 12,
      "name": "Rock_Sandstone_Brick"
    },
    {
      "x": 10,
      "y": -27,
      "z": 12,
      "name": "Rock_Sandstone_Brick"
    },
    {
      "x": 10,
      "y": -26,
      "z": 12,
      "name": "Rock_Sandstone_Brick"
    },
    {
      "x": 10,
      "y": -25,
      "z": 12,
      "name": "Rock_Sandstone"
    },
    {
      "x": 10,
      "y": -24,
      "z": 12,
      "name": "Rock_Sandstone_Brick"
    },
    {
      "x": 10,
      "y": -23,
      "z": 12,
      "name": "Rock_Sandstone_Brick"
    },
    {
      "x": 10,
      "y": -22,
      "z": 12,
      "name": "Rock_Sandstone_Brick"
    },
    {
      "x": 10,
      "y": -34,
      "z": 13,
      "name": "Rock_Sandstone"
    },
    {
      "x": 10,
      "y": -33,
      "z": 13,
      "name": "Rock_Sandstone_Brick"
    },
    {
      "x": 10,
      "y": -32,
      "z": 13,
      "name": "Rock_Sandstone_Cobble"
    },
    {
      "x": 10,
      "y": -31,
      "z": 13,
      "name": "Rock_Sandstone_Brick"
    },
    {
      "x": 10,
      "y": -30,
      "z": 13,
      "name": "Rock_Sandstone_Brick"
    },
    {
      "x": 10,
      "y": -29,
      "z": 13,
      "name": "Rock_Sandstone_Brick"
    },
    {
      "x": 10,
      "y": -28,
      "z": 13,
      "name": "Rock_Sandstone_Brick"
    },
    {
      "x": 10,
      "y": -27,
      "z": 13,
      "name": "Rock_Sandstone_Brick"
    },
    {
      "x": 10,
      "y": -26,
      "z": 13,
      "name": "Rock_Sandstone_Brick"
    },
    {
      "x": 10,
      "y": -25,
      "z": 13,
      "name": "Rock_Sandstone_Brick"
    },
    {
      "x": 10,
      "y": -24,
      "z": 13,
      "name": "Rock_Sandstone_Brick"
    },
    {
      "x": 10,
      "y": -23,
      "z": 13,
      "name": "Rock_Sandstone_Brick"
    },
    {
      "x": 10,
      "y": -22,
      "z": 13,
      "name": "Rock_Sandstone_Cobble"
    },
    {
      "x": 10,
      "y": -34,
      "z": 14,
      "name": "Rock_Sandstone_Brick"
    },
    {
      "x": 10,
      "y": -33,
      "z": 14,
      "name": "Rock_Sandstone_Cobble"
    },
    {
      "x": 10,
      "y": -32,
      "z": 14,
      "name": "Rock_Sandstone_Brick"
    },
    {
      "x": 10,
      "y": -31,
      "z": 14,
      "name": "Rock_Sandstone"
    },
    {
      "x": 10,
      "y": -30,
      "z": 14,
      "name": "Rock_Sandstone_Brick"
    },
    {
      "x": 10,
      "y": -29,
      "z": 14,
      "name": "Rock_Sandstone_Cobble"
    },
    {
      "x": 10,
      "y": -28,
      "z": 14,
      "name": "Rock_Sandstone_Brick"
    },
    {
      "x": 10,
      "y": -27,
      "z": 14,
      "name": "Rock_Sandstone_Brick"
    },
    {
      "x": 10,
      "y": -26,
      "z": 14,
      "name": "Rock_Sandstone_Brick"
    },
    {
      "x": 10,
      "y": -25,
      "z": 14,
      "name": "Rock_Sandstone_Cobble"
    },
    {
      "x": 10,
      "y": -24,
      "z": 14,
      "name": "Rock_Sandstone_Cobble"
    },
    {
      "x": 10,
      "y": -23,
      "z": 14,
      "name": "Rock_Sandstone_Cobble",
      "rotation": 2
    },
    {
      "x": 10,
      "y": -22,
      "z": 14,
      "name": "Rock_Sandstone",
      "rotation": 2
    },
    {
      "x": 11,
      "y": -34,
      "z": 7,
      "name": "Rock_Sandstone"
    },
    {
      "x": 11,
      "y": -33,
      "z": 7,
      "name": "Rock_Sandstone_Brick"
    },
    {
      "x": 11,
      "y": -32,
      "z": 7,
      "name": "Rock_Sandstone_Brick"
    },
    {
      "x": 11,
      "y": -31,
      "z": 7,
      "name": "Rock_Sandstone_Brick"
    },
    {
      "x": 11,
      "y": -30,
      "z": 7,
      "name": "Rock_Sandstone_Brick"
    },
    {
      "x": 11,
      "y": -29,
      "z": 7,
      "name": "Rock_Sandstone_Brick"
    },
    {
      "x": 11,
      "y": -28,
      "z": 7,
      "name": "Rock_Sandstone_Brick"
    },
    {
      "x": 11,
      "y": -27,
      "z": 7,
      "name": "Rock_Sandstone_Brick"
    },
    {
      "x": 11,
      "y": -26,
      "z": 7,
      "name": "Rock_Sandstone_Brick"
    },
    {
      "x": 11,
      "y": -25,
      "z": 7,
      "name": "Rock_Sandstone_Brick"
    },
    {
      "x": 11,
      "y": -24,
      "z": 7,
      "name": "Rock_Sandstone_Brick"
    },
    {
      "x": 11,
      "y": -34,
      "z": 8,
      "name": "Rock_Sandstone_Cobble"
    },
    {
      "x": 11,
      "y": -33,
      "z": 8,
      "name": "Rock_Sandstone_Brick"
    },
    {
      "x": 11,
      "y": -32,
      "z": 8,
      "name": "Rock_Sandstone_Brick"
    },
    {
      "x": 11,
      "y": -31,
      "z": 8,
      "name": "Rock_Sandstone"
    },
    {
      "x": 11,
      "y": -30,
      "z": 8,
      "name": "Rock_Sandstone_Brick"
    },
    {
      "x": 11,
      "y": -29,
      "z": 8,
      "name": "Rock_Sandstone"
    },
    {
      "x": 11,
      "y": -28,
      "z": 8,
      "name": "Rock_Sandstone_Brick"
    },
    {
      "x": 11,
      "y": -27,
      "z": 8,
      "name": "Rock_Sandstone_Brick"
    },
    {
      "x": 11,
      "y": -26,
      "z": 8,
      "name": "Rock_Sandstone_Brick"
    },
    {
      "x": 11,
      "y": -25,
      "z": 8,
      "name": "Rock_Sandstone_Brick"
    },
    {
      "x": 11,
      "y": -24,
      "z": 8,
      "name": "Rock_Sandstone_Cobble"
    },
    {
      "x": 11,
      "y": -23,
      "z": 8,
      "name": "Rock_Sandstone_Brick"
    },
    {
      "x": 11,
      "y": -34,
      "z": 9,
      "name": "Rock_Sandstone"
    },
    {
      "x": 11,
      "y": -33,
      "z": 9,
      "name": "Rock_Sandstone_Brick"
    },
    {
      "x": 11,
      "y": -32,
      "z": 9,
      "name": "Rock_Sandstone_Cobble"
    },
    {
      "x": 11,
      "y": -31,
      "z": 9,
      "name": "Rock_Sandstone_Brick"
    },
    {
      "x": 11,
      "y": -30,
      "z": 9,
      "name": "Rock_Sandstone"
    },
    {
      "x": 11,
      "y": -29,
      "z": 9,
      "name": "Rock_Sandstone_Brick"
    },
    {
      "x": 11,
      "y": -28,
      "z": 9,
      "name": "Rock_Sandstone_Brick"
    },
    {
      "x": 11,
      "y": -27,
      "z": 9,
      "name": "Rock_Sandstone_Brick"
    },
    {
      "x": 11,
      "y": -26,
      "z": 9,
      "name": "Rock_Sandstone_Brick"
    },
    {
      "x": 11,
      "y": -25,
      "z": 9,
      "name": "Rock_Sandstone_Brick"
    },
    {
      "x": 11,
      "y": -24,
      "z": 9,
      "name": "Rock_Sandstone_Brick"
    },
    {
      "x": 11,
      "y": -23,
      "z": 9,
      "name": "Rock_Sandstone_Cobble"
    },
    {
      "x": 11,
      "y": -22,
      "z": 9,
      "name": "Rock_Sandstone_Cobble"
    },
    {
      "x": 11,
      "y": -34,
      "z": 10,
      "name": "Rock_Sandstone_Brick"
    },
    {
      "x": 11,
      "y": -33,
      "z": 10,
      "name": "Rock_Sandstone_Brick"
    },
    {
      "x": 11,
      "y": -32,
      "z": 10,
      "name": "Rock_Sandstone_Brick"
    },
    {
      "x": 11,
      "y": -31,
      "z": 10,
      "name": "Rock_Sandstone_Brick"
    },
    {
      "x": 11,
      "y": -30,
      "z": 10,
      "name": "Rock_Sandstone"
    },
    {
      "x": 11,
      "y": -29,
      "z": 10,
      "name": "Rock_Sandstone_Brick"
    },
    {
      "x": 11,
      "y": -28,
      "z": 10,
      "name": "Rock_Sandstone_Cobble"
    },
    {
      "x": 11,
      "y": -27,
      "z": 10,
      "name": "Rock_Sandstone_Brick"
    },
    {
      "x": 11,
      "y": -26,
      "z": 10,
      "name": "Rock_Sandstone_Brick"
    },
    {
      "x": 11,
      "y": -25,
      "z": 10,
      "name": "Rock_Sandstone_Brick"
    },
    {
      "x": 11,
      "y": -24,
      "z": 10,
      "name": "Rock_Sandstone"
    },
    {
      "x": 11,
      "y": -23,
      "z": 10,
      "name": "Rock_Sandstone"
    },
    {
      "x": 11,
      "y": -22,
      "z": 10,
      "name": "Rock_Sandstone"
    },
    {
      "x": 11,
      "y": -34,
      "z": 11,
      "name": "Rock_Sandstone_Brick"
    },
    {
      "x": 11,
      "y": -33,
      "z": 11,
      "name": "Rock_Sandstone_Cobble"
    },
    {
      "x": 11,
      "y": -32,
      "z": 11,
      "name": "Rock_Sandstone_Brick"
    },
    {
      "x": 11,
      "y": -31,
      "z": 11,
      "name": "Rock_Sandstone_Brick"
    },
    {
      "x": 11,
      "y": -30,
      "z": 11,
      "name": "Rock_Sandstone_Brick"
    },
    {
      "x": 11,
      "y": -29,
      "z": 11,
      "name": "Rock_Sandstone_Brick"
    },
    {
      "x": 11,
      "y": -28,
      "z": 11,
      "name": "Rock_Sandstone_Brick"
    },
    {
      "x": 11,
      "y": -27,
      "z": 11,
      "name": "Rock_Sandstone_Brick"
    },
    {
      "x": 11,
      "y": -26,
      "z": 11,
      "name": "Rock_Sandstone"
    },
    {
      "x": 11,
      "y": -25,
      "z": 11,
      "name": "Rock_Sandstone_Brick"
    },
    {
      "x": 11,
      "y": -24,
      "z": 11,
      "name": "Rock_Sandstone_Brick"
    },
    {
      "x": 11,
      "y": -23,
      "z": 11,
      "name": "Rock_Sandstone_Cobble"
    },
    {
      "x": 11,
      "y": -22,
      "z": 11,
      "name": "Rock_Sandstone"
    },
    {
      "x": 11,
      "y": -34,
      "z": 12,
      "name": "Rock_Sandstone_Brick"
    },
    {
      "x": 11,
      "y": -33,
      "z": 12,
      "name": "Rock_Sandstone"
    },
    {
      "x": 11,
      "y": -32,
      "z": 12,
      "name": "Rock_Sandstone_Cobble"
    },
    {
      "x": 11,
      "y": -31,
      "z": 12,
      "name": "Rock_Sandstone_Brick"
    },
    {
      "x": 11,
      "y": -30,
      "z": 12,
      "name": "Rock_Sandstone"
    },
    {
      "x": 11,
      "y": -29,
      "z": 12,
      "name": "Rock_Sandstone_Cobble"
    },
    {
      "x": 11,
      "y": -28,
      "z": 12,
      "name": "Rock_Sandstone"
    },
    {
      "x": 11,
      "y": -27,
      "z": 12,
      "name": "Rock_Sandstone_Brick"
    },
    {
      "x": 11,
      "y": -26,
      "z": 12,
      "name": "Rock_Sandstone_Cobble"
    },
    {
      "x": 11,
      "y": -25,
      "z": 12,
      "name": "Rock_Sandstone_Brick"
    },
    {
      "x": 11,
      "y": -24,
      "z": 12,
      "name": "Rock_Sandstone_Brick"
    },
    {
      "x": 11,
      "y": -23,
      "z": 12,
      "name": "Rock_Sandstone_Brick"
    },
    {
      "x": 11,
      "y": -22,
      "z": 12,
      "name": "Rock_Sandstone_Brick"
    },
    {
      "x": 11,
      "y": -34,
      "z": 13,
      "name": "Rock_Sandstone_Brick"
    },
    {
      "x": 11,
      "y": -33,
      "z": 13,
      "name": "Rock_Sandstone"
    },
    {
      "x": 11,
      "y": -32,
      "z": 13,
      "name": "Rock_Sandstone_Brick"
    },
    {
      "x": 11,
      "y": -31,
      "z": 13,
      "name": "Rock_Sandstone"
    },
    {
      "x": 11,
      "y": -30,
      "z": 13,
      "name": "Rock_Sandstone_Brick"
    },
    {
      "x": 11,
      "y": -29,
      "z": 13,
      "name": "Rock_Sandstone_Brick"
    },
    {
      "x": 11,
      "y": -28,
      "z": 13,
      "name": "Rock_Sandstone_Brick"
    },
    {
      "x": 11,
      "y": -27,
      "z": 13,
      "name": "Rock_Sandstone"
    },
    {
      "x": 11,
      "y": -26,
      "z": 13,
      "name": "Rock_Sandstone_Brick"
    },
    {
      "x": 11,
      "y": -25,
      "z": 13,
      "name": "Rock_Sandstone"
    },
    {
      "x": 11,
      "y": -24,
      "z": 13,
      "name": "Rock_Sandstone_Brick"
    },
    {
      "x": 11,
      "y": -23,
      "z": 13,
      "name": "Rock_Sandstone"
    },
    {
      "x": 11,
      "y": -22,
      "z": 13,
      "name": "Rock_Sandstone_Cobble"
    },
    {
      "x": 11,
      "y": -34,
      "z": 14,
      "name": "Rock_Sandstone_Cobble"
    },
    {
      "x": 11,
      "y": -33,
      "z": 14,
      "name": "Rock_Sandstone_Brick"
    },
    {
      "x": 11,
      "y": -32,
      "z": 14,
      "name": "Rock_Sandstone_Cobble"
    },
    {
      "x": 11,
      "y": -31,
      "z": 14,
      "name": "Rock_Sandstone"
    },
    {
      "x": 11,
      "y": -30,
      "z": 14,
      "name": "Rock_Sandstone_Brick"
    },
    {
      "x": 11,
      "y": -29,
      "z": 14,
      "name": "Rock_Sandstone_Brick"
    },
    {
      "x": 11,
      "y": -28,
      "z": 14,
      "name": "Rock_Sandstone"
    },
    {
      "x": 11,
      "y": -27,
      "z": 14,
      "name": "Rock_Sandstone_Brick"
    },
    {
      "x": 11,
      "y": -26,
      "z": 14,
      "name": "Rock_Sandstone_Brick"
    },
    {
      "x": 11,
      "y": -25,
      "z": 14,
      "name": "Rock_Sandstone"
    },
    {
      "x": 11,
      "y": -24,
      "z": 14,
      "name": "Rock_Sandstone"
    },
    {
      "x": 11,
      "y": -23,
      "z": 14,
      "name": "Rock_Sandstone",
      "rotation": 2
    },
    {
      "x": 11,
      "y": -22,
      "z": 14,
      "name": "Rock_Sandstone_Brick",
      "rotation": 2
    },
    {
      "x": 12,
      "y": -34,
      "z": 8,
      "name": "Rock_Sandstone"
    },
    {
      "x": 12,
      "y": -33,
      "z": 8,
      "name": "Rock_Sandstone_Brick"
    },
    {
      "x": 12,
      "y": -32,
      "z": 8,
      "name": "Rock_Sandstone_Brick"
    },
    {
      "x": 12,
      "y": -31,
      "z": 8,
      "name": "Rock_Sandstone_Brick"
    },
    {
      "x": 12,
      "y": -30,
      "z": 8,
      "name": "Rock_Sandstone"
    },
    {
      "x": 12,
      "y": -29,
      "z": 8,
      "name": "Rock_Sandstone_Brick"
    },
    {
      "x": 12,
      "y": -28,
      "z": 8,
      "name": "Rock_Sandstone_Brick"
    },
    {
      "x": 12,
      "y": -27,
      "z": 8,
      "name": "Rock_Sandstone_Cobble"
    },
    {
      "x": 12,
      "y": -26,
      "z": 8,
      "name": "Rock_Sandstone_Brick"
    },
    {
      "x": 12,
      "y": -25,
      "z": 8,
      "name": "Rock_Sandstone_Brick"
    },
    {
      "x": 12,
      "y": -24,
      "z": 8,
      "name": "Rock_Sandstone_Brick"
    },
    {
      "x": 12,
      "y": -34,
      "z": 9,
      "name": "Rock_Sandstone_Cobble"
    },
    {
      "x": 12,
      "y": -33,
      "z": 9,
      "name": "Rock_Sandstone_Brick"
    },
    {
      "x": 12,
      "y": -32,
      "z": 9,
      "name": "Rock_Sandstone_Brick"
    },
    {
      "x": 12,
      "y": -31,
      "z": 9,
      "name": "Rock_Sandstone_Brick"
    },
    {
      "x": 12,
      "y": -30,
      "z": 9,
      "name": "Rock_Sandstone_Brick"
    },
    {
      "x": 12,
      "y": -29,
      "z": 9,
      "name": "Rock_Sandstone_Brick"
    },
    {
      "x": 12,
      "y": -28,
      "z": 9,
      "name": "Rock_Sandstone_Cobble"
    },
    {
      "x": 12,
      "y": -27,
      "z": 9,
      "name": "Rock_Sandstone_Brick"
    },
    {
      "x": 12,
      "y": -26,
      "z": 9,
      "name": "Rock_Sandstone_Cobble"
    },
    {
      "x": 12,
      "y": -25,
      "z": 9,
      "name": "Rock_Sandstone_Brick"
    },
    {
      "x": 12,
      "y": -24,
      "z": 9,
      "name": "Rock_Sandstone_Brick"
    },
    {
      "x": 12,
      "y": -23,
      "z": 9,
      "name": "Rock_Sandstone_Brick"
    },
    {
      "x": 12,
      "y": -22,
      "z": 9,
      "name": "Rock_Sandstone_Brick"
    },
    {
      "x": 12,
      "y": -34,
      "z": 10,
      "name": "Rock_Sandstone"
    },
    {
      "x": 12,
      "y": -33,
      "z": 10,
      "name": "Rock_Sandstone_Cobble"
    },
    {
      "x": 12,
      "y": -32,
      "z": 10,
      "name": "Rock_Sandstone_Brick"
    },
    {
      "x": 12,
      "y": -31,
      "z": 10,
      "name": "Rock_Sandstone_Brick"
    },
    {
      "x": 12,
