{
  "version": 8,
  "blockIdVersion": 11,
  "anchorX": -5,
  "anchorY": 35,
  "anchorZ": 6,
  "blocks": [
    {
      "x": -5,
      "y": 0,
      "z": -4,
      "name": "Rock_Sandstone_Cobble"
    },
    {
      "x": -5,
      "y": 1,
      "z": -4,
      "name": "Rock_Sandstone"
    },
    {
      "x": -5,
      "y": 2,
      "z": -4,
      "name": "Rock_Sandstone_Brick"
    },
    {
      "x": -5,
      "y": 3,
      "z": -4,
      "name": "Rock_Sandstone_Brick"
    },
    {
      "x": -5,
      "y": 4,
      "z": -4,
      "name": "Rock_Sandstone_Brick"
    },
    {
      "x": -5,
      "y": 5,
      "z": -4,
      "name": "Rock_Sandstone_Brick"
    },
    {
      "x": -5,
      "y": 6,
      "z": -4,
      "name": "Rock_Sandstone_Brick"
    },
    {
      "x": -5,
      "y": 7,
      "z": -4,
      "name": "Rock_Sandstone_Brick"
    },
    {
      "x": -5,
      "y": 8,
      "z": -4,
      "name": "Rock_Sandstone"
    },
    {
      "x": -5,
      "y": 9,
      "z": -4,
      "name": "Rock_Sandstone_Brick"
    },
    {
      "x": -5,
      "y": 10,
      "z": -4,
      "name": "Rock_Sandstone_Cobble"
    },
    {
      "x": -5,
      "y": 11,
      "z": -4,
      "name": "Rock_Sandstone_Brick"
    },
    {
      "x": -5,
      "y": 12,
      "z": -4,
      "name": "Rock_Sandstone_Brick"
    },
    {
      "x": -5,
      "y": 13,
      "z": -4,
      "name": "Rock_Sandstone_Cobble"
    },
    {
      "x": -5,
      "y": 14,
      "z": -4,
      "name": "Rock_Sandstone_Brick"
    },
    {
      "x": -5,
      "y": 15,
      "z": -4,
      "name": "Rock_Sandstone_Cobble"
    },
    {
      "x": -5,
      "y": 16,
      "z": -4,
      "name": "Rock_Sandstone_Brick"
    },
    {
      "x": -5,
      "y": 17,
      "z": -4,
      "name": "Rock_Sandstone_Brick"
    },
    {
      "x": -5,
      "y": 18,
      "z": -4,
      "name": "Rock_Sandstone_Brick"
    },
    {
      "x": -5,
      "y": 19,
      "z": -4,
      "name": "Rock_Sandstone_Brick"
    },
    {
      "x": -5,
      "y": 20,
      "z": -4,
      "name": "Rock_Sandstone"
    },
    {
      "x": -5,
      "y": 21,
      "z": -4,
      "name": "Rock_Sandstone_Brick"
    },
    {
      "x": -5,
      "y": 22,
      "z": -4,
      "name": "Rock_Sandstone_Brick"
    },
    {
      "x": -5,
      "y": 23,
      "z": -4,
      "name": "Rock_Sandstone_Brick"
    },
    {
      "x": -5,
      "y": 24,
      "z": -4,
      "name": "Rock_Sandstone_Cobble"
    },
    {
      "x": -5,
      "y": 25,
      "z": -4,
      "name": "Rock_Sandstone_Cobble"
    },
    {
      "x": -5,
      "y": 26,
      "z": -4,
      "name": "Rock_Sandstone"
    },
    {
      "x": -5,
      "y": 27,
      "z": -4,
      "name": "Rock_Sandstone"
    },
    {
      "x": -5,
      "y": 28,
      "z": -4,
      "name": "Rock_Sandstone_Brick"
    },
    {
      "x": -5,
      "y": 29,
      "z": -4,
      "name": "Rock_Sandstone"
    },
    {
      "x": -5,
      "y": 30,
      "z": -4,
      "name": "Rock_Sandstone"
    },
    {
      "x": -5,
      "y": 31,
      "z": -4,
      "name": "Rock_Sandstone_Cobble"
    },
    {
      "x": -5,
      "y": 32,
      "z": -4,
      "name": "Rock_Sandstone_Brick"
    },
    {
      "x": -5,
      "y": 33,
      "z": -4,
      "name": "Rock_Sandstone_Brick"
    },
    {
      "x": -5,
      "y": 34,
      "z": -4,
      "name": "Rock_Sandstone_Brick"
    },
    {
      "x": -5,
      "y": 35,
      "z": -4,
      "name": "Rock_Sandstone_Brick"
    },
    {
      "x": -5,
      "y": 0,
      "z": -3,
      "name": "Rock_Sandstone"
    },
    {
      "x": -5,
      "y": 1,
      "z": -3,
      "name": "Rock_Sandstone_Brick"
    },
    {
      "x": -5,
      "y": 2,
      "z": -3,
      "name": "Rock_Sandstone"
    },
    {
      "x": -5,
      "y": 3,
      "z": -3,
      "name": "Rock_Sandstone_Cobble"
    },
    {
      "x": -5,
      "y": 4,
      "z": -3,
      "name": "Rock_Sandstone_Brick"
    },
    {
      "x": -5,
      "y": 5,
      "z": -3,
      "name": "Rock_Sandstone_Brick"
    },
    {
      "x": -5,
      "y": 6,
      "z": -3,
      "name": "Rock_Sandstone_Brick"
    },
    {
      "x": -5,
      "y": 7,
      "z": -3,
      "name": "Rock_Sandstone_Cobble"
    },
    {
      "x": -5,
      "y": 8,
      "z": -3,
      "name": "Rock_Sandstone_Brick"
    },
    {
      "x": -5,
      "y": 9,
      "z": -3,
      "name": "Rock_Sandstone_Brick"
    },
    {
      "x": -5,
      "y": 10,
      "z": -3,
      "name": "Rock_Sandstone_Brick"
    },
    {
      "x": -5,
      "y": 11,
      "z": -3,
      "name": "Rock_Sandstone_Brick"
    },
    {
      "x": -5,
      "y": 12,
      "z": -3,
      "name": "Rock_Sandstone_Brick"
    },
    {
      "x": -5,
      "y": 13,
      "z": -3,
      "name": "Rock_Sandstone"
    },
    {
      "x": -5,
      "y": 14,
      "z": -3,
      "name": "Rock_Sandstone_Brick"
    },
    {
      "x": -5,
      "y": 15,
      "z": -3,
      "name": "Rock_Sandstone_Brick"
    },
    {
      "x": -5,
      "y": 16,
      "z": -3,
      "name": "Rock_Sandstone_Brick"
    },
    {
      "x": -5,
      "y": 17,
      "z": -3,
      "name": "Rock_Sandstone_Brick"
    },
    {
      "x": -5,
      "y": 18,
      "z": -3,
      "name": "Rock_Sandstone_Brick"
    },
    {
      "x": -5,
      "y": 19,
      "z": -3,
      "name": "Rock_Sandstone_Brick"
    },
    {
      "x": -5,
      "y": 20,
      "z": -3,
      "name": "Rock_Sandstone_Brick"
    },
    {
      "x": -5,
      "y": 21,
      "z": -3,
      "name": "Rock_Sandstone"
    },
    {
      "x": -5,
      "y": 22,
      "z": -3,
      "name": "Rock_Sandstone_Brick"
    },
    {
      "x": -5,
      "y": 23,
      "z": -3,
      "name": "Rock_Sandstone"
    },
    {
      "x": -5,
      "y": 24,
      "z": -3,
      "name": "Rock_Sandstone_Brick"
    },
    {
      "x": -5,
      "y": 25,
      "z": -3,
      "name": "Rock_Sandstone"
    },
    {
      "x": -5,
      "y": 26,
      "z": -3,
      "name": "Rock_Sandstone_Brick"
    },
    {
      "x": -5,
      "y": 27,
      "z": -3,
      "name": "Rock_Sandstone_Brick"
    },
    {
      "x": -5,
      "y": 28,
      "z": -3,
      "name": "Rock_Sandstone_Brick"
    },
    {
      "x": -5,
      "y": 29,
      "z": -3,
      "name": "Rock_Sandstone_Brick"
    },
    {
      "x": -5,
      "y": 30,
      "z": -3,
      "name": "Rock_Sandstone"
    },
    {
      "x": -5,
      "y": 31,
      "z": -3,
      "name": "Rock_Sandstone_Brick"
    },
    {
      "x": -5,
      "y": 32,
      "z": -3,
      "name": "Rock_Sandstone_Brick"
    },
    {
      "x": -5,
      "y": 33,
      "z": -3,
      "name": "Rock_Sandstone_Brick"
    },
    {
      "x": -5,
      "y": 34,
      "z": -3,
      "name": "Rock_Sandstone_Brick"
    },
    {
      "x": -5,
      "y": 35,
      "z": -3,
      "name": "Rock_Sandstone_Brick"
    },
    {
      "x": -5,
      "y": 32,
      "z": -2,
      "name": "Rock_Sandstone_Brick_Stairs",
      "rotation": 10
    },
    {
      "x": -5,
      "y": 33,
      "z": -2,
      "name": "Rock_Sandstone_Brick"
    },
    {
      "x": -5,
      "y": 34,
      "z": -2,
      "name": "Rock_Sandstone_Brick"
    },
    {
      "x": -5,
      "y": 35,
      "z": -2,
      "name": "Rock_Sandstone_Brick"
    },
    {
      "x": -5,
      "y": 33,
      "z": -1,
      "name": "Rock_Sandstone_Brick"
    },
    {
      "x": -5,
      "y": 34,
      "z": -1,
      "name": "Rock_Sandstone_Brick"
    },
    {
      "x": -5,
      "y": 35,
      "z": -1,
      "name": "Rock_Sandstone_Brick"
    },
    {
      "x": -5,
      "y": 33,
      "z": 0,
      "name": "Rock_Sandstone_Brick"
    },
    {
      "x": -5,
      "y": 34,
      "z": 0,
      "name": "Rock_Sandstone_Brick"
    },
    {
      "x": -5,
      "y": 35,
      "z": 0,
      "name": "Rock_Sandstone_Brick"
    },
    {
      "x": -5,
      "y": 33,
      "z": 1,
      "name": "Rock_Sandstone_Brick"
    },
    {
      "x": -5,
      "y": 34,
      "z": 1,
      "name": "Rock_Sandstone_Brick"
    },
    {
      "x": -5,
      "y": 33,
      "z": 2,
      "name": "Rock_Sandstone_Brick"
    },
    {
      "x": -5,
      "y": 32,
      "z": 3,
      "name": "Rock_Sandstone_Brick_Stairs",
      "rotation": 34
    },
    {
      "x": -5,
      "y": 0,
      "z": 4,
      "name": "Rock_Sandstone"
    },
    {
      "x": -5,
      "y": 1,
      "z": 4,
      "name": "Rock_Sandstone_Brick"
    },
    {
      "x": -5,
      "y": 2,
      "z": 4,
      "name": "Rock_Sandstone_Brick"
    },
    {
      "x": -5,
      "y": 3,
      "z": 4,
      "name": "Rock_Sandstone_Brick"
    },
    {
      "x": -5,
      "y": 4,
      "z": 4,
      "name": "Rock_Sandstone"
    },
    {
      "x": -5,
      "y": 5,
      "z": 4,
      "name": "Rock_Sandstone_Brick"
    },
    {
      "x": -5,
      "y": 6,
      "z": 4,
      "name": "Rock_Sandstone_Brick"
    },
    {
      "x": -5,
      "y": 7,
      "z": 4,
      "name": "Rock_Sandstone_Cobble"
    },
    {
      "x": -5,
      "y": 8,
      "z": 4,
      "name": "Rock_Sandstone_Cobble"
    },
    {
      "x": -5,
      "y": 9,
      "z": 4,
      "name": "Rock_Sandstone_Brick"
    },
    {
      "x": -5,
      "y": 10,
      "z": 4,
      "name": "Rock_Sandstone_Brick"
    },
    {
      "x": -5,
      "y": 11,
      "z": 4,
      "name": "Rock_Sandstone"
    },
    {
      "x": -5,
      "y": 12,
      "z": 4,
      "name": "Rock_Sandstone_Brick"
    },
    {
      "x": -5,
      "y": 13,
      "z": 4,
      "name": "Rock_Sandstone"
    },
    {
      "x": -5,
      "y": 14,
      "z": 4,
      "name": "Rock_Sandstone"
    },
    {
      "x": -5,
      "y": 15,
      "z": 4,
      "name": "Rock_Sandstone_Brick"
    },
    {
      "x": -5,
      "y": 16,
      "z": 4,
      "name": "Rock_Sandstone_Brick"
    },
    {
      "x": -5,
      "y": 17,
      "z": 4,
      "name": "Rock_Sandstone_Brick"
    },
    {
      "x": -5,
      "y": 18,
      "z": 4,
      "name": "Rock_Sandstone_Brick"
    },
    {
      "x": -5,
      "y": 19,
      "z": 4,
      "name": "Rock_Sandstone"
    },
    {
      "x": -5,
      "y": 20,
      "z": 4,
      "name": "Rock_Sandstone"
    },
    {
      "x": -5,
      "y": 21,
      "z": 4,
      "name": "Rock_Sandstone_Brick"
    },
    {
      "x": -5,
      "y": 22,
      "z": 4,
      "name": "Rock_Sandstone_Brick"
    },
    {
      "x": -5,
      "y": 23,
      "z": 4,
      "name": "Rock_Sandstone"
    },
    {
      "x": -5,
      "y": 24,
      "z": 4,
      "name": "Rock_Sandstone_Brick"
    },
    {
      "x": -5,
      "y": 25,
      "z": 4,
      "name": "Rock_Sandstone"
    },
    {
      "x": -5,
      "y": 26,
      "z": 4,
      "name": "Rock_Sandstone_Brick"
    },
    {
      "x": -5,
      "y": 27,
      "z": 4,
      "name": "Rock_Sandstone"
    },
    {
      "x": -5,
      "y": 28,
      "z": 4,
      "name": "Rock_Sandstone_Brick"
    },
    {
      "x": -5,
      "y": 29,
      "z": 4,
      "name": "Rock_Sandstone_Brick"
    },
    {
      "x": -5,
      "y": 30,
      "z": 4,
      "name": "Rock_Sandstone_Brick"
    },
    {
      "x": -5,
      "y": 31,
      "z": 4,
      "name": "Rock_Sandstone_Brick"
    },
    {
      "x": -5,
      "y": 32,
      "z": 4,
      "name": "Rock_Sandstone_Brick"
    },
    {
      "x": -5,
      "y": 0,
      "z": 5,
      "name": "Rock_Sandstone_Brick"
    },
    {
      "x": -5,
      "y": 1,
      "z": 5,
      "name": "Rock_Sandstone"
    },
    {
      "x": -5,
      "y": 2,
      "z": 5,
      "name": "Rock_Sandstone_Brick"
    },
    {
      "x": -5,
      "y": 3,
      "z": 5,
      "name": "Rock_Sandstone"
    },
    {
      "x": -5,
      "y": 4,
      "z": 5,
      "name": "Rock_Sandstone"
    },
    {
      "x": -5,
      "y": 5,
      "z": 5,
      "name": "Rock_Sandstone_Brick"
    },
    {
      "x": -5,
      "y": 6,
      "z": 5,
      "name": "Rock_Sandstone_Brick"
    },
    {
      "x": -5,
      "y": 7,
      "z": 5,
      "name": "Rock_Sandstone_Brick"
    },
    {
      "x": -5,
      "y": 8,
      "z": 5,
      "name": "Rock_Sandstone_Brick"
    },
    {
      "x": -5,
      "y": 9,
      "z": 5,
      "name": "Rock_Sandstone_Brick"
    },
    {
      "x": -5,
      "y": 10,
      "z": 5,
      "name": "Rock_Sandstone"
    },
    {
      "x": -5,
      "y": 11,
      "z": 5,
      "name": "Rock_Sandstone_Brick"
    },
    {
      "x": -5,
      "y": 12,
      "z": 5,
      "name": "Rock_Sandstone_Brick"
    },
    {
      "x": -5,
      "y": 13,
      "z": 5,
      "name": "Rock_Sandstone"
    },
    {
      "x": -5,
      "y": 14,
      "z": 5,
      "name": "Rock_Sandstone"
    },
    {
      "x": -5,
      "y": 15,
      "z": 5,
      "name": "Rock_Sandstone_Brick"
    },
    {
      "x": -5,
      "y": 16,
      "z": 5,
      "name": "Rock_Sandstone"
    },
    {
      "x": -5,
      "y": 17,
      "z": 5,
      "name": "Rock_Sandstone"
    },
    {
      "x": -5,
      "y": 18,
      "z": 5,
      "name": "Rock_Sandstone_Brick"
    },
    {
      "x": -5,
      "y": 19,
      "z": 5,
      "name": "Rock_Sandstone"
    },
    {
      "x": -5,
      "y": 20,
      "z": 5,
      "name": "Rock_Sandstone"
    },
    {
      "x": -5,
      "y": 21,
      "z": 5,
      "name": "Rock_Sandstone_Brick"
    },
    {
      "x": -5,
      "y": 22,
      "z": 5,
      "name": "Rock_Sandstone_Cobble"
    },
    {
      "x": -5,
      "y": 23,
      "z": 5,
      "name": "Rock_Sandstone_Brick"
    },
    {
      "x": -5,
      "y": 24,
      "z": 5,
      "name": "Rock_Sandstone_Brick"
    },
    {
      "x": -5,
      "y": 25,
      "z": 5,
      "name": "Rock_Sandstone_Brick"
    },
    {
      "x": -5,
      "y": 26,
      "z": 5,
      "name": "Rock_Sandstone_Brick"
    },
    {
      "x": -5,
      "y": 27,
      "z": 5,
      "name": "Rock_Sandstone_Brick"
    },
    {
      "x": -5,
      "y": 28,
      "z": 5,
      "name": "Rock_Sandstone_Brick"
    },
    {
      "x": -5,
      "y": 29,
      "z": 5,
      "name": "Rock_Sandstone_Brick"
    },
    {
      "x": -5,
      "y": 30,
      "z": 5,
      "name": "Rock_Sandstone_Brick"
    },
    {
      "x": -5,
      "y": 31,
      "z": 5,
      "name": "Rock_Sandstone_Brick"
    },
    {
      "x": -5,
      "y": 32,
      "z": 5,
      "name": "Rock_Sandstone"
    },
    {
      "x": -4,
      "y": 0,
      "z": -5,
      "name": "Rock_Sandstone_Brick"
    },
    {
      "x": -4,
      "y": 1,
      "z": -5,
      "name": "Rock_Sandstone_Brick"
    },
    {
      "x": -4,
      "y": 2,
      "z": -5,
      "name": "Rock_Sandstone_Brick"
    },
    {
      "x": -4,
      "y": 3,
      "z": -5,
      "name": "Rock_Sandstone_Brick"
    },
    {
      "x": -4,
      "y": 4,
      "z": -5,
      "name": "Rock_Sandstone_Brick"
    },
    {
      "x": -4,
      "y": 5,
      "z": -5,
      "name": "Rock_Sandstone_Brick"
    },
    {
      "x": -4,
      "y": 6,
      "z": -5,
      "name": "Rock_Sandstone_Cobble"
    },
    {
      "x": -4,
      "y": 7,
      "z": -5,
      "name": "Rock_Sandstone_Brick"
    },
    {
      "x": -4,
      "y": 8,
      "z": -5,
      "name": "Rock_Sandstone_Brick"
    },
    {
      "x": -4,
      "y": 9,
      "z": -5,
      "name": "Rock_Sandstone_Brick"
    },
    {
      "x": -4,
      "y": 10,
      "z": -5,
      "name": "Rock_Sandstone_Cobble"
    },
    {
      "x": -4,
      "y": 11,
      "z": -5,
      "name": "Rock_Sandstone_Cobble"
    },
    {
      "x": -4,
      "y": 12,
      "z": -5,
      "name": "Rock_Sandstone_Brick"
    },
    {
      "x": -4,
      "y": 13,
      "z": -5,
      "name": "Rock_Sandstone"
    },
    {
      "x": -4,
      "y": 14,
      "z": -5,
      "name": "Rock_Sandstone_Cobble"
    },
    {
      "x": -4,
      "y": 15,
      "z": -5,
      "name": "Rock_Sandstone"
    },
    {
      "x": -4,
      "y": 16,
      "z": -5,
      "name": "Rock_Sandstone_Brick"
    },
    {
      "x": -4,
      "y": 17,
      "z": -5,
      "name": "Rock_Sandstone_Brick"
    },
    {
      "x": -4,
      "y": 18,
      "z": -5,
      "name": "Rock_Sandstone"
    },
    {
      "x": -4,
      "y": 19,
      "z": -5,
      "name": "Rock_Sandstone_Brick"
    },
    {
      "x": -4,
      "y": 20,
      "z": -5,
      "name": "Rock_Sandstone_Cobble"
    },
    {
      "x": -4,
      "y": 21,
      "z": -5,
      "name": "Rock_Sandstone"
    },
    {
      "x": -4,
      "y": 22,
      "z": -5,
      "name": "Rock_Sandstone_Brick"
    },
    {
      "x": -4,
      "y": 23,
      "z": -5,
      "name": "Rock_Sandstone_Brick"
    },
    {
      "x": -4,
      "y": 24,
      "z": -5,
      "name": "Rock_Sandstone_Brick"
    },
    {
      "x": -4,
      "y": 25,
      "z": -5,
      "name": "Rock_Sandstone_Brick"
    },
    {
      "x": -4,
      "y": 26,
      "z": -5,
      "name": "Rock_Sandstone"
    },
    {
      "x": -4,
      "y": 27,
      "z": -5,
      "name": "Rock_Sandstone_Brick"
    },
    {
      "x": -4,
      "y": 28,
      "z": -5,
      "name": "Rock_Sandstone_Cobble"
    },
    {
      "x": -4,
      "y": 29,
      "z": -5,
      "name": "Rock_Sandstone_Brick"
    },
    {
      "x": -4,
      "y": 30,
      "z": -5,
      "name": "Rock_Sandstone_Brick"
    },
    {
      "x": -4,
      "y": 31,
      "z": -5,
      "name": "Rock_Sandstone_Brick"
    },
    {
      "x": -4,
      "y": 32,
      "z": -5,
      "name": "Rock_Sandstone_Brick"
    },
    {
      "x": -4,
      "y": 33,
      "z": -5,
      "name": "Rock_Sandstone_Brick"
    },
    {
      "x": -4,
      "y": 34,
      "z": -5,
      "name": "Rock_Sandstone_Brick"
    },
    {
      "x": -4,
      "y": 35,
      "z": -5,
      "name": "Rock_Sandstone_Brick"
    },
    {
      "x": -4,
      "y": 0,
      "z": -4,
      "name": "Rock_Sandstone_Brick"
    },
    {
      "x": -4,
      "y": 1,
      "z": -4,
      "name": "Rock_Sandstone_Brick"
    },
    {
      "x": -4,
      "y": 2,
      "z": -4,
      "name": "Rock_Sandstone"
    },
    {
      "x": -4,
      "y": 3,
      "z": -4,
      "name": "Rock_Sandstone_Brick"
    },
    {
      "x": -4,
      "y": 4,
      "z": -4,
      "name": "Rock_Sandstone_Brick"
    },
    {
      "x": -4,
      "y": 5,
      "z": -4,
      "name": "Rock_Sandstone_Brick"
    },
    {
      "x": -4,
      "y": 6,
      "z": -4,
      "name": "Rock_Sandstone_Brick"
    },
    {
      "x": -4,
      "y": 7,
      "z": -4,
      "name": "Rock_Sandstone_Brick"
    },
    {
      "x": -4,
      "y": 8,
      "z": -4,
      "name": "Rock_Sandstone_Brick"
    },
    {
      "x": -4,
      "y": 9,
      "z": -4,
      "name": "Rock_Sandstone_Brick"
    },
    {
      "x": -4,
      "y": 10,
      "z": -4,
      "name": "Rock_Sandstone"
    },
    {
      "x": -4,
      "y": 11,
      "z": -4,
      "name": "Rock_Sandstone_Brick"
    },
    {
      "x": -4,
      "y": 12,
      "z": -4,
      "name": "Rock_Sandstone_Brick"
    },
    {
      "x": -4,
      "y": 13,
      "z": -4,
      "name": "Rock_Sandstone_Brick"
    },
    {
      "x": -4,
      "y": 14,
      "z": -4,
      "name": "Rock_Sandstone_Brick"
    },
    {
      "x": -4,
      "y": 15,
      "z": -4,
      "name": "Rock_Sandstone_Brick"
    },
    {
      "x": -4,
      "y": 16,
      "z": -4,
      "name": "Rock_Sandstone_Brick"
    },
    {
      "x": -4,
      "y": 17,
      "z": -4,
      "name": "Rock_Sandstone_Brick"
    },
    {
      "x": -4,
      "y": 18,
      "z": -4,
      "name": "Rock_Sandstone_Brick"
    },
    {
      "x": -4,
      "y": 19,
      "z": -4,
      "name": "Rock_Sandstone_Brick"
    },
    {
      "x": -4,
      "y": 20,
      "z": -4,
      "name": "Rock_Sandstone_Brick"
    },
    {
      "x": -4,
      "y": 21,
      "z": -4,
      "name": "Rock_Sandstone_Cobble"
    },
    {
      "x": -4,
      "y": 22,
      "z": -4,
      "name": "Rock_Sandstone"
    },
    {
      "x": -4,
      "y": 23,
      "z": -4,
      "name": "Rock_Sandstone_Cobble"
    },
    {
      "x": -4,
      "y": 24,
      "z": -4,
      "name": "Rock_Sandstone_Brick"
    },
    {
      "x": -4,
      "y": 25,
      "z": -4,
      "name": "Rock_Sandstone_Brick"
    },
    {
      "x": -4,
      "y": 26,
      "z": -4,
      "name": "Rock_Sandstone_Brick"
    },
    {
      "x": -4,
      "y": 27,
      "z": -4,
      "name": "Rock_Sandstone_Brick"
    },
    {
      "x": -4,
      "y": 28,
      "z": -4,
      "name": "Rock_Sandstone_Brick"
    },
    {
      "x": -4,
      "y": 29,
      "z": -4,
      "name": "Rock_Sandstone_Cobble"
    },
    {
      "x": -4,
      "y": 30,
      "z": -4,
      "name": "Rock_Sandstone_Brick"
    },
    {
      "x": -4,
      "y": 31,
      "z": -4,
      "name": "Rock_Sandstone_Brick"
    },
    {
      "x": -4,
      "y": 32,
      "z": -4,
      "name": "Rock_Sandstone_Brick"
    },
    {
      "x": -4,
      "y": 33,
      "z": -4,
      "name": "Rock_Sandstone_Brick"
    },
    {
      "x": -4,
      "y": 34,
      "z": -4,
      "name": "Rock_Sandstone_Brick"
    },
    {
      "x": -4,
      "y": 35,
      "z": -4,
      "name": "Rock_Sandstone_Brick"
    },
    {
      "x": -4,
      "y": 0,
      "z": -3,
      "name": "Rock_Sandstone"
    },
    {
      "x": -4,
      "y": 1,
      "z": -3,
      "name": "Rock_Sandstone"
    },
    {
      "x": -4,
      "y": 2,
      "z": -3,
      "name": "Rock_Sandstone_Brick"
    },
    {
      "x": -4,
      "y": 3,
      "z": -3,
      "name": "Rock_Sandstone"
    },
    {
      "x": -4,
      "y": 4,
      "z": -3,
      "name": "Rock_Sandstone_Brick"
    },
    {
      "x": -4,
      "y": 5,
      "z": -3,
      "name": "Rock_Sandstone_Cobble"
    },
    {
      "x": -4,
      "y": 6,
      "z": -3,
      "name": "Rock_Sandstone_Brick"
    },
    {
      "x": -4,
      "y": 7,
      "z": -3,
      "name": "Rock_Sandstone_Cobble"
    },
    {
      "x": -4,
      "y": 8,
      "z": -3,
      "name": "Rock_Sandstone"
    },
    {
      "x": -4,
      "y": 9,
      "z": -3,
      "name": "Rock_Sandstone_Brick"
    },
    {
      "x": -4,
      "y": 10,
      "z": -3,
      "name": "Rock_Sandstone_Brick"
    },
    {
      "x": -4,
      "y": 11,
      "z": -3,
      "name": "Rock_Sandstone_Brick"
    },
    {
      "x": -4,
      "y": 12,
      "z": -3,
      "name": "Rock_Sandstone_Brick"
    },
    {
      "x": -4,
      "y": 13,
      "z": -3,
      "name": "Rock_Sandstone_Cobble"
    },
    {
      "x": -4,
      "y": 14,
      "z": -3,
      "name": "Rock_Sandstone_Brick"
    },
    {
      "x": -4,
      "y": 15,
      "z": -3,
      "name": "Rock_Sandstone_Brick"
    },
    {
      "x": -4,
      "y": 16,
      "z": -3,
      "name": "Rock_Sandstone_Brick"
    },
    {
      "x": -4,
      "y": 17,
      "z": -3,
      "name": "Rock_Sandstone_Brick"
    },
    {
      "x": -4,
      "y": 18,
      "z": -3,
      "name": "Rock_Sandstone_Brick"
    },
    {
      "x": -4,
      "y": 19,
      "z": -3,
      "name": "Rock_Sandstone_Brick"
    },
    {
      "x": -4,
      "y": 20,
      "z": -3,
      "name": "Rock_Sandstone_Brick"
    },
    {
      "x": -4,
      "y": 21,
      "z": -3,
      "name": "Rock_Sandstone"
    },
    {
      "x": -4,
      "y": 22,
      "z": -3,
      "name": "Rock_Sandstone_Brick"
    },
    {
      "x": -4,
      "y": 23,
      "z": -3,
      "name": "Rock_Sandstone_Brick"
    },
    {
      "x": -4,
      "y": 24,
      "z": -3,
      "name": "Rock_Sandstone_Brick"
    },
    {
      "x": -4,
      "y": 25,
      "z": -3,
      "name": "Rock_Sandstone_Brick"
    },
    {
      "x": -4,
      "y": 26,
      "z": -3,
      "name": "Rock_Sandstone_Brick"
    },
    {
      "x": -4,
      "y": 27,
      "z": -3,
      "name": "Rock_Sandstone_Brick"
    },
    {
      "x": -4,
      "y": 28,
      "z": -3,
      "name": "Rock_Sandstone_Brick"
    },
    {
      "x": -4,
      "y": 29,
      "z": -3,
      "name": "Rock_Sandstone_Brick"
    },
    {
      "x": -4,
      "y": 30,
      "z": -3,
      "name": "Rock_Sandstone_Brick"
    },
    {
      "x": -4,
      "y": 31,
      "z": -3,
      "name": "Rock_Sandstone"
    },
    {
      "x": -4,
      "y": 32,
      "z": -3,
      "name": "Rock_Sandstone"
    },
    {
      "x": -4,
      "y": 33,
      "z": -3,
      "name": "Rock_Sandstone_Brick"
    },
    {
      "x": -4,
      "y": 34,
      "z": -3,
      "name": "Rock_Sandstone_Brick"
    },
    {
      "x": -4,
      "y": 35,
      "z": -3,
      "name": "Rock_Sandstone_Brick"
    },
    {
      "x": -4,
      "y": 31,
      "z": -2,
      "name": "Rock_Sandstone_Brick_Stairs",
      "rotation": 10
    },
    {
      "x": -4,
      "y": 32,
      "z": -2,
      "name": "Rock_Sandstone_Brick"
    },
    {
      "x": -4,
      "y": 33,
      "z": -2,
      "name": "Rock_Sandstone_Brick"
    },
    {
      "x": -4,
      "y": 34,
      "z": -2,
      "name": "Rock_Sandstone_Brick"
    },
    {
      "x": -4,
      "y": 35,
      "z": -2,
      "name": "Rock_Sandstone_Brick"
    },
    {
      "x": -4,
      "y": 32,
      "z": -1,
      "name": "Rock_Sandstone_Brick"
    },
    {
      "x": -4,
      "y": 33,
      "z": -1,
      "name": "Rock_Sandstone_Brick"
    },
    {
      "x": -4,
      "y": 34,
      "z": -1,
      "name": "Rock_Sandstone_Brick"
    },
    {
      "x": -4,
      "y": 35,
      "z": -1,
      "name": "Rock_Sandstone_Brick"
    },
    {
      "x": -4,
      "y": 32,
      "z": 0,
      "name": "Rock_Sandstone_Brick"
    },
    {
      "x": -4,
      "y": 33,
      "z": 0,
      "name": "Rock_Sandstone_Brick"
    },
    {
      "x": -4,
      "y": 34,
      "z": 0,
      "name": "Rock_Sandstone_Brick"
    },
    {
      "x": -4,
      "y": 35,
      "z": 0,
      "name": "Rock_Sandstone_Brick"
    },
    {
      "x": -4,
      "y": 32,
      "z": 1,
      "name": "Rock_Sandstone_Brick"
    },
    {
      "x": -4,
      "y": 33,
      "z": 1,
      "name": "Rock_Sandstone_Brick"
    },
    {
      "x": -4,
      "y": 34,
      "z": 1,
      "name": "Rock_Sandstone_Brick"
    },
    {
      "x": -4,
      "y": 32,
      "z": 2,
      "name": "Rock_Sandstone"
    },
    {
      "x": -4,
      "y": 33,
      "z": 2,
      "name": "Rock_Sandstone_Brick"
    },
    {
      "x": -4,
      "y": 31,
      "z": 3,
      "name": "Rock_Sandstone_Brick_Stairs",
      "rotation": 34
    },
    {
      "x": -4,
      "y": 32,
      "z": 3,
      "name": "Rock_Sandstone_Brick"
    },
    {
      "x": -4,
      "y": 33,
      "z": 3,
      "name": "Rock_Sandstone_Brick"
    },
    {
      "x": -4,
      "y": 0,
      "z": 4,
      "name": "Rock_Sandstone_Brick"
    },
    {
      "x": -4,
      "y": 1,
      "z": 4,
      "name": "Rock_Sandstone_Brick"
    },
    {
      "x": -4,
      "y": 2,
      "z": 4,
      "name": "Rock_Sandstone_Brick"
    },
    {
      "x": -4,
      "y": 3,
      "z": 4,
      "name": "Rock_Sandstone_Brick"
    },
    {
      "x": -4,
      "y": 4,
      "z": 4,
      "name": "Rock_Sandstone_Brick"
    },
    {
      "x": -4,
      "y": 5,
      "z": 4,
      "name": "Rock_Sandstone_Brick"
    },
    {
      "x": -4,
      "y": 6,
      "z": 4,
      "name": "Rock_Sandstone_Brick"
    },
    {
      "x": -4,
      "y": 7,
      "z": 4,
      "name": "Rock_Sandstone_Brick"
    },
    {
      "x": -4,
      "y": 8,
      "z": 4,
      "name": "Rock_Sandstone_Brick"
    },
    {
      "x": -4,
      "y": 9,
      "z": 4,
      "name": "Rock_Sandstone_Cobble"
    },
    {
      "x": -4,
      "y": 10,
      "z": 4,
      "name": "Rock_Sandstone_Brick"
    },
    {
      "x": -4,
      "y": 11,
      "z": 4,
      "name": "Rock_Sandstone_Brick"
    },
    {
      "x": -4,
      "y": 12,
      "z": 4,
      "name": "Rock_Sandstone_Brick"
    },
    {
      "x": -4,
      "y": 13,
      "z": 4,
      "name": "Rock_Sandstone"
    },
    {
      "x": -4,
      "y": 14,
      "z": 4,
      "name": "Rock_Sandstone_Brick"
    },
    {
      "x": -4,
      "y": 15,
      "z": 4,
      "name": "Rock_Sandstone_Brick"
    },
    {
      "x": -4,
      "y": 16,
      "z": 4,
      "name": "Rock_Sandstone_Brick"
    },
    {
      "x": -4,
      "y": 17,
      "z": 4,
      "name": "Rock_Sandstone_Brick"
    },
    {
      "x": -4,
      "y": 18,
      "z": 4,
      "name": "Rock_Sandstone"
    },
    {
      "x": -4,
      "y": 19,
      "z": 4,
      "name": "Rock_Sandstone_Brick"
    },
    {
      "x": -4,
      "y": 20,
      "z": 4,
      "name": "Rock_Sandstone_Brick"
    },
    {
      "x": -4,
      "y": 21,
      "z": 4,
      "name": "Rock_Sandstone_Cobble"
    },
    {
      "x": -4,
      "y": 22,
      "z": 4,
      "name": "Rock_Sandstone"
    },
    {
      "x": -4,
      "y": 23,
      "z": 4,
      "name": "Rock_Sandstone"
    },
    {
      "x": -4,
      "y": 24,
      "z": 4,
      "name": "Rock_Sandstone_Cobble"
    },
    {
      "x": -4,
      "y": 25,
      "z": 4,
      "name": "Rock_Sandstone_Brick"
    },
    {
      "x": -4,
      "y": 26,
      "z": 4,
      "name": "Rock_Sandstone_Brick"
    },
    {
      "x": -4,
      "y": 27,
      "z": 4,
      "name": "Rock_Sandstone_Brick"
    },
    {
      "x": -4,
      "y": 28,
      "z": 4,
      "name": "Rock_Sandstone_Brick"
    },
    {
      "x": -4,
      "y": 29,
      "z": 4,
      "name": "Rock_Sandstone"
    },
    {
      "x": -4,
      "y": 30,
      "z": 4,
      "name": "Rock_Sandstone_Brick"
    },
    {
      "x": -4,
      "y": 31,
      "z": 4,
      "name": "Rock_Sandstone_Brick"
    },
    {
      "x": -4,
      "y": 32,
      "z": 4,
      "name": "Rock_Sandstone_Brick"
    },
    {
      "x": -4,
      "y": 0,
      "z": 5,
      "name": "Rock_Sandstone_Brick"
    },
    {
      "x": -4,
      "y": 1,
      "z": 5,
      "name": "Rock_Sandstone_Cobble"
    },
    {
      "x": -4,
      "y": 2,
      "z": 5,
      "name": "Rock_Sandstone_Brick"
    },
    {
      "x": -4,
      "y": 3,
      "z": 5,
      "name": "Rock_Sandstone_Brick"
    },
    {
      "x": -4,
      "y": 4,
      "z": 5,
      "name": "Rock_Sandstone"
    },
    {
      "x": -4,
      "y": 5,
      "z": 5,
      "name": "Rock_Sandstone_Brick"
    },
    {
      "x": -4,
      "y": 6,
      "z": 5,
      "name": "Rock_Sandstone_Brick"
    },
    {
      "x": -4,
      "y": 7,
      "z": 5,
      "name": "Rock_Sandstone_Brick"
    },
    {
      "x": -4,
      "y": 8,
      "z": 5,
      "name": "Rock_Sandstone_Brick"
    },
    {
      "x": -4,
      "y": 9,
      "z": 5,
      "name": "Rock_Sandstone_Brick"
    },
    {
      "x": -4,
      "y": 10,
      "z": 5,
      "name": "Rock_Sandstone_Brick"
    },
    {
      "x": -4,
      "y": 11,
      "z": 5,
      "name": "Rock_Sandstone_Brick"
    },
    {
      "x": -4,
      "y": 12,
      "z": 5,
      "name": "Rock_Sandstone_Cobble"
    },
    {
      "x": -4,
      "y": 13,
      "z": 5,
      "name": "Rock_Sandstone"
    },
    {
      "x": -4,
      "y": 14,
      "z": 5,
      "name": "Rock_Sandstone"
    },
    {
      "x": -4,
      "y": 15,
      "z": 5,
      "name": "Rock_Sandstone_Brick"
    },
    {
      "x": -4,
      "y": 16,
      "z": 5,
      "name": "Rock_Sandstone_Brick"
    },
    {
      "x": -4,
      "y": 17,
      "z": 5,
      "name": "Rock_Sandstone_Brick"
    },
    {
      "x": -4,
      "y": 18,
      "z": 5,
      "name": "Rock_Sandstone_Brick"
    },
    {
      "x": -4,
      "y": 19,
      "z": 5,
      "name": "Rock_Sandstone"
    },
    {
      "x": -4,
      "y": 20,
      "z": 5,
      "name": "Rock_Sandstone"
    },
    {
      "x": -4,
      "y": 21,
      "z": 5,
      "name": "Rock_Sandstone_Brick"
    },
    {
      "x": -4,
      "y": 22,
      "z": 5,
      "name": "Rock_Sandstone_Brick"
    },
    {
      "x": -4,
      "y": 23,
      "z": 5,
      "name": "Rock_Sandstone_Cobble"
    },
    {
      "x": -4,
      "y": 24,
      "z": 5,
      "name": "Rock_Sandstone"
    },
    {
      "x": -4,
      "y": 25,
      "z": 5,
      "name": "Rock_Sandstone_Cobble"
    },
    {
      "x": -4,
      "y": 26,
      "z": 5,
      "name": "Rock_Sandstone_Cobble"
    },
    {
      "x": -4,
      "y": 27,
      "z": 5,
      "name": "Rock_Sandstone_Brick"
    },
    {
      "x": -4,
      "y": 28,
      "z": 5,
      "name": "Rock_Sandstone_Cobble"
    },
    {
      "x": -4,
      "y": 29,
      "z": 5,
      "name": "Rock_Sandstone_Cobble"
    },
    {
      "x": -4,
      "y": 30,
      "z": 5,
      "name": "Rock_Sandstone"
    },
    {
      "x": -4,
      "y": 31,
      "z": 5,
      "name": "Rock_Sandstone_Brick"
    },
    {
      "x": -4,
      "y": 32,
      "z": 5,
      "name": "Rock_Sandstone_Cobble"
    },
    {
      "x": -4,
      "y": 0,
      "z": 6,
      "name": "Rock_Sandstone_Brick"
    },
    {
      "x": -4,
      "y": 1,
      "z": 6,
      "name": "Rock_Sandstone_Brick"
    },
    {
      "x": -4,
      "y": 2,
      "z": 6,
      "name": "Rock_Sandstone_Brick"
    },
    {
      "x": -4,
      "y": 3,
      "z": 6,
      "name": "Rock_Sandstone_Brick"
    },
    {
      "x": -4,
      "y": 4,
      "z": 6,
      "name": "Rock_Sandstone"
    },
    {
      "x": -4,
      "y": 5,
      "z": 6,
      "name": "Rock_Sandstone_Cobble"
    },
    {
      "x": -4,
      "y": 6,
      "z": 6,
      "name": "Rock_Sandstone_Brick"
    },
    {
      "x": -4,
      "y": 7,
      "z": 6,
      "name": "Rock_Sandstone_Brick"
    },
    {
      "x": -4,
      "y": 8,
      "z": 6,
      "name": "Rock_Sandstone"
    },
    {
      "x": -4,
      "y": 9,
      "z": 6,
      "name": "Rock_Sandstone_Brick"
    },
    {
      "x": -4,
      "y": 10,
      "z": 6,
      "name": "Rock_Sandstone_Brick"
    },
    {
      "x": -4,
      "y": 11,
      "z": 6,
      "name": "Rock_Sandstone"
    },
    {
      "x": -4,
      "y": 12,
      "z": 6,
      "name": "Rock_Sandstone_Brick"
    },
    {
      "x": -4,
      "y": 13,
      "z": 6,
      "name": "Rock_Sandstone_Brick"
    },
    {
      "x": -4,
      "y": 14,
      "z": 6,
      "name": "Rock_Sandstone"
    },
    {
      "x": -4,
      "y": 15,
      "z": 6,
      "name": "Rock_Sandstone_Cobble"
    },
    {
      "x": -4,
      "y": 16,
      "z": 6,
      "name": "Rock_Sandstone_Brick"
    },
    {
      "x": -4,
      "y": 17,
      "z": 6,
      "name": "Rock_Sandstone_Brick"
    },
    {
      "x": -4,
      "y": 18,
      "z": 6,
      "name": "Rock_Sandstone_Cobble"
    },
    {
      "x": -4,
      "y": 19,
      "z": 6,
      "name": "Rock_Sandstone_Brick"
    },
    {
      "x": -4,
      "y": 20,
      "z": 6,
      "name": "Rock_Sandstone_Brick"
    },
    {
      "x": -4,
      "y": 21,
      "z": 6,
      "name": "Rock_Sandstone_Cobble"
    },
    {
      "x": -4,
      "y": 22,
      "z": 6,
      "name": "Rock_Sandstone_Brick"
    },
    {
      "x": -4,
      "y": 23,
      "z": 6,
      "name": "Rock_Sandstone_Brick"
    },
    {
      "x": -4,
      "y": 24,
      "z": 6,
      "name": "Rock_Sandstone_Brick"
    },
    {
      "x": -4,
      "y": 25,
      "z": 6,
      "name": "Rock_Sandstone_Cobble"
    },
    {
      "x": -4,
      "y": 26,
      "z": 6,
      "name": "Rock_Sandstone"
    },
    {
      "x": -4,
      "y": 27,
      "z": 6,
      "name": "Rock_Sandstone_Cobble"
    },
    {
      "x": -4,
      "y": 28,
      "z": 6,
      "name": "Rock_Sandstone"
    },
    {
      "x": -4,
      "y": 29,
      "z": 6,
      "name": "Rock_Sandstone_Cobble"
    },
    {
      "x": -4,
      "y": 30,
      "z": 6,
      "name": "Rock_Sandstone_Brick"
    },
    {
      "x": -4,
      "y": 31,
      "z": 6,
      "name": "Rock_Sandstone_Brick"
    },
    {
      "x": -4,
      "y": 32,
      "z": 6,
      "name": "Rock_Sandstone_Cobble"
    },
    {
      "x": -3,
      "y": 0,
      "z": -5,
      "name": "Rock_Sandstone"
    },
    {
      "x": -3,
      "y": 1,
      "z": -5,
      "name": "Rock_Sandstone_Cobble"
    },
    {
      "x": -3,
      "y": 2,
      "z": -5,
      "name": "Rock_Sandstone_Brick"
    },
    {
      "x": -3,
      "y": 3,
      "z": -5,
      "name": "Rock_Sandstone_Brick"
    },
    {
      "x": -3,
      "y": 4,
      "z": -5,
      "name": "Rock_Sandstone_Cobble"
    },
    {
      "x": -3,
      "y": 5,
      "z": -5,
      "name": "Rock_Sandstone_Brick"
    },
    {
      "x": -3,
      "y": 6,
      "z": -5,
      "name": "Rock_Sandstone"
    },
    {
      "x": -3,
      "y": 7,
      "z": -5,
      "name": "Rock_Sandstone_Brick"
    },
    {
      "x": -3,
      "y": 8,
      "z": -5,
      "name": "Rock_Sandstone_Brick"
    },
    {
      "x": -3,
      "y": 9,
      "z": -5,
      "name": "Rock_Sandstone_Brick"
    },
    {
      "x": -3,
      "y": 10,
      "z": -5,
      "name": "Rock_Sandstone_Cobble"
    },
    {
      "x": -3,
      "y": 11,
      "z": -5,
      "name": "Rock_Sandstone_Brick"
    },
    {
      "x": -3,
      "y": 12,
      "z": -5,
      "name": "Rock_Sandstone"
    },
    {
      "x": -3,
      "y": 13,
      "z": -5,
      "name": "Rock_Sandstone_Brick"
    },
    {
      "x": -3,
      "y": 14,
      "z": -5,
      "name": "Rock_Sandstone_Brick"
    },
    {
      "x": -3,
      "y": 15,
      "z": -5,
      "name": "Rock_Sandstone_Brick"
    },
    {
      "x": -3,
      "y": 16,
      "z": -5,
      "name": "Rock_Sandstone"
    },
    {
      "x": -3,
      "y": 17,
      "z": -5,
      "name": "Rock_Sandstone_Brick"
    },
    {
      "x": -3,
      "y": 18,
      "z": -5,
      "name": "Rock_Sandstone_Brick"
    },
    {
      "x": -3,
      "y": 19,
      "z": -5,
      "name": "Rock_Sandstone_Brick"
    },
    {
      "x": -3,
      "y": 20,
      "z": -5,
      "name": "Rock_Sandstone_Brick"
    },
    {
      "x": -3,
      "y": 21,
      "z": -5,
      "name": "Rock_Sandstone"
    },
    {
      "x": -3,
      "y": 22,
      "z": -5,
      "name": "Rock_Sandstone_Brick"
    },
    {
      "x": -3,
      "y": 23,
      "z": -5,
      "name": "Rock_Sandstone_Brick"
    },
    {
      "x": -3,
      "y": 24,
      "z": -5,
      "name": "Rock_Sandstone_Brick"
    },
    {
      "x": -3,
      "y": 25,
      "z": -5,
      "name": "Rock_Sandstone_Brick"
    },
    {
      "x": -3,
      "y": 26,
      "z": -5,
      "name": "Rock_Sandstone_Brick"
    },
    {
      "x": -3,
      "y": 27,
      "z": -5,
      "name": "Rock_Sandstone_Brick"
    },
    {
      "x": -3,
      "y": 28,
      "z": -5,
      "name": "Rock_Sandstone_Brick"
    },
    {
      "x": -3,
      "y": 29,
      "z": -5,
      "name": "Rock_Sandstone_Cobble"
    },
    {
      "x": -3,
      "y": 30,
      "z": -5,
      "name": "Rock_Sandstone"
    },
    {
      "x": -3,
      "y": 31,
      "z": -5,
      "name": "Rock_Sandstone_Brick"
    },
    {
      "x": -3,
      "y": 32,
      "z": -5,
      "name": "Rock_Sandstone_Brick"
    },
    {
      "x": -3,
      "y": 33,
      "z": -5,
      "name": "Rock_Sandstone_Brick"
    },
    {
      "x": -3,
      "y": 34,
      "z": -5,
      "name": "Rock_Sandstone_Brick"
    },
    {
      "x": -3,
      "y": 35,
      "z": -5,
      "name": "Rock_Sandstone_Brick"
    },
    {
      "x": -3,
      "y": 0,
      "z": -4,
      "name": "Rock_Sandstone_Cobble"
    },
    {
      "x": -3,
      "y": 1,
      "z": -4,
      "name": "Rock_Sandstone_Brick"
    },
    {
      "x": -3,
      "y": 2,
      "z": -4,
      "name": "Rock_Sandstone_Brick"
    },
    {
      "x": -3,
      "y": 3,
      "z": -4,
      "name": "Rock_Sandstone"
    },
    {
      "x": -3,
      "y": 4,
      "z": -4,
      "name": "Rock_Sandstone_Brick"
    },
    {
      "x": -3,
      "y": 5,
      "z": -4,
      "name": "Rock_Sandstone_Brick"
    },
    {
      "x": -3,
      "y": 6,
      "z": -4,
      "name": "Rock_Sandstone_Brick"
    },
    {
      "x": -3,
      "y": 7,
      "z": -4,
      "name": "Rock_Sandstone_Cobble"
    },
    {
      "x": -3,
      "y": 8,
      "z": -4,
      "name": "Rock_Sandstone_Brick"
    },
    {
      "x": -3,
      "y": 9,
      "z": -4,
      "name": "Rock_Sandstone_Brick"
    },
    {
      "x": -3,
      "y": 10,
      "z": -4,
      "name": "Rock_Sandstone_Cobble"
    },
    {
      "x": -3,
      "y": 11,
      "z": -4,
      "name": "Rock_Sandstone_Brick"
    },
    {
      "x": -3,
      "y": 12,
      "z": -4,
      "name": "Rock_Sandstone"
    },
    {
      "x": -3,
      "y": 13,
      "z": -4,
      "name": "Rock_Sandstone_Brick"
    },
    {
      "x": -3,
      "y": 14,
      "z": -4,
      "name": "Rock_Sandstone_Brick"
    },
    {
      "x": -3,
      "y": 15,
      "z": -4,
      "name": "Rock_Sandstone_Brick"
    },
    {
      "x": -3,
      "y": 16,
      "z": -4,
      "name": "Rock_Sandstone_Brick"
    },
    {
      "x": -3,
      "y": 17,
      "z": -4,
      "name": "Rock_Sandstone_Brick"
    },
    {
      "x": -3,
      "y": 18,
      "z": -4,
      "name": "Rock_Sandstone_Brick"
    },
    {
      "x": -3,
      "y": 19,
      "z": -4,
      "name": "Rock_Sandstone_Brick"
    },
    {
      "x": -3,
      "y": 20,
      "z": -4,
      "name": "Rock_Sandstone_Brick"
    },
    {
      "x": -3,
      "y": 21,
      "z": -4,
      "name": "Rock_Sandstone_Cobble"
    },
    {
      "x": -3,
      "y": 22,
      "z": -4,
      "name": "Rock_Sandstone_Brick"
    },
    {
      "x": -3,
      "y": 23,
      "z": -4,
      "name": "Rock_Sandstone_Brick"
    },
    {
      "x": -3,
      "y": 24,
      "z": -4,
      "name": "Rock_Sandstone_Brick"
    },
    {
      "x": -3,
      "y": 25,
      "z": -4,
      "name": "Rock_Sandstone"
    },
    {
      "x": -3,
      "y": 26,
      "z": -4,
      "name": "Rock_Sandstone_Brick"
    },
    {
      "x": -3,
      "y": 27,
      "z": -4,
      "name": "Rock_Sandstone"
    },
    {
      "x": -3,
      "y": 28,
      "z": -4,
      "name": "Rock_Sandstone"
    },
    {
      "x": -3,
      "y": 29,
      "z": -4,
      "name": "Rock_Sandstone_Brick"
    },
    {
      "x": -3,
      "y": 30,
      "z": -4,
      "name": "Rock_Sandstone"
    },
    {
      "x": -3,
      "y": 31,
      "z": -4,
      "name": "Rock_Sandstone"
    },
    {
      "x": -3,
      "y": 32,
      "z": -4,
      "name": "Rock_Sandstone_Brick"
    },
    {
      "x": -3,
      "y": 33,
      "z": -4,
      "name": "Rock_Sandstone_Brick"
    },
    {
      "x": -3,
      "y": 34,
      "z": -4,
      "name": "Rock_Sandstone_Brick"
    },
    {
      "x": -3,
      "y": 35,
      "z": -4,
      "name": "Rock_Sandstone_Brick"
    },
    {
      "x": -3,
      "y": 0,
      "z": -3,
      "name": "Rock_Sandstone_Cobble"
    },
    {
      "x": -3,
      "y": 1,
      "z": -3,
      "name": "Rock_Sandstone_Brick"
    },
    {
      "x": -3,
      "y": 2,
      "z": -3,
      "name": "Rock_Sandstone"
    },
    {
      "x": -3,
      "y": 3,
      "z": -3,
      "name": "Rock_Sandstone_Brick"
    },
    {
      "x": -3,
      "y": 4,
      "z": -3,
      "name": "Rock_Sandstone_Brick"
    },
    {
      "x": -3,
      "y": 5,
      "z": -3,
      "name": "Rock_Sandstone_Brick"
    },
    {
      "x": -3,
      "y": 6,
      "z": -3,
      "name": "Rock_Sandstone_Brick"
    },
    {
      "x": -3,
      "y": 7,
      "z": -3,
      "name": "Rock_Sandstone"
    },
    {
      "x": -3,
      "y": 8,
      "z": -3,
      "name": "Rock_Sandstone"
    },
    {
      "x": -3,
      "y": 9,
      "z": -3,
      "name": "Rock_Sandstone_Brick"
    },
    {
      "x": -3,
      "y": 10,
      "z": -3,
      "name": "Rock_Sandstone"
    },
    {
      "x": -3,
      "y": 11,
      "z": -3,
      "name": "Rock_Sandstone"
    },
    {
      "x": -3,
      "y": 12,
      "z": -3,
      "name": "Rock_Sandstone_Brick"
    },
    {
      "x": -3,
      "y": 13,
      "z": -3,
      "name": "Rock_Sandstone_Brick"
    },
    {
      "x": -3,
      "y": 14,
      "z": -3,
      "name": "Rock_Sandstone_Brick"
    },
    {
      "x": -3,
      "y": 15,
      "z": -3,
      "name": "Rock_Sandstone"
    },
    {
      "x": -3,
      "y": 16,
      "z": -3,
      "name": "Rock_Sandstone_Brick"
    },
    {
      "x": -3,
      "y": 17,
      "z": -3,
      "name": "Rock_Sandstone_Brick"
    },
    {
      "x": -3,
      "y": 18,
      "z": -3,
      "name": "Rock_Sandstone_Brick"
    },
    {
      "x": -3,
      "y": 19,
      "z": -3,
      "name": "Rock_Sandstone_Brick"
    },
    {
      "x": -3,
      "y": 20,
      "z": -3,
      "name": "Rock_Sandstone_Brick"
    },
    {
      "x": -3,
      "y": 21,
      "z": -3,
      "name": "Rock_Sandstone"
    },
    {
      "x": -3,
      "y": 22,
      "z": -3,
      "name": "Rock_Sandstone_Brick"
    },
    {
      "x": -3,
      "y": 23,
      "z": -3,
      "name": "Rock_Sandstone_Brick"
    },
    {
      "x": -3,
      "y": 24,
      "z": -3,
      "name": "Rock_Sandstone"
    },
    {
      "x": -3,
      "y": 25,
      "z": -3,
      "name": "Rock_Sandstone"
    },
    {
      "x": -3,
      "y": 26,
      "z": -3,
      "name": "Rock_Sandstone_Brick"
    },
    {
      "x": -3,
      "y": 27,
      "z": -3,
      "name": "Rock_Sandstone_Brick"
    },
    {
      "x": -3,
      "y": 28,
      "z": -3,
      "name": "Rock_Sandstone_Brick"
    },
    {
      "x": -3,
      "y": 29,
      "z": -3,
      "name": "Rock_Sandstone_Brick"
    },
    {
      "x": -3,
      "y": 30,
      "z": -3,
      "name": "Rock_Sandstone_Brick"
    },
    {
      "x": -3,
      "y": 31,
      "z": -3,
      "name": "Rock_Sandstone"
    },
    {
      "x": -3,
      "y": 32,
      "z": -3,
      "name": "Rock_Sandstone_Brick"
    },
    {
      "x": -3,
      "y": 33,
      "z": -3,
      "name": "Rock_Sandstone_Brick"
    },
    {
      "x": -3,
      "y": 34,
      "z": -3,
      "name": "Rock_Sandstone_Brick"
    },
    {
      "x": -3,
      "y": 35,
      "z": -3,
      "name": "Rock_Sandstone_Brick"
    },
    {
      "x": -3,
      "y": 30,
      "z": -2,
      "name": "Rock_Sandstone_Brick_Stairs",
      "rotation": 10
    },
    {
      "x": -3,
      "y": 31,
      "z": -2,
      "name": "Rock_Sandstone"
    },
    {
      "x": -3,
      "y": 32,
      "z": -2,
      "name": "Rock_Sandstone_Brick"
    },
    {
      "x": -3,
      "y": 33,
      "z": -2,
      "name": "Rock_Sandstone_Brick"
    },
    {
      "x": -3,
      "y": 34,
      "z": -2,
      "name": "Rock_Sandstone_Brick"
    },
    {
      "x": -3,
      "y": 35,
      "z": -2,
      "name": "Rock_Sandstone_Brick"
    },
    {
      "x": -3,
      "y": 31,
      "z": -1,
      "name": "Rock_Sandstone_Brick"
    },
    {
      "x": -3,
      "y": 32,
      "z": -1,
      "name": "Rock_Sandstone_Brick"
    },
    {
      "x": -3,
      "y": 33,
      "z": -1,
      "name": "Rock_Sandstone_Brick"
    },
    {
      "x": -3,
      "y": 34,
      "z": -1,
      "name": "Rock_Sandstone_Brick"
    },
    {
      "x": -3,
      "y": 35,
      "z": -1,
      "name": "Rock_Sandstone_Brick"
    },
    {
      "x": -3,
      "y": 31,
      "z": 0,
      "name": "Rock_Sandstone_Brick"
    },
    {
      "x": -3,
      "y": 32,
      "z": 0,
      "name": "Rock_Sandstone_Brick"
    },
    {
      "x": -3,
      "y": 33,
      "z": 0,
      "name": "Rock_Sandstone_Brick"
    },
    {
      "x": -3,
      "y": 34,
      "z": 0,
      "name": "Rock_Sandstone_Brick"
    },
    {
      "x": -3,
      "y": 35,
      "z": 0,
      "name": "Rock_Sandstone_Brick"
    },
    {
      "x": -3,
      "y": 31,
      "z": 1,
      "name": "Rock_Sandstone_Cobble"
    },
    {
      "x": -3,
      "y": 32,
      "z": 1,
      "name": "Rock_Sandstone_Brick"
    },
    {
      "x": -3,
      "y": 33,
      "z": 1,
      "name": "Rock_Sandstone_Brick"
    },
    {
      "x": -3,
      "y": 34,
      "z": 1,
      "name": "Rock_Sandstone_Brick"
    },
    {
      "x": -3,
      "y": 31,
      "z": 2,
      "name": "Rock_Sandstone_Brick"
    },
    {
      "x": -3,
      "y": 32,
      "z": 2,
      "name": "Rock_Sandstone_Brick"
    },
    {
      "x": -3,
      "y": 33,
      "z": 2,
      "name": "Rock_Sandstone_Brick"
    },
    {
      "x": -3,
      "y": 30,
      "z": 3,
      "name": "Rock_Sandstone_Brick_Stairs",
      "rotation": 34
    },
    {
      "x": -3,
      "y": 0,
      "z": 4,
      "name": "Rock_Sandstone_Brick"
    },
    {
      "x": -3,
      "y": 1,
      "z": 4,
      "name": "Rock_Sandstone_Brick"
    },
    {
      "x": -3,
      "y": 2,
      "z": 4,
      "name": "Rock_Sandstone_Brick"
    },
    {
      "x": -3,
      "y": 3,
      "z": 4,
      "name": "Rock_Sandstone_Brick"
    },
    {
      "x": -3,
      "y": 4,
      "z": 4,
      "name": "Rock_Sandstone_Brick"
    },
    {
      "x": -3,
      "y": 5,
      "z": 4,
      "name": "Rock_Sandstone_Brick"
    },
    {
      "x": -3,
      "y": 6,
      "z": 4,
      "name": "Rock_Sandstone_Brick"
    },
    {
      "x": -3,
      "y": 7,
      "z": 4,
      "name": "Rock_Sandstone_Cobble"
    },
    {
      "x": -3,
      "y": 8,
      "z": 4,
      "name": "Rock_Sandstone_Brick"
    },
    {
      "x": -3,
      "y": 9,
      "z": 4,
      "name": "Rock_Sandstone_Brick"
    },
    {
      "x": -3,
      "y": 10,
      "z": 4,
      "name": "Rock_Sandstone"
    },
    {
      "x": -3,
      "y": 11,
      "z": 4,
      "name": "Rock_Sandstone_Brick"
    },
    {
      "x": -3,
      "y": 12,
      "z": 4,
      "name": "Rock_Sandstone_Cobble"
    },
    {
      "x": -3,
      "y": 13,
      "z": 4,
      "name": "Rock_Sandstone_Cobble"
    },
    {
      "x": -3,
      "y": 14,
      "z": 4,
      "name": "Rock_Sandstone_Brick"
    },
    {
      "x": -3,
      "y": 15,
      "z": 4,
      "name": "Rock_Sandstone_Brick"
    },
    {
      "x": -3,
      "y": 16,
      "z": 4,
      "name": "Rock_Sandstone_Brick"
    },
    {
      "x": -3,
      "y": 17,
      "z": 4,
      "name": "Rock_Sandstone_Brick"
    },
    {
      "x": -3,
      "y": 18,
      "z": 4,
      "name": "Rock_Sandstone"
    },
    {
      "x": -3,
      "y": 19,
      "z": 4,
      "name": "Rock_Sandstone"
    },
    {
      "x": -3,
      "y": 20,
      "z": 4,
      "name": "Rock_Sandstone_Brick"
    },
    {
      "x": -3,
      "y": 21,
      "z": 4,
      "name": "Rock_Sandstone"
    },
    {
      "x": -3,
      "y": 22,
      "z": 4,
      "name": "Rock_Sandstone_Brick"
    },
    {
      "x": -3,
      "y": 23,
      "z": 4,
      "name": "Rock_Sandstone"
    },
    {
      "x": -3,
      "y": 24,
      "z": 4,
      "name": "Rock_Sandstone_Cobble"
    },
    {
      "x": -3,
      "y": 25,
      "z": 4,
      "name": "Rock_Sandstone_Brick"
    },
    {
      "x": -3,
      "y": 26,
      "z": 4,
      "name": "Rock_Sandstone_Cobble"
    },
    {
      "x": -3,
      "y": 27,
      "z": 4,
      "name": "Rock_Sandstone"
    },
    {
      "x": -3,
      "y": 28,
      "z": 4,
      "name": "Rock_Sandstone_Cobble"
    },
    {
      "x": -3,
      "y": 29,
      "z": 4,
      "name": "Rock_Sandstone_Brick"
    },
    {
      "x": -3,
      "y": 30,
      "z": 4,
      "name": "Rock_Sandstone_Brick"
    },
    {
      "x": -3,
      "y": 0,
      "z": 5,
      "name": "Rock_Sandstone_Brick"
    },
    {
      "x": -3,
      "y": 1,
      "z": 5,
      "name": "Rock_Sandstone_Brick"
    },
    {
      "x": -3,
      "y": 2,
      "z": 5,
      "name": "Rock_Sandstone_Cobble"
    },
    {
      "x": -3,
      "y": 3,
      "z": 5,
      "name": "Rock_Sandstone_Cobble"
    },
    {
      "x": -3,
      "y": 4,
      "z": 5,
      "name": "Rock_Sandstone"
    },
    {
      "x": -3,
      "y": 5,
      "z": 5,
      "name": "Rock_Sandstone"
    },
    {
      "x": -3,
      "y": 6,
      "z": 5,
      "name": "Rock_Sandstone_Brick"
    },
    {
      "x": -3,
      "y": 7,
      "z": 5,
      "name": "Rock_Sandstone_Cobble"
    },
    {
      "x": -3,
      "y": 8,
      "z": 5,
      "name": "Rock_Sandstone_Brick"
    },
    {
      "x": -3,
      "y": 9,
      "z": 5,
      "name": "Rock_Sandstone_Brick"
    },
    {
      "x": -3,
      "y": 10,
      "z": 5,
      "name": "Rock_Sandstone_Brick"
    },
    {
      "x": -3,
      "y": 11,
      "z": 5,
      "name": "Rock_Sandstone"
    },
    {
      "x": -3,
      "y": 12,
      "z": 5,
      "name": "Rock_Sandstone_Brick"
    },
    {
      "x": -3,
      "y": 13,
      "z": 5,
      "name": "Rock_Sandstone_Brick"
    },
    {
      "x": -3,
      "y": 14,
      "z": 5,
      "name": "Rock_Sandstone_Brick"
    },
    {
      "x": -3,
      "y": 15,
      "z": 5,
      "name": "Rock_Sandstone_Brick"
    },
    {
      "x": -3,
      "y": 16,
      "z": 5,
      "name": "Rock_Sandstone_Brick"
    },
    {
      "x": -3,
      "y": 17,
      "z": 5,
      "name": "Rock_Sandstone_Brick"
    },
    {
      "x": -3,
      "y": 18,
      "z": 5,
      "name": "Rock_Sandstone_Cobble"
    },
    {
      "x": -3,
      "y": 19,
      "z": 5,
      "name": "Rock_Sandstone_Cobble"
    },
    {
      "x": -3,
      "y": 20,
      "z": 5,
      "name": "Rock_Sandstone_Brick"
    },
    {
      "x": -3,
      "y": 21,
      "z": 5,
      "name": "Rock_Sandstone"
    },
    {
      "x": -3,
      "y": 22,
      "z": 5,
      "name": "Rock_Sandstone_Brick"
    },
    {
      "x": -3,
      "y": 23,
      "z": 5,
      "name": "Rock_Sandstone_Brick"
    },
    {
      "x": -3,
      "y": 24,
      "z": 5,
      "name": "Rock_Sandstone_Brick"
    },
    {
      "x": -3,
      "y": 25,
      "z": 5,
      "name": "Rock_Sandstone_Cobble"
    },
    {
      "x": -3,
      "y": 26,
      "z": 5,
      "name": "Rock_Sandstone_Brick"
    },
    {
      "x": -3,
      "y": 27,
      "z": 5,
      "name": "Rock_Sandstone_Brick"
    },
    {
      "x": -3,
      "y": 28,
      "z": 5,
      "name": "Rock_Sandstone"
    },
    {
      "x": -3,
      "y": 29,
      "z": 5,
      "name": "Rock_Sandstone"
    },
    {
      "x": -3,
      "y": 30,
      "z": 5,
      "name": "Rock_Sandstone"
    },
    {
      "x": -3,
      "y": 31,
      "z": 5,
      "name": "Rock_Sandstone_Brick"
    },
    {
      "x": -3,
      "y": 32,
      "z": 5,
      "name": "Rock_Sandstone_Brick"
    },
    {
      "x": -3,
      "y": 0,
      "z": 6,
      "name": "Rock_Sandstone"
    },
    {
      "x": -3,
      "y": 1,
      "z": 6,
      "name": "Rock_Sandstone_Brick"
    },
    {
      "x": -3,
      "y": 2,
      "z": 6,
      "name": "Rock_Sandstone_Brick"
    },
    {
      "x": -3,
      "y": 3,
      "z": 6,
      "name": "Rock_Sandstone_Brick"
    },
    {
      "x": -3,
      "y": 4,
      "z": 6,
      "name": "Rock_Sandstone_Brick"
    },
    {
      "x": -3,
      "y": 5,
      "z": 6,
      "name": "Rock_Sandstone_Brick"
    },
    {
      "x": -3,
      "y": 6,
      "z": 6,
      "name": "Rock_Sandstone_Cobble"
    },
    {
      "x": -3,
      "y": 7,
      "z": 6,
      "name": "Rock_Sandstone_Brick"
    },
    {
      "x": -3,
      "y": 8,
      "z": 6,
      "name": "Rock_Sandstone_Brick"
    },
    {
      "x": -3,
      "y": 9,
      "z": 6,
      "name": "Rock_Sandstone"
    },
    {
      "x": -3,
      "y": 10,
      "z": 6,
      "name": "Rock_Sandstone_Cobble"
    },
    {
      "x": -3,
      "y": 11,
      "z": 6,
      "name": "Rock_Sandstone_Brick"
    },
    {
      "x": -3,
      "y": 12,
      "z": 6,
      "name": "Rock_Sandstone_Brick"
    },
    {
      "x": -3,
      "y": 13,
      "z": 6,
      "name": "Rock_Sandstone_Brick"
    },
    {
      "x": -3,
      "y": 14,
      "z": 6,
      "name": "Rock_Sandstone"
    },
    {
      "x": -3,
      "y": 15,
      "z": 6,
      "name": "Rock_Sandstone_Brick"
    },
    {
      "x": -3,
      "y": 16,
      "z": 6,
      "name": "Rock_Sandstone"
    },
    {
      "x": -3,
      "y": 17,
      "z": 6,
      "name": "Rock_Sandstone_Brick"
    },
    {
      "x": -3,
      "y": 18,
      "z": 6,
      "name": "Rock_Sandstone_Brick"
    },
    {
      "x": -3,
      "y": 19,
      "z": 6,
      "name": "Rock_Sandstone_Brick"
    },
    {
      "x": -3,
      "y": 20,
      "z": 6,
      "name": "Rock_Sandstone_Brick"
    },
    {
      "x": -3,
      "y": 21,
      "z": 6,
      "name": "Rock_Sandstone_Brick"
    },
    {
      "x": -3,
      "y": 22,
      "z": 6,
      "name": "Rock_Sandstone_Brick"
    },
    {
      "x": -3,
      "y": 23,
      "z": 6,
      "name": "Rock_Sandstone_Brick"
    },
    {
      "x": -3,
      "y": 24,
      "z": 6,
      "name": "Rock_Sandstone_Brick"
    },
    {
      "x": -3,
      "y": 25,
      "z": 6,
      "name": "Rock_Sandstone_Brick"
    },
    {
      "x": -3,
      "y": 26,
      "z": 6,
      "name": "Rock_Sandstone"
    },
    {
      "x": -3,
      "y": 27,
      "z": 6,
      "name": "Rock_Sandstone_Brick"
    },
    {
      "x": -3,
      "y": 28,
      "z": 6,
      "name": "Rock_Sandstone_Cobble"
    },
    {
      "x": -3,
      "y": 29,
      "z": 6,
      "name": "Rock_Sandstone_Brick"
    },
    {
      "x": -3,
      "y": 30,
      "z": 6,
      "name": "Rock_Sandstone"
    },
    {
      "x": -3,
      "y": 31,
      "z": 6,
      "name": "Rock_Sandstone_Brick"
    },
    {
      "x": -3,
      "y": 32,
      "z": 6,
      "name": "Rock_Sandstone_Brick"
    },
    {
      "x": -3,
      "y": 33,
      "z": 6,
      "name": "Rock_Sandstone_Brick"
    },
    {
      "x": -2,
      "y": 32,
      "z": -5,
      "name": "Rock_Sandstone_Brick_Stairs",
      "rotation": 11
    },
    {
      "x": -2,
      "y": 33,
      "z": -5,
      "name": "Rock_Sandstone_Brick",
      "rotation": 3
    },
    {
      "x": -2,
      "y": 34,
      "z": -5,
      "name": "Rock_Sandstone_Brick",
      "rotation": 3
    },
    {
      "x": -2,
      "y": 35,
      "z": -5,
      "name": "Rock_Sandstone_Brick"
    },
    {
      "x": -2,
      "y": 31,
      "z": -4,
      "name": "Rock_Sandstone_Brick_Stairs",
      "rotation": 11
    },
    {
      "x": -2,
      "y": 32,
      "z": -4,
      "name": "Rock_Sandstone_Brick",
      "rotation": 3
    },
    {
      "x": -2,
      "y": 33,
      "z": -4,
      "name": "Rock_Sandstone_Brick",
      "rotation": 3
    },
    {
      "x": -2,
      "y": 34,
      "z": -4,
      "name": "Rock_Sandstone_Brick",
      "rotation": 3
    },
    {
      "x": -2,
      "y": 35,
      "z": -4,
      "name": "Rock_Sandstone_Brick"
    },
    {
      "x": -2,
      "y": 30,
      "z": -3,
      "name": "Rock_Sandstone_Brick_Stairs",
      "rotation": 11
    },
    {
      "x": -2,
      "y": 31,
      "z": -3,
      "name": "Rock_Sandstone_Brick",
      "rotation": 3
    },
    {
      "x": -2,
      "y": 32,
      "z": -3,
      "name": "Rock_Sandstone_Brick",
      "rotation": 3
    },
    {
      "x": -2,
      "y": 33,
      "z": -3,
      "name": "Rock_Sandstone_Brick",
      "rotation": 3
    },
    {
      "x": -2,
      "y": 34,
      "z": -3,
      "name": "Rock_Sandstone_Brick",
      "rotation": 3
    },
    {
      "x": -2,
      "y": 35,
      "z": -3,
      "name": "Rock_Sandstone_Brick"
    },
    {
      "x": -2,
      "y": 32,
      "z": -2,
      "name": "Rock_Sandstone_Brick"
    },
    {
      "x": -2,
      "y": 33,
      "z": -2,
      "name": "Rock_Sandstone_Brick"
    },
    {
      "x": -2,
      "y": 34,
      "z": -2,
      "name": "Rock_Sandstone_Brick"
    },
    {
      "x": -2,
      "y": 35,
      "z": -2,
      "name": "Rock_Sandstone_Brick"
    },
    {
      "x": -2,
      "y": 33,
      "z": -1,
      "name": "Rock_Sandstone_Brick"
    },
    {
      "x": -2,
      "y": 34,
      "z": -1,
      "name": "Rock_Sandstone_Brick"
    },
    {
      "x": -2,
      "y": 35,
      "z": -1,
      "name": "Rock_Sandstone_Brick"
    },
    {
      "x": -2,
      "y": 33,
      "z": 0,
      "name": "Rock_Sandstone_Brick"
    },
    {
      "x": -2,
      "y": 34,
      "z": 0,
      "name": "Rock_Sandstone_Brick"
    },
    {
      "x": -2,
      "y": 35,
      "z": 0,
      "name": "Rock_Sandstone_Brick"
    },
    {
      "x": -2,
      "y": 33,
      "z": 1,
      "name": "Rock_Sandstone_Brick"
    },
    {
      "x": -2,
      "y": 34,
      "z": 1,
      "name": "Rock_Sandstone_Brick"
    },
    {
      "x": -2,
      "y": 35,
      "z": 1,
      "name": "Rock_Sandstone_Brick"
    },
    {
      "x": -2,
      "y": 34,
      "z": 2,
      "name": "Rock_Sandstone_Brick"
    },
    {
      "x": -2,
      "y": 30,
      "z": 4,
      "name": "Rock_Sandstone_Brick_Stairs",
      "rotation": 33
    },
    {
      "x": -2,
      "y": 31,
      "z": 5,
      "name": "Rock_Sandstone_Brick_Stairs",
      "rotation": 33
    },
    {
      "x": -2,
      "y": 32,
      "z": 5,
      "name": "Rock_Sandstone_Brick",
      "rotation": 1
    },
    {
      "x": -2,
      "y": 33,
      "z": 5,
      "name": "Rock_Sandstone_Brick",
      "rotation": 1
    },
    {
      "x": -2,
      "y": 32,
      "z": 6,
      "name": "Rock_Sandstone_Brick_Stairs",
      "rotation": 33
    },
    {
      "x": -2,
      "y": 33,
      "z": 6,
      "name": "Rock_Sandstone_Brick",
      "rotation": 1
    },
    {
      "x": -1,
      "y": 33,
      "z": -5,
      "name": "Rock_Sandstone_Brick",
      "rotation": 3
    },
    {
      "x": -1,
      "y": 34,
      "z": -5,
      "name": "Rock_Sandstone_Brick",
      "rotation": 3
    },
    {
      "x": -1,
      "y": 35,
      "z": -5,
      "name": "Rock_Sandstone_Brick"
    },
    {
      "x": -1,
      "y": 32,
      "z": -4,
      "name": "Rock_Sandstone",
      "rotation": 3
    },
    {
      "x": -1,
      "y": 33,
      "z": -4,
      "name": "Rock_Sandstone_Brick",
      "rotation": 3
    },
    {
      "x": -1,
      "y": 34,
      "z": -4,
      "name": "Rock_Sandstone_Brick",
      "rotation": 3
    },
    {
      "x": -1,
      "y": 35,
      "z": -4,
      "name": "Rock_Sandstone_Brick"
    },
    {
      "x": -1,
      "y": 31,
      "z": -3,
      "name": "Rock_Sandstone_Brick",
      "rotation": 3
    },
    {
      "x": -1,
      "y": 32,
      "z": -3,
      "name": "Rock_Sandstone_Brick",
      "rotation": 3
    },
    {
      "x": -1,
      "y": 33,
      "z": -3,
      "name": "Rock_Sandstone_Brick",
      "rotation": 3
    },
    {
      "x": -1,
      "y": 34,
      "z": -3,
      "name": "Rock_Sandstone_Brick",
      "rotation": 3
    },
    {
      "x": -1,
      "y": 35,
      "z": -3,
      "name": "Rock_Sandstone_Brick"
    },
    {
      "x": -1,
      "y": 33,
      "z": -2,
      "name": "Rock_Sandstone_Brick"
    },
    {
      "x": -1,
      "y": 34,
      "z": -2,
      "name": "Rock_Sandstone_Brick"
    },
    {
      "x": -1,
      "y": 35,
      "z": -2,
      "name": "Rock_Sandstone_Brick"
    },
    {
      "x": -1,
      "y": 34,
      "z": -1,
      "name": "Rock_Sandstone_Brick"
    },
    {
      "x": -1,
      "y": 35,
      "z": -1,
      "name": "Rock_Sandstone_Brick"
    },
    {
      "x": -1,
      "y": 34,
      "z": 0,
      "name": "Rock_Sandstone_Brick"
    },
    {
      "x": -1,
      "y": 35,
      "z": 0,
      "name": "Rock_Sandstone_Brick"
    },
    {
      "x": -1,
      "y": 34,
      "z": 1,
      "name": "Rock_Sandstone_Brick"
    },
    {
      "x": -1,
      "y": 35,
      "z": 1,
      "name": "Rock_Sandstone_Brick"
    },
    {
      "x": -1,
      "y": 34,
      "z": 2,
      "name": "Rock_Sandstone_Brick"
    },
    {
      "x": -1,
      "y": 35,
      "z": 2,
      "name": "Rock_Sandstone_Brick"
    },
    {
      "x": -1,
      "y": 34,
      "z": 3,
      "name": "Rock_Sandstone_Brick"
    },
    {
      "x": -1,
      "y": 31,
      "z": 4,
      "name": "Rock_Sandstone_Brick",
      "rotation": 1
    },
    {
      "x": -1,
      "y": 32,
      "z": 4,
      "name": "Rock_Sandstone_Cobble",
      "rotation": 1
    },
    {
      "x": -1,
      "y": 33,
      "z": 4,
      "name": "Rock_Sandstone_Brick",
      "rotation": 1
    },
    {
      "x": -1,
      "y": 34,
      "z": 4,
      "name": "Rock_Sandstone_Brick",
      "rotation": 1
    },
    {
      "x": -1,
      "y": 32,
      "z": 5,
      "name": "Rock_Sandstone_Brick",
      "rotation": 1
    },
    {
      "x": -1,
      "y": 33,
      "z": 5,
      "name": "Rock_Sandstone_Brick",
      "rotation": 1
    },
    {
      "x": -1,
      "y": 34,
      "z": 5,
      "name": "Rock_Sandstone_Brick",
      "rotation": 1
    },
    {
      "x": -1,
      "y": 33,
      "z": 6,
      "name": "Rock_Sandstone_Brick",
      "rotation": 1
    },
    {
      "x": -1,
      "y": 34,
      "z": 6,
      "name": "Rock_Sandstone_Brick",
      "rotation": 1
    },
    {
      "x": 0,
      "y": 33,
      "z": -5,
      "name": "Rock_Sandstone_Brick",
      "rotation": 3
    },
    {
      "x": 0,
      "y": 34,
      "z": -5,
      "name": "Rock_Sandstone_Brick",
      "rotation": 3
    },
    {
      "x": 0,
      "y": 35,
      "z": -5,
      "name": "Rock_Sandstone_Brick"
    },
    {
      "x": 0,
      "y": 32,
      "z": -4,
      "name": "Rock_Sandstone_Cobble",
      "rotation": 3
    },
    {
      "x": 0,
      "y": 33,
      "z": -4,
      "name": "Rock_Sandstone_Brick",
      "rotation": 3
    },
    {
      "x": 0,
      "y": 34,
      "z": -4,
      "name": "Rock_Sandstone_Brick",
      "rotation": 3
    },
    {
      "x": 0,
      "y": 35,
      "z": -4,
      "name": "Rock_Sandstone_Brick"
    },
    {
      "x": 0,
      "y": 31,
      "z": -3,
      "name": "Rock_Sandstone",
      "rotation": 3
    },
    {
      "x": 0,
      "y": 32,
      "z": -3,
      "name": "Rock_Sandstone_Brick",
      "rotation": 3
    },
    {
      "x": 0,
      "y": 33,
      "z": -3,
      "name": "Rock_Sandstone_Brick",
      "rotation": 3
    },
    {
      "x": 0,
      "y": 34,
      "z": -3,
      "name": "Rock_Sandstone_Brick",
      "rotation": 3
    },
    {
      "x": 0,
      "y": 35,
      "z": -3,
      "name": "Rock_Sandstone_Brick"
    },
    {
      "x": 0,
      "y": 33,
      "z": -2,
      "name": "Rock_Sandstone_Brick"
    },
    {
      "x": 0,
      "y": 34,
      "z": -2,
      "name": "Rock_Sandstone_Brick"
    },
    {
      "x": 0,
      "y": 35,
      "z": -2,
      "name": "Rock_Sandstone_Brick"
    },
    {
      "x": 0,
      "y": 34,
      "z": -1,
      "name": "Rock_Sandstone_Brick"
    },
    {
      "x": 0,
      "y": 35,
      "z": -1,
      "name": "Rock_Sandstone_Brick"
    },
    {
      "x": 0,
      "y": 34,
      "z": 0,
      "name": "Rock_Sandstone_Brick"
    },
    {
      "x": 0,
      "y": 35,
      "z": 0,
      "name": "Rock_Sandstone_Brick"
    },
    {
      "x": 0,
      "y": 34,
      "z": 1,
      "name": "Rock_Sandstone_Brick"
    },
    {
      "x": 0,
      "y": 35,
      "z": 1,
      "name": "Rock_Sandstone_Brick"
    },
    {
      "x": 0,
      "y": 34,
      "z": 2,
      "name": "Rock_Sandstone_Brick"
    },
    {
      "x": 0,
      "y": 35,
      "z": 2,
      "name": "Rock_Sandstone_Brick"
    },
    {
      "x": 0,
      "y": 33,
      "z": 3,
      "name": "Rock_Sandstone_Brick"
    },
    {
      "x": 0,
      "y": 34,
      "z": 3,
      "name": "Rock_Sandstone_Brick"
    },
    {
      "x": 0,
      "y": 35,
      "z": 3,
      "name": "Rock_Sandstone_Brick"
    },
    {
      "x": 0,
      "y": 31,
      "z": 4,
      "name": "Rock_Sandstone",
      "rotation": 1
    },
    {
      "x": 0,
      "y": 32,
      "z": 4,
      "name": "Rock_Sandstone_Brick",
      "rotation": 1
    },
    {
      "x": 0,
      "y": 33,
      "z": 4,
      "name": "Rock_Sandstone_Brick",
      "rotation": 1
    },
    {
      "x": 0,
      "y": 34,
      "z": 4,
      "name": "Rock_Sandstone_Brick",
      "rotation": 1
    },
    {
      "x": 0,
      "y": 35,
      "z": 4,
      "name": "Rock_Sandstone_Brick"
    },
    {
      "x": 0,
      "y": 32,
      "z": 5,
      "name": "Rock_Sandstone",
      "rotation": 1
    },
    {
      "x": 0,
      "y": 33,
      "z": 5,
      "name": "Rock_Sandstone_Brick",
      "rotation": 1
    },
    {
      "x": 0,
      "y": 34,
      "z": 5,
      "name": "Rock_Sandstone_Brick",
      "rotation": 1
    },
    {
      "x": 0,
      "y": 35,
      "z": 5,
      "name": "Rock_Sandstone_Brick"
    },
    {
      "x": 0,
      "y": 33,
      "z": 6,
      "name": "Rock_Sandstone_Brick",
      "rotation": 1
    },
    {
      "x": 0,
      "y": 34,
      "z": 6,
      "name": "Rock_Sandstone_Brick",
      "rotation": 1
    },
    {
      "x": 0,
      "y": 35,
      "z": 6,
      "name": "Rock_Sandstone_Brick"
    },
    {
      "x": 1,
      "y": 33,
      "z": -5,
      "name": "Rock_Sandstone_Brick"
    },
    {
      "x": 1,
      "y": 34,
      "z": -5,
      "name": "Rock_Sandstone_Brick"
    },
    {
      "x": 1,
      "y": 35,
      "z": -5,
      "name": "Rock_Sandstone_Brick"
    },
    {
      "x": 1,
      "y": 32,
      "z": -4,
      "name": "Rock_Sandstone_Brick"
    },
    {
      "x": 1,
      "y": 33,
      "z": -4,
      "name": "Rock_Sandstone_Brick"
    },
    {
      "x": 1,
      "y": 34,
      "z": -4,
      "name": "Rock_Sandstone_Brick"
    },
    {
      "x": 1,
      "y": 35,
      "z": -4,
      "name": "Rock_Sandstone_Brick"
    },
    {
      "x": 1,
      "y": 31,
      "z": -3,
      "name": "Rock_Sandstone_Brick"
    },
    {
      "x": 1,
      "y": 32,
      "z": -3,
      "name": "Rock_Sandstone_Brick"
    },
    {
      "x": 1,
      "y": 33,
      "z": -3,
      "name": "Rock_Sandstone_Brick"
    },
    {
      "x": 1,
      "y": 34,
      "z": -3,
      "name": "Rock_Sandstone_Brick"
    },
    {
      "x": 1,
      "y": 35,
      "z": -3,
      "name": "Rock_Sandstone_Brick"
    },
    {
      "x": 1,
      "y": 33,
      "z": -2,
      "name": "Rock_Sandstone_Brick"
    },
    {
      "x": 1,
      "y": 34,
      "z": -2,
      "name": "Rock_Sandstone_Brick"
    },
    {
      "x": 1,
      "y": 35,
      "z": -2,
      "name": "Rock_Sandstone_Brick"
    },
    {
      "x": 1,
      "y": 34,
      "z": -1,
      "name": "Rock_Sandstone_Brick"
    },
    {
      "x": 1,
      "y": 35,
      "z": -1,
      "name": "Rock_Sandstone_Brick"
    },
    {
      "x": 1,
      "y": 34,
      "z": 0,
      "name": "Rock_Sandstone_Brick"
    },
    {
      "x": 1,
      "y": 35,
      "z": 0,
      "name": "Rock_Sandstone_Brick"
    },
    {
      "x": 1,
      "y": 34,
      "z": 1,
      "name": "Rock_Sandstone_Brick"
    },
    {
      "x": 1,
      "y": 35,
      "z": 1,
      "name": "Rock_Sandstone_Brick"
    },
    {
      "x": 1,
      "y": 34,
      "z": 2,
      "name": "Rock_Sandstone_Brick"
    },
    {
      "x": 1,
      "y": 35,
      "z": 2,
      "name": "Rock_Sandstone_Brick"
    },
    {
      "x": 1,
      "y": 33,
      "z": 3,
      "name": "Rock_Sandstone_Brick"
    },
    {
      "x": 1,
      "y": 34,
      "z": 3,
      "name": "Rock_Sandstone_Brick"
    },
    {
      "x": 1,
      "y": 35,
      "z": 3,
      "name": "Rock_Sandstone_Brick"
    },
    {
      "x": 1,
      "y": 31,
      "z": 4,
      "name": "Rock_Sandstone_Brick"
    },
    {
      "x": 1,
      "y": 32,
      "z": 4,
      "name": "Rock_Sandstone_Brick"
    },
    {
      "x": 1,
      "y": 33,
      "z": 4,
      "name": "Rock_Sandstone_Brick"
    },
    {
      "x": 1,
      "y": 34,
      "z": 4,
      "name": "Rock_Sandstone_Brick"
    },
    {
      "x": 1,
      "y": 35,
      "z": 4,
      "name": "Rock_Sandstone_Brick"
    },
    {
      "x": 1,
      "y": 32,
      "z": 5,
      "name": "Rock_Sandstone_Brick"
    },
    {
      "x": 1,
      "y": 33,
      "z": 5,
      "name": "Rock_Sandstone_Brick"
    },
    {
      "x": 1,
      "y": 34,
      "z": 5,
      "name": "Rock_Sandstone_Brick"
    },
    {
      "x": 1,
      "y": 35,
      "z": 5,
      "name": "Rock_Sandstone_Brick"
    },
    {
      "x": 1,
      "y": 33,
      "z": 6,
      "name": "Rock_Sandstone_Brick"
    },
    {
      "x": 1,
      "y": 34,
      "z": 6,
      "name": "Rock_Sandstone_Brick"
    },
    {
      "x": 1,
      "y": 35,
      "z": 6,
      "name": "Rock_Sandstone_Brick"
    },
    {
      "x": 2,
      "y": 33,
      "z": -5,
      "name": "Rock_Sandstone_Brick"
    },
    {
      "x": 2,
      "y": 34,
      "z": -5,
      "name": "Rock_Sandstone_Brick"
    },
    {
      "x": 2,
      "y": 35,
      "z": -5,
      "name": "Rock_Sandstone_Brick"
    },
    {
      "x": 2,
      "y": 32,
      "z": -4,
      "name": "Rock_Sandstone_Brick"
    },
    {
      "x": 2,
      "y": 33,
      "z": -4,
      "name": "Rock_Sandstone_Brick"
    },
    {
      "x": 2,
      "y": 34,
      "z": -4,
      "name": "Rock_Sandstone_Brick"
    },
    {
      "x": 2,
      "y": 35,
      "z": -4,
      "name": "Rock_Sandstone_Brick"
    },
    {
      "x": 2,
      "y": 31,
      "z": -3,
      "name": "Rock_Sandstone_Brick"
    },
    {
      "x": 2,
      "y": 32,
      "z": -3,
      "name": "Rock_Sandstone_Brick"
    },
    {
      "x": 2,
      "y": 33,
      "z": -3,
      "name": "Rock_Sandstone_Brick"
    },
    {
      "x": 2,
      "y": 34,
      "z": -3,
      "name": "Rock_Sandstone_Brick"
    },
    {
      "x": 2,
      "y": 35,
      "z": -3,
      "name": "Rock_Sandstone_Brick"
    },
    {
      "x": 2,
      "y": 33,
      "z": -2,
      "name": "Rock_Sandstone_Brick"
    },
    {
      "x": 2,
      "y": 34,
      "z": -2,
      "name": "Rock_Sandstone_Brick"
    },
    {
      "x": 2,
      "y": 35,
      "z": -2,
      "name": "Rock_Sandstone_Brick"
    },
    {
      "x": 2,
      "y": 34,
      "z": -1,
      "name": "Rock_Sandstone_Brick"
    },
    {
      "x": 2,
      "y": 35,
      "z": -1,
      "name": "Rock_Sandstone_Brick"
    },
    {
      "x": 2,
      "y": 34,
      "z": 0,
      "name": "Rock_Sandstone_Brick"
    },
    {
      "x": 2,
      "y": 35,
      "z": 0,
      "name": "Rock_Sandstone_Brick"
    },
    {
      "x": 2,
      "y": 34,
      "z": 1,
      "name": "Rock_Sandstone_Brick"
    },
    {
      "x": 2,
      "y": 35,
      "z": 1,
      "name": "Rock_Sandstone_Brick"
    },
    {
      "x": 2,
      "y": 34,
      "z": 2,
      "name": "Rock_Sandstone_Brick"
    },
    {
      "x": 2,
      "y": 35,
      "z": 2,
      "name": "Rock_Sandstone_Brick"
    },
    {
      "x": 2,
      "y": 33,
      "z": 3,
      "name": "Rock_Sandstone_Brick"
    },
    {
      "x": 2,
      "y": 34,
      "z": 3,
      "name": "Rock_Sandstone_Brick"
    },
    {
      "x": 2,
      "y": 35,
      "z": 3,
      "name": "Rock_Sandstone_Brick"
    },
    {
      "x": 2,
      "y": 31,
      "z": 4,
      "name": "Rock_Sandstone_Brick"
    },
    {
      "x": 2,
      "y": 32,
      "z": 4,
      "name": "Rock_Sandstone_Brick"
    },
    {
      "x": 2,
      "y": 33,
      "z": 4,
      "name": "Rock_Sandstone_Brick"
    },
    {
      "x": 2,
      "y": 34,
      "z": 4,
      "name": "Rock_Sandstone_Brick"
    },
    {
      "x": 2,
      "y": 35,
      "z": 4,
      "name": "Rock_Sandstone_Brick"
    },
    {
      "x": 2,
      "y": 32,
      "z": 5,
      "name": "Rock_Sandstone_Brick"
    },
    {
      "x": 2,
      "y": 33,
      "z": 5,
      "name": "Rock_Sandstone_Brick"
    },
    {
      "x": 2,
      "y": 34,
      "z": 5,
      "name": "Rock_Sandstone_Brick"
    },
    {
      "x": 2,
      "y": 35,
      "z": 5,
      "name": "Rock_Sandstone_Brick"
    },
    {
      "x": 2,
      "y": 33,
      "z": 6,
      "name": "Rock_Sandstone_Brick"
    },
    {
      "x": 2,
      "y": 34,
      "z": 6,
      "name": "Rock_Sandstone_Brick"
    },
    {
      "x": 2,
      "y": 35,
      "z": 6,
      "name": "Rock_Sandstone_Brick"
    },
    {
      "x": 3,
      "y": 32,
      "z": -5,
      "name": "Rock_Sandstone_Brick_Stairs",
      "rotation": 9
    },
    {
      "x": 3,
      "y": 33,
      "z": -5,
      "name": "Rock_Sandstone_Brick",
      "rotation": 3
    },
    {
      "x": 3,
      "y": 34,
      "z": -5,
      "name": "Rock_Sandstone_Brick",
      "rotation": 3
    },
    {
      "x": 3,
      "y": 35,
      "z": -5,
      "name": "Rock_Sandstone_Brick"
    },
    {
      "x": 3,
      "y": 31,
      "z": -4,
      "name": "Rock_Sandstone_Brick_Stairs",
      "rotation": 9
    },
    {
      "x": 3,
      "y": 32,
      "z": -4,
      "name": "Rock_Sandstone",
      "rotation": 3
    },
    {
      "x": 3,
      "y": 33,
      "z": -4,
      "name": "Rock_Sandstone_Brick",
      "rotation": 3
    },
    {
      "x": 3,
      "y": 34,
      "z": -4,
      "name": "Rock_Sandstone_Brick",
      "rotation": 3
    },
    {
      "x": 3,
      "y": 35,
      "z": -4,
      "name": "Rock_Sandstone_Brick"
    },
    {
      "x": 3,
      "y": 30,
      "z": -3,
      "name": "Rock_Sandstone_Brick_Stairs",
      "rotation": 9
    },
    {
      "x": 3,
      "y": 31,
      "z": -3,
      "name": "Rock_Sandstone",
      "rotation": 3
    },
    {
      "x": 3,
      "y": 32,
      "z": -3,
      "name": "Rock_Sandstone_Cobble",
      "rotation": 3
    },
    {
      "x": 3,
      "y": 33,
      "z": -3,
      "name": "Rock_Sandstone_Brick",
      "rotation": 3
    },
    {
      "x": 3,
      "y": 34,
      "z": -3,
      "name": "Rock_Sandstone_Brick",
      "rotation": 3
    },
    {
      "x": 3,
      "y": 35,
      "z": -3,
      "name": "Rock_Sandstone_Brick"
    },
    {
      "x": 3,
      "y": 32,
      "z": -2,
      "name": "Rock_Sandstone_Brick"
    },
    {
      "x": 3,
      "y": 33,
      "z": -2,
      "name": "Rock_Sandstone_Brick"
    },
    {
      "x": 3,
      "y": 34,
      "z": -2,
      "name": "Rock_Sandstone_Brick"
    },
    {
      "x": 3,
      "y": 35,
      "z": -2,
      "name": "Rock_Sandstone_Brick"
    },
    {
      "x": 3,
      "y": 33,
      "z": -1,
      "name": "Rock_Sandstone_Brick"
    },
    {
      "x": 3,
      "y": 34,
      "z": -1,
      "name": "Rock_Sandstone_Brick"
    },
    {
      "x": 3,
      "y": 35,
      "z": -1,
      "name": "Rock_Sandstone_Brick"
    },
    {
      "x": 3,
      "y": 33,
      "z": 0,
      "name": "Rock_Sandstone_Brick"
    },
    {
      "x": 3,
      "y": 34,
      "z": 0,
      "name": "Rock_Sandstone_Brick"
    },
    {
      "x": 3,
      "y": 35,
      "z": 0,
      "name": "Rock_Sandstone_Brick"
    },
    {
      "x": 3,
      "y": 33,
      "z": 1,
      "name": "Rock_Sandstone_Brick"
    },
    {
      "x": 3,
      "y": 34,
      "z": 1,
      "name": "Rock_Sandstone_Brick"
    },
    {
      "x": 3,
      "y": 35,
      "z": 1,
      "name": "Rock_Sandstone_Brick"
    },
    {
      "x": 3,
      "y": 33,
      "z": 2,
      "name": "Rock_Sandstone_Brick"
    },
    {
      "x": 3,
      "y": 34,
      "z": 2,
      "name": "Rock_Sandstone_Brick"
    },
    {
      "x": 3,
      "y": 35,
      "z": 2,
      "name": "Rock_Sandstone_Brick"
    },
    {
      "x": 3,
      "y": 32,
      "z": 3,
      "name": "Rock_Sandstone_Brick"
    },
    {
      "x": 3,
      "y": 33,
      "z": 3,
      "name": "Rock_Sandstone_Brick"
    },
    {
      "x": 3,
      "y": 34,
      "z": 3,
      "name": "Rock_Sandstone_Brick"
    },
    {
      "x": 3,
      "y": 35,
      "z": 3,
      "name": "Rock_Sandstone_Brick"
    },
    {
      "x": 3,
      "y": 30,
      "z": 4,
      "name": "Rock_Sandstone_Brick_Stairs",
      "rotation": 9
    },
    {
      "x": 3,
      "y": 31,
      "z": 4,
      "name": "Rock_Sandstone",
      "rotation": 1
    },
    {
      "x": 3,
      "y": 32,
      "z": 4,
      "name": "Rock_Sandstone",
      "rotation": 1
    },
    {
      "x": 3,
      "y": 33,
      "z": 4,
      "name": "Rock_Sandstone_Brick",
      "rotation": 1
    },
    {
      "x": 3,
      "y": 34,
      "z": 4,
      "name": "Rock_Sandstone_Brick",
      "rotation": 1
    },
    {
      "x": 3,
      "y": 35,
      "z": 4,
      "name": "Rock_Sandstone_Brick"
    },
    {
      "x": 3,
      "y": 31,
      "z": 5,
      "name": "Rock_Sandstone_Brick_Stairs",
      "rotation": 9
    },
    {
      "x": 3,
      "y": 32,
      "z": 5,
      "name": "Rock_Sandstone",
      "rotation": 1
    },
    {
      "x": 3,
      "y": 33,
      "z": 5,
      "name": "Rock_Sandstone_Brick",
      "rotation": 1
    },
    {
      "x": 3,
      "y": 34,
      "z": 5,
      "name": "Rock_Sandstone_Brick",
      "rotation": 1
    },
    {
      "x": 3,
      "y": 35,
      "z": 5,
      "name": "Rock_Sandstone_Brick"
    },
    {
      "x": 3,
      "y": 32,
      "z": 6,
      "name": "Rock_Sandstone_Brick_Stairs",
      "rotation": 9
    },
    {
      "x": 3,
      "y": 33,
      "z": 6,
      "name": "Rock_Sandstone_Brick",
      "rotation": 1
    },
    {
      "x": 3,
      "y": 34,
      "z": 6,
      "name": "Rock_Sandstone_Brick",
      "rotation": 1
    },
    {
      "x": 3,
      "y": 35,
      "z": 6,
      "name": "Rock_Sandstone_Brick"
    },
    {
      "x": 4,
      "y": 0,
      "z": -5,
      "name": "Rock_Sandstone_Brick"
    },
    {
      "x": 4,
      "y": 1,
      "z": -5,
      "name": "Rock_Sandstone_Brick"
    },
    {
      "x": 4,
      "y": 2,
      "z": -5,
      "name": "Rock_Sandstone"
    },
    {
      "x": 4,
      "y": 3,
      "z": -5,
      "name": "Rock_Sandstone_Brick"
    },
    {
      "x": 4,
      "y": 4,
      "z": -5,
      "name": "Rock_Sandstone_Brick"
    },
    {
      "x": 4,
      "y": 5,
      "z": -5,
      "name": "Rock_Sandstone"
    },
    {
      "x": 4,
      "y": 6,
      "z": -5,
      "name": "Rock_Sandstone_Brick"
    },
    {
      "x": 4,
      "y": 7,
      "z": -5,
      "name": "Rock_Sandstone_Brick"
    },
    {
      "x": 4,
      "y": 8,
      "z": -5,
      "name": "Rock_Sandstone_Brick"
    },
    {
      "x": 4,
      "y": 9,
      "z": -5,
      "name": "Rock_Sandstone_Brick"
    },
    {
      "x": 4,
      "y": 10,
      "z": -5,
      "name": "Rock_Sandstone_Brick"
    },
    {
      "x": 4,
      "y": 11,
      "z": -5,
      "name": "Rock_Sandstone_Brick"
    },
    {
      "x": 4,
      "y": 12,
      "z": -5,
      "name": "Rock_Sandstone_Brick"
    },
    {
      "x": 4,
      "y": 13,
      "z": -5,
      "name": "Rock_Sandstone_Brick"
    },
    {
      "x": 4,
      "y": 14,
      "z": -5,
      "name": "Rock_Sandstone_Cobble"
    },
    {
      "x": 4,
      "y": 15,
      "z": -5,
      "name": "Rock_Sandstone_Brick"
    },
    {
      "x": 4,
      "y": 16,
      "z": -5,
      "name": "Rock_Sandstone"
    },
    {
      "x": 4,
      "y": 17,
      "z": -5,
      "name": "Rock_Sandstone_Brick"
    },
    {
      "x": 4,
      "y": 18,
      "z": -5,
      "name": "Rock_Sandstone_Brick"
    },
    {
      "x": 4,
      "y": 19,
      "z": -5,
      "name": "Rock_Sandstone"
    },
    {
      "x": 4,
      "y": 20,
      "z": -5,
      "name": "Rock_Sandstone_Brick"
    },
    {
      "x": 4,
      "y": 21,
      "z": -5,
      "name": "Rock_Sandstone_Cobble"
    },
    {
      "x": 4,
      "y": 22,
      "z": -5,
      "name": "Rock_Sandstone_Brick"
    },
    {
      "x": 4,
      "y": 23,
      "z": -5,
      "name": "Rock_Sandstone_Brick"
    },
    {
      "x": 4,
      "y": 24,
      "z": -5,
      "name": "Rock_Sandstone_Brick"
    },
    {
      "x": 4,
      "y": 25,
      "z": -5,
      "name": "Rock_Sandstone_Brick"
    },
    {
      "x": 4,
      "y": 26,
      "z": -5,
      "name": "Rock_Sandstone"
    },
    {
      "x": 4,
      "y": 27,
      "z": -5,
      "name": "Rock_Sandstone_Brick"
    },
    {
      "x": 4,
      "y": 28,
      "z": -5,
      "name": "Rock_Sandstone"
    },
    {
      "x": 4,
      "y": 29,
      "z": -5,
      "name": "Rock_Sandstone_Brick"
    },
    {
      "x": 4,
      "y": 30,
      "z": -5,
      "name": "Rock_Sandstone"
    },
    {
      "x": 4,
      "y": 31,
      "z": -5,
      "name": "Rock_Sandstone_Brick"
    },
    {
      "x": 4,
      "y": 32,
      "z": -5,
      "name": "Rock_Sandstone"
    },
    {
      "x": 4,
      "y": 33,
      "z": -5,
      "name": "Rock_Sandstone_Brick"
    },
    {
      "x": 4,
      "y": 34,
      "z": -5,
      "name": "Rock_Sandstone_Brick"
    },
    {
      "x": 4,
      "y": 35,
      "z": -5,
      "name": "Rock_Sandstone_Brick"
    },
    {
      "x": 4,
      "y": 0,
      "z": -4,
      "name": "Rock_Sandstone_Brick"
    },
    {
      "x": 4,
      "y": 1,
      "z": -4,
      "name": "Rock_Sandstone"
    },
    {
      "x": 4,
      "y": 2,
      "z": -4,
      "name": "Rock_Sandstone_Brick"
    },
    {
      "x": 4,
      "y": 3,
      "z": -4,
      "name": "Rock_Sandstone_Cobble"
    },
    {
      "x": 4,
      "y": 4,
      "z": -4,
      "name": "Rock_Sandstone_Brick"
    },
    {
      "x": 4,
      "y": 5,
      "z": -4,
      "name": "Rock_Sandstone_Brick"
    },
    {
      "x": 4,
      "y": 6,
      "z": -4,
      "name": "Rock_Sandstone"
    },
    {
      "x": 4,
      "y": 7,
      "z": -4,
      "name": "Rock_Sandstone"
    },
    {
      "x": 4,
      "y": 8,
      "z": -4,
      "name": "Rock_Sandstone_Brick"
    },
    {
      "x": 4,
      "y": 9,
      "z": -4,
      "name": "Rock_Sandstone_Brick"
    },
    {
      "x": 4,
      "y": 10,
      "z": -4,
      "name": "Rock_Sandstone"
    },
    {
      "x": 4,
      "y": 11,
      "z": -4,
      "name": "Rock_Sandstone_Brick"
    },
    {
      "x": 4,
      "y": 12,
      "z": -4,
      "name": "Rock_Sandstone_Brick"
    },
    {
      "x": 4,
      "y": 13,
      "z": -4,
      "name": "Rock_Sandstone_Brick"
    },
    {
      "x": 4,
      "y": 14,
      "z": -4,
      "name": "Rock_Sandstone_Brick"
    },
    {
      "x": 4,
      "y": 15,
      "z": -4,
      "name": "Rock_Sandstone_Brick"
    },
    {
      "x": 4,
      "y": 16,
      "z": -4,
      "name": "Rock_Sandstone_Cobble"
    },
    {
      "x": 4,
      "y": 17,
      "z": -4,
      "name": "Rock_Sandstone"
    },
    {
      "x": 4,
      "y": 18,
      "z": -4,
      "name": "Rock_Sandstone_Brick"
    },
    {
      "x": 4,
      "y": 19,
      "z": -4,
      "name": "Rock_Sandstone_Brick"
    },
    {
      "x": 4,
      "y": 20,
      "z": -4,
      "name": "Rock_Sandstone_Brick"
    },
    {
      "x": 4,
      "y": 21,
      "z": -4,
      "name": "Rock_Sandstone_Brick"
    },
    {
      "x": 4,
      "y": 22,
      "z": -4,
      "name": "Rock_Sandstone_Brick"
    },
    {
      "x": 4,
      "y": 23,
      "z": -4,
      "name": "Rock_Sandstone_Brick"
    },
    {
      "x": 4,
      "y": 24,
      "z": -4,
      "name": "Rock_Sandstone_Brick"
    },
    {
      "x": 4,
      "y": 25,
      "z": -4,
      "name": "Rock_Sandstone_Brick"
    },
    {
      "x": 4,
      "y": 26,
      "z": -4,
      "name": "Rock_Sandstone"
    },
    {
      "x": 4,
      "y": 27,
      "z": -4,
      "name": "Rock_Sandstone_Brick"
    },
    {
      "x": 4,
      "y": 28,
      "z": -4,
      "name": "Rock_Sandstone_Brick"
    },
    {
      "x": 4,
      "y": 29,
      "z": -4,
      "name": "Rock_Sandstone_Brick"
    },
    {
      "x": 4,
      "y": 30,
      "z": -4,
      "name": "Rock_Sandstone_Brick"
    },
    {
      "x": 4,
      "y": 31,
      "z": -4,
      "name": "Rock_Sandstone"
    },
    {
      "x": 4,
      "y": 32,
      "z": -4,
      "name": "Rock_Sandstone_Brick"
    },
    {
      "x": 4,
      "y": 33,
      "z": -4,
      "name": "Rock_Sandstone_Brick"
    },
    {
      "x": 4,
      "y": 34,
      "z": -4,
      "name": "Rock_Sandstone_Brick"
    },
    {
      "x": 4,
      "y": 35,
      "z": -4,
      "name": "Rock_Sandstone_Brick"
    },
    {
      "x": 4,
      "y": 0,
      "z": -3,
      "name": "Rock_Sandstone"
    },
    {
      "x": 4,
      "y": 1,
      "z": -3,
      "name": "Rock_Sandstone_Brick"
    },
    {
      "x": 4,
      "y": 2,
      "z": -3,
      "name": "Rock_Sandstone_Brick"
    },
    {
      "x": 4,
      "y": 3,
      "z": -3,
      "name": "Rock_Sandstone_Brick"
    },
    {
      "x": 4,
      "y": 4,
      "z": -3,
      "name": "Rock_Sandstone_Brick"
    },
    {
      "x": 4,
      "y": 5,
      "z": -3,
      "name": "Rock_Sandstone_Brick"
    },
    {
      "x": 4,
      "y": 6,
      "z": -3,
      "name": "Rock_Sandstone_Brick"
    },
    {
      "x": 4,
      "y": 7,
      "z": -3,
      "name": "Rock_Sandstone_Cobble"
    },
    {
      "x": 4,
      "y": 8,
      "z": -3,
      "name": "Rock_Sandstone_Cobble"
    },
    {
      "x": 4,
      "y": 9,
      "z": -3,
      "name": "Rock_Sandstone_Brick"
    },
    {
      "x": 4,
      "y": 10,
      "z": -3,
      "name": "Rock_Sandstone_Cobble"
    },
    {
      "x": 4,
      "y": 11,
      "z": -3,
      "name": "Rock_Sandstone_Brick"
    },
    {
      "x": 4,
      "y": 12,
      "z": -3,
      "name": "Rock_Sandstone_Brick"
    },
    {
      "x": 4,
      "y": 13,
      "z": -3,
      "name": "Rock_Sandstone_Brick"
    },
    {
      "x": 4,
      "y": 14,
      "z": -3,
      "name": "Rock_Sandstone_Brick"
    },
    {
      "x": 4,
      "y": 15,
      "z": -3,
      "name": "Rock_Sandstone_Brick"
    },
    {
      "x": 4,
      "y": 16,
      "z": -3,
      "name": "Rock_Sandstone_Brick"
    },
    {
      "x": 4,
      "y": 17,
      "z": -3,
      "name": "Rock_Sandstone_Brick"
    },
    {
      "x": 4,
      "y": 18,
      "z": -3,
      "name": "Rock_Sandstone"
    },
    {
      "x": 4,
      "y": 19,
      "z": -3,
      "name": "Rock_Sandstone_Brick"
    },
    {
      "x": 4,
      "y": 20,
      "z": -3,
      "name": "Rock_Sandstone"
    },
    {
      "x": 4,
      "y": 21,
      "z": -3,
      "name": "Rock_Sandstone_Brick"
    },
    {
      "x": 4,
      "y": 22,
      "z": -3,
      "name": "Rock_Sandstone_Brick"
    },
    {
      "x": 4,
      "y": 23,
      "z": -3,
      "name": "Rock_Sandstone"
    },
    {
      "x": 4,
      "y": 24,
      "z": -3,
      "name": "Rock_Sandstone_Brick"
    },
    {
      "x": 4,
      "y": 25,
      "z": -3,
      "name": "Rock_Sandstone_Brick"
    },
    {
      "x": 4,
      "y": 26,
      "z": -3,
      "name": "Rock_Sandstone_Brick"
    },
    {
      "x": 4,
      "y": 27,
      "z": -3,
      "name": "Rock_Sandstone_Brick"
    },
    {
      "x": 4,
      "y": 28,
      "z": -3,
      "name": "Rock_Sandstone_Cobble"
    },
    {
      "x": 4,
      "y": 29,
      "z": -3,
      "name": "Rock_Sandstone_Brick"
    },
    {
      "x": 4,
      "y": 30,
      "z": -3,
      "name": "Rock_Sandstone_Brick"
    },
    {
      "x": 4,
      "y": 31,
      "z": -3,
      "name": "Rock_Sandstone_Cobble"
    },
    {
      "x": 4,
      "y": 32,
      "z": -3,
      "name": "Rock_Sandstone_Brick"
    },
    {
      "x": 4,
      "y": 33,
      "z": -3,
      "name": "Rock_Sandstone_Brick"
    },
    {
      "x": 4,
      "y": 34,
      "z": -3,
      "name": "Rock_Sandstone_Brick"
    },
    {
      "x": 4,
      "y": 35,
      "z": -3,
      "name": "Rock_Sandstone_Brick"
    },
    {
      "x": 4,
      "y": 30,
      "z": -2,
      "name": "Rock_Sandstone_Brick_Stairs",
      "rotation": 10
    },
    {
      "x": 4,
      "y": 31,
      "z": -2,
      "name": "Rock_Sandstone_Cobble",
      "rotation": 2
    },
    {
      "x": 4,
      "y": 32,
      "z": -2,
      "name": "Rock_Sandstone_Cobble",
      "rotation": 2
    },
    {
      "x": 4,
      "y": 33,
      "z": -2,
      "name": "Rock_Sandstone_Brick",
      "rotation": 2
    },
    {
      "x": 4,
      "y": 34,
      "z": -2,
      "name": "Rock_Sandstone_Brick",
      "rotation": 2
    },
    {
      "x": 4,
      "y": 35,
      "z": -2,
      "name": "Rock_Sandstone_Brick"
    },
    {
      "x": 4,
      "y": 31,
      "z": -1,
      "name": "Rock_Sandstone_Brick"
    },
    {
      "x": 4,
      "y": 32,
      "z": -1,
      "name": "Rock_Sandstone_Brick"
    },
    {
      "x": 4,
      "y": 33,
      "z": -1,
      "name": "Rock_Sandstone_Brick"
    },
    {
      "x": 4,
      "y": 34,
      "z": -1,
      "name": "Rock_Sandstone_Brick"
    },
    {
      "x": 4,
      "y": 35,
      "z": -1,
      "name": "Rock_Sandstone_Brick"
    },
    {
      "x": 4,
      "y": 31,
      "z": 0,
      "name": "Rock_Sandstone_Brick"
    },
    {
      "x": 4,
      "y": 32,
      "z": 0,
      "name": "Rock_Sandstone_Brick"
    },
    {
      "x": 4,
      "y": 33,
      "z": 0,
      "name": "Rock_Sandstone_Brick"
    },
    {
      "x": 4,
      "y": 34,
      "z": 0,
      "name": "Rock_Sandstone_Brick"
    },
    {
      "x": 4,
      "y": 35,
      "z": 0,
      "name": "Rock_Sandstone_Brick"
    },
    {
      "x": 4,
      "y": 31,
      "z": 1,
      "name": "Rock_Sandstone",
      "rotation": 2
    },
    {
      "x": 4,
      "y": 32,
      "z": 1,
      "name": "Rock_Sandstone",
      "rotation": 2
    },
    {
      "x": 4,
      "y": 33,
      "z": 1,
      "name": "Rock_Sandstone_Brick",
      "rotation": 2
    },
    {
      "x": 4,
      "y": 34,
      "z": 1,
      "name": "Rock_Sandstone_Brick",
      "rotation": 2
    },
    {
      "x": 4,
      "y": 35,
      "z": 1,
      "name": "Rock_Sandstone_Brick"
    },
    {
      "x": 4,
      "y": 31,
      "z": 2,
      "name": "Rock_Sandstone_Brick",
      "rotation": 2
    },
    {
      "x": 4,
      "y": 32,
      "z": 2,
      "name": "Rock_Sandstone_Brick",
      "rotation": 2
    },
    {
      "x": 4,
      "y": 33,
      "z": 2,
      "name": "Rock_Sandstone_Brick",
      "rotation": 2
    },
    {
      "x": 4,
      "y": 34,
      "z": 2,
      "name": "Rock_Sandstone_Brick",
      "rotation": 2
    },
    {
      "x": 4,
      "y": 35,
      "z": 2,
      "name": "Rock_Sandstone_Brick"
    },
    {
      "x": 4,
      "y": 30,
      "z": 3,
      "name": "Rock_Sandstone_Brick_Stairs",
      "rotation": 8
    },
    {
      "x": 4,
      "y": 31,
      "z": 3,
      "name": "Rock_Sandstone_Brick",
      "rotation": 2
    },
    {
      "x": 4,
      "y": 32,
      "z": 3,
      "name": "Rock_Sandstone_Brick",
      "rotation": 2
    },
    {
      "x": 4,
      "y": 33,
      "z": 3,
      "name": "Rock_Sandstone_Brick",
      "rotation": 2
    },
    {
      "x": 4,
      "y": 34,
      "z": 3,
      "name": "Rock_Sandstone_Brick",
      "rotation": 2
    },
    {
      "x": 4,
      "y": 35,
      "z": 3,
      "name": "Rock_Sandstone_Brick"
    },
    {
      "x": 4,
      "y": 0,
      "z": 4,
      "name": "Rock_Sandstone"
    },
    {
      "x": 4,
      "y": 1,
      "z": 4,
      "name": "Rock_Sandstone"
    },
    {
      "x": 4,
      "y": 2,
      "z": 4,
      "name": "Rock_Sandstone"
    },
    {
      "x": 4,
      "y": 3,
      "z": 4,
      "name": "Rock_Sandstone"
    },
    {
      "x": 4,
      "y": 4,
      "z": 4,
      "name": "Rock_Sandstone"
    },
    {
      "x": 4,
      "y": 5,
      "z": 4,
      "name": "Rock_Sandstone_Brick"
    },
    {
      "x": 4,
      "y": 6,
      "z": 4,
      "name": "Rock_Sandstone_Brick"
    },
    {
      "x": 4,
      "y": 7,
      "z": 4,
      "name": "Rock_Sandstone_Brick"
    },
    {
      "x": 4,
      "y": 8,
      "z": 4,
      "name": "Rock_Sandstone_Brick"
    },
    {
      "x": 4,
      "y": 9,
      "z": 4,
      "name": "Rock_Sandstone"
    },
    {
      "x": 4,
      "y": 10,
      "z": 4,
      "name": "Rock_Sandstone_Brick"
    },
    {
      "x": 4,
      "y": 11,
      "z": 4,
      "name": "Rock_Sandstone_Cobble"
    },
    {
      "x": 4,
      "y": 12,
      "z": 4,
      "name": "Rock_Sandstone_Cobble"
    },
    {
      "x": 4,
      "y": 13,
      "z": 4,
      "name": "Rock_Sandstone_Brick"
    },
    {
      "x": 4,
      "y": 14,
      "z": 4,
      "name": "Rock_Sandstone_Cobble"
    },
    {
      "x": 4,
      "y": 15,
      "z": 4,
      "name": "Rock_Sandstone"
    },
    {
      "x": 4,
      "y": 16,
      "z": 4,
      "name": "Rock_Sandstone_Brick"
    },
    {
      "x": 4,
      "y": 17,
      "z": 4,
      "name": "Rock_Sandstone_Cobble"
    },
    {
      "x": 4,
      "y": 18,
      "z": 4,
      "name": "Rock_Sandstone_Brick"
    },
    {
      "x": 4,
      "y": 19,
      "z": 4,
      "name": "Rock_Sandstone"
    },
    {
      "x": 4,
      "y": 20,
      "z": 4,
      "name": "Rock_Sandstone_Brick"
    },
    {
      "x": 4,
      "y": 21,
      "z": 4,
      "name": "Rock_Sandstone"
    },
    {
      "x": 4,
      "y": 22,
      "z": 4,
      "name": "Rock_Sandstone_Brick"
    },
    {
      "x": 4,
      "y": 23,
      "z": 4,
      "name": "Rock_Sandstone_Brick"
    },
    {
      "x": 4,
      "y": 24,
      "z": 4,
      "name": "Rock_Sandstone_Brick"
    },
    {
      "x": 4,
      "y": 25,
      "z": 4,
      "name": "Rock_Sandstone"
    },
    {
      "x": 4,
      "y": 26,
      "z": 4,
      "name": "Rock_Sandstone_Cobble"
    },
    {
      "x": 4,
      "y": 27,
      "z": 4,
      "name": "Rock_Sandstone_Cobble"
    },
    {
      "x": 4,
      "y": 28,
      "z": 4,
      "name": "Rock_Sandstone_Brick"
    },
    {
      "x": 4,
      "y": 29,
      "z": 4,
      "name": "Rock_Sandstone"
    },
    {
      "x": 4,
      "y": 30,
      "z": 4,
      "name": "Rock_Sandstone_Brick"
    },
    {
      "x": 4,
      "y": 31,
      "z": 4,
      "name": "Rock_Sandstone_Brick"
    },
    {
      "x": 4,
      "y": 32,
      "z": 4,
      "name": "Rock_Sandstone"
    },
    {
      "x": 4,
      "y": 33,
      "z": 4,
      "name": "Rock_Sandstone_Brick"
    },
    {
      "x": 4,
      "y": 34,
      "z": 4,
      "name": "Rock_Sandstone_Brick"
    },
    {
      "x": 4,
      "y": 35,
      "z": 4,
      "name": "Rock_Sandstone_Brick"
    },
    {
      "x": 4,
      "y": 0,
      "z": 5,
      "name": "Rock_Sandstone_Cobble"
    },
    {
      "x": 4,
      "y": 1,
      "z": 5,
      "name": "Rock_Sandstone_Brick"
    },
    {
      "x": 4,
      "y": 2,
      "z": 5,
      "name": "Rock_Sandstone_Brick"
    },
    {
      "x": 4,
      "y": 3,
      "z": 5,
      "name": "Rock_Sandstone"
    },
    {
      "x": 4,
      "y": 4,
      "z": 5,
      "name": "Rock_Sandstone"
    },
    {
      "x": 4,
      "y": 5,
      "z": 5,
      "name": "Rock_Sandstone_Brick"
    },
    {
      "x": 4,
      "y": 6,
      "z": 5,
      "name": "Rock_Sandstone"
    },
    {
      "x": 4,
      "y": 7,
      "z": 5,
      "name": "Rock_Sandstone"
    },
    {
      "x": 4,
      "y": 8,
      "z": 5,
      "name": "Rock_Sandstone_Brick"
    },
    {
      "x": 4,
      "y": 9,
      "z": 5,
      "name": "Rock_Sandstone"
    },
    {
      "x": 4,
      "y": 10,
      "z": 5,
      "name": "Rock_Sandstone_Brick"
    },
    {
      "x": 4,
      "y": 11,
      "z": 5,
      "name": "Rock_Sandstone_Brick"
    },
    {
      "x": 4,
      "y": 12,
      "z": 5,
      "name": "Rock_Sandstone_Brick"
    },
    {
      "x": 4,
      "y": 13,
      "z": 5,
      "name": "Rock_Sandstone_Brick"
    },
    {
      "x": 4,
      "y": 14,
      "z": 5,
      "name": "Rock_Sandstone_Brick"
    },
    {
      "x": 4,
      "y": 15,
      "z": 5,
      "name": "Rock_Sandstone_Cobble"
    },
    {
      "x": 4,
      "y": 16,
      "z": 5,
      "name": "Rock_Sandstone_Brick"
    },
    {
      "x": 4,
      "y": 17,
      "z": 5,
      "name": "Rock_Sandstone_Brick"
    },
    {
      "x": 4,
      "y": 18,
      "z": 5,
      "name": "Rock_Sandstone_Brick"
    },
    {
      "x": 4,
      "y": 19,
      "z": 5,
      "name": "Rock_Sandstone_Brick"
    },
    {
      "x": 4,
      "y": 20,
      "z": 5,
      "name": "Rock_Sandstone_Brick"
    },
    {
      "x": 4,
      "y": 21,
      "z": 5,
      "name": "Rock_Sandstone_Cobble"
    },
    {
      "x": 4,
      "y": 22,
      "z": 5,
      "name": "Rock_Sandstone_Brick"
    },
    {
      "x": 4,
      "y": 23,
      "z": 5,
      "name": "Rock_Sandstone_Brick"
    },
    {
      "x": 4,
      "y": 24,
      "z": 5,
      "name": "Rock_Sandstone"
    },
    {
      "x": 4,
      "y": 25,
      "z": 5,
      "name": "Rock_Sandstone_Brick"
    },
    {
      "x": 4,
      "y": 26,
      "z": 5,
      "name": "Rock_Sandstone_Cobble"
    },
    {
      "x": 4,
      "y": 27,
      "z": 5,
      "name": "Rock_Sandstone_Brick"
    },
    {
      "x": 4,
      "y": 28,
      "z": 5,
      "name": "Rock_Sandstone_Brick"
    },
    {
      "x": 4,
      "y": 29,
      "z": 5,
