{
  "version": 8,
  "blockIdVersion": 11,
  "anchorX": 0,
  "anchorY": 11,
  "anchorZ": 0,
  "blocks": [
    {
      "x": -4,
      "y": 11,
      "z": -1,
      "name": "SS_Large_Lilypad_Leaf_Block"
    },
    {
      "x": -4,
      "y": 11,
      "z": 0,
      "name": "SS_Large_Lilypad_Leaf_Block"
    },
    {
      "x": -4,
      "y": 11,
      "z": 1,
      "name": "SS_Large_Lilypad_Leaf_Block"
    },
    {
      "x": -3,
      "y": 10,
      "z": -1,
      "name": "SS_Large_Lilypad_Leaf_Block"
    },
    {
      "x": -3,
      "y": 11,
      "z": -1,
      "name": "Empty"
    },
    {
      "x": -3,
      "y": 10,
      "z": 0,
      "name": "SS_Large_Lilypad_Leaf_Block"
    },
    {
      "x": -3,
      "y": 11,
      "z": 0,
      "name": "Empty"
    },
    {
      "x": -3,
      "y": 10,
      "z": 1,
      "name": "SS_Large_Lilypad_Leaf_Block"
    },
    {
      "x": -3,
      "y": 11,
      "z": 1,
      "name": "Empty"
    },
    {
      "x": -3,
      "y": 11,
      "z": 2,
      "name": "SS_Large_Lilypad_Leaf_Block"
    },
    {
      "x": -3,
      "y": 11,
      "z": 3,
      "name": "SS_Large_Lilypad_Leaf_Block"
    },
    {
      "x": -2,
      "y": 10,
      "z": 0,
      "name": "SS_Large_Lilypad_Leaf_Block"
    },
    {
      "x": -2,
      "y": 11,
      "z": 0,
      "name": "Empty"
    },
    {
      "x": -2,
      "y": 10,
      "z": 1,
      "name": "SS_Large_Lilypad_Leaf_Block"
    },
    {
      "x": -2,
      "y": 11,
      "z": 1,
      "name": "Empty"
    },
    {
      "x": -2,
      "y": 10,
      "z": 2,
      "name": "SS_Large_Lilypad_Leaf_Block"
    },
    {
      "x": -2,
      "y": 11,
      "z": 2,
      "name": "Empty"
    },
    {
      "x": -2,
      "y": 11,
      "z": 3,
      "name": "SS_Large_Lilypad_Leaf_Block"
    },
    {
      "x": -1,
      "y": 11,
      "z": -4,
      "name": "SS_Large_Lilypad_Leaf_Block"
    },
    {
      "x": -1,
      "y": 10,
      "z": -3,
      "name": "SS_Large_Lilypad_Leaf_Block"
    },
    {
      "x": -1,
      "y": 11,
      "z": -3,
      "name": "Empty"
    },
    {
      "x": -1,
      "y": 10,
      "z": 0,
      "name": "SS_Large_Lilypad_Leaf_Block"
    },
    {
      "x": -1,
      "y": 11,
      "z": 0,
      "name": "Empty"
    },
    {
      "x": -1,
      "y": 3,
      "z": 1,
      "name": "Wood_Windwillow_Branch_Corner"
    },
    {
      "x": -1,
      "y": 4,
      "z": 1,
      "name": "Wood_Windwillow_Branch_Long"
    },
    {
      "x": -1,
      "y": 5,
      "z": 1,
      "name": "Wood_Windwillow_Branch_Long"
    },
    {
      "x": -1,
      "y": 6,
      "z": 1,
      "name": "Wood_Windwillow_Branch_Corner",
      "rotation": 9
    },
    {
      "x": -1,
      "y": 9,
      "z": 1,
      "name": "Wood_Windwillow_Branch_Corner",
      "rotation": 3
    },
    {
      "x": -1,
      "y": 10,
      "z": 1,
      "name": "SS_Large_Lilypad_Leaf_Block"
    },
    {
      "x": -1,
      "y": 11,
      "z": 1,
      "name": "Empty"
    },
    {
      "x": -1,
      "y": 12,
      "z": 1,
      "name": "Cloth_Block_Wool_White_Half",
      "rotation": 7
    },
    {
      "x": -1,
      "y": 10,
      "z": 2,
      "name": "SS_Large_Lilypad_Leaf_Block"
    },
    {
      "x": -1,
      "y": 11,
      "z": 2,
      "name": "Empty"
    },
    {
      "x": -1,
      "y": 10,
      "z": 3,
      "name": "SS_Large_Lilypad_Leaf_Block"
    },
    {
      "x": -1,
      "y": 11,
      "z": 3,
      "name": "Empty"
    },
    {
      "x": -1,
      "y": 11,
      "z": 4,
      "name": "SS_Large_Lilypad_Leaf_Block"
    },
    {
      "x": 0,
      "y": 11,
      "z": -4,
      "name": "SS_Large_Lilypad_Leaf_Block"
    },
    {
      "x": 0,
      "y": 10,
      "z": -3,
      "name": "SS_Large_Lilypad_Leaf_Block"
    },
    {
      "x": 0,
      "y": 11,
      "z": -3,
      "name": "Empty"
    },
    {
      "x": 0,
      "y": 10,
      "z": -2,
      "name": "SS_Large_Lilypad_Leaf_Block"
    },
    {
      "x": 0,
      "y": 11,
      "z": -2,
      "name": "Empty"
    },
    {
      "x": 0,
      "y": 10,
      "z": -1,
      "name": "SS_Large_Lilypad_Leaf_Block"
    },
    {
      "x": 0,
      "y": 11,
      "z": -1,
      "name": "Empty"
    },
    {
      "x": 0,
      "y": 9,
      "z": 0,
      "name": "Wood_Windwillow_Branch_Corner",
      "rotation": 3
    },
    {
      "x": 0,
      "y": 10,
      "z": 0,
      "name": "SS_Large_Lilypad_Leaf_Block"
    },
    {
      "x": 0,
      "y": 11,
      "z": 0,
      "name": "Empty"
    },
    {
      "x": 0,
      "y": 12,
      "z": 0,
      "name": "Cloth_Block_Wool_White"
    },
    {
      "x": 0,
      "y": 6,
      "z": 1,
      "name": "Wood_Windwillow_Branch_Corner",
      "rotation": 1
    },
    {
      "x": 0,
      "y": 7,
      "z": 1,
      "name": "Wood_Windwillow_Branch_Long"
    },
    {
      "x": 0,
      "y": 8,
      "z": 1,
      "name": "Wood_Windwillow_Branch_Corner",
      "rotation": 9
    },
    {
      "x": 0,
      "y": 9,
      "z": 1,
      "name": "Wood_Windwillow_Trunk_Full",
      "support": 15
    },
    {
      "x": 0,
      "y": 10,
      "z": 1,
      "name": "SS_Large_Lilypad_Leaf_Block"
    },
    {
      "x": 0,
      "y": 11,
      "z": 1,
      "name": "Cloth_Block_Wool_White_Stairs",
      "rotation": 9
    },
    {
      "x": 0,
      "y": 12,
      "z": 1,
      "name": "Cloth_Block_Wool_White_Stairs",
      "rotation": 1
    },
    {
      "x": 0,
      "y": 13,
      "z": 1,
      "name": "Cloth_Block_Wool_White_Half",
      "rotation": 5
    },
    {
      "x": 0,
      "y": 9,
      "z": 2,
      "name": "Wood_Windwillow_Branch_Long",
      "rotation": 4
    },
    {
      "x": 0,
      "y": 10,
      "z": 2,
      "name": "SS_Large_Lilypad_Leaf_Block"
    },
    {
      "x": 0,
      "y": 11,
      "z": 2,
      "name": "Empty"
    },
    {
      "x": 0,
      "y": 12,
      "z": 2,
      "name": "Cloth_Block_Wool_White"
    },
    {
      "x": 0,
      "y": 9,
      "z": 3,
      "name": "Wood_Windwillow_Branch_Corner"
    },
    {
      "x": 0,
      "y": 10,
      "z": 3,
      "name": "SS_Large_Lilypad_Leaf_Block"
    },
    {
      "x": 0,
      "y": 11,
      "z": 3,
      "name": "Empty"
    },
    {
      "x": 0,
      "y": 11,
      "z": 4,
      "name": "SS_Large_Lilypad_Leaf_Block"
    },
    {
      "x": 1,
      "y": 11,
      "z": -4,
      "name": "SS_Large_Lilypad_Leaf_Block"
    },
    {
      "x": 1,
      "y": 10,
      "z": -3,
      "name": "SS_Large_Lilypad_Leaf_Block"
    },
    {
      "x": 1,
      "y": 11,
      "z": -3,
      "name": "Empty"
    },
    {
      "x": 1,
      "y": 9,
      "z": -2,
      "name": "Wood_Windwillow_Branch_Corner",
      "rotation": 2
    },
    {
      "x": 1,
      "y": 10,
      "z": -2,
      "name": "SS_Large_Lilypad_Leaf_Block"
    },
    {
      "x": 1,
      "y": 11,
      "z": -2,
      "name": "Empty"
    },
    {
      "x": 1,
      "y": 4,
      "z": -1,
      "name": "Wood_Windwillow_Branch_Corner"
    },
    {
      "x": 1,
      "y": 5,
      "z": -1,
      "name": "Wood_Windwillow_Branch_Long"
    },
    {
      "x": 1,
      "y": 6,
      "z": -1,
      "name": "Wood_Windwillow_Branch_Corner",
      "rotation": 8
    },
    {
      "x": 1,
      "y": 9,
      "z": -1,
      "name": "Wood_Windwillow_Branch_Long",
      "rotation": 4
    },
    {
      "x": 1,
      "y": 10,
      "z": -1,
      "name": "SS_Large_Lilypad_Leaf_Block"
    },
    {
      "x": 1,
      "y": 11,
      "z": -1,
      "name": "Empty"
    },
    {
      "x": 1,
      "y": 12,
      "z": -1,
      "name": "Cloth_Block_Wool_White_Half",
      "rotation": 6
    },
    {
      "x": 1,
      "y": 6,
      "z": 0,
      "name": "Wood_Windwillow_Branch_Corner"
    },
    {
      "x": 1,
      "y": 7,
      "z": 0,
      "name": "Wood_Windwillow_Branch_Corner",
      "rotation": 8
    },
    {
      "x": 1,
      "y": 10,
      "z": 0,
      "name": "SS_Large_Lilypad_Leaf_Block"
    },
    {
      "x": 1,
      "y": 11,
      "z": 0,
      "name": "Cloth_Block_Wool_White_Stairs",
      "rotation": 8
    },
    {
      "x": 1,
      "y": 12,
      "z": 0,
      "name": "Cloth_Block_Wool_White_Stairs"
    },
    {
      "x": 1,
      "y": 13,
      "z": 0,
      "name": "Cloth_Block_Wool_White_Half",
      "rotation": 4
    },
    {
      "x": 1,
      "y": 1,
      "z": 1,
      "name": "Wood_Windwillow_Branch_Corner",
      "rotation": 2
    },
    {
      "x": 1,
      "y": 2,
      "z": 1,
      "name": "Wood_Windwillow_Branch_Long"
    },
    {
      "x": 1,
      "y": 3,
      "z": 1,
      "name": "Wood_Windwillow_Branch_Long"
    },
    {
      "x": 1,
      "y": 4,
      "z": 1,
      "name": "Wood_Windwillow_Branch_Long"
    },
    {
      "x": 1,
      "y": 5,
      "z": 1,
      "name": "Wood_Windwillow_Trunk_Full",
      "support": 15
    },
    {
      "x": 1,
      "y": 6,
      "z": 1,
      "name": "Wood_Windwillow_Trunk_Full",
      "support": 15
    },
    {
      "x": 1,
      "y": 7,
      "z": 1,
      "name": "Wood_Windwillow_Trunk_Full",
      "support": 15
    },
    {
      "x": 1,
      "y": 8,
      "z": 1,
      "name": "Wood_Windwillow_Trunk_Full",
      "support": 15
    },
    {
      "x": 1,
      "y": 9,
      "z": 1,
      "name": "Wood_Windwillow_Trunk_Full",
      "support": 15
    },
    {
      "x": 1,
      "y": 10,
      "z": 1,
      "name": "SS_Large_Lilypad_Leaf_Block"
    },
    {
      "x": 1,
      "y": 11,
      "z": 1,
      "name": "Rock_Chalk"
    },
    {
      "x": 1,
      "y": 12,
      "z": 1,
      "name": "Rock_Crystal_White_Large"
    },
    {
      "x": 1,
      "y": 0,
      "z": 2,
      "name": "Wood_Windwillow_Branch_Long"
    },
    {
      "x": 1,
      "y": 1,
      "z": 2,
      "name": "Wood_Windwillow_Branch_Corner",
      "rotation": 10
    },
    {
      "x": 1,
      "y": 5,
      "z": 2,
      "name": "Wood_Windwillow_Branch_Corner",
      "rotation": 2
    },
    {
      "x": 1,
      "y": 6,
      "z": 2,
      "name": "Wood_Windwillow_Branch_Corner",
      "rotation": 10
    },
    {
      "x": 1,
      "y": 9,
      "z": 2,
      "name": "Wood_Windwillow_Branch_Corner"
    },
    {
      "x": 1,
      "y": 10,
      "z": 2,
      "name": "SS_Large_Lilypad_Leaf_Block"
    },
    {
      "x": 1,
      "y": 11,
      "z": 2,
      "name": "Cloth_Block_Wool_White_Stairs",
      "rotation": 10
    },
    {
      "x": 1,
      "y": 12,
      "z": 2,
      "name": "Cloth_Block_Wool_White_Stairs",
      "rotation": 2
    },
    {
      "x": 1,
      "y": 13,
      "z": 2,
      "name": "Cloth_Block_Wool_White_Half",
      "rotation": 6
    },
    {
      "x": 1,
      "y": 3,
      "z": 3,
      "name": "Wood_Windwillow_Branch_Long"
    },
    {
      "x": 1,
      "y": 4,
      "z": 3,
      "name": "Wood_Windwillow_Branch_Long"
    },
    {
      "x": 1,
      "y": 5,
      "z": 3,
      "name": "Wood_Windwillow_Branch_Corner",
      "rotation": 10
    },
    {
      "x": 1,
      "y": 10,
      "z": 3,
      "name": "SS_Large_Lilypad_Leaf_Block"
    },
    {
      "x": 1,
      "y": 11,
      "z": 3,
      "name": "Empty"
    },
    {
      "x": 1,
      "y": 12,
      "z": 3,
      "name": "Cloth_Block_Wool_White_Half",
      "rotation": 4
    },
    {
      "x": 1,
      "y": 11,
      "z": 4,
      "name": "SS_Large_Lilypad_Leaf_Block"
    },
    {
      "x": 2,
      "y": 11,
      "z": -3,
      "name": "SS_Large_Lilypad_Leaf_Block"
    },
    {
      "x": 2,
      "y": 10,
      "z": -2,
      "name": "SS_Large_Lilypad_Leaf_Block"
    },
    {
      "x": 2,
      "y": 11,
      "z": -2,
      "name": "Empty"
    },
    {
      "x": 2,
      "y": 10,
      "z": -1,
      "name": "SS_Large_Lilypad_Leaf_Block"
    },
    {
      "x": 2,
      "y": 11,
      "z": -1,
      "name": "Empty"
    },
    {
      "x": 2,
      "y": 10,
      "z": 0,
      "name": "SS_Large_Lilypad_Leaf_Block"
    },
    {
      "x": 2,
      "y": 11,
      "z": 0,
      "name": "Empty"
    },
    {
      "x": 2,
      "y": 12,
      "z": 0,
      "name": "Cloth_Block_Wool_White"
    },
    {
      "x": 2,
      "y": 5,
      "z": 1,
      "name": "Wood_Windwillow_Branch_Corner",
      "rotation": 3
    },
    {
      "x": 2,
      "y": 6,
      "z": 1,
      "name": "Wood_Windwillow_Branch_Corner",
      "rotation": 11
    },
    {
      "x": 2,
      "y": 7,
      "z": 1,
      "name": "Wood_Windwillow_Branch_Corner",
      "rotation": 3
    },
    {
      "x": 2,
      "y": 8,
      "z": 1,
      "name": "Wood_Windwillow_Branch_Corner",
      "rotation": 11
    },
    {
      "x": 2,
      "y": 9,
      "z": 1,
      "name": "Wood_Windwillow_Branch_Corner",
      "rotation": 1
    },
    {
      "x": 2,
      "y": 10,
      "z": 1,
      "name": "SS_Large_Lilypad_Leaf_Block"
    },
    {
      "x": 2,
      "y": 11,
      "z": 1,
      "name": "Cloth_Block_Wool_White_Stairs",
      "rotation": 11
    },
    {
      "x": 2,
      "y": 12,
      "z": 1,
      "name": "Cloth_Block_Wool_White_Stairs",
      "rotation": 3
    },
    {
      "x": 2,
      "y": 13,
      "z": 1,
      "name": "Cloth_Block_Wool_White_Half",
      "rotation": 7
    },
    {
      "x": 2,
      "y": 10,
      "z": 2,
      "name": "SS_Large_Lilypad_Leaf_Block"
    },
    {
      "x": 2,
      "y": 11,
      "z": 2,
      "name": "Empty"
    },
    {
      "x": 2,
      "y": 12,
      "z": 2,
      "name": "Cloth_Block_Wool_White"
    },
    {
      "x": 2,
      "y": 11,
      "z": 3,
      "name": "SS_Large_Lilypad_Leaf_Block"
    },
    {
      "x": 3,
      "y": 11,
      "z": -3,
      "name": "SS_Large_Lilypad_Leaf_Block"
    },
    {
      "x": 3,
      "y": 11,
      "z": -2,
      "name": "SS_Large_Lilypad_Leaf_Block"
    },
    {
      "x": 3,
      "y": 10,
      "z": -1,
      "name": "SS_Large_Lilypad_Leaf_Block"
    },
    {
      "x": 3,
      "y": 11,
      "z": -1,
      "name": "Empty"
    },
    {
      "x": 3,
      "y": 10,
      "z": 0,
      "name": "SS_Large_Lilypad_Leaf_Block"
    },
    {
      "x": 3,
      "y": 11,
      "z": 0,
      "name": "Empty"
    },
    {
      "x": 3,
      "y": 4,
      "z": 1,
      "name": "Wood_Windwillow_Branch_Long"
    },
    {
      "x": 3,
      "y": 5,
      "z": 1,
      "name": "Wood_Windwillow_Branch_Corner",
      "rotation": 11
    },
    {
      "x": 3,
      "y": 10,
      "z": 1,
      "name": "SS_Large_Lilypad_Leaf_Block"
    },
    {
      "x": 3,
      "y": 11,
      "z": 1,
      "name": "Empty"
    },
    {
      "x": 3,
      "y": 12,
      "z": 1,
      "name": "Cloth_Block_Wool_White_Half",
      "rotation": 5
    },
    {
      "x": 3,
      "y": 11,
      "z": 2,
      "name": "SS_Large_Lilypad_Leaf_Block"
    },
    {
      "x": 3,
      "y": 11,
      "z": 3,
      "name": "SS_Large_Lilypad_Leaf_Block"
    },
    {
      "x": 4,
      "y": 11,
      "z": -1,
      "name": "SS_Large_Lilypad_Leaf_Block"
    },
    {
      "x": 4,
      "y": 11,
      "z": 0,
      "name": "SS_Large_Lilypad_Leaf_Block"
    },
    {
      "x": 4,
      "y": 11,
      "z": 1,
      "name": "SS_Large_Lilypad_Leaf_Block"
    }
  ],
  "fluids": [
    {
      "x": -1,
      "y": 3,
      "z": 1,
      "name": "Water_Source",
      "level": 1
    },
    {
      "x": -1,
      "y": 4,
      "z": 1,
      "name": "Water_Source",
      "level": 1
    },
    {
      "x": -1,
      "y": 5,
      "z": 1,
      "name": "Water_Source",
      "level": 1
    },
    {
      "x": -1,
      "y": 6,
      "z": 1,
      "name": "Water_Source",
      "level": 1
    },
    {
      "x": -1,
      "y": 9,
      "z": 1,
      "name": "Water_Source",
      "level": 1
    },
    {
      "x": 0,
      "y": 9,
      "z": 0,
      "name": "Water_Source",
      "level": 1
    },
    {
      "x": 0,
      "y": 6,
      "z": 1,
      "name": "Water_Source",
      "level": 1
    },
    {
      "x": 0,
      "y": 7,
      "z": 1,
      "name": "Water_Source",
      "level": 1
    },
    {
      "x": 0,
      "y": 8,
      "z": 1,
      "name": "Water_Source",
      "level": 1
    },
    {
      "x": 0,
      "y": 9,
      "z": 2,
      "name": "Water_Source",
      "level": 1
    },
    {
      "x": 0,
      "y": 9,
      "z": 3,
      "name": "Water_Source",
      "level": 1
    },
    {
      "x": 1,
      "y": 9,
      "z": -2,
      "name": "Water_Source",
      "level": 1
    },
    {
      "x": 1,
      "y": 4,
      "z": -1,
      "name": "Water_Source",
      "level": 1
    },
    {
      "x": 1,
      "y": 5,
      "z": -1,
      "name": "Water_Source",
      "level": 1
    },
    {
      "x": 1,
      "y": 6,
      "z": -1,
      "name": "Water_Source",
      "level": 1
    },
    {
      "x": 1,
      "y": 9,
      "z": -1,
      "name": "Water_Source",
      "level": 1
    },
    {
      "x": 1,
      "y": 6,
      "z": 0,
      "name": "Water_Source",
      "level": 1
    },
    {
      "x": 1,
      "y": 7,
      "z": 0,
      "name": "Water_Source",
      "level": 1
    },
    {
      "x": 1,
      "y": 1,
      "z": 1,
      "name": "Water_Source",
      "level": 1
    },
    {
      "x": 1,
      "y": 2,
      "z": 1,
      "name": "Water_Source",
      "level": 1
    },
    {
      "x": 1,
      "y": 3,
      "z": 1,
      "name": "Water_Source",
      "level": 1
    },
    {
      "x": 1,
      "y": 4,
      "z": 1,
      "name": "Water_Source",
      "level": 1
    },
    {
      "x": 1,
      "y": 0,
      "z": 2,
      "name": "Water_Source",
      "level": 1
    },
    {
      "x": 1,
      "y": 1,
      "z": 2,
      "name": "Water_Source",
      "level": 1
    },
    {
      "x": 1,
      "y": 5,
      "z": 2,
      "name": "Water_Source",
      "level": 1
    },
    {
      "x": 1,
      "y": 6,
      "z": 2,
      "name": "Water_Source",
      "level": 1
    },
    {
      "x": 1,
      "y": 9,
      "z": 2,
      "name": "Water_Source",
      "level": 1
    },
    {
      "x": 1,
      "y": 3,
      "z": 3,
      "name": "Water_Source",
      "level": 1
    },
    {
      "x": 1,
      "y": 4,
      "z": 3,
      "name": "Water_Source",
      "level": 1
    },
    {
      "x": 1,
      "y": 5,
      "z": 3,
      "name": "Water_Source",
      "level": 1
    },
    {
      "x": 2,
      "y": 5,
      "z": 1,
      "name": "Water_Source",
      "level": 1
    },
    {
      "x": 2,
      "y": 6,
      "z": 1,
      "name": "Water_Source",
      "level": 1
    },
    {
      "x": 2,
      "y": 7,
      "z": 1,
      "name": "Water_Source",
      "level": 1
    },
    {
      "x": 2,
      "y": 8,
      "z": 1,
      "name": "Water_Source",
      "level": 1
    },
    {
      "x": 2,
      "y": 9,
      "z": 1,
      "name": "Water_Source",
      "level": 1
    },
    {
      "x": 3,
      "y": 4,
      "z": 1,
      "name": "Water_Source",
      "level": 1
    },
    {
      "x": 3,
      "y": 5,
      "z": 1,
      "name": "Water_Source",
      "level": 1
    }
  ]
}