{
  "version": 8,
  "blockIdVersion": 11,
  "anchorX": 4,
  "anchorY": 1,
  "anchorZ": -5,
  "blocks": [
    {
      "x": 0,
      "y": 1,
      "z": -7,
      "name": "Rock_Sandstone_Cobble",
      "rotation": 3
    },
    {
      "x": 0,
      "y": 2,
      "z": -7,
      "name": "Rock_Sandstone_Cobble",
      "rotation": 3
    },
    {
      "x": 0,
      "y": 3,
      "z": -7,
      "name": "Rock_Sandstone_Cobble",
      "rotation": 3
    },
    {
      "x": 0,
      "y": 4,
      "z": -7,
      "name": "Rock_Sandstone_Brick",
      "rotation": 3
    },
    {
      "x": 0,
      "y": 5,
      "z": -7,
      "name": "Rock_Sandstone_Brick",
      "rotation": 3
    },
    {
      "x": 0,
      "y": 6,
      "z": -7,
      "name": "Rock_Sandstone_Brick_Pillar_Base",
      "rotation": 3
    },
    {
      "x": 0,
      "y": 7,
      "z": -7,
      "name": "Rock_Sandstone_Brick_Half",
      "rotation": 3
    },
    {
      "x": 0,
      "y": 1,
      "z": -6,
      "name": "Rock_Sandstone_Cobble",
      "rotation": 3
    },
    {
      "x": 0,
      "y": 2,
      "z": -6,
      "name": "Rock_Sandstone_Cobble",
      "rotation": 3
    },
    {
      "x": 0,
      "y": 3,
      "z": -6,
      "name": "Rock_Sandstone_Brick",
      "rotation": 3
    },
    {
      "x": 0,
      "y": 4,
      "z": -6,
      "name": "Rock_Sandstone_Brick",
      "rotation": 3
    },
    {
      "x": 0,
      "y": 5,
      "z": -6,
      "name": "Rock_Sandstone_Brick",
      "rotation": 3
    },
    {
      "x": 0,
      "y": 6,
      "z": -6,
      "name": "Rock_Sandstone_Brick_Pillar_Base",
      "rotation": 3
    },
    {
      "x": 0,
      "y": 7,
      "z": -6,
      "name": "Rock_Sandstone_Brick",
      "rotation": 3
    },
    {
      "x": 0,
      "y": 1,
      "z": -5,
      "name": "Rock_Sandstone_Cobble",
      "rotation": 3
    },
    {
      "x": 0,
      "y": 2,
      "z": -5,
      "name": "Rock_Sandstone_Cobble",
      "rotation": 3
    },
    {
      "x": 0,
      "y": 3,
      "z": -5,
      "name": "Rock_Sandstone_Cobble",
      "rotation": 3
    },
    {
      "x": 0,
      "y": 4,
      "z": -5,
      "name": "Rock_Sandstone_Brick",
      "rotation": 3
    },
    {
      "x": 0,
      "y": 5,
      "z": -5,
      "name": "Rock_Sandstone_Brick",
      "rotation": 3
    },
    {
      "x": 0,
      "y": 6,
      "z": -5,
      "name": "Rock_Sandstone_Brick_Pillar_Base",
      "rotation": 3
    },
    {
      "x": 0,
      "y": 7,
      "z": -5,
      "name": "Rock_Sandstone_Brick",
      "rotation": 3
    },
    {
      "x": 0,
      "y": 8,
      "z": -5,
      "name": "Rock_Sandstone_Cobble_Stairs",
      "rotation": 3
    },
    {
      "x": 0,
      "y": 9,
      "z": -5,
      "name": "Rock_Sandstone_Cobble_Half",
      "rotation": 7
    },
    {
      "x": 0,
      "y": 1,
      "z": -4,
      "name": "Rock_Sandstone_Cobble",
      "rotation": 3
    },
    {
      "x": 0,
      "y": 2,
      "z": -4,
      "name": "Rock_Sandstone_Cobble",
      "rotation": 3
    },
    {
      "x": 0,
      "y": 3,
      "z": -4,
      "name": "Rock_Sandstone_Cobble",
      "rotation": 3
    },
    {
      "x": 0,
      "y": 4,
      "z": -4,
      "name": "Rock_Sandstone_Cobble",
      "rotation": 3
    },
    {
      "x": 0,
      "y": 5,
      "z": -4,
      "name": "Rock_Sandstone_Brick",
      "rotation": 3
    },
    {
      "x": 0,
      "y": 6,
      "z": -4,
      "name": "Rock_Sandstone_Brick_Pillar_Base",
      "rotation": 3
    },
    {
      "x": 0,
      "y": 7,
      "z": -4,
      "name": "Rock_Sandstone_Brick",
      "rotation": 3
    },
    {
      "x": 0,
      "y": 8,
      "z": -4,
      "name": "Rock_Sandstone_Cobble_Stairs",
      "rotation": 3
    },
    {
      "x": 0,
      "y": 9,
      "z": -4,
      "name": "Rock_Sandstone_Cobble_Half",
      "rotation": 7
    },
    {
      "x": 0,
      "y": 1,
      "z": -3,
      "name": "Rock_Sandstone_Cobble",
      "rotation": 3
    },
    {
      "x": 0,
      "y": 2,
      "z": -3,
      "name": "Rock_Sandstone_Cobble",
      "rotation": 3
    },
    {
      "x": 0,
      "y": 3,
      "z": -3,
      "name": "Rock_Sandstone_Cobble",
      "rotation": 3
    },
    {
      "x": 0,
      "y": 4,
      "z": -3,
      "name": "Rock_Sandstone_Cobble",
      "rotation": 3
    },
    {
      "x": 0,
      "y": 5,
      "z": -3,
      "name": "Rock_Sandstone_Brick",
      "rotation": 3
    },
    {
      "x": 0,
      "y": 6,
      "z": -3,
      "name": "Rock_Sandstone_Brick_Pillar_Base",
      "rotation": 3
    },
    {
      "x": 0,
      "y": 7,
      "z": -3,
      "name": "Rock_Sandstone_Brick",
      "rotation": 3
    },
    {
      "x": 0,
      "y": 8,
      "z": -3,
      "name": "Rock_Sandstone_Cobble_Stairs",
      "rotation": 3
    },
    {
      "x": 0,
      "y": 9,
      "z": -3,
      "name": "Rock_Sandstone_Cobble_Half",
      "rotation": 7
    },
    {
      "x": 0,
      "y": 22,
      "z": -3,
      "name": "Rock_Sandstone_Brick_Smooth_Half",
      "rotation": 7
    },
    {
      "x": 0,
      "y": 1,
      "z": -2,
      "name": "Rock_Sandstone_Cobble",
      "rotation": 3
    },
    {
      "x": 0,
      "y": 2,
      "z": -2,
      "name": "Rock_Sandstone_Cobble",
      "rotation": 3
    },
    {
      "x": 0,
      "y": 3,
      "z": -2,
      "name": "Rock_Sandstone_Cobble",
      "rotation": 3
    },
    {
      "x": 0,
      "y": 4,
      "z": -2,
      "name": "Rock_Sandstone_Brick",
      "rotation": 3
    },
    {
      "x": 0,
      "y": 5,
      "z": -2,
      "name": "Rock_Sandstone_Brick",
      "rotation": 3
    },
    {
      "x": 0,
      "y": 6,
      "z": -2,
      "name": "Rock_Sandstone_Brick_Pillar_Base",
      "rotation": 3
    },
    {
      "x": 0,
      "y": 7,
      "z": -2,
      "name": "Rock_Sandstone_Brick",
      "rotation": 3
    },
    {
      "x": 0,
      "y": 1,
      "z": -1,
      "name": "Rock_Sandstone_Cobble",
      "rotation": 3
    },
    {
      "x": 0,
      "y": 2,
      "z": -1,
      "name": "Rock_Sandstone_Cobble",
      "rotation": 3
    },
    {
      "x": 0,
      "y": 3,
      "z": -1,
      "name": "Rock_Sandstone_Brick",
      "rotation": 3
    },
    {
      "x": 0,
      "y": 4,
      "z": -1,
      "name": "Rock_Sandstone_Brick",
      "rotation": 3
    },
    {
      "x": 0,
      "y": 5,
      "z": -1,
      "name": "Rock_Sandstone_Brick",
      "rotation": 3
    },
    {
      "x": 0,
      "y": 6,
      "z": -1,
      "name": "Rock_Sandstone_Brick_Pillar_Base",
      "rotation": 3
    },
    {
      "x": 0,
      "y": 7,
      "z": -1,
      "name": "Rock_Sandstone_Brick_Half",
      "rotation": 3
    },
    {
      "x": 1,
      "y": 1,
      "z": -8,
      "name": "Rock_Sandstone_Cobble",
      "rotation": 3
    },
    {
      "x": 1,
      "y": 2,
      "z": -8,
      "name": "Rock_Sandstone_Cobble",
      "rotation": 3
    },
    {
      "x": 1,
      "y": 3,
      "z": -8,
      "name": "Rock_Sandstone_Brick",
      "rotation": 3
    },
    {
      "x": 1,
      "y": 4,
      "z": -8,
      "name": "Rock_Sandstone_Brick",
      "rotation": 3
    },
    {
      "x": 1,
      "y": 5,
      "z": -8,
      "name": "Rock_Sandstone_Brick",
      "rotation": 3
    },
    {
      "x": 1,
      "y": 6,
      "z": -8,
      "name": "Rock_Sandstone_Brick_Pillar_Base",
      "rotation": 3
    },
    {
      "x": 1,
      "y": 7,
      "z": -8,
      "name": "Rock_Sandstone_Brick_Half",
      "rotation": 3
    },
    {
      "x": 1,
      "y": 1,
      "z": -7,
      "name": "Rock_Sandstone_Cobble",
      "rotation": 3
    },
    {
      "x": 1,
      "y": 2,
      "z": -7,
      "name": "Rock_Sandstone_Cobble",
      "rotation": 3
    },
    {
      "x": 1,
      "y": 3,
      "z": -7,
      "name": "Rock_Sandstone_Brick",
      "rotation": 3
    },
    {
      "x": 1,
      "y": 4,
      "z": -7,
      "name": "Rock_Sandstone_Brick",
      "rotation": 3
    },
    {
      "x": 1,
      "y": 5,
      "z": -7,
      "name": "Rock_Sandstone_Brick",
      "rotation": 3
    },
    {
      "x": 1,
      "y": 6,
      "z": -7,
      "name": "Rock_Sandstone_Brick",
      "rotation": 3
    },
    {
      "x": 1,
      "y": 1,
      "z": -6,
      "name": "Rock_Sandstone_Cobble",
      "rotation": 3
    },
    {
      "x": 1,
      "y": 2,
      "z": -6,
      "name": "Rock_Sandstone_Brick",
      "rotation": 3
    },
    {
      "x": 1,
      "y": 3,
      "z": -6,
      "name": "Rock_Sandstone_Brick",
      "rotation": 3
    },
    {
      "x": 1,
      "y": 4,
      "z": -6,
      "name": "Rock_Sandstone_Brick",
      "rotation": 3
    },
    {
      "x": 1,
      "y": 5,
      "z": -6,
      "name": "Rock_Sandstone_Brick",
      "rotation": 3
    },
    {
      "x": 1,
      "y": 6,
      "z": -6,
      "name": "Rock_Sandstone_Brick",
      "rotation": 3
    },
    {
      "x": 1,
      "y": 7,
      "z": -6,
      "name": "Rock_Sandstone_Brick",
      "rotation": 3
    },
    {
      "x": 1,
      "y": 1,
      "z": -5,
      "name": "Rock_Sandstone_Brick",
      "rotation": 3
    },
    {
      "x": 1,
      "y": 2,
      "z": -5,
      "name": "Rock_Sandstone_Cobble",
      "rotation": 3
    },
    {
      "x": 1,
      "y": 3,
      "z": -5,
      "name": "Rock_Sandstone_Brick",
      "rotation": 3
    },
    {
      "x": 1,
      "y": 4,
      "z": -5,
      "name": "Rock_Sandstone_Brick",
      "rotation": 3
    },
    {
      "x": 1,
      "y": 5,
      "z": -5,
      "name": "Rock_Sandstone_Brick",
      "rotation": 3
    },
    {
      "x": 1,
      "y": 6,
      "z": -5,
      "name": "Rock_Sandstone_Brick",
      "rotation": 3
    },
    {
      "x": 1,
      "y": 7,
      "z": -5,
      "name": "Rock_Sandstone_Cobble",
      "rotation": 3
    },
    {
      "x": 1,
      "y": 8,
      "z": -5,
      "name": "Rock_Sandstone_Cobble",
      "rotation": 3
    },
    {
      "x": 1,
      "y": 1,
      "z": -4,
      "name": "Rock_Sandstone_Cobble",
      "rotation": 3
    },
    {
      "x": 1,
      "y": 2,
      "z": -4,
      "name": "Rock_Sandstone_Cobble",
      "rotation": 3
    },
    {
      "x": 1,
      "y": 3,
      "z": -4,
      "name": "Rock_Sandstone_Cobble",
      "rotation": 3
    },
    {
      "x": 1,
      "y": 4,
      "z": -4,
      "name": "Rock_Sandstone_Brick",
      "rotation": 3
    },
    {
      "x": 1,
      "y": 5,
      "z": -4,
      "name": "Rock_Sandstone_Brick",
      "rotation": 3
    },
    {
      "x": 1,
      "y": 6,
      "z": -4,
      "name": "Rock_Sandstone_Brick",
      "rotation": 3
    },
    {
      "x": 1,
      "y": 7,
      "z": -4,
      "name": "Rock_Sandstone_Cobble",
      "rotation": 3
    },
    {
      "x": 1,
      "y": 8,
      "z": -4,
      "name": "Rock_Sandstone_Cobble",
      "rotation": 3
    },
    {
      "x": 1,
      "y": 9,
      "z": -4,
      "name": "Rock_Sandstone_Cobble",
      "rotation": 3
    },
    {
      "x": 1,
      "y": 10,
      "z": -4,
      "name": "Rock_Sandstone_Brick",
      "rotation": 3
    },
    {
      "x": 1,
      "y": 16,
      "z": -4,
      "name": "Rock_Sandstone_Brick",
      "rotation": 3
    },
    {
      "x": 1,
      "y": 17,
      "z": -4,
      "name": "Rock_Sandstone_Brick_Ornate",
      "rotation": 3
    },
    {
      "x": 1,
      "y": 1,
      "z": -3,
      "name": "Rock_Sandstone_Cobble",
      "rotation": 3
    },
    {
      "x": 1,
      "y": 2,
      "z": -3,
      "name": "Rock_Sandstone_Brick",
      "rotation": 3
    },
    {
      "x": 1,
      "y": 3,
      "z": -3,
      "name": "Rock_Sandstone_Brick",
      "rotation": 3
    },
    {
      "x": 1,
      "y": 4,
      "z": -3,
      "name": "Rock_Sandstone_Brick",
      "rotation": 3
    },
    {
      "x": 1,
      "y": 5,
      "z": -3,
      "name": "Rock_Sandstone_Brick",
      "rotation": 3
    },
    {
      "x": 1,
      "y": 6,
      "z": -3,
      "name": "Rock_Sandstone_Brick",
      "rotation": 3
    },
    {
      "x": 1,
      "y": 7,
      "z": -3,
      "name": "Rock_Sandstone_Brick",
      "rotation": 3
    },
    {
      "x": 1,
      "y": 8,
      "z": -3,
      "name": "Rock_Sandstone_Cobble",
      "rotation": 3
    },
    {
      "x": 1,
      "y": 9,
      "z": -3,
      "name": "Rock_Sandstone_Cobble",
      "rotation": 3
    },
    {
      "x": 1,
      "y": 10,
      "z": -3,
      "name": "Rock_Sandstone_Brick",
      "rotation": 3
    },
    {
      "x": 1,
      "y": 11,
      "z": -3,
      "name": "Rock_Sandstone_Brick",
      "rotation": 3
    },
    {
      "x": 1,
      "y": 12,
      "z": -3,
      "name": "Rock_Sandstone_Brick",
      "rotation": 3
    },
    {
      "x": 1,
      "y": 13,
      "z": -3,
      "name": "Rock_Sandstone_Brick",
      "rotation": 3
    },
    {
      "x": 1,
      "y": 14,
      "z": -3,
      "name": "Rock_Sandstone_Brick",
      "rotation": 3
    },
    {
      "x": 1,
      "y": 15,
      "z": -3,
      "name": "Rock_Sandstone_Brick",
      "rotation": 3
    },
    {
      "x": 1,
      "y": 16,
      "z": -3,
      "name": "Rock_Sandstone_Brick",
      "rotation": 3
    },
    {
      "x": 1,
      "y": 17,
      "z": -3,
      "name": "Rock_Sandstone_Brick_Ornate",
      "rotation": 3
    },
    {
      "x": 1,
      "y": 18,
      "z": -3,
      "name": "Rock_Sandstone_Brick_Pillar_Base",
      "rotation": 3
    },
    {
      "x": 1,
      "y": 19,
      "z": -3,
      "name": "Rock_Sandstone_Brick_Pillar_Middle",
      "rotation": 3
    },
    {
      "x": 1,
      "y": 25,
      "z": -3,
      "name": "Rock_Sandstone_White_Brick",
      "rotation": 3
    },
    {
      "x": 1,
      "y": 26,
      "z": -3,
      "name": "Rock_Sandstone_White_Brick",
      "rotation": 3
    },
    {
      "x": 1,
      "y": 27,
      "z": -3,
      "name": "Rock_Sandstone_Brick_Smooth_Half",
      "rotation": 3
    },
    {
      "x": 1,
      "y": 1,
      "z": -2,
      "name": "Rock_Sandstone_Cobble",
      "rotation": 3
    },
    {
      "x": 1,
      "y": 2,
      "z": -2,
      "name": "Rock_Sandstone_Brick",
      "rotation": 3
    },
    {
      "x": 1,
      "y": 3,
      "z": -2,
      "name": "Rock_Sandstone_Brick",
      "rotation": 3
    },
    {
      "x": 1,
      "y": 4,
      "z": -2,
      "name": "Rock_Sandstone_Brick",
      "rotation": 3
    },
    {
      "x": 1,
      "y": 5,
      "z": -2,
      "name": "Rock_Sandstone_Brick",
      "rotation": 3
    },
    {
      "x": 1,
      "y": 6,
      "z": -2,
      "name": "Rock_Sandstone_Brick",
      "rotation": 3
    },
    {
      "x": 1,
      "y": 7,
      "z": -2,
      "name": "Rock_Sandstone_Brick",
      "rotation": 3
    },
    {
      "x": 1,
      "y": 8,
      "z": -2,
      "name": "Rock_Sandstone_Brick_Pillar_Base",
      "rotation": 3
    },
    {
      "x": 1,
      "y": 9,
      "z": -2,
      "name": "Rock_Sandstone_Brick_Pillar_Middle",
      "rotation": 3
    },
    {
      "x": 1,
      "y": 10,
      "z": -2,
      "name": "Rock_Sandstone_Brick_Pillar_Base",
      "rotation": 33
    },
    {
      "x": 1,
      "y": 11,
      "z": -2,
      "name": "Rock_Sandstone_Brick_Pillar_Middle",
      "rotation": 3
    },
    {
      "x": 1,
      "y": 12,
      "z": -2,
      "name": "Rock_Sandstone_Brick_Pillar_Middle",
      "rotation": 3
    },
    {
      "x": 1,
      "y": 13,
      "z": -2,
      "name": "Rock_Sandstone_Brick_Pillar_Middle",
      "rotation": 3
    },
    {
      "x": 1,
      "y": 14,
      "z": -2,
      "name": "Rock_Sandstone_Brick_Pillar_Middle",
      "rotation": 3
    },
    {
      "x": 1,
      "y": 15,
      "z": -2,
      "name": "Rock_Sandstone_Brick_Pillar_Base",
      "rotation": 33
    },
    {
      "x": 1,
      "y": 16,
      "z": -2,
      "name": "Rock_Sandstone_Brick_Stairs",
      "rotation": 3
    },
    {
      "x": 1,
      "y": 17,
      "z": -2,
      "name": "Rock_Sandstone_Brick_Ornate",
      "rotation": 3
    },
    {
      "x": 1,
      "y": 18,
      "z": -2,
      "name": "Rock_Sandstone_Brick_Wall",
      "rotation": 3
    },
    {
      "x": 1,
      "y": 22,
      "z": -2,
      "name": "Rock_Sandstone_Brick_Smooth",
      "rotation": 3
    },
    {
      "x": 1,
      "y": 1,
      "z": -1,
      "name": "Rock_Sandstone_Cobble",
      "rotation": 3
    },
    {
      "x": 1,
      "y": 2,
      "z": -1,
      "name": "Rock_Sandstone_Brick",
      "rotation": 3
    },
    {
      "x": 1,
      "y": 3,
      "z": -1,
      "name": "Rock_Sandstone_Brick",
      "rotation": 3
    },
    {
      "x": 1,
      "y": 4,
      "z": -1,
      "name": "Rock_Sandstone_Brick",
      "rotation": 3
    },
    {
      "x": 1,
      "y": 5,
      "z": -1,
      "name": "Rock_Sandstone_Brick",
      "rotation": 3
    },
    {
      "x": 1,
      "y": 6,
      "z": -1,
      "name": "Rock_Sandstone_Brick",
      "rotation": 3
    },
    {
      "x": 1,
      "y": 7,
      "z": -1,
      "name": "Rock_Sandstone_Brick",
      "rotation": 3
    },
    {
      "x": 1,
      "y": 17,
      "z": -1,
      "name": "Rock_Sandstone_Brick_Ornate",
      "rotation": 3
    },
    {
      "x": 1,
      "y": 18,
      "z": -1,
      "name": "*Rock_Sandstone_Brick_Wall_State_Definitions_Corner",
      "rotation": 2
    },
    {
      "x": 1,
      "y": 1,
      "z": 0,
      "name": "Rock_Sandstone_Cobble",
      "rotation": 3
    },
    {
      "x": 1,
      "y": 2,
      "z": 0,
      "name": "Rock_Sandstone_Cobble",
      "rotation": 3
    },
    {
      "x": 1,
      "y": 3,
      "z": 0,
      "name": "Rock_Sandstone_Brick",
      "rotation": 3
    },
    {
      "x": 1,
      "y": 4,
      "z": 0,
      "name": "Rock_Sandstone_Brick",
      "rotation": 3
    },
    {
      "x": 1,
      "y": 5,
      "z": 0,
      "name": "Rock_Sandstone_Brick",
      "rotation": 3
    },
    {
      "x": 1,
      "y": 6,
      "z": 0,
      "name": "Rock_Sandstone_Brick_Pillar_Base",
      "rotation": 3
    },
    {
      "x": 1,
      "y": 7,
      "z": 0,
      "name": "Rock_Sandstone_Brick_Half",
      "rotation": 3
    },
    {
      "x": 2,
      "y": 1,
      "z": -8,
      "name": "Rock_Sandstone_Cobble",
      "rotation": 3
    },
    {
      "x": 2,
      "y": 2,
      "z": -8,
      "name": "Rock_Sandstone_Cobble",
      "rotation": 3
    },
    {
      "x": 2,
      "y": 3,
      "z": -8,
      "name": "Rock_Sandstone_Cobble",
      "rotation": 3
    },
    {
      "x": 2,
      "y": 4,
      "z": -8,
      "name": "Rock_Sandstone_Brick",
      "rotation": 3
    },
    {
      "x": 2,
      "y": 5,
      "z": -8,
      "name": "Rock_Sandstone_Brick",
      "rotation": 3
    },
    {
      "x": 2,
      "y": 6,
      "z": -8,
      "name": "Rock_Sandstone_Brick_Pillar_Base",
      "rotation": 3
    },
    {
      "x": 2,
      "y": 1,
      "z": -7,
      "name": "Rock_Sandstone_Cobble",
      "rotation": 3
    },
    {
      "x": 2,
      "y": 6,
      "z": -7,
      "name": "Rock_Sandstone_Brick",
      "rotation": 3
    },
    {
      "x": 2,
      "y": 1,
      "z": -6,
      "name": "Rock_Sandstone_Cobble",
      "rotation": 3
    },
    {
      "x": 2,
      "y": 2,
      "z": -6,
      "name": "Rock_Sandstone_Cobble_Stairs",
      "rotation": 2
    },
    {
      "x": 2,
      "y": 6,
      "z": -6,
      "name": "Rock_Sandstone_Brick",
      "rotation": 3
    },
    {
      "x": 2,
      "y": 1,
      "z": -5,
      "name": "Rock_Sandstone_Cobble",
      "rotation": 3
    },
    {
      "x": 2,
      "y": 2,
      "z": -5,
      "name": "Rock_Sandstone_Cobble",
      "rotation": 3
    },
    {
      "x": 2,
      "y": 3,
      "z": -5,
      "name": "Rock_Sandstone_Cobble_Stairs",
      "rotation": 2
    },
    {
      "x": 2,
      "y": 1,
      "z": -4,
      "name": "Rock_Sandstone_Brick",
      "rotation": 3
    },
    {
      "x": 2,
      "y": 2,
      "z": -4,
      "name": "Rock_Sandstone_Cobble",
      "rotation": 3
    },
    {
      "x": 2,
      "y": 3,
      "z": -4,
      "name": "Rock_Sandstone_Cobble",
      "rotation": 3
    },
    {
      "x": 2,
      "y": 4,
      "z": -4,
      "name": "Rock_Sandstone_Cobble_Stairs",
      "rotation": 2
    },
    {
      "x": 2,
      "y": 9,
      "z": -4,
      "name": "Rock_Sandstone_Cobble",
      "rotation": 3
    },
    {
      "x": 2,
      "y": 1,
      "z": -3,
      "name": "Rock_Sandstone_Brick",
      "rotation": 3
    },
    {
      "x": 2,
      "y": 2,
      "z": -3,
      "name": "Rock_Sandstone_Cobble",
      "rotation": 3
    },
    {
      "x": 2,
      "y": 3,
      "z": -3,
      "name": "Rock_Sandstone_Cobble",
      "rotation": 3
    },
    {
      "x": 2,
      "y": 4,
      "z": -3,
      "name": "Rock_Sandstone_Cobble",
      "rotation": 3
    },
    {
      "x": 2,
      "y": 5,
      "z": -3,
      "name": "Rock_Sandstone_Cobble_Stairs",
      "rotation": 2
    },
    {
      "x": 2,
      "y": 9,
      "z": -3,
      "name": "Rock_Sandstone_Cobble",
      "rotation": 3
    },
    {
      "x": 2,
      "y": 17,
      "z": -3,
      "name": "Wood_Drywood_Planks",
      "rotation": 3
    },
    {
      "x": 2,
      "y": 18,
      "z": -3,
      "name": "Rock_Sandstone_Brick_Smooth_Half",
      "rotation": 6
    },
    {
      "x": 2,
      "y": 1,
      "z": -2,
      "name": "Rock_Sandstone_Brick",
      "rotation": 3
    },
    {
      "x": 2,
      "y": 2,
      "z": -2,
      "name": "Rock_Sandstone_Cobble",
      "rotation": 3
    },
    {
      "x": 2,
      "y": 3,
      "z": -2,
      "name": "Rock_Sandstone_Cobble",
      "rotation": 3
    },
    {
      "x": 2,
      "y": 4,
      "z": -2,
      "name": "Rock_Sandstone_Cobble",
      "rotation": 3
    },
    {
      "x": 2,
      "y": 5,
      "z": -2,
      "name": "Rock_Sandstone_Brick",
      "rotation": 3
    },
    {
      "x": 2,
      "y": 6,
      "z": -2,
      "name": "Rock_Sandstone_Brick",
      "rotation": 3
    },
    {
      "x": 2,
      "y": 7,
      "z": -2,
      "name": "Rock_Sandstone_Cobble",
      "rotation": 3
    },
    {
      "x": 2,
      "y": 8,
      "z": -2,
      "name": "Rock_Sandstone_Cobble",
      "rotation": 3
    },
    {
      "x": 2,
      "y": 9,
      "z": -2,
      "name": "Rock_Sandstone_Cobble",
      "rotation": 3
    },
    {
      "x": 2,
      "y": 10,
      "z": -2,
      "name": "Rock_Sandstone_Brick",
      "rotation": 3
    },
    {
      "x": 2,
      "y": 11,
      "z": -2,
      "name": "Rock_Sandstone_Brick",
      "rotation": 3
    },
    {
      "x": 2,
      "y": 12,
      "z": -2,
      "name": "Rock_Sandstone_Brick",
      "rotation": 3
    },
    {
      "x": 2,
      "y": 13,
      "z": -2,
      "name": "Rock_Sandstone_Brick",
      "rotation": 3
    },
    {
      "x": 2,
      "y": 14,
      "z": -2,
      "name": "Rock_Sandstone_Brick",
      "rotation": 3
    },
    {
      "x": 2,
      "y": 15,
      "z": -2,
      "name": "Rock_Sandstone_Brick",
      "rotation": 3
    },
    {
      "x": 2,
      "y": 16,
      "z": -2,
      "name": "Rock_Sandstone_Brick",
      "rotation": 3
    },
    {
      "x": 2,
      "y": 17,
      "z": -2,
      "name": "Rock_Sandstone_Brick_Ornate",
      "rotation": 3
    },
    {
      "x": 2,
      "y": 18,
      "z": -2,
      "name": "Rock_Sandstone_Brick",
      "rotation": 3
    },
    {
      "x": 2,
      "y": 19,
      "z": -2,
      "name": "Rock_Sandstone_Brick",
      "rotation": 3
    },
    {
      "x": 2,
      "y": 20,
      "z": -2,
      "name": "Rock_Sandstone_Brick",
      "rotation": 3
    },
    {
      "x": 2,
      "y": 21,
      "z": -2,
      "name": "Rock_Sandstone_Brick_Ornate",
      "rotation": 3
    },
    {
      "x": 2,
      "y": 22,
      "z": -2,
      "name": "Rock_Sandstone_Brick",
      "rotation": 3
    },
    {
      "x": 2,
      "y": 23,
      "z": -2,
      "name": "Rock_Sandstone_Brick_Smooth",
      "rotation": 3
    },
    {
      "x": 2,
      "y": 24,
      "z": -2,
      "name": "Rock_Sandstone_Brick_Smooth",
      "rotation": 3
    },
    {
      "x": 2,
      "y": 25,
      "z": -2,
      "name": "Rock_Sandstone_White_Brick",
      "rotation": 3
    },
    {
      "x": 2,
      "y": 26,
      "z": -2,
      "name": "Rock_Sandstone_White_Brick",
      "rotation": 3
    },
    {
      "x": 2,
      "y": 27,
      "z": -2,
      "name": "Rock_Sandstone_Brick_Smooth",
      "rotation": 3
    },
    {
      "x": 2,
      "y": 1,
      "z": -1,
      "name": "Rock_Sandstone_Cobble",
      "rotation": 3
    },
    {
      "x": 2,
      "y": 2,
      "z": -1,
      "name": "Rock_Sandstone_Cobble",
      "rotation": 3
    },
    {
      "x": 2,
      "y": 3,
      "z": -1,
      "name": "Rock_Sandstone_Brick",
      "rotation": 3
    },
    {
      "x": 2,
      "y": 4,
      "z": -1,
      "name": "Rock_Sandstone_Brick",
      "rotation": 3
    },
    {
      "x": 2,
      "y": 5,
      "z": -1,
      "name": "Rock_Sandstone_Brick",
      "rotation": 3
    },
    {
      "x": 2,
      "y": 6,
      "z": -1,
      "name": "Rock_Sandstone_Brick",
      "rotation": 3
    },
    {
      "x": 2,
      "y": 7,
      "z": -1,
      "name": "Rock_Sandstone_Brick",
      "rotation": 3
    },
    {
      "x": 2,
      "y": 8,
      "z": -1,
      "name": "Rock_Sandstone_Brick_Pillar_Base",
      "rotation": 3
    },
    {
      "x": 2,
      "y": 9,
      "z": -1,
      "name": "Rock_Sandstone_Brick_Pillar_Middle",
      "rotation": 3
    },
    {
      "x": 2,
      "y": 10,
      "z": -1,
      "name": "Rock_Sandstone_Brick_Pillar_Base",
      "rotation": 33
    },
    {
      "x": 2,
      "y": 11,
      "z": -1,
      "name": "Rock_Sandstone_Brick_Pillar_Middle",
      "rotation": 3
    },
    {
      "x": 2,
      "y": 12,
      "z": -1,
      "name": "Rock_Sandstone_Brick_Pillar_Middle",
      "rotation": 3
    },
    {
      "x": 2,
      "y": 13,
      "z": -1,
      "name": "Rock_Sandstone_Brick_Pillar_Middle",
      "rotation": 3
    },
    {
      "x": 2,
      "y": 14,
      "z": -1,
      "name": "Rock_Sandstone_Brick_Pillar_Middle",
      "rotation": 3
    },
    {
      "x": 2,
      "y": 15,
      "z": -1,
      "name": "Rock_Sandstone_Brick_Pillar_Base",
      "rotation": 33
    },
    {
      "x": 2,
      "y": 16,
      "z": -1,
      "name": "Rock_Sandstone_Brick_Stairs"
    },
    {
      "x": 2,
      "y": 17,
      "z": -1,
      "name": "Rock_Sandstone_Brick_Ornate",
      "rotation": 3
    },
    {
      "x": 2,
      "y": 18,
      "z": -1,
      "name": "Rock_Sandstone_Brick_Wall"
    },
    {
      "x": 2,
      "y": 22,
      "z": -1,
      "name": "Rock_Sandstone_Brick_Smooth",
      "rotation": 3
    },
    {
      "x": 2,
      "y": 27,
      "z": -1,
      "name": "Rock_Sandstone_Brick_Smooth_Half",
      "rotation": 4
    },
    {
      "x": 2,
      "y": 1,
      "z": 0,
      "name": "Rock_Sandstone_Cobble",
      "rotation": 3
    },
    {
      "x": 2,
      "y": 2,
      "z": 0,
      "name": "Rock_Sandstone_Cobble",
      "rotation": 3
    },
    {
      "x": 2,
      "y": 3,
      "z": 0,
      "name": "Rock_Sandstone_Cobble",
      "rotation": 3
    },
    {
      "x": 2,
      "y": 4,
      "z": 0,
      "name": "Rock_Sandstone_Brick",
      "rotation": 3
    },
    {
      "x": 2,
      "y": 5,
      "z": 0,
      "name": "Rock_Sandstone_Brick",
      "rotation": 3
    },
    {
      "x": 2,
      "y": 6,
      "z": 0,
      "name": "Rock_Sandstone_Brick_Pillar_Base",
      "rotation": 3
    },
    {
      "x": 2,
      "y": 7,
      "z": 0,
      "name": "Rock_Sandstone_Brick",
      "rotation": 3
    },
    {
      "x": 3,
      "y": 1,
      "z": -9,
      "name": "Rock_Sandstone_Cobble_Stairs",
      "rotation": 2
    },
    {
      "x": 3,
      "y": 1,
      "z": -8,
      "name": "Rock_Sandstone_Cobble",
      "rotation": 3
    },
    {
      "x": 3,
      "y": 2,
      "z": -8,
      "name": "Wood_Drywood_Planks_Half",
      "rotation": 5
    },
    {
      "x": 3,
      "y": 3,
      "z": -8,
      "name": "Wood_Drywood_Planks_Half",
      "rotation": 5
    },
    {
      "x": 3,
      "y": 4,
      "z": -8,
      "name": "Wood_Drywood_Stairs",
      "rotation": 33
    },
    {
      "x": 3,
      "y": 5,
      "z": -8,
      "name": "Rock_Sandstone_Brick",
      "rotation": 3
    },
    {
      "x": 3,
      "y": 6,
      "z": -8,
      "name": "Rock_Sandstone_Brick_Pillar_Base",
      "rotation": 3
    },
    {
      "x": 3,
      "y": 7,
      "z": -8,
      "name": "Rock_Sandstone_Brick",
      "rotation": 3
    },
    {
      "x": 3,
      "y": 1,
      "z": -7,
      "name": "Rock_Sandstone_Cobble",
      "rotation": 3
    },
    {
      "x": 3,
      "y": 6,
      "z": -7,
      "name": "Rock_Sandstone_Brick",
      "rotation": 3
    },
    {
      "x": 3,
      "y": 1,
      "z": -6,
      "name": "Rock_Sandstone_Cobble",
      "rotation": 3
    },
    {
      "x": 3,
      "y": 2,
      "z": -6,
      "name": "Rock_Sandstone_Cobble_Stairs",
      "rotation": 2
    },
    {
      "x": 3,
      "y": 6,
      "z": -6,
      "name": "Rock_Sandstone_Brick",
      "rotation": 3
    },
    {
      "x": 3,
      "y": 7,
      "z": -6,
      "name": "Rock_Sandstone_Cobble",
      "rotation": 3
    },
    {
      "x": 3,
      "y": 1,
      "z": -5,
      "name": "Rock_Sandstone_Cobble",
      "rotation": 3
    },
    {
      "x": 3,
      "y": 2,
      "z": -5,
      "name": "Rock_Sandstone_Cobble",
      "rotation": 3
    },
    {
      "x": 3,
      "y": 3,
      "z": -5,
      "name": "Rock_Sandstone_Cobble_Stairs",
      "rotation": 2
    },
    {
      "x": 3,
      "y": 1,
      "z": -4,
      "name": "Rock_Sandstone_Brick",
      "rotation": 3
    },
    {
      "x": 3,
      "y": 2,
      "z": -4,
      "name": "Rock_Sandstone_Cobble",
      "rotation": 3
    },
    {
      "x": 3,
      "y": 3,
      "z": -4,
      "name": "Rock_Sandstone_Cobble",
      "rotation": 3
    },
    {
      "x": 3,
      "y": 4,
      "z": -4,
      "name": "Rock_Sandstone_Cobble_Stairs",
      "rotation": 2
    },
    {
      "x": 3,
      "y": 9,
      "z": -4,
      "name": "Rock_Sandstone_Cobble",
      "rotation": 3
    },
    {
      "x": 3,
      "y": 1,
      "z": -3,
      "name": "Rock_Sandstone_Brick",
      "rotation": 3
    },
    {
      "x": 3,
      "y": 2,
      "z": -3,
      "name": "Rock_Sandstone_Cobble",
      "rotation": 3
    },
    {
      "x": 3,
      "y": 3,
      "z": -3,
      "name": "Rock_Sandstone_Cobble",
      "rotation": 3
    },
    {
      "x": 3,
      "y": 4,
      "z": -3,
      "name": "Rock_Sandstone_Cobble",
      "rotation": 3
    },
    {
      "x": 3,
      "y": 5,
      "z": -3,
      "name": "Rock_Sandstone_Cobble_Stairs",
      "rotation": 2
    },
    {
      "x": 3,
      "y": 9,
      "z": -3,
      "name": "Rock_Sandstone_Cobble",
      "rotation": 3
    },
    {
      "x": 3,
      "y": 12,
      "z": -3,
      "name": "Furniture_Desert_Ladder",
      "rotation": 2
    },
    {
      "x": 3,
      "y": 13,
      "z": -3,
      "name": "Furniture_Desert_Ladder",
      "rotation": 2
    },
    {
      "x": 3,
      "y": 14,
      "z": -3,
      "name": "Furniture_Desert_Ladder",
      "rotation": 2
    },
    {
      "x": 3,
      "y": 15,
      "z": -3,
      "name": "Furniture_Desert_Ladder",
      "rotation": 2
    },
    {
      "x": 3,
      "y": 16,
      "z": -3,
      "name": "Furniture_Desert_Ladder",
      "rotation": 2
    },
    {
      "x": 3,
      "y": 17,
      "z": -3,
      "name": "Furniture_Desert_Ladder",
      "rotation": 2
    },
    {
      "x": 3,
      "y": 19,
      "z": -3,
      "name": "Furniture_Desert_Ladder",
      "rotation": 2
    },
    {
      "x": 3,
      "y": 1,
      "z": -2,
      "name": "Rock_Sandstone_Brick",
      "rotation": 3
    },
    {
      "x": 3,
      "y": 2,
      "z": -2,
      "name": "Rock_Sandstone_Cobble",
      "rotation": 3
    },
    {
      "x": 3,
      "y": 3,
      "z": -2,
      "name": "Rock_Sandstone_Cobble",
      "rotation": 3
    },
    {
      "x": 3,
      "y": 4,
      "z": -2,
      "name": "Rock_Sandstone_Cobble",
      "rotation": 3
    },
    {
      "x": 3,
      "y": 5,
      "z": -2,
      "name": "Rock_Sandstone_Cobble",
      "rotation": 3
    },
    {
      "x": 3,
      "y": 9,
      "z": -2,
      "name": "Rock_Sandstone_Cobble",
      "rotation": 3
    },
    {
      "x": 3,
      "y": 10,
      "z": -2,
      "name": "Wood_Dry_Trunk",
      "rotation": 3
    },
    {
      "x": 3,
      "y": 11,
      "z": -2,
      "name": "Wood_Dry_Trunk",
      "rotation": 3
    },
    {
      "x": 3,
      "y": 12,
      "z": -2,
      "name": "Wood_Dry_Trunk",
      "rotation": 3
    },
    {
      "x": 3,
      "y": 13,
      "z": -2,
      "name": "Wood_Dry_Trunk",
      "rotation": 3
    },
    {
      "x": 3,
      "y": 14,
      "z": -2,
      "name": "Wood_Dry_Trunk",
      "rotation": 3
    },
    {
      "x": 3,
      "y": 15,
      "z": -2,
      "name": "Wood_Dry_Trunk",
      "rotation": 3
    },
    {
      "x": 3,
      "y": 16,
      "z": -2,
      "name": "Wood_Dry_Trunk",
      "rotation": 3
    },
    {
      "x": 3,
      "y": 17,
      "z": -2,
      "name": "Wood_Dry_Trunk",
      "rotation": 3
    },
    {
      "x": 3,
      "y": 18,
      "z": -2,
      "name": "Wood_Dry_Trunk",
      "rotation": 3
    },
    {
      "x": 3,
      "y": 19,
      "z": -2,
      "name": "Wood_Dry_Trunk",
      "rotation": 3
    },
    {
      "x": 3,
      "y": 20,
      "z": -2,
      "name": "Wood_Dry_Trunk",
      "rotation": 3
    },
    {
      "x": 3,
      "y": 21,
      "z": -2,
      "name": "Wood_Dry_Trunk",
      "rotation": 3
    },
    {
      "x": 3,
      "y": 22,
      "z": -2,
      "name": "Wood_Dry_Trunk",
      "rotation": 3
    },
    {
      "x": 3,
      "y": 23,
      "z": -2,
      "name": "Wood_Drywood_Planks",
      "rotation": 3
    },
    {
      "x": 3,
      "y": 1,
      "z": -1,
      "name": "Rock_Sandstone_Brick",
      "rotation": 3
    },
    {
      "x": 3,
      "y": 2,
      "z": -1,
      "name": "Rock_Sandstone_Brick",
      "rotation": 3
    },
    {
      "x": 3,
      "y": 3,
      "z": -1,
      "name": "Rock_Sandstone_Cobble",
      "rotation": 3
    },
    {
      "x": 3,
      "y": 4,
      "z": -1,
      "name": "Rock_Sandstone_Brick",
      "rotation": 3
    },
    {
      "x": 3,
      "y": 5,
      "z": -1,
      "name": "Rock_Sandstone_Brick",
      "rotation": 3
    },
    {
      "x": 3,
      "y": 6,
      "z": -1,
      "name": "Rock_Sandstone_Brick",
      "rotation": 3
    },
    {
      "x": 3,
      "y": 7,
      "z": -1,
      "name": "Rock_Sandstone_Brick",
      "rotation": 3
    },
    {
      "x": 3,
      "y": 8,
      "z": -1,
      "name": "Rock_Sandstone_Cobble",
      "rotation": 3
    },
    {
      "x": 3,
      "y": 9,
      "z": -1,
      "name": "Rock_Sandstone_Cobble",
      "rotation": 3
    },
    {
      "x": 3,
      "y": 10,
      "z": -1,
      "name": "Rock_Sandstone_Brick",
      "rotation": 3
    },
    {
      "x": 3,
      "y": 11,
      "z": -1,
      "name": "Rock_Sandstone_Brick",
      "rotation": 3
    },
    {
      "x": 3,
      "y": 12,
      "z": -1,
      "name": "Rock_Sandstone_Brick",
      "rotation": 3
    },
    {
      "x": 3,
      "y": 13,
      "z": -1,
      "name": "Rock_Sandstone_Brick",
      "rotation": 3
    },
    {
      "x": 3,
      "y": 14,
      "z": -1,
      "name": "Rock_Sandstone_Brick",
      "rotation": 3
    },
    {
      "x": 3,
      "y": 15,
      "z": -1,
      "name": "Rock_Sandstone_Brick",
      "rotation": 3
    },
    {
      "x": 3,
      "y": 16,
      "z": -1,
      "name": "Rock_Sandstone_Brick",
      "rotation": 3
    },
    {
      "x": 3,
      "y": 17,
      "z": -1,
      "name": "Rock_Sandstone_Brick_Ornate",
      "rotation": 3
    },
    {
      "x": 3,
      "y": 18,
      "z": -1,
      "name": "Rock_Sandstone_Brick_Pillar_Base",
      "rotation": 3
    },
    {
      "x": 3,
      "y": 19,
      "z": -1,
      "name": "Rock_Sandstone_Brick_Pillar_Middle",
      "rotation": 3
    },
    {
      "x": 3,
      "y": 20,
      "z": -1,
      "name": "Rock_Sandstone_Brick_Pillar_Base",
      "rotation": 33
    },
    {
      "x": 3,
      "y": 21,
      "z": -1,
      "name": "Rock_Sandstone_Brick_Ornate",
      "rotation": 3
    },
    {
      "x": 3,
      "y": 22,
      "z": -1,
      "name": "Rock_Sandstone_Brick",
      "rotation": 3
    },
    {
      "x": 3,
      "y": 23,
      "z": -1,
      "name": "Rock_Sandstone_Brick_Stairs"
    },
    {
      "x": 3,
      "y": 24,
      "z": -1,
      "name": "Rock_Sandstone_Brick_Stairs",
      "rotation": 32
    },
    {
      "x": 3,
      "y": 25,
      "z": -1,
      "name": "Rock_Sandstone_White_Brick",
      "rotation": 3
    },
    {
      "x": 3,
      "y": 26,
      "z": -1,
      "name": "Rock_Sandstone_White_Brick",
      "rotation": 3
    },
    {
      "x": 3,
      "y": 27,
      "z": -1,
      "name": "Rock_Sandstone_Brick_Smooth",
      "rotation": 3
    },
    {
      "x": 3,
      "y": 1,
      "z": 0,
      "name": "Rock_Sandstone_Cobble",
      "rotation": 3
    },
    {
      "x": 3,
      "y": 2,
      "z": 0,
      "name": "Rock_Sandstone_Cobble",
      "rotation": 3
    },
    {
      "x": 3,
      "y": 3,
      "z": 0,
      "name": "Rock_Sandstone_Cobble",
      "rotation": 3
    },
    {
      "x": 3,
      "y": 4,
      "z": 0,
      "name": "Rock_Sandstone_Cobble",
      "rotation": 3
    },
    {
      "x": 3,
      "y": 5,
      "z": 0,
      "name": "Rock_Sandstone_Brick",
      "rotation": 3
    },
    {
      "x": 3,
      "y": 6,
      "z": 0,
      "name": "Rock_Sandstone_Brick_Pillar_Base",
      "rotation": 3
    },
    {
      "x": 3,
      "y": 7,
      "z": 0,
      "name": "Rock_Sandstone_Brick",
      "rotation": 3
    },
    {
      "x": 3,
      "y": 8,
      "z": 0,
      "name": "Rock_Sandstone_Cobble_Stairs"
    },
    {
      "x": 3,
      "y": 9,
      "z": 0,
      "name": "Rock_Sandstone_Cobble_Half",
      "rotation": 4
    },
    {
      "x": 3,
      "y": 12,
      "z": 0,
      "name": "Rock_Sandstone_Brick_Smooth_Half",
      "rotation": 7
    },
    {
      "x": 3,
      "y": 13,
      "z": 0,
      "name": "Rock_Sandstone_Brick_Smooth_Half",
      "rotation": 7
    },
    {
      "x": 3,
      "y": 22,
      "z": 0,
      "name": "Rock_Sandstone_Brick_Smooth_Half",
      "rotation": 4
    },
    {
      "x": 4,
      "y": 1,
      "z": -9,
      "name": "Rock_Sandstone_Cobble_Stairs",
      "rotation": 2
    },
    {
      "x": 4,
      "y": 1,
      "z": -8,
      "name": "Rock_Sandstone_Cobble",
      "rotation": 3
    },
    {
      "x": 4,
      "y": 6,
      "z": -8,
      "name": "Rock_Sandstone_Brick_Half",
      "rotation": 33
    },
    {
      "x": 4,
      "y": 7,
      "z": -8,
      "name": "Rock_Sandstone_Brick",
      "rotation": 3
    },
    {
      "x": 4,
      "y": 8,
      "z": -8,
      "name": "Rock_Sandstone_Cobble_Stairs",
      "rotation": 2
    },
    {
      "x": 4,
      "y": 1,
      "z": -7,
      "name": "Rock_Sandstone_Cobble",
      "rotation": 3
    },
    {
      "x": 4,
      "y": 6,
      "z": -7,
      "name": "Rock_Sandstone_Brick_Half",
      "rotation": 33
    },
    {
      "x": 4,
      "y": 7,
      "z": -7,
      "name": "Rock_Sandstone_Brick",
      "rotation": 3
    },
    {
      "x": 4,
      "y": 1,
      "z": -6,
      "name": "Rock_Sandstone_Cobble",
      "rotation": 3
    },
    {
      "x": 4,
      "y": 6,
      "z": -6,
      "name": "Rock_Sandstone_Brick",
      "rotation": 3
    },
    {
      "x": 4,
      "y": 7,
      "z": -6,
      "name": "Rock_Sandstone_Cobble",
      "rotation": 3
    },
    {
      "x": 4,
      "y": 8,
      "z": -6,
      "name": "Rock_Sandstone_Cobble",
      "rotation": 3
    },
    {
      "x": 4,
      "y": 1,
      "z": -5,
      "name": "Rock_Sandstone_Cobble",
      "rotation": 1
    },
    {
      "x": 4,
      "y": 6,
      "z": -5,
      "name": "Rock_Sandstone_Brick",
      "rotation": 3
    },
    {
      "x": 4,
      "y": 7,
      "z": -5,
      "name": "Rock_Sandstone_Cobble",
      "rotation": 3
    },
    {
      "x": 4,
      "y": 8,
      "z": -5,
      "name": "Rock_Sandstone_Cobble",
      "rotation": 3
    },
    {
      "x": 4,
      "y": 1,
      "z": -4,
      "name": "Rock_Sandstone_Brick",
      "rotation": 3
    },
    {
      "x": 4,
      "y": 2,
      "z": -4,
      "name": "Rock_Sandstone_Brick",
      "rotation": 3
    },
    {
      "x": 4,
      "y": 3,
      "z": -4,
      "name": "Rock_Sandstone_Brick",
      "rotation": 3
    },
    {
      "x": 4,
      "y": 4,
      "z": -4,
      "name": "Rock_Sandstone_Brick",
      "rotation": 3
    },
    {
      "x": 4,
      "y": 5,
      "z": -4,
      "name": "Rock_Sandstone_Brick",
      "rotation": 3
    },
    {
      "x": 4,
      "y": 6,
      "z": -4,
      "name": "Rock_Sandstone_Brick",
      "rotation": 3
    },
    {
      "x": 4,
      "y": 7,
      "z": -4,
      "name": "Rock_Sandstone_Brick",
      "rotation": 3
    },
    {
      "x": 4,
      "y": 8,
      "z": -4,
      "name": "Rock_Sandstone_Brick",
      "rotation": 3
    },
    {
      "x": 4,
      "y": 9,
      "z": -4,
      "name": "Rock_Sandstone_Brick",
      "rotation": 3
    },
    {
      "x": 4,
      "y": 1,
      "z": -3,
      "name": "Rock_Sandstone_Brick",
      "rotation": 3
    },
    {
      "x": 4,
      "y": 2,
      "z": -3,
      "name": "Rock_Sandstone_Cobble",
      "rotation": 3
    },
    {
      "x": 4,
      "y": 3,
      "z": -3,
      "name": "Rock_Sandstone_Cobble",
      "rotation": 3
    },
    {
      "x": 4,
      "y": 4,
      "z": -3,
      "name": "Rock_Sandstone_Cobble",
      "rotation": 3
    },
    {
      "x": 4,
      "y": 5,
      "z": -3,
      "name": "Rock_Sandstone_Cobble",
      "rotation": 3
    },
    {
      "x": 4,
      "y": 6,
      "z": -3,
      "name": "Rock_Sandstone_Cobble_Stairs",
      "rotation": 3
    },
    {
      "x": 4,
      "y": 9,
      "z": -3,
      "name": "Rock_Sandstone_Cobble_Half",
      "rotation": 33
    },
    {
      "x": 4,
      "y": 17,
      "z": -3,
      "name": "Wood_Drywood_Planks",
      "rotation": 3
    },
    {
      "x": 4,
      "y": 23,
      "z": -3,
      "name": "Wood_Drywood_Planks",
      "rotation": 3
    },
    {
      "x": 4,
      "y": 1,
      "z": -2,
      "name": "Rock_Sandstone_Brick",
      "rotation": 3
    },
    {
      "x": 4,
      "y": 2,
      "z": -2,
      "name": "Rock_Sandstone_Cobble",
      "rotation": 3
    },
    {
      "x": 4,
      "y": 3,
      "z": -2,
      "name": "Rock_Sandstone_Cobble",
      "rotation": 3
    },
    {
      "x": 4,
      "y": 4,
      "z": -2,
      "name": "Rock_Sandstone_Cobble",
      "rotation": 3
    },
    {
      "x": 4,
      "y": 5,
      "z": -2,
      "name": "Rock_Sandstone_Cobble",
      "rotation": 3
    },
    {
      "x": 4,
      "y": 6,
      "z": -2,
      "name": "Rock_Sandstone_Cobble_Stairs",
      "rotation": 3
    },
    {
      "x": 4,
      "y": 9,
      "z": -2,
      "name": "Rock_Sandstone_Cobble_Half",
      "rotation": 33
    },
    {
      "x": 4,
      "y": 10,
      "z": -2,
      "name": "Furniture_Village_Crate",
      "rotation": 3
    },
    {
      "x": 4,
      "y": 11,
      "z": -2,
      "name": "Furniture_Ancient_Barrel",
      "rotation": 3
    },
    {
      "x": 4,
      "y": 17,
      "z": -2,
      "name": "Wood_Drywood_Planks",
      "rotation": 3
    },
    {
      "x": 4,
      "y": 21,
      "z": -2,
      "name": "Rock_Sandstone_Brick",
      "rotation": 3
    },
    {
      "x": 4,
      "y": 22,
      "z": -2,
      "name": "Rock_Sandstone_Brick",
      "rotation": 3
    },
    {
      "x": 4,
      "y": 23,
      "z": -2,
      "name": "Wood_Drywood_Planks",
      "rotation": 3
    },
    {
      "x": 4,
      "y": 1,
      "z": -1,
      "name": "Rock_Sandstone_Brick",
      "rotation": 3
    },
    {
      "x": 4,
      "y": 2,
      "z": -1,
      "name": "Rock_Sandstone_Cobble",
      "rotation": 3
    },
    {
      "x": 4,
      "y": 3,
      "z": -1,
      "name": "Rock_Sandstone_Brick",
      "rotation": 3
    },
    {
      "x": 4,
      "y": 4,
      "z": -1,
      "name": "Rock_Sandstone_Brick",
      "rotation": 3
    },
    {
      "x": 4,
      "y": 5,
      "z": -1,
      "name": "Rock_Sandstone_Brick",
      "rotation": 3
    },
    {
      "x": 4,
      "y": 6,
      "z": -1,
      "name": "Rock_Sandstone_Brick",
      "rotation": 3
    },
    {
      "x": 4,
      "y": 7,
      "z": -1,
      "name": "Rock_Sandstone_Brick",
      "rotation": 3
    },
    {
      "x": 4,
      "y": 8,
      "z": -1,
      "name": "Rock_Sandstone_Cobble",
      "rotation": 3
    },
    {
      "x": 4,
      "y": 9,
      "z": -1,
      "name": "Rock_Sandstone_Cobble",
      "rotation": 3
    },
    {
      "x": 4,
      "y": 10,
      "z": -1,
      "name": "Rock_Sandstone_Brick",
      "rotation": 3
    },
    {
      "x": 4,
      "y": 11,
      "z": -1,
      "name": "Rock_Sandstone_Brick",
      "rotation": 3
    },
    {
      "x": 4,
      "y": 12,
      "z": -1,
      "name": "Furniture_Desert_Window"
    },
    {
      "x": 4,
      "y": 13,
      "z": -1,
      "name": "Furniture_Desert_Window"
    },
    {
      "x": 4,
      "y": 14,
      "z": -1,
      "name": "Rock_Sandstone_Brick",
      "rotation": 3
    },
    {
      "x": 4,
      "y": 15,
      "z": -1,
      "name": "Rock_Sandstone_Brick",
      "rotation": 3
    },
    {
      "x": 4,
      "y": 16,
      "z": -1,
      "name": "Rock_Sandstone_Brick",
      "rotation": 3
    },
    {
      "x": 4,
      "y": 17,
      "z": -1,
      "name": "Rock_Sandstone_Brick_Ornate",
      "rotation": 3
    },
    {
      "x": 4,
      "y": 18,
      "z": -1,
      "name": "Rock_Sandstone_Brick_Wall"
    },
    {
      "x": 4,
      "y": 21,
      "z": -1,
      "name": "Rock_Sandstone_Brick_Ornate",
      "rotation": 3
    },
    {
      "x": 4,
      "y": 22,
      "z": -1,
      "name": "Rock_Sandstone_Brick",
      "rotation": 3
    },
    {
      "x": 4,
      "y": 23,
      "z": -1,
      "name": "Rock_Sandstone_Brick_Stairs"
    },
    {
      "x": 4,
      "y": 24,
      "z": -1,
      "name": "Rock_Sandstone_Brick_Stairs",
      "rotation": 32
    },
    {
      "x": 4,
      "y": 25,
      "z": -1,
      "name": "Furniture_Desert_Window"
    },
    {
      "x": 4,
      "y": 26,
      "z": -1,
      "name": "Furniture_Desert_Window"
    },
    {
      "x": 4,
      "y": 27,
      "z": -1,
      "name": "Rock_Sandstone_Brick_Smooth_Half",
      "rotation": 3
    },
    {
      "x": 4,
      "y": 1,
      "z": 0,
      "name": "Rock_Sandstone_Cobble",
      "rotation": 3
    },
    {
      "x": 4,
      "y": 2,
      "z": 0,
      "name": "Rock_Sandstone_Cobble",
      "rotation": 3
    },
    {
      "x": 4,
      "y": 3,
      "z": 0,
      "name": "Rock_Sandstone_Cobble",
      "rotation": 3
    },
    {
      "x": 4,
      "y": 4,
      "z": 0,
      "name": "Rock_Sandstone_Brick",
      "rotation": 3
    },
    {
      "x": 4,
      "y": 5,
      "z": 0,
      "name": "Rock_Sandstone_Brick",
      "rotation": 3
    },
    {
      "x": 4,
      "y": 6,
      "z": 0,
      "name": "Rock_Sandstone_Brick_Pillar_Base",
      "rotation": 3
    },
    {
      "x": 4,
      "y": 7,
      "z": 0,
      "name": "Rock_Sandstone_Brick",
      "rotation": 3
    },
    {
      "x": 4,
      "y": 8,
      "z": 0,
      "name": "Rock_Sandstone_Cobble_Stairs"
    },
    {
      "x": 4,
      "y": 9,
      "z": 0,
      "name": "Rock_Sandstone_Cobble_Half",
      "rotation": 4
    },
    {
      "x": 4,
      "y": 11,
      "z": 0,
      "name": "Rock_Sandstone_Brick_Smooth_Half",
      "rotation": 4
    },
    {
      "x": 4,
      "y": 14,
      "z": 0,
      "name": "Rock_Sandstone_Brick_Smooth_Half",
      "rotation": 3
    },
    {
      "x": 4,
      "y": 22,
      "z": 0,
      "name": "Rock_Sandstone_Brick_Smooth_Half",
      "rotation": 4
    },
    {
      "x": 5,
      "y": 1,
      "z": -9,
      "name": "Rock_Sandstone_Cobble_Stairs",
      "rotation": 2
    },
    {
      "x": 5,
      "y": 1,
      "z": -8,
      "name": "Rock_Sandstone_Cobble",
      "rotation": 3
    },
    {
      "x": 5,
      "y": 2,
      "z": -8,
      "name": "Wood_Drywood_Planks_Half",
      "rotation": 7
    },
    {
      "x": 5,
      "y": 3,
      "z": -8,
      "name": "Wood_Drywood_Planks_Half",
      "rotation": 7
    },
    {
      "x": 5,
      "y": 8,
      "z": -8,
      "name": "Rock_Sandstone_Cobble_Half",
      "rotation": 6
    },
    {
      "x": 5,
      "y": 9,
      "z": -8,
      "name": "Rock_Sandstone_Cobble_Half",
      "rotation": 6
    },
    {
      "x": 5,
      "y": 1,
      "z": -7,
      "name": "Rock_Sandstone_Cobble",
      "rotation": 3
    },
    {
      "x": 5,
      "y": 6,
      "z": -7,
      "name": "Rock_Sandstone_Brick_Half",
      "rotation": 33
    },
    {
      "x": 5,
      "y": 7,
      "z": -7,
      "name": "Rock_Sandstone_Brick",
      "rotation": 3
    },
    {
      "x": 5,
      "y": 8,
      "z": -7,
      "name": "Rock_Sandstone_Cobble",
      "rotation": 3
    },
    {
      "x": 5,
      "y": 9,
      "z": -7,
      "name": "Rock_Sandstone_Cobble",
      "rotation": 3
    },
    {
      "x": 5,
      "y": 1,
      "z": -6,
      "name": "Rock_Sandstone_Cobble",
      "rotation": 3
    },
    {
      "x": 5,
      "y": 6,
      "z": -6,
      "name": "Rock_Sandstone_Cobble",
      "rotation": 3
    },
    {
      "x": 5,
      "y": 7,
      "z": -6,
      "name": "Rock_Sandstone_Cobble",
      "rotation": 3
    },
    {
      "x": 5,
      "y": 8,
      "z": -6,
      "name": "Rock_Sandstone_Cobble_Half",
      "rotation": 3
    },
    {
      "x": 5,
      "y": 1,
      "z": -5,
      "name": "Rock_Sandstone_Cobble",
      "rotation": 3
    },
    {
      "x": 5,
      "y": 6,
      "z": -5,
      "name": "Rock_Sandstone_Cobble",
      "rotation": 3
    },
    {
      "x": 5,
      "y": 7,
      "z": -5,
      "name": "Rock_Sandstone_Cobble",
      "rotation": 3
    },
    {
      "x": 5,
      "y": 8,
      "z": -5,
      "name": "Rock_Sandstone_Cobble_Half",
      "rotation": 3
    },
    {
      "x": 5,
      "y": 1,
      "z": -4,
      "name": "Rock_Sandstone_Cobble",
      "rotation": 3
    },
    {
      "x": 5,
      "y": 6,
      "z": -4,
      "name": "Rock_Sandstone_Cobble",
      "rotation": 3
    },
    {
      "x": 5,
      "y": 7,
      "z": -4,
      "name": "Rock_Sandstone_Cobble",
      "rotation": 3
    },
    {
      "x": 5,
      "y": 23,
      "z": -4,
      "name": "Wood_Drywood_Beam",
      "rotation": 7
    },
    {
      "x": 5,
      "y": 1,
      "z": -3,
      "name": "Rock_Sandstone_Cobble",
      "rotation": 3
    },
    {
      "x": 5,
      "y": 2,
      "z": -3,
      "name": "Furniture_Desert_Chair",
      "rotation": 1
    },
    {
      "x": 5,
      "y": 6,
      "z": -3,
      "name": "Rock_Sandstone_Cobble",
      "rotation": 3
    },
    {
      "x": 5,
      "y": 7,
      "z": -3,
      "name": "Rock_Sandstone_Cobble_Half",
      "rotation": 3
    },
    {
      "x": 5,
      "y": 17,
      "z": -3,
      "name": "Wood_Drywood_Planks",
      "rotation": 3
    },
    {
      "x": 5,
      "y": 23,
      "z": -3,
      "name": "Wood_Drywood_Planks",
      "rotation": 3
    },
    {
      "x": 5,
      "y": 1,
      "z": -2,
      "name": "Rock_Sandstone_Cobble",
      "rotation": 3
    },
    {
      "x": 5,
      "y": 2,
      "z": -2,
      "name": "Furniture_Desert_Table",
      "filler": 31,
      "rotation": 3
    },
    {
      "x": 5,
      "y": 6,
      "z": -2,
      "name": "Rock_Sandstone_Cobble",
      "rotation": 3
    },
    {
      "x": 5,
      "y": 17,
      "z": -2,
      "name": "Wood_Drywood_Planks",
      "rotation": 3
    },
    {
      "x": 5,
      "y": 18,
      "z": -2,
      "name": "Rock_Sandstone_Brick_Smooth_Half",
      "rotation": 7
    },
    {
      "x": 5,
      "y": 19,
      "z": -2,
      "name": "Rock_Sandstone_Brick_Smooth_Half",
      "rotation": 7
    },
    {
      "x": 5,
      "y": 20,
      "z": -2,
      "name": "Rock_Sandstone_Brick_Smooth_Half",
      "rotation": 7
    },
    {
      "x": 5,
      "y": 21,
      "z": -2,
      "name": "Rock_Sandstone_Brick",
      "rotation": 3
    },
    {
      "x": 5,
      "y": 22,
      "z": -2,
      "name": "Rock_Sandstone_Brick",
      "rotation": 3
    },
    {
      "x": 5,
      "y": 23,
      "z": -2,
      "name": "Wood_Drywood_Planks",
      "rotation": 3
    },
    {
      "x": 5,
      "y": 25,
      "z": -2,
      "name": "*Wood_Torch_Wall_State_Definitions_Off",
      "rotation": 2
    },
    {
      "x": 5,
      "y": 1,
      "z": -1,
      "name": "Rock_Sandstone_Cobble",
      "rotation": 3
    },
    {
      "x": 5,
      "y": 2,
      "z": -1,
      "name": "Furniture_Desert_Table",
      "filler": 63,
      "rotation": 3
    },
    {
      "x": 5,
      "y": 6,
      "z": -1,
      "name": "Rock_Sandstone_Brick",
      "rotation": 3
    },
    {
      "x": 5,
      "y": 7,
      "z": -1,
      "name": "Rock_Sandstone_Cobble",
      "rotation": 3
    },
    {
      "x": 5,
      "y": 8,
      "z": -1,
      "name": "Rock_Sandstone_Cobble",
      "rotation": 3
    },
    {
      "x": 5,
      "y": 9,
      "z": -1,
      "name": "Rock_Sandstone_Cobble",
      "rotation": 3
    },
    {
      "x": 5,
      "y": 10,
      "z": -1,
      "name": "Rock_Sandstone_Brick",
      "rotation": 3
    },
    {
      "x": 5,
      "y": 11,
      "z": -1,
      "name": "Rock_Sandstone_Brick",
      "rotation": 3
    },
    {
      "x": 5,
      "y": 12,
      "z": -1,
      "name": "Rock_Sandstone_Brick",
      "rotation": 3
    },
    {
      "x": 5,
      "y": 13,
      "z": -1,
      "name": "Rock_Sandstone_Brick",
      "rotation": 3
    },
    {
      "x": 5,
      "y": 14,
      "z": -1,
      "name": "Rock_Sandstone_Brick",
      "rotation": 3
    },
    {
      "x": 5,
      "y": 15,
      "z": -1,
      "name": "Rock_Sandstone_Brick",
      "rotation": 3
    },
    {
      "x": 5,
      "y": 16,
      "z": -1,
      "name": "Rock_Sandstone_Brick",
      "rotation": 3
    },
    {
      "x": 5,
      "y": 17,
      "z": -1,
      "name": "Rock_Sandstone_Brick_Ornate",
      "rotation": 3
    },
    {
      "x": 5,
      "y": 18,
      "z": -1,
      "name": "Rock_Sandstone_Brick_Pillar_Base",
      "rotation": 3
    },
    {
      "x": 5,
      "y": 19,
      "z": -1,
      "name": "Rock_Sandstone_Brick_Pillar_Middle",
      "rotation": 3
    },
    {
      "x": 5,
      "y": 20,
      "z": -1,
      "name": "Rock_Sandstone_Brick_Pillar_Base",
      "rotation": 33
    },
    {
      "x": 5,
      "y": 21,
      "z": -1,
      "name": "Rock_Sandstone_Brick_Ornate",
      "rotation": 3
    },
    {
      "x": 5,
      "y": 22,
      "z": -1,
      "name": "Rock_Sandstone_Brick",
      "rotation": 3
    },
    {
      "x": 5,
      "y": 23,
      "z": -1,
      "name": "Rock_Sandstone_Brick_Stairs"
    },
    {
      "x": 5,
      "y": 24,
      "z": -1,
      "name": "Rock_Sandstone_Brick_Stairs",
      "rotation": 32
    },
    {
      "x": 5,
      "y": 25,
      "z": -1,
      "name": "Rock_Sandstone_White_Brick",
      "rotation": 3
    },
    {
      "x": 5,
      "y": 26,
      "z": -1,
      "name": "Rock_Sandstone_White_Brick_Half",
      "rotation": 3
    },
    {
      "x": 5,
      "y": 1,
      "z": 0,
      "name": "Rock_Sandstone_Cobble",
      "rotation": 3
    },
    {
      "x": 5,
      "y": 2,
      "z": 0,
      "name": "Rock_Sandstone_Cobble",
      "rotation": 3
    },
    {
      "x": 5,
      "y": 3,
      "z": 0,
      "name": "Rock_Sandstone_Brick",
      "rotation": 3
    },
    {
      "x": 5,
      "y": 4,
      "z": 0,
      "name": "Rock_Sandstone_Brick",
      "rotation": 3
    },
    {
      "x": 5,
      "y": 5,
      "z": 0,
      "name": "Rock_Sandstone_Brick",
      "rotation": 3
    },
    {
      "x": 5,
      "y": 6,
      "z": 0,
      "name": "Rock_Sandstone_Brick_Pillar_Base",
      "rotation": 3
    },
    {
      "x": 5,
      "y": 7,
      "z": 0,
      "name": "Rock_Sandstone_Brick",
      "rotation": 3
    },
    {
      "x": 5,
      "y": 8,
      "z": 0,
      "name": "Rock_Sandstone_Cobble_Stairs"
    },
    {
      "x": 5,
      "y": 9,
      "z": 0,
      "name": "Rock_Sandstone_Cobble_Half",
      "rotation": 4
    },
    {
      "x": 5,
      "y": 12,
      "z": 0,
      "name": "Rock_Sandstone_Brick_Smooth_Half",
      "rotation": 5
    },
    {
      "x": 5,
      "y": 13,
      "z": 0,
      "name": "Rock_Sandstone_Brick_Smooth_Half",
      "rotation": 5
    },
    {
      "x": 5,
      "y": 22,
      "z": 0,
      "name": "Rock_Sandstone_Brick_Smooth_Half",
      "rotation": 4
    },
    {
      "x": 6,
      "y": 1,
      "z": -8,
      "name": "Rock_Sandstone_Cobble",
      "rotation": 3
    },
    {
      "x": 6,
      "y": 2,
      "z": -8,
      "name": "Rock_Sandstone_Cobble",
      "rotation": 3
    },
    {
      "x": 6,
      "y": 3,
      "z": -8,
      "name": "Rock_Sandstone_Brick",
      "rotation": 3
    },
    {
      "x": 6,
      "y": 4,
      "z": -8,
      "name": "Rock_Sandstone_Brick",
      "rotation": 3
    },
    {
      "x": 6,
      "y": 5,
      "z": -8,
      "name": "Rock_Sandstone_Brick_Half",
      "rotation": 7
    },
    {
      "x": 6,
      "y": 1,
      "z": -7,
      "name": "Rock_Sandstone_Cobble",
      "rotation": 3
    },
    {
      "x": 6,
      "y": 2,
      "z": -7,
      "name": "Rubble_Sandstone",
      "support": 15
    },
    {
      "x": 6,
      "y": 6,
      "z": -7,
      "name": "Rock_Sandstone_Brick",
      "rotation": 3
    },
    {
      "x": 6,
      "y": 7,
      "z": -7,
      "name": "Rock_Sandstone_Brick",
      "rotation": 3
    },
    {
      "x": 6,
      "y": 8,
      "z": -7,
      "name": "Rock_Sandstone_Brick_Pillar_Base",
      "rotation": 3
    },
    {
      "x": 6,
      "y": 9,
      "z": -7,
      "name": "Rock_Sandstone_Brick_Pillar_Middle",
      "rotation": 3
    },
    {
      "x": 6,
      "y": 10,
      "z": -7,
      "name": "Rock_Sandstone_Brick_Pillar_Base",
      "rotation": 33
    },
    {
      "x": 6,
      "y": 11,
      "z": -7,
      "name": "Rock_Sandstone_Brick_Pillar_Middle",
      "rotation": 3
    },
    {
      "x": 6,
      "y": 12,
      "z": -7,
      "name": "Rock_Sandstone_Brick_Pillar_Middle",
      "rotation": 3
    },
    {
      "x": 6,
      "y": 1,
      "z": -6,
      "name": "Rock_Sandstone_Cobble",
      "rotation": 3
    },
    {
      "x": 6,
      "y": 6,
      "z": -6,
      "name": "Rock_Sandstone_Cobble",
      "rotation": 3
    },
    {
      "x": 6,
      "y": 7,
      "z": -6,
      "name": "Rock_Sandstone_Brick",
      "rotation": 3
    },
    {
      "x": 6,
      "y": 8,
      "z": -6,
      "name": "Rock_Sandstone_Cobble",
      "rotation": 3
    },
    {
      "x": 6,
      "y": 9,
      "z": -6,
      "name": "Rock_Sandstone_Cobble",
      "rotation": 3
    },
    {
      "x": 6,
      "y": 10,
      "z": -6,
      "name": "Rock_Sandstone_Brick",
      "rotation": 3
    },
    {
      "x": 6,
      "y": 11,
      "z": -6,
      "name": "Rock_Sandstone_Brick",
      "rotation": 3
    },
    {
      "x": 6,
      "y": 12,
      "z": -6,
      "name": "Rock_Sandstone_Brick",
      "rotation": 3
    },
    {
      "x": 6,
      "y": 13,
      "z": -6,
      "name": "Rock_Sandstone_Brick",
      "rotation": 3
    },
    {
      "x": 6,
      "y": 1,
      "z": -5,
      "name": "Rock_Sandstone_Cobble",
      "rotation": 3
    },
    {
      "x": 6,
      "y": 6,
      "z": -5,
      "name": "Rock_Sandstone_Cobble",
      "rotation": 3
    },
    {
      "x": 6,
      "y": 7,
      "z": -5,
      "name": "Rock_Sandstone_Cobble",
      "rotation": 3
    },
    {
      "x": 6,
      "y": 8,
      "z": -5,
      "name": "Rock_Sandstone_Cobble_Half",
      "rotation": 3
    },
    {
      "x": 6,
      "y": 1,
      "z": -4,
      "name": "Rock_Sandstone_Cobble",
      "rotation": 3
    },
    {
      "x": 6,
      "y": 6,
      "z": -4,
      "name": "Rock_Sandstone_Cobble",
      "rotation": 3
    },
    {
      "x": 6,
      "y": 7,
      "z": -4,
      "name": "Rock_Sandstone_Cobble",
      "rotation": 3
    },
    {
      "x": 6,
      "y": 23,
      "z": -4,
      "name": "Wood_Drywood_Beam",
      "rotation": 7
    },
    {
      "x": 6,
      "y": 1,
      "z": -3,
      "name": "Rock_Sandstone_Cobble",
      "rotation": 3
    },
    {
      "x": 6,
      "y": 6,
      "z": -3,
      "name": "Rock_Sandstone_Cobble",
      "rotation": 3
    },
    {
      "x": 6,
      "y": 7,
      "z": -3,
      "name": "Rock_Sandstone_Cobble_Half",
      "rotation": 3
    },
    {
      "x": 6,
      "y": 17,
      "z": -3,
      "name": "Wood_Drywood_Planks",
      "rotation": 3
    },
    {
      "x": 6,
      "y": 18,
      "z": -3,
      "name": "Rock_Sandstone_Brick_Smooth_Half",
      "rotation": 6
    },
    {
      "x": 6,
      "y": 19,
      "z": -3,
      "name": "Rock_Sandstone_Brick_Smooth_Half",
      "rotation": 6
    },
    {
      "x": 6,
      "y": 20,
      "z": -3,
      "name": "Rock_Sandstone_Brick_Smooth_Half",
      "rotation": 6
    },
    {
      "x": 6,
      "y": 21,
      "z": -3,
      "name": "Rock_Sandstone_Brick",
      "rotation": 3
    },
    {
      "x": 6,
      "y": 22,
      "z": -3,
      "name": "Rock_Sandstone_Brick",
      "rotation": 3
    },
    {
      "x": 6,
      "y": 23,
      "z": -3,
      "name": "Wood_Drywood_Planks",
      "rotation": 3
    },
    {
      "x": 6,
      "y": 24,
      "z": -3,
      "name": "Deco_Pot_Clay_Broken"
    },
    {
      "x": 6,
      "y": 1,
      "z": -2,
      "name": "Rock_Sandstone_Cobble",
      "rotation": 3
    },
    {
      "x": 6,
      "y": 2,
      "z": -2,
      "name": "Furniture_Desert_Table",
      "rotation": 3
    },
    {
      "x": 6,
      "y": 6,
      "z": -2,
      "name": "Rock_Sandstone_Cobble",
      "rotation": 3
    },
    {
      "x": 6,
      "y": 7,
      "z": -2,
      "name": "Rock_Sandstone_Brick",
      "rotation": 3
    },
    {
      "x": 6,
      "y": 8,
      "z": -2,
      "name": "Rock_Sandstone_Cobble",
      "rotation": 3
    },
    {
      "x": 6,
      "y": 9,
      "z": -2,
      "name": "Rock_Sandstone_Cobble",
      "rotation": 3
    },
    {
      "x": 6,
      "y": 10,
      "z": -2,
      "name": "Rock_Sandstone_Brick",
      "rotation": 3
    },
    {
      "x": 6,
      "y": 11,
      "z": -2,
      "name": "Rock_Sandstone_Brick",
      "rotation": 3
    },
    {
      "x": 6,
      "y": 12,
      "z": -2,
      "name": "Rock_Sandstone_Brick",
      "rotation": 3
    },
    {
      "x": 6,
      "y": 13,
      "z": -2,
      "name": "Rock_Sandstone_Brick",
      "rotation": 3
    },
    {
      "x": 6,
      "y": 14,
      "z": -2,
      "name": "Rock_Sandstone_Brick",
      "rotation": 3
    },
    {
      "x": 6,
      "y": 15,
      "z": -2,
      "name": "Rock_Sandstone_Brick",
      "rotation": 3
    },
    {
      "x": 6,
      "y": 16,
      "z": -2,
      "name": "Rock_Sandstone_Brick",
      "rotation": 3
    },
    {
      "x": 6,
      "y": 17,
      "z": -2,
      "name": "Rock_Sandstone_Brick_Ornate",
      "rotation": 3
    },
    {
      "x": 6,
      "y": 18,
      "z": -2,
      "name": "Rock_Sandstone_Brick",
      "rotation": 3
    },
    {
      "x": 6,
      "y": 19,
      "z": -2,
      "name": "Rock_Sandstone_Brick",
      "rotation": 3
    },
    {
      "x": 6,
      "y": 20,
      "z": -2,
      "name": "Rock_Sandstone_Brick",
      "rotation": 3
    },
    {
      "x": 6,
      "y": 21,
      "z": -2,
      "name": "Rock_Sandstone_Brick_Ornate",
      "rotation": 3
    },
    {
      "x": 6,
      "y": 22,
      "z": -2,
      "name": "Rock_Sandstone_Brick",
      "rotation": 3
    },
    {
      "x": 6,
      "y": 23,
      "z": -2,
      "name": "Rock_Sandstone_Brick_Smooth",
      "rotation": 3
    },
    {
      "x": 6,
      "y": 24,
      "z": -2,
      "name": "Rock_Sandstone_Brick_Smooth",
      "rotation": 3
    },
    {
      "x": 6,
      "y": 25,
      "z": -2,
      "name": "Rock_Sandstone_White_Brick_Half",
      "rotation": 3
    },
    {
      "x": 6,
      "y": 1,
      "z": -1,
      "name": "Rock_Sandstone_Cobble",
      "rotation": 3
    },
    {
      "x": 6,
      "y": 2,
      "z": -1,
      "name": "Furniture_Desert_Table",
      "filler": 32,
      "rotation": 3
    },
    {
      "x": 6,
      "y": 6,
      "z": -1,
      "name": "Rock_Sandstone_Brick",
      "rotation": 3
    },
    {
      "x": 6,
      "y": 7,
      "z": -1,
      "name": "Rock_Sandstone_Brick",
      "rotation": 3
    },
    {
      "x": 6,
      "y": 8,
      "z": -1,
      "name": "Rock_Sandstone_Brick_Pillar_Base",
      "rotation": 3
    },
    {
      "x": 6,
      "y": 9,
      "z": -1,
      "name": "Rock_Sandstone_Brick_Pillar_Middle",
      "rotation": 3
    },
    {
      "x": 6,
      "y": 10,
      "z": -1,
      "name": "Rock_Sandstone_Brick_Pillar_Base",
      "rotation": 33
    },
    {
      "x": 6,
      "y": 11,
      "z": -1,
      "name": "Rock_Sandstone_Brick_Pillar_Middle",
      "rotation": 3
    },
    {
      "x": 6,
      "y": 12,
      "z": -1,
      "name": "Rock_Sandstone_Brick_Pillar_Middle",
      "rotation": 3
    },
    {
      "x": 6,
      "y": 13,
      "z": -1,
      "name": "Rock_Sandstone_Brick_Pillar_Middle",
      "rotation": 3
    },
    {
      "x": 6,
      "y": 14,
      "z": -1,
      "name": "Rock_Sandstone_Brick_Pillar_Middle",
      "rotation": 3
    },
    {
      "x": 6,
      "y": 15,
      "z": -1,
      "name": "Rock_Sandstone_Brick_Pillar_Base",
      "rotation": 33
    },
    {
      "x": 6,
      "y": 16,
      "z": -1,
      "name": "Rock_Sandstone_Brick_Stairs"
    },
    {
      "x": 6,
      "y": 17,
      "z": -1,
      "name": "Rock_Sandstone_Brick_Ornate",
      "rotation": 3
    },
    {
      "x": 6,
      "y": 18,
      "z": -1,
      "name": "Rock_Sandstone_Brick_Wall"
    },
    {
      "x": 6,
      "y": 22,
      "z": -1,
      "name": "Rock_Sandstone_Brick_Smooth",
      "rotation": 3
    },
    {
      "x": 6,
      "y": 1,
      "z": 0,
      "name": "Rock_Sandstone_Cobble",
      "rotation": 3
    },
    {
      "x": 6,
      "y": 2,
      "z": 0,
      "name": "Rock_Sandstone_Cobble",
      "rotation": 3
    },
    {
      "x": 6,
      "y": 3,
      "z": 0,
      "name": "Rock_Sandstone_Brick",
      "rotation": 3
    },
    {
      "x": 6,
      "y": 4,
      "z": 0,
      "name": "Rock_Sandstone_Brick",
      "rotation": 3
    },
    {
      "x": 6,
      "y": 5,
      "z": 0,
      "name": "Rock_Sandstone_Brick",
      "rotation": 3
    },
    {
      "x": 6,
      "y": 6,
      "z": 0,
      "name": "Rock_Sandstone_Brick_Pillar_Base",
      "rotation": 3
    },
    {
      "x": 6,
      "y": 7,
      "z": 0,
      "name": "Rock_Sandstone_Brick",
      "rotation": 3
    },
    {
      "x": 7,
      "y": 1,
      "z": -8,
      "name": "Rock_Sandstone_Cobble",
      "rotation": 3
    },
    {
      "x": 7,
      "y": 2,
      "z": -8,
      "name": "Rock_Sandstone_Cobble",
      "rotation": 3
    },
    {
      "x": 7,
      "y": 3,
      "z": -8,
      "name": "Rock_Sandstone_Cobble",
      "rotation": 3
    },
    {
      "x": 7,
      "y": 4,
      "z": -8,
      "name": "Rock_Sandstone_Brick",
      "rotation": 3
    },
    {
      "x": 7,
      "y": 5,
      "z": -8,
      "name": "Rock_Sandstone_Brick",
      "rotation": 3
    },
    {
      "x": 7,
      "y": 6,
      "z": -8,
      "name": "Rock_Sandstone_Brick_Pillar_Base",
      "rotation": 3
    },
    {
      "x": 7,
      "y": 7,
      "z": -8,
      "name": "Rock_Sandstone_Brick_Half",
      "rotation": 3
    },
    {
      "x": 7,
      "y": 1,
      "z": -7,
      "name": "Rock_Sandstone_Cobble",
      "rotation": 3
    },
    {
      "x": 7,
      "y": 2,
      "z": -7,
      "name": "Rubble_Sandstone_Medium",
      "support": 15
    },
    {
      "x": 7,
      "y": 6,
      "z": -7,
      "name": "Rock_Sandstone_Brick",
      "rotation": 3
    },
    {
      "x": 7,
      "y": 7,
      "z": -7,
      "name": "Rock_Sandstone_Brick",
      "rotation": 3
    },
    {
      "x": 7,
      "y": 8,
      "z": -7,
      "name": "Rubble_Sandstone",
      "support": 15
    },
    {
      "x": 7,
      "y": 1,
      "z": -6,
      "name": "Rock_Sandstone_Cobble",
      "rotation": 3
    },
    {
      "x": 7,
      "y": 2,
      "z": -6,
      "name": "Rubble_Sandstone",
      "support": 15
    },
    {
      "x": 7,
      "y": 6,
      "z": -6,
      "name": "Rock_Sandstone_Brick",
      "rotation": 3
    },
    {
      "x": 7,
      "y": 7,
      "z": -6,
      "name": "Rock_Sandstone_Brick",
      "rotation": 3
    },
    {
      "x": 7,
      "y": 8,
      "z": -6,
      "name": "Rock_Sandstone_Brick_Pillar_Base",
      "rotation": 3
    },
    {
      "x": 7,
      "y": 9,
      "z": -6,
      "name": "Rock_Sandstone_Brick_Pillar_Middle",
      "rotation": 3
    },
    {
      "x": 7,
      "y": 10,
      "z": -6,
      "name": "Rock_Sandstone_Brick_Pillar_Base",
      "rotation": 33
    },
    {
      "x": 7,
      "y": 11,
      "z": -6,
      "name": "Rock_Sandstone_Brick_Pillar_Middle",
      "rotation": 3
    },
    {
      "x": 7,
      "y": 12,
      "z": -6,
      "name": "Rock_Sandstone_Brick_Pillar_Middle",
      "rotation": 3
    },
    {
      "x": 7,
      "y": 13,
      "z": -6,
      "name": "Rock_Sandstone_Brick_Pillar_Middle",
      "rotation": 3
    },
    {
      "x": 7,
      "y": 14,
      "z": -6,
      "name": "Rock_Sandstone_Brick_Pillar_Middle",
      "rotation": 3
    },
    {
      "x": 7,
      "y": 1,
      "z": -5,
      "name": "Rock_Sandstone_Cobble",
      "rotation": 3
    },
    {
      "x": 7,
      "y": 6,
      "z": -5,
      "name": "Rock_Sandstone_Brick",
      "rotation": 3
    },
    {
      "x": 7,
      "y": 7,
      "z": -5,
      "name": "Rock_Sandstone_Brick",
      "rotation": 3
    },
    {
      "x": 7,
      "y": 8,
      "z": -5,
      "name": "Rock_Sandstone_Cobble",
      "rotation": 3
    },
    {
      "x": 7,
      "y": 9,
      "z": -5,
      "name": "Rock_Sandstone_Cobble",
      "rotation": 3
    },
    {
      "x": 7,
      "y": 10,
      "z": -5,
      "name": "Rock_Sandstone_Brick",
      "rotation": 3
    },
    {
      "x": 7,
      "y": 11,
      "z": -5,
      "name": "Rock_Sandstone_Brick",
      "rotation": 3
    },
    {
      "x": 7,
      "y": 12,
      "z": -5,
      "name": "Rock_Sandstone_Brick",
      "rotation": 3
    },
    {
      "x": 7,
      "y": 13,
      "z": -5,
      "name": "Rock_Sandstone_Brick",
      "rotation": 3
    },
    {
      "x": 7,
      "y": 14,
      "z": -5,
      "name": "Rock_Sandstone_Brick",
      "rotation": 3
    },
    {
      "x": 7,
      "y": 15,
      "z": -5,
      "name": "Rock_Sandstone_Brick",
      "rotation": 3
    },
    {
      "x": 7,
      "y": 1,
      "z": -4,
      "name": "Rock_Sandstone_Cobble",
      "rotation": 3
    },
    {
      "x": 7,
      "y": 6,
      "z": -4,
      "name": "Rock_Sandstone_Brick",
      "rotation": 3
    },
    {
      "x": 7,
      "y": 7,
      "z": -4,
      "name": "Rock_Sandstone_Cobble",
      "rotation": 3
    },
    {
      "x": 7,
      "y": 8,
      "z": -4,
      "name": "Rock_Sandstone_Cobble",
      "rotation": 3
    },
    {
      "x": 7,
      "y": 9,
      "z": -4,
      "name": "Rock_Sandstone_Cobble",
      "rotation": 3
    },
    {
      "x": 7,
      "y": 10,
      "z": -4,
      "name": "Rock_Sandstone_Brick",
      "rotation": 3
    },
    {
      "x": 7,
      "y": 11,
      "z": -4,
      "name": "Rock_Sandstone_Brick",
      "rotation": 3
    },
    {
      "x": 7,
      "y": 13,
      "z": -4,
      "name": "Furniture_Desert_Window",
      "rotation": 3
    },
    {
      "x": 7,
      "y": 14,
      "z": -4,
      "name": "Rock_Sandstone_Brick",
      "rotation": 3
    },
    {
      "x": 7,
      "y": 15,
      "z": -4,
      "name": "Rock_Sandstone_Brick",
      "rotation": 3
    },
    {
      "x": 7,
      "y": 16,
      "z": -4,
      "name": "Rock_Sandstone_Brick",
      "rotation": 3
    },
    {
      "x": 7,
      "y": 17,
      "z": -4,
      "name": "Rock_Sandstone_Brick_Ornate",
      "rotation": 3
    },
    {
      "x": 7,
      "y": 18,
      "z": -4,
      "name": "Rock_Sandstone_Brick_Wall",
      "rotation": 3
    },
    {
      "x": 7,
      "y": 1,
      "z": -3,
      "name": "Rock_Sandstone_Cobble",
      "rotation": 3
    },
    {
      "x": 7,
      "y": 6,
      "z": -3,
      "name": "Rock_Sandstone_Brick",
      "rotation": 3
    },
    {
      "x": 7,
      "y": 7,
      "z": -3,
      "name": "Rock_Sandstone_Brick",
      "rotation": 3
    },
    {
      "x": 7,
      "y": 8,
      "z": -3,
      "name": "Rock_Sandstone_Cobble",
      "rotation": 3
    },
    {
      "x": 7,
      "y": 9,
      "z": -3,
      "name": "Rock_Sandstone_Cobble",
      "rotation": 3
    },
    {
      "x": 7,
      "y": 10,
      "z": -3,
      "name": "Rock_Sandstone_Brick",
      "rotation": 3
    },
    {
      "x": 7,
      "y": 11,
      "z": -3,
      "name": "Rock_Sandstone_Brick",
      "rotation": 3
    },
    {
      "x": 7,
      "y": 12,
      "z": -3,
      "name": "Rock_Sandstone_Brick",
      "rotation": 3
    },
    {
      "x": 7,
      "y": 13,
      "z": -3,
      "name": "Rock_Sandstone_Brick",
      "rotation": 3
    },
    {
      "x": 7,
      "y": 14,
      "z": -3,
      "name": "Rock_Sandstone_Brick",
      "rotation": 3
    },
    {
      "x": 7,
      "y": 15,
      "z": -3,
      "name": "Rock_Sandstone_Brick",
      "rotation": 3
    },
    {
      "x": 7,
      "y": 16,
      "z": -3,
      "name": "Rock_Sandstone_Brick",
      "rotation": 3
    },
    {
      "x": 7,
      "y": 17,
      "z": -3,
      "name": "Rock_Sandstone_Brick_Ornate",
      "rotation": 3
    },
    {
      "x": 7,
      "y": 18,
      "z": -3,
      "name": "Rock_Sandstone_Brick_Pillar_Base",
      "rotation": 3
    },
    {
      "x": 7,
      "y": 19,
      "z": -3,
      "name": "Rock_Sandstone_Brick_Pillar_Middle",
      "rotation": 3
    },
    {
      "x": 7,
      "y": 20,
      "z": -3,
      "name": "Rock_Sandstone_Brick_Pillar_Base",
      "rotation": 33
    },
    {
      "x": 7,
      "y": 21,
      "z": -3,
      "name": "Rock_Sandstone_Brick_Ornate",
      "rotation": 3
    },
    {
      "x": 7,
      "y": 22,
      "z": -3,
      "name": "Rock_Sandstone_Brick",
      "rotation": 3
    },
    {
      "x": 7,
      "y": 23,
      "z": -3,
      "name": "Rock_Sandstone_Brick_Half",
      "rotation": 3
    },
    {
      "x": 7,
      "y": 1,
      "z": -2,
      "name": "Rock_Sandstone_Cobble",
      "rotation": 3
    },
    {
      "x": 7,
      "y": 6,
      "z": -2,
      "name": "Rock_Sandstone_Brick",
      "rotation": 3
    },
    {
      "x": 7,
      "y": 7,
      "z": -2,
      "name": "Rock_Sandstone_Brick",
      "rotation": 3
    },
    {
      "x": 7,
      "y": 8,
      "z": -2,
      "name": "Rock_Sandstone_Brick_Pillar_Base",
      "rotation": 3
    },
    {
      "x": 7,
      "y": 9,
      "z": -2,
      "name": "Rock_Sandstone_Brick_Pillar_Middle",
      "rotation": 3
    },
    {
      "x": 7,
      "y": 10,
      "z": -2,
      "name": "Rock_Sandstone_Brick_Pillar_Base",
      "rotation": 33
    },
    {
      "x": 7,
      "y": 11,
      "z": -2,
      "name": "Rock_Sandstone_Brick_Pillar_Middle",
      "rotation": 3
    },
    {
      "x": 7,
      "y": 12,
      "z": -2,
      "name": "Rock_Sandstone_Brick_Pillar_Middle",
      "rotation": 3
    },
    {
      "x": 7,
      "y": 13,
      "z": -2,
      "name": "Rock_Sandstone_Brick_Pillar_Middle",
      "rotation": 3
    },
    {
      "x": 7,
      "y": 14,
      "z": -2,
      "name": "Rock_Sandstone_Brick_Pillar_Middle",
      "rotation": 3
    },
    {
      "x": 7,
      "y": 15,
      "z": -2,
      "name": "Rock_Sandstone_Brick_Pillar_Base",
      "rotation": 33
    },
    {
      "x": 7,
      "y": 16,
      "z": -2,
      "name": "Rock_Sandstone_Brick_Stairs",
      "rotation": 1
    },
    {
      "x": 7,
      "y": 17,
      "z": -2,
      "name": "Rock_Sandstone_Brick_Ornate",
      "rotation": 3
    },
    {
      "x": 7,
      "y": 18,
      "z": -2,
      "name": "Rock_Sandstone_Brick_Wall",
      "rotation": 3
    },
    {
      "x": 7,
      "y": 22,
      "z": -2,
      "name": "Rock_Sandstone_Brick_Smooth",
      "rotation": 3
    },
    {
      "x": 7,
      "y": 23,
      "z": -2,
      "name": "Rubble_Sandstone_Medium",
      "support": 15
    },
    {
      "x": 7,
      "y": 1,
      "z": -1,
      "name": "Rock_Sandstone_Cobble",
      "rotation": 3
    },
    {
      "x": 7,
      "y": 6,
      "z": -1,
      "name": "Rock_Sandstone_Brick",
      "rotation": 3
    },
    {
      "x": 7,
      "y": 7,
      "z": -1,
      "name": "Rock_Sandstone_Brick",
      "rotation": 3
    },
    {
      "x": 7,
      "y": 1,
      "z": 0,
      "name": "Rock_Sandstone_Cobble",
      "rotation": 3
    },
    {
      "x": 7,
      "y": 2,
      "z": 0,
      "name": "Rock_Sandstone_Cobble",
      "rotation": 3
    },
    {
      "x": 7,
      "y": 3,
      "z": 0,
      "name": "Rock_Sandstone_Brick",
      "rotation": 3
    },
    {
      "x": 7,
      "y": 4,
      "z": 0,
      "name": "Rock_Sandstone_Brick",
      "rotation": 3
    },
    {
      "x": 7,
      "y": 5,
      "z": 0,
      "name": "Rock_Sandstone_Brick",
      "rotation": 3
    },
    {
      "x": 7,
      "y": 6,
      "z": 0,
      "name": "Rock_Sandstone_Brick_Pillar_Base",
      "rotation": 3
    },
    {
      "x": 7,
      "y": 7,
      "z": 0,
      "name": "Rock_Sandstone_Brick_Half",
      "rotation": 3
    },
    {
      "x": 8,
      "y": 1,
      "z": -7,
      "name": "Rock_Sandstone_Cobble",
      "rotation": 3
    },
    {
      "x": 8,
      "y": 2,
      "z": -7,
      "name": "Rock_Sandstone_Cobble",
      "rotation": 3
    },
    {
      "x": 8,
      "y": 3,
      "z": -7,
      "name": "Rock_Sandstone_Cobble",
      "rotation": 3
    },
    {
      "x": 8,
      "y": 4,
      "z": -7,
      "name": "Rock_Sandstone_Cobble",
      "rotation": 3
    },
    {
      "x": 8,
      "y": 5,
      "z": -7,
      "name": "Rock_Sandstone_Brick",
      "rotation": 3
    },
    {
      "x": 8,
      "y": 6,
      "z": -7,
      "name": "Rock_Sandstone_Brick_Pillar_Base",
      "rotation": 3
    },
    {
      "x": 8,
      "y": 7,
      "z": -7,
      "name": "Rock_Sandstone_Brick_Half",
      "rotation": 3
    },
    {
      "x": 8,
      "y": 1,
      "z": -6,
      "name": "Rock_Sandstone_Cobble",
      "rotation": 3
    },
    {
      "x": 8,
      "y": 2,
      "z": -6,
      "name": "Rock_Sandstone_Cobble",
      "rotation": 3
    },
    {
      "x": 8,
      "y": 3,
      "z": -6,
      "name": "Rock_Sandstone_Cobble",
      "rotation": 3
    },
    {
      "x": 8,
      "y": 4,
      "z": -6,
      "name": "Rock_Sandstone_Brick",
      "rotation": 3
    },
    {
      "x": 8,
      "y": 5,
      "z": -6,
      "name": "Rock_Sandstone_Brick",
      "rotation": 3
    },
    {
      "x": 8,
      "y": 6,
      "z": -6,
      "name": "Rock_Sandstone_Brick_Pillar_Base",
      "rotation": 3
    },
    {
      "x": 8,
      "y": 7,
      "z": -6,
      "name": "Rock_Sandstone_Brick",
      "rotation": 3
    },
    {
      "x": 8,
      "y": 1,
      "z": -5,
      "name": "Rock_Sandstone_Cobble",
      "rotation": 3
    },
    {
      "x": 8,
      "y": 2,
      "z": -5,
      "name": "Wood_Drywood_Planks_Half",
      "rotation": 4
    },
    {
      "x": 8,
      "y": 3,
      "z": -5,
      "name": "Wood_Drywood_Planks_Half",
      "rotation": 4
    },
    {
      "x": 8,
      "y": 4,
      "z": -5,
      "name": "Wood_Drywood_Stairs",
      "rotation": 32
    },
    {
      "x": 8,
      "y": 5,
      "z": -5,
      "name": "Rock_Sandstone_Brick",
      "rotation": 3
    },
    {
      "x": 8,
      "y": 6,
      "z": -5,
      "name": "Rock_Sandstone_Brick_Pillar_Base",
      "rotation": 3
    },
    {
      "x": 8,
      "y": 7,
      "z": -5,
      "name": "Rock_Sandstone_Brick",
      "rotation": 3
    },
    {
      "x": 8,
      "y": 8,
      "z": -5,
      "name": "Rock_Sandstone_Cobble_Stairs",
      "rotation": 1
    },
    {
      "x": 8,
      "y": 9,
      "z": -5,
      "name": "Rock_Sandstone_Cobble_Half",
      "rotation": 5
    },
    {
      "x": 8,
      "y": 12,
      "z": -5,
      "name": "Rock_Sandstone_Brick_Smooth_Half",
      "rotation": 6
    },
    {
      "x": 8,
      "y": 13,
      "z": -5,
      "name": "Rock_Sandstone_Brick_Smooth_Half",
      "rotation": 6
    },
    {
      "x": 8,
      "y": 1,
      "z": -4,
      "name": "Rock_Sandstone_Cobble",
      "rotation": 3
    },
    {
      "x": 8,
      "y": 4,
      "z": -4,
      "name": "Wood_Drywood_Planks_Half",
      "rotation": 33
    },
    {
      "x": 8,
      "y": 5,
      "z": -4,
      "name": "Rock_Sandstone_Brick",
      "rotation": 3
    },
    {
      "x": 8,
      "y": 6,
      "z": -4,
      "name": "Rock_Sandstone_Brick_Pillar_Base",
      "rotation": 3
    },
    {
      "x": 8,
      "y": 7,
      "z": -4,
      "name": "Rock_Sandstone_Brick",
      "rotation": 3
    },
    {
      "x": 8,
      "y": 8,
      "z": -4,
      "name": "Rock_Sandstone_Cobble_Stairs",
      "rotation": 1
    },
    {
      "x": 8,
      "y": 9,
      "z": -4,
      "name": "Rock_Sandstone_Cobble_Half",
      "rotation": 5
    },
    {
      "x": 8,
      "y": 14,
      "z": -4,
      "name": "Rock_Sandstone_Brick_Smooth_Half",
      "rotation": 3
    },
    {
      "x": 8,
      "y": 1,
      "z": -3,
      "name": "Rock_Sandstone_Cobble",
      "rotation": 3
    },
    {
      "x": 8,
      "y": 2,
      "z": -3,
      "name": "Wood_Drywood_Planks_Half",
      "rotation": 6
    },
    {
      "x": 8,
      "y": 3,
      "z": -3,
      "name": "Wood_Drywood_Planks_Half",
      "rotation": 6
    },
    {
      "x": 8,
      "y": 4,
      "z": -3,
      "name": "Wood_Drywood_Stairs",
      "rotation": 34
    },
    {
      "x": 8,
      "y": 5,
      "z": -3,
      "name": "Rock_Sandstone_Brick",
      "rotation": 3
    },
    {
      "x": 8,
      "y": 6,
      "z": -3,
      "name": "Rock_Sandstone_Brick_Pillar_Base",
      "rotation": 3
    },
    {
      "x": 8,
      "y": 7,
      "z": -3,
      "name": "Rock_Sandstone_Brick",
      "rotation": 3
    },
    {
      "x": 8,
      "y": 8,
      "z": -3,
      "name": "Rock_Sandstone_Cobble_Stairs",
      "rotation": 1
    },
    {
      "x": 8,
      "y": 9,
      "z": -3,
      "name": "Rock_Sandstone_Cobble_Half",
      "rotation": 5
    },
    {
      "x": 8,
      "y": 12,
      "z": -3,
      "name": "Rock_Sandstone_Brick_Smooth_Half",
      "rotation": 4
    },
    {
      "x": 8,
      "y": 13,
      "z": -3,
      "name": "Rock_Sandstone_Brick_Smooth_Half",
      "rotation": 4
    },
    {
      "x": 8,
      "y": 1,
      "z": -2,
      "name": "Rock_Sandstone_Cobble",
      "rotation": 3
    },
    {
      "x": 8,
      "y": 2,
      "z": -2,
      "name": "Rock_Sandstone_Cobble",
      "rotation": 3
    },
    {
      "x": 8,
      "y": 3,
      "z": -2,
      "name": "Rock_Sandstone_Brick",
      "rotation": 3
    },
    {
      "x": 8,
      "y": 4,
      "z": -2,
      "name": "Rock_Sandstone_Brick",
      "rotation": 3
    },
    {
      "x": 8,
      "y": 5,
      "z": -2,
      "name": "Rock_Sandstone_Brick",
      "rotation": 3
    },
    {
      "x": 8,
      "y": 6,
      "z": -2,
      "name": "Rock_Sandstone_Brick_Pillar_Base",
      "rotation": 3
    },
    {
      "x": 8,
      "y": 7,
      "z": -2,
      "name": "Rock_Sandstone_Brick",
      "rotation": 3
    },
    {
      "x": 8,
      "y": 1,
      "z": -1,
      "name": "Rock_Sandstone_Cobble",
      "rotation": 3
    },
    {
      "x": 8,
      "y": 2,
      "z": -1,
      "name": "Rock_Sandstone_Cobble",
      "rotation": 3
    },
    {
      "x": 8,
      "y": 3,
      "z": -1,
      "name": "Rock_Sandstone_Cobble",
      "rotation": 3
    },
    {
      "x": 8,
      "y": 4,
      "z": -1,
      "name": "Rock_Sandstone_Brick",
      "rotation": 3
    },
    {
      "x": 8,
      "y": 5,
      "z": -1,
      "name": "Rock_Sandstone_Brick",
      "rotation": 3
    },
    {
      "x": 8,
      "y": 6,
      "z": -1,
      "name": "Rock_Sandstone_Brick_Pillar_Base",
      "rotation": 3
    },
    {
      "x": 8,
      "y": 7,
      "z": -1,
      "name": "Rock_Sandstone_Brick_Half",
      "rotation": 3
    },
    {
      "x": 9,
      "y": 1,
      "z": -5,
      "name": "Rock_Sandstone_Cobble_Stairs",
      "rotation": 1
    },
    {
      "x": 9,
      "y": 1,
      "z": -4,
      "name": "Rock_Sandstone_Cobble_Stairs",
      "rotation": 1
    },
    {
      "x": 9,
      "y": 1,
      "z": -3,
      "name": "Rock_Sandstone_Cobble_Stairs",
      "rotation": 1
    }
  ]
}