{
  "version": 8,
  "blockIdVersion": 11,
  "anchorX": 0,
  "anchorY": 8,
  "anchorZ": 0,
  "blocks": [
    {
      "x": -4,
      "y": 13,
      "z": 0,
      "name": "Rock_Marble",
      "rotation": 33
    },
    {
      "x": -4,
      "y": 14,
      "z": 0,
      "name": "Soil_Clay_White",
      "rotation": 33
    },
    {
      "x": -4,
      "y": 15,
      "z": 0,
      "name": "Rock_Chalk",
      "rotation": 33
    },
    {
      "x": -4,
      "y": 12,
      "z": 1,
      "name": "Soil_Clay_White",
      "rotation": 33
    },
    {
      "x": -4,
      "y": 13,
      "z": 1,
      "name": "Rock_Marble",
      "rotation": 33
    },
    {
      "x": -4,
      "y": 14,
      "z": 1,
      "name": "Soil_Clay_White",
      "rotation": 33
    },
    {
      "x": -4,
      "y": 15,
      "z": 1,
      "name": "Rock_Chalk",
      "rotation": 33
    },
    {
      "x": -4,
      "y": 12,
      "z": 2,
      "name": "Soil_Clay_White",
      "rotation": 33
    },
    {
      "x": -4,
      "y": 13,
      "z": 2,
      "name": "Rock_Marble",
      "rotation": 33
    },
    {
      "x": -4,
      "y": 14,
      "z": 2,
      "name": "Soil_Clay_White",
      "rotation": 33
    },
    {
      "x": -3,
      "y": 12,
      "z": -2,
      "name": "Soil_Clay_White",
      "rotation": 33
    },
    {
      "x": -3,
      "y": 13,
      "z": -2,
      "name": "Rock_Marble",
      "rotation": 33
    },
    {
      "x": -3,
      "y": 14,
      "z": -2,
      "name": "Soil_Clay_White",
      "rotation": 33
    },
    {
      "x": -3,
      "y": 15,
      "z": -2,
      "name": "Rock_Chalk",
      "rotation": 33
    },
    {
      "x": -3,
      "y": 16,
      "z": -2,
      "name": "Rock_Chalk",
      "rotation": 33
    },
    {
      "x": -3,
      "y": 10,
      "z": -1,
      "name": "Soil_Clay_GreyLight",
      "rotation": 33
    },
    {
      "x": -3,
      "y": 11,
      "z": -1,
      "name": "Rock_Marble",
      "rotation": 33
    },
    {
      "x": -3,
      "y": 12,
      "z": -1,
      "name": "Soil_Clay_White",
      "rotation": 33
    },
    {
      "x": -3,
      "y": 13,
      "z": -1,
      "name": "Rock_Marble",
      "rotation": 33
    },
    {
      "x": -3,
      "y": 14,
      "z": -1,
      "name": "Soil_Clay_White",
      "rotation": 33
    },
    {
      "x": -3,
      "y": 15,
      "z": -1,
      "name": "Rock_Chalk",
      "rotation": 33
    },
    {
      "x": -3,
      "y": 16,
      "z": -1,
      "name": "Rock_Chalk",
      "rotation": 33
    },
    {
      "x": -3,
      "y": 8,
      "z": 0,
      "name": "Soil_Clay_White",
      "rotation": 33
    },
    {
      "x": -3,
      "y": 9,
      "z": 0,
      "name": "Rock_Marble_Cobble",
      "rotation": 33
    },
    {
      "x": -3,
      "y": 10,
      "z": 0,
      "name": "Soil_Clay_GreyLight",
      "rotation": 33
    },
    {
      "x": -3,
      "y": 11,
      "z": 0,
      "name": "Rock_Marble",
      "rotation": 33
    },
    {
      "x": -3,
      "y": 12,
      "z": 0,
      "name": "Soil_Clay_White",
      "rotation": 33
    },
    {
      "x": -3,
      "y": 13,
      "z": 0,
      "name": "Rock_Marble",
      "rotation": 33
    },
    {
      "x": -3,
      "y": 14,
      "z": 0,
      "name": "Soil_Clay_White",
      "rotation": 33
    },
    {
      "x": -3,
      "y": 15,
      "z": 0,
      "name": "Rock_Chalk",
      "rotation": 33
    },
    {
      "x": -3,
      "y": 16,
      "z": 0,
      "name": "Rock_Chalk",
      "rotation": 33
    },
    {
      "x": -3,
      "y": 8,
      "z": 1,
      "name": "Soil_Clay_White",
      "rotation": 33
    },
    {
      "x": -3,
      "y": 9,
      "z": 1,
      "name": "Rock_Marble_Cobble",
      "rotation": 33
    },
    {
      "x": -3,
      "y": 10,
      "z": 1,
      "name": "Soil_Clay_GreyLight",
      "rotation": 33
    },
    {
      "x": -3,
      "y": 11,
      "z": 1,
      "name": "Rock_Marble",
      "rotation": 33
    },
    {
      "x": -3,
      "y": 12,
      "z": 1,
      "name": "Soil_Clay_White",
      "rotation": 33
    },
    {
      "x": -3,
      "y": 13,
      "z": 1,
      "name": "Rock_Marble",
      "rotation": 33
    },
    {
      "x": -3,
      "y": 14,
      "z": 1,
      "name": "Soil_Clay_White",
      "rotation": 33
    },
    {
      "x": -3,
      "y": 15,
      "z": 1,
      "name": "Rock_Chalk",
      "rotation": 33
    },
    {
      "x": -3,
      "y": 16,
      "z": 1,
      "name": "Rock_Chalk",
      "rotation": 33
    },
    {
      "x": -3,
      "y": 9,
      "z": 2,
      "name": "Rock_Marble_Cobble",
      "rotation": 33
    },
    {
      "x": -3,
      "y": 10,
      "z": 2,
      "name": "Soil_Clay_GreyLight",
      "rotation": 33
    },
    {
      "x": -3,
      "y": 11,
      "z": 2,
      "name": "Rock_Marble",
      "rotation": 33
    },
    {
      "x": -3,
      "y": 12,
      "z": 2,
      "name": "Soil_Clay_White",
      "rotation": 33
    },
    {
      "x": -3,
      "y": 13,
      "z": 2,
      "name": "Rock_Marble",
      "rotation": 33
    },
    {
      "x": -3,
      "y": 14,
      "z": 2,
      "name": "Soil_Clay_White",
      "rotation": 33
    },
    {
      "x": -3,
      "y": 15,
      "z": 2,
      "name": "Rock_Chalk",
      "rotation": 33
    },
    {
      "x": -3,
      "y": 10,
      "z": 3,
      "name": "Soil_Clay_GreyLight",
      "rotation": 33
    },
    {
      "x": -3,
      "y": 11,
      "z": 3,
      "name": "Rock_Marble",
      "rotation": 33
    },
    {
      "x": -3,
      "y": 12,
      "z": 3,
      "name": "Soil_Clay_White",
      "rotation": 33
    },
    {
      "x": -3,
      "y": 13,
      "z": 3,
      "name": "Rock_Marble",
      "rotation": 33
    },
    {
      "x": -3,
      "y": 14,
      "z": 3,
      "name": "Soil_Clay_White",
      "rotation": 33
    },
    {
      "x": -2,
      "y": 12,
      "z": -3,
      "name": "Soil_Clay_White",
      "rotation": 33
    },
    {
      "x": -2,
      "y": 13,
      "z": -3,
      "name": "Rock_Marble",
      "rotation": 33
    },
    {
      "x": -2,
      "y": 14,
      "z": -3,
      "name": "Soil_Clay_White",
      "rotation": 33
    },
    {
      "x": -2,
      "y": 15,
      "z": -3,
      "name": "Rock_Chalk",
      "rotation": 33
    },
    {
      "x": -2,
      "y": 16,
      "z": -3,
      "name": "Rock_Chalk",
      "rotation": 33
    },
    {
      "x": -2,
      "y": 8,
      "z": -2,
      "name": "Soil_Clay_White",
      "rotation": 33
    },
    {
      "x": -2,
      "y": 9,
      "z": -2,
      "name": "Rock_Marble_Cobble",
      "rotation": 33
    },
    {
      "x": -2,
      "y": 10,
      "z": -2,
      "name": "Soil_Clay_GreyLight",
      "rotation": 33
    },
    {
      "x": -2,
      "y": 11,
      "z": -2,
      "name": "Rock_Marble",
      "rotation": 33
    },
    {
      "x": -2,
      "y": 12,
      "z": -2,
      "name": "Soil_Clay_White",
      "rotation": 33
    },
    {
      "x": -2,
      "y": 13,
      "z": -2,
      "name": "Rock_Marble",
      "rotation": 33
    },
    {
      "x": -2,
      "y": 14,
      "z": -2,
      "name": "Soil_Clay_White",
      "rotation": 33
    },
    {
      "x": -2,
      "y": 15,
      "z": -2,
      "name": "Rock_Chalk",
      "rotation": 33
    },
    {
      "x": -2,
      "y": 16,
      "z": -2,
      "name": "Rock_Chalk",
      "rotation": 33
    },
    {
      "x": -2,
      "y": 17,
      "z": -2,
      "name": "Rock_Chalk",
      "rotation": 33
    },
    {
      "x": -2,
      "y": 7,
      "z": -1,
      "name": "Rock_Marble",
      "rotation": 33
    },
    {
      "x": -2,
      "y": 8,
      "z": -1,
      "name": "Soil_Clay_White",
      "rotation": 33
    },
    {
      "x": -2,
      "y": 9,
      "z": -1,
      "name": "Rock_Marble_Cobble",
      "rotation": 33
    },
    {
      "x": -2,
      "y": 10,
      "z": -1,
      "name": "Soil_Clay_GreyLight",
      "rotation": 33
    },
    {
      "x": -2,
      "y": 11,
      "z": -1,
      "name": "Rock_Marble",
      "rotation": 33
    },
    {
      "x": -2,
      "y": 12,
      "z": -1,
      "name": "Soil_Clay_White",
      "rotation": 33
    },
    {
      "x": -2,
      "y": 13,
      "z": -1,
      "name": "Rock_Marble",
      "rotation": 33
    },
    {
      "x": -2,
      "y": 14,
      "z": -1,
      "name": "Soil_Clay_White",
      "rotation": 33
    },
    {
      "x": -2,
      "y": 15,
      "z": -1,
      "name": "Rock_Chalk",
      "rotation": 33
    },
    {
      "x": -2,
      "y": 16,
      "z": -1,
      "name": "Rock_Chalk",
      "rotation": 33
    },
    {
      "x": -2,
      "y": 17,
      "z": -1,
      "name": "Rock_Chalk",
      "rotation": 33
    },
    {
      "x": -2,
      "y": 7,
      "z": 0,
      "name": "Rock_Marble",
      "rotation": 33
    },
    {
      "x": -2,
      "y": 8,
      "z": 0,
      "name": "Soil_Clay_White",
      "rotation": 33
    },
    {
      "x": -2,
      "y": 9,
      "z": 0,
      "name": "Rock_Marble_Cobble",
      "rotation": 33
    },
    {
      "x": -2,
      "y": 10,
      "z": 0,
      "name": "Soil_Clay_GreyLight",
      "rotation": 33
    },
    {
      "x": -2,
      "y": 11,
      "z": 0,
      "name": "Rock_Marble",
      "rotation": 33
    },
    {
      "x": -2,
      "y": 12,
      "z": 0,
      "name": "Soil_Clay_White",
      "rotation": 33
    },
    {
      "x": -2,
      "y": 13,
      "z": 0,
      "name": "Rock_Marble",
      "rotation": 33
    },
    {
      "x": -2,
      "y": 14,
      "z": 0,
      "name": "Soil_Clay_White",
      "rotation": 33
    },
    {
      "x": -2,
      "y": 15,
      "z": 0,
      "name": "Rock_Chalk",
      "rotation": 33
    },
    {
      "x": -2,
      "y": 16,
      "z": 0,
      "name": "Rock_Chalk",
      "rotation": 33
    },
    {
      "x": -2,
      "y": 17,
      "z": 0,
      "name": "Rock_Chalk",
      "rotation": 33
    },
    {
      "x": -2,
      "y": 7,
      "z": 1,
      "name": "Rock_Marble",
      "rotation": 33
    },
    {
      "x": -2,
      "y": 8,
      "z": 1,
      "name": "Soil_Clay_White",
      "rotation": 33
    },
    {
      "x": -2,
      "y": 9,
      "z": 1,
      "name": "Rock_Marble_Cobble",
      "rotation": 33
    },
    {
      "x": -2,
      "y": 10,
      "z": 1,
      "name": "Soil_Clay_GreyLight",
      "rotation": 33
    },
    {
      "x": -2,
      "y": 11,
      "z": 1,
      "name": "Rock_Marble",
      "rotation": 33
    },
    {
      "x": -2,
      "y": 12,
      "z": 1,
      "name": "Soil_Clay_White",
      "rotation": 33
    },
    {
      "x": -2,
      "y": 13,
      "z": 1,
      "name": "Rock_Marble",
      "rotation": 33
    },
    {
      "x": -2,
      "y": 14,
      "z": 1,
      "name": "Soil_Clay_White",
      "rotation": 33
    },
    {
      "x": -2,
      "y": 15,
      "z": 1,
      "name": "Rock_Chalk",
      "rotation": 33
    },
    {
      "x": -2,
      "y": 16,
      "z": 1,
      "name": "Rock_Chalk",
      "rotation": 33
    },
    {
      "x": -2,
      "y": 17,
      "z": 1,
      "name": "Rock_Chalk",
      "rotation": 33
    },
    {
      "x": -2,
      "y": 7,
      "z": 2,
      "name": "Rock_Marble",
      "rotation": 33
    },
    {
      "x": -2,
      "y": 8,
      "z": 2,
      "name": "Soil_Clay_White",
      "rotation": 33
    },
    {
      "x": -2,
      "y": 9,
      "z": 2,
      "name": "Rock_Marble_Cobble",
      "rotation": 33
    },
    {
      "x": -2,
      "y": 10,
      "z": 2,
      "name": "Soil_Clay_GreyLight",
      "rotation": 33
    },
    {
      "x": -2,
      "y": 11,
      "z": 2,
      "name": "Rock_Marble",
      "rotation": 33
    },
    {
      "x": -2,
      "y": 12,
      "z": 2,
      "name": "Soil_Clay_White",
      "rotation": 33
    },
    {
      "x": -2,
      "y": 13,
      "z": 2,
      "name": "Rock_Marble",
      "rotation": 33
    },
    {
      "x": -2,
      "y": 14,
      "z": 2,
      "name": "Soil_Clay_White",
      "rotation": 33
    },
    {
      "x": -2,
      "y": 15,
      "z": 2,
      "name": "Rock_Chalk",
      "rotation": 33
    },
    {
      "x": -2,
      "y": 16,
      "z": 2,
      "name": "Rock_Chalk",
      "rotation": 33
    },
    {
      "x": -2,
      "y": 8,
      "z": 3,
      "name": "Soil_Clay_White",
      "rotation": 33
    },
    {
      "x": -2,
      "y": 9,
      "z": 3,
      "name": "Rock_Marble_Cobble",
      "rotation": 33
    },
    {
      "x": -2,
      "y": 10,
      "z": 3,
      "name": "Soil_Clay_GreyLight",
      "rotation": 33
    },
    {
      "x": -2,
      "y": 11,
      "z": 3,
      "name": "Rock_Marble",
      "rotation": 33
    },
    {
      "x": -2,
      "y": 12,
      "z": 3,
      "name": "Soil_Clay_White",
      "rotation": 33
    },
    {
      "x": -2,
      "y": 13,
      "z": 3,
      "name": "Rock_Marble",
      "rotation": 33
    },
    {
      "x": -2,
      "y": 14,
      "z": 3,
      "name": "Soil_Clay_White",
      "rotation": 33
    },
    {
      "x": -2,
      "y": 15,
      "z": 3,
      "name": "Soil_Clay_White",
      "rotation": 33
    },
    {
      "x": -2,
      "y": 10,
      "z": 4,
      "name": "Soil_Clay_GreyLight",
      "rotation": 33
    },
    {
      "x": -2,
      "y": 11,
      "z": 4,
      "name": "Rock_Marble",
      "rotation": 33
    },
    {
      "x": -2,
      "y": 12,
      "z": 4,
      "name": "Soil_Clay_White",
      "rotation": 33
    },
    {
      "x": -2,
      "y": 13,
      "z": 4,
      "name": "Rock_Marble",
      "rotation": 33
    },
    {
      "x": -2,
      "y": 14,
      "z": 4,
      "name": "Soil_Clay_White",
      "rotation": 33
    },
    {
      "x": -1,
      "y": 15,
      "z": -4,
      "name": "Rock_Chalk",
      "rotation": 33
    },
    {
      "x": -1,
      "y": 9,
      "z": -3,
      "name": "Rock_Marble_Cobble",
      "rotation": 33
    },
    {
      "x": -1,
      "y": 10,
      "z": -3,
      "name": "Soil_Clay_GreyLight",
      "rotation": 33
    },
    {
      "x": -1,
      "y": 11,
      "z": -3,
      "name": "Rock_Marble",
      "rotation": 33
    },
    {
      "x": -1,
      "y": 12,
      "z": -3,
      "name": "Soil_Clay_White",
      "rotation": 33
    },
    {
      "x": -1,
      "y": 13,
      "z": -3,
      "name": "Rock_Marble",
      "rotation": 33
    },
    {
      "x": -1,
      "y": 14,
      "z": -3,
      "name": "Soil_Clay_White",
      "rotation": 33
    },
    {
      "x": -1,
      "y": 15,
      "z": -3,
      "name": "Rock_Chalk",
      "rotation": 33
    },
    {
      "x": -1,
      "y": 16,
      "z": -3,
      "name": "Rock_Chalk",
      "rotation": 33
    },
    {
      "x": -1,
      "y": 17,
      "z": -3,
      "name": "Rock_Chalk",
      "rotation": 33
    },
    {
      "x": -1,
      "y": 7,
      "z": -2,
      "name": "Rock_Marble",
      "rotation": 33
    },
    {
      "x": -1,
      "y": 8,
      "z": -2,
      "name": "Soil_Clay_White",
      "rotation": 33
    },
    {
      "x": -1,
      "y": 9,
      "z": -2,
      "name": "Rock_Marble_Cobble",
      "rotation": 33
    },
    {
      "x": -1,
      "y": 10,
      "z": -2,
      "name": "Soil_Clay_GreyLight",
      "rotation": 33
    },
    {
      "x": -1,
      "y": 11,
      "z": -2,
      "name": "Rock_Marble",
      "rotation": 33
    },
    {
      "x": -1,
      "y": 12,
      "z": -2,
      "name": "Soil_Clay_White",
      "rotation": 33
    },
    {
      "x": -1,
      "y": 13,
      "z": -2,
      "name": "Rock_Marble",
      "rotation": 33
    },
    {
      "x": -1,
      "y": 14,
      "z": -2,
      "name": "Soil_Clay_White",
      "rotation": 33
    },
    {
      "x": -1,
      "y": 15,
      "z": -2,
      "name": "Rock_Chalk",
      "rotation": 33
    },
    {
      "x": -1,
      "y": 16,
      "z": -2,
      "name": "Rock_Chalk",
      "rotation": 33
    },
    {
      "x": -1,
      "y": 17,
      "z": -2,
      "name": "Rock_Chalk",
      "rotation": 33
    },
    {
      "x": -1,
      "y": 6,
      "z": -1,
      "name": "Rock_Marble_Cobble",
      "rotation": 33
    },
    {
      "x": -1,
      "y": 7,
      "z": -1,
      "name": "Rock_Marble",
      "rotation": 33
    },
    {
      "x": -1,
      "y": 8,
      "z": -1,
      "name": "Soil_Clay_White",
      "rotation": 33
    },
    {
      "x": -1,
      "y": 9,
      "z": -1,
      "name": "Rock_Marble_Cobble",
      "rotation": 33
    },
    {
      "x": -1,
      "y": 10,
      "z": -1,
      "name": "Soil_Clay_GreyLight",
      "rotation": 33
    },
    {
      "x": -1,
      "y": 11,
      "z": -1,
      "name": "Rock_Marble",
      "rotation": 33
    },
    {
      "x": -1,
      "y": 12,
      "z": -1,
      "name": "Soil_Clay_White",
      "rotation": 33
    },
    {
      "x": -1,
      "y": 13,
      "z": -1,
      "name": "Rock_Marble",
      "rotation": 33
    },
    {
      "x": -1,
      "y": 14,
      "z": -1,
      "name": "Soil_Clay_White",
      "rotation": 33
    },
    {
      "x": -1,
      "y": 15,
      "z": -1,
      "name": "Rock_Chalk",
      "rotation": 33
    },
    {
      "x": -1,
      "y": 16,
      "z": -1,
      "name": "Rock_Chalk",
      "rotation": 33
    },
    {
      "x": -1,
      "y": 17,
      "z": -1,
      "name": "Rock_Chalk",
      "rotation": 33
    },
    {
      "x": -1,
      "y": 6,
      "z": 0,
      "name": "Rock_Marble_Cobble",
      "rotation": 33
    },
    {
      "x": -1,
      "y": 7,
      "z": 0,
      "name": "Rock_Marble",
      "rotation": 33
    },
    {
      "x": -1,
      "y": 8,
      "z": 0,
      "name": "Soil_Clay_White",
      "rotation": 33
    },
    {
      "x": -1,
      "y": 9,
      "z": 0,
      "name": "Rock_Marble_Cobble",
      "rotation": 33
    },
    {
      "x": -1,
      "y": 10,
      "z": 0,
      "name": "Soil_Clay_GreyLight",
      "rotation": 33
    },
    {
      "x": -1,
      "y": 11,
      "z": 0,
      "name": "Rock_Marble",
      "rotation": 33
    },
    {
      "x": -1,
      "y": 12,
      "z": 0,
      "name": "Soil_Clay_White",
      "rotation": 33
    },
    {
      "x": -1,
      "y": 13,
      "z": 0,
      "name": "Rock_Marble",
      "rotation": 33
    },
    {
      "x": -1,
      "y": 14,
      "z": 0,
      "name": "Soil_Clay_White",
      "rotation": 33
    },
    {
      "x": -1,
      "y": 15,
      "z": 0,
      "name": "Rock_Chalk",
      "rotation": 33
    },
    {
      "x": -1,
      "y": 16,
      "z": 0,
      "name": "Rock_Chalk",
      "rotation": 33
    },
    {
      "x": -1,
      "y": 17,
      "z": 0,
      "name": "Rock_Chalk",
      "rotation": 33
    },
    {
      "x": -1,
      "y": 6,
      "z": 1,
      "name": "Rock_Marble_Cobble",
      "rotation": 33
    },
    {
      "x": -1,
      "y": 7,
      "z": 1,
      "name": "Rock_Marble",
      "rotation": 33
    },
    {
      "x": -1,
      "y": 8,
      "z": 1,
      "name": "Soil_Clay_White",
      "rotation": 33
    },
    {
      "x": -1,
      "y": 9,
      "z": 1,
      "name": "Rock_Marble_Cobble",
      "rotation": 33
    },
    {
      "x": -1,
      "y": 10,
      "z": 1,
      "name": "Soil_Clay_GreyLight",
      "rotation": 33
    },
    {
      "x": -1,
      "y": 11,
      "z": 1,
      "name": "Rock_Marble",
      "rotation": 33
    },
    {
      "x": -1,
      "y": 12,
      "z": 1,
      "name": "Soil_Clay_White",
      "rotation": 33
    },
    {
      "x": -1,
      "y": 13,
      "z": 1,
      "name": "Rock_Marble",
      "rotation": 33
    },
    {
      "x": -1,
      "y": 14,
      "z": 1,
      "name": "Soil_Clay_White",
      "rotation": 33
    },
    {
      "x": -1,
      "y": 15,
      "z": 1,
      "name": "Rock_Chalk",
      "rotation": 33
    },
    {
      "x": -1,
      "y": 16,
      "z": 1,
      "name": "Rock_Chalk",
      "rotation": 33
    },
    {
      "x": -1,
      "y": 17,
      "z": 1,
      "name": "Rock_Chalk",
      "rotation": 33
    },
    {
      "x": -1,
      "y": 7,
      "z": 2,
      "name": "Rock_Marble",
      "rotation": 33
    },
    {
      "x": -1,
      "y": 8,
      "z": 2,
      "name": "Soil_Clay_White",
      "rotation": 33
    },
    {
      "x": -1,
      "y": 9,
      "z": 2,
      "name": "Rock_Marble_Cobble",
      "rotation": 33
    },
    {
      "x": -1,
      "y": 10,
      "z": 2,
      "name": "Soil_Clay_GreyLight",
      "rotation": 33
    },
    {
      "x": -1,
      "y": 11,
      "z": 2,
      "name": "Rock_Marble",
      "rotation": 33
    },
    {
      "x": -1,
      "y": 12,
      "z": 2,
      "name": "Soil_Clay_White",
      "rotation": 33
    },
    {
      "x": -1,
      "y": 13,
      "z": 2,
      "name": "Rock_Marble",
      "rotation": 33
    },
    {
      "x": -1,
      "y": 14,
      "z": 2,
      "name": "Soil_Clay_White",
      "rotation": 33
    },
    {
      "x": -1,
      "y": 15,
      "z": 2,
      "name": "Rock_Chalk",
      "rotation": 33
    },
    {
      "x": -1,
      "y": 16,
      "z": 2,
      "name": "Rock_Chalk",
      "rotation": 33
    },
    {
      "x": -1,
      "y": 17,
      "z": 2,
      "name": "Rock_Chalk",
      "rotation": 33
    },
    {
      "x": -1,
      "y": 7,
      "z": 3,
      "name": "Rock_Marble",
      "rotation": 33
    },
    {
      "x": -1,
      "y": 8,
      "z": 3,
      "name": "Soil_Clay_White",
      "rotation": 33
    },
    {
      "x": -1,
      "y": 9,
      "z": 3,
      "name": "Rock_Marble_Cobble",
      "rotation": 33
    },
    {
      "x": -1,
      "y": 10,
      "z": 3,
      "name": "Soil_Clay_GreyLight",
      "rotation": 33
    },
    {
      "x": -1,
      "y": 11,
      "z": 3,
      "name": "Rock_Marble",
      "rotation": 33
    },
    {
      "x": -1,
      "y": 12,
      "z": 3,
      "name": "Soil_Clay_White",
      "rotation": 33
    },
    {
      "x": -1,
      "y": 13,
      "z": 3,
      "name": "Rock_Marble",
      "rotation": 33
    },
    {
      "x": -1,
      "y": 14,
      "z": 3,
      "name": "Soil_Clay_White",
      "rotation": 33
    },
    {
      "x": -1,
      "y": 15,
      "z": 3,
      "name": "Soil_Clay_White",
      "rotation": 33
    },
    {
      "x": -1,
      "y": 16,
      "z": 3,
      "name": "Rock_Chalk",
      "rotation": 33
    },
    {
      "x": -1,
      "y": 9,
      "z": 4,
      "name": "Rock_Marble_Cobble",
      "rotation": 33
    },
    {
      "x": -1,
      "y": 10,
      "z": 4,
      "name": "Soil_Clay_GreyLight",
      "rotation": 33
    },
    {
      "x": -1,
      "y": 11,
      "z": 4,
      "name": "Rock_Marble",
      "rotation": 33
    },
    {
      "x": -1,
      "y": 12,
      "z": 4,
      "name": "Soil_Clay_White",
      "rotation": 33
    },
    {
      "x": -1,
      "y": 13,
      "z": 4,
      "name": "Rock_Marble",
      "rotation": 33
    },
    {
      "x": -1,
      "y": 14,
      "z": 4,
      "name": "Soil_Clay_White",
      "rotation": 33
    },
    {
      "x": -1,
      "y": 15,
      "z": 4,
      "name": "Soil_Clay_White",
      "rotation": 33
    },
    {
      "x": 0,
      "y": 14,
      "z": -4,
      "name": "Soil_Clay_White",
      "rotation": 33
    },
    {
      "x": 0,
      "y": 15,
      "z": -4,
      "name": "Rock_Chalk",
      "rotation": 33
    },
    {
      "x": 0,
      "y": 7,
      "z": -3,
      "name": "Rock_Marble",
      "rotation": 33
    },
    {
      "x": 0,
      "y": 8,
      "z": -3,
      "name": "Soil_Clay_White",
      "rotation": 33
    },
    {
      "x": 0,
      "y": 9,
      "z": -3,
      "name": "Rock_Marble_Cobble",
      "rotation": 33
    },
    {
      "x": 0,
      "y": 10,
      "z": -3,
      "name": "Soil_Clay_GreyLight",
      "rotation": 33
    },
    {
      "x": 0,
      "y": 11,
      "z": -3,
      "name": "Rock_Marble",
      "rotation": 33
    },
    {
      "x": 0,
      "y": 12,
      "z": -3,
      "name": "Soil_Clay_White",
      "rotation": 33
    },
    {
      "x": 0,
      "y": 13,
      "z": -3,
      "name": "Rock_Marble",
      "rotation": 33
    },
    {
      "x": 0,
      "y": 14,
      "z": -3,
      "name": "Soil_Clay_White",
      "rotation": 33
    },
    {
      "x": 0,
      "y": 15,
      "z": -3,
      "name": "Rock_Chalk",
      "rotation": 33
    },
    {
      "x": 0,
      "y": 16,
      "z": -3,
      "name": "Rock_Chalk",
      "rotation": 33
    },
    {
      "x": 0,
      "y": 17,
      "z": -3,
      "name": "Rock_Chalk",
      "rotation": 33
    },
    {
      "x": 0,
      "y": 6,
      "z": -2,
      "name": "Rock_Marble_Cobble",
      "rotation": 33
    },
    {
      "x": 0,
      "y": 7,
      "z": -2,
      "name": "Rock_Marble",
      "rotation": 33
    },
    {
      "x": 0,
      "y": 8,
      "z": -2,
      "name": "Soil_Clay_White",
      "rotation": 33
    },
    {
      "x": 0,
      "y": 9,
      "z": -2,
      "name": "Rock_Marble_Cobble",
      "rotation": 33
    },
    {
      "x": 0,
      "y": 10,
      "z": -2,
      "name": "Soil_Clay_GreyLight",
      "rotation": 33
    },
    {
      "x": 0,
      "y": 11,
      "z": -2,
      "name": "Rock_Marble",
      "rotation": 33
    },
    {
      "x": 0,
      "y": 12,
      "z": -2,
      "name": "Soil_Clay_White",
      "rotation": 33
    },
    {
      "x": 0,
      "y": 13,
      "z": -2,
      "name": "Rock_Marble",
      "rotation": 33
    },
    {
      "x": 0,
      "y": 14,
      "z": -2,
      "name": "Soil_Clay_White",
      "rotation": 33
    },
    {
      "x": 0,
      "y": 15,
      "z": -2,
      "name": "Rock_Chalk",
      "rotation": 33
    },
    {
      "x": 0,
      "y": 16,
      "z": -2,
      "name": "Rock_Chalk",
      "rotation": 33
    },
    {
      "x": 0,
      "y": 17,
      "z": -2,
      "name": "Rock_Chalk",
      "rotation": 33
    },
    {
      "x": 0,
      "y": 6,
      "z": -1,
      "name": "Rock_Marble_Cobble",
      "rotation": 33
    },
    {
      "x": 0,
      "y": 7,
      "z": -1,
      "name": "Rock_Marble",
      "rotation": 33
    },
    {
      "x": 0,
      "y": 8,
      "z": -1,
      "name": "Soil_Clay_White",
      "rotation": 33
    },
    {
      "x": 0,
      "y": 9,
      "z": -1,
      "name": "Rock_Marble_Cobble",
      "rotation": 33
    },
    {
      "x": 0,
      "y": 10,
      "z": -1,
      "name": "Soil_Clay_GreyLight",
      "rotation": 33
    },
    {
      "x": 0,
      "y": 11,
      "z": -1,
      "name": "Rock_Marble",
      "rotation": 33
    },
    {
      "x": 0,
      "y": 12,
      "z": -1,
      "name": "Soil_Clay_White",
      "rotation": 33
    },
    {
      "x": 0,
      "y": 13,
      "z": -1,
      "name": "Rock_Marble",
      "rotation": 33
    },
    {
      "x": 0,
      "y": 14,
      "z": -1,
      "name": "Soil_Clay_White",
      "rotation": 33
    },
    {
      "x": 0,
      "y": 15,
      "z": -1,
      "name": "Rock_Chalk",
      "rotation": 33
    },
    {
      "x": 0,
      "y": 16,
      "z": -1,
      "name": "Rock_Chalk",
      "rotation": 33
    },
    {
      "x": 0,
      "y": 17,
      "z": -1,
      "name": "Rock_Chalk",
      "rotation": 33
    },
    {
      "x": 0,
      "y": 6,
      "z": 0,
      "name": "Rock_Marble_Cobble",
      "rotation": 33
    },
    {
      "x": 0,
      "y": 7,
      "z": 0,
      "name": "Rock_Marble",
      "rotation": 33
    },
    {
      "x": 0,
      "y": 8,
      "z": 0,
      "name": "Soil_Clay_White",
      "rotation": 33
    },
    {
      "x": 0,
      "y": 9,
      "z": 0,
      "name": "Rock_Marble_Cobble",
      "rotation": 33
    },
    {
      "x": 0,
      "y": 10,
      "z": 0,
      "name": "Soil_Clay_GreyLight",
      "rotation": 33
    },
    {
      "x": 0,
      "y": 11,
      "z": 0,
      "name": "Rock_Marble",
      "rotation": 33
    },
    {
      "x": 0,
      "y": 12,
      "z": 0,
      "name": "Soil_Clay_White",
      "rotation": 33
    },
    {
      "x": 0,
      "y": 13,
      "z": 0,
      "name": "Rock_Marble",
      "rotation": 33
    },
    {
      "x": 0,
      "y": 14,
      "z": 0,
      "name": "Soil_Clay_White",
      "rotation": 33
    },
    {
      "x": 0,
      "y": 15,
      "z": 0,
      "name": "Rock_Chalk",
      "rotation": 33
    },
    {
      "x": 0,
      "y": 16,
      "z": 0,
      "name": "Rock_Chalk",
      "rotation": 33
    },
    {
      "x": 0,
      "y": 17,
      "z": 0,
      "name": "Rock_Chalk",
      "rotation": 33
    },
    {
      "x": 0,
      "y": 6,
      "z": 1,
      "name": "Rock_Marble_Cobble",
      "rotation": 33
    },
    {
      "x": 0,
      "y": 7,
      "z": 1,
      "name": "Rock_Marble",
      "rotation": 33
    },
    {
      "x": 0,
      "y": 8,
      "z": 1,
      "name": "Soil_Clay_White",
      "rotation": 33
    },
    {
      "x": 0,
      "y": 9,
      "z": 1,
      "name": "Rock_Marble_Cobble",
      "rotation": 33
    },
    {
      "x": 0,
      "y": 10,
      "z": 1,
      "name": "Soil_Clay_GreyLight",
      "rotation": 33
    },
    {
      "x": 0,
      "y": 11,
      "z": 1,
      "name": "Rock_Marble",
      "rotation": 33
    },
    {
      "x": 0,
      "y": 12,
      "z": 1,
      "name": "Soil_Clay_White",
      "rotation": 33
    },
    {
      "x": 0,
      "y": 13,
      "z": 1,
      "name": "Rock_Marble",
      "rotation": 33
    },
    {
      "x": 0,
      "y": 14,
      "z": 1,
      "name": "Soil_Clay_White",
      "rotation": 33
    },
    {
      "x": 0,
      "y": 15,
      "z": 1,
      "name": "Rock_Chalk",
      "rotation": 33
    },
    {
      "x": 0,
      "y": 16,
      "z": 1,
      "name": "Rock_Chalk",
      "rotation": 33
    },
    {
      "x": 0,
      "y": 17,
      "z": 1,
      "name": "Rock_Chalk",
      "rotation": 33
    },
    {
      "x": 0,
      "y": 6,
      "z": 2,
      "name": "Rock_Marble_Cobble",
      "rotation": 33
    },
    {
      "x": 0,
      "y": 7,
      "z": 2,
      "name": "Rock_Marble",
      "rotation": 33
    },
    {
      "x": 0,
      "y": 8,
      "z": 2,
      "name": "Soil_Clay_White",
      "rotation": 33
    },
    {
      "x": 0,
      "y": 9,
      "z": 2,
      "name": "Rock_Marble_Cobble",
      "rotation": 33
    },
    {
      "x": 0,
      "y": 10,
      "z": 2,
      "name": "Soil_Clay_GreyLight",
      "rotation": 33
    },
    {
      "x": 0,
      "y": 11,
      "z": 2,
      "name": "Rock_Marble",
      "rotation": 33
    },
    {
      "x": 0,
      "y": 12,
      "z": 2,
      "name": "Soil_Clay_White",
      "rotation": 33
    },
    {
      "x": 0,
      "y": 13,
      "z": 2,
      "name": "Rock_Marble",
      "rotation": 33
    },
    {
      "x": 0,
      "y": 14,
      "z": 2,
      "name": "Soil_Clay_White",
      "rotation": 33
    },
    {
      "x": 0,
      "y": 15,
      "z": 2,
      "name": "Rock_Chalk",
      "rotation": 33
    },
    {
      "x": 0,
      "y": 16,
      "z": 2,
      "name": "Rock_Chalk",
      "rotation": 33
    },
    {
      "x": 0,
      "y": 17,
      "z": 2,
      "name": "Rock_Chalk",
      "rotation": 33
    },
    {
      "x": 0,
      "y": 7,
      "z": 3,
      "name": "Rock_Marble",
      "rotation": 33
    },
    {
      "x": 0,
      "y": 8,
      "z": 3,
      "name": "Soil_Clay_White",
      "rotation": 33
    },
    {
      "x": 0,
      "y": 9,
      "z": 3,
      "name": "Rock_Marble_Cobble",
      "rotation": 33
    },
    {
      "x": 0,
      "y": 10,
      "z": 3,
      "name": "Soil_Clay_GreyLight",
      "rotation": 33
    },
    {
      "x": 0,
      "y": 11,
      "z": 3,
      "name": "Rock_Marble",
      "rotation": 33
    },
    {
      "x": 0,
      "y": 12,
      "z": 3,
      "name": "Soil_Clay_White",
      "rotation": 33
    },
    {
      "x": 0,
      "y": 13,
      "z": 3,
      "name": "Rock_Marble",
      "rotation": 33
    },
    {
      "x": 0,
      "y": 14,
      "z": 3,
      "name": "Soil_Clay_White",
      "rotation": 33
    },
    {
      "x": 0,
      "y": 15,
      "z": 3,
      "name": "Soil_Clay_White",
      "rotation": 33
    },
    {
      "x": 0,
      "y": 16,
      "z": 3,
      "name": "Rock_Chalk",
      "rotation": 33
    },
    {
      "x": 0,
      "y": 13,
      "z": 4,
      "name": "Rock_Marble",
      "rotation": 33
    },
    {
      "x": 0,
      "y": 14,
      "z": 4,
      "name": "Soil_Clay_White",
      "rotation": 33
    },
    {
      "x": 0,
      "y": 15,
      "z": 4,
      "name": "Soil_Clay_White",
      "rotation": 33
    },
    {
      "x": 1,
      "y": 14,
      "z": -4,
      "name": "Soil_Clay_White",
      "rotation": 33
    },
    {
      "x": 1,
      "y": 15,
      "z": -4,
      "name": "Rock_Chalk",
      "rotation": 33
    },
    {
      "x": 1,
      "y": 7,
      "z": -3,
      "name": "Rock_Marble",
      "rotation": 33
    },
    {
      "x": 1,
      "y": 8,
      "z": -3,
      "name": "Rock_Marble",
      "rotation": 33
    },
    {
      "x": 1,
      "y": 12,
      "z": -3,
      "name": "Soil_Clay_White",
      "rotation": 33
    },
    {
      "x": 1,
      "y": 13,
      "z": -3,
      "name": "Soil_Clay_White",
      "rotation": 33
    },
    {
      "x": 1,
      "y": 14,
      "z": -3,
      "name": "Soil_Clay_White",
      "rotation": 33
    },
    {
      "x": 1,
      "y": 15,
      "z": -3,
      "name": "Rock_Chalk",
      "rotation": 33
    },
    {
      "x": 1,
      "y": 16,
      "z": -3,
      "name": "Rock_Chalk",
      "rotation": 33
    },
    {
      "x": 1,
      "y": 17,
      "z": -3,
      "name": "Soil_Clay_White",
      "rotation": 33
    },
    {
      "x": 1,
      "y": 6,
      "z": -2,
      "name": "Rock_Marble_Cobble",
      "rotation": 33
    },
    {
      "x": 1,
      "y": 7,
      "z": -2,
      "name": "Rock_Marble",
      "rotation": 33
    },
    {
      "x": 1,
      "y": 8,
      "z": -2,
      "name": "Rock_Marble",
      "rotation": 33
    },
    {
      "x": 1,
      "y": 9,
      "z": -2,
      "name": "Rock_Marble_Cobble",
      "rotation": 33
    },
    {
      "x": 1,
      "y": 10,
      "z": -2,
      "name": "Soil_Clay_GreyLight",
      "rotation": 33
    },
    {
      "x": 1,
      "y": 11,
      "z": -2,
      "name": "Rock_Marble",
      "rotation": 33
    },
    {
      "x": 1,
      "y": 12,
      "z": -2,
      "name": "Soil_Clay_White",
      "rotation": 33
    },
    {
      "x": 1,
      "y": 13,
      "z": -2,
      "name": "Rock_Marble",
      "rotation": 33
    },
    {
      "x": 1,
      "y": 14,
      "z": -2,
      "name": "Soil_Clay_White",
      "rotation": 33
    },
    {
      "x": 1,
      "y": 15,
      "z": -2,
      "name": "Rock_Chalk",
      "rotation": 33
    },
    {
      "x": 1,
      "y": 16,
      "z": -2,
      "name": "Rock_Chalk",
      "rotation": 33
    },
    {
      "x": 1,
      "y": 17,
      "z": -2,
      "name": "Soil_Clay_White",
      "rotation": 33
    },
    {
      "x": 1,
      "y": 5,
      "z": -1,
      "name": "Rock_Marble_Cobble",
      "rotation": 33
    },
    {
      "x": 1,
      "y": 6,
      "z": -1,
      "name": "Rock_Marble_Cobble",
      "rotation": 33
    },
    {
      "x": 1,
      "y": 7,
      "z": -1,
      "name": "Rock_Marble",
      "rotation": 33
    },
    {
      "x": 1,
      "y": 8,
      "z": -1,
      "name": "Rock_Marble",
      "rotation": 33
    },
    {
      "x": 1,
      "y": 9,
      "z": -1,
      "name": "Rock_Marble_Cobble",
      "rotation": 33
    },
    {
      "x": 1,
      "y": 10,
      "z": -1,
      "name": "Soil_Clay_GreyLight",
      "rotation": 33
    },
    {
      "x": 1,
      "y": 11,
      "z": -1,
      "name": "Rock_Marble",
      "rotation": 33
    },
    {
      "x": 1,
      "y": 12,
      "z": -1,
      "name": "Soil_Clay_White",
      "rotation": 33
    },
    {
      "x": 1,
      "y": 13,
      "z": -1,
      "name": "Rock_Marble",
      "rotation": 33
    },
    {
      "x": 1,
      "y": 14,
      "z": -1,
      "name": "Soil_Clay_White",
      "rotation": 33
    },
    {
      "x": 1,
      "y": 15,
      "z": -1,
      "name": "Rock_Chalk",
      "rotation": 33
    },
    {
      "x": 1,
      "y": 16,
      "z": -1,
      "name": "Rock_Chalk",
      "rotation": 33
    },
    {
      "x": 1,
      "y": 17,
      "z": -1,
      "name": "Rock_Chalk",
      "rotation": 33
    },
    {
      "x": 1,
      "y": 5,
      "z": 0,
      "name": "Rock_Marble_Cobble",
      "rotation": 33
    },
    {
      "x": 1,
      "y": 6,
      "z": 0,
      "name": "Rock_Marble_Cobble",
      "rotation": 33
    },
    {
      "x": 1,
      "y": 7,
      "z": 0,
      "name": "Rock_Marble",
      "rotation": 33
    },
    {
      "x": 1,
      "y": 8,
      "z": 0,
      "name": "Rock_Marble",
      "rotation": 33
    },
    {
      "x": 1,
      "y": 9,
      "z": 0,
      "name": "Rock_Marble_Cobble",
      "rotation": 33
    },
    {
      "x": 1,
      "y": 10,
      "z": 0,
      "name": "Soil_Clay_GreyLight",
      "rotation": 33
    },
    {
      "x": 1,
      "y": 11,
      "z": 0,
      "name": "Rock_Marble",
      "rotation": 33
    },
    {
      "x": 1,
      "y": 12,
      "z": 0,
      "name": "Soil_Clay_White",
      "rotation": 33
    },
    {
      "x": 1,
      "y": 13,
      "z": 0,
      "name": "Rock_Marble",
      "rotation": 33
    },
    {
      "x": 1,
      "y": 14,
      "z": 0,
      "name": "Soil_Clay_White",
      "rotation": 33
    },
    {
      "x": 1,
      "y": 15,
      "z": 0,
      "name": "Rock_Chalk",
      "rotation": 33
    },
    {
      "x": 1,
      "y": 16,
      "z": 0,
      "name": "Rock_Chalk",
      "rotation": 33
    },
    {
      "x": 1,
      "y": 17,
      "z": 0,
      "name": "Rock_Chalk",
      "rotation": 33
    },
    {
      "x": 1,
      "y": 6,
      "z": 1,
      "name": "Rock_Marble_Cobble",
      "rotation": 33
    },
    {
      "x": 1,
      "y": 7,
      "z": 1,
      "name": "Rock_Marble",
      "rotation": 33
    },
    {
      "x": 1,
      "y": 8,
      "z": 1,
      "name": "Rock_Marble",
      "rotation": 33
    },
    {
      "x": 1,
      "y": 9,
      "z": 1,
      "name": "Rock_Marble_Cobble",
      "rotation": 33
    },
    {
      "x": 1,
      "y": 10,
      "z": 1,
      "name": "Soil_Clay_GreyLight",
      "rotation": 33
    },
    {
      "x": 1,
      "y": 11,
      "z": 1,
      "name": "Rock_Marble",
      "rotation": 33
    },
    {
      "x": 1,
      "y": 12,
      "z": 1,
      "name": "Soil_Clay_White",
      "rotation": 33
    },
    {
      "x": 1,
      "y": 13,
      "z": 1,
      "name": "Rock_Marble",
      "rotation": 33
    },
    {
      "x": 1,
      "y": 14,
      "z": 1,
      "name": "Soil_Clay_White",
      "rotation": 33
    },
    {
      "x": 1,
      "y": 15,
      "z": 1,
      "name": "Rock_Chalk",
      "rotation": 33
    },
    {
      "x": 1,
      "y": 16,
      "z": 1,
      "name": "Rock_Chalk",
      "rotation": 33
    },
    {
      "x": 1,
      "y": 17,
      "z": 1,
      "name": "Rock_Chalk",
      "rotation": 33
    },
    {
      "x": 1,
      "y": 6,
      "z": 2,
      "name": "Rock_Marble_Cobble",
      "rotation": 33
    },
    {
      "x": 1,
      "y": 7,
      "z": 2,
      "name": "Rock_Marble",
      "rotation": 33
    },
    {
      "x": 1,
      "y": 8,
      "z": 2,
      "name": "Rock_Marble",
      "rotation": 33
    },
    {
      "x": 1,
      "y": 9,
      "z": 2,
      "name": "Rock_Marble_Cobble",
      "rotation": 33
    },
    {
      "x": 1,
      "y": 10,
      "z": 2,
      "name": "Soil_Clay_GreyLight",
      "rotation": 33
    },
    {
      "x": 1,
      "y": 11,
      "z": 2,
      "name": "Rock_Marble",
      "rotation": 33
    },
    {
      "x": 1,
      "y": 12,
      "z": 2,
      "name": "Soil_Clay_White",
      "rotation": 33
    },
    {
      "x": 1,
      "y": 13,
      "z": 2,
      "name": "Rock_Marble",
      "rotation": 33
    },
    {
      "x": 1,
      "y": 14,
      "z": 2,
      "name": "Soil_Clay_White",
      "rotation": 33
    },
    {
      "x": 1,
      "y": 15,
      "z": 2,
      "name": "Soil_Clay_White",
      "rotation": 33
    },
    {
      "x": 1,
      "y": 16,
      "z": 2,
      "name": "Rock_Chalk",
      "rotation": 33
    },
    {
      "x": 1,
      "y": 17,
      "z": 2,
      "name": "Rock_Chalk",
      "rotation": 33
    },
    {
      "x": 1,
      "y": 8,
      "z": 3,
      "name": "Rock_Marble",
      "rotation": 33
    },
    {
      "x": 1,
      "y": 9,
      "z": 3,
      "name": "Rock_Marble_Cobble",
      "rotation": 33
    },
    {
      "x": 1,
      "y": 10,
      "z": 3,
      "name": "Soil_Clay_GreyLight",
      "rotation": 33
    },
    {
      "x": 1,
      "y": 11,
      "z": 3,
      "name": "Rock_Marble",
      "rotation": 33
    },
    {
      "x": 1,
      "y": 12,
      "z": 3,
      "name": "Soil_Clay_White",
      "rotation": 33
    },
    {
      "x": 1,
      "y": 13,
      "z": 3,
      "name": "Rock_Marble",
      "rotation": 33
    },
    {
      "x": 1,
      "y": 14,
      "z": 3,
      "name": "Soil_Clay_White",
      "rotation": 33
    },
    {
      "x": 1,
      "y": 15,
      "z": 3,
      "name": "Soil_Clay_White",
      "rotation": 33
    },
    {
      "x": 1,
      "y": 16,
      "z": 3,
      "name": "Rock_Chalk",
      "rotation": 33
    },
    {
      "x": 2,
      "y": 13,
      "z": -3,
      "name": "Soil_Clay_White",
      "rotation": 33
    },
    {
      "x": 2,
      "y": 14,
      "z": -3,
      "name": "Soil_Clay_White",
      "rotation": 33
    },
    {
      "x": 2,
      "y": 15,
      "z": -3,
      "name": "Rock_Chalk",
      "rotation": 33
    },
    {
      "x": 2,
      "y": 16,
      "z": -3,
      "name": "Rock_Chalk",
      "rotation": 33
    },
    {
      "x": 2,
      "y": 6,
      "z": -2,
      "name": "Rock_Marble_Cobble",
      "rotation": 33
    },
    {
      "x": 2,
      "y": 7,
      "z": -2,
      "name": "Rock_Marble",
      "rotation": 33
    },
    {
      "x": 2,
      "y": 8,
      "z": -2,
      "name": "Rock_Marble",
      "rotation": 33
    },
    {
      "x": 2,
      "y": 9,
      "z": -2,
      "name": "Rock_Marble_Cobble",
      "rotation": 33
    },
    {
      "x": 2,
      "y": 12,
      "z": -2,
      "name": "Soil_Clay_White",
      "rotation": 33
    },
    {
      "x": 2,
      "y": 13,
      "z": -2,
      "name": "Soil_Clay_White",
      "rotation": 33
    },
    {
      "x": 2,
      "y": 14,
      "z": -2,
      "name": "Soil_Clay_White",
      "rotation": 33
    },
    {
      "x": 2,
      "y": 15,
      "z": -2,
      "name": "Rock_Chalk",
      "rotation": 33
    },
    {
      "x": 2,
      "y": 16,
      "z": -2,
      "name": "Rock_Chalk",
      "rotation": 33
    },
    {
      "x": 2,
      "y": 17,
      "z": -2,
      "name": "Soil_Clay_White",
      "rotation": 33
    },
    {
      "x": 2,
      "y": 5,
      "z": -1,
      "name": "Rock_Marble_Cobble",
      "rotation": 33
    },
    {
      "x": 2,
      "y": 6,
      "z": -1,
      "name": "Rock_Marble_Cobble",
      "rotation": 33
    },
    {
      "x": 2,
      "y": 7,
      "z": -1,
      "name": "Rock_Marble",
      "rotation": 33
    },
    {
      "x": 2,
      "y": 8,
      "z": -1,
      "name": "Rock_Marble",
      "rotation": 33
    },
    {
      "x": 2,
      "y": 9,
      "z": -1,
      "name": "Rock_Marble_Cobble",
      "rotation": 33
    },
    {
      "x": 2,
      "y": 10,
      "z": -1,
      "name": "Soil_Clay_GreyLight",
      "rotation": 33
    },
    {
      "x": 2,
      "y": 11,
      "z": -1,
      "name": "Rock_Marble",
      "rotation": 33
    },
    {
      "x": 2,
      "y": 12,
      "z": -1,
      "name": "Soil_Clay_White",
      "rotation": 33
    },
    {
      "x": 2,
      "y": 13,
      "z": -1,
      "name": "Soil_Clay_White",
      "rotation": 33
    },
    {
      "x": 2,
      "y": 14,
      "z": -1,
      "name": "Soil_Clay_White",
      "rotation": 33
    },
    {
      "x": 2,
      "y": 15,
      "z": -1,
      "name": "Rock_Chalk",
      "rotation": 33
    },
    {
      "x": 2,
      "y": 16,
      "z": -1,
      "name": "Rock_Chalk",
      "rotation": 33
    },
    {
      "x": 2,
      "y": 17,
      "z": -1,
      "name": "Soil_Clay_White",
      "rotation": 33
    },
    {
      "x": 2,
      "y": 5,
      "z": 0,
      "name": "Rock_Marble_Cobble",
      "rotation": 33
    },
    {
      "x": 2,
      "y": 6,
      "z": 0,
      "name": "Rock_Marble_Cobble",
      "rotation": 33
    },
    {
      "x": 2,
      "y": 7,
      "z": 0,
      "name": "Rock_Marble",
      "rotation": 33
    },
    {
      "x": 2,
      "y": 8,
      "z": 0,
      "name": "Rock_Marble",
      "rotation": 33
    },
    {
      "x": 2,
      "y": 9,
      "z": 0,
      "name": "Rock_Marble_Cobble",
      "rotation": 33
    },
    {
      "x": 2,
      "y": 10,
      "z": 0,
      "name": "Soil_Clay_GreyLight",
      "rotation": 33
    },
    {
      "x": 2,
      "y": 11,
      "z": 0,
      "name": "Rock_Marble",
      "rotation": 33
    },
    {
      "x": 2,
      "y": 12,
      "z": 0,
      "name": "Soil_Clay_White",
      "rotation": 33
    },
    {
      "x": 2,
      "y": 13,
      "z": 0,
      "name": "Rock_Marble",
      "rotation": 33
    },
    {
      "x": 2,
      "y": 14,
      "z": 0,
      "name": "Soil_Clay_White",
      "rotation": 33
    },
    {
      "x": 2,
      "y": 15,
      "z": 0,
      "name": "Rock_Chalk",
      "rotation": 33
    },
    {
      "x": 2,
      "y": 16,
      "z": 0,
      "name": "Rock_Chalk",
      "rotation": 33
    },
    {
      "x": 2,
      "y": 17,
      "z": 0,
      "name": "Soil_Clay_White",
      "rotation": 33
    },
    {
      "x": 2,
      "y": 6,
      "z": 1,
      "name": "Rock_Marble_Cobble",
      "rotation": 33
    },
    {
      "x": 2,
      "y": 7,
      "z": 1,
      "name": "Rock_Marble",
      "rotation": 33
    },
    {
      "x": 2,
      "y": 8,
      "z": 1,
      "name": "Rock_Marble",
      "rotation": 33
    },
    {
      "x": 2,
      "y": 9,
      "z": 1,
      "name": "Rock_Marble_Cobble",
      "rotation": 33
    },
    {
      "x": 2,
      "y": 10,
      "z": 1,
      "name": "Soil_Clay_GreyLight",
      "rotation": 33
    },
    {
      "x": 2,
      "y": 11,
      "z": 1,
      "name": "Rock_Marble",
      "rotation": 33
    },
    {
      "x": 2,
      "y": 12,
      "z": 1,
      "name": "Soil_Clay_White",
      "rotation": 33
    },
    {
      "x": 2,
      "y": 13,
      "z": 1,
      "name": "Rock_Marble",
      "rotation": 33
    },
    {
      "x": 2,
      "y": 14,
      "z": 1,
      "name": "Soil_Clay_White",
      "rotation": 33
    },
    {
      "x": 2,
      "y": 15,
      "z": 1,
      "name": "Rock_Chalk",
      "rotation": 33
    },
    {
      "x": 2,
      "y": 16,
      "z": 1,
      "name": "Rock_Chalk",
      "rotation": 33
    },
    {
      "x": 2,
      "y": 17,
      "z": 1,
      "name": "Soil_Clay_White",
      "rotation": 33
    },
    {
      "x": 2,
      "y": 7,
      "z": 2,
      "name": "Rock_Marble",
      "rotation": 33
    },
    {
      "x": 2,
      "y": 8,
      "z": 2,
      "name": "Rock_Marble",
      "rotation": 33
    },
    {
      "x": 2,
      "y": 9,
      "z": 2,
      "name": "Rock_Marble_Cobble",
      "rotation": 33
    },
    {
      "x": 2,
      "y": 10,
      "z": 2,
      "name": "Soil_Clay_GreyLight",
      "rotation": 33
    },
    {
      "x": 2,
      "y": 11,
      "z": 2,
      "name": "Rock_Marble",
      "rotation": 33
    },
    {
      "x": 2,
      "y": 12,
      "z": 2,
      "name": "Soil_Clay_White",
      "rotation": 33
    },
    {
      "x": 2,
      "y": 13,
      "z": 2,
      "name": "Rock_Marble",
      "rotation": 33
    },
    {
      "x": 2,
      "y": 14,
      "z": 2,
      "name": "Soil_Clay_White",
      "rotation": 33
    },
    {
      "x": 2,
      "y": 15,
      "z": 2,
      "name": "Soil_Clay_White",
      "rotation": 33
    },
    {
      "x": 2,
      "y": 16,
      "z": 2,
      "name": "Rock_Chalk",
      "rotation": 33
    },
    {
      "x": 2,
      "y": 13,
      "z": 3,
      "name": "Rock_Marble",
      "rotation": 33
    },
    {
      "x": 2,
      "y": 14,
      "z": 3,
      "name": "Soil_Clay_White",
      "rotation": 33
    },
    {
      "x": 2,
      "y": 15,
      "z": 3,
      "name": "Soil_Clay_White",
      "rotation": 33
    },
    {
      "x": 3,
      "y": 14,
      "z": -3,
      "name": "Soil_Clay_White",
      "rotation": 33
    },
    {
      "x": 3,
      "y": 15,
      "z": -3,
      "name": "Rock_Chalk",
      "rotation": 33
    },
    {
      "x": 3,
      "y": 7,
      "z": -2,
      "name": "Rock_Marble",
      "rotation": 33
    },
    {
      "x": 3,
      "y": 13,
      "z": -2,
      "name": "Soil_Clay_White",
      "rotation": 33
    },
    {
      "x": 3,
      "y": 14,
      "z": -2,
      "name": "Soil_Clay_White",
      "rotation": 33
    },
    {
      "x": 3,
      "y": 15,
      "z": -2,
      "name": "Rock_Chalk",
      "rotation": 33
    },
    {
      "x": 3,
      "y": 16,
      "z": -2,
      "name": "Rock_Chalk",
      "rotation": 33
    },
    {
      "x": 3,
      "y": 6,
      "z": -1,
      "name": "Rock_Marble_Cobble",
      "rotation": 33
    },
    {
      "x": 3,
      "y": 7,
      "z": -1,
      "name": "Rock_Marble",
      "rotation": 33
    },
    {
      "x": 3,
      "y": 8,
      "z": -1,
      "name": "Rock_Marble",
      "rotation": 33
    },
    {
      "x": 3,
      "y": 12,
      "z": -1,
      "name": "Soil_Clay_White",
      "rotation": 33
    },
    {
      "x": 3,
      "y": 13,
      "z": -1,
      "name": "Soil_Clay_White",
      "rotation": 33
    },
    {
      "x": 3,
      "y": 14,
      "z": -1,
      "name": "Soil_Clay_White",
      "rotation": 33
    },
    {
      "x": 3,
      "y": 15,
      "z": -1,
      "name": "Rock_Chalk",
      "rotation": 33
    },
    {
      "x": 3,
      "y": 16,
      "z": -1,
      "name": "Rock_Chalk",
      "rotation": 33
    },
    {
      "x": 3,
      "y": 17,
      "z": -1,
      "name": "Soil_Clay_White",
      "rotation": 33
    },
    {
      "x": 3,
      "y": 6,
      "z": 0,
      "name": "Rock_Marble_Cobble",
      "rotation": 33
    },
    {
      "x": 3,
      "y": 7,
      "z": 0,
      "name": "Rock_Marble",
      "rotation": 33
    },
    {
      "x": 3,
      "y": 8,
      "z": 0,
      "name": "Rock_Marble",
      "rotation": 33
    },
    {
      "x": 3,
      "y": 9,
      "z": 0,
      "name": "Rock_Marble_Cobble",
      "rotation": 33
    },
    {
      "x": 3,
      "y": 11,
      "z": 0,
      "name": "Rock_Marble",
      "rotation": 33
    },
    {
      "x": 3,
      "y": 12,
      "z": 0,
      "name": "Soil_Clay_White",
      "rotation": 33
    },
    {
      "x": 3,
      "y": 13,
      "z": 0,
      "name": "Soil_Clay_White",
      "rotation": 33
    },
    {
      "x": 3,
      "y": 14,
      "z": 0,
      "name": "Soil_Clay_White",
      "rotation": 33
    },
    {
      "x": 3,
      "y": 15,
      "z": 0,
      "name": "Rock_Chalk",
      "rotation": 33
    },
    {
      "x": 3,
      "y": 16,
      "z": 0,
      "name": "Rock_Chalk",
      "rotation": 33
    },
    {
      "x": 3,
      "y": 17,
      "z": 0,
      "name": "Soil_Clay_White",
      "rotation": 33
    },
    {
      "x": 3,
      "y": 7,
      "z": 1,
      "name": "Rock_Marble",
      "rotation": 33
    },
    {
      "x": 3,
      "y": 8,
      "z": 1,
      "name": "Rock_Marble",
      "rotation": 33
    },
    {
      "x": 3,
      "y": 12,
      "z": 1,
      "name": "Soil_Clay_White",
      "rotation": 33
    },
    {
      "x": 3,
      "y": 13,
      "z": 1,
      "name": "Rock_Marble",
      "rotation": 33
    },
    {
      "x": 3,
      "y": 14,
      "z": 1,
      "name": "Soil_Clay_White",
      "rotation": 33
    },
    {
      "x": 3,
      "y": 15,
      "z": 1,
      "name": "Rock_Chalk",
      "rotation": 33
    },
    {
      "x": 3,
      "y": 16,
      "z": 1,
      "name": "Rock_Chalk",
      "rotation": 33
    },
    {
      "x": 3,
      "y": 13,
      "z": 2,
      "name": "Rock_Marble",
      "rotation": 33
    },
    {
      "x": 3,
      "y": 14,
      "z": 2,
      "name": "Soil_Clay_White",
      "rotation": 33
    },
    {
      "x": 3,
      "y": 15,
      "z": 2,
      "name": "Soil_Clay_White",
      "rotation": 33
    },
    {
      "x": 4,
      "y": 14,
      "z": -2,
      "name": "Soil_Clay_White",
      "rotation": 33
    },
    {
      "x": 4,
      "y": 15,
      "z": -2,
      "name": "Rock_Chalk",
      "rotation": 33
    },
    {
      "x": 4,
      "y": 13,
      "z": -1,
      "name": "Soil_Clay_White",
      "rotation": 33
    },
    {
      "x": 4,
      "y": 14,
      "z": -1,
      "name": "Soil_Clay_White",
      "rotation": 33
    },
    {
      "x": 4,
      "y": 15,
      "z": -1,
      "name": "Rock_Chalk",
      "rotation": 33
    },
    {
      "x": 4,
      "y": 16,
      "z": -1,
      "name": "Rock_Chalk",
      "rotation": 33
    },
    {
      "x": 4,
      "y": 13,
      "z": 0,
      "name": "Soil_Clay_White",
      "rotation": 33
    },
    {
      "x": 4,
      "y": 14,
      "z": 0,
      "name": "Soil_Clay_White",
      "rotation": 33
    },
    {
      "x": 4,
      "y": 15,
      "z": 0,
      "name": "Rock_Chalk",
      "rotation": 33
    },
    {
      "x": 4,
      "y": 16,
      "z": 0,
      "name": "Rock_Chalk",
      "rotation": 33
    },
    {
      "x": 4,
      "y": 14,
      "z": 1,
      "name": "Soil_Clay_White",
      "rotation": 33
    },
    {
      "x": 4,
      "y": 15,
      "z": 1,
      "name": "Rock_Chalk",
      "rotation": 33
    }
  ]
}