{
  "version": 8,
  "blockIdVersion": 11,
  "anchorX": -1,
  "anchorY": 3,
  "anchorZ": 0,
  "blocks": [
    {
      "x": -5,
      "y": 4,
      "z": 0,
      "name": "Soil_Clay_White",
      "rotation": 33
    },
    {
      "x": -5,
      "y": 5,
      "z": 0,
      "name": "Rock_Marble",
      "rotation": 33
    },
    {
      "x": -5,
      "y": 4,
      "z": 1,
      "name": "Soil_Clay_White",
      "rotation": 33
    },
    {
      "x": -5,
      "y": 5,
      "z": 1,
      "name": "Rock_Marble",
      "rotation": 33
    },
    {
      "x": -4,
      "y": 4,
      "z": -2,
      "name": "Soil_Clay_White",
      "rotation": 33
    },
    {
      "x": -4,
      "y": 5,
      "z": -2,
      "name": "Rock_Marble",
      "rotation": 33
    },
    {
      "x": -4,
      "y": 6,
      "z": -2,
      "name": "Rock_Marble",
      "rotation": 33
    },
    {
      "x": -4,
      "y": 3,
      "z": -1,
      "name": "Soil_Clay_White",
      "rotation": 33
    },
    {
      "x": -4,
      "y": 4,
      "z": -1,
      "name": "Soil_Clay_White",
      "rotation": 33
    },
    {
      "x": -4,
      "y": 5,
      "z": -1,
      "name": "Rock_Marble",
      "rotation": 33
    },
    {
      "x": -4,
      "y": 6,
      "z": -1,
      "name": "Rock_Marble",
      "rotation": 33
    },
    {
      "x": -4,
      "y": 7,
      "z": -1,
      "name": "Soil_Clay_White",
      "rotation": 33
    },
    {
      "x": -4,
      "y": 3,
      "z": 0,
      "name": "Soil_Clay_White",
      "rotation": 33
    },
    {
      "x": -4,
      "y": 4,
      "z": 0,
      "name": "Soil_Clay_White",
      "rotation": 33
    },
    {
      "x": -4,
      "y": 5,
      "z": 0,
      "name": "Rock_Marble",
      "rotation": 33
    },
    {
      "x": -4,
      "y": 6,
      "z": 0,
      "name": "Rock_Marble",
      "rotation": 33
    },
    {
      "x": -4,
      "y": 7,
      "z": 0,
      "name": "Soil_Clay_White",
      "rotation": 33
    },
    {
      "x": -4,
      "y": 3,
      "z": 1,
      "name": "Soil_Clay_White",
      "rotation": 33
    },
    {
      "x": -4,
      "y": 4,
      "z": 1,
      "name": "Soil_Clay_White",
      "rotation": 33
    },
    {
      "x": -4,
      "y": 5,
      "z": 1,
      "name": "Rock_Marble",
      "rotation": 33
    },
    {
      "x": -4,
      "y": 6,
      "z": 1,
      "name": "Rock_Marble",
      "rotation": 33
    },
    {
      "x": -4,
      "y": 7,
      "z": 1,
      "name": "Soil_Clay_White",
      "rotation": 33
    },
    {
      "x": -4,
      "y": 3,
      "z": 2,
      "name": "Soil_Clay_White",
      "rotation": 33
    },
    {
      "x": -4,
      "y": 4,
      "z": 2,
      "name": "Soil_Clay_White",
      "rotation": 33
    },
    {
      "x": -4,
      "y": 5,
      "z": 2,
      "name": "Rock_Marble",
      "rotation": 33
    },
    {
      "x": -4,
      "y": 6,
      "z": 2,
      "name": "Rock_Marble",
      "rotation": 33
    },
    {
      "x": -4,
      "y": 7,
      "z": 2,
      "name": "Soil_Clay_White",
      "rotation": 33
    },
    {
      "x": -4,
      "y": 4,
      "z": 3,
      "name": "Soil_Clay_White",
      "rotation": 33
    },
    {
      "x": -4,
      "y": 5,
      "z": 3,
      "name": "Rock_Marble",
      "rotation": 33
    },
    {
      "x": -4,
      "y": 6,
      "z": 3,
      "name": "Rock_Marble",
      "rotation": 33
    },
    {
      "x": -3,
      "y": 3,
      "z": -3,
      "name": "Soil_Clay_White",
      "rotation": 33
    },
    {
      "x": -3,
      "y": 4,
      "z": -3,
      "name": "Soil_Clay_White",
      "rotation": 33
    },
    {
      "x": -3,
      "y": 5,
      "z": -3,
      "name": "Rock_Marble",
      "rotation": 33
    },
    {
      "x": -3,
      "y": 6,
      "z": -3,
      "name": "Rock_Marble",
      "rotation": 33
    },
    {
      "x": -3,
      "y": 3,
      "z": -2,
      "name": "Soil_Clay_White",
      "rotation": 33
    },
    {
      "x": -3,
      "y": 4,
      "z": -2,
      "name": "Soil_Clay_White",
      "rotation": 33
    },
    {
      "x": -3,
      "y": 5,
      "z": -2,
      "name": "Rock_Marble",
      "rotation": 33
    },
    {
      "x": -3,
      "y": 6,
      "z": -2,
      "name": "Rock_Marble",
      "rotation": 33
    },
    {
      "x": -3,
      "y": 7,
      "z": -2,
      "name": "Soil_Clay_White",
      "rotation": 33
    },
    {
      "x": -3,
      "y": 2,
      "z": -1,
      "name": "Rock_Marble",
      "rotation": 33
    },
    {
      "x": -3,
      "y": 3,
      "z": -1,
      "name": "Soil_Clay_White",
      "rotation": 33
    },
    {
      "x": -3,
      "y": 4,
      "z": -1,
      "name": "Soil_Clay_White",
      "rotation": 33
    },
    {
      "x": -3,
      "y": 5,
      "z": -1,
      "name": "Rock_Marble",
      "rotation": 33
    },
    {
      "x": -3,
      "y": 6,
      "z": -1,
      "name": "Rock_Marble",
      "rotation": 33
    },
    {
      "x": -3,
      "y": 7,
      "z": -1,
      "name": "Soil_Clay_White",
      "rotation": 33
    },
    {
      "x": -3,
      "y": 8,
      "z": -1,
      "name": "Rock_Marble_Cobble",
      "rotation": 33
    },
    {
      "x": -3,
      "y": 2,
      "z": 0,
      "name": "Rock_Marble",
      "rotation": 33
    },
    {
      "x": -3,
      "y": 3,
      "z": 0,
      "name": "Soil_Clay_White",
      "rotation": 33
    },
    {
      "x": -3,
      "y": 4,
      "z": 0,
      "name": "Soil_Clay_White",
      "rotation": 33
    },
    {
      "x": -3,
      "y": 5,
      "z": 0,
      "name": "Rock_Marble",
      "rotation": 33
    },
    {
      "x": -3,
      "y": 6,
      "z": 0,
      "name": "Rock_Marble",
      "rotation": 33
    },
    {
      "x": -3,
      "y": 7,
      "z": 0,
      "name": "Soil_Clay_White",
      "rotation": 33
    },
    {
      "x": -3,
      "y": 8,
      "z": 0,
      "name": "Rock_Marble_Cobble",
      "rotation": 33
    },
    {
      "x": -3,
      "y": 2,
      "z": 1,
      "name": "Rock_Marble",
      "rotation": 33
    },
    {
      "x": -3,
      "y": 3,
      "z": 1,
      "name": "Soil_Clay_White",
      "rotation": 33
    },
    {
      "x": -3,
      "y": 4,
      "z": 1,
      "name": "Soil_Clay_White",
      "rotation": 33
    },
    {
      "x": -3,
      "y": 5,
      "z": 1,
      "name": "Rock_Marble",
      "rotation": 33
    },
    {
      "x": -3,
      "y": 6,
      "z": 1,
      "name": "Rock_Marble",
      "rotation": 33
    },
    {
      "x": -3,
      "y": 7,
      "z": 1,
      "name": "Soil_Clay_White",
      "rotation": 33
    },
    {
      "x": -3,
      "y": 8,
      "z": 1,
      "name": "Rock_Marble_Cobble",
      "rotation": 33
    },
    {
      "x": -3,
      "y": 2,
      "z": 2,
      "name": "Rock_Marble",
      "rotation": 33
    },
    {
      "x": -3,
      "y": 3,
      "z": 2,
      "name": "Soil_Clay_White",
      "rotation": 33
    },
    {
      "x": -3,
      "y": 4,
      "z": 2,
      "name": "Soil_Clay_White",
      "rotation": 33
    },
    {
      "x": -3,
      "y": 5,
      "z": 2,
      "name": "Rock_Marble",
      "rotation": 33
    },
    {
      "x": -3,
      "y": 6,
      "z": 2,
      "name": "Rock_Marble",
      "rotation": 33
    },
    {
      "x": -3,
      "y": 7,
      "z": 2,
      "name": "Soil_Clay_White",
      "rotation": 33
    },
    {
      "x": -3,
      "y": 8,
      "z": 2,
      "name": "Rock_Marble_Cobble",
      "rotation": 33
    },
    {
      "x": -3,
      "y": 3,
      "z": 3,
      "name": "Soil_Clay_White",
      "rotation": 33
    },
    {
      "x": -3,
      "y": 4,
      "z": 3,
      "name": "Soil_Clay_White",
      "rotation": 33
    },
    {
      "x": -3,
      "y": 5,
      "z": 3,
      "name": "Rock_Marble",
      "rotation": 33
    },
    {
      "x": -3,
      "y": 6,
      "z": 3,
      "name": "Rock_Marble",
      "rotation": 33
    },
    {
      "x": -3,
      "y": 7,
      "z": 3,
      "name": "Soil_Clay_White",
      "rotation": 33
    },
    {
      "x": -3,
      "y": 8,
      "z": 3,
      "name": "Rock_Marble_Cobble",
      "rotation": 33
    },
    {
      "x": -3,
      "y": 4,
      "z": 4,
      "name": "Soil_Clay_White",
      "rotation": 33
    },
    {
      "x": -3,
      "y": 5,
      "z": 4,
      "name": "Rock_Marble",
      "rotation": 33
    },
    {
      "x": -3,
      "y": 6,
      "z": 4,
      "name": "Rock_Marble",
      "rotation": 33
    },
    {
      "x": -3,
      "y": 7,
      "z": 4,
      "name": "Soil_Clay_White",
      "rotation": 33
    },
    {
      "x": -2,
      "y": 4,
      "z": -4,
      "name": "Soil_Clay_White",
      "rotation": 33
    },
    {
      "x": -2,
      "y": 5,
      "z": -4,
      "name": "Rock_Marble",
      "rotation": 33
    },
    {
      "x": -2,
      "y": 6,
      "z": -4,
      "name": "Rock_Marble",
      "rotation": 33
    },
    {
      "x": -2,
      "y": 3,
      "z": -3,
      "name": "Soil_Clay_White",
      "rotation": 33
    },
    {
      "x": -2,
      "y": 4,
      "z": -3,
      "name": "Soil_Clay_White",
      "rotation": 33
    },
    {
      "x": -2,
      "y": 5,
      "z": -3,
      "name": "Rock_Marble",
      "rotation": 33
    },
    {
      "x": -2,
      "y": 6,
      "z": -3,
      "name": "Rock_Marble",
      "rotation": 33
    },
    {
      "x": -2,
      "y": 7,
      "z": -3,
      "name": "Soil_Clay_White",
      "rotation": 33
    },
    {
      "x": -2,
      "y": 2,
      "z": -2,
      "name": "Rock_Marble",
      "rotation": 33
    },
    {
      "x": -2,
      "y": 3,
      "z": -2,
      "name": "Soil_Clay_White",
      "rotation": 33
    },
    {
      "x": -2,
      "y": 4,
      "z": -2,
      "name": "Soil_Clay_White",
      "rotation": 33
    },
    {
      "x": -2,
      "y": 5,
      "z": -2,
      "name": "Rock_Marble",
      "rotation": 33
    },
    {
      "x": -2,
      "y": 6,
      "z": -2,
      "name": "Rock_Marble",
      "rotation": 33
    },
    {
      "x": -2,
      "y": 7,
      "z": -2,
      "name": "Soil_Clay_White",
      "rotation": 33
    },
    {
      "x": -2,
      "y": 8,
      "z": -2,
      "name": "Rock_Marble_Cobble",
      "rotation": 33
    },
    {
      "x": -2,
      "y": 2,
      "z": -1,
      "name": "Rock_Marble",
      "rotation": 33
    },
    {
      "x": -2,
      "y": 3,
      "z": -1,
      "name": "Soil_Clay_White",
      "rotation": 33
    },
    {
      "x": -2,
      "y": 4,
      "z": -1,
      "name": "Soil_Clay_White",
      "rotation": 33
    },
    {
      "x": -2,
      "y": 5,
      "z": -1,
      "name": "Rock_Marble",
      "rotation": 33
    },
    {
      "x": -2,
      "y": 6,
      "z": -1,
      "name": "Rock_Marble",
      "rotation": 33
    },
    {
      "x": -2,
      "y": 7,
      "z": -1,
      "name": "Soil_Clay_White",
      "rotation": 33
    },
    {
      "x": -2,
      "y": 8,
      "z": -1,
      "name": "Rock_Marble_Cobble",
      "rotation": 33
    },
    {
      "x": -2,
      "y": 1,
      "z": 0,
      "name": "Rock_Marble",
      "rotation": 33
    },
    {
      "x": -2,
      "y": 2,
      "z": 0,
      "name": "Rock_Marble",
      "rotation": 33
    },
    {
      "x": -2,
      "y": 3,
      "z": 0,
      "name": "Soil_Clay_White",
      "rotation": 33
    },
    {
      "x": -2,
      "y": 4,
      "z": 0,
      "name": "Soil_Clay_White",
      "rotation": 33
    },
    {
      "x": -2,
      "y": 5,
      "z": 0,
      "name": "Rock_Marble",
      "rotation": 33
    },
    {
      "x": -2,
      "y": 6,
      "z": 0,
      "name": "Rock_Marble",
      "rotation": 33
    },
    {
      "x": -2,
      "y": 7,
      "z": 0,
      "name": "Soil_Clay_White",
      "rotation": 33
    },
    {
      "x": -2,
      "y": 8,
      "z": 0,
      "name": "Rock_Marble_Cobble",
      "rotation": 33
    },
    {
      "x": -2,
      "y": 9,
      "z": 0,
      "name": "Rock_Marble",
      "rotation": 33
    },
    {
      "x": -2,
      "y": 1,
      "z": 1,
      "name": "Rock_Marble",
      "rotation": 33
    },
    {
      "x": -2,
      "y": 2,
      "z": 1,
      "name": "Rock_Marble",
      "rotation": 33
    },
    {
      "x": -2,
      "y": 3,
      "z": 1,
      "name": "Soil_Clay_White",
      "rotation": 33
    },
    {
      "x": -2,
      "y": 4,
      "z": 1,
      "name": "Soil_Clay_White",
      "rotation": 33
    },
    {
      "x": -2,
      "y": 5,
      "z": 1,
      "name": "Rock_Marble",
      "rotation": 33
    },
    {
      "x": -2,
      "y": 6,
      "z": 1,
      "name": "Rock_Marble",
      "rotation": 33
    },
    {
      "x": -2,
      "y": 7,
      "z": 1,
      "name": "Soil_Clay_White",
      "rotation": 33
    },
    {
      "x": -2,
      "y": 8,
      "z": 1,
      "name": "Rock_Marble_Cobble",
      "rotation": 33
    },
    {
      "x": -2,
      "y": 9,
      "z": 1,
      "name": "Rock_Marble",
      "rotation": 33
    },
    {
      "x": -2,
      "y": 2,
      "z": 2,
      "name": "Rock_Marble",
      "rotation": 33
    },
    {
      "x": -2,
      "y": 3,
      "z": 2,
      "name": "Soil_Clay_White",
      "rotation": 33
    },
    {
      "x": -2,
      "y": 4,
      "z": 2,
      "name": "Soil_Clay_White",
      "rotation": 33
    },
    {
      "x": -2,
      "y": 5,
      "z": 2,
      "name": "Rock_Marble",
      "rotation": 33
    },
    {
      "x": -2,
      "y": 6,
      "z": 2,
      "name": "Rock_Marble",
      "rotation": 33
    },
    {
      "x": -2,
      "y": 7,
      "z": 2,
      "name": "Soil_Clay_White",
      "rotation": 33
    },
    {
      "x": -2,
      "y": 8,
      "z": 2,
      "name": "Rock_Marble_Cobble",
      "rotation": 33
    },
    {
      "x": -2,
      "y": 9,
      "z": 2,
      "name": "Rock_Marble",
      "rotation": 33
    },
    {
      "x": -2,
      "y": 2,
      "z": 3,
      "name": "Rock_Marble",
      "rotation": 33
    },
    {
      "x": -2,
      "y": 3,
      "z": 3,
      "name": "Soil_Clay_White",
      "rotation": 33
    },
    {
      "x": -2,
      "y": 4,
      "z": 3,
      "name": "Soil_Clay_White",
      "rotation": 33
    },
    {
      "x": -2,
      "y": 5,
      "z": 3,
      "name": "Rock_Marble",
      "rotation": 33
    },
    {
      "x": -2,
      "y": 6,
      "z": 3,
      "name": "Rock_Marble",
      "rotation": 33
    },
    {
      "x": -2,
      "y": 7,
      "z": 3,
      "name": "Soil_Clay_White",
      "rotation": 33
    },
    {
      "x": -2,
      "y": 8,
      "z": 3,
      "name": "Rock_Marble_Cobble",
      "rotation": 33
    },
    {
      "x": -2,
      "y": 3,
      "z": 4,
      "name": "Soil_Clay_White",
      "rotation": 33
    },
    {
      "x": -2,
      "y": 4,
      "z": 4,
      "name": "Soil_Clay_White",
      "rotation": 33
    },
    {
      "x": -2,
      "y": 5,
      "z": 4,
      "name": "Rock_Marble",
      "rotation": 33
    },
    {
      "x": -2,
      "y": 6,
      "z": 4,
      "name": "Rock_Marble",
      "rotation": 33
    },
    {
      "x": -2,
      "y": 7,
      "z": 4,
      "name": "Soil_Clay_White",
      "rotation": 33
    },
    {
      "x": -2,
      "y": 5,
      "z": 5,
      "name": "Rock_Marble",
      "rotation": 33
    },
    {
      "x": -2,
      "y": 6,
      "z": 5,
      "name": "Rock_Marble",
      "rotation": 33
    },
    {
      "x": -1,
      "y": 4,
      "z": -4,
      "name": "Soil_Clay_White",
      "rotation": 33
    },
    {
      "x": -1,
      "y": 5,
      "z": -4,
      "name": "Rock_Marble",
      "rotation": 33
    },
    {
      "x": -1,
      "y": 6,
      "z": -4,
      "name": "Rock_Marble",
      "rotation": 33
    },
    {
      "x": -1,
      "y": 3,
      "z": -3,
      "name": "Soil_Clay_White",
      "rotation": 33
    },
    {
      "x": -1,
      "y": 4,
      "z": -3,
      "name": "Soil_Clay_White",
      "rotation": 33
    },
    {
      "x": -1,
      "y": 5,
      "z": -3,
      "name": "Rock_Marble",
      "rotation": 33
    },
    {
      "x": -1,
      "y": 6,
      "z": -3,
      "name": "Rock_Marble",
      "rotation": 33
    },
    {
      "x": -1,
      "y": 7,
      "z": -3,
      "name": "Soil_Clay_White",
      "rotation": 33
    },
    {
      "x": -1,
      "y": 2,
      "z": -2,
      "name": "Rock_Marble",
      "rotation": 33
    },
    {
      "x": -1,
      "y": 3,
      "z": -2,
      "name": "Soil_Clay_White",
      "rotation": 33
    },
    {
      "x": -1,
      "y": 4,
      "z": -2,
      "name": "Soil_Clay_White",
      "rotation": 33
    },
    {
      "x": -1,
      "y": 5,
      "z": -2,
      "name": "Rock_Marble",
      "rotation": 33
    },
    {
      "x": -1,
      "y": 6,
      "z": -2,
      "name": "Rock_Marble",
      "rotation": 33
    },
    {
      "x": -1,
      "y": 7,
      "z": -2,
      "name": "Soil_Clay_White",
      "rotation": 33
    },
    {
      "x": -1,
      "y": 8,
      "z": -2,
      "name": "Rock_Marble_Cobble",
      "rotation": 33
    },
    {
      "x": -1,
      "y": 1,
      "z": -1,
      "name": "Rock_Marble",
      "rotation": 33
    },
    {
      "x": -1,
      "y": 2,
      "z": -1,
      "name": "Rock_Marble",
      "rotation": 33
    },
    {
      "x": -1,
      "y": 3,
      "z": -1,
      "name": "Soil_Clay_White",
      "rotation": 33
    },
    {
      "x": -1,
      "y": 4,
      "z": -1,
      "name": "Soil_Clay_White",
      "rotation": 33
    },
    {
      "x": -1,
      "y": 5,
      "z": -1,
      "name": "Rock_Marble",
      "rotation": 33
    },
    {
      "x": -1,
      "y": 6,
      "z": -1,
      "name": "Rock_Marble",
      "rotation": 33
    },
    {
      "x": -1,
      "y": 7,
      "z": -1,
      "name": "Soil_Clay_White",
      "rotation": 33
    },
    {
      "x": -1,
      "y": 8,
      "z": -1,
      "name": "Rock_Marble_Cobble",
      "rotation": 33
    },
    {
      "x": -1,
      "y": 9,
      "z": -1,
      "name": "Rock_Marble",
      "rotation": 33
    },
    {
      "x": -1,
      "y": 1,
      "z": 0,
      "name": "Rock_Marble",
      "rotation": 33
    },
    {
      "x": -1,
      "y": 2,
      "z": 0,
      "name": "Rock_Marble",
      "rotation": 33
    },
    {
      "x": -1,
      "y": 3,
      "z": 0,
      "name": "Soil_Clay_White",
      "rotation": 33
    },
    {
      "x": -1,
      "y": 4,
      "z": 0,
      "name": "Soil_Clay_White",
      "rotation": 33
    },
    {
      "x": -1,
      "y": 5,
      "z": 0,
      "name": "Rock_Marble",
      "rotation": 33
    },
    {
      "x": -1,
      "y": 6,
      "z": 0,
      "name": "Rock_Marble",
      "rotation": 33
    },
    {
      "x": -1,
      "y": 7,
      "z": 0,
      "name": "Soil_Clay_White",
      "rotation": 33
    },
    {
      "x": -1,
      "y": 8,
      "z": 0,
      "name": "Rock_Marble_Cobble",
      "rotation": 33
    },
    {
      "x": -1,
      "y": 9,
      "z": 0,
      "name": "Rock_Marble",
      "rotation": 33
    },
    {
      "x": -1,
      "y": 1,
      "z": 1,
      "name": "Rock_Marble",
      "rotation": 33
    },
    {
      "x": -1,
      "y": 2,
      "z": 1,
      "name": "Rock_Marble",
      "rotation": 33
    },
    {
      "x": -1,
      "y": 3,
      "z": 1,
      "name": "Soil_Clay_White",
      "rotation": 33
    },
    {
      "x": -1,
      "y": 4,
      "z": 1,
      "name": "Soil_Clay_White",
      "rotation": 33
    },
    {
      "x": -1,
      "y": 5,
      "z": 1,
      "name": "Rock_Marble",
      "rotation": 33
    },
    {
      "x": -1,
      "y": 6,
      "z": 1,
      "name": "Rock_Marble",
      "rotation": 33
    },
    {
      "x": -1,
      "y": 7,
      "z": 1,
      "name": "Soil_Clay_White",
      "rotation": 33
    },
    {
      "x": -1,
      "y": 8,
      "z": 1,
      "name": "Rock_Marble_Cobble",
      "rotation": 33
    },
    {
      "x": -1,
      "y": 9,
      "z": 1,
      "name": "Rock_Marble",
      "rotation": 33
    },
    {
      "x": -1,
      "y": 2,
      "z": 2,
      "name": "Rock_Marble",
      "rotation": 33
    },
    {
      "x": -1,
      "y": 3,
      "z": 2,
      "name": "Soil_Clay_White",
      "rotation": 33
    },
    {
      "x": -1,
      "y": 4,
      "z": 2,
      "name": "Soil_Clay_White",
      "rotation": 33
    },
    {
      "x": -1,
      "y": 5,
      "z": 2,
      "name": "Rock_Marble",
      "rotation": 33
    },
    {
      "x": -1,
      "y": 6,
      "z": 2,
      "name": "Rock_Marble",
      "rotation": 33
    },
    {
      "x": -1,
      "y": 7,
      "z": 2,
      "name": "Soil_Clay_White",
      "rotation": 33
    },
    {
      "x": -1,
      "y": 8,
      "z": 2,
      "name": "Rock_Marble_Cobble",
      "rotation": 33
    },
    {
      "x": -1,
      "y": 9,
      "z": 2,
      "name": "Rock_Marble",
      "rotation": 33
    },
    {
      "x": -1,
      "y": 2,
      "z": 3,
      "name": "Rock_Marble",
      "rotation": 33
    },
    {
      "x": -1,
      "y": 3,
      "z": 3,
      "name": "Soil_Clay_White",
      "rotation": 33
    },
    {
      "x": -1,
      "y": 4,
      "z": 3,
      "name": "Soil_Clay_White",
      "rotation": 33
    },
    {
      "x": -1,
      "y": 5,
      "z": 3,
      "name": "Rock_Marble",
      "rotation": 33
    },
    {
      "x": -1,
      "y": 6,
      "z": 3,
      "name": "Rock_Marble",
      "rotation": 33
    },
    {
      "x": -1,
      "y": 7,
      "z": 3,
      "name": "Soil_Clay_White",
      "rotation": 33
    },
    {
      "x": -1,
      "y": 8,
      "z": 3,
      "name": "Rock_Marble_Cobble",
      "rotation": 33
    },
    {
      "x": -1,
      "y": 9,
      "z": 3,
      "name": "Rock_Marble",
      "rotation": 33
    },
    {
      "x": -1,
      "y": 3,
      "z": 4,
      "name": "Soil_Clay_White",
      "rotation": 33
    },
    {
      "x": -1,
      "y": 4,
      "z": 4,
      "name": "Soil_Clay_White",
      "rotation": 33
    },
    {
      "x": -1,
      "y": 5,
      "z": 4,
      "name": "Rock_Marble",
      "rotation": 33
    },
    {
      "x": -1,
      "y": 6,
      "z": 4,
      "name": "Rock_Marble",
      "rotation": 33
    },
    {
      "x": -1,
      "y": 7,
      "z": 4,
      "name": "Soil_Clay_White",
      "rotation": 33
    },
    {
      "x": -1,
      "y": 8,
      "z": 4,
      "name": "Rock_Marble_Cobble",
      "rotation": 33
    },
    {
      "x": -1,
      "y": 4,
      "z": 5,
      "name": "Soil_Clay_White",
      "rotation": 33
    },
    {
      "x": -1,
      "y": 5,
      "z": 5,
      "name": "Rock_Marble",
      "rotation": 33
    },
    {
      "x": -1,
      "y": 6,
      "z": 5,
      "name": "Rock_Marble",
      "rotation": 33
    },
    {
      "x": 0,
      "y": 5,
      "z": -4,
      "name": "Rock_Marble",
      "rotation": 33
    },
    {
      "x": 0,
      "y": 3,
      "z": -3,
      "name": "Soil_Clay_White",
      "rotation": 33
    },
    {
      "x": 0,
      "y": 4,
      "z": -3,
      "name": "Soil_Clay_White",
      "rotation": 33
    },
    {
      "x": 0,
      "y": 5,
      "z": -3,
      "name": "Rock_Marble",
      "rotation": 33
    },
    {
      "x": 0,
      "y": 6,
      "z": -3,
      "name": "Rock_Marble",
      "rotation": 33
    },
    {
      "x": 0,
      "y": 7,
      "z": -3,
      "name": "Soil_Clay_White",
      "rotation": 33
    },
    {
      "x": 0,
      "y": 2,
      "z": -2,
      "name": "Rock_Marble",
      "rotation": 33
    },
    {
      "x": 0,
      "y": 3,
      "z": -2,
      "name": "Soil_Clay_White",
      "rotation": 33
    },
    {
      "x": 0,
      "y": 4,
      "z": -2,
      "name": "Soil_Clay_White",
      "rotation": 33
    },
    {
      "x": 0,
      "y": 5,
      "z": -2,
      "name": "Rock_Marble",
      "rotation": 33
    },
    {
      "x": 0,
      "y": 6,
      "z": -2,
      "name": "Rock_Marble",
      "rotation": 33
    },
    {
      "x": 0,
      "y": 7,
      "z": -2,
      "name": "Soil_Clay_White",
      "rotation": 33
    },
    {
      "x": 0,
      "y": 8,
      "z": -2,
      "name": "Rock_Marble_Cobble",
      "rotation": 33
    },
    {
      "x": 0,
      "y": 2,
      "z": -1,
      "name": "Rock_Marble",
      "rotation": 33
    },
    {
      "x": 0,
      "y": 3,
      "z": -1,
      "name": "Soil_Clay_White",
      "rotation": 33
    },
    {
      "x": 0,
      "y": 4,
      "z": -1,
      "name": "Soil_Clay_White",
      "rotation": 33
    },
    {
      "x": 0,
      "y": 5,
      "z": -1,
      "name": "Rock_Marble",
      "rotation": 33
    },
    {
      "x": 0,
      "y": 6,
      "z": -1,
      "name": "Rock_Marble",
      "rotation": 33
    },
    {
      "x": 0,
      "y": 7,
      "z": -1,
      "name": "Soil_Clay_White",
      "rotation": 33
    },
    {
      "x": 0,
      "y": 8,
      "z": -1,
      "name": "Rock_Marble_Cobble",
      "rotation": 33
    },
    {
      "x": 0,
      "y": 9,
      "z": -1,
      "name": "Rock_Marble",
      "rotation": 33
    },
    {
      "x": 0,
      "y": 1,
      "z": 0,
      "name": "Rock_Marble",
      "rotation": 33
    },
    {
      "x": 0,
      "y": 2,
      "z": 0,
      "name": "Rock_Marble",
      "rotation": 33
    },
    {
      "x": 0,
      "y": 3,
      "z": 0,
      "name": "Soil_Clay_White",
      "rotation": 33
    },
    {
      "x": 0,
      "y": 4,
      "z": 0,
      "name": "Soil_Clay_White",
      "rotation": 33
    },
    {
      "x": 0,
      "y": 5,
      "z": 0,
      "name": "Rock_Marble",
      "rotation": 33
    },
    {
      "x": 0,
      "y": 6,
      "z": 0,
      "name": "Rock_Marble",
      "rotation": 33
    },
    {
      "x": 0,
      "y": 7,
      "z": 0,
      "name": "Soil_Clay_White",
      "rotation": 33
    },
    {
      "x": 0,
      "y": 8,
      "z": 0,
      "name": "Rock_Marble_Cobble",
      "rotation": 33
    },
    {
      "x": 0,
      "y": 9,
      "z": 0,
      "name": "Rock_Marble",
      "rotation": 33
    },
    {
      "x": 0,
      "y": 1,
      "z": 1,
      "name": "Rock_Marble",
      "rotation": 33
    },
    {
      "x": 0,
      "y": 2,
      "z": 1,
      "name": "Rock_Marble",
      "rotation": 33
    },
    {
      "x": 0,
      "y": 3,
      "z": 1,
      "name": "Soil_Clay_White",
      "rotation": 33
    },
    {
      "x": 0,
      "y": 4,
      "z": 1,
      "name": "Soil_Clay_White",
      "rotation": 33
    },
    {
      "x": 0,
      "y": 5,
      "z": 1,
      "name": "Rock_Marble",
      "rotation": 33
    },
    {
      "x": 0,
      "y": 6,
      "z": 1,
      "name": "Rock_Marble",
      "rotation": 33
    },
    {
      "x": 0,
      "y": 7,
      "z": 1,
      "name": "Soil_Clay_White",
      "rotation": 33
    },
    {
      "x": 0,
      "y": 8,
      "z": 1,
      "name": "Rock_Marble_Cobble",
      "rotation": 33
    },
    {
      "x": 0,
      "y": 9,
      "z": 1,
      "name": "Rock_Marble",
      "rotation": 33
    },
    {
      "x": 0,
      "y": 2,
      "z": 2,
      "name": "Rock_Marble",
      "rotation": 33
    },
    {
      "x": 0,
      "y": 3,
      "z": 2,
      "name": "Soil_Clay_White",
      "rotation": 33
    },
    {
      "x": 0,
      "y": 4,
      "z": 2,
      "name": "Soil_Clay_White",
      "rotation": 33
    },
    {
      "x": 0,
      "y": 5,
      "z": 2,
      "name": "Rock_Marble",
      "rotation": 33
    },
    {
      "x": 0,
      "y": 6,
      "z": 2,
      "name": "Rock_Marble",
      "rotation": 33
    },
    {
      "x": 0,
      "y": 7,
      "z": 2,
      "name": "Soil_Clay_White",
      "rotation": 33
    },
    {
      "x": 0,
      "y": 8,
      "z": 2,
      "name": "Rock_Marble_Cobble",
      "rotation": 33
    },
    {
      "x": 0,
      "y": 9,
      "z": 2,
      "name": "Rock_Marble",
      "rotation": 33
    },
    {
      "x": 0,
      "y": 2,
      "z": 3,
      "name": "Rock_Marble",
      "rotation": 33
    },
    {
      "x": 0,
      "y": 3,
      "z": 3,
      "name": "Soil_Clay_White",
      "rotation": 33
    },
    {
      "x": 0,
      "y": 4,
      "z": 3,
      "name": "Soil_Clay_White",
      "rotation": 33
    },
    {
      "x": 0,
      "y": 5,
      "z": 3,
      "name": "Rock_Marble",
      "rotation": 33
    },
    {
      "x": 0,
      "y": 6,
      "z": 3,
      "name": "Rock_Marble",
      "rotation": 33
    },
    {
      "x": 0,
      "y": 7,
      "z": 3,
      "name": "Soil_Clay_White",
      "rotation": 33
    },
    {
      "x": 0,
      "y": 8,
      "z": 3,
      "name": "Rock_Marble_Cobble",
      "rotation": 33
    },
    {
      "x": 0,
      "y": 9,
      "z": 3,
      "name": "Rock_Marble",
      "rotation": 33
    },
    {
      "x": 0,
      "y": 3,
      "z": 4,
      "name": "Soil_Clay_White",
      "rotation": 33
    },
    {
      "x": 0,
      "y": 4,
      "z": 4,
      "name": "Soil_Clay_White",
      "rotation": 33
    },
    {
      "x": 0,
      "y": 5,
      "z": 4,
      "name": "Rock_Marble",
      "rotation": 33
    },
    {
      "x": 0,
      "y": 6,
      "z": 4,
      "name": "Rock_Marble",
      "rotation": 33
    },
    {
      "x": 0,
      "y": 7,
      "z": 4,
      "name": "Soil_Clay_White",
      "rotation": 33
    },
    {
      "x": 0,
      "y": 8,
      "z": 4,
      "name": "Rock_Marble_Cobble",
      "rotation": 33
    },
    {
      "x": 0,
      "y": 5,
      "z": 5,
      "name": "Rock_Marble",
      "rotation": 33
    },
    {
      "x": 0,
      "y": 6,
      "z": 5,
      "name": "Rock_Marble",
      "rotation": 33
    },
    {
      "x": 1,
      "y": 4,
      "z": -3,
      "name": "Soil_Clay_White",
      "rotation": 33
    },
    {
      "x": 1,
      "y": 5,
      "z": -3,
      "name": "Rock_Marble",
      "rotation": 33
    },
    {
      "x": 1,
      "y": 6,
      "z": -3,
      "name": "Rock_Marble",
      "rotation": 33
    },
    {
      "x": 1,
      "y": 7,
      "z": -3,
      "name": "Soil_Clay_White",
      "rotation": 33
    },
    {
      "x": 1,
      "y": 3,
      "z": -2,
      "name": "Soil_Clay_White",
      "rotation": 33
    },
    {
      "x": 1,
      "y": 4,
      "z": -2,
      "name": "Soil_Clay_White",
      "rotation": 33
    },
    {
      "x": 1,
      "y": 5,
      "z": -2,
      "name": "Rock_Marble",
      "rotation": 33
    },
    {
      "x": 1,
      "y": 6,
      "z": -2,
      "name": "Rock_Marble",
      "rotation": 33
    },
    {
      "x": 1,
      "y": 7,
      "z": -2,
      "name": "Soil_Clay_White",
      "rotation": 33
    },
    {
      "x": 1,
      "y": 2,
      "z": -1,
      "name": "Rock_Marble",
      "rotation": 33
    },
    {
      "x": 1,
      "y": 3,
      "z": -1,
      "name": "Soil_Clay_White",
      "rotation": 33
    },
    {
      "x": 1,
      "y": 4,
      "z": -1,
      "name": "Soil_Clay_White",
      "rotation": 33
    },
    {
      "x": 1,
      "y": 5,
      "z": -1,
      "name": "Rock_Marble",
      "rotation": 33
    },
    {
      "x": 1,
      "y": 6,
      "z": -1,
      "name": "Rock_Marble",
      "rotation": 33
    },
    {
      "x": 1,
      "y": 7,
      "z": -1,
      "name": "Soil_Clay_White",
      "rotation": 33
    },
    {
      "x": 1,
      "y": 8,
      "z": -1,
      "name": "Rock_Marble_Cobble",
      "rotation": 33
    },
    {
      "x": 1,
      "y": 2,
      "z": 0,
      "name": "Rock_Marble",
      "rotation": 33
    },
    {
      "x": 1,
      "y": 3,
      "z": 0,
      "name": "Soil_Clay_White",
      "rotation": 33
    },
    {
      "x": 1,
      "y": 4,
      "z": 0,
      "name": "Soil_Clay_White",
      "rotation": 33
    },
    {
      "x": 1,
      "y": 5,
      "z": 0,
      "name": "Rock_Marble",
      "rotation": 33
    },
    {
      "x": 1,
      "y": 6,
      "z": 0,
      "name": "Rock_Marble",
      "rotation": 33
    },
    {
      "x": 1,
      "y": 7,
      "z": 0,
      "name": "Soil_Clay_White",
      "rotation": 33
    },
    {
      "x": 1,
      "y": 8,
      "z": 0,
      "name": "Rock_Marble_Cobble",
      "rotation": 33
    },
    {
      "x": 1,
      "y": 9,
      "z": 0,
      "name": "Rock_Marble",
      "rotation": 33
    },
    {
      "x": 1,
      "y": 2,
      "z": 1,
      "name": "Rock_Marble",
      "rotation": 33
    },
    {
      "x": 1,
      "y": 3,
      "z": 1,
      "name": "Soil_Clay_White",
      "rotation": 33
    },
    {
      "x": 1,
      "y": 4,
      "z": 1,
      "name": "Soil_Clay_White",
      "rotation": 33
    },
    {
      "x": 1,
      "y": 5,
      "z": 1,
      "name": "Rock_Marble",
      "rotation": 33
    },
    {
      "x": 1,
      "y": 6,
      "z": 1,
      "name": "Rock_Marble",
      "rotation": 33
    },
    {
      "x": 1,
      "y": 7,
      "z": 1,
      "name": "Soil_Clay_White",
      "rotation": 33
    },
    {
      "x": 1,
      "y": 8,
      "z": 1,
      "name": "Rock_Marble_Cobble",
      "rotation": 33
    },
    {
      "x": 1,
      "y": 9,
      "z": 1,
      "name": "Rock_Marble",
      "rotation": 33
    },
    {
      "x": 1,
      "y": 2,
      "z": 2,
      "name": "Rock_Marble",
      "rotation": 33
    },
    {
      "x": 1,
      "y": 3,
      "z": 2,
      "name": "Soil_Clay_White",
      "rotation": 33
    },
    {
      "x": 1,
      "y": 4,
      "z": 2,
      "name": "Soil_Clay_White",
      "rotation": 33
    },
    {
      "x": 1,
      "y": 5,
      "z": 2,
      "name": "Rock_Marble",
      "rotation": 33
    },
    {
      "x": 1,
      "y": 6,
      "z": 2,
      "name": "Rock_Marble",
      "rotation": 33
    },
    {
      "x": 1,
      "y": 7,
      "z": 2,
      "name": "Soil_Clay_White",
      "rotation": 33
    },
    {
      "x": 1,
      "y": 8,
      "z": 2,
      "name": "Rock_Marble_Cobble",
      "rotation": 33
    },
    {
      "x": 1,
      "y": 3,
      "z": 3,
      "name": "Soil_Clay_White",
      "rotation": 33
    },
    {
      "x": 1,
      "y": 4,
      "z": 3,
      "name": "Soil_Clay_White",
      "rotation": 33
    },
    {
      "x": 1,
      "y": 5,
      "z": 3,
      "name": "Rock_Marble",
      "rotation": 33
    },
    {
      "x": 1,
      "y": 6,
      "z": 3,
      "name": "Rock_Marble",
      "rotation": 33
    },
    {
      "x": 1,
      "y": 7,
      "z": 3,
      "name": "Soil_Clay_White",
      "rotation": 33
    },
    {
      "x": 1,
      "y": 8,
      "z": 3,
      "name": "Rock_Marble_Cobble",
      "rotation": 33
    },
    {
      "x": 1,
      "y": 4,
      "z": 4,
      "name": "Soil_Clay_White",
      "rotation": 33
    },
    {
      "x": 1,
      "y": 5,
      "z": 4,
      "name": "Rock_Marble",
      "rotation": 33
    },
    {
      "x": 1,
      "y": 6,
      "z": 4,
      "name": "Rock_Marble",
      "rotation": 33
    },
    {
      "x": 1,
      "y": 7,
      "z": 4,
      "name": "Soil_Clay_White",
      "rotation": 33
    },
    {
      "x": 2,
      "y": 3,
      "z": -2,
      "name": "Soil_Clay_White",
      "rotation": 33
    },
    {
      "x": 2,
      "y": 4,
      "z": -2,
      "name": "Soil_Clay_White",
      "rotation": 33
    },
    {
      "x": 2,
      "y": 5,
      "z": -2,
      "name": "Rock_Marble",
      "rotation": 33
    },
    {
      "x": 2,
      "y": 6,
      "z": -2,
      "name": "Rock_Marble",
      "rotation": 33
    },
    {
      "x": 2,
      "y": 7,
      "z": -2,
      "name": "Soil_Clay_White",
      "rotation": 33
    },
    {
      "x": 2,
      "y": 2,
      "z": -1,
      "name": "Rock_Marble",
      "rotation": 33
    },
    {
      "x": 2,
      "y": 3,
      "z": -1,
      "name": "Soil_Clay_White",
      "rotation": 33
    },
    {
      "x": 2,
      "y": 4,
      "z": -1,
      "name": "Soil_Clay_White",
      "rotation": 33
    },
    {
      "x": 2,
      "y": 5,
      "z": -1,
      "name": "Rock_Marble",
      "rotation": 33
    },
    {
      "x": 2,
      "y": 6,
      "z": -1,
      "name": "Rock_Marble",
      "rotation": 33
    },
    {
      "x": 2,
      "y": 7,
      "z": -1,
      "name": "Soil_Clay_White",
      "rotation": 33
    },
    {
      "x": 2,
      "y": 2,
      "z": 0,
      "name": "Rock_Marble",
      "rotation": 33
    },
    {
      "x": 2,
      "y": 3,
      "z": 0,
      "name": "Soil_Clay_White",
      "rotation": 33
    },
    {
      "x": 2,
      "y": 4,
      "z": 0,
      "name": "Soil_Clay_White",
      "rotation": 33
    },
    {
      "x": 2,
      "y": 5,
      "z": 0,
      "name": "Rock_Marble",
      "rotation": 33
    },
    {
      "x": 2,
      "y": 6,
      "z": 0,
      "name": "Rock_Marble",
      "rotation": 33
    },
    {
      "x": 2,
      "y": 7,
      "z": 0,
      "name": "Soil_Clay_White",
      "rotation": 33
    },
    {
      "x": 2,
      "y": 8,
      "z": 0,
      "name": "Rock_Marble_Cobble",
      "rotation": 33
    },
    {
      "x": 2,
      "y": 2,
      "z": 1,
      "name": "Rock_Marble",
      "rotation": 33
    },
    {
      "x": 2,
      "y": 3,
      "z": 1,
      "name": "Soil_Clay_White",
      "rotation": 33
    },
    {
      "x": 2,
      "y": 4,
      "z": 1,
      "name": "Soil_Clay_White",
      "rotation": 33
    },
    {
      "x": 2,
      "y": 5,
      "z": 1,
      "name": "Rock_Marble",
      "rotation": 33
    },
    {
      "x": 2,
      "y": 6,
      "z": 1,
      "name": "Rock_Marble",
      "rotation": 33
    },
    {
      "x": 2,
      "y": 7,
      "z": 1,
      "name": "Soil_Clay_White",
      "rotation": 33
    },
    {
      "x": 2,
      "y": 8,
      "z": 1,
      "name": "Rock_Marble_Cobble",
      "rotation": 33
    },
    {
      "x": 2,
      "y": 3,
      "z": 2,
      "name": "Soil_Clay_White",
      "rotation": 33
    },
    {
      "x": 2,
      "y": 4,
      "z": 2,
      "name": "Soil_Clay_White",
      "rotation": 33
    },
    {
      "x": 2,
      "y": 5,
      "z": 2,
      "name": "Rock_Marble",
      "rotation": 33
    },
    {
      "x": 2,
      "y": 6,
      "z": 2,
      "name": "Rock_Marble",
      "rotation": 33
    },
    {
      "x": 2,
      "y": 7,
      "z": 2,
      "name": "Soil_Clay_White",
      "rotation": 33
    },
    {
      "x": 2,
      "y": 8,
      "z": 2,
      "name": "Rock_Marble_Cobble",
      "rotation": 33
    },
    {
      "x": 2,
      "y": 4,
      "z": 3,
      "name": "Soil_Clay_White",
      "rotation": 33
    },
    {
      "x": 2,
      "y": 5,
      "z": 3,
      "name": "Rock_Marble",
      "rotation": 33
    },
    {
      "x": 2,
      "y": 6,
      "z": 3,
      "name": "Rock_Marble",
      "rotation": 33
    },
    {
      "x": 2,
      "y": 7,
      "z": 3,
      "name": "Soil_Clay_White",
      "rotation": 33
    },
    {
      "x": 3,
      "y": 5,
      "z": -2,
      "name": "Rock_Marble",
      "rotation": 33
    },
    {
      "x": 3,
      "y": 3,
      "z": -1,
      "name": "Soil_Clay_White",
      "rotation": 33
    },
    {
      "x": 3,
      "y": 4,
      "z": -1,
      "name": "Soil_Clay_White",
      "rotation": 33
    },
    {
      "x": 3,
      "y": 5,
      "z": -1,
      "name": "Rock_Marble",
      "rotation": 33
    },
    {
      "x": 3,
      "y": 6,
      "z": -1,
      "name": "Rock_Marble",
      "rotation": 33
    },
    {
      "x": 3,
      "y": 3,
      "z": 0,
      "name": "Soil_Clay_White",
      "rotation": 33
    },
    {
      "x": 3,
      "y": 4,
      "z": 0,
      "name": "Soil_Clay_White",
      "rotation": 33
    },
    {
      "x": 3,
      "y": 5,
      "z": 0,
      "name": "Rock_Marble",
      "rotation": 33
    },
    {
      "x": 3,
      "y": 6,
      "z": 0,
      "name": "Rock_Marble",
      "rotation": 33
    },
    {
      "x": 3,
      "y": 7,
      "z": 0,
      "name": "Soil_Clay_White",
      "rotation": 33
    },
    {
      "x": 3,
      "y": 3,
      "z": 1,
      "name": "Soil_Clay_White",
      "rotation": 33
    },
    {
      "x": 3,
      "y": 4,
      "z": 1,
      "name": "Soil_Clay_White",
      "rotation": 33
    },
    {
      "x": 3,
      "y": 5,
      "z": 1,
      "name": "Rock_Marble",
      "rotation": 33
    },
    {
      "x": 3,
      "y": 6,
      "z": 1,
      "name": "Rock_Marble",
      "rotation": 33
    },
    {
      "x": 3,
      "y": 7,
      "z": 1,
      "name": "Soil_Clay_White",
      "rotation": 33
    },
    {
      "x": 3,
      "y": 4,
      "z": 2,
      "name": "Soil_Clay_White",
      "rotation": 33
    },
    {
      "x": 3,
      "y": 5,
      "z": 2,
      "name": "Rock_Marble",
      "rotation": 33
    },
    {
      "x": 3,
      "y": 6,
      "z": 2,
      "name": "Rock_Marble",
      "rotation": 33
    },
    {
      "x": 4,
      "y": 4,
      "z": 0,
      "name": "Soil_Clay_White",
      "rotation": 33
    },
    {
      "x": 4,
      "y": 5,
      "z": 0,
      "name": "Rock_Marble",
      "rotation": 33
    }
  ]
}