{
  "anchorX": 0,
  "anchorY": 0,
  "anchorZ": -1,
  "blockIdVersion": 11,
  "blocks": [
    {
      "name": "Soil_Dirt",
      "x": -6,
      "y": 1,
      "z": 1
    },
    {
      "name": "Soil_Dirt",
      "x": -6,
      "y": 2,
      "z": 1
    },
    {
      "name": "Soil_Dirt",
      "x": -6,
      "y": 1,
      "z": 2
    },
    {
      "name": "Soil_Dirt",
      "x": -6,
      "y": 2,
      "z": 2
    },
    {
      "name": "Soil_Dirt",
      "x": -6,
      "y": 1,
      "z": 3
    },
    {
      "name": "Soil_Dirt",
      "x": -6,
      "y": 2,
      "z": 3
    },
    {
      "name": "Soil_Dirt",
      "x": -6,
      "y": 1,
      "z": 4
    },
    {
      "name": "Soil_Dirt",
      "x": -6,
      "y": 2,
      "z": 4
    },
    {
      "name": "Soil_Dirt",
      "x": -6,
      "y": 1,
      "z": 5
    },
    {
      "name": "Soil_Dirt",
      "x": -6,
      "y": 2,
      "z": 5
    },
    {
      "name": "Soil_Dirt",
      "x": -5,
      "y": 1,
      "z": -5
    },
    {
      "name": "Soil_Dirt",
      "x": -5,
      "y": 2,
      "z": -5
    },
    {
      "name": "Soil_Dirt",
      "x": -5,
      "y": 1,
      "z": -4
    },
    {
      "name": "Soil_Dirt",
      "x": -5,
      "y": 2,
      "z": -4
    },
    {
      "name": "Soil_Dirt",
      "x": -5,
      "y": 1,
      "z": -3
    },
    {
      "name": "Soil_Dirt",
      "x": -5,
      "y": 2,
      "z": -3
    },
    {
      "name": "Soil_Dirt",
      "x": -5,
      "y": 1,
      "z": -2
    },
    {
      "name": "Soil_Dirt",
      "x": -5,
      "y": 2,
      "z": -2
    },
    {
      "name": "Soil_Dirt",
      "x": -5,
      "y": 1,
      "z": -1
    },
    {
      "name": "Soil_Dirt",
      "x": -5,
      "y": 2,
      "z": -1
    },
    {
      "name": "Soil_Dirt",
      "x": -5,
      "y": 1,
      "z": 0
    },
    {
      "name": "Soil_Dirt",
      "x": -5,
      "y": 2,
      "z": 0
    },
    {
      "name": "Soil_Dirt",
      "x": -5,
      "y": -1,
      "z": 1
    },
    {
      "name": "Soil_Grass",
      "x": -5,
      "y": 0,
      "z": 1
    },
    {
      "name": "Soil_Dirt",
      "x": -5,
      "y": 1,
      "z": 1
    },
    {
      "name": "Soil_Dirt",
      "x": -5,
      "y": 2,
      "z": 1
    },
    {
      "name": "Soil_Dirt",
      "x": -5,
      "y": -1,
      "z": 2
    },
    {
      "name": "Soil_Grass",
      "x": -5,
      "y": 0,
      "z": 2
    },
    {
      "name": "Empty",
      "x": -5,
      "y": 1,
      "z": 2
    },
    {
      "name": "Empty",
      "x": -5,
      "y": 2,
      "z": 2
    },
    {
      "name": "Empty",
      "x": -5,
      "y": 3,
      "z": 2
    },
    {
      "name": "Soil_Dirt",
      "x": -5,
      "y": -1,
      "z": 3
    },
    {
      "name": "Soil_Grass",
      "x": -5,
      "y": 0,
      "z": 3
    },
    {
      "name": "Empty",
      "x": -5,
      "y": 1,
      "z": 3
    },
    {
      "name": "Empty",
      "x": -5,
      "y": 2,
      "z": 3
    },
    {
      "name": "Empty",
      "x": -5,
      "y": 3,
      "z": 3
    },
    {
      "name": "Soil_Dirt",
      "x": -5,
      "y": -1,
      "z": 4
    },
    {
      "name": "Soil_Grass",
      "x": -5,
      "y": 0,
      "z": 4
    },
    {
      "name": "Empty",
      "x": -5,
      "y": 1,
      "z": 4
    },
    {
      "name": "Empty",
      "x": -5,
      "y": 2,
      "z": 4
    },
    {
      "name": "Empty",
      "x": -5,
      "y": 3,
      "z": 4
    },
    {
      "name": "Soil_Dirt",
      "x": -5,
      "y": -1,
      "z": 5
    },
    {
      "name": "Soil_Grass",
      "x": -5,
      "y": 0,
      "z": 5
    },
    {
      "name": "Empty",
      "x": -5,
      "y": 1,
      "z": 5
    },
    {
      "name": "Empty",
      "x": -5,
      "y": 2,
      "z": 5
    },
    {
      "name": "Empty",
      "x": -5,
      "y": 3,
      "z": 5
    },
    {
      "name": "Soil_Dirt",
      "x": -5,
      "y": -1,
      "z": 6
    },
    {
      "name": "Soil_Grass",
      "x": -5,
      "y": 0,
      "z": 6
    },
    {
      "name": "Soil_Dirt",
      "x": -5,
      "y": 1,
      "z": 6
    },
    {
      "name": "Soil_Dirt",
      "x": -5,
      "y": 2,
      "z": 6
    },
    {
      "name": "Soil_Dirt",
      "x": -5,
      "y": 1,
      "z": 7
    },
    {
      "name": "Soil_Dirt",
      "x": -5,
      "y": 2,
      "z": 7
    },
    {
      "name": "Soil_Dirt",
      "x": -4,
      "y": 1,
      "z": -7
    },
    {
      "name": "Soil_Dirt",
      "x": -4,
      "y": 2,
      "z": -7
    },
    {
      "name": "Soil_Dirt",
      "x": -4,
      "y": 1,
      "z": -6
    },
    {
      "name": "Soil_Dirt",
      "x": -4,
      "y": 2,
      "z": -6
    },
    {
      "name": "Soil_Dirt",
      "x": -4,
      "y": -1,
      "z": -5
    },
    {
      "name": "Soil_Grass",
      "x": -4,
      "y": 0,
      "z": -5
    },
    {
      "name": "Soil_Dirt",
      "x": -4,
      "y": 1,
      "z": -5
    },
    {
      "name": "Soil_Dirt",
      "x": -4,
      "y": 2,
      "z": -5
    },
    {
      "name": "Soil_Dirt",
      "x": -4,
      "y": -1,
      "z": -4
    },
    {
      "name": "Soil_Grass",
      "x": -4,
      "y": 0,
      "z": -4
    },
    {
      "name": "Soil_Dirt",
      "x": -4,
      "y": 1,
      "z": -4
    },
    {
      "name": "Soil_Dirt",
      "x": -4,
      "y": 2,
      "z": -4
    },
    {
      "name": "Soil_Dirt",
      "x": -4,
      "y": -1,
      "z": -3
    },
    {
      "name": "Soil_Grass",
      "x": -4,
      "y": 0,
      "z": -3
    },
    {
      "name": "Empty",
      "x": -4,
      "y": 1,
      "z": -3
    },
    {
      "name": "Empty",
      "x": -4,
      "y": 2,
      "z": -3
    },
    {
      "name": "Empty",
      "x": -4,
      "y": 3,
      "z": -3
    },
    {
      "name": "Soil_Dirt",
      "x": -4,
      "y": -1,
      "z": -2
    },
    {
      "name": "Soil_Grass",
      "x": -4,
      "y": 0,
      "z": -2
    },
    {
      "name": "Empty",
      "x": -4,
      "y": 1,
      "z": -2
    },
    {
      "name": "Empty",
      "x": -4,
      "y": 2,
      "z": -2
    },
    {
      "name": "Empty",
      "x": -4,
      "y": 3,
      "z": -2
    },
    {
      "name": "Soil_Dirt",
      "x": -4,
      "y": -1,
      "z": -1
    },
    {
      "name": "Soil_Grass",
      "x": -4,
      "y": 0,
      "z": -1
    },
    {
      "name": "Empty",
      "x": -4,
      "y": 1,
      "z": -1
    },
    {
      "name": "Empty",
      "x": -4,
      "y": 2,
      "z": -1
    },
    {
      "name": "Empty",
      "x": -4,
      "y": 3,
      "z": -1
    },
    {
      "name": "Soil_Dirt",
      "x": -4,
      "y": -1,
      "z": 0
    },
    {
      "name": "Soil_Grass",
      "x": -4,
      "y": 0,
      "z": 0
    },
    {
      "name": "Soil_Dirt",
      "x": -4,
      "y": 1,
      "z": 0
    },
    {
      "name": "Soil_Dirt",
      "x": -4,
      "y": 2,
      "z": 0
    },
    {
      "name": "Rock_Quartzite_Brick",
      "x": -4,
      "y": -1,
      "z": 1
    },
    {
      "name": "Rock_Quartzite_Brick",
      "x": -4,
      "y": 0,
      "z": 1
    },
    {
      "name": "Empty",
      "x": -4,
      "y": 1,
      "z": 1
    },
    {
      "name": "Empty",
      "x": -4,
      "y": 2,
      "z": 1
    },
    {
      "name": "Empty",
      "x": -4,
      "y": 3,
      "z": 1
    },
    {
      "name": "Soil_Dirt",
      "x": -4,
      "y": -1,
      "z": 2
    },
    {
      "name": "Rock_Quartzite_Brick",
      "x": -4,
      "y": 0,
      "z": 2
    },
    {
      "name": "Empty",
      "x": -4,
      "y": 1,
      "z": 2
    },
    {
      "name": "Empty",
      "x": -4,
      "y": 2,
      "z": 2
    },
    {
      "name": "Empty",
      "x": -4,
      "y": 3,
      "z": 2
    },
    {
      "name": "Soil_Dirt",
      "x": -4,
      "y": -1,
      "z": 3
    },
    {
      "name": "Rock_Quartzite_Brick",
      "x": -4,
      "y": 0,
      "z": 3
    },
    {
      "name": "Plant_Moss_Rug_Green",
      "support": 15,
      "x": -4,
      "y": 1,
      "z": 3
    },
    {
      "name": "Empty",
      "x": -4,
      "y": 2,
      "z": 3
    },
    {
      "name": "Empty",
      "x": -4,
      "y": 3,
      "z": 3
    },
    {
      "name": "Soil_Dirt",
      "x": -4,
      "y": -1,
      "z": 4
    },
    {
      "name": "Rock_Quartzite_Brick",
      "x": -4,
      "y": 0,
      "z": 4
    },
    {
      "name": "Plant_Moss_Rug_Green",
      "support": 15,
      "x": -4,
      "y": 1,
      "z": 4
    },
    {
      "name": "Empty",
      "x": -4,
      "y": 2,
      "z": 4
    },
    {
      "name": "Empty",
      "x": -4,
      "y": 3,
      "z": 4
    },
    {
      "name": "Rock_Quartzite_Brick",
      "x": -4,
      "y": -1,
      "z": 5
    },
    {
      "name": "Rock_Quartzite_Brick",
      "x": -4,
      "y": 0,
      "z": 5
    },
    {
      "name": "Empty",
      "x": -4,
      "y": 1,
      "z": 5
    },
    {
      "name": "Empty",
      "x": -4,
      "y": 2,
      "z": 5
    },
    {
      "name": "Empty",
      "x": -4,
      "y": 3,
      "z": 5
    },
    {
      "name": "Soil_Dirt",
      "x": -4,
      "y": -1,
      "z": 6
    },
    {
      "name": "Soil_Grass",
      "x": -4,
      "y": 0,
      "z": 6
    },
    {
      "name": "Empty",
      "x": -4,
      "y": 1,
      "z": 6
    },
    {
      "name": "Empty",
      "x": -4,
      "y": 2,
      "z": 6
    },
    {
      "name": "Empty",
      "x": -4,
      "y": 3,
      "z": 6
    },
    {
      "name": "Soil_Dirt",
      "x": -4,
      "y": -1,
      "z": 7
    },
    {
      "name": "Soil_Grass",
      "x": -4,
      "y": 0,
      "z": 7
    },
    {
      "name": "Empty",
      "x": -4,
      "y": 1,
      "z": 7
    },
    {
      "name": "Empty",
      "x": -4,
      "y": 2,
      "z": 7
    },
    {
      "name": "Empty",
      "x": -4,
      "y": 3,
      "z": 7
    },
    {
      "name": "Soil_Dirt",
      "x": -4,
      "y": 1,
      "z": 8
    },
    {
      "name": "Soil_Dirt",
      "x": -4,
      "y": 2,
      "z": 8
    },
    {
      "name": "Soil_Dirt",
      "x": -4,
      "y": 1,
      "z": 9
    },
    {
      "name": "Soil_Dirt",
      "x": -4,
      "y": 2,
      "z": 9
    },
    {
      "name": "Soil_Dirt",
      "x": -3,
      "y": 1,
      "z": -8
    },
    {
      "name": "Soil_Dirt",
      "x": -3,
      "y": 2,
      "z": -8
    },
    {
      "name": "Rock_Quartzite_Brick_Smooth",
      "x": -3,
      "y": -20,
      "z": -7
    },
    {
      "name": "Rock_Quartzite_Brick_Smooth",
      "x": -3,
      "y": -19,
      "z": -7
    },
    {
      "name": "Rock_Quartzite_Brick_Smooth",
      "x": -3,
      "y": -18,
      "z": -7
    },
    {
      "name": "Rock_Quartzite_Brick_Smooth",
      "x": -3,
      "y": -17,
      "z": -7
    },
    {
      "name": "Rock_Quartzite_Brick_Smooth",
      "x": -3,
      "y": -16,
      "z": -7
    },
    {
      "name": "Rock_Quartzite_Brick_Smooth",
      "x": -3,
      "y": -15,
      "z": -7
    },
    {
      "name": "Rock_Quartzite_Brick_Smooth",
      "x": -3,
      "y": -14,
      "z": -7
    },
    {
      "name": "Rock_Quartzite_Brick_Smooth",
      "x": -3,
      "y": -13,
      "z": -7
    },
    {
      "name": "Rock_Quartzite_Brick_Smooth",
      "x": -3,
      "y": -12,
      "z": -7
    },
    {
      "name": "Rock_Quartzite_Brick_Smooth",
      "x": -3,
      "y": -11,
      "z": -7
    },
    {
      "name": "Rock_Quartzite_Brick_Smooth",
      "x": -3,
      "y": -10,
      "z": -7
    },
    {
      "name": "Rock_Quartzite_Brick_Smooth",
      "x": -3,
      "y": -9,
      "z": -7
    },
    {
      "name": "Rock_Quartzite_Brick_Smooth",
      "x": -3,
      "y": -8,
      "z": -7
    },
    {
      "name": "Rock_Quartzite_Brick_Smooth",
      "x": -3,
      "y": -7,
      "z": -7
    },
    {
      "name": "Rock_Quartzite_Brick_Smooth",
      "x": -3,
      "y": -6,
      "z": -7
    },
    {
      "name": "Rock_Quartzite_Brick_Smooth",
      "x": -3,
      "y": -5,
      "z": -7
    },
    {
      "name": "Rock_Quartzite_Brick_Smooth",
      "x": -3,
      "y": -4,
      "z": -7
    },
    {
      "name": "Rock_Quartzite_Brick_Smooth",
      "x": -3,
      "y": -3,
      "z": -7
    },
    {
      "name": "Soil_Dirt",
      "x": -3,
      "y": -1,
      "z": -7
    },
    {
      "name": "Soil_Grass",
      "x": -3,
      "y": 0,
      "z": -7
    },
    {
      "name": "Soil_Dirt",
      "x": -3,
      "y": 1,
      "z": -7
    },
    {
      "name": "Soil_Dirt",
      "x": -3,
      "y": 2,
      "z": -7
    },
    {
      "name": "Rock_Quartzite_Brick_Smooth",
      "x": -3,
      "y": -20,
      "z": -6
    },
    {
      "name": "Rock_Quartzite_Brick_Smooth",
      "x": -3,
      "y": -19,
      "z": -6
    },
    {
      "name": "Rock_Quartzite_Brick_Smooth",
      "x": -3,
      "y": -18,
      "z": -6
    },
    {
      "name": "Rock_Quartzite_Brick_Smooth",
      "x": -3,
      "y": -17,
      "z": -6
    },
    {
      "name": "Rock_Quartzite_Brick_Smooth",
      "x": -3,
      "y": -16,
      "z": -6
    },
    {
      "name": "Rock_Quartzite_Brick_Smooth",
      "x": -3,
      "y": -15,
      "z": -6
    },
    {
      "name": "Rock_Quartzite_Brick_Smooth",
      "x": -3,
      "y": -14,
      "z": -6
    },
    {
      "name": "Rock_Quartzite_Brick_Smooth",
      "x": -3,
      "y": -13,
      "z": -6
    },
    {
      "name": "Rock_Quartzite_Brick_Smooth",
      "x": -3,
      "y": -12,
      "z": -6
    },
    {
      "name": "Rock_Quartzite_Brick_Smooth",
      "x": -3,
      "y": -11,
      "z": -6
    },
    {
      "name": "Rock_Quartzite_Brick_Smooth",
      "x": -3,
      "y": -10,
      "z": -6
    },
    {
      "name": "Rock_Quartzite_Brick_Smooth",
      "x": -3,
      "y": -9,
      "z": -6
    },
    {
      "name": "Rock_Quartzite_Brick_Smooth",
      "x": -3,
      "y": -8,
      "z": -6
    },
    {
      "name": "Rock_Quartzite_Brick_Smooth",
      "x": -3,
      "y": -7,
      "z": -6
    },
    {
      "name": "Rock_Quartzite_Brick_Smooth",
      "x": -3,
      "y": -6,
      "z": -6
    },
    {
      "name": "Rock_Quartzite_Brick_Smooth",
      "x": -3,
      "y": -5,
      "z": -6
    },
    {
      "name": "Rock_Quartzite_Brick_Smooth",
      "x": -3,
      "y": -4,
      "z": -6
    },
    {
      "name": "Rock_Quartzite_Brick_Smooth",
      "x": -3,
      "y": -3,
      "z": -6
    },
    {
      "name": "Rock_Quartzite_Brick_Smooth",
      "x": -3,
      "y": -2,
      "z": -6
    },
    {
      "name": "Soil_Dirt",
      "x": -3,
      "y": -1,
      "z": -6
    },
    {
      "name": "Soil_Grass",
      "x": -3,
      "y": 0,
      "z": -6
    },
    {
      "name": "Empty",
      "x": -3,
      "y": 1,
      "z": -6
    },
    {
      "name": "Empty",
      "x": -3,
      "y": 2,
      "z": -6
    },
    {
      "name": "Empty",
      "x": -3,
      "y": 3,
      "z": -6
    },
    {
      "name": "Rock_Quartzite_Brick_Smooth",
      "x": -3,
      "y": -9,
      "z": -5
    },
    {
      "name": "Rock_Quartzite_Brick_Smooth",
      "x": -3,
      "y": -5,
      "z": -5
    },
    {
      "name": "Rock_Quartzite_Brick",
      "x": -3,
      "y": -3,
      "z": -5
    },
    {
      "name": "Rock_Quartzite_Brick",
      "x": -3,
      "y": -2,
      "z": -5
    },
    {
      "name": "Rock_Quartzite_Brick",
      "x": -3,
      "y": -1,
      "z": -5
    },
    {
      "name": "Rock_Quartzite_Brick",
      "x": -3,
      "y": 0,
      "z": -5
    },
    {
      "name": "Rock_Quartzite_Brick_Pillar_Base",
      "rotation": 4,
      "x": -3,
      "y": 1,
      "z": -5
    },
    {
      "name": "Empty",
      "x": -3,
      "y": 2,
      "z": -5
    },
    {
      "name": "Empty",
      "x": -3,
      "y": 3,
      "z": -5
    },
    {
      "name": "Rock_Quartzite_Brick_Smooth",
      "x": -3,
      "y": -10,
      "z": -4
    },
    {
      "name": "Rock_Quartzite_Brick_Smooth",
      "x": -3,
      "y": -9,
      "z": -4
    },
    {
      "name": "Rock_Quartzite_Brick_Smooth",
      "x": -3,
      "y": -5,
      "z": -4
    },
    {
      "name": "Rock_Quartzite_Brick",
      "x": -3,
      "y": -3,
      "z": -4
    },
    {
      "name": "Rock_Quartzite_Brick",
      "x": -3,
      "y": -2,
      "z": -4
    },
    {
      "name": "Soil_Dirt",
      "x": -3,
      "y": -1,
      "z": -4
    },
    {
      "name": "Rock_Quartzite_Brick",
      "x": -3,
      "y": 0,
      "z": -4
    },
    {
      "name": "Rubble_Quartzite_Medium",
      "support": 15,
      "x": -3,
      "y": 1,
      "z": -4
    },
    {
      "name": "Empty",
      "x": -3,
      "y": 2,
      "z": -4
    },
    {
      "name": "Empty",
      "x": -3,
      "y": 3,
      "z": -4
    },
    {
      "name": "Rock_Quartzite_Brick_Smooth",
      "x": -3,
      "y": -10,
      "z": -3
    },
    {
      "name": "Rock_Quartzite_Brick_Smooth",
      "x": -3,
      "y": -5,
      "z": -3
    },
    {
      "name": "Soil_Dirt",
      "x": -3,
      "y": -1,
      "z": -3
    },
    {
      "name": "Rock_Quartzite_Brick",
      "x": -3,
      "y": 0,
      "z": -3
    },
    {
      "name": "Rock_Quartzite_Brick_Pillar_Middle",
      "rotation": 6,
      "x": -3,
      "y": 1,
      "z": -3
    },
    {
      "name": "Empty",
      "x": -3,
      "y": 2,
      "z": -3
    },
    {
      "name": "Empty",
      "x": -3,
      "y": 3,
      "z": -3
    },
    {
      "name": "Rock_Quartzite_Brick_Smooth",
      "x": -3,
      "y": -14,
      "z": -2
    },
    {
      "name": "Rock_Quartzite_Brick_Smooth",
      "x": -3,
      "y": -10,
      "z": -2
    },
    {
      "name": "Rock_Quartzite_Brick_Smooth",
      "x": -3,
      "y": -7,
      "z": -2
    },
    {
      "name": "Rock_Quartzite_Brick_Smooth",
      "x": -3,
      "y": -6,
      "z": -2
    },
    {
      "name": "Rock_Quartzite_Brick_Smooth",
      "x": -3,
      "y": -5,
      "z": -2
    },
    {
      "name": "Soil_Dirt",
      "x": -3,
      "y": -1,
      "z": -2
    },
    {
      "name": "Rock_Quartzite_Brick",
      "x": -3,
      "y": 0,
      "z": -2
    },
    {
      "name": "Rock_Quartzite_Brick_Pillar_Middle",
      "rotation": 6,
      "x": -3,
      "y": 1,
      "z": -2
    },
    {
      "name": "Empty",
      "x": -3,
      "y": 2,
      "z": -2
    },
    {
      "name": "Empty",
      "x": -3,
      "y": 3,
      "z": -2
    },
    {
      "name": "Rock_Quartzite_Brick_Smooth",
      "x": -3,
      "y": -14,
      "z": -1
    },
    {
      "name": "Rock_Quartzite_Brick_Smooth",
      "x": -3,
      "y": -10,
      "z": -1
    },
    {
      "name": "Rock_Quartzite_Brick_Smooth",
      "x": -3,
      "y": -7,
      "z": -1
    },
    {
      "name": "Soil_Dirt",
      "x": -3,
      "y": -1,
      "z": -1
    },
    {
      "name": "Rock_Quartzite_Brick",
      "x": -3,
      "y": 0,
      "z": -1
    },
    {
      "name": "Rock_Quartzite_Brick_Pillar_Base",
      "rotation": 6,
      "x": -3,
      "y": 1,
      "z": -1
    },
    {
      "name": "Empty",
      "x": -3,
      "y": 2,
      "z": -1
    },
    {
      "name": "Empty",
      "x": -3,
      "y": 3,
      "z": -1
    },
    {
      "name": "Rock_Quartzite_Brick_Smooth",
      "x": -3,
      "y": -13,
      "z": 0
    },
    {
      "name": "Rock_Quartzite_Brick_Smooth",
      "x": -3,
      "y": -12,
      "z": 0
    },
    {
      "name": "Rock_Quartzite_Brick_Smooth",
      "x": -3,
      "y": -11,
      "z": 0
    },
    {
      "name": "Rock_Quartzite_Brick_Smooth",
      "x": -3,
      "y": -10,
      "z": 0
    },
    {
      "name": "Rock_Quartzite_Brick_Smooth",
      "x": -3,
      "y": -9,
      "z": 0
    },
    {
      "name": "Rock_Quartzite_Brick_Smooth",
      "x": -3,
      "y": -8,
      "z": 0
    },
    {
      "name": "Rock_Quartzite_Brick_Smooth",
      "x": -3,
      "y": -7,
      "z": 0
    },
    {
      "name": "Rock_Quartzite_Brick",
      "x": -3,
      "y": -2,
      "z": 0
    },
    {
      "name": "Rock_Quartzite_Brick",
      "x": -3,
      "y": -1,
      "z": 0
    },
    {
      "name": "Rock_Quartzite_Brick",
      "x": -3,
      "y": 0,
      "z": 0
    },
    {
      "name": "Empty",
      "x": -3,
      "y": 1,
      "z": 0
    },
    {
      "name": "Empty",
      "x": -3,
      "y": 2,
      "z": 0
    },
    {
      "name": "Empty",
      "x": -3,
      "y": 3,
      "z": 0
    },
    {
      "name": "Rock_Quartzite_Brick_Smooth",
      "x": -3,
      "y": -14,
      "z": 1
    },
    {
      "name": "Rock_Quartzite_Brick_Smooth",
      "x": -3,
      "y": -10,
      "z": 1
    },
    {
      "name": "Rock_Quartzite_Brick_Smooth",
      "x": -3,
      "y": -7,
      "z": 1
    },
    {
      "name": "Rock_Quartzite_Brick",
      "x": -3,
      "y": -3,
      "z": 1
    },
    {
      "name": "Rock_Quartzite_Brick",
      "x": -3,
      "y": -2,
      "z": 1
    },
    {
      "name": "Rock_Quartzite_Brick",
      "x": -3,
      "y": -1,
      "z": 1
    },
    {
      "name": "Rock_Quartzite_Brick",
      "x": -3,
      "y": 0,
      "z": 1
    },
    {
      "name": "Empty",
      "x": -3,
      "y": 1,
      "z": 1
    },
    {
      "name": "Empty",
      "x": -3,
      "y": 2,
      "z": 1
    },
    {
      "name": "Empty",
      "x": -3,
      "y": 3,
      "z": 1
    },
    {
      "name": "Rock_Quartzite_Brick_Smooth",
      "x": -3,
      "y": -14,
      "z": 2
    },
    {
      "name": "Rock_Quartzite_Brick_Smooth",
      "x": -3,
      "y": -10,
      "z": 2
    },
    {
      "name": "Rock_Quartzite_Brick_Smooth",
      "x": -3,
      "y": -7,
      "z": 2
    },
    {
      "name": "Rock_Quartzite_Brick_Smooth",
      "x": -3,
      "y": -6,
      "z": 2
    },
    {
      "name": "Rock_Quartzite_Brick_Smooth",
      "x": -3,
      "y": -5,
      "z": 2
    },
    {
      "name": "Rock_Quartzite_Brick",
      "x": -3,
      "y": -3,
      "z": 2
    },
    {
      "name": "Rock_Quartzite_Brick",
      "x": -3,
      "y": -2,
      "z": 2
    },
    {
      "name": "Rock_Quartzite_Brick",
      "x": -3,
      "y": -1,
      "z": 2
    },
    {
      "name": "Rock_Quartzite_Brick_Ornate",
      "x": -3,
      "y": 0,
      "z": 2
    },
    {
      "name": "Rock_Quartzite_Brick_Wall",
      "rotation": 1,
      "x": -3,
      "y": 1,
      "z": 2
    },
    {
      "name": "Empty",
      "x": -3,
      "y": 2,
      "z": 2
    },
    {
      "name": "Empty",
      "x": -3,
      "y": 3,
      "z": 2
    },
    {
      "name": "Rock_Quartzite_Brick_Smooth",
      "x": -3,
      "y": -10,
      "z": 3
    },
    {
      "name": "Rock_Quartzite_Brick_Smooth",
      "x": -3,
      "y": -5,
      "z": 3
    },
    {
      "name": "Rock_Quartzite_Brick",
      "x": -3,
      "y": -3,
      "z": 3
    },
    {
      "name": "Rock_Quartzite_Brick",
      "x": -3,
      "y": -2,
      "z": 3
    },
    {
      "name": "Rock_Quartzite_Brick",
      "x": -3,
      "y": -1,
      "z": 3
    },
    {
      "name": "Rock_Quartzite_Brick_Ornate",
      "x": -3,
      "y": 0,
      "z": 3
    },
    {
      "name": "Rock_Quartzite_Brick_Wall",
      "rotation": 3,
      "x": -3,
      "y": 1,
      "z": 3
    },
    {
      "name": "Deco_Lantern",
      "x": -3,
      "y": 2,
      "z": 3
    },
    {
      "name": "Empty",
      "x": -3,
      "y": 3,
      "z": 3
    },
    {
      "name": "Rock_Quartzite_Brick_Smooth",
      "x": -3,
      "y": -10,
      "z": 4
    },
    {
      "name": "Rock_Quartzite_Brick_Smooth",
      "x": -3,
      "y": -9,
      "z": 4
    },
    {
      "name": "Rock_Quartzite_Brick_Smooth",
      "x": -3,
      "y": -5,
      "z": 4
    },
    {
      "name": "Rock_Quartzite_Brick",
      "x": -3,
      "y": -3,
      "z": 4
    },
    {
      "name": "Rock_Quartzite_Brick",
      "x": -3,
      "y": -2,
      "z": 4
    },
    {
      "name": "Rock_Quartzite_Brick",
      "x": -3,
      "y": -1,
      "z": 4
    },
    {
      "name": "Rock_Quartzite_Brick_Ornate",
      "x": -3,
      "y": 0,
      "z": 4
    },
    {
      "name": "Rubble_Quartzite",
      "support": 15,
      "x": -3,
      "y": 1,
      "z": 4
    },
    {
      "name": "Empty",
      "x": -3,
      "y": 2,
      "z": 4
    },
    {
      "name": "Empty",
      "x": -3,
      "y": 3,
      "z": 4
    },
    {
      "name": "Rock_Quartzite_Brick_Smooth",
      "x": -3,
      "y": -9,
      "z": 5
    },
    {
      "name": "Rock_Quartzite_Brick_Smooth",
      "x": -3,
      "y": -5,
      "z": 5
    },
    {
      "name": "Rock_Quartzite_Brick",
      "x": -3,
      "y": -3,
      "z": 5
    },
    {
      "name": "Rock_Quartzite_Brick",
      "x": -3,
      "y": -2,
      "z": 5
    },
    {
      "name": "Rock_Quartzite_Brick",
      "x": -3,
      "y": -1,
      "z": 5
    },
    {
      "name": "Rock_Quartzite_Brick",
      "x": -3,
      "y": 0,
      "z": 5
    },
    {
      "name": "Empty",
      "x": -3,
      "y": 1,
      "z": 5
    },
    {
      "name": "Empty",
      "x": -3,
      "y": 2,
      "z": 5
    },
    {
      "name": "Empty",
      "x": -3,
      "y": 3,
      "z": 5
    },
    {
      "name": "Rock_Quartzite_Brick_Smooth",
      "x": -3,
      "y": -20,
      "z": 6
    },
    {
      "name": "Rock_Quartzite_Brick_Smooth",
      "x": -3,
      "y": -19,
      "z": 6
    },
    {
      "name": "Rock_Quartzite_Brick_Smooth",
      "x": -3,
      "y": -18,
      "z": 6
    },
    {
      "name": "Rock_Quartzite_Brick_Smooth",
      "x": -3,
      "y": -17,
      "z": 6
    },
    {
      "name": "Rock_Quartzite_Brick_Smooth",
      "x": -3,
      "y": -16,
      "z": 6
    },
    {
      "name": "Rock_Quartzite_Brick_Smooth",
      "x": -3,
      "y": -15,
      "z": 6
    },
    {
      "name": "Rock_Quartzite_Brick_Smooth",
      "x": -3,
      "y": -14,
      "z": 6
    },
    {
      "name": "Rock_Quartzite_Brick_Smooth",
      "x": -3,
      "y": -13,
      "z": 6
    },
    {
      "name": "Rock_Quartzite_Brick_Smooth",
      "x": -3,
      "y": -12,
      "z": 6
    },
    {
      "name": "Rock_Quartzite_Brick_Smooth",
      "x": -3,
      "y": -11,
      "z": 6
    },
    {
      "name": "Rock_Quartzite_Brick_Smooth",
      "x": -3,
      "y": -10,
      "z": 6
    },
    {
      "name": "Rock_Quartzite_Brick_Smooth",
      "x": -3,
      "y": -9,
      "z": 6
    },
    {
      "name": "Rock_Quartzite_Brick_Smooth",
      "x": -3,
      "y": -8,
      "z": 6
    },
    {
      "name": "Rock_Quartzite_Brick_Smooth",
      "x": -3,
      "y": -7,
      "z": 6
    },
    {
      "name": "Rock_Quartzite_Brick_Smooth",
      "x": -3,
      "y": -6,
      "z": 6
    },
    {
      "name": "Rock_Quartzite_Brick_Smooth",
      "x": -3,
      "y": -5,
      "z": 6
    },
    {
      "name": "Rock_Quartzite_Brick_Smooth",
      "x": -3,
      "y": -4,
      "z": 6
    },
    {
      "name": "Rock_Quartzite_Brick_Smooth",
      "x": -3,
      "y": -3,
      "z": 6
    },
    {
      "name": "Rock_Quartzite_Brick",
      "x": -3,
      "y": -2,
      "z": 6
    },
    {
      "name": "Rock_Quartzite_Brick",
      "x": -3,
      "y": -1,
      "z": 6
    },
    {
      "name": "Rock_Quartzite_Brick",
      "x": -3,
      "y": 0,
      "z": 6
    },
    {
      "name": "Rock_Quartzite_Brick_Pillar_Base",
      "x": -3,
      "y": 1,
      "z": 6
    },
    {
      "name": "Rock_Quartzite_Brick_Pillar_Middle",
      "x": -3,
      "y": 2,
      "z": 6
    },
    {
      "name": "Rubble_Quartzite_Medium",
      "support": 15,
      "x": -3,
      "y": 3,
      "z": 6
    },
    {
      "name": "Rock_Quartzite_Brick_Smooth",
      "x": -3,
      "y": -20,
      "z": 7
    },
    {
      "name": "Rock_Quartzite_Brick_Smooth",
      "x": -3,
      "y": -19,
      "z": 7
    },
    {
      "name": "Rock_Quartzite_Brick_Smooth",
      "x": -3,
      "y": -18,
      "z": 7
    },
    {
      "name": "Rock_Quartzite_Brick_Smooth",
      "x": -3,
      "y": -17,
      "z": 7
    },
    {
      "name": "Rock_Quartzite_Brick_Smooth",
      "x": -3,
      "y": -16,
      "z": 7
    },
    {
      "name": "Rock_Quartzite_Brick_Smooth",
      "x": -3,
      "y": -15,
      "z": 7
    },
    {
      "name": "Rock_Quartzite_Brick_Smooth",
      "x": -3,
      "y": -14,
      "z": 7
    },
    {
      "name": "Rock_Quartzite_Brick_Smooth",
      "x": -3,
      "y": -13,
      "z": 7
    },
    {
      "name": "Rock_Quartzite_Brick_Smooth",
      "x": -3,
      "y": -12,
      "z": 7
    },
    {
      "name": "Rock_Quartzite_Brick_Smooth",
      "x": -3,
      "y": -11,
      "z": 7
    },
    {
      "name": "Rock_Quartzite_Brick_Smooth",
      "x": -3,
      "y": -10,
      "z": 7
    },
    {
      "name": "Rock_Quartzite_Brick_Smooth",
      "x": -3,
      "y": -9,
      "z": 7
    },
    {
      "name": "Rock_Quartzite_Brick_Smooth",
      "x": -3,
      "y": -8,
      "z": 7
    },
    {
      "name": "Rock_Quartzite_Brick_Smooth",
      "x": -3,
      "y": -7,
      "z": 7
    },
    {
      "name": "Rock_Quartzite_Brick_Smooth",
      "x": -3,
      "y": -6,
      "z": 7
    },
    {
      "name": "Rock_Quartzite_Brick_Smooth",
      "x": -3,
      "y": -5,
      "z": 7
    },
    {
      "name": "Rock_Quartzite_Brick_Smooth",
      "x": -3,
      "y": -4,
      "z": 7
    },
    {
      "name": "Rock_Quartzite_Brick_Smooth",
      "x": -3,
      "y": -3,
      "z": 7
    },
    {
      "name": "Rock_Quartzite_Brick_Smooth",
      "x": -3,
      "y": -2,
      "z": 7
    },
    {
      "name": "Soil_Dirt",
      "x": -3,
      "y": -1,
      "z": 7
    },
    {
      "name": "Soil_Grass",
      "x": -3,
      "y": 0,
      "z": 7
    },
    {
      "name": "Empty",
      "x": -3,
      "y": 1,
      "z": 7
    },
    {
      "name": "Empty",
      "x": -3,
      "y": 2,
      "z": 7
    },
    {
      "name": "Empty",
      "x": -3,
      "y": 3,
      "z": 7
    },
    {
      "name": "Soil_Dirt",
      "x": -3,
      "y": -1,
      "z": 8
    },
    {
      "name": "Soil_Grass",
      "x": -3,
      "y": 0,
      "z": 8
    },
    {
      "name": "Empty",
      "x": -3,
      "y": 1,
      "z": 8
    },
    {
      "name": "Empty",
      "x": -3,
      "y": 2,
      "z": 8
    },
    {
      "name": "Empty",
      "x": -3,
      "y": 3,
      "z": 8
    },
    {
      "name": "Soil_Dirt",
      "x": -3,
      "y": 1,
      "z": 9
    },
    {
      "name": "Soil_Dirt",
      "x": -3,
      "y": 2,
      "z": 9
    },
    {
      "name": "Soil_Dirt",
      "x": -3,
      "y": 1,
      "z": 10
    },
    {
      "name": "Soil_Dirt",
      "x": -3,
      "y": 2,
      "z": 10
    },
    {
      "name": "Soil_Dirt",
      "x": -2,
      "y": 1,
      "z": -9
    },
    {
      "name": "Soil_Dirt",
      "x": -2,
      "y": 2,
      "z": -9
    },
    {
      "name": "Soil_Dirt",
      "x": -2,
      "y": -1,
      "z": -8
    },
    {
      "name": "Soil_Grass",
      "x": -2,
      "y": 0,
      "z": -8
    },
    {
      "name": "Soil_Dirt",
      "x": -2,
      "y": 1,
      "z": -8
    },
    {
      "name": "Soil_Dirt",
      "x": -2,
      "y": 2,
      "z": -8
    },
    {
      "name": "Rock_Quartzite_Brick_Smooth",
      "x": -2,
      "y": -20,
      "z": -7
    },
    {
      "name": "Rock_Quartzite_Brick_Smooth",
      "x": -2,
      "y": -19,
      "z": -7
    },
    {
      "name": "Rock_Quartzite_Brick_Smooth",
      "x": -2,
      "y": -18,
      "z": -7
    },
    {
      "name": "Rock_Quartzite_Brick_Smooth",
      "x": -2,
      "y": -17,
      "z": -7
    },
    {
      "name": "Rock_Quartzite_Brick_Smooth",
      "x": -2,
      "y": -16,
      "z": -7
    },
    {
      "name": "Rock_Quartzite_Brick_Smooth",
      "x": -2,
      "y": -15,
      "z": -7
    },
    {
      "name": "Rock_Quartzite_Brick_Smooth",
      "x": -2,
      "y": -14,
      "z": -7
    },
    {
      "name": "Rock_Quartzite_Brick_Smooth",
      "x": -2,
      "y": -13,
      "z": -7
    },
    {
      "name": "Rock_Quartzite_Brick_Smooth",
      "x": -2,
      "y": -12,
      "z": -7
    },
    {
      "name": "Rock_Quartzite_Brick_Smooth",
      "x": -2,
      "y": -11,
      "z": -7
    },
    {
      "name": "Rock_Quartzite_Brick_Smooth",
      "x": -2,
      "y": -10,
      "z": -7
    },
    {
      "name": "Rock_Quartzite_Brick_Smooth",
      "x": -2,
      "y": -9,
      "z": -7
    },
    {
      "name": "Rock_Quartzite_Brick_Smooth",
      "x": -2,
      "y": -8,
      "z": -7
    },
    {
      "name": "Rock_Quartzite_Brick_Smooth",
      "x": -2,
      "y": -7,
      "z": -7
    },
    {
      "name": "Rock_Quartzite_Brick_Smooth",
      "x": -2,
      "y": -6,
      "z": -7
    },
    {
      "name": "Rock_Quartzite_Brick_Smooth",
      "x": -2,
      "y": -5,
      "z": -7
    },
    {
      "name": "Rock_Quartzite_Brick_Smooth",
      "x": -2,
      "y": -4,
      "z": -7
    },
    {
      "name": "Rock_Quartzite_Brick_Smooth",
      "x": -2,
      "y": -3,
      "z": -7
    },
    {
      "name": "Rock_Quartzite_Brick",
      "x": -2,
      "y": -2,
      "z": -7
    },
    {
      "name": "Rock_Quartzite_Brick",
      "x": -2,
      "y": -1,
      "z": -7
    },
    {
      "name": "Rock_Quartzite_Brick",
      "x": -2,
      "y": 0,
      "z": -7
    },
    {
      "name": "Empty",
      "x": -2,
      "y": 1,
      "z": -7
    },
    {
      "name": "Empty",
      "x": -2,
      "y": 2,
      "z": -7
    },
    {
      "name": "Empty",
      "x": -2,
      "y": 3,
      "z": -7
    },
    {
      "name": "Rock_Quartzite_Brick_Smooth",
      "x": -2,
      "y": -20,
      "z": -6
    },
    {
      "name": "Rock_Quartzite_Brick_Smooth",
      "x": -2,
      "y": -19,
      "z": -6
    },
    {
      "name": "Rock_Quartzite_Brick_Smooth",
      "x": -2,
      "y": -18,
      "z": -6
    },
    {
      "name": "Rock_Quartzite_Brick_Smooth",
      "x": -2,
      "y": -17,
      "z": -6
    },
    {
      "name": "Rock_Quartzite_Brick_Smooth",
      "x": -2,
      "y": -16,
      "z": -6
    },
    {
      "name": "Rock_Quartzite_Brick_Smooth",
      "x": -2,
      "y": -15,
      "z": -6
    },
    {
      "name": "Rock_Quartzite_Brick_Smooth",
      "x": -2,
      "y": -14,
      "z": -6
    },
    {
      "name": "Rock_Quartzite_Brick_Smooth",
      "x": -2,
      "y": -13,
      "z": -6
    },
    {
      "name": "Rock_Quartzite_Brick_Smooth",
      "x": -2,
      "y": -12,
      "z": -6
    },
    {
      "name": "Rock_Quartzite_Brick_Smooth",
      "x": -2,
      "y": -11,
      "z": -6
    },
    {
      "name": "Rock_Quartzite_Brick_Smooth",
      "x": -2,
      "y": -10,
      "z": -6
    },
    {
      "name": "Rock_Quartzite_Brick_Smooth",
      "x": -2,
      "y": -9,
      "z": -6
    },
    {
      "name": "Rock_Quartzite_Brick_Smooth",
      "x": -2,
      "y": -8,
      "z": -6
    },
    {
      "name": "Rock_Quartzite_Brick_Smooth",
      "x": -2,
      "y": -7,
      "z": -6
    },
    {
      "name": "Rock_Quartzite_Brick_Smooth",
      "x": -2,
      "y": -6,
      "z": -6
    },
    {
      "name": "Rock_Quartzite_Brick_Smooth",
      "x": -2,
      "y": -5,
      "z": -6
    },
    {
      "name": "Rock_Quartzite_Brick_Smooth",
      "x": -2,
      "y": -4,
      "z": -6
    },
    {
      "name": "Rock_Quartzite_Brick_Smooth",
      "x": -2,
      "y": -3,
      "z": -6
    },
    {
      "name": "Rock_Quartzite_Brick",
      "x": -2,
      "y": -2,
      "z": -6
    },
    {
      "name": "Rock_Quartzite_Brick",
      "x": -2,
      "y": -1,
      "z": -6
    },
    {
      "name": "Rock_Quartzite_Brick",
      "x": -2,
      "y": 0,
      "z": -6
    },
    {
      "name": "Empty",
      "x": -2,
      "y": 1,
      "z": -6
    },
    {
      "name": "Empty",
      "x": -2,
      "y": 2,
      "z": -6
    },
    {
      "name": "Empty",
      "x": -2,
      "y": 3,
      "z": -6
    },
    {
      "name": "Rock_Quartzite_Brick_Smooth",
      "x": -2,
      "y": -20,
      "z": -5
    },
    {
      "name": "Rock_Quartzite_Brick_Smooth",
      "x": -2,
      "y": -19,
      "z": -5
    },
    {
      "name": "Rock_Quartzite_Brick_Smooth",
      "x": -2,
      "y": -18,
      "z": -5
    },
    {
      "name": "Rock_Quartzite_Brick_Smooth",
      "x": -2,
      "y": -17,
      "z": -5
    },
    {
      "name": "Rock_Quartzite_Brick_Smooth",
      "x": -2,
      "y": -16,
      "z": -5
    },
    {
      "name": "Rock_Quartzite_Brick_Smooth",
      "x": -2,
      "y": -15,
      "z": -5
    },
    {
      "name": "Rock_Quartzite_Brick_Smooth",
      "x": -2,
      "y": -14,
      "z": -5
    },
    {
      "name": "Rock_Quartzite_Brick_Smooth",
      "x": -2,
      "y": -13,
      "z": -5
    },
    {
      "name": "Rock_Quartzite_Brick_Smooth",
      "x": -2,
      "y": -12,
      "z": -5
    },
    {
      "name": "Rock_Quartzite_Brick_Smooth",
      "x": -2,
      "y": -11,
      "z": -5
    },
    {
      "name": "Rock_Quartzite_Brick_Smooth",
      "x": -2,
      "y": -10,
      "z": -5
    },
    {
      "name": "Rock_Quartzite_Brick_Smooth",
      "x": -2,
      "y": -9,
      "z": -5
    },
    {
      "name": "Rock_Quartzite_Brick_Smooth",
      "x": -2,
      "y": -8,
      "z": -5
    },
    {
      "name": "Rock_Quartzite_Brick_Smooth",
      "x": -2,
      "y": -7,
      "z": -5
    },
    {
      "name": "Rock_Quartzite_Brick_Smooth",
      "x": -2,
      "y": -6,
      "z": -5
    },
    {
      "name": "Rock_Quartzite_Brick_Smooth",
      "x": -2,
      "y": -5,
      "z": -5
    },
    {
      "name": "Rock_Quartzite_Brick_Smooth",
      "x": -2,
      "y": -4,
      "z": -5
    },
    {
      "name": "Rock_Quartzite_Brick",
      "x": -2,
      "y": -3,
      "z": -5
    },
    {
      "name": "Rock_Quartzite_Brick",
      "x": -2,
      "y": -2,
      "z": -5
    },
    {
      "name": "Rock_Quartzite_Brick",
      "x": -2,
      "y": -1,
      "z": -5
    },
    {
      "name": "Rock_Quartzite_Brick",
      "x": -2,
      "y": 0,
      "z": -5
    },
    {
      "name": "Empty",
      "x": -2,
      "y": 1,
      "z": -5
    },
    {
      "name": "Empty",
      "x": -2,
      "y": 2,
      "z": -5
    },
    {
      "name": "Empty",
      "x": -2,
      "y": 3,
      "z": -5
    },
    {
      "name": "Rock_Quartzite_Brick_Smooth",
      "x": -2,
      "y": -20,
      "z": -4
    },
    {
      "name": "Rock_Quartzite_Brick_Smooth",
      "x": -2,
      "y": -19,
      "z": -4
    },
    {
      "name": "Rock_Quartzite_Brick_Smooth",
      "x": -2,
      "y": -18,
      "z": -4
    },
    {
      "name": "Rock_Quartzite_Brick_Smooth",
      "x": -2,
      "y": -17,
      "z": -4
    },
    {
      "name": "Rock_Quartzite_Brick_Smooth",
      "x": -2,
      "y": -16,
      "z": -4
    },
    {
      "name": "Rock_Quartzite_Brick_Smooth",
      "x": -2,
      "y": -15,
      "z": -4
    },
    {
      "name": "Rock_Quartzite_Brick_Smooth",
      "x": -2,
      "y": -14,
      "z": -4
    },
    {
      "name": "Rock_Quartzite_Brick_Smooth",
      "x": -2,
      "y": -13,
      "z": -4
    },
    {
      "name": "Rock_Quartzite_Brick_Smooth",
      "x": -2,
      "y": -12,
      "z": -4
    },
    {
      "name": "Rock_Quartzite_Brick_Smooth",
      "x": -2,
      "y": -11,
      "z": -4
    },
    {
      "name": "Rock_Quartzite_Brick_Smooth",
      "x": -2,
      "y": -10,
      "z": -4
    },
    {
      "name": "Rock_Quartzite_Brick_Smooth",
      "x": -2,
      "y": -9,
      "z": -4
    },
    {
      "name": "Rock_Quartzite_Brick_Smooth",
      "x": -2,
      "y": -8,
      "z": -4
    },
    {
      "name": "Rock_Quartzite_Brick_Smooth",
      "x": -2,
      "y": -7,
      "z": -4
    },
    {
      "name": "Rock_Quartzite_Brick_Smooth",
      "x": -2,
      "y": -6,
      "z": -4
    },
    {
      "name": "Rock_Quartzite_Brick_Smooth",
      "x": -2,
      "y": -5,
      "z": -4
    },
    {
      "name": "Rock_Quartzite_Brick_Smooth",
      "x": -2,
      "y": -4,
      "z": -4
    },
    {
      "name": "Rock_Quartzite_Brick",
      "x": -2,
      "y": -3,
      "z": -4
    },
    {
      "name": "Rock_Quartzite_Brick",
      "x": -2,
      "y": -2,
      "z": -4
    },
    {
      "name": "Rock_Quartzite_Brick",
      "x": -2,
      "y": -1,
      "z": -4
    },
    {
      "name": "Rock_Quartzite_Brick",
      "x": -2,
      "y": 0,
      "z": -4
    },
    {
      "name": "Empty",
      "x": -2,
      "y": 1,
      "z": -4
    },
    {
      "name": "Empty",
      "x": -2,
      "y": 2,
      "z": -4
    },
    {
      "name": "Empty",
      "x": -2,
      "y": 3,
      "z": -4
    },
    {
      "name": "Rock_Quartzite_Brick_Smooth",
      "x": -2,
      "y": -20,
      "z": -3
    },
    {
      "name": "Rock_Quartzite_Brick_Smooth",
      "x": -2,
      "y": -19,
      "z": -3
    },
    {
      "name": "Rock_Quartzite_Brick_Smooth",
      "x": -2,
      "y": -18,
      "z": -3
    },
    {
      "name": "Rock_Quartzite_Brick_Smooth",
      "x": -2,
      "y": -17,
      "z": -3
    },
    {
      "name": "Rock_Quartzite_Brick_Smooth",
      "x": -2,
      "y": -16,
      "z": -3
    },
    {
      "name": "Rock_Quartzite_Brick_Smooth",
      "x": -2,
      "y": -15,
      "z": -3
    },
    {
      "name": "Rock_Quartzite_Brick_Smooth",
      "x": -2,
      "y": -14,
      "z": -3
    },
    {
      "name": "Rock_Quartzite_Brick_Smooth",
      "x": -2,
      "y": -13,
      "z": -3
    },
    {
      "name": "Rock_Quartzite_Brick_Smooth",
      "x": -2,
      "y": -12,
      "z": -3
    },
    {
      "name": "Rock_Quartzite_Brick_Smooth",
      "x": -2,
      "y": -11,
      "z": -3
    },
    {
      "name": "Rock_Quartzite_Brick_Smooth",
      "x": -2,
      "y": -10,
      "z": -3
    },
    {
      "name": "Rock_Quartzite_Brick_Smooth",
      "x": -2,
      "y": -9,
      "z": -3
    },
    {
      "name": "Rock_Quartzite_Brick_Smooth",
      "x": -2,
      "y": -8,
      "z": -3
    },
    {
      "name": "Rock_Quartzite_Brick_Smooth",
      "x": -2,
      "y": -7,
      "z": -3
    },
    {
      "name": "Rock_Quartzite_Brick_Smooth",
      "x": -2,
      "y": -6,
      "z": -3
    },
    {
      "name": "Rock_Quartzite_Brick_Smooth",
      "x": -2,
      "y": -5,
      "z": -3
    },
    {
      "name": "Rock_Quartzite_Brick_Smooth",
      "x": -2,
      "y": -4,
      "z": -3
    },
    {
      "name": "Rock_Quartzite_Brick",
      "x": -2,
      "y": -3,
      "z": -3
    },
    {
      "name": "Rock_Quartzite_Brick",
      "x": -2,
      "y": -2,
      "z": -3
    },
    {
      "name": "Rock_Quartzite_Brick",
      "x": -2,
      "y": -1,
      "z": -3
    },
    {
      "name": "Rock_Quartzite_Brick",
      "x": -2,
      "y": 0,
      "z": -3
    },
    {
      "name": "Empty",
      "x": -2,
      "y": 1,
      "z": -3
    },
    {
      "name": "Empty",
      "x": -2,
      "y": 2,
      "z": -3
    },
    {
      "name": "Empty",
      "x": -2,
      "y": 3,
      "z": -3
    },
    {
      "name": "Rock_Quartzite_Brick_Smooth",
      "x": -2,
      "y": -20,
      "z": -2
    },
    {
      "name": "Rock_Quartzite_Brick_Smooth",
      "x": -2,
      "y": -19,
      "z": -2
    },
    {
      "name": "Rock_Quartzite_Brick_Smooth",
      "x": -2,
      "y": -18,
      "z": -2
    },
    {
      "name": "Rock_Quartzite_Brick_Smooth",
      "x": -2,
      "y": -17,
      "z": -2
    },
    {
      "name": "Rock_Quartzite_Brick_Smooth",
      "x": -2,
      "y": -16,
      "z": -2
    },
    {
      "name": "Rock_Quartzite_Brick_Smooth",
      "x": -2,
      "y": -15,
      "z": -2
    },
    {
      "name": "Rock_Quartzite_Brick_Smooth",
      "x": -2,
      "y": -14,
      "z": -2
    },
    {
      "name": "Rock_Quartzite_Brick_Smooth",
      "x": -2,
      "y": -13,
      "z": -2
    },
    {
      "name": "Rock_Quartzite_Brick_Smooth",
      "x": -2,
      "y": -12,
      "z": -2
    },
    {
      "name": "Rock_Quartzite_Brick_Smooth",
      "x": -2,
      "y": -11,
      "z": -2
    },
    {
      "name": "Rock_Quartzite_Brick_Smooth",
      "x": -2,
      "y": -10,
      "z": -2
    },
    {
      "name": "Rock_Quartzite_Brick_Smooth",
      "x": -2,
      "y": -9,
      "z": -2
    },
    {
      "name": "Rock_Quartzite_Brick_Smooth",
      "x": -2,
      "y": -8,
      "z": -2
    },
    {
      "name": "Rock_Quartzite_Brick_Smooth",
      "x": -2,
      "y": -7,
      "z": -2
    },
    {
      "name": "Rock_Quartzite_Brick_Smooth",
      "x": -2,
      "y": -6,
      "z": -2
    },
    {
      "name": "Rock_Quartzite_Brick_Smooth",
      "x": -2,
      "y": -5,
      "z": -2
    },
    {
      "name": "Rock_Quartzite_Brick_Smooth",
      "x": -2,
      "y": -4,
      "z": -2
    },
    {
      "name": "Rock_Quartzite_Brick",
      "x": -2,
      "y": -3,
      "z": -2
    },
    {
      "name": "Rock_Quartzite_Brick",
      "x": -2,
      "y": -2,
      "z": -2
    },
    {
      "name": "Rock_Quartzite_Brick",
      "x": -2,
      "y": -1,
      "z": -2
    },
    {
      "name": "Rock_Quartzite_Brick",
      "x": -2,
      "y": 0,
      "z": -2
    },
    {
      "name": "Empty",
      "x": -2,
      "y": 1,
      "z": -2
    },
    {
      "name": "Empty",
      "x": -2,
      "y": 2,
      "z": -2
    },
    {
      "name": "Empty",
      "x": -2,
      "y": 3,
      "z": -2
    },
    {
      "name": "Rock_Quartzite_Brick_Smooth",
      "x": -2,
      "y": -20,
      "z": -1
    },
    {
      "name": "Rock_Quartzite_Brick_Smooth",
      "x": -2,
      "y": -19,
      "z": -1
    },
    {
      "name": "Rock_Quartzite_Brick_Smooth",
      "x": -2,
      "y": -18,
      "z": -1
    },
    {
      "name": "Rock_Quartzite_Brick_Smooth",
      "x": -2,
      "y": -17,
      "z": -1
    },
    {
      "name": "Rock_Quartzite_Brick_Smooth",
      "x": -2,
      "y": -16,
      "z": -1
    },
    {
      "name": "Rock_Quartzite_Brick_Smooth",
      "x": -2,
      "y": -15,
      "z": -1
    },
    {
      "name": "Rock_Quartzite_Brick_Smooth",
      "x": -2,
      "y": -14,
      "z": -1
    },
    {
      "name": "Rock_Quartzite_Brick_Smooth",
      "x": -2,
      "y": -13,
      "z": -1
    },
    {
      "name": "Rock_Quartzite_Brick_Smooth",
      "x": -2,
      "y": -12,
      "z": -1
    },
    {
      "name": "Rock_Quartzite_Brick_Smooth",
      "x": -2,
      "y": -11,
      "z": -1
    },
    {
      "name": "Rock_Quartzite_Brick_Smooth",
      "x": -2,
      "y": -10,
      "z": -1
    },
    {
      "name": "Rock_Quartzite_Brick_Smooth",
      "x": -2,
      "y": -9,
      "z": -1
    },
    {
      "name": "Rock_Quartzite_Brick_Smooth",
      "x": -2,
      "y": -8,
      "z": -1
    },
    {
      "name": "Rock_Quartzite_Brick_Smooth",
      "x": -2,
      "y": -7,
      "z": -1
    },
    {
      "name": "Rock_Quartzite_Brick_Smooth",
      "x": -2,
      "y": -6,
      "z": -1
    },
    {
      "name": "Rock_Quartzite_Brick_Smooth",
      "x": -2,
      "y": -5,
      "z": -1
    },
    {
      "name": "Rock_Quartzite_Brick_Smooth",
      "x": -2,
      "y": -4,
      "z": -1
    },
    {
      "name": "Rock_Quartzite_Brick",
      "x": -2,
      "y": -3,
      "z": -1
    },
    {
      "name": "Rock_Quartzite_Brick",
      "x": -2,
      "y": -2,
      "z": -1
    },
    {
      "name": "Rock_Quartzite_Brick",
      "x": -2,
      "y": -1,
      "z": -1
    },
    {
      "name": "Rock_Quartzite_Brick",
      "x": -2,
      "y": 0,
      "z": -1
    },
    {
      "name": "Empty",
      "x": -2,
      "y": 1,
      "z": -1
    },
    {
      "name": "Empty",
      "x": -2,
      "y": 2,
      "z": -1
    },
    {
      "name": "Empty",
      "x": -2,
      "y": 3,
      "z": -1
    },
    {
      "name": "Rock_Quartzite_Brick_Smooth",
      "x": -2,
      "y": -20,
      "z": 0
    },
    {
      "name": "Rock_Quartzite_Brick_Smooth",
      "x": -2,
      "y": -19,
      "z": 0
    },
    {
      "name": "Rock_Quartzite_Brick_Smooth",
      "x": -2,
      "y": -18,
      "z": 0
    },
    {
      "name": "Rock_Quartzite_Brick_Smooth",
      "x": -2,
      "y": -17,
      "z": 0
    },
    {
      "name": "Rock_Quartzite_Brick_Smooth",
      "x": -2,
      "y": -16,
      "z": 0
    },
    {
      "name": "Rock_Quartzite_Brick_Smooth",
      "x": -2,
      "y": -15,
      "z": 0
    },
    {
      "name": "Rock_Quartzite_Brick_Smooth",
      "x": -2,
      "y": -14,
      "z": 0
    },
    {
      "name": "Rock_Quartzite_Brick_Smooth",
      "x": -2,
      "y": -13,
      "z": 0
    },
    {
      "name": "Rock_Quartzite_Brick_Smooth",
      "x": -2,
      "y": -12,
      "z": 0
    },
    {
      "name": "Rock_Quartzite_Brick_Smooth",
      "x": -2,
      "y": -11,
      "z": 0
    },
    {
      "name": "Rock_Quartzite_Brick_Smooth",
      "x": -2,
      "y": -10,
      "z": 0
    },
    {
      "name": "Rock_Quartzite_Brick_Smooth",
      "x": -2,
      "y": -9,
      "z": 0
    },
    {
      "name": "Rock_Quartzite_Brick_Smooth",
      "x": -2,
      "y": -8,
      "z": 0
    },
    {
      "name": "Rock_Quartzite_Brick_Smooth",
      "x": -2,
      "y": -7,
      "z": 0
    },
    {
      "name": "Rock_Quartzite_Brick_Smooth",
      "x": -2,
      "y": -6,
      "z": 0
    },
    {
      "name": "Rock_Quartzite_Brick_Smooth",
      "x": -2,
      "y": -5,
      "z": 0
    },
    {
      "name": "Rock_Quartzite_Brick_Smooth",
      "x": -2,
      "y": -4,
      "z": 0
    },
    {
      "name": "Rock_Quartzite_Brick",
      "x": -2,
      "y": -3,
      "z": 0
    },
    {
      "name": "Rock_Quartzite_Brick",
      "x": -2,
      "y": -2,
      "z": 0
    },
    {
      "name": "Rock_Quartzite_Brick",
      "x": -2,
      "y": -1,
      "z": 0
    },
    {
      "name": "Rock_Quartzite_Brick",
      "x": -2,
      "y": 0,
      "z": 0
    },
    {
      "name": "Plant_Moss_Rug_Green",
      "support": 15,
      "x": -2,
      "y": 1,
      "z": 0
    },
    {
      "name": "Empty",
      "x": -2,
      "y": 2,
      "z": 0
    },
    {
      "name": "Empty",
      "x": -2,
      "y": 3,
      "z": 0
    },
    {
      "name": "Rock_Quartzite_Brick_Smooth",
      "x": -2,
      "y": -20,
      "z": 1
    },
    {
      "name": "Rock_Quartzite_Brick_Smooth",
      "x": -2,
      "y": -19,
      "z": 1
    },
    {
      "name": "Rock_Quartzite_Brick_Smooth",
      "x": -2,
      "y": -18,
      "z": 1
    },
    {
      "name": "Rock_Quartzite_Brick_Smooth",
      "x": -2,
      "y": -17,
      "z": 1
    },
    {
      "name": "Rock_Quartzite_Brick_Smooth",
      "x": -2,
      "y": -16,
      "z": 1
    },
    {
      "name": "Rock_Quartzite_Brick_Smooth",
      "x": -2,
      "y": -15,
      "z": 1
    },
    {
      "name": "Rock_Quartzite_Brick_Smooth",
      "x": -2,
      "y": -14,
      "z": 1
    },
    {
      "name": "Rock_Quartzite_Brick_Smooth",
      "x": -2,
      "y": -13,
      "z": 1
    },
    {
      "name": "Rock_Quartzite_Brick_Smooth",
      "x": -2,
      "y": -12,
      "z": 1
    },
    {
      "name": "Rock_Quartzite_Brick_Smooth",
      "x": -2,
      "y": -11,
      "z": 1
    },
    {
      "name": "Rock_Quartzite_Brick_Smooth",
      "x": -2,
      "y": -10,
      "z": 1
    },
    {
      "name": "Rock_Quartzite_Brick_Smooth",
      "x": -2,
      "y": -9,
      "z": 1
    },
    {
      "name": "Rock_Quartzite_Brick_Smooth",
      "x": -2,
      "y": -8,
      "z": 1
    },
    {
      "name": "Rock_Quartzite_Brick_Smooth",
      "x": -2,
      "y": -7,
      "z": 1
    },
    {
      "name": "Rock_Quartzite_Brick_Smooth",
      "x": -2,
      "y": -6,
      "z": 1
    },
    {
      "name": "Rock_Quartzite_Brick_Smooth",
      "x": -2,
      "y": -5,
      "z": 1
    },
    {
      "name": "Rock_Quartzite_Brick_Smooth",
      "x": -2,
      "y": -4,
      "z": 1
    },
    {
      "name": "Rock_Quartzite_Brick",
      "x": -2,
      "y": -3,
      "z": 1
    },
    {
      "name": "Rock_Quartzite_Brick",
      "x": -2,
      "y": -2,
      "z": 1
    },
    {
      "name": "Rock_Quartzite_Brick",
      "x": -2,
      "y": -1,
      "z": 1
    },
    {
      "name": "Rock_Quartzite_Brick_Ornate",
      "x": -2,
      "y": 0,
      "z": 1
    },
    {
      "name": "Rubble_Quartzite",
      "support": 15,
      "x": -2,
      "y": 1,
      "z": 1
    },
    {
      "name": "Empty",
      "x": -2,
      "y": 2,
      "z": 1
    },
    {
      "name": "Empty",
      "x": -2,
      "y": 3,
      "z": 1
    },
    {
      "name": "Rock_Quartzite_Brick_Smooth",
      "x": -2,
      "y": -20,
      "z": 2
    },
    {
      "name": "Rock_Quartzite_Brick_Smooth",
      "x": -2,
      "y": -19,
      "z": 2
    },
    {
      "name": "Rock_Quartzite_Brick_Smooth",
      "x": -2,
      "y": -18,
      "z": 2
    },
    {
      "name": "Rock_Quartzite_Brick_Smooth",
      "x": -2,
      "y": -17,
      "z": 2
    },
    {
      "name": "Rock_Quartzite_Brick_Smooth",
      "x": -2,
      "y": -16,
      "z": 2
    },
    {
      "name": "Rock_Quartzite_Brick_Smooth",
      "x": -2,
      "y": -15,
      "z": 2
    },
    {
      "name": "Rock_Quartzite_Brick_Smooth",
      "x": -2,
      "y": -14,
      "z": 2
    },
    {
      "name": "Rock_Quartzite_Brick_Smooth",
      "x": -2,
      "y": -13,
      "z": 2
    },
    {
      "name": "Rock_Quartzite_Brick_Smooth",
      "x": -2,
      "y": -12,
      "z": 2
    },
    {
      "name": "Rock_Quartzite_Brick_Smooth",
      "x": -2,
      "y": -11,
      "z": 2
    },
    {
      "name": "Rock_Quartzite_Brick_Smooth",
      "x": -2,
      "y": -10,
      "z": 2
    },
    {
      "name": "Rock_Quartzite_Brick_Smooth",
      "x": -2,
      "y": -9,
      "z": 2
    },
    {
      "name": "Rock_Quartzite_Brick_Smooth",
      "x": -2,
      "y": -8,
      "z": 2
    },
    {
      "name": "Rock_Quartzite_Brick_Smooth",
      "x": -2,
      "y": -7,
      "z": 2
    },
    {
      "name": "Rock_Quartzite_Brick_Smooth",
      "x": -2,
      "y": -6,
      "z": 2
    },
    {
      "name": "Rock_Quartzite_Brick_Smooth",
      "x": -2,
      "y": -5,
      "z": 2
    },
    {
      "name": "Rock_Quartzite_Brick_Smooth",
      "x": -2,
      "y": -4,
      "z": 2
    },
    {
      "name": "Rock_Quartzite_Brick",
      "x": -2,
      "y": -3,
      "z": 2
    },
    {
      "name": "Rock_Quartzite_Brick",
      "x": -2,
      "y": -2,
      "z": 2
    },
    {
      "name": "Rock_Quartzite_Brick",
      "x": -2,
      "y": -1,
      "z": 2
    },
    {
      "name": "Rock_Quartzite_Brick_Smooth",
      "x": -2,
      "y": 0,
      "z": 2
    },
    {
      "name": "Empty",
      "x": -2,
      "y": 1,
      "z": 2
    },
    {
      "name": "Empty",
      "x": -2,
      "y": 2,
      "z": 2
    },
    {
      "name": "Empty",
      "x": -2,
      "y": 3,
      "z": 2
    },
    {
      "name": "Rock_Quartzite_Brick_Smooth",
      "x": -2,
      "y": -20,
      "z": 3
    },
    {
      "name": "Rock_Quartzite_Brick_Smooth",
      "x": -2,
      "y": -19,
      "z": 3
    },
    {
      "name": "Rock_Quartzite_Brick_Smooth",
      "x": -2,
      "y": -18,
      "z": 3
    },
    {
      "name": "Rock_Quartzite_Brick_Smooth",
      "x": -2,
      "y": -17,
      "z": 3
    },
    {
      "name": "Rock_Quartzite_Brick_Smooth",
      "x": -2,
      "y": -16,
      "z": 3
    },
    {
      "name": "Rock_Quartzite_Brick_Smooth",
      "x": -2,
      "y": -15,
      "z": 3
    },
    {
      "name": "Rock_Quartzite_Brick_Smooth",
      "x": -2,
      "y": -14,
      "z": 3
    },
    {
      "name": "Rock_Quartzite_Brick_Smooth",
      "x": -2,
      "y": -13,
      "z": 3
    },
    {
      "name": "Rock_Quartzite_Brick_Smooth",
      "x": -2,
      "y": -12,
      "z": 3
    },
    {
      "name": "Rock_Quartzite_Brick_Smooth",
      "x": -2,
      "y": -11,
      "z": 3
    },
    {
      "name": "Rock_Quartzite_Brick_Smooth",
      "x": -2,
      "y": -10,
      "z": 3
    },
    {
      "name": "Rock_Quartzite_Brick_Smooth",
      "x": -2,
      "y": -9,
      "z": 3
    },
    {
      "name": "Rock_Quartzite_Brick_Smooth",
      "x": -2,
      "y": -8,
      "z": 3
    },
    {
      "name": "Rock_Quartzite_Brick_Smooth",
      "x": -2,
      "y": -7,
      "z": 3
    },
    {
      "name": "Rock_Quartzite_Brick_Smooth",
      "x": -2,
      "y": -6,
      "z": 3
    },
    {
      "name": "Rock_Quartzite_Brick_Smooth",
      "x": -2,
      "y": -5,
      "z": 3
    },
    {
      "name": "Rock_Quartzite_Brick_Smooth",
      "x": -2,
      "y": -4,
      "z": 3
    },
    {
      "name": "Rock_Quartzite_Brick",
      "x": -2,
      "y": -3,
      "z": 3
    },
    {
      "name": "Rock_Quartzite_Brick",
      "x": -2,
      "y": -2,
      "z": 3
    },
    {
      "name": "Rock_Quartzite_Brick",
      "x": -2,
      "y": -1,
      "z": 3
    },
    {
      "name": "Rock_Quartzite_Brick_Smooth",
      "x": -2,
      "y": 0,
      "z": 3
    },
    {
      "name": "Empty",
      "x": -2,
      "y": 1,
      "z": 3
    },
    {
      "name": "Empty",
      "x": -2,
      "y": 2,
      "z": 3
    },
    {
      "name": "Empty",
      "x": -2,
      "y": 3,
      "z": 3
    },
    {
      "name": "Rock_Quartzite_Brick_Smooth",
      "x": -2,
      "y": -20,
      "z": 4
    },
    {
      "name": "Rock_Quartzite_Brick_Smooth",
      "x": -2,
      "y": -19,
      "z": 4
    },
    {
      "name": "Rock_Quartzite_Brick_Smooth",
      "x": -2,
      "y": -18,
      "z": 4
    },
    {
      "name": "Rock_Quartzite_Brick_Smooth",
      "x": -2,
      "y": -17,
      "z": 4
    },
    {
      "name": "Rock_Quartzite_Brick_Smooth",
      "x": -2,
      "y": -16,
      "z": 4
    },
    {
      "name": "Rock_Quartzite_Brick_Smooth",
      "x": -2,
      "y": -15,
      "z": 4
    },
    {
      "name": "Rock_Quartzite_Brick_Smooth",
      "x": -2,
      "y": -14,
      "z": 4
    },
    {
      "name": "Rock_Quartzite_Brick_Smooth",
      "x": -2,
      "y": -13,
      "z": 4
    },
    {
      "name": "Rock_Quartzite_Brick_Smooth",
      "x": -2,
      "y": -12,
      "z": 4
    },
    {
      "name": "Rock_Quartzite_Brick_Smooth",
      "x": -2,
      "y": -11,
      "z": 4
    },
    {
      "name": "Rock_Quartzite_Brick_Smooth",
      "x": -2,
      "y": -10,
      "z": 4
    },
    {
      "name": "Rock_Quartzite_Brick_Smooth",
      "x": -2,
      "y": -9,
      "z": 4
    },
    {
      "name": "Rock_Quartzite_Brick_Smooth",
      "x": -2,
      "y": -8,
      "z": 4
    },
    {
      "name": "Rock_Quartzite_Brick_Smooth",
      "x": -2,
      "y": -7,
      "z": 4
    },
    {
      "name": "Rock_Quartzite_Brick_Smooth",
      "x": -2,
      "y": -6,
      "z": 4
    },
    {
      "name": "Rock_Quartzite_Brick_Smooth",
      "x": -2,
      "y": -5,
      "z": 4
    },
    {
      "name": "Rock_Quartzite_Brick_Smooth",
      "x": -2,
      "y": -4,
      "z": 4
    },
    {
      "name": "Rock_Quartzite_Brick",
      "x": -2,
      "y": -3,
      "z": 4
    },
    {
      "name": "Rock_Quartzite_Brick",
      "x": -2,
      "y": -2,
      "z": 4
    },
    {
      "name": "Rock_Quartzite_Brick",
      "x": -2,
      "y": -1,
      "z": 4
    },
    {
      "name": "Rock_Quartzite_Brick_Smooth",
      "x": -2,
      "y": 0,
      "z": 4
    },
    {
      "name": "Empty",
      "x": -2,
      "y": 1,
      "z": 4
    },
    {
      "name": "Empty",
      "x": -2,
      "y": 2,
      "z": 4
    },
    {
      "name": "Empty",
      "x": -2,
      "y": 3,
      "z": 4
    },
    {
      "name": "Rock_Quartzite_Brick_Smooth",
      "x": -2,
      "y": -20,
      "z": 5
    },
    {
      "name": "Rock_Quartzite_Brick_Smooth",
      "x": -2,
      "y": -19,
      "z": 5
    },
    {
      "name": "Rock_Quartzite_Brick_Smooth",
      "x": -2,
      "y": -18,
      "z": 5
    },
    {
      "name": "Rock_Quartzite_Brick_Smooth",
      "x": -2,
      "y": -17,
      "z": 5
    },
    {
      "name": "Rock_Quartzite_Brick_Smooth",
      "x": -2,
      "y": -16,
      "z": 5
    },
    {
      "name": "Rock_Quartzite_Brick_Smooth",
      "x": -2,
      "y": -15,
      "z": 5
    },
    {
      "name": "Rock_Quartzite_Brick_Smooth",
      "x": -2,
      "y": -14,
      "z": 5
    },
    {
      "name": "Rock_Quartzite_Brick_Smooth",
      "x": -2,
      "y": -13,
      "z": 5
    },
    {
      "name": "Rock_Quartzite_Brick_Smooth",
      "x": -2,
      "y": -12,
      "z": 5
    },
    {
      "name": "Rock_Quartzite_Brick_Smooth",
      "x": -2,
      "y": -11,
      "z": 5
    },
    {
      "name": "Rock_Quartzite_Brick_Smooth",
      "x": -2,
      "y": -10,
      "z": 5
    },
    {
      "name": "Rock_Quartzite_Brick_Smooth",
      "x": -2,
      "y": -9,
      "z": 5
    },
    {
      "name": "Rock_Quartzite_Brick_Smooth",
      "x": -2,
      "y": -8,
      "z": 5
    },
    {
      "name": "Rock_Quartzite_Brick_Smooth",
      "x": -2,
      "y": -7,
      "z": 5
    },
    {
      "name": "Rock_Quartzite_Brick_Smooth",
      "x": -2,
      "y": -6,
      "z": 5
    },
    {
      "name": "Rock_Quartzite_Brick_Smooth",
      "x": -2,
      "y": -5,
      "z": 5
    },
    {
      "name": "Rock_Quartzite_Brick_Smooth",
      "x": -2,
      "y": -4,
      "z": 5
    },
    {
      "name": "Rock_Quartzite_Brick",
      "x": -2,
      "y": -3,
      "z": 5
    },
    {
      "name": "Rock_Quartzite_Brick",
      "x": -2,
      "y": -2,
      "z": 5
    },
    {
      "name": "Rock_Quartzite_Brick",
      "x": -2,
      "y": -1,
      "z": 5
    },
    {
      "name": "Rock_Quartzite_Brick_Ornate",
      "x": -2,
      "y": 0,
      "z": 5
    },
    {
      "name": "Rubble_Quartzite",
      "support": 15,
      "x": -2,
      "y": 1,
      "z": 5
    },
    {
      "name": "Empty",
      "x": -2,
      "y": 2,
      "z": 5
    },
    {
      "name": "Empty",
      "x": -2,
      "y": 3,
      "z": 5
    },
    {
      "name": "Rock_Quartzite_Brick_Smooth",
      "x": -2,
      "y": -20,
      "z": 6
    },
    {
      "name": "Rock_Quartzite_Brick_Smooth",
      "x": -2,
      "y": -19,
      "z": 6
    },
    {
      "name": "Rock_Quartzite_Brick_Smooth",
      "x": -2,
      "y": -18,
      "z": 6
    },
    {
      "name": "Rock_Quartzite_Brick_Smooth",
      "x": -2,
      "y": -17,
      "z": 6
    },
    {
      "name": "Rock_Quartzite_Brick_Smooth",
      "x": -2,
      "y": -16,
      "z": 6
    },
    {
      "name": "Rock_Quartzite_Brick_Smooth",
      "x": -2,
      "y": -15,
      "z": 6
    },
    {
      "name": "Rock_Quartzite_Brick_Smooth",
      "x": -2,
      "y": -14,
      "z": 6
    },
    {
      "name": "Rock_Quartzite_Brick_Smooth",
      "x": -2,
      "y": -13,
      "z": 6
    },
    {
      "name": "Rock_Quartzite_Brick_Smooth",
      "x": -2,
      "y": -12,
      "z": 6
    },
    {
      "name": "Rock_Quartzite_Brick_Smooth",
      "x": -2,
      "y": -11,
      "z": 6
    },
    {
      "name": "Rock_Quartzite_Brick_Smooth",
      "x": -2,
      "y": -10,
      "z": 6
    },
    {
      "name": "Rock_Quartzite_Brick_Smooth",
      "x": -2,
      "y": -9,
      "z": 6
    },
    {
      "name": "Rock_Quartzite_Brick_Smooth",
      "x": -2,
      "y": -8,
      "z": 6
    },
    {
      "name": "Rock_Quartzite_Brick_Smooth",
      "x": -2,
      "y": -7,
      "z": 6
    },
    {
      "name": "Rock_Quartzite_Brick_Smooth",
      "x": -2,
      "y": -6,
      "z": 6
    },
    {
      "name": "Rock_Quartzite_Brick_Smooth",
      "x": -2,
      "y": -5,
      "z": 6
    },
    {
      "name": "Rock_Quartzite_Brick_Smooth",
      "x": -2,
      "y": -4,
      "z": 6
    },
    {
      "name": "Rock_Quartzite_Brick",
      "x": -2,
      "y": -3,
      "z": 6
    },
    {
      "name": "Rock_Quartzite_Brick",
      "x": -2,
      "y": -2,
      "z": 6
    },
    {
      "name": "Rock_Quartzite_Brick",
      "x": -2,
      "y": -1,
      "z": 6
    },
    {
      "name": "Rock_Quartzite_Brick",
      "x": -2,
      "y": 0,
      "z": 6
    },
    {
      "name": "Empty",
      "x": -2,
      "y": 1,
      "z": 6
    },
    {
      "name": "Empty",
      "x": -2,
      "y": 2,
      "z": 6
    },
    {
      "name": "Empty",
      "x": -2,
      "y": 3,
      "z": 6
    },
    {
      "name": "Rock_Quartzite_Brick_Smooth",
      "x": -2,
      "y": -20,
      "z": 7
    },
    {
      "name": "Rock_Quartzite_Brick_Smooth",
      "x": -2,
      "y": -19,
      "z": 7
    },
    {
      "name": "Rock_Quartzite_Brick_Smooth",
      "x": -2,
      "y": -18,
      "z": 7
    },
    {
      "name": "Rock_Quartzite_Brick_Smooth",
      "x": -2,
      "y": -17,
      "z": 7
    },
    {
      "name": "Rock_Quartzite_Brick_Smooth",
      "x": -2,
      "y": -16,
      "z": 7
    },
    {
      "name": "Rock_Quartzite_Brick_Smooth",
      "x": -2,
      "y": -15,
      "z": 7
    },
    {
      "name": "Rock_Quartzite_Brick_Smooth",
      "x": -2,
      "y": -14,
      "z": 7
    },
    {
      "name": "Rock_Quartzite_Brick_Smooth",
      "x": -2,
      "y": -13,
      "z": 7
    },
    {
      "name": "Rock_Quartzite_Brick_Smooth",
      "x": -2,
      "y": -12,
      "z": 7
    },
    {
      "name": "Rock_Quartzite_Brick_Smooth",
      "x": -2,
      "y": -11,
      "z": 7
    },
    {
      "name": "Rock_Quartzite_Brick_Smooth",
      "x": -2,
      "y": -10,
      "z": 7
    },
    {
      "name": "Rock_Quartzite_Brick_Smooth",
      "x": -2,
      "y": -9,
      "z": 7
    },
    {
      "name": "Rock_Quartzite_Brick_Smooth",
      "x": -2,
      "y": -8,
      "z": 7
    },
    {
      "name": "Rock_Quartzite_Brick_Smooth",
      "x": -2,
      "y": -7,
      "z": 7
    },
    {
      "name": "Rock_Quartzite_Brick_Smooth",
      "x": -2,
      "y": -6,
      "z": 7
    },
    {
      "name": "Rock_Quartzite_Brick_Smooth",
      "x": -2,
      "y": -5,
      "z": 7
    },
    {
      "name": "Rock_Quartzite_Brick_Smooth",
      "x": -2,
      "y": -4,
      "z": 7
    },
    {
      "name": "Rock_Quartzite_Brick_Smooth",
      "x": -2,
      "y": -3,
      "z": 7
    },
    {
      "name": "Rock_Quartzite_Brick_Smooth",
      "x": -2,
      "y": -2,
      "z": 7
    },
    {
      "name": "Rock_Quartzite_Brick",
      "x": -2,
      "y": -1,
      "z": 7
    },
    {
      "name": "Rock_Quartzite_Brick",
      "x": -2,
      "y": 0,
      "z": 7
    },
    {
      "name": "Empty",
      "x": -2,
      "y": 1,
      "z": 7
    },
    {
      "name": "Empty",
      "x": -2,
      "y": 2,
      "z": 7
    },
    {
      "name": "Empty",
      "x": -2,
      "y": 3,
      "z": 7
    },
    {
      "name": "Soil_Dirt",
      "x": -2,
      "y": -1,
      "z": 8
    },
    {
      "name": "Soil_Grass",
      "x": -2,
      "y": 0,
      "z": 8
    },
    {
      "name": "Empty",
      "x": -2,
      "y": 1,
      "z": 8
    },
    {
      "name": "Empty",
      "x": -2,
      "y": 2,
      "z": 8
    },
    {
      "name": "Empty",
      "x": -2,
      "y": 3,
      "z": 8
    },
    {
      "name": "Soil_Dirt",
      "x": -2,
      "y": -1,
      "z": 9
    },
    {
      "name": "Soil_Grass",
      "x": -2,
      "y": 0,
      "z": 9
    },
    {
      "name": "Empty",
      "x": -2,
      "y": 1,
      "z": 9
    },
    {
      "name": "Empty",
      "x": -2,
      "y": 2,
      "z": 9
    },
    {
      "name": "Empty",
      "x": -2,
      "y": 3,
      "z": 9
    },
    {
      "name": "Soil_Dirt",
      "x": -2,
      "y": 1,
      "z": 10
    },
    {
      "name": "Soil_Dirt",
      "x": -2,
      "y": 2,
      "z": 10
    },
    {
      "name": "Soil_Dirt",
      "x": -1,
      "y": 1,
      "z": -9
    },
    {
      "name": "Soil_Dirt",
      "x": -1,
      "y": 2,
      "z": -9
    },
    {
      "name": "Soil_Dirt",
      "x": -1,
      "y": -1,
      "z": -8
    },
    {
      "name": "Soil_Grass",
      "x": -1,
      "y": 0,
      "z": -8
    },
    {
      "name": "Empty",
      "x": -1,
      "y": 1,
      "z": -8
    },
    {
      "name": "Empty",
      "x": -1,
      "y": 2,
      "z": -8
    },
    {
      "name": "Empty",
      "x": -1,
      "y": 3,
      "z": -8
    },
    {
      "name": "Rock_Quartzite_Brick_Smooth",
      "x": -1,
      "y": -5,
      "z": -7
    },
    {
      "name": "Rock_Quartzite_Brick",
      "x": -1,
      "y": -3,
      "z": -7
    },
    {
      "name": "Rock_Quartzite_Brick",
      "x": -1,
      "y": -2,
      "z": -7
    },
    {
      "name": "Soil_Dirt",
      "x": -1,
      "y": -1,
      "z": -7
    },
    {
      "name": "Rock_Quartzite_Brick",
      "x": -1,
      "y": 0,
      "z": -7
    },
    {
      "name": "Plant_Moss_Rug_Green",
      "support": 15,
      "x": -1,
      "y": 1,
      "z": -7
    },
    {
      "name": "Empty",
      "x": -1,
      "y": 2,
      "z": -7
    },
    {
      "name": "Empty",
      "x": -1,
      "y": 3,
      "z": -7
    },
    {
      "name": "Rock_Quartzite_Brick_Smooth",
      "x": -1,
      "y": -20,
      "z": -6
    },
    {
      "name": "Rock_Quartzite_Brick_Smooth",
      "x": -1,
      "y": -19,
      "z": -6
    },
    {
      "name": "Rock_Quartzite_Brick_Smooth",
      "x": -1,
      "y": -18,
      "z": -6
    },
    {
      "name": "Rock_Quartzite_Brick_Smooth",
      "x": -1,
      "y": -17,
      "z": -6
    },
    {
      "name": "Rock_Quartzite_Brick_Smooth",
      "x": -1,
      "y": -16,
      "z": -6
    },
    {
      "name": "Rock_Quartzite_Brick_Smooth",
      "x": -1,
      "y": -15,
      "z": -6
    },
    {
      "name": "Rock_Quartzite_Brick_Smooth",
      "x": -1,
      "y": -14,
      "z": -6
    },
    {
      "name": "Rock_Quartzite_Brick_Smooth",
      "x": -1,
      "y": -13,
      "z": -6
    },
    {
      "name": "Rock_Quartzite_Brick_Smooth",
      "x": -1,
      "y": -12,
      "z": -6
    },
    {
      "name": "Rock_Quartzite_Brick_Smooth",
      "x": -1,
      "y": -11,
      "z": -6
    },
    {
      "name": "Rock_Quartzite_Brick_Smooth",
      "x": -1,
      "y": -10,
      "z": -6
    },
    {
      "name": "Rock_Quartzite_Brick_Smooth",
      "x": -1,
      "y": -9,
      "z": -6
    },
    {
      "name": "Rock_Quartzite_Brick_Smooth",
      "x": -1,
      "y": -8,
      "z": -6
    },
    {
      "name": "Rock_Quartzite_Brick_Smooth",
      "x": -1,
      "y": -7,
      "z": -6
    },
    {
      "name": "Rock_Quartzite_Brick_Smooth",
      "x": -1,
      "y": -6,
      "z": -6
    },
    {
      "name": "Rock_Quartzite_Brick_Smooth",
      "x": -1,
      "y": -5,
      "z": -6
    },
    {
      "name": "Rock_Quartzite_Brick_Smooth",
      "x": -1,
      "y": -4,
      "z": -6
    },
    {
      "name": "Rock_Quartzite_Brick",
      "x": -1,
      "y": -3,
      "z": -6
    },
    {
      "name": "Rock_Quartzite_Brick",
      "x": -1,
      "y": -2,
      "z": -6
    },
    {
      "name": "Rock_Quartzite_Brick",
      "x": -1,
      "y": -1,
      "z": -6
    },
    {
      "name": "Rock_Quartzite_Brick",
      "x": -1,
      "y": 0,
      "z": -6
    },
    {
      "name": "Empty",
      "x": -1,
      "y": 1,
      "z": -6
    },
    {
      "name": "Empty",
      "x": -1,
      "y": 2,
      "z": -6
    },
    {
      "name": "Empty",
      "x": -1,
      "y": 3,
      "z": -6
    },
    {
      "name": "Rock_Quartzite_Brick_Smooth",
      "x": -1,
      "y": -20,
      "z": -5
    },
    {
      "name": "Rock_Quartzite_Brick_Smooth",
      "x": -1,
      "y": -19,
      "z": -5
    },
    {
      "name": "Rock_Quartzite_Brick_Smooth",
      "x": -1,
      "y": -18,
      "z": -5
    },
    {
      "name": "Rock_Quartzite_Brick_Smooth",
      "x": -1,
      "y": -17,
      "z": -5
    },
    {
      "name": "Rock_Quartzite_Brick_Smooth",
      "x": -1,
      "y": -16,
      "z": -5
    },
    {
      "name": "Rock_Quartzite_Brick_Smooth",
      "x": -1,
      "y": -15,
      "z": -5
    },
    {
      "name": "Rock_Quartzite_Brick_Smooth",
      "x": -1,
      "y": -14,
      "z": -5
    },
    {
      "name": "Rock_Quartzite_Brick_Smooth",
      "x": -1,
      "y": -13,
      "z": -5
    },
    {
      "name": "Rock_Quartzite_Brick_Smooth",
      "x": -1,
      "y": -12,
      "z": -5
    },
    {
      "name": "Rock_Quartzite_Brick_Smooth",
      "x": -1,
      "y": -11,
      "z": -5
    },
    {
      "name": "Rock_Quartzite_Brick_Smooth",
      "x": -1,
      "y": -10,
      "z": -5
    },
    {
      "name": "Rock_Quartzite_Brick_Smooth",
      "x": -1,
      "y": -9,
      "z": -5
    },
    {
      "name": "Rock_Quartzite_Brick_Smooth",
      "x": -1,
      "y": -8,
      "z": -5
    },
    {
      "name": "Rock_Quartzite_Brick_Smooth",
      "x": -1,
      "y": -7,
      "z": -5
    },
    {
      "name": "Rock_Quartzite_Brick_Smooth",
      "x": -1,
      "y": -6,
      "z": -5
    },
    {
      "name": "Rock_Quartzite_Brick_Smooth",
      "x": -1,
      "y": -5,
      "z": -5
    },
    {
      "name": "Rock_Quartzite_Brick_Smooth",
      "x": -1,
      "y": -4,
      "z": -5
    },
    {
      "name": "Rock_Quartzite_Brick",
      "x": -1,
      "y": -3,
      "z": -5
    },
    {
      "name": "Rock_Quartzite_Brick",
      "x": -1,
      "y": -2,
      "z": -5
    },
    {
      "name": "Rock_Quartzite_Brick",
      "x": -1,
      "y": -1,
      "z": -5
    },
    {
      "name": "Rock_Quartzite_Brick",
      "x": -1,
      "y": 0,
      "z": -5
    },
    {
      "name": "Empty",
      "x": -1,
      "y": 1,
      "z": -5
    },
    {
      "name": "Empty",
      "x": -1,
      "y": 2,
      "z": -5
    },
    {
      "name": "Empty",
      "x": -1,
      "y": 3,
      "z": -5
    },
    {
      "name": "Rock_Quartzite_Brick_Smooth",
      "x": -1,
      "y": -20,
      "z": -4
    },
    {
      "name": "Rock_Quartzite_Brick_Smooth",
      "x": -1,
      "y": -19,
      "z": -4
    },
    {
      "name": "Rock_Quartzite_Brick_Smooth",
      "x": -1,
      "y": -18,
      "z": -4
    },
    {
      "name": "Rock_Quartzite_Brick_Smooth",
      "x": -1,
      "y": -17,
      "z": -4
    },
    {
      "name": "Rock_Quartzite_Brick_Smooth",
      "x": -1,
      "y": -16,
      "z": -4
    },
    {
      "name": "Rock_Quartzite_Brick_Smooth",
      "x": -1,
      "y": -15,
      "z": -4
    },
    {
      "name": "Rock_Quartzite_Brick_Smooth",
      "x": -1,
      "y": -14,
      "z": -4
    },
    {
      "name": "Rock_Quartzite_Brick_Smooth",
      "x": -1,
      "y": -13,
      "z": -4
    },
    {
      "name": "Rock_Quartzite_Brick_Smooth",
      "x": -1,
      "y": -12,
      "z": -4
    },
    {
      "name": "Rock_Quartzite_Brick_Smooth",
      "x": -1,
      "y": -11,
      "z": -4
    },
    {
      "name": "Rock_Quartzite_Brick_Smooth",
      "x": -1,
      "y": -10,
      "z": -4
    },
    {
      "name": "Rock_Quartzite_Brick_Smooth",
      "x": -1,
      "y": -9,
      "z": -4
    },
    {
      "name": "Rock_Quartzite_Brick_Smooth",
      "x": -1,
      "y": -8,
      "z": -4
    },
    {
      "name": "Rock_Quartzite_Brick_Smooth",
      "x": -1,
      "y": -7,
      "z": -4
    },
    {
      "name": "Rock_Quartzite_Brick_Smooth",
      "x": -1,
      "y": -6,
      "z": -4
    },
    {
      "name": "Rock_Quartzite_Brick_Smooth",
      "x": -1,
      "y": -5,
      "z": -4
    },
    {
      "name": "Rock_Quartzite_Brick_Smooth",
      "x": -1,
      "y": -4,
      "z": -4
    },
    {
      "name": "Rock_Quartzite_Brick",
      "x": -1,
      "y": -3,
      "z": -4
    },
    {
      "name": "Rock_Quartzite_Brick",
      "x": -1,
      "y": -2,
      "z": -4
    },
    {
      "name": "Rock_Quartzite_Brick",
      "x": -1,
      "y": -1,
      "z": -4
    },
    {
      "name": "Rock_Quartzite_Brick",
      "x": -1,
      "y": 0,
      "z": -4
    },
    {
      "name": "Plant_Moss_Rug_Green",
      "support": 15,
      "x": -1,
      "y": 1,
      "z": -4
    },
    {
      "name": "Empty",
      "x": -1,
      "y": 2,
      "z": -4
    },
    {
      "name": "Empty",
      "x": -1,
      "y": 3,
      "z": -4
    },
    {
      "name": "Rock_Quartzite_Brick_Smooth",
      "x": -1,
      "y": -20,
      "z": -3
    },
    {
      "name": "Rock_Quartzite_Brick_Smooth",
      "x": -1,
      "y": -19,
      "z": -3
    },
    {
      "name": "Rock_Quartzite_Brick_Smooth",
      "x": -1,
      "y": -18,
      "z": -3
    },
    {
      "name": "Rock_Quartzite_Brick_Smooth",
      "x": -1,
      "y": -17,
      "z": -3
    },
    {
      "name": "Rock_Quartzite_Brick_Smooth",
      "x": -1,
      "y": -16,
      "z": -3
    },
    {
      "name": "Rock_Quartzite_Brick_Smooth",
      "x": -1,
      "y": -15,
      "z": -3
    },
    {
      "name": "Rock_Quartzite_Brick_Smooth",
      "x": -1,
      "y": -14,
      "z": -3
    },
    {
      "name": "Rock_Quartzite_Brick_Smooth",
      "x": -1,
      "y": -13,
      "z": -3
    },
    {
      "name": "Rock_Quartzite_Brick_Smooth",
      "x": -1,
      "y": -12,
      "z": -3
    },
    {
      "name": "Rock_Quartzite_Brick_Smooth",
      "x": -1,
      "y": -11,
      "z": -3
    },
    {
      "name": "Rock_Quartzite_Brick_Smooth",
      "x": -1,
      "y": -10,
      "z": -3
    },
    {
      "name": "Rock_Quartzite_Brick_Smooth",
      "x": -1,
      "y": -9,
      "z": -3
    },
    {
      "name": "Rock_Quartzite_Brick_Smooth",
      "x": -1,
      "y": -8,
      "z": -3
    },
    {
      "name": "Rock_Quartzite_Brick_Smooth",
      "x": -1,
      "y": -7,
      "z": -3
    },
    {
      "name": "Rock_Quartzite_Brick_Smooth",
      "x": -1,
      "y": -6,
      "z": -3
    },
    {
      "name": "Rock_Quartzite_Brick_Smooth",
      "x": -1,
      "y": -5,
      "z": -3
    },
    {
      "name": "Rock_Quartzite_Brick_Smooth",
      "x": -1,
      "y": -4,
      "z": -3
    },
    {
      "name": "Rock_Quartzite_Brick",
      "x": -1,
      "y": -3,
      "z": -3
    },
    {
      "name": "Rock_Quartzite_Brick",
      "x": -1,
      "y": -2,
      "z": -3
    },
    {
      "name": "Rock_Quartzite_Brick",
      "x": -1,
      "y": -1,
      "z": -3
    },
    {
      "name": "Rock_Quartzite_Brick",
      "x": -1,
      "y": 0,
      "z": -3
    },
    {
      "name": "Empty",
      "x": -1,
      "y": 1,
      "z": -3
    },
    {
      "name": "Empty",
      "x": -1,
      "y": 2,
      "z": -3
    },
    {
      "name": "Empty",
      "x": -1,
      "y": 3,
      "z": -3
    },
    {
      "name": "Rock_Quartzite_Brick_Smooth",
      "x": -1,
      "y": -20,
      "z": -2
    },
    {
      "name": "Rock_Quartzite_Brick_Smooth",
      "x": -1,
      "y": -19,
      "z": -2
    },
    {
      "name": "Rock_Quartzite_Brick_Smooth",
      "x": -1,
      "y": -18,
      "z": -2
    },
    {
      "name": "Rock_Quartzite_Brick_Smooth",
      "x": -1,
      "y": -17,
      "z": -2
    },
    {
      "name": "Rock_Quartzite_Brick_Smooth",
      "x": -1,
      "y": -16,
      "z": -2
    },
    {
      "name": "Rock_Quartzite_Brick_Smooth",
      "x": -1,
      "y": -15,
      "z": -2
    },
    {
      "name": "Rock_Quartzite_Brick_Smooth",
      "x": -1,
      "y": -14,
      "z": -2
    },
    {
      "name": "Rock_Quartzite_Brick_Smooth",
      "x": -1,
      "y": -13,
      "z": -2
    },
    {
      "name": "Rock_Quartzite_Brick_Smooth",
      "x": -1,
      "y": -12,
      "z": -2
    },
    {
      "name": "Rock_Quartzite_Brick_Smooth",
      "x": -1,
      "y": -11,
      "z": -2
    },
    {
      "name": "Rock_Quartzite_Brick_Smooth",
      "x": -1,
      "y": -10,
      "z": -2
    },
    {
      "name": "Rock_Quartzite_Brick_Smooth",
      "x": -1,
      "y": -9,
      "z": -2
    },
    {
      "name": "Rock_Quartzite_Brick_Smooth",
      "x": -1,
      "y": -8,
      "z": -2
    },
    {
      "name": "Rock_Quartzite_Brick_Smooth",
      "x": -1,
      "y": -7,
      "z": -2
    },
    {
      "name": "Rock_Quartzite_Brick_Smooth",
      "x": -1,
      "y": -6,
      "z": -2
    },
    {
      "name": "Rock_Quartzite_Brick_Smooth",
      "x": -1,
      "y": -5,
      "z": -2
    },
    {
      "name": "Rock_Quartzite_Brick_Smooth",
      "x": -1,
      "y": -4,
      "z": -2
    },
    {
      "name": "Rock_Quartzite_Brick",
      "x": -1,
      "y": -3,
      "z": -2
    },
    {
      "name": "Rock_Quartzite_Brick",
      "x": -1,
      "y": -2,
      "z": -2
    },
    {
      "name": "Rock_Quartzite_Brick",
      "x": -1,
      "y": -1,
      "z": -2
    },
    {
      "name": "Rock_Quartzite_Brick",
      "x": -1,
      "y": 0,
      "z": -2
    },
    {
      "name": "Empty",
      "x": -1,
      "y": 1,
      "z": -2
    },
    {
      "name": "Empty",
      "x": -1,
      "y": 2,
      "z": -2
    },
    {
      "name": "Empty",
      "x": -1,
      "y": 3,
      "z": -2
    },
    {
      "name": "Rock_Quartzite_Brick_Smooth",
      "x": -1,
      "y": -20,
      "z": -1
    },
    {
      "name": "Rock_Quartzite_Brick_Smooth",
      "x": -1,
      "y": -19,
      "z": -1
    },
    {
      "name": "Rock_Quartzite_Brick_Smooth",
      "x": -1,
      "y": -18,
      "z": -1
    },
    {
      "name": "Rock_Quartzite_Brick_Smooth",
      "x": -1,
      "y": -17,
      "z": -1
    },
    {
      "name": "Rock_Quartzite_Brick_Smooth",
      "x": -1,
      "y": -16,
      "z": -1
    },
    {
      "name": "Rock_Quartzite_Brick_Smooth",
      "x": -1,
      "y": -15,
      "z": -1
    },
    {
      "name": "Rock_Quartzite_Brick_Smooth",
      "x": -1,
      "y": -14,
      "z": -1
    },
    {
      "name": "Rock_Quartzite_Brick_Smooth",
      "x": -1,
      "y": -13,
      "z": -1
    },
    {
      "name": "Rock_Quartzite_Brick_Smooth",
      "x": -1,
      "y": -12,
      "z": -1
    },
    {
      "name": "Rock_Quartzite_Brick_Smooth",
      "x": -1,
      "y": -11,
      "z": -1
    },
    {
      "name": "Rock_Quartzite_Brick_Smooth",
      "x": -1,
      "y": -10,
      "z": -1
    },
    {
      "name": "Rock_Quartzite_Brick_Smooth",
      "x": -1,
      "y": -9,
      "z": -1
    },
    {
      "name": "Rock_Quartzite_Brick_Smooth",
      "x": -1,
      "y": -8,
      "z": -1
    },
    {
      "name": "Rock_Quartzite_Brick_Smooth",
      "x": -1,
      "y": -7,
      "z": -1
    },
    {
      "name": "Rock_Quartzite_Brick_Smooth",
      "x": -1,
      "y": -6,
      "z": -1
    },
    {
      "name": "Rock_Quartzite_Brick_Smooth",
      "x": -1,
      "y": -5,
      "z": -1
    },
    {
      "name": "Rock_Quartzite_Brick_Smooth",
      "x": -1,
      "y": -4,
      "z": -1
    },
    {
      "name": "Rock_Quartzite_Brick",
      "x": -1,
      "y": -3,
      "z": -1
    },
    {
      "name": "Rock_Quartzite_Brick",
      "x": -1,
      "y": -2,
      "z": -1
    },
    {
      "name": "Rock_Quartzite_Brick",
      "x": -1,
      "y": -1,
      "z": -1
    },
    {
      "name": "Rock_Quartzite_Brick",
      "x": -1,
      "y": 0,
      "z": -1
    },
    {
      "name": "Empty",
      "x": -1,
      "y": 1,
      "z": -1
    },
    {
      "name": "Empty",
      "x": -1,
      "y": 2,
      "z": -1
    },
    {
      "name": "Empty",
      "x": -1,
      "y": 3,
      "z": -1
    },
    {
      "name": "Rock_Quartzite_Brick_Smooth",
      "x": -1,
      "y": -20,
      "z": 0
    },
    {
      "name": "Rock_Quartzite_Brick_Smooth",
      "x": -1,
      "y": -19,
      "z": 0
    },
    {
      "name": "Rock_Quartzite_Brick_Smooth",
      "x": -1,
      "y": -18,
      "z": 0
    },
    {
      "name": "Rock_Quartzite_Brick_Smooth",
      "x": -1,
      "y": -17,
      "z": 0
    },
    {
      "name": "Rock_Quartzite_Brick_Smooth",
      "x": -1,
      "y": -16,
      "z": 0
    },
    {
      "name": "Rock_Quartzite_Brick_Smooth",
      "x": -1,
      "y": -15,
      "z": 0
    },
    {
      "name": "Rock_Quartzite_Brick_Smooth",
      "x": -1,
      "y": -14,
      "z": 0
    },
    {
      "name": "Rock_Quartzite_Brick_Smooth",
      "x": -1,
      "y": -13,
      "z": 0
    },
    {
      "name": "Rock_Quartzite_Brick_Smooth",
      "x": -1,
      "y": -12,
      "z": 0
    },
    {
      "name": "Rock_Quartzite_Brick_Smooth",
      "x": -1,
      "y": -11,
      "z": 0
    },
    {
      "name": "Rock_Quartzite_Brick_Smooth",
      "x": -1,
      "y": -10,
      "z": 0
    },
    {
      "name": "Rock_Quartzite_Brick_Smooth",
      "x": -1,
      "y": -9,
      "z": 0
    },
    {
      "name": "Rock_Quartzite_Brick_Smooth",
      "x": -1,
      "y": -8,
      "z": 0
    },
    {
      "name": "Rock_Quartzite_Brick_Smooth",
      "x": -1,
      "y": -7,
      "z": 0
    },
    {
      "name": "Rock_Quartzite_Brick_Smooth",
      "x": -1,
      "y": -6,
      "z": 0
    },
    {
      "name": "Rock_Quartzite_Brick_Smooth",
      "x": -1,
      "y": -5,
      "z": 0
    },
    {
      "name": "Rock_Quartzite_Brick_Smooth",
      "x": -1,
      "y": -4,
      "z": 0
    },
    {
      "name": "Rock_Quartzite_Brick",
      "x": -1,
      "y": -3,
      "z": 0
    },
    {
      "name": "Rock_Quartzite_Brick",
      "x": -1,
      "y": -2,
      "z": 0
    },
    {
      "name": "Rock_Quartzite_Brick",
      "x": -1,
      "y": -1,
      "z": 0
    },
    {
      "name": "Rock_Quartzite_Brick_Ornate",
      "x": -1,
      "y": 0,
      "z": 0
    },
    {
      "name": "Empty",
      "x": -1,
      "y": 1,
      "z": 0
    },
    {
      "name": "Empty",
      "x": -1,
      "y": 2,
      "z": 0
    },
    {
      "name": "Empty",
      "x": -1,
      "y": 3,
      "z": 0
    },
    {
      "name": "Rock_Quartzite_Brick_Smooth",
      "x": -1,
      "y": -20,
      "z": 1
    },
    {
      "name": "Rock_Quartzite_Brick_Smooth",
      "x": -1,
      "y": -19,
      "z": 1
    },
    {
      "name": "Rock_Quartzite_Brick_Smooth",
      "x": -1,
      "y": -18,
      "z": 1
    },
    {
      "name": "Rock_Quartzite_Brick_Smooth",
      "x": -1,
      "y": -17,
      "z": 1
    },
    {
      "name": "Rock_Quartzite_Brick_Smooth",
      "x": -1,
      "y": -16,
      "z": 1
    },
    {
      "name": "Rock_Quartzite_Brick_Smooth",
      "x": -1,
      "y": -15,
      "z": 1
    },
    {
      "name": "Rock_Quartzite_Brick_Smooth",
      "x": -1,
      "y": -14,
      "z": 1
    },
    {
      "name": "Rock_Quartzite_Brick_Smooth",
      "x": -1,
      "y": -13,
      "z": 1
    },
    {
      "name": "Rock_Quartzite_Brick_Smooth",
      "x": -1,
      "y": -12,
      "z": 1
    },
    {
      "name": "Rock_Quartzite_Brick_Smooth",
      "x": -1,
      "y": -11,
      "z": 1
    },
    {
      "name": "Rock_Quartzite_Brick_Smooth",
      "x": -1,
      "y": -10,
      "z": 1
    },
    {
      "name": "Rock_Quartzite_Brick_Smooth",
      "x": -1,
      "y": -9,
      "z": 1
    },
    {
      "name": "Rock_Quartzite_Brick_Smooth",
      "x": -1,
      "y": -8,
      "z": 1
    },
    {
      "name": "Rock_Quartzite_Brick_Smooth",
      "x": -1,
      "y": -7,
      "z": 1
    },
    {
      "name": "Rock_Quartzite_Brick_Smooth",
      "x": -1,
      "y": -6,
      "z": 1
    },
    {
      "name": "Rock_Quartzite_Brick_Smooth",
      "x": -1,
      "y": -5,
      "z": 1
    },
    {
      "name": "Rock_Quartzite_Brick_Smooth",
      "x": -1,
      "y": -4,
      "z": 1
    },
    {
      "name": "Rock_Quartzite_Brick",
      "x": -1,
      "y": -3,
      "z": 1
    },
    {
      "name": "Rock_Quartzite_Brick",
      "x": -1,
      "y": -2,
      "z": 1
    },
    {
      "name": "Rock_Quartzite_Brick",
      "x": -1,
      "y": -1,
      "z": 1
    },
    {
      "name": "Rock_Quartzite_Brick_Smooth",
      "x": -1,
      "y": 0,
      "z": 1
    },
    {
      "name": "Empty",
      "x": -1,
      "y": 1,
      "z": 1
    },
    {
      "name": "Empty",
      "x": -1,
      "y": 2,
      "z": 1
    },
    {
      "name": "Empty",
      "x": -1,
      "y": 3,
      "z": 1
    },
    {
      "name": "Rock_Quartzite_Brick_Smooth",
      "x": -1,
      "y": -20,
      "z": 2
    },
    {
      "name": "Rock_Quartzite_Brick_Smooth",
      "x": -1,
      "y": -19,
      "z": 2
    },
    {
      "name": "Rock_Quartzite_Brick_Smooth",
      "x": -1,
      "y": -18,
      "z": 2
    },
    {
      "name": "Rock_Quartzite_Brick_Smooth",
      "x": -1,
      "y": -17,
      "z": 2
    },
    {
      "name": "Rock_Quartzite_Brick_Smooth",
      "x": -1,
      "y": -16,
      "z": 2
    },
    {
      "name": "Rock_Quartzite_Brick_Smooth",
      "x": -1,
      "y": -15,
      "z": 2
    },
    {
      "name": "Rock_Quartzite_Brick_Smooth",
      "x": -1,
      "y": -14,
      "z": 2
    },
    {
      "name": "Rock_Quartzite_Brick_Smooth",
      "x": -1,
      "y": -13,
      "z": 2
    },
    {
      "name": "Rock_Quartzite_Brick_Smooth",
      "x": -1,
      "y": -12,
      "z": 2
    },
    {
      "name": "Rock_Quartzite_Brick_Smooth",
      "x": -1,
      "y": -11,
      "z": 2
    },
    {
      "name": "Rock_Quartzite_Brick_Smooth",
      "x": -1,
      "y": -10,
      "z": 2
    },
    {
      "name": "Rock_Quartzite_Brick_Smooth",
      "x": -1,
      "y": -9,
      "z": 2
    },
    {
      "name": "Rock_Quartzite_Brick_Smooth",
      "x": -1,
      "y": -8,
      "z": 2
    },
    {
      "name": "Rock_Quartzite_Brick_Smooth",
      "x": -1,
      "y": -7,
      "z": 2
    },
    {
      "name": "Rock_Quartzite_Brick_Smooth",
      "x": -1,
      "y": -6,
      "z": 2
    },
    {
      "name": "Rock_Quartzite_Brick_Smooth",
      "x": -1,
      "y": -5,
      "z": 2
    },
    {
      "name": "Rock_Quartzite_Brick_Smooth",
      "x": -1,
      "y": -4,
      "z": 2
    },
    {
      "name": "Rock_Quartzite_Brick",
      "x": -1,
      "y": -2,
      "z": 2
    },
    {
      "name": "Rock_Quartzite_Brick",
      "x": -1,
      "y": -1,
      "z": 2
    },
    {
      "name": "Rock_Quartzite_Brick_Smooth",
      "x": -1,
      "y": 0,
      "z": 2
    },
    {
      "name": "Empty",
      "rotation": 2,
      "x": -1,
      "y": 1,
      "z": 2
    },
    {
      "name": "Empty",
      "x": -1,
      "y": 2,
      "z": 2
    },
    {
      "name": "Empty",
      "x": -1,
      "y": 3,
      "z": 2
    },
    {
      "name": "Rock_Quartzite_Brick_Smooth",
      "x": -1,
      "y": -20,
      "z": 3
    },
    {
      "name": "Rock_Quartzite_Brick_Smooth",
      "x": -1,
      "y": -19,
      "z": 3
    },
    {
      "name": "Rock_Quartzite_Brick_Smooth",
      "x": -1,
      "y": -18,
      "z": 3
    },
    {
      "name": "Rock_Quartzite_Brick_Smooth",
      "x": -1,
      "y": -17,
      "z": 3
    },
    {
      "name": "Rock_Quartzite_Brick_Smooth",
      "x": -1,
      "y": -16,
      "z": 3
    },
    {
      "name": "Rock_Quartzite_Brick_Smooth",
      "x": -1,
      "y": -15,
      "z": 3
    },
    {
      "name": "Rock_Quartzite_Brick_Smooth",
      "x": -1,
      "y": -14,
      "z": 3
    },
    {
      "name": "Rock_Quartzite_Brick_Smooth",
      "x": -1,
      "y": -13,
      "z": 3
    },
    {
      "name": "Rock_Quartzite_Brick_Smooth",
      "x": -1,
      "y": -12,
      "z": 3
    },
    {
      "name": "Rock_Quartzite_Brick_Smooth",
      "x": -1,
      "y": -11,
      "z": 3
    },
    {
      "name": "Rock_Quartzite_Brick_Smooth",
      "x": -1,
      "y": -10,
      "z": 3
    },
    {
      "name": "Rock_Quartzite_Brick_Smooth",
      "x": -1,
      "y": -9,
      "z": 3
    },
    {
      "name": "Rock_Quartzite_Brick_Smooth",
      "x": -1,
      "y": -8,
      "z": 3
    },
    {
      "name": "Rock_Quartzite_Brick_Smooth",
      "x": -1,
      "y": -7,
      "z": 3
    },
    {
      "name": "Rock_Quartzite_Brick_Smooth",
      "x": -1,
      "y": -6,
      "z": 3
    },
    {
      "name": "Rock_Quartzite_Brick_Smooth",
      "x": -1,
      "y": -5,
      "z": 3
    },
    {
      "name": "Rock_Quartzite_Brick_Smooth",
      "x": -1,
      "y": -4,
      "z": 3
    },
    {
      "name": "Rock_Quartzite_Brick",
      "x": -1,
      "y": -2,
      "z": 3
    },
    {
      "name": "Rock_Quartzite_Brick",
      "x": -1,
      "y": -1,
      "z": 3
    },
    {
      "name": "Rock_Quartzite_Brick_Smooth",
      "x": -1,
      "y": 0,
      "z": 3
    },
    {
      "name": "Empty",
      "rotation": 2,
      "x": -1,
      "y": 1,
      "z": 3
    },
    {
      "name": "Empty",
      "x": -1,
      "y": 2,
      "z": 3
    },
    {
      "name": "Empty",
      "x": -1,
      "y": 3,
      "z": 3
    },
    {
      "name": "Rock_Quartzite_Brick_Smooth",
      "x": -1,
      "y": -20,
      "z": 4
    },
    {
      "name": "Rock_Quartzite_Brick_Smooth",
      "x": -1,
      "y": -19,
      "z": 4
    },
    {
      "name": "Rock_Quartzite_Brick_Smooth",
      "x": -1,
      "y": -18,
      "z": 4
    },
    {
      "name": "Rock_Quartzite_Brick_Smooth",
      "x": -1,
      "y": -17,
      "z": 4
    },
    {
      "name": "Rock_Quartzite_Brick_Smooth",
      "x": -1,
      "y": -16,
      "z": 4
    },
    {
      "name": "Rock_Quartzite_Brick_Smooth",
      "x": -1,
      "y": -15,
      "z": 4
    },
    {
      "name": "Rock_Quartzite_Brick_Smooth",
      "x": -1,
      "y": -14,
      "z": 4
    },
    {
      "name": "Rock_Quartzite_Brick_Smooth",
      "x": -1,
      "y": -13,
      "z": 4
    },
    {
      "name": "Rock_Quartzite_Brick_Smooth",
      "x": -1,
      "y": -12,
      "z": 4
    },
    {
      "name": "Rock_Quartzite_Brick_Smooth",
      "x": -1,
      "y": -11,
      "z": 4
    },
    {
      "name": "Rock_Quartzite_Brick_Smooth",
      "x": -1,
      "y": -10,
      "z": 4
    },
    {
      "name": "Rock_Quartzite_Brick_Smooth",
      "x": -1,
      "y": -9,
      "z": 4
    },
    {
      "name": "Rock_Quartzite_Brick_Smooth",
      "x": -1,
      "y": -8,
      "z": 4
    },
    {
      "name": "Rock_Quartzite_Brick_Smooth",
      "x": -1,
      "y": -7,
      "z": 4
    },
    {
      "name": "Rock_Quartzite_Brick_Smooth",
      "x": -1,
      "y": -6,
      "z": 4
    },
    {
      "name": "Rock_Quartzite_Brick_Smooth",
      "x": -1,
      "y": -5,
      "z": 4
    },
    {
      "name": "Rock_Quartzite_Brick_Smooth",
      "x": -1,
      "y": -4,
      "z": 4
    },
    {
      "name": "Rock_Quartzite_Brick",
      "x": -1,
      "y": -3,
      "z": 4
    },
    {
      "name": "Rock_Quartzite_Brick",
      "x": -1,
      "y": -2,
      "z": 4
    },
    {
      "name": "Rock_Quartzite_Brick",
      "x": -1,
      "y": -1,
      "z": 4
    },
    {
      "name": "Rock_Quartzite_Brick_Smooth",
      "x": -1,
      "y": 0,
      "z": 4
    },
    {
      "name": "Empty",
      "rotation": 2,
      "x": -1,
      "y": 1,
      "z": 4
    },
    {
      "name": "Empty",
      "x": -1,
      "y": 2,
      "z": 4
    },
    {
      "name": "Empty",
      "x": -1,
      "y": 3,
      "z": 4
    },
    {
      "name": "Rock_Quartzite_Brick_Smooth",
      "x": -1,
      "y": -20,
      "z": 5
    },
    {
      "name": "Rock_Quartzite_Brick_Smooth",
      "x": -1,
      "y": -19,
      "z": 5
    },
    {
      "name": "Rock_Quartzite_Brick_Smooth",
      "x": -1,
      "y": -18,
      "z": 5
    },
    {
      "name": "Rock_Quartzite_Brick_Smooth",
      "x": -1,
      "y": -17,
      "z": 5
    },
    {
      "name": "Rock_Quartzite_Brick_Smooth",
      "x": -1,
      "y": -16,
      "z": 5
    },
    {
      "name": "Rock_Quartzite_Brick_Smooth",
      "x": -1,
      "y": -15,
      "z": 5
    },
    {
      "name": "Rock_Quartzite_Brick_Smooth",
      "x": -1,
      "y": -14,
      "z": 5
    },
    {
      "name": "Rock_Quartzite_Brick_Smooth",
      "x": -1,
      "y": -13,
      "z": 5
    },
    {
      "name": "Rock_Quartzite_Brick_Smooth",
      "x": -1,
      "y": -12,
      "z": 5
    },
    {
      "name": "Rock_Quartzite_Brick_Smooth",
      "x": -1,
      "y": -11,
      "z": 5
    },
    {
      "name": "Rock_Quartzite_Brick_Smooth",
      "x": -1,
      "y": -10,
      "z": 5
    },
    {
      "name": "Rock_Quartzite_Brick_Smooth",
      "x": -1,
      "y": -9,
      "z": 5
    },
    {
      "name": "Rock_Quartzite_Brick_Smooth",
      "x": -1,
      "y": -8,
      "z": 5
    },
    {
      "name": "Rock_Quartzite_Brick_Smooth",
      "x": -1,
      "y": -7,
      "z": 5
    },
    {
      "name": "Rock_Quartzite_Brick_Smooth",
      "x": -1,
      "y": -6,
      "z": 5
    },
    {
      "name": "Rock_Quartzite_Brick_Smooth",
      "x": -1,
      "y": -5,
      "z": 5
    },
    {
      "name": "Rock_Quartzite_Brick_Smooth",
      "x": -1,
      "y": -4,
      "z": 5
    },
    {
      "name": "Rock_Quartzite_Brick",
      "x": -1,
      "y": -3,
      "z": 5
    },
    {
      "name": "Rock_Quartzite_Brick",
      "x": -1,
      "y": -2,
      "z": 5
    },
    {
      "name": "Rock_Quartzite_Brick",
      "x": -1,
      "y": -1,
      "z": 5
    },
    {
      "name": "Rock_Quartzite_Brick_Smooth",
      "x": -1,
      "y": 0,
      "z": 5
    },
    {
      "name": "Empty",
      "x": -1,
      "y": 1,
      "z": 5
    },
    {
      "name": "Empty",
      "x": -1,
      "y": 2,
      "z": 5
    },
    {
      "name": "Empty",
      "x": -1,
      "y": 3,
      "z": 5
    },
    {
      "name": "Rock_Quartzite_Brick_Smooth",
      "x": -1,
      "y": -20,
      "z": 6
    },
    {
      "name": "Rock_Quartzite_Brick_Smooth",
      "x": -1,
      "y": -19,
      "z": 6
    },
    {
      "name": "Rock_Quartzite_Brick_Smooth",
      "x": -1,
      "y": -18,
      "z": 6
    },
    {
      "name": "Rock_Quartzite_Brick_Smooth",
      "x": -1,
      "y": -17,
      "z": 6
    },
    {
      "name": "Rock_Quartzite_Brick_Smooth",
      "x": -1,
      "y": -16,
      "z": 6
    },
    {
      "name": "Rock_Quartzite_Brick_Smooth",
      "x": -1,
      "y": -15,
      "z": 6
    },
    {
      "name": "Rock_Quartzite_Brick_Smooth",
      "x": -1,
      "y": -14,
      "z": 6
    },
    {
      "name": "Rock_Quartzite_Brick_Smooth",
      "x": -1,
      "y": -13,
      "z": 6
    },
    {
      "name": "Rock_Quartzite_Brick_Smooth",
      "x": -1,
      "y": -12,
      "z": 6
    },
    {
      "name": "Rock_Quartzite_Brick_Smooth",
      "x": -1,
      "y": -11,
      "z": 6
    },
    {
      "name": "Rock_Quartzite_Brick_Smooth",
      "x": -1,
      "y": -10,
      "z": 6
    },
    {
      "name": "Rock_Quartzite_Brick_Smooth",
      "x": -1,
      "y": -9,
      "z": 6
    },
    {
      "name": "Rock_Quartzite_Brick_Smooth",
      "x": -1,
      "y": -8,
      "z": 6
    },
    {
      "name": "Rock_Quartzite_Brick_Smooth",
      "x": -1,
      "y": -7,
      "z": 6
    },
    {
      "name": "Rock_Quartzite_Brick_Smooth",
      "x": -1,
      "y": -6,
      "z": 6
    },
    {
      "name": "Rock_Quartzite_Brick_Smooth",
      "x": -1,
      "y": -5,
      "z": 6
    },
    {
      "name": "Rock_Quartzite_Brick_Smooth",
      "x": -1,
      "y": -4,
      "z": 6
    },
    {
      "name": "Rock_Quartzite_Brick",
      "x": -1,
      "y": -3,
      "z": 6
    },
    {
      "name": "Rock_Quartzite_Brick",
      "x": -1,
      "y": -2,
      "z": 6
    },
    {
      "name": "Rock_Quartzite_Brick",
      "x": -1,
      "y": -1,
      "z": 6
    },
    {
      "name": "Rock_Quartzite_Brick_Ornate",
      "x": -1,
      "y": 0,
      "z": 6
    },
    {
      "name": "Rock_Quartzite_Brick_Wall",
      "rotation": 2,
      "x": -1,
      "y": 1,
      "z": 6
    },
    {
      "name": "Empty",
      "x": -1,
      "y": 2,
      "z": 6
    },
    {
      "name": "Empty",
      "x": -1,
      "y": 3,
      "z": 6
    },
    {
      "name": "Rock_Quartzite_Brick_Smooth",
      "x": -1,
      "y": -6,
      "z": 7
    },
    {
      "name": "Rock_Quartzite_Brick_Smooth",
      "x": -1,
      "y": -5,
      "z": 7
    },
    {
      "name": "Soil_Dirt",
      "x": -1,
      "y": -1,
      "z": 7
    },
    {
      "name": "Rock_Quartzite_Brick",
      "x": -1,
      "y": 0,
      "z": 7
    },
    {
      "name": "Empty",
      "x": -1,
      "y": 1,
      "z": 7
    },
    {
      "name": "Empty",
      "x": -1,
      "y": 2,
      "z": 7
    },
    {
      "name": "Empty",
      "x": -1,
      "y": 3,
      "z": 7
    },
    {
      "name": "Soil_Dirt",
      "x": -1,
      "y": -1,
      "z": 8
    },
    {
      "name": "Soil_Grass",
      "x": -1,
      "y": 0,
      "z": 8
    },
    {
