{
  "version": 8,
  "blockIdVersion": 11,
  "anchorX": 0,
  "anchorY": 5,
  "anchorZ": 2,
  "blocks": [
    {
      "x": -8,
      "y": 5,
      "z": -7,
      "name": "Soil_Dirt_Dry"
    },
    {
      "x": -8,
      "y": 6,
      "z": -7,
      "name": "Furniture_Village_Pot"
    },
    {
      "x": -8,
      "y": 8,
      "z": -7,
      "name": "Cloth_Roof_Orange",
      "rotation": 3
    },
    {
      "x": -8,
      "y": 5,
      "z": -6,
      "name": "Soil_Dirt_Dry"
    },
    {
      "x": -8,
      "y": 6,
      "z": -6,
      "name": "Furniture_Ancient_Pot"
    },
    {
      "x": -8,
      "y": 8,
      "z": -6,
      "name": "Cloth_Roof_Orange",
      "rotation": 3
    },
    {
      "x": -8,
      "y": 5,
      "z": -5,
      "name": "Soil_Dirt_Dry"
    },
    {
      "x": -8,
      "y": 8,
      "z": -5,
      "name": "Cloth_Roof_Orange",
      "rotation": 3
    },
    {
      "x": -8,
      "y": 5,
      "z": -4,
      "name": "Soil_Dirt_Dry"
    },
    {
      "x": -8,
      "y": 6,
      "z": -4,
      "name": "Cloth_Roof_Orange_Flap",
      "rotation": 2
    },
    {
      "x": -8,
      "y": 7,
      "z": -4,
      "name": "Cloth_Roof_Orange_Vertical",
      "rotation": 2
    },
    {
      "x": -8,
      "y": 8,
      "z": -4,
      "name": "*Cloth_Roof_Orange_State_Definitions_Corner_Right"
    },
    {
      "x": -7,
      "y": 5,
      "z": -7,
      "name": "Soil_Dirt_Dry"
    },
    {
      "x": -7,
      "y": 9,
      "z": -7,
      "name": "Cloth_Roof_Orange_Flat"
    },
    {
      "x": -7,
      "y": 5,
      "z": -6,
      "name": "Soil_Dirt_Dry"
    },
    {
      "x": -7,
      "y": 5,
      "z": -5,
      "name": "Soil_Dirt_Dry"
    },
    {
      "x": -7,
      "y": 6,
      "z": -5,
      "name": "Wood_Drywood_Beam"
    },
    {
      "x": -7,
      "y": 7,
      "z": -5,
      "name": "Wood_Drywood_Beam"
    },
    {
      "x": -7,
      "y": 8,
      "z": -5,
      "name": "Wood_Drywood_Beam"
    },
    {
      "x": -7,
      "y": 9,
      "z": -5,
      "name": "Cloth_Roof_Orange_Flat"
    },
    {
      "x": -7,
      "y": 5,
      "z": -4,
      "name": "Soil_Dirt_Dry"
    },
    {
      "x": -7,
      "y": 6,
      "z": -4,
      "name": "Furniture_Village_Pot"
    },
    {
      "x": -7,
      "y": 7,
      "z": -4,
      "name": "Cloth_Roof_Orange_Vertical",
      "rotation": 2
    },
    {
      "x": -7,
      "y": 8,
      "z": -4,
      "name": "Cloth_Roof_Orange"
    },
    {
      "x": -7,
      "y": 5,
      "z": -3,
      "name": "Rock_Sandstone_Brick"
    },
    {
      "x": -7,
      "y": 6,
      "z": -3,
      "name": "Rock_Sandstone_Brick"
    },
    {
      "x": -7,
      "y": 7,
      "z": -3,
      "name": "Rock_Sandstone_Brick_Stairs",
      "rotation": 3
    },
    {
      "x": -6,
      "y": 5,
      "z": -7,
      "name": "Soil_Dirt_Dry"
    },
    {
      "x": -6,
      "y": 9,
      "z": -7,
      "name": "Cloth_Roof_Orange",
      "rotation": 3
    },
    {
      "x": -6,
      "y": 5,
      "z": -6,
      "name": "Soil_Dirt_Dry"
    },
    {
      "x": -6,
      "y": 9,
      "z": -6,
      "name": "Cloth_Roof_Orange",
      "rotation": 3
    },
    {
      "x": -6,
      "y": 5,
      "z": -5,
      "name": "Soil_Dirt_Dry"
    },
    {
      "x": -6,
      "y": 6,
      "z": -5,
      "name": "Furniture_Temple_Wind_Pot"
    },
    {
      "x": -6,
      "y": 7,
      "z": -5,
      "name": "Furniture_Temple_Wind_Pot",
      "filler": 1024
    },
    {
      "x": -6,
      "y": 9,
      "z": -5,
      "name": "*Cloth_Roof_Orange_State_Definitions_Corner_Right"
    },
    {
      "x": -6,
      "y": 5,
      "z": -4,
      "name": "Soil_Dirt_Dry"
    },
    {
      "x": -6,
      "y": 6,
      "z": -4,
      "name": "Furniture_Village_Pot"
    },
    {
      "x": -6,
      "y": 7,
      "z": -4,
      "name": "Cloth_Roof_Orange_Vertical",
      "rotation": 2
    },
    {
      "x": -6,
      "y": 8,
      "z": -4,
      "name": "Cloth_Roof_Orange"
    },
    {
      "x": -6,
      "y": 5,
      "z": -3,
      "name": "Rock_Sandstone_Brick"
    },
    {
      "x": -6,
      "y": 6,
      "z": -3,
      "name": "Rock_Sandstone_Brick"
    },
    {
      "x": -6,
      "y": 7,
      "z": -3,
      "name": "Rock_Sandstone_Brick"
    },
    {
      "x": -6,
      "y": 8,
      "z": -3,
      "name": "Rock_Sandstone_Brick_Stairs",
      "rotation": 3
    },
    {
      "x": -6,
      "y": 21,
      "z": -1,
      "name": "Wood_Dry_Branch_Short",
      "rotation": 3
    },
    {
      "x": -6,
      "y": 5,
      "z": 3,
      "name": "Rock_Sandstone_Cobble"
    },
    {
      "x": -6,
      "y": 6,
      "z": 3,
      "name": "Rock_Sandstone_Brick"
    },
    {
      "x": -6,
      "y": 7,
      "z": 3,
      "name": "Rock_Sandstone_Brick"
    },
    {
      "x": -6,
      "y": 8,
      "z": 3,
      "name": "Rock_Sandstone_Brick"
    },
    {
      "x": -6,
      "y": 9,
      "z": 3,
      "name": "Rock_Sandstone_Brick"
    },
    {
      "x": -6,
      "y": 10,
      "z": 3,
      "name": "Rock_Sandstone_Brick"
    },
    {
      "x": -6,
      "y": 11,
      "z": 3,
      "name": "Rock_Sandstone_Brick_Half",
      "rotation": 7
    },
    {
      "x": -6,
      "y": 12,
      "z": 3,
      "name": "Rock_Sandstone_Brick_Half",
      "rotation": 7
    },
    {
      "x": -6,
      "y": 13,
      "z": 3,
      "name": "Rock_Sandstone_Brick_Half",
      "rotation": 7
    },
    {
      "x": -6,
      "y": 14,
      "z": 3,
      "name": "Rock_Sandstone_Brick_Half",
      "rotation": 7
    },
    {
      "x": -6,
      "y": 15,
      "z": 3,
      "name": "Rock_Sandstone_Brick_Half",
      "rotation": 7
    },
    {
      "x": -6,
      "y": 21,
      "z": 3,
      "name": "Wood_Dry_Branch_Short",
      "rotation": 3
    },
    {
      "x": -6,
      "y": 5,
      "z": 4,
      "name": "Rock_Sandstone_Cobble"
    },
    {
      "x": -6,
      "y": 6,
      "z": 4,
      "name": "Rock_Sandstone_Brick"
    },
    {
      "x": -6,
      "y": 7,
      "z": 4,
      "name": "Rock_Sandstone_Brick"
    },
    {
      "x": -6,
      "y": 8,
      "z": 4,
      "name": "Rock_Sandstone_Brick"
    },
    {
      "x": -6,
      "y": 9,
      "z": 4,
      "name": "Rock_Sandstone_Brick"
    },
    {
      "x": -6,
      "y": 10,
      "z": 4,
      "name": "Rock_Sandstone_Brick"
    },
    {
      "x": -6,
      "y": 11,
      "z": 4,
      "name": "Rock_Sandstone_Brick_Half",
      "rotation": 7
    },
    {
      "x": -6,
      "y": 12,
      "z": 4,
      "name": "Rock_Sandstone_Brick_Half",
      "rotation": 7
    },
    {
      "x": -6,
      "y": 13,
      "z": 4,
      "name": "Rock_Sandstone_Brick_Half",
      "rotation": 7
    },
    {
      "x": -6,
      "y": 14,
      "z": 4,
      "name": "Rock_Sandstone_Brick_Half",
      "rotation": 7
    },
    {
      "x": -6,
      "y": 15,
      "z": 4,
      "name": "Rock_Sandstone_Brick_Half",
      "rotation": 7
    },
    {
      "x": -6,
      "y": 17,
      "z": 5,
      "name": "Rock_Sandstone_Brick_Smooth_Half",
      "rotation": 7
    },
    {
      "x": -6,
      "y": 19,
      "z": 5,
      "name": "Wood_Drywood_Roof_Hollow",
      "rotation": 3
    },
    {
      "x": -6,
      "y": 17,
      "z": 6,
      "name": "Rock_Sandstone_Brick_Smooth_Half",
      "rotation": 7
    },
    {
      "x": -6,
      "y": 19,
      "z": 6,
      "name": "Wood_Drywood_Roof_Hollow",
      "rotation": 3
    },
    {
      "x": -6,
      "y": 21,
      "z": 7,
      "name": "Wood_Dry_Branch_Short",
      "rotation": 3
    },
    {
      "x": -5,
      "y": 5,
      "z": -7,
      "name": "Soil_Dirt_Dry"
    },
    {
      "x": -5,
      "y": 6,
      "z": -7,
      "name": "Bench_WorkBench",
      "filler": 992,
      "rotation": 3
    },
    {
      "x": -5,
      "y": 9,
      "z": -7,
      "name": "Rock_Sandstone_Brick_Stairs",
      "rotation": 10
    },
    {
      "x": -5,
      "y": 10,
      "z": -7,
      "name": "Cloth_Roof_Orange_Flat"
    },
    {
      "x": -5,
      "y": 5,
      "z": -6,
      "name": "Soil_Dirt_Dry"
    },
    {
      "x": -5,
      "y": 6,
      "z": -6,
      "name": "Bench_WorkBench",
      "components": {
        "Components": {
          "BenchBlock": {
            "TierLevel": 1,
            "UpgradeItems": []
          }
        }
      },
      "rotation": 3
    },
    {
      "x": -5,
      "y": 9,
      "z": -6,
      "name": "Rock_Sandstone_Brick_Stairs",
      "rotation": 8
    },
    {
      "x": -5,
      "y": 10,
      "z": -6,
      "name": "Cloth_Roof_Orange_Flat"
    },
    {
      "x": -5,
      "y": 5,
      "z": -5,
      "name": "Rock_Sandstone_Brick"
    },
    {
      "x": -5,
      "y": 6,
      "z": -5,
      "name": "Rock_Sandstone_Brick_Pillar_Base"
    },
    {
      "x": -5,
      "y": 7,
      "z": -5,
      "name": "Rock_Sandstone_Brick_Pillar_Middle"
    },
    {
      "x": -5,
      "y": 8,
      "z": -5,
      "name": "Rock_Sandstone_Brick_Pillar_Base",
      "rotation": 8
    },
    {
      "x": -5,
      "y": 9,
      "z": -5,
      "name": "Rock_Sandstone_Brick"
    },
    {
      "x": -5,
      "y": 5,
      "z": -4,
      "name": "Rock_Sandstone_Brick"
    },
    {
      "x": -5,
      "y": 6,
      "z": -4,
      "name": "Rock_Sandstone_Brick"
    },
    {
      "x": -5,
      "y": 7,
      "z": -4,
      "name": "Rock_Sandstone_Brick"
    },
    {
      "x": -5,
      "y": 8,
      "z": -4,
      "name": "Rock_Sandstone_Brick"
    },
    {
      "x": -5,
      "y": 9,
      "z": -4,
      "name": "Rock_Sandstone_Brick_Half",
      "rotation": 4
    },
    {
      "x": -5,
      "y": 5,
      "z": -3,
      "name": "Rock_Sandstone_Brick"
    },
    {
      "x": -5,
      "y": 6,
      "z": -3,
      "name": "Rock_Sandstone_Brick"
    },
    {
      "x": -5,
      "y": 7,
      "z": -3,
      "name": "Rock_Sandstone_Brick"
    },
    {
      "x": -5,
      "y": 8,
      "z": -3,
      "name": "Rock_Sandstone_Brick"
    },
    {
      "x": -5,
      "y": 5,
      "z": -2,
      "name": "Rock_Sandstone_Brick"
    },
    {
      "x": -5,
      "y": 6,
      "z": -2,
      "name": "Rock_Sandstone_Brick_Pillar_Base"
    },
    {
      "x": -5,
      "y": 7,
      "z": -2,
      "name": "Rock_Sandstone_Brick_Pillar_Middle"
    },
    {
      "x": -5,
      "y": 8,
      "z": -2,
      "name": "Wood_Drywood_Beam",
      "rotation": 4
    },
    {
      "x": -5,
      "y": 15,
      "z": -2,
      "name": "Rock_Sandstone_Brick_Half",
      "rotation": 8
    },
    {
      "x": -5,
      "y": 16,
      "z": -2,
      "name": "Rock_Sandstone_Brick_Decorative"
    },
    {
      "x": -5,
      "y": 17,
      "z": -2,
      "name": "Wood_Dry_Trunk"
    },
    {
      "x": -5,
      "y": 18,
      "z": -2,
      "name": "Wood_Dry_Trunk"
    },
    {
      "x": -5,
      "y": 19,
      "z": -2,
      "name": "Wood_Dry_Trunk"
    },
    {
      "x": -5,
      "y": 20,
      "z": -2,
      "name": "Wood_Dry_Trunk"
    },
    {
      "x": -5,
      "y": 21,
      "z": -2,
      "name": "Wood_Dry_Trunk"
    },
    {
      "x": -5,
      "y": 22,
      "z": -2,
      "name": "*Wood_Drywood_Fence_State_Definitions_Corner",
      "rotation": 1
    },
    {
      "x": -5,
      "y": 5,
      "z": -1,
      "name": "Rock_Sandstone_White_Cobble"
    },
    {
      "x": -5,
      "y": 8,
      "z": -1,
      "name": "Wood_Drywood_Beam",
      "rotation": 4
    },
    {
      "x": -5,
      "y": 15,
      "z": -1,
      "name": "Rock_Sandstone_Brick"
    },
    {
      "x": -5,
      "y": 16,
      "z": -1,
      "name": "Rock_Sandstone_Brick_Decorative"
    },
    {
      "x": -5,
      "y": 17,
      "z": -1,
      "name": "Rock_Sandstone_White_Cobble"
    },
    {
      "x": -5,
      "y": 18,
      "z": -1,
      "name": "Rock_Sandstone_White_Cobble"
    },
    {
      "x": -5,
      "y": 19,
      "z": -1,
      "name": "Rock_Sandstone_White_Cobble"
    },
    {
      "x": -5,
      "y": 20,
      "z": -1,
      "name": "Rock_Sandstone_White_Cobble"
    },
    {
      "x": -5,
      "y": 21,
      "z": -1,
      "name": "Wood_Dry_Trunk",
      "rotation": 4
    },
    {
      "x": -5,
      "y": 22,
      "z": -1,
      "name": "Wood_Drywood_Fence",
      "rotation": 3
    },
    {
      "x": -5,
      "y": 5,
      "z": 0,
      "name": "Rock_Sandstone_White_Cobble"
    },
    {
      "x": -5,
      "y": 8,
      "z": 0,
      "name": "Wood_Drywood_Beam",
      "rotation": 4
    },
    {
      "x": -5,
      "y": 9,
      "z": 0,
      "name": "Rock_Sandstone_Brick_Stairs",
      "rotation": 8
    },
    {
      "x": -5,
      "y": 14,
      "z": 0,
      "name": "Rock_Sandstone_Brick"
    },
    {
      "x": -5,
      "y": 15,
      "z": 0,
      "name": "Rock_Sandstone_Brick"
    },
    {
      "x": -5,
      "y": 16,
      "z": 0,
      "name": "Rock_Sandstone_Brick_Decorative"
    },
    {
      "x": -5,
      "y": 17,
      "z": 0,
      "name": "Rock_Sandstone_White_Cobble"
    },
    {
      "x": -5,
      "y": 18,
      "z": 0,
      "name": "Rock_Sandstone_White_Cobble"
    },
    {
      "x": -5,
      "y": 19,
      "z": 0,
      "name": "Rock_Sandstone_White_Cobble"
    },
    {
      "x": -5,
      "y": 20,
      "z": 0,
      "name": "Rock_Sandstone_White_Cobble"
    },
    {
      "x": -5,
      "y": 21,
      "z": 0,
      "name": "Wood_Dry_Trunk",
      "rotation": 4
    },
    {
      "x": -5,
      "y": 22,
      "z": 0,
      "name": "Wood_Drywood_Fence",
      "rotation": 3
    },
    {
      "x": -5,
      "y": 5,
      "z": 1,
      "name": "Rock_Sandstone_Brick"
    },
    {
      "x": -5,
      "y": 6,
      "z": 1,
      "name": "Rock_Sandstone_Brick_Pillar_Base"
    },
    {
      "x": -5,
      "y": 7,
      "z": 1,
      "name": "Rock_Sandstone_Brick_Pillar_Middle"
    },
    {
      "x": -5,
      "y": 8,
      "z": 1,
      "name": "Rock_Sandstone_Brick_Pillar_Base",
      "rotation": 8
    },
    {
      "x": -5,
      "y": 9,
      "z": 1,
      "name": "Rock_Sandstone_Brick"
    },
    {
      "x": -5,
      "y": 10,
      "z": 1,
      "name": "Rock_Sandstone_Brick_Half",
      "rotation": 6
    },
    {
      "x": -5,
      "y": 11,
      "z": 1,
      "name": "Rock_Sandstone_Brick_Half",
      "rotation": 6
    },
    {
      "x": -5,
      "y": 12,
      "z": 1,
      "name": "Rock_Sandstone_Brick"
    },
    {
      "x": -5,
      "y": 13,
      "z": 1,
      "name": "Rock_Sandstone_Brick"
    },
    {
      "x": -5,
      "y": 14,
      "z": 1,
      "name": "Rock_Sandstone_Brick"
    },
    {
      "x": -5,
      "y": 15,
      "z": 1,
      "name": "Rock_Sandstone_Brick"
    },
    {
      "x": -5,
      "y": 16,
      "z": 1,
      "name": "Rock_Sandstone_Brick_Decorative"
    },
    {
      "x": -5,
      "y": 17,
      "z": 1,
      "name": "Rock_Sandstone_White_Cobble"
    },
    {
      "x": -5,
      "y": 18,
      "z": 1,
      "name": "Rock_Sandstone_White_Cobble"
    },
    {
      "x": -5,
      "y": 19,
      "z": 1,
      "name": "Rock_Sandstone_White_Cobble"
    },
    {
      "x": -5,
      "y": 20,
      "z": 1,
      "name": "Rock_Sandstone_White_Cobble"
    },
    {
      "x": -5,
      "y": 21,
      "z": 1,
      "name": "Wood_Dry_Trunk",
      "rotation": 4
    },
    {
      "x": -5,
      "y": 22,
      "z": 1,
      "name": "Wood_Drywood_Fence",
      "rotation": 3
    },
    {
      "x": -5,
      "y": 5,
      "z": 2,
      "name": "Rock_Sandstone_Cobble"
    },
    {
      "x": -5,
      "y": 6,
      "z": 2,
      "name": "Rock_Sandstone_Brick"
    },
    {
      "x": -5,
      "y": 7,
      "z": 2,
      "name": "Rock_Sandstone_Brick"
    },
    {
      "x": -5,
      "y": 8,
      "z": 2,
      "name": "Rock_Sandstone_Brick"
    },
    {
      "x": -5,
      "y": 9,
      "z": 2,
      "name": "Rock_Sandstone_Brick"
    },
    {
      "x": -5,
      "y": 10,
      "z": 2,
      "name": "Rock_Sandstone_Brick"
    },
    {
      "x": -5,
      "y": 11,
      "z": 2,
      "name": "Rock_Sandstone_Brick"
    },
    {
      "x": -5,
      "y": 12,
      "z": 2,
      "name": "Rock_Sandstone_Brick"
    },
    {
      "x": -5,
      "y": 13,
      "z": 2,
      "name": "Rock_Sandstone_Brick"
    },
    {
      "x": -5,
      "y": 14,
      "z": 2,
      "name": "Rock_Sandstone_Brick"
    },
    {
      "x": -5,
      "y": 15,
      "z": 2,
      "name": "Rock_Sandstone_Brick"
    },
    {
      "x": -5,
      "y": 16,
      "z": 2,
      "name": "Rock_Sandstone_Brick_Decorative"
    },
    {
      "x": -5,
      "y": 17,
      "z": 2,
      "name": "Rock_Sandstone_White_Cobble"
    },
    {
      "x": -5,
      "y": 18,
      "z": 2,
      "name": "Rock_Sandstone_White_Cobble"
    },
    {
      "x": -5,
      "y": 19,
      "z": 2,
      "name": "Rock_Sandstone_White_Cobble"
    },
    {
      "x": -5,
      "y": 20,
      "z": 2,
      "name": "Rock_Sandstone_White_Cobble"
    },
    {
      "x": -5,
      "y": 21,
      "z": 2,
      "name": "Wood_Dry_Trunk",
      "rotation": 4
    },
    {
      "x": -5,
      "y": 22,
      "z": 2,
      "name": "Wood_Drywood_Fence",
      "rotation": 3
    },
    {
      "x": -5,
      "y": 5,
      "z": 3,
      "name": "Rock_Sandstone_Cobble"
    },
    {
      "x": -5,
      "y": 6,
      "z": 3,
      "name": "Rock_Sandstone_Brick"
    },
    {
      "x": -5,
      "y": 7,
      "z": 3,
      "name": "Rock_Sandstone_Brick"
    },
    {
      "x": -5,
      "y": 8,
      "z": 3,
      "name": "Rock_Sandstone_Brick"
    },
    {
      "x": -5,
      "y": 9,
      "z": 3,
      "name": "Rock_Sandstone_Brick"
    },
    {
      "x": -5,
      "y": 10,
      "z": 3,
      "name": "Rock_Sandstone_Brick"
    },
    {
      "x": -5,
      "y": 11,
      "z": 3,
      "name": "Rock_Sandstone_Brick"
    },
    {
      "x": -5,
      "y": 12,
      "z": 3,
      "name": "Rock_Sandstone_Brick"
    },
    {
      "x": -5,
      "y": 13,
      "z": 3,
      "name": "Rock_Sandstone_Brick"
    },
    {
      "x": -5,
      "y": 14,
      "z": 3,
      "name": "Rock_Sandstone_Brick"
    },
    {
      "x": -5,
      "y": 15,
      "z": 3,
      "name": "Rock_Sandstone_Brick"
    },
    {
      "x": -5,
      "y": 16,
      "z": 3,
      "name": "Rock_Sandstone_Brick_Decorative"
    },
    {
      "x": -5,
      "y": 17,
      "z": 3,
      "name": "Wood_Dry_Trunk"
    },
    {
      "x": -5,
      "y": 18,
      "z": 3,
      "name": "Wood_Dry_Trunk"
    },
    {
      "x": -5,
      "y": 19,
      "z": 3,
      "name": "Wood_Dry_Trunk"
    },
    {
      "x": -5,
      "y": 20,
      "z": 3,
      "name": "Wood_Dry_Trunk"
    },
    {
      "x": -5,
      "y": 21,
      "z": 3,
      "name": "Wood_Dry_Trunk"
    },
    {
      "x": -5,
      "y": 22,
      "z": 3,
      "name": "Wood_Drywood_Fence",
      "rotation": 3
    },
    {
      "x": -5,
      "y": 5,
      "z": 4,
      "name": "Rock_Sandstone_Cobble"
    },
    {
      "x": -5,
      "y": 6,
      "z": 4,
      "name": "Rock_Sandstone_Cobble"
    },
    {
      "x": -5,
      "y": 7,
      "z": 4,
      "name": "Rock_Sandstone_Cobble"
    },
    {
      "x": -5,
      "y": 8,
      "z": 4,
      "name": "Rock_Sandstone_Brick"
    },
    {
      "x": -5,
      "y": 9,
      "z": 4,
      "name": "Rock_Sandstone_Brick"
    },
    {
      "x": -5,
      "y": 10,
      "z": 4,
      "name": "Rock_Sandstone_Brick"
    },
    {
      "x": -5,
      "y": 11,
      "z": 4,
      "name": "Rock_Sandstone_Brick"
    },
    {
      "x": -5,
      "y": 12,
      "z": 4,
      "name": "Rock_Sandstone_Brick"
    },
    {
      "x": -5,
      "y": 13,
      "z": 4,
      "name": "Rock_Sandstone_Brick"
    },
    {
      "x": -5,
      "y": 14,
      "z": 4,
      "name": "Rock_Sandstone_Brick"
    },
    {
      "x": -5,
      "y": 15,
      "z": 4,
      "name": "Rock_Sandstone_Brick"
    },
    {
      "x": -5,
      "y": 16,
      "z": 4,
      "name": "Rock_Sandstone_Brick_Decorative"
    },
    {
      "x": -5,
      "y": 17,
      "z": 4,
      "name": "Rock_Sandstone_White_Cobble"
    },
    {
      "x": -5,
      "y": 18,
      "z": 4,
      "name": "Rock_Sandstone_White_Cobble"
    },
    {
      "x": -5,
      "y": 19,
      "z": 4,
      "name": "Rock_Sandstone_White_Cobble"
    },
    {
      "x": -5,
      "y": 20,
      "z": 4,
      "name": "Rock_Sandstone_White_Cobble"
    },
    {
      "x": -5,
      "y": 21,
      "z": 4,
      "name": "Wood_Dry_Trunk",
      "rotation": 4
    },
    {
      "x": -5,
      "y": 22,
      "z": 4,
      "name": "Wood_Drywood_Fence",
      "rotation": 3
    },
    {
      "x": -5,
      "y": 5,
      "z": 5,
      "name": "Rock_Sandstone_Cobble"
    },
    {
      "x": -5,
      "y": 6,
      "z": 5,
      "name": "Rock_Sandstone_Cobble"
    },
    {
      "x": -5,
      "y": 7,
      "z": 5,
      "name": "Rock_Sandstone_Cobble"
    },
    {
      "x": -5,
      "y": 8,
      "z": 5,
      "name": "Rock_Sandstone_Cobble"
    },
    {
      "x": -5,
      "y": 9,
      "z": 5,
      "name": "Rock_Sandstone_Brick"
    },
    {
      "x": -5,
      "y": 10,
      "z": 5,
      "name": "Rock_Sandstone_Brick"
    },
    {
      "x": -5,
      "y": 11,
      "z": 5,
      "name": "Rock_Sandstone_Brick"
    },
    {
      "x": -5,
      "y": 12,
      "z": 5,
      "name": "Rock_Sandstone_Cobble"
    },
    {
      "x": -5,
      "y": 13,
      "z": 5,
      "name": "Rock_Sandstone_Cobble"
    },
    {
      "x": -5,
      "y": 14,
      "z": 5,
      "name": "Rock_Sandstone_Cobble"
    },
    {
      "x": -5,
      "y": 15,
      "z": 5,
      "name": "Rock_Sandstone_Brick"
    },
    {
      "x": -5,
      "y": 16,
      "z": 5,
      "name": "Rock_Sandstone_Brick_Decorative"
    },
    {
      "x": -5,
      "y": 17,
      "z": 5,
      "name": "Rock_Sandstone_White_Cobble"
    },
    {
      "x": -5,
      "y": 18,
      "z": 5,
      "name": "Furniture_Desert_Window",
      "rotation": 1
    },
    {
      "x": -5,
      "y": 19,
      "z": 5,
      "name": "Furniture_Desert_Window",
      "rotation": 1
    },
    {
      "x": -5,
      "y": 20,
      "z": 5,
      "name": "Rock_Sandstone_White_Cobble"
    },
    {
      "x": -5,
      "y": 21,
      "z": 5,
      "name": "Wood_Dry_Trunk",
      "rotation": 4
    },
    {
      "x": -5,
      "y": 22,
      "z": 5,
      "name": "Wood_Drywood_Fence",
      "rotation": 3
    },
    {
      "x": -5,
      "y": 5,
      "z": 6,
      "name": "Rock_Sandstone_Cobble"
    },
    {
      "x": -5,
      "y": 6,
      "z": 6,
      "name": "Rock_Sandstone_Cobble"
    },
    {
      "x": -5,
      "y": 7,
      "z": 6,
      "name": "Rock_Sandstone_Cobble"
    },
    {
      "x": -5,
      "y": 8,
      "z": 6,
      "name": "Rock_Sandstone_Cobble"
    },
    {
      "x": -5,
      "y": 9,
      "z": 6,
      "name": "Rock_Sandstone_Cobble"
    },
    {
      "x": -5,
      "y": 10,
      "z": 6,
      "name": "Rock_Sandstone_Brick"
    },
    {
      "x": -5,
      "y": 11,
      "z": 6,
      "name": "Rock_Sandstone_Brick"
    },
    {
      "x": -5,
      "y": 12,
      "z": 6,
      "name": "Rock_Sandstone_Cobble"
    },
    {
      "x": -5,
      "y": 13,
      "z": 6,
      "name": "Rock_Sandstone_Cobble"
    },
    {
      "x": -5,
      "y": 14,
      "z": 6,
      "name": "Rock_Sandstone_Cobble"
    },
    {
      "x": -5,
      "y": 15,
      "z": 6,
      "name": "Rock_Sandstone_Brick"
    },
    {
      "x": -5,
      "y": 16,
      "z": 6,
      "name": "Rock_Sandstone_Brick_Decorative"
    },
    {
      "x": -5,
      "y": 17,
      "z": 6,
      "name": "Rock_Sandstone_White_Cobble"
    },
    {
      "x": -5,
      "y": 18,
      "z": 6,
      "name": "Furniture_Desert_Window",
      "rotation": 1
    },
    {
      "x": -5,
      "y": 19,
      "z": 6,
      "name": "Furniture_Desert_Window",
      "rotation": 1
    },
    {
      "x": -5,
      "y": 20,
      "z": 6,
      "name": "Rock_Sandstone_White_Cobble"
    },
    {
      "x": -5,
      "y": 21,
      "z": 6,
      "name": "Wood_Dry_Trunk",
      "rotation": 4
    },
    {
      "x": -5,
      "y": 22,
      "z": 6,
      "name": "Wood_Drywood_Fence",
      "rotation": 3
    },
    {
      "x": -5,
      "y": 5,
      "z": 7,
      "name": "Rock_Sandstone_Cobble"
    },
    {
      "x": -5,
      "y": 6,
      "z": 7,
      "name": "Rock_Sandstone_Cobble"
    },
    {
      "x": -5,
      "y": 7,
      "z": 7,
      "name": "Rock_Sandstone_Cobble"
    },
    {
      "x": -5,
      "y": 8,
      "z": 7,
      "name": "Rock_Sandstone_Cobble"
    },
    {
      "x": -5,
      "y": 9,
      "z": 7,
      "name": "Rock_Sandstone_Brick"
    },
    {
      "x": -5,
      "y": 10,
      "z": 7,
      "name": "Rock_Sandstone_Brick"
    },
    {
      "x": -5,
      "y": 11,
      "z": 7,
      "name": "Rock_Sandstone_Brick"
    },
    {
      "x": -5,
      "y": 12,
      "z": 7,
      "name": "Rock_Sandstone_Brick"
    },
    {
      "x": -5,
      "y": 13,
      "z": 7,
      "name": "Rock_Sandstone_Brick"
    },
    {
      "x": -5,
      "y": 14,
      "z": 7,
      "name": "Rock_Sandstone_Brick"
    },
    {
      "x": -5,
      "y": 15,
      "z": 7,
      "name": "Rock_Sandstone_Brick"
    },
    {
      "x": -5,
      "y": 16,
      "z": 7,
      "name": "Rock_Sandstone_Brick_Decorative"
    },
    {
      "x": -5,
      "y": 17,
      "z": 7,
      "name": "Rock_Sandstone_White_Cobble"
    },
    {
      "x": -5,
      "y": 18,
      "z": 7,
      "name": "Rock_Sandstone_White_Cobble"
    },
    {
      "x": -5,
      "y": 19,
      "z": 7,
      "name": "Rock_Sandstone_White_Cobble"
    },
    {
      "x": -5,
      "y": 20,
      "z": 7,
      "name": "Rock_Sandstone_White_Cobble"
    },
    {
      "x": -5,
      "y": 21,
      "z": 7,
      "name": "Wood_Dry_Trunk",
      "rotation": 4
    },
    {
      "x": -5,
      "y": 22,
      "z": 7,
      "name": "Wood_Drywood_Fence",
      "rotation": 3
    },
    {
      "x": -5,
      "y": 5,
      "z": 8,
      "name": "Rock_Sandstone_Cobble"
    },
    {
      "x": -5,
      "y": 6,
      "z": 8,
      "name": "Rock_Sandstone_Cobble"
    },
    {
      "x": -5,
      "y": 7,
      "z": 8,
      "name": "Rock_Sandstone_Cobble"
    },
    {
      "x": -5,
      "y": 8,
      "z": 8,
      "name": "Rock_Sandstone_Cobble"
    },
    {
      "x": -5,
      "y": 9,
      "z": 8,
      "name": "Rock_Sandstone_Cobble"
    },
    {
      "x": -5,
      "y": 10,
      "z": 8,
      "name": "Rock_Sandstone_Cobble"
    },
    {
      "x": -5,
      "y": 11,
      "z": 8,
      "name": "Rock_Sandstone_Brick_Smooth"
    },
    {
      "x": -5,
      "y": 12,
      "z": 8,
      "name": "Rock_Sandstone_White_Cobble"
    },
    {
      "x": -5,
      "y": 13,
      "z": 8,
      "name": "Rock_Sandstone_White_Cobble"
    },
    {
      "x": -5,
      "y": 14,
      "z": 8,
      "name": "Rock_Sandstone_White_Cobble"
    },
    {
      "x": -5,
      "y": 15,
      "z": 8,
      "name": "Rock_Sandstone_Brick"
    },
    {
      "x": -5,
      "y": 16,
      "z": 8,
      "name": "Rock_Sandstone_Brick_Decorative"
    },
    {
      "x": -5,
      "y": 17,
      "z": 8,
      "name": "Wood_Dry_Trunk"
    },
    {
      "x": -5,
      "y": 18,
      "z": 8,
      "name": "Wood_Dry_Trunk"
    },
    {
      "x": -5,
      "y": 19,
      "z": 8,
      "name": "Wood_Dry_Trunk"
    },
    {
      "x": -5,
      "y": 20,
      "z": 8,
      "name": "Wood_Dry_Trunk"
    },
    {
      "x": -5,
      "y": 21,
      "z": 8,
      "name": "Wood_Dry_Trunk"
    },
    {
      "x": -5,
      "y": 22,
      "z": 8,
      "name": "*Wood_Drywood_Fence_State_Definitions_Corner",
      "rotation": 2
    },
    {
      "x": -5,
      "y": 5,
      "z": 9,
      "name": "Rock_Sandstone_Cobble"
    },
    {
      "x": -5,
      "y": 6,
      "z": 9,
      "name": "Rock_Sandstone_Cobble"
    },
    {
      "x": -5,
      "y": 7,
      "z": 9,
      "name": "Rock_Sandstone_Cobble"
    },
    {
      "x": -5,
      "y": 8,
      "z": 9,
      "name": "Rock_Sandstone_Cobble"
    },
    {
      "x": -5,
      "y": 9,
      "z": 9,
      "name": "Rock_Sandstone_Cobble"
    },
    {
      "x": -5,
      "y": 10,
      "z": 9,
      "name": "Rock_Sandstone_Cobble"
    },
    {
      "x": -5,
      "y": 11,
      "z": 9,
      "name": "Rock_Sandstone_Brick_Smooth"
    },
    {
      "x": -5,
      "y": 12,
      "z": 9,
      "name": "Rock_Sandstone_White_Cobble"
    },
    {
      "x": -5,
      "y": 13,
      "z": 9,
      "name": "Rock_Sandstone_White_Cobble"
    },
    {
      "x": -5,
      "y": 14,
      "z": 9,
      "name": "Rock_Sandstone_White_Cobble"
    },
    {
      "x": -5,
      "y": 15,
      "z": 9,
      "name": "Rock_Sandstone_Brick"
    },
    {
      "x": -5,
      "y": 16,
      "z": 9,
      "name": "Rock_Sandstone_Brick_Smooth_Half"
    },
    {
      "x": -5,
      "y": 5,
      "z": 10,
      "name": "Rock_Sandstone_Cobble"
    },
    {
      "x": -5,
      "y": 6,
      "z": 10,
      "name": "Rock_Sandstone_Brick"
    },
    {
      "x": -5,
      "y": 7,
      "z": 10,
      "name": "Rock_Sandstone_Brick"
    },
    {
      "x": -5,
      "y": 8,
      "z": 10,
      "name": "Rock_Sandstone_Cobble"
    },
    {
      "x": -5,
      "y": 9,
      "z": 10,
      "name": "Rock_Sandstone_Cobble"
    },
    {
      "x": -5,
      "y": 10,
      "z": 10,
      "name": "Rock_Sandstone_Cobble"
    },
    {
      "x": -5,
      "y": 11,
      "z": 10,
      "name": "Rock_Sandstone_Brick_Smooth"
    },
    {
      "x": -5,
      "y": 12,
      "z": 10,
      "name": "Rock_Sandstone_White_Cobble"
    },
    {
      "x": -5,
      "y": 13,
      "z": 10,
      "name": "Rock_Sandstone_White_Cobble"
    },
    {
      "x": -5,
      "y": 14,
      "z": 10,
      "name": "Rock_Sandstone_White_Cobble"
    },
    {
      "x": -5,
      "y": 15,
      "z": 10,
      "name": "Rock_Sandstone_Brick"
    },
    {
      "x": -5,
      "y": 16,
      "z": 10,
      "name": "Rock_Sandstone_Brick_Smooth_Half"
    },
    {
      "x": -5,
      "y": 5,
      "z": 11,
      "name": "Rock_Sandstone_Cobble"
    },
    {
      "x": -5,
      "y": 6,
      "z": 11,
      "name": "Rock_Sandstone_Brick"
    },
    {
      "x": -5,
      "y": 7,
      "z": 11,
      "name": "Rock_Sandstone_Brick"
    },
    {
      "x": -5,
      "y": 8,
      "z": 11,
      "name": "Rock_Sandstone_Brick"
    },
    {
      "x": -5,
      "y": 9,
      "z": 11,
      "name": "Rock_Sandstone_Brick"
    },
    {
      "x": -5,
      "y": 10,
      "z": 11,
      "name": "Rock_Sandstone_Cobble"
    },
    {
      "x": -5,
      "y": 11,
      "z": 11,
      "name": "Rock_Sandstone_Brick_Smooth_Half",
      "rotation": 4
    },
    {
      "x": -5,
      "y": 15,
      "z": 11,
      "name": "Rock_Sandstone_Brick"
    },
    {
      "x": -5,
      "y": 16,
      "z": 11,
      "name": "Rock_Sandstone_Brick_Smooth_Half"
    },
    {
      "x": -4,
      "y": 5,
      "z": -7,
      "name": "Rock_Sandstone_White_Cobble"
    },
    {
      "x": -4,
      "y": 9,
      "z": -7,
      "name": "Cloth_Roof_Orange_Flap",
      "rotation": 1
    },
    {
      "x": -4,
      "y": 5,
      "z": -6,
      "name": "Rock_Sandstone_White_Cobble"
    },
    {
      "x": -4,
      "y": 8,
      "z": -6,
      "name": "Cloth_Roof_Orange_Flap",
      "rotation": 1
    },
    {
      "x": -4,
      "y": 9,
      "z": -6,
      "name": "Cloth_Roof_Orange_Vertical",
      "rotation": 1
    },
    {
      "x": -4,
      "y": 5,
      "z": -5,
      "name": "Rock_Sandstone_White_Cobble"
    },
    {
      "x": -4,
      "y": 8,
      "z": -5,
      "name": "Cloth_Roof_Orange_Flap",
      "rotation": 1
    },
    {
      "x": -4,
      "y": 9,
      "z": -5,
      "name": "Cloth_Roof_Orange_Vertical",
      "rotation": 1
    },
    {
      "x": -4,
      "y": 5,
      "z": -4,
      "name": "Rock_Sandstone_White_Cobble"
    },
    {
      "x": -4,
      "y": 5,
      "z": -3,
      "name": "Rock_Sandstone_White_Cobble"
    },
    {
      "x": -4,
      "y": 6,
      "z": -3,
      "name": "Furniture_Ancient_Pot"
    },
    {
      "x": -4,
      "y": 21,
      "z": -3,
      "name": "Wood_Dry_Branch_Short",
      "rotation": 2
    },
    {
      "x": -4,
      "y": 5,
      "z": -2,
      "name": "Rock_Sandstone_White_Cobble"
    },
    {
      "x": -4,
      "y": 15,
      "z": -2,
      "name": "Rock_Sandstone_Brick_Half",
      "rotation": 8
    },
    {
      "x": -4,
      "y": 16,
      "z": -2,
      "name": "Rock_Sandstone_Brick_Decorative"
    },
    {
      "x": -4,
      "y": 17,
      "z": -2,
      "name": "Rock_Sandstone_White_Cobble"
    },
    {
      "x": -4,
      "y": 18,
      "z": -2,
      "name": "Rock_Sandstone_White_Cobble"
    },
    {
      "x": -4,
      "y": 19,
      "z": -2,
      "name": "Rock_Sandstone_White_Cobble"
    },
    {
      "x": -4,
      "y": 20,
      "z": -2,
      "name": "Rock_Sandstone_White_Cobble"
    },
    {
      "x": -4,
      "y": 21,
      "z": -2,
      "name": "Wood_Dry_Trunk",
      "rotation": 5
    },
    {
      "x": -4,
      "y": 22,
      "z": -2,
      "name": "Wood_Drywood_Fence",
      "rotation": 2
    },
    {
      "x": -4,
      "y": 5,
      "z": -1,
      "name": "Rock_Sandstone_White_Cobble"
    },
    {
      "x": -4,
      "y": 15,
      "z": -1,
      "name": "Rock_Sandstone_Brick"
    },
    {
      "x": -4,
      "y": 16,
      "z": -1,
      "name": "Wood_Drywood_Planks"
    },
    {
      "x": -4,
      "y": 21,
      "z": -1,
      "name": "Wood_Drywood_Planks"
    },
    {
      "x": -4,
      "y": 22,
      "z": -1,
      "name": "Furniture_Temple_Wind_Pot"
    },
    {
      "x": -4,
      "y": 23,
      "z": -1,
      "name": "Furniture_Temple_Wind_Pot",
      "filler": 1024
    },
    {
      "x": -4,
      "y": 5,
      "z": 0,
      "name": "Rock_Sandstone_White_Cobble"
    },
    {
      "x": -4,
      "y": 14,
      "z": 0,
      "name": "Rock_Sandstone_Brick"
    },
    {
      "x": -4,
      "y": 15,
      "z": 0,
      "name": "Rock_Sandstone_Brick"
    },
    {
      "x": -4,
      "y": 16,
      "z": 0,
      "name": "Wood_Drywood_Planks"
    },
    {
      "x": -4,
      "y": 21,
      "z": 0,
      "name": "Wood_Drywood_Planks"
    },
    {
      "x": -4,
      "y": 5,
      "z": 1,
      "name": "Rock_Sandstone_White_Cobble"
    },
    {
      "x": -4,
      "y": 10,
      "z": 1,
      "name": "Rock_Sandstone_Brick_Half",
      "rotation": 6
    },
    {
      "x": -4,
      "y": 11,
      "z": 1,
      "name": "Rock_Sandstone_Brick_Half",
      "rotation": 6
    },
    {
      "x": -4,
      "y": 12,
      "z": 1,
      "name": "Rock_Sandstone_Brick"
    },
    {
      "x": -4,
      "y": 13,
      "z": 1,
      "name": "Rock_Sandstone_Brick"
    },
    {
      "x": -4,
      "y": 14,
      "z": 1,
      "name": "Rock_Sandstone_Brick"
    },
    {
      "x": -4,
      "y": 15,
      "z": 1,
      "name": "Rock_Sandstone_Brick"
    },
    {
      "x": -4,
      "y": 16,
      "z": 1,
      "name": "Wood_Drywood_Planks"
    },
    {
      "x": -4,
      "y": 21,
      "z": 1,
      "name": "Wood_Drywood_Planks"
    },
    {
      "x": -4,
      "y": 22,
      "z": 1,
      "name": "Furniture_Village_Pot"
    },
    {
      "x": -4,
      "y": 23,
      "z": 1,
      "name": "Plant_Flower_Bushy_Green",
      "components": {
        "Components": {
          "FarmingBlock": {
            "LastTickGameTime": "0001-01-01T12:00:00Z"
          }
        }
      }
    },
    {
      "x": -4,
      "y": 5,
      "z": 2,
      "name": "Rock_Sandstone_Cobble"
    },
    {
      "x": -4,
      "y": 6,
      "z": 2,
      "name": "Rock_Sandstone_Brick"
    },
    {
      "x": -4,
      "y": 7,
      "z": 2,
      "name": "Rock_Sandstone_Brick"
    },
    {
      "x": -4,
      "y": 8,
      "z": 2,
      "name": "Rock_Sandstone_Brick"
    },
    {
      "x": -4,
      "y": 9,
      "z": 2,
      "name": "Rock_Sandstone_Brick"
    },
    {
      "x": -4,
      "y": 10,
      "z": 2,
      "name": "Rock_Sandstone_Brick"
    },
    {
      "x": -4,
      "y": 11,
      "z": 2,
      "name": "Rock_Sandstone_Brick"
    },
    {
      "x": -4,
      "y": 12,
      "z": 2,
      "name": "Rock_Sandstone_Brick"
    },
    {
      "x": -4,
      "y": 13,
      "z": 2,
      "name": "Rock_Sandstone_Brick"
    },
    {
      "x": -4,
      "y": 14,
      "z": 2,
      "name": "Rock_Sandstone_Brick"
    },
    {
      "x": -4,
      "y": 15,
      "z": 2,
      "name": "Rock_Sandstone_Brick"
    },
    {
      "x": -4,
      "y": 16,
      "z": 2,
      "name": "Rock_Sandstone_Brick_Stairs"
    },
    {
      "x": -4,
      "y": 21,
      "z": 2,
      "name": "Wood_Drywood_Planks"
    },
    {
      "x": -4,
      "y": 5,
      "z": 3,
      "name": "Rock_Sandstone_Cobble"
    },
    {
      "x": -4,
      "y": 6,
      "z": 3,
      "name": "Rock_Sandstone_Brick"
    },
    {
      "x": -4,
      "y": 7,
      "z": 3,
      "name": "Rock_Sandstone_Brick"
    },
    {
      "x": -4,
      "y": 8,
      "z": 3,
      "name": "Rock_Sandstone_Brick"
    },
    {
      "x": -4,
      "y": 9,
      "z": 3,
      "name": "Rock_Sandstone_Brick"
    },
    {
      "x": -4,
      "y": 10,
      "z": 3,
      "name": "Rock_Sandstone_Brick"
    },
    {
      "x": -4,
      "y": 11,
      "z": 3,
      "name": "Rock_Sandstone_Brick"
    },
    {
      "x": -4,
      "y": 12,
      "z": 3,
      "name": "Rock_Sandstone_White_Cobble"
    },
    {
      "x": -4,
      "y": 13,
      "z": 3,
      "name": "Rock_Sandstone_White_Cobble"
    },
    {
      "x": -4,
      "y": 14,
      "z": 3,
      "name": "Rock_Sandstone_White_Cobble"
    },
    {
      "x": -4,
      "y": 15,
      "z": 3,
      "name": "Wood_Drywood_Planks"
    },
    {
      "x": -4,
      "y": 21,
      "z": 3,
      "name": "Wood_Drywood_Planks"
    },
    {
      "x": -4,
      "y": 11,
      "z": 4,
      "name": "Rock_Sandstone_Brick"
    },
    {
      "x": -4,
      "y": 15,
      "z": 4,
      "name": "Wood_Drywood_Planks"
    },
    {
      "x": -4,
      "y": 21,
      "z": 4,
      "name": "Wood_Drywood_Planks"
    },
    {
      "x": -4,
      "y": 11,
      "z": 5,
      "name": "Rock_Sandstone_Brick"
    },
    {
      "x": -4,
      "y": 15,
      "z": 5,
      "name": "Wood_Drywood_Planks"
    },
    {
      "x": -4,
      "y": 21,
      "z": 5,
      "name": "Wood_Drywood_Planks"
    },
    {
      "x": -4,
      "y": 11,
      "z": 6,
      "name": "Rock_Sandstone_Brick"
    },
    {
      "x": -4,
      "y": 15,
      "z": 6,
      "name": "Wood_Drywood_Planks"
    },
    {
      "x": -4,
      "y": 21,
      "z": 6,
      "name": "Wood_Drywood_Planks"
    },
    {
      "x": -4,
      "y": 22,
      "z": 6,
      "name": "Furniture_Village_Pot"
    },
    {
      "x": -4,
      "y": 23,
      "z": 6,
      "name": "Plant_Flower_Bushy_Green",
      "components": {
        "Components": {
          "FarmingBlock": {
            "LastTickGameTime": "0001-01-01T12:00:00Z"
          }
        }
      }
    },
    {
      "x": -4,
      "y": 11,
      "z": 7,
      "name": "Rock_Sandstone_Brick"
    },
    {
      "x": -4,
      "y": 15,
      "z": 7,
      "name": "Wood_Drywood_Planks"
    },
    {
      "x": -4,
      "y": 21,
      "z": 7,
      "name": "Wood_Drywood_Planks"
    },
    {
      "x": -4,
      "y": 22,
      "z": 7,
      "name": "Furniture_Village_Pot"
    },
    {
      "x": -4,
      "y": 11,
      "z": 8,
      "name": "Rock_Sandstone_Brick"
    },
    {
      "x": -4,
      "y": 15,
      "z": 8,
      "name": "Wood_Drywood_Planks"
    },
    {
      "x": -4,
      "y": 16,
      "z": 8,
      "name": "Rock_Sandstone_Brick_Decorative"
    },
    {
      "x": -4,
      "y": 17,
      "z": 8,
      "name": "Rock_Sandstone_White_Cobble"
    },
    {
      "x": -4,
      "y": 18,
      "z": 8,
      "name": "Rock_Sandstone_White_Cobble"
    },
    {
      "x": -4,
      "y": 19,
      "z": 8,
      "name": "Rock_Sandstone_White_Cobble"
    },
    {
      "x": -4,
      "y": 20,
      "z": 8,
      "name": "Rock_Sandstone_White_Cobble"
    },
    {
      "x": -4,
      "y": 21,
      "z": 8,
      "name": "Wood_Dry_Trunk",
      "rotation": 5
    },
    {
      "x": -4,
      "y": 22,
      "z": 8,
      "name": "Wood_Drywood_Fence"
    },
    {
      "x": -4,
      "y": 11,
      "z": 9,
      "name": "Rock_Sandstone_Brick"
    },
    {
      "x": -4,
      "y": 15,
      "z": 9,
      "name": "Wood_Drywood_Planks"
    },
    {
      "x": -4,
      "y": 21,
      "z": 9,
      "name": "Wood_Dry_Branch_Short"
    },
    {
      "x": -4,
      "y": 5,
      "z": 10,
      "name": "Rock_Sandstone_Cobble"
    },
    {
      "x": -4,
      "y": 6,
      "z": 10,
      "name": "Rock_Sandstone_Brick"
    },
    {
      "x": -4,
      "y": 7,
      "z": 10,
      "name": "Rock_Sandstone_Brick"
    },
    {
      "x": -4,
      "y": 8,
      "z": 10,
      "name": "Rock_Sandstone_Brick"
    },
    {
      "x": -4,
      "y": 9,
      "z": 10,
      "name": "Rock_Sandstone_Brick"
    },
    {
      "x": -4,
      "y": 10,
      "z": 10,
      "name": "Rock_Sandstone_Brick"
    },
    {
      "x": -4,
      "y": 11,
      "z": 10,
      "name": "Rock_Sandstone_Brick"
    },
    {
      "x": -4,
      "y": 12,
      "z": 10,
      "name": "Rock_Sandstone_White_Cobble"
    },
    {
      "x": -4,
      "y": 13,
      "z": 10,
      "name": "Rock_Sandstone_White_Cobble"
    },
    {
      "x": -4,
      "y": 14,
      "z": 10,
      "name": "Rock_Sandstone_White_Cobble"
    },
    {
      "x": -4,
      "y": 15,
      "z": 10,
      "name": "Wood_Drywood_Planks"
    },
    {
      "x": -4,
      "y": 5,
      "z": 11,
      "name": "Rock_Sandstone_Cobble"
    },
    {
      "x": -4,
      "y": 6,
      "z": 11,
      "name": "Rock_Sandstone_Brick"
    },
    {
      "x": -4,
      "y": 7,
      "z": 11,
      "name": "Rock_Sandstone_Brick"
    },
    {
      "x": -4,
      "y": 8,
      "z": 11,
      "name": "Rock_Sandstone_Brick"
    },
    {
      "x": -4,
      "y": 9,
      "z": 11,
      "name": "Rock_Sandstone_Brick"
    },
    {
      "x": -4,
      "y": 10,
      "z": 11,
      "name": "Rock_Sandstone_Brick"
    },
    {
      "x": -4,
      "y": 11,
      "z": 11,
      "name": "Rock_Sandstone_Brick_Smooth"
    },
    {
      "x": -4,
      "y": 12,
      "z": 11,
      "name": "Rock_Sandstone_White_Cobble"
    },
    {
      "x": -4,
      "y": 13,
      "z": 11,
      "name": "Rock_Sandstone_White_Cobble"
    },
    {
      "x": -4,
      "y": 14,
      "z": 11,
      "name": "Rock_Sandstone_White_Cobble"
    },
    {
      "x": -4,
      "y": 15,
      "z": 11,
      "name": "Rock_Sandstone_Brick"
    },
    {
      "x": -4,
      "y": 16,
      "z": 11,
      "name": "Rock_Sandstone_Brick_Smooth_Half"
    },
    {
      "x": -3,
      "y": 5,
      "z": -7,
      "name": "Rock_Sandstone_White_Cobble"
    },
    {
      "x": -3,
      "y": 5,
      "z": -6,
      "name": "Rock_Sandstone_White_Cobble"
    },
    {
      "x": -3,
      "y": 5,
      "z": -5,
      "name": "Rock_Sandstone_White_Cobble"
    },
    {
      "x": -3,
      "y": 5,
      "z": -4,
      "name": "Rock_Sandstone_White_Cobble"
    },
    {
      "x": -3,
      "y": 5,
      "z": -3,
      "name": "Rock_Sandstone_White_Cobble"
    },
    {
      "x": -3,
      "y": 18,
      "z": -3,
      "name": "Rock_Sandstone_Brick_Smooth_Half",
      "rotation": 6
    },
    {
      "x": -3,
      "y": 20,
      "z": -3,
      "name": "Wood_Drywood_Roof_Hollow",
      "rotation": 2
    },
    {
      "x": -3,
      "y": 5,
      "z": -2,
      "name": "Rock_Sandstone_White_Cobble"
    },
    {
      "x": -3,
      "y": 15,
      "z": -2,
      "name": "Rock_Sandstone_Brick_Smooth_Half",
      "rotation": 8
    },
    {
      "x": -3,
      "y": 16,
      "z": -2,
      "name": "Rock_Sandstone_Brick_Decorative"
    },
    {
      "x": -3,
      "y": 17,
      "z": -2,
      "name": "Rock_Sandstone_White_Cobble"
    },
    {
      "x": -3,
      "y": 18,
      "z": -2,
      "name": "Rock_Sandstone_White_Cobble"
    },
    {
      "x": -3,
      "y": 19,
      "z": -2,
      "name": "Furniture_Desert_Window"
    },
    {
      "x": -3,
      "y": 20,
      "z": -2,
      "name": "Furniture_Desert_Window"
    },
    {
      "x": -3,
      "y": 21,
      "z": -2,
      "name": "Wood_Dry_Trunk",
      "rotation": 5
    },
    {
      "x": -3,
      "y": 22,
      "z": -2,
      "name": "Wood_Drywood_Fence",
      "rotation": 2
    },
    {
      "x": -3,
      "y": 5,
      "z": -1,
      "name": "Rock_Sandstone_White_Cobble"
    },
    {
      "x": -3,
      "y": 16,
      "z": -1,
      "name": "Wood_Drywood_Planks"
    },
    {
      "x": -3,
      "y": 21,
      "z": -1,
      "name": "Wood_Drywood_Planks"
    },
    {
      "x": -3,
      "y": 22,
      "z": -1,
      "name": "Furniture_Temple_Wind_Pot"
    },
    {
      "x": -3,
      "y": 23,
      "z": -1,
      "name": "Furniture_Temple_Wind_Pot",
      "filler": 1024
    },
    {
      "x": -3,
      "y": 5,
      "z": 0,
      "name": "Rock_Sandstone_White_Cobble"
    },
    {
      "x": -3,
      "y": 14,
      "z": 0,
      "name": "Cloth_Roof_Orange_Flap"
    },
    {
      "x": -3,
      "y": 15,
      "z": 0,
      "name": "Cloth_Roof_Orange_Vertical"
    },
    {
      "x": -3,
      "y": 16,
      "z": 0,
      "name": "Wood_Drywood_Planks"
    },
    {
      "x": -3,
      "y": 21,
      "z": 0,
      "name": "Wood_Drywood_Planks"
    },
    {
      "x": -3,
      "y": 22,
      "z": 0,
      "name": "Furniture_Temple_Wind_Pot"
    },
    {
      "x": -3,
      "y": 23,
      "z": 0,
      "name": "Furniture_Temple_Wind_Pot",
      "filler": 1024
    },
    {
      "x": -3,
      "y": 5,
      "z": 1,
      "name": "Rock_Sandstone_White_Cobble"
    },
    {
      "x": -3,
      "y": 16,
      "z": 1,
      "name": "Wood_Drywood_Planks"
    },
    {
      "x": -3,
      "y": 21,
      "z": 1,
      "name": "Wood_Drywood_Planks"
    },
    {
      "x": -3,
      "y": 5,
      "z": 2,
      "name": "Rock_Sandstone_White_Cobble"
    },
    {
      "x": -3,
      "y": 6,
      "z": 2,
      "name": "Rubble_Sandstone_White_Medium"
    },
    {
      "x": -3,
      "y": 8,
      "z": 2,
      "name": "Rock_Sandstone_Brick_Half",
      "rotation": 5
    },
    {
      "x": -3,
      "y": 9,
      "z": 2,
      "name": "Rock_Sandstone_Brick"
    },
    {
      "x": -3,
      "y": 10,
      "z": 2,
      "name": "Rock_Sandstone_Brick"
    },
    {
      "x": -3,
      "y": 11,
      "z": 2,
      "name": "Rock_Sandstone_Brick"
    },
    {
      "x": -3,
      "y": 12,
      "z": 2,
      "name": "Rock_Sandstone_Brick"
    },
    {
      "x": -3,
      "y": 13,
      "z": 2,
      "name": "Rock_Sandstone_Brick"
    },
    {
      "x": -3,
      "y": 14,
      "z": 2,
      "name": "Rock_Sandstone_Brick"
    },
    {
      "x": -3,
      "y": 15,
      "z": 2,
      "name": "Rock_Sandstone_Brick"
    },
    {
      "x": -3,
      "y": 16,
      "z": 2,
      "name": "Rock_Sandstone_Brick_Stairs"
    },
    {
      "x": -3,
      "y": 21,
      "z": 2,
      "name": "Wood_Drywood_Planks"
    },
    {
      "x": -3,
      "y": 8,
      "z": 3,
      "name": "Rock_Sandstone_Brick_Half",
      "rotation": 5
    },
    {
      "x": -3,
      "y": 9,
      "z": 3,
      "name": "Rock_Sandstone_Brick"
    },
    {
      "x": -3,
      "y": 10,
      "z": 3,
      "name": "Rock_Sandstone_Brick"
    },
    {
      "x": -3,
      "y": 11,
      "z": 3,
      "name": "Rock_Sandstone_Brick"
    },
    {
      "x": -3,
      "y": 12,
      "z": 3,
      "name": "Rock_Sandstone_White_Cobble"
    },
    {
      "x": -3,
      "y": 13,
      "z": 3,
      "name": "Rock_Sandstone_White_Cobble"
    },
    {
      "x": -3,
      "y": 14,
      "z": 3,
      "name": "Rock_Sandstone_White_Cobble"
    },
    {
      "x": -3,
      "y": 15,
      "z": 3,
      "name": "Wood_Drywood_Planks"
    },
    {
      "x": -3,
      "y": 21,
      "z": 3,
      "name": "Wood_Drywood_Planks"
    },
    {
      "x": -3,
      "y": 15,
      "z": 4,
      "name": "Wood_Drywood_Planks"
    },
    {
      "x": -3,
      "y": 21,
      "z": 4,
      "name": "Wood_Drywood_Planks"
    },
    {
      "x": -3,
      "y": 15,
      "z": 5,
      "name": "Wood_Drywood_Planks"
    },
    {
      "x": -3,
      "y": 21,
      "z": 5,
      "name": "Wood_Drywood_Planks"
    },
    {
      "x": -3,
      "y": 15,
      "z": 6,
      "name": "Wood_Drywood_Planks"
    },
    {
      "x": -3,
      "y": 21,
      "z": 6,
      "name": "Wood_Drywood_Planks"
    },
    {
      "x": -3,
      "y": 15,
      "z": 7,
      "name": "Wood_Drywood_Planks"
    },
    {
      "x": -3,
      "y": 21,
      "z": 7,
      "name": "Wood_Drywood_Planks"
    },
    {
      "x": -3,
      "y": 15,
      "z": 8,
      "name": "Wood_Drywood_Planks"
    },
    {
      "x": -3,
      "y": 19,
      "z": 8,
      "name": "Rock_Sandstone_White_Cobble_Stairs",
      "rotation": 11
    },
    {
      "x": -3,
      "y": 20,
      "z": 8,
      "name": "Rock_Sandstone_White_Cobble"
    },
    {
      "x": -3,
      "y": 21,
      "z": 8,
      "name": "Wood_Dry_Trunk",
      "rotation": 5
    },
    {
      "x": -3,
      "y": 22,
      "z": 8,
      "name": "Wood_Drywood_Fence"
    },
    {
      "x": -3,
      "y": 15,
      "z": 9,
      "name": "Wood_Drywood_Planks"
    },
    {
      "x": -3,
      "y": 8,
      "z": 10,
      "name": "Rock_Sandstone_Brick_Half",
      "rotation": 5
    },
    {
      "x": -3,
      "y": 9,
      "z": 10,
      "name": "Rock_Sandstone_Brick"
    },
    {
      "x": -3,
      "y": 10,
      "z": 10,
      "name": "Rock_Sandstone_Brick"
    },
    {
      "x": -3,
      "y": 11,
      "z": 10,
      "name": "Rock_Sandstone_Brick"
    },
    {
      "x": -3,
      "y": 12,
      "z": 10,
      "name": "Rock_Sandstone_White_Cobble"
    },
    {
      "x": -3,
      "y": 13,
      "z": 10,
      "name": "Rock_Sandstone_White_Cobble"
    },
    {
      "x": -3,
      "y": 14,
      "z": 10,
      "name": "Rock_Sandstone_White_Cobble"
    },
    {
      "x": -3,
      "y": 15,
      "z": 10,
      "name": "Wood_Drywood_Planks"
    },
    {
      "x": -3,
      "y": 11,
      "z": 11,
      "name": "Rock_Sandstone_Brick_Smooth"
    },
    {
      "x": -3,
      "y": 12,
      "z": 11,
      "name": "Rock_Sandstone_White_Cobble"
    },
    {
      "x": -3,
      "y": 13,
      "z": 11,
      "name": "Rock_Sandstone_White_Cobble"
    },
    {
      "x": -3,
      "y": 14,
      "z": 11,
      "name": "Rock_Sandstone_White_Cobble"
    },
    {
      "x": -3,
      "y": 15,
      "z": 11,
      "name": "Rock_Sandstone_Brick"
    },
    {
      "x": -3,
      "y": 16,
      "z": 11,
      "name": "Rock_Sandstone_Brick_Smooth_Half"
    },
    {
      "x": -2,
      "y": 5,
      "z": -7,
      "name": "Rock_Sandstone_White_Cobble"
    },
    {
      "x": -2,
      "y": 5,
      "z": -6,
      "name": "Rock_Sandstone_Brick"
    },
    {
      "x": -2,
      "y": 6,
      "z": -6,
      "name": "Rock_Sandstone_Red_Brick_Smooth_Half"
    },
    {
      "x": -2,
      "y": 5,
      "z": -5,
      "name": "Rock_Sandstone_Brick"
    },
    {
      "x": -2,
      "y": 6,
      "z": -5,
      "name": "Rock_Sandstone_Brick_Half"
    },
    {
      "x": -2,
      "y": 5,
      "z": -4,
      "name": "Rock_Sandstone_Brick"
    },
    {
      "x": -2,
      "y": 6,
      "z": -4,
      "name": "Rock_Sandstone_Brick_Half"
    },
    {
      "x": -2,
      "y": 5,
      "z": -3,
      "name": "Rock_Sandstone_Brick"
    },
    {
      "x": -2,
      "y": 6,
      "z": -3,
      "name": "Rock_Sandstone_Brick_Half"
    },
    {
      "x": -2,
      "y": 18,
      "z": -3,
      "name": "Rock_Sandstone_Brick_Smooth_Half",
      "rotation": 6
    },
    {
      "x": -2,
      "y": 20,
      "z": -3,
      "name": "Wood_Drywood_Roof_Hollow",
      "rotation": 2
    },
    {
      "x": -2,
      "y": 5,
      "z": -2,
      "name": "Rock_Sandstone_Brick"
    },
    {
      "x": -2,
      "y": 6,
      "z": -2,
      "name": "Rock_Sandstone_Red_Brick_Smooth_Half"
    },
    {
      "x": -2,
      "y": 15,
      "z": -2,
      "name": "Rock_Sandstone_Brick_Smooth_Half",
      "rotation": 8
    },
    {
      "x": -2,
      "y": 16,
      "z": -2,
      "name": "Rock_Sandstone_Brick_Decorative"
    },
    {
      "x": -2,
      "y": 17,
      "z": -2,
      "name": "Rock_Sandstone_White_Cobble"
    },
    {
      "x": -2,
      "y": 18,
      "z": -2,
      "name": "Rock_Sandstone_White_Cobble"
    },
    {
      "x": -2,
      "y": 19,
      "z": -2,
      "name": "Furniture_Desert_Window"
    },
    {
      "x": -2,
      "y": 20,
      "z": -2,
      "name": "Furniture_Desert_Window"
    },
    {
      "x": -2,
      "y": 21,
      "z": -2,
      "name": "Wood_Dry_Trunk",
      "rotation": 5
    },
    {
      "x": -2,
      "y": 22,
      "z": -2,
      "name": "Wood_Drywood_Fence",
      "rotation": 2
    },
    {
      "x": -2,
      "y": 5,
      "z": -1,
      "name": "Rock_Sandstone_White_Cobble"
    },
    {
      "x": -2,
      "y": 16,
      "z": -1,
      "name": "Wood_Drywood_Planks"
    },
    {
      "x": -2,
      "y": 21,
      "z": -1,
      "name": "Wood_Drywood_Planks"
    },
    {
      "x": -2,
      "y": 22,
      "z": -1,
      "name": "Wood_Dry_Branch_Long"
    },
    {
      "x": -2,
      "y": 23,
      "z": -1,
      "name": "Wood_Dry_Branch_Long"
    },
    {
      "x": -2,
      "y": 5,
      "z": 0,
      "name": "Rock_Sandstone_White_Cobble"
    },
    {
      "x": -2,
      "y": 13,
      "z": 0,
      "name": "Cloth_Roof_Orange_Flap"
    },
    {
      "x": -2,
      "y": 14,
      "z": 0,
      "name": "Cloth_Roof_Orange_Vertical"
    },
    {
      "x": -2,
      "y": 15,
      "z": 0,
      "name": "Cloth_Roof_Orange_Vertical"
    },
    {
      "x": -2,
      "y": 16,
      "z": 0,
      "name": "Wood_Drywood_Planks"
    },
    {
      "x": -2,
      "y": 21,
      "z": 0,
      "name": "Wood_Drywood_Planks"
    },
    {
      "x": -2,
      "y": 5,
      "z": 1,
      "name": "Rock_Sandstone_White_Cobble"
    },
    {
      "x": -2,
      "y": 16,
      "z": 1,
      "name": "Wood_Drywood_Planks"
    },
    {
      "x": -2,
      "y": 21,
      "z": 1,
      "name": "Wood_Drywood_Planks"
    },
    {
      "x": -2,
      "y": 5,
      "z": 2,
      "name": "Rock_Sandstone_White_Cobble"
    },
    {
      "x": -2,
      "y": 9,
      "z": 2,
      "name": "Rock_Sandstone_Brick_Half",
      "rotation": 8
    },
    {
      "x": -2,
      "y": 10,
      "z": 2,
      "name": "Rock_Sandstone_Brick"
    },
    {
      "x": -2,
      "y": 11,
      "z": 2,
      "name": "Rock_Sandstone_Brick"
    },
    {
      "x": -2,
      "y": 12,
      "z": 2,
      "name": "Rock_Sandstone_Brick"
    },
    {
      "x": -2,
      "y": 13,
      "z": 2,
      "name": "Rock_Sandstone_Brick"
    },
    {
      "x": -2,
      "y": 14,
      "z": 2,
      "name": "Rock_Sandstone_Brick"
    },
    {
      "x": -2,
      "y": 15,
      "z": 2,
      "name": "Rock_Sandstone_Brick"
    },
    {
      "x": -2,
      "y": 16,
      "z": 2,
      "name": "Rock_Sandstone_Brick_Stairs"
    },
    {
      "x": -2,
      "y": 21,
      "z": 2,
      "name": "Wood_Drywood_Planks"
    },
    {
      "x": -2,
      "y": 9,
      "z": 3,
      "name": "Rock_Sandstone_Brick_Half",
      "rotation": 8
    },
    {
      "x": -2,
      "y": 10,
      "z": 3,
      "name": "Rock_Sandstone_Brick"
    },
    {
      "x": -2,
      "y": 11,
      "z": 3,
      "name": "Rock_Sandstone_Brick"
    },
    {
      "x": -2,
      "y": 12,
      "z": 3,
      "name": "Rock_Sandstone_White_Cobble"
    },
    {
      "x": -2,
      "y": 13,
      "z": 3,
      "name": "Rock_Sandstone_White_Cobble"
    },
    {
      "x": -2,
      "y": 14,
      "z": 3,
      "name": "Rock_Sandstone_White_Cobble"
    },
    {
      "x": -2,
      "y": 15,
      "z": 3,
      "name": "Wood_Drywood_Planks"
    },
    {
      "x": -2,
      "y": 21,
      "z": 3,
      "name": "Wood_Drywood_Planks"
    },
    {
      "x": -2,
      "y": 15,
      "z": 4,
      "name": "Wood_Drywood_Planks"
    },
    {
      "x": -2,
      "y": 21,
      "z": 4,
      "name": "Wood_Drywood_Planks"
    },
    {
      "x": -2,
      "y": 15,
      "z": 5,
      "name": "Wood_Drywood_Planks"
    },
    {
      "x": -2,
      "y": 21,
      "z": 5,
      "name": "Wood_Drywood_Planks"
    },
    {
      "x": -2,
      "y": 22,
      "z": 5,
      "name": "Wood_Dry_Branch_Long"
    },
    {
      "x": -2,
      "y": 23,
      "z": 5,
      "name": "Wood_Dry_Branch_Long"
    },
    {
      "x": -2,
      "y": 15,
      "z": 6,
      "name": "Wood_Drywood_Planks"
    },
    {
      "x": -2,
      "y": 21,
      "z": 6,
      "name": "Wood_Drywood_Planks"
    },
    {
      "x": -2,
      "y": 15,
      "z": 7,
      "name": "Wood_Drywood_Planks"
    },
    {
      "x": -2,
      "y": 21,
      "z": 7,
      "name": "Wood_Drywood_Planks"
    },
    {
      "x": -2,
      "y": 15,
      "z": 8,
      "name": "Wood_Drywood_Planks"
    },
    {
      "x": -2,
      "y": 19,
      "z": 8,
      "name": "Rock_Sandstone_White_Cobble_Half",
      "rotation": 8
    },
    {
      "x": -2,
      "y": 20,
      "z": 8,
      "name": "Rock_Sandstone_White_Cobble"
    },
    {
      "x": -2,
      "y": 21,
      "z": 8,
      "name": "Wood_Dry_Trunk",
      "rotation": 5
    },
    {
      "x": -2,
      "y": 22,
      "z": 8,
      "name": "Wood_Drywood_Fence"
    },
    {
      "x": -2,
      "y": 15,
      "z": 9,
      "name": "Wood_Drywood_Planks"
    },
    {
      "x": -2,
      "y": 9,
      "z": 10,
      "name": "Rock_Sandstone_Brick_Half",
      "rotation": 8
    },
    {
      "x": -2,
      "y": 10,
      "z": 10,
      "name": "Rock_Sandstone_Brick"
    },
    {
      "x": -2,
      "y": 11,
      "z": 10,
      "name": "Rock_Sandstone_Brick"
    },
    {
      "x": -2,
      "y": 12,
      "z": 10,
      "name": "Rock_Sandstone_White_Cobble"
    },
    {
      "x": -2,
      "y": 13,
      "z": 10,
      "name": "Rock_Sandstone_White_Cobble"
    },
    {
      "x": -2,
      "y": 14,
      "z": 10,
      "name": "Rock_Sandstone_White_Cobble"
    },
    {
      "x": -2,
      "y": 15,
      "z": 10,
      "name": "Wood_Drywood_Planks"
    },
    {
      "x": -2,
      "y": 11,
      "z": 11,
      "name": "Rock_Sandstone_Brick_Smooth"
    },
    {
      "x": -2,
      "y": 12,
      "z": 11,
      "name": "Rock_Sandstone_White_Cobble"
    },
    {
      "x": -2,
      "y": 13,
      "z": 11,
      "name": "Rock_Sandstone_White_Cobble"
    },
    {
      "x": -2,
      "y": 14,
      "z": 11,
      "name": "Rock_Sandstone_White_Cobble"
    },
    {
      "x": -2,
      "y": 15,
      "z": 11,
      "name": "Rock_Sandstone_Brick"
    },
    {
      "x": -2,
      "y": 16,
      "z": 11,
      "name": "Rock_Sandstone_Brick_Smooth_Half"
    },
    {
      "x": -1,
      "y": 5,
      "z": -7,
      "name": "Rock_Sandstone_White_Cobble"
    },
    {
      "x": -1,
      "y": 6,
      "z": -7,
      "name": "Deco_Pot_Clay_Broken"
    },
    {
      "x": -1,
      "y": 5,
      "z": -6,
      "name": "Rock_Sandstone_Brick"
    },
    {
      "x": -1,
      "y": 6,
      "z": -6,
      "name": "Rock_Sandstone_Brick_Half"
    },
    {
      "x": -1,
      "y": 5,
      "z": -5,
      "name": "Soil_Mud_Dry"
    },
    {
      "x": -1,
      "y": 5,
      "z": -4,
      "name": "Soil_Mud_Dry"
    },
    {
      "x": -1,
      "y": 5,
      "z": -3,
      "name": "Soil_Mud_Dry"
    },
    {
      "x": -1,
      "y": 18,
      "z": -3,
      "name": "Rock_Sandstone_Brick_Smooth_Half",
      "rotation": 6
    },
    {
      "x": -1,
      "y": 20,
      "z": -3,
      "name": "Wood_Drywood_Roof_Hollow",
      "rotation": 2
    },
    {
      "x": -1,
      "y": 5,
      "z": -2,
      "name": "Rock_Sandstone_Brick"
    },
    {
      "x": -1,
      "y": 6,
      "z": -2,
      "name": "Rock_Sandstone_Brick"
    },
    {
      "x": -1,
      "y": 15,
      "z": -2,
      "name": "Rock_Sandstone_Brick_Smooth_Half",
      "rotation": 8
    },
    {
      "x": -1,
      "y": 16,
      "z": -2,
      "name": "Rock_Sandstone_Brick_Decorative"
    },
    {
      "x": -1,
      "y": 17,
      "z": -2,
      "name": "Rock_Sandstone_White_Cobble"
    },
    {
      "x": -1,
      "y": 18,
      "z": -2,
      "name": "Rock_Sandstone_White_Cobble"
    },
    {
      "x": -1,
      "y": 19,
      "z": -2,
      "name": "Furniture_Desert_Window"
    },
    {
      "x": -1,
      "y": 20,
      "z": -2,
      "name": "Furniture_Desert_Window"
    },
    {
      "x": -1,
      "y": 21,
      "z": -2,
      "name": "Wood_Dry_Trunk",
      "rotation": 5
    },
    {
      "x": -1,
      "y": 22,
      "z": -2,
      "name": "Wood_Drywood_Fence",
      "rotation": 2
    },
    {
      "x": -1,
      "y": 5,
      "z": -1,
      "name": "Rock_Sandstone_White_Cobble"
    },
    {
      "x": -1,
      "y": 16,
      "z": -1,
      "name": "Wood_Drywood_Planks"
    },
    {
      "x": -1,
      "y": 21,
      "z": -1,
      "name": "Wood_Drywood_Planks"
    },
    {
      "x": -1,
      "y": 5,
      "z": 0,
      "name": "Rock_Sandstone_White_Cobble"
    },
    {
      "x": -1,
      "y": 13,
      "z": 0,
      "name": "Cloth_Roof_Orange_Flap"
    },
    {
      "x": -1,
      "y": 14,
      "z": 0,
      "name": "Cloth_Roof_Orange_Vertical"
    },
    {
      "x": -1,
      "y": 15,
      "z": 0,
      "name": "Cloth_Roof_Orange_Vertical"
    },
    {
      "x": -1,
      "y": 16,
      "z": 0,
      "name": "Wood_Drywood_Planks"
    },
    {
      "x": -1,
      "y": 21,
      "z": 0,
      "name": "Wood_Drywood_Planks"
    },
    {
      "x": -1,
      "y": 5,
      "z": 1,
      "name": "Rock_Sandstone_White_Cobble"
    },
    {
      "x": -1,
      "y": 16,
      "z": 1,
      "name": "Wood_Drywood_Planks"
    },
    {
      "x": -1,
      "y": 21,
      "z": 1,
      "name": "Wood_Drywood_Planks"
    },
    {
      "x": -1,
      "y": 5,
      "z": 2,
      "name": "Rock_Sandstone_White_Cobble"
    },
    {
      "x": -1,
      "y": 8,
      "z": 2,
      "name": "Rock_Sandstone_Brick_Half",
      "rotation": 7
    },
    {
      "x": -1,
      "y": 9,
      "z": 2,
      "name": "Rock_Sandstone_Brick"
    },
    {
      "x": -1,
      "y": 10,
      "z": 2,
      "name": "Rock_Sandstone_Brick"
    },
    {
      "x": -1,
      "y": 11,
      "z": 2,
      "name": "Rock_Sandstone_Brick"
    },
    {
      "x": -1,
      "y": 12,
      "z": 2,
      "name": "Rock_Sandstone_Brick"
    },
    {
      "x": -1,
      "y": 13,
      "z": 2,
      "name": "Rock_Sandstone_Brick"
    },
    {
      "x": -1,
      "y": 14,
      "z": 2,
      "name": "Rock_Sandstone_Brick"
    },
    {
      "x": -1,
      "y": 15,
      "z": 2,
      "name": "Rock_Sandstone_Brick"
    },
    {
      "x": -1,
      "y": 16,
      "z": 2,
      "name": "Rock_Sandstone_Brick_Stairs"
    },
    {
      "x": -1,
      "y": 21,
      "z": 2,
      "name": "Wood_Drywood_Planks"
    },
    {
      "x": -1,
      "y": 8,
      "z": 3,
      "name": "Rock_Sandstone_Brick_Half",
      "rotation": 7
    },
    {
      "x": -1,
      "y": 9,
      "z": 3,
      "name": "Rock_Sandstone_Brick"
    },
    {
      "x": -1,
      "y": 10,
      "z": 3,
      "name": "Rock_Sandstone_Brick"
    },
    {
      "x": -1,
      "y": 11,
      "z": 3,
      "name": "Rock_Sandstone_Brick"
    },
    {
      "x": -1,
      "y": 12,
      "z": 3,
      "name": "Rock_Sandstone_White_Cobble"
    },
    {
      "x": -1,
      "y": 13,
      "z": 3,
      "name": "Rock_Sandstone_White_Cobble"
    },
    {
      "x": -1,
      "y": 14,
      "z": 3,
      "name": "Rock_Sandstone_White_Cobble"
    },
    {
      "x": -1,
      "y": 15,
      "z": 3,
      "name": "Wood_Drywood_Planks"
    },
    {
      "x": -1,
      "y": 21,
      "z": 3,
      "name": "Wood_Drywood_Planks"
    },
    {
      "x": -1,
      "y": 15,
      "z": 4,
      "name": "Wood_Drywood_Planks"
    },
    {
      "x": -1,
      "y": 21,
      "z": 4,
      "name": "Wood_Drywood_Planks"
    },
    {
      "x": -1,
      "y": 15,
      "z": 5,
      "name": "Wood_Drywood_Planks"
    },
    {
      "x": -1,
      "y": 21,
      "z": 5,
      "name": "Wood_Drywood_Planks"
    },
    {
      "x": -1,
      "y": 15,
      "z": 6,
      "name": "Wood_Drywood_Planks"
    },
    {
      "x": -1,
      "y": 21,
      "z": 6,
      "name": "Wood_Drywood_Planks"
    },
    {
      "x": -1,
      "y": 15,
      "z": 7,
      "name": "Wood_Drywood_Planks"
    },
    {
      "x": -1,
      "y": 21,
      "z": 7,
      "name": "Wood_Drywood_Planks"
    },
    {
      "x": -1,
      "y": 15,
      "z": 8,
      "name": "Wood_Drywood_Planks"
    },
    {
      "x": -1,
      "y": 19,
      "z": 8,
      "name": "Rock_Sandstone_White_Cobble_Stairs",
      "rotation": 9
    },
    {
      "x": -1,
      "y": 20,
      "z": 8,
      "name": "Rock_Sandstone_White_Cobble"
    },
    {
      "x": -1,
      "y": 21,
      "z": 8,
      "name": "Wood_Dry_Trunk",
      "rotation": 5
    },
    {
      "x": -1,
      "y": 22,
      "z": 8,
      "name": "Wood_Drywood_Fence"
    },
    {
      "x": -1,
      "y": 15,
      "z": 9,
      "name": "Wood_Drywood_Planks"
    },
    {
      "x": -1,
      "y": 8,
      "z": 10,
      "name": "Rock_Sandstone_Brick_Half",
      "rotation": 7
    },
    {
      "x": -1,
      "y": 9,
      "z": 10,
      "name": "Rock_Sandstone_Brick"
    },
    {
      "x": -1,
      "y": 10,
      "z": 10,
      "name": "Rock_Sandstone_Brick"
    },
    {
      "x": -1,
      "y": 11,
      "z": 10,
      "name": "Rock_Sandstone_Brick"
    },
    {
      "x": -1,
      "y": 12,
      "z": 10,
      "name": "Rock_Sandstone_White_Cobble"
    },
    {
      "x": -1,
      "y": 13,
      "z": 10,
      "name": "Rock_Sandstone_White_Cobble"
    },
    {
      "x": -1,
      "y": 14,
      "z": 10,
      "name": "Rock_Sandstone_White_Cobble"
    },
    {
      "x": -1,
      "y": 15,
      "z": 10,
      "name": "Wood_Drywood_Planks"
    },
    {
      "x": -1,
      "y": 11,
      "z": 11,
      "name": "Rock_Sandstone_Brick_Smooth"
    },
    {
      "x": -1,
      "y": 12,
      "z": 11,
      "name": "Rock_Sandstone_White_Cobble"
    },
    {
      "x": -1,
      "y": 13,
      "z": 11,
      "name": "Rock_Sandstone_White_Cobble"
    },
    {
      "x": -1,
      "y": 14,
      "z": 11,
      "name": "Rock_Sandstone_White_Cobble"
    },
    {
      "x": -1,
      "y": 15,
      "z": 11,
      "name": "Rock_Sandstone_Brick"
    },
    {
      "x": -1,
      "y": 16,
      "z": 11,
      "name": "Rock_Sandstone_Brick_Smooth_Half"
    },
    {
      "x": 0,
      "y": 5,
      "z": -7,
      "name": "Rock_Sandstone_White_Cobble"
    },
    {
      "x": 0,
      "y": 6,
      "z": -7,
      "name": "Deco_Bucket"
    },
    {
      "x": 0,
      "y": 5,
      "z": -6,
      "name": "Rock_Sandstone_Brick"
    },
    {
      "x": 0,
      "y": 6,
      "z": -6,
      "name": "Rock_Sandstone_Brick_Half"
    },
    {
      "x": 0,
      "y": 5,
      "z": -5,
      "name": "Soil_Mud_Dry"
    },
    {
      "x": 0,
      "y": 5,
      "z": -4,
      "name": "Soil_Mud_Dry"
    },
    {
      "x": 0,
      "y": 6,
      "z": -4,
      "name": "Furniture_Human_Ruins_Statue_Broken",
      "rotation": 2
    },
    {
      "x": 0,
      "y": 7,
      "z": -4,
      "name": "Furniture_Human_Ruins_Statue_Broken",
      "filler": 1024,
      "rotation": 2
    },
    {
      "x": 0,
      "y": 8,
      "z": -4,
      "name": "Furniture_Human_Ruins_Statue_Broken",
      "filler": 2048,
      "rotation": 2
    },
    {
      "x": 0,
      "y": 5,
      "z": -3,
      "name": "Soil_Mud_Dry"
    },
    {
      "x": 0,
      "y": 21,
      "z": -3,
      "name": "Wood_Dry_Branch_Short",
      "rotation": 2
    },
    {
      "x": 0,
      "y": 5,
      "z": -2,
      "name": "Rock_Sandstone_Brick"
    },
    {
      "x": 0,
      "y": 6,
      "z": -2,
      "name": "Rock_Sandstone_Red_Brick"
    },
    {
      "x": 0,
      "y": 7,
      "z": -2,
      "name": "Rock_Sandstone_Red_Brick_Smooth_Half"
    },
    {
      "x": 0,
      "y": 15,
      "z": -2,
      "name": "Rock_Sandstone_Brick_Smooth_Half",
      "rotation": 8
    },
    {
      "x": 0,
      "y": 16,
      "z": -2,
      "name": "Rock_Sandstone_Brick_Decorative"
    },
    {
      "x": 0,
      "y": 17,
      "z": -2,
      "name": "Rock_Sandstone_White_Cobble"
    },
    {
      "x": 0,
      "y": 18,
      "z": -2,
      "name": "Rock_Sandstone_White_Cobble"
    },
    {
      "x": 0,
      "y": 19,
      "z": -2,
      "name": "Rock_Sandstone_White_Cobble"
    },
    {
      "x": 0,
      "y": 20,
      "z": -2,
      "name": "Rock_Sandstone_White_Cobble"
    },
    {
      "x": 0,
      "y": 21,
      "z": -2,
      "name": "Wood_Dry_Trunk",
      "rotation": 5
    },
    {
      "x": 0,
      "y": 22,
      "z": -2,
      "name": "Wood_Drywood_Fence",
      "rotation": 2
    },
    {
      "x": 0,
      "y": 5,
      "z": -1,
      "name": "Rock_Sandstone_White_Cobble"
    },
    {
      "x": 0,
      "y": 16,
      "z": -1,
      "name": "Wood_Drywood_Planks"
    },
    {
      "x": 0,
      "y": 17,
      "z": -1,
      "name": "Rock_Sandstone_Brick_Stairs",
      "rotation": 3
    },
    {
      "x": 0,
      "y": 21,
      "z": -1,
      "name": "Wood_Drywood_Planks"
    },
    {
      "x": 0,
      "y": 22,
      "z": -1,
      "name": "Wood_Drywood_Beam"
    },
    {
      "x": 0,
      "y": 23,
      "z": -1,
      "name": "Wood_Drywood_Beam"
    },
    {
      "x": 0,
      "y": 24,
      "z": -1,
      "name": "Wood_Drywood_Beam"
    },
    {
      "x": 0,
      "y": 5,
      "z": 0,
      "name": "Rock_Sandstone_White_Cobble"
    },
    {
      "x": 0,
      "y": 14,
      "z": 0,
      "name": "Cloth_Roof_Orange_Flap"
    },
    {
      "x": 0,
      "y": 15,
      "z": 0,
      "name": "Cloth_Roof_Orange_Vertical"
    },
    {
      "x": 0,
      "y": 16,
      "z": 0,
      "name": "Wood_Drywood_Planks"
    },
    {
      "x": 0,
      "y": 17,
      "z": 0,
      "name": "Rock_Sandstone_Brick_Stairs",
      "rotation": 3
    },
    {
      "x": 0,
      "y": 21,
      "z": 0,
      "name": "Wood_Drywood_Planks"
    },
    {
      "x": 0,
      "y": 5,
      "z": 1,
      "name": "Rock_Sandstone_White_Cobble"
    },
    {
      "x": 0,
      "y": 16,
      "z": 1,
      "name": "Wood_Drywood_Planks"
    },
    {
      "x": 0,
      "y": 17,
      "z": 1,
      "name": "Rock_Sandstone_Brick_Stairs",
      "rotation": 3
    },
    {
      "x": 0,
      "y": 21,
      "z": 1,
      "name": "Wood_Drywood_Planks"
    },
    {
      "x": 0,
      "y": 5,
      "z": 2,
      "name": "Rock_Sandstone_Cobble"
    },
    {
      "x": 0,
      "y": 6,
      "z": 2,
      "name": "Rock_Sandstone_Brick"
    },
    {
      "x": 0,
      "y": 7,
      "z": 2,
      "name": "Rock_Sandstone_Brick"
    },
    {
      "x": 0,
      "y": 8,
      "z": 2,
      "name": "Rock_Sandstone_Brick"
    },
    {
      "x": 0,
      "y": 9,
      "z": 2,
      "name": "Rock_Sandstone_Brick"
    },
    {
      "x": 0,
      "y": 10,
      "z": 2,
      "name": "Rock_Sandstone_Brick"
    },
    {
      "x": 0,
      "y": 11,
      "z": 2,
      "name": "Rock_Sandstone_Brick"
    },
    {
      "x": 0,
      "y": 12,
      "z": 2,
      "name": "Rock_Sandstone_Brick"
    },
    {
      "x": 0,
      "y": 13,
      "z": 2,
      "name": "Rock_Sandstone_Brick"
    },
    {
      "x": 0,
      "y": 14,
      "z": 2,
      "name": "Rock_Sandstone_Brick"
    },
    {
      "x": 0,
      "y": 15,
      "z": 2,
      "name": "Rock_Sandstone_Brick"
    },
    {
      "x": 0,
      "y": 16,
      "z": 2,
      "name": "Wood_Dry_Trunk"
    },
    {
      "x": 0,
      "y": 17,
      "z": 2,
      "name": "Wood_Dry_Trunk"
    },
    {
      "x": 0,
      "y": 18,
      "z": 2,
      "name": "Wood_Dry_Trunk"
    },
    {
      "x": 0,
      "y": 19,
      "z": 2,
      "name": "Wood_Dry_Trunk"
    },
    {
      "x": 0,
      "y": 20,
      "z": 2,
      "name": "Wood_Dry_Trunk"
    },
    {
      "x": 0,
      "y": 21,
      "z": 2,
      "name": "Wood_Drywood_Planks"
    },
    {
      "x": 0,
      "y": 5,
      "z": 3,
      "name": "Rock_Sandstone_Cobble"
    },
    {
      "x": 0,
      "y": 6,
      "z": 3,
      "name": "Rock_Sandstone_Brick"
    },
    {
      "x": 0,
      "y": 7,
      "z": 3,
      "name": "Rock_Sandstone_Brick"
    },
    {
      "x": 0,
      "y": 8,
      "z": 3,
      "name": "Rock_Sandstone_Brick"
    },
    {
      "x": 0,
      "y": 9,
      "z": 3,
      "name": "Rock_Sandstone_Brick"
    },
    {
      "x": 0,
      "y": 10,
      "z": 3,
      "name": "Rock_Sandstone_Brick"
    },
    {
      "x": 0,
      "y": 11,
      "z": 3,
      "name": "Rock_Sandstone_Brick"
    },
    {
      "x": 0,
      "y": 12,
      "z": 3,
      "name": "Rock_Sandstone_White_Cobble"
    },
    {
      "x": 0,
      "y": 13,
      "z": 3,
      "name": "Rock_Sandstone_White_Cobble"
    },
    {
      "x": 0,
      "y": 14,
      "z": 3,
      "name": "Rock_Sandstone_White_Cobble"
    },
    {
      "x": 0,
      "y": 15,
      "z": 3,
      "name": "Wood_Drywood_Planks"
    },
    {
      "x": 0,
      "y": 17,
      "z": 3,
      "name": "Wood_Torch_Wall"
    },
    {
      "x": 0,
      "y": 21,
      "z": 3,
      "name": "Wood_Drywood_Planks"
    },
    {
      "x": 0,
      "y": 25,
      "z": 3,
      "name": "Wood_Drywood_Beam",
      "rotation": 4
    },
    {
      "x": 0,
      "y": 11,
      "z": 4,
      "name": "Rock_Sandstone_Brick"
    },
    {
      "x": 0,
      "y": 15,
      "z": 4,
      "name": "Wood_Drywood_Planks"
    },
    {
      "x": 0,
      "y": 21,
      "z": 4,
      "name": "Wood_Drywood_Planks"
    },
    {
      "x": 0,
      "y": 25,
      "z": 4,
      "name": "Wood_Drywood_Beam",
      "rotation": 4
    },
    {
      "x": 0,
      "y": 11,
      "z": 5,
      "name": "Rock_Sandstone_Brick"
    },
    {
      "x": 0,
      "y": 15,
      "z": 5,
      "name": "Wood_Drywood_Planks"
    },
    {
      "x": 0,
      "y": 21,
      "z": 5,
      "name": "Wood_Drywood_Planks"
    },
    {
      "x": 0,
      "y": 22,
      "z": 5,
      "name": "Wood_Drywood_Beam"
    },
    {
      "x": 0,
      "y": 23,
      "z": 5,
      "name": "Wood_Drywood_Beam"
    },
    {
      "x": 0,
      "y": 24,
      "z": 5,
      "name": "Wood_Drywood_Beam"
    },
    {
      "x": 0,
      "y": 25,
      "z": 5,
      "name": "Wood_Drywood_Planks_Half"
    },
    {
      "x": 0,
      "y": 11,
      "z": 6,
      "name": "Rock_Sandstone_Brick"
    },
    {
      "x": 0,
      "y": 15,
      "z": 6,
      "name": "Wood_Drywood_Planks"
    },
    {
      "x": 0,
      "y": 21,
      "z": 6,
      "name": "Wood_Drywood_Planks"
    },
    {
      "x": 0,
      "y": 11,
      "z": 7,
      "name": "Rock_Sandstone_Brick"
    },
    {
      "x": 0,
      "y": 15,
      "z": 7,
      "name": "Wood_Drywood_Planks"
    },
    {
      "x": 0,
      "y": 21,
      "z": 7,
      "name": "Wood_Drywood_Planks"
    },
    {
      "x": 0,
      "y": 11,
      "z": 8,
      "name": "Rock_Sandstone_Brick"
    },
    {
      "x": 0,
      "y": 15,
      "z": 8,
      "name": "Wood_Drywood_Planks"
    },
    {
      "x": 0,
      "y": 16,
      "z": 8,
      "name": "Rock_Sandstone_Brick_Decorative"
    },
    {
      "x": 0,
      "y": 17,
      "z": 8,
      "name": "Rock_Sandstone_White_Cobble"
    },
    {
      "x": 0,
      "y": 18,
      "z": 8,
      "name": "Rock_Sandstone_White_Cobble"
    },
    {
      "x": 0,
      "y": 19,
      "z": 8,
      "name": "Rock_Sandstone_White_Cobble"
    },
    {
      "x": 0,
      "y": 20,
      "z": 8,
      "name": "Rock_Sandstone_White_Cobble"
    },
    {
      "x": 0,
      "y": 21,
      "z": 8,
      "name": "Wood_Dry_Trunk",
      "rotation": 5
    },
    {
      "x": 0,
      "y": 22,
      "z": 8,
      "name": "Wood_Drywood_Fence"
    },
    {
      "x": 0,
      "y": 23,
      "z": 8,
      "name": "Furniture_Crude_Torch"
    },
    {
      "x": 0,
      "y": 11,
      "z": 9,
      "name": "Rock_Sandstone_Brick"
    },
    {
      "x": 0,
      "y": 15,
      "z": 9,
      "name": "Wood_Drywood_Planks"
    },
    {
      "x": 0,
      "y": 21,
      "z": 9,
      "name": "Wood_Dry_Branch_Short"
    },
    {
      "x": 0,
      "y": 5,
      "z": 10,
      "name": "Rock_Sandstone_Cobble"
    },
    {
      "x": 0,
      "y": 6,
      "z": 10,
      "name": "Rock_Sandstone_Brick"
    },
    {
      "x": 0,
      "y": 7,
      "z": 10,
      "name": "Rock_Sandstone_Brick"
    },
    {
      "x": 0,
      "y": 8,
      "z": 10,
      "name": "Rock_Sandstone_Brick"
    },
    {
      "x": 0,
      "y": 9,
      "z": 10,
      "name": "Rock_Sandstone_Brick"
    },
    {
      "x": 0,
      "y": 10,
      "z": 10,
      "name": "Rock_Sandstone_Brick"
    },
    {
      "x": 0,
      "y": 11,
      "z": 10,
      "name": "Rock_Sandstone_Brick"
    },
    {
      "x": 0,
      "y": 12,
      "z": 10,
      "name": "Rock_Sandstone_White_Cobble"
    },
    {
      "x": 0,
      "y": 13,
      "z": 10,
      "name": "Rock_Sandstone_White_Cobble"
    },
    {
      "x": 0,
      "y": 14,
      "z": 10,
      "name": "Rock_Sandstone_White_Cobble"
    },
    {
      "x": 0,
      "y": 15,
      "z": 10,
      "name": "Wood_Drywood_Planks"
    },
    {
      "x": 0,
      "y": 5,
      "z": 11,
      "name": "Rock_Sandstone_Cobble"
    },
    {
      "x": 0,
      "y": 6,
      "z": 11,
      "name": "Rock_Sandstone_Brick_Half",
      "rotation": 4
    },
    {
      "x": 0,
      "y": 7,
      "z": 11,
      "name": "Rock_Sandstone_Brick_Half",
      "rotation": 4
    },
    {
      "x": 0,
      "y": 8,
      "z": 11,
      "name": "Rock_Sandstone_Brick_Half",
      "rotation": 4
    },
    {
      "x": 0,
      "y": 9,
      "z": 11,
      "name": "Rock_Sandstone_Brick_Half",
      "rotation": 4
    },
    {
      "x": 0,
      "y": 10,
      "z": 11,
      "name": "Rock_Sandstone_Brick_Half",
      "rotation": 4
    },
    {
      "x": 0,
      "y": 11,
      "z": 11,
      "name": "Rock_Sandstone_Brick_Smooth"
    },
    {
      "x": 0,
      "y": 12,
      "z": 11,
      "name": "Rock_Sandstone_White_Cobble"
    },
    {
      "x": 0,
      "y": 13,
      "z": 11,
      "name": "Rock_Sandstone_White_Cobble"
    },
    {
      "x": 0,
      "y": 14,
      "z": 11,
      "name": "Rock_Sandstone_White_Cobble"
    },
    {
      "x": 0,
      "y": 15,
      "z": 11,
      "name": "Rock_Sandstone_Brick"
    },
    {
      "x": 0,
      "y": 16,
      "z": 11,
      "name": "Rock_Sandstone_Brick_Smooth_Half"
    },
    {
      "x": 1,
      "y": 5,
      "z": -7,
      "name": "Rock_Sandstone_White_Cobble"
    },
    {
      "x": 1,
      "y": 5,
      "z": -6,
      "name": "Rock_Sandstone_Brick"
    },
    {
      "x": 1,
      "y": 6,
      "z": -6,
      "name": "Rock_Sandstone_Brick_Half"
    },
    {
      "x": 1,
      "y": 5,
      "z": -5,
      "name": "Soil_Mud_Dry"
    },
    {
      "x": 1,
      "y": 5,
      "z": -4,
      "name": "Soil_Mud_Dry"
    },
    {
      "x": 1,
      "y": 5,
      "z": -3,
      "name": "Soil_Mud_Dry"
    },
    {
      "x": 1,
      "y": 18,
      "z": -3,
      "name": "Rock_Sandstone_Brick_Smooth_Half",
      "rotation": 6
    },
    {
      "x": 1,
      "y": 20,
      "z": -3,
      "name": "Wood_Drywood_Roof_Hollow",
      "rotation": 2
    },
    {
      "x": 1,
      "y": 5,
      "z": -2,
      "name": "Rock_Sandstone_Brick"
    },
    {
      "x": 1,
      "y": 6,
      "z": -2,
      "name": "Rock_Sandstone_Brick"
    },
    {
      "x": 1,
      "y": 15,
      "z": -2,
      "name": "Rock_Sandstone_Brick_Smooth_Half",
      "rotation": 8
    },
    {
      "x": 1,
      "y": 16,
      "z": -2,
      "name": "Rock_Sandstone_Brick_Decorative"
    },
    {
      "x": 1,
      "y": 17,
      "z": -2,
      "name": "Rock_Sandstone_White_Cobble"
    },
    {
      "x": 1,
      "y": 18,
      "z": -2,
      "name": "Rock_Sandstone_White_Cobble"
    },
    {
      "x": 1,
      "y": 19,
      "z": -2,
      "name": "Furniture_Desert_Window"
    },
    {
      "x": 1,
      "y": 20,
      "z": -2,
      "name": "Furniture_Desert_Window"
    },
    {
      "x": 1,
      "y": 21,
      "z": -2,
      "name": "Wood_Dry_Trunk",
      "rotation": 5
    },
    {
      "x": 1,
      "y": 22,
      "z": -2,
      "name": "Wood_Drywood_Fence",
      "rotation": 2
    },
    {
      "x": 1,
      "y": 5,
      "z": -1,
      "name": "Rock_Sandstone_White_Cobble"
    },
    {
      "x": 1,
      "y": 16,
      "z": -1,
      "name": "Wood_Drywood_Planks"
    },
    {
      "x": 1,
      "y": 17,
      "z": -1,
      "name": "Wood_Drywood_Planks"
    },
    {
      "x": 1,
      "y": 21,
      "z": -1,
      "name": "Wood_Drywood_Planks"
    },
    {
      "x": 1,
      "y": 5,
      "z": 0,
      "name": "Rock_Sandstone_White_Cobble"
    },
    {
      "x": 1,
      "y": 14,
      "z": 0,
      "name": "Cloth_Roof_Orange_Flap"
    },
    {
      "x": 1,
      "y": 15,
      "z": 0,
      "name": "Cloth_Roof_Orange_Vertical"
    },
    {
      "x": 1,
      "y": 16,
      "z": 0,
      "name": "Wood_Drywood_Planks"
    },
    {
      "x": 1,
      "y": 17,
      "z": 0,
      "name": "Wood_Drywood_Planks"
    },
    {
      "x": 1,
      "y": 21,
      "z": 0,
      "name": "Wood_Drywood_Planks"
    },
    {
      "x": 1,
      "y": 5,
      "z": 1,
      "name": "Rock_Sandstone_White_Cobble"
    },
    {
      "x": 1,
      "y": 16,
      "z": 1,
      "name": "Wood_Drywood_Planks"
    },
    {
      "x": 1,
      "y": 17,
      "z": 1,
      "name": "Wood_Drywood_Planks"
    },
    {
      "x": 1,
      "y": 21,
      "z": 1,
      "name": "Wood_Drywood_Planks"
    },
    {
      "x": 1,
      "y": 5,
      "z": 2,
      "name": "Rock_Sandstone_White_Cobble"
    },
    {
      "x": 1,
      "y": 8,
      "z": 2,
      "name": "Rock_Sandstone_Brick_Half",
      "rotation": 5
    },
    {
      "x": 1,
      "y": 9,
      "z": 2,
      "name": "Rock_Sandstone_Brick"
    },
    {
      "x": 1,
      "y": 10,
      "z": 2,
      "name": "Rock_Sandstone_Brick"
    },
    {
      "x": 1,
      "y": 11,
      "z": 2,
      "name": "Rock_Sandstone_Brick"
    },
    {
      "x": 1,
      "y": 12,
      "z": 2,
      "name": "Rock_Sandstone_Brick"
    },
    {
      "x": 1,
      "y": 13,
      "z": 2,
      "name": "Rock_Sandstone_Brick"
    },
    {
      "x": 1,
      "y": 14,
      "z": 2,
      "name": "Rock_Sandstone_Brick"
    },
    {
      "x": 1,
      "y": 15,
      "z": 2,
      "name": "Rock_Sandstone_Brick"
    },
    {
      "x": 1,
      "y": 16,
      "z": 2,
      "name": "Rock_Sandstone_Brick_Decorative"
    },
    {
      "x": 1,
      "y": 17,
      "z": 2,
      "name": "Rock_Sandstone_Brick"
    },
    {
      "x": 1,
      "y": 21,
      "z": 2,
      "name": "Wood_Drywood_Planks"
    },
    {
      "x": 1,
      "y": 25,
      "z": 2,
      "name": "Wood_Drywood_Beam",
      "rotation": 4
    },
    {
      "x": 1,
      "y": 8,
      "z": 3,
      "name": "Rock_Sandstone_Brick_Half",
      "rotation": 5
    },
    {
      "x": 1,
      "y": 9,
      "z": 3,
      "name": "Rock_Sandstone_Brick"
    },
    {
      "x": 1,
      "y": 10,
      "z": 3,
      "name": "Rock_Sandstone_Brick"
    },
    {
      "x": 1,
      "y": 11,
      "z": 3,
      "name": "Rock_Sandstone_Brick"
    },
    {
      "x": 1,
      "y": 12,
      "z": 3,
      "name": "Rock_Sandstone_White_Cobble"
    },
    {
      "x": 1,
      "y": 13,
      "z": 3,
      "name": "Rock_Sandstone_White_Cobble"
    },
    {
      "x": 1,
      "y": 14,
      "z": 3,
      "name": "Rock_Sandstone_White_Cobble"
    },
    {
      "x": 1,
      "y": 15,
      "z": 3,
      "name": "Wood_Drywood_Planks"
    },
    {
      "x": 1,
      "y": 21,
      "z": 3,
      "name": "Wood_Drywood_Planks"
    },
    {
      "x": 1,
      "y": 25,
      "z": 3,
      "name": "Wood_Drywood_Beam",
      "rotation": 4
    },
    {
      "x": 1,
      "y": 15,
      "z": 4,
      "name": "Wood_Drywood_Planks"
    },
    {
      "x": 1,
      "y": 21,
      "z": 4,
      "name": "Wood_Drywood_Planks"
    },
    {
      "x": 1,
      "y": 25,
      "z": 4,
      "name": "Wood_Drywood_Beam",
      "rotation": 4
    },
    {
      "x": 1,
      "y": 15,
      "z": 5,
      "name": "Wood_Drywood_Planks"
    },
    {
      "x": 1,
      "y": 21,
      "z": 5,
      "name": "Wood_Drywood_Planks"
    },
    {
      "x": 1,
      "y": 25,
      "z": 5,
      "name": "Wood_Drywood_Planks_Half"
    },
    {
      "x": 1,
      "y": 15,
      "z": 6,
      "name": "Wood_Drywood_Planks"
    },
    {
      "x": 1,
      "y": 21,
      "z": 6,
      "name": "Wood_Drywood_Planks"
    },
    {
      "x": 1,
      "y": 15,
      "z": 7,
      "name": "Wood_Drywood_Planks"
    },
    {
      "x": 1,
      "y": 21,
      "z": 7,
      "name": "Wood_Drywood_Planks"
    },
    {
      "x": 1,
      "y": 15,
      "z": 8,
      "name": "Wood_Drywood_Planks"
    },
    {
      "x": 1,
      "y": 16,
      "z": 8,
      "name": "Rock_Sandstone_Brick_Decorative"
    },
    {
      "x": 1,
      "y": 17,
      "z": 8,
      "name": "Rock_Sandstone_White_Cobble"
    },
    {
      "x": 1,
      "y": 18,
      "z": 8,
      "name": "Rock_Sandstone_White_Cobble"
    },
    {
      "x": 1,
      "y": 19,
      "z": 8,
      "name": "Rock_Sandstone_White_Cobble"
    },
    {
      "x": 1,
      "y": 20,
      "z": 8,
      "name": "Rock_Sandstone_White_Cobble"
    },
    {
      "x": 1,
      "y": 21,
      "z": 8,
      "name": "Wood_Dry_Trunk",
      "rotation": 5
    },
    {
      "x": 1,
      "y": 22,
      "z": 8,
      "name": "*Wood_Drywood_Fence_State_Definitions_Corner"
    },
    {
      "x": 1,
      "y": 15,
      "z": 9,
      "name": "Wood_Drywood_Planks"
    },
    {
      "x": 1,
      "y": 8,
      "z": 10,
      "name": "Rock_Sandstone_Brick_Half",
      "rotation": 5
    },
    {
      "x": 1,
      "y": 9,
      "z": 10,
      "name": "Rock_Sandstone_Brick"
    },
    {
      "x": 1,
      "y": 10,
      "z": 10,
      "name": "Rock_Sandstone_Brick"
    },
    {
      "x": 1,
      "y": 11,
      "z": 10,
      "name": "Rock_Sandstone_Brick"
    },
    {
      "x": 1,
      "y": 12,
      "z": 10,
      "name": "Rock_Sandstone_White_Cobble"
    },
    {
      "x": 1,
      "y": 13,
      "z": 10,
      "name": "Rock_Sandstone_White_Cobble"
    },
    {
      "x": 1,
      "y": 14,
      "z": 10,
      "name": "Rock_Sandstone_White_Cobble"
    },
    {
      "x": 1,
      "y": 15,
      "z": 10,
      "name": "Wood_Drywood_Planks"
    },
    {
      "x": 1,
      "y": 11,
      "z": 11,
      "name": "Rock_Sandstone_Brick_Smooth"
    },
    {
      "x": 1,
      "y": 12,
      "z": 11,
      "name": "Rock_Sandstone_White_Cobble"
    },
    {
      "x": 1,
      "y": 13,
      "z": 11,
      "name": "Rock_Sandstone_White_Cobble"
    },
    {
      "x": 1,
      "y": 14,
      "z": 11,
      "name": "Rock_Sandstone_White_Cobble"
    },
    {
      "x": 1,
      "y": 15,
      "z": 11,
      "name": "Rock_Sandstone_Brick"
    },
    {
      "x": 1,
      "y": 16,
      "z": 11,
      "name": "Rock_Sandstone_Brick_Smooth_Half"
    },
    {
      "x": 2,
      "y": 5,
      "z": -7,
      "name": "Rock_Sandstone_White_Cobble"
    },
    {
      "x": 2,
      "y": 5,
      "z": -6,
      "name": "Rock_Sandstone_Brick"
    },
    {
      "x": 2,
      "y": 6,
      "z": -6,
      "name": "Rock_Sandstone_Red_Brick_Smooth_Half"
    },
    {
      "x": 2,
      "y": 5,
      "z": -5,
      "name": "Rock_Sandstone_Brick"
    },
    {
      "x": 2,
      "y": 6,
      "z": -5,
      "name": "Rock_Sandstone_Brick_Half"
    },
    {
      "x": 2,
      "y": 5,
      "z": -4,
      "name": "Rock_Sandstone_Brick"
    },
    {
      "x": 2,
      "y": 6,
      "z": -4,
      "name": "Rock_Sandstone_Brick_Half"
    },
    {
      "x": 2,
      "y": 5,
      "z": -3,
      "name": "Rock_Sandstone_Brick"
    },
    {
      "x": 2,
      "y": 6,
      "z": -3,
      "name": "Rock_Sandstone_Brick_Half"
    },
    {
      "x": 2,
      "y": 18,
      "z": -3,
      "name": "Rock_Sandstone_Brick_Smooth_Half",
      "rotation": 6
    },
    {
      "x": 2,
      "y": 20,
      "z": -3,
      "name": "Wood_Drywood_Roof_Hollow",
      "rotation": 2
    },
    {
      "x": 2,
      "y": 5,
      "z": -2,
      "name": "Rock_Sandstone_Brick"
    },
    {
      "x": 2,
      "y": 6,
      "z": -2,
      "name": "Rock_Sandstone_Red_Brick_Smooth_Half"
    },
    {
      "x": 2,
      "y": 15,
      "z": -2,
      "name": "Rock_Sandstone_Brick_Smooth_Half",
      "rotation": 8
    },
    {
      "x": 2,
      "y": 16,
      "z": -2,
      "name": "Rock_Sandstone_Brick_Decorative"
    },
    {
      "x": 2,
      "y": 17,
      "z": -2,
      "name": "Rock_Sandstone_White_Cobble"
    },
    {
      "x": 2,
      "y": 18,
      "z": -2,
      "name": "Rock_Sandstone_White_Cobble"
    },
    {
      "x": 2,
      "y": 19,
      "z": -2,
      "name": "Furniture_Desert_Window"
    },
    {
      "x": 2,
      "y": 20,
      "z": -2,
      "name": "Furniture_Desert_Window"
    },
    {
      "x": 2,
      "y": 21,
      "z": -2,
      "name": "Wood_Dry_Trunk",
      "rotation": 5
    },
    {
      "x": 2,
      "y": 22,
      "z": -2,
      "name": "Wood_Drywood_Fence",
      "rotation": 2
    },
    {
      "x": 2,
      "y": 5,
      "z": -1,
      "name": "Rock_Sandstone_White_Cobble"
    },
    {
      "x": 2,
      "y": 16,
      "z": -1,
      "name": "Wood_Drywood_Planks"
    },
    {
      "x": 2,
      "y": 17,
      "z": -1,
      "name": "Wood_Drywood_Planks"
    },
    {
      "x": 2,
      "y": 21,
      "z": -1,
      "name": "Wood_Drywood_Planks"
    },
    {
      "x": 2,
      "y": 22,
      "z": -1,
      "name": "Wood_Drywood_Beam"
    },
    {
      "x": 2,
      "y": 23,
      "z": -1,
      "name": "Wood_Drywood_Beam"
    },
    {
      "x": 2,
      "y": 24,
      "z": -1,
      "name": "Wood_Drywood_Beam"
    },
    {
      "x": 2,
      "y": 25,
      "z": -1,
      "name": "Wood_Drywood_Planks_Half"
    },
    {
      "x": 2,
      "y": 5,
      "z": 0,
      "name": "Rock_Sandstone_White_Cobble"
    },
    {
      "x": 2,
      "y": 13,
      "z": 0,
      "name": "Cloth_Roof_Orange_Flap"
    },
    {
      "x": 2,
      "y": 14,
      "z": 0,
      "name": "Cloth_Roof_Orange_Vertical"
    },
    {
      "x": 2,
      "y": 15,
      "z": 0,
      "name": "Cloth_Roof_Orange_Vertical"
    },
    {
      "x": 2,
      "y": 16,
      "z": 0,
      "name": "Wood_Drywood_Planks"
    },
    {
      "x": 2,
      "y": 17,
      "z": 0,
      "name": "Wood_Drywood_Planks"
    },
    {
      "x": 2,
      "y": 21,
      "z": 0,
      "name": "Wood_Drywood_Planks"
    },
    {
      "x": 2,
      "y": 25,
      "z": 0,
      "name": "Wood_Drywood_Beam",
      "rotation": 4
    },
    {
      "x": 2,
      "y": 5,
      "z": 1,
      "name": "Rock_Sandstone_White_Cobble"
    },
    {
      "x": 2,
      "y": 16,
      "z": 1,
      "name": "Wood_Drywood_Planks"
    },
    {
      "x": 2,
      "y": 17,
      "z": 1,
      "name": "Wood_Drywood_Planks"
    },
    {
      "x": 2,
      "y": 21,
      "z": 1,
      "name": "Wood_Drywood_Planks"
    },
    {
      "x": 2,
      "y": 25,
      "z": 1,
      "name": "Wood_Drywood_Beam",
      "rotation": 4
    },
    {
      "x": 2,
      "y": 5,
      "z": 2,
      "name": "Rock_Sandstone_White_Cobble"
    },
    {
      "x": 2,
      "y": 9,
      "z": 2,
      "name": "Rock_Sandstone_Brick_Half",
      "rotation": 8
    },
    {
      "x": 2,
      "y": 10,
      "z": 2,
      "name": "Rock_Sandstone_Brick"
    },
    {
      "x": 2,
      "y": 11,
      "z": 2,
      "name": "Rock_Sandstone_Brick"
    },
    {
      "x": 2,
      "y": 12,
      "z": 2,
      "name": "Rock_Sandstone_Brick"
    },
    {
      "x": 2,
      "y": 13,
      "z": 2,
      "name": "Rock_Sandstone_Brick"
    },
    {
      "x": 2,
      "y": 14,
      "z": 2,
      "name": "Rock_Sandstone_Brick"
    },
    {
      "x": 2,
      "y": 15,
      "z": 2,
      "name": "Rock_Sandstone_Brick"
    },
    {
      "x": 2,
      "y": 16,
      "z": 2,
      "name": "Rock_Sandstone_Brick_Decorative"
    },
    {
      "x": 2,
      "y": 17,
      "z": 2,
      "name": "Rock_Sandstone_Brick"
    },
    {
      "x": 2,
      "y": 21,
      "z": 2,
      "name": "Wood_Drywood_Planks"
    },
    {
      "x": 2,
      "y": 25,
      "z": 2,
      "name": "Wood_Drywood_Beam",
      "rotation": 4
    },
    {
      "x": 2,
      "y": 9,
      "z": 3,
      "name": "Rock_Sandstone_Brick_Half",
      "rotation": 8
    },
    {
      "x": 2,
      "y": 10,
      "z": 3,
      "name": "Rock_Sandstone_Brick"
    },
    {
      "x": 2,
      "y": 11,
      "z": 3,
      "name": "Rock_Sandstone_Brick"
    },
    {
      "x": 2,
      "y": 12,
      "z": 3,
      "name": "Rock_Sandstone_White_Cobble"
    },
    {
      "x": 2,
      "y": 13,
      "z": 3,
      "name": "Rock_Sandstone_White_Cobble"
    },
    {
      "x": 2,
      "y": 14,
      "z": 3,
      "name": "Rock_Sandstone_White_Cobble"
    },
    {
      "x": 2,
      "y": 15,
      "z": 3,
      "name": "Wood_Drywood_Planks"
    },
    {
      "x": 2,
      "y": 21,
      "z": 3,
      "name": "Wood_Drywood_Planks"
    },
    {
      "x": 2,
      "y": 25,
      "z": 3,
      "name": "Wood_Drywood_Beam",
      "rotation": 4
    },
    {
      "x": 2,
      "y": 15,
      "z": 4,
      "name": "Wood_Drywood_Planks"
    },
    {
      "x": 2,
      "y": 21,
      "z": 4,
      "name": "Wood_Drywood_Planks"
    },
    {
      "x": 2,
      "y": 25,
      "z": 4,
      "name": "Wood_Drywood_Beam",
      "rotation": 4
    },
    {
      "x": 2,
      "y": 15,
      "z": 5,
      "name": "Wood_Drywood_Planks"
    },
    {
      "x": 2,
      "y": 21,
      "z": 5,
      "name": "Wood_Drywood_Planks"
    },
    {
      "x": 2,
      "y": 22,
      "z": 5,
      "name": "Wood_Drywood_Beam"
    },
    {
      "x": 2,
      "y": 23,
      "z": 5,
      "name": "Wood_Drywood_Beam"
    },
    {
      "x": 2,
      "y": 24,
      "z": 5,
      "name": "Wood_Drywood_Beam"
    },
    {
      "x": 2,
      "y": 25,
      "z": 5,
      "name": "Wood_Drywood_Planks_Half"
    },
    {
      "x": 2,
      "y": 15,
      "z": 6,
      "name": "Wood_Drywood_Planks"
    },
    {
      "x": 2,
      "y": 21,
      "z": 6,
      "name": "Wood_Drywood_Planks"
    },
    {
      "x": 2,
      "y": 15,
      "z": 7,
      "name": "Wood_Drywood_Planks"
    },
    {
      "x": 2,
      "y": 21,
      "z": 7,
      "name": "Wood_Drywood_Planks"
    },
    {
      "x": 2,
      "y": 15,
      "z": 8,
      "name": "Wood_Drywood_Planks"
    },
    {
      "x": 2,
      "y": 16,
      "z": 8,
      "name": "Rock_Sandstone_Brick_Decorative"
    },
    {
      "x": 2,
      "y": 17,
      "z": 8,
      "name": "Rock_Sandstone_White_Cobble"
    },
    {
      "x": 2,
      "y": 18,
      "z": 8,
      "name": "Rock_Sandstone_White_Cobble"
    },
    {
      "x": 2,
      "y": 19,
      "z": 8,
      "name": "Rock_Sandstone_White_Cobble"
    },
    {
      "x": 2,
      "y": 20,
      "z": 8,
      "name": "Rock_Sandstone_White_Cobble"
    },
    {
      "x": 2,
      "y": 21,
      "z": 8,
      "name": "Wood_Dry_Trunk",
      "rotation": 5
    },
    {
      "x": 2,
      "y": 15,
      "z": 9,
      "name": "Wood_Drywood_Planks"
    },
    {
      "x": 2,
      "y": 16,
      "z": 9,
      "name": "Furniture_Desert_Ladder"
    },
    {
      "x": 2,
      "y": 17,
      "z": 9,
      "name": "Furniture_Desert_Ladder"
    },
    {
      "x": 2,
      "y": 18,
      "z": 9,
      "name": "Furniture_Desert_Ladder"
    },
    {
      "x": 2,
      "y": 19,
      "z": 9,
      "name": "Furniture_Desert_Ladder"
    },
    {
      "x": 2,
      "y": 20,
      "z": 9,
      "name": "Furniture_Desert_Ladder"
    },
    {
      "x": 2,
      "y": 21,
      "z": 9,
      "name": "Furniture_Desert_Ladder"
    },
    {
      "x": 2,
      "y": 9,
      "z": 10,
      "name": "Rock_Sandstone_Brick_Half",
      "rotation": 8
    },
    {
      "x": 2,
      "y": 10,
      "z": 10,
      "name": "Rock_Sandstone_Brick"
    },
    {
      "x": 2,
      "y": 11,
      "z": 10,
      "name": "Rock_Sandstone_Brick"
    },
    {
      "x": 2,
      "y": 12,
      "z": 10,
      "name": "Rock_Sandstone_White_Cobble"
    },
    {
      "x": 2,
      "y": 13,
      "z": 10,
      "name": "Rock_Sandstone_White_Cobble"
    },
    {
      "x": 2,
      "y": 14,
      "z": 10,
      "name": "Rock_Sandstone_White_Cobble"
    },
    {
      "x": 2,
      "y": 15,
      "z": 10,
      "name": "Wood_Drywood_Planks"
    },
    {
      "x": 2,
      "y": 11,
      "z": 11,
      "name": "Rock_Sandstone_Brick_Smooth"
    },
    {
      "x": 2,
      "y": 12,
      "z": 11,
      "name": "Rock_Sandstone_White_Cobble"
    },
    {
      "x": 2,
      "y": 13,
      "z": 11,
      "name": "Rock_Sandstone_White_Cobble"
    },
    {
      "x": 2,
      "y": 14,
      "z": 11,
      "name": "Rock_Sandstone_White_Cobble"
    },
    {
      "x": 2,
      "y": 15,
      "z": 11,
      "name": "Rock_Sandstone_Brick"
    },
    {
      "x": 2,
      "y": 16,
      "z": 11,
      "name": "Rock_Sandstone_Brick_Smooth_Half"
    },
    {
      "x": 3,
      "y": 5,
      "z": -7,
      "name": "Rock_Sandstone_White_Cobble"
    },
    {
      "x": 3,
      "y": 5,
      "z": -6,
      "name": "Rock_Sandstone_White_Cobble"
    },
    {
      "x": 3,
      "y": 5,
      "z": -5,
      "name": "Rock_Sandstone_White_Cobble"
    },
    {
      "x": 3,
      "y": 5,
      "z": -4,
      "name": "Rock_Sandstone_White_Cobble"
    },
    {
      "x": 3,
      "y": 5,
      "z": -3,
      "name": "Rock_Sandstone_White_Cobble"
    },
    {
      "x": 3,
      "y": 18,
      "z": -3,
      "name": "Rock_Sandstone_Brick_Smooth_Half",
      "rotation": 6
    },
    {
      "x": 3,
      "y": 20,
      "z": -3,
      "name": "Wood_Drywood_Roof_Hollow",
      "rotation": 2
    },
    {
      "x": 3,
      "y": 5,
      "z": -2,
      "name": "Rock_Sandstone_White_Cobble"
    },
    {
      "x": 3,
      "y": 15,
      "z": -2,
      "name": "Rock_Sandstone_Brick_Smooth_Half",
      "rotation": 8
    },
    {
      "x": 3,
      "y": 16,
      "z": -2,
      "name": "Rock_Sandstone_Brick_Decorative"
    },
    {
      "x": 3,
      "y": 17,
      "z": -2,
      "name": "Rock_Sandstone_White_Cobble"
    },
    {
      "x": 3,
      "y": 18,
      "z": -2,
      "name": "Rock_Sandstone_White_Cobble"
    },
    {
      "x": 3,
      "y": 19,
      "z": -2,
      "name": "Furniture_Desert_Window"
    },
    {
      "x": 3,
      "y": 20,
      "z": -2,
      "name": "Furniture_Desert_Window"
    },
    {
      "x": 3,
      "y": 21,
      "z": -2,
      "name": "Wood_Dry_Trunk",
      "rotation": 5
    },
    {
      "x": 3,
      "y": 22,
      "z": -2,
      "name": "Wood_Drywood_Fence",
      "rotation": 2
    },
    {
      "x": 3,
      "y": 5,
      "z": -1,
      "name": "Rock_Sandstone_White_Cobble"
    },
    {
      "x": 3,
      "y": 16,
      "z": -1,
      "name": "Wood_Drywood_Planks"
    },
    {
      "x": 3,
      "y": 17,
      "z": -1,
      "name": "Wood_Drywood_Planks"
    },
    {
      "x": 3,
      "y": 21,
      "z": -1,
      "name": "Wood_Drywood_Planks"
    },
    {
      "x": 3,
      "y": 25,
      "z": -1,
