{
  "version": 8,
  "blockIdVersion": 11,
  "anchorX": 1,
  "anchorY": 3,
  "anchorZ": 0,
  "blocks": [
    {
      "x": -3,
      "y": 3,
      "z": -3,
      "name": "Rock_Sandstone_Cobble",
      "rotation": 2
    },
    {
      "x": -3,
      "y": 4,
      "z": -3,
      "name": "Rock_Sandstone_Cobble",
      "rotation": 2
    },
    {
      "x": -3,
      "y": 5,
      "z": -3,
      "name": "Rock_Sandstone_Brick",
      "rotation": 2
    },
    {
      "x": -3,
      "y": 6,
      "z": -3,
      "name": "Rock_Sandstone_Brick",
      "rotation": 2
    },
    {
      "x": -3,
      "y": 7,
      "z": -3,
      "name": "Rock_Sandstone_Brick",
      "rotation": 2
    },
    {
      "x": -3,
      "y": 8,
      "z": -3,
      "name": "Rock_Sandstone_Brick_Pillar_Base",
      "rotation": 2
    },
    {
      "x": -3,
      "y": 9,
      "z": -3,
      "name": "Rock_Sandstone_Brick_Half",
      "rotation": 2
    },
    {
      "x": -3,
      "y": 3,
      "z": -2,
      "name": "Rock_Sandstone_Cobble",
      "rotation": 2
    },
    {
      "x": -3,
      "y": 4,
      "z": -2,
      "name": "Rock_Sandstone_Cobble",
      "rotation": 2
    },
    {
      "x": -3,
      "y": 5,
      "z": -2,
      "name": "Rock_Sandstone_Cobble",
      "rotation": 2
    },
    {
      "x": -3,
      "y": 6,
      "z": -2,
      "name": "Rock_Sandstone_Brick",
      "rotation": 2
    },
    {
      "x": -3,
      "y": 7,
      "z": -2,
      "name": "Rock_Sandstone_Brick",
      "rotation": 2
    },
    {
      "x": -3,
      "y": 8,
      "z": -2,
      "name": "Rock_Sandstone_Brick_Pillar_Base",
      "rotation": 2
    },
    {
      "x": -3,
      "y": 9,
      "z": -2,
      "name": "Rock_Sandstone_Brick",
      "rotation": 2
    },
    {
      "x": -3,
      "y": 10,
      "z": -2,
      "name": "Plant_Bush_Arid_Sharp",
      "rotation": 2
    },
    {
      "x": -3,
      "y": 3,
      "z": -1,
      "name": "Rock_Sandstone_Cobble",
      "rotation": 2
    },
    {
      "x": -3,
      "y": 4,
      "z": -1,
      "name": "Rock_Sandstone_Cobble",
      "rotation": 2
    },
    {
      "x": -3,
      "y": 5,
      "z": -1,
      "name": "Rock_Sandstone_Cobble",
      "rotation": 2
    },
    {
      "x": -3,
      "y": 6,
      "z": -1,
      "name": "Rock_Sandstone_Cobble",
      "rotation": 2
    },
    {
      "x": -3,
      "y": 7,
      "z": -1,
      "name": "Rock_Sandstone_Brick",
      "rotation": 2
    },
    {
      "x": -3,
      "y": 8,
      "z": -1,
      "name": "Rock_Sandstone_Brick_Pillar_Base",
      "rotation": 2
    },
    {
      "x": -3,
      "y": 9,
      "z": -1,
      "name": "Rock_Sandstone_Brick",
      "rotation": 2
    },
    {
      "x": -3,
      "y": 10,
      "z": -1,
      "name": "Rock_Sandstone_Cobble_Stairs",
      "rotation": 3
    },
    {
      "x": -3,
      "y": 11,
      "z": -1,
      "name": "Rock_Sandstone_Cobble_Half",
      "rotation": 7
    },
    {
      "x": -3,
      "y": 14,
      "z": -1,
      "name": "Rock_Sandstone_Brick_Smooth_Half",
      "rotation": 6
    },
    {
      "x": -3,
      "y": 15,
      "z": -1,
      "name": "Rock_Sandstone_Brick_Smooth_Half",
      "rotation": 6
    },
    {
      "x": -3,
      "y": 24,
      "z": -1,
      "name": "Rock_Sandstone_Brick_Smooth_Half",
      "rotation": 7
    },
    {
      "x": -3,
      "y": 3,
      "z": 0,
      "name": "Rock_Sandstone_Cobble",
      "rotation": 2
    },
    {
      "x": -3,
      "y": 4,
      "z": 0,
      "name": "Rock_Sandstone_Cobble",
      "rotation": 2
    },
    {
      "x": -3,
      "y": 5,
      "z": 0,
      "name": "Rock_Sandstone_Cobble",
      "rotation": 2
    },
    {
      "x": -3,
      "y": 6,
      "z": 0,
      "name": "Rock_Sandstone_Brick",
      "rotation": 2
    },
    {
      "x": -3,
      "y": 7,
      "z": 0,
      "name": "Rock_Sandstone_Brick",
      "rotation": 2
    },
    {
      "x": -3,
      "y": 8,
      "z": 0,
      "name": "Rock_Sandstone_Brick_Pillar_Base",
      "rotation": 2
    },
    {
      "x": -3,
      "y": 9,
      "z": 0,
      "name": "Rock_Sandstone_Brick",
      "rotation": 2
    },
    {
      "x": -3,
      "y": 10,
      "z": 0,
      "name": "Rock_Sandstone_Cobble_Stairs",
      "rotation": 3
    },
    {
      "x": -3,
      "y": 11,
      "z": 0,
      "name": "Rock_Sandstone_Cobble_Half",
      "rotation": 7
    },
    {
      "x": -3,
      "y": 13,
      "z": 0,
      "name": "Rock_Sandstone_Brick_Smooth_Half",
      "rotation": 7
    },
    {
      "x": -3,
      "y": 16,
      "z": 0,
      "name": "Rock_Sandstone_Brick_Smooth_Half",
      "rotation": 2
    },
    {
      "x": -3,
      "y": 24,
      "z": 0,
      "name": "Rock_Sandstone_Brick_Smooth_Half",
      "rotation": 7
    },
    {
      "x": -3,
      "y": 3,
      "z": 1,
      "name": "Rock_Sandstone_Cobble",
      "rotation": 2
    },
    {
      "x": -3,
      "y": 4,
      "z": 1,
      "name": "Rock_Sandstone_Cobble",
      "rotation": 2
    },
    {
      "x": -3,
      "y": 5,
      "z": 1,
      "name": "Rock_Sandstone_Brick",
      "rotation": 2
    },
    {
      "x": -3,
      "y": 6,
      "z": 1,
      "name": "Rock_Sandstone_Brick",
      "rotation": 2
    },
    {
      "x": -3,
      "y": 7,
      "z": 1,
      "name": "Rock_Sandstone_Brick",
      "rotation": 2
    },
    {
      "x": -3,
      "y": 8,
      "z": 1,
      "name": "Rock_Sandstone_Brick_Pillar_Base",
      "rotation": 2
    },
    {
      "x": -3,
      "y": 9,
      "z": 1,
      "name": "Rock_Sandstone_Brick",
      "rotation": 2
    },
    {
      "x": -3,
      "y": 10,
      "z": 1,
      "name": "Rock_Sandstone_Cobble_Stairs",
      "rotation": 3
    },
    {
      "x": -3,
      "y": 11,
      "z": 1,
      "name": "Rock_Sandstone_Cobble_Half",
      "rotation": 7
    },
    {
      "x": -3,
      "y": 14,
      "z": 1,
      "name": "Rock_Sandstone_Brick_Smooth_Half",
      "rotation": 4
    },
    {
      "x": -3,
      "y": 15,
      "z": 1,
      "name": "Rock_Sandstone_Brick_Smooth_Half",
      "rotation": 4
    },
    {
      "x": -3,
      "y": 24,
      "z": 1,
      "name": "Rock_Sandstone_Brick_Smooth_Half",
      "rotation": 7
    },
    {
      "x": -3,
      "y": 3,
      "z": 2,
      "name": "Rock_Sandstone_Cobble",
      "rotation": 2
    },
    {
      "x": -3,
      "y": 4,
      "z": 2,
      "name": "Rock_Sandstone_Cobble",
      "rotation": 2
    },
    {
      "x": -3,
      "y": 5,
      "z": 2,
      "name": "Rock_Sandstone_Brick",
      "rotation": 2
    },
    {
      "x": -3,
      "y": 6,
      "z": 2,
      "name": "Rock_Sandstone_Brick",
      "rotation": 2
    },
    {
      "x": -3,
      "y": 7,
      "z": 2,
      "name": "Rock_Sandstone_Brick",
      "rotation": 2
    },
    {
      "x": -3,
      "y": 8,
      "z": 2,
      "name": "Rock_Sandstone_Brick_Pillar_Base",
      "rotation": 2
    },
    {
      "x": -3,
      "y": 9,
      "z": 2,
      "name": "Rock_Sandstone_Brick",
      "rotation": 2
    },
    {
      "x": -3,
      "y": 3,
      "z": 3,
      "name": "Rock_Sandstone_Cobble",
      "rotation": 2
    },
    {
      "x": -3,
      "y": 4,
      "z": 3,
      "name": "Rock_Sandstone_Cobble",
      "rotation": 2
    },
    {
      "x": -3,
      "y": 5,
      "z": 3,
      "name": "Rock_Sandstone_Brick",
      "rotation": 2
    },
    {
      "x": -3,
      "y": 6,
      "z": 3,
      "name": "Rock_Sandstone_Brick",
      "rotation": 2
    },
    {
      "x": -3,
      "y": 7,
      "z": 3,
      "name": "Rock_Sandstone_Brick",
      "rotation": 2
    },
    {
      "x": -3,
      "y": 8,
      "z": 3,
      "name": "Rock_Sandstone_Brick_Pillar_Base",
      "rotation": 2
    },
    {
      "x": -3,
      "y": 9,
      "z": 3,
      "name": "Rock_Sandstone_Brick_Half",
      "rotation": 2
    },
    {
      "x": -2,
      "y": 3,
      "z": -4,
      "name": "Rock_Sandstone_Cobble",
      "rotation": 2
    },
    {
      "x": -2,
      "y": 4,
      "z": -4,
      "name": "Rock_Sandstone_Cobble",
      "rotation": 2
    },
    {
      "x": -2,
      "y": 5,
      "z": -4,
      "name": "Rock_Sandstone_Brick",
      "rotation": 2
    },
    {
      "x": -2,
      "y": 6,
      "z": -4,
      "name": "Rock_Sandstone_Brick",
      "rotation": 2
    },
    {
      "x": -2,
      "y": 7,
      "z": -4,
      "name": "Rock_Sandstone_Brick",
      "rotation": 2
    },
    {
      "x": -2,
      "y": 8,
      "z": -4,
      "name": "Rock_Sandstone_Brick_Pillar_Base",
      "rotation": 2
    },
    {
      "x": -2,
      "y": 9,
      "z": -4,
      "name": "Rock_Sandstone_Brick_Half",
      "rotation": 2
    },
    {
      "x": -2,
      "y": 3,
      "z": -3,
      "name": "Rock_Sandstone_Cobble",
      "rotation": 2
    },
    {
      "x": -2,
      "y": 4,
      "z": -3,
      "name": "Rock_Sandstone_Brick",
      "rotation": 2
    },
    {
      "x": -2,
      "y": 5,
      "z": -3,
      "name": "Rock_Sandstone_Brick",
      "rotation": 2
    },
    {
      "x": -2,
      "y": 6,
      "z": -3,
      "name": "Rock_Sandstone_Brick",
      "rotation": 2
    },
    {
      "x": -2,
      "y": 7,
      "z": -3,
      "name": "Rock_Sandstone_Brick",
      "rotation": 2
    },
    {
      "x": -2,
      "y": 8,
      "z": -3,
      "name": "Rock_Sandstone_Brick",
      "rotation": 2
    },
    {
      "x": -2,
      "y": 9,
      "z": -3,
      "name": "Rock_Sandstone_Brick",
      "rotation": 2
    },
    {
      "x": -2,
      "y": 19,
      "z": -3,
      "name": "Rock_Sandstone_Brick_Ornate",
      "rotation": 2
    },
    {
      "x": -2,
      "y": 20,
      "z": -3,
      "name": "*Rock_Sandstone_Brick_Wall_State_Definitions_Corner",
      "rotation": 1
    },
    {
      "x": -2,
      "y": 3,
      "z": -2,
      "name": "Rock_Sandstone_Cobble",
      "rotation": 2
    },
    {
      "x": -2,
      "y": 4,
      "z": -2,
      "name": "Rock_Sandstone_Cobble",
      "rotation": 2
    },
    {
      "x": -2,
      "y": 5,
      "z": -2,
      "name": "Rock_Sandstone_Brick",
      "rotation": 2
    },
    {
      "x": -2,
      "y": 6,
      "z": -2,
      "name": "Rock_Sandstone_Brick",
      "rotation": 2
    },
    {
      "x": -2,
      "y": 7,
      "z": -2,
      "name": "Rock_Sandstone_Brick",
      "rotation": 2
    },
    {
      "x": -2,
      "y": 8,
      "z": -2,
      "name": "Rock_Sandstone_Brick",
      "rotation": 2
    },
    {
      "x": -2,
      "y": 9,
      "z": -2,
      "name": "Rock_Sandstone_Brick",
      "rotation": 2
    },
    {
      "x": -2,
      "y": 10,
      "z": -2,
      "name": "Rock_Sandstone_Brick_Pillar_Base",
      "rotation": 2
    },
    {
      "x": -2,
      "y": 11,
      "z": -2,
      "name": "Rock_Sandstone_Brick_Pillar_Middle",
      "rotation": 2
    },
    {
      "x": -2,
      "y": 12,
      "z": -2,
      "name": "Rock_Sandstone_Brick_Pillar_Base",
      "rotation": 10
    },
    {
      "x": -2,
      "y": 13,
      "z": -2,
      "name": "Rock_Sandstone_Brick_Pillar_Middle",
      "rotation": 2
    },
    {
      "x": -2,
      "y": 14,
      "z": -2,
      "name": "Rock_Sandstone_Brick_Pillar_Middle",
      "rotation": 2
    },
    {
      "x": -2,
      "y": 15,
      "z": -2,
      "name": "Rock_Sandstone_Brick_Pillar_Middle",
      "rotation": 2
    },
    {
      "x": -2,
      "y": 16,
      "z": -2,
      "name": "Rock_Sandstone_Brick_Pillar_Middle",
      "rotation": 2
    },
    {
      "x": -2,
      "y": 17,
      "z": -2,
      "name": "Rock_Sandstone_Brick_Pillar_Base",
      "rotation": 10
    },
    {
      "x": -2,
      "y": 18,
      "z": -2,
      "name": "Rock_Sandstone_Brick_Stairs",
      "rotation": 3
    },
    {
      "x": -2,
      "y": 19,
      "z": -2,
      "name": "Rock_Sandstone_Brick_Ornate",
      "rotation": 2
    },
    {
      "x": -2,
      "y": 20,
      "z": -2,
      "name": "Rock_Sandstone_Brick_Wall",
      "rotation": 3
    },
    {
      "x": -2,
      "y": 24,
      "z": -2,
      "name": "Rock_Sandstone_Brick_Smooth",
      "rotation": 2
    },
    {
      "x": -2,
      "y": 29,
      "z": -2,
      "name": "Rock_Sandstone_Brick_Smooth_Half",
      "rotation": 7
    },
    {
      "x": -2,
      "y": 3,
      "z": -1,
      "name": "Rock_Sandstone_Brick",
      "rotation": 2
    },
    {
      "x": -2,
      "y": 4,
      "z": -1,
      "name": "Rock_Sandstone_Brick",
      "rotation": 2
    },
    {
      "x": -2,
      "y": 5,
      "z": -1,
      "name": "Rock_Sandstone_Cobble",
      "rotation": 2
    },
    {
      "x": -2,
      "y": 6,
      "z": -1,
      "name": "Rock_Sandstone_Brick",
      "rotation": 2
    },
    {
      "x": -2,
      "y": 7,
      "z": -1,
      "name": "Rock_Sandstone_Brick",
      "rotation": 2
    },
    {
      "x": -2,
      "y": 8,
      "z": -1,
      "name": "Rock_Sandstone_Brick",
      "rotation": 2
    },
    {
      "x": -2,
      "y": 9,
      "z": -1,
      "name": "Rock_Sandstone_Brick",
      "rotation": 2
    },
    {
      "x": -2,
      "y": 10,
      "z": -1,
      "name": "Rock_Sandstone_Cobble",
      "rotation": 2
    },
    {
      "x": -2,
      "y": 11,
      "z": -1,
      "name": "Rock_Sandstone_Cobble",
      "rotation": 2
    },
    {
      "x": -2,
      "y": 12,
      "z": -1,
      "name": "Rock_Sandstone_Brick",
      "rotation": 2
    },
    {
      "x": -2,
      "y": 13,
      "z": -1,
      "name": "Rock_Sandstone_Brick",
      "rotation": 2
    },
    {
      "x": -2,
      "y": 14,
      "z": -1,
      "name": "Rock_Sandstone_Brick",
      "rotation": 2
    },
    {
      "x": -2,
      "y": 15,
      "z": -1,
      "name": "Rock_Sandstone_Brick",
      "rotation": 2
    },
    {
      "x": -2,
      "y": 16,
      "z": -1,
      "name": "Rock_Sandstone_Brick",
      "rotation": 2
    },
    {
      "x": -2,
      "y": 17,
      "z": -1,
      "name": "Rock_Sandstone_Brick",
      "rotation": 2
    },
    {
      "x": -2,
      "y": 18,
      "z": -1,
      "name": "Rock_Sandstone_Brick",
      "rotation": 2
    },
    {
      "x": -2,
      "y": 19,
      "z": -1,
      "name": "Rock_Sandstone_Brick_Ornate",
      "rotation": 2
    },
    {
      "x": -2,
      "y": 20,
      "z": -1,
      "name": "Rock_Sandstone_Brick_Pillar_Base",
      "rotation": 2
    },
    {
      "x": -2,
      "y": 21,
      "z": -1,
      "name": "Rock_Sandstone_Brick_Pillar_Middle",
      "rotation": 2
    },
    {
      "x": -2,
      "y": 22,
      "z": -1,
      "name": "Rock_Sandstone_Brick_Pillar_Base",
      "rotation": 10
    },
    {
      "x": -2,
      "y": 23,
      "z": -1,
      "name": "Rock_Sandstone_Brick_Ornate",
      "rotation": 2
    },
    {
      "x": -2,
      "y": 24,
      "z": -1,
      "name": "Rock_Sandstone_Brick",
      "rotation": 2
    },
    {
      "x": -2,
      "y": 25,
      "z": -1,
      "name": "Rock_Sandstone_Brick_Stairs",
      "rotation": 3
    },
    {
      "x": -2,
      "y": 26,
      "z": -1,
      "name": "Rock_Sandstone_Brick_Stairs",
      "rotation": 9
    },
    {
      "x": -2,
      "y": 27,
      "z": -1,
      "name": "Rock_Sandstone_White_Brick",
      "rotation": 2
    },
    {
      "x": -2,
      "y": 28,
      "z": -1,
      "name": "Rock_Sandstone_White_Brick",
      "rotation": 2
    },
    {
      "x": -2,
      "y": 29,
      "z": -1,
      "name": "Rock_Sandstone_Brick_Smooth",
      "rotation": 2
    },
    {
      "x": -2,
      "y": 3,
      "z": 0,
      "name": "Rock_Sandstone_Brick",
      "rotation": 2
    },
    {
      "x": -2,
      "y": 4,
      "z": 0,
      "name": "Rock_Sandstone_Cobble",
      "rotation": 2
    },
    {
      "x": -2,
      "y": 5,
      "z": 0,
      "name": "Rock_Sandstone_Brick",
      "rotation": 2
    },
    {
      "x": -2,
      "y": 6,
      "z": 0,
      "name": "Rock_Sandstone_Brick",
      "rotation": 2
    },
    {
      "x": -2,
      "y": 7,
      "z": 0,
      "name": "Rock_Sandstone_Brick",
      "rotation": 2
    },
    {
      "x": -2,
      "y": 8,
      "z": 0,
      "name": "Rock_Sandstone_Brick",
      "rotation": 2
    },
    {
      "x": -2,
      "y": 9,
      "z": 0,
      "name": "Rock_Sandstone_Brick",
      "rotation": 2
    },
    {
      "x": -2,
      "y": 10,
      "z": 0,
      "name": "Rock_Sandstone_Cobble",
      "rotation": 2
    },
    {
      "x": -2,
      "y": 11,
      "z": 0,
      "name": "Rock_Sandstone_Cobble",
      "rotation": 2
    },
    {
      "x": -2,
      "y": 12,
      "z": 0,
      "name": "Rock_Sandstone_Brick",
      "rotation": 2
    },
    {
      "x": -2,
      "y": 13,
      "z": 0,
      "name": "Rock_Sandstone_Brick",
      "rotation": 2
    },
    {
      "x": -2,
      "y": 14,
      "z": 0,
      "name": "Furniture_Desert_Window",
      "rotation": 3
    },
    {
      "x": -2,
      "y": 15,
      "z": 0,
      "name": "Furniture_Desert_Window",
      "rotation": 3
    },
    {
      "x": -2,
      "y": 16,
      "z": 0,
      "name": "Rock_Sandstone_Brick",
      "rotation": 2
    },
    {
      "x": -2,
      "y": 17,
      "z": 0,
      "name": "Rock_Sandstone_Brick",
      "rotation": 2
    },
    {
      "x": -2,
      "y": 18,
      "z": 0,
      "name": "Rock_Sandstone_Brick",
      "rotation": 2
    },
    {
      "x": -2,
      "y": 19,
      "z": 0,
      "name": "Rock_Sandstone_Brick_Ornate",
      "rotation": 2
    },
    {
      "x": -2,
      "y": 20,
      "z": 0,
      "name": "Rock_Sandstone_Brick_Wall",
      "rotation": 3
    },
    {
      "x": -2,
      "y": 23,
      "z": 0,
      "name": "Rock_Sandstone_Brick_Ornate",
      "rotation": 2
    },
    {
      "x": -2,
      "y": 24,
      "z": 0,
      "name": "Rock_Sandstone_Brick",
      "rotation": 2
    },
    {
      "x": -2,
      "y": 25,
      "z": 0,
      "name": "Rock_Sandstone_Brick_Stairs",
      "rotation": 3
    },
    {
      "x": -2,
      "y": 26,
      "z": 0,
      "name": "Rock_Sandstone_Brick_Stairs",
      "rotation": 9
    },
    {
      "x": -2,
      "y": 27,
      "z": 0,
      "name": "Furniture_Desert_Window",
      "rotation": 3
    },
    {
      "x": -2,
      "y": 28,
      "z": 0,
      "name": "Furniture_Desert_Window",
      "rotation": 3
    },
    {
      "x": -2,
      "y": 29,
      "z": 0,
      "name": "Rock_Sandstone_Brick_Smooth_Half",
      "rotation": 2
    },
    {
      "x": -2,
      "y": 3,
      "z": 1,
      "name": "Rock_Sandstone_Cobble",
      "rotation": 2
    },
    {
      "x": -2,
      "y": 4,
      "z": 1,
      "name": "Furniture_Desert_Table",
      "filler": 1023,
      "rotation": 2
    },
    {
      "x": -2,
      "y": 8,
      "z": 1,
      "name": "Rock_Sandstone_Brick",
      "rotation": 2
    },
    {
      "x": -2,
      "y": 9,
      "z": 1,
      "name": "Rock_Sandstone_Cobble",
      "rotation": 2
    },
    {
      "x": -2,
      "y": 10,
      "z": 1,
      "name": "Rock_Sandstone_Cobble",
      "rotation": 2
    },
    {
      "x": -2,
      "y": 11,
      "z": 1,
      "name": "Rock_Sandstone_Cobble",
      "rotation": 2
    },
    {
      "x": -2,
      "y": 12,
      "z": 1,
      "name": "Rock_Sandstone_Brick",
      "rotation": 2
    },
    {
      "x": -2,
      "y": 13,
      "z": 1,
      "name": "Rock_Sandstone_Brick",
      "rotation": 2
    },
    {
      "x": -2,
      "y": 14,
      "z": 1,
      "name": "Rock_Sandstone_Brick",
      "rotation": 2
    },
    {
      "x": -2,
      "y": 15,
      "z": 1,
      "name": "Rock_Sandstone_Brick",
      "rotation": 2
    },
    {
      "x": -2,
      "y": 16,
      "z": 1,
      "name": "Rock_Sandstone_Brick",
      "rotation": 2
    },
    {
      "x": -2,
      "y": 17,
      "z": 1,
      "name": "Rock_Sandstone_Brick",
      "rotation": 2
    },
    {
      "x": -2,
      "y": 18,
      "z": 1,
      "name": "Rock_Sandstone_Brick",
      "rotation": 2
    },
    {
      "x": -2,
      "y": 19,
      "z": 1,
      "name": "Rock_Sandstone_Brick_Ornate",
      "rotation": 2
    },
    {
      "x": -2,
      "y": 20,
      "z": 1,
      "name": "Rock_Sandstone_Brick_Pillar_Base",
      "rotation": 2
    },
    {
      "x": -2,
      "y": 21,
      "z": 1,
      "name": "Rock_Sandstone_Brick_Pillar_Middle",
      "rotation": 2
    },
    {
      "x": -2,
      "y": 22,
      "z": 1,
      "name": "Rock_Sandstone_Brick_Pillar_Base",
      "rotation": 10
    },
    {
      "x": -2,
      "y": 23,
      "z": 1,
      "name": "Rock_Sandstone_Brick_Ornate",
      "rotation": 2
    },
    {
      "x": -2,
      "y": 24,
      "z": 1,
      "name": "Rock_Sandstone_Brick",
      "rotation": 2
    },
    {
      "x": -2,
      "y": 25,
      "z": 1,
      "name": "Rock_Sandstone_Brick_Stairs",
      "rotation": 3
    },
    {
      "x": -2,
      "y": 26,
      "z": 1,
      "name": "Rock_Sandstone_Brick_Stairs",
      "rotation": 9
    },
    {
      "x": -2,
      "y": 27,
      "z": 1,
      "name": "Rock_Sandstone_White_Brick",
      "rotation": 2
    },
    {
      "x": -2,
      "y": 28,
      "z": 1,
      "name": "Rock_Sandstone_White_Brick_Half",
      "rotation": 2
    },
    {
      "x": -2,
      "y": 3,
      "z": 2,
      "name": "Rock_Sandstone_Cobble",
      "rotation": 2
    },
    {
      "x": -2,
      "y": 4,
      "z": 2,
      "name": "Furniture_Desert_Table",
      "filler": 31,
      "rotation": 2
    },
    {
      "x": -2,
      "y": 8,
      "z": 2,
      "name": "Rock_Sandstone_Brick",
      "rotation": 2
    },
    {
      "x": -2,
      "y": 9,
      "z": 2,
      "name": "Rock_Sandstone_Brick",
      "rotation": 2
    },
    {
      "x": -2,
      "y": 10,
      "z": 2,
      "name": "Rock_Sandstone_Brick_Pillar_Base",
      "rotation": 2
    },
    {
      "x": -2,
      "y": 11,
      "z": 2,
      "name": "Rock_Sandstone_Brick_Pillar_Middle",
      "rotation": 2
    },
    {
      "x": -2,
      "y": 12,
      "z": 2,
      "name": "Rock_Sandstone_Brick_Pillar_Base",
      "rotation": 10
    },
    {
      "x": -2,
      "y": 13,
      "z": 2,
      "name": "Rock_Sandstone_Brick_Pillar_Middle",
      "rotation": 2
    },
    {
      "x": -2,
      "y": 14,
      "z": 2,
      "name": "Rock_Sandstone_Brick_Pillar_Middle",
      "rotation": 2
    },
    {
      "x": -2,
      "y": 15,
      "z": 2,
      "name": "Rock_Sandstone_Brick_Pillar_Middle",
      "rotation": 2
    },
    {
      "x": -2,
      "y": 16,
      "z": 2,
      "name": "Rock_Sandstone_Brick_Pillar_Middle",
      "rotation": 2
    },
    {
      "x": -2,
      "y": 17,
      "z": 2,
      "name": "Rock_Sandstone_Brick_Pillar_Base",
      "rotation": 10
    },
    {
      "x": -2,
      "y": 18,
      "z": 2,
      "name": "Rock_Sandstone_Brick_Stairs",
      "rotation": 3
    },
    {
      "x": -2,
      "y": 19,
      "z": 2,
      "name": "Rock_Sandstone_Brick_Ornate",
      "rotation": 2
    },
    {
      "x": -2,
      "y": 20,
      "z": 2,
      "name": "Rock_Sandstone_Brick_Wall",
      "rotation": 3
    },
    {
      "x": -2,
      "y": 24,
      "z": 2,
      "name": "Rock_Sandstone_Brick_Smooth",
      "rotation": 2
    },
    {
      "x": -2,
      "y": 3,
      "z": 3,
      "name": "Rock_Sandstone_Cobble",
      "rotation": 2
    },
    {
      "x": -2,
      "y": 8,
      "z": 3,
      "name": "Rock_Sandstone_Brick",
      "rotation": 2
    },
    {
      "x": -2,
      "y": 9,
      "z": 3,
      "name": "Rock_Sandstone_Brick",
      "rotation": 2
    },
    {
      "x": -2,
      "y": 19,
      "z": 3,
      "name": "Rock_Sandstone_Brick_Ornate",
      "rotation": 2
    },
    {
      "x": -2,
      "y": 20,
      "z": 3,
      "name": "*Rock_Sandstone_Brick_Wall_State_Definitions_Corner",
      "rotation": 2
    },
    {
      "x": -2,
      "y": 3,
      "z": 4,
      "name": "Rock_Sandstone_Cobble",
      "rotation": 2
    },
    {
      "x": -2,
      "y": 4,
      "z": 4,
      "name": "Rock_Sandstone_Cobble",
      "rotation": 2
    },
    {
      "x": -2,
      "y": 5,
      "z": 4,
      "name": "Rock_Sandstone_Cobble",
      "rotation": 2
    },
    {
      "x": -2,
      "y": 6,
      "z": 4,
      "name": "Rock_Sandstone_Brick",
      "rotation": 2
    },
    {
      "x": -2,
      "y": 7,
      "z": 4,
      "name": "Rock_Sandstone_Brick",
      "rotation": 2
    },
    {
      "x": -2,
      "y": 8,
      "z": 4,
      "name": "Rock_Sandstone_Brick_Pillar_Base",
      "rotation": 2
    },
    {
      "x": -2,
      "y": 9,
      "z": 4,
      "name": "Rock_Sandstone_Brick_Half",
      "rotation": 2
    },
    {
      "x": -1,
      "y": 3,
      "z": -4,
      "name": "Rock_Sandstone_Cobble",
      "rotation": 2
    },
    {
      "x": -1,
      "y": 4,
      "z": -4,
      "name": "Rock_Sandstone_Cobble",
      "rotation": 2
    },
    {
      "x": -1,
      "y": 5,
      "z": -4,
      "name": "Rock_Sandstone_Cobble",
      "rotation": 2
    },
    {
      "x": -1,
      "y": 6,
      "z": -4,
      "name": "Rock_Sandstone_Brick",
      "rotation": 2
    },
    {
      "x": -1,
      "y": 7,
      "z": -4,
      "name": "Rock_Sandstone_Brick",
      "rotation": 2
    },
    {
      "x": -1,
      "y": 8,
      "z": -4,
      "name": "Rock_Sandstone_Brick_Pillar_Base",
      "rotation": 2
    },
    {
      "x": -1,
      "y": 9,
      "z": -4,
      "name": "Rock_Sandstone_Brick",
      "rotation": 2
    },
    {
      "x": -1,
      "y": 3,
      "z": -3,
      "name": "Rock_Sandstone_Cobble",
      "rotation": 2
    },
    {
      "x": -1,
      "y": 4,
      "z": -3,
      "name": "Rock_Sandstone_Brick",
      "rotation": 2
    },
    {
      "x": -1,
      "y": 5,
      "z": -3,
      "name": "Rock_Sandstone_Brick",
      "rotation": 2
    },
    {
      "x": -1,
      "y": 6,
      "z": -3,
      "name": "Rock_Sandstone_Brick",
      "rotation": 2
    },
    {
      "x": -1,
      "y": 7,
      "z": -3,
      "name": "Rock_Sandstone_Brick",
      "rotation": 2
    },
    {
      "x": -1,
      "y": 8,
      "z": -3,
      "name": "Rock_Sandstone_Brick",
      "rotation": 2
    },
    {
      "x": -1,
      "y": 9,
      "z": -3,
      "name": "Rock_Sandstone_Brick",
      "rotation": 2
    },
    {
      "x": -1,
      "y": 10,
      "z": -3,
      "name": "Rock_Sandstone_Brick_Pillar_Base",
      "rotation": 2
    },
    {
      "x": -1,
      "y": 11,
      "z": -3,
      "name": "Rock_Sandstone_Brick_Pillar_Middle",
      "rotation": 2
    },
    {
      "x": -1,
      "y": 12,
      "z": -3,
      "name": "Rock_Sandstone_Brick_Pillar_Base",
      "rotation": 10
    },
    {
      "x": -1,
      "y": 13,
      "z": -3,
      "name": "Rock_Sandstone_Brick_Pillar_Middle",
      "rotation": 2
    },
    {
      "x": -1,
      "y": 14,
      "z": -3,
      "name": "Rock_Sandstone_Brick_Pillar_Middle",
      "rotation": 2
    },
    {
      "x": -1,
      "y": 15,
      "z": -3,
      "name": "Rock_Sandstone_Brick_Pillar_Middle",
      "rotation": 2
    },
    {
      "x": -1,
      "y": 16,
      "z": -3,
      "name": "Rock_Sandstone_Brick_Pillar_Middle",
      "rotation": 2
    },
    {
      "x": -1,
      "y": 17,
      "z": -3,
      "name": "Rock_Sandstone_Brick_Pillar_Base",
      "rotation": 10
    },
    {
      "x": -1,
      "y": 18,
      "z": -3,
      "name": "Rock_Sandstone_Brick_Stairs",
      "rotation": 2
    },
    {
      "x": -1,
      "y": 19,
      "z": -3,
      "name": "Rock_Sandstone_Brick_Ornate",
      "rotation": 2
    },
    {
      "x": -1,
      "y": 20,
      "z": -3,
      "name": "Rock_Sandstone_Brick_Wall",
      "rotation": 2
    },
    {
      "x": -1,
      "y": 24,
      "z": -3,
      "name": "Rock_Sandstone_Brick_Smooth",
      "rotation": 2
    },
    {
      "x": -1,
      "y": 3,
      "z": -2,
      "name": "Rock_Sandstone_Brick",
      "rotation": 2
    },
    {
      "x": -1,
      "y": 4,
      "z": -2,
      "name": "Rock_Sandstone_Cobble",
      "rotation": 2
    },
    {
      "x": -1,
      "y": 5,
      "z": -2,
      "name": "Rock_Sandstone_Cobble",
      "rotation": 2
    },
    {
      "x": -1,
      "y": 6,
      "z": -2,
      "name": "Rock_Sandstone_Cobble",
      "rotation": 2
    },
    {
      "x": -1,
      "y": 7,
      "z": -2,
      "name": "Rock_Sandstone_Brick",
      "rotation": 2
    },
    {
      "x": -1,
      "y": 8,
      "z": -2,
      "name": "Rock_Sandstone_Brick",
      "rotation": 2
    },
    {
      "x": -1,
      "y": 9,
      "z": -2,
      "name": "Rock_Sandstone_Cobble",
      "rotation": 2
    },
    {
      "x": -1,
      "y": 10,
      "z": -2,
      "name": "Rock_Sandstone_Cobble",
      "rotation": 2
    },
    {
      "x": -1,
      "y": 11,
      "z": -2,
      "name": "Rock_Sandstone_Cobble",
      "rotation": 2
    },
    {
      "x": -1,
      "y": 12,
      "z": -2,
      "name": "Rock_Sandstone_Brick",
      "rotation": 2
    },
    {
      "x": -1,
      "y": 13,
      "z": -2,
      "name": "Rock_Sandstone_Brick",
      "rotation": 2
    },
    {
      "x": -1,
      "y": 14,
      "z": -2,
      "name": "Rock_Sandstone_Brick",
      "rotation": 2
    },
    {
      "x": -1,
      "y": 15,
      "z": -2,
      "name": "Rock_Sandstone_Brick",
      "rotation": 2
    },
    {
      "x": -1,
      "y": 16,
      "z": -2,
      "name": "Rock_Sandstone_Brick",
      "rotation": 2
    },
    {
      "x": -1,
      "y": 17,
      "z": -2,
      "name": "Rock_Sandstone_Brick",
      "rotation": 2
    },
    {
      "x": -1,
      "y": 18,
      "z": -2,
      "name": "Rock_Sandstone_Brick",
      "rotation": 2
    },
    {
      "x": -1,
      "y": 19,
      "z": -2,
      "name": "Rock_Sandstone_Brick_Ornate",
      "rotation": 2
    },
    {
      "x": -1,
      "y": 20,
      "z": -2,
      "name": "Rock_Sandstone_Brick",
      "rotation": 2
    },
    {
      "x": -1,
      "y": 21,
      "z": -2,
      "name": "Rock_Sandstone_Brick",
      "rotation": 2
    },
    {
      "x": -1,
      "y": 22,
      "z": -2,
      "name": "Rock_Sandstone_Brick",
      "rotation": 2
    },
    {
      "x": -1,
      "y": 23,
      "z": -2,
      "name": "Rock_Sandstone_Brick_Ornate",
      "rotation": 2
    },
    {
      "x": -1,
      "y": 24,
      "z": -2,
      "name": "Rock_Sandstone_Brick",
      "rotation": 2
    },
    {
      "x": -1,
      "y": 25,
      "z": -2,
      "name": "Rock_Sandstone_Brick_Smooth",
      "rotation": 2
    },
    {
      "x": -1,
      "y": 26,
      "z": -2,
      "name": "Rock_Sandstone_Brick_Smooth",
      "rotation": 2
    },
    {
      "x": -1,
      "y": 27,
      "z": -2,
      "name": "Rock_Sandstone_White_Brick",
      "rotation": 2
    },
    {
      "x": -1,
      "y": 28,
      "z": -2,
      "name": "Rock_Sandstone_White_Brick",
      "rotation": 2
    },
    {
      "x": -1,
      "y": 29,
      "z": -2,
      "name": "Rock_Sandstone_Brick_Smooth",
      "rotation": 2
    },
    {
      "x": -1,
      "y": 3,
      "z": -1,
      "name": "Rock_Sandstone_Brick",
      "rotation": 2
    },
    {
      "x": -1,
      "y": 4,
      "z": -1,
      "name": "Rock_Sandstone_Cobble",
      "rotation": 2
    },
    {
      "x": -1,
      "y": 5,
      "z": -1,
      "name": "Rock_Sandstone_Cobble",
      "rotation": 2
    },
    {
      "x": -1,
      "y": 6,
      "z": -1,
      "name": "Rock_Sandstone_Cobble",
      "rotation": 2
    },
    {
      "x": -1,
      "y": 7,
      "z": -1,
      "name": "Rock_Sandstone_Cobble",
      "rotation": 2
    },
    {
      "x": -1,
      "y": 11,
      "z": -1,
      "name": "Rock_Sandstone_Cobble",
      "rotation": 2
    },
    {
      "x": -1,
      "y": 12,
      "z": -1,
      "name": "Wood_Dry_Trunk",
      "rotation": 2
    },
    {
      "x": -1,
      "y": 13,
      "z": -1,
      "name": "Wood_Dry_Trunk",
      "rotation": 2
    },
    {
      "x": -1,
      "y": 14,
      "z": -1,
      "name": "Wood_Dry_Trunk",
      "rotation": 2
    },
    {
      "x": -1,
      "y": 15,
      "z": -1,
      "name": "Wood_Dry_Trunk",
      "rotation": 2
    },
    {
      "x": -1,
      "y": 16,
      "z": -1,
      "name": "Wood_Dry_Trunk",
      "rotation": 2
    },
    {
      "x": -1,
      "y": 17,
      "z": -1,
      "name": "Wood_Dry_Trunk",
      "rotation": 2
    },
    {
      "x": -1,
      "y": 18,
      "z": -1,
      "name": "Wood_Dry_Trunk",
      "rotation": 2
    },
    {
      "x": -1,
      "y": 19,
      "z": -1,
      "name": "Wood_Dry_Trunk",
      "rotation": 2
    },
    {
      "x": -1,
      "y": 20,
      "z": -1,
      "name": "Wood_Dry_Trunk",
      "rotation": 2
    },
    {
      "x": -1,
      "y": 21,
      "z": -1,
      "name": "Wood_Dry_Trunk",
      "rotation": 2
    },
    {
      "x": -1,
      "y": 22,
      "z": -1,
      "name": "Wood_Dry_Trunk",
      "rotation": 2
    },
    {
      "x": -1,
      "y": 23,
      "z": -1,
      "name": "Wood_Dry_Trunk",
      "rotation": 2
    },
    {
      "x": -1,
      "y": 24,
      "z": -1,
      "name": "Wood_Dry_Trunk",
      "rotation": 2
    },
    {
      "x": -1,
      "y": 25,
      "z": -1,
      "name": "Wood_Drywood_Planks",
      "rotation": 2
    },
    {
      "x": -1,
      "y": 3,
      "z": 0,
      "name": "Rock_Sandstone_Brick",
      "rotation": 2
    },
    {
      "x": -1,
      "y": 4,
      "z": 0,
      "name": "Rock_Sandstone_Cobble",
      "rotation": 2
    },
    {
      "x": -1,
      "y": 5,
      "z": 0,
      "name": "Rock_Sandstone_Cobble",
      "rotation": 2
    },
    {
      "x": -1,
      "y": 6,
      "z": 0,
      "name": "Rock_Sandstone_Cobble",
      "rotation": 2
    },
    {
      "x": -1,
      "y": 7,
      "z": 0,
      "name": "Rock_Sandstone_Cobble",
      "rotation": 2
    },
    {
      "x": -1,
      "y": 8,
      "z": 0,
      "name": "Rock_Sandstone_Cobble_Stairs",
      "rotation": 2
    },
    {
      "x": -1,
      "y": 11,
      "z": 0,
      "name": "Rock_Sandstone_Cobble_Half",
      "rotation": 10
    },
    {
      "x": -1,
      "y": 12,
      "z": 0,
      "name": "Furniture_Village_Crate",
      "rotation": 2
    },
    {
      "x": -1,
      "y": 13,
      "z": 0,
      "name": "Furniture_Ancient_Barrel",
      "rotation": 2
    },
    {
      "x": -1,
      "y": 19,
      "z": 0,
      "name": "Wood_Drywood_Planks",
      "rotation": 2
    },
    {
      "x": -1,
      "y": 23,
      "z": 0,
      "name": "Rock_Sandstone_Brick",
      "rotation": 2
    },
    {
      "x": -1,
      "y": 24,
      "z": 0,
      "name": "Rock_Sandstone_Brick",
      "rotation": 2
    },
    {
      "x": -1,
      "y": 25,
      "z": 0,
      "name": "Wood_Drywood_Planks",
      "rotation": 2
    },
    {
      "x": -1,
      "y": 3,
      "z": 1,
      "name": "Rock_Sandstone_Cobble",
      "rotation": 2
    },
    {
      "x": -1,
      "y": 4,
      "z": 1,
      "name": "Furniture_Desert_Table",
      "filler": 992,
      "rotation": 2
    },
    {
      "x": -1,
      "y": 8,
      "z": 1,
      "name": "Rock_Sandstone_Cobble",
      "rotation": 2
    },
    {
      "x": -1,
      "y": 19,
      "z": 1,
      "name": "Wood_Drywood_Planks",
      "rotation": 2
    },
    {
      "x": -1,
      "y": 20,
      "z": 1,
      "name": "Rock_Sandstone_Brick_Smooth_Half",
      "rotation": 6
    },
    {
      "x": -1,
      "y": 21,
      "z": 1,
      "name": "Rock_Sandstone_Brick_Smooth_Half",
      "rotation": 6
    },
    {
      "x": -1,
      "y": 22,
      "z": 1,
      "name": "Rock_Sandstone_Brick_Smooth_Half",
      "rotation": 6
    },
    {
      "x": -1,
      "y": 23,
      "z": 1,
      "name": "Rock_Sandstone_Brick",
      "rotation": 2
    },
    {
      "x": -1,
      "y": 24,
      "z": 1,
      "name": "Rock_Sandstone_Brick",
      "rotation": 2
    },
    {
      "x": -1,
      "y": 25,
      "z": 1,
      "name": "Wood_Drywood_Planks",
      "rotation": 2
    },
    {
      "x": -1,
      "y": 26,
      "z": 1,
      "name": "Block_Spawner_Block",
      "components": {
        "Components": {
          "BlockSpawner": {}
        }
      },
      "rotation": 1
    },
    {
      "x": -1,
      "y": 27,
      "z": 1,
      "name": "Wood_Torch_Wall",
      "rotation": 1
    },
    {
      "x": -1,
      "y": 3,
      "z": 2,
      "name": "Rock_Sandstone_Cobble",
      "rotation": 2
    },
    {
      "x": -1,
      "y": 4,
      "z": 2,
      "name": "Furniture_Desert_Table",
      "rotation": 2
    },
    {
      "x": -1,
      "y": 8,
      "z": 2,
      "name": "Rock_Sandstone_Cobble",
      "rotation": 2
    },
    {
      "x": -1,
      "y": 9,
      "z": 2,
      "name": "Rock_Sandstone_Brick",
      "rotation": 2
    },
    {
      "x": -1,
      "y": 10,
      "z": 2,
      "name": "Rock_Sandstone_Cobble",
      "rotation": 2
    },
    {
      "x": -1,
      "y": 11,
      "z": 2,
      "name": "Rock_Sandstone_Cobble",
      "rotation": 2
    },
    {
      "x": -1,
      "y": 12,
      "z": 2,
      "name": "Rock_Sandstone_Brick",
      "rotation": 2
    },
    {
      "x": -1,
      "y": 13,
      "z": 2,
      "name": "Rock_Sandstone_Brick",
      "rotation": 2
    },
    {
      "x": -1,
      "y": 14,
      "z": 2,
      "name": "Rock_Sandstone_Brick",
      "rotation": 2
    },
    {
      "x": -1,
      "y": 15,
      "z": 2,
      "name": "Rock_Sandstone_Brick",
      "rotation": 2
    },
    {
      "x": -1,
      "y": 16,
      "z": 2,
      "name": "Rock_Sandstone_Brick",
      "rotation": 2
    },
    {
      "x": -1,
      "y": 17,
      "z": 2,
      "name": "Rock_Sandstone_Brick",
      "rotation": 2
    },
    {
      "x": -1,
      "y": 18,
      "z": 2,
      "name": "Rock_Sandstone_Brick",
      "rotation": 2
    },
    {
      "x": -1,
      "y": 19,
      "z": 2,
      "name": "Rock_Sandstone_Brick_Ornate",
      "rotation": 2
    },
    {
      "x": -1,
      "y": 20,
      "z": 2,
      "name": "Rock_Sandstone_Brick",
      "rotation": 2
    },
    {
      "x": -1,
      "y": 21,
      "z": 2,
      "name": "Rock_Sandstone_Brick",
      "rotation": 2
    },
    {
      "x": -1,
      "y": 22,
      "z": 2,
      "name": "Rock_Sandstone_Brick",
      "rotation": 2
    },
    {
      "x": -1,
      "y": 23,
      "z": 2,
      "name": "Rock_Sandstone_Brick_Ornate",
      "rotation": 2
    },
    {
      "x": -1,
      "y": 24,
      "z": 2,
      "name": "Rock_Sandstone_Brick",
      "rotation": 2
    },
    {
      "x": -1,
      "y": 25,
      "z": 2,
      "name": "Rock_Sandstone_Brick_Smooth",
      "rotation": 2
    },
    {
      "x": -1,
      "y": 26,
      "z": 2,
      "name": "Rock_Sandstone_Brick_Smooth",
      "rotation": 2
    },
    {
      "x": -1,
      "y": 27,
      "z": 2,
      "name": "Rock_Sandstone_White_Brick_Half",
      "rotation": 2
    },
    {
      "x": -1,
      "y": 3,
      "z": 3,
      "name": "Rock_Sandstone_Cobble",
      "rotation": 2
    },
    {
      "x": -1,
      "y": 8,
      "z": 3,
      "name": "Rock_Sandstone_Brick",
      "rotation": 2
    },
    {
      "x": -1,
      "y": 9,
      "z": 3,
      "name": "Rock_Sandstone_Brick",
      "rotation": 2
    },
    {
      "x": -1,
      "y": 10,
      "z": 3,
      "name": "Rock_Sandstone_Brick_Pillar_Base",
      "rotation": 2
    },
    {
      "x": -1,
      "y": 11,
      "z": 3,
      "name": "Rock_Sandstone_Brick_Pillar_Middle",
      "rotation": 2
    },
    {
      "x": -1,
      "y": 12,
      "z": 3,
      "name": "Rock_Sandstone_Brick_Pillar_Base",
      "rotation": 10
    },
    {
      "x": -1,
      "y": 13,
      "z": 3,
      "name": "Rock_Sandstone_Brick_Pillar_Middle",
      "rotation": 2
    },
    {
      "x": -1,
      "y": 14,
      "z": 3,
      "name": "Rock_Sandstone_Brick_Pillar_Middle",
      "rotation": 2
    },
    {
      "x": -1,
      "y": 15,
      "z": 3,
      "name": "Rock_Sandstone_Brick_Pillar_Middle",
      "rotation": 2
    },
    {
      "x": -1,
      "y": 16,
      "z": 3,
      "name": "Rock_Sandstone_Brick_Pillar_Middle",
      "rotation": 2
    },
    {
      "x": -1,
      "y": 17,
      "z": 3,
      "name": "Rock_Sandstone_Brick_Pillar_Base",
      "rotation": 10
    },
    {
      "x": -1,
      "y": 18,
      "z": 3,
      "name": "Rock_Sandstone_Brick_Stairs"
    },
    {
      "x": -1,
      "y": 19,
      "z": 3,
      "name": "Rock_Sandstone_Brick_Ornate",
      "rotation": 2
    },
    {
      "x": -1,
      "y": 20,
      "z": 3,
      "name": "Rock_Sandstone_Brick_Wall",
      "rotation": 2
    },
    {
      "x": -1,
      "y": 24,
      "z": 3,
      "name": "Rock_Sandstone_Brick_Smooth",
      "rotation": 2
    },
    {
      "x": -1,
      "y": 3,
      "z": 4,
      "name": "Rock_Sandstone_Cobble",
      "rotation": 2
    },
    {
      "x": -1,
      "y": 4,
      "z": 4,
      "name": "Rock_Sandstone_Cobble",
      "rotation": 2
    },
    {
      "x": -1,
      "y": 5,
      "z": 4,
      "name": "Rock_Sandstone_Brick",
      "rotation": 2
    },
    {
      "x": -1,
      "y": 6,
      "z": 4,
      "name": "Rock_Sandstone_Brick",
      "rotation": 2
    },
    {
      "x": -1,
      "y": 7,
      "z": 4,
      "name": "Rock_Sandstone_Brick",
      "rotation": 2
    },
    {
      "x": -1,
      "y": 8,
      "z": 4,
      "name": "Rock_Sandstone_Brick_Pillar_Base",
      "rotation": 2
    },
    {
      "x": -1,
      "y": 9,
      "z": 4,
      "name": "Rock_Sandstone_Brick",
      "rotation": 2
    },
    {
      "x": 0,
      "y": 3,
      "z": -4,
      "name": "Rock_Sandstone_Cobble",
      "rotation": 2
    },
    {
      "x": 0,
      "y": 4,
      "z": -4,
      "name": "Rock_Sandstone_Cobble",
      "rotation": 2
    },
    {
      "x": 0,
      "y": 5,
      "z": -4,
      "name": "Rock_Sandstone_Cobble",
      "rotation": 2
    },
    {
      "x": 0,
      "y": 6,
      "z": -4,
      "name": "Rock_Sandstone_Cobble",
      "rotation": 2
    },
    {
      "x": 0,
      "y": 7,
      "z": -4,
      "name": "Rock_Sandstone_Brick",
      "rotation": 2
    },
    {
      "x": 0,
      "y": 8,
      "z": -4,
      "name": "Rock_Sandstone_Brick_Pillar_Base",
      "rotation": 2
    },
    {
      "x": 0,
      "y": 9,
      "z": -4,
      "name": "Rock_Sandstone_Brick",
      "rotation": 2
    },
    {
      "x": 0,
      "y": 10,
      "z": -4,
      "name": "Rock_Sandstone_Cobble_Stairs",
      "rotation": 2
    },
    {
      "x": 0,
      "y": 11,
      "z": -4,
      "name": "Rock_Sandstone_Cobble_Half",
      "rotation": 6
    },
    {
      "x": 0,
      "y": 14,
      "z": -4,
      "name": "Rock_Sandstone_Brick_Smooth_Half",
      "rotation": 7
    },
    {
      "x": 0,
      "y": 15,
      "z": -4,
      "name": "Rock_Sandstone_Brick_Smooth_Half",
      "rotation": 7
    },
    {
      "x": 0,
      "y": 24,
      "z": -4,
      "name": "Rock_Sandstone_Brick_Smooth_Half",
      "rotation": 6
    },
    {
      "x": 0,
      "y": 3,
      "z": -3,
      "name": "Rock_Sandstone_Cobble",
      "rotation": 2
    },
    {
      "x": 0,
      "y": 4,
      "z": -3,
      "name": "Rock_Sandstone_Brick",
      "rotation": 2
    },
    {
      "x": 0,
      "y": 5,
      "z": -3,
      "name": "Rock_Sandstone_Brick",
      "rotation": 2
    },
    {
      "x": 0,
      "y": 6,
      "z": -3,
      "name": "Rock_Sandstone_Brick",
      "rotation": 2
    },
    {
      "x": 0,
      "y": 7,
      "z": -3,
      "name": "Rock_Sandstone_Brick",
      "rotation": 2
    },
    {
      "x": 0,
      "y": 8,
      "z": -3,
      "name": "Rock_Sandstone_Brick",
      "rotation": 2
    },
    {
      "x": 0,
      "y": 9,
      "z": -3,
      "name": "Rock_Sandstone_Brick",
      "rotation": 2
    },
    {
      "x": 0,
      "y": 10,
      "z": -3,
      "name": "Rock_Sandstone_Cobble",
      "rotation": 2
    },
    {
      "x": 0,
      "y": 11,
      "z": -3,
      "name": "Rock_Sandstone_Cobble",
      "rotation": 2
    },
    {
      "x": 0,
      "y": 12,
      "z": -3,
      "name": "Rock_Sandstone_Brick",
      "rotation": 2
    },
    {
      "x": 0,
      "y": 13,
      "z": -3,
      "name": "Rock_Sandstone_Brick",
      "rotation": 2
    },
    {
      "x": 0,
      "y": 14,
      "z": -3,
      "name": "Rock_Sandstone_Brick",
      "rotation": 2
    },
    {
      "x": 0,
      "y": 15,
      "z": -3,
      "name": "Rock_Sandstone_Brick",
      "rotation": 2
    },
    {
      "x": 0,
      "y": 16,
      "z": -3,
      "name": "Rock_Sandstone_Brick",
      "rotation": 2
    },
    {
      "x": 0,
      "y": 17,
      "z": -3,
      "name": "Rock_Sandstone_Brick",
      "rotation": 2
    },
    {
      "x": 0,
      "y": 18,
      "z": -3,
      "name": "Rock_Sandstone_Brick",
      "rotation": 2
    },
    {
      "x": 0,
      "y": 19,
      "z": -3,
      "name": "Rock_Sandstone_Brick_Ornate",
      "rotation": 2
    },
    {
      "x": 0,
      "y": 20,
      "z": -3,
      "name": "Rock_Sandstone_Brick_Pillar_Base",
      "rotation": 2
    },
    {
      "x": 0,
      "y": 21,
      "z": -3,
      "name": "Rock_Sandstone_Brick_Pillar_Middle",
      "rotation": 2
    },
    {
      "x": 0,
      "y": 22,
      "z": -3,
      "name": "Rock_Sandstone_Brick_Pillar_Base",
      "rotation": 10
    },
    {
      "x": 0,
      "y": 23,
      "z": -3,
      "name": "Rock_Sandstone_Brick_Ornate",
      "rotation": 2
    },
    {
      "x": 0,
      "y": 24,
      "z": -3,
      "name": "Rock_Sandstone_Brick",
      "rotation": 2
    },
    {
      "x": 0,
      "y": 25,
      "z": -3,
      "name": "Rock_Sandstone_Brick_Stairs",
      "rotation": 2
    },
    {
      "x": 0,
      "y": 26,
      "z": -3,
      "name": "Rock_Sandstone_Brick_Stairs",
      "rotation": 8
    },
    {
      "x": 0,
      "y": 27,
      "z": -3,
      "name": "Rock_Sandstone_White_Brick",
      "rotation": 2
    },
    {
      "x": 0,
      "y": 28,
      "z": -3,
      "name": "Rock_Sandstone_White_Brick",
      "rotation": 2
    },
    {
      "x": 0,
      "y": 29,
      "z": -3,
      "name": "Rock_Sandstone_Brick_Smooth_Half",
      "rotation": 2
    },
    {
      "x": 0,
      "y": 3,
      "z": -2,
      "name": "Rock_Sandstone_Brick",
      "rotation": 2
    },
    {
      "x": 0,
      "y": 4,
      "z": -2,
      "name": "Rock_Sandstone_Cobble",
      "rotation": 2
    },
    {
      "x": 0,
      "y": 5,
      "z": -2,
      "name": "Rock_Sandstone_Cobble",
      "rotation": 2
    },
    {
      "x": 0,
      "y": 6,
      "z": -2,
      "name": "Rock_Sandstone_Cobble",
      "rotation": 2
    },
    {
      "x": 0,
      "y": 7,
      "z": -2,
      "name": "Rock_Sandstone_Cobble_Stairs",
      "rotation": 1
    },
    {
      "x": 0,
      "y": 11,
      "z": -2,
      "name": "Rock_Sandstone_Cobble",
      "rotation": 2
    },
    {
      "x": 0,
      "y": 19,
      "z": -2,
      "name": "Wood_Drywood_Planks",
      "rotation": 2
    },
    {
      "x": 0,
      "y": 20,
      "z": -2,
      "name": "Rock_Sandstone_Brick_Smooth_Half",
      "rotation": 5
    },
    {
      "x": 0,
      "y": 21,
      "z": -2,
      "name": "Rock_Sandstone_Brick_Smooth_Half",
      "rotation": 5
    },
    {
      "x": 0,
      "y": 22,
      "z": -2,
      "name": "Rock_Sandstone_Brick_Smooth_Half",
      "rotation": 5
    },
    {
      "x": 0,
      "y": 23,
      "z": -2,
      "name": "Rock_Sandstone_Brick",
      "rotation": 2
    },
    {
      "x": 0,
      "y": 24,
      "z": -2,
      "name": "Rock_Sandstone_Brick",
      "rotation": 2
    },
    {
      "x": 0,
      "y": 25,
      "z": -2,
      "name": "Wood_Drywood_Planks",
      "rotation": 2
    },
    {
      "x": 0,
      "y": 26,
      "z": -2,
      "name": "Furniture_Temple_Wind_Pot",
      "rotation": 2
    },
    {
      "x": 0,
      "y": 27,
      "z": -2,
      "name": "Furniture_Temple_Wind_Pot",
      "filler": 1024,
      "rotation": 2
    },
    {
      "x": 0,
      "y": 3,
      "z": -1,
      "name": "Rock_Sandstone_Brick",
      "rotation": 2
    },
    {
      "x": 0,
      "y": 4,
      "z": -1,
      "name": "Rock_Sandstone_Cobble",
      "rotation": 2
    },
    {
      "x": 0,
      "y": 5,
      "z": -1,
      "name": "Rock_Sandstone_Cobble",
      "rotation": 2
    },
    {
      "x": 0,
      "y": 6,
      "z": -1,
      "name": "Rock_Sandstone_Cobble",
      "rotation": 2
    },
    {
      "x": 0,
      "y": 7,
      "z": -1,
      "name": "Rock_Sandstone_Cobble_Stairs",
      "rotation": 1
    },
    {
      "x": 0,
      "y": 11,
      "z": -1,
      "name": "Rock_Sandstone_Cobble",
      "rotation": 2
    },
    {
      "x": 0,
      "y": 12,
      "z": -1,
      "name": "Furniture_Desert_Ladder",
      "rotation": 1
    },
    {
      "x": 0,
      "y": 13,
      "z": -1,
      "name": "Furniture_Desert_Ladder",
      "rotation": 1
    },
    {
      "x": 0,
      "y": 14,
      "z": -1,
      "name": "Furniture_Desert_Ladder",
      "rotation": 1
    },
    {
      "x": 0,
      "y": 15,
      "z": -1,
      "name": "Furniture_Desert_Ladder",
      "rotation": 1
    },
    {
      "x": 0,
      "y": 16,
      "z": -1,
      "name": "Furniture_Desert_Ladder",
      "rotation": 1
    },
    {
      "x": 0,
      "y": 17,
      "z": -1,
      "name": "Furniture_Desert_Ladder",
      "rotation": 1
    },
    {
      "x": 0,
      "y": 18,
      "z": -1,
      "name": "Furniture_Desert_Ladder",
      "rotation": 1
    },
    {
      "x": 0,
      "y": 19,
      "z": -1,
      "name": "Furniture_Desert_Ladder",
      "rotation": 1
    },
    {
      "x": 0,
      "y": 20,
      "z": -1,
      "name": "Furniture_Desert_Ladder",
      "rotation": 1
    },
    {
      "x": 0,
      "y": 21,
      "z": -1,
      "name": "Furniture_Desert_Ladder",
      "rotation": 1
    },
    {
      "x": 0,
      "y": 22,
      "z": -1,
      "name": "Furniture_Desert_Ladder",
      "rotation": 1
    },
    {
      "x": 0,
      "y": 23,
      "z": -1,
      "name": "Furniture_Desert_Ladder",
      "rotation": 1
    },
    {
      "x": 0,
      "y": 24,
      "z": -1,
      "name": "Furniture_Desert_Ladder",
      "rotation": 1
    },
    {
      "x": 0,
      "y": 25,
      "z": -1,
      "name": "Furniture_Desert_Ladder",
      "rotation": 1
    },
    {
      "x": 0,
      "y": 3,
      "z": 0,
      "name": "Rock_Sandstone_Brick",
      "rotation": 2
    },
    {
      "x": 0,
      "y": 4,
      "z": 0,
      "name": "Rock_Sandstone_Cobble",
      "rotation": 2
    },
    {
      "x": 0,
      "y": 5,
      "z": 0,
      "name": "Rock_Sandstone_Cobble",
      "rotation": 2
    },
    {
      "x": 0,
      "y": 6,
      "z": 0,
      "name": "Rock_Sandstone_Cobble",
      "rotation": 2
    },
    {
      "x": 0,
      "y": 7,
      "z": 0,
      "name": "Rock_Sandstone_Cobble",
      "rotation": 2
    },
    {
      "x": 0,
      "y": 8,
      "z": 0,
      "name": "Rock_Sandstone_Cobble_Stairs",
      "rotation": 2
    },
    {
      "x": 0,
      "y": 11,
      "z": 0,
      "name": "Rock_Sandstone_Cobble_Half",
      "rotation": 10
    },
    {
      "x": 0,
      "y": 19,
      "z": 0,
      "name": "Wood_Drywood_Planks",
      "rotation": 2
    },
    {
      "x": 0,
      "y": 25,
      "z": 0,
      "name": "Wood_Drywood_Planks",
      "rotation": 2
    },
    {
      "x": 0,
      "y": 3,
      "z": 1,
      "name": "Rock_Sandstone_Cobble",
      "rotation": 2
    },
    {
      "x": 0,
      "y": 4,
      "z": 1,
      "name": "Furniture_Desert_Chair"
    },
    {
      "x": 0,
      "y": 6,
      "z": 1,
      "name": "Wood_Torch_Wall"
    },
    {
      "x": 0,
      "y": 8,
      "z": 1,
      "name": "Rock_Sandstone_Cobble",
      "rotation": 2
    },
    {
      "x": 0,
      "y": 9,
      "z": 1,
      "name": "Rock_Sandstone_Cobble_Half",
      "rotation": 2
    },
    {
      "x": 0,
      "y": 19,
      "z": 1,
      "name": "Wood_Drywood_Planks",
      "rotation": 2
    },
    {
      "x": 0,
      "y": 25,
      "z": 1,
      "name": "Wood_Drywood_Planks",
      "rotation": 2
    },
    {
      "x": 0,
      "y": 3,
      "z": 2,
      "name": "Rock_Sandstone_Cobble",
      "rotation": 2
    },
    {
      "x": 0,
      "y": 8,
      "z": 2,
      "name": "Rock_Sandstone_Cobble",
      "rotation": 2
    },
    {
      "x": 0,
      "y": 9,
      "z": 2,
      "name": "Rock_Sandstone_Cobble_Half",
      "rotation": 2
    },
    {
      "x": 0,
      "y": 19,
      "z": 2,
      "name": "Wood_Drywood_Planks",
      "rotation": 2
    },
    {
      "x": 0,
      "y": 20,
      "z": 2,
      "name": "Rock_Sandstone_Brick_Smooth_Half",
      "rotation": 5
    },
    {
      "x": 0,
      "y": 21,
      "z": 2,
      "name": "Rock_Sandstone_Brick_Smooth_Half",
      "rotation": 5
    },
    {
      "x": 0,
      "y": 22,
      "z": 2,
      "name": "Rock_Sandstone_Brick_Smooth_Half",
      "rotation": 5
    },
    {
      "x": 0,
      "y": 23,
      "z": 2,
      "name": "Rock_Sandstone_Brick",
      "rotation": 2
    },
    {
      "x": 0,
      "y": 24,
      "z": 2,
      "name": "Rock_Sandstone_Brick",
      "rotation": 2
    },
    {
      "x": 0,
      "y": 25,
      "z": 2,
      "name": "Wood_Drywood_Planks",
      "rotation": 2
    },
    {
      "x": 0,
      "y": 3,
      "z": 3,
      "name": "Rock_Sandstone_Cobble",
      "rotation": 2
    },
    {
      "x": 0,
      "y": 8,
      "z": 3,
      "name": "Rock_Sandstone_Brick",
      "rotation": 2
    },
    {
      "x": 0,
      "y": 9,
      "z": 3,
      "name": "Rock_Sandstone_Brick",
      "rotation": 2
    },
    {
      "x": 0,
      "y": 10,
      "z": 3,
      "name": "Rock_Sandstone_Cobble",
      "rotation": 2
    },
    {
      "x": 0,
      "y": 11,
      "z": 3,
      "name": "Rock_Sandstone_Cobble",
      "rotation": 2
    },
    {
      "x": 0,
      "y": 12,
      "z": 3,
      "name": "Rock_Sandstone_Brick",
      "rotation": 2
    },
    {
      "x": 0,
      "y": 13,
      "z": 3,
      "name": "Rock_Sandstone_Brick",
      "rotation": 2
    },
    {
      "x": 0,
      "y": 14,
      "z": 3,
      "name": "Rock_Sandstone_Brick",
      "rotation": 2
    },
    {
      "x": 0,
      "y": 15,
      "z": 3,
      "name": "Rock_Sandstone_Brick",
      "rotation": 2
    },
    {
      "x": 0,
      "y": 16,
      "z": 3,
      "name": "Rock_Sandstone_Brick",
      "rotation": 2
    },
    {
      "x": 0,
      "y": 17,
      "z": 3,
      "name": "Rock_Sandstone_Brick",
      "rotation": 2
    },
    {
      "x": 0,
      "y": 18,
      "z": 3,
      "name": "Rock_Sandstone_Brick",
      "rotation": 2
    },
    {
      "x": 0,
      "y": 19,
      "z": 3,
      "name": "Rock_Sandstone_Brick_Ornate",
      "rotation": 2
    },
    {
      "x": 0,
      "y": 20,
      "z": 3,
      "name": "Rock_Sandstone_Brick_Pillar_Base",
      "rotation": 2
    },
    {
      "x": 0,
      "y": 21,
      "z": 3,
      "name": "Rock_Sandstone_Brick_Pillar_Middle",
      "rotation": 2
    },
    {
      "x": 0,
      "y": 22,
      "z": 3,
      "name": "Rock_Sandstone_Brick_Pillar_Base",
      "rotation": 10
    },
    {
      "x": 0,
      "y": 23,
      "z": 3,
      "name": "Rock_Sandstone_Brick_Ornate",
      "rotation": 2
    },
    {
      "x": 0,
      "y": 24,
      "z": 3,
      "name": "Rock_Sandstone_Brick",
      "rotation": 2
    },
    {
      "x": 0,
      "y": 25,
      "z": 3,
      "name": "Rock_Sandstone_Brick_Half",
      "rotation": 2
    },
    {
      "x": 0,
      "y": 3,
      "z": 4,
      "name": "Rock_Sandstone_Cobble",
      "rotation": 2
    },
    {
      "x": 0,
      "y": 4,
      "z": 4,
      "name": "Wood_Drywood_Planks_Half",
      "rotation": 5
    },
    {
      "x": 0,
      "y": 5,
      "z": 4,
      "name": "Wood_Drywood_Planks_Half",
      "rotation": 5
    },
    {
      "x": 0,
      "y": 6,
      "z": 4,
      "name": "Wood_Drywood_Stairs",
      "rotation": 11
    },
    {
      "x": 0,
      "y": 7,
      "z": 4,
      "name": "Rock_Sandstone_Brick",
      "rotation": 2
    },
    {
      "x": 0,
      "y": 8,
      "z": 4,
      "name": "Rock_Sandstone_Brick_Pillar_Base",
      "rotation": 2
    },
    {
      "x": 0,
      "y": 9,
      "z": 4,
      "name": "Rock_Sandstone_Brick",
      "rotation": 2
    },
    {
      "x": 0,
      "y": 10,
      "z": 4,
      "name": "Rock_Sandstone_Cobble_Stairs"
    },
    {
      "x": 0,
      "y": 11,
      "z": 4,
      "name": "Rock_Sandstone_Cobble_Half",
      "rotation": 4
    },
    {
      "x": 0,
      "y": 14,
      "z": 4,
      "name": "Rock_Sandstone_Brick_Smooth_Half",
      "rotation": 7
    },
    {
      "x": 0,
      "y": 15,
      "z": 4,
      "name": "Rock_Sandstone_Brick_Smooth_Half",
      "rotation": 7
    },
    {
      "x": 0,
      "y": 3,
      "z": 5,
      "name": "Rock_Sandstone_Cobble_Stairs"
    },
    {
      "x": 1,
      "y": 3,
      "z": -4,
      "name": "Rock_Sandstone_Cobble",
      "rotation": 2
    },
    {
      "x": 1,
      "y": 4,
      "z": -4,
      "name": "Rock_Sandstone_Cobble",
      "rotation": 2
    },
    {
      "x": 1,
      "y": 5,
      "z": -4,
      "name": "Rock_Sandstone_Cobble",
      "rotation": 2
    },
    {
      "x": 1,
      "y": 6,
      "z": -4,
      "name": "Rock_Sandstone_Cobble",
      "rotation": 2
    },
    {
      "x": 1,
      "y": 7,
      "z": -4,
      "name": "Rock_Sandstone_Brick",
      "rotation": 2
    },
    {
      "x": 1,
      "y": 8,
      "z": -4,
      "name": "Rock_Sandstone_Brick_Pillar_Base",
      "rotation": 2
    },
    {
      "x": 1,
      "y": 9,
      "z": -4,
      "name": "Rock_Sandstone_Brick",
      "rotation": 2
    },
    {
      "x": 1,
      "y": 10,
      "z": -4,
      "name": "Rock_Sandstone_Cobble_Stairs",
      "rotation": 2
    },
    {
      "x": 1,
      "y": 11,
      "z": -4,
      "name": "Rock_Sandstone_Cobble_Half",
      "rotation": 6
    },
    {
      "x": 1,
      "y": 13,
      "z": -4,
      "name": "Rock_Sandstone_Brick_Smooth_Half",
      "rotation": 6
    },
    {
      "x": 1,
      "y": 16,
      "z": -4,
      "name": "Rock_Sandstone_Brick_Smooth_Half",
      "rotation": 2
    },
    {
      "x": 1,
      "y": 24,
      "z": -4,
      "name": "Rock_Sandstone_Brick_Smooth_Half",
      "rotation": 6
    },
    {
      "x": 1,
      "y": 3,
      "z": -3,
      "name": "Rock_Sandstone_Cobble",
      "rotation": 2
    },
    {
      "x": 1,
      "y": 4,
      "z": -3,
      "name": "Rock_Sandstone_Cobble",
      "rotation": 2
    },
    {
      "x": 1,
      "y": 5,
      "z": -3,
      "name": "Rock_Sandstone_Cobble",
      "rotation": 2
    },
    {
      "x": 1,
      "y": 6,
      "z": -3,
      "name": "Rock_Sandstone_Brick",
      "rotation": 2
    },
    {
      "x": 1,
      "y": 7,
      "z": -3,
      "name": "Rock_Sandstone_Brick",
      "rotation": 2
    },
    {
      "x": 1,
      "y": 8,
      "z": -3,
      "name": "Rock_Sandstone_Brick",
      "rotation": 2
    },
    {
      "x": 1,
      "y": 9,
      "z": -3,
      "name": "Rock_Sandstone_Cobble",
      "rotation": 2
    },
    {
      "x": 1,
      "y": 10,
      "z": -3,
      "name": "Rock_Sandstone_Cobble",
      "rotation": 2
    },
    {
      "x": 1,
      "y": 11,
      "z": -3,
      "name": "Rock_Sandstone_Cobble",
      "rotation": 2
    },
    {
      "x": 1,
      "y": 12,
      "z": -3,
      "name": "Rock_Sandstone_Brick",
      "rotation": 2
    },
    {
      "x": 1,
      "y": 13,
      "z": -3,
      "name": "Rock_Sandstone_Brick",
      "rotation": 2
    },
    {
      "x": 1,
      "y": 14,
      "z": -3,
      "name": "Furniture_Desert_Window",
      "rotation": 2
    },
    {
      "x": 1,
      "y": 15,
      "z": -3,
      "name": "Furniture_Desert_Window",
      "rotation": 2
    },
    {
      "x": 1,
      "y": 16,
      "z": -3,
      "name": "Rock_Sandstone_Brick",
      "rotation": 2
    },
    {
      "x": 1,
      "y": 17,
      "z": -3,
      "name": "Rock_Sandstone_Brick",
      "rotation": 2
    },
    {
      "x": 1,
      "y": 18,
      "z": -3,
      "name": "Rock_Sandstone_Brick",
      "rotation": 2
    },
    {
      "x": 1,
      "y": 19,
      "z": -3,
      "name": "Rock_Sandstone_Brick_Ornate",
      "rotation": 2
    },
    {
      "x": 1,
      "y": 23,
      "z": -3,
      "name": "Rock_Sandstone_Brick_Ornate",
      "rotation": 2
    },
    {
      "x": 1,
      "y": 24,
      "z": -3,
      "name": "Rock_Sandstone_Brick",
      "rotation": 2
    },
    {
      "x": 1,
      "y": 25,
      "z": -3,
      "name": "Rock_Sandstone_Brick_Stairs",
      "rotation": 2
    },
    {
      "x": 1,
      "y": 26,
      "z": -3,
      "name": "Rock_Sandstone_Brick_Stairs",
      "rotation": 8
    },
    {
      "x": 1,
      "y": 27,
      "z": -3,
      "name": "Furniture_Desert_Window",
      "rotation": 2
    },
    {
      "x": 1,
      "y": 3,
      "z": -2,
      "name": "Rock_Sandstone_Brick",
      "rotation": 2
    },
    {
      "x": 1,
      "y": 4,
      "z": -2,
      "name": "Rock_Sandstone_Cobble",
      "rotation": 2
    },
    {
      "x": 1,
      "y": 5,
      "z": -2,
      "name": "Rock_Sandstone_Cobble",
      "rotation": 2
    },
    {
      "x": 1,
      "y": 6,
      "z": -2,
      "name": "Rock_Sandstone_Cobble_Stairs",
      "rotation": 1
    },
    {
      "x": 1,
      "y": 11,
      "z": -2,
      "name": "Rock_Sandstone_Cobble",
      "rotation": 2
    },
    {
      "x": 1,
      "y": 13,
      "z": -2,
      "name": "Wood_Torch_Wall"
    },
    {
      "x": 1,
      "y": 19,
      "z": -2,
      "name": "Wood_Drywood_Planks",
      "rotation": 2
    },
    {
      "x": 1,
      "y": 23,
      "z": -2,
      "name": "Rock_Sandstone_Brick_Half",
      "rotation": 10
    },
    {
      "x": 1,
      "y": 24,
      "z": -2,
      "name": "Rock_Sandstone_Brick",
      "rotation": 2
    },
    {
      "x": 1,
      "y": 25,
      "z": -2,
      "name": "Wood_Drywood_Planks",
      "rotation": 2
    },
    {
      "x": 1,
      "y": 26,
      "z": -2,
      "name": "Furniture_Village_Crate",
      "rotation": 2
    },
    {
      "x": 1,
      "y": 3,
      "z": -1,
      "name": "Rock_Sandstone_Brick",
      "rotation": 2
    },
    {
      "x": 1,
      "y": 4,
      "z": -1,
      "name": "Rock_Sandstone_Cobble",
      "rotation": 2
    },
    {
      "x": 1,
      "y": 5,
      "z": -1,
      "name": "Rock_Sandstone_Cobble",
      "rotation": 2
    },
    {
      "x": 1,
      "y": 6,
      "z": -1,
      "name": "Rock_Sandstone_Cobble_Stairs",
      "rotation": 1
    },
    {
      "x": 1,
      "y": 11,
      "z": -1,
      "name": "Rock_Sandstone_Cobble",
      "rotation": 2
    },
    {
      "x": 1,
      "y": 19,
      "z": -1,
      "name": "Wood_Drywood_Planks_Half",
      "rotation": 7
    },
    {
      "x": 1,
      "y": 25,
      "z": -1,
      "name": "Wood_Drywood_Planks_Half",
      "rotation": 7
    },
    {
      "x": 1,
      "y": 3,
      "z": 0,
      "name": "Rock_Sandstone_Brick",
      "rotation": 2
    },
    {
      "x": 1,
      "y": 4,
      "z": 0,
      "name": "Rock_Sandstone_Brick",
      "rotation": 2
    },
    {
      "x": 1,
      "y": 5,
      "z": 0,
      "name": "Rock_Sandstone_Brick",
      "rotation": 2
    },
    {
      "x": 1,
      "y": 6,
      "z": 0,
      "name": "Rock_Sandstone_Brick",
      "rotation": 2
    },
    {
      "x": 1,
      "y": 7,
      "z": 0,
      "name": "Rock_Sandstone_Brick",
      "rotation": 2
    },
    {
      "x": 1,
      "y": 8,
      "z": 0,
      "name": "Rock_Sandstone_Brick",
      "rotation": 2
    },
    {
      "x": 1,
      "y": 9,
      "z": 0,
      "name": "Rock_Sandstone_Brick",
      "rotation": 2
    },
    {
      "x": 1,
      "y": 10,
      "z": 0,
      "name": "Rock_Sandstone_Brick",
      "rotation": 2
    },
    {
      "x": 1,
      "y": 11,
      "z": 0,
      "name": "Rock_Sandstone_Brick",
      "rotation": 2
    },
    {
      "x": 1,
      "y": 19,
      "z": 0,
      "name": "Wood_Drywood_Planks",
      "rotation": 2
    },
    {
      "x": 1,
      "y": 25,
      "z": 0,
      "name": "Wood_Drywood_Planks",
      "rotation": 2
    },
    {
      "x": 1,
      "y": 3,
      "z": 1,
      "name": "Rock_Sandstone_Cobble",
      "rotation": 2
    },
    {
      "x": 1,
      "y": 8,
      "z": 1,
      "name": "Rock_Sandstone_Cobble",
      "rotation": 2
    },
    {
      "x": 1,
      "y": 9,
      "z": 1,
      "name": "Rock_Sandstone_Cobble",
      "rotation": 2
    },
    {
      "x": 1,
      "y": 19,
      "z": 1,
      "name": "Wood_Drywood_Planks",
      "rotation": 2
    },
    {
      "x": 1,
      "y": 25,
      "z": 1,
      "name": "Wood_Drywood_Beam",
      "rotation": 6
    },
    {
      "x": 1,
      "y": 3,
      "z": 2,
      "name": "Rock_Sandstone_Cobble",
      "rotation": 2
    },
    {
      "x": 1,
      "y": 8,
      "z": 2,
      "name": "Rock_Sandstone_Cobble",
      "rotation": 2
    },
    {
      "x": 1,
      "y": 9,
      "z": 2,
      "name": "Rock_Sandstone_Cobble",
      "rotation": 2
    },
    {
      "x": 1,
      "y": 19,
      "z": 2,
      "name": "Wood_Drywood_Planks",
      "rotation": 2
    },
    {
      "x": 1,
      "y": 25,
      "z": 2,
      "name": "Wood_Drywood_Beam",
      "rotation": 6
    },
    {
      "x": 1,
      "y": 3,
      "z": 3,
      "name": "Rock_Sandstone_Cobble",
      "rotation": 2
    },
    {
      "x": 1,
      "y": 8,
      "z": 3,
      "name": "Rock_Sandstone_Brick",
      "rotation": 2
    },
    {
      "x": 1,
      "y": 9,
      "z": 3,
      "name": "Rock_Sandstone_Cobble",
      "rotation": 2
    },
    {
      "x": 1,
      "y": 10,
      "z": 3,
      "name": "Rock_Sandstone_Cobble",
      "rotation": 2
    },
    {
      "x": 1,
      "y": 11,
      "z": 3,
      "name": "Rock_Sandstone_Cobble",
      "rotation": 2
    },
    {
      "x": 1,
      "y": 12,
      "z": 3,
      "name": "Rock_Sandstone_Brick",
      "rotation": 2
    },
    {
      "x": 1,
      "y": 13,
      "z": 3,
      "name": "Rock_Sandstone_Brick",
      "rotation": 2
    },
    {
      "x": 1,
      "y": 14,
      "z": 3,
      "name": "Furniture_Desert_Window",
      "rotation": 2
    },
    {
      "x": 1,
      "y": 15,
      "z": 3,
      "name": "Furniture_Desert_Window",
      "rotation": 2
    },
    {
      "x": 1,
      "y": 16,
      "z": 3,
      "name": "Rock_Sandstone_Brick",
      "rotation": 2
    },
    {
      "x": 1,
      "y": 17,
      "z": 3,
      "name": "Rock_Sandstone_Brick",
      "rotation": 2
    },
    {
      "x": 1,
      "y": 18,
      "z": 3,
      "name": "Rock_Sandstone_Brick",
      "rotation": 2
    },
    {
      "x": 1,
      "y": 19,
      "z": 3,
      "name": "Rock_Sandstone_Brick_Ornate",
      "rotation": 2
    },
    {
      "x": 1,
      "y": 20,
      "z": 3,
      "name": "Rock_Sandstone_Brick_Wall",
      "rotation": 2
    },
    {
      "x": 1,
      "y": 3,
      "z": 4,
      "name": "Rock_Sandstone_Cobble",
      "rotation": 2
    },
    {
      "x": 1,
      "y": 6,
      "z": 4,
      "name": "Wood_Drywood_Planks_Half",
      "rotation": 10
    },
    {
      "x": 1,
      "y": 7,
      "z": 4,
      "name": "Rock_Sandstone_Brick",
      "rotation": 2
    },
    {
      "x": 1,
      "y": 8,
      "z": 4,
      "name": "Rock_Sandstone_Brick_Pillar_Base",
      "rotation": 2
    },
    {
      "x": 1,
      "y": 9,
      "z": 4,
      "name": "Rock_Sandstone_Brick",
      "rotation": 2
    },
    {
      "x": 1,
      "y": 10,
      "z": 4,
      "name": "Rock_Sandstone_Cobble_Stairs"
    },
    {
      "x": 1,
      "y": 11,
      "z": 4,
      "name": "Rock_Sandstone_Cobble_Half",
      "rotation": 4
    },
    {
      "x": 1,
      "y": 13,
      "z": 4,
      "name": "Rock_Sandstone_Brick_Smooth_Half",
      "rotation": 4
    },
    {
      "x": 1,
      "y": 16,
      "z": 4,
      "name": "Rock_Sandstone_Brick_Smooth_Half",
      "rotation": 2
    },
    {
      "x": 1,
      "y": 3,
      "z": 5,
      "name": "Rock_Sandstone_Cobble_Stairs"
    },
    {
      "x": 2,
      "y": 3,
      "z": -4,
      "name": "Rock_Sandstone_Cobble",
      "rotation": 2
    },
    {
      "x": 2,
      "y": 4,
      "z": -4,
      "name": "Rock_Sandstone_Cobble",
      "rotation": 2
    },
    {
      "x": 2,
      "y": 5,
      "z": -4,
      "name": "Rock_Sandstone_Cobble",
      "rotation": 2
    },
    {
      "x": 2,
      "y": 6,
      "z": -4,
      "name": "Rock_Sandstone_Brick",
      "rotation": 2
    },
    {
      "x": 2,
      "y": 7,
      "z": -4,
      "name": "Rock_Sandstone_Brick",
      "rotation": 2
    },
    {
      "x": 2,
      "y": 8,
      "z": -4,
      "name": "Rock_Sandstone_Brick_Pillar_Base",
      "rotation": 2
    },
    {
      "x": 2,
      "y": 9,
      "z": -4,
      "name": "Rock_Sandstone_Brick",
      "rotation": 2
    },
    {
      "x": 2,
      "y": 10,
      "z": -4,
      "name": "Rock_Sandstone_Cobble_Stairs",
      "rotation": 2
    },
    {
      "x": 2,
      "y": 11,
      "z": -4,
      "name": "Rock_Sandstone_Cobble_Half",
      "rotation": 6
    },
    {
      "x": 2,
      "y": 14,
      "z": -4,
      "name": "Rock_Sandstone_Brick_Smooth_Half",
      "rotation": 5
    },
    {
      "x": 2,
      "y": 15,
      "z": -4,
      "name": "Rock_Sandstone_Brick_Smooth_Half",
      "rotation": 5
    },
    {
      "x": 2,
      "y": 3,
      "z": -3,
      "name": "Rock_Sandstone_Brick",
      "rotation": 2
    },
    {
      "x": 2,
      "y": 4,
      "z": -3,
      "name": "Rock_Sandstone_Cobble",
      "rotation": 2
    },
    {
      "x": 2,
      "y": 5,
      "z": -3,
      "name": "Rock_Sandstone_Brick",
      "rotation": 2
    },
    {
      "x": 2,
      "y": 6,
      "z": -3,
      "name": "Rock_Sandstone_Brick",
      "rotation": 2
    },
    {
      "x": 2,
      "y": 7,
      "z": -3,
      "name": "Rock_Sandstone_Brick",
      "rotation": 2
    },
    {
      "x": 2,
      "y": 8,
      "z": -3,
      "name": "Rock_Sandstone_Brick",
      "rotation": 2
    },
    {
      "x": 2,
      "y": 9,
      "z": -3,
      "name": "Rock_Sandstone_Cobble",
      "rotation": 2
    },
    {
      "x": 2,
      "y": 10,
      "z": -3,
      "name": "Rock_Sandstone_Cobble",
      "rotation": 2
    },
    {
      "x": 2,
      "y": 11,
      "z": -3,
      "name": "Rock_Sandstone_Cobble",
      "rotation": 2
    },
    {
      "x": 2,
      "y": 12,
      "z": -3,
      "name": "Rock_Sandstone_Brick",
      "rotation": 2
    },
    {
      "x": 2,
      "y": 13,
      "z": -3,
      "name": "Rock_Sandstone_Brick",
      "rotation": 2
    },
    {
      "x": 2,
      "y": 14,
      "z": -3,
      "name": "Rock_Sandstone_Brick",
      "rotation": 2
    },
    {
      "x": 2,
      "y": 15,
      "z": -3,
      "name": "Rock_Sandstone_Brick",
      "rotation": 2
    },
    {
      "x": 2,
      "y": 16,
      "z": -3,
      "name": "Rock_Sandstone_Brick_Half",
      "rotation": 5
    },
    {
      "x": 2,
      "y": 17,
      "z": -3,
      "name": "Rock_Sandstone_Brick_Half",
      "rotation": 5
    },
    {
      "x": 2,
      "y": 22,
      "z": -3,
      "name": "Rock_Sandstone_Brick_Pillar_Base",
      "rotation": 10
    },
    {
      "x": 2,
      "y": 23,
      "z": -3,
      "name": "Rock_Sandstone_Brick_Ornate",
      "rotation": 2
    },
    {
      "x": 2,
      "y": 24,
      "z": -3,
      "name": "Rock_Sandstone_Brick",
      "rotation": 2
    },
    {
      "x": 2,
      "y": 25,
      "z": -3,
      "name": "Rock_Sandstone_Brick_Half",
      "rotation": 6
    },
    {
      "x": 2,
      "y": 26,
      "z": -3,
      "name": "Rock_Sandstone_Brick_Stairs",
      "rotation": 8
    },
    {
      "x": 2,
      "y": 27,
      "z": -3,
      "name": "Rock_Sandstone_White_Brick",
      "rotation": 2
    },
    {
      "x": 2,
      "y": 28,
      "z": -3,
      "name": "Rock_Sandstone_White_Brick_Half",
      "rotation": 2
    },
    {
      "x": 2,
      "y": 3,
      "z": -2,
      "name": "Rock_Sandstone_Cobble",
      "rotation": 2
    },
    {
      "x": 2,
      "y": 4,
      "z": -2,
      "name": "Rock_Sandstone_Cobble",
      "rotation": 2
    },
    {
      "x": 2,
      "y": 5,
      "z": -2,
      "name": "Rock_Sandstone_Cobble_Stairs",
      "rotation": 1
    },
    {
      "x": 2,
      "y": 9,
      "z": -2,
      "name": "Rock_Sandstone_Cobble_Half",
      "rotation": 7
    },
    {
      "x": 2,
      "y": 10,
      "z": -2,
      "name": "Rock_Sandstone_Cobble",
      "rotation": 2
    },
    {
      "x": 2,
      "y": 11,
      "z": -2,
      "name": "Rock_Sandstone_Cobble",
      "rotation": 2
    },
    {
      "x": 2,
      "y": 19,
      "z": -2,
      "name": "Wood_Drywood_Planks",
      "rotation": 2
    },
    {
      "x": 2,
      "y": 23,
      "z": -2,
      "name": "Rock_Sandstone_Brick_Half",
      "rotation": 10
    },
    {
      "x": 2,
      "y": 24,
      "z": -2,
      "name": "Rock_Sandstone_Brick",
      "rotation": 2
    },
    {
      "x": 2,
      "y": 25,
      "z": -2,
      "name": "Wood_Drywood_Planks",
      "rotation": 2
    },
    {
      "x": 2,
      "y": 3,
      "z": -1,
      "name": "Rock_Sandstone_Cobble",
      "rotation": 2
    },
    {
      "x": 2,
      "y": 4,
      "z": -1,
      "name": "Rock_Sandstone_Cobble",
      "rotation": 2
    },
    {
      "x": 2,
      "y": 5,
      "z": -1,
      "name": "Rock_Sandstone_Cobble_Stairs",
      "rotation": 1
    },
    {
      "x": 2,
      "y": 9,
      "z": -1,
      "name": "Rock_Sandstone_Cobble_Half",
      "rotation": 7
    },
    {
      "x": 2,
      "y": 10,
      "z": -1,
      "name": "Rock_Sandstone_Cobble",
      "rotation": 2
    },
    {
      "x": 2,
      "y": 11,
      "z": -1,
      "name": "Rock_Sandstone_Cobble_Half",
      "rotation": 2
    },
    {
      "x": 2,
      "y": 19,
      "z": -1,
      "name": "Wood_Drywood_Planks",
      "rotation": 2
    },
    {
      "x": 2,
      "y": 25,
      "z": -1,
      "name": "Wood_Drywood_Planks",
      "rotation": 2
    },
    {
      "x": 2,
      "y": 3,
      "z": 0,
      "name": "Rock_Sandstone_Cobble"
    },
    {
      "x": 2,
      "y": 8,
      "z": 0,
      "name": "Rock_Sandstone_Brick",
      "rotation": 2
    },
    {
      "x": 2,
      "y": 9,
      "z": 0,
      "name": "Rock_Sandstone_Cobble",
      "rotation": 2
    },
    {
      "x": 2,
      "y": 10,
      "z": 0,
      "name": "Rock_Sandstone_Cobble",
      "rotation": 2
    },
    {
      "x": 2,
      "y": 19,
      "z": 0,
      "name": "Wood_Drywood_Planks",
      "rotation": 2
    },
    {
      "x": 2,
      "y": 25,
      "z": 0,
      "name": "Wood_Drywood_Planks",
      "rotation": 2
    },
    {
      "x": 2,
      "y": 3,
      "z": 1,
      "name": "Rock_Sandstone_Cobble",
      "rotation": 2
    },
    {
      "x": 2,
      "y": 8,
      "z": 1,
      "name": "Rock_Sandstone_Cobble",
      "rotation": 2
    },
    {
      "x": 2,
      "y": 9,
      "z": 1,
      "name": "Rock_Sandstone_Cobble",
      "rotation": 2
    },
    {
      "x": 2,
      "y": 10,
      "z": 1,
      "name": "Rock_Sandstone_Cobble_Half",
      "rotation": 2
    },
    {
      "x": 2,
      "y": 19,
      "z": 1,
      "name": "Wood_Drywood_Planks",
      "rotation": 2
    },
    {
      "x": 2,
      "y": 25,
      "z": 1,
      "name": "Wood_Drywood_Planks_Half",
      "rotation": 4
    },
    {
      "x": 2,
      "y": 3,
      "z": 2,
      "name": "Rock_Sandstone_Cobble",
      "rotation": 2
    },
    {
      "x": 2,
      "y": 8,
      "z": 2,
      "name": "Rock_Sandstone_Cobble",
      "rotation": 2
    },
    {
      "x": 2,
      "y": 9,
      "z": 2,
      "name": "Rock_Sandstone_Cobble",
      "rotation": 2
    },
    {
      "x": 2,
      "y": 10,
      "z": 2,
      "name": "Rock_Sandstone_Cobble_Half",
      "rotation": 2
    },
    {
      "x": 2,
      "y": 19,
      "z": 2,
      "name": "Wood_Drywood_Planks",
      "rotation": 2
    },
    {
      "x": 2,
      "y": 20,
      "z": 2,
      "name": "Rock_Sandstone_Brick_Smooth_Half",
      "rotation": 7
    },
    {
      "x": 2,
      "y": 21,
      "z": 2,
      "name": "Rock_Sandstone_Brick_Smooth_Half",
      "rotation": 7
    },
    {
      "x": 2,
      "y": 3,
      "z": 3,
      "name": "Rock_Sandstone_Cobble",
      "rotation": 2
    },
    {
      "x": 2,
      "y": 8,
      "z": 3,
      "name": "Rock_Sandstone_Brick",
      "rotation": 2
    },
    {
      "x": 2,
      "y": 9,
      "z": 3,
      "name": "Rock_Sandstone_Brick",
      "rotation": 2
    },
    {
      "x": 2,
      "y": 10,
      "z": 3,
      "name": "Rock_Sandstone_Cobble",
      "rotation": 2
    },
    {
      "x": 2,
      "y": 11,
      "z": 3,
      "name": "Rock_Sandstone_Cobble",
      "rotation": 2
    },
    {
      "x": 2,
      "y": 12,
      "z": 3,
      "name": "Rock_Sandstone_Brick",
      "rotation": 2
    },
    {
      "x": 2,
      "y": 13,
      "z": 3,
      "name": "Rock_Sandstone_Brick",
      "rotation": 2
    },
    {
      "x": 2,
      "y": 14,
      "z": 3,
      "name": "Rock_Sandstone_Brick",
      "rotation": 2
    },
    {
      "x": 2,
      "y": 15,
      "z": 3,
      "name": "Rock_Sandstone_Brick",
      "rotation": 2
    },
    {
      "x": 2,
      "y": 16,
      "z": 3,
      "name": "Rock_Sandstone_Brick",
      "rotation": 2
    },
    {
      "x": 2,
      "y": 17,
      "z": 3,
      "name": "Rock_Sandstone_Brick",
      "rotation": 2
    },
    {
      "x": 2,
      "y": 18,
      "z": 3,
      "name": "Rock_Sandstone_Brick",
      "rotation": 2
    },
    {
      "x": 2,
      "y": 19,
      "z": 3,
      "name": "Rock_Sandstone_Brick_Ornate",
      "rotation": 2
    },
    {
      "x": 2,
      "y": 20,
      "z": 3,
      "name": "Rock_Sandstone_Brick_Pillar_Base",
      "rotation": 2
    },
    {
      "x": 2,
      "y": 21,
      "z": 3,
      "name": "Rock_Sandstone_Brick_Pillar_Middle",
      "rotation": 2
    },
    {
      "x": 2,
      "y": 3,
      "z": 4,
      "name": "Rock_Sandstone_Cobble",
      "rotation": 2
    },
    {
      "x": 2,
      "y": 4,
      "z": 4,
      "name": "Wood_Drywood_Planks_Half",
      "rotation": 7
    },
    {
      "x": 2,
      "y": 5,
      "z": 4,
      "name": "Wood_Drywood_Planks_Half",
      "rotation": 7
    },
    {
      "x": 2,
      "y": 6,
      "z": 4,
      "name": "Wood_Drywood_Stairs",
      "rotation": 9
    },
    {
      "x": 2,
      "y": 7,
      "z": 4,
      "name": "Rock_Sandstone_Brick",
      "rotation": 2
    },
    {
      "x": 2,
      "y": 8,
      "z": 4,
      "name": "Rock_Sandstone_Brick_Pillar_Base",
      "rotation": 2
    },
    {
      "x": 2,
      "y": 9,
      "z": 4,
      "name": "Rock_Sandstone_Brick",
      "rotation": 2
    },
    {
      "x": 2,
      "y": 10,
      "z": 4,
      "name": "Rock_Sandstone_Cobble_Stairs"
    },
    {
      "x": 2,
      "y": 11,
      "z": 4,
      "name": "Rock_Sandstone_Cobble_Half",
      "rotation": 4
    },
    {
      "x": 2,
      "y": 14,
      "z": 4,
      "name": "Rock_Sandstone_Brick_Smooth_Half",
      "rotation": 5
    },
    {
      "x": 2,
      "y": 15,
      "z": 4,
      "name": "Rock_Sandstone_Brick_Smooth_Half",
      "rotation": 5
    },
    {
      "x": 2,
      "y": 3,
      "z": 5,
      "name": "Rock_Sandstone_Cobble_Stairs"
    },
    {
      "x": 3,
      "y": 3,
      "z": -4,
      "name": "Rock_Sandstone_Cobble",
      "rotation": 2
    },
    {
      "x": 3,
      "y": 4,
      "z": -4,
      "name": "Rock_Sandstone_Cobble",
      "rotation": 2
    },
    {
      "x": 3,
      "y": 5,
      "z": -4,
      "name": "Rock_Sandstone_Brick",
      "rotation": 2
    },
    {
      "x": 3,
      "y": 6,
      "z": -4,
      "name": "Rock_Sandstone_Brick",
      "rotation": 2
    },
    {
      "x": 3,
      "y": 7,
      "z": -4,
      "name": "Rock_Sandstone_Brick",
      "rotation": 2
    },
    {
      "x": 3,
      "y": 8,
      "z": -4,
      "name": "Rock_Sandstone_Brick_Pillar_Base",
      "rotation": 2
    },
    {
      "x": 3,
      "y": 9,
      "z": -4,
      "name": "Rock_Sandstone_Brick",
      "rotation": 2
    },
    {
      "x": 3,
      "y": 3,
      "z": -3,
      "name": "Rock_Sandstone_Cobble",
      "rotation": 2
    },
    {
      "x": 3,
      "y": 4,
      "z": -3,
      "name": "Rock_Sandstone_Brick",
      "rotation": 2
    },
    {
      "x": 3,
      "y": 5,
      "z": -3,
      "name": "Rock_Sandstone_Brick",
      "rotation": 2
    },
    {
      "x": 3,
      "y": 6,
      "z": -3,
      "name": "Rock_Sandstone_Brick",
      "rotation": 2
    },
    {
      "x": 3,
      "y": 7,
      "z": -3,
      "name": "Rock_Sandstone_Brick",
      "rotation": 2
    },
    {
      "x": 3,
      "y": 8,
      "z": -3,
      "name": "Rock_Sandstone_Brick",
      "rotation": 2
    },
    {
      "x": 3,
      "y": 9,
      "z": -3,
      "name": "Rock_Sandstone_Brick",
      "rotation": 2
    },
    {
      "x": 3,
      "y": 10,
      "z": -3,
      "name": "Rock_Sandstone_Brick_Pillar_Base",
      "rotation": 2
    },
    {
      "x": 3,
      "y": 11,
      "z": -3,
      "name": "Rock_Sandstone_Brick_Pillar_Middle",
      "rotation": 2
    },
    {
      "x": 3,
      "y": 12,
      "z": -3,
      "name": "Rock_Sandstone_Brick_Pillar_Base",
      "rotation": 10
    },
    {
      "x": 3,
      "y": 13,
      "z": -3,
      "name": "Rock_Sandstone_Brick_Pillar_Middle",
      "rotation": 2
    },
    {
      "x": 3,
      "y": 3,
      "z": -2,
      "name": "Rock_Sandstone_Cobble",
      "rotation": 2
    },
    {
      "x": 3,
      "y": 4,
      "z": -2,
      "name": "Rock_Sandstone_Cobble_Stairs",
      "rotation": 1
    },
    {
      "x": 3,
      "y": 8,
      "z": -2,
      "name": "Rock_Sandstone_Brick",
      "rotation": 2
    },
    {
      "x": 3,
      "y": 9,
      "z": -2,
      "name": "Rock_Sandstone_Brick",
      "rotation": 2
    },
    {
      "x": 3,
      "y": 10,
      "z": -2,
      "name": "Rock_Sandstone_Brick",
      "rotation": 2
    },
    {
      "x": 3,
      "y": 11,
      "z": -2,
      "name": "Rock_Sandstone_Cobble",
      "rotation": 2
    },
    {
      "x": 3,
      "y": 12,
      "z": -2,
      "name": "Rock_Sandstone_Brick",
      "rotation": 2
    },
    {
      "x": 3,
      "y": 13,
      "z": -2,
      "name": "Rock_Sandstone_Brick",
      "rotation": 2
    },
    {
      "x": 3,
      "y": 14,
      "z": -2,
      "name": "Rock_Sandstone_Brick",
      "rotation": 2
    },
    {
      "x": 3,
      "y": 24,
      "z": -2,
      "name": "Rock_Sandstone_Brick_Half",
      "rotation": 5
    },
    {
      "x": 3,
      "y": 25,
      "z": -2,
      "name": "Wood_Drywood_Planks_Half",
      "rotation": 5
    },
    {
      "x": 3,
      "y": 3,
      "z": -1,
      "name": "Rock_Sandstone_Cobble",
      "rotation": 2
    },
    {
      "x": 3,
      "y": 4,
      "z": -1,
      "name": "Rock_Sandstone_Cobble_Stairs",
      "rotation": 1
    },
    {
      "x": 3,
      "y": 8,
      "z": -1,
      "name": "Rock_Sandstone_Brick",
      "rotation": 2
    },
    {
      "x": 3,
      "y": 9,
      "z": -1,
      "name": "Rock_Sandstone_Cobble",
      "rotation": 2
    },
    {
      "x": 3,
      "y": 10,
      "z": -1,
      "name": "Rock_Sandstone_Cobble",
      "rotation": 2
    },
    {
      "x": 3,
      "y": 11,
      "z": -1,
      "name": "Rock_Sandstone_Cobble_Half",
      "rotation": 2
    },
    {
      "x": 3,
      "y": 19,
      "z": -1,
      "name": "Wood_Drywood_Beam",
      "rotation": 6
    },
    {
      "x": 3,
      "y": 25,
      "z": -1,
      "name": "Wood_Drywood_Planks",
      "rotation": 2
    },
    {
      "x": 3,
      "y": 3,
      "z": 0,
      "name": "Rock_Sandstone_Cobble",
      "rotation": 2
    },
    {
      "x": 3,
      "y": 8,
      "z": 0,
      "name": "Rock_Sandstone_Brick",
      "rotation": 2
    },
    {
      "x": 3,
      "y": 9,
      "z": 0,
      "name": "Rock_Sandstone_Cobble",
      "rotation": 2
    },
    {
      "x": 3,
      "y": 10,
      "z": 0,
      "name": "Rock_Sandstone_Cobble",
      "rotation": 2
    },
    {
      "x": 3,
      "y": 19,
      "z": 0,
      "name": "Wood_Drywood_Planks",
      "rotation": 2
    },
    {
      "x": 3,
      "y": 24,
      "z": 0,
      "name": "Rock_Sandstone_Brick",
      "rotation": 2
    },
    {
      "x": 3,
      "y": 25,
      "z": 0,
      "name": "Wood_Drywood_Planks",
      "rotation": 2
    },
    {
      "x": 3,
      "y": 3,
      "z": 1,
      "name": "Rock_Sandstone_Cobble",
      "rotation": 2
    },
    {
      "x": 3,
      "y": 8,
      "z": 1,
      "name": "Rock_Sandstone_Cobble",
      "rotation": 2
    },
    {
      "x": 3,
      "y": 9,
      "z": 1,
      "name": "Rock_Sandstone_Cobble",
      "rotation": 2
    },
    {
      "x": 3,
      "y": 10,
      "z": 1,
      "name": "Rock_Sandstone_Cobble_Half",
      "rotation": 2
    },
    {
      "x": 3,
      "y": 19,
      "z": 1,
      "name": "Wood_Drywood_Planks",
      "rotation": 2
    },
    {
      "x": 3,
      "y": 20,
      "z": 1,
      "name": "Rock_Sandstone_Brick_Smooth_Half",
      "rotation": 6
    },
    {
      "x": 3,
      "y": 21,
      "z": 1,
      "name": "Rock_Sandstone_Brick_Smooth_Half",
      "rotation": 6
    },
    {
      "x": 3,
      "y": 22,
      "z": 1,
      "name": "Rock_Sandstone_Brick_Smooth_Half",
      "rotation": 6
    },
    {
      "x": 3,
      "y": 23,
      "z": 1,
      "name": "Rock_Sandstone_Brick",
      "rotation": 2
    },
    {
      "x": 3,
      "y": 24,
      "z": 1,
      "name": "Rock_Sandstone_Brick",
      "rotation": 2
    },
    {
      "x": 3,
      "y": 25,
      "z": 1,
      "name": "Wood_Drywood_Planks",
      "rotation": 2
    },
    {
      "x": 3,
      "y": 3,
      "z": 2,
      "name": "Rock_Sandstone_Cobble",
      "rotation": 2
    },
    {
      "x": 3,
      "y": 8,
      "z": 2,
      "name": "Rock_Sandstone_Cobble",
      "rotation": 2
    },
    {
      "x": 3,
      "y": 9,
      "z": 2,
      "name": "Rock_Sandstone_Brick",
      "rotation": 2
    },
    {
      "x": 3,
      "y": 10,
      "z": 2,
      "name": "Rock_Sandstone_Cobble",
      "rotation": 2
    },
    {
      "x": 3,
      "y": 11,
      "z": 2,
      "name": "Rock_Sandstone_Cobble",
      "rotation": 2
    },
    {
      "x": 3,
      "y": 12,
      "z": 2,
      "name": "Rock_Sandstone_Brick",
      "rotation": 2
    },
    {
      "x": 3,
      "y": 13,
      "z": 2,
      "name": "Rock_Sandstone_Brick",
      "rotation": 2
    },
    {
      "x": 3,
      "y": 14,
      "z": 2,
      "name": "Rock_Sandstone_Brick",
      "rotation": 2
    },
    {
      "x": 3,
      "y": 15,
      "z": 2,
      "name": "Rock_Sandstone_Brick",
      "rotation": 2
    },
    {
      "x": 3,
      "y": 16,
      "z": 2,
      "name": "Rock_Sandstone_Brick",
      "rotation": 2
    },
    {
      "x": 3,
      "y": 17,
      "z": 2,
      "name": "Rock_Sandstone_Brick",
      "rotation": 2
    },
    {
      "x": 3,
      "y": 18,
      "z": 2,
      "name": "Rock_Sandstone_Brick",
      "rotation": 2
    },
    {
      "x": 3,
      "y": 19,
      "z": 2,
      "name": "Rock_Sandstone_Brick_Ornate",
      "rotation": 2
    },
    {
      "x": 3,
      "y": 20,
      "z": 2,
      "name": "Rock_Sandstone_Brick",
      "rotation": 2
    },
    {
      "x": 3,
      "y": 21,
      "z": 2,
      "name": "Rock_Sandstone_Brick",
      "rotation": 2
    },
    {
      "x": 3,
      "y": 22,
      "z": 2,
      "name": "Rock_Sandstone_Brick",
      "rotation": 2
    },
    {
      "x": 3,
      "y": 23,
      "z": 2,
      "name": "Rock_Sandstone_Brick_Half",
      "rotation": 4
    },
    {
      "x": 3,
      "y": 24,
      "z": 2,
      "name": "Rock_Sandstone_Brick_Half",
      "rotation": 4
    },
    {
      "x": 3,
      "y": 25,
      "z": 2,
      "name": "Wood_Drywood_Beam",
      "rotation": 6
    },
    {
      "x": 3,
      "y": 3,
      "z": 3,
      "name": "Rock_Sandstone_Cobble",
      "rotation": 2
    },
    {
      "x": 3,
      "y": 8,
      "z": 3,
      "name": "Rock_Sandstone_Brick",
      "rotation": 2
    },
    {
      "x": 3,
      "y": 9,
      "z": 3,
      "name": "Rock_Sandstone_Brick",
      "rotation": 2
    },
    {
      "x": 3,
      "y": 10,
      "z": 3,
      "name": "Rock_Sandstone_Brick_Pillar_Base",
      "rotation": 2
    },
    {
      "x": 3,
      "y": 11,
      "z": 3,
      "name": "Rock_Sandstone_Brick_Pillar_Middle",
      "rotation": 2
    },
    {
      "x": 3,
      "y": 12,
      "z": 3,
      "name": "Rock_Sandstone_Brick_Pillar_Base",
      "rotation": 10
    },
    {
      "x": 3,
      "y": 13,
      "z": 3,
      "name": "Rock_Sandstone_Brick_Pillar_Middle",
      "rotation": 2
    },
    {
      "x": 3,
      "y": 14,
      "z": 3,
      "name": "Rock_Sandstone_Brick_Pillar_Middle",
      "rotation": 2
    },
    {
      "x": 3,
      "y": 15,
      "z": 3,
      "name": "Rock_Sandstone_Brick_Pillar_Middle",
      "rotation": 2
    },
    {
      "x": 3,
      "y": 16,
      "z": 3,
      "name": "Rock_Sandstone_Brick_Pillar_Middle",
      "rotation": 2
    },
    {
      "x": 3,
      "y": 17,
      "z": 3,
      "name": "Rock_Sandstone_Brick_Pillar_Base",
      "rotation": 10
    },
    {
      "x": 3,
      "y": 18,
      "z": 3,
      "name": "Rock_Sandstone_Brick_Half",
      "rotation": 2
    },
    {
      "x": 3,
      "y": 3,
      "z": 4,
      "name": "Rock_Sandstone_Cobble",
      "rotation": 2
    },
    {
      "x": 3,
      "y": 4,
      "z": 4,
      "name": "Rock_Sandstone_Cobble",
      "rotation": 2
    },
    {
      "x": 3,
      "y": 5,
      "z": 4,
      "name": "Rock_Sandstone_Cobble",
      "rotation": 2
    },
    {
      "x": 3,
      "y": 6,
      "z": 4,
      "name": "Rock_Sandstone_Brick",
      "rotation": 2
    },
    {
      "x": 3,
      "y": 7,
      "z": 4,
      "name": "Rock_Sandstone_Brick",
      "rotation": 2
    },
    {
      "x": 3,
      "y": 8,
      "z": 4,
      "name": "Rock_Sandstone_Brick_Pillar_Base",
      "rotation": 2
    },
    {
      "x": 3,
      "y": 9,
      "z": 4,
      "name": "Rock_Sandstone_Brick",
      "rotation": 2
    },
    {
      "x": 4,
      "y": 3,
      "z": -4,
      "name": "Rock_Sandstone_Cobble",
      "rotation": 2
    },
    {
      "x": 4,
      "y": 4,
      "z": -4,
      "name": "Rock_Sandstone_Cobble",
      "rotation": 2
    },
    {
      "x": 4,
      "y": 5,
      "z": -4,
      "name": "Rock_Sandstone_Cobble",
      "rotation": 2
    },
    {
      "x": 4,
      "y": 6,
      "z": -4,
      "name": "Rock_Sandstone_Brick",
      "rotation": 2
    },
    {
      "x": 4,
      "y": 7,
      "z": -4,
      "name": "Rock_Sandstone_Brick",
      "rotation": 2
    },
    {
      "x": 4,
      "y": 8,
      "z": -4,
      "name": "Rock_Sandstone_Brick_Pillar_Base",
      "rotation": 2
    },
    {
      "x": 4,
      "y": 9,
      "z": -4,
      "name": "Rock_Sandstone_Brick_Half",
      "rotation": 2
    },
    {
      "x": 4,
      "y": 3,
      "z": -3,
      "name": "Rock_Sandstone_Cobble",
      "rotation": 2
    },
    {
      "x": 4,
      "y": 4,
      "z": -3,
      "name": "Rock_Sandstone_Cobble",
      "rotation": 2
    },
    {
      "x": 4,
      "y": 5,
      "z": -3,
      "name": "Rock_Sandstone_Brick",
      "rotation": 2
    },
    {
      "x": 4,
      "y": 6,
      "z": -3,
      "name": "Rock_Sandstone_Brick",
      "rotation": 2
    },
    {
      "x": 4,
      "y": 7,
      "z": -3,
      "name": "Rock_Sandstone_Brick",
      "rotation": 2
    },
    {
      "x": 4,
      "y": 8,
      "z": -3,
      "name": "Rock_Sandstone_Brick",
      "rotation": 2
    },
    {
      "x": 4,
      "y": 9,
      "z": -3,
      "name": "Rock_Sandstone_Brick",
      "rotation": 2
    },
    {
      "x": 4,
      "y": 3,
      "z": -2,
      "name": "Rock_Sandstone_Cobble",
      "rotation": 2
    },
    {
      "x": 4,
      "y": 8,
      "z": -2,
      "name": "Rock_Sandstone_Brick",
      "rotation": 2
    },
    {
      "x": 4,
      "y": 9,
      "z": -2,
      "name": "Rock_Sandstone_Brick",
      "rotation": 2
    },
    {
      "x": 4,
      "y": 10,
      "z": -2,
      "name": "Rock_Sandstone_Brick_Pillar_Base",
      "rotation": 2
    },
    {
      "x": 4,
      "y": 11,
      "z": -2,
      "name": "Rock_Sandstone_Brick_Pillar_Middle",
      "rotation": 2
    },
    {
      "x": 4,
      "y": 12,
      "z": -2,
      "name": "Rock_Sandstone_Brick_Pillar_Base",
      "rotation": 10
    },
    {
      "x": 4,
      "y": 13,
      "z": -2,
      "name": "Rock_Sandstone_Brick_Pillar_Middle",
      "rotation": 2
    },
    {
      "x": 4,
      "y": 14,
      "z": -2,
      "name": "Rock_Sandstone_Brick_Pillar_Middle",
      "rotation": 2
    },
    {
      "x": 4,
      "y": 15,
      "z": -2,
      "name": "Rock_Sandstone_Brick_Pillar_Middle",
      "rotation": 2
    },
    {
      "x": 4,
      "y": 3,
      "z": -1,
      "name": "Rock_Sandstone_Cobble",
      "rotation": 2
    },
    {
      "x": 4,
      "y": 8,
      "z": -1,
      "name": "Rock_Sandstone_Brick",
      "rotation": 2
    },
    {
      "x": 4,
      "y": 9,
      "z": -1,
      "name": "Rock_Sandstone_Cobble",
      "rotation": 2
    },
    {
      "x": 4,
      "y": 10,
      "z": -1,
      "name": "Rock_Sandstone_Cobble",
      "rotation": 2
    },
    {
      "x": 4,
      "y": 11,
      "z": -1,
      "name": "Rock_Sandstone_Cobble",
      "rotation": 2
    },
    {
      "x": 4,
      "y": 12,
      "z": -1,
      "name": "Rock_Sandstone_Brick",
      "rotation": 2
    },
    {
      "x": 4,
      "y": 13,
      "z": -1,
      "name": "Rock_Sandstone_Brick",
      "rotation": 2
    },
    {
      "x": 4,
      "y": 14,
      "z": -1,
      "name": "Rock_Sandstone_Brick",
      "rotation": 2
    },
    {
      "x": 4,
      "y": 15,
      "z": -1,
      "name": "Rock_Sandstone_Brick",
      "rotation": 2
    },
    {
      "x": 4,
      "y": 16,
      "z": -1,
      "name": "Rock_Sandstone_Brick",
      "rotation": 2
    },
    {
      "x": 4,
      "y": 18,
      "z": -1,
      "name": "Rock_Sandstone_Brick_Half",
      "rotation": 6
    },
    {
      "x": 4,
      "y": 19,
      "z": -1,
      "name": "Rock_Sandstone_Brick_Half",
      "rotation": 6
    },
    {
      "x": 4,
      "y": 3,
      "z": 0,
      "name": "Rock_Sandstone_Cobble",
      "rotation": 2
    },
    {
      "x": 4,
      "y": 8,
      "z": 0,
      "name": "Rock_Sandstone_Brick_Half",
      "rotation": 10
    },
    {
      "x": 4,
      "y": 9,
      "z": 0,
      "name": "Rock_Sandstone_Brick",
      "rotation": 2
    },
    {
      "x": 4,
      "y": 10,
      "z": 0,
      "name": "Rock_Sandstone_Cobble",
      "rotation": 2
    },
    {
      "x": 4,
      "y": 11,
      "z": 0,
      "name": "Rock_Sandstone_Cobble",
      "rotation": 2
    },
    {
      "x": 4,
      "y": 12,
      "z": 0,
      "name": "Rock_Sandstone_Brick",
      "rotation": 2
    },
    {
      "x": 4,
      "y": 13,
      "z": 0,
      "name": "Rock_Sandstone_Brick",
      "rotation": 2
    },
    {
      "x": 4,
      "y": 14,
      "z": 0,
      "name": "Furniture_Desert_Window",
      "rotation": 3
    },
    {
      "x": 4,
      "y": 15,
      "z": 0,
      "name": "Furniture_Desert_Window",
      "rotation": 3
    },
    {
      "x": 4,
      "y": 16,
      "z": 0,
      "name": "Rock_Sandstone_Brick",
      "rotation": 2
    },
    {
      "x": 4,
      "y": 17,
      "z": 0,
      "name": "Rock_Sandstone_Brick",
      "rotation": 2
    },
    {
      "x": 4,
      "y": 18,
      "z": 0,
      "name": "Rock_Sandstone_Brick",
      "rotation": 2
    },
    {
      "x": 4,
      "y": 19,
      "z": 0,
      "name": "Rock_Sandstone_Brick_Ornate",
      "rotation": 2
    },
    {
      "x": 4,
      "y": 24,
      "z": 0,
      "name": "Rock_Sandstone_Brick_Half",
      "rotation": 5
    },
    {
      "x": 4,
      "y": 3,
      "z": 1,
      "name": "Rock_Sandstone_Cobble",
      "rotation": 2
    },
    {
      "x": 4,
      "y": 8,
      "z": 1,
      "name": "Rock_Sandstone_Brick_Half",
      "rotation": 10
    },
    {
      "x": 4,
      "y": 9,
      "z": 1,
      "name": "Rock_Sandstone_Brick",
      "rotation": 2
    },
    {
      "x": 4,
      "y": 10,
      "z": 1,
      "name": "Rock_Sandstone_Cobble",
      "rotation": 2
    },
    {
      "x": 4,
      "y": 11,
      "z": 1,
      "name": "Rock_Sandstone_Cobble",
      "rotation": 2
    },
    {
      "x": 4,
      "y": 12,
      "z": 1,
      "name": "Rock_Sandstone_Brick",
      "rotation": 2
    },
    {
      "x": 4,
      "y": 13,
      "z": 1,
      "name": "Rock_Sandstone_Brick",
      "rotation": 2
    },
    {
      "x": 4,
      "y": 14,
      "z": 1,
      "name": "Rock_Sandstone_Brick",
      "rotation": 2
    },
    {
      "x": 4,
      "y": 15,
      "z": 1,
      "name": "Rock_Sandstone_Brick",
      "rotation": 2
    },
    {
      "x": 4,
      "y": 16,
      "z": 1,
      "name": "Rock_Sandstone_Brick",
      "rotation": 2
    },
    {
      "x": 4,
      "y": 17,
      "z": 1,
      "name": "Rock_Sandstone_Brick",
      "rotation": 2
    },
    {
      "x": 4,
      "y": 18,
      "z": 1,
      "name": "Rock_Sandstone_Brick",
      "rotation": 2
    },
    {
      "x": 4,
      "y": 19,
      "z": 1,
      "name": "Rock_Sandstone_Brick_Ornate",
      "rotation": 2
    },
    {
      "x": 4,
      "y": 20,
      "z": 1,
      "name": "Rock_Sandstone_Brick_Pillar_Base",
      "rotation": 2
    },
    {
      "x": 4,
      "y": 21,
      "z": 1,
      "name": "Rock_Sandstone_Brick_Pillar_Middle",
      "rotation": 2
    },
    {
      "x": 4,
      "y": 22,
      "z": 1,
      "name": "Rock_Sandstone_Brick_Pillar_Base",
      "rotation": 10
    },
    {
      "x": 4,
      "y": 23,
      "z": 1,
      "name": "Rock_Sandstone_Brick_Ornate",
      "rotation": 2
    },
    {
      "x": 4,
      "y": 24,
      "z": 1,
      "name": "Rock_Sandstone_Brick",
      "rotation": 2
    },
    {
      "x": 4,
      "y": 3,
      "z": 2,
      "name": "Rock_Sandstone_Cobble",
      "rotation": 2
    },
    {
      "x": 4,
      "y": 8,
      "z": 2,
      "name": "Rock_Sandstone_Brick",
      "rotation": 2
    },
    {
      "x": 4,
      "y": 9,
      "z": 2,
      "name": "Rock_Sandstone_Brick",
      "rotation": 2
    },
    {
      "x": 4,
      "y": 10,
      "z": 2,
      "name": "Rock_Sandstone_Brick_Pillar_Base",
      "rotation": 2
    },
    {
      "x": 4,
      "y": 11,
      "z": 2,
      "name": "Rock_Sandstone_Brick_Pillar_Middle",
      "rotation": 2
    },
    {
      "x": 4,
      "y": 12,
      "z": 2,
      "name": "Rock_Sandstone_Brick_Pillar_Base",
      "rotation": 10
    },
    {
      "x": 4,
      "y": 13,
      "z": 2,
      "name": "Rock_Sandstone_Brick_Pillar_Middle",
      "rotation": 2
    },
    {
      "x": 4,
      "y": 14,
      "z": 2,
      "name": "Rock_Sandstone_Brick_Pillar_Middle",
      "rotation": 2
    },
    {
      "x": 4,
      "y": 15,
      "z": 2,
      "name": "Rock_Sandstone_Brick_Pillar_Middle",
      "rotation": 2
    },
    {
      "x": 4,
      "y": 16,
      "z": 2,
      "name": "Rock_Sandstone_Brick_Pillar_Middle",
      "rotation": 2
    },
    {
      "x": 4,
      "y": 17,
      "z": 2,
      "name": "Rock_Sandstone_Brick_Pillar_Base",
      "rotation": 10
    },
    {
      "x": 4,
      "y": 18,
      "z": 2,
      "name": "Rock_Sandstone_Brick_Stairs",
      "rotation": 1
    },
    {
      "x": 4,
      "y": 19,
      "z": 2,
      "name": "Rock_Sandstone_Brick_Ornate",
      "rotation": 2
    },
    {
      "x": 4,
      "y": 3,
      "z": 3,
      "name": "Rock_Sandstone_Cobble",
      "rotation": 2
    },
    {
      "x": 4,
      "y": 8,
      "z": 3,
      "name": "Rock_Sandstone_Brick",
      "rotation": 2
    },
    {
      "x": 4,
      "y": 9,
      "z": 3,
      "name": "Rock_Sandstone_Brick",
      "rotation": 2
    },
    {
      "x": 4,
      "y": 10,
      "z": 3,
      "name": "Plant_Bush_Arid_Sharp",
