{
  "version": 8,
  "blockIdVersion": 11,
  "anchorX": 1,
  "anchorY": 4,
  "anchorZ": 1,
  "blocks": [
    {
      "x": -8,
      "y": 5,
      "z": -9,
      "name": "Soil_Clay_GreyLight",
      "rotation": 33
    },
    {
      "x": -8,
      "y": 6,
      "z": -9,
      "name": "Rock_Marble",
      "rotation": 33
    },
    {
      "x": -8,
      "y": 4,
      "z": -8,
      "name": "Rock_Marble_Cobble",
      "rotation": 33
    },
    {
      "x": -8,
      "y": 5,
      "z": -8,
      "name": "Soil_Clay_GreyLight",
      "rotation": 33
    },
    {
      "x": -8,
      "y": 6,
      "z": -8,
      "name": "Rock_Marble",
      "rotation": 33
    },
    {
      "x": -8,
      "y": 7,
      "z": -8,
      "name": "Soil_Clay_White",
      "rotation": 33
    },
    {
      "x": -8,
      "y": 8,
      "z": -8,
      "name": "Rock_Marble",
      "rotation": 33
    },
    {
      "x": -8,
      "y": 9,
      "z": -8,
      "name": "Soil_Clay_White",
      "rotation": 33
    },
    {
      "x": -8,
      "y": 4,
      "z": -7,
      "name": "Rock_Marble_Cobble",
      "rotation": 33
    },
    {
      "x": -8,
      "y": 5,
      "z": -7,
      "name": "Soil_Clay_GreyLight",
      "rotation": 33
    },
    {
      "x": -8,
      "y": 6,
      "z": -7,
      "name": "Rock_Marble",
      "rotation": 33
    },
    {
      "x": -8,
      "y": 7,
      "z": -7,
      "name": "Soil_Clay_White",
      "rotation": 33
    },
    {
      "x": -8,
      "y": 8,
      "z": -7,
      "name": "Rock_Marble",
      "rotation": 33
    },
    {
      "x": -8,
      "y": 9,
      "z": -7,
      "name": "Soil_Clay_White",
      "rotation": 33
    },
    {
      "x": -8,
      "y": 10,
      "z": -7,
      "name": "Rock_Chalk",
      "rotation": 33
    },
    {
      "x": -8,
      "y": 11,
      "z": -7,
      "name": "Rock_Chalk",
      "rotation": 33
    },
    {
      "x": -8,
      "y": 12,
      "z": -7,
      "name": "Rock_Chalk",
      "rotation": 33
    },
    {
      "x": -8,
      "y": 13,
      "z": -7,
      "name": "Rock_Marble",
      "rotation": 33
    },
    {
      "x": -8,
      "y": 14,
      "z": -7,
      "name": "Rock_Marble_Cobble",
      "rotation": 33
    },
    {
      "x": -8,
      "y": 5,
      "z": -6,
      "name": "Soil_Clay_GreyLight",
      "rotation": 33
    },
    {
      "x": -8,
      "y": 6,
      "z": -6,
      "name": "Rock_Marble",
      "rotation": 33
    },
    {
      "x": -8,
      "y": 7,
      "z": -6,
      "name": "Soil_Clay_White",
      "rotation": 33
    },
    {
      "x": -8,
      "y": 8,
      "z": -6,
      "name": "Rock_Marble",
      "rotation": 33
    },
    {
      "x": -8,
      "y": 9,
      "z": -6,
      "name": "Soil_Clay_White",
      "rotation": 33
    },
    {
      "x": -8,
      "y": 10,
      "z": -6,
      "name": "Rock_Chalk",
      "rotation": 33
    },
    {
      "x": -8,
      "y": 11,
      "z": -6,
      "name": "Rock_Chalk",
      "rotation": 33
    },
    {
      "x": -8,
      "y": 12,
      "z": -6,
      "name": "Rock_Chalk",
      "rotation": 33
    },
    {
      "x": -8,
      "y": 13,
      "z": -6,
      "name": "Rock_Marble",
      "rotation": 33
    },
    {
      "x": -8,
      "y": 14,
      "z": -6,
      "name": "Rock_Marble_Cobble",
      "rotation": 33
    },
    {
      "x": -8,
      "y": 6,
      "z": -5,
      "name": "Rock_Marble",
      "rotation": 33
    },
    {
      "x": -8,
      "y": 7,
      "z": -5,
      "name": "Soil_Clay_White",
      "rotation": 33
    },
    {
      "x": -7,
      "y": 3,
      "z": -10,
      "name": "Soil_Clay_White",
      "rotation": 33
    },
    {
      "x": -7,
      "y": 4,
      "z": -10,
      "name": "Rock_Marble_Cobble",
      "rotation": 33
    },
    {
      "x": -7,
      "y": 5,
      "z": -10,
      "name": "Soil_Clay_GreyLight",
      "rotation": 33
    },
    {
      "x": -7,
      "y": 6,
      "z": -10,
      "name": "Rock_Marble",
      "rotation": 33
    },
    {
      "x": -7,
      "y": 7,
      "z": -10,
      "name": "Soil_Clay_White",
      "rotation": 33
    },
    {
      "x": -7,
      "y": 2,
      "z": -9,
      "name": "Rock_Marble",
      "rotation": 33
    },
    {
      "x": -7,
      "y": 3,
      "z": -9,
      "name": "Soil_Clay_White",
      "rotation": 33
    },
    {
      "x": -7,
      "y": 4,
      "z": -9,
      "name": "Rock_Marble_Cobble",
      "rotation": 33
    },
    {
      "x": -7,
      "y": 5,
      "z": -9,
      "name": "Soil_Clay_GreyLight",
      "rotation": 33
    },
    {
      "x": -7,
      "y": 6,
      "z": -9,
      "name": "Rock_Marble",
      "rotation": 33
    },
    {
      "x": -7,
      "y": 7,
      "z": -9,
      "name": "Soil_Clay_White",
      "rotation": 33
    },
    {
      "x": -7,
      "y": 8,
      "z": -9,
      "name": "Rock_Marble",
      "rotation": 33
    },
    {
      "x": -7,
      "y": 9,
      "z": -9,
      "name": "Soil_Clay_White",
      "rotation": 33
    },
    {
      "x": -7,
      "y": 10,
      "z": -9,
      "name": "Rock_Chalk",
      "rotation": 33
    },
    {
      "x": -7,
      "y": 11,
      "z": -9,
      "name": "Rock_Chalk",
      "rotation": 33
    },
    {
      "x": -7,
      "y": 12,
      "z": -9,
      "name": "Rock_Chalk",
      "rotation": 33
    },
    {
      "x": -7,
      "y": 13,
      "z": -9,
      "name": "Rock_Marble",
      "rotation": 33
    },
    {
      "x": -7,
      "y": 2,
      "z": -8,
      "name": "Rock_Marble",
      "rotation": 33
    },
    {
      "x": -7,
      "y": 3,
      "z": -8,
      "name": "Soil_Clay_White",
      "rotation": 33
    },
    {
      "x": -7,
      "y": 4,
      "z": -8,
      "name": "Rock_Marble_Cobble",
      "rotation": 33
    },
    {
      "x": -7,
      "y": 5,
      "z": -8,
      "name": "Soil_Clay_GreyLight",
      "rotation": 33
    },
    {
      "x": -7,
      "y": 6,
      "z": -8,
      "name": "Rock_Marble",
      "rotation": 33
    },
    {
      "x": -7,
      "y": 7,
      "z": -8,
      "name": "Soil_Clay_White",
      "rotation": 33
    },
    {
      "x": -7,
      "y": 8,
      "z": -8,
      "name": "Rock_Marble",
      "rotation": 33
    },
    {
      "x": -7,
      "y": 9,
      "z": -8,
      "name": "Soil_Clay_White",
      "rotation": 33
    },
    {
      "x": -7,
      "y": 10,
      "z": -8,
      "name": "Rock_Chalk",
      "rotation": 33
    },
    {
      "x": -7,
      "y": 11,
      "z": -8,
      "name": "Rock_Chalk",
      "rotation": 33
    },
    {
      "x": -7,
      "y": 12,
      "z": -8,
      "name": "Rock_Chalk",
      "rotation": 33
    },
    {
      "x": -7,
      "y": 13,
      "z": -8,
      "name": "Rock_Marble",
      "rotation": 33
    },
    {
      "x": -7,
      "y": 14,
      "z": -8,
      "name": "Rock_Marble_Cobble",
      "rotation": 33
    },
    {
      "x": -7,
      "y": 15,
      "z": -8,
      "name": "Rock_Marble",
      "rotation": 33
    },
    {
      "x": -7,
      "y": 16,
      "z": -8,
      "name": "Soil_Clay_White",
      "rotation": 33
    },
    {
      "x": -7,
      "y": 17,
      "z": -8,
      "name": "Rock_Marble",
      "rotation": 33
    },
    {
      "x": -7,
      "y": 2,
      "z": -7,
      "name": "Rock_Marble",
      "rotation": 33
    },
    {
      "x": -7,
      "y": 3,
      "z": -7,
      "name": "Soil_Clay_White",
      "rotation": 33
    },
    {
      "x": -7,
      "y": 4,
      "z": -7,
      "name": "Rock_Marble_Cobble",
      "rotation": 33
    },
    {
      "x": -7,
      "y": 5,
      "z": -7,
      "name": "Soil_Clay_GreyLight",
      "rotation": 33
    },
    {
      "x": -7,
      "y": 6,
      "z": -7,
      "name": "Rock_Marble",
      "rotation": 33
    },
    {
      "x": -7,
      "y": 7,
      "z": -7,
      "name": "Soil_Clay_White",
      "rotation": 33
    },
    {
      "x": -7,
      "y": 8,
      "z": -7,
      "name": "Rock_Marble",
      "rotation": 33
    },
    {
      "x": -7,
      "y": 9,
      "z": -7,
      "name": "Soil_Clay_White",
      "rotation": 33
    },
    {
      "x": -7,
      "y": 10,
      "z": -7,
      "name": "Rock_Chalk",
      "rotation": 33
    },
    {
      "x": -7,
      "y": 11,
      "z": -7,
      "name": "Rock_Chalk",
      "rotation": 33
    },
    {
      "x": -7,
      "y": 12,
      "z": -7,
      "name": "Rock_Chalk",
      "rotation": 33
    },
    {
      "x": -7,
      "y": 13,
      "z": -7,
      "name": "Rock_Marble",
      "rotation": 33
    },
    {
      "x": -7,
      "y": 14,
      "z": -7,
      "name": "Rock_Marble_Cobble",
      "rotation": 33
    },
    {
      "x": -7,
      "y": 15,
      "z": -7,
      "name": "Rock_Marble",
      "rotation": 33
    },
    {
      "x": -7,
      "y": 16,
      "z": -7,
      "name": "Soil_Clay_White",
      "rotation": 33
    },
    {
      "x": -7,
      "y": 17,
      "z": -7,
      "name": "Rock_Marble",
      "rotation": 33
    },
    {
      "x": -7,
      "y": 18,
      "z": -7,
      "name": "Soil_Clay_White",
      "rotation": 33
    },
    {
      "x": -7,
      "y": 19,
      "z": -7,
      "name": "Soil_Clay_White",
      "rotation": 33
    },
    {
      "x": -7,
      "y": 20,
      "z": -7,
      "name": "Rock_Marble",
      "rotation": 33
    },
    {
      "x": -7,
      "y": 2,
      "z": -6,
      "name": "Rock_Marble",
      "rotation": 33
    },
    {
      "x": -7,
      "y": 3,
      "z": -6,
      "name": "Soil_Clay_White",
      "rotation": 33
    },
    {
      "x": -7,
      "y": 4,
      "z": -6,
      "name": "Rock_Marble_Cobble",
      "rotation": 33
    },
    {
      "x": -7,
      "y": 5,
      "z": -6,
      "name": "Soil_Clay_GreyLight",
      "rotation": 33
    },
    {
      "x": -7,
      "y": 6,
      "z": -6,
      "name": "Rock_Marble",
      "rotation": 33
    },
    {
      "x": -7,
      "y": 7,
      "z": -6,
      "name": "Soil_Clay_White",
      "rotation": 33
    },
    {
      "x": -7,
      "y": 8,
      "z": -6,
      "name": "Rock_Marble",
      "rotation": 33
    },
    {
      "x": -7,
      "y": 9,
      "z": -6,
      "name": "Soil_Clay_White",
      "rotation": 33
    },
    {
      "x": -7,
      "y": 10,
      "z": -6,
      "name": "Rock_Chalk",
      "rotation": 33
    },
    {
      "x": -7,
      "y": 11,
      "z": -6,
      "name": "Rock_Chalk",
      "rotation": 33
    },
    {
      "x": -7,
      "y": 12,
      "z": -6,
      "name": "Rock_Chalk",
      "rotation": 33
    },
    {
      "x": -7,
      "y": 13,
      "z": -6,
      "name": "Rock_Marble",
      "rotation": 33
    },
    {
      "x": -7,
      "y": 14,
      "z": -6,
      "name": "Rock_Marble_Cobble",
      "rotation": 33
    },
    {
      "x": -7,
      "y": 15,
      "z": -6,
      "name": "Rock_Marble",
      "rotation": 33
    },
    {
      "x": -7,
      "y": 16,
      "z": -6,
      "name": "Soil_Clay_White",
      "rotation": 33
    },
    {
      "x": -7,
      "y": 17,
      "z": -6,
      "name": "Rock_Marble",
      "rotation": 33
    },
    {
      "x": -7,
      "y": 18,
      "z": -6,
      "name": "Soil_Clay_White",
      "rotation": 33
    },
    {
      "x": -7,
      "y": 19,
      "z": -6,
      "name": "Soil_Clay_White",
      "rotation": 33
    },
    {
      "x": -7,
      "y": 20,
      "z": -6,
      "name": "Rock_Marble",
      "rotation": 33
    },
    {
      "x": -7,
      "y": 21,
      "z": -6,
      "name": "Rock_Marble",
      "rotation": 33
    },
    {
      "x": -7,
      "y": 3,
      "z": -5,
      "name": "Soil_Clay_White",
      "rotation": 33
    },
    {
      "x": -7,
      "y": 4,
      "z": -5,
      "name": "Rock_Marble_Cobble",
      "rotation": 33
    },
    {
      "x": -7,
      "y": 5,
      "z": -5,
      "name": "Soil_Clay_GreyLight",
      "rotation": 33
    },
    {
      "x": -7,
      "y": 6,
      "z": -5,
      "name": "Rock_Marble",
      "rotation": 33
    },
    {
      "x": -7,
      "y": 7,
      "z": -5,
      "name": "Soil_Clay_White",
      "rotation": 33
    },
    {
      "x": -7,
      "y": 8,
      "z": -5,
      "name": "Rock_Marble",
      "rotation": 33
    },
    {
      "x": -7,
      "y": 9,
      "z": -5,
      "name": "Soil_Clay_White",
      "rotation": 33
    },
    {
      "x": -7,
      "y": 10,
      "z": -5,
      "name": "Rock_Chalk",
      "rotation": 33
    },
    {
      "x": -7,
      "y": 11,
      "z": -5,
      "name": "Rock_Chalk",
      "rotation": 33
    },
    {
      "x": -7,
      "y": 12,
      "z": -5,
      "name": "Rock_Chalk",
      "rotation": 33
    },
    {
      "x": -7,
      "y": 13,
      "z": -5,
      "name": "Rock_Marble",
      "rotation": 33
    },
    {
      "x": -7,
      "y": 14,
      "z": -5,
      "name": "Rock_Marble_Cobble",
      "rotation": 33
    },
    {
      "x": -7,
      "y": 15,
      "z": -5,
      "name": "Rock_Marble",
      "rotation": 33
    },
    {
      "x": -7,
      "y": 16,
      "z": -5,
      "name": "Soil_Clay_White",
      "rotation": 33
    },
    {
      "x": -7,
      "y": 17,
      "z": -5,
      "name": "Rock_Marble",
      "rotation": 33
    },
    {
      "x": -7,
      "y": 18,
      "z": -5,
      "name": "Soil_Clay_White",
      "rotation": 33
    },
    {
      "x": -7,
      "y": 19,
      "z": -5,
      "name": "Soil_Clay_White",
      "rotation": 33
    },
    {
      "x": -7,
      "y": 4,
      "z": -4,
      "name": "Rock_Marble_Cobble",
      "rotation": 33
    },
    {
      "x": -7,
      "y": 5,
      "z": -4,
      "name": "Soil_Clay_GreyLight",
      "rotation": 33
    },
    {
      "x": -7,
      "y": 6,
      "z": -4,
      "name": "Rock_Marble",
      "rotation": 33
    },
    {
      "x": -7,
      "y": 7,
      "z": -4,
      "name": "Soil_Clay_White",
      "rotation": 33
    },
    {
      "x": -7,
      "y": 8,
      "z": -4,
      "name": "Rock_Marble",
      "rotation": 33
    },
    {
      "x": -7,
      "y": 12,
      "z": -4,
      "name": "Rock_Chalk",
      "rotation": 33
    },
    {
      "x": -7,
      "y": 13,
      "z": -4,
      "name": "Rock_Marble",
      "rotation": 33
    },
    {
      "x": -7,
      "y": 14,
      "z": -4,
      "name": "Rock_Marble_Cobble",
      "rotation": 33
    },
    {
      "x": -6,
      "y": 2,
      "z": -10,
      "name": "Rock_Marble",
      "rotation": 33
    },
    {
      "x": -6,
      "y": 3,
      "z": -10,
      "name": "Soil_Clay_White",
      "rotation": 33
    },
    {
      "x": -6,
      "y": 4,
      "z": -10,
      "name": "Rock_Marble_Cobble",
      "rotation": 33
    },
    {
      "x": -6,
      "y": 5,
      "z": -10,
      "name": "Soil_Clay_GreyLight",
      "rotation": 33
    },
    {
      "x": -6,
      "y": 6,
      "z": -10,
      "name": "Rock_Marble",
      "rotation": 33
    },
    {
      "x": -6,
      "y": 7,
      "z": -10,
      "name": "Soil_Clay_White",
      "rotation": 33
    },
    {
      "x": -6,
      "y": 8,
      "z": -10,
      "name": "Rock_Marble",
      "rotation": 33
    },
    {
      "x": -6,
      "y": 9,
      "z": -10,
      "name": "Soil_Clay_White",
      "rotation": 33
    },
    {
      "x": -6,
      "y": 10,
      "z": -10,
      "name": "Rock_Chalk",
      "rotation": 33
    },
    {
      "x": -6,
      "y": 11,
      "z": -10,
      "name": "Rock_Chalk",
      "rotation": 33
    },
    {
      "x": -6,
      "y": 12,
      "z": -10,
      "name": "Rock_Chalk",
      "rotation": 33
    },
    {
      "x": -6,
      "y": 1,
      "z": -9,
      "name": "Rock_Marble_Cobble",
      "rotation": 33
    },
    {
      "x": -6,
      "y": 2,
      "z": -9,
      "name": "Rock_Marble",
      "rotation": 33
    },
    {
      "x": -6,
      "y": 3,
      "z": -9,
      "name": "Soil_Clay_White",
      "rotation": 33
    },
    {
      "x": -6,
      "y": 4,
      "z": -9,
      "name": "Rock_Marble_Cobble",
      "rotation": 33
    },
    {
      "x": -6,
      "y": 5,
      "z": -9,
      "name": "Soil_Clay_GreyLight",
      "rotation": 33
    },
    {
      "x": -6,
      "y": 6,
      "z": -9,
      "name": "Rock_Marble",
      "rotation": 33
    },
    {
      "x": -6,
      "y": 7,
      "z": -9,
      "name": "Soil_Clay_White",
      "rotation": 33
    },
    {
      "x": -6,
      "y": 8,
      "z": -9,
      "name": "Rock_Marble",
      "rotation": 33
    },
    {
      "x": -6,
      "y": 9,
      "z": -9,
      "name": "Soil_Clay_White",
      "rotation": 33
    },
    {
      "x": -6,
      "y": 10,
      "z": -9,
      "name": "Rock_Chalk",
      "rotation": 33
    },
    {
      "x": -6,
      "y": 11,
      "z": -9,
      "name": "Rock_Chalk",
      "rotation": 33
    },
    {
      "x": -6,
      "y": 12,
      "z": -9,
      "name": "Rock_Chalk",
      "rotation": 33
    },
    {
      "x": -6,
      "y": 13,
      "z": -9,
      "name": "Rock_Marble",
      "rotation": 33
    },
    {
      "x": -6,
      "y": 14,
      "z": -9,
      "name": "Rock_Marble_Cobble",
      "rotation": 33
    },
    {
      "x": -6,
      "y": 15,
      "z": -9,
      "name": "Rock_Marble",
      "rotation": 33
    },
    {
      "x": -6,
      "y": 16,
      "z": -9,
      "name": "Soil_Clay_White",
      "rotation": 33
    },
    {
      "x": -6,
      "y": 17,
      "z": -9,
      "name": "Soil_Clay_White",
      "rotation": 33
    },
    {
      "x": -6,
      "y": 18,
      "z": -9,
      "name": "Soil_Clay_White",
      "rotation": 33
    },
    {
      "x": -6,
      "y": 19,
      "z": -9,
      "name": "Soil_Clay_White",
      "rotation": 33
    },
    {
      "x": -6,
      "y": 20,
      "z": -9,
      "name": "Rock_Marble",
      "rotation": 33
    },
    {
      "x": -6,
      "y": 21,
      "z": -9,
      "name": "Rock_Marble",
      "rotation": 33
    },
    {
      "x": -6,
      "y": 1,
      "z": -8,
      "name": "Rock_Marble_Cobble",
      "rotation": 33
    },
    {
      "x": -6,
      "y": 2,
      "z": -8,
      "name": "Rock_Marble",
      "rotation": 33
    },
    {
      "x": -6,
      "y": 3,
      "z": -8,
      "name": "Soil_Clay_White",
      "rotation": 33
    },
    {
      "x": -6,
      "y": 4,
      "z": -8,
      "name": "Rock_Marble_Cobble",
      "rotation": 33
    },
    {
      "x": -6,
      "y": 5,
      "z": -8,
      "name": "Soil_Clay_GreyLight",
      "rotation": 33
    },
    {
      "x": -6,
      "y": 6,
      "z": -8,
      "name": "Rock_Marble",
      "rotation": 33
    },
    {
      "x": -6,
      "y": 7,
      "z": -8,
      "name": "Soil_Clay_White",
      "rotation": 33
    },
    {
      "x": -6,
      "y": 8,
      "z": -8,
      "name": "Rock_Marble",
      "rotation": 33
    },
    {
      "x": -6,
      "y": 9,
      "z": -8,
      "name": "Soil_Clay_White",
      "rotation": 33
    },
    {
      "x": -6,
      "y": 10,
      "z": -8,
      "name": "Rock_Chalk",
      "rotation": 33
    },
    {
      "x": -6,
      "y": 11,
      "z": -8,
      "name": "Rock_Chalk",
      "rotation": 33
    },
    {
      "x": -6,
      "y": 12,
      "z": -8,
      "name": "Rock_Chalk",
      "rotation": 33
    },
    {
      "x": -6,
      "y": 13,
      "z": -8,
      "name": "Rock_Marble",
      "rotation": 33
    },
    {
      "x": -6,
      "y": 14,
      "z": -8,
      "name": "Rock_Marble_Cobble",
      "rotation": 33
    },
    {
      "x": -6,
      "y": 15,
      "z": -8,
      "name": "Rock_Marble",
      "rotation": 33
    },
    {
      "x": -6,
      "y": 16,
      "z": -8,
      "name": "Soil_Clay_White",
      "rotation": 33
    },
    {
      "x": -6,
      "y": 17,
      "z": -8,
      "name": "Rock_Marble",
      "rotation": 33
    },
    {
      "x": -6,
      "y": 18,
      "z": -8,
      "name": "Soil_Clay_White",
      "rotation": 33
    },
    {
      "x": -6,
      "y": 19,
      "z": -8,
      "name": "Soil_Clay_White",
      "rotation": 33
    },
    {
      "x": -6,
      "y": 20,
      "z": -8,
      "name": "Rock_Marble",
      "rotation": 33
    },
    {
      "x": -6,
      "y": 21,
      "z": -8,
      "name": "Rock_Marble",
      "rotation": 33
    },
    {
      "x": -6,
      "y": 22,
      "z": -8,
      "name": "Rock_Marble",
      "rotation": 33
    },
    {
      "x": -6,
      "y": 23,
      "z": -8,
      "name": "Rock_Marble_Cobble",
      "rotation": 33
    },
    {
      "x": -6,
      "y": 24,
      "z": -8,
      "name": "Rock_Marble_Cobble",
      "rotation": 33
    },
    {
      "x": -6,
      "y": 25,
      "z": -8,
      "name": "Rock_Marble",
      "rotation": 33
    },
    {
      "x": -6,
      "y": 1,
      "z": -7,
      "name": "Rock_Marble_Cobble",
      "rotation": 33
    },
    {
      "x": -6,
      "y": 2,
      "z": -7,
      "name": "Rock_Marble",
      "rotation": 33
    },
    {
      "x": -6,
      "y": 3,
      "z": -7,
      "name": "Soil_Clay_White",
      "rotation": 33
    },
    {
      "x": -6,
      "y": 4,
      "z": -7,
      "name": "Rock_Marble_Cobble",
      "rotation": 33
    },
    {
      "x": -6,
      "y": 5,
      "z": -7,
      "name": "Soil_Clay_GreyLight",
      "rotation": 33
    },
    {
      "x": -6,
      "y": 6,
      "z": -7,
      "name": "Rock_Marble",
      "rotation": 33
    },
    {
      "x": -6,
      "y": 7,
      "z": -7,
      "name": "Soil_Clay_White",
      "rotation": 33
    },
    {
      "x": -6,
      "y": 8,
      "z": -7,
      "name": "Rock_Marble",
      "rotation": 33
    },
    {
      "x": -6,
      "y": 9,
      "z": -7,
      "name": "Soil_Clay_White",
      "rotation": 33
    },
    {
      "x": -6,
      "y": 10,
      "z": -7,
      "name": "Rock_Chalk",
      "rotation": 33
    },
    {
      "x": -6,
      "y": 11,
      "z": -7,
      "name": "Rock_Chalk",
      "rotation": 33
    },
    {
      "x": -6,
      "y": 12,
      "z": -7,
      "name": "Rock_Chalk",
      "rotation": 33
    },
    {
      "x": -6,
      "y": 13,
      "z": -7,
      "name": "Rock_Marble",
      "rotation": 33
    },
    {
      "x": -6,
      "y": 14,
      "z": -7,
      "name": "Rock_Marble_Cobble",
      "rotation": 33
    },
    {
      "x": -6,
      "y": 15,
      "z": -7,
      "name": "Rock_Marble",
      "rotation": 33
    },
    {
      "x": -6,
      "y": 16,
      "z": -7,
      "name": "Soil_Clay_White",
      "rotation": 33
    },
    {
      "x": -6,
      "y": 17,
      "z": -7,
      "name": "Rock_Marble",
      "rotation": 33
    },
    {
      "x": -6,
      "y": 18,
      "z": -7,
      "name": "Soil_Clay_White",
      "rotation": 33
    },
    {
      "x": -6,
      "y": 19,
      "z": -7,
      "name": "Soil_Clay_White",
      "rotation": 33
    },
    {
      "x": -6,
      "y": 20,
      "z": -7,
      "name": "Rock_Marble",
      "rotation": 33
    },
    {
      "x": -6,
      "y": 21,
      "z": -7,
      "name": "Rock_Marble",
      "rotation": 33
    },
    {
      "x": -6,
      "y": 22,
      "z": -7,
      "name": "Rock_Marble",
      "rotation": 33
    },
    {
      "x": -6,
      "y": 23,
      "z": -7,
      "name": "Rock_Marble_Cobble",
      "rotation": 33
    },
    {
      "x": -6,
      "y": 24,
      "z": -7,
      "name": "Rock_Marble_Cobble",
      "rotation": 33
    },
    {
      "x": -6,
      "y": 25,
      "z": -7,
      "name": "Rock_Marble",
      "rotation": 33
    },
    {
      "x": -6,
      "y": 26,
      "z": -7,
      "name": "Rock_Marble",
      "rotation": 33
    },
    {
      "x": -6,
      "y": 34,
      "z": -7,
      "name": "Plant_Moss_Wall_Green",
      "rotation": 3
    },
    {
      "x": -6,
      "y": 1,
      "z": -6,
      "name": "Rock_Marble_Cobble",
      "rotation": 33
    },
    {
      "x": -6,
      "y": 2,
      "z": -6,
      "name": "Rock_Marble",
      "rotation": 33
    },
    {
      "x": -6,
      "y": 3,
      "z": -6,
      "name": "Soil_Clay_White",
      "rotation": 33
    },
    {
      "x": -6,
      "y": 4,
      "z": -6,
      "name": "Rock_Marble_Cobble",
      "rotation": 33
    },
    {
      "x": -6,
      "y": 5,
      "z": -6,
      "name": "Soil_Clay_GreyLight",
      "rotation": 33
    },
    {
      "x": -6,
      "y": 6,
      "z": -6,
      "name": "Rock_Marble",
      "rotation": 33
    },
    {
      "x": -6,
      "y": 7,
      "z": -6,
      "name": "Soil_Clay_White",
      "rotation": 33
    },
    {
      "x": -6,
      "y": 8,
      "z": -6,
      "name": "Rock_Marble",
      "rotation": 33
    },
    {
      "x": -6,
      "y": 9,
      "z": -6,
      "name": "Soil_Clay_White",
      "rotation": 33
    },
    {
      "x": -6,
      "y": 10,
      "z": -6,
      "name": "Rock_Chalk",
      "rotation": 33
    },
    {
      "x": -6,
      "y": 11,
      "z": -6,
      "name": "Rock_Chalk",
      "rotation": 33
    },
    {
      "x": -6,
      "y": 12,
      "z": -6,
      "name": "Rock_Chalk",
      "rotation": 33
    },
    {
      "x": -6,
      "y": 13,
      "z": -6,
      "name": "Rock_Marble",
      "rotation": 33
    },
    {
      "x": -6,
      "y": 14,
      "z": -6,
      "name": "Rock_Marble_Cobble",
      "rotation": 33
    },
    {
      "x": -6,
      "y": 15,
      "z": -6,
      "name": "Rock_Marble",
      "rotation": 33
    },
    {
      "x": -6,
      "y": 16,
      "z": -6,
      "name": "Soil_Clay_White",
      "rotation": 33
    },
    {
      "x": -6,
      "y": 17,
      "z": -6,
      "name": "Rock_Marble",
      "rotation": 33
    },
    {
      "x": -6,
      "y": 18,
      "z": -6,
      "name": "Soil_Clay_White",
      "rotation": 33
    },
    {
      "x": -6,
      "y": 19,
      "z": -6,
      "name": "Soil_Clay_White",
      "rotation": 33
    },
    {
      "x": -6,
      "y": 20,
      "z": -6,
      "name": "Rock_Marble",
      "rotation": 33
    },
    {
      "x": -6,
      "y": 21,
      "z": -6,
      "name": "Rock_Marble",
      "rotation": 33
    },
    {
      "x": -6,
      "y": 22,
      "z": -6,
      "name": "Rock_Marble",
      "rotation": 33
    },
    {
      "x": -6,
      "y": 23,
      "z": -6,
      "name": "Rock_Marble_Cobble",
      "rotation": 33
    },
    {
      "x": -6,
      "y": 24,
      "z": -6,
      "name": "Rock_Marble_Cobble",
      "rotation": 33
    },
    {
      "x": -6,
      "y": 25,
      "z": -6,
      "name": "Rock_Marble",
      "rotation": 33
    },
    {
      "x": -6,
      "y": 33,
      "z": -6,
      "name": "Plant_Moss_Wall_Green",
      "rotation": 3
    },
    {
      "x": -6,
      "y": 1,
      "z": -5,
      "name": "Rock_Marble_Cobble",
      "rotation": 33
    },
    {
      "x": -6,
      "y": 2,
      "z": -5,
      "name": "Rock_Marble",
      "rotation": 33
    },
    {
      "x": -6,
      "y": 3,
      "z": -5,
      "name": "Soil_Clay_White",
      "rotation": 33
    },
    {
      "x": -6,
      "y": 4,
      "z": -5,
      "name": "Rock_Marble_Cobble",
      "rotation": 33
    },
    {
      "x": -6,
      "y": 5,
      "z": -5,
      "name": "Soil_Clay_GreyLight",
      "rotation": 33
    },
    {
      "x": -6,
      "y": 6,
      "z": -5,
      "name": "Rock_Marble",
      "rotation": 33
    },
    {
      "x": -6,
      "y": 7,
      "z": -5,
      "name": "Soil_Clay_White",
      "rotation": 33
    },
    {
      "x": -6,
      "y": 8,
      "z": -5,
      "name": "Rock_Marble",
      "rotation": 33
    },
    {
      "x": -6,
      "y": 9,
      "z": -5,
      "name": "Soil_Clay_White",
      "rotation": 33
    },
    {
      "x": -6,
      "y": 10,
      "z": -5,
      "name": "Rock_Chalk",
      "rotation": 33
    },
    {
      "x": -6,
      "y": 11,
      "z": -5,
      "name": "Rock_Chalk",
      "rotation": 33
    },
    {
      "x": -6,
      "y": 12,
      "z": -5,
      "name": "Rock_Chalk",
      "rotation": 33
    },
    {
      "x": -6,
      "y": 13,
      "z": -5,
      "name": "Rock_Marble",
      "rotation": 33
    },
    {
      "x": -6,
      "y": 14,
      "z": -5,
      "name": "Rock_Marble_Cobble",
      "rotation": 33
    },
    {
      "x": -6,
      "y": 15,
      "z": -5,
      "name": "Rock_Marble",
      "rotation": 33
    },
    {
      "x": -6,
      "y": 16,
      "z": -5,
      "name": "Soil_Clay_White",
      "rotation": 33
    },
    {
      "x": -6,
      "y": 17,
      "z": -5,
      "name": "Rock_Marble",
      "rotation": 33
    },
    {
      "x": -6,
      "y": 18,
      "z": -5,
      "name": "Soil_Clay_White",
      "rotation": 33
    },
    {
      "x": -6,
      "y": 19,
      "z": -5,
      "name": "Soil_Clay_White",
      "rotation": 33
    },
    {
      "x": -6,
      "y": 20,
      "z": -5,
      "name": "Rock_Marble",
      "rotation": 33
    },
    {
      "x": -6,
      "y": 21,
      "z": -5,
      "name": "Rock_Marble",
      "rotation": 33
    },
    {
      "x": -6,
      "y": 22,
      "z": -5,
      "name": "Soil_Clay_White",
      "rotation": 33
    },
    {
      "x": -6,
      "y": 2,
      "z": -4,
      "name": "Rock_Marble",
      "rotation": 33
    },
    {
      "x": -6,
      "y": 3,
      "z": -4,
      "name": "Soil_Clay_White",
      "rotation": 33
    },
    {
      "x": -6,
      "y": 4,
      "z": -4,
      "name": "Rock_Marble_Cobble",
      "rotation": 33
    },
    {
      "x": -6,
      "y": 5,
      "z": -4,
      "name": "Soil_Clay_GreyLight",
      "rotation": 33
    },
    {
      "x": -6,
      "y": 6,
      "z": -4,
      "name": "Rock_Marble",
      "rotation": 33
    },
    {
      "x": -6,
      "y": 7,
      "z": -4,
      "name": "Soil_Clay_White",
      "rotation": 33
    },
    {
      "x": -6,
      "y": 8,
      "z": -4,
      "name": "Rock_Marble",
      "rotation": 33
    },
    {
      "x": -6,
      "y": 9,
      "z": -4,
      "name": "Soil_Clay_White",
      "rotation": 33
    },
    {
      "x": -6,
      "y": 10,
      "z": -4,
      "name": "Rock_Chalk",
      "rotation": 33
    },
    {
      "x": -6,
      "y": 11,
      "z": -4,
      "name": "Rock_Chalk",
      "rotation": 33
    },
    {
      "x": -6,
      "y": 12,
      "z": -4,
      "name": "Rock_Chalk",
      "rotation": 33
    },
    {
      "x": -6,
      "y": 13,
      "z": -4,
      "name": "Rock_Marble",
      "rotation": 33
    },
    {
      "x": -6,
      "y": 14,
      "z": -4,
      "name": "Rock_Marble_Cobble",
      "rotation": 33
    },
    {
      "x": -6,
      "y": 15,
      "z": -4,
      "name": "Rock_Marble",
      "rotation": 33
    },
    {
      "x": -6,
      "y": 16,
      "z": -4,
      "name": "Soil_Clay_White",
      "rotation": 33
    },
    {
      "x": -6,
      "y": 17,
      "z": -4,
      "name": "Rock_Marble",
      "rotation": 33
    },
    {
      "x": -6,
      "y": 18,
      "z": -4,
      "name": "Soil_Clay_White",
      "rotation": 33
    },
    {
      "x": -6,
      "y": 3,
      "z": -3,
      "name": "Soil_Clay_White",
      "rotation": 33
    },
    {
      "x": -6,
      "y": 4,
      "z": -3,
      "name": "Rock_Marble_Cobble",
      "rotation": 33
    },
    {
      "x": -6,
      "y": 5,
      "z": -3,
      "name": "Soil_Clay_GreyLight",
      "rotation": 33
    },
    {
      "x": -6,
      "y": 12,
      "z": -3,
      "name": "Rock_Chalk",
      "rotation": 33
    },
    {
      "x": -6,
      "y": 13,
      "z": -3,
      "name": "Rock_Marble",
      "rotation": 33
    },
    {
      "x": -5,
      "y": 3,
      "z": -11,
      "name": "Soil_Clay_White",
      "rotation": 33
    },
    {
      "x": -5,
      "y": 4,
      "z": -11,
      "name": "Rock_Marble_Cobble",
      "rotation": 33
    },
    {
      "x": -5,
      "y": 5,
      "z": -11,
      "name": "Soil_Clay_GreyLight",
      "rotation": 33
    },
    {
      "x": -5,
      "y": 6,
      "z": -11,
      "name": "Rock_Marble",
      "rotation": 33
    },
    {
      "x": -5,
      "y": 7,
      "z": -11,
      "name": "Soil_Clay_White",
      "rotation": 33
    },
    {
      "x": -5,
      "y": 8,
      "z": -11,
      "name": "Rock_Marble",
      "rotation": 33
    },
    {
      "x": -5,
      "y": 2,
      "z": -10,
      "name": "Rock_Marble",
      "rotation": 33
    },
    {
      "x": -5,
      "y": 3,
      "z": -10,
      "name": "Soil_Clay_White",
      "rotation": 33
    },
    {
      "x": -5,
      "y": 4,
      "z": -10,
      "name": "Rock_Marble_Cobble",
      "rotation": 33
    },
    {
      "x": -5,
      "y": 5,
      "z": -10,
      "name": "Soil_Clay_GreyLight",
      "rotation": 33
    },
    {
      "x": -5,
      "y": 6,
      "z": -10,
      "name": "Rock_Marble",
      "rotation": 33
    },
    {
      "x": -5,
      "y": 7,
      "z": -10,
      "name": "Soil_Clay_White",
      "rotation": 33
    },
    {
      "x": -5,
      "y": 8,
      "z": -10,
      "name": "Rock_Marble",
      "rotation": 33
    },
    {
      "x": -5,
      "y": 9,
      "z": -10,
      "name": "Soil_Clay_White",
      "rotation": 33
    },
    {
      "x": -5,
      "y": 10,
      "z": -10,
      "name": "Rock_Chalk",
      "rotation": 33
    },
    {
      "x": -5,
      "y": 11,
      "z": -10,
      "name": "Rock_Chalk",
      "rotation": 33
    },
    {
      "x": -5,
      "y": 12,
      "z": -10,
      "name": "Rock_Chalk",
      "rotation": 33
    },
    {
      "x": -5,
      "y": 13,
      "z": -10,
      "name": "Rock_Marble",
      "rotation": 33
    },
    {
      "x": -5,
      "y": 14,
      "z": -10,
      "name": "Rock_Marble_Cobble",
      "rotation": 33
    },
    {
      "x": -5,
      "y": 15,
      "z": -10,
      "name": "Rock_Marble",
      "rotation": 33
    },
    {
      "x": -5,
      "y": 16,
      "z": -10,
      "name": "Soil_Clay_White",
      "rotation": 33
    },
    {
      "x": -5,
      "y": 17,
      "z": -10,
      "name": "Soil_Clay_White",
      "rotation": 33
    },
    {
      "x": -5,
      "y": 18,
      "z": -10,
      "name": "Soil_Clay_White",
      "rotation": 33
    },
    {
      "x": -5,
      "y": 19,
      "z": -10,
      "name": "Soil_Clay_White",
      "rotation": 33
    },
    {
      "x": -5,
      "y": 20,
      "z": -10,
      "name": "Rock_Marble",
      "rotation": 33
    },
    {
      "x": -5,
      "y": 1,
      "z": -9,
      "name": "Rock_Marble_Cobble",
      "rotation": 33
    },
    {
      "x": -5,
      "y": 2,
      "z": -9,
      "name": "Rock_Marble",
      "rotation": 33
    },
    {
      "x": -5,
      "y": 3,
      "z": -9,
      "name": "Soil_Clay_White",
      "rotation": 33
    },
    {
      "x": -5,
      "y": 4,
      "z": -9,
      "name": "Rock_Marble_Cobble",
      "rotation": 33
    },
    {
      "x": -5,
      "y": 5,
      "z": -9,
      "name": "Soil_Clay_GreyLight",
      "rotation": 33
    },
    {
      "x": -5,
      "y": 6,
      "z": -9,
      "name": "Rock_Marble",
      "rotation": 33
    },
    {
      "x": -5,
      "y": 7,
      "z": -9,
      "name": "Soil_Clay_White",
      "rotation": 33
    },
    {
      "x": -5,
      "y": 8,
      "z": -9,
      "name": "Rock_Marble",
      "rotation": 33
    },
    {
      "x": -5,
      "y": 9,
      "z": -9,
      "name": "Soil_Clay_White",
      "rotation": 33
    },
    {
      "x": -5,
      "y": 10,
      "z": -9,
      "name": "Rock_Chalk",
      "rotation": 33
    },
    {
      "x": -5,
      "y": 11,
      "z": -9,
      "name": "Rock_Chalk",
      "rotation": 33
    },
    {
      "x": -5,
      "y": 12,
      "z": -9,
      "name": "Rock_Chalk",
      "rotation": 33
    },
    {
      "x": -5,
      "y": 13,
      "z": -9,
      "name": "Rock_Marble",
      "rotation": 33
    },
    {
      "x": -5,
      "y": 14,
      "z": -9,
      "name": "Rock_Marble_Cobble",
      "rotation": 33
    },
    {
      "x": -5,
      "y": 15,
      "z": -9,
      "name": "Rock_Marble",
      "rotation": 33
    },
    {
      "x": -5,
      "y": 16,
      "z": -9,
      "name": "Soil_Clay_White",
      "rotation": 33
    },
    {
      "x": -5,
      "y": 17,
      "z": -9,
      "name": "Soil_Clay_White",
      "rotation": 33
    },
    {
      "x": -5,
      "y": 18,
      "z": -9,
      "name": "Soil_Clay_White",
      "rotation": 33
    },
    {
      "x": -5,
      "y": 19,
      "z": -9,
      "name": "Soil_Clay_White",
      "rotation": 33
    },
    {
      "x": -5,
      "y": 20,
      "z": -9,
      "name": "Rock_Marble",
      "rotation": 33
    },
    {
      "x": -5,
      "y": 21,
      "z": -9,
      "name": "Rock_Marble",
      "rotation": 33
    },
    {
      "x": -5,
      "y": 22,
      "z": -9,
      "name": "Rock_Marble",
      "rotation": 33
    },
    {
      "x": -5,
      "y": 23,
      "z": -9,
      "name": "Rock_Marble_Cobble",
      "rotation": 33
    },
    {
      "x": -5,
      "y": 24,
      "z": -9,
      "name": "Rock_Marble_Cobble",
      "rotation": 33
    },
    {
      "x": -5,
      "y": 25,
      "z": -9,
      "name": "Rock_Marble",
      "rotation": 33
    },
    {
      "x": -5,
      "y": 26,
      "z": -9,
      "name": "Rock_Marble",
      "rotation": 33
    },
    {
      "x": -5,
      "y": 1,
      "z": -8,
      "name": "Rock_Marble_Cobble",
      "rotation": 33
    },
    {
      "x": -5,
      "y": 2,
      "z": -8,
      "name": "Rock_Marble",
      "rotation": 33
    },
    {
      "x": -5,
      "y": 3,
      "z": -8,
      "name": "Soil_Clay_White",
      "rotation": 33
    },
    {
      "x": -5,
      "y": 4,
      "z": -8,
      "name": "Rock_Marble_Cobble",
      "rotation": 33
    },
    {
      "x": -5,
      "y": 5,
      "z": -8,
      "name": "Soil_Clay_GreyLight",
      "rotation": 33
    },
    {
      "x": -5,
      "y": 6,
      "z": -8,
      "name": "Rock_Marble",
      "rotation": 33
    },
    {
      "x": -5,
      "y": 7,
      "z": -8,
      "name": "Soil_Clay_White",
      "rotation": 33
    },
    {
      "x": -5,
      "y": 8,
      "z": -8,
      "name": "Rock_Marble",
      "rotation": 33
    },
    {
      "x": -5,
      "y": 9,
      "z": -8,
      "name": "Soil_Clay_White",
      "rotation": 33
    },
    {
      "x": -5,
      "y": 10,
      "z": -8,
      "name": "Rock_Chalk",
      "rotation": 33
    },
    {
      "x": -5,
      "y": 11,
      "z": -8,
      "name": "Rock_Chalk",
      "rotation": 33
    },
    {
      "x": -5,
      "y": 12,
      "z": -8,
      "name": "Rock_Chalk",
      "rotation": 33
    },
    {
      "x": -5,
      "y": 13,
      "z": -8,
      "name": "Rock_Marble",
      "rotation": 33
    },
    {
      "x": -5,
      "y": 14,
      "z": -8,
      "name": "Rock_Marble_Cobble",
      "rotation": 33
    },
    {
      "x": -5,
      "y": 15,
      "z": -8,
      "name": "Rock_Marble",
      "rotation": 33
    },
    {
      "x": -5,
      "y": 16,
      "z": -8,
      "name": "Soil_Clay_White",
      "rotation": 33
    },
    {
      "x": -5,
      "y": 17,
      "z": -8,
      "name": "Rock_Marble",
      "rotation": 33
    },
    {
      "x": -5,
      "y": 18,
      "z": -8,
      "name": "Soil_Clay_White",
      "rotation": 33
    },
    {
      "x": -5,
      "y": 19,
      "z": -8,
      "name": "Soil_Clay_White",
      "rotation": 33
    },
    {
      "x": -5,
      "y": 20,
      "z": -8,
      "name": "Rock_Marble",
      "rotation": 33
    },
    {
      "x": -5,
      "y": 21,
      "z": -8,
      "name": "Rock_Marble",
      "rotation": 33
    },
    {
      "x": -5,
      "y": 22,
      "z": -8,
      "name": "Rock_Marble",
      "rotation": 33
    },
    {
      "x": -5,
      "y": 23,
      "z": -8,
      "name": "Rock_Marble_Cobble",
      "rotation": 33
    },
    {
      "x": -5,
      "y": 24,
      "z": -8,
      "name": "Rock_Marble_Cobble",
      "rotation": 33
    },
    {
      "x": -5,
      "y": 25,
      "z": -8,
      "name": "Rock_Marble",
      "rotation": 33
    },
    {
      "x": -5,
      "y": 26,
      "z": -8,
      "name": "Rock_Marble",
      "rotation": 33
    },
    {
      "x": -5,
      "y": 27,
      "z": -8,
      "name": "Rock_Marble_Cobble",
      "rotation": 33
    },
    {
      "x": -5,
      "y": 28,
      "z": -8,
      "name": "Rock_Marble",
      "rotation": 33
    },
    {
      "x": -5,
      "y": 29,
      "z": -8,
      "name": "Soil_Clay_White",
      "rotation": 33
    },
    {
      "x": -5,
      "y": 30,
      "z": -8,
      "name": "Rock_Marble",
      "rotation": 33
    },
    {
      "x": -5,
      "y": 31,
      "z": -8,
      "name": "Rock_Marble_Cobble",
      "rotation": 33
    },
    {
      "x": -5,
      "y": 34,
      "z": -8,
      "name": "Plant_Moss_Wall_Green",
      "rotation": 2
    },
    {
      "x": -5,
      "y": 0,
      "z": -7,
      "name": "Rock_Marble_Cobble",
      "rotation": 33
    },
    {
      "x": -5,
      "y": 1,
      "z": -7,
      "name": "Rock_Marble_Cobble",
      "rotation": 33
    },
    {
      "x": -5,
      "y": 2,
      "z": -7,
      "name": "Rock_Marble",
      "rotation": 33
    },
    {
      "x": -5,
      "y": 3,
      "z": -7,
      "name": "Soil_Clay_White",
      "rotation": 33
    },
    {
      "x": -5,
      "y": 4,
      "z": -7,
      "name": "Rock_Marble_Cobble",
      "rotation": 33
    },
    {
      "x": -5,
      "y": 5,
      "z": -7,
      "name": "Soil_Clay_GreyLight",
      "rotation": 33
    },
    {
      "x": -5,
      "y": 6,
      "z": -7,
      "name": "Rock_Marble",
      "rotation": 33
    },
    {
      "x": -5,
      "y": 7,
      "z": -7,
      "name": "Soil_Clay_White",
      "rotation": 33
    },
    {
      "x": -5,
      "y": 8,
      "z": -7,
      "name": "Rock_Marble",
      "rotation": 33
    },
    {
      "x": -5,
      "y": 9,
      "z": -7,
      "name": "Soil_Clay_White",
      "rotation": 33
    },
    {
      "x": -5,
      "y": 10,
      "z": -7,
      "name": "Rock_Chalk",
      "rotation": 33
    },
    {
      "x": -5,
      "y": 11,
      "z": -7,
      "name": "Rock_Chalk",
      "rotation": 33
    },
    {
      "x": -5,
      "y": 12,
      "z": -7,
      "name": "Rock_Chalk",
      "rotation": 33
    },
    {
      "x": -5,
      "y": 13,
      "z": -7,
      "name": "Rock_Marble",
      "rotation": 33
    },
    {
      "x": -5,
      "y": 14,
      "z": -7,
      "name": "Rock_Marble_Cobble",
      "rotation": 33
    },
    {
      "x": -5,
      "y": 15,
      "z": -7,
      "name": "Rock_Marble",
      "rotation": 33
    },
    {
      "x": -5,
      "y": 16,
      "z": -7,
      "name": "Soil_Clay_White",
      "rotation": 33
    },
    {
      "x": -5,
      "y": 17,
      "z": -7,
      "name": "Rock_Marble",
      "rotation": 33
    },
    {
      "x": -5,
      "y": 18,
      "z": -7,
      "name": "Soil_Clay_White",
      "rotation": 33
    },
    {
      "x": -5,
      "y": 19,
      "z": -7,
      "name": "Soil_Clay_White",
      "rotation": 33
    },
    {
      "x": -5,
      "y": 20,
      "z": -7,
      "name": "Rock_Marble",
      "rotation": 33
    },
    {
      "x": -5,
      "y": 21,
      "z": -7,
      "name": "Rock_Marble",
      "rotation": 33
    },
    {
      "x": -5,
      "y": 22,
      "z": -7,
      "name": "Rock_Marble",
      "rotation": 33
    },
    {
      "x": -5,
      "y": 23,
      "z": -7,
      "name": "Rock_Marble_Cobble",
      "rotation": 33
    },
    {
      "x": -5,
      "y": 24,
      "z": -7,
      "name": "Rock_Marble_Cobble",
      "rotation": 33
    },
    {
      "x": -5,
      "y": 25,
      "z": -7,
      "name": "Rock_Marble",
      "rotation": 33
    },
    {
      "x": -5,
      "y": 26,
      "z": -7,
      "name": "Rock_Marble",
      "rotation": 33
    },
    {
      "x": -5,
      "y": 27,
      "z": -7,
      "name": "Rock_Marble_Cobble",
      "rotation": 33
    },
    {
      "x": -5,
      "y": 28,
      "z": -7,
      "name": "Rock_Marble",
      "rotation": 33
    },
    {
      "x": -5,
      "y": 29,
      "z": -7,
      "name": "Soil_Clay_White",
      "rotation": 33
    },
    {
      "x": -5,
      "y": 30,
      "z": -7,
      "name": "Rock_Marble",
      "rotation": 33
    },
    {
      "x": -5,
      "y": 31,
      "z": -7,
      "name": "Rock_Marble_Cobble",
      "rotation": 33
    },
    {
      "x": -5,
      "y": 32,
      "z": -7,
      "name": "Rock_Marble_Cobble",
      "rotation": 33
    },
    {
      "x": -5,
      "y": 33,
      "z": -7,
      "name": "Rock_Marble_Cobble",
      "rotation": 33
    },
    {
      "x": -5,
      "y": 34,
      "z": -7,
      "name": "Plant_Moss_Block_Green"
    },
    {
      "x": -5,
      "y": 35,
      "z": -7,
      "name": "Plant_Moss_Block_Green"
    },
    {
      "x": -5,
      "y": 1,
      "z": -6,
      "name": "Rock_Marble_Cobble",
      "rotation": 33
    },
    {
      "x": -5,
      "y": 2,
      "z": -6,
      "name": "Rock_Marble",
      "rotation": 33
    },
    {
      "x": -5,
      "y": 3,
      "z": -6,
      "name": "Soil_Clay_White",
      "rotation": 33
    },
    {
      "x": -5,
      "y": 4,
      "z": -6,
      "name": "Rock_Marble_Cobble",
      "rotation": 33
    },
    {
      "x": -5,
      "y": 5,
      "z": -6,
      "name": "Soil_Clay_GreyLight",
      "rotation": 33
    },
    {
      "x": -5,
      "y": 6,
      "z": -6,
      "name": "Rock_Marble",
      "rotation": 33
    },
    {
      "x": -5,
      "y": 7,
      "z": -6,
      "name": "Soil_Clay_White",
      "rotation": 33
    },
    {
      "x": -5,
      "y": 8,
      "z": -6,
      "name": "Rock_Marble",
      "rotation": 33
    },
    {
      "x": -5,
      "y": 9,
      "z": -6,
      "name": "Soil_Clay_White",
      "rotation": 33
    },
    {
      "x": -5,
      "y": 10,
      "z": -6,
      "name": "Rock_Chalk",
      "rotation": 33
    },
    {
      "x": -5,
      "y": 11,
      "z": -6,
      "name": "Rock_Chalk",
      "rotation": 33
    },
    {
      "x": -5,
      "y": 12,
      "z": -6,
      "name": "Rock_Chalk",
      "rotation": 33
    },
    {
      "x": -5,
      "y": 13,
      "z": -6,
      "name": "Rock_Marble",
      "rotation": 33
    },
    {
      "x": -5,
      "y": 14,
      "z": -6,
      "name": "Rock_Marble_Cobble",
      "rotation": 33
    },
    {
      "x": -5,
      "y": 15,
      "z": -6,
      "name": "Rock_Marble",
      "rotation": 33
    },
    {
      "x": -5,
      "y": 16,
      "z": -6,
      "name": "Soil_Clay_White",
      "rotation": 33
    },
    {
      "x": -5,
      "y": 17,
      "z": -6,
      "name": "Rock_Marble",
      "rotation": 33
    },
    {
      "x": -5,
      "y": 18,
      "z": -6,
      "name": "Soil_Clay_White",
      "rotation": 33
    },
    {
      "x": -5,
      "y": 19,
      "z": -6,
      "name": "Soil_Clay_White",
      "rotation": 33
    },
    {
      "x": -5,
      "y": 20,
      "z": -6,
      "name": "Rock_Marble",
      "rotation": 33
    },
    {
      "x": -5,
      "y": 21,
      "z": -6,
      "name": "Rock_Marble",
      "rotation": 33
    },
    {
      "x": -5,
      "y": 22,
      "z": -6,
      "name": "Rock_Marble",
      "rotation": 33
    },
    {
      "x": -5,
      "y": 23,
      "z": -6,
      "name": "Rock_Marble_Cobble",
      "rotation": 33
    },
    {
      "x": -5,
      "y": 24,
      "z": -6,
      "name": "Rock_Marble_Cobble",
      "rotation": 33
    },
    {
      "x": -5,
      "y": 25,
      "z": -6,
      "name": "Rock_Marble",
      "rotation": 33
    },
    {
      "x": -5,
      "y": 26,
      "z": -6,
      "name": "Rock_Marble",
      "rotation": 33
    },
    {
      "x": -5,
      "y": 27,
      "z": -6,
      "name": "Rock_Marble_Cobble",
      "rotation": 33
    },
    {
      "x": -5,
      "y": 32,
      "z": -6,
      "name": "Rock_Marble_Cobble",
      "rotation": 33
    },
    {
      "x": -5,
      "y": 33,
      "z": -6,
      "name": "Plant_Moss_Block_Green"
    },
    {
      "x": -5,
      "y": 34,
      "z": -6,
      "name": "Plant_Moss_Block_Green"
    },
    {
      "x": -5,
      "y": 1,
      "z": -5,
      "name": "Rock_Marble_Cobble",
      "rotation": 33
    },
    {
      "x": -5,
      "y": 2,
      "z": -5,
      "name": "Rock_Marble",
      "rotation": 33
    },
    {
      "x": -5,
      "y": 3,
      "z": -5,
      "name": "Soil_Clay_White",
      "rotation": 33
    },
    {
      "x": -5,
      "y": 4,
      "z": -5,
      "name": "Rock_Marble_Cobble",
      "rotation": 33
    },
    {
      "x": -5,
      "y": 5,
      "z": -5,
      "name": "Soil_Clay_GreyLight",
      "rotation": 33
    },
    {
      "x": -5,
      "y": 6,
      "z": -5,
      "name": "Rock_Marble",
      "rotation": 33
    },
    {
      "x": -5,
      "y": 7,
      "z": -5,
      "name": "Soil_Clay_White",
      "rotation": 33
    },
    {
      "x": -5,
      "y": 8,
      "z": -5,
      "name": "Rock_Marble",
      "rotation": 33
    },
    {
      "x": -5,
      "y": 9,
      "z": -5,
      "name": "Soil_Clay_White",
      "rotation": 33
    },
    {
      "x": -5,
      "y": 10,
      "z": -5,
      "name": "Rock_Chalk",
      "rotation": 33
    },
    {
      "x": -5,
      "y": 11,
      "z": -5,
      "name": "Rock_Chalk",
      "rotation": 33
    },
    {
      "x": -5,
      "y": 12,
      "z": -5,
      "name": "Rock_Chalk",
      "rotation": 33
    },
    {
      "x": -5,
      "y": 13,
      "z": -5,
      "name": "Rock_Marble",
      "rotation": 33
    },
    {
      "x": -5,
      "y": 14,
      "z": -5,
      "name": "Rock_Marble_Cobble",
      "rotation": 33
    },
    {
      "x": -5,
      "y": 15,
      "z": -5,
      "name": "Rock_Marble",
      "rotation": 33
    },
    {
      "x": -5,
      "y": 16,
      "z": -5,
      "name": "Soil_Clay_White",
      "rotation": 33
    },
    {
      "x": -5,
      "y": 17,
      "z": -5,
      "name": "Rock_Marble",
      "rotation": 33
    },
    {
      "x": -5,
      "y": 18,
      "z": -5,
      "name": "Soil_Clay_White",
      "rotation": 33
    },
    {
      "x": -5,
      "y": 19,
      "z": -5,
      "name": "Soil_Clay_White",
      "rotation": 33
    },
    {
      "x": -5,
      "y": 20,
      "z": -5,
      "name": "Rock_Marble",
      "rotation": 33
    },
    {
      "x": -5,
      "y": 21,
      "z": -5,
      "name": "Rock_Marble",
      "rotation": 33
    },
    {
      "x": -5,
      "y": 22,
      "z": -5,
      "name": "Soil_Clay_White",
      "rotation": 33
    },
    {
      "x": -5,
      "y": 23,
      "z": -5,
      "name": "Rock_Marble_Cobble",
      "rotation": 33
    },
    {
      "x": -5,
      "y": 24,
      "z": -5,
      "name": "Rock_Marble_Cobble",
      "rotation": 33
    },
    {
      "x": -5,
      "y": 25,
      "z": -5,
      "name": "Rock_Marble",
      "rotation": 33
    },
    {
      "x": -5,
      "y": 26,
      "z": -5,
      "name": "Rock_Marble",
      "rotation": 33
    },
    {
      "x": -5,
      "y": 33,
      "z": -5,
      "name": "Plant_Moss_Wall_Green",
      "rotation": 3
    },
    {
      "x": -5,
      "y": 1,
      "z": -4,
      "name": "Rock_Marble_Cobble",
      "rotation": 33
    },
    {
      "x": -5,
      "y": 2,
      "z": -4,
      "name": "Rock_Marble",
      "rotation": 33
    },
    {
      "x": -5,
      "y": 3,
      "z": -4,
      "name": "Soil_Clay_White",
      "rotation": 33
    },
    {
      "x": -5,
      "y": 4,
      "z": -4,
      "name": "Rock_Marble_Cobble",
      "rotation": 33
    },
    {
      "x": -5,
      "y": 5,
      "z": -4,
      "name": "Soil_Clay_GreyLight",
      "rotation": 33
    },
    {
      "x": -5,
      "y": 6,
      "z": -4,
      "name": "Rock_Marble",
      "rotation": 33
    },
    {
      "x": -5,
      "y": 7,
      "z": -4,
      "name": "Soil_Clay_White",
      "rotation": 33
    },
    {
      "x": -5,
      "y": 8,
      "z": -4,
      "name": "Rock_Marble",
      "rotation": 33
    },
    {
      "x": -5,
      "y": 9,
      "z": -4,
      "name": "Soil_Clay_White",
      "rotation": 33
    },
    {
      "x": -5,
      "y": 10,
      "z": -4,
      "name": "Rock_Chalk",
      "rotation": 33
    },
    {
      "x": -5,
      "y": 11,
      "z": -4,
      "name": "Rock_Chalk",
      "rotation": 33
    },
    {
      "x": -5,
      "y": 12,
      "z": -4,
      "name": "Rock_Chalk",
      "rotation": 33
    },
    {
      "x": -5,
      "y": 13,
      "z": -4,
      "name": "Rock_Marble",
      "rotation": 33
    },
    {
      "x": -5,
      "y": 14,
      "z": -4,
      "name": "Rock_Marble_Cobble",
      "rotation": 33
    },
    {
      "x": -5,
      "y": 15,
      "z": -4,
      "name": "Rock_Marble",
      "rotation": 33
    },
    {
      "x": -5,
      "y": 16,
      "z": -4,
      "name": "Soil_Clay_White",
      "rotation": 33
    },
    {
      "x": -5,
      "y": 17,
      "z": -4,
      "name": "Rock_Marble",
      "rotation": 33
    },
    {
      "x": -5,
      "y": 18,
      "z": -4,
      "name": "Soil_Clay_White",
      "rotation": 33
    },
    {
      "x": -5,
      "y": 19,
      "z": -4,
      "name": "Soil_Clay_White",
      "rotation": 33
    },
    {
      "x": -5,
      "y": 20,
      "z": -4,
      "name": "Rock_Marble",
      "rotation": 33
    },
    {
      "x": -5,
      "y": 2,
      "z": -3,
      "name": "Rock_Marble",
      "rotation": 33
    },
    {
      "x": -5,
      "y": 3,
      "z": -3,
      "name": "Soil_Clay_White",
      "rotation": 33
    },
    {
      "x": -5,
      "y": 4,
      "z": -3,
      "name": "Rock_Marble_Cobble",
      "rotation": 33
    },
    {
      "x": -5,
      "y": 5,
      "z": -3,
      "name": "Soil_Clay_GreyLight",
      "rotation": 33
    },
    {
      "x": -5,
      "y": 6,
      "z": -3,
      "name": "Rock_Marble",
      "rotation": 33
    },
    {
      "x": -5,
      "y": 7,
      "z": -3,
      "name": "Soil_Clay_White",
      "rotation": 33
    },
    {
      "x": -5,
      "y": 10,
      "z": -3,
      "name": "Rock_Chalk",
      "rotation": 33
    },
    {
      "x": -5,
      "y": 11,
      "z": -3,
      "name": "Rock_Chalk",
      "rotation": 33
    },
    {
      "x": -5,
      "y": 12,
      "z": -3,
      "name": "Rock_Chalk",
      "rotation": 33
    },
    {
      "x": -5,
      "y": 13,
      "z": -3,
      "name": "Rock_Marble",
      "rotation": 33
    },
    {
      "x": -5,
      "y": 14,
      "z": -3,
      "name": "Rock_Marble_Cobble",
      "rotation": 33
    },
    {
      "x": -5,
      "y": 15,
      "z": -3,
      "name": "Rock_Marble",
      "rotation": 33
    },
    {
      "x": -5,
      "y": 16,
      "z": -3,
      "name": "Soil_Clay_White",
      "rotation": 33
    },
    {
      "x": -4,
      "y": 3,
      "z": -11,
      "name": "Soil_Clay_White",
      "rotation": 33
    },
    {
      "x": -4,
      "y": 4,
      "z": -11,
      "name": "Rock_Marble_Cobble",
      "rotation": 33
    },
    {
      "x": -4,
      "y": 5,
      "z": -11,
      "name": "Soil_Clay_GreyLight",
      "rotation": 33
    },
    {
      "x": -4,
      "y": 6,
      "z": -11,
      "name": "Rock_Marble",
      "rotation": 33
    },
    {
      "x": -4,
      "y": 7,
      "z": -11,
      "name": "Soil_Clay_White",
      "rotation": 33
    },
    {
      "x": -4,
      "y": 8,
      "z": -11,
      "name": "Rock_Marble",
      "rotation": 33
    },
    {
      "x": -4,
      "y": 9,
      "z": -11,
      "name": "Soil_Clay_White",
      "rotation": 33
    },
    {
      "x": -4,
      "y": 10,
      "z": -11,
      "name": "Soil_Clay_White",
      "rotation": 33
    },
    {
      "x": -4,
      "y": 11,
      "z": -11,
      "name": "Rock_Chalk",
      "rotation": 33
    },
    {
      "x": -4,
      "y": 12,
      "z": -11,
      "name": "Rock_Chalk",
      "rotation": 33
    },
    {
      "x": -4,
      "y": 1,
      "z": -10,
      "name": "Rock_Marble_Cobble",
      "rotation": 33
    },
    {
      "x": -4,
      "y": 2,
      "z": -10,
      "name": "Rock_Marble",
      "rotation": 33
    },
    {
      "x": -4,
      "y": 3,
      "z": -10,
      "name": "Soil_Clay_White",
      "rotation": 33
    },
    {
      "x": -4,
      "y": 4,
      "z": -10,
      "name": "Rock_Marble_Cobble",
      "rotation": 33
    },
    {
      "x": -4,
      "y": 5,
      "z": -10,
      "name": "Soil_Clay_GreyLight",
      "rotation": 33
    },
    {
      "x": -4,
      "y": 6,
      "z": -10,
      "name": "Rock_Marble",
      "rotation": 33
    },
    {
      "x": -4,
      "y": 7,
      "z": -10,
      "name": "Soil_Clay_White",
      "rotation": 33
    },
    {
      "x": -4,
      "y": 8,
      "z": -10,
      "name": "Rock_Marble",
      "rotation": 33
    },
    {
      "x": -4,
      "y": 9,
      "z": -10,
      "name": "Soil_Clay_White",
      "rotation": 33
    },
    {
      "x": -4,
      "y": 10,
      "z": -10,
      "name": "Rock_Chalk",
      "rotation": 33
    },
    {
      "x": -4,
      "y": 11,
      "z": -10,
      "name": "Rock_Chalk",
      "rotation": 33
    },
    {
      "x": -4,
      "y": 12,
      "z": -10,
      "name": "Rock_Chalk",
      "rotation": 33
    },
    {
      "x": -4,
      "y": 13,
      "z": -10,
      "name": "Rock_Marble",
      "rotation": 33
    },
    {
      "x": -4,
      "y": 14,
      "z": -10,
      "name": "Rock_Marble_Cobble",
      "rotation": 33
    },
    {
      "x": -4,
      "y": 15,
      "z": -10,
      "name": "Rock_Marble",
      "rotation": 33
    },
    {
      "x": -4,
      "y": 16,
      "z": -10,
      "name": "Soil_Clay_White",
      "rotation": 33
    },
    {
      "x": -4,
      "y": 17,
      "z": -10,
      "name": "Soil_Clay_White",
      "rotation": 33
    },
    {
      "x": -4,
      "y": 18,
      "z": -10,
      "name": "Soil_Clay_White",
      "rotation": 33
    },
    {
      "x": -4,
      "y": 19,
      "z": -10,
      "name": "Soil_Clay_White",
      "rotation": 33
    },
    {
      "x": -4,
      "y": 20,
      "z": -10,
      "name": "Rock_Marble",
      "rotation": 33
    },
    {
      "x": -4,
      "y": 21,
      "z": -10,
      "name": "Rock_Marble",
      "rotation": 33
    },
    {
      "x": -4,
      "y": 22,
      "z": -10,
      "name": "Rock_Marble",
      "rotation": 33
    },
    {
      "x": -4,
      "y": 23,
      "z": -10,
      "name": "Rock_Marble_Cobble",
      "rotation": 33
    },
    {
      "x": -4,
      "y": 24,
      "z": -10,
      "name": "Rock_Marble_Cobble",
      "rotation": 33
    },
    {
      "x": -4,
      "y": 25,
      "z": -10,
      "name": "Rock_Marble",
      "rotation": 33
    },
    {
      "x": -4,
      "y": 1,
      "z": -9,
      "name": "Rock_Marble_Cobble",
      "rotation": 33
    },
    {
      "x": -4,
      "y": 2,
      "z": -9,
      "name": "Rock_Marble",
      "rotation": 33
    },
    {
      "x": -4,
      "y": 3,
      "z": -9,
      "name": "Soil_Clay_White",
      "rotation": 33
    },
    {
      "x": -4,
      "y": 4,
      "z": -9,
      "name": "Rock_Marble_Cobble",
      "rotation": 33
    },
    {
      "x": -4,
      "y": 5,
      "z": -9,
      "name": "Soil_Clay_GreyLight",
      "rotation": 33
    },
    {
      "x": -4,
      "y": 6,
      "z": -9,
      "name": "Rock_Marble",
      "rotation": 33
    },
    {
      "x": -4,
      "y": 7,
      "z": -9,
      "name": "Soil_Clay_White",
      "rotation": 33
    },
    {
      "x": -4,
      "y": 8,
      "z": -9,
      "name": "Rock_Marble",
      "rotation": 33
    },
    {
      "x": -4,
      "y": 9,
      "z": -9,
      "name": "Soil_Clay_White",
      "rotation": 33
    },
    {
      "x": -4,
      "y": 10,
      "z": -9,
      "name": "Rock_Chalk",
      "rotation": 33
    },
    {
      "x": -4,
      "y": 11,
      "z": -9,
      "name": "Rock_Chalk",
      "rotation": 33
    },
    {
      "x": -4,
      "y": 12,
      "z": -9,
      "name": "Rock_Chalk",
      "rotation": 33
    },
    {
      "x": -4,
      "y": 13,
      "z": -9,
      "name": "Rock_Marble",
      "rotation": 33
    },
    {
      "x": -4,
      "y": 14,
      "z": -9,
      "name": "Rock_Marble_Cobble",
      "rotation": 33
    },
    {
      "x": -4,
      "y": 15,
      "z": -9,
      "name": "Rock_Marble",
      "rotation": 33
    },
    {
      "x": -4,
      "y": 16,
      "z": -9,
      "name": "Soil_Clay_White",
      "rotation": 33
    },
    {
      "x": -4,
      "y": 17,
      "z": -9,
      "name": "Soil_Clay_White",
      "rotation": 33
    },
    {
      "x": -4,
      "y": 18,
      "z": -9,
      "name": "Soil_Clay_White",
      "rotation": 33
    },
    {
      "x": -4,
      "y": 19,
      "z": -9,
      "name": "Soil_Clay_White",
      "rotation": 33
    },
    {
      "x": -4,
      "y": 20,
      "z": -9,
      "name": "Rock_Marble",
      "rotation": 33
    },
    {
      "x": -4,
      "y": 21,
      "z": -9,
      "name": "Rock_Marble",
      "rotation": 33
    },
    {
      "x": -4,
      "y": 22,
      "z": -9,
      "name": "Rock_Marble",
      "rotation": 33
    },
    {
      "x": -4,
      "y": 23,
      "z": -9,
      "name": "Rock_Marble_Cobble",
      "rotation": 33
    },
    {
      "x": -4,
      "y": 24,
      "z": -9,
      "name": "Rock_Marble_Cobble",
      "rotation": 33
    },
    {
      "x": -4,
      "y": 25,
      "z": -9,
      "name": "Rock_Marble",
      "rotation": 33
    },
    {
      "x": -4,
      "y": 26,
      "z": -9,
      "name": "Rock_Marble",
      "rotation": 33
    },
    {
      "x": -4,
      "y": 27,
      "z": -9,
      "name": "Rock_Marble_Cobble",
      "rotation": 33
    },
    {
      "x": -4,
      "y": 28,
      "z": -9,
      "name": "Rock_Marble",
      "rotation": 33
    },
    {
      "x": -4,
      "y": 29,
      "z": -9,
      "name": "Soil_Clay_White",
      "rotation": 33
    },
    {
      "x": -4,
      "y": 30,
      "z": -9,
      "name": "Rock_Marble",
      "rotation": 33
    },
    {
      "x": -4,
      "y": 0,
      "z": -8,
      "name": "Rock_Marble_Cobble",
      "rotation": 33
    },
    {
      "x": -4,
      "y": 1,
      "z": -8,
      "name": "Rock_Marble_Cobble",
      "rotation": 33
    },
    {
      "x": -4,
      "y": 2,
      "z": -8,
      "name": "Rock_Marble",
      "rotation": 33
    },
    {
      "x": -4,
      "y": 3,
      "z": -8,
      "name": "Soil_Clay_White",
      "rotation": 33
    },
    {
      "x": -4,
      "y": 4,
      "z": -8,
      "name": "Rock_Marble_Cobble",
      "rotation": 33
    },
    {
      "x": -4,
      "y": 5,
      "z": -8,
      "name": "Soil_Clay_GreyLight",
      "rotation": 33
    },
    {
      "x": -4,
      "y": 6,
      "z": -8,
      "name": "Rock_Marble",
      "rotation": 33
    },
    {
      "x": -4,
      "y": 7,
      "z": -8,
      "name": "Soil_Clay_White",
      "rotation": 33
    },
    {
      "x": -4,
      "y": 8,
      "z": -8,
      "name": "Rock_Marble",
      "rotation": 33
    },
    {
      "x": -4,
      "y": 9,
      "z": -8,
      "name": "Soil_Clay_White",
      "rotation": 33
    },
    {
      "x": -4,
      "y": 10,
      "z": -8,
      "name": "Rock_Chalk",
      "rotation": 33
    },
    {
      "x": -4,
      "y": 11,
      "z": -8,
      "name": "Rock_Chalk",
      "rotation": 33
    },
    {
      "x": -4,
      "y": 12,
      "z": -8,
      "name": "Rock_Chalk",
      "rotation": 33
    },
    {
      "x": -4,
      "y": 13,
      "z": -8,
      "name": "Rock_Marble",
      "rotation": 33
    },
    {
      "x": -4,
      "y": 14,
      "z": -8,
      "name": "Rock_Marble_Cobble",
      "rotation": 33
    },
    {
      "x": -4,
      "y": 15,
      "z": -8,
      "name": "Rock_Marble",
      "rotation": 33
    },
    {
      "x": -4,
      "y": 16,
      "z": -8,
      "name": "Soil_Clay_White",
      "rotation": 33
    },
    {
      "x": -4,
      "y": 17,
      "z": -8,
      "name": "Rock_Marble",
      "rotation": 33
    },
    {
      "x": -4,
      "y": 18,
      "z": -8,
      "name": "Soil_Clay_White",
      "rotation": 33
    },
    {
      "x": -4,
      "y": 19,
      "z": -8,
      "name": "Soil_Clay_White",
      "rotation": 33
    },
    {
      "x": -4,
      "y": 20,
      "z": -8,
      "name": "Rock_Marble",
      "rotation": 33
    },
    {
      "x": -4,
      "y": 21,
      "z": -8,
      "name": "Rock_Marble",
      "rotation": 33
    },
    {
      "x": -4,
      "y": 22,
      "z": -8,
      "name": "Rock_Marble",
      "rotation": 33
    },
    {
      "x": -4,
      "y": 23,
      "z": -8,
      "name": "Rock_Marble_Cobble",
      "rotation": 33
    },
    {
      "x": -4,
      "y": 24,
      "z": -8,
      "name": "Rock_Marble_Cobble",
      "rotation": 33
    },
    {
      "x": -4,
      "y": 25,
      "z": -8,
      "name": "Rock_Marble",
      "rotation": 33
    },
    {
      "x": -4,
      "y": 26,
      "z": -8,
      "name": "Rock_Marble",
      "rotation": 33
    },
    {
      "x": -4,
      "y": 27,
      "z": -8,
      "name": "Rock_Marble_Cobble",
      "rotation": 33
    },
    {
      "x": -4,
      "y": 28,
      "z": -8,
      "name": "Rock_Marble",
      "rotation": 33
    },
    {
      "x": -4,
      "y": 29,
      "z": -8,
      "name": "Soil_Clay_White",
      "rotation": 33
    },
    {
      "x": -4,
      "y": 30,
      "z": -8,
      "name": "Rock_Marble",
      "rotation": 33
    },
    {
      "x": -4,
      "y": 31,
      "z": -8,
      "name": "Rock_Marble_Cobble",
      "rotation": 33
    },
    {
      "x": -4,
      "y": 32,
      "z": -8,
      "name": "Rock_Marble_Cobble",
      "rotation": 33
    },
    {
      "x": -4,
      "y": 33,
      "z": -8,
      "name": "Rock_Marble_Cobble",
      "rotation": 33
    },
    {
      "x": -4,
      "y": 34,
      "z": -8,
      "name": "Rock_Marble",
      "rotation": 33
    },
    {
      "x": -4,
      "y": 35,
      "z": -8,
      "name": "Plant_Moss_Block_Green"
    },
    {
      "x": -4,
      "y": 0,
      "z": -7,
      "name": "Rock_Marble_Cobble",
      "rotation": 33
    },
    {
      "x": -4,
      "y": 1,
      "z": -7,
      "name": "Rock_Marble_Cobble",
      "rotation": 33
    },
    {
      "x": -4,
      "y": 2,
      "z": -7,
      "name": "Rock_Marble",
      "rotation": 33
    },
    {
      "x": -4,
      "y": 3,
      "z": -7,
      "name": "Soil_Clay_White",
      "rotation": 33
    },
    {
      "x": -4,
      "y": 4,
      "z": -7,
      "name": "Rock_Marble_Cobble",
      "rotation": 33
    },
    {
      "x": -4,
      "y": 5,
      "z": -7,
      "name": "Soil_Clay_GreyLight",
      "rotation": 33
    },
    {
      "x": -4,
      "y": 6,
      "z": -7,
      "name": "Rock_Marble",
      "rotation": 33
    },
    {
      "x": -4,
      "y": 7,
      "z": -7,
      "name": "Soil_Clay_White",
      "rotation": 33
    },
    {
      "x": -4,
      "y": 8,
      "z": -7,
      "name": "Rock_Marble",
      "rotation": 33
    },
    {
      "x": -4,
      "y": 9,
      "z": -7,
      "name": "Soil_Clay_White",
      "rotation": 33
    },
    {
      "x": -4,
      "y": 10,
      "z": -7,
      "name": "Rock_Chalk",
      "rotation": 33
    },
    {
      "x": -4,
      "y": 11,
      "z": -7,
      "name": "Rock_Chalk",
      "rotation": 33
    },
    {
      "x": -4,
      "y": 12,
      "z": -7,
      "name": "Rock_Chalk",
      "rotation": 33
    },
    {
      "x": -4,
      "y": 13,
      "z": -7,
      "name": "Rock_Marble",
      "rotation": 33
    },
    {
      "x": -4,
      "y": 14,
      "z": -7,
      "name": "Rock_Marble_Cobble",
      "rotation": 33
    },
    {
      "x": -4,
      "y": 15,
      "z": -7,
      "name": "Rock_Marble",
      "rotation": 33
    },
    {
      "x": -4,
      "y": 16,
      "z": -7,
      "name": "Soil_Clay_White",
      "rotation": 33
    },
    {
      "x": -4,
      "y": 17,
      "z": -7,
      "name": "Rock_Marble",
      "rotation": 33
    },
    {
      "x": -4,
      "y": 18,
      "z": -7,
      "name": "Soil_Clay_White",
      "rotation": 33
    },
    {
      "x": -4,
      "y": 19,
      "z": -7,
      "name": "Soil_Clay_White",
      "rotation": 33
    },
    {
      "x": -4,
      "y": 20,
      "z": -7,
      "name": "Rock_Marble",
      "rotation": 33
    },
    {
      "x": -4,
      "y": 21,
      "z": -7,
      "name": "Rock_Marble",
      "rotation": 33
    },
    {
      "x": -4,
      "y": 22,
      "z": -7,
      "name": "Rock_Marble",
      "rotation": 33
    },
    {
      "x": -4,
      "y": 23,
      "z": -7,
      "name": "Rock_Marble_Cobble",
      "rotation": 33
    },
    {
      "x": -4,
      "y": 24,
      "z": -7,
      "name": "Rock_Marble_Cobble",
      "rotation": 33
    },
    {
      "x": -4,
      "y": 25,
      "z": -7,
      "name": "Rock_Marble",
      "rotation": 33
    },
    {
      "x": -4,
      "y": 26,
      "z": -7,
      "name": "Rock_Marble",
      "rotation": 33
    },
    {
      "x": -4,
      "y": 27,
      "z": -7,
      "name": "Rock_Marble_Cobble",
      "rotation": 33
    },
    {
      "x": -4,
      "y": 28,
      "z": -7,
      "name": "Rock_Marble",
      "rotation": 33
    },
    {
      "x": -4,
      "y": 29,
      "z": -7,
      "name": "Soil_Clay_White",
      "rotation": 33
    },
    {
      "x": -4,
      "y": 30,
      "z": -7,
      "name": "Rock_Marble",
      "rotation": 33
    },
    {
      "x": -4,
      "y": 31,
      "z": -7,
      "name": "Rock_Marble_Cobble",
      "rotation": 33
    },
    {
      "x": -4,
      "y": 32,
      "z": -7,
      "name": "Rock_Marble_Cobble",
      "rotation": 33
    },
    {
      "x": -4,
      "y": 33,
      "z": -7,
      "name": "Rock_Marble_Cobble",
      "rotation": 33
    },
    {
      "x": -4,
      "y": 34,
      "z": -7,
      "name": "Rock_Marble",
      "rotation": 33
    },
    {
      "x": -4,
      "y": 35,
      "z": -7,
      "name": "Plant_Moss_Block_Green"
    },
    {
      "x": -4,
      "y": 36,
      "z": -7,
      "name": "Plant_Moss_Block_Green"
    },
    {
      "x": -4,
      "y": 0,
      "z": -6,
      "name": "Rock_Marble_Cobble",
      "rotation": 33
    },
    {
      "x": -4,
      "y": 1,
      "z": -6,
      "name": "Rock_Marble_Cobble",
      "rotation": 33
    },
    {
      "x": -4,
      "y": 2,
      "z": -6,
      "name": "Rock_Marble",
      "rotation": 33
    },
    {
      "x": -4,
      "y": 3,
      "z": -6,
      "name": "Soil_Clay_White",
      "rotation": 33
    },
    {
      "x": -4,
      "y": 4,
      "z": -6,
      "name": "Rock_Marble_Cobble",
      "rotation": 33
    },
    {
      "x": -4,
      "y": 5,
      "z": -6,
      "name": "Soil_Clay_GreyLight",
      "rotation": 33
    },
    {
      "x": -4,
      "y": 6,
      "z": -6,
      "name": "Rock_Marble",
      "rotation": 33
    },
    {
      "x": -4,
      "y": 7,
      "z": -6,
      "name": "Soil_Clay_White",
      "rotation": 33
    },
    {
      "x": -4,
      "y": 8,
      "z": -6,
      "name": "Rock_Marble",
      "rotation": 33
    },
    {
      "x": -4,
      "y": 9,
      "z": -6,
      "name": "Soil_Clay_White",
      "rotation": 33
    },
    {
      "x": -4,
      "y": 10,
      "z": -6,
      "name": "Rock_Chalk",
      "rotation": 33
    },
    {
      "x": -4,
      "y": 11,
      "z": -6,
      "name": "Rock_Chalk",
      "rotation": 33
    },
    {
      "x": -4,
      "y": 12,
      "z": -6,
      "name": "Rock_Chalk",
      "rotation": 33
    },
    {
      "x": -4,
      "y": 13,
      "z": -6,
      "name": "Rock_Marble",
      "rotation": 33
    },
    {
      "x": -4,
      "y": 14,
      "z": -6,
      "name": "Rock_Marble_Cobble",
      "rotation": 33
    },
    {
      "x": -4,
      "y": 15,
      "z": -6,
      "name": "Rock_Marble",
      "rotation": 33
    },
    {
      "x": -4,
      "y": 16,
      "z": -6,
      "name": "Soil_Clay_White",
      "rotation": 33
    },
    {
      "x": -4,
      "y": 17,
      "z": -6,
      "name": "Rock_Marble",
      "rotation": 33
    },
    {
      "x": -4,
      "y": 18,
      "z": -6,
      "name": "Soil_Clay_White",
      "rotation": 33
    },
    {
      "x": -4,
      "y": 19,
      "z": -6,
      "name": "Soil_Clay_White",
      "rotation": 33
    },
    {
      "x": -4,
      "y": 20,
      "z": -6,
      "name": "Rock_Marble",
      "rotation": 33
    },
    {
      "x": -4,
      "y": 21,
      "z": -6,
      "name": "Rock_Marble",
      "rotation": 33
    },
    {
      "x": -4,
      "y": 22,
      "z": -6,
      "name": "Rock_Marble",
      "rotation": 33
    },
    {
      "x": -4,
      "y": 23,
      "z": -6,
      "name": "Rock_Marble_Cobble",
      "rotation": 33
    },
    {
      "x": -4,
      "y": 24,
      "z": -6,
      "name": "Rock_Marble_Cobble",
      "rotation": 33
    },
    {
      "x": -4,
      "y": 25,
      "z": -6,
      "name": "Rock_Marble",
      "rotation": 33
    },
    {
      "x": -4,
      "y": 26,
      "z": -6,
      "name": "Rock_Marble",
      "rotation": 33
    },
    {
      "x": -4,
      "y": 27,
      "z": -6,
      "name": "Rock_Marble_Cobble",
      "rotation": 33
    },
    {
      "x": -4,
      "y": 28,
      "z": -6,
      "name": "Rock_Marble",
      "rotation": 33
    },
    {
      "x": -4,
      "y": 29,
      "z": -6,
      "name": "Soil_Clay_White",
      "rotation": 33
    },
    {
      "x": -4,
      "y": 30,
      "z": -6,
      "name": "Rock_Marble",
      "rotation": 33
    },
    {
      "x": -4,
      "y": 31,
      "z": -6,
      "name": "Rock_Marble_Cobble",
      "rotation": 33
    },
    {
      "x": -4,
      "y": 32,
      "z": -6,
      "name": "Rock_Marble_Cobble",
      "rotation": 33
    },
    {
      "x": -4,
      "y": 33,
      "z": -6,
      "name": "Rock_Marble_Cobble",
      "rotation": 33
    },
    {
      "x": -4,
      "y": 34,
      "z": -6,
      "name": "Plant_Moss_Block_Green"
    },
    {
      "x": -4,
      "y": 35,
      "z": -6,
      "name": "Plant_Moss_Block_Green"
    },
    {
      "x": -4,
      "y": 0,
      "z": -5,
      "name": "Rock_Marble_Cobble",
      "rotation": 33
    },
    {
      "x": -4,
      "y": 1,
      "z": -5,
      "name": "Rock_Marble_Cobble",
      "rotation": 33
    },
    {
      "x": -4,
      "y": 2,
      "z": -5,
      "name": "Rock_Marble",
      "rotation": 33
    },
    {
      "x": -4,
      "y": 3,
      "z": -5,
      "name": "Soil_Clay_White",
      "rotation": 33
    },
    {
      "x": -4,
      "y": 4,
      "z": -5,
      "name": "Rock_Marble_Cobble",
      "rotation": 33
    },
    {
      "x": -4,
      "y": 5,
      "z": -5,
      "name": "Soil_Clay_GreyLight",
      "rotation": 33
    },
    {
      "x": -4,
      "y": 6,
      "z": -5,
      "name": "Rock_Marble",
      "rotation": 33
    },
    {
      "x": -4,
      "y": 7,
      "z": -5,
      "name": "Soil_Clay_White",
      "rotation": 33
    },
    {
      "x": -4,
      "y": 8,
      "z": -5,
      "name": "Rock_Marble",
      "rotation": 33
    },
    {
      "x": -4,
      "y": 9,
      "z": -5,
      "name": "Soil_Clay_White",
      "rotation": 33
    },
    {
      "x": -4,
      "y": 10,
      "z": -5,
      "name": "Rock_Chalk",
      "rotation": 33
    },
    {
      "x": -4,
      "y": 11,
      "z": -5,
      "name": "Rock_Chalk",
      "rotation": 33
    },
    {
      "x": -4,
      "y": 12,
      "z": -5,
      "name": "Rock_Chalk",
      "rotation": 33
    },
    {
      "x": -4,
      "y": 13,
      "z": -5,
      "name": "Rock_Marble",
      "rotation": 33
    },
    {
      "x": -4,
      "y": 14,
      "z": -5,
      "name": "Rock_Marble_Cobble",
      "rotation": 33
    },
    {
      "x": -4,
      "y": 15,
      "z": -5,
      "name": "Rock_Marble",
      "rotation": 33
    },
    {
      "x": -4,
      "y": 16,
      "z": -5,
      "name": "Soil_Clay_White",
      "rotation": 33
    },
    {
      "x": -4,
      "y": 17,
      "z": -5,
      "name": "Rock_Marble",
      "rotation": 33
    },
    {
      "x": -4,
      "y": 18,
      "z": -5,
      "name": "Soil_Clay_White",
      "rotation": 33
    },
    {
      "x": -4,
      "y": 19,
      "z": -5,
      "name": "Soil_Clay_White",
      "rotation": 33
    },
    {
      "x": -4,
      "y": 20,
      "z": -5,
      "name": "Rock_Marble",
      "rotation": 33
    },
    {
      "x": -4,
      "y": 21,
      "z": -5,
      "name": "Rock_Marble",
      "rotation": 33
    },
    {
      "x": -4,
      "y": 22,
      "z": -5,
      "name": "Soil_Clay_White",
      "rotation": 33
    },
    {
      "x": -4,
      "y": 23,
      "z": -5,
      "name": "Rock_Marble_Cobble",
      "rotation": 33
    },
    {
      "x": -4,
      "y": 24,
      "z": -5,
      "name": "Rock_Marble_Cobble",
      "rotation": 33
    },
    {
      "x": -4,
      "y": 25,
      "z": -5,
      "name": "Rock_Marble",
      "rotation": 33
    },
    {
      "x": -4,
      "y": 26,
      "z": -5,
      "name": "Rock_Marble",
      "rotation": 33
    },
    {
      "x": -4,
      "y": 27,
      "z": -5,
      "name": "Rock_Marble_Cobble",
      "rotation": 33
    },
    {
      "x": -4,
      "y": 28,
      "z": -5,
      "name": "Rock_Marble",
      "rotation": 33
    },
    {
      "x": -4,
      "y": 31,
      "z": -5,
      "name": "Rock_Marble_Cobble",
      "rotation": 33
    },
    {
      "x": -4,
      "y": 32,
      "z": -5,
      "name": "Rock_Marble_Cobble",
      "rotation": 33
    },
    {
      "x": -4,
      "y": 33,
      "z": -5,
      "name": "Plant_Moss_Block_Green"
    },
    {
      "x": -4,
      "y": 1,
      "z": -4,
      "name": "Rock_Marble_Cobble",
      "rotation": 33
    },
    {
      "x": -4,
      "y": 2,
      "z": -4,
      "name": "Rock_Marble",
      "rotation": 33
    },
    {
      "x": -4,
      "y": 3,
      "z": -4,
      "name": "Soil_Clay_White",
      "rotation": 33
    },
    {
      "x": -4,
      "y": 4,
      "z": -4,
      "name": "Rock_Marble_Cobble",
      "rotation": 33
    },
    {
      "x": -4,
      "y": 5,
      "z": -4,
      "name": "Soil_Clay_GreyLight",
      "rotation": 33
    },
    {
      "x": -4,
      "y": 6,
      "z": -4,
      "name": "Rock_Marble",
      "rotation": 33
    },
    {
      "x": -4,
      "y": 7,
      "z": -4,
      "name": "Soil_Clay_White",
      "rotation": 33
    },
    {
      "x": -4,
      "y": 8,
      "z": -4,
      "name": "Soil_Clay_White",
      "rotation": 33
    },
    {
      "x": -4,
      "y": 9,
      "z": -4,
      "name": "Soil_Clay_White",
      "rotation": 33
    },
    {
      "x": -4,
      "y": 10,
      "z": -4,
      "name": "Rock_Chalk",
      "rotation": 33
    },
    {
      "x": -4,
      "y": 11,
      "z": -4,
      "name": "Rock_Chalk",
      "rotation": 33
    },
    {
      "x": -4,
      "y": 12,
      "z": -4,
      "name": "Rock_Chalk",
      "rotation": 33
    },
    {
      "x": -4,
      "y": 13,
      "z": -4,
      "name": "Rock_Marble",
      "rotation": 33
    },
    {
      "x": -4,
      "y": 14,
      "z": -4,
      "name": "Rock_Marble_Cobble",
      "rotation": 33
    },
    {
      "x": -4,
      "y": 15,
      "z": -4,
      "name": "Rock_Marble",
      "rotation": 33
    },
    {
      "x": -4,
      "y": 16,
      "z": -4,
      "name": "Soil_Clay_White",
      "rotation": 33
    },
    {
      "x": -4,
      "y": 17,
      "z": -4,
      "name": "Rock_Marble",
      "rotation": 33
    },
    {
      "x": -4,
      "y": 18,
      "z": -4,
      "name": "Soil_Clay_White",
      "rotation": 33
    },
    {
      "x": -4,
      "y": 19,
      "z": -4,
      "name": "Soil_Clay_White",
      "rotation": 33
    },
    {
      "x": -4,
      "y": 20,
      "z": -4,
      "name": "Rock_Marble",
      "rotation": 33
    },
    {
      "x": -4,
      "y": 33,
      "z": -4,
      "name": "Plant_Moss_Wall_Green"
    },
    {
      "x": -4,
      "y": 1,
      "z": -3,
      "name": "Rock_Marble_Cobble",
      "rotation": 33
    },
    {
      "x": -4,
      "y": 2,
      "z": -3,
      "name": "Rock_Marble",
      "rotation": 33
    },
    {
      "x": -4,
      "y": 3,
      "z": -3,
      "name": "Soil_Clay_White",
      "rotation": 33
    },
    {
      "x": -4,
      "y": 4,
      "z": -3,
      "name": "Rock_Marble_Cobble",
      "rotation": 33
    },
    {
      "x": -4,
      "y": 5,
      "z": -3,
      "name": "Soil_Clay_GreyLight",
      "rotation": 33
    },
    {
      "x": -4,
      "y": 6,
      "z": -3,
      "name": "Rock_Marble",
      "rotation": 33
    },
    {
      "x": -4,
      "y": 7,
      "z": -3,
      "name": "Soil_Clay_White",
      "rotation": 33
    },
    {
      "x": -4,
      "y": 8,
      "z": -3,
      "name": "Soil_Clay_White",
      "rotation": 33
    },
    {
      "x": -4,
      "y": 9,
      "z": -3,
      "name": "Soil_Clay_White",
      "rotation": 33
    },
    {
      "x": -4,
      "y": 10,
      "z": -3,
      "name": "Rock_Chalk",
      "rotation": 33
    },
    {
      "x": -4,
      "y": 11,
      "z": -3,
      "name": "Rock_Chalk",
      "rotation": 33
    },
    {
      "x": -4,
      "y": 12,
      "z": -3,
      "name": "Soil_Clay_White",
      "rotation": 33
    },
    {
      "x": -4,
      "y": 13,
      "z": -3,
      "name": "Rock_Marble",
      "rotation": 33
    },
    {
      "x": -4,
      "y": 14,
      "z": -3,
      "name": "Rock_Marble_Cobble",
      "rotation": 33
    },
    {
      "x": -4,
      "y": 15,
      "z": -3,
      "name": "Rock_Marble",
      "rotation": 33
    },
    {
      "x": -4,
      "y": 16,
      "z": -3,
      "name": "Soil_Clay_White",
      "rotation": 33
    },
    {
      "x": -4,
      "y": 17,
      "z": -3,
      "name": "Rock_Marble",
      "rotation": 33
    },
    {
      "x": -4,
      "y": 3,
      "z": -2,
      "name": "Soil_Clay_White",
      "rotation": 33
    },
    {
      "x": -4,
      "y": 4,
      "z": -2,
      "name": "Rock_Marble_Cobble",
      "rotation": 33
    },
    {
      "x": -4,
      "y": 5,
      "z": -2,
      "name": "Soil_Clay_GreyLight",
      "rotation": 33
    },
    {
      "x": -4,
      "y": 12,
      "z": -2,
      "name": "Soil_Clay_White",
      "rotation": 33
    },
    {
      "x": -4,
      "y": 13,
      "z": -2,
      "name": "Rock_Marble",
      "rotation": 33
    },
    {
      "x": -4,
      "y": 14,
      "z": -2,
      "name": "Rock_Marble_Cobble",
      "rotation": 33
    },
    {
      "x": -4,
      "y": 15,
      "z": -2,
      "name": "Rock_Marble",
      "rotation": 33
    },
    {
      "x": -3,
      "y": 2,
      "z": -11,
      "name": "Rock_Marble",
      "rotation": 33
    },
    {
      "x": -3,
      "y": 3,
      "z": -11,
      "name": "Rock_Marble",
      "rotation": 33
    },
    {
      "x": -3,
      "y": 4,
      "z": -11,
      "name": "Rock_Marble_Cobble",
      "rotation": 33
    },
    {
      "x": -3,
      "y": 5,
      "z": -11,
      "name": "Soil_Clay_GreyLight",
      "rotation": 33
    },
    {
      "x": -3,
      "y": 6,
      "z": -11,
      "name": "Rock_Marble",
      "rotation": 33
    },
    {
      "x": -3,
      "y": 7,
      "z": -11,
      "name": "Soil_Clay_White",
      "rotation": 33
    },
    {
      "x": -3,
      "y": 8,
      "z": -11,
      "name": "Rock_Marble",
      "rotation": 33
    },
    {
      "x": -3,
      "y": 9,
      "z": -11,
      "name": "Soil_Clay_White",
      "rotation": 33
    },
    {
      "x": -3,
      "y": 10,
      "z": -11,
      "name": "Soil_Clay_White",
      "rotation": 33
    },
    {
      "x": -3,
      "y": 11,
      "z": -11,
      "name": "Rock_Chalk",
      "rotation": 33
    },
    {
      "x": -3,
      "y": 12,
      "z": -11,
      "name": "Rock_Chalk",
      "rotation": 33
    },
    {
      "x": -3,
      "y": 13,
      "z": -11,
      "name": "Rock_Marble",
      "rotation": 33
    },
    {
      "x": -3,
      "y": 14,
      "z": -11,
      "name": "Rock_Marble_Cobble",
      "rotation": 33
    },
    {
      "x": -3,
      "y": 15,
      "z": -11,
      "name": "Rock_Marble",
      "rotation": 33
    },
    {
      "x": -3,
      "y": 18,
      "z": -11,
      "name": "Soil_Clay_White",
      "rotation": 33
    },
    {
      "x": -3,
      "y": 19,
      "z": -11,
      "name": "Soil_Clay_White",
      "rotation": 33
    },
    {
      "x": -3,
      "y": 20,
      "z": -11,
      "name": "Rock_Marble",
      "rotation": 33
    },
    {
      "x": -3,
      "y": 1,
      "z": -10,
      "name": "Rock_Marble_Cobble",
      "rotation": 33
    },
    {
      "x": -3,
      "y": 2,
      "z": -10,
      "name": "Rock_Marble",
      "rotation": 33
    },
    {
      "x": -3,
      "y": 3,
      "z": -10,
      "name": "Rock_Marble",
      "rotation": 33
    },
    {
      "x": -3,
      "y": 4,
      "z": -10,
      "name": "Rock_Marble_Cobble",
      "rotation": 33
    },
    {
      "x": -3,
      "y": 5,
      "z": -10,
      "name": "Soil_Clay_GreyLight",
      "rotation": 33
    },
    {
      "x": -3,
      "y": 6,
      "z": -10,
      "name": "Rock_Marble",
      "rotation": 33
    },
    {
      "x": -3,
      "y": 7,
      "z": -10,
      "name": "Soil_Clay_White",
      "rotation": 33
    },
    {
      "x": -3,
      "y": 8,
      "z": -10,
      "name": "Rock_Marble",
      "rotation": 33
    },
    {
      "x": -3,
      "y": 9,
      "z": -10,
      "name": "Soil_Clay_White",
      "rotation": 33
    },
    {
      "x": -3,
      "y": 10,
      "z": -10,
      "name": "Soil_Clay_White",
      "rotation": 33
    },
    {
      "x": -3,
      "y": 11,
      "z": -10,
      "name": "Rock_Chalk",
      "rotation": 33
    },
    {
      "x": -3,
      "y": 12,
      "z": -10,
      "name": "Rock_Chalk",
      "rotation": 33
    },
    {
      "x": -3,
      "y": 13,
      "z": -10,
      "name": "Rock_Marble",
      "rotation": 33
    },
    {
      "x": -3,
      "y": 14,
      "z": -10,
      "name": "Rock_Marble_Cobble",
      "rotation": 33
    },
    {
      "x": -3,
      "y": 15,
      "z": -10,
      "name": "Rock_Marble",
      "rotation": 33
    },
    {
      "x": -3,
      "y": 16,
      "z": -10,
      "name": "Soil_Clay_White",
      "rotation": 33
    },
    {
      "x": -3,
      "y": 17,
      "z": -10,
      "name": "Soil_Clay_White",
      "rotation": 33
    },
    {
      "x": -3,
      "y": 18,
      "z": -10,
      "name": "Soil_Clay_White",
      "rotation": 33
    },
    {
      "x": -3,
      "y": 19,
      "z": -10,
      "name": "Soil_Clay_White",
      "rotation": 33
    },
    {
      "x": -3,
      "y": 20,
      "z": -10,
      "name": "Rock_Marble",
      "rotation": 33
    },
    {
      "x": -3,
      "y": 21,
      "z": -10,
      "name": "Rock_Marble",
      "rotation": 33
    },
    {
      "x": -3,
      "y": 22,
      "z": -10,
      "name": "Rock_Marble",
      "rotation": 33
    },
    {
      "x": -3,
      "y": 23,
      "z": -10,
      "name": "Rock_Marble_Cobble",
      "rotation": 33
    },
    {
      "x": -3,
      "y": 24,
      "z": -10,
      "name": "Rock_Marble_Cobble",
      "rotation": 33
    },
    {
      "x": -3,
      "y": 25,
      "z": -10,
      "name": "Rock_Marble",
      "rotation": 33
    },
    {
      "x": -3,
      "y": 0,
      "z": -9,
      "name": "Rock_Marble_Cobble",
      "rotation": 33
    },
    {
      "x": -3,
      "y": 1,
      "z": -9,
      "name": "Rock_Marble_Cobble",
      "rotation": 33
    },
    {
      "x": -3,
      "y": 2,
      "z": -9,
      "name": "Rock_Marble",
      "rotation": 33
    },
    {
      "x": -3,
      "y": 3,
      "z": -9,
      "name": "Rock_Marble",
      "rotation": 33
    },
    {
      "x": -3,
      "y": 4,
      "z": -9,
      "name": "Rock_Marble_Cobble",
      "rotation": 33
    },
    {
      "x": -3,
      "y": 5,
      "z": -9,
      "name": "Soil_Clay_GreyLight",
      "rotation": 33
    },
    {
      "x": -3,
      "y": 6,
      "z": -9,
      "name": "Rock_Marble",
      "rotation": 33
    },
    {
      "x": -3,
      "y": 7,
      "z": -9,
      "name": "Soil_Clay_White",
      "rotation": 33
    },
    {
      "x": -3,
      "y": 8,
      "z": -9,
      "name": "Rock_Marble",
      "rotation": 33
    },
    {
      "x": -3,
      "y": 9,
      "z": -9,
      "name": "Soil_Clay_White",
      "rotation": 33
    },
    {
      "x": -3,
      "y": 10,
      "z": -9,
      "name": "Rock_Chalk",
      "rotation": 33
    },
    {
      "x": -3,
      "y": 11,
      "z": -9,
      "name": "Rock_Chalk",
      "rotation": 33
    },
    {
      "x": -3,
      "y": 12,
      "z": -9,
      "name": "Rock_Chalk",
      "rotation": 33
    },
    {
      "x": -3,
      "y": 13,
      "z": -9,
      "name": "Rock_Marble",
      "rotation": 33
    },
    {
      "x": -3,
      "y": 14,
      "z": -9,
      "name": "Rock_Marble_Cobble",
      "rotation": 33
    },
    {
      "x": -3,
      "y": 15,
      "z": -9,
      "name": "Rock_Marble",
      "rotation": 33
    },
    {
      "x": -3,
      "y": 16,
      "z": -9,
      "name": "Soil_Clay_White",
      "rotation": 33
    },
    {
      "x": -3,
      "y": 17,
      "z": -9,
      "name": "Soil_Clay_White",
      "rotation": 33
    },
    {
      "x": -3,
      "y": 18,
      "z": -9,
      "name": "Soil_Clay_White",
      "rotation": 33
    },
    {
      "x": -3,
      "y": 19,
      "z": -9,
      "name": "Soil_Clay_White",
      "rotation": 33
    },
    {
      "x": -3,
      "y": 20,
      "z": -9,
      "name": "Rock_Marble",
      "rotation": 33
    },
    {
      "x": -3,
      "y": 21,
      "z": -9,
      "name": "Rock_Marble",
      "rotation": 33
    },
    {
      "x": -3,
      "y": 22,
      "z": -9,
      "name": "Rock_Marble",
      "rotation": 33
    },
    {
      "x": -3,
      "y": 23,
      "z": -9,
      "name": "Rock_Marble_Cobble",
      "rotation": 33
    },
    {
      "x": -3,
      "y": 24,
      "z": -9,
      "name": "Rock_Marble_Cobble",
      "rotation": 33
    },
    {
      "x": -3,
      "y": 25,
      "z": -9,
      "name": "Rock_Marble",
      "rotation": 33
    },
    {
      "x": -3,
      "y": 26,
      "z": -9,
      "name": "Rock_Marble",
      "rotation": 33
    },
    {
      "x": -3,
      "y": 27,
      "z": -9,
      "name": "Rock_Marble_Cobble",
      "rotation": 33
    },
    {
      "x": -3,
      "y": 28,
      "z": -9,
      "name": "Rock_Marble",
      "rotation": 33
    },
    {
      "x": -3,
      "y": 29,
      "z": -9,
      "name": "Soil_Clay_White",
      "rotation": 33
    },
    {
      "x": -3,
      "y": 30,
      "z": -9,
      "name": "Rock_Marble",
      "rotation": 33
    },
    {
      "x": -3,
      "y": 31,
      "z": -9,
      "name": "Rock_Marble_Cobble",
      "rotation": 33
    },
    {
      "x": -3,
      "y": 32,
      "z": -9,
      "name": "Rock_Marble_Cobble",
      "rotation": 33
    },
    {
      "x": -3,
      "y": 35,
      "z": -9,
      "name": "Plant_Moss_Wall_Green",
      "rotation": 2
    },
    {
      "x": -3,
      "y": 0,
      "z": -8,
      "name": "Rock_Marble_Cobble",
      "rotation": 33
    },
    {
      "x": -3,
      "y": 1,
      "z": -8,
      "name": "Rock_Marble_Cobble",
      "rotation": 33
    },
    {
      "x": -3,
      "y": 2,
      "z": -8,
      "name": "Rock_Marble",
      "rotation": 33
    },
    {
      "x": -3,
      "y": 3,
      "z": -8,
      "name": "Rock_Marble",
      "rotation": 33
    },
    {
      "x": -3,
      "y": 4,
      "z": -8,
      "name": "Rock_Marble_Cobble",
      "rotation": 33
    },
    {
      "x": -3,
      "y": 5,
      "z": -8,
      "name": "Soil_Clay_GreyLight",
      "rotation": 33
    },
    {
      "x": -3,
      "y": 6,
      "z": -8,
      "name": "Rock_Marble",
      "rotation": 33
    },
    {
      "x": -3,
      "y": 7,
      "z": -8,
      "name": "Soil_Clay_White",
      "rotation": 33
    },
    {
      "x": -3,
      "y": 8,
      "z": -8,
      "name": "Rock_Marble",
      "rotation": 33
    },
    {
      "x": -3,
      "y": 9,
      "z": -8,
      "name": "Soil_Clay_White",
      "rotation": 33
    },
    {
      "x": -3,
      "y": 10,
      "z": -8,
      "name": "Rock_Chalk",
      "rotation": 33
    },
    {
      "x": -3,
      "y": 11,
      "z": -8,
      "name": "Rock_Chalk",
      "rotation": 33
    },
    {
      "x": -3,
      "y": 12,
      "z": -8,
      "name": "Rock_Chalk",
      "rotation": 33
    },
    {
      "x": -3,
      "y": 13,
      "z": -8,
      "name": "Rock_Marble",
      "rotation": 33
    },
    {
      "x": -3,
      "y": 14,
      "z": -8,
      "name": "Rock_Marble_Cobble",
      "rotation": 33
    },
    {
      "x": -3,
      "y": 15,
      "z": -8,
      "name": "Rock_Marble",
      "rotation": 33
    },
    {
      "x": -3,
      "y": 16,
      "z": -8,
      "name": "Soil_Clay_White",
      "rotation": 33
    },
    {
      "x": -3,
      "y": 17,
      "z": -8,
      "name": "Rock_Marble",
      "rotation": 33
    },
    {
      "x": -3,
      "y": 18,
      "z": -8,
      "name": "Soil_Clay_White",
      "rotation": 33
    },
    {
      "x": -3,
      "y": 19,
      "z": -8,
      "name": "Soil_Clay_White",
      "rotation": 33
    },
    {
      "x": -3,
      "y": 20,
      "z": -8,
      "name": "Rock_Marble",
      "rotation": 33
    },
    {
      "x": -3,
      "y": 21,
      "z": -8,
      "name": "Rock_Marble",
      "rotation": 33
    },
    {
      "x": -3,
      "y": 22,
      "z": -8,
      "name": "Rock_Marble",
      "rotation": 33
    },
    {
      "x": -3,
      "y": 23,
      "z": -8,
      "name": "Rock_Marble_Cobble",
      "rotation": 33
    },
    {
      "x": -3,
      "y": 24,
      "z": -8,
      "name": "Rock_Marble_Cobble",
      "rotation": 33
    },
    {
      "x": -3,
      "y": 25,
      "z": -8,
      "name": "Rock_Marble",
      "rotation": 33
    },
    {
      "x": -3,
      "y": 26,
      "z": -8,
      "name": "Rock_Marble",
      "rotation": 33
    },
    {
      "x": -3,
      "y": 27,
      "z": -8,
      "name": "Rock_Marble_Cobble",
      "rotation": 33
    },
    {
      "x": -3,
      "y": 28,
      "z": -8,
      "name": "Rock_Marble",
      "rotation": 33
    },
    {
      "x": -3,
      "y": 29,
      "z": -8,
      "name": "Soil_Clay_White",
      "rotation": 33
    },
    {
      "x": -3,
      "y": 30,
      "z": -8,
      "name": "Rock_Marble",
      "rotation": 33
    },
    {
      "x": -3,
      "y": 31,
      "z": -8,
      "name": "Rock_Marble_Cobble",
      "rotation": 33
    },
    {
      "x": -3,
      "y": 32,
      "z": -8,
      "name": "Rock_Marble_Cobble",
      "rotation": 33
    },
    {
      "x": -3,
      "y": 33,
      "z": -8,
      "name": "Rock_Marble_Cobble",
      "rotation": 33
    },
    {
      "x": -3,
      "y": 34,
      "z": -8,
      "name": "Rock_Marble",
      "rotation": 33
    },
    {
      "x": -3,
      "y": 35,
      "z": -8,
      "name": "Plant_Moss_Block_Green"
    },
    {
      "x": -3,
      "y": 36,
      "z": -8,
      "name": "Plant_Moss_Block_Green"
    },
    {
      "x": -3,
      "y": 0,
      "z": -7,
      "name": "Rock_Marble_Cobble",
      "rotation": 33
    },
    {
      "x": -3,
      "y": 1,
      "z": -7,
      "name": "Rock_Marble_Cobble",
      "rotation": 33
    },
    {
      "x": -3,
      "y": 2,
      "z": -7,
      "name": "Rock_Marble",
      "rotation": 33
    },
    {
      "x": -3,
      "y": 3,
      "z": -7,
      "name": "Rock_Marble",
      "rotation": 33
    },
    {
      "x": -3,
      "y": 4,
      "z": -7,
      "name": "Rock_Marble_Cobble",
      "rotation": 33
    },
    {
      "x": -3,
      "y": 5,
      "z": -7,
      "name": "Soil_Clay_GreyLight",
      "rotation": 33
    },
    {
      "x": -3,
      "y": 6,
      "z": -7,
      "name": "Rock_Marble",
      "rotation": 33
    },
    {
      "x": -3,
      "y": 7,
      "z": -7,
      "name": "Soil_Clay_White",
      "rotation": 33
    },
    {
      "x": -3,
      "y": 8,
      "z": -7,
      "name": "Rock_Marble",
      "rotation": 33
    },
    {
      "x": -3,
      "y": 9,
      "z": -7,
      "name": "Soil_Clay_White",
      "rotation": 33
    },
    {
      "x": -3,
      "y": 10,
      "z": -7,
      "name": "Rock_Chalk",
      "rotation": 33
    },
    {
      "x": -3,
      "y": 11,
      "z": -7,
      "name": "Rock_Chalk",
      "rotation": 33
    },
    {
      "x": -3,
      "y": 12,
      "z": -7,
      "name": "Rock_Chalk",
      "rotation": 33
    },
    {
      "x": -3,
      "y": 13,
      "z": -7,
      "name": "Rock_Marble",
      "rotation": 33
    },
    {
      "x": -3,
      "y": 14,
      "z": -7,
      "name": "Rock_Marble_Cobble",
      "rotation": 33
    },
    {
      "x": -3,
      "y": 15,
      "z": -7,
      "name": "Rock_Marble",
      "rotation": 33
    },
    {
      "x": -3,
      "y": 16,
      "z": -7,
      "name": "Soil_Clay_White",
      "rotation": 33
    },
    {
      "x": -3,
      "y": 17,
      "z": -7,
      "name": "Rock_Marble",
      "rotation": 33
    },
    {
      "x": -3,
      "y": 18,
      "z": -7,
      "name": "Soil_Clay_White",
      "rotation": 33
    },
    {
      "x": -3,
      "y": 19,
      "z": -7,
      "name": "Soil_Clay_White",
      "rotation": 33
    },
    {
      "x": -3,
      "y": 20,
      "z": -7,
      "name": "Rock_Marble",
      "rotation": 33
    },
    {
      "x": -3,
      "y": 21,
      "z": -7,
      "name": "Rock_Marble",
      "rotation": 33
    },
    {
      "x": -3,
      "y": 22,
      "z": -7,
      "name": "Rock_Marble",
      "rotation": 33
    },
    {
      "x": -3,
      "y": 23,
      "z": -7,
      "name": "Rock_Marble_Cobble",
      "rotation": 33
    },
    {
      "x": -3,
      "y": 24,
      "z": -7,
      "name": "Rock_Marble_Cobble",
      "rotation": 33
    },
    {
      "x": -3,
      "y": 25,
      "z": -7,
      "name": "Rock_Marble",
      "rotation": 33
    },
    {
      "x": -3,
      "y": 26,
      "z": -7,
      "name": "Rock_Marble",
      "rotation": 33
    },
    {
      "x": -3,
      "y": 27,
      "z": -7,
      "name": "Rock_Marble_Cobble",
      "rotation": 33
    },
    {
      "x": -3,
      "y": 28,
      "z": -7,
      "name": "Rock_Marble",
      "rotation": 33
    },
    {
      "x": -3,
      "y": 29,
      "z": -7,
      "name": "Soil_Clay_White",
      "rotation": 33
    },
    {
      "x": -3,
      "y": 30,
      "z": -7,
      "name": "Rock_Marble",
      "rotation": 33
    },
    {
      "x": -3,
      "y": 31,
      "z": -7,
      "name": "Rock_Marble_Cobble",
      "rotation": 33
    },
    {
      "x": -3,
      "y": 32,
      "z": -7,
      "name": "Rock_Marble_Cobble",
      "rotation": 33
    },
    {
      "x": -3,
      "y": 33,
      "z": -7,
      "name": "Rock_Marble_Cobble",
      "rotation": 33
    },
    {
      "x": -3,
      "y": 34,
      "z": -7,
      "name": "Rock_Marble",
      "rotation": 33
    },
    {
      "x": -3,
      "y": 35,
      "z": -7,
      "name": "Plant_Moss_Block_Green"
    },
    {
      "x": -3,
      "y": 36,
      "z": -7,
      "name": "Plant_Moss_Block_Green"
    },
    {
      "x": -3,
      "y": 0,
      "z": -6,
      "name": "Rock_Marble_Cobble",
      "rotation": 33
    },
    {
      "x": -3,
      "y": 1,
      "z": -6,
      "name": "Rock_Marble_Cobble",
      "rotation": 33
    },
    {
      "x": -3,
      "y": 2,
      "z": -6,
      "name": "Rock_Marble",
      "rotation": 33
    },
    {
      "x": -3,
      "y": 3,
      "z": -6,
      "name": "Rock_Marble",
      "rotation": 33
    },
    {
      "x": -3,
      "y": 4,
      "z": -6,
      "name": "Rock_Marble_Cobble",
      "rotation": 33
    },
    {
      "x": -3,
      "y": 5,
      "z": -6,
      "name": "Soil_Clay_GreyLight",
      "rotation": 33
    },
    {
      "x": -3,
      "y": 6,
      "z": -6,
      "name": "Rock_Marble",
      "rotation": 33
    },
    {
      "x": -3,
      "y": 7,
      "z": -6,
      "name": "Soil_Clay_White",
      "rotation": 33
    },
    {
      "x": -3,
      "y": 8,
      "z": -6,
      "name": "Rock_Marble",
      "rotation": 33
    },
    {
      "x": -3,
      "y": 9,
      "z": -6,
      "name": "Soil_Clay_White",
      "rotation": 33
    },
    {
      "x": -3,
      "y": 10,
      "z": -6,
      "name": "Rock_Chalk",
      "rotation": 33
    },
    {
      "x": -3,
      "y": 11,
      "z": -6,
      "name": "Rock_Chalk",
      "rotation": 33
    },
    {
      "x": -3,
      "y": 12,
      "z": -6,
      "name": "Soil_Clay_White",
      "rotation": 33
    },
    {
      "x": -3,
      "y": 13,
      "z": -6,
      "name": "Rock_Marble",
      "rotation": 33
