{"anchorX":5,"anchorY":7,"anchorZ":3,"blockIdVersion":11,"blocks":[{"name":"Rock_Sandstone_Brick","x":2,"y":6,"z":1},{"name":"Rock_Sandstone_Brick","x":2,"y":7,"z":1},{"name":"Rock_Sandstone_Brick","x":2,"y":8,"z":1},{"name":"Rock_Sandstone_Brick","x":2,"y":9,"z":1},{"name":"Rock_Sandstone_Brick","x":2,"y":10,"z":1},{"name":"Rock_Sandstone_Brick","x":2,"y":11,"z":1},{"name":"Rock_Sandstone_Brick","x":2,"y":6,"z":2},{"name":"Rock_Sandstone_Brick","x":2,"y":7,"z":2},{"name":"Rock_Sandstone_Brick","x":2,"y":8,"z":2},{"name":"Rock_Sandstone_Brick","x":2,"y":9,"z":2},{"name":"Rock_Sandstone_Brick","x":2,"y":10,"z":2},{"name":"Rock_Sandstone_Brick","x":2,"y":11,"z":2},{"name":"Rock_Sandstone_Brick","x":2,"y":6,"z":3},{"name":"Rock_Sandstone_Brick","x":2,"y":7,"z":3},{"name":"Rock_Sandstone_Brick","x":2,"y":8,"z":3},{"name":"Rock_Sandstone_Brick","x":2,"y":9,"z":3},{"name":"Rock_Sandstone_Brick","x":2,"y":10,"z":3},{"name":"Rock_Sandstone_Brick","x":2,"y":11,"z":3},{"name":"Rock_Sandstone_Brick","x":2,"y":6,"z":4},{"name":"Rock_Sandstone_Brick","x":2,"y":7,"z":4},{"name":"Rock_Sandstone_Brick","x":2,"y":8,"z":4},{"name":"Rock_Sandstone_Brick","x":2,"y":9,"z":4},{"name":"Rock_Sandstone_Brick","x":2,"y":10,"z":4},{"name":"Rock_Sandstone_Brick","x":2,"y":11,"z":4},{"name":"Rock_Sandstone_Brick","x":2,"y":6,"z":5},{"name":"Rock_Sandstone_Brick","x":2,"y":7,"z":5},{"name":"Rock_Sandstone_Brick","x":2,"y":8,"z":5},{"name":"Rock_Sandstone_Brick","x":2,"y":9,"z":5},{"name":"Rock_Sandstone_Brick","x":2,"y":10,"z":5},{"name":"Rock_Sandstone_Brick","x":2,"y":11,"z":5},{"name":"Rock_Sandstone_Brick","x":2,"y":12,"z":5},{"name":"Rock_Sandstone_Brick","x":2,"y":6,"z":6},{"name":"Rock_Sandstone_Brick","x":2,"y":7,"z":6},{"name":"Rock_Sandstone_Brick","x":2,"y":8,"z":6},{"name":"Rock_Sandstone_Brick_Smooth","x":2,"y":9,"z":6},{"name":"Rock_Sandstone_Brick_Smooth","x":2,"y":10,"z":6},{"name":"Rock_Sandstone_Brick","x":2,"y":11,"z":6},{"name":"Rock_Sandstone_Brick","x":2,"y":12,"z":6},{"name":"Rock_Sandstone_Brick_Smooth","x":2,"y":6,"z":7},{"name":"Rock_Sandstone_Brick_Smooth","x":2,"y":7,"z":7},{"name":"Rock_Sandstone_Brick_Smooth","x":2,"y":8,"z":7},{"name":"Rock_Sandstone_Brick_Smooth","x":2,"y":9,"z":7},{"name":"Rock_Sandstone_Brick_Smooth","x":2,"y":10,"z":7},{"name":"Rock_Sandstone_Brick_Smooth","x":2,"y":11,"z":7},{"name":"Rock_Sandstone_Brick_Smooth","x":2,"y":12,"z":7},{"name":"Rock_Sandstone_Brick","x":3,"y":6,"z":-1},{"name":"Rock_Sandstone_Brick","x":3,"y":7,"z":-1},{"name":"Rock_Sandstone_Brick","x":3,"y":8,"z":-1},{"name":"Rock_Sandstone_Brick","x":3,"y":9,"z":-1},{"name":"Rock_Sandstone_Brick","x":3,"y":10,"z":-1},{"name":"Rock_Sandstone_Brick","x":3,"y":11,"z":-1},{"name":"Rock_Sandstone_Brick","x":3,"y":12,"z":-1},{"name":"Rock_Sandstone_Brick","x":3,"y":13,"z":-1},{"name":"Soil_Gravel_Sand_White","x":3,"y":6,"z":0},{"name":"Soil_Gravel_Sand_White","x":3,"y":7,"z":0},{"name":"Soil_Gravel_Sand_White","x":3,"y":8,"z":0},{"name":"Soil_Gravel_Sand_White","x":3,"y":9,"z":0},{"name":"Soil_Gravel_Sand_White","x":3,"y":10,"z":0},{"name":"Soil_Gravel_Sand_White","x":3,"y":11,"z":0},{"name":"Soil_Gravel_Sand_White","x":3,"y":12,"z":0},{"name":"Soil_Gravel_Sand_White","x":3,"y":13,"z":0},{"name":"Rock_Sandstone_Brick","x":3,"y":6,"z":1},{"name":"Rock_Sandstone_Brick","x":3,"y":7,"z":1},{"name":"Rock_Sandstone_Brick","x":3,"y":8,"z":1},{"name":"Rock_Sandstone_Brick","x":3,"y":9,"z":1},{"name":"Rock_Sandstone_Brick","x":3,"y":10,"z":1},{"name":"Rock_Sandstone_Brick","x":3,"y":11,"z":1},{"name":"Rock_Sandstone_Brick","x":3,"y":12,"z":1},{"name":"Rock_Sandstone_Brick","x":3,"y":13,"z":1},{"name":"Rock_Sandstone_Brick","x":3,"y":6,"z":7},{"name":"Rock_Sandstone_Brick_Smooth","x":3,"y":7,"z":7},{"name":"Rock_Sandstone_Brick_Smooth","x":3,"y":8,"z":7},{"name":"Rock_Sandstone_Brick","x":3,"y":9,"z":7},{"name":"Rock_Sandstone_Brick","x":3,"y":10,"z":7},{"name":"Rock_Sandstone_Brick_Smooth","x":3,"y":11,"z":7},{"name":"Rock_Sandstone_Brick_Smooth","x":3,"y":12,"z":7},{"name":"Rock_Sandstone_Brick","x":3,"y":13,"z":7},{"name":"Rock_Sandstone_Brick","x":4,"y":6,"z":-1},{"name":"Rock_Sandstone_Brick","x":4,"y":7,"z":-1},{"name":"Rock_Sandstone_Brick","x":4,"y":8,"z":-1},{"name":"Rock_Sandstone_Brick","x":4,"y":9,"z":-1},{"name":"Rock_Sandstone_Brick","x":4,"y":10,"z":-1},{"name":"Rock_Sandstone_Brick","x":4,"y":11,"z":-1},{"name":"Rock_Sandstone_Brick","x":4,"y":12,"z":-1},{"name":"Rock_Sandstone_Brick","x":4,"y":13,"z":-1},{"name":"Soil_Gravel_Sand_White","x":4,"y":6,"z":0},{"name":"Soil_Gravel_Sand_White","x":4,"y":7,"z":0},{"name":"Soil_Gravel_Sand_White","x":4,"y":8,"z":0},{"name":"Soil_Gravel_Sand_White","x":4,"y":9,"z":0},{"name":"Soil_Gravel_Sand_White","x":4,"y":10,"z":0},{"name":"Soil_Gravel_Sand_White","x":4,"y":11,"z":0},{"name":"Soil_Gravel_Sand_White","x":4,"y":12,"z":0},{"name":"Soil_Gravel_Sand_White","x":4,"y":13,"z":0},{"name":"Rock_Sandstone_Brick","x":4,"y":6,"z":1},{"name":"Rock_Sandstone_Brick","x":4,"y":7,"z":1},{"name":"Rock_Sandstone_Brick","x":4,"y":8,"z":1},{"name":"Rock_Sandstone_Brick","x":4,"y":9,"z":1},{"name":"Rock_Sandstone_Brick","x":4,"y":10,"z":1},{"name":"Rock_Sandstone_Brick","x":4,"y":11,"z":1},{"name":"Rock_Sandstone_Brick","x":4,"y":12,"z":1},{"name":"Rock_Sandstone_Brick","x":4,"y":13,"z":1},{"name":"Rock_Sandstone_Brick","x":4,"y":14,"z":1},{"name":"Plant_Coral_Block_Green","x":4,"y":13,"z":2},{"name":"Rock_Sandstone_Brick","x":4,"y":6,"z":7},{"name":"Rock_Sandstone_Brick","x":4,"y":7,"z":7},{"name":"Rock_Sandstone_Brick","x":4,"y":8,"z":7},{"name":"Rock_Sandstone_Brick","x":4,"y":9,"z":7},{"name":"Rock_Sandstone_Brick","x":4,"y":10,"z":7},{"name":"Rock_Sandstone_Brick","x":4,"y":11,"z":7},{"name":"Rock_Sandstone_Brick","x":4,"y":12,"z":7},{"name":"Rock_Sandstone_Brick","x":4,"y":13,"z":7},{"name":"Rock_Sandstone_Brick","x":4,"y":14,"z":7},{"name":"Plant_Coral_Block_Green","x":4,"y":15,"z":7},{"name":"Plant_Coral_Block_Green","x":4,"y":15,"z":8},{"name":"Plant_Coral_Block_Green","x":5,"y":12,"z":-2},{"name":"Rock_Sandstone_Brick","x":5,"y":6,"z":-1},{"name":"Rock_Sandstone_Brick_Smooth","x":5,"y":7,"z":-1},{"name":"Rock_Sandstone_Brick_Smooth","x":5,"y":8,"z":-1},{"name":"Rock_Sandstone_Brick","x":5,"y":9,"z":-1},{"name":"Rock_Sandstone_Brick","x":5,"y":10,"z":-1},{"name":"Rock_Sandstone_Brick_Smooth","x":5,"y":11,"z":-1},{"name":"Rock_Sandstone_Brick_Smooth","x":5,"y":12,"z":-1},{"name":"Rock_Sandstone_Brick","x":5,"y":13,"z":-1},{"name":"Rock_Sandstone_Brick","x":5,"y":14,"z":-1},{"name":"Soil_Gravel_Sand_White","x":5,"y":6,"z":0},{"name":"Soil_Gravel_Sand_White","x":5,"y":7,"z":0},{"name":"Soil_Gravel_Sand_White","x":5,"y":8,"z":0},{"name":"Soil_Gravel_Sand_White","x":5,"y":9,"z":0},{"name":"Soil_Gravel_Sand_White","x":5,"y":10,"z":0},{"name":"Soil_Gravel_Sand_White","x":5,"y":11,"z":0},{"name":"Soil_Gravel_Sand_White","x":5,"y":12,"z":0},{"name":"Soil_Gravel_Sand_White","x":5,"y":13,"z":0},{"name":"Soil_Gravel_Sand_White","x":5,"y":14,"z":0},{"name":"Rock_Sandstone_Brick","x":5,"y":6,"z":1},{"name":"Rock_Sandstone_Brick_Smooth","x":5,"y":7,"z":1},{"name":"Rock_Sandstone_Brick_Smooth","x":5,"y":8,"z":1},{"name":"Rock_Sandstone_Brick","x":5,"y":9,"z":1},{"name":"Rock_Sandstone_Brick","x":5,"y":10,"z":1},{"name":"Rock_Sandstone_Brick_Smooth","x":5,"y":11,"z":1},{"name":"Rock_Sandstone_Brick_Smooth","x":5,"y":12,"z":1},{"name":"Rock_Sandstone_Brick","x":5,"y":13,"z":1},{"name":"Rock_Sandstone_Brick","x":5,"y":14,"z":1},{"name":"Plant_Coral_Block_Lime","x":5,"y":13,"z":2},{"name":"Plant_Coral_Block_Green","x":5,"y":13,"z":3},{"name":"Rock_Sandstone_Brick","x":5,"y":6,"z":7},{"name":"Rock_Sandstone_Brick","x":5,"y":7,"z":7},{"name":"Rock_Sandstone_Brick","x":5,"y":8,"z":7},{"name":"Rock_Sandstone_Brick","x":5,"y":9,"z":7},{"name":"Rock_Sandstone_Brick","x":5,"y":10,"z":7},{"name":"Rock_Sandstone_Brick","x":5,"y":11,"z":7},{"name":"Rock_Sandstone_Brick","x":5,"y":12,"z":7},{"name":"Rock_Sandstone_Brick","x":5,"y":13,"z":7},{"name":"Rock_Sandstone_Brick","x":5,"y":14,"z":7},{"name":"Rock_Sandstone_Brick","x":5,"y":15,"z":7},{"name":"Plant_Coral_Block_Lime","x":5,"y":15,"z":8},{"name":"Plant_Coral_Bush_Lime","x":5,"y":16,"z":8},{"name":"Plant_Coral_Block_Green","x":5,"y":15,"z":9},{"name":"Plant_Coral_Block_Green","x":6,"y":12,"z":-3},{"name":"Plant_Coral_Block_Lime","x":6,"y":12,"z":-2},{"name":"Plant_Coral_Bush_Lime","x":6,"y":13,"z":-2},{"name":"Rock_Sandstone_Brick_Smooth","x":6,"y":6,"z":-1},{"name":"Rock_Sandstone_Brick_Smooth","x":6,"y":7,"z":-1},{"name":"Rock_Sandstone_Brick_Smooth","x":6,"y":8,"z":-1},{"name":"Rock_Sandstone_Brick_Smooth","x":6,"y":9,"z":-1},{"name":"Rock_Sandstone_Brick_Smooth","x":6,"y":10,"z":-1},{"name":"Rock_Sandstone_Brick_Smooth","x":6,"y":11,"z":-1},{"name":"Rock_Sandstone_Brick_Smooth","x":6,"y":12,"z":-1},{"name":"Rock_Sandstone_Brick_Smooth","x":6,"y":13,"z":-1},{"name":"Rock_Sandstone_Brick_Smooth","x":6,"y":14,"z":-1},{"name":"Soil_Gravel_Sand_White","x":6,"y":6,"z":0},{"name":"Soil_Gravel_Sand_White","x":6,"y":7,"z":0},{"name":"Soil_Gravel_Sand_White","x":6,"y":8,"z":0},{"name":"Soil_Gravel_Sand_White","x":6,"y":9,"z":0},{"name":"Soil_Gravel_Sand_White","x":6,"y":10,"z":0},{"name":"Soil_Gravel_Sand_White","x":6,"y":11,"z":0},{"name":"Soil_Gravel_Sand_White","x":6,"y":12,"z":0},{"name":"Soil_Gravel_Sand_White","x":6,"y":13,"z":0},{"name":"Soil_Gravel_Sand_White","x":6,"y":14,"z":0},{"name":"Rock_Sandstone_Brick_Smooth","x":6,"y":6,"z":1},{"name":"Rock_Sandstone_Brick_Smooth","x":6,"y":7,"z":1},{"name":"Rock_Sandstone_Brick_Smooth","x":6,"y":8,"z":1},{"name":"Rock_Sandstone_Brick_Smooth","x":6,"y":9,"z":1},{"name":"Rock_Sandstone_Brick_Smooth","x":6,"y":10,"z":1},{"name":"Rock_Sandstone_Brick_Smooth","x":6,"y":11,"z":1},{"name":"Rock_Sandstone_Brick_Smooth","x":6,"y":12,"z":1},{"name":"Rock_Sandstone_Brick_Smooth","x":6,"y":13,"z":1},{"name":"Rock_Sandstone_Brick_Smooth","x":6,"y":14,"z":1},{"name":"Plant_Coral_Block_Lime","x":6,"y":13,"z":2},{"name":"Plant_Coral_Model_Green","x":6,"y":14,"z":2},{"name":"Plant_Coral_Block_Green","x":6,"y":13,"z":3},{"name":"Rock_Sandstone_Brick","x":6,"y":6,"z":7},{"name":"Rock_Sandstone_Brick","x":6,"y":7,"z":7},{"name":"Rock_Sandstone_Brick","x":6,"y":8,"z":7},{"name":"Rock_Sandstone_Brick","x":6,"y":9,"z":7},{"name":"Rock_Sandstone_Brick","x":6,"y":10,"z":7},{"name":"Rock_Sandstone_Brick","x":6,"y":11,"z":7},{"name":"Rock_Sandstone_Brick","x":6,"y":12,"z":7},{"name":"Rock_Sandstone_Brick","x":6,"y":13,"z":7},{"name":"Rock_Sandstone_Brick","x":6,"y":14,"z":7},{"name":"Rock_Sandstone_Brick","x":6,"y":15,"z":7},{"name":"Plant_Coral_Block_Lime","x":6,"y":15,"z":8},{"name":"Plant_Coral_Model_Green","x":6,"y":16,"z":8},{"name":"Plant_Coral_Block_Green","x":6,"y":15,"z":9},{"name":"Plant_Coral_Block_Green","x":7,"y":12,"z":-3},{"name":"Plant_Coral_Block_Lime","x":7,"y":12,"z":-2},{"name":"Rock_Sandstone_Brick","x":7,"y":6,"z":-1},{"name":"Rock_Sandstone_Brick","x":7,"y":7,"z":-1},{"name":"Rock_Sandstone_Brick","x":7,"y":8,"z":-1},{"name":"Rock_Sandstone_Brick_Smooth","x":7,"y":9,"z":-1},{"name":"Rock_Sandstone_Brick_Smooth","x":7,"y":10,"z":-1},{"name":"Rock_Sandstone_Brick","x":7,"y":11,"z":-1},{"name":"Rock_Sandstone_Brick","x":7,"y":12,"z":-1},{"name":"Rock_Sandstone_Brick_Smooth","x":7,"y":13,"z":-1},{"name":"Rock_Sandstone_Brick_Smooth","x":7,"y":14,"z":-1},{"name":"Soil_Gravel_Sand_White","x":7,"y":6,"z":0},{"name":"Soil_Gravel_Sand_White","x":7,"y":7,"z":0},{"name":"Soil_Gravel_Sand_White","x":7,"y":8,"z":0},{"name":"Soil_Gravel_Sand_White","x":7,"y":9,"z":0},{"name":"Soil_Gravel_Sand_White","x":7,"y":10,"z":0},{"name":"Soil_Gravel_Sand_White","x":7,"y":11,"z":0},{"name":"Soil_Gravel_Sand_White","x":7,"y":12,"z":0},{"name":"Soil_Gravel_Sand_White","x":7,"y":13,"z":0},{"name":"Soil_Gravel_Sand_White","x":7,"y":14,"z":0},{"name":"Rock_Sandstone_Brick","x":7,"y":6,"z":1},{"name":"Rock_Sandstone_Brick","x":7,"y":7,"z":1},{"name":"Rock_Sandstone_Brick","x":7,"y":8,"z":1},{"name":"Rock_Sandstone_Brick_Smooth","x":7,"y":9,"z":1},{"name":"Rock_Sandstone_Brick_Smooth","x":7,"y":10,"z":1},{"name":"Rock_Sandstone_Brick","x":7,"y":11,"z":1},{"name":"Rock_Sandstone_Brick","x":7,"y":12,"z":1},{"name":"Rock_Sandstone_Brick_Smooth","x":7,"y":13,"z":1},{"name":"Rock_Sandstone_Brick_Smooth","x":7,"y":14,"z":1},{"name":"Rock_Sandstone_Brick","x":7,"y":15,"z":1},{"name":"Plant_Coral_Block_Lime","x":7,"y":13,"z":2},{"name":"Plant_Coral_Bush_Lime","x":7,"y":14,"z":2},{"name":"Plant_Coral_Block_Green","x":7,"y":13,"z":3},{"name":"Rock_Sandstone_Brick","x":7,"y":6,"z":7},{"name":"Rock_Sandstone_Brick","x":7,"y":7,"z":7},{"name":"Rock_Sandstone_Brick","x":7,"y":8,"z":7},{"name":"Rock_Sandstone_Brick","x":7,"y":9,"z":7},{"name":"Rock_Sandstone_Brick","x":7,"y":10,"z":7},{"name":"Rock_Sandstone_Brick","x":7,"y":11,"z":7},{"name":"Rock_Sandstone_Brick","x":7,"y":12,"z":7},{"name":"Rock_Sandstone_Brick","x":7,"y":13,"z":7},{"name":"Rock_Sandstone_Brick","x":7,"y":14,"z":7},{"name":"Rock_Sandstone_Brick","x":7,"y":15,"z":7},{"name":"Plant_Coral_Block_Lime","x":7,"y":15,"z":8},{"name":"Plant_Coral_Block_Green","x":7,"y":15,"z":9},{"name":"Plant_Coral_Block_Green","x":8,"y":12,"z":-3},{"name":"Plant_Coral_Model_Green","x":8,"y":13,"z":-3},{"name":"Plant_Coral_Block_Lime","x":8,"y":12,"z":-2},{"name":"Rock_Sandstone_Brick","x":8,"y":6,"z":-1},{"name":"Rock_Sandstone_Brick","x":8,"y":7,"z":-1},{"name":"Rock_Sandstone_Brick","x":8,"y":8,"z":-1},{"name":"Rock_Sandstone_Brick","x":8,"y":9,"z":-1},{"name":"Rock_Sandstone_Brick","x":8,"y":10,"z":-1},{"name":"Rock_Sandstone_Brick","x":8,"y":11,"z":-1},{"name":"Rock_Sandstone_Brick","x":8,"y":12,"z":-1},{"name":"Rock_Sandstone_Brick","x":8,"y":13,"z":-1},{"name":"Rock_Sandstone_Brick","x":8,"y":14,"z":-1},{"name":"Rock_Sandstone_Brick","x":8,"y":15,"z":-1},{"name":"Soil_Gravel_Sand_White","x":8,"y":6,"z":0},{"name":"Soil_Gravel_Sand_White","x":8,"y":7,"z":0},{"name":"Soil_Gravel_Sand_White","x":8,"y":8,"z":0},{"name":"Soil_Gravel_Sand_White","x":8,"y":9,"z":0},{"name":"Soil_Gravel_Sand_White","x":8,"y":10,"z":0},{"name":"Soil_Gravel_Sand_White","x":8,"y":11,"z":0},{"name":"Soil_Gravel_Sand_White","x":8,"y":12,"z":0},{"name":"Soil_Gravel_Sand_White","x":8,"y":13,"z":0},{"name":"Soil_Gravel_Sand_White","x":8,"y":14,"z":0},{"name":"Soil_Gravel_Sand_White","x":8,"y":15,"z":0},{"name":"Rock_Sandstone_Brick","x":8,"y":6,"z":1},{"name":"Rock_Sandstone_Brick","x":8,"y":7,"z":1},{"name":"Rock_Sandstone_Brick","x":8,"y":8,"z":1},{"name":"Rock_Sandstone_Brick","x":8,"y":9,"z":1},{"name":"Rock_Sandstone_Brick","x":8,"y":10,"z":1},{"name":"Rock_Sandstone_Brick","x":8,"y":11,"z":1},{"name":"Rock_Sandstone_Brick","x":8,"y":12,"z":1},{"name":"Rock_Sandstone_Brick","x":8,"y":13,"z":1},{"name":"Rock_Sandstone_Brick","x":8,"y":14,"z":1},{"name":"Rock_Sandstone_Brick","x":8,"y":15,"z":1},{"name":"Plant_Coral_Block_Green","x":8,"y":13,"z":2},{"name":"Rock_Sandstone_Brick","x":8,"y":6,"z":7},{"name":"Rock_Sandstone_Brick","x":8,"y":7,"z":7},{"name":"Rock_Sandstone_Brick","x":8,"y":8,"z":7},{"name":"Rock_Sandstone_Brick","x":8,"y":9,"z":7},{"name":"Rock_Sandstone_Brick","x":8,"y":10,"z":7},{"name":"Rock_Sandstone_Brick","x":8,"y":11,"z":7},{"name":"Rock_Sandstone_Brick","x":8,"y":12,"z":7},{"name":"Rock_Sandstone_Brick","x":8,"y":13,"z":7},{"name":"Rock_Sandstone_Brick","x":8,"y":14,"z":7},{"name":"Plant_Coral_Block_Green","x":8,"y":15,"z":8},{"name":"Plant_Coral_Block_Green","x":9,"y":12,"z":-2},{"name":"Rock_Sandstone_Brick","x":9,"y":6,"z":-1},{"name":"Rock_Sandstone_Brick","x":9,"y":7,"z":-1},{"name":"Rock_Sandstone_Brick","x":9,"y":8,"z":-1},{"name":"Rock_Sandstone_Brick","x":9,"y":9,"z":-1},{"name":"Rock_Sandstone_Brick","x":9,"y":10,"z":-1},{"name":"Rock_Sandstone_Brick","x":9,"y":11,"z":-1},{"name":"Rock_Sandstone_Brick","x":9,"y":12,"z":-1},{"name":"Rock_Sandstone_Brick","x":9,"y":13,"z":-1},{"name":"Rock_Sandstone_Brick","x":9,"y":14,"z":-1},{"name":"Rock_Sandstone_Brick","x":9,"y":15,"z":-1},{"name":"Soil_Gravel_Sand_White","x":9,"y":6,"z":0},{"name":"Soil_Gravel_Sand_White","x":9,"y":7,"z":0},{"name":"Soil_Gravel_Sand_White","x":9,"y":8,"z":0},{"name":"Soil_Gravel_Sand_White","x":9,"y":9,"z":0},{"name":"Soil_Gravel_Sand_White","x":9,"y":10,"z":0},{"name":"Soil_Gravel_Sand_White","x":9,"y":11,"z":0},{"name":"Soil_Gravel_Sand_White","x":9,"y":12,"z":0},{"name":"Soil_Gravel_Sand_White","x":9,"y":13,"z":0},{"name":"Soil_Gravel_Sand_White","x":9,"y":14,"z":0},{"name":"Soil_Gravel_Sand_White","x":9,"y":15,"z":0},{"name":"Rock_Sandstone_Brick","x":9,"y":6,"z":1},{"name":"Rock_Sandstone_Brick","x":9,"y":7,"z":1},{"name":"Rock_Sandstone_Brick","x":9,"y":8,"z":1},{"name":"Rock_Sandstone_Brick","x":9,"y":9,"z":1},{"name":"Rock_Sandstone_Brick","x":9,"y":10,"z":1},{"name":"Rock_Sandstone_Brick","x":9,"y":11,"z":1},{"name":"Rock_Sandstone_Brick","x":9,"y":12,"z":1},{"name":"Rock_Sandstone_Brick","x":9,"y":13,"z":1},{"name":"Rock_Sandstone_Brick","x":9,"y":14,"z":1},{"name":"Rock_Sandstone_Brick","x":9,"y":10,"z":7},{"name":"Soil_Gravel_Sand_White","x":10,"y":10,"z":0}],"fluids":[{"level":1,"name":"Water_Source","x":2,"y":6,"z":1},{"level":1,"name":"Water_Source","x":2,"y":7,"z":1},{"level":1,"name":"Water_Source","x":2,"y":8,"z":1},{"level":1,"name":"Water_Source","x":2,"y":9,"z":1},{"level":1,"name":"Water_Source","x":2,"y":10,"z":1},{"level":1,"name":"Water_Source","x":2,"y":11,"z":1},{"level":1,"name":"Water_Source","x":2,"y":6,"z":2},{"level":1,"name":"Water_Source","x":2,"y":7,"z":2},{"level":1,"name":"Water_Source","x":2,"y":8,"z":2},{"level":1,"name":"Water_Source","x":2,"y":9,"z":2},{"level":1,"name":"Water_Source","x":2,"y":10,"z":2},{"level":1,"name":"Water_Source","x":2,"y":11,"z":2},{"level":1,"name":"Water_Source","x":2,"y":6,"z":3},{"level":1,"name":"Water_Source","x":2,"y":7,"z":3},{"level":1,"name":"Water_Source","x":2,"y":8,"z":3},{"level":1,"name":"Water_Source","x":2,"y":9,"z":3},{"level":1,"name":"Water_Source","x":2,"y":10,"z":3},{"level":1,"name":"Water_Source","x":2,"y":11,"z":3},{"level":1,"name":"Water_Source","x":2,"y":6,"z":4},{"level":1,"name":"Water_Source","x":2,"y":7,"z":4},{"level":1,"name":"Water_Source","x":2,"y":8,"z":4},{"level":1,"name":"Water_Source","x":2,"y":9,"z":4},{"level":1,"name":"Water_Source","x":2,"y":10,"z":4},{"level":1,"name":"Water_Source","x":2,"y":11,"z":4},{"level":1,"name":"Water_Source","x":2,"y":6,"z":5},{"level":1,"name":"Water_Source","x":2,"y":7,"z":5},{"level":1,"name":"Water_Source","x":2,"y":8,"z":5},{"level":1,"name":"Water_Source","x":2,"y":9,"z":5},{"level":1,"name":"Water_Source","x":2,"y":10,"z":5},{"level":1,"name":"Water_Source","x":2,"y":11,"z":5},{"level":1,"name":"Water_Source","x":2,"y":12,"z":5},{"level":1,"name":"Water_Source","x":2,"y":6,"z":6},{"level":1,"name":"Water_Source","x":2,"y":7,"z":6},{"level":1,"name":"Water_Source","x":2,"y":8,"z":6},{"level":1,"name":"Water_Source","x":2,"y":9,"z":6},{"level":1,"name":"Water_Source","x":2,"y":10,"z":6},{"level":1,"name":"Water_Source","x":2,"y":11,"z":6},{"level":1,"name":"Water_Source","x":2,"y":12,"z":6},{"level":1,"name":"Water_Source","x":2,"y":6,"z":7},{"level":1,"name":"Water_Source","x":2,"y":7,"z":7},{"level":1,"name":"Water_Source","x":2,"y":8,"z":7},{"level":1,"name":"Water_Source","x":2,"y":9,"z":7},{"level":1,"name":"Water_Source","x":2,"y":10,"z":7},{"level":1,"name":"Water_Source","x":2,"y":11,"z":7},{"level":1,"name":"Water_Source","x":2,"y":12,"z":7},{"level":1,"name":"Water_Source","x":3,"y":6,"z":-1},{"level":1,"name":"Water_Source","x":3,"y":7,"z":-1},{"level":1,"name":"Water_Source","x":3,"y":8,"z":-1},{"level":1,"name":"Water_Source","x":3,"y":9,"z":-1},{"level":1,"name":"Water_Source","x":3,"y":10,"z":-1},{"level":1,"name":"Water_Source","x":3,"y":11,"z":-1},{"level":1,"name":"Water_Source","x":3,"y":12,"z":-1},{"level":1,"name":"Water_Source","x":3,"y":13,"z":-1},{"level":1,"name":"Water_Source","x":3,"y":6,"z":0},{"level":1,"name":"Water_Source","x":3,"y":7,"z":0},{"level":1,"name":"Water_Source","x":3,"y":8,"z":0},{"level":1,"name":"Water_Source","x":3,"y":9,"z":0},{"level":1,"name":"Water_Source","x":3,"y":10,"z":0},{"level":1,"name":"Water_Source","x":3,"y":11,"z":0},{"level":1,"name":"Water_Source","x":3,"y":12,"z":0},{"level":1,"name":"Water_Source","x":3,"y":13,"z":0},{"level":1,"name":"Water_Source","x":3,"y":6,"z":1},{"level":1,"name":"Water_Source","x":3,"y":7,"z":1},{"level":1,"name":"Water_Source","x":3,"y":8,"z":1},{"level":1,"name":"Water_Source","x":3,"y":9,"z":1},{"level":1,"name":"Water_Source","x":3,"y":10,"z":1},{"level":1,"name":"Water_Source","x":3,"y":11,"z":1},{"level":1,"name":"Water_Source","x":3,"y":12,"z":1},{"level":1,"name":"Water_Source","x":3,"y":13,"z":1},{"level":1,"name":"Water_Source","x":3,"y":6,"z":7},{"level":1,"name":"Water_Source","x":3,"y":7,"z":7},{"level":1,"name":"Water_Source","x":3,"y":8,"z":7},{"level":1,"name":"Water_Source","x":3,"y":9,"z":7},{"level":1,"name":"Water_Source","x":3,"y":10,"z":7},{"level":1,"name":"Water_Source","x":3,"y":11,"z":7},{"level":1,"name":"Water_Source","x":3,"y":12,"z":7},{"level":1,"name":"Water_Source","x":3,"y":13,"z":7},{"level":1,"name":"Water_Source","x":4,"y":6,"z":-1},{"level":1,"name":"Water_Source","x":4,"y":7,"z":-1},{"level":1,"name":"Water_Source","x":4,"y":8,"z":-1},{"level":1,"name":"Water_Source","x":4,"y":9,"z":-1},{"level":1,"name":"Water_Source","x":4,"y":10,"z":-1},{"level":1,"name":"Water_Source","x":4,"y":11,"z":-1},{"level":1,"name":"Water_Source","x":4,"y":12,"z":-1},{"level":1,"name":"Water_Source","x":4,"y":13,"z":-1},{"level":1,"name":"Water_Source","x":4,"y":6,"z":0},{"level":1,"name":"Water_Source","x":4,"y":7,"z":0},{"level":1,"name":"Water_Source","x":4,"y":8,"z":0},{"level":1,"name":"Water_Source","x":4,"y":9,"z":0},{"level":1,"name":"Water_Source","x":4,"y":10,"z":0},{"level":1,"name":"Water_Source","x":4,"y":11,"z":0},{"level":1,"name":"Water_Source","x":4,"y":12,"z":0},{"level":1,"name":"Water_Source","x":4,"y":13,"z":0},{"level":1,"name":"Water_Source","x":4,"y":6,"z":1},{"level":1,"name":"Water_Source","x":4,"y":7,"z":1},{"level":1,"name":"Water_Source","x":4,"y":8,"z":1},{"level":1,"name":"Water_Source","x":4,"y":9,"z":1},{"level":1,"name":"Water_Source","x":4,"y":10,"z":1},{"level":1,"name":"Water_Source","x":4,"y":11,"z":1},{"level":1,"name":"Water_Source","x":4,"y":12,"z":1},{"level":1,"name":"Water_Source","x":4,"y":13,"z":1},{"level":1,"name":"Water_Source","x":4,"y":14,"z":1},{"level":1,"name":"Water_Source","x":4,"y":13,"z":2},{"level":1,"name":"Water_Source","x":4,"y":6,"z":7},{"level":1,"name":"Water_Source","x":4,"y":7,"z":7},{"level":1,"name":"Water_Source","x":4,"y":8,"z":7},{"level":1,"name":"Water_Source","x":4,"y":9,"z":7},{"level":1,"name":"Water_Source","x":4,"y":10,"z":7},{"level":1,"name":"Water_Source","x":4,"y":11,"z":7},{"level":1,"name":"Water_Source","x":4,"y":12,"z":7},{"level":1,"name":"Water_Source","x":4,"y":13,"z":7},{"level":1,"name":"Water_Source","x":4,"y":14,"z":7},{"level":1,"name":"Water_Source","x":4,"y":15,"z":7},{"level":1,"name":"Water_Source","x":4,"y":15,"z":8},{"level":1,"name":"Water_Source","x":5,"y":12,"z":-2},{"level":1,"name":"Water_Source","x":5,"y":6,"z":-1},{"level":1,"name":"Water_Source","x":5,"y":7,"z":-1},{"level":1,"name":"Water_Source","x":5,"y":8,"z":-1},{"level":1,"name":"Water_Source","x":5,"y":9,"z":-1},{"level":1,"name":"Water_Source","x":5,"y":10,"z":-1},{"level":1,"name":"Water_Source","x":5,"y":11,"z":-1},{"level":1,"name":"Water_Source","x":5,"y":12,"z":-1},{"level":1,"name":"Water_Source","x":5,"y":13,"z":-1},{"level":1,"name":"Water_Source","x":5,"y":14,"z":-1},{"level":1,"name":"Water_Source","x":5,"y":6,"z":0},{"level":1,"name":"Water_Source","x":5,"y":7,"z":0},{"level":1,"name":"Water_Source","x":5,"y":8,"z":0},{"level":1,"name":"Water_Source","x":5,"y":9,"z":0},{"level":1,"name":"Water_Source","x":5,"y":10,"z":0},{"level":1,"name":"Water_Source","x":5,"y":11,"z":0},{"level":1,"name":"Water_Source","x":5,"y":12,"z":0},{"level":1,"name":"Water_Source","x":5,"y":13,"z":0},{"level":1,"name":"Water_Source","x":5,"y":14,"z":0},{"level":1,"name":"Water_Source","x":5,"y":6,"z":1},{"level":1,"name":"Water_Source","x":5,"y":7,"z":1},{"level":1,"name":"Water_Source","x":5,"y":8,"z":1},{"level":1,"name":"Water_Source","x":5,"y":9,"z":1},{"level":1,"name":"Water_Source","x":5,"y":10,"z":1},{"level":1,"name":"Water_Source","x":5,"y":11,"z":1},{"level":1,"name":"Water_Source","x":5,"y":12,"z":1},{"level":1,"name":"Water_Source","x":5,"y":13,"z":1},{"level":1,"name":"Water_Source","x":5,"y":14,"z":1},{"level":1,"name":"Water_Source","x":5,"y":13,"z":2},{"level":1,"name":"Water_Source","x":5,"y":13,"z":3},{"level":1,"name":"Water_Source","x":5,"y":6,"z":7},{"level":1,"name":"Water_Source","x":5,"y":7,"z":7},{"level":1,"name":"Water_Source","x":5,"y":8,"z":7},{"level":1,"name":"Water_Source","x":5,"y":9,"z":7},{"level":1,"name":"Water_Source","x":5,"y":10,"z":7},{"level":1,"name":"Water_Source","x":5,"y":11,"z":7},{"level":1,"name":"Water_Source","x":5,"y":12,"z":7},{"level":1,"name":"Water_Source","x":5,"y":13,"z":7},{"level":1,"name":"Water_Source","x":5,"y":14,"z":7},{"level":1,"name":"Water_Source","x":5,"y":15,"z":7},{"level":1,"name":"Water_Source","x":5,"y":15,"z":8},{"level":1,"name":"Water_Source","x":5,"y":16,"z":8},{"level":1,"name":"Water_Source","x":5,"y":15,"z":9},{"level":1,"name":"Water_Source","x":6,"y":12,"z":-3},{"level":1,"name":"Water_Source","x":6,"y":12,"z":-2},{"level":1,"name":"Water_Source","x":6,"y":13,"z":-2},{"level":1,"name":"Water_Source","x":6,"y":6,"z":-1},{"level":1,"name":"Water_Source","x":6,"y":7,"z":-1},{"level":1,"name":"Water_Source","x":6,"y":8,"z":-1},{"level":1,"name":"Water_Source","x":6,"y":9,"z":-1},{"level":1,"name":"Water_Source","x":6,"y":10,"z":-1},{"level":1,"name":"Water_Source","x":6,"y":11,"z":-1},{"level":1,"name":"Water_Source","x":6,"y":12,"z":-1},{"level":1,"name":"Water_Source","x":6,"y":13,"z":-1},{"level":1,"name":"Water_Source","x":6,"y":14,"z":-1},{"level":1,"name":"Water_Source","x":6,"y":6,"z":0},{"level":1,"name":"Water_Source","x":6,"y":7,"z":0},{"level":1,"name":"Water_Source","x":6,"y":8,"z":0},{"level":1,"name":"Water_Source","x":6,"y":9,"z":0},{"level":1,"name":"Water_Source","x":6,"y":10,"z":0},{"level":1,"name":"Water_Source","x":6,"y":11,"z":0},{"level":1,"name":"Water_Source","x":6,"y":12,"z":0},{"level":1,"name":"Water_Source","x":6,"y":13,"z":0},{"level":1,"name":"Water_Source","x":6,"y":14,"z":0},{"level":1,"name":"Water_Source","x":6,"y":6,"z":1},{"level":1,"name":"Water_Source","x":6,"y":7,"z":1},{"level":1,"name":"Water_Source","x":6,"y":8,"z":1},{"level":1,"name":"Water_Source","x":6,"y":9,"z":1},{"level":1,"name":"Water_Source","x":6,"y":10,"z":1},{"level":1,"name":"Water_Source","x":6,"y":11,"z":1},{"level":1,"name":"Water_Source","x":6,"y":12,"z":1},{"level":1,"name":"Water_Source","x":6,"y":13,"z":1},{"level":1,"name":"Water_Source","x":6,"y":14,"z":1},{"level":1,"name":"Water_Source","x":6,"y":13,"z":2},{"level":1,"name":"Water_Source","x":6,"y":14,"z":2},{"level":1,"name":"Water_Source","x":6,"y":13,"z":3},{"level":1,"name":"Water_Source","x":6,"y":6,"z":7},{"level":1,"name":"Water_Source","x":6,"y":7,"z":7},{"level":1,"name":"Water_Source","x":6,"y":8,"z":7},{"level":1,"name":"Water_Source","x":6,"y":9,"z":7},{"level":1,"name":"Water_Source","x":6,"y":10,"z":7},{"level":1,"name":"Water_Source","x":6,"y":11,"z":7},{"level":1,"name":"Water_Source","x":6,"y":12,"z":7},{"level":1,"name":"Water_Source","x":6,"y":13,"z":7},{"level":1,"name":"Water_Source","x":6,"y":14,"z":7},{"level":1,"name":"Water_Source","x":6,"y":15,"z":7},{"level":1,"name":"Water_Source","x":6,"y":15,"z":8},{"level":1,"name":"Water_Source","x":6,"y":16,"z":8},{"level":1,"name":"Water_Source","x":6,"y":15,"z":9},{"level":1,"name":"Water_Source","x":7,"y":12,"z":-3},{"level":1,"name":"Water_Source","x":7,"y":12,"z":-2},{"level":1,"name":"Water_Source","x":7,"y":6,"z":-1},{"level":1,"name":"Water_Source","x":7,"y":7,"z":-1},{"level":1,"name":"Water_Source","x":7,"y":8,"z":-1},{"level":1,"name":"Water_Source","x":7,"y":9,"z":-1},{"level":1,"name":"Water_Source","x":7,"y":10,"z":-1},{"level":1,"name":"Water_Source","x":7,"y":11,"z":-1},{"level":1,"name":"Water_Source","x":7,"y":12,"z":-1},{"level":1,"name":"Water_Source","x":7,"y":13,"z":-1},{"level":1,"name":"Water_Source","x":7,"y":14,"z":-1},{"level":1,"name":"Water_Source","x":7,"y":6,"z":0},{"level":1,"name":"Water_Source","x":7,"y":7,"z":0},{"level":1,"name":"Water_Source","x":7,"y":8,"z":0},{"level":1,"name":"Water_Source","x":7,"y":9,"z":0},{"level":1,"name":"Water_Source","x":7,"y":10,"z":0},{"level":1,"name":"Water_Source","x":7,"y":11,"z":0},{"level":1,"name":"Water_Source","x":7,"y":12,"z":0},{"level":1,"name":"Water_Source","x":7,"y":13,"z":0},{"level":1,"name":"Water_Source","x":7,"y":14,"z":0},{"level":1,"name":"Water_Source","x":7,"y":6,"z":1},{"level":1,"name":"Water_Source","x":7,"y":7,"z":1},{"level":1,"name":"Water_Source","x":7,"y":8,"z":1},{"level":1,"name":"Water_Source","x":7,"y":9,"z":1},{"level":1,"name":"Water_Source","x":7,"y":10,"z":1},{"level":1,"name":"Water_Source","x":7,"y":11,"z":1},{"level":1,"name":"Water_Source","x":7,"y":12,"z":1},{"level":1,"name":"Water_Source","x":7,"y":13,"z":1},{"level":1,"name":"Water_Source","x":7,"y":14,"z":1},{"level":1,"name":"Water_Source","x":7,"y":15,"z":1},{"level":1,"name":"Water_Source","x":7,"y":13,"z":2},{"level":1,"name":"Water_Source","x":7,"y":14,"z":2},{"level":1,"name":"Water_Source","x":7,"y":13,"z":3},{"level":1,"name":"Water_Source","x":7,"y":6,"z":7},{"level":1,"name":"Water_Source","x":7,"y":7,"z":7},{"level":1,"name":"Water_Source","x":7,"y":8,"z":7},{"level":1,"name":"Water_Source","x":7,"y":9,"z":7},{"level":1,"name":"Water_Source","x":7,"y":10,"z":7},{"level":1,"name":"Water_Source","x":7,"y":11,"z":7},{"level":1,"name":"Water_Source","x":7,"y":12,"z":7},{"level":1,"name":"Water_Source","x":7,"y":13,"z":7},{"level":1,"name":"Water_Source","x":7,"y":14,"z":7},{"level":1,"name":"Water_Source","x":7,"y":15,"z":7},{"level":1,"name":"Water_Source","x":7,"y":15,"z":8},{"level":1,"name":"Water_Source","x":7,"y":15,"z":9},{"level":1,"name":"Water_Source","x":8,"y":12,"z":-3},{"level":1,"name":"Water_Source","x":8,"y":13,"z":-3},{"level":1,"name":"Water_Source","x":8,"y":12,"z":-2},{"level":1,"name":"Water_Source","x":8,"y":6,"z":-1},{"level":1,"name":"Water_Source","x":8,"y":7,"z":-1},{"level":1,"name":"Water_Source","x":8,"y":8,"z":-1},{"level":1,"name":"Water_Source","x":8,"y":9,"z":-1},{"level":1,"name":"Water_Source","x":8,"y":10,"z":-1},{"level":1,"name":"Water_Source","x":8,"y":11,"z":-1},{"level":1,"name":"Water_Source","x":8,"y":12,"z":-1},{"level":1,"name":"Water_Source","x":8,"y":13,"z":-1},{"level":1,"name":"Water_Source","x":8,"y":14,"z":-1},{"level":1,"name":"Water_Source","x":8,"y":15,"z":-1},{"level":1,"name":"Water_Source","x":8,"y":6,"z":0},{"level":1,"name":"Water_Source","x":8,"y":7,"z":0},{"level":1,"name":"Water_Source","x":8,"y":8,"z":0},{"level":1,"name":"Water_Source","x":8,"y":9,"z":0},{"level":1,"name":"Water_Source","x":8,"y":10,"z":0},{"level":1,"name":"Water_Source","x":8,"y":11,"z":0},{"level":1,"name":"Water_Source","x":8,"y":12,"z":0},{"level":1,"name":"Water_Source","x":8,"y":13,"z":0},{"level":1,"name":"Water_Source","x":8,"y":14,"z":0},{"level":1,"name":"Water_Source","x":8,"y":15,"z":0},{"level":1,"name":"Water_Source","x":8,"y":6,"z":1},{"level":1,"name":"Water_Source","x":8,"y":7,"z":1},{"level":1,"name":"Water_Source","x":8,"y":8,"z":1},{"level":1,"name":"Water_Source","x":8,"y":9,"z":1},{"level":1,"name":"Water_Source","x":8,"y":10,"z":1},{"level":1,"name":"Water_Source","x":8,"y":11,"z":1},{"level":1,"name":"Water_Source","x":8,"y":12,"z":1},{"level":1,"name":"Water_Source","x":8,"y":13,"z":1},{"level":1,"name":"Water_Source","x":8,"y":14,"z":1},{"level":1,"name":"Water_Source","x":8,"y":15,"z":1},{"level":1,"name":"Water_Source","x":8,"y":13,"z":2},{"level":1,"name":"Water_Source","x":8,"y":6,"z":7},{"level":1,"name":"Water_Source","x":8,"y":7,"z":7},{"level":1,"name":"Water_Source","x":8,"y":8,"z":7},{"level":1,"name":"Water_Source","x":8,"y":9,"z":7},{"level":1,"name":"Water_Source","x":8,"y":10,"z":7},{"level":1,"name":"Water_Source","x":8,"y":11,"z":7},{"level":1,"name":"Water_Source","x":8,"y":12,"z":7},{"level":1,"name":"Water_Source","x":8,"y":13,"z":7},{"level":1,"name":"Water_Source","x":8,"y":14,"z":7},{"level":1,"name":"Water_Source","x":8,"y":15,"z":8},{"level":1,"name":"Water_Source","x":9,"y":12,"z":-2},{"level":1,"name":"Water_Source","x":9,"y":6,"z":-1},{"level":1,"name":"Water_Source","x":9,"y":7,"z":-1},{"level":1,"name":"Water_Source","x":9,"y":8,"z":-1},{"level":1,"name":"Water_Source","x":9,"y":9,"z":-1},{"level":1,"name":"Water_Source","x":9,"y":10,"z":-1},{"level":1,"name":"Water_Source","x":9,"y":11,"z":-1},{"level":1,"name":"Water_Source","x":9,"y":12,"z":-1},{"level":1,"name":"Water_Source","x":9,"y":13,"z":-1},{"level":1,"name":"Water_Source","x":9,"y":14,"z":-1},{"level":1,"name":"Water_Source","x":9,"y":15,"z":-1},{"level":1,"name":"Water_Source","x":9,"y":6,"z":0},{"level":1,"name":"Water_Source","x":9,"y":7,"z":0},{"level":1,"name":"Water_Source","x":9,"y":8,"z":0},{"level":1,"name":"Water_Source","x":9,"y":9,"z":0},{"level":1,"name":"Water_Source","x":9,"y":10,"z":0},{"level":1,"name":"Water_Source","x":9,"y":11,"z":0},{"level":1,"name":"Water_Source","x":9,"y":12,"z":0},{"level":1,"name":"Water_Source","x":9,"y":13,"z":0},{"level":1,"name":"Water_Source","x":9,"y":14,"z":0},{"level":1,"name":"Water_Source","x":9,"y":15,"z":0},{"level":1,"name":"Water_Source","x":9,"y":6,"z":1},{"level":1,"name":"Water_Source","x":9,"y":7,"z":1},{"level":1,"name":"Water_Source","x":9,"y":8,"z":1},{"level":1,"name":"Water_Source","x":9,"y":9,"z":1},{"level":1,"name":"Water_Source","x":9,"y":10,"z":1},{"level":1,"name":"Water_Source","x":9,"y":11,"z":1},{"level":1,"name":"Water_Source","x":9,"y":12,"z":1},{"level":1,"name":"Water_Source","x":9,"y":13,"z":1},{"level":1,"name":"Water_Source","x":9,"y":14,"z":1},{"level":1,"name":"Water_Source","x":9,"y":10,"z":7},{"level":1,"name":"Water_Source","x":10,"y":10,"z":0}],"version":8}