{"anchorX":0,"anchorY":7,"anchorZ":0,"blockIdVersion":11,"blocks":[{"name":"Rock_Sandstone_Brick","x":-4,"y":6,"z":-4},{"name":"Rock_Sandstone_Brick","x":-4,"y":7,"z":-4},{"name":"Rock_Sandstone_Brick","x":-4,"y":8,"z":-4},{"name":"Rock_Sandstone_Brick","x":-4,"y":9,"z":-4},{"name":"Rock_Sandstone_Brick","x":-4,"y":10,"z":-4},{"name":"Rock_Sandstone_Brick","x":-4,"y":11,"z":-4},{"name":"Rock_Sandstone_Brick","x":-4,"y":12,"z":-4},{"name":"Rock_Sandstone_Brick","x":-4,"y":13,"z":-4},{"name":"Rock_Sandstone_Brick","x":-4,"y":14,"z":-4},{"name":"Rock_Sandstone_Brick","x":-4,"y":6,"z":-3},{"name":"Rock_Sandstone_Brick","x":-4,"y":7,"z":-3},{"name":"Rock_Sandstone_Brick","x":-4,"y":8,"z":-3},{"name":"Rock_Sandstone_Brick","x":-4,"y":9,"z":-3},{"name":"Rock_Sandstone_Brick","x":-4,"y":10,"z":-3},{"name":"Rock_Sandstone_Brick","x":-4,"y":11,"z":-3},{"name":"Rock_Sandstone_Brick","x":-4,"y":12,"z":-3},{"name":"Rock_Sandstone_Brick","x":-4,"y":13,"z":-3},{"name":"Rock_Sandstone_Brick","x":-4,"y":14,"z":-3},{"name":"Rock_Sandstone_Brick","x":-4,"y":6,"z":-2},{"name":"Rock_Sandstone_Brick","x":-4,"y":7,"z":-2},{"name":"Rock_Sandstone_Brick","x":-4,"y":8,"z":-2},{"name":"Rock_Sandstone_Brick","x":-4,"y":9,"z":-2},{"name":"Rock_Sandstone_Brick","x":-4,"y":10,"z":-2},{"name":"Rock_Sandstone_Brick","x":-4,"y":11,"z":-2},{"name":"Rock_Sandstone_Brick","x":-4,"y":12,"z":-2},{"name":"Rock_Sandstone_Brick","x":-4,"y":13,"z":-2},{"name":"Rock_Sandstone_Brick","x":-4,"y":14,"z":-2},{"name":"Rock_Sandstone_Brick","x":-4,"y":6,"z":-1},{"name":"Rock_Sandstone_Brick","x":-4,"y":7,"z":-1},{"name":"Rock_Sandstone_Brick","x":-4,"y":8,"z":-1},{"name":"Rock_Sandstone_Brick","x":-4,"y":9,"z":-1},{"name":"Rock_Sandstone_Brick","x":-4,"y":10,"z":-1},{"name":"Rock_Sandstone_Brick","x":-4,"y":13,"z":-1},{"name":"Rock_Sandstone_Brick","x":-4,"y":6,"z":0},{"name":"Rock_Sandstone_Brick","x":-4,"y":7,"z":0},{"name":"Rock_Sandstone_Brick","x":-4,"y":8,"z":0},{"name":"Rock_Sandstone_Brick","x":-4,"y":9,"z":0},{"name":"Rock_Sandstone_Brick","x":-4,"y":10,"z":0},{"name":"Rock_Sandstone_Brick","x":-4,"y":13,"z":0},{"name":"Rock_Sandstone_Brick","x":-4,"y":6,"z":1},{"name":"Rock_Sandstone_Brick","x":-4,"y":7,"z":1},{"name":"Rock_Sandstone_Brick","x":-4,"y":8,"z":1},{"name":"Rock_Sandstone_Brick","x":-4,"y":9,"z":1},{"name":"Rock_Sandstone_Brick","x":-4,"y":10,"z":1},{"name":"Rock_Sandstone_Brick","x":-4,"y":11,"z":1},{"name":"Rock_Sandstone_Brick","x":-4,"y":12,"z":1},{"name":"Rock_Sandstone_Brick","x":-4,"y":13,"z":1},{"name":"Rock_Sandstone_Brick","x":-4,"y":6,"z":2},{"name":"Rock_Sandstone_Brick","x":-4,"y":7,"z":2},{"name":"Rock_Sandstone_Brick","x":-4,"y":8,"z":2},{"name":"Rock_Sandstone_Brick","x":-4,"y":9,"z":2},{"name":"Rock_Sandstone_Brick","x":-4,"y":10,"z":2},{"name":"Rock_Sandstone_Brick","x":-4,"y":11,"z":2},{"name":"Rock_Sandstone_Brick","x":-4,"y":12,"z":2},{"name":"Rock_Sandstone_Brick","x":-4,"y":13,"z":2},{"name":"Rock_Sandstone_Brick","x":-4,"y":6,"z":3},{"name":"Rock_Sandstone_Brick","x":-4,"y":7,"z":3},{"name":"Rock_Sandstone_Brick","x":-4,"y":8,"z":3},{"name":"Rock_Sandstone_Brick","x":-4,"y":9,"z":3},{"name":"Rock_Sandstone_Brick","x":-4,"y":10,"z":3},{"name":"Rock_Sandstone_Brick","x":-4,"y":11,"z":3},{"name":"Rock_Sandstone_Brick","x":-4,"y":12,"z":3},{"name":"Rock_Sandstone_Brick","x":-4,"y":13,"z":3},{"name":"Rock_Sandstone_Brick","x":-4,"y":6,"z":4},{"name":"Rock_Sandstone_Brick","x":-4,"y":7,"z":4},{"name":"Rock_Sandstone_Brick","x":-4,"y":8,"z":4},{"name":"Rock_Sandstone_Brick","x":-4,"y":9,"z":4},{"name":"Rock_Sandstone_Brick","x":-4,"y":10,"z":4},{"name":"Rock_Sandstone_Brick","x":-4,"y":11,"z":4},{"name":"Rock_Sandstone_Brick","x":-4,"y":12,"z":4},{"name":"Rock_Sandstone_Brick","x":-4,"y":6,"z":5},{"name":"Rock_Sandstone_Brick","x":-4,"y":7,"z":5},{"name":"Rock_Sandstone_Brick","x":-4,"y":8,"z":5},{"name":"Rock_Sandstone_Brick","x":-4,"y":9,"z":5},{"name":"Rock_Sandstone_Brick","x":-4,"y":10,"z":5},{"name":"Rock_Sandstone_Brick","x":-4,"y":11,"z":5},{"name":"Rock_Sandstone_Brick","x":-4,"y":12,"z":5},{"name":"Rock_Sandstone_Brick","x":-4,"y":13,"z":5},{"name":"Rock_Sandstone_Brick","x":-4,"y":14,"z":5},{"name":"Rock_Sandstone_Brick","x":-4,"y":15,"z":5},{"name":"Rock_Sandstone_Brick","x":-3,"y":6,"z":5},{"name":"Rock_Sandstone_Brick","x":-3,"y":7,"z":5},{"name":"Rock_Sandstone_Brick","x":-3,"y":8,"z":5},{"name":"Rock_Sandstone_Brick","x":-3,"y":9,"z":5},{"name":"Rock_Sandstone_Brick","x":-3,"y":10,"z":5},{"name":"Rock_Sandstone_Brick_Half","rotation":5,"x":-3,"y":11,"z":5},{"name":"Rock_Sandstone_Brick_Half","rotation":5,"x":-3,"y":12,"z":5},{"name":"Rock_Sandstone_Brick_Half","rotation":5,"x":-3,"y":13,"z":5},{"name":"Rock_Sandstone_Brick","x":-3,"y":14,"z":5},{"name":"Rock_Sandstone_Brick","x":-3,"y":15,"z":5},{"name":"Rock_Sandstone_Brick","x":-2,"y":6,"z":5},{"name":"Rock_Sandstone_Brick","x":-2,"y":7,"z":5},{"name":"Rock_Sandstone_Brick","x":-2,"y":8,"z":5},{"name":"Rock_Sandstone_Brick","x":-2,"y":9,"z":5},{"name":"Rock_Sandstone_Brick","x":-2,"y":10,"z":5},{"name":"Rock_Sandstone_Brick_Half","rotation":8,"x":-2,"y":14,"z":5},{"name":"Rock_Sandstone_Brick","x":-2,"y":15,"z":5},{"name":"Rock_Sandstone_Brick","x":-1,"y":6,"z":5},{"name":"Rock_Sandstone_Brick","x":-1,"y":7,"z":5},{"name":"Rock_Sandstone_Brick","x":-1,"y":8,"z":5},{"name":"Rock_Sandstone_Brick","x":-1,"y":9,"z":5},{"name":"Rock_Sandstone_Brick","x":-1,"y":10,"z":5},{"name":"Rock_Sandstone_Brick_Half","rotation":7,"x":-1,"y":11,"z":5},{"name":"Rock_Sandstone_Brick_Half","rotation":7,"x":-1,"y":12,"z":5},{"name":"Rock_Sandstone_Brick_Half","rotation":7,"x":-1,"y":13,"z":5},{"name":"Rock_Sandstone_Brick","x":-1,"y":14,"z":5},{"name":"Plant_Coral_Block_Red","x":0,"y":15,"z":4},{"name":"Rock_Sandstone_Brick","x":0,"y":6,"z":5},{"name":"Rock_Sandstone_Brick","x":0,"y":7,"z":5},{"name":"Rock_Sandstone_Brick","x":0,"y":8,"z":5},{"name":"Rock_Sandstone_Brick","x":0,"y":9,"z":5},{"name":"Rock_Sandstone_Brick","x":0,"y":10,"z":5},{"name":"Rock_Sandstone_Brick","x":0,"y":11,"z":5},{"name":"Rock_Sandstone_Brick","x":0,"y":12,"z":5},{"name":"Rock_Sandstone_Brick","x":0,"y":13,"z":5},{"name":"Rock_Sandstone_Brick","x":0,"y":14,"z":5},{"name":"Plant_Coral_Block_Red","x":0,"y":15,"z":5},{"name":"Plant_Coral_Block_Red","x":0,"y":15,"z":6},{"name":"Plant_Coral_Block_Red","x":1,"y":15,"z":2},{"name":"Plant_Coral_Block_Red","x":1,"y":15,"z":3},{"name":"Plant_Coral_Block_Yellow","x":1,"y":15,"z":4},{"name":"Rock_Sandstone_Brick","x":1,"y":6,"z":5},{"name":"Rock_Sandstone_Brick","x":1,"y":7,"z":5},{"name":"Rock_Sandstone_Brick","x":1,"y":8,"z":5},{"name":"Rock_Sandstone_Brick","x":1,"y":9,"z":5},{"name":"Rock_Sandstone_Brick","x":1,"y":10,"z":5},{"name":"Rock_Sandstone_Brick","x":1,"y":11,"z":5},{"name":"Rock_Sandstone_Brick","x":1,"y":12,"z":5},{"name":"Rock_Sandstone_Brick","x":1,"y":13,"z":5},{"name":"Rock_Sandstone_Brick","x":1,"y":14,"z":5},{"name":"Plant_Coral_Block_Yellow","x":1,"y":15,"z":5},{"name":"Plant_Coral_Block_Yellow","x":1,"y":15,"z":6},{"name":"Plant_Coral_Model_Orange","x":1,"y":16,"z":6},{"name":"Plant_Coral_Block_Red","x":2,"y":15,"z":2},{"name":"Plant_Coral_Block_Yellow","x":2,"y":15,"z":3},{"name":"Plant_Coral_Block_Yellow","x":2,"y":15,"z":4},{"name":"Plant_Coral_Model_Orange","x":2,"y":16,"z":4},{"name":"Rock_Sandstone_Brick","x":2,"y":6,"z":5},{"name":"Rock_Sandstone_Brick","x":2,"y":7,"z":5},{"name":"Rock_Sandstone_Brick","x":2,"y":8,"z":5},{"name":"Rock_Sandstone_Brick","x":2,"y":9,"z":5},{"name":"Rock_Sandstone_Brick","x":2,"y":10,"z":5},{"name":"Rock_Sandstone_Brick","x":2,"y":11,"z":5},{"name":"Rock_Sandstone_Brick","x":2,"y":12,"z":5},{"name":"Rock_Sandstone_Brick","x":2,"y":13,"z":5},{"name":"Rock_Sandstone_Brick","x":2,"y":14,"z":5},{"name":"Rock_Sandstone_Brick","x":2,"y":15,"z":5},{"name":"Plant_Coral_Block_Yellow","x":2,"y":15,"z":6},{"name":"Plant_Coral_Block_Yellow","x":2,"y":15,"z":7},{"name":"Plant_Coral_Block_Red","x":2,"y":15,"z":8},{"name":"Plant_Coral_Block_Yellow","x":3,"y":15,"z":3},{"name":"Plant_Coral_Block_Yellow","x":3,"y":15,"z":4},{"name":"Rock_Sandstone_Brick","x":3,"y":6,"z":5},{"name":"Rock_Sandstone_Brick","x":3,"y":7,"z":5},{"name":"Rock_Sandstone_Brick","x":3,"y":8,"z":5},{"name":"Rock_Sandstone_Brick","x":3,"y":9,"z":5},{"name":"Rock_Sandstone_Brick","x":3,"y":10,"z":5},{"name":"Rock_Sandstone_Brick","x":3,"y":11,"z":5},{"name":"Wood_Goldenwood_Fence","x":3,"y":12,"z":5},{"name":"Wood_Goldenwood_Fence","x":3,"y":13,"z":5},{"name":"Rock_Sandstone_Brick_Stairs","rotation":11,"x":3,"y":14,"z":5},{"name":"Rock_Sandstone_Brick","x":3,"y":15,"z":5},{"name":"Plant_Coral_Bush_Orange","x":3,"y":16,"z":5},{"name":"Plant_Coral_Block_Yellow","x":3,"y":15,"z":6},{"name":"Plant_Coral_Bush_Orange","x":3,"y":16,"z":6},{"name":"Plant_Coral_Block_Yellow","x":3,"y":15,"z":7},{"name":"Plant_Coral_Block_Red","x":3,"y":15,"z":8},{"name":"Plant_Coral_Block_Red","x":4,"y":15,"z":2},{"name":"Plant_Coral_Block_Yellow","x":4,"y":15,"z":3},{"name":"Plant_Coral_Block_Yellow","x":4,"y":15,"z":4},{"name":"Plant_Coral_Bush_Orange","x":4,"y":16,"z":4},{"name":"Rock_Sandstone_Brick","x":4,"y":6,"z":5},{"name":"Rock_Sandstone_Brick","x":4,"y":7,"z":5},{"name":"Rock_Sandstone_Brick","x":4,"y":8,"z":5},{"name":"Rock_Sandstone_Brick","x":4,"y":9,"z":5},{"name":"Rock_Sandstone_Brick","x":4,"y":10,"z":5},{"name":"Rock_Sandstone_Brick","x":4,"y":11,"z":5},{"name":"Wood_Goldenwood_Fence","rotation":2,"x":4,"y":12,"z":5},{"name":"Wood_Goldenwood_Fence","rotation":2,"x":4,"y":13,"z":5},{"name":"Rock_Sandstone_Brick_Stairs","rotation":9,"x":4,"y":14,"z":5},{"name":"Rock_Sandstone_Brick","x":4,"y":15,"z":5},{"name":"Plant_Coral_Block_Yellow","x":4,"y":15,"z":6},{"name":"Plant_Coral_Block_Yellow","x":4,"y":15,"z":7},{"name":"Plant_Coral_Block_Red","x":4,"y":15,"z":8},{"name":"Rock_Sandstone_Brick","x":5,"y":6,"z":-1},{"name":"Rock_Sandstone_Brick","x":5,"y":7,"z":-1},{"name":"Rock_Sandstone_Brick","x":5,"y":8,"z":-1},{"name":"Rock_Sandstone_Brick","x":5,"y":9,"z":-1},{"name":"Rock_Sandstone_Brick","x":5,"y":10,"z":-1},{"name":"Rock_Sandstone_Brick","x":5,"y":11,"z":-1},{"name":"Rock_Sandstone_Brick","x":5,"y":6,"z":0},{"name":"Rock_Sandstone_Brick","x":5,"y":7,"z":0},{"name":"Rock_Sandstone_Brick","x":5,"y":8,"z":0},{"name":"Rock_Sandstone_Brick","x":5,"y":9,"z":0},{"name":"Rock_Sandstone_Brick","x":5,"y":10,"z":0},{"name":"Rock_Sandstone_Brick","x":5,"y":11,"z":0},{"name":"Rock_Sandstone_Brick","x":5,"y":12,"z":0},{"name":"Rock_Sandstone_Brick","x":5,"y":6,"z":1},{"name":"Rock_Sandstone_Brick","x":5,"y":7,"z":1},{"name":"Rock_Sandstone_Brick","x":5,"y":8,"z":1},{"name":"Rock_Sandstone_Brick","x":5,"y":9,"z":1},{"name":"Rock_Sandstone_Brick","x":5,"y":10,"z":1},{"name":"Rock_Sandstone_Brick","x":5,"y":11,"z":1},{"name":"Rock_Sandstone_Brick","x":5,"y":12,"z":1},{"name":"Rock_Sandstone_Brick","x":5,"y":6,"z":2},{"name":"Rock_Sandstone_Brick","x":5,"y":7,"z":2},{"name":"Rock_Sandstone_Brick","x":5,"y":8,"z":2},{"name":"Rock_Sandstone_Brick","x":5,"y":9,"z":2},{"name":"Rock_Sandstone_Brick","x":5,"y":10,"z":2},{"name":"Rock_Sandstone_Brick","x":5,"y":11,"z":2},{"name":"Rock_Sandstone_Brick","x":5,"y":12,"z":2},{"name":"Rock_Sandstone_Brick","x":5,"y":6,"z":3},{"name":"Rock_Sandstone_Brick","x":5,"y":7,"z":3},{"name":"Rock_Sandstone_Brick","x":5,"y":8,"z":3},{"name":"Rock_Sandstone_Brick","x":5,"y":9,"z":3},{"name":"Rock_Sandstone_Brick","x":5,"y":10,"z":3},{"name":"Rock_Sandstone_Brick","x":5,"y":11,"z":3},{"name":"Rock_Sandstone_Brick","x":5,"y":12,"z":3},{"name":"Rock_Sandstone_Brick","x":5,"y":13,"z":3},{"name":"Plant_Coral_Block_Red","x":5,"y":15,"z":3},{"name":"Rock_Sandstone_Brick","x":5,"y":6,"z":4},{"name":"Rock_Sandstone_Brick","x":5,"y":7,"z":4},{"name":"Rock_Sandstone_Brick","x":5,"y":8,"z":4},{"name":"Rock_Sandstone_Brick","x":5,"y":9,"z":4},{"name":"Rock_Sandstone_Brick","x":5,"y":10,"z":4},{"name":"Rock_Sandstone_Brick","x":5,"y":11,"z":4},{"name":"Rock_Sandstone_Brick","x":5,"y":12,"z":4},{"name":"Rock_Sandstone_Brick","x":5,"y":13,"z":4},{"name":"Plant_Coral_Block_Yellow","x":5,"y":15,"z":4},{"name":"Rock_Sandstone_Brick","x":5,"y":6,"z":5},{"name":"Rock_Sandstone_Brick","x":5,"y":7,"z":5},{"name":"Rock_Sandstone_Brick","x":5,"y":8,"z":5},{"name":"Rock_Sandstone_Brick","x":5,"y":9,"z":5},{"name":"Rock_Sandstone_Brick","x":5,"y":10,"z":5},{"name":"Rock_Sandstone_Brick","x":5,"y":11,"z":5},{"name":"Rock_Sandstone_Brick","x":5,"y":12,"z":5},{"name":"Rock_Sandstone_Brick","x":5,"y":13,"z":5},{"name":"Rock_Sandstone_Brick","x":5,"y":14,"z":5},{"name":"Plant_Coral_Block_Yellow","x":5,"y":15,"z":5},{"name":"Plant_Coral_Block_Yellow","x":5,"y":15,"z":6},{"name":"Plant_Coral_Block_Red","x":5,"y":15,"z":7},{"name":"Plant_Coral_Block_Red","x":6,"y":15,"z":3},{"name":"Plant_Coral_Block_Red","x":6,"y":15,"z":4},{"name":"Plant_Coral_Block_Red","x":6,"y":15,"z":5}],"fluids":[{"level":1,"name":"Water_Source","x":-4,"y":6,"z":-4},{"level":1,"name":"Water_Source","x":-4,"y":7,"z":-4},{"level":1,"name":"Water_Source","x":-4,"y":8,"z":-4},{"level":1,"name":"Water_Source","x":-4,"y":9,"z":-4},{"level":1,"name":"Water_Source","x":-4,"y":10,"z":-4},{"level":1,"name":"Water_Source","x":-4,"y":11,"z":-4},{"level":1,"name":"Water_Source","x":-4,"y":12,"z":-4},{"level":1,"name":"Water_Source","x":-4,"y":13,"z":-4},{"level":1,"name":"Water_Source","x":-4,"y":14,"z":-4},{"level":1,"name":"Water_Source","x":-4,"y":6,"z":-3},{"level":1,"name":"Water_Source","x":-4,"y":7,"z":-3},{"level":1,"name":"Water_Source","x":-4,"y":8,"z":-3},{"level":1,"name":"Water_Source","x":-4,"y":9,"z":-3},{"level":1,"name":"Water_Source","x":-4,"y":10,"z":-3},{"level":1,"name":"Water_Source","x":-4,"y":11,"z":-3},{"level":1,"name":"Water_Source","x":-4,"y":12,"z":-3},{"level":1,"name":"Water_Source","x":-4,"y":13,"z":-3},{"level":1,"name":"Water_Source","x":-4,"y":14,"z":-3},{"level":1,"name":"Water_Source","x":-4,"y":6,"z":-2},{"level":1,"name":"Water_Source","x":-4,"y":7,"z":-2},{"level":1,"name":"Water_Source","x":-4,"y":8,"z":-2},{"level":1,"name":"Water_Source","x":-4,"y":9,"z":-2},{"level":1,"name":"Water_Source","x":-4,"y":10,"z":-2},{"level":1,"name":"Water_Source","x":-4,"y":11,"z":-2},{"level":1,"name":"Water_Source","x":-4,"y":12,"z":-2},{"level":1,"name":"Water_Source","x":-4,"y":13,"z":-2},{"level":1,"name":"Water_Source","x":-4,"y":14,"z":-2},{"level":1,"name":"Water_Source","x":-4,"y":6,"z":-1},{"level":1,"name":"Water_Source","x":-4,"y":7,"z":-1},{"level":1,"name":"Water_Source","x":-4,"y":8,"z":-1},{"level":1,"name":"Water_Source","x":-4,"y":9,"z":-1},{"level":1,"name":"Water_Source","x":-4,"y":10,"z":-1},{"level":1,"name":"Water_Source","x":-4,"y":13,"z":-1},{"level":1,"name":"Water_Source","x":-4,"y":6,"z":0},{"level":1,"name":"Water_Source","x":-4,"y":7,"z":0},{"level":1,"name":"Water_Source","x":-4,"y":8,"z":0},{"level":1,"name":"Water_Source","x":-4,"y":9,"z":0},{"level":1,"name":"Water_Source","x":-4,"y":10,"z":0},{"level":1,"name":"Water_Source","x":-4,"y":13,"z":0},{"level":1,"name":"Water_Source","x":-4,"y":6,"z":1},{"level":1,"name":"Water_Source","x":-4,"y":7,"z":1},{"level":1,"name":"Water_Source","x":-4,"y":8,"z":1},{"level":1,"name":"Water_Source","x":-4,"y":9,"z":1},{"level":1,"name":"Water_Source","x":-4,"y":10,"z":1},{"level":1,"name":"Water_Source","x":-4,"y":11,"z":1},{"level":1,"name":"Water_Source","x":-4,"y":12,"z":1},{"level":1,"name":"Water_Source","x":-4,"y":13,"z":1},{"level":1,"name":"Water_Source","x":-4,"y":6,"z":2},{"level":1,"name":"Water_Source","x":-4,"y":7,"z":2},{"level":1,"name":"Water_Source","x":-4,"y":8,"z":2},{"level":1,"name":"Water_Source","x":-4,"y":9,"z":2},{"level":1,"name":"Water_Source","x":-4,"y":10,"z":2},{"level":1,"name":"Water_Source","x":-4,"y":11,"z":2},{"level":1,"name":"Water_Source","x":-4,"y":12,"z":2},{"level":1,"name":"Water_Source","x":-4,"y":13,"z":2},{"level":1,"name":"Water_Source","x":-4,"y":6,"z":3},{"level":1,"name":"Water_Source","x":-4,"y":7,"z":3},{"level":1,"name":"Water_Source","x":-4,"y":8,"z":3},{"level":1,"name":"Water_Source","x":-4,"y":9,"z":3},{"level":1,"name":"Water_Source","x":-4,"y":10,"z":3},{"level":1,"name":"Water_Source","x":-4,"y":11,"z":3},{"level":1,"name":"Water_Source","x":-4,"y":12,"z":3},{"level":1,"name":"Water_Source","x":-4,"y":13,"z":3},{"level":1,"name":"Water_Source","x":-4,"y":6,"z":4},{"level":1,"name":"Water_Source","x":-4,"y":7,"z":4},{"level":1,"name":"Water_Source","x":-4,"y":8,"z":4},{"level":1,"name":"Water_Source","x":-4,"y":9,"z":4},{"level":1,"name":"Water_Source","x":-4,"y":10,"z":4},{"level":1,"name":"Water_Source","x":-4,"y":11,"z":4},{"level":1,"name":"Water_Source","x":-4,"y":12,"z":4},{"level":1,"name":"Water_Source","x":-4,"y":6,"z":5},{"level":1,"name":"Water_Source","x":-4,"y":7,"z":5},{"level":1,"name":"Water_Source","x":-4,"y":8,"z":5},{"level":1,"name":"Water_Source","x":-4,"y":9,"z":5},{"level":1,"name":"Water_Source","x":-4,"y":10,"z":5},{"level":1,"name":"Water_Source","x":-4,"y":11,"z":5},{"level":1,"name":"Water_Source","x":-4,"y":12,"z":5},{"level":1,"name":"Water_Source","x":-4,"y":13,"z":5},{"level":1,"name":"Water_Source","x":-4,"y":14,"z":5},{"level":1,"name":"Water_Source","x":-4,"y":15,"z":5},{"level":1,"name":"Water_Source","x":-3,"y":6,"z":5},{"level":1,"name":"Water_Source","x":-3,"y":7,"z":5},{"level":1,"name":"Water_Source","x":-3,"y":8,"z":5},{"level":1,"name":"Water_Source","x":-3,"y":9,"z":5},{"level":1,"name":"Water_Source","x":-3,"y":10,"z":5},{"level":1,"name":"Water_Source","x":-3,"y":11,"z":5},{"level":1,"name":"Water_Source","x":-3,"y":12,"z":5},{"level":1,"name":"Water_Source","x":-3,"y":13,"z":5},{"level":1,"name":"Water_Source","x":-3,"y":14,"z":5},{"level":1,"name":"Water_Source","x":-3,"y":15,"z":5},{"level":1,"name":"Water_Source","x":-2,"y":6,"z":5},{"level":1,"name":"Water_Source","x":-2,"y":7,"z":5},{"level":1,"name":"Water_Source","x":-2,"y":8,"z":5},{"level":1,"name":"Water_Source","x":-2,"y":9,"z":5},{"level":1,"name":"Water_Source","x":-2,"y":10,"z":5},{"level":1,"name":"Water_Source","x":-2,"y":14,"z":5},{"level":1,"name":"Water_Source","x":-2,"y":15,"z":5},{"level":1,"name":"Water_Source","x":-1,"y":6,"z":5},{"level":1,"name":"Water_Source","x":-1,"y":7,"z":5},{"level":1,"name":"Water_Source","x":-1,"y":8,"z":5},{"level":1,"name":"Water_Source","x":-1,"y":9,"z":5},{"level":1,"name":"Water_Source","x":-1,"y":10,"z":5},{"level":1,"name":"Water_Source","x":-1,"y":11,"z":5},{"level":1,"name":"Water_Source","x":-1,"y":12,"z":5},{"level":1,"name":"Water_Source","x":-1,"y":13,"z":5},{"level":1,"name":"Water_Source","x":-1,"y":14,"z":5},{"level":1,"name":"Water_Source","x":0,"y":15,"z":4},{"level":1,"name":"Water_Source","x":0,"y":6,"z":5},{"level":1,"name":"Water_Source","x":0,"y":7,"z":5},{"level":1,"name":"Water_Source","x":0,"y":8,"z":5},{"level":1,"name":"Water_Source","x":0,"y":9,"z":5},{"level":1,"name":"Water_Source","x":0,"y":10,"z":5},{"level":1,"name":"Water_Source","x":0,"y":11,"z":5},{"level":1,"name":"Water_Source","x":0,"y":12,"z":5},{"level":1,"name":"Water_Source","x":0,"y":13,"z":5},{"level":1,"name":"Water_Source","x":0,"y":14,"z":5},{"level":1,"name":"Water_Source","x":0,"y":15,"z":5},{"level":1,"name":"Water_Source","x":0,"y":15,"z":6},{"level":1,"name":"Water_Source","x":1,"y":15,"z":2},{"level":1,"name":"Water_Source","x":1,"y":15,"z":3},{"level":1,"name":"Water_Source","x":1,"y":15,"z":4},{"level":1,"name":"Water_Source","x":1,"y":6,"z":5},{"level":1,"name":"Water_Source","x":1,"y":7,"z":5},{"level":1,"name":"Water_Source","x":1,"y":8,"z":5},{"level":1,"name":"Water_Source","x":1,"y":9,"z":5},{"level":1,"name":"Water_Source","x":1,"y":10,"z":5},{"level":1,"name":"Water_Source","x":1,"y":11,"z":5},{"level":1,"name":"Water_Source","x":1,"y":12,"z":5},{"level":1,"name":"Water_Source","x":1,"y":13,"z":5},{"level":1,"name":"Water_Source","x":1,"y":14,"z":5},{"level":1,"name":"Water_Source","x":1,"y":15,"z":5},{"level":1,"name":"Water_Source","x":1,"y":15,"z":6},{"level":1,"name":"Water_Source","x":1,"y":16,"z":6},{"level":1,"name":"Water_Source","x":2,"y":15,"z":2},{"level":1,"name":"Water_Source","x":2,"y":15,"z":3},{"level":1,"name":"Water_Source","x":2,"y":15,"z":4},{"level":1,"name":"Water_Source","x":2,"y":16,"z":4},{"level":1,"name":"Water_Source","x":2,"y":6,"z":5},{"level":1,"name":"Water_Source","x":2,"y":7,"z":5},{"level":1,"name":"Water_Source","x":2,"y":8,"z":5},{"level":1,"name":"Water_Source","x":2,"y":9,"z":5},{"level":1,"name":"Water_Source","x":2,"y":10,"z":5},{"level":1,"name":"Water_Source","x":2,"y":11,"z":5},{"level":1,"name":"Water_Source","x":2,"y":12,"z":5},{"level":1,"name":"Water_Source","x":2,"y":13,"z":5},{"level":1,"name":"Water_Source","x":2,"y":14,"z":5},{"level":1,"name":"Water_Source","x":2,"y":15,"z":5},{"level":1,"name":"Water_Source","x":2,"y":15,"z":6},{"level":1,"name":"Water_Source","x":2,"y":15,"z":7},{"level":1,"name":"Water_Source","x":2,"y":15,"z":8},{"level":1,"name":"Water_Source","x":3,"y":15,"z":3},{"level":1,"name":"Water_Source","x":3,"y":15,"z":4},{"level":1,"name":"Water_Source","x":3,"y":6,"z":5},{"level":1,"name":"Water_Source","x":3,"y":7,"z":5},{"level":1,"name":"Water_Source","x":3,"y":8,"z":5},{"level":1,"name":"Water_Source","x":3,"y":9,"z":5},{"level":1,"name":"Water_Source","x":3,"y":10,"z":5},{"level":1,"name":"Water_Source","x":3,"y":11,"z":5},{"level":1,"name":"Water_Source","x":3,"y":12,"z":5},{"level":1,"name":"Water_Source","x":3,"y":13,"z":5},{"level":1,"name":"Water_Source","x":3,"y":14,"z":5},{"level":1,"name":"Water_Source","x":3,"y":15,"z":5},{"level":1,"name":"Water_Source","x":3,"y":16,"z":5},{"level":1,"name":"Water_Source","x":3,"y":15,"z":6},{"level":1,"name":"Water_Source","x":3,"y":16,"z":6},{"level":1,"name":"Water_Source","x":3,"y":15,"z":7},{"level":1,"name":"Water_Source","x":3,"y":15,"z":8},{"level":1,"name":"Water_Source","x":4,"y":15,"z":2},{"level":1,"name":"Water_Source","x":4,"y":15,"z":3},{"level":1,"name":"Water_Source","x":4,"y":15,"z":4},{"level":1,"name":"Water_Source","x":4,"y":16,"z":4},{"level":1,"name":"Water_Source","x":4,"y":6,"z":5},{"level":1,"name":"Water_Source","x":4,"y":7,"z":5},{"level":1,"name":"Water_Source","x":4,"y":8,"z":5},{"level":1,"name":"Water_Source","x":4,"y":9,"z":5},{"level":1,"name":"Water_Source","x":4,"y":10,"z":5},{"level":1,"name":"Water_Source","x":4,"y":11,"z":5},{"level":1,"name":"Water_Source","x":4,"y":12,"z":5},{"level":1,"name":"Water_Source","x":4,"y":13,"z":5},{"level":1,"name":"Water_Source","x":4,"y":14,"z":5},{"level":1,"name":"Water_Source","x":4,"y":15,"z":5},{"level":1,"name":"Water_Source","x":4,"y":15,"z":6},{"level":1,"name":"Water_Source","x":4,"y":15,"z":7},{"level":1,"name":"Water_Source","x":4,"y":15,"z":8},{"level":1,"name":"Water_Source","x":5,"y":6,"z":-1},{"level":1,"name":"Water_Source","x":5,"y":7,"z":-1},{"level":1,"name":"Water_Source","x":5,"y":8,"z":-1},{"level":1,"name":"Water_Source","x":5,"y":9,"z":-1},{"level":1,"name":"Water_Source","x":5,"y":10,"z":-1},{"level":1,"name":"Water_Source","x":5,"y":11,"z":-1},{"level":1,"name":"Water_Source","x":5,"y":6,"z":0},{"level":1,"name":"Water_Source","x":5,"y":7,"z":0},{"level":1,"name":"Water_Source","x":5,"y":8,"z":0},{"level":1,"name":"Water_Source","x":5,"y":9,"z":0},{"level":1,"name":"Water_Source","x":5,"y":10,"z":0},{"level":1,"name":"Water_Source","x":5,"y":11,"z":0},{"level":1,"name":"Water_Source","x":5,"y":12,"z":0},{"level":1,"name":"Water_Source","x":5,"y":6,"z":1},{"level":1,"name":"Water_Source","x":5,"y":7,"z":1},{"level":1,"name":"Water_Source","x":5,"y":8,"z":1},{"level":1,"name":"Water_Source","x":5,"y":9,"z":1},{"level":1,"name":"Water_Source","x":5,"y":10,"z":1},{"level":1,"name":"Water_Source","x":5,"y":11,"z":1},{"level":1,"name":"Water_Source","x":5,"y":12,"z":1},{"level":1,"name":"Water_Source","x":5,"y":6,"z":2},{"level":1,"name":"Water_Source","x":5,"y":7,"z":2},{"level":1,"name":"Water_Source","x":5,"y":8,"z":2},{"level":1,"name":"Water_Source","x":5,"y":9,"z":2},{"level":1,"name":"Water_Source","x":5,"y":10,"z":2},{"level":1,"name":"Water_Source","x":5,"y":11,"z":2},{"level":1,"name":"Water_Source","x":5,"y":12,"z":2},{"level":1,"name":"Water_Source","x":5,"y":6,"z":3},{"level":1,"name":"Water_Source","x":5,"y":7,"z":3},{"level":1,"name":"Water_Source","x":5,"y":8,"z":3},{"level":1,"name":"Water_Source","x":5,"y":9,"z":3},{"level":1,"name":"Water_Source","x":5,"y":10,"z":3},{"level":1,"name":"Water_Source","x":5,"y":11,"z":3},{"level":1,"name":"Water_Source","x":5,"y":12,"z":3},{"level":1,"name":"Water_Source","x":5,"y":13,"z":3},{"level":1,"name":"Water_Source","x":5,"y":15,"z":3},{"level":1,"name":"Water_Source","x":5,"y":6,"z":4},{"level":1,"name":"Water_Source","x":5,"y":7,"z":4},{"level":1,"name":"Water_Source","x":5,"y":8,"z":4},{"level":1,"name":"Water_Source","x":5,"y":9,"z":4},{"level":1,"name":"Water_Source","x":5,"y":10,"z":4},{"level":1,"name":"Water_Source","x":5,"y":11,"z":4},{"level":1,"name":"Water_Source","x":5,"y":12,"z":4},{"level":1,"name":"Water_Source","x":5,"y":13,"z":4},{"level":1,"name":"Water_Source","x":5,"y":15,"z":4},{"level":1,"name":"Water_Source","x":5,"y":6,"z":5},{"level":1,"name":"Water_Source","x":5,"y":7,"z":5},{"level":1,"name":"Water_Source","x":5,"y":8,"z":5},{"level":1,"name":"Water_Source","x":5,"y":9,"z":5},{"level":1,"name":"Water_Source","x":5,"y":10,"z":5},{"level":1,"name":"Water_Source","x":5,"y":11,"z":5},{"level":1,"name":"Water_Source","x":5,"y":12,"z":5},{"level":1,"name":"Water_Source","x":5,"y":13,"z":5},{"level":1,"name":"Water_Source","x":5,"y":14,"z":5},{"level":1,"name":"Water_Source","x":5,"y":15,"z":5},{"level":1,"name":"Water_Source","x":5,"y":15,"z":6},{"level":1,"name":"Water_Source","x":5,"y":15,"z":7},{"level":1,"name":"Water_Source","x":6,"y":15,"z":3},{"level":1,"name":"Water_Source","x":6,"y":15,"z":4},{"level":1,"name":"Water_Source","x":6,"y":15,"z":5}],"version":8}