{"anchorX":6,"anchorY":7,"anchorZ":0,"blockIdVersion":11,"blocks":[{"name":"Rock_Sandstone_Brick","x":3,"y":6,"z":-2},{"name":"Rock_Sandstone_Brick","x":3,"y":7,"z":-2},{"name":"Rock_Sandstone_Brick","x":3,"y":8,"z":-2},{"name":"Rock_Sandstone_Brick","x":3,"y":9,"z":-2},{"name":"Rock_Sandstone_Brick","x":3,"y":10,"z":-2},{"name":"Rock_Sandstone_Brick","x":3,"y":11,"z":-2},{"name":"Rock_Sandstone_Brick","x":3,"y":6,"z":-1},{"name":"Rock_Sandstone_Brick","x":3,"y":7,"z":-1},{"name":"Rock_Sandstone_Brick","x":3,"y":8,"z":-1},{"name":"Rock_Sandstone_Brick","x":3,"y":9,"z":-1},{"name":"Rock_Sandstone_Brick","x":3,"y":10,"z":-1},{"name":"Rock_Sandstone_Brick","x":3,"y":11,"z":-1},{"name":"Rock_Sandstone_Brick","x":3,"y":6,"z":0},{"name":"Rock_Sandstone_Brick","x":3,"y":7,"z":0},{"name":"Rock_Sandstone_Brick","x":3,"y":8,"z":0},{"name":"Rock_Sandstone_Brick","x":3,"y":9,"z":0},{"name":"Rock_Sandstone_Brick","x":3,"y":10,"z":0},{"name":"Rock_Sandstone_Brick","x":3,"y":11,"z":0},{"name":"Rock_Sandstone_Brick","x":3,"y":6,"z":1},{"name":"Rock_Sandstone_Brick","x":3,"y":7,"z":1},{"name":"Rock_Sandstone_Brick","x":3,"y":8,"z":1},{"name":"Rock_Sandstone_Brick","x":3,"y":9,"z":1},{"name":"Rock_Sandstone_Brick","x":3,"y":10,"z":1},{"name":"Rock_Sandstone_Brick","x":3,"y":11,"z":1},{"name":"Rock_Sandstone_Brick","x":3,"y":6,"z":2},{"name":"Rock_Sandstone_Brick","x":3,"y":7,"z":2},{"name":"Rock_Sandstone_Brick","x":3,"y":8,"z":2},{"name":"Rock_Sandstone_Brick","x":3,"y":9,"z":2},{"name":"Rock_Sandstone_Brick","x":3,"y":10,"z":2},{"name":"Rock_Sandstone_Brick","x":3,"y":11,"z":2},{"name":"Rock_Sandstone_Brick","x":3,"y":12,"z":2},{"name":"Rock_Sandstone_Brick","x":3,"y":6,"z":3},{"name":"Rock_Sandstone_Brick","x":3,"y":7,"z":3},{"name":"Rock_Sandstone_Brick","x":3,"y":8,"z":3},{"name":"Rock_Sandstone_Brick_Smooth","x":3,"y":9,"z":3},{"name":"Rock_Sandstone_Brick_Smooth","x":3,"y":10,"z":3},{"name":"Rock_Sandstone_Brick","x":3,"y":11,"z":3},{"name":"Rock_Sandstone_Brick","x":3,"y":12,"z":3},{"name":"Rock_Sandstone_Brick_Smooth","x":3,"y":6,"z":4},{"name":"Rock_Sandstone_Brick_Smooth","x":3,"y":7,"z":4},{"name":"Rock_Sandstone_Brick_Smooth","x":3,"y":8,"z":4},{"name":"Rock_Sandstone_Brick_Smooth","x":3,"y":9,"z":4},{"name":"Rock_Sandstone_Brick_Smooth","x":3,"y":10,"z":4},{"name":"Rock_Sandstone_Brick_Smooth","x":3,"y":11,"z":4},{"name":"Rock_Sandstone_Brick_Smooth","x":3,"y":12,"z":4},{"name":"Rock_Sandstone_Brick","x":4,"y":6,"z":-4},{"name":"Rock_Sandstone_Brick","x":4,"y":7,"z":-4},{"name":"Rock_Sandstone_Brick","x":4,"y":8,"z":-4},{"name":"Rock_Sandstone_Brick","x":4,"y":9,"z":-4},{"name":"Rock_Sandstone_Brick","x":4,"y":10,"z":-4},{"name":"Rock_Sandstone_Brick","x":4,"y":11,"z":-4},{"name":"Rock_Sandstone_Brick","x":4,"y":12,"z":-4},{"name":"Rock_Sandstone_Brick","x":4,"y":13,"z":-4},{"name":"Soil_Gravel_Sand_White","x":4,"y":6,"z":-3},{"name":"Soil_Gravel_Sand_White","x":4,"y":7,"z":-3},{"name":"Soil_Gravel_Sand_White","x":4,"y":8,"z":-3},{"name":"Soil_Gravel_Sand_White","x":4,"y":9,"z":-3},{"name":"Soil_Gravel_Sand_White","x":4,"y":10,"z":-3},{"name":"Soil_Gravel_Sand_White","x":4,"y":11,"z":-3},{"name":"Soil_Gravel_Sand_White","x":4,"y":12,"z":-3},{"name":"Soil_Gravel_Sand_White","x":4,"y":13,"z":-3},{"name":"Rock_Sandstone_Brick","x":4,"y":6,"z":-2},{"name":"Rock_Sandstone_Brick","x":4,"y":7,"z":-2},{"name":"Rock_Sandstone_Brick","x":4,"y":8,"z":-2},{"name":"Rock_Sandstone_Brick","x":4,"y":9,"z":-2},{"name":"Rock_Sandstone_Brick","x":4,"y":10,"z":-2},{"name":"Rock_Sandstone_Brick","x":4,"y":11,"z":-2},{"name":"Rock_Sandstone_Brick","x":4,"y":12,"z":-2},{"name":"Rock_Sandstone_Brick","x":4,"y":13,"z":-2},{"name":"Rock_Sandstone_Brick","x":4,"y":6,"z":4},{"name":"Rock_Sandstone_Brick_Smooth","x":4,"y":7,"z":4},{"name":"Rock_Sandstone_Brick_Smooth","x":4,"y":8,"z":4},{"name":"Rock_Sandstone_Brick","x":4,"y":9,"z":4},{"name":"Rock_Sandstone_Brick","x":4,"y":10,"z":4},{"name":"Rock_Sandstone_Brick_Smooth","x":4,"y":11,"z":4},{"name":"Rock_Sandstone_Brick_Smooth","x":4,"y":12,"z":4},{"name":"Rock_Sandstone_Brick","x":4,"y":13,"z":4},{"name":"Rock_Sandstone_Brick","x":5,"y":6,"z":-4},{"name":"Rock_Sandstone_Brick","x":5,"y":7,"z":-4},{"name":"Rock_Sandstone_Brick","x":5,"y":8,"z":-4},{"name":"Rock_Sandstone_Brick","x":5,"y":9,"z":-4},{"name":"Rock_Sandstone_Brick","x":5,"y":10,"z":-4},{"name":"Rock_Sandstone_Brick","x":5,"y":11,"z":-4},{"name":"Rock_Sandstone_Brick","x":5,"y":12,"z":-4},{"name":"Rock_Sandstone_Brick","x":5,"y":13,"z":-4},{"name":"Soil_Gravel_Sand_White","x":5,"y":6,"z":-3},{"name":"Soil_Gravel_Sand_White","x":5,"y":7,"z":-3},{"name":"Soil_Gravel_Sand_White","x":5,"y":8,"z":-3},{"name":"Soil_Gravel_Sand_White","x":5,"y":9,"z":-3},{"name":"Soil_Gravel_Sand_White","x":5,"y":10,"z":-3},{"name":"Soil_Gravel_Sand_White","x":5,"y":11,"z":-3},{"name":"Soil_Gravel_Sand_White","x":5,"y":12,"z":-3},{"name":"Soil_Gravel_Sand_White","x":5,"y":13,"z":-3},{"name":"Rock_Sandstone_Brick","x":5,"y":6,"z":-2},{"name":"Rock_Sandstone_Brick","x":5,"y":7,"z":-2},{"name":"Rock_Sandstone_Brick","x":5,"y":8,"z":-2},{"name":"Rock_Sandstone_Brick","x":5,"y":9,"z":-2},{"name":"Rock_Sandstone_Brick","x":5,"y":10,"z":-2},{"name":"Rock_Sandstone_Brick","x":5,"y":11,"z":-2},{"name":"Rock_Sandstone_Brick","x":5,"y":12,"z":-2},{"name":"Rock_Sandstone_Brick","x":5,"y":13,"z":-2},{"name":"Rock_Sandstone_Brick","x":5,"y":14,"z":-2},{"name":"Plant_Coral_Block_Red","x":5,"y":13,"z":-1},{"name":"Rock_Sandstone_Brick","x":5,"y":6,"z":4},{"name":"Rock_Sandstone_Brick","x":5,"y":7,"z":4},{"name":"Rock_Sandstone_Brick","x":5,"y":8,"z":4},{"name":"Rock_Sandstone_Brick","x":5,"y":9,"z":4},{"name":"Rock_Sandstone_Brick","x":5,"y":10,"z":4},{"name":"Rock_Sandstone_Brick","x":5,"y":11,"z":4},{"name":"Rock_Sandstone_Brick","x":5,"y":12,"z":4},{"name":"Rock_Sandstone_Brick","x":5,"y":13,"z":4},{"name":"Rock_Sandstone_Brick","x":5,"y":14,"z":4},{"name":"Plant_Coral_Block_Red","x":5,"y":15,"z":4},{"name":"Plant_Coral_Block_Red","x":5,"y":15,"z":5},{"name":"Plant_Coral_Block_Red","x":6,"y":12,"z":-5},{"name":"Rock_Sandstone_Brick","x":6,"y":6,"z":-4},{"name":"Rock_Sandstone_Brick_Smooth","x":6,"y":7,"z":-4},{"name":"Rock_Sandstone_Brick_Smooth","x":6,"y":8,"z":-4},{"name":"Rock_Sandstone_Brick","x":6,"y":9,"z":-4},{"name":"Rock_Sandstone_Brick","x":6,"y":10,"z":-4},{"name":"Rock_Sandstone_Brick_Smooth","x":6,"y":11,"z":-4},{"name":"Rock_Sandstone_Brick_Smooth","x":6,"y":12,"z":-4},{"name":"Rock_Sandstone_Brick","x":6,"y":13,"z":-4},{"name":"Rock_Sandstone_Brick","x":6,"y":14,"z":-4},{"name":"Soil_Gravel_Sand_White","x":6,"y":6,"z":-3},{"name":"Soil_Gravel_Sand_White","x":6,"y":7,"z":-3},{"name":"Soil_Gravel_Sand_White","x":6,"y":8,"z":-3},{"name":"Soil_Gravel_Sand_White","x":6,"y":9,"z":-3},{"name":"Soil_Gravel_Sand_White","x":6,"y":10,"z":-3},{"name":"Soil_Gravel_Sand_White","x":6,"y":11,"z":-3},{"name":"Soil_Gravel_Sand_White","x":6,"y":12,"z":-3},{"name":"Soil_Gravel_Sand_White","x":6,"y":13,"z":-3},{"name":"Soil_Gravel_Sand_White","x":6,"y":14,"z":-3},{"name":"Rock_Sandstone_Brick","x":6,"y":6,"z":-2},{"name":"Rock_Sandstone_Brick_Smooth","x":6,"y":7,"z":-2},{"name":"Rock_Sandstone_Brick_Smooth","x":6,"y":8,"z":-2},{"name":"Rock_Sandstone_Brick","x":6,"y":9,"z":-2},{"name":"Rock_Sandstone_Brick","x":6,"y":10,"z":-2},{"name":"Rock_Sandstone_Brick_Smooth","x":6,"y":11,"z":-2},{"name":"Rock_Sandstone_Brick_Smooth","x":6,"y":12,"z":-2},{"name":"Rock_Sandstone_Brick","x":6,"y":13,"z":-2},{"name":"Rock_Sandstone_Brick","x":6,"y":14,"z":-2},{"name":"Plant_Coral_Block_Yellow","x":6,"y":13,"z":-1},{"name":"Plant_Coral_Block_Red","x":6,"y":13,"z":0},{"name":"Rock_Sandstone_Brick","x":6,"y":6,"z":4},{"name":"Rock_Sandstone_Brick","x":6,"y":7,"z":4},{"name":"Rock_Sandstone_Brick","x":6,"y":8,"z":4},{"name":"Rock_Sandstone_Brick","x":6,"y":9,"z":4},{"name":"Rock_Sandstone_Brick","x":6,"y":10,"z":4},{"name":"Rock_Sandstone_Brick","x":6,"y":11,"z":4},{"name":"Rock_Sandstone_Brick","x":6,"y":12,"z":4},{"name":"Rock_Sandstone_Brick","x":6,"y":13,"z":4},{"name":"Rock_Sandstone_Brick","x":6,"y":14,"z":4},{"name":"Rock_Sandstone_Brick","x":6,"y":15,"z":4},{"name":"Plant_Coral_Block_Yellow","x":6,"y":15,"z":5},{"name":"Plant_Coral_Bush_Orange","x":6,"y":16,"z":5},{"name":"Plant_Coral_Block_Red","x":6,"y":15,"z":6},{"name":"Plant_Coral_Block_Red","x":7,"y":12,"z":-6},{"name":"Plant_Coral_Block_Yellow","x":7,"y":12,"z":-5},{"name":"Plant_Coral_Bush_Orange","x":7,"y":13,"z":-5},{"name":"Rock_Sandstone_Brick_Smooth","x":7,"y":6,"z":-4},{"name":"Rock_Sandstone_Brick_Smooth","x":7,"y":7,"z":-4},{"name":"Rock_Sandstone_Brick_Smooth","x":7,"y":8,"z":-4},{"name":"Rock_Sandstone_Brick_Smooth","x":7,"y":9,"z":-4},{"name":"Rock_Sandstone_Brick_Smooth","x":7,"y":10,"z":-4},{"name":"Rock_Sandstone_Brick_Smooth","x":7,"y":11,"z":-4},{"name":"Rock_Sandstone_Brick_Smooth","x":7,"y":12,"z":-4},{"name":"Rock_Sandstone_Brick_Smooth","x":7,"y":13,"z":-4},{"name":"Rock_Sandstone_Brick_Smooth","x":7,"y":14,"z":-4},{"name":"Soil_Gravel_Sand_White","x":7,"y":6,"z":-3},{"name":"Soil_Gravel_Sand_White","x":7,"y":7,"z":-3},{"name":"Soil_Gravel_Sand_White","x":7,"y":8,"z":-3},{"name":"Soil_Gravel_Sand_White","x":7,"y":9,"z":-3},{"name":"Soil_Gravel_Sand_White","x":7,"y":10,"z":-3},{"name":"Soil_Gravel_Sand_White","x":7,"y":11,"z":-3},{"name":"Soil_Gravel_Sand_White","x":7,"y":12,"z":-3},{"name":"Soil_Gravel_Sand_White","x":7,"y":13,"z":-3},{"name":"Soil_Gravel_Sand_White","x":7,"y":14,"z":-3},{"name":"Rock_Sandstone_Brick_Smooth","x":7,"y":6,"z":-2},{"name":"Rock_Sandstone_Brick_Smooth","x":7,"y":7,"z":-2},{"name":"Rock_Sandstone_Brick_Smooth","x":7,"y":8,"z":-2},{"name":"Rock_Sandstone_Brick_Smooth","x":7,"y":9,"z":-2},{"name":"Rock_Sandstone_Brick_Smooth","x":7,"y":10,"z":-2},{"name":"Rock_Sandstone_Brick_Smooth","x":7,"y":11,"z":-2},{"name":"Rock_Sandstone_Brick_Smooth","x":7,"y":12,"z":-2},{"name":"Rock_Sandstone_Brick_Smooth","x":7,"y":13,"z":-2},{"name":"Rock_Sandstone_Brick_Smooth","x":7,"y":14,"z":-2},{"name":"Plant_Coral_Block_Yellow","x":7,"y":13,"z":-1},{"name":"Plant_Coral_Model_Orange","x":7,"y":14,"z":-1},{"name":"Plant_Coral_Block_Red","x":7,"y":13,"z":0},{"name":"Rock_Sandstone_Brick","x":7,"y":6,"z":4},{"name":"Rock_Sandstone_Brick","x":7,"y":7,"z":4},{"name":"Rock_Sandstone_Brick","x":7,"y":8,"z":4},{"name":"Rock_Sandstone_Brick","x":7,"y":9,"z":4},{"name":"Rock_Sandstone_Brick","x":7,"y":10,"z":4},{"name":"Rock_Sandstone_Brick","x":7,"y":11,"z":4},{"name":"Rock_Sandstone_Brick","x":7,"y":12,"z":4},{"name":"Rock_Sandstone_Brick","x":7,"y":13,"z":4},{"name":"Rock_Sandstone_Brick","x":7,"y":14,"z":4},{"name":"Rock_Sandstone_Brick","x":7,"y":15,"z":4},{"name":"Plant_Coral_Block_Yellow","x":7,"y":15,"z":5},{"name":"Plant_Coral_Model_Orange","x":7,"y":16,"z":5},{"name":"Plant_Coral_Block_Red","x":7,"y":15,"z":6},{"name":"Plant_Coral_Block_Red","x":8,"y":12,"z":-6},{"name":"Plant_Coral_Block_Yellow","x":8,"y":12,"z":-5},{"name":"Rock_Sandstone_Brick","x":8,"y":6,"z":-4},{"name":"Rock_Sandstone_Brick","x":8,"y":7,"z":-4},{"name":"Rock_Sandstone_Brick","x":8,"y":8,"z":-4},{"name":"Rock_Sandstone_Brick_Smooth","x":8,"y":9,"z":-4},{"name":"Rock_Sandstone_Brick_Smooth","x":8,"y":10,"z":-4},{"name":"Rock_Sandstone_Brick","x":8,"y":11,"z":-4},{"name":"Rock_Sandstone_Brick","x":8,"y":12,"z":-4},{"name":"Rock_Sandstone_Brick_Smooth","x":8,"y":13,"z":-4},{"name":"Rock_Sandstone_Brick_Smooth","x":8,"y":14,"z":-4},{"name":"Soil_Gravel_Sand_White","x":8,"y":6,"z":-3},{"name":"Soil_Gravel_Sand_White","x":8,"y":7,"z":-3},{"name":"Soil_Gravel_Sand_White","x":8,"y":8,"z":-3},{"name":"Soil_Gravel_Sand_White","x":8,"y":9,"z":-3},{"name":"Soil_Gravel_Sand_White","x":8,"y":10,"z":-3},{"name":"Soil_Gravel_Sand_White","x":8,"y":11,"z":-3},{"name":"Soil_Gravel_Sand_White","x":8,"y":12,"z":-3},{"name":"Soil_Gravel_Sand_White","x":8,"y":13,"z":-3},{"name":"Soil_Gravel_Sand_White","x":8,"y":14,"z":-3},{"name":"Rock_Sandstone_Brick","x":8,"y":6,"z":-2},{"name":"Rock_Sandstone_Brick","x":8,"y":7,"z":-2},{"name":"Rock_Sandstone_Brick","x":8,"y":8,"z":-2},{"name":"Rock_Sandstone_Brick_Smooth","x":8,"y":9,"z":-2},{"name":"Rock_Sandstone_Brick_Smooth","x":8,"y":10,"z":-2},{"name":"Rock_Sandstone_Brick","x":8,"y":11,"z":-2},{"name":"Rock_Sandstone_Brick","x":8,"y":12,"z":-2},{"name":"Rock_Sandstone_Brick_Smooth","x":8,"y":13,"z":-2},{"name":"Rock_Sandstone_Brick_Smooth","x":8,"y":14,"z":-2},{"name":"Rock_Sandstone_Brick","x":8,"y":15,"z":-2},{"name":"Plant_Coral_Block_Yellow","x":8,"y":13,"z":-1},{"name":"Plant_Coral_Bush_Orange","x":8,"y":14,"z":-1},{"name":"Plant_Coral_Block_Red","x":8,"y":13,"z":0},{"name":"Rock_Sandstone_Brick","x":8,"y":6,"z":4},{"name":"Rock_Sandstone_Brick","x":8,"y":7,"z":4},{"name":"Rock_Sandstone_Brick","x":8,"y":8,"z":4},{"name":"Rock_Sandstone_Brick","x":8,"y":9,"z":4},{"name":"Rock_Sandstone_Brick","x":8,"y":10,"z":4},{"name":"Rock_Sandstone_Brick","x":8,"y":11,"z":4},{"name":"Rock_Sandstone_Brick","x":8,"y":12,"z":4},{"name":"Rock_Sandstone_Brick","x":8,"y":13,"z":4},{"name":"Rock_Sandstone_Brick","x":8,"y":14,"z":4},{"name":"Rock_Sandstone_Brick","x":8,"y":15,"z":4},{"name":"Plant_Coral_Block_Yellow","x":8,"y":15,"z":5},{"name":"Plant_Coral_Block_Red","x":8,"y":15,"z":6},{"name":"Plant_Coral_Block_Red","x":9,"y":12,"z":-6},{"name":"Plant_Coral_Model_Orange","x":9,"y":13,"z":-6},{"name":"Plant_Coral_Block_Yellow","x":9,"y":12,"z":-5},{"name":"Rock_Sandstone_Brick","x":9,"y":6,"z":-4},{"name":"Rock_Sandstone_Brick","x":9,"y":7,"z":-4},{"name":"Rock_Sandstone_Brick","x":9,"y":8,"z":-4},{"name":"Rock_Sandstone_Brick","x":9,"y":9,"z":-4},{"name":"Rock_Sandstone_Brick","x":9,"y":10,"z":-4},{"name":"Rock_Sandstone_Brick","x":9,"y":11,"z":-4},{"name":"Rock_Sandstone_Brick","x":9,"y":12,"z":-4},{"name":"Rock_Sandstone_Brick","x":9,"y":13,"z":-4},{"name":"Rock_Sandstone_Brick","x":9,"y":14,"z":-4},{"name":"Rock_Sandstone_Brick","x":9,"y":15,"z":-4},{"name":"Soil_Gravel_Sand_White","x":9,"y":6,"z":-3},{"name":"Soil_Gravel_Sand_White","x":9,"y":7,"z":-3},{"name":"Soil_Gravel_Sand_White","x":9,"y":8,"z":-3},{"name":"Soil_Gravel_Sand_White","x":9,"y":9,"z":-3},{"name":"Soil_Gravel_Sand_White","x":9,"y":10,"z":-3},{"name":"Soil_Gravel_Sand_White","x":9,"y":11,"z":-3},{"name":"Soil_Gravel_Sand_White","x":9,"y":12,"z":-3},{"name":"Soil_Gravel_Sand_White","x":9,"y":13,"z":-3},{"name":"Soil_Gravel_Sand_White","x":9,"y":14,"z":-3},{"name":"Soil_Gravel_Sand_White","x":9,"y":15,"z":-3},{"name":"Rock_Sandstone_Brick","x":9,"y":6,"z":-2},{"name":"Rock_Sandstone_Brick","x":9,"y":7,"z":-2},{"name":"Rock_Sandstone_Brick","x":9,"y":8,"z":-2},{"name":"Rock_Sandstone_Brick","x":9,"y":9,"z":-2},{"name":"Rock_Sandstone_Brick","x":9,"y":10,"z":-2},{"name":"Rock_Sandstone_Brick","x":9,"y":11,"z":-2},{"name":"Rock_Sandstone_Brick","x":9,"y":12,"z":-2},{"name":"Rock_Sandstone_Brick","x":9,"y":13,"z":-2},{"name":"Rock_Sandstone_Brick","x":9,"y":14,"z":-2},{"name":"Rock_Sandstone_Brick","x":9,"y":15,"z":-2},{"name":"Plant_Coral_Block_Red","x":9,"y":13,"z":-1},{"name":"Rock_Sandstone_Brick","x":9,"y":6,"z":4},{"name":"Rock_Sandstone_Brick","x":9,"y":7,"z":4},{"name":"Rock_Sandstone_Brick","x":9,"y":8,"z":4},{"name":"Rock_Sandstone_Brick","x":9,"y":9,"z":4},{"name":"Rock_Sandstone_Brick","x":9,"y":10,"z":4},{"name":"Rock_Sandstone_Brick","x":9,"y":11,"z":4},{"name":"Rock_Sandstone_Brick","x":9,"y":12,"z":4},{"name":"Rock_Sandstone_Brick","x":9,"y":13,"z":4},{"name":"Rock_Sandstone_Brick","x":9,"y":14,"z":4},{"name":"Plant_Coral_Block_Red","x":9,"y":15,"z":5},{"name":"Plant_Coral_Block_Red","x":10,"y":12,"z":-5},{"name":"Rock_Sandstone_Brick","x":10,"y":6,"z":-4},{"name":"Rock_Sandstone_Brick","x":10,"y":7,"z":-4},{"name":"Rock_Sandstone_Brick","x":10,"y":8,"z":-4},{"name":"Rock_Sandstone_Brick","x":10,"y":9,"z":-4},{"name":"Rock_Sandstone_Brick","x":10,"y":10,"z":-4},{"name":"Rock_Sandstone_Brick","x":10,"y":11,"z":-4},{"name":"Rock_Sandstone_Brick","x":10,"y":12,"z":-4},{"name":"Rock_Sandstone_Brick","x":10,"y":13,"z":-4},{"name":"Rock_Sandstone_Brick","x":10,"y":14,"z":-4},{"name":"Rock_Sandstone_Brick","x":10,"y":15,"z":-4},{"name":"Soil_Gravel_Sand_White","x":10,"y":6,"z":-3},{"name":"Soil_Gravel_Sand_White","x":10,"y":7,"z":-3},{"name":"Soil_Gravel_Sand_White","x":10,"y":8,"z":-3},{"name":"Soil_Gravel_Sand_White","x":10,"y":9,"z":-3},{"name":"Soil_Gravel_Sand_White","x":10,"y":10,"z":-3},{"name":"Soil_Gravel_Sand_White","x":10,"y":11,"z":-3},{"name":"Soil_Gravel_Sand_White","x":10,"y":12,"z":-3},{"name":"Soil_Gravel_Sand_White","x":10,"y":13,"z":-3},{"name":"Soil_Gravel_Sand_White","x":10,"y":14,"z":-3},{"name":"Soil_Gravel_Sand_White","x":10,"y":15,"z":-3},{"name":"Rock_Sandstone_Brick","x":10,"y":6,"z":-2},{"name":"Rock_Sandstone_Brick","x":10,"y":7,"z":-2},{"name":"Rock_Sandstone_Brick","x":10,"y":8,"z":-2},{"name":"Rock_Sandstone_Brick","x":10,"y":9,"z":-2},{"name":"Rock_Sandstone_Brick","x":10,"y":10,"z":-2},{"name":"Rock_Sandstone_Brick","x":10,"y":11,"z":-2},{"name":"Rock_Sandstone_Brick","x":10,"y":12,"z":-2},{"name":"Rock_Sandstone_Brick","x":10,"y":13,"z":-2},{"name":"Rock_Sandstone_Brick","x":10,"y":14,"z":-2},{"name":"Rock_Sandstone_Brick","x":10,"y":10,"z":4},{"name":"Soil_Gravel_Sand_White","x":11,"y":10,"z":-3}],"fluids":[{"level":1,"name":"Water_Source","x":3,"y":6,"z":-2},{"level":1,"name":"Water_Source","x":3,"y":7,"z":-2},{"level":1,"name":"Water_Source","x":3,"y":8,"z":-2},{"level":1,"name":"Water_Source","x":3,"y":9,"z":-2},{"level":1,"name":"Water_Source","x":3,"y":10,"z":-2},{"level":1,"name":"Water_Source","x":3,"y":11,"z":-2},{"level":1,"name":"Water_Source","x":3,"y":6,"z":-1},{"level":1,"name":"Water_Source","x":3,"y":7,"z":-1},{"level":1,"name":"Water_Source","x":3,"y":8,"z":-1},{"level":1,"name":"Water_Source","x":3,"y":9,"z":-1},{"level":1,"name":"Water_Source","x":3,"y":10,"z":-1},{"level":1,"name":"Water_Source","x":3,"y":11,"z":-1},{"level":1,"name":"Water_Source","x":3,"y":6,"z":0},{"level":1,"name":"Water_Source","x":3,"y":7,"z":0},{"level":1,"name":"Water_Source","x":3,"y":8,"z":0},{"level":1,"name":"Water_Source","x":3,"y":9,"z":0},{"level":1,"name":"Water_Source","x":3,"y":10,"z":0},{"level":1,"name":"Water_Source","x":3,"y":11,"z":0},{"level":1,"name":"Water_Source","x":3,"y":6,"z":1},{"level":1,"name":"Water_Source","x":3,"y":7,"z":1},{"level":1,"name":"Water_Source","x":3,"y":8,"z":1},{"level":1,"name":"Water_Source","x":3,"y":9,"z":1},{"level":1,"name":"Water_Source","x":3,"y":10,"z":1},{"level":1,"name":"Water_Source","x":3,"y":11,"z":1},{"level":1,"name":"Water_Source","x":3,"y":6,"z":2},{"level":1,"name":"Water_Source","x":3,"y":7,"z":2},{"level":1,"name":"Water_Source","x":3,"y":8,"z":2},{"level":1,"name":"Water_Source","x":3,"y":9,"z":2},{"level":1,"name":"Water_Source","x":3,"y":10,"z":2},{"level":1,"name":"Water_Source","x":3,"y":11,"z":2},{"level":1,"name":"Water_Source","x":3,"y":12,"z":2},{"level":1,"name":"Water_Source","x":3,"y":6,"z":3},{"level":1,"name":"Water_Source","x":3,"y":7,"z":3},{"level":1,"name":"Water_Source","x":3,"y":8,"z":3},{"level":1,"name":"Water_Source","x":3,"y":9,"z":3},{"level":1,"name":"Water_Source","x":3,"y":10,"z":3},{"level":1,"name":"Water_Source","x":3,"y":11,"z":3},{"level":1,"name":"Water_Source","x":3,"y":12,"z":3},{"level":1,"name":"Water_Source","x":3,"y":6,"z":4},{"level":1,"name":"Water_Source","x":3,"y":7,"z":4},{"level":1,"name":"Water_Source","x":3,"y":8,"z":4},{"level":1,"name":"Water_Source","x":3,"y":9,"z":4},{"level":1,"name":"Water_Source","x":3,"y":10,"z":4},{"level":1,"name":"Water_Source","x":3,"y":11,"z":4},{"level":1,"name":"Water_Source","x":3,"y":12,"z":4},{"level":1,"name":"Water_Source","x":4,"y":6,"z":-4},{"level":1,"name":"Water_Source","x":4,"y":7,"z":-4},{"level":1,"name":"Water_Source","x":4,"y":8,"z":-4},{"level":1,"name":"Water_Source","x":4,"y":9,"z":-4},{"level":1,"name":"Water_Source","x":4,"y":10,"z":-4},{"level":1,"name":"Water_Source","x":4,"y":11,"z":-4},{"level":1,"name":"Water_Source","x":4,"y":12,"z":-4},{"level":1,"name":"Water_Source","x":4,"y":13,"z":-4},{"level":1,"name":"Water_Source","x":4,"y":6,"z":-3},{"level":1,"name":"Water_Source","x":4,"y":7,"z":-3},{"level":1,"name":"Water_Source","x":4,"y":8,"z":-3},{"level":1,"name":"Water_Source","x":4,"y":9,"z":-3},{"level":1,"name":"Water_Source","x":4,"y":10,"z":-3},{"level":1,"name":"Water_Source","x":4,"y":11,"z":-3},{"level":1,"name":"Water_Source","x":4,"y":12,"z":-3},{"level":1,"name":"Water_Source","x":4,"y":13,"z":-3},{"level":1,"name":"Water_Source","x":4,"y":6,"z":-2},{"level":1,"name":"Water_Source","x":4,"y":7,"z":-2},{"level":1,"name":"Water_Source","x":4,"y":8,"z":-2},{"level":1,"name":"Water_Source","x":4,"y":9,"z":-2},{"level":1,"name":"Water_Source","x":4,"y":10,"z":-2},{"level":1,"name":"Water_Source","x":4,"y":11,"z":-2},{"level":1,"name":"Water_Source","x":4,"y":12,"z":-2},{"level":1,"name":"Water_Source","x":4,"y":13,"z":-2},{"level":1,"name":"Water_Source","x":4,"y":6,"z":4},{"level":1,"name":"Water_Source","x":4,"y":7,"z":4},{"level":1,"name":"Water_Source","x":4,"y":8,"z":4},{"level":1,"name":"Water_Source","x":4,"y":9,"z":4},{"level":1,"name":"Water_Source","x":4,"y":10,"z":4},{"level":1,"name":"Water_Source","x":4,"y":11,"z":4},{"level":1,"name":"Water_Source","x":4,"y":12,"z":4},{"level":1,"name":"Water_Source","x":4,"y":13,"z":4},{"level":1,"name":"Water_Source","x":5,"y":6,"z":-4},{"level":1,"name":"Water_Source","x":5,"y":7,"z":-4},{"level":1,"name":"Water_Source","x":5,"y":8,"z":-4},{"level":1,"name":"Water_Source","x":5,"y":9,"z":-4},{"level":1,"name":"Water_Source","x":5,"y":10,"z":-4},{"level":1,"name":"Water_Source","x":5,"y":11,"z":-4},{"level":1,"name":"Water_Source","x":5,"y":12,"z":-4},{"level":1,"name":"Water_Source","x":5,"y":13,"z":-4},{"level":1,"name":"Water_Source","x":5,"y":6,"z":-3},{"level":1,"name":"Water_Source","x":5,"y":7,"z":-3},{"level":1,"name":"Water_Source","x":5,"y":8,"z":-3},{"level":1,"name":"Water_Source","x":5,"y":9,"z":-3},{"level":1,"name":"Water_Source","x":5,"y":10,"z":-3},{"level":1,"name":"Water_Source","x":5,"y":11,"z":-3},{"level":1,"name":"Water_Source","x":5,"y":12,"z":-3},{"level":1,"name":"Water_Source","x":5,"y":13,"z":-3},{"level":1,"name":"Water_Source","x":5,"y":6,"z":-2},{"level":1,"name":"Water_Source","x":5,"y":7,"z":-2},{"level":1,"name":"Water_Source","x":5,"y":8,"z":-2},{"level":1,"name":"Water_Source","x":5,"y":9,"z":-2},{"level":1,"name":"Water_Source","x":5,"y":10,"z":-2},{"level":1,"name":"Water_Source","x":5,"y":11,"z":-2},{"level":1,"name":"Water_Source","x":5,"y":12,"z":-2},{"level":1,"name":"Water_Source","x":5,"y":13,"z":-2},{"level":1,"name":"Water_Source","x":5,"y":14,"z":-2},{"level":1,"name":"Water_Source","x":5,"y":13,"z":-1},{"level":1,"name":"Water_Source","x":5,"y":6,"z":4},{"level":1,"name":"Water_Source","x":5,"y":7,"z":4},{"level":1,"name":"Water_Source","x":5,"y":8,"z":4},{"level":1,"name":"Water_Source","x":5,"y":9,"z":4},{"level":1,"name":"Water_Source","x":5,"y":10,"z":4},{"level":1,"name":"Water_Source","x":5,"y":11,"z":4},{"level":1,"name":"Water_Source","x":5,"y":12,"z":4},{"level":1,"name":"Water_Source","x":5,"y":13,"z":4},{"level":1,"name":"Water_Source","x":5,"y":14,"z":4},{"level":1,"name":"Water_Source","x":5,"y":15,"z":4},{"level":1,"name":"Water_Source","x":5,"y":15,"z":5},{"level":1,"name":"Water_Source","x":6,"y":12,"z":-5},{"level":1,"name":"Water_Source","x":6,"y":6,"z":-4},{"level":1,"name":"Water_Source","x":6,"y":7,"z":-4},{"level":1,"name":"Water_Source","x":6,"y":8,"z":-4},{"level":1,"name":"Water_Source","x":6,"y":9,"z":-4},{"level":1,"name":"Water_Source","x":6,"y":10,"z":-4},{"level":1,"name":"Water_Source","x":6,"y":11,"z":-4},{"level":1,"name":"Water_Source","x":6,"y":12,"z":-4},{"level":1,"name":"Water_Source","x":6,"y":13,"z":-4},{"level":1,"name":"Water_Source","x":6,"y":14,"z":-4},{"level":1,"name":"Water_Source","x":6,"y":6,"z":-3},{"level":1,"name":"Water_Source","x":6,"y":7,"z":-3},{"level":1,"name":"Water_Source","x":6,"y":8,"z":-3},{"level":1,"name":"Water_Source","x":6,"y":9,"z":-3},{"level":1,"name":"Water_Source","x":6,"y":10,"z":-3},{"level":1,"name":"Water_Source","x":6,"y":11,"z":-3},{"level":1,"name":"Water_Source","x":6,"y":12,"z":-3},{"level":1,"name":"Water_Source","x":6,"y":13,"z":-3},{"level":1,"name":"Water_Source","x":6,"y":14,"z":-3},{"level":1,"name":"Water_Source","x":6,"y":6,"z":-2},{"level":1,"name":"Water_Source","x":6,"y":7,"z":-2},{"level":1,"name":"Water_Source","x":6,"y":8,"z":-2},{"level":1,"name":"Water_Source","x":6,"y":9,"z":-2},{"level":1,"name":"Water_Source","x":6,"y":10,"z":-2},{"level":1,"name":"Water_Source","x":6,"y":11,"z":-2},{"level":1,"name":"Water_Source","x":6,"y":12,"z":-2},{"level":1,"name":"Water_Source","x":6,"y":13,"z":-2},{"level":1,"name":"Water_Source","x":6,"y":14,"z":-2},{"level":1,"name":"Water_Source","x":6,"y":13,"z":-1},{"level":1,"name":"Water_Source","x":6,"y":13,"z":0},{"level":1,"name":"Water_Source","x":6,"y":6,"z":4},{"level":1,"name":"Water_Source","x":6,"y":7,"z":4},{"level":1,"name":"Water_Source","x":6,"y":8,"z":4},{"level":1,"name":"Water_Source","x":6,"y":9,"z":4},{"level":1,"name":"Water_Source","x":6,"y":10,"z":4},{"level":1,"name":"Water_Source","x":6,"y":11,"z":4},{"level":1,"name":"Water_Source","x":6,"y":12,"z":4},{"level":1,"name":"Water_Source","x":6,"y":13,"z":4},{"level":1,"name":"Water_Source","x":6,"y":14,"z":4},{"level":1,"name":"Water_Source","x":6,"y":15,"z":4},{"level":1,"name":"Water_Source","x":6,"y":15,"z":5},{"level":1,"name":"Water_Source","x":6,"y":16,"z":5},{"level":1,"name":"Water_Source","x":6,"y":15,"z":6},{"level":1,"name":"Water_Source","x":7,"y":12,"z":-6},{"level":1,"name":"Water_Source","x":7,"y":12,"z":-5},{"level":1,"name":"Water_Source","x":7,"y":13,"z":-5},{"level":1,"name":"Water_Source","x":7,"y":6,"z":-4},{"level":1,"name":"Water_Source","x":7,"y":7,"z":-4},{"level":1,"name":"Water_Source","x":7,"y":8,"z":-4},{"level":1,"name":"Water_Source","x":7,"y":9,"z":-4},{"level":1,"name":"Water_Source","x":7,"y":10,"z":-4},{"level":1,"name":"Water_Source","x":7,"y":11,"z":-4},{"level":1,"name":"Water_Source","x":7,"y":12,"z":-4},{"level":1,"name":"Water_Source","x":7,"y":13,"z":-4},{"level":1,"name":"Water_Source","x":7,"y":14,"z":-4},{"level":1,"name":"Water_Source","x":7,"y":6,"z":-3},{"level":1,"name":"Water_Source","x":7,"y":7,"z":-3},{"level":1,"name":"Water_Source","x":7,"y":8,"z":-3},{"level":1,"name":"Water_Source","x":7,"y":9,"z":-3},{"level":1,"name":"Water_Source","x":7,"y":10,"z":-3},{"level":1,"name":"Water_Source","x":7,"y":11,"z":-3},{"level":1,"name":"Water_Source","x":7,"y":12,"z":-3},{"level":1,"name":"Water_Source","x":7,"y":13,"z":-3},{"level":1,"name":"Water_Source","x":7,"y":14,"z":-3},{"level":1,"name":"Water_Source","x":7,"y":6,"z":-2},{"level":1,"name":"Water_Source","x":7,"y":7,"z":-2},{"level":1,"name":"Water_Source","x":7,"y":8,"z":-2},{"level":1,"name":"Water_Source","x":7,"y":9,"z":-2},{"level":1,"name":"Water_Source","x":7,"y":10,"z":-2},{"level":1,"name":"Water_Source","x":7,"y":11,"z":-2},{"level":1,"name":"Water_Source","x":7,"y":12,"z":-2},{"level":1,"name":"Water_Source","x":7,"y":13,"z":-2},{"level":1,"name":"Water_Source","x":7,"y":14,"z":-2},{"level":1,"name":"Water_Source","x":7,"y":13,"z":-1},{"level":1,"name":"Water_Source","x":7,"y":14,"z":-1},{"level":1,"name":"Water_Source","x":7,"y":13,"z":0},{"level":1,"name":"Water_Source","x":7,"y":6,"z":4},{"level":1,"name":"Water_Source","x":7,"y":7,"z":4},{"level":1,"name":"Water_Source","x":7,"y":8,"z":4},{"level":1,"name":"Water_Source","x":7,"y":9,"z":4},{"level":1,"name":"Water_Source","x":7,"y":10,"z":4},{"level":1,"name":"Water_Source","x":7,"y":11,"z":4},{"level":1,"name":"Water_Source","x":7,"y":12,"z":4},{"level":1,"name":"Water_Source","x":7,"y":13,"z":4},{"level":1,"name":"Water_Source","x":7,"y":14,"z":4},{"level":1,"name":"Water_Source","x":7,"y":15,"z":4},{"level":1,"name":"Water_Source","x":7,"y":15,"z":5},{"level":1,"name":"Water_Source","x":7,"y":16,"z":5},{"level":1,"name":"Water_Source","x":7,"y":15,"z":6},{"level":1,"name":"Water_Source","x":8,"y":12,"z":-6},{"level":1,"name":"Water_Source","x":8,"y":12,"z":-5},{"level":1,"name":"Water_Source","x":8,"y":6,"z":-4},{"level":1,"name":"Water_Source","x":8,"y":7,"z":-4},{"level":1,"name":"Water_Source","x":8,"y":8,"z":-4},{"level":1,"name":"Water_Source","x":8,"y":9,"z":-4},{"level":1,"name":"Water_Source","x":8,"y":10,"z":-4},{"level":1,"name":"Water_Source","x":8,"y":11,"z":-4},{"level":1,"name":"Water_Source","x":8,"y":12,"z":-4},{"level":1,"name":"Water_Source","x":8,"y":13,"z":-4},{"level":1,"name":"Water_Source","x":8,"y":14,"z":-4},{"level":1,"name":"Water_Source","x":8,"y":6,"z":-3},{"level":1,"name":"Water_Source","x":8,"y":7,"z":-3},{"level":1,"name":"Water_Source","x":8,"y":8,"z":-3},{"level":1,"name":"Water_Source","x":8,"y":9,"z":-3},{"level":1,"name":"Water_Source","x":8,"y":10,"z":-3},{"level":1,"name":"Water_Source","x":8,"y":11,"z":-3},{"level":1,"name":"Water_Source","x":8,"y":12,"z":-3},{"level":1,"name":"Water_Source","x":8,"y":13,"z":-3},{"level":1,"name":"Water_Source","x":8,"y":14,"z":-3},{"level":1,"name":"Water_Source","x":8,"y":6,"z":-2},{"level":1,"name":"Water_Source","x":8,"y":7,"z":-2},{"level":1,"name":"Water_Source","x":8,"y":8,"z":-2},{"level":1,"name":"Water_Source","x":8,"y":9,"z":-2},{"level":1,"name":"Water_Source","x":8,"y":10,"z":-2},{"level":1,"name":"Water_Source","x":8,"y":11,"z":-2},{"level":1,"name":"Water_Source","x":8,"y":12,"z":-2},{"level":1,"name":"Water_Source","x":8,"y":13,"z":-2},{"level":1,"name":"Water_Source","x":8,"y":14,"z":-2},{"level":1,"name":"Water_Source","x":8,"y":15,"z":-2},{"level":1,"name":"Water_Source","x":8,"y":13,"z":-1},{"level":1,"name":"Water_Source","x":8,"y":14,"z":-1},{"level":1,"name":"Water_Source","x":8,"y":13,"z":0},{"level":1,"name":"Water_Source","x":8,"y":6,"z":4},{"level":1,"name":"Water_Source","x":8,"y":7,"z":4},{"level":1,"name":"Water_Source","x":8,"y":8,"z":4},{"level":1,"name":"Water_Source","x":8,"y":9,"z":4},{"level":1,"name":"Water_Source","x":8,"y":10,"z":4},{"level":1,"name":"Water_Source","x":8,"y":11,"z":4},{"level":1,"name":"Water_Source","x":8,"y":12,"z":4},{"level":1,"name":"Water_Source","x":8,"y":13,"z":4},{"level":1,"name":"Water_Source","x":8,"y":14,"z":4},{"level":1,"name":"Water_Source","x":8,"y":15,"z":4},{"level":1,"name":"Water_Source","x":8,"y":15,"z":5},{"level":1,"name":"Water_Source","x":8,"y":15,"z":6},{"level":1,"name":"Water_Source","x":9,"y":12,"z":-6},{"level":1,"name":"Water_Source","x":9,"y":13,"z":-6},{"level":1,"name":"Water_Source","x":9,"y":12,"z":-5},{"level":1,"name":"Water_Source","x":9,"y":6,"z":-4},{"level":1,"name":"Water_Source","x":9,"y":7,"z":-4},{"level":1,"name":"Water_Source","x":9,"y":8,"z":-4},{"level":1,"name":"Water_Source","x":9,"y":9,"z":-4},{"level":1,"name":"Water_Source","x":9,"y":10,"z":-4},{"level":1,"name":"Water_Source","x":9,"y":11,"z":-4},{"level":1,"name":"Water_Source","x":9,"y":12,"z":-4},{"level":1,"name":"Water_Source","x":9,"y":13,"z":-4},{"level":1,"name":"Water_Source","x":9,"y":14,"z":-4},{"level":1,"name":"Water_Source","x":9,"y":15,"z":-4},{"level":1,"name":"Water_Source","x":9,"y":6,"z":-3},{"level":1,"name":"Water_Source","x":9,"y":7,"z":-3},{"level":1,"name":"Water_Source","x":9,"y":8,"z":-3},{"level":1,"name":"Water_Source","x":9,"y":9,"z":-3},{"level":1,"name":"Water_Source","x":9,"y":10,"z":-3},{"level":1,"name":"Water_Source","x":9,"y":11,"z":-3},{"level":1,"name":"Water_Source","x":9,"y":12,"z":-3},{"level":1,"name":"Water_Source","x":9,"y":13,"z":-3},{"level":1,"name":"Water_Source","x":9,"y":14,"z":-3},{"level":1,"name":"Water_Source","x":9,"y":15,"z":-3},{"level":1,"name":"Water_Source","x":9,"y":6,"z":-2},{"level":1,"name":"Water_Source","x":9,"y":7,"z":-2},{"level":1,"name":"Water_Source","x":9,"y":8,"z":-2},{"level":1,"name":"Water_Source","x":9,"y":9,"z":-2},{"level":1,"name":"Water_Source","x":9,"y":10,"z":-2},{"level":1,"name":"Water_Source","x":9,"y":11,"z":-2},{"level":1,"name":"Water_Source","x":9,"y":12,"z":-2},{"level":1,"name":"Water_Source","x":9,"y":13,"z":-2},{"level":1,"name":"Water_Source","x":9,"y":14,"z":-2},{"level":1,"name":"Water_Source","x":9,"y":15,"z":-2},{"level":1,"name":"Water_Source","x":9,"y":13,"z":-1},{"level":1,"name":"Water_Source","x":9,"y":6,"z":4},{"level":1,"name":"Water_Source","x":9,"y":7,"z":4},{"level":1,"name":"Water_Source","x":9,"y":8,"z":4},{"level":1,"name":"Water_Source","x":9,"y":9,"z":4},{"level":1,"name":"Water_Source","x":9,"y":10,"z":4},{"level":1,"name":"Water_Source","x":9,"y":11,"z":4},{"level":1,"name":"Water_Source","x":9,"y":12,"z":4},{"level":1,"name":"Water_Source","x":9,"y":13,"z":4},{"level":1,"name":"Water_Source","x":9,"y":14,"z":4},{"level":1,"name":"Water_Source","x":9,"y":15,"z":5},{"level":1,"name":"Water_Source","x":10,"y":12,"z":-5},{"level":1,"name":"Water_Source","x":10,"y":6,"z":-4},{"level":1,"name":"Water_Source","x":10,"y":7,"z":-4},{"level":1,"name":"Water_Source","x":10,"y":8,"z":-4},{"level":1,"name":"Water_Source","x":10,"y":9,"z":-4},{"level":1,"name":"Water_Source","x":10,"y":10,"z":-4},{"level":1,"name":"Water_Source","x":10,"y":11,"z":-4},{"level":1,"name":"Water_Source","x":10,"y":12,"z":-4},{"level":1,"name":"Water_Source","x":10,"y":13,"z":-4},{"level":1,"name":"Water_Source","x":10,"y":14,"z":-4},{"level":1,"name":"Water_Source","x":10,"y":15,"z":-4},{"level":1,"name":"Water_Source","x":10,"y":6,"z":-3},{"level":1,"name":"Water_Source","x":10,"y":7,"z":-3},{"level":1,"name":"Water_Source","x":10,"y":8,"z":-3},{"level":1,"name":"Water_Source","x":10,"y":9,"z":-3},{"level":1,"name":"Water_Source","x":10,"y":10,"z":-3},{"level":1,"name":"Water_Source","x":10,"y":11,"z":-3},{"level":1,"name":"Water_Source","x":10,"y":12,"z":-3},{"level":1,"name":"Water_Source","x":10,"y":13,"z":-3},{"level":1,"name":"Water_Source","x":10,"y":14,"z":-3},{"level":1,"name":"Water_Source","x":10,"y":15,"z":-3},{"level":1,"name":"Water_Source","x":10,"y":6,"z":-2},{"level":1,"name":"Water_Source","x":10,"y":7,"z":-2},{"level":1,"name":"Water_Source","x":10,"y":8,"z":-2},{"level":1,"name":"Water_Source","x":10,"y":9,"z":-2},{"level":1,"name":"Water_Source","x":10,"y":10,"z":-2},{"level":1,"name":"Water_Source","x":10,"y":11,"z":-2},{"level":1,"name":"Water_Source","x":10,"y":12,"z":-2},{"level":1,"name":"Water_Source","x":10,"y":13,"z":-2},{"level":1,"name":"Water_Source","x":10,"y":14,"z":-2},{"level":1,"name":"Water_Source","x":10,"y":10,"z":4},{"level":1,"name":"Water_Source","x":11,"y":10,"z":-3}],"version":8}