{"anchorX":-3,"anchorY":10,"anchorZ":1,"blockIdVersion":11,"blocks":[{"name":"Rock_Sandstone_Brick","x":-7,"y":9,"z":-1},{"name":"Rock_Sandstone_Brick","x":-7,"y":10,"z":-1},{"name":"Rock_Sandstone_Brick","x":-7,"y":11,"z":-1},{"name":"Rock_Sandstone_Brick","x":-7,"y":12,"z":-1},{"name":"Rock_Sandstone_Brick","x":-7,"y":13,"z":-1},{"name":"Rock_Sandstone_Brick","x":-7,"y":14,"z":-1},{"name":"Rock_Sandstone_Brick","x":-7,"y":9,"z":0},{"name":"Rock_Sandstone_Brick","x":-7,"y":10,"z":0},{"name":"Rock_Sandstone_Brick","x":-7,"y":11,"z":0},{"name":"Rock_Sandstone_Brick","x":-7,"y":12,"z":0},{"name":"Rock_Sandstone_Brick","x":-7,"y":13,"z":0},{"name":"Rock_Sandstone_Brick","x":-7,"y":14,"z":0},{"name":"Rock_Sandstone_Brick","x":-7,"y":9,"z":1},{"name":"Rock_Sandstone_Brick","x":-7,"y":10,"z":1},{"name":"Rock_Sandstone_Brick","x":-7,"y":11,"z":1},{"name":"Rock_Sandstone_Brick","x":-7,"y":12,"z":1},{"name":"Rock_Sandstone_Brick","x":-7,"y":13,"z":1},{"name":"Rock_Sandstone_Brick","x":-7,"y":14,"z":1},{"name":"Rock_Sandstone_Brick","x":-7,"y":9,"z":2},{"name":"Rock_Sandstone_Brick","x":-7,"y":10,"z":2},{"name":"Rock_Sandstone_Brick","x":-7,"y":11,"z":2},{"name":"Rock_Sandstone_Brick","x":-7,"y":12,"z":2},{"name":"Rock_Sandstone_Brick","x":-7,"y":13,"z":2},{"name":"Rock_Sandstone_Brick","x":-7,"y":14,"z":2},{"name":"Rock_Sandstone_Brick","x":-7,"y":9,"z":3},{"name":"Rock_Sandstone_Brick","x":-7,"y":10,"z":3},{"name":"Rock_Sandstone_Brick","x":-7,"y":11,"z":3},{"name":"Rock_Sandstone_Brick","x":-7,"y":12,"z":3},{"name":"Rock_Sandstone_Brick","x":-7,"y":13,"z":3},{"name":"Rock_Sandstone_Brick","x":-7,"y":14,"z":3},{"name":"Rock_Sandstone_Brick","x":-7,"y":15,"z":3},{"name":"Rock_Sandstone_Brick","x":-7,"y":9,"z":4},{"name":"Rock_Sandstone_Brick","x":-7,"y":10,"z":4},{"name":"Rock_Sandstone_Brick","x":-7,"y":11,"z":4},{"name":"Rock_Sandstone_Brick_Smooth","x":-7,"y":12,"z":4},{"name":"Rock_Sandstone_Brick_Smooth","x":-7,"y":13,"z":4},{"name":"Rock_Sandstone_Brick","x":-7,"y":14,"z":4},{"name":"Rock_Sandstone_Brick","x":-7,"y":15,"z":4},{"name":"Rock_Sandstone_Brick_Smooth","x":-7,"y":9,"z":5},{"name":"Rock_Sandstone_Brick_Smooth","x":-7,"y":10,"z":5},{"name":"Rock_Sandstone_Brick_Smooth","x":-7,"y":11,"z":5},{"name":"Rock_Sandstone_Brick_Smooth","x":-7,"y":12,"z":5},{"name":"Rock_Sandstone_Brick_Smooth","x":-7,"y":13,"z":5},{"name":"Rock_Sandstone_Brick_Smooth","x":-7,"y":14,"z":5},{"name":"Rock_Sandstone_Brick_Smooth","x":-7,"y":15,"z":5},{"name":"Rock_Sandstone_Brick","x":-6,"y":9,"z":-3},{"name":"Rock_Sandstone_Brick","x":-6,"y":10,"z":-3},{"name":"Rock_Sandstone_Brick","x":-6,"y":11,"z":-3},{"name":"Rock_Sandstone_Brick","x":-6,"y":12,"z":-3},{"name":"Rock_Sandstone_Brick","x":-6,"y":13,"z":-3},{"name":"Rock_Sandstone_Brick","x":-6,"y":14,"z":-3},{"name":"Rock_Sandstone_Brick","x":-6,"y":15,"z":-3},{"name":"Rock_Sandstone_Brick","x":-6,"y":16,"z":-3},{"name":"Soil_Gravel_Sand_White","x":-6,"y":9,"z":-2},{"name":"Soil_Gravel_Sand_White","x":-6,"y":10,"z":-2},{"name":"Soil_Gravel_Sand_White","x":-6,"y":11,"z":-2},{"name":"Soil_Gravel_Sand_White","x":-6,"y":12,"z":-2},{"name":"Soil_Gravel_Sand_White","x":-6,"y":13,"z":-2},{"name":"Soil_Gravel_Sand_White","x":-6,"y":14,"z":-2},{"name":"Soil_Gravel_Sand_White","x":-6,"y":15,"z":-2},{"name":"Soil_Gravel_Sand_White","x":-6,"y":16,"z":-2},{"name":"Rock_Sandstone_Brick","x":-6,"y":9,"z":-1},{"name":"Rock_Sandstone_Brick","x":-6,"y":10,"z":-1},{"name":"Rock_Sandstone_Brick","x":-6,"y":11,"z":-1},{"name":"Rock_Sandstone_Brick","x":-6,"y":12,"z":-1},{"name":"Rock_Sandstone_Brick","x":-6,"y":13,"z":-1},{"name":"Rock_Sandstone_Brick","x":-6,"y":14,"z":-1},{"name":"Rock_Sandstone_Brick","x":-6,"y":15,"z":-1},{"name":"Rock_Sandstone_Brick","x":-6,"y":16,"z":-1},{"name":"Rock_Sandstone_Brick","x":-6,"y":9,"z":5},{"name":"Rock_Sandstone_Brick_Smooth","x":-6,"y":10,"z":5},{"name":"Rock_Sandstone_Brick_Smooth","x":-6,"y":11,"z":5},{"name":"Rock_Sandstone_Brick","x":-6,"y":12,"z":5},{"name":"Rock_Sandstone_Brick","x":-6,"y":13,"z":5},{"name":"Rock_Sandstone_Brick_Smooth","x":-6,"y":14,"z":5},{"name":"Rock_Sandstone_Brick_Smooth","x":-6,"y":15,"z":5},{"name":"Rock_Sandstone_Brick","x":-6,"y":16,"z":5},{"name":"Rock_Sandstone_Brick","x":-5,"y":9,"z":-3},{"name":"Rock_Sandstone_Brick","x":-5,"y":10,"z":-3},{"name":"Rock_Sandstone_Brick","x":-5,"y":11,"z":-3},{"name":"Rock_Sandstone_Brick","x":-5,"y":12,"z":-3},{"name":"Rock_Sandstone_Brick","x":-5,"y":13,"z":-3},{"name":"Rock_Sandstone_Brick","x":-5,"y":14,"z":-3},{"name":"Rock_Sandstone_Brick","x":-5,"y":15,"z":-3},{"name":"Rock_Sandstone_Brick","x":-5,"y":16,"z":-3},{"name":"Soil_Gravel_Sand_White","x":-5,"y":9,"z":-2},{"name":"Soil_Gravel_Sand_White","x":-5,"y":10,"z":-2},{"name":"Soil_Gravel_Sand_White","x":-5,"y":11,"z":-2},{"name":"Soil_Gravel_Sand_White","x":-5,"y":12,"z":-2},{"name":"Soil_Gravel_Sand_White","x":-5,"y":13,"z":-2},{"name":"Soil_Gravel_Sand_White","x":-5,"y":14,"z":-2},{"name":"Soil_Gravel_Sand_White","x":-5,"y":15,"z":-2},{"name":"Soil_Gravel_Sand_White","x":-5,"y":16,"z":-2},{"name":"Rock_Sandstone_Brick","x":-5,"y":9,"z":-1},{"name":"Rock_Sandstone_Brick","x":-5,"y":10,"z":-1},{"name":"Rock_Sandstone_Brick","x":-5,"y":11,"z":-1},{"name":"Rock_Sandstone_Brick","x":-5,"y":12,"z":-1},{"name":"Rock_Sandstone_Brick","x":-5,"y":13,"z":-1},{"name":"Rock_Sandstone_Brick","x":-5,"y":14,"z":-1},{"name":"Rock_Sandstone_Brick","x":-5,"y":15,"z":-1},{"name":"Rock_Sandstone_Brick","x":-5,"y":16,"z":-1},{"name":"Rock_Sandstone_Brick","x":-5,"y":17,"z":-1},{"name":"Rock_Sandstone_Brick","x":-5,"y":9,"z":5},{"name":"Rock_Sandstone_Brick","x":-5,"y":10,"z":5},{"name":"Rock_Sandstone_Brick","x":-5,"y":11,"z":5},{"name":"Rock_Sandstone_Brick","x":-5,"y":12,"z":5},{"name":"Rock_Sandstone_Brick","x":-5,"y":13,"z":5},{"name":"Rock_Sandstone_Brick","x":-5,"y":14,"z":5},{"name":"Rock_Sandstone_Brick","x":-5,"y":15,"z":5},{"name":"Rock_Sandstone_Brick","x":-5,"y":16,"z":5},{"name":"Rock_Sandstone_Brick","x":-5,"y":17,"z":5},{"name":"Rock_Sandstone_Brick","x":-4,"y":9,"z":-3},{"name":"Rock_Sandstone_Brick_Smooth","x":-4,"y":10,"z":-3},{"name":"Rock_Sandstone_Brick_Smooth","x":-4,"y":11,"z":-3},{"name":"Rock_Sandstone_Brick","x":-4,"y":12,"z":-3},{"name":"Rock_Sandstone_Brick","x":-4,"y":13,"z":-3},{"name":"Rock_Sandstone_Brick_Smooth","x":-4,"y":14,"z":-3},{"name":"Rock_Sandstone_Brick_Smooth","x":-4,"y":15,"z":-3},{"name":"Rock_Sandstone_Brick","x":-4,"y":16,"z":-3},{"name":"Rock_Sandstone_Brick","x":-4,"y":17,"z":-3},{"name":"Soil_Gravel_Sand_White","x":-4,"y":9,"z":-2},{"name":"Soil_Gravel_Sand_White","x":-4,"y":10,"z":-2},{"name":"Soil_Gravel_Sand_White","x":-4,"y":11,"z":-2},{"name":"Soil_Gravel_Sand_White","x":-4,"y":12,"z":-2},{"name":"Soil_Gravel_Sand_White","x":-4,"y":13,"z":-2},{"name":"Soil_Gravel_Sand_White","x":-4,"y":14,"z":-2},{"name":"Soil_Gravel_Sand_White","x":-4,"y":15,"z":-2},{"name":"Soil_Gravel_Sand_White","x":-4,"y":16,"z":-2},{"name":"Soil_Gravel_Sand_White","x":-4,"y":17,"z":-2},{"name":"Rock_Sandstone_Brick","x":-4,"y":9,"z":-1},{"name":"Rock_Sandstone_Brick_Smooth","x":-4,"y":10,"z":-1},{"name":"Rock_Sandstone_Brick_Smooth","x":-4,"y":11,"z":-1},{"name":"Rock_Sandstone_Brick","x":-4,"y":12,"z":-1},{"name":"Rock_Sandstone_Brick","x":-4,"y":13,"z":-1},{"name":"Rock_Sandstone_Brick_Smooth","x":-4,"y":14,"z":-1},{"name":"Rock_Sandstone_Brick_Smooth","x":-4,"y":15,"z":-1},{"name":"Rock_Sandstone_Brick","x":-4,"y":16,"z":-1},{"name":"Rock_Sandstone_Brick","x":-4,"y":17,"z":-1},{"name":"Rock_Sandstone_Brick","x":-4,"y":9,"z":5},{"name":"Rock_Sandstone_Brick","x":-4,"y":10,"z":5},{"name":"Rock_Sandstone_Brick","x":-4,"y":11,"z":5},{"name":"Rock_Sandstone_Brick","x":-4,"y":12,"z":5},{"name":"Rock_Sandstone_Brick","x":-4,"y":13,"z":5},{"name":"Rock_Sandstone_Brick","x":-4,"y":14,"z":5},{"name":"Rock_Sandstone_Brick","x":-4,"y":15,"z":5},{"name":"Rock_Sandstone_Brick","x":-4,"y":16,"z":5},{"name":"Rock_Sandstone_Brick","x":-4,"y":17,"z":5},{"name":"Rock_Sandstone_Brick","x":-4,"y":18,"z":5},{"name":"Rock_Sandstone_Brick_Smooth","x":-3,"y":9,"z":-3},{"name":"Rock_Sandstone_Brick_Smooth","x":-3,"y":10,"z":-3},{"name":"Rock_Sandstone_Brick_Smooth","x":-3,"y":11,"z":-3},{"name":"Rock_Sandstone_Brick_Smooth","x":-3,"y":12,"z":-3},{"name":"Rock_Sandstone_Brick_Smooth","x":-3,"y":13,"z":-3},{"name":"Rock_Sandstone_Brick_Smooth","x":-3,"y":14,"z":-3},{"name":"Rock_Sandstone_Brick_Smooth","x":-3,"y":15,"z":-3},{"name":"Rock_Sandstone_Brick_Smooth","x":-3,"y":16,"z":-3},{"name":"Rock_Sandstone_Brick_Smooth","x":-3,"y":17,"z":-3},{"name":"Soil_Gravel_Sand_White","x":-3,"y":9,"z":-2},{"name":"Soil_Gravel_Sand_White","x":-3,"y":10,"z":-2},{"name":"Soil_Gravel_Sand_White","x":-3,"y":11,"z":-2},{"name":"Soil_Gravel_Sand_White","x":-3,"y":12,"z":-2},{"name":"Soil_Gravel_Sand_White","x":-3,"y":13,"z":-2},{"name":"Soil_Gravel_Sand_White","x":-3,"y":14,"z":-2},{"name":"Soil_Gravel_Sand_White","x":-3,"y":15,"z":-2},{"name":"Soil_Gravel_Sand_White","x":-3,"y":16,"z":-2},{"name":"Soil_Gravel_Sand_White","x":-3,"y":17,"z":-2},{"name":"Rock_Sandstone_Brick_Smooth","x":-3,"y":9,"z":-1},{"name":"Rock_Sandstone_Brick_Smooth","x":-3,"y":10,"z":-1},{"name":"Rock_Sandstone_Brick_Smooth","x":-3,"y":11,"z":-1},{"name":"Rock_Sandstone_Brick_Smooth","x":-3,"y":12,"z":-1},{"name":"Rock_Sandstone_Brick_Smooth","x":-3,"y":13,"z":-1},{"name":"Rock_Sandstone_Brick_Smooth","x":-3,"y":14,"z":-1},{"name":"Rock_Sandstone_Brick_Smooth","x":-3,"y":15,"z":-1},{"name":"Rock_Sandstone_Brick_Smooth","x":-3,"y":16,"z":-1},{"name":"Rock_Sandstone_Brick_Smooth","x":-3,"y":17,"z":-1},{"name":"Rock_Sandstone_Brick","x":-3,"y":9,"z":5},{"name":"Rock_Sandstone_Brick","x":-3,"y":10,"z":5},{"name":"Rock_Sandstone_Brick","x":-3,"y":11,"z":5},{"name":"Rock_Sandstone_Brick","x":-3,"y":12,"z":5},{"name":"Rock_Sandstone_Brick","x":-3,"y":13,"z":5},{"name":"Rock_Sandstone_Brick","x":-3,"y":14,"z":5},{"name":"Rock_Sandstone_Brick","x":-3,"y":15,"z":5},{"name":"Rock_Sandstone_Brick","x":-3,"y":16,"z":5},{"name":"Rock_Sandstone_Brick","x":-3,"y":17,"z":5},{"name":"Rock_Sandstone_Brick","x":-3,"y":18,"z":5},{"name":"Rock_Sandstone_Brick","x":-2,"y":9,"z":-3},{"name":"Rock_Sandstone_Brick","x":-2,"y":10,"z":-3},{"name":"Rock_Sandstone_Brick","x":-2,"y":11,"z":-3},{"name":"Rock_Sandstone_Brick_Smooth","x":-2,"y":12,"z":-3},{"name":"Rock_Sandstone_Brick_Smooth","x":-2,"y":13,"z":-3},{"name":"Rock_Sandstone_Brick","x":-2,"y":14,"z":-3},{"name":"Rock_Sandstone_Brick","x":-2,"y":15,"z":-3},{"name":"Rock_Sandstone_Brick_Smooth","x":-2,"y":16,"z":-3},{"name":"Rock_Sandstone_Brick_Smooth","x":-2,"y":17,"z":-3},{"name":"Soil_Gravel_Sand_White","x":-2,"y":9,"z":-2},{"name":"Soil_Gravel_Sand_White","x":-2,"y":10,"z":-2},{"name":"Soil_Gravel_Sand_White","x":-2,"y":11,"z":-2},{"name":"Soil_Gravel_Sand_White","x":-2,"y":12,"z":-2},{"name":"Soil_Gravel_Sand_White","x":-2,"y":13,"z":-2},{"name":"Soil_Gravel_Sand_White","x":-2,"y":14,"z":-2},{"name":"Soil_Gravel_Sand_White","x":-2,"y":15,"z":-2},{"name":"Soil_Gravel_Sand_White","x":-2,"y":16,"z":-2},{"name":"Soil_Gravel_Sand_White","x":-2,"y":17,"z":-2},{"name":"Rock_Sandstone_Brick","x":-2,"y":9,"z":-1},{"name":"Rock_Sandstone_Brick","x":-2,"y":10,"z":-1},{"name":"Rock_Sandstone_Brick","x":-2,"y":11,"z":-1},{"name":"Rock_Sandstone_Brick_Smooth","x":-2,"y":12,"z":-1},{"name":"Rock_Sandstone_Brick_Smooth","x":-2,"y":13,"z":-1},{"name":"Rock_Sandstone_Brick","x":-2,"y":14,"z":-1},{"name":"Rock_Sandstone_Brick","x":-2,"y":15,"z":-1},{"name":"Rock_Sandstone_Brick_Smooth","x":-2,"y":16,"z":-1},{"name":"Rock_Sandstone_Brick_Smooth","x":-2,"y":17,"z":-1},{"name":"Rock_Sandstone_Brick","x":-2,"y":18,"z":-1},{"name":"Rock_Sandstone_Brick","x":-2,"y":9,"z":5},{"name":"Rock_Sandstone_Brick","x":-2,"y":10,"z":5},{"name":"Rock_Sandstone_Brick","x":-2,"y":11,"z":5},{"name":"Rock_Sandstone_Brick","x":-2,"y":12,"z":5},{"name":"Rock_Sandstone_Brick","x":-2,"y":13,"z":5},{"name":"Rock_Sandstone_Brick","x":-2,"y":14,"z":5},{"name":"Rock_Sandstone_Brick","x":-2,"y":15,"z":5},{"name":"Rock_Sandstone_Brick","x":-2,"y":16,"z":5},{"name":"Rock_Sandstone_Brick","x":-2,"y":17,"z":5},{"name":"Rock_Sandstone_Brick","x":-2,"y":18,"z":5},{"name":"Rock_Sandstone_Brick","x":-1,"y":9,"z":-3},{"name":"Rock_Sandstone_Brick","x":-1,"y":10,"z":-3},{"name":"Rock_Sandstone_Brick","x":-1,"y":11,"z":-3},{"name":"Rock_Sandstone_Brick","x":-1,"y":12,"z":-3},{"name":"Rock_Sandstone_Brick","x":-1,"y":13,"z":-3},{"name":"Rock_Sandstone_Brick","x":-1,"y":14,"z":-3},{"name":"Rock_Sandstone_Brick","x":-1,"y":15,"z":-3},{"name":"Rock_Sandstone_Brick","x":-1,"y":16,"z":-3},{"name":"Rock_Sandstone_Brick","x":-1,"y":17,"z":-3},{"name":"Rock_Sandstone_Brick","x":-1,"y":18,"z":-3},{"name":"Soil_Gravel_Sand_White","x":-1,"y":9,"z":-2},{"name":"Soil_Gravel_Sand_White","x":-1,"y":10,"z":-2},{"name":"Soil_Gravel_Sand_White","x":-1,"y":11,"z":-2},{"name":"Soil_Gravel_Sand_White","x":-1,"y":12,"z":-2},{"name":"Soil_Gravel_Sand_White","x":-1,"y":13,"z":-2},{"name":"Soil_Gravel_Sand_White","x":-1,"y":14,"z":-2},{"name":"Soil_Gravel_Sand_White","x":-1,"y":15,"z":-2},{"name":"Soil_Gravel_Sand_White","x":-1,"y":16,"z":-2},{"name":"Soil_Gravel_Sand_White","x":-1,"y":17,"z":-2},{"name":"Soil_Gravel_Sand_White","x":-1,"y":18,"z":-2},{"name":"Rock_Sandstone_Brick","x":-1,"y":9,"z":-1},{"name":"Rock_Sandstone_Brick","x":-1,"y":10,"z":-1},{"name":"Rock_Sandstone_Brick","x":-1,"y":11,"z":-1},{"name":"Rock_Sandstone_Brick","x":-1,"y":12,"z":-1},{"name":"Rock_Sandstone_Brick","x":-1,"y":13,"z":-1},{"name":"Rock_Sandstone_Brick","x":-1,"y":14,"z":-1},{"name":"Rock_Sandstone_Brick","x":-1,"y":15,"z":-1},{"name":"Rock_Sandstone_Brick","x":-1,"y":16,"z":-1},{"name":"Rock_Sandstone_Brick","x":-1,"y":17,"z":-1},{"name":"Rock_Sandstone_Brick","x":-1,"y":18,"z":-1},{"name":"Rock_Sandstone_Brick","x":-1,"y":9,"z":5},{"name":"Rock_Sandstone_Brick","x":-1,"y":10,"z":5},{"name":"Rock_Sandstone_Brick","x":-1,"y":11,"z":5},{"name":"Rock_Sandstone_Brick","x":-1,"y":12,"z":5},{"name":"Rock_Sandstone_Brick","x":-1,"y":13,"z":5},{"name":"Rock_Sandstone_Brick","x":-1,"y":14,"z":5},{"name":"Rock_Sandstone_Brick","x":-1,"y":15,"z":5},{"name":"Rock_Sandstone_Brick","x":-1,"y":16,"z":5},{"name":"Rock_Sandstone_Brick","x":-1,"y":17,"z":5},{"name":"Rock_Sandstone_Brick","x":0,"y":9,"z":-3},{"name":"Rock_Sandstone_Brick","x":0,"y":10,"z":-3},{"name":"Rock_Sandstone_Brick","x":0,"y":11,"z":-3},{"name":"Rock_Sandstone_Brick","x":0,"y":12,"z":-3},{"name":"Rock_Sandstone_Brick","x":0,"y":13,"z":-3},{"name":"Rock_Sandstone_Brick","x":0,"y":14,"z":-3},{"name":"Rock_Sandstone_Brick","x":0,"y":15,"z":-3},{"name":"Rock_Sandstone_Brick","x":0,"y":16,"z":-3},{"name":"Rock_Sandstone_Brick","x":0,"y":17,"z":-3},{"name":"Rock_Sandstone_Brick","x":0,"y":18,"z":-3},{"name":"Soil_Gravel_Sand_White","x":0,"y":9,"z":-2},{"name":"Soil_Gravel_Sand_White","x":0,"y":10,"z":-2},{"name":"Soil_Gravel_Sand_White","x":0,"y":11,"z":-2},{"name":"Soil_Gravel_Sand_White","x":0,"y":12,"z":-2},{"name":"Soil_Gravel_Sand_White","x":0,"y":13,"z":-2},{"name":"Soil_Gravel_Sand_White","x":0,"y":14,"z":-2},{"name":"Soil_Gravel_Sand_White","x":0,"y":15,"z":-2},{"name":"Soil_Gravel_Sand_White","x":0,"y":16,"z":-2},{"name":"Soil_Gravel_Sand_White","x":0,"y":17,"z":-2},{"name":"Soil_Gravel_Sand_White","x":0,"y":18,"z":-2},{"name":"Rock_Sandstone_Brick","x":0,"y":9,"z":-1},{"name":"Rock_Sandstone_Brick","x":0,"y":10,"z":-1},{"name":"Rock_Sandstone_Brick","x":0,"y":11,"z":-1},{"name":"Rock_Sandstone_Brick","x":0,"y":12,"z":-1},{"name":"Rock_Sandstone_Brick","x":0,"y":13,"z":-1},{"name":"Rock_Sandstone_Brick","x":0,"y":14,"z":-1},{"name":"Rock_Sandstone_Brick","x":0,"y":15,"z":-1},{"name":"Rock_Sandstone_Brick","x":0,"y":16,"z":-1},{"name":"Rock_Sandstone_Brick","x":0,"y":17,"z":-1},{"name":"Rock_Sandstone_Brick","x":0,"y":13,"z":5},{"name":"Soil_Gravel_Sand_White","x":1,"y":13,"z":-2}],"fluids":[{"level":1,"name":"Water_Source","x":-7,"y":9,"z":-1},{"level":1,"name":"Water_Source","x":-7,"y":10,"z":-1},{"level":1,"name":"Water_Source","x":-7,"y":11,"z":-1},{"level":1,"name":"Water_Source","x":-7,"y":12,"z":-1},{"level":1,"name":"Water_Source","x":-7,"y":13,"z":-1},{"level":1,"name":"Water_Source","x":-7,"y":14,"z":-1},{"level":1,"name":"Water_Source","x":-7,"y":9,"z":0},{"level":1,"name":"Water_Source","x":-7,"y":10,"z":0},{"level":1,"name":"Water_Source","x":-7,"y":11,"z":0},{"level":1,"name":"Water_Source","x":-7,"y":12,"z":0},{"level":1,"name":"Water_Source","x":-7,"y":13,"z":0},{"level":1,"name":"Water_Source","x":-7,"y":14,"z":0},{"level":1,"name":"Water_Source","x":-7,"y":9,"z":1},{"level":1,"name":"Water_Source","x":-7,"y":10,"z":1},{"level":1,"name":"Water_Source","x":-7,"y":11,"z":1},{"level":1,"name":"Water_Source","x":-7,"y":12,"z":1},{"level":1,"name":"Water_Source","x":-7,"y":13,"z":1},{"level":1,"name":"Water_Source","x":-7,"y":14,"z":1},{"level":1,"name":"Water_Source","x":-7,"y":9,"z":2},{"level":1,"name":"Water_Source","x":-7,"y":10,"z":2},{"level":1,"name":"Water_Source","x":-7,"y":11,"z":2},{"level":1,"name":"Water_Source","x":-7,"y":12,"z":2},{"level":1,"name":"Water_Source","x":-7,"y":13,"z":2},{"level":1,"name":"Water_Source","x":-7,"y":14,"z":2},{"level":1,"name":"Water_Source","x":-7,"y":9,"z":3},{"level":1,"name":"Water_Source","x":-7,"y":10,"z":3},{"level":1,"name":"Water_Source","x":-7,"y":11,"z":3},{"level":1,"name":"Water_Source","x":-7,"y":12,"z":3},{"level":1,"name":"Water_Source","x":-7,"y":13,"z":3},{"level":1,"name":"Water_Source","x":-7,"y":14,"z":3},{"level":1,"name":"Water_Source","x":-7,"y":15,"z":3},{"level":1,"name":"Water_Source","x":-7,"y":9,"z":4},{"level":1,"name":"Water_Source","x":-7,"y":10,"z":4},{"level":1,"name":"Water_Source","x":-7,"y":11,"z":4},{"level":1,"name":"Water_Source","x":-7,"y":12,"z":4},{"level":1,"name":"Water_Source","x":-7,"y":13,"z":4},{"level":1,"name":"Water_Source","x":-7,"y":14,"z":4},{"level":1,"name":"Water_Source","x":-7,"y":15,"z":4},{"level":1,"name":"Water_Source","x":-7,"y":9,"z":5},{"level":1,"name":"Water_Source","x":-7,"y":10,"z":5},{"level":1,"name":"Water_Source","x":-7,"y":11,"z":5},{"level":1,"name":"Water_Source","x":-7,"y":12,"z":5},{"level":1,"name":"Water_Source","x":-7,"y":13,"z":5},{"level":1,"name":"Water_Source","x":-7,"y":14,"z":5},{"level":1,"name":"Water_Source","x":-7,"y":15,"z":5},{"level":1,"name":"Water_Source","x":-6,"y":9,"z":-3},{"level":1,"name":"Water_Source","x":-6,"y":10,"z":-3},{"level":1,"name":"Water_Source","x":-6,"y":11,"z":-3},{"level":1,"name":"Water_Source","x":-6,"y":12,"z":-3},{"level":1,"name":"Water_Source","x":-6,"y":13,"z":-3},{"level":1,"name":"Water_Source","x":-6,"y":14,"z":-3},{"level":1,"name":"Water_Source","x":-6,"y":15,"z":-3},{"level":1,"name":"Water_Source","x":-6,"y":16,"z":-3},{"level":1,"name":"Water_Source","x":-6,"y":9,"z":-2},{"level":1,"name":"Water_Source","x":-6,"y":10,"z":-2},{"level":1,"name":"Water_Source","x":-6,"y":11,"z":-2},{"level":1,"name":"Water_Source","x":-6,"y":12,"z":-2},{"level":1,"name":"Water_Source","x":-6,"y":13,"z":-2},{"level":1,"name":"Water_Source","x":-6,"y":14,"z":-2},{"level":1,"name":"Water_Source","x":-6,"y":15,"z":-2},{"level":1,"name":"Water_Source","x":-6,"y":16,"z":-2},{"level":1,"name":"Water_Source","x":-6,"y":9,"z":-1},{"level":1,"name":"Water_Source","x":-6,"y":10,"z":-1},{"level":1,"name":"Water_Source","x":-6,"y":11,"z":-1},{"level":1,"name":"Water_Source","x":-6,"y":12,"z":-1},{"level":1,"name":"Water_Source","x":-6,"y":13,"z":-1},{"level":1,"name":"Water_Source","x":-6,"y":14,"z":-1},{"level":1,"name":"Water_Source","x":-6,"y":15,"z":-1},{"level":1,"name":"Water_Source","x":-6,"y":16,"z":-1},{"level":1,"name":"Water_Source","x":-6,"y":9,"z":5},{"level":1,"name":"Water_Source","x":-6,"y":10,"z":5},{"level":1,"name":"Water_Source","x":-6,"y":11,"z":5},{"level":1,"name":"Water_Source","x":-6,"y":12,"z":5},{"level":1,"name":"Water_Source","x":-6,"y":13,"z":5},{"level":1,"name":"Water_Source","x":-6,"y":14,"z":5},{"level":1,"name":"Water_Source","x":-6,"y":15,"z":5},{"level":1,"name":"Water_Source","x":-6,"y":16,"z":5},{"level":1,"name":"Water_Source","x":-5,"y":9,"z":-3},{"level":1,"name":"Water_Source","x":-5,"y":10,"z":-3},{"level":1,"name":"Water_Source","x":-5,"y":11,"z":-3},{"level":1,"name":"Water_Source","x":-5,"y":12,"z":-3},{"level":1,"name":"Water_Source","x":-5,"y":13,"z":-3},{"level":1,"name":"Water_Source","x":-5,"y":14,"z":-3},{"level":1,"name":"Water_Source","x":-5,"y":15,"z":-3},{"level":1,"name":"Water_Source","x":-5,"y":16,"z":-3},{"level":1,"name":"Water_Source","x":-5,"y":9,"z":-2},{"level":1,"name":"Water_Source","x":-5,"y":10,"z":-2},{"level":1,"name":"Water_Source","x":-5,"y":11,"z":-2},{"level":1,"name":"Water_Source","x":-5,"y":12,"z":-2},{"level":1,"name":"Water_Source","x":-5,"y":13,"z":-2},{"level":1,"name":"Water_Source","x":-5,"y":14,"z":-2},{"level":1,"name":"Water_Source","x":-5,"y":15,"z":-2},{"level":1,"name":"Water_Source","x":-5,"y":16,"z":-2},{"level":1,"name":"Water_Source","x":-5,"y":9,"z":-1},{"level":1,"name":"Water_Source","x":-5,"y":10,"z":-1},{"level":1,"name":"Water_Source","x":-5,"y":11,"z":-1},{"level":1,"name":"Water_Source","x":-5,"y":12,"z":-1},{"level":1,"name":"Water_Source","x":-5,"y":13,"z":-1},{"level":1,"name":"Water_Source","x":-5,"y":14,"z":-1},{"level":1,"name":"Water_Source","x":-5,"y":15,"z":-1},{"level":1,"name":"Water_Source","x":-5,"y":16,"z":-1},{"level":1,"name":"Water_Source","x":-5,"y":17,"z":-1},{"level":1,"name":"Water_Source","x":-5,"y":9,"z":5},{"level":1,"name":"Water_Source","x":-5,"y":10,"z":5},{"level":1,"name":"Water_Source","x":-5,"y":11,"z":5},{"level":1,"name":"Water_Source","x":-5,"y":12,"z":5},{"level":1,"name":"Water_Source","x":-5,"y":13,"z":5},{"level":1,"name":"Water_Source","x":-5,"y":14,"z":5},{"level":1,"name":"Water_Source","x":-5,"y":15,"z":5},{"level":1,"name":"Water_Source","x":-5,"y":16,"z":5},{"level":1,"name":"Water_Source","x":-5,"y":17,"z":5},{"level":1,"name":"Water_Source","x":-4,"y":9,"z":-3},{"level":1,"name":"Water_Source","x":-4,"y":10,"z":-3},{"level":1,"name":"Water_Source","x":-4,"y":11,"z":-3},{"level":1,"name":"Water_Source","x":-4,"y":12,"z":-3},{"level":1,"name":"Water_Source","x":-4,"y":13,"z":-3},{"level":1,"name":"Water_Source","x":-4,"y":14,"z":-3},{"level":1,"name":"Water_Source","x":-4,"y":15,"z":-3},{"level":1,"name":"Water_Source","x":-4,"y":16,"z":-3},{"level":1,"name":"Water_Source","x":-4,"y":17,"z":-3},{"level":1,"name":"Water_Source","x":-4,"y":9,"z":-2},{"level":1,"name":"Water_Source","x":-4,"y":10,"z":-2},{"level":1,"name":"Water_Source","x":-4,"y":11,"z":-2},{"level":1,"name":"Water_Source","x":-4,"y":12,"z":-2},{"level":1,"name":"Water_Source","x":-4,"y":13,"z":-2},{"level":1,"name":"Water_Source","x":-4,"y":14,"z":-2},{"level":1,"name":"Water_Source","x":-4,"y":15,"z":-2},{"level":1,"name":"Water_Source","x":-4,"y":16,"z":-2},{"level":1,"name":"Water_Source","x":-4,"y":17,"z":-2},{"level":1,"name":"Water_Source","x":-4,"y":9,"z":-1},{"level":1,"name":"Water_Source","x":-4,"y":10,"z":-1},{"level":1,"name":"Water_Source","x":-4,"y":11,"z":-1},{"level":1,"name":"Water_Source","x":-4,"y":12,"z":-1},{"level":1,"name":"Water_Source","x":-4,"y":13,"z":-1},{"level":1,"name":"Water_Source","x":-4,"y":14,"z":-1},{"level":1,"name":"Water_Source","x":-4,"y":15,"z":-1},{"level":1,"name":"Water_Source","x":-4,"y":16,"z":-1},{"level":1,"name":"Water_Source","x":-4,"y":17,"z":-1},{"level":1,"name":"Water_Source","x":-4,"y":9,"z":5},{"level":1,"name":"Water_Source","x":-4,"y":10,"z":5},{"level":1,"name":"Water_Source","x":-4,"y":11,"z":5},{"level":1,"name":"Water_Source","x":-4,"y":12,"z":5},{"level":1,"name":"Water_Source","x":-4,"y":13,"z":5},{"level":1,"name":"Water_Source","x":-4,"y":14,"z":5},{"level":1,"name":"Water_Source","x":-4,"y":15,"z":5},{"level":1,"name":"Water_Source","x":-4,"y":16,"z":5},{"level":1,"name":"Water_Source","x":-4,"y":17,"z":5},{"level":1,"name":"Water_Source","x":-4,"y":18,"z":5},{"level":1,"name":"Water_Source","x":-3,"y":9,"z":-3},{"level":1,"name":"Water_Source","x":-3,"y":10,"z":-3},{"level":1,"name":"Water_Source","x":-3,"y":11,"z":-3},{"level":1,"name":"Water_Source","x":-3,"y":12,"z":-3},{"level":1,"name":"Water_Source","x":-3,"y":13,"z":-3},{"level":1,"name":"Water_Source","x":-3,"y":14,"z":-3},{"level":1,"name":"Water_Source","x":-3,"y":15,"z":-3},{"level":1,"name":"Water_Source","x":-3,"y":16,"z":-3},{"level":1,"name":"Water_Source","x":-3,"y":17,"z":-3},{"level":1,"name":"Water_Source","x":-3,"y":9,"z":-2},{"level":1,"name":"Water_Source","x":-3,"y":10,"z":-2},{"level":1,"name":"Water_Source","x":-3,"y":11,"z":-2},{"level":1,"name":"Water_Source","x":-3,"y":12,"z":-2},{"level":1,"name":"Water_Source","x":-3,"y":13,"z":-2},{"level":1,"name":"Water_Source","x":-3,"y":14,"z":-2},{"level":1,"name":"Water_Source","x":-3,"y":15,"z":-2},{"level":1,"name":"Water_Source","x":-3,"y":16,"z":-2},{"level":1,"name":"Water_Source","x":-3,"y":17,"z":-2},{"level":1,"name":"Water_Source","x":-3,"y":9,"z":-1},{"level":1,"name":"Water_Source","x":-3,"y":10,"z":-1},{"level":1,"name":"Water_Source","x":-3,"y":11,"z":-1},{"level":1,"name":"Water_Source","x":-3,"y":12,"z":-1},{"level":1,"name":"Water_Source","x":-3,"y":13,"z":-1},{"level":1,"name":"Water_Source","x":-3,"y":14,"z":-1},{"level":1,"name":"Water_Source","x":-3,"y":15,"z":-1},{"level":1,"name":"Water_Source","x":-3,"y":16,"z":-1},{"level":1,"name":"Water_Source","x":-3,"y":17,"z":-1},{"level":1,"name":"Water_Source","x":-3,"y":9,"z":5},{"level":1,"name":"Water_Source","x":-3,"y":10,"z":5},{"level":1,"name":"Water_Source","x":-3,"y":11,"z":5},{"level":1,"name":"Water_Source","x":-3,"y":12,"z":5},{"level":1,"name":"Water_Source","x":-3,"y":13,"z":5},{"level":1,"name":"Water_Source","x":-3,"y":14,"z":5},{"level":1,"name":"Water_Source","x":-3,"y":15,"z":5},{"level":1,"name":"Water_Source","x":-3,"y":16,"z":5},{"level":1,"name":"Water_Source","x":-3,"y":17,"z":5},{"level":1,"name":"Water_Source","x":-3,"y":18,"z":5},{"level":1,"name":"Water_Source","x":-2,"y":9,"z":-3},{"level":1,"name":"Water_Source","x":-2,"y":10,"z":-3},{"level":1,"name":"Water_Source","x":-2,"y":11,"z":-3},{"level":1,"name":"Water_Source","x":-2,"y":12,"z":-3},{"level":1,"name":"Water_Source","x":-2,"y":13,"z":-3},{"level":1,"name":"Water_Source","x":-2,"y":14,"z":-3},{"level":1,"name":"Water_Source","x":-2,"y":15,"z":-3},{"level":1,"name":"Water_Source","x":-2,"y":16,"z":-3},{"level":1,"name":"Water_Source","x":-2,"y":17,"z":-3},{"level":1,"name":"Water_Source","x":-2,"y":9,"z":-2},{"level":1,"name":"Water_Source","x":-2,"y":10,"z":-2},{"level":1,"name":"Water_Source","x":-2,"y":11,"z":-2},{"level":1,"name":"Water_Source","x":-2,"y":12,"z":-2},{"level":1,"name":"Water_Source","x":-2,"y":13,"z":-2},{"level":1,"name":"Water_Source","x":-2,"y":14,"z":-2},{"level":1,"name":"Water_Source","x":-2,"y":15,"z":-2},{"level":1,"name":"Water_Source","x":-2,"y":16,"z":-2},{"level":1,"name":"Water_Source","x":-2,"y":17,"z":-2},{"level":1,"name":"Water_Source","x":-2,"y":9,"z":-1},{"level":1,"name":"Water_Source","x":-2,"y":10,"z":-1},{"level":1,"name":"Water_Source","x":-2,"y":11,"z":-1},{"level":1,"name":"Water_Source","x":-2,"y":12,"z":-1},{"level":1,"name":"Water_Source","x":-2,"y":13,"z":-1},{"level":1,"name":"Water_Source","x":-2,"y":14,"z":-1},{"level":1,"name":"Water_Source","x":-2,"y":15,"z":-1},{"level":1,"name":"Water_Source","x":-2,"y":16,"z":-1},{"level":1,"name":"Water_Source","x":-2,"y":17,"z":-1},{"level":1,"name":"Water_Source","x":-2,"y":18,"z":-1},{"level":1,"name":"Water_Source","x":-2,"y":9,"z":5},{"level":1,"name":"Water_Source","x":-2,"y":10,"z":5},{"level":1,"name":"Water_Source","x":-2,"y":11,"z":5},{"level":1,"name":"Water_Source","x":-2,"y":12,"z":5},{"level":1,"name":"Water_Source","x":-2,"y":13,"z":5},{"level":1,"name":"Water_Source","x":-2,"y":14,"z":5},{"level":1,"name":"Water_Source","x":-2,"y":15,"z":5},{"level":1,"name":"Water_Source","x":-2,"y":16,"z":5},{"level":1,"name":"Water_Source","x":-2,"y":17,"z":5},{"level":1,"name":"Water_Source","x":-2,"y":18,"z":5},{"level":1,"name":"Water_Source","x":-1,"y":9,"z":-3},{"level":1,"name":"Water_Source","x":-1,"y":10,"z":-3},{"level":1,"name":"Water_Source","x":-1,"y":11,"z":-3},{"level":1,"name":"Water_Source","x":-1,"y":12,"z":-3},{"level":1,"name":"Water_Source","x":-1,"y":13,"z":-3},{"level":1,"name":"Water_Source","x":-1,"y":14,"z":-3},{"level":1,"name":"Water_Source","x":-1,"y":15,"z":-3},{"level":1,"name":"Water_Source","x":-1,"y":16,"z":-3},{"level":1,"name":"Water_Source","x":-1,"y":17,"z":-3},{"level":1,"name":"Water_Source","x":-1,"y":18,"z":-3},{"level":1,"name":"Water_Source","x":-1,"y":9,"z":-2},{"level":1,"name":"Water_Source","x":-1,"y":10,"z":-2},{"level":1,"name":"Water_Source","x":-1,"y":11,"z":-2},{"level":1,"name":"Water_Source","x":-1,"y":12,"z":-2},{"level":1,"name":"Water_Source","x":-1,"y":13,"z":-2},{"level":1,"name":"Water_Source","x":-1,"y":14,"z":-2},{"level":1,"name":"Water_Source","x":-1,"y":15,"z":-2},{"level":1,"name":"Water_Source","x":-1,"y":16,"z":-2},{"level":1,"name":"Water_Source","x":-1,"y":17,"z":-2},{"level":1,"name":"Water_Source","x":-1,"y":18,"z":-2},{"level":1,"name":"Water_Source","x":-1,"y":9,"z":-1},{"level":1,"name":"Water_Source","x":-1,"y":10,"z":-1},{"level":1,"name":"Water_Source","x":-1,"y":11,"z":-1},{"level":1,"name":"Water_Source","x":-1,"y":12,"z":-1},{"level":1,"name":"Water_Source","x":-1,"y":13,"z":-1},{"level":1,"name":"Water_Source","x":-1,"y":14,"z":-1},{"level":1,"name":"Water_Source","x":-1,"y":15,"z":-1},{"level":1,"name":"Water_Source","x":-1,"y":16,"z":-1},{"level":1,"name":"Water_Source","x":-1,"y":17,"z":-1},{"level":1,"name":"Water_Source","x":-1,"y":18,"z":-1},{"level":1,"name":"Water_Source","x":-1,"y":9,"z":5},{"level":1,"name":"Water_Source","x":-1,"y":10,"z":5},{"level":1,"name":"Water_Source","x":-1,"y":11,"z":5},{"level":1,"name":"Water_Source","x":-1,"y":12,"z":5},{"level":1,"name":"Water_Source","x":-1,"y":13,"z":5},{"level":1,"name":"Water_Source","x":-1,"y":14,"z":5},{"level":1,"name":"Water_Source","x":-1,"y":15,"z":5},{"level":1,"name":"Water_Source","x":-1,"y":16,"z":5},{"level":1,"name":"Water_Source","x":-1,"y":17,"z":5},{"level":1,"name":"Water_Source","x":0,"y":9,"z":-3},{"level":1,"name":"Water_Source","x":0,"y":10,"z":-3},{"level":1,"name":"Water_Source","x":0,"y":11,"z":-3},{"level":1,"name":"Water_Source","x":0,"y":12,"z":-3},{"level":1,"name":"Water_Source","x":0,"y":13,"z":-3},{"level":1,"name":"Water_Source","x":0,"y":14,"z":-3},{"level":1,"name":"Water_Source","x":0,"y":15,"z":-3},{"level":1,"name":"Water_Source","x":0,"y":16,"z":-3},{"level":1,"name":"Water_Source","x":0,"y":17,"z":-3},{"level":1,"name":"Water_Source","x":0,"y":18,"z":-3},{"level":1,"name":"Water_Source","x":0,"y":9,"z":-2},{"level":1,"name":"Water_Source","x":0,"y":10,"z":-2},{"level":1,"name":"Water_Source","x":0,"y":11,"z":-2},{"level":1,"name":"Water_Source","x":0,"y":12,"z":-2},{"level":1,"name":"Water_Source","x":0,"y":13,"z":-2},{"level":1,"name":"Water_Source","x":0,"y":14,"z":-2},{"level":1,"name":"Water_Source","x":0,"y":15,"z":-2},{"level":1,"name":"Water_Source","x":0,"y":16,"z":-2},{"level":1,"name":"Water_Source","x":0,"y":17,"z":-2},{"level":1,"name":"Water_Source","x":0,"y":18,"z":-2},{"level":1,"name":"Water_Source","x":0,"y":9,"z":-1},{"level":1,"name":"Water_Source","x":0,"y":10,"z":-1},{"level":1,"name":"Water_Source","x":0,"y":11,"z":-1},{"level":1,"name":"Water_Source","x":0,"y":12,"z":-1},{"level":1,"name":"Water_Source","x":0,"y":13,"z":-1},{"level":1,"name":"Water_Source","x":0,"y":14,"z":-1},{"level":1,"name":"Water_Source","x":0,"y":15,"z":-1},{"level":1,"name":"Water_Source","x":0,"y":16,"z":-1},{"level":1,"name":"Water_Source","x":0,"y":17,"z":-1},{"level":1,"name":"Water_Source","x":0,"y":13,"z":5},{"level":1,"name":"Water_Source","x":1,"y":13,"z":-2}],"version":8}