{"anchorX":-4,"anchorY":7,"anchorZ":0,"blockIdVersion":11,"blocks":[{"name":"Rock_Sandstone_Brick","x":-7,"y":6,"z":-3},{"name":"Rock_Sandstone_Brick","x":-7,"y":7,"z":-3},{"name":"Rock_Sandstone_Brick","x":-7,"y":8,"z":-3},{"name":"Rock_Sandstone_Brick","x":-7,"y":9,"z":-3},{"name":"Rock_Sandstone_Brick","x":-7,"y":10,"z":-3},{"name":"Rock_Sandstone_Brick","x":-7,"y":11,"z":-3},{"name":"Rock_Sandstone_Brick","x":-7,"y":6,"z":-2},{"name":"Rock_Sandstone_Brick","x":-7,"y":7,"z":-2},{"name":"Rock_Sandstone_Brick","x":-7,"y":8,"z":-2},{"name":"Rock_Sandstone_Brick","x":-7,"y":9,"z":-2},{"name":"Rock_Sandstone_Brick","x":-7,"y":10,"z":-2},{"name":"Rock_Sandstone_Brick","x":-7,"y":11,"z":-2},{"name":"Rock_Sandstone_Brick","x":-7,"y":12,"z":-2},{"name":"Rock_Sandstone_Brick","x":-7,"y":13,"z":-2},{"name":"Rock_Sandstone_Brick","x":-7,"y":6,"z":-1},{"name":"Rock_Sandstone_Brick_Smooth","x":-7,"y":7,"z":-1},{"name":"Rock_Sandstone_Brick_Smooth","x":-7,"y":8,"z":-1},{"name":"Rock_Sandstone_Brick","x":-7,"y":9,"z":-1},{"name":"Rock_Sandstone_Brick","x":-7,"y":10,"z":-1},{"name":"Rock_Sandstone_Brick_Smooth","x":-7,"y":11,"z":-1},{"name":"Rock_Sandstone_Brick_Smooth","x":-7,"y":12,"z":-1},{"name":"Rock_Sandstone_Brick","x":-7,"y":13,"z":-1},{"name":"Rock_Sandstone_Brick","x":-7,"y":14,"z":-1},{"name":"Rock_Sandstone_Brick_Smooth","x":-7,"y":6,"z":0},{"name":"Rock_Sandstone_Brick_Smooth","x":-7,"y":7,"z":0},{"name":"Rock_Sandstone_Brick_Smooth","x":-7,"y":8,"z":0},{"name":"Rock_Sandstone_Brick_Smooth","x":-7,"y":9,"z":0},{"name":"Rock_Sandstone_Brick_Smooth","x":-7,"y":10,"z":0},{"name":"Rock_Sandstone_Brick_Smooth","x":-7,"y":11,"z":0},{"name":"Rock_Sandstone_Brick_Smooth","x":-7,"y":12,"z":0},{"name":"Rock_Sandstone_Brick_Smooth","x":-7,"y":13,"z":0},{"name":"Rock_Sandstone_Brick_Smooth","x":-7,"y":14,"z":0},{"name":"Rock_Sandstone_Brick_Smooth","x":-7,"y":15,"z":0},{"name":"Rock_Sandstone_Brick","x":-7,"y":6,"z":1},{"name":"Rock_Sandstone_Brick","x":-7,"y":7,"z":1},{"name":"Rock_Sandstone_Brick","x":-7,"y":8,"z":1},{"name":"Rock_Sandstone_Brick_Smooth","x":-7,"y":9,"z":1},{"name":"Rock_Sandstone_Brick_Smooth","x":-7,"y":10,"z":1},{"name":"Rock_Sandstone_Brick","x":-7,"y":11,"z":1},{"name":"Rock_Sandstone_Brick","x":-7,"y":12,"z":1},{"name":"Rock_Sandstone_Brick_Smooth","x":-7,"y":13,"z":1},{"name":"Rock_Sandstone_Brick_Smooth","x":-7,"y":14,"z":1},{"name":"Rock_Sandstone_Brick","x":-7,"y":15,"z":1},{"name":"Rock_Sandstone_Brick","x":-7,"y":6,"z":2},{"name":"Rock_Sandstone_Brick","x":-7,"y":7,"z":2},{"name":"Rock_Sandstone_Brick","x":-7,"y":8,"z":2},{"name":"Rock_Sandstone_Brick","x":-7,"y":9,"z":2},{"name":"Rock_Sandstone_Brick","x":-7,"y":10,"z":2},{"name":"Rock_Sandstone_Brick","x":-7,"y":11,"z":2},{"name":"Rock_Sandstone_Brick","x":-7,"y":12,"z":2},{"name":"Rock_Sandstone_Brick","x":-7,"y":13,"z":2},{"name":"Rock_Sandstone_Brick","x":-7,"y":14,"z":2},{"name":"Rock_Sandstone_Brick","x":-7,"y":15,"z":2},{"name":"Rock_Sandstone_Brick","x":-7,"y":6,"z":3},{"name":"Rock_Sandstone_Brick","x":-7,"y":7,"z":3},{"name":"Rock_Sandstone_Brick","x":-7,"y":8,"z":3},{"name":"Rock_Sandstone_Brick","x":-7,"y":9,"z":3},{"name":"Rock_Sandstone_Brick","x":-7,"y":10,"z":3},{"name":"Rock_Sandstone_Brick","x":-7,"y":11,"z":3},{"name":"Rock_Sandstone_Brick","x":-7,"y":12,"z":3},{"name":"Rock_Sandstone_Brick","x":-7,"y":13,"z":3},{"name":"Rock_Sandstone_Brick","x":-7,"y":14,"z":3},{"name":"Rock_Sandstone_Brick","x":-7,"y":6,"z":4},{"name":"Rock_Sandstone_Brick","x":-7,"y":7,"z":4},{"name":"Rock_Sandstone_Brick","x":-7,"y":8,"z":4},{"name":"Rock_Sandstone_Brick","x":-7,"y":9,"z":4},{"name":"Rock_Sandstone_Brick","x":-7,"y":10,"z":4},{"name":"Rock_Sandstone_Brick","x":-7,"y":11,"z":4},{"name":"Plant_Coral_Block_Red","x":-6,"y":14,"z":-1},{"name":"Plant_Coral_Block_Yellow","x":-6,"y":14,"z":0},{"name":"Plant_Coral_Bush_Orange","x":-6,"y":15,"z":0},{"name":"Plant_Coral_Block_Yellow","x":-6,"y":14,"z":1},{"name":"Plant_Coral_Model_Orange","x":-6,"y":15,"z":1},{"name":"Plant_Coral_Block_Yellow","x":-6,"y":14,"z":2},{"name":"Plant_Coral_Block_Red","x":-6,"y":14,"z":3},{"name":"Rock_Sandstone_Brick","x":-6,"y":6,"z":4},{"name":"Rock_Sandstone_Brick","x":-6,"y":7,"z":4},{"name":"Rock_Sandstone_Brick","x":-6,"y":8,"z":4},{"name":"Rock_Sandstone_Brick","x":-6,"y":9,"z":4},{"name":"Rock_Sandstone_Brick","x":-6,"y":10,"z":4},{"name":"Rock_Sandstone_Brick","x":-6,"y":11,"z":4},{"name":"Rock_Sandstone_Brick","x":-6,"y":12,"z":4},{"name":"Rock_Sandstone_Brick","x":-5,"y":6,"z":-1},{"name":"Rock_Sandstone_Brick","x":-5,"y":7,"z":-1},{"name":"Rock_Sandstone_Brick","x":-5,"y":8,"z":-1},{"name":"Rock_Sandstone_Brick","x":-5,"y":9,"z":-1},{"name":"Rock_Sandstone_Brick","x":-5,"y":10,"z":-1},{"name":"Rock_Sandstone_Brick","x":-5,"y":11,"z":-1},{"name":"Rock_Sandstone_Brick","x":-5,"y":12,"z":-1},{"name":"Plant_Coral_Block_Red","x":-5,"y":14,"z":0},{"name":"Plant_Coral_Block_Red","x":-5,"y":14,"z":1},{"name":"Plant_Coral_Block_Red","x":-5,"y":14,"z":2},{"name":"Rock_Sandstone_Brick","x":-5,"y":6,"z":4},{"name":"Rock_Sandstone_Brick","x":-5,"y":7,"z":4},{"name":"Rock_Sandstone_Brick","x":-5,"y":8,"z":4},{"name":"Rock_Sandstone_Brick","x":-5,"y":9,"z":4},{"name":"Rock_Sandstone_Brick","x":-5,"y":10,"z":4},{"name":"Rock_Sandstone_Brick","x":-5,"y":11,"z":4},{"name":"Rock_Sandstone_Brick","x":-5,"y":12,"z":4},{"name":"Rock_Sandstone_Brick","x":-5,"y":13,"z":4},{"name":"Rock_Sandstone_Brick","x":-4,"y":6,"z":-1},{"name":"Rock_Sandstone_Brick","x":-4,"y":7,"z":-1},{"name":"Rock_Sandstone_Brick","x":-4,"y":8,"z":-1},{"name":"Rock_Sandstone_Brick","x":-4,"y":9,"z":-1},{"name":"Rock_Sandstone_Brick","x":-4,"y":10,"z":-1},{"name":"Rock_Sandstone_Brick","x":-4,"y":11,"z":-1},{"name":"Rock_Sandstone_Brick","x":-4,"y":12,"z":-1},{"name":"Rock_Sandstone_Brick","x":-4,"y":13,"z":-1},{"name":"Rock_Sandstone_Brick","x":-4,"y":6,"z":4},{"name":"Rock_Sandstone_Brick","x":-4,"y":7,"z":4},{"name":"Rock_Sandstone_Brick","x":-4,"y":8,"z":4},{"name":"Rock_Sandstone_Brick","x":-4,"y":9,"z":4},{"name":"Rock_Sandstone_Brick","x":-4,"y":10,"z":4},{"name":"Rock_Sandstone_Brick","x":-4,"y":11,"z":4},{"name":"Wood_Goldenwood_Fence","x":-4,"y":12,"z":4},{"name":"Wood_Goldenwood_Fence","x":-4,"y":13,"z":4},{"name":"Rock_Sandstone_Brick","x":-3,"y":6,"z":-1},{"name":"Rock_Sandstone_Brick","x":-3,"y":7,"z":-1},{"name":"Rock_Sandstone_Brick","x":-3,"y":8,"z":-1},{"name":"Rock_Sandstone_Brick","x":-3,"y":9,"z":-1},{"name":"Rock_Sandstone_Brick","x":-3,"y":10,"z":-1},{"name":"Rock_Sandstone_Brick","x":-3,"y":11,"z":-1},{"name":"Rock_Sandstone_Brick","x":-3,"y":12,"z":-1},{"name":"Rock_Sandstone_Brick","x":-3,"y":13,"z":-1},{"name":"Rock_Sandstone_Brick","x":-3,"y":14,"z":-1},{"name":"Rock_Sandstone_Brick","x":-3,"y":6,"z":4},{"name":"Rock_Sandstone_Brick","x":-3,"y":7,"z":4},{"name":"Rock_Sandstone_Brick","x":-3,"y":8,"z":4},{"name":"Rock_Sandstone_Brick","x":-3,"y":9,"z":4},{"name":"Rock_Sandstone_Brick","x":-3,"y":10,"z":4},{"name":"Rock_Sandstone_Brick","x":-3,"y":11,"z":4},{"name":"Wood_Goldenwood_Fence","x":-3,"y":12,"z":4},{"name":"Wood_Goldenwood_Fence","x":-3,"y":13,"z":4},{"name":"Rock_Sandstone_Brick_Stairs","rotation":9,"x":-3,"y":14,"z":4},{"name":"Rock_Sandstone_Brick","x":-2,"y":6,"z":-1},{"name":"Rock_Sandstone_Brick","x":-2,"y":7,"z":-1},{"name":"Rock_Sandstone_Brick","x":-2,"y":8,"z":-1},{"name":"Rock_Sandstone_Brick","x":-2,"y":9,"z":-1},{"name":"Rock_Sandstone_Brick","x":-2,"y":10,"z":-1},{"name":"Rock_Sandstone_Brick","x":-2,"y":11,"z":-1},{"name":"Rock_Sandstone_Brick","x":-2,"y":12,"z":-1},{"name":"Rock_Sandstone_Brick","x":-2,"y":13,"z":-1},{"name":"Rock_Sandstone_Brick","x":-2,"y":14,"z":-1},{"name":"Rock_Sandstone_Brick","x":-2,"y":6,"z":4},{"name":"Rock_Sandstone_Brick","x":-2,"y":7,"z":4},{"name":"Rock_Sandstone_Brick","x":-2,"y":8,"z":4},{"name":"Rock_Sandstone_Brick","x":-2,"y":9,"z":4},{"name":"Rock_Sandstone_Brick","x":-2,"y":10,"z":4},{"name":"Rock_Sandstone_Brick","x":-2,"y":11,"z":4},{"name":"Rock_Sandstone_Brick","x":-2,"y":12,"z":4},{"name":"Rock_Sandstone_Brick","x":-2,"y":13,"z":4},{"name":"Rock_Sandstone_Brick","x":-2,"y":14,"z":4},{"name":"Plant_Coral_Block_Red","x":-2,"y":13,"z":5},{"name":"Rock_Sandstone_Brick","x":-1,"y":6,"z":-3},{"name":"Rock_Sandstone_Brick","x":-1,"y":7,"z":-3},{"name":"Rock_Sandstone_Brick","x":-1,"y":8,"z":-3},{"name":"Rock_Sandstone_Brick","x":-1,"y":9,"z":-3},{"name":"Rock_Sandstone_Brick","x":-1,"y":10,"z":-3},{"name":"Rock_Sandstone_Brick","x":-1,"y":11,"z":-3},{"name":"Rock_Sandstone_Brick","x":-1,"y":12,"z":-3},{"name":"Rock_Sandstone_Brick","x":-1,"y":13,"z":-3},{"name":"Rock_Sandstone_Brick","x":-1,"y":14,"z":-3},{"name":"Rock_Sandstone_Brick","x":-1,"y":6,"z":-2},{"name":"Rock_Sandstone_Brick","x":-1,"y":7,"z":-2},{"name":"Rock_Sandstone_Brick","x":-1,"y":8,"z":-2},{"name":"Rock_Sandstone_Brick","x":-1,"y":9,"z":-2},{"name":"Rock_Sandstone_Brick","x":-1,"y":10,"z":-2},{"name":"Rock_Sandstone_Brick","x":-1,"y":11,"z":-2},{"name":"Rock_Sandstone_Brick","x":-1,"y":12,"z":-2},{"name":"Rock_Sandstone_Brick","x":-1,"y":13,"z":-2},{"name":"Rock_Sandstone_Brick","x":-1,"y":14,"z":-2},{"name":"Rock_Sandstone_Brick","x":-1,"y":6,"z":-1},{"name":"Rock_Sandstone_Brick","x":-1,"y":7,"z":-1},{"name":"Rock_Sandstone_Brick","x":-1,"y":8,"z":-1},{"name":"Rock_Sandstone_Brick","x":-1,"y":9,"z":-1},{"name":"Rock_Sandstone_Brick","x":-1,"y":10,"z":-1},{"name":"Rock_Sandstone_Brick","x":-1,"y":11,"z":-1},{"name":"Rock_Sandstone_Brick","x":-1,"y":12,"z":-1},{"name":"Rock_Sandstone_Brick","x":-1,"y":13,"z":-1},{"name":"Rock_Sandstone_Brick","x":-1,"y":14,"z":-1},{"name":"Rock_Sandstone_Brick","x":-1,"y":6,"z":0},{"name":"Rock_Sandstone_Brick","x":-1,"y":7,"z":0},{"name":"Rock_Sandstone_Brick","x":-1,"y":8,"z":0},{"name":"Rock_Sandstone_Brick","x":-1,"y":9,"z":0},{"name":"Rock_Sandstone_Brick","x":-1,"y":10,"z":0},{"name":"Rock_Sandstone_Brick","x":-1,"y":11,"z":0},{"name":"Rock_Sandstone_Brick","x":-1,"y":12,"z":0},{"name":"Rock_Sandstone_Brick","x":-1,"y":13,"z":0},{"name":"Rock_Sandstone_Brick","x":-1,"y":14,"z":0},{"name":"Rock_Sandstone_Brick","x":-1,"y":15,"z":0},{"name":"Rock_Sandstone_Brick","x":-1,"y":6,"z":1},{"name":"Rock_Sandstone_Brick","x":-1,"y":7,"z":1},{"name":"Rock_Sandstone_Brick","x":-1,"y":8,"z":1},{"name":"Rock_Sandstone_Brick","x":-1,"y":9,"z":1},{"name":"Rock_Sandstone_Brick","x":-1,"y":10,"z":1},{"name":"Rock_Sandstone_Brick","x":-1,"y":11,"z":1},{"name":"Rock_Sandstone_Brick","x":-1,"y":12,"z":1},{"name":"Rock_Sandstone_Brick","x":-1,"y":13,"z":1},{"name":"Rock_Sandstone_Brick","x":-1,"y":14,"z":1},{"name":"Rock_Sandstone_Brick","x":-1,"y":15,"z":1},{"name":"Rock_Sandstone_Brick","x":-1,"y":6,"z":2},{"name":"Rock_Sandstone_Brick","x":-1,"y":7,"z":2},{"name":"Rock_Sandstone_Brick","x":-1,"y":8,"z":2},{"name":"Rock_Sandstone_Brick","x":-1,"y":9,"z":2},{"name":"Rock_Sandstone_Brick","x":-1,"y":10,"z":2},{"name":"Rock_Sandstone_Brick","x":-1,"y":11,"z":2},{"name":"Rock_Sandstone_Brick","x":-1,"y":12,"z":2},{"name":"Rock_Sandstone_Brick","x":-1,"y":13,"z":2},{"name":"Rock_Sandstone_Brick","x":-1,"y":14,"z":2},{"name":"Rock_Sandstone_Brick","x":-1,"y":15,"z":2},{"name":"Rock_Sandstone_Brick","x":-1,"y":6,"z":3},{"name":"Rock_Sandstone_Brick","x":-1,"y":7,"z":3},{"name":"Rock_Sandstone_Brick","x":-1,"y":8,"z":3},{"name":"Rock_Sandstone_Brick","x":-1,"y":9,"z":3},{"name":"Rock_Sandstone_Brick","x":-1,"y":10,"z":3},{"name":"Rock_Sandstone_Brick","x":-1,"y":11,"z":3},{"name":"Rock_Sandstone_Brick","x":-1,"y":12,"z":3},{"name":"Rock_Sandstone_Brick","x":-1,"y":13,"z":3},{"name":"Rock_Sandstone_Brick","x":-1,"y":14,"z":3},{"name":"Rock_Sandstone_Brick","x":-1,"y":6,"z":4},{"name":"Rock_Sandstone_Brick","x":-1,"y":7,"z":4},{"name":"Rock_Sandstone_Brick","x":-1,"y":8,"z":4},{"name":"Rock_Sandstone_Brick","x":-1,"y":9,"z":4},{"name":"Rock_Sandstone_Brick","x":-1,"y":10,"z":4},{"name":"Rock_Sandstone_Brick","x":-1,"y":11,"z":4},{"name":"Rock_Sandstone_Brick","x":-1,"y":12,"z":4},{"name":"Rock_Sandstone_Brick","x":-1,"y":13,"z":4},{"name":"Plant_Coral_Bush_Orange","x":-1,"y":14,"z":4},{"name":"Plant_Coral_Block_Yellow","x":-1,"y":13,"z":5},{"name":"Plant_Coral_Block_Red","x":-1,"y":13,"z":6},{"name":"Plant_Coral_Block_Red","x":0,"y":13,"z":0},{"name":"Plant_Coral_Block_Yellow","x":0,"y":13,"z":1},{"name":"Plant_Coral_Bush_Orange","x":0,"y":14,"z":1},{"name":"Plant_Coral_Block_Yellow","x":0,"y":13,"z":2},{"name":"Plant_Coral_Block_Yellow","x":0,"y":13,"z":3},{"name":"Plant_Coral_Model_Orange","x":0,"y":14,"z":3},{"name":"Plant_Coral_Block_Yellow","x":0,"y":13,"z":4},{"name":"Plant_Coral_Block_Yellow","x":0,"y":13,"z":5},{"name":"Plant_Coral_Block_Red","x":0,"y":13,"z":6},{"name":"Plant_Coral_Block_Red","x":1,"y":13,"z":0},{"name":"Plant_Coral_Block_Red","x":1,"y":13,"z":1},{"name":"Plant_Coral_Block_Yellow","x":1,"y":13,"z":2},{"name":"Plant_Coral_Block_Yellow","x":1,"y":13,"z":3},{"name":"Plant_Coral_Model_Orange","x":1,"y":14,"z":3},{"name":"Plant_Coral_Block_Yellow","x":1,"y":13,"z":4},{"name":"Plant_Coral_Model_Orange","x":1,"y":14,"z":4},{"name":"Plant_Coral_Block_Red","x":1,"y":13,"z":5},{"name":"Plant_Coral_Block_Red","x":2,"y":13,"z":2},{"name":"Plant_Coral_Block_Red","x":2,"y":13,"z":3},{"name":"Plant_Coral_Block_Red","x":2,"y":13,"z":4},{"name":"Plant_Coral_Block_Red","x":2,"y":13,"z":5}],"fluids":[{"level":1,"name":"Water_Source","x":-7,"y":6,"z":-3},{"level":1,"name":"Water_Source","x":-7,"y":7,"z":-3},{"level":1,"name":"Water_Source","x":-7,"y":8,"z":-3},{"level":1,"name":"Water_Source","x":-7,"y":9,"z":-3},{"level":1,"name":"Water_Source","x":-7,"y":10,"z":-3},{"level":1,"name":"Water_Source","x":-7,"y":11,"z":-3},{"level":1,"name":"Water_Source","x":-7,"y":6,"z":-2},{"level":1,"name":"Water_Source","x":-7,"y":7,"z":-2},{"level":1,"name":"Water_Source","x":-7,"y":8,"z":-2},{"level":1,"name":"Water_Source","x":-7,"y":9,"z":-2},{"level":1,"name":"Water_Source","x":-7,"y":10,"z":-2},{"level":1,"name":"Water_Source","x":-7,"y":11,"z":-2},{"level":1,"name":"Water_Source","x":-7,"y":12,"z":-2},{"level":1,"name":"Water_Source","x":-7,"y":13,"z":-2},{"level":1,"name":"Water_Source","x":-7,"y":6,"z":-1},{"level":1,"name":"Water_Source","x":-7,"y":7,"z":-1},{"level":1,"name":"Water_Source","x":-7,"y":8,"z":-1},{"level":1,"name":"Water_Source","x":-7,"y":9,"z":-1},{"level":1,"name":"Water_Source","x":-7,"y":10,"z":-1},{"level":1,"name":"Water_Source","x":-7,"y":11,"z":-1},{"level":1,"name":"Water_Source","x":-7,"y":12,"z":-1},{"level":1,"name":"Water_Source","x":-7,"y":13,"z":-1},{"level":1,"name":"Water_Source","x":-7,"y":14,"z":-1},{"level":1,"name":"Water_Source","x":-7,"y":6,"z":0},{"level":1,"name":"Water_Source","x":-7,"y":7,"z":0},{"level":1,"name":"Water_Source","x":-7,"y":8,"z":0},{"level":1,"name":"Water_Source","x":-7,"y":9,"z":0},{"level":1,"name":"Water_Source","x":-7,"y":10,"z":0},{"level":1,"name":"Water_Source","x":-7,"y":11,"z":0},{"level":1,"name":"Water_Source","x":-7,"y":12,"z":0},{"level":1,"name":"Water_Source","x":-7,"y":13,"z":0},{"level":1,"name":"Water_Source","x":-7,"y":14,"z":0},{"level":1,"name":"Water_Source","x":-7,"y":15,"z":0},{"level":1,"name":"Water_Source","x":-7,"y":6,"z":1},{"level":1,"name":"Water_Source","x":-7,"y":7,"z":1},{"level":1,"name":"Water_Source","x":-7,"y":8,"z":1},{"level":1,"name":"Water_Source","x":-7,"y":9,"z":1},{"level":1,"name":"Water_Source","x":-7,"y":10,"z":1},{"level":1,"name":"Water_Source","x":-7,"y":11,"z":1},{"level":1,"name":"Water_Source","x":-7,"y":12,"z":1},{"level":1,"name":"Water_Source","x":-7,"y":13,"z":1},{"level":1,"name":"Water_Source","x":-7,"y":14,"z":1},{"level":1,"name":"Water_Source","x":-7,"y":15,"z":1},{"level":1,"name":"Water_Source","x":-7,"y":6,"z":2},{"level":1,"name":"Water_Source","x":-7,"y":7,"z":2},{"level":1,"name":"Water_Source","x":-7,"y":8,"z":2},{"level":1,"name":"Water_Source","x":-7,"y":9,"z":2},{"level":1,"name":"Water_Source","x":-7,"y":10,"z":2},{"level":1,"name":"Water_Source","x":-7,"y":11,"z":2},{"level":1,"name":"Water_Source","x":-7,"y":12,"z":2},{"level":1,"name":"Water_Source","x":-7,"y":13,"z":2},{"level":1,"name":"Water_Source","x":-7,"y":14,"z":2},{"level":1,"name":"Water_Source","x":-7,"y":15,"z":2},{"level":1,"name":"Water_Source","x":-7,"y":6,"z":3},{"level":1,"name":"Water_Source","x":-7,"y":7,"z":3},{"level":1,"name":"Water_Source","x":-7,"y":8,"z":3},{"level":1,"name":"Water_Source","x":-7,"y":9,"z":3},{"level":1,"name":"Water_Source","x":-7,"y":10,"z":3},{"level":1,"name":"Water_Source","x":-7,"y":11,"z":3},{"level":1,"name":"Water_Source","x":-7,"y":12,"z":3},{"level":1,"name":"Water_Source","x":-7,"y":13,"z":3},{"level":1,"name":"Water_Source","x":-7,"y":14,"z":3},{"level":1,"name":"Water_Source","x":-7,"y":6,"z":4},{"level":1,"name":"Water_Source","x":-7,"y":7,"z":4},{"level":1,"name":"Water_Source","x":-7,"y":8,"z":4},{"level":1,"name":"Water_Source","x":-7,"y":9,"z":4},{"level":1,"name":"Water_Source","x":-7,"y":10,"z":4},{"level":1,"name":"Water_Source","x":-7,"y":11,"z":4},{"level":1,"name":"Water_Source","x":-6,"y":14,"z":-1},{"level":1,"name":"Water_Source","x":-6,"y":14,"z":0},{"level":1,"name":"Water_Source","x":-6,"y":15,"z":0},{"level":1,"name":"Water_Source","x":-6,"y":14,"z":1},{"level":1,"name":"Water_Source","x":-6,"y":15,"z":1},{"level":1,"name":"Water_Source","x":-6,"y":14,"z":2},{"level":1,"name":"Water_Source","x":-6,"y":14,"z":3},{"level":1,"name":"Water_Source","x":-6,"y":6,"z":4},{"level":1,"name":"Water_Source","x":-6,"y":7,"z":4},{"level":1,"name":"Water_Source","x":-6,"y":8,"z":4},{"level":1,"name":"Water_Source","x":-6,"y":9,"z":4},{"level":1,"name":"Water_Source","x":-6,"y":10,"z":4},{"level":1,"name":"Water_Source","x":-6,"y":11,"z":4},{"level":1,"name":"Water_Source","x":-6,"y":12,"z":4},{"level":1,"name":"Water_Source","x":-5,"y":6,"z":-1},{"level":1,"name":"Water_Source","x":-5,"y":7,"z":-1},{"level":1,"name":"Water_Source","x":-5,"y":8,"z":-1},{"level":1,"name":"Water_Source","x":-5,"y":9,"z":-1},{"level":1,"name":"Water_Source","x":-5,"y":10,"z":-1},{"level":1,"name":"Water_Source","x":-5,"y":11,"z":-1},{"level":1,"name":"Water_Source","x":-5,"y":12,"z":-1},{"level":1,"name":"Water_Source","x":-5,"y":14,"z":0},{"level":1,"name":"Water_Source","x":-5,"y":14,"z":1},{"level":1,"name":"Water_Source","x":-5,"y":14,"z":2},{"level":1,"name":"Water_Source","x":-5,"y":6,"z":4},{"level":1,"name":"Water_Source","x":-5,"y":7,"z":4},{"level":1,"name":"Water_Source","x":-5,"y":8,"z":4},{"level":1,"name":"Water_Source","x":-5,"y":9,"z":4},{"level":1,"name":"Water_Source","x":-5,"y":10,"z":4},{"level":1,"name":"Water_Source","x":-5,"y":11,"z":4},{"level":1,"name":"Water_Source","x":-5,"y":12,"z":4},{"level":1,"name":"Water_Source","x":-5,"y":13,"z":4},{"level":1,"name":"Water_Source","x":-4,"y":6,"z":-1},{"level":1,"name":"Water_Source","x":-4,"y":7,"z":-1},{"level":1,"name":"Water_Source","x":-4,"y":8,"z":-1},{"level":1,"name":"Water_Source","x":-4,"y":9,"z":-1},{"level":1,"name":"Water_Source","x":-4,"y":10,"z":-1},{"level":1,"name":"Water_Source","x":-4,"y":11,"z":-1},{"level":1,"name":"Water_Source","x":-4,"y":12,"z":-1},{"level":1,"name":"Water_Source","x":-4,"y":13,"z":-1},{"level":1,"name":"Water_Source","x":-4,"y":6,"z":4},{"level":1,"name":"Water_Source","x":-4,"y":7,"z":4},{"level":1,"name":"Water_Source","x":-4,"y":8,"z":4},{"level":1,"name":"Water_Source","x":-4,"y":9,"z":4},{"level":1,"name":"Water_Source","x":-4,"y":10,"z":4},{"level":1,"name":"Water_Source","x":-4,"y":11,"z":4},{"level":1,"name":"Water_Source","x":-4,"y":12,"z":4},{"level":1,"name":"Water_Source","x":-4,"y":13,"z":4},{"level":1,"name":"Water_Source","x":-3,"y":6,"z":-1},{"level":1,"name":"Water_Source","x":-3,"y":7,"z":-1},{"level":1,"name":"Water_Source","x":-3,"y":8,"z":-1},{"level":1,"name":"Water_Source","x":-3,"y":9,"z":-1},{"level":1,"name":"Water_Source","x":-3,"y":10,"z":-1},{"level":1,"name":"Water_Source","x":-3,"y":11,"z":-1},{"level":1,"name":"Water_Source","x":-3,"y":12,"z":-1},{"level":1,"name":"Water_Source","x":-3,"y":13,"z":-1},{"level":1,"name":"Water_Source","x":-3,"y":14,"z":-1},{"level":1,"name":"Water_Source","x":-3,"y":6,"z":4},{"level":1,"name":"Water_Source","x":-3,"y":7,"z":4},{"level":1,"name":"Water_Source","x":-3,"y":8,"z":4},{"level":1,"name":"Water_Source","x":-3,"y":9,"z":4},{"level":1,"name":"Water_Source","x":-3,"y":10,"z":4},{"level":1,"name":"Water_Source","x":-3,"y":11,"z":4},{"level":1,"name":"Water_Source","x":-3,"y":12,"z":4},{"level":1,"name":"Water_Source","x":-3,"y":13,"z":4},{"level":1,"name":"Water_Source","x":-3,"y":14,"z":4},{"level":1,"name":"Water_Source","x":-2,"y":6,"z":-1},{"level":1,"name":"Water_Source","x":-2,"y":7,"z":-1},{"level":1,"name":"Water_Source","x":-2,"y":8,"z":-1},{"level":1,"name":"Water_Source","x":-2,"y":9,"z":-1},{"level":1,"name":"Water_Source","x":-2,"y":10,"z":-1},{"level":1,"name":"Water_Source","x":-2,"y":11,"z":-1},{"level":1,"name":"Water_Source","x":-2,"y":12,"z":-1},{"level":1,"name":"Water_Source","x":-2,"y":13,"z":-1},{"level":1,"name":"Water_Source","x":-2,"y":14,"z":-1},{"level":1,"name":"Water_Source","x":-2,"y":6,"z":4},{"level":1,"name":"Water_Source","x":-2,"y":7,"z":4},{"level":1,"name":"Water_Source","x":-2,"y":8,"z":4},{"level":1,"name":"Water_Source","x":-2,"y":9,"z":4},{"level":1,"name":"Water_Source","x":-2,"y":10,"z":4},{"level":1,"name":"Water_Source","x":-2,"y":11,"z":4},{"level":1,"name":"Water_Source","x":-2,"y":12,"z":4},{"level":1,"name":"Water_Source","x":-2,"y":13,"z":4},{"level":1,"name":"Water_Source","x":-2,"y":14,"z":4},{"level":1,"name":"Water_Source","x":-2,"y":13,"z":5},{"level":1,"name":"Water_Source","x":-1,"y":6,"z":-3},{"level":1,"name":"Water_Source","x":-1,"y":7,"z":-3},{"level":1,"name":"Water_Source","x":-1,"y":8,"z":-3},{"level":1,"name":"Water_Source","x":-1,"y":9,"z":-3},{"level":1,"name":"Water_Source","x":-1,"y":10,"z":-3},{"level":1,"name":"Water_Source","x":-1,"y":11,"z":-3},{"level":1,"name":"Water_Source","x":-1,"y":12,"z":-3},{"level":1,"name":"Water_Source","x":-1,"y":13,"z":-3},{"level":1,"name":"Water_Source","x":-1,"y":14,"z":-3},{"level":1,"name":"Water_Source","x":-1,"y":6,"z":-2},{"level":1,"name":"Water_Source","x":-1,"y":7,"z":-2},{"level":1,"name":"Water_Source","x":-1,"y":8,"z":-2},{"level":1,"name":"Water_Source","x":-1,"y":9,"z":-2},{"level":1,"name":"Water_Source","x":-1,"y":10,"z":-2},{"level":1,"name":"Water_Source","x":-1,"y":11,"z":-2},{"level":1,"name":"Water_Source","x":-1,"y":12,"z":-2},{"level":1,"name":"Water_Source","x":-1,"y":13,"z":-2},{"level":1,"name":"Water_Source","x":-1,"y":14,"z":-2},{"level":1,"name":"Water_Source","x":-1,"y":6,"z":-1},{"level":1,"name":"Water_Source","x":-1,"y":7,"z":-1},{"level":1,"name":"Water_Source","x":-1,"y":8,"z":-1},{"level":1,"name":"Water_Source","x":-1,"y":9,"z":-1},{"level":1,"name":"Water_Source","x":-1,"y":10,"z":-1},{"level":1,"name":"Water_Source","x":-1,"y":11,"z":-1},{"level":1,"name":"Water_Source","x":-1,"y":12,"z":-1},{"level":1,"name":"Water_Source","x":-1,"y":13,"z":-1},{"level":1,"name":"Water_Source","x":-1,"y":14,"z":-1},{"level":1,"name":"Water_Source","x":-1,"y":6,"z":0},{"level":1,"name":"Water_Source","x":-1,"y":7,"z":0},{"level":1,"name":"Water_Source","x":-1,"y":8,"z":0},{"level":1,"name":"Water_Source","x":-1,"y":9,"z":0},{"level":1,"name":"Water_Source","x":-1,"y":10,"z":0},{"level":1,"name":"Water_Source","x":-1,"y":11,"z":0},{"level":1,"name":"Water_Source","x":-1,"y":12,"z":0},{"level":1,"name":"Water_Source","x":-1,"y":13,"z":0},{"level":1,"name":"Water_Source","x":-1,"y":14,"z":0},{"level":1,"name":"Water_Source","x":-1,"y":15,"z":0},{"level":1,"name":"Water_Source","x":-1,"y":6,"z":1},{"level":1,"name":"Water_Source","x":-1,"y":7,"z":1},{"level":1,"name":"Water_Source","x":-1,"y":8,"z":1},{"level":1,"name":"Water_Source","x":-1,"y":9,"z":1},{"level":1,"name":"Water_Source","x":-1,"y":10,"z":1},{"level":1,"name":"Water_Source","x":-1,"y":11,"z":1},{"level":1,"name":"Water_Source","x":-1,"y":12,"z":1},{"level":1,"name":"Water_Source","x":-1,"y":13,"z":1},{"level":1,"name":"Water_Source","x":-1,"y":14,"z":1},{"level":1,"name":"Water_Source","x":-1,"y":15,"z":1},{"level":1,"name":"Water_Source","x":-1,"y":6,"z":2},{"level":1,"name":"Water_Source","x":-1,"y":7,"z":2},{"level":1,"name":"Water_Source","x":-1,"y":8,"z":2},{"level":1,"name":"Water_Source","x":-1,"y":9,"z":2},{"level":1,"name":"Water_Source","x":-1,"y":10,"z":2},{"level":1,"name":"Water_Source","x":-1,"y":11,"z":2},{"level":1,"name":"Water_Source","x":-1,"y":12,"z":2},{"level":1,"name":"Water_Source","x":-1,"y":13,"z":2},{"level":1,"name":"Water_Source","x":-1,"y":14,"z":2},{"level":1,"name":"Water_Source","x":-1,"y":15,"z":2},{"level":1,"name":"Water_Source","x":-1,"y":6,"z":3},{"level":1,"name":"Water_Source","x":-1,"y":7,"z":3},{"level":1,"name":"Water_Source","x":-1,"y":8,"z":3},{"level":1,"name":"Water_Source","x":-1,"y":9,"z":3},{"level":1,"name":"Water_Source","x":-1,"y":10,"z":3},{"level":1,"name":"Water_Source","x":-1,"y":11,"z":3},{"level":1,"name":"Water_Source","x":-1,"y":12,"z":3},{"level":1,"name":"Water_Source","x":-1,"y":13,"z":3},{"level":1,"name":"Water_Source","x":-1,"y":14,"z":3},{"level":1,"name":"Water_Source","x":-1,"y":6,"z":4},{"level":1,"name":"Water_Source","x":-1,"y":7,"z":4},{"level":1,"name":"Water_Source","x":-1,"y":8,"z":4},{"level":1,"name":"Water_Source","x":-1,"y":9,"z":4},{"level":1,"name":"Water_Source","x":-1,"y":10,"z":4},{"level":1,"name":"Water_Source","x":-1,"y":11,"z":4},{"level":1,"name":"Water_Source","x":-1,"y":12,"z":4},{"level":1,"name":"Water_Source","x":-1,"y":13,"z":4},{"level":1,"name":"Water_Source","x":-1,"y":14,"z":4},{"level":1,"name":"Water_Source","x":-1,"y":13,"z":5},{"level":1,"name":"Water_Source","x":-1,"y":13,"z":6},{"level":1,"name":"Water_Source","x":0,"y":13,"z":0},{"level":1,"name":"Water_Source","x":0,"y":13,"z":1},{"level":1,"name":"Water_Source","x":0,"y":14,"z":1},{"level":1,"name":"Water_Source","x":0,"y":13,"z":2},{"level":1,"name":"Water_Source","x":0,"y":13,"z":3},{"level":1,"name":"Water_Source","x":0,"y":14,"z":3},{"level":1,"name":"Water_Source","x":0,"y":13,"z":4},{"level":1,"name":"Water_Source","x":0,"y":13,"z":5},{"level":1,"name":"Water_Source","x":0,"y":13,"z":6},{"level":1,"name":"Water_Source","x":1,"y":13,"z":0},{"level":1,"name":"Water_Source","x":1,"y":13,"z":1},{"level":1,"name":"Water_Source","x":1,"y":13,"z":2},{"level":1,"name":"Water_Source","x":1,"y":13,"z":3},{"level":1,"name":"Water_Source","x":1,"y":14,"z":3},{"level":1,"name":"Water_Source","x":1,"y":13,"z":4},{"level":1,"name":"Water_Source","x":1,"y":14,"z":4},{"level":1,"name":"Water_Source","x":1,"y":13,"z":5},{"level":1,"name":"Water_Source","x":2,"y":13,"z":2},{"level":1,"name":"Water_Source","x":2,"y":13,"z":3},{"level":1,"name":"Water_Source","x":2,"y":13,"z":4},{"level":1,"name":"Water_Source","x":2,"y":13,"z":5}],"version":8}