{
  "version": 8,
  "blockIdVersion": 11,
  "anchorX": -11,
  "anchorY": 1,
  "anchorZ": -11,
  "blocks": [
    {
      "x": -21,
      "y": 4,
      "z": -17,
      "name": "Cloth_Roof_Leather_Flap",
      "rotation": 3
    },
    {
      "x": -21,
      "y": 20,
      "z": -15,
      "name": "Cloth_Roof_Leather_Flap",
      "rotation": 3
    },
    {
      "x": -21,
      "y": 4,
      "z": -14,
      "name": "Cloth_Roof_Leather_Flap",
      "rotation": 3
    },
    {
      "x": -21,
      "y": 20,
      "z": -13,
      "name": "Cloth_Roof_Leather_Flap",
      "rotation": 3
    },
    {
      "x": -21,
      "y": 20,
      "z": -12,
      "name": "Cloth_Roof_Leather_Flap",
      "rotation": 3
    },
    {
      "x": -21,
      "y": 20,
      "z": -9,
      "name": "Cloth_Roof_Leather_Flap",
      "rotation": 3
    },
    {
      "x": -21,
      "y": 20,
      "z": -8,
      "name": "Cloth_Roof_Leather_Flap",
      "rotation": 3
    },
    {
      "x": -21,
      "y": 20,
      "z": -7,
      "name": "Cloth_Roof_Leather_Flap",
      "rotation": 3
    },
    {
      "x": -20,
      "y": 1,
      "z": -20,
      "name": "Rock_Sandstone_Red_Cobble"
    },
    {
      "x": -20,
      "y": 2,
      "z": -20,
      "name": "Rock_Sandstone_Brick"
    },
    {
      "x": -20,
      "y": 3,
      "z": -20,
      "name": "Rock_Sandstone_Brick"
    },
    {
      "x": -20,
      "y": 4,
      "z": -20,
      "name": "Rock_Sandstone_White_Brick"
    },
    {
      "x": -20,
      "y": 5,
      "z": -20,
      "name": "Rock_Sandstone_Brick"
    },
    {
      "x": -20,
      "y": 6,
      "z": -20,
      "name": "Rock_Sandstone_Red_Brick"
    },
    {
      "x": -20,
      "y": 1,
      "z": -19,
      "name": "Rock_Sandstone_Red_Cobble"
    },
    {
      "x": -20,
      "y": 2,
      "z": -19,
      "name": "Rock_Sandstone_Brick"
    },
    {
      "x": -20,
      "y": 3,
      "z": -19,
      "name": "Rock_Sandstone_Brick"
    },
    {
      "x": -20,
      "y": 4,
      "z": -19,
      "name": "Rock_Sandstone_White_Brick"
    },
    {
      "x": -20,
      "y": 5,
      "z": -19,
      "name": "Rock_Sandstone_Brick"
    },
    {
      "x": -20,
      "y": 6,
      "z": -19,
      "name": "Rock_Sandstone_Red_Brick"
    },
    {
      "x": -20,
      "y": 1,
      "z": -18,
      "name": "Rock_Sandstone_Red_Cobble"
    },
    {
      "x": -20,
      "y": 2,
      "z": -18,
      "name": "Rock_Sandstone_Brick"
    },
    {
      "x": -20,
      "y": 3,
      "z": -18,
      "name": "Rock_Sandstone_Brick"
    },
    {
      "x": -20,
      "y": 4,
      "z": -18,
      "name": "Rock_Sandstone_White_Brick"
    },
    {
      "x": -20,
      "y": 5,
      "z": -18,
      "name": "Rock_Sandstone_Brick"
    },
    {
      "x": -20,
      "y": 6,
      "z": -18,
      "name": "Rock_Sandstone_Red_Brick"
    },
    {
      "x": -20,
      "y": 1,
      "z": -17,
      "name": "Rock_Sandstone_Red_Cobble"
    },
    {
      "x": -20,
      "y": 2,
      "z": -17,
      "name": "Rock_Sandstone_Brick"
    },
    {
      "x": -20,
      "y": 3,
      "z": -17,
      "name": "Rock_Sandstone_Brick_Half"
    },
    {
      "x": -20,
      "y": 4,
      "z": -17,
      "name": "Cloth_Roof_Leather_Flap",
      "rotation": 3
    },
    {
      "x": -20,
      "y": 5,
      "z": -17,
      "name": "Rock_Sandstone_Brick"
    },
    {
      "x": -20,
      "y": 6,
      "z": -17,
      "name": "Rock_Sandstone_Red_Brick"
    },
    {
      "x": -20,
      "y": 7,
      "z": -17,
      "name": "Rock_Sandstone_Brick_Pillar_Middle"
    },
    {
      "x": -20,
      "y": 8,
      "z": -17,
      "name": "Rock_Sandstone_Brick_Pillar_Base",
      "rotation": 8
    },
    {
      "x": -20,
      "y": 9,
      "z": -17,
      "name": "Rock_Sandstone_Brick"
    },
    {
      "x": -20,
      "y": 10,
      "z": -17,
      "name": "Rock_Sandstone_Brick"
    },
    {
      "x": -20,
      "y": 11,
      "z": -17,
      "name": "Rock_Sandstone"
    },
    {
      "x": -20,
      "y": 12,
      "z": -17,
      "name": "Rock_Sandstone"
    },
    {
      "x": -20,
      "y": 13,
      "z": -17,
      "name": "Rock_Sandstone"
    },
    {
      "x": -20,
      "y": 1,
      "z": -16,
      "name": "Rock_Sandstone_Red_Cobble"
    },
    {
      "x": -20,
      "y": 2,
      "z": -16,
      "name": "Rock_Sandstone_Brick"
    },
    {
      "x": -20,
      "y": 3,
      "z": -16,
      "name": "Rock_Sandstone_Brick"
    },
    {
      "x": -20,
      "y": 4,
      "z": -16,
      "name": "Rock_Sandstone_White_Brick"
    },
    {
      "x": -20,
      "y": 5,
      "z": -16,
      "name": "Rock_Sandstone_Brick"
    },
    {
      "x": -20,
      "y": 6,
      "z": -16,
      "name": "Rock_Sandstone_Red_Brick"
    },
    {
      "x": -20,
      "y": 7,
      "z": -16,
      "name": "Rock_Sandstone_Brick"
    },
    {
      "x": -20,
      "y": 8,
      "z": -16,
      "name": "Rock_Sandstone_Brick"
    },
    {
      "x": -20,
      "y": 9,
      "z": -16,
      "name": "Rock_Sandstone_Brick"
    },
    {
      "x": -20,
      "y": 10,
      "z": -16,
      "name": "Rock_Sandstone_Brick"
    },
    {
      "x": -20,
      "y": 11,
      "z": -16,
      "name": "Rock_Sandstone"
    },
    {
      "x": -20,
      "y": 12,
      "z": -16,
      "name": "Rock_Sandstone"
    },
    {
      "x": -20,
      "y": 13,
      "z": -16,
      "name": "Rock_Sandstone"
    },
    {
      "x": -20,
      "y": 14,
      "z": -16,
      "name": "Rock_Sandstone_Red_Brick_Half",
      "rotation": 6
    },
    {
      "x": -20,
      "y": 15,
      "z": -16,
      "name": "Rock_Sandstone_Red_Brick_Half",
      "rotation": 6
    },
    {
      "x": -20,
      "y": 16,
      "z": -16,
      "name": "Rock_Sandstone_Red_Brick_Half",
      "rotation": 6
    },
    {
      "x": -20,
      "y": 1,
      "z": -15,
      "name": "Rock_Sandstone_Red_Cobble"
    },
    {
      "x": -20,
      "y": 2,
      "z": -15,
      "name": "Rock_Sandstone_Brick"
    },
    {
      "x": -20,
      "y": 3,
      "z": -15,
      "name": "Rock_Sandstone_Brick"
    },
    {
      "x": -20,
      "y": 4,
      "z": -15,
      "name": "Rock_Sandstone_White_Brick"
    },
    {
      "x": -20,
      "y": 5,
      "z": -15,
      "name": "Rock_Sandstone_Brick"
    },
    {
      "x": -20,
      "y": 6,
      "z": -15,
      "name": "Rock_Sandstone_Red_Brick"
    },
    {
      "x": -20,
      "y": 7,
      "z": -15,
      "name": "Rock_Sandstone_Brick"
    },
    {
      "x": -20,
      "y": 8,
      "z": -15,
      "name": "Rock_Sandstone_Brick"
    },
    {
      "x": -20,
      "y": 9,
      "z": -15,
      "name": "Rock_Sandstone_Brick"
    },
    {
      "x": -20,
      "y": 10,
      "z": -15,
      "name": "Rock_Sandstone_Brick"
    },
    {
      "x": -20,
      "y": 11,
      "z": -15,
      "name": "Rock_Sandstone_Brick"
    },
    {
      "x": -20,
      "y": 12,
      "z": -15,
      "name": "Rock_Sandstone_Brick"
    },
    {
      "x": -20,
      "y": 13,
      "z": -15,
      "name": "Rock_Sandstone_Brick"
    },
    {
      "x": -20,
      "y": 14,
      "z": -15,
      "name": "Rock_Sandstone_Red_Brick"
    },
    {
      "x": -20,
      "y": 15,
      "z": -15,
      "name": "Rock_Sandstone_Red_Brick"
    },
    {
      "x": -20,
      "y": 16,
      "z": -15,
      "name": "Rock_Sandstone_Red_Brick"
    },
    {
      "x": -20,
      "y": 17,
      "z": -15,
      "name": "Rock_Sandstone_Brick"
    },
    {
      "x": -20,
      "y": 18,
      "z": -15,
      "name": "Rock_Sandstone_Brick"
    },
    {
      "x": -20,
      "y": 19,
      "z": -15,
      "name": "Rock_Sandstone_Brick"
    },
    {
      "x": -20,
      "y": 20,
      "z": -15,
      "name": "Rock_Sandstone_Brick"
    },
    {
      "x": -20,
      "y": 21,
      "z": -15,
      "name": "Rock_Sandstone_Brick"
    },
    {
      "x": -20,
      "y": 22,
      "z": -15,
      "name": "Rock_Sandstone_Brick"
    },
    {
      "x": -20,
      "y": 23,
      "z": -15,
      "name": "Rock_Gold_Brick_Smooth"
    },
    {
      "x": -20,
      "y": 24,
      "z": -15,
      "name": "Rock_Sandstone_Brick"
    },
    {
      "x": -20,
      "y": 25,
      "z": -15,
      "name": "Soil_Clay_Ocean_Brick_Ornate"
    },
    {
      "x": -20,
      "y": 26,
      "z": -15,
      "name": "Soil_Clay_Ocean_Brick_Ornate"
    },
    {
      "x": -20,
      "y": 27,
      "z": -15,
      "name": "Rock_Sandstone_Brick"
    },
    {
      "x": -20,
      "y": 28,
      "z": -15,
      "name": "Rock_Sandstone_Brick"
    },
    {
      "x": -20,
      "y": 29,
      "z": -15,
      "name": "Rock_Sandstone_Brick"
    },
    {
      "x": -20,
      "y": 1,
      "z": -14,
      "name": "Rock_Sandstone_Red_Cobble"
    },
    {
      "x": -20,
      "y": 2,
      "z": -14,
      "name": "Rock_Sandstone_Brick"
    },
    {
      "x": -20,
      "y": 3,
      "z": -14,
      "name": "Rock_Sandstone_Brick_Half"
    },
    {
      "x": -20,
      "y": 4,
      "z": -14,
      "name": "Cloth_Roof_Leather_Flap",
      "rotation": 3
    },
    {
      "x": -20,
      "y": 5,
      "z": -14,
      "name": "Rock_Sandstone_Brick"
    },
    {
      "x": -20,
      "y": 6,
      "z": -14,
      "name": "Rock_Sandstone_Red_Brick"
    },
    {
      "x": -20,
      "y": 8,
      "z": -14,
      "name": "Rock_Sandstone_Brick"
    },
    {
      "x": -20,
      "y": 9,
      "z": -14,
      "name": "Rock_Sandstone_Brick"
    },
    {
      "x": -20,
      "y": 10,
      "z": -14,
      "name": "Rock_Sandstone_Brick"
    },
    {
      "x": -20,
      "y": 11,
      "z": -14,
      "name": "Rock_Sandstone_Brick"
    },
    {
      "x": -20,
      "y": 12,
      "z": -14,
      "name": "Rock_Sandstone_Brick"
    },
    {
      "x": -20,
      "y": 13,
      "z": -14,
      "name": "Rock_Sandstone_Brick"
    },
    {
      "x": -20,
      "y": 14,
      "z": -14,
      "name": "Rock_Sandstone_Red_Brick"
    },
    {
      "x": -20,
      "y": 15,
      "z": -14,
      "name": "Rock_Sandstone_Red_Brick"
    },
    {
      "x": -20,
      "y": 16,
      "z": -14,
      "name": "Rock_Gold_Brick_Decorative"
    },
    {
      "x": -20,
      "y": 17,
      "z": -14,
      "name": "Rock_Sandstone_Brick"
    },
    {
      "x": -20,
      "y": 18,
      "z": -14,
      "name": "Rock_Sandstone_Brick"
    },
    {
      "x": -20,
      "y": 19,
      "z": -14,
      "name": "Rock_Sandstone_Brick"
    },
    {
      "x": -20,
      "y": 20,
      "z": -14,
      "name": "Rock_Sandstone_Brick"
    },
    {
      "x": -20,
      "y": 21,
      "z": -14,
      "name": "Rock_Sandstone_Brick"
    },
    {
      "x": -20,
      "y": 22,
      "z": -14,
      "name": "Rock_Sandstone_Brick"
    },
    {
      "x": -20,
      "y": 23,
      "z": -14,
      "name": "Rock_Gold_Brick_Smooth"
    },
    {
      "x": -20,
      "y": 24,
      "z": -14,
      "name": "Rock_Sandstone_Brick"
    },
    {
      "x": -20,
      "y": 25,
      "z": -14,
      "name": "Soil_Clay_Ocean_Brick_Ornate"
    },
    {
      "x": -20,
      "y": 26,
      "z": -14,
      "name": "Soil_Clay_Ocean_Brick_Ornate"
    },
    {
      "x": -20,
      "y": 27,
      "z": -14,
      "name": "Rock_Sandstone_Brick"
    },
    {
      "x": -20,
      "y": 28,
      "z": -14,
      "name": "Rock_Sandstone_Brick"
    },
    {
      "x": -20,
      "y": 29,
      "z": -14,
      "name": "Rock_Sandstone_Brick"
    },
    {
      "x": -20,
      "y": 1,
      "z": -13,
      "name": "Rock_Sandstone_Red_Cobble"
    },
    {
      "x": -20,
      "y": 2,
      "z": -13,
      "name": "Rock_Sandstone_Brick"
    },
    {
      "x": -20,
      "y": 3,
      "z": -13,
      "name": "Rock_Sandstone_Brick"
    },
    {
      "x": -20,
      "y": 4,
      "z": -13,
      "name": "Rock_Sandstone_White_Brick"
    },
    {
      "x": -20,
      "y": 5,
      "z": -13,
      "name": "Rock_Sandstone_Brick"
    },
    {
      "x": -20,
      "y": 6,
      "z": -13,
      "name": "Rock_Sandstone_Red_Brick"
    },
    {
      "x": -20,
      "y": 8,
      "z": -13,
      "name": "Rock_Sandstone_Brick"
    },
    {
      "x": -20,
      "y": 9,
      "z": -13,
      "name": "Rock_Sandstone_Brick"
    },
    {
      "x": -20,
      "y": 10,
      "z": -13,
      "name": "Rock_Sandstone_Brick"
    },
    {
      "x": -20,
      "y": 11,
      "z": -13,
      "name": "Rock_Sandstone_Brick"
    },
    {
      "x": -20,
      "y": 12,
      "z": -13,
      "name": "Rock_Sandstone_Brick"
    },
    {
      "x": -20,
      "y": 13,
      "z": -13,
      "name": "Rock_Sandstone_Brick"
    },
    {
      "x": -20,
      "y": 14,
      "z": -13,
      "name": "Rock_Sandstone_Red_Brick"
    },
    {
      "x": -20,
      "y": 15,
      "z": -13,
      "name": "Rock_Sandstone_Red_Brick"
    },
    {
      "x": -20,
      "y": 16,
      "z": -13,
      "name": "Rock_Sandstone_Red_Brick"
    },
    {
      "x": -20,
      "y": 17,
      "z": -13,
      "name": "Rock_Sandstone_Brick"
    },
    {
      "x": -20,
      "y": 18,
      "z": -13,
      "name": "Rock_Sandstone_Brick"
    },
    {
      "x": -20,
      "y": 19,
      "z": -13,
      "name": "Rock_Sandstone_Brick"
    },
    {
      "x": -20,
      "y": 20,
      "z": -13,
      "name": "Rock_Sandstone_Brick"
    },
    {
      "x": -20,
      "y": 21,
      "z": -13,
      "name": "Rock_Sandstone_Brick"
    },
    {
      "x": -20,
      "y": 22,
      "z": -13,
      "name": "Rock_Sandstone_Brick"
    },
    {
      "x": -20,
      "y": 23,
      "z": -13,
      "name": "Rock_Gold_Brick_Smooth"
    },
    {
      "x": -20,
      "y": 24,
      "z": -13,
      "name": "Rock_Sandstone_Brick"
    },
    {
      "x": -20,
      "y": 25,
      "z": -13,
      "name": "Soil_Clay_Ocean_Brick_Ornate"
    },
    {
      "x": -20,
      "y": 26,
      "z": -13,
      "name": "Soil_Clay_Ocean_Brick_Ornate"
    },
    {
      "x": -20,
      "y": 27,
      "z": -13,
      "name": "Rock_Sandstone_Brick"
    },
    {
      "x": -20,
      "y": 28,
      "z": -13,
      "name": "Rock_Sandstone_Brick"
    },
    {
      "x": -20,
      "y": 29,
      "z": -13,
      "name": "Rock_Sandstone_Brick"
    },
    {
      "x": -20,
      "y": 1,
      "z": -12,
      "name": "Rock_Sandstone_Red_Cobble"
    },
    {
      "x": -20,
      "y": 2,
      "z": -12,
      "name": "Rock_Sandstone_Brick"
    },
    {
      "x": -20,
      "y": 3,
      "z": -12,
      "name": "Rock_Sandstone_Brick"
    },
    {
      "x": -20,
      "y": 4,
      "z": -12,
      "name": "Rock_Sandstone_White_Brick"
    },
    {
      "x": -20,
      "y": 5,
      "z": -12,
      "name": "Rock_Sandstone_Brick"
    },
    {
      "x": -20,
      "y": 6,
      "z": -12,
      "name": "Rock_Sandstone_Red_Brick"
    },
    {
      "x": -20,
      "y": 8,
      "z": -12,
      "name": "Rock_Sandstone_Brick"
    },
    {
      "x": -20,
      "y": 9,
      "z": -12,
      "name": "Rock_Sandstone_Brick"
    },
    {
      "x": -20,
      "y": 10,
      "z": -12,
      "name": "Rock_Sandstone_Brick"
    },
    {
      "x": -20,
      "y": 11,
      "z": -12,
      "name": "Rock_Sandstone_Brick"
    },
    {
      "x": -20,
      "y": 12,
      "z": -12,
      "name": "Rock_Sandstone_Brick"
    },
    {
      "x": -20,
      "y": 13,
      "z": -12,
      "name": "Rock_Sandstone_Brick"
    },
    {
      "x": -20,
      "y": 14,
      "z": -12,
      "name": "Rock_Sandstone_Red_Brick"
    },
    {
      "x": -20,
      "y": 15,
      "z": -12,
      "name": "Rock_Sandstone_Red_Brick"
    },
    {
      "x": -20,
      "y": 16,
      "z": -12,
      "name": "Rock_Gold_Brick_Decorative"
    },
    {
      "x": -20,
      "y": 17,
      "z": -12,
      "name": "Rock_Sandstone_Brick",
      "support": 15
    },
    {
      "x": -20,
      "y": 18,
      "z": -12,
      "name": "Rock_Sandstone_Brick"
    },
    {
      "x": -20,
      "y": 19,
      "z": -12,
      "name": "Rock_Sandstone_Brick"
    },
    {
      "x": -20,
      "y": 20,
      "z": -12,
      "name": "Rock_Sandstone_Brick"
    },
    {
      "x": -20,
      "y": 21,
      "z": -12,
      "name": "Rock_Sandstone_Brick"
    },
    {
      "x": -20,
      "y": 22,
      "z": -12,
      "name": "Rock_Sandstone_Brick"
    },
    {
      "x": -20,
      "y": 23,
      "z": -12,
      "name": "Rock_Gold_Brick_Smooth"
    },
    {
      "x": -20,
      "y": 24,
      "z": -12,
      "name": "Rock_Sandstone_Brick"
    },
    {
      "x": -20,
      "y": 25,
      "z": -12,
      "name": "Soil_Clay_Ocean_Brick_Ornate"
    },
    {
      "x": -20,
      "y": 26,
      "z": -12,
      "name": "Soil_Clay_Ocean_Brick_Ornate"
    },
    {
      "x": -20,
      "y": 27,
      "z": -12,
      "name": "Rock_Sandstone_Brick"
    },
    {
      "x": -20,
      "y": 28,
      "z": -12,
      "name": "Rock_Sandstone_Brick"
    },
    {
      "x": -20,
      "y": 29,
      "z": -12,
      "name": "Rock_Sandstone_Brick"
    },
    {
      "x": -20,
      "y": 1,
      "z": -11,
      "name": "Rock_Sandstone_Red_Cobble"
    },
    {
      "x": -20,
      "y": 2,
      "z": -11,
      "name": "Rock_Sandstone_Brick"
    },
    {
      "x": -20,
      "y": 3,
      "z": -11,
      "name": "Rock_Sandstone_Brick"
    },
    {
      "x": -20,
      "y": 4,
      "z": -11,
      "name": "Rock_Sandstone_White_Brick"
    },
    {
      "x": -20,
      "y": 5,
      "z": -11,
      "name": "Rock_Sandstone_Brick"
    },
    {
      "x": -20,
      "y": 6,
      "z": -11,
      "name": "Rock_Sandstone_Red_Brick"
    },
    {
      "x": -20,
      "y": 11,
      "z": -11,
      "name": "Rock_Sandstone_Brick"
    },
    {
      "x": -20,
      "y": 12,
      "z": -11,
      "name": "Rock_Sandstone_Brick"
    },
    {
      "x": -20,
      "y": 13,
      "z": -11,
      "name": "Rock_Sandstone_Brick"
    },
    {
      "x": -20,
      "y": 14,
      "z": -11,
      "name": "Rock_Sandstone_Red_Brick"
    },
    {
      "x": -20,
      "y": 15,
      "z": -11,
      "name": "Rock_Sandstone_Red_Brick"
    },
    {
      "x": -20,
      "y": 16,
      "z": -11,
      "name": "Rock_Sandstone_Red_Brick"
    },
    {
      "x": -20,
      "y": 17,
      "z": -11,
      "name": "Rock_Sandstone_Brick"
    },
    {
      "x": -20,
      "y": 18,
      "z": -11,
      "name": "Rock_Sandstone_Brick"
    },
    {
      "x": -20,
      "y": 19,
      "z": -11,
      "name": "Rock_Sandstone_Brick"
    },
    {
      "x": -20,
      "y": 20,
      "z": -11,
      "name": "Rock_Sandstone_Brick"
    },
    {
      "x": -20,
      "y": 21,
      "z": -11,
      "name": "Rock_Sandstone_Brick"
    },
    {
      "x": -20,
      "y": 22,
      "z": -11,
      "name": "Rock_Sandstone_Brick"
    },
    {
      "x": -20,
      "y": 23,
      "z": -11,
      "name": "Rock_Gold_Brick_Smooth"
    },
    {
      "x": -20,
      "y": 24,
      "z": -11,
      "name": "Rock_Sandstone_Brick"
    },
    {
      "x": -20,
      "y": 25,
      "z": -11,
      "name": "Soil_Clay_Ocean_Brick_Ornate"
    },
    {
      "x": -20,
      "y": 26,
      "z": -11,
      "name": "Soil_Clay_Ocean_Brick_Ornate"
    },
    {
      "x": -20,
      "y": 27,
      "z": -11,
      "name": "Rock_Sandstone_Brick"
    },
    {
      "x": -20,
      "y": 28,
      "z": -11,
      "name": "Rock_Sandstone_Brick"
    },
    {
      "x": -20,
      "y": 29,
      "z": -11,
      "name": "Rock_Sandstone_Brick"
    },
    {
      "x": -20,
      "y": 1,
      "z": -10,
      "name": "Rock_Sandstone_Red_Cobble"
    },
    {
      "x": -20,
      "y": 2,
      "z": -10,
      "name": "Rock_Sandstone_Brick"
    },
    {
      "x": -20,
      "y": 3,
      "z": -10,
      "name": "Rock_Sandstone_Brick"
    },
    {
      "x": -20,
      "y": 4,
      "z": -10,
      "name": "Rock_Sandstone_White_Brick"
    },
    {
      "x": -20,
      "y": 5,
      "z": -10,
      "name": "Rock_Sandstone_Brick"
    },
    {
      "x": -20,
      "y": 6,
      "z": -10,
      "name": "Rock_Sandstone_Red_Brick"
    },
    {
      "x": -20,
      "y": 11,
      "z": -10,
      "name": "Rock_Sandstone_Brick"
    },
    {
      "x": -20,
      "y": 12,
      "z": -10,
      "name": "Rock_Sandstone_Brick"
    },
    {
      "x": -20,
      "y": 13,
      "z": -10,
      "name": "Rock_Sandstone_Brick"
    },
    {
      "x": -20,
      "y": 14,
      "z": -10,
      "name": "Rock_Sandstone_Red_Brick"
    },
    {
      "x": -20,
      "y": 15,
      "z": -10,
      "name": "Rock_Sandstone_Red_Brick"
    },
    {
      "x": -20,
      "y": 16,
      "z": -10,
      "name": "Rock_Gold_Brick_Decorative"
    },
    {
      "x": -20,
      "y": 17,
      "z": -10,
      "name": "Rock_Sandstone_Brick"
    },
    {
      "x": -20,
      "y": 18,
      "z": -10,
      "name": "Rock_Sandstone_Brick"
    },
    {
      "x": -20,
      "y": 19,
      "z": -10,
      "name": "Rock_Sandstone_Brick"
    },
    {
      "x": -20,
      "y": 20,
      "z": -10,
      "name": "Rock_Sandstone_Brick"
    },
    {
      "x": -20,
      "y": 21,
      "z": -10,
      "name": "Rock_Sandstone_Brick"
    },
    {
      "x": -20,
      "y": 22,
      "z": -10,
      "name": "Rock_Sandstone_Brick"
    },
    {
      "x": -20,
      "y": 23,
      "z": -10,
      "name": "Rock_Gold_Brick_Smooth"
    },
    {
      "x": -20,
      "y": 24,
      "z": -10,
      "name": "Rock_Sandstone_Brick"
    },
    {
      "x": -20,
      "y": 25,
      "z": -10,
      "name": "Soil_Clay_Ocean_Brick_Ornate"
    },
    {
      "x": -20,
      "y": 26,
      "z": -10,
      "name": "Soil_Clay_Ocean_Brick_Ornate"
    },
    {
      "x": -20,
      "y": 27,
      "z": -10,
      "name": "Rock_Sandstone_Brick"
    },
    {
      "x": -20,
      "y": 28,
      "z": -10,
      "name": "Rock_Sandstone_Brick"
    },
    {
      "x": -20,
      "y": 29,
      "z": -10,
      "name": "Rock_Sandstone_Brick"
    },
    {
      "x": -20,
      "y": 1,
      "z": -9,
      "name": "Rock_Sandstone_Red_Cobble"
    },
    {
      "x": -20,
      "y": 2,
      "z": -9,
      "name": "Rock_Sandstone_Brick"
    },
    {
      "x": -20,
      "y": 3,
      "z": -9,
      "name": "Rock_Sandstone_Brick"
    },
    {
      "x": -20,
      "y": 4,
      "z": -9,
      "name": "Rock_Sandstone_White_Brick"
    },
    {
      "x": -20,
      "y": 5,
      "z": -9,
      "name": "Rock_Sandstone_Brick"
    },
    {
      "x": -20,
      "y": 6,
      "z": -9,
      "name": "Rock_Sandstone_Red_Brick"
    },
    {
      "x": -20,
      "y": 10,
      "z": -9,
      "name": "Rock_Sandstone_Brick"
    },
    {
      "x": -20,
      "y": 11,
      "z": -9,
      "name": "Rock_Sandstone_Brick"
    },
    {
      "x": -20,
      "y": 12,
      "z": -9,
      "name": "Rock_Sandstone_Brick"
    },
    {
      "x": -20,
      "y": 13,
      "z": -9,
      "name": "Rock_Sandstone_Brick"
    },
    {
      "x": -20,
      "y": 14,
      "z": -9,
      "name": "Rock_Sandstone_Red_Brick"
    },
    {
      "x": -20,
      "y": 15,
      "z": -9,
      "name": "Rock_Sandstone_Red_Brick"
    },
    {
      "x": -20,
      "y": 16,
      "z": -9,
      "name": "Rock_Sandstone_Red_Brick"
    },
    {
      "x": -20,
      "y": 17,
      "z": -9,
      "name": "Rock_Sandstone_Brick"
    },
    {
      "x": -20,
      "y": 18,
      "z": -9,
      "name": "Rock_Sandstone_Brick"
    },
    {
      "x": -20,
      "y": 19,
      "z": -9,
      "name": "Rock_Sandstone_Brick"
    },
    {
      "x": -20,
      "y": 20,
      "z": -9,
      "name": "Rock_Sandstone_Brick"
    },
    {
      "x": -20,
      "y": 21,
      "z": -9,
      "name": "Rock_Sandstone_Brick"
    },
    {
      "x": -20,
      "y": 22,
      "z": -9,
      "name": "Rock_Sandstone_Brick"
    },
    {
      "x": -20,
      "y": 23,
      "z": -9,
      "name": "Rock_Gold_Brick_Smooth"
    },
    {
      "x": -20,
      "y": 24,
      "z": -9,
      "name": "Rock_Sandstone_Brick"
    },
    {
      "x": -20,
      "y": 25,
      "z": -9,
      "name": "Soil_Clay_Ocean_Brick_Ornate"
    },
    {
      "x": -20,
      "y": 26,
      "z": -9,
      "name": "Soil_Clay_Ocean_Brick_Ornate"
    },
    {
      "x": -20,
      "y": 27,
      "z": -9,
      "name": "Rock_Sandstone_Brick"
    },
    {
      "x": -20,
      "y": 28,
      "z": -9,
      "name": "Rock_Sandstone_Brick"
    },
    {
      "x": -20,
      "y": 29,
      "z": -9,
      "name": "Rock_Sandstone_Brick"
    },
    {
      "x": -20,
      "y": 1,
      "z": -8,
      "name": "Rock_Sandstone_Red_Cobble"
    },
    {
      "x": -20,
      "y": 2,
      "z": -8,
      "name": "Rock_Sandstone_Brick"
    },
    {
      "x": -20,
      "y": 3,
      "z": -8,
      "name": "Rock_Sandstone_Brick_Half"
    },
    {
      "x": -20,
      "y": 4,
      "z": -8,
      "name": "Cloth_Roof_Leather_Flap",
      "rotation": 1
    },
    {
      "x": -20,
      "y": 5,
      "z": -8,
      "name": "Rock_Sandstone_Brick"
    },
    {
      "x": -20,
      "y": 6,
      "z": -8,
      "name": "Rock_Sandstone_Red_Brick"
    },
    {
      "x": -20,
      "y": 7,
      "z": -8,
      "name": "Rock_Sandstone_Brick"
    },
    {
      "x": -20,
      "y": 8,
      "z": -8,
      "name": "Rock_Sandstone_Brick"
    },
    {
      "x": -20,
      "y": 9,
      "z": -8,
      "name": "Rock_Sandstone_Brick"
    },
    {
      "x": -20,
      "y": 10,
      "z": -8,
      "name": "Rock_Sandstone_Brick"
    },
    {
      "x": -20,
      "y": 11,
      "z": -8,
      "name": "Rock_Sandstone_Brick"
    },
    {
      "x": -20,
      "y": 12,
      "z": -8,
      "name": "Rock_Sandstone_Brick"
    },
    {
      "x": -20,
      "y": 13,
      "z": -8,
      "name": "Rock_Sandstone_Brick"
    },
    {
      "x": -20,
      "y": 14,
      "z": -8,
      "name": "Rock_Sandstone_Red_Brick"
    },
    {
      "x": -20,
      "y": 15,
      "z": -8,
      "name": "Rock_Sandstone_Red_Brick"
    },
    {
      "x": -20,
      "y": 16,
      "z": -8,
      "name": "Rock_Gold_Brick_Decorative"
    },
    {
      "x": -20,
      "y": 17,
      "z": -8,
      "name": "Rock_Sandstone_Brick"
    },
    {
      "x": -20,
      "y": 18,
      "z": -8,
      "name": "Rock_Sandstone_Brick"
    },
    {
      "x": -20,
      "y": 19,
      "z": -8,
      "name": "Rock_Sandstone_Brick"
    },
    {
      "x": -20,
      "y": 20,
      "z": -8,
      "name": "Rock_Sandstone_Brick"
    },
    {
      "x": -20,
      "y": 21,
      "z": -8,
      "name": "Rock_Sandstone_Brick"
    },
    {
      "x": -20,
      "y": 22,
      "z": -8,
      "name": "Rock_Sandstone_Brick"
    },
    {
      "x": -20,
      "y": 23,
      "z": -8,
      "name": "Rock_Gold_Brick_Smooth"
    },
    {
      "x": -20,
      "y": 24,
      "z": -8,
      "name": "Rock_Sandstone_Brick"
    },
    {
      "x": -20,
      "y": 25,
      "z": -8,
      "name": "Soil_Clay_Ocean_Brick_Ornate"
    },
    {
      "x": -20,
      "y": 26,
      "z": -8,
      "name": "Soil_Clay_Ocean_Brick_Ornate"
    },
    {
      "x": -20,
      "y": 27,
      "z": -8,
      "name": "Rock_Sandstone_Brick"
    },
    {
      "x": -20,
      "y": 28,
      "z": -8,
      "name": "Rock_Sandstone_Brick"
    },
    {
      "x": -20,
      "y": 29,
      "z": -8,
      "name": "Rock_Sandstone_Brick"
    },
    {
      "x": -20,
      "y": 1,
      "z": -7,
      "name": "Rock_Sandstone_Red_Cobble"
    },
    {
      "x": -20,
      "y": 2,
      "z": -7,
      "name": "Rock_Sandstone_Brick"
    },
    {
      "x": -20,
      "y": 3,
      "z": -7,
      "name": "Rock_Sandstone_Brick"
    },
    {
      "x": -20,
      "y": 4,
      "z": -7,
      "name": "Rock_Sandstone_White_Brick"
    },
    {
      "x": -20,
      "y": 5,
      "z": -7,
      "name": "Rock_Sandstone_Brick"
    },
    {
      "x": -20,
      "y": 6,
      "z": -7,
      "name": "Rock_Sandstone_Red_Brick"
    },
    {
      "x": -20,
      "y": 7,
      "z": -7,
      "name": "Rock_Sandstone_Brick"
    },
    {
      "x": -20,
      "y": 8,
      "z": -7,
      "name": "Rock_Sandstone_Brick"
    },
    {
      "x": -20,
      "y": 9,
      "z": -7,
      "name": "Rock_Sandstone_Brick"
    },
    {
      "x": -20,
      "y": 10,
      "z": -7,
      "name": "Rock_Sandstone_Brick"
    },
    {
      "x": -20,
      "y": 11,
      "z": -7,
      "name": "Rock_Sandstone_Brick"
    },
    {
      "x": -20,
      "y": 12,
      "z": -7,
      "name": "Rock_Sandstone_Brick"
    },
    {
      "x": -20,
      "y": 13,
      "z": -7,
      "name": "Rock_Sandstone_Brick"
    },
    {
      "x": -20,
      "y": 14,
      "z": -7,
      "name": "Rock_Sandstone_Red_Brick"
    },
    {
      "x": -20,
      "y": 15,
      "z": -7,
      "name": "Rock_Sandstone_Red_Brick"
    },
    {
      "x": -20,
      "y": 16,
      "z": -7,
      "name": "Rock_Sandstone_Red_Brick"
    },
    {
      "x": -20,
      "y": 17,
      "z": -7,
      "name": "Rock_Sandstone_Brick",
      "support": 15
    },
    {
      "x": -20,
      "y": 18,
      "z": -7,
      "name": "Rock_Sandstone_Brick"
    },
    {
      "x": -20,
      "y": 19,
      "z": -7,
      "name": "Rock_Sandstone_Brick"
    },
    {
      "x": -20,
      "y": 20,
      "z": -7,
      "name": "Rock_Sandstone_Brick"
    },
    {
      "x": -20,
      "y": 21,
      "z": -7,
      "name": "Rock_Sandstone_Brick"
    },
    {
      "x": -20,
      "y": 22,
      "z": -7,
      "name": "Rock_Sandstone_Brick"
    },
    {
      "x": -20,
      "y": 23,
      "z": -7,
      "name": "Rock_Gold_Brick_Smooth"
    },
    {
      "x": -20,
      "y": 24,
      "z": -7,
      "name": "Rock_Sandstone_Brick"
    },
    {
      "x": -20,
      "y": 25,
      "z": -7,
      "name": "Soil_Clay_Ocean_Brick_Ornate"
    },
    {
      "x": -20,
      "y": 26,
      "z": -7,
      "name": "Soil_Clay_Ocean_Brick_Ornate"
    },
    {
      "x": -20,
      "y": 27,
      "z": -7,
      "name": "Rock_Sandstone_Brick"
    },
    {
      "x": -20,
      "y": 28,
      "z": -7,
      "name": "Rock_Sandstone_Brick"
    },
    {
      "x": -20,
      "y": 29,
      "z": -7,
      "name": "Rock_Sandstone_Brick"
    },
    {
      "x": -20,
      "y": 1,
      "z": -6,
      "name": "Rock_Sandstone_Red_Cobble"
    },
    {
      "x": -20,
      "y": 2,
      "z": -6,
      "name": "Rock_Sandstone_Brick"
    },
    {
      "x": -20,
      "y": 3,
      "z": -6,
      "name": "Rock_Sandstone_Brick"
    },
    {
      "x": -20,
      "y": 4,
      "z": -6,
      "name": "Rock_Sandstone_White_Brick"
    },
    {
      "x": -20,
      "y": 5,
      "z": -6,
      "name": "Rock_Sandstone_Brick"
    },
    {
      "x": -20,
      "y": 6,
      "z": -6,
      "name": "Rock_Sandstone_Red_Brick"
    },
    {
      "x": -20,
      "y": 7,
      "z": -6,
      "name": "Rock_Sandstone_Brick"
    },
    {
      "x": -20,
      "y": 8,
      "z": -6,
      "name": "Rock_Sandstone_Brick_Stairs",
      "rotation": 10
    },
    {
      "x": -20,
      "y": 9,
      "z": -6,
      "name": "Rock_Sandstone_Brick"
    },
    {
      "x": -20,
      "y": 10,
      "z": -6,
      "name": "Rock_Sandstone_Brick"
    },
    {
      "x": -20,
      "y": 11,
      "z": -6,
      "name": "Rock_Sandstone_Brick"
    },
    {
      "x": -20,
      "y": 12,
      "z": -6,
      "name": "Rock_Sandstone_Brick"
    },
    {
      "x": -20,
      "y": 13,
      "z": -6,
      "name": "Rock_Sandstone_Brick"
    },
    {
      "x": -20,
      "y": 14,
      "z": -6,
      "name": "Rock_Sandstone_Red_Brick"
    },
    {
      "x": -20,
      "y": 15,
      "z": -6,
      "name": "Rock_Sandstone_Red_Brick"
    },
    {
      "x": -20,
      "y": 16,
      "z": -6,
      "name": "Rock_Gold_Brick_Decorative"
    },
    {
      "x": -20,
      "y": 17,
      "z": -6,
      "name": "Rock_Sandstone_Brick"
    },
    {
      "x": -20,
      "y": 18,
      "z": -6,
      "name": "Rock_Sandstone_Brick"
    },
    {
      "x": -20,
      "y": 1,
      "z": -5,
      "name": "Rock_Sandstone_Red_Cobble"
    },
    {
      "x": -20,
      "y": 2,
      "z": -5,
      "name": "Rock_Sandstone_Brick"
    },
    {
      "x": -20,
      "y": 3,
      "z": -5,
      "name": "Rock_Sandstone_Brick_Half"
    },
    {
      "x": -20,
      "y": 4,
      "z": -5,
      "name": "Cloth_Roof_Leather_Flap",
      "rotation": 1
    },
    {
      "x": -20,
      "y": 5,
      "z": -5,
      "name": "Rock_Sandstone_Brick"
    },
    {
      "x": -20,
      "y": 6,
      "z": -5,
      "name": "Rock_Sandstone_Red_Brick"
    },
    {
      "x": -20,
      "y": 7,
      "z": -5,
      "name": "Rock_Sandstone_Brick"
    },
    {
      "x": -20,
      "y": 9,
      "z": -5,
      "name": "Rock_Sandstone_Brick"
    },
    {
      "x": -20,
      "y": 10,
      "z": -5,
      "name": "Rock_Sandstone_Brick"
    },
    {
      "x": -20,
      "y": 11,
      "z": -5,
      "name": "Rock_Sandstone_Brick"
    },
    {
      "x": -20,
      "y": 12,
      "z": -5,
      "name": "Rock_Sandstone_Brick"
    },
    {
      "x": -20,
      "y": 13,
      "z": -5,
      "name": "Rock_Sandstone_Brick"
    },
    {
      "x": -20,
      "y": 14,
      "z": -5,
      "name": "Rock_Sandstone_Red_Brick"
    },
    {
      "x": -20,
      "y": 15,
      "z": -5,
      "name": "Rock_Sandstone_Red_Brick"
    },
    {
      "x": -20,
      "y": 16,
      "z": -5,
      "name": "Rock_Sandstone_Red_Brick"
    },
    {
      "x": -20,
      "y": 17,
      "z": -5,
      "name": "Rock_Sandstone_Brick"
    },
    {
      "x": -20,
      "y": 18,
      "z": -5,
      "name": "Rock_Sandstone_Brick"
    },
    {
      "x": -20,
      "y": 1,
      "z": -4,
      "name": "Rock_Sandstone_Red_Cobble"
    },
    {
      "x": -20,
      "y": 2,
      "z": -4,
      "name": "Rock_Sandstone_Brick"
    },
    {
      "x": -20,
      "y": 3,
      "z": -4,
      "name": "Rock_Sandstone_Brick"
    },
    {
      "x": -20,
      "y": 4,
      "z": -4,
      "name": "Rock_Sandstone_White_Brick"
    },
    {
      "x": -20,
      "y": 5,
      "z": -4,
      "name": "Rock_Sandstone_Brick"
    },
    {
      "x": -20,
      "y": 6,
      "z": -4,
      "name": "Rock_Sandstone_Red_Brick"
    },
    {
      "x": -20,
      "y": 7,
      "z": -4,
      "name": "Rock_Sandstone_Brick"
    },
    {
      "x": -20,
      "y": 8,
      "z": -4,
      "name": "Rock_Sandstone_Brick_Stairs",
      "rotation": 8
    },
    {
      "x": -20,
      "y": 9,
      "z": -4,
      "name": "Rock_Sandstone_Brick"
    },
    {
      "x": -20,
      "y": 10,
      "z": -4,
      "name": "Rock_Sandstone_Brick"
    },
    {
      "x": -20,
      "y": 11,
      "z": -4,
      "name": "Rock_Sandstone_Brick"
    },
    {
      "x": -20,
      "y": 12,
      "z": -4,
      "name": "Rock_Sandstone_Brick"
    },
    {
      "x": -20,
      "y": 13,
      "z": -4,
      "name": "Rock_Sandstone_Brick"
    },
    {
      "x": -20,
      "y": 14,
      "z": -4,
      "name": "Rock_Sandstone_Red_Brick"
    },
    {
      "x": -20,
      "y": 15,
      "z": -4,
      "name": "Rock_Sandstone_Red_Brick"
    },
    {
      "x": -20,
      "y": 16,
      "z": -4,
      "name": "Rock_Gold_Brick_Decorative"
    },
    {
      "x": -20,
      "y": 17,
      "z": -4,
      "name": "Rock_Sandstone_Brick"
    },
    {
      "x": -20,
      "y": 18,
      "z": -4,
      "name": "Rock_Sandstone_Brick"
    },
    {
      "x": -20,
      "y": 1,
      "z": -3,
      "name": "Rock_Sandstone_Red_Cobble"
    },
    {
      "x": -20,
      "y": 2,
      "z": -3,
      "name": "Rock_Sandstone_Brick"
    },
    {
      "x": -20,
      "y": 3,
      "z": -3,
      "name": "Rock_Sandstone_Brick"
    },
    {
      "x": -20,
      "y": 4,
      "z": -3,
      "name": "Rock_Sandstone_White_Brick"
    },
    {
      "x": -20,
      "y": 5,
      "z": -3,
      "name": "Rock_Sandstone_Brick"
    },
    {
      "x": -20,
      "y": 6,
      "z": -3,
      "name": "Rock_Sandstone_Red_Brick"
    },
    {
      "x": -20,
      "y": 7,
      "z": -3,
      "name": "Rock_Sandstone_Brick"
    },
    {
      "x": -20,
      "y": 8,
      "z": -3,
      "name": "Rock_Sandstone_Brick"
    },
    {
      "x": -20,
      "y": 9,
      "z": -3,
      "name": "Rock_Sandstone_Brick"
    },
    {
      "x": -20,
      "y": 10,
      "z": -3,
      "name": "Rock_Sandstone_Brick"
    },
    {
      "x": -20,
      "y": 11,
      "z": -3,
      "name": "Rock_Sandstone_Brick"
    },
    {
      "x": -20,
      "y": 12,
      "z": -3,
      "name": "Rock_Sandstone_Brick"
    },
    {
      "x": -20,
      "y": 13,
      "z": -3,
      "name": "Rock_Sandstone_Brick"
    },
    {
      "x": -20,
      "y": 14,
      "z": -3,
      "name": "Rock_Sandstone_Red_Brick"
    },
    {
      "x": -20,
      "y": 15,
      "z": -3,
      "name": "Rock_Sandstone_Red_Brick"
    },
    {
      "x": -20,
      "y": 16,
      "z": -3,
      "name": "Rock_Sandstone_Red_Brick"
    },
    {
      "x": -20,
      "y": 17,
      "z": -3,
      "name": "Rock_Sandstone_Brick"
    },
    {
      "x": -20,
      "y": 18,
      "z": -3,
      "name": "Rock_Sandstone_Brick"
    },
    {
      "x": -20,
      "y": 1,
      "z": -2,
      "name": "Rock_Sandstone_Red_Cobble"
    },
    {
      "x": -20,
      "y": 2,
      "z": -2,
      "name": "Rock_Sandstone_Brick"
    },
    {
      "x": -20,
      "y": 3,
      "z": -2,
      "name": "Rock_Sandstone_Brick"
    },
    {
      "x": -20,
      "y": 4,
      "z": -2,
      "name": "Rock_Sandstone_White_Brick"
    },
    {
      "x": -20,
      "y": 5,
      "z": -2,
      "name": "Rock_Sandstone_Brick"
    },
    {
      "x": -20,
      "y": 6,
      "z": -2,
      "name": "Rock_Sandstone_Red_Brick"
    },
    {
      "x": -20,
      "y": 7,
      "z": -2,
      "name": "Rock_Sandstone_Brick"
    },
    {
      "x": -20,
      "y": 8,
      "z": -2,
      "name": "Rock_Sandstone_Brick"
    },
    {
      "x": -20,
      "y": 9,
      "z": -2,
      "name": "Rock_Sandstone_Brick"
    },
    {
      "x": -20,
      "y": 10,
      "z": -2,
      "name": "Rock_Sandstone_Brick"
    },
    {
      "x": -20,
      "y": 15,
      "z": -2,
      "name": "Rock_Sandstone_Red_Brick"
    },
    {
      "x": -20,
      "y": 16,
      "z": -2,
      "name": "Rock_Gold_Brick_Decorative"
    },
    {
      "x": -20,
      "y": 17,
      "z": -2,
      "name": "Rock_Sandstone_Brick"
    },
    {
      "x": -20,
      "y": 18,
      "z": -2,
      "name": "Rock_Sandstone_Brick"
    },
    {
      "x": -20,
      "y": 1,
      "z": -1,
      "name": "Rock_Sandstone_Red_Cobble"
    },
    {
      "x": -20,
      "y": 2,
      "z": -1,
      "name": "Rock_Sandstone_Brick"
    },
    {
      "x": -20,
      "y": 3,
      "z": -1,
      "name": "Rock_Sandstone_Brick"
    },
    {
      "x": -20,
      "y": 4,
      "z": -1,
      "name": "Rock_Sandstone_White_Brick"
    },
    {
      "x": -20,
      "y": 5,
      "z": -1,
      "name": "Rock_Sandstone_Brick"
    },
    {
      "x": -20,
      "y": 6,
      "z": -1,
      "name": "Rock_Sandstone_Red_Brick"
    },
    {
      "x": -20,
      "y": 7,
      "z": -1,
      "name": "Rock_Sandstone_Brick"
    },
    {
      "x": -20,
      "y": 8,
      "z": -1,
      "name": "Rock_Sandstone_Brick"
    },
    {
      "x": -20,
      "y": 9,
      "z": -1,
      "name": "Rock_Sandstone_Brick"
    },
    {
      "x": -20,
      "y": 10,
      "z": -1,
      "name": "Rock_Sandstone_Brick"
    },
    {
      "x": -20,
      "y": 15,
      "z": -1,
      "name": "Rock_Sandstone_Red_Brick"
    },
    {
      "x": -20,
      "y": 16,
      "z": -1,
      "name": "Rock_Sandstone_Red_Brick"
    },
    {
      "x": -20,
      "y": 17,
      "z": -1,
      "name": "Rock_Sandstone_Brick"
    },
    {
      "x": -20,
      "y": 18,
      "z": -1,
      "name": "Rock_Sandstone_Brick"
    },
    {
      "x": -19,
      "y": 1,
      "z": -20,
      "name": "Rock_Sandstone_Red_Cobble"
    },
    {
      "x": -19,
      "y": 2,
      "z": -20,
      "name": "Rock_Sandstone_Brick"
    },
    {
      "x": -19,
      "y": 3,
      "z": -20,
      "name": "Rock_Sandstone_Brick"
    },
    {
      "x": -19,
      "y": 4,
      "z": -20,
      "name": "Rock_Sandstone_White_Brick"
    },
    {
      "x": -19,
      "y": 5,
      "z": -20,
      "name": "Rock_Sandstone_Brick"
    },
    {
      "x": -19,
      "y": 6,
      "z": -20,
      "name": "Rock_Sandstone_Red_Brick"
    },
    {
      "x": -19,
      "y": 1,
      "z": -19,
      "name": "Rock_Sandstone_Red_Cobble"
    },
    {
      "x": -19,
      "y": 6,
      "z": -19,
      "name": "Rock_Sandstone_Red_Brick"
    },
    {
      "x": -19,
      "y": 1,
      "z": -18,
      "name": "Rock_Sandstone_Red_Cobble"
    },
    {
      "x": -19,
      "y": 6,
      "z": -18,
      "name": "Rock_Sandstone_Red_Brick"
    },
    {
      "x": -19,
      "y": 1,
      "z": -17,
      "name": "Rock_Sandstone_Red_Cobble"
    },
    {
      "x": -19,
      "y": 6,
      "z": -17,
      "name": "Rock_Sandstone_Red_Brick"
    },
    {
      "x": -19,
      "y": 7,
      "z": -17,
      "name": "Rock_Sandstone_Brick"
    },
    {
      "x": -19,
      "y": 8,
      "z": -17,
      "name": "Rock_Sandstone_Brick"
    },
    {
      "x": -19,
      "y": 9,
      "z": -17,
      "name": "Rock_Sandstone_Brick"
    },
    {
      "x": -19,
      "y": 10,
      "z": -17,
      "name": "Rock_Sandstone_Brick"
    },
    {
      "x": -19,
      "y": 11,
      "z": -17,
      "name": "Rock_Sandstone"
    },
    {
      "x": -19,
      "y": 12,
      "z": -17,
      "name": "Rock_Sandstone"
    },
    {
      "x": -19,
      "y": 13,
      "z": -17,
      "name": "Rock_Sandstone"
    },
    {
      "x": -19,
      "y": 14,
      "z": -17,
      "name": "Rock_Sandstone_Red_Brick_Half",
      "rotation": 7
    },
    {
      "x": -19,
      "y": 15,
      "z": -17,
      "name": "Rock_Sandstone_Red_Brick_Half",
      "rotation": 7
    },
    {
      "x": -19,
      "y": 16,
      "z": -17,
      "name": "Rock_Sandstone_Red_Brick_Half",
      "rotation": 7
    },
    {
      "x": -19,
      "y": 1,
      "z": -16,
      "name": "Rock_Sandstone_Red_Cobble"
    },
    {
      "x": -19,
      "y": 6,
      "z": -16,
      "name": "Rock_Sandstone_Red_Brick"
    },
    {
      "x": -19,
      "y": 7,
      "z": -16,
      "name": "Rock_Sandstone_Brick"
    },
    {
      "x": -19,
      "y": 8,
      "z": -16,
      "name": "Rock_Sandstone_Brick"
    },
    {
      "x": -19,
      "y": 9,
      "z": -16,
      "name": "Rock_Sandstone_Brick"
    },
    {
      "x": -19,
      "y": 10,
      "z": -16,
      "name": "Rock_Sandstone_Brick"
    },
    {
      "x": -19,
      "y": 11,
      "z": -16,
      "name": "Rock_Sandstone_Brick"
    },
    {
      "x": -19,
      "y": 12,
      "z": -16,
      "name": "Rock_Sandstone_Brick"
    },
    {
      "x": -19,
      "y": 13,
      "z": -16,
      "name": "Rock_Sandstone_Brick"
    },
    {
      "x": -19,
      "y": 14,
      "z": -16,
      "name": "Rock_Sandstone_Red_Brick"
    },
    {
      "x": -19,
      "y": 15,
      "z": -16,
      "name": "Rock_Sandstone_Red_Brick"
    },
    {
      "x": -19,
      "y": 16,
      "z": -16,
      "name": "Rock_Sandstone_Red_Brick"
    },
    {
      "x": -19,
      "y": 17,
      "z": -16,
      "name": "Rock_Sandstone_Brick"
    },
    {
      "x": -19,
      "y": 18,
      "z": -16,
      "name": "Rock_Sandstone_Brick"
    },
    {
      "x": -19,
      "y": 19,
      "z": -16,
      "name": "Rock_Sandstone_Brick"
    },
    {
      "x": -19,
      "y": 20,
      "z": -16,
      "name": "Rock_Sandstone_Brick"
    },
    {
      "x": -19,
      "y": 21,
      "z": -16,
      "name": "Rock_Sandstone_Brick"
    },
    {
      "x": -19,
      "y": 22,
      "z": -16,
      "name": "Rock_Sandstone_Brick"
    },
    {
      "x": -19,
      "y": 23,
      "z": -16,
      "name": "Rock_Gold_Brick_Smooth"
    },
    {
      "x": -19,
      "y": 24,
      "z": -16,
      "name": "Rock_Sandstone_Brick"
    },
    {
      "x": -19,
      "y": 25,
      "z": -16,
      "name": "Soil_Clay_Ocean_Brick_Ornate"
    },
    {
      "x": -19,
      "y": 26,
      "z": -16,
      "name": "Soil_Clay_Ocean_Brick_Ornate"
    },
    {
      "x": -19,
      "y": 27,
      "z": -16,
      "name": "Rock_Sandstone_Brick"
    },
    {
      "x": -19,
      "y": 28,
      "z": -16,
      "name": "Rock_Sandstone_Brick"
    },
    {
      "x": -19,
      "y": 29,
      "z": -16,
      "name": "Rock_Sandstone_Brick"
    },
    {
      "x": -19,
      "y": 1,
      "z": -15,
      "name": "Rock_Sandstone_Red_Cobble"
    },
    {
      "x": -19,
      "y": 6,
      "z": -15,
      "name": "Rock_Sandstone_Red_Brick"
    },
    {
      "x": -19,
      "y": 8,
      "z": -15,
      "name": "Rock_Sandstone_Brick"
    },
    {
      "x": -19,
      "y": 9,
      "z": -15,
      "name": "Rock_Sandstone_Brick"
    },
    {
      "x": -19,
      "y": 10,
      "z": -15,
      "name": "Rock_Sandstone_Brick"
    },
    {
      "x": -19,
      "y": 11,
      "z": -15,
      "name": "Rock_Sandstone_Brick"
    },
    {
      "x": -19,
      "y": 12,
      "z": -15,
      "name": "Rock_Sandstone_Brick"
    },
    {
      "x": -19,
      "y": 17,
      "z": -15,
      "name": "Rock_Sandstone_Brick"
    },
    {
      "x": -19,
      "y": 18,
      "z": -15,
      "name": "Wood_Drywood_Planks"
    },
    {
      "x": -19,
      "y": 25,
      "z": -15,
      "name": "Rock_Sandstone_Brick"
    },
    {
      "x": -19,
      "y": 29,
      "z": -15,
      "name": "Rock_Sandstone_Brick"
    },
    {
      "x": -19,
      "y": 30,
      "z": -15,
      "name": "*Rock_Sandstone_Brick_Stairs_State_Definitions_Corner_Right",
      "rotation": 3
    },
    {
      "x": -19,
      "y": 1,
      "z": -14,
      "name": "Rock_Sandstone_Red_Cobble"
    },
    {
      "x": -19,
      "y": 6,
      "z": -14,
      "name": "Rock_Sandstone_Red_Brick"
    },
    {
      "x": -19,
      "y": 11,
      "z": -14,
      "name": "Rock_Sandstone_Brick"
    },
    {
      "x": -19,
      "y": 12,
      "z": -14,
      "name": "Rock_Sandstone_Brick"
    },
    {
      "x": -19,
      "y": 18,
      "z": -14,
      "name": "Wood_Drywood_Planks"
    },
    {
      "x": -19,
      "y": 25,
      "z": -14,
      "name": "Rock_Sandstone_Brick"
    },
    {
      "x": -19,
      "y": 29,
      "z": -14,
      "name": "Rock_Sandstone_Brick"
    },
    {
      "x": -19,
      "y": 30,
      "z": -14,
      "name": "Rock_Sandstone_Brick_Stairs",
      "rotation": 3
    },
    {
      "x": -19,
      "y": 35,
      "z": -14,
      "name": "Rock_Sandstone_Brick_Stairs",
      "rotation": 9
    },
    {
      "x": -19,
      "y": 36,
      "z": -14,
      "name": "Soil_Clay_Ocean_Brick_Smooth",
      "rotation": 3
    },
    {
      "x": -19,
      "y": 1,
      "z": -13,
      "name": "Rock_Sandstone_Red_Cobble"
    },
    {
      "x": -19,
      "y": 6,
      "z": -13,
      "name": "Rock_Sandstone_Red_Brick"
    },
    {
      "x": -19,
      "y": 11,
      "z": -13,
      "name": "Rock_Sandstone_Brick"
    },
    {
      "x": -19,
      "y": 12,
      "z": -13,
      "name": "Rock_Sandstone_Brick"
    },
    {
      "x": -19,
      "y": 18,
      "z": -13,
      "name": "Wood_Drywood_Planks"
    },
    {
      "x": -19,
      "y": 25,
      "z": -13,
      "name": "Rock_Sandstone_Brick"
    },
    {
      "x": -19,
      "y": 29,
      "z": -13,
      "name": "Rock_Sandstone_Brick"
    },
    {
      "x": -19,
      "y": 30,
      "z": -13,
      "name": "Rock_Sandstone_Brick_Stairs",
      "rotation": 3
    },
    {
      "x": -19,
      "y": 35,
      "z": -13,
      "name": "Rock_Sandstone_Brick_Stairs",
      "rotation": 9
    },
    {
      "x": -19,
      "y": 36,
      "z": -13,
      "name": "Soil_Clay_Ocean_Brick_Smooth",
      "rotation": 3
    },
    {
      "x": -19,
      "y": 1,
      "z": -12,
      "name": "Rock_Sandstone_Red_Cobble"
    },
    {
      "x": -19,
      "y": 6,
      "z": -12,
      "name": "Rock_Sandstone_Red_Brick"
    },
    {
      "x": -19,
      "y": 11,
      "z": -12,
      "name": "Rock_Sandstone_Brick"
    },
    {
      "x": -19,
      "y": 12,
      "z": -12,
      "name": "Rock_Sandstone_Cobble"
    },
    {
      "x": -19,
      "y": 18,
      "z": -12,
      "name": "Wood_Drywood_Planks"
    },
    {
      "x": -19,
      "y": 25,
      "z": -12,
      "name": "Rock_Sandstone_Brick"
    },
    {
      "x": -19,
      "y": 29,
      "z": -12,
      "name": "Rock_Sandstone_Brick"
    },
    {
      "x": -19,
      "y": 30,
      "z": -12,
      "name": "Rock_Sandstone_Brick_Stairs",
      "rotation": 3
    },
    {
      "x": -19,
      "y": 35,
      "z": -12,
      "name": "Rock_Sandstone_Brick_Stairs",
      "rotation": 9
    },
    {
      "x": -19,
      "y": 36,
      "z": -12,
      "name": "Soil_Clay_Ocean_Brick_Smooth",
      "rotation": 3
    },
    {
      "x": -19,
      "y": 1,
      "z": -11,
      "name": "Rock_Sandstone_Red_Cobble"
    },
    {
      "x": -19,
      "y": 2,
      "z": -11,
      "name": "Rock_Sandstone_Brick"
    },
    {
      "x": -19,
      "y": 3,
      "z": -11,
      "name": "Rock_Sandstone_Brick"
    },
    {
      "x": -19,
      "y": 4,
      "z": -11,
      "name": "Rock_Sandstone_White_Brick"
    },
    {
      "x": -19,
      "y": 5,
      "z": -11,
      "name": "Rock_Sandstone_Brick"
    },
    {
      "x": -19,
      "y": 6,
      "z": -11,
      "name": "Rock_Sandstone_Red_Brick"
    },
    {
      "x": -19,
      "y": 11,
      "z": -11,
      "name": "Rock_Sandstone_Brick"
    },
    {
      "x": -19,
      "y": 12,
      "z": -11,
      "name": "Rock_Sandstone_Cobble"
    },
    {
      "x": -19,
      "y": 18,
      "z": -11,
      "name": "Wood_Drywood_Planks"
    },
    {
      "x": -19,
      "y": 25,
      "z": -11,
      "name": "Rock_Sandstone_Brick"
    },
    {
      "x": -19,
      "y": 29,
      "z": -11,
      "name": "Rock_Sandstone_Brick"
    },
    {
      "x": -19,
      "y": 30,
      "z": -11,
      "name": "Rock_Sandstone_Brick_Stairs",
      "rotation": 3
    },
    {
      "x": -19,
      "y": 35,
      "z": -11,
      "name": "Rock_Sandstone_Brick_Stairs",
      "rotation": 9
    },
    {
      "x": -19,
      "y": 36,
      "z": -11,
      "name": "Soil_Clay_Ocean_Brick_Smooth",
      "rotation": 3
    },
    {
      "x": -19,
      "y": 1,
      "z": -10,
      "name": "Rock_Sandstone_Red_Cobble"
    },
    {
      "x": -19,
      "y": 6,
      "z": -10,
      "name": "Rock_Sandstone_Red_Brick"
    },
    {
      "x": -19,
      "y": 11,
      "z": -10,
      "name": "Rock_Sandstone_Brick"
    },
    {
      "x": -19,
      "y": 12,
      "z": -10,
      "name": "Rock_Sandstone_Cobble"
    },
    {
      "x": -19,
      "y": 18,
      "z": -10,
      "name": "Wood_Drywood_Planks"
    },
    {
      "x": -19,
      "y": 25,
      "z": -10,
      "name": "Rock_Sandstone_Brick"
    },
    {
      "x": -19,
      "y": 29,
      "z": -10,
      "name": "Rock_Sandstone_Brick"
    },
    {
      "x": -19,
      "y": 30,
      "z": -10,
      "name": "Rock_Sandstone_Brick_Stairs",
      "rotation": 3
    },
    {
      "x": -19,
      "y": 35,
      "z": -10,
      "name": "Rock_Sandstone_Brick_Stairs",
      "rotation": 9
    },
    {
      "x": -19,
      "y": 36,
      "z": -10,
      "name": "Soil_Clay_Ocean_Brick_Smooth",
      "rotation": 3
    },
    {
      "x": -19,
      "y": 1,
      "z": -9,
      "name": "Rock_Sandstone_Red_Cobble"
    },
    {
      "x": -19,
      "y": 6,
      "z": -9,
      "name": "Rock_Sandstone_Red_Brick"
    },
    {
      "x": -19,
      "y": 11,
      "z": -9,
      "name": "Rock_Sandstone_Brick"
    },
    {
      "x": -19,
      "y": 12,
      "z": -9,
      "name": "Rock_Sandstone_Cobble"
    },
    {
      "x": -19,
      "y": 18,
      "z": -9,
      "name": "Wood_Drywood_Planks"
    },
    {
      "x": -19,
      "y": 25,
      "z": -9,
      "name": "Rock_Sandstone_Brick"
    },
    {
      "x": -19,
      "y": 29,
      "z": -9,
      "name": "Rock_Sandstone_Brick"
    },
    {
      "x": -19,
      "y": 30,
      "z": -9,
      "name": "Rock_Sandstone_Brick_Stairs",
      "rotation": 3
    },
    {
      "x": -19,
      "y": 35,
      "z": -9,
      "name": "Rock_Sandstone_Brick_Stairs",
      "rotation": 9
    },
    {
      "x": -19,
      "y": 36,
      "z": -9,
      "name": "Soil_Clay_Ocean_Brick_Smooth",
      "rotation": 3
    },
    {
      "x": -19,
      "y": 1,
      "z": -8,
      "name": "Rock_Sandstone_Red_Cobble"
    },
    {
      "x": -19,
      "y": 6,
      "z": -8,
      "name": "Rock_Sandstone_Red_Brick"
    },
    {
      "x": -19,
      "y": 7,
      "z": -8,
      "name": "Soil_Clay_Ocean_Brick_Smooth"
    },
    {
      "x": -19,
      "y": 8,
      "z": -8,
      "name": "Soil_Clay_Ocean_Brick_Wall"
    },
    {
      "x": -19,
      "y": 11,
      "z": -8,
      "name": "Rock_Sandstone_Brick"
    },
    {
      "x": -19,
      "y": 12,
      "z": -8,
      "name": "Rock_Sandstone_Cobble"
    },
    {
      "x": -19,
      "y": 18,
      "z": -8,
      "name": "Wood_Drywood_Planks"
    },
    {
      "x": -19,
      "y": 25,
      "z": -8,
      "name": "Rock_Sandstone_Brick"
    },
    {
      "x": -19,
      "y": 29,
      "z": -8,
      "name": "Rock_Sandstone_Brick"
    },
    {
      "x": -19,
      "y": 30,
      "z": -8,
      "name": "Rock_Sandstone_Brick_Stairs",
      "rotation": 3
    },
    {
      "x": -19,
      "y": 1,
      "z": -7,
      "name": "Rock_Sandstone_Red_Cobble"
    },
    {
      "x": -19,
      "y": 6,
      "z": -7,
      "name": "Rock_Sandstone_Red_Brick"
    },
    {
      "x": -19,
      "y": 7,
      "z": -7,
      "name": "Soil_Clay_Ocean_Brick_Smooth"
    },
    {
      "x": -19,
      "y": 8,
      "z": -7,
      "name": "Soil_Clay_Ocean_Brick_Wall"
    },
    {
      "x": -19,
      "y": 11,
      "z": -7,
      "name": "Rock_Sandstone_Brick"
    },
    {
      "x": -19,
      "y": 12,
      "z": -7,
      "name": "Rock_Sandstone_Cobble"
    },
    {
      "x": -19,
      "y": 18,
      "z": -7,
      "name": "Rock_Sandstone_Brick"
    },
    {
      "x": -19,
      "y": 19,
      "z": -7,
      "name": "Rock_Sandstone_Brick"
    },
    {
      "x": -19,
      "y": 20,
      "z": -7,
      "name": "Rock_Sandstone_Brick"
    },
    {
      "x": -19,
      "y": 21,
      "z": -7,
      "name": "Rock_Sandstone_Brick"
    },
    {
      "x": -19,
      "y": 22,
      "z": -7,
      "name": "Rock_Sandstone_Brick"
    },
    {
      "x": -19,
      "y": 23,
      "z": -7,
      "name": "Rock_Gold_Brick_Smooth"
    },
    {
      "x": -19,
      "y": 24,
      "z": -7,
      "name": "Rock_Sandstone_Brick"
    },
    {
      "x": -19,
      "y": 25,
      "z": -7,
      "name": "Soil_Clay_Ocean_Brick_Ornate"
    },
    {
      "x": -19,
      "y": 26,
      "z": -7,
      "name": "Soil_Clay_Ocean_Brick_Ornate"
    },
    {
      "x": -19,
      "y": 27,
      "z": -7,
      "name": "Rock_Sandstone_Brick"
    },
    {
      "x": -19,
      "y": 28,
      "z": -7,
      "name": "Rock_Sandstone_Brick"
    },
    {
      "x": -19,
      "y": 29,
      "z": -7,
      "name": "Rock_Sandstone_Brick"
    },
    {
      "x": -19,
      "y": 30,
      "z": -7,
      "name": "*Rock_Sandstone_Brick_Stairs_State_Definitions_Corner_Right"
    },
    {
      "x": -19,
      "y": 1,
      "z": -6,
      "name": "Rock_Sandstone_Red_Cobble"
    },
    {
      "x": -19,
      "y": 6,
      "z": -6,
      "name": "Rock_Sandstone_Red_Brick"
    },
    {
      "x": -19,
      "y": 11,
      "z": -6,
      "name": "Rock_Sandstone_Brick"
    },
    {
      "x": -19,
      "y": 12,
      "z": -6,
      "name": "Rock_Sandstone_Cobble"
    },
    {
      "x": -19,
      "y": 17,
      "z": -6,
      "name": "Cloth_Roof_Leather_Flap"
    },
    {
      "x": -19,
      "y": 29,
      "z": -6,
      "name": "*Rock_Sandstone_Brick_Stairs_State_Definitions_Corner_Right",
      "rotation": 9
    },
    {
      "x": -19,
      "y": 30,
      "z": -6,
      "name": "Rock_Sandstone_Brick_Half"
    },
    {
      "x": -19,
      "y": 1,
      "z": -5,
      "name": "Rock_Sandstone_Red_Cobble"
    },
    {
      "x": -19,
      "y": 4,
      "z": -5,
      "name": "Cloth_Roof_Leather_Flap",
      "rotation": 1
    },
    {
      "x": -19,
      "y": 6,
      "z": -5,
      "name": "Rock_Sandstone_Red_Brick"
    },
    {
      "x": -19,
      "y": 11,
      "z": -5,
      "name": "Rock_Sandstone_Brick"
    },
    {
      "x": -19,
      "y": 12,
      "z": -5,
      "name": "Rock_Sandstone_Cobble"
    },
    {
      "x": -19,
      "y": 1,
      "z": -4,
      "name": "Rock_Sandstone_Red_Cobble"
    },
    {
      "x": -19,
      "y": 6,
      "z": -4,
      "name": "Rock_Sandstone_Red_Brick"
    },
    {
      "x": -19,
      "y": 1,
      "z": -3,
      "name": "Rock_Sandstone_Red_Cobble"
    },
    {
      "x": -19,
      "y": 6,
      "z": -3,
      "name": "Rock_Sandstone_Red_Brick"
    },
    {
      "x": -19,
      "y": 14,
      "z": -3,
      "name": "Rock_Sandstone_Brick_Stairs",
      "rotation": 2
    },
    {
      "x": -19,
      "y": 1,
      "z": -2,
      "name": "Rock_Sandstone_Red_Cobble"
    },
    {
      "x": -19,
      "y": 6,
      "z": -2,
      "name": "Rock_Sandstone_Red_Brick"
    },
    {
      "x": -19,
      "y": 1,
      "z": -1,
      "name": "Rock_Sandstone_Red_Cobble"
    },
    {
      "x": -19,
      "y": 2,
      "z": -1,
      "name": "Rock_Sandstone_Brick"
    },
    {
      "x": -19,
      "y": 3,
      "z": -1,
      "name": "Rock_Sandstone_Brick"
    },
    {
      "x": -19,
      "y": 4,
      "z": -1,
      "name": "Rock_Sandstone_White_Brick"
    },
    {
      "x": -19,
      "y": 5,
      "z": -1,
      "name": "Rock_Sandstone_Brick"
    },
    {
      "x": -19,
      "y": 6,
      "z": -1,
      "name": "Rock_Sandstone_Red_Brick"
    },
    {
      "x": -19,
      "y": 7,
      "z": -1,
      "name": "Rock_Sandstone_Brick"
    },
    {
      "x": -19,
      "y": 8,
      "z": -1,
      "name": "Rock_Sandstone_Brick_Stairs",
      "rotation": 9
    },
    {
      "x": -19,
      "y": 9,
      "z": -1,
      "name": "Rock_Sandstone_Brick"
    },
    {
      "x": -19,
      "y": 10,
      "z": -1,
      "name": "Rock_Sandstone_Brick"
    },
    {
      "x": -19,
      "y": 15,
      "z": -1,
      "name": "Rock_Sandstone_Red_Brick"
    },
    {
      "x": -19,
      "y": 16,
      "z": -1,
      "name": "Rock_Sandstone_Red_Brick"
    },
    {
      "x": -18,
      "y": 1,
      "z": -20,
      "name": "Rock_Sandstone_Red_Cobble"
    },
    {
      "x": -18,
      "y": 2,
      "z": -20,
      "name": "Rock_Sandstone_Brick"
    },
    {
      "x": -18,
      "y": 3,
      "z": -20,
      "name": "Rock_Sandstone_Brick"
    },
    {
      "x": -18,
      "y": 4,
      "z": -20,
      "name": "Rock_Sandstone_White_Brick"
    },
    {
      "x": -18,
      "y": 5,
      "z": -20,
      "name": "Rock_Sandstone_Brick"
    },
    {
      "x": -18,
      "y": 6,
      "z": -20,
      "name": "Rock_Sandstone_Red_Brick"
    },
    {
      "x": -18,
      "y": 1,
      "z": -19,
      "name": "Rock_Sandstone_Red_Cobble"
    },
    {
      "x": -18,
      "y": 6,
      "z": -19,
      "name": "Rock_Sandstone_Red_Brick"
    },
    {
      "x": -18,
      "y": 9,
      "z": -19,
      "name": "Rock_Sandstone_Brick_Stairs",
      "rotation": 9
    },
    {
      "x": -18,
      "y": 10,
      "z": -19,
      "name": "Rock_Sandstone_Brick"
    },
    {
      "x": -18,
      "y": 11,
      "z": -19,
      "name": "Rock_Sandstone"
    },
    {
      "x": -18,
      "y": 12,
      "z": -19,
      "name": "Rock_Sandstone"
    },
    {
      "x": -18,
      "y": 1,
      "z": -18,
      "name": "Rock_Sandstone_Red_Cobble"
    },
    {
      "x": -18,
      "y": 6,
      "z": -18,
      "name": "Rock_Sandstone_Red_Brick"
    },
    {
      "x": -18,
      "y": 9,
      "z": -18,
      "name": "Rock_Sandstone_Brick_Half",
      "rotation": 8
    },
    {
      "x": -18,
      "y": 10,
      "z": -18,
      "name": "Rock_Sandstone_Brick"
    },
    {
      "x": -18,
      "y": 11,
      "z": -18,
      "name": "Rock_Sandstone"
    },
    {
      "x": -18,
      "y": 12,
      "z": -18,
      "name": "Rock_Sandstone"
    },
    {
      "x": -18,
      "y": 1,
      "z": -17,
      "name": "Rock_Sandstone_Red_Cobble"
    },
    {
      "x": -18,
      "y": 6,
      "z": -17,
      "name": "Rock_Sandstone_Red_Brick"
    },
    {
      "x": -18,
      "y": 7,
      "z": -17,
      "name": "Rock_Sandstone_Brick"
    },
    {
      "x": -18,
      "y": 8,
      "z": -17,
      "name": "Rock_Sandstone_Brick"
    },
    {
      "x": -18,
      "y": 9,
      "z": -17,
      "name": "Rock_Sandstone_Brick"
    },
    {
      "x": -18,
      "y": 10,
      "z": -17,
      "name": "Rock_Sandstone_Brick"
    },
    {
      "x": -18,
      "y": 11,
      "z": -17,
      "name": "Rock_Sandstone_Brick"
    },
    {
      "x": -18,
      "y": 12,
      "z": -17,
      "name": "Rock_Sandstone_Brick"
    },
    {
      "x": -18,
      "y": 13,
      "z": -17,
      "name": "Rock_Sandstone_Brick"
    },
    {
      "x": -18,
      "y": 14,
      "z": -17,
      "name": "Rock_Sandstone_Red_Brick"
    },
    {
      "x": -18,
      "y": 15,
      "z": -17,
      "name": "Rock_Sandstone_Red_Brick"
    },
    {
      "x": -18,
      "y": 16,
      "z": -17,
      "name": "Rock_Sandstone_Red_Brick"
    },
    {
      "x": -18,
      "y": 17,
      "z": -17,
      "name": "Rock_Sandstone_Brick"
    },
    {
      "x": -18,
      "y": 18,
      "z": -17,
      "name": "Rock_Sandstone_Brick"
    },
    {
      "x": -18,
      "y": 19,
      "z": -17,
      "name": "Rock_Sandstone_Brick"
    },
    {
      "x": -18,
      "y": 20,
      "z": -17,
      "name": "Rock_Sandstone_Brick"
    },
    {
      "x": -18,
      "y": 21,
      "z": -17,
      "name": "Rock_Sandstone_Brick"
    },
    {
      "x": -18,
      "y": 22,
      "z": -17,
      "name": "Rock_Sandstone_Brick"
    },
    {
      "x": -18,
      "y": 23,
      "z": -17,
      "name": "Rock_Gold_Brick_Smooth"
    },
    {
      "x": -18,
      "y": 24,
      "z": -17,
      "name": "Rock_Sandstone_Brick"
    },
    {
      "x": -18,
      "y": 25,
      "z": -17,
      "name": "Soil_Clay_Ocean_Brick_Ornate"
    },
    {
      "x": -18,
      "y": 26,
      "z": -17,
      "name": "Soil_Clay_Ocean_Brick_Ornate"
    },
    {
      "x": -18,
      "y": 27,
      "z": -17,
      "name": "Rock_Sandstone_Brick"
    },
    {
      "x": -18,
      "y": 28,
      "z": -17,
      "name": "Rock_Sandstone_Brick"
    },
    {
      "x": -18,
      "y": 29,
      "z": -17,
      "name": "Rock_Sandstone_Brick"
    },
    {
      "x": -18,
      "y": 30,
      "z": -17,
      "name": "*Rock_Sandstone_Brick_Stairs_State_Definitions_Corner_Left",
      "rotation": 2
    },
    {
      "x": -18,
      "y": 1,
      "z": -16,
      "name": "Rock_Sandstone_Red_Cobble"
    },
    {
      "x": -18,
      "y": 6,
      "z": -16,
      "name": "Rock_Sandstone_Red_Brick"
    },
    {
      "x": -18,
      "y": 8,
      "z": -16,
      "name": "Rock_Sandstone_Brick"
    },
    {
      "x": -18,
      "y": 9,
      "z": -16,
      "name": "Rock_Sandstone_Brick"
    },
    {
      "x": -18,
      "y": 10,
      "z": -16,
      "name": "Rock_Sandstone_Brick"
    },
    {
      "x": -18,
      "y": 11,
      "z": -16,
      "name": "Rock_Sandstone_Brick"
    },
    {
      "x": -18,
      "y": 12,
      "z": -16,
      "name": "Rock_Sandstone_Brick"
    },
    {
      "x": -18,
      "y": 13,
      "z": -16,
      "name": "Rock_Sandstone_Brick"
    },
    {
      "x": -18,
      "y": 14,
      "z": -16,
      "name": "Rock_Sandstone_Brick"
    },
    {
      "x": -18,
      "y": 15,
      "z": -16,
      "name": "Rock_Sandstone_Brick"
    },
    {
      "x": -18,
      "y": 16,
      "z": -16,
      "name": "Rock_Sandstone_Brick"
    },
    {
      "x": -18,
      "y": 17,
      "z": -16,
      "name": "Rock_Sandstone_Brick"
    },
    {
      "x": -18,
      "y": 18,
      "z": -16,
      "name": "Wood_Drywood_Planks"
    },
    {
      "x": -18,
      "y": 25,
      "z": -16,
      "name": "Rock_Sandstone_Brick"
    },
    {
      "x": -18,
      "y": 29,
      "z": -16,
      "name": "Rock_Sandstone_Brick"
    },
    {
      "x": -18,
      "y": 30,
      "z": -16,
      "name": "Rock_Sandstone_Brick_Stairs",
      "rotation": 3
    },
    {
      "x": -18,
      "y": 35,
      "z": -16,
      "name": "Rock_Sandstone_Brick_Stairs",
      "rotation": 9
    },
    {
      "x": -18,
      "y": 36,
      "z": -16,
      "name": "Soil_Clay_Ocean_Brick_Smooth",
      "rotation": 3
    },
    {
      "x": -18,
      "y": 1,
      "z": -15,
      "name": "Rock_Sandstone_Red_Cobble"
    },
    {
      "x": -18,
      "y": 6,
      "z": -15,
      "name": "Rock_Sandstone_Red_Brick"
    },
    {
      "x": -18,
      "y": 11,
      "z": -15,
      "name": "Rock_Sandstone_Brick"
    },
    {
      "x": -18,
      "y": 12,
      "z": -15,
      "name": "Rock_Sandstone_Brick"
    },
    {
      "x": -18,
      "y": 17,
      "z": -15,
      "name": "Rock_Sandstone_Brick"
    },
    {
      "x": -18,
      "y": 18,
      "z": -15,
      "name": "Wood_Drywood_Planks"
    },
    {
      "x": -18,
      "y": 25,
      "z": -15,
      "name": "Rock_Sandstone_Brick"
    },
    {
      "x": -18,
      "y": 29,
      "z": -15,
      "name": "Rock_Sandstone_Brick"
    },
    {
      "x": -18,
      "y": 30,
      "z": -15,
      "name": "*Rock_Sandstone_Brick_Stairs_State_Definitions_Inverted_Corner_Left",
      "rotation": 2
    },
    {
      "x": -18,
      "y": 35,
      "z": -15,
      "name": "Rock_Sandstone_Brick_Stairs",
      "rotation": 9
    },
    {
      "x": -18,
      "y": 36,
      "z": -15,
      "name": "Soil_Clay_Ocean_Brick_Smooth",
      "rotation": 3
    },
    {
      "x": -18,
      "y": 1,
      "z": -14,
      "name": "Rock_Sandstone_Red_Cobble"
    },
    {
      "x": -18,
      "y": 6,
      "z": -14,
      "name": "Rock_Sandstone_Red_Brick"
    },
    {
      "x": -18,
      "y": 11,
      "z": -14,
      "name": "Rock_Sandstone_Brick"
    },
    {
      "x": -18,
      "y": 12,
      "z": -14,
      "name": "Rock_Sandstone_Brick"
    },
    {
      "x": -18,
      "y": 18,
      "z": -14,
      "name": "Wood_Drywood_Planks"
    },
    {
      "x": -18,
      "y": 25,
      "z": -14,
      "name": "Rock_Sandstone_Brick"
    },
    {
      "x": -18,
      "y": 29,
      "z": -14,
      "name": "Rock_Sandstone_Brick"
    },
    {
      "x": -18,
      "y": 30,
      "z": -14,
      "name": "Rock_Sandstone_Brick"
    },
    {
      "x": -18,
      "y": 31,
      "z": -14,
      "name": "Rock_Sandstone_Brick",
      "rotation": 3
    },
    {
      "x": -18,
      "y": 32,
      "z": -14,
      "name": "Rock_Sandstone_Brick",
      "rotation": 3
    },
    {
      "x": -18,
      "y": 33,
      "z": -14,
      "name": "Rock_Sandstone_Brick",
      "rotation": 3
    },
    {
      "x": -18,
      "y": 34,
      "z": -14,
      "name": "Rock_Sandstone_Brick",
      "rotation": 3
    },
    {
      "x": -18,
      "y": 35,
      "z": -14,
      "name": "Rock_Sandstone_Brick",
      "rotation": 3
    },
    {
      "x": -18,
      "y": 36,
      "z": -14,
      "name": "Soil_Clay_Ocean_Brick_Smooth",
      "rotation": 3
    },
    {
      "x": -18,
      "y": 1,
      "z": -13,
      "name": "Rock_Sandstone_Red_Cobble"
    },
    {
      "x": -18,
      "y": 6,
      "z": -13,
      "name": "Rock_Sandstone_Red_Brick"
    },
    {
      "x": -18,
      "y": 11,
      "z": -13,
      "name": "Rock_Sandstone_Brick"
    },
    {
      "x": -18,
      "y": 12,
      "z": -13,
      "name": "Rock_Sandstone_Brick"
    },
    {
      "x": -18,
      "y": 18,
      "z": -13,
      "name": "Wood_Drywood_Planks"
    },
    {
      "x": -18,
      "y": 25,
      "z": -13,
      "name": "Rock_Sandstone_Brick"
    },
    {
      "x": -18,
      "y": 29,
      "z": -13,
      "name": "Rock_Sandstone_Brick"
    },
    {
      "x": -18,
      "y": 30,
      "z": -13,
      "name": "Rock_Sandstone_Brick"
    },
    {
      "x": -18,
      "y": 31,
      "z": -13,
      "name": "Rock_Sandstone_Brick",
      "rotation": 3
    },
    {
      "x": -18,
      "y": 32,
      "z": -13,
      "name": "Rock_Sandstone_Brick",
      "rotation": 3
    },
    {
      "x": -18,
      "y": 33,
      "z": -13,
      "name": "Furniture_Desert_Window",
      "rotation": 3
    },
    {
      "x": -18,
      "y": 34,
      "z": -13,
      "name": "Furniture_Desert_Window",
      "rotation": 3
    },
    {
      "x": -18,
      "y": 35,
      "z": -13,
      "name": "Rock_Sandstone_Brick",
      "rotation": 3
    },
    {
      "x": -18,
      "y": 36,
      "z": -13,
      "name": "Soil_Clay_Ocean_Brick_Smooth",
      "rotation": 3
    },
    {
      "x": -18,
      "y": 37,
      "z": -13,
      "name": "Soil_Clay_Ocean_Brick_Half",
      "rotation": 3
    },
    {
      "x": -18,
      "y": 1,
      "z": -12,
      "name": "Rock_Sandstone_Red_Cobble"
    },
    {
      "x": -18,
      "y": 6,
      "z": -12,
      "name": "Rock_Sandstone_Red_Brick"
    },
    {
      "x": -18,
      "y": 11,
      "z": -12,
      "name": "Rock_Sandstone_Brick"
    },
    {
      "x": -18,
      "y": 12,
      "z": -12,
      "name": "Rock_Sandstone_Cobble"
    },
    {
      "x": -18,
      "y": 18,
      "z": -12,
      "name": "Wood_Drywood_Planks"
    },
    {
      "x": -18,
      "y": 25,
      "z": -12,
      "name": "Rock_Sandstone_Brick"
    },
    {
      "x": -18,
      "y": 26,
      "z": -12,
      "name": "Rock_Sandstone_Brick"
    },
    {
      "x": -18,
      "y": 27,
      "z": -12,
      "name": "Rock_Sandstone_Brick"
    },
    {
      "x": -18,
      "y": 28,
      "z": -12,
      "name": "Rock_Sandstone_Brick"
    },
    {
      "x": -18,
      "y": 29,
      "z": -12,
      "name": "Rock_Sandstone_Brick"
    },
    {
      "x": -18,
      "y": 30,
      "z": -12,
      "name": "Rock_Sandstone_Brick"
    },
    {
      "x": -18,
      "y": 31,
      "z": -12,
      "name": "Rock_Sandstone_Brick",
      "rotation": 3
    },
    {
      "x": -18,
      "y": 32,
      "z": -12,
      "name": "Rock_Sandstone_Brick",
      "rotation": 3
    },
    {
      "x": -18,
      "y": 33,
      "z": -12,
      "name": "Rock_Sandstone_Brick",
      "rotation": 3
    },
    {
      "x": -18,
      "y": 34,
      "z": -12,
      "name": "Rock_Sandstone_Brick",
      "rotation": 3
    },
    {
      "x": -18,
      "y": 35,
      "z": -12,
      "name": "Rock_Sandstone_Brick",
      "rotation": 3
    },
    {
      "x": -18,
      "y": 36,
      "z": -12,
      "name": "Soil_Clay_Ocean_Brick_Smooth",
      "rotation": 3
    },
    {
      "x": -18,
      "y": 37,
      "z": -12,
      "name": "Soil_Clay_Ocean_Brick_Half",
      "rotation": 3
    },
    {
      "x": -18,
      "y": 1,
      "z": -11,
      "name": "Rock_Sandstone_Red_Cobble"
    },
    {
      "x": -18,
      "y": 4,
      "z": -11,
      "name": "Rock_Sandstone_White_Brick_Half",
      "rotation": 8
    },
    {
      "x": -18,
      "y": 5,
      "z": -11,
      "name": "Rock_Sandstone_Brick"
    },
    {
      "x": -18,
      "y": 6,
      "z": -11,
      "name": "Rock_Sandstone_Red_Brick"
    },
    {
      "x": -18,
      "y": 11,
      "z": -11,
      "name": "Rock_Sandstone_Brick"
    },
    {
      "x": -18,
      "y": 12,
      "z": -11,
      "name": "Rock_Sandstone_Cobble"
    },
    {
      "x": -18,
      "y": 18,
      "z": -11,
      "name": "Wood_Drywood_Planks"
    },
    {
      "x": -18,
      "y": 25,
      "z": -11,
      "name": "Rock_Sandstone_Brick"
    },
    {
      "x": -18,
      "y": 26,
      "z": -11,
      "name": "Rock_Sandstone_Brick"
    },
    {
      "x": -18,
      "y": 27,
      "z": -11,
      "name": "Rock_Sandstone_Brick"
    },
    {
      "x": -18,
      "y": 28,
      "z": -11,
      "name": "Rock_Sandstone_Brick"
    },
    {
      "x": -18,
      "y": 29,
      "z": -11,
      "name": "Rock_Sandstone_Brick"
    },
    {
      "x": -18,
      "y": 30,
      "z": -11,
      "name": "Rock_Sandstone_Brick"
    },
    {
      "x": -18,
      "y": 31,
      "z": -11,
      "name": "Rock_Sandstone_Brick",
      "rotation": 3
    },
    {
      "x": -18,
      "y": 32,
      "z": -11,
      "name": "Rock_Sandstone_Brick",
      "rotation": 3
    },
    {
      "x": -18,
      "y": 33,
      "z": -11,
      "name": "Rock_Sandstone_Brick",
      "rotation": 3
    },
    {
      "x": -18,
      "y": 34,
      "z": -11,
      "name": "Rock_Sandstone_Brick",
      "rotation": 3
    },
    {
      "x": -18,
      "y": 35,
      "z": -11,
      "name": "Rock_Sandstone_Brick",
      "rotation": 3
    },
    {
      "x": -18,
      "y": 36,
      "z": -11,
      "name": "Soil_Clay_Ocean_Brick_Smooth",
      "rotation": 3
    },
    {
      "x": -18,
      "y": 37,
      "z": -11,
      "name": "Soil_Clay_Ocean_Brick_Half",
      "rotation": 3
    },
    {
      "x": -18,
      "y": 1,
      "z": -10,
      "name": "Rock_Sandstone_Red_Cobble"
    },
    {
      "x": -18,
      "y": 6,
      "z": -10,
      "name": "Rock_Sandstone_Red_Brick"
    },
    {
      "x": -18,
      "y": 11,
      "z": -10,
      "name": "Rock_Sandstone_Brick"
    },
    {
      "x": -18,
      "y": 12,
      "z": -10,
      "name": "Rock_Sandstone_Cobble"
    },
    {
      "x": -18,
      "y": 18,
      "z": -10,
      "name": "Wood_Drywood_Planks"
    },
    {
      "x": -18,
      "y": 25,
      "z": -10,
      "name": "Rock_Sandstone_Brick"
    },
    {
      "x": -18,
      "y": 29,
      "z": -10,
      "name": "Rock_Sandstone_Brick"
    },
    {
      "x": -18,
      "y": 30,
      "z": -10,
      "name": "Rock_Sandstone_Brick"
    },
    {
      "x": -18,
      "y": 31,
      "z": -10,
      "name": "Rock_Sandstone_Brick",
      "rotation": 3
    },
    {
      "x": -18,
      "y": 32,
      "z": -10,
      "name": "Rock_Sandstone_Brick",
      "rotation": 3
    },
    {
      "x": -18,
      "y": 33,
      "z": -10,
      "name": "Furniture_Desert_Window",
      "rotation": 3
    },
    {
      "x": -18,
      "y": 34,
      "z": -10,
      "name": "Furniture_Desert_Window",
      "rotation": 3
    },
    {
      "x": -18,
      "y": 35,
      "z": -10,
      "name": "Rock_Sandstone_Brick",
      "rotation": 3
    },
    {
      "x": -18,
      "y": 36,
      "z": -10,
      "name": "Soil_Clay_Ocean_Brick_Smooth",
      "rotation": 3
    },
    {
      "x": -18,
      "y": 37,
      "z": -10,
      "name": "Soil_Clay_Ocean_Brick_Half",
      "rotation": 3
    },
    {
      "x": -18,
      "y": 1,
      "z": -9,
      "name": "Rock_Sandstone_Red_Cobble"
    },
    {
      "x": -18,
      "y": 6,
      "z": -9,
      "name": "Rock_Sandstone_Red_Brick"
    },
    {
      "x": -18,
      "y": 11,
      "z": -9,
      "name": "Rock_Sandstone_Brick"
    },
    {
      "x": -18,
      "y": 12,
      "z": -9,
      "name": "Rock_Sandstone_Cobble"
    },
    {
      "x": -18,
      "y": 18,
      "z": -9,
      "name": "Wood_Drywood_Planks"
    },
    {
      "x": -18,
      "y": 25,
      "z": -9,
      "name": "Rock_Sandstone_Brick"
    },
    {
      "x": -18,
      "y": 29,
      "z": -9,
      "name": "Rock_Sandstone_Brick"
    },
    {
      "x": -18,
      "y": 30,
      "z": -9,
      "name": "Rock_Sandstone_Brick"
    },
    {
      "x": -18,
      "y": 31,
      "z": -9,
      "name": "Rock_Sandstone_Brick",
      "rotation": 3
    },
    {
      "x": -18,
      "y": 32,
      "z": -9,
      "name": "Rock_Sandstone_Brick",
      "rotation": 3
    },
    {
      "x": -18,
      "y": 33,
      "z": -9,
      "name": "Rock_Sandstone_Brick",
      "rotation": 3
    },
    {
      "x": -18,
      "y": 34,
      "z": -9,
      "name": "Rock_Sandstone_Brick",
      "rotation": 3
    },
    {
      "x": -18,
      "y": 35,
      "z": -9,
      "name": "Rock_Sandstone_Brick",
      "rotation": 3
    },
    {
      "x": -18,
      "y": 36,
      "z": -9,
      "name": "Soil_Clay_Ocean_Brick_Smooth",
      "rotation": 3
    },
    {
      "x": -18,
      "y": 1,
      "z": -8,
      "name": "Rock_Sandstone_Red_Cobble"
    },
    {
      "x": -18,
      "y": 6,
      "z": -8,
      "name": "Rock_Sandstone_Red_Brick"
    },
    {
      "x": -18,
      "y": 7,
      "z": -8,
      "name": "Soil_Clay_Ocean_Brick_Smooth"
    },
    {
      "x": -18,
      "y": 8,
      "z": -8,
      "name": "Soil_Clay_Ocean_Brick_Wall"
    },
    {
      "x": -18,
      "y": 11,
      "z": -8,
      "name": "Rock_Sandstone_Brick"
    },
    {
      "x": -18,
      "y": 12,
      "z": -8,
      "name": "Rock_Sandstone_Cobble"
    },
    {
      "x": -18,
      "y": 18,
      "z": -8,
      "name": "Wood_Drywood_Planks"
    },
    {
      "x": -18,
      "y": 25,
      "z": -8,
      "name": "Rock_Sandstone_Brick"
    },
    {
      "x": -18,
      "y": 29,
      "z": -8,
      "name": "Rock_Sandstone_Brick"
    },
    {
      "x": -18,
      "y": 30,
      "z": -8,
      "name": "Rock_Sandstone_Brick"
    },
    {
      "x": -18,
      "y": 35,
      "z": -8,
      "name": "Rock_Sandstone_Brick_Stairs",
      "rotation": 9
    },
    {
      "x": -18,
      "y": 36,
      "z": -8,
      "name": "Soil_Clay_Ocean_Brick_Smooth",
      "rotation": 3
    },
    {
      "x": -18,
      "y": 1,
      "z": -7,
      "name": "Rock_Sandstone_Red_Cobble"
    },
    {
      "x": -18,
      "y": 6,
      "z": -7,
      "name": "Rock_Sandstone_Red_Brick"
    },
    {
      "x": -18,
      "y": 7,
      "z": -7,
      "name": "Soil_Clay_Ocean_Brick_Smooth"
    },
    {
      "x": -18,
      "y": 8,
      "z": -7,
      "name": "Soil_Clay_Ocean_Brick_Wall"
    },
    {
      "x": -18,
      "y": 11,
      "z": -7,
      "name": "Rock_Sandstone_Brick"
    },
    {
      "x": -18,
      "y": 12,
      "z": -7,
      "name": "Rock_Sandstone_Cobble"
    },
    {
      "x": -18,
      "y": 17,
      "z": -7,
      "name": "Cloth_Roof_Leather_Flap",
      "rotation": 2
    },
    {
      "x": -18,
      "y": 18,
      "z": -7,
      "name": "Rock_Sandstone_Brick"
    },
    {
      "x": -18,
      "y": 19,
      "z": -7,
      "name": "Rock_Sandstone_Brick"
    },
    {
      "x": -18,
      "y": 20,
      "z": -7,
      "name": "Rock_Sandstone_Brick"
    },
    {
      "x": -18,
      "y": 21,
      "z": -7,
      "name": "Rock_Sandstone_Brick"
    },
    {
      "x": -18,
      "y": 22,
      "z": -7,
      "name": "Rock_Sandstone_Brick"
    },
    {
      "x": -18,
      "y": 23,
      "z": -7,
      "name": "Rock_Gold_Brick_Smooth"
    },
    {
      "x": -18,
      "y": 24,
      "z": -7,
      "name": "Rock_Sandstone_Brick"
    },
    {
      "x": -18,
      "y": 25,
      "z": -7,
      "name": "Soil_Clay_Ocean_Brick_Ornate"
    },
    {
      "x": -18,
      "y": 26,
      "z": -7,
      "name": "Soil_Clay_Ocean_Brick_Ornate"
    },
    {
      "x": -18,
      "y": 27,
      "z": -7,
      "name": "Rock_Sandstone_Brick"
    },
    {
      "x": -18,
      "y": 28,
      "z": -7,
      "name": "Rock_Sandstone_Brick"
    },
    {
      "x": -18,
      "y": 29,
      "z": -7,
      "name": "Rock_Sandstone_Brick"
    },
    {
      "x": -18,
      "y": 30,
      "z": -7,
      "name": "*Rock_Sandstone_Brick_Stairs_State_Definitions_Inverted_Corner_Right"
    },
    {
      "x": -18,
      "y": 35,
      "z": -7,
      "name": "Rock_Sandstone_Brick_Stairs",
      "rotation": 9
    },
    {
      "x": -18,
      "y": 36,
      "z": -7,
      "name": "Soil_Clay_Ocean_Brick_Smooth",
      "rotation": 3
    },
    {
      "x": -18,
      "y": 1,
      "z": -6,
      "name": "Rock_Sandstone_Red_Cobble"
    },
    {
      "x": -18,
      "y": 6,
      "z": -6,
      "name": "Rock_Sandstone_Red_Brick"
    },
    {
      "x": -18,
      "y": 11,
      "z": -6,
      "name": "Rock_Sandstone_Brick"
    },
    {
      "x": -18,
      "y": 12,
      "z": -6,
      "name": "Rock_Sandstone_Cobble"
    },
    {
      "x": -18,
      "y": 29,
      "z": -6,
      "name": "Rock_Sandstone_Brick_Stairs",
      "rotation": 10
    },
    {
      "x": -18,
      "y": 30,
      "z": -6,
      "name": "*Rock_Sandstone_Brick_Stairs_State_Definitions_Corner_Left",
      "rotation": 3
    },
    {
      "x": -18,
      "y": 1,
      "z": -5,
      "name": "Rock_Sandstone_Red_Cobble"
    },
    {
      "x": -18,
      "y": 6,
      "z": -5,
      "name": "Rock_Sandstone_Red_Brick"
    },
    {
      "x": -18,
      "y": 11,
      "z": -5,
      "name": "Rock_Sandstone_Brick"
    },
    {
      "x": -18,
      "y": 12,
      "z": -5,
      "name": "Rock_Sandstone_Cobble"
    },
    {
      "x": -18,
      "y": 1,
      "z": -4,
      "name": "Rock_Sandstone_Red_Cobble"
    },
    {
      "x": -18,
      "y": 6,
      "z": -4,
      "name": "Rock_Sandstone_Red_Brick"
    },
    {
      "x": -18,
      "y": 1,
      "z": -3,
      "name": "Rock_Sandstone_Red_Cobble"
    },
    {
      "x": -18,
      "y": 6,
      "z": -3,
      "name": "Rock_Sandstone_Red_Brick"
    },
    {
      "x": -18,
      "y": 14,
      "z": -3,
      "name": "Rock_Sandstone_Brick_Stairs",
      "rotation": 2
    },
    {
      "x": -18,
      "y": 1,
      "z": -2,
      "name": "Rock_Sandstone_Red_Cobble"
    },
    {
      "x": -18,
      "y": 6,
      "z": -2,
      "name": "Rock_Sandstone_Red_Brick"
    },
    {
      "x": -18,
      "y": 14,
      "z": -2,
      "name": "Rock_Sandstone_Brick"
    },
    {
      "x": -18,
      "y": 1,
      "z": -1,
      "name": "Rock_Sandstone_Red_Cobble"
    },
    {
      "x": -18,
      "y": 2,
      "z": -1,
      "name": "Rock_Sandstone_Brick"
    },
    {
      "x": -18,
      "y": 3,
      "z": -1,
      "name": "Rock_Sandstone_Brick"
    },
    {
      "x": -18,
      "y": 4,
      "z": -1,
      "name": "Rock_Sandstone_White_Brick"
    },
    {
      "x": -18,
      "y": 5,
      "z": -1,
      "name": "Rock_Sandstone_Brick"
    },
    {
      "x": -18,
      "y": 6,
      "z": -1,
      "name": "Rock_Sandstone_Red_Brick"
    },
    {
      "x": -18,
      "y": 7,
      "z": -1,
      "name": "Rock_Sandstone_Brick"
    },
    {
      "x": -18,
      "y": 8,
      "z": -1,
      "name": "Rock_Sandstone_Brick"
    },
    {
      "x": -18,
      "y": 9,
      "z": -1,
      "name": "Rock_Sandstone_Brick"
    },
    {
      "x": -18,
      "y": 10,
      "z": -1,
      "name": "Rock_Sandstone_Brick"
    },
    {
      "x": -18,
      "y": 11,
      "z": -1,
      "name": "Rock_Sandstone_Brick"
    },
    {
      "x": -18,
      "y": 15,
      "z": -1,
      "name": "Rock_Sandstone_Red_Brick"
    },
    {
      "x": -18,
      "y": 16,
      "z": -1,
      "name": "Rock_Gold_Brick_Decorative"
    },
    {
      "x": -17,
      "y": 1,
      "z": -20,
      "name": "Rock_Sandstone_Red_Cobble"
    },
    {
      "x": -17,
      "y": 2,
      "z": -20,
      "name": "Rock_Sandstone_Brick"
    },
    {
      "x": -17,
      "y": 3,
      "z": -20,
      "name": "Rock_Sandstone_Brick"
    },
    {
      "x": -17,
      "y": 4,
      "z": -20,
      "name": "Rock_Sandstone_White_Brick"
    },
    {
      "x": -17,
      "y": 5,
      "z": -20,
      "name": "Rock_Sandstone_Brick"
    },
    {
      "x": -17,
      "y": 6,
      "z": -20,
      "name": "Rock_Sandstone_Red_Brick"
    },
    {
      "x": -17,
      "y": 7,
      "z": -20,
      "name": "Rock_Sandstone_Brick_Pillar_Middle"
    },
    {
      "x": -17,
      "y": 8,
      "z": -20,
      "name": "Rock_Sandstone_Brick_Pillar_Base",
      "rotation": 8
    },
    {
      "x": -17,
      "y": 9,
      "z": -20,
      "name": "Rock_Sandstone_Brick"
    },
    {
      "x": -17,
      "y": 10,
      "z": -20,
      "name": "Rock_Sandstone_Brick"
    },
    {
      "x": -17,
      "y": 1,
      "z": -19,
      "name": "Rock_Sandstone_Red_Cobble"
    },
    {
      "x": -17,
      "y": 6,
      "z": -19,
      "name": "Rock_Sandstone_Red_Brick"
    },
    {
      "x": -17,
      "y": 7,
      "z": -19,
      "name": "Rock_Sandstone_Brick"
    },
    {
      "x": -17,
      "y": 8,
      "z": -19,
      "name": "Rock_Sandstone_Brick"
    },
    {
      "x": -17,
      "y": 9,
      "z": -19,
      "name": "Rock_Sandstone_Brick"
    },
    {
      "x": -17,
      "y": 10,
      "z": -19,
      "name": "Rock_Sandstone_Brick"
    },
    {
      "x": -17,
      "y": 11,
      "z": -19,
      "name": "Rock_Sandstone"
    },
    {
      "x": -17,
      "y": 12,
      "z": -19,
      "name": "Rock_Sandstone"
    },
    {
      "x": -17,
      "y": 1,
      "z": -18,
      "name": "Rock_Sandstone_Red_Cobble"
    },
    {
      "x": -17,
      "y": 6,
      "z": -18,
      "name": "Rock_Sandstone_Red_Brick"
    },
    {
      "x": -17,
      "y": 7,
      "z": -18,
      "name": "Rock_Sandstone_Brick"
    },
    {
      "x": -17,
      "y": 8,
      "z": -18,
      "name": "Rock_Sandstone_Brick"
    },
    {
      "x": -17,
      "y": 9,
      "z": -18,
      "name": "Rock_Sandstone_Brick"
    },
    {
      "x": -17,
      "y": 10,
      "z": -18,
      "name": "Rock_Sandstone_Brick"
    },
    {
      "x": -17,
      "y": 11,
      "z": -18,
      "name": "Rock_Sandstone"
    },
    {
      "x": -17,
      "y": 12,
      "z": -18,
      "name": "Rock_Sandstone"
    },
    {
      "x": -17,
      "y": 1,
      "z": -17,
      "name": "Rock_Sandstone_Red_Cobble"
    },
    {
      "x": -17,
      "y": 6,
      "z": -17,
      "name": "Rock_Sandstone_Red_Brick"
    },
    {
      "x": -17,
      "y": 8,
      "z": -17,
      "name": "Rock_Sandstone_Brick"
    },
    {
      "x": -17,
      "y": 9,
      "z": -17,
      "name": "Rock_Sandstone_Brick"
    },
    {
      "x": -17,
      "y": 10,
      "z": -17,
      "name": "Rock_Sandstone_Brick"
    },
    {
      "x": -17,
      "y": 11,
      "z": -17,
      "name": "Rock_Sandstone_Brick"
    },
    {
      "x": -17,
      "y": 12,
      "z": -17,
      "name": "Rock_Sandstone_Brick"
    },
    {
      "x": -17,
      "y": 13,
      "z": -17,
      "name": "Rock_Sandstone_Brick"
    },
    {
      "x": -17,
      "y": 14,
      "z": -17,
      "name": "Rock_Sandstone_Red_Brick"
    },
    {
      "x": -17,
      "y": 15,
      "z": -17,
      "name": "Rock_Sandstone_Red_Brick"
    },
    {
      "x": -17,
      "y": 16,
      "z": -17,
      "name": "Rock_Sandstone_Red_Brick"
    },
    {
      "x": -17,
      "y": 17,
      "z": -17,
      "name": "Rock_Sandstone_Brick"
    },
    {
      "x": -17,
      "y": 18,
      "z": -17,
      "name": "Rock_Sandstone_Brick"
    },
    {
      "x": -17,
      "y": 19,
      "z": -17,
      "name": "Rock_Sandstone_Brick"
    },
    {
      "x": -17,
      "y": 20,
      "z": -17,
      "name": "Rock_Sandstone_Brick"
    },
    {
      "x": -17,
      "y": 21,
      "z": -17,
      "name": "Rock_Sandstone_Brick"
    },
    {
      "x": -17,
      "y": 22,
      "z": -17,
      "name": "Rock_Sandstone_Brick"
    },
    {
      "x": -17,
      "y": 23,
      "z": -17,
      "name": "Rock_Gold_Brick_Smooth"
    },
    {
      "x": -17,
      "y": 24,
      "z": -17,
      "name": "Rock_Sandstone_Brick"
    },
    {
      "x": -17,
      "y": 25,
      "z": -17,
      "name": "Soil_Clay_Ocean_Brick_Ornate"
    },
    {
      "x": -17,
      "y": 26,
      "z": -17,
      "name": "Soil_Clay_Ocean_Brick_Ornate"
    },
    {
      "x": -17,
      "y": 27,
      "z": -17,
      "name": "Rock_Sandstone_Brick"
    },
    {
      "x": -17,
      "y": 28,
      "z": -17,
      "name": "Rock_Sandstone_Brick"
    },
    {
      "x": -17,
      "y": 29,
      "z": -17,
      "name": "Rock_Sandstone_Brick"
    },
    {
      "x": -17,
      "y": 30,
      "z": -17,
      "name": "Rock_Sandstone_Brick_Stairs",
      "rotation": 2
    },
    {
      "x": -17,
      "y": 35,
      "z": -17,
      "name": "Rock_Sandstone_Brick_Stairs",
      "rotation": 9
    },
    {
      "x": -17,
      "y": 36,
      "z": -17,
      "name": "Soil_Clay_Ocean_Brick_Smooth",
      "rotation": 3
    },
    {
      "x": -17,
      "y": 1,
      "z": -16,
      "name": "Rock_Sandstone_Red_Cobble"
    },
    {
      "x": -17,
      "y": 6,
      "z": -16,
      "name": "Rock_Sandstone_Red_Brick"
    },
    {
      "x": -17,
      "y": 11,
      "z": -16,
      "name": "Rock_Sandstone_Brick"
    },
    {
      "x": -17,
      "y": 12,
      "z": -16,
      "name": "Rock_Sandstone_Brick"
    },
    {
      "x": -17,
      "y": 13,
      "z": -16,
      "name": "Rock_Sandstone_Brick"
    },
    {
      "x": -17,
      "y": 14,
      "z": -16,
      "name": "Rock_Sandstone_Brick"
    },
    {
      "x": -17,
      "y": 15,
      "z": -16,
      "name": "Rock_Sandstone_Brick"
    },
    {
      "x": -17,
      "y": 16,
      "z": -16,
      "name": "Rock_Sandstone_Brick"
    },
    {
      "x": -17,
      "y": 17,
      "z": -16,
      "name": "Rock_Sandstone_Brick"
    },
    {
      "x": -17,
      "y": 18,
      "z": -16,
      "name": "Wood_Drywood_Planks"
    },
    {
      "x": -17,
      "y": 25,
      "z": -16,
      "name": "Rock_Sandstone_Brick"
    },
    {
      "x": -17,
      "y": 29,
      "z": -16,
      "name": "Rock_Sandstone_Brick"
    },
    {
      "x": -17,
      "y": 30,
      "z": -16,
      "name": "Rock_Sandstone_Brick"
    },
    {
      "x": -17,
      "y": 31,
      "z": -16,
      "name": "Rock_Sandstone_Brick",
      "rotation": 3
    },
    {
      "x": -17,
      "y": 32,
      "z": -16,
      "name": "Rock_Sandstone_Brick",
      "rotation": 3
    },
    {
      "x": -17,
      "y": 33,
      "z": -16,
      "name": "Rock_Sandstone_Brick",
      "rotation": 3
    },
    {
      "x": -17,
      "y": 34,
      "z": -16,
      "name": "Rock_Sandstone_Brick",
      "rotation": 3
    },
    {
      "x": -17,
      "y": 35,
      "z": -16,
      "name": "Rock_Sandstone_Brick",
      "rotation": 3
    },
    {
      "x": -17,
      "y": 36,
      "z": -16,
      "name": "Soil_Clay_Ocean_Brick_Smooth",
      "rotation": 3
    },
    {
      "x": -17,
      "y": 1,
      "z": -15,
      "name": "Rock_Sandstone_Red_Cobble"
    },
    {
      "x": -17,
      "y": 6,
      "z": -15,
      "name": "Rock_Sandstone_Red_Brick"
    },
    {
      "x": -17,
      "y": 11,
      "z": -15,
      "name": "Rock_Sandstone_Brick"
    },
    {
      "x": -17,
      "y": 12,
      "z": -15,
      "name": "Rock_Sandstone_Brick"
    },
    {
      "x": -17,
      "y": 17,
      "z": -15,
      "name": "Rock_Sandstone_Brick"
    },
    {
      "x": -17,
      "y": 18,
      "z": -15,
      "name": "Wood_Drywood_Planks"
    },
    {
      "x": -17,
      "y": 25,
      "z": -15,
      "name": "Rock_Sandstone_Brick"
    },
    {
      "x": -17,
      "y": 29,
      "z": -15,
      "name": "Rock_Sandstone_Brick"
    },
    {
      "x": -17,
      "y": 30,
      "z": -15,
      "name": "Rock_Sandstone_Brick"
    },
    {
      "x": -17,
      "y": 31,
      "z": -15,
      "name": "Rock_Sandstone_Brick",
      "rotation": 3
    },
    {
      "x": -17,
      "y": 32,
      "z": -15,
      "name": "Rock_Sandstone_Brick",
      "rotation": 3
    },
    {
      "x": -17,
      "y": 33,
      "z": -15,
      "name": "Rock_Sandstone_Brick",
      "rotation": 3
    },
    {
      "x": -17,
      "y": 34,
      "z": -15,
      "name": "Rock_Sandstone_Brick",
      "rotation": 3
    },
    {
      "x": -17,
      "y": 35,
      "z": -15,
      "name": "Rock_Sandstone_Brick",
      "rotation": 3
    },
    {
      "x": -17,
      "y": 36,
      "z": -15,
      "name": "Soil_Clay_Ocean_Brick_Smooth",
      "rotation": 3
    },
    {
      "x": -17,
      "y": 37,
      "z": -15,
      "name": "Soil_Clay_Ocean_Brick_Half",
      "rotation": 3
    },
    {
      "x": -17,
      "y": 1,
      "z": -14,
      "name": "Rock_Sandstone_Red_Cobble"
    },
    {
      "x": -17,
      "y": 6,
      "z": -14,
      "name": "Rock_Sandstone_Red_Brick"
    },
    {
      "x": -17,
      "y": 11,
      "z": -14,
      "name": "Rock_Sandstone_Brick"
    },
    {
      "x": -17,
      "y": 12,
      "z": -14,
      "name": "Rock_Sandstone_Brick"
    },
    {
      "x": -17,
      "y": 18,
      "z": -14,
      "name": "Wood_Drywood_Planks"
    },
    {
      "x": -17,
      "y": 25,
      "z": -14,
      "name": "Rock_Sandstone_Brick"
    },
    {
      "x": -17,
      "y": 29,
      "z": -14,
      "name": "Rock_Sandstone_Brick"
    },
    {
      "x": -17,
      "y": 30,
      "z": -14,
      "name": "Rock_Sandstone_Brick"
    },
    {
      "x": -17,
      "y": 31,
      "z": -14,
      "name": "Rock_Sandstone_Brick",
      "rotation": 3
    },
    {
      "x": -17,
      "y": 36,
      "z": -14,
      "name": "Soil_Clay_Ocean_Brick_Smooth",
      "rotation": 3
    },
    {
      "x": -17,
      "y": 37,
      "z": -14,
      "name": "Soil_Clay_Ocean_Brick_Half",
      "rotation": 3
    },
    {
      "x": -17,
      "y": 1,
      "z": -13,
      "name": "Rock_Sandstone_Red_Cobble"
    },
    {
      "x": -17,
      "y": 6,
      "z": -13,
      "name": "Rock_Sandstone_Red_Brick"
    },
    {
      "x": -17,
      "y": 11,
      "z": -13,
      "name": "Rock_Sandstone_Brick"
    },
    {
      "x": -17,
      "y": 12,
      "z": -13,
      "name": "Rock_Sandstone_Brick"
    },
    {
      "x": -17,
      "y": 18,
      "z": -13,
      "name": "Wood_Drywood_Planks"
    },
    {
      "x": -17,
      "y": 25,
      "z": -13,
      "name": "Rock_Sandstone_Brick"
    },
    {
      "x": -17,
      "y": 29,
      "z": -13,
      "name": "Rock_Sandstone_Brick"
    },
    {
      "x": -17,
      "y": 31,
      "z": -13,
      "name": "Rock_Sandstone_Brick",
      "rotation": 3
    },
    {
      "x": -17,
      "y": 36,
      "z": -13,
      "name": "Soil_Clay_Ocean_Brick_Smooth",
      "rotation": 3
    },
    {
      "x": -17,
      "y": 37,
      "z": -13,
      "name": "Rock_Sandstone_Brick_Smooth",
      "rotation": 3
    },
    {
      "x": -17,
      "y": 1,
      "z": -12,
      "name": "Rock_Sandstone_Red_Cobble"
    },
    {
      "x": -17,
      "y": 6,
      "z": -12,
      "name": "Rock_Sandstone_Red_Brick"
    },
    {
      "x": -17,
      "y": 11,
      "z": -12,
      "name": "Rock_Sandstone_Brick"
    },
    {
      "x": -17,
      "y": 12,
      "z": -12,
      "name": "Rock_Sandstone_Brick"
    },
    {
      "x": -17,
      "y": 18,
      "z": -12,
      "name": "Wood_Drywood_Planks"
    },
    {
      "x": -17,
      "y": 25,
      "z": -12,
      "name": "Rock_Sandstone_Brick"
    },
    {
      "x": -17,
      "y": 36,
      "z": -12,
      "name": "Soil_Clay_Ocean_Brick_Smooth",
      "rotation": 3
    },
    {
      "x": -17,
      "y": 37,
      "z": -12,
      "name": "Rock_Sandstone_Brick_Smooth",
      "rotation": 3
    },
    {
      "x": -17,
      "y": 1,
      "z": -11,
      "name": "Rock_Sandstone_Red_Cobble"
    },
    {
      "x": -17,
      "y": 4,
      "z": -11,
      "name": "Rock_Sandstone_White_Brick_Half",
      "rotation": 8
    },
    {
      "x": -17,
      "y": 5,
      "z": -11,
      "name": "Rock_Sandstone_Brick"
    },
    {
      "x": -17,
      "y": 6,
      "z": -11,
      "name": "Rock_Sandstone_Red_Brick"
    },
    {
      "x": -17,
      "y": 11,
      "z": -11,
      "name": "Rock_Sandstone_Brick"
    },
    {
      "x": -17,
      "y": 12,
      "z": -11,
      "name": "Rock_Sandstone_Brick"
    },
    {
      "x": -17,
      "y": 18,
      "z": -11,
      "name": "Wood_Drywood_Planks"
    },
    {
      "x": -17,
      "y": 25,
      "z": -11,
      "name": "Rock_Sandstone_Brick"
    },
    {
      "x": -17,
      "y": 36,
      "z": -11,
      "name": "Soil_Clay_Ocean_Brick_Smooth",
      "rotation": 3
    },
    {
      "x": -17,
      "y": 37,
      "z": -11,
      "name": "Rock_Sandstone_Brick_Smooth",
      "rotation": 3
    },
    {
      "x": -17,
      "y": 1,
      "z": -10,
      "name": "Rock_Sandstone_Red_Cobble"
    },
    {
      "x": -17,
      "y": 6,
      "z": -10,
      "name": "Rock_Sandstone_Red_Brick"
    },
    {
      "x": -17,
      "y": 11,
      "z": -10,
      "name": "Rock_Sandstone_Brick"
    },
    {
      "x": -17,
      "y": 12,
      "z": -10,
      "name": "Rock_Sandstone_Brick"
    },
    {
      "x": -17,
      "y": 18,
      "z": -10,
      "name": "Wood_Drywood_Planks"
    },
    {
      "x": -17,
      "y": 25,
      "z": -10,
      "name": "Rock_Sandstone_Brick"
    },
    {
      "x": -17,
      "y": 29,
      "z": -10,
      "name": "Rock_Sandstone_Brick"
    },
    {
      "x": -17,
      "y": 36,
      "z": -10,
      "name": "Soil_Clay_Ocean_Brick_Smooth",
      "rotation": 3
    },
    {
      "x": -17,
      "y": 37,
      "z": -10,
      "name": "Rock_Sandstone_Brick_Smooth",
      "rotation": 3
    },
    {
      "x": -17,
      "y": 1,
      "z": -9,
      "name": "Rock_Sandstone_Red_Cobble"
    },
    {
      "x": -17,
      "y": 6,
      "z": -9,
      "name": "Rock_Sandstone_Red_Brick"
    },
    {
      "x": -17,
      "y": 11,
      "z": -9,
      "name": "Rock_Sandstone_Brick"
    },
    {
      "x": -17,
      "y": 12,
      "z": -9,
      "name": "Rock_Sandstone_Brick"
    },
    {
      "x": -17,
      "y": 18,
      "z": -9,
      "name": "Wood_Drywood_Planks"
    },
    {
      "x": -17,
      "y": 25,
      "z": -9,
      "name": "Rock_Sandstone_Brick"
    },
    {
      "x": -17,
      "y": 29,
      "z": -9,
      "name": "Rock_Sandstone_Brick"
    },
    {
      "x": -17,
      "y": 31,
      "z": -9,
      "name": "Rock_Sandstone_Brick",
      "rotation": 3
    },
    {
      "x": -17,
      "y": 36,
      "z": -9,
      "name": "Soil_Clay_Ocean_Brick_Smooth",
      "rotation": 3
    },
    {
      "x": -17,
      "y": 37,
      "z": -9,
      "name": "Soil_Clay_Ocean_Brick_Half",
      "rotation": 3
    },
    {
      "x": -17,
      "y": 1,
      "z": -8,
      "name": "Rock_Sandstone_Red_Cobble"
    },
    {
      "x": -17,
      "y": 6,
      "z": -8,
      "name": "Rock_Sandstone_Red_Brick"
    },
    {
      "x": -17,
      "y": 7,
      "z": -8,
      "name": "Soil_Clay_Ocean_Brick_Smooth"
    },
    {
      "x": -17,
      "y": 8,
      "z": -8,
      "name": "Soil_Clay_Ocean_Brick_Wall"
    },
    {
      "x": -17,
      "y": 11,
      "z": -8,
      "name": "Rock_Sandstone_Brick"
    },
    {
      "x": -17,
      "y": 12,
      "z": -8,
      "name": "Rock_Sandstone_Brick"
    },
    {
      "x": -17,
      "y": 18,
      "z": -8,
      "name": "Wood_Drywood_Planks"
    },
    {
      "x": -17,
      "y": 25,
      "z": -8,
      "name": "Rock_Sandstone_Brick"
    },
    {
      "x": -17,
      "y": 29,
      "z": -8,
      "name": "Rock_Sandstone_Brick"
    },
    {
      "x": -17,
      "y": 30,
      "z": -8,
      "name": "Rock_Sandstone_Brick"
    },
    {
      "x": -17,
      "y": 31,
      "z": -8,
      "name": "Rock_Sandstone_Brick",
      "rotation": 3
    },
    {
      "x": -17,
      "y": 32,
      "z": -8,
      "name": "Rock_Sandstone_Brick",
      "rotation": 3
    },
    {
      "x": -17,
      "y": 33,
      "z": -8,
      "name": "Rock_Sandstone_Brick",
      "rotation": 3
    },
    {
      "x": -17,
      "y": 34,
      "z": -8,
      "name": "Rock_Sandstone_Brick",
      "rotation": 3
    },
    {
      "x": -17,
      "y": 35,
      "z": -8,
      "name": "Rock_Sandstone_Brick",
      "rotation": 3
    },
    {
      "x": -17,
      "y": 36,
      "z": -8,
      "name": "Soil_Clay_Ocean_Brick_Smooth",
      "rotation": 3
    },
    {
      "x": -17,
      "y": 37,
      "z": -8,
      "name": "Soil_Clay_Ocean_Brick_Half",
      "rotation": 3
    },
    {
      "x": -17,
      "y": 1,
      "z": -7,
      "name": "Rock_Sandstone_Red_Cobble"
    },
    {
      "x": -17,
      "y": 6,
      "z": -7,
