{
  "version": 8,
  "blockIdVersion": 11,
  "anchorX": -11,
  "anchorY": 1,
  "anchorZ": -11,
  "blocks": [
    {
      "x": -21,
      "y": 1,
      "z": -19,
      "name": "Rock_Sandstone_Red_Brick",
      "rotation": 3
    },
    {
      "x": -21,
      "y": 2,
      "z": -19,
      "name": "Rock_Sandstone_Red_Brick",
      "rotation": 3
    },
    {
      "x": -21,
      "y": 3,
      "z": -19,
      "name": "Rock_Sandstone_Red_Brick_Stairs",
      "rotation": 3
    },
    {
      "x": -21,
      "y": 1,
      "z": -18,
      "name": "Rock_Sandstone_Red_Cobble",
      "rotation": 3
    },
    {
      "x": -21,
      "y": 2,
      "z": -18,
      "name": "Rock_Sandstone_Red_Brick",
      "rotation": 3
    },
    {
      "x": -21,
      "y": 3,
      "z": -18,
      "name": "Rock_Sandstone_Red_Brick_Stairs",
      "rotation": 3
    },
    {
      "x": -21,
      "y": 1,
      "z": -16,
      "name": "Rock_Sandstone"
    },
    {
      "x": -21,
      "y": 1,
      "z": -15,
      "name": "Rock_Sandstone_Red_Brick",
      "rotation": 3
    },
    {
      "x": -21,
      "y": 2,
      "z": -15,
      "name": "Rock_Sandstone_Red_Brick",
      "rotation": 3
    },
    {
      "x": -21,
      "y": 3,
      "z": -15,
      "name": "Rock_Sandstone_Red_Brick_Stairs",
      "rotation": 3
    },
    {
      "x": -21,
      "y": 1,
      "z": -14,
      "name": "Rock_Sandstone_Red_Cobble",
      "rotation": 3
    },
    {
      "x": -21,
      "y": 2,
      "z": -14,
      "name": "Rock_Sandstone_Red_Brick",
      "rotation": 3
    },
    {
      "x": -21,
      "y": 3,
      "z": -14,
      "name": "Rock_Sandstone_Red_Brick_Stairs",
      "rotation": 3
    },
    {
      "x": -21,
      "y": 1,
      "z": -11,
      "name": "Rock_Sandstone_Red_Cobble",
      "rotation": 3
    },
    {
      "x": -21,
      "y": 2,
      "z": -11,
      "name": "Rock_Sandstone_Red_Brick",
      "rotation": 3
    },
    {
      "x": -21,
      "y": 3,
      "z": -11,
      "name": "Rock_Sandstone_Red_Brick_Stairs",
      "rotation": 3
    },
    {
      "x": -21,
      "y": 1,
      "z": -10,
      "name": "Rock_Sandstone_Red_Brick",
      "rotation": 3
    },
    {
      "x": -21,
      "y": 2,
      "z": -10,
      "name": "Rock_Sandstone_Red_Brick",
      "rotation": 3
    },
    {
      "x": -21,
      "y": 3,
      "z": -10,
      "name": "Rock_Sandstone_Red_Brick_Stairs",
      "rotation": 3
    },
    {
      "x": -21,
      "y": 1,
      "z": -7,
      "name": "Rock_Sandstone_Red_Brick",
      "rotation": 3
    },
    {
      "x": -21,
      "y": 2,
      "z": -7,
      "name": "Rock_Sandstone_Red_Brick",
      "rotation": 3
    },
    {
      "x": -21,
      "y": 3,
      "z": -7,
      "name": "Rock_Sandstone_Red_Brick_Stairs",
      "rotation": 3
    },
    {
      "x": -21,
      "y": 1,
      "z": -6,
      "name": "Rock_Sandstone_Red_Brick",
      "rotation": 3
    },
    {
      "x": -21,
      "y": 2,
      "z": -6,
      "name": "Rock_Sandstone_Red_Brick",
      "rotation": 3
    },
    {
      "x": -21,
      "y": 3,
      "z": -6,
      "name": "Rock_Sandstone_Red_Brick_Stairs",
      "rotation": 3
    },
    {
      "x": -21,
      "y": 1,
      "z": -5,
      "name": "Rock_Sandstone",
      "rotation": 3
    },
    {
      "x": -21,
      "y": 1,
      "z": -3,
      "name": "Rock_Sandstone_Red_Cobble",
      "rotation": 3
    },
    {
      "x": -21,
      "y": 2,
      "z": -3,
      "name": "Rock_Sandstone_Red_Brick",
      "rotation": 3
    },
    {
      "x": -21,
      "y": 3,
      "z": -3,
      "name": "Rock_Sandstone_Red_Brick_Stairs",
      "rotation": 3
    },
    {
      "x": -21,
      "y": 1,
      "z": -2,
      "name": "Rock_Sandstone_Red_Brick",
      "rotation": 3
    },
    {
      "x": -21,
      "y": 2,
      "z": -2,
      "name": "Rock_Sandstone_Red_Brick",
      "rotation": 3
    },
    {
      "x": -21,
      "y": 3,
      "z": -2,
      "name": "Rock_Sandstone_Red_Brick_Stairs",
      "rotation": 3
    },
    {
      "x": -20,
      "y": 1,
      "z": -19,
      "name": "Rock_Sandstone_Red_Brick",
      "rotation": 3
    },
    {
      "x": -20,
      "y": 2,
      "z": -19,
      "name": "Rock_Sandstone_Red_Brick",
      "rotation": 3
    },
    {
      "x": -20,
      "y": 3,
      "z": -19,
      "name": "Rock_Sandstone_Red_Brick",
      "rotation": 3
    },
    {
      "x": -20,
      "y": 4,
      "z": -19,
      "name": "Rock_Sandstone_Red_Brick_Stairs",
      "rotation": 3
    },
    {
      "x": -20,
      "y": 1,
      "z": -18,
      "name": "Rock_Sandstone_Red_Cobble",
      "rotation": 3
    },
    {
      "x": -20,
      "y": 2,
      "z": -18,
      "name": "Rock_Sandstone_Red_Brick",
      "rotation": 3
    },
    {
      "x": -20,
      "y": 3,
      "z": -18,
      "name": "Rock_Sandstone_Red_Brick",
      "rotation": 3
    },
    {
      "x": -20,
      "y": 4,
      "z": -18,
      "name": "Rock_Sandstone_Red_Brick_Stairs",
      "rotation": 3
    },
    {
      "x": -20,
      "y": 1,
      "z": -17,
      "name": "Rock_Sandstone"
    },
    {
      "x": -20,
      "y": 1,
      "z": -16,
      "name": "Rock_Sandstone"
    },
    {
      "x": -20,
      "y": 1,
      "z": -15,
      "name": "Rock_Sandstone_Red_Brick",
      "rotation": 3
    },
    {
      "x": -20,
      "y": 2,
      "z": -15,
      "name": "Rock_Sandstone_Red_Brick",
      "rotation": 3
    },
    {
      "x": -20,
      "y": 3,
      "z": -15,
      "name": "Rock_Sandstone_Red_Brick",
      "rotation": 3
    },
    {
      "x": -20,
      "y": 4,
      "z": -15,
      "name": "Rock_Sandstone_Red_Brick_Stairs",
      "rotation": 3
    },
    {
      "x": -20,
      "y": 1,
      "z": -14,
      "name": "Rock_Sandstone_Red_Brick",
      "rotation": 3
    },
    {
      "x": -20,
      "y": 2,
      "z": -14,
      "name": "Rock_Sandstone_Red_Brick",
      "rotation": 3
    },
    {
      "x": -20,
      "y": 3,
      "z": -14,
      "name": "Rock_Sandstone_Red_Brick",
      "rotation": 3
    },
    {
      "x": -20,
      "y": 4,
      "z": -14,
      "name": "Rock_Sandstone_Red_Brick_Stairs",
      "rotation": 3
    },
    {
      "x": -20,
      "y": 1,
      "z": -13,
      "name": "Rock_Sandstone"
    },
    {
      "x": -20,
      "y": 2,
      "z": -13,
      "name": "Rock_Sandstone"
    },
    {
      "x": -20,
      "y": 1,
      "z": -12,
      "name": "Rock_Sandstone"
    },
    {
      "x": -20,
      "y": 1,
      "z": -11,
      "name": "Rock_Sandstone_Red_Cobble",
      "rotation": 3
    },
    {
      "x": -20,
      "y": 2,
      "z": -11,
      "name": "Rock_Sandstone_Red_Cobble",
      "rotation": 3
    },
    {
      "x": -20,
      "y": 3,
      "z": -11,
      "name": "Rock_Sandstone_Red_Brick",
      "rotation": 3
    },
    {
      "x": -20,
      "y": 4,
      "z": -11,
      "name": "Rock_Sandstone_Red_Brick_Stairs",
      "rotation": 3
    },
    {
      "x": -20,
      "y": 1,
      "z": -10,
      "name": "Rock_Sandstone_Red_Brick",
      "rotation": 3
    },
    {
      "x": -20,
      "y": 2,
      "z": -10,
      "name": "Rock_Sandstone_Red_Brick",
      "rotation": 3
    },
    {
      "x": -20,
      "y": 3,
      "z": -10,
      "name": "Rock_Sandstone_Red_Brick",
      "rotation": 3
    },
    {
      "x": -20,
      "y": 4,
      "z": -10,
      "name": "Rock_Sandstone_Red_Brick_Stairs",
      "rotation": 3
    },
    {
      "x": -20,
      "y": 1,
      "z": -9,
      "name": "Rock_Sandstone_Cobble",
      "rotation": 3
    },
    {
      "x": -20,
      "y": 1,
      "z": -7,
      "name": "Rock_Sandstone_Red_Brick",
      "rotation": 3
    },
    {
      "x": -20,
      "y": 2,
      "z": -7,
      "name": "Rock_Sandstone_Red_Brick",
      "rotation": 3
    },
    {
      "x": -20,
      "y": 3,
      "z": -7,
      "name": "Rock_Sandstone_Red_Brick",
      "rotation": 3
    },
    {
      "x": -20,
      "y": 4,
      "z": -7,
      "name": "Rock_Sandstone_Red_Brick_Stairs",
      "rotation": 3
    },
    {
      "x": -20,
      "y": 1,
      "z": -6,
      "name": "Rock_Sandstone_Red_Brick",
      "rotation": 3
    },
    {
      "x": -20,
      "y": 2,
      "z": -6,
      "name": "Rock_Sandstone_Red_Brick",
      "rotation": 3
    },
    {
      "x": -20,
      "y": 3,
      "z": -6,
      "name": "Rock_Sandstone_Red_Brick",
      "rotation": 3
    },
    {
      "x": -20,
      "y": 4,
      "z": -6,
      "name": "Rock_Sandstone_Red_Brick_Stairs",
      "rotation": 3
    },
    {
      "x": -20,
      "y": 1,
      "z": -5,
      "name": "Rock_Sandstone",
      "rotation": 3
    },
    {
      "x": -20,
      "y": 1,
      "z": -4,
      "name": "Rock_Sandstone",
      "rotation": 3
    },
    {
      "x": -20,
      "y": 1,
      "z": -3,
      "name": "Rock_Sandstone_Red_Brick",
      "rotation": 3
    },
    {
      "x": -20,
      "y": 2,
      "z": -3,
      "name": "Rock_Sandstone_Red_Brick",
      "rotation": 3
    },
    {
      "x": -20,
      "y": 3,
      "z": -3,
      "name": "Rock_Sandstone_Red_Brick",
      "rotation": 3
    },
    {
      "x": -20,
      "y": 4,
      "z": -3,
      "name": "Rock_Sandstone_Red_Brick_Stairs",
      "rotation": 3
    },
    {
      "x": -20,
      "y": 1,
      "z": -2,
      "name": "Rock_Sandstone_Red_Brick",
      "rotation": 3
    },
    {
      "x": -20,
      "y": 2,
      "z": -2,
      "name": "Rock_Sandstone_Red_Brick",
      "rotation": 3
    },
    {
      "x": -20,
      "y": 3,
      "z": -2,
      "name": "Rock_Sandstone_Red_Brick",
      "rotation": 3
    },
    {
      "x": -20,
      "y": 4,
      "z": -2,
      "name": "Rock_Sandstone_Red_Brick_Stairs",
      "rotation": 3
    },
    {
      "x": -19,
      "y": 1,
      "z": -21,
      "name": "Rock_Sandstone_Red_Cobble",
      "rotation": 3
    },
    {
      "x": -19,
      "y": 2,
      "z": -21,
      "name": "Rock_Sandstone_Red_Brick",
      "rotation": 3
    },
    {
      "x": -19,
      "y": 3,
      "z": -21,
      "name": "Rock_Sandstone_Red_Brick_Stairs",
      "rotation": 2
    },
    {
      "x": -19,
      "y": 1,
      "z": -20,
      "name": "Rock_Sandstone_Red_Brick",
      "rotation": 3
    },
    {
      "x": -19,
      "y": 2,
      "z": -20,
      "name": "Rock_Sandstone_Red_Brick",
      "rotation": 3
    },
    {
      "x": -19,
      "y": 3,
      "z": -20,
      "name": "Rock_Sandstone_Red_Brick",
      "rotation": 3
    },
    {
      "x": -19,
      "y": 4,
      "z": -20,
      "name": "Rock_Sandstone_Red_Brick_Stairs",
      "rotation": 2
    },
    {
      "x": -19,
      "y": 1,
      "z": -19,
      "name": "Rock_Sandstone_Brick",
      "rotation": 3
    },
    {
      "x": -19,
      "y": 2,
      "z": -19,
      "name": "Rock_Sandstone_Brick",
      "rotation": 3
    },
    {
      "x": -19,
      "y": 3,
      "z": -19,
      "name": "Rock_Sandstone_Brick",
      "rotation": 3
    },
    {
      "x": -19,
      "y": 4,
      "z": -19,
      "name": "Rock_Sandstone_Brick",
      "rotation": 3
    },
    {
      "x": -19,
      "y": 5,
      "z": -19,
      "name": "Rock_Sandstone_Brick_Ornate",
      "rotation": 3
    },
    {
      "x": -19,
      "y": 6,
      "z": -19,
      "name": "*Rock_Sandstone_Brick_Stairs_State_Definitions_Corner_Right",
      "rotation": 3
    },
    {
      "x": -19,
      "y": 1,
      "z": -18,
      "name": "Rock_Sandstone_Brick",
      "rotation": 3
    },
    {
      "x": -19,
      "y": 2,
      "z": -18,
      "name": "Rock_Sandstone_Brick",
      "rotation": 3
    },
    {
      "x": -19,
      "y": 3,
      "z": -18,
      "name": "Rock_Sandstone_Brick",
      "rotation": 3
    },
    {
      "x": -19,
      "y": 4,
      "z": -18,
      "name": "Rock_Sandstone_Brick",
      "rotation": 3
    },
    {
      "x": -19,
      "y": 5,
      "z": -18,
      "name": "Rock_Sandstone_Brick_Ornate",
      "rotation": 3
    },
    {
      "x": -19,
      "y": 6,
      "z": -18,
      "name": "Rock_Sandstone_Brick_Stairs",
      "rotation": 3
    },
    {
      "x": -19,
      "y": 1,
      "z": -17,
      "name": "Rock_Sandstone_Brick",
      "rotation": 3
    },
    {
      "x": -19,
      "y": 2,
      "z": -17,
      "name": "Rock_Sandstone_Cobble",
      "rotation": 3
    },
    {
      "x": -19,
      "y": 3,
      "z": -17,
      "name": "Rock_Sandstone_Brick",
      "rotation": 3
    },
    {
      "x": -19,
      "y": 4,
      "z": -17,
      "name": "Rock_Sandstone_Cobble",
      "rotation": 3
    },
    {
      "x": -19,
      "y": 5,
      "z": -17,
      "name": "Rock_Sandstone_Brick_Ornate",
      "rotation": 3
    },
    {
      "x": -19,
      "y": 6,
      "z": -17,
      "name": "Rock_Sandstone_Brick_Stairs",
      "rotation": 3
    },
    {
      "x": -19,
      "y": 1,
      "z": -16,
      "name": "Rock_Sandstone_Brick",
      "rotation": 3
    },
    {
      "x": -19,
      "y": 2,
      "z": -16,
      "name": "Rock_Sandstone_Brick",
      "rotation": 3
    },
    {
      "x": -19,
      "y": 3,
      "z": -16,
      "name": "Rock_Sandstone_Cobble",
      "rotation": 3
    },
    {
      "x": -19,
      "y": 4,
      "z": -16,
      "name": "Rock_Sandstone_Cobble",
      "rotation": 3
    },
    {
      "x": -19,
      "y": 5,
      "z": -16,
      "name": "Rock_Sandstone_Brick_Ornate",
      "rotation": 3
    },
    {
      "x": -19,
      "y": 6,
      "z": -16,
      "name": "Rock_Sandstone_Brick_Stairs",
      "rotation": 3
    },
    {
      "x": -19,
      "y": 1,
      "z": -15,
      "name": "Rock_Sandstone_Brick",
      "rotation": 3
    },
    {
      "x": -19,
      "y": 2,
      "z": -15,
      "name": "Rock_Sandstone_Brick",
      "rotation": 3
    },
    {
      "x": -19,
      "y": 3,
      "z": -15,
      "name": "Rock_Sandstone_Brick",
      "rotation": 3
    },
    {
      "x": -19,
      "y": 4,
      "z": -15,
      "name": "Rock_Sandstone_Brick",
      "rotation": 3
    },
    {
      "x": -19,
      "y": 5,
      "z": -15,
      "name": "Rock_Sandstone_Brick_Ornate",
      "rotation": 3
    },
    {
      "x": -19,
      "y": 6,
      "z": -15,
      "name": "Rock_Sandstone_Brick_Stairs",
      "rotation": 3
    },
    {
      "x": -19,
      "y": 1,
      "z": -14,
      "name": "Rock_Sandstone_Brick",
      "rotation": 3
    },
    {
      "x": -19,
      "y": 2,
      "z": -14,
      "name": "Rock_Sandstone_Brick",
      "rotation": 3
    },
    {
      "x": -19,
      "y": 3,
      "z": -14,
      "name": "Rock_Sandstone_Brick",
      "rotation": 3
    },
    {
      "x": -19,
      "y": 4,
      "z": -14,
      "name": "Rock_Sandstone_Brick",
      "rotation": 3
    },
    {
      "x": -19,
      "y": 5,
      "z": -14,
      "name": "Rock_Sandstone_Brick_Ornate",
      "rotation": 3
    },
    {
      "x": -19,
      "y": 6,
      "z": -14,
      "name": "Rock_Sandstone_Brick_Stairs",
      "rotation": 3
    },
    {
      "x": -19,
      "y": 1,
      "z": -13,
      "name": "Rock_Sandstone_Cobble",
      "rotation": 3
    },
    {
      "x": -19,
      "y": 2,
      "z": -13,
      "name": "Rock_Sandstone_Cobble",
      "rotation": 3
    },
    {
      "x": -19,
      "y": 3,
      "z": -13,
      "name": "Rock_Sandstone_Cobble",
      "rotation": 3
    },
    {
      "x": -19,
      "y": 4,
      "z": -13,
      "name": "Rock_Sandstone_Cobble",
      "rotation": 3
    },
    {
      "x": -19,
      "y": 5,
      "z": -13,
      "name": "Rock_Sandstone_Brick_Ornate",
      "rotation": 3
    },
    {
      "x": -19,
      "y": 6,
      "z": -13,
      "name": "Rock_Sandstone_Brick_Stairs",
      "rotation": 3
    },
    {
      "x": -19,
      "y": 1,
      "z": -12,
      "name": "Rock_Sandstone_Brick",
      "rotation": 3
    },
    {
      "x": -19,
      "y": 2,
      "z": -12,
      "name": "Rock_Sandstone_Cobble",
      "rotation": 3
    },
    {
      "x": -19,
      "y": 3,
      "z": -12,
      "name": "Rock_Sandstone_Cobble",
      "rotation": 3
    },
    {
      "x": -19,
      "y": 4,
      "z": -12,
      "name": "Rock_Sandstone_Cobble",
      "rotation": 3
    },
    {
      "x": -19,
      "y": 5,
      "z": -12,
      "name": "Rock_Sandstone_Brick_Ornate",
      "rotation": 3
    },
    {
      "x": -19,
      "y": 6,
      "z": -12,
      "name": "Rock_Sandstone_Brick_Stairs",
      "rotation": 3
    },
    {
      "x": -19,
      "y": 10,
      "z": -12,
      "name": "Rock_Sandstone_Brick_Stairs",
      "rotation": 9
    },
    {
      "x": -19,
      "y": 11,
      "z": -12,
      "name": "Rock_Sandstone_Brick",
      "rotation": 3
    },
    {
      "x": -19,
      "y": 1,
      "z": -11,
      "name": "Rock_Sandstone_Brick",
      "rotation": 3
    },
    {
      "x": -19,
      "y": 2,
      "z": -11,
      "name": "Rock_Sandstone_Brick",
      "rotation": 3
    },
    {
      "x": -19,
      "y": 3,
      "z": -11,
      "name": "Rock_Sandstone_Brick",
      "rotation": 3
    },
    {
      "x": -19,
      "y": 4,
      "z": -11,
      "name": "Rock_Sandstone_Brick",
      "rotation": 3
    },
    {
      "x": -19,
      "y": 5,
      "z": -11,
      "name": "Rock_Sandstone_Brick_Ornate",
      "rotation": 3
    },
    {
      "x": -19,
      "y": 6,
      "z": -11,
      "name": "Rock_Sandstone_Brick_Stairs",
      "rotation": 3
    },
    {
      "x": -19,
      "y": 10,
      "z": -11,
      "name": "Rock_Sandstone_Brick_Stairs",
      "rotation": 9
    },
    {
      "x": -19,
      "y": 11,
      "z": -11,
      "name": "Rock_Sandstone_Brick",
      "rotation": 3
    },
    {
      "x": -19,
      "y": 12,
      "z": -11,
      "name": "Rock_Sandstone_Brick",
      "rotation": 3
    },
    {
      "x": -19,
      "y": 1,
      "z": -10,
      "name": "Rock_Sandstone_Brick",
      "rotation": 3
    },
    {
      "x": -19,
      "y": 2,
      "z": -10,
      "name": "Rock_Sandstone_Brick",
      "rotation": 3
    },
    {
      "x": -19,
      "y": 3,
      "z": -10,
      "name": "Rock_Sandstone_Brick",
      "rotation": 3
    },
    {
      "x": -19,
      "y": 4,
      "z": -10,
      "name": "Rock_Sandstone_Brick",
      "rotation": 3
    },
    {
      "x": -19,
      "y": 5,
      "z": -10,
      "name": "Rock_Sandstone_Brick_Ornate",
      "rotation": 3
    },
    {
      "x": -19,
      "y": 6,
      "z": -10,
      "name": "Rock_Sandstone_Brick_Stairs",
      "rotation": 3
    },
    {
      "x": -19,
      "y": 10,
      "z": -10,
      "name": "Rock_Sandstone_Brick_Stairs",
      "rotation": 9
    },
    {
      "x": -19,
      "y": 11,
      "z": -10,
      "name": "Rock_Sandstone_Brick",
      "rotation": 3
    },
    {
      "x": -19,
      "y": 12,
      "z": -10,
      "name": "Rock_Sandstone_Brick",
      "rotation": 3
    },
    {
      "x": -19,
      "y": 1,
      "z": -9,
      "name": "Rock_Sandstone_Brick",
      "rotation": 3
    },
    {
      "x": -19,
      "y": 2,
      "z": -9,
      "name": "Rock_Sandstone_Cobble",
      "rotation": 3
    },
    {
      "x": -19,
      "y": 3,
      "z": -9,
      "name": "Rock_Sandstone_Brick",
      "rotation": 3
    },
    {
      "x": -19,
      "y": 4,
      "z": -9,
      "name": "Rock_Sandstone_Cobble",
      "rotation": 3
    },
    {
      "x": -19,
      "y": 5,
      "z": -9,
      "name": "Rock_Sandstone_Brick_Ornate",
      "rotation": 3
    },
    {
      "x": -19,
      "y": 6,
      "z": -9,
      "name": "Rock_Sandstone_Brick_Stairs",
      "rotation": 3
    },
    {
      "x": -19,
      "y": 10,
      "z": -9,
      "name": "Rock_Sandstone_Brick_Stairs",
      "rotation": 35
    },
    {
      "x": -19,
      "y": 11,
      "z": -9,
      "name": "Rock_Sandstone_Brick",
      "rotation": 3
    },
    {
      "x": -19,
      "y": 12,
      "z": -9,
      "name": "Rock_Sandstone_Brick",
      "rotation": 3
    },
    {
      "x": -19,
      "y": 1,
      "z": -8,
      "name": "Rock_Sandstone_Brick",
      "rotation": 3
    },
    {
      "x": -19,
      "y": 2,
      "z": -8,
      "name": "Rock_Sandstone_Brick",
      "rotation": 3
    },
    {
      "x": -19,
      "y": 3,
      "z": -8,
      "name": "Rock_Sandstone_Cobble",
      "rotation": 3
    },
    {
      "x": -19,
      "y": 4,
      "z": -8,
      "name": "Rock_Sandstone_Cobble",
      "rotation": 3
    },
    {
      "x": -19,
      "y": 5,
      "z": -8,
      "name": "Rock_Sandstone_Brick_Ornate",
      "rotation": 3
    },
    {
      "x": -19,
      "y": 6,
      "z": -8,
      "name": "Rock_Sandstone_Brick_Stairs",
      "rotation": 3
    },
    {
      "x": -19,
      "y": 10,
      "z": -8,
      "name": "Rock_Sandstone_Brick_Stairs",
      "rotation": 35
    },
    {
      "x": -19,
      "y": 11,
      "z": -8,
      "name": "Rock_Sandstone_Brick",
      "rotation": 3
    },
    {
      "x": -19,
      "y": 12,
      "z": -8,
      "name": "Rock_Sandstone_Brick",
      "rotation": 3
    },
    {
      "x": -19,
      "y": 1,
      "z": -7,
      "name": "Rock_Sandstone_Brick",
      "rotation": 3
    },
    {
      "x": -19,
      "y": 2,
      "z": -7,
      "name": "Rock_Sandstone_Brick",
      "rotation": 3
    },
    {
      "x": -19,
      "y": 3,
      "z": -7,
      "name": "Rock_Sandstone_Brick",
      "rotation": 3
    },
    {
      "x": -19,
      "y": 4,
      "z": -7,
      "name": "Rock_Sandstone_Brick",
      "rotation": 3
    },
    {
      "x": -19,
      "y": 5,
      "z": -7,
      "name": "Rock_Sandstone_Brick_Ornate",
      "rotation": 3
    },
    {
      "x": -19,
      "y": 6,
      "z": -7,
      "name": "Rock_Sandstone_Brick_Stairs",
      "rotation": 3
    },
    {
      "x": -19,
      "y": 10,
      "z": -7,
      "name": "Rock_Sandstone_Brick_Stairs",
      "rotation": 35
    },
    {
      "x": -19,
      "y": 11,
      "z": -7,
      "name": "Rock_Sandstone_Brick",
      "rotation": 3
    },
    {
      "x": -19,
      "y": 12,
      "z": -7,
      "name": "Rock_Sandstone_Brick",
      "rotation": 3
    },
    {
      "x": -19,
      "y": 13,
      "z": -7,
      "name": "Rock_Sandstone_Brick_Half",
      "rotation": 3
    },
    {
      "x": -19,
      "y": 1,
      "z": -6,
      "name": "Rock_Sandstone_Brick",
      "rotation": 3
    },
    {
      "x": -19,
      "y": 2,
      "z": -6,
      "name": "Rock_Sandstone_Brick",
      "rotation": 3
    },
    {
      "x": -19,
      "y": 3,
      "z": -6,
      "name": "Rock_Sandstone_Brick",
      "rotation": 3
    },
    {
      "x": -19,
      "y": 4,
      "z": -6,
      "name": "Rock_Sandstone_Brick",
      "rotation": 3
    },
    {
      "x": -19,
      "y": 5,
      "z": -6,
      "name": "Rock_Sandstone_Brick_Ornate",
      "rotation": 3
    },
    {
      "x": -19,
      "y": 6,
      "z": -6,
      "name": "Rock_Sandstone_Brick_Stairs",
      "rotation": 3
    },
    {
      "x": -19,
      "y": 10,
      "z": -6,
      "name": "Rock_Sandstone_Brick_Half",
      "rotation": 7
    },
    {
      "x": -19,
      "y": 11,
      "z": -6,
      "name": "Rock_Sandstone_Brick",
      "rotation": 3
    },
    {
      "x": -19,
      "y": 12,
      "z": -6,
      "name": "Rock_Sandstone_Brick",
      "rotation": 3
    },
    {
      "x": -19,
      "y": 13,
      "z": -6,
      "name": "Rock_Sandstone_Brick_Half",
      "rotation": 3
    },
    {
      "x": -19,
      "y": 1,
      "z": -5,
      "name": "Rock_Sandstone_Cobble",
      "rotation": 3
    },
    {
      "x": -19,
      "y": 2,
      "z": -5,
      "name": "Rock_Sandstone_Cobble",
      "rotation": 3
    },
    {
      "x": -19,
      "y": 3,
      "z": -5,
      "name": "Rock_Sandstone_Cobble",
      "rotation": 3
    },
    {
      "x": -19,
      "y": 4,
      "z": -5,
      "name": "Rock_Sandstone_Cobble",
      "rotation": 3
    },
    {
      "x": -19,
      "y": 5,
      "z": -5,
      "name": "Rock_Sandstone_Brick_Ornate",
      "rotation": 3
    },
    {
      "x": -19,
      "y": 6,
      "z": -5,
      "name": "Rock_Sandstone_Brick_Stairs",
      "rotation": 3
    },
    {
      "x": -19,
      "y": 11,
      "z": -5,
      "name": "Rock_Sandstone_Brick",
      "rotation": 3
    },
    {
      "x": -19,
      "y": 12,
      "z": -5,
      "name": "Rock_Sandstone_Brick",
      "rotation": 3
    },
    {
      "x": -19,
      "y": 1,
      "z": -4,
      "name": "Rock_Sandstone_Brick",
      "rotation": 3
    },
    {
      "x": -19,
      "y": 2,
      "z": -4,
      "name": "Rock_Sandstone_Cobble",
      "rotation": 3
    },
    {
      "x": -19,
      "y": 3,
      "z": -4,
      "name": "Rock_Sandstone_Cobble",
      "rotation": 3
    },
    {
      "x": -19,
      "y": 4,
      "z": -4,
      "name": "Rock_Sandstone_Cobble",
      "rotation": 3
    },
    {
      "x": -19,
      "y": 5,
      "z": -4,
      "name": "Rock_Sandstone_Brick_Ornate",
      "rotation": 3
    },
    {
      "x": -19,
      "y": 6,
      "z": -4,
      "name": "Rock_Sandstone_Brick_Stairs",
      "rotation": 3
    },
    {
      "x": -19,
      "y": 10,
      "z": -4,
      "name": "Rock_Sandstone_Brick_Stairs",
      "rotation": 35
    },
    {
      "x": -19,
      "y": 11,
      "z": -4,
      "name": "Rock_Sandstone_Brick",
      "rotation": 3
    },
    {
      "x": -19,
      "y": 12,
      "z": -4,
      "name": "Rock_Sandstone_Brick",
      "rotation": 3
    },
    {
      "x": -19,
      "y": 1,
      "z": -3,
      "name": "Rock_Sandstone_Brick",
      "rotation": 3
    },
    {
      "x": -19,
      "y": 2,
      "z": -3,
      "name": "Rock_Sandstone_Brick",
      "rotation": 3
    },
    {
      "x": -19,
      "y": 3,
      "z": -3,
      "name": "Rock_Sandstone_Brick",
      "rotation": 3
    },
    {
      "x": -19,
      "y": 4,
      "z": -3,
      "name": "Rock_Sandstone_Brick",
      "rotation": 3
    },
    {
      "x": -19,
      "y": 5,
      "z": -3,
      "name": "Rock_Sandstone_Brick_Ornate",
      "rotation": 3
    },
    {
      "x": -19,
      "y": 10,
      "z": -3,
      "name": "Rock_Sandstone_Brick_Stairs",
      "rotation": 35
    },
    {
      "x": -19,
      "y": 11,
      "z": -3,
      "name": "Rock_Sandstone_Brick",
      "rotation": 3
    },
    {
      "x": -19,
      "y": 12,
      "z": -3,
      "name": "Rock_Sandstone_Brick",
      "rotation": 3
    },
    {
      "x": -19,
      "y": 1,
      "z": -2,
      "name": "Rock_Sandstone_Brick",
      "rotation": 3
    },
    {
      "x": -19,
      "y": 2,
      "z": -2,
      "name": "Rock_Sandstone_Brick",
      "rotation": 3
    },
    {
      "x": -19,
      "y": 3,
      "z": -2,
      "name": "Rock_Sandstone_Brick",
      "rotation": 3
    },
    {
      "x": -19,
      "y": 4,
      "z": -2,
      "name": "Rock_Sandstone_Brick",
      "rotation": 3
    },
    {
      "x": -19,
      "y": 5,
      "z": -2,
      "name": "Rock_Sandstone_Brick_Ornate",
      "rotation": 3
    },
    {
      "x": -19,
      "y": 10,
      "z": -2,
      "name": "*Rock_Sandstone_Brick_Stairs_State_Definitions_Corner_Right",
      "rotation": 35
    },
    {
      "x": -19,
      "y": 11,
      "z": -2,
      "name": "Rock_Sandstone_Brick",
      "rotation": 3
    },
    {
      "x": -19,
      "y": 12,
      "z": -2,
      "name": "Rock_Sandstone_Brick",
      "rotation": 3
    },
    {
      "x": -19,
      "y": 1,
      "z": -1,
      "name": "Rock_Sandstone_Red_Brick",
      "rotation": 3
    },
    {
      "x": -19,
      "y": 2,
      "z": -1,
      "name": "Rock_Sandstone_Red_Brick",
      "rotation": 3
    },
    {
      "x": -19,
      "y": 3,
      "z": -1,
      "name": "Rock_Sandstone_Red_Brick",
      "rotation": 3
    },
    {
      "x": -19,
      "y": 4,
      "z": -1,
      "name": "Rock_Sandstone_Red_Brick_Stairs"
    },
    {
      "x": -19,
      "y": 1,
      "z": 0,
      "name": "Rock_Sandstone_Red_Cobble",
      "rotation": 3
    },
    {
      "x": -19,
      "y": 2,
      "z": 0,
      "name": "Rock_Sandstone_Red_Brick",
      "rotation": 3
    },
    {
      "x": -19,
      "y": 3,
      "z": 0,
      "name": "Rock_Sandstone_Red_Brick_Stairs"
    },
    {
      "x": -18,
      "y": 1,
      "z": -21,
      "name": "Rock_Sandstone_Red_Brick",
      "rotation": 3
    },
    {
      "x": -18,
      "y": 2,
      "z": -21,
      "name": "Rock_Sandstone_Red_Brick",
      "rotation": 3
    },
    {
      "x": -18,
      "y": 3,
      "z": -21,
      "name": "Rock_Sandstone_Red_Brick_Stairs",
      "rotation": 2
    },
    {
      "x": -18,
      "y": 1,
      "z": -20,
      "name": "Rock_Sandstone_Red_Brick",
      "rotation": 3
    },
    {
      "x": -18,
      "y": 2,
      "z": -20,
      "name": "Rock_Sandstone_Red_Brick",
      "rotation": 3
    },
    {
      "x": -18,
      "y": 3,
      "z": -20,
      "name": "Rock_Sandstone_Red_Brick",
      "rotation": 3
    },
    {
      "x": -18,
      "y": 4,
      "z": -20,
      "name": "Rock_Sandstone_Red_Brick_Stairs",
      "rotation": 2
    },
    {
      "x": -18,
      "y": 1,
      "z": -19,
      "name": "Rock_Sandstone_Brick",
      "rotation": 3
    },
    {
      "x": -18,
      "y": 2,
      "z": -19,
      "name": "Rock_Sandstone_Brick",
      "rotation": 3
    },
    {
      "x": -18,
      "y": 3,
      "z": -19,
      "name": "Rock_Sandstone_Brick",
      "rotation": 3
    },
    {
      "x": -18,
      "y": 4,
      "z": -19,
      "name": "Rock_Sandstone_Brick",
      "rotation": 3
    },
    {
      "x": -18,
      "y": 5,
      "z": -19,
      "name": "Rock_Sandstone_Brick_Ornate",
      "rotation": 3
    },
    {
      "x": -18,
      "y": 6,
      "z": -19,
      "name": "Rock_Sandstone_Brick_Stairs",
      "rotation": 2
    },
    {
      "x": -18,
      "y": 1,
      "z": -18,
      "name": "Rock_Sandstone_Brick",
      "rotation": 3
    },
    {
      "x": -18,
      "y": 2,
      "z": -18,
      "name": "Rock_Sandstone_Brick",
      "rotation": 3
    },
    {
      "x": -18,
      "y": 3,
      "z": -18,
      "name": "Rock_Sandstone_Brick",
      "rotation": 3
    },
    {
      "x": -18,
      "y": 4,
      "z": -18,
      "name": "Rock_Sandstone_Brick",
      "rotation": 3
    },
    {
      "x": -18,
      "y": 5,
      "z": -18,
      "name": "Rock_Sandstone_Brick",
      "rotation": 3
    },
    {
      "x": -18,
      "y": 6,
      "z": -18,
      "name": "Rock_Sandstone_Cobble",
      "rotation": 3
    },
    {
      "x": -18,
      "y": 7,
      "z": -18,
      "name": "Rock_Sandstone_Cobble",
      "rotation": 3
    },
    {
      "x": -18,
      "y": 8,
      "z": -18,
      "name": "Rock_Sandstone_Cobble"
    },
    {
      "x": -18,
      "y": 1,
      "z": -17,
      "name": "Rock_Sandstone_Brick",
      "rotation": 3
    },
    {
      "x": -18,
      "y": 2,
      "z": -17,
      "name": "Rock_Sandstone_Brick",
      "rotation": 3
    },
    {
      "x": -18,
      "y": 3,
      "z": -17,
      "name": "Rock_Sandstone_Brick",
      "rotation": 3
    },
    {
      "x": -18,
      "y": 4,
      "z": -17,
      "name": "Rock_Sandstone_Red_Brick",
      "rotation": 3
    },
    {
      "x": -18,
      "y": 5,
      "z": -17,
      "name": "Rock_Sandstone_Brick",
      "rotation": 3
    },
    {
      "x": -18,
      "y": 6,
      "z": -17,
      "name": "Rock_Sandstone_Cobble",
      "rotation": 3
    },
    {
      "x": -18,
      "y": 7,
      "z": -17,
      "name": "Rock_Sandstone_Cobble",
      "rotation": 3
    },
    {
      "x": -18,
      "y": 8,
      "z": -17,
      "name": "Rock_Sandstone_Cobble",
      "rotation": 3
    },
    {
      "x": -18,
      "y": 1,
      "z": -16,
      "name": "Rock_Sandstone_Brick",
      "rotation": 3
    },
    {
      "x": -18,
      "y": 2,
      "z": -16,
      "name": "Rock_Sandstone_Brick",
      "rotation": 3
    },
    {
      "x": -18,
      "y": 3,
      "z": -16,
      "name": "Rock_Sandstone_Brick",
      "rotation": 3
    },
    {
      "x": -18,
      "y": 4,
      "z": -16,
      "name": "Rock_Sandstone_Red_Brick",
      "rotation": 3
    },
    {
      "x": -18,
      "y": 5,
      "z": -16,
      "name": "Rock_Sandstone_Brick",
      "rotation": 3
    },
    {
      "x": -18,
      "y": 6,
      "z": -16,
      "name": "Rock_Sandstone_Cobble",
      "rotation": 3
    },
    {
      "x": -18,
      "y": 7,
      "z": -16,
      "name": "Rock_Sandstone_Cobble",
      "rotation": 3
    },
    {
      "x": -18,
      "y": 8,
      "z": -16,
      "name": "Rock_Sandstone_Cobble",
      "rotation": 3
    },
    {
      "x": -18,
      "y": 1,
      "z": -15,
      "name": "Rock_Sandstone_Brick",
      "rotation": 3
    },
    {
      "x": -18,
      "y": 2,
      "z": -15,
      "name": "Rock_Sandstone_Brick",
      "rotation": 3
    },
    {
      "x": -18,
      "y": 3,
      "z": -15,
      "name": "Rock_Sandstone_Brick",
      "rotation": 3
    },
    {
      "x": -18,
      "y": 4,
      "z": -15,
      "name": "Rock_Sandstone_Red_Brick",
      "rotation": 3
    },
    {
      "x": -18,
      "y": 5,
      "z": -15,
      "name": "Rock_Sandstone_Brick",
      "rotation": 3
    },
    {
      "x": -18,
      "y": 6,
      "z": -15,
      "name": "Rock_Sandstone_Cobble",
      "rotation": 3
    },
    {
      "x": -18,
      "y": 7,
      "z": -15,
      "name": "Rock_Sandstone_Cobble",
      "rotation": 3
    },
    {
      "x": -18,
      "y": 8,
      "z": -15,
      "name": "Rock_Sandstone_Cobble"
    },
    {
      "x": -18,
      "y": 1,
      "z": -14,
      "name": "Rock_Sandstone_Brick",
      "rotation": 3
    },
    {
      "x": -18,
      "y": 2,
      "z": -14,
      "name": "Rock_Sandstone_Brick",
      "rotation": 3
    },
    {
      "x": -18,
      "y": 3,
      "z": -14,
      "name": "Rock_Sandstone_Brick",
      "rotation": 3
    },
    {
      "x": -18,
      "y": 4,
      "z": -14,
      "name": "Rock_Sandstone_Red_Brick",
      "rotation": 3
    },
    {
      "x": -18,
      "y": 5,
      "z": -14,
      "name": "Rock_Sandstone_Brick",
      "rotation": 3
    },
    {
      "x": -18,
      "y": 6,
      "z": -14,
      "name": "Rock_Sandstone_Cobble",
      "rotation": 3
    },
    {
      "x": -18,
      "y": 7,
      "z": -14,
      "name": "Rock_Sandstone_Cobble",
      "rotation": 3
    },
    {
      "x": -18,
      "y": 8,
      "z": -14,
      "name": "Rock_Sandstone_Cobble",
      "rotation": 3
    },
    {
      "x": -18,
      "y": 9,
      "z": -14,
      "name": "Rock_Sandstone_Cobble"
    },
    {
      "x": -18,
      "y": 1,
      "z": -13,
      "name": "Rock_Sandstone_Brick",
      "rotation": 3
    },
    {
      "x": -18,
      "y": 2,
      "z": -13,
      "name": "Rock_Sandstone_Brick",
      "rotation": 3
    },
    {
      "x": -18,
      "y": 3,
      "z": -13,
      "name": "Rock_Sandstone_Brick",
      "rotation": 3
    },
    {
      "x": -18,
      "y": 4,
      "z": -13,
      "name": "Rock_Sandstone_Red_Brick",
      "rotation": 3
    },
    {
      "x": -18,
      "y": 5,
      "z": -13,
      "name": "Rock_Sandstone_Brick",
      "rotation": 3
    },
    {
      "x": -18,
      "y": 6,
      "z": -13,
      "name": "Rock_Sandstone_Cobble",
      "rotation": 3
    },
    {
      "x": -18,
      "y": 7,
      "z": -13,
      "name": "Rock_Sandstone_Cobble",
      "rotation": 3
    },
    {
      "x": -18,
      "y": 8,
      "z": -13,
      "name": "Rock_Sandstone_Cobble",
      "rotation": 3
    },
    {
      "x": -18,
      "y": 9,
      "z": -13,
      "name": "Rock_Sandstone_Cobble",
      "rotation": 3
    },
    {
      "x": -18,
      "y": 10,
      "z": -13,
      "name": "Rock_Sandstone_Cobble"
    },
    {
      "x": -18,
      "y": 11,
      "z": -13,
      "name": "Rock_Sandstone_Cobble"
    },
    {
      "x": -18,
      "y": 1,
      "z": -12,
      "name": "Rock_Sandstone_Brick",
      "rotation": 3
    },
    {
      "x": -18,
      "y": 2,
      "z": -12,
      "name": "Rock_Sandstone_Brick",
      "rotation": 3
    },
    {
      "x": -18,
      "y": 3,
      "z": -12,
      "name": "Rock_Sandstone_Brick",
      "rotation": 3
    },
    {
      "x": -18,
      "y": 4,
      "z": -12,
      "name": "Rock_Sandstone_Red_Brick",
      "rotation": 3
    },
    {
      "x": -18,
      "y": 5,
      "z": -12,
      "name": "Rock_Sandstone_Brick",
      "rotation": 3
    },
    {
      "x": -18,
      "y": 6,
      "z": -12,
      "name": "Rock_Sandstone_Cobble",
      "rotation": 3
    },
    {
      "x": -18,
      "y": 7,
      "z": -12,
      "name": "Rock_Sandstone_Cobble",
      "rotation": 3
    },
    {
      "x": -18,
      "y": 8,
      "z": -12,
      "name": "Rock_Sandstone_Cobble",
      "rotation": 3
    },
    {
      "x": -18,
      "y": 9,
      "z": -12,
      "name": "Rock_Sandstone_Cobble",
      "rotation": 3
    },
    {
      "x": -18,
      "y": 10,
      "z": -12,
      "name": "Rock_Sandstone_Cobble",
      "rotation": 3
    },
    {
      "x": -18,
      "y": 11,
      "z": -12,
      "name": "Rock_Sandstone_Cobble"
    },
    {
      "x": -18,
      "y": 1,
      "z": -11,
      "name": "Rock_Sandstone_Red_Brick",
      "rotation": 3
    },
    {
      "x": -18,
      "y": 2,
      "z": -11,
      "name": "Rock_Sandstone_Red_Brick",
      "rotation": 3
    },
    {
      "x": -18,
      "y": 3,
      "z": -11,
      "name": "Rock_Sandstone_Red_Brick",
      "rotation": 3
    },
    {
      "x": -18,
      "y": 4,
      "z": -11,
      "name": "Rock_Sandstone_Red_Brick",
      "rotation": 3
    },
    {
      "x": -18,
      "y": 5,
      "z": -11,
      "name": "Rock_Sandstone_Brick",
      "rotation": 3
    },
    {
      "x": -18,
      "y": 6,
      "z": -11,
      "name": "Rock_Sandstone_Cobble",
      "rotation": 3
    },
    {
      "x": -18,
      "y": 7,
      "z": -11,
      "name": "Rock_Sandstone_Cobble",
      "rotation": 3
    },
    {
      "x": -18,
      "y": 8,
      "z": -11,
      "name": "Rock_Sandstone_Cobble",
      "rotation": 3
    },
    {
      "x": -18,
      "y": 9,
      "z": -11,
      "name": "Rock_Sandstone_Cobble",
      "rotation": 3
    },
    {
      "x": -18,
      "y": 10,
      "z": -11,
      "name": "Rock_Sandstone_Cobble",
      "rotation": 3
    },
    {
      "x": -18,
      "y": 11,
      "z": -11,
      "name": "Rock_Sandstone_Brick",
      "rotation": 3
    },
    {
      "x": -18,
      "y": 12,
      "z": -11,
      "name": "Rock_Sandstone_Brick"
    },
    {
      "x": -18,
      "y": 1,
      "z": -10,
      "name": "Rock_Sandstone_Brick",
      "rotation": 3
    },
    {
      "x": -18,
      "y": 2,
      "z": -10,
      "name": "Rock_Sandstone_Brick",
      "rotation": 3
    },
    {
      "x": -18,
      "y": 3,
      "z": -10,
      "name": "Rock_Sandstone_Brick",
      "rotation": 3
    },
    {
      "x": -18,
      "y": 4,
      "z": -10,
      "name": "Rock_Sandstone_Brick",
      "rotation": 3
    },
    {
      "x": -18,
      "y": 5,
      "z": -10,
      "name": "Rock_Sandstone_Brick",
      "rotation": 3
    },
    {
      "x": -18,
      "y": 6,
      "z": -10,
      "name": "Rock_Sandstone_Cobble",
      "rotation": 3
    },
    {
      "x": -18,
      "y": 7,
      "z": -10,
      "name": "Rock_Sandstone_Cobble",
      "rotation": 3
    },
    {
      "x": -18,
      "y": 8,
      "z": -10,
      "name": "Rock_Sandstone_Cobble",
      "rotation": 3
    },
    {
      "x": -18,
      "y": 9,
      "z": -10,
      "name": "Rock_Sandstone_Cobble",
      "rotation": 3
    },
    {
      "x": -18,
      "y": 10,
      "z": -10,
      "name": "Rock_Sandstone_Cobble",
      "rotation": 3
    },
    {
      "x": -18,
      "y": 11,
      "z": -10,
      "name": "Rock_Sandstone_Brick",
      "rotation": 3
    },
    {
      "x": -18,
      "y": 12,
      "z": -10,
      "name": "Rock_Sandstone_Brick",
      "rotation": 3
    },
    {
      "x": -18,
      "y": 1,
      "z": -9,
      "name": "Rock_Sandstone_Brick",
      "rotation": 3
    },
    {
      "x": -18,
      "y": 2,
      "z": -9,
      "name": "Rock_Sandstone_Brick",
      "rotation": 3
    },
    {
      "x": -18,
      "y": 3,
      "z": -9,
      "name": "Rock_Sandstone_Brick",
      "rotation": 3
    },
    {
      "x": -18,
      "y": 4,
      "z": -9,
      "name": "Rock_Sandstone_Red_Brick",
      "rotation": 3
    },
    {
      "x": -18,
      "y": 5,
      "z": -9,
      "name": "Rock_Sandstone_Brick",
      "rotation": 3
    },
    {
      "x": -18,
      "y": 6,
      "z": -9,
      "name": "Rock_Sandstone_Cobble",
      "rotation": 3
    },
    {
      "x": -18,
      "y": 7,
      "z": -9,
      "name": "Rock_Sandstone_Cobble",
      "rotation": 3
    },
    {
      "x": -18,
      "y": 8,
      "z": -9,
      "name": "Rock_Sandstone_Cobble",
      "rotation": 3
    },
    {
      "x": -18,
      "y": 9,
      "z": -9,
      "name": "Rock_Sandstone_Cobble",
      "rotation": 3
    },
    {
      "x": -18,
      "y": 10,
      "z": -9,
      "name": "Rock_Sandstone_Cobble",
      "rotation": 3
    },
    {
      "x": -18,
      "y": 11,
      "z": -9,
      "name": "Rock_Sandstone_Brick",
      "rotation": 3
    },
    {
      "x": -18,
      "y": 12,
      "z": -9,
      "name": "Rock_Sandstone_Brick",
      "rotation": 3
    },
    {
      "x": -18,
      "y": 1,
      "z": -8,
      "name": "Rock_Sandstone_Brick",
      "rotation": 3
    },
    {
      "x": -18,
      "y": 2,
      "z": -8,
      "name": "Rock_Sandstone_Brick",
      "rotation": 3
    },
    {
      "x": -18,
      "y": 3,
      "z": -8,
      "name": "Rock_Sandstone_Brick",
      "rotation": 3
    },
    {
      "x": -18,
      "y": 4,
      "z": -8,
      "name": "Rock_Sandstone_Red_Brick",
      "rotation": 3
    },
    {
      "x": -18,
      "y": 5,
      "z": -8,
      "name": "Rock_Sandstone_Brick",
      "rotation": 3
    },
    {
      "x": -18,
      "y": 6,
      "z": -8,
      "name": "Rock_Sandstone_Cobble",
      "rotation": 3
    },
    {
      "x": -18,
      "y": 7,
      "z": -8,
      "name": "Rock_Sandstone_Cobble",
      "rotation": 3
    },
    {
      "x": -18,
      "y": 8,
      "z": -8,
      "name": "Rock_Sandstone_Cobble",
      "rotation": 3
    },
    {
      "x": -18,
      "y": 9,
      "z": -8,
      "name": "Rock_Sandstone_Cobble",
      "rotation": 3
    },
    {
      "x": -18,
      "y": 10,
      "z": -8,
      "name": "Rock_Sandstone_Cobble",
      "rotation": 3
    },
    {
      "x": -18,
      "y": 11,
      "z": -8,
      "name": "Rock_Sandstone_Brick",
      "rotation": 3
    },
    {
      "x": -18,
      "y": 12,
      "z": -8,
      "name": "Rock_Sandstone_Brick",
      "rotation": 3
    },
    {
      "x": -18,
      "y": 1,
      "z": -7,
      "name": "Rock_Sandstone_Brick"
    },
    {
      "x": -18,
      "y": 2,
      "z": -7,
      "name": "Rock_Sandstone_Brick",
      "rotation": 3
    },
    {
      "x": -18,
      "y": 3,
      "z": -7,
      "name": "Rock_Sandstone_Brick",
      "rotation": 3
    },
    {
      "x": -18,
      "y": 4,
      "z": -7,
      "name": "Rock_Sandstone_Red_Brick",
      "rotation": 3
    },
    {
      "x": -18,
      "y": 5,
      "z": -7,
      "name": "Rock_Sandstone_Brick",
      "rotation": 3
    },
    {
      "x": -18,
      "y": 6,
      "z": -7,
      "name": "Rock_Sandstone_Cobble",
      "rotation": 3
    },
    {
      "x": -18,
      "y": 7,
      "z": -7,
      "name": "Rock_Sandstone_Cobble",
      "rotation": 3
    },
    {
      "x": -18,
      "y": 8,
      "z": -7,
      "name": "Rock_Sandstone_Cobble",
      "rotation": 3
    },
    {
      "x": -18,
      "y": 9,
      "z": -7,
      "name": "Rock_Sandstone_Cobble",
      "rotation": 3
    },
    {
      "x": -18,
      "y": 10,
      "z": -7,
      "name": "Rock_Sandstone_Cobble",
      "rotation": 3
    },
    {
      "x": -18,
      "y": 11,
      "z": -7,
      "name": "Rock_Sandstone_Brick",
      "rotation": 3
    },
    {
      "x": -18,
      "y": 12,
      "z": -7,
      "name": "Rock_Sandstone_Brick",
      "rotation": 3
    },
    {
      "x": -18,
      "y": 13,
      "z": -7,
      "name": "Rock_Sandstone_Brick_Half",
      "rotation": 3
    },
    {
      "x": -18,
      "y": 1,
      "z": -6,
      "name": "Rock_Sandstone_Brick",
      "rotation": 3
    },
    {
      "x": -18,
      "y": 2,
      "z": -6,
      "name": "Rock_Sandstone_Brick",
      "rotation": 3
    },
    {
      "x": -18,
      "y": 3,
      "z": -6,
      "name": "Rock_Sandstone_Brick",
      "rotation": 3
    },
    {
      "x": -18,
      "y": 4,
      "z": -6,
      "name": "Rock_Sandstone_Red_Brick",
      "rotation": 3
    },
    {
      "x": -18,
      "y": 5,
      "z": -6,
      "name": "Rock_Sandstone_Brick",
      "rotation": 3
    },
    {
      "x": -18,
      "y": 6,
      "z": -6,
      "name": "Rock_Sandstone_Cobble",
      "rotation": 3
    },
    {
      "x": -18,
      "y": 7,
      "z": -6,
      "name": "Rock_Sandstone_Cobble",
      "rotation": 3
    },
    {
      "x": -18,
      "y": 8,
      "z": -6,
      "name": "Rock_Sandstone_Cobble",
      "rotation": 3
    },
    {
      "x": -18,
      "y": 9,
      "z": -6,
      "name": "Rock_Sandstone_Cobble",
      "rotation": 3
    },
    {
      "x": -18,
      "y": 10,
      "z": -6,
      "name": "Rock_Sandstone_Cobble",
      "rotation": 3
    },
    {
      "x": -18,
      "y": 11,
      "z": -6,
      "name": "Rock_Sandstone_Brick",
      "rotation": 3
    },
    {
      "x": -18,
      "y": 12,
      "z": -6,
      "name": "Rock_Sandstone_Brick",
      "rotation": 3
    },
    {
      "x": -18,
      "y": 13,
      "z": -6,
      "name": "Rock_Sandstone_Brick_Half",
      "rotation": 3
    },
    {
      "x": -18,
      "y": 1,
      "z": -5,
      "name": "Rock_Sandstone_Brick",
      "rotation": 3
    },
    {
      "x": -18,
      "y": 2,
      "z": -5,
      "name": "Rock_Sandstone_Brick",
      "rotation": 3
    },
    {
      "x": -18,
      "y": 3,
      "z": -5,
      "name": "Rock_Sandstone_Brick",
      "rotation": 3
    },
    {
      "x": -18,
      "y": 4,
      "z": -5,
      "name": "Rock_Sandstone_Red_Brick",
      "rotation": 3
    },
    {
      "x": -18,
      "y": 5,
      "z": -5,
      "name": "Rock_Sandstone_Brick",
      "rotation": 3
    },
    {
      "x": -18,
      "y": 6,
      "z": -5,
      "name": "Rock_Sandstone_Cobble",
      "rotation": 3
    },
    {
      "x": -18,
      "y": 7,
      "z": -5,
      "name": "Rock_Sandstone_Cobble",
      "rotation": 3
    },
    {
      "x": -18,
      "y": 8,
      "z": -5,
      "name": "Rock_Sandstone_Cobble",
      "rotation": 3
    },
    {
      "x": -18,
      "y": 9,
      "z": -5,
      "name": "Rock_Sandstone_Cobble",
      "rotation": 3
    },
    {
      "x": -18,
      "y": 10,
      "z": -5,
      "name": "Rock_Sandstone_Cobble",
      "rotation": 3
    },
    {
      "x": -18,
      "y": 11,
      "z": -5,
      "name": "Rock_Sandstone_Brick",
      "rotation": 3
    },
    {
      "x": -18,
      "y": 12,
      "z": -5,
      "name": "Rock_Sandstone_Brick",
      "rotation": 3
    },
    {
      "x": -18,
      "y": 1,
      "z": -4,
      "name": "Rock_Sandstone_Brick",
      "rotation": 3
    },
    {
      "x": -18,
      "y": 2,
      "z": -4,
      "name": "Rock_Sandstone_Brick",
      "rotation": 3
    },
    {
      "x": -18,
      "y": 3,
      "z": -4,
      "name": "Rock_Sandstone_Brick",
      "rotation": 3
    },
    {
      "x": -18,
      "y": 4,
      "z": -4,
      "name": "Rock_Sandstone_Red_Brick",
      "rotation": 3
    },
    {
      "x": -18,
      "y": 5,
      "z": -4,
      "name": "Rock_Sandstone_Brick",
      "rotation": 3
    },
    {
      "x": -18,
      "y": 6,
      "z": -4,
      "name": "Rock_Sandstone_Cobble",
      "rotation": 3
    },
    {
      "x": -18,
      "y": 7,
      "z": -4,
      "name": "Rock_Sandstone_Cobble",
      "rotation": 3
    },
    {
      "x": -18,
      "y": 8,
      "z": -4,
      "name": "Rock_Sandstone_Cobble",
      "rotation": 3
    },
    {
      "x": -18,
      "y": 9,
      "z": -4,
      "name": "Rock_Sandstone_Cobble",
      "rotation": 3
    },
    {
      "x": -18,
      "y": 10,
      "z": -4,
      "name": "Rock_Sandstone_Cobble",
      "rotation": 3
    },
    {
      "x": -18,
      "y": 11,
      "z": -4,
      "name": "Rock_Sandstone_Brick",
      "rotation": 3
    },
    {
      "x": -18,
      "y": 12,
      "z": -4,
      "name": "Rock_Sandstone_Brick",
      "rotation": 3
    },
    {
      "x": -18,
      "y": 1,
      "z": -3,
      "name": "Rock_Sandstone_Brick",
      "rotation": 3
    },
    {
      "x": -18,
      "y": 2,
      "z": -3,
      "name": "Rock_Sandstone_Brick",
      "rotation": 3
    },
    {
      "x": -18,
      "y": 3,
      "z": -3,
      "name": "Rock_Sandstone_Brick",
      "rotation": 3
    },
    {
      "x": -18,
      "y": 4,
      "z": -3,
      "name": "Rock_Sandstone_Brick",
      "rotation": 3
    },
    {
      "x": -18,
      "y": 5,
      "z": -3,
      "name": "Rock_Sandstone_Brick",
      "rotation": 3
    },
    {
      "x": -18,
      "y": 6,
      "z": -3,
      "name": "Rock_Sandstone_Cobble",
      "rotation": 3
    },
    {
      "x": -18,
      "y": 8,
      "z": -3,
      "name": "Rock_Sandstone_Brick",
      "rotation": 3
    },
    {
      "x": -18,
      "y": 9,
      "z": -3,
      "name": "Rock_Sandstone_Brick",
      "rotation": 3
    },
    {
      "x": -18,
      "y": 10,
      "z": -3,
      "name": "Rock_Sandstone_Brick",
      "rotation": 3
    },
    {
      "x": -18,
      "y": 11,
      "z": -3,
      "name": "Rock_Sandstone_Brick",
      "rotation": 3
    },
    {
      "x": -18,
      "y": 12,
      "z": -3,
      "name": "Rock_Sandstone_Brick",
      "rotation": 3
    },
    {
      "x": -18,
      "y": 1,
      "z": -2,
      "name": "Rock_Sandstone_Brick",
      "rotation": 3
    },
    {
      "x": -18,
      "y": 2,
      "z": -2,
      "name": "Rock_Sandstone_Brick",
      "rotation": 3
    },
    {
      "x": -18,
      "y": 3,
      "z": -2,
      "name": "Rock_Sandstone_Brick",
      "rotation": 3
    },
    {
      "x": -18,
      "y": 4,
      "z": -2,
      "name": "Rock_Sandstone_Brick",
      "rotation": 3
    },
    {
      "x": -18,
      "y": 5,
      "z": -2,
      "name": "Rock_Sandstone_Brick_Ornate",
      "rotation": 3
    },
    {
      "x": -18,
      "y": 10,
      "z": -2,
      "name": "Rock_Sandstone_Brick_Stairs",
      "rotation": 32
    },
    {
      "x": -18,
      "y": 11,
      "z": -2,
      "name": "Rock_Sandstone_Brick",
      "rotation": 3
    },
    {
      "x": -18,
      "y": 12,
      "z": -2,
      "name": "Rock_Sandstone_Brick",
      "rotation": 3
    },
    {
      "x": -18,
      "y": 1,
      "z": -1,
      "name": "Rock_Sandstone_Red_Brick",
      "rotation": 3
    },
    {
      "x": -18,
      "y": 2,
      "z": -1,
      "name": "Rock_Sandstone_Red_Brick",
      "rotation": 3
    },
    {
      "x": -18,
      "y": 3,
      "z": -1,
      "name": "Rock_Sandstone_Red_Brick",
      "rotation": 3
    },
    {
      "x": -18,
      "y": 4,
      "z": -1,
      "name": "Rock_Sandstone_Red_Brick_Stairs"
    },
    {
      "x": -18,
      "y": 1,
      "z": 0,
      "name": "Rock_Sandstone_Red_Cobble",
      "rotation": 3
    },
    {
      "x": -18,
      "y": 2,
      "z": 0,
      "name": "Rock_Sandstone_Red_Brick",
      "rotation": 3
    },
    {
      "x": -18,
      "y": 3,
      "z": 0,
      "name": "Rock_Sandstone_Red_Brick_Stairs"
    },
    {
      "x": -17,
      "y": 1,
      "z": -20,
      "name": "Rock_Sandstone_Cobble_Half"
    },
    {
      "x": -17,
      "y": 1,
      "z": -19,
      "name": "Rock_Sandstone_Cobble",
      "rotation": 3
    },
    {
      "x": -17,
      "y": 2,
      "z": -19,
      "name": "Rock_Sandstone_Cobble",
      "rotation": 3
    },
    {
      "x": -17,
      "y": 3,
      "z": -19,
      "name": "Rock_Sandstone_Cobble",
      "rotation": 3
    },
    {
      "x": -17,
      "y": 4,
      "z": -19,
      "name": "Rock_Sandstone_Cobble",
      "rotation": 3
    },
    {
      "x": -17,
      "y": 5,
      "z": -19,
      "name": "Rock_Sandstone_Brick_Ornate",
      "rotation": 3
    },
    {
      "x": -17,
      "y": 6,
      "z": -19,
      "name": "Rock_Sandstone_Brick_Stairs",
      "rotation": 2
    },
    {
      "x": -17,
      "y": 1,
      "z": -18,
      "name": "Rock_Sandstone_Brick",
      "rotation": 3
    },
    {
      "x": -17,
      "y": 2,
      "z": -18,
      "name": "Rock_Sandstone_Brick",
      "rotation": 3
    },
    {
      "x": -17,
      "y": 3,
      "z": -18,
      "name": "Rock_Sandstone_Brick",
      "rotation": 3
    },
    {
      "x": -17,
      "y": 4,
      "z": -18,
      "name": "Rock_Sandstone_Brick",
      "rotation": 3
    },
    {
      "x": -17,
      "y": 5,
      "z": -18,
      "name": "Rock_Sandstone_Brick",
      "rotation": 3
    },
    {
      "x": -17,
      "y": 6,
      "z": -18,
      "name": "Rock_Sandstone_Cobble",
      "rotation": 3
    },
    {
      "x": -17,
      "y": 7,
      "z": -18,
      "name": "Rock_Sandstone_Cobble"
    },
    {
      "x": -17,
      "y": 8,
      "z": -18,
      "name": "Rock_Sandstone_Cobble"
    },
    {
      "x": -17,
      "y": 1,
      "z": -17,
      "name": "Rock_Sandstone_Brick"
    },
    {
      "x": -17,
      "y": 2,
      "z": -17,
      "name": "Rock_Sandstone_Brick",
      "rotation": 3
    },
    {
      "x": -17,
      "y": 3,
      "z": -17,
      "name": "Rock_Sandstone_Brick",
      "rotation": 3
    },
    {
      "x": -17,
      "y": 4,
      "z": -17,
      "name": "Soil_Sand",
      "rotation": 3
    },
    {
      "x": -17,
      "y": 5,
      "z": -17,
      "name": "Soil_Sand",
      "rotation": 3
    },
    {
      "x": -17,
      "y": 6,
      "z": -17,
      "name": "Rubble_Sandstone",
      "support": 15
    },
    {
      "x": -17,
      "y": 9,
      "z": -17,
      "name": "Rock_Sandstone_Red_Brick"
    },
    {
      "x": -17,
      "y": 1,
      "z": -16,
      "name": "Rock_Sandstone_Brick"
    },
    {
      "x": -17,
      "y": 2,
      "z": -16,
      "name": "Rock_Sandstone_Brick",
      "rotation": 3
    },
    {
      "x": -17,
      "y": 3,
      "z": -16,
      "name": "Soil_Sand",
      "rotation": 3
    },
    {
      "x": -17,
      "y": 4,
      "z": -16,
      "name": "Soil_Sand",
      "rotation": 3
    },
    {
      "x": -17,
      "y": 9,
      "z": -16,
      "name": "Rock_Sandstone_Red_Brick"
    },
    {
      "x": -17,
      "y": 10,
      "z": -16,
      "name": "Rock_Sandstone_Red_Brick"
    },
    {
      "x": -17,
      "y": 1,
      "z": -15,
      "name": "Rock_Sandstone_Brick"
    },
    {
      "x": -17,
      "y": 2,
      "z": -15,
      "name": "Rock_Sandstone_Brick",
      "rotation": 3
    },
    {
      "x": -17,
      "y": 3,
      "z": -15,
      "name": "Soil_Sand",
      "rotation": 3
    },
    {
      "x": -17,
      "y": 9,
      "z": -15,
      "name": "Rock_Sandstone_Red_Brick"
    },
    {
      "x": -17,
      "y": 10,
      "z": -15,
      "name": "Rock_Sandstone_Red_Brick"
    },
    {
      "x": -17,
      "y": 11,
      "z": -15,
      "name": "Rock_Sandstone_Cobble"
    },
    {
      "x": -17,
      "y": 1,
      "z": -14,
      "name": "Rock_Sandstone_Brick"
    },
    {
      "x": -17,
      "y": 2,
      "z": -14,
      "name": "Rock_Sandstone_Brick",
      "rotation": 3
    },
    {
      "x": -17,
      "y": 3,
      "z": -14,
      "name": "Soil_Sand",
      "rotation": 3
    },
    {
      "x": -17,
      "y": 4,
      "z": -14,
      "name": "Rubble_Sandstone",
      "rotation": 3
    },
    {
      "x": -17,
      "y": 9,
      "z": -14,
      "name": "Rock_Sandstone_Red_Brick"
    },
    {
      "x": -17,
      "y": 10,
      "z": -14,
      "name": "Rock_Sandstone_Red_Brick"
    },
    {
      "x": -17,
      "y": 11,
      "z": -14,
      "name": "Rock_Sandstone_Cobble"
    },
    {
      "x": -17,
      "y": 1,
      "z": -13,
      "name": "Rock_Sandstone_Brick"
    },
    {
      "x": -17,
      "y": 2,
      "z": -13,
      "name": "Rock_Sandstone_Brick",
      "rotation": 3
    },
    {
      "x": -17,
      "y": 3,
      "z": -13,
      "name": "Rock_Sandstone_Brick",
      "rotation": 3
    },
    {
      "x": -17,
      "y": 9,
      "z": -13,
      "name": "Rock_Sandstone_Red_Brick"
    },
    {
      "x": -17,
      "y": 10,
      "z": -13,
      "name": "Rock_Sandstone_Red_Brick"
    },
    {
      "x": -17,
      "y": 11,
      "z": -13,
      "name": "Rock_Sandstone_Cobble"
    },
    {
      "x": -17,
      "y": 12,
      "z": -13,
      "name": "Rock_Sandstone_Brick"
    },
    {
      "x": -17,
      "y": 1,
      "z": -12,
      "name": "Rock_Sandstone_Brick"
    },
    {
      "x": -17,
      "y": 9,
      "z": -12,
      "name": "Rock_Sandstone_Red_Brick"
    },
    {
      "x": -17,
      "y": 10,
      "z": -12,
      "name": "Rock_Sandstone_Red_Brick",
      "rotation": 3
    },
    {
      "x": -17,
      "y": 11,
      "z": -12,
      "name": "Rock_Sandstone_Cobble"
    },
    {
      "x": -17,
      "y": 12,
      "z": -12,
      "name": "Rock_Sandstone_Brick"
    },
    {
      "x": -17,
      "y": 1,
      "z": -11,
      "name": "Rock_Sandstone_Brick"
    },
    {
      "x": -17,
      "y": 9,
      "z": -11,
      "name": "Rock_Sandstone_Red_Cobble",
      "rotation": 3
    },
    {
      "x": -17,
      "y": 10,
      "z": -11,
      "name": "Rock_Sandstone_Red_Brick",
      "rotation": 3
    },
    {
      "x": -17,
      "y": 11,
      "z": -11,
      "name": "Rock_Sandstone_Cobble"
    },
    {
      "x": -17,
      "y": 12,
      "z": -11,
      "name": "Rock_Sandstone_Brick"
    },
    {
      "x": -17,
      "y": 1,
      "z": -10,
      "name": "Rock_Sandstone_Brick"
    },
    {
      "x": -17,
      "y": 8,
      "z": -10,
      "name": "Rock_Sandstone_Brick_Stairs",
      "rotation": 11
    },
    {
      "x": -17,
      "y": 9,
      "z": -10,
      "name": "Rock_Sandstone_Red_Brick",
      "rotation": 3
    },
    {
      "x": -17,
      "y": 10,
      "z": -10,
      "name": "Rock_Sandstone_Red_Brick",
      "rotation": 3
    },
    {
      "x": -17,
      "y": 11,
      "z": -10,
      "name": "Rock_Sandstone_Cobble"
    },
    {
      "x": -17,
      "y": 12,
      "z": -10,
      "name": "Rock_Sandstone_Brick"
    },
    {
      "x": -17,
      "y": 1,
      "z": -9,
      "name": "Rock_Sandstone_Brick"
    },
    {
      "x": -17,
      "y": 8,
      "z": -9,
      "name": "Rock_Sandstone_Brick_Stairs",
      "rotation": 33
    },
    {
      "x": -17,
      "y": 9,
      "z": -9,
      "name": "Rock_Sandstone_Red_Brick",
      "rotation": 3
    },
    {
      "x": -17,
      "y": 10,
      "z": -9,
      "name": "Rock_Sandstone_Red_Brick",
      "rotation": 3
    },
    {
      "x": -17,
      "y": 11,
      "z": -9,
      "name": "Rock_Sandstone_Cobble",
      "rotation": 3
    },
    {
      "x": -17,
      "y": 12,
      "z": -9,
      "name": "Rock_Sandstone_Brick"
    },
    {
      "x": -17,
      "y": 1,
      "z": -8,
      "name": "Rock_Sandstone_Brick",
      "rotation": 3
    },
    {
      "x": -17,
      "y": 2,
      "z": -8,
      "name": "Rock_Sandstone_Brick",
      "rotation": 3
    },
    {
      "x": -17,
      "y": 3,
      "z": -8,
      "name": "Rock_Sandstone_Brick",
      "rotation": 3
    },
    {
      "x": -17,
      "y": 8,
      "z": -8,
      "name": "Rock_Sandstone_Brick_Stairs",
      "rotation": 33
    },
    {
      "x": -17,
      "y": 9,
      "z": -8,
      "name": "Rock_Sandstone_Red_Brick",
      "rotation": 3
    },
    {
      "x": -17,
      "y": 10,
      "z": -8,
      "name": "Rock_Sandstone_Red_Brick",
      "rotation": 3
    },
    {
      "x": -17,
      "y": 11,
      "z": -8,
      "name": "Rock_Sandstone_Cobble",
      "rotation": 3
    },
    {
      "x": -17,
      "y": 12,
      "z": -8,
      "name": "Rock_Sandstone_Brick"
    },
    {
      "x": -17,
      "y": 1,
      "z": -7,
      "name": "Rock_Sandstone_Brick"
    },
    {
      "x": -17,
      "y": 2,
      "z": -7,
      "name": "Rock_Sandstone_Brick",
      "rotation": 3
    },
    {
      "x": -17,
      "y": 3,
      "z": -7,
      "name": "Soil_Sand"
    },
    {
      "x": -17,
      "y": 8,
      "z": -7,
      "name": "Rock_Sandstone_Brick_Stairs",
      "rotation": 33
    },
    {
      "x": -17,
      "y": 9,
      "z": -7,
      "name": "Rock_Sandstone_Red_Brick",
      "rotation": 3
    },
    {
      "x": -17,
      "y": 10,
      "z": -7,
      "name": "Rock_Sandstone_Red_Brick",
      "rotation": 3
    },
    {
      "x": -17,
      "y": 11,
      "z": -7,
      "name": "Rock_Sandstone_Cobble",
      "rotation": 3
    },
    {
      "x": -17,
      "y": 12,
      "z": -7,
      "name": "Rock_Sandstone_Brick"
    },
    {
      "x": -17,
      "y": 1,
      "z": -6,
      "name": "Rock_Sandstone_Brick"
    },
    {
      "x": -17,
      "y": 2,
      "z": -6,
      "name": "Rock_Sandstone_Brick",
      "rotation": 3
    },
    {
      "x": -17,
      "y": 3,
      "z": -6,
      "name": "Soil_Sand"
    },
    {
      "x": -17,
      "y": 8,
      "z": -6,
      "name": "Rock_Sandstone_Brick_Stairs",
      "rotation": 33
    },
    {
      "x": -17,
      "y": 9,
      "z": -6,
      "name": "Rock_Sandstone_Red_Brick",
      "rotation": 3
    },
    {
      "x": -17,
      "y": 10,
      "z": -6,
      "name": "Rock_Sandstone_Red_Brick",
      "rotation": 3
    },
    {
      "x": -17,
      "y": 11,
      "z": -6,
      "name": "Rock_Sandstone",
      "rotation": 3
    },
    {
      "x": -17,
      "y": 12,
      "z": -6,
      "name": "Rock_Sandstone_Brick"
    },
    {
      "x": -17,
      "y": 1,
      "z": -5,
      "name": "Rock_Sandstone_Brick"
    },
    {
      "x": -17,
      "y": 2,
      "z": -5,
      "name": "Rock_Sandstone_Brick",
      "rotation": 3
    },
    {
      "x": -17,
      "y": 3,
      "z": -5,
      "name": "Soil_Sand"
    },
    {
      "x": -17,
      "y": 4,
      "z": -5,
      "name": "Soil_Sand"
    },
    {
      "x": -17,
      "y": 8,
      "z": -5,
      "name": "Rock_Sandstone_Brick_Stairs",
      "rotation": 33
    },
    {
      "x": -17,
      "y": 9,
      "z": -5,
      "name": "Rock_Sandstone_Red_Brick",
      "rotation": 3
    },
    {
      "x": -17,
      "y": 10,
      "z": -5,
      "name": "Rock_Sandstone_Red_Brick",
      "rotation": 3
    },
    {
      "x": -17,
      "y": 11,
      "z": -5,
      "name": "Rock_Sandstone",
      "rotation": 3
    },
    {
      "x": -17,
      "y": 12,
      "z": -5,
      "name": "Rock_Sandstone_Brick"
    },
    {
      "x": -17,
      "y": 1,
      "z": -4,
      "name": "Rock_Sandstone_Brick"
    },
    {
      "x": -17,
      "y": 2,
      "z": -4,
      "name": "Rock_Sandstone_Brick",
      "rotation": 3
    },
    {
      "x": -17,
      "y": 3,
      "z": -4,
      "name": "Rock_Sandstone_Brick",
      "rotation": 3
    },
    {
      "x": -17,
      "y": 4,
      "z": -4,
      "name": "Soil_Sand"
    },
    {
      "x": -17,
      "y": 5,
      "z": -4,
      "name": "Soil_Sand"
    },
    {
      "x": -17,
      "y": 8,
      "z": -4,
      "name": "*Rock_Sandstone_Brick_Stairs_State_Definitions_Inverted_Corner_Right",
      "rotation": 33
    },
    {
      "x": -17,
      "y": 9,
      "z": -4,
      "name": "Rock_Sandstone_Red_Brick",
      "rotation": 3
    },
    {
      "x": -17,
      "y": 10,
      "z": -4,
      "name": "Rock_Sandstone_Red_Brick",
      "rotation": 3
    },
    {
      "x": -17,
      "y": 11,
      "z": -4,
      "name": "Rock_Sandstone",
      "rotation": 3
    },
    {
      "x": -17,
      "y": 12,
      "z": -4,
      "name": "Rock_Sandstone_Brick"
    },
    {
      "x": -17,
      "y": 1,
      "z": -3,
      "name": "Rock_Sandstone_Brick",
      "rotation": 3
    },
    {
      "x": -17,
      "y": 2,
      "z": -3,
      "name": "Rock_Sandstone_Brick",
      "rotation": 3
    },
    {
      "x": -17,
      "y": 3,
      "z": -3,
      "name": "Rock_Sandstone_Brick",
      "rotation": 3
    },
    {
      "x": -17,
      "y": 4,
      "z": -3,
      "name": "Rock_Sandstone_Brick",
      "rotation": 3
    },
    {
      "x": -17,
      "y": 5,
      "z": -3,
      "name": "Rock_Sandstone_Brick",
      "rotation": 3
    },
    {
      "x": -17,
      "y": 6,
      "z": -3,
      "name": "Rock_Sandstone_Cobble",
      "rotation": 3
    },
    {
      "x": -17,
      "y": 7,
      "z": -3,
      "name": "Rock_Sandstone_Cobble",
      "rotation": 3
    },
    {
      "x": -17,
      "y": 8,
      "z": -3,
      "name": "Rock_Sandstone_Cobble",
      "rotation": 3
    },
    {
      "x": -17,
      "y": 9,
      "z": -3,
      "name": "Rock_Sandstone_Brick",
      "rotation": 3
    },
    {
      "x": -17,
      "y": 10,
      "z": -3,
      "name": "Rock_Sandstone_Brick",
      "rotation": 3
    },
    {
      "x": -17,
      "y": 11,
      "z": -3,
      "name": "Rock_Sandstone_Brick",
      "rotation": 3
    },
    {
      "x": -17,
      "y": 12,
      "z": -3,
      "name": "Rock_Sandstone_Brick",
      "rotation": 3
    },
    {
      "x": -17,
      "y": 1,
      "z": -2,
      "name": "Rock_Sandstone_Cobble",
      "rotation": 3
    },
    {
      "x": -17,
      "y": 2,
      "z": -2,
      "name": "Rock_Sandstone_Cobble",
      "rotation": 3
    },
    {
      "x": -17,
      "y": 3,
      "z": -2,
      "name": "Rock_Sandstone_Cobble",
      "rotation": 3
    },
    {
      "x": -17,
      "y": 4,
      "z": -2,
      "name": "Rock_Sandstone_Cobble",
      "rotation": 3
    },
    {
      "x": -17,
      "y": 5,
      "z": -2,
      "name": "Rock_Sandstone_Brick_Ornate",
      "rotation": 3
    },
    {
      "x": -17,
      "y": 6,
      "z": -2,
      "name": "Rock_Sandstone_Brick_Stairs"
    },
    {
      "x": -17,
      "y": 10,
      "z": -2,
      "name": "Rock_Sandstone_Brick_Stairs",
      "rotation": 32
    },
    {
      "x": -17,
      "y": 11,
      "z": -2,
      "name": "Rock_Sandstone_Brick",
      "rotation": 3
    },
    {
      "x": -17,
      "y": 12,
      "z": -2,
      "name": "Rock_Sandstone_Brick",
      "rotation": 3
    },
    {
      "x": -17,
      "y": 1,
      "z": -1,
      "name": "Soil_Sand"
    },
    {
      "x": -17,
      "y": 2,
      "z": -1,
      "name": "Soil_Sand"
    },
    {
      "x": -16,
      "y": 1,
      "z": -20,
      "name": "Rock_Sandstone"
    },
    {
      "x": -16,
      "y": 1,
      "z": -19,
      "name": "Rock_Sandstone_Cobble",
      "rotation": 3
    },
    {
      "x": -16,
      "y": 2,
      "z": -19,
      "name": "Rock_Sandstone_Cobble",
      "rotation": 3
    },
    {
      "x": -16,
      "y": 3,
      "z": -19,
      "name": "Rock_Sandstone_Cobble",
      "rotation": 3
    },
    {
      "x": -16,
      "y": 4,
      "z": -19,
      "name": "Rock_Sandstone_Cobble",
      "rotation": 3
    },
    {
      "x": -16,
      "y": 5,
      "z": -19,
      "name": "Rock_Sandstone_Brick_Ornate",
      "rotation": 3
    },
    {
      "x": -16,
      "y": 6,
      "z": -19,
      "name": "Rock_Sandstone_Brick_Stairs",
      "rotation": 2
    },
    {
      "x": -16,
      "y": 1,
      "z": -18,
      "name": "Rock_Sandstone_Brick",
      "rotation": 3
    },
    {
      "x": -16,
      "y": 2,
      "z": -18,
      "name": "Rock_Sandstone_Brick",
      "rotation": 3
    },
    {
      "x": -16,
      "y": 3,
      "z": -18,
      "name": "Rock_Sandstone_Brick",
      "rotation": 3
    },
    {
      "x": -16,
      "y": 4,
      "z": -18,
      "name": "Rock_Sandstone_Brick",
      "rotation": 3
    },
    {
      "x": -16,
      "y": 5,
      "z": -18,
      "name": "Rock_Sandstone_Brick",
      "rotation": 3
    },
    {
      "x": -16,
      "y": 6,
      "z": -18,
      "name": "Rock_Sandstone_Cobble",
      "rotation": 3
    },
    {
      "x": -16,
      "y": 7,
      "z": -18,
      "name": "Rock_Sandstone_Cobble",
      "rotation": 3
    },
    {
      "x": -16,
      "y": 8,
      "z": -18,
      "name": "Rock_Sandstone_Cobble",
      "rotation": 3
    },
    {
      "x": -16,
      "y": 9,
      "z": -18,
      "name": "Rock_Sandstone_Cobble"
    },
    {
      "x": -16,
      "y": 1,
      "z": -17,
      "name": "Rock_Sandstone_Brick"
    },
    {
      "x": -16,
      "y": 2,
      "z": -17,
      "name": "Rock_Sandstone_Brick_Stairs",
      "rotation": 11
    },
    {
      "x": -16,
      "y": 3,
      "z": -17,
      "name": "Rock_Sandstone_Brick",
      "rotation": 3
    },
    {
      "x": -16,
      "y": 4,
      "z": -17,
      "name": "Soil_Sand",
      "rotation": 3
    },
    {
      "x": -16,
      "y": 9,
      "z": -17,
      "name": "Rock_Sandstone_Red_Brick"
    },
    {
      "x": -16,
      "y": 10,
      "z": -17,
      "name": "Rock_Sandstone_Red_Brick"
    },
    {
      "x": -16,
      "y": 1,
      "z": -16,
      "name": "Rock_Sandstone_Brick"
    },
    {
      "x": -16,
      "y": 2,
      "z": -16,
      "name": "Rock_Sandstone_Brick_Stairs",
      "rotation": 11
    },
    {
      "x": -16,
      "y": 3,
      "z": -16,
      "name": "Rock_Sandstone_Brick",
      "rotation": 3
    },
    {
      "x": -16,
      "y": 1,
      "z": -15,
      "name": "Rock_Sandstone_Brick"
    },
    {
      "x": -16,
      "y": 2,
      "z": -15,
      "name": "Rock_Sandstone_Brick_Stairs",
      "rotation": 11
    },
    {
      "x": -16,
      "y": 3,
      "z": -15,
      "name": "Rock_Sandstone_Brick",
      "rotation": 3
    },
    {
      "x": -16,
      "y": 11,
      "z": -15,
      "name": "Rock_Sandstone_Cobble"
    },
    {
      "x": -16,
      "y": 1,
      "z": -14,
      "name": "Rock_Sandstone_Brick"
    },
    {
      "x": -16,
      "y": 2,
      "z": -14,
      "name": "Rock_Sandstone_Brick_Stairs",
      "rotation": 11
    },
    {
      "x": -16,
      "y": 3,
      "z": -14,
      "name": "Rock_Sandstone_Brick",
      "rotation": 3
    },
    {
      "x": -16,
      "y": 11,
      "z": -14,
      "name": "Rock_Sandstone_Cobble"
    },
    {
      "x": -16,
      "y": 12,
      "z": -14,
      "name": "Rock_Sandstone_Brick"
    },
    {
      "x": -16,
      "y": 1,
      "z": -13,
      "name": "Rock_Sandstone_Brick"
    },
    {
      "x": -16,
      "y": 2,
      "z": -13,
      "name": "Rock_Sandstone_Brick_Stairs",
      "rotation": 11
    },
    {
      "x": -16,
      "y": 3,
      "z": -13,
      "name": "Rock_Sandstone_Brick",
      "rotation": 3
    },
    {
      "x": -16,
      "y": 11,
      "z": -13,
      "name": "Rock_Sandstone_Cobble"
    },
    {
      "x": -16,
      "y": 12,
      "z": -13,
      "name": "Rock_Sandstone_Brick"
    },
    {
      "x": -16,
      "y": 1,
      "z": -12,
      "name": "Rock_Sandstone_Brick"
    },
    {
      "x": -16,
      "y": 11,
      "z": -12,
      "name": "Rock_Sandstone_Cobble"
    },
    {
      "x": -16,
      "y": 12,
      "z": -12,
      "name": "Rock_Sandstone_Brick",
      "rotation": 1
    },
    {
      "x": -16,
      "y": 13,
      "z": -12,
      "name": "Rock_Sandstone_Brick_Smooth_Half",
      "rotation": 6
    },
    {
      "x": -16,
      "y": 14,
      "z": -12,
      "name": "Rock_Sandstone_Brick_Half",
      "rotation": 6
    },
    {
      "x": -16,
      "y": 15,
      "z": -12,
      "name": "Rock_Sandstone_Brick_Half",
      "rotation": 6
    },
    {
      "x": -16,
      "y": 16,
      "z": -12,
      "name": "Rock_Sandstone_Brick_Half",
      "rotation": 6
    },
    {
      "x": -16,
      "y": 17,
      "z": -12,
      "name": "Rock_Sandstone_Brick_Half",
      "rotation": 6
    },
    {
      "x": -16,
      "y": 18,
      "z": -12,
      "name": "Rock_Sandstone_Brick_Smooth_Half",
      "rotation": 6
    },
    {
      "x": -16,
      "y": 1,
      "z": -11,
      "name": "Rock_Sandstone_Brick"
    },
    {
      "x": -16,
      "y": 11,
      "z": -11,
      "name": "Rock_Sandstone_Cobble"
    },
    {
      "x": -16,
      "y": 12,
      "z": -11,
      "name": "Rock_Sandstone_Brick",
      "rotation": 1
    },
    {
      "x": -16,
      "y": 18,
      "z": -11,
      "name": "Rock_Sandstone_Brick_Smooth_Half",
      "rotation": 4
    },
    {
      "x": -16,
      "y": 19,
      "z": -11,
      "name": "Rock_Sandstone_Brick_Stairs",
      "rotation": 2
    },
    {
      "x": -16,
      "y": 20,
      "z": -11,
      "name": "Rock_Gold_Brick_Smooth_Half",
      "rotation": 7
    },
    {
      "x": -16,
      "y": 1,
      "z": -10,
      "name": "Soil_Sand"
    },
    {
      "x": -16,
      "y": 11,
      "z": -10,
      "name": "Rock_Sandstone_Cobble",
      "rotation": 3
    },
    {
      "x": -16,
      "y": 12,
      "z": -10,
      "name": "Rock_Sandstone_Brick",
      "rotation": 1
    },
    {
      "x": -16,
      "y": 19,
      "z": -10,
      "name": "Rock_Sandstone_Brick_Smooth_Half",
      "rotation": 35
    },
    {
      "x": -16,
      "y": 20,
      "z": -10,
      "name": "Rock_Sandstone_Brick_Smooth_Half",
      "rotation": 1
    },
    {
      "x": -16,
      "y": 1,
      "z": -9,
      "name": "Rock_Sandstone_Brick"
    },
    {
      "x": -16,
      "y": 11,
      "z": -9,
      "name": "Rock_Sandstone_Cobble",
      "rotation": 3
    },
    {
      "x": -16,
      "y": 12,
      "z": -9,
      "name": "Rock_Sandstone_Brick",
      "rotation": 1
    },
    {
      "x": -16,
      "y": 18,
      "z": -9,
      "name": "Rock_Sandstone_Brick_Smooth_Half",
      "rotation": 6
    },
    {
      "x": -16,
      "y": 19,
      "z": -9,
      "name": "Rock_Sandstone_Brick_Stairs"
    },
    {
      "x": -16,
      "y": 20,
      "z": -9,
      "name": "Rock_Gold_Brick_Smooth_Half",
      "rotation": 7
    },
    {
      "x": -16,
      "y": 1,
      "z": -8,
      "name": "Rock_Sandstone_Brick"
    },
    {
      "x": -16,
      "y": 2,
      "z": -8,
      "name": "Rock_Sandstone_Brick_Stairs",
      "rotation": 33
    },
    {
      "x": -16,
      "y": 3,
      "z": -8,
      "name": "Rock_Sandstone_Brick",
      "rotation": 3
    },
    {
      "x": -16,
      "y": 11,
      "z": -8,
      "name": "Rock_Sandstone_Cobble",
      "rotation": 3
    },
    {
      "x": -16,
      "y": 12,
      "z": -8,
      "name": "Rock_Sandstone_Brick",
      "rotation": 1
    },
    {
      "x": -16,
      "y": 13,
      "z": -8,
      "name": "Rock_Sandstone_Brick_Smooth_Half",
      "rotation": 4
    },
    {
      "x": -16,
      "y": 14,
      "z": -8,
      "name": "Rock_Sandstone_Brick_Half",
      "rotation": 4
    },
    {
      "x": -16,
      "y": 15,
      "z": -8,
      "name": "Rock_Sandstone_Brick_Half",
      "rotation": 4
    },
    {
      "x": -16,
      "y": 16,
      "z": -8,
      "name": "Rock_Sandstone_Brick_Half",
      "rotation": 4
    },
    {
      "x": -16,
      "y": 17,
      "z": -8,
      "name": "Rock_Sandstone_Brick_Half",
      "rotation": 4
    },
    {
      "x": -16,
      "y": 18,
      "z": -8,
      "name": "Rock_Sandstone_Brick_Smooth_Half",
      "rotation": 4
    },
    {
      "x": -16,
      "y": 1,
      "z": -7,
      "name": "Rock_Sandstone_Brick"
    },
    {
      "x": -16,
      "y": 2,
      "z": -7,
      "name": "Rock_Sandstone_Brick_Stairs",
      "rotation": 33
    },
    {
      "x": -16,
      "y": 3,
      "z": -7,
      "name": "Rock_Sandstone_Brick",
      "rotation": 3
    },
    {
      "x": -16,
      "y": 10,
      "z": -7,
      "name": "Rock_Sandstone_Cobble_Half",
      "rotation": 33
    },
    {
      "x": -16,
      "y": 11,
      "z": -7,
      "name": "Rock_Sandstone_Cobble",
      "rotation": 3
    },
    {
      "x": -16,
      "y": 12,
      "z": -7,
      "name": "Rock_Sandstone_Brick"
    },
    {
      "x": -16,
      "y": 1,
      "z": -6,
      "name": "Rock_Sandstone_Brick"
    },
    {
      "x": -16,
      "y": 2,
      "z": -6,
      "name": "Rock_Sandstone_Brick_Stairs",
      "rotation": 33
    },
    {
      "x": -16,
      "y": 3,
      "z": -6,
      "name": "Rock_Sandstone_Brick",
      "rotation": 3
    },
    {
      "x": -16,
      "y": 10,
      "z": -6,
      "name": "Rock_Sandstone_Cobble_Half",
      "rotation": 33
    },
    {
      "x": -16,
      "y": 11,
      "z": -6,
      "name": "Rock_Sandstone",
      "rotation": 3
    },
    {
      "x": -16,
      "y": 12,
      "z": -6,
      "name": "Rock_Sandstone_Brick"
    },
    {
      "x": -16,
      "y": 1,
      "z": -5,
      "name": "Rock_Sandstone_Brick"
    },
    {
      "x": -16,
      "y": 2,
      "z": -5,
      "name": "Rock_Sandstone_Brick_Stairs",
      "rotation": 33
    },
    {
      "x": -16,
      "y": 3,
      "z": -5,
      "name": "Rock_Sandstone_Brick",
      "rotation": 3
    },
    {
      "x": -16,
      "y": 10,
      "z": -5,
      "name": "Rock_Sandstone_Cobble_Half",
      "rotation": 33
    },
    {
      "x": -16,
      "y": 11,
      "z": -5,
      "name": "Rock_Sandstone",
      "rotation": 3
    },
    {
      "x": -16,
      "y": 12,
      "z": -5,
      "name": "Rock_Sandstone_Brick"
    },
    {
      "x": -16,
      "y": 1,
      "z": -4,
      "name": "Rock_Sandstone_Brick"
    },
    {
      "x": -16,
      "y": 2,
      "z": -4,
      "name": "Rock_Sandstone_Brick_Stairs",
      "rotation": 33
    },
    {
      "x": -16,
      "y": 3,
      "z": -4,
      "name": "Rock_Sandstone_Brick",
      "rotation": 3
    },
    {
      "x": -16,
      "y": 4,
      "z": -4,
      "name": "Rock_Sandstone_Red_Brick_Half",
      "rotation": 6
    },
    {
      "x": -16,
      "y": 8,
      "z": -4,
      "name": "Rock_Sandstone_Brick_Stairs",
      "rotation": 34
    },
    {
      "x": -16,
      "y": 9,
      "z": -4,
      "name": "Rock_Sandstone_Red_Brick",
      "rotation": 3
    },
    {
      "x": -16,
      "y": 10,
      "z": -4,
      "name": "Rock_Sandstone_Red_Brick",
      "rotation": 3
    },
    {
      "x": -16,
      "y": 11,
      "z": -4,
      "name": "Rock_Sandstone",
      "rotation": 3
    },
    {
      "x": -16,
      "y": 12,
      "z": -4,
      "name": "Rock_Sandstone_Brick"
    },
    {
      "x": -16,
      "y": 1,
      "z": -3,
      "name": "Rock_Sandstone_Brick",
      "rotation": 3
    },
    {
      "x": -16,
      "y": 2,
      "z": -3,
      "name": "Rock_Sandstone_Brick",
      "rotation": 3
    },
    {
      "x": -16,
      "y": 3,
      "z": -3,
      "name": "Rock_Sandstone_Brick",
      "rotation": 3
    },
    {
      "x": -16,
      "y": 4,
      "z": -3,
      "name": "Rock_Sandstone_Brick",
      "rotation": 3
    },
    {
      "x": -16,
      "y": 5,
      "z": -3,
      "name": "Rock_Sandstone_Brick",
      "rotation": 3
    },
    {
      "x": -16,
      "y": 6,
      "z": -3,
      "name": "Rock_Sandstone_Cobble",
      "rotation": 3
    },
    {
      "x": -16,
      "y": 7,
      "z": -3,
      "name": "Rock_Sandstone_Cobble",
      "rotation": 3
    },
    {
      "x": -16,
      "y": 8,
      "z": -3,
      "name": "Rock_Sandstone_Cobble",
      "rotation": 3
    },
    {
      "x": -16,
      "y": 9,
      "z": -3,
      "name": "Rock_Sandstone_Cobble",
      "rotation": 3
    },
    {
      "x": -16,
      "y": 10,
      "z": -3,
      "name": "Rock_Sandstone_Cobble",
      "rotation": 3
    },
    {
      "x": -16,
      "y": 11,
      "z": -3,
      "name": "Rock_Sandstone_Brick",
      "rotation": 3
    },
    {
      "x": -16,
      "y": 12,
      "z": -3,
      "name": "Rock_Sandstone_Brick",
      "rotation": 3
    },
    {
      "x": -16,
      "y": 1,
      "z": -2,
      "name": "Rock_Sandstone_Cobble",
      "rotation": 3
    },
    {
      "x": -16,
      "y": 2,
      "z": -2,
      "name": "Rock_Sandstone_Cobble",
      "rotation": 3
    },
    {
      "x": -16,
      "y": 3,
      "z": -2,
      "name": "Rock_Sandstone_Cobble",
      "rotation": 3
    },
    {
      "x": -16,
      "y": 4,
      "z": -2,
      "name": "Rock_Sandstone_Cobble",
      "rotation": 3
    },
    {
      "x": -16,
      "y": 5,
      "z": -2,
      "name": "Rock_Sandstone_Brick_Ornate",
      "rotation": 3
    },
    {
      "x": -16,
      "y": 6,
      "z": -2,
      "name": "Rock_Sandstone_Brick_Stairs"
    },
    {
      "x": -16,
      "y": 10,
      "z": -2,
      "name": "Rock_Sandstone_Brick_Stairs",
      "rotation": 32
    },
    {
      "x": -16,
      "y": 11,
      "z": -2,
      "name": "Rock_Sandstone_Brick",
      "rotation": 3
    },
    {
      "x": -16,
      "y": 12,
      "z": -2,
      "name": "Rock_Sandstone_Brick",
      "rotation": 3
    },
    {
      "x": -16,
      "y": 1,
      "z": -1,
      "name": "Soil_Sand"
    },
    {
      "x": -16,
      "y": 2,
      "z": -1,
      "name": "Soil_Sand"
    },
    {
      "x": -16,
      "y": 3,
      "z": -1,
      "name": "Soil_Sand"
    },
    {
      "x": -16,
      "y": 1,
      "z": 0,
      "name": "Soil_Sand"
    },
    {
      "x": -15,
      "y": 1,
      "z": -21,
      "name": "Rock_Sandstone_Red_Brick",
      "rotation": 3
    },
    {
      "x": -15,
      "y": 2,
      "z": -21,
      "name": "Rock_Sandstone_Red_Brick",
      "rotation": 3
    },
    {
      "x": -15,
      "y": 3,
      "z": -21,
      "name": "Rock_Sandstone_Red_Brick_Stairs",
      "rotation": 2
    },
    {
      "x": -15,
      "y": 1,
      "z": -20,
      "name": "Rock_Sandstone_Red_Brick",
      "rotation": 3
    },
    {
      "x": -15,
      "y": 2,
      "z": -20,
      "name": "Rock_Sandstone_Red_Brick",
      "rotation": 3
    },
    {
      "x": -15,
      "y": 3,
      "z": -20,
      "name": "Rock_Sandstone_Red_Brick",
      "rotation": 3
    },
    {
      "x": -15,
      "y": 4,
      "z": -20,
      "name": "Rock_Sandstone_Red_Brick_Stairs",
      "rotation": 2
    },
    {
      "x": -15,
      "y": 1,
      "z": -19,
      "name": "Rock_Sandstone_Brick",
      "rotation": 3
    },
    {
      "x": -15,
      "y": 2,
      "z": -19,
      "name": "Rock_Sandstone_Brick",
      "rotation": 3
    },
    {
      "x": -15,
      "y": 3,
      "z": -19,
      "name": "Rock_Sandstone_Brick",
      "rotation": 3
    },
    {
      "x": -15,
      "y": 4,
      "z": -19,
      "name": "Rock_Sandstone_Brick",
      "rotation": 3
    },
    {
      "x": -15,
      "y": 5,
      "z": -19,
      "name": "Rock_Sandstone_Brick_Ornate",
      "rotation": 3
    },
    {
      "x": -15,
      "y": 6,
      "z": -19,
      "name": "Rock_Sandstone_Brick_Stairs",
      "rotation": 2
    },
    {
      "x": -15,
      "y": 1,
      "z": -18,
      "name": "Rock_Sandstone_Brick",
      "rotation": 3
    },
    {
      "x": -15,
      "y": 2,
      "z": -18,
      "name": "Rock_Sandstone_Brick",
      "rotation": 3
    },
    {
      "x": -15,
      "y": 3,
      "z": -18,
      "name": "Rock_Sandstone_Brick",
      "rotation": 3
    },
    {
      "x": -15,
      "y": 4,
      "z": -18,
      "name": "Rock_Sandstone_Brick",
      "rotation": 3
    },
    {
      "x": -15,
      "y": 5,
      "z": -18,
      "name": "Rock_Sandstone_Brick",
      "rotation": 3
    },
    {
      "x": -15,
      "y": 6,
      "z": -18,
      "name": "Rock_Sandstone_Cobble",
      "rotation": 3
    },
    {
      "x": -15,
      "y": 7,
      "z": -18,
      "name": "Rock_Sandstone_Cobble",
      "rotation": 3
    },
    {
      "x": -15,
      "y": 8,
      "z": -18,
      "name": "Rock_Sandstone_Cobble",
      "rotation": 3
    },
    {
      "x": -15,
      "y": 9,
      "z": -18,
      "name": "Rock_Sandstone_Cobble"
    },
    {
      "x": -15,
      "y": 1,
      "z": -17,
      "name": "Rock_Sandstone_Brick"
    },
    {
      "x": -15,
      "y": 4,
      "z": -17,
      "name": "Rock_Sandstone_Red_Brick_Half",
      "rotation": 4
    },
    {
      "x": -15,
      "y": 9,
      "z": -17,
      "name": "Rock_Sandstone_Red_Brick"
    },
    {
      "x": -15,
      "y": 10,
      "z": -17,
      "name": "Rock_Sandstone_Red_Cobble"
    },
    {
      "x": -15,
      "y": 1,
      "z": -16,
      "name": "Rock_Sandstone_Brick"
    },
    {
      "x": -15,
      "y": 11,
      "z": -16,
      "name": "Rock_Sandstone_Cobble"
    },
    {
      "x": -15,
      "y": 1,
      "z": -15,
      "name": "Rock_Sandstone_Brick"
    },
    {
      "x": -15,
      "y": 11,
      "z": -15,
      "name": "Rock_Sandstone_Cobble"
    },
    {
      "x": -15,
      "y": 1,
      "z": -14,
      "name": "Rock_Sandstone_Brick"
    },
    {
      "x": -15,
      "y": 11,
      "z": -14,
      "name": "Rock_Sandstone_Cobble_Half",
      "rotation": 8
    },
    {
      "x": -15,
      "y": 12,
      "z": -14,
      "name": "Rock_Sandstone_Brick"
    },
    {
      "x": -15,
      "y": 13,
      "z": -14,
      "name": "Rock_Sandstone_Brick_Pillar_Base",
      "rotation": 1
    },
    {
      "x": -15,
      "y": 14,
      "z": -14,
      "name": "Rock_Sandstone_Brick_Pillar_Middle",
      "rotation": 1
    },
    {
      "x": -15,
      "y": 15,
      "z": -14,
      "name": "Rock_Sandstone_Brick_Pillar_Middle",
      "rotation": 1
    },
    {
      "x": -15,
      "y": 16,
      "z": -14,
      "name": "Rock_Sandstone_Brick_Pillar_Middle",
      "rotation": 1
    },
    {
      "x": -15,
      "y": 17,
      "z": -14,
      "name": "Rock_Sandstone_Brick_Pillar_Middle",
      "rotation": 1
    },
    {
      "x": -15,
      "y": 18,
      "z": -14,
      "name": "Rock_Sandstone_Brick_Pillar_Middle",
      "rotation": 1
    },
    {
      "x": -15,
      "y": 19,
      "z": -14,
      "name": "Rock_Sandstone_Brick_Pillar_Middle",
      "rotation": 1
    },
    {
      "x": -15,
      "y": 20,
      "z": -14,
      "name": "Rock_Sandstone_Brick_Pillar_Base",
      "rotation": 35
    },
    {
      "x": -15,
      "y": 1,
      "z": -13,
      "name": "Rock_Sandstone_Brick"
    },
    {
      "x": -15,
      "y": 11,
      "z": -13,
      "name": "Rock_Sandstone_Cobble"
    },
    {
      "x": -15,
      "y": 12,
      "z": -13,
      "name": "Rock_Sandstone_Brick_Smooth",
      "rotation": 1
    },
    {
      "x": -15,
      "y": 20,
      "z": -13,
      "name": "Rock_Gold_Brick_Smooth_Half",
      "rotation": 7
    },
    {
      "x": -15,
      "y": 1,
      "z": -12,
      "name": "Rock_Sandstone_Brick"
    },
    {
      "x": -15,
      "y": 11,
      "z": -12,
      "name": "Rock_Sandstone_Cobble"
    },
    {
      "x": -15,
      "y": 12,
      "z": -12,
      "name": "Wood_Drywood_Planks",
      "rotation": 1
    },
    {
      "x": -15,
      "y": 13,
      "z": -12,
      "name": "Rock_Sandstone_Brick",
      "rotation": 1
    },
    {
      "x": -15,
      "y": 14,
      "z": -12,
      "name": "Wood_Drywood_Planks",
      "rotation": 1
    },
    {
      "x": -15,
      "y": 15,
      "z": -12,
      "name": "Wood_Drywood_Planks",
      "rotation": 1
    },
    {
      "x": -15,
      "y": 16,
      "z": -12,
      "name": "Wood_Drywood_Planks",
      "rotation": 1
    },
    {
      "x": -15,
      "y": 17,
      "z": -12,
      "name": "Wood_Drywood_Planks",
      "rotation": 1
    },
    {
      "x": -15,
      "y": 18,
      "z": -12,
      "name": "Wood_Drywood_Planks",
      "rotation": 1
    },
    {
      "x": -15,
      "y": 19,
      "z": -12,
      "name": "Wood_Drywood_Planks",
      "rotation": 1
    },
    {
      "x": -15,
      "y": 20,
      "z": -12,
      "name": "Rock_Sandstone_Brick"
    },
    {
      "x": -15,
      "y": 21,
      "z": -12,
      "name": "Rock_Sandstone_Brick",
      "rotation": 1
    },
    {
      "x": -15,
      "y": 22,
      "z": -12,
      "name": "Rock_Sandstone_Brick",
      "rotation": 1
    },
    {
      "x": -15,
      "y": 23,
      "z": -12,
      "name": "Rock_Sandstone_Brick_Beam",
      "rotation": 1
    },
    {
      "x": -15,
      "y": 24,
      "z": -12,
      "name": "Rock_Sandstone_Brick_Beam",
      "rotation": 1
    },
    {
      "x": -15,
      "y": 1,
      "z": -11,
      "name": "Soil_Sand"
    },
    {
      "x": -15,
      "y": 11,
      "z": -11,
      "name": "Rock_Sandstone_Cobble"
    },
    {
      "x": -15,
      "y": 12,
      "z": -11,
      "name": "Wood_Drywood_Planks",
      "rotation": 1
    },
    {
      "x": -15,
      "y": 16,
      "z": -11,
      "name": "Furniture_Desert_Window",
      "rotation": 1
    },
    {
      "x": -15,
      "y": 17,
      "z": -11,
      "name": "Furniture_Desert_Window",
      "rotation": 1
    },
    {
      "x": -15,
      "y": 18,
      "z": -11,
      "name": "Furniture_Desert_Window",
      "rotation": 1
    },
    {
      "x": -15,
      "y": 19,
      "z": -11,
      "name": "Wood_Drywood_Planks",
      "rotation": 1
    },
    {
      "x": -15,
      "y": 20,
      "z": -11,
      "name": "Rock_Sandstone_Brick",
      "rotation": 1
    },
    {
      "x": -15,
      "y": 21,
      "z": -11,
      "name": "Rock_Sandstone_Brick_Smooth",
      "rotation": 1
    },
    {
      "x": -15,
      "y": 1,
      "z": -10,
      "name": "Soil_Sand"
    },
    {
      "x": -15,
      "y": 11,
      "z": -10,
      "name": "Rock_Sandstone_Cobble"
    },
    {
      "x": -15,
      "y": 12,
      "z": -10,
      "name": "Wood_Drywood_Planks",
      "rotation": 1
    },
    {
      "x": -15,
      "y": 16,
      "z": -10,
      "name": "Wood_Drywood_Beam"
    },
    {
      "x": -15,
      "y": 17,
      "z": -10,
      "name": "Furniture_Desert_Window",
      "rotation": 1
    },
    {
      "x": -15,
      "y": 18,
      "z": -10,
      "name": "Furniture_Desert_Window",
      "rotation": 1
    },
    {
      "x": -15,
      "y": 19,
      "z": -10,
      "name": "Furniture_Desert_Window",
      "rotation": 1
    },
    {
      "x": -15,
      "y": 20,
      "z": -10,
      "name": "Rock_Sandstone_Brick",
      "rotation": 1
    },
    {
      "x": -15,
      "y": 21,
      "z": -10,
      "name": "Rock_Sandstone_Brick_Smooth",
      "rotation": 1
    },
    {
      "x": -15,
      "y": 1,
      "z": -9,
      "name": "Rock_Sandstone_Brick"
    },
    {
      "x": -15,
      "y": 11,
      "z": -9,
      "name": "Rock_Sandstone_Cobble",
      "rotation": 3
    },
    {
      "x": -15,
      "y": 12,
      "z": -9,
      "name": "Wood_Drywood_Planks",
      "rotation": 1
    },
    {
      "x": -15,
      "y": 14,
      "z": -9,
      "name": "Wood_Drywood_Beam"
    },
    {
      "x": -15,
      "y": 15,
      "z": -9,
      "name": "Furniture_Desert_Window",
      "rotation": 1
    },
    {
      "x": -15,
      "y": 16,
      "z": -9,
      "name": "Furniture_Desert_Window",
      "rotation": 1
    },
    {
      "x": -15,
      "y": 17,
      "z": -9,
      "name": "Furniture_Desert_Window",
      "rotation": 1
    },
    {
      "x": -15,
      "y": 18,
      "z": -9,
      "name": "Furniture_Desert_Window",
      "rotation": 1
    },
    {
      "x": -15,
      "y": 19,
      "z": -9,
      "name": "Wood_Drywood_Planks",
      "rotation": 1
    },
    {
      "x": -15,
      "y": 20,
      "z": -9,
      "name": "Rock_Gold_Brick_Smooth_Half",
      "rotation": 7
    },
    {
      "x": -15,
      "y": 21,
      "z": -9,
      "name": "Rock_Sandstone_Brick",
      "rotation": 1
    },
    {
      "x": -15,
      "y": 22,
      "z": -9,
      "name": "Rock_Sandstone_Brick",
      "rotation": 1
    },
    {
      "x": -15,
      "y": 23,
      "z": -9,
      "name": "Rock_Sandstone_Brick_Beam",
      "rotation": 1
    },
    {
      "x": -15,
      "y": 24,
      "z": -9,
      "name": "Rock_Sandstone_Brick_Beam",
      "rotation": 1
    },
    {
      "x": -15,
      "y": 1,
      "z": -8,
      "name": "Rock_Sandstone_Brick"
    },
    {
      "x": -15,
      "y": 11,
      "z": -8,
      "name": "Rock_Sandstone_Cobble",
      "rotation": 3
    },
    {
      "x": -15,
      "y": 12,
      "z": -8,
      "name": "Wood_Drywood_Planks",
      "rotation": 1
    },
    {
      "x": -15,
      "y": 13,
      "z": -8,
      "name": "Rock_Sandstone_Brick",
      "rotation": 1
    },
    {
      "x": -15,
      "y": 14,
      "z": -8,
      "name": "Wood_Drywood_Planks",
      "rotation": 1
    },
    {
      "x": -15,
      "y": 15,
      "z": -8,
      "name": "Wood_Drywood_Planks",
      "rotation": 1
    },
    {
      "x": -15,
      "y": 16,
      "z": -8,
      "name": "Wood_Drywood_Planks",
      "rotation": 1
    },
    {
      "x": -15,
      "y": 17,
      "z": -8,
      "name": "Wood_Drywood_Planks",
      "rotation": 1
    },
    {
      "x": -15,
      "y": 18,
      "z": -8,
      "name": "Wood_Drywood_Planks",
      "rotation": 1
    },
    {
      "x": -15,
      "y": 19,
      "z": -8,
      "name": "Wood_Drywood_Planks",
      "rotation": 1
    },
    {
      "x": -15,
      "y": 20,
      "z": -8,
      "name": "Rock_Sandstone_Brick"
    },
    {
      "x": -15,
      "y": 1,
      "z": -7,
      "name": "Rock_Sandstone_Brick"
    },
    {
      "x": -15,
      "y": 11,
      "z": -7,
      "name": "Rock_Sandstone_Cobble",
      "rotation": 3
    },
    {
      "x": -15,
      "y": 12,
      "z": -7,
      "name": "Rock_Sandstone_Brick"
    },
    {
      "x": -15,
      "y": 20,
      "z": -7,
      "name": "Rock_Gold_Brick_Smooth_Half",
      "rotation": 7
    },
    {
      "x": -15,
      "y": 1,
      "z": -6,
      "name": "Rock_Sandstone_Brick"
    },
    {
      "x": -15,
      "y": 10,
      "z": -6,
      "name": "Rock_Sandstone_Cobble_Half",
      "rotation": 33
    },
    {
      "x": -15,
      "y": 11,
      "z": -6,
      "name": "Rock_Sandstone_Cobble",
      "rotation": 3
    },
    {
      "x": -15,
      "y": 12,
      "z": -6,
      "name": "Rock_Sandstone_Brick",
      "rotation": 1
    },
    {
      "x": -15,
      "y": 13,
      "z": -6,
      "name": "Rock_Sandstone_Brick",
      "rotation": 1
    },
    {
      "x": -15,
      "y": 14,
      "z": -6,
      "name": "Rock_Sandstone_Brick_Beam",
      "rotation": 1
    },
    {
      "x": -15,
      "y": 15,
      "z": -6,
      "name": "Rock_Sandstone_Brick_Beam",
      "rotation": 1
    },
    {
      "x": -15,
      "y": 16,
      "z": -6,
      "name": "Rock_Sandstone_Brick_Pillar_Middle",
      "rotation": 1
    },
    {
      "x": -15,
      "y": 17,
      "z": -6,
      "name": "Rock_Sandstone_Brick_Pillar_Middle",
      "rotation": 1
    },
    {
      "x": -15,
      "y": 18,
      "z": -6,
      "name": "Rock_Sandstone_Brick_Pillar_Middle",
      "rotation": 1
    },
    {
      "x": -15,
      "y": 19,
      "z": -6,
      "name": "Rock_Sandstone_Brick_Pillar_Middle",
      "rotation": 1
    },
    {
      "x": -15,
      "y": 20,
      "z": -6,
      "name": "Rock_Sandstone_Brick_Pillar_Base",
      "rotation": 35
    },
    {
      "x": -15,
      "y": 1,
      "z": -5,
      "name": "Rock_Sandstone_Brick"
    },
    {
      "x": -15,
      "y": 10,
      "z": -5,
      "name": "Rock_Sandstone_Cobble_Half",
      "rotation": 33
    },
    {
      "x": -15,
      "y": 11,
      "z": -5,
      "name": "Rock_Sandstone",
      "rotation": 3
    },
    {
      "x": -15,
      "y": 12,
      "z": -5,
      "name": "Rock_Sandstone_Brick"
    },
    {
      "x": -15,
      "y": 1,
      "z": -4,
      "name": "Rock_Sandstone_Brick"
    },
    {
      "x": -15,
      "y": 4,
      "z": -4,
      "name": "Rock_Sandstone_Red_Brick_Half",
      "rotation": 6
    },
    {
      "x": -15,
      "y": 8,
      "z": -4,
      "name": "Rock_Sandstone_Brick_Stairs",
      "rotation": 34
    },
    {
      "x": -15,
      "y": 9,
      "z": -4,
      "name": "Rock_Sandstone_Red_Brick",
      "rotation": 3
    },
    {
      "x": -15,
      "y": 10,
      "z": -4,
      "name": "Rock_Sandstone_Red_Cobble",
      "rotation": 3
    },
    {
      "x": -15,
      "y": 11,
      "z": -4,
      "name": "Rock_Sandstone",
      "rotation": 3
    },
    {
      "x": -15,
      "y": 12,
      "z": -4,
      "name": "Rock_Sandstone_Brick"
    },
    {
      "x": -15,
      "y": 1,
      "z": -3,
      "name": "Rock_Sandstone_Brick",
      "rotation": 3
    },
    {
      "x": -15,
      "y": 2,
      "z": -3,
      "name": "Rock_Sandstone_Brick",
      "rotation": 3
    },
    {
      "x": -15,
      "y": 3,
      "z": -3,
      "name": "Rock_Sandstone_Brick",
      "rotation": 3
    },
    {
      "x": -15,
      "y": 4,
      "z": -3,
      "name": "Rock_Sandstone_Brick",
      "rotation": 3
    },
    {
      "x": -15,
      "y": 5,
      "z": -3,
      "name": "Rock_Sandstone_Brick",
      "rotation": 3
    },
    {
      "x": -15,
      "y": 6,
      "z": -3,
      "name": "Rock_Sandstone_Cobble",
      "rotation": 3
    },
    {
      "x": -15,
      "y": 7,
      "z": -3,
      "name": "Rock_Sandstone_Cobble",
      "rotation": 3
    },
    {
      "x": -15,
      "y": 8,
      "z": -3,
      "name": "Rock_Sandstone_Cobble",
      "rotation": 3
    },
    {
      "x": -15,
      "y": 9,
      "z": -3,
      "name": "Rock_Sandstone_Cobble",
      "rotation": 3
    },
    {
      "x": -15,
      "y": 10,
      "z": -3,
      "name": "Rock_Sandstone_Cobble",
      "rotation": 3
    },
    {
      "x": -15,
      "y": 11,
      "z": -3,
      "name": "Rock_Sandstone_Brick",
      "rotation": 3
    },
    {
      "x": -15,
      "y": 12,
      "z": -3,
      "name": "Rock_Sandstone_Brick",
      "rotation": 3
    },
    {
      "x": -15,
      "y": 1,
      "z": -2,
      "name": "Rock_Sandstone_Brick",
      "rotation": 3
    },
    {
      "x": -15,
      "y": 2,
      "z": -2,
      "name": "Rock_Sandstone_Brick",
      "rotation": 3
    },
    {
      "x": -15,
      "y": 3,
      "z": -2,
      "name": "Rock_Sandstone_Brick",
      "rotation": 3
    },
    {
      "x": -15,
      "y": 4,
      "z": -2,
      "name": "Rock_Sandstone_Brick",
      "rotation": 3
    },
    {
      "x": -15,
      "y": 5,
      "z": -2,
      "name": "Rock_Sandstone_Brick_Ornate",
      "rotation": 3
    },
    {
      "x": -15,
      "y": 6,
      "z": -2,
      "name": "Rock_Sandstone_Brick_Stairs"
    },
    {
      "x": -15,
      "y": 10,
      "z": -2,
      "name": "Rock_Sandstone_Brick_Stairs",
      "rotation": 32
    },
    {
      "x": -15,
      "y": 11,
      "z": -2,
      "name": "Rock_Sandstone_Brick",
      "rotation": 3
    },
    {
      "x": -15,
      "y": 12,
      "z": -2,
      "name": "Rock_Sandstone_Brick",
      "rotation": 3
    },
    {
      "x": -15,
      "y": 1,
      "z": -1,
      "name": "Rock_Sandstone_Red_Cobble",
      "rotation": 3
    },
    {
      "x": -15,
      "y": 2,
      "z": -1,
      "name": "Rock_Sandstone_Red_Brick",
      "rotation": 3
    },
    {
      "x": -15,
      "y": 3,
      "z": -1,
      "name": "Rock_Sandstone_Red_Brick",
      "rotation": 3
    },
    {
      "x": -15,
      "y": 4,
      "z": -1,
      "name": "Rock_Sandstone_Red_Brick_Stairs"
    },
    {
      "x": -15,
      "y": 1,
      "z": 0,
      "name": "Rock_Sandstone_Red_Brick",
      "rotation": 3
    },
    {
      "x": -15,
      "y": 2,
      "z": 0,
      "name": "Rock_Sandstone_Red_Brick",
      "rotation": 3
    },
    {
      "x": -15,
      "y": 3,
      "z": 0,
      "name": "Rock_Sandstone_Red_Brick_Stairs"
    },
    {
      "x": -14,
      "y": 1,
      "z": -21,
      "name": "Rock_Sandstone_Red_Cobble",
      "rotation": 3
    },
    {
      "x": -14,
      "y": 2,
      "z": -21,
      "name": "Rock_Sandstone_Red_Brick",
      "rotation": 3
    },
    {
      "x": -14,
      "y": 3,
      "z": -21,
      "name": "Rock_Sandstone_Red_Brick_Stairs",
      "rotation": 2
    },
    {
      "x": -14,
      "y": 1,
      "z": -20,
      "name": "Rock_Sandstone_Red_Brick",
      "rotation": 3
    },
    {
      "x": -14,
      "y": 2,
      "z": -20,
      "name": "Rock_Sandstone_Red_Brick",
      "rotation": 3
    },
    {
      "x": -14,
      "y": 3,
      "z": -20,
      "name": "Rock_Sandstone_Red_Brick",
      "rotation": 3
    },
    {
      "x": -14,
      "y": 4,
      "z": -20,
      "name": "Rock_Sandstone_Red_Brick_Stairs",
      "rotation": 2
    },
    {
      "x": -14,
      "y": 1,
      "z": -19,
      "name": "Rock_Sandstone_Brick",
      "rotation": 3
    },
    {
      "x": -14,
      "y": 2,
