{
  "version": 8,
  "blockIdVersion": 11,
  "anchorX": 0,
  "anchorY": 3,
  "anchorZ": -1,
  "blocks": [
    {
      "x": -14,
      "y": 17,
      "z": -2,
      "name": "Plant_Leaves_Wisteria_Wild"
    },
    {
      "x": -14,
      "y": 17,
      "z": 0,
      "name": "Plant_Leaves_Wisteria_Wild"
    },
    {
      "x": -13,
      "y": 17,
      "z": -2,
      "name": "Plant_Leaves_Wisteria_Wild"
    },
    {
      "x": -13,
      "y": 17,
      "z": -1,
      "name": "Plant_Leaves_Wisteria_Wild"
    },
    {
      "x": -13,
      "y": 17,
      "z": 0,
      "name": "Plant_Leaves_Wisteria_Wild"
    },
    {
      "x": -13,
      "y": 17,
      "z": 1,
      "name": "Plant_Leaves_Wisteria_Wild"
    },
    {
      "x": -12,
      "y": 17,
      "z": -3,
      "name": "Plant_Leaves_Wisteria_Wild"
    },
    {
      "x": -12,
      "y": 17,
      "z": -2,
      "name": "Plant_Leaves_Wisteria_Wild"
    },
    {
      "x": -12,
      "y": 18,
      "z": -2,
      "name": "Plant_Leaves_Wisteria_Wild"
    },
    {
      "x": -12,
      "y": 17,
      "z": -1,
      "name": "Plant_Leaves_Wisteria_Wild"
    },
    {
      "x": -12,
      "y": 17,
      "z": 0,
      "name": "Plant_Leaves_Wisteria_Wild"
    },
    {
      "x": -12,
      "y": 16,
      "z": 1,
      "name": "Plant_Leaves_Wisteria_Wild"
    },
    {
      "x": -12,
      "y": 17,
      "z": 1,
      "name": "Plant_Leaves_Wisteria_Wild"
    },
    {
      "x": -12,
      "y": 18,
      "z": 1,
      "name": "Plant_Leaves_Wisteria_Wild"
    },
    {
      "x": -12,
      "y": 16,
      "z": 2,
      "name": "Plant_Leaves_Wisteria_Wild"
    },
    {
      "x": -12,
      "y": 16,
      "z": 3,
      "name": "Plant_Leaves_Wisteria_Wild"
    },
    {
      "x": -11,
      "y": 16,
      "z": -5,
      "name": "Plant_Leaves_Wisteria_Wild"
    },
    {
      "x": -11,
      "y": 16,
      "z": -4,
      "name": "Plant_Leaves_Wisteria_Wild"
    },
    {
      "x": -11,
      "y": 17,
      "z": -4,
      "name": "Plant_Leaves_Wisteria_Wild"
    },
    {
      "x": -11,
      "y": 17,
      "z": -3,
      "name": "Plant_Leaves_Wisteria_Wild"
    },
    {
      "x": -11,
      "y": 17,
      "z": -2,
      "name": "Plant_Leaves_Wisteria_Wild"
    },
    {
      "x": -11,
      "y": 18,
      "z": -2,
      "name": "Plant_Leaves_Wisteria_Wild"
    },
    {
      "x": -11,
      "y": 17,
      "z": -1,
      "name": "Plant_Leaves_Wisteria_Wild"
    },
    {
      "x": -11,
      "y": 16,
      "z": 0,
      "name": "Plant_Leaves_Wisteria_Wild"
    },
    {
      "x": -11,
      "y": 18,
      "z": 0,
      "name": "Plant_Leaves_Wisteria_Wild"
    },
    {
      "x": -11,
      "y": 16,
      "z": 1,
      "name": "Plant_Leaves_Wisteria_Wild"
    },
    {
      "x": -11,
      "y": 17,
      "z": 1,
      "name": "Plant_Leaves_Wisteria_Wild"
    },
    {
      "x": -11,
      "y": 18,
      "z": 1,
      "name": "Plant_Leaves_Wisteria_Wild"
    },
    {
      "x": -11,
      "y": 17,
      "z": 2,
      "name": "Plant_Leaves_Wisteria_Wild"
    },
    {
      "x": -11,
      "y": 17,
      "z": 3,
      "name": "Plant_Leaves_Wisteria_Wild"
    },
    {
      "x": -11,
      "y": 16,
      "z": 4,
      "name": "Plant_Leaves_Wisteria_Wild"
    },
    {
      "x": -10,
      "y": 16,
      "z": -7,
      "name": "Plant_Leaves_Wisteria_Wild"
    },
    {
      "x": -10,
      "y": 16,
      "z": -6,
      "name": "Plant_Leaves_Wisteria_Wild"
    },
    {
      "x": -10,
      "y": 16,
      "z": -5,
      "name": "Plant_Leaves_Wisteria_Wild"
    },
    {
      "x": -10,
      "y": 17,
      "z": -4,
      "name": "Plant_Leaves_Wisteria_Wild"
    },
    {
      "x": -10,
      "y": 16,
      "z": -3,
      "name": "Plant_Leaves_Wisteria_Wild"
    },
    {
      "x": -10,
      "y": 17,
      "z": -3,
      "name": "Plant_Leaves_Wisteria_Wild"
    },
    {
      "x": -10,
      "y": 16,
      "z": -2,
      "name": "Plant_Leaves_Wisteria_Wild"
    },
    {
      "x": -10,
      "y": 17,
      "z": -2,
      "name": "Plant_Leaves_Wisteria_Wild"
    },
    {
      "x": -10,
      "y": 18,
      "z": -2,
      "name": "Plant_Leaves_Wisteria_Wild"
    },
    {
      "x": -10,
      "y": 17,
      "z": -1,
      "name": "Plant_Leaves_Wisteria_Wild"
    },
    {
      "x": -10,
      "y": 18,
      "z": -1,
      "name": "Plant_Leaves_Wisteria_Wild"
    },
    {
      "x": -10,
      "y": 17,
      "z": 0,
      "name": "Plant_Leaves_Wisteria_Wild"
    },
    {
      "x": -10,
      "y": 18,
      "z": 0,
      "name": "Plant_Leaves_Wisteria_Wild"
    },
    {
      "x": -10,
      "y": 17,
      "z": 1,
      "name": "Plant_Leaves_Wisteria_Wild"
    },
    {
      "x": -10,
      "y": 18,
      "z": 1,
      "name": "Plant_Leaves_Wisteria_Wild"
    },
    {
      "x": -10,
      "y": 17,
      "z": 2,
      "name": "Plant_Leaves_Wisteria_Wild"
    },
    {
      "x": -10,
      "y": 18,
      "z": 2,
      "name": "Plant_Leaves_Wisteria_Wild"
    },
    {
      "x": -10,
      "y": 16,
      "z": 3,
      "name": "Plant_Leaves_Wisteria_Wild"
    },
    {
      "x": -10,
      "y": 17,
      "z": 3,
      "name": "Plant_Leaves_Wisteria_Wild"
    },
    {
      "x": -10,
      "y": 16,
      "z": 4,
      "name": "Plant_Leaves_Wisteria_Wild"
    },
    {
      "x": -9,
      "y": 18,
      "z": -9,
      "name": "Plant_Leaves_Wisteria_Wild"
    },
    {
      "x": -9,
      "y": 18,
      "z": -8,
      "name": "Plant_Leaves_Wisteria_Wild"
    },
    {
      "x": -9,
      "y": 16,
      "z": -7,
      "name": "Plant_Leaves_Wisteria_Wild"
    },
    {
      "x": -9,
      "y": 16,
      "z": -6,
      "name": "Plant_Leaves_Wisteria_Wild"
    },
    {
      "x": -9,
      "y": 17,
      "z": -6,
      "name": "Plant_Leaves_Wisteria_Wild"
    },
    {
      "x": -9,
      "y": 16,
      "z": -5,
      "name": "Plant_Leaves_Wisteria_Wild"
    },
    {
      "x": -9,
      "y": 17,
      "z": -5,
      "name": "Plant_Leaves_Wisteria_Wild"
    },
    {
      "x": -9,
      "y": 16,
      "z": -4,
      "name": "Plant_Leaves_Wisteria_Wild"
    },
    {
      "x": -9,
      "y": 17,
      "z": -4,
      "name": "Plant_Leaves_Wisteria_Wild"
    },
    {
      "x": -9,
      "y": 18,
      "z": -4,
      "name": "Plant_Leaves_Wisteria_Wild"
    },
    {
      "x": -9,
      "y": 17,
      "z": -3,
      "name": "Plant_Leaves_Wisteria_Wild"
    },
    {
      "x": -9,
      "y": 18,
      "z": -3,
      "name": "Plant_Leaves_Wisteria_Wild"
    },
    {
      "x": -9,
      "y": 17,
      "z": -2,
      "name": "Plant_Leaves_Wisteria_Wild"
    },
    {
      "x": -9,
      "y": 18,
      "z": -2,
      "name": "Plant_Leaves_Wisteria_Wild"
    },
    {
      "x": -9,
      "y": 19,
      "z": -2,
      "name": "Plant_Leaves_Wisteria_Wild"
    },
    {
      "x": -9,
      "y": 17,
      "z": -1,
      "name": "Wood_Wisteria_Wild_Trunk_Full"
    },
    {
      "x": -9,
      "y": 19,
      "z": -1,
      "name": "Plant_Leaves_Wisteria_Wild"
    },
    {
      "x": -9,
      "y": 17,
      "z": 0,
      "name": "Plant_Leaves_Wisteria_Wild"
    },
    {
      "x": -9,
      "y": 18,
      "z": 0,
      "name": "Plant_Leaves_Wisteria_Wild"
    },
    {
      "x": -9,
      "y": 19,
      "z": 0,
      "name": "Plant_Leaves_Wisteria_Wild"
    },
    {
      "x": -9,
      "y": 17,
      "z": 1,
      "name": "Plant_Leaves_Wisteria_Wild"
    },
    {
      "x": -9,
      "y": 18,
      "z": 1,
      "name": "Plant_Leaves_Wisteria_Wild"
    },
    {
      "x": -9,
      "y": 19,
      "z": 1,
      "name": "Plant_Leaves_Wisteria_Wild"
    },
    {
      "x": -9,
      "y": 17,
      "z": 2,
      "name": "Plant_Leaves_Wisteria_Wild"
    },
    {
      "x": -9,
      "y": 18,
      "z": 2,
      "name": "Plant_Leaves_Wisteria_Wild"
    },
    {
      "x": -9,
      "y": 16,
      "z": 3,
      "name": "Plant_Leaves_Wisteria_Wild"
    },
    {
      "x": -9,
      "y": 17,
      "z": 3,
      "name": "Plant_Leaves_Wisteria_Wild"
    },
    {
      "x": -9,
      "y": 16,
      "z": 4,
      "name": "Plant_Leaves_Wisteria_Wild"
    },
    {
      "x": -9,
      "y": 17,
      "z": 4,
      "name": "Plant_Leaves_Wisteria_Wild"
    },
    {
      "x": -8,
      "y": 18,
      "z": -10,
      "name": "Plant_Leaves_Wisteria_Wild"
    },
    {
      "x": -8,
      "y": 18,
      "z": -9,
      "name": "Plant_Leaves_Wisteria_Wild"
    },
    {
      "x": -8,
      "y": 16,
      "z": -8,
      "name": "Plant_Leaves_Wisteria_Wild"
    },
    {
      "x": -8,
      "y": 18,
      "z": -8,
      "name": "Plant_Leaves_Wisteria_Wild"
    },
    {
      "x": -8,
      "y": 16,
      "z": -7,
      "name": "Plant_Leaves_Wisteria_Wild"
    },
    {
      "x": -8,
      "y": 17,
      "z": -7,
      "name": "Plant_Leaves_Wisteria_Wild"
    },
    {
      "x": -8,
      "y": 18,
      "z": -7,
      "name": "Plant_Leaves_Wisteria_Wild"
    },
    {
      "x": -8,
      "y": 17,
      "z": -6,
      "name": "Plant_Leaves_Wisteria_Wild"
    },
    {
      "x": -8,
      "y": 18,
      "z": -6,
      "name": "Plant_Leaves_Wisteria_Wild"
    },
    {
      "x": -8,
      "y": 17,
      "z": -5,
      "name": "Plant_Leaves_Wisteria_Wild"
    },
    {
      "x": -8,
      "y": 18,
      "z": -5,
      "name": "Plant_Leaves_Wisteria_Wild"
    },
    {
      "x": -8,
      "y": 17,
      "z": -4,
      "name": "Plant_Leaves_Wisteria_Wild"
    },
    {
      "x": -8,
      "y": 18,
      "z": -4,
      "name": "Plant_Leaves_Wisteria_Wild"
    },
    {
      "x": -8,
      "y": 18,
      "z": -3,
      "name": "Plant_Leaves_Wisteria_Wild"
    },
    {
      "x": -8,
      "y": 19,
      "z": -3,
      "name": "Plant_Leaves_Wisteria_Wild"
    },
    {
      "x": -8,
      "y": 16,
      "z": -2,
      "name": "Plant_Leaves_Wisteria_Wild"
    },
    {
      "x": -8,
      "y": 17,
      "z": -2,
      "name": "Plant_Leaves_Wisteria_Wild"
    },
    {
      "x": -8,
      "y": 18,
      "z": -2,
      "name": "Plant_Leaves_Wisteria_Wild"
    },
    {
      "x": -8,
      "y": 19,
      "z": -2,
      "name": "Plant_Leaves_Wisteria_Wild"
    },
    {
      "x": -8,
      "y": 17,
      "z": -1,
      "name": "Wood_Wisteria_Wild_Trunk_Full"
    },
    {
      "x": -8,
      "y": 19,
      "z": -1,
      "name": "Plant_Leaves_Wisteria_Wild"
    },
    {
      "x": -8,
      "y": 17,
      "z": 0,
      "name": "Plant_Leaves_Wisteria_Wild"
    },
    {
      "x": -8,
      "y": 19,
      "z": 0,
      "name": "Plant_Leaves_Wisteria_Wild"
    },
    {
      "x": -8,
      "y": 18,
      "z": 1,
      "name": "Plant_Leaves_Wisteria_Wild"
    },
    {
      "x": -8,
      "y": 18,
      "z": 2,
      "name": "Plant_Leaves_Wisteria_Wild"
    },
    {
      "x": -8,
      "y": 17,
      "z": 3,
      "name": "Plant_Leaves_Wisteria_Wild"
    },
    {
      "x": -8,
      "y": 18,
      "z": 3,
      "name": "Plant_Leaves_Wisteria_Wild"
    },
    {
      "x": -8,
      "y": 16,
      "z": 4,
      "name": "Plant_Leaves_Wisteria_Wild"
    },
    {
      "x": -8,
      "y": 17,
      "z": 4,
      "name": "Plant_Leaves_Wisteria_Wild"
    },
    {
      "x": -8,
      "y": 18,
      "z": 4,
      "name": "Plant_Leaves_Wisteria_Wild"
    },
    {
      "x": -8,
      "y": 16,
      "z": 5,
      "name": "Plant_Leaves_Wisteria_Wild"
    },
    {
      "x": -8,
      "y": 17,
      "z": 6,
      "name": "Plant_Leaves_Wisteria_Wild"
    },
    {
      "x": -7,
      "y": 17,
      "z": -13,
      "name": "Plant_Leaves_Wisteria_Wild"
    },
    {
      "x": -7,
      "y": 18,
      "z": -12,
      "name": "Plant_Leaves_Wisteria_Wild"
    },
    {
      "x": -7,
      "y": 18,
      "z": -11,
      "name": "Plant_Leaves_Wisteria_Wild"
    },
    {
      "x": -7,
      "y": 18,
      "z": -10,
      "name": "Plant_Leaves_Wisteria_Wild"
    },
    {
      "x": -7,
      "y": 18,
      "z": -9,
      "name": "Plant_Leaves_Wisteria_Wild"
    },
    {
      "x": -7,
      "y": 19,
      "z": -9,
      "name": "Plant_Leaves_Wisteria_Wild"
    },
    {
      "x": -7,
      "y": 16,
      "z": -8,
      "name": "Plant_Leaves_Wisteria_Wild"
    },
    {
      "x": -7,
      "y": 17,
      "z": -8,
      "name": "Plant_Leaves_Wisteria_Wild"
    },
    {
      "x": -7,
      "y": 18,
      "z": -8,
      "name": "Plant_Leaves_Wisteria_Wild"
    },
    {
      "x": -7,
      "y": 19,
      "z": -8,
      "name": "Plant_Leaves_Wisteria_Wild"
    },
    {
      "x": -7,
      "y": 17,
      "z": -7,
      "name": "Plant_Leaves_Wisteria_Wild"
    },
    {
      "x": -7,
      "y": 18,
      "z": -7,
      "name": "Plant_Leaves_Wisteria_Wild"
    },
    {
      "x": -7,
      "y": 19,
      "z": -7,
      "name": "Plant_Leaves_Wisteria_Wild"
    },
    {
      "x": -7,
      "y": 17,
      "z": -6,
      "name": "Plant_Leaves_Wisteria_Wild"
    },
    {
      "x": -7,
      "y": 18,
      "z": -6,
      "name": "Plant_Leaves_Wisteria_Wild"
    },
    {
      "x": -7,
      "y": 17,
      "z": -5,
      "name": "Plant_Leaves_Wisteria_Wild"
    },
    {
      "x": -7,
      "y": 18,
      "z": -5,
      "name": "Plant_Leaves_Wisteria_Wild"
    },
    {
      "x": -7,
      "y": 18,
      "z": -4,
      "name": "Wood_Wisteria_Wild_Trunk_Full"
    },
    {
      "x": -7,
      "y": 19,
      "z": -4,
      "name": "Plant_Leaves_Wisteria_Wild"
    },
    {
      "x": -7,
      "y": 18,
      "z": -3,
      "name": "Wood_Wisteria_Wild_Trunk_Full"
    },
    {
      "x": -7,
      "y": 19,
      "z": -3,
      "name": "Plant_Leaves_Wisteria_Wild"
    },
    {
      "x": -7,
      "y": 18,
      "z": -2,
      "name": "Wood_Wisteria_Wild_Trunk_Full"
    },
    {
      "x": -7,
      "y": 19,
      "z": -2,
      "name": "Plant_Leaves_Wisteria_Wild"
    },
    {
      "x": -7,
      "y": 17,
      "z": -1,
      "name": "Wood_Wisteria_Wild_Trunk_Full"
    },
    {
      "x": -7,
      "y": 18,
      "z": -1,
      "name": "Wood_Wisteria_Wild_Trunk_Full",
      "rotation": 5
    },
    {
      "x": -7,
      "y": 19,
      "z": 0,
      "name": "Plant_Leaves_Wisteria_Wild"
    },
    {
      "x": -7,
      "y": 18,
      "z": 1,
      "name": "Wood_Wisteria_Wild_Trunk_Full"
    },
    {
      "x": -7,
      "y": 19,
      "z": 1,
      "name": "Plant_Leaves_Wisteria_Wild"
    },
    {
      "x": -7,
      "y": 17,
      "z": 2,
      "name": "Plant_Leaves_Wisteria_Wild"
    },
    {
      "x": -7,
      "y": 18,
      "z": 2,
      "name": "Plant_Leaves_Wisteria_Wild"
    },
    {
      "x": -7,
      "y": 19,
      "z": 2,
      "name": "Plant_Leaves_Wisteria_Wild"
    },
    {
      "x": -7,
      "y": 16,
      "z": 3,
      "name": "Plant_Leaves_Wisteria_Wild"
    },
    {
      "x": -7,
      "y": 17,
      "z": 3,
      "name": "Plant_Leaves_Wisteria_Wild"
    },
    {
      "x": -7,
      "y": 18,
      "z": 3,
      "name": "Plant_Leaves_Wisteria_Wild"
    },
    {
      "x": -7,
      "y": 17,
      "z": 4,
      "name": "Plant_Leaves_Wisteria_Wild"
    },
    {
      "x": -7,
      "y": 18,
      "z": 4,
      "name": "Plant_Leaves_Wisteria_Wild"
    },
    {
      "x": -7,
      "y": 17,
      "z": 5,
      "name": "Plant_Leaves_Wisteria_Wild"
    },
    {
      "x": -7,
      "y": 17,
      "z": 6,
      "name": "Plant_Leaves_Wisteria_Wild"
    },
    {
      "x": -7,
      "y": 17,
      "z": 7,
      "name": "Plant_Leaves_Wisteria_Wild"
    },
    {
      "x": -6,
      "y": 17,
      "z": -14,
      "name": "Plant_Leaves_Wisteria_Wild"
    },
    {
      "x": -6,
      "y": 17,
      "z": -13,
      "name": "Plant_Leaves_Wisteria_Wild"
    },
    {
      "x": -6,
      "y": 17,
      "z": -12,
      "name": "Plant_Leaves_Wisteria_Wild"
    },
    {
      "x": -6,
      "y": 18,
      "z": -12,
      "name": "Plant_Leaves_Wisteria_Wild"
    },
    {
      "x": -6,
      "y": 19,
      "z": -10,
      "name": "Plant_Leaves_Wisteria_Wild"
    },
    {
      "x": -6,
      "y": 18,
      "z": -9,
      "name": "Plant_Leaves_Wisteria_Wild"
    },
    {
      "x": -6,
      "y": 19,
      "z": -9,
      "name": "Plant_Leaves_Wisteria_Wild"
    },
    {
      "x": -6,
      "y": 16,
      "z": -8,
      "name": "Plant_Leaves_Wisteria_Wild"
    },
    {
      "x": -6,
      "y": 17,
      "z": -8,
      "name": "Plant_Leaves_Wisteria_Wild"
    },
    {
      "x": -6,
      "y": 18,
      "z": -8,
      "name": "Plant_Leaves_Wisteria_Wild"
    },
    {
      "x": -6,
      "y": 16,
      "z": -7,
      "name": "Plant_Leaves_Wisteria_Wild"
    },
    {
      "x": -6,
      "y": 17,
      "z": -7,
      "name": "Plant_Leaves_Wisteria_Wild"
    },
    {
      "x": -6,
      "y": 18,
      "z": -7,
      "name": "Plant_Leaves_Wisteria_Wild"
    },
    {
      "x": -6,
      "y": 19,
      "z": -7,
      "name": "Plant_Leaves_Wisteria_Wild"
    },
    {
      "x": -6,
      "y": 17,
      "z": -6,
      "name": "Plant_Leaves_Wisteria_Wild"
    },
    {
      "x": -6,
      "y": 18,
      "z": -6,
      "name": "Plant_Leaves_Wisteria_Wild"
    },
    {
      "x": -6,
      "y": 19,
      "z": -6,
      "name": "Plant_Leaves_Wisteria_Wild"
    },
    {
      "x": -6,
      "y": 17,
      "z": -5,
      "name": "Plant_Leaves_Wisteria_Wild"
    },
    {
      "x": -6,
      "y": 18,
      "z": -5,
      "name": "Plant_Leaves_Wisteria_Wild"
    },
    {
      "x": -6,
      "y": 17,
      "z": -4,
      "name": "Plant_Leaves_Wisteria_Wild"
    },
    {
      "x": -6,
      "y": 18,
      "z": -4,
      "name": "Plant_Leaves_Wisteria_Wild"
    },
    {
      "x": -6,
      "y": 17,
      "z": -3,
      "name": "Plant_Leaves_Wisteria_Wild"
    },
    {
      "x": -6,
      "y": 18,
      "z": -3,
      "name": "Plant_Leaves_Wisteria_Wild"
    },
    {
      "x": -6,
      "y": 19,
      "z": -3,
      "name": "Plant_Leaves_Wisteria_Wild"
    },
    {
      "x": -6,
      "y": 19,
      "z": -2,
      "name": "Plant_Leaves_Wisteria_Wild"
    },
    {
      "x": -6,
      "y": 17,
      "z": -1,
      "name": "Wood_Wisteria_Wild_Trunk_Full"
    },
    {
      "x": -6,
      "y": 18,
      "z": -1,
      "name": "Wood_Wisteria_Wild_Trunk_Full"
    },
    {
      "x": -6,
      "y": 18,
      "z": 0,
      "name": "Wood_Wisteria_Wild_Trunk_Full"
    },
    {
      "x": -6,
      "y": 19,
      "z": 0,
      "name": "Plant_Leaves_Wisteria_Wild"
    },
    {
      "x": -6,
      "y": 18,
      "z": 1,
      "name": "Wood_Wisteria_Wild_Trunk_Full"
    },
    {
      "x": -6,
      "y": 19,
      "z": 1,
      "name": "Plant_Leaves_Wisteria_Wild"
    },
    {
      "x": -6,
      "y": 18,
      "z": 2,
      "name": "Wood_Wisteria_Wild_Trunk_Full"
    },
    {
      "x": -6,
      "y": 19,
      "z": 2,
      "name": "Plant_Leaves_Wisteria_Wild"
    },
    {
      "x": -6,
      "y": 16,
      "z": 3,
      "name": "Plant_Leaves_Wisteria_Wild"
    },
    {
      "x": -6,
      "y": 18,
      "z": 3,
      "name": "Wood_Wisteria_Wild_Trunk_Full"
    },
    {
      "x": -6,
      "y": 17,
      "z": 4,
      "name": "Plant_Leaves_Wisteria_Wild"
    },
    {
      "x": -6,
      "y": 19,
      "z": 4,
      "name": "Plant_Leaves_Wisteria_Wild"
    },
    {
      "x": -6,
      "y": 17,
      "z": 5,
      "name": "Plant_Leaves_Wisteria_Wild"
    },
    {
      "x": -6,
      "y": 18,
      "z": 5,
      "name": "Plant_Leaves_Wisteria_Wild"
    },
    {
      "x": -6,
      "y": 17,
      "z": 6,
      "name": "Plant_Leaves_Wisteria_Wild"
    },
    {
      "x": -6,
      "y": 17,
      "z": 7,
      "name": "Plant_Leaves_Wisteria_Wild"
    },
    {
      "x": -5,
      "y": 17,
      "z": -14,
      "name": "Plant_Leaves_Wisteria_Wild"
    },
    {
      "x": -5,
      "y": 17,
      "z": -13,
      "name": "Plant_Leaves_Wisteria_Wild"
    },
    {
      "x": -5,
      "y": 17,
      "z": -12,
      "name": "Plant_Leaves_Wisteria_Wild"
    },
    {
      "x": -5,
      "y": 18,
      "z": -12,
      "name": "Plant_Leaves_Wisteria_Wild"
    },
    {
      "x": -5,
      "y": 17,
      "z": -11,
      "name": "Plant_Leaves_Wisteria_Wild"
    },
    {
      "x": -5,
      "y": 18,
      "z": -11,
      "name": "Plant_Leaves_Wisteria_Wild"
    },
    {
      "x": -5,
      "y": 17,
      "z": -10,
      "name": "Plant_Leaves_Wisteria_Wild"
    },
    {
      "x": -5,
      "y": 18,
      "z": -10,
      "name": "Plant_Leaves_Wisteria_Wild"
    },
    {
      "x": -5,
      "y": 18,
      "z": -9,
      "name": "Plant_Leaves_Wisteria_Wild"
    },
    {
      "x": -5,
      "y": 19,
      "z": -9,
      "name": "Plant_Leaves_Wisteria_Wild"
    },
    {
      "x": -5,
      "y": 20,
      "z": -9,
      "name": "Plant_Leaves_Wisteria_Wild"
    },
    {
      "x": -5,
      "y": 18,
      "z": -8,
      "name": "Plant_Leaves_Wisteria_Wild"
    },
    {
      "x": -5,
      "y": 19,
      "z": -8,
      "name": "Plant_Leaves_Wisteria_Wild"
    },
    {
      "x": -5,
      "y": 20,
      "z": -8,
      "name": "Plant_Leaves_Wisteria_Wild"
    },
    {
      "x": -5,
      "y": 17,
      "z": -7,
      "name": "Plant_Leaves_Wisteria_Wild"
    },
    {
      "x": -5,
      "y": 18,
      "z": -7,
      "name": "Plant_Leaves_Wisteria_Wild"
    },
    {
      "x": -5,
      "y": 19,
      "z": -7,
      "name": "Plant_Leaves_Wisteria_Wild"
    },
    {
      "x": -5,
      "y": 17,
      "z": -6,
      "name": "Plant_Leaves_Wisteria_Wild"
    },
    {
      "x": -5,
      "y": 18,
      "z": -6,
      "name": "Plant_Leaves_Wisteria_Wild"
    },
    {
      "x": -5,
      "y": 17,
      "z": -5,
      "name": "Plant_Leaves_Wisteria_Wild"
    },
    {
      "x": -5,
      "y": 18,
      "z": -5,
      "name": "Plant_Leaves_Wisteria_Wild"
    },
    {
      "x": -5,
      "y": 19,
      "z": -5,
      "name": "Plant_Leaves_Wisteria_Wild"
    },
    {
      "x": -5,
      "y": 17,
      "z": -4,
      "name": "Plant_Leaves_Wisteria_Wild"
    },
    {
      "x": -5,
      "y": 18,
      "z": -4,
      "name": "Plant_Leaves_Wisteria_Wild"
    },
    {
      "x": -5,
      "y": 17,
      "z": -3,
      "name": "Plant_Leaves_Wisteria_Wild"
    },
    {
      "x": -5,
      "y": 18,
      "z": -3,
      "name": "Plant_Leaves_Wisteria_Wild"
    },
    {
      "x": -5,
      "y": 18,
      "z": -2,
      "name": "Plant_Leaves_Wisteria_Wild"
    },
    {
      "x": -5,
      "y": 17,
      "z": -1,
      "name": "Wood_Wisteria_Wild_Trunk_Full"
    },
    {
      "x": -5,
      "y": 19,
      "z": 0,
      "name": "Plant_Leaves_Wisteria_Wild"
    },
    {
      "x": -5,
      "y": 18,
      "z": 1,
      "name": "Plant_Leaves_Wisteria_Wild"
    },
    {
      "x": -5,
      "y": 18,
      "z": 2,
      "name": "Plant_Leaves_Wisteria_Wild"
    },
    {
      "x": -5,
      "y": 17,
      "z": 3,
      "name": "Plant_Leaves_Wisteria_Wild"
    },
    {
      "x": -5,
      "y": 18,
      "z": 3,
      "name": "Plant_Leaves_Wisteria_Wild"
    },
    {
      "x": -5,
      "y": 18,
      "z": 4,
      "name": "Plant_Leaves_Wisteria_Wild"
    },
    {
      "x": -5,
      "y": 17,
      "z": 5,
      "name": "Plant_Leaves_Wisteria_Wild"
    },
    {
      "x": -5,
      "y": 14,
      "z": 6,
      "name": "Plant_Leaves_Wisteria_Wild"
    },
    {
      "x": -5,
      "y": 17,
      "z": 6,
      "name": "Plant_Leaves_Wisteria_Wild"
    },
    {
      "x": -5,
      "y": 14,
      "z": 7,
      "name": "Plant_Leaves_Wisteria_Wild"
    },
    {
      "x": -5,
      "y": 17,
      "z": 7,
      "name": "Plant_Leaves_Wisteria_Wild"
    },
    {
      "x": -5,
      "y": 14,
      "z": 10,
      "name": "Plant_Leaves_Wisteria_Wild"
    },
    {
      "x": -5,
      "y": 14,
      "z": 11,
      "name": "Plant_Leaves_Wisteria_Wild"
    },
    {
      "x": -5,
      "y": 14,
      "z": 12,
      "name": "Plant_Leaves_Wisteria_Wild"
    },
    {
      "x": -4,
      "y": 19,
      "z": -14,
      "name": "Plant_Leaves_Wisteria_Wild"
    },
    {
      "x": -4,
      "y": 19,
      "z": -13,
      "name": "Plant_Leaves_Wisteria_Wild"
    },
    {
      "x": -4,
      "y": 19,
      "z": -12,
      "name": "Plant_Leaves_Wisteria_Wild"
    },
    {
      "x": -4,
      "y": 19,
      "z": -11,
      "name": "Plant_Leaves_Wisteria_Wild"
    },
    {
      "x": -4,
      "y": 18,
      "z": -10,
      "name": "Plant_Leaves_Wisteria_Wild"
    },
    {
      "x": -4,
      "y": 19,
      "z": -9,
      "name": "Plant_Leaves_Wisteria_Wild"
    },
    {
      "x": -4,
      "y": 20,
      "z": -9,
      "name": "Plant_Leaves_Wisteria_Wild"
    },
    {
      "x": -4,
      "y": 19,
      "z": -8,
      "name": "Wood_Wisteria_Wild_Trunk_Full"
    },
    {
      "x": -4,
      "y": 20,
      "z": -8,
      "name": "Plant_Leaves_Wisteria_Wild"
    },
    {
      "x": -4,
      "y": 17,
      "z": -7,
      "name": "Plant_Leaves_Wisteria_Wild"
    },
    {
      "x": -4,
      "y": 18,
      "z": -7,
      "name": "Plant_Leaves_Wisteria_Wild"
    },
    {
      "x": -4,
      "y": 20,
      "z": -7,
      "name": "Plant_Leaves_Wisteria_Wild"
    },
    {
      "x": -4,
      "y": 17,
      "z": -5,
      "name": "Plant_Leaves_Wisteria_Wild"
    },
    {
      "x": -4,
      "y": 17,
      "z": -4,
      "name": "Plant_Leaves_Wisteria_Wild"
    },
    {
      "x": -4,
      "y": 17,
      "z": -1,
      "name": "Wood_Wisteria_Wild_Trunk_Full"
    },
    {
      "x": -4,
      "y": 15,
      "z": 0,
      "name": "Wood_Wisteria_Wild_Trunk_Full"
    },
    {
      "x": -4,
      "y": 16,
      "z": 0,
      "name": "Wood_Wisteria_Wild_Trunk_Full"
    },
    {
      "x": -4,
      "y": 15,
      "z": 1,
      "name": "Wood_Wisteria_Wild_Trunk_Full"
    },
    {
      "x": -4,
      "y": 14,
      "z": 2,
      "name": "Wood_Wisteria_Wild_Trunk_Full"
    },
    {
      "x": -4,
      "y": 18,
      "z": 2,
      "name": "Plant_Leaves_Wisteria_Wild"
    },
    {
      "x": -4,
      "y": 17,
      "z": 3,
      "name": "Plant_Leaves_Wisteria_Wild"
    },
    {
      "x": -4,
      "y": 17,
      "z": 4,
      "name": "Plant_Leaves_Wisteria_Wild"
    },
    {
      "x": -4,
      "y": 18,
      "z": 4,
      "name": "Plant_Leaves_Wisteria_Wild"
    },
    {
      "x": -4,
      "y": 14,
      "z": 5,
      "name": "Plant_Leaves_Wisteria_Wild"
    },
    {
      "x": -4,
      "y": 17,
      "z": 5,
      "name": "Plant_Leaves_Wisteria_Wild"
    },
    {
      "x": -4,
      "y": 14,
      "z": 6,
      "name": "Plant_Leaves_Wisteria_Wild"
    },
    {
      "x": -4,
      "y": 15,
      "z": 6,
      "name": "Plant_Leaves_Wisteria_Wild"
    },
    {
      "x": -4,
      "y": 17,
      "z": 6,
      "name": "Plant_Leaves_Wisteria_Wild"
    },
    {
      "x": -4,
      "y": 14,
      "z": 7,
      "name": "Plant_Leaves_Wisteria_Wild"
    },
    {
      "x": -4,
      "y": 15,
      "z": 7,
      "name": "Plant_Leaves_Wisteria_Wild"
    },
    {
      "x": -4,
      "y": 17,
      "z": 7,
      "name": "Plant_Leaves_Wisteria_Wild"
    },
    {
      "x": -4,
      "y": 14,
      "z": 8,
      "name": "Plant_Leaves_Wisteria_Wild"
    },
    {
      "x": -4,
      "y": 14,
      "z": 10,
      "name": "Plant_Leaves_Wisteria_Wild"
    },
    {
      "x": -4,
      "y": 14,
      "z": 11,
      "name": "Plant_Leaves_Wisteria_Wild"
    },
    {
      "x": -4,
      "y": 14,
      "z": 12,
      "name": "Plant_Leaves_Wisteria_Wild"
    },
    {
      "x": -3,
      "y": 18,
      "z": -15,
      "name": "Plant_Leaves_Wisteria_Wild"
    },
    {
      "x": -3,
      "y": 19,
      "z": -14,
      "name": "Plant_Leaves_Wisteria_Wild"
    },
    {
      "x": -3,
      "y": 18,
      "z": -13,
      "name": "Plant_Leaves_Wisteria_Wild"
    },
    {
      "x": -3,
      "y": 19,
      "z": -13,
      "name": "Plant_Leaves_Wisteria_Wild"
    },
    {
      "x": -3,
      "y": 18,
      "z": -12,
      "name": "Plant_Leaves_Wisteria_Wild"
    },
    {
      "x": -3,
      "y": 19,
      "z": -11,
      "name": "Plant_Leaves_Wisteria_Wild"
    },
    {
      "x": -3,
      "y": 19,
      "z": -9,
      "name": "Plant_Leaves_Wisteria_Wild"
    },
    {
      "x": -3,
      "y": 19,
      "z": -8,
      "name": "Wood_Wisteria_Wild_Trunk_Full"
    },
    {
      "x": -3,
      "y": 20,
      "z": -7,
      "name": "Plant_Leaves_Wisteria_Wild"
    },
    {
      "x": -3,
      "y": 20,
      "z": -6,
      "name": "Plant_Leaves_Wisteria_Wild"
    },
    {
      "x": -3,
      "y": 17,
      "z": -5,
      "name": "Plant_Leaves_Wisteria_Wild"
    },
    {
      "x": -3,
      "y": 20,
      "z": -5,
      "name": "Plant_Leaves_Wisteria_Wild"
    },
    {
      "x": -3,
      "y": 16,
      "z": -2,
      "name": "Wood_Wisteria_Wild_Trunk_Full"
    },
    {
      "x": -3,
      "y": 17,
      "z": -2,
      "name": "Wood_Wisteria_Wild_Trunk_Full"
    },
    {
      "x": -3,
      "y": 16,
      "z": -1,
      "name": "Wood_Wisteria_Wild_Trunk_Full"
    },
    {
      "x": -3,
      "y": 17,
      "z": -1,
      "name": "Wood_Wisteria_Wild_Trunk_Full"
    },
    {
      "x": -3,
      "y": 0,
      "z": 0,
      "name": "Wood_Wisteria_Wild_Trunk"
    },
    {
      "x": -3,
      "y": 1,
      "z": 0,
      "name": "Wood_Wisteria_Wild_Trunk"
    },
    {
      "x": -3,
      "y": 2,
      "z": 0,
      "name": "Wood_Wisteria_Wild_Trunk"
    },
    {
      "x": -3,
      "y": 3,
      "z": 0,
      "name": "Wood_Wisteria_Wild_Trunk_Full"
    },
    {
      "x": -3,
      "y": 15,
      "z": 0,
      "name": "Wood_Wisteria_Wild_Trunk_Full"
    },
    {
      "x": -3,
      "y": 16,
      "z": 0,
      "name": "Wood_Wisteria_Wild_Trunk_Full"
    },
    {
      "x": -3,
      "y": 15,
      "z": 1,
      "name": "Wood_Wisteria_Wild_Trunk_Full"
    },
    {
      "x": -3,
      "y": 16,
      "z": 1,
      "name": "Wood_Wisteria_Wild_Trunk_Full"
    },
    {
      "x": -3,
      "y": 15,
      "z": 2,
      "name": "Wood_Wisteria_Wild_Trunk_Full"
    },
    {
      "x": -3,
      "y": 14,
      "z": 4,
      "name": "Plant_Leaves_Wisteria_Wild"
    },
    {
      "x": -3,
      "y": 17,
      "z": 4,
      "name": "Plant_Leaves_Wisteria_Wild"
    },
    {
      "x": -3,
      "y": 14,
      "z": 5,
      "name": "Plant_Leaves_Wisteria_Wild"
    },
    {
      "x": -3,
      "y": 17,
      "z": 5,
      "name": "Plant_Leaves_Wisteria_Wild"
    },
    {
      "x": -3,
      "y": 14,
      "z": 6,
      "name": "Plant_Leaves_Wisteria_Wild"
    },
    {
      "x": -3,
      "y": 15,
      "z": 6,
      "name": "Plant_Leaves_Wisteria_Wild"
    },
    {
      "x": -3,
      "y": 14,
      "z": 7,
      "name": "Plant_Leaves_Wisteria_Wild"
    },
    {
      "x": -3,
      "y": 15,
      "z": 7,
      "name": "Plant_Leaves_Wisteria_Wild"
    },
    {
      "x": -3,
      "y": 15,
      "z": 8,
      "name": "Plant_Leaves_Wisteria_Wild"
    },
    {
      "x": -3,
      "y": 14,
      "z": 9,
      "name": "Plant_Leaves_Wisteria_Wild"
    },
    {
      "x": -3,
      "y": 15,
      "z": 9,
      "name": "Plant_Leaves_Wisteria_Wild"
    },
    {
      "x": -3,
      "y": 14,
      "z": 10,
      "name": "Plant_Leaves_Wisteria_Wild"
    },
    {
      "x": -3,
      "y": 15,
      "z": 10,
      "name": "Plant_Leaves_Wisteria_Wild"
    },
    {
      "x": -3,
      "y": 14,
      "z": 11,
      "name": "Plant_Leaves_Wisteria_Wild"
    },
    {
      "x": -3,
      "y": 15,
      "z": 11,
      "name": "Plant_Leaves_Wisteria_Wild"
    },
    {
      "x": -3,
      "y": 14,
      "z": 12,
      "name": "Plant_Leaves_Wisteria_Wild"
    },
    {
      "x": -2,
      "y": 18,
      "z": -15,
      "name": "Plant_Leaves_Wisteria_Wild"
    },
    {
      "x": -2,
      "y": 18,
      "z": -14,
      "name": "Plant_Leaves_Wisteria_Wild"
    },
    {
      "x": -2,
      "y": 18,
      "z": -13,
      "name": "Plant_Leaves_Wisteria_Wild"
    },
    {
      "x": -2,
      "y": 19,
      "z": -13,
      "name": "Plant_Leaves_Wisteria_Wild"
    },
    {
      "x": -2,
      "y": 19,
      "z": -11,
      "name": "Wood_Wisteria_Wild_Trunk_Full"
    },
    {
      "x": -2,
      "y": 20,
      "z": -11,
      "name": "Plant_Leaves_Wisteria_Wild"
    },
    {
      "x": -2,
      "y": 19,
      "z": -10,
      "name": "Wood_Wisteria_Wild_Trunk_Full"
    },
    {
      "x": -2,
      "y": 20,
      "z": -10,
      "name": "Plant_Leaves_Wisteria_Wild"
    },
    {
      "x": -2,
      "y": 19,
      "z": -9,
      "name": "Wood_Wisteria_Wild_Trunk_Full"
    },
    {
      "x": -2,
      "y": 20,
      "z": -9,
      "name": "Plant_Leaves_Wisteria_Wild"
    },
    {
      "x": -2,
      "y": 18,
      "z": -8,
      "name": "Wood_Wisteria_Wild_Trunk_Full"
    },
    {
      "x": -2,
      "y": 19,
      "z": -8,
      "name": "Wood_Wisteria_Wild_Trunk_Full"
    },
    {
      "x": -2,
      "y": 20,
      "z": -8,
      "name": "Plant_Leaves_Wisteria_Wild"
    },
    {
      "x": -2,
      "y": 18,
      "z": -7,
      "name": "Wood_Wisteria_Wild_Trunk_Full"
    },
    {
      "x": -2,
      "y": 18,
      "z": -6,
      "name": "Wood_Wisteria_Wild_Trunk_Full"
    },
    {
      "x": -2,
      "y": 20,
      "z": -6,
      "name": "Plant_Leaves_Wisteria_Wild"
    },
    {
      "x": -2,
      "y": 18,
      "z": -5,
      "name": "Wood_Wisteria_Wild_Trunk_Full"
    },
    {
      "x": -2,
      "y": 19,
      "z": -5,
      "name": "Wood_Wisteria_Wild_Trunk_Full"
    },
    {
      "x": -2,
      "y": 20,
      "z": -5,
      "name": "Plant_Leaves_Wisteria_Wild"
    },
    {
      "x": -2,
      "y": 18,
      "z": -4,
      "name": "Wood_Wisteria_Wild_Trunk_Full"
    },
    {
      "x": -2,
      "y": 19,
      "z": -4,
      "name": "Plant_Leaves_Wisteria_Wild"
    },
    {
      "x": -2,
      "y": 17,
      "z": -3,
      "name": "Wood_Wisteria_Wild_Trunk_Full"
    },
    {
      "x": -2,
      "y": 18,
      "z": -3,
      "name": "Wood_Wisteria_Wild_Trunk_Full"
    },
    {
      "x": -2,
      "y": 16,
      "z": -2,
      "name": "Wood_Wisteria_Wild_Trunk_Full"
    },
    {
      "x": -2,
      "y": 17,
      "z": -2,
      "name": "Wood_Wisteria_Wild_Trunk_Full"
    },
    {
      "x": -2,
      "y": 16,
      "z": -1,
      "name": "Wood_Wisteria_Wild_Trunk_Full"
    },
    {
      "x": -2,
      "y": 17,
      "z": -1,
      "name": "Wood_Wisteria_Wild_Trunk_Full"
    },
    {
      "x": -2,
      "y": 3,
      "z": 0,
      "name": "Wood_Wisteria_Wild_Trunk_Full"
    },
    {
      "x": -2,
      "y": 4,
      "z": 0,
      "name": "Wood_Wisteria_Wild_Trunk"
    },
    {
      "x": -2,
      "y": 5,
      "z": 0,
      "name": "Wood_Wisteria_Wild_Trunk_Full"
    },
    {
      "x": -2,
      "y": 18,
      "z": 0,
      "name": "Plant_Leaves_Wisteria_Wild"
    },
    {
      "x": -2,
      "y": 19,
      "z": 0,
      "name": "Plant_Leaves_Wisteria_Wild"
    },
    {
      "x": -2,
      "y": 4,
      "z": 1,
      "name": "Wood_Wisteria_Wild_Trunk_Full"
    },
    {
      "x": -2,
      "y": 15,
      "z": 2,
      "name": "Wood_Wisteria_Wild_Trunk_Full"
    },
    {
      "x": -2,
      "y": 13,
      "z": 3,
      "name": "Wood_Wisteria_Wild_Trunk_Full"
    },
    {
      "x": -2,
      "y": 15,
      "z": 3,
      "name": "Wood_Wisteria_Wild_Trunk_Full"
    },
    {
      "x": -2,
      "y": 14,
      "z": 4,
      "name": "Plant_Leaves_Wisteria_Wild"
    },
    {
      "x": -2,
      "y": 14,
      "z": 5,
      "name": "Plant_Leaves_Wisteria_Wild"
    },
    {
      "x": -2,
      "y": 15,
      "z": 5,
      "name": "Plant_Leaves_Wisteria_Wild"
    },
    {
      "x": -2,
      "y": 14,
      "z": 6,
      "name": "Plant_Leaves_Wisteria_Wild"
    },
    {
      "x": -2,
      "y": 15,
      "z": 6,
      "name": "Plant_Leaves_Wisteria_Wild"
    },
    {
      "x": -2,
      "y": 16,
      "z": 6,
      "name": "Plant_Leaves_Wisteria_Wild"
    },
    {
      "x": -2,
      "y": 15,
      "z": 7,
      "name": "Wood_Wisteria_Wild_Trunk_Full"
    },
    {
      "x": -2,
      "y": 16,
      "z": 7,
      "name": "Plant_Leaves_Wisteria_Wild"
    },
    {
      "x": -2,
      "y": 15,
      "z": 8,
      "name": "Wood_Wisteria_Wild_Trunk_Full"
    },
    {
      "x": -2,
      "y": 16,
      "z": 8,
      "name": "Plant_Leaves_Wisteria_Wild"
    },
    {
      "x": -2,
      "y": 15,
      "z": 9,
      "name": "Wood_Wisteria_Wild_Trunk_Full"
    },
    {
      "x": -2,
      "y": 16,
      "z": 9,
      "name": "Plant_Leaves_Wisteria_Wild"
    },
    {
      "x": -2,
      "y": 14,
      "z": 10,
      "name": "Plant_Leaves_Wisteria_Wild"
    },
    {
      "x": -2,
      "y": 15,
      "z": 10,
      "name": "Plant_Leaves_Wisteria_Wild"
    },
    {
      "x": -2,
      "y": 16,
      "z": 10,
      "name": "Plant_Leaves_Wisteria_Wild"
    },
    {
      "x": -2,
      "y": 14,
      "z": 11,
      "name": "Plant_Leaves_Wisteria_Wild"
    },
    {
      "x": -2,
      "y": 15,
      "z": 11,
      "name": "Plant_Leaves_Wisteria_Wild"
    },
    {
      "x": -2,
      "y": 14,
      "z": 12,
      "name": "Plant_Leaves_Wisteria_Wild"
    },
    {
      "x": -2,
      "y": 15,
      "z": 12,
      "name": "Plant_Leaves_Wisteria_Wild"
    },
    {
      "x": -2,
      "y": 13,
      "z": 13,
      "name": "Plant_Leaves_Wisteria_Wild"
    },
    {
      "x": -2,
      "y": 14,
      "z": 13,
      "name": "Plant_Leaves_Wisteria_Wild"
    },
    {
      "x": -2,
      "y": 13,
      "z": 14,
      "name": "Plant_Leaves_Wisteria_Wild"
    },
    {
      "x": -2,
      "y": 14,
      "z": 14,
      "name": "Plant_Leaves_Wisteria_Wild"
    },
    {
      "x": -2,
      "y": 13,
      "z": 15,
      "name": "Plant_Leaves_Wisteria_Wild"
    },
    {
      "x": -2,
      "y": 14,
      "z": 15,
      "name": "Plant_Leaves_Wisteria_Wild"
    },
    {
      "x": -1,
      "y": 18,
      "z": -15,
      "name": "Plant_Leaves_Wisteria_Wild"
    },
    {
      "x": -1,
      "y": 18,
      "z": -14,
      "name": "Plant_Leaves_Wisteria_Wild"
    },
    {
      "x": -1,
      "y": 18,
      "z": -12,
      "name": "Plant_Leaves_Wisteria_Wild"
    },
    {
      "x": -1,
      "y": 19,
      "z": -12,
      "name": "Plant_Leaves_Wisteria_Wild"
    },
    {
      "x": -1,
      "y": 18,
      "z": -11,
      "name": "Plant_Leaves_Wisteria_Wild"
    },
    {
      "x": -1,
      "y": 19,
      "z": -10,
      "name": "Plant_Leaves_Wisteria_Wild"
    },
    {
      "x": -1,
      "y": 20,
      "z": -7,
      "name": "Plant_Leaves_Wisteria_Wild"
    },
    {
      "x": -1,
      "y": 20,
      "z": -6,
      "name": "Plant_Leaves_Wisteria_Wild"
    },
    {
      "x": -1,
      "y": 19,
      "z": -5,
      "name": "Wood_Wisteria_Wild_Trunk_Full"
    },
    {
      "x": -1,
      "y": 20,
      "z": -5,
      "name": "Plant_Leaves_Wisteria_Wild"
    },
    {
      "x": -1,
      "y": 0,
      "z": -2,
      "name": "Wood_Wisteria_Wild_Roots"
    },
    {
      "x": -1,
      "y": 1,
      "z": -2,
      "name": "Wood_Wisteria_Wild_Trunk_Full"
    },
    {
      "x": -1,
      "y": 2,
      "z": -2,
      "name": "Wood_Wisteria_Wild_Trunk"
    },
    {
      "x": -1,
      "y": 3,
      "z": -2,
      "name": "Wood_Wisteria_Wild_Trunk"
    },
    {
      "x": -1,
      "y": 4,
      "z": -2,
      "name": "Wood_Wisteria_Wild_Trunk_Full"
    },
    {
      "x": -1,
      "y": 3,
      "z": -1,
      "name": "Wood_Wisteria_Wild_Trunk_Full"
    },
    {
      "x": -1,
      "y": 4,
      "z": -1,
      "name": "Wood_Wisteria_Wild_Trunk"
    },
    {
      "x": -1,
      "y": 5,
      "z": -1,
      "name": "Wood_Wisteria_Wild_Trunk_Full"
    },
    {
      "x": -1,
      "y": 17,
      "z": -1,
      "name": "Wood_Wisteria_Wild_Trunk_Full"
    },
    {
      "x": -1,
      "y": 18,
      "z": -1,
      "name": "Plant_Leaves_Wisteria_Wild"
    },
    {
      "x": -1,
      "y": 4,
      "z": 0,
      "name": "Wood_Wisteria_Wild_Trunk_Full"
    },
    {
      "x": -1,
      "y": 5,
      "z": 0,
      "name": "Wood_Wisteria_Wild_Trunk"
    },
    {
      "x": -1,
      "y": 6,
      "z": 0,
      "name": "Wood_Wisteria_Wild_Trunk_Full"
    },
    {
      "x": -1,
      "y": 17,
      "z": 0,
      "name": "Wood_Wisteria_Wild_Trunk_Full"
    },
    {
      "x": -1,
      "y": 18,
      "z": 0,
      "name": "Plant_Leaves_Wisteria_Wild"
    },
    {
      "x": -1,
      "y": 4,
      "z": 1,
      "name": "Wood_Wisteria_Wild_Trunk_Full"
    },
    {
      "x": -1,
      "y": 5,
      "z": 1,
      "name": "Wood_Wisteria_Wild_Trunk_Full"
    },
    {
      "x": -1,
      "y": 18,
      "z": 1,
      "name": "Plant_Leaves_Wisteria_Wild"
    },
    {
      "x": -1,
      "y": 14,
      "z": 2,
      "name": "Wood_Wisteria_Wild_Trunk_Full"
    },
    {
      "x": -1,
      "y": 15,
      "z": 2,
      "name": "Wood_Wisteria_Wild_Trunk_Full"
    },
    {
      "x": -1,
      "y": 17,
      "z": 2,
      "name": "Plant_Leaves_Wisteria_Wild"
    },
    {
      "x": -1,
      "y": 13,
      "z": 3,
      "name": "Wood_Wisteria_Wild_Trunk_Full"
    },
    {
      "x": -1,
      "y": 17,
      "z": 3,
      "name": "Plant_Leaves_Wisteria_Wild"
    },
    {
      "x": -1,
      "y": 15,
      "z": 6,
      "name": "Plant_Leaves_Wisteria_Wild"
    },
    {
      "x": -1,
      "y": 15,
      "z": 7,
      "name": "Wood_Wisteria_Wild_Trunk_Full"
    },
    {
      "x": -1,
      "y": 16,
      "z": 7,
      "name": "Plant_Leaves_Wisteria_Wild"
    },
    {
      "x": -1,
      "y": 16,
      "z": 8,
      "name": "Plant_Leaves_Wisteria_Wild"
    },
    {
      "x": -1,
      "y": 16,
      "z": 9,
      "name": "Plant_Leaves_Wisteria_Wild"
    },
    {
      "x": -1,
      "y": 16,
      "z": 10,
      "name": "Plant_Leaves_Wisteria_Wild"
    },
    {
      "x": -1,
      "y": 14,
      "z": 11,
      "name": "Plant_Leaves_Wisteria_Wild"
    },
    {
      "x": -1,
      "y": 15,
      "z": 11,
      "name": "Plant_Leaves_Wisteria_Wild"
    },
    {
      "x": -1,
      "y": 16,
      "z": 11,
      "name": "Plant_Leaves_Wisteria_Wild"
    },
    {
      "x": -1,
      "y": 13,
      "z": 12,
      "name": "Plant_Leaves_Wisteria_Wild"
    },
    {
      "x": -1,
      "y": 14,
      "z": 12,
      "name": "Plant_Leaves_Wisteria_Wild"
    },
    {
      "x": -1,
      "y": 15,
      "z": 12,
      "name": "Plant_Leaves_Wisteria_Wild"
    },
    {
      "x": -1,
      "y": 13,
      "z": 13,
      "name": "Plant_Leaves_Wisteria_Wild"
    },
    {
      "x": -1,
      "y": 14,
      "z": 13,
      "name": "Plant_Leaves_Wisteria_Wild"
    },
    {
      "x": -1,
      "y": 15,
      "z": 13,
      "name": "Plant_Leaves_Wisteria_Wild"
    },
    {
      "x": -1,
      "y": 13,
      "z": 14,
      "name": "Plant_Leaves_Wisteria_Wild"
    },
    {
      "x": -1,
      "y": 14,
      "z": 14,
      "name": "Plant_Leaves_Wisteria_Wild"
    },
    {
      "x": -1,
      "y": 13,
      "z": 15,
      "name": "Plant_Leaves_Wisteria_Wild"
    },
    {
      "x": -1,
      "y": 14,
      "z": 15,
      "name": "Plant_Leaves_Wisteria_Wild"
    },
    {
      "x": -1,
      "y": 13,
      "z": 16,
      "name": "Plant_Leaves_Wisteria_Wild"
    },
    {
      "x": 0,
      "y": 17,
      "z": -15,
      "name": "Plant_Leaves_Wisteria_Wild"
    },
    {
      "x": 0,
      "y": 18,
      "z": -15,
      "name": "Plant_Leaves_Wisteria_Wild"
    },
    {
      "x": 0,
      "y": 17,
      "z": -14,
      "name": "Plant_Leaves_Wisteria_Wild"
    },
    {
      "x": 0,
      "y": 18,
      "z": -14,
      "name": "Plant_Leaves_Wisteria_Wild"
    },
    {
      "x": 0,
      "y": 18,
      "z": -13,
      "name": "Plant_Leaves_Wisteria_Wild"
    },
    {
      "x": 0,
      "y": 19,
      "z": -13,
      "name": "Plant_Leaves_Wisteria_Wild"
    },
    {
      "x": 0,
      "y": 18,
      "z": -12,
      "name": "Plant_Leaves_Wisteria_Wild"
    },
    {
      "x": 0,
      "y": 18,
      "z": -11,
      "name": "Plant_Leaves_Wisteria_Wild"
    },
    {
      "x": 0,
      "y": 19,
      "z": -11,
      "name": "Plant_Leaves_Wisteria_Wild"
    },
    {
      "x": 0,
      "y": 19,
      "z": -10,
      "name": "Plant_Leaves_Wisteria_Wild"
    },
    {
      "x": 0,
      "y": 19,
      "z": -9,
      "name": "Plant_Leaves_Wisteria_Wild"
    },
    {
      "x": 0,
      "y": 20,
      "z": -9,
      "name": "Plant_Leaves_Wisteria_Wild"
    },
    {
      "x": 0,
      "y": 19,
      "z": -8,
      "name": "Plant_Leaves_Wisteria_Wild"
    },
    {
      "x": 0,
      "y": 20,
      "z": -8,
      "name": "Plant_Leaves_Wisteria_Wild"
    },
    {
      "x": 0,
      "y": 19,
      "z": -7,
      "name": "Wood_Wisteria_Wild_Trunk_Full"
    },
    {
      "x": 0,
      "y": 20,
      "z": -7,
      "name": "Plant_Leaves_Wisteria_Wild"
    },
    {
      "x": 0,
      "y": 19,
      "z": -6,
      "name": "Wood_Wisteria_Wild_Trunk_Full"
    },
    {
      "x": 0,
      "y": 20,
      "z": -6,
      "name": "Plant_Leaves_Wisteria_Wild"
    },
    {
      "x": 0,
      "y": 19,
      "z": -5,
      "name": "Wood_Wisteria_Wild_Trunk_Full"
    },
    {
      "x": 0,
      "y": 20,
      "z": -5,
      "name": "Plant_Leaves_Wisteria_Wild"
    },
    {
      "x": 0,
      "y": 18,
      "z": -4,
      "name": "Plant_Leaves_Wisteria_Wild"
    },
    {
      "x": 0,
      "y": 4,
      "z": -2,
      "name": "Wood_Wisteria_Wild_Trunk_Full"
    },
    {
      "x": 0,
      "y": 18,
      "z": -2,
      "name": "Plant_Leaves_Wisteria_Wild"
    },
    {
      "x": 0,
      "y": 3,
      "z": -1,
      "name": "Wood_Wisteria_Wild_Trunk_Full"
    },
    {
      "x": 0,
      "y": 4,
      "z": -1,
      "name": "Wood_Wisteria_Wild_Trunk_Full"
    },
    {
      "x": 0,
      "y": 5,
      "z": -1,
      "name": "Wood_Wisteria_Wild_Trunk"
    },
    {
      "x": 0,
      "y": 6,
      "z": -1,
      "name": "Wood_Wisteria_Wild_Trunk"
    },
    {
      "x": 0,
      "y": 7,
      "z": -1,
      "name": "Wood_Wisteria_Wild_Trunk_Full"
    },
    {
      "x": 0,
      "y": 18,
      "z": -1,
      "name": "Plant_Leaves_Wisteria_Wild"
    },
    {
      "x": 0,
      "y": 4,
      "z": 0,
      "name": "Wood_Wisteria_Wild_Trunk_Full"
    },
    {
      "x": 0,
      "y": 5,
      "z": 0,
      "name": "Wood_Wisteria_Wild_Trunk"
    },
    {
      "x": 0,
      "y": 6,
      "z": 0,
      "name": "Wood_Wisteria_Wild_Trunk_Full"
    },
    {
      "x": 0,
      "y": 17,
      "z": 0,
      "name": "Wood_Wisteria_Wild_Trunk_Full"
    },
    {
      "x": 0,
      "y": 18,
      "z": 0,
      "name": "Plant_Leaves_Wisteria_Wild"
    },
    {
      "x": 0,
      "y": 12,
      "z": 1,
      "name": "Wood_Wisteria_Wild_Trunk_Full"
    },
    {
      "x": 0,
      "y": 13,
      "z": 1,
      "name": "Wood_Wisteria_Wild_Trunk_Full"
    },
    {
      "x": 0,
      "y": 18,
      "z": 1,
      "name": "Plant_Leaves_Wisteria_Wild"
    },
    {
      "x": 0,
      "y": 13,
      "z": 2,
      "name": "Wood_Wisteria_Wild_Trunk_Full"
    },
    {
      "x": 0,
      "y": 14,
      "z": 2,
      "name": "Wood_Wisteria_Wild_Trunk_Full"
    },
    {
      "x": 0,
      "y": 17,
      "z": 2,
      "name": "Plant_Leaves_Wisteria_Wild"
    },
    {
      "x": 0,
      "y": 18,
      "z": 2,
      "name": "Plant_Leaves_Wisteria_Wild"
    },
    {
      "x": 0,
      "y": 13,
      "z": 3,
      "name": "Wood_Wisteria_Wild_Trunk_Full"
    },
    {
      "x": 0,
      "y": 14,
      "z": 3,
      "name": "Wood_Wisteria_Wild_Trunk_Full"
    },
    {
      "x": 0,
      "y": 18,
      "z": 3,
      "name": "Plant_Leaves_Wisteria_Wild"
    },
    {
      "x": 0,
      "y": 14,
      "z": 4,
      "name": "Wood_Wisteria_Wild_Trunk_Full"
    },
    {
      "x": 0,
      "y": 17,
      "z": 4,
      "name": "Plant_Leaves_Wisteria_Wild"
    },
    {
      "x": 0,
      "y": 18,
      "z": 4,
      "name": "Plant_Leaves_Wisteria_Wild"
    },
    {
      "x": 0,
      "y": 14,
      "z": 5,
      "name": "Wood_Wisteria_Wild_Trunk_Full"
    },
    {
      "x": 0,
      "y": 17,
      "z": 5,
      "name": "Plant_Leaves_Wisteria_Wild"
    },
    {
      "x": 0,
      "y": 14,
      "z": 6,
      "name": "Wood_Wisteria_Wild_Trunk_Full"
    },
    {
      "x": 0,
      "y": 15,
      "z": 6,
      "name": "Plant_Leaves_Wisteria_Wild"
    },
    {
      "x": 0,
      "y": 14,
      "z": 7,
      "name": "Wood_Wisteria_Wild_Trunk_Full"
    },
    {
      "x": 0,
      "y": 15,
      "z": 7,
      "name": "Wood_Wisteria_Wild_Trunk_Full"
    },
    {
      "x": 0,
      "y": 16,
      "z": 8,
      "name": "Plant_Leaves_Wisteria_Wild"
    },
    {
      "x": 0,
      "y": 16,
      "z": 9,
      "name": "Plant_Leaves_Wisteria_Wild"
    },
    {
      "x": 0,
      "y": 13,
      "z": 10,
      "name": "Plant_Leaves_Wisteria_Wild"
    },
    {
      "x": 0,
      "y": 14,
      "z": 10,
      "name": "Plant_Leaves_Wisteria_Wild"
    },
    {
      "x": 0,
      "y": 15,
      "z": 10,
      "name": "Plant_Leaves_Wisteria_Wild"
    },
    {
      "x": 0,
      "y": 16,
      "z": 10,
      "name": "Plant_Leaves_Wisteria_Wild"
    },
    {
      "x": 0,
      "y": 14,
      "z": 11,
      "name": "Plant_Leaves_Wisteria_Wild"
    },
    {
      "x": 0,
      "y": 15,
      "z": 11,
      "name": "Plant_Leaves_Wisteria_Wild"
    },
    {
      "x": 0,
      "y": 16,
      "z": 11,
      "name": "Plant_Leaves_Wisteria_Wild"
    },
    {
      "x": 0,
      "y": 15,
      "z": 12,
      "name": "Plant_Leaves_Wisteria_Wild"
    },
    {
      "x": 0,
      "y": 15,
      "z": 13,
      "name": "Plant_Leaves_Wisteria_Wild"
    },
    {
      "x": 0,
      "y": 14,
      "z": 14,
      "name": "Plant_Leaves_Wisteria_Wild"
    },
    {
      "x": 0,
      "y": 15,
      "z": 14,
      "name": "Plant_Leaves_Wisteria_Wild"
    },
    {
      "x": 0,
      "y": 13,
      "z": 15,
      "name": "Plant_Leaves_Wisteria_Wild"
    },
    {
      "x": 0,
      "y": 14,
      "z": 15,
      "name": "Plant_Leaves_Wisteria_Wild"
    },
    {
      "x": 0,
      "y": 13,
      "z": 16,
      "name": "Plant_Leaves_Wisteria_Wild"
    },
    {
      "x": 0,
      "y": 14,
      "z": 16,
      "name": "Plant_Leaves_Wisteria_Wild"
    },
    {
      "x": 1,
      "y": 17,
      "z": -15,
      "name": "Plant_Leaves_Wisteria_Wild"
    },
    {
      "x": 1,
      "y": 17,
      "z": -14,
      "name": "Plant_Leaves_Wisteria_Wild"
    },
    {
      "x": 1,
      "y": 18,
      "z": -14,
      "name": "Plant_Leaves_Wisteria_Wild"
    },
    {
      "x": 1,
      "y": 18,
      "z": -12,
      "name": "Plant_Leaves_Wisteria_Wild"
    },
    {
      "x": 1,
      "y": 18,
      "z": -11,
      "name": "Plant_Leaves_Wisteria_Wild"
    },
    {
      "x": 1,
      "y": 17,
      "z": -10,
      "name": "Plant_Leaves_Wisteria_Wild"
    },
    {
      "x": 1,
      "y": 18,
      "z": -10,
      "name": "Plant_Leaves_Wisteria_Wild"
    },
    {
      "x": 1,
      "y": 18,
      "z": -9,
      "name": "Plant_Leaves_Wisteria_Wild"
    },
    {
      "x": 1,
      "y": 18,
      "z": -8,
      "name": "Plant_Leaves_Wisteria_Wild"
    },
    {
      "x": 1,
      "y": 19,
      "z": -8,
      "name": "Plant_Leaves_Wisteria_Wild"
    },
    {
      "x": 1,
      "y": 18,
      "z": -7,
      "name": "Plant_Leaves_Wisteria_Wild"
    },
    {
      "x": 1,
      "y": 19,
      "z": -7,
      "name": "Plant_Leaves_Wisteria_Wild"
    },
    {
      "x": 1,
      "y": 20,
      "z": -7,
      "name": "Plant_Leaves_Wisteria_Wild"
    },
    {
      "x": 1,
      "y": 18,
      "z": -6,
      "name": "Plant_Leaves_Wisteria_Wild"
    },
    {
      "x": 1,
      "y": 19,
      "z": -6,
      "name": "Plant_Leaves_Wisteria_Wild"
    },
    {
      "x": 1,
      "y": 18,
      "z": -5,
      "name": "Plant_Leaves_Wisteria_Wild"
    },
    {
      "x": 1,
      "y": 19,
      "z": -5,
      "name": "Plant_Leaves_Wisteria_Wild"
    },
    {
      "x": 1,
      "y": 18,
      "z": -4,
      "name": "Plant_Leaves_Wisteria_Wild"
    },
    {
      "x": 1,
      "y": 0,
      "z": -3,
      "name": "Wood_Wisteria_Wild_Trunk_Full"
    },
    {
      "x": 1,
      "y": 1,
      "z": -3,
      "name": "Wood_Wisteria_Wild_Trunk"
    },
    {
      "x": 1,
      "y": 2,
      "z": -3,
      "name": "Wood_Wisteria_Wild_Trunk"
    },
    {
      "x": 1,
      "y": 3,
      "z": -3,
      "name": "Wood_Wisteria_Wild_Trunk"
    },
    {
      "x": 1,
      "y": 4,
      "z": -3,
      "name": "Wood_Wisteria_Wild_Trunk_Full"
    },
    {
      "x": 1,
      "y": 17,
      "z": -3,
      "name": "Plant_Leaves_Wisteria_Wild"
    },
    {
      "x": 1,
      "y": 18,
      "z": -3,
      "name": "Plant_Leaves_Wisteria_Wild"
    },
    {
      "x": 1,
      "y": 3,
      "z": -2,
      "name": "Wood_Wisteria_Wild_Trunk_Full"
    },
    {
      "x": 1,
      "y": 4,
      "z": -2,
      "name": "Wood_Wisteria_Wild_Trunk"
    },
    {
      "x": 1,
      "y": 5,
      "z": -2,
      "name": "Wood_Wisteria_Wild_Trunk"
    },
    {
      "x": 1,
      "y": 6,
      "z": -2,
      "name": "Wood_Wisteria_Wild_Trunk"
    },
    {
      "x": 1,
      "y": 7,
      "z": -2,
      "name": "Wood_Wisteria_Wild_Trunk"
    },
    {
      "x": 1,
      "y": 8,
      "z": -2,
      "name": "Wood_Wisteria_Wild_Trunk"
    },
    {
      "x": 1,
      "y": 9,
      "z": -2,
      "name": "Wood_Wisteria_Wild_Trunk_Full"
    },
    {
      "x": 1,
      "y": 18,
      "z": -2,
      "name": "Plant_Leaves_Wisteria_Wild"
    },
    {
      "x": 1,
      "y": 4,
      "z": -1,
      "name": "Wood_Wisteria_Wild_Trunk_Full"
    },
    {
      "x": 1,
      "y": 5,
      "z": -1,
      "name": "Wood_Wisteria_Wild_Trunk"
    },
    {
      "x": 1,
      "y": 6,
      "z": -1,
      "name": "Wood_Wisteria_Wild_Trunk"
    },
    {
      "x": 1,
      "y": 7,
      "z": -1,
      "name": "Wood_Wisteria_Wild_Trunk"
    },
    {
      "x": 1,
      "y": 8,
      "z": -1,
      "name": "Wood_Wisteria_Wild_Trunk_Full"
    },
    {
      "x": 1,
      "y": 18,
      "z": -1,
      "name": "Plant_Leaves_Wisteria_Wild"
    },
    {
      "x": 1,
      "y": 5,
      "z": 0,
      "name": "Wood_Wisteria_Wild_Trunk_Full"
    },
    {
      "x": 1,
      "y": 12,
      "z": 0,
      "name": "Wood_Wisteria_Wild_Trunk_Full"
    },
    {
      "x": 1,
      "y": 13,
      "z": 0,
      "name": "Wood_Wisteria_Wild_Trunk_Full"
    },
    {
      "x": 1,
      "y": 17,
      "z": 0,
      "name": "Wood_Wisteria_Wild_Trunk_Full"
    },
    {
      "x": 1,
      "y": 5,
      "z": 1,
      "name": "Wood_Wisteria_Wild_Trunk_Full"
    },
    {
      "x": 1,
      "y": 12,
      "z": 1,
      "name": "Wood_Wisteria_Wild_Trunk_Full"
    },
    {
      "x": 1,
      "y": 13,
      "z": 1,
      "name": "Wood_Wisteria_Wild_Trunk_Full"
    },
    {
      "x": 1,
      "y": 17,
      "z": 1,
      "name": "Wood_Wisteria_Wild_Trunk_Full"
    },
    {
      "x": 1,
      "y": 18,
      "z": 1,
      "name": "Plant_Leaves_Wisteria_Wild"
    },
    {
      "x": 1,
      "y": 19,
      "z": 1,
      "name": "Plant_Leaves_Wisteria_Wild"
    },
    {
      "x": 1,
      "y": 2,
      "z": 2,
      "name": "Wood_Wisteria_Wild_Roots"
    },
    {
      "x": 1,
      "y": 3,
      "z": 2,
      "name": "Wood_Wisteria_Wild_Trunk_Full"
    },
    {
      "x": 1,
      "y": 4,
      "z": 2,
      "name": "Wood_Wisteria_Wild_Trunk"
    },
    {
      "x": 1,
      "y": 5,
      "z": 2,
      "name": "Wood_Wisteria_Wild_Trunk_Full"
    },
    {
      "x": 1,
      "y": 13,
      "z": 2,
      "name": "Wood_Wisteria_Wild_Trunk_Full"
    },
    {
      "x": 1,
      "y": 14,
      "z": 2,
      "name": "Wood_Wisteria_Wild_Trunk_Full"
    },
    {
      "x": 1,
      "y": 18,
      "z": 2,
      "name": "Plant_Leaves_Wisteria_Wild"
    },
    {
      "x": 1,
      "y": 17,
      "z": 3,
      "name": "Plant_Leaves_Wisteria_Wild"
    },
    {
      "x": 1,
      "y": 18,
      "z": 3,
      "name": "Plant_Leaves_Wisteria_Wild"
    },
    {
      "x": 1,
      "y": 17,
      "z": 4,
      "name": "Plant_Leaves_Wisteria_Wild"
    },
    {
      "x": 1,
      "y": 17,
      "z": 5,
      "name": "Plant_Leaves_Wisteria_Wild"
    },
    {
      "x": 1,
      "y": 14,
      "z": 7,
      "name": "Wood_Wisteria_Wild_Trunk_Full"
    },
    {
      "x": 1,
      "y": 15,
      "z": 7,
      "name": "Wood_Wisteria_Wild_Trunk_Full"
    },
    {
      "x": 1,
      "y": 16,
      "z": 7,
      "name": "Plant_Leaves_Wisteria_Wild"
    },
    {
      "x": 1,
      "y": 15,
      "z": 8,
      "name": "Wood_Wisteria_Wild_Trunk_Full"
    },
    {
      "x": 1,
      "y": 16,
      "z": 8,
      "name": "Plant_Leaves_Wisteria_Wild"
    },
    {
      "x": 1,
      "y": 15,
      "z": 9,
      "name": "Wood_Wisteria_Wild_Trunk_Full"
    },
    {
      "x": 1,
      "y": 15,
      "z": 10,
      "name": "Wood_Wisteria_Wild_Trunk_Full"
    },
    {
      "x": 1,
      "y": 15,
      "z": 11,
      "name": "Wood_Wisteria_Wild_Trunk_Full"
    },
    {
      "x": 1,
      "y": 14,
      "z": 12,
      "name": "Plant_Leaves_Wisteria_Wild"
    },
    {
      "x": 1,
      "y": 16,
      "z": 12,
      "name": "Plant_Leaves_Wisteria_Wild"
    },
    {
      "x": 1,
      "y": 15,
      "z": 13,
      "name": "Plant_Leaves_Wisteria_Wild"
    },
    {
      "x": 1,
      "y": 16,
      "z": 13,
      "name": "Plant_Leaves_Wisteria_Wild"
    },
    {
      "x": 1,
      "y": 14,
      "z": 14,
      "name": "Plant_Leaves_Wisteria_Wild"
    },
    {
      "x": 1,
      "y": 15,
      "z": 14,
      "name": "Plant_Leaves_Wisteria_Wild"
    },
    {
      "x": 1,
      "y": 14,
      "z": 15,
      "name": "Plant_Leaves_Wisteria_Wild"
    },
    {
      "x": 1,
      "y": 13,
      "z": 16,
      "name": "Plant_Leaves_Wisteria_Wild"
    },
    {
      "x": 1,
      "y": 14,
      "z": 16,
      "name": "Plant_Leaves_Wisteria_Wild"
    },
    {
      "x": 2,
      "y": 17,
      "z": -14,
      "name": "Plant_Leaves_Wisteria_Wild"
    },
    {
      "x": 2,
      "y": 17,
      "z": -13,
      "name": "Plant_Leaves_Wisteria_Wild"
    },
    {
      "x": 2,
      "y": 17,
      "z": -12,
      "name": "Plant_Leaves_Wisteria_Wild"
    },
    {
      "x": 2,
      "y": 17,
      "z": -11,
      "name": "Plant_Leaves_Wisteria_Wild"
    },
    {
      "x": 2,
      "y": 17,
      "z": -10,
      "name": "Plant_Leaves_Wisteria_Wild"
    },
    {
      "x": 2,
      "y": 18,
      "z": -8,
      "name": "Plant_Leaves_Wisteria_Wild"
    },
    {
      "x": 2,
      "y": 19,
      "z": -8,
      "name": "Plant_Leaves_Wisteria_Wild"
    },
    {
      "x": 2,
      "y": 18,
      "z": -7,
      "name": "Plant_Leaves_Wisteria_Wild"
    },
    {
      "x": 2,
      "y": 19,
      "z": -7,
      "name": "Plant_Leaves_Wisteria_Wild"
    },
    {
      "x": 2,
      "y": 18,
      "z": -6,
      "name": "Plant_Leaves_Wisteria_Wild"
    },
    {
      "x": 2,
      "y": 19,
      "z": -6,
      "name": "Plant_Leaves_Wisteria_Wild"
    },
    {
      "x": 2,
      "y": 18,
      "z": -5,
      "name": "Plant_Leaves_Wisteria_Wild"
    },
    {
      "x": 2,
      "y": 19,
      "z": -5,
      "name": "Plant_Leaves_Wisteria_Wild"
    },
    {
      "x": 2,
      "y": 18,
      "z": -4,
      "name": "Plant_Leaves_Wisteria_Wild"
    },
    {
      "x": 2,
      "y": 8,
      "z": -3,
      "name": "Wood_Wisteria_Wild_Trunk_Full"
    },
    {
      "x": 2,
      "y": 9,
      "z": -3,
      "name": "Wood_Wisteria_Wild_Trunk"
    },
    {
      "x": 2,
      "y": 10,
      "z": -3,
      "name": "Wood_Wisteria_Wild_Trunk_Full"
    },
    {
      "x": 2,
      "y": 17,
      "z": -3,
      "name": "Plant_Leaves_Wisteria_Wild"
    },
    {
      "x": 2,
      "y": 18,
      "z": -3,
      "name": "Plant_Leaves_Wisteria_Wild"
    },
    {
      "x": 2,
      "y": 7,
      "z": -2,
      "name": "Wood_Wisteria_Wild_Trunk_Full"
    },
    {
      "x": 2,
      "y": 8,
      "z": -2,
      "name": "Wood_Wisteria_Wild_Trunk"
    },
    {
      "x": 2,
      "y": 9,
      "z": -2,
      "name": "Wood_Wisteria_Wild_Trunk"
    },
    {
      "x": 2,
      "y": 10,
      "z": -2,
      "name": "Wood_Wisteria_Wild_Trunk"
    },
    {
      "x": 2,
      "y": 11,
      "z": -2,
      "name": "Wood_Wisteria_Wild_Trunk"
    },
    {
      "x": 2,
      "y": 12,
      "z": -2,
      "name": "Wood_Wisteria_Wild_Trunk_Full"
    },
    {
      "x": 2,
      "y": 18,
      "z": -2,
      "name": "Plant_Leaves_Wisteria_Wild"
    },
    {
      "x": 2,
      "y": 4,
      "z": -1,
      "name": "Wood_Wisteria_Wild_Trunk_Full"
    },
    {
      "x": 2,
      "y": 11,
      "z": -1,
      "name": "Wood_Wisteria_Wild_Trunk_Full"
    },
    {
      "x": 2,
      "y": 12,
      "z": -1,
      "name": "Wood_Wisteria_Wild_Trunk_Full"
    },
    {
      "x": 2,
      "y": 18,
      "z": -1,
      "name": "Plant_Leaves_Wisteria_Wild"
    },
    {
      "x": 2,
      "y": 19,
      "z": -1,
      "name": "Plant_Leaves_Wisteria_Wild"
    },
    {
      "x": 2,
      "y": 4,
      "z": 0,
      "name": "Wood_Wisteria_Wild_Trunk_Full"
    },
    {
      "x": 2,
      "y": 12,
      "z": 0,
      "name": "Wood_Wisteria_Wild_Trunk_Full"
    },
    {
      "x": 2,
      "y": 13,
      "z": 0,
      "name": "Wood_Wisteria_Wild_Trunk_Full"
    },
    {
      "x": 2,
      "y": 18,
      "z": 0,
      "name": "Plant_Leaves_Wisteria_Wild"
    },
    {
      "x": 2,
      "y": 19,
      "z": 0,
      "name": "Plant_Leaves_Wisteria_Wild"
    },
    {
      "x": 2,
      "y": 12,
      "z": 1,
      "name": "Wood_Wisteria_Wild_Trunk_Full"
    },
    {
      "x": 2,
      "y": 13,
      "z": 1,
      "name": "Wood_Wisteria_Wild_Trunk_Full"
    },
    {
      "x": 2,
      "y": 17,
      "z": 1,
      "name": "Wood_Wisteria_Wild_Trunk_Full"
    },
    {
      "x": 2,
      "y": 19,
      "z": 1,
      "name": "Plant_Leaves_Wisteria_Wild"
    },
    {
      "x": 2,
      "y": 18,
      "z": 2,
      "name": "Plant_Leaves_Wisteria_Wild"
    },
    {
      "x": 2,
      "y": 19,
      "z": 2,
      "name": "Plant_Leaves_Wisteria_Wild"
    },
    {
      "x": 2,
      "y": 17,
      "z": 3,
      "name": "Plant_Leaves_Wisteria_Wild"
    },
    {
      "x": 2,
      "y": 18,
      "z": 3,
      "name": "Plant_Leaves_Wisteria_Wild"
    },
    {
      "x": 2,
      "y": 15,
      "z": 4,
      "name": "Plant_Leaves_Wisteria_Wild"
    },
    {
      "x": 2,
      "y": 17,
      "z": 4,
      "name": "Plant_Leaves_Wisteria_Wild"
    },
    {
      "x": 2,
      "y": 18,
      "z": 4,
      "name": "Plant_Leaves_Wisteria_Wild"
    },
    {
      "x": 2,
      "y": 15,
      "z": 5,
      "name": "Plant_Leaves_Wisteria_Wild"
    },
    {
      "x": 2,
      "y": 17,
      "z": 5,
      "name": "Plant_Leaves_Wisteria_Wild"
    },
    {
      "x": 2,
      "y": 15,
      "z": 7,
      "name": "Wood_Wisteria_Wild_Trunk_Full"
    },
    {
      "x": 2,
      "y": 16,
      "z": 7,
      "name": "Plant_Leaves_Wisteria_Wild"
    },
    {
      "x": 2,
      "y": 15,
      "z": 8,
      "name": "Plant_Leaves_Wisteria_Wild"
    },
    {
      "x": 2,
      "y": 15,
      "z": 9,
      "name": "Plant_Leaves_Wisteria_Wild"
    },
    {
      "x": 2,
      "y": 15,
      "z": 10,
      "name": "Plant_Leaves_Wisteria_Wild"
    },
    {
      "x": 2,
      "y": 16,
      "z": 10,
      "name": "Plant_Leaves_Wisteria_Wild"
    },
    {
      "x": 2,
      "y": 14,
      "z": 11,
      "name": "Plant_Leaves_Wisteria_Wild"
    },
    {
      "x": 2,
      "y": 15,
      "z": 11,
      "name": "Plant_Leaves_Wisteria_Wild"
    },
    {
      "x": 2,
      "y": 14,
      "z": 12,
      "name": "Plant_Leaves_Wisteria_Wild"
    },
    {
      "x": 2,
      "y": 15,
      "z": 12,
      "name": "Plant_Leaves_Wisteria_Wild"
    },
    {
      "x": 2,
      "y": 14,
      "z": 13,
      "name": "Plant_Leaves_Wisteria_Wild"
    },
    {
      "x": 2,
      "y": 15,
      "z": 13,
      "name": "Plant_Leaves_Wisteria_Wild"
    },
    {
      "x": 2,
      "y": 14,
      "z": 14,
      "name": "Plant_Leaves_Wisteria_Wild"
    },
    {
      "x": 2,
      "y": 15,
      "z": 15,
      "name": "Plant_Leaves_Wisteria_Wild"
    },
    {
      "x": 2,
      "y": 14,
      "z": 16,
      "name": "Plant_Leaves_Wisteria_Wild"
    },
    {
      "x": 3,
      "y": 18,
      "z": -10,
      "name": "Plant_Leaves_Wisteria_Wild"
    },
    {
      "x": 3,
      "y": 18,
      "z": -9,
      "name": "Plant_Leaves_Wisteria_Wild"
    },
    {
      "x": 3,
      "y": 18,
      "z": -8,
      "name": "Plant_Leaves_Wisteria_Wild"
    },
    {
      "x": 3,
      "y": 18,
      "z": -7,
      "name": "Plant_Leaves_Wisteria_Wild"
    },
    {
      "x": 3,
      "y": 19,
      "z": -7,
      "name": "Plant_Leaves_Wisteria_Wild"
    },
    {
      "x": 3,
      "y": 18,
      "z": -6,
      "name": "Plant_Leaves_Wisteria_Wild"
    },
    {
      "x": 3,
      "y": 18,
      "z": -5,
      "name": "Plant_Leaves_Wisteria_Wild"
    },
    {
      "x": 3,
      "y": 10,
      "z": -4,
      "name": "Wood_Wisteria_Wild_Trunk_Full"
    },
    {
      "x": 3,
      "y": 11,
      "z": -4,
      "name": "Wood_Wisteria_Wild_Trunk_Full"
    },
    {
      "x": 3,
      "y": 18,
      "z": -4,
      "name": "Plant_Leaves_Wisteria_Wild"
    },
    {
      "x": 3,
      "y": 9,
      "z": -3,
      "name": "Wood_Wisteria_Wild_Trunk_Full"
    },
    {
      "x": 3,
      "y": 10,
      "z": -3,
      "name": "Wood_Wisteria_Wild_Trunk"
    },
    {
      "x": 3,
      "y": 11,
      "z": -3,
      "name": "Wood_Wisteria_Wild_Trunk_Full"
    },
    {
      "x": 3,
      "y": 17,
      "z": -3,
      "name": "Plant_Leaves_Wisteria_Wild"
    },
    {
      "x": 3,
      "y": 18,
      "z": -3,
      "name": "Plant_Leaves_Wisteria_Wild"
    },
    {
      "x": 3,
      "y": 9,
      "z": -2,
      "name": "Wood_Wisteria_Wild_Trunk_Full"
    },
    {
      "x": 3,
      "y": 10,
      "z": -2,
      "name": "Wood_Wisteria_Wild_Trunk"
    },
    {
      "x": 3,
      "y": 11,
      "z": -2,
      "name": "Wood_Wisteria_Wild_Trunk_Full"
    },
    {
      "x": 3,
      "y": 18,
      "z": -2,
      "name": "Plant_Leaves_Wisteria_Wild"
    },
    {
      "x": 3,
      "y": 10,
      "z": -1,
      "name": "Plant_Leaves_Wisteria_Wild"
    },
    {
      "x": 3,
      "y": 11,
      "z": -1,
      "name": "Plant_Leaves_Wisteria_Wild"
    },
    {
      "x": 3,
      "y": 12,
      "z": -1,
      "name": "Wood_Wisteria_Wild_Trunk_Full"
    },
    {
      "x": 3,
      "y": 18,
      "z": -1,
      "name": "Plant_Leaves_Wisteria_Wild"
    },
    {
      "x": 3,
      "y": 1,
      "z": 0,
      "name": "Wood_Wisteria_Wild_Roots"
    },
    {
      "x": 3,
      "y": 2,
      "z": 0,
      "name": "Wood_Wisteria_Wild_Trunk_Full"
    },
    {
      "x": 3,
      "y": 3,
      "z": 0,
      "name": "Wood_Wisteria_Wild_Trunk"
    },
    {
      "x": 3,
      "y": 4,
      "z": 0,
      "name": "Wood_Wisteria_Wild_Trunk_Full"
    },
    {
      "x": 3,
      "y": 10,
      "z": 0,
      "name": "Plant_Leaves_Wisteria_Wild"
    },
    {
      "x": 3,
      "y": 11,
      "z": 0,
      "name": "Plant_Leaves_Wisteria_Wild"
    },
    {
      "x": 3,
      "y": 18,
      "z": 0,
      "name": "Plant_Leaves_Wisteria_Wild"
    },
    {
      "x": 3,
      "y": 19,
      "z": 0,
      "name": "Plant_Leaves_Wisteria_Wild"
    },
    {
      "x": 3,
      "y": 10,
      "z": 1,
      "name": "Plant_Leaves_Wisteria_Wild"
    },
    {
      "x": 3,
      "y": 11,
      "z": 1,
      "name": "Plant_Leaves_Wisteria_Wild"
    },
    {
      "x": 3,
      "y": 18,
      "z": 1,
      "name": "Plant_Leaves_Wisteria_Wild"
    },
    {
      "x": 3,
      "y": 19,
      "z": 1,
      "name": "Plant_Leaves_Wisteria_Wild"
    },
    {
      "x": 3,
      "y": 10,
      "z": 2,
      "name": "Plant_Leaves_Wisteria_Wild"
    },
    {
      "x": 3,
      "y": 18,
      "z": 2,
      "name": "Plant_Leaves_Wisteria_Wild"
    },
    {
      "x": 3,
      "y": 18,
      "z": 3,
      "name": "Plant_Leaves_Wisteria_Wild"
    },
    {
      "x": 3,
      "y": 19,
      "z": 3,
      "name": "Plant_Leaves_Wisteria_Wild"
    },
    {
      "x": 3,
      "y": 15,
      "z": 4,
      "name": "Plant_Leaves_Wisteria_Wild"
    },
    {
      "x": 3,
      "y": 17,
      "z": 4,
      "name": "Plant_Leaves_Wisteria_Wild"
    },
    {
      "x": 3,
      "y": 18,
      "z": 4,
      "name": "Plant_Leaves_Wisteria_Wild"
    },
    {
      "x": 3,
      "y": 14,
      "z": 5,
      "name": "Plant_Leaves_Wisteria_Wild"
    },
    {
      "x": 3,
      "y": 15,
      "z": 5,
      "name": "Plant_Leaves_Wisteria_Wild"
    },
    {
      "x": 3,
      "y": 17,
      "z": 5,
      "name": "Plant_Leaves_Wisteria_Wild"
    },
    {
      "x": 3,
      "y": 15,
      "z": 6,
      "name": "Wood_Wisteria_Wild_Trunk_Full"
    },
    {
      "x": 3,
      "y": 15,
      "z": 7,
      "name": "Wood_Wisteria_Wild_Trunk_Full"
    },
    {
      "x": 3,
      "y": 16,
      "z": 7,
      "name": "Plant_Leaves_Wisteria_Wild"
    },
    {
      "x": 3,
      "y": 14,
      "z": 8,
      "name": "Plant_Leaves_Wisteria_Wild"
    },
    {
      "x": 3,
      "y": 16,
      "z": 8,
      "name": "Plant_Leaves_Wisteria_Wild"
    },
    {
      "x": 3,
      "y": 15,
      "z": 9,
      "name": "Plant_Leaves_Wisteria_Wild"
    },
    {
      "x": 3,
      "y": 16,
      "z": 9,
      "name": "Plant_Leaves_Wisteria_Wild"
    },
    {
      "x": 3,
      "y": 15,
      "z": 10,
      "name": "Plant_Leaves_Wisteria_Wild"
    },
    {
      "x": 3,
      "y": 14,
      "z": 12,
      "name": "Plant_Leaves_Wisteria_Wild"
    },
    {
      "x": 3,
      "y": 15,
      "z": 12,
      "name": "Plant_Leaves_Wisteria_Wild"
    },
    {
      "x": 3,
      "y": 14,
      "z": 13,
      "name": "Plant_Leaves_Wisteria_Wild"
    },
    {
      "x": 3,
      "y": 15,
      "z": 13,
      "name": "Plant_Leaves_Wisteria_Wild"
    },
    {
      "x": 3,
      "y": 15,
      "z": 14,
      "name": "Plant_Leaves_Wisteria_Wild"
    },
    {
      "x": 3,
      "y": 15,
      "z": 15,
      "name": "Plant_Leaves_Wisteria_Wild"
    },
    {
      "x": 4,
      "y": 18,
      "z": -9,
      "name": "Plant_Leaves_Wisteria_Wild"
    },
    {
      "x": 4,
      "y": 18,
      "z": -8,
      "name": "Plant_Leaves_Wisteria_Wild"
    },
    {
      "x": 4,
      "y": 18,
      "z": -7,
      "name": "Plant_Leaves_Wisteria_Wild"
    },
    {
      "x": 4,
      "y": 18,
      "z": -6,
      "name": "Plant_Leaves_Wisteria_Wild"
    },
    {
      "x": 4,
      "y": 18,
      "z": -5,
      "name": "Plant_Leaves_Wisteria_Wild"
    },
    {
      "x": 4,
      "y": 10,
      "z": -4,
      "name": "Wood_Wisteria_Wild_Trunk_Full"
    },
    {
      "x": 4,
      "y": 11,
      "z": -4,
      "name": "Wood_Wisteria_Wild_Trunk_Full"
    },
    {
      "x": 4,
      "y": 17,
      "z": -4,
      "name": "Plant_Leaves_Wisteria_Wild"
    },
    {
      "x": 4,
      "y": 18,
      "z": -4,
      "name": "Plant_Leaves_Wisteria_Wild"
    },
    {
      "x": 4,
      "y": 10,
      "z": -3,
      "name": "Wood_Wisteria_Wild_Trunk_Full"
    },
    {
      "x": 4,
      "y": 11,
      "z": -3,
      "name": "Wood_Wisteria_Wild_Trunk_Full"
    },
    {
      "x": 4,
      "y": 12,
      "z": -3,
      "name": "Wood_Wisteria_Wild_Trunk_Full"
    },
    {
      "x": 4,
      "y": 17,
      "z": -3,
      "name": "Plant_Leaves_Wisteria_Wild"
    },
    {
      "x": 4,
      "y": 11,
      "z": -2,
      "name": "Plant_Leaves_Wisteria_Wild"
    },
    {
      "x": 4,
      "y": 11,
      "z": -1,
      "name": "Plant_Leaves_Wisteria_Wild"
    },
    {
      "x": 4,
      "y": 18,
      "z": -1,
      "name": "Plant_Leaves_Wisteria_Wild"
    },
    {
      "x": 4,
      "y": 11,
      "z": 0,
      "name": "Plant_Leaves_Wisteria_Wild"
    },
    {
      "x": 4,
      "y": 18,
      "z": 0,
      "name": "Plant_Leaves_Wisteria_Wild"
    },
    {
      "x": 4,
      "y": 19,
      "z": 0,
      "name": "Plant_Leaves_Wisteria_Wild"
    },
    {
      "x": 4,
      "y": 11,
      "z": 1,
      "name": "Plant_Leaves_Wisteria_Wild"
    },
    {
      "x": 4,
      "y": 18,
      "z": 1,
      "name": "Plant_Leaves_Wisteria_Wild"
    },
    {
      "x": 4,
      "y": 19,
      "z": 1,
      "name": "Plant_Leaves_Wisteria_Wild"
    },
    {
      "x": 4,
      "y": 10,
      "z": 2,
      "name": "Plant_Leaves_Wisteria_Wild"
    },
    {
      "x": 4,
      "y": 11,
      "z": 2,
      "name": "Plant_Leaves_Wisteria_Wild"
    },
    {
      "x": 4,
      "y": 18,
      "z": 2,
      "name": "Plant_Leaves_Wisteria_Wild"
    },
    {
      "x": 4,
      "y": 19,
      "z": 2,
      "name": "Plant_Leaves_Wisteria_Wild"
    },
    {
      "x": 4,
      "y": 10,
      "z": 3,
      "name": "Plant_Leaves_Wisteria_Wild"
    },
    {
      "x": 4,
      "y": 11,
      "z": 3,
      "name": "Plant_Leaves_Wisteria_Wild"
    },
    {
      "x": 4,
      "y": 18,
      "z": 3,
      "name": "Plant_Leaves_Wisteria_Wild"
    },
    {
      "x": 4,
      "y": 15,
      "z": 4,
      "name": "Plant_Leaves_Wisteria_Wild"
    },
    {
      "x": 4,
      "y": 17,
      "z": 4,
      "name": "Plant_Leaves_Wisteria_Wild"
    },
    {
      "x": 4,
      "y": 15,
      "z": 5,
      "name": "Plant_Leaves_Wisteria_Wild"
    },
    {
      "x": 4,
      "y": 17,
      "z": 5,
      "name": "Plant_Leaves_Wisteria_Wild"
    },
    {
      "x": 4,
      "y": 15,
      "z": 6,
      "name": "Wood_Wisteria_Wild_Trunk_Full"
    },
    {
      "x": 4,
      "y": 16,
      "z": 6,
      "name": "Plant_Leaves_Wisteria_Wild"
    },
    {
      "x": 4,
      "y": 13,
      "z": 7,
      "name": "Plant_Leaves_Wisteria_Wild"
    },
    {
      "x": 4,
      "y": 14,
      "z": 7,
      "name": "Plant_Leaves_Wisteria_Wild"
    },
    {
      "x": 4,
      "y": 16,
      "z": 7,
      "name": "Plant_Leaves_Wisteria_Wild"
    },
    {
      "x": 4,
      "y": 14,
      "z": 8,
      "name": "Plant_Leaves_Wisteria_Wild"
    },
    {
      "x": 4,
      "y": 15,
      "z": 8,
      "name": "Plant_Leaves_Wisteria_Wild"
    },
    {
      "x": 4,
      "y": 16,
      "z": 8,
      "name": "Plant_Leaves_Wisteria_Wild"
    },
    {
      "x": 4,
      "y": 13,
      "z": 9,
      "name": "Plant_Leaves_Wisteria_Wild"
    },
    {
      "x": 4,
      "y": 14,
      "z": 9,
      "name": "Plant_Leaves_Wisteria_Wild"
    },
    {
      "x": 4,
      "y": 15,
      "z": 9,
      "name": "Plant_Leaves_Wisteria_Wild"
    },
    {
      "x": 4,
      "y": 13,
      "z": 10,
      "name": "Plant_Leaves_Wisteria_Wild"
    },
    {
      "x": 4,
      "y": 15,
      "z": 10,
      "name": "Plant_Leaves_Wisteria_Wild"
    },
    {
      "x": 4,
      "y": 13,
      "z": 11,
      "name": "Plant_Leaves_Wisteria_Wild"
    },
    {
      "x": 4,
      "y": 15,
      "z": 12,
      "name": "Plant_Leaves_Wisteria_Wild"
    },
    {
      "x": 4,
      "y": 15,
      "z": 13,
      "name": "Plant_Leaves_Wisteria_Wild"
    },
    {
      "x": 4,
      "y": 15,
      "z": 14,
      "name": "Plant_Leaves_Wisteria_Wild"
    },
    {
      "x": 5,
      "y": 11,
      "z": -8,
      "name": "Plant_Leaves_Wisteria_Wild"
    },
    {
      "x": 5,
      "y": 11,
      "z": -7,
      "name": "Plant_Leaves_Wisteria_Wild"
    },
    {
      "x": 5,
      "y": 12,
      "z": -7,
      "name": "Plant_Leaves_Wisteria_Wild"
    },
    {
      "x": 5,
      "y": 18,
      "z": -7,
      "name": "Plant_Leaves_Wisteria_Wild"
    },
    {
      "x": 5,
      "y": 18,
      "z": -6,
      "name": "Plant_Leaves_Wisteria_Wild"
    },
    {
      "x": 5,
      "y": 13,
      "z": -5,
      "name": "Plant_Leaves_Wisteria_Wild"
    },
    {
      "x": 5,
      "y": 17,
      "z": -5,
      "name": "Plant_Leaves_Wisteria_Wild"
    },
    {
      "x": 5,
      "y": 18,
      "z": -5,
      "name": "Plant_Leaves_Wisteria_Wild"
    },
    {
      "x": 5,
      "y": 11,
      "z": -4,
      "name": "Wood_Wisteria_Wild_Trunk_Full"
    },
    {
      "x": 5,
      "y": 17,
      "z": -4,
      "name": "Plant_Leaves_Wisteria_Wild"
    },
    {
      "x": 5,
      "y": 18,
      "z": -4,
      "name": "Plant_Leaves_Wisteria_Wild"
    },
    {
      "x": 5,
      "y": 12,
      "z": -3,
      "name": "Wood_Wisteria_Wild_Trunk_Full"
    },
    {
      "x": 5,
      "y": 12,
      "z": -2,
      "name": "Wood_Wisteria_Wild_Trunk_Full"
    },
    {
      "x": 5,
      "y": 11,
      "z": -1,
      "name": "Plant_Leaves_Wisteria_Wild"
    },
    {
      "x": 5,
      "y": 12,
      "z": -1,
      "name": "Plant_Leaves_Wisteria_Wild"
    },
    {
      "x": 5,
      "y": 18,
      "z": -1,
      "name": "Plant_Leaves_Wisteria_Wild"
    },
    {
      "x": 5,
      "y": 11,
      "z": 0,
      "name": "Plant_Leaves_Wisteria_Wild"
    },
    {
      "x": 5,
      "y": 12,
      "z": 0,
      "name": "Plant_Leaves_Wisteria_Wild"
    },
    {
      "x": 5,
      "y": 18,
      "z": 0,
      "name": "Plant_Leaves_Wisteria_Wild"
    },
    {
      "x": 5,
      "y": 11,
      "z": 1,
      "name": "Plant_Leaves_Wisteria_Wild"
    },
    {
      "x": 5,
      "y": 18,
      "z": 1,
      "name": "Plant_Leaves_Wisteria_Wild"
    },
    {
      "x": 5,
      "y": 11,
      "z": 2,
      "name": "Plant_Leaves_Wisteria_Wild"
    },
    {
      "x": 5,
      "y": 18,
      "z": 2,
      "name": "Plant_Leaves_Wisteria_Wild"
    },
    {
      "x": 5,
      "y": 10,
      "z": 3,
      "name": "Plant_Leaves_Wisteria_Wild"
    },
    {
      "x": 5,
      "y": 11,
      "z": 3,
      "name": "Plant_Leaves_Wisteria_Wild"
    },
    {
      "x": 5,
      "y": 18,
      "z": 3,
      "name": "Plant_Leaves_Wisteria_Wild"
    },
    {
      "x": 5,
      "y": 14,
      "z": 4,
      "name": "Plant_Leaves_Wisteria_Wild"
    },
    {
      "x": 5,
      "y": 15,
      "z": 4,
      "name": "Plant_Leaves_Wisteria_Wild"
    },
    {
      "x": 5,
      "y": 14,
      "z": 5,
      "name": "Plant_Leaves_Wisteria_Wild"
    },
    {
      "x": 5,
      "y": 15,
      "z": 5,
      "name": "Plant_Leaves_Wisteria_Wild"
    },
    {
      "x": 5,
      "y": 14,
      "z": 6,
      "name": "Plant_Leaves_Wisteria_Wild"
    },
    {
      "x": 5,
      "y": 15,
      "z": 6,
      "name": "Plant_Leaves_Wisteria_Wild"
    },
    {
      "x": 5,
      "y": 14,
      "z": 7,
      "name": "Plant_Leaves_Wisteria_Wild"
    },
    {
      "x": 5,
      "y": 15,
      "z": 7,
      "name": "Plant_Leaves_Wisteria_Wild"
    },
    {
      "x": 5,
      "y": 14,
      "z": 8,
      "name": "Plant_Leaves_Wisteria_Wild"
    },
    {
      "x": 5,
      "y": 15,
      "z": 8,
      "name": "Plant_Leaves_Wisteria_Wild"
    },
    {
      "x": 5,
      "y": 14,
      "z": 9,
      "name": "Plant_Leaves_Wisteria_Wild"
    },
    {
      "x": 5,
      "y": 15,
      "z": 9,
      "name": "Plant_Leaves_Wisteria_Wild"
    },
    {
      "x": 5,
      "y": 13,
      "z": 10,
      "name": "Plant_Leaves_Wisteria_Wild"
    },
    {
      "x": 5,
      "y": 14,
      "z": 10,
      "name": "Plant_Leaves_Wisteria_Wild"
    },
    {
      "x": 5,
      "y": 13,
      "z": 11,
      "name": "Plant_Leaves_Wisteria_Wild"
    },
    {
      "x": 5,
      "y": 15,
      "z": 12,
      "name": "Plant_Leaves_Wisteria_Wild"
    },
    {
      "x": 5,
      "y": 15,
      "z": 13,
      "name": "Plant_Leaves_Wisteria_Wild"
    },
    {
      "x": 5,
      "y": 15,
      "z": 14,
      "name": "Plant_Leaves_Wisteria_Wild"
    },
    {
      "x": 6,
      "y": 11,
      "z": -10,
      "name": "Plant_Leaves_Wisteria_Wild"
    },
    {
      "x": 6,
      "y": 11,
      "z": -9,
      "name": "Plant_Leaves_Wisteria_Wild"
    },
    {
      "x": 6,
      "y": 11,
      "z": -8,
      "name": "Plant_Leaves_Wisteria_Wild"
    },
    {
      "x": 6,
      "y": 12,
      "z": -8,
      "name": "Plant_Leaves_Wisteria_Wild"
    },
    {
      "x": 6,
      "y": 11,
      "z": -7,
      "name": "Plant_Leaves_Wisteria_Wild"
    },
    {
      "x": 6,
      "y": 18,
      "z": -6,
      "name": "Plant_Leaves_Wisteria_Wild"
    },
    {
      "x": 6,
      "y": 13,
      "z": -5,
      "name": "Plant_Leaves_Wisteria_Wild"
    },
    {
      "x": 6,
      "y": 11,
      "z": -4,
      "name": "Wood_Wisteria_Wild_Trunk_Full"
    },
    {
      "x": 6,
      "y": 13,
      "z": -4,
      "name": "Plant_Leaves_Wisteria_Wild"
    },
    {
      "x": 6,
      "y": 13,
      "z": -3,
      "name": "Plant_Leaves_Wisteria_Wild"
    },
    {
      "x": 6,
      "y": 12,
      "z": -2,
      "name": "Wood_Wisteria_Wild_Trunk_Full"
    },
    {
      "x": 6,
      "y": 13,
      "z": -2,
      "name": "Plant_Leaves_Wisteria_Wild"
    },
    {
      "x": 6,
      "y": 11,
      "z": -1,
      "name": "Plant_Leaves_Wisteria_Wild"
    },
    {
      "x": 6,
      "y": 12,
      "z": -1,
      "name": "Plant_Leaves_Wisteria_Wild"
    },
    {
      "x": 6,
      "y": 11,
      "z": 0,
      "name": "Plant_Leaves_Wisteria_Wild"
    },
    {
      "x": 6,
      "y": 12,
      "z": 0,
      "name": "Plant_Leaves_Wisteria_Wild"
    },
    {
      "x": 6,
      "y": 11,
      "z": 1,
      "name": "Plant_Leaves_Wisteria_Wild"
    },
    {
      "x": 6,
      "y": 18,
      "z": 1,
      "name": "Plant_Leaves_Wisteria_Wild"
    },
    {
      "x": 6,
      "y": 11,
      "z": 2,
      "name": "Plant_Leaves_Wisteria_Wild"
    },
    {
      "x": 6,
      "y": 18,
      "z": 2,
      "name": "Plant_Leaves_Wisteria_Wild"
    },
    {
      "x": 6,
      "y": 11,
      "z": 3,
      "name": "Plant_Leaves_Wisteria_Wild"
    },
    {
      "x": 6,
      "y": 11,
      "z": 4,
      "name": "Plant_Leaves_Wisteria_Wild"
    },
    {
      "x": 6,
      "y": 14,
      "z": 4,
      "name": "Plant_Leaves_Wisteria_Wild"
    },
    {
      "x": 6,
      "y": 14,
      "z": 5,
      "name": "Plant_Leaves_Wisteria_Wild"
    },
    {
      "x": 6,
      "y": 15,
      "z": 5,
      "name": "Plant_Leaves_Wisteria_Wild"
    },
    {
      "x": 6,
      "y": 14,
      "z": 6,
      "name": "Plant_Leaves_Wisteria_Wild"
    },
    {
      "x": 6,
      "y": 15,
      "z": 6,
      "name": "Plant_Leaves_Wisteria_Wild"
    },
    {
      "x": 6,
      "y": 14,
      "z": 7,
      "name": "Plant_Leaves_Wisteria_Wild"
    },
    {
      "x": 6,
      "y": 15,
      "z": 7,
      "name": "Plant_Leaves_Wisteria_Wild"
    },
    {
      "x": 6,
      "y": 14,
      "z": 9,
      "name": "Plant_Leaves_Wisteria_Wild"
    },
    {
      "x": 6,
      "y": 13,
      "z": 10,
      "name": "Plant_Leaves_Wisteria_Wild"
    },
    {
      "x": 6,
      "y": 14,
      "z": 10,
      "name": "Plant_Leaves_Wisteria_Wild"
    },
    {
      "x": 7,
      "y": 11,
      "z": -10,
      "name": "Plant_Leaves_Wisteria_Wild"
    },
    {
      "x": 7,
      "y": 11,
      "z": -9,
      "name": "Plant_Leaves_Wisteria_Wild"
    },
    {
      "x": 7,
      "y": 12,
      "z": -9,
      "name": "Plant_Leaves_Wisteria_Wild"
    },
    {
      "x": 7,
      "y": 11,
      "z": -8,
      "name": "Plant_Leaves_Wisteria_Wild"
    },
    {
      "x": 7,
      "y": 12,
      "z": -8,
      "name": "Plant_Leaves_Wisteria_Wild"
    },
    {
      "x": 7,
      "y": 11,
      "z": -7,
      "name": "Plant_Leaves_Wisteria_Wild"
    },
    {
      "x": 7,
      "y": 12,
      "z": -7,
      "name": "Plant_Leaves_Wisteria_Wild"
    },
    {
      "x": 7,
      "y": 11,
      "z": -6,
      "name": "Plant_Leaves_Wisteria_Wild"
    },
    {
      "x": 7,
      "y": 13,
      "z": -6,
      "name": "Plant_Leaves_Wisteria_Wild"
    },
    {
      "x": 7,
      "y": 13,
      "z": -5,
      "name": "Plant_Leaves_Wisteria_Wild"
    },
    {
      "x": 7,
      "y": 11,
      "z": -4,
      "name": "Wood_Wisteria_Wild_Trunk_Full"
    },
    {
      "x": 7,
      "y": 13,
      "z": -3,
      "name": "Plant_Leaves_Wisteria_Wild"
    },
    {
      "x": 7,
      "y": 12,
      "z": -2,
      "name": "Wood_Wisteria_Wild_Trunk_Full"
    },
    {
      "x": 7,
      "y": 13,
      "z": -2,
      "name": "Plant_Leaves_Wisteria_Wild"
    },
    {
      "x": 7,
      "y": 11,
      "z": -1,
      "name": "Plant_Leaves_Wisteria_Wild"
    },
    {
      "x": 7,
      "y": 12,
      "z": -1,
      "name": "Plant_Leaves_Wisteria_Wild"
    },
    {
      "x": 7,
      "y": 13,
      "z": -1,
      "name": "Plant_Leaves_Wisteria_Wild"
    },
    {
      "x": 7,
      "y": 11,
      "z": 0,
      "name": "Plant_Leaves_Wisteria_Wild"
    },
    {
      "x": 7,
      "y": 12,
      "z": 0,
      "name": "Plant_Leaves_Wisteria_Wild"
    },
    {
      "x": 7,
      "y": 11,
      "z": 1,
      "name": "Plant_Leaves_Wisteria_Wild"
    },
    {
      "x": 7,
      "y": 12,
      "z": 1,
      "name": "Plant_Leaves_Wisteria_Wild"
    },
    {
      "x": 7,
      "y": 18,
      "z": 1,
      "name": "Plant_Leaves_Wisteria_Wild"
    },
    {
      "x": 7,
      "y": 11,
      "z": 2,
      "name": "Plant_Leaves_Wisteria_Wild"
    },
    {
      "x": 7,
      "y": 11,
      "z": 3,
      "name": "Plant_Leaves_Wisteria_Wild"
    },
    {
      "x": 7,
      "y": 14,
      "z": 6,
      "name": "Plant_Leaves_Wisteria_Wild"
    },
    {
      "x": 7,
      "y": 14,
      "z": 7,
      "name": "Plant_Leaves_Wisteria_Wild"
    },
    {
      "x": 7,
      "y": 14,
      "z": 8,
      "name": "Plant_Leaves_Wisteria_Wild"
    },
    {
      "x": 7,
      "y": 13,
      "z": 9,
      "name": "Plant_Leaves_Wisteria_Wild"
    },
    {
      "x": 7,
      "y": 14,
      "z": 9,
      "name": "Plant_Leaves_Wisteria_Wild"
    },
    {
      "x": 7,
      "y": 13,
      "z": 10,
      "name": "Plant_Leaves_Wisteria_Wild"
    },
    {
      "x": 8,
      "y": 11,
      "z": -11,
      "name": "Plant_Leaves_Wisteria_Wild"
    },
    {
      "x": 8,
      "y": 11,
      "z": -10,
      "name": "Plant_Leaves_Wisteria_Wild"
    },
    {
      "x": 8,
      "y": 11,
      "z": -9,
      "name": "Plant_Leaves_Wisteria_Wild"
    },
    {
      "x": 8,
      "y": 12,
      "z": -9,
      "name": "Plant_Leaves_Wisteria_Wild"
    },
    {
      "x": 8,
      "y": 11,
      "z": -8,
      "name": "Plant_Leaves_Wisteria_Wild"
    },
    {
      "x": 8,
      "y": 11,
      "z": -7,
      "name": "Plant_Leaves_Wisteria_Wild"
    },
    {
      "x": 8,
      "y": 12,
      "z": -7,
      "name": "Plant_Leaves_Wisteria_Wild"
    },
    {
      "x": 8,
      "y": 13,
      "z": -7,
      "name": "Plant_Leaves_Wisteria_Wild"
    },
    {
      "x": 8,
      "y": 12,
      "z": -6,
      "name": "Wood_Wisteria_Wild_Trunk_Full"
    },
    {
      "x": 8,
      "y": 13,
      "z": -6,
      "name": "Plant_Leaves_Wisteria_Wild"
    },
    {
      "x": 8,
      "y": 12,
      "z": -5,
      "name": "Wood_Wisteria_Wild_Trunk_Full"
    },
    {
      "x": 8,
      "y": 11,
      "z": -4,
      "name": "Wood_Wisteria_Wild_Trunk_Full"
    },
    {
      "x": 8,
      "y": 12,
      "z": -4,
      "name": "Wood_Wisteria_Wild_Trunk_Full"
    },
    {
      "x": 8,
      "y": 13,
      "z": -4,
      "name": "Plant_Leaves_Wisteria_Wild"
    },
    {
      "x": 8,
      "y": 12,
      "z": -2,
      "name": "Plant_Leaves_Wisteria_Wild"
    },
    {
      "x": 8,
      "y": 13,
      "z": -2,
      "name": "Plant_Leaves_Wisteria_Wild"
    },
    {
      "x": 8,
      "y": 11,
      "z": -1,
      "name": "Plant_Leaves_Wisteria_Wild"
    },
    {
      "x": 8,
      "y": 12,
      "z": -1,
      "name": "Plant_Leaves_Wisteria_Wild"
    },
    {
      "x": 8,
      "y": 11,
      "z": 0,
      "name": "Plant_Leaves_Wisteria_Wild"
    },
    {
      "x": 8,
      "y": 12,
      "z": 0,
      "name": "Plant_Leaves_Wisteria_Wild"
    },
    {
      "x": 8,
      "y": 11,
      "z": 1,
      "name": "Plant_Leaves_Wisteria_Wild"
    },
    {
      "x": 8,
      "y": 11,
      "z": 2,
      "name": "Plant_Leaves_Wisteria_Wild"
    },
    {
      "x": 8,
      "y": 14,
      "z": 6,
      "name": "Plant_Leaves_Wisteria_Wild"
    },
    {
      "x": 8,
      "y": 14,
      "z": 7,
      "name": "Plant_Leaves_Wisteria_Wild"
    },
    {
      "x": 8,
      "y": 14,
      "z": 8,
      "name": "Plant_Leaves_Wisteria_Wild"
    },
    {
      "x": 8,
      "y": 13,
      "z": 9,
      "name": "Plant_Leaves_Wisteria_Wild"
    },
    {
      "x": 9,
      "y": 11,
      "z": -11,
      "name": "Plant_Leaves_Wisteria_Wild"
    },
    {
      "x": 9,
      "y": 11,
      "z": -10,
      "name": "Plant_Leaves_Wisteria_Wild"
    },
    {
      "x": 9,
      "y": 11,
      "z": -9,
      "name": "Plant_Leaves_Wisteria_Wild"
    },
    {
      "x": 9,
      "y": 12,
      "z": -9,
      "name": "Plant_Leaves_Wisteria_Wild"
    },
    {
      "x": 9,
      "y": 11,
      "z": -8,
      "name": "Plant_Leaves_Wisteria_Wild"
    },
    {
      "x": 9,
      "y": 12,
      "z": -8,
      "name": "Plant_Leaves_Wisteria_Wild"
    },
    {
      "x": 9,
      "y": 11,
      "z": -7,
      "name": "Plant_Leaves_Wisteria_Wild"
    },
    {
      "x": 9,
      "y": 12,
      "z": -7,
      "name": "Plant_Leaves_Wisteria_Wild"
    },
    {
      "x": 9,
      "y": 13,
      "z": -7,
      "name": "Plant_Leaves_Wisteria_Wild"
    },
    {
      "x": 9,
      "y": 12,
      "z": -6,
      "name": "Plant_Leaves_Wisteria_Wild"
    },
    {
      "x": 9,
      "y": 13,
      "z": -6,
      "name": "Plant_Leaves_Wisteria_Wild"
    },
    {
      "x": 9,
      "y": 11,
      "z": -4,
      "name": "Wood_Wisteria_Wild_Trunk_Full"
    },
    {
      "x": 9,
      "y": 12,
      "z": -4,
      "name": "Plant_Leaves_Wisteria_Wild"
    },
    {
      "x": 9,
      "y": 12,
      "z": -2,
      "name": "Plant_Leaves_Wisteria_Wild"
    },
    {
      "x": 9,
      "y": 13,
      "z": -2,
      "name": "Plant_Leaves_Wisteria_Wild"
    },
    {
      "x": 9,
      "y": 11,
      "z": -1,
      "name": "Plant_Leaves_Wisteria_Wild"
    },
    {
      "x": 9,
      "y": 11,
      "z": 1,
      "name": "Plant_Leaves_Wisteria_Wild"
    },
    {
      "x": 9,
      "y": 11,
      "z": 2,
      "name": "Plant_Leaves_Wisteria_Wild"
    },
    {
      "x": 10,
      "y": 11,
      "z": -10,
      "name": "Plant_Leaves_Wisteria_Wild"
    },
    {
      "x": 10,
      "y": 11,
      "z": -9,
      "name": "Plant_Leaves_Wisteria_Wild"
    },
    {
      "x": 10,
      "y": 12,
      "z": -8,
      "name": "Plant_Leaves_Wisteria_Wild"
    },
    {
      "x": 10,
      "y": 10,
      "z": -7,
      "name": "Plant_Leaves_Wisteria_Wild"
    },
    {
      "x": 10,
      "y": 11,
      "z": -7,
      "name": "Plant_Leaves_Wisteria_Wild"
    },
    {
      "x": 10,
      "y": 11,
      "z": -6,
      "name": "Plant_Leaves_Wisteria_Wild"
    },
    {
      "x": 10,
      "y": 11,
      "z": -4,
      "name": "Wood_Wisteria_Wild_Trunk_Full"
    },
    {
      "x": 10,
      "y": 12,
      "z": -4,
      "name": "Wood_Wisteria_Wild_Trunk_Full",
      "rotation": 4
    },
    {
      "x": 10,
      "y": 13,
      "z": -4,
      "name": "Plant_Leaves_Wisteria_Wild"
    },
    {
      "x": 10,
      "y": 12,
      "z": -2,
      "name": "Plant_Leaves_Wisteria_Wild"
    },
    {
      "x": 10,
      "y": 10,
      "z": -1,
      "name": "Plant_Leaves_Wisteria_Wild"
    },
    {
      "x": 10,
      "y": 11,
      "z": -1,
      "name": "Plant_Leaves_Wisteria_Wild"
    },
    {
      "x": 10,
      "y": 10,
      "z": 0,
      "name": "Plant_Leaves_Wisteria_Wild"
    },
    {
      "x": 10,
      "y": 11,
      "z": 1,
      "name": "Plant_Leaves_Wisteria_Wild"
    },
    {
      "x": 11,
      "y": 11,
      "z": -9,
      "name": "Plant_Leaves_Wisteria_Wild"
    },
    {
      "x": 11,
      "y": 10,
      "z": -7,
      "name": "Plant_Leaves_Wisteria_Wild"
    },
    {
      "x": 11,
      "y": 11,
      "z": -7,
      "name": "Plant_Leaves_Wisteria_Wild"
    },
    {
      "x": 11,
      "y": 12,
      "z": -6,
      "name": "Plant_Leaves_Wisteria_Wild"
    },
    {
      "x": 11,
      "y": 12,
      "z": -5,
      "name": "Plant_Leaves_Wisteria_Wild"
    },
    {
      "x": 11,
      "y": 12,
      "z": -4,
      "name": "Wood_Wisteria_Wild_Trunk_Full"
    },
    {
      "x": 11,
      "y": 13,
      "z": -4,
      "name": "Plant_Leaves_Wisteria_Wild"
    },
    {
      "x": 11,
      "y": 11,
      "z": -3,
      "name": "Plant_Leaves_Wisteria_Wild"
    },
    {
      "x": 11,
      "y": 11,
      "z": -2,
      "name": "Plant_Leaves_Wisteria_Wild"
    },
    {
      "x": 11,
      "y": 12,
      "z": -2,
      "name": "Plant_Leaves_Wisteria_Wild"
    },
    {
      "x": 11,
      "y": 11,
      "z": -1,
      "name": "Plant_Leaves_Wisteria_Wild"
    },
    {
      "x": 11,
      "y": 10,
      "z": 0,
      "name": "Plant_Leaves_Wisteria_Wild"
    },
    {
      "x": 12,
      "y": 11,
      "z": -9,
      "name": "Plant_Leaves_Wisteria_Wild"
    },
    {
      "x": 12,
      "y": 10,
      "z": -8,
      "name": "Plant_Leaves_Wisteria_Wild"
    },
    {
      "x": 12,
      "y": 11,
      "z": -8,
      "name": "Plant_Leaves_Wisteria_Wild"
    },
    {
      "x": 12,
      "y": 10,
      "z": -7,
      "name": "Plant_Leaves_Wisteria_Wild"
    },
    {
      "x": 12,
      "y": 11,
      "z": -7,
      "name": "Plant_Leaves_Wisteria_Wild"
    },
    {
      "x": 12,
      "y": 12,
      "z": -6,
      "name": "Plant_Leaves_Wisteria_Wild"
    },
    {
      "x": 12,
      "y": 11,
      "z": -5,
      "name": "Plant_Leaves_Wisteria_Wild"
    },
    {
      "x": 12,
      "y": 11,
      "z": -3,
      "name": "Plant_Leaves_Wisteria_Wild"
    },
    {
      "x": 12,
      "y": 12,
      "z": -3,
      "name": "Plant_Leaves_Wisteria_Wild"
    },
    {
      "x": 12,
      "y": 11,
      "z": -2,
      "name": "Plant_Leaves_Wisteria_Wild"
    },
    {
      "x": 12,
      "y": 11,
      "z": -1,
      "name": "Plant_Leaves_Wisteria_Wild"
    },
    {
      "x": 12,
      "y": 10,
      "z": 0,
      "name": "Plant_Leaves_Wisteria_Wild"
    },
    {
      "x": 13,
      "y": 10,
      "z": -9,
      "name": "Plant_Leaves_Wisteria_Wild"
    },
    {
      "x": 13,
      "y": 10,
      "z": -8,
      "name": "Plant_Leaves_Wisteria_Wild"
    },
    {
      "x": 13,
      "y": 10,
      "z": -7,
      "name": "Plant_Leaves_Wisteria_Wild"
    },
    {
      "x": 13,
      "y": 12,
      "z": -6,
      "name": "Plant_Leaves_Wisteria_Wild"
    },
    {
      "x": 13,
      "y": 11,
      "z": -5,
      "name": "Plant_Leaves_Wisteria_Wild"
    },
    {
      "x": 13,
      "y": 12,
      "z": -5,
      "name": "Plant_Leaves_Wisteria_Wild"
    },
    {
      "x": 13,
      "y": 11,
      "z": -4,
      "name": "Plant_Leaves_Wisteria_Wild"
    },
    {
      "x": 13,
      "y": 12,
      "z": -4,
      "name": "Plant_Leaves_Wisteria_Wild"
    },
    {
      "x": 13,
      "y": 11,
      "z": -2,
      "name": "Plant_Leaves_Wisteria_Wild"
    },
    {
      "x": 13,
      "y": 12,
      "z": -2,
      "name": "Plant_Leaves_Wisteria_Wild"
    },
    {
      "x": 13,
      "y": 10,
      "z": 0,
      "name": "Plant_Leaves_Wisteria_Wild"
    },
    {
      "x": 14,
      "y": 10,
      "z": -8,
      "name": "Plant_Leaves_Wisteria_Wild"
    },
    {
      "x": 14,
      "y": 10,
      "z": -7,
      "name": "Plant_Leaves_Wisteria_Wild"
    },
    {
      "x": 14,
      "y": 12,
      "z": -6,
      "name": "Plant_Leaves_Wisteria_Wild"
    },
    {
      "x": 14,
      "y": 12,
      "z": -5,
      "name": "Plant_Leaves_Wisteria_Wild"
    },
    {
      "x": 14,
      "y": 11,
      "z": -4,
      "name": "Plant_Leaves_Wisteria_Wild"
    },
    {
      "x": 14,
      "y": 11,
      "z": -3,
      "name": "Plant_Leaves_Wisteria_Wild"
    },
    {
      "x": 14,
      "y": 10,
      "z": -2,
      "name": "Plant_Leaves_Wisteria_Wild"
    },
    {
      "x": 14,
      "y": 11,
      "z": -2,
      "name": "Plant_Leaves_Wisteria_Wild"
    },
    {
      "x": 14,
      "y": 10,
      "z": -1,
      "name": "Plant_Leaves_Wisteria_Wild"
    },
    {
      "x": 14,
      "y": 11,
      "z": -1,
      "name": "Plant_Leaves_Wisteria_Wild"
    },
    {
      "x": 14,
      "y": 10,
      "z": 0,
      "name": "Plant_Leaves_Wisteria_Wild"
    },
    {
      "x": 15,
      "y": 11,
      "z": -5,
      "name": "Plant_Leaves_Wisteria_Wild"
    },
    {
      "x": 15,
      "y": 11,
      "z": -4,
      "name": "Plant_Leaves_Wisteria_Wild"
    },
    {
      "x": 15,
      "y": 11,
      "z": -3,
      "name": "Plant_Leaves_Wisteria_Wild"
    },
    {
      "x": 15,
      "y": 10,
      "z": -2,
      "name": "Plant_Leaves_Wisteria_Wild"
    },
    {
      "x": 15,
      "y": 11,
      "z": -2,
      "name": "Plant_Leaves_Wisteria_Wild"
    },
    {
      "x": 15,
      "y": 10,
      "z": -1,
      "name": "Plant_Leaves_Wisteria_Wild"
    }
  ]
}