{
  "version": 8,
  "blockIdVersion": 10,
  "anchorX": 0,
  "anchorY": 0,
  "anchorZ": 0,
  "blocks": [
    {
      "x": 3,
      "y": 13,
      "z": 0,
      "name": "Plant_Seaweed_Wet_Stack"
    },
    {
      "x": 4,
      "y": 13,
      "z": 0,
      "name": "Plant_Seaweed_Wet_Stack"
    },
    {
      "x": 5,
      "y": 13,
      "z": 0,
      "name": "Plant_Seaweed_Wet_Stack"
    },
    {
      "x": 6,
      "y": 13,
      "z": 0,
      "name": "Plant_Seaweed_Wet_Stack"
    },
    {
      "x": 7,
      "y": 13,
      "z": 0,
      "name": "Plant_Seaweed_Wet_Stack"
    },
    {
      "x": 8,
      "y": 13,
      "z": 0,
      "name": "Plant_Seaweed_Wet_Stack"
    },
    {
      "x": 9,
      "y": 13,
      "z": 0,
      "name": "Plant_Seaweed_Wet_Stack"
    },
    {
      "x": 3,
      "y": 14,
      "z": 0,
      "name": "Plant_Seaweed_Wet_Stack"
    },
    {
      "x": 4,
      "y": 14,
      "z": 0,
      "name": "Plant_Seaweed_Wet_Stack"
    },
    {
      "x": 5,
      "y": 14,
      "z": 0,
      "name": "Plant_Seaweed_Wet_Stack"
    },
    {
      "x": 6,
      "y": 14,
      "z": 0,
      "name": "Plant_Seaweed_Wet_Stack"
    },
    {
      "x": 7,
      "y": 14,
      "z": 0,
      "name": "Plant_Seaweed_Wet_Stack"
    },
    {
      "x": 8,
      "y": 14,
      "z": 0,
      "name": "Plant_Seaweed_Wet_Stack"
    },
    {
      "x": 3,
      "y": 15,
      "z": 0,
      "name": "Plant_Seaweed_Wet_Stack"
    },
    {
      "x": 4,
      "y": 15,
      "z": 0,
      "name": "Plant_Seaweed_Wet_Stack"
    },
    {
      "x": 5,
      "y": 15,
      "z": 0,
      "name": "Plant_Seaweed_Wet_Stack"
    },
    {
      "x": 6,
      "y": 15,
      "z": 0,
      "name": "Plant_Seaweed_Wet_Stack"
    },
    {
      "x": 7,
      "y": 15,
      "z": 0,
      "name": "Plant_Seaweed_Wet_Stack"
    },
    {
      "x": 8,
      "y": 15,
      "z": 0,
      "name": "Plant_Seaweed_Wet_Stack"
    },
    {
      "x": 3,
      "y": 16,
      "z": 0,
      "name": "Plant_Seaweed_Wet_Stack"
    },
    {
      "x": 4,
      "y": 16,
      "z": 0,
      "name": "Plant_Seaweed_Wet_Stack"
    },
    {
      "x": 5,
      "y": 16,
      "z": 0,
      "name": "Plant_Seaweed_Wet_Stack"
    },
    {
      "x": 6,
      "y": 16,
      "z": 0,
      "name": "Plant_Seaweed_Wet_Stack"
    },
    {
      "x": 7,
      "y": 16,
      "z": 0,
      "name": "Plant_Seaweed_Wet_Stack"
    },
    {
      "x": 8,
      "y": 16,
      "z": 0,
      "name": "Plant_Seaweed_Wet_Stack"
    },
    {
      "x": 3,
      "y": 17,
      "z": 0,
      "name": "Plant_Seaweed_Wet_Stack"
    },
    {
      "x": 4,
      "y": 17,
      "z": 0,
      "name": "Plant_Seaweed_Wet_Stack"
    },
    {
      "x": 5,
      "y": 17,
      "z": 0,
      "name": "Plant_Seaweed_Wet_Stack"
    },
    {
      "x": 6,
      "y": 17,
      "z": 0,
      "name": "Plant_Seaweed_Wet_Stack"
    },
    {
      "x": 7,
      "y": 17,
      "z": 0,
      "name": "Plant_Seaweed_Wet_Stack"
    },
    {
      "x": 8,
      "y": 17,
      "z": 0,
      "name": "Plant_Seaweed_Wet_Stack"
    },
    {
      "x": 3,
      "y": 18,
      "z": 0,
      "name": "Plant_Seaweed_Wet_Stack"
    },
    {
      "x": 4,
      "y": 18,
      "z": 0,
      "name": "Plant_Seaweed_Wet_Stack"
    },
    {
      "x": 5,
      "y": 18,
      "z": 0,
      "name": "Plant_Seaweed_Wet_Stack"
    },
    {
      "x": 6,
      "y": 18,
      "z": 0,
      "name": "Plant_Seaweed_Wet_Stack"
    },
    {
      "x": 7,
      "y": 18,
      "z": 0,
      "name": "Plant_Seaweed_Wet_Stack"
    },
    {
      "x": 3,
      "y": 19,
      "z": 0,
      "name": "Plant_Seaweed_Wet_Stack"
    },
    {
      "x": 4,
      "y": 19,
      "z": 0,
      "name": "Plant_Seaweed_Wet_Stack"
    },
    {
      "x": 5,
      "y": 19,
      "z": 0,
      "name": "Plant_Seaweed_Wet_Stack"
    },
    {
      "x": 6,
      "y": 19,
      "z": 0,
      "name": "Plant_Seaweed_Wet_Stack"
    },
    {
      "x": 7,
      "y": 19,
      "z": 0,
      "name": "Plant_Seaweed_Wet_Stack"
    },
    {
      "x": 3,
      "y": 20,
      "z": 0,
      "name": "Plant_Seaweed_Wet_Stack"
    },
    {
      "x": 4,
      "y": 20,
      "z": 0,
      "name": "Plant_Seaweed_Wet_Stack"
    },
    {
      "x": 5,
      "y": 20,
      "z": 0,
      "name": "Plant_Seaweed_Wet_Stack"
    },
    {
      "x": 3,
      "y": 21,
      "z": 0,
      "name": "Plant_Seaweed_Wet_Stack"
    },
    {
      "x": 4,
      "y": 21,
      "z": 0,
      "name": "Plant_Seaweed_Wet_Stack"
    },
    {
      "x": 5,
      "y": 21,
      "z": 0,
      "name": "Plant_Seaweed_Wet_Stack"
    },
    {
      "x": 3,
      "y": 22,
      "z": 0,
      "name": "Plant_Seaweed_Wet_Stack"
    },
    {
      "x": 2,
      "y": 13,
      "z": 1,
      "name": "Plant_Seaweed_Wet_Stack"
    },
    {
      "x": 3,
      "y": 13,
      "z": 1,
      "name": "Plant_Seaweed_Wet_Stack"
    },
    {
      "x": 4,
      "y": 13,
      "z": 1,
      "name": "Plant_Seaweed_Wet_Stack"
    },
    {
      "x": 6,
      "y": 13,
      "z": 1,
      "name": "Plant_Seaweed_Wet_Stack"
    },
    {
      "x": 7,
      "y": 13,
      "z": 1,
      "name": "Plant_Seaweed_Wet_Stack"
    },
    {
      "x": 2,
      "y": 14,
      "z": 1,
      "name": "Plant_Seaweed_Wet_Stack"
    },
    {
      "x": 3,
      "y": 14,
      "z": 1,
      "name": "Plant_Seaweed_Wet_Stack"
    },
    {
      "x": 4,
      "y": 14,
      "z": 1,
      "name": "Plant_Seaweed_Wet_Stack"
    },
    {
      "x": 6,
      "y": 14,
      "z": 1,
      "name": "Plant_Seaweed_Wet_Stack"
    },
    {
      "x": 7,
      "y": 14,
      "z": 1,
      "name": "Plant_Seaweed_Wet_Stack"
    },
    {
      "x": 4,
      "y": 15,
      "z": 1,
      "name": "Plant_Seaweed_Wet_Stack"
    },
    {
      "x": 6,
      "y": 15,
      "z": 1,
      "name": "Plant_Seaweed_Wet_Stack"
    },
    {
      "x": 7,
      "y": 15,
      "z": 1,
      "name": "Plant_Seaweed_Wet_Stack"
    },
    {
      "x": 4,
      "y": 16,
      "z": 1,
      "name": "Plant_Seaweed_Wet_Stack"
    },
    {
      "x": 6,
      "y": 16,
      "z": 1,
      "name": "Plant_Seaweed_Wet_Stack"
    },
    {
      "x": 4,
      "y": 17,
      "z": 1,
      "name": "Plant_Seaweed_Wet_Stack"
    },
    {
      "x": 6,
      "y": 17,
      "z": 1,
      "name": "Plant_Seaweed_Wet_Stack"
    },
    {
      "x": 4,
      "y": 18,
      "z": 1,
      "name": "Plant_Seaweed_Wet_Stack"
    },
    {
      "x": 6,
      "y": 18,
      "z": 1,
      "name": "Plant_Seaweed_Wet_Stack"
    },
    {
      "x": 6,
      "y": 19,
      "z": 1,
      "name": "Plant_Seaweed_Wet_Stack"
    },
    {
      "x": 2,
      "y": 13,
      "z": 2,
      "name": "Plant_Seaweed_Wet_Stack"
    },
    {
      "x": 3,
      "y": 13,
      "z": 2,
      "name": "Plant_Seaweed_Wet_Stack"
    },
    {
      "x": 4,
      "y": 13,
      "z": 2,
      "name": "Plant_Seaweed_Wet_Stack"
    },
    {
      "x": 5,
      "y": 13,
      "z": 2,
      "name": "Plant_Seaweed_Wet_Stack"
    },
    {
      "x": 6,
      "y": 13,
      "z": 2,
      "name": "Plant_Seaweed_Wet_Stack"
    },
    {
      "x": 8,
      "y": 13,
      "z": 2,
      "name": "Plant_Seaweed_Wet_Stack"
    },
    {
      "x": 2,
      "y": 14,
      "z": 2,
      "name": "Plant_Seaweed_Wet_Stack"
    },
    {
      "x": 3,
      "y": 14,
      "z": 2,
      "name": "Plant_Seaweed_Wet_Stack"
    },
    {
      "x": 4,
      "y": 14,
      "z": 2,
      "name": "Plant_Seaweed_Wet_Stack"
    },
    {
      "x": 5,
      "y": 14,
      "z": 2,
      "name": "Plant_Seaweed_Wet_Stack"
    },
    {
      "x": 6,
      "y": 14,
      "z": 2,
      "name": "Plant_Seaweed_Wet_Stack"
    },
    {
      "x": 2,
      "y": 15,
      "z": 2,
      "name": "Plant_Seaweed_Wet_Stack"
    },
    {
      "x": 3,
      "y": 15,
      "z": 2,
      "name": "Plant_Seaweed_Wet_Stack"
    },
    {
      "x": 4,
      "y": 15,
      "z": 2,
      "name": "Plant_Seaweed_Wet_Stack"
    },
    {
      "x": 5,
      "y": 15,
      "z": 2,
      "name": "Plant_Seaweed_Wet_Stack"
    },
    {
      "x": 6,
      "y": 15,
      "z": 2,
      "name": "Plant_Seaweed_Wet_Stack"
    },
    {
      "x": 4,
      "y": 16,
      "z": 2,
      "name": "Plant_Seaweed_Wet_Stack"
    },
    {
      "x": 5,
      "y": 16,
      "z": 2,
      "name": "Plant_Seaweed_Wet_Stack"
    },
    {
      "x": 6,
      "y": 16,
      "z": 2,
      "name": "Plant_Seaweed_Wet_Stack"
    },
    {
      "x": 4,
      "y": 17,
      "z": 2,
      "name": "Plant_Seaweed_Wet_Stack"
    },
    {
      "x": 3,
      "y": 13,
      "z": 3,
      "name": "Plant_Seaweed_Wet_Stack"
    },
    {
      "x": 4,
      "y": 13,
      "z": 3,
      "name": "Plant_Seaweed_Wet_Stack"
    },
    {
      "x": 5,
      "y": 13,
      "z": 3,
      "name": "Plant_Seaweed_Wet_Stack"
    },
    {
      "x": 6,
      "y": 13,
      "z": 3,
      "name": "Plant_Seaweed_Wet_Stack"
    },
    {
      "x": 7,
      "y": 13,
      "z": 3,
      "name": "Plant_Seaweed_Wet_Stack"
    },
    {
      "x": 8,
      "y": 13,
      "z": 3,
      "name": "Plant_Seaweed_Wet_Stack"
    },
    {
      "x": 3,
      "y": 14,
      "z": 3,
      "name": "Plant_Seaweed_Wet_Stack"
    },
    {
      "x": 4,
      "y": 14,
      "z": 3,
      "name": "Plant_Seaweed_Wet_Stack"
    },
    {
      "x": 5,
      "y": 14,
      "z": 3,
      "name": "Plant_Seaweed_Wet_Stack"
    },
    {
      "x": 6,
      "y": 14,
      "z": 3,
      "name": "Plant_Seaweed_Wet_Stack"
    },
    {
      "x": 7,
      "y": 14,
      "z": 3,
      "name": "Plant_Seaweed_Wet_Stack"
    },
    {
      "x": 3,
      "y": 15,
      "z": 3,
      "name": "Plant_Seaweed_Wet_Stack"
    },
    {
      "x": 4,
      "y": 15,
      "z": 3,
      "name": "Plant_Seaweed_Wet_Stack"
    },
    {
      "x": 5,
      "y": 15,
      "z": 3,
      "name": "Plant_Seaweed_Wet_Stack"
    },
    {
      "x": 6,
      "y": 15,
      "z": 3,
      "name": "Plant_Seaweed_Wet_Stack"
    },
    {
      "x": 7,
      "y": 15,
      "z": 3,
      "name": "Plant_Seaweed_Wet_Stack"
    },
    {
      "x": 3,
      "y": 16,
      "z": 3,
      "name": "Plant_Seaweed_Wet_Stack"
    },
    {
      "x": 5,
      "y": 16,
      "z": 3,
      "name": "Plant_Seaweed_Wet_Stack"
    },
    {
      "x": 6,
      "y": 16,
      "z": 3,
      "name": "Plant_Seaweed_Wet_Stack"
    },
    {
      "x": 7,
      "y": 16,
      "z": 3,
      "name": "Plant_Seaweed_Wet_Stack"
    },
    {
      "x": 3,
      "y": 13,
      "z": 4,
      "name": "Plant_Seaweed_Wet_Stack"
    },
    {
      "x": 4,
      "y": 13,
      "z": 4,
      "name": "Plant_Seaweed_Wet_Stack"
    },
    {
      "x": 5,
      "y": 13,
      "z": 4,
      "name": "Plant_Seaweed_Wet_Stack"
    },
    {
      "x": 6,
      "y": 13,
      "z": 4,
      "name": "Plant_Seaweed_Wet_Stack"
    },
    {
      "x": 7,
      "y": 13,
      "z": 4,
      "name": "Plant_Seaweed_Wet_Stack"
    },
    {
      "x": 3,
      "y": 14,
      "z": 4,
      "name": "Plant_Seaweed_Wet_Stack"
    },
    {
      "x": 4,
      "y": 14,
      "z": 4,
      "name": "Plant_Seaweed_Wet_Stack"
    },
    {
      "x": 5,
      "y": 14,
      "z": 4,
      "name": "Plant_Seaweed_Wet_Stack"
    },
    {
      "x": 6,
      "y": 14,
      "z": 4,
      "name": "Plant_Seaweed_Wet_Stack"
    },
    {
      "x": 3,
      "y": 15,
      "z": 4,
      "name": "Plant_Seaweed_Wet_Stack"
    },
    {
      "x": 6,
      "y": 15,
      "z": 4,
      "name": "Plant_Seaweed_Wet_Stack"
    },
    {
      "x": 6,
      "y": 16,
      "z": 4,
      "name": "Plant_Seaweed_Wet_Stack"
    },
    {
      "x": 6,
      "y": 17,
      "z": 4,
      "name": "Plant_Seaweed_Wet_Stack"
    },
    {
      "x": 2,
      "y": 13,
      "z": 5,
      "name": "Plant_Seaweed_Wet_Stack"
    },
    {
      "x": 3,
      "y": 13,
      "z": 5,
      "name": "Plant_Seaweed_Wet_Stack"
    },
    {
      "x": 5,
      "y": 13,
      "z": 5,
      "name": "Plant_Seaweed_Wet_Stack"
    },
    {
      "x": 6,
      "y": 13,
      "z": 5,
      "name": "Plant_Seaweed_Wet_Stack"
    },
    {
      "x": 7,
      "y": 13,
      "z": 5,
      "name": "Plant_Seaweed_Wet_Stack"
    },
    {
      "x": 8,
      "y": 13,
      "z": 5,
      "name": "Plant_Seaweed_Wet_Stack"
    },
    {
      "x": 2,
      "y": 14,
      "z": 5,
      "name": "Plant_Seaweed_Wet_Stack"
    },
    {
      "x": 3,
      "y": 14,
      "z": 5,
      "name": "Plant_Seaweed_Wet_Stack"
    },
    {
      "x": 5,
      "y": 14,
      "z": 5,
      "name": "Plant_Seaweed_Wet_Stack"
    },
    {
      "x": 3,
      "y": 15,
      "z": 5,
      "name": "Plant_Seaweed_Wet_Stack"
    },
    {
      "x": 5,
      "y": 15,
      "z": 5,
      "name": "Plant_Seaweed_Wet_Stack"
    },
    {
      "x": 3,
      "y": 16,
      "z": 5,
      "name": "Plant_Seaweed_Wet_Stack"
    },
    {
      "x": 5,
      "y": 16,
      "z": 5,
      "name": "Plant_Seaweed_Wet_Stack"
    },
    {
      "x": 5,
      "y": 13,
      "z": 6,
      "name": "Plant_Seaweed_Wet_Stack"
    },
    {
      "x": 6,
      "y": 13,
      "z": 6,
      "name": "Plant_Seaweed_Wet_Stack"
    },
    {
      "x": 5,
      "y": 14,
      "z": 6,
      "name": "Plant_Seaweed_Wet_Stack"
    },
    {
      "x": 3,
      "y": 7,
      "z": -12,
      "name": "Plant_Moss_Block_Green"
    },
    {
      "x": 3,
      "y": 8,
      "z": -12,
      "name": "Plant_Seaweed_Wet_Stack"
    },
    {
      "x": 3,
      "y": 9,
      "z": -12,
      "name": "Plant_Seaweed_Wet_Stack"
    },
    {
      "x": 3,
      "y": 10,
      "z": -12,
      "name": "Plant_Seaweed_Wet_Stack"
    },
    {
      "x": 3,
      "y": 11,
      "z": -12,
      "name": "Plant_Seaweed_Wet_Stack"
    },
    {
      "x": 3,
      "y": 12,
      "z": -12,
      "name": "Plant_Seaweed_Wet_Stack"
    },
    {
      "x": 2,
      "y": 6,
      "z": -11,
      "name": "Plant_Moss_Block_Green"
    },
    {
      "x": 3,
      "y": 6,
      "z": -11,
      "name": "Plant_Moss_Block_Green"
    },
    {
      "x": 5,
      "y": 6,
      "z": -11,
      "name": "Plant_Moss_Block_Green"
    },
    {
      "x": 2,
      "y": 7,
      "z": -11,
      "name": "Plant_Seaweed_Wet_Stack"
    },
    {
      "x": 3,
      "y": 7,
      "z": -11,
      "name": "Plant_Moss_Block_Green"
    },
    {
      "x": 5,
      "y": 7,
      "z": -11,
      "name": "Plant_Seaweed_Wet_Stack"
    },
    {
      "x": 2,
      "y": 8,
      "z": -11,
      "name": "Plant_Seaweed_Wet_Stack"
    },
    {
      "x": 3,
      "y": 8,
      "z": -11,
      "name": "Plant_Seaweed_Wet_Stack"
    },
    {
      "x": 5,
      "y": 8,
      "z": -11,
      "name": "Plant_Seaweed_Wet_Stack"
    },
    {
      "x": 2,
      "y": 9,
      "z": -11,
      "name": "Plant_Seaweed_Wet_Stack"
    },
    {
      "x": 3,
      "y": 9,
      "z": -11,
      "name": "Plant_Seaweed_Wet_Stack"
    },
    {
      "x": 5,
      "y": 9,
      "z": -11,
      "name": "Plant_Seaweed_Wet_Stack"
    },
    {
      "x": 2,
      "y": 10,
      "z": -11,
      "name": "Plant_Seaweed_Wet_Stack"
    },
    {
      "x": 3,
      "y": 10,
      "z": -11,
      "name": "Plant_Seaweed_Wet_Stack"
    },
    {
      "x": 5,
      "y": 10,
      "z": -11,
      "name": "Plant_Seaweed_Wet_Stack"
    },
    {
      "x": 2,
      "y": 11,
      "z": -11,
      "name": "Plant_Seaweed_Wet_Stack"
    },
    {
      "x": 3,
      "y": 11,
      "z": -11,
      "name": "Plant_Seaweed_Wet_Stack"
    },
    {
      "x": 5,
      "y": 11,
      "z": -11,
      "name": "Plant_Seaweed_Wet_Stack"
    },
    {
      "x": 2,
      "y": 12,
      "z": -11,
      "name": "Plant_Seaweed_Wet_Stack"
    },
    {
      "x": 3,
      "y": 12,
      "z": -11,
      "name": "Plant_Seaweed_Wet_Stack"
    },
    {
      "x": 5,
      "y": 12,
      "z": -11,
      "name": "Plant_Seaweed_Wet_Stack"
    },
    {
      "x": 1,
      "y": 4,
      "z": -10,
      "name": "Plant_Moss_Block_Green"
    },
    {
      "x": 5,
      "y": 4,
      "z": -10,
      "name": "Plant_Moss_Block_Green"
    },
    {
      "x": 1,
      "y": 5,
      "z": -10,
      "name": "Plant_Seaweed_Wet_Stack"
    },
    {
      "x": 2,
      "y": 5,
      "z": -10,
      "name": "Plant_Moss_Block_Green"
    },
    {
      "x": 4,
      "y": 5,
      "z": -10,
      "name": "Plant_Moss_Block_Green"
    },
    {
      "x": 5,
      "y": 5,
      "z": -10,
      "name": "Plant_Moss_Block_Green"
    },
    {
      "x": 0,
      "y": 6,
      "z": -10,
      "name": "Plant_Moss_Block_Green"
    },
    {
      "x": 1,
      "y": 6,
      "z": -10,
      "name": "Plant_Seaweed_Wet_Stack"
    },
    {
      "x": 2,
      "y": 6,
      "z": -10,
      "name": "Plant_Moss_Block_Green"
    },
    {
      "x": 4,
      "y": 6,
      "z": -10,
      "name": "Plant_Seaweed_Wet_Stack"
    },
    {
      "x": 5,
      "y": 6,
      "z": -10,
      "name": "Plant_Moss_Block_Green"
    },
    {
      "x": 0,
      "y": 7,
      "z": -10,
      "name": "Plant_Moss_Block_Green"
    },
    {
      "x": 1,
      "y": 7,
      "z": -10,
      "name": "Plant_Seaweed_Wet_Stack"
    },
    {
      "x": 2,
      "y": 7,
      "z": -10,
      "name": "Plant_Seaweed_Wet_Stack"
    },
    {
      "x": 4,
      "y": 7,
      "z": -10,
      "name": "Plant_Seaweed_Wet_Stack"
    },
    {
      "x": 5,
      "y": 7,
      "z": -10,
      "name": "Plant_Moss_Block_Green"
    },
    {
      "x": 0,
      "y": 8,
      "z": -10,
      "name": "Plant_Seaweed_Wet_Stack"
    },
    {
      "x": 1,
      "y": 8,
      "z": -10,
      "name": "Plant_Seaweed_Wet_Stack"
    },
    {
      "x": 2,
      "y": 8,
      "z": -10,
      "name": "Plant_Seaweed_Wet_Stack"
    },
    {
      "x": 4,
      "y": 8,
      "z": -10,
      "name": "Plant_Seaweed_Wet_Stack"
    },
    {
      "x": 5,
      "y": 8,
      "z": -10,
      "name": "Plant_Seaweed_Wet_Stack"
    },
    {
      "x": 0,
      "y": 9,
      "z": -10,
      "name": "Plant_Seaweed_Wet_Stack"
    },
    {
      "x": 1,
      "y": 9,
      "z": -10,
      "name": "Plant_Seaweed_Wet_Stack"
    },
    {
      "x": 2,
      "y": 9,
      "z": -10,
      "name": "Plant_Seaweed_Wet_Stack"
    },
    {
      "x": 4,
      "y": 9,
      "z": -10,
      "name": "Plant_Seaweed_Wet_Stack"
    },
    {
      "x": 5,
      "y": 9,
      "z": -10,
      "name": "Plant_Seaweed_Wet_Stack"
    },
    {
      "x": 0,
      "y": 10,
      "z": -10,
      "name": "Plant_Seaweed_Wet_Stack"
    },
    {
      "x": 1,
      "y": 10,
      "z": -10,
      "name": "Plant_Seaweed_Wet_Stack"
    },
    {
      "x": 2,
      "y": 10,
      "z": -10,
      "name": "Plant_Seaweed_Wet_Stack"
    },
    {
      "x": 4,
      "y": 10,
      "z": -10,
      "name": "Plant_Seaweed_Wet_Stack"
    },
    {
      "x": 5,
      "y": 10,
      "z": -10,
      "name": "Plant_Seaweed_Wet_Stack"
    },
    {
      "x": 0,
      "y": 11,
      "z": -10,
      "name": "Plant_Seaweed_Wet_Stack"
    },
    {
      "x": 1,
      "y": 11,
      "z": -10,
      "name": "Plant_Seaweed_Wet_Stack"
    },
    {
      "x": 2,
      "y": 11,
      "z": -10,
      "name": "Plant_Seaweed_Wet_Stack"
    },
    {
      "x": 4,
      "y": 11,
      "z": -10,
      "name": "Plant_Seaweed_Wet_Stack"
    },
    {
      "x": 5,
      "y": 11,
      "z": -10,
      "name": "Plant_Seaweed_Wet_Stack"
    },
    {
      "x": 0,
      "y": 12,
      "z": -10,
      "name": "Plant_Seaweed_Wet_Stack"
    },
    {
      "x": 1,
      "y": 12,
      "z": -10,
      "name": "Plant_Seaweed_Wet_Stack"
    },
    {
      "x": 2,
      "y": 12,
      "z": -10,
      "name": "Plant_Seaweed_Wet_Stack"
    },
    {
      "x": 4,
      "y": 12,
      "z": -10,
      "name": "Plant_Seaweed_Wet_Stack"
    },
    {
      "x": 5,
      "y": 12,
      "z": -10,
      "name": "Plant_Seaweed_Wet_Stack"
    },
    {
      "x": 3,
      "y": 4,
      "z": -9,
      "name": "Plant_Moss_Block_Green"
    },
    {
      "x": 0,
      "y": 5,
      "z": -9,
      "name": "Plant_Moss_Block_Green"
    },
    {
      "x": 1,
      "y": 5,
      "z": -9,
      "name": "Plant_Moss_Block_Green"
    },
    {
      "x": 2,
      "y": 5,
      "z": -9,
      "name": "Plant_Moss_Block_Green"
    },
    {
      "x": 3,
      "y": 5,
      "z": -9,
      "name": "Plant_Seaweed_Wet_Stack"
    },
    {
      "x": 4,
      "y": 5,
      "z": -9,
      "name": "Plant_Moss_Block_Green"
    },
    {
      "x": 0,
      "y": 6,
      "z": -9,
      "name": "Plant_Moss_Block_Green"
    },
    {
      "x": 1,
      "y": 6,
      "z": -9,
      "name": "Plant_Moss_Block_Green"
    },
    {
      "x": 2,
      "y": 6,
      "z": -9,
      "name": "Plant_Seaweed_Wet_Stack"
    },
    {
      "x": 3,
      "y": 6,
      "z": -9,
      "name": "Plant_Seaweed_Wet_Stack"
    },
    {
      "x": 4,
      "y": 6,
      "z": -9,
      "name": "Plant_Seaweed_Wet_Stack"
    },
    {
      "x": 6,
      "y": 6,
      "z": -9,
      "name": "Plant_Moss_Block_Green"
    },
    {
      "x": 0,
      "y": 7,
      "z": -9,
      "name": "Plant_Seaweed_Wet_Stack"
    },
    {
      "x": 1,
      "y": 7,
      "z": -9,
      "name": "Plant_Seaweed_Wet_Stack"
    },
    {
      "x": 2,
      "y": 7,
      "z": -9,
      "name": "Plant_Seaweed_Wet_Stack"
    },
    {
      "x": 3,
      "y": 7,
      "z": -9,
      "name": "Plant_Seaweed_Wet_Stack"
    },
    {
      "x": 4,
      "y": 7,
      "z": -9,
      "name": "Plant_Seaweed_Wet_Stack"
    },
    {
      "x": 6,
      "y": 7,
      "z": -9,
      "name": "Plant_Moss_Block_Green"
    },
    {
      "x": 0,
      "y": 8,
      "z": -9,
      "name": "Plant_Seaweed_Wet_Stack"
    },
    {
      "x": 1,
      "y": 8,
      "z": -9,
      "name": "Plant_Seaweed_Wet_Stack"
    },
    {
      "x": 2,
      "y": 8,
      "z": -9,
      "name": "Plant_Seaweed_Wet_Stack"
    },
    {
      "x": 3,
      "y": 8,
      "z": -9,
      "name": "Plant_Seaweed_Wet_Stack"
    },
    {
      "x": 4,
      "y": 8,
      "z": -9,
      "name": "Plant_Seaweed_Wet_Stack"
    },
    {
      "x": 6,
      "y": 8,
      "z": -9,
      "name": "Plant_Seaweed_Wet_Stack"
    },
    {
      "x": 0,
      "y": 9,
      "z": -9,
      "name": "Plant_Seaweed_Wet_Stack"
    },
    {
      "x": 1,
      "y": 9,
      "z": -9,
      "name": "Plant_Seaweed_Wet_Stack"
    },
    {
      "x": 2,
      "y": 9,
      "z": -9,
      "name": "Plant_Seaweed_Wet_Stack"
    },
    {
      "x": 3,
      "y": 9,
      "z": -9,
      "name": "Plant_Seaweed_Wet_Stack"
    },
    {
      "x": 4,
      "y": 9,
      "z": -9,
      "name": "Plant_Seaweed_Wet_Stack"
    },
    {
      "x": 6,
      "y": 9,
      "z": -9,
      "name": "Plant_Seaweed_Wet_Stack"
    },
    {
      "x": 0,
      "y": 10,
      "z": -9,
      "name": "Plant_Seaweed_Wet_Stack"
    },
    {
      "x": 1,
      "y": 10,
      "z": -9,
      "name": "Plant_Seaweed_Wet_Stack"
    },
    {
      "x": 2,
      "y": 10,
      "z": -9,
      "name": "Plant_Seaweed_Wet_Stack"
    },
    {
      "x": 3,
      "y": 10,
      "z": -9,
      "name": "Plant_Seaweed_Wet_Stack"
    },
    {
      "x": 4,
      "y": 10,
      "z": -9,
      "name": "Plant_Seaweed_Wet_Stack"
    },
    {
      "x": 6,
      "y": 10,
      "z": -9,
      "name": "Plant_Seaweed_Wet_Stack"
    },
    {
      "x": 0,
      "y": 11,
      "z": -9,
      "name": "Plant_Seaweed_Wet_Stack"
    },
    {
      "x": 1,
      "y": 11,
      "z": -9,
      "name": "Plant_Seaweed_Wet_Stack"
    },
    {
      "x": 2,
      "y": 11,
      "z": -9,
      "name": "Plant_Seaweed_Wet_Stack"
    },
    {
      "x": 3,
      "y": 11,
      "z": -9,
      "name": "Plant_Seaweed_Wet_Stack"
    },
    {
      "x": 4,
      "y": 11,
      "z": -9,
      "name": "Plant_Seaweed_Wet_Stack"
    },
    {
      "x": 6,
      "y": 11,
      "z": -9,
      "name": "Plant_Seaweed_Wet_Stack"
    },
    {
      "x": 0,
      "y": 12,
      "z": -9,
      "name": "Plant_Seaweed_Wet_Stack"
    },
    {
      "x": 1,
      "y": 12,
      "z": -9,
      "name": "Plant_Seaweed_Wet_Stack"
    },
    {
      "x": 2,
      "y": 12,
      "z": -9,
      "name": "Plant_Seaweed_Wet_Stack"
    },
    {
      "x": 3,
      "y": 12,
      "z": -9,
      "name": "Plant_Seaweed_Wet_Stack"
    },
    {
      "x": 4,
      "y": 12,
      "z": -9,
      "name": "Plant_Seaweed_Wet_Stack"
    },
    {
      "x": 6,
      "y": 12,
      "z": -9,
      "name": "Plant_Seaweed_Wet_Stack"
    },
    {
      "x": 0,
      "y": 3,
      "z": -8,
      "name": "Plant_Moss_Block_Green"
    },
    {
      "x": 0,
      "y": 4,
      "z": -8,
      "name": "Plant_Moss_Block_Green"
    },
    {
      "x": 1,
      "y": 4,
      "z": -8,
      "name": "Plant_Moss_Block_Green"
    },
    {
      "x": 3,
      "y": 4,
      "z": -8,
      "name": "Wood_Spiral_Trunk_Full"
    },
    {
      "x": 4,
      "y": 4,
      "z": -8,
      "name": "Plant_Moss_Block_Green"
    },
    {
      "x": 6,
      "y": 4,
      "z": -8,
      "name": "Plant_Moss_Block_Green"
    },
    {
      "x": 0,
      "y": 5,
      "z": -8,
      "name": "Plant_Moss_Block_Green"
    },
    {
      "x": 1,
      "y": 5,
      "z": -8,
      "name": "Plant_Seaweed_Wet_Stack"
    },
    {
      "x": 2,
      "y": 5,
      "z": -8,
      "name": "Plant_Moss_Block_Green"
    },
    {
      "x": 3,
      "y": 5,
      "z": -8,
      "name": "Wood_Spiral_Trunk_Full"
    },
    {
      "x": 4,
      "y": 5,
      "z": -8,
      "name": "Plant_Moss_Block_Green"
    },
    {
      "x": 5,
      "y": 5,
      "z": -8,
      "name": "Plant_Moss_Block_Green"
    },
    {
      "x": 6,
      "y": 5,
      "z": -8,
      "name": "Plant_Seaweed_Wet_Stack"
    },
    {
      "x": 0,
      "y": 6,
      "z": -8,
      "name": "Plant_Moss_Block_Green"
    },
    {
      "x": 1,
      "y": 6,
      "z": -8,
      "name": "Plant_Seaweed_Wet_Stack"
    },
    {
      "x": 2,
      "y": 6,
      "z": -8,
      "name": "Plant_Seaweed_Wet_Stack"
    },
    {
      "x": 3,
      "y": 6,
      "z": -8,
      "name": "Plant_Moss_Block_Green"
    },
    {
      "x": 4,
      "y": 6,
      "z": -8,
      "name": "Plant_Seaweed_Wet_Stack"
    },
    {
      "x": 5,
      "y": 6,
      "z": -8,
      "name": "Plant_Moss_Block_Green"
    },
    {
      "x": 6,
      "y": 6,
      "z": -8,
      "name": "Plant_Seaweed_Wet_Stack"
    },
    {
      "x": 0,
      "y": 7,
      "z": -8,
      "name": "Plant_Seaweed_Wet_Stack"
    },
    {
      "x": 1,
      "y": 7,
      "z": -8,
      "name": "Plant_Seaweed_Wet_Stack"
    },
    {
      "x": 2,
      "y": 7,
      "z": -8,
      "name": "Plant_Seaweed_Wet_Stack"
    },
    {
      "x": 3,
      "y": 7,
      "z": -8,
      "name": "Plant_Moss_Block_Green"
    },
    {
      "x": 4,
      "y": 7,
      "z": -8,
      "name": "Plant_Seaweed_Wet_Stack"
    },
    {
      "x": 5,
      "y": 7,
      "z": -8,
      "name": "Plant_Moss_Block_Green"
    },
    {
      "x": 6,
      "y": 7,
      "z": -8,
      "name": "Plant_Seaweed_Wet_Stack"
    },
    {
      "x": 0,
      "y": 8,
      "z": -8,
      "name": "Plant_Seaweed_Wet_Stack"
    },
    {
      "x": 1,
      "y": 8,
      "z": -8,
      "name": "Plant_Seaweed_Wet_Stack"
    },
    {
      "x": 2,
      "y": 8,
      "z": -8,
      "name": "Plant_Seaweed_Wet_Stack"
    },
    {
      "x": 3,
      "y": 8,
      "z": -8,
      "name": "Plant_Seaweed_Wet_Stack"
    },
    {
      "x": 4,
      "y": 8,
      "z": -8,
      "name": "Plant_Seaweed_Wet_Stack"
    },
    {
      "x": 5,
      "y": 8,
      "z": -8,
      "name": "Plant_Moss_Block_Green"
    },
    {
      "x": 6,
      "y": 8,
      "z": -8,
      "name": "Plant_Seaweed_Wet_Stack"
    },
    {
      "x": 0,
      "y": 9,
      "z": -8,
      "name": "Plant_Seaweed_Wet_Stack"
    },
    {
      "x": 1,
      "y": 9,
      "z": -8,
      "name": "Plant_Seaweed_Wet_Stack"
    },
    {
      "x": 2,
      "y": 9,
      "z": -8,
      "name": "Plant_Seaweed_Wet_Stack"
    },
    {
      "x": 3,
      "y": 9,
      "z": -8,
      "name": "Plant_Seaweed_Wet_Stack"
    },
    {
      "x": 4,
      "y": 9,
      "z": -8,
      "name": "Plant_Seaweed_Wet_Stack"
    },
    {
      "x": 5,
      "y": 9,
      "z": -8,
      "name": "Plant_Seaweed_Wet_Stack"
    },
    {
      "x": 6,
      "y": 9,
      "z": -8,
      "name": "Plant_Seaweed_Wet_Stack"
    },
    {
      "x": 0,
      "y": 10,
      "z": -8,
      "name": "Plant_Seaweed_Wet_Stack"
    },
    {
      "x": 1,
      "y": 10,
      "z": -8,
      "name": "Plant_Seaweed_Wet_Stack"
    },
    {
      "x": 2,
      "y": 10,
      "z": -8,
      "name": "Plant_Seaweed_Wet_Stack"
    },
    {
      "x": 3,
      "y": 10,
      "z": -8,
      "name": "Plant_Seaweed_Wet_Stack"
    },
    {
      "x": 4,
      "y": 10,
      "z": -8,
      "name": "Plant_Seaweed_Wet_Stack"
    },
    {
      "x": 5,
      "y": 10,
      "z": -8,
      "name": "Plant_Seaweed_Wet_Stack"
    },
    {
      "x": 6,
      "y": 10,
      "z": -8,
      "name": "Plant_Seaweed_Wet_Stack"
    },
    {
      "x": 0,
      "y": 11,
      "z": -8,
      "name": "Plant_Seaweed_Wet_Stack"
    },
    {
      "x": 1,
      "y": 11,
      "z": -8,
      "name": "Plant_Seaweed_Wet_Stack"
    },
    {
      "x": 2,
      "y": 11,
      "z": -8,
      "name": "Plant_Seaweed_Wet_Stack"
    },
    {
      "x": 3,
      "y": 11,
      "z": -8,
      "name": "Plant_Seaweed_Wet_Stack"
    },
    {
      "x": 4,
      "y": 11,
      "z": -8,
      "name": "Plant_Seaweed_Wet_Stack"
    },
    {
      "x": 5,
      "y": 11,
      "z": -8,
      "name": "Plant_Seaweed_Wet_Stack"
    },
    {
      "x": 6,
      "y": 11,
      "z": -8,
      "name": "Plant_Seaweed_Wet_Stack"
    },
    {
      "x": 0,
      "y": 12,
      "z": -8,
      "name": "Plant_Seaweed_Wet_Stack"
    },
    {
      "x": 1,
      "y": 12,
      "z": -8,
      "name": "Plant_Seaweed_Wet_Stack"
    },
    {
      "x": 2,
      "y": 12,
      "z": -8,
      "name": "Plant_Seaweed_Wet_Stack"
    },
    {
      "x": 3,
      "y": 12,
      "z": -8,
      "name": "Plant_Seaweed_Wet_Stack"
    },
    {
      "x": 4,
      "y": 12,
      "z": -8,
      "name": "Plant_Seaweed_Wet_Stack"
    },
    {
      "x": 5,
      "y": 12,
      "z": -8,
      "name": "Plant_Seaweed_Wet_Stack"
    },
    {
      "x": 6,
      "y": 12,
      "z": -8,
      "name": "Plant_Seaweed_Wet_Stack"
    },
    {
      "x": 3,
      "y": 3,
      "z": -7,
      "name": "Wood_Spiral_Trunk_Full"
    },
    {
      "x": 3,
      "y": 4,
      "z": -7,
      "name": "Wood_Spiral_Trunk_Full"
    },
    {
      "x": 1,
      "y": 5,
      "z": -7,
      "name": "Plant_Moss_Block_Green"
    },
    {
      "x": 2,
      "y": 5,
      "z": -7,
      "name": "Plant_Moss_Block_Green"
    },
    {
      "x": 3,
      "y": 5,
      "z": -7,
      "name": "Plant_Moss_Block_Green"
    },
    {
      "x": 4,
      "y": 5,
      "z": -7,
      "name": "Plant_Moss_Block_Green"
    },
    {
      "x": 5,
      "y": 5,
      "z": -7,
      "name": "Plant_Moss_Block_Green"
    },
    {
      "x": 1,
      "y": 6,
      "z": -7,
      "name": "Plant_Moss_Block_Green"
    },
    {
      "x": 2,
      "y": 6,
      "z": -7,
      "name": "Plant_Moss_Block_Green"
    },
    {
      "x": 3,
      "y": 6,
      "z": -7,
      "name": "Plant_Seaweed_Wet_Stack"
    },
    {
      "x": 4,
      "y": 6,
      "z": -7,
      "name": "Plant_Moss_Block_Green"
    },
    {
      "x": 5,
      "y": 6,
      "z": -7,
      "name": "Plant_Seaweed_Wet_Stack"
    },
    {
      "x": 1,
      "y": 7,
      "z": -7,
      "name": "Plant_Moss_Block_Green"
    },
    {
      "x": 2,
      "y": 7,
      "z": -7,
      "name": "Plant_Seaweed_Wet_Stack"
    },
    {
      "x": 3,
      "y": 7,
      "z": -7,
      "name": "Plant_Seaweed_Wet_Stack"
    },
    {
      "x": 4,
      "y": 7,
      "z": -7,
      "name": "Plant_Seaweed_Wet_Stack"
    },
    {
      "x": 5,
      "y": 7,
      "z": -7,
      "name": "Plant_Seaweed_Wet_Stack"
    },
    {
      "x": 1,
      "y": 8,
      "z": -7,
      "name": "Plant_Seaweed_Wet_Stack"
    },
    {
      "x": 2,
      "y": 8,
      "z": -7,
      "name": "Plant_Seaweed_Wet_Stack"
    },
    {
      "x": 3,
      "y": 8,
      "z": -7,
      "name": "Plant_Seaweed_Wet_Stack"
    },
    {
      "x": 4,
      "y": 8,
      "z": -7,
      "name": "Plant_Seaweed_Wet_Stack"
    },
    {
      "x": 5,
      "y": 8,
      "z": -7,
      "name": "Plant_Seaweed_Wet_Stack"
    },
    {
      "x": 1,
      "y": 9,
      "z": -7,
      "name": "Plant_Seaweed_Wet_Stack"
    },
    {
      "x": 2,
      "y": 9,
      "z": -7,
      "name": "Plant_Seaweed_Wet_Stack"
    },
    {
      "x": 3,
      "y": 9,
      "z": -7,
      "name": "Plant_Seaweed_Wet_Stack"
    },
    {
      "x": 4,
      "y": 9,
      "z": -7,
      "name": "Plant_Seaweed_Wet_Stack"
    },
    {
      "x": 5,
      "y": 9,
      "z": -7,
      "name": "Plant_Seaweed_Wet_Stack"
    },
    {
      "x": 1,
      "y": 10,
      "z": -7,
      "name": "Plant_Seaweed_Wet_Stack"
    },
    {
      "x": 2,
      "y": 10,
      "z": -7,
      "name": "Plant_Seaweed_Wet_Stack"
    },
    {
      "x": 3,
      "y": 10,
      "z": -7,
      "name": "Plant_Seaweed_Wet_Stack"
    },
    {
      "x": 4,
      "y": 10,
      "z": -7,
      "name": "Plant_Seaweed_Wet_Stack"
    },
    {
      "x": 5,
      "y": 10,
      "z": -7,
      "name": "Plant_Seaweed_Wet_Stack"
    },
    {
      "x": 1,
      "y": 11,
      "z": -7,
      "name": "Plant_Seaweed_Wet_Stack"
    },
    {
      "x": 2,
      "y": 11,
      "z": -7,
      "name": "Plant_Seaweed_Wet_Stack"
    },
    {
      "x": 3,
      "y": 11,
      "z": -7,
      "name": "Plant_Seaweed_Wet_Stack"
    },
    {
      "x": 4,
      "y": 11,
      "z": -7,
      "name": "Plant_Seaweed_Wet_Stack"
    },
    {
      "x": 5,
      "y": 11,
      "z": -7,
      "name": "Plant_Seaweed_Wet_Stack"
    },
    {
      "x": 1,
      "y": 12,
      "z": -7,
      "name": "Plant_Seaweed_Wet_Stack"
    },
    {
      "x": 2,
      "y": 12,
      "z": -7,
      "name": "Plant_Seaweed_Wet_Stack"
    },
    {
      "x": 3,
      "y": 12,
      "z": -7,
      "name": "Plant_Seaweed_Wet_Stack"
    },
    {
      "x": 4,
      "y": 12,
      "z": -7,
      "name": "Plant_Seaweed_Wet_Stack"
    },
    {
      "x": 5,
      "y": 12,
      "z": -7,
      "name": "Plant_Seaweed_Wet_Stack"
    },
    {
      "x": 1,
      "y": 3,
      "z": -6,
      "name": "Plant_Moss_Block_Green"
    },
    {
      "x": 2,
      "y": 3,
      "z": -6,
      "name": "Wood_Spiral_Trunk_Full"
    },
    {
      "x": 3,
      "y": 3,
      "z": -6,
      "name": "Wood_Spiral_Trunk_Full"
    },
    {
      "x": 0,
      "y": 4,
      "z": -6,
      "name": "Plant_Moss_Block_Green"
    },
    {
      "x": 1,
      "y": 4,
      "z": -6,
      "name": "Plant_Seaweed_Wet_Stack"
    },
    {
      "x": 0,
      "y": 5,
      "z": -6,
      "name": "Plant_Moss_Block_Green"
    },
    {
      "x": 1,
      "y": 5,
      "z": -6,
      "name": "Plant_Seaweed_Wet_Stack"
    },
    {
      "x": 4,
      "y": 5,
      "z": -6,
      "name": "Plant_Moss_Block_Green"
    },
    {
      "x": 0,
      "y": 6,
      "z": -6,
      "name": "Plant_Moss_Block_Green"
    },
    {
      "x": 1,
      "y": 6,
      "z": -6,
      "name": "Plant_Seaweed_Wet_Stack"
    },
    {
      "x": 4,
      "y": 6,
      "z": -6,
      "name": "Plant_Moss_Block_Green"
    },
    {
      "x": 5,
      "y": 6,
      "z": -6,
      "name": "Plant_Moss_Block_Green"
    },
    {
      "x": 0,
      "y": 7,
      "z": -6,
      "name": "Plant_Moss_Block_Green"
    },
    {
      "x": 1,
      "y": 7,
      "z": -6,
      "name": "Plant_Seaweed_Wet_Stack"
    },
    {
      "x": 3,
      "y": 7,
      "z": -6,
      "name": "Plant_Moss_Block_Green"
    },
    {
      "x": 4,
      "y": 7,
      "z": -6,
      "name": "Plant_Seaweed_Wet_Stack"
    },
    {
      "x": 5,
      "y": 7,
      "z": -6,
      "name": "Plant_Moss_Block_Green"
    },
    {
      "x": 6,
      "y": 7,
      "z": -6,
      "name": "Plant_Moss_Block_Green"
    },
    {
      "x": 0,
      "y": 8,
      "z": -6,
      "name": "Plant_Seaweed_Wet_Stack"
    },
    {
      "x": 1,
      "y": 8,
      "z": -6,
      "name": "Plant_Seaweed_Wet_Stack"
    },
    {
      "x": 3,
      "y": 8,
      "z": -6,
      "name": "Plant_Seaweed_Wet_Stack"
    },
    {
      "x": 4,
      "y": 8,
      "z": -6,
      "name": "Plant_Seaweed_Wet_Stack"
    },
    {
      "x": 5,
      "y": 8,
      "z": -6,
      "name": "Plant_Seaweed_Wet_Stack"
    },
    {
      "x": 6,
      "y": 8,
      "z": -6,
      "name": "Plant_Seaweed_Wet_Stack"
    },
    {
      "x": 0,
      "y": 9,
      "z": -6,
      "name": "Plant_Seaweed_Wet_Stack"
    },
    {
      "x": 1,
      "y": 9,
      "z": -6,
      "name": "Plant_Seaweed_Wet_Stack"
    },
    {
      "x": 3,
      "y": 9,
      "z": -6,
      "name": "Plant_Seaweed_Wet_Stack"
    },
    {
      "x": 4,
      "y": 9,
      "z": -6,
      "name": "Plant_Seaweed_Wet_Stack"
    },
    {
      "x": 5,
      "y": 9,
      "z": -6,
      "name": "Plant_Seaweed_Wet_Stack"
    },
    {
      "x": 6,
      "y": 9,
      "z": -6,
      "name": "Plant_Seaweed_Wet_Stack"
    },
    {
      "x": 0,
      "y": 10,
      "z": -6,
      "name": "Plant_Seaweed_Wet_Stack"
    },
    {
      "x": 1,
      "y": 10,
      "z": -6,
      "name": "Plant_Seaweed_Wet_Stack"
    },
    {
      "x": 3,
      "y": 10,
      "z": -6,
      "name": "Plant_Seaweed_Wet_Stack"
    },
    {
      "x": 4,
      "y": 10,
      "z": -6,
      "name": "Plant_Seaweed_Wet_Stack"
    },
    {
      "x": 5,
      "y": 10,
      "z": -6,
      "name": "Plant_Seaweed_Wet_Stack"
    },
    {
      "x": 6,
      "y": 10,
      "z": -6,
      "name": "Plant_Seaweed_Wet_Stack"
    },
    {
      "x": 0,
      "y": 11,
      "z": -6,
      "name": "Plant_Seaweed_Wet_Stack"
    },
    {
      "x": 1,
      "y": 11,
      "z": -6,
      "name": "Plant_Seaweed_Wet_Stack"
    },
    {
      "x": 3,
      "y": 11,
      "z": -6,
      "name": "Plant_Seaweed_Wet_Stack"
    },
    {
      "x": 4,
      "y": 11,
      "z": -6,
      "name": "Plant_Seaweed_Wet_Stack"
    },
    {
      "x": 5,
      "y": 11,
      "z": -6,
      "name": "Plant_Seaweed_Wet_Stack"
    },
    {
      "x": 6,
      "y": 11,
      "z": -6,
      "name": "Plant_Seaweed_Wet_Stack"
    },
    {
      "x": 0,
      "y": 12,
      "z": -6,
      "name": "Plant_Seaweed_Wet_Stack"
    },
    {
      "x": 1,
      "y": 12,
      "z": -6,
      "name": "Plant_Seaweed_Wet_Stack"
    },
    {
      "x": 3,
      "y": 12,
      "z": -6,
      "name": "Plant_Seaweed_Wet_Stack"
    },
    {
      "x": 4,
      "y": 12,
      "z": -6,
      "name": "Plant_Seaweed_Wet_Stack"
    },
    {
      "x": 5,
      "y": 12,
      "z": -6,
      "name": "Plant_Seaweed_Wet_Stack"
    },
    {
      "x": 6,
      "y": 12,
      "z": -6,
      "name": "Plant_Seaweed_Wet_Stack"
    },
    {
      "x": 2,
      "y": 2,
      "z": -5,
      "name": "Wood_Spiral_Trunk_Full"
    },
    {
      "x": 2,
      "y": 3,
      "z": -5,
      "name": "Wood_Spiral_Trunk_Full"
    },
    {
      "x": 0,
      "y": 4,
      "z": -5,
      "name": "Plant_Moss_Block_Green"
    },
    {
      "x": 0,
      "y": 5,
      "z": -5,
      "name": "Plant_Seaweed_Wet_Stack"
    },
    {
      "x": 4,
      "y": 5,
      "z": -5,
      "name": "Plant_Moss_Block_Green"
    },
    {
      "x": 0,
      "y": 6,
      "z": -5,
      "name": "Plant_Seaweed_Wet_Stack"
    },
    {
      "x": 4,
      "y": 6,
      "z": -5,
      "name": "Plant_Seaweed_Wet_Stack"
    },
    {
      "x": 5,
      "y": 6,
      "z": -5,
      "name": "Plant_Moss_Block_Green"
    },
    {
      "x": 6,
      "y": 6,
      "z": -5,
      "name": "Plant_Moss_Block_Green"
    },
    {
      "x": 8,
      "y": 6,
      "z": -5,
      "name": "Plant_Moss_Block_Green"
    },
    {
      "x": 0,
      "y": 7,
      "z": -5,
      "name": "Plant_Seaweed_Wet_Stack"
    },
    {
      "x": 3,
      "y": 7,
      "z": -5,
      "name": "Plant_Moss_Block_Green"
    },
    {
      "x": 4,
      "y": 7,
      "z": -5,
      "name": "Plant_Seaweed_Wet_Stack"
    },
    {
      "x": 5,
      "y": 7,
      "z": -5,
      "name": "Plant_Seaweed_Wet_Stack"
    },
    {
      "x": 6,
      "y": 7,
      "z": -5,
      "name": "Plant_Moss_Block_Green"
    },
    {
      "x": 8,
      "y": 7,
      "z": -5,
      "name": "Plant_Seaweed_Wet_Stack"
    },
    {
      "x": 0,
      "y": 8,
      "z": -5,
      "name": "Plant_Seaweed_Wet_Stack"
    },
    {
      "x": 3,
      "y": 8,
      "z": -5,
      "name": "Plant_Seaweed_Wet_Stack"
    },
    {
      "x": 4,
      "y": 8,
      "z": -5,
      "name": "Plant_Seaweed_Wet_Stack"
    },
    {
      "x": 5,
      "y": 8,
      "z": -5,
      "name": "Plant_Seaweed_Wet_Stack"
    },
    {
      "x": 6,
      "y": 8,
      "z": -5,
      "name": "Plant_Seaweed_Wet_Stack"
    },
    {
      "x": 8,
      "y": 8,
      "z": -5,
      "name": "Plant_Seaweed_Wet_Stack"
    },
    {
      "x": 0,
      "y": 9,
      "z": -5,
      "name": "Plant_Seaweed_Wet_Stack"
    },
    {
      "x": 3,
      "y": 9,
      "z": -5,
      "name": "Plant_Seaweed_Wet_Stack"
    },
    {
      "x": 4,
      "y": 9,
      "z": -5,
      "name": "Plant_Seaweed_Wet_Stack"
    },
    {
      "x": 5,
      "y": 9,
      "z": -5,
      "name": "Plant_Seaweed_Wet_Stack"
    },
    {
      "x": 6,
      "y": 9,
      "z": -5,
      "name": "Plant_Seaweed_Wet_Stack"
    },
    {
      "x": 8,
      "y": 9,
      "z": -5,
      "name": "Plant_Seaweed_Wet_Stack"
    },
    {
      "x": 0,
      "y": 10,
      "z": -5,
      "name": "Plant_Seaweed_Wet_Stack"
    },
    {
      "x": 3,
      "y": 10,
      "z": -5,
      "name": "Plant_Seaweed_Wet_Stack"
    },
    {
      "x": 4,
      "y": 10,
      "z": -5,
      "name": "Plant_Seaweed_Wet_Stack"
    },
    {
      "x": 5,
      "y": 10,
      "z": -5,
      "name": "Plant_Seaweed_Wet_Stack"
    },
    {
      "x": 6,
      "y": 10,
      "z": -5,
      "name": "Plant_Seaweed_Wet_Stack"
    },
    {
      "x": 8,
      "y": 10,
      "z": -5,
      "name": "Plant_Seaweed_Wet_Stack"
    },
    {
      "x": 0,
      "y": 11,
      "z": -5,
      "name": "Plant_Seaweed_Wet_Stack"
    },
    {
      "x": 3,
      "y": 11,
      "z": -5,
      "name": "Plant_Seaweed_Wet_Stack"
    },
    {
      "x": 4,
      "y": 11,
      "z": -5,
      "name": "Plant_Seaweed_Wet_Stack"
    },
    {
      "x": 5,
      "y": 11,
      "z": -5,
      "name": "Plant_Seaweed_Wet_Stack"
    },
    {
      "x": 6,
      "y": 11,
      "z": -5,
      "name": "Plant_Seaweed_Wet_Stack"
    },
    {
      "x": 8,
      "y": 11,
      "z": -5,
      "name": "Plant_Seaweed_Wet_Stack"
    },
    {
      "x": 0,
      "y": 12,
      "z": -5,
      "name": "Plant_Seaweed_Wet_Stack"
    },
    {
      "x": 3,
      "y": 12,
      "z": -5,
      "name": "Plant_Seaweed_Wet_Stack"
    },
    {
      "x": 4,
      "y": 12,
      "z": -5,
      "name": "Plant_Seaweed_Wet_Stack"
    },
    {
      "x": 5,
      "y": 12,
      "z": -5,
      "name": "Plant_Seaweed_Wet_Stack"
    },
    {
      "x": 6,
      "y": 12,
      "z": -5,
      "name": "Plant_Seaweed_Wet_Stack"
    },
    {
      "x": 8,
      "y": 12,
      "z": -5,
      "name": "Plant_Seaweed_Wet_Stack"
    },
    {
      "x": 0,
      "y": 2,
      "z": -4,
      "name": "Wood_Spiral_Trunk_Full"
    },
    {
      "x": 2,
      "y": 2,
      "z": -4,
      "name": "Wood_Spiral_Trunk_Full"
    },
    {
      "x": 0,
      "y": 3,
      "z": -4,
      "name": "Wood_Spiral_Trunk_Full"
    },
    {
      "x": 4,
      "y": 4,
      "z": -4,
      "name": "Plant_Moss_Block_Green"
    },
    {
      "x": 8,
      "y": 4,
      "z": -4,
      "name": "Plant_Moss_Block_Green"
    },
    {
      "x": 0,
      "y": 5,
      "z": -4,
      "name": "Plant_Moss_Block_Green"
    },
    {
      "x": 4,
      "y": 5,
      "z": -4,
      "name": "Plant_Seaweed_Wet_Stack"
    },
    {
      "x": 5,
      "y": 5,
      "z": -4,
      "name": "Plant_Moss_Block_Green"
    },
    {
      "x": 7,
      "y": 5,
      "z": -4,
      "name": "Plant_Moss_Block_Green"
    },
    {
      "x": 8,
      "y": 5,
      "z": -4,
      "name": "Plant_Moss_Block_Green"
    },
    {
      "x": 0,
      "y": 6,
      "z": -4,
      "name": "Plant_Moss_Block_Green"
    },
    {
      "x": 1,
      "y": 6,
      "z": -4,
      "name": "Plant_Moss_Block_Green"
    },
    {
      "x": 3,
      "y": 6,
      "z": -4,
      "name": "Plant_Moss_Block_Green"
    },
    {
      "x": 4,
      "y": 6,
      "z": -4,
      "name": "Plant_Seaweed_Wet_Stack"
    },
    {
      "x": 5,
      "y": 6,
      "z": -4,
      "name": "Plant_Moss_Block_Green"
    },
    {
      "x": 7,
      "y": 6,
      "z": -4,
      "name": "Plant_Seaweed_Wet_Stack"
    },
    {
      "x": 8,
      "y": 6,
      "z": -4,
      "name": "Plant_Moss_Block_Green"
    },
    {
      "x": 0,
      "y": 7,
      "z": -4,
      "name": "Plant_Seaweed_Wet_Stack"
    },
    {
      "x": 1,
      "y": 7,
      "z": -4,
      "name": "Plant_Seaweed_Wet_Stack"
    },
    {
      "x": 3,
      "y": 7,
      "z": -4,
      "name": "Plant_Moss_Block_Green"
    },
    {
      "x": 4,
      "y": 7,
      "z": -4,
      "name": "Plant_Seaweed_Wet_Stack"
    },
    {
      "x": 5,
      "y": 7,
      "z": -4,
      "name": "Plant_Seaweed_Wet_Stack"
    },
    {
      "x": 7,
      "y": 7,
      "z": -4,
      "name": "Plant_Seaweed_Wet_Stack"
    },
    {
      "x": 8,
      "y": 7,
      "z": -4,
      "name": "Plant_Moss_Block_Green"
    },
    {
      "x": 0,
      "y": 8,
      "z": -4,
      "name": "Plant_Seaweed_Wet_Stack"
    },
    {
      "x": 1,
      "y": 8,
      "z": -4,
      "name": "Plant_Seaweed_Wet_Stack"
    },
    {
      "x": 3,
      "y": 8,
      "z": -4,
      "name": "Plant_Seaweed_Wet_Stack"
    },
    {
      "x": 4,
      "y": 8,
      "z": -4,
      "name": "Plant_Seaweed_Wet_Stack"
    },
    {
      "x": 5,
      "y": 8,
      "z": -4,
      "name": "Plant_Seaweed_Wet_Stack"
    },
    {
      "x": 7,
      "y": 8,
      "z": -4,
      "name": "Plant_Seaweed_Wet_Stack"
    },
    {
      "x": 8,
      "y": 8,
      "z": -4,
      "name": "Plant_Seaweed_Wet_Stack"
    },
    {
      "x": 0,
      "y": 9,
      "z": -4,
      "name": "Plant_Seaweed_Wet_Stack"
    },
    {
      "x": 1,
      "y": 9,
      "z": -4,
      "name": "Plant_Seaweed_Wet_Stack"
    },
    {
      "x": 3,
      "y": 9,
      "z": -4,
      "name": "Plant_Seaweed_Wet_Stack"
    },
    {
      "x": 4,
      "y": 9,
      "z": -4,
      "name": "Plant_Seaweed_Wet_Stack"
    },
    {
      "x": 5,
      "y": 9,
      "z": -4,
      "name": "Plant_Seaweed_Wet_Stack"
    },
    {
      "x": 7,
      "y": 9,
      "z": -4,
      "name": "Plant_Seaweed_Wet_Stack"
    },
    {
      "x": 8,
      "y": 9,
      "z": -4,
      "name": "Plant_Seaweed_Wet_Stack"
    },
    {
      "x": 0,
      "y": 10,
      "z": -4,
      "name": "Plant_Seaweed_Wet_Stack"
    },
    {
      "x": 1,
      "y": 10,
      "z": -4,
      "name": "Plant_Seaweed_Wet_Stack"
    },
    {
      "x": 3,
      "y": 10,
      "z": -4,
      "name": "Plant_Seaweed_Wet_Stack"
    },
    {
      "x": 4,
      "y": 10,
      "z": -4,
      "name": "Plant_Seaweed_Wet_Stack"
    },
    {
      "x": 5,
      "y": 10,
      "z": -4,
      "name": "Plant_Seaweed_Wet_Stack"
    },
    {
      "x": 7,
      "y": 10,
      "z": -4,
      "name": "Plant_Seaweed_Wet_Stack"
    },
    {
      "x": 8,
      "y": 10,
      "z": -4,
      "name": "Plant_Seaweed_Wet_Stack"
    },
    {
      "x": 0,
      "y": 11,
      "z": -4,
      "name": "Plant_Seaweed_Wet_Stack"
    },
    {
      "x": 1,
      "y": 11,
      "z": -4,
      "name": "Plant_Seaweed_Wet_Stack"
    },
    {
      "x": 3,
      "y": 11,
      "z": -4,
      "name": "Plant_Seaweed_Wet_Stack"
    },
    {
      "x": 4,
      "y": 11,
      "z": -4,
      "name": "Plant_Seaweed_Wet_Stack"
    },
    {
      "x": 5,
      "y": 11,
      "z": -4,
      "name": "Plant_Seaweed_Wet_Stack"
    },
    {
      "x": 7,
      "y": 11,
      "z": -4,
      "name": "Plant_Seaweed_Wet_Stack"
    },
    {
      "x": 8,
      "y": 11,
      "z": -4,
      "name": "Plant_Seaweed_Wet_Stack"
    },
    {
      "x": 0,
      "y": 12,
      "z": -4,
      "name": "Plant_Seaweed_Wet_Stack"
    },
    {
      "x": 1,
      "y": 12,
      "z": -4,
      "name": "Plant_Seaweed_Wet_Stack"
    },
    {
      "x": 3,
      "y": 12,
      "z": -4,
      "name": "Plant_Seaweed_Wet_Stack"
    },
    {
      "x": 4,
      "y": 12,
      "z": -4,
      "name": "Plant_Seaweed_Wet_Stack"
    },
    {
      "x": 5,
      "y": 12,
      "z": -4,
      "name": "Plant_Seaweed_Wet_Stack"
    },
    {
      "x": 7,
      "y": 12,
      "z": -4,
      "name": "Plant_Seaweed_Wet_Stack"
    },
    {
      "x": 8,
      "y": 12,
      "z": -4,
      "name": "Plant_Seaweed_Wet_Stack"
    },
    {
      "x": 0,
      "y": 2,
      "z": -3,
      "name": "Wood_Spiral_Trunk_Full"
    },
    {
      "x": 1,
      "y": 2,
      "z": -3,
      "name": "Wood_Spiral_Trunk_Full"
    },
    {
      "x": 2,
      "y": 2,
      "z": -3,
      "name": "Wood_Spiral_Trunk_Full"
    },
    {
      "x": 6,
      "y": 4,
      "z": -3,
      "name": "Plant_Moss_Block_Green"
    },
    {
      "x": 4,
      "y": 5,
      "z": -3,
      "name": "Plant_Moss_Block_Green"
    },
    {
      "x": 5,
      "y": 5,
      "z": -3,
      "name": "Plant_Moss_Block_Green"
    },
    {
      "x": 6,
      "y": 5,
      "z": -3,
      "name": "Plant_Seaweed_Wet_Stack"
    },
    {
      "x": 7,
      "y": 5,
      "z": -3,
      "name": "Plant_Moss_Block_Green"
    },
    {
      "x": 3,
      "y": 6,
      "z": -3,
      "name": "Plant_Moss_Block_Green"
    },
    {
      "x": 4,
      "y": 6,
      "z": -3,
      "name": "Plant_Moss_Block_Green"
    },
    {
      "x": 5,
      "y": 6,
      "z": -3,
      "name": "Plant_Seaweed_Wet_Stack"
    },
    {
      "x": 6,
      "y": 6,
      "z": -3,
      "name": "Plant_Seaweed_Wet_Stack"
    },
    {
      "x": 7,
      "y": 6,
      "z": -3,
      "name": "Plant_Seaweed_Wet_Stack"
    },
    {
      "x": 9,
      "y": 6,
      "z": -3,
      "name": "Plant_Moss_Block_Green"
    },
    {
      "x": 3,
      "y": 7,
      "z": -3,
      "name": "Plant_Seaweed_Wet_Stack"
    },
    {
      "x": 4,
      "y": 7,
      "z": -3,
      "name": "Plant_Seaweed_Wet_Stack"
    },
    {
      "x": 5,
      "y": 7,
      "z": -3,
      "name": "Plant_Seaweed_Wet_Stack"
    },
    {
      "x": 6,
      "y": 7,
      "z": -3,
      "name": "Plant_Seaweed_Wet_Stack"
    },
    {
      "x": 7,
      "y": 7,
      "z": -3,
      "name": "Plant_Seaweed_Wet_Stack"
    },
    {
      "x": 9,
      "y": 7,
      "z": -3,
      "name": "Plant_Moss_Block_Green"
    },
    {
      "x": 3,
      "y": 8,
      "z": -3,
      "name": "Plant_Seaweed_Wet_Stack"
    },
    {
      "x": 4,
      "y": 8,
      "z": -3,
      "name": "Plant_Seaweed_Wet_Stack"
    },
    {
      "x": 5,
      "y": 8,
      "z": -3,
      "name": "Plant_Seaweed_Wet_Stack"
    },
    {
      "x": 6,
      "y": 8,
      "z": -3,
      "name": "Plant_Seaweed_Wet_Stack"
    },
    {
      "x": 7,
      "y": 8,
      "z": -3,
      "name": "Plant_Seaweed_Wet_Stack"
    },
    {
      "x": 9,
      "y": 8,
      "z": -3,
      "name": "Plant_Seaweed_Wet_Stack"
    },
    {
      "x": 3,
      "y": 9,
      "z": -3,
      "name": "Plant_Seaweed_Wet_Stack"
    },
    {
      "x": 4,
      "y": 9,
      "z": -3,
      "name": "Plant_Seaweed_Wet_Stack"
    },
    {
      "x": 5,
      "y": 9,
      "z": -3,
      "name": "Plant_Seaweed_Wet_Stack"
    },
    {
      "x": 6,
      "y": 9,
      "z": -3,
      "name": "Plant_Seaweed_Wet_Stack"
    },
    {
      "x": 7,
      "y": 9,
      "z": -3,
      "name": "Plant_Seaweed_Wet_Stack"
    },
    {
      "x": 9,
      "y": 9,
      "z": -3,
      "name": "Plant_Seaweed_Wet_Stack"
    },
    {
      "x": 3,
      "y": 10,
      "z": -3,
      "name": "Plant_Seaweed_Wet_Stack"
    },
    {
      "x": 4,
      "y": 10,
      "z": -3,
      "name": "Plant_Seaweed_Wet_Stack"
    },
    {
      "x": 5,
      "y": 10,
      "z": -3,
      "name": "Plant_Seaweed_Wet_Stack"
    },
    {
      "x": 6,
      "y": 10,
      "z": -3,
      "name": "Plant_Seaweed_Wet_Stack"
    },
    {
      "x": 7,
      "y": 10,
      "z": -3,
      "name": "Plant_Seaweed_Wet_Stack"
    },
    {
      "x": 9,
      "y": 10,
      "z": -3,
      "name": "Plant_Seaweed_Wet_Stack"
    },
    {
      "x": 3,
      "y": 11,
      "z": -3,
      "name": "Plant_Seaweed_Wet_Stack"
    },
    {
      "x": 4,
      "y": 11,
      "z": -3,
      "name": "Plant_Seaweed_Wet_Stack"
    },
    {
      "x": 5,
      "y": 11,
      "z": -3,
      "name": "Plant_Seaweed_Wet_Stack"
    },
    {
      "x": 6,
      "y": 11,
      "z": -3,
      "name": "Plant_Seaweed_Wet_Stack"
    },
    {
      "x": 7,
      "y": 11,
      "z": -3,
      "name": "Plant_Seaweed_Wet_Stack"
    },
    {
      "x": 9,
      "y": 11,
      "z": -3,
      "name": "Plant_Seaweed_Wet_Stack"
    },
    {
      "x": 3,
      "y": 12,
      "z": -3,
      "name": "Plant_Seaweed_Wet_Stack"
    },
    {
      "x": 4,
      "y": 12,
      "z": -3,
      "name": "Plant_Seaweed_Wet_Stack"
    },
    {
      "x": 5,
      "y": 12,
      "z": -3,
      "name": "Plant_Seaweed_Wet_Stack"
    },
    {
      "x": 6,
      "y": 12,
      "z": -3,
      "name": "Plant_Seaweed_Wet_Stack"
    },
    {
      "x": 7,
      "y": 12,
      "z": -3,
      "name": "Plant_Seaweed_Wet_Stack"
    },
    {
      "x": 9,
      "y": 12,
      "z": -3,
      "name": "Plant_Seaweed_Wet_Stack"
    },
    {
      "x": 1,
      "y": 2,
      "z": -2,
      "name": "Wood_Spiral_Trunk_Full"
    },
    {
      "x": 2,
      "y": 2,
      "z": -2,
      "name": "Wood_Spiral_Trunk_Full"
    },
    {
      "x": 5,
      "y": 3,
      "z": -2,
      "name": "Wood_Spiral_Trunk_Full"
    },
    {
      "x": 6,
      "y": 3,
      "z": -2,
      "name": "Wood_Spiral_Trunk_Full"
    },
    {
      "x": 4,
      "y": 4,
      "z": -2,
      "name": "Plant_Moss_Block_Green"
    },
    {
      "x": 6,
      "y": 4,
      "z": -2,
      "name": "Wood_Spiral_Trunk_Full"
    },
    {
      "x": 7,
      "y": 4,
      "z": -2,
      "name": "Plant_Moss_Block_Green"
    },
    {
      "x": 9,
      "y": 4,
      "z": -2,
      "name": "Plant_Moss_Block_Green"
    },
    {
      "x": 4,
      "y": 5,
      "z": -2,
      "name": "Plant_Seaweed_Wet_Stack"
    },
    {
      "x": 5,
      "y": 5,
      "z": -2,
      "name": "Plant_Moss_Block_Green"
    },
    {
      "x": 6,
      "y": 5,
      "z": -2,
      "name": "Wood_Spiral_Trunk_Full"
    },
    {
      "x": 7,
      "y": 5,
      "z": -2,
      "name": "Plant_Moss_Block_Green"
    },
    {
      "x": 8,
      "y": 5,
      "z": -2,
      "name": "Plant_Moss_Block_Green"
    },
    {
      "x": 9,
      "y": 5,
      "z": -2,
      "name": "Plant_Seaweed_Wet_Stack"
    },
    {
      "x": 4,
      "y": 6,
      "z": -2,
      "name": "Plant_Seaweed_Wet_Stack"
    },
    {
      "x": 5,
      "y": 6,
      "z": -2,
      "name": "Plant_Seaweed_Wet_Stack"
    },
    {
      "x": 6,
      "y": 6,
      "z": -2,
      "name": "Plant_Moss_Block_Green"
    },
    {
      "x": 7,
      "y": 6,
      "z": -2,
      "name": "Plant_Seaweed_Wet_Stack"
    },
    {
      "x": 8,
      "y": 6,
      "z": -2,
      "name": "Plant_Moss_Block_Green"
    },
    {
      "x": 9,
      "y": 6,
      "z": -2,
      "name": "Plant_Seaweed_Wet_Stack"
    },
    {
      "x": 4,
      "y": 7,
      "z": -2,
      "name": "Plant_Seaweed_Wet_Stack"
    },
    {
      "x": 5,
      "y": 7,
      "z": -2,
      "name": "Plant_Seaweed_Wet_Stack"
    },
    {
      "x": 6,
      "y": 7,
      "z": -2,
      "name": "Plant_Moss_Block_Green"
    },
    {
      "x": 7,
      "y": 7,
      "z": -2,
      "name": "Plant_Seaweed_Wet_Stack"
    },
    {
      "x": 8,
      "y": 7,
      "z": -2,
      "name": "Plant_Moss_Block_Green"
    },
    {
      "x": 9,
      "y": 7,
      "z": -2,
      "name": "Plant_Seaweed_Wet_Stack"
    },
    {
      "x": 4,
      "y": 8,
      "z": -2,
      "name": "Plant_Seaweed_Wet_Stack"
    },
    {
      "x": 5,
      "y": 8,
      "z": -2,
      "name": "Plant_Seaweed_Wet_Stack"
    },
    {
      "x": 6,
      "y": 8,
      "z": -2,
      "name": "Plant_Seaweed_Wet_Stack"
    },
    {
      "x": 7,
      "y": 8,
      "z": -2,
      "name": "Plant_Seaweed_Wet_Stack"
    },
    {
      "x": 8,
      "y": 8,
      "z": -2,
      "name": "Plant_Moss_Block_Green"
    },
    {
      "x": 9,
      "y": 8,
      "z": -2,
      "name": "Plant_Seaweed_Wet_Stack"
    },
    {
      "x": 4,
      "y": 9,
      "z": -2,
      "name": "Plant_Seaweed_Wet_Stack"
    },
    {
      "x": 5,
      "y": 9,
      "z": -2,
      "name": "Plant_Seaweed_Wet_Stack"
    },
    {
      "x": 6,
      "y": 9,
      "z": -2,
      "name": "Plant_Seaweed_Wet_Stack"
    },
    {
      "x": 7,
      "y": 9,
      "z": -2,
      "name": "Plant_Seaweed_Wet_Stack"
    },
    {
      "x": 8,
      "y": 9,
      "z": -2,
      "name": "Plant_Seaweed_Wet_Stack"
    },
    {
      "x": 9,
      "y": 9,
      "z": -2,
      "name": "Plant_Seaweed_Wet_Stack"
    },
    {
      "x": 4,
      "y": 10,
      "z": -2,
      "name": "Plant_Seaweed_Wet_Stack"
    },
    {
      "x": 5,
      "y": 10,
      "z": -2,
      "name": "Plant_Seaweed_Wet_Stack"
    },
    {
      "x": 6,
      "y": 10,
      "z": -2,
      "name": "Plant_Seaweed_Wet_Stack"
    },
    {
      "x": 7,
      "y": 10,
      "z": -2,
      "name": "Plant_Seaweed_Wet_Stack"
    },
    {
      "x": 8,
      "y": 10,
      "z": -2,
      "name": "Plant_Seaweed_Wet_Stack"
    },
    {
      "x": 9,
      "y": 10,
      "z": -2,
      "name": "Plant_Seaweed_Wet_Stack"
    },
    {
      "x": 4,
      "y": 11,
      "z": -2,
      "name": "Plant_Seaweed_Wet_Stack"
    },
    {
      "x": 5,
      "y": 11,
      "z": -2,
      "name": "Plant_Seaweed_Wet_Stack"
    },
    {
      "x": 6,
      "y": 11,
      "z": -2,
      "name": "Plant_Seaweed_Wet_Stack"
    },
    {
      "x": 7,
      "y": 11,
      "z": -2,
      "name": "Plant_Seaweed_Wet_Stack"
    },
    {
      "x": 8,
      "y": 11,
      "z": -2,
      "name": "Plant_Seaweed_Wet_Stack"
    },
    {
      "x": 9,
      "y": 11,
      "z": -2,
      "name": "Plant_Seaweed_Wet_Stack"
    },
    {
      "x": 4,
      "y": 12,
      "z": -2,
      "name": "Plant_Seaweed_Wet_Stack"
    },
    {
      "x": 5,
      "y": 12,
      "z": -2,
      "name": "Plant_Seaweed_Wet_Stack"
    },
    {
      "x": 6,
      "y": 12,
      "z": -2,
      "name": "Plant_Seaweed_Wet_Stack"
    },
    {
      "x": 7,
      "y": 12,
      "z": -2,
      "name": "Plant_Seaweed_Wet_Stack"
    },
    {
      "x": 8,
      "y": 12,
      "z": -2,
      "name": "Plant_Seaweed_Wet_Stack"
    },
    {
      "x": 9,
      "y": 12,
      "z": -2,
      "name": "Plant_Seaweed_Wet_Stack"
    },
    {
      "x": 0,
      "y": 1,
      "z": -1,
      "name": "Wood_Spiral_Trunk_Full"
    },
    {
      "x": 1,
      "y": 1,
      "z": -1,
      "name": "Wood_Spiral_Trunk_Full"
    },
    {
      "x": 1,
      "y": 2,
      "z": -1,
      "name": "Wood_Spiral_Trunk_Full"
    },
    {
      "x": 5,
      "y": 2,
      "z": -1,
      "name": "Wood_Spiral_Trunk_Full"
    },
    {
      "x": 5,
      "y": 3,
      "z": -1,
      "name": "Wood_Spiral_Trunk_Full"
    },
    {
      "x": 5,
      "y": 5,
      "z": -1,
      "name": "Plant_Moss_Block_Green"
    },
    {
      "x": 6,
      "y": 5,
      "z": -1,
      "name": "Plant_Moss_Block_Green"
    },
    {
      "x": 7,
      "y": 5,
      "z": -1,
      "name": "Plant_Moss_Block_Green"
    },
    {
      "x": 8,
      "y": 5,
      "z": -1,
      "name": "Plant_Moss_Block_Green"
    },
    {
      "x": 4,
      "y": 6,
      "z": -1,
      "name": "Plant_Moss_Block_Green"
    },
    {
      "x": 5,
      "y": 6,
      "z": -1,
      "name": "Plant_Moss_Block_Green"
    },
    {
      "x": 6,
      "y": 6,
      "z": -1,
      "name": "Plant_Seaweed_Wet_Stack"
    },
    {
      "x": 7,
      "y": 6,
      "z": -1,
      "name": "Plant_Moss_Block_Green"
    },
    {
      "x": 8,
      "y": 6,
      "z": -1,
      "name": "Plant_Seaweed_Wet_Stack"
    },
    {
      "x": 4,
      "y": 7,
      "z": -1,
      "name": "Plant_Moss_Block_Green"
    },
    {
      "x": 5,
      "y": 7,
      "z": -1,
      "name": "Plant_Seaweed_Wet_Stack"
    },
    {
      "x": 6,
      "y": 7,
      "z": -1,
      "name": "Plant_Seaweed_Wet_Stack"
    },
    {
      "x": 7,
      "y": 7,
      "z": -1,
      "name": "Plant_Seaweed_Wet_Stack"
    },
    {
      "x": 8,
      "y": 7,
      "z": -1,
      "name": "Plant_Seaweed_Wet_Stack"
    },
    {
      "x": 4,
      "y": 8,
      "z": -1,
      "name": "Plant_Seaweed_Wet_Stack"
    },
    {
      "x": 5,
      "y": 8,
      "z": -1,
      "name": "Plant_Seaweed_Wet_Stack"
    },
    {
      "x": 6,
      "y": 8,
      "z": -1,
      "name": "Plant_Seaweed_Wet_Stack"
    },
    {
      "x": 7,
      "y": 8,
      "z": -1,
      "name": "Plant_Seaweed_Wet_Stack"
    },
    {
      "x": 8,
      "y": 8,
      "z": -1,
      "name": "Plant_Seaweed_Wet_Stack"
    },
    {
      "x": 4,
      "y": 9,
      "z": -1,
      "name": "Plant_Seaweed_Wet_Stack"
    },
    {
      "x": 5,
      "y": 9,
      "z": -1,
      "name": "Plant_Seaweed_Wet_Stack"
    },
    {
      "x": 6,
      "y": 9,
      "z": -1,
      "name": "Plant_Seaweed_Wet_Stack"
    },
    {
      "x": 7,
      "y": 9,
      "z": -1,
      "name": "Plant_Seaweed_Wet_Stack"
    },
    {
      "x": 8,
      "y": 9,
      "z": -1,
      "name": "Plant_Seaweed_Wet_Stack"
    },
    {
      "x": 4,
      "y": 10,
      "z": -1,
      "name": "Plant_Seaweed_Wet_Stack"
    },
    {
      "x": 5,
      "y": 10,
      "z": -1,
      "name": "Plant_Seaweed_Wet_Stack"
    },
    {
      "x": 6,
      "y": 10,
      "z": -1,
      "name": "Plant_Seaweed_Wet_Stack"
    },
    {
      "x": 7,
      "y": 10,
      "z": -1,
      "name": "Plant_Seaweed_Wet_Stack"
    },
    {
      "x": 8,
      "y": 10,
      "z": -1,
      "name": "Plant_Seaweed_Wet_Stack"
    },
    {
      "x": 4,
      "y": 11,
      "z": -1,
      "name": "Plant_Seaweed_Wet_Stack"
    },
    {
      "x": 5,
      "y": 11,
      "z": -1,
      "name": "Plant_Seaweed_Wet_Stack"
    },
    {
      "x": 6,
      "y": 11,
      "z": -1,
      "name": "Plant_Seaweed_Wet_Stack"
    },
    {
      "x": 7,
      "y": 11,
      "z": -1,
      "name": "Plant_Seaweed_Wet_Stack"
    },
    {
      "x": 8,
      "y": 11,
      "z": -1,
      "name": "Plant_Seaweed_Wet_Stack"
    },
    {
      "x": 4,
      "y": 12,
      "z": -1,
      "name": "Plant_Seaweed_Wet_Stack"
    },
    {
      "x": 5,
      "y": 12,
      "z": -1,
      "name": "Plant_Seaweed_Wet_Stack"
    },
    {
      "x": 6,
      "y": 12,
      "z": -1,
      "name": "Plant_Seaweed_Wet_Stack"
    },
    {
      "x": 7,
      "y": 12,
      "z": -1,
      "name": "Plant_Seaweed_Wet_Stack"
    },
    {
      "x": 8,
      "y": 12,
      "z": -1,
      "name": "Plant_Seaweed_Wet_Stack"
    },
    {
      "x": 3,
      "y": 13,
      "z": -12,
      "name": "Plant_Seaweed_Wet_Stack"
    },
    {
      "x": 2,
      "y": 13,
      "z": -11,
      "name": "Plant_Seaweed_Wet_Stack"
    },
    {
      "x": 3,
      "y": 13,
      "z": -11,
      "name": "Plant_Seaweed_Wet_Stack"
    },
    {
      "x": 5,
      "y": 13,
      "z": -11,
      "name": "Plant_Seaweed_Wet_Stack"
    },
    {
      "x": 2,
      "y": 14,
      "z": -11,
      "name": "Plant_Seaweed_Wet_Stack"
    },
    {
      "x": 2,
      "y": 15,
      "z": -11,
      "name": "Plant_Seaweed_Wet_Stack"
    },
    {
      "x": 0,
      "y": 13,
      "z": -10,
      "name": "Plant_Seaweed_Wet_Stack"
    },
    {
      "x": 1,
      "y": 13,
      "z": -10,
      "name": "Plant_Seaweed_Wet_Stack"
    },
    {
      "x": 2,
      "y": 13,
      "z": -10,
      "name": "Plant_Seaweed_Wet_Stack"
    },
    {
      "x": 4,
      "y": 13,
      "z": -10,
      "name": "Plant_Seaweed_Wet_Stack"
    },
    {
      "x": 5,
      "y": 13,
      "z": -10,
      "name": "Plant_Seaweed_Wet_Stack"
    },
    {
      "x": 0,
      "y": 14,
      "z": -10,
      "name": "Plant_Seaweed_Wet_Stack"
    },
    {
      "x": 1,
      "y": 14,
      "z": -10,
      "name": "Plant_Seaweed_Wet_Stack"
    },
    {
      "x": 2,
      "y": 14,
      "z": -10,
      "name": "Plant_Seaweed_Wet_Stack"
    },
    {
      "x": 0,
      "y": 15,
      "z": -10,
      "name": "Plant_Seaweed_Wet_Stack"
    },
    {
      "x": 1,
      "y": 15,
      "z": -10,
      "name": "Plant_Seaweed_Wet_Stack"
    },
    {
      "x": 0,
      "y": 16,
      "z": -10,
      "name": "Plant_Seaweed_Wet_Stack"
    },
    {
      "x": 1,
      "y": 16,
      "z": -10,
      "name": "Plant_Seaweed_Wet_Stack"
    },
    {
      "x": 1,
      "y": 17,
      "z": -10,
      "name": "Plant_Seaweed_Wet_Stack"
    },
    {
      "x": 0,
      "y": 13,
      "z": -9,
      "name": "Plant_Seaweed_Wet_Stack"
    },
    {
      "x": 1,
      "y": 13,
      "z": -9,
      "name": "Plant_Seaweed_Wet_Stack"
    },
    {
      "x": 2,
      "y": 13,
      "z": -9,
      "name": "Plant_Seaweed_Wet_Stack"
    },
    {
      "x": 3,
      "y": 13,
      "z": -9,
      "name": "Plant_Seaweed_Wet_Stack"
    },
    {
      "x": 4,
      "y": 13,
      "z": -9,
      "name": "Plant_Seaweed_Wet_Stack"
    },
    {
      "x": 6,
      "y": 13,
      "z": -9,
      "name": "Plant_Seaweed_Wet_Stack"
    },
    {
      "x": 0,
      "y": 14,
      "z": -9,
      "name": "Plant_Seaweed_Wet_Stack"
    },
    {
      "x": 1,
      "y": 14,
      "z": -9,
      "name": "Plant_Seaweed_Wet_Stack"
    },
    {
      "x": 3,
      "y": 14,
      "z": -9,
      "name": "Plant_Seaweed_Wet_Stack"
    },
    {
      "x": 4,
      "y": 14,
      "z": -9,
      "name": "Plant_Seaweed_Wet_Stack"
    },
    {
      "x": 0,
      "y": 15,
      "z": -9,
      "name": "Plant_Seaweed_Wet_Stack"
    },
    {
      "x": 1,
      "y": 15,
      "z": -9,
      "name": "Plant_Seaweed_Wet_Stack"
    },
    {
      "x": 4,
      "y": 15,
      "z": -9,
      "name": "Plant_Seaweed_Wet_Stack"
    },
    {
      "x": 0,
      "y": 16,
      "z": -9,
      "name": "Plant_Seaweed_Wet_Stack"
    },
    {
      "x": 1,
      "y": 16,
      "z": -9,
      "name": "Plant_Seaweed_Wet_Stack"
    },
    {
      "x": 4,
      "y": 16,
      "z": -9,
      "name": "Plant_Seaweed_Wet_Stack"
    },
    {
      "x": 1,
      "y": 17,
      "z": -9,
      "name": "Plant_Seaweed_Wet_Stack"
    },
    {
      "x": 1,
      "y": 18,
      "z": -9,
      "name": "Plant_Seaweed_Wet_Stack"
    },
    {
      "x": 0,
      "y": 13,
      "z": -8,
      "name": "Plant_Seaweed_Wet_Stack"
    },
    {
      "x": 1,
      "y": 13,
      "z": -8,
      "name": "Plant_Seaweed_Wet_Stack"
    },
    {
      "x": 2,
      "y": 13,
      "z": -8,
      "name": "Plant_Seaweed_Wet_Stack"
    },
    {
      "x": 3,
      "y": 13,
      "z": -8,
      "name": "Plant_Seaweed_Wet_Stack"
    },
    {
      "x": 4,
      "y": 13,
      "z": -8,
      "name": "Plant_Seaweed_Wet_Stack"
    },
    {
      "x": 5,
      "y": 13,
      "z": -8,
      "name": "Plant_Seaweed_Wet_Stack"
    },
    {
      "x": 6,
      "y": 13,
      "z": -8,
      "name": "Plant_Seaweed_Wet_Stack"
    },
    {
      "x": 0,
      "y": 14,
      "z": -8,
      "name": "Plant_Seaweed_Wet_Stack"
    },
    {
      "x": 1,
      "y": 14,
      "z": -8,
      "name": "Plant_Seaweed_Wet_Stack"
    },
    {
      "x": 2,
      "y": 14,
      "z": -8,
      "name": "Plant_Seaweed_Wet_Stack"
    },
    {
      "x": 4,
      "y": 14,
      "z": -8,
      "name": "Plant_Seaweed_Wet_Stack"
    },
    {
      "x": 5,
      "y": 14,
      "z": -8,
      "name": "Plant_Seaweed_Wet_Stack"
    },
    {
      "x": 0,
      "y": 15,
      "z": -8,
      "name": "Plant_Seaweed_Wet_Stack"
    },
    {
      "x": 1,
      "y": 15,
      "z": -8,
      "name": "Plant_Seaweed_Wet_Stack"
    },
    {
      "x": 2,
      "y": 15,
      "z": -8,
      "name": "Plant_Seaweed_Wet_Stack"
    },
    {
      "x": 0,
      "y": 16,
      "z": -8,
      "name": "Plant_Seaweed_Wet_Stack"
    },
    {
      "x": 1,
      "y": 16,
      "z": -8,
      "name": "Plant_Seaweed_Wet_Stack"
    },
    {
      "x": 0,
      "y": 17,
      "z": -8,
      "name": "Plant_Seaweed_Wet_Stack"
    },
    {
      "x": 1,
      "y": 17,
      "z": -8,
      "name": "Plant_Seaweed_Wet_Stack"
    },
    {
      "x": 1,
      "y": 13,
      "z": -7,
      "name": "Plant_Seaweed_Wet_Stack"
    },
    {
      "x": 2,
      "y": 13,
      "z": -7,
      "name": "Plant_Seaweed_Wet_Stack"
    },
    {
      "x": 3,
      "y": 13,
      "z": -7,
      "name": "Plant_Seaweed_Wet_Stack"
    },
    {
      "x": 4,
      "y": 13,
      "z": -7,
      "name": "Plant_Seaweed_Wet_Stack"
    },
    {
      "x": 5,
      "y": 13,
      "z": -7,
      "name": "Plant_Seaweed_Wet_Stack"
    },
    {
      "x": 1,
      "y": 14,
      "z": -7,
      "name": "Plant_Seaweed_Wet_Stack"
    },
    {
      "x": 2,
      "y": 14,
      "z": -7,
      "name": "Plant_Seaweed_Wet_Stack"
    },
    {
      "x": 3,
      "y": 14,
      "z": -7,
      "name": "Plant_Seaweed_Wet_Stack"
    },
    {
      "x": 4,
      "y": 14,
      "z": -7,
      "name": "Plant_Seaweed_Wet_Stack"
    },
    {
      "x": 1,
      "y": 15,
      "z": -7,
      "name": "Plant_Seaweed_Wet_Stack"
    },
    {
      "x": 2,
      "y": 15,
      "z": -7,
      "name": "Plant_Seaweed_Wet_Stack"
    },
    {
      "x": 3,
      "y": 15,
      "z": -7,
      "name": "Plant_Seaweed_Wet_Stack"
    },
    {
      "x": 1,
      "y": 16,
      "z": -7,
      "name": "Plant_Seaweed_Wet_Stack"
    },
    {
      "x": 1,
      "y": 17,
      "z": -7,
      "name": "Plant_Seaweed_Wet_Stack"
    },
    {
      "x": 1,
      "y": 18,
      "z": -7,
      "name": "Plant_Seaweed_Wet_Stack"
    },
    {
      "x": 0,
      "y": 13,
      "z": -6,
      "name": "Plant_Seaweed_Wet_Stack"
    },
    {
      "x": 1,
      "y": 13,
      "z": -6,
      "name": "Plant_Seaweed_Wet_Stack"
    },
    {
      "x": 3,
      "y": 13,
      "z": -6,
      "name": "Plant_Seaweed_Wet_Stack"
    },
    {
      "x": 4,
      "y": 13,
      "z": -6,
      "name": "Plant_Seaweed_Wet_Stack"
    },
    {
      "x": 5,
      "y": 13,
      "z": -6,
      "name": "Plant_Seaweed_Wet_Stack"
    },
    {
      "x": 6,
      "y": 13,
      "z": -6,
      "name": "Plant_Seaweed_Wet_Stack"
    },
    {
      "x": 0,
      "y": 14,
      "z": -6,
      "name": "Plant_Seaweed_Wet_Stack"
    },
    {
      "x": 1,
      "y": 14,
      "z": -6,
      "name": "Plant_Seaweed_Wet_Stack"
    },
    {
      "x": 4,
      "y": 14,
      "z": -6,
      "name": "Plant_Seaweed_Wet_Stack"
    },
    {
      "x": 5,
      "y": 14,
      "z": -6,
      "name": "Plant_Seaweed_Wet_Stack"
    },
    {
      "x": 6,
      "y": 14,
      "z": -6,
      "name": "Plant_Seaweed_Wet_Stack"
    },
    {
      "x": 0,
      "y": 15,
      "z": -6,
      "name": "Plant_Seaweed_Wet_Stack"
    },
    {
      "x": 1,
      "y": 15,
      "z": -6,
      "name": "Plant_Seaweed_Wet_Stack"
    },
    {
      "x": 0,
      "y": 16,
      "z": -6,
      "name": "Plant_Seaweed_Wet_Stack"
    },
    {
      "x": 0,
      "y": 17,
      "z": -6,
      "name": "Plant_Seaweed_Wet_Stack"
    },
    {
      "x": 0,
      "y": 18,
      "z": -6,
      "name": "Plant_Seaweed_Wet_Stack"
    },
    {
      "x": 0,
      "y": 19,
      "z": -6,
      "name": "Plant_Seaweed_Wet_Stack"
    },
    {
      "x": 0,
      "y": 20,
      "z": -6,
      "name": "Plant_Seaweed_Wet_Stack"
    },
    {
      "x": 0,
      "y": 21,
      "z": -6,
      "name": "Plant_Seaweed_Wet_Stack"
    },
    {
      "x": 0,
      "y": 13,
      "z": -5,
      "name": "Plant_Seaweed_Wet_Stack"
    },
    {
      "x": 3,
      "y": 13,
      "z": -5,
      "name": "Plant_Seaweed_Wet_Stack"
    },
    {
      "x": 4,
      "y": 13,
      "z": -5,
      "name": "Plant_Seaweed_Wet_Stack"
    },
    {
      "x": 5,
      "y": 13,
      "z": -5,
      "name": "Plant_Seaweed_Wet_Stack"
    },
    {
      "x": 6,
      "y": 13,
      "z": -5,
      "name": "Plant_Seaweed_Wet_Stack"
    },
    {
      "x": 8,
      "y": 13,
      "z": -5,
      "name": "Plant_Seaweed_Wet_Stack"
    },
    {
      "x": 0,
      "y": 14,
      "z": -5,
      "name": "Plant_Seaweed_Wet_Stack"
    },
    {
      "x": 4,
      "y": 14,
      "z": -5,
      "name": "Plant_Seaweed_Wet_Stack"
    },
    {
      "x": 5,
      "y": 14,
      "z": -5,
      "name": "Plant_Seaweed_Wet_Stack"
    },
    {
      "x": 6,
      "y": 14,
      "z": -5,
      "name": "Plant_Seaweed_Wet_Stack"
    },
    {
      "x": 0,
      "y": 15,
      "z": -5,
      "name": "Plant_Seaweed_Wet_Stack"
    },
    {
      "x": 4,
      "y": 15,
      "z": -5,
      "name": "Plant_Seaweed_Wet_Stack"
    },
    {
      "x": 5,
      "y": 15,
      "z": -5,
      "name": "Plant_Seaweed_Wet_Stack"
    },
    {
      "x": 0,
      "y": 16,
      "z": -5,
      "name": "Plant_Seaweed_Wet_Stack"
    },
    {
      "x": 4,
      "y": 16,
      "z": -5,
      "name": "Plant_Seaweed_Wet_Stack"
    },
    {
      "x": 5,
      "y": 16,
      "z": -5,
      "name": "Plant_Seaweed_Wet_Stack"
    },
    {
      "x": 0,
      "y": 17,
      "z": -5,
      "name": "Plant_Seaweed_Wet_Stack"
    },
    {
      "x": 4,
      "y": 17,
      "z": -5,
      "name": "Plant_Seaweed_Wet_Stack"
    },
    {
      "x": 0,
      "y": 18,
      "z": -5,
      "name": "Plant_Seaweed_Wet_Stack"
    },
    {
      "x": 4,
      "y": 18,
      "z": -5,
      "name": "Plant_Seaweed_Wet_Stack"
    },
    {
      "x": 4,
      "y": 19,
      "z": -5,
      "name": "Plant_Seaweed_Wet_Stack"
    },
    {
      "x": 4,
      "y": 20,
      "z": -5,
      "name": "Plant_Seaweed_Wet_Stack"
    },
    {
      "x": 0,
      "y": 13,
      "z": -4,
      "name": "Plant_Seaweed_Wet_Stack"
    },
    {
      "x": 1,
      "y": 13,
      "z": -4,
      "name": "Plant_Seaweed_Wet_Stack"
    },
    {
      "x": 3,
      "y": 13,
      "z": -4,
      "name": "Plant_Seaweed_Wet_Stack"
    },
    {
      "x": 4,
      "y": 13,
      "z": -4,
      "name": "Plant_Seaweed_Wet_Stack"
    },
    {
      "x": 5,
      "y": 13,
      "z": -4,
      "name": "Plant_Seaweed_Wet_Stack"
    },
    {
      "x": 7,
      "y": 13,
      "z": -4,
      "name": "Plant_Seaweed_Wet_Stack"
    },
    {
      "x": 8,
      "y": 13,
      "z": -4,
      "name": "Plant_Seaweed_Wet_Stack"
    },
    {
      "x": 3,
      "y": 14,
      "z": -4,
      "name": "Plant_Seaweed_Wet_Stack"
    },
    {
      "x": 4,
      "y": 14,
      "z": -4,
      "name": "Plant_Seaweed_Wet_Stack"
    },
    {
      "x": 5,
      "y": 14,
      "z": -4,
      "name": "Plant_Seaweed_Wet_Stack"
    },
    {
      "x": 7,
      "y": 14,
      "z": -4,
      "name": "Plant_Seaweed_Wet_Stack"
    },
    {
      "x": 8,
      "y": 14,
      "z": -4,
      "name": "Plant_Seaweed_Wet_Stack"
    },
    {
      "x": 3,
      "y": 15,
      "z": -4,
      "name": "Plant_Seaweed_Wet_Stack"
    },
    {
      "x": 4,
      "y": 15,
      "z": -4,
      "name": "Plant_Seaweed_Wet_Stack"
    },
    {
      "x": 5,
      "y": 15,
      "z": -4,
      "name": "Plant_Seaweed_Wet_Stack"
    },
    {
      "x": 7,
      "y": 15,
      "z": -4,
      "name": "Plant_Seaweed_Wet_Stack"
    },
    {
      "x": 8,
      "y": 15,
      "z": -4,
      "name": "Plant_Seaweed_Wet_Stack"
    },
    {
      "x": 3,
      "y": 16,
      "z": -4,
      "name": "Plant_Seaweed_Wet_Stack"
    },
    {
      "x": 4,
      "y": 16,
      "z": -4,
      "name": "Plant_Seaweed_Wet_Stack"
    },
    {
      "x": 5,
      "y": 16,
      "z": -4,
      "name": "Plant_Seaweed_Wet_Stack"
    },
    {
      "x": 7,
      "y": 16,
      "z": -4,
      "name": "Plant_Seaweed_Wet_Stack"
    },
    {
      "x": 8,
      "y": 16,
      "z": -4,
      "name": "Plant_Seaweed_Wet_Stack"
    },
    {
      "x": 3,
      "y": 17,
      "z": -4,
      "name": "Plant_Seaweed_Wet_Stack"
    },
    {
      "x": 4,
      "y": 17,
      "z": -4,
      "name": "Plant_Seaweed_Wet_Stack"
    },
    {
      "x": 5,
      "y": 17,
      "z": -4,
      "name": "Plant_Seaweed_Wet_Stack"
    },
    {
      "x": 7,
      "y": 17,
      "z": -4,
      "name": "Plant_Seaweed_Wet_Stack"
    },
    {
      "x": 3,
      "y": 18,
      "z": -4,
      "name": "Plant_Seaweed_Wet_Stack"
    },
    {
      "x": 4,
      "y": 18,
      "z": -4,
      "name": "Plant_Seaweed_Wet_Stack"
    },
    {
      "x": 3,
      "y": 19,
      "z": -4,
      "name": "Plant_Seaweed_Wet_Stack"
    },
    {
      "x": 4,
      "y": 19,
      "z": -4,
      "name": "Plant_Seaweed_Wet_Stack"
    },
    {
      "x": 3,
      "y": 20,
      "z": -4,
      "name": "Plant_Seaweed_Wet_Stack"
    },
    {
      "x": 4,
      "y": 20,
      "z": -4,
      "name": "Plant_Seaweed_Wet_Stack"
    },
    {
      "x": 4,
      "y": 21,
      "z": -4,
      "name": "Plant_Seaweed_Wet_Stack"
    },
    {
      "x": 3,
      "y": 13,
      "z": -3,
      "name": "Plant_Seaweed_Wet_Stack"
    },
    {
      "x": 4,
      "y": 13,
      "z": -3,
      "name": "Plant_Seaweed_Wet_Stack"
    },
    {
      "x": 5,
      "y": 13,
      "z": -3,
      "name": "Plant_Seaweed_Wet_Stack"
    },
    {
      "x": 6,
      "y": 13,
      "z": -3,
      "name": "Plant_Seaweed_Wet_Stack"
    },
    {
      "x": 7,
      "y": 13,
      "z": -3,
      "name": "Plant_Seaweed_Wet_Stack"
    },
    {
      "x": 9,
      "y": 13,
      "z": -3,
      "name": "Plant_Seaweed_Wet_Stack"
    },
    {
      "x": 3,
      "y": 14,
      "z": -3,
      "name": "Plant_Seaweed_Wet_Stack"
    },
    {
      "x": 4,
      "y": 14,
      "z": -3,
      "name": "Plant_Seaweed_Wet_Stack"
    },
    {
      "x": 5,
      "y": 14,
      "z": -3,
      "name": "Plant_Seaweed_Wet_Stack"
    },
    {
      "x": 6,
      "y": 14,
      "z": -3,
      "name": "Plant_Seaweed_Wet_Stack"
    },
    {
      "x": 7,
      "y": 14,
      "z": -3,
      "name": "Plant_Seaweed_Wet_Stack"
    },
    {
      "x": 4,
      "y": 15,
      "z": -3,
      "name": "Plant_Seaweed_Wet_Stack"
    },
    {
      "x": 5,
      "y": 15,
      "z": -3,
      "name": "Plant_Seaweed_Wet_Stack"
    },
    {
      "x": 6,
      "y": 15,
      "z": -3,
      "name": "Plant_Seaweed_Wet_Stack"
    },
    {
      "x": 7,
      "y": 15,
      "z": -3,
      "name": "Plant_Seaweed_Wet_Stack"
    },
    {
      "x": 4,
      "y": 16,
      "z": -3,
      "name": "Plant_Seaweed_Wet_Stack"
    },
    {
      "x": 5,
      "y": 16,
      "z": -3,
      "name": "Plant_Seaweed_Wet_Stack"
    },
    {
      "x": 6,
      "y": 16,
      "z": -3,
      "name": "Plant_Seaweed_Wet_Stack"
    },
    {
      "x": 7,
      "y": 16,
      "z": -3,
      "name": "Plant_Seaweed_Wet_Stack"
    },
    {
      "x": 4,
      "y": 17,
      "z": -3,
      "name": "Plant_Seaweed_Wet_Stack"
    },
    {
      "x": 5,
      "y": 17,
      "z": -3,
      "name": "Plant_Seaweed_Wet_Stack"
    },
    {
      "x": 6,
      "y": 17,
      "z": -3,
      "name": "Plant_Seaweed_Wet_Stack"
    },
    {
      "x": 7,
      "y": 17,
      "z": -3,
      "name": "Plant_Seaweed_Wet_Stack"
    },
    {
      "x": 4,
      "y": 18,
      "z": -3,
      "name": "Plant_Seaweed_Wet_Stack"
    },
    {
      "x": 5,
      "y": 18,
      "z": -3,
      "name": "Plant_Seaweed_Wet_Stack"
    },
    {
      "x": 6,
      "y": 18,
      "z": -3,
      "name": "Plant_Seaweed_Wet_Stack"
    },
    {
      "x": 7,
      "y": 18,
      "z": -3,
      "name": "Plant_Seaweed_Wet_Stack"
    },
    {
      "x": 4,
      "y": 19,
      "z": -3,
      "name": "Plant_Seaweed_Wet_Stack"
    },
    {
      "x": 5,
      "y": 19,
      "z": -3,
      "name": "Plant_Seaweed_Wet_Stack"
    },
    {
      "x": 6,
      "y": 19,
      "z": -3,
      "name": "Plant_Seaweed_Wet_Stack"
    },
    {
      "x": 7,
      "y": 19,
      "z": -3,
      "name": "Plant_Seaweed_Wet_Stack"
    },
    {
      "x": 4,
      "y": 20,
      "z": -3,
      "name": "Plant_Seaweed_Wet_Stack"
    },
    {
      "x": 6,
      "y": 20,
      "z": -3,
      "name": "Plant_Seaweed_Wet_Stack"
    },
    {
      "x": 7,
      "y": 20,
      "z": -3,
      "name": "Plant_Seaweed_Wet_Stack"
    },
    {
      "x": 4,
      "y": 21,
      "z": -3,
      "name": "Plant_Seaweed_Wet_Stack"
    },
    {
      "x": 6,
      "y": 21,
      "z": -3,
      "name": "Plant_Seaweed_Wet_Stack"
    },
    {
      "x": 4,
      "y": 22,
      "z": -3,
      "name": "Plant_Seaweed_Wet_Stack"
    },
    {
      "x": 6,
      "y": 22,
      "z": -3,
      "name": "Plant_Seaweed_Wet_Stack"
    },
    {
      "x": 4,
      "y": 13,
      "z": -2,
      "name": "Plant_Seaweed_Wet_Stack"
    },
    {
      "x": 5,
      "y": 13,
      "z": -2,
      "name": "Plant_Seaweed_Wet_Stack"
    },
    {
      "x": 6,
      "y": 13,
      "z": -2,
      "name": "Plant_Seaweed_Wet_Stack"
    },
    {
      "x": 7,
      "y": 13,
      "z": -2,
      "name": "Plant_Seaweed_Wet_Stack"
    },
    {
      "x": 8,
      "y": 13,
      "z": -2,
      "name": "Plant_Seaweed_Wet_Stack"
    },
    {
      "x": 9,
      "y": 13,
      "z": -2,
      "name": "Plant_Seaweed_Wet_Stack"
    },
    {
      "x": 4,
      "y": 14,
      "z": -2,
      "name": "Plant_Seaweed_Wet_Stack"
    },
    {
      "x": 5,
      "y": 14,
      "z": -2,
      "name": "Plant_Seaweed_Wet_Stack"
    },
    {
      "x": 6,
      "y": 14,
      "z": -2,
      "name": "Plant_Seaweed_Wet_Stack"
    },
    {
      "x": 7,
      "y": 14,
      "z": -2,
      "name": "Plant_Seaweed_Wet_Stack"
    },
    {
      "x": 8,
      "y": 14,
      "z": -2,
      "name": "Plant_Seaweed_Wet_Stack"
    },
    {
      "x": 4,
      "y": 15,
      "z": -2,
      "name": "Plant_Seaweed_Wet_Stack"
    },
    {
      "x": 5,
      "y": 15,
      "z": -2,
      "name": "Plant_Seaweed_Wet_Stack"
    },
    {
      "x": 6,
      "y": 15,
      "z": -2,
      "name": "Plant_Seaweed_Wet_Stack"
    },
    {
      "x": 7,
      "y": 15,
      "z": -2,
      "name": "Plant_Seaweed_Wet_Stack"
    },
    {
      "x": 8,
      "y": 15,
      "z": -2,
      "name": "Plant_Seaweed_Wet_Stack"
    },
    {
      "x": 4,
      "y": 16,
      "z": -2,
      "name": "Plant_Seaweed_Wet_Stack"
    },
    {
      "x": 5,
      "y": 16,
      "z": -2,
      "name": "Plant_Seaweed_Wet_Stack"
    },
    {
      "x": 6,
      "y": 16,
      "z": -2,
      "name": "Plant_Seaweed_Wet_Stack"
    },
    {
      "x": 7,
      "y": 16,
      "z": -2,
      "name": "Plant_Seaweed_Wet_Stack"
    },
    {
      "x": 8,
      "y": 16,
      "z": -2,
      "name": "Plant_Seaweed_Wet_Stack"
    },
    {
      "x": 4,
      "y": 17,
      "z": -2,
      "name": "Plant_Seaweed_Wet_Stack"
    },
    {
      "x": 5,
      "y": 17,
      "z": -2,
      "name": "Plant_Seaweed_Wet_Stack"
    },
    {
      "x": 6,
      "y": 17,
      "z": -2,
      "name": "Plant_Seaweed_Wet_Stack"
    },
    {
      "x": 7,
      "y": 17,
      "z": -2,
      "name": "Plant_Seaweed_Wet_Stack"
    },
    {
      "x": 8,
      "y": 17,
      "z": -2,
      "name": "Plant_Seaweed_Wet_Stack"
    },
    {
      "x": 4,
      "y": 18,
      "z": -2,
      "name": "Plant_Seaweed_Wet_Stack"
    },
    {
      "x": 5,
      "y": 18,
      "z": -2,
      "name": "Plant_Seaweed_Wet_Stack"
    },
    {
      "x": 6,
      "y": 18,
      "z": -2,
      "name": "Plant_Seaweed_Wet_Stack"
    },
    {
      "x": 8,
      "y": 18,
      "z": -2,
      "name": "Plant_Seaweed_Wet_Stack"
    },
    {
      "x": 4,
      "y": 19,
      "z": -2,
      "name": "Plant_Seaweed_Wet_Stack"
    },
    {
      "x": 5,
      "y": 19,
      "z": -2,
      "name": "Plant_Seaweed_Wet_Stack"
    },
    {
      "x": 6,
      "y": 19,
      "z": -2,
      "name": "Plant_Seaweed_Wet_Stack"
    },
    {
      "x": 8,
      "y": 19,
      "z": -2,
      "name": "Plant_Seaweed_Wet_Stack"
    },
    {
      "x": 4,
      "y": 20,
      "z": -2,
      "name": "Plant_Seaweed_Wet_Stack"
    },
    {
      "x": 5,
      "y": 20,
      "z": -2,
      "name": "Plant_Seaweed_Wet_Stack"
    },
    {
      "x": 6,
      "y": 20,
      "z": -2,
      "name": "Plant_Seaweed_Wet_Stack"
    },
    {
      "x": 8,
      "y": 20,
      "z": -2,
      "name": "Plant_Seaweed_Wet_Stack"
    },
    {
      "x": 4,
      "y": 21,
      "z": -2,
      "name": "Plant_Seaweed_Wet_Stack"
    },
    {
      "x": 6,
      "y": 21,
      "z": -2,
      "name": "Plant_Seaweed_Wet_Stack"
    },
    {
      "x": 6,
      "y": 22,
      "z": -2,
      "name": "Plant_Seaweed_Wet_Stack"
    },
    {
      "x": 6,
      "y": 23,
      "z": -2,
      "name": "Plant_Seaweed_Wet_Stack"
    },
    {
      "x": 6,
      "y": 24,
      "z": -2,
      "name": "Plant_Seaweed_Wet_Stack"
    },
    {
      "x": 6,
      "y": 25,
      "z": -2,
      "name": "Plant_Seaweed_Wet_Stack"
    },
    {
      "x": 6,
      "y": 26,
      "z": -2,
      "name": "Plant_Seaweed_Wet_Stack"
    },
    {
      "x": 6,
      "y": 27,
      "z": -2,
      "name": "Plant_Seaweed_Wet_Stack"
    },
    {
      "x": 4,
      "y": 13,
      "z": -1,
      "name": "Plant_Seaweed_Wet_Stack"
    },
    {
      "x": 5,
      "y": 13,
      "z": -1,
      "name": "Plant_Seaweed_Wet_Stack"
    },
    {
      "x": 6,
      "y": 13,
      "z": -1,
      "name": "Plant_Seaweed_Wet_Stack"
    },
    {
      "x": 7,
      "y": 13,
      "z": -1,
      "name": "Plant_Seaweed_Wet_Stack"
    },
    {
      "x": 8,
      "y": 13,
      "z": -1,
      "name": "Plant_Seaweed_Wet_Stack"
    },
    {
      "x": 4,
      "y": 14,
      "z": -1,
      "name": "Plant_Seaweed_Wet_Stack"
    },
    {
      "x": 5,
      "y": 14,
      "z": -1,
      "name": "Plant_Seaweed_Wet_Stack"
    },
    {
      "x": 6,
      "y": 14,
      "z": -1,
      "name": "Plant_Seaweed_Wet_Stack"
    },
    {
      "x": 7,
      "y": 14,
      "z": -1,
      "name": "Plant_Seaweed_Wet_Stack"
    },
    {
      "x": 8,
      "y": 14,
      "z": -1,
      "name": "Plant_Seaweed_Wet_Stack"
    },
    {
      "x": 4,
      "y": 15,
      "z": -1,
      "name": "Plant_Seaweed_Wet_Stack"
    },
    {
      "x": 5,
      "y": 15,
      "z": -1,
      "name": "Plant_Seaweed_Wet_Stack"
    },
    {
      "x": 6,
      "y": 15,
      "z": -1,
      "name": "Plant_Seaweed_Wet_Stack"
    },
    {
      "x": 7,
      "y": 15,
      "z": -1,
      "name": "Plant_Seaweed_Wet_Stack"
    },
    {
      "x": 8,
      "y": 15,
      "z": -1,
      "name": "Plant_Seaweed_Wet_Stack"
    },
    {
      "x": 4,
      "y": 16,
      "z": -1,
      "name": "Plant_Seaweed_Wet_Stack"
    },
    {
      "x": 5,
      "y": 16,
      "z": -1,
      "name": "Plant_Seaweed_Wet_Stack"
    },
    {
      "x": 6,
      "y": 16,
      "z": -1,
      "name": "Plant_Seaweed_Wet_Stack"
    },
    {
      "x": 7,
      "y": 16,
      "z": -1,
      "name": "Plant_Seaweed_Wet_Stack"
    },
    {
      "x": 8,
      "y": 16,
      "z": -1,
      "name": "Plant_Seaweed_Wet_Stack"
    },
    {
      "x": 4,
      "y": 17,
      "z": -1,
      "name": "Plant_Seaweed_Wet_Stack"
    },
    {
      "x": 5,
      "y": 17,
      "z": -1,
      "name": "Plant_Seaweed_Wet_Stack"
    },
    {
      "x": 6,
      "y": 17,
      "z": -1,
      "name": "Plant_Seaweed_Wet_Stack"
    },
    {
      "x": 7,
      "y": 17,
      "z": -1,
      "name": "Plant_Seaweed_Wet_Stack"
    },
    {
      "x": 8,
      "y": 17,
      "z": -1,
      "name": "Plant_Seaweed_Wet_Stack"
    },
    {
      "x": 4,
      "y": 18,
      "z": -1,
      "name": "Plant_Seaweed_Wet_Stack"
    },
    {
      "x": 5,
      "y": 18,
      "z": -1,
      "name": "Plant_Seaweed_Wet_Stack"
    },
    {
      "x": 6,
      "y": 18,
      "z": -1,
      "name": "Plant_Seaweed_Wet_Stack"
    },
    {
      "x": 7,
      "y": 18,
      "z": -1,
      "name": "Plant_Seaweed_Wet_Stack"
    },
    {
      "x": 4,
      "y": 19,
      "z": -1,
      "name": "Plant_Seaweed_Wet_Stack"
    },
    {
      "x": 5,
      "y": 19,
      "z": -1,
      "name": "Plant_Seaweed_Wet_Stack"
    },
    {
      "x": 6,
      "y": 19,
      "z": -1,
      "name": "Plant_Seaweed_Wet_Stack"
    },
    {
      "x": 4,
      "y": 20,
      "z": -1,
      "name": "Plant_Seaweed_Wet_Stack"
    },
    {
      "x": 5,
      "y": 20,
      "z": -1,
      "name": "Plant_Seaweed_Wet_Stack"
    },
    {
      "x": 6,
      "y": 20,
      "z": -1,
      "name": "Plant_Seaweed_Wet_Stack"
    },
    {
      "x": 4,
      "y": 21,
      "z": -1,
      "name": "Plant_Seaweed_Wet_Stack"
    },
    {
      "x": 5,
      "y": 21,
      "z": -1,
      "name": "Plant_Seaweed_Wet_Stack"
    },
    {
      "x": 6,
      "y": 21,
      "z": -1,
      "name": "Plant_Seaweed_Wet_Stack"
    },
    {
      "x": 4,
      "y": 22,
      "z": -1,
      "name": "Plant_Seaweed_Wet_Stack"
    },
    {
      "x": 4,
      "y": 23,
      "z": -1,
      "name": "Plant_Seaweed_Wet_Stack"
    },
    {
      "x": 4,
      "y": 24,
      "z": -1,
      "name": "Plant_Seaweed_Wet_Stack"
    },
    {
      "x": 4,
      "y": 25,
      "z": -1,
      "name": "Plant_Seaweed_Wet_Stack"
    },
    {
      "x": -2,
      "y": 13,
      "z": -10,
      "name": "Plant_Seaweed_Wet_Stack"
    },
    {
      "x": -2,
      "y": 14,
      "z": -10,
      "name": "Plant_Seaweed_Wet_Stack"
    },
    {
      "x": -2,
      "y": 15,
      "z": -10,
      "name": "Plant_Seaweed_Wet_Stack"
    },
    {
      "x": -2,
      "y": 16,
      "z": -10,
      "name": "Plant_Seaweed_Wet_Stack"
    },
    {
      "x": -3,
      "y": 13,
      "z": -9,
      "name": "Plant_Seaweed_Wet_Stack"
    },
    {
      "x": -2,
      "y": 13,
      "z": -9,
      "name": "Plant_Seaweed_Wet_Stack"
    },
    {
      "x": -3,
      "y": 14,
      "z": -9,
      "name": "Plant_Seaweed_Wet_Stack"
    },
    {
      "x": -2,
      "y": 14,
      "z": -9,
      "name": "Plant_Seaweed_Wet_Stack"
    },
    {
      "x": -3,
      "y": 15,
      "z": -9,
      "name": "Plant_Seaweed_Wet_Stack"
    },
    {
      "x": -2,
      "y": 15,
      "z": -9,
      "name": "Plant_Seaweed_Wet_Stack"
    },
    {
      "x": -3,
      "y": 16,
      "z": -9,
      "name": "Plant_Seaweed_Wet_Stack"
    },
    {
      "x": -2,
      "y": 16,
      "z": -9,
      "name": "Plant_Seaweed_Wet_Stack"
    },
    {
      "x": -3,
      "y": 17,
      "z": -9,
      "name": "Plant_Seaweed_Wet_Stack"
    },
    {
      "x": -3,
      "y": 18,
      "z": -9,
      "name": "Plant_Seaweed_Wet_Stack"
    },
    {
      "x": -5,
      "y": 13,
      "z": -8,
      "name": "Plant_Seaweed_Wet_Stack"
    },
    {
      "x": -4,
      "y": 13,
      "z": -8,
      "name": "Plant_Seaweed_Wet_Stack"
    },
    {
      "x": -3,
      "y": 13,
      "z": -8,
      "name": "Plant_Seaweed_Wet_Stack"
    },
    {
      "x": -1,
      "y": 13,
      "z": -8,
      "name": "Plant_Seaweed_Wet_Stack"
    },
    {
      "x": -4,
      "y": 14,
      "z": -8,
      "name": "Plant_Seaweed_Wet_Stack"
    },
    {
      "x": -3,
      "y": 14,
      "z": -8,
      "name": "Plant_Seaweed_Wet_Stack"
    },
    {
      "x": -1,
      "y": 14,
      "z": -8,
      "name": "Plant_Seaweed_Wet_Stack"
    },
    {
      "x": -4,
      "y": 15,
      "z": -8,
      "name": "Plant_Seaweed_Wet_Stack"
    },
    {
      "x": -3,
      "y": 15,
      "z": -8,
      "name": "Plant_Seaweed_Wet_Stack"
    },
    {
      "x": -1,
      "y": 15,
      "z": -8,
      "name": "Plant_Seaweed_Wet_Stack"
    },
    {
      "x": -4,
      "y": 16,
      "z": -8,
      "name": "Plant_Seaweed_Wet_Stack"
    },
    {
      "x": -3,
      "y": 16,
      "z": -8,
      "name": "Plant_Seaweed_Wet_Stack"
    },
    {
      "x": -1,
      "y": 16,
      "z": -8,
      "name": "Plant_Seaweed_Wet_Stack"
    },
    {
      "x": -4,
      "y": 17,
      "z": -8,
      "name": "Plant_Seaweed_Wet_Stack"
    },
    {
      "x": -3,
      "y": 17,
      "z": -8,
      "name": "Plant_Seaweed_Wet_Stack"
    },
    {
      "x": -1,
      "y": 17,
      "z": -8,
      "name": "Plant_Seaweed_Wet_Stack"
    },
    {
      "x": -3,
      "y": 18,
      "z": -8,
      "name": "Plant_Seaweed_Wet_Stack"
    },
    {
      "x": -1,
      "y": 18,
      "z": -8,
      "name": "Plant_Seaweed_Wet_Stack"
    },
    {
      "x": -1,
      "y": 19,
      "z": -8,
      "name": "Plant_Seaweed_Wet_Stack"
    },
    {
      "x": -1,
      "y": 20,
      "z": -8,
      "name": "Plant_Seaweed_Wet_Stack"
    },
    {
      "x": -1,
      "y": 21,
      "z": -8,
      "name": "Plant_Seaweed_Wet_Stack"
    },
    {
      "x": -5,
      "y": 13,
      "z": -7,
      "name": "Plant_Seaweed_Wet_Stack"
    },
    {
      "x": -4,
      "y": 13,
      "z": -7,
      "name": "Plant_Seaweed_Wet_Stack"
    },
    {
      "x": -3,
      "y": 13,
      "z": -7,
      "name": "Plant_Seaweed_Wet_Stack"
    },
    {
      "x": -2,
      "y": 13,
      "z": -7,
      "name": "Plant_Seaweed_Wet_Stack"
    },
    {
      "x": -1,
      "y": 13,
      "z": -7,
      "name": "Plant_Seaweed_Wet_Stack"
    },
    {
      "x": -5,
      "y": 14,
      "z": -7,
      "name": "Plant_Seaweed_Wet_Stack"
    },
    {
      "x": -4,
      "y": 14,
      "z": -7,
      "name": "Plant_Seaweed_Wet_Stack"
    },
    {
      "x": -3,
      "y": 14,
      "z": -7,
      "name": "Plant_Seaweed_Wet_Stack"
    },
    {
      "x": -2,
      "y": 14,
      "z": -7,
      "name": "Plant_Seaweed_Wet_Stack"
    },
    {
      "x": -1,
      "y": 14,
      "z": -7,
      "name": "Plant_Seaweed_Wet_Stack"
    },
    {
      "x": -5,
      "y": 15,
      "z": -7,
      "name": "Plant_Seaweed_Wet_Stack"
    },
    {
      "x": -4,
      "y": 15,
      "z": -7,
      "name": "Plant_Seaweed_Wet_Stack"
    },
    {
      "x": -3,
      "y": 15,
      "z": -7,
      "name": "Plant_Seaweed_Wet_Stack"
    },
    {
      "x": -2,
      "y": 15,
      "z": -7,
      "name": "Plant_Seaweed_Wet_Stack"
    },
    {
      "x": -1,
      "y": 15,
      "z": -7,
      "name": "Plant_Seaweed_Wet_Stack"
    },
    {
      "x": -5,
      "y": 16,
      "z": -7,
      "name": "Plant_Seaweed_Wet_Stack"
    },
    {
      "x": -4,
      "y": 16,
      "z": -7,
      "name": "Plant_Seaweed_Wet_Stack"
    },
    {
      "x": -3,
      "y": 16,
      "z": -7,
      "name": "Plant_Seaweed_Wet_Stack"
    },
    {
      "x": -2,
      "y": 16,
      "z": -7,
      "name": "Plant_Seaweed_Wet_Stack"
    },
    {
      "x": -1,
      "y": 16,
      "z": -7,
      "name": "Plant_Seaweed_Wet_Stack"
    },
    {
      "x": -5,
      "y": 17,
      "z": -7,
      "name": "Plant_Seaweed_Wet_Stack"
    },
    {
      "x": -4,
      "y": 17,
      "z": -7,
      "name": "Plant_Seaweed_Wet_Stack"
    },
    {
      "x": -3,
      "y": 17,
      "z": -7,
      "name": "Plant_Seaweed_Wet_Stack"
    },
    {
      "x": -1,
      "y": 17,
      "z": -7,
      "name": "Plant_Seaweed_Wet_Stack"
    },
    {
      "x": -5,
      "y": 18,
      "z": -7,
      "name": "Plant_Seaweed_Wet_Stack"
    },
    {
      "x": -4,
      "y": 18,
      "z": -7,
      "name": "Plant_Seaweed_Wet_Stack"
    },
    {
      "x": -3,
      "y": 18,
      "z": -7,
      "name": "Plant_Seaweed_Wet_Stack"
    },
    {
      "x": -1,
      "y": 18,
      "z": -7,
      "name": "Plant_Seaweed_Wet_Stack"
    },
    {
      "x": -5,
      "y": 19,
      "z": -7,
      "name": "Plant_Seaweed_Wet_Stack"
    },
    {
      "x": -3,
      "y": 19,
      "z": -7,
      "name": "Plant_Seaweed_Wet_Stack"
    },
    {
      "x": -1,
      "y": 19,
      "z": -7,
      "name": "Plant_Seaweed_Wet_Stack"
    },
    {
      "x": -1,
      "y": 20,
      "z": -7,
      "name": "Plant_Seaweed_Wet_Stack"
    },
    {
      "x": -1,
      "y": 21,
      "z": -7,
      "name": "Plant_Seaweed_Wet_Stack"
    },
    {
      "x": -1,
      "y": 22,
      "z": -7,
      "name": "Plant_Seaweed_Wet_Stack"
    },
    {
      "x": -4,
      "y": 13,
      "z": -6,
      "name": "Plant_Seaweed_Wet_Stack"
    },
    {
      "x": -3,
      "y": 13,
      "z": -6,
      "name": "Plant_Seaweed_Wet_Stack"
    },
    {
      "x": -2,
      "y": 13,
      "z": -6,
      "name": "Plant_Seaweed_Wet_Stack"
    },
    {
      "x": -4,
      "y": 14,
      "z": -6,
      "name": "Plant_Seaweed_Wet_Stack"
    },
    {
      "x": -3,
      "y": 14,
      "z": -6,
      "name": "Plant_Seaweed_Wet_Stack"
    },
    {
      "x": -2,
      "y": 14,
      "z": -6,
      "name": "Plant_Seaweed_Wet_Stack"
    },
    {
      "x": -4,
      "y": 15,
      "z": -6,
      "name": "Plant_Seaweed_Wet_Stack"
    },
    {
      "x": -3,
      "y": 15,
      "z": -6,
      "name": "Plant_Seaweed_Wet_Stack"
    },
    {
      "x": -2,
      "y": 15,
      "z": -6,
      "name": "Plant_Seaweed_Wet_Stack"
    },
    {
      "x": -4,
      "y": 16,
      "z": -6,
      "name": "Plant_Seaweed_Wet_Stack"
    },
    {
      "x": -3,
      "y": 16,
      "z": -6,
      "name": "Plant_Seaweed_Wet_Stack"
    },
    {
      "x": -2,
      "y": 16,
      "z": -6,
      "name": "Plant_Seaweed_Wet_Stack"
    },
    {
      "x": -4,
      "y": 17,
      "z": -6,
      "name": "Plant_Seaweed_Wet_Stack"
    },
    {
      "x": -3,
      "y": 17,
      "z": -6,
      "name": "Plant_Seaweed_Wet_Stack"
    },
    {
      "x": -2,
      "y": 17,
      "z": -6,
      "name": "Plant_Seaweed_Wet_Stack"
    },
    {
      "x": -3,
      "y": 18,
      "z": -6,
      "name": "Plant_Seaweed_Wet_Stack"
    },
    {
      "x": -2,
      "y": 18,
      "z": -6,
      "name": "Plant_Seaweed_Wet_Stack"
    },
    {
      "x": -3,
      "y": 19,
      "z": -6,
      "name": "Plant_Seaweed_Wet_Stack"
    },
    {
      "x": -2,
      "y": 19,
      "z": -6,
      "name": "Plant_Seaweed_Wet_Stack"
    },
    {
      "x": -3,
      "y": 20,
      "z": -6,
      "name": "Plant_Seaweed_Wet_Stack"
    },
    {
      "x": -2,
      "y": 20,
      "z": -6,
      "name": "Plant_Seaweed_Wet_Stack"
    },
    {
      "x": -3,
      "y": 21,
      "z": -6,
      "name": "Plant_Seaweed_Wet_Stack"
    },
    {
      "x": -3,
      "y": 22,
      "z": -6,
      "name": "Plant_Seaweed_Wet_Stack"
    },
    {
      "x": -4,
      "y": 13,
      "z": -5,
      "name": "Plant_Seaweed_Wet_Stack"
    },
    {
      "x": -3,
      "y": 13,
      "z": -5,
      "name": "Plant_Seaweed_Wet_Stack"
    },
    {
      "x": -2,
      "y": 13,
      "z": -5,
      "name": "Plant_Seaweed_Wet_Stack"
    },
    {
      "x": -1,
      "y": 13,
      "z": -5,
      "name": "Plant_Seaweed_Wet_Stack"
    },
    {
      "x": -4,
      "y": 14,
      "z": -5,
      "name": "Plant_Seaweed_Wet_Stack"
    },
    {
      "x": -3,
      "y": 14,
      "z": -5,
      "name": "Plant_Seaweed_Wet_Stack"
    },
    {
      "x": -2,
      "y": 14,
      "z": -5,
      "name": "Plant_Seaweed_Wet_Stack"
    },
    {
      "x": -1,
      "y": 14,
      "z": -5,
      "name": "Plant_Seaweed_Wet_Stack"
    },
    {
      "x": -4,
      "y": 15,
      "z": -5,
      "name": "Plant_Seaweed_Wet_Stack"
    },
    {
      "x": -3,
      "y": 15,
      "z": -5,
      "name": "Plant_Seaweed_Wet_Stack"
    },
    {
      "x": -2,
      "y": 15,
      "z": -5,
      "name": "Plant_Seaweed_Wet_Stack"
    },
    {
