{
  "version": 8,
  "blockIdVersion": 10,
  "anchorX": 0,
  "anchorY": 6,
  "anchorZ": 0,
  "blocks": [
    {
      "x": 14,
      "y": 18,
      "z": 0,
      "name": "Plant_Seaweed_Moss_Stack"
    },
    {
      "x": 14,
      "y": 19,
      "z": 0,
      "name": "Plant_Seaweed_Moss_Stack"
    },
    {
      "x": 14,
      "y": 20,
      "z": 0,
      "name": "Plant_Seaweed_Moss_Stack"
    },
    {
      "x": 14,
      "y": 21,
      "z": 0,
      "name": "Plant_Seaweed_Moss_Stack"
    },
    {
      "x": 14,
      "y": 22,
      "z": 0,
      "name": "Plant_Seaweed_Moss_Stack"
    },
    {
      "x": 14,
      "y": 23,
      "z": 0,
      "name": "Plant_Seaweed_Moss_Stack"
    },
    {
      "x": 14,
      "y": 24,
      "z": 0,
      "name": "Plant_Seaweed_Moss_Stack"
    },
    {
      "x": 10,
      "y": 18,
      "z": 1,
      "name": "Plant_Seaweed_Moss_Stack"
    },
    {
      "x": 12,
      "y": 18,
      "z": 1,
      "name": "Plant_Seaweed_Moss_Stack"
    },
    {
      "x": 10,
      "y": 19,
      "z": 1,
      "name": "Plant_Seaweed_Moss_Stack"
    },
    {
      "x": 12,
      "y": 19,
      "z": 1,
      "name": "Plant_Seaweed_Moss_Stack"
    },
    {
      "x": 11,
      "y": 18,
      "z": 2,
      "name": "Plant_Seaweed_Moss_Stack"
    },
    {
      "x": 11,
      "y": 19,
      "z": 2,
      "name": "Plant_Seaweed_Moss_Stack"
    },
    {
      "x": 14,
      "y": 18,
      "z": 3,
      "name": "Plant_Seaweed_Moss_Stack"
    },
    {
      "x": 15,
      "y": 18,
      "z": 3,
      "name": "Plant_Seaweed_Moss_Stack"
    },
    {
      "x": 14,
      "y": 19,
      "z": 3,
      "name": "Plant_Seaweed_Moss_Stack"
    },
    {
      "x": 15,
      "y": 19,
      "z": 3,
      "name": "Plant_Seaweed_Moss_Stack"
    },
    {
      "x": 14,
      "y": 20,
      "z": 3,
      "name": "Plant_Seaweed_Moss_Stack"
    },
    {
      "x": 14,
      "y": 21,
      "z": 3,
      "name": "Plant_Seaweed_Moss_Stack"
    },
    {
      "x": 14,
      "y": 22,
      "z": 3,
      "name": "Plant_Seaweed_Moss_Stack"
    },
    {
      "x": 14,
      "y": 23,
      "z": 3,
      "name": "Plant_Seaweed_Moss_Stack"
    },
    {
      "x": 14,
      "y": 24,
      "z": 3,
      "name": "Plant_Seaweed_Moss_Stack"
    },
    {
      "x": 10,
      "y": 18,
      "z": 4,
      "name": "Plant_Seaweed_Moss_Stack"
    },
    {
      "x": 13,
      "y": 18,
      "z": 5,
      "name": "Plant_Seaweed_Moss_Stack"
    },
    {
      "x": 13,
      "y": 19,
      "z": 5,
      "name": "Plant_Seaweed_Moss_Stack"
    },
    {
      "x": 13,
      "y": 20,
      "z": 5,
      "name": "Plant_Seaweed_Moss_Stack"
    },
    {
      "x": 13,
      "y": 21,
      "z": 5,
      "name": "Plant_Seaweed_Moss_Stack"
    },
    {
      "x": 13,
      "y": 22,
      "z": 5,
      "name": "Plant_Seaweed_Moss_Stack"
    },
    {
      "x": 13,
      "y": 23,
      "z": 5,
      "name": "Plant_Seaweed_Moss_Stack"
    },
    {
      "x": 13,
      "y": 24,
      "z": 5,
      "name": "Plant_Seaweed_Moss_Stack"
    },
    {
      "x": 8,
      "y": 18,
      "z": 6,
      "name": "Plant_Seaweed_Moss_Stack"
    },
    {
      "x": 8,
      "y": 19,
      "z": 6,
      "name": "Plant_Seaweed_Moss_Stack"
    },
    {
      "x": 8,
      "y": 20,
      "z": 6,
      "name": "Plant_Seaweed_Moss_Stack"
    },
    {
      "x": 8,
      "y": 21,
      "z": 6,
      "name": "Plant_Seaweed_Moss_Stack"
    },
    {
      "x": 8,
      "y": 22,
      "z": 6,
      "name": "Plant_Seaweed_Moss_Stack"
    },
    {
      "x": 8,
      "y": 23,
      "z": 6,
      "name": "Plant_Seaweed_Moss_Stack"
    },
    {
      "x": 8,
      "y": 24,
      "z": 6,
      "name": "Plant_Seaweed_Moss_Stack"
    },
    {
      "x": 8,
      "y": 25,
      "z": 6,
      "name": "Plant_Seaweed_Moss_Stack"
    },
    {
      "x": 8,
      "y": 26,
      "z": 6,
      "name": "Plant_Seaweed_Moss_Stack"
    },
    {
      "x": 9,
      "y": 18,
      "z": 7,
      "name": "Plant_Seaweed_Moss_Stack"
    },
    {
      "x": 7,
      "y": 18,
      "z": 8,
      "name": "Plant_Seaweed_Moss_Stack"
    },
    {
      "x": 11,
      "y": 18,
      "z": 8,
      "name": "Plant_Seaweed_Moss_Stack"
    },
    {
      "x": 12,
      "y": 18,
      "z": 8,
      "name": "Plant_Seaweed_Moss_Stack"
    },
    {
      "x": 7,
      "y": 19,
      "z": 8,
      "name": "Plant_Seaweed_Moss_Stack"
    },
    {
      "x": 11,
      "y": 19,
      "z": 8,
      "name": "Plant_Seaweed_Moss_Stack"
    },
    {
      "x": 12,
      "y": 19,
      "z": 8,
      "name": "Plant_Seaweed_Moss_Stack"
    },
    {
      "x": 7,
      "y": 20,
      "z": 8,
      "name": "Plant_Seaweed_Moss_Stack"
    },
    {
      "x": 11,
      "y": 20,
      "z": 8,
      "name": "Plant_Seaweed_Moss_Stack"
    },
    {
      "x": 12,
      "y": 20,
      "z": 8,
      "name": "Plant_Seaweed_Moss_Stack"
    },
    {
      "x": 7,
      "y": 21,
      "z": 8,
      "name": "Plant_Seaweed_Moss_Stack"
    },
    {
      "x": 11,
      "y": 21,
      "z": 8,
      "name": "Plant_Seaweed_Moss_Stack"
    },
    {
      "x": 12,
      "y": 21,
      "z": 8,
      "name": "Plant_Seaweed_Moss_Stack"
    },
    {
      "x": 7,
      "y": 22,
      "z": 8,
      "name": "Plant_Seaweed_Moss_Stack"
    },
    {
      "x": 11,
      "y": 22,
      "z": 8,
      "name": "Plant_Seaweed_Moss_Stack"
    },
    {
      "x": 12,
      "y": 22,
      "z": 8,
      "name": "Plant_Seaweed_Moss_Stack"
    },
    {
      "x": 7,
      "y": 23,
      "z": 8,
      "name": "Plant_Seaweed_Moss_Stack"
    },
    {
      "x": 11,
      "y": 23,
      "z": 8,
      "name": "Plant_Seaweed_Moss_Stack"
    },
    {
      "x": 12,
      "y": 23,
      "z": 8,
      "name": "Plant_Seaweed_Moss_Stack"
    },
    {
      "x": 7,
      "y": 24,
      "z": 8,
      "name": "Plant_Seaweed_Moss_Stack"
    },
    {
      "x": 11,
      "y": 24,
      "z": 8,
      "name": "Plant_Seaweed_Moss_Stack"
    },
    {
      "x": 12,
      "y": 24,
      "z": 8,
      "name": "Plant_Seaweed_Moss_Stack"
    },
    {
      "x": 11,
      "y": 25,
      "z": 8,
      "name": "Plant_Seaweed_Moss_Stack"
    },
    {
      "x": 11,
      "y": 26,
      "z": 8,
      "name": "Plant_Seaweed_Moss_Stack"
    },
    {
      "x": 11,
      "y": 27,
      "z": 8,
      "name": "Plant_Seaweed_Moss_Stack"
    },
    {
      "x": 11,
      "y": 28,
      "z": 8,
      "name": "Plant_Seaweed_Moss_Stack"
    },
    {
      "x": 11,
      "y": 29,
      "z": 8,
      "name": "Plant_Seaweed_Moss_Stack"
    },
    {
      "x": 11,
      "y": 30,
      "z": 8,
      "name": "Plant_Seaweed_Moss_Stack"
    },
    {
      "x": 11,
      "y": 31,
      "z": 8,
      "name": "Plant_Seaweed_Moss_Stack"
    },
    {
      "x": 11,
      "y": 32,
      "z": 8,
      "name": "Plant_Seaweed_Moss_Stack"
    },
    {
      "x": 11,
      "y": 33,
      "z": 8,
      "name": "Plant_Seaweed_Moss_Stack"
    },
    {
      "x": 6,
      "y": 18,
      "z": 9,
      "name": "Plant_Seaweed_Moss_Stack"
    },
    {
      "x": 12,
      "y": 18,
      "z": 9,
      "name": "Plant_Seaweed_Moss_Stack"
    },
    {
      "x": 6,
      "y": 19,
      "z": 9,
      "name": "Plant_Seaweed_Moss_Stack"
    },
    {
      "x": 12,
      "y": 19,
      "z": 9,
      "name": "Plant_Seaweed_Moss_Stack"
    },
    {
      "x": 6,
      "y": 20,
      "z": 9,
      "name": "Plant_Seaweed_Moss_Stack"
    },
    {
      "x": 12,
      "y": 20,
      "z": 9,
      "name": "Plant_Seaweed_Moss_Stack"
    },
    {
      "x": 6,
      "y": 21,
      "z": 9,
      "name": "Plant_Seaweed_Moss_Stack"
    },
    {
      "x": 12,
      "y": 21,
      "z": 9,
      "name": "Plant_Seaweed_Moss_Stack"
    },
    {
      "x": 6,
      "y": 22,
      "z": 9,
      "name": "Plant_Seaweed_Moss_Stack"
    },
    {
      "x": 12,
      "y": 22,
      "z": 9,
      "name": "Plant_Seaweed_Moss_Stack"
    },
    {
      "x": 6,
      "y": 23,
      "z": 9,
      "name": "Plant_Seaweed_Moss_Stack"
    },
    {
      "x": 12,
      "y": 23,
      "z": 9,
      "name": "Plant_Seaweed_Moss_Stack"
    },
    {
      "x": 6,
      "y": 24,
      "z": 9,
      "name": "Plant_Seaweed_Moss_Stack"
    },
    {
      "x": 12,
      "y": 24,
      "z": 9,
      "name": "Plant_Seaweed_Moss_Stack"
    },
    {
      "x": 6,
      "y": 25,
      "z": 9,
      "name": "Plant_Seaweed_Moss_Stack"
    },
    {
      "x": 12,
      "y": 25,
      "z": 9,
      "name": "Plant_Seaweed_Moss_Stack"
    },
    {
      "x": 6,
      "y": 26,
      "z": 9,
      "name": "Plant_Seaweed_Moss_Stack"
    },
    {
      "x": 12,
      "y": 26,
      "z": 9,
      "name": "Plant_Seaweed_Moss_Stack"
    },
    {
      "x": 6,
      "y": 27,
      "z": 9,
      "name": "Plant_Seaweed_Moss_Stack"
    },
    {
      "x": 7,
      "y": 18,
      "z": 10,
      "name": "Plant_Seaweed_Moss_Stack"
    },
    {
      "x": 10,
      "y": 18,
      "z": 11,
      "name": "Plant_Seaweed_Moss_Stack"
    },
    {
      "x": 10,
      "y": 19,
      "z": 11,
      "name": "Plant_Seaweed_Moss_Stack"
    },
    {
      "x": 10,
      "y": 20,
      "z": 11,
      "name": "Plant_Seaweed_Moss_Stack"
    },
    {
      "x": 10,
      "y": 21,
      "z": 11,
      "name": "Plant_Seaweed_Moss_Stack"
    },
    {
      "x": 10,
      "y": 22,
      "z": 11,
      "name": "Plant_Seaweed_Moss_Stack"
    },
    {
      "x": 10,
      "y": 23,
      "z": 11,
      "name": "Plant_Seaweed_Moss_Stack"
    },
    {
      "x": 10,
      "y": 24,
      "z": 11,
      "name": "Plant_Seaweed_Moss_Stack"
    },
    {
      "x": 10,
      "y": 25,
      "z": 11,
      "name": "Plant_Seaweed_Moss_Stack"
    },
    {
      "x": 10,
      "y": 26,
      "z": 11,
      "name": "Plant_Seaweed_Moss_Stack"
    },
    {
      "x": 8,
      "y": 18,
      "z": 12,
      "name": "Plant_Seaweed_Moss_Stack"
    },
    {
      "x": 8,
      "y": 19,
      "z": 12,
      "name": "Plant_Seaweed_Moss_Stack"
    },
    {
      "x": 8,
      "y": 20,
      "z": 12,
      "name": "Plant_Seaweed_Moss_Stack"
    },
    {
      "x": 8,
      "y": 21,
      "z": 12,
      "name": "Plant_Seaweed_Moss_Stack"
    },
    {
      "x": 8,
      "y": 22,
      "z": 12,
      "name": "Plant_Seaweed_Moss_Stack"
    },
    {
      "x": 8,
      "y": 23,
      "z": 12,
      "name": "Plant_Seaweed_Moss_Stack"
    },
    {
      "x": 0,
      "y": 8,
      "z": -10,
      "name": "Plant_Coral_Block_White"
    },
    {
      "x": 0,
      "y": 9,
      "z": -10,
      "name": "Plant_Seaweed_Moss_Stack"
    },
    {
      "x": 0,
      "y": 10,
      "z": -10,
      "name": "Plant_Seaweed_Moss_Stack"
    },
    {
      "x": 0,
      "y": 11,
      "z": -10,
      "name": "Plant_Seaweed_Moss_Stack"
    },
    {
      "x": 0,
      "y": 12,
      "z": -10,
      "name": "Plant_Seaweed_Moss_Stack"
    },
    {
      "x": 0,
      "y": 13,
      "z": -10,
      "name": "Plant_Seaweed_Moss_Stack"
    },
    {
      "x": 0,
      "y": 14,
      "z": -10,
      "name": "Plant_Seaweed_Moss_Stack"
    },
    {
      "x": 0,
      "y": 15,
      "z": -10,
      "name": "Plant_Seaweed_Moss_Stack"
    },
    {
      "x": 0,
      "y": 16,
      "z": -10,
      "name": "Plant_Seaweed_Moss_Stack"
    },
    {
      "x": 0,
      "y": 9,
      "z": -9,
      "name": "Plant_Coral_Block_White"
    },
    {
      "x": 0,
      "y": 10,
      "z": -9,
      "name": "Plant_Coral_Block_White"
    },
    {
      "x": 0,
      "y": 11,
      "z": -9,
      "name": "Plant_Coral_Block_White"
    },
    {
      "x": 0,
      "y": 12,
      "z": -9,
      "name": "Plant_Seaweed_Moss_Stack"
    },
    {
      "x": 2,
      "y": 12,
      "z": -9,
      "name": "Plant_Coral_Block_White"
    },
    {
      "x": 0,
      "y": 13,
      "z": -9,
      "name": "Plant_Seaweed_Moss_Stack"
    },
    {
      "x": 2,
      "y": 13,
      "z": -9,
      "name": "Plant_Seaweed_Grass_Tall"
    },
    {
      "x": 0,
      "y": 14,
      "z": -9,
      "name": "Plant_Seaweed_Moss_Stack"
    },
    {
      "x": 0,
      "y": 15,
      "z": -9,
      "name": "Plant_Seaweed_Moss_Stack"
    },
    {
      "x": 0,
      "y": 10,
      "z": -8,
      "name": "Plant_Coral_Block_White"
    },
    {
      "x": 1,
      "y": 10,
      "z": -8,
      "name": "Plant_Coral_Block_White"
    },
    {
      "x": 0,
      "y": 11,
      "z": -8,
      "name": "Plant_Coral_Block_White"
    },
    {
      "x": 1,
      "y": 11,
      "z": -8,
      "name": "Plant_Seaweed_Grass"
    },
    {
      "x": 2,
      "y": 11,
      "z": -8,
      "name": "Plant_Coral_Block_White"
    },
    {
      "x": 0,
      "y": 12,
      "z": -8,
      "name": "Plant_Coral_Block_White"
    },
    {
      "x": 2,
      "y": 12,
      "z": -8,
      "name": "Plant_Coral_Block_White"
    },
    {
      "x": 0,
      "y": 13,
      "z": -8,
      "name": "Plant_Coral_Block_White"
    },
    {
      "x": 2,
      "y": 13,
      "z": -8,
      "name": "Plant_Seaweed_Grass_Tall"
    },
    {
      "x": 0,
      "y": 14,
      "z": -8,
      "name": "Plant_Seaweed_Moss_Stack"
    },
    {
      "x": 0,
      "y": 15,
      "z": -8,
      "name": "Plant_Seaweed_Moss_Stack"
    },
    {
      "x": 0,
      "y": 16,
      "z": -8,
      "name": "Plant_Seaweed_Moss_Stack"
    },
    {
      "x": 0,
      "y": 9,
      "z": -7,
      "name": "Plant_Coral_Block_White"
    },
    {
      "x": 0,
      "y": 10,
      "z": -7,
      "name": "Plant_Coral_Block_White"
    },
    {
      "x": 1,
      "y": 10,
      "z": -7,
      "name": "Plant_Coral_Block_White"
    },
    {
      "x": 2,
      "y": 10,
      "z": -7,
      "name": "Plant_Coral_Block_White"
    },
    {
      "x": 3,
      "y": 10,
      "z": -7,
      "name": "Plant_Coral_Block_White"
    },
    {
      "x": 0,
      "y": 11,
      "z": -7,
      "name": "Plant_Seaweed_Grass_Tall"
    },
    {
      "x": 1,
      "y": 11,
      "z": -7,
      "name": "Plant_Coral_Block_White"
    },
    {
      "x": 2,
      "y": 11,
      "z": -7,
      "name": "Plant_Coral_Block_White"
    },
    {
      "x": 3,
      "y": 11,
      "z": -7,
      "name": "Plant_Seaweed_Moss_Stack"
    },
    {
      "x": 1,
      "y": 12,
      "z": -7,
      "name": "Plant_Seaweed_Grass_Tall"
    },
    {
      "x": 2,
      "y": 12,
      "z": -7,
      "name": "Plant_Seaweed_Moss_Stack"
    },
    {
      "x": 3,
      "y": 12,
      "z": -7,
      "name": "Plant_Seaweed_Moss_Stack"
    },
    {
      "x": 2,
      "y": 13,
      "z": -7,
      "name": "Plant_Seaweed_Moss_Stack"
    },
    {
      "x": 3,
      "y": 13,
      "z": -7,
      "name": "Plant_Seaweed_Moss_Stack"
    },
    {
      "x": 2,
      "y": 14,
      "z": -7,
      "name": "Plant_Seaweed_Moss_Stack"
    },
    {
      "x": 3,
      "y": 14,
      "z": -7,
      "name": "Plant_Seaweed_Moss_Stack"
    },
    {
      "x": 2,
      "y": 15,
      "z": -7,
      "name": "Plant_Seaweed_Moss_Stack"
    },
    {
      "x": 3,
      "y": 15,
      "z": -7,
      "name": "Plant_Seaweed_Moss_Stack"
    },
    {
      "x": 2,
      "y": 16,
      "z": -7,
      "name": "Plant_Seaweed_Moss_Stack"
    },
    {
      "x": 3,
      "y": 16,
      "z": -7,
      "name": "Plant_Seaweed_Moss_Stack"
    },
    {
      "x": 2,
      "y": 17,
      "z": -7,
      "name": "Plant_Seaweed_Moss_Stack"
    },
    {
      "x": 3,
      "y": 17,
      "z": -7,
      "name": "Plant_Seaweed_Moss_Stack"
    },
    {
      "x": 0,
      "y": 9,
      "z": -6,
      "name": "Plant_Coral_Block_White"
    },
    {
      "x": 0,
      "y": 10,
      "z": -6,
      "name": "Wood_Spiral_Trunk_Full"
    },
    {
      "x": 1,
      "y": 10,
      "z": -6,
      "name": "Plant_Coral_Block_White"
    },
    {
      "x": 0,
      "y": 11,
      "z": -6,
      "name": "Plant_Coral_Block_White"
    },
    {
      "x": 1,
      "y": 11,
      "z": -6,
      "name": "Plant_Seaweed_Moss_Stack"
    },
    {
      "x": 0,
      "y": 12,
      "z": -6,
      "name": "Plant_Coral_Block_White"
    },
    {
      "x": 1,
      "y": 12,
      "z": -6,
      "name": "Plant_Seaweed_Moss_Stack"
    },
    {
      "x": 2,
      "y": 12,
      "z": -6,
      "name": "Plant_Coral_Block_White"
    },
    {
      "x": 3,
      "y": 12,
      "z": -6,
      "name": "Plant_Coral_Block_White"
    },
    {
      "x": 0,
      "y": 13,
      "z": -6,
      "name": "Plant_Seaweed_Grass"
    },
    {
      "x": 1,
      "y": 13,
      "z": -6,
      "name": "Plant_Seaweed_Moss_Stack"
    },
    {
      "x": 2,
      "y": 13,
      "z": -6,
      "name": "Plant_Seaweed_Moss_Stack"
    },
    {
      "x": 3,
      "y": 13,
      "z": -6,
      "name": "Plant_Seaweed_Moss_Stack"
    },
    {
      "x": 2,
      "y": 14,
      "z": -6,
      "name": "Plant_Seaweed_Moss_Stack"
    },
    {
      "x": 3,
      "y": 14,
      "z": -6,
      "name": "Plant_Seaweed_Moss_Stack"
    },
    {
      "x": 2,
      "y": 15,
      "z": -6,
      "name": "Plant_Seaweed_Moss_Stack"
    },
    {
      "x": 3,
      "y": 15,
      "z": -6,
      "name": "Plant_Seaweed_Moss_Stack"
    },
    {
      "x": 2,
      "y": 16,
      "z": -6,
      "name": "Plant_Seaweed_Moss_Stack"
    },
    {
      "x": 3,
      "y": 16,
      "z": -6,
      "name": "Plant_Seaweed_Moss_Stack"
    },
    {
      "x": 2,
      "y": 17,
      "z": -6,
      "name": "Plant_Seaweed_Moss_Stack"
    },
    {
      "x": 3,
      "y": 17,
      "z": -6,
      "name": "Plant_Seaweed_Moss_Stack"
    },
    {
      "x": 0,
      "y": 9,
      "z": -5,
      "name": "Wood_Spiral_Trunk_Full"
    },
    {
      "x": 0,
      "y": 10,
      "z": -5,
      "name": "Wood_Spiral_Trunk_Full"
    },
    {
      "x": 1,
      "y": 10,
      "z": -5,
      "name": "Plant_Coral_Block_White"
    },
    {
      "x": 1,
      "y": 11,
      "z": -5,
      "name": "Plant_Coral_Block_White"
    },
    {
      "x": 1,
      "y": 12,
      "z": -5,
      "name": "Plant_Seaweed_Moss_Stack"
    },
    {
      "x": 0,
      "y": 8,
      "z": -4,
      "name": "Wood_Spiral_Trunk_Full"
    },
    {
      "x": 0,
      "y": 9,
      "z": -4,
      "name": "Wood_Spiral_Trunk_Full"
    },
    {
      "x": 1,
      "y": 11,
      "z": -4,
      "name": "Plant_Coral_Block_White"
    },
    {
      "x": 2,
      "y": 11,
      "z": -4,
      "name": "Plant_Coral_Block_White"
    },
    {
      "x": 1,
      "y": 12,
      "z": -4,
      "name": "Plant_Coral_Block_White"
    },
    {
      "x": 2,
      "y": 12,
      "z": -4,
      "name": "Plant_Seaweed_Grass_Tall"
    },
    {
      "x": 1,
      "y": 13,
      "z": -4,
      "name": "Plant_Seaweed_Moss_Stack"
    },
    {
      "x": 1,
      "y": 14,
      "z": -4,
      "name": "Plant_Seaweed_Moss_Stack"
    },
    {
      "x": 2,
      "y": 11,
      "z": -3,
      "name": "Plant_Coral_Block_White"
    },
    {
      "x": 2,
      "y": 12,
      "z": -3,
      "name": "Plant_Seaweed_Grass_Tall"
    },
    {
      "x": 9,
      "y": 0,
      "z": 6,
      "name": "Wood_Spiral_Trunk_Full"
    },
    {
      "x": 9,
      "y": 1,
      "z": 6,
      "name": "Wood_Spiral_Trunk_Full"
    },
    {
      "x": 9,
      "y": 0,
      "z": 7,
      "name": "Wood_Spiral_Trunk_Full"
    },
    {
      "x": 10,
      "y": 0,
      "z": 7,
      "name": "Wood_Spiral_Trunk_Full"
    },
    {
      "x": 9,
      "y": 1,
      "z": 7,
      "name": "Wood_Spiral_Trunk_Full"
    },
    {
      "x": 10,
      "y": 1,
      "z": 7,
      "name": "Wood_Spiral_Trunk_Full"
    },
    {
      "x": 9,
      "y": 0,
      "z": 8,
      "name": "Wood_Spiral_Trunk_Full"
    },
    {
      "x": 10,
      "y": 0,
      "z": 8,
      "name": "Wood_Spiral_Trunk_Full"
    },
    {
      "x": 9,
      "y": 1,
      "z": 8,
      "name": "Wood_Spiral_Trunk_Full"
    },
    {
      "x": 10,
      "y": 1,
      "z": 8,
      "name": "Wood_Spiral_Trunk_Full"
    },
    {
      "x": 2,
      "y": 18,
      "z": -6,
      "name": "Plant_Seaweed_Moss_Stack"
    },
    {
      "x": 3,
      "y": 18,
      "z": -6,
      "name": "Plant_Seaweed_Moss_Stack"
    },
    {
      "x": 2,
      "y": 19,
      "z": -6,
      "name": "Plant_Seaweed_Moss_Stack"
    },
    {
      "x": 3,
      "y": 19,
      "z": -6,
      "name": "Plant_Seaweed_Moss_Stack"
    },
    {
      "x": 2,
      "y": 20,
      "z": -6,
      "name": "Plant_Seaweed_Moss_Stack"
    },
    {
      "x": 3,
      "y": 20,
      "z": -6,
      "name": "Plant_Seaweed_Moss_Stack"
    },
    {
      "x": 2,
      "y": 21,
      "z": -6,
      "name": "Plant_Seaweed_Moss_Stack"
    },
    {
      "x": 3,
      "y": 21,
      "z": -6,
      "name": "Plant_Seaweed_Moss_Stack"
    },
    {
      "x": 2,
      "y": 22,
      "z": -6,
      "name": "Plant_Seaweed_Moss_Stack"
    },
    {
      "x": 2,
      "y": 23,
      "z": -6,
      "name": "Plant_Seaweed_Moss_Stack"
    },
    {
      "x": 11,
      "y": 34,
      "z": 8,
      "name": "Plant_Seaweed_Moss_Stack"
    },
    {
      "x": 11,
      "y": 35,
      "z": 8,
      "name": "Plant_Seaweed_Moss_Stack"
    },
    {
      "x": 11,
      "y": 36,
      "z": 8,
      "name": "Plant_Seaweed_Moss_Stack"
    },
    {
      "x": -4,
      "y": 18,
      "z": -12,
      "name": "Plant_Seaweed_Moss_Stack"
    },
    {
      "x": -1,
      "y": 18,
      "z": -12,
      "name": "Plant_Seaweed_Moss_Stack"
    },
    {
      "x": -1,
      "y": 19,
      "z": -12,
      "name": "Plant_Seaweed_Moss_Stack"
    },
    {
      "x": -1,
      "y": 20,
      "z": -12,
      "name": "Plant_Seaweed_Moss_Stack"
    },
    {
      "x": -1,
      "y": 21,
      "z": -12,
      "name": "Plant_Seaweed_Moss_Stack"
    },
    {
      "x": -1,
      "y": 22,
      "z": -12,
      "name": "Plant_Seaweed_Moss_Stack"
    },
    {
      "x": -6,
      "y": 18,
      "z": -11,
      "name": "Plant_Seaweed_Moss_Stack"
    },
    {
      "x": -6,
      "y": 19,
      "z": -11,
      "name": "Plant_Seaweed_Moss_Stack"
    },
    {
      "x": -2,
      "y": 18,
      "z": -10,
      "name": "Plant_Seaweed_Moss_Stack"
    },
    {
      "x": -2,
      "y": 19,
      "z": -10,
      "name": "Plant_Seaweed_Moss_Stack"
    },
    {
      "x": -2,
      "y": 20,
      "z": -10,
      "name": "Plant_Seaweed_Moss_Stack"
    },
    {
      "x": -2,
      "y": 21,
      "z": -10,
      "name": "Plant_Seaweed_Moss_Stack"
    },
    {
      "x": -2,
      "y": 22,
      "z": -10,
      "name": "Plant_Seaweed_Moss_Stack"
    },
    {
      "x": -2,
      "y": 23,
      "z": -10,
      "name": "Plant_Seaweed_Moss_Stack"
    },
    {
      "x": -2,
      "y": 24,
      "z": -10,
      "name": "Plant_Seaweed_Moss_Stack"
    },
    {
      "x": -2,
      "y": 25,
      "z": -10,
      "name": "Plant_Seaweed_Moss_Stack"
    },
    {
      "x": -2,
      "y": 26,
      "z": -10,
      "name": "Plant_Seaweed_Moss_Stack"
    },
    {
      "x": -2,
      "y": 27,
      "z": -10,
      "name": "Plant_Seaweed_Moss_Stack"
    },
    {
      "x": -2,
      "y": 28,
      "z": -10,
      "name": "Plant_Seaweed_Moss_Stack"
    },
    {
      "x": -2,
      "y": 29,
      "z": -10,
      "name": "Plant_Seaweed_Moss_Stack"
    },
    {
      "x": -13,
      "y": 18,
      "z": -9,
      "name": "Plant_Seaweed_Moss_Stack"
    },
    {
      "x": -2,
      "y": 18,
      "z": -9,
      "name": "Plant_Seaweed_Moss_Stack"
    },
    {
      "x": -1,
      "y": 18,
      "z": -9,
      "name": "Plant_Seaweed_Moss_Stack"
    },
    {
      "x": -13,
      "y": 19,
      "z": -9,
      "name": "Plant_Seaweed_Moss_Stack"
    },
    {
      "x": -2,
      "y": 19,
      "z": -9,
      "name": "Plant_Seaweed_Moss_Stack"
    },
    {
      "x": -1,
      "y": 19,
      "z": -9,
      "name": "Plant_Seaweed_Moss_Stack"
    },
    {
      "x": -13,
      "y": 20,
      "z": -9,
      "name": "Plant_Seaweed_Moss_Stack"
    },
    {
      "x": -2,
      "y": 20,
      "z": -9,
      "name": "Plant_Seaweed_Moss_Stack"
    },
    {
      "x": -1,
      "y": 20,
      "z": -9,
      "name": "Plant_Seaweed_Moss_Stack"
    },
    {
      "x": -13,
      "y": 21,
      "z": -9,
      "name": "Plant_Seaweed_Moss_Stack"
    },
    {
      "x": -2,
      "y": 21,
      "z": -9,
      "name": "Plant_Seaweed_Moss_Stack"
    },
    {
      "x": -1,
      "y": 21,
      "z": -9,
      "name": "Plant_Seaweed_Moss_Stack"
    },
    {
      "x": -13,
      "y": 22,
      "z": -9,
      "name": "Plant_Seaweed_Moss_Stack"
    },
    {
      "x": -2,
      "y": 22,
      "z": -9,
      "name": "Plant_Seaweed_Moss_Stack"
    },
    {
      "x": -1,
      "y": 22,
      "z": -9,
      "name": "Plant_Seaweed_Moss_Stack"
    },
    {
      "x": -13,
      "y": 23,
      "z": -9,
      "name": "Plant_Seaweed_Moss_Stack"
    },
    {
      "x": -2,
      "y": 23,
      "z": -9,
      "name": "Plant_Seaweed_Moss_Stack"
    },
    {
      "x": -1,
      "y": 23,
      "z": -9,
      "name": "Plant_Seaweed_Moss_Stack"
    },
    {
      "x": -13,
      "y": 24,
      "z": -9,
      "name": "Plant_Seaweed_Moss_Stack"
    },
    {
      "x": -2,
      "y": 24,
      "z": -9,
      "name": "Plant_Seaweed_Moss_Stack"
    },
    {
      "x": -1,
      "y": 24,
      "z": -9,
      "name": "Plant_Seaweed_Moss_Stack"
    },
    {
      "x": -13,
      "y": 25,
      "z": -9,
      "name": "Plant_Seaweed_Moss_Stack"
    },
    {
      "x": -1,
      "y": 25,
      "z": -9,
      "name": "Plant_Seaweed_Moss_Stack"
    },
    {
      "x": -13,
      "y": 26,
      "z": -9,
      "name": "Plant_Seaweed_Moss_Stack"
    },
    {
      "x": -1,
      "y": 26,
      "z": -9,
      "name": "Plant_Seaweed_Moss_Stack"
    },
    {
      "x": -1,
      "y": 27,
      "z": -9,
      "name": "Plant_Seaweed_Moss_Stack"
    },
    {
      "x": -1,
      "y": 28,
      "z": -9,
      "name": "Plant_Seaweed_Moss_Stack"
    },
    {
      "x": -1,
      "y": 29,
      "z": -9,
      "name": "Plant_Seaweed_Moss_Stack"
    },
    {
      "x": -1,
      "y": 30,
      "z": -9,
      "name": "Plant_Seaweed_Moss_Stack"
    },
    {
      "x": -1,
      "y": 31,
      "z": -9,
      "name": "Plant_Seaweed_Moss_Stack"
    },
    {
      "x": -1,
      "y": 32,
      "z": -9,
      "name": "Plant_Seaweed_Moss_Stack"
    },
    {
      "x": -10,
      "y": 18,
      "z": -8,
      "name": "Plant_Seaweed_Moss_Stack"
    },
    {
      "x": -9,
      "y": 18,
      "z": -8,
      "name": "Plant_Seaweed_Moss_Stack"
    },
    {
      "x": -6,
      "y": 18,
      "z": -8,
      "name": "Plant_Seaweed_Moss_Stack"
    },
    {
      "x": -5,
      "y": 18,
      "z": -8,
      "name": "Plant_Seaweed_Moss_Stack"
    },
    {
      "x": -2,
      "y": 18,
      "z": -8,
      "name": "Plant_Seaweed_Moss_Stack"
    },
    {
      "x": -10,
      "y": 19,
      "z": -8,
      "name": "Plant_Seaweed_Moss_Stack"
    },
    {
      "x": -6,
      "y": 19,
      "z": -8,
      "name": "Plant_Seaweed_Moss_Stack"
    },
    {
      "x": -5,
      "y": 19,
      "z": -8,
      "name": "Plant_Seaweed_Moss_Stack"
    },
    {
      "x": -2,
      "y": 19,
      "z": -8,
      "name": "Plant_Seaweed_Moss_Stack"
    },
    {
      "x": -6,
      "y": 20,
      "z": -8,
      "name": "Plant_Seaweed_Moss_Stack"
    },
    {
      "x": -2,
      "y": 20,
      "z": -8,
      "name": "Plant_Seaweed_Moss_Stack"
    },
    {
      "x": -14,
      "y": 18,
      "z": -7,
      "name": "Plant_Seaweed_Moss_Stack"
    },
    {
      "x": -10,
      "y": 18,
      "z": -7,
      "name": "Plant_Seaweed_Moss_Stack"
    },
    {
      "x": -7,
      "y": 18,
      "z": -7,
      "name": "Plant_Seaweed_Moss_Stack"
    },
    {
      "x": -2,
      "y": 18,
      "z": -7,
      "name": "Plant_Seaweed_Moss_Stack"
    },
    {
      "x": -1,
      "y": 18,
      "z": -7,
      "name": "Plant_Seaweed_Moss_Stack"
    },
    {
      "x": -14,
      "y": 19,
      "z": -7,
      "name": "Plant_Seaweed_Moss_Stack"
    },
    {
      "x": -7,
      "y": 19,
      "z": -7,
      "name": "Plant_Seaweed_Moss_Stack"
    },
    {
      "x": -2,
      "y": 19,
      "z": -7,
      "name": "Plant_Seaweed_Moss_Stack"
    },
    {
      "x": -1,
      "y": 19,
      "z": -7,
      "name": "Plant_Seaweed_Moss_Stack"
    },
    {
      "x": -14,
      "y": 20,
      "z": -7,
      "name": "Plant_Seaweed_Moss_Stack"
    },
    {
      "x": -7,
      "y": 20,
      "z": -7,
      "name": "Plant_Seaweed_Moss_Stack"
    },
    {
      "x": -2,
      "y": 20,
      "z": -7,
      "name": "Plant_Seaweed_Moss_Stack"
    },
    {
      "x": -1,
      "y": 20,
      "z": -7,
      "name": "Plant_Seaweed_Moss_Stack"
    },
    {
      "x": -14,
      "y": 21,
      "z": -7,
      "name": "Plant_Seaweed_Moss_Stack"
    },
    {
      "x": -2,
      "y": 21,
      "z": -7,
      "name": "Plant_Seaweed_Moss_Stack"
    },
    {
      "x": -1,
      "y": 21,
      "z": -7,
      "name": "Plant_Seaweed_Moss_Stack"
    },
    {
      "x": -14,
      "y": 22,
      "z": -7,
      "name": "Plant_Seaweed_Moss_Stack"
    },
    {
      "x": -2,
      "y": 22,
      "z": -7,
      "name": "Plant_Seaweed_Moss_Stack"
    },
    {
      "x": -1,
      "y": 22,
      "z": -7,
      "name": "Plant_Seaweed_Moss_Stack"
    },
    {
      "x": -14,
      "y": 23,
      "z": -7,
      "name": "Plant_Seaweed_Moss_Stack"
    },
    {
      "x": -2,
      "y": 23,
      "z": -7,
      "name": "Plant_Seaweed_Moss_Stack"
    },
    {
      "x": -1,
      "y": 23,
      "z": -7,
      "name": "Plant_Seaweed_Moss_Stack"
    },
    {
      "x": -14,
      "y": 24,
      "z": -7,
      "name": "Plant_Seaweed_Moss_Stack"
    },
    {
      "x": -2,
      "y": 24,
      "z": -7,
      "name": "Plant_Seaweed_Moss_Stack"
    },
    {
      "x": -1,
      "y": 24,
      "z": -7,
      "name": "Plant_Seaweed_Moss_Stack"
    },
    {
      "x": -2,
      "y": 25,
      "z": -7,
      "name": "Plant_Seaweed_Moss_Stack"
    },
    {
      "x": -1,
      "y": 25,
      "z": -7,
      "name": "Plant_Seaweed_Moss_Stack"
    },
    {
      "x": -2,
      "y": 26,
      "z": -7,
      "name": "Plant_Seaweed_Moss_Stack"
    },
    {
      "x": -1,
      "y": 26,
      "z": -7,
      "name": "Plant_Seaweed_Moss_Stack"
    },
    {
      "x": -2,
      "y": 27,
      "z": -7,
      "name": "Plant_Seaweed_Moss_Stack"
    },
    {
      "x": -1,
      "y": 27,
      "z": -7,
      "name": "Plant_Seaweed_Moss_Stack"
    },
    {
      "x": -2,
      "y": 28,
      "z": -7,
      "name": "Plant_Seaweed_Moss_Stack"
    },
    {
      "x": -1,
      "y": 28,
      "z": -7,
      "name": "Plant_Seaweed_Moss_Stack"
    },
    {
      "x": -2,
      "y": 29,
      "z": -7,
      "name": "Plant_Seaweed_Moss_Stack"
    },
    {
      "x": -1,
      "y": 29,
      "z": -7,
      "name": "Plant_Seaweed_Moss_Stack"
    },
    {
      "x": -2,
      "y": 30,
      "z": -7,
      "name": "Plant_Seaweed_Moss_Stack"
    },
    {
      "x": -1,
      "y": 30,
      "z": -7,
      "name": "Plant_Seaweed_Moss_Stack"
    },
    {
      "x": -9,
      "y": 18,
      "z": -6,
      "name": "Plant_Seaweed_Moss_Stack"
    },
    {
      "x": -9,
      "y": 19,
      "z": -6,
      "name": "Plant_Seaweed_Moss_Stack"
    },
    {
      "x": -9,
      "y": 20,
      "z": -6,
      "name": "Plant_Seaweed_Moss_Stack"
    },
    {
      "x": -9,
      "y": 21,
      "z": -6,
      "name": "Plant_Seaweed_Moss_Stack"
    },
    {
      "x": -9,
      "y": 22,
      "z": -6,
      "name": "Plant_Seaweed_Moss_Stack"
    },
    {
      "x": -9,
      "y": 23,
      "z": -6,
      "name": "Plant_Seaweed_Moss_Stack"
    },
    {
      "x": -9,
      "y": 24,
      "z": -6,
      "name": "Plant_Seaweed_Moss_Stack"
    },
    {
      "x": -9,
      "y": 25,
      "z": -6,
      "name": "Plant_Seaweed_Moss_Stack"
    },
    {
      "x": -9,
      "y": 26,
      "z": -6,
      "name": "Plant_Seaweed_Moss_Stack"
    },
    {
      "x": -7,
      "y": 18,
      "z": -5,
      "name": "Plant_Seaweed_Moss_Stack"
    },
    {
      "x": -5,
      "y": 18,
      "z": -5,
      "name": "Plant_Seaweed_Moss_Stack"
    },
    {
      "x": -7,
      "y": 19,
      "z": -5,
      "name": "Plant_Seaweed_Moss_Stack"
    },
    {
      "x": -5,
      "y": 19,
      "z": -5,
      "name": "Plant_Seaweed_Moss_Stack"
    },
    {
      "x": -7,
      "y": 20,
      "z": -5,
      "name": "Plant_Seaweed_Moss_Stack"
    },
    {
      "x": -5,
      "y": 20,
      "z": -5,
      "name": "Plant_Seaweed_Moss_Stack"
    },
    {
      "x": -7,
      "y": 21,
      "z": -5,
      "name": "Plant_Seaweed_Moss_Stack"
    },
    {
      "x": -5,
      "y": 21,
      "z": -5,
      "name": "Plant_Seaweed_Moss_Stack"
    },
    {
      "x": -5,
      "y": 22,
      "z": -5,
      "name": "Plant_Seaweed_Moss_Stack"
    },
    {
      "x": -5,
      "y": 23,
      "z": -5,
      "name": "Plant_Seaweed_Moss_Stack"
    },
    {
      "x": -5,
      "y": 24,
      "z": -5,
      "name": "Plant_Seaweed_Moss_Stack"
    },
    {
      "x": -5,
      "y": 25,
      "z": -5,
      "name": "Plant_Seaweed_Moss_Stack"
    },
    {
      "x": -5,
      "y": 26,
      "z": -5,
      "name": "Plant_Seaweed_Moss_Stack"
    },
    {
      "x": -5,
      "y": 27,
      "z": -5,
      "name": "Plant_Seaweed_Moss_Stack"
    },
    {
      "x": -5,
      "y": 28,
      "z": -5,
      "name": "Plant_Seaweed_Moss_Stack"
    },
    {
      "x": -5,
      "y": 29,
      "z": -5,
      "name": "Plant_Seaweed_Moss_Stack"
    },
    {
      "x": -5,
      "y": 30,
      "z": -5,
      "name": "Plant_Seaweed_Moss_Stack"
    },
    {
      "x": -5,
      "y": 31,
      "z": -5,
      "name": "Plant_Seaweed_Moss_Stack"
    },
    {
      "x": -5,
      "y": 32,
      "z": -5,
      "name": "Plant_Seaweed_Moss_Stack"
    },
    {
      "x": -5,
      "y": 33,
      "z": -5,
      "name": "Plant_Seaweed_Moss_Stack"
    },
    {
      "x": -12,
      "y": 18,
      "z": -4,
      "name": "Plant_Seaweed_Moss_Stack"
    },
    {
      "x": -11,
      "y": 18,
      "z": -4,
      "name": "Plant_Seaweed_Moss_Stack"
    },
    {
      "x": -9,
      "y": 18,
      "z": -4,
      "name": "Plant_Seaweed_Moss_Stack"
    },
    {
      "x": -6,
      "y": 18,
      "z": -4,
      "name": "Plant_Seaweed_Moss_Stack"
    },
    {
      "x": -12,
      "y": 19,
      "z": -4,
      "name": "Plant_Seaweed_Moss_Stack"
    },
    {
      "x": -11,
      "y": 19,
      "z": -4,
      "name": "Plant_Seaweed_Moss_Stack"
    },
    {
      "x": -9,
      "y": 19,
      "z": -4,
      "name": "Plant_Seaweed_Moss_Stack"
    },
    {
      "x": -6,
      "y": 19,
      "z": -4,
      "name": "Plant_Seaweed_Moss_Stack"
    },
    {
      "x": -12,
      "y": 20,
      "z": -4,
      "name": "Plant_Seaweed_Moss_Stack"
    },
    {
      "x": -11,
      "y": 20,
      "z": -4,
      "name": "Plant_Seaweed_Moss_Stack"
    },
    {
      "x": -9,
      "y": 20,
      "z": -4,
      "name": "Plant_Seaweed_Moss_Stack"
    },
    {
      "x": -6,
      "y": 20,
      "z": -4,
      "name": "Plant_Seaweed_Moss_Stack"
    },
    {
      "x": -12,
      "y": 21,
      "z": -4,
      "name": "Plant_Seaweed_Moss_Stack"
    },
    {
      "x": -9,
      "y": 21,
      "z": -4,
      "name": "Plant_Seaweed_Moss_Stack"
    },
    {
      "x": -6,
      "y": 21,
      "z": -4,
      "name": "Plant_Seaweed_Moss_Stack"
    },
    {
      "x": -12,
      "y": 22,
      "z": -4,
      "name": "Plant_Seaweed_Moss_Stack"
    },
    {
      "x": -9,
      "y": 22,
      "z": -4,
      "name": "Plant_Seaweed_Moss_Stack"
    },
    {
      "x": -6,
      "y": 22,
      "z": -4,
      "name": "Plant_Seaweed_Moss_Stack"
    },
    {
      "x": -12,
      "y": 23,
      "z": -4,
      "name": "Plant_Seaweed_Moss_Stack"
    },
    {
      "x": -9,
      "y": 23,
      "z": -4,
      "name": "Plant_Seaweed_Moss_Stack"
    },
    {
      "x": -6,
      "y": 23,
      "z": -4,
      "name": "Plant_Seaweed_Moss_Stack"
    },
    {
      "x": -9,
      "y": 24,
      "z": -4,
      "name": "Plant_Seaweed_Moss_Stack"
    },
    {
      "x": -6,
      "y": 24,
      "z": -4,
      "name": "Plant_Seaweed_Moss_Stack"
    },
    {
      "x": -9,
      "y": 25,
      "z": -4,
      "name": "Plant_Seaweed_Moss_Stack"
    },
    {
      "x": -6,
      "y": 25,
      "z": -4,
      "name": "Plant_Seaweed_Moss_Stack"
    },
    {
      "x": -9,
      "y": 26,
      "z": -4,
      "name": "Plant_Seaweed_Moss_Stack"
    },
    {
      "x": -6,
      "y": 26,
      "z": -4,
      "name": "Plant_Seaweed_Moss_Stack"
    },
    {
      "x": -9,
      "y": 18,
      "z": -3,
      "name": "Plant_Seaweed_Moss_Stack"
    },
    {
      "x": -3,
      "y": 18,
      "z": -3,
      "name": "Plant_Seaweed_Moss_Stack"
    },
    {
      "x": -9,
      "y": 19,
      "z": -3,
      "name": "Plant_Seaweed_Moss_Stack"
    },
    {
      "x": -3,
      "y": 19,
      "z": -3,
      "name": "Plant_Seaweed_Moss_Stack"
    },
    {
      "x": -9,
      "y": 20,
      "z": -3,
      "name": "Plant_Seaweed_Moss_Stack"
    },
    {
      "x": -3,
      "y": 20,
      "z": -3,
      "name": "Plant_Seaweed_Moss_Stack"
    },
    {
      "x": -3,
      "y": 21,
      "z": -3,
      "name": "Plant_Seaweed_Moss_Stack"
    },
    {
      "x": -3,
      "y": 22,
      "z": -3,
      "name": "Plant_Seaweed_Moss_Stack"
    },
    {
      "x": -3,
      "y": 23,
      "z": -3,
      "name": "Plant_Seaweed_Moss_Stack"
    },
    {
      "x": -3,
      "y": 24,
      "z": -3,
      "name": "Plant_Seaweed_Moss_Stack"
    },
    {
      "x": -3,
      "y": 25,
      "z": -3,
      "name": "Plant_Seaweed_Moss_Stack"
    },
    {
      "x": -3,
      "y": 26,
      "z": -3,
      "name": "Plant_Seaweed_Moss_Stack"
    },
    {
      "x": -3,
      "y": 27,
      "z": -3,
      "name": "Plant_Seaweed_Moss_Stack"
    },
    {
      "x": -3,
      "y": 28,
      "z": -3,
      "name": "Plant_Seaweed_Moss_Stack"
    },
    {
      "x": -3,
      "y": 29,
      "z": -3,
      "name": "Plant_Seaweed_Moss_Stack"
    },
    {
      "x": -10,
      "y": 18,
      "z": -2,
      "name": "Plant_Seaweed_Moss_Stack"
    },
    {
      "x": -9,
      "y": 18,
      "z": -2,
      "name": "Plant_Seaweed_Moss_Stack"
    },
    {
      "x": -7,
      "y": 18,
      "z": -2,
      "name": "Plant_Seaweed_Moss_Stack"
    },
    {
      "x": -5,
      "y": 18,
      "z": -2,
      "name": "Plant_Seaweed_Moss_Stack"
    },
    {
      "x": -10,
      "y": 19,
      "z": -2,
      "name": "Plant_Seaweed_Moss_Stack"
    },
    {
      "x": -9,
      "y": 19,
      "z": -2,
      "name": "Plant_Seaweed_Moss_Stack"
    },
    {
      "x": -7,
      "y": 19,
      "z": -2,
      "name": "Plant_Seaweed_Moss_Stack"
    },
    {
      "x": -10,
      "y": 20,
      "z": -2,
      "name": "Plant_Seaweed_Moss_Stack"
    },
    {
      "x": -9,
      "y": 20,
      "z": -2,
      "name": "Plant_Seaweed_Moss_Stack"
    },
    {
      "x": -7,
      "y": 20,
      "z": -2,
      "name": "Plant_Seaweed_Moss_Stack"
    },
    {
      "x": -10,
      "y": 21,
      "z": -2,
      "name": "Plant_Seaweed_Moss_Stack"
    },
    {
      "x": -9,
      "y": 21,
      "z": -2,
      "name": "Plant_Seaweed_Moss_Stack"
    },
    {
      "x": -7,
      "y": 21,
      "z": -2,
      "name": "Plant_Seaweed_Moss_Stack"
    },
    {
      "x": -10,
      "y": 22,
      "z": -2,
      "name": "Plant_Seaweed_Moss_Stack"
    },
    {
      "x": -9,
      "y": 22,
      "z": -2,
      "name": "Plant_Seaweed_Moss_Stack"
    },
    {
      "x": -7,
      "y": 22,
      "z": -2,
      "name": "Plant_Seaweed_Moss_Stack"
    },
    {
      "x": -10,
      "y": 23,
      "z": -2,
      "name": "Plant_Seaweed_Moss_Stack"
    },
    {
      "x": -9,
      "y": 23,
      "z": -2,
      "name": "Plant_Seaweed_Moss_Stack"
    },
    {
      "x": -7,
      "y": 23,
      "z": -2,
      "name": "Plant_Seaweed_Moss_Stack"
    },
    {
      "x": -10,
      "y": 24,
      "z": -2,
      "name": "Plant_Seaweed_Moss_Stack"
    },
    {
      "x": -9,
      "y": 24,
      "z": -2,
      "name": "Plant_Seaweed_Moss_Stack"
    },
    {
      "x": -7,
      "y": 24,
      "z": -2,
      "name": "Plant_Seaweed_Moss_Stack"
    },
    {
      "x": -10,
      "y": 25,
      "z": -2,
      "name": "Plant_Seaweed_Moss_Stack"
    },
    {
      "x": -9,
      "y": 25,
      "z": -2,
      "name": "Plant_Seaweed_Moss_Stack"
    },
    {
      "x": -9,
      "y": 26,
      "z": -2,
      "name": "Plant_Seaweed_Moss_Stack"
    },
    {
      "x": -3,
      "y": 7,
      "z": -12,
      "name": "Plant_Coral_Block_White"
    },
    {
      "x": -3,
      "y": 8,
      "z": -12,
      "name": "Plant_Seaweed_Grass_Tall"
    },
    {
      "x": -4,
      "y": 9,
      "z": -12,
      "name": "Plant_Coral_Block_White"
    },
    {
      "x": -3,
      "y": 9,
      "z": -12,
      "name": "Plant_Coral_Block_White"
    },
    {
      "x": -4,
      "y": 10,
      "z": -12,
      "name": "Plant_Coral_Block_White"
    },
    {
      "x": -3,
      "y": 10,
      "z": -12,
      "name": "Plant_Seaweed_Moss_Stack"
    },
    {
      "x": -1,
      "y": 10,
      "z": -12,
      "name": "Plant_Coral_Block_White"
    },
    {
      "x": -4,
      "y": 11,
      "z": -12,
      "name": "Plant_Seaweed_Moss_Stack"
    },
    {
      "x": -3,
      "y": 11,
      "z": -12,
      "name": "Plant_Seaweed_Moss_Stack"
    },
    {
      "x": -1,
      "y": 11,
      "z": -12,
      "name": "Plant_Seaweed_Moss_Stack"
    },
    {
      "x": -4,
      "y": 12,
      "z": -12,
      "name": "Plant_Seaweed_Moss_Stack"
    },
    {
      "x": -3,
      "y": 12,
      "z": -12,
      "name": "Plant_Seaweed_Moss_Stack"
    },
    {
      "x": -1,
      "y": 12,
      "z": -12,
      "name": "Plant_Seaweed_Moss_Stack"
    },
    {
      "x": -4,
      "y": 13,
      "z": -12,
      "name": "Plant_Seaweed_Moss_Stack"
    },
    {
      "x": -3,
      "y": 13,
      "z": -12,
      "name": "Plant_Seaweed_Moss_Stack"
    },
    {
      "x": -1,
      "y": 13,
      "z": -12,
      "name": "Plant_Seaweed_Moss_Stack"
    },
    {
      "x": -4,
      "y": 14,
      "z": -12,
      "name": "Plant_Seaweed_Moss_Stack"
    },
    {
      "x": -3,
      "y": 14,
      "z": -12,
      "name": "Plant_Seaweed_Moss_Stack"
    },
    {
      "x": -1,
      "y": 14,
      "z": -12,
      "name": "Plant_Seaweed_Moss_Stack"
    },
    {
      "x": -4,
      "y": 15,
      "z": -12,
      "name": "Plant_Seaweed_Moss_Stack"
    },
    {
      "x": -3,
      "y": 15,
      "z": -12,
      "name": "Plant_Seaweed_Moss_Stack"
    },
    {
      "x": -1,
      "y": 15,
      "z": -12,
      "name": "Plant_Seaweed_Moss_Stack"
    },
    {
      "x": -4,
      "y": 16,
      "z": -12,
      "name": "Plant_Seaweed_Moss_Stack"
    },
    {
      "x": -3,
      "y": 16,
      "z": -12,
      "name": "Plant_Seaweed_Moss_Stack"
    },
    {
      "x": -1,
      "y": 16,
      "z": -12,
      "name": "Plant_Seaweed_Moss_Stack"
    },
    {
      "x": -4,
      "y": 17,
      "z": -12,
      "name": "Plant_Seaweed_Moss_Stack"
    },
    {
      "x": -3,
      "y": 17,
      "z": -12,
      "name": "Plant_Seaweed_Moss_Stack"
    },
    {
      "x": -1,
      "y": 17,
      "z": -12,
      "name": "Plant_Seaweed_Moss_Stack"
    },
    {
      "x": -5,
      "y": 7,
      "z": -11,
      "name": "Plant_Coral_Block_White"
    },
    {
      "x": -5,
      "y": 8,
      "z": -11,
      "name": "Plant_Coral_Block_White"
    },
    {
      "x": -3,
      "y": 8,
      "z": -11,
      "name": "Plant_Coral_Block_White"
    },
    {
      "x": -2,
      "y": 8,
      "z": -11,
      "name": "Plant_Coral_Block_White"
    },
    {
      "x": -6,
      "y": 9,
      "z": -11,
      "name": "Plant_Coral_Block_White"
    },
    {
      "x": -5,
      "y": 9,
      "z": -11,
      "name": "Plant_Coral_Block_White"
    },
    {
      "x": -3,
      "y": 9,
      "z": -11,
      "name": "Plant_Coral_Block_White"
    },
    {
      "x": -2,
      "y": 9,
      "z": -11,
      "name": "Plant_Seaweed_Grass"
    },
    {
      "x": -1,
      "y": 9,
      "z": -11,
      "name": "Plant_Coral_Block_White"
    },
    {
      "x": -6,
      "y": 10,
      "z": -11,
      "name": "Plant_Seaweed_Moss_Stack"
    },
    {
      "x": -5,
      "y": 10,
      "z": -11,
      "name": "Plant_Coral_Block_White"
    },
    {
      "x": -3,
      "y": 10,
      "z": -11,
      "name": "Plant_Coral_Block_White"
    },
    {
      "x": -1,
      "y": 10,
      "z": -11,
      "name": "Plant_Coral_Block_White"
    },
    {
      "x": -6,
      "y": 11,
      "z": -11,
      "name": "Plant_Seaweed_Moss_Stack"
    },
    {
      "x": -5,
      "y": 11,
      "z": -11,
      "name": "Plant_Seaweed_Grass_Tall"
    },
    {
      "x": -3,
      "y": 11,
      "z": -11,
      "name": "Plant_Coral_Block_White"
    },
    {
      "x": -1,
      "y": 11,
      "z": -11,
      "name": "Plant_Seaweed_Grass"
    },
    {
      "x": -6,
      "y": 12,
      "z": -11,
      "name": "Plant_Seaweed_Moss_Stack"
    },
    {
      "x": -3,
      "y": 12,
      "z": -11,
      "name": "Plant_Seaweed_Grass"
    },
    {
      "x": -6,
      "y": 13,
      "z": -11,
      "name": "Plant_Seaweed_Moss_Stack"
    },
    {
      "x": -6,
      "y": 14,
      "z": -11,
      "name": "Plant_Seaweed_Moss_Stack"
    },
    {
      "x": -6,
      "y": 15,
      "z": -11,
      "name": "Plant_Seaweed_Moss_Stack"
    },
    {
      "x": -6,
      "y": 16,
      "z": -11,
      "name": "Plant_Seaweed_Moss_Stack"
    },
    {
      "x": -6,
      "y": 17,
      "z": -11,
      "name": "Plant_Seaweed_Moss_Stack"
    },
    {
      "x": -3,
      "y": 7,
      "z": -10,
      "name": "Plant_Coral_Block_White"
    },
    {
      "x": -10,
      "y": 8,
      "z": -10,
      "name": "Plant_Coral_Block_White"
    },
    {
      "x": -5,
      "y": 8,
      "z": -10,
      "name": "Plant_Coral_Block_White"
    },
    {
      "x": -4,
      "y": 8,
      "z": -10,
      "name": "Plant_Coral_Block_White"
    },
    {
      "x": -3,
      "y": 8,
      "z": -10,
      "name": "Plant_Coral_Block_White"
    },
    {
      "x": -2,
      "y": 8,
      "z": -10,
      "name": "Plant_Coral_Block_White"
    },
    {
      "x": -1,
      "y": 8,
      "z": -10,
      "name": "Plant_Coral_Block_White"
    },
    {
      "x": -10,
      "y": 9,
      "z": -10,
      "name": "Plant_Seaweed_Grass"
    },
    {
      "x": -5,
      "y": 9,
      "z": -10,
      "name": "Plant_Seaweed_Grass_Tall"
    },
    {
      "x": -4,
      "y": 9,
      "z": -10,
      "name": "Plant_Seaweed_Grass"
    },
    {
      "x": -3,
      "y": 9,
      "z": -10,
      "name": "Plant_Seaweed_Moss_Stack"
    },
    {
      "x": -2,
      "y": 9,
      "z": -10,
      "name": "Plant_Coral_Block_White"
    },
    {
      "x": -1,
      "y": 9,
      "z": -10,
      "name": "Plant_Coral_Block_White"
    },
    {
      "x": -11,
      "y": 10,
      "z": -10,
      "name": "Plant_Coral_Block_White"
    },
    {
      "x": -3,
      "y": 10,
      "z": -10,
      "name": "Plant_Seaweed_Moss_Stack"
    },
    {
      "x": -2,
      "y": 10,
      "z": -10,
      "name": "Plant_Seaweed_Moss_Stack"
    },
    {
      "x": -1,
      "y": 10,
      "z": -10,
      "name": "Plant_Seaweed_Grass"
    },
    {
      "x": -11,
      "y": 11,
      "z": -10,
      "name": "Plant_Coral_Block_White"
    },
    {
      "x": -8,
      "y": 11,
      "z": -10,
      "name": "Plant_Coral_Block_White"
    },
    {
      "x": -2,
      "y": 11,
      "z": -10,
      "name": "Plant_Seaweed_Moss_Stack"
    },
    {
      "x": -11,
      "y": 12,
      "z": -10,
      "name": "Plant_Seaweed_Grass_Tall"
    },
    {
      "x": -8,
      "y": 12,
      "z": -10,
      "name": "Plant_Seaweed_Grass_Tall"
    },
    {
      "x": -2,
      "y": 12,
      "z": -10,
      "name": "Plant_Seaweed_Moss_Stack"
    },
    {
      "x": -2,
      "y": 13,
      "z": -10,
      "name": "Plant_Seaweed_Moss_Stack"
    },
    {
      "x": -2,
      "y": 14,
      "z": -10,
      "name": "Plant_Seaweed_Moss_Stack"
    },
    {
      "x": -2,
      "y": 15,
      "z": -10,
      "name": "Plant_Seaweed_Moss_Stack"
    },
    {
      "x": -2,
      "y": 16,
      "z": -10,
      "name": "Plant_Seaweed_Moss_Stack"
    },
    {
      "x": -2,
      "y": 17,
      "z": -10,
      "name": "Plant_Seaweed_Moss_Stack"
    },
    {
      "x": -4,
      "y": 7,
      "z": -9,
      "name": "Plant_Coral_Block_White"
    },
    {
      "x": -3,
      "y": 7,
      "z": -9,
      "name": "Plant_Coral_Block_White"
    },
    {
      "x": -12,
      "y": 8,
      "z": -9,
      "name": "Plant_Coral_Block_White"
    },
    {
      "x": -4,
      "y": 8,
      "z": -9,
      "name": "Plant_Seaweed_Grass_Tall"
    },
    {
      "x": -3,
      "y": 8,
      "z": -9,
      "name": "Wood_Spiral_Trunk_Full"
    },
    {
      "x": -2,
      "y": 8,
      "z": -9,
      "name": "Plant_Coral_Block_White"
    },
    {
      "x": -12,
      "y": 9,
      "z": -9,
      "name": "Plant_Coral_Block_White"
    },
    {
      "x": -10,
      "y": 9,
      "z": -9,
      "name": "Plant_Coral_Block_White"
    },
    {
      "x": -9,
      "y": 9,
      "z": -9,
      "name": "Plant_Coral_Block_White"
    },
    {
      "x": -6,
      "y": 9,
      "z": -9,
      "name": "Plant_Coral_Block_White"
    },
    {
      "x": -3,
      "y": 9,
      "z": -9,
      "name": "Plant_Coral_Block_White"
    },
    {
      "x": -2,
      "y": 9,
      "z": -9,
      "name": "Plant_Seaweed_Moss_Stack"
    },
    {
      "x": -13,
      "y": 10,
      "z": -9,
      "name": "Plant_Coral_Block_White"
    },
    {
      "x": -12,
      "y": 10,
      "z": -9,
      "name": "Plant_Coral_Block_White"
    },
    {
      "x": -10,
      "y": 10,
      "z": -9,
      "name": "Plant_Coral_Block_White"
    },
    {
      "x": -9,
      "y": 10,
      "z": -9,
      "name": "Plant_Seaweed_Grass_Tall"
    },
    {
      "x": -8,
      "y": 10,
      "z": -9,
      "name": "Plant_Coral_Block_White"
    },
    {
      "x": -7,
      "y": 10,
      "z": -9,
      "name": "Plant_Coral_Block_White"
    },
    {
      "x": -6,
      "y": 10,
      "z": -9,
      "name": "Plant_Coral_Block_White"
    },
    {
      "x": -4,
      "y": 10,
      "z": -9,
      "name": "Plant_Coral_Block_White"
    },
    {
      "x": -3,
      "y": 10,
      "z": -9,
      "name": "Plant_Coral_Block_White"
    },
    {
      "x": -2,
      "y": 10,
      "z": -9,
      "name": "Plant_Seaweed_Moss_Stack"
    },
    {
      "x": -1,
      "y": 10,
      "z": -9,
      "name": "Plant_Coral_Block_White"
    },
    {
      "x": -13,
      "y": 11,
      "z": -9,
      "name": "Plant_Seaweed_Moss_Stack"
    },
    {
      "x": -12,
      "y": 11,
      "z": -9,
      "name": "Plant_Coral_Block_White"
    },
    {
      "x": -10,
      "y": 11,
      "z": -9,
      "name": "Plant_Coral_Block_White"
    },
    {
      "x": -8,
      "y": 11,
      "z": -9,
      "name": "Plant_Coral_Block_White"
    },
    {
      "x": -7,
      "y": 11,
      "z": -9,
      "name": "Plant_Seaweed_Grass_Tall"
    },
    {
      "x": -6,
      "y": 11,
      "z": -9,
      "name": "Plant_Seaweed_Grass"
    },
    {
      "x": -4,
      "y": 11,
      "z": -9,
      "name": "Plant_Coral_Block_White"
    },
    {
      "x": -3,
      "y": 11,
      "z": -9,
      "name": "Plant_Seaweed_Moss_Stack"
    },
    {
      "x": -2,
      "y": 11,
      "z": -9,
      "name": "Plant_Seaweed_Moss_Stack"
    },
    {
      "x": -1,
      "y": 11,
      "z": -9,
      "name": "Plant_Coral_Block_White"
    },
    {
      "x": -13,
      "y": 12,
      "z": -9,
      "name": "Plant_Seaweed_Moss_Stack"
    },
    {
      "x": -12,
      "y": 12,
      "z": -9,
      "name": "Plant_Seaweed_Grass_Tall"
    },
    {
      "x": -10,
      "y": 12,
      "z": -9,
      "name": "Plant_Coral_Block_White"
    },
    {
      "x": -8,
      "y": 12,
      "z": -9,
      "name": "Plant_Seaweed_Grass_Tall"
    },
    {
      "x": -4,
      "y": 12,
      "z": -9,
      "name": "Plant_Seaweed_Grass"
    },
    {
      "x": -3,
      "y": 12,
      "z": -9,
      "name": "Plant_Seaweed_Moss_Stack"
    },
    {
      "x": -2,
      "y": 12,
      "z": -9,
      "name": "Plant_Seaweed_Moss_Stack"
    },
    {
      "x": -1,
      "y": 12,
      "z": -9,
      "name": "Plant_Coral_Block_White"
    },
    {
      "x": -13,
      "y": 13,
      "z": -9,
      "name": "Plant_Seaweed_Moss_Stack"
    },
    {
      "x": -10,
      "y": 13,
      "z": -9,
      "name": "Plant_Seaweed_Grass_Tall"
    },
    {
      "x": -2,
      "y": 13,
      "z": -9,
      "name": "Plant_Seaweed_Moss_Stack"
    },
    {
      "x": -1,
      "y": 13,
      "z": -9,
      "name": "Plant_Seaweed_Moss_Stack"
    },
    {
      "x": -13,
      "y": 14,
      "z": -9,
      "name": "Plant_Seaweed_Moss_Stack"
    },
    {
      "x": -2,
      "y": 14,
      "z": -9,
      "name": "Plant_Seaweed_Moss_Stack"
    },
    {
      "x": -1,
      "y": 14,
      "z": -9,
      "name": "Plant_Seaweed_Moss_Stack"
    },
    {
      "x": -13,
      "y": 15,
      "z": -9,
      "name": "Plant_Seaweed_Moss_Stack"
    },
    {
      "x": -2,
      "y": 15,
      "z": -9,
      "name": "Plant_Seaweed_Moss_Stack"
    },
    {
      "x": -1,
      "y": 15,
      "z": -9,
      "name": "Plant_Seaweed_Moss_Stack"
    },
    {
      "x": -13,
      "y": 16,
      "z": -9,
      "name": "Plant_Seaweed_Moss_Stack"
    },
    {
      "x": -2,
      "y": 16,
      "z": -9,
      "name": "Plant_Seaweed_Moss_Stack"
    },
    {
      "x": -1,
      "y": 16,
      "z": -9,
      "name": "Plant_Seaweed_Moss_Stack"
    },
    {
      "x": -13,
      "y": 17,
      "z": -9,
      "name": "Plant_Seaweed_Moss_Stack"
    },
    {
      "x": -2,
      "y": 17,
      "z": -9,
      "name": "Plant_Seaweed_Moss_Stack"
    },
    {
      "x": -1,
      "y": 17,
      "z": -9,
      "name": "Plant_Seaweed_Moss_Stack"
    },
    {
      "x": -10,
      "y": 8,
      "z": -8,
      "name": "Plant_Coral_Block_White"
    },
    {
      "x": -5,
      "y": 8,
      "z": -8,
      "name": "Plant_Coral_Block_White"
    },
    {
      "x": -4,
      "y": 8,
      "z": -8,
      "name": "Wood_Spiral_Trunk_Full"
    },
    {
      "x": -3,
      "y": 8,
      "z": -8,
      "name": "Wood_Spiral_Trunk_Full"
    },
    {
      "x": -2,
      "y": 8,
      "z": -8,
      "name": "Plant_Coral_Block_White"
    },
    {
      "x": -12,
      "y": 9,
      "z": -8,
      "name": "Plant_Coral_Block_White"
    },
    {
      "x": -11,
      "y": 9,
      "z": -8,
      "name": "Plant_Coral_Block_White"
    },
    {
      "x": -10,
      "y": 9,
      "z": -8,
      "name": "Plant_Coral_Block_White"
    },
    {
      "x": -9,
      "y": 9,
      "z": -8,
      "name": "Plant_Coral_Block_White"
    },
    {
      "x": -8,
      "y": 9,
      "z": -8,
      "name": "Plant_Coral_Block_White"
    },
    {
      "x": -7,
      "y": 9,
      "z": -8,
      "name": "Plant_Coral_Block_White"
    },
    {
      "x": -6,
      "y": 9,
      "z": -8,
      "name": "Plant_Coral_Block_White"
    },
    {
      "x": -5,
      "y": 9,
      "z": -8,
      "name": "Plant_Coral_Block_White"
    },
    {
      "x": -2,
      "y": 9,
      "z": -8,
      "name": "Plant_Coral_Block_White"
    },
    {
      "x": -12,
      "y": 10,
      "z": -8,
      "name": "Plant_Seaweed_Grass_Tall"
    },
    {
      "x": -11,
      "y": 10,
      "z": -8,
      "name": "Plant_Seaweed_Moss_Stack"
    },
    {
      "x": -10,
      "y": 10,
      "z": -8,
      "name": "Plant_Seaweed_Moss_Stack"
    },
    {
      "x": -9,
      "y": 10,
      "z": -8,
      "name": "Plant_Coral_Block_White"
    },
    {
      "x": -8,
      "y": 10,
      "z": -8,
      "name": "Plant_Coral_Block_White"
    },
    {
      "x": -7,
      "y": 10,
      "z": -8,
      "name": "Plant_Seaweed_Moss_Stack"
    },
    {
      "x": -6,
      "y": 10,
      "z": -8,
      "name": "Plant_Seaweed_Moss_Stack"
    },
    {
      "x": -5,
      "y": 10,
      "z": -8,
      "name": "Plant_Seaweed_Moss_Stack"
    },
    {
      "x": -2,
      "y": 10,
      "z": -8,
      "name": "Plant_Coral_Block_White"
    },
    {
      "x": -11,
      "y": 11,
      "z": -8,
      "name": "Plant_Seaweed_Moss_Stack"
    },
    {
      "x": -10,
      "y": 11,
      "z": -8,
      "name": "Plant_Seaweed_Moss_Stack"
    },
    {
      "x": -9,
      "y": 11,
      "z": -8,
      "name": "Plant_Seaweed_Moss_Stack"
    },
    {
      "x": -8,
      "y": 11,
      "z": -8,
      "name": "Plant_Seaweed_Grass_Tall"
    },
    {
      "x": -6,
      "y": 11,
      "z": -8,
      "name": "Plant_Seaweed_Moss_Stack"
    },
    {
      "x": -5,
      "y": 11,
      "z": -8,
      "name": "Plant_Seaweed_Moss_Stack"
    },
    {
      "x": -3,
      "y": 11,
      "z": -8,
      "name": "Plant_Coral_Block_White"
    },
    {
      "x": -2,
      "y": 11,
      "z": -8,
      "name": "Plant_Coral_Block_White"
    },
    {
      "x": -11,
      "y": 12,
      "z": -8,
      "name": "Plant_Seaweed_Moss_Stack"
    },
    {
      "x": -10,
      "y": 12,
      "z": -8,
      "name": "Plant_Seaweed_Moss_Stack"
    },
    {
      "x": -9,
      "y": 12,
      "z": -8,
      "name": "Plant_Seaweed_Moss_Stack"
    },
    {
      "x": -6,
      "y": 12,
      "z": -8,
      "name": "Plant_Seaweed_Moss_Stack"
    },
    {
      "x": -5,
      "y": 12,
      "z": -8,
      "name": "Plant_Seaweed_Moss_Stack"
    },
    {
      "x": -3,
      "y": 12,
      "z": -8,
      "name": "Plant_Seaweed_Grass"
    },
    {
      "x": -2,
      "y": 12,
      "z": -8,
      "name": "Plant_Coral_Block_White"
    },
    {
      "x": -11,
      "y": 13,
      "z": -8,
      "name": "Plant_Seaweed_Moss_Stack"
    },
    {
      "x": -10,
      "y": 13,
      "z": -8,
      "name": "Plant_Seaweed_Moss_Stack"
    },
    {
      "x": -9,
      "y": 13,
      "z": -8,
      "name": "Plant_Seaweed_Moss_Stack"
    },
    {
      "x": -6,
      "y": 13,
      "z": -8,
      "name": "Plant_Seaweed_Moss_Stack"
    },
    {
      "x": -5,
      "y": 13,
      "z": -8,
      "name": "Plant_Seaweed_Moss_Stack"
    },
    {
      "x": -2,
      "y": 13,
      "z": -8,
      "name": "Plant_Seaweed_Moss_Stack"
    },
    {
      "x": -10,
      "y": 14,
      "z": -8,
      "name": "Plant_Seaweed_Moss_Stack"
    },
    {
      "x": -9,
      "y": 14,
      "z": -8,
      "name": "Plant_Seaweed_Moss_Stack"
    },
    {
      "x": -6,
      "y": 14,
      "z": -8,
      "name": "Plant_Seaweed_Moss_Stack"
    },
    {
      "x": -5,
      "y": 14,
      "z": -8,
      "name": "Plant_Seaweed_Moss_Stack"
    },
    {
      "x": -2,
      "y": 14,
      "z": -8,
      "name": "Plant_Seaweed_Moss_Stack"
    },
    {
      "x": -10,
      "y": 15,
      "z": -8,
      "name": "Plant_Seaweed_Moss_Stack"
    },
    {
      "x": -9,
      "y": 15,
      "z": -8,
      "name": "Plant_Seaweed_Moss_Stack"
    },
    {
      "x": -6,
      "y": 15,
      "z": -8,
      "name": "Plant_Seaweed_Moss_Stack"
    },
    {
      "x": -5,
      "y": 15,
      "z": -8,
      "name": "Plant_Seaweed_Moss_Stack"
    },
    {
      "x": -2,
      "y": 15,
      "z": -8,
      "name": "Plant_Seaweed_Moss_Stack"
    },
    {
      "x": -10,
      "y": 16,
      "z": -8,
      "name": "Plant_Seaweed_Moss_Stack"
    },
    {
      "x": -9,
      "y": 16,
      "z": -8,
      "name": "Plant_Seaweed_Moss_Stack"
    },
    {
      "x": -6,
      "y": 16,
      "z": -8,
      "name": "Plant_Seaweed_Moss_Stack"
    },
    {
      "x": -5,
      "y": 16,
      "z": -8,
      "name": "Plant_Seaweed_Moss_Stack"
    },
    {
      "x": -2,
      "y": 16,
      "z": -8,
      "name": "Plant_Seaweed_Moss_Stack"
    },
    {
      "x": -10,
      "y": 17,
      "z": -8,
      "name": "Plant_Seaweed_Moss_Stack"
    },
    {
      "x": -9,
      "y": 17,
      "z": -8,
      "name": "Plant_Seaweed_Moss_Stack"
    },
    {
      "x": -6,
      "y": 17,
      "z": -8,
      "name": "Plant_Seaweed_Moss_Stack"
    },
    {
      "x": -5,
      "y": 17,
      "z": -8,
      "name": "Plant_Seaweed_Moss_Stack"
    },
    {
      "x": -2,
      "y": 17,
      "z": -8,
      "name": "Plant_Seaweed_Moss_Stack"
    },
    {
      "x": -5,
      "y": 7,
      "z": -7,
      "name": "Plant_Coral_Block_White"
    },
    {
      "x": -4,
      "y": 7,
      "z": -7,
      "name": "Wood_Spiral_Trunk_Full"
    },
    {
      "x": -3,
      "y": 7,
      "z": -7,
      "name": "Plant_Coral_Block_White"
    },
    {
      "x": -11,
      "y": 8,
      "z": -7,
      "name": "Plant_Coral_Block_White"
    },
    {
      "x": -10,
      "y": 8,
      "z": -7,
      "name": "Plant_Coral_Block_White"
    },
    {
      "x": -5,
      "y": 8,
      "z": -7,
      "name": "Plant_Seaweed_Grass_Tall"
    },
    {
      "x": -4,
      "y": 8,
      "z": -7,
      "name": "Wood_Spiral_Trunk_Full"
    },
    {
      "x": -3,
      "y": 8,
      "z": -7,
      "name": "Plant_Seaweed_Grass"
    },
    {
      "x": -11,
      "y": 9,
      "z": -7,
      "name": "Plant_Seaweed_Grass_Tall"
    },
    {
      "x": -10,
      "y": 9,
      "z": -7,
      "name": "Wood_Spiral_Trunk_Full"
    },
    {
      "x": -9,
      "y": 9,
      "z": -7,
      "name": "Wood_Spiral_Trunk_Full"
    },
    {
      "x": -4,
      "y": 9,
      "z": -7,
      "name": "Plant_Coral_Block_White"
    },
    {
      "x": -2,
      "y": 9,
      "z": -7,
      "name": "Plant_Coral_Block_White"
    },
    {
      "x": -1,
      "y": 9,
      "z": -7,
      "name": "Plant_Coral_Block_White"
    },
    {
      "x": -13,
      "y": 10,
      "z": -7,
      "name": "Plant_Coral_Block_White"
    },
    {
      "x": -10,
      "y": 10,
      "z": -7,
      "name": "Plant_Coral_Block_White"
    },
    {
      "x": -4,
      "y": 10,
      "z": -7,
      "name": "Plant_Seaweed_Grass"
    },
    {
      "x": -2,
      "y": 10,
      "z": -7,
      "name": "Plant_Coral_Block_White"
    },
    {
      "x": -1,
      "y": 10,
      "z": -7,
      "name": "Plant_Coral_Block_White"
    },
    {
      "x": -14,
      "y": 11,
      "z": -7,
      "name": "Plant_Coral_Block_White"
    },
    {
      "x": -13,
      "y": 11,
      "z": -7,
      "name": "Plant_Coral_Block_White"
    },
    {
      "x": -10,
      "y": 11,
      "z": -7,
      "name": "Plant_Coral_Block_White"
    },
    {
      "x": -8,
      "y": 11,
      "z": -7,
      "name": "Plant_Coral_Block_White"
    },
    {
      "x": -7,
      "y": 11,
      "z": -7,
      "name": "Plant_Coral_Block_White"
    },
    {
      "x": -2,
      "y": 11,
      "z": -7,
      "name": "Plant_Seaweed_Moss_Stack"
    },
    {
      "x": -1,
      "y": 11,
      "z": -7,
      "name": "Plant_Seaweed_Moss_Stack"
    },
    {
      "x": -14,
      "y": 12,
      "z": -7,
      "name": "Plant_Seaweed_Moss_Stack"
    },
    {
      "x": -13,
      "y": 12,
      "z": -7,
      "name": "Plant_Seaweed_Moss_Stack"
    },
    {
      "x": -10,
      "y": 12,
      "z": -7,
      "name": "Plant_Seaweed_Moss_Stack"
    },
    {
      "x": -8,
      "y": 12,
      "z": -7,
      "name": "Plant_Seaweed_Moss_Stack"
    },
    {
      "x": -7,
      "y": 12,
      "z": -7,
      "name": "Plant_Seaweed_Moss_Stack"
    },
    {
      "x": -2,
      "y": 12,
      "z": -7,
      "name": "Plant_Seaweed_Moss_Stack"
    },
    {
      "x": -1,
      "y": 12,
      "z": -7,
      "name": "Plant_Seaweed_Moss_Stack"
    },
    {
      "x": -14,
      "y": 13,
      "z": -7,
      "name": "Plant_Seaweed_Moss_Stack"
    },
    {
      "x": -13,
      "y": 13,
      "z": -7,
      "name": "Plant_Seaweed_Moss_Stack"
    },
    {
      "x": -10,
      "y": 13,
      "z": -7,
      "name": "Plant_Seaweed_Moss_Stack"
    },
    {
      "x": -8,
      "y": 13,
      "z": -7,
      "name": "Plant_Seaweed_Moss_Stack"
    },
    {
      "x": -7,
      "y": 13,
      "z": -7,
      "name": "Plant_Seaweed_Moss_Stack"
    },
    {
      "x": -2,
      "y": 13,
      "z": -7,
      "name": "Plant_Seaweed_Moss_Stack"
    },
    {
      "x": -1,
      "y": 13,
      "z": -7,
      "name": "Plant_Seaweed_Moss_Stack"
    },
    {
      "x": -14,
      "y": 14,
      "z": -7,
      "name": "Plant_Seaweed_Moss_Stack"
    },
    {
      "x": -13,
      "y": 14,
      "z": -7,
      "name": "Plant_Seaweed_Moss_Stack"
    },
    {
      "x": -10,
      "y": 14,
      "z": -7,
      "name": "Plant_Seaweed_Moss_Stack"
    },
    {
      "x": -8,
      "y": 14,
      "z": -7,
      "name": "Plant_Seaweed_Moss_Stack"
    },
    {
      "x": -7,
      "y": 14,
      "z": -7,
      "name": "Plant_Seaweed_Moss_Stack"
    },
    {
      "x": -2,
      "y": 14,
      "z": -7,
      "name": "Plant_Seaweed_Moss_Stack"
    },
    {
      "x": -1,
      "y": 14,
      "z": -7,
      "name": "Plant_Seaweed_Moss_Stack"
    },
    {
      "x": -14,
      "y": 15,
      "z": -7,
      "name": "Plant_Seaweed_Moss_Stack"
    },
    {
      "x": -13,
      "y": 15,
      "z": -7,
      "name": "Plant_Seaweed_Moss_Stack"
    },
    {
      "x": -10,
      "y": 15,
      "z": -7,
      "name": "Plant_Seaweed_Moss_Stack"
    },
    {
      "x": -7,
      "y": 15,
      "z": -7,
      "name": "Plant_Seaweed_Moss_Stack"
    },
    {
      "x": -2,
      "y": 15,
      "z": -7,
      "name": "Plant_Seaweed_Moss_Stack"
    },
    {
      "x": -1,
      "y": 15,
      "z": -7,
      "name": "Plant_Seaweed_Moss_Stack"
    },
    {
      "x": -14,
      "y": 16,
      "z": -7,
      "name": "Plant_Seaweed_Moss_Stack"
    },
    {
      "x": -10,
      "y": 16,
      "z": -7,
      "name": "Plant_Seaweed_Moss_Stack"
    },
    {
      "x": -7,
      "y": 16,
      "z": -7,
      "name": "Plant_Seaweed_Moss_Stack"
    },
    {
      "x": -2,
      "y": 16,
      "z": -7,
      "name": "Plant_Seaweed_Moss_Stack"
    },
    {
      "x": -1,
      "y": 16,
      "z": -7,
      "name": "Plant_Seaweed_Moss_Stack"
    },
    {
      "x": -14,
      "y": 17,
      "z": -7,
      "name": "Plant_Seaweed_Moss_Stack"
    },
    {
      "x": -10,
      "y": 17,
      "z": -7,
      "name": "Plant_Seaweed_Moss_Stack"
    },
    {
      "x": -7,
      "y": 17,
      "z": -7,
      "name": "Plant_Seaweed_Moss_Stack"
    },
    {
      "x": -2,
      "y": 17,
      "z": -7,
      "name": "Plant_Seaweed_Moss_Stack"
    },
    {
      "x": -1,
      "y": 17,
      "z": -7,
      "name": "Plant_Seaweed_Moss_Stack"
    },
    {
      "x": -5,
      "y": 7,
      "z": -6,
      "name": "Wood_Spiral_Trunk_Full"
    },
    {
      "x": -4,
      "y": 7,
      "z": -6,
      "name": "Wood_Spiral_Trunk_Full"
    },
    {
      "x": -9,
      "y": 8,
      "z": -6,
      "name": "Wood_Spiral_Trunk_Full"
    },
    {
      "x": -12,
      "y": 9,
      "z": -6,
      "name": "Plant_Coral_Block_White"
    },
    {
      "x": -11,
      "y": 9,
      "z": -6,
      "name": "Plant_Coral_Block_White"
    },
    {
      "x": -10,
      "y": 9,
      "z": -6,
      "name": "Plant_Coral_Block_White"
    },
    {
      "x": -9,
      "y": 9,
      "z": -6,
      "name": "Wood_Spiral_Trunk_Full"
    },
    {
      "x": -5,
      "y": 9,
      "z": -6,
      "name": "Plant_Coral_Block_White"
    },
    {
      "x": -4,
      "y": 9,
      "z": -6,
      "name": "Plant_Coral_Block_White"
    },
    {
      "x": -1,
      "y": 9,
      "z": -6,
      "name": "Plant_Coral_Block_White"
    },
    {
      "x": -13,
      "y": 10,
      "z": -6,
      "name": "Plant_Coral_Block_White"
    },
    {
      "x": -12,
      "y": 10,
      "z": -6,
      "name": "Plant_Coral_Block_White"
    },
    {
      "x": -11,
      "y": 10,
      "z": -6,
      "name": "Plant_Seaweed_Moss_Stack"
    },
    {
      "x": -10,
      "y": 10,
      "z": -6,
      "name": "Plant_Seaweed_Grass"
    },
    {
      "x": -9,
      "y": 10,
      "z": -6,
      "name": "Plant_Coral_Block_White"
    },
    {
      "x": -5,
      "y": 10,
      "z": -6,
      "name": "Plant_Coral_Block_White"
    },
    {
      "x": -4,
      "y": 10,
      "z": -6,
      "name": "Plant_Seaweed_Grass"
    },
    {
      "x": -1,
      "y": 10,
      "z": -6,
      "name": "Plant_Seaweed_Grass_Tall"
    },
    {
      "x": -13,
      "y": 11,
      "z": -6,
      "name": "Plant_Seaweed_Moss_Stack"
    },
    {
      "x": -12,
      "y": 11,
      "z": -6,
      "name": "Plant_Seaweed_Grass_Tall"
    },
    {
      "x": -11,
      "y": 11,
      "z": -6,
      "name": "Plant_Seaweed_Moss_Stack"
    },
    {
      "x": -9,
      "y": 11,
      "z": -6,
      "name": "Plant_Seaweed_Moss_Stack"
    },
    {
      "x": -5,
      "y": 11,
      "z": -6,
      "name": "Plant_Coral_Block_White"
    },
    {
      "x": -3,
      "y": 11,
      "z": -6,
      "name": "Plant_Coral_Block_White"
    },
    {
      "x": -11,
      "y": 12,
      "z": -6,
      "name": "Plant_Seaweed_Moss_Stack"
    },
    {
      "x": -9,
      "y": 12,
      "z": -6,
      "name": "Plant_Seaweed_Moss_Stack"
    },
    {
      "x": -5,
      "y": 12,
      "z": -6,
      "name": "Plant_Seaweed_Grass_Tall"
    },
    {
      "x": -3,
      "y": 12,
      "z": -6,
      "name": "Plant_Coral_Block_White"
    },
    {
      "x": -9,
      "y": 13,
      "z": -6,
      "name": "Plant_Seaweed_Moss_Stack"
    },
    {
      "x": -6,
      "y": 13,
      "z": -6,
      "name": "Plant_Coral_Block_White"
    },
    {
      "x": -3,
      "y": 13,
      "z": -6,
      "name": "Plant_Seaweed_Moss_Stack"
    },
    {
      "x": -9,
      "y": 14,
      "z": -6,
      "name": "Plant_Seaweed_Moss_Stack"
    },
    {
      "x": -6,
      "y": 14,
      "z": -6,
      "name": "Plant_Coral_Block_White"
    },
    {
      "x": -3,
      "y": 14,
      "z": -6,
      "name": "Plant_Seaweed_Moss_Stack"
    },
    {
      "x": -9,
      "y": 15,
      "z": -6,
      "name": "Plant_Seaweed_Moss_Stack"
    },
    {
      "x": -6,
      "y": 15,
      "z": -6,
      "name": "Plant_Seaweed_Grass_Tall"
    },
    {
      "x": -3,
      "y": 15,
      "z": -6,
      "name": "Plant_Seaweed_Moss_Stack"
    },
    {
      "x": -9,
      "y": 16,
      "z": -6,
      "name": "Plant_Seaweed_Moss_Stack"
    },
    {
      "x": -9,
      "y": 17,
      "z": -6,
      "name": "Plant_Seaweed_Moss_Stack"
    },
    {
      "x": -5,
      "y": 6,
      "z": -5,
      "name": "Wood_Spiral_Trunk_Full"
    },
    {
      "x": -8,
      "y": 7,
      "z": -5,
      "name": "Wood_Spiral_Trunk_Full"
    },
    {
      "x": -5,
      "y": 7,
      "z": -5,
      "name": "Wood_Spiral_Trunk_Full"
    },
    {
      "x": -12,
      "y": 8,
      "z": -5,
      "name": "Plant_Coral_Block_White"
    },
    {
      "x": -10,
      "y": 8,
      "z": -5,
      "name": "Plant_Coral_Block_White"
    },
    {
      "x": -9,
      "y": 8,
      "z": -5,
      "name": "Wood_Spiral_Trunk_Full"
    },
    {
      "x": -8,
      "y": 8,
      "z": -5,
      "name": "Wood_Spiral_Trunk_Full"
    },
    {
      "x": -12,
      "y": 9,
      "z": -5,
      "name": "Plant_Seaweed_Moss_Stack"
    },
    {
      "x": -11,
      "y": 9,
      "z": -5,
      "name": "Plant_Coral_Block_White"
    },
    {
      "x": -10,
      "y": 9,
      "z": -5,
      "name": "Plant_Coral_Block_White"
    },
    {
      "x": -12,
      "y": 10,
      "z": -5,
      "name": "Plant_Seaweed_Moss_Stack"
    },
    {
      "x": -11,
      "y": 10,
      "z": -5,
      "name": "Plant_Coral_Block_White"
    },
    {
      "x": -10,
      "y": 10,
      "z": -5,
      "name": "Plant_Seaweed_Moss_Stack"
    },
    {
      "x": -9,
      "y": 10,
      "z": -5,
      "name": "Plant_Coral_Block_White"
    },
    {
      "x": -8,
      "y": 10,
      "z": -5,
      "name": "Plant_Coral_Block_White"
    },
    {
      "x": -2,
      "y": 10,
      "z": -5,
      "name": "Plant_Coral_Block_White"
    },
    {
      "x": -1,
      "y": 10,
      "z": -5,
      "name": "Plant_Coral_Block_White"
    },
    {
      "x": -12,
      "y": 11,
      "z": -5,
      "name": "Plant_Seaweed_Moss_Stack"
    },
    {
      "x": -11,
      "y": 11,
      "z": -5,
      "name": "Plant_Coral_Block_White"
    },
    {
      "x": -10,
      "y": 11,
      "z": -5,
      "name": "Plant_Seaweed_Moss_Stack"
    },
    {
      "x": -9,
      "y": 11,
      "z": -5,
      "name": "Plant_Coral_Block_White"
    },
    {
      "x": -8,
      "y": 11,
      "z": -5,
      "name": "Plant_Seaweed_Grass"
    },
    {
      "x": -7,
      "y": 11,
      "z": -5,
      "name": "Plant_Coral_Block_White"
    },
    {
      "x": -3,
      "y": 11,
      "z": -5,
      "name": "Plant_Coral_Block_White"
    },
    {
      "x": -2,
      "y": 11,
      "z": -5,
      "name": "Plant_Coral_Block_White"
    },
    {
      "x": -1,
      "y": 11,
      "z": -5,
      "name": "Plant_Seaweed_Grass"
    },
    {
      "x": -12,
      "y": 12,
      "z": -5,
      "name": "Plant_Seaweed_Moss_Stack"
    },
    {
      "x": -11,
      "y": 12,
      "z": -5,
      "name": "Plant_Coral_Block_White"
    },
    {
      "x": -10,
      "y": 12,
      "z": -5,
      "name": "Plant_Seaweed_Moss_Stack"
    },
    {
      "x": -9,
      "y": 12,
      "z": -5,
      "name": "Plant_Seaweed_Moss_Stack"
    },
    {
      "x": -7,
      "y": 12,
      "z": -5,
      "name": "Plant_Coral_Block_White"
    },
    {
      "x": -5,
      "y": 12,
      "z": -5,
      "name": "Plant_Coral_Block_White"
    },
    {
      "x": -4,
      "y": 12,
      "z": -5,
      "name": "Plant_Coral_Block_White"
    },
    {
      "x": -3,
      "y": 12,
      "z": -5,
      "name": "Plant_Seaweed_Grass_Tall"
    },
    {
      "x": -2,
      "y": 12,
      "z": -5,
      "name": "Plant_Seaweed_Grass_Tall"
    },
    {
      "x": -12,
      "y": 13,
      "z": -5,
      "name": "Plant_Seaweed_Moss_Stack"
    },
    {
      "x": -11,
      "y": 13,
      "z": -5,
      "name": "Plant_Seaweed_Grass_Tall"
    },
    {
      "x": -10,
      "y": 13,
      "z": -5,
      "name": "Plant_Seaweed_Moss_Stack"
    },
    {
      "x": -7,
      "y": 13,
      "z": -5,
      "name": "Plant_Coral_Block_White"
    },
    {
      "x": -5,
      "y": 13,
      "z": -5,
      "name": "Plant_Coral_Block_White"
    },
    {
      "x": -4,
      "y": 13,
      "z": -5,
      "name": "Plant_Seaweed_Moss_Stack"
    },
    {
      "x": -12,
      "y": 14,
      "z": -5,
      "name": "Plant_Seaweed_Moss_Stack"
    },
    {
      "x": -10,
      "y": 14,
      "z": -5,
      "name": "Plant_Seaweed_Moss_Stack"
    },
    {
      "x": -7,
      "y": 14,
      "z": -5,
      "name": "Plant_Coral_Block_White"
    },
    {
      "x": -5,
      "y": 14,
      "z": -5,
      "name": "Plant_Coral_Block_White"
    },
    {
      "x": -12,
      "y": 15,
      "z": -5,
      "name": "Plant_Seaweed_Moss_Stack"
    },
    {
      "x": -7,
      "y": 15,
      "z": -5,
      "name": "Plant_Seaweed_Moss_Stack"
    },
    {
      "x": -5,
      "y": 15,
      "z": -5,
      "name": "Plant_Coral_Block_White"
    },
    {
      "x": -12,
      "y": 16,
      "z": -5,
      "name": "Plant_Seaweed_Moss_Stack"
    },
    {
      "x": -7,
      "y": 16,
      "z": -5,
      "name": "Plant_Seaweed_Moss_Stack"
    },
    {
      "x": -5,
      "y": 16,
      "z": -5,
      "name": "Plant_Seaweed_Moss_Stack"
    },
    {
      "x": -12,
      "y": 17,
      "z": -5,
      "name": "Plant_Seaweed_Moss_Stack"
    },
    {
      "x": -7,
      "y": 17,
      "z": -5,
      "name": "Plant_Seaweed_Moss_Stack"
    },
    {
      "x": -5,
      "y": 17,
      "z": -5,
      "name": "Plant_Seaweed_Moss_Stack"
    },
    {
      "x": -7,
      "y": 6,
      "z": -4,
      "name": "Wood_Spiral_Trunk_Full"
    },
    {
      "x": -5,
      "y": 6,
      "z": -4,
      "name": "Wood_Spiral_Trunk_Full"
    },
    {
      "x": -8,
      "y": 7,
      "z": -4,
      "name": "Wood_Spiral_Trunk_Full"
    },
    {
      "x": -7,
      "y": 7,
      "z": -4,
      "name": "Wood_Spiral_Trunk_Full"
    },
    {
      "x": -5,
      "y": 7,
      "z": -4,
      "name": "Wood_Spiral_Trunk_Half"
    },
    {
      "x": -8,
      "y": 8,
      "z": -4,
      "name": "Wood_Spiral_Trunk_Half"
    },
    {
      "x": -1,
      "y": 8,
      "z": -4,
      "name": "Wood_Spiral_Trunk_Full"
    },
    {
      "x": -12,
      "y": 9,
      "z": -4,
      "name": "Plant_Coral_Block_White"
    },
    {
      "x": -2,
      "y": 9,
      "z": -4,
      "name": "Plant_Coral_Block_White"
    },
    {
      "x": -12,
      "y": 10,
      "z": -4,
      "name": "Plant_Coral_Block_White"
    },
    {
      "x": -11,
      "y": 10,
      "z": -4,
      "name": "Plant_Coral_Block_White"
    },
    {
      "x": -10,
      "y": 10,
      "z": -4,
      "name": "Plant_Coral_Block_White"
    },
    {
      "x": -9,
      "y": 10,
      "z": -4,
      "name": "Plant_Coral_Block_White"
    },
    {
      "x": -8,
      "y": 10,
      "z": -4,
      "name": "Plant_Coral_Block_White"
    },
    {
      "x": -2,
      "y": 10,
      "z": -4,
      "name": "Plant_Seaweed_Grass"
    },
    {
      "x": -1,
      "y": 10,
      "z": -4,
      "name": "Plant_Coral_Block_White"
    },
    {
      "x": -13,
      "y": 11,
      "z": -4,
      "name": "Plant_Coral_Block_White"
    },
    {
      "x": -12,
      "y": 11,
      "z": -4,
      "name": "Plant_Coral_Block_White"
    },
    {
      "x": -11,
      "y": 11,
      "z": -4,
      "name": "Plant_Seaweed_Moss_Stack"
    },
    {
      "x": -10,
      "y": 11,
      "z": -4,
      "name": "Plant_Coral_Block_White"
    },
    {
      "x": -9,
      "y": 11,
      "z": -4,
      "name": "Plant_Seaweed_Moss_Stack"
    },
    {
      "x": -8,
      "y": 11,
      "z": -4,
      "name": "Plant_Coral_Block_White"
    },
    {
      "x": -5,
      "y": 11,
      "z": -4,
      "name": "Plant_Coral_Block_White"
    },
    {
      "x": -1,
      "y": 11,
      "z": -4,
      "name": "Plant_Coral_Block_White"
    },
    {
      "x": -13,
      "y": 12,
      "z": -4,
      "name": "Plant_Seaweed_Moss_Stack"
    },
    {
      "x": -12,
      "y": 12,
      "z": -4,
      "name": "Plant_Coral_Block_White"
    },
    {
      "x": -11,
      "y": 12,
      "z": -4,
      "name": "Plant_Seaweed_Moss_Stack"
    },
    {
      "x": -10,
      "y": 12,
      "z": -4,
      "name": "Plant_Coral_Block_White"
    },
    {
      "x": -9,
      "y": 12,
      "z": -4,
      "name": "Plant_Seaweed_Moss_Stack"
    },
    {
      "x": -8,
      "y": 12,
      "z": -4,
      "name": "Plant_Coral_Block_White"
    },
    {
      "x": -7,
      "y": 12,
      "z": -4,
      "name": "Plant_Coral_Block_White"
    },
    {
      "x": -6,
      "y": 12,
      "z": -4,
      "name": "Plant_Coral_Block_White"
    },
    {
      "x": -5,
      "y": 12,
      "z": -4,
      "name": "Plant_Coral_Block_White"
    },
    {
      "x": -4,
      "y": 12,
      "z": -4,
      "name": "Plant_Coral_Block_White"
    },
    {
      "x": -3,
      "y": 12,
      "z": -4,
      "name": "Plant_Coral_Block_White"
    },
    {
      "x": -1,
      "y": 12,
      "z": -4,
      "name": "Plant_Seaweed_Grass_Tall"
    },
    {
      "x": -13,
      "y": 13,
      "z": -4,
      "name": "Plant_Seaweed_Moss_Stack"
    },
    {
      "x": -12,
      "y": 13,
      "z": -4,
      "name": "Plant_Seaweed_Moss_Stack"
    },
    {
      "x": -11,
      "y": 13,
      "z": -4,
      "name": "Plant_Seaweed_Moss_Stack"
    },
    {
      "x": -10,
      "y": 13,
      "z": -4,
      "name": "Plant_Coral_Block_White"
    },
    {
      "x": -9,
      "y": 13,
      "z": -4,
      "name": "Plant_Seaweed_Moss_Stack"
    },
    {
      "x": -8,
      "y": 13,
      "z": -4,
      "name": "Plant_Seaweed_Moss_Stack"
    },
    {
      "x": -7,
      "y": 13,
      "z": -4,
      "name": "Plant_Seaweed_Grass_Tall"
    },
    {
      "x": -6,
      "y": 13,
      "z": -4,
      "name": "Plant_Seaweed_Moss_Stack"
    },
    {
      "x": -5,
      "y": 13,
      "z": -4,
      "name": "Plant_Seaweed_Grass"
    },
    {
      "x": -4,
      "y": 13,
      "z": -4,
      "name": "Plant_Coral_Block_White"
    },
    {
      "x": -3,
      "y": 13,
      "z": -4,
      "name": "Plant_Coral_Block_White"
    },
    {
      "x": -13,
      "y": 14,
      "z": -4,
      "name": "Plant_Seaweed_Moss_Stack"
    },
    {
      "x": -12,
      "y": 14,
      "z": -4,
      "name": "Plant_Seaweed_Moss_Stack"
    },
    {
      "x": -11,
      "y": 14,
      "z": -4,
      "name": "Plant_Seaweed_Moss_Stack"
    },
    {
      "x": -10,
      "y": 14,
      "z": -4,
      "name": "Plant_Seaweed_Grass_Tall"
    },
    {
      "x": -9,
      "y": 14,
      "z": -4,
      "name": "Plant_Seaweed_Moss_Stack"
    },
    {
      "x": -6,
      "y": 14,
      "z": -4,
      "name": "Plant_Seaweed_Moss_Stack"
    },
    {
      "x": -4,
      "y": 14,
      "z": -4,
      "name": "Plant_Seaweed_Moss_Stack"
    },
    {
      "x": -3,
      "y": 14,
      "z": -4,
      "name": "Plant_Seaweed_Grass"
    },
    {
      "x": -13,
      "y": 15,
      "z": -4,
      "name": "Plant_Seaweed_Moss_Stack"
    },
    {
      "x": -12,
      "y": 15,
      "z": -4,
      "name": "Plant_Seaweed_Moss_Stack"
    },
    {
      "x": -11,
      "y": 15,
      "z": -4,
      "name": "Plant_Seaweed_Moss_Stack"
    },
    {
      "x": -9,
      "y": 15,
      "z": -4,
      "name": "Plant_Seaweed_Moss_Stack"
    },
    {
      "x": -6,
      "y": 15,
      "z": -4,
      "name": "Plant_Seaweed_Moss_Stack"
    },
    {
      "x": -4,
      "y": 15,
      "z": -4,
      "name": "Plant_Seaweed_Moss_Stack"
    },
    {
      "x": -13,
      "y": 16,
      "z": -4,
      "name": "Plant_Seaweed_Moss_Stack"
    },
    {
      "x": -12,
      "y": 16,
      "z": -4,
      "name": "Plant_Seaweed_Moss_Stack"
    },
    {
      "x": -11,
      "y": 16,
      "z": -4,
      "name": "Plant_Seaweed_Moss_Stack"
    },
    {
      "x": -9,
      "y": 16,
      "z": -4,
      "name": "Plant_Seaweed_Moss_Stack"
    },
    {
      "x": -6,
      "y": 16,
      "z": -4,
      "name": "Plant_Seaweed_Moss_Stack"
    },
    {
      "x": -4,
      "y": 16,
      "z": -4,
      "name": "Plant_Seaweed_Moss_Stack"
    },
    {
      "x": -12,
      "y": 17,
      "z": -4,
      "name": "Plant_Seaweed_Moss_Stack"
    },
    {
      "x": -11,
      "y": 17,
      "z": -4,
      "name": "Plant_Seaweed_Moss_Stack"
    },
    {
      "x": -9,
      "y": 17,
      "z": -4,
      "name": "Plant_Seaweed_Moss_Stack"
    },
    {
      "x": -6,
      "y": 17,
      "z": -4,
      "name": "Plant_Seaweed_Moss_Stack"
    },
    {
      "x": -4,
      "y": 17,
      "z": -4,
      "name": "Plant_Seaweed_Moss_Stack"
    },
    {
      "x": -7,
      "y": 6,
      "z": -3,
      "name": "Wood_Spiral_Trunk_Full"
    },
    {
      "x": -6,
      "y": 6,
      "z": -3,
      "name": "Wood_Spiral_Trunk_Full"
    },
    {
      "x": -5,
      "y": 6,
      "z": -3,
      "name": "Wood_Spiral_Trunk_Full"
    },
    {
      "x": -9,
      "y": 7,
      "z": -3,
      "name": "Wood_Spiral_Trunk_Full"
    },
    {
      "x": -8,
      "y": 7,
      "z": -3,
      "name": "Wood_Spiral_Trunk_Full"
    },
    {
      "x": -1,
      "y": 7,
      "z": -3,
      "name": "Wood_Spiral_Trunk_Full"
    },
    {
      "x": -1,
      "y": 8,
      "z": -3,
      "name": "Wood_Spiral_Trunk_Full"
    },
    {
      "x": -10,
      "y": 9,
      "z": -3,
      "name": "Plant_Coral_Block_White"
    },
    {
      "x": -12,
      "y": 10,
      "z": -3,
      "name": "Plant_Coral_Block_White"
    },
    {
      "x": -11,
      "y": 10,
      "z": -3,
      "name": "Plant_Coral_Block_White"
    },
    {
      "x": -10,
      "y": 10,
      "z": -3,
      "name": "Plant_Coral_Block_White"
    },
    {
      "x": -9,
      "y": 10,
      "z": -3,
      "name": "Plant_Coral_Block_White"
    },
    {
      "x": -8,
      "y": 10,
      "z": -3,
      "name": "Plant_Coral_Block_White"
    },
    {
      "x": -7,
      "y": 10,
      "z": -3,
      "name": "Plant_Coral_Block_White"
    },
    {
      "x": -5,
      "y": 10,
      "z": -3,
      "name": "Wood_Spiral_Trunk_Full"
    },
    {
      "x": -12,
      "y": 11,
      "z": -3,
      "name": "Plant_Seaweed_Moss_Stack"
    },
    {
      "x": -11,
      "y": 11,
      "z": -3,
      "name": "Plant_Seaweed_Grass"
    },
    {
      "x": -10,
      "y": 11,
      "z": -3,
      "name": "Plant_Seaweed_Moss_Stack"
    },
    {
      "x": -9,
      "y": 11,
      "z": -3,
      "name": "Plant_Coral_Block_White"
    },
    {
      "x": -8,
      "y": 11,
      "z": -3,
      "name": "Plant_Coral_Block_White"
    },
    {
      "x": -7,
      "y": 11,
      "z": -3,
      "name": "Plant_Seaweed_Grass_Tall"
    },
    {
      "x": -6,
      "y": 11,
      "z": -3,
      "name": "Plant_Coral_Block_White"
    },
    {
      "x": -5,
      "y": 11,
      "z": -3,
      "name": "Wood_Spiral_Trunk_Full"
    },
    {
      "x": -2,
      "y": 11,
      "z": -3,
      "name": "Plant_Coral_Block_White"
    },
    {
      "x": -1,
      "y": 11,
      "z": -3,
      "name": "Plant_Coral_Block_White"
    },
    {
      "x": -10,
      "y": 12,
      "z": -3,
      "name": "Plant_Seaweed_Moss_Stack"
    },
    {
      "x": -9,
      "y": 12,
      "z": -3,
      "name": "Plant_Seaweed_Moss_Stack"
    },
    {
      "x": -8,
      "y": 12,
      "z": -3,
      "name": "Plant_Seaweed_Moss_Stack"
    },
    {
      "x": -6,
      "y": 12,
      "z": -3,
      "name": "Plant_Seaweed_Grass_Tall"
    },
    {
      "x": -5,
      "y": 12,
      "z": -3,
      "name": "Wood_Spiral_Trunk_Full"
    },
    {
      "x": -4,
      "y": 12,
      "z": -3,
      "name": "Plant_Coral_Block_White"
    },
    {
      "x": -2,
      "y": 12,
      "z": -3,
      "name": "Plant_Coral_Block_White"
    },
    {
      "x": -1,
      "y": 12,
      "z": -3,
      "name": "Plant_Seaweed_Moss_Stack"
    },
    {
      "x": -9,
      "y": 13,
      "z": -3,
      "name": "Plant_Seaweed_Moss_Stack"
    },
    {
      "x": -5,
      "y": 13,
      "z": -3,
      "name": "Plant_Coral_Block_White"
    },
    {
      "x": -4,
      "y": 13,
      "z": -3,
      "name": "Plant_Seaweed_Moss_Stack"
    },
    {
      "x": -2,
      "y": 13,
      "z": -3,
      "name": "Plant_Seaweed_Grass"
    },
    {
      "x": -9,
      "y": 14,
      "z": -3,
      "name": "Plant_Seaweed_Moss_Stack"
    },
    {
      "x": -5,
      "y": 14,
      "z": -3,
      "name": "Plant_Coral_Block_White"
    },
    {
      "x": -4,
      "y": 14,
      "z": -3,
      "name": "Plant_Seaweed_Moss_Stack"
    },
    {
      "x": -3,
      "y": 14,
      "z": -3,
      "name": "Plant_Coral_Block_White"
    },
    {
      "x": -9,
      "y": 15,
      "z": -3,
      "name": "Plant_Seaweed_Moss_Stack"
    },
    {
      "x": -5,
      "y": 15,
      "z": -3,
      "name": "Plant_Seaweed_Grass_Tall"
    },
    {
      "x": -4,
      "y": 15,
      "z": -3,
      "name": "Plant_Seaweed_Moss_Stack"
    },
    {
      "x": -3,
      "y": 15,
      "z": -3,
      "name": "Plant_Seaweed_Moss_Stack"
    },
    {
      "x": -9,
      "y": 16,
      "z": -3,
      "name": "Plant_Seaweed_Moss_Stack"
    },
    {
      "x": -3,
      "y": 16,
      "z": -3,
      "name": "Plant_Seaweed_Moss_Stack"
    },
    {
      "x": -9,
      "y": 17,
      "z": -3,
      "name": "Plant_Seaweed_Moss_Stack"
    },
    {
      "x": -3,
      "y": 17,
      "z": -3,
      "name": "Plant_Seaweed_Moss_Stack"
    },
    {
      "x": -5,
      "y": 6,
      "z": -2,
      "name": "Wood_Spiral_Trunk_Full"
    },
    {
      "x": -4,
      "y": 6,
      "z": -2,
      "name": "Wood_Spiral_Trunk_Full"
    },
    {
      "x": -9,
      "y": 7,
      "z": -2,
      "name": "Wood_Spiral_Trunk_Full"
    },
    {
      "x": -2,
      "y": 7,
      "z": -2,
      "name": "Wood_Spiral_Trunk_Full"
    },
    {
      "x": -1,
      "y": 7,
      "z": -2,
      "name": "Wood_Spiral_Trunk_Full"
    },
    {
      "x": -10,
      "y": 8,
      "z": -2,
      "name": "Wood_Spiral_Trunk_Full"
    },
    {
      "x": -9,
      "y": 8,
      "z": -2,
      "name": "Wood_Spiral_Trunk_Full"
    },
    {
      "x": -4,
      "y": 8,
      "z": -2,
      "name": "Wood_Spiral_Trunk_Full"
    },
    {
      "x": -1,
      "y": 8,
      "z": -2,
      "name": "Wood_Spiral_Trunk_Half"
    },
    {
      "x": -11,
      "y": 9,
      "z": -2,
      "name": "Plant_Coral_Block_White"
    },
    {
      "x": -10,
      "y": 9,
      "z": -2,
      "name": "Wood_Spiral_Trunk_Full"
    },
    {
      "x": -4,
      "y": 9,
      "z": -2,
      "name": "Wood_Spiral_Trunk_Full"
    },
    {
      "x": -11,
      "y": 10,
      "z": -2,
      "name": "Plant_Seaweed_Grass_Tall"
    },
    {
      "x": -10,
      "y": 10,
      "z": -2,
      "name": "Wood_Spiral_Trunk_Full"
    },
    {
      "x": -9,
      "y": 10,
      "z": -2,
      "name": "Plant_Coral_Block_White"
    },
    {
      "x": -5,
      "y": 10,
      "z": -2,
      "name": "Wood_Spiral_Trunk_Full"
    },
    {
      "x": -4,
      "y": 10,
      "z": -2,
      "name": "Wood_Spiral_Trunk_Full"
    },
    {
      "x": -13,
      "y": 11,
      "z": -2,
      "name": "Plant_Coral_Block_White"
    },
    {
      "x": -10,
      "y": 11,
      "z": -2,
      "name": "Plant_Coral_Block_White"
    },
    {
      "x": -9,
      "y": 11,
      "z": -2,
      "name": "Plant_Seaweed_Moss_Stack"
    },
    {
      "x": -14,
      "y": 12,
      "z": -2,
      "name": "Plant_Coral_Block_White"
    },
    {
      "x": -13,
      "y": 12,
      "z": -2,
      "name": "Plant_Coral_Block_White"
    },
    {
      "x": -10,
      "y": 12,
      "z": -2,
      "name": "Plant_Coral_Block_White"
    },
    {
      "x": -9,
      "y": 12,
      "z": -2,
      "name": "Plant_Seaweed_Moss_Stack"
    },
    {
      "x": -8,
      "y": 12,
      "z": -2,
      "name": "Plant_Coral_Block_White"
    },
    {
      "x": -7,
      "y": 12,
      "z": -2,
      "name": "Plant_Coral_Block_White"
    },
    {
      "x": -6,
      "y": 12,
      "z": -2,
      "name": "Plant_Coral_Block_White"
    },
    {
      "x": -5,
      "y": 12,
      "z": -2,
      "name": "Plant_Coral_Block_White"
    },
    {
      "x": -4,
      "y": 12,
      "z": -2,
      "name": "Plant_Coral_Block_White"
    },
    {
      "x": -14,
      "y": 13,
      "z": -2,
      "name": "Plant_Seaweed_Moss_Stack"
    },
    {
      "x": -13,
      "y": 13,
      "z": -2,
      "name": "Plant_Seaweed_Moss_Stack"
    },
    {
      "x": -10,
      "y": 13,
      "z": -2,
      "name": "Plant_Seaweed_Moss_Stack"
    },
    {
      "x": -9,
      "y": 13,
      "z": -2,
      "name": "Plant_Seaweed_Moss_Stack"
    },
    {
      "x": -8,
      "y": 13,
      "z": -2,
      "name": "Plant_Coral_Block_White"
    },
    {
      "x": -7,
      "y": 13,
      "z": -2,
      "name": "Plant_Coral_Block_White"
    },
    {
      "x": -6,
      "y": 13,
      "z": -2,
      "name": "Plant_Seaweed_Moss_Stack"
    },
    {
      "x": -5,
      "y": 13,
      "z": -2,
      "name": "Plant_Seaweed_Moss_Stack"
    },
    {
      "x": -4,
      "y": 13,
      "z": -2,
      "name": "Plant_Coral_Block_White"
    },
    {
      "x": -14,
      "y": 14,
      "z": -2,
      "name": "Plant_Seaweed_Moss_Stack"
    },
    {
      "x": -13,
      "y": 14,
      "z": -2,
      "name": "Plant_Seaweed_Moss_Stack"
    },
    {
      "x": -10,
      "y": 14,
      "z": -2,
      "name": "Plant_Seaweed_Moss_Stack"
    },
    {
      "x": -9,
      "y": 14,
      "z": -2,
      "name": "Plant_Seaweed_Moss_Stack"
    },
    {
      "x": -8,
      "y": 14,
      "z": -2,
      "name": "Plant_Seaweed_Grass"
    },
    {
      "x": -7,
      "y": 14,
      "z": -2,
      "name": "Plant_Seaweed_Moss_Stack"
    },
    {
      "x": -6,
      "y": 14,
      "z": -2,
      "name": "Plant_Seaweed_Moss_Stack"
    },
    {
      "x": -5,
      "y": 14,
      "z": -2,
      "name": "Plant_Seaweed_Moss_Stack"
    },
    {
      "x": -4,
      "y": 14,
      "z": -2,
      "name": "Plant_Seaweed_Grass"
    },
    {
      "x": -14,
      "y": 15,
      "z": -2,
      "name": "Plant_Seaweed_Moss_Stack"
    },
    {
      "x": -10,
      "y": 15,
      "z": -2,
      "name": "Plant_Seaweed_Moss_Stack"
    },
    {
      "x": -9,
      "y": 15,
      "z": -2,
      "name": "Plant_Seaweed_Moss_Stack"
    },
    {
      "x": -7,
      "y": 15,
      "z": -2,
      "name": "Plant_Seaweed_Moss_Stack"
    },
    {
      "x": -5,
      "y": 15,
      "z": -2,
      "name": "Plant_Seaweed_Moss_Stack"
    },
    {
      "x": -10,
      "y": 16,
      "z": -2,
      "name": "Plant_Seaweed_Moss_Stack"
    },
    {
      "x": -9,
      "y": 16,
      "z": -2,
      "name": "Plant_Seaweed_Moss_Stack"
    },
    {
      "x": -7,
      "y": 16,
      "z": -2,
      "name": "Plant_Seaweed_Moss_Stack"
    },
    {
      "x": -5,
      "y": 16,
      "z": -2,
      "name": "Plant_Seaweed_Moss_Stack"
    },
    {
      "x": -10,
      "y": 17,
      "z": -2,
      "name": "Plant_Seaweed_Moss_Stack"
    },
    {
      "x": -9,
      "y": 17,
      "z": -2,
      "name": "Plant_Seaweed_Moss_Stack"
    },
    {
      "x": -7,
      "y": 17,
      "z": -2,
      "name": "Plant_Seaweed_Moss_Stack"
    },
    {
      "x": -5,
      "y": 17,
      "z": -2,
      "name": "Plant_Seaweed_Moss_Stack"
    },
    {
      "x": -5,
      "y": 34,
      "z": -5,
      "name": "Plant_Seaweed_Moss_Stack"
    },
    {
      "x": -5,
      "y": 35,
      "z": -5,
      "name": "Plant_Seaweed_Moss_Stack"
    },
    {
      "x": -5,
      "y": 36,
      "z": -5,
      "name": "Plant_Seaweed_Moss_Stack"
    },
    {
      "x": -4,
      "y": 6,
      "z": -1,
      "name": "Wood_Spiral_Trunk_Full"
    },
    {
      "x": -3,
      "y": 6,
      "z": -1,
      "name": "Wood_Spiral_Trunk_Full"
    },
    {
      "x": -2,
      "y": 6,
      "z": -1,
      "name": "Wood_Spiral_Trunk_Full"
    },
    {
      "x": -3,
      "y": 7,
      "z": -1,
      "name": "Wood_Spiral_Trunk_Full"
    },
    {
      "x": -2,
      "y": 7,
      "z": -1,
      "name": "Wood_Spiral_Trunk_Full"
    },
    {
      "x": -4,
      "y": 8,
      "z": -1,
      "name": "Wood_Spiral_Trunk_Full"
    },
    {
      "x": -3,
      "y": 8,
      "z": -1,
      "name": "Wood_Spiral_Trunk_Full"
    },
    {
      "x": -12,
      "y": 10,
      "z": -1,
      "name": "Plant_Coral_Block_White"
    },
    {
      "x": -11,
      "y": 10,
      "z": -1,
      "name": "Plant_Coral_Block_White"
    },
    {
      "x": -10,
      "y": 10,
      "z": -1,
      "name": "Plant_Coral_Block_White"
    },
    {
      "x": -9,
      "y": 10,
      "z": -1,
      "name": "Plant_Coral_Block_White"
    },
    {
      "x": -13,
      "y": 11,
      "z": -1,
      "name": "Plant_Coral_Block_White"
    },
    {
      "x": -12,
      "y": 11,
      "z": -1,
      "name": "Plant_Coral_Block_White"
    },
    {
      "x": -11,
      "y": 11,
      "z": -1,
      "name": "Plant_Seaweed_Grass_Tall"
    },
    {
      "x": -10,
      "y": 11,
      "z": -1,
      "name": "Plant_Seaweed_Grass_Tall"
    },
    {
      "x": -9,
      "y": 11,
      "z": -1,
      "name": "Plant_Coral_Block_White"
    },
    {
      "x": -7,
      "y": 11,
      "z": -1,
      "name": "Plant_Coral_Block_White"
    },
    {
      "x": -5,
      "y": 11,
      "z": -1,
      "name": "Plant_Coral_Block_White"
    },
    {
      "x": -13,
      "y": 12,
      "z": -1,
      "name": "Plant_Seaweed_Moss_Stack"
    },
    {
      "x": -12,
      "y": 12,
      "z": -1,
      "name": "Plant_Seaweed_Grass"
    },
    {
      "x": -9,
      "y": 12,
      "z": -1,
      "name": "Plant_Seaweed_Moss_Stack"
    },
    {
      "x": -7,
      "y": 12,
      "z": -1,
      "name": "Plant_Seaweed_Moss_Stack"
    },
    {
      "x": -6,
      "y": 12,
      "z": -1,
      "name": "Plant_Coral_Block_White"
    },
    {
      "x": -5,
      "y": 12,
      "z": -1,
      "name": "Plant_Seaweed_Moss_Stack"
    },
    {
      "x": -13,
      "y": 13,
      "z": -1,
      "name": "Plant_Seaweed_Moss_Stack"
    },
    {
      "x": -9,
      "y": 13,
      "z": -1,
      "name": "Plant_Seaweed_Moss_Stack"
    },
    {
      "x": -6,
      "y": 13,
      "z": -1,
      "name": "Plant_Coral_Block_White"
    },
    {
      "x": -5,
      "y": 13,
      "z": -1,
      "name": "Plant_Seaweed_Moss_Stack"
    },
    {
      "x": -4,
      "y": 13,
      "z": -1,
      "name": "Plant_Coral_Block_White"
    },
    {
      "x": -3,
      "y": 13,
      "z": -1,
      "name": "Plant_Coral_Block_White"
    },
    {
      "x": -13,
      "y": 14,
      "z": -1,
      "name": "Plant_Seaweed_Moss_Stack"
    },
    {
      "x": -9,
      "y": 14,
      "z": -1,
      "name": "Plant_Seaweed_Moss_Stack"
    },
    {
      "x": -6,
      "y": 14,
      "z": -1,
      "name": "Plant_Seaweed_Grass_Tall"
    },
    {
      "x": -5,
      "y": 14,
      "z": -1,
      "name": "Plant_Seaweed_Moss_Stack"
    },
    {
      "x": -4,
      "y": 14,
      "z": -1,
      "name": "Plant_Coral_Block_White"
    },
    {
      "x": -3,
      "y": 14,
      "z": -1,
      "name": "Plant_Seaweed_Grass_Tall"
    },
    {
      "x": -13,
      "y": 15,
      "z": -1,
      "name": "Plant_Seaweed_Moss_Stack"
    },
    {
      "x": -4,
      "y": 15,
      "z": -1,
      "name": "Plant_Seaweed_Grass_Tall"
    },
    {
      "x": -13,
      "y": 16,
      "z": -1,
      "name": "Plant_Seaweed_Moss_Stack"
    },
    {
      "x": -13,
      "y": 17,
      "z": -1,
      "name": "Plant_Seaweed_Moss_Stack"
    },
    {
      "x": -2,
      "y": 7,
      "z": 0,
      "name": "Wood_Spiral_Trunk_Full"
    },
    {
      "x": -1,
      "y": 7,
      "z": 0,
      "name": "Wood_Spiral_Trunk_Full"
    },
    {
      "x": -1,
      "y": 8,
      "z": 0,
      "name": "Wood_Spiral_Trunk_Half"
    },
    {
      "x": -12,
      "y": 9,
      "z": 0,
      "name": "Plant_Coral_Block_White"
    },
    {
      "x": -10,
      "y": 9,
      "z": 0,
      "name": "Plant_Coral_Block_White"
    },
    {
      "x": -12,
      "y": 10,
      "z": 0,
      "name": "Plant_Seaweed_Moss_Stack"
    },
    {
      "x": -11,
      "y": 10,
      "z": 0,
      "name": "Plant_Coral_Block_White"
    },
    {
      "x": -10,
      "y": 10,
      "z": 0,
      "name": "Plant_Seaweed_Moss_Stack"
    },
    {
      "x": -12,
      "y": 11,
      "z": 0,
      "name": "Plant_Seaweed_Moss_Stack"
    },
    {
      "x": -11,
      "y": 11,
      "z": 0,
      "name": "Plant_Coral_Block_White"
    },
    {
      "x": -10,
      "y": 11,
      "z": 0,
      "name": "Plant_Seaweed_Moss_Stack"
    },
    {
      "x": -9,
      "y": 11,
      "z": 0,
      "name": "Plant_Coral_Block_White"
    },
    {
      "x": -8,
      "y": 11,
      "z": 0,
      "name": "Plant_Coral_Block_White"
    },
    {
      "x": -12,
      "y": 12,
      "z": 0,
      "name": "Plant_Seaweed_Moss_Stack"
    },
    {
      "x": -11,
      "y": 12,
      "z": 0,
      "name": "Plant_Seaweed_Moss_Stack"
    },
    {
      "x": -10,
      "y": 12,
      "z": 0,
      "name": "Plant_Seaweed_Moss_Stack"
    },
    {
      "x": -9,
      "y": 12,
      "z": 0,
      "name": "Plant_Coral_Block_White"
    },
    {
      "x": -8,
      "y": 12,
      "z": 0,
      "name": "Plant_Seaweed_Moss_Stack"
    },
    {
      "x": -12,
      "y": 13,
      "z": 0,
      "name": "Plant_Seaweed_Moss_Stack"
    },
    {
      "x": -11,
      "y": 13,
      "z": 0,
      "name": "Plant_Seaweed_Moss_Stack"
    },
    {
      "x": -9,
      "y": 13,
      "z": 0,
      "name": "Plant_Seaweed_Grass_Tall"
    },
    {
      "x": -8,
      "y": 13,
      "z": 0,
      "name": "Plant_Seaweed_Moss_Stack"
    },
    {
      "x": -7,
      "y": 13,
      "z": 0,
      "name": "Plant_Coral_Block_White"
