{
  "version": 8,
  "blockIdVersion": 10,
  "anchorX": 0,
  "anchorY": 0,
  "anchorZ": 0,
  "blocks": [
    {
      "x": 6,
      "y": 13,
      "z": 0,
      "name": "Plant_Seaweed_Wet_Stack"
    },
    {
      "x": 7,
      "y": 13,
      "z": 0,
      "name": "Plant_Seaweed_Wet_Stack"
    },
    {
      "x": 8,
      "y": 13,
      "z": 0,
      "name": "Plant_Seaweed_Wet_Stack"
    },
    {
      "x": 9,
      "y": 13,
      "z": 0,
      "name": "Plant_Seaweed_Wet_Stack"
    },
    {
      "x": 10,
      "y": 13,
      "z": 0,
      "name": "Plant_Seaweed_Wet_Stack"
    },
    {
      "x": 6,
      "y": 14,
      "z": 0,
      "name": "Plant_Seaweed_Wet_Stack"
    },
    {
      "x": 7,
      "y": 14,
      "z": 0,
      "name": "Plant_Seaweed_Wet_Stack"
    },
    {
      "x": 8,
      "y": 14,
      "z": 0,
      "name": "Plant_Seaweed_Wet_Stack"
    },
    {
      "x": 9,
      "y": 14,
      "z": 0,
      "name": "Plant_Seaweed_Wet_Stack"
    },
    {
      "x": 10,
      "y": 14,
      "z": 0,
      "name": "Plant_Seaweed_Wet_Stack"
    },
    {
      "x": 6,
      "y": 15,
      "z": 0,
      "name": "Plant_Seaweed_Wet_Stack"
    },
    {
      "x": 7,
      "y": 15,
      "z": 0,
      "name": "Plant_Seaweed_Wet_Stack"
    },
    {
      "x": 9,
      "y": 15,
      "z": 0,
      "name": "Plant_Seaweed_Wet_Stack"
    },
    {
      "x": 10,
      "y": 15,
      "z": 0,
      "name": "Plant_Seaweed_Wet_Stack"
    },
    {
      "x": 4,
      "y": 13,
      "z": 1,
      "name": "Plant_Seaweed_Wet_Stack"
    },
    {
      "x": 5,
      "y": 13,
      "z": 1,
      "name": "Plant_Seaweed_Wet_Stack"
    },
    {
      "x": 6,
      "y": 13,
      "z": 1,
      "name": "Plant_Seaweed_Wet_Stack"
    },
    {
      "x": 7,
      "y": 13,
      "z": 1,
      "name": "Plant_Seaweed_Wet_Stack"
    },
    {
      "x": 8,
      "y": 13,
      "z": 1,
      "name": "Plant_Seaweed_Wet_Stack"
    },
    {
      "x": 4,
      "y": 14,
      "z": 1,
      "name": "Plant_Seaweed_Wet_Stack"
    },
    {
      "x": 5,
      "y": 14,
      "z": 1,
      "name": "Plant_Seaweed_Wet_Stack"
    },
    {
      "x": 6,
      "y": 14,
      "z": 1,
      "name": "Plant_Seaweed_Wet_Stack"
    },
    {
      "x": 7,
      "y": 14,
      "z": 1,
      "name": "Plant_Seaweed_Wet_Stack"
    },
    {
      "x": 8,
      "y": 14,
      "z": 1,
      "name": "Plant_Seaweed_Wet_Stack"
    },
    {
      "x": 5,
      "y": 15,
      "z": 1,
      "name": "Plant_Seaweed_Wet_Stack"
    },
    {
      "x": 7,
      "y": 15,
      "z": 1,
      "name": "Plant_Seaweed_Wet_Stack"
    },
    {
      "x": 5,
      "y": 16,
      "z": 1,
      "name": "Plant_Seaweed_Wet_Stack"
    },
    {
      "x": 3,
      "y": 13,
      "z": 2,
      "name": "Plant_Seaweed_Wet_Stack"
    },
    {
      "x": 4,
      "y": 13,
      "z": 2,
      "name": "Plant_Seaweed_Wet_Stack"
    },
    {
      "x": 6,
      "y": 13,
      "z": 2,
      "name": "Plant_Seaweed_Wet_Stack"
    },
    {
      "x": 7,
      "y": 13,
      "z": 2,
      "name": "Plant_Seaweed_Wet_Stack"
    },
    {
      "x": 8,
      "y": 13,
      "z": 2,
      "name": "Plant_Seaweed_Wet_Stack"
    },
    {
      "x": 9,
      "y": 13,
      "z": 2,
      "name": "Plant_Seaweed_Wet_Stack"
    },
    {
      "x": 6,
      "y": 14,
      "z": 2,
      "name": "Plant_Seaweed_Wet_Stack"
    },
    {
      "x": 7,
      "y": 14,
      "z": 2,
      "name": "Plant_Seaweed_Wet_Stack"
    },
    {
      "x": 8,
      "y": 14,
      "z": 2,
      "name": "Plant_Seaweed_Wet_Stack"
    },
    {
      "x": 8,
      "y": 15,
      "z": 2,
      "name": "Plant_Seaweed_Wet_Stack"
    },
    {
      "x": 6,
      "y": 13,
      "z": 3,
      "name": "Plant_Seaweed_Wet_Stack"
    },
    {
      "x": 7,
      "y": 13,
      "z": 3,
      "name": "Plant_Seaweed_Wet_Stack"
    },
    {
      "x": 6,
      "y": 14,
      "z": 3,
      "name": "Plant_Seaweed_Wet_Stack"
    },
    {
      "x": 7,
      "y": 14,
      "z": 3,
      "name": "Plant_Seaweed_Wet_Stack"
    },
    {
      "x": 7,
      "y": 15,
      "z": 3,
      "name": "Plant_Seaweed_Wet_Stack"
    },
    {
      "x": 0,
      "y": 13,
      "z": 11,
      "name": "Plant_Seaweed_Wet_Stack"
    },
    {
      "x": 0,
      "y": 13,
      "z": 12,
      "name": "Plant_Seaweed_Wet_Stack"
    },
    {
      "x": 0,
      "y": 13,
      "z": 14,
      "name": "Plant_Seaweed_Wet_Stack"
    },
    {
      "x": 7,
      "y": 6,
      "z": -14,
      "name": "Plant_Moss_Block_Green"
    },
    {
      "x": 2,
      "y": 7,
      "z": -14,
      "name": "Plant_Moss_Block_Green"
    },
    {
      "x": 7,
      "y": 7,
      "z": -14,
      "name": "Plant_Seaweed_Wet_Stack"
    },
    {
      "x": 2,
      "y": 8,
      "z": -14,
      "name": "Plant_Seaweed_Wet_Stack"
    },
    {
      "x": 7,
      "y": 8,
      "z": -14,
      "name": "Plant_Seaweed_Wet_Stack"
    },
    {
      "x": 2,
      "y": 9,
      "z": -14,
      "name": "Plant_Seaweed_Wet_Stack"
    },
    {
      "x": 7,
      "y": 9,
      "z": -14,
      "name": "Plant_Seaweed_Wet_Stack"
    },
    {
      "x": 2,
      "y": 10,
      "z": -14,
      "name": "Plant_Seaweed_Wet_Stack"
    },
    {
      "x": 7,
      "y": 10,
      "z": -14,
      "name": "Plant_Seaweed_Wet_Stack"
    },
    {
      "x": 2,
      "y": 11,
      "z": -14,
      "name": "Plant_Seaweed_Wet_Stack"
    },
    {
      "x": 7,
      "y": 11,
      "z": -14,
      "name": "Plant_Seaweed_Wet_Stack"
    },
    {
      "x": 2,
      "y": 12,
      "z": -14,
      "name": "Plant_Seaweed_Wet_Stack"
    },
    {
      "x": 7,
      "y": 12,
      "z": -14,
      "name": "Plant_Seaweed_Wet_Stack"
    },
    {
      "x": 6,
      "y": 5,
      "z": -13,
      "name": "Plant_Moss_Block_Green"
    },
    {
      "x": 7,
      "y": 5,
      "z": -13,
      "name": "Plant_Moss_Block_Green"
    },
    {
      "x": 9,
      "y": 5,
      "z": -13,
      "name": "Plant_Moss_Block_Green"
    },
    {
      "x": 1,
      "y": 6,
      "z": -13,
      "name": "Plant_Moss_Block_Green"
    },
    {
      "x": 2,
      "y": 6,
      "z": -13,
      "name": "Plant_Moss_Block_Green"
    },
    {
      "x": 4,
      "y": 6,
      "z": -13,
      "name": "Plant_Moss_Block_Green"
    },
    {
      "x": 6,
      "y": 6,
      "z": -13,
      "name": "Plant_Seaweed_Wet_Stack"
    },
    {
      "x": 7,
      "y": 6,
      "z": -13,
      "name": "Plant_Moss_Block_Green"
    },
    {
      "x": 9,
      "y": 6,
      "z": -13,
      "name": "Plant_Seaweed_Wet_Stack"
    },
    {
      "x": 1,
      "y": 7,
      "z": -13,
      "name": "Plant_Seaweed_Wet_Stack"
    },
    {
      "x": 2,
      "y": 7,
      "z": -13,
      "name": "Plant_Moss_Block_Green"
    },
    {
      "x": 4,
      "y": 7,
      "z": -13,
      "name": "Plant_Seaweed_Wet_Stack"
    },
    {
      "x": 6,
      "y": 7,
      "z": -13,
      "name": "Plant_Seaweed_Wet_Stack"
    },
    {
      "x": 7,
      "y": 7,
      "z": -13,
      "name": "Plant_Seaweed_Wet_Stack"
    },
    {
      "x": 9,
      "y": 7,
      "z": -13,
      "name": "Plant_Seaweed_Wet_Stack"
    },
    {
      "x": 1,
      "y": 8,
      "z": -13,
      "name": "Plant_Seaweed_Wet_Stack"
    },
    {
      "x": 2,
      "y": 8,
      "z": -13,
      "name": "Plant_Seaweed_Wet_Stack"
    },
    {
      "x": 4,
      "y": 8,
      "z": -13,
      "name": "Plant_Seaweed_Wet_Stack"
    },
    {
      "x": 6,
      "y": 8,
      "z": -13,
      "name": "Plant_Seaweed_Wet_Stack"
    },
    {
      "x": 7,
      "y": 8,
      "z": -13,
      "name": "Plant_Seaweed_Wet_Stack"
    },
    {
      "x": 9,
      "y": 8,
      "z": -13,
      "name": "Plant_Seaweed_Wet_Stack"
    },
    {
      "x": 1,
      "y": 9,
      "z": -13,
      "name": "Plant_Seaweed_Wet_Stack"
    },
    {
      "x": 2,
      "y": 9,
      "z": -13,
      "name": "Plant_Seaweed_Wet_Stack"
    },
    {
      "x": 4,
      "y": 9,
      "z": -13,
      "name": "Plant_Seaweed_Wet_Stack"
    },
    {
      "x": 6,
      "y": 9,
      "z": -13,
      "name": "Plant_Seaweed_Wet_Stack"
    },
    {
      "x": 7,
      "y": 9,
      "z": -13,
      "name": "Plant_Seaweed_Wet_Stack"
    },
    {
      "x": 9,
      "y": 9,
      "z": -13,
      "name": "Plant_Seaweed_Wet_Stack"
    },
    {
      "x": 1,
      "y": 10,
      "z": -13,
      "name": "Plant_Seaweed_Wet_Stack"
    },
    {
      "x": 2,
      "y": 10,
      "z": -13,
      "name": "Plant_Seaweed_Wet_Stack"
    },
    {
      "x": 4,
      "y": 10,
      "z": -13,
      "name": "Plant_Seaweed_Wet_Stack"
    },
    {
      "x": 6,
      "y": 10,
      "z": -13,
      "name": "Plant_Seaweed_Wet_Stack"
    },
    {
      "x": 7,
      "y": 10,
      "z": -13,
      "name": "Plant_Seaweed_Wet_Stack"
    },
    {
      "x": 9,
      "y": 10,
      "z": -13,
      "name": "Plant_Seaweed_Wet_Stack"
    },
    {
      "x": 1,
      "y": 11,
      "z": -13,
      "name": "Plant_Seaweed_Wet_Stack"
    },
    {
      "x": 2,
      "y": 11,
      "z": -13,
      "name": "Plant_Seaweed_Wet_Stack"
    },
    {
      "x": 4,
      "y": 11,
      "z": -13,
      "name": "Plant_Seaweed_Wet_Stack"
    },
    {
      "x": 6,
      "y": 11,
      "z": -13,
      "name": "Plant_Seaweed_Wet_Stack"
    },
    {
      "x": 7,
      "y": 11,
      "z": -13,
      "name": "Plant_Seaweed_Wet_Stack"
    },
    {
      "x": 9,
      "y": 11,
      "z": -13,
      "name": "Plant_Seaweed_Wet_Stack"
    },
    {
      "x": 1,
      "y": 12,
      "z": -13,
      "name": "Plant_Seaweed_Wet_Stack"
    },
    {
      "x": 2,
      "y": 12,
      "z": -13,
      "name": "Plant_Seaweed_Wet_Stack"
    },
    {
      "x": 4,
      "y": 12,
      "z": -13,
      "name": "Plant_Seaweed_Wet_Stack"
    },
    {
      "x": 6,
      "y": 12,
      "z": -13,
      "name": "Plant_Seaweed_Wet_Stack"
    },
    {
      "x": 7,
      "y": 12,
      "z": -13,
      "name": "Plant_Seaweed_Wet_Stack"
    },
    {
      "x": 9,
      "y": 12,
      "z": -13,
      "name": "Plant_Seaweed_Wet_Stack"
    },
    {
      "x": 5,
      "y": 3,
      "z": -12,
      "name": "Plant_Moss_Block_Green"
    },
    {
      "x": 9,
      "y": 3,
      "z": -12,
      "name": "Plant_Moss_Block_Green"
    },
    {
      "x": 0,
      "y": 4,
      "z": -12,
      "name": "Plant_Moss_Block_Green"
    },
    {
      "x": 4,
      "y": 4,
      "z": -12,
      "name": "Plant_Moss_Block_Green"
    },
    {
      "x": 5,
      "y": 4,
      "z": -12,
      "name": "Plant_Seaweed_Wet_Stack"
    },
    {
      "x": 6,
      "y": 4,
      "z": -12,
      "name": "Plant_Moss_Block_Green"
    },
    {
      "x": 8,
      "y": 4,
      "z": -12,
      "name": "Plant_Moss_Block_Green"
    },
    {
      "x": 9,
      "y": 4,
      "z": -12,
      "name": "Plant_Moss_Block_Green"
    },
    {
      "x": 0,
      "y": 5,
      "z": -12,
      "name": "Plant_Seaweed_Wet_Stack"
    },
    {
      "x": 1,
      "y": 5,
      "z": -12,
      "name": "Plant_Moss_Block_Green"
    },
    {
      "x": 3,
      "y": 5,
      "z": -12,
      "name": "Plant_Moss_Block_Green"
    },
    {
      "x": 4,
      "y": 5,
      "z": -12,
      "name": "Plant_Moss_Block_Green"
    },
    {
      "x": 5,
      "y": 5,
      "z": -12,
      "name": "Plant_Seaweed_Wet_Stack"
    },
    {
      "x": 6,
      "y": 5,
      "z": -12,
      "name": "Plant_Moss_Block_Green"
    },
    {
      "x": 8,
      "y": 5,
      "z": -12,
      "name": "Plant_Seaweed_Wet_Stack"
    },
    {
      "x": 9,
      "y": 5,
      "z": -12,
      "name": "Plant_Moss_Block_Green"
    },
    {
      "x": 0,
      "y": 6,
      "z": -12,
      "name": "Plant_Seaweed_Wet_Stack"
    },
    {
      "x": 1,
      "y": 6,
      "z": -12,
      "name": "Plant_Moss_Block_Green"
    },
    {
      "x": 3,
      "y": 6,
      "z": -12,
      "name": "Plant_Seaweed_Wet_Stack"
    },
    {
      "x": 4,
      "y": 6,
      "z": -12,
      "name": "Plant_Moss_Block_Green"
    },
    {
      "x": 5,
      "y": 6,
      "z": -12,
      "name": "Plant_Seaweed_Wet_Stack"
    },
    {
      "x": 6,
      "y": 6,
      "z": -12,
      "name": "Plant_Seaweed_Wet_Stack"
    },
    {
      "x": 8,
      "y": 6,
      "z": -12,
      "name": "Plant_Seaweed_Wet_Stack"
    },
    {
      "x": 9,
      "y": 6,
      "z": -12,
      "name": "Plant_Moss_Block_Green"
    },
    {
      "x": 0,
      "y": 7,
      "z": -12,
      "name": "Plant_Seaweed_Wet_Stack"
    },
    {
      "x": 1,
      "y": 7,
      "z": -12,
      "name": "Plant_Seaweed_Wet_Stack"
    },
    {
      "x": 3,
      "y": 7,
      "z": -12,
      "name": "Plant_Seaweed_Wet_Stack"
    },
    {
      "x": 4,
      "y": 7,
      "z": -12,
      "name": "Plant_Moss_Block_Green"
    },
    {
      "x": 5,
      "y": 7,
      "z": -12,
      "name": "Plant_Seaweed_Wet_Stack"
    },
    {
      "x": 6,
      "y": 7,
      "z": -12,
      "name": "Plant_Seaweed_Wet_Stack"
    },
    {
      "x": 8,
      "y": 7,
      "z": -12,
      "name": "Plant_Seaweed_Wet_Stack"
    },
    {
      "x": 9,
      "y": 7,
      "z": -12,
      "name": "Plant_Seaweed_Wet_Stack"
    },
    {
      "x": 0,
      "y": 8,
      "z": -12,
      "name": "Plant_Seaweed_Wet_Stack"
    },
    {
      "x": 1,
      "y": 8,
      "z": -12,
      "name": "Plant_Seaweed_Wet_Stack"
    },
    {
      "x": 3,
      "y": 8,
      "z": -12,
      "name": "Plant_Seaweed_Wet_Stack"
    },
    {
      "x": 4,
      "y": 8,
      "z": -12,
      "name": "Plant_Seaweed_Wet_Stack"
    },
    {
      "x": 5,
      "y": 8,
      "z": -12,
      "name": "Plant_Seaweed_Wet_Stack"
    },
    {
      "x": 6,
      "y": 8,
      "z": -12,
      "name": "Plant_Seaweed_Wet_Stack"
    },
    {
      "x": 8,
      "y": 8,
      "z": -12,
      "name": "Plant_Seaweed_Wet_Stack"
    },
    {
      "x": 9,
      "y": 8,
      "z": -12,
      "name": "Plant_Seaweed_Wet_Stack"
    },
    {
      "x": 0,
      "y": 9,
      "z": -12,
      "name": "Plant_Seaweed_Wet_Stack"
    },
    {
      "x": 1,
      "y": 9,
      "z": -12,
      "name": "Plant_Seaweed_Wet_Stack"
    },
    {
      "x": 3,
      "y": 9,
      "z": -12,
      "name": "Plant_Seaweed_Wet_Stack"
    },
    {
      "x": 4,
      "y": 9,
      "z": -12,
      "name": "Plant_Seaweed_Wet_Stack"
    },
    {
      "x": 5,
      "y": 9,
      "z": -12,
      "name": "Plant_Seaweed_Wet_Stack"
    },
    {
      "x": 6,
      "y": 9,
      "z": -12,
      "name": "Plant_Seaweed_Wet_Stack"
    },
    {
      "x": 8,
      "y": 9,
      "z": -12,
      "name": "Plant_Seaweed_Wet_Stack"
    },
    {
      "x": 9,
      "y": 9,
      "z": -12,
      "name": "Plant_Seaweed_Wet_Stack"
    },
    {
      "x": 0,
      "y": 10,
      "z": -12,
      "name": "Plant_Seaweed_Wet_Stack"
    },
    {
      "x": 1,
      "y": 10,
      "z": -12,
      "name": "Plant_Seaweed_Wet_Stack"
    },
    {
      "x": 3,
      "y": 10,
      "z": -12,
      "name": "Plant_Seaweed_Wet_Stack"
    },
    {
      "x": 4,
      "y": 10,
      "z": -12,
      "name": "Plant_Seaweed_Wet_Stack"
    },
    {
      "x": 5,
      "y": 10,
      "z": -12,
      "name": "Plant_Seaweed_Wet_Stack"
    },
    {
      "x": 6,
      "y": 10,
      "z": -12,
      "name": "Plant_Seaweed_Wet_Stack"
    },
    {
      "x": 8,
      "y": 10,
      "z": -12,
      "name": "Plant_Seaweed_Wet_Stack"
    },
    {
      "x": 9,
      "y": 10,
      "z": -12,
      "name": "Plant_Seaweed_Wet_Stack"
    },
    {
      "x": 0,
      "y": 11,
      "z": -12,
      "name": "Plant_Seaweed_Wet_Stack"
    },
    {
      "x": 1,
      "y": 11,
      "z": -12,
      "name": "Plant_Seaweed_Wet_Stack"
    },
    {
      "x": 3,
      "y": 11,
      "z": -12,
      "name": "Plant_Seaweed_Wet_Stack"
    },
    {
      "x": 4,
      "y": 11,
      "z": -12,
      "name": "Plant_Seaweed_Wet_Stack"
    },
    {
      "x": 5,
      "y": 11,
      "z": -12,
      "name": "Plant_Seaweed_Wet_Stack"
    },
    {
      "x": 6,
      "y": 11,
      "z": -12,
      "name": "Plant_Seaweed_Wet_Stack"
    },
    {
      "x": 8,
      "y": 11,
      "z": -12,
      "name": "Plant_Seaweed_Wet_Stack"
    },
    {
      "x": 9,
      "y": 11,
      "z": -12,
      "name": "Plant_Seaweed_Wet_Stack"
    },
    {
      "x": 0,
      "y": 12,
      "z": -12,
      "name": "Plant_Seaweed_Wet_Stack"
    },
    {
      "x": 1,
      "y": 12,
      "z": -12,
      "name": "Plant_Seaweed_Wet_Stack"
    },
    {
      "x": 3,
      "y": 12,
      "z": -12,
      "name": "Plant_Seaweed_Wet_Stack"
    },
    {
      "x": 4,
      "y": 12,
      "z": -12,
      "name": "Plant_Seaweed_Wet_Stack"
    },
    {
      "x": 5,
      "y": 12,
      "z": -12,
      "name": "Plant_Seaweed_Wet_Stack"
    },
    {
      "x": 6,
      "y": 12,
      "z": -12,
      "name": "Plant_Seaweed_Wet_Stack"
    },
    {
      "x": 8,
      "y": 12,
      "z": -12,
      "name": "Plant_Seaweed_Wet_Stack"
    },
    {
      "x": 9,
      "y": 12,
      "z": -12,
      "name": "Plant_Seaweed_Wet_Stack"
    },
    {
      "x": 7,
      "y": 3,
      "z": -11,
      "name": "Plant_Moss_Block_Green"
    },
    {
      "x": 2,
      "y": 4,
      "z": -11,
      "name": "Plant_Moss_Block_Green"
    },
    {
      "x": 5,
      "y": 4,
      "z": -11,
      "name": "Plant_Moss_Block_Green"
    },
    {
      "x": 6,
      "y": 4,
      "z": -11,
      "name": "Plant_Moss_Block_Green"
    },
    {
      "x": 7,
      "y": 4,
      "z": -11,
      "name": "Plant_Seaweed_Wet_Stack"
    },
    {
      "x": 8,
      "y": 4,
      "z": -11,
      "name": "Plant_Moss_Block_Green"
    },
    {
      "x": 0,
      "y": 5,
      "z": -11,
      "name": "Plant_Moss_Block_Green"
    },
    {
      "x": 1,
      "y": 5,
      "z": -11,
      "name": "Plant_Moss_Block_Green"
    },
    {
      "x": 2,
      "y": 5,
      "z": -11,
      "name": "Plant_Seaweed_Wet_Stack"
    },
    {
      "x": 3,
      "y": 5,
      "z": -11,
      "name": "Plant_Moss_Block_Green"
    },
    {
      "x": 4,
      "y": 5,
      "z": -11,
      "name": "Plant_Moss_Block_Green"
    },
    {
      "x": 5,
      "y": 5,
      "z": -11,
      "name": "Plant_Moss_Block_Green"
    },
    {
      "x": 6,
      "y": 5,
      "z": -11,
      "name": "Plant_Seaweed_Wet_Stack"
    },
    {
      "x": 7,
      "y": 5,
      "z": -11,
      "name": "Plant_Seaweed_Wet_Stack"
    },
    {
      "x": 8,
      "y": 5,
      "z": -11,
      "name": "Plant_Seaweed_Wet_Stack"
    },
    {
      "x": 10,
      "y": 5,
      "z": -11,
      "name": "Plant_Moss_Block_Green"
    },
    {
      "x": 0,
      "y": 6,
      "z": -11,
      "name": "Plant_Moss_Block_Green"
    },
    {
      "x": 1,
      "y": 6,
      "z": -11,
      "name": "Plant_Seaweed_Wet_Stack"
    },
    {
      "x": 2,
      "y": 6,
      "z": -11,
      "name": "Plant_Seaweed_Wet_Stack"
    },
    {
      "x": 3,
      "y": 6,
      "z": -11,
      "name": "Plant_Seaweed_Wet_Stack"
    },
    {
      "x": 4,
      "y": 6,
      "z": -11,
      "name": "Plant_Seaweed_Wet_Stack"
    },
    {
      "x": 5,
      "y": 6,
      "z": -11,
      "name": "Plant_Moss_Block_Green"
    },
    {
      "x": 6,
      "y": 6,
      "z": -11,
      "name": "Plant_Seaweed_Wet_Stack"
    },
    {
      "x": 7,
      "y": 6,
      "z": -11,
      "name": "Plant_Seaweed_Wet_Stack"
    },
    {
      "x": 8,
      "y": 6,
      "z": -11,
      "name": "Plant_Seaweed_Wet_Stack"
    },
    {
      "x": 10,
      "y": 6,
      "z": -11,
      "name": "Plant_Moss_Block_Green"
    },
    {
      "x": 0,
      "y": 7,
      "z": -11,
      "name": "Plant_Seaweed_Wet_Stack"
    },
    {
      "x": 1,
      "y": 7,
      "z": -11,
      "name": "Plant_Seaweed_Wet_Stack"
    },
    {
      "x": 2,
      "y": 7,
      "z": -11,
      "name": "Plant_Seaweed_Wet_Stack"
    },
    {
      "x": 3,
      "y": 7,
      "z": -11,
      "name": "Plant_Seaweed_Wet_Stack"
    },
    {
      "x": 4,
      "y": 7,
      "z": -11,
      "name": "Plant_Seaweed_Wet_Stack"
    },
    {
      "x": 5,
      "y": 7,
      "z": -11,
      "name": "Plant_Moss_Block_Green"
    },
    {
      "x": 6,
      "y": 7,
      "z": -11,
      "name": "Plant_Seaweed_Wet_Stack"
    },
    {
      "x": 7,
      "y": 7,
      "z": -11,
      "name": "Plant_Seaweed_Wet_Stack"
    },
    {
      "x": 8,
      "y": 7,
      "z": -11,
      "name": "Plant_Seaweed_Wet_Stack"
    },
    {
      "x": 10,
      "y": 7,
      "z": -11,
      "name": "Plant_Seaweed_Wet_Stack"
    },
    {
      "x": 0,
      "y": 8,
      "z": -11,
      "name": "Plant_Seaweed_Wet_Stack"
    },
    {
      "x": 1,
      "y": 8,
      "z": -11,
      "name": "Plant_Seaweed_Wet_Stack"
    },
    {
      "x": 2,
      "y": 8,
      "z": -11,
      "name": "Plant_Seaweed_Wet_Stack"
    },
    {
      "x": 3,
      "y": 8,
      "z": -11,
      "name": "Plant_Seaweed_Wet_Stack"
    },
    {
      "x": 4,
      "y": 8,
      "z": -11,
      "name": "Plant_Seaweed_Wet_Stack"
    },
    {
      "x": 5,
      "y": 8,
      "z": -11,
      "name": "Plant_Seaweed_Wet_Stack"
    },
    {
      "x": 6,
      "y": 8,
      "z": -11,
      "name": "Plant_Seaweed_Wet_Stack"
    },
    {
      "x": 7,
      "y": 8,
      "z": -11,
      "name": "Plant_Seaweed_Wet_Stack"
    },
    {
      "x": 8,
      "y": 8,
      "z": -11,
      "name": "Plant_Seaweed_Wet_Stack"
    },
    {
      "x": 10,
      "y": 8,
      "z": -11,
      "name": "Plant_Seaweed_Wet_Stack"
    },
    {
      "x": 0,
      "y": 9,
      "z": -11,
      "name": "Plant_Seaweed_Wet_Stack"
    },
    {
      "x": 1,
      "y": 9,
      "z": -11,
      "name": "Plant_Seaweed_Wet_Stack"
    },
    {
      "x": 2,
      "y": 9,
      "z": -11,
      "name": "Plant_Seaweed_Wet_Stack"
    },
    {
      "x": 3,
      "y": 9,
      "z": -11,
      "name": "Plant_Seaweed_Wet_Stack"
    },
    {
      "x": 4,
      "y": 9,
      "z": -11,
      "name": "Plant_Seaweed_Wet_Stack"
    },
    {
      "x": 5,
      "y": 9,
      "z": -11,
      "name": "Plant_Seaweed_Wet_Stack"
    },
    {
      "x": 6,
      "y": 9,
      "z": -11,
      "name": "Plant_Seaweed_Wet_Stack"
    },
    {
      "x": 7,
      "y": 9,
      "z": -11,
      "name": "Plant_Seaweed_Wet_Stack"
    },
    {
      "x": 8,
      "y": 9,
      "z": -11,
      "name": "Plant_Seaweed_Wet_Stack"
    },
    {
      "x": 10,
      "y": 9,
      "z": -11,
      "name": "Plant_Seaweed_Wet_Stack"
    },
    {
      "x": 0,
      "y": 10,
      "z": -11,
      "name": "Plant_Seaweed_Wet_Stack"
    },
    {
      "x": 1,
      "y": 10,
      "z": -11,
      "name": "Plant_Seaweed_Wet_Stack"
    },
    {
      "x": 2,
      "y": 10,
      "z": -11,
      "name": "Plant_Seaweed_Wet_Stack"
    },
    {
      "x": 3,
      "y": 10,
      "z": -11,
      "name": "Plant_Seaweed_Wet_Stack"
    },
    {
      "x": 4,
      "y": 10,
      "z": -11,
      "name": "Plant_Seaweed_Wet_Stack"
    },
    {
      "x": 5,
      "y": 10,
      "z": -11,
      "name": "Plant_Seaweed_Wet_Stack"
    },
    {
      "x": 6,
      "y": 10,
      "z": -11,
      "name": "Plant_Seaweed_Wet_Stack"
    },
    {
      "x": 7,
      "y": 10,
      "z": -11,
      "name": "Plant_Seaweed_Wet_Stack"
    },
    {
      "x": 8,
      "y": 10,
      "z": -11,
      "name": "Plant_Seaweed_Wet_Stack"
    },
    {
      "x": 10,
      "y": 10,
      "z": -11,
      "name": "Plant_Seaweed_Wet_Stack"
    },
    {
      "x": 0,
      "y": 11,
      "z": -11,
      "name": "Plant_Seaweed_Wet_Stack"
    },
    {
      "x": 1,
      "y": 11,
      "z": -11,
      "name": "Plant_Seaweed_Wet_Stack"
    },
    {
      "x": 2,
      "y": 11,
      "z": -11,
      "name": "Plant_Seaweed_Wet_Stack"
    },
    {
      "x": 3,
      "y": 11,
      "z": -11,
      "name": "Plant_Seaweed_Wet_Stack"
    },
    {
      "x": 4,
      "y": 11,
      "z": -11,
      "name": "Plant_Seaweed_Wet_Stack"
    },
    {
      "x": 5,
      "y": 11,
      "z": -11,
      "name": "Plant_Seaweed_Wet_Stack"
    },
    {
      "x": 6,
      "y": 11,
      "z": -11,
      "name": "Plant_Seaweed_Wet_Stack"
    },
    {
      "x": 7,
      "y": 11,
      "z": -11,
      "name": "Plant_Seaweed_Wet_Stack"
    },
    {
      "x": 8,
      "y": 11,
      "z": -11,
      "name": "Plant_Seaweed_Wet_Stack"
    },
    {
      "x": 10,
      "y": 11,
      "z": -11,
      "name": "Plant_Seaweed_Wet_Stack"
    },
    {
      "x": 0,
      "y": 12,
      "z": -11,
      "name": "Plant_Seaweed_Wet_Stack"
    },
    {
      "x": 1,
      "y": 12,
      "z": -11,
      "name": "Plant_Seaweed_Wet_Stack"
    },
    {
      "x": 2,
      "y": 12,
      "z": -11,
      "name": "Plant_Seaweed_Wet_Stack"
    },
    {
      "x": 3,
      "y": 12,
      "z": -11,
      "name": "Plant_Seaweed_Wet_Stack"
    },
    {
      "x": 4,
      "y": 12,
      "z": -11,
      "name": "Plant_Seaweed_Wet_Stack"
    },
    {
      "x": 5,
      "y": 12,
      "z": -11,
      "name": "Plant_Seaweed_Wet_Stack"
    },
    {
      "x": 6,
      "y": 12,
      "z": -11,
      "name": "Plant_Seaweed_Wet_Stack"
    },
    {
      "x": 7,
      "y": 12,
      "z": -11,
      "name": "Plant_Seaweed_Wet_Stack"
    },
    {
      "x": 8,
      "y": 12,
      "z": -11,
      "name": "Plant_Seaweed_Wet_Stack"
    },
    {
      "x": 10,
      "y": 12,
      "z": -11,
      "name": "Plant_Seaweed_Wet_Stack"
    },
    {
      "x": 2,
      "y": 3,
      "z": -10,
      "name": "Wood_Spiral_Trunk_Full"
    },
    {
      "x": 5,
      "y": 3,
      "z": -10,
      "name": "Plant_Moss_Block_Green"
    },
    {
      "x": 7,
      "y": 3,
      "z": -10,
      "name": "Plant_Moss_Block_Green"
    },
    {
      "x": 8,
      "y": 3,
      "z": -10,
      "name": "Plant_Moss_Block_Green"
    },
    {
      "x": 10,
      "y": 3,
      "z": -10,
      "name": "Plant_Moss_Block_Green"
    },
    {
      "x": 0,
      "y": 4,
      "z": -10,
      "name": "Plant_Moss_Block_Green"
    },
    {
      "x": 2,
      "y": 4,
      "z": -10,
      "name": "Wood_Spiral_Trunk_Full"
    },
    {
      "x": 3,
      "y": 4,
      "z": -10,
      "name": "Plant_Moss_Block_Green"
    },
    {
      "x": 5,
      "y": 4,
      "z": -10,
      "name": "Plant_Moss_Block_Green"
    },
    {
      "x": 6,
      "y": 4,
      "z": -10,
      "name": "Plant_Moss_Block_Green"
    },
    {
      "x": 7,
      "y": 4,
      "z": -10,
      "name": "Wood_Spiral_Trunk_Full"
    },
    {
      "x": 8,
      "y": 4,
      "z": -10,
      "name": "Plant_Moss_Block_Green"
    },
    {
      "x": 9,
      "y": 4,
      "z": -10,
      "name": "Plant_Moss_Block_Green"
    },
    {
      "x": 10,
      "y": 4,
      "z": -10,
      "name": "Plant_Seaweed_Wet_Stack"
    },
    {
      "x": 0,
      "y": 5,
      "z": -10,
      "name": "Plant_Seaweed_Wet_Stack"
    },
    {
      "x": 1,
      "y": 5,
      "z": -10,
      "name": "Plant_Moss_Block_Green"
    },
    {
      "x": 2,
      "y": 5,
      "z": -10,
      "name": "Wood_Spiral_Trunk_Full"
    },
    {
      "x": 3,
      "y": 5,
      "z": -10,
      "name": "Plant_Moss_Block_Green"
    },
    {
      "x": 4,
      "y": 5,
      "z": -10,
      "name": "Plant_Moss_Block_Green"
    },
    {
      "x": 5,
      "y": 5,
      "z": -10,
      "name": "Plant_Seaweed_Wet_Stack"
    },
    {
      "x": 6,
      "y": 5,
      "z": -10,
      "name": "Plant_Seaweed_Wet_Stack"
    },
    {
      "x": 7,
      "y": 5,
      "z": -10,
      "name": "Plant_Moss_Block_Green"
    },
    {
      "x": 8,
      "y": 5,
      "z": -10,
      "name": "Plant_Seaweed_Wet_Stack"
    },
    {
      "x": 9,
      "y": 5,
      "z": -10,
      "name": "Plant_Moss_Block_Green"
    },
    {
      "x": 10,
      "y": 5,
      "z": -10,
      "name": "Plant_Seaweed_Wet_Stack"
    },
    {
      "x": 0,
      "y": 6,
      "z": -10,
      "name": "Plant_Seaweed_Wet_Stack"
    },
    {
      "x": 1,
      "y": 6,
      "z": -10,
      "name": "Plant_Seaweed_Wet_Stack"
    },
    {
      "x": 2,
      "y": 6,
      "z": -10,
      "name": "Plant_Moss_Block_Green"
    },
    {
      "x": 3,
      "y": 6,
      "z": -10,
      "name": "Plant_Seaweed_Wet_Stack"
    },
    {
      "x": 4,
      "y": 6,
      "z": -10,
      "name": "Plant_Moss_Block_Green"
    },
    {
      "x": 5,
      "y": 6,
      "z": -10,
      "name": "Plant_Seaweed_Wet_Stack"
    },
    {
      "x": 6,
      "y": 6,
      "z": -10,
      "name": "Plant_Seaweed_Wet_Stack"
    },
    {
      "x": 7,
      "y": 6,
      "z": -10,
      "name": "Plant_Moss_Block_Green"
    },
    {
      "x": 8,
      "y": 6,
      "z": -10,
      "name": "Plant_Seaweed_Wet_Stack"
    },
    {
      "x": 9,
      "y": 6,
      "z": -10,
      "name": "Plant_Moss_Block_Green"
    },
    {
      "x": 10,
      "y": 6,
      "z": -10,
      "name": "Plant_Seaweed_Wet_Stack"
    },
    {
      "x": 0,
      "y": 7,
      "z": -10,
      "name": "Plant_Seaweed_Wet_Stack"
    },
    {
      "x": 1,
      "y": 7,
      "z": -10,
      "name": "Plant_Seaweed_Wet_Stack"
    },
    {
      "x": 2,
      "y": 7,
      "z": -10,
      "name": "Plant_Moss_Block_Green"
    },
    {
      "x": 3,
      "y": 7,
      "z": -10,
      "name": "Plant_Seaweed_Wet_Stack"
    },
    {
      "x": 4,
      "y": 7,
      "z": -10,
      "name": "Plant_Moss_Block_Green"
    },
    {
      "x": 5,
      "y": 7,
      "z": -10,
      "name": "Plant_Seaweed_Wet_Stack"
    },
    {
      "x": 6,
      "y": 7,
      "z": -10,
      "name": "Plant_Seaweed_Wet_Stack"
    },
    {
      "x": 7,
      "y": 7,
      "z": -10,
      "name": "Plant_Seaweed_Wet_Stack"
    },
    {
      "x": 8,
      "y": 7,
      "z": -10,
      "name": "Plant_Seaweed_Wet_Stack"
    },
    {
      "x": 9,
      "y": 7,
      "z": -10,
      "name": "Plant_Moss_Block_Green"
    },
    {
      "x": 10,
      "y": 7,
      "z": -10,
      "name": "Plant_Seaweed_Wet_Stack"
    },
    {
      "x": 0,
      "y": 8,
      "z": -10,
      "name": "Plant_Seaweed_Wet_Stack"
    },
    {
      "x": 1,
      "y": 8,
      "z": -10,
      "name": "Plant_Seaweed_Wet_Stack"
    },
    {
      "x": 2,
      "y": 8,
      "z": -10,
      "name": "Plant_Seaweed_Wet_Stack"
    },
    {
      "x": 3,
      "y": 8,
      "z": -10,
      "name": "Plant_Seaweed_Wet_Stack"
    },
    {
      "x": 4,
      "y": 8,
      "z": -10,
      "name": "Plant_Moss_Block_Green"
    },
    {
      "x": 5,
      "y": 8,
      "z": -10,
      "name": "Plant_Seaweed_Wet_Stack"
    },
    {
      "x": 6,
      "y": 8,
      "z": -10,
      "name": "Plant_Seaweed_Wet_Stack"
    },
    {
      "x": 7,
      "y": 8,
      "z": -10,
      "name": "Plant_Seaweed_Wet_Stack"
    },
    {
      "x": 8,
      "y": 8,
      "z": -10,
      "name": "Plant_Seaweed_Wet_Stack"
    },
    {
      "x": 9,
      "y": 8,
      "z": -10,
      "name": "Plant_Seaweed_Wet_Stack"
    },
    {
      "x": 10,
      "y": 8,
      "z": -10,
      "name": "Plant_Seaweed_Wet_Stack"
    },
    {
      "x": 0,
      "y": 9,
      "z": -10,
      "name": "Plant_Seaweed_Wet_Stack"
    },
    {
      "x": 1,
      "y": 9,
      "z": -10,
      "name": "Plant_Seaweed_Wet_Stack"
    },
    {
      "x": 2,
      "y": 9,
      "z": -10,
      "name": "Plant_Seaweed_Wet_Stack"
    },
    {
      "x": 3,
      "y": 9,
      "z": -10,
      "name": "Plant_Seaweed_Wet_Stack"
    },
    {
      "x": 4,
      "y": 9,
      "z": -10,
      "name": "Plant_Seaweed_Wet_Stack"
    },
    {
      "x": 5,
      "y": 9,
      "z": -10,
      "name": "Plant_Seaweed_Wet_Stack"
    },
    {
      "x": 6,
      "y": 9,
      "z": -10,
      "name": "Plant_Seaweed_Wet_Stack"
    },
    {
      "x": 7,
      "y": 9,
      "z": -10,
      "name": "Plant_Seaweed_Wet_Stack"
    },
    {
      "x": 8,
      "y": 9,
      "z": -10,
      "name": "Plant_Seaweed_Wet_Stack"
    },
    {
      "x": 9,
      "y": 9,
      "z": -10,
      "name": "Plant_Seaweed_Wet_Stack"
    },
    {
      "x": 10,
      "y": 9,
      "z": -10,
      "name": "Plant_Seaweed_Wet_Stack"
    },
    {
      "x": 0,
      "y": 10,
      "z": -10,
      "name": "Plant_Seaweed_Wet_Stack"
    },
    {
      "x": 1,
      "y": 10,
      "z": -10,
      "name": "Plant_Seaweed_Wet_Stack"
    },
    {
      "x": 2,
      "y": 10,
      "z": -10,
      "name": "Plant_Seaweed_Wet_Stack"
    },
    {
      "x": 3,
      "y": 10,
      "z": -10,
      "name": "Plant_Seaweed_Wet_Stack"
    },
    {
      "x": 4,
      "y": 10,
      "z": -10,
      "name": "Plant_Seaweed_Wet_Stack"
    },
    {
      "x": 5,
      "y": 10,
      "z": -10,
      "name": "Plant_Seaweed_Wet_Stack"
    },
    {
      "x": 6,
      "y": 10,
      "z": -10,
      "name": "Plant_Seaweed_Wet_Stack"
    },
    {
      "x": 7,
      "y": 10,
      "z": -10,
      "name": "Plant_Seaweed_Wet_Stack"
    },
    {
      "x": 8,
      "y": 10,
      "z": -10,
      "name": "Plant_Seaweed_Wet_Stack"
    },
    {
      "x": 9,
      "y": 10,
      "z": -10,
      "name": "Plant_Seaweed_Wet_Stack"
    },
    {
      "x": 10,
      "y": 10,
      "z": -10,
      "name": "Plant_Seaweed_Wet_Stack"
    },
    {
      "x": 0,
      "y": 11,
      "z": -10,
      "name": "Plant_Seaweed_Wet_Stack"
    },
    {
      "x": 1,
      "y": 11,
      "z": -10,
      "name": "Plant_Seaweed_Wet_Stack"
    },
    {
      "x": 2,
      "y": 11,
      "z": -10,
      "name": "Plant_Seaweed_Wet_Stack"
    },
    {
      "x": 3,
      "y": 11,
      "z": -10,
      "name": "Plant_Seaweed_Wet_Stack"
    },
    {
      "x": 4,
      "y": 11,
      "z": -10,
      "name": "Plant_Seaweed_Wet_Stack"
    },
    {
      "x": 5,
      "y": 11,
      "z": -10,
      "name": "Plant_Seaweed_Wet_Stack"
    },
    {
      "x": 6,
      "y": 11,
      "z": -10,
      "name": "Plant_Seaweed_Wet_Stack"
    },
    {
      "x": 7,
      "y": 11,
      "z": -10,
      "name": "Plant_Seaweed_Wet_Stack"
    },
    {
      "x": 8,
      "y": 11,
      "z": -10,
      "name": "Plant_Seaweed_Wet_Stack"
    },
    {
      "x": 9,
      "y": 11,
      "z": -10,
      "name": "Plant_Seaweed_Wet_Stack"
    },
    {
      "x": 10,
      "y": 11,
      "z": -10,
      "name": "Plant_Seaweed_Wet_Stack"
    },
    {
      "x": 0,
      "y": 12,
      "z": -10,
      "name": "Plant_Seaweed_Wet_Stack"
    },
    {
      "x": 1,
      "y": 12,
      "z": -10,
      "name": "Plant_Seaweed_Wet_Stack"
    },
    {
      "x": 2,
      "y": 12,
      "z": -10,
      "name": "Plant_Seaweed_Wet_Stack"
    },
    {
      "x": 3,
      "y": 12,
      "z": -10,
      "name": "Plant_Seaweed_Wet_Stack"
    },
    {
      "x": 4,
      "y": 12,
      "z": -10,
      "name": "Plant_Seaweed_Wet_Stack"
    },
    {
      "x": 5,
      "y": 12,
      "z": -10,
      "name": "Plant_Seaweed_Wet_Stack"
    },
    {
      "x": 6,
      "y": 12,
      "z": -10,
      "name": "Plant_Seaweed_Wet_Stack"
    },
    {
      "x": 7,
      "y": 12,
      "z": -10,
      "name": "Plant_Seaweed_Wet_Stack"
    },
    {
      "x": 8,
      "y": 12,
      "z": -10,
      "name": "Plant_Seaweed_Wet_Stack"
    },
    {
      "x": 9,
      "y": 12,
      "z": -10,
      "name": "Plant_Seaweed_Wet_Stack"
    },
    {
      "x": 10,
      "y": 12,
      "z": -10,
      "name": "Plant_Seaweed_Wet_Stack"
    },
    {
      "x": 2,
      "y": 2,
      "z": -9,
      "name": "Wood_Spiral_Trunk_Full"
    },
    {
      "x": 3,
      "y": 2,
      "z": -9,
      "name": "Wood_Spiral_Trunk_Full"
    },
    {
      "x": 2,
      "y": 3,
      "z": -9,
      "name": "Wood_Spiral_Trunk_Full"
    },
    {
      "x": 5,
      "y": 3,
      "z": -9,
      "name": "Wood_Spiral_Trunk_Full"
    },
    {
      "x": 6,
      "y": 3,
      "z": -9,
      "name": "Wood_Spiral_Trunk_Full"
    },
    {
      "x": 6,
      "y": 4,
      "z": -9,
      "name": "Wood_Spiral_Trunk_Full"
    },
    {
      "x": 7,
      "y": 4,
      "z": -9,
      "name": "Wood_Spiral_Trunk_Full"
    },
    {
      "x": 8,
      "y": 4,
      "z": -9,
      "name": "Plant_Moss_Block_Green"
    },
    {
      "x": 9,
      "y": 4,
      "z": -9,
      "name": "Plant_Moss_Block_Green"
    },
    {
      "x": 1,
      "y": 5,
      "z": -9,
      "name": "Plant_Moss_Block_Green"
    },
    {
      "x": 2,
      "y": 5,
      "z": -9,
      "name": "Plant_Moss_Block_Green"
    },
    {
      "x": 3,
      "y": 5,
      "z": -9,
      "name": "Plant_Moss_Block_Green"
    },
    {
      "x": 4,
      "y": 5,
      "z": -9,
      "name": "Plant_Moss_Block_Green"
    },
    {
      "x": 5,
      "y": 5,
      "z": -9,
      "name": "Plant_Moss_Block_Green"
    },
    {
      "x": 6,
      "y": 5,
      "z": -9,
      "name": "Plant_Moss_Block_Green"
    },
    {
      "x": 8,
      "y": 5,
      "z": -9,
      "name": "Plant_Moss_Block_Green"
    },
    {
      "x": 9,
      "y": 5,
      "z": -9,
      "name": "Plant_Seaweed_Wet_Stack"
    },
    {
      "x": 0,
      "y": 6,
      "z": -9,
      "name": "Plant_Moss_Block_Green"
    },
    {
      "x": 1,
      "y": 6,
      "z": -9,
      "name": "Plant_Moss_Block_Green"
    },
    {
      "x": 2,
      "y": 6,
      "z": -9,
      "name": "Plant_Seaweed_Wet_Stack"
    },
    {
      "x": 3,
      "y": 6,
      "z": -9,
      "name": "Plant_Moss_Block_Green"
    },
    {
      "x": 4,
      "y": 6,
      "z": -9,
      "name": "Plant_Seaweed_Wet_Stack"
    },
    {
      "x": 5,
      "y": 6,
      "z": -9,
      "name": "Plant_Moss_Block_Green"
    },
    {
      "x": 6,
      "y": 6,
      "z": -9,
      "name": "Plant_Seaweed_Wet_Stack"
    },
    {
      "x": 8,
      "y": 6,
      "z": -9,
      "name": "Plant_Seaweed_Wet_Stack"
    },
    {
      "x": 9,
      "y": 6,
      "z": -9,
      "name": "Plant_Seaweed_Wet_Stack"
    },
    {
      "x": 0,
      "y": 7,
      "z": -9,
      "name": "Plant_Moss_Block_Green"
    },
    {
      "x": 1,
      "y": 7,
      "z": -9,
      "name": "Plant_Seaweed_Wet_Stack"
    },
    {
      "x": 2,
      "y": 7,
      "z": -9,
      "name": "Plant_Seaweed_Wet_Stack"
    },
    {
      "x": 3,
      "y": 7,
      "z": -9,
      "name": "Plant_Seaweed_Wet_Stack"
    },
    {
      "x": 4,
      "y": 7,
      "z": -9,
      "name": "Plant_Seaweed_Wet_Stack"
    },
    {
      "x": 5,
      "y": 7,
      "z": -9,
      "name": "Plant_Seaweed_Wet_Stack"
    },
    {
      "x": 6,
      "y": 7,
      "z": -9,
      "name": "Plant_Seaweed_Wet_Stack"
    },
    {
      "x": 8,
      "y": 7,
      "z": -9,
      "name": "Plant_Seaweed_Wet_Stack"
    },
    {
      "x": 9,
      "y": 7,
      "z": -9,
      "name": "Plant_Seaweed_Wet_Stack"
    },
    {
      "x": 0,
      "y": 8,
      "z": -9,
      "name": "Plant_Seaweed_Wet_Stack"
    },
    {
      "x": 1,
      "y": 8,
      "z": -9,
      "name": "Plant_Seaweed_Wet_Stack"
    },
    {
      "x": 2,
      "y": 8,
      "z": -9,
      "name": "Plant_Seaweed_Wet_Stack"
    },
    {
      "x": 3,
      "y": 8,
      "z": -9,
      "name": "Plant_Seaweed_Wet_Stack"
    },
    {
      "x": 4,
      "y": 8,
      "z": -9,
      "name": "Plant_Seaweed_Wet_Stack"
    },
    {
      "x": 5,
      "y": 8,
      "z": -9,
      "name": "Plant_Seaweed_Wet_Stack"
    },
    {
      "x": 6,
      "y": 8,
      "z": -9,
      "name": "Plant_Seaweed_Wet_Stack"
    },
    {
      "x": 8,
      "y": 8,
      "z": -9,
      "name": "Plant_Seaweed_Wet_Stack"
    },
    {
      "x": 9,
      "y": 8,
      "z": -9,
      "name": "Plant_Seaweed_Wet_Stack"
    },
    {
      "x": 0,
      "y": 9,
      "z": -9,
      "name": "Plant_Seaweed_Wet_Stack"
    },
    {
      "x": 1,
      "y": 9,
      "z": -9,
      "name": "Plant_Seaweed_Wet_Stack"
    },
    {
      "x": 2,
      "y": 9,
      "z": -9,
      "name": "Plant_Seaweed_Wet_Stack"
    },
    {
      "x": 3,
      "y": 9,
      "z": -9,
      "name": "Plant_Seaweed_Wet_Stack"
    },
    {
      "x": 4,
      "y": 9,
      "z": -9,
      "name": "Plant_Seaweed_Wet_Stack"
    },
    {
      "x": 5,
      "y": 9,
      "z": -9,
      "name": "Plant_Seaweed_Wet_Stack"
    },
    {
      "x": 6,
      "y": 9,
      "z": -9,
      "name": "Plant_Seaweed_Wet_Stack"
    },
    {
      "x": 8,
      "y": 9,
      "z": -9,
      "name": "Plant_Seaweed_Wet_Stack"
    },
    {
      "x": 9,
      "y": 9,
      "z": -9,
      "name": "Plant_Seaweed_Wet_Stack"
    },
    {
      "x": 0,
      "y": 10,
      "z": -9,
      "name": "Plant_Seaweed_Wet_Stack"
    },
    {
      "x": 1,
      "y": 10,
      "z": -9,
      "name": "Plant_Seaweed_Wet_Stack"
    },
    {
      "x": 2,
      "y": 10,
      "z": -9,
      "name": "Plant_Seaweed_Wet_Stack"
    },
    {
      "x": 3,
      "y": 10,
      "z": -9,
      "name": "Plant_Seaweed_Wet_Stack"
    },
    {
      "x": 4,
      "y": 10,
      "z": -9,
      "name": "Plant_Seaweed_Wet_Stack"
    },
    {
      "x": 5,
      "y": 10,
      "z": -9,
      "name": "Plant_Seaweed_Wet_Stack"
    },
    {
      "x": 6,
      "y": 10,
      "z": -9,
      "name": "Plant_Seaweed_Wet_Stack"
    },
    {
      "x": 8,
      "y": 10,
      "z": -9,
      "name": "Plant_Seaweed_Wet_Stack"
    },
    {
      "x": 9,
      "y": 10,
      "z": -9,
      "name": "Plant_Seaweed_Wet_Stack"
    },
    {
      "x": 0,
      "y": 11,
      "z": -9,
      "name": "Plant_Seaweed_Wet_Stack"
    },
    {
      "x": 1,
      "y": 11,
      "z": -9,
      "name": "Plant_Seaweed_Wet_Stack"
    },
    {
      "x": 2,
      "y": 11,
      "z": -9,
      "name": "Plant_Seaweed_Wet_Stack"
    },
    {
      "x": 3,
      "y": 11,
      "z": -9,
      "name": "Plant_Seaweed_Wet_Stack"
    },
    {
      "x": 4,
      "y": 11,
      "z": -9,
      "name": "Plant_Seaweed_Wet_Stack"
    },
    {
      "x": 5,
      "y": 11,
      "z": -9,
      "name": "Plant_Seaweed_Wet_Stack"
    },
    {
      "x": 6,
      "y": 11,
      "z": -9,
      "name": "Plant_Seaweed_Wet_Stack"
    },
    {
      "x": 8,
      "y": 11,
      "z": -9,
      "name": "Plant_Seaweed_Wet_Stack"
    },
    {
      "x": 9,
      "y": 11,
      "z": -9,
      "name": "Plant_Seaweed_Wet_Stack"
    },
    {
      "x": 0,
      "y": 12,
      "z": -9,
      "name": "Plant_Seaweed_Wet_Stack"
    },
    {
      "x": 1,
      "y": 12,
      "z": -9,
      "name": "Plant_Seaweed_Wet_Stack"
    },
    {
      "x": 2,
      "y": 12,
      "z": -9,
      "name": "Plant_Seaweed_Wet_Stack"
    },
    {
      "x": 3,
      "y": 12,
      "z": -9,
      "name": "Plant_Seaweed_Wet_Stack"
    },
    {
      "x": 4,
      "y": 12,
      "z": -9,
      "name": "Plant_Seaweed_Wet_Stack"
    },
    {
      "x": 5,
      "y": 12,
      "z": -9,
      "name": "Plant_Seaweed_Wet_Stack"
    },
    {
      "x": 6,
      "y": 12,
      "z": -9,
      "name": "Plant_Seaweed_Wet_Stack"
    },
    {
      "x": 8,
      "y": 12,
      "z": -9,
      "name": "Plant_Seaweed_Wet_Stack"
    },
    {
      "x": 9,
      "y": 12,
      "z": -9,
      "name": "Plant_Seaweed_Wet_Stack"
    },
    {
      "x": 3,
      "y": 2,
      "z": -8,
      "name": "Wood_Spiral_Trunk_Full"
    },
    {
      "x": 4,
      "y": 2,
      "z": -8,
      "name": "Wood_Spiral_Trunk_Full"
    },
    {
      "x": 5,
      "y": 2,
      "z": -8,
      "name": "Wood_Spiral_Trunk_Full"
    },
    {
      "x": 4,
      "y": 3,
      "z": -8,
      "name": "Wood_Spiral_Trunk_Half"
    },
    {
      "x": 5,
      "y": 3,
      "z": -8,
      "name": "Wood_Spiral_Trunk_Full"
    },
    {
      "x": 8,
      "y": 4,
      "z": -8,
      "name": "Plant_Moss_Block_Green"
    },
    {
      "x": 3,
      "y": 5,
      "z": -8,
      "name": "Plant_Moss_Block_Green"
    },
    {
      "x": 4,
      "y": 5,
      "z": -8,
      "name": "Plant_Moss_Block_Green"
    },
    {
      "x": 5,
      "y": 5,
      "z": -8,
      "name": "Plant_Moss_Block_Green"
    },
    {
      "x": 8,
      "y": 5,
      "z": -8,
      "name": "Plant_Moss_Block_Green"
    },
    {
      "x": 9,
      "y": 5,
      "z": -8,
      "name": "Plant_Moss_Block_Green"
    },
    {
      "x": 0,
      "y": 6,
      "z": -8,
      "name": "Plant_Moss_Block_Green"
    },
    {
      "x": 3,
      "y": 6,
      "z": -8,
      "name": "Plant_Moss_Block_Green"
    },
    {
      "x": 4,
      "y": 6,
      "z": -8,
      "name": "Plant_Moss_Block_Green"
    },
    {
      "x": 5,
      "y": 6,
      "z": -8,
      "name": "Plant_Seaweed_Wet_Stack"
    },
    {
      "x": 7,
      "y": 6,
      "z": -8,
      "name": "Plant_Moss_Block_Green"
    },
    {
      "x": 8,
      "y": 6,
      "z": -8,
      "name": "Plant_Seaweed_Wet_Stack"
    },
    {
      "x": 9,
      "y": 6,
      "z": -8,
      "name": "Plant_Moss_Block_Green"
    },
    {
      "x": 10,
      "y": 6,
      "z": -8,
      "name": "Plant_Moss_Block_Green"
    },
    {
      "x": 0,
      "y": 7,
      "z": -8,
      "name": "Plant_Seaweed_Wet_Stack"
    },
    {
      "x": 2,
      "y": 7,
      "z": -8,
      "name": "Plant_Moss_Block_Green"
    },
    {
      "x": 3,
      "y": 7,
      "z": -8,
      "name": "Plant_Seaweed_Wet_Stack"
    },
    {
      "x": 4,
      "y": 7,
      "z": -8,
      "name": "Plant_Moss_Block_Green"
    },
    {
      "x": 5,
      "y": 7,
      "z": -8,
      "name": "Plant_Seaweed_Wet_Stack"
    },
    {
      "x": 7,
      "y": 7,
      "z": -8,
      "name": "Plant_Seaweed_Wet_Stack"
    },
    {
      "x": 8,
      "y": 7,
      "z": -8,
      "name": "Plant_Seaweed_Wet_Stack"
    },
    {
      "x": 9,
      "y": 7,
      "z": -8,
      "name": "Plant_Seaweed_Wet_Stack"
    },
    {
      "x": 10,
      "y": 7,
      "z": -8,
      "name": "Plant_Seaweed_Wet_Stack"
    },
    {
      "x": 0,
      "y": 8,
      "z": -8,
      "name": "Plant_Seaweed_Wet_Stack"
    },
    {
      "x": 2,
      "y": 8,
      "z": -8,
      "name": "Plant_Moss_Block_Green"
    },
    {
      "x": 3,
      "y": 8,
      "z": -8,
      "name": "Plant_Seaweed_Wet_Stack"
    },
    {
      "x": 4,
      "y": 8,
      "z": -8,
      "name": "Plant_Seaweed_Wet_Stack"
    },
    {
      "x": 5,
      "y": 8,
      "z": -8,
      "name": "Plant_Seaweed_Wet_Stack"
    },
    {
      "x": 7,
      "y": 8,
      "z": -8,
      "name": "Plant_Seaweed_Wet_Stack"
    },
    {
      "x": 8,
      "y": 8,
      "z": -8,
      "name": "Plant_Seaweed_Wet_Stack"
    },
    {
      "x": 9,
      "y": 8,
      "z": -8,
      "name": "Plant_Seaweed_Wet_Stack"
    },
    {
      "x": 10,
      "y": 8,
      "z": -8,
      "name": "Plant_Seaweed_Wet_Stack"
    },
    {
      "x": 0,
      "y": 9,
      "z": -8,
      "name": "Plant_Seaweed_Wet_Stack"
    },
    {
      "x": 2,
      "y": 9,
      "z": -8,
      "name": "Plant_Seaweed_Wet_Stack"
    },
    {
      "x": 3,
      "y": 9,
      "z": -8,
      "name": "Plant_Seaweed_Wet_Stack"
    },
    {
      "x": 4,
      "y": 9,
      "z": -8,
      "name": "Plant_Seaweed_Wet_Stack"
    },
    {
      "x": 5,
      "y": 9,
      "z": -8,
      "name": "Plant_Seaweed_Wet_Stack"
    },
    {
      "x": 7,
      "y": 9,
      "z": -8,
      "name": "Plant_Seaweed_Wet_Stack"
    },
    {
      "x": 8,
      "y": 9,
      "z": -8,
      "name": "Plant_Seaweed_Wet_Stack"
    },
    {
      "x": 9,
      "y": 9,
      "z": -8,
      "name": "Plant_Seaweed_Wet_Stack"
    },
    {
      "x": 10,
      "y": 9,
      "z": -8,
      "name": "Plant_Seaweed_Wet_Stack"
    },
    {
      "x": 0,
      "y": 10,
      "z": -8,
      "name": "Plant_Seaweed_Wet_Stack"
    },
    {
      "x": 2,
      "y": 10,
      "z": -8,
      "name": "Plant_Seaweed_Wet_Stack"
    },
    {
      "x": 3,
      "y": 10,
      "z": -8,
      "name": "Plant_Seaweed_Wet_Stack"
    },
    {
      "x": 4,
      "y": 10,
      "z": -8,
      "name": "Plant_Seaweed_Wet_Stack"
    },
    {
      "x": 5,
      "y": 10,
      "z": -8,
      "name": "Plant_Seaweed_Wet_Stack"
    },
    {
      "x": 7,
      "y": 10,
      "z": -8,
      "name": "Plant_Seaweed_Wet_Stack"
    },
    {
      "x": 8,
      "y": 10,
      "z": -8,
      "name": "Plant_Seaweed_Wet_Stack"
    },
    {
      "x": 9,
      "y": 10,
      "z": -8,
      "name": "Plant_Seaweed_Wet_Stack"
    },
    {
      "x": 10,
      "y": 10,
      "z": -8,
      "name": "Plant_Seaweed_Wet_Stack"
    },
    {
      "x": 0,
      "y": 11,
      "z": -8,
      "name": "Plant_Seaweed_Wet_Stack"
    },
    {
      "x": 2,
      "y": 11,
      "z": -8,
      "name": "Plant_Seaweed_Wet_Stack"
    },
    {
      "x": 3,
      "y": 11,
      "z": -8,
      "name": "Plant_Seaweed_Wet_Stack"
    },
    {
      "x": 4,
      "y": 11,
      "z": -8,
      "name": "Plant_Seaweed_Wet_Stack"
    },
    {
      "x": 5,
      "y": 11,
      "z": -8,
      "name": "Plant_Seaweed_Wet_Stack"
    },
    {
      "x": 7,
      "y": 11,
      "z": -8,
      "name": "Plant_Seaweed_Wet_Stack"
    },
    {
      "x": 8,
      "y": 11,
      "z": -8,
      "name": "Plant_Seaweed_Wet_Stack"
    },
    {
      "x": 9,
      "y": 11,
      "z": -8,
      "name": "Plant_Seaweed_Wet_Stack"
    },
    {
      "x": 10,
      "y": 11,
      "z": -8,
      "name": "Plant_Seaweed_Wet_Stack"
    },
    {
      "x": 0,
      "y": 12,
      "z": -8,
      "name": "Plant_Seaweed_Wet_Stack"
    },
    {
      "x": 2,
      "y": 12,
      "z": -8,
      "name": "Plant_Seaweed_Wet_Stack"
    },
    {
      "x": 3,
      "y": 12,
      "z": -8,
      "name": "Plant_Seaweed_Wet_Stack"
    },
    {
      "x": 4,
      "y": 12,
      "z": -8,
      "name": "Plant_Seaweed_Wet_Stack"
    },
    {
      "x": 5,
      "y": 12,
      "z": -8,
      "name": "Plant_Seaweed_Wet_Stack"
    },
    {
      "x": 7,
      "y": 12,
      "z": -8,
      "name": "Plant_Seaweed_Wet_Stack"
    },
    {
      "x": 8,
      "y": 12,
      "z": -8,
      "name": "Plant_Seaweed_Wet_Stack"
    },
    {
      "x": 9,
      "y": 12,
      "z": -8,
      "name": "Plant_Seaweed_Wet_Stack"
    },
    {
      "x": 10,
      "y": 12,
      "z": -8,
      "name": "Plant_Seaweed_Wet_Stack"
    },
    {
      "x": 3,
      "y": 1,
      "z": -7,
      "name": "Wood_Spiral_Trunk_Full"
    },
    {
      "x": 4,
      "y": 1,
      "z": -7,
      "name": "Wood_Spiral_Trunk_Full"
    },
    {
      "x": 4,
      "y": 2,
      "z": -7,
      "name": "Wood_Spiral_Trunk_Full"
    },
    {
      "x": 8,
      "y": 4,
      "z": -7,
      "name": "Plant_Moss_Block_Green"
    },
    {
      "x": 3,
      "y": 5,
      "z": -7,
      "name": "Plant_Moss_Block_Green"
    },
    {
      "x": 8,
      "y": 5,
      "z": -7,
      "name": "Plant_Seaweed_Wet_Stack"
    },
    {
      "x": 9,
      "y": 5,
      "z": -7,
      "name": "Plant_Moss_Block_Green"
    },
    {
      "x": 1,
      "y": 6,
      "z": -7,
      "name": "Plant_Moss_Block_Green"
    },
    {
      "x": 3,
      "y": 6,
      "z": -7,
      "name": "Plant_Seaweed_Wet_Stack"
    },
    {
      "x": 5,
      "y": 6,
      "z": -7,
      "name": "Plant_Moss_Block_Green"
    },
    {
      "x": 7,
      "y": 6,
      "z": -7,
      "name": "Plant_Moss_Block_Green"
    },
    {
      "x": 8,
      "y": 6,
      "z": -7,
      "name": "Plant_Seaweed_Wet_Stack"
    },
    {
      "x": 9,
      "y": 6,
      "z": -7,
      "name": "Plant_Seaweed_Wet_Stack"
    },
    {
      "x": 1,
      "y": 7,
      "z": -7,
      "name": "Plant_Seaweed_Wet_Stack"
    },
    {
      "x": 2,
      "y": 7,
      "z": -7,
      "name": "Plant_Moss_Block_Green"
    },
    {
      "x": 3,
      "y": 7,
      "z": -7,
      "name": "Plant_Seaweed_Wet_Stack"
    },
    {
      "x": 4,
      "y": 7,
      "z": -7,
      "name": "Plant_Moss_Block_Green"
    },
    {
      "x": 5,
      "y": 7,
      "z": -7,
      "name": "Plant_Moss_Block_Green"
    },
    {
      "x": 7,
      "y": 7,
      "z": -7,
      "name": "Plant_Seaweed_Wet_Stack"
    },
    {
      "x": 8,
      "y": 7,
      "z": -7,
      "name": "Plant_Seaweed_Wet_Stack"
    },
    {
      "x": 9,
      "y": 7,
      "z": -7,
      "name": "Plant_Seaweed_Wet_Stack"
    },
    {
      "x": 0,
      "y": 8,
      "z": -7,
      "name": "Plant_Moss_Block_Green"
    },
    {
      "x": 1,
      "y": 8,
      "z": -7,
      "name": "Plant_Seaweed_Wet_Stack"
    },
    {
      "x": 2,
      "y": 8,
      "z": -7,
      "name": "Plant_Moss_Block_Green"
    },
    {
      "x": 3,
      "y": 8,
      "z": -7,
      "name": "Plant_Seaweed_Wet_Stack"
    },
    {
      "x": 4,
      "y": 8,
      "z": -7,
      "name": "Plant_Seaweed_Wet_Stack"
    },
    {
      "x": 5,
      "y": 8,
      "z": -7,
      "name": "Plant_Moss_Block_Green"
    },
    {
      "x": 7,
      "y": 8,
      "z": -7,
      "name": "Plant_Seaweed_Wet_Stack"
    },
    {
      "x": 8,
      "y": 8,
      "z": -7,
      "name": "Plant_Seaweed_Wet_Stack"
    },
    {
      "x": 9,
      "y": 8,
      "z": -7,
      "name": "Plant_Seaweed_Wet_Stack"
    },
    {
      "x": 0,
      "y": 9,
      "z": -7,
      "name": "Plant_Moss_Block_Green"
    },
    {
      "x": 1,
      "y": 9,
      "z": -7,
      "name": "Plant_Seaweed_Wet_Stack"
    },
    {
      "x": 2,
      "y": 9,
      "z": -7,
      "name": "Plant_Seaweed_Wet_Stack"
    },
    {
      "x": 3,
      "y": 9,
      "z": -7,
      "name": "Plant_Seaweed_Wet_Stack"
    },
    {
      "x": 4,
      "y": 9,
      "z": -7,
      "name": "Plant_Seaweed_Wet_Stack"
    },
    {
      "x": 5,
      "y": 9,
      "z": -7,
      "name": "Plant_Moss_Block_Green"
    },
    {
      "x": 7,
      "y": 9,
      "z": -7,
      "name": "Plant_Seaweed_Wet_Stack"
    },
    {
      "x": 8,
      "y": 9,
      "z": -7,
      "name": "Plant_Seaweed_Wet_Stack"
    },
    {
      "x": 9,
      "y": 9,
      "z": -7,
      "name": "Plant_Seaweed_Wet_Stack"
    },
    {
      "x": 0,
      "y": 10,
      "z": -7,
      "name": "Plant_Seaweed_Wet_Stack"
    },
    {
      "x": 1,
      "y": 10,
      "z": -7,
      "name": "Plant_Seaweed_Wet_Stack"
    },
    {
      "x": 2,
      "y": 10,
      "z": -7,
      "name": "Plant_Seaweed_Wet_Stack"
    },
    {
      "x": 3,
      "y": 10,
      "z": -7,
      "name": "Plant_Seaweed_Wet_Stack"
    },
    {
      "x": 4,
      "y": 10,
      "z": -7,
      "name": "Plant_Seaweed_Wet_Stack"
    },
    {
      "x": 5,
      "y": 10,
      "z": -7,
      "name": "Plant_Seaweed_Wet_Stack"
    },
    {
      "x": 7,
      "y": 10,
      "z": -7,
      "name": "Plant_Seaweed_Wet_Stack"
    },
    {
      "x": 8,
      "y": 10,
      "z": -7,
      "name": "Plant_Seaweed_Wet_Stack"
    },
    {
      "x": 9,
      "y": 10,
      "z": -7,
      "name": "Plant_Seaweed_Wet_Stack"
    },
    {
      "x": 0,
      "y": 11,
      "z": -7,
      "name": "Plant_Seaweed_Wet_Stack"
    },
    {
      "x": 1,
      "y": 11,
      "z": -7,
      "name": "Plant_Seaweed_Wet_Stack"
    },
    {
      "x": 2,
      "y": 11,
      "z": -7,
      "name": "Plant_Seaweed_Wet_Stack"
    },
    {
      "x": 3,
      "y": 11,
      "z": -7,
      "name": "Plant_Seaweed_Wet_Stack"
    },
    {
      "x": 4,
      "y": 11,
      "z": -7,
      "name": "Plant_Seaweed_Wet_Stack"
    },
    {
      "x": 5,
      "y": 11,
      "z": -7,
      "name": "Plant_Seaweed_Wet_Stack"
    },
    {
      "x": 7,
      "y": 11,
      "z": -7,
      "name": "Plant_Seaweed_Wet_Stack"
    },
    {
      "x": 8,
      "y": 11,
      "z": -7,
      "name": "Plant_Seaweed_Wet_Stack"
    },
    {
      "x": 9,
      "y": 11,
      "z": -7,
      "name": "Plant_Seaweed_Wet_Stack"
    },
    {
      "x": 0,
      "y": 12,
      "z": -7,
      "name": "Plant_Seaweed_Wet_Stack"
    },
    {
      "x": 1,
      "y": 12,
      "z": -7,
      "name": "Plant_Seaweed_Wet_Stack"
    },
    {
      "x": 2,
      "y": 12,
      "z": -7,
      "name": "Plant_Seaweed_Wet_Stack"
    },
    {
      "x": 3,
      "y": 12,
      "z": -7,
      "name": "Plant_Seaweed_Wet_Stack"
    },
    {
      "x": 4,
      "y": 12,
      "z": -7,
      "name": "Plant_Seaweed_Wet_Stack"
    },
    {
      "x": 5,
      "y": 12,
      "z": -7,
      "name": "Plant_Seaweed_Wet_Stack"
    },
    {
      "x": 7,
      "y": 12,
      "z": -7,
      "name": "Plant_Seaweed_Wet_Stack"
    },
    {
      "x": 8,
      "y": 12,
      "z": -7,
      "name": "Plant_Seaweed_Wet_Stack"
    },
    {
      "x": 9,
      "y": 12,
      "z": -7,
      "name": "Plant_Seaweed_Wet_Stack"
    },
    {
      "x": 3,
      "y": 1,
      "z": -6,
      "name": "Wood_Spiral_Trunk_Full"
    },
    {
      "x": 8,
      "y": 4,
      "z": -6,
      "name": "Plant_Moss_Block_Green"
    },
    {
      "x": 9,
      "y": 4,
      "z": -6,
      "name": "Plant_Moss_Block_Green"
    },
    {
      "x": 11,
      "y": 4,
      "z": -6,
      "name": "Plant_Moss_Block_Green"
    },
    {
      "x": 8,
      "y": 5,
      "z": -6,
      "name": "Plant_Seaweed_Wet_Stack"
    },
    {
      "x": 9,
      "y": 5,
      "z": -6,
      "name": "Plant_Moss_Block_Green"
    },
    {
      "x": 11,
      "y": 5,
      "z": -6,
      "name": "Plant_Seaweed_Wet_Stack"
    },
    {
      "x": 3,
      "y": 6,
      "z": -6,
      "name": "Plant_Moss_Block_Green"
    },
    {
      "x": 8,
      "y": 6,
      "z": -6,
      "name": "Plant_Seaweed_Wet_Stack"
    },
    {
      "x": 9,
      "y": 6,
      "z": -6,
      "name": "Plant_Seaweed_Wet_Stack"
    },
    {
      "x": 11,
      "y": 6,
      "z": -6,
      "name": "Plant_Seaweed_Wet_Stack"
    },
    {
      "x": 1,
      "y": 7,
      "z": -6,
      "name": "Plant_Moss_Block_Green"
    },
    {
      "x": 2,
      "y": 7,
      "z": -6,
      "name": "Plant_Moss_Block_Green"
    },
    {
      "x": 3,
      "y": 7,
      "z": -6,
      "name": "Plant_Seaweed_Wet_Stack"
    },
    {
      "x": 4,
      "y": 7,
      "z": -6,
      "name": "Plant_Moss_Block_Green"
    },
    {
      "x": 8,
      "y": 7,
      "z": -6,
      "name": "Plant_Seaweed_Wet_Stack"
    },
    {
      "x": 9,
      "y": 7,
      "z": -6,
      "name": "Plant_Seaweed_Wet_Stack"
    },
    {
      "x": 11,
      "y": 7,
      "z": -6,
      "name": "Plant_Seaweed_Wet_Stack"
    },
    {
      "x": 0,
      "y": 8,
      "z": -6,
      "name": "Plant_Moss_Block_Green"
    },
    {
      "x": 1,
      "y": 8,
      "z": -6,
      "name": "Plant_Moss_Block_Green"
    },
    {
      "x": 2,
      "y": 8,
      "z": -6,
      "name": "Plant_Seaweed_Wet_Stack"
    },
    {
      "x": 3,
      "y": 8,
      "z": -6,
      "name": "Plant_Seaweed_Wet_Stack"
    },
    {
      "x": 4,
      "y": 8,
      "z": -6,
      "name": "Plant_Seaweed_Wet_Stack"
    },
    {
      "x": 6,
      "y": 8,
      "z": -6,
      "name": "Plant_Moss_Block_Green"
    },
    {
      "x": 8,
      "y": 8,
      "z": -6,
      "name": "Plant_Seaweed_Wet_Stack"
    },
    {
      "x": 9,
      "y": 8,
      "z": -6,
      "name": "Plant_Seaweed_Wet_Stack"
    },
    {
      "x": 11,
      "y": 8,
      "z": -6,
      "name": "Plant_Seaweed_Wet_Stack"
    },
    {
      "x": 0,
      "y": 9,
      "z": -6,
      "name": "Plant_Seaweed_Wet_Stack"
    },
    {
      "x": 1,
      "y": 9,
      "z": -6,
      "name": "Plant_Seaweed_Wet_Stack"
    },
    {
      "x": 2,
      "y": 9,
      "z": -6,
      "name": "Plant_Seaweed_Wet_Stack"
    },
    {
      "x": 3,
      "y": 9,
      "z": -6,
      "name": "Plant_Seaweed_Wet_Stack"
    },
    {
      "x": 4,
      "y": 9,
      "z": -6,
      "name": "Plant_Seaweed_Wet_Stack"
    },
    {
      "x": 6,
      "y": 9,
      "z": -6,
      "name": "Plant_Moss_Block_Green"
    },
    {
      "x": 8,
      "y": 9,
      "z": -6,
      "name": "Plant_Seaweed_Wet_Stack"
    },
    {
      "x": 9,
      "y": 9,
      "z": -6,
      "name": "Plant_Seaweed_Wet_Stack"
    },
    {
      "x": 11,
      "y": 9,
      "z": -6,
      "name": "Plant_Seaweed_Wet_Stack"
    },
    {
      "x": 0,
      "y": 10,
      "z": -6,
      "name": "Plant_Seaweed_Wet_Stack"
    },
    {
      "x": 1,
      "y": 10,
      "z": -6,
      "name": "Plant_Seaweed_Wet_Stack"
    },
    {
      "x": 2,
      "y": 10,
      "z": -6,
      "name": "Plant_Seaweed_Wet_Stack"
    },
    {
      "x": 3,
      "y": 10,
      "z": -6,
      "name": "Plant_Seaweed_Wet_Stack"
    },
    {
      "x": 4,
      "y": 10,
      "z": -6,
      "name": "Plant_Seaweed_Wet_Stack"
    },
    {
      "x": 6,
      "y": 10,
      "z": -6,
      "name": "Plant_Seaweed_Wet_Stack"
    },
    {
      "x": 8,
      "y": 10,
      "z": -6,
      "name": "Plant_Seaweed_Wet_Stack"
    },
    {
      "x": 9,
      "y": 10,
      "z": -6,
      "name": "Plant_Seaweed_Wet_Stack"
    },
    {
      "x": 11,
      "y": 10,
      "z": -6,
      "name": "Plant_Seaweed_Wet_Stack"
    },
    {
      "x": 0,
      "y": 11,
      "z": -6,
      "name": "Plant_Seaweed_Wet_Stack"
    },
    {
      "x": 1,
      "y": 11,
      "z": -6,
      "name": "Plant_Seaweed_Wet_Stack"
    },
    {
      "x": 2,
      "y": 11,
      "z": -6,
      "name": "Plant_Seaweed_Wet_Stack"
    },
    {
      "x": 3,
      "y": 11,
      "z": -6,
      "name": "Plant_Seaweed_Wet_Stack"
    },
    {
      "x": 4,
      "y": 11,
      "z": -6,
      "name": "Plant_Seaweed_Wet_Stack"
    },
    {
      "x": 6,
      "y": 11,
      "z": -6,
      "name": "Plant_Seaweed_Wet_Stack"
    },
    {
      "x": 8,
      "y": 11,
      "z": -6,
      "name": "Plant_Seaweed_Wet_Stack"
    },
    {
      "x": 9,
      "y": 11,
      "z": -6,
      "name": "Plant_Seaweed_Wet_Stack"
    },
    {
      "x": 11,
      "y": 11,
      "z": -6,
      "name": "Plant_Seaweed_Wet_Stack"
    },
    {
      "x": 0,
      "y": 12,
      "z": -6,
      "name": "Plant_Seaweed_Wet_Stack"
    },
    {
      "x": 1,
      "y": 12,
      "z": -6,
      "name": "Plant_Seaweed_Wet_Stack"
    },
    {
      "x": 2,
      "y": 12,
      "z": -6,
      "name": "Plant_Seaweed_Wet_Stack"
    },
    {
      "x": 3,
      "y": 12,
      "z": -6,
      "name": "Plant_Seaweed_Wet_Stack"
    },
    {
      "x": 4,
      "y": 12,
      "z": -6,
      "name": "Plant_Seaweed_Wet_Stack"
    },
    {
      "x": 6,
      "y": 12,
      "z": -6,
      "name": "Plant_Seaweed_Wet_Stack"
    },
    {
      "x": 8,
      "y": 12,
      "z": -6,
      "name": "Plant_Seaweed_Wet_Stack"
    },
    {
      "x": 9,
      "y": 12,
      "z": -6,
      "name": "Plant_Seaweed_Wet_Stack"
    },
    {
      "x": 11,
      "y": 12,
      "z": -6,
      "name": "Plant_Seaweed_Wet_Stack"
    },
    {
      "x": 2,
      "y": 1,
      "z": -5,
      "name": "Wood_Spiral_Trunk_Full"
    },
    {
      "x": 3,
      "y": 1,
      "z": -5,
      "name": "Wood_Spiral_Trunk_Full"
    },
    {
      "x": 4,
      "y": 1,
      "z": -5,
      "name": "Wood_Spiral_Trunk_Full"
    },
    {
      "x": 5,
      "y": 1,
      "z": -5,
      "name": "Wood_Spiral_Trunk_Full"
    },
    {
      "x": 4,
      "y": 2,
      "z": -5,
      "name": "Wood_Spiral_Trunk_Half"
    },
    {
      "x": 5,
      "y": 2,
      "z": -5,
      "name": "Wood_Spiral_Trunk_Full"
    },
    {
      "x": 6,
      "y": 2,
      "z": -5,
      "name": "Wood_Spiral_Trunk_Full"
    },
    {
      "x": 7,
      "y": 2,
      "z": -5,
      "name": "Plant_Moss_Block_Green"
    },
    {
      "x": 11,
      "y": 2,
      "z": -5,
      "name": "Plant_Moss_Block_Green"
    },
    {
      "x": 7,
      "y": 3,
      "z": -5,
      "name": "Plant_Seaweed_Wet_Stack"
    },
    {
      "x": 8,
      "y": 3,
      "z": -5,
      "name": "Plant_Moss_Block_Green"
    },
    {
      "x": 10,
      "y": 3,
      "z": -5,
      "name": "Plant_Moss_Block_Green"
    },
    {
      "x": 11,
      "y": 3,
      "z": -5,
      "name": "Plant_Moss_Block_Green"
    },
    {
      "x": 6,
      "y": 4,
      "z": -5,
      "name": "Plant_Moss_Block_Green"
    },
    {
      "x": 8,
      "y": 4,
      "z": -5,
      "name": "Plant_Moss_Block_Green"
    },
    {
      "x": 10,
      "y": 4,
      "z": -5,
      "name": "Plant_Seaweed_Wet_Stack"
    },
    {
      "x": 11,
      "y": 4,
      "z": -5,
      "name": "Plant_Moss_Block_Green"
    },
    {
      "x": 2,
      "y": 5,
      "z": -5,
      "name": "Wood_Spiral_Trunk_Full"
    },
    {
      "x": 3,
      "y": 5,
      "z": -5,
      "name": "Wood_Spiral_Trunk_Full"
    },
    {
      "x": 6,
      "y": 5,
      "z": -5,
      "name": "Plant_Moss_Block_Green"
    },
    {
      "x": 8,
      "y": 5,
      "z": -5,
      "name": "Plant_Seaweed_Wet_Stack"
    },
    {
      "x": 10,
      "y": 5,
      "z": -5,
      "name": "Plant_Seaweed_Wet_Stack"
    },
    {
      "x": 11,
      "y": 5,
      "z": -5,
      "name": "Plant_Moss_Block_Green"
    },
    {
      "x": 1,
      "y": 6,
      "z": -5,
      "name": "Plant_Moss_Block_Green"
    },
    {
      "x": 3,
      "y": 6,
      "z": -5,
      "name": "Wood_Spiral_Trunk_Full"
    },
    {
      "x": 4,
      "y": 6,
      "z": -5,
      "name": "Plant_Moss_Block_Green"
    },
    {
      "x": 6,
      "y": 6,
      "z": -5,
      "name": "Plant_Moss_Block_Green"
    },
    {
      "x": 8,
      "y": 6,
      "z": -5,
      "name": "Plant_Seaweed_Wet_Stack"
    },
    {
      "x": 10,
      "y": 6,
      "z": -5,
      "name": "Plant_Seaweed_Wet_Stack"
    },
    {
      "x": 11,
      "y": 6,
      "z": -5,
      "name": "Plant_Seaweed_Wet_Stack"
    },
    {
      "x": 1,
      "y": 7,
      "z": -5,
      "name": "Plant_Seaweed_Wet_Stack"
    },
    {
      "x": 2,
      "y": 7,
      "z": -5,
      "name": "Plant_Moss_Block_Green"
    },
    {
      "x": 3,
      "y": 7,
      "z": -5,
      "name": "Wood_Spiral_Trunk_Full"
    },
    {
      "x": 4,
      "y": 7,
      "z": -5,
      "name": "Plant_Moss_Block_Green"
    },
    {
      "x": 5,
      "y": 7,
      "z": -5,
      "name": "Plant_Moss_Block_Green"
    },
    {
      "x": 6,
      "y": 7,
      "z": -5,
      "name": "Plant_Seaweed_Wet_Stack"
    },
    {
      "x": 8,
      "y": 7,
      "z": -5,
      "name": "Plant_Seaweed_Wet_Stack"
    },
    {
      "x": 10,
      "y": 7,
      "z": -5,
      "name": "Plant_Seaweed_Wet_Stack"
    },
    {
      "x": 11,
      "y": 7,
      "z": -5,
      "name": "Plant_Seaweed_Wet_Stack"
    },
    {
      "x": 1,
      "y": 8,
      "z": -5,
      "name": "Plant_Seaweed_Wet_Stack"
    },
    {
      "x": 2,
      "y": 8,
      "z": -5,
      "name": "Plant_Seaweed_Wet_Stack"
    },
    {
      "x": 3,
      "y": 8,
      "z": -5,
      "name": "Plant_Moss_Block_Green"
    },
    {
      "x": 4,
      "y": 8,
      "z": -5,
      "name": "Plant_Seaweed_Wet_Stack"
    },
    {
      "x": 5,
      "y": 8,
      "z": -5,
      "name": "Plant_Moss_Block_Green"
    },
    {
      "x": 6,
      "y": 8,
      "z": -5,
      "name": "Plant_Seaweed_Wet_Stack"
    },
    {
      "x": 8,
      "y": 8,
      "z": -5,
      "name": "Plant_Seaweed_Wet_Stack"
    },
    {
      "x": 10,
      "y": 8,
      "z": -5,
      "name": "Plant_Seaweed_Wet_Stack"
    },
    {
      "x": 11,
      "y": 8,
      "z": -5,
      "name": "Plant_Seaweed_Wet_Stack"
    },
    {
      "x": 1,
      "y": 9,
      "z": -5,
      "name": "Plant_Seaweed_Wet_Stack"
    },
    {
      "x": 2,
      "y": 9,
      "z": -5,
      "name": "Plant_Seaweed_Wet_Stack"
    },
    {
      "x": 3,
      "y": 9,
      "z": -5,
      "name": "Plant_Moss_Block_Green"
    },
    {
      "x": 4,
      "y": 9,
      "z": -5,
      "name": "Plant_Seaweed_Wet_Stack"
    },
    {
      "x": 5,
      "y": 9,
      "z": -5,
      "name": "Plant_Moss_Block_Green"
    },
    {
      "x": 6,
      "y": 9,
      "z": -5,
      "name": "Plant_Seaweed_Wet_Stack"
    },
    {
      "x": 8,
      "y": 9,
      "z": -5,
      "name": "Plant_Seaweed_Wet_Stack"
    },
    {
      "x": 10,
      "y": 9,
      "z": -5,
      "name": "Plant_Seaweed_Wet_Stack"
    },
    {
      "x": 11,
      "y": 9,
      "z": -5,
      "name": "Plant_Seaweed_Wet_Stack"
    },
    {
      "x": 1,
      "y": 10,
      "z": -5,
      "name": "Plant_Seaweed_Wet_Stack"
    },
    {
      "x": 2,
      "y": 10,
      "z": -5,
      "name": "Plant_Seaweed_Wet_Stack"
    },
    {
      "x": 3,
      "y": 10,
      "z": -5,
      "name": "Plant_Seaweed_Wet_Stack"
    },
    {
      "x": 4,
      "y": 10,
      "z": -5,
      "name": "Plant_Seaweed_Wet_Stack"
    },
    {
      "x": 5,
      "y": 10,
      "z": -5,
      "name": "Plant_Moss_Block_Green"
    },
    {
      "x": 6,
      "y": 10,
      "z": -5,
      "name": "Plant_Seaweed_Wet_Stack"
    },
    {
      "x": 8,
      "y": 10,
      "z": -5,
      "name": "Plant_Seaweed_Wet_Stack"
    },
    {
      "x": 10,
      "y": 10,
      "z": -5,
      "name": "Plant_Seaweed_Wet_Stack"
    },
    {
      "x": 11,
      "y": 10,
      "z": -5,
      "name": "Plant_Seaweed_Wet_Stack"
    },
    {
      "x": 1,
      "y": 11,
      "z": -5,
      "name": "Plant_Seaweed_Wet_Stack"
    },
    {
      "x": 2,
      "y": 11,
      "z": -5,
      "name": "Plant_Seaweed_Wet_Stack"
    },
    {
      "x": 3,
      "y": 11,
      "z": -5,
      "name": "Plant_Seaweed_Wet_Stack"
    },
    {
      "x": 4,
      "y": 11,
      "z": -5,
      "name": "Plant_Seaweed_Wet_Stack"
    },
    {
      "x": 5,
      "y": 11,
      "z": -5,
      "name": "Plant_Seaweed_Wet_Stack"
    },
    {
      "x": 6,
      "y": 11,
      "z": -5,
      "name": "Plant_Seaweed_Wet_Stack"
    },
    {
      "x": 8,
      "y": 11,
      "z": -5,
      "name": "Plant_Seaweed_Wet_Stack"
    },
    {
      "x": 10,
      "y": 11,
      "z": -5,
      "name": "Plant_Seaweed_Wet_Stack"
    },
    {
      "x": 11,
      "y": 11,
      "z": -5,
      "name": "Plant_Seaweed_Wet_Stack"
    },
    {
      "x": 1,
      "y": 12,
      "z": -5,
      "name": "Plant_Seaweed_Wet_Stack"
    },
    {
      "x": 2,
      "y": 12,
      "z": -5,
      "name": "Plant_Seaweed_Wet_Stack"
    },
    {
      "x": 3,
      "y": 12,
      "z": -5,
      "name": "Plant_Seaweed_Wet_Stack"
    },
    {
      "x": 4,
      "y": 12,
      "z": -5,
      "name": "Plant_Seaweed_Wet_Stack"
    },
    {
      "x": 5,
      "y": 12,
      "z": -5,
      "name": "Plant_Seaweed_Wet_Stack"
    },
    {
      "x": 6,
      "y": 12,
      "z": -5,
      "name": "Plant_Seaweed_Wet_Stack"
    },
    {
      "x": 8,
      "y": 12,
      "z": -5,
      "name": "Plant_Seaweed_Wet_Stack"
    },
    {
      "x": 10,
      "y": 12,
      "z": -5,
      "name": "Plant_Seaweed_Wet_Stack"
    },
    {
      "x": 11,
      "y": 12,
      "z": -5,
      "name": "Plant_Seaweed_Wet_Stack"
    },
    {
      "x": 1,
      "y": 1,
      "z": -4,
      "name": "Wood_Spiral_Trunk_Full"
    },
    {
      "x": 2,
      "y": 1,
      "z": -4,
      "name": "Wood_Spiral_Trunk_Full"
    },
    {
      "x": 6,
      "y": 2,
      "z": -4,
      "name": "Wood_Spiral_Trunk_Full"
    },
    {
      "x": 7,
      "y": 2,
      "z": -4,
      "name": "Wood_Spiral_Trunk_Full"
    },
    {
      "x": 9,
      "y": 2,
      "z": -4,
      "name": "Plant_Moss_Block_Green"
    },
    {
      "x": 1,
      "y": 3,
      "z": -4,
      "name": "Wood_Spiral_Trunk_Full"
    },
    {
      "x": 2,
      "y": 3,
      "z": -4,
      "name": "Wood_Spiral_Trunk_Full"
    },
    {
      "x": 7,
      "y": 3,
      "z": -4,
      "name": "Wood_Spiral_Trunk_Full"
    },
    {
      "x": 8,
      "y": 3,
      "z": -4,
      "name": "Wood_Spiral_Trunk_Full"
    },
    {
      "x": 9,
      "y": 3,
      "z": -4,
      "name": "Plant_Seaweed_Wet_Stack"
    },
    {
      "x": 10,
      "y": 3,
      "z": -4,
      "name": "Plant_Moss_Block_Green"
    },
    {
      "x": 2,
      "y": 4,
      "z": -4,
      "name": "Wood_Spiral_Trunk_Full"
    },
    {
      "x": 6,
      "y": 4,
      "z": -4,
      "name": "Plant_Moss_Block_Green"
    },
    {
      "x": 7,
      "y": 4,
      "z": -4,
      "name": "Plant_Moss_Block_Green"
    },
    {
      "x": 10,
      "y": 4,
      "z": -4,
      "name": "Plant_Seaweed_Wet_Stack"
    },
    {
      "x": 12,
      "y": 4,
      "z": -4,
      "name": "Plant_Moss_Block_Green"
    },
    {
      "x": 2,
      "y": 5,
      "z": -4,
      "name": "Wood_Spiral_Trunk_Full"
    },
    {
      "x": 6,
      "y": 5,
      "z": -4,
      "name": "Plant_Seaweed_Wet_Stack"
    },
    {
      "x": 7,
      "y": 5,
      "z": -4,
      "name": "Plant_Seaweed_Wet_Stack"
    },
    {
      "x": 9,
      "y": 5,
      "z": -4,
      "name": "Plant_Moss_Block_Green"
    },
    {
      "x": 10,
      "y": 5,
      "z": -4,
      "name": "Plant_Seaweed_Wet_Stack"
    },
    {
      "x": 12,
      "y": 5,
      "z": -4,
      "name": "Plant_Moss_Block_Green"
    },
    {
      "x": 6,
      "y": 6,
      "z": -4,
      "name": "Plant_Seaweed_Wet_Stack"
    },
    {
      "x": 7,
      "y": 6,
      "z": -4,
      "name": "Plant_Seaweed_Wet_Stack"
    },
    {
      "x": 9,
      "y": 6,
      "z": -4,
      "name": "Plant_Moss_Block_Green"
    },
    {
      "x": 10,
      "y": 6,
      "z": -4,
      "name": "Plant_Seaweed_Wet_Stack"
    },
    {
      "x": 12,
      "y": 6,
      "z": -4,
      "name": "Plant_Seaweed_Wet_Stack"
    },
    {
      "x": 2,
      "y": 7,
      "z": -4,
      "name": "Plant_Moss_Block_Green"
    },
    {
      "x": 3,
      "y": 7,
      "z": -4,
      "name": "Plant_Moss_Block_Green"
    },
    {
      "x": 4,
      "y": 7,
      "z": -4,
      "name": "Plant_Moss_Block_Green"
    },
    {
      "x": 5,
      "y": 7,
      "z": -4,
      "name": "Plant_Moss_Block_Green"
    },
    {
      "x": 6,
      "y": 7,
      "z": -4,
      "name": "Plant_Seaweed_Wet_Stack"
    },
    {
      "x": 7,
      "y": 7,
      "z": -4,
      "name": "Plant_Seaweed_Wet_Stack"
    },
    {
      "x": 9,
      "y": 7,
      "z": -4,
      "name": "Plant_Seaweed_Wet_Stack"
    },
    {
      "x": 10,
      "y": 7,
      "z": -4,
      "name": "Plant_Seaweed_Wet_Stack"
    },
    {
      "x": 12,
      "y": 7,
      "z": -4,
      "name": "Plant_Seaweed_Wet_Stack"
    },
    {
      "x": 1,
      "y": 8,
      "z": -4,
      "name": "Plant_Moss_Block_Green"
    },
    {
      "x": 2,
      "y": 8,
      "z": -4,
      "name": "Plant_Moss_Block_Green"
    },
    {
      "x": 3,
      "y": 8,
      "z": -4,
      "name": "Plant_Seaweed_Wet_Stack"
    },
    {
      "x": 4,
      "y": 8,
      "z": -4,
      "name": "Plant_Moss_Block_Green"
    },
    {
      "x": 5,
      "y": 8,
      "z": -4,
      "name": "Plant_Seaweed_Wet_Stack"
    },
    {
      "x": 6,
      "y": 8,
      "z": -4,
      "name": "Plant_Seaweed_Wet_Stack"
    },
    {
      "x": 7,
      "y": 8,
      "z": -4,
      "name": "Plant_Seaweed_Wet_Stack"
    },
    {
      "x": 9,
      "y": 8,
      "z": -4,
      "name": "Plant_Seaweed_Wet_Stack"
    },
    {
      "x": 10,
      "y": 8,
      "z": -4,
      "name": "Plant_Seaweed_Wet_Stack"
    },
    {
      "x": 12,
      "y": 8,
      "z": -4,
      "name": "Plant_Seaweed_Wet_Stack"
    },
    {
      "x": 1,
      "y": 9,
      "z": -4,
      "name": "Plant_Moss_Block_Green"
    },
    {
      "x": 2,
      "y": 9,
      "z": -4,
      "name": "Plant_Seaweed_Wet_Stack"
    },
    {
      "x": 3,
      "y": 9,
      "z": -4,
      "name": "Plant_Seaweed_Wet_Stack"
    },
    {
      "x": 4,
      "y": 9,
      "z": -4,
      "name": "Plant_Seaweed_Wet_Stack"
    },
    {
      "x": 5,
      "y": 9,
      "z": -4,
      "name": "Plant_Seaweed_Wet_Stack"
    },
    {
      "x": 6,
      "y": 9,
      "z": -4,
      "name": "Plant_Seaweed_Wet_Stack"
    },
    {
      "x": 7,
      "y": 9,
      "z": -4,
      "name": "Plant_Seaweed_Wet_Stack"
    },
    {
      "x": 9,
      "y": 9,
      "z": -4,
      "name": "Plant_Seaweed_Wet_Stack"
    },
    {
      "x": 10,
      "y": 9,
      "z": -4,
      "name": "Plant_Seaweed_Wet_Stack"
    },
    {
      "x": 12,
      "y": 9,
      "z": -4,
      "name": "Plant_Seaweed_Wet_Stack"
    },
    {
      "x": 1,
      "y": 10,
      "z": -4,
      "name": "Plant_Seaweed_Wet_Stack"
    },
    {
      "x": 2,
      "y": 10,
      "z": -4,
      "name": "Plant_Seaweed_Wet_Stack"
    },
    {
      "x": 3,
      "y": 10,
      "z": -4,
      "name": "Plant_Seaweed_Wet_Stack"
    },
    {
      "x": 4,
      "y": 10,
      "z": -4,
      "name": "Plant_Seaweed_Wet_Stack"
    },
    {
      "x": 5,
      "y": 10,
      "z": -4,
      "name": "Plant_Seaweed_Wet_Stack"
    },
    {
      "x": 6,
      "y": 10,
      "z": -4,
      "name": "Plant_Seaweed_Wet_Stack"
    },
    {
      "x": 7,
      "y": 10,
      "z": -4,
      "name": "Plant_Seaweed_Wet_Stack"
    },
    {
      "x": 9,
      "y": 10,
      "z": -4,
      "name": "Plant_Seaweed_Wet_Stack"
    },
    {
      "x": 10,
      "y": 10,
      "z": -4,
      "name": "Plant_Seaweed_Wet_Stack"
    },
    {
      "x": 12,
      "y": 10,
      "z": -4,
      "name": "Plant_Seaweed_Wet_Stack"
    },
    {
      "x": 1,
      "y": 11,
      "z": -4,
      "name": "Plant_Seaweed_Wet_Stack"
    },
    {
      "x": 2,
      "y": 11,
      "z": -4,
      "name": "Plant_Seaweed_Wet_Stack"
    },
    {
      "x": 3,
      "y": 11,
      "z": -4,
      "name": "Plant_Seaweed_Wet_Stack"
    },
    {
      "x": 4,
      "y": 11,
      "z": -4,
      "name": "Plant_Seaweed_Wet_Stack"
    },
    {
      "x": 5,
      "y": 11,
      "z": -4,
      "name": "Plant_Seaweed_Wet_Stack"
    },
    {
      "x": 6,
      "y": 11,
      "z": -4,
      "name": "Plant_Seaweed_Wet_Stack"
    },
    {
      "x": 7,
      "y": 11,
      "z": -4,
      "name": "Plant_Seaweed_Wet_Stack"
    },
    {
      "x": 9,
      "y": 11,
      "z": -4,
      "name": "Plant_Seaweed_Wet_Stack"
    },
    {
      "x": 10,
      "y": 11,
      "z": -4,
      "name": "Plant_Seaweed_Wet_Stack"
    },
    {
      "x": 12,
      "y": 11,
      "z": -4,
      "name": "Plant_Seaweed_Wet_Stack"
    },
    {
      "x": 1,
      "y": 12,
      "z": -4,
      "name": "Plant_Seaweed_Wet_Stack"
    },
    {
      "x": 2,
      "y": 12,
      "z": -4,
      "name": "Plant_Seaweed_Wet_Stack"
    },
    {
      "x": 3,
      "y": 12,
      "z": -4,
      "name": "Plant_Seaweed_Wet_Stack"
    },
    {
      "x": 4,
      "y": 12,
      "z": -4,
      "name": "Plant_Seaweed_Wet_Stack"
    },
    {
      "x": 5,
      "y": 12,
      "z": -4,
      "name": "Plant_Seaweed_Wet_Stack"
    },
    {
      "x": 6,
      "y": 12,
      "z": -4,
      "name": "Plant_Seaweed_Wet_Stack"
    },
    {
      "x": 7,
      "y": 12,
      "z": -4,
      "name": "Plant_Seaweed_Wet_Stack"
    },
    {
      "x": 9,
      "y": 12,
      "z": -4,
      "name": "Plant_Seaweed_Wet_Stack"
    },
    {
      "x": 10,
      "y": 12,
      "z": -4,
      "name": "Plant_Seaweed_Wet_Stack"
    },
    {
      "x": 12,
      "y": 12,
      "z": -4,
      "name": "Plant_Seaweed_Wet_Stack"
    },
    {
      "x": 1,
      "y": 1,
      "z": -3,
      "name": "Wood_Spiral_Trunk_Full"
    },
    {
      "x": 1,
      "y": 2,
      "z": -3,
      "name": "Wood_Spiral_Trunk_Full"
    },
    {
      "x": 7,
      "y": 2,
      "z": -3,
      "name": "Plant_Moss_Block_Green"
    },
    {
      "x": 9,
      "y": 2,
      "z": -3,
      "name": "Plant_Moss_Block_Green"
    },
    {
      "x": 10,
      "y": 2,
      "z": -3,
      "name": "Plant_Moss_Block_Green"
    },
    {
      "x": 12,
      "y": 2,
      "z": -3,
      "name": "Plant_Moss_Block_Green"
    },
    {
      "x": 1,
      "y": 3,
      "z": -3,
      "name": "Wood_Spiral_Trunk_Full"
    },
    {
      "x": 7,
      "y": 3,
      "z": -3,
      "name": "Plant_Seaweed_Wet_Stack"
    },
    {
      "x": 8,
      "y": 3,
      "z": -3,
      "name": "Wood_Spiral_Trunk_Full"
    },
    {
      "x": 9,
      "y": 3,
      "z": -3,
      "name": "Wood_Spiral_Trunk_Full"
    },
    {
      "x": 10,
      "y": 3,
      "z": -3,
      "name": "Plant_Moss_Block_Green"
    },
    {
      "x": 11,
      "y": 3,
      "z": -3,
      "name": "Plant_Moss_Block_Green"
    },
    {
      "x": 12,
      "y": 3,
      "z": -3,
      "name": "Plant_Seaweed_Wet_Stack"
    },
    {
      "x": 9,
      "y": 4,
      "z": -3,
      "name": "Plant_Moss_Block_Green"
    },
    {
      "x": 10,
      "y": 4,
      "z": -3,
      "name": "Plant_Seaweed_Wet_Stack"
    },
    {
      "x": 11,
      "y": 4,
      "z": -3,
      "name": "Plant_Moss_Block_Green"
    },
    {
      "x": 12,
      "y": 4,
      "z": -3,
      "name": "Plant_Moss_Block_Green"
    },
    {
      "x": 9,
      "y": 5,
      "z": -3,
      "name": "Plant_Moss_Block_Green"
    },
    {
      "x": 10,
      "y": 5,
      "z": -3,
      "name": "Plant_Seaweed_Wet_Stack"
    },
    {
      "x": 11,
      "y": 5,
      "z": -3,
      "name": "Plant_Moss_Block_Green"
    },
    {
      "x": 12,
      "y": 5,
      "z": -3,
      "name": "Plant_Seaweed_Wet_Stack"
    },
    {
      "x": 5,
      "y": 6,
      "z": -3,
      "name": "Plant_Moss_Block_Green"
    },
    {
      "x": 6,
      "y": 6,
      "z": -3,
      "name": "Plant_Moss_Block_Green"
    },
    {
      "x": 8,
      "y": 6,
      "z": -3,
      "name": "Plant_Moss_Block_Green"
    },
    {
      "x": 9,
      "y": 6,
      "z": -3,
      "name": "Plant_Seaweed_Wet_Stack"
    },
    {
      "x": 10,
      "y": 6,
      "z": -3,
      "name": "Plant_Seaweed_Wet_Stack"
    },
    {
      "x": 11,
      "y": 6,
      "z": -3,
      "name": "Plant_Moss_Block_Green"
    },
    {
      "x": 12,
      "y": 6,
      "z": -3,
      "name": "Plant_Seaweed_Wet_Stack"
    },
    {
      "x": 4,
      "y": 7,
      "z": -3,
      "name": "Plant_Moss_Block_Green"
    },
    {
      "x": 5,
      "y": 7,
      "z": -3,
      "name": "Plant_Seaweed_Wet_Stack"
    },
    {
      "x": 6,
      "y": 7,
      "z": -3,
      "name": "Plant_Moss_Block_Green"
    },
    {
      "x": 8,
      "y": 7,
      "z": -3,
      "name": "Plant_Seaweed_Wet_Stack"
    },
    {
      "x": 9,
      "y": 7,
      "z": -3,
      "name": "Plant_Seaweed_Wet_Stack"
    },
    {
      "x": 10,
      "y": 7,
      "z": -3,
      "name": "Plant_Seaweed_Wet_Stack"
    },
    {
      "x": 11,
      "y": 7,
      "z": -3,
      "name": "Plant_Seaweed_Wet_Stack"
    },
    {
      "x": 12,
      "y": 7,
      "z": -3,
      "name": "Plant_Seaweed_Wet_Stack"
    },
    {
      "x": 0,
      "y": 8,
      "z": -3,
      "name": "Plant_Moss_Block_Green"
    },
    {
      "x": 1,
      "y": 8,
      "z": -3,
      "name": "Plant_Moss_Block_Green"
    },
    {
      "x": 4,
      "y": 8,
      "z": -3,
      "name": "Plant_Moss_Block_Green"
    },
    {
      "x": 5,
      "y": 8,
      "z": -3,
      "name": "Plant_Seaweed_Wet_Stack"
    },
    {
      "x": 6,
      "y": 8,
      "z": -3,
      "name": "Plant_Seaweed_Wet_Stack"
    },
    {
      "x": 8,
      "y": 8,
      "z": -3,
      "name": "Plant_Seaweed_Wet_Stack"
    },
    {
      "x": 9,
      "y": 8,
      "z": -3,
      "name": "Plant_Seaweed_Wet_Stack"
    },
    {
      "x": 10,
      "y": 8,
      "z": -3,
      "name": "Plant_Seaweed_Wet_Stack"
    },
    {
      "x": 11,
      "y": 8,
      "z": -3,
      "name": "Plant_Seaweed_Wet_Stack"
    },
    {
      "x": 12,
      "y": 8,
      "z": -3,
      "name": "Plant_Seaweed_Wet_Stack"
    },
    {
      "x": 0,
      "y": 9,
      "z": -3,
      "name": "Plant_Seaweed_Wet_Stack"
    },
    {
      "x": 1,
      "y": 9,
      "z": -3,
      "name": "Plant_Seaweed_Wet_Stack"
    },
    {
      "x": 3,
      "y": 9,
      "z": -3,
      "name": "Plant_Moss_Block_Green"
    },
    {
      "x": 4,
      "y": 9,
      "z": -3,
      "name": "Plant_Seaweed_Wet_Stack"
    },
    {
      "x": 5,
      "y": 9,
      "z": -3,
      "name": "Plant_Seaweed_Wet_Stack"
    },
    {
      "x": 6,
      "y": 9,
      "z": -3,
      "name": "Plant_Seaweed_Wet_Stack"
    },
    {
      "x": 8,
      "y": 9,
      "z": -3,
      "name": "Plant_Seaweed_Wet_Stack"
    },
    {
      "x": 9,
      "y": 9,
      "z": -3,
      "name": "Plant_Seaweed_Wet_Stack"
    },
    {
      "x": 10,
      "y": 9,
      "z": -3,
      "name": "Plant_Seaweed_Wet_Stack"
    },
    {
      "x": 11,
      "y": 9,
      "z": -3,
      "name": "Plant_Seaweed_Wet_Stack"
    },
    {
      "x": 12,
      "y": 9,
      "z": -3,
      "name": "Plant_Seaweed_Wet_Stack"
    },
    {
      "x": 0,
      "y": 10,
      "z": -3,
      "name": "Plant_Seaweed_Wet_Stack"
    },
    {
      "x": 1,
      "y": 10,
      "z": -3,
      "name": "Plant_Seaweed_Wet_Stack"
    },
    {
      "x": 3,
      "y": 10,
      "z": -3,
      "name": "Plant_Seaweed_Wet_Stack"
    },
    {
      "x": 4,
      "y": 10,
      "z": -3,
      "name": "Plant_Seaweed_Wet_Stack"
    },
    {
      "x": 5,
      "y": 10,
      "z": -3,
      "name": "Plant_Seaweed_Wet_Stack"
    },
    {
      "x": 6,
      "y": 10,
      "z": -3,
      "name": "Plant_Seaweed_Wet_Stack"
    },
    {
      "x": 8,
      "y": 10,
      "z": -3,
      "name": "Plant_Seaweed_Wet_Stack"
    },
    {
      "x": 9,
      "y": 10,
      "z": -3,
      "name": "Plant_Seaweed_Wet_Stack"
    },
    {
      "x": 10,
      "y": 10,
      "z": -3,
      "name": "Plant_Seaweed_Wet_Stack"
    },
    {
      "x": 11,
      "y": 10,
      "z": -3,
      "name": "Plant_Seaweed_Wet_Stack"
    },
    {
      "x": 12,
      "y": 10,
      "z": -3,
      "name": "Plant_Seaweed_Wet_Stack"
    },
    {
      "x": 0,
      "y": 11,
      "z": -3,
      "name": "Plant_Seaweed_Wet_Stack"
    },
    {
      "x": 1,
      "y": 11,
      "z": -3,
      "name": "Plant_Seaweed_Wet_Stack"
    },
    {
      "x": 3,
      "y": 11,
      "z": -3,
      "name": "Plant_Seaweed_Wet_Stack"
    },
    {
      "x": 4,
      "y": 11,
      "z": -3,
      "name": "Plant_Seaweed_Wet_Stack"
    },
    {
      "x": 5,
      "y": 11,
      "z": -3,
      "name": "Plant_Seaweed_Wet_Stack"
    },
    {
      "x": 6,
      "y": 11,
      "z": -3,
      "name": "Plant_Seaweed_Wet_Stack"
    },
    {
      "x": 8,
      "y": 11,
      "z": -3,
      "name": "Plant_Seaweed_Wet_Stack"
    },
    {
      "x": 9,
      "y": 11,
      "z": -3,
      "name": "Plant_Seaweed_Wet_Stack"
    },
    {
      "x": 10,
      "y": 11,
      "z": -3,
      "name": "Plant_Seaweed_Wet_Stack"
    },
    {
      "x": 11,
      "y": 11,
      "z": -3,
      "name": "Plant_Seaweed_Wet_Stack"
    },
    {
      "x": 12,
      "y": 11,
      "z": -3,
      "name": "Plant_Seaweed_Wet_Stack"
    },
    {
      "x": 0,
      "y": 12,
      "z": -3,
      "name": "Plant_Seaweed_Wet_Stack"
    },
    {
      "x": 1,
      "y": 12,
      "z": -3,
      "name": "Plant_Seaweed_Wet_Stack"
    },
    {
      "x": 3,
      "y": 12,
      "z": -3,
      "name": "Plant_Seaweed_Wet_Stack"
    },
    {
      "x": 4,
      "y": 12,
      "z": -3,
      "name": "Plant_Seaweed_Wet_Stack"
    },
    {
      "x": 5,
      "y": 12,
      "z": -3,
      "name": "Plant_Seaweed_Wet_Stack"
    },
    {
      "x": 6,
      "y": 12,
      "z": -3,
      "name": "Plant_Seaweed_Wet_Stack"
    },
    {
      "x": 8,
      "y": 12,
      "z": -3,
      "name": "Plant_Seaweed_Wet_Stack"
    },
    {
      "x": 9,
      "y": 12,
      "z": -3,
      "name": "Plant_Seaweed_Wet_Stack"
    },
    {
      "x": 10,
      "y": 12,
      "z": -3,
      "name": "Plant_Seaweed_Wet_Stack"
    },
    {
      "x": 11,
      "y": 12,
      "z": -3,
      "name": "Plant_Seaweed_Wet_Stack"
    },
    {
      "x": 12,
      "y": 12,
      "z": -3,
      "name": "Plant_Seaweed_Wet_Stack"
    },
    {
      "x": 1,
      "y": 1,
      "z": -2,
      "name": "Wood_Spiral_Trunk_Full"
    },
    {
      "x": 0,
      "y": 2,
      "z": -2,
      "name": "Wood_Spiral_Trunk_Full"
    },
    {
      "x": 1,
      "y": 2,
      "z": -2,
      "name": "Wood_Spiral_Trunk_Full"
    },
    {
      "x": 2,
      "y": 2,
      "z": -2,
      "name": "Wood_Spiral_Trunk_Full"
    },
    {
      "x": 8,
      "y": 3,
      "z": -2,
      "name": "Plant_Moss_Block_Green"
    },
    {
      "x": 9,
      "y": 3,
      "z": -2,
      "name": "Plant_Moss_Block_Green"
    },
    {
      "x": 10,
      "y": 3,
      "z": -2,
      "name": "Plant_Moss_Block_Green"
    },
    {
      "x": 11,
      "y": 3,
      "z": -2,
      "name": "Plant_Moss_Block_Green"
    },
    {
      "x": 4,
      "y": 4,
      "z": -2,
      "name": "Plant_Moss_Block_Green"
    },
    {
      "x": 7,
      "y": 4,
      "z": -2,
      "name": "Plant_Moss_Block_Green"
    },
    {
      "x": 8,
      "y": 4,
      "z": -2,
      "name": "Plant_Moss_Block_Green"
    },
    {
      "x": 9,
      "y": 4,
      "z": -2,
      "name": "Plant_Seaweed_Wet_Stack"
    },
    {
      "x": 10,
      "y": 4,
      "z": -2,
      "name": "Plant_Moss_Block_Green"
    },
    {
      "x": 11,
      "y": 4,
      "z": -2,
      "name": "Plant_Seaweed_Wet_Stack"
    },
    {
      "x": 4,
      "y": 5,
      "z": -2,
      "name": "Plant_Seaweed_Wet_Stack"
    },
    {
      "x": 5,
      "y": 5,
      "z": -2,
      "name": "Plant_Moss_Block_Green"
    },
    {
      "x": 7,
      "y": 5,
      "z": -2,
      "name": "Plant_Moss_Block_Green"
    },
    {
      "x": 8,
      "y": 5,
      "z": -2,
      "name": "Plant_Moss_Block_Green"
    },
    {
      "x": 9,
      "y": 5,
      "z": -2,
      "name": "Plant_Seaweed_Wet_Stack"
    },
    {
      "x": 10,
      "y": 5,
      "z": -2,
      "name": "Plant_Seaweed_Wet_Stack"
    },
    {
      "x": 11,
      "y": 5,
      "z": -2,
      "name": "Plant_Seaweed_Wet_Stack"
    },
    {
      "x": 3,
      "y": 6,
      "z": -2,
      "name": "Plant_Moss_Block_Green"
    },
    {
      "x": 4,
      "y": 6,
      "z": -2,
      "name": "Plant_Seaweed_Wet_Stack"
    },
    {
      "x": 5,
      "y": 6,
      "z": -2,
      "name": "Plant_Moss_Block_Green"
    },
    {
      "x": 7,
      "y": 6,
      "z": -2,
      "name": "Plant_Seaweed_Wet_Stack"
    },
    {
      "x": 8,
      "y": 6,
      "z": -2,
      "name": "Plant_Moss_Block_Green"
    },
    {
      "x": 9,
      "y": 6,
      "z": -2,
      "name": "Plant_Seaweed_Wet_Stack"
    },
    {
      "x": 10,
      "y": 6,
      "z": -2,
      "name": "Plant_Seaweed_Wet_Stack"
    },
    {
      "x": 11,
      "y": 6,
      "z": -2,
      "name": "Plant_Seaweed_Wet_Stack"
    },
    {
      "x": 3,
      "y": 7,
      "z": -2,
      "name": "Plant_Moss_Block_Green"
    },
    {
      "x": 4,
      "y": 7,
      "z": -2,
      "name": "Plant_Seaweed_Wet_Stack"
    },
    {
      "x": 5,
      "y": 7,
      "z": -2,
      "name": "Plant_Seaweed_Wet_Stack"
    },
    {
      "x": 7,
      "y": 7,
      "z": -2,
      "name": "Plant_Seaweed_Wet_Stack"
    },
    {
      "x": 8,
      "y": 7,
      "z": -2,
      "name": "Plant_Moss_Block_Green"
    },
    {
      "x": 9,
      "y": 7,
      "z": -2,
      "name": "Plant_Seaweed_Wet_Stack"
    },
    {
      "x": 10,
      "y": 7,
      "z": -2,
      "name": "Plant_Seaweed_Wet_Stack"
    },
    {
      "x": 11,
      "y": 7,
      "z": -2,
      "name": "Plant_Seaweed_Wet_Stack"
    },
    {
      "x": 3,
      "y": 8,
      "z": -2,
      "name": "Plant_Seaweed_Wet_Stack"
    },
    {
      "x": 4,
      "y": 8,
      "z": -2,
      "name": "Plant_Seaweed_Wet_Stack"
    },
    {
      "x": 5,
      "y": 8,
      "z": -2,
      "name": "Plant_Seaweed_Wet_Stack"
    },
    {
      "x": 7,
      "y": 8,
      "z": -2,
      "name": "Plant_Seaweed_Wet_Stack"
    },
    {
      "x": 8,
      "y": 8,
      "z": -2,
      "name": "Plant_Seaweed_Wet_Stack"
    },
    {
      "x": 9,
      "y": 8,
      "z": -2,
      "name": "Plant_Seaweed_Wet_Stack"
    },
    {
      "x": 10,
      "y": 8,
      "z": -2,
      "name": "Plant_Seaweed_Wet_Stack"
    },
    {
      "x": 11,
      "y": 8,
      "z": -2,
      "name": "Plant_Seaweed_Wet_Stack"
    },
    {
      "x": 3,
      "y": 9,
      "z": -2,
      "name": "Plant_Seaweed_Wet_Stack"
    },
    {
      "x": 4,
      "y": 9,
      "z": -2,
      "name": "Plant_Seaweed_Wet_Stack"
    },
    {
      "x": 5,
      "y": 9,
      "z": -2,
      "name": "Plant_Seaweed_Wet_Stack"
    },
    {
      "x": 7,
      "y": 9,
      "z": -2,
      "name": "Plant_Seaweed_Wet_Stack"
    },
    {
      "x": 8,
      "y": 9,
      "z": -2,
      "name": "Plant_Seaweed_Wet_Stack"
    },
    {
      "x": 9,
      "y": 9,
      "z": -2,
      "name": "Plant_Seaweed_Wet_Stack"
    },
    {
      "x": 10,
      "y": 9,
      "z": -2,
      "name": "Plant_Seaweed_Wet_Stack"
    },
    {
      "x": 11,
      "y": 9,
      "z": -2,
      "name": "Plant_Seaweed_Wet_Stack"
    },
    {
      "x": 3,
      "y": 10,
      "z": -2,
      "name": "Plant_Seaweed_Wet_Stack"
    },
    {
      "x": 4,
      "y": 10,
      "z": -2,
      "name": "Plant_Seaweed_Wet_Stack"
    },
    {
      "x": 5,
      "y": 10,
      "z": -2,
      "name": "Plant_Seaweed_Wet_Stack"
    },
    {
      "x": 7,
      "y": 10,
      "z": -2,
      "name": "Plant_Seaweed_Wet_Stack"
    },
    {
      "x": 8,
      "y": 10,
      "z": -2,
      "name": "Plant_Seaweed_Wet_Stack"
    },
    {
      "x": 9,
      "y": 10,
      "z": -2,
      "name": "Plant_Seaweed_Wet_Stack"
    },
    {
      "x": 10,
      "y": 10,
      "z": -2,
      "name": "Plant_Seaweed_Wet_Stack"
    },
    {
      "x": 11,
      "y": 10,
      "z": -2,
      "name": "Plant_Seaweed_Wet_Stack"
    },
    {
      "x": 3,
      "y": 11,
      "z": -2,
      "name": "Plant_Seaweed_Wet_Stack"
    },
    {
      "x": 4,
      "y": 11,
      "z": -2,
      "name": "Plant_Seaweed_Wet_Stack"
    },
    {
      "x": 5,
      "y": 11,
      "z": -2,
      "name": "Plant_Seaweed_Wet_Stack"
    },
    {
      "x": 7,
      "y": 11,
      "z": -2,
      "name": "Plant_Seaweed_Wet_Stack"
    },
    {
      "x": 8,
      "y": 11,
      "z": -2,
      "name": "Plant_Seaweed_Wet_Stack"
    },
    {
      "x": 9,
      "y": 11,
      "z": -2,
      "name": "Plant_Seaweed_Wet_Stack"
    },
    {
      "x": 10,
      "y": 11,
      "z": -2,
      "name": "Plant_Seaweed_Wet_Stack"
    },
    {
      "x": 11,
      "y": 11,
      "z": -2,
      "name": "Plant_Seaweed_Wet_Stack"
    },
    {
      "x": 3,
      "y": 12,
      "z": -2,
      "name": "Plant_Seaweed_Wet_Stack"
    },
    {
      "x": 4,
      "y": 12,
      "z": -2,
      "name": "Plant_Seaweed_Wet_Stack"
    },
    {
      "x": 5,
      "y": 12,
      "z": -2,
      "name": "Plant_Seaweed_Wet_Stack"
    },
    {
      "x": 7,
      "y": 12,
      "z": -2,
      "name": "Plant_Seaweed_Wet_Stack"
    },
    {
      "x": 8,
      "y": 12,
      "z": -2,
      "name": "Plant_Seaweed_Wet_Stack"
    },
    {
      "x": 9,
      "y": 12,
      "z": -2,
      "name": "Plant_Seaweed_Wet_Stack"
    },
    {
      "x": 10,
      "y": 12,
      "z": -2,
      "name": "Plant_Seaweed_Wet_Stack"
    },
    {
      "x": 11,
      "y": 12,
      "z": -2,
      "name": "Plant_Seaweed_Wet_Stack"
    },
    {
      "x": 0,
      "y": 2,
      "z": -1,
      "name": "Wood_Spiral_Trunk_Full"
    },
    {
      "x": 2,
      "y": 2,
      "z": -1,
      "name": "Wood_Spiral_Trunk_Full"
    },
    {
      "x": 3,
      "y": 2,
      "z": -1,
      "name": "Wood_Spiral_Trunk_Full"
    },
    {
      "x": 0,
      "y": 3,
      "z": -1,
      "name": "Wood_Spiral_Trunk_Half"
    },
    {
      "x": 2,
      "y": 3,
      "z": -1,
      "name": "Wood_Spiral_Trunk_Half"
    },
    {
      "x": 3,
      "y": 3,
      "z": -1,
      "name": "Wood_Spiral_Trunk_Full"
    },
    {
      "x": 4,
      "y": 3,
      "z": -1,
      "name": "Wood_Spiral_Trunk_Full"
    },
    {
      "x": 10,
      "y": 3,
      "z": -1,
      "name": "Plant_Moss_Block_Green"
    },
    {
      "x": 6,
      "y": 4,
      "z": -1,
      "name": "Plant_Moss_Block_Green"
    },
    {
      "x": 7,
      "y": 4,
      "z": -1,
      "name": "Plant_Moss_Block_Green"
    },
    {
      "x": 10,
      "y": 4,
      "z": -1,
      "name": "Plant_Moss_Block_Green"
    },
    {
      "x": 11,
      "y": 4,
      "z": -1,
      "name": "Plant_Moss_Block_Green"
    },
    {
      "x": 4,
      "y": 5,
      "z": -1,
      "name": "Plant_Moss_Block_Green"
    },
    {
      "x": 5,
      "y": 5,
      "z": -1,
      "name": "Plant_Moss_Block_Green"
    },
    {
      "x": 6,
      "y": 5,
      "z": -1,
      "name": "Plant_Seaweed_Wet_Stack"
    },
    {
      "x": 7,
      "y": 5,
      "z": -1,
      "name": "Plant_Moss_Block_Green"
    },
    {
      "x": 9,
      "y": 5,
      "z": -1,
      "name": "Plant_Moss_Block_Green"
    },
    {
      "x": 10,
      "y": 5,
      "z": -1,
      "name": "Plant_Seaweed_Wet_Stack"
    },
    {
      "x": 11,
      "y": 5,
      "z": -1,
      "name": "Plant_Moss_Block_Green"
    },
    {
      "x": 12,
      "y": 5,
      "z": -1,
      "name": "Plant_Moss_Block_Green"
    },
    {
      "x": 3,
      "y": 6,
      "z": -1,
      "name": "Plant_Moss_Block_Green"
    },
    {
      "x": 4,
      "y": 6,
      "z": -1,
      "name": "Plant_Moss_Block_Green"
    },
    {
      "x": 5,
      "y": 6,
      "z": -1,
      "name": "Plant_Seaweed_Wet_Stack"
    },
    {
      "x": 6,
      "y": 6,
      "z": -1,
      "name": "Plant_Seaweed_Wet_Stack"
    },
    {
      "x": 7,
      "y": 6,
      "z": -1,
      "name": "Plant_Seaweed_Wet_Stack"
    },
    {
      "x": 9,
      "y": 6,
      "z": -1,
      "name": "Plant_Moss_Block_Green"
    },
    {
      "x": 10,
      "y": 6,
      "z": -1,
      "name": "Plant_Seaweed_Wet_Stack"
    },
    {
      "x": 11,
      "y": 6,
      "z": -1,
      "name": "Plant_Seaweed_Wet_Stack"
    },
    {
      "x": 12,
      "y": 6,
      "z": -1,
      "name": "Plant_Seaweed_Wet_Stack"
    },
    {
      "x": 3,
      "y": 7,
      "z": -1,
      "name": "Plant_Seaweed_Wet_Stack"
    },
    {
      "x": 4,
      "y": 7,
      "z": -1,
      "name": "Plant_Seaweed_Wet_Stack"
    },
    {
      "x": 5,
      "y": 7,
      "z": -1,
      "name": "Plant_Seaweed_Wet_Stack"
    },
    {
      "x": 6,
      "y": 7,
      "z": -1,
      "name": "Plant_Seaweed_Wet_Stack"
    },
    {
      "x": 7,
      "y": 7,
      "z": -1,
      "name": "Plant_Seaweed_Wet_Stack"
    },
    {
      "x": 9,
      "y": 7,
      "z": -1,
      "name": "Plant_Moss_Block_Green"
    },
    {
      "x": 10,
      "y": 7,
      "z": -1,
      "name": "Plant_Seaweed_Wet_Stack"
    },
    {
      "x": 11,
      "y": 7,
      "z": -1,
      "name": "Plant_Seaweed_Wet_Stack"
    },
    {
      "x": 12,
      "y": 7,
      "z": -1,
      "name": "Plant_Seaweed_Wet_Stack"
    },
    {
      "x": 3,
      "y": 8,
      "z": -1,
      "name": "Plant_Seaweed_Wet_Stack"
    },
    {
      "x": 4,
      "y": 8,
      "z": -1,
      "name": "Plant_Seaweed_Wet_Stack"
    },
    {
      "x": 5,
      "y": 8,
      "z": -1,
      "name": "Plant_Seaweed_Wet_Stack"
    },
    {
      "x": 6,
      "y": 8,
      "z": -1,
      "name": "Plant_Seaweed_Wet_Stack"
    },
    {
      "x": 7,
      "y": 8,
      "z": -1,
      "name": "Plant_Seaweed_Wet_Stack"
    },
    {
      "x": 9,
      "y": 8,
      "z": -1,
      "name": "Plant_Seaweed_Wet_Stack"
    },
    {
      "x": 10,
      "y": 8,
      "z": -1,
      "name": "Plant_Seaweed_Wet_Stack"
    },
    {
      "x": 11,
      "y": 8,
      "z": -1,
      "name": "Plant_Seaweed_Wet_Stack"
    },
    {
      "x": 12,
      "y": 8,
      "z": -1,
      "name": "Plant_Seaweed_Wet_Stack"
    },
    {
      "x": 3,
      "y": 9,
      "z": -1,
      "name": "Plant_Seaweed_Wet_Stack"
    },
    {
      "x": 4,
      "y": 9,
      "z": -1,
      "name": "Plant_Seaweed_Wet_Stack"
    },
    {
      "x": 5,
      "y": 9,
      "z": -1,
      "name": "Plant_Seaweed_Wet_Stack"
    },
    {
      "x": 6,
      "y": 9,
      "z": -1,
      "name": "Plant_Seaweed_Wet_Stack"
    },
    {
      "x": 7,
      "y": 9,
      "z": -1,
      "name": "Plant_Seaweed_Wet_Stack"
    },
    {
      "x": 9,
      "y": 9,
      "z": -1,
      "name": "Plant_Seaweed_Wet_Stack"
    },
