{"anchorX":9,"anchorY":6,"anchorZ":6,"blockIdVersion":11,"blocks":[{"name":"Plant_Coral_Block_White","x":-15,"y":13,"z":-3},{"name":"Plant_Seaweed_Grass","x":-15,"y":14,"z":-3},{"name":"Plant_Coral_Block_White","x":-14,"y":13,"z":-8},{"name":"Plant_Seaweed_Moss_Stack","x":-14,"y":14,"z":-8},{"name":"Plant_Seaweed_Moss_Stack","x":-14,"y":15,"z":-8},{"name":"Plant_Seaweed_Moss_Stack","x":-14,"y":16,"z":-8},{"name":"Plant_Seaweed_Moss_Stack","x":-14,"y":17,"z":-8},{"name":"Plant_Seaweed_Moss_Stack","x":-14,"y":18,"z":-8},{"name":"Plant_Seaweed_Moss_Stack","x":-14,"y":19,"z":-8},{"name":"Plant_Seaweed_Moss_Stack","x":-14,"y":20,"z":-8},{"name":"Plant_Seaweed_Moss_Stack","x":-14,"y":21,"z":-8},{"name":"Plant_Seaweed_Moss_Stack","x":-14,"y":22,"z":-8},{"name":"Plant_Coral_Block_White","x":-14,"y":12,"z":-5},{"name":"Plant_Seaweed_Grass_Tall","x":-14,"y":13,"z":-5},{"filler":1024,"name":"Plant_Seaweed_Grass_Tall","x":-14,"y":14,"z":-5},{"name":"Plant_Coral_Block_White","x":-14,"y":12,"z":-3},{"name":"Plant_Coral_Block_White","x":-14,"y":13,"z":-3},{"name":"Plant_Seaweed_Moss_Stack","x":-14,"y":14,"z":-3},{"name":"Plant_Coral_Block_White","x":-14,"y":12,"z":-2},{"name":"Plant_Seaweed_Moss_Stack","x":-14,"y":13,"z":-2},{"name":"Plant_Seaweed_Moss_Stack","x":-14,"y":14,"z":-2},{"name":"Plant_Seaweed_Moss_Stack","x":-14,"y":15,"z":-2},{"name":"Plant_Coral_Block_White","x":-13,"y":12,"z":-10},{"name":"Plant_Seaweed_Moss_Stack","x":-13,"y":13,"z":-10},{"name":"Plant_Seaweed_Moss_Stack","x":-13,"y":14,"z":-10},{"name":"Plant_Seaweed_Moss_Stack","x":-13,"y":15,"z":-10},{"name":"Plant_Seaweed_Moss_Stack","x":-13,"y":16,"z":-10},{"name":"Plant_Seaweed_Moss_Stack","x":-13,"y":17,"z":-10},{"name":"Plant_Seaweed_Moss_Stack","x":-13,"y":18,"z":-10},{"name":"Plant_Seaweed_Moss_Stack","x":-13,"y":19,"z":-10},{"name":"Plant_Seaweed_Moss_Stack","x":-13,"y":20,"z":-10},{"name":"Plant_Seaweed_Moss_Stack","x":-13,"y":21,"z":-10},{"name":"Plant_Seaweed_Moss_Stack","x":-13,"y":22,"z":-10},{"name":"Plant_Seaweed_Moss_Stack","x":-13,"y":23,"z":-10},{"name":"Plant_Seaweed_Moss_Stack","x":-13,"y":24,"z":-10},{"name":"Plant_Seaweed_Moss_Stack","x":-13,"y":25,"z":-10},{"name":"Plant_Seaweed_Moss_Stack","x":-13,"y":26,"z":-10},{"name":"Plant_Coral_Block_White","x":-13,"y":12,"z":-8},{"name":"Plant_Coral_Block_White","x":-13,"y":13,"z":-8},{"name":"Plant_Seaweed_Moss_Stack","x":-13,"y":14,"z":-8},{"name":"Plant_Coral_Block_White","x":-13,"y":12,"z":-7},{"name":"Plant_Seaweed_Grass_Tall","x":-13,"y":13,"z":-7},{"filler":1024,"name":"Plant_Seaweed_Grass_Tall","x":-13,"y":14,"z":-7},{"name":"Plant_Coral_Block_White","x":-13,"y":10,"z":-5},{"name":"Plant_Coral_Block_White","x":-13,"y":11,"z":-5},{"name":"Plant_Coral_Block_White","x":-13,"y":12,"z":-5},{"name":"Plant_Coral_Block_White","x":-13,"y":13,"z":-5},{"name":"Plant_Seaweed_Moss_Stack","x":-13,"y":14,"z":-5},{"name":"Plant_Seaweed_Moss_Stack","x":-13,"y":15,"z":-5},{"name":"Plant_Seaweed_Moss_Stack","x":-13,"y":16,"z":-5},{"name":"Plant_Seaweed_Moss_Stack","x":-13,"y":17,"z":-5},{"name":"Plant_Seaweed_Moss_Stack","x":-13,"y":18,"z":-5},{"name":"Plant_Seaweed_Moss_Stack","x":-13,"y":19,"z":-5},{"name":"Plant_Seaweed_Moss_Stack","x":-13,"y":20,"z":-5},{"name":"Plant_Seaweed_Moss_Stack","x":-13,"y":21,"z":-5},{"name":"Plant_Seaweed_Moss_Stack","x":-13,"y":22,"z":-5},{"name":"Plant_Seaweed_Moss_Stack","x":-13,"y":23,"z":-5},{"name":"Plant_Seaweed_Moss_Stack","x":-13,"y":24,"z":-5},{"name":"Plant_Seaweed_Moss_Stack","x":-13,"y":25,"z":-5},{"name":"Plant_Seaweed_Moss_Stack","x":-13,"y":26,"z":-5},{"name":"Plant_Seaweed_Moss_Stack","x":-13,"y":27,"z":-5},{"name":"Plant_Seaweed_Moss_Stack","x":-13,"y":28,"z":-5},{"name":"Plant_Seaweed_Moss_Stack","x":-13,"y":29,"z":-5},{"name":"Plant_Seaweed_Moss_Stack","x":-13,"y":30,"z":-5},{"name":"Plant_Seaweed_Moss_Stack","x":-13,"y":31,"z":-5},{"name":"Plant_Seaweed_Moss_Stack","x":-13,"y":32,"z":-5},{"name":"Plant_Seaweed_Moss_Stack","x":-13,"y":33,"z":-5},{"name":"Plant_Coral_Block_White","x":-13,"y":11,"z":-4},{"name":"Plant_Seaweed_Grass","x":-13,"y":12,"z":-4},{"name":"Plant_Coral_Block_White","x":-13,"y":11,"z":-2},{"name":"Plant_Coral_Block_White","x":-13,"y":12,"z":-2},{"name":"Plant_Seaweed_Moss_Stack","x":-13,"y":13,"z":-2},{"name":"Plant_Seaweed_Moss_Stack","x":-13,"y":14,"z":-2},{"name":"Plant_Seaweed_Moss_Stack","x":-13,"y":15,"z":-2},{"name":"Plant_Seaweed_Moss_Stack","x":-13,"y":16,"z":-2},{"name":"Plant_Seaweed_Moss_Stack","x":-13,"y":17,"z":-2},{"name":"Plant_Seaweed_Moss_Stack","x":-13,"y":18,"z":-2},{"name":"Plant_Seaweed_Moss_Stack","x":-13,"y":19,"z":-2},{"name":"Plant_Seaweed_Moss_Stack","x":-13,"y":20,"z":-2},{"name":"Plant_Seaweed_Moss_Stack","x":-13,"y":21,"z":-2},{"name":"Plant_Seaweed_Moss_Stack","x":-13,"y":22,"z":-2},{"name":"Plant_Seaweed_Moss_Stack","x":-13,"y":23,"z":-2},{"name":"Plant_Seaweed_Moss_Stack","x":-13,"y":24,"z":-2},{"name":"Plant_Seaweed_Moss_Stack","x":-13,"y":25,"z":-2},{"name":"Plant_Seaweed_Moss_Stack","x":-13,"y":26,"z":-2},{"name":"Plant_Coral_Block_White","x":-13,"y":10,"z":-1},{"name":"Plant_Seaweed_Moss_Stack","x":-13,"y":11,"z":-1},{"name":"Plant_Seaweed_Moss_Stack","x":-13,"y":12,"z":-1},{"name":"Plant_Seaweed_Moss_Stack","x":-13,"y":13,"z":-1},{"name":"Plant_Seaweed_Moss_Stack","x":-13,"y":14,"z":-1},{"name":"Plant_Coral_Block_White","x":-13,"y":12,"z":0},{"name":"Plant_Coral_Block_White","x":-13,"y":13,"z":0},{"name":"Plant_Seaweed_Grass","x":-13,"y":14,"z":0},{"name":"Plant_Coral_Block_White","x":-12,"y":10,"z":-10},{"name":"Plant_Coral_Block_White","x":-12,"y":11,"z":-10},{"name":"Plant_Coral_Block_White","x":-12,"y":12,"z":-10},{"name":"Plant_Coral_Block_White","x":-12,"y":13,"z":-10},{"name":"Plant_Seaweed_Moss_Stack","x":-12,"y":14,"z":-10},{"name":"Plant_Seaweed_Moss_Stack","x":-12,"y":15,"z":-10},{"name":"Plant_Seaweed_Moss_Stack","x":-12,"y":16,"z":-10},{"name":"Plant_Seaweed_Moss_Stack","x":-12,"y":17,"z":-10},{"name":"Plant_Seaweed_Moss_Stack","x":-12,"y":18,"z":-10},{"name":"Plant_Seaweed_Moss_Stack","x":-12,"y":19,"z":-10},{"name":"Plant_Coral_Block_White","x":-12,"y":11,"z":-9},{"name":"Plant_Seaweed_Grass","x":-12,"y":12,"z":-9},{"name":"Plant_Coral_Block_White","x":-12,"y":11,"z":-7},{"name":"Plant_Coral_Block_White","x":-12,"y":12,"z":-7},{"name":"Plant_Seaweed_Grass","x":-12,"y":13,"z":-7},{"name":"Plant_Coral_Block_White","x":-12,"y":10,"z":-6},{"name":"Plant_Seaweed_Moss_Stack","x":-12,"y":11,"z":-6},{"name":"Plant_Seaweed_Moss_Stack","x":-12,"y":12,"z":-6},{"name":"Plant_Seaweed_Moss_Stack","x":-12,"y":13,"z":-6},{"name":"Plant_Coral_Block_White","x":-12,"y":12,"z":-5},{"name":"Plant_Coral_Block_White","x":-12,"y":13,"z":-5},{"name":"Plant_Seaweed_Grass","x":-12,"y":14,"z":-5},{"name":"Plant_Coral_Block_White","x":-12,"y":11,"z":-4},{"name":"Plant_Seaweed_Moss_Stack","x":-12,"y":12,"z":-4},{"name":"Plant_Seaweed_Moss_Stack","x":-12,"y":13,"z":-4},{"name":"Plant_Seaweed_Moss_Stack","x":-12,"y":14,"z":-4},{"name":"Plant_Seaweed_Moss_Stack","x":-12,"y":15,"z":-4},{"name":"Plant_Seaweed_Moss_Stack","x":-12,"y":16,"z":-4},{"name":"Plant_Seaweed_Moss_Stack","x":-12,"y":17,"z":-4},{"name":"Plant_Seaweed_Moss_Stack","x":-12,"y":18,"z":-4},{"name":"Plant_Seaweed_Moss_Stack","x":-12,"y":19,"z":-4},{"name":"Plant_Coral_Block_White","x":-12,"y":10,"z":-3},{"name":"Plant_Seaweed_Moss_Stack","x":-12,"y":11,"z":-3},{"name":"Plant_Seaweed_Moss_Stack","x":-12,"y":12,"z":-3},{"name":"Plant_Seaweed_Moss_Stack","x":-12,"y":13,"z":-3},{"name":"Plant_Seaweed_Moss_Stack","x":-12,"y":14,"z":-3},{"name":"Plant_Seaweed_Moss_Stack","x":-12,"y":15,"z":-3},{"name":"Plant_Seaweed_Moss_Stack","x":-12,"y":16,"z":-3},{"name":"Plant_Seaweed_Moss_Stack","x":-12,"y":17,"z":-3},{"name":"Plant_Seaweed_Moss_Stack","x":-12,"y":18,"z":-3},{"name":"Plant_Seaweed_Moss_Stack","x":-12,"y":19,"z":-3},{"name":"Plant_Seaweed_Moss_Stack","x":-12,"y":20,"z":-3},{"name":"Plant_Seaweed_Moss_Stack","x":-12,"y":21,"z":-3},{"name":"Plant_Seaweed_Moss_Stack","x":-12,"y":22,"z":-3},{"name":"Plant_Seaweed_Moss_Stack","x":-12,"y":23,"z":-3},{"name":"Plant_Seaweed_Moss_Stack","x":-12,"y":24,"z":-3},{"name":"Plant_Coral_Block_White","x":-12,"y":11,"z":-2},{"name":"Plant_Seaweed_Grass_Tall","x":-12,"y":12,"z":-2},{"filler":1024,"name":"Plant_Seaweed_Grass_Tall","x":-12,"y":13,"z":-2},{"name":"Plant_Coral_Block_White","x":-12,"y":11,"z":-1},{"name":"Plant_Coral_Block_White","x":-12,"y":12,"z":-1},{"name":"Plant_Seaweed_Grass","x":-12,"y":13,"z":-1},{"name":"Plant_Coral_Block_White","x":-12,"y":12,"z":0},{"name":"Plant_Seaweed_Moss_Stack","x":-12,"y":13,"z":0},{"name":"Plant_Seaweed_Moss_Stack","x":-12,"y":14,"z":0},{"name":"Plant_Seaweed_Moss_Stack","x":-12,"y":15,"z":0},{"name":"Plant_Seaweed_Moss_Stack","x":-12,"y":16,"z":0},{"name":"Plant_Seaweed_Moss_Stack","x":-12,"y":17,"z":0},{"name":"Plant_Seaweed_Moss_Stack","x":-12,"y":18,"z":0},{"name":"Plant_Seaweed_Moss_Stack","x":-12,"y":19,"z":0},{"name":"Plant_Seaweed_Moss_Stack","x":-12,"y":20,"z":0},{"name":"Plant_Seaweed_Moss_Stack","x":-12,"y":21,"z":0},{"name":"Plant_Seaweed_Moss_Stack","x":-12,"y":22,"z":0},{"name":"Plant_Seaweed_Moss_Stack","x":-12,"y":23,"z":0},{"name":"Plant_Coral_Block_White","x":-11,"y":12,"z":-11},{"name":"Plant_Coral_Block_White","x":-11,"y":13,"z":-11},{"name":"Plant_Seaweed_Grass_Tall","x":-11,"y":14,"z":-11},{"filler":1024,"name":"Plant_Seaweed_Grass_Tall","x":-11,"y":15,"z":-11},{"name":"Plant_Coral_Block_White","x":-11,"y":11,"z":-9},{"name":"Plant_Seaweed_Moss_Stack","x":-11,"y":12,"z":-9},{"name":"Plant_Seaweed_Moss_Stack","x":-11,"y":13,"z":-9},{"name":"Plant_Seaweed_Moss_Stack","x":-11,"y":14,"z":-9},{"name":"Plant_Seaweed_Moss_Stack","x":-11,"y":15,"z":-9},{"name":"Plant_Seaweed_Moss_Stack","x":-11,"y":16,"z":-9},{"name":"Plant_Seaweed_Moss_Stack","x":-11,"y":17,"z":-9},{"name":"Plant_Seaweed_Moss_Stack","x":-11,"y":18,"z":-9},{"name":"Plant_Seaweed_Moss_Stack","x":-11,"y":19,"z":-9},{"name":"Plant_Seaweed_Moss_Stack","x":-11,"y":20,"z":-9},{"name":"Plant_Seaweed_Moss_Stack","x":-11,"y":21,"z":-9},{"name":"Plant_Seaweed_Moss_Stack","x":-11,"y":22,"z":-9},{"name":"Plant_Seaweed_Moss_Stack","x":-11,"y":23,"z":-9},{"name":"Plant_Seaweed_Moss_Stack","x":-11,"y":24,"z":-9},{"name":"Plant_Seaweed_Moss_Stack","x":-11,"y":25,"z":-9},{"name":"Plant_Coral_Block_White","x":-11,"y":10,"z":-8},{"name":"Plant_Seaweed_Moss_Stack","x":-11,"y":11,"z":-8},{"name":"Plant_Seaweed_Moss_Stack","x":-11,"y":12,"z":-8},{"name":"Plant_Seaweed_Moss_Stack","x":-11,"y":13,"z":-8},{"name":"Plant_Seaweed_Moss_Stack","x":-11,"y":14,"z":-8},{"name":"Plant_Seaweed_Moss_Stack","x":-11,"y":15,"z":-8},{"name":"Plant_Seaweed_Moss_Stack","x":-11,"y":16,"z":-8},{"name":"Plant_Seaweed_Moss_Stack","x":-11,"y":17,"z":-8},{"name":"Plant_Seaweed_Moss_Stack","x":-11,"y":18,"z":-8},{"name":"Plant_Seaweed_Moss_Stack","x":-11,"y":19,"z":-8},{"name":"Plant_Seaweed_Moss_Stack","x":-11,"y":20,"z":-8},{"name":"Plant_Seaweed_Moss_Stack","x":-11,"y":21,"z":-8},{"name":"Plant_Seaweed_Moss_Stack","x":-11,"y":22,"z":-8},{"name":"Plant_Seaweed_Moss_Stack","x":-11,"y":23,"z":-8},{"name":"Plant_Seaweed_Moss_Stack","x":-11,"y":24,"z":-8},{"name":"Plant_Coral_Block_White","x":-11,"y":11,"z":-7},{"name":"Plant_Seaweed_Grass","x":-11,"y":12,"z":-7},{"name":"Plant_Coral_Block_White","x":-11,"y":10,"z":-6},{"name":"Plant_Coral_Block_White","x":-11,"y":11,"z":-6},{"name":"Plant_Coral_Block_White","x":-11,"y":12,"z":-6},{"name":"Plant_Seaweed_Grass_Tall","x":-11,"y":13,"z":-6},{"filler":1024,"name":"Plant_Seaweed_Grass_Tall","x":-11,"y":14,"z":-6},{"name":"Plant_Coral_Block_White","x":-11,"y":11,"z":-5},{"name":"Plant_Coral_Block_White","x":-11,"y":12,"z":-5},{"name":"Plant_Coral_Block_White","x":-11,"y":13,"z":-5},{"name":"Plant_Coral_Block_White","x":-11,"y":14,"z":-5},{"name":"Plant_Seaweed_Grass_Tall","x":-11,"y":15,"z":-5},{"filler":1024,"name":"Plant_Seaweed_Grass_Tall","x":-11,"y":16,"z":-5},{"name":"Plant_Coral_Block_White","x":-11,"y":10,"z":-4},{"name":"Plant_Coral_Block_White","x":-11,"y":11,"z":-4},{"name":"Plant_Seaweed_Moss_Stack","x":-11,"y":12,"z":-4},{"name":"Plant_Seaweed_Moss_Stack","x":-11,"y":13,"z":-4},{"name":"Plant_Seaweed_Moss_Stack","x":-11,"y":14,"z":-4},{"name":"Plant_Seaweed_Moss_Stack","x":-11,"y":15,"z":-4},{"name":"Plant_Seaweed_Moss_Stack","x":-11,"y":16,"z":-4},{"name":"Plant_Seaweed_Moss_Stack","x":-11,"y":17,"z":-4},{"name":"Plant_Seaweed_Moss_Stack","x":-11,"y":18,"z":-4},{"name":"Plant_Seaweed_Moss_Stack","x":-11,"y":19,"z":-4},{"name":"Plant_Seaweed_Moss_Stack","x":-11,"y":20,"z":-4},{"name":"Wood_Spiral_Trunk_Full","x":-11,"y":9,"z":-3},{"name":"Wood_Spiral_Trunk_Full","x":-11,"y":10,"z":-3},{"name":"Wood_Spiral_Trunk_Full","x":-11,"y":11,"z":-3},{"name":"Plant_Coral_Block_White","x":-11,"y":12,"z":-3},{"name":"Plant_Coral_Block_White","x":-11,"y":13,"z":-3},{"name":"Plant_Seaweed_Grass","x":-11,"y":14,"z":-3},{"name":"Plant_Coral_Block_White","x":-11,"y":11,"z":-2},{"name":"Plant_Seaweed_Moss_Stack","x":-11,"y":12,"z":-2},{"name":"Plant_Seaweed_Moss_Stack","x":-11,"y":13,"z":-2},{"name":"Plant_Seaweed_Moss_Stack","x":-11,"y":14,"z":-2},{"name":"Plant_Seaweed_Moss_Stack","x":-11,"y":15,"z":-2},{"name":"Plant_Seaweed_Moss_Stack","x":-11,"y":16,"z":-2},{"name":"Plant_Coral_Block_White","x":-11,"y":10,"z":-1},{"name":"Plant_Seaweed_Grass_Tall","x":-11,"y":11,"z":-1},{"filler":1024,"name":"Plant_Seaweed_Grass_Tall","x":-11,"y":12,"z":-1},{"name":"Plant_Coral_Block_White","x":-10,"y":10,"z":-11},{"name":"Plant_Seaweed_Moss_Stack","x":-10,"y":11,"z":-11},{"name":"Plant_Seaweed_Moss_Stack","x":-10,"y":12,"z":-11},{"name":"Plant_Seaweed_Moss_Stack","x":-10,"y":13,"z":-11},{"name":"Plant_Seaweed_Moss_Stack","x":-10,"y":14,"z":-11},{"name":"Plant_Seaweed_Moss_Stack","x":-10,"y":15,"z":-11},{"name":"Plant_Seaweed_Moss_Stack","x":-10,"y":16,"z":-11},{"name":"Plant_Seaweed_Moss_Stack","x":-10,"y":17,"z":-11},{"name":"Plant_Seaweed_Moss_Stack","x":-10,"y":18,"z":-11},{"name":"Plant_Seaweed_Moss_Stack","x":-10,"y":19,"z":-11},{"name":"Plant_Seaweed_Moss_Stack","x":-10,"y":20,"z":-11},{"name":"Plant_Seaweed_Moss_Stack","x":-10,"y":21,"z":-11},{"name":"Plant_Seaweed_Moss_Stack","x":-10,"y":22,"z":-11},{"name":"Plant_Seaweed_Moss_Stack","x":-10,"y":23,"z":-11},{"name":"Plant_Seaweed_Moss_Stack","x":-10,"y":24,"z":-11},{"name":"Plant_Coral_Block_White","x":-10,"y":11,"z":-10},{"name":"Plant_Coral_Block_White","x":-10,"y":12,"z":-10},{"name":"Plant_Coral_Block_White","x":-10,"y":13,"z":-10},{"name":"Plant_Coral_Block_White","x":-10,"y":14,"z":-10},{"name":"Plant_Seaweed_Moss_Stack","x":-10,"y":15,"z":-10},{"name":"Plant_Seaweed_Moss_Stack","x":-10,"y":16,"z":-10},{"name":"Plant_Seaweed_Moss_Stack","x":-10,"y":17,"z":-10},{"name":"Plant_Seaweed_Moss_Stack","x":-10,"y":18,"z":-10},{"name":"Plant_Seaweed_Moss_Stack","x":-10,"y":19,"z":-10},{"name":"Plant_Seaweed_Moss_Stack","x":-10,"y":20,"z":-10},{"name":"Plant_Seaweed_Moss_Stack","x":-10,"y":21,"z":-10},{"name":"Plant_Seaweed_Moss_Stack","x":-10,"y":22,"z":-10},{"name":"Plant_Seaweed_Moss_Stack","x":-10,"y":23,"z":-10},{"name":"Plant_Seaweed_Moss_Stack","x":-10,"y":24,"z":-10},{"name":"Plant_Seaweed_Moss_Stack","x":-10,"y":25,"z":-10},{"name":"Plant_Seaweed_Moss_Stack","x":-10,"y":26,"z":-10},{"name":"Plant_Seaweed_Moss_Stack","x":-10,"y":27,"z":-10},{"name":"Plant_Seaweed_Moss_Stack","x":-10,"y":28,"z":-10},{"name":"Plant_Seaweed_Moss_Stack","x":-10,"y":29,"z":-10},{"name":"Plant_Seaweed_Moss_Stack","x":-10,"y":30,"z":-10},{"name":"Plant_Seaweed_Moss_Stack","x":-10,"y":31,"z":-10},{"name":"Plant_Seaweed_Moss_Stack","x":-10,"y":32,"z":-10},{"name":"Plant_Seaweed_Moss_Stack","x":-10,"y":33,"z":-10},{"name":"Plant_Seaweed_Moss_Stack","x":-10,"y":34,"z":-10},{"name":"Plant_Seaweed_Moss_Stack","x":-10,"y":35,"z":-10},{"name":"Plant_Seaweed_Moss_Stack","x":-10,"y":36,"z":-10},{"name":"Plant_Coral_Block_White","x":-10,"y":10,"z":-9},{"name":"Plant_Coral_Block_White","x":-10,"y":11,"z":-9},{"name":"Plant_Seaweed_Moss_Stack","x":-10,"y":12,"z":-9},{"name":"Plant_Seaweed_Moss_Stack","x":-10,"y":13,"z":-9},{"name":"Plant_Seaweed_Moss_Stack","x":-10,"y":14,"z":-9},{"name":"Plant_Seaweed_Moss_Stack","x":-10,"y":15,"z":-9},{"name":"Plant_Seaweed_Moss_Stack","x":-10,"y":16,"z":-9},{"name":"Plant_Seaweed_Moss_Stack","x":-10,"y":17,"z":-9},{"name":"Plant_Seaweed_Moss_Stack","x":-10,"y":18,"z":-9},{"name":"Plant_Seaweed_Moss_Stack","x":-10,"y":19,"z":-9},{"name":"Plant_Seaweed_Moss_Stack","x":-10,"y":20,"z":-9},{"name":"Plant_Seaweed_Moss_Stack","x":-10,"y":21,"z":-9},{"name":"Wood_Spiral_Trunk_Full","x":-10,"y":9,"z":-8},{"name":"Wood_Spiral_Trunk_Full","x":-10,"y":10,"z":-8},{"name":"Wood_Spiral_Trunk_Full","x":-10,"y":11,"z":-8},{"name":"Plant_Coral_Block_White","x":-10,"y":12,"z":-8},{"name":"Plant_Coral_Block_White","x":-10,"y":13,"z":-8},{"name":"Plant_Seaweed_Moss_Stack","x":-10,"y":14,"z":-8},{"name":"Plant_Seaweed_Moss_Stack","x":-10,"y":15,"z":-8},{"name":"Plant_Seaweed_Moss_Stack","x":-10,"y":16,"z":-8},{"name":"Plant_Seaweed_Moss_Stack","x":-10,"y":17,"z":-8},{"name":"Plant_Seaweed_Moss_Stack","x":-10,"y":18,"z":-8},{"name":"Plant_Seaweed_Moss_Stack","x":-10,"y":19,"z":-8},{"name":"Plant_Seaweed_Moss_Stack","x":-10,"y":20,"z":-8},{"name":"Plant_Seaweed_Moss_Stack","x":-10,"y":21,"z":-8},{"name":"Plant_Coral_Block_White","x":-10,"y":11,"z":-7},{"name":"Plant_Seaweed_Moss_Stack","x":-10,"y":12,"z":-7},{"name":"Plant_Seaweed_Moss_Stack","x":-10,"y":13,"z":-7},{"name":"Plant_Seaweed_Moss_Stack","x":-10,"y":14,"z":-7},{"name":"Plant_Coral_Block_White","x":-10,"y":10,"z":-6},{"name":"Plant_Seaweed_Moss_Stack","x":-10,"y":11,"z":-6},{"name":"Plant_Seaweed_Moss_Stack","x":-10,"y":12,"z":-6},{"name":"Plant_Seaweed_Moss_Stack","x":-10,"y":13,"z":-6},{"name":"Plant_Seaweed_Moss_Stack","x":-10,"y":14,"z":-6},{"name":"Plant_Seaweed_Moss_Stack","x":-10,"y":15,"z":-6},{"name":"Plant_Seaweed_Moss_Stack","x":-10,"y":16,"z":-6},{"name":"Plant_Seaweed_Moss_Stack","x":-10,"y":17,"z":-6},{"name":"Plant_Seaweed_Moss_Stack","x":-10,"y":18,"z":-6},{"name":"Plant_Seaweed_Moss_Stack","x":-10,"y":19,"z":-6},{"name":"Plant_Seaweed_Moss_Stack","x":-10,"y":20,"z":-6},{"name":"Plant_Seaweed_Moss_Stack","x":-10,"y":21,"z":-6},{"name":"Plant_Seaweed_Moss_Stack","x":-10,"y":22,"z":-6},{"name":"Plant_Seaweed_Moss_Stack","x":-10,"y":23,"z":-6},{"name":"Plant_Seaweed_Moss_Stack","x":-10,"y":24,"z":-6},{"name":"Plant_Coral_Block_White","x":-10,"y":11,"z":-5},{"name":"Plant_Seaweed_Grass_Tall","x":-10,"y":12,"z":-5},{"filler":1024,"name":"Plant_Seaweed_Grass_Tall","x":-10,"y":13,"z":-5},{"name":"Wood_Spiral_Trunk_Full","x":-10,"y":7,"z":-4},{"name":"Wood_Spiral_Trunk_Full","x":-10,"y":8,"z":-4},{"name":"Wood_Spiral_Trunk_Full","x":-10,"y":9,"z":-4},{"name":"Plant_Coral_Block_White","x":-10,"y":11,"z":-4},{"name":"Plant_Coral_Block_White","x":-10,"y":12,"z":-4},{"name":"Plant_Seaweed_Grass","x":-10,"y":13,"z":-4},{"name":"Wood_Spiral_Trunk_Full","x":-10,"y":9,"z":-3},{"name":"Plant_Coral_Block_White","x":-10,"y":11,"z":-3},{"name":"Plant_Seaweed_Moss_Stack","x":-10,"y":12,"z":-3},{"name":"Plant_Seaweed_Moss_Stack","x":-10,"y":13,"z":-3},{"name":"Plant_Seaweed_Moss_Stack","x":-10,"y":14,"z":-3},{"name":"Plant_Seaweed_Moss_Stack","x":-10,"y":15,"z":-3},{"name":"Plant_Seaweed_Moss_Stack","x":-10,"y":16,"z":-3},{"name":"Plant_Coral_Block_White","x":-10,"y":11,"z":-2},{"name":"Plant_Coral_Block_White","x":-10,"y":12,"z":-2},{"name":"Plant_Seaweed_Moss_Stack","x":-10,"y":13,"z":-2},{"name":"Plant_Seaweed_Moss_Stack","x":-10,"y":14,"z":-2},{"name":"Plant_Seaweed_Moss_Stack","x":-10,"y":15,"z":-2},{"name":"Plant_Seaweed_Moss_Stack","x":-10,"y":16,"z":-2},{"name":"Plant_Seaweed_Moss_Stack","x":-10,"y":17,"z":-2},{"name":"Plant_Seaweed_Moss_Stack","x":-10,"y":18,"z":-2},{"name":"Plant_Seaweed_Moss_Stack","x":-10,"y":19,"z":-2},{"name":"Plant_Seaweed_Moss_Stack","x":-10,"y":20,"z":-2},{"name":"Plant_Seaweed_Moss_Stack","x":-10,"y":21,"z":-2},{"name":"Plant_Seaweed_Moss_Stack","x":-10,"y":22,"z":-2},{"name":"Plant_Seaweed_Moss_Stack","x":-10,"y":23,"z":-2},{"name":"Plant_Seaweed_Moss_Stack","x":-10,"y":24,"z":-2},{"name":"Plant_Seaweed_Moss_Stack","x":-10,"y":25,"z":-2},{"name":"Plant_Seaweed_Moss_Stack","x":-10,"y":26,"z":-2},{"name":"Plant_Coral_Block_White","x":-10,"y":12,"z":-1},{"name":"Plant_Coral_Block_White","x":-10,"y":13,"z":-1},{"name":"Plant_Seaweed_Moss_Stack","x":-10,"y":14,"z":-1},{"name":"Plant_Seaweed_Moss_Stack","x":-10,"y":15,"z":-1},{"name":"Plant_Seaweed_Moss_Stack","x":-10,"y":16,"z":-1},{"name":"Plant_Seaweed_Moss_Stack","x":-10,"y":17,"z":-1},{"name":"Plant_Seaweed_Moss_Stack","x":-10,"y":18,"z":-1},{"name":"Plant_Seaweed_Moss_Stack","x":-10,"y":19,"z":-1},{"name":"Plant_Seaweed_Moss_Stack","x":-10,"y":20,"z":-1},{"name":"Plant_Seaweed_Moss_Stack","x":-10,"y":21,"z":-1},{"name":"Plant_Seaweed_Moss_Stack","x":-10,"y":22,"z":-1},{"name":"Plant_Seaweed_Moss_Stack","x":-10,"y":23,"z":-1},{"name":"Plant_Seaweed_Moss_Stack","x":-10,"y":24,"z":-1},{"name":"Plant_Seaweed_Moss_Stack","x":-10,"y":25,"z":-1},{"name":"Plant_Coral_Block_White","x":-9,"y":11,"z":-10},{"name":"Plant_Seaweed_Moss_Stack","x":-9,"y":12,"z":-10},{"name":"Plant_Seaweed_Moss_Stack","x":-9,"y":13,"z":-10},{"name":"Plant_Seaweed_Moss_Stack","x":-9,"y":14,"z":-10},{"name":"Plant_Seaweed_Moss_Stack","x":-9,"y":15,"z":-10},{"name":"Plant_Seaweed_Moss_Stack","x":-9,"y":16,"z":-10},{"name":"Plant_Coral_Block_White","x":-9,"y":11,"z":-9},{"name":"Plant_Coral_Block_White","x":-9,"y":12,"z":-9},{"name":"Plant_Seaweed_Grass","x":-9,"y":13,"z":-9},{"name":"Wood_Spiral_Trunk_Full","x":-9,"y":9,"z":-8},{"name":"Plant_Coral_Block_White","x":-9,"y":11,"z":-8},{"name":"Plant_Seaweed_Grass_Tall","x":-9,"y":12,"z":-8},{"filler":1024,"name":"Plant_Seaweed_Grass_Tall","x":-9,"y":13,"z":-8},{"name":"Wood_Spiral_Trunk_Full","x":-9,"y":8,"z":-7},{"name":"Wood_Spiral_Trunk_Full","x":-9,"y":9,"z":-7},{"name":"Plant_Coral_Block_White","x":-9,"y":11,"z":-7},{"name":"Plant_Coral_Block_White","x":-9,"y":12,"z":-7},{"name":"Plant_Seaweed_Moss_Stack","x":-9,"y":13,"z":-7},{"name":"Plant_Seaweed_Moss_Stack","x":-9,"y":14,"z":-7},{"name":"Plant_Seaweed_Moss_Stack","x":-9,"y":15,"z":-7},{"name":"Plant_Seaweed_Moss_Stack","x":-9,"y":16,"z":-7},{"name":"Plant_Seaweed_Moss_Stack","x":-9,"y":17,"z":-7},{"name":"Plant_Seaweed_Moss_Stack","x":-9,"y":18,"z":-7},{"name":"Plant_Seaweed_Moss_Stack","x":-9,"y":19,"z":-7},{"name":"Plant_Seaweed_Moss_Stack","x":-9,"y":20,"z":-7},{"name":"Plant_Seaweed_Moss_Stack","x":-9,"y":21,"z":-7},{"name":"Plant_Seaweed_Moss_Stack","x":-9,"y":22,"z":-7},{"name":"Plant_Seaweed_Moss_Stack","x":-9,"y":23,"z":-7},{"name":"Plant_Seaweed_Moss_Stack","x":-9,"y":24,"z":-7},{"name":"Plant_Seaweed_Moss_Stack","x":-9,"y":25,"z":-7},{"name":"Wood_Spiral_Trunk_Full","x":-9,"y":8,"z":-6},{"name":"Plant_Coral_Block_White","x":-9,"y":12,"z":-6},{"name":"Plant_Coral_Block_White","x":-9,"y":13,"z":-6},{"name":"Plant_Seaweed_Moss_Stack","x":-9,"y":14,"z":-6},{"name":"Plant_Seaweed_Moss_Stack","x":-9,"y":15,"z":-6},{"name":"Plant_Seaweed_Moss_Stack","x":-9,"y":16,"z":-6},{"name":"Plant_Seaweed_Moss_Stack","x":-9,"y":17,"z":-6},{"name":"Plant_Seaweed_Moss_Stack","x":-9,"y":18,"z":-6},{"name":"Plant_Seaweed_Moss_Stack","x":-9,"y":19,"z":-6},{"name":"Plant_Seaweed_Moss_Stack","x":-9,"y":20,"z":-6},{"name":"Plant_Seaweed_Moss_Stack","x":-9,"y":21,"z":-6},{"name":"Plant_Seaweed_Moss_Stack","x":-9,"y":22,"z":-6},{"name":"Plant_Seaweed_Moss_Stack","x":-9,"y":23,"z":-6},{"name":"Plant_Seaweed_Moss_Stack","x":-9,"y":24,"z":-6},{"name":"Plant_Seaweed_Moss_Stack","x":-9,"y":25,"z":-6},{"name":"Plant_Seaweed_Moss_Stack","x":-9,"y":26,"z":-6},{"name":"Plant_Seaweed_Moss_Stack","x":-9,"y":27,"z":-6},{"name":"Plant_Seaweed_Moss_Stack","x":-9,"y":28,"z":-6},{"name":"Plant_Seaweed_Moss_Stack","x":-9,"y":29,"z":-6},{"name":"Plant_Seaweed_Moss_Stack","x":-9,"y":30,"z":-6},{"name":"Plant_Seaweed_Moss_Stack","x":-9,"y":31,"z":-6},{"name":"Plant_Seaweed_Moss_Stack","x":-9,"y":32,"z":-6},{"name":"Plant_Seaweed_Moss_Stack","x":-9,"y":33,"z":-6},{"name":"Plant_Seaweed_Moss_Stack","x":-9,"y":34,"z":-6},{"name":"Plant_Coral_Block_White","x":-9,"y":12,"z":-5},{"name":"Plant_Coral_Block_White","x":-9,"y":13,"z":-5},{"name":"Plant_Seaweed_Grass_Tall","x":-9,"y":14,"z":-5},{"filler":1024,"name":"Plant_Seaweed_Grass_Tall","x":-9,"y":15,"z":-5},{"name":"Wood_Spiral_Trunk_Full","x":-9,"y":7,"z":-4},{"name":"Plant_Coral_Block_White","x":-9,"y":11,"z":-4},{"name":"Plant_Coral_Block_White","x":-9,"y":12,"z":-4},{"name":"Plant_Seaweed_Moss_Stack","x":-9,"y":13,"z":-4},{"name":"Plant_Seaweed_Moss_Stack","x":-9,"y":14,"z":-4},{"name":"Plant_Seaweed_Moss_Stack","x":-9,"y":15,"z":-4},{"name":"Plant_Seaweed_Moss_Stack","x":-9,"y":16,"z":-4},{"name":"Plant_Seaweed_Moss_Stack","x":-9,"y":17,"z":-4},{"name":"Plant_Seaweed_Moss_Stack","x":-9,"y":18,"z":-4},{"name":"Plant_Seaweed_Moss_Stack","x":-9,"y":19,"z":-4},{"name":"Plant_Coral_Block_White","x":-9,"y":13,"z":-3},{"name":"Plant_Seaweed_Moss_Stack","x":-9,"y":14,"z":-3},{"name":"Plant_Seaweed_Moss_Stack","x":-9,"y":15,"z":-3},{"name":"Plant_Seaweed_Moss_Stack","x":-9,"y":16,"z":-3},{"name":"Plant_Seaweed_Moss_Stack","x":-9,"y":17,"z":-3},{"name":"Plant_Seaweed_Moss_Stack","x":-9,"y":18,"z":-3},{"name":"Plant_Seaweed_Moss_Stack","x":-9,"y":19,"z":-3},{"name":"Plant_Seaweed_Moss_Stack","x":-9,"y":20,"z":-3},{"name":"Plant_Seaweed_Moss_Stack","x":-9,"y":21,"z":-3},{"name":"Plant_Seaweed_Moss_Stack","x":-9,"y":22,"z":-3},{"name":"Plant_Seaweed_Moss_Stack","x":-9,"y":23,"z":-3},{"name":"Plant_Seaweed_Moss_Stack","x":-9,"y":24,"z":-3},{"name":"Plant_Seaweed_Moss_Stack","x":-9,"y":25,"z":-3},{"name":"Plant_Seaweed_Moss_Stack","x":-9,"y":26,"z":-3},{"name":"Plant_Seaweed_Moss_Stack","x":-9,"y":27,"z":-3},{"name":"Plant_Coral_Block_White","x":-9,"y":12,"z":-1},{"name":"Plant_Seaweed_Moss_Stack","x":-9,"y":13,"z":-1},{"name":"Plant_Seaweed_Moss_Stack","x":-9,"y":14,"z":-1},{"name":"Plant_Seaweed_Moss_Stack","x":-9,"y":15,"z":-1},{"name":"Plant_Coral_Block_White","x":-9,"y":12,"z":0},{"name":"Plant_Seaweed_Moss_Stack","x":-9,"y":13,"z":0},{"name":"Plant_Seaweed_Moss_Stack","x":-9,"y":14,"z":0},{"name":"Plant_Seaweed_Moss_Stack","x":-9,"y":15,"z":0},{"name":"Plant_Seaweed_Moss_Stack","x":-9,"y":16,"z":0},{"name":"Plant_Seaweed_Moss_Stack","x":-9,"y":17,"z":0},{"name":"Plant_Coral_Block_White","x":-8,"y":13,"z":-11},{"name":"Plant_Seaweed_Moss_Stack","x":-8,"y":14,"z":-11},{"name":"Plant_Seaweed_Moss_Stack","x":-8,"y":15,"z":-11},{"name":"Plant_Seaweed_Moss_Stack","x":-8,"y":16,"z":-11},{"name":"Plant_Seaweed_Moss_Stack","x":-8,"y":17,"z":-11},{"name":"Plant_Seaweed_Moss_Stack","x":-8,"y":18,"z":-11},{"name":"Plant_Coral_Block_White","x":-8,"y":12,"z":-10},{"name":"Plant_Coral_Block_White","x":-8,"y":13,"z":-10},{"name":"Plant_Seaweed_Moss_Stack","x":-8,"y":14,"z":-10},{"name":"Plant_Seaweed_Moss_Stack","x":-8,"y":15,"z":-10},{"name":"Plant_Seaweed_Moss_Stack","x":-8,"y":16,"z":-10},{"name":"Plant_Seaweed_Moss_Stack","x":-8,"y":17,"z":-10},{"name":"Plant_Seaweed_Moss_Stack","x":-8,"y":18,"z":-10},{"name":"Plant_Seaweed_Moss_Stack","x":-8,"y":19,"z":-10},{"name":"Plant_Seaweed_Moss_Stack","x":-8,"y":20,"z":-10},{"name":"Plant_Coral_Block_White","x":-8,"y":11,"z":-9},{"name":"Plant_Coral_Block_White","x":-8,"y":12,"z":-9},{"name":"Plant_Seaweed_Moss_Stack","x":-8,"y":13,"z":-9},{"name":"Plant_Coral_Block_White","x":-8,"y":13,"z":-8},{"name":"Plant_Seaweed_Moss_Stack","x":-8,"y":14,"z":-8},{"name":"Wood_Spiral_Trunk_Full","x":-8,"y":7,"z":-6},{"name":"Wood_Spiral_Trunk_Full","x":-8,"y":8,"z":-6},{"name":"Plant_Coral_Block_White","x":-8,"y":12,"z":-6},{"name":"Plant_Seaweed_Moss_Stack","x":-8,"y":13,"z":-6},{"name":"Plant_Seaweed_Moss_Stack","x":-8,"y":14,"z":-6},{"name":"Plant_Seaweed_Moss_Stack","x":-8,"y":15,"z":-6},{"name":"Wood_Spiral_Trunk_Full","x":-8,"y":7,"z":-5},{"name":"Wood_Spiral_Trunk_Half","x":-8,"y":8,"z":-5},{"name":"Plant_Coral_Block_White","x":-8,"y":12,"z":-5},{"name":"Plant_Seaweed_Grass_Tall","x":-8,"y":13,"z":-5},{"filler":1024,"name":"Plant_Seaweed_Grass_Tall","x":-8,"y":14,"z":-5},{"name":"Wood_Spiral_Trunk_Full","x":-8,"y":6,"z":-4},{"name":"Wood_Spiral_Trunk_Full","x":-8,"y":7,"z":-4},{"name":"Plant_Coral_Block_White","x":-8,"y":11,"z":-4},{"name":"Plant_Seaweed_Grass_Tall","x":-8,"y":12,"z":-4},{"filler":1024,"name":"Plant_Seaweed_Grass_Tall","x":-8,"y":13,"z":-4},{"name":"Plant_Coral_Block_White","x":-8,"y":13,"z":-3},{"name":"Plant_Seaweed_Moss_Stack","x":-8,"y":14,"z":-3},{"name":"Plant_Seaweed_Moss_Stack","x":-8,"y":15,"z":-3},{"name":"Plant_Seaweed_Moss_Stack","x":-8,"y":16,"z":-3},{"name":"Plant_Seaweed_Moss_Stack","x":-8,"y":17,"z":-3},{"name":"Plant_Seaweed_Moss_Stack","x":-8,"y":18,"z":-3},{"name":"Plant_Seaweed_Moss_Stack","x":-8,"y":19,"z":-3},{"name":"Plant_Seaweed_Moss_Stack","x":-8,"y":20,"z":-3},{"name":"Plant_Seaweed_Moss_Stack","x":-8,"y":21,"z":-3},{"name":"Plant_Coral_Block_White","x":-7,"y":11,"z":-11},{"name":"Plant_Seaweed_Moss_Stack","x":-7,"y":12,"z":-11},{"name":"Plant_Seaweed_Moss_Stack","x":-7,"y":13,"z":-11},{"name":"Plant_Seaweed_Moss_Stack","x":-7,"y":14,"z":-11},{"name":"Plant_Seaweed_Moss_Stack","x":-7,"y":15,"z":-11},{"name":"Plant_Seaweed_Moss_Stack","x":-7,"y":16,"z":-11},{"name":"Plant_Seaweed_Moss_Stack","x":-7,"y":17,"z":-11},{"name":"Plant_Seaweed_Moss_Stack","x":-7,"y":18,"z":-11},{"name":"Plant_Seaweed_Moss_Stack","x":-7,"y":19,"z":-11},{"name":"Plant_Seaweed_Moss_Stack","x":-7,"y":20,"z":-11},{"name":"Plant_Seaweed_Moss_Stack","x":-7,"y":21,"z":-11},{"name":"Plant_Seaweed_Moss_Stack","x":-7,"y":22,"z":-11},{"name":"Plant_Coral_Block_White","x":-7,"y":11,"z":-9},{"name":"Plant_Coral_Block_White","x":-7,"y":12,"z":-9},{"name":"Plant_Seaweed_Grass","x":-7,"y":13,"z":-9},{"name":"Plant_Coral_Block_White","x":-7,"y":11,"z":-8},{"name":"Plant_Seaweed_Grass_Tall","x":-7,"y":12,"z":-8},{"filler":1024,"name":"Plant_Seaweed_Grass_Tall","x":-7,"y":13,"z":-8},{"name":"Wood_Spiral_Trunk_Full","x":-7,"y":8,"z":-6},{"name":"Wood_Spiral_Trunk_Full","x":-7,"y":9,"z":-6},{"name":"Wood_Spiral_Trunk_Full","x":-7,"y":6,"z":-4},{"name":"Wood_Spiral_Trunk_Half","x":-7,"y":7,"z":-4},{"name":"Wood_Spiral_Trunk_Full","x":-7,"y":5,"z":-3},{"name":"Wood_Spiral_Trunk_Full","x":-7,"y":6,"z":-3},{"name":"Plant_Coral_Block_White","x":-6,"y":9,"z":-11},{"name":"Plant_Coral_Block_White","x":-6,"y":10,"z":-11},{"name":"Plant_Coral_Block_White","x":-6,"y":11,"z":-11},{"name":"Plant_Coral_Block_White","x":-6,"y":12,"z":-11},{"name":"Plant_Seaweed_Moss_Stack","x":-6,"y":13,"z":-11},{"name":"Plant_Seaweed_Moss_Stack","x":-6,"y":14,"z":-11},{"name":"Plant_Seaweed_Moss_Stack","x":-6,"y":15,"z":-11},{"name":"Plant_Seaweed_Moss_Stack","x":-6,"y":16,"z":-11},{"name":"Plant_Seaweed_Moss_Stack","x":-6,"y":17,"z":-11},{"name":"Plant_Seaweed_Moss_Stack","x":-6,"y":18,"z":-11},{"name":"Plant_Seaweed_Moss_Stack","x":-6,"y":19,"z":-11},{"name":"Plant_Seaweed_Moss_Stack","x":-6,"y":20,"z":-11},{"name":"Plant_Coral_Block_White","x":-6,"y":10,"z":-10},{"name":"Plant_Seaweed_Moss_Stack","x":-6,"y":11,"z":-10},{"name":"Plant_Seaweed_Moss_Stack","x":-6,"y":12,"z":-10},{"name":"Plant_Seaweed_Moss_Stack","x":-6,"y":13,"z":-10},{"name":"Plant_Seaweed_Moss_Stack","x":-6,"y":14,"z":-10},{"name":"Plant_Seaweed_Moss_Stack","x":-6,"y":15,"z":-10},{"name":"Plant_Seaweed_Moss_Stack","x":-6,"y":16,"z":-10},{"name":"Plant_Seaweed_Moss_Stack","x":-6,"y":17,"z":-10},{"name":"Plant_Seaweed_Moss_Stack","x":-6,"y":18,"z":-10},{"name":"Plant_Seaweed_Moss_Stack","x":-6,"y":19,"z":-10},{"name":"Plant_Seaweed_Moss_Stack","x":-6,"y":20,"z":-10},{"name":"Plant_Seaweed_Moss_Stack","x":-6,"y":21,"z":-10},{"name":"Plant_Seaweed_Moss_Stack","x":-6,"y":22,"z":-10},{"name":"Plant_Seaweed_Moss_Stack","x":-6,"y":23,"z":-10},{"name":"Plant_Coral_Block_White","x":-6,"y":10,"z":-8},{"name":"Plant_Coral_Block_White","x":-6,"y":11,"z":-8},{"name":"Plant_Seaweed_Moss_Stack","x":-6,"y":12,"z":-8},{"name":"Plant_Seaweed_Moss_Stack","x":-6,"y":13,"z":-8},{"name":"Plant_Seaweed_Moss_Stack","x":-6,"y":14,"z":-8},{"name":"Plant_Seaweed_Moss_Stack","x":-6,"y":15,"z":-8},{"name":"Plant_Seaweed_Moss_Stack","x":-6,"y":16,"z":-8},{"name":"Plant_Seaweed_Moss_Stack","x":-6,"y":17,"z":-8},{"name":"Plant_Seaweed_Moss_Stack","x":-6,"y":18,"z":-8},{"name":"Plant_Seaweed_Moss_Stack","x":-6,"y":19,"z":-8},{"name":"Plant_Seaweed_Moss_Stack","x":-6,"y":20,"z":-8},{"name":"Plant_Seaweed_Moss_Stack","x":-6,"y":21,"z":-8},{"name":"Plant_Seaweed_Moss_Stack","x":-6,"y":22,"z":-8},{"name":"Wood_Spiral_Trunk_Full","x":-6,"y":9,"z":-7},{"name":"Wood_Spiral_Trunk_Full","x":-6,"y":9,"z":-6},{"name":"Plant_Coral_Block_White","x":-6,"y":11,"z":-6},{"name":"Plant_Coral_Block_White","x":-6,"y":12,"z":-6},{"name":"Plant_Seaweed_Grass_Tall","x":-6,"y":13,"z":-6},{"filler":1024,"name":"Plant_Seaweed_Grass_Tall","x":-6,"y":14,"z":-6},{"name":"Wood_Spiral_Trunk_Full","x":-6,"y":9,"z":-5},{"name":"Wood_Spiral_Trunk_Full","x":-6,"y":10,"z":-5},{"name":"Wood_Spiral_Trunk_Full","x":-6,"y":11,"z":-5},{"name":"Wood_Spiral_Trunk_Full","x":-6,"y":5,"z":-3},{"name":"Wood_Spiral_Trunk_Full","x":-6,"y":6,"z":-3},{"name":"Plant_Coral_Block_White","x":-5,"y":11,"z":-12},{"name":"Plant_Coral_Block_White","x":-5,"y":12,"z":-12},{"name":"Plant_Seaweed_Moss_Stack","x":-5,"y":13,"z":-12},{"name":"Plant_Seaweed_Moss_Stack","x":-5,"y":14,"z":-12},{"name":"Plant_Seaweed_Moss_Stack","x":-5,"y":15,"z":-12},{"name":"Plant_Seaweed_Moss_Stack","x":-5,"y":16,"z":-12},{"name":"Plant_Seaweed_Moss_Stack","x":-5,"y":17,"z":-12},{"name":"Plant_Seaweed_Moss_Stack","x":-5,"y":18,"z":-12},{"name":"Plant_Seaweed_Moss_Stack","x":-5,"y":19,"z":-12},{"name":"Plant_Seaweed_Moss_Stack","x":-5,"y":20,"z":-12},{"name":"Plant_Seaweed_Moss_Stack","x":-5,"y":21,"z":-12},{"name":"Plant_Seaweed_Moss_Stack","x":-5,"y":22,"z":-12},{"name":"Plant_Seaweed_Moss_Stack","x":-5,"y":23,"z":-12},{"name":"Plant_Seaweed_Moss_Stack","x":-5,"y":24,"z":-12},{"name":"Plant_Seaweed_Moss_Stack","x":-5,"y":25,"z":-12},{"name":"Plant_Seaweed_Moss_Stack","x":-5,"y":26,"z":-12},{"name":"Plant_Coral_Block_White","x":-5,"y":10,"z":-10},{"name":"Plant_Seaweed_Moss_Stack","x":-5,"y":11,"z":-10},{"name":"Plant_Seaweed_Moss_Stack","x":-5,"y":12,"z":-10},{"name":"Plant_Seaweed_Moss_Stack","x":-5,"y":13,"z":-10},{"name":"Plant_Seaweed_Moss_Stack","x":-5,"y":14,"z":-10},{"name":"Plant_Seaweed_Moss_Stack","x":-5,"y":15,"z":-10},{"name":"Plant_Seaweed_Moss_Stack","x":-5,"y":16,"z":-10},{"name":"Plant_Seaweed_Moss_Stack","x":-5,"y":17,"z":-10},{"name":"Plant_Coral_Block_White","x":-5,"y":9,"z":-9},{"name":"Wood_Spiral_Trunk_Full","x":-5,"y":10,"z":-9},{"name":"Plant_Coral_Block_White","x":-5,"y":12,"z":-9},{"name":"Plant_Coral_Block_White","x":-5,"y":13,"z":-9},{"name":"Plant_Seaweed_Moss_Stack","x":-5,"y":14,"z":-9},{"name":"Plant_Seaweed_Moss_Stack","x":-5,"y":15,"z":-9},{"name":"Plant_Seaweed_Moss_Stack","x":-5,"y":16,"z":-9},{"name":"Plant_Seaweed_Moss_Stack","x":-5,"y":17,"z":-9},{"name":"Plant_Seaweed_Moss_Stack","x":-5,"y":18,"z":-9},{"name":"Plant_Seaweed_Moss_Stack","x":-5,"y":19,"z":-9},{"name":"Plant_Seaweed_Moss_Stack","x":-5,"y":20,"z":-9},{"name":"Plant_Seaweed_Moss_Stack","x":-5,"y":21,"z":-9},{"name":"Plant_Seaweed_Moss_Stack","x":-5,"y":22,"z":-9},{"name":"Wood_Spiral_Trunk_Full","x":-5,"y":9,"z":-8},{"name":"Wood_Spiral_Trunk_Full","x":-5,"y":10,"z":-8},{"name":"Wood_Spiral_Trunk_Full","x":-5,"y":9,"z":-7},{"name":"Plant_Coral_Block_White","x":-5,"y":10,"z":-7},{"name":"Plant_Coral_Block_White","x":-5,"y":11,"z":-7},{"name":"Plant_Seaweed_Grass","x":-5,"y":12,"z":-7},{"name":"Plant_Coral_Block_White","x":-5,"y":11,"z":-6},{"name":"Plant_Seaweed_Moss_Stack","x":-5,"y":12,"z":-6},{"name":"Plant_Seaweed_Moss_Stack","x":-5,"y":13,"z":-6},{"name":"Plant_Seaweed_Moss_Stack","x":-5,"y":14,"z":-6},{"name":"Plant_Seaweed_Moss_Stack","x":-5,"y":15,"z":-6},{"name":"Plant_Seaweed_Moss_Stack","x":-5,"y":16,"z":-6},{"name":"Plant_Seaweed_Moss_Stack","x":-5,"y":17,"z":-6},{"name":"Plant_Seaweed_Moss_Stack","x":-5,"y":18,"z":-6},{"name":"Plant_Seaweed_Moss_Stack","x":-5,"y":19,"z":-6},{"name":"Plant_Seaweed_Moss_Stack","x":-5,"y":20,"z":-6},{"name":"Plant_Seaweed_Moss_Stack","x":-5,"y":21,"z":-6},{"name":"Plant_Seaweed_Moss_Stack","x":-5,"y":22,"z":-6},{"name":"Plant_Seaweed_Moss_Stack","x":-5,"y":23,"z":-6},{"name":"Plant_Seaweed_Moss_Stack","x":-5,"y":24,"z":-6},{"name":"Plant_Seaweed_Moss_Stack","x":-5,"y":25,"z":-6},{"name":"Plant_Seaweed_Moss_Stack","x":-5,"y":26,"z":-6},{"name":"Plant_Seaweed_Moss_Stack","x":-5,"y":27,"z":-6},{"name":"Wood_Spiral_Trunk_Full","x":-5,"y":5,"z":-3},{"name":"Wood_Spiral_Trunk_Full","x":-5,"y":6,"z":-3},{"name":"Wood_Spiral_Trunk_Full","x":-5,"y":5,"z":-2},{"name":"Plant_Coral_Block_White","x":-4,"y":9,"z":-12},{"name":"Plant_Seaweed_Grass","x":-4,"y":10,"z":-12},{"name":"Plant_Coral_Block_White","x":-4,"y":10,"z":-11},{"name":"Plant_Coral_Block_White","x":-4,"y":11,"z":-11},{"name":"Plant_Coral_Block_White","x":-4,"y":12,"z":-11},{"name":"Plant_Coral_Block_White","x":-4,"y":13,"z":-11},{"name":"Plant_Seaweed_Grass","x":-4,"y":14,"z":-11},{"name":"Plant_Coral_Block_White","x":-4,"y":9,"z":-10},{"name":"Plant_Coral_Block_White","x":-4,"y":10,"z":-10},{"name":"Plant_Seaweed_Grass","x":-4,"y":11,"z":-10},{"name":"Plant_Coral_Block_White","x":-4,"y":9,"z":-9},{"name":"Wood_Spiral_Trunk_Full","x":-4,"y":10,"z":-9},{"name":"Plant_Coral_Block_White","x":-4,"y":11,"z":-9},{"name":"Plant_Coral_Block_White","x":-4,"y":12,"z":-9},{"name":"Plant_Seaweed_Moss_Stack","x":-4,"y":13,"z":-9},{"name":"Plant_Seaweed_Moss_Stack","x":-4,"y":14,"z":-9},{"name":"Plant_Seaweed_Moss_Stack","x":-4,"y":15,"z":-9},{"name":"Plant_Seaweed_Moss_Stack","x":-4,"y":16,"z":-9},{"name":"Plant_Seaweed_Moss_Stack","x":-4,"y":17,"z":-9},{"name":"Plant_Seaweed_Moss_Stack","x":-4,"y":18,"z":-9},{"name":"Plant_Seaweed_Moss_Stack","x":-4,"y":19,"z":-9},{"name":"Plant_Coral_Block_White","x":-4,"y":10,"z":-8},{"name":"Plant_Seaweed_Grass","x":-4,"y":11,"z":-8},{"name":"Plant_Coral_Block_White","x":-4,"y":9,"z":-7},{"name":"Plant_Seaweed_Grass_Tall","x":-4,"y":10,"z":-7},{"filler":1024,"name":"Plant_Seaweed_Grass_Tall","x":-4,"y":11,"z":-7},{"name":"Wood_Spiral_Trunk_Full","x":-4,"y":5,"z":-2},{"name":"Wood_Spiral_Trunk_Full","x":-4,"y":6,"z":-2},{"name":"Plant_Coral_Block_White","x":-3,"y":10,"z":-11},{"name":"Plant_Seaweed_Moss_Stack","x":-3,"y":11,"z":-11},{"name":"Plant_Seaweed_Moss_Stack","x":-3,"y":12,"z":-11},{"name":"Plant_Seaweed_Moss_Stack","x":-3,"y":13,"z":-11},{"name":"Plant_Seaweed_Moss_Stack","x":-3,"y":14,"z":-11},{"name":"Plant_Seaweed_Moss_Stack","x":-3,"y":15,"z":-11},{"name":"Plant_Coral_Block_White","x":-3,"y":10,"z":-10},{"name":"Plant_Coral_Block_White","x":-3,"y":11,"z":-10},{"name":"Plant_Seaweed_Grass_Tall","x":-3,"y":12,"z":-10},{"filler":1024,"name":"Plant_Seaweed_Grass_Tall","x":-3,"y":13,"z":-10},{"name":"Plant_Coral_Block_White","x":-3,"y":10,"z":-9},{"name":"Plant_Seaweed_Moss_Stack","x":-3,"y":11,"z":-9},{"name":"Plant_Seaweed_Moss_Stack","x":-3,"y":12,"z":-9},{"name":"Plant_Seaweed_Moss_Stack","x":-3,"y":13,"z":-9},{"name":"Plant_Seaweed_Moss_Stack","x":-3,"y":14,"z":-9},{"name":"Plant_Coral_Block_White","x":-3,"y":10,"z":-8},{"name":"Plant_Coral_Block_White","x":-3,"y":11,"z":-8},{"name":"Plant_Seaweed_Moss_Stack","x":-3,"y":12,"z":-8},{"name":"Plant_Seaweed_Moss_Stack","x":-3,"y":13,"z":-8},{"name":"Plant_Seaweed_Moss_Stack","x":-3,"y":14,"z":-8},{"name":"Plant_Seaweed_Moss_Stack","x":-3,"y":15,"z":-8},{"name":"Plant_Coral_Block_White","x":-3,"y":11,"z":-7},{"name":"Plant_Coral_Block_White","x":-3,"y":12,"z":-7},{"name":"Plant_Seaweed_Grass","x":-3,"y":13,"z":-7},{"name":"Wood_Spiral_Trunk_Full","x":-3,"y":5,"z":-2},{"name":"Wood_Spiral_Trunk_Full","x":-3,"y":6,"z":-2},{"name":"Wood_Spiral_Trunk_Full","x":-3,"y":5,"z":-1},{"name":"Wood_Spiral_Trunk_Full","x":-3,"y":6,"z":-1},{"name":"Plant_Coral_Block_White","x":-2,"y":12,"z":-12},{"name":"Plant_Seaweed_Grass","x":-2,"y":13,"z":-12},{"name":"Plant_Coral_Block_White","x":-2,"y":11,"z":-11},{"name":"Plant_Coral_Block_White","x":-2,"y":12,"z":-11},{"name":"Plant_Seaweed_Moss_Stack","x":-2,"y":13,"z":-11},{"name":"Plant_Seaweed_Moss_Stack","x":-2,"y":14,"z":-11},{"name":"Plant_Seaweed_Moss_Stack","x":-2,"y":15,"z":-11},{"name":"Plant_Seaweed_Moss_Stack","x":-2,"y":16,"z":-11},{"name":"Plant_Seaweed_Moss_Stack","x":-2,"y":17,"z":-11},{"name":"Plant_Seaweed_Moss_Stack","x":-2,"y":18,"z":-11},{"name":"Plant_Seaweed_Moss_Stack","x":-2,"y":19,"z":-11},{"name":"Plant_Seaweed_Moss_Stack","x":-2,"y":20,"z":-11},{"name":"Plant_Seaweed_Moss_Stack","x":-2,"y":21,"z":-11},{"name":"Plant_Seaweed_Moss_Stack","x":-2,"y":22,"z":-11},{"name":"Plant_Coral_Block_White","x":-2,"y":10,"z":-10},{"name":"Plant_Coral_Block_White","x":-2,"y":11,"z":-10},{"name":"Plant_Seaweed_Grass_Tall","x":-2,"y":12,"z":-10},{"filler":1024,"name":"Plant_Seaweed_Grass_Tall","x":-2,"y":13,"z":-10},{"name":"Plant_Coral_Block_White","x":-2,"y":12,"z":-9},{"name":"Plant_Seaweed_Moss_Stack","x":-2,"y":13,"z":-9},{"name":"Plant_Seaweed_Moss_Stack","x":-2,"y":14,"z":-9},{"name":"Plant_Seaweed_Moss_Stack","x":-2,"y":15,"z":-9},{"name":"Plant_Seaweed_Moss_Stack","x":-2,"y":16,"z":-9},{"name":"Plant_Seaweed_Moss_Stack","x":-2,"y":17,"z":-9},{"name":"Plant_Seaweed_Moss_Stack","x":-2,"y":18,"z":-9},{"name":"Plant_Seaweed_Moss_Stack","x":-2,"y":19,"z":-9},{"name":"Plant_Seaweed_Moss_Stack","x":-2,"y":20,"z":-9},{"name":"Plant_Seaweed_Moss_Stack","x":-2,"y":21,"z":-9},{"name":"Plant_Seaweed_Moss_Stack","x":-2,"y":22,"z":-9},{"name":"Plant_Seaweed_Moss_Stack","x":-2,"y":23,"z":-9},{"name":"Plant_Seaweed_Moss_Stack","x":-2,"y":24,"z":-9},{"name":"Plant_Seaweed_Moss_Stack","x":-2,"y":25,"z":-9},{"name":"Plant_Seaweed_Moss_Stack","x":-2,"y":26,"z":-9},{"name":"Plant_Coral_Block_White","x":-2,"y":11,"z":-7},{"name":"Plant_Seaweed_Grass","x":-2,"y":12,"z":-7},{"name":"Plant_Coral_Block_White","x":-2,"y":11,"z":-6},{"name":"Plant_Seaweed_Moss_Stack","x":-2,"y":12,"z":-6},{"name":"Plant_Seaweed_Moss_Stack","x":-2,"y":13,"z":-6},{"name":"Plant_Seaweed_Moss_Stack","x":-2,"y":14,"z":-6},{"name":"Plant_Seaweed_Moss_Stack","x":-2,"y":15,"z":-6},{"name":"Plant_Seaweed_Moss_Stack","x":-2,"y":16,"z":-6},{"name":"Plant_Seaweed_Moss_Stack","x":-2,"y":17,"z":-6},{"name":"Plant_Seaweed_Moss_Stack","x":-2,"y":18,"z":-6},{"name":"Plant_Seaweed_Moss_Stack","x":-2,"y":19,"z":-6},{"name":"Plant_Seaweed_Moss_Stack","x":-2,"y":20,"z":-6},{"name":"Plant_Seaweed_Moss_Stack","x":-2,"y":21,"z":-6},{"name":"Wood_Spiral_Trunk_Full","x":-2,"y":6,"z":-1},{"name":"Wood_Spiral_Trunk_Half","x":-2,"y":7,"z":-1},{"name":"Plant_Coral_Block_White","x":-1,"y":10,"z":-10},{"name":"Plant_Seaweed_Grass_Tall","x":-1,"y":11,"z":-10},{"filler":1024,"name":"Plant_Seaweed_Grass_Tall","x":-1,"y":12,"z":-10},{"name":"Plant_Coral_Block_White","x":-1,"y":12,"z":-9},{"name":"Plant_Seaweed_Moss_Stack","x":-1,"y":13,"z":-9},{"name":"Plant_Seaweed_Moss_Stack","x":-1,"y":14,"z":-9},{"name":"Plant_Seaweed_Moss_Stack","x":-1,"y":15,"z":-9},{"name":"Plant_Seaweed_Moss_Stack","x":-1,"y":16,"z":-9},{"name":"Plant_Seaweed_Moss_Stack","x":-1,"y":17,"z":-9},{"name":"Plant_Seaweed_Moss_Stack","x":-1,"y":18,"z":-9},{"name":"Plant_Seaweed_Moss_Stack","x":-1,"y":19,"z":-9},{"name":"Plant_Seaweed_Moss_Stack","x":-1,"y":20,"z":-9},{"name":"Plant_Seaweed_Moss_Stack","x":-1,"y":21,"z":-9},{"name":"Plant_Seaweed_Moss_Stack","x":-1,"y":22,"z":-9},{"name":"Plant_Seaweed_Moss_Stack","x":-1,"y":23,"z":-9},{"name":"Plant_Seaweed_Moss_Stack","x":-1,"y":24,"z":-9},{"name":"Plant_Seaweed_Moss_Stack","x":-1,"y":25,"z":-9},{"name":"Plant_Seaweed_Moss_Stack","x":-1,"y":26,"z":-9},{"name":"Wood_Spiral_Trunk_Full","x":-1,"y":6,"z":-1},{"name":"Wood_Spiral_Trunk_Half","x":-1,"y":7,"z":-1},{"name":"Wood_Spiral_Trunk_Full","x":-1,"y":6,"z":0},{"name":"Wood_Spiral_Trunk_Full","x":-1,"y":7,"z":0},{"name":"Wood_Spiral_Trunk_Full","x":0,"y":6,"z":0},{"name":"Wood_Spiral_Trunk_Half","rotation":8,"x":0,"y":7,"z":0},{"name":"Wood_Spiral_Trunk_Full","x":0,"y":6,"z":1},{"name":"Wood_Spiral_Trunk_Full","x":0,"y":7,"z":1},{"name":"Wood_Spiral_Trunk_Full","x":1,"y":6,"z":1},{"name":"Wood_Spiral_Trunk_Full","x":1,"y":7,"z":1},{"name":"Wood_Spiral_Trunk_Full","x":1,"y":6,"z":2},{"name":"Wood_Spiral_Trunk_Half","x":1,"y":7,"z":2},{"name":"Wood_Spiral_Trunk_Full","x":2,"y":6,"z":1},{"name":"Wood_Spiral_Trunk_Full","x":2,"y":7,"z":1},{"name":"Wood_Spiral_Trunk_Full","x":2,"y":6,"z":2},{"name":"Wood_Spiral_Trunk_Full","x":2,"y":7,"z":2},{"name":"Wood_Spiral_Trunk_Half","x":2,"y":8,"z":2},{"name":"Wood_Spiral_Trunk_Full","x":3,"y":7,"z":2},{"name":"Wood_Spiral_Trunk_Full","x":3,"y":8,"z":2},{"name":"Wood_Spiral_Trunk_Full","x":3,"y":7,"z":3},{"name":"Wood_Spiral_Trunk_Full","x":3,"y":8,"z":3},{"name":"Wood_Spiral_Trunk_Half","x":3,"y":9,"z":3},{"name":"Plant_Coral_Block_White","x":4,"y":16,"z":1},{"name":"Plant_Seaweed_Grass_Tall","x":4,"y":17,"z":1},{"filler":1024,"name":"Plant_Seaweed_Grass_Tall","x":4,"y":18,"z":1},{"name":"Wood_Spiral_Trunk_Full","x":4,"y":7,"z":2},{"name":"Wood_Spiral_Trunk_Full","x":4,"y":8,"z":2},{"name":"Wood_Spiral_Trunk_Half","x":4,"y":9,"z":2},{"name":"Wood_Spiral_Trunk_Full","x":4,"y":7,"z":3},{"name":"Wood_Spiral_Trunk_Full","x":4,"y":8,"z":3},{"name":"Wood_Spiral_Trunk_Full","x":4,"y":9,"z":3},{"name":"Wood_Spiral_Trunk_Full","x":4,"y":8,"z":4},{"name":"Wood_Spiral_Trunk_Half","x":4,"y":9,"z":4},{"name":"Plant_Coral_Block_White","x":4,"y":14,"z":8},{"name":"Plant_Seaweed_Moss_Stack","x":4,"y":15,"z":8},{"name":"Plant_Seaweed_Moss_Stack","x":4,"y":16,"z":8},{"name":"Plant_Seaweed_Moss_Stack","x":4,"y":17,"z":8},{"name":"Plant_Seaweed_Moss_Stack","x":4,"y":18,"z":8},{"name":"Plant_Seaweed_Moss_Stack","x":4,"y":19,"z":8},{"name":"Plant_Coral_Block_White","x":5,"y":15,"z":-1},{"name":"Plant_Seaweed_Grass_Tall","x":5,"y":16,"z":-1},{"filler":1024,"name":"Plant_Seaweed_Grass_Tall","x":5,"y":17,"z":-1},{"name":"Plant_Coral_Block_White","x":5,"y":15,"z":1},{"name":"Plant_Coral_Block_White","x":5,"y":16,"z":1},{"name":"Plant_Seaweed_Grass_Tall","x":5,"y":17,"z":1},{"filler":1024,"name":"Plant_Seaweed_Grass_Tall","x":5,"y":18,"z":1},{"name":"Plant_Coral_Block_White","x":5,"y":15,"z":2},{"name":"Plant_Seaweed_Grass","x":5,"y":16,"z":2},{"name":"Wood_Spiral_Trunk_Full","x":5,"y":8,"z":3},{"name":"Wood_Spiral_Trunk_Full","x":5,"y":9,"z":3},{"name":"Wood_Spiral_Trunk_Full","x":5,"y":8,"z":4},{"name":"Wood_Spiral_Trunk_Full","x":5,"y":9,"z":4},{"name":"Plant_Coral_Block_White","x":5,"y":13,"z":6},{"name":"Plant_Seaweed_Grass_Tall","x":5,"y":14,"z":6},{"filler":1024,"name":"Plant_Seaweed_Grass_Tall","x":5,"y":15,"z":6},{"name":"Plant_Coral_Block_White","x":5,"y":13,"z":8},{"name":"Plant_Coral_Block_White","x":5,"y":14,"z":8},{"name":"Plant_Seaweed_Moss_Stack","x":5,"y":15,"z":8},{"name":"Plant_Seaweed_Moss_Stack","x":5,"y":16,"z":8},{"name":"Plant_Seaweed_Moss_Stack","x":5,"y":17,"z":8},{"name":"Plant_Seaweed_Moss_Stack","x":5,"y":18,"z":8},{"name":"Plant_Seaweed_Moss_Stack","x":5,"y":19,"z":8},{"name":"Plant_Seaweed_Moss_Stack","x":5,"y":20,"z":8},{"name":"Plant_Seaweed_Moss_Stack","x":5,"y":21,"z":8},{"name":"Plant_Seaweed_Moss_Stack","x":5,"y":22,"z":8},{"name":"Plant_Seaweed_Moss_Stack","x":5,"y":23,"z":8},{"name":"Plant_Seaweed_Moss_Stack","x":5,"y":24,"z":8},{"name":"Plant_Seaweed_Moss_Stack","x":5,"y":25,"z":8},{"name":"Plant_Coral_Block_White","x":5,"y":13,"z":9},{"name":"Plant_Seaweed_Moss_Stack","x":5,"y":14,"z":9},{"name":"Plant_Seaweed_Moss_Stack","x":5,"y":15,"z":9},{"name":"Plant_Seaweed_Moss_Stack","x":5,"y":16,"z":9},{"name":"Plant_Seaweed_Moss_Stack","x":5,"y":17,"z":9},{"name":"Plant_Seaweed_Moss_Stack","x":5,"y":18,"z":9},{"name":"Plant_Seaweed_Moss_Stack","x":5,"y":19,"z":9},{"name":"Plant_Coral_Block_White","x":6,"y":13,"z":-1},{"name":"Plant_Coral_Block_White","x":6,"y":14,"z":-1},{"name":"Plant_Coral_Block_White","x":6,"y":15,"z":-1},{"name":"Plant_Coral_Block_White","x":6,"y":16,"z":-1},{"name":"Plant_Seaweed_Moss_Stack","x":6,"y":17,"z":-1},{"name":"Plant_Seaweed_Moss_Stack","x":6,"y":18,"z":-1},{"name":"Plant_Seaweed_Moss_Stack","x":6,"y":19,"z":-1},{"name":"Plant_Seaweed_Moss_Stack","x":6,"y":20,"z":-1},{"name":"Plant_Coral_Block_White","x":6,"y":14,"z":0},{"name":"Plant_Seaweed_Grass_Tall","x":6,"y":15,"z":0},{"filler":1024,"name":"Plant_Seaweed_Grass_Tall","x":6,"y":16,"z":0},{"name":"Plant_Coral_Block_White","x":6,"y":14,"z":2},{"name":"Plant_Coral_Block_White","x":6,"y":15,"z":2},{"name":"Plant_Seaweed_Moss_Stack","x":6,"y":16,"z":2},{"name":"Plant_Seaweed_Moss_Stack","x":6,"y":17,"z":2},{"name":"Plant_Seaweed_Moss_Stack","x":6,"y":18,"z":2},{"name":"Plant_Seaweed_Moss_Stack","x":6,"y":19,"z":2},{"name":"Plant_Seaweed_Moss_Stack","x":6,"y":20,"z":2},{"name":"Plant_Seaweed_Moss_Stack","x":6,"y":21,"z":2},{"name":"Wood_Spiral_Trunk_Full","x":6,"y":9,"z":3},{"name":"Plant_Coral_Block_White","x":6,"y":13,"z":3},{"name":"Plant_Seaweed_Grass","x":6,"y":14,"z":3},{"name":"Wood_Spiral_Trunk_Full","x":6,"y":8,"z":4},{"name":"Wood_Spiral_Trunk_Full","x":6,"y":9,"z":4},{"name":"Plant_Coral_Block_White","x":6,"y":15,"z":4},{"name":"Plant_Coral_Block_White","x":6,"y":16,"z":4},{"name":"Plant_Seaweed_Moss_Stack","x":6,"y":17,"z":4},{"name":"Plant_Seaweed_Moss_Stack","x":6,"y":18,"z":4},{"name":"Plant_Seaweed_Moss_Stack","x":6,"y":19,"z":4},{"name":"Plant_Seaweed_Moss_Stack","x":6,"y":20,"z":4},{"name":"Plant_Seaweed_Moss_Stack","x":6,"y":21,"z":4},{"name":"Plant_Seaweed_Moss_Stack","x":6,"y":22,"z":4},{"name":"Plant_Seaweed_Moss_Stack","x":6,"y":23,"z":4},{"name":"Plant_Seaweed_Moss_Stack","x":6,"y":24,"z":4},{"name":"Plant_Seaweed_Moss_Stack","x":6,"y":25,"z":4},{"name":"Plant_Seaweed_Moss_Stack","x":6,"y":26,"z":4},{"name":"Plant_Seaweed_Moss_Stack","x":6,"y":27,"z":4},{"name":"Plant_Seaweed_Moss_Stack","x":6,"y":28,"z":4},{"name":"Plant_Seaweed_Moss_Stack","x":6,"y":29,"z":4},{"name":"Plant_Seaweed_Moss_Stack","x":6,"y":30,"z":4},{"name":"Wood_Spiral_Trunk_Full","x":6,"y":8,"z":5},{"name":"Plant_Coral_Block_White","x":6,"y":11,"z":6},{"name":"Plant_Coral_Block_White","x":6,"y":12,"z":6},{"name":"Plant_Coral_Block_White","x":6,"y":13,"z":6},{"name":"Plant_Coral_Block_White","x":6,"y":14,"z":6},{"name":"Plant_Seaweed_Moss_Stack","x":6,"y":15,"z":6},{"name":"Plant_Seaweed_Moss_Stack","x":6,"y":16,"z":6},{"name":"Plant_Seaweed_Moss_Stack","x":6,"y":17,"z":6},{"name":"Plant_Coral_Block_White","x":6,"y":12,"z":7},{"name":"Plant_Seaweed_Moss_Stack","x":6,"y":13,"z":7},{"name":"Plant_Seaweed_Moss_Stack","x":6,"y":14,"z":7},{"name":"Plant_Seaweed_Moss_Stack","x":6,"y":15,"z":7},{"name":"Plant_Seaweed_Moss_Stack","x":6,"y":16,"z":7},{"name":"Plant_Seaweed_Moss_Stack","x":6,"y":17,"z":7},{"name":"Plant_Seaweed_Moss_Stack","x":6,"y":18,"z":7},{"name":"Plant_Seaweed_Moss_Stack","x":6,"y":19,"z":7},{"name":"Plant_Seaweed_Moss_Stack","x":6,"y":20,"z":7},{"name":"Plant_Seaweed_Moss_Stack","x":6,"y":21,"z":7},{"name":"Plant_Seaweed_Moss_Stack","x":6,"y":22,"z":7},{"name":"Plant_Coral_Block_White","x":6,"y":12,"z":9},{"name":"Plant_Coral_Block_White","x":6,"y":13,"z":9},{"name":"Plant_Seaweed_Moss_Stack","x":6,"y":14,"z":9},{"name":"Plant_Seaweed_Moss_Stack","x":6,"y":15,"z":9},{"name":"Plant_Seaweed_Moss_Stack","x":6,"y":16,"z":9},{"name":"Plant_Seaweed_Moss_Stack","x":6,"y":17,"z":9},{"name":"Plant_Seaweed_Moss_Stack","x":6,"y":18,"z":9},{"name":"Plant_Coral_Block_White","x":6,"y":11,"z":10},{"name":"Plant_Seaweed_Moss_Stack","x":6,"y":12,"z":10},{"name":"Plant_Seaweed_Moss_Stack","x":6,"y":13,"z":10},{"name":"Plant_Seaweed_Moss_Stack","x":6,"y":14,"z":10},{"name":"Plant_Seaweed_Moss_Stack","x":6,"y":15,"z":10},{"name":"Plant_Seaweed_Moss_Stack","x":6,"y":16,"z":10},{"name":"Plant_Seaweed_Moss_Stack","x":6,"y":17,"z":10},{"name":"Plant_Seaweed_Moss_Stack","x":6,"y":18,"z":10},{"name":"Plant_Seaweed_Moss_Stack","x":6,"y":19,"z":10},{"name":"Plant_Seaweed_Moss_Stack","x":6,"y":20,"z":10},{"name":"Plant_Seaweed_Moss_Stack","x":6,"y":21,"z":10},{"name":"Plant_Seaweed_Moss_Stack","x":6,"y":22,"z":10},{"name":"Plant_Seaweed_Moss_Stack","x":6,"y":23,"z":10},{"name":"Plant_Seaweed_Moss_Stack","x":6,"y":24,"z":10},{"name":"Plant_Seaweed_Moss_Stack","x":6,"y":25,"z":10},{"name":"Plant_Coral_Block_White","x":6,"y":13,"z":11},{"name":"Plant_Coral_Block_White","x":6,"y":14,"z":11},{"name":"Plant_Seaweed_Grass_Tall","x":6,"y":15,"z":11},{"filler":1024,"name":"Plant_Seaweed_Grass_Tall","x":6,"y":16,"z":11},{"name":"Plant_Coral_Block_White","x":7,"y":15,"z":-2},{"name":"Plant_Coral_Block_White","x":7,"y":16,"z":-2},{"name":"Plant_Seaweed_Grass","x":7,"y":17,"z":-2},{"name":"Plant_Coral_Block_White","x":7,"y":14,"z":0},{"name":"Plant_Seaweed_Grass_Tall","x":7,"y":15,"z":0},{"filler":1024,"name":"Plant_Seaweed_Grass_Tall","x":7,"y":16,"z":0},{"name":"Plant_Coral_Block_White","x":7,"y":13,"z":1},{"name":"Plant_Seaweed_Grass_Tall","x":7,"y":14,"z":1},{"filler":1024,"name":"Plant_Seaweed_Grass_Tall","x":7,"y":15,"z":1},{"name":"Plant_Coral_Block_White","x":7,"y":14,"z":2},{"name":"Plant_Seaweed_Grass_Tall","x":7,"y":15,"z":2},{"filler":1024,"name":"Plant_Seaweed_Grass_Tall","x":7,"y":16,"z":2},{"name":"Plant_Coral_Block_White","x":7,"y":14,"z":3},{"name":"Plant_Coral_Block_White","x":7,"y":15,"z":3},{"name":"Plant_Seaweed_Moss_Stack","x":7,"y":16,"z":3},{"name":"Wood_Spiral_Trunk_Full","x":7,"y":8,"z":4},{"name":"Wood_Spiral_Trunk_Full","x":7,"y":9,"z":4},{"name":"Plant_Coral_Block_White","x":7,"y":15,"z":4},{"name":"Plant_Seaweed_Moss_Stack","x":7,"y":16,"z":4},{"name":"Plant_Seaweed_Moss_Stack","x":7,"y":17,"z":4},{"name":"Plant_Seaweed_Moss_Stack","x":7,"y":18,"z":4},{"name":"Plant_Seaweed_Moss_Stack","x":7,"y":19,"z":4},{"name":"Plant_Seaweed_Moss_Stack","x":7,"y":20,"z":4},{"name":"Wood_Spiral_Trunk_Full","x":7,"y":7,"z":5},{"name":"Wood_Spiral_Trunk_Full","x":7,"y":8,"z":5},{"name":"Plant_Coral_Block_White","x":7,"y":13,"z":5},{"name":"Plant_Coral_Block_White","x":7,"y":14,"z":5},{"name":"Plant_Seaweed_Grass_Tall","x":7,"y":15,"z":5},{"filler":1024,"name":"Plant_Seaweed_Grass_Tall","x":7,"y":16,"z":5},{"name":"Wood_Spiral_Trunk_Full","x":7,"y":7,"z":6},{"name":"Plant_Coral_Block_White","x":7,"y":12,"z":7},{"name":"Plant_Seaweed_Grass_Tall","x":7,"y":13,"z":7},{"filler":1024,"name":"Plant_Seaweed_Grass_Tall","x":7,"y":14,"z":7},{"name":"Plant_Coral_Block_White","x":7,"y":11,"z":8},{"name":"Plant_Seaweed_Grass_Tall","x":7,"y":12,"z":8},{"filler":1024,"name":"Plant_Seaweed_Grass_Tall","x":7,"y":13,"z":8},{"name":"Plant_Coral_Block_White","x":7,"y":12,"z":9},{"name":"Plant_Seaweed_Grass","x":7,"y":13,"z":9},{"name":"Plant_Coral_Block_White","x":7,"y":12,"z":10},{"name":"Plant_Coral_Block_White","x":7,"y":13,"z":10},{"name":"Plant_Seaweed_Moss_Stack","x":7,"y":14,"z":10},{"name":"Plant_Seaweed_Moss_Stack","x":7,"y":15,"z":10},{"name":"Plant_Seaweed_Moss_Stack","x":7,"y":16,"z":10},{"name":"Plant_Seaweed_Moss_Stack","x":7,"y":17,"z":10},{"name":"Plant_Seaweed_Moss_Stack","x":7,"y":18,"z":10},{"name":"Plant_Seaweed_Moss_Stack","x":7,"y":19,"z":10},{"name":"Plant_Seaweed_Moss_Stack","x":7,"y":20,"z":10},{"name":"Plant_Seaweed_Moss_Stack","x":7,"y":21,"z":10},{"name":"Plant_Seaweed_Moss_Stack","x":7,"y":22,"z":10},{"name":"Plant_Seaweed_Moss_Stack","x":7,"y":23,"z":10},{"name":"Plant_Seaweed_Moss_Stack","x":7,"y":24,"z":10},{"name":"Plant_Coral_Block_White","x":7,"y":13,"z":11},{"name":"Plant_Seaweed_Grass_Tall","x":7,"y":14,"z":11},{"filler":1024,"name":"Plant_Seaweed_Grass_Tall","x":7,"y":15,"z":11},{"name":"Plant_Coral_Block_White","x":8,"y":13,"z":-2},{"name":"Plant_Seaweed_Moss_Stack","x":8,"y":14,"z":-2},{"name":"Plant_Seaweed_Moss_Stack","x":8,"y":15,"z":-2},{"name":"Plant_Seaweed_Moss_Stack","x":8,"y":16,"z":-2},{"name":"Plant_Seaweed_Moss_Stack","x":8,"y":17,"z":-2},{"name":"Plant_Seaweed_Moss_Stack","x":8,"y":18,"z":-2},{"name":"Plant_Seaweed_Moss_Stack","x":8,"y":19,"z":-2},{"name":"Plant_Seaweed_Moss_Stack","x":8,"y":20,"z":-2},{"name":"Plant_Seaweed_Moss_Stack","x":8,"y":21,"z":-2},{"name":"Plant_Seaweed_Moss_Stack","x":8,"y":22,"z":-2},{"name":"Plant_Seaweed_Moss_Stack","x":8,"y":23,"z":-2},{"name":"Plant_Seaweed_Moss_Stack","x":8,"y":24,"z":-2},{"name":"Plant_Seaweed_Moss_Stack","x":8,"y":25,"z":-2},{"name":"Plant_Seaweed_Moss_Stack","x":8,"y":26,"z":-2},{"name":"Plant_Seaweed_Moss_Stack","x":8,"y":27,"z":-2},{"name":"Plant_Coral_Block_White","x":8,"y":14,"z":-1},{"name":"Plant_Coral_Block_White","x":8,"y":15,"z":-1},{"name":"Plant_Coral_Block_White","x":8,"y":16,"z":-1},{"name":"Plant_Coral_Block_White","x":8,"y":17,"z":-1},{"name":"Plant_Seaweed_Moss_Stack","x":8,"y":18,"z":-1},{"name":"Plant_Seaweed_Moss_Stack","x":8,"y":19,"z":-1},{"name":"Plant_Coral_Block_White","x":8,"y":13,"z":0},{"name":"Plant_Coral_Block_White","x":8,"y":14,"z":0},{"name":"Plant_Seaweed_Moss_Stack","x":8,"y":15,"z":0},{"name":"Plant_Seaweed_Moss_Stack","x":8,"y":16,"z":0},{"name":"Plant_Seaweed_Moss_Stack","x":8,"y":17,"z":0},{"name":"Plant_Seaweed_Moss_Stack","x":8,"y":18,"z":0},{"name":"Plant_Seaweed_Moss_Stack","x":8,"y":19,"z":0},{"name":"Wood_Spiral_Trunk_Full","x":8,"y":12,"z":1},{"name":"Wood_Spiral_Trunk_Full","x":8,"y":13,"z":1},{"name":"Wood_Spiral_Trunk_Full","x":8,"y":14,"z":1},{"name":"Plant_Coral_Block_White","x":8,"y":15,"z":1},{"name":"Plant_Coral_Block_White","x":8,"y":16,"z":1},{"name":"Plant_Seaweed_Grass","x":8,"y":17,"z":1},{"name":"Wood_Spiral_Trunk_Full","x":8,"y":12,"z":2},{"name":"Plant_Coral_Block_White","x":8,"y":14,"z":2},{"name":"Plant_Seaweed_Moss_Stack","x":8,"y":15,"z":2},{"name":"Plant_Seaweed_Moss_Stack","x":8,"y":16,"z":2},{"name":"Plant_Seaweed_Moss_Stack","x":8,"y":17,"z":2},{"name":"Plant_Seaweed_Moss_Stack","x":8,"y":18,"z":2},{"name":"Plant_Seaweed_Moss_Stack","x":8,"y":19,"z":2},{"name":"Plant_Seaweed_Moss_Stack","x":8,"y":20,"z":2},{"name":"Plant_Seaweed_Moss_Stack","x":8,"y":21,"z":2},{"name":"Plant_Seaweed_Moss_Stack","x":8,"y":22,"z":2},{"name":"Plant_Seaweed_Moss_Stack","x":8,"y":23,"z":2},{"name":"Plant_Seaweed_Moss_Stack","x":8,"y":24,"z":2},{"name":"Plant_Seaweed_Moss_Stack","x":8,"y":25,"z":2},{"name":"Plant_Seaweed_Moss_Stack","x":8,"y":26,"z":2},{"name":"Plant_Seaweed_Moss_Stack","x":8,"y":27,"z":2},{"name":"Plant_Coral_Block_White","x":8,"y":13,"z":3},{"name":"Plant_Seaweed_Moss_Stack","x":8,"y":14,"z":3},{"name":"Plant_Seaweed_Moss_Stack","x":8,"y":15,"z":3},{"name":"Plant_Seaweed_Moss_Stack","x":8,"y":16,"z":3},{"name":"Plant_Seaweed_Moss_Stack","x":8,"y":17,"z":3},{"name":"Plant_Seaweed_Moss_Stack","x":8,"y":18,"z":3},{"name":"Plant_Seaweed_Moss_Stack","x":8,"y":19,"z":3},{"name":"Plant_Seaweed_Moss_Stack","x":8,"y":20,"z":3},{"name":"Plant_Seaweed_Moss_Stack","x":8,"y":21,"z":3},{"name":"Plant_Seaweed_Moss_Stack","x":8,"y":22,"z":3},{"name":"Wood_Spiral_Trunk_Full","x":8,"y":8,"z":4},{"name":"Wood_Spiral_Trunk_Full","x":8,"y":9,"z":4},{"name":"Wood_Spiral_Trunk_Full","x":8,"y":7,"z":5},{"name":"Wood_Spiral_Trunk_Full","x":8,"y":8,"z":5},{"name":"Wood_Spiral_Trunk_Full","x":8,"y":9,"z":5},{"name":"Plant_Coral_Block_White","x":8,"y":11,"z":5},{"name":"Plant_Seaweed_Moss_Stack","x":8,"y":12,"z":5},{"name":"Plant_Seaweed_Moss_Stack","x":8,"y":13,"z":5},{"name":"Plant_Seaweed_Moss_Stack","x":8,"y":14,"z":5},{"name":"Plant_Seaweed_Moss_Stack","x":8,"y":15,"z":5},{"name":"Plant_Seaweed_Moss_Stack","x":8,"y":16,"z":5},{"name":"Plant_Seaweed_Moss_Stack","x":8,"y":17,"z":5},{"name":"Plant_Seaweed_Moss_Stack","x":8,"y":18,"z":5},{"name":"Wood_Spiral_Trunk_Full","x":8,"y":6,"z":6},{"name":"Wood_Spiral_Trunk_Full","x":8,"y":7,"z":6},{"name":"Wood_Spiral_Trunk_Full","x":8,"y":8,"z":6},{"name":"Plant_Coral_Block_White","x":8,"y":12,"z":6},{"name":"Plant_Coral_Block_White","x":8,"y":13,"z":6},{"name":"Plant_Coral_Block_White","x":8,"y":14,"z":6},{"name":"Plant_Coral_Block_White","x":8,"y":15,"z":6},{"name":"Plant_Seaweed_Moss_Stack","x":8,"y":16,"z":6},{"name":"Plant_Seaweed_Moss_Stack","x":8,"y":17,"z":6},{"name":"Plant_Seaweed_Moss_Stack","x":8,"y":18,"z":6},{"name":"Plant_Seaweed_Moss_Stack","x":8,"y":19,"z":6},{"name":"Plant_Seaweed_Moss_Stack","x":8,"y":20,"z":6},{"name":"Plant_Seaweed_Moss_Stack","x":8,"y":21,"z":6},{"name":"Plant_Seaweed_Moss_Stack","x":8,"y":22,"z":6},{"name":"Plant_Seaweed_Moss_Stack","x":8,"y":23,"z":6},{"name":"Plant_Seaweed_Moss_Stack","x":8,"y":24,"z":6},{"name":"Plant_Coral_Block_White","x":8,"y":11,"z":7},{"name":"Plant_Coral_Block_White","x":8,"y":12,"z":7},{"name":"Plant_Seaweed_Grass","x":8,"y":13,"z":7},{"name":"Wood_Spiral_Trunk_Full","x":8,"y":11,"z":8},{"name":"Wood_Spiral_Trunk_Full","x":8,"y":12,"z":8},{"name":"Plant_Coral_Block_White","x":8,"y":13,"z":8},{"name":"Plant_Coral_Block_White","x":8,"y":14,"z":8},{"name":"Plant_Seaweed_Moss_Stack","x":8,"y":15,"z":8},{"name":"Plant_Seaweed_Moss_Stack","x":8,"y":16,"z":8},{"name":"Plant_Seaweed_Moss_Stack","x":8,"y":17,"z":8},{"name":"Plant_Coral_Block_White","x":8,"y":12,"z":9},{"name":"Plant_Coral_Block_White","x":8,"y":13,"z":9},{"name":"Plant_Seaweed_Grass_Tall","x":8,"y":14,"z":9},{"filler":1024,"name":"Plant_Seaweed_Grass_Tall","x":8,"y":15,"z":9},{"name":"Plant_Coral_Block_White","x":8,"y":11,"z":10},{"name":"Plant_Seaweed_Grass","x":8,"y":12,"z":10},{"name":"Plant_Coral_Block_White","x":9,"y":13,"z":-1},{"name":"Plant_Coral_Block_White","x":9,"y":14,"z":-1},{"name":"Plant_Seaweed_Moss_Stack","x":9,"y":15,"z":-1},{"name":"Plant_Seaweed_Moss_Stack","x":9,"y":16,"z":-1},{"name":"Plant_Seaweed_Moss_Stack","x":9,"y":17,"z":-1},{"name":"Plant_Seaweed_Moss_Stack","x":9,"y":18,"z":-1},{"name":"Plant_Seaweed_Moss_Stack","x":9,"y":19,"z":-1},{"name":"Plant_Seaweed_Moss_Stack","x":9,"y":20,"z":-1},{"name":"Plant_Coral_Block_White","x":9,"y":14,"z":0},{"name":"Plant_Coral_Block_White","x":9,"y":15,"z":0},{"name":"Plant_Seaweed_Grass_Tall","x":9,"y":16,"z":0},{"filler":1024,"name":"Plant_Seaweed_Grass_Tall","x":9,"y":17,"z":0},{"name":"Plant_Coral_Block_White","x":9,"y":13,"z":1},{"name":"Plant_Coral_Block_White","x":9,"y":14,"z":1},{"name":"Plant_Seaweed_Grass","x":9,"y":15,"z":1},{"name":"Wood_Spiral_Trunk_Full","x":9,"y":10,"z":2},{"name":"Wood_Spiral_Trunk_Full","x":9,"y":11,"z":2},{"name":"Wood_Spiral_Trunk_Full","x":9,"y":12,"z":2},{"name":"Plant_Coral_Block_White","x":9,"y":13,"z":2},{"name":"Plant_Coral_Block_White","x":9,"y":14,"z":2},{"name":"Plant_Coral_Block_White","x":9,"y":15,"z":2},{"name":"Plant_Seaweed_Moss_Stack","x":9,"y":16,"z":2},{"name":"Plant_Seaweed_Moss_Stack","x":9,"y":17,"z":2},{"name":"Plant_Seaweed_Moss_Stack","x":9,"y":18,"z":2},{"name":"Plant_Seaweed_Moss_Stack","x":9,"y":19,"z":2},{"name":"Wood_Spiral_Trunk_Full","x":9,"y":10,"z":3},{"name":"Plant_Coral_Block_White","x":9,"y":15,"z":3},{"name":"Plant_Coral_Block_White","x":9,"y":16,"z":3},{"name":"Plant_Seaweed_Grass_Tall","x":9,"y":17,"z":3},{"filler":1024,"name":"Plant_Seaweed_Grass_Tall","x":9,"y":18,"z":3},{"name":"Wood_Spiral_Trunk_Full","x":9,"y":9,"z":4},{"name":"Wood_Spiral_Trunk_Full","x":9,"y":10,"z":4},{"name":"Wood_Spiral_Trunk_Full","x":9,"y":7,"z":5},{"name":"Wood_Spiral_Trunk_Full","x":9,"y":8,"z":5},{"name":"Wood_Spiral_Trunk_Full","x":9,"y":5,"z":6},{"name":"Wood_Spiral_Trunk_Full","x":9,"y":6,"z":6},{"name":"Wood_Spiral_Trunk_Full","x":9,"y":7,"z":6},{"name":"Wood_Spiral_Trunk_Full","x":9,"y":8,"z":6},{"name":"Plant_Coral_Block_White","x":9,"y":12,"z":6},{"name":"Plant_Seaweed_Moss_Stack","x":9,"y":13,"z":6},{"name":"Wood_Spiral_Trunk_Full","x":9,"y":0,"z":7},{"name":"Wood_Spiral_Trunk_Full","x":9,"y":1,"z":7},{"name":"Wood_Spiral_Trunk_Full","x":9,"y":2,"z":7},{"name":"Wood_Spiral_Trunk_Full","x":9,"y":3,"z":7},{"name":"Wood_Spiral_Trunk_Full","x":9,"y":4,"z":7},{"name":"Wood_Spiral_Trunk_Full","x":9,"y":5,"z":7},{"name":"Wood_Spiral_Trunk_Full","x":9,"y":8,"z":7},{"name":"Wood_Spiral_Trunk_Full","x":9,"y":9,"z":7},{"name":"Plant_Coral_Block_White","x":9,"y":12,"z":7},{"name":"Plant_Coral_Block_White","x":9,"y":13,"z":7},{"name":"Plant_Seaweed_Grass_Tall","x":9,"y":14,"z":7},{"filler":1024,"name":"Plant_Seaweed_Grass_Tall","x":9,"y":15,"z":7},{"name":"Wood_Spiral_Trunk_Full","x":9,"y":9,"z":8},{"name":"Wood_Spiral_Trunk_Full","x":9,"y":10,"z":8},{"name":"Wood_Spiral_Trunk_Full","x":9,"y":11,"z":8},{"name":"Plant_Coral_Block_White","x":9,"y":12,"z":8},{"name":"Plant_Seaweed_Grass_Tall","x":9,"y":13,"z":8},{"filler":1024,"name":"Plant_Seaweed_Grass_Tall","x":9,"y":14,"z":8},{"name":"Plant_Coral_Block_White","x":9,"y":12,"z":9},{"name":"Plant_Coral_Block_White","x":9,"y":13,"z":9},{"name":"Plant_Seaweed_Grass","x":9,"y":14,"z":9},{"name":"Plant_Coral_Block_White","x":9,"y":12,"z":10},{"name":"Plant_Coral_Block_White","x":9,"y":13,"z":10},{"name":"Plant_Coral_Block_White","x":9,"y":14,"z":10},{"name":"Plant_Seaweed_Moss_Stack","x":9,"y":15,"z":10},{"name":"Plant_Seaweed_Moss_Stack","x":9,"y":16,"z":10},{"name":"Plant_Seaweed_Moss_Stack","x":9,"y":17,"z":10},{"name":"Plant_Seaweed_Moss_Stack","x":9,"y":18,"z":10},{"name":"Plant_Coral_Block_White","x":10,"y":16,"z":-2},{"name":"Plant_Seaweed_Grass","x":10,"y":17,"z":-2},{"name":"Plant_Coral_Block_White","x":10,"y":11,"z":-1},{"name":"Plant_Coral_Block_White","x":10,"y":12,"z":-1},{"name":"Plant_Coral_Block_White","x":10,"y":13,"z":-1},{"name":"Plant_Coral_Block_White","x":10,"y":14,"z":-1},{"name":"Plant_Coral_Block_White","x":10,"y":15,"z":-1},{"name":"Plant_Coral_Block_White","x":10,"y":16,"z":-1},{"name":"Plant_Seaweed_Grass","x":10,"y":17,"z":-1},{"name":"Plant_Coral_Block_White","x":10,"y":12,"z":0},{"name":"Plant_Seaweed_Grass_Tall","x":10,"y":13,"z":0},{"filler":1024,"name":"Plant_Seaweed_Grass_Tall","x":10,"y":14,"z":0},{"name":"Plant_Coral_Block_White","x":10,"y":16,"z":1},{"name":"Plant_Seaweed_Grass_Tall","x":10,"y":17,"z":1},{"filler":1024,"name":"Plant_Seaweed_Grass_Tall","x":10,"y":18,"z":1},{"name":"Plant_Coral_Block_White","x":10,"y":12,"z":2},{"name":"Plant_Coral_Block_White","x":10,"y":13,"z":2},{"name":"Plant_Seaweed_Moss_Stack","x":10,"y":14,"z":2},{"name":"Plant_Seaweed_Moss_Stack","x":10,"y":15,"z":2},{"name":"Plant_Seaweed_Moss_Stack","x":10,"y":16,"z":2},{"name":"Plant_Seaweed_Moss_Stack","x":10,"y":17,"z":2},{"name":"Plant_Seaweed_Moss_Stack","x":10,"y":18,"z":2},{"name":"Plant_Seaweed_Moss_Stack","x":10,"y":19,"z":2},{"name":"Plant_Seaweed_Moss_Stack","x":10,"y":20,"z":2},{"name":"Plant_Seaweed_Moss_Stack","x":10,"y":21,"z":2},{"name":"Plant_Seaweed_Moss_Stack","x":10,"y":22,"z":2},{"name":"Plant_Seaweed_Moss_Stack","x":10,"y":23,"z":2},{"name":"Plant_Seaweed_Moss_Stack","x":10,"y":24,"z":2},{"name":"Plant_Seaweed_Moss_Stack","x":10,"y":25,"z":2},{"name":"Plant_Seaweed_Moss_Stack","x":10,"y":26,"z":2},{"name":"Plant_Seaweed_Moss_Stack","x":10,"y":27,"z":2},{"name":"Wood_Spiral_Trunk_Full","x":10,"y":10,"z":3},{"name":"Plant_Coral_Block_White","x":10,"y":11,"z":3},{"name":"Plant_Seaweed_Moss_Stack","x":10,"y":12,"z":3},{"name":"Plant_Seaweed_Moss_Stack","x":10,"y":13,"z":3},{"name":"Plant_Seaweed_Moss_Stack","x":10,"y":14,"z":3},{"name":"Plant_Seaweed_Moss_Stack","x":10,"y":15,"z":3},{"name":"Plant_Seaweed_Moss_Stack","x":10,"y":16,"z":3},{"name":"Plant_Seaweed_Moss_Stack","x":10,"y":17,"z":3},{"name":"Plant_Seaweed_Moss_Stack","x":10,"y":18,"z":3},{"name":"Plant_Seaweed_Moss_Stack","x":10,"y":19,"z":3},{"name":"Plant_Seaweed_Moss_Stack","x":10,"y":20,"z":3},{"name":"Plant_Seaweed_Moss_Stack","x":10,"y":21,"z":3},{"name":"Plant_Seaweed_Moss_Stack","x":10,"y":22,"z":3},{"name":"Plant_Seaweed_Moss_Stack","x":10,"y":23,"z":3},{"name":"Plant_Coral_Block_White","x":10,"y":13,"z":4},{"name":"Plant_Coral_Block_White","x":10,"y":14,"z":4},{"name":"Plant_Coral_Block_White","x":10,"y":15,"z":4},{"name":"Plant_Seaweed_Grass_Tall","x":10,"y":16,"z":4},{"filler":1024,"name":"Plant_Seaweed_Grass_Tall","x":10,"y":17,"z":4},{"name":"Plant_Coral_Block_White","x":10,"y":14,"z":5},{"name":"Plant_Seaweed_Moss_Stack","x":10,"y":15,"z":5},{"name":"Plant_Seaweed_Moss_Stack","x":10,"y":16,"z":5},{"name":"Plant_Seaweed_Moss_Stack","x":10,"y":17,"z":5},{"name":"Plant_Seaweed_Moss_Stack","x":10,"y":18,"z":5},{"name":"Wood_Spiral_Trunk_Full","x":10,"y":0,"z":6},{"name":"Wood_Spiral_Trunk_Full","x":10,"y":1,"z":6},{"name":"Wood_Spiral_Trunk_Full","x":10,"y":2,"z":6},{"name":"Wood_Spiral_Trunk_Full","x":10,"y":3,"z":6},{"name":"Wood_Spiral_Trunk_Full","x":10,"y":4,"z":6},{"name":"Wood_Spiral_Trunk_Full","x":10,"y":5,"z":6},{"name":"Wood_Spiral_Trunk_Full","x":10,"y":6,"z":6},{"name":"Wood_Spiral_Trunk_Full","x":10,"y":7,"z":6},{"name":"Plant_Coral_Block_White","x":10,"y":13,"z":6},{"name":"Plant_Coral_Block_White","x":10,"y":14,"z":6},{"name":"Plant_Seaweed_Grass_Tall","x":10,"y":15,"z":6},{"filler":1024,"name":"Plant_Seaweed_Grass_Tall","x":10,"y":16,"z":6},{"name":"Wood_Spiral_Trunk_Full","x":10,"y":0,"z":7},{"name":"Wood_Spiral_Trunk_Full","x":10,"y":1,"z":7},{"name":"Wood_Spiral_Trunk_Full","x":10,"y":2,"z":7},{"name":"Wood_Spiral_Trunk_Full","x":10,"y":3,"z":7},{"name":"Wood_Spiral_Trunk_Full","x":10,"y":4,"z":7},{"name":"Wood_Spiral_Trunk_Full","x":10,"y":5,"z":7},{"name":"Wood_Spiral_Trunk_Full","x":10,"y":6,"z":7},{"name":"Wood_Spiral_Trunk_Full","x":10,"y":7,"z":7},{"name":"Plant_Coral_Block_White","x":10,"y":10,"z":7},{"name":"Plant_Coral_Block_White","x":10,"y":11,"z":7},{"name":"Plant_Coral_Block_White","x":10,"y":12,"z":7},{"name":"Plant_Coral_Block_White","x":10,"y":13,"z":7},{"name":"Plant_Seaweed_Moss_Stack","x":10,"y":14,"z":7},{"name":"Plant_Seaweed_Moss_Stack","x":10,"y":15,"z":7},{"name":"Plant_Seaweed_Moss_Stack","x":10,"y":16,"z":7},{"name":"Wood_Spiral_Trunk_Full","x":10,"y":5,"z":8},{"name":"Wood_Spiral_Trunk_Full","x":10,"y":6,"z":8},{"name":"Wood_Spiral_Trunk_Full","x":10,"y":10,"z":8},{"name":"Plant_Coral_Block_White","x":10,"y":11,"z":8},{"name":"Plant_Seaweed_Grass_Tall","x":10,"y":12,"z":8},{"filler":1024,"name":"Plant_Seaweed_Grass_Tall","x":10,"y":13,"z":8},{"name":"Wood_Spiral_Trunk_Full","x":10,"y":10,"z":9},{"name":"Plant_Coral_Block_White","x":10,"y":11,"z":10},{"name":"Plant_Coral_Block_White","x":10,"y":12,"z":10},{"name":"Plant_Coral_Block_White","x":10,"y":13,"z":10},{"name":"Plant_Seaweed_Grass","x":10,"y":14,"z":10},{"name":"Plant_Coral_Block_White","x":10,"y":10,"z":11},{"name":"Plant_Seaweed_Moss_Stack","x":10,"y":11,"z":11},{"name":"Plant_Seaweed_Moss_Stack","x":10,"y":12,"z":11},{"name":"Plant_Seaweed_Moss_Stack","x":10,"y":13,"z":11},{"name":"Plant_Seaweed_Moss_Stack","x":10,"y":14,"z":11},{"name":"Plant_Seaweed_Moss_Stack","x":10,"y":15,"z":11},{"name":"Plant_Seaweed_Moss_Stack","x":10,"y":16,"z":11},{"name":"Plant_Seaweed_Moss_Stack","x":10,"y":17,"z":11},{"name":"Plant_Seaweed_Moss_Stack","x":10,"y":18,"z":11},{"name":"Plant_Coral_Block_White","x":10,"y":12,"z":12},{"name":"Plant_Coral_Block_White","x":10,"y":13,"z":12},{"name":"Plant_Seaweed_Moss_Stack","x":10,"y":14,"z":12},{"name":"Plant_Seaweed_Moss_Stack","x":10,"y":15,"z":12},{"name":"Plant_Coral_Block_White","x":11,"y":13,"z":-2},{"name":"Plant_Coral_Block_White","x":11,"y":14,"z":-2},{"name":"Plant_Seaweed_Grass_Tall","x":11,"y":15,"z":-2},{"filler":1024,"name":"Plant_Seaweed_Grass_Tall","x":11,"y":16,"z":-2},{"name":"Plant_Coral_Block_White","x":11,"y":12,"z":0},{"name":"Plant_Seaweed_Grass_Tall","x":11,"y":13,"z":0},{"filler":1024,"name":"Plant_Seaweed_Grass_Tall","x":11,"y":14,"z":0},{"name":"Plant_Coral_Block_White","x":11,"y":11,"z":1},{"name":"Plant_Seaweed_Moss_Stack","x":11,"y":12,"z":1},{"name":"Plant_Seaweed_Moss_Stack","x":11,"y":13,"z":1},{"name":"Plant_Seaweed_Moss_Stack","x":11,"y":14,"z":1},{"name":"Plant_Seaweed_Moss_Stack","x":11,"y":15,"z":1},{"name":"Plant_Seaweed_Moss_Stack","x":11,"y":16,"z":1},{"name":"Plant_Seaweed_Moss_Stack","x":11,"y":17,"z":1},{"name":"Plant_Seaweed_Moss_Stack","x":11,"y":18,"z":1},{"name":"Plant_Seaweed_Moss_Stack","x":11,"y":19,"z":1},{"name":"Plant_Seaweed_Moss_Stack","x":11,"y":20,"z":1},{"name":"Wood_Spiral_Trunk_Full","x":11,"y":11,"z":2},{"name":"Plant_Coral_Block_White","x":11,"y":12,"z":2},{"name":"Plant_Seaweed_Moss_Stack","x":11,"y":13,"z":2},{"name":"Plant_Seaweed_Moss_Stack","x":11,"y":14,"z":2},{"name":"Plant_Seaweed_Moss_Stack","x":11,"y":15,"z":2},{"name":"Plant_Seaweed_Moss_Stack","x":11,"y":16,"z":2},{"name":"Plant_Seaweed_Moss_Stack","x":11,"y":17,"z":2},{"name":"Plant_Seaweed_Moss_Stack","x":11,"y":18,"z":2},{"name":"Wood_Spiral_Trunk_Full","x":11,"y":10,"z":3},{"name":"Wood_Spiral_Trunk_Full","x":11,"y":11,"z":3},{"name":"Plant_Coral_Block_White","x":11,"y":12,"z":3},{"name":"Plant_Coral_Block_White","x":11,"y":13,"z":3},{"name":"Plant_Seaweed_Grass","x":11,"y":14,"z":3},{"name":"Plant_Coral_Block_White","x":11,"y":13,"z":4},{"name":"Plant_Seaweed_Grass","x":11,"y":14,"z":4},{"name":"Plant_Coral_Block_White","x":11,"y":12,"z":6},{"name":"Plant_Coral_Block_White","x":11,"y":13,"z":6},{"name":"Plant_Seaweed_Moss_Stack","x":11,"y":14,"z":6},{"name":"Plant_Seaweed_Moss_Stack","x":11,"y":15,"z":6},{"name":"Plant_Seaweed_Moss_Stack","x":11,"y":16,"z":6},{"name":"Wood_Spiral_Trunk_Full","x":11,"y":0,"z":7},{"name":"Wood_Spiral_Trunk_Full","x":11,"y":1,"z":7},{"name":"Wood_Spiral_Trunk_Full","x":11,"y":2,"z":7},{"name":"Wood_Spiral_Trunk_Full","x":11,"y":3,"z":7},{"name":"Wood_Spiral_Trunk_Full","x":11,"y":4,"z":7},{"name":"Wood_Spiral_Trunk_Full","x":11,"y":5,"z":7},{"name":"Wood_Spiral_Trunk_Full","x":11,"y":6,"z":7},{"name":"Plant_Coral_Block_White","x":11,"y":12,"z":7},{"name":"Plant_Seaweed_Moss_Stack","x":11,"y":13,"z":7},{"name":"Wood_Spiral_Trunk_Full","x":11,"y":0,"z":8},{"name":"Wood_Spiral_Trunk_Full","x":11,"y":1,"z":8},{"name":"Wood_Spiral_Trunk_Full","x":11,"y":2,"z":8},{"name":"Wood_Spiral_Trunk_Full","x":11,"y":3,"z":8},{"name":"Wood_Spiral_Trunk_Full","x":11,"y":4,"z":8},{"name":"Wood_Spiral_Trunk_Full","x":11,"y":5,"z":8},{"name":"Plant_Coral_Block_White","x":11,"y":11,"z":8},{"name":"Plant_Seaweed_Moss_Stack","x":11,"y":12,"z":8},{"name":"Plant_Seaweed_Moss_Stack","x":11,"y":13,"z":8},{"name":"Plant_Seaweed_Moss_Stack","x":11,"y":14,"z":8},{"name":"Plant_Seaweed_Moss_Stack","x":11,"y":15,"z":8},{"name":"Plant_Seaweed_Moss_Stack","x":11,"y":16,"z":8},{"name":"Plant_Seaweed_Moss_Stack","x":11,"y":17,"z":8},{"name":"Plant_Seaweed_Moss_Stack","x":11,"y":18,"z":8},{"name":"Plant_Seaweed_Moss_Stack","x":11,"y":19,"z":8},{"name":"Plant_Seaweed_Moss_Stack","x":11,"y":20,"z":8},{"name":"Plant_Seaweed_Moss_Stack","x":11,"y":21,"z":8},{"name":"Plant_Seaweed_Moss_Stack","x":11,"y":22,"z":8},{"name":"Plant_Seaweed_Moss_Stack","x":11,"y":23,"z":8},{"name":"Plant_Seaweed_Moss_Stack","x":11,"y":24,"z":8},{"name":"Plant_Seaweed_Moss_Stack","x":11,"y":25,"z":8},{"name":"Wood_Spiral_Trunk_Full","x":11,"y":10,"z":9},{"name":"Wood_Spiral_Trunk_Full","x":11,"y":11,"z":9},{"name":"Plant_Coral_Block_White","x":11,"y":13,"z":9},{"name":"Plant_Coral_Block_White","x":11,"y":14,"z":9},{"name":"Plant_Seaweed_Moss_Stack","x":11,"y":15,"z":9},{"name":"Plant_Seaweed_Moss_Stack","x":11,"y":16,"z":9},{"name":"Plant_Seaweed_Moss_Stack","x":11,"y":17,"z":9},{"name":"Plant_Seaweed_Moss_Stack","x":11,"y":18,"z":9},{"name":"Plant_Seaweed_Moss_Stack","x":11,"y":19,"z":9},{"name":"Plant_Seaweed_Moss_Stack","x":11,"y":20,"z":9},{"name":"Plant_Seaweed_Moss_Stack","x":11,"y":21,"z":9},{"name":"Plant_Seaweed_Moss_Stack","x":11,"y":22,"z":9},{"name":"Plant_Seaweed_Moss_Stack","x":11,"y":23,"z":9},{"name":"Plant_Seaweed_Moss_Stack","x":11,"y":24,"z":9},{"name":"Plant_Seaweed_Moss_Stack","x":11,"y":25,"z":9},{"name":"Plant_Coral_Block_White","x":11,"y":11,"z":10},{"name":"Plant_Seaweed_Grass","x":11,"y":12,"z":10},{"name":"Plant_Coral_Block_White","x":11,"y":11,"z":11},{"name":"Plant_Coral_Block_White","x":11,"y":12,"z":11},{"name":"Plant_Seaweed_Moss_Stack","x":11,"y":13,"z":11},{"name":"Plant_Seaweed_Moss_Stack","x":11,"y":14,"z":11},{"name":"Plant_Seaweed_Moss_Stack","x":11,"y":15,"z":11},{"name":"Plant_Seaweed_Moss_Stack","x":11,"y":16,"z":11},{"name":"Plant_Seaweed_Moss_Stack","x":11,"y":17,"z":11},{"name":"Plant_Seaweed_Moss_Stack","x":11,"y":18,"z":11},{"name":"Plant_Seaweed_Moss_Stack","x":11,"y":19,"z":11},{"name":"Plant_Seaweed_Moss_Stack","x":11,"y":20,"z":11},{"name":"Plant_Seaweed_Moss_Stack","x":11,"y":21,"z":11},{"name":"Plant_Seaweed_Moss_Stack","x":11,"y":22,"z":11},{"name":"Plant_Seaweed_Moss_Stack","x":11,"y":23,"z":11},{"name":"Plant_Seaweed_Moss_Stack","x":11,"y":24,"z":11},{"name":"Plant_Seaweed_Moss_Stack","x":11,"y":25,"z":11},{"name":"Plant_Seaweed_Moss_Stack","x":11,"y":26,"z":11},{"name":"Plant_Coral_Block_White","x":11,"y":12,"z":12},{"name":"Plant_Seaweed_Grass_Tall","x":11,"y":13,"z":12},{"filler":1024,"name":"Plant_Seaweed_Grass_Tall","x":11,"y":14,"z":12},{"name":"Plant_Coral_Block_White","x":12,"y":11,"z":-2},{"name":"Plant_Seaweed_Moss_Stack","x":12,"y":12,"z":-2},{"name":"Plant_Seaweed_Moss_Stack","x":12,"y":13,"z":-2},{"name":"Plant_Seaweed_Moss_Stack","x":12,"y":14,"z":-2},{"name":"Plant_Seaweed_Moss_Stack","x":12,"y":15,"z":-2},{"name":"Plant_Seaweed_Moss_Stack","x":12,"y":16,"z":-2},{"name":"Plant_Seaweed_Moss_Stack","x":12,"y":17,"z":-2},{"name":"Plant_Coral_Block_White","x":12,"y":12,"z":-1},{"name":"Plant_Coral_Block_White","x":12,"y":13,"z":-1},{"name":"Plant_Coral_Block_White","x":12,"y":14,"z":-1},{"name":"Plant_Coral_Block_White","x":12,"y":15,"z":-1},{"name":"Plant_Seaweed_Moss_Stack","x":12,"y":16,"z":-1},{"name":"Plant_Seaweed_Moss_Stack","x":12,"y":17,"z":-1},{"name":"Plant_Seaweed_Moss_Stack","x":12,"y":18,"z":-1},{"name":"Plant_Seaweed_Moss_Stack","x":12,"y":19,"z":-1},{"name":"Plant_Coral_Block_White","x":12,"y":11,"z":0},{"name":"Plant_Coral_Block_White","x":12,"y":12,"z":0},{"name":"Plant_Seaweed_Grass_Tall","x":12,"y":13,"z":0},{"filler":1024,"name":"Plant_Seaweed_Grass_Tall","x":12,"y":14,"z":0},{"name":"Wood_Spiral_Trunk_Full","x":12,"y":11,"z":1},{"name":"Wood_Spiral_Trunk_Full","x":12,"y":12,"z":1},{"name":"Plant_Coral_Block_White","x":12,"y":13,"z":1},{"name":"Plant_Coral_Block_White","x":12,"y":14,"z":1},{"name":"Plant_Seaweed_Moss_Stack","x":12,"y":15,"z":1},{"name":"Plant_Seaweed_Moss_Stack","x":12,"y":16,"z":1},{"name":"Plant_Seaweed_Moss_Stack","x":12,"y":17,"z":1},{"name":"Plant_Seaweed_Moss_Stack","x":12,"y":18,"z":1},{"name":"Plant_Seaweed_Moss_Stack","x":12,"y":19,"z":1},{"name":"Plant_Seaweed_Moss_Stack","x":12,"y":20,"z":1},{"name":"Plant_Seaweed_Moss_Stack","x":12,"y":21,"z":1},{"name":"Wood_Spiral_Trunk_Full","x":12,"y":11,"z":2},{"name":"Plant_Coral_Block_White","x":12,"y":12,"z":2},{"name":"Plant_Seaweed_Grass_Tall","x":12,"y":13,"z":2},{"filler":1024,"name":"Plant_Seaweed_Grass_Tall","x":12,"y":14,"z":2},{"name":"Plant_Coral_Block_White","x":12,"y":11,"z":3},{"name":"Plant_Seaweed_Moss_Stack","x":12,"y":12,"z":3},{"name":"Plant_Seaweed_Moss_Stack","x":12,"y":13,"z":3},{"name":"Plant_Seaweed_Moss_Stack","x":12,"y":14,"z":3},{"name":"Plant_Seaweed_Moss_Stack","x":12,"y":15,"z":3},{"name":"Plant_Seaweed_Moss_Stack","x":12,"y":16,"z":3},{"name":"Plant_Seaweed_Moss_Stack","x":12,"y":17,"z":3},{"name":"Plant_Seaweed_Moss_Stack","x":12,"y":18,"z":3},{"name":"Plant_Seaweed_Moss_Stack","x":12,"y":19,"z":3},{"name":"Plant_Seaweed_Moss_Stack","x":12,"y":20,"z":3},{"name":"Plant_Seaweed_Moss_Stack","x":12,"y":21,"z":3},{"name":"Plant_Seaweed_Moss_Stack","x":12,"y":22,"z":3},{"name":"Plant_Seaweed_Moss_Stack","x":12,"y":23,"z":3},{"name":"Plant_Coral_Block_White","x":12,"y":10,"z":6},{"name":"Plant_Seaweed_Moss_Stack","x":12,"y":11,"z":6},{"name":"Plant_Seaweed_Moss_Stack","x":12,"y":12,"z":6},{"name":"Plant_Seaweed_Moss_Stack","x":12,"y":13,"z":6},{"name":"Plant_Seaweed_Moss_Stack","x":12,"y":14,"z":6},{"name":"Plant_Seaweed_Moss_Stack","x":12,"y":15,"z":6},{"name":"Plant_Seaweed_Moss_Stack","x":12,"y":16,"z":6},{"name":"Plant_Seaweed_Moss_Stack","x":12,"y":17,"z":6},{"name":"Plant_Seaweed_Moss_Stack","x":12,"y":18,"z":6},{"name":"Plant_Seaweed_Moss_Stack","x":12,"y":19,"z":6},{"name":"Plant_Seaweed_Moss_Stack","x":12,"y":20,"z":6},{"name":"Plant_Seaweed_Moss_Stack","x":12,"y":21,"z":6},{"name":"Plant_Seaweed_Moss_Stack","x":12,"y":22,"z":6},{"name":"Plant_Seaweed_Moss_Stack","x":12,"y":23,"z":6},{"name":"Plant_Seaweed_Moss_Stack","x":12,"y":24,"z":6},{"name":"Wood_Spiral_Trunk_Full","x":12,"y":0,"z":7},{"name":"Wood_Spiral_Trunk_Full","x":12,"y":1,"z":7},{"name":"Wood_Spiral_Trunk_Full","x":12,"y":2,"z":7},{"name":"Wood_Spiral_Trunk_Full","x":12,"y":3,"z":7},{"name":"Wood_Spiral_Trunk_Full","x":12,"y":4,"z":7},{"name":"Plant_Coral_Block_White","x":12,"y":11,"z":7},{"name":"Plant_Coral_Block_White","x":12,"y":12,"z":7},{"name":"Plant_Coral_Block_White","x":12,"y":13,"z":7},{"name":"Plant_Coral_Block_White","x":12,"y":14,"z":7},{"name":"Plant_Seaweed_Grass_Tall","x":12,"y":15,"z":7},{"filler":1024,"name":"Plant_Seaweed_Grass_Tall","x":12,"y":16,"z":7},{"name":"Wood_Spiral_Trunk_Full","x":12,"y":0,"z":8},{"name":"Wood_Spiral_Trunk_Full","x":12,"y":1,"z":8},{"name":"Wood_Spiral_Trunk_Full","x":12,"y":2,"z":8},{"name":"Wood_Spiral_Trunk_Full","x":12,"y":3,"z":8},{"name":"Plant_Coral_Block_White","x":12,"y":10,"z":8},{"name":"Plant_Coral_Block_White","x":12,"y":11,"z":8},{"name":"Plant_Seaweed_Moss_Stack","x":12,"y":12,"z":8},{"name":"Plant_Seaweed_Moss_Stack","x":12,"y":13,"z":8},{"name":"Plant_Coral_Block_White","x":12,"y":10,"z":9},{"name":"Wood_Spiral_Trunk_Full","x":12,"y":11,"z":9},{"name":"Plant_Coral_Block_White","x":12,"y":12,"z":9},{"name":"Plant_Coral_Block_White","x":12,"y":13,"z":9},{"name":"Plant_Seaweed_Grass","x":12,"y":14,"z":9},{"name":"Plant_Coral_Block_White","x":12,"y":11,"z":10},{"name":"Plant_Seaweed_Grass","x":12,"y":12,"z":10},{"name":"Plant_Coral_Block_White","x":12,"y":10,"z":11},{"name":"Plant_Seaweed_Moss_Stack","x":12,"y":11,"z":11},{"name":"Plant_Seaweed_Moss_Stack","x":12,"y":12,"z":11},{"name":"Plant_Seaweed_Moss_Stack","x":12,"y":13,"z":11},{"name":"Plant_Seaweed_Moss_Stack","x":12,"y":14,"z":11},{"name":"Plant_Seaweed_Moss_Stack","x":12,"y":15,"z":11},{"name":"Plant_Seaweed_Moss_Stack","x":12,"y":16,"z":11},{"name":"Plant_Seaweed_Moss_Stack","x":12,"y":17,"z":11},{"name":"Plant_Seaweed_Moss_Stack","x":12,"y":18,"z":11},{"name":"Plant_Seaweed_Moss_Stack","x":12,"y":19,"z":11},{"name":"Plant_Seaweed_Moss_Stack","x":12,"y":20,"z":11},{"name":"Plant_Seaweed_Moss_Stack","x":12,"y":21,"z":11},{"name":"Plant_Seaweed_Moss_Stack","x":12,"y":22,"z":11},{"name":"Plant_Seaweed_Moss_Stack","x":12,"y":23,"z":11},{"name":"Plant_Seaweed_Moss_Stack","x":12,"y":24,"z":11},{"name":"Plant_Coral_Block_White","x":13,"y":12,"z":-1},{"name":"Plant_Seaweed_Grass","x":13,"y":13,"z":-1},{"name":"Plant_Coral_Block_White","x":13,"y":12,"z":0},{"name":"Plant_Coral_Block_White","x":13,"y":13,"z":0},{"name":"Plant_Seaweed_Moss_Stack","x":13,"y":14,"z":0},{"name":"Plant_Seaweed_Moss_Stack","x":13,"y":15,"z":0},{"name":"Plant_Seaweed_Moss_Stack","x":13,"y":16,"z":0},{"name":"Plant_Seaweed_Moss_Stack","x":13,"y":17,"z":0},{"name":"Plant_Seaweed_Moss_Stack","x":13,"y":18,"z":0},{"name":"Plant_Seaweed_Moss_Stack","x":13,"y":19,"z":0},{"name":"Plant_Seaweed_Moss_Stack","x":13,"y":20,"z":0},{"name":"Plant_Seaweed_Moss_Stack","x":13,"y":21,"z":0},{"name":"Plant_Seaweed_Moss_Stack","x":13,"y":22,"z":0},{"name":"Plant_Seaweed_Moss_Stack","x":13,"y":23,"z":0},{"name":"Plant_Seaweed_Moss_Stack","x":13,"y":24,"z":0},{"name":"Plant_Seaweed_Moss_Stack","x":13,"y":25,"z":0},{"name":"Plant_Seaweed_Moss_Stack","x":13,"y":26,"z":0},{"name":"Plant_Seaweed_Moss_Stack","x":13,"y":27,"z":0},{"name":"Plant_Coral_Block_White","x":13,"y":12,"z":1},{"name":"Plant_Seaweed_Moss_Stack","x":13,"y":13,"z":1},{"name":"Plant_Seaweed_Moss_Stack","x":13,"y":14,"z":1},{"name":"Plant_Seaweed_Moss_Stack","x":13,"y":15,"z":1},{"name":"Plant_Seaweed_Moss_Stack","x":13,"y":16,"z":1},{"name":"Plant_Seaweed_Moss_Stack","x":13,"y":17,"z":1},{"name":"Plant_Seaweed_Moss_Stack","x":13,"y":18,"z":1},{"name":"Plant_Seaweed_Moss_Stack","x":13,"y":19,"z":1},{"name":"Plant_Coral_Block_White","x":13,"y":12,"z":2},{"name":"Plant_Coral_Block_White","x":13,"y":13,"z":2},{"name":"Plant_Seaweed_Moss_Stack","x":13,"y":14,"z":2},{"name":"Plant_Seaweed_Moss_Stack","x":13,"y":15,"z":2},{"name":"Plant_Seaweed_Moss_Stack","x":13,"y":16,"z":2},{"name":"Plant_Seaweed_Moss_Stack","x":13,"y":17,"z":2},{"name":"Plant_Seaweed_Moss_Stack","x":13,"y":18,"z":2},{"name":"Plant_Seaweed_Moss_Stack","x":13,"y":19,"z":2},{"name":"Plant_Seaweed_Moss_Stack","x":13,"y":20,"z":2},{"name":"Plant_Seaweed_Moss_Stack","x":13,"y":21,"z":2},{"name":"Plant_Seaweed_Moss_Stack","x":13,"y":22,"z":2},{"name":"Plant_Seaweed_Moss_Stack","x":13,"y":23,"z":2},{"name":"Plant_Coral_Block_White","x":13,"y":13,"z":3},{"name":"Plant_Coral_Block_White","x":13,"y":14,"z":3},{"name":"Plant_Seaweed_Grass","x":13,"y":15,"z":3},{"name":"Plant_Coral_Block_White","x":13,"y":11,"z":7},{"name":"Plant_Seaweed_Moss_Stack","x":13,"y":12,"z":7},{"name":"Plant_Seaweed_Moss_Stack","x":13,"y":13,"z":7},{"name":"Plant_Seaweed_Moss_Stack","x":13,"y":14,"z":7},{"name":"Plant_Seaweed_Moss_Stack","x":13,"y":15,"z":7},{"name":"Plant_Coral_Block_White","x":13,"y":11,"z":8},{"name":"Plant_Coral_Block_White","x":13,"y":12,"z":8},{"name":"Plant_Seaweed_Grass_Tall","x":13,"y":13,"z":8},{"filler":1024,"name":"Plant_Seaweed_Grass_Tall","x":13,"y":14,"z":8},{"name":"Plant_Coral_Block_White","x":13,"y":11,"z":9},{"name":"Plant_Seaweed_Grass","x":13,"y":12,"z":9},{"name":"Plant_Coral_Block_White","x":13,"y":11,"z":10},{"name":"Plant_Coral_Block_White","x":13,"y":12,"z":10},{"name":"Plant_Seaweed_Grass_Tall","x":13,"y":13,"z":10},{"filler":1024,"name":"Plant_Seaweed_Grass_Tall","x":13,"y":14,"z":10},{"name":"Plant_Coral_Block_White","x":13,"y":12,"z":11},{"name":"Plant_Coral_Block_White","x":13,"y":13,"z":11},{"name":"Plant_Seaweed_Moss_Stack","x":13,"y":14,"z":11},{"name":"Plant_Seaweed_Moss_Stack","x":13,"y":15,"z":11},{"name":"Plant_Seaweed_Moss_Stack","x":13,"y":16,"z":11},{"name":"Plant_Seaweed_Moss_Stack","x":13,"y":17,"z":11},{"name":"Plant_Seaweed_Moss_Stack","x":13,"y":18,"z":11},{"name":"Plant_Seaweed_Moss_Stack","x":13,"y":19,"z":11},{"name":"Plant_Seaweed_Moss_Stack","x":13,"y":20,"z":11},{"name":"Plant_Seaweed_Moss_Stack","x":13,"y":21,"z":11},{"name":"Plant_Seaweed_Moss_Stack","x":13,"y":22,"z":11},{"name":"Plant_Seaweed_Moss_Stack","x":13,"y":23,"z":11},{"name":"Plant_Seaweed_Moss_Stack","x":13,"y":24,"z":11},{"name":"Plant_Seaweed_Moss_Stack","x":13,"y":25,"z":11},{"name":"Plant_Seaweed_Moss_Stack","x":13,"y":26,"z":11},{"name":"Plant_Seaweed_Moss_Stack","x":13,"y":27,"z":11},{"name":"Plant_Coral_Block_White","x":14,"y":14,"z":-2},{"name":"Plant_Seaweed_Grass","x":14,"y":15,"z":-2},{"name":"Plant_Coral_Block_White","x":14,"y":13,"z":-1},{"name":"Plant_Coral_Block_White","x":14,"y":14,"z":-1},{"name":"Plant_Seaweed_Moss_Stack","x":14,"y":15,"z":-1},{"name":"Plant_Seaweed_Moss_Stack","x":14,"y":16,"z":-1},{"name":"Plant_Seaweed_Moss_Stack","x":14,"y":17,"z":-1},{"name":"Plant_Seaweed_Moss_Stack","x":14,"y":18,"z":-1},{"name":"Plant_Seaweed_Moss_Stack","x":14,"y":19,"z":-1},{"name":"Plant_Seaweed_Moss_Stack","x":14,"y":20,"z":-1},{"name":"Plant_Seaweed_Moss_Stack","x":14,"y":21,"z":-1},{"name":"Plant_Seaweed_Moss_Stack","x":14,"y":22,"z":-1},{"name":"Plant_Coral_Block_White","x":14,"y":12,"z":0},{"name":"Plant_Coral_Block_White","x":14,"y":13,"z":0},{"name":"Plant_Seaweed_Moss_Stack","x":14,"y":14,"z":0},{"name":"Plant_Seaweed_Moss_Stack","x":14,"y":15,"z":0},{"name":"Plant_Coral_Block_White","x":14,"y":14,"z":1},{"name":"Plant_Seaweed_Moss_Stack","x":14,"y":15,"z":1},{"name":"Plant_Seaweed_Moss_Stack","x":14,"y":16,"z":1},{"name":"Plant_Seaweed_Moss_Stack","x":14,"y":17,"z":1},{"name":"Plant_Seaweed_Moss_Stack","x":14,"y":18,"z":1},{"name":"Plant_Seaweed_Moss_Stack","x":14,"y":19,"z":1},{"name":"Plant_Seaweed_Moss_Stack","x":14,"y":20,"z":1},{"name":"Plant_Seaweed_Moss_Stack","x":14,"y":21,"z":1},{"name":"Plant_Seaweed_Moss_Stack","x":14,"y":22,"z":1},{"name":"Plant_Seaweed_Moss_Stack","x":14,"y":23,"z":1},{"name":"Plant_Seaweed_Moss_Stack","x":14,"y":24,"z":1},{"name":"Plant_Seaweed_Moss_Stack","x":14,"y":25,"z":1},{"name":"Plant_Seaweed_Moss_Stack","x":14,"y":26,"z":1},{"name":"Plant_Seaweed_Moss_Stack","x":14,"y":27,"z":1},{"name":"Plant_Seaweed_Moss_Stack","x":14,"y":28,"z":1},{"name":"Plant_Seaweed_Moss_Stack","x":14,"y":29,"z":1},{"name":"Plant_Seaweed_Moss_Stack","x":14,"y":30,"z":1},{"name":"Plant_Coral_Block_White","x":14,"y":13,"z":3},{"name":"Plant_Seaweed_Moss_Stack","x":14,"y":14,"z":3},{"name":"Plant_Seaweed_Moss_Stack","x":14,"y":15,"z":3},{"name":"Plant_Seaweed_Moss_Stack","x":14,"y":16,"z":3},{"name":"Plant_Seaweed_Moss_Stack","x":14,"y":17,"z":3},{"name":"Plant_Seaweed_Moss_Stack","x":14,"y":18,"z":3},{"name":"Plant_Seaweed_Moss_Stack","x":14,"y":19,"z":3},{"name":"Plant_Seaweed_Moss_Stack","x":14,"y":20,"z":3},{"name":"Plant_Seaweed_Moss_Stack","x":14,"y":21,"z":3},{"name":"Plant_Seaweed_Moss_Stack","x":14,"y":22,"z":3},{"name":"Plant_Seaweed_Moss_Stack","x":14,"y":23,"z":3},{"name":"Plant_Seaweed_Moss_Stack","x":14,"y":24,"z":3},{"name":"Plant_Seaweed_Moss_Stack","x":14,"y":25,"z":3},{"name":"Plant_Seaweed_Moss_Stack","x":14,"y":26,"z":3},{"name":"Plant_Seaweed_Moss_Stack","x":14,"y":27,"z":3},{"name":"Plant_Seaweed_Moss_Stack","x":14,"y":28,"z":3},{"name":"Plant_Seaweed_Moss_Stack","x":14,"y":29,"z":3},{"name":"Plant_Seaweed_Moss_Stack","x":14,"y":30,"z":3},{"name":"Plant_Seaweed_Moss_Stack","x":14,"y":31,"z":3},{"name":"Plant_Seaweed_Moss_Stack","x":14,"y":32,"z":3},{"name":"Plant_Seaweed_Moss_Stack","x":14,"y":33,"z":3},{"name":"Plant_Coral_Block_White","x":14,"y":13,"z":4},{"name":"Plant_Seaweed_Moss_Stack","x":14,"y":14,"z":4},{"name":"Plant_Seaweed_Moss_Stack","x":14,"y":15,"z":4},{"name":"Plant_Coral_Block_White","x":14,"y":13,"z":6},{"name":"Plant_Seaweed_Moss_Stack","x":14,"y":14,"z":6},{"name":"Plant_Seaweed_Moss_Stack","x":14,"y":15,"z":6},{"name":"Plant_Seaweed_Moss_Stack","x":14,"y":16,"z":6},{"name":"Plant_Seaweed_Moss_Stack","x":14,"y":17,"z":6},{"name":"Plant_Seaweed_Moss_Stack","x":14,"y":18,"z":6},{"name":"Plant_Seaweed_Moss_Stack","x":14,"y":19,"z":6},{"name":"Plant_Seaweed_Moss_Stack","x":14,"y":20,"z":6},{"name":"Plant_Seaweed_Moss_Stack","x":14,"y":21,"z":6},{"name":"Plant_Seaweed_Moss_Stack","x":14,"y":22,"z":6},{"name":"Plant_Seaweed_Moss_Stack","x":14,"y":23,"z":6},{"name":"Plant_Seaweed_Moss_Stack","x":14,"y":24,"z":6},{"name":"Plant_Coral_Block_White","x":14,"y":12,"z":7},{"name":"Plant_Coral_Block_White","x":14,"y":13,"z":7},{"name":"Plant_Seaweed_Moss_Stack","x":14,"y":14,"z":7},{"name":"Plant_Seaweed_Moss_Stack","x":14,"y":15,"z":7},{"name":"Plant_Seaweed_Moss_Stack","x":14,"y":16,"z":7},{"name":"Plant_Seaweed_Moss_Stack","x":14,"y":17,"z":7},{"name":"Plant_Seaweed_Moss_Stack","x":14,"y":18,"z":7},{"name":"Plant_Seaweed_Moss_Stack","x":14,"y":19,"z":7},{"name":"Plant_Seaweed_Moss_Stack","x":14,"y":20,"z":7},{"name":"Plant_Seaweed_Moss_Stack","x":14,"y":21,"z":7},{"name":"Plant_Seaweed_Moss_Stack","x":14,"y":22,"z":7},{"name":"Plant_Seaweed_Moss_Stack","x":14,"y":23,"z":7},{"name":"Plant_Seaweed_Moss_Stack","x":14,"y":24,"z":7},{"name":"Plant_Seaweed_Moss_Stack","x":14,"y":25,"z":7},{"name":"Plant_Seaweed_Moss_Stack","x":14,"y":26,"z":7},{"name":"Plant_Seaweed_Moss_Stack","x":14,"y":27,"z":7},{"name":"Plant_Coral_Block_White","x":14,"y":11,"z":8},{"name":"Plant_Coral_Block_White","x":14,"y":12,"z":8},{"name":"Plant_Seaweed_Grass_Tall","x":14,"y":13,"z":8},{"filler":1024,"name":"Plant_Seaweed_Grass_Tall","x":14,"y":14,"z":8},{"name":"Plant_Coral_Block_White","x":14,"y":13,"z":9},{"name":"Plant_Seaweed_Moss_Stack","x":14,"y":14,"z":9},{"name":"Plant_Seaweed_Moss_Stack","x":14,"y":15,"z":9},{"name":"Plant_Seaweed_Moss_Stack","x":14,"y":16,"z":9},{"name":"Plant_Coral_Block_White","x":14,"y":12,"z":11},{"name":"Plant_Seaweed_Grass","x":14,"y":13,"z":11},{"name":"Plant_Coral_Block_White","x":14,"y":12,"z":12},{"name":"Plant_Seaweed_Moss_Stack","x":14,"y":13,"z":12},{"name":"Plant_Seaweed_Moss_Stack","x":14,"y":14,"z":12},{"name":"Plant_Seaweed_Moss_Stack","x":14,"y":15,"z":12},{"name":"Plant_Seaweed_Moss_Stack","x":14,"y":16,"z":12},{"name":"Plant_Seaweed_Moss_Stack","x":14,"y":17,"z":12},{"name":"Plant_Seaweed_Moss_Stack","x":14,"y":18,"z":12},{"name":"Plant_Seaweed_Moss_Stack","x":14,"y":19,"z":12},{"name":"Plant_Coral_Block_White","x":15,"y":12,"z":0},{"name":"Plant_Seaweed_Grass_Tall","x":15,"y":13,"z":0},{"filler":1024,"name":"Plant_Seaweed_Grass_Tall","x":15,"y":14,"z":0},{"name":"Plant_Coral_Block_White","x":15,"y":14,"z":1},{"name":"Plant_Seaweed_Grass_Tall","x":15,"y":15,"z":1},{"filler":1024,"name":"Plant_Seaweed_Grass_Tall","x":15,"y":16,"z":1},{"name":"Plant_Coral_Block_White","x":15,"y":11,"z":8},{"name":"Plant_Seaweed_Moss_Stack","x":15,"y":12,"z":8},{"name":"Plant_Seaweed_Moss_Stack","x":15,"y":13,"z":8},{"name":"Plant_Seaweed_Moss_Stack","x":15,"y":14,"z":8},{"name":"Plant_Seaweed_Moss_Stack","x":15,"y":15,"z":8},{"name":"Plant_Coral_Block_White","x":15,"y":13,"z":9},{"name":"Plant_Seaweed_Moss_Stack","x":15,"y":14,"z":9},{"name":"Plant_Seaweed_Moss_Stack","x":15,"y":15,"z":9}],"fluids":[{"level":1,"name":"Water_Source","x":-15,"y":13,"z":-3},{"level":1,"name":"Water_Source","x":-15,"y":14,"z":-3},{"level":1,"name":"Water_Source","x":-14,"y":13,"z":-8},{"level":1,"name":"Water_Source","x":-14,"y":14,"z":-8},{"level":1,"name":"Water_Source","x":-14,"y":15,"z":-8},{"level":1,"name":"Water_Source","x":-14,"y":16,"z":-8},{"level":1,"name":"Water_Source","x":-14,"y":17,"z":-8},{"level":1,"name":"Water_Source","x":-14,"y":18,"z":-8},{"level":1,"name":"Water_Source","x":-14,"y":19,"z":-8},{"level":1,"name":"Water_Source","x":-14,"y":20,"z":-8},{"level":1,"name":"Water_Source","x":-14,"y":21,"z":-8},{"level":1,"name":"Water_Source","x":-14,"y":22,"z":-8},{"level":1,"name":"Water_Source","x":-14,"y":12,"z":-5},{"level":1,"name":"Water_Source","x":-14,"y":13,"z":-5},{"level":1,"name":"Water_Source","x":-14,"y":14,"z":-5},{"level":1,"name":"Water_Source","x":-14,"y":12,"z":-3},{"level":1,"name":"Water_Source","x":-14,"y":13,"z":-3},{"level":1,"name":"Water_Source","x":-14,"y":14,"z":-3},{"level":1,"name":"Water_Source","x":-14,"y":12,"z":-2},{"level":1,"name":"Water_Source","x":-14,"y":13,"z":-2},{"level":1,"name":"Water_Source","x":-14,"y":14,"z":-2},{"level":1,"name":"Water_Source","x":-14,"y":15,"z":-2},{"level":1,"name":"Water_Source","x":-13,"y":12,"z":-10},{"level":1,"name":"Water_Source","x":-13,"y":13,"z":-10},{"level":1,"name":"Water_Source","x":-13,"y":14,"z":-10},{"level":1,"name":"Water_Source","x":-13,"y":15,"z":-10},{"level":1,"name":"Water_Source","x":-13,"y":16,"z":-10},{"level":1,"name":"Water_Source","x":-13,"y":17,"z":-10},{"level":1,"name":"Water_Source","x":-13,"y":18,"z":-10},{"level":1,"name":"Water_Source","x":-13,"y":19,"z":-10},{"level":1,"name":"Water_Source","x":-13,"y":20,"z":-10},{"level":1,"name":"Water_Source","x":-13,"y":21,"z":-10},{"level":1,"name":"Water_Source","x":-13,"y":22,"z":-10},{"level":1,"name":"Water_Source","x":-13,"y":23,"z":-10},{"level":1,"name":"Water_Source","x":-13,"y":24,"z":-10},{"level":1,"name":"Water_Source","x":-13,"y":25,"z":-10},{"level":1,"name":"Water_Source","x":-13,"y":26,"z":-10},{"level":1,"name":"Water_Source","x":-13,"y":12,"z":-8},{"level":1,"name":"Water_Source","x":-13,"y":13,"z":-8},{"level":1,"name":"Water_Source","x":-13,"y":14,"z":-8},{"level":1,"name":"Water_Source","x":-13,"y":12,"z":-7},{"level":1,"name":"Water_Source","x":-13,"y":13,"z":-7},{"level":1,"name":"Water_Source","x":-13,"y":14,"z":-7},{"level":1,"name":"Water_Source","x":-13,"y":10,"z":-5},{"level":1,"name":"Water_Source","x":-13,"y":11,"z":-5},{"level":1,"name":"Water_Source","x":-13,"y":12,"z":-5},{"level":1,"name":"Water_Source","x":-13,"y":13,"z":-5},{"level":1,"name":"Water_Source","x":-13,"y":14,"z":-5},{"level":1,"name":"Water_Source","x":-13,"y":15,"z":-5},{"level":1,"name":"Water_Source","x":-13,"y":16,"z":-5},{"level":1,"name":"Water_Source","x":-13,"y":17,"z":-5},{"level":1,"name":"Water_Source","x":-13,"y":18,"z":-5},{"level":1,"name":"Water_Source","x":-13,"y":19,"z":-5},{"level":1,"name":"Water_Source","x":-13,"y":20,"z":-5},{"level":1,"name":"Water_Source","x":-13,"y":21,"z":-5},{"level":1,"name":"Water_Source","x":-13,"y":22,"z":-5},{"level":1,"name":"Water_Source","x":-13,"y":23,"z":-5},{"level":1,"name":"Water_Source","x":-13,"y":24,"z":-5},{"level":1,"name":"Water_Source","x":-13,"y":25,"z":-5},{"level":1,"name":"Water_Source","x":-13,"y":26,"z":-5},{"level":1,"name":"Water_Source","x":-13,"y":27,"z":-5},{"level":1,"name":"Water_Source","x":-13,"y":28,"z":-5},{"level":1,"name":"Water_Source","x":-13,"y":29,"z":-5},{"level":1,"name":"Water_Source","x":-13,"y":30,"z":-5},{"level":1,"name":"Water_Source","x":-13,"y":31,"z":-5},{"level":1,"name":"Water_Source","x":-13,"y":32,"z":-5},{"level":1,"name":"Water_Source","x":-13,"y":33,"z":-5},{"level":1,"name":"Water_Source","x":-13,"y":11,"z":-4},{"level":1,"name":"Water_Source","x":-13,"y":12,"z":-4},{"level":1,"name":"Water_Source","x":-13,"y":11,"z":-2},{"level":1,"name":"Water_Source","x":-13,"y":12,"z":-2},{"level":1,"name":"Water_Source","x":-13,"y":13,"z":-2},{"level":1,"name":"Water_Source","x":-13,"y":14,"z":-2},{"level":1,"name":"Water_Source","x":-13,"y":15,"z":-2},{"level":1,"name":"Water_Source","x":-13,"y":16,"z":-2},{"level":1,"name":"Water_Source","x":-13,"y":17,"z":-2},{"level":1,"name":"Water_Source","x":-13,"y":18,"z":-2},{"level":1,"name":"Water_Source","x":-13,"y":19,"z":-2},{"level":1,"name":"Water_Source","x":-13,"y":20,"z":-2},{"level":1,"name":"Water_Source","x":-13,"y":21,"z":-2},{"level":1,"name":"Water_Source","x":-13,"y":22,"z":-2},{"level":1,"name":"Water_Source","x":-13,"y":23,"z":-2},{"level":1,"name":"Water_Source","x":-13,"y":24,"z":-2},{"level":1,"name":"Water_Source","x":-13,"y":25,"z":-2},{"level":1,"name":"Water_Source","x":-13,"y":26,"z":-2},{"level":1,"name":"Water_Source","x":-13,"y":10,"z":-1},{"level":1,"name":"Water_Source","x":-13,"y":11,"z":-1},{"level":1,"name":"Water_Source","x":-13,"y":12,"z":-1},{"level":1,"name":"Water_Source","x":-13,"y":13,"z":-1},{"level":1,"name":"Water_Source","x":-13,"y":14,"z":-1},{"level":1,"name":"Water_Source","x":-13,"y":12,"z":0},{"level":1,"name":"Water_Source","x":-13,"y":13,"z":0},{"level":1,"name":"Water_Source","x":-13,"y":14,"z":0},{"level":1,"name":"Water_Source","x":-12,"y":10,"z":-10},{"level":1,"name":"Water_Source","x":-12,"y":11,"z":-10},{"level":1,"name":"Water_Source","x":-12,"y":12,"z":-10},{"level":1,"name":"Water_Source","x":-12,"y":13,"z":-10},{"level":1,"name":"Water_Source","x":-12,"y":14,"z":-10},{"level":1,"name":"Water_Source","x":-12,"y":15,"z":-10},{"level":1,"name":"Water_Source","x":-12,"y":16,"z":-10},{"level":1,"name":"Water_Source","x":-12,"y":17,"z":-10},{"level":1,"name":"Water_Source","x":-12,"y":18,"z":-10},{"level":1,"name":"Water_Source","x":-12,"y":19,"z":-10},{"level":1,"name":"Water_Source","x":-12,"y":11,"z":-9},{"level":1,"name":"Water_Source","x":-12,"y":12,"z":-9},{"level":1,"name":"Water_Source","x":-12,"y":11,"z":-7},{"level":1,"name":"Water_Source","x":-12,"y":12,"z":-7},{"level":1,"name":"Water_Source","x":-12,"y":13,"z":-7},{"level":1,"name":"Water_Source","x":-12,"y":10,"z":-6},{"level":1,"name":"Water_Source","x":-12,"y":11,"z":-6},{"level":1,"name":"Water_Source","x":-12,"y":12,"z":-6},{"level":1,"name":"Water_Source","x":-12,"y":13,"z":-6},{"level":1,"name":"Water_Source","x":-12,"y":12,"z":-5},{"level":1,"name":"Water_Source","x":-12,"y":13,"z":-5},{"level":1,"name":"Water_Source","x":-12,"y":14,"z":-5},{"level":1,"name":"Water_Source","x":-12,"y":11,"z":-4},{"level":1,"name":"Water_Source","x":-12,"y":12,"z":-4},{"level":1,"name":"Water_Source","x":-12,"y":13,"z":-4},{"level":1,"name":"Water_Source","x":-12,"y":14,"z":-4},{"level":1,"name":"Water_Source","x":-12,"y":15,"z":-4},{"level":1,"name":"Water_Source","x":-12,"y":16,"z":-4},{"level":1,"name":"Water_Source","x":-12,"y":17,"z":-4},{"level":1,"name":"Water_Source","x":-12,"y":18,"z":-4},{"level":1,"name":"Water_Source","x":-12,"y":19,"z":-4},