{
  "version": 8,
  "blockIdVersion": 11,
  "anchorX": 0,
  "anchorY": 5,
  "anchorZ": -1,
  "blocks": [
    {
      "x": -7,
      "y": 2,
      "z": -3,
      "name": "Rock_Marble"
    },
    {
      "x": -7,
      "y": 1,
      "z": -2,
      "name": "Rock_Marble"
    },
    {
      "x": -7,
      "y": 2,
      "z": -2,
      "name": "Rock_Marble"
    },
    {
      "x": -7,
      "y": 3,
      "z": -2,
      "name": "Rock_Marble"
    },
    {
      "x": -7,
      "y": 1,
      "z": -1,
      "name": "Rock_Marble"
    },
    {
      "x": -7,
      "y": 2,
      "z": -1,
      "name": "Rock_Marble"
    },
    {
      "x": -7,
      "y": 3,
      "z": -1,
      "name": "Rock_Marble"
    },
    {
      "x": -7,
      "y": 4,
      "z": -1,
      "name": "Rock_Marble"
    },
    {
      "x": -7,
      "y": 5,
      "z": -1,
      "name": "Rock_Marble"
    },
    {
      "x": -7,
      "y": 6,
      "z": -1,
      "name": "Rock_Marble"
    },
    {
      "x": -7,
      "y": 7,
      "z": -1,
      "name": "Rock_Marble"
    },
    {
      "x": -7,
      "y": 1,
      "z": 0,
      "name": "Rock_Marble"
    },
    {
      "x": -7,
      "y": 2,
      "z": 0,
      "name": "Rock_Marble"
    },
    {
      "x": -7,
      "y": 3,
      "z": 0,
      "name": "Rock_Marble"
    },
    {
      "x": -7,
      "y": 4,
      "z": 0,
      "name": "Rock_Marble"
    },
    {
      "x": -7,
      "y": 5,
      "z": 0,
      "name": "Rock_Marble"
    },
    {
      "x": -7,
      "y": 2,
      "z": 1,
      "name": "Rock_Marble"
    },
    {
      "x": -7,
      "y": 3,
      "z": 1,
      "name": "Rock_Marble"
    },
    {
      "x": -6,
      "y": 1,
      "z": -4,
      "name": "Rock_Marble"
    },
    {
      "x": -6,
      "y": 2,
      "z": -4,
      "name": "Rock_Marble"
    },
    {
      "x": -6,
      "y": 3,
      "z": -4,
      "name": "Rock_Marble"
    },
    {
      "x": -6,
      "y": 0,
      "z": -3,
      "name": "Rock_Marble"
    },
    {
      "x": -6,
      "y": 1,
      "z": -3,
      "name": "Rock_Marble"
    },
    {
      "x": -6,
      "y": 2,
      "z": -3,
      "name": "Rock_Marble"
    },
    {
      "x": -6,
      "y": 3,
      "z": -3,
      "name": "Rock_Marble"
    },
    {
      "x": -6,
      "y": 4,
      "z": -3,
      "name": "Rock_Marble"
    },
    {
      "x": -6,
      "y": 5,
      "z": -3,
      "name": "Rock_Marble"
    },
    {
      "x": -6,
      "y": 0,
      "z": -2,
      "name": "Rock_Marble"
    },
    {
      "x": -6,
      "y": 1,
      "z": -2,
      "name": "Rock_Marble"
    },
    {
      "x": -6,
      "y": 2,
      "z": -2,
      "name": "Rock_Marble"
    },
    {
      "x": -6,
      "y": 3,
      "z": -2,
      "name": "Rock_Marble"
    },
    {
      "x": -6,
      "y": 4,
      "z": -2,
      "name": "Rock_Marble"
    },
    {
      "x": -6,
      "y": 5,
      "z": -2,
      "name": "Rock_Marble"
    },
    {
      "x": -6,
      "y": 6,
      "z": -2,
      "name": "Rock_Marble"
    },
    {
      "x": -6,
      "y": 7,
      "z": -2,
      "name": "Rock_Marble"
    },
    {
      "x": -6,
      "y": 8,
      "z": -2,
      "name": "Rock_Marble"
    },
    {
      "x": -6,
      "y": 9,
      "z": -2,
      "name": "Rock_Marble"
    },
    {
      "x": -6,
      "y": 10,
      "z": -2,
      "name": "Rock_Marble"
    },
    {
      "x": -6,
      "y": 0,
      "z": -1,
      "name": "Rock_Marble"
    },
    {
      "x": -6,
      "y": 1,
      "z": -1,
      "name": "Rock_Marble"
    },
    {
      "x": -6,
      "y": 2,
      "z": -1,
      "name": "Rock_Marble"
    },
    {
      "x": -6,
      "y": 3,
      "z": -1,
      "name": "Rock_Marble"
    },
    {
      "x": -6,
      "y": 4,
      "z": -1,
      "name": "Rock_Marble"
    },
    {
      "x": -6,
      "y": 5,
      "z": -1,
      "name": "Rock_Marble"
    },
    {
      "x": -6,
      "y": 6,
      "z": -1,
      "name": "Rock_Marble"
    },
    {
      "x": -6,
      "y": 7,
      "z": -1,
      "name": "Rock_Marble"
    },
    {
      "x": -6,
      "y": 8,
      "z": -1,
      "name": "Rock_Marble"
    },
    {
      "x": -6,
      "y": 9,
      "z": -1,
      "name": "Rock_Marble"
    },
    {
      "x": -6,
      "y": 10,
      "z": -1,
      "name": "Rock_Marble"
    },
    {
      "x": -6,
      "y": 11,
      "z": -1,
      "name": "Rock_Marble"
    },
    {
      "x": -6,
      "y": 12,
      "z": -1,
      "name": "Rock_Marble"
    },
    {
      "x": -6,
      "y": 0,
      "z": 0,
      "name": "Rock_Marble"
    },
    {
      "x": -6,
      "y": 1,
      "z": 0,
      "name": "Rock_Marble"
    },
    {
      "x": -6,
      "y": 2,
      "z": 0,
      "name": "Rock_Marble"
    },
    {
      "x": -6,
      "y": 3,
      "z": 0,
      "name": "Rock_Marble"
    },
    {
      "x": -6,
      "y": 4,
      "z": 0,
      "name": "Rock_Marble"
    },
    {
      "x": -6,
      "y": 5,
      "z": 0,
      "name": "Rock_Marble"
    },
    {
      "x": -6,
      "y": 6,
      "z": 0,
      "name": "Rock_Marble"
    },
    {
      "x": -6,
      "y": 7,
      "z": 0,
      "name": "Rock_Marble"
    },
    {
      "x": -6,
      "y": 8,
      "z": 0,
      "name": "Rock_Marble"
    },
    {
      "x": -6,
      "y": 9,
      "z": 0,
      "name": "Rock_Marble"
    },
    {
      "x": -6,
      "y": 10,
      "z": 0,
      "name": "Rock_Marble"
    },
    {
      "x": -6,
      "y": 1,
      "z": 1,
      "name": "Rock_Marble"
    },
    {
      "x": -6,
      "y": 2,
      "z": 1,
      "name": "Rock_Marble"
    },
    {
      "x": -6,
      "y": 3,
      "z": 1,
      "name": "Rock_Marble"
    },
    {
      "x": -6,
      "y": 4,
      "z": 1,
      "name": "Rock_Marble"
    },
    {
      "x": -6,
      "y": 5,
      "z": 1,
      "name": "Rock_Marble"
    },
    {
      "x": -6,
      "y": 6,
      "z": 1,
      "name": "Rock_Marble"
    },
    {
      "x": -6,
      "y": 7,
      "z": 1,
      "name": "Rock_Marble"
    },
    {
      "x": -6,
      "y": 2,
      "z": 2,
      "name": "Rock_Marble"
    },
    {
      "x": -6,
      "y": 3,
      "z": 2,
      "name": "Rock_Marble"
    },
    {
      "x": -5,
      "y": 1,
      "z": -5,
      "name": "Rock_Marble"
    },
    {
      "x": -5,
      "y": 2,
      "z": -5,
      "name": "Rock_Marble"
    },
    {
      "x": -5,
      "y": 3,
      "z": -5,
      "name": "Rock_Marble"
    },
    {
      "x": -5,
      "y": 4,
      "z": -5,
      "name": "Rock_Marble"
    },
    {
      "x": -5,
      "y": 0,
      "z": -4,
      "name": "Rock_Marble"
    },
    {
      "x": -5,
      "y": 1,
      "z": -4,
      "name": "Rock_Marble"
    },
    {
      "x": -5,
      "y": 2,
      "z": -4,
      "name": "Rock_Marble"
    },
    {
      "x": -5,
      "y": 3,
      "z": -4,
      "name": "Rock_Marble"
    },
    {
      "x": -5,
      "y": 4,
      "z": -4,
      "name": "Rock_Marble"
    },
    {
      "x": -5,
      "y": 5,
      "z": -4,
      "name": "Rock_Marble"
    },
    {
      "x": -5,
      "y": 6,
      "z": -4,
      "name": "Rock_Marble"
    },
    {
      "x": -5,
      "y": 0,
      "z": -3,
      "name": "Rock_Marble"
    },
    {
      "x": -5,
      "y": 1,
      "z": -3,
      "name": "Rock_Marble"
    },
    {
      "x": -5,
      "y": 2,
      "z": -3,
      "name": "Rock_Marble"
    },
    {
      "x": -5,
      "y": 3,
      "z": -3,
      "name": "Rock_Marble"
    },
    {
      "x": -5,
      "y": 4,
      "z": -3,
      "name": "Rock_Marble"
    },
    {
      "x": -5,
      "y": 5,
      "z": -3,
      "name": "Rock_Marble"
    },
    {
      "x": -5,
      "y": 6,
      "z": -3,
      "name": "Rock_Marble"
    },
    {
      "x": -5,
      "y": 7,
      "z": -3,
      "name": "Rock_Marble"
    },
    {
      "x": -5,
      "y": 8,
      "z": -3,
      "name": "Rock_Marble"
    },
    {
      "x": -5,
      "y": 9,
      "z": -3,
      "name": "Rock_Marble"
    },
    {
      "x": -5,
      "y": 10,
      "z": -3,
      "name": "Rock_Marble"
    },
    {
      "x": -5,
      "y": 0,
      "z": -2,
      "name": "Rock_Marble"
    },
    {
      "x": -5,
      "y": 1,
      "z": -2,
      "name": "Rock_Marble"
    },
    {
      "x": -5,
      "y": 2,
      "z": -2,
      "name": "Rock_Marble"
    },
    {
      "x": -5,
      "y": 3,
      "z": -2,
      "name": "Rock_Marble"
    },
    {
      "x": -5,
      "y": 4,
      "z": -2,
      "name": "Rock_Marble"
    },
    {
      "x": -5,
      "y": 5,
      "z": -2,
      "name": "Rock_Marble"
    },
    {
      "x": -5,
      "y": 6,
      "z": -2,
      "name": "Rock_Marble"
    },
    {
      "x": -5,
      "y": 7,
      "z": -2,
      "name": "Rock_Marble"
    },
    {
      "x": -5,
      "y": 8,
      "z": -2,
      "name": "Rock_Marble"
    },
    {
      "x": -5,
      "y": 9,
      "z": -2,
      "name": "Rock_Marble"
    },
    {
      "x": -5,
      "y": 10,
      "z": -2,
      "name": "Rock_Marble"
    },
    {
      "x": -5,
      "y": 11,
      "z": -2,
      "name": "Rock_Marble"
    },
    {
      "x": -5,
      "y": 12,
      "z": -2,
      "name": "Rock_Marble"
    },
    {
      "x": -5,
      "y": 13,
      "z": -2,
      "name": "Rock_Marble"
    },
    {
      "x": -5,
      "y": 14,
      "z": -2,
      "name": "Rock_Marble"
    },
    {
      "x": -5,
      "y": 15,
      "z": -2,
      "name": "Rock_Marble"
    },
    {
      "x": -5,
      "y": 16,
      "z": -2,
      "name": "Rock_Marble"
    },
    {
      "x": -5,
      "y": 0,
      "z": -1,
      "name": "Rock_Marble"
    },
    {
      "x": -5,
      "y": 1,
      "z": -1,
      "name": "Rock_Marble"
    },
    {
      "x": -5,
      "y": 2,
      "z": -1,
      "name": "Rock_Marble"
    },
    {
      "x": -5,
      "y": 3,
      "z": -1,
      "name": "Rock_Marble"
    },
    {
      "x": -5,
      "y": 4,
      "z": -1,
      "name": "Rock_Marble"
    },
    {
      "x": -5,
      "y": 5,
      "z": -1,
      "name": "Rock_Marble"
    },
    {
      "x": -5,
      "y": 6,
      "z": -1,
      "name": "Rock_Marble"
    },
    {
      "x": -5,
      "y": 7,
      "z": -1,
      "name": "Rock_Marble"
    },
    {
      "x": -5,
      "y": 8,
      "z": -1,
      "name": "Rock_Marble"
    },
    {
      "x": -5,
      "y": 9,
      "z": -1,
      "name": "Rock_Marble"
    },
    {
      "x": -5,
      "y": 10,
      "z": -1,
      "name": "Rock_Marble"
    },
    {
      "x": -5,
      "y": 11,
      "z": -1,
      "name": "Rock_Marble"
    },
    {
      "x": -5,
      "y": 12,
      "z": -1,
      "name": "Rock_Marble"
    },
    {
      "x": -5,
      "y": 13,
      "z": -1,
      "name": "Rock_Marble"
    },
    {
      "x": -5,
      "y": 14,
      "z": -1,
      "name": "Rock_Marble"
    },
    {
      "x": -5,
      "y": 15,
      "z": -1,
      "name": "Rock_Marble"
    },
    {
      "x": -5,
      "y": 16,
      "z": -1,
      "name": "Rock_Marble"
    },
    {
      "x": -5,
      "y": 17,
      "z": -1,
      "name": "Rock_Marble"
    },
    {
      "x": -5,
      "y": 18,
      "z": -1,
      "name": "Rock_Marble"
    },
    {
      "x": -5,
      "y": 0,
      "z": 0,
      "name": "Rock_Marble"
    },
    {
      "x": -5,
      "y": 1,
      "z": 0,
      "name": "Rock_Marble"
    },
    {
      "x": -5,
      "y": 2,
      "z": 0,
      "name": "Rock_Marble"
    },
    {
      "x": -5,
      "y": 3,
      "z": 0,
      "name": "Rock_Marble"
    },
    {
      "x": -5,
      "y": 4,
      "z": 0,
      "name": "Rock_Marble"
    },
    {
      "x": -5,
      "y": 5,
      "z": 0,
      "name": "Rock_Marble"
    },
    {
      "x": -5,
      "y": 6,
      "z": 0,
      "name": "Rock_Marble"
    },
    {
      "x": -5,
      "y": 7,
      "z": 0,
      "name": "Rock_Marble"
    },
    {
      "x": -5,
      "y": 8,
      "z": 0,
      "name": "Rock_Marble"
    },
    {
      "x": -5,
      "y": 9,
      "z": 0,
      "name": "Rock_Marble"
    },
    {
      "x": -5,
      "y": 10,
      "z": 0,
      "name": "Rock_Marble"
    },
    {
      "x": -5,
      "y": 11,
      "z": 0,
      "name": "Rock_Marble"
    },
    {
      "x": -5,
      "y": 12,
      "z": 0,
      "name": "Rock_Marble"
    },
    {
      "x": -5,
      "y": 13,
      "z": 0,
      "name": "Rock_Marble"
    },
    {
      "x": -5,
      "y": 0,
      "z": 1,
      "name": "Rock_Marble"
    },
    {
      "x": -5,
      "y": 1,
      "z": 1,
      "name": "Rock_Marble"
    },
    {
      "x": -5,
      "y": 2,
      "z": 1,
      "name": "Rock_Marble"
    },
    {
      "x": -5,
      "y": 3,
      "z": 1,
      "name": "Rock_Marble"
    },
    {
      "x": -5,
      "y": 4,
      "z": 1,
      "name": "Rock_Marble"
    },
    {
      "x": -5,
      "y": 5,
      "z": 1,
      "name": "Rock_Marble"
    },
    {
      "x": -5,
      "y": 6,
      "z": 1,
      "name": "Rock_Marble"
    },
    {
      "x": -5,
      "y": 7,
      "z": 1,
      "name": "Rock_Marble"
    },
    {
      "x": -5,
      "y": 8,
      "z": 1,
      "name": "Rock_Marble"
    },
    {
      "x": -5,
      "y": 9,
      "z": 1,
      "name": "Rock_Marble"
    },
    {
      "x": -5,
      "y": 10,
      "z": 1,
      "name": "Rock_Marble"
    },
    {
      "x": -5,
      "y": 1,
      "z": 2,
      "name": "Rock_Marble"
    },
    {
      "x": -5,
      "y": 2,
      "z": 2,
      "name": "Rock_Marble"
    },
    {
      "x": -5,
      "y": 3,
      "z": 2,
      "name": "Rock_Marble"
    },
    {
      "x": -5,
      "y": 4,
      "z": 2,
      "name": "Rock_Marble"
    },
    {
      "x": -5,
      "y": 5,
      "z": 2,
      "name": "Rock_Marble"
    },
    {
      "x": -5,
      "y": 6,
      "z": 2,
      "name": "Rock_Marble"
    },
    {
      "x": -4,
      "y": 2,
      "z": -6,
      "name": "Rock_Marble"
    },
    {
      "x": -4,
      "y": 3,
      "z": -6,
      "name": "Rock_Marble"
    },
    {
      "x": -4,
      "y": 4,
      "z": -6,
      "name": "Rock_Marble"
    },
    {
      "x": -4,
      "y": 0,
      "z": -5,
      "name": "Rock_Marble"
    },
    {
      "x": -4,
      "y": 1,
      "z": -5,
      "name": "Rock_Marble"
    },
    {
      "x": -4,
      "y": 2,
      "z": -5,
      "name": "Rock_Marble"
    },
    {
      "x": -4,
      "y": 3,
      "z": -5,
      "name": "Rock_Marble"
    },
    {
      "x": -4,
      "y": 4,
      "z": -5,
      "name": "Rock_Marble"
    },
    {
      "x": -4,
      "y": 5,
      "z": -5,
      "name": "Rock_Marble"
    },
    {
      "x": -4,
      "y": 6,
      "z": -5,
      "name": "Rock_Marble"
    },
    {
      "x": -4,
      "y": 7,
      "z": -5,
      "name": "Rock_Marble"
    },
    {
      "x": -4,
      "y": 0,
      "z": -4,
      "name": "Rock_Marble"
    },
    {
      "x": -4,
      "y": 1,
      "z": -4,
      "name": "Rock_Marble"
    },
    {
      "x": -4,
      "y": 2,
      "z": -4,
      "name": "Rock_Marble"
    },
    {
      "x": -4,
      "y": 3,
      "z": -4,
      "name": "Rock_Marble"
    },
    {
      "x": -4,
      "y": 4,
      "z": -4,
      "name": "Rock_Marble"
    },
    {
      "x": -4,
      "y": 5,
      "z": -4,
      "name": "Rock_Marble"
    },
    {
      "x": -4,
      "y": 6,
      "z": -4,
      "name": "Rock_Marble"
    },
    {
      "x": -4,
      "y": 7,
      "z": -4,
      "name": "Rock_Marble"
    },
    {
      "x": -4,
      "y": 8,
      "z": -4,
      "name": "Rock_Marble"
    },
    {
      "x": -4,
      "y": 9,
      "z": -4,
      "name": "Rock_Marble"
    },
    {
      "x": -4,
      "y": 10,
      "z": -4,
      "name": "Rock_Marble"
    },
    {
      "x": -4,
      "y": 0,
      "z": -3,
      "name": "Rock_Marble"
    },
    {
      "x": -4,
      "y": 1,
      "z": -3,
      "name": "Rock_Marble"
    },
    {
      "x": -4,
      "y": 2,
      "z": -3,
      "name": "Rock_Marble"
    },
    {
      "x": -4,
      "y": 3,
      "z": -3,
      "name": "Rock_Marble"
    },
    {
      "x": -4,
      "y": 4,
      "z": -3,
      "name": "Rock_Marble"
    },
    {
      "x": -4,
      "y": 5,
      "z": -3,
      "name": "Rock_Marble"
    },
    {
      "x": -4,
      "y": 6,
      "z": -3,
      "name": "Rock_Marble"
    },
    {
      "x": -4,
      "y": 7,
      "z": -3,
      "name": "Rock_Marble"
    },
    {
      "x": -4,
      "y": 8,
      "z": -3,
      "name": "Rock_Marble"
    },
    {
      "x": -4,
      "y": 9,
      "z": -3,
      "name": "Rock_Marble"
    },
    {
      "x": -4,
      "y": 10,
      "z": -3,
      "name": "Rock_Marble"
    },
    {
      "x": -4,
      "y": 11,
      "z": -3,
      "name": "Rock_Marble"
    },
    {
      "x": -4,
      "y": 12,
      "z": -3,
      "name": "Rock_Marble"
    },
    {
      "x": -4,
      "y": 13,
      "z": -3,
      "name": "Rock_Marble"
    },
    {
      "x": -4,
      "y": 14,
      "z": -3,
      "name": "Rock_Marble"
    },
    {
      "x": -4,
      "y": 15,
      "z": -3,
      "name": "Rock_Marble"
    },
    {
      "x": -4,
      "y": 0,
      "z": -2,
      "name": "Rock_Marble"
    },
    {
      "x": -4,
      "y": 1,
      "z": -2,
      "name": "Rock_Marble"
    },
    {
      "x": -4,
      "y": 2,
      "z": -2,
      "name": "Rock_Marble"
    },
    {
      "x": -4,
      "y": 3,
      "z": -2,
      "name": "Rock_Marble"
    },
    {
      "x": -4,
      "y": 4,
      "z": -2,
      "name": "Rock_Marble"
    },
    {
      "x": -4,
      "y": 5,
      "z": -2,
      "name": "Rock_Marble"
    },
    {
      "x": -4,
      "y": 6,
      "z": -2,
      "name": "Rock_Marble"
    },
    {
      "x": -4,
      "y": 7,
      "z": -2,
      "name": "Rock_Marble"
    },
    {
      "x": -4,
      "y": 8,
      "z": -2,
      "name": "Rock_Marble"
    },
    {
      "x": -4,
      "y": 9,
      "z": -2,
      "name": "Rock_Marble"
    },
    {
      "x": -4,
      "y": 10,
      "z": -2,
      "name": "Rock_Marble"
    },
    {
      "x": -4,
      "y": 11,
      "z": -2,
      "name": "Rock_Marble"
    },
    {
      "x": -4,
      "y": 12,
      "z": -2,
      "name": "Rock_Marble"
    },
    {
      "x": -4,
      "y": 13,
      "z": -2,
      "name": "Rock_Marble"
    },
    {
      "x": -4,
      "y": 14,
      "z": -2,
      "name": "Rock_Marble"
    },
    {
      "x": -4,
      "y": 15,
      "z": -2,
      "name": "Rock_Marble"
    },
    {
      "x": -4,
      "y": 16,
      "z": -2,
      "name": "Rock_Marble"
    },
    {
      "x": -4,
      "y": 17,
      "z": -2,
      "name": "Rock_Marble"
    },
    {
      "x": -4,
      "y": 18,
      "z": -2,
      "name": "Rock_Marble"
    },
    {
      "x": -4,
      "y": 19,
      "z": -2,
      "name": "Rock_Marble"
    },
    {
      "x": -4,
      "y": 20,
      "z": -2,
      "name": "Rock_Marble"
    },
    {
      "x": -4,
      "y": 25,
      "z": -2,
      "name": "Rock_Marble"
    },
    {
      "x": -4,
      "y": 26,
      "z": -2,
      "name": "Rock_Marble"
    },
    {
      "x": -4,
      "y": 27,
      "z": -2,
      "name": "Rock_Marble"
    },
    {
      "x": -4,
      "y": 0,
      "z": -1,
      "name": "Rock_Marble"
    },
    {
      "x": -4,
      "y": 1,
      "z": -1,
      "name": "Rock_Marble"
    },
    {
      "x": -4,
      "y": 2,
      "z": -1,
      "name": "Rock_Marble"
    },
    {
      "x": -4,
      "y": 3,
      "z": -1,
      "name": "Rock_Marble"
    },
    {
      "x": -4,
      "y": 4,
      "z": -1,
      "name": "Rock_Marble"
    },
    {
      "x": -4,
      "y": 5,
      "z": -1,
      "name": "Rock_Marble"
    },
    {
      "x": -4,
      "y": 6,
      "z": -1,
      "name": "Rock_Marble"
    },
    {
      "x": -4,
      "y": 7,
      "z": -1,
      "name": "Rock_Marble"
    },
    {
      "x": -4,
      "y": 8,
      "z": -1,
      "name": "Rock_Marble"
    },
    {
      "x": -4,
      "y": 9,
      "z": -1,
      "name": "Rock_Marble"
    },
    {
      "x": -4,
      "y": 10,
      "z": -1,
      "name": "Rock_Marble"
    },
    {
      "x": -4,
      "y": 11,
      "z": -1,
      "name": "Rock_Marble"
    },
    {
      "x": -4,
      "y": 12,
      "z": -1,
      "name": "Rock_Marble"
    },
    {
      "x": -4,
      "y": 13,
      "z": -1,
      "name": "Rock_Marble"
    },
    {
      "x": -4,
      "y": 14,
      "z": -1,
      "name": "Rock_Marble"
    },
    {
      "x": -4,
      "y": 15,
      "z": -1,
      "name": "Rock_Marble"
    },
    {
      "x": -4,
      "y": 16,
      "z": -1,
      "name": "Rock_Marble"
    },
    {
      "x": -4,
      "y": 17,
      "z": -1,
      "name": "Rock_Marble"
    },
    {
      "x": -4,
      "y": 18,
      "z": -1,
      "name": "Rock_Marble"
    },
    {
      "x": -4,
      "y": 19,
      "z": -1,
      "name": "Rock_Marble"
    },
    {
      "x": -4,
      "y": 20,
      "z": -1,
      "name": "Rock_Marble"
    },
    {
      "x": -4,
      "y": 21,
      "z": -1,
      "name": "Rock_Marble"
    },
    {
      "x": -4,
      "y": 22,
      "z": -1,
      "name": "Rock_Marble"
    },
    {
      "x": -4,
      "y": 23,
      "z": -1,
      "name": "Rock_Marble"
    },
    {
      "x": -4,
      "y": 24,
      "z": -1,
      "name": "Rock_Marble"
    },
    {
      "x": -4,
      "y": 25,
      "z": -1,
      "name": "Rock_Marble"
    },
    {
      "x": -4,
      "y": 26,
      "z": -1,
      "name": "Rock_Marble"
    },
    {
      "x": -4,
      "y": 27,
      "z": -1,
      "name": "Rock_Marble"
    },
    {
      "x": -4,
      "y": 28,
      "z": -1,
      "name": "Rock_Marble"
    },
    {
      "x": -4,
      "y": 0,
      "z": 0,
      "name": "Rock_Marble"
    },
    {
      "x": -4,
      "y": 1,
      "z": 0,
      "name": "Rock_Marble"
    },
    {
      "x": -4,
      "y": 2,
      "z": 0,
      "name": "Rock_Marble"
    },
    {
      "x": -4,
      "y": 3,
      "z": 0,
      "name": "Rock_Marble"
    },
    {
      "x": -4,
      "y": 4,
      "z": 0,
      "name": "Rock_Marble"
    },
    {
      "x": -4,
      "y": 5,
      "z": 0,
      "name": "Rock_Marble"
    },
    {
      "x": -4,
      "y": 6,
      "z": 0,
      "name": "Rock_Marble"
    },
    {
      "x": -4,
      "y": 7,
      "z": 0,
      "name": "Rock_Marble"
    },
    {
      "x": -4,
      "y": 8,
      "z": 0,
      "name": "Rock_Marble"
    },
    {
      "x": -4,
      "y": 9,
      "z": 0,
      "name": "Rock_Marble"
    },
    {
      "x": -4,
      "y": 10,
      "z": 0,
      "name": "Rock_Marble"
    },
    {
      "x": -4,
      "y": 11,
      "z": 0,
      "name": "Rock_Marble"
    },
    {
      "x": -4,
      "y": 12,
      "z": 0,
      "name": "Rock_Marble"
    },
    {
      "x": -4,
      "y": 13,
      "z": 0,
      "name": "Rock_Marble"
    },
    {
      "x": -4,
      "y": 14,
      "z": 0,
      "name": "Rock_Marble"
    },
    {
      "x": -4,
      "y": 15,
      "z": 0,
      "name": "Rock_Marble"
    },
    {
      "x": -4,
      "y": 16,
      "z": 0,
      "name": "Rock_Marble"
    },
    {
      "x": -4,
      "y": 17,
      "z": 0,
      "name": "Rock_Marble"
    },
    {
      "x": -4,
      "y": 18,
      "z": 0,
      "name": "Rock_Marble"
    },
    {
      "x": -4,
      "y": 23,
      "z": 0,
      "name": "Rock_Marble"
    },
    {
      "x": -4,
      "y": 24,
      "z": 0,
      "name": "Rock_Marble"
    },
    {
      "x": -4,
      "y": 25,
      "z": 0,
      "name": "Rock_Marble"
    },
    {
      "x": -4,
      "y": 26,
      "z": 0,
      "name": "Rock_Marble"
    },
    {
      "x": -4,
      "y": 0,
      "z": 1,
      "name": "Rock_Marble"
    },
    {
      "x": -4,
      "y": 1,
      "z": 1,
      "name": "Rock_Marble"
    },
    {
      "x": -4,
      "y": 2,
      "z": 1,
      "name": "Rock_Marble"
    },
    {
      "x": -4,
      "y": 3,
      "z": 1,
      "name": "Rock_Marble"
    },
    {
      "x": -4,
      "y": 4,
      "z": 1,
      "name": "Rock_Marble"
    },
    {
      "x": -4,
      "y": 5,
      "z": 1,
      "name": "Rock_Marble"
    },
    {
      "x": -4,
      "y": 6,
      "z": 1,
      "name": "Rock_Marble"
    },
    {
      "x": -4,
      "y": 7,
      "z": 1,
      "name": "Rock_Marble"
    },
    {
      "x": -4,
      "y": 8,
      "z": 1,
      "name": "Rock_Marble"
    },
    {
      "x": -4,
      "y": 9,
      "z": 1,
      "name": "Rock_Marble"
    },
    {
      "x": -4,
      "y": 10,
      "z": 1,
      "name": "Rock_Marble"
    },
    {
      "x": -4,
      "y": 11,
      "z": 1,
      "name": "Rock_Marble"
    },
    {
      "x": -4,
      "y": 0,
      "z": 2,
      "name": "Rock_Marble"
    },
    {
      "x": -4,
      "y": 1,
      "z": 2,
      "name": "Rock_Marble"
    },
    {
      "x": -4,
      "y": 2,
      "z": 2,
      "name": "Rock_Marble"
    },
    {
      "x": -4,
      "y": 3,
      "z": 2,
      "name": "Rock_Marble"
    },
    {
      "x": -4,
      "y": 4,
      "z": 2,
      "name": "Rock_Marble"
    },
    {
      "x": -4,
      "y": 5,
      "z": 2,
      "name": "Rock_Marble"
    },
    {
      "x": -4,
      "y": 6,
      "z": 2,
      "name": "Rock_Marble"
    },
    {
      "x": -4,
      "y": 7,
      "z": 2,
      "name": "Rock_Marble"
    },
    {
      "x": -4,
      "y": 1,
      "z": 3,
      "name": "Rock_Marble"
    },
    {
      "x": -4,
      "y": 2,
      "z": 3,
      "name": "Rock_Marble"
    },
    {
      "x": -3,
      "y": 3,
      "z": -7,
      "name": "Rock_Marble"
    },
    {
      "x": -3,
      "y": 4,
      "z": -7,
      "name": "Rock_Marble"
    },
    {
      "x": -3,
      "y": 5,
      "z": -7,
      "name": "Rock_Marble"
    },
    {
      "x": -3,
      "y": 1,
      "z": -6,
      "name": "Rock_Marble"
    },
    {
      "x": -3,
      "y": 2,
      "z": -6,
      "name": "Rock_Marble"
    },
    {
      "x": -3,
      "y": 3,
      "z": -6,
      "name": "Rock_Marble"
    },
    {
      "x": -3,
      "y": 4,
      "z": -6,
      "name": "Rock_Marble"
    },
    {
      "x": -3,
      "y": 5,
      "z": -6,
      "name": "Rock_Marble"
    },
    {
      "x": -3,
      "y": 6,
      "z": -6,
      "name": "Rock_Marble"
    },
    {
      "x": -3,
      "y": 7,
      "z": -6,
      "name": "Rock_Marble"
    },
    {
      "x": -3,
      "y": 8,
      "z": -6,
      "name": "Rock_Marble"
    },
    {
      "x": -3,
      "y": 0,
      "z": -5,
      "name": "Rock_Marble"
    },
    {
      "x": -3,
      "y": 1,
      "z": -5,
      "name": "Rock_Marble"
    },
    {
      "x": -3,
      "y": 2,
      "z": -5,
      "name": "Rock_Marble"
    },
    {
      "x": -3,
      "y": 3,
      "z": -5,
      "name": "Rock_Marble"
    },
    {
      "x": -3,
      "y": 4,
      "z": -5,
      "name": "Rock_Marble"
    },
    {
      "x": -3,
      "y": 5,
      "z": -5,
      "name": "Rock_Marble"
    },
    {
      "x": -3,
      "y": 6,
      "z": -5,
      "name": "Rock_Marble"
    },
    {
      "x": -3,
      "y": 7,
      "z": -5,
      "name": "Rock_Marble"
    },
    {
      "x": -3,
      "y": 8,
      "z": -5,
      "name": "Rock_Marble"
    },
    {
      "x": -3,
      "y": 9,
      "z": -5,
      "name": "Rock_Marble"
    },
    {
      "x": -3,
      "y": 10,
      "z": -5,
      "name": "Rock_Marble"
    },
    {
      "x": -3,
      "y": 11,
      "z": -5,
      "name": "Rock_Marble"
    },
    {
      "x": -3,
      "y": 0,
      "z": -4,
      "name": "Rock_Marble"
    },
    {
      "x": -3,
      "y": 1,
      "z": -4,
      "name": "Rock_Marble"
    },
    {
      "x": -3,
      "y": 2,
      "z": -4,
      "name": "Rock_Marble"
    },
    {
      "x": -3,
      "y": 3,
      "z": -4,
      "name": "Rock_Marble"
    },
    {
      "x": -3,
      "y": 4,
      "z": -4,
      "name": "Rock_Marble"
    },
    {
      "x": -3,
      "y": 5,
      "z": -4,
      "name": "Rock_Marble"
    },
    {
      "x": -3,
      "y": 6,
      "z": -4,
      "name": "Rock_Marble"
    },
    {
      "x": -3,
      "y": 7,
      "z": -4,
      "name": "Rock_Marble"
    },
    {
      "x": -3,
      "y": 8,
      "z": -4,
      "name": "Rock_Marble"
    },
    {
      "x": -3,
      "y": 9,
      "z": -4,
      "name": "Rock_Marble"
    },
    {
      "x": -3,
      "y": 10,
      "z": -4,
      "name": "Rock_Marble"
    },
    {
      "x": -3,
      "y": 11,
      "z": -4,
      "name": "Rock_Marble"
    },
    {
      "x": -3,
      "y": 12,
      "z": -4,
      "name": "Rock_Marble"
    },
    {
      "x": -3,
      "y": 13,
      "z": -4,
      "name": "Rock_Marble"
    },
    {
      "x": -3,
      "y": 14,
      "z": -4,
      "name": "Rock_Marble"
    },
    {
      "x": -3,
      "y": 15,
      "z": -4,
      "name": "Rock_Marble"
    },
    {
      "x": -3,
      "y": 0,
      "z": -3,
      "name": "Rock_Marble"
    },
    {
      "x": -3,
      "y": 1,
      "z": -3,
      "name": "Rock_Marble"
    },
    {
      "x": -3,
      "y": 2,
      "z": -3,
      "name": "Rock_Marble"
    },
    {
      "x": -3,
      "y": 3,
      "z": -3,
      "name": "Rock_Marble"
    },
    {
      "x": -3,
      "y": 4,
      "z": -3,
      "name": "Rock_Marble"
    },
    {
      "x": -3,
      "y": 5,
      "z": -3,
      "name": "Rock_Marble"
    },
    {
      "x": -3,
      "y": 6,
      "z": -3,
      "name": "Rock_Marble"
    },
    {
      "x": -3,
      "y": 7,
      "z": -3,
      "name": "Rock_Marble"
    },
    {
      "x": -3,
      "y": 8,
      "z": -3,
      "name": "Rock_Marble"
    },
    {
      "x": -3,
      "y": 9,
      "z": -3,
      "name": "Rock_Marble"
    },
    {
      "x": -3,
      "y": 10,
      "z": -3,
      "name": "Rock_Marble"
    },
    {
      "x": -3,
      "y": 11,
      "z": -3,
      "name": "Rock_Marble"
    },
    {
      "x": -3,
      "y": 12,
      "z": -3,
      "name": "Rock_Marble"
    },
    {
      "x": -3,
      "y": 13,
      "z": -3,
      "name": "Rock_Marble"
    },
    {
      "x": -3,
      "y": 14,
      "z": -3,
      "name": "Rock_Marble"
    },
    {
      "x": -3,
      "y": 15,
      "z": -3,
      "name": "Rock_Marble"
    },
    {
      "x": -3,
      "y": 16,
      "z": -3,
      "name": "Rock_Marble"
    },
    {
      "x": -3,
      "y": 17,
      "z": -3,
      "name": "Rock_Marble"
    },
    {
      "x": -3,
      "y": 18,
      "z": -3,
      "name": "Rock_Marble"
    },
    {
      "x": -3,
      "y": 19,
      "z": -3,
      "name": "Rock_Marble"
    },
    {
      "x": -3,
      "y": 20,
      "z": -3,
      "name": "Rock_Marble"
    },
    {
      "x": -3,
      "y": 24,
      "z": -3,
      "name": "Rock_Marble"
    },
    {
      "x": -3,
      "y": 25,
      "z": -3,
      "name": "Rock_Marble"
    },
    {
      "x": -3,
      "y": 26,
      "z": -3,
      "name": "Rock_Marble"
    },
    {
      "x": -3,
      "y": 27,
      "z": -3,
      "name": "Rock_Marble"
    },
    {
      "x": -3,
      "y": 28,
      "z": -3,
      "name": "Rock_Marble"
    },
    {
      "x": -3,
      "y": 29,
      "z": -3,
      "name": "Rock_Marble"
    },
    {
      "x": -3,
      "y": 0,
      "z": -2,
      "name": "Rock_Marble"
    },
    {
      "x": -3,
      "y": 1,
      "z": -2,
      "name": "Rock_Marble"
    },
    {
      "x": -3,
      "y": 2,
      "z": -2,
      "name": "Rock_Marble"
    },
    {
      "x": -3,
      "y": 3,
      "z": -2,
      "name": "Rock_Marble"
    },
    {
      "x": -3,
      "y": 4,
      "z": -2,
      "name": "Rock_Marble"
    },
    {
      "x": -3,
      "y": 5,
      "z": -2,
      "name": "Rock_Marble"
    },
    {
      "x": -3,
      "y": 6,
      "z": -2,
      "name": "Rock_Marble"
    },
    {
      "x": -3,
      "y": 7,
      "z": -2,
      "name": "Rock_Marble"
    },
    {
      "x": -3,
      "y": 8,
      "z": -2,
      "name": "Rock_Marble"
    },
    {
      "x": -3,
      "y": 9,
      "z": -2,
      "name": "Rock_Marble"
    },
    {
      "x": -3,
      "y": 10,
      "z": -2,
      "name": "Rock_Marble"
    },
    {
      "x": -3,
      "y": 11,
      "z": -2,
      "name": "Rock_Marble"
    },
    {
      "x": -3,
      "y": 12,
      "z": -2,
      "name": "Rock_Marble"
    },
    {
      "x": -3,
      "y": 13,
      "z": -2,
      "name": "Rock_Marble"
    },
    {
      "x": -3,
      "y": 14,
      "z": -2,
      "name": "Rock_Marble"
    },
    {
      "x": -3,
      "y": 15,
      "z": -2,
      "name": "Rock_Marble"
    },
    {
      "x": -3,
      "y": 16,
      "z": -2,
      "name": "Rock_Marble"
    },
    {
      "x": -3,
      "y": 17,
      "z": -2,
      "name": "Rock_Marble"
    },
    {
      "x": -3,
      "y": 18,
      "z": -2,
      "name": "Rock_Marble"
    },
    {
      "x": -3,
      "y": 19,
      "z": -2,
      "name": "Rock_Marble"
    },
    {
      "x": -3,
      "y": 20,
      "z": -2,
      "name": "Rock_Marble"
    },
    {
      "x": -3,
      "y": 21,
      "z": -2,
      "name": "Rock_Marble"
    },
    {
      "x": -3,
      "y": 22,
      "z": -2,
      "name": "Rock_Marble"
    },
    {
      "x": -3,
      "y": 23,
      "z": -2,
      "name": "Rock_Marble"
    },
    {
      "x": -3,
      "y": 24,
      "z": -2,
      "name": "Rock_Marble"
    },
    {
      "x": -3,
      "y": 25,
      "z": -2,
      "name": "Rock_Marble"
    },
    {
      "x": -3,
      "y": 26,
      "z": -2,
      "name": "Rock_Marble"
    },
    {
      "x": -3,
      "y": 27,
      "z": -2,
      "name": "Rock_Marble"
    },
    {
      "x": -3,
      "y": 28,
      "z": -2,
      "name": "Rock_Marble"
    },
    {
      "x": -3,
      "y": 29,
      "z": -2,
      "name": "Rock_Marble"
    },
    {
      "x": -3,
      "y": 30,
      "z": -2,
      "name": "Plant_Moss_Block_Green",
      "support": 15
    },
    {
      "x": -3,
      "y": 0,
      "z": -1,
      "name": "Rock_Marble"
    },
    {
      "x": -3,
      "y": 1,
      "z": -1,
      "name": "Rock_Marble"
    },
    {
      "x": -3,
      "y": 2,
      "z": -1,
      "name": "Rock_Marble"
    },
    {
      "x": -3,
      "y": 3,
      "z": -1,
      "name": "Rock_Marble"
    },
    {
      "x": -3,
      "y": 4,
      "z": -1,
      "name": "Rock_Marble"
    },
    {
      "x": -3,
      "y": 5,
      "z": -1,
      "name": "Rock_Marble"
    },
    {
      "x": -3,
      "y": 6,
      "z": -1,
      "name": "Rock_Marble"
    },
    {
      "x": -3,
      "y": 7,
      "z": -1,
      "name": "Rock_Marble"
    },
    {
      "x": -3,
      "y": 8,
      "z": -1,
      "name": "Rock_Marble"
    },
    {
      "x": -3,
      "y": 9,
      "z": -1,
      "name": "Rock_Marble"
    },
    {
      "x": -3,
      "y": 10,
      "z": -1,
      "name": "Rock_Marble"
    },
    {
      "x": -3,
      "y": 11,
      "z": -1,
      "name": "Rock_Marble"
    },
    {
      "x": -3,
      "y": 12,
      "z": -1,
      "name": "Rock_Marble"
    },
    {
      "x": -3,
      "y": 13,
      "z": -1,
      "name": "Rock_Marble"
    },
    {
      "x": -3,
      "y": 14,
      "z": -1,
      "name": "Rock_Marble"
    },
    {
      "x": -3,
      "y": 15,
      "z": -1,
      "name": "Rock_Marble"
    },
    {
      "x": -3,
      "y": 16,
      "z": -1,
      "name": "Rock_Marble"
    },
    {
      "x": -3,
      "y": 17,
      "z": -1,
      "name": "Rock_Marble"
    },
    {
      "x": -3,
      "y": 18,
      "z": -1,
      "name": "Rock_Marble"
    },
    {
      "x": -3,
      "y": 19,
      "z": -1,
      "name": "Rock_Marble"
    },
    {
      "x": -3,
      "y": 20,
      "z": -1,
      "name": "Rock_Marble"
    },
    {
      "x": -3,
      "y": 21,
      "z": -1,
      "name": "Rock_Marble"
    },
    {
      "x": -3,
      "y": 22,
      "z": -1,
      "name": "Rock_Marble"
    },
    {
      "x": -3,
      "y": 23,
      "z": -1,
      "name": "Rock_Marble"
    },
    {
      "x": -3,
      "y": 24,
      "z": -1,
      "name": "Rock_Marble"
    },
    {
      "x": -3,
      "y": 25,
      "z": -1,
      "name": "Rock_Marble"
    },
    {
      "x": -3,
      "y": 26,
      "z": -1,
      "name": "Rock_Marble"
    },
    {
      "x": -3,
      "y": 27,
      "z": -1,
      "name": "Rock_Marble"
    },
    {
      "x": -3,
      "y": 28,
      "z": -1,
      "name": "Rock_Marble"
    },
    {
      "x": -3,
      "y": 29,
      "z": -1,
      "name": "Rock_Marble"
    },
    {
      "x": -3,
      "y": 30,
      "z": -1,
      "name": "Rock_Marble"
    },
    {
      "x": -3,
      "y": 31,
      "z": -1,
      "name": "Plant_Moss_Block_Green",
      "support": 15
    },
    {
      "x": -3,
      "y": 0,
      "z": 0,
      "name": "Rock_Marble"
    },
    {
      "x": -3,
      "y": 1,
      "z": 0,
      "name": "Rock_Marble"
    },
    {
      "x": -3,
      "y": 2,
      "z": 0,
      "name": "Rock_Marble"
    },
    {
      "x": -3,
      "y": 3,
      "z": 0,
      "name": "Rock_Marble"
    },
    {
      "x": -3,
      "y": 4,
      "z": 0,
      "name": "Rock_Marble"
    },
    {
      "x": -3,
      "y": 5,
      "z": 0,
      "name": "Rock_Marble"
    },
    {
      "x": -3,
      "y": 6,
      "z": 0,
      "name": "Rock_Marble"
    },
    {
      "x": -3,
      "y": 7,
      "z": 0,
      "name": "Rock_Marble"
    },
    {
      "x": -3,
      "y": 8,
      "z": 0,
      "name": "Rock_Marble"
    },
    {
      "x": -3,
      "y": 9,
      "z": 0,
      "name": "Rock_Marble"
    },
    {
      "x": -3,
      "y": 10,
      "z": 0,
      "name": "Rock_Marble"
    },
    {
      "x": -3,
      "y": 11,
      "z": 0,
      "name": "Rock_Marble"
    },
    {
      "x": -3,
      "y": 12,
      "z": 0,
      "name": "Rock_Marble"
    },
    {
      "x": -3,
      "y": 13,
      "z": 0,
      "name": "Rock_Marble"
    },
    {
      "x": -3,
      "y": 14,
      "z": 0,
      "name": "Rock_Marble"
    },
    {
      "x": -3,
      "y": 15,
      "z": 0,
      "name": "Rock_Marble"
    },
    {
      "x": -3,
      "y": 16,
      "z": 0,
      "name": "Rock_Marble"
    },
    {
      "x": -3,
      "y": 17,
      "z": 0,
      "name": "Rock_Marble"
    },
    {
      "x": -3,
      "y": 18,
      "z": 0,
      "name": "Rock_Marble"
    },
    {
      "x": -3,
      "y": 19,
      "z": 0,
      "name": "Rock_Marble"
    },
    {
      "x": -3,
      "y": 20,
      "z": 0,
      "name": "Rock_Marble"
    },
    {
      "x": -3,
      "y": 21,
      "z": 0,
      "name": "Rock_Marble"
    },
    {
      "x": -3,
      "y": 22,
      "z": 0,
      "name": "Rock_Marble"
    },
    {
      "x": -3,
      "y": 23,
      "z": 0,
      "name": "Rock_Marble"
    },
    {
      "x": -3,
      "y": 24,
      "z": 0,
      "name": "Rock_Marble"
    },
    {
      "x": -3,
      "y": 25,
      "z": 0,
      "name": "Rock_Marble"
    },
    {
      "x": -3,
      "y": 26,
      "z": 0,
      "name": "Rock_Marble"
    },
    {
      "x": -3,
      "y": 27,
      "z": 0,
      "name": "Rock_Marble"
    },
    {
      "x": -3,
      "y": 28,
      "z": 0,
      "name": "Rock_Marble"
    },
    {
      "x": -3,
      "y": 29,
      "z": 0,
      "name": "Rock_Marble"
    },
    {
      "x": -3,
      "y": 0,
      "z": 1,
      "name": "Rock_Marble"
    },
    {
      "x": -3,
      "y": 1,
      "z": 1,
      "name": "Rock_Marble"
    },
    {
      "x": -3,
      "y": 2,
      "z": 1,
      "name": "Rock_Marble"
    },
    {
      "x": -3,
      "y": 3,
      "z": 1,
      "name": "Rock_Marble"
    },
    {
      "x": -3,
      "y": 4,
      "z": 1,
      "name": "Rock_Marble"
    },
    {
      "x": -3,
      "y": 5,
      "z": 1,
      "name": "Rock_Marble"
    },
    {
      "x": -3,
      "y": 6,
      "z": 1,
      "name": "Rock_Marble"
    },
    {
      "x": -3,
      "y": 7,
      "z": 1,
      "name": "Rock_Marble"
    },
    {
      "x": -3,
      "y": 8,
      "z": 1,
      "name": "Rock_Marble"
    },
    {
      "x": -3,
      "y": 9,
      "z": 1,
      "name": "Rock_Marble"
    },
    {
      "x": -3,
      "y": 10,
      "z": 1,
      "name": "Rock_Marble"
    },
    {
      "x": -3,
      "y": 15,
      "z": 1,
      "name": "Rock_Marble"
    },
    {
      "x": -3,
      "y": 16,
      "z": 1,
      "name": "Rock_Marble"
    },
    {
      "x": -3,
      "y": 17,
      "z": 1,
      "name": "Rock_Marble"
    },
    {
      "x": -3,
      "y": 23,
      "z": 1,
      "name": "Rock_Marble"
    },
    {
      "x": -3,
      "y": 24,
      "z": 1,
      "name": "Rock_Marble"
    },
    {
      "x": -3,
      "y": 25,
      "z": 1,
      "name": "Rock_Marble"
    },
    {
      "x": -3,
      "y": 26,
      "z": 1,
      "name": "Rock_Marble"
    },
    {
      "x": -3,
      "y": 0,
      "z": 2,
      "name": "Rock_Marble"
    },
    {
      "x": -3,
      "y": 1,
      "z": 2,
      "name": "Rock_Marble"
    },
    {
      "x": -3,
      "y": 2,
      "z": 2,
      "name": "Rock_Marble"
    },
    {
      "x": -3,
      "y": 3,
      "z": 2,
      "name": "Rock_Marble"
    },
    {
      "x": -3,
      "y": 4,
      "z": 2,
      "name": "Rock_Marble"
    },
    {
      "x": -3,
      "y": 5,
      "z": 2,
      "name": "Rock_Marble"
    },
    {
      "x": -3,
      "y": 6,
      "z": 2,
      "name": "Rock_Marble"
    },
    {
      "x": -3,
      "y": 7,
      "z": 2,
      "name": "Rock_Marble"
    },
    {
      "x": -3,
      "y": 0,
      "z": 3,
      "name": "Rock_Marble"
    },
    {
      "x": -3,
      "y": 1,
      "z": 3,
      "name": "Rock_Marble"
    },
    {
      "x": -3,
      "y": 2,
      "z": 3,
      "name": "Rock_Marble"
    },
    {
      "x": -3,
      "y": 3,
      "z": 3,
      "name": "Rock_Marble"
    },
    {
      "x": -3,
      "y": 4,
      "z": 3,
      "name": "Rock_Marble"
    },
    {
      "x": -3,
      "y": 1,
      "z": 4,
      "name": "Rock_Marble"
    },
    {
      "x": -3,
      "y": 2,
      "z": 4,
      "name": "Rock_Marble"
    },
    {
      "x": -2,
      "y": 3,
      "z": -8,
      "name": "Rock_Marble"
    },
    {
      "x": -2,
      "y": 4,
      "z": -8,
      "name": "Rock_Marble"
    },
    {
      "x": -2,
      "y": 1,
      "z": -7,
      "name": "Rock_Marble"
    },
    {
      "x": -2,
      "y": 2,
      "z": -7,
      "name": "Rock_Marble"
    },
    {
      "x": -2,
      "y": 3,
      "z": -7,
      "name": "Rock_Marble"
    },
    {
      "x": -2,
      "y": 4,
      "z": -7,
      "name": "Rock_Marble"
    },
    {
      "x": -2,
      "y": 5,
      "z": -7,
      "name": "Rock_Marble"
    },
    {
      "x": -2,
      "y": 6,
      "z": -7,
      "name": "Rock_Marble"
    },
    {
      "x": -2,
      "y": 7,
      "z": -7,
      "name": "Rock_Marble"
    },
    {
      "x": -2,
      "y": 8,
      "z": -7,
      "name": "Rock_Marble"
    },
    {
      "x": -2,
      "y": 9,
      "z": -7,
      "name": "Rock_Marble"
    },
    {
      "x": -2,
      "y": 0,
      "z": -6,
      "name": "Rock_Marble"
    },
    {
      "x": -2,
      "y": 1,
      "z": -6,
      "name": "Rock_Marble"
    },
    {
      "x": -2,
      "y": 2,
      "z": -6,
      "name": "Rock_Marble"
    },
    {
      "x": -2,
      "y": 3,
      "z": -6,
      "name": "Rock_Marble"
    },
    {
      "x": -2,
      "y": 4,
      "z": -6,
      "name": "Rock_Marble"
    },
    {
      "x": -2,
      "y": 5,
      "z": -6,
      "name": "Rock_Marble"
    },
    {
      "x": -2,
      "y": 6,
      "z": -6,
      "name": "Rock_Marble"
    },
    {
      "x": -2,
      "y": 7,
      "z": -6,
      "name": "Rock_Marble"
    },
    {
      "x": -2,
      "y": 8,
      "z": -6,
      "name": "Rock_Marble"
    },
    {
      "x": -2,
      "y": 9,
      "z": -6,
      "name": "Rock_Marble"
    },
    {
      "x": -2,
      "y": 10,
      "z": -6,
      "name": "Rock_Marble"
    },
    {
      "x": -2,
      "y": 11,
      "z": -6,
      "name": "Rock_Marble"
    },
    {
      "x": -2,
      "y": 12,
      "z": -6,
      "name": "Rock_Marble"
    },
    {
      "x": -2,
      "y": 13,
      "z": -6,
      "name": "Rock_Marble"
    },
    {
      "x": -2,
      "y": 0,
      "z": -5,
      "name": "Rock_Marble"
    },
    {
      "x": -2,
      "y": 1,
      "z": -5,
      "name": "Rock_Marble"
    },
    {
      "x": -2,
      "y": 2,
      "z": -5,
      "name": "Rock_Marble"
    },
    {
      "x": -2,
      "y": 3,
      "z": -5,
      "name": "Rock_Marble"
    },
    {
      "x": -2,
      "y": 4,
      "z": -5,
      "name": "Rock_Marble"
    },
    {
      "x": -2,
      "y": 5,
      "z": -5,
      "name": "Rock_Marble"
    },
    {
      "x": -2,
      "y": 6,
      "z": -5,
      "name": "Rock_Marble"
    },
    {
      "x": -2,
      "y": 7,
      "z": -5,
      "name": "Rock_Marble"
    },
    {
      "x": -2,
      "y": 8,
      "z": -5,
      "name": "Rock_Marble"
    },
    {
      "x": -2,
      "y": 9,
      "z": -5,
      "name": "Rock_Marble"
    },
    {
      "x": -2,
      "y": 10,
      "z": -5,
      "name": "Rock_Marble"
    },
    {
      "x": -2,
      "y": 11,
      "z": -5,
      "name": "Rock_Marble"
    },
    {
      "x": -2,
      "y": 12,
      "z": -5,
      "name": "Rock_Marble"
    },
    {
      "x": -2,
      "y": 13,
      "z": -5,
      "name": "Rock_Marble"
    },
    {
      "x": -2,
      "y": 14,
      "z": -5,
      "name": "Rock_Marble"
    },
    {
      "x": -2,
      "y": 15,
      "z": -5,
      "name": "Rock_Marble"
    },
    {
      "x": -2,
      "y": 16,
      "z": -5,
      "name": "Rock_Marble"
    },
    {
      "x": -2,
      "y": 0,
      "z": -4,
      "name": "Rock_Marble"
    },
    {
      "x": -2,
      "y": 1,
      "z": -4,
      "name": "Rock_Marble"
    },
    {
      "x": -2,
      "y": 2,
      "z": -4,
      "name": "Rock_Marble"
    },
    {
      "x": -2,
      "y": 3,
      "z": -4,
      "name": "Rock_Marble"
    },
    {
      "x": -2,
      "y": 4,
      "z": -4,
      "name": "Rock_Marble"
    },
    {
      "x": -2,
      "y": 5,
      "z": -4,
      "name": "Rock_Marble"
    },
    {
      "x": -2,
      "y": 6,
      "z": -4,
      "name": "Rock_Marble"
    },
    {
      "x": -2,
      "y": 7,
      "z": -4,
      "name": "Rock_Marble"
    },
    {
      "x": -2,
      "y": 8,
      "z": -4,
      "name": "Rock_Marble"
    },
    {
      "x": -2,
      "y": 9,
      "z": -4,
      "name": "Rock_Marble"
    },
    {
      "x": -2,
      "y": 10,
      "z": -4,
      "name": "Rock_Marble"
    },
    {
      "x": -2,
      "y": 11,
      "z": -4,
      "name": "Rock_Marble"
    },
    {
      "x": -2,
      "y": 12,
      "z": -4,
      "name": "Rock_Marble"
    },
    {
      "x": -2,
      "y": 13,
      "z": -4,
      "name": "Rock_Marble"
    },
    {
      "x": -2,
      "y": 14,
      "z": -4,
      "name": "Rock_Marble"
    },
    {
      "x": -2,
      "y": 15,
      "z": -4,
      "name": "Rock_Marble"
    },
    {
      "x": -2,
      "y": 16,
      "z": -4,
      "name": "Rock_Marble"
    },
    {
      "x": -2,
      "y": 17,
      "z": -4,
      "name": "Rock_Marble"
    },
    {
      "x": -2,
      "y": 18,
      "z": -4,
      "name": "Rock_Marble"
    },
    {
      "x": -2,
      "y": 19,
      "z": -4,
      "name": "Rock_Marble"
    },
    {
      "x": -2,
      "y": 24,
      "z": -4,
      "name": "Rock_Marble"
    },
    {
      "x": -2,
      "y": 25,
      "z": -4,
      "name": "Rock_Marble"
    },
    {
      "x": -2,
      "y": 26,
      "z": -4,
      "name": "Rock_Marble"
    },
    {
      "x": -2,
      "y": 27,
      "z": -4,
      "name": "Rock_Marble"
    },
    {
      "x": -2,
      "y": 28,
      "z": -4,
      "name": "Rock_Marble"
    },
    {
      "x": -2,
      "y": 29,
      "z": -4,
      "name": "Rock_Marble"
    },
    {
      "x": -2,
      "y": 0,
      "z": -3,
      "name": "Rock_Marble"
    },
    {
      "x": -2,
      "y": 1,
      "z": -3,
      "name": "Rock_Marble"
    },
    {
      "x": -2,
      "y": 2,
      "z": -3,
      "name": "Rock_Marble"
    },
    {
      "x": -2,
      "y": 3,
      "z": -3,
      "name": "Rock_Marble"
    },
    {
      "x": -2,
      "y": 4,
      "z": -3,
      "name": "Rock_Marble"
    },
    {
      "x": -2,
      "y": 5,
      "z": -3,
      "name": "Rock_Marble"
    },
    {
      "x": -2,
      "y": 6,
      "z": -3,
      "name": "Rock_Marble"
    },
    {
      "x": -2,
      "y": 7,
      "z": -3,
      "name": "Rock_Marble"
    },
    {
      "x": -2,
      "y": 8,
      "z": -3,
      "name": "Rock_Marble"
    },
    {
      "x": -2,
      "y": 9,
      "z": -3,
      "name": "Rock_Marble"
    },
    {
      "x": -2,
      "y": 10,
      "z": -3,
      "name": "Rock_Marble"
    },
    {
      "x": -2,
      "y": 11,
      "z": -3,
      "name": "Rock_Marble"
    },
    {
      "x": -2,
      "y": 12,
      "z": -3,
      "name": "Rock_Marble"
    },
    {
      "x": -2,
      "y": 13,
      "z": -3,
      "name": "Rock_Marble"
    },
    {
      "x": -2,
      "y": 14,
      "z": -3,
      "name": "Rock_Marble"
    },
    {
      "x": -2,
      "y": 15,
      "z": -3,
      "name": "Rock_Marble"
    },
    {
      "x": -2,
      "y": 16,
      "z": -3,
      "name": "Rock_Marble"
    },
    {
      "x": -2,
      "y": 17,
      "z": -3,
      "name": "Rock_Marble"
    },
    {
      "x": -2,
      "y": 18,
      "z": -3,
      "name": "Rock_Marble"
    },
    {
      "x": -2,
      "y": 19,
      "z": -3,
      "name": "Rock_Marble"
    },
    {
      "x": -2,
      "y": 20,
      "z": -3,
      "name": "Rock_Marble"
    },
    {
      "x": -2,
      "y": 21,
      "z": -3,
      "name": "Rock_Marble"
    },
    {
      "x": -2,
      "y": 22,
      "z": -3,
      "name": "Rock_Marble"
    },
    {
      "x": -2,
      "y": 23,
      "z": -3,
      "name": "Rock_Marble"
    },
    {
      "x": -2,
      "y": 24,
      "z": -3,
      "name": "Rock_Marble"
    },
    {
      "x": -2,
      "y": 25,
      "z": -3,
      "name": "Rock_Marble"
    },
    {
      "x": -2,
      "y": 26,
      "z": -3,
      "name": "Rock_Marble"
    },
    {
      "x": -2,
      "y": 27,
      "z": -3,
      "name": "Rock_Marble"
    },
    {
      "x": -2,
      "y": 28,
      "z": -3,
      "name": "Rock_Marble"
    },
    {
      "x": -2,
      "y": 29,
      "z": -3,
      "name": "Rock_Marble"
    },
    {
      "x": -2,
      "y": 30,
      "z": -3,
      "name": "Rock_Marble"
    },
    {
      "x": -2,
      "y": 31,
      "z": -3,
      "name": "Plant_Moss_Block_Green",
      "support": 15
    },
    {
      "x": -2,
      "y": 32,
      "z": -3,
      "name": "Plant_Moss_Block_Green",
      "support": 15
    },
    {
      "x": -2,
      "y": 0,
      "z": -2,
      "name": "Rock_Marble"
    },
    {
      "x": -2,
      "y": 1,
      "z": -2,
      "name": "Rock_Marble"
    },
    {
      "x": -2,
      "y": 2,
      "z": -2,
      "name": "Rock_Marble"
    },
    {
      "x": -2,
      "y": 3,
      "z": -2,
      "name": "Rock_Marble"
    },
    {
      "x": -2,
      "y": 4,
      "z": -2,
      "name": "Rock_Marble"
    },
    {
      "x": -2,
      "y": 5,
      "z": -2,
      "name": "Rock_Marble"
    },
    {
      "x": -2,
      "y": 6,
      "z": -2,
      "name": "Rock_Marble"
    },
    {
      "x": -2,
      "y": 7,
      "z": -2,
      "name": "Rock_Marble"
    },
    {
      "x": -2,
      "y": 8,
      "z": -2,
      "name": "Rock_Marble"
    },
    {
      "x": -2,
      "y": 9,
      "z": -2,
      "name": "Rock_Marble"
    },
    {
      "x": -2,
      "y": 10,
      "z": -2,
      "name": "Rock_Marble"
    },
    {
      "x": -2,
      "y": 11,
      "z": -2,
      "name": "Rock_Marble"
    },
    {
      "x": -2,
      "y": 12,
      "z": -2,
      "name": "Rock_Marble"
    },
    {
      "x": -2,
      "y": 13,
      "z": -2,
      "name": "Rock_Marble"
    },
    {
      "x": -2,
      "y": 14,
      "z": -2,
      "name": "Rock_Marble"
    },
    {
      "x": -2,
      "y": 15,
      "z": -2,
      "name": "Rock_Marble"
    },
    {
      "x": -2,
      "y": 16,
      "z": -2,
      "name": "Rock_Marble"
    },
    {
      "x": -2,
      "y": 17,
      "z": -2,
      "name": "Rock_Marble"
    },
    {
      "x": -2,
      "y": 18,
      "z": -2,
      "name": "Rock_Marble"
    },
    {
      "x": -2,
      "y": 19,
      "z": -2,
      "name": "Rock_Marble"
    },
    {
      "x": -2,
      "y": 20,
      "z": -2,
      "name": "Rock_Marble"
    },
    {
      "x": -2,
      "y": 21,
      "z": -2,
      "name": "Rock_Marble"
    },
    {
      "x": -2,
      "y": 22,
      "z": -2,
      "name": "Rock_Marble"
    },
    {
      "x": -2,
      "y": 23,
      "z": -2,
      "name": "Rock_Marble"
    },
    {
      "x": -2,
      "y": 24,
      "z": -2,
      "name": "Rock_Marble"
    },
    {
      "x": -2,
      "y": 25,
      "z": -2,
      "name": "Rock_Marble"
    },
    {
      "x": -2,
      "y": 26,
      "z": -2,
      "name": "Rock_Marble"
    },
    {
      "x": -2,
      "y": 27,
      "z": -2,
      "name": "Rock_Marble"
    },
    {
      "x": -2,
      "y": 28,
      "z": -2,
      "name": "Rock_Marble"
    },
    {
      "x": -2,
      "y": 29,
      "z": -2,
      "name": "Rock_Marble"
    },
    {
      "x": -2,
      "y": 30,
      "z": -2,
      "name": "Rock_Marble"
    },
    {
      "x": -2,
      "y": 31,
      "z": -2,
      "name": "Plant_Moss_Block_Green",
      "support": 15
    },
    {
      "x": -2,
      "y": 32,
      "z": -2,
      "name": "Plant_Moss_Block_Green",
      "support": 15
    },
    {
      "x": -2,
      "y": 33,
      "z": -2,
      "name": "Plant_Moss_Block_Green",
      "support": 15
    },
    {
      "x": -2,
      "y": 0,
      "z": -1,
      "name": "Rock_Marble"
    },
    {
      "x": -2,
      "y": 1,
      "z": -1,
      "name": "Rock_Marble"
    },
    {
      "x": -2,
      "y": 2,
      "z": -1,
      "name": "Rock_Marble"
    },
    {
      "x": -2,
      "y": 3,
      "z": -1,
      "name": "Rock_Marble"
    },
    {
      "x": -2,
      "y": 4,
      "z": -1,
      "name": "Rock_Marble"
    },
    {
      "x": -2,
      "y": 5,
      "z": -1,
      "name": "Rock_Marble"
    },
    {
      "x": -2,
      "y": 6,
      "z": -1,
      "name": "Rock_Marble"
    },
    {
      "x": -2,
      "y": 7,
      "z": -1,
      "name": "Rock_Marble"
    },
    {
      "x": -2,
      "y": 8,
      "z": -1,
      "name": "Rock_Marble"
    },
    {
      "x": -2,
      "y": 9,
      "z": -1,
      "name": "Rock_Marble"
    },
    {
      "x": -2,
      "y": 10,
      "z": -1,
      "name": "Rock_Marble"
    },
    {
      "x": -2,
      "y": 11,
      "z": -1,
      "name": "Rock_Marble"
    },
    {
      "x": -2,
      "y": 12,
      "z": -1,
      "name": "Rock_Marble"
    },
    {
      "x": -2,
      "y": 13,
      "z": -1,
      "name": "Rock_Marble"
    },
    {
      "x": -2,
      "y": 14,
      "z": -1,
      "name": "Rock_Marble"
    },
    {
      "x": -2,
      "y": 15,
      "z": -1,
      "name": "Rock_Marble"
    },
    {
      "x": -2,
      "y": 16,
      "z": -1,
      "name": "Rock_Marble"
    },
    {
      "x": -2,
      "y": 17,
      "z": -1,
      "name": "Rock_Marble"
    },
    {
      "x": -2,
      "y": 18,
      "z": -1,
      "name": "Rock_Marble"
    },
    {
      "x": -2,
      "y": 19,
      "z": -1,
      "name": "Rock_Marble"
    },
    {
      "x": -2,
      "y": 20,
      "z": -1,
      "name": "Rock_Marble"
    },
    {
      "x": -2,
      "y": 21,
      "z": -1,
      "name": "Rock_Marble"
    },
    {
      "x": -2,
      "y": 22,
      "z": -1,
      "name": "Rock_Marble"
    },
    {
      "x": -2,
      "y": 23,
      "z": -1,
      "name": "Rock_Marble"
    },
    {
      "x": -2,
      "y": 24,
      "z": -1,
      "name": "Rock_Marble"
    },
    {
      "x": -2,
      "y": 25,
      "z": -1,
      "name": "Rock_Marble"
    },
    {
      "x": -2,
      "y": 26,
      "z": -1,
      "name": "Rock_Marble"
    },
    {
      "x": -2,
      "y": 27,
      "z": -1,
      "name": "Rock_Marble"
    },
    {
      "x": -2,
      "y": 28,
      "z": -1,
      "name": "Rock_Marble"
    },
    {
      "x": -2,
      "y": 29,
      "z": -1,
      "name": "Rock_Marble"
    },
    {
      "x": -2,
      "y": 30,
      "z": -1,
      "name": "Rock_Marble"
    },
    {
      "x": -2,
      "y": 31,
      "z": -1,
      "name": "Rock_Marble"
    },
    {
      "x": -2,
      "y": 32,
      "z": -1,
      "name": "Plant_Moss_Block_Green",
      "support": 15
    },
    {
      "x": -2,
      "y": 33,
      "z": -1,
      "name": "Plant_Moss_Block_Green",
      "support": 15
    },
    {
      "x": -2,
      "y": 0,
      "z": 0,
      "name": "Rock_Marble"
    },
    {
      "x": -2,
      "y": 1,
      "z": 0,
      "name": "Rock_Marble"
    },
    {
      "x": -2,
      "y": 2,
      "z": 0,
      "name": "Rock_Marble"
    },
    {
      "x": -2,
      "y": 3,
      "z": 0,
      "name": "Rock_Marble"
    },
    {
      "x": -2,
      "y": 4,
      "z": 0,
      "name": "Rock_Marble"
    },
    {
      "x": -2,
      "y": 5,
      "z": 0,
      "name": "Rock_Marble"
    },
    {
      "x": -2,
      "y": 6,
      "z": 0,
      "name": "Rock_Marble"
    },
    {
      "x": -2,
      "y": 7,
      "z": 0,
      "name": "Rock_Marble"
    },
    {
      "x": -2,
      "y": 8,
      "z": 0,
      "name": "Rock_Marble"
    },
    {
      "x": -2,
      "y": 9,
      "z": 0,
      "name": "Rock_Marble"
    },
    {
      "x": -2,
      "y": 10,
      "z": 0,
      "name": "Rock_Marble"
    },
    {
      "x": -2,
      "y": 11,
      "z": 0,
      "name": "Rock_Marble"
    },
    {
      "x": -2,
      "y": 12,
      "z": 0,
      "name": "Rock_Marble"
    },
    {
      "x": -2,
      "y": 13,
      "z": 0,
      "name": "Rock_Marble"
    },
    {
      "x": -2,
      "y": 14,
      "z": 0,
      "name": "Rock_Marble"
    },
    {
      "x": -2,
      "y": 15,
      "z": 0,
      "name": "Rock_Marble"
    },
    {
      "x": -2,
      "y": 16,
      "z": 0,
      "name": "Rock_Marble"
    },
    {
      "x": -2,
      "y": 17,
      "z": 0,
      "name": "Rock_Marble"
    },
    {
      "x": -2,
      "y": 18,
      "z": 0,
      "name": "Rock_Marble"
    },
    {
      "x": -2,
      "y": 19,
      "z": 0,
      "name": "Rock_Marble"
    },
    {
      "x": -2,
      "y": 20,
      "z": 0,
      "name": "Rock_Marble"
    },
    {
      "x": -2,
      "y": 21,
      "z": 0,
      "name": "Rock_Marble"
    },
    {
      "x": -2,
      "y": 22,
      "z": 0,
      "name": "Rock_Marble"
    },
    {
      "x": -2,
      "y": 23,
      "z": 0,
      "name": "Rock_Marble"
    },
    {
      "x": -2,
      "y": 24,
      "z": 0,
      "name": "Rock_Marble"
    },
    {
      "x": -2,
      "y": 25,
      "z": 0,
      "name": "Rock_Marble"
    },
    {
      "x": -2,
      "y": 26,
      "z": 0,
      "name": "Rock_Marble"
    },
    {
      "x": -2,
      "y": 27,
      "z": 0,
      "name": "Rock_Marble"
    },
    {
      "x": -2,
      "y": 28,
      "z": 0,
      "name": "Rock_Marble"
    },
    {
      "x": -2,
      "y": 29,
      "z": 0,
      "name": "Rock_Marble"
    },
    {
      "x": -2,
      "y": 30,
      "z": 0,
      "name": "Rock_Marble"
    },
    {
      "x": -2,
      "y": 31,
      "z": 0,
      "name": "Plant_Moss_Block_Green",
      "support": 15
    },
    {
      "x": -2,
      "y": 32,
      "z": 0,
      "name": "Plant_Moss_Block_Green",
      "support": 15
    },
    {
      "x": -2,
      "y": 0,
      "z": 1,
      "name": "Rock_Marble"
    },
    {
      "x": -2,
      "y": 1,
      "z": 1,
      "name": "Rock_Marble"
    },
    {
      "x": -2,
      "y": 2,
      "z": 1,
      "name": "Rock_Marble"
    },
    {
      "x": -2,
      "y": 3,
      "z": 1,
      "name": "Rock_Marble"
    },
    {
      "x": -2,
      "y": 4,
      "z": 1,
      "name": "Rock_Marble"
    },
    {
      "x": -2,
      "y": 5,
      "z": 1,
      "name": "Rock_Marble"
    },
    {
      "x": -2,
      "y": 6,
      "z": 1,
      "name": "Rock_Marble"
    },
    {
      "x": -2,
      "y": 7,
      "z": 1,
      "name": "Rock_Marble"
    },
    {
      "x": -2,
      "y": 8,
      "z": 1,
      "name": "Rock_Marble"
    },
    {
      "x": -2,
      "y": 9,
      "z": 1,
      "name": "Rock_Marble"
    },
    {
      "x": -2,
      "y": 14,
      "z": 1,
      "name": "Rock_Marble"
    },
    {
      "x": -2,
      "y": 15,
      "z": 1,
      "name": "Rock_Marble"
    },
    {
      "x": -2,
      "y": 16,
      "z": 1,
      "name": "Rock_Marble"
    },
    {
      "x": -2,
      "y": 17,
      "z": 1,
      "name": "Rock_Marble"
    },
    {
      "x": -2,
      "y": 18,
      "z": 1,
      "name": "Rock_Marble"
    },
    {
      "x": -2,
      "y": 19,
      "z": 1,
      "name": "Rock_Marble"
    },
    {
      "x": -2,
      "y": 20,
      "z": 1,
      "name": "Rock_Marble"
    },
    {
      "x": -2,
      "y": 21,
      "z": 1,
      "name": "Rock_Marble"
    },
    {
      "x": -2,
      "y": 22,
      "z": 1,
      "name": "Rock_Marble"
    },
    {
      "x": -2,
      "y": 23,
      "z": 1,
      "name": "Rock_Marble"
    },
    {
      "x": -2,
      "y": 24,
      "z": 1,
      "name": "Rock_Marble"
    },
    {
      "x": -2,
      "y": 25,
      "z": 1,
      "name": "Rock_Marble"
    },
    {
      "x": -2,
      "y": 26,
      "z": 1,
      "name": "Rock_Marble"
    },
    {
      "x": -2,
      "y": 27,
      "z": 1,
      "name": "Rock_Marble"
    },
    {
      "x": -2,
      "y": 28,
      "z": 1,
      "name": "Rock_Marble"
    },
    {
      "x": -2,
      "y": 0,
      "z": 2,
      "name": "Rock_Marble"
    },
    {
      "x": -2,
      "y": 1,
      "z": 2,
      "name": "Rock_Marble"
    },
    {
      "x": -2,
      "y": 2,
      "z": 2,
      "name": "Rock_Marble"
    },
    {
      "x": -2,
      "y": 3,
      "z": 2,
      "name": "Rock_Marble"
    },
    {
      "x": -2,
      "y": 4,
      "z": 2,
      "name": "Rock_Marble"
    },
    {
      "x": -2,
      "y": 5,
      "z": 2,
      "name": "Rock_Marble"
    },
    {
      "x": -2,
      "y": 6,
      "z": 2,
      "name": "Rock_Marble"
    },
    {
      "x": -2,
      "y": 16,
      "z": 2,
      "name": "Rock_Marble"
    },
    {
      "x": -2,
      "y": 17,
      "z": 2,
      "name": "Rock_Marble"
    },
    {
      "x": -2,
      "y": 18,
      "z": 2,
      "name": "Rock_Marble"
    },
    {
      "x": -2,
      "y": 19,
      "z": 2,
      "name": "Rock_Marble"
    },
    {
      "x": -2,
      "y": 0,
      "z": 3,
      "name": "Rock_Marble"
    },
    {
      "x": -2,
      "y": 1,
      "z": 3,
      "name": "Rock_Marble"
    },
    {
      "x": -2,
      "y": 2,
      "z": 3,
      "name": "Rock_Marble"
    },
    {
      "x": -2,
      "y": 3,
      "z": 3,
      "name": "Rock_Marble"
    },
    {
      "x": -2,
      "y": 4,
      "z": 3,
      "name": "Rock_Marble"
    },
    {
      "x": -2,
      "y": 5,
      "z": 3,
      "name": "Rock_Marble"
    },
    {
      "x": -2,
      "y": 0,
      "z": 4,
      "name": "Rock_Marble"
    },
    {
      "x": -2,
      "y": 1,
      "z": 4,
      "name": "Rock_Marble"
    },
    {
      "x": -2,
      "y": 2,
      "z": 4,
      "name": "Rock_Marble"
    },
    {
      "x": -2,
      "y": 3,
      "z": 4,
      "name": "Rock_Marble"
    },
    {
      "x": -1,
      "y": 2,
      "z": -8,
      "name": "Rock_Marble"
    },
    {
      "x": -1,
      "y": 3,
      "z": -8,
      "name": "Rock_Marble"
    },
    {
      "x": -1,
      "y": 4,
      "z": -8,
      "name": "Rock_Marble"
    },
    {
      "x": -1,
      "y": 5,
      "z": -8,
      "name": "Rock_Marble"
    },
    {
      "x": -1,
      "y": 6,
      "z": -8,
      "name": "Rock_Marble"
    },
    {
      "x": -1,
      "y": 7,
      "z": -8,
      "name": "Rock_Marble"
    },
    {
      "x": -1,
      "y": 1,
      "z": -7,
      "name": "Rock_Marble"
    },
    {
      "x": -1,
      "y": 2,
      "z": -7,
      "name": "Rock_Marble"
    },
    {
      "x": -1,
      "y": 3,
      "z": -7,
      "name": "Rock_Marble"
    },
    {
      "x": -1,
      "y": 4,
      "z": -7,
      "name": "Rock_Marble"
    },
    {
      "x": -1,
      "y": 5,
      "z": -7,
      "name": "Rock_Marble"
    },
    {
      "x": -1,
      "y": 6,
      "z": -7,
      "name": "Rock_Marble"
    },
    {
      "x": -1,
      "y": 7,
      "z": -7,
      "name": "Rock_Marble"
    },
    {
      "x": -1,
      "y": 8,
      "z": -7,
      "name": "Rock_Marble"
    },
    {
      "x": -1,
      "y": 9,
      "z": -7,
      "name": "Rock_Marble"
    },
    {
      "x": -1,
      "y": 10,
      "z": -7,
      "name": "Rock_Marble"
    },
    {
      "x": -1,
      "y": 11,
      "z": -7,
      "name": "Rock_Marble"
    },
    {
      "x": -1,
      "y": 12,
      "z": -7,
      "name": "Rock_Marble"
    },
    {
      "x": -1,
      "y": 13,
      "z": -7,
      "name": "Rock_Marble"
    },
    {
      "x": -1,
      "y": 14,
      "z": -7,
      "name": "Rock_Marble"
    },
    {
      "x": -1,
      "y": 0,
      "z": -6,
      "name": "Rock_Marble"
    },
    {
      "x": -1,
      "y": 1,
      "z": -6,
      "name": "Rock_Marble"
    },
    {
      "x": -1,
      "y": 2,
      "z": -6,
      "name": "Rock_Marble"
    },
    {
      "x": -1,
      "y": 3,
      "z": -6,
      "name": "Rock_Marble"
    },
    {
      "x": -1,
      "y": 4,
      "z": -6,
      "name": "Rock_Marble"
    },
    {
      "x": -1,
      "y": 5,
      "z": -6,
      "name": "Rock_Marble"
    },
    {
      "x": -1,
      "y": 6,
      "z": -6,
      "name": "Rock_Marble"
    },
    {
      "x": -1,
      "y": 7,
      "z": -6,
      "name": "Rock_Marble"
    },
    {
      "x": -1,
      "y": 8,
      "z": -6,
      "name": "Rock_Marble"
    },
    {
      "x": -1,
      "y": 9,
      "z": -6,
      "name": "Rock_Marble"
    },
    {
      "x": -1,
      "y": 10,
      "z": -6,
      "name": "Rock_Marble"
    },
    {
      "x": -1,
      "y": 11,
      "z": -6,
      "name": "Rock_Marble"
    },
    {
      "x": -1,
      "y": 12,
      "z": -6,
      "name": "Rock_Marble"
    },
    {
      "x": -1,
      "y": 13,
      "z": -6,
      "name": "Rock_Marble"
    },
    {
      "x": -1,
      "y": 14,
      "z": -6,
      "name": "Rock_Marble"
    },
    {
      "x": -1,
      "y": 15,
      "z": -6,
      "name": "Rock_Marble"
    },
    {
      "x": -1,
      "y": 16,
      "z": -6,
      "name": "Rock_Marble"
    },
    {
      "x": -1,
      "y": 17,
      "z": -6,
      "name": "Rock_Marble"
    },
    {
      "x": -1,
      "y": 18,
      "z": -6,
      "name": "Rock_Marble"
    },
    {
      "x": -1,
      "y": 0,
      "z": -5,
      "name": "Rock_Marble"
    },
    {
      "x": -1,
      "y": 1,
      "z": -5,
      "name": "Rock_Marble"
    },
    {
      "x": -1,
      "y": 2,
      "z": -5,
      "name": "Rock_Marble"
    },
    {
      "x": -1,
      "y": 3,
      "z": -5,
      "name": "Rock_Marble"
    },
    {
      "x": -1,
      "y": 4,
      "z": -5,
      "name": "Rock_Marble"
    },
    {
      "x": -1,
      "y": 5,
      "z": -5,
      "name": "Rock_Marble"
    },
    {
      "x": -1,
      "y": 6,
      "z": -5,
      "name": "Rock_Marble"
    },
    {
      "x": -1,
      "y": 7,
      "z": -5,
      "name": "Rock_Marble"
    },
    {
      "x": -1,
      "y": 8,
      "z": -5,
      "name": "Rock_Marble"
    },
    {
      "x": -1,
      "y": 9,
      "z": -5,
      "name": "Rock_Marble"
    },
    {
      "x": -1,
      "y": 10,
      "z": -5,
      "name": "Rock_Marble"
    },
    {
      "x": -1,
      "y": 11,
      "z": -5,
      "name": "Rock_Marble"
    },
    {
      "x": -1,
      "y": 12,
      "z": -5,
      "name": "Rock_Marble"
    },
    {
      "x": -1,
      "y": 13,
      "z": -5,
      "name": "Rock_Marble"
    },
    {
      "x": -1,
      "y": 14,
      "z": -5,
      "name": "Rock_Marble"
    },
    {
      "x": -1,
      "y": 15,
      "z": -5,
      "name": "Rock_Marble"
    },
    {
      "x": -1,
      "y": 16,
      "z": -5,
      "name": "Rock_Marble"
    },
    {
      "x": -1,
      "y": 17,
      "z": -5,
      "name": "Rock_Marble"
    },
    {
      "x": -1,
      "y": 18,
      "z": -5,
      "name": "Rock_Marble"
    },
    {
      "x": -1,
      "y": 19,
      "z": -5,
      "name": "Rock_Marble"
    },
    {
      "x": -1,
      "y": 23,
      "z": -5,
      "name": "Rock_Marble"
    },
    {
      "x": -1,
      "y": 24,
      "z": -5,
      "name": "Rock_Marble"
    },
    {
      "x": -1,
      "y": 25,
      "z": -5,
      "name": "Rock_Marble"
    },
    {
      "x": -1,
      "y": 26,
      "z": -5,
      "name": "Rock_Marble"
    },
    {
      "x": -1,
      "y": 27,
      "z": -5,
      "name": "Rock_Marble"
    },
    {
      "x": -1,
      "y": 28,
      "z": -5,
      "name": "Rock_Marble"
    },
    {
      "x": -1,
      "y": 0,
      "z": -4,
      "name": "Rock_Marble"
    },
    {
      "x": -1,
      "y": 1,
      "z": -4,
      "name": "Rock_Marble"
    },
    {
      "x": -1,
      "y": 2,
      "z": -4,
      "name": "Rock_Marble"
    },
    {
      "x": -1,
      "y": 3,
      "z": -4,
      "name": "Rock_Marble"
    },
    {
      "x": -1,
      "y": 4,
      "z": -4,
      "name": "Rock_Marble"
    },
    {
      "x": -1,
      "y": 5,
      "z": -4,
      "name": "Rock_Marble"
    },
    {
      "x": -1,
      "y": 6,
      "z": -4,
      "name": "Rock_Marble"
    },
    {
      "x": -1,
      "y": 7,
      "z": -4,
      "name": "Rock_Marble"
    },
    {
      "x": -1,
      "y": 8,
      "z": -4,
      "name": "Rock_Marble"
    },
    {
      "x": -1,
      "y": 9,
      "z": -4,
      "name": "Rock_Marble"
    },
    {
      "x": -1,
      "y": 10,
      "z": -4,
      "name": "Rock_Marble"
    },
    {
      "x": -1,
      "y": 11,
      "z": -4,
      "name": "Rock_Marble"
    },
    {
      "x": -1,
      "y": 12,
      "z": -4,
      "name": "Rock_Marble"
    },
    {
      "x": -1,
      "y": 13,
      "z": -4,
      "name": "Rock_Marble"
    },
    {
      "x": -1,
      "y": 14,
      "z": -4,
      "name": "Rock_Marble"
    },
    {
      "x": -1,
      "y": 15,
      "z": -4,
      "name": "Rock_Marble"
    },
    {
      "x": -1,
      "y": 16,
      "z": -4,
      "name": "Rock_Marble"
    },
    {
      "x": -1,
      "y": 17,
      "z": -4,
      "name": "Rock_Marble"
    },
    {
      "x": -1,
      "y": 18,
      "z": -4,
      "name": "Rock_Marble"
    },
    {
      "x": -1,
      "y": 19,
      "z": -4,
      "name": "Rock_Marble"
    },
    {
      "x": -1,
      "y": 20,
      "z": -4,
      "name": "Rock_Marble"
    },
    {
      "x": -1,
      "y": 21,
      "z": -4,
      "name": "Rock_Marble"
    },
    {
      "x": -1,
      "y": 22,
      "z": -4,
      "name": "Rock_Marble"
    },
    {
      "x": -1,
      "y": 23,
      "z": -4,
      "name": "Rock_Marble"
    },
    {
      "x": -1,
      "y": 24,
      "z": -4,
      "name": "Rock_Marble"
    },
    {
      "x": -1,
      "y": 25,
      "z": -4,
      "name": "Rock_Marble"
    },
    {
      "x": -1,
      "y": 26,
      "z": -4,
      "name": "Rock_Marble"
    },
    {
      "x": -1,
      "y": 27,
      "z": -4,
      "name": "Rock_Marble"
    },
    {
      "x": -1,
      "y": 28,
      "z": -4,
      "name": "Rock_Marble"
    },
    {
      "x": -1,
      "y": 29,
      "z": -4,
      "name": "Rock_Marble"
    },
    {
      "x": -1,
      "y": 30,
      "z": -4,
      "name": "Rock_Marble"
    },
    {
      "x": -1,
      "y": 31,
      "z": -4,
      "name": "Plant_Moss_Block_Green",
      "support": 15
    },
    {
      "x": -1,
      "y": 0,
      "z": -3,
      "name": "Rock_Marble"
    },
    {
      "x": -1,
      "y": 1,
      "z": -3,
      "name": "Rock_Marble"
    },
    {
      "x": -1,
      "y": 2,
      "z": -3,
      "name": "Rock_Marble"
    },
    {
      "x": -1,
      "y": 3,
      "z": -3,
      "name": "Rock_Marble"
    },
    {
      "x": -1,
      "y": 4,
      "z": -3,
      "name": "Rock_Marble"
    },
    {
      "x": -1,
      "y": 5,
      "z": -3,
      "name": "Rock_Marble"
    },
    {
      "x": -1,
      "y": 6,
      "z": -3,
      "name": "Rock_Marble"
    },
    {
      "x": -1,
      "y": 7,
      "z": -3,
      "name": "Rock_Marble"
    },
    {
      "x": -1,
      "y": 8,
      "z": -3,
      "name": "Rock_Marble"
    },
    {
      "x": -1,
      "y": 9,
      "z": -3,
      "name": "Rock_Marble"
    },
    {
      "x": -1,
      "y": 10,
      "z": -3,
      "name": "Rock_Marble"
    },
    {
      "x": -1,
      "y": 11,
      "z": -3,
      "name": "Rock_Marble"
    },
    {
      "x": -1,
      "y": 12,
      "z": -3,
      "name": "Rock_Marble"
    },
    {
      "x": -1,
      "y": 13,
      "z": -3,
      "name": "Rock_Marble"
    },
    {
      "x": -1,
      "y": 14,
      "z": -3,
      "name": "Rock_Marble"
    },
    {
      "x": -1,
      "y": 15,
      "z": -3,
      "name": "Rock_Marble"
    },
    {
      "x": -1,
      "y": 16,
      "z": -3,
      "name": "Rock_Marble"
    },
    {
      "x": -1,
      "y": 17,
      "z": -3,
      "name": "Rock_Marble"
    },
    {
      "x": -1,
      "y": 18,
      "z": -3,
      "name": "Rock_Marble"
    },
    {
      "x": -1,
      "y": 19,
      "z": -3,
      "name": "Rock_Marble"
    },
    {
      "x": -1,
      "y": 20,
      "z": -3,
      "name": "Rock_Marble"
    },
    {
      "x": -1,
      "y": 21,
      "z": -3,
      "name": "Rock_Marble"
    },
    {
      "x": -1,
      "y": 22,
      "z": -3,
      "name": "Rock_Marble"
    },
    {
      "x": -1,
      "y": 23,
      "z": -3,
      "name": "Rock_Marble"
    },
    {
      "x": -1,
      "y": 24,
      "z": -3,
      "name": "Rock_Marble"
    },
    {
      "x": -1,
      "y": 25,
      "z": -3,
      "name": "Rock_Marble"
    },
    {
      "x": -1,
      "y": 26,
      "z": -3,
      "name": "Rock_Marble"
    },
    {
      "x": -1,
      "y": 27,
      "z": -3,
      "name": "Rock_Marble"
    },
    {
      "x": -1,
      "y": 28,
      "z": -3,
      "name": "Rock_Marble"
    },
    {
      "x": -1,
      "y": 29,
      "z": -3,
      "name": "Rock_Marble"
    },
    {
      "x": -1,
      "y": 30,
      "z": -3,
      "name": "Rock_Marble"
    },
    {
      "x": -1,
      "y": 31,
      "z": -3,
      "name": "Rock_Marble"
    },
    {
      "x": -1,
      "y": 32,
      "z": -3,
      "name": "Plant_Moss_Block_Green",
      "support": 15
    },
    {
      "x": -1,
      "y": 33,
      "z": -3,
      "name": "Plant_Moss_Block_Green",
      "support": 15
    },
    {
      "x": -1,
      "y": 0,
      "z": -2,
      "name": "Rock_Marble"
    },
    {
      "x": -1,
      "y": 1,
      "z": -2,
      "name": "Rock_Marble"
    },
    {
      "x": -1,
      "y": 2,
      "z": -2,
      "name": "Rock_Marble"
    },
    {
      "x": -1,
      "y": 3,
      "z": -2,
      "name": "Rock_Marble"
    },
    {
      "x": -1,
      "y": 4,
      "z": -2,
      "name": "Rock_Marble"
    },
    {
      "x": -1,
      "y": 5,
      "z": -2,
      "name": "Rock_Marble"
    },
    {
      "x": -1,
      "y": 6,
      "z": -2,
      "name": "Rock_Marble"
    },
    {
      "x": -1,
      "y": 7,
      "z": -2,
      "name": "Rock_Marble"
    },
    {
      "x": -1,
      "y": 8,
      "z": -2,
      "name": "Rock_Marble"
    },
    {
      "x": -1,
      "y": 9,
      "z": -2,
      "name": "Rock_Marble"
    },
    {
      "x": -1,
      "y": 10,
      "z": -2,
      "name": "Rock_Marble"
    },
    {
      "x": -1,
      "y": 11,
      "z": -2,
      "name": "Rock_Marble"
    },
    {
      "x": -1,
      "y": 12,
      "z": -2,
      "name": "Rock_Marble"
    },
    {
      "x": -1,
      "y": 13,
      "z": -2,
      "name": "Rock_Marble"
    },
    {
      "x": -1,
      "y": 14,
      "z": -2,
      "name": "Rock_Marble"
    },
    {
      "x": -1,
      "y": 15,
      "z": -2,
      "name": "Rock_Marble"
    },
    {
      "x": -1,
      "y": 16,
      "z": -2,
      "name": "Rock_Marble"
    },
    {
      "x": -1,
      "y": 17,
      "z": -2,
      "name": "Rock_Marble"
    },
    {
      "x": -1,
      "y": 18,
      "z": -2,
      "name": "Rock_Marble"
    },
    {
      "x": -1,
      "y": 19,
      "z": -2,
      "name": "Rock_Marble"
    },
    {
      "x": -1,
      "y": 20,
      "z": -2,
      "name": "Rock_Marble"
    },
    {
      "x": -1,
      "y": 21,
      "z": -2,
      "name": "Rock_Marble"
    },
    {
      "x": -1,
      "y": 22,
      "z": -2,
      "name": "Rock_Marble"
    },
    {
      "x": -1,
      "y": 23,
      "z": -2,
      "name": "Rock_Marble"
    },
    {
      "x": -1,
      "y": 24,
      "z": -2,
      "name": "Rock_Marble"
    },
    {
      "x": -1,
      "y": 25,
      "z": -2,
      "name": "Rock_Marble"
    },
    {
      "x": -1,
      "y": 26,
      "z": -2,
      "name": "Rock_Marble"
    },
    {
      "x": -1,
      "y": 27,
      "z": -2,
      "name": "Rock_Marble"
    },
    {
      "x": -1,
      "y": 28,
      "z": -2,
      "name": "Rock_Marble"
    },
    {
      "x": -1,
      "y": 29,
      "z": -2,
      "name": "Rock_Marble"
    },
    {
      "x": -1,
      "y": 30,
      "z": -2,
      "name": "Rock_Marble"
    },
    {
      "x": -1,
      "y": 31,
      "z": -2,
      "name": "Rock_Marble"
    },
    {
      "x": -1,
      "y": 32,
      "z": -2,
      "name": "Rock_Marble"
    },
    {
      "x": -1,
      "y": 33,
      "z": -2,
      "name": "Rock_Marble"
    },
    {
      "x": -1,
      "y": 34,
      "z": -2,
      "name": "Plant_Moss_Block_Green",
      "support": 15
    },
    {
      "x": -1,
      "y": 0,
      "z": -1,
      "name": "Rock_Marble"
    },
    {
      "x": -1,
      "y": 1,
      "z": -1,
      "name": "Rock_Marble"
    },
    {
      "x": -1,
      "y": 2,
      "z": -1,
      "name": "Rock_Marble"
    },
    {
      "x": -1,
      "y": 3,
      "z": -1,
      "name": "Rock_Marble"
    },
    {
      "x": -1,
      "y": 4,
      "z": -1,
      "name": "Rock_Marble"
    },
    {
      "x": -1,
      "y": 5,
      "z": -1,
      "name": "Rock_Marble"
    },
    {
      "x": -1,
      "y": 6,
      "z": -1,
      "name": "Rock_Marble"
    },
    {
      "x": -1,
      "y": 7,
      "z": -1,
      "name": "Rock_Marble"
    },
    {
      "x": -1,
      "y": 8,
      "z": -1,
      "name": "Rock_Marble"
    },
    {
      "x": -1,
      "y": 9,
      "z": -1,
      "name": "Rock_Marble"
    },
    {
      "x": -1,
      "y": 10,
      "z": -1,
      "name": "Rock_Marble"
    },
    {
      "x": -1,
      "y": 11,
      "z": -1,
      "name": "Rock_Marble"
    },
    {
      "x": -1,
      "y": 12,
      "z": -1,
      "name": "Rock_Marble"
    },
    {
      "x": -1,
      "y": 13,
      "z": -1,
      "name": "Rock_Marble"
    },
    {
      "x": -1,
      "y": 14,
      "z": -1,
      "name": "Rock_Marble"
    },
    {
      "x": -1,
      "y": 15,
      "z": -1,
      "name": "Rock_Marble"
    },
    {
      "x": -1,
      "y": 16,
      "z": -1,
      "name": "Rock_Marble"
    },
    {
      "x": -1,
      "y": 17,
      "z": -1,
      "name": "Rock_Marble"
    },
    {
      "x": -1,
      "y": 18,
      "z": -1,
      "name": "Rock_Marble"
    },
    {
      "x": -1,
      "y": 19,
      "z": -1,
      "name": "Rock_Marble"
    },
    {
      "x": -1,
      "y": 20,
      "z": -1,
      "name": "Rock_Marble"
    },
    {
      "x": -1,
      "y": 21,
      "z": -1,
      "name": "Rock_Marble"
    },
    {
      "x": -1,
      "y": 22,
      "z": -1,
      "name": "Rock_Marble"
    },
    {
      "x": -1,
      "y": 23,
      "z": -1,
      "name": "Rock_Marble"
    },
    {
      "x": -1,
      "y": 24,
      "z": -1,
      "name": "Rock_Marble"
    },
    {
      "x": -1,
      "y": 25,
      "z": -1,
      "name": "Rock_Marble"
    },
    {
      "x": -1,
      "y": 26,
      "z": -1,
      "name": "Rock_Marble"
    },
    {
      "x": -1,
      "y": 27,
      "z": -1,
      "name": "Rock_Marble"
    },
    {
      "x": -1,
      "y": 28,
      "z": -1,
      "name": "Rock_Marble"
    },
    {
      "x": -1,
      "y": 29,
      "z": -1,
      "name": "Rock_Marble"
    },
    {
      "x": -1,
      "y": 30,
      "z": -1,
      "name": "Rock_Marble"
    },
    {
      "x": -1,
      "y": 31,
      "z": -1,
      "name": "Rock_Marble"
    },
    {
      "x": -1,
      "y": 32,
      "z": -1,
      "name": "Rock_Marble"
    },
    {
      "x": -1,
      "y": 33,
      "z": -1,
      "name": "Rock_Marble"
    },
    {
      "x": -1,
      "y": 34,
      "z": -1,
      "name": "Plant_Moss_Block_Green",
      "support": 15
    },
    {
      "x": -1,
      "y": 0,
      "z": 0,
      "name": "Rock_Marble"
    },
    {
      "x": -1,
      "y": 1,
      "z": 0,
      "name": "Rock_Marble"
    },
    {
      "x": -1,
      "y": 2,
      "z": 0,
      "name": "Rock_Marble"
    },
    {
      "x": -1,
      "y": 3,
      "z": 0,
      "name": "Rock_Marble"
    },
    {
      "x": -1,
      "y": 4,
      "z": 0,
      "name": "Rock_Marble"
    },
    {
      "x": -1,
      "y": 5,
      "z": 0,
      "name": "Rock_Marble"
    },
    {
      "x": -1,
      "y": 6,
      "z": 0,
      "name": "Rock_Marble"
    },
    {
      "x": -1,
      "y": 7,
      "z": 0,
      "name": "Rock_Marble"
    },
    {
      "x": -1,
      "y": 8,
      "z": 0,
      "name": "Rock_Marble"
    },
    {
      "x": -1,
      "y": 9,
      "z": 0,
      "name": "Rock_Marble"
    },
    {
      "x": -1,
      "y": 10,
      "z": 0,
      "name": "Rock_Marble"
    },
    {
      "x": -1,
      "y": 11,
      "z": 0,
      "name": "Rock_Marble"
    },
    {
      "x": -1,
      "y": 12,
      "z": 0,
      "name": "Rock_Marble"
    },
    {
      "x": -1,
      "y": 13,
      "z": 0,
      "name": "Rock_Marble"
    },
    {
      "x": -1,
      "y": 14,
      "z": 0,
      "name": "Rock_Marble"
    },
    {
      "x": -1,
      "y": 15,
      "z": 0,
      "name": "Rock_Marble"
    },
    {
      "x": -1,
      "y": 16,
      "z": 0,
      "name": "Rock_Marble"
    },
    {
      "x": -1,
      "y": 17,
      "z": 0,
      "name": "Rock_Marble"
    },
    {
      "x": -1,
      "y": 18,
      "z": 0,
      "name": "Rock_Marble"
    },
    {
      "x": -1,
      "y": 19,
      "z": 0,
      "name": "Rock_Marble"
    },
    {
      "x": -1,
      "y": 20,
      "z": 0,
      "name": "Rock_Marble"
    },
    {
      "x": -1,
      "y": 21,
      "z": 0,
      "name": "Rock_Marble"
    },
    {
      "x": -1,
      "y": 22,
      "z": 0,
      "name": "Rock_Marble"
    },
    {
      "x": -1,
      "y": 23,
      "z": 0,
      "name": "Rock_Marble"
    },
    {
      "x": -1,
      "y": 24,
      "z": 0,
      "name": "Rock_Marble"
    },
    {
      "x": -1,
      "y": 25,
      "z": 0,
      "name": "Rock_Marble"
    },
    {
      "x": -1,
      "y": 26,
      "z": 0,
      "name": "Rock_Marble"
    },
    {
      "x": -1,
      "y": 27,
      "z": 0,
      "name": "Rock_Marble"
    },
    {
      "x": -1,
      "y": 28,
      "z": 0,
      "name": "Rock_Marble"
    },
    {
      "x": -1,
      "y": 29,
      "z": 0,
      "name": "Rock_Marble"
    },
    {
      "x": -1,
      "y": 30,
      "z": 0,
      "name": "Rock_Marble"
    },
    {
      "x": -1,
      "y": 31,
      "z": 0,
      "name": "Rock_Marble"
    },
    {
      "x": -1,
      "y": 32,
      "z": 0,
      "name": "Rock_Marble"
    },
    {
      "x": -1,
      "y": 33,
      "z": 0,
      "name": "Plant_Moss_Block_Green",
      "support": 15
    },
    {
      "x": -1,
      "y": 34,
      "z": 0,
      "name": "Plant_Moss_Block_Green",
      "support": 15
    },
    {
      "x": -1,
      "y": 0,
      "z": 1,
      "name": "Rock_Marble"
    },
    {
      "x": -1,
      "y": 1,
      "z": 1,
      "name": "Rock_Marble"
    },
    {
      "x": -1,
      "y": 2,
      "z": 1,
      "name": "Rock_Marble"
    },
    {
      "x": -1,
      "y": 3,
      "z": 1,
      "name": "Rock_Marble"
    },
    {
      "x": -1,
      "y": 4,
      "z": 1,
      "name": "Rock_Marble"
    },
    {
      "x": -1,
      "y": 5,
      "z": 1,
      "name": "Rock_Marble"
    },
    {
      "x": -1,
      "y": 6,
      "z": 1,
      "name": "Rock_Marble"
    },
    {
      "x": -1,
      "y": 7,
      "z": 1,
      "name": "Rock_Marble"
    },
    {
      "x": -1,
      "y": 8,
      "z": 1,
      "name": "Rock_Marble"
    },
    {
      "x": -1,
      "y": 13,
      "z": 1,
      "name": "Rock_Marble"
    },
    {
      "x": -1,
      "y": 14,
      "z": 1,
      "name": "Rock_Marble"
    },
    {
      "x": -1,
      "y": 15,
      "z": 1,
      "name": "Rock_Marble"
    },
    {
      "x": -1,
      "y": 16,
      "z": 1,
      "name": "Rock_Marble"
    },
    {
      "x": -1,
      "y": 17,
      "z": 1,
      "name": "Rock_Marble"
    },
    {
      "x": -1,
      "y": 18,
      "z": 1,
      "name": "Rock_Marble"
    },
    {
      "x": -1,
      "y": 19,
      "z": 1,
      "name": "Rock_Marble"
    },
    {
      "x": -1,
      "y": 20,
      "z": 1,
      "name": "Rock_Marble"
    },
    {
      "x": -1,
      "y": 21,
      "z": 1,
      "name": "Rock_Marble"
    },
    {
      "x": -1,
      "y": 22,
      "z": 1,
      "name": "Rock_Marble"
    },
    {
      "x": -1,
      "y": 23,
      "z": 1,
      "name": "Rock_Marble"
    },
    {
      "x": -1,
      "y": 24,
      "z": 1,
      "name": "Rock_Marble"
    },
    {
      "x": -1,
      "y": 25,
      "z": 1,
      "name": "Rock_Marble"
    },
    {
      "x": -1,
      "y": 26,
      "z": 1,
      "name": "Rock_Marble"
    },
    {
      "x": -1,
      "y": 27,
      "z": 1,
      "name": "Rock_Marble"
    },
    {
      "x": -1,
      "y": 28,
      "z": 1,
      "name": "Rock_Marble"
    },
    {
      "x": -1,
      "y": 29,
      "z": 1,
      "name": "Rock_Marble"
    },
    {
      "x": -1,
      "y": 30,
      "z": 1,
      "name": "Rock_Marble"
    },
    {
      "x": -1,
      "y": 31,
      "z": 1,
      "name": "Plant_Moss_Block_Green",
      "support": 15
    },
    {
      "x": -1,
      "y": 32,
      "z": 1,
      "name": "Plant_Moss_Block_Green",
      "support": 15
    },
    {
      "x": -1,
      "y": 33,
      "z": 1,
      "name": "Plant_Moss_Block_Green",
      "support": 15
    },
    {
      "x": -1,
      "y": 0,
      "z": 2,
      "name": "Rock_Marble"
    },
    {
      "x": -1,
      "y": 1,
      "z": 2,
      "name": "Rock_Marble"
    },
    {
      "x": -1,
      "y": 2,
      "z": 2,
      "name": "Rock_Marble"
    },
    {
      "x": -1,
      "y": 3,
      "z": 2,
      "name": "Rock_Marble"
    },
    {
      "x": -1,
      "y": 4,
      "z": 2,
      "name": "Rock_Marble"
    },
    {
      "x": -1,
      "y": 5,
      "z": 2,
      "name": "Rock_Marble"
    },
    {
      "x": -1,
      "y": 6,
      "z": 2,
      "name": "Rock_Marble"
    },
    {
      "x": -1,
      "y": 15,
      "z": 2,
      "name": "Rock_Marble"
    },
    {
      "x": -1,
      "y": 16,
      "z": 2,
      "name": "Rock_Marble"
    },
    {
      "x": -1,
      "y": 17,
      "z": 2,
      "name": "Rock_Marble"
    },
    {
      "x": -1,
      "y": 18,
      "z": 2,
      "name": "Rock_Marble"
    },
    {
      "x": -1,
      "y": 19,
      "z": 2,
      "name": "Rock_Marble"
    },
    {
      "x": -1,
      "y": 20,
      "z": 2,
      "name": "Rock_Marble"
    },
    {
      "x": -1,
      "y": 21,
      "z": 2,
      "name": "Rock_Marble"
    },
    {
      "x": -1,
      "y": 22,
      "z": 2,
      "name": "Rock_Marble"
    },
    {
      "x": -1,
      "y": 23,
      "z": 2,
      "name": "Rock_Marble"
    },
    {
      "x": -1,
      "y": 0,
      "z": 3,
      "name": "Rock_Marble"
    },
    {
      "x": -1,
      "y": 1,
      "z": 3,
      "name": "Rock_Marble"
    },
    {
      "x": -1,
      "y": 2,
      "z": 3,
      "name": "Rock_Marble"
    },
    {
      "x": -1,
      "y": 3,
      "z": 3,
      "name": "Rock_Marble"
    },
    {
      "x": -1,
      "y": 4,
      "z": 3,
      "name": "Rock_Marble"
    },
    {
      "x": -1,
      "y": 5,
      "z": 3,
      "name": "Rock_Marble"
    },
    {
      "x": -1,
      "y": 16,
      "z": 3,
      "name": "Rock_Marble"
    },
    {
      "x": -1,
      "y": 17,
      "z": 3,
      "name": "Rock_Marble"
    },
    {
      "x": -1,
      "y": 18,
      "z": 3,
      "name": "Rock_Marble"
    },
    {
      "x": -1,
      "y": 19,
      "z": 3,
      "name": "Rock_Marble"
    },
    {
      "x": -1,
      "y": 0,
      "z": 4,
      "name": "Rock_Marble"
    },
    {
      "x": -1,
      "y": 1,
      "z": 4,
      "name": "Rock_Marble"
    },
    {
      "x": -1,
      "y": 2,
      "z": 4,
      "name": "Rock_Marble"
    },
    {
      "x": -1,
      "y": 3,
      "z": 4,
      "name": "Rock_Marble"
    },
    {
      "x": -1,
      "y": 4,
      "z": 4,
      "name": "Rock_Marble"
    },
    {
      "x": -1,
      "y": 17,
      "z": 4,
      "name": "Rock_Marble"
    },
    {
      "x": -1,
      "y": 18,
      "z": 4,
      "name": "Rock_Marble"
    },
    {
      "x": -1,
      "y": 1,
      "z": 5,
      "name": "Rock_Marble"
    },
    {
      "x": -1,
      "y": 2,
      "z": 5,
      "name": "Rock_Marble"
    },
    {
      "x": 0,
      "y": 1,
      "z": -8,
      "name": "Rock_Marble"
    },
    {
      "x": 0,
      "y": 2,
      "z": -8,
      "name": "Rock_Marble"
    },
    {
      "x": 0,
      "y": 3,
      "z": -8,
      "name": "Rock_Marble"
    },
    {
      "x": 0,
      "y": 4,
      "z": -8,
      "name": "Rock_Marble"
    },
    {
      "x": 0,
      "y": 5,
      "z": -8,
      "name": "Rock_Marble"
    },
    {
      "x": 0,
      "y": 6,
      "z": -8,
      "name": "Rock_Marble"
    },
    {
      "x": 0,
      "y": 7,
      "z": -8,
      "name": "Rock_Marble"
    },
    {
      "x": 0,
      "y": 8,
      "z": -8,
      "name": "Rock_Marble"
    },
    {
      "x": 0,
      "y": 9,
      "z": -8,
      "name": "Rock_Marble"
    },
    {
      "x": 0,
      "y": 10,
      "z": -8,
      "name": "Rock_Marble"
    },
    {
      "x": 0,
      "y": 0,
      "z": -7,
      "name": "Rock_Marble"
    },
    {
      "x": 0,
      "y": 1,
      "z": -7,
      "name": "Rock_Marble"
    },
    {
      "x": 0,
      "y": 2,
      "z": -7,
      "name": "Rock_Marble"
    },
    {
      "x": 0,
      "y": 3,
      "z": -7,
      "name": "Rock_Marble"
    },
    {
      "x": 0,
      "y": 4,
      "z": -7,
      "name": "Rock_Marble"
    },
    {
      "x": 0,
      "y": 5,
      "z": -7,
      "name": "Rock_Marble"
    },
    {
      "x": 0,
      "y": 6,
      "z": -7,
      "name": "Rock_Marble"
    },
    {
      "x": 0,
      "y": 7,
      "z": -7,
      "name": "Rock_Marble"
    },
    {
      "x": 0,
      "y": 8,
      "z": -7,
      "name": "Rock_Marble"
    },
    {
      "x": 0,
      "y": 9,
      "z": -7,
      "name": "Rock_Marble"
    },
    {
      "x": 0,
      "y": 10,
      "z": -7,
      "name": "Rock_Marble"
    },
    {
      "x": 0,
      "y": 11,
      "z": -7,
      "name": "Rock_Marble"
    },
    {
      "x": 0,
      "y": 12,
      "z": -7,
      "name": "Rock_Marble"
    },
    {
      "x": 0,
      "y": 13,
      "z": -7,
      "name": "Rock_Marble"
    },
    {
      "x": 0,
      "y": 14,
      "z": -7,
      "name": "Rock_Marble"
    },
    {
      "x": 0,
      "y": 15,
      "z": -7,
      "name": "Rock_Marble"
    },
    {
      "x": 0,
      "y": 16,
      "z": -7,
      "name": "Rock_Marble"
    },
    {
      "x": 0,
      "y": 17,
      "z": -7,
      "name": "Rock_Marble"
    },
    {
      "x": 0,
      "y": 18,
      "z": -7,
      "name": "Rock_Marble"
    },
    {
      "x": 0,
      "y": 0,
      "z": -6,
      "name": "Rock_Marble"
    },
    {
      "x": 0,
      "y": 1,
      "z": -6,
      "name": "Rock_Marble"
    },
    {
      "x": 0,
      "y": 2,
      "z": -6,
      "name": "Rock_Marble"
    },
    {
      "x": 0,
      "y": 3,
      "z": -6,
      "name": "Rock_Marble"
    },
    {
      "x": 0,
      "y": 4,
      "z": -6,
      "name": "Rock_Marble"
    },
    {
      "x": 0,
      "y": 5,
      "z": -6,
      "name": "Rock_Marble"
    },
    {
      "x": 0,
      "y": 6,
      "z": -6,
      "name": "Rock_Marble"
    },
    {
      "x": 0,
      "y": 7,
      "z": -6,
      "name": "Rock_Marble"
    },
    {
      "x": 0,
      "y": 8,
      "z": -6,
      "name": "Rock_Marble"
    },
    {
      "x": 0,
      "y": 9,
      "z": -6,
      "name": "Rock_Marble"
    },
    {
      "x": 0,
      "y": 10,
      "z": -6,
      "name": "Rock_Marble"
    },
    {
      "x": 0,
      "y": 11,
      "z": -6,
      "name": "Rock_Marble"
    },
    {
      "x": 0,
      "y": 12,
      "z": -6,
      "name": "Rock_Marble"
    },
    {
      "x": 0,
      "y": 13,
      "z": -6,
      "name": "Rock_Marble"
    },
    {
      "x": 0,
      "y": 14,
      "z": -6,
      "name": "Rock_Marble"
    },
    {
      "x": 0,
      "y": 15,
      "z": -6,
      "name": "Rock_Marble"
    },
    {
      "x": 0,
      "y": 16,
      "z": -6,
      "name": "Rock_Marble"
    },
    {
      "x": 0,
      "y": 17,
      "z": -6,
      "name": "Rock_Marble"
    },
    {
      "x": 0,
      "y": 18,
      "z": -6,
      "name": "Rock_Marble"
    },
    {
      "x": 0,
      "y": 19,
      "z": -6,
      "name": "Rock_Marble"
    },
    {
      "x": 0,
      "y": 20,
      "z": -6,
      "name": "Rock_Marble"
    },
    {
      "x": 0,
      "y": 24,
      "z": -6,
      "name": "Rock_Marble"
    },
    {
      "x": 0,
      "y": 25,
      "z": -6,
      "name": "Rock_Marble"
    },
    {
      "x": 0,
      "y": 26,
      "z": -6,
      "name": "Rock_Marble"
    },
    {
      "x": 0,
      "y": 27,
      "z": -6,
      "name": "Rock_Marble"
    },
    {
      "x": 0,
      "y": 0,
      "z": -5,
      "name": "Rock_Marble"
    },
    {
      "x": 0,
      "y": 1,
      "z": -5,
      "name": "Rock_Marble"
    },
    {
      "x": 0,
      "y": 2,
      "z": -5,
      "name": "Rock_Marble"
    },
    {
      "x": 0,
      "y": 3,
      "z": -5,
      "name": "Rock_Marble"
    },
    {
      "x": 0,
      "y": 4,
      "z": -5,
      "name": "Rock_Marble"
    },
    {
      "x": 0,
      "y": 5,
      "z": -5,
      "name": "Rock_Marble"
    },
    {
      "x": 0,
      "y": 6,
      "z": -5,
      "name": "Rock_Marble"
    },
    {
      "x": 0,
      "y": 7,
      "z": -5,
      "name": "Rock_Marble"
    },
    {
      "x": 0,
      "y": 8,
      "z": -5,
      "name": "Rock_Marble"
    },
    {
      "x": 0,
      "y": 9,
      "z": -5,
      "name": "Rock_Marble"
    },
    {
      "x": 0,
      "y": 10,
      "z": -5,
      "name": "Rock_Marble"
    },
    {
      "x": 0,
      "y": 11,
      "z": -5,
      "name": "Rock_Marble"
    },
    {
      "x": 0,
      "y": 12,
      "z": -5,
      "name": "Rock_Marble"
    },
    {
      "x": 0,
      "y": 13,
      "z": -5,
      "name": "Rock_Marble"
    },
    {
      "x": 0,
      "y": 14,
      "z": -5,
      "name": "Rock_Marble"
    },
    {
      "x": 0,
      "y": 15,
      "z": -5,
      "name": "Rock_Marble"
    },
    {
      "x": 0,
      "y": 16,
      "z": -5,
      "name": "Rock_Marble"
    },
    {
      "x": 0,
      "y": 17,
      "z": -5,
      "name": "Rock_Marble"
    },
    {
      "x": 0,
      "y": 18,
      "z": -5,
      "name": "Rock_Marble"
    },
    {
      "x": 0,
      "y": 19,
      "z": -5,
      "name": "Rock_Marble"
    },
    {
      "x": 0,
      "y": 20,
      "z": -5,
      "name": "Rock_Marble"
    },
    {
      "x": 0,
      "y": 21,
      "z": -5,
      "name": "Rock_Marble"
    },
    {
      "x": 0,
      "y": 22,
      "z": -5,
      "name": "Rock_Marble"
    },
    {
      "x": 0,
      "y": 23,
      "z": -5,
      "name": "Rock_Marble"
    },
    {
      "x": 0,
      "y": 24,
      "z": -5,
      "name": "Rock_Marble"
    },
    {
      "x": 0,
      "y": 25,
      "z": -5,
      "name": "Rock_Marble"
    },
    {
      "x": 0,
      "y": 26,
      "z": -5,
      "name": "Rock_Marble"
    },
    {
      "x": 0,
      "y": 27,
      "z": -5,
      "name": "Rock_Marble"
    },
    {
      "x": 0,
      "y": 28,
      "z": -5,
      "name": "Rock_Marble"
    },
    {
      "x": 0,
      "y": 29,
      "z": -5,
      "name": "Rock_Marble"
    },
    {
      "x": 0,
      "y": 0,
      "z": -4,
      "name": "Rock_Marble"
    },
    {
      "x": 0,
      "y": 1,
      "z": -4,
      "name": "Rock_Marble"
    },
    {
      "x": 0,
      "y": 2,
      "z": -4,
      "name": "Rock_Marble"
    },
    {
      "x": 0,
      "y": 3,
      "z": -4,
      "name": "Rock_Marble"
    },
    {
      "x": 0,
      "y": 4,
      "z": -4,
      "name": "Rock_Marble"
    },
    {
      "x": 0,
      "y": 5,
      "z": -4,
      "name": "Rock_Marble"
    },
    {
      "x": 0,
      "y": 6,
      "z": -4,
      "name": "Rock_Marble"
    },
    {
      "x": 0,
      "y": 7,
      "z": -4,
      "name": "Rock_Marble"
    },
    {
      "x": 0,
      "y": 8,
      "z": -4,
      "name": "Rock_Marble"
    },
    {
      "x": 0,
      "y": 9,
      "z": -4,
      "name": "Rock_Marble"
    },
    {
      "x": 0,
      "y": 10,
      "z": -4,
      "name": "Rock_Marble"
    },
    {
      "x": 0,
      "y": 11,
      "z": -4,
      "name": "Rock_Marble"
    },
    {
      "x": 0,
      "y": 12,
      "z": -4,
      "name": "Rock_Marble"
    },
    {
      "x": 0,
      "y": 13,
      "z": -4,
      "name": "Rock_Marble"
    },
    {
      "x": 0,
      "y": 14,
      "z": -4,
      "name": "Rock_Marble"
    },
    {
      "x": 0,
      "y": 15,
      "z": -4,
      "name": "Rock_Marble"
    },
    {
      "x": 0,
      "y": 16,
      "z": -4,
      "name": "Rock_Marble"
    },
    {
      "x": 0,
      "y": 17,
      "z": -4,
      "name": "Rock_Marble"
    },
    {
      "x": 0,
      "y": 18,
      "z": -4,
      "name": "Rock_Marble"
    },
    {
      "x": 0,
      "y": 19,
      "z": -4,
      "name": "Rock_Marble"
    },
    {
      "x": 0,
      "y": 20,
      "z": -4,
      "name": "Rock_Marble"
    },
    {
      "x": 0,
      "y": 21,
      "z": -4,
      "name": "Rock_Marble"
    },
    {
      "x": 0,
      "y": 22,
      "z": -4,
      "name": "Rock_Marble"
    },
    {
      "x": 0,
      "y": 23,
      "z": -4,
      "name": "Rock_Marble"
    },
    {
      "x": 0,
      "y": 24,
      "z": -4,
      "name": "Rock_Marble"
    },
    {
      "x": 0,
      "y": 25,
      "z": -4,
      "name": "Rock_Marble"
    },
    {
      "x": 0,
      "y": 26,
      "z": -4,
      "name": "Rock_Marble"
    },
    {
      "x": 0,
      "y": 27,
      "z": -4,
      "name": "Rock_Marble"
    },
    {
      "x": 0,
      "y": 28,
      "z": -4,
      "name": "Rock_Marble"
    },
    {
      "x": 0,
      "y": 29,
      "z": -4,
      "name": "Rock_Marble"
    },
    {
      "x": 0,
      "y": 30,
      "z": -4,
      "name": "Rock_Marble"
    },
    {
      "x": 0,
      "y": 31,
      "z": -4,
      "name": "Rock_Marble"
    },
    {
      "x": 0,
      "y": 32,
      "z": -4,
      "name": "Plant_Moss_Block_Green",
      "support": 15
    },
    {
      "x": 0,
      "y": 33,
      "z": -4,
      "name": "Plant_Moss_Block_Green",
      "support": 15
    },
    {
      "x": 0,
      "y": 0,
      "z": -3,
      "name": "Rock_Marble"
    },
    {
      "x": 0,
      "y": 1,
      "z": -3,
      "name": "Rock_Marble"
    },
    {
      "x": 0,
      "y": 2,
      "z": -3,
      "name": "Rock_Marble"
    },
    {
      "x": 0,
      "y": 3,
      "z": -3,
      "name": "Rock_Marble"
    },
    {
      "x": 0,
      "y": 4,
      "z": -3,
      "name": "Rock_Marble"
    },
    {
      "x": 0,
      "y": 5,
      "z": -3,
      "name": "Rock_Marble"
    },
    {
      "x": 0,
      "y": 6,
      "z": -3,
      "name": "Rock_Marble"
    },
    {
      "x": 0,
      "y": 7,
      "z": -3,
      "name": "Rock_Marble"
    },
    {
      "x": 0,
      "y": 8,
      "z": -3,
      "name": "Rock_Marble"
    },
    {
      "x": 0,
      "y": 9,
      "z": -3,
      "name": "Rock_Marble"
    },
    {
      "x": 0,
