{
  "version": 8,
  "blockIdVersion": 11,
  "anchorX": -1,
  "anchorY": 5,
  "anchorZ": 2,
  "blocks": [
    {
      "x": -6,
      "y": 4,
      "z": 0,
      "name": "Rock_Marble_Cobble",
      "rotation": 1
    },
    {
      "x": -6,
      "y": 5,
      "z": 0,
      "name": "Rock_Marble_Cobble",
      "rotation": 1
    },
    {
      "x": -6,
      "y": 6,
      "z": 0,
      "name": "Rock_Marble_Cobble",
      "rotation": 1
    },
    {
      "x": -6,
      "y": 7,
      "z": 0,
      "name": "Rock_Marble",
      "rotation": 1
    },
    {
      "x": -6,
      "y": 8,
      "z": 0,
      "name": "Rock_Chalk",
      "rotation": 1
    },
    {
      "x": -6,
      "y": 4,
      "z": 1,
      "name": "Rock_Marble_Cobble",
      "rotation": 1
    },
    {
      "x": -6,
      "y": 5,
      "z": 1,
      "name": "Rock_Marble_Cobble",
      "rotation": 1
    },
    {
      "x": -6,
      "y": 6,
      "z": 1,
      "name": "Rock_Marble_Cobble",
      "rotation": 1
    },
    {
      "x": -6,
      "y": 7,
      "z": 1,
      "name": "Rock_Marble",
      "rotation": 1
    },
    {
      "x": -6,
      "y": 8,
      "z": 1,
      "name": "Rock_Chalk",
      "rotation": 1
    },
    {
      "x": -6,
      "y": 9,
      "z": 1,
      "name": "Rock_Chalk",
      "rotation": 1
    },
    {
      "x": -6,
      "y": 4,
      "z": 2,
      "name": "Rock_Marble_Cobble",
      "rotation": 1
    },
    {
      "x": -6,
      "y": 5,
      "z": 2,
      "name": "Rock_Marble_Cobble",
      "rotation": 1
    },
    {
      "x": -6,
      "y": 6,
      "z": 2,
      "name": "Rock_Marble_Cobble",
      "rotation": 1
    },
    {
      "x": -6,
      "y": 7,
      "z": 2,
      "name": "Rock_Marble",
      "rotation": 1
    },
    {
      "x": -6,
      "y": 8,
      "z": 2,
      "name": "Rock_Chalk",
      "rotation": 1
    },
    {
      "x": -5,
      "y": 5,
      "z": -2,
      "name": "Rock_Marble_Cobble",
      "rotation": 1
    },
    {
      "x": -5,
      "y": 6,
      "z": -2,
      "name": "Rock_Marble_Cobble",
      "rotation": 1
    },
    {
      "x": -5,
      "y": 7,
      "z": -2,
      "name": "Rock_Marble",
      "rotation": 1
    },
    {
      "x": -5,
      "y": 8,
      "z": -2,
      "name": "Rock_Chalk",
      "rotation": 1
    },
    {
      "x": -5,
      "y": 9,
      "z": -2,
      "name": "Rock_Chalk",
      "rotation": 1
    },
    {
      "x": -5,
      "y": 2,
      "z": -1,
      "name": "Rock_Marble_Cobble",
      "rotation": 1
    },
    {
      "x": -5,
      "y": 3,
      "z": -1,
      "name": "Rock_Marble_Cobble",
      "rotation": 1
    },
    {
      "x": -5,
      "y": 4,
      "z": -1,
      "name": "Rock_Marble_Cobble",
      "rotation": 1
    },
    {
      "x": -5,
      "y": 5,
      "z": -1,
      "name": "Rock_Marble_Cobble",
      "rotation": 1
    },
    {
      "x": -5,
      "y": 6,
      "z": -1,
      "name": "Rock_Marble_Cobble",
      "rotation": 1
    },
    {
      "x": -5,
      "y": 7,
      "z": -1,
      "name": "Rock_Marble",
      "rotation": 1
    },
    {
      "x": -5,
      "y": 8,
      "z": -1,
      "name": "Rock_Chalk",
      "rotation": 1
    },
    {
      "x": -5,
      "y": 9,
      "z": -1,
      "name": "Rock_Chalk",
      "rotation": 1
    },
    {
      "x": -5,
      "y": 10,
      "z": -1,
      "name": "Rock_Chalk",
      "rotation": 1
    },
    {
      "x": -5,
      "y": 1,
      "z": 0,
      "name": "Soil_Clay_White",
      "rotation": 1
    },
    {
      "x": -5,
      "y": 2,
      "z": 0,
      "name": "Rock_Marble_Cobble",
      "rotation": 1
    },
    {
      "x": -5,
      "y": 3,
      "z": 0,
      "name": "Rock_Marble_Cobble",
      "rotation": 1
    },
    {
      "x": -5,
      "y": 4,
      "z": 0,
      "name": "Rock_Marble_Cobble",
      "rotation": 1
    },
    {
      "x": -5,
      "y": 5,
      "z": 0,
      "name": "Rock_Marble_Cobble",
      "rotation": 1
    },
    {
      "x": -5,
      "y": 6,
      "z": 0,
      "name": "Rock_Marble_Cobble",
      "rotation": 1
    },
    {
      "x": -5,
      "y": 7,
      "z": 0,
      "name": "Rock_Marble",
      "rotation": 1
    },
    {
      "x": -5,
      "y": 8,
      "z": 0,
      "name": "Rock_Chalk",
      "rotation": 1
    },
    {
      "x": -5,
      "y": 9,
      "z": 0,
      "name": "Rock_Chalk",
      "rotation": 1
    },
    {
      "x": -5,
      "y": 10,
      "z": 0,
      "name": "Rock_Chalk",
      "rotation": 1
    },
    {
      "x": -5,
      "y": 1,
      "z": 1,
      "name": "Soil_Clay_White",
      "rotation": 1
    },
    {
      "x": -5,
      "y": 2,
      "z": 1,
      "name": "Rock_Marble_Cobble",
      "rotation": 1
    },
    {
      "x": -5,
      "y": 3,
      "z": 1,
      "name": "Rock_Marble_Cobble",
      "rotation": 1
    },
    {
      "x": -5,
      "y": 4,
      "z": 1,
      "name": "Rock_Marble_Cobble",
      "rotation": 1
    },
    {
      "x": -5,
      "y": 5,
      "z": 1,
      "name": "Rock_Marble_Cobble",
      "rotation": 1
    },
    {
      "x": -5,
      "y": 6,
      "z": 1,
      "name": "Rock_Marble_Cobble",
      "rotation": 1
    },
    {
      "x": -5,
      "y": 7,
      "z": 1,
      "name": "Rock_Marble",
      "rotation": 1
    },
    {
      "x": -5,
      "y": 8,
      "z": 1,
      "name": "Rock_Chalk",
      "rotation": 1
    },
    {
      "x": -5,
      "y": 9,
      "z": 1,
      "name": "Rock_Chalk",
      "rotation": 1
    },
    {
      "x": -5,
      "y": 10,
      "z": 1,
      "name": "Rock_Chalk",
      "rotation": 1
    },
    {
      "x": -5,
      "y": 11,
      "z": 1,
      "name": "Rock_Chalk",
      "rotation": 1
    },
    {
      "x": -5,
      "y": 2,
      "z": 2,
      "name": "Rock_Marble_Cobble",
      "rotation": 1
    },
    {
      "x": -5,
      "y": 3,
      "z": 2,
      "name": "Rock_Marble_Cobble",
      "rotation": 1
    },
    {
      "x": -5,
      "y": 4,
      "z": 2,
      "name": "Rock_Marble_Cobble",
      "rotation": 1
    },
    {
      "x": -5,
      "y": 5,
      "z": 2,
      "name": "Rock_Marble_Cobble",
      "rotation": 1
    },
    {
      "x": -5,
      "y": 6,
      "z": 2,
      "name": "Rock_Marble_Cobble",
      "rotation": 1
    },
    {
      "x": -5,
      "y": 7,
      "z": 2,
      "name": "Rock_Marble",
      "rotation": 1
    },
    {
      "x": -5,
      "y": 8,
      "z": 2,
      "name": "Rock_Chalk",
      "rotation": 1
    },
    {
      "x": -5,
      "y": 9,
      "z": 2,
      "name": "Rock_Chalk",
      "rotation": 1
    },
    {
      "x": -5,
      "y": 10,
      "z": 2,
      "name": "Rock_Chalk",
      "rotation": 1
    },
    {
      "x": -5,
      "y": 11,
      "z": 2,
      "name": "Rock_Chalk",
      "rotation": 1
    },
    {
      "x": -5,
      "y": 3,
      "z": 3,
      "name": "Rock_Marble_Cobble",
      "rotation": 1
    },
    {
      "x": -5,
      "y": 4,
      "z": 3,
      "name": "Rock_Marble_Cobble",
      "rotation": 1
    },
    {
      "x": -5,
      "y": 5,
      "z": 3,
      "name": "Rock_Marble_Cobble",
      "rotation": 1
    },
    {
      "x": -5,
      "y": 6,
      "z": 3,
      "name": "Rock_Marble_Cobble",
      "rotation": 1
    },
    {
      "x": -5,
      "y": 7,
      "z": 3,
      "name": "Rock_Marble",
      "rotation": 1
    },
    {
      "x": -5,
      "y": 8,
      "z": 3,
      "name": "Rock_Chalk",
      "rotation": 1
    },
    {
      "x": -5,
      "y": 9,
      "z": 3,
      "name": "Rock_Chalk",
      "rotation": 1
    },
    {
      "x": -5,
      "y": 10,
      "z": 3,
      "name": "Rock_Chalk",
      "rotation": 1
    },
    {
      "x": -5,
      "y": 7,
      "z": 4,
      "name": "Rock_Marble",
      "rotation": 1
    },
    {
      "x": -5,
      "y": 8,
      "z": 4,
      "name": "Rock_Chalk",
      "rotation": 1
    },
    {
      "x": -5,
      "y": 9,
      "z": 4,
      "name": "Rock_Chalk",
      "rotation": 1
    },
    {
      "x": -4,
      "y": 2,
      "z": -3,
      "name": "Rock_Marble_Cobble",
      "rotation": 1
    },
    {
      "x": -4,
      "y": 3,
      "z": -3,
      "name": "Rock_Marble_Cobble",
      "rotation": 1
    },
    {
      "x": -4,
      "y": 4,
      "z": -3,
      "name": "Rock_Marble_Cobble",
      "rotation": 1
    },
    {
      "x": -4,
      "y": 5,
      "z": -3,
      "name": "Rock_Marble_Cobble",
      "rotation": 1
    },
    {
      "x": -4,
      "y": 6,
      "z": -3,
      "name": "Rock_Marble_Cobble",
      "rotation": 1
    },
    {
      "x": -4,
      "y": 7,
      "z": -3,
      "name": "Rock_Marble",
      "rotation": 1
    },
    {
      "x": -4,
      "y": 8,
      "z": -3,
      "name": "Rock_Chalk",
      "rotation": 1
    },
    {
      "x": -4,
      "y": 9,
      "z": -3,
      "name": "Rock_Chalk",
      "rotation": 1
    },
    {
      "x": -4,
      "y": 10,
      "z": -3,
      "name": "Rock_Chalk",
      "rotation": 1
    },
    {
      "x": -4,
      "y": 1,
      "z": -2,
      "name": "Rock_Marble",
      "rotation": 1
    },
    {
      "x": -4,
      "y": 2,
      "z": -2,
      "name": "Rock_Marble_Cobble",
      "rotation": 1
    },
    {
      "x": -4,
      "y": 3,
      "z": -2,
      "name": "Rock_Marble_Cobble",
      "rotation": 1
    },
    {
      "x": -4,
      "y": 4,
      "z": -2,
      "name": "Rock_Marble_Cobble",
      "rotation": 1
    },
    {
      "x": -4,
      "y": 5,
      "z": -2,
      "name": "Rock_Marble_Cobble",
      "rotation": 1
    },
    {
      "x": -4,
      "y": 6,
      "z": -2,
      "name": "Rock_Marble_Cobble",
      "rotation": 1
    },
    {
      "x": -4,
      "y": 7,
      "z": -2,
      "name": "Rock_Marble",
      "rotation": 1
    },
    {
      "x": -4,
      "y": 8,
      "z": -2,
      "name": "Rock_Chalk",
      "rotation": 1
    },
    {
      "x": -4,
      "y": 9,
      "z": -2,
      "name": "Rock_Chalk",
      "rotation": 1
    },
    {
      "x": -4,
      "y": 10,
      "z": -2,
      "name": "Rock_Chalk",
      "rotation": 1
    },
    {
      "x": -4,
      "y": 11,
      "z": -2,
      "name": "Rock_Chalk",
      "rotation": 1
    },
    {
      "x": -4,
      "y": 0,
      "z": -1,
      "name": "Rock_Marble_Cobble",
      "rotation": 1
    },
    {
      "x": -4,
      "y": 1,
      "z": -1,
      "name": "Rock_Marble",
      "rotation": 1
    },
    {
      "x": -4,
      "y": 2,
      "z": -1,
      "name": "Rock_Marble_Cobble",
      "rotation": 1
    },
    {
      "x": -4,
      "y": 3,
      "z": -1,
      "name": "Rock_Marble_Cobble",
      "rotation": 1
    },
    {
      "x": -4,
      "y": 4,
      "z": -1,
      "name": "Rock_Marble_Cobble",
      "rotation": 1
    },
    {
      "x": -4,
      "y": 5,
      "z": -1,
      "name": "Rock_Marble_Cobble",
      "rotation": 1
    },
    {
      "x": -4,
      "y": 6,
      "z": -1,
      "name": "Rock_Marble_Cobble",
      "rotation": 1
    },
    {
      "x": -4,
      "y": 7,
      "z": -1,
      "name": "Rock_Marble",
      "rotation": 1
    },
    {
      "x": -4,
      "y": 8,
      "z": -1,
      "name": "Rock_Chalk",
      "rotation": 1
    },
    {
      "x": -4,
      "y": 9,
      "z": -1,
      "name": "Rock_Chalk",
      "rotation": 1
    },
    {
      "x": -4,
      "y": 10,
      "z": -1,
      "name": "Rock_Chalk",
      "rotation": 1
    },
    {
      "x": -4,
      "y": 11,
      "z": -1,
      "name": "Rock_Chalk",
      "rotation": 1
    },
    {
      "x": -4,
      "y": 12,
      "z": -1,
      "name": "Rock_Marble",
      "rotation": 1
    },
    {
      "x": -4,
      "y": 0,
      "z": 0,
      "name": "Rock_Marble_Cobble",
      "rotation": 1
    },
    {
      "x": -4,
      "y": 1,
      "z": 0,
      "name": "Soil_Clay_White",
      "rotation": 1
    },
    {
      "x": -4,
      "y": 2,
      "z": 0,
      "name": "Rock_Marble_Cobble",
      "rotation": 1
    },
    {
      "x": -4,
      "y": 3,
      "z": 0,
      "name": "Rock_Marble_Cobble",
      "rotation": 1
    },
    {
      "x": -4,
      "y": 4,
      "z": 0,
      "name": "Rock_Marble_Cobble",
      "rotation": 1
    },
    {
      "x": -4,
      "y": 5,
      "z": 0,
      "name": "Rock_Marble_Cobble",
      "rotation": 1
    },
    {
      "x": -4,
      "y": 6,
      "z": 0,
      "name": "Rock_Marble_Cobble",
      "rotation": 1
    },
    {
      "x": -4,
      "y": 7,
      "z": 0,
      "name": "Rock_Marble",
      "rotation": 1
    },
    {
      "x": -4,
      "y": 8,
      "z": 0,
      "name": "Rock_Chalk",
      "rotation": 1
    },
    {
      "x": -4,
      "y": 9,
      "z": 0,
      "name": "Rock_Chalk",
      "rotation": 1
    },
    {
      "x": -4,
      "y": 10,
      "z": 0,
      "name": "Rock_Chalk",
      "rotation": 1
    },
    {
      "x": -4,
      "y": 11,
      "z": 0,
      "name": "Rock_Chalk",
      "rotation": 1
    },
    {
      "x": -4,
      "y": 12,
      "z": 0,
      "name": "Rock_Marble",
      "rotation": 1
    },
    {
      "x": -4,
      "y": 13,
      "z": 0,
      "name": "Rock_Marble_Cobble",
      "rotation": 1
    },
    {
      "x": -4,
      "y": 0,
      "z": 1,
      "name": "Rock_Marble_Cobble",
      "rotation": 1
    },
    {
      "x": -4,
      "y": 1,
      "z": 1,
      "name": "Soil_Clay_White",
      "rotation": 1
    },
    {
      "x": -4,
      "y": 2,
      "z": 1,
      "name": "Rock_Marble_Cobble",
      "rotation": 1
    },
    {
      "x": -4,
      "y": 3,
      "z": 1,
      "name": "Rock_Marble_Cobble",
      "rotation": 1
    },
    {
      "x": -4,
      "y": 4,
      "z": 1,
      "name": "Rock_Marble_Cobble",
      "rotation": 1
    },
    {
      "x": -4,
      "y": 5,
      "z": 1,
      "name": "Rock_Marble_Cobble",
      "rotation": 1
    },
    {
      "x": -4,
      "y": 6,
      "z": 1,
      "name": "Rock_Marble_Cobble",
      "rotation": 1
    },
    {
      "x": -4,
      "y": 7,
      "z": 1,
      "name": "Rock_Marble",
      "rotation": 1
    },
    {
      "x": -4,
      "y": 8,
      "z": 1,
      "name": "Rock_Chalk",
      "rotation": 1
    },
    {
      "x": -4,
      "y": 9,
      "z": 1,
      "name": "Rock_Chalk",
      "rotation": 1
    },
    {
      "x": -4,
      "y": 10,
      "z": 1,
      "name": "Rock_Chalk",
      "rotation": 1
    },
    {
      "x": -4,
      "y": 11,
      "z": 1,
      "name": "Rock_Chalk",
      "rotation": 1
    },
    {
      "x": -4,
      "y": 12,
      "z": 1,
      "name": "Rock_Marble",
      "rotation": 1
    },
    {
      "x": -4,
      "y": 13,
      "z": 1,
      "name": "Rock_Marble_Cobble",
      "rotation": 1
    },
    {
      "x": -4,
      "y": 14,
      "z": 1,
      "name": "Rock_Marble_Cobble",
      "rotation": 1
    },
    {
      "x": -4,
      "y": 0,
      "z": 2,
      "name": "Rock_Marble_Cobble",
      "rotation": 1
    },
    {
      "x": -4,
      "y": 1,
      "z": 2,
      "name": "Soil_Clay_White",
      "rotation": 1
    },
    {
      "x": -4,
      "y": 2,
      "z": 2,
      "name": "Rock_Marble_Cobble",
      "rotation": 1
    },
    {
      "x": -4,
      "y": 3,
      "z": 2,
      "name": "Rock_Marble_Cobble",
      "rotation": 1
    },
    {
      "x": -4,
      "y": 4,
      "z": 2,
      "name": "Rock_Marble_Cobble",
      "rotation": 1
    },
    {
      "x": -4,
      "y": 5,
      "z": 2,
      "name": "Rock_Marble_Cobble",
      "rotation": 1
    },
    {
      "x": -4,
      "y": 6,
      "z": 2,
      "name": "Rock_Marble_Cobble",
      "rotation": 1
    },
    {
      "x": -4,
      "y": 7,
      "z": 2,
      "name": "Rock_Marble",
      "rotation": 1
    },
    {
      "x": -4,
      "y": 8,
      "z": 2,
      "name": "Rock_Chalk",
      "rotation": 1
    },
    {
      "x": -4,
      "y": 9,
      "z": 2,
      "name": "Rock_Chalk",
      "rotation": 1
    },
    {
      "x": -4,
      "y": 10,
      "z": 2,
      "name": "Rock_Chalk",
      "rotation": 1
    },
    {
      "x": -4,
      "y": 11,
      "z": 2,
      "name": "Rock_Chalk",
      "rotation": 1
    },
    {
      "x": -4,
      "y": 12,
      "z": 2,
      "name": "Rock_Marble",
      "rotation": 1
    },
    {
      "x": -4,
      "y": 13,
      "z": 2,
      "name": "Rock_Marble_Cobble",
      "rotation": 1
    },
    {
      "x": -4,
      "y": 1,
      "z": 3,
      "name": "Soil_Clay_White",
      "rotation": 1
    },
    {
      "x": -4,
      "y": 2,
      "z": 3,
      "name": "Rock_Marble_Cobble",
      "rotation": 1
    },
    {
      "x": -4,
      "y": 3,
      "z": 3,
      "name": "Rock_Marble_Cobble",
      "rotation": 1
    },
    {
      "x": -4,
      "y": 4,
      "z": 3,
      "name": "Rock_Marble_Cobble",
      "rotation": 1
    },
    {
      "x": -4,
      "y": 5,
      "z": 3,
      "name": "Rock_Marble_Cobble",
      "rotation": 1
    },
    {
      "x": -4,
      "y": 6,
      "z": 3,
      "name": "Rock_Marble_Cobble",
      "rotation": 1
    },
    {
      "x": -4,
      "y": 7,
      "z": 3,
      "name": "Rock_Marble",
      "rotation": 1
    },
    {
      "x": -4,
      "y": 8,
      "z": 3,
      "name": "Rock_Chalk",
      "rotation": 1
    },
    {
      "x": -4,
      "y": 9,
      "z": 3,
      "name": "Rock_Chalk",
      "rotation": 1
    },
    {
      "x": -4,
      "y": 10,
      "z": 3,
      "name": "Rock_Chalk",
      "rotation": 1
    },
    {
      "x": -4,
      "y": 11,
      "z": 3,
      "name": "Rock_Chalk",
      "rotation": 1
    },
    {
      "x": -4,
      "y": 12,
      "z": 3,
      "name": "Rock_Marble",
      "rotation": 1
    },
    {
      "x": -4,
      "y": 3,
      "z": 4,
      "name": "Rock_Marble_Cobble",
      "rotation": 1
    },
    {
      "x": -4,
      "y": 4,
      "z": 4,
      "name": "Rock_Marble_Cobble",
      "rotation": 1
    },
    {
      "x": -4,
      "y": 5,
      "z": 4,
      "name": "Rock_Marble_Cobble",
      "rotation": 1
    },
    {
      "x": -4,
      "y": 6,
      "z": 4,
      "name": "Rock_Marble_Cobble",
      "rotation": 1
    },
    {
      "x": -4,
      "y": 7,
      "z": 4,
      "name": "Rock_Marble",
      "rotation": 1
    },
    {
      "x": -4,
      "y": 8,
      "z": 4,
      "name": "Rock_Chalk",
      "rotation": 1
    },
    {
      "x": -4,
      "y": 9,
      "z": 4,
      "name": "Rock_Chalk",
      "rotation": 1
    },
    {
      "x": -4,
      "y": 10,
      "z": 4,
      "name": "Rock_Chalk",
      "rotation": 1
    },
    {
      "x": -4,
      "y": 11,
      "z": 4,
      "name": "Rock_Chalk",
      "rotation": 1
    },
    {
      "x": -4,
      "y": 7,
      "z": 5,
      "name": "Rock_Marble",
      "rotation": 1
    },
    {
      "x": -4,
      "y": 8,
      "z": 5,
      "name": "Rock_Chalk",
      "rotation": 1
    },
    {
      "x": -4,
      "y": 9,
      "z": 5,
      "name": "Rock_Chalk",
      "rotation": 1
    },
    {
      "x": -3,
      "y": 2,
      "z": -4,
      "name": "Rock_Marble_Cobble",
      "rotation": 1
    },
    {
      "x": -3,
      "y": 3,
      "z": -4,
      "name": "Rock_Marble_Cobble",
      "rotation": 1
    },
    {
      "x": -3,
      "y": 4,
      "z": -4,
      "name": "Rock_Marble_Cobble",
      "rotation": 1
    },
    {
      "x": -3,
      "y": 5,
      "z": -4,
      "name": "Rock_Marble_Cobble",
      "rotation": 1
    },
    {
      "x": -3,
      "y": 6,
      "z": -4,
      "name": "Rock_Marble_Cobble",
      "rotation": 1
    },
    {
      "x": -3,
      "y": 7,
      "z": -4,
      "name": "Rock_Marble",
      "rotation": 1
    },
    {
      "x": -3,
      "y": 8,
      "z": -4,
      "name": "Rock_Chalk",
      "rotation": 1
    },
    {
      "x": -3,
      "y": 9,
      "z": -4,
      "name": "Rock_Chalk",
      "rotation": 1
    },
    {
      "x": -3,
      "y": 10,
      "z": -4,
      "name": "Rock_Chalk",
      "rotation": 1
    },
    {
      "x": -3,
      "y": 1,
      "z": -3,
      "name": "Rock_Marble",
      "rotation": 1
    },
    {
      "x": -3,
      "y": 2,
      "z": -3,
      "name": "Rock_Marble_Cobble",
      "rotation": 1
    },
    {
      "x": -3,
      "y": 3,
      "z": -3,
      "name": "Rock_Marble_Cobble",
      "rotation": 1
    },
    {
      "x": -3,
      "y": 4,
      "z": -3,
      "name": "Rock_Marble_Cobble",
      "rotation": 1
    },
    {
      "x": -3,
      "y": 5,
      "z": -3,
      "name": "Rock_Marble_Cobble",
      "rotation": 1
    },
    {
      "x": -3,
      "y": 6,
      "z": -3,
      "name": "Rock_Marble_Cobble",
      "rotation": 1
    },
    {
      "x": -3,
      "y": 7,
      "z": -3,
      "name": "Rock_Marble",
      "rotation": 1
    },
    {
      "x": -3,
      "y": 8,
      "z": -3,
      "name": "Rock_Chalk",
      "rotation": 1
    },
    {
      "x": -3,
      "y": 9,
      "z": -3,
      "name": "Rock_Chalk",
      "rotation": 1
    },
    {
      "x": -3,
      "y": 10,
      "z": -3,
      "name": "Rock_Chalk",
      "rotation": 1
    },
    {
      "x": -3,
      "y": 11,
      "z": -3,
      "name": "Rock_Chalk",
      "rotation": 1
    },
    {
      "x": -3,
      "y": 12,
      "z": -3,
      "name": "Rock_Marble",
      "rotation": 1
    },
    {
      "x": -3,
      "y": 13,
      "z": -3,
      "name": "Rock_Marble_Cobble",
      "rotation": 1
    },
    {
      "x": -3,
      "y": 0,
      "z": -2,
      "name": "Rock_Marble_Cobble",
      "rotation": 1
    },
    {
      "x": -3,
      "y": 1,
      "z": -2,
      "name": "Rock_Marble",
      "rotation": 1
    },
    {
      "x": -3,
      "y": 2,
      "z": -2,
      "name": "Rock_Marble_Cobble",
      "rotation": 1
    },
    {
      "x": -3,
      "y": 3,
      "z": -2,
      "name": "Rock_Marble_Cobble",
      "rotation": 1
    },
    {
      "x": -3,
      "y": 4,
      "z": -2,
      "name": "Rock_Marble_Cobble",
      "rotation": 1
    },
    {
      "x": -3,
      "y": 5,
      "z": -2,
      "name": "Rock_Marble_Cobble",
      "rotation": 1
    },
    {
      "x": -3,
      "y": 6,
      "z": -2,
      "name": "Rock_Marble_Cobble",
      "rotation": 1
    },
    {
      "x": -3,
      "y": 7,
      "z": -2,
      "name": "Rock_Marble",
      "rotation": 1
    },
    {
      "x": -3,
      "y": 8,
      "z": -2,
      "name": "Rock_Chalk",
      "rotation": 1
    },
    {
      "x": -3,
      "y": 9,
      "z": -2,
      "name": "Rock_Chalk",
      "rotation": 1
    },
    {
      "x": -3,
      "y": 10,
      "z": -2,
      "name": "Rock_Chalk",
      "rotation": 1
    },
    {
      "x": -3,
      "y": 11,
      "z": -2,
      "name": "Rock_Chalk",
      "rotation": 1
    },
    {
      "x": -3,
      "y": 12,
      "z": -2,
      "name": "Rock_Marble",
      "rotation": 1
    },
    {
      "x": -3,
      "y": 13,
      "z": -2,
      "name": "Rock_Marble_Cobble",
      "rotation": 1
    },
    {
      "x": -3,
      "y": 14,
      "z": -2,
      "name": "Rock_Marble_Cobble",
      "rotation": 1
    },
    {
      "x": -3,
      "y": 15,
      "z": -2,
      "name": "Rock_Marble_Cobble",
      "rotation": 1
    },
    {
      "x": -3,
      "y": 0,
      "z": -1,
      "name": "Rock_Marble_Cobble",
      "rotation": 1
    },
    {
      "x": -3,
      "y": 1,
      "z": -1,
      "name": "Rock_Marble",
      "rotation": 1
    },
    {
      "x": -3,
      "y": 2,
      "z": -1,
      "name": "Rock_Marble_Cobble",
      "rotation": 1
    },
    {
      "x": -3,
      "y": 3,
      "z": -1,
      "name": "Rock_Marble_Cobble",
      "rotation": 1
    },
    {
      "x": -3,
      "y": 4,
      "z": -1,
      "name": "Rock_Marble_Cobble",
      "rotation": 1
    },
    {
      "x": -3,
      "y": 5,
      "z": -1,
      "name": "Rock_Marble_Cobble",
      "rotation": 1
    },
    {
      "x": -3,
      "y": 6,
      "z": -1,
      "name": "Rock_Marble_Cobble",
      "rotation": 1
    },
    {
      "x": -3,
      "y": 7,
      "z": -1,
      "name": "Rock_Marble",
      "rotation": 1
    },
    {
      "x": -3,
      "y": 8,
      "z": -1,
      "name": "Rock_Chalk",
      "rotation": 1
    },
    {
      "x": -3,
      "y": 9,
      "z": -1,
      "name": "Rock_Chalk",
      "rotation": 1
    },
    {
      "x": -3,
      "y": 10,
      "z": -1,
      "name": "Rock_Chalk",
      "rotation": 1
    },
    {
      "x": -3,
      "y": 11,
      "z": -1,
      "name": "Rock_Chalk",
      "rotation": 1
    },
    {
      "x": -3,
      "y": 12,
      "z": -1,
      "name": "Rock_Marble",
      "rotation": 1
    },
    {
      "x": -3,
      "y": 13,
      "z": -1,
      "name": "Rock_Marble_Cobble",
      "rotation": 1
    },
    {
      "x": -3,
      "y": 14,
      "z": -1,
      "name": "Rock_Marble_Cobble",
      "rotation": 1
    },
    {
      "x": -3,
      "y": 15,
      "z": -1,
      "name": "Rock_Marble_Cobble",
      "rotation": 1
    },
    {
      "x": -3,
      "y": 16,
      "z": -1,
      "name": "Rock_Marble_Cobble",
      "rotation": 1
    },
    {
      "x": -3,
      "y": 17,
      "z": -1,
      "name": "Rock_Marble",
      "rotation": 1
    },
    {
      "x": -3,
      "y": 30,
      "z": -1,
      "name": "Plant_Moss_Wall_Green",
      "rotation": 3
    },
    {
      "x": -3,
      "y": 0,
      "z": 0,
      "name": "Rock_Marble_Cobble",
      "rotation": 1
    },
    {
      "x": -3,
      "y": 1,
      "z": 0,
      "name": "Rock_Marble",
      "rotation": 1
    },
    {
      "x": -3,
      "y": 2,
      "z": 0,
      "name": "Rock_Marble_Cobble",
      "rotation": 1
    },
    {
      "x": -3,
      "y": 3,
      "z": 0,
      "name": "Rock_Marble_Cobble",
      "rotation": 1
    },
    {
      "x": -3,
      "y": 4,
      "z": 0,
      "name": "Rock_Marble_Cobble",
      "rotation": 1
    },
    {
      "x": -3,
      "y": 5,
      "z": 0,
      "name": "Rock_Marble_Cobble",
      "rotation": 1
    },
    {
      "x": -3,
      "y": 6,
      "z": 0,
      "name": "Rock_Marble_Cobble",
      "rotation": 1
    },
    {
      "x": -3,
      "y": 7,
      "z": 0,
      "name": "Rock_Marble",
      "rotation": 1
    },
    {
      "x": -3,
      "y": 8,
      "z": 0,
      "name": "Rock_Chalk",
      "rotation": 1
    },
    {
      "x": -3,
      "y": 9,
      "z": 0,
      "name": "Rock_Chalk",
      "rotation": 1
    },
    {
      "x": -3,
      "y": 10,
      "z": 0,
      "name": "Rock_Chalk",
      "rotation": 1
    },
    {
      "x": -3,
      "y": 11,
      "z": 0,
      "name": "Rock_Chalk",
      "rotation": 1
    },
    {
      "x": -3,
      "y": 12,
      "z": 0,
      "name": "Rock_Marble",
      "rotation": 1
    },
    {
      "x": -3,
      "y": 13,
      "z": 0,
      "name": "Rock_Marble_Cobble",
      "rotation": 1
    },
    {
      "x": -3,
      "y": 14,
      "z": 0,
      "name": "Rock_Marble_Cobble",
      "rotation": 1
    },
    {
      "x": -3,
      "y": 15,
      "z": 0,
      "name": "Rock_Marble_Cobble",
      "rotation": 1
    },
    {
      "x": -3,
      "y": 16,
      "z": 0,
      "name": "Rock_Marble_Cobble",
      "rotation": 1
    },
    {
      "x": -3,
      "y": 17,
      "z": 0,
      "name": "Rock_Marble",
      "rotation": 1
    },
    {
      "x": -3,
      "y": 18,
      "z": 0,
      "name": "Rock_Marble",
      "rotation": 1
    },
    {
      "x": -3,
      "y": 19,
      "z": 0,
      "name": "Soil_Clay_White",
      "rotation": 1
    },
    {
      "x": -3,
      "y": 25,
      "z": 0,
      "name": "Rock_Marble",
      "rotation": 1
    },
    {
      "x": -3,
      "y": 26,
      "z": 0,
      "name": "Rock_Marble_Cobble",
      "rotation": 1
    },
    {
      "x": -3,
      "y": 27,
      "z": 0,
      "name": "Rock_Marble_Cobble",
      "rotation": 1
    },
    {
      "x": -3,
      "y": 28,
      "z": 0,
      "name": "Rock_Marble_Cobble",
      "rotation": 1
    },
    {
      "x": -3,
      "y": 32,
      "z": 0,
      "name": "Plant_Moss_Wall_Green",
      "rotation": 3
    },
    {
      "x": -3,
      "y": 0,
      "z": 1,
      "name": "Rock_Marble_Cobble",
      "rotation": 1
    },
    {
      "x": -3,
      "y": 1,
      "z": 1,
      "name": "Rock_Marble",
      "rotation": 1
    },
    {
      "x": -3,
      "y": 2,
      "z": 1,
      "name": "Rock_Marble_Cobble",
      "rotation": 1
    },
    {
      "x": -3,
      "y": 3,
      "z": 1,
      "name": "Rock_Marble_Cobble",
      "rotation": 1
    },
    {
      "x": -3,
      "y": 4,
      "z": 1,
      "name": "Rock_Marble_Cobble",
      "rotation": 1
    },
    {
      "x": -3,
      "y": 5,
      "z": 1,
      "name": "Rock_Marble_Cobble",
      "rotation": 1
    },
    {
      "x": -3,
      "y": 6,
      "z": 1,
      "name": "Rock_Marble_Cobble",
      "rotation": 1
    },
    {
      "x": -3,
      "y": 7,
      "z": 1,
      "name": "Rock_Marble",
      "rotation": 1
    },
    {
      "x": -3,
      "y": 8,
      "z": 1,
      "name": "Rock_Chalk",
      "rotation": 1
    },
    {
      "x": -3,
      "y": 9,
      "z": 1,
      "name": "Rock_Chalk",
      "rotation": 1
    },
    {
      "x": -3,
      "y": 10,
      "z": 1,
      "name": "Rock_Chalk",
      "rotation": 1
    },
    {
      "x": -3,
      "y": 11,
      "z": 1,
      "name": "Rock_Chalk",
      "rotation": 1
    },
    {
      "x": -3,
      "y": 12,
      "z": 1,
      "name": "Rock_Marble",
      "rotation": 1
    },
    {
      "x": -3,
      "y": 13,
      "z": 1,
      "name": "Rock_Marble_Cobble",
      "rotation": 1
    },
    {
      "x": -3,
      "y": 14,
      "z": 1,
      "name": "Rock_Marble_Cobble",
      "rotation": 1
    },
    {
      "x": -3,
      "y": 15,
      "z": 1,
      "name": "Rock_Marble_Cobble",
      "rotation": 1
    },
    {
      "x": -3,
      "y": 16,
      "z": 1,
      "name": "Rock_Marble_Cobble",
      "rotation": 1
    },
    {
      "x": -3,
      "y": 17,
      "z": 1,
      "name": "Rock_Marble",
      "rotation": 1
    },
    {
      "x": -3,
      "y": 18,
      "z": 1,
      "name": "Rock_Marble",
      "rotation": 1
    },
    {
      "x": -3,
      "y": 19,
      "z": 1,
      "name": "Soil_Clay_White",
      "rotation": 1
    },
    {
      "x": -3,
      "y": 20,
      "z": 1,
      "name": "Rock_Chalk",
      "rotation": 1
    },
    {
      "x": -3,
      "y": 21,
      "z": 1,
      "name": "Rock_Marble",
      "rotation": 1
    },
    {
      "x": -3,
      "y": 22,
      "z": 1,
      "name": "Rock_Marble",
      "rotation": 1
    },
    {
      "x": -3,
      "y": 23,
      "z": 1,
      "name": "Rock_Marble_Cobble",
      "rotation": 1
    },
    {
      "x": -3,
      "y": 24,
      "z": 1,
      "name": "Rock_Marble_Cobble",
      "rotation": 1
    },
    {
      "x": -3,
      "y": 25,
      "z": 1,
      "name": "Rock_Marble",
      "rotation": 1
    },
    {
      "x": -3,
      "y": 26,
      "z": 1,
      "name": "Rock_Marble_Cobble",
      "rotation": 1
    },
    {
      "x": -3,
      "y": 27,
      "z": 1,
      "name": "Rock_Marble_Cobble",
      "rotation": 1
    },
    {
      "x": -3,
      "y": 28,
      "z": 1,
      "name": "Rock_Marble_Cobble",
      "rotation": 1
    },
    {
      "x": -3,
      "y": 29,
      "z": 1,
      "name": "Rock_Marble_Cobble",
      "rotation": 1
    },
    {
      "x": -3,
      "y": 30,
      "z": 1,
      "name": "Rock_Marble",
      "rotation": 1
    },
    {
      "x": -3,
      "y": 33,
      "z": 1,
      "name": "Plant_Moss_Wall_Green",
      "rotation": 3
    },
    {
      "x": -3,
      "y": 0,
      "z": 2,
      "name": "Rock_Marble_Cobble",
      "rotation": 1
    },
    {
      "x": -3,
      "y": 1,
      "z": 2,
      "name": "Rock_Marble",
      "rotation": 1
    },
    {
      "x": -3,
      "y": 2,
      "z": 2,
      "name": "Rock_Marble_Cobble",
      "rotation": 1
    },
    {
      "x": -3,
      "y": 3,
      "z": 2,
      "name": "Rock_Marble_Cobble",
      "rotation": 1
    },
    {
      "x": -3,
      "y": 4,
      "z": 2,
      "name": "Rock_Marble_Cobble",
      "rotation": 1
    },
    {
      "x": -3,
      "y": 5,
      "z": 2,
      "name": "Rock_Marble_Cobble",
      "rotation": 1
    },
    {
      "x": -3,
      "y": 6,
      "z": 2,
      "name": "Rock_Marble_Cobble",
      "rotation": 1
    },
    {
      "x": -3,
      "y": 7,
      "z": 2,
      "name": "Rock_Marble",
      "rotation": 1
    },
    {
      "x": -3,
      "y": 8,
      "z": 2,
      "name": "Rock_Chalk",
      "rotation": 1
    },
    {
      "x": -3,
      "y": 9,
      "z": 2,
      "name": "Rock_Chalk",
      "rotation": 1
    },
    {
      "x": -3,
      "y": 10,
      "z": 2,
      "name": "Rock_Chalk",
      "rotation": 1
    },
    {
      "x": -3,
      "y": 11,
      "z": 2,
      "name": "Rock_Chalk",
      "rotation": 1
    },
    {
      "x": -3,
      "y": 12,
      "z": 2,
      "name": "Rock_Marble",
      "rotation": 1
    },
    {
      "x": -3,
      "y": 13,
      "z": 2,
      "name": "Rock_Marble_Cobble",
      "rotation": 1
    },
    {
      "x": -3,
      "y": 14,
      "z": 2,
      "name": "Rock_Marble_Cobble",
      "rotation": 1
    },
    {
      "x": -3,
      "y": 15,
      "z": 2,
      "name": "Rock_Marble_Cobble",
      "rotation": 1
    },
    {
      "x": -3,
      "y": 16,
      "z": 2,
      "name": "Rock_Marble_Cobble",
      "rotation": 1
    },
    {
      "x": -3,
      "y": 17,
      "z": 2,
      "name": "Rock_Marble",
      "rotation": 1
    },
    {
      "x": -3,
      "y": 18,
      "z": 2,
      "name": "Rock_Marble",
      "rotation": 1
    },
    {
      "x": -3,
      "y": 19,
      "z": 2,
      "name": "Soil_Clay_White",
      "rotation": 1
    },
    {
      "x": -3,
      "y": 20,
      "z": 2,
      "name": "Rock_Chalk",
      "rotation": 1
    },
    {
      "x": -3,
      "y": 21,
      "z": 2,
      "name": "Rock_Marble",
      "rotation": 1
    },
    {
      "x": -3,
      "y": 22,
      "z": 2,
      "name": "Rock_Marble",
      "rotation": 1
    },
    {
      "x": -3,
      "y": 23,
      "z": 2,
      "name": "Rock_Marble_Cobble",
      "rotation": 1
    },
    {
      "x": -3,
      "y": 24,
      "z": 2,
      "name": "Rock_Marble_Cobble",
      "rotation": 1
    },
    {
      "x": -3,
      "y": 25,
      "z": 2,
      "name": "Rock_Marble",
      "rotation": 1
    },
    {
      "x": -3,
      "y": 26,
      "z": 2,
      "name": "Rock_Marble_Cobble",
      "rotation": 1
    },
    {
      "x": -3,
      "y": 27,
      "z": 2,
      "name": "Soil_Clay_GreyLight",
      "rotation": 1
    },
    {
      "x": -3,
      "y": 28,
      "z": 2,
      "name": "Rock_Marble_Cobble",
      "rotation": 1
    },
    {
      "x": -3,
      "y": 29,
      "z": 2,
      "name": "Rock_Marble",
      "rotation": 1
    },
    {
      "x": -3,
      "y": 30,
      "z": 2,
      "name": "Rock_Marble",
      "rotation": 1
    },
    {
      "x": -3,
      "y": 32,
      "z": 2,
      "name": "Plant_Moss_Wall_Green",
      "rotation": 3
    },
    {
      "x": -3,
      "y": 0,
      "z": 3,
      "name": "Rock_Marble_Cobble",
      "rotation": 1
    },
    {
      "x": -3,
      "y": 1,
      "z": 3,
      "name": "Soil_Clay_White",
      "rotation": 1
    },
    {
      "x": -3,
      "y": 2,
      "z": 3,
      "name": "Rock_Marble_Cobble",
      "rotation": 1
    },
    {
      "x": -3,
      "y": 3,
      "z": 3,
      "name": "Rock_Marble_Cobble",
      "rotation": 1
    },
    {
      "x": -3,
      "y": 4,
      "z": 3,
      "name": "Rock_Marble_Cobble",
      "rotation": 1
    },
    {
      "x": -3,
      "y": 5,
      "z": 3,
      "name": "Rock_Marble_Cobble",
      "rotation": 1
    },
    {
      "x": -3,
      "y": 6,
      "z": 3,
      "name": "Rock_Marble_Cobble",
      "rotation": 1
    },
    {
      "x": -3,
      "y": 7,
      "z": 3,
      "name": "Rock_Marble",
      "rotation": 1
    },
    {
      "x": -3,
      "y": 8,
      "z": 3,
      "name": "Rock_Chalk",
      "rotation": 1
    },
    {
      "x": -3,
      "y": 9,
      "z": 3,
      "name": "Rock_Chalk",
      "rotation": 1
    },
    {
      "x": -3,
      "y": 10,
      "z": 3,
      "name": "Rock_Chalk",
      "rotation": 1
    },
    {
      "x": -3,
      "y": 11,
      "z": 3,
      "name": "Rock_Chalk",
      "rotation": 1
    },
    {
      "x": -3,
      "y": 12,
      "z": 3,
      "name": "Rock_Marble",
      "rotation": 1
    },
    {
      "x": -3,
      "y": 13,
      "z": 3,
      "name": "Rock_Marble_Cobble",
      "rotation": 1
    },
    {
      "x": -3,
      "y": 14,
      "z": 3,
      "name": "Rock_Marble_Cobble",
      "rotation": 1
    },
    {
      "x": -3,
      "y": 15,
      "z": 3,
      "name": "Rock_Marble_Cobble",
      "rotation": 1
    },
    {
      "x": -3,
      "y": 16,
      "z": 3,
      "name": "Rock_Marble_Cobble",
      "rotation": 1
    },
    {
      "x": -3,
      "y": 27,
      "z": 3,
      "name": "Soil_Clay_GreyLight",
      "rotation": 1
    },
    {
      "x": -3,
      "y": 28,
      "z": 3,
      "name": "Rock_Marble_Cobble",
      "rotation": 1
    },
    {
      "x": -3,
      "y": 29,
      "z": 3,
      "name": "Rock_Marble",
      "rotation": 1
    },
    {
      "x": -3,
      "y": 31,
      "z": 3,
      "name": "Plant_Moss_Wall_Green",
      "rotation": 3
    },
    {
      "x": -3,
      "y": 32,
      "z": 3,
      "name": "Plant_Moss_Wall_Green",
      "rotation": 3
    },
    {
      "x": -3,
      "y": 1,
      "z": 4,
      "name": "Soil_Clay_White",
      "rotation": 1
    },
    {
      "x": -3,
      "y": 2,
      "z": 4,
      "name": "Rock_Marble_Cobble",
      "rotation": 1
    },
    {
      "x": -3,
      "y": 3,
      "z": 4,
      "name": "Rock_Marble_Cobble",
      "rotation": 1
    },
    {
      "x": -3,
      "y": 4,
      "z": 4,
      "name": "Rock_Marble_Cobble",
      "rotation": 1
    },
    {
      "x": -3,
      "y": 5,
      "z": 4,
      "name": "Rock_Marble_Cobble",
      "rotation": 1
    },
    {
      "x": -3,
      "y": 6,
      "z": 4,
      "name": "Rock_Marble_Cobble",
      "rotation": 1
    },
    {
      "x": -3,
      "y": 7,
      "z": 4,
      "name": "Rock_Marble",
      "rotation": 1
    },
    {
      "x": -3,
      "y": 8,
      "z": 4,
      "name": "Rock_Chalk",
      "rotation": 1
    },
    {
      "x": -3,
      "y": 9,
      "z": 4,
      "name": "Rock_Chalk",
      "rotation": 1
    },
    {
      "x": -3,
      "y": 10,
      "z": 4,
      "name": "Rock_Chalk",
      "rotation": 1
    },
    {
      "x": -3,
      "y": 11,
      "z": 4,
      "name": "Rock_Chalk",
      "rotation": 1
    },
    {
      "x": -3,
      "y": 12,
      "z": 4,
      "name": "Rock_Marble",
      "rotation": 1
    },
    {
      "x": -3,
      "y": 13,
      "z": 4,
      "name": "Rock_Marble_Cobble",
      "rotation": 1
    },
    {
      "x": -3,
      "y": 3,
      "z": 5,
      "name": "Rock_Marble_Cobble",
      "rotation": 1
    },
    {
      "x": -3,
      "y": 4,
      "z": 5,
      "name": "Rock_Marble_Cobble",
      "rotation": 1
    },
    {
      "x": -3,
      "y": 5,
      "z": 5,
      "name": "Rock_Marble_Cobble",
      "rotation": 1
    },
    {
      "x": -3,
      "y": 6,
      "z": 5,
      "name": "Rock_Marble_Cobble",
      "rotation": 1
    },
    {
      "x": -3,
      "y": 7,
      "z": 5,
      "name": "Rock_Marble",
      "rotation": 1
    },
    {
      "x": -3,
      "y": 8,
      "z": 5,
      "name": "Rock_Chalk",
      "rotation": 1
    },
    {
      "x": -3,
      "y": 9,
      "z": 5,
      "name": "Rock_Chalk",
      "rotation": 1
    },
    {
      "x": -3,
      "y": 10,
      "z": 5,
      "name": "Rock_Chalk",
      "rotation": 1
    },
    {
      "x": -3,
      "y": 11,
      "z": 5,
      "name": "Rock_Chalk",
      "rotation": 1
    },
    {
      "x": -3,
      "y": 7,
      "z": 6,
      "name": "Rock_Marble",
      "rotation": 1
    },
    {
      "x": -3,
      "y": 8,
      "z": 6,
      "name": "Rock_Chalk",
      "rotation": 1
    },
    {
      "x": -3,
      "y": 9,
      "z": 6,
      "name": "Rock_Chalk",
      "rotation": 1
    },
    {
      "x": -2,
      "y": 3,
      "z": -5,
      "name": "Rock_Marble_Cobble",
      "rotation": 1
    },
    {
      "x": -2,
      "y": 4,
      "z": -5,
      "name": "Rock_Marble_Cobble",
      "rotation": 1
    },
    {
      "x": -2,
      "y": 5,
      "z": -5,
      "name": "Rock_Marble_Cobble",
      "rotation": 1
    },
    {
      "x": -2,
      "y": 6,
      "z": -5,
      "name": "Rock_Marble_Cobble",
      "rotation": 1
    },
    {
      "x": -2,
      "y": 7,
      "z": -5,
      "name": "Rock_Marble",
      "rotation": 1
    },
    {
      "x": -2,
      "y": 8,
      "z": -5,
      "name": "Rock_Chalk",
      "rotation": 1
    },
    {
      "x": -2,
      "y": 9,
      "z": -5,
      "name": "Rock_Chalk",
      "rotation": 1
    },
    {
      "x": -2,
      "y": 1,
      "z": -4,
      "name": "Rock_Marble",
      "rotation": 1
    },
    {
      "x": -2,
      "y": 2,
      "z": -4,
      "name": "Rock_Marble_Cobble",
      "rotation": 1
    },
    {
      "x": -2,
      "y": 3,
      "z": -4,
      "name": "Rock_Marble_Cobble",
      "rotation": 1
    },
    {
      "x": -2,
      "y": 4,
      "z": -4,
      "name": "Rock_Marble_Cobble",
      "rotation": 1
    },
    {
      "x": -2,
      "y": 5,
      "z": -4,
      "name": "Rock_Marble_Cobble",
      "rotation": 1
    },
    {
      "x": -2,
      "y": 6,
      "z": -4,
      "name": "Rock_Marble_Cobble",
      "rotation": 1
    },
    {
      "x": -2,
      "y": 7,
      "z": -4,
      "name": "Rock_Marble",
      "rotation": 1
    },
    {
      "x": -2,
      "y": 8,
      "z": -4,
      "name": "Rock_Chalk",
      "rotation": 1
    },
    {
      "x": -2,
      "y": 9,
      "z": -4,
      "name": "Rock_Chalk",
      "rotation": 1
    },
    {
      "x": -2,
      "y": 10,
      "z": -4,
      "name": "Rock_Chalk",
      "rotation": 1
    },
    {
      "x": -2,
      "y": 11,
      "z": -4,
      "name": "Rock_Chalk",
      "rotation": 1
    },
    {
      "x": -2,
      "y": 12,
      "z": -4,
      "name": "Rock_Marble",
      "rotation": 1
    },
    {
      "x": -2,
      "y": 13,
      "z": -4,
      "name": "Rock_Marble_Cobble",
      "rotation": 1
    },
    {
      "x": -2,
      "y": 0,
      "z": -3,
      "name": "Rock_Marble_Cobble",
      "rotation": 1
    },
    {
      "x": -2,
      "y": 1,
      "z": -3,
      "name": "Rock_Marble",
      "rotation": 1
    },
    {
      "x": -2,
      "y": 2,
      "z": -3,
      "name": "Rock_Marble_Cobble",
      "rotation": 1
    },
    {
      "x": -2,
      "y": 3,
      "z": -3,
      "name": "Rock_Marble_Cobble",
      "rotation": 1
    },
    {
      "x": -2,
      "y": 4,
      "z": -3,
      "name": "Rock_Marble_Cobble",
      "rotation": 1
    },
    {
      "x": -2,
      "y": 5,
      "z": -3,
      "name": "Rock_Marble_Cobble",
      "rotation": 1
    },
    {
      "x": -2,
      "y": 6,
      "z": -3,
      "name": "Rock_Marble_Cobble",
      "rotation": 1
    },
    {
      "x": -2,
      "y": 7,
      "z": -3,
      "name": "Rock_Marble",
      "rotation": 1
    },
    {
      "x": -2,
      "y": 8,
      "z": -3,
      "name": "Rock_Chalk",
      "rotation": 1
    },
    {
      "x": -2,
      "y": 9,
      "z": -3,
      "name": "Rock_Chalk",
      "rotation": 1
    },
    {
      "x": -2,
      "y": 10,
      "z": -3,
      "name": "Rock_Chalk",
      "rotation": 1
    },
    {
      "x": -2,
      "y": 11,
      "z": -3,
      "name": "Rock_Chalk",
      "rotation": 1
    },
    {
      "x": -2,
      "y": 12,
      "z": -3,
      "name": "Rock_Marble",
      "rotation": 1
    },
    {
      "x": -2,
      "y": 13,
      "z": -3,
      "name": "Rock_Marble_Cobble",
      "rotation": 1
    },
    {
      "x": -2,
      "y": 14,
      "z": -3,
      "name": "Rock_Marble_Cobble",
      "rotation": 1
    },
    {
      "x": -2,
      "y": 15,
      "z": -3,
      "name": "Rock_Marble_Cobble",
      "rotation": 1
    },
    {
      "x": -2,
      "y": 16,
      "z": -3,
      "name": "Rock_Marble_Cobble",
      "rotation": 1
    },
    {
      "x": -2,
      "y": 0,
      "z": -2,
      "name": "Rock_Marble_Cobble",
      "rotation": 1
    },
    {
      "x": -2,
      "y": 1,
      "z": -2,
      "name": "Rock_Marble",
      "rotation": 1
    },
    {
      "x": -2,
      "y": 2,
      "z": -2,
      "name": "Rock_Marble_Cobble",
      "rotation": 1
    },
    {
      "x": -2,
      "y": 3,
      "z": -2,
      "name": "Rock_Marble_Cobble",
      "rotation": 1
    },
    {
      "x": -2,
      "y": 4,
      "z": -2,
      "name": "Rock_Marble_Cobble",
      "rotation": 1
    },
    {
      "x": -2,
      "y": 5,
      "z": -2,
      "name": "Rock_Marble_Cobble",
      "rotation": 1
    },
    {
      "x": -2,
      "y": 6,
      "z": -2,
      "name": "Rock_Marble_Cobble",
      "rotation": 1
    },
    {
      "x": -2,
      "y": 7,
      "z": -2,
      "name": "Rock_Marble",
      "rotation": 1
    },
    {
      "x": -2,
      "y": 8,
      "z": -2,
      "name": "Rock_Chalk",
      "rotation": 1
    },
    {
      "x": -2,
      "y": 9,
      "z": -2,
      "name": "Rock_Chalk",
      "rotation": 1
    },
    {
      "x": -2,
      "y": 10,
      "z": -2,
      "name": "Rock_Chalk",
      "rotation": 1
    },
    {
      "x": -2,
      "y": 11,
      "z": -2,
      "name": "Rock_Chalk",
      "rotation": 1
    },
    {
      "x": -2,
      "y": 12,
      "z": -2,
      "name": "Rock_Marble",
      "rotation": 1
    },
    {
      "x": -2,
      "y": 13,
      "z": -2,
      "name": "Rock_Marble_Cobble",
      "rotation": 1
    },
    {
      "x": -2,
      "y": 14,
      "z": -2,
      "name": "Rock_Marble_Cobble",
      "rotation": 1
    },
    {
      "x": -2,
      "y": 15,
      "z": -2,
      "name": "Rock_Marble_Cobble",
      "rotation": 1
    },
    {
      "x": -2,
      "y": 16,
      "z": -2,
      "name": "Rock_Marble_Cobble",
      "rotation": 1
    },
    {
      "x": -2,
      "y": 17,
      "z": -2,
      "name": "Soil_Clay_White",
      "rotation": 1
    },
    {
      "x": -2,
      "y": 18,
      "z": -2,
      "name": "Rock_Marble",
      "rotation": 1
    },
    {
      "x": -2,
      "y": 19,
      "z": -2,
      "name": "Soil_Clay_White",
      "rotation": 1
    },
    {
      "x": -2,
      "y": 30,
      "z": -2,
      "name": "Plant_Moss_Wall_Green",
      "rotation": 2
    },
    {
      "x": -2,
      "y": 0,
      "z": -1,
      "name": "Rock_Marble_Cobble",
      "rotation": 1
    },
    {
      "x": -2,
      "y": 1,
      "z": -1,
      "name": "Rock_Marble",
      "rotation": 1
    },
    {
      "x": -2,
      "y": 2,
      "z": -1,
      "name": "Rock_Marble_Cobble",
      "rotation": 1
    },
    {
      "x": -2,
      "y": 3,
      "z": -1,
      "name": "Rock_Marble_Cobble",
      "rotation": 1
    },
    {
      "x": -2,
      "y": 4,
      "z": -1,
      "name": "Rock_Marble_Cobble",
      "rotation": 1
    },
    {
      "x": -2,
      "y": 5,
      "z": -1,
      "name": "Rock_Marble_Cobble",
      "rotation": 1
    },
    {
      "x": -2,
      "y": 6,
      "z": -1,
      "name": "Rock_Marble_Cobble",
      "rotation": 1
    },
    {
      "x": -2,
      "y": 7,
      "z": -1,
      "name": "Rock_Marble",
      "rotation": 1
    },
    {
      "x": -2,
      "y": 8,
      "z": -1,
      "name": "Rock_Chalk",
      "rotation": 1
    },
    {
      "x": -2,
      "y": 9,
      "z": -1,
      "name": "Rock_Chalk",
      "rotation": 1
    },
    {
      "x": -2,
      "y": 10,
      "z": -1,
      "name": "Rock_Chalk",
      "rotation": 1
    },
    {
      "x": -2,
      "y": 11,
      "z": -1,
      "name": "Rock_Chalk",
      "rotation": 1
    },
    {
      "x": -2,
      "y": 12,
      "z": -1,
      "name": "Rock_Marble",
      "rotation": 1
    },
    {
      "x": -2,
      "y": 13,
      "z": -1,
      "name": "Rock_Marble_Cobble",
      "rotation": 1
    },
    {
      "x": -2,
      "y": 14,
      "z": -1,
      "name": "Rock_Marble_Cobble",
      "rotation": 1
    },
    {
      "x": -2,
      "y": 15,
      "z": -1,
      "name": "Rock_Marble_Cobble",
      "rotation": 1
    },
    {
      "x": -2,
      "y": 16,
      "z": -1,
      "name": "Rock_Marble_Cobble",
      "rotation": 1
    },
    {
      "x": -2,
      "y": 17,
      "z": -1,
      "name": "Rock_Marble",
      "rotation": 1
    },
    {
      "x": -2,
      "y": 18,
      "z": -1,
      "name": "Rock_Marble",
      "rotation": 1
    },
    {
      "x": -2,
      "y": 19,
      "z": -1,
      "name": "Soil_Clay_White",
      "rotation": 1
    },
    {
      "x": -2,
      "y": 20,
      "z": -1,
      "name": "Rock_Chalk",
      "rotation": 1
    },
    {
      "x": -2,
      "y": 21,
      "z": -1,
      "name": "Rock_Marble",
      "rotation": 1
    },
    {
      "x": -2,
      "y": 22,
      "z": -1,
      "name": "Rock_Marble_Cobble",
      "rotation": 1
    },
    {
      "x": -2,
      "y": 23,
      "z": -1,
      "name": "Rock_Marble_Cobble",
      "rotation": 1
    },
    {
      "x": -2,
      "y": 24,
      "z": -1,
      "name": "Rock_Marble_Cobble",
      "rotation": 1
    },
    {
      "x": -2,
      "y": 25,
      "z": -1,
      "name": "Rock_Marble",
      "rotation": 1
    },
    {
      "x": -2,
      "y": 26,
      "z": -1,
      "name": "Rock_Marble_Cobble",
      "rotation": 1
    },
    {
      "x": -2,
      "y": 27,
      "z": -1,
      "name": "Rock_Marble_Cobble",
      "rotation": 1
    },
    {
      "x": -2,
      "y": 28,
      "z": -1,
      "name": "Rock_Marble_Cobble",
      "rotation": 1
    },
    {
      "x": -2,
      "y": 29,
      "z": -1,
      "name": "Rock_Marble_Cobble",
      "rotation": 1
    },
    {
      "x": -2,
      "y": 30,
      "z": -1,
      "name": "Plant_Moss_Block_Green"
    },
    {
      "x": -2,
      "y": 0,
      "z": 0,
      "name": "Rock_Marble_Cobble",
      "rotation": 1
    },
    {
      "x": -2,
      "y": 1,
      "z": 0,
      "name": "Rock_Marble",
      "rotation": 1
    },
    {
      "x": -2,
      "y": 2,
      "z": 0,
      "name": "Rock_Marble_Cobble",
      "rotation": 1
    },
    {
      "x": -2,
      "y": 3,
      "z": 0,
      "name": "Rock_Marble_Cobble",
      "rotation": 1
    },
    {
      "x": -2,
      "y": 4,
      "z": 0,
      "name": "Rock_Marble_Cobble",
      "rotation": 1
    },
    {
      "x": -2,
      "y": 5,
      "z": 0,
      "name": "Rock_Marble_Cobble",
      "rotation": 1
    },
    {
      "x": -2,
      "y": 6,
      "z": 0,
      "name": "Rock_Marble_Cobble",
      "rotation": 1
    },
    {
      "x": -2,
      "y": 7,
      "z": 0,
      "name": "Rock_Marble",
      "rotation": 1
    },
    {
      "x": -2,
      "y": 8,
      "z": 0,
      "name": "Rock_Chalk",
      "rotation": 1
    },
    {
      "x": -2,
      "y": 9,
      "z": 0,
      "name": "Rock_Chalk",
      "rotation": 1
    },
    {
      "x": -2,
      "y": 10,
      "z": 0,
      "name": "Rock_Chalk",
      "rotation": 1
    },
    {
      "x": -2,
      "y": 11,
      "z": 0,
      "name": "Rock_Chalk",
      "rotation": 1
    },
    {
      "x": -2,
      "y": 12,
      "z": 0,
      "name": "Rock_Marble",
      "rotation": 1
    },
    {
      "x": -2,
      "y": 13,
      "z": 0,
      "name": "Rock_Marble_Cobble",
      "rotation": 1
    },
    {
      "x": -2,
      "y": 14,
      "z": 0,
      "name": "Rock_Marble_Cobble",
      "rotation": 1
    },
    {
      "x": -2,
      "y": 15,
      "z": 0,
      "name": "Rock_Marble_Cobble",
      "rotation": 1
    },
    {
      "x": -2,
      "y": 16,
      "z": 0,
      "name": "Rock_Marble_Cobble",
      "rotation": 1
    },
    {
      "x": -2,
      "y": 17,
      "z": 0,
      "name": "Rock_Marble",
      "rotation": 1
    },
    {
      "x": -2,
      "y": 18,
      "z": 0,
      "name": "Rock_Marble",
      "rotation": 1
    },
    {
      "x": -2,
      "y": 19,
      "z": 0,
      "name": "Soil_Clay_White",
      "rotation": 1
    },
    {
      "x": -2,
      "y": 20,
      "z": 0,
      "name": "Rock_Chalk",
      "rotation": 1
    },
    {
      "x": -2,
      "y": 21,
      "z": 0,
      "name": "Rock_Marble",
      "rotation": 1
    },
    {
      "x": -2,
      "y": 22,
      "z": 0,
      "name": "Rock_Marble_Cobble",
      "rotation": 1
    },
    {
      "x": -2,
      "y": 23,
      "z": 0,
      "name": "Rock_Marble_Cobble",
      "rotation": 1
    },
    {
      "x": -2,
      "y": 24,
      "z": 0,
      "name": "Rock_Marble_Cobble",
      "rotation": 1
    },
    {
      "x": -2,
      "y": 25,
      "z": 0,
      "name": "Rock_Marble",
      "rotation": 1
    },
    {
      "x": -2,
      "y": 26,
      "z": 0,
      "name": "Rock_Marble_Cobble",
      "rotation": 1
    },
    {
      "x": -2,
      "y": 27,
      "z": 0,
      "name": "Rock_Marble_Cobble",
      "rotation": 1
    },
    {
      "x": -2,
      "y": 28,
      "z": 0,
      "name": "Rock_Marble_Cobble",
      "rotation": 1
    },
    {
      "x": -2,
      "y": 29,
      "z": 0,
      "name": "Rock_Marble_Cobble",
      "rotation": 1
    },
    {
      "x": -2,
      "y": 30,
      "z": 0,
      "name": "Rock_Marble",
      "rotation": 1
    },
    {
      "x": -2,
      "y": 31,
      "z": 0,
      "name": "Soil_Clay_White",
      "rotation": 1
    },
    {
      "x": -2,
      "y": 32,
      "z": 0,
      "name": "Plant_Moss_Block_Green"
    },
    {
      "x": -2,
      "y": 33,
      "z": 0,
      "name": "Plant_Moss_Block_Green"
    },
    {
      "x": -2,
      "y": 0,
      "z": 1,
      "name": "Rock_Marble_Cobble",
      "rotation": 1
    },
    {
      "x": -2,
      "y": 1,
      "z": 1,
      "name": "Rock_Marble",
      "rotation": 1
    },
    {
      "x": -2,
      "y": 2,
      "z": 1,
      "name": "Rock_Marble_Cobble",
      "rotation": 1
    },
    {
      "x": -2,
      "y": 3,
      "z": 1,
      "name": "Rock_Marble_Cobble",
      "rotation": 1
    },
    {
      "x": -2,
      "y": 4,
      "z": 1,
      "name": "Rock_Marble_Cobble",
      "rotation": 1
    },
    {
      "x": -2,
      "y": 5,
      "z": 1,
      "name": "Rock_Marble_Cobble",
      "rotation": 1
    },
    {
      "x": -2,
      "y": 6,
      "z": 1,
      "name": "Rock_Marble_Cobble",
      "rotation": 1
    },
    {
      "x": -2,
      "y": 7,
      "z": 1,
      "name": "Rock_Marble",
      "rotation": 1
    },
    {
      "x": -2,
      "y": 8,
      "z": 1,
      "name": "Rock_Chalk",
      "rotation": 1
    },
    {
      "x": -2,
      "y": 9,
      "z": 1,
      "name": "Rock_Chalk",
      "rotation": 1
    },
    {
      "x": -2,
      "y": 10,
      "z": 1,
      "name": "Rock_Chalk",
      "rotation": 1
    },
    {
      "x": -2,
      "y": 11,
      "z": 1,
      "name": "Rock_Chalk",
      "rotation": 1
    },
    {
      "x": -2,
      "y": 12,
      "z": 1,
      "name": "Rock_Marble",
      "rotation": 1
    },
    {
      "x": -2,
      "y": 13,
      "z": 1,
      "name": "Rock_Marble_Cobble",
      "rotation": 1
    },
    {
      "x": -2,
      "y": 14,
      "z": 1,
      "name": "Rock_Marble_Cobble",
      "rotation": 1
    },
    {
      "x": -2,
      "y": 15,
      "z": 1,
      "name": "Rock_Marble_Cobble",
      "rotation": 1
    },
    {
      "x": -2,
      "y": 16,
      "z": 1,
      "name": "Rock_Marble_Cobble",
      "rotation": 1
    },
    {
      "x": -2,
      "y": 17,
      "z": 1,
      "name": "Rock_Marble",
      "rotation": 1
    },
    {
      "x": -2,
      "y": 18,
      "z": 1,
      "name": "Rock_Marble",
      "rotation": 1
    },
    {
      "x": -2,
      "y": 19,
      "z": 1,
      "name": "Soil_Clay_White",
      "rotation": 1
    },
    {
      "x": -2,
      "y": 20,
      "z": 1,
      "name": "Rock_Chalk",
      "rotation": 1
    },
    {
      "x": -2,
      "y": 21,
      "z": 1,
      "name": "Rock_Marble",
      "rotation": 1
    },
    {
      "x": -2,
      "y": 22,
      "z": 1,
      "name": "Rock_Marble_Cobble",
      "rotation": 1
    },
    {
      "x": -2,
      "y": 23,
      "z": 1,
      "name": "Rock_Marble_Cobble",
      "rotation": 1
    },
    {
      "x": -2,
      "y": 24,
      "z": 1,
      "name": "Rock_Marble_Cobble",
      "rotation": 1
    },
    {
      "x": -2,
      "y": 25,
      "z": 1,
      "name": "Rock_Marble",
      "rotation": 1
    },
    {
      "x": -2,
      "y": 26,
      "z": 1,
      "name": "Rock_Marble_Cobble",
      "rotation": 1
    },
    {
      "x": -2,
      "y": 27,
      "z": 1,
      "name": "Rock_Marble_Cobble",
      "rotation": 1
    },
    {
      "x": -2,
      "y": 28,
      "z": 1,
      "name": "Rock_Marble_Cobble",
      "rotation": 1
    },
    {
      "x": -2,
      "y": 29,
      "z": 1,
      "name": "Rock_Marble_Cobble",
      "rotation": 1
    },
    {
      "x": -2,
      "y": 30,
      "z": 1,
      "name": "Rock_Marble",
      "rotation": 1
    },
    {
      "x": -2,
      "y": 31,
      "z": 1,
      "name": "Soil_Clay_White",
      "rotation": 1
    },
    {
      "x": -2,
      "y": 32,
      "z": 1,
      "name": "Rock_Chalk",
      "rotation": 1
    },
    {
      "x": -2,
      "y": 33,
      "z": 1,
      "name": "Plant_Moss_Block_Green"
    },
    {
      "x": -2,
      "y": 0,
      "z": 2,
      "name": "Rock_Marble_Cobble",
      "rotation": 1
    },
    {
      "x": -2,
      "y": 1,
      "z": 2,
      "name": "Rock_Marble",
      "rotation": 1
    },
    {
      "x": -2,
      "y": 2,
      "z": 2,
      "name": "Rock_Marble_Cobble",
      "rotation": 1
    },
    {
      "x": -2,
      "y": 3,
      "z": 2,
      "name": "Rock_Marble_Cobble",
      "rotation": 1
    },
    {
      "x": -2,
      "y": 4,
      "z": 2,
      "name": "Rock_Marble_Cobble",
      "rotation": 1
    },
    {
      "x": -2,
      "y": 5,
      "z": 2,
      "name": "Rock_Marble_Cobble",
      "rotation": 1
    },
    {
      "x": -2,
      "y": 6,
      "z": 2,
      "name": "Rock_Marble_Cobble",
      "rotation": 1
    },
    {
      "x": -2,
      "y": 7,
      "z": 2,
      "name": "Rock_Marble",
      "rotation": 1
    },
    {
      "x": -2,
      "y": 8,
      "z": 2,
      "name": "Rock_Chalk",
      "rotation": 1
    },
    {
      "x": -2,
      "y": 9,
      "z": 2,
      "name": "Rock_Chalk",
      "rotation": 1
    },
    {
      "x": -2,
      "y": 10,
      "z": 2,
      "name": "Rock_Chalk",
      "rotation": 1
    },
    {
      "x": -2,
      "y": 11,
      "z": 2,
      "name": "Rock_Chalk",
      "rotation": 1
    },
    {
      "x": -2,
      "y": 12,
      "z": 2,
      "name": "Rock_Marble",
      "rotation": 1
    },
    {
      "x": -2,
      "y": 13,
      "z": 2,
      "name": "Rock_Marble_Cobble",
      "rotation": 1
    },
    {
      "x": -2,
      "y": 14,
      "z": 2,
      "name": "Rock_Marble_Cobble",
      "rotation": 1
    },
    {
      "x": -2,
      "y": 15,
      "z": 2,
      "name": "Rock_Marble_Cobble",
      "rotation": 1
    },
    {
      "x": -2,
      "y": 16,
      "z": 2,
      "name": "Rock_Marble_Cobble",
      "rotation": 1
    },
    {
      "x": -2,
      "y": 17,
      "z": 2,
      "name": "Rock_Marble",
      "rotation": 1
    },
    {
      "x": -2,
      "y": 18,
      "z": 2,
      "name": "Rock_Marble",
      "rotation": 1
    },
    {
      "x": -2,
      "y": 19,
      "z": 2,
      "name": "Soil_Clay_White",
      "rotation": 1
    },
    {
      "x": -2,
      "y": 20,
      "z": 2,
      "name": "Rock_Chalk",
      "rotation": 1
    },
    {
      "x": -2,
      "y": 21,
      "z": 2,
      "name": "Rock_Marble",
      "rotation": 1
    },
    {
      "x": -2,
      "y": 22,
      "z": 2,
      "name": "Rock_Marble",
      "rotation": 1
    },
    {
      "x": -2,
      "y": 23,
      "z": 2,
      "name": "Rock_Marble_Cobble",
      "rotation": 1
    },
    {
      "x": -2,
      "y": 24,
      "z": 2,
      "name": "Rock_Marble_Cobble",
      "rotation": 1
    },
    {
      "x": -2,
      "y": 25,
      "z": 2,
      "name": "Rock_Marble",
      "rotation": 1
    },
    {
      "x": -2,
      "y": 26,
      "z": 2,
      "name": "Rock_Marble_Cobble",
      "rotation": 1
    },
    {
      "x": -2,
      "y": 27,
      "z": 2,
      "name": "Rock_Marble_Cobble",
      "rotation": 1
    },
    {
      "x": -2,
      "y": 28,
      "z": 2,
      "name": "Rock_Marble_Cobble",
      "rotation": 1
    },
    {
      "x": -2,
      "y": 29,
      "z": 2,
      "name": "Rock_Marble",
      "rotation": 1
    },
    {
      "x": -2,
      "y": 30,
      "z": 2,
      "name": "Rock_Marble",
      "rotation": 1
    },
    {
      "x": -2,
      "y": 31,
      "z": 2,
      "name": "Soil_Clay_White",
      "rotation": 1
    },
    {
      "x": -2,
      "y": 32,
      "z": 2,
      "name": "Plant_Moss_Block_Green"
    },
    {
      "x": -2,
      "y": 33,
      "z": 2,
      "name": "Plant_Moss_Block_Green"
    },
    {
      "x": -2,
      "y": 34,
      "z": 2,
      "name": "Plant_Moss_Block_Green"
    },
    {
      "x": -2,
      "y": 0,
      "z": 3,
      "name": "Rock_Marble_Cobble",
      "rotation": 1
    },
    {
      "x": -2,
      "y": 1,
      "z": 3,
      "name": "Rock_Marble",
      "rotation": 1
    },
    {
      "x": -2,
      "y": 2,
      "z": 3,
      "name": "Rock_Marble_Cobble",
      "rotation": 1
    },
    {
      "x": -2,
      "y": 3,
      "z": 3,
      "name": "Rock_Marble_Cobble",
      "rotation": 1
    },
    {
      "x": -2,
      "y": 4,
      "z": 3,
      "name": "Rock_Marble_Cobble",
      "rotation": 1
    },
    {
      "x": -2,
      "y": 5,
      "z": 3,
      "name": "Rock_Marble_Cobble",
      "rotation": 1
    },
    {
      "x": -2,
      "y": 6,
      "z": 3,
      "name": "Rock_Marble_Cobble",
      "rotation": 1
    },
    {
      "x": -2,
      "y": 7,
      "z": 3,
      "name": "Rock_Marble",
      "rotation": 1
    },
    {
      "x": -2,
      "y": 8,
      "z": 3,
      "name": "Rock_Chalk",
      "rotation": 1
    },
    {
      "x": -2,
      "y": 9,
      "z": 3,
      "name": "Rock_Chalk",
      "rotation": 1
    },
    {
      "x": -2,
      "y": 10,
      "z": 3,
      "name": "Rock_Chalk",
      "rotation": 1
    },
    {
      "x": -2,
      "y": 11,
      "z": 3,
      "name": "Rock_Chalk",
      "rotation": 1
    },
    {
      "x": -2,
      "y": 12,
      "z": 3,
      "name": "Rock_Marble",
      "rotation": 1
    },
    {
      "x": -2,
      "y": 13,
      "z": 3,
      "name": "Rock_Marble_Cobble",
      "rotation": 1
    },
    {
      "x": -2,
      "y": 14,
      "z": 3,
      "name": "Rock_Marble_Cobble",
      "rotation": 1
    },
    {
      "x": -2,
      "y": 15,
      "z": 3,
      "name": "Rock_Marble_Cobble",
      "rotation": 1
    },
    {
      "x": -2,
      "y": 16,
      "z": 3,
      "name": "Rock_Marble_Cobble",
      "rotation": 1
    },
    {
      "x": -2,
      "y": 17,
      "z": 3,
      "name": "Rock_Marble",
      "rotation": 1
    },
    {
      "x": -2,
      "y": 18,
      "z": 3,
      "name": "Rock_Marble",
      "rotation": 1
    },
    {
      "x": -2,
      "y": 19,
      "z": 3,
      "name": "Soil_Clay_White",
      "rotation": 1
    },
    {
      "x": -2,
      "y": 20,
      "z": 3,
      "name": "Rock_Chalk",
      "rotation": 1
    },
    {
      "x": -2,
      "y": 21,
      "z": 3,
      "name": "Rock_Marble",
      "rotation": 1
    },
    {
      "x": -2,
      "y": 22,
      "z": 3,
      "name": "Rock_Marble",
      "rotation": 1
    },
    {
      "x": -2,
      "y": 23,
      "z": 3,
      "name": "Rock_Marble_Cobble",
      "rotation": 1
    },
    {
      "x": -2,
      "y": 24,
      "z": 3,
      "name": "Rock_Marble_Cobble",
      "rotation": 1
    },
    {
      "x": -2,
      "y": 25,
      "z": 3,
      "name": "Rock_Marble",
      "rotation": 1
    },
    {
      "x": -2,
      "y": 26,
      "z": 3,
      "name": "Rock_Marble_Cobble",
      "rotation": 1
    },
    {
      "x": -2,
      "y": 27,
      "z": 3,
      "name": "Rock_Marble_Cobble",
      "rotation": 1
    },
    {
      "x": -2,
      "y": 28,
      "z": 3,
      "name": "Rock_Marble_Cobble",
      "rotation": 1
    },
    {
      "x": -2,
      "y": 29,
      "z": 3,
      "name": "Rock_Marble",
      "rotation": 1
    },
    {
      "x": -2,
      "y": 30,
      "z": 3,
      "name": "Rock_Marble",
      "rotation": 1
    },
    {
      "x": -2,
      "y": 31,
      "z": 3,
      "name": "Plant_Moss_Block_Green"
    },
    {
      "x": -2,
      "y": 32,
      "z": 3,
      "name": "Plant_Moss_Block_Green"
    },
    {
      "x": -2,
      "y": 33,
      "z": 3,
      "name": "Plant_Moss_Block_Green"
    },
    {
      "x": -2,
      "y": 0,
      "z": 4,
      "name": "Rock_Marble_Cobble",
      "rotation": 1
    },
    {
      "x": -2,
      "y": 1,
      "z": 4,
      "name": "Rock_Marble",
      "rotation": 1
    },
    {
      "x": -2,
      "y": 2,
      "z": 4,
      "name": "Rock_Marble_Cobble",
      "rotation": 1
    },
    {
      "x": -2,
      "y": 3,
      "z": 4,
      "name": "Rock_Marble_Cobble",
      "rotation": 1
    },
    {
      "x": -2,
      "y": 4,
      "z": 4,
      "name": "Rock_Marble_Cobble",
      "rotation": 1
    },
    {
      "x": -2,
      "y": 5,
      "z": 4,
      "name": "Rock_Marble_Cobble",
      "rotation": 1
    },
    {
      "x": -2,
      "y": 6,
      "z": 4,
      "name": "Rock_Marble_Cobble",
      "rotation": 1
    },
    {
      "x": -2,
      "y": 7,
      "z": 4,
      "name": "Rock_Marble",
      "rotation": 1
    },
    {
      "x": -2,
      "y": 8,
      "z": 4,
      "name": "Rock_Chalk",
      "rotation": 1
    },
    {
      "x": -2,
      "y": 9,
      "z": 4,
      "name": "Rock_Chalk",
      "rotation": 1
    },
    {
      "x": -2,
      "y": 10,
      "z": 4,
      "name": "Rock_Chalk",
      "rotation": 1
    },
    {
      "x": -2,
      "y": 11,
      "z": 4,
      "name": "Rock_Chalk",
      "rotation": 1
    },
    {
      "x": -2,
      "y": 12,
      "z": 4,
      "name": "Rock_Marble",
      "rotation": 1
    },
    {
      "x": -2,
      "y": 13,
      "z": 4,
      "name": "Rock_Marble_Cobble",
      "rotation": 1
    },
    {
      "x": -2,
      "y": 14,
      "z": 4,
      "name": "Rock_Marble_Cobble",
      "rotation": 1
    },
    {
      "x": -2,
      "y": 15,
      "z": 4,
      "name": "Rock_Marble_Cobble",
      "rotation": 1
    },
    {
      "x": -2,
      "y": 16,
      "z": 4,
      "name": "Rock_Marble_Cobble",
      "rotation": 1
    },
    {
      "x": -2,
      "y": 17,
      "z": 4,
      "name": "Rock_Marble",
      "rotation": 1
    },
    {
      "x": -2,
      "y": 18,
      "z": 4,
      "name": "Rock_Marble",
      "rotation": 1
    },
    {
      "x": -2,
      "y": 25,
      "z": 4,
      "name": "Rock_Marble",
      "rotation": 1
    },
    {
      "x": -2,
      "y": 26,
      "z": 4,
      "name": "Rock_Marble_Cobble",
      "rotation": 1
    },
    {
      "x": -2,
      "y": 27,
      "z": 4,
      "name": "Soil_Clay_GreyLight",
      "rotation": 1
    },
    {
      "x": -2,
      "y": 28,
      "z": 4,
      "name": "Rock_Marble_Cobble",
      "rotation": 1
    },
    {
      "x": -2,
      "y": 29,
      "z": 4,
      "name": "Rock_Marble",
      "rotation": 1
    },
    {
      "x": -2,
      "y": 30,
      "z": 4,
      "name": "Rock_Marble",
      "rotation": 1
    },
    {
      "x": -2,
      "y": 31,
      "z": 4,
      "name": "Plant_Moss_Block_Green"
    },
    {
      "x": -2,
      "y": 2,
      "z": 5,
      "name": "Rock_Marble_Cobble",
      "rotation": 1
    },
    {
      "x": -2,
      "y": 3,
      "z": 5,
      "name": "Rock_Marble_Cobble",
      "rotation": 1
    },
    {
      "x": -2,
      "y": 4,
      "z": 5,
      "name": "Rock_Marble_Cobble",
      "rotation": 1
    },
    {
      "x": -2,
      "y": 5,
      "z": 5,
      "name": "Rock_Marble_Cobble",
      "rotation": 1
    },
    {
      "x": -2,
      "y": 6,
      "z": 5,
      "name": "Rock_Marble_Cobble",
      "rotation": 1
    },
    {
      "x": -2,
      "y": 7,
      "z": 5,
      "name": "Rock_Marble",
      "rotation": 1
    },
    {
      "x": -2,
      "y": 8,
      "z": 5,
      "name": "Rock_Chalk",
      "rotation": 1
    },
    {
      "x": -2,
      "y": 9,
      "z": 5,
      "name": "Rock_Chalk",
      "rotation": 1
    },
    {
      "x": -2,
      "y": 10,
      "z": 5,
      "name": "Rock_Chalk",
      "rotation": 1
    },
    {
      "x": -2,
      "y": 11,
      "z": 5,
      "name": "Rock_Chalk",
      "rotation": 1
    },
    {
      "x": -2,
      "y": 12,
      "z": 5,
      "name": "Rock_Marble",
      "rotation": 1
    },
    {
      "x": -2,
      "y": 30,
      "z": 5,
      "name": "Plant_Moss_Wall_Green",
      "rotation": 3
    },
    {
      "x": -2,
      "y": 31,
      "z": 5,
      "name": "Plant_Moss_Wall_Green"
    },
    {
      "x": -2,
      "y": 5,
      "z": 6,
      "name": "Rock_Marble_Cobble",
      "rotation": 1
    },
    {
      "x": -2,
      "y": 6,
      "z": 6,
      "name": "Rock_Marble_Cobble",
      "rotation": 1
    },
    {
      "x": -2,
      "y": 7,
      "z": 6,
      "name": "Rock_Marble",
      "rotation": 1
    },
    {
      "x": -2,
      "y": 8,
      "z": 6,
      "name": "Rock_Chalk",
      "rotation": 1
    },
    {
      "x": -2,
      "y": 9,
      "z": 6,
      "name": "Rock_Chalk",
      "rotation": 1
    },
    {
      "x": -2,
      "y": 10,
      "z": 6,
      "name": "Rock_Chalk",
      "rotation": 1
    },
    {
      "x": -1,
      "y": 4,
      "z": -6,
      "name": "Rock_Marble_Cobble",
      "rotation": 1
    },
    {
      "x": -1,
      "y": 5,
      "z": -6,
      "name": "Rock_Marble_Cobble",
      "rotation": 1
    },
    {
      "x": -1,
      "y": 6,
      "z": -6,
      "name": "Rock_Marble_Cobble",
      "rotation": 1
    },
    {
      "x": -1,
      "y": 7,
      "z": -6,
      "name": "Rock_Marble",
      "rotation": 1
    },
    {
      "x": -1,
      "y": 2,
      "z": -5,
      "name": "Rock_Marble_Cobble",
      "rotation": 1
    },
    {
      "x": -1,
      "y": 3,
      "z": -5,
      "name": "Rock_Marble_Cobble",
      "rotation": 1
    },
    {
      "x": -1,
      "y": 4,
      "z": -5,
      "name": "Rock_Marble_Cobble",
      "rotation": 1
    },
    {
      "x": -1,
      "y": 5,
      "z": -5,
      "name": "Rock_Marble_Cobble",
      "rotation": 1
    },
    {
      "x": -1,
      "y": 6,
      "z": -5,
      "name": "Rock_Marble_Cobble",
      "rotation": 1
    },
    {
      "x": -1,
      "y": 7,
      "z": -5,
      "name": "Rock_Marble",
      "rotation": 1
    },
    {
      "x": -1,
      "y": 8,
      "z": -5,
      "name": "Rock_Chalk",
      "rotation": 1
    },
    {
      "x": -1,
      "y": 9,
      "z": -5,
      "name": "Rock_Chalk",
      "rotation": 1
    },
    {
      "x": -1,
      "y": 10,
      "z": -5,
      "name": "Rock_Chalk",
      "rotation": 1
    },
    {
      "x": -1,
      "y": 11,
      "z": -5,
      "name": "Rock_Chalk",
      "rotation": 1
    },
    {
      "x": -1,
      "y": 1,
      "z": -4,
      "name": "Rock_Marble",
      "rotation": 1
    },
    {
      "x": -1,
      "y": 2,
      "z": -4,
      "name": "Rock_Marble_Cobble",
      "rotation": 1
    },
    {
      "x": -1,
      "y": 3,
      "z": -4,
      "name": "Rock_Marble_Cobble",
      "rotation": 1
    },
    {
      "x": -1,
      "y": 4,
      "z": -4,
      "name": "Rock_Marble_Cobble",
      "rotation": 1
    },
    {
      "x": -1,
      "y": 5,
      "z": -4,
      "name": "Rock_Marble_Cobble",
      "rotation": 1
    },
    {
      "x": -1,
      "y": 6,
      "z": -4,
      "name": "Rock_Marble_Cobble",
      "rotation": 1
    },
    {
      "x": -1,
      "y": 7,
      "z": -4,
      "name": "Rock_Marble",
      "rotation": 1
    },
    {
      "x": -1,
      "y": 8,
      "z": -4,
      "name": "Rock_Chalk",
      "rotation": 1
    },
    {
      "x": -1,
      "y": 9,
      "z": -4,
      "name": "Rock_Chalk",
      "rotation": 1
    },
    {
      "x": -1,
      "y": 10,
      "z": -4,
      "name": "Rock_Chalk",
      "rotation": 1
    },
    {
      "x": -1,
      "y": 11,
      "z": -4,
      "name": "Rock_Chalk",
      "rotation": 1
    },
    {
      "x": -1,
      "y": 12,
      "z": -4,
      "name": "Rock_Marble",
      "rotation": 1
    },
    {
      "x": -1,
      "y": 13,
      "z": -4,
      "name": "Rock_Marble_Cobble",
      "rotation": 1
    },
    {
      "x": -1,
      "y": 14,
      "z": -4,
      "name": "Rock_Marble_Cobble",
      "rotation": 1
    },
    {
      "x": -1,
      "y": 15,
      "z": -4,
      "name": "Rock_Marble_Cobble",
      "rotation": 1
    },
    {
      "x": -1,
      "y": 0,
      "z": -3,
      "name": "Rock_Marble_Cobble",
      "rotation": 1
    },
    {
      "x": -1,
      "y": 1,
      "z": -3,
      "name": "Rock_Marble",
      "rotation": 1
    },
    {
      "x": -1,
      "y": 2,
      "z": -3,
      "name": "Rock_Marble_Cobble",
      "rotation": 1
    },
    {
      "x": -1,
      "y": 3,
      "z": -3,
      "name": "Rock_Marble_Cobble",
      "rotation": 1
    },
    {
      "x": -1,
      "y": 4,
      "z": -3,
      "name": "Rock_Marble_Cobble",
      "rotation": 1
    },
    {
      "x": -1,
      "y": 5,
      "z": -3,
      "name": "Rock_Marble_Cobble",
      "rotation": 1
    },
    {
      "x": -1,
      "y": 6,
      "z": -3,
      "name": "Rock_Marble_Cobble",
      "rotation": 1
    },
    {
      "x": -1,
      "y": 7,
      "z": -3,
      "name": "Rock_Marble",
      "rotation": 1
    },
    {
      "x": -1,
      "y": 8,
      "z": -3,
      "name": "Rock_Chalk",
      "rotation": 1
    },
    {
      "x": -1,
      "y": 9,
      "z": -3,
      "name": "Rock_Chalk",
      "rotation": 1
    },
    {
      "x": -1,
      "y": 10,
      "z": -3,
      "name": "Rock_Chalk",
      "rotation": 1
    },
    {
      "x": -1,
      "y": 11,
      "z": -3,
      "name": "Rock_Chalk",
      "rotation": 1
    },
    {
      "x": -1,
      "y": 12,
      "z": -3,
      "name": "Rock_Marble",
      "rotation": 1
    },
    {
      "x": -1,
      "y": 13,
      "z": -3,
      "name": "Rock_Marble_Cobble",
      "rotation": 1
    },
    {
      "x": -1,
      "y": 14,
      "z": -3,
      "name": "Rock_Marble_Cobble",
      "rotation": 1
    },
    {
      "x": -1,
      "y": 15,
      "z": -3,
      "name": "Rock_Marble_Cobble",
      "rotation": 1
    },
    {
      "x": -1,
      "y": 16,
      "z": -3,
      "name": "Rock_Marble_Cobble",
      "rotation": 1
    },
    {
      "x": -1,
      "y": 17,
      "z": -3,
      "name": "Soil_Clay_White",
      "rotation": 1
    },
    {
      "x": -1,
      "y": 18,
      "z": -3,
      "name": "Rock_Marble",
      "rotation": 1
    },
    {
      "x": -1,
      "y": 19,
      "z": -3,
      "name": "Soil_Clay_White",
      "rotation": 1
    },
    {
      "x": -1,
      "y": 0,
      "z": -2,
      "name": "Rock_Marble_Cobble",
      "rotation": 1
    },
    {
      "x": -1,
      "y": 1,
      "z": -2,
      "name": "Rock_Marble",
      "rotation": 1
    },
    {
      "x": -1,
      "y": 2,
      "z": -2,
      "name": "Rock_Marble_Cobble",
      "rotation": 1
    },
    {
      "x": -1,
      "y": 3,
      "z": -2,
      "name": "Rock_Marble_Cobble",
      "rotation": 1
    },
    {
      "x": -1,
      "y": 4,
      "z": -2,
      "name": "Rock_Marble_Cobble",
      "rotation": 1
    },
    {
      "x": -1,
      "y": 5,
      "z": -2,
      "name": "Rock_Marble_Cobble",
      "rotation": 1
    },
    {
      "x": -1,
      "y": 6,
      "z": -2,
      "name": "Rock_Marble_Cobble",
      "rotation": 1
    },
    {
      "x": -1,
      "y": 7,
      "z": -2,
      "name": "Rock_Marble",
      "rotation": 1
    },
    {
      "x": -1,
      "y": 8,
      "z": -2,
      "name": "Rock_Chalk",
      "rotation": 1
    },
    {
      "x": -1,
      "y": 9,
      "z": -2,
      "name": "Rock_Chalk",
      "rotation": 1
    },
    {
      "x": -1,
      "y": 10,
      "z": -2,
      "name": "Rock_Chalk",
      "rotation": 1
    },
    {
      "x": -1,
      "y": 11,
      "z": -2,
      "name": "Rock_Chalk",
      "rotation": 1
    },
    {
      "x": -1,
      "y": 12,
      "z": -2,
      "name": "Rock_Marble",
      "rotation": 1
    },
    {
      "x": -1,
      "y": 13,
      "z": -2,
      "name": "Rock_Marble_Cobble",
      "rotation": 1
    },
    {
      "x": -1,
      "y": 14,
      "z": -2,
      "name": "Rock_Marble_Cobble",
      "rotation": 1
    },
    {
      "x": -1,
      "y": 15,
      "z": -2,
      "name": "Rock_Marble_Cobble",
      "rotation": 1
    },
    {
      "x": -1,
      "y": 16,
      "z": -2,
      "name": "Rock_Marble_Cobble",
      "rotation": 1
    },
    {
      "x": -1,
      "y": 17,
      "z": -2,
      "name": "Soil_Clay_White",
      "rotation": 1
    },
    {
      "x": -1,
      "y": 18,
      "z": -2,
      "name": "Rock_Marble",
      "rotation": 1
    },
    {
      "x": -1,
      "y": 19,
      "z": -2,
      "name": "Soil_Clay_White",
      "rotation": 1
    },
    {
      "x": -1,
      "y": 20,
      "z": -2,
      "name": "Rock_Chalk",
      "rotation": 1
    },
    {
      "x": -1,
      "y": 21,
      "z": -2,
      "name": "Rock_Marble",
      "rotation": 1
    },
    {
      "x": -1,
      "y": 22,
      "z": -2,
      "name": "Rock_Marble_Cobble",
      "rotation": 1
    },
    {
      "x": -1,
      "y": 23,
      "z": -2,
      "name": "Rock_Marble_Cobble",
      "rotation": 1
    },
    {
      "x": -1,
      "y": 24,
      "z": -2,
      "name": "Rock_Marble_Cobble",
      "rotation": 1
    },
    {
      "x": -1,
      "y": 25,
      "z": -2,
      "name": "Rock_Marble",
      "rotation": 1
    },
    {
      "x": -1,
      "y": 26,
      "z": -2,
      "name": "Rock_Marble_Cobble",
      "rotation": 1
    },
    {
      "x": -1,
      "y": 27,
      "z": -2,
      "name": "Rock_Marble_Cobble",
      "rotation": 1
    },
    {
      "x": -1,
      "y": 28,
      "z": -2,
      "name": "Rock_Marble_Cobble",
      "rotation": 1
    },
    {
      "x": -1,
      "y": 30,
      "z": -2,
      "name": "Plant_Moss_Wall_Green",
      "rotation": 2
    },
    {
      "x": -1,
      "y": 31,
      "z": -2,
      "name": "Plant_Moss_Wall_Green",
      "rotation": 2
    },
    {
      "x": -1,
      "y": 0,
      "z": -1,
      "name": "Rock_Marble_Cobble",
      "rotation": 1
    },
    {
      "x": -1,
      "y": 1,
      "z": -1,
      "name": "Rock_Marble",
      "rotation": 1
    },
    {
      "x": -1,
      "y": 2,
      "z": -1,
      "name": "Rock_Marble_Cobble",
      "rotation": 1
    },
    {
      "x": -1,
      "y": 3,
      "z": -1,
      "name": "Rock_Marble_Cobble",
      "rotation": 1
    },
    {
      "x": -1,
      "y": 4,
      "z": -1,
      "name": "Rock_Marble_Cobble",
      "rotation": 1
    },
    {
      "x": -1,
      "y": 5,
      "z": -1,
      "name": "Rock_Marble_Cobble",
      "rotation": 1
    },
    {
      "x": -1,
      "y": 6,
      "z": -1,
      "name": "Rock_Marble_Cobble",
      "rotation": 1
    },
    {
      "x": -1,
      "y": 7,
      "z": -1,
      "name": "Rock_Marble",
      "rotation": 1
    },
    {
      "x": -1,
      "y": 8,
      "z": -1,
      "name": "Rock_Chalk",
      "rotation": 1
    },
    {
      "x": -1,
      "y": 9,
      "z": -1,
      "name": "Rock_Chalk",
      "rotation": 1
    },
    {
      "x": -1,
      "y": 10,
      "z": -1,
      "name": "Rock_Chalk",
      "rotation": 1
    },
    {
      "x": -1,
      "y": 11,
      "z": -1,
      "name": "Rock_Chalk",
      "rotation": 1
    },
    {
      "x": -1,
      "y": 12,
      "z": -1,
      "name": "Rock_Marble",
      "rotation": 1
    },
    {
      "x": -1,
      "y": 13,
      "z": -1,
      "name": "Rock_Marble_Cobble",
      "rotation": 1
    },
    {
      "x": -1,
      "y": 14,
      "z": -1,
      "name": "Rock_Marble_Cobble",
      "rotation": 1
    },
    {
      "x": -1,
      "y": 15,
      "z": -1,
      "name": "Rock_Marble_Cobble",
      "rotation": 1
    },
    {
      "x": -1,
      "y": 16,
      "z": -1,
      "name": "Rock_Marble_Cobble",
      "rotation": 1
    },
    {
      "x": -1,
      "y": 17,
      "z": -1,
      "name": "Soil_Clay_White",
      "rotation": 1
    },
    {
      "x": -1,
      "y": 18,
      "z": -1,
      "name": "Rock_Marble",
      "rotation": 1
    },
    {
      "x": -1,
      "y": 19,
      "z": -1,
      "name": "Soil_Clay_White",
      "rotation": 1
    },
    {
      "x": -1,
      "y": 20,
      "z": -1,
      "name": "Rock_Chalk",
      "rotation": 1
    },
    {
      "x": -1,
      "y": 21,
      "z": -1,
      "name": "Rock_Marble",
      "rotation": 1
    },
    {
      "x": -1,
      "y": 22,
      "z": -1,
      "name": "Rock_Marble_Cobble",
      "rotation": 1
    },
    {
      "x": -1,
      "y": 23,
      "z": -1,
      "name": "Rock_Marble_Cobble",
      "rotation": 1
    },
    {
      "x": -1,
      "y": 24,
      "z": -1,
      "name": "Rock_Marble_Cobble",
      "rotation": 1
    },
    {
      "x": -1,
      "y": 25,
      "z": -1,
      "name": "Rock_Marble",
      "rotation": 1
    },
    {
      "x": -1,
      "y": 26,
      "z": -1,
      "name": "Rock_Marble_Cobble",
      "rotation": 1
    },
    {
      "x": -1,
      "y": 27,
      "z": -1,
      "name": "Rock_Marble_Cobble",
      "rotation": 1
    },
    {
      "x": -1,
      "y": 28,
      "z": -1,
      "name": "Rock_Marble_Cobble",
      "rotation": 1
    },
    {
      "x": -1,
      "y": 29,
      "z": -1,
      "name": "Rock_Marble_Cobble",
      "rotation": 1
    },
    {
      "x": -1,
      "y": 30,
      "z": -1,
      "name": "Rock_Marble",
      "rotation": 1
    },
    {
      "x": -1,
      "y": 31,
      "z": -1,
      "name": "Plant_Moss_Block_Green"
    },
    {
      "x": -1,
      "y": 32,
      "z": -1,
      "name": "Plant_Moss_Block_Green"
    },
    {
      "x": -1,
      "y": 0,
      "z": 0,
      "name": "Rock_Marble_Cobble",
      "rotation": 1
    },
    {
      "x": -1,
      "y": 1,
      "z": 0,
      "name": "Rock_Marble",
      "rotation": 1
    },
    {
      "x": -1,
      "y": 2,
      "z": 0,
      "name": "Rock_Marble_Cobble",
      "rotation": 1
    },
    {
      "x": -1,
      "y": 3,
      "z": 0,
      "name": "Rock_Marble_Cobble",
      "rotation": 1
    },
    {
      "x": -1,
      "y": 4,
      "z": 0,
      "name": "Rock_Marble_Cobble",
      "rotation": 1
    },
    {
      "x": -1,
      "y": 5,
      "z": 0,
      "name": "Rock_Marble_Cobble",
      "rotation": 1
    },
    {
      "x": -1,
      "y": 6,
      "z": 0,
      "name": "Rock_Marble_Cobble",
      "rotation": 1
    },
    {
      "x": -1,
      "y": 7,
      "z": 0,
      "name": "Rock_Marble",
      "rotation": 1
    },
    {
      "x": -1,
      "y": 8,
      "z": 0,
      "name": "Rock_Chalk",
      "rotation": 1
    },
    {
      "x": -1,
      "y": 9,
      "z": 0,
      "name": "Rock_Chalk",
      "rotation": 1
    },
    {
      "x": -1,
      "y": 10,
      "z": 0,
      "name": "Rock_Chalk",
      "rotation": 1
    },
    {
      "x": -1,
      "y": 11,
      "z": 0,
      "name": "Rock_Chalk",
      "rotation": 1
    },
    {
      "x": -1,
      "y": 12,
      "z": 0,
      "name": "Rock_Marble",
      "rotation": 1
    },
    {
      "x": -1,
      "y": 13,
      "z": 0,
      "name": "Rock_Marble_Cobble",
      "rotation": 1
    },
    {
      "x": -1,
      "y": 14,
      "z": 0,
      "name": "Rock_Marble_Cobble",
      "rotation": 1
    },
    {
      "x": -1,
      "y": 15,
      "z": 0,
      "name": "Rock_Marble_Cobble",
      "rotation": 1
    },
    {
      "x": -1,
      "y": 16,
      "z": 0,
      "name": "Rock_Marble_Cobble",
      "rotation": 1
    },
    {
      "x": -1,
      "y": 17,
      "z": 0,
      "name": "Rock_Marble",
      "rotation": 1
    },
    {
      "x": -1,
      "y": 18,
      "z": 0,
      "name": "Rock_Marble",
      "rotation": 1
    },
    {
      "x": -1,
      "y": 19,
      "z": 0,
      "name": "Soil_Clay_White",
      "rotation": 1
    },
    {
      "x": -1,
      "y": 20,
      "z": 0,
      "name": "Rock_Chalk",
      "rotation": 1
    },
    {
      "x": -1,
      "y": 21,
      "z": 0,
      "name": "Rock_Marble",
      "rotation": 1
    },
    {
      "x": -1,
      "y": 22,
      "z": 0,
      "name": "Rock_Marble_Cobble",
      "rotation": 1
    },
    {
      "x": -1,
      "y": 23,
      "z": 0,
      "name": "Rock_Marble_Cobble",
      "rotation": 1
    },
    {
      "x": -1,
      "y": 24,
      "z": 0,
      "name": "Rock_Marble_Cobble",
      "rotation": 1
    },
    {
      "x": -1,
      "y": 25,
      "z": 0,
      "name": "Rock_Marble",
      "rotation": 1
    },
    {
      "x": -1,
      "y": 26,
      "z": 0,
      "name": "Rock_Marble_Cobble",
      "rotation": 1
    },
    {
      "x": -1,
      "y": 27,
      "z": 0,
      "name": "Rock_Marble_Cobble",
      "rotation": 1
    },
    {
      "x": -1,
      "y": 28,
      "z": 0,
      "name": "Rock_Marble_Cobble",
      "rotation": 1
    },
    {
      "x": -1,
      "y": 29,
      "z": 0,
      "name": "Rock_Marble_Cobble",
      "rotation": 1
    },
    {
      "x": -1,
      "y": 30,
      "z": 0,
      "name": "Rock_Marble",
      "rotation": 1
    },
    {
      "x": -1,
      "y": 31,
      "z": 0,
      "name": "Soil_Clay_White",
      "rotation": 1
    },
    {
      "x": -1,
      "y": 32,
      "z": 0,
      "name": "Rock_Chalk",
      "rotation": 1
    },
    {
      "x": -1,
      "y": 33,
      "z": 0,
      "name": "Plant_Moss_Block_Green"
    },
    {
      "x": -1,
      "y": 34,
      "z": 0,
      "name": "Plant_Moss_Block_Green"
    },
    {
      "x": -1,
      "y": 0,
      "z": 1,
      "name": "Rock_Marble_Cobble",
      "rotation": 1
    },
    {
      "x": -1,
      "y": 1,
      "z": 1,
      "name": "Rock_Marble",
      "rotation": 1
    },
    {
      "x": -1,
      "y": 2,
      "z": 1,
      "name": "Rock_Marble_Cobble",
      "rotation": 1
    },
    {
      "x": -1,
      "y": 3,
      "z": 1,
      "name": "Rock_Marble_Cobble",
      "rotation": 1
    },
    {
      "x": -1,
      "y": 4,
      "z": 1,
      "name": "Rock_Marble_Cobble",
      "rotation": 1
    },
    {
      "x": -1,
      "y": 5,
      "z": 1,
      "name": "Rock_Marble_Cobble",
      "rotation": 1
    },
    {
      "x": -1,
      "y": 6,
      "z": 1,
      "name": "Rock_Marble_Cobble",
      "rotation": 1
    },
    {
      "x": -1,
      "y": 7,
      "z": 1,
      "name": "Rock_Marble",
      "rotation": 1
    },
    {
      "x": -1,
      "y": 8,
      "z": 1,
      "name": "Rock_Chalk",
      "rotation": 1
    },
    {
      "x": -1,
      "y": 9,
      "z": 1,
      "name": "Rock_Chalk",
      "rotation": 1
    },
    {
      "x": -1,
      "y": 10,
      "z": 1,
      "name": "Rock_Chalk",
      "rotation": 1
    },
    {
      "x": -1,
      "y": 11,
      "z": 1,
      "name": "Rock_Chalk",
      "rotation": 1
    },
    {
      "x": -1,
      "y": 12,
      "z": 1,
      "name": "Rock_Marble",
      "rotation": 1
    },
    {
      "x": -1,
      "y": 13,
      "z": 1,
      "name": "Rock_Marble_Cobble",
      "rotation": 1
    },
    {
      "x": -1,
      "y": 14,
      "z": 1,
      "name": "Rock_Marble_Cobble",
      "rotation": 1
    },
    {
      "x": -1,
      "y": 15,
      "z": 1,
      "name": "Rock_Marble_Cobble",
      "rotation": 1
    },
    {
      "x": -1,
      "y": 16,
      "z": 1,
      "name": "Rock_Marble_Cobble",
      "rotation": 1
    },
    {
      "x": -1,
      "y": 17,
      "z": 1,
      "name": "Rock_Marble",
      "rotation": 1
    },
    {
      "x": -1,
      "y": 18,
      "z": 1,
      "name": "Rock_Marble",
      "rotation": 1
    },
    {
      "x": -1,
      "y": 19,
      "z": 1,
      "name": "Soil_Clay_White",
      "rotation": 1
    },
    {
      "x": -1,
      "y": 20,
      "z": 1,
      "name": "Rock_Chalk",
      "rotation": 1
    },
    {
      "x": -1,
      "y": 21,
      "z": 1,
      "name": "Rock_Marble",
      "rotation": 1
    },
    {
      "x": -1,
      "y": 22,
      "z": 1,
      "name": "Rock_Marble_Cobble",
      "rotation": 1
    },
    {
      "x": -1,
      "y": 23,
      "z": 1,
      "name": "Rock_Marble_Cobble",
      "rotation": 1
    },
    {
      "x": -1,
      "y": 24,
      "z": 1,
      "name": "Rock_Marble_Cobble",
      "rotation": 1
    },
    {
      "x": -1,
      "y": 25,
      "z": 1,
      "name": "Rock_Marble",
      "rotation": 1
    },
    {
      "x": -1,
      "y": 26,
      "z": 1,
      "name": "Rock_Marble_Cobble",
      "rotation": 1
    },
    {
      "x": -1,
      "y": 27,
      "z": 1,
      "name": "Rock_Marble_Cobble",
      "rotation": 1
    },
    {
      "x": -1,
      "y": 28,
      "z": 1,
      "name": "Rock_Marble_Cobble",
      "rotation": 1
    },
    {
      "x": -1,
      "y": 29,
      "z": 1,
      "name": "Rock_Marble_Cobble",
      "rotation": 1
    },
    {
      "x": -1,
      "y": 30,
      "z": 1,
      "name": "Rock_Marble",
      "rotation": 1
    },
    {
      "x": -1,
      "y": 31,
      "z": 1,
      "name": "Soil_Clay_White",
      "rotation": 1
    },
    {
      "x": -1,
      "y": 32,
      "z": 1,
      "name": "Rock_Chalk",
      "rotation": 1
    },
    {
      "x": -1,
      "y": 33,
      "z": 1,
      "name": "Soil_Clay_White",
      "rotation": 1
    },
    {
      "x": -1,
      "y": 34,
      "z": 1,
      "name": "Plant_Moss_Block_Green"
    },
    {
      "x": -1,
      "y": 0,
      "z": 2,
      "name": "Rock_Marble_Cobble",
      "rotation": 1
    },
    {
      "x": -1,
      "y": 1,
      "z": 2,
      "name": "Rock_Marble",
      "rotation": 1
    },
    {
      "x": -1,
      "y": 2,
      "z": 2,
      "name": "Rock_Marble_Cobble",
      "rotation": 1
    },
    {
      "x": -1,
      "y": 3,
      "z": 2,
      "name": "Rock_Marble_Cobble",
      "rotation": 1
    },
    {
      "x": -1,
      "y": 4,
      "z": 2,
      "name": "Rock_Marble_Cobble",
      "rotation": 1
    },
    {
      "x": -1,
      "y": 5,
      "z": 2,
      "name": "Rock_Marble_Cobble",
      "rotation": 1
    },
    {
      "x": -1,
      "y": 6,
      "z": 2,
      "name": "Rock_Marble_Cobble",
      "rotation": 1
    },
    {
      "x": -1,
      "y": 7,
      "z": 2,
      "name": "Rock_Marble",
      "rotation": 1
    },
    {
      "x": -1,
      "y": 8,
      "z": 2,
      "name": "Rock_Chalk",
      "rotation": 1
    },
    {
      "x": -1,
      "y": 9,
      "z": 2,
      "name": "Rock_Chalk",
      "rotation": 1
    },
    {
      "x": -1,
      "y": 10,
      "z": 2,
      "name": "Rock_Chalk",
      "rotation": 1
    },
    {
      "x": -1,
      "y": 11,
      "z": 2,
      "name": "Rock_Chalk",
      "rotation": 1
    },
    {
      "x": -1,
      "y": 12,
      "z": 2,
      "name": "Rock_Marble",
      "rotation": 1
    },
    {
      "x": -1,
      "y": 13,
      "z": 2,
      "name": "Rock_Marble_Cobble",
      "rotation": 1
    },
    {
      "x": -1,
      "y": 14,
      "z": 2,
      "name": "Rock_Marble_Cobble",
      "rotation": 1
    },
    {
      "x": -1,
      "y": 15,
      "z": 2,
      "name": "Rock_Marble_Cobble",
      "rotation": 1
    },
    {
      "x": -1,
      "y": 16,
      "z": 2,
      "name": "Rock_Marble_Cobble",
      "rotation": 1
    },
    {
      "x": -1,
      "y": 17,
      "z": 2,
      "name": "Rock_Marble",
      "rotation": 1
    },
    {
      "x": -1,
      "y": 18,
      "z": 2,
      "name": "Rock_Marble",
      "rotation": 1
    },
    {
      "x": -1,
      "y": 19,
      "z": 2,
      "name": "Soil_Clay_White",
      "rotation": 1
    },
    {
      "x": -1,
      "y": 20,
      "z": 2,
      "name": "Rock_Chalk",
      "rotation": 1
    },
    {
      "x": -1,
      "y": 21,
      "z": 2,
      "name": "Rock_Marble",
      "rotation": 1
    },
    {
      "x": -1,
      "y": 22,
      "z": 2,
      "name": "Rock_Marble_Cobble",
      "rotation": 1
    },
    {
      "x": -1,
      "y": 23,
      "z": 2,
      "name": "Rock_Marble_Cobble",
      "rotation": 1
    },
    {
      "x": -1,
      "y": 24,
      "z": 2,
      "name": "Rock_Marble_Cobble",
      "rotation": 1
    },
    {
      "x": -1,
      "y": 25,
      "z": 2,
      "name": "Rock_Marble",
      "rotation": 1
    },
    {
      "x": -1,
      "y": 26,
      "z": 2,
      "name": "Rock_Marble_Cobble",
      "rotation": 1
    },
    {
      "x": -1,
      "y": 27,
      "z": 2,
      "name": "Rock_Marble_Cobble",
      "rotation": 1
    },
    {
      "x": -1,
      "y": 28,
      "z": 2,
      "name": "Rock_Marble_Cobble",
      "rotation": 1
    },
    {
      "x": -1,
      "y": 29,
      "z": 2,
      "name": "Rock_Marble_Cobble",
      "rotation": 1
    },
    {
      "x": -1,
      "y": 30,
      "z": 2,
      "name": "Rock_Marble",
      "rotation": 1
    },
    {
      "x": -1,
      "y": 31,
      "z": 2,
      "name": "Soil_Clay_White",
      "rotation": 1
    },
    {
      "x": -1,
      "y": 32,
      "z": 2,
      "name": "Rock_Chalk",
      "rotation": 1
    },
    {
      "x": -1,
      "y": 33,
      "z": 2,
      "name": "Soil_Clay_White",
      "rotation": 1
    },
    {
      "x": -1,
      "y": 34,
      "z": 2,
      "name": "Plant_Moss_Block_Green"
    },
    {
      "x": -1,
      "y": 0,
      "z": 3,
      "name": "Rock_Marble_Cobble",
      "rotation": 1
    },
    {
      "x": -1,
      "y": 1,
      "z": 3,
      "name": "Rock_Marble",
      "rotation": 1
    },
    {
      "x": -1,
      "y": 2,
      "z": 3,
      "name": "Rock_Marble_Cobble",
      "rotation": 1
    },
    {
      "x": -1,
      "y": 3,
      "z": 3,
      "name": "Rock_Marble_Cobble",
      "rotation": 1
    },
    {
      "x": -1,
      "y": 4,
      "z": 3,
      "name": "Rock_Marble_Cobble",
      "rotation": 1
    },
    {
      "x": -1,
      "y": 5,
      "z": 3,
      "name": "Rock_Marble_Cobble",
      "rotation": 1
    },
    {
      "x": -1,
      "y": 6,
      "z": 3,
      "name": "Rock_Marble_Cobble",
      "rotation": 1
    },
    {
      "x": -1,
      "y": 7,
      "z": 3,
      "name": "Rock_Marble",
      "rotation": 1
    },
    {
      "x": -1,
      "y": 8,
      "z": 3,
      "name": "Rock_Chalk",
      "rotation": 1
    },
    {
      "x": -1,
      "y": 9,
      "z": 3,
      "name": "Rock_Chalk",
      "rotation": 1
    },
    {
      "x": -1,
      "y": 10,
      "z": 3,
      "name": "Rock_Chalk",
      "rotation": 1
    },
    {
      "x": -1,
      "y": 11,
      "z": 3,
      "name": "Rock_Chalk",
      "rotation": 1
    },
    {
      "x": -1,
      "y": 12,
      "z": 3,
      "name": "Rock_Marble",
      "rotation": 1
    },
    {
      "x": -1,
      "y": 13,
      "z": 3,
      "name": "Rock_Marble_Cobble",
      "rotation": 1
    },
    {
      "x": -1,
      "y": 14,
      "z": 3,
      "name": "Rock_Marble_Cobble",
      "rotation": 1
    },
    {
      "x": -1,
      "y": 15,
      "z": 3,
      "name": "Rock_Marble_Cobble",
      "rotation": 1
    },
    {
      "x": -1,
      "y": 16,
      "z": 3,
      "name": "Rock_Marble_Cobble",
      "rotation": 1
    },
    {
      "x": -1,
      "y": 17,
      "z": 3,
      "name": "Rock_Marble",
      "rotation": 1
    },
    {
      "x": -1,
      "y": 18,
      "z": 3,
      "name": "Rock_Marble",
      "rotation": 1
    },
    {
      "x": -1,
      "y": 19,
      "z": 3,
      "name": "Soil_Clay_White",
      "rotation": 1
    },
    {
      "x": -1,
      "y": 20,
      "z": 3,
      "name": "Rock_Chalk",
      "rotation": 1
    },
    {
      "x": -1,
      "y": 21,
      "z": 3,
      "name": "Rock_Marble",
      "rotation": 1
    },
    {
      "x": -1,
      "y": 22,
      "z": 3,
      "name": "Rock_Marble_Cobble",
      "rotation": 1
    },
    {
      "x": -1,
      "y": 23,
      "z": 3,
      "name": "Rock_Marble_Cobble",
      "rotation": 1
    },
    {
      "x": -1,
      "y": 24,
      "z": 3,
      "name": "Rock_Marble_Cobble",
      "rotation": 1
    },
    {
      "x": -1,
      "y": 25,
      "z": 3,
      "name": "Rock_Marble",
      "rotation": 1
    },
    {
      "x": -1,
      "y": 26,
      "z": 3,
      "name": "Rock_Marble_Cobble",
      "rotation": 1
    },
    {
      "x": -1,
      "y": 27,
      "z": 3,
      "name": "Rock_Marble_Cobble",
      "rotation": 1
    },
    {
      "x": -1,
      "y": 28,
      "z": 3,
      "name": "Rock_Marble_Cobble",
      "rotation": 1
    },
    {
      "x": -1,
      "y": 29,
      "z": 3,
      "name": "Rock_Marble",
      "rotation": 1
    },
    {
      "x": -1,
      "y": 30,
      "z": 3,
      "name": "Rock_Marble",
      "rotation": 1
    },
    {
      "x": -1,
      "y": 31,
      "z": 3,
      "name": "Soil_Clay_White",
      "rotation": 1
    },
    {
      "x": -1,
      "y": 32,
      "z": 3,
      "name": "Rock_Chalk",
      "rotation": 1
    },
    {
      "x": -1,
      "y": 33,
      "z": 3,
      "name": "Soil_Clay_White",
      "rotation": 1
    },
    {
      "x": -1,
      "y": 34,
      "z": 3,
      "name": "Plant_Moss_Block_Green"
    },
    {
      "x": -1,
      "y": 0,
      "z": 4,
      "name": "Rock_Marble_Cobble",
      "rotation": 1
    },
    {
      "x": -1,
      "y": 1,
      "z": 4,
      "name": "Rock_Marble",
      "rotation": 1
    },
    {
      "x": -1,
      "y": 2,
      "z": 4,
      "name": "Rock_Marble_Cobble",
      "rotation": 1
    },
    {
      "x": -1,
      "y": 3,
      "z": 4,
      "name": "Rock_Marble_Cobble",
      "rotation": 1
    },
    {
      "x": -1,
      "y": 4,
      "z": 4,
      "name": "Rock_Marble_Cobble",
      "rotation": 1
    },
    {
      "x": -1,
      "y": 5,
      "z": 4,
      "name": "Rock_Marble_Cobble",
      "rotation": 1
    },
    {
      "x": -1,
      "y": 6,
      "z": 4,
      "name": "Rock_Marble_Cobble",
      "rotation": 1
    },
    {
      "x": -1,
      "y": 7,
      "z": 4,
      "name": "Rock_Marble",
      "rotation": 1
    },
    {
      "x": -1,
      "y": 8,
      "z": 4,
      "name": "Rock_Chalk",
      "rotation": 1
    },
    {
      "x": -1,
      "y": 9,
      "z": 4,
      "name": "Rock_Chalk",
      "rotation": 1
    },
    {
      "x": -1,
      "y": 10,
      "z": 4,
      "name": "Rock_Chalk",
      "rotation": 1
    },
    {
      "x": -1,
      "y": 11,
      "z": 4,
      "name": "Rock_Chalk",
      "rotation": 1
    },
    {
      "x": -1,
      "y": 12,
      "z": 4,
      "name": "Rock_Marble",
      "rotation": 1
    },
    {
      "x": -1,
      "y": 13,
      "z": 4,
      "name": "Rock_Marble_Cobble",
      "rotation": 1
    },
    {
      "x": -1,
      "y": 14,
      "z": 4,
      "name": "Rock_Marble_Cobble",
      "rotation": 1
    },
    {
      "x": -1,
      "y": 15,
      "z": 4,
      "name": "Rock_Marble_Cobble",
      "rotation": 1
    },
    {
      "x": -1,
      "y": 16,
      "z": 4,
      "name": "Rock_Marble_Cobble",
      "rotation": 1
    },
    {
      "x": -1,
      "y": 17,
      "z": 4,
      "name": "Rock_Marble",
      "rotation": 1
    },
    {
      "x": -1,
      "y": 18,
      "z": 4,
      "name": "Rock_Marble",
      "rotation": 1
    },
    {
      "x": -1,
      "y": 19,
      "z": 4,
      "name": "Soil_Clay_White",
      "rotation": 1
    },
    {
      "x": -1,
      "y": 20,
      "z": 4,
      "name": "Rock_Chalk",
      "rotation": 1
    },
    {
      "x": -1,
      "y": 21,
      "z": 4,
      "name": "Rock_Marble",
      "rotation": 1
    },
    {
      "x": -1,
      "y": 22,
      "z": 4,
      "name": "Rock_Marble_Cobble",
      "rotation": 1
    },
    {
      "x": -1,
      "y": 23,
      "z": 4,
      "name": "Rock_Marble_Cobble",
      "rotation": 1
    },
    {
      "x": -1,
      "y": 24,
      "z": 4,
      "name": "Rock_Marble_Cobble",
      "rotation": 1
    },
    {
      "x": -1,
      "y": 25,
      "z": 4,
      "name": "Rock_Marble",
      "rotation": 1
    },
    {
      "x": -1,
      "y": 26,
