{
  "version": 8,
  "blockIdVersion": 11,
  "anchorX": -21,
  "anchorY": 0,
  "anchorZ": 0,
  "blocks": [
    {
      "x": -21,
      "y": -35,
      "z": -20,
      "name": "Rock_Sandstone_Brick"
    },
    {
      "x": -21,
      "y": -34,
      "z": -20,
      "name": "Rock_Sandstone_Brick"
    },
    {
      "x": -21,
      "y": -33,
      "z": -20,
      "name": "Rock_Sandstone_Brick"
    },
    {
      "x": -21,
      "y": -32,
      "z": -20,
      "name": "Rock_Sandstone_Brick"
    },
    {
      "x": -21,
      "y": -31,
      "z": -20,
      "name": "Rock_Sandstone"
    },
    {
      "x": -21,
      "y": -30,
      "z": -20,
      "name": "Rock_Sandstone_Brick"
    },
    {
      "x": -21,
      "y": -29,
      "z": -20,
      "name": "Rock_Sandstone_Brick"
    },
    {
      "x": -21,
      "y": -28,
      "z": -20,
      "name": "Rock_Sandstone_Brick"
    },
    {
      "x": -21,
      "y": -27,
      "z": -20,
      "name": "Rock_Sandstone"
    },
    {
      "x": -21,
      "y": -26,
      "z": -20,
      "name": "Rock_Sandstone_Brick"
    },
    {
      "x": -21,
      "y": -25,
      "z": -20,
      "name": "Rock_Sandstone_Brick",
      "rotation": 3
    },
    {
      "x": -21,
      "y": -24,
      "z": -20,
      "name": "Rock_Sandstone_Brick",
      "rotation": 3
    },
    {
      "x": -21,
      "y": -23,
      "z": -20,
      "name": "Rock_Sandstone_Brick",
      "rotation": 3
    },
    {
      "x": -21,
      "y": -22,
      "z": -20,
      "name": "Rock_Sandstone_Brick",
      "rotation": 3
    },
    {
      "x": -21,
      "y": -21,
      "z": -20,
      "name": "Rock_Sandstone",
      "rotation": 3
    },
    {
      "x": -21,
      "y": -20,
      "z": -20,
      "name": "Rock_Sandstone_Brick",
      "rotation": 3
    },
    {
      "x": -21,
      "y": -19,
      "z": -20,
      "name": "Rock_Sandstone_Brick",
      "rotation": 3
    },
    {
      "x": -21,
      "y": -18,
      "z": -20,
      "name": "Rock_Sandstone_Brick",
      "rotation": 3
    },
    {
      "x": -21,
      "y": -17,
      "z": -20,
      "name": "Rock_Sandstone_Brick",
      "rotation": 3
    },
    {
      "x": -21,
      "y": -16,
      "z": -20,
      "name": "Rock_Sandstone_Brick",
      "rotation": 3
    },
    {
      "x": -21,
      "y": -15,
      "z": -20,
      "name": "Rock_Sandstone",
      "rotation": 3
    },
    {
      "x": -21,
      "y": -14,
      "z": -20,
      "name": "Rock_Sandstone_Brick",
      "rotation": 3
    },
    {
      "x": -21,
      "y": -13,
      "z": -20,
      "name": "Rock_Sandstone_Brick",
      "rotation": 3
    },
    {
      "x": -21,
      "y": -12,
      "z": -20,
      "name": "Rock_Sandstone_Brick",
      "rotation": 3
    },
    {
      "x": -21,
      "y": -35,
      "z": -19,
      "name": "Rock_Sandstone_Cobble"
    },
    {
      "x": -21,
      "y": -34,
      "z": -19,
      "name": "Rock_Sandstone_Brick"
    },
    {
      "x": -21,
      "y": -33,
      "z": -19,
      "name": "Rock_Sandstone_Brick"
    },
    {
      "x": -21,
      "y": -32,
      "z": -19,
      "name": "Rock_Sandstone_Brick"
    },
    {
      "x": -21,
      "y": -31,
      "z": -19,
      "name": "Rock_Sandstone_Brick"
    },
    {
      "x": -21,
      "y": -30,
      "z": -19,
      "name": "Rock_Sandstone_Brick"
    },
    {
      "x": -21,
      "y": -29,
      "z": -19,
      "name": "Rock_Sandstone"
    },
    {
      "x": -21,
      "y": -28,
      "z": -19,
      "name": "Rock_Sandstone_Cobble"
    },
    {
      "x": -21,
      "y": -27,
      "z": -19,
      "name": "Rock_Sandstone_Brick"
    },
    {
      "x": -21,
      "y": -26,
      "z": -19,
      "name": "Rock_Sandstone_Cobble"
    },
    {
      "x": -21,
      "y": -25,
      "z": -19,
      "name": "Rock_Sandstone_Brick",
      "rotation": 3
    },
    {
      "x": -21,
      "y": -24,
      "z": -19,
      "name": "Rock_Sandstone_Brick",
      "rotation": 3
    },
    {
      "x": -21,
      "y": -23,
      "z": -19,
      "name": "Rock_Sandstone_Brick",
      "rotation": 3
    },
    {
      "x": -21,
      "y": -22,
      "z": -19,
      "name": "Rock_Sandstone_Brick",
      "rotation": 3
    },
    {
      "x": -21,
      "y": -21,
      "z": -19,
      "name": "Rock_Sandstone_Brick",
      "rotation": 3
    },
    {
      "x": -21,
      "y": -20,
      "z": -19,
      "name": "Rock_Sandstone",
      "rotation": 3
    },
    {
      "x": -21,
      "y": -19,
      "z": -19,
      "name": "Rock_Sandstone_Brick",
      "rotation": 3
    },
    {
      "x": -21,
      "y": -18,
      "z": -19,
      "name": "Rock_Sandstone_Brick",
      "rotation": 3
    },
    {
      "x": -21,
      "y": -17,
      "z": -19,
      "name": "Rock_Sandstone",
      "rotation": 3
    },
    {
      "x": -21,
      "y": -16,
      "z": -19,
      "name": "Rock_Sandstone_Brick",
      "rotation": 3
    },
    {
      "x": -21,
      "y": -15,
      "z": -19,
      "name": "Rock_Sandstone_Brick",
      "rotation": 3
    },
    {
      "x": -21,
      "y": -14,
      "z": -19,
      "name": "Rock_Sandstone",
      "rotation": 3
    },
    {
      "x": -21,
      "y": -13,
      "z": -19,
      "name": "Rock_Sandstone_Brick",
      "rotation": 3
    },
    {
      "x": -21,
      "y": -12,
      "z": -19,
      "name": "Rock_Sandstone_Cobble",
      "rotation": 3
    },
    {
      "x": -21,
      "y": -11,
      "z": -19,
      "name": "Rock_Sandstone_Brick",
      "rotation": 3
    },
    {
      "x": -21,
      "y": -35,
      "z": -18,
      "name": "Rock_Sandstone_Brick"
    },
    {
      "x": -21,
      "y": -34,
      "z": -18,
      "name": "Rock_Sandstone_Brick"
    },
    {
      "x": -21,
      "y": -33,
      "z": -18,
      "name": "Rock_Sandstone_Brick"
    },
    {
      "x": -21,
      "y": -32,
      "z": -18,
      "name": "Rock_Sandstone"
    },
    {
      "x": -21,
      "y": -31,
      "z": -18,
      "name": "Rock_Sandstone_Cobble"
    },
    {
      "x": -21,
      "y": -30,
      "z": -18,
      "name": "Rock_Sandstone_Brick"
    },
    {
      "x": -21,
      "y": -29,
      "z": -18,
      "name": "Rock_Sandstone_Brick"
    },
    {
      "x": -21,
      "y": -28,
      "z": -18,
      "name": "Rock_Sandstone"
    },
    {
      "x": -21,
      "y": -27,
      "z": -18,
      "name": "Rock_Sandstone_Brick"
    },
    {
      "x": -21,
      "y": -26,
      "z": -18,
      "name": "Rock_Sandstone_Cobble"
    },
    {
      "x": -21,
      "y": -25,
      "z": -18,
      "name": "Rock_Sandstone",
      "rotation": 3
    },
    {
      "x": -21,
      "y": -24,
      "z": -18,
      "name": "Rock_Sandstone_Brick",
      "rotation": 3
    },
    {
      "x": -21,
      "y": -23,
      "z": -18,
      "name": "Rock_Sandstone_Brick",
      "rotation": 3
    },
    {
      "x": -21,
      "y": -22,
      "z": -18,
      "name": "Rock_Sandstone_Brick",
      "rotation": 3
    },
    {
      "x": -21,
      "y": -21,
      "z": -18,
      "name": "Rock_Sandstone_Brick",
      "rotation": 3
    },
    {
      "x": -21,
      "y": -20,
      "z": -18,
      "name": "Rock_Sandstone_Cobble",
      "rotation": 3
    },
    {
      "x": -21,
      "y": -19,
      "z": -18,
      "name": "Rock_Sandstone_Brick",
      "rotation": 3
    },
    {
      "x": -21,
      "y": -18,
      "z": -18,
      "name": "Rock_Sandstone_Brick",
      "rotation": 3
    },
    {
      "x": -21,
      "y": -17,
      "z": -18,
      "name": "Rock_Sandstone",
      "rotation": 3
    },
    {
      "x": -21,
      "y": -16,
      "z": -18,
      "name": "Rock_Sandstone_Brick",
      "rotation": 3
    },
    {
      "x": -21,
      "y": -15,
      "z": -18,
      "name": "Rock_Sandstone_Brick",
      "rotation": 3
    },
    {
      "x": -21,
      "y": -14,
      "z": -18,
      "name": "Rock_Sandstone_Cobble",
      "rotation": 3
    },
    {
      "x": -21,
      "y": 0,
      "z": -6,
      "name": "Rock_Sandstone_Brick"
    },
    {
      "x": -21,
      "y": 0,
      "z": -5,
      "name": "Rock_Sandstone_Brick"
    },
    {
      "x": -21,
      "y": -5,
      "z": -4,
      "name": "Rock_Sandstone_Brick_Stairs",
      "rotation": 8
    },
    {
      "x": -21,
      "y": -4,
      "z": -4,
      "name": "Rock_Sandstone_Brick"
    },
    {
      "x": -21,
      "y": -3,
      "z": -4,
      "name": "Rock_Sandstone"
    },
    {
      "x": -21,
      "y": -2,
      "z": -4,
      "name": "Rock_Sandstone_Brick"
    },
    {
      "x": -21,
      "y": -1,
      "z": -4,
      "name": "Rock_Sandstone_Brick"
    },
    {
      "x": -21,
      "y": 0,
      "z": -4,
      "name": "Rock_Sandstone_Brick"
    },
    {
      "x": -21,
      "y": -35,
      "z": -3,
      "name": "Rock_Sandstone_Brick"
    },
    {
      "x": -21,
      "y": -34,
      "z": -3,
      "name": "Rock_Sandstone_Brick"
    },
    {
      "x": -21,
      "y": -33,
      "z": -3,
      "name": "Rock_Sandstone_Cobble"
    },
    {
      "x": -21,
      "y": -32,
      "z": -3,
      "name": "Rock_Sandstone_Brick"
    },
    {
      "x": -21,
      "y": -31,
      "z": -3,
      "name": "Rock_Sandstone_Brick"
    },
    {
      "x": -21,
      "y": -30,
      "z": -3,
      "name": "Rock_Sandstone_Brick"
    },
    {
      "x": -21,
      "y": -29,
      "z": -3,
      "name": "Rock_Sandstone_Brick"
    },
    {
      "x": -21,
      "y": -28,
      "z": -3,
      "name": "Rock_Sandstone_Brick"
    },
    {
      "x": -21,
      "y": -27,
      "z": -3,
      "name": "Rock_Sandstone_Cobble"
    },
    {
      "x": -21,
      "y": -26,
      "z": -3,
      "name": "Rock_Sandstone_Brick"
    },
    {
      "x": -21,
      "y": -25,
      "z": -3,
      "name": "Rock_Sandstone_Brick"
    },
    {
      "x": -21,
      "y": -24,
      "z": -3,
      "name": "Rock_Sandstone",
      "rotation": 1
    },
    {
      "x": -21,
      "y": -23,
      "z": -3,
      "name": "Rock_Sandstone_Brick",
      "rotation": 1
    },
    {
      "x": -21,
      "y": -22,
      "z": -3,
      "name": "Rock_Sandstone",
      "rotation": 1
    },
    {
      "x": -21,
      "y": -21,
      "z": -3,
      "name": "Rock_Sandstone_Brick",
      "rotation": 1
    },
    {
      "x": -21,
      "y": -20,
      "z": -3,
      "name": "Rock_Sandstone",
      "rotation": 1
    },
    {
      "x": -21,
      "y": -19,
      "z": -3,
      "name": "Rock_Sandstone",
      "rotation": 1
    },
    {
      "x": -21,
      "y": -18,
      "z": -3,
      "name": "Rock_Sandstone_Brick",
      "rotation": 1
    },
    {
      "x": -21,
      "y": -17,
      "z": -3,
      "name": "Rock_Sandstone_Brick",
      "rotation": 1
    },
    {
      "x": -21,
      "y": -16,
      "z": -3,
      "name": "Rock_Sandstone_Brick",
      "rotation": 1
    },
    {
      "x": -21,
      "y": -15,
      "z": -3,
      "name": "Rock_Sandstone_Cobble",
      "rotation": 1
    },
    {
      "x": -21,
      "y": -14,
      "z": -3,
      "name": "Rock_Sandstone_Brick",
      "rotation": 1
    },
    {
      "x": -21,
      "y": -13,
      "z": -3,
      "name": "Rock_Sandstone_Brick",
      "rotation": 1
    },
    {
      "x": -21,
      "y": -12,
      "z": -3,
      "name": "Rock_Sandstone_Cobble",
      "rotation": 1
    },
    {
      "x": -21,
      "y": -11,
      "z": -3,
      "name": "Rock_Sandstone_Brick",
      "rotation": 1
    },
    {
      "x": -21,
      "y": -10,
      "z": -3,
      "name": "Rock_Sandstone_Cobble",
      "rotation": 1
    },
    {
      "x": -21,
      "y": -9,
      "z": -3,
      "name": "Rock_Sandstone_Brick",
      "rotation": 1
    },
    {
      "x": -21,
      "y": -8,
      "z": -3,
      "name": "Rock_Sandstone_Brick",
      "rotation": 1
    },
    {
      "x": -21,
      "y": -7,
      "z": -3,
      "name": "Rock_Sandstone_Brick",
      "rotation": 1
    },
    {
      "x": -21,
      "y": -6,
      "z": -3,
      "name": "Rock_Sandstone_Brick",
      "rotation": 1
    },
    {
      "x": -21,
      "y": -5,
      "z": -3,
      "name": "Rock_Sandstone_Brick",
      "rotation": 1
    },
    {
      "x": -21,
      "y": -4,
      "z": -3,
      "name": "Rock_Sandstone_Brick",
      "rotation": 1
    },
    {
      "x": -21,
      "y": -3,
      "z": -3,
      "name": "Rock_Sandstone",
      "rotation": 1
    },
    {
      "x": -21,
      "y": -2,
      "z": -3,
      "name": "Rock_Sandstone_Brick",
      "rotation": 1
    },
    {
      "x": -21,
      "y": -1,
      "z": -3,
      "name": "Rock_Sandstone_Brick",
      "rotation": 1
    },
    {
      "x": -21,
      "y": 0,
      "z": -3,
      "name": "Rock_Sandstone_Brick"
    },
    {
      "x": -21,
      "y": -35,
      "z": -2,
      "name": "Rock_Sandstone_Brick"
    },
    {
      "x": -21,
      "y": -34,
      "z": -2,
      "name": "Rock_Sandstone_Brick"
    },
    {
      "x": -21,
      "y": -33,
      "z": -2,
      "name": "Rock_Sandstone_Brick"
    },
    {
      "x": -21,
      "y": -32,
      "z": -2,
      "name": "Rock_Sandstone_Brick"
    },
    {
      "x": -21,
      "y": -31,
      "z": -2,
      "name": "Rock_Sandstone_Brick"
    },
    {
      "x": -21,
      "y": -30,
      "z": -2,
      "name": "Rock_Sandstone_Brick"
    },
    {
      "x": -21,
      "y": -29,
      "z": -2,
      "name": "Rock_Sandstone_Brick"
    },
    {
      "x": -21,
      "y": -28,
      "z": -2,
      "name": "Rock_Sandstone"
    },
    {
      "x": -21,
      "y": -27,
      "z": -2,
      "name": "Rock_Sandstone_Brick"
    },
    {
      "x": -21,
      "y": -26,
      "z": -2,
      "name": "Rock_Sandstone_Cobble"
    },
    {
      "x": -21,
      "y": -25,
      "z": -2,
      "name": "Rock_Sandstone_Brick"
    },
    {
      "x": -21,
      "y": -24,
      "z": -2,
      "name": "Rock_Sandstone_Brick",
      "rotation": 1
    },
    {
      "x": -21,
      "y": -23,
      "z": -2,
      "name": "Rock_Sandstone_Brick",
      "rotation": 1
    },
    {
      "x": -21,
      "y": -22,
      "z": -2,
      "name": "Rock_Sandstone_Brick",
      "rotation": 1
    },
    {
      "x": -21,
      "y": -21,
      "z": -2,
      "name": "Rock_Sandstone_Brick",
      "rotation": 1
    },
    {
      "x": -21,
      "y": -20,
      "z": -2,
      "name": "Rock_Sandstone_Brick",
      "rotation": 1
    },
    {
      "x": -21,
      "y": -19,
      "z": -2,
      "name": "Rock_Sandstone",
      "rotation": 1
    },
    {
      "x": -21,
      "y": -18,
      "z": -2,
      "name": "Rock_Sandstone_Cobble",
      "rotation": 1
    },
    {
      "x": -21,
      "y": -17,
      "z": -2,
      "name": "Rock_Sandstone_Cobble",
      "rotation": 1
    },
    {
      "x": -21,
      "y": -16,
      "z": -2,
      "name": "Rock_Sandstone_Brick",
      "rotation": 1
    },
    {
      "x": -21,
      "y": -15,
      "z": -2,
      "name": "Rock_Sandstone_Cobble",
      "rotation": 1
    },
    {
      "x": -21,
      "y": -14,
      "z": -2,
      "name": "Rock_Sandstone_Brick",
      "rotation": 1
    },
    {
      "x": -21,
      "y": -13,
      "z": -2,
      "name": "Rock_Sandstone_Brick",
      "rotation": 1
    },
    {
      "x": -21,
      "y": -12,
      "z": -2,
      "name": "Rock_Sandstone",
      "rotation": 1
    },
    {
      "x": -21,
      "y": -11,
      "z": -2,
      "name": "Rock_Sandstone_Brick",
      "rotation": 1
    },
    {
      "x": -21,
      "y": -10,
      "z": -2,
      "name": "Rock_Sandstone_Brick",
      "rotation": 1
    },
    {
      "x": -21,
      "y": -9,
      "z": -2,
      "name": "Rock_Sandstone_Cobble",
      "rotation": 1
    },
    {
      "x": -21,
      "y": -8,
      "z": -2,
      "name": "Rock_Sandstone_Brick",
      "rotation": 1
    },
    {
      "x": -21,
      "y": -7,
      "z": -2,
      "name": "Rock_Sandstone_Brick",
      "rotation": 1
    },
    {
      "x": -21,
      "y": -6,
      "z": -2,
      "name": "Rock_Sandstone",
      "rotation": 1
    },
    {
      "x": -21,
      "y": -5,
      "z": -2,
      "name": "Rock_Sandstone_Cobble",
      "rotation": 1
    },
    {
      "x": -21,
      "y": -4,
      "z": -2,
      "name": "Rock_Sandstone_Brick",
      "rotation": 1
    },
    {
      "x": -21,
      "y": -3,
      "z": -2,
      "name": "Rock_Sandstone_Brick",
      "rotation": 1
    },
    {
      "x": -21,
      "y": -2,
      "z": -2,
      "name": "Rock_Sandstone_Brick",
      "rotation": 1
    },
    {
      "x": -21,
      "y": -1,
      "z": -2,
      "name": "Rock_Sandstone_Brick",
      "rotation": 1
    },
    {
      "x": -21,
      "y": 0,
      "z": -2,
      "name": "Rock_Sandstone_Brick"
    },
    {
      "x": -21,
      "y": -35,
      "z": -1,
      "name": "Rock_Sandstone"
    },
    {
      "x": -21,
      "y": -34,
      "z": -1,
      "name": "Rock_Sandstone_Cobble"
    },
    {
      "x": -21,
      "y": -33,
      "z": -1,
      "name": "Rock_Sandstone_Brick"
    },
    {
      "x": -21,
      "y": -32,
      "z": -1,
      "name": "Rock_Sandstone_Brick"
    },
    {
      "x": -21,
      "y": -31,
      "z": -1,
      "name": "Rock_Sandstone_Brick"
    },
    {
      "x": -21,
      "y": -30,
      "z": -1,
      "name": "Rock_Sandstone_Brick"
    },
    {
      "x": -21,
      "y": -29,
      "z": -1,
      "name": "Rock_Sandstone_Brick"
    },
    {
      "x": -21,
      "y": -28,
      "z": -1,
      "name": "Rock_Sandstone_Cobble"
    },
    {
      "x": -21,
      "y": -27,
      "z": -1,
      "name": "Rock_Sandstone_Brick"
    },
    {
      "x": -21,
      "y": -26,
      "z": -1,
      "name": "Rock_Sandstone_Brick"
    },
    {
      "x": -21,
      "y": -25,
      "z": -1,
      "name": "Rock_Sandstone_Cobble"
    },
    {
      "x": -21,
      "y": -24,
      "z": -1,
      "name": "Rock_Sandstone_Brick",
      "rotation": 1
    },
    {
      "x": -21,
      "y": -23,
      "z": -1,
      "name": "Rock_Sandstone_Brick",
      "rotation": 1
    },
    {
      "x": -21,
      "y": -22,
      "z": -1,
      "name": "Rock_Sandstone_Brick",
      "rotation": 1
    },
    {
      "x": -21,
      "y": -21,
      "z": -1,
      "name": "Rock_Sandstone",
      "rotation": 1
    },
    {
      "x": -21,
      "y": -20,
      "z": -1,
      "name": "Rock_Sandstone_Brick",
      "rotation": 1
    },
    {
      "x": -21,
      "y": -19,
      "z": -1,
      "name": "Rock_Sandstone_Brick",
      "rotation": 1
    },
    {
      "x": -21,
      "y": -18,
      "z": -1,
      "name": "Rock_Sandstone",
      "rotation": 1
    },
    {
      "x": -21,
      "y": -17,
      "z": -1,
      "name": "Rock_Sandstone_Brick",
      "rotation": 1
    },
    {
      "x": -21,
      "y": -16,
      "z": -1,
      "name": "Rock_Sandstone",
      "rotation": 1
    },
    {
      "x": -21,
      "y": -15,
      "z": -1,
      "name": "Rock_Sandstone_Brick",
      "rotation": 1
    },
    {
      "x": -21,
      "y": -14,
      "z": -1,
      "name": "Rock_Sandstone",
      "rotation": 1
    },
    {
      "x": -21,
      "y": -13,
      "z": -1,
      "name": "Rock_Sandstone_Brick",
      "rotation": 1
    },
    {
      "x": -21,
      "y": -12,
      "z": -1,
      "name": "Rock_Sandstone_Brick",
      "rotation": 1
    },
    {
      "x": -21,
      "y": -11,
      "z": -1,
      "name": "Rock_Sandstone_Brick",
      "rotation": 1
    },
    {
      "x": -21,
      "y": -10,
      "z": -1,
      "name": "Rock_Sandstone_Brick",
      "rotation": 1
    },
    {
      "x": -21,
      "y": -9,
      "z": -1,
      "name": "Rock_Sandstone",
      "rotation": 1
    },
    {
      "x": -21,
      "y": -8,
      "z": -1,
      "name": "Rock_Sandstone_Brick",
      "rotation": 1
    },
    {
      "x": -21,
      "y": -7,
      "z": -1,
      "name": "Rock_Sandstone_Brick",
      "rotation": 1
    },
    {
      "x": -21,
      "y": -6,
      "z": -1,
      "name": "Rock_Sandstone_Brick",
      "rotation": 1
    },
    {
      "x": -21,
      "y": -5,
      "z": -1,
      "name": "Rock_Sandstone_Brick",
      "rotation": 1
    },
    {
      "x": -21,
      "y": -4,
      "z": -1,
      "name": "Rock_Sandstone_Brick",
      "rotation": 1
    },
    {
      "x": -21,
      "y": -3,
      "z": -1,
      "name": "Rock_Sandstone_Brick",
      "rotation": 1
    },
    {
      "x": -21,
      "y": -2,
      "z": -1,
      "name": "Rock_Sandstone_Brick",
      "rotation": 1
    },
    {
      "x": -21,
      "y": -1,
      "z": -1,
      "name": "Rock_Sandstone_Brick",
      "rotation": 1
    },
    {
      "x": -21,
      "y": 0,
      "z": -1,
      "name": "Rock_Sandstone_Brick"
    },
    {
      "x": -20,
      "y": -35,
      "z": -21,
      "name": "Rock_Sandstone_Cobble"
    },
    {
      "x": -20,
      "y": -34,
      "z": -21,
      "name": "Rock_Sandstone"
    },
    {
      "x": -20,
      "y": -33,
      "z": -21,
      "name": "Rock_Sandstone_Brick"
    },
    {
      "x": -20,
      "y": -32,
      "z": -21,
      "name": "Rock_Sandstone_Brick"
    },
    {
      "x": -20,
      "y": -31,
      "z": -21,
      "name": "Rock_Sandstone"
    },
    {
      "x": -20,
      "y": -30,
      "z": -21,
      "name": "Rock_Sandstone_Brick"
    },
    {
      "x": -20,
      "y": -29,
      "z": -21,
      "name": "Rock_Sandstone_Brick"
    },
    {
      "x": -20,
      "y": -28,
      "z": -21,
      "name": "Rock_Sandstone_Brick"
    },
    {
      "x": -20,
      "y": -27,
      "z": -21,
      "name": "Rock_Sandstone"
    },
    {
      "x": -20,
      "y": -26,
      "z": -21,
      "name": "Rock_Sandstone_Cobble"
    },
    {
      "x": -20,
      "y": -25,
      "z": -21,
      "name": "Rock_Sandstone_Brick"
    },
    {
      "x": -20,
      "y": -24,
      "z": -21,
      "name": "Rock_Sandstone_Brick"
    },
    {
      "x": -20,
      "y": -23,
      "z": -21,
      "name": "Rock_Sandstone_Brick"
    },
    {
      "x": -20,
      "y": -22,
      "z": -21,
      "name": "Rock_Sandstone"
    },
    {
      "x": -20,
      "y": -21,
      "z": -21,
      "name": "Rock_Sandstone_Brick"
    },
    {
      "x": -20,
      "y": -20,
      "z": -21,
      "name": "Rock_Sandstone_Brick"
    },
    {
      "x": -20,
      "y": -19,
      "z": -21,
      "name": "Rock_Sandstone_Brick"
    },
    {
      "x": -20,
      "y": -18,
      "z": -21,
      "name": "Rock_Sandstone_Brick"
    },
    {
      "x": -20,
      "y": -17,
      "z": -21,
      "name": "Rock_Sandstone_Brick"
    },
    {
      "x": -20,
      "y": -16,
      "z": -21,
      "name": "Rock_Sandstone_Cobble"
    },
    {
      "x": -20,
      "y": -15,
      "z": -21,
      "name": "Rock_Sandstone_Cobble"
    },
    {
      "x": -20,
      "y": -14,
      "z": -21,
      "name": "Rock_Sandstone_Brick"
    },
    {
      "x": -20,
      "y": -13,
      "z": -21,
      "name": "Rock_Sandstone_Brick"
    },
    {
      "x": -20,
      "y": -12,
      "z": -21,
      "name": "Rock_Sandstone"
    },
    {
      "x": -20,
      "y": -11,
      "z": -21,
      "name": "Rock_Sandstone_Brick"
    },
    {
      "x": -20,
      "y": -35,
      "z": -20,
      "name": "Rock_Sandstone_Brick"
    },
    {
      "x": -20,
      "y": -34,
      "z": -20,
      "name": "Rock_Sandstone_Brick"
    },
    {
      "x": -20,
      "y": -33,
      "z": -20,
      "name": "Rock_Sandstone_Brick"
    },
    {
      "x": -20,
      "y": -32,
      "z": -20,
      "name": "Rock_Sandstone_Cobble"
    },
    {
      "x": -20,
      "y": -31,
      "z": -20,
      "name": "Rock_Sandstone"
    },
    {
      "x": -20,
      "y": -30,
      "z": -20,
      "name": "Rock_Sandstone_Brick"
    },
    {
      "x": -20,
      "y": -29,
      "z": -20,
      "name": "Rock_Sandstone"
    },
    {
      "x": -20,
      "y": -28,
      "z": -20,
      "name": "Rock_Sandstone_Brick"
    },
    {
      "x": -20,
      "y": -27,
      "z": -20,
      "name": "Rock_Sandstone_Brick"
    },
    {
      "x": -20,
      "y": -26,
      "z": -20,
      "name": "Rock_Sandstone"
    },
    {
      "x": -20,
      "y": -25,
      "z": -20,
      "name": "Rock_Sandstone_Brick",
      "rotation": 3
    },
    {
      "x": -20,
      "y": -24,
      "z": -20,
      "name": "Rock_Sandstone_Brick",
      "rotation": 3
    },
    {
      "x": -20,
      "y": -23,
      "z": -20,
      "name": "Rock_Sandstone_Cobble",
      "rotation": 3
    },
    {
      "x": -20,
      "y": -22,
      "z": -20,
      "name": "Rock_Sandstone_Brick",
      "rotation": 3
    },
    {
      "x": -20,
      "y": -21,
      "z": -20,
      "name": "Rock_Sandstone_Brick",
      "rotation": 3
    },
    {
      "x": -20,
      "y": -20,
      "z": -20,
      "name": "Rock_Sandstone_Brick",
      "rotation": 3
    },
    {
      "x": -20,
      "y": -19,
      "z": -20,
      "name": "Rock_Sandstone_Brick",
      "rotation": 3
    },
    {
      "x": -20,
      "y": -18,
      "z": -20,
      "name": "Rock_Sandstone_Brick",
      "rotation": 3
    },
    {
      "x": -20,
      "y": -17,
      "z": -20,
      "name": "Rock_Sandstone_Brick",
      "rotation": 3
    },
    {
      "x": -20,
      "y": -16,
      "z": -20,
      "name": "Rock_Sandstone_Brick",
      "rotation": 3
    },
    {
      "x": -20,
      "y": -15,
      "z": -20,
      "name": "Rock_Sandstone_Brick",
      "rotation": 3
    },
    {
      "x": -20,
      "y": -14,
      "z": -20,
      "name": "Rock_Sandstone_Brick",
      "rotation": 3
    },
    {
      "x": -20,
      "y": -13,
      "z": -20,
      "name": "Rock_Sandstone_Brick",
      "rotation": 3
    },
    {
      "x": -20,
      "y": -12,
      "z": -20,
      "name": "Rock_Sandstone_Brick",
      "rotation": 3
    },
    {
      "x": -20,
      "y": -11,
      "z": -20,
      "name": "Rock_Sandstone_Brick",
      "rotation": 3
    },
    {
      "x": -20,
      "y": -35,
      "z": -19,
      "name": "Rock_Sandstone_Cobble"
    },
    {
      "x": -20,
      "y": -34,
      "z": -19,
      "name": "Rock_Sandstone"
    },
    {
      "x": -20,
      "y": -33,
      "z": -19,
      "name": "Rock_Sandstone_Brick"
    },
    {
      "x": -20,
      "y": -32,
      "z": -19,
      "name": "Rock_Sandstone_Brick"
    },
    {
      "x": -20,
      "y": -31,
      "z": -19,
      "name": "Rock_Sandstone_Brick"
    },
    {
      "x": -20,
      "y": -30,
      "z": -19,
      "name": "Rock_Sandstone_Brick"
    },
    {
      "x": -20,
      "y": -29,
      "z": -19,
      "name": "Rock_Sandstone"
    },
    {
      "x": -20,
      "y": -28,
      "z": -19,
      "name": "Rock_Sandstone"
    },
    {
      "x": -20,
      "y": -27,
      "z": -19,
      "name": "Rock_Sandstone_Cobble"
    },
    {
      "x": -20,
      "y": -26,
      "z": -19,
      "name": "Rock_Sandstone"
    },
    {
      "x": -20,
      "y": -25,
      "z": -19,
      "name": "Rock_Sandstone_Brick",
      "rotation": 3
    },
    {
      "x": -20,
      "y": -24,
      "z": -19,
      "name": "Rock_Sandstone_Cobble",
      "rotation": 3
    },
    {
      "x": -20,
      "y": -23,
      "z": -19,
      "name": "Rock_Sandstone_Brick",
      "rotation": 3
    },
    {
      "x": -20,
      "y": -22,
      "z": -19,
      "name": "Rock_Sandstone_Cobble",
      "rotation": 3
    },
    {
      "x": -20,
      "y": -21,
      "z": -19,
      "name": "Rock_Sandstone_Cobble",
      "rotation": 3
    },
    {
      "x": -20,
      "y": -20,
      "z": -19,
      "name": "Rock_Sandstone_Brick",
      "rotation": 3
    },
    {
      "x": -20,
      "y": -19,
      "z": -19,
      "name": "Rock_Sandstone_Brick",
      "rotation": 3
    },
    {
      "x": -20,
      "y": -18,
      "z": -19,
      "name": "Rock_Sandstone_Brick",
      "rotation": 3
    },
    {
      "x": -20,
      "y": -17,
      "z": -19,
      "name": "Rock_Sandstone_Brick",
      "rotation": 3
    },
    {
      "x": -20,
      "y": -16,
      "z": -19,
      "name": "Rock_Sandstone_Brick",
      "rotation": 3
    },
    {
      "x": -20,
      "y": -15,
      "z": -19,
      "name": "Rock_Sandstone_Brick",
      "rotation": 3
    },
    {
      "x": -20,
      "y": -14,
      "z": -19,
      "name": "Rock_Sandstone",
      "rotation": 3
    },
    {
      "x": -20,
      "y": -13,
      "z": -19,
      "name": "Rock_Sandstone_Brick",
      "rotation": 3
    },
    {
      "x": -20,
      "y": -12,
      "z": -19,
      "name": "Rock_Sandstone_Brick",
      "rotation": 3
    },
    {
      "x": -20,
      "y": -11,
      "z": -19,
      "name": "Rock_Sandstone",
      "rotation": 3
    },
    {
      "x": -20,
      "y": -10,
      "z": -19,
      "name": "Rock_Sandstone_Cobble",
      "rotation": 3
    },
    {
      "x": -20,
      "y": -9,
      "z": -19,
      "name": "Rock_Sandstone_Brick",
      "rotation": 3
    },
    {
      "x": -20,
      "y": -35,
      "z": -18,
      "name": "Rock_Sandstone_Brick"
    },
    {
      "x": -20,
      "y": -34,
      "z": -18,
      "name": "Rock_Sandstone_Brick"
    },
    {
      "x": -20,
      "y": -33,
      "z": -18,
      "name": "Rock_Sandstone_Brick"
    },
    {
      "x": -20,
      "y": -32,
      "z": -18,
      "name": "Rock_Sandstone_Brick"
    },
    {
      "x": -20,
      "y": -31,
      "z": -18,
      "name": "Rock_Sandstone_Brick"
    },
    {
      "x": -20,
      "y": -30,
      "z": -18,
      "name": "Rock_Sandstone"
    },
    {
      "x": -20,
      "y": -29,
      "z": -18,
      "name": "Rock_Sandstone_Brick"
    },
    {
      "x": -20,
      "y": -28,
      "z": -18,
      "name": "Rock_Sandstone"
    },
    {
      "x": -20,
      "y": -27,
      "z": -18,
      "name": "Rock_Sandstone"
    },
    {
      "x": -20,
      "y": -26,
      "z": -18,
      "name": "Rock_Sandstone_Brick"
    },
    {
      "x": -20,
      "y": -25,
      "z": -18,
      "name": "Rock_Sandstone_Cobble",
      "rotation": 3
    },
    {
      "x": -20,
      "y": -24,
      "z": -18,
      "name": "Rock_Sandstone_Brick",
      "rotation": 3
    },
    {
      "x": -20,
      "y": -23,
      "z": -18,
      "name": "Rock_Sandstone_Brick",
      "rotation": 3
    },
    {
      "x": -20,
      "y": -22,
      "z": -18,
      "name": "Rock_Sandstone_Brick",
      "rotation": 3
    },
    {
      "x": -20,
      "y": -21,
      "z": -18,
      "name": "Rock_Sandstone_Brick",
      "rotation": 3
    },
    {
      "x": -20,
      "y": -20,
      "z": -18,
      "name": "Rock_Sandstone",
      "rotation": 3
    },
    {
      "x": -20,
      "y": -19,
      "z": -18,
      "name": "Rock_Sandstone_Brick",
      "rotation": 3
    },
    {
      "x": -20,
      "y": -18,
      "z": -18,
      "name": "Rock_Sandstone_Cobble",
      "rotation": 3
    },
    {
      "x": -20,
      "y": -17,
      "z": -18,
      "name": "Rock_Sandstone_Brick",
      "rotation": 3
    },
    {
      "x": -20,
      "y": -16,
      "z": -18,
      "name": "Rock_Sandstone_Brick",
      "rotation": 3
    },
    {
      "x": -20,
      "y": -15,
      "z": -18,
      "name": "Rock_Sandstone_Cobble",
      "rotation": 3
    },
    {
      "x": -20,
      "y": -14,
      "z": -18,
      "name": "Rock_Sandstone_Brick",
      "rotation": 3
    },
    {
      "x": -20,
      "y": -13,
      "z": -18,
      "name": "Rock_Sandstone",
      "rotation": 3
    },
    {
      "x": -20,
      "y": -12,
      "z": -18,
      "name": "Rock_Sandstone_Brick",
      "rotation": 3
    },
    {
      "x": -20,
      "y": -11,
      "z": -18,
      "name": "Rock_Sandstone_Brick",
      "rotation": 3
    },
    {
      "x": -20,
      "y": -10,
      "z": -18,
      "name": "Rock_Sandstone_Brick",
      "rotation": 3
    },
    {
      "x": -20,
      "y": -9,
      "z": -18,
      "name": "Rock_Sandstone_Brick",
      "rotation": 3
    },
    {
      "x": -20,
      "y": 21,
      "z": -13,
      "name": "Rock_Sandstone_Brick",
      "rotation": 3
    },
    {
      "x": -20,
      "y": 22,
      "z": -13,
      "name": "Rock_Sandstone_Cobble",
      "rotation": 3
    },
    {
      "x": -20,
      "y": 23,
      "z": -13,
      "name": "Rock_Sandstone_Brick",
      "rotation": 3
    },
    {
      "x": -20,
      "y": 24,
      "z": -13,
      "name": "Rock_Sandstone_Brick",
      "rotation": 3
    },
    {
      "x": -20,
      "y": 25,
      "z": -13,
      "name": "Rock_Sandstone_Brick",
      "rotation": 3
    },
    {
      "x": -20,
      "y": 26,
      "z": -13,
      "name": "Rock_Sandstone_Cobble",
      "rotation": 3
    },
    {
      "x": -20,
      "y": 4,
      "z": -12,
      "name": "Wood_Redwood_Planks"
    },
    {
      "x": -20,
      "y": 17,
      "z": -12,
      "name": "Rock_Sandstone_Red_Cobble"
    },
    {
      "x": -20,
      "y": 18,
      "z": -12,
      "name": "Rock_Sandstone_Red_Cobble"
    },
    {
      "x": -20,
      "y": 19,
      "z": -12,
      "name": "Rock_Sandstone_Red_Cobble"
    },
    {
      "x": -20,
      "y": 20,
      "z": -12,
      "name": "Rock_Sandstone_Red"
    },
    {
      "x": -20,
      "y": 21,
      "z": -12,
      "name": "Rock_Sandstone_Brick",
      "rotation": 3
    },
    {
      "x": -20,
      "y": 22,
      "z": -12,
      "name": "Rock_Sandstone_Brick",
      "rotation": 3
    },
    {
      "x": -20,
      "y": 23,
      "z": -12,
      "name": "Rock_Sandstone_Cobble",
      "rotation": 3
    },
    {
      "x": -20,
      "y": 24,
      "z": -12,
      "name": "Rock_Sandstone_Brick",
      "rotation": 3
    },
    {
      "x": -20,
      "y": 25,
      "z": -12,
      "name": "Rock_Sandstone_Brick",
      "rotation": 3
    },
    {
      "x": -20,
      "y": 26,
      "z": -12,
      "name": "Rock_Sandstone_Cobble",
      "rotation": 3
    },
    {
      "x": -20,
      "y": 27,
      "z": -12,
      "name": "Rock_Sandstone_Brick"
    },
    {
      "x": -20,
      "y": 28,
      "z": -12,
      "name": "Rock_Sandstone_Brick"
    },
    {
      "x": -20,
      "y": 34,
      "z": -12,
      "name": "Rock_Sandstone_Brick"
    },
    {
      "x": -20,
      "y": 35,
      "z": -12,
      "name": "Soil_Clay_Ocean_Brick"
    },
    {
      "x": -20,
      "y": 36,
      "z": -12,
      "name": "Soil_Clay_Ocean_Brick"
    },
    {
      "x": -20,
      "y": 3,
      "z": -11,
      "name": "Wood_Redwood_Planks"
    },
    {
      "x": -20,
      "y": 4,
      "z": -11,
      "name": "Wood_Redwood_Planks"
    },
    {
      "x": -20,
      "y": 7,
      "z": -11,
      "name": "Rock_Sandstone_Brick",
      "rotation": 1
    },
    {
      "x": -20,
      "y": 8,
      "z": -11,
      "name": "Rock_Sandstone_Cobble",
      "rotation": 1
    },
    {
      "x": -20,
      "y": 9,
      "z": -11,
      "name": "Rock_Sandstone_Cobble",
      "rotation": 1
    },
    {
      "x": -20,
      "y": 10,
      "z": -11,
      "name": "Rock_Sandstone_Brick",
      "rotation": 1
    },
    {
      "x": -20,
      "y": 11,
      "z": -11,
      "name": "Rock_Sandstone_Brick",
      "rotation": 1
    },
    {
      "x": -20,
      "y": 12,
      "z": -11,
      "name": "Rock_Sandstone_Cobble",
      "rotation": 1
    },
    {
      "x": -20,
      "y": 13,
      "z": -11,
      "name": "Rock_Sandstone_Red_Cobble"
    },
    {
      "x": -20,
      "y": 14,
      "z": -11,
      "name": "Wood_Redwood_Planks"
    },
    {
      "x": -20,
      "y": 15,
      "z": -11,
      "name": "Wood_Redwood_Planks"
    },
    {
      "x": -20,
      "y": 16,
      "z": -11,
      "name": "Wood_Redwood_Planks"
    },
    {
      "x": -20,
      "y": 17,
      "z": -11,
      "name": "Rock_Sandstone_Red_Brick_Ornate"
    },
    {
      "x": -20,
      "y": 18,
      "z": -11,
      "name": "Rock_Sandstone_Red_Cobble"
    },
    {
      "x": -20,
      "y": 19,
      "z": -11,
      "name": "Rock_Sandstone_Red_Brick_Ornate"
    },
    {
      "x": -20,
      "y": 20,
      "z": -11,
      "name": "Rock_Sandstone_Red_Cobble"
    },
    {
      "x": -20,
      "y": 21,
      "z": -11,
      "name": "Rock_Sandstone_Brick",
      "rotation": 3
    },
    {
      "x": -20,
      "y": 22,
      "z": -11,
      "name": "Rock_Sandstone_Cobble",
      "rotation": 3
    },
    {
      "x": -20,
      "y": 23,
      "z": -11,
      "name": "Rock_Sandstone_Brick",
      "rotation": 3
    },
    {
      "x": -20,
      "y": 24,
      "z": -11,
      "name": "Rock_Sandstone_Cobble",
      "rotation": 3
    },
    {
      "x": -20,
      "y": 25,
      "z": -11,
      "name": "Rock_Sandstone_Brick",
      "rotation": 3
    },
    {
      "x": -20,
      "y": 26,
      "z": -11,
      "name": "Rock_Sandstone_Brick",
      "rotation": 3
    },
    {
      "x": -20,
      "y": 27,
      "z": -11,
      "name": "Rock_Sandstone_Brick"
    },
    {
      "x": -20,
      "y": 28,
      "z": -11,
      "name": "Rock_Sandstone_Brick"
    },
    {
      "x": -20,
      "y": 29,
      "z": -11,
      "name": "Rock_Sandstone_Brick"
    },
    {
      "x": -20,
      "y": 30,
      "z": -11,
      "name": "Rock_Sandstone_Brick"
    },
    {
      "x": -20,
      "y": 31,
      "z": -11,
      "name": "Rock_Sandstone_Brick"
    },
    {
      "x": -20,
      "y": 32,
      "z": -11,
      "name": "Rock_Sandstone_Brick"
    },
    {
      "x": -20,
      "y": 33,
      "z": -11,
      "name": "Rock_Sandstone_Brick"
    },
    {
      "x": -20,
      "y": 34,
      "z": -11,
      "name": "Rock_Sandstone_Brick"
    },
    {
      "x": -20,
      "y": 35,
      "z": -11,
      "name": "Soil_Clay_Ocean_Brick_Smooth"
    },
    {
      "x": -20,
      "y": 36,
      "z": -11,
      "name": "Soil_Clay_Ocean_Brick"
    },
    {
      "x": -20,
      "y": 1,
      "z": -10,
      "name": "Wood_Redwood_Ornate"
    },
    {
      "x": -20,
      "y": 2,
      "z": -10,
      "name": "Wood_Redwood_Planks"
    },
    {
      "x": -20,
      "y": 3,
      "z": -10,
      "name": "Wood_Redwood_Planks"
    },
    {
      "x": -20,
      "y": 4,
      "z": -10,
      "name": "Wood_Redwood_Planks"
    },
    {
      "x": -20,
      "y": 5,
      "z": -10,
      "name": "Rock_Sandstone_Brick",
      "rotation": 1
    },
    {
      "x": -20,
      "y": 6,
      "z": -10,
      "name": "Rock_Sandstone_Brick",
      "rotation": 1
    },
    {
      "x": -20,
      "y": 7,
      "z": -10,
      "name": "Rock_Sandstone_Brick",
      "rotation": 1
    },
    {
      "x": -20,
      "y": 8,
      "z": -10,
      "name": "Rock_Sandstone_Brick",
      "rotation": 1
    },
    {
      "x": -20,
      "y": 9,
      "z": -10,
      "name": "Rock_Sandstone_Cobble",
      "rotation": 1
    },
    {
      "x": -20,
      "y": 10,
      "z": -10,
      "name": "Rock_Sandstone_Brick",
      "rotation": 1
    },
    {
      "x": -20,
      "y": 11,
      "z": -10,
      "name": "Rock_Sandstone_Brick",
      "rotation": 1
    },
    {
      "x": -20,
      "y": 12,
      "z": -10,
      "name": "Rock_Sandstone_Brick",
      "rotation": 1
    },
    {
      "x": -20,
      "y": 13,
      "z": -10,
      "name": "Rock_Sandstone_Red_Cobble"
    },
    {
      "x": -20,
      "y": 14,
      "z": -10,
      "name": "Wood_Redwood_Planks"
    },
    {
      "x": -20,
      "y": 15,
      "z": -10,
      "name": "Wood_Redwood_Planks"
    },
    {
      "x": -20,
      "y": 16,
      "z": -10,
      "name": "Wood_Redwood_Planks"
    },
    {
      "x": -20,
      "y": 17,
      "z": -10,
      "name": "Rock_Sandstone_Red"
    },
    {
      "x": -20,
      "y": 18,
      "z": -10,
      "name": "Rock_Sandstone_Red"
    },
    {
      "x": -20,
      "y": 19,
      "z": -10,
      "name": "Rock_Sandstone_Red_Cobble"
    },
    {
      "x": -20,
      "y": 20,
      "z": -10,
      "name": "Rock_Sandstone_Red_Cobble"
    },
    {
      "x": -20,
      "y": 21,
      "z": -10,
      "name": "Rock_Sandstone_Cobble",
      "rotation": 3
    },
    {
      "x": -20,
      "y": 22,
      "z": -10,
      "name": "Rock_Sandstone_Cobble",
      "rotation": 3
    },
    {
      "x": -20,
      "y": 23,
      "z": -10,
      "name": "Rock_Sandstone_Brick",
      "rotation": 3
    },
    {
      "x": -20,
      "y": 24,
      "z": -10,
      "name": "Rock_Sandstone_Cobble",
      "rotation": 3
    },
    {
      "x": -20,
      "y": 25,
      "z": -10,
      "name": "Rock_Sandstone_Cobble",
      "rotation": 3
    },
    {
      "x": -20,
      "y": 26,
      "z": -10,
      "name": "Rock_Sandstone_Brick",
      "rotation": 3
    },
    {
      "x": -20,
      "y": 27,
      "z": -10,
      "name": "Rock_Sandstone_Brick",
      "rotation": 3
    },
    {
      "x": -20,
      "y": 28,
      "z": -10,
      "name": "Rock_Sandstone_Brick",
      "rotation": 3
    },
    {
      "x": -20,
      "y": 29,
      "z": -10,
      "name": "Rock_Sandstone_Brick"
    },
    {
      "x": -20,
      "y": 30,
      "z": -10,
      "name": "Rock_Sandstone_Brick"
    },
    {
      "x": -20,
      "y": 31,
      "z": -10,
      "name": "Rock_Sandstone_Brick"
    },
    {
      "x": -20,
      "y": 32,
      "z": -10,
      "name": "Rock_Sandstone_Brick"
    },
    {
      "x": -20,
      "y": 33,
      "z": -10,
      "name": "Rock_Sandstone_Brick"
    },
    {
      "x": -20,
      "y": 34,
      "z": -10,
      "name": "Rock_Sandstone_Brick"
    },
    {
      "x": -20,
      "y": 35,
      "z": -10,
      "name": "Soil_Clay_Ocean_Brick"
    },
    {
      "x": -20,
      "y": 36,
      "z": -10,
      "name": "Soil_Clay_Ocean_Brick"
    },
    {
      "x": -20,
      "y": 1,
      "z": -9,
      "name": "Wood_Redwood_Planks"
    },
    {
      "x": -20,
      "y": 2,
      "z": -9,
      "name": "Wood_Redwood_Planks"
    },
    {
      "x": -20,
      "y": 3,
      "z": -9,
      "name": "Wood_Redwood_Planks"
    },
    {
      "x": -20,
      "y": 4,
      "z": -9,
      "name": "Wood_Redwood_Ornate"
    },
    {
      "x": -20,
      "y": 5,
      "z": -9,
      "name": "Wood_Redwood_Planks"
    },
    {
      "x": -20,
      "y": 6,
      "z": -9,
      "name": "Wood_Redwood_Planks"
    },
    {
      "x": -20,
      "y": 7,
      "z": -9,
      "name": "Rock_Sandstone_Brick",
      "rotation": 1
    },
    {
      "x": -20,
      "y": 8,
      "z": -9,
      "name": "Rock_Sandstone_Cobble",
      "rotation": 1
    },
    {
      "x": -20,
      "y": 9,
      "z": -9,
      "name": "Rock_Sandstone_Brick",
      "rotation": 1
    },
    {
      "x": -20,
      "y": 10,
      "z": -9,
      "name": "Rock_Sandstone_Cobble",
      "rotation": 1
    },
    {
      "x": -20,
      "y": 11,
      "z": -9,
      "name": "Rock_Sandstone_Brick",
      "rotation": 1
    },
    {
      "x": -20,
      "y": 12,
      "z": -9,
      "name": "Rock_Sandstone_Brick",
      "rotation": 1
    },
    {
      "x": -20,
      "y": 13,
      "z": -9,
      "name": "Rock_Sandstone_Red_Cobble"
    },
    {
      "x": -20,
      "y": 14,
      "z": -9,
      "name": "Rock_Sandstone_Red_Cobble"
    },
    {
      "x": -20,
      "y": 15,
      "z": -9,
      "name": "Wood_Redwood_Planks"
    },
    {
      "x": -20,
      "y": 16,
      "z": -9,
      "name": "Rock_Sandstone_Red_Cobble"
    },
    {
      "x": -20,
      "y": 17,
      "z": -9,
      "name": "Rock_Sandstone_Red_Brick_Ornate"
    },
    {
      "x": -20,
      "y": 18,
      "z": -9,
      "name": "Rock_Sandstone_Red_Cobble"
    },
    {
      "x": -20,
      "y": 19,
      "z": -9,
      "name": "Rock_Sandstone_Red_Cobble"
    },
    {
      "x": -20,
      "y": 20,
      "z": -9,
      "name": "Rock_Sandstone_Red_Cobble"
    },
    {
      "x": -20,
      "y": 21,
      "z": -9,
      "name": "Rock_Sandstone_Cobble",
      "rotation": 3
    },
    {
      "x": -20,
      "y": 22,
      "z": -9,
      "name": "Rock_Sandstone_Brick",
      "rotation": 3
    },
    {
      "x": -20,
      "y": 23,
      "z": -9,
      "name": "Rock_Sandstone_Brick",
      "rotation": 3
    },
    {
      "x": -20,
      "y": 24,
      "z": -9,
      "name": "Rock_Sandstone_Cobble",
      "rotation": 3
    },
    {
      "x": -20,
      "y": 25,
      "z": -9,
      "name": "Rock_Sandstone_Brick",
      "rotation": 3
    },
    {
      "x": -20,
      "y": 26,
      "z": -9,
      "name": "Rock_Sandstone_Cobble",
      "rotation": 3
    },
    {
      "x": -20,
      "y": 27,
      "z": -9,
      "name": "Rock_Sandstone_Cobble",
      "rotation": 3
    },
    {
      "x": -20,
      "y": 28,
      "z": -9,
      "name": "Rock_Sandstone_Brick",
      "rotation": 3
    },
    {
      "x": -20,
      "y": 29,
      "z": -9,
      "name": "Rock_Sandstone_Brick"
    },
    {
      "x": -20,
      "y": 30,
      "z": -9,
      "name": "Rock_Sandstone_Brick"
    },
    {
      "x": -20,
      "y": 31,
      "z": -9,
      "name": "Rock_Sandstone_Brick"
    },
    {
      "x": -20,
      "y": 32,
      "z": -9,
      "name": "Rock_Sandstone_Brick"
    },
    {
      "x": -20,
      "y": 33,
      "z": -9,
      "name": "Rock_Sandstone_Brick"
    },
    {
      "x": -20,
      "y": 34,
      "z": -9,
      "name": "Rock_Sandstone_Brick"
    },
    {
      "x": -20,
      "y": 35,
      "z": -9,
      "name": "Soil_Clay_Ocean_Brick"
    },
    {
      "x": -20,
      "y": 36,
      "z": -9,
      "name": "Soil_Clay_Ocean_Brick"
    },
    {
      "x": -20,
      "y": 0,
      "z": -8,
      "name": "Rock_Sandstone_Brick"
    },
    {
      "x": -20,
      "y": 1,
      "z": -8,
      "name": "Wood_Redwood_Planks"
    },
    {
      "x": -20,
      "y": 2,
      "z": -8,
      "name": "Wood_Redwood_Planks"
    },
    {
      "x": -20,
      "y": 3,
      "z": -8,
      "name": "Wood_Redwood_Trunk_Full"
    },
    {
      "x": -20,
      "y": 4,
      "z": -8,
      "name": "Wood_Redwood_Planks"
    },
    {
      "x": -20,
      "y": 5,
      "z": -8,
      "name": "Wood_Redwood_Trunk_Full"
    },
    {
      "x": -20,
      "y": 6,
      "z": -8,
      "name": "Wood_Redwood_Ornate"
    },
    {
      "x": -20,
      "y": 7,
      "z": -8,
      "name": "Rock_Sandstone_Cobble",
      "rotation": 1
    },
    {
      "x": -20,
      "y": 8,
      "z": -8,
      "name": "Rock_Sandstone_Brick",
      "rotation": 1
    },
    {
      "x": -20,
      "y": 9,
      "z": -8,
      "name": "Rock_Sandstone_Brick",
      "rotation": 1
    },
    {
      "x": -20,
      "y": 10,
      "z": -8,
      "name": "Rock_Sandstone_Cobble",
      "rotation": 1
    },
    {
      "x": -20,
      "y": 11,
      "z": -8,
      "name": "Rock_Sandstone_Brick",
      "rotation": 1
    },
    {
      "x": -20,
      "y": 12,
      "z": -8,
      "name": "Rock_Sandstone_Brick",
      "rotation": 1
    },
    {
      "x": -20,
      "y": 13,
      "z": -8,
      "name": "Rock_Sandstone_Red_Cobble"
    },
    {
      "x": -20,
      "y": 14,
      "z": -8,
      "name": "Rock_Sandstone_Red"
    },
    {
      "x": -20,
      "y": 15,
      "z": -8,
      "name": "Rock_Sandstone_Red"
    },
    {
      "x": -20,
      "y": 16,
      "z": -8,
      "name": "Rock_Sandstone_Red_Cobble"
    },
    {
      "x": -20,
      "y": 17,
      "z": -8,
      "name": "Rock_Sandstone_Red_Cobble"
    },
    {
      "x": -20,
      "y": 18,
      "z": -8,
      "name": "Rock_Sandstone_Red_Cobble"
    },
    {
      "x": -20,
      "y": 19,
      "z": -8,
      "name": "Rock_Sandstone_Red_Cobble"
    },
    {
      "x": -20,
      "y": 20,
      "z": -8,
      "name": "Rock_Sandstone_Red_Cobble"
    },
    {
      "x": -20,
      "y": 21,
      "z": -8,
      "name": "Rock_Sandstone_Red_Cobble"
    },
    {
      "x": -20,
      "y": 22,
      "z": -8,
      "name": "Rock_Sandstone_Red_Cobble"
    },
    {
      "x": -20,
      "y": 23,
      "z": -8,
      "name": "Rock_Sandstone_Brick",
      "rotation": 3
    },
    {
      "x": -20,
      "y": 24,
      "z": -8,
      "name": "Rock_Sandstone_Brick",
      "rotation": 3
    },
    {
      "x": -20,
      "y": 25,
      "z": -8,
      "name": "Rock_Sandstone_Brick",
      "rotation": 3
    },
    {
      "x": -20,
      "y": 26,
      "z": -8,
      "name": "Rock_Sandstone_Brick",
      "rotation": 3
    },
    {
      "x": -20,
      "y": 27,
      "z": -8,
      "name": "Rock_Sandstone_Brick",
      "rotation": 3
    },
    {
      "x": -20,
      "y": 28,
      "z": -8,
      "name": "Rock_Sandstone_Cobble",
      "rotation": 3
    },
    {
      "x": -20,
      "y": 29,
      "z": -8,
      "name": "Rock_Sandstone_Brick"
    },
    {
      "x": -20,
      "y": 30,
      "z": -8,
      "name": "Rock_Sandstone_Brick"
    },
    {
      "x": -20,
      "y": 34,
      "z": -8,
      "name": "Rock_Sandstone_Brick"
    },
    {
      "x": -20,
      "y": 35,
      "z": -8,
      "name": "Soil_Clay_Ocean_Brick"
    },
    {
      "x": -20,
      "y": 36,
      "z": -8,
      "name": "Soil_Clay_Ocean_Brick"
    },
    {
      "x": -20,
      "y": -3,
      "z": -7,
      "name": "Rock_Sandstone_Brick_Half",
      "rotation": 8
    },
    {
      "x": -20,
      "y": -2,
      "z": -7,
      "name": "Rock_Sandstone_Brick"
    },
    {
      "x": -20,
      "y": -1,
      "z": -7,
      "name": "Rock_Sandstone_Brick"
    },
    {
      "x": -20,
      "y": 0,
      "z": -7,
      "name": "Rock_Sandstone_Brick"
    },
    {
      "x": -20,
      "y": 1,
      "z": -7,
      "name": "Wood_Redwood_Planks"
    },
    {
      "x": -20,
      "y": 2,
      "z": -7,
      "name": "Wood_Redwood_Planks"
    },
    {
      "x": -20,
      "y": 3,
      "z": -7,
      "name": "Wood_Redwood_Planks"
    },
    {
      "x": -20,
      "y": 4,
      "z": -7,
      "name": "Wood_Redwood_Planks"
    },
    {
      "x": -20,
      "y": 5,
      "z": -7,
      "name": "Wood_Redwood_Planks"
    },
    {
      "x": -20,
      "y": 6,
      "z": -7,
      "name": "Wood_Redwood_Planks"
    },
    {
      "x": -20,
      "y": 7,
      "z": -7,
      "name": "Rock_Sandstone_Brick",
      "rotation": 1
    },
    {
      "x": -20,
      "y": 8,
      "z": -7,
      "name": "Rock_Sandstone_Cobble",
      "rotation": 1
    },
    {
      "x": -20,
      "y": 9,
      "z": -7,
      "name": "Rock_Sandstone_Brick",
      "rotation": 1
    },
    {
      "x": -20,
      "y": 10,
      "z": -7,
      "name": "Rock_Sandstone_Cobble",
      "rotation": 1
    },
    {
      "x": -20,
      "y": 11,
      "z": -7,
      "name": "Rock_Sandstone_Cobble",
      "rotation": 1
    },
    {
      "x": -20,
      "y": 12,
      "z": -7,
      "name": "Rock_Sandstone_Cobble",
      "rotation": 1
    },
    {
      "x": -20,
      "y": 13,
      "z": -7,
      "name": "Rock_Sandstone_Red_Cobble"
    },
    {
      "x": -20,
      "y": 14,
      "z": -7,
      "name": "Wood_Redwood_Planks"
    },
    {
      "x": -20,
      "y": 15,
      "z": -7,
      "name": "Wood_Redwood_Planks"
    },
    {
      "x": -20,
      "y": 16,
      "z": -7,
      "name": "Wood_Redwood_Planks"
    },
    {
      "x": -20,
      "y": 17,
      "z": -7,
      "name": "Rock_Sandstone_Red_Cobble"
    },
    {
      "x": -20,
      "y": 18,
      "z": -7,
      "name": "Rock_Sandstone_Red_Cobble"
    },
    {
      "x": -20,
      "y": 19,
      "z": -7,
      "name": "Rock_Sandstone_Red_Cobble"
    },
    {
      "x": -20,
      "y": 20,
      "z": -7,
      "name": "Rock_Sandstone_Red_Cobble"
    },
    {
      "x": -20,
      "y": 21,
      "z": -7,
      "name": "Rock_Sandstone_Red"
    },
    {
      "x": -20,
      "y": 22,
      "z": -7,
      "name": "Rock_Sandstone_Red_Brick_Ornate"
    },
    {
      "x": -20,
      "y": 23,
      "z": -7,
      "name": "Rock_Sandstone_Cobble",
      "rotation": 3
    },
    {
      "x": -20,
      "y": 24,
      "z": -7,
      "name": "Rock_Sandstone_Brick",
      "rotation": 3
    },
    {
      "x": -20,
      "y": 25,
      "z": -7,
      "name": "Rock_Sandstone_Brick",
      "rotation": 3
    },
    {
      "x": -20,
      "y": 26,
      "z": -7,
      "name": "Rock_Sandstone_Brick",
      "rotation": 3
    },
    {
      "x": -20,
      "y": 27,
      "z": -7,
      "name": "Rock_Sandstone_Brick",
      "rotation": 3
    },
    {
      "x": -20,
      "y": 28,
      "z": -7,
      "name": "Rock_Sandstone_Brick",
      "rotation": 3
    },
    {
      "x": -20,
      "y": -3,
      "z": -6,
      "name": "Rock_Sandstone_Brick"
    },
    {
      "x": -20,
      "y": -2,
      "z": -6,
      "name": "Rock_Sandstone_Brick"
    },
    {
      "x": -20,
      "y": -1,
      "z": -6,
      "name": "Rock_Sandstone_Brick"
    },
    {
      "x": -20,
      "y": 0,
      "z": -6,
      "name": "Rock_Sandstone_Brick"
    },
    {
      "x": -20,
      "y": 15,
      "z": -6,
      "name": "Wood_Redwood_Planks"
    },
    {
      "x": -20,
      "y": 16,
      "z": -6,
      "name": "Wood_Redwood_Planks"
    },
    {
      "x": -20,
      "y": 17,
      "z": -6,
      "name": "Rock_Sandstone_Red_Brick_Ornate"
    },
    {
      "x": -20,
      "y": 18,
      "z": -6,
      "name": "Rock_Sandstone_Red_Cobble"
    },
    {
      "x": -20,
      "y": 19,
      "z": -6,
      "name": "Rock_Sandstone_Red_Cobble"
    },
    {
      "x": -20,
      "y": 20,
      "z": -6,
      "name": "Rock_Sandstone_Red_Cobble"
    },
    {
      "x": -20,
      "y": 21,
      "z": -6,
      "name": "Rock_Sandstone_Red_Cobble"
    },
    {
      "x": -20,
      "y": 22,
      "z": -6,
      "name": "Rock_Sandstone_Red"
    },
    {
      "x": -20,
      "y": 23,
      "z": -6,
      "name": "Rock_Sandstone_Cobble",
      "rotation": 3
    },
    {
      "x": -20,
      "y": 24,
      "z": -6,
      "name": "Rock_Sandstone_Brick",
      "rotation": 3
    },
    {
      "x": -20,
      "y": 25,
      "z": -6,
      "name": "Rock_Sandstone_Brick",
      "rotation": 3
    },
    {
      "x": -20,
      "y": 26,
      "z": -6,
      "name": "Rock_Sandstone_Brick",
      "rotation": 3
    },
    {
      "x": -20,
      "y": 27,
      "z": -6,
      "name": "Rock_Sandstone_Brick",
      "rotation": 3
    },
    {
      "x": -20,
      "y": 28,
      "z": -6,
      "name": "Rock_Sandstone_Brick",
      "rotation": 3
    },
    {
      "x": -20,
      "y": -4,
      "z": -5,
      "name": "Rock_Sandstone_Brick_Stairs",
      "rotation": 8
    },
    {
      "x": -20,
      "y": -3,
      "z": -5,
      "name": "Rock_Sandstone_Cobble"
    },
    {
      "x": -20,
      "y": -2,
      "z": -5,
      "name": "Rock_Sandstone_Brick"
    },
    {
      "x": -20,
      "y": -1,
      "z": -5,
      "name": "Rock_Sandstone_Brick"
    },
    {
      "x": -20,
      "y": 0,
      "z": -5,
      "name": "Rock_Sandstone_Brick"
    },
    {
      "x": -20,
      "y": -5,
      "z": -4,
      "name": "Rock_Sandstone_Brick_Stairs",
      "rotation": 8
    },
    {
      "x": -20,
      "y": -4,
      "z": -4,
      "name": "Rock_Sandstone"
    },
    {
      "x": -20,
      "y": -3,
      "z": -4,
      "name": "Rock_Sandstone_Brick"
    },
    {
      "x": -20,
      "y": -2,
      "z": -4,
      "name": "Rock_Sandstone_Brick"
    },
    {
      "x": -20,
      "y": -1,
      "z": -4,
      "name": "Rock_Sandstone_Brick"
    },
    {
      "x": -20,
      "y": 0,
      "z": -4,
      "name": "Rock_Sandstone_Brick"
    },
    {
      "x": -20,
      "y": -35,
      "z": -3,
      "name": "Rock_Sandstone_Brick"
    },
    {
      "x": -20,
      "y": -34,
      "z": -3,
      "name": "Rock_Sandstone"
    },
    {
      "x": -20,
      "y": -33,
      "z": -3,
      "name": "Rock_Sandstone_Brick"
    },
    {
      "x": -20,
      "y": -32,
      "z": -3,
      "name": "Rock_Sandstone_Brick"
    },
    {
      "x": -20,
      "y": -31,
      "z": -3,
      "name": "Rock_Sandstone_Brick"
    },
    {
      "x": -20,
      "y": -30,
      "z": -3,
      "name": "Rock_Sandstone_Brick"
    },
    {
      "x": -20,
      "y": -29,
      "z": -3,
      "name": "Rock_Sandstone_Brick"
    },
    {
      "x": -20,
      "y": -28,
      "z": -3,
      "name": "Rock_Sandstone_Cobble"
    },
    {
      "x": -20,
      "y": -27,
      "z": -3,
      "name": "Rock_Sandstone_Brick"
    },
    {
      "x": -20,
      "y": -26,
      "z": -3,
      "name": "Rock_Sandstone_Brick"
    },
    {
      "x": -20,
      "y": -25,
      "z": -3,
      "name": "Rock_Sandstone"
    },
    {
      "x": -20,
      "y": -24,
      "z": -3,
      "name": "Rock_Sandstone_Brick",
      "rotation": 1
    },
    {
      "x": -20,
      "y": -23,
      "z": -3,
      "name": "Rock_Sandstone_Brick",
      "rotation": 1
    },
    {
      "x": -20,
      "y": -22,
      "z": -3,
      "name": "Rock_Sandstone_Brick",
      "rotation": 1
    },
    {
      "x": -20,
      "y": -21,
      "z": -3,
      "name": "Rock_Sandstone_Cobble",
      "rotation": 1
    },
    {
      "x": -20,
      "y": -20,
      "z": -3,
      "name": "Rock_Sandstone_Brick",
      "rotation": 1
    },
    {
      "x": -20,
      "y": -19,
      "z": -3,
      "name": "Rock_Sandstone_Brick",
      "rotation": 1
    },
    {
      "x": -20,
      "y": -18,
      "z": -3,
      "name": "Rock_Sandstone_Brick",
      "rotation": 1
    },
    {
      "x": -20,
      "y": -17,
      "z": -3,
      "name": "Rock_Sandstone_Brick",
      "rotation": 1
    },
    {
      "x": -20,
      "y": -16,
      "z": -3,
      "name": "Rock_Sandstone_Brick",
      "rotation": 1
    },
    {
      "x": -20,
      "y": -15,
      "z": -3,
      "name": "Rock_Sandstone_Brick",
      "rotation": 1
    },
    {
      "x": -20,
      "y": -14,
      "z": -3,
      "name": "Rock_Sandstone_Brick",
      "rotation": 1
    },
    {
      "x": -20,
      "y": -13,
      "z": -3,
      "name": "Rock_Sandstone_Cobble",
      "rotation": 1
    },
    {
      "x": -20,
      "y": -12,
      "z": -3,
      "name": "Rock_Sandstone_Brick",
      "rotation": 1
    },
    {
      "x": -20,
      "y": -11,
      "z": -3,
      "name": "Rock_Sandstone_Cobble",
      "rotation": 1
    },
    {
      "x": -20,
      "y": -10,
      "z": -3,
      "name": "Rock_Sandstone_Brick",
      "rotation": 1
    },
    {
      "x": -20,
      "y": -9,
      "z": -3,
      "name": "Rock_Sandstone_Brick",
      "rotation": 1
    },
    {
      "x": -20,
      "y": -8,
      "z": -3,
      "name": "Rock_Sandstone_Brick",
      "rotation": 1
    },
    {
      "x": -20,
      "y": -7,
      "z": -3,
      "name": "Rock_Sandstone_Brick",
      "rotation": 1
    },
    {
      "x": -20,
      "y": -6,
      "z": -3,
      "name": "Rock_Sandstone_Brick",
      "rotation": 1
    },
    {
      "x": -20,
      "y": -5,
      "z": -3,
      "name": "Rock_Sandstone_Brick",
      "rotation": 1
    },
    {
      "x": -20,
      "y": -4,
      "z": -3,
      "name": "Rock_Sandstone_Brick",
      "rotation": 1
    },
    {
      "x": -20,
      "y": -3,
      "z": -3,
      "name": "Rock_Sandstone_Brick",
      "rotation": 1
    },
    {
      "x": -20,
      "y": -2,
      "z": -3,
      "name": "Rock_Sandstone_Brick",
      "rotation": 1
    },
    {
      "x": -20,
      "y": -1,
      "z": -3,
      "name": "Rock_Sandstone_Brick",
      "rotation": 1
    },
    {
      "x": -20,
      "y": 0,
      "z": -3,
      "name": "Rock_Sandstone_Brick"
    },
    {
      "x": -20,
      "y": -35,
      "z": -2,
      "name": "Rock_Sandstone_Brick"
    },
    {
      "x": -20,
      "y": -34,
      "z": -2,
      "name": "Rock_Sandstone"
    },
    {
      "x": -20,
      "y": -33,
      "z": -2,
      "name": "Rock_Sandstone_Brick"
    },
    {
      "x": -20,
      "y": -32,
      "z": -2,
      "name": "Rock_Sandstone_Brick"
    },
    {
      "x": -20,
      "y": -31,
      "z": -2,
      "name": "Rock_Sandstone"
    },
    {
      "x": -20,
      "y": -30,
      "z": -2,
      "name": "Rock_Sandstone_Brick"
    },
    {
      "x": -20,
      "y": -29,
      "z": -2,
      "name": "Rock_Sandstone_Cobble"
    },
    {
      "x": -20,
      "y": -28,
      "z": -2,
      "name": "Rock_Sandstone_Brick"
    },
    {
      "x": -20,
      "y": -27,
      "z": -2,
      "name": "Rock_Sandstone_Brick"
    },
    {
      "x": -20,
      "y": -26,
      "z": -2,
      "name": "Rock_Sandstone_Brick"
    },
    {
      "x": -20,
      "y": -25,
      "z": -2,
      "name": "Rock_Sandstone_Cobble"
    },
    {
      "x": -20,
      "y": -24,
      "z": -2,
      "name": "Rock_Sandstone_Brick",
      "rotation": 1
    },
    {
      "x": -20,
      "y": -23,
      "z": -2,
      "name": "Rock_Sandstone_Brick",
      "rotation": 1
    },
    {
      "x": -20,
      "y": -22,
      "z": -2,
      "name": "Rock_Sandstone_Brick",
      "rotation": 1
    },
    {
      "x": -20,
      "y": -21,
      "z": -2,
      "name": "Rock_Sandstone",
      "rotation": 1
    },
    {
      "x": -20,
      "y": -20,
      "z": -2,
      "name": "Rock_Sandstone_Brick",
      "rotation": 1
    },
    {
      "x": -20,
      "y": -19,
      "z": -2,
      "name": "Rock_Sandstone_Brick",
      "rotation": 1
    },
    {
      "x": -20,
      "y": -18,
      "z": -2,
      "name": "Rock_Sandstone_Cobble",
      "rotation": 1
    },
    {
      "x": -20,
      "y": -17,
      "z": -2,
      "name": "Rock_Sandstone_Brick",
      "rotation": 1
    },
    {
      "x": -20,
      "y": -16,
      "z": -2,
      "name": "Rock_Sandstone",
      "rotation": 1
    },
    {
      "x": -20,
      "y": -15,
      "z": -2,
      "name": "Rock_Sandstone",
      "rotation": 1
    },
    {
      "x": -20,
      "y": -14,
      "z": -2,
      "name": "Rock_Sandstone_Brick",
      "rotation": 1
    },
    {
      "x": -20,
      "y": -13,
      "z": -2,
      "name": "Rock_Sandstone_Brick",
      "rotation": 1
    },
    {
      "x": -20,
      "y": -12,
      "z": -2,
      "name": "Rock_Sandstone_Brick",
      "rotation": 1
    },
    {
      "x": -20,
      "y": -11,
      "z": -2,
      "name": "Rock_Sandstone_Cobble",
      "rotation": 1
    },
    {
      "x": -20,
      "y": -10,
      "z": -2,
      "name": "Rock_Sandstone_Brick",
      "rotation": 1
    },
    {
      "x": -20,
      "y": -9,
      "z": -2,
      "name": "Rock_Sandstone_Brick",
      "rotation": 1
    },
    {
      "x": -20,
      "y": -8,
      "z": -2,
      "name": "Rock_Sandstone",
      "rotation": 1
    },
    {
      "x": -20,
      "y": -7,
      "z": -2,
      "name": "Rock_Sandstone_Cobble",
      "rotation": 1
    },
    {
      "x": -20,
      "y": -6,
      "z": -2,
      "name": "Rock_Sandstone_Brick",
      "rotation": 1
    },
    {
      "x": -20,
      "y": -5,
      "z": -2,
      "name": "Rock_Sandstone_Brick",
      "rotation": 1
    },
    {
      "x": -20,
      "y": -4,
      "z": -2,
      "name": "Rock_Sandstone_Brick",
      "rotation": 1
    },
    {
      "x": -20,
      "y": -3,
      "z": -2,
      "name": "Rock_Sandstone_Brick",
      "rotation": 1
    },
    {
      "x": -20,
      "y": -2,
      "z": -2,
      "name": "Rock_Sandstone_Brick",
      "rotation": 1
    },
    {
      "x": -20,
      "y": -1,
      "z": -2,
      "name": "Rock_Sandstone_Brick",
      "rotation": 1
    },
    {
      "x": -20,
      "y": 0,
      "z": -2,
      "name": "Rock_Sandstone_Brick"
    },
    {
      "x": -20,
      "y": -35,
      "z": -1,
      "name": "Rock_Sandstone_Cobble"
    },
    {
      "x": -20,
      "y": -34,
      "z": -1,
      "name": "Rock_Sandstone_Brick"
    },
    {
      "x": -20,
      "y": -33,
      "z": -1,
      "name": "Rock_Sandstone_Brick"
    },
    {
      "x": -20,
      "y": -32,
      "z": -1,
      "name": "Rock_Sandstone"
    },
    {
      "x": -20,
      "y": -31,
      "z": -1,
      "name": "Rock_Sandstone_Brick"
    },
    {
      "x": -20,
      "y": -30,
      "z": -1,
      "name": "Rock_Sandstone_Brick"
    },
    {
      "x": -20,
      "y": -29,
      "z": -1,
      "name": "Rock_Sandstone_Brick"
    },
    {
      "x": -20,
      "y": -28,
      "z": -1,
      "name": "Rock_Sandstone"
    },
    {
      "x": -20,
      "y": -27,
      "z": -1,
      "name": "Rock_Sandstone_Brick"
    },
    {
      "x": -20,
      "y": -26,
      "z": -1,
      "name": "Rock_Sandstone_Brick"
    },
    {
      "x": -20,
      "y": -25,
      "z": -1,
      "name": "Rock_Sandstone"
    },
    {
      "x": -20,
      "y": -24,
      "z": -1,
      "name": "Rock_Sandstone_Brick",
      "rotation": 1
    },
    {
      "x": -20,
      "y": -23,
      "z": -1,
      "name": "Rock_Sandstone_Brick",
      "rotation": 1
    },
    {
      "x": -20,
      "y": -22,
      "z": -1,
      "name": "Rock_Sandstone_Brick",
      "rotation": 1
    },
    {
      "x": -20,
      "y": -21,
      "z": -1,
      "name": "Rock_Sandstone",
      "rotation": 1
    },
    {
      "x": -20,
      "y": -20,
      "z": -1,
      "name": "Rock_Sandstone_Brick",
      "rotation": 1
    },
    {
      "x": -20,
      "y": -19,
      "z": -1,
      "name": "Rock_Sandstone_Brick",
      "rotation": 1
    },
    {
      "x": -20,
      "y": -18,
      "z": -1,
      "name": "Rock_Sandstone_Brick",
      "rotation": 1
    },
    {
      "x": -20,
      "y": -17,
      "z": -1,
      "name": "Rock_Sandstone_Cobble",
      "rotation": 1
    },
    {
      "x": -20,
      "y": -16,
      "z": -1,
      "name": "Rock_Sandstone_Brick",
      "rotation": 1
    },
    {
      "x": -20,
      "y": -15,
      "z": -1,
      "name": "Rock_Sandstone_Brick",
      "rotation": 1
    },
    {
      "x": -20,
      "y": -14,
      "z": -1,
      "name": "Rock_Sandstone_Brick",
      "rotation": 1
    },
    {
      "x": -20,
      "y": -13,
      "z": -1,
      "name": "Rock_Sandstone_Cobble",
      "rotation": 1
    },
    {
      "x": -20,
      "y": -12,
      "z": -1,
      "name": "Rock_Sandstone_Brick",
      "rotation": 1
    },
    {
      "x": -20,
      "y": -11,
      "z": -1,
      "name": "Rock_Sandstone_Brick",
      "rotation": 1
    },
    {
      "x": -20,
      "y": -10,
      "z": -1,
      "name": "Rock_Sandstone_Brick",
      "rotation": 1
    },
    {
      "x": -20,
      "y": -9,
      "z": -1,
      "name": "Rock_Sandstone_Brick",
      "rotation": 1
    },
    {
      "x": -20,
      "y": -8,
      "z": -1,
      "name": "Rock_Sandstone_Brick",
      "rotation": 1
    },
    {
      "x": -20,
      "y": -7,
      "z": -1,
      "name": "Rock_Sandstone_Cobble",
      "rotation": 1
    },
    {
      "x": -20,
      "y": -6,
      "z": -1,
      "name": "Rock_Sandstone_Brick",
      "rotation": 1
    },
    {
      "x": -20,
      "y": -5,
      "z": -1,
      "name": "Rock_Sandstone_Brick",
      "rotation": 1
    },
    {
      "x": -20,
      "y": -4,
      "z": -1,
      "name": "Rock_Sandstone_Brick",
      "rotation": 1
    },
    {
      "x": -20,
      "y": -3,
      "z": -1,
      "name": "Rock_Sandstone_Brick",
      "rotation": 1
    },
    {
      "x": -20,
      "y": -2,
      "z": -1,
      "name": "Rock_Sandstone_Brick",
      "rotation": 1
    },
    {
      "x": -20,
      "y": -1,
      "z": -1,
      "name": "Rock_Sandstone_Brick",
      "rotation": 1
    },
    {
      "x": -20,
      "y": 0,
      "z": -1,
      "name": "Rock_Sandstone_Brick"
    },
    {
      "x": -20,
      "y": -35,
      "z": 0,
      "name": "Rock_Sandstone_Brick"
    },
    {
      "x": -20,
      "y": -34,
      "z": 0,
      "name": "Rock_Sandstone_Brick"
    },
    {
      "x": -20,
      "y": -33,
      "z": 0,
      "name": "Rock_Sandstone_Brick"
    },
    {
      "x": -20,
      "y": -32,
      "z": 0,
      "name": "Rock_Sandstone_Brick"
    },
    {
      "x": -20,
      "y": -31,
      "z": 0,
      "name": "Rock_Sandstone_Cobble"
    },
    {
      "x": -20,
      "y": -30,
      "z": 0,
      "name": "Rock_Sandstone_Brick"
    },
    {
      "x": -20,
      "y": -29,
      "z": 0,
      "name": "Rock_Sandstone"
    },
    {
      "x": -20,
      "y": -28,
      "z": 0,
      "name": "Rock_Sandstone_Brick"
    },
    {
      "x": -20,
      "y": -27,
      "z": 0,
      "name": "Rock_Sandstone"
    },
    {
      "x": -20,
      "y": -26,
      "z": 0,
      "name": "Rock_Sandstone"
    },
    {
      "x": -20,
      "y": -25,
      "z": 0,
      "name": "Rock_Sandstone_Brick"
    },
    {
      "x": -20,
      "y": -24,
      "z": 0,
      "name": "Rock_Sandstone"
    },
    {
      "x": -20,
      "y": -23,
      "z": 0,
      "name": "Rock_Sandstone_Brick"
    },
    {
      "x": -20,
      "y": -22,
      "z": 0,
      "name": "Rock_Sandstone_Brick"
    },
    {
      "x": -20,
      "y": -21,
      "z": 0,
      "name": "Rock_Sandstone_Brick"
    },
    {
      "x": -20,
      "y": -20,
      "z": 0,
      "name": "Rock_Sandstone_Brick"
    },
    {
      "x": -20,
      "y": -19,
      "z": 0,
      "name": "Rock_Sandstone_Cobble"
    },
    {
      "x": -20,
      "y": -18,
      "z": 0,
      "name": "Rock_Sandstone"
    },
    {
      "x": -20,
      "y": -17,
      "z": 0,
      "name": "Rock_Sandstone_Cobble"
    },
    {
      "x": -20,
      "y": -16,
      "z": 0,
      "name": "Rock_Sandstone_Brick"
    },
    {
      "x": -20,
      "y": -15,
      "z": 0,
      "name": "Rock_Sandstone_Brick"
    },
    {
      "x": -20,
      "y": -14,
      "z": 0,
      "name": "Rock_Sandstone_Brick"
    },
    {
      "x": -20,
      "y": -13,
      "z": 0,
      "name": "Rock_Sandstone"
    },
    {
      "x": -20,
      "y": -12,
      "z": 0,
      "name": "Rock_Sandstone_Brick"
    },
    {
      "x": -20,
      "y": -11,
      "z": 0,
      "name": "Rock_Sandstone_Brick"
    },
    {
      "x": -20,
      "y": -10,
      "z": 0,
      "name": "Rock_Sandstone_Brick"
    },
    {
      "x": -20,
      "y": -9,
      "z": 0,
      "name": "Rock_Sandstone_Brick"
    },
    {
      "x": -20,
      "y": -8,
      "z": 0,
      "name": "Rock_Sandstone_Brick"
    },
    {
      "x": -20,
      "y": -7,
      "z": 0,
      "name": "Rock_Sandstone_Brick"
    },
    {
      "x": -20,
      "y": -6,
      "z": 0,
      "name": "Rock_Sandstone_Brick"
    },
    {
      "x": -20,
      "y": -5,
      "z": 0,
      "name": "Rock_Sandstone_Brick"
    },
    {
      "x": -20,
      "y": -4,
      "z": 0,
      "name": "Rock_Sandstone_Brick"
    },
    {
      "x": -20,
      "y": -3,
      "z": 0,
      "name": "Rock_Sandstone_Cobble"
    },
    {
      "x": -20,
      "y": -2,
      "z": 0,
      "name": "Rock_Sandstone_Brick"
    },
    {
      "x": -20,
      "y": -1,
      "z": 0,
      "name": "Rock_Sandstone_Brick"
    },
    {
      "x": -20,
      "y": 0,
      "z": 0,
      "name": "Rock_Sandstone_Brick"
    },
    {
      "x": -19,
      "y": -35,
      "z": -21,
      "name": "Rock_Sandstone_Brick"
    },
    {
      "x": -19,
      "y": -34,
      "z": -21,
      "name": "Rock_Sandstone_Brick"
    },
    {
      "x": -19,
      "y": -33,
      "z": -21,
      "name": "Rock_Sandstone"
    },
    {
      "x": -19,
      "y": -32,
      "z": -21,
      "name": "Rock_Sandstone"
    },
    {
      "x": -19,
      "y": -31,
      "z": -21,
      "name": "Rock_Sandstone_Brick"
    },
    {
      "x": -19,
      "y": -30,
      "z": -21,
      "name": "Rock_Sandstone_Brick"
    },
    {
      "x": -19,
      "y": -29,
      "z": -21,
      "name": "Rock_Sandstone"
    },
    {
      "x": -19,
      "y": -28,
      "z": -21,
      "name": "Rock_Sandstone_Brick"
    },
    {
      "x": -19,
      "y": -27,
      "z": -21,
      "name": "Rock_Sandstone"
    },
    {
      "x": -19,
      "y": -26,
      "z": -21,
      "name": "Rock_Sandstone_Cobble"
    },
    {
      "x": -19,
      "y": -25,
      "z": -21,
      "name": "Rock_Sandstone_Brick"
    },
    {
      "x": -19,
      "y": -24,
      "z": -21,
      "name": "Rock_Sandstone"
    },
    {
      "x": -19,
      "y": -23,
      "z": -21,
      "name": "Rock_Sandstone_Brick"
    },
    {
      "x": -19,
      "y": -22,
      "z": -21,
      "name": "Rock_Sandstone"
    },
    {
      "x": -19,
      "y": -21,
      "z": -21,
      "name": "Rock_Sandstone_Brick"
    },
    {
      "x": -19,
      "y": -20,
      "z": -21,
      "name": "Rock_Sandstone_Brick"
    },
    {
      "x": -19,
      "y": -19,
      "z": -21,
      "name": "Rock_Sandstone_Brick"
    },
    {
      "x": -19,
      "y": -18,
      "z": -21,
      "name": "Rock_Sandstone_Brick"
    },
    {
      "x": -19,
      "y": -17,
      "z": -21,
      "name": "Rock_Sandstone_Brick"
    },
    {
      "x": -19,
      "y": -16,
      "z": -21,
      "name": "Rock_Sandstone_Cobble"
    },
    {
      "x": -19,
      "y": -15,
      "z": -21,
      "name": "Rock_Sandstone_Cobble"
    },
    {
      "x": -19,
      "y": -14,
      "z": -21,
      "name": "Rock_Sandstone_Brick"
    },
    {
      "x": -19,
      "y": -13,
      "z": -21,
      "name": "Rock_Sandstone_Brick"
    },
    {
      "x": -19,
      "y": -12,
      "z": -21,
      "name": "Rock_Sandstone_Cobble"
    },
    {
      "x": -19,
      "y": -11,
      "z": -21,
      "name": "Rock_Sandstone_Cobble"
    },
    {
      "x": -19,
      "y": -10,
      "z": -21,
      "name": "Rock_Sandstone_Brick"
    },
    {
      "x": -19,
      "y": -35,
      "z": -20,
      "name": "Rock_Sandstone_Cobble"
    },
    {
      "x": -19,
      "y": -34,
      "z": -20,
      "name": "Rock_Sandstone_Brick"
    },
    {
      "x": -19,
      "y": -33,
      "z": -20,
      "name": "Rock_Sandstone_Brick"
    },
    {
      "x": -19,
      "y": -32,
      "z": -20,
      "name": "Rock_Sandstone_Brick"
    },
    {
      "x": -19,
      "y": -31,
      "z": -20,
      "name": "Rock_Sandstone_Brick"
    },
    {
      "x": -19,
      "y": -30,
      "z": -20,
      "name": "Rock_Sandstone_Brick"
    },
    {
      "x": -19,
      "y": -29,
      "z": -20,
      "name": "Rock_Sandstone_Brick"
    },
    {
      "x": -19,
      "y": -28,
      "z": -20,
      "name": "Rock_Sandstone_Brick"
    },
    {
      "x": -19,
      "y": -27,
      "z": -20,
      "name": "Rock_Sandstone_Brick"
    },
    {
      "x": -19,
      "y": -26,
      "z": -20,
      "name": "Rock_Sandstone_Brick"
    },
    {
      "x": -19,
      "y": -25,
      "z": -20,
      "name": "Rock_Sandstone_Brick",
      "rotation": 3
    },
    {
      "x": -19,
      "y": -24,
      "z": -20,
      "name": "Rock_Sandstone_Brick",
      "rotation": 3
    },
    {
      "x": -19,
      "y": -23,
      "z": -20,
      "name": "Rock_Sandstone_Brick",
      "rotation": 3
    },
    {
      "x": -19,
      "y": -22,
      "z": -20,
      "name": "Rock_Sandstone_Brick",
      "rotation": 3
    },
    {
      "x": -19,
      "y": -21,
      "z": -20,
      "name": "Rock_Sandstone_Brick",
      "rotation": 3
    },
    {
      "x": -19,
      "y": -20,
      "z": -20,
      "name": "Rock_Sandstone_Brick",
      "rotation": 3
    },
    {
      "x": -19,
      "y": -19,
      "z": -20,
      "name": "Rock_Sandstone_Brick",
      "rotation": 3
    },
    {
      "x": -19,
      "y": -18,
      "z": -20,
      "name": "Rock_Sandstone_Brick",
      "rotation": 3
    },
    {
      "x": -19,
      "y": -17,
      "z": -20,
      "name": "Rock_Sandstone_Brick",
      "rotation": 3
    },
    {
      "x": -19,
      "y": -16,
      "z": -20,
      "name": "Rock_Sandstone_Brick",
      "rotation": 3
    },
    {
      "x": -19,
      "y": -15,
      "z": -20,
      "name": "Rock_Sandstone_Brick",
      "rotation": 3
    },
    {
      "x": -19,
      "y": -14,
      "z": -20,
      "name": "Rock_Sandstone",
      "rotation": 3
    },
    {
      "x": -19,
      "y": -13,
      "z": -20,
      "name": "Rock_Sandstone_Brick",
      "rotation": 3
    },
    {
      "x": -19,
      "y": -12,
      "z": -20,
      "name": "Rock_Sandstone_Brick",
      "rotation": 3
    },
    {
      "x": -19,
      "y": -11,
      "z": -20,
      "name": "Rock_Sandstone_Brick",
      "rotation": 3
    },
    {
      "x": -19,
      "y": -10,
      "z": -20,
      "name": "Rock_Sandstone_Brick",
      "rotation": 3
    },
    {
      "x": -19,
      "y": -9,
      "z": -20,
      "name": "Rock_Sandstone_Brick",
      "rotation": 3
    },
    {
      "x": -19,
      "y": -35,
      "z": -19,
      "name": "Rock_Sandstone_Brick"
    },
    {
      "x": -19,
      "y": -34,
      "z": -19,
      "name": "Rock_Sandstone_Brick"
    },
    {
      "x": -19,
      "y": -33,
      "z": -19,
      "name": "Rock_Sandstone_Brick"
    },
    {
      "x": -19,
      "y": -32,
      "z": -19,
      "name": "Rock_Sandstone_Brick"
    },
    {
      "x": -19,
      "y": -31,
      "z": -19,
      "name": "Rock_Sandstone_Brick"
    },
    {
      "x": -19,
      "y": -30,
      "z": -19,
      "name": "Rock_Sandstone_Brick"
    },
    {
      "x": -19,
      "y": -29,
      "z": -19,
      "name": "Rock_Sandstone_Brick"
    },
    {
      "x": -19,
      "y": -28,
      "z": -19,
      "name": "Rock_Sandstone_Brick"
    },
    {
      "x": -19,
      "y": -27,
      "z": -19,
      "name": "Rock_Sandstone_Cobble"
    },
    {
      "x": -19,
      "y": -26,
      "z": -19,
      "name": "Rock_Sandstone_Brick"
    },
    {
      "x": -19,
      "y": -25,
      "z": -19,
      "name": "Rock_Sandstone_Cobble",
      "rotation": 3
    },
    {
      "x": -19,
      "y": -24,
      "z": -19,
      "name": "Rock_Sandstone_Brick",
      "rotation": 3
    },
    {
      "x": -19,
      "y": -23,
      "z": -19,
      "name": "Rock_Sandstone_Cobble",
      "rotation": 3
    },
    {
      "x": -19,
      "y": -22,
      "z": -19,
      "name": "Rock_Sandstone",
      "rotation": 3
    },
    {
      "x": -19,
      "y": -21,
      "z": -19,
      "name": "Rock_Sandstone_Brick",
      "rotation": 3
    },
    {
      "x": -19,
      "y": -20,
      "z": -19,
      "name": "Rock_Sandstone_Brick",
      "rotation": 3
    },
    {
      "x": -19,
      "y": -19,
      "z": -19,
      "name": "Rock_Sandstone_Brick",
      "rotation": 3
    },
    {
      "x": -19,
      "y": -18,
      "z": -19,
      "name": "Rock_Sandstone_Brick",
      "rotation": 3
    },
    {
      "x": -19,
      "y": -17,
      "z": -19,
      "name": "Rock_Sandstone_Brick",
      "rotation": 3
    },
    {
      "x": -19,
      "y": -16,
      "z": -19,
      "name": "Rock_Sandstone",
      "rotation": 3
    },
    {
      "x": -19,
      "y": -15,
      "z": -19,
      "name": "Rock_Sandstone_Brick",
      "rotation": 3
    },
    {
      "x": -19,
      "y": -14,
      "z": -19,
      "name": "Rock_Sandstone_Brick",
      "rotation": 3
    },
    {
      "x": -19,
      "y": -13,
      "z": -19,
      "name": "Rock_Sandstone_Brick",
      "rotation": 3
    },
    {
      "x": -19,
      "y": -12,
      "z": -19,
      "name": "Rock_Sandstone_Brick",
      "rotation": 3
    },
    {
      "x": -19,
      "y": -11,
      "z": -19,
      "name": "Rock_Sandstone_Brick",
      "rotation": 3
    },
    {
      "x": -19,
      "y": -10,
      "z": -19,
      "name": "Rock_Sandstone_Brick",
      "rotation": 3
    },
    {
      "x": -19,
      "y": -9,
      "z": -19,
      "name": "Rock_Sandstone",
      "rotation": 3
    },
    {
      "x": -19,
      "y": -35,
      "z": -18,
      "name": "Rock_Sandstone"
    },
    {
      "x": -19,
      "y": -34,
      "z": -18,
      "name": "Rock_Sandstone"
    },
    {
      "x": -19,
      "y": -33,
      "z": -18,
      "name": "Rock_Sandstone_Brick"
    },
    {
      "x": -19,
      "y": -32,
      "z": -18,
      "name": "Rock_Sandstone_Brick"
    },
    {
      "x": -19,
      "y": -31,
      "z": -18,
      "name": "Rock_Sandstone_Brick"
    },
    {
      "x": -19,
      "y": -30,
      "z": -18,
      "name": "Rock_Sandstone_Brick"
    },
    {
      "x": -19,
      "y": -29,
      "z": -18,
      "name": "Rock_Sandstone_Brick"
    },
    {
      "x": -19,
      "y": -28,
      "z": -18,
      "name": "Rock_Sandstone_Brick"
    },
    {
      "x": -19,
      "y": -27,
      "z": -18,
      "name": "Rock_Sandstone_Brick"
    },
    {
      "x": -19,
      "y": -26,
      "z": -18,
      "name": "Rock_Sandstone_Cobble"
    },
    {
      "x": -19,
      "y": -25,
      "z": -18,
      "name": "Rock_Sandstone_Brick",
      "rotation": 3
    },
    {
      "x": -19,
      "y": -24,
      "z": -18,
      "name": "Rock_Sandstone",
      "rotation": 3
    },
    {
      "x": -19,
      "y": -23,
      "z": -18,
      "name": "Rock_Sandstone_Brick",
      "rotation": 3
    },
    {
      "x": -19,
      "y": -22,
      "z": -18,
      "name": "Rock_Sandstone_Brick",
      "rotation": 3
    },
    {
      "x": -19,
      "y": -21,
      "z": -18,
      "name": "Rock_Sandstone_Brick",
      "rotation": 3
    },
    {
      "x": -19,
      "y": -20,
      "z": -18,
      "name": "Rock_Sandstone_Cobble",
      "rotation": 3
    },
    {
      "x": -19,
      "y": -19,
      "z": -18,
      "name": "Rock_Sandstone_Brick",
      "rotation": 3
    },
    {
      "x": -19,
      "y": -18,
      "z": -18,
      "name": "Rock_Sandstone",
      "rotation": 3
    },
    {
      "x": -19,
      "y": -17,
      "z": -18,
      "name": "Rock_Sandstone_Brick",
      "rotation": 3
    },
    {
      "x": -19,
      "y": -16,
      "z": -18,
      "name": "Rock_Sandstone_Brick",
      "rotation": 3
    },
    {
      "x": -19,
      "y": -15,
      "z": -18,
      "name": "Rock_Sandstone",
      "rotation": 3
    },
    {
      "x": -19,
      "y": -14,
      "z": -18,
      "name": "Rock_Sandstone_Brick",
      "rotation": 3
    },
    {
      "x": -19,
      "y": -13,
      "z": -18,
      "name": "Rock_Sandstone_Brick",
      "rotation": 3
    },
    {
      "x": -19,
      "y": -12,
      "z": -18,
      "name": "Rock_Sandstone_Cobble",
      "rotation": 3
    },
    {
      "x": -19,
      "y": -11,
      "z": -18,
      "name": "Rock_Sandstone_Brick",
      "rotation": 3
    },
    {
      "x": -19,
      "y": -10,
      "z": -18,
      "name": "Rock_Sandstone_Brick",
      "rotation": 3
    },
    {
      "x": -19,
      "y": -9,
      "z": -18,
      "name": "Rock_Sandstone_Cobble",
      "rotation": 3
    },
    {
      "x": -19,
      "y": -35,
      "z": -17,
      "name": "Rock_Sandstone_Brick"
    },
    {
      "x": -19,
      "y": -34,
      "z": -17,
      "name": "Rock_Sandstone_Brick"
    },
    {
      "x": -19,
      "y": -33,
      "z": -17,
      "name": "Rock_Sandstone_Brick"
    },
    {
      "x": -19,
      "y": -32,
      "z": -17,
      "name": "Rock_Sandstone_Brick"
    },
    {
      "x": -19,
      "y": -31,
      "z": -17,
      "name": "Rock_Sandstone_Brick"
    },
    {
      "x": -19,
      "y": -30,
      "z": -17,
      "name": "Rock_Sandstone_Brick"
    },
    {
      "x": -19,
      "y": -29,
      "z": -17,
      "name": "Rock_Sandstone_Brick"
    },
    {
      "x": -19,
      "y": -28,
      "z": -17,
      "name": "Rock_Sandstone_Brick"
    },
    {
      "x": -19,
      "y": -27,
      "z": -17,
      "name": "Rock_Sandstone_Brick"
    },
    {
      "x": -19,
      "y": -26,
      "z": -17,
      "name": "Rock_Sandstone_Brick"
    },
    {
      "x": -19,
      "y": -25,
      "z": -17,
      "name": "Rock_Sandstone_Cobble"
    },
    {
      "x": -19,
      "y": -24,
      "z": -17,
      "name": "Rock_Sandstone_Cobble"
    },
    {
      "x": -19,
      "y": -23,
      "z": -17,
      "name": "Rock_Sandstone_Brick"
    },
    {
      "x": -19,
      "y": -22,
      "z": -17,
      "name": "Rock_Sandstone_Brick"
    },
    {
      "x": -19,
      "y": -21,
      "z": -17,
      "name": "Rock_Sandstone_Brick"
    },
    {
      "x": -19,
      "y": -20,
      "z": -17,
      "name": "Rock_Sandstone_Brick"
    },
    {
      "x": -19,
      "y": -19,
      "z": -17,
      "name": "Rock_Sandstone"
    },
    {
      "x": -19,
      "y": -18,
      "z": -17,
      "name": "Rock_Sandstone"
    },
    {
      "x": -19,
      "y": -17,
      "z": -17,
      "name": "Rock_Sandstone_Brick"
    },
    {
      "x": -19,
      "y": -16,
      "z": -17,
      "name": "Rock_Sandstone_Cobble"
    },
    {
      "x": -19,
      "y": -15,
      "z": -17,
      "name": "Rock_Sandstone_Brick"
    },
    {
      "x": -19,
      "y": -14,
      "z": -17,
      "name": "Rock_Sandstone_Brick"
    },
    {
      "x": -19,
      "y": -13,
      "z": -17,
      "name": "Rock_Sandstone_Brick"
    },
    {
      "x": -19,
      "y": -12,
      "z": -17,
      "name": "Rock_Sandstone_Cobble"
    },
    {
      "x": -19,
      "y": -11,
      "z": -17,
      "name": "Rock_Sandstone"
    },
    {
      "x": -19,
      "y": -35,
      "z": -16,
      "name": "Rock_Sandstone_Brick"
    },
    {
      "x": -19,
      "y": -34,
      "z": -16,
      "name": "Rock_Sandstone_Brick"
    },
    {
      "x": -19,
      "y": -33,
      "z": -16,
      "name": "Rock_Sandstone_Cobble"
    },
    {
      "x": -19,
      "y": -32,
      "z": -16,
      "name": "Rock_Sandstone"
    },
    {
      "x": -19,
      "y": -31,
      "z": -16,
      "name": "Rock_Sandstone"
    },
    {
      "x": -19,
      "y": -30,
      "z": -16,
      "name": "Rock_Sandstone_Brick"
    },
    {
      "x": -19,
      "y": -29,
      "z": -16,
      "name": "Rock_Sandstone"
    },
    {
      "x": -19,
      "y": -28,
      "z": -16,
      "name": "Rock_Sandstone"
    },
    {
      "x": -19,
      "y": -27,
      "z": -16,
      "name": "Rock_Sandstone"
    },
    {
      "x": -19,
      "y": -26,
      "z": -16,
      "name": "Rock_Sandstone_Cobble"
    },
    {
      "x": -19,
      "y": -25,
      "z": -16,
      "name": "Rock_Sandstone_Brick"
    },
    {
      "x": -19,
      "y": -24,
      "z": -16,
      "name": "Rock_Sandstone_Brick"
    },
    {
      "x": -19,
      "y": -23,
      "z": -16,
      "name": "Rock_Sandstone_Brick"
    },
    {
      "x": -19,
      "y": -22,
      "z": -16,
      "name": "Rock_Sandstone_Brick"
    },
    {
      "x": -19,
      "y": -21,
      "z": -16,
      "name": "Rock_Sandstone_Brick"
    },
    {
      "x": -19,
      "y": -20,
      "z": -16,
      "name": "Rock_Sandstone_Cobble"
    },
    {
      "x": -19,
      "y": -19,
      "z": -16,
      "name": "Rock_Sandstone_Brick"
    },
    {
      "x": -19,
      "y": -18,
      "z": -16,
      "name": "Rock_Sandstone"
    },
    {
      "x": -19,
      "y": -17,
      "z": -16,
      "name": "Rock_Sandstone_Brick"
    },
    {
      "x": -19,
      "y": -16,
      "z": -16,
      "name": "Rock_Sandstone_Brick"
    },
    {
      "x": -19,
      "y": -15,
      "z": -16,
      "name": "Rock_Sandstone"
    },
    {
      "x": -19,
      "y": -14,
      "z": -16,
      "name": "Rock_Sandstone_Brick"
    },
    {
      "x": -19,
      "y": -13,
      "z": -16,
      "name": "Rock_Sandstone_Brick"
    },
    {
      "x": -19,
      "y": 35,
      "z": -15,
      "name": "Soil_Clay_Ocean_Brick_Smooth"
    },
    {
      "x": -19,
      "y": 24,
      "z": -14,
      "name": "Rock_Sandstone_Cobble",
      "rotation": 3
    },
    {
      "x": -19,
      "y": 25,
      "z": -14,
      "name": "Soil_Clay"
    },
    {
      "x": -19,
      "y": 26,
      "z": -14,
      "name": "Rock_Sandstone_Red_Brick"
    },
    {
      "x": -19,
      "y": 27,
      "z": -14,
      "name": "Soil_Clay_Smooth_Orange"
    },
    {
      "x": -19,
      "y": 28,
      "z": -14,
      "name": "Rock_Sandstone_Red_Brick"
    },
    {
      "x": -19,
      "y": 29,
      "z": -14,
      "name": "Rock_Sandstone_Red_Brick"
    },
    {
      "x": -19,
      "y": 30,
      "z": -14,
      "name": "Soil_Clay_Smooth_Orange"
    },
    {
      "x": -19,
      "y": 31,
      "z": -14,
      "name": "Soil_Clay"
    },
    {
      "x": -19,
      "y": 32,
      "z": -14,
      "name": "Soil_Clay"
    },
    {
      "x": -19,
      "y": 33,
      "z": -14,
      "name": "Soil_Sand_Red"
    },
    {
      "x": -19,
      "y": 34,
      "z": -14,
      "name": "Soil_Clay_Smooth_Orange"
    },
    {
      "x": -19,
      "y": 35,
      "z": -14,
      "name": "Soil_Clay_Ocean_Brick_Smooth"
    },
    {
      "x": -19,
      "y": 36,
      "z": -14,
      "name": "Soil_Clay_Ocean_Brick"
    },
    {
      "x": -19,
      "y": 37,
      "z": -14,
      "name": "Soil_Clay_Ocean_Brick"
    },
    {
      "x": -19,
      "y": 22,
      "z": -13,
      "name": "Rock_Sandstone_Cobble",
      "rotation": 3
    },
    {
      "x": -19,
      "y": 23,
      "z": -13,
      "name": "Rock_Sandstone_Brick",
      "rotation": 3
    },
    {
      "x": -19,
      "y": 24,
      "z": -13,
      "name": "Rock_Sandstone_Brick",
      "rotation": 3
    },
    {
      "x": -19,
      "y": 25,
      "z": -13,
      "name": "Rock_Sandstone_Cobble",
      "rotation": 3
    },
    {
      "x": -19,
      "y": 26,
      "z": -13,
      "name": "Rock_Sandstone_Brick",
      "rotation": 3
    },
    {
      "x": -19,
      "y": 27,
      "z": -13,
      "name": "Rock_Sandstone_Red_Brick"
    },
    {
      "x": -19,
      "y": 28,
      "z": -13,
      "name": "Soil_Clay"
    },
    {
      "x": -19,
      "y": 29,
      "z": -13,
      "name": "Rock_Sandstone_Red_Brick"
    },
    {
      "x": -19,
      "y": 30,
      "z": -13,
      "name": "Rock_Sandstone_Red_Brick"
    },
    {
      "x": -19,
      "y": 31,
      "z": -13,
      "name": "Soil_Clay"
    },
    {
      "x": -19,
      "y": 32,
      "z": -13,
      "name": "Soil_Clay"
    },
    {
      "x": -19,
      "y": 33,
      "z": -13,
      "name": "Soil_Sand_Red"
    },
    {
      "x": -19,
      "y": 34,
      "z": -13,
      "name": "Soil_Sand_Red"
    },
    {
      "x": -19,
      "y": 35,
      "z": -13,
      "name": "Soil_Clay_Ocean_Brick_Smooth"
    },
    {
      "x": -19,
      "y": 36,
      "z": -13,
      "name": "Soil_Clay_Ocean_Brick_Smooth"
    },
    {
      "x": -19,
      "y": 37,
      "z": -13,
      "name": "Soil_Clay_Ocean_Brick"
    },
    {
      "x": -19,
      "y": 19,
      "z": -12,
      "name": "Rock_Sandstone_Brick",
      "rotation": 3
    },
    {
      "x": -19,
      "y": 20,
      "z": -12,
      "name": "Rock_Sandstone_Brick",
      "rotation": 3
    },
    {
      "x": -19,
      "y": 21,
      "z": -12,
      "name": "Rock_Sandstone_Brick",
      "rotation": 3
    },
    {
      "x": -19,
      "y": 22,
      "z": -12,
      "name": "Rock_Sandstone_Brick",
      "rotation": 3
    },
    {
      "x": -19,
      "y": 23,
      "z": -12,
      "name": "Rock_Sandstone_Brick",
      "rotation": 3
    },
    {
      "x": -19,
      "y": 24,
      "z": -12,
      "name": "Rock_Sandstone_Brick",
      "rotation": 3
    },
    {
      "x": -19,
      "y": 25,
      "z": -12,
      "name": "Rock_Sandstone_Brick",
      "rotation": 3
    },
    {
      "x": -19,
      "y": 26,
      "z": -12,
      "name": "Rock_Sandstone_Brick",
      "rotation": 3
    },
    {
      "x": -19,
      "y": 27,
      "z": -12,
      "name": "Soil_Clay"
    },
    {
      "x": -19,
      "y": 28,
      "z": -12,
      "name": "Soil_Clay_Smooth_Orange"
    },
    {
      "x": -19,
      "y": 29,
      "z": -12,
      "name": "Rock_Sandstone_Red_Brick"
    },
    {
      "x": -19,
      "y": 30,
      "z": -12,
      "name": "Soil_Clay"
    },
    {
      "x": -19,
      "y": 31,
      "z": -12,
      "name": "Soil_Clay"
    },
    {
      "x": -19,
      "y": 32,
      "z": -12,
      "name": "Soil_Clay_Smooth_Orange"
    },
    {
      "x": -19,
      "y": 33,
      "z": -12,
      "name": "Soil_Clay_Smooth_Orange"
    },
    {
      "x": -19,
      "y": 34,
      "z": -12,
      "name": "Soil_Sand_Red"
    },
    {
      "x": -19,
      "y": 35,
      "z": -12,
      "name": "Soil_Clay_Ocean_Brick_Smooth"
    },
    {
      "x": -19,
      "y": 36,
      "z": -12,
      "name": "Soil_Clay_Ocean_Brick"
    },
    {
      "x": -19,
      "y": 37,
      "z": -12,
      "name": "Soil_Clay_Ocean_Brick"
    },
    {
      "x": -19,
      "y": 38,
      "z": -12,
      "name": "Soil_Clay_Ocean_Brick"
    },
    {
      "x": -19,
      "y": 6,
      "z": -11,
      "name": "Rock_Sandstone_Brick",
      "rotation": 1
    },
    {
      "x": -19,
      "y": 7,
      "z": -11,
      "name": "Rock_Sandstone_Brick",
      "rotation": 1
    },
    {
      "x": -19,
      "y": 21,
      "z": -11,
      "name": "Rock_Sandstone_Cobble",
      "rotation": 3
    },
    {
      "x": -19,
      "y": 22,
      "z": -11,
      "name": "Rock_Sandstone_Brick",
      "rotation": 3
    },
    {
      "x": -19,
      "y": 23,
      "z": -11,
      "name": "Rock_Sandstone_Cobble",
      "rotation": 3
    },
    {
      "x": -19,
      "y": 24,
      "z": -11,
      "name": "Rock_Sandstone_Cobble",
      "rotation": 3
    },
    {
      "x": -19,
      "y": 25,
      "z": -11,
      "name": "Rock_Sandstone_Brick",
      "rotation": 3
    },
    {
      "x": -19,
      "y": 26,
      "z": -11,
      "name": "Rock_Sandstone_Brick",
      "rotation": 3
    },
    {
      "x": -19,
      "y": 27,
      "z": -11,
      "name": "Soil_Clay"
    },
    {
      "x": -19,
      "y": 28,
      "z": -11,
      "name": "Soil_Clay"
    },
    {
      "x": -19,
      "y": 29,
      "z": -11,
      "name": "Rock_Sandstone_Red_Brick"
    },
    {
      "x": -19,
      "y": 30,
      "z": -11,
      "name": "Rock_Sandstone_Red_Brick"
    },
    {
      "x": -19,
      "y": 31,
      "z": -11,
      "name": "Soil_Clay"
    },
    {
      "x": -19,
      "y": 32,
      "z": -11,
      "name": "Soil_Clay"
    },
    {
      "x": -19,
      "y": 33,
      "z": -11,
      "name": "Soil_Clay_Smooth_Orange"
    },
    {
      "x": -19,
      "y": 34,
      "z": -11,
      "name": "Soil_Sand_Red"
    },
    {
      "x": -19,
      "y": 35,
      "z": -11,
      "name": "Soil_Clay_Ocean_Brick"
    },
    {
      "x": -19,
      "y": 36,
      "z": -11,
      "name": "Soil_Clay_Ocean_Brick"
    },
    {
      "x": -19,
      "y": 37,
      "z": -11,
      "name": "Soil_Clay_Ocean_Brick_Smooth"
    },
    {
      "x": -19,
      "y": 38,
      "z": -11,
      "name": "Soil_Clay_Ocean_Brick_Smooth"
    },
    {
      "x": -19,
      "y": 4,
      "z": -10,
      "name": "Wood_Torch_Wall",
      "rotation": 1
    },
    {
      "x": -19,
      "y": 5,
      "z": -10,
      "name": "Rock_Sandstone_Brick",
      "rotation": 1
    },
    {
      "x": -19,
      "y": 6,
      "z": -10,
      "name": "Rock_Sandstone_Brick",
      "rotation": 1
    },
    {
      "x": -19,
      "y": 7,
      "z": -10,
      "name": "Rock_Sandstone_Brick",
      "rotation": 1
    },
    {
      "x": -19,
      "y": 8,
      "z": -10,
      "name": "Rock_Sandstone_Brick",
      "rotation": 1
    },
    {
      "x": -19,
      "y": 9,
      "z": -10,
      "name": "Rock_Sandstone_Brick",
      "rotation": 1
    },
    {
      "x": -19,
      "y": 10,
      "z": -10,
      "name": "Rock_Sandstone_Brick",
      "rotation": 1
    },
    {
      "x": -19,
      "y": 11,
      "z": -10,
      "name": "Rock_Sandstone_Brick",
      "rotation": 1
    },
    {
      "x": -19,
      "y": 12,
      "z": -10,
      "name": "Rock_Sandstone_Brick",
      "rotation": 1
    },
    {
      "x": -19,
      "y": 21,
      "z": -10,
      "name": "Rock_Sandstone_Brick",
      "rotation": 3
    },
    {
      "x": -19,
      "y": 22,
      "z": -10,
      "name": "Rock_Sandstone_Brick",
      "rotation": 3
    },
    {
      "x": -19,
      "y": 23,
      "z": -10,
      "name": "Rock_Sandstone_Cobble",
      "rotation": 3
    },
    {
      "x": -19,
      "y": 24,
      "z": -10,
      "name": "Rock_Sandstone_Brick",
      "rotation": 3
    },
    {
      "x": -19,
      "y": 25,
      "z": -10,
      "name": "Rock_Sandstone_Cobble",
      "rotation": 3
    },
    {
      "x": -19,
      "y": 26,
      "z": -10,
      "name": "Rock_Sandstone_Brick",
      "rotation": 3
    },
    {
      "x": -19,
      "y": 27,
      "z": -10,
      "name": "Rock_Sandstone_Cobble",
      "rotation": 3
    },
    {
      "x": -19,
      "y": 28,
      "z": -10,
      "name": "Rock_Sandstone_Brick",
      "rotation": 3
    },
    {
      "x": -19,
      "y": 29,
      "z": -10,
      "name": "Soil_Clay_Smooth_Orange"
    },
    {
      "x": -19,
      "y": 30,
      "z": -10,
      "name": "Soil_Clay_Smooth_Orange"
    },
    {
      "x": -19,
      "y": 31,
      "z": -10,
      "name": "Rock_Sandstone_Red_Brick"
    },
    {
      "x": -19,
      "y": 32,
      "z": -10,
      "name": "Soil_Clay_Smooth_Orange"
    },
    {
      "x": -19,
      "y": 33,
      "z": -10,
      "name": "Soil_Sand_Red"
    },
    {
      "x": -19,
      "y": 34,
      "z": -10,
      "name": "Soil_Sand_Red"
    },
    {
      "x": -19,
      "y": 35,
      "z": -10,
      "name": "Soil_Clay_Ocean_Brick"
    },
    {
      "x": -19,
      "y": 36,
      "z": -10,
      "name": "Soil_Clay_Ocean_Brick_Smooth"
    },
    {
      "x": -19,
      "y": 37,
      "z": -10,
      "name": "Soil_Clay_Ocean_Brick"
    },
    {
      "x": -19,
      "y": 38,
      "z": -10,
      "name": "Soil_Clay_Ocean_Brick"
    },
    {
      "x": -19,
      "y": 7,
      "z": -9,
      "name": "Rock_Sandstone_Brick",
      "rotation": 1
    },
    {
      "x": -19,
      "y": 8,
      "z": -9,
      "name": "Rock_Sandstone_Cobble",
      "rotation": 1
    },
    {
      "x": -19,
      "y": 9,
      "z": -9,
      "name": "Rock_Sandstone_Cobble",
      "rotation": 1
    },
    {
      "x": -19,
      "y": 10,
      "z": -9,
      "name": "Rock_Sandstone_Brick",
      "rotation": 1
    },
    {
      "x": -19,
      "y": 11,
      "z": -9,
      "name": "Rock_Sandstone_Brick",
      "rotation": 1
    },
    {
      "x": -19,
      "y": 12,
      "z": -9,
      "name": "Rock_Sandstone_Cobble",
      "rotation": 1
    },
    {
      "x": -19,
      "y": 16,
      "z": -9,
      "name": "Wood_Torch_Wall",
      "rotation": 1
    },
    {
      "x": -19,
      "y": 21,
      "z": -9,
      "name": "Rock_Sandstone_Brick",
      "rotation": 3
    },
    {
      "x": -19,
      "y": 22,
      "z": -9,
      "name": "Rock_Sandstone_Brick",
      "rotation": 3
    },
    {
      "x": -19,
      "y": 23,
      "z": -9,
      "name": "Rock_Sandstone_Cobble",
      "rotation": 3
    },
    {
      "x": -19,
      "y": 24,
      "z": -9,
      "name": "Rock_Sandstone_Brick",
      "rotation": 3
    },
    {
      "x": -19,
      "y": 25,
      "z": -9,
      "name": "Rock_Sandstone_Cobble",
      "rotation": 3
    },
    {
      "x": -19,
      "y": 26,
      "z": -9,
      "name": "Rock_Sandstone_Brick",
      "rotation": 3
    },
    {
      "x": -19,
      "y": 27,
      "z": -9,
      "name": "Rock_Sandstone_Brick",
      "rotation": 3
    },
    {
      "x": -19,
      "y": 28,
      "z": -9,
      "name": "Rock_Sandstone_Brick",
      "rotation": 3
    },
    {
      "x": -19,
      "y": 29,
      "z": -9,
      "name": "Rock_Sandstone_Red_Brick"
    },
    {
      "x": -19,
      "y": 30,
      "z": -9,
      "name": "Soil_Clay"
    },
    {
      "x": -19,
      "y": 31,
      "z": -9,
      "name": "Soil_Clay"
    },
    {
      "x": -19,
      "y": 32,
      "z": -9,
      "name": "Soil_Clay"
    },
    {
      "x": -19,
      "y": 33,
      "z": -9,
      "name": "Soil_Sand_Red"
    },
    {
      "x": -19,
      "y": 34,
      "z": -9,
      "name": "Soil_Sand_Red"
    },
    {
      "x": -19,
      "y": 35,
      "z": -9,
      "name": "Soil_Clay_Ocean_Brick_Smooth"
    },
    {
      "x": -19,
      "y": 36,
      "z": -9,
      "name": "Soil_Clay_Ocean_Brick_Smooth"
    },
    {
      "x": -19,
      "y": 37,
      "z": -9,
      "name": "Soil_Clay_Ocean_Brick"
    },
    {
      "x": -19,
      "y": 38,
      "z": -9,
      "name": "Soil_Clay_Ocean_Brick_Smooth"
    },
    {
      "x": -19,
      "y": -2,
      "z": -8,
      "name": "Rock_Sandstone_Brick"
    },
    {
      "x": -19,
      "y": -1,
      "z": -8,
      "name": "Rock_Sandstone_Brick"
    },
    {
      "x": -19,
      "y": 0,
      "z": -8,
      "name": "Rock_Sandstone_Brick"
    },
    {
      "x": -19,
      "y": 1,
      "z": -8,
      "name": "Rock_Sandstone_Cobble"
    },
    {
      "x": -19,
      "y": 7,
      "z": -8,
      "name": "Rock_Sandstone_Brick",
      "rotation": 1
    },
    {
      "x": -19,
      "y": 8,
      "z": -8,
      "name": "Rock_Sandstone_Cobble",
      "rotation": 1
    },
    {
