{
  "version": 8,
  "blockIdVersion": 11,
  "anchorX": 0,
  "anchorY": 0,
  "anchorZ": 0,
  "blocks": [
    {
      "x": -10,
      "y": 0,
      "z": -9,
      "name": "Rock_Sandstone_Brick"
    },
    {
      "x": -10,
      "y": 1,
      "z": -9,
      "name": "Rock_Sandstone_Brick"
    },
    {
      "x": -10,
      "y": 2,
      "z": -9,
      "name": "Rock_Sandstone_Brick"
    },
    {
      "x": -10,
      "y": 3,
      "z": -9,
      "name": "Rock_Sandstone_Brick"
    },
    {
      "x": -10,
      "y": 4,
      "z": -9,
      "name": "Rock_Sandstone"
    },
    {
      "x": -10,
      "y": 5,
      "z": -9,
      "name": "Rock_Sandstone_Brick"
    },
    {
      "x": -10,
      "y": 6,
      "z": -9,
      "name": "Rock_Sandstone_Brick"
    },
    {
      "x": -10,
      "y": 7,
      "z": -9,
      "name": "Rock_Sandstone_Brick"
    },
    {
      "x": -10,
      "y": 8,
      "z": -9,
      "name": "Rock_Sandstone"
    },
    {
      "x": -10,
      "y": 9,
      "z": -9,
      "name": "Rock_Sandstone_Brick"
    },
    {
      "x": -10,
      "y": 10,
      "z": -9,
      "name": "Rock_Sandstone_Brick",
      "rotation": 3
    },
    {
      "x": -10,
      "y": 11,
      "z": -9,
      "name": "Rock_Sandstone_Brick",
      "rotation": 3
    },
    {
      "x": -10,
      "y": 12,
      "z": -9,
      "name": "Rock_Sandstone_Brick",
      "rotation": 3
    },
    {
      "x": -10,
      "y": 13,
      "z": -9,
      "name": "Rock_Sandstone_Brick",
      "rotation": 3
    },
    {
      "x": -10,
      "y": 14,
      "z": -9,
      "name": "Rock_Sandstone",
      "rotation": 3
    },
    {
      "x": -10,
      "y": 15,
      "z": -9,
      "name": "Rock_Sandstone_Brick",
      "rotation": 3
    },
    {
      "x": -10,
      "y": 16,
      "z": -9,
      "name": "Rock_Sandstone_Brick",
      "rotation": 3
    },
    {
      "x": -10,
      "y": 17,
      "z": -9,
      "name": "Rock_Sandstone_Brick",
      "rotation": 3
    },
    {
      "x": -10,
      "y": 18,
      "z": -9,
      "name": "Rock_Sandstone_Brick",
      "rotation": 3
    },
    {
      "x": -10,
      "y": 19,
      "z": -9,
      "name": "Rock_Sandstone_Brick",
      "rotation": 3
    },
    {
      "x": -10,
      "y": 20,
      "z": -9,
      "name": "Rock_Sandstone",
      "rotation": 3
    },
    {
      "x": -10,
      "y": 21,
      "z": -9,
      "name": "Rock_Sandstone_Brick",
      "rotation": 3
    },
    {
      "x": -10,
      "y": 22,
      "z": -9,
      "name": "Rock_Sandstone_Brick",
      "rotation": 3
    },
    {
      "x": -10,
      "y": 23,
      "z": -9,
      "name": "Rock_Sandstone_Brick",
      "rotation": 3
    },
    {
      "x": -10,
      "y": 0,
      "z": -8,
      "name": "Rock_Sandstone_Cobble"
    },
    {
      "x": -10,
      "y": 1,
      "z": -8,
      "name": "Rock_Sandstone_Brick"
    },
    {
      "x": -10,
      "y": 2,
      "z": -8,
      "name": "Rock_Sandstone_Brick"
    },
    {
      "x": -10,
      "y": 3,
      "z": -8,
      "name": "Rock_Sandstone_Brick"
    },
    {
      "x": -10,
      "y": 4,
      "z": -8,
      "name": "Rock_Sandstone_Brick"
    },
    {
      "x": -10,
      "y": 5,
      "z": -8,
      "name": "Rock_Sandstone_Brick"
    },
    {
      "x": -10,
      "y": 6,
      "z": -8,
      "name": "Rock_Sandstone"
    },
    {
      "x": -10,
      "y": 7,
      "z": -8,
      "name": "Rock_Sandstone_Cobble"
    },
    {
      "x": -10,
      "y": 8,
      "z": -8,
      "name": "Rock_Sandstone_Brick"
    },
    {
      "x": -10,
      "y": 9,
      "z": -8,
      "name": "Rock_Sandstone_Cobble"
    },
    {
      "x": -10,
      "y": 10,
      "z": -8,
      "name": "Rock_Sandstone_Brick",
      "rotation": 3
    },
    {
      "x": -10,
      "y": 11,
      "z": -8,
      "name": "Rock_Sandstone_Brick",
      "rotation": 3
    },
    {
      "x": -10,
      "y": 12,
      "z": -8,
      "name": "Rock_Sandstone_Brick",
      "rotation": 3
    },
    {
      "x": -10,
      "y": 13,
      "z": -8,
      "name": "Rock_Sandstone_Brick",
      "rotation": 3
    },
    {
      "x": -10,
      "y": 14,
      "z": -8,
      "name": "Rock_Sandstone_Brick",
      "rotation": 3
    },
    {
      "x": -10,
      "y": 15,
      "z": -8,
      "name": "Rock_Sandstone",
      "rotation": 3
    },
    {
      "x": -10,
      "y": 16,
      "z": -8,
      "name": "Rock_Sandstone_Brick",
      "rotation": 3
    },
    {
      "x": -10,
      "y": 17,
      "z": -8,
      "name": "Rock_Sandstone_Brick",
      "rotation": 3
    },
    {
      "x": -10,
      "y": 18,
      "z": -8,
      "name": "Rock_Sandstone",
      "rotation": 3
    },
    {
      "x": -10,
      "y": 19,
      "z": -8,
      "name": "Rock_Sandstone_Brick",
      "rotation": 3
    },
    {
      "x": -10,
      "y": 20,
      "z": -8,
      "name": "Rock_Sandstone_Brick",
      "rotation": 3
    },
    {
      "x": -10,
      "y": 21,
      "z": -8,
      "name": "Rock_Sandstone",
      "rotation": 3
    },
    {
      "x": -10,
      "y": 22,
      "z": -8,
      "name": "Rock_Sandstone_Brick",
      "rotation": 3
    },
    {
      "x": -10,
      "y": 23,
      "z": -8,
      "name": "Rock_Sandstone_Cobble",
      "rotation": 3
    },
    {
      "x": -10,
      "y": 24,
      "z": -8,
      "name": "Rock_Sandstone_Brick",
      "rotation": 3
    },
    {
      "x": -10,
      "y": 0,
      "z": -7,
      "name": "Rock_Sandstone_Brick"
    },
    {
      "x": -10,
      "y": 1,
      "z": -7,
      "name": "Rock_Sandstone_Brick"
    },
    {
      "x": -10,
      "y": 2,
      "z": -7,
      "name": "Rock_Sandstone_Brick"
    },
    {
      "x": -10,
      "y": 3,
      "z": -7,
      "name": "Rock_Sandstone"
    },
    {
      "x": -10,
      "y": 4,
      "z": -7,
      "name": "Rock_Sandstone_Cobble"
    },
    {
      "x": -10,
      "y": 5,
      "z": -7,
      "name": "Rock_Sandstone_Brick"
    },
    {
      "x": -10,
      "y": 6,
      "z": -7,
      "name": "Rock_Sandstone_Brick"
    },
    {
      "x": -10,
      "y": 7,
      "z": -7,
      "name": "Rock_Sandstone"
    },
    {
      "x": -10,
      "y": 8,
      "z": -7,
      "name": "Rock_Sandstone_Brick"
    },
    {
      "x": -10,
      "y": 9,
      "z": -7,
      "name": "Rock_Sandstone_Cobble"
    },
    {
      "x": -10,
      "y": 10,
      "z": -7,
      "name": "Rock_Sandstone",
      "rotation": 3
    },
    {
      "x": -10,
      "y": 11,
      "z": -7,
      "name": "Rock_Sandstone_Brick",
      "rotation": 3
    },
    {
      "x": -10,
      "y": 12,
      "z": -7,
      "name": "Rock_Sandstone_Brick",
      "rotation": 3
    },
    {
      "x": -10,
      "y": 13,
      "z": -7,
      "name": "Rock_Sandstone_Brick",
      "rotation": 3
    },
    {
      "x": -10,
      "y": 14,
      "z": -7,
      "name": "Rock_Sandstone_Brick",
      "rotation": 3
    },
    {
      "x": -10,
      "y": 15,
      "z": -7,
      "name": "Rock_Sandstone_Cobble",
      "rotation": 3
    },
    {
      "x": -10,
      "y": 16,
      "z": -7,
      "name": "Rock_Sandstone_Brick",
      "rotation": 3
    },
    {
      "x": -10,
      "y": 17,
      "z": -7,
      "name": "Rock_Sandstone_Brick",
      "rotation": 3
    },
    {
      "x": -10,
      "y": 18,
      "z": -7,
      "name": "Rock_Sandstone",
      "rotation": 3
    },
    {
      "x": -10,
      "y": 19,
      "z": -7,
      "name": "Rock_Sandstone_Brick",
      "rotation": 3
    },
    {
      "x": -10,
      "y": 20,
      "z": -7,
      "name": "Rock_Sandstone_Brick",
      "rotation": 3
    },
    {
      "x": -10,
      "y": 21,
      "z": -7,
      "name": "Rock_Sandstone_Cobble",
      "rotation": 3
    },
    {
      "x": -10,
      "y": 35,
      "z": 5,
      "name": "Rock_Sandstone_Brick"
    },
    {
      "x": -10,
      "y": 35,
      "z": 6,
      "name": "Rock_Sandstone_Brick"
    },
    {
      "x": -10,
      "y": 30,
      "z": 7,
      "name": "Rock_Sandstone_Brick_Stairs",
      "rotation": 8
    },
    {
      "x": -10,
      "y": 31,
      "z": 7,
      "name": "Rock_Sandstone_Brick"
    },
    {
      "x": -10,
      "y": 32,
      "z": 7,
      "name": "Rock_Sandstone"
    },
    {
      "x": -10,
      "y": 33,
      "z": 7,
      "name": "Rock_Sandstone_Brick"
    },
    {
      "x": -10,
      "y": 34,
      "z": 7,
      "name": "Rock_Sandstone_Brick"
    },
    {
      "x": -10,
      "y": 35,
      "z": 7,
      "name": "Rock_Sandstone_Brick"
    },
    {
      "x": -10,
      "y": 0,
      "z": 8,
      "name": "Rock_Sandstone_Brick"
    },
    {
      "x": -10,
      "y": 1,
      "z": 8,
      "name": "Rock_Sandstone_Brick"
    },
    {
      "x": -10,
      "y": 2,
      "z": 8,
      "name": "Rock_Sandstone_Cobble"
    },
    {
      "x": -10,
      "y": 3,
      "z": 8,
      "name": "Rock_Sandstone_Brick"
    },
    {
      "x": -10,
      "y": 4,
      "z": 8,
      "name": "Rock_Sandstone_Brick"
    },
    {
      "x": -10,
      "y": 5,
      "z": 8,
      "name": "Rock_Sandstone_Brick"
    },
    {
      "x": -10,
      "y": 6,
      "z": 8,
      "name": "Rock_Sandstone_Brick"
    },
    {
      "x": -10,
      "y": 7,
      "z": 8,
      "name": "Rock_Sandstone_Brick"
    },
    {
      "x": -10,
      "y": 8,
      "z": 8,
      "name": "Rock_Sandstone_Cobble"
    },
    {
      "x": -10,
      "y": 9,
      "z": 8,
      "name": "Rock_Sandstone_Brick"
    },
    {
      "x": -10,
      "y": 10,
      "z": 8,
      "name": "Rock_Sandstone_Brick"
    },
    {
      "x": -10,
      "y": 11,
      "z": 8,
      "name": "Rock_Sandstone",
      "rotation": 1
    },
    {
      "x": -10,
      "y": 12,
      "z": 8,
      "name": "Rock_Sandstone_Brick",
      "rotation": 1
    },
    {
      "x": -10,
      "y": 13,
      "z": 8,
      "name": "Rock_Sandstone",
      "rotation": 1
    },
    {
      "x": -10,
      "y": 14,
      "z": 8,
      "name": "Rock_Sandstone_Brick",
      "rotation": 1
    },
    {
      "x": -10,
      "y": 15,
      "z": 8,
      "name": "Rock_Sandstone",
      "rotation": 1
    },
    {
      "x": -10,
      "y": 16,
      "z": 8,
      "name": "Rock_Sandstone",
      "rotation": 1
    },
    {
      "x": -10,
      "y": 17,
      "z": 8,
      "name": "Rock_Sandstone_Brick",
      "rotation": 1
    },
    {
      "x": -10,
      "y": 18,
      "z": 8,
      "name": "Rock_Sandstone_Brick",
      "rotation": 1
    },
    {
      "x": -10,
      "y": 19,
      "z": 8,
      "name": "Rock_Sandstone_Brick",
      "rotation": 1
    },
    {
      "x": -10,
      "y": 20,
      "z": 8,
      "name": "Rock_Sandstone_Cobble",
      "rotation": 1
    },
    {
      "x": -10,
      "y": 21,
      "z": 8,
      "name": "Rock_Sandstone_Brick",
      "rotation": 1
    },
    {
      "x": -10,
      "y": 22,
      "z": 8,
      "name": "Rock_Sandstone_Brick",
      "rotation": 1
    },
    {
      "x": -10,
      "y": 23,
      "z": 8,
      "name": "Rock_Sandstone_Cobble",
      "rotation": 1
    },
    {
      "x": -10,
      "y": 24,
      "z": 8,
      "name": "Rock_Sandstone_Brick",
      "rotation": 1
    },
    {
      "x": -10,
      "y": 25,
      "z": 8,
      "name": "Rock_Sandstone_Cobble",
      "rotation": 1
    },
    {
      "x": -10,
      "y": 26,
      "z": 8,
      "name": "Rock_Sandstone_Brick",
      "rotation": 1
    },
    {
      "x": -10,
      "y": 27,
      "z": 8,
      "name": "Rock_Sandstone_Brick",
      "rotation": 1
    },
    {
      "x": -10,
      "y": 28,
      "z": 8,
      "name": "Rock_Sandstone_Brick",
      "rotation": 1
    },
    {
      "x": -10,
      "y": 29,
      "z": 8,
      "name": "Rock_Sandstone_Brick",
      "rotation": 1
    },
    {
      "x": -10,
      "y": 30,
      "z": 8,
      "name": "Rock_Sandstone_Brick",
      "rotation": 1
    },
    {
      "x": -10,
      "y": 31,
      "z": 8,
      "name": "Rock_Sandstone_Brick",
      "rotation": 1
    },
    {
      "x": -10,
      "y": 32,
      "z": 8,
      "name": "Rock_Sandstone",
      "rotation": 1
    },
    {
      "x": -10,
      "y": 33,
      "z": 8,
      "name": "Rock_Sandstone_Brick",
      "rotation": 1
    },
    {
      "x": -10,
      "y": 34,
      "z": 8,
      "name": "Rock_Sandstone_Brick",
      "rotation": 1
    },
    {
      "x": -10,
      "y": 35,
      "z": 8,
      "name": "Rock_Sandstone_Brick"
    },
    {
      "x": -10,
      "y": 0,
      "z": 9,
      "name": "Rock_Sandstone_Brick"
    },
    {
      "x": -10,
      "y": 1,
      "z": 9,
      "name": "Rock_Sandstone_Brick"
    },
    {
      "x": -10,
      "y": 2,
      "z": 9,
      "name": "Rock_Sandstone_Brick"
    },
    {
      "x": -10,
      "y": 3,
      "z": 9,
      "name": "Rock_Sandstone_Brick"
    },
    {
      "x": -10,
      "y": 4,
      "z": 9,
      "name": "Rock_Sandstone_Brick"
    },
    {
      "x": -10,
      "y": 5,
      "z": 9,
      "name": "Rock_Sandstone_Brick"
    },
    {
      "x": -10,
      "y": 6,
      "z": 9,
      "name": "Rock_Sandstone_Brick"
    },
    {
      "x": -10,
      "y": 7,
      "z": 9,
      "name": "Rock_Sandstone"
    },
    {
      "x": -10,
      "y": 8,
      "z": 9,
      "name": "Rock_Sandstone_Brick"
    },
    {
      "x": -10,
      "y": 9,
      "z": 9,
      "name": "Rock_Sandstone_Cobble"
    },
    {
      "x": -10,
      "y": 10,
      "z": 9,
      "name": "Rock_Sandstone_Brick"
    },
    {
      "x": -10,
      "y": 11,
      "z": 9,
      "name": "Rock_Sandstone_Brick",
      "rotation": 1
    },
    {
      "x": -10,
      "y": 12,
      "z": 9,
      "name": "Rock_Sandstone_Brick",
      "rotation": 1
    },
    {
      "x": -10,
      "y": 13,
      "z": 9,
      "name": "Rock_Sandstone_Brick",
      "rotation": 1
    },
    {
      "x": -10,
      "y": 14,
      "z": 9,
      "name": "Rock_Sandstone_Brick",
      "rotation": 1
    },
    {
      "x": -10,
      "y": 15,
      "z": 9,
      "name": "Rock_Sandstone_Brick",
      "rotation": 1
    },
    {
      "x": -10,
      "y": 16,
      "z": 9,
      "name": "Rock_Sandstone",
      "rotation": 1
    },
    {
      "x": -10,
      "y": 17,
      "z": 9,
      "name": "Rock_Sandstone_Cobble",
      "rotation": 1
    },
    {
      "x": -10,
      "y": 18,
      "z": 9,
      "name": "Rock_Sandstone_Cobble",
      "rotation": 1
    },
    {
      "x": -10,
      "y": 19,
      "z": 9,
      "name": "Rock_Sandstone_Brick",
      "rotation": 1
    },
    {
      "x": -10,
      "y": 20,
      "z": 9,
      "name": "Rock_Sandstone_Cobble",
      "rotation": 1
    },
    {
      "x": -10,
      "y": 21,
      "z": 9,
      "name": "Rock_Sandstone_Brick",
      "rotation": 1
    },
    {
      "x": -10,
      "y": 22,
      "z": 9,
      "name": "Rock_Sandstone_Brick",
      "rotation": 1
    },
    {
      "x": -10,
      "y": 23,
      "z": 9,
      "name": "Rock_Sandstone",
      "rotation": 1
    },
    {
      "x": -10,
      "y": 24,
      "z": 9,
      "name": "Rock_Sandstone_Brick",
      "rotation": 1
    },
    {
      "x": -10,
      "y": 25,
      "z": 9,
      "name": "Rock_Sandstone_Brick",
      "rotation": 1
    },
    {
      "x": -10,
      "y": 26,
      "z": 9,
      "name": "Rock_Sandstone_Cobble",
      "rotation": 1
    },
    {
      "x": -10,
      "y": 27,
      "z": 9,
      "name": "Rock_Sandstone_Brick",
      "rotation": 1
    },
    {
      "x": -10,
      "y": 28,
      "z": 9,
      "name": "Rock_Sandstone_Brick",
      "rotation": 1
    },
    {
      "x": -10,
      "y": 29,
      "z": 9,
      "name": "Rock_Sandstone",
      "rotation": 1
    },
    {
      "x": -10,
      "y": 30,
      "z": 9,
      "name": "Rock_Sandstone_Cobble",
      "rotation": 1
    },
    {
      "x": -10,
      "y": 31,
      "z": 9,
      "name": "Rock_Sandstone_Brick",
      "rotation": 1
    },
    {
      "x": -10,
      "y": 32,
      "z": 9,
      "name": "Rock_Sandstone_Brick",
      "rotation": 1
    },
    {
      "x": -10,
      "y": 33,
      "z": 9,
      "name": "Rock_Sandstone_Brick",
      "rotation": 1
    },
    {
      "x": -10,
      "y": 34,
      "z": 9,
      "name": "Rock_Sandstone_Brick",
      "rotation": 1
    },
    {
      "x": -10,
      "y": 35,
      "z": 9,
      "name": "Rock_Sandstone_Brick"
    },
    {
      "x": -10,
      "y": 0,
      "z": 10,
      "name": "Rock_Sandstone"
    },
    {
      "x": -10,
      "y": 1,
      "z": 10,
      "name": "Rock_Sandstone_Cobble"
    },
    {
      "x": -10,
      "y": 2,
      "z": 10,
      "name": "Rock_Sandstone_Brick"
    },
    {
      "x": -10,
      "y": 3,
      "z": 10,
      "name": "Rock_Sandstone_Brick"
    },
    {
      "x": -10,
      "y": 4,
      "z": 10,
      "name": "Rock_Sandstone_Brick"
    },
    {
      "x": -10,
      "y": 5,
      "z": 10,
      "name": "Rock_Sandstone_Brick"
    },
    {
      "x": -10,
      "y": 6,
      "z": 10,
      "name": "Rock_Sandstone_Brick"
    },
    {
      "x": -10,
      "y": 7,
      "z": 10,
      "name": "Rock_Sandstone_Cobble"
    },
    {
      "x": -10,
      "y": 8,
      "z": 10,
      "name": "Rock_Sandstone_Brick"
    },
    {
      "x": -10,
      "y": 9,
      "z": 10,
      "name": "Rock_Sandstone_Brick"
    },
    {
      "x": -10,
      "y": 10,
      "z": 10,
      "name": "Rock_Sandstone_Cobble"
    },
    {
      "x": -10,
      "y": 11,
      "z": 10,
      "name": "Rock_Sandstone_Brick",
      "rotation": 1
    },
    {
      "x": -10,
      "y": 12,
      "z": 10,
      "name": "Rock_Sandstone_Brick",
      "rotation": 1
    },
    {
      "x": -10,
      "y": 13,
      "z": 10,
      "name": "Rock_Sandstone_Brick",
      "rotation": 1
    },
    {
      "x": -10,
      "y": 14,
      "z": 10,
      "name": "Rock_Sandstone",
      "rotation": 1
    },
    {
      "x": -10,
      "y": 15,
      "z": 10,
      "name": "Rock_Sandstone_Brick",
      "rotation": 1
    },
    {
      "x": -10,
      "y": 16,
      "z": 10,
      "name": "Rock_Sandstone_Brick",
      "rotation": 1
    },
    {
      "x": -10,
      "y": 17,
      "z": 10,
      "name": "Rock_Sandstone",
      "rotation": 1
    },
    {
      "x": -10,
      "y": 18,
      "z": 10,
      "name": "Rock_Sandstone_Brick",
      "rotation": 1
    },
    {
      "x": -10,
      "y": 19,
      "z": 10,
      "name": "Rock_Sandstone",
      "rotation": 1
    },
    {
      "x": -10,
      "y": 20,
      "z": 10,
      "name": "Rock_Sandstone_Brick",
      "rotation": 1
    },
    {
      "x": -10,
      "y": 21,
      "z": 10,
      "name": "Rock_Sandstone",
      "rotation": 1
    },
    {
      "x": -10,
      "y": 22,
      "z": 10,
      "name": "Rock_Sandstone_Brick",
      "rotation": 1
    },
    {
      "x": -10,
      "y": 23,
      "z": 10,
      "name": "Rock_Sandstone_Brick",
      "rotation": 1
    },
    {
      "x": -10,
      "y": 24,
      "z": 10,
      "name": "Rock_Sandstone_Brick",
      "rotation": 1
    },
    {
      "x": -10,
      "y": 25,
      "z": 10,
      "name": "Rock_Sandstone_Brick",
      "rotation": 1
    },
    {
      "x": -10,
      "y": 26,
      "z": 10,
      "name": "Rock_Sandstone",
      "rotation": 1
    },
    {
      "x": -10,
      "y": 27,
      "z": 10,
      "name": "Rock_Sandstone_Brick",
      "rotation": 1
    },
    {
      "x": -10,
      "y": 28,
      "z": 10,
      "name": "Rock_Sandstone_Brick",
      "rotation": 1
    },
    {
      "x": -10,
      "y": 29,
      "z": 10,
      "name": "Rock_Sandstone_Brick",
      "rotation": 1
    },
    {
      "x": -10,
      "y": 30,
      "z": 10,
      "name": "Rock_Sandstone_Brick",
      "rotation": 1
    },
    {
      "x": -10,
      "y": 31,
      "z": 10,
      "name": "Rock_Sandstone_Brick",
      "rotation": 1
    },
    {
      "x": -10,
      "y": 32,
      "z": 10,
      "name": "Rock_Sandstone_Brick",
      "rotation": 1
    },
    {
      "x": -10,
      "y": 33,
      "z": 10,
      "name": "Rock_Sandstone_Brick",
      "rotation": 1
    },
    {
      "x": -10,
      "y": 34,
      "z": 10,
      "name": "Rock_Sandstone_Brick",
      "rotation": 1
    },
    {
      "x": -10,
      "y": 35,
      "z": 10,
      "name": "Rock_Sandstone_Brick"
    },
    {
      "x": -9,
      "y": 0,
      "z": -10,
      "name": "Rock_Sandstone_Cobble"
    },
    {
      "x": -9,
      "y": 1,
      "z": -10,
      "name": "Rock_Sandstone"
    },
    {
      "x": -9,
      "y": 2,
      "z": -10,
      "name": "Rock_Sandstone_Brick"
    },
    {
      "x": -9,
      "y": 3,
      "z": -10,
      "name": "Rock_Sandstone_Brick"
    },
    {
      "x": -9,
      "y": 4,
      "z": -10,
      "name": "Rock_Sandstone"
    },
    {
      "x": -9,
      "y": 5,
      "z": -10,
      "name": "Rock_Sandstone_Brick"
    },
    {
      "x": -9,
      "y": 6,
      "z": -10,
      "name": "Rock_Sandstone_Brick"
    },
    {
      "x": -9,
      "y": 7,
      "z": -10,
      "name": "Rock_Sandstone_Brick"
    },
    {
      "x": -9,
      "y": 8,
      "z": -10,
      "name": "Rock_Sandstone"
    },
    {
      "x": -9,
      "y": 9,
      "z": -10,
      "name": "Rock_Sandstone_Cobble"
    },
    {
      "x": -9,
      "y": 10,
      "z": -10,
      "name": "Rock_Sandstone_Brick"
    },
    {
      "x": -9,
      "y": 11,
      "z": -10,
      "name": "Rock_Sandstone_Brick"
    },
    {
      "x": -9,
      "y": 12,
      "z": -10,
      "name": "Rock_Sandstone_Brick"
    },
    {
      "x": -9,
      "y": 13,
      "z": -10,
      "name": "Rock_Sandstone"
    },
    {
      "x": -9,
      "y": 14,
      "z": -10,
      "name": "Rock_Sandstone_Brick"
    },
    {
      "x": -9,
      "y": 15,
      "z": -10,
      "name": "Rock_Sandstone_Brick"
    },
    {
      "x": -9,
      "y": 16,
      "z": -10,
      "name": "Rock_Sandstone_Brick"
    },
    {
      "x": -9,
      "y": 17,
      "z": -10,
      "name": "Rock_Sandstone_Brick"
    },
    {
      "x": -9,
      "y": 18,
      "z": -10,
      "name": "Rock_Sandstone_Brick"
    },
    {
      "x": -9,
      "y": 19,
      "z": -10,
      "name": "Rock_Sandstone_Cobble"
    },
    {
      "x": -9,
      "y": 20,
      "z": -10,
      "name": "Rock_Sandstone_Cobble"
    },
    {
      "x": -9,
      "y": 21,
      "z": -10,
      "name": "Rock_Sandstone_Brick"
    },
    {
      "x": -9,
      "y": 22,
      "z": -10,
      "name": "Rock_Sandstone_Brick"
    },
    {
      "x": -9,
      "y": 23,
      "z": -10,
      "name": "Rock_Sandstone"
    },
    {
      "x": -9,
      "y": 24,
      "z": -10,
      "name": "Rock_Sandstone_Brick"
    },
    {
      "x": -9,
      "y": 0,
      "z": -9,
      "name": "Rock_Sandstone_Brick"
    },
    {
      "x": -9,
      "y": 1,
      "z": -9,
      "name": "Rock_Sandstone_Brick"
    },
    {
      "x": -9,
      "y": 2,
      "z": -9,
      "name": "Rock_Sandstone_Brick"
    },
    {
      "x": -9,
      "y": 3,
      "z": -9,
      "name": "Rock_Sandstone_Cobble"
    },
    {
      "x": -9,
      "y": 4,
      "z": -9,
      "name": "Rock_Sandstone"
    },
    {
      "x": -9,
      "y": 5,
      "z": -9,
      "name": "Rock_Sandstone_Brick"
    },
    {
      "x": -9,
      "y": 6,
      "z": -9,
      "name": "Rock_Sandstone"
    },
    {
      "x": -9,
      "y": 7,
      "z": -9,
      "name": "Rock_Sandstone_Brick"
    },
    {
      "x": -9,
      "y": 8,
      "z": -9,
      "name": "Rock_Sandstone_Brick"
    },
    {
      "x": -9,
      "y": 9,
      "z": -9,
      "name": "Rock_Sandstone"
    },
    {
      "x": -9,
      "y": 10,
      "z": -9,
      "name": "Rock_Sandstone_Brick",
      "rotation": 3
    },
    {
      "x": -9,
      "y": 11,
      "z": -9,
      "name": "Rock_Sandstone_Brick",
      "rotation": 3
    },
    {
      "x": -9,
      "y": 12,
      "z": -9,
      "name": "Rock_Sandstone_Cobble",
      "rotation": 3
    },
    {
      "x": -9,
      "y": 13,
      "z": -9,
      "name": "Rock_Sandstone_Brick",
      "rotation": 3
    },
    {
      "x": -9,
      "y": 14,
      "z": -9,
      "name": "Rock_Sandstone_Brick",
      "rotation": 3
    },
    {
      "x": -9,
      "y": 15,
      "z": -9,
      "name": "Rock_Sandstone_Brick",
      "rotation": 3
    },
    {
      "x": -9,
      "y": 16,
      "z": -9,
      "name": "Rock_Sandstone_Brick",
      "rotation": 3
    },
    {
      "x": -9,
      "y": 17,
      "z": -9,
      "name": "Rock_Sandstone_Brick",
      "rotation": 3
    },
    {
      "x": -9,
      "y": 18,
      "z": -9,
      "name": "Rock_Sandstone_Brick",
      "rotation": 3
    },
    {
      "x": -9,
      "y": 19,
      "z": -9,
      "name": "Rock_Sandstone_Brick",
      "rotation": 3
    },
    {
      "x": -9,
      "y": 20,
      "z": -9,
      "name": "Rock_Sandstone_Brick",
      "rotation": 3
    },
    {
      "x": -9,
      "y": 21,
      "z": -9,
      "name": "Rock_Sandstone_Brick",
      "rotation": 3
    },
    {
      "x": -9,
      "y": 22,
      "z": -9,
      "name": "Rock_Sandstone_Brick",
      "rotation": 3
    },
    {
      "x": -9,
      "y": 23,
      "z": -9,
      "name": "Rock_Sandstone_Brick",
      "rotation": 3
    },
    {
      "x": -9,
      "y": 24,
      "z": -9,
      "name": "Rock_Sandstone_Brick",
      "rotation": 3
    },
    {
      "x": -9,
      "y": 0,
      "z": -8,
      "name": "Rock_Sandstone_Cobble"
    },
    {
      "x": -9,
      "y": 1,
      "z": -8,
      "name": "Rock_Sandstone"
    },
    {
      "x": -9,
      "y": 2,
      "z": -8,
      "name": "Rock_Sandstone_Brick"
    },
    {
      "x": -9,
      "y": 3,
      "z": -8,
      "name": "Rock_Sandstone_Brick"
    },
    {
      "x": -9,
      "y": 4,
      "z": -8,
      "name": "Rock_Sandstone_Brick"
    },
    {
      "x": -9,
      "y": 5,
      "z": -8,
      "name": "Rock_Sandstone_Brick"
    },
    {
      "x": -9,
      "y": 6,
      "z": -8,
      "name": "Rock_Sandstone"
    },
    {
      "x": -9,
      "y": 7,
      "z": -8,
      "name": "Rock_Sandstone"
    },
    {
      "x": -9,
      "y": 8,
      "z": -8,
      "name": "Rock_Sandstone_Cobble"
    },
    {
      "x": -9,
      "y": 9,
      "z": -8,
      "name": "Rock_Sandstone"
    },
    {
      "x": -9,
      "y": 10,
      "z": -8,
      "name": "Rock_Sandstone_Brick",
      "rotation": 3
    },
    {
      "x": -9,
      "y": 11,
      "z": -8,
      "name": "Rock_Sandstone_Cobble",
      "rotation": 3
    },
    {
      "x": -9,
      "y": 12,
      "z": -8,
      "name": "Rock_Sandstone_Brick",
      "rotation": 3
    },
    {
      "x": -9,
      "y": 13,
      "z": -8,
      "name": "Rock_Sandstone_Cobble",
      "rotation": 3
    },
    {
      "x": -9,
      "y": 14,
      "z": -8,
      "name": "Rock_Sandstone_Cobble",
      "rotation": 3
    },
    {
      "x": -9,
      "y": 15,
      "z": -8,
      "name": "Rock_Sandstone_Brick",
      "rotation": 3
    },
    {
      "x": -9,
      "y": 16,
      "z": -8,
      "name": "Rock_Sandstone_Brick",
      "rotation": 3
    },
    {
      "x": -9,
      "y": 17,
      "z": -8,
      "name": "Rock_Sandstone_Brick",
      "rotation": 3
    },
    {
      "x": -9,
      "y": 18,
      "z": -8,
      "name": "Rock_Sandstone_Brick",
      "rotation": 3
    },
    {
      "x": -9,
      "y": 19,
      "z": -8,
      "name": "Rock_Sandstone_Brick",
      "rotation": 3
    },
    {
      "x": -9,
      "y": 20,
      "z": -8,
      "name": "Rock_Sandstone_Brick",
      "rotation": 3
    },
    {
      "x": -9,
      "y": 21,
      "z": -8,
      "name": "Rock_Sandstone",
      "rotation": 3
    },
    {
      "x": -9,
      "y": 22,
      "z": -8,
      "name": "Rock_Sandstone_Brick",
      "rotation": 3
    },
    {
      "x": -9,
      "y": 23,
      "z": -8,
      "name": "Rock_Sandstone_Brick",
      "rotation": 3
    },
    {
      "x": -9,
      "y": 24,
      "z": -8,
      "name": "Rock_Sandstone",
      "rotation": 3
    },
    {
      "x": -9,
      "y": 25,
      "z": -8,
      "name": "Rock_Sandstone_Cobble",
      "rotation": 3
    },
    {
      "x": -9,
      "y": 26,
      "z": -8,
      "name": "Rock_Sandstone_Brick",
      "rotation": 3
    },
    {
      "x": -9,
      "y": 0,
      "z": -7,
      "name": "Rock_Sandstone_Brick"
    },
    {
      "x": -9,
      "y": 1,
      "z": -7,
      "name": "Rock_Sandstone_Brick"
    },
    {
      "x": -9,
      "y": 2,
      "z": -7,
      "name": "Rock_Sandstone_Brick"
    },
    {
      "x": -9,
      "y": 3,
      "z": -7,
      "name": "Rock_Sandstone_Brick"
    },
    {
      "x": -9,
      "y": 4,
      "z": -7,
      "name": "Rock_Sandstone_Brick"
    },
    {
      "x": -9,
      "y": 5,
      "z": -7,
      "name": "Rock_Sandstone"
    },
    {
      "x": -9,
      "y": 6,
      "z": -7,
      "name": "Rock_Sandstone_Brick"
    },
    {
      "x": -9,
      "y": 7,
      "z": -7,
      "name": "Rock_Sandstone"
    },
    {
      "x": -9,
      "y": 8,
      "z": -7,
      "name": "Rock_Sandstone"
    },
    {
      "x": -9,
      "y": 9,
      "z": -7,
      "name": "Rock_Sandstone_Brick"
    },
    {
      "x": -9,
      "y": 10,
      "z": -7,
      "name": "Rock_Sandstone_Cobble",
      "rotation": 3
    },
    {
      "x": -9,
      "y": 11,
      "z": -7,
      "name": "Rock_Sandstone_Brick",
      "rotation": 3
    },
    {
      "x": -9,
      "y": 12,
      "z": -7,
      "name": "Rock_Sandstone_Brick",
      "rotation": 3
    },
    {
      "x": -9,
      "y": 13,
      "z": -7,
      "name": "Rock_Sandstone_Brick",
      "rotation": 3
    },
    {
      "x": -9,
      "y": 14,
      "z": -7,
      "name": "Rock_Sandstone_Brick",
      "rotation": 3
    },
    {
      "x": -9,
      "y": 15,
      "z": -7,
      "name": "Rock_Sandstone",
      "rotation": 3
    },
    {
      "x": -9,
      "y": 16,
      "z": -7,
      "name": "Rock_Sandstone_Brick",
      "rotation": 3
    },
    {
      "x": -9,
      "y": 17,
      "z": -7,
      "name": "Rock_Sandstone_Cobble",
      "rotation": 3
    },
    {
      "x": -9,
      "y": 18,
      "z": -7,
      "name": "Rock_Sandstone_Brick",
      "rotation": 3
    },
    {
      "x": -9,
      "y": 19,
      "z": -7,
      "name": "Rock_Sandstone_Brick",
      "rotation": 3
    },
    {
      "x": -9,
      "y": 20,
      "z": -7,
      "name": "Rock_Sandstone_Cobble",
      "rotation": 3
    },
    {
      "x": -9,
      "y": 21,
      "z": -7,
      "name": "Rock_Sandstone_Brick",
      "rotation": 3
    },
    {
      "x": -9,
      "y": 22,
      "z": -7,
      "name": "Rock_Sandstone",
      "rotation": 3
    },
    {
      "x": -9,
      "y": 23,
      "z": -7,
      "name": "Rock_Sandstone_Brick",
      "rotation": 3
    },
    {
      "x": -9,
      "y": 24,
      "z": -7,
      "name": "Rock_Sandstone_Brick",
      "rotation": 3
    },
    {
      "x": -9,
      "y": 25,
      "z": -7,
      "name": "Rock_Sandstone_Brick",
      "rotation": 3
    },
    {
      "x": -9,
      "y": 26,
      "z": -7,
      "name": "Rock_Sandstone_Brick",
      "rotation": 3
    },
    {
      "x": -9,
      "y": 38,
      "z": -2,
      "name": "Rock_Sandstone_Brick",
      "rotation": 3
    },
    {
      "x": -9,
      "y": 39,
      "z": -2,
      "name": "Rock_Sandstone_Cobble",
      "rotation": 3
    },
    {
      "x": -9,
      "y": 40,
      "z": -2,
      "name": "Rock_Sandstone_Brick",
      "rotation": 3
    },
    {
      "x": -9,
      "y": 41,
      "z": -2,
      "name": "Rock_Sandstone_Brick",
      "rotation": 3
    },
    {
      "x": -9,
      "y": 42,
      "z": -2,
      "name": "Rock_Sandstone_Brick",
      "rotation": 3
    },
    {
      "x": -9,
      "y": 43,
      "z": -2,
      "name": "Rock_Sandstone_Cobble",
      "rotation": 3
    },
    {
      "x": -9,
      "y": 36,
      "z": -1,
      "name": "Rock_Sandstone_Red_Cobble"
    },
    {
      "x": -9,
      "y": 37,
      "z": -1,
      "name": "Rock_Sandstone_Red"
    },
    {
      "x": -9,
      "y": 38,
      "z": -1,
      "name": "Rock_Sandstone_Brick",
      "rotation": 3
    },
    {
      "x": -9,
      "y": 39,
      "z": -1,
      "name": "Rock_Sandstone_Brick",
      "rotation": 3
    },
    {
      "x": -9,
      "y": 40,
      "z": -1,
      "name": "Rock_Sandstone_Cobble",
      "rotation": 3
    },
    {
      "x": -9,
      "y": 41,
      "z": -1,
      "name": "Rock_Sandstone_Brick",
      "rotation": 3
    },
    {
      "x": -9,
      "y": 42,
      "z": -1,
      "name": "Rock_Sandstone_Brick",
      "rotation": 3
    },
    {
      "x": -9,
      "y": 43,
      "z": -1,
      "name": "Rock_Sandstone_Cobble",
      "rotation": 3
    },
    {
      "x": -9,
      "y": 44,
      "z": -1,
      "name": "Rock_Sandstone_Brick"
    },
    {
      "x": -9,
      "y": 45,
      "z": -1,
      "name": "Rock_Sandstone_Brick"
    },
    {
      "x": -9,
      "y": 51,
      "z": -1,
      "name": "Rock_Sandstone_Brick"
    },
    {
      "x": -9,
      "y": 52,
      "z": -1,
      "name": "Soil_Clay_Ocean_Brick"
    },
    {
      "x": -9,
      "y": 53,
      "z": -1,
      "name": "Soil_Clay_Ocean_Brick"
    },
    {
      "x": -9,
      "y": 36,
      "z": 0,
      "name": "Rock_Sandstone_Red_Brick_Ornate"
    },
    {
      "x": -9,
      "y": 37,
      "z": 0,
      "name": "Rock_Sandstone_Red_Cobble"
    },
    {
      "x": -9,
      "y": 38,
      "z": 0,
      "name": "Rock_Sandstone_Brick",
      "rotation": 3
    },
    {
      "x": -9,
      "y": 39,
      "z": 0,
      "name": "Rock_Sandstone_Cobble",
      "rotation": 3
    },
    {
      "x": -9,
      "y": 40,
      "z": 0,
      "name": "Rock_Sandstone_Brick",
      "rotation": 3
    },
    {
      "x": -9,
      "y": 41,
      "z": 0,
      "name": "Rock_Sandstone_Cobble",
      "rotation": 3
    },
    {
      "x": -9,
      "y": 42,
      "z": 0,
      "name": "Rock_Sandstone_Brick",
      "rotation": 3
    },
    {
      "x": -9,
      "y": 43,
      "z": 0,
      "name": "Rock_Sandstone_Brick",
      "rotation": 3
    },
    {
      "x": -9,
      "y": 44,
      "z": 0,
      "name": "Rock_Sandstone_Brick"
    },
    {
      "x": -9,
      "y": 45,
      "z": 0,
      "name": "Rock_Sandstone_Brick"
    },
    {
      "x": -9,
      "y": 46,
      "z": 0,
      "name": "Rock_Sandstone_Brick"
    },
    {
      "x": -9,
      "y": 47,
      "z": 0,
      "name": "Rock_Sandstone_Brick"
    },
    {
      "x": -9,
      "y": 48,
      "z": 0,
      "name": "Rock_Sandstone_Brick"
    },
    {
      "x": -9,
      "y": 49,
      "z": 0,
      "name": "Rock_Sandstone_Brick"
    },
    {
      "x": -9,
      "y": 50,
      "z": 0,
      "name": "Rock_Sandstone_Brick"
    },
    {
      "x": -9,
      "y": 51,
      "z": 0,
      "name": "Rock_Sandstone_Brick"
    },
    {
      "x": -9,
      "y": 52,
      "z": 0,
      "name": "Soil_Clay_Ocean_Brick_Smooth"
    },
    {
      "x": -9,
      "y": 53,
      "z": 0,
      "name": "Soil_Clay_Ocean_Brick"
    },
    {
      "x": -9,
      "y": 36,
      "z": 1,
      "name": "Rock_Sandstone_Red_Cobble"
    },
    {
      "x": -9,
      "y": 37,
      "z": 1,
      "name": "Rock_Sandstone_Red_Cobble"
    },
    {
      "x": -9,
      "y": 38,
      "z": 1,
      "name": "Rock_Sandstone_Cobble",
      "rotation": 3
    },
    {
      "x": -9,
      "y": 39,
      "z": 1,
      "name": "Rock_Sandstone_Cobble",
      "rotation": 3
    },
    {
      "x": -9,
      "y": 40,
      "z": 1,
      "name": "Rock_Sandstone_Brick",
      "rotation": 3
    },
    {
      "x": -9,
      "y": 41,
      "z": 1,
      "name": "Rock_Sandstone_Cobble",
      "rotation": 3
    },
    {
      "x": -9,
      "y": 42,
      "z": 1,
      "name": "Rock_Sandstone_Cobble",
      "rotation": 3
    },
    {
      "x": -9,
      "y": 43,
      "z": 1,
      "name": "Rock_Sandstone_Brick",
      "rotation": 3
    },
    {
      "x": -9,
      "y": 44,
      "z": 1,
      "name": "Rock_Sandstone_Brick",
      "rotation": 3
    },
    {
      "x": -9,
      "y": 45,
      "z": 1,
      "name": "Rock_Sandstone_Brick",
      "rotation": 3
    },
    {
      "x": -9,
      "y": 46,
      "z": 1,
      "name": "Rock_Sandstone_Brick"
    },
    {
      "x": -9,
      "y": 47,
      "z": 1,
      "name": "Rock_Sandstone_Brick"
    },
    {
      "x": -9,
      "y": 48,
      "z": 1,
      "name": "Rock_Sandstone_Brick"
    },
    {
      "x": -9,
      "y": 49,
      "z": 1,
      "name": "Rock_Sandstone_Brick"
    },
    {
      "x": -9,
      "y": 50,
      "z": 1,
      "name": "Rock_Sandstone_Brick"
    },
    {
      "x": -9,
      "y": 51,
      "z": 1,
      "name": "Rock_Sandstone_Brick"
    },
    {
      "x": -9,
      "y": 52,
      "z": 1,
      "name": "Soil_Clay_Ocean_Brick"
    },
    {
      "x": -9,
      "y": 53,
      "z": 1,
      "name": "Soil_Clay_Ocean_Brick"
    },
    {
      "x": -9,
      "y": 36,
      "z": 2,
      "name": "Rock_Sandstone_Red_Cobble"
    },
    {
      "x": -9,
      "y": 37,
      "z": 2,
      "name": "Rock_Sandstone_Red_Cobble"
    },
    {
      "x": -9,
      "y": 38,
      "z": 2,
      "name": "Rock_Sandstone_Cobble",
      "rotation": 3
    },
    {
      "x": -9,
      "y": 39,
      "z": 2,
      "name": "Rock_Sandstone_Brick",
      "rotation": 3
    },
    {
      "x": -9,
      "y": 40,
      "z": 2,
      "name": "Rock_Sandstone_Brick",
      "rotation": 3
    },
    {
      "x": -9,
      "y": 41,
      "z": 2,
      "name": "Rock_Sandstone_Cobble",
      "rotation": 3
    },
    {
      "x": -9,
      "y": 42,
      "z": 2,
      "name": "Rock_Sandstone_Brick",
      "rotation": 3
    },
    {
      "x": -9,
      "y": 43,
      "z": 2,
      "name": "Rock_Sandstone_Cobble",
      "rotation": 3
    },
    {
      "x": -9,
      "y": 44,
      "z": 2,
      "name": "Rock_Sandstone_Cobble",
      "rotation": 3
    },
    {
      "x": -9,
      "y": 45,
      "z": 2,
      "name": "Rock_Sandstone_Brick",
      "rotation": 3
    },
    {
      "x": -9,
      "y": 46,
      "z": 2,
      "name": "Rock_Sandstone_Brick"
    },
    {
      "x": -9,
      "y": 47,
      "z": 2,
      "name": "Rock_Sandstone_Brick"
    },
    {
      "x": -9,
      "y": 48,
      "z": 2,
      "name": "Rock_Sandstone_Brick"
    },
    {
      "x": -9,
      "y": 49,
      "z": 2,
      "name": "Rock_Sandstone_Brick"
    },
    {
      "x": -9,
      "y": 50,
      "z": 2,
      "name": "Rock_Sandstone_Brick"
    },
    {
      "x": -9,
      "y": 51,
      "z": 2,
      "name": "Rock_Sandstone_Brick"
    },
    {
      "x": -9,
      "y": 52,
      "z": 2,
      "name": "Soil_Clay_Ocean_Brick"
    },
    {
      "x": -9,
      "y": 53,
      "z": 2,
      "name": "Soil_Clay_Ocean_Brick"
    },
    {
      "x": -9,
      "y": 35,
      "z": 3,
      "name": "Rock_Sandstone_Brick"
    },
    {
      "x": -9,
      "y": 36,
      "z": 3,
      "name": "Rock_Sandstone_Red_Cobble"
    },
    {
      "x": -9,
      "y": 37,
      "z": 3,
      "name": "Rock_Sandstone_Red_Cobble"
    },
    {
      "x": -9,
      "y": 38,
      "z": 3,
      "name": "Rock_Sandstone_Red_Cobble"
    },
    {
      "x": -9,
      "y": 39,
      "z": 3,
      "name": "Rock_Sandstone_Red_Cobble"
    },
    {
      "x": -9,
      "y": 40,
      "z": 3,
      "name": "Rock_Sandstone_Brick",
      "rotation": 3
    },
    {
      "x": -9,
      "y": 41,
      "z": 3,
      "name": "Rock_Sandstone_Brick",
      "rotation": 3
    },
    {
      "x": -9,
      "y": 42,
      "z": 3,
      "name": "Rock_Sandstone_Brick",
      "rotation": 3
    },
    {
      "x": -9,
      "y": 43,
      "z": 3,
      "name": "Rock_Sandstone_Brick",
      "rotation": 3
    },
    {
      "x": -9,
      "y": 44,
      "z": 3,
      "name": "Rock_Sandstone_Brick",
      "rotation": 3
    },
    {
      "x": -9,
      "y": 45,
      "z": 3,
      "name": "Rock_Sandstone_Cobble",
      "rotation": 3
    },
    {
      "x": -9,
      "y": 46,
      "z": 3,
      "name": "Rock_Sandstone_Brick"
    },
    {
      "x": -9,
      "y": 47,
      "z": 3,
      "name": "Rock_Sandstone_Brick"
    },
    {
      "x": -9,
      "y": 51,
      "z": 3,
      "name": "Rock_Sandstone_Brick"
    },
    {
      "x": -9,
      "y": 52,
      "z": 3,
      "name": "Soil_Clay_Ocean_Brick"
    },
    {
      "x": -9,
      "y": 53,
      "z": 3,
      "name": "Soil_Clay_Ocean_Brick"
    },
    {
      "x": -9,
      "y": 32,
      "z": 4,
      "name": "Rock_Sandstone_Brick_Half",
      "rotation": 8
    },
    {
      "x": -9,
      "y": 33,
      "z": 4,
      "name": "Rock_Sandstone_Brick"
    },
    {
      "x": -9,
      "y": 34,
      "z": 4,
      "name": "Rock_Sandstone_Brick"
    },
    {
      "x": -9,
      "y": 35,
      "z": 4,
      "name": "Rock_Sandstone_Brick"
    },
    {
      "x": -9,
      "y": 36,
      "z": 4,
      "name": "Rock_Sandstone_Red_Cobble"
    },
    {
      "x": -9,
      "y": 37,
      "z": 4,
      "name": "Rock_Sandstone_Red_Cobble"
    },
    {
      "x": -9,
      "y": 38,
      "z": 4,
      "name": "Rock_Sandstone_Red"
    },
    {
      "x": -9,
      "y": 39,
      "z": 4,
      "name": "Rock_Sandstone_Red_Brick_Ornate"
    },
    {
      "x": -9,
      "y": 40,
      "z": 4,
      "name": "Rock_Sandstone_Cobble",
      "rotation": 3
    },
    {
      "x": -9,
      "y": 41,
      "z": 4,
      "name": "Rock_Sandstone_Brick",
      "rotation": 3
    },
    {
      "x": -9,
      "y": 42,
      "z": 4,
      "name": "Rock_Sandstone_Brick",
      "rotation": 3
    },
    {
      "x": -9,
      "y": 43,
      "z": 4,
      "name": "Rock_Sandstone_Brick",
      "rotation": 3
    },
    {
      "x": -9,
      "y": 44,
      "z": 4,
      "name": "Rock_Sandstone_Brick",
      "rotation": 3
    },
    {
      "x": -9,
      "y": 45,
      "z": 4,
      "name": "Rock_Sandstone_Brick",
      "rotation": 3
    },
    {
      "x": -9,
      "y": 32,
      "z": 5,
      "name": "Rock_Sandstone_Brick"
    },
    {
      "x": -9,
      "y": 33,
      "z": 5,
      "name": "Rock_Sandstone_Brick"
    },
    {
      "x": -9,
      "y": 34,
      "z": 5,
      "name": "Rock_Sandstone_Brick"
    },
    {
      "x": -9,
      "y": 35,
      "z": 5,
      "name": "Rock_Sandstone_Brick"
    },
    {
      "x": -9,
      "y": 36,
      "z": 5,
      "name": "Rock_Sandstone_Red_Cobble"
    },
    {
      "x": -9,
      "y": 37,
      "z": 5,
      "name": "Rock_Sandstone_Red_Cobble"
    },
    {
      "x": -9,
      "y": 38,
      "z": 5,
      "name": "Rock_Sandstone_Red_Cobble"
    },
    {
      "x": -9,
      "y": 39,
      "z": 5,
      "name": "Rock_Sandstone_Red"
    },
    {
      "x": -9,
      "y": 40,
      "z": 5,
      "name": "Rock_Sandstone_Cobble",
      "rotation": 3
    },
    {
      "x": -9,
      "y": 41,
      "z": 5,
      "name": "Rock_Sandstone_Brick",
      "rotation": 3
    },
    {
      "x": -9,
      "y": 42,
      "z": 5,
      "name": "Rock_Sandstone_Brick",
      "rotation": 3
    },
    {
      "x": -9,
      "y": 43,
      "z": 5,
      "name": "Rock_Sandstone_Brick",
      "rotation": 3
    },
    {
      "x": -9,
      "y": 44,
      "z": 5,
      "name": "Rock_Sandstone_Brick",
      "rotation": 3
    },
    {
      "x": -9,
      "y": 45,
      "z": 5,
      "name": "Rock_Sandstone_Brick",
      "rotation": 3
    },
    {
      "x": -9,
      "y": 31,
      "z": 6,
      "name": "Rock_Sandstone_Brick_Stairs",
      "rotation": 8
    },
    {
      "x": -9,
      "y": 32,
      "z": 6,
      "name": "Rock_Sandstone_Cobble"
    },
    {
      "x": -9,
      "y": 33,
      "z": 6,
      "name": "Rock_Sandstone_Brick"
    },
    {
      "x": -9,
      "y": 34,
      "z": 6,
      "name": "Rock_Sandstone_Brick"
    },
    {
      "x": -9,
      "y": 35,
      "z": 6,
      "name": "Rock_Sandstone_Brick"
    },
    {
      "x": -9,
      "y": 30,
      "z": 7,
      "name": "Rock_Sandstone_Brick_Stairs",
      "rotation": 8
    },
    {
      "x": -9,
      "y": 31,
      "z": 7,
      "name": "Rock_Sandstone"
    },
    {
      "x": -9,
      "y": 32,
      "z": 7,
      "name": "Rock_Sandstone_Brick"
    },
    {
      "x": -9,
      "y": 33,
      "z": 7,
      "name": "Rock_Sandstone_Brick"
    },
    {
      "x": -9,
      "y": 34,
      "z": 7,
      "name": "Rock_Sandstone_Brick"
    },
    {
      "x": -9,
      "y": 35,
      "z": 7,
      "name": "Rock_Sandstone_Brick"
    },
    {
      "x": -9,
      "y": 0,
      "z": 8,
      "name": "Rock_Sandstone_Brick"
    },
    {
      "x": -9,
      "y": 1,
      "z": 8,
      "name": "Rock_Sandstone"
    },
    {
      "x": -9,
      "y": 2,
      "z": 8,
      "name": "Rock_Sandstone_Brick"
    },
    {
      "x": -9,
      "y": 3,
      "z": 8,
      "name": "Rock_Sandstone_Brick"
    },
    {
      "x": -9,
      "y": 4,
      "z": 8,
      "name": "Rock_Sandstone_Brick"
    },
    {
      "x": -9,
      "y": 5,
      "z": 8,
      "name": "Rock_Sandstone_Brick"
    },
    {
      "x": -9,
      "y": 6,
      "z": 8,
      "name": "Rock_Sandstone_Brick"
    },
    {
      "x": -9,
      "y": 7,
      "z": 8,
      "name": "Rock_Sandstone_Cobble"
    },
    {
      "x": -9,
      "y": 8,
      "z": 8,
      "name": "Rock_Sandstone_Brick"
    },
    {
      "x": -9,
      "y": 9,
      "z": 8,
      "name": "Rock_Sandstone_Brick"
    },
    {
      "x": -9,
      "y": 10,
      "z": 8,
      "name": "Rock_Sandstone"
    },
    {
      "x": -9,
      "y": 11,
      "z": 8,
      "name": "Rock_Sandstone_Brick",
      "rotation": 1
    },
    {
      "x": -9,
      "y": 12,
      "z": 8,
      "name": "Rock_Sandstone_Brick",
      "rotation": 1
    },
    {
      "x": -9,
      "y": 13,
      "z": 8,
      "name": "Rock_Sandstone_Brick",
      "rotation": 1
    },
    {
      "x": -9,
      "y": 14,
      "z": 8,
      "name": "Rock_Sandstone_Cobble",
      "rotation": 1
    },
    {
      "x": -9,
      "y": 15,
      "z": 8,
      "name": "Rock_Sandstone_Brick",
      "rotation": 1
    },
    {
      "x": -9,
      "y": 16,
      "z": 8,
      "name": "Rock_Sandstone_Brick",
      "rotation": 1
    },
    {
      "x": -9,
      "y": 17,
      "z": 8,
      "name": "Rock_Sandstone_Brick",
      "rotation": 1
    },
    {
      "x": -9,
      "y": 18,
      "z": 8,
      "name": "Rock_Sandstone_Brick",
      "rotation": 1
    },
    {
      "x": -9,
      "y": 19,
      "z": 8,
      "name": "Rock_Sandstone_Brick",
      "rotation": 1
    },
    {
      "x": -9,
      "y": 20,
      "z": 8,
      "name": "Rock_Sandstone_Brick",
      "rotation": 1
    },
    {
      "x": -9,
      "y": 21,
      "z": 8,
      "name": "Rock_Sandstone_Brick",
      "rotation": 1
    },
    {
      "x": -9,
      "y": 22,
      "z": 8,
      "name": "Rock_Sandstone_Cobble",
      "rotation": 1
    },
    {
      "x": -9,
      "y": 23,
      "z": 8,
      "name": "Rock_Sandstone_Brick",
      "rotation": 1
    },
    {
      "x": -9,
      "y": 24,
      "z": 8,
      "name": "Rock_Sandstone_Cobble",
      "rotation": 1
    },
    {
      "x": -9,
      "y": 25,
      "z": 8,
      "name": "Rock_Sandstone_Brick",
      "rotation": 1
    },
    {
      "x": -9,
      "y": 26,
      "z": 8,
      "name": "Rock_Sandstone_Brick",
      "rotation": 1
    },
    {
      "x": -9,
      "y": 27,
      "z": 8,
      "name": "Rock_Sandstone_Brick",
      "rotation": 1
    },
    {
      "x": -9,
      "y": 28,
      "z": 8,
      "name": "Rock_Sandstone_Brick",
      "rotation": 1
    },
    {
      "x": -9,
      "y": 29,
      "z": 8,
      "name": "Rock_Sandstone_Brick",
      "rotation": 1
    },
    {
      "x": -9,
      "y": 30,
      "z": 8,
      "name": "Rock_Sandstone_Brick",
      "rotation": 1
    },
    {
      "x": -9,
      "y": 31,
      "z": 8,
      "name": "Rock_Sandstone_Brick",
      "rotation": 1
    },
    {
      "x": -9,
      "y": 32,
      "z": 8,
      "name": "Rock_Sandstone_Brick",
      "rotation": 1
    },
    {
      "x": -9,
      "y": 33,
      "z": 8,
      "name": "Rock_Sandstone_Brick",
      "rotation": 1
    },
    {
      "x": -9,
      "y": 34,
      "z": 8,
      "name": "Rock_Sandstone_Brick",
      "rotation": 1
    },
    {
      "x": -9,
      "y": 35,
      "z": 8,
      "name": "Rock_Sandstone_Brick"
    },
    {
      "x": -9,
      "y": 0,
      "z": 9,
      "name": "Rock_Sandstone_Brick"
    },
    {
      "x": -9,
      "y": 1,
      "z": 9,
      "name": "Rock_Sandstone"
    },
    {
      "x": -9,
      "y": 2,
      "z": 9,
      "name": "Rock_Sandstone_Brick"
    },
    {
      "x": -9,
      "y": 3,
      "z": 9,
      "name": "Rock_Sandstone_Brick"
    },
    {
      "x": -9,
      "y": 4,
      "z": 9,
      "name": "Rock_Sandstone"
    },
    {
      "x": -9,
      "y": 5,
      "z": 9,
      "name": "Rock_Sandstone_Brick"
    },
    {
      "x": -9,
      "y": 6,
      "z": 9,
      "name": "Rock_Sandstone_Cobble"
    },
    {
      "x": -9,
      "y": 7,
      "z": 9,
      "name": "Rock_Sandstone_Brick"
    },
    {
      "x": -9,
      "y": 8,
      "z": 9,
      "name": "Rock_Sandstone_Brick"
    },
    {
      "x": -9,
      "y": 9,
      "z": 9,
      "name": "Rock_Sandstone_Brick"
    },
    {
      "x": -9,
      "y": 10,
      "z": 9,
      "name": "Rock_Sandstone_Cobble"
    },
    {
      "x": -9,
      "y": 11,
      "z": 9,
      "name": "Rock_Sandstone_Brick",
      "rotation": 1
    },
    {
      "x": -9,
      "y": 12,
      "z": 9,
      "name": "Rock_Sandstone_Brick",
      "rotation": 1
    },
    {
      "x": -9,
      "y": 13,
      "z": 9,
      "name": "Rock_Sandstone_Brick",
      "rotation": 1
    },
    {
      "x": -9,
      "y": 14,
      "z": 9,
      "name": "Rock_Sandstone",
      "rotation": 1
    },
    {
      "x": -9,
      "y": 15,
      "z": 9,
      "name": "Rock_Sandstone_Brick",
      "rotation": 1
    },
    {
      "x": -9,
      "y": 16,
      "z": 9,
      "name": "Rock_Sandstone_Brick",
      "rotation": 1
    },
    {
      "x": -9,
      "y": 17,
      "z": 9,
      "name": "Rock_Sandstone_Cobble",
      "rotation": 1
    },
    {
      "x": -9,
      "y": 18,
      "z": 9,
      "name": "Rock_Sandstone_Brick",
      "rotation": 1
    },
    {
      "x": -9,
      "y": 19,
      "z": 9,
      "name": "Rock_Sandstone",
      "rotation": 1
    },
    {
      "x": -9,
      "y": 20,
      "z": 9,
      "name": "Rock_Sandstone",
      "rotation": 1
    },
    {
      "x": -9,
      "y": 21,
      "z": 9,
      "name": "Rock_Sandstone_Brick",
      "rotation": 1
    },
    {
      "x": -9,
      "y": 22,
      "z": 9,
      "name": "Rock_Sandstone_Brick",
      "rotation": 1
    },
    {
      "x": -9,
      "y": 23,
      "z": 9,
      "name": "Rock_Sandstone_Brick",
      "rotation": 1
    },
    {
      "x": -9,
      "y": 24,
      "z": 9,
      "name": "Rock_Sandstone_Cobble",
      "rotation": 1
    },
    {
      "x": -9,
      "y": 25,
      "z": 9,
      "name": "Rock_Sandstone_Brick",
      "rotation": 1
    },
    {
      "x": -9,
      "y": 26,
      "z": 9,
      "name": "Rock_Sandstone_Brick",
      "rotation": 1
    },
    {
      "x": -9,
      "y": 27,
      "z": 9,
      "name": "Rock_Sandstone",
      "rotation": 1
    },
    {
      "x": -9,
      "y": 28,
      "z": 9,
      "name": "Rock_Sandstone_Cobble",
      "rotation": 1
    },
    {
      "x": -9,
      "y": 29,
      "z": 9,
      "name": "Rock_Sandstone_Brick",
      "rotation": 1
    },
    {
      "x": -9,
      "y": 30,
      "z": 9,
      "name": "Rock_Sandstone_Brick",
      "rotation": 1
    },
    {
      "x": -9,
      "y": 31,
      "z": 9,
      "name": "Rock_Sandstone_Brick",
      "rotation": 1
    },
    {
      "x": -9,
      "y": 32,
      "z": 9,
      "name": "Rock_Sandstone_Brick",
      "rotation": 1
    },
    {
      "x": -9,
      "y": 33,
      "z": 9,
      "name": "Rock_Sandstone_Brick",
      "rotation": 1
    },
    {
      "x": -9,
      "y": 34,
      "z": 9,
      "name": "Rock_Sandstone_Brick",
      "rotation": 1
    },
    {
      "x": -9,
      "y": 35,
      "z": 9,
      "name": "Rock_Sandstone_Brick"
    },
    {
      "x": -9,
      "y": 0,
      "z": 10,
      "name": "Rock_Sandstone_Cobble"
    },
    {
      "x": -9,
      "y": 1,
      "z": 10,
      "name": "Rock_Sandstone_Brick"
    },
    {
      "x": -9,
      "y": 2,
      "z": 10,
      "name": "Rock_Sandstone_Brick"
    },
    {
      "x": -9,
      "y": 3,
      "z": 10,
      "name": "Rock_Sandstone"
    },
    {
      "x": -9,
      "y": 4,
      "z": 10,
      "name": "Rock_Sandstone_Brick"
    },
    {
      "x": -9,
      "y": 5,
      "z": 10,
      "name": "Rock_Sandstone_Brick"
    },
    {
      "x": -9,
      "y": 6,
      "z": 10,
      "name": "Rock_Sandstone_Brick"
    },
    {
      "x": -9,
      "y": 7,
      "z": 10,
      "name": "Rock_Sandstone"
    },
    {
      "x": -9,
      "y": 8,
      "z": 10,
      "name": "Rock_Sandstone_Brick"
    },
    {
      "x": -9,
      "y": 9,
      "z": 10,
      "name": "Rock_Sandstone_Brick"
    },
    {
      "x": -9,
      "y": 10,
      "z": 10,
      "name": "Rock_Sandstone"
    },
    {
      "x": -9,
      "y": 11,
      "z": 10,
      "name": "Rock_Sandstone_Brick",
      "rotation": 1
    },
    {
      "x": -9,
      "y": 12,
      "z": 10,
      "name": "Rock_Sandstone_Brick",
      "rotation": 1
    },
    {
      "x": -9,
      "y": 13,
      "z": 10,
      "name": "Rock_Sandstone_Brick",
      "rotation": 1
    },
    {
      "x": -9,
      "y": 14,
      "z": 10,
      "name": "Rock_Sandstone",
      "rotation": 1
    },
    {
      "x": -9,
      "y": 15,
      "z": 10,
      "name": "Rock_Sandstone_Brick",
      "rotation": 1
    },
    {
      "x": -9,
      "y": 16,
      "z": 10,
      "name": "Rock_Sandstone_Brick",
      "rotation": 1
    },
    {
      "x": -9,
      "y": 17,
      "z": 10,
      "name": "Rock_Sandstone_Brick",
      "rotation": 1
    },
    {
      "x": -9,
      "y": 18,
      "z": 10,
      "name": "Rock_Sandstone_Cobble",
      "rotation": 1
    },
    {
      "x": -9,
      "y": 19,
      "z": 10,
      "name": "Rock_Sandstone_Brick",
      "rotation": 1
    },
    {
      "x": -9,
      "y": 20,
      "z": 10,
      "name": "Rock_Sandstone_Brick",
      "rotation": 1
    },
    {
      "x": -9,
      "y": 21,
      "z": 10,
      "name": "Rock_Sandstone_Brick",
      "rotation": 1
    },
    {
      "x": -9,
      "y": 22,
      "z": 10,
      "name": "Rock_Sandstone_Cobble",
      "rotation": 1
    },
    {
      "x": -9,
      "y": 23,
      "z": 10,
      "name": "Rock_Sandstone_Brick",
      "rotation": 1
    },
    {
      "x": -9,
      "y": 24,
      "z": 10,
      "name": "Rock_Sandstone_Brick",
      "rotation": 1
    },
    {
      "x": -9,
      "y": 25,
      "z": 10,
      "name": "Rock_Sandstone_Brick",
      "rotation": 1
    },
    {
      "x": -9,
      "y": 26,
      "z": 10,
      "name": "Rock_Sandstone_Brick",
      "rotation": 1
    },
    {
      "x": -9,
      "y": 27,
      "z": 10,
      "name": "Rock_Sandstone_Brick",
      "rotation": 1
    },
    {
      "x": -9,
      "y": 28,
      "z": 10,
      "name": "Rock_Sandstone_Cobble",
      "rotation": 1
    },
    {
      "x": -9,
      "y": 29,
      "z": 10,
      "name": "Rock_Sandstone_Brick",
      "rotation": 1
    },
    {
      "x": -9,
      "y": 30,
      "z": 10,
      "name": "Rock_Sandstone_Brick",
      "rotation": 1
    },
    {
      "x": -9,
      "y": 31,
      "z": 10,
      "name": "Rock_Sandstone_Brick",
      "rotation": 1
    },
    {
      "x": -9,
      "y": 32,
      "z": 10,
      "name": "Rock_Sandstone_Brick",
      "rotation": 1
    },
    {
      "x": -9,
      "y": 33,
      "z": 10,
      "name": "Rock_Sandstone_Brick",
      "rotation": 1
    },
    {
      "x": -9,
      "y": 34,
      "z": 10,
      "name": "Rock_Sandstone_Brick",
      "rotation": 1
    },
    {
      "x": -9,
      "y": 35,
      "z": 10,
      "name": "Rock_Sandstone_Brick"
    },
    {
      "x": -9,
      "y": 0,
      "z": 11,
      "name": "Rock_Sandstone_Brick"
    },
    {
      "x": -9,
      "y": 1,
      "z": 11,
      "name": "Rock_Sandstone_Brick"
    },
    {
      "x": -9,
      "y": 2,
      "z": 11,
      "name": "Rock_Sandstone_Brick"
    },
    {
      "x": -9,
      "y": 3,
      "z": 11,
      "name": "Rock_Sandstone_Brick"
    },
    {
      "x": -9,
      "y": 4,
      "z": 11,
      "name": "Rock_Sandstone_Cobble"
    },
    {
      "x": -9,
      "y": 5,
      "z": 11,
      "name": "Rock_Sandstone_Brick"
    },
    {
      "x": -9,
      "y": 6,
      "z": 11,
      "name": "Rock_Sandstone"
    },
    {
      "x": -9,
      "y": 7,
      "z": 11,
      "name": "Rock_Sandstone_Brick"
    },
    {
      "x": -9,
      "y": 8,
      "z": 11,
      "name": "Rock_Sandstone"
    },
    {
      "x": -9,
      "y": 9,
      "z": 11,
      "name": "Rock_Sandstone"
    },
    {
      "x": -9,
      "y": 10,
      "z": 11,
      "name": "Rock_Sandstone_Brick"
    },
    {
      "x": -9,
      "y": 11,
      "z": 11,
      "name": "Rock_Sandstone"
    },
    {
      "x": -9,
      "y": 12,
      "z": 11,
      "name": "Rock_Sandstone_Brick"
    },
    {
      "x": -9,
      "y": 13,
      "z": 11,
      "name": "Rock_Sandstone_Brick"
    },
    {
      "x": -9,
      "y": 14,
      "z": 11,
      "name": "Rock_Sandstone_Brick"
    },
    {
      "x": -9,
      "y": 15,
      "z": 11,
      "name": "Rock_Sandstone_Brick"
    },
    {
      "x": -9,
      "y": 16,
      "z": 11,
      "name": "Rock_Sandstone_Cobble"
    },
    {
      "x": -9,
      "y": 17,
      "z": 11,
      "name": "Rock_Sandstone"
    },
    {
      "x": -9,
      "y": 18,
      "z": 11,
      "name": "Rock_Sandstone_Cobble"
    },
    {
      "x": -9,
      "y": 19,
      "z": 11,
      "name": "Rock_Sandstone_Brick"
    },
    {
      "x": -9,
      "y": 20,
      "z": 11,
      "name": "Rock_Sandstone_Brick"
    },
    {
      "x": -9,
      "y": 21,
      "z": 11,
      "name": "Rock_Sandstone_Brick"
    },
    {
      "x": -9,
      "y": 22,
      "z": 11,
      "name": "Rock_Sandstone"
    },
    {
      "x": -9,
      "y": 23,
      "z": 11,
      "name": "Rock_Sandstone_Brick"
    },
    {
      "x": -9,
      "y": 24,
      "z": 11,
      "name": "Rock_Sandstone_Brick"
    },
    {
      "x": -9,
      "y": 25,
      "z": 11,
      "name": "Rock_Sandstone_Brick"
    },
    {
      "x": -9,
      "y": 26,
      "z": 11,
      "name": "Rock_Sandstone_Brick"
    },
    {
      "x": -9,
      "y": 27,
      "z": 11,
      "name": "Rock_Sandstone_Brick"
    },
    {
      "x": -9,
      "y": 28,
      "z": 11,
      "name": "Rock_Sandstone_Brick"
    },
    {
      "x": -9,
      "y": 29,
      "z": 11,
      "name": "Rock_Sandstone_Brick"
    },
    {
      "x": -9,
      "y": 30,
      "z": 11,
      "name": "Rock_Sandstone_Brick"
    },
    {
      "x": -9,
      "y": 31,
      "z": 11,
      "name": "Rock_Sandstone_Brick"
    },
    {
      "x": -9,
      "y": 32,
      "z": 11,
      "name": "Rock_Sandstone_Cobble"
    },
    {
      "x": -9,
      "y": 33,
      "z": 11,
      "name": "Rock_Sandstone_Brick"
    },
    {
      "x": -9,
      "y": 34,
      "z": 11,
      "name": "Rock_Sandstone_Brick"
    },
    {
      "x": -9,
      "y": 35,
      "z": 11,
      "name": "Rock_Sandstone_Brick"
    },
    {
      "x": -8,
      "y": 0,
      "z": -10,
      "name": "Rock_Sandstone_Brick"
    },
    {
      "x": -8,
      "y": 1,
      "z": -10,
      "name": "Rock_Sandstone_Brick"
    },
    {
      "x": -8,
      "y": 2,
      "z": -10,
      "name": "Rock_Sandstone"
    },
    {
      "x": -8,
      "y": 3,
      "z": -10,
      "name": "Rock_Sandstone"
    },
    {
      "x": -8,
      "y": 4,
      "z": -10,
      "name": "Rock_Sandstone_Brick"
    },
    {
      "x": -8,
      "y": 5,
      "z": -10,
      "name": "Rock_Sandstone_Brick"
    },
    {
      "x": -8,
      "y": 6,
      "z": -10,
      "name": "Rock_Sandstone"
    },
    {
      "x": -8,
      "y": 7,
      "z": -10,
      "name": "Rock_Sandstone_Brick"
    },
    {
      "x": -8,
      "y": 8,
      "z": -10,
      "name": "Rock_Sandstone"
    },
    {
      "x": -8,
      "y": 9,
      "z": -10,
      "name": "Rock_Sandstone_Cobble"
    },
    {
      "x": -8,
      "y": 10,
      "z": -10,
      "name": "Rock_Sandstone_Brick"
    },
    {
      "x": -8,
      "y": 11,
      "z": -10,
      "name": "Rock_Sandstone"
    },
    {
      "x": -8,
      "y": 12,
      "z": -10,
      "name": "Rock_Sandstone_Brick"
    },
    {
      "x": -8,
      "y": 13,
      "z": -10,
      "name": "Rock_Sandstone"
    },
    {
      "x": -8,
      "y": 14,
      "z": -10,
      "name": "Rock_Sandstone_Brick"
    },
    {
      "x": -8,
      "y": 15,
      "z": -10,
      "name": "Rock_Sandstone_Brick"
    },
    {
      "x": -8,
      "y": 16,
      "z": -10,
      "name": "Rock_Sandstone_Brick"
    },
    {
      "x": -8,
      "y": 17,
      "z": -10,
      "name": "Rock_Sandstone_Brick"
    },
    {
      "x": -8,
      "y": 18,
      "z": -10,
      "name": "Rock_Sandstone_Brick"
    },
    {
      "x": -8,
      "y": 19,
      "z": -10,
      "name": "Rock_Sandstone_Cobble"
    },
    {
      "x": -8,
      "y": 20,
      "z": -10,
      "name": "Rock_Sandstone_Cobble"
    },
    {
      "x": -8,
      "y": 21,
      "z": -10,
      "name": "Rock_Sandstone_Brick"
    },
    {
      "x": -8,
      "y": 22,
      "z": -10,
      "name": "Rock_Sandstone_Brick"
    },
    {
      "x": -8,
      "y": 23,
      "z": -10,
      "name": "Rock_Sandstone_Cobble"
    },
    {
      "x": -8,
      "y": 24,
      "z": -10,
      "name": "Rock_Sandstone_Cobble"
    },
    {
      "x": -8,
      "y": 25,
      "z": -10,
      "name": "Rock_Sandstone_Brick"
    },
    {
      "x": -8,
      "y": 0,
      "z": -9,
      "name": "Rock_Sandstone_Cobble"
    },
    {
      "x": -8,
      "y": 1,
      "z": -9,
      "name": "Rock_Sandstone_Brick"
    },
    {
      "x": -8,
      "y": 2,
      "z": -9,
      "name": "Rock_Sandstone_Brick"
    },
    {
      "x": -8,
      "y": 3,
      "z": -9,
      "name": "Rock_Sandstone_Brick"
    },
    {
      "x": -8,
      "y": 4,
      "z": -9,
      "name": "Rock_Sandstone_Brick"
    },
    {
      "x": -8,
      "y": 5,
      "z": -9,
      "name": "Rock_Sandstone_Brick"
    },
    {
      "x": -8,
      "y": 6,
      "z": -9,
      "name": "Rock_Sandstone_Brick"
    },
    {
      "x": -8,
      "y": 7,
      "z": -9,
      "name": "Rock_Sandstone_Brick"
    },
    {
      "x": -8,
      "y": 8,
      "z": -9,
      "name": "Rock_Sandstone_Brick"
    },
    {
      "x": -8,
      "y": 9,
      "z": -9,
      "name": "Rock_Sandstone_Brick"
    },
    {
      "x": -8,
      "y": 10,
      "z": -9,
      "name": "Rock_Sandstone_Brick",
      "rotation": 3
    },
    {
      "x": -8,
      "y": 11,
      "z": -9,
      "name": "Rock_Sandstone_Brick",
      "rotation": 3
    },
    {
      "x": -8,
      "y": 12,
      "z": -9,
      "name": "Rock_Sandstone_Brick",
      "rotation": 3
    },
    {
      "x": -8,
      "y": 13,
      "z": -9,
      "name": "Rock_Sandstone_Brick",
      "rotation": 3
    },
    {
      "x": -8,
      "y": 14,
      "z": -9,
      "name": "Rock_Sandstone_Brick",
      "rotation": 3
    },
    {
      "x": -8,
      "y": 15,
      "z": -9,
      "name": "Rock_Sandstone_Brick",
      "rotation": 3
    },
    {
      "x": -8,
      "y": 16,
      "z": -9,
      "name": "Rock_Sandstone_Brick",
      "rotation": 3
    },
    {
      "x": -8,
      "y": 17,
      "z": -9,
      "name": "Rock_Sandstone_Brick",
      "rotation": 3
    },
    {
      "x": -8,
      "y": 18,
      "z": -9,
      "name": "Rock_Sandstone_Brick",
      "rotation": 3
    },
    {
      "x": -8,
      "y": 19,
      "z": -9,
      "name": "Rock_Sandstone_Brick",
      "rotation": 3
    },
    {
      "x": -8,
      "y": 20,
      "z": -9,
      "name": "Rock_Sandstone_Brick",
      "rotation": 3
    },
    {
      "x": -8,
      "y": 21,
      "z": -9,
      "name": "Rock_Sandstone",
      "rotation": 3
    },
    {
      "x": -8,
      "y": 22,
      "z": -9,
      "name": "Rock_Sandstone_Brick",
      "rotation": 3
    },
    {
      "x": -8,
      "y": 23,
      "z": -9,
      "name": "Rock_Sandstone_Brick",
      "rotation": 3
    },
    {
      "x": -8,
      "y": 24,
      "z": -9,
      "name": "Rock_Sandstone_Brick",
      "rotation": 3
    },
    {
      "x": -8,
      "y": 25,
      "z": -9,
      "name": "Rock_Sandstone_Brick",
      "rotation": 3
    },
    {
      "x": -8,
      "y": 26,
      "z": -9,
      "name": "Rock_Sandstone_Brick",
      "rotation": 3
    },
    {
      "x": -8,
      "y": 0,
      "z": -8,
      "name": "Rock_Sandstone_Brick"
    },
    {
      "x": -8,
      "y": 1,
      "z": -8,
      "name": "Rock_Sandstone_Brick"
    },
    {
      "x": -8,
      "y": 2,
      "z": -8,
      "name": "Rock_Sandstone_Brick"
    },
    {
      "x": -8,
      "y": 3,
      "z": -8,
      "name": "Rock_Sandstone_Brick"
    },
    {
      "x": -8,
      "y": 4,
      "z": -8,
      "name": "Rock_Sandstone_Brick"
    },
    {
      "x": -8,
      "y": 5,
      "z": -8,
      "name": "Rock_Sandstone_Brick"
    },
    {
      "x": -8,
      "y": 6,
      "z": -8,
      "name": "Rock_Sandstone_Brick"
    },
    {
      "x": -8,
      "y": 7,
      "z": -8,
      "name": "Rock_Sandstone_Brick"
    },
    {
      "x": -8,
      "y": 8,
      "z": -8,
      "name": "Rock_Sandstone_Cobble"
    },
    {
      "x": -8,
      "y": 9,
      "z": -8,
      "name": "Rock_Sandstone_Brick"
    },
    {
      "x": -8,
      "y": 10,
      "z": -8,
      "name": "Rock_Sandstone_Cobble",
      "rotation": 3
    },
    {
      "x": -8,
      "y": 11,
      "z": -8,
      "name": "Rock_Sandstone_Brick",
      "rotation": 3
    },
    {
      "x": -8,
      "y": 12,
      "z": -8,
      "name": "Rock_Sandstone_Cobble",
      "rotation": 3
    },
    {
      "x": -8,
      "y": 13,
      "z": -8,
      "name": "Rock_Sandstone",
      "rotation": 3
    },
    {
      "x": -8,
      "y": 14,
      "z": -8,
      "name": "Rock_Sandstone_Brick",
      "rotation": 3
    },
    {
      "x": -8,
      "y": 15,
      "z": -8,
      "name": "Rock_Sandstone_Brick",
      "rotation": 3
    },
    {
      "x": -8,
      "y": 16,
      "z": -8,
      "name": "Rock_Sandstone_Brick",
      "rotation": 3
    },
    {
      "x": -8,
      "y": 17,
      "z": -8,
      "name": "Rock_Sandstone_Brick",
      "rotation": 3
    },
    {
      "x": -8,
      "y": 18,
      "z": -8,
      "name": "Rock_Sandstone_Brick",
      "rotation": 3
    },
    {
      "x": -8,
      "y": 19,
      "z": -8,
      "name": "Rock_Sandstone",
      "rotation": 3
    },
    {
      "x": -8,
      "y": 20,
      "z": -8,
      "name": "Rock_Sandstone_Brick",
      "rotation": 3
    },
    {
      "x": -8,
      "y": 21,
      "z": -8,
      "name": "Rock_Sandstone_Brick",
      "rotation": 3
    },
    {
      "x": -8,
      "y": 22,
      "z": -8,
      "name": "Rock_Sandstone_Brick",
      "rotation": 3
    },
    {
      "x": -8,
      "y": 23,
      "z": -8,
      "name": "Rock_Sandstone_Brick",
      "rotation": 3
    },
    {
      "x": -8,
      "y": 24,
      "z": -8,
      "name": "Rock_Sandstone_Brick",
      "rotation": 3
    },
    {
      "x": -8,
      "y": 25,
      "z": -8,
      "name": "Rock_Sandstone_Brick",
      "rotation": 3
    },
    {
      "x": -8,
      "y": 26,
      "z": -8,
      "name": "Rock_Sandstone",
      "rotation": 3
    },
    {
      "x": -8,
      "y": 0,
      "z": -7,
      "name": "Rock_Sandstone"
    },
    {
      "x": -8,
      "y": 1,
      "z": -7,
      "name": "Rock_Sandstone"
    },
    {
      "x": -8,
      "y": 2,
      "z": -7,
      "name": "Rock_Sandstone_Brick"
    },
    {
      "x": -8,
      "y": 3,
      "z": -7,
      "name": "Rock_Sandstone_Brick"
    },
    {
      "x": -8,
      "y": 4,
      "z": -7,
      "name": "Rock_Sandstone_Brick"
    },
    {
      "x": -8,
      "y": 5,
      "z": -7,
      "name": "Rock_Sandstone_Brick"
    },
    {
      "x": -8,
      "y": 6,
      "z": -7,
      "name": "Rock_Sandstone_Brick"
    },
    {
      "x": -8,
      "y": 7,
      "z": -7,
      "name": "Rock_Sandstone_Brick"
    },
    {
      "x": -8,
      "y": 8,
      "z": -7,
      "name": "Rock_Sandstone_Brick"
    },
    {
      "x": -8,
      "y": 9,
      "z": -7,
      "name": "Rock_Sandstone_Cobble"
    },
    {
      "x": -8,
      "y": 10,
      "z": -7,
      "name": "Rock_Sandstone_Brick",
      "rotation": 3
    },
    {
      "x": -8,
      "y": 11,
      "z": -7,
      "name": "Rock_Sandstone",
      "rotation": 3
    },
    {
      "x": -8,
      "y": 12,
      "z": -7,
      "name": "Rock_Sandstone_Brick",
      "rotation": 3
    },
    {
      "x": -8,
      "y": 13,
      "z": -7,
      "name": "Rock_Sandstone_Brick",
      "rotation": 3
    },
    {
      "x": -8,
      "y": 14,
      "z": -7,
      "name": "Rock_Sandstone_Brick",
      "rotation": 3
    },
    {
      "x": -8,
      "y": 15,
      "z": -7,
      "name": "Rock_Sandstone_Cobble",
      "rotation": 3
    },
    {
      "x": -8,
      "y": 16,
      "z": -7,
      "name": "Rock_Sandstone_Brick",
      "rotation": 3
    },
    {
      "x": -8,
      "y": 17,
      "z": -7,
      "name": "Rock_Sandstone",
      "rotation": 3
    },
    {
      "x": -8,
      "y": 18,
      "z": -7,
      "name": "Rock_Sandstone_Brick",
      "rotation": 3
    },
    {
      "x": -8,
      "y": 19,
      "z": -7,
      "name": "Rock_Sandstone_Brick",
      "rotation": 3
    },
    {
      "x": -8,
      "y": 20,
      "z": -7,
      "name": "Rock_Sandstone",
      "rotation": 3
    },
    {
      "x": -8,
      "y": 21,
      "z": -7,
      "name": "Rock_Sandstone_Brick",
      "rotation": 3
    },
    {
      "x": -8,
      "y": 22,
      "z": -7,
      "name": "Rock_Sandstone_Brick",
      "rotation": 3
    },
    {
      "x": -8,
      "y": 23,
      "z": -7,
      "name": "Rock_Sandstone_Cobble",
      "rotation": 3
    },
    {
      "x": -8,
      "y": 24,
      "z": -7,
      "name": "Rock_Sandstone_Brick",
      "rotation": 3
    },
    {
      "x": -8,
      "y": 25,
      "z": -7,
      "name": "Rock_Sandstone_Brick",
      "rotation": 3
    },
    {
      "x": -8,
      "y": 26,
      "z": -7,
      "name": "Rock_Sandstone_Cobble",
      "rotation": 3
    },
    {
      "x": -8,
      "y": 0,
      "z": -6,
      "name": "Rock_Sandstone_Brick"
    },
    {
      "x": -8,
      "y": 1,
      "z": -6,
      "name": "Rock_Sandstone_Brick"
    },
    {
      "x": -8,
      "y": 2,
      "z": -6,
      "name": "Rock_Sandstone_Brick"
    },
    {
      "x": -8,
      "y": 3,
      "z": -6,
      "name": "Rock_Sandstone_Brick"
    },
    {
      "x": -8,
      "y": 4,
      "z": -6,
      "name": "Rock_Sandstone_Brick"
    },
    {
      "x": -8,
      "y": 5,
      "z": -6,
      "name": "Rock_Sandstone_Brick"
    },
    {
      "x": -8,
      "y": 6,
      "z": -6,
      "name": "Rock_Sandstone_Brick"
    },
    {
      "x": -8,
      "y": 7,
      "z": -6,
      "name": "Rock_Sandstone_Brick"
    },
    {
      "x": -8,
      "y": 8,
      "z": -6,
      "name": "Rock_Sandstone_Brick"
    },
    {
      "x": -8,
      "y": 9,
      "z": -6,
      "name": "Rock_Sandstone_Brick"
    },
    {
      "x": -8,
      "y": 10,
      "z": -6,
      "name": "Rock_Sandstone_Cobble"
    },
    {
      "x": -8,
      "y": 11,
      "z": -6,
      "name": "Rock_Sandstone_Cobble"
    },
    {
      "x": -8,
      "y": 12,
      "z": -6,
      "name": "Rock_Sandstone_Brick"
    },
    {
      "x": -8,
      "y": 13,
      "z": -6,
      "name": "Rock_Sandstone_Brick"
    },
    {
      "x": -8,
      "y": 14,
      "z": -6,
      "name": "Rock_Sandstone_Brick"
    },
    {
      "x": -8,
      "y": 15,
      "z": -6,
      "name": "Rock_Sandstone_Brick"
    },
    {
      "x": -8,
      "y": 16,
      "z": -6,
      "name": "Rock_Sandstone"
    },
    {
      "x": -8,
      "y": 17,
      "z": -6,
      "name": "Rock_Sandstone"
    },
    {
      "x": -8,
      "y": 18,
      "z": -6,
      "name": "Rock_Sandstone_Brick"
    },
    {
      "x": -8,
      "y": 19,
      "z": -6,
      "name": "Rock_Sandstone_Cobble"
    },
    {
      "x": -8,
      "y": 20,
      "z": -6,
      "name": "Rock_Sandstone_Brick"
    },
    {
      "x": -8,
      "y": 21,
      "z": -6,
      "name": "Rock_Sandstone_Brick"
    },
    {
      "x": -8,
      "y": 22,
      "z": -6,
      "name": "Rock_Sandstone_Brick"
    },
    {
      "x": -8,
      "y": 23,
      "z": -6,
      "name": "Rock_Sandstone_Cobble"
    },
    {
      "x": -8,
      "y": 24,
      "z": -6,
      "name": "Rock_Sandstone"
    },
    {
      "x": -8,
      "y": 0,
      "z": -5,
      "name": "Rock_Sandstone_Brick"
    },
    {
      "x": -8,
      "y": 1,
      "z": -5,
      "name": "Rock_Sandstone_Brick"
    },
    {
      "x": -8,
      "y": 2,
      "z": -5,
      "name": "Rock_Sandstone_Cobble"
    },
    {
      "x": -8,
      "y": 3,
      "z": -5,
      "name": "Rock_Sandstone"
    },
    {
      "x": -8,
      "y": 4,
      "z": -5,
      "name": "Rock_Sandstone"
    },
    {
      "x": -8,
      "y": 5,
      "z": -5,
      "name": "Rock_Sandstone_Brick"
    },
    {
      "x": -8,
      "y": 6,
      "z": -5,
      "name": "Rock_Sandstone"
    },
    {
      "x": -8,
      "y": 7,
      "z": -5,
      "name": "Rock_Sandstone"
    },
    {
      "x": -8,
      "y": 8,
      "z": -5,
      "name": "Rock_Sandstone"
    },
    {
      "x": -8,
      "y": 9,
      "z": -5,
      "name": "Rock_Sandstone_Cobble"
    },
    {
      "x": -8,
      "y": 10,
      "z": -5,
      "name": "Rock_Sandstone_Brick"
    },
    {
      "x": -8,
      "y": 11,
      "z": -5,
      "name": "Rock_Sandstone_Brick"
    },
    {
      "x": -8,
      "y": 12,
      "z": -5,
      "name": "Rock_Sandstone_Brick"
    },
    {
      "x": -8,
      "y": 13,
      "z": -5,
      "name": "Rock_Sandstone_Brick"
    },
    {
      "x": -8,
      "y": 14,
      "z": -5,
      "name": "Rock_Sandstone_Brick"
    },
    {
      "x": -8,
      "y": 15,
      "z": -5,
      "name": "Rock_Sandstone_Cobble"
    },
    {
      "x": -8,
      "y": 16,
      "z": -5,
      "name": "Rock_Sandstone_Brick"
    },
    {
      "x": -8,
      "y": 17,
      "z": -5,
      "name": "Rock_Sandstone"
    },
    {
      "x": -8,
      "y": 18,
      "z": -5,
      "name": "Rock_Sandstone_Brick"
    },
    {
      "x": -8,
      "y": 19,
      "z": -5,
      "name": "Rock_Sandstone_Brick"
    },
    {
      "x": -8,
      "y": 20,
      "z": -5,
      "name": "Rock_Sandstone"
    },
    {
      "x": -8,
      "y": 21,
      "z": -5,
      "name": "Rock_Sandstone_Brick"
    },
    {
      "x": -8,
      "y": 22,
      "z": -5,
      "name": "Rock_Sandstone_Brick"
    },
    {
      "x": -8,
      "y": 52,
      "z": -4,
      "name": "Soil_Clay_Ocean_Brick_Smooth"
    },
    {
      "x": -8,
      "y": 41,
      "z": -3,
      "name": "Rock_Sandstone_Cobble",
      "rotation": 3
    },
    {
      "x": -8,
      "y": 42,
      "z": -3,
      "name": "Soil_Clay"
    },
    {
      "x": -8,
      "y": 43,
      "z": -3,
      "name": "Rock_Sandstone_Red_Brick"
    },
    {
      "x": -8,
      "y": 44,
      "z": -3,
      "name": "Soil_Clay_Smooth_Orange"
    },
    {
      "x": -8,
      "y": 45,
      "z": -3,
      "name": "Rock_Sandstone_Red_Brick"
    },
    {
      "x": -8,
      "y": 46,
      "z": -3,
      "name": "Rock_Sandstone_Red_Brick"
    },
    {
      "x": -8,
      "y": 47,
      "z": -3,
      "name": "Soil_Clay_Smooth_Orange"
    },
    {
      "x": -8,
      "y": 48,
      "z": -3,
      "name": "Soil_Clay"
    },
    {
      "x": -8,
      "y": 49,
      "z": -3,
      "name": "Soil_Clay"
    },
    {
      "x": -8,
      "y": 50,
      "z": -3,
      "name": "Soil_Sand_Red"
    },
    {
      "x": -8,
      "y": 51,
      "z": -3,
      "name": "Soil_Clay_Smooth_Orange"
    },
    {
      "x": -8,
      "y": 52,
      "z": -3,
      "name": "Soil_Clay_Ocean_Brick_Smooth"
    },
    {
      "x": -8,
      "y": 53,
      "z": -3,
      "name": "Soil_Clay_Ocean_Brick"
    },
    {
      "x": -8,
      "y": 54,
      "z": -3,
      "name": "Soil_Clay_Ocean_Brick"
    },
    {
      "x": -8,
      "y": 39,
      "z": -2,
      "name": "Rock_Sandstone_Cobble",
      "rotation": 3
    },
    {
      "x": -8,
      "y": 40,
      "z": -2,
      "name": "Rock_Sandstone_Brick",
      "rotation": 3
    },
    {
      "x": -8,
      "y": 41,
      "z": -2,
      "name": "Rock_Sandstone_Brick",
      "rotation": 3
    },
    {
      "x": -8,
      "y": 42,
      "z": -2,
      "name": "Rock_Sandstone_Cobble",
      "rotation": 3
    },
    {
      "x": -8,
      "y": 43,
      "z": -2,
      "name": "Rock_Sandstone_Brick",
      "rotation": 3
    },
    {
      "x": -8,
      "y": 44,
      "z": -2,
      "name": "Rock_Sandstone_Red_Brick"
    },
    {
      "x": -8,
      "y": 45,
      "z": -2,
      "name": "Soil_Clay"
    },
    {
      "x": -8,
      "y": 46,
      "z": -2,
      "name": "Rock_Sandstone_Red_Brick"
    },
    {
      "x": -8,
      "y": 47,
      "z": -2,
      "name": "Rock_Sandstone_Red_Brick"
    },
    {
      "x": -8,
      "y": 48,
      "z": -2,
      "name": "Soil_Clay"
    },
    {
      "x": -8,
      "y": 49,
      "z": -2,
      "name": "Soil_Clay"
    },
    {
      "x": -8,
      "y": 50,
      "z": -2,
      "name": "Soil_Sand_Red"
    },
    {
      "x": -8,
      "y": 51,
      "z": -2,
      "name": "Soil_Sand_Red"
    },
    {
      "x": -8,
      "y": 52,
      "z": -2,
      "name": "Soil_Clay_Ocean_Brick_Smooth"
    },
    {
      "x": -8,
      "y": 53,
      "z": -2,
      "name": "Soil_Clay_Ocean_Brick_Smooth"
    },
    {
      "x": -8,
      "y": 54,
      "z": -2,
      "name": "Soil_Clay_Ocean_Brick"
    },
    {
      "x": -8,
      "y": 36,
      "z": -1,
      "name": "Rock_Sandstone_Brick",
      "rotation": 3
    },
    {
      "x": -8,
      "y": 37,
      "z": -1,
      "name": "Rock_Sandstone_Brick",
      "rotation": 3
    },
    {
      "x": -8,
      "y": 38,
      "z": -1,
      "name": "Rock_Sandstone_Brick",
      "rotation": 3
    },
    {
      "x": -8,
      "y": 39,
      "z": -1,
      "name": "Rock_Sandstone_Brick",
      "rotation": 3
    },
    {
      "x": -8,
      "y": 40,
      "z": -1,
      "name": "Rock_Sandstone_Brick",
      "rotation": 3
    },
    {
      "x": -8,
      "y": 41,
      "z": -1,
      "name": "Rock_Sandstone_Brick",
      "rotation": 3
    },
    {
      "x": -8,
      "y": 42,
      "z": -1,
      "name": "Rock_Sandstone_Brick",
      "rotation": 3
    },
    {
      "x": -8,
      "y": 43,
      "z": -1,
      "name": "Rock_Sandstone_Brick",
      "rotation": 3
    },
    {
      "x": -8,
      "y": 44,
      "z": -1,
      "name": "Soil_Clay"
    },
    {
      "x": -8,
      "y": 45,
      "z": -1,
      "name": "Soil_Clay_Smooth_Orange"
    },
    {
      "x": -8,
      "y": 46,
      "z": -1,
      "name": "Rock_Sandstone_Red_Brick"
    },
    {
      "x": -8,
      "y": 47,
      "z": -1,
      "name": "Soil_Clay"
    },
    {
      "x": -8,
      "y": 48,
      "z": -1,
      "name": "Soil_Clay"
    },
    {
      "x": -8,
      "y": 49,
      "z": -1,
      "name": "Soil_Clay_Smooth_Orange"
    },
    {
      "x": -8,
      "y": 50,
      "z": -1,
      "name": "Soil_Clay_Smooth_Orange"
    },
    {
      "x": -8,
      "y": 51,
      "z": -1,
      "name": "Soil_Sand_Red"
    },
    {
      "x": -8,
      "y": 52,
      "z": -1,
      "name": "Soil_Clay_Ocean_Brick_Smooth"
    },
    {
      "x": -8,
      "y": 53,
      "z": -1,
      "name": "Soil_Clay_Ocean_Brick"
    },
    {
      "x": -8,
      "y": 54,
      "z": -1,
      "name": "Soil_Clay_Ocean_Brick"
    },
    {
      "x": -8,
      "y": 55,
      "z": -1,
      "name": "Soil_Clay_Ocean_Brick"
    },
    {
      "x": -8,
      "y": 38,
      "z": 0,
      "name": "Rock_Sandstone_Cobble",
      "rotation": 3
    },
    {
      "x": -8,
      "y": 39,
      "z": 0,
      "name": "Rock_Sandstone_Brick",
      "rotation": 3
    },
    {
      "x": -8,
      "y": 40,
      "z": 0,
      "name": "Rock_Sandstone_Cobble",
      "rotation": 3
    },
    {
      "x": -8,
      "y": 41,
      "z": 0,
      "name": "Rock_Sandstone_Cobble",
      "rotation": 3
    },
    {
      "x": -8,
      "y": 42,
      "z": 0,
      "name": "Rock_Sandstone_Brick",
      "rotation": 3
    },
    {
      "x": -8,
      "y": 43,
      "z": 0,
      "name": "Rock_Sandstone_Brick",
      "rotation": 3
    },
    {
      "x": -8,
      "y": 44,
      "z": 0,
      "name": "Soil_Clay"
    },
    {
      "x": -8,
      "y": 45,
      "z": 0,
      "name": "Soil_Clay"
    },
    {
      "x": -8,
      "y": 46,
      "z": 0,
      "name": "Rock_Sandstone_Red_Brick"
    },
    {
      "x": -8,
      "y": 47,
      "z": 0,
      "name": "Rock_Sandstone_Red_Brick"
    },
    {
      "x": -8,
      "y": 48,
      "z": 0,
      "name": "Soil_Clay"
    },
    {
      "x": -8,
      "y": 49,
      "z": 0,
      "name": "Soil_Clay"
    },
    {
      "x": -8,
      "y": 50,
      "z": 0,
      "name": "Soil_Clay_Smooth_Orange"
    },
    {
      "x": -8,
      "y": 51,
      "z": 0,
      "name": "Soil_Sand_Red"
    },
    {
      "x": -8,
      "y": 52,
      "z": 0,
      "name": "Soil_Clay_Ocean_Brick"
    },
    {
      "x": -8,
      "y": 53,
      "z": 0,
      "name": "Soil_Clay_Ocean_Brick"
    },
    {
      "x": -8,
      "y": 54,
      "z": 0,
      "name": "Soil_Clay_Ocean_Brick_Smooth"
    },
    {
      "x": -8,
      "y": 55,
      "z": 0,
      "name": "Soil_Clay_Ocean_Brick_Smooth"
    },
    {
      "x": -8,
      "y": 38,
      "z": 1,
      "name": "Rock_Sandstone_Brick",
      "rotation": 3
    },
    {
      "x": -8,
      "y": 39,
      "z": 1,
      "name": "Rock_Sandstone_Brick",
      "rotation": 3
    },
    {
      "x": -8,
      "y": 40,
      "z": 1,
      "name": "Rock_Sandstone_Cobble",
      "rotation": 3
    },
    {
      "x": -8,
      "y": 41,
      "z": 1,
      "name": "Rock_Sandstone_Brick",
      "rotation": 3
    },
    {
      "x": -8,
      "y": 42,
      "z": 1,
      "name": "Rock_Sandstone_Cobble",
      "rotation": 3
    },
    {
      "x": -8,
      "y": 43,
      "z": 1,
      "name": "Rock_Sandstone_Brick",
      "rotation": 3
    },
    {
      "x": -8,
      "y": 44,
      "z": 1,
      "name": "Rock_Sandstone_Cobble",
      "rotation": 3
    },
    {
      "x": -8,
      "y": 45,
      "z": 1,
      "name": "Rock_Sandstone_Brick",
      "rotation": 3
    },
    {
      "x": -8,
      "y": 46,
      "z": 1,
      "name": "Soil_Clay_Smooth_Orange"
    },
    {
      "x": -8,
      "y": 47,
      "z": 1,
      "name": "Soil_Clay_Smooth_Orange"
    },
    {
      "x": -8,
      "y": 48,
      "z": 1,
      "name": "Rock_Sandstone_Red_Brick"
    },
    {
      "x": -8,
      "y": 49,
      "z": 1,
      "name": "Soil_Clay_Smooth_Orange"
    },
    {
      "x": -8,
      "y": 50,
      "z": 1,
      "name": "Soil_Sand_Red"
    },
    {
      "x": -8,
      "y": 51,
      "z": 1,
      "name": "Soil_Sand_Red"
    },
    {
      "x": -8,
      "y": 52,
      "z": 1,
      "name": "Soil_Clay_Ocean_Brick"
    },
    {
      "x": -8,
      "y": 53,
      "z": 1,
      "name": "Soil_Clay_Ocean_Brick_Smooth"
    },
    {
      "x": -8,
      "y": 54,
      "z": 1,
      "name": "Soil_Clay_Ocean_Brick"
    },
    {
      "x": -8,
      "y": 55,
      "z": 1,
      "name": "Soil_Clay_Ocean_Brick"
    },
    {
      "x": -8,
      "y": 38,
      "z": 2,
      "name": "Rock_Sandstone_Brick",
      "rotation": 3
    },
    {
      "x": -8,
      "y": 39,
      "z": 2,
      "name": "Rock_Sandstone_Brick",
      "rotation": 3
    },
    {
      "x": -8,
      "y": 40,
      "z": 2,
      "name": "Rock_Sandstone_Cobble",
      "rotation": 3
    },
    {
      "x": -8,
      "y": 41,
      "z": 2,
      "name": "Rock_Sandstone_Brick",
      "rotation": 3
    },
    {
      "x": -8,
      "y": 42,
      "z": 2,
      "name": "Rock_Sandstone_Cobble",
      "rotation": 3
    },
    {
      "x": -8,
      "y": 43,
      "z": 2,
      "name": "Rock_Sandstone_Brick",
      "rotation": 3
    },
    {
      "x": -8,
      "y": 44,
      "z": 2,
      "name": "Rock_Sandstone_Brick",
      "rotation": 3
    },
    {
      "x": -8,
      "y": 45,
      "z": 2,
      "name": "Rock_Sandstone_Brick",
      "rotation": 3
    },
    {
      "x": -8,
      "y": 46,
      "z": 2,
      "name": "Rock_Sandstone_Red_Brick"
    },
    {
      "x": -8,
      "y": 47,
      "z": 2,
      "name": "Soil_Clay"
    },
    {
      "x": -8,
      "y": 48,
      "z": 2,
      "name": "Soil_Clay"
    },
    {
      "x": -8,
      "y": 49,
      "z": 2,
      "name": "Soil_Clay"
    },
    {
      "x": -8,
      "y": 50,
      "z": 2,
      "name": "Soil_Sand_Red"
    },
    {
      "x": -8,
      "y": 51,
      "z": 2,
      "name": "Soil_Sand_Red"
    },
    {
      "x": -8,
      "y": 52,
      "z": 2,
      "name": "Soil_Clay_Ocean_Brick_Smooth"
    },
    {
      "x": -8,
      "y": 53,
      "z": 2,
      "name": "Soil_Clay_Ocean_Brick_Smooth"
    },
    {
      "x": -8,
      "y": 54,
      "z": 2,
      "name": "Soil_Clay_Ocean_Brick"
    },
    {
      "x": -8,
      "y": 55,
      "z": 2,
      "name": "Soil_Clay_Ocean_Brick_Smooth"
    },
    {
      "x": -8,
      "y": 33,
      "z": 3,
      "name": "Rock_Sandstone_Brick"
    },
    {
      "x": -8,
      "y": 34,
      "z": 3,
      "name": "Rock_Sandstone_Brick"
    },
    {
      "x": -8,
      "y": 35,
      "z": 3,
      "name": "Rock_Sandstone_Brick"
    },
    {
      "x": -8,
      "y": 36,
      "z": 3,
      "name": "Rock_Sandstone_White_Cobble"
    },
    {
      "x": -8,
      "y": 40,
      "z": 3,
      "name": "Rock_Sandstone_Brick",
      "rotation": 3
    },
    {
      "x": -8,
      "y": 41,
      "z": 3,
      "name": "Rock_Sandstone_Brick",
      "rotation": 3
    },
    {
      "x": -8,
      "y": 42,
      "z": 3,
      "name": "Rock_Sandstone_Cobble",
      "rotation": 3
    },
    {
      "x": -8,
      "y": 43,
      "z": 3,
      "name": "Rock_Sandstone_Brick",
      "rotation": 3
    },
    {
      "x": -8,
      "y": 44,
      "z": 3,
      "name": "Rock_Sandstone_Brick",
      "rotation": 3
    },
    {
      "x": -8,
      "y": 45,
      "z": 3,
      "name": "Rock_Sandstone_Cobble",
      "rotation": 3
    },
    {
      "x": -8,
      "y": 46,
      "z": 3,
      "name": "Soil_Clay_Smooth_Orange"
    },
    {
      "x": -8,
      "y": 47,
      "z": 3,
      "name": "Rock_Sandstone_Red_Brick"
    },
    {
      "x": -8,
      "y": 48,
      "z": 3,
      "name": "Soil_Clay_Smooth_Orange"
    },
    {
      "x": -8,
      "y": 49,
      "z": 3,
      "name": "Soil_Clay"
    },
    {
      "x": -8,
      "y": 50,
      "z": 3,
      "name": "Soil_Sand_Red"
    },
    {
      "x": -8,
      "y": 51,
      "z": 3,
      "name": "Soil_Sand_Red"
    },
    {
      "x": -8,
      "y": 52,
      "z": 3,
      "name": "Soil_Clay_Ocean_Brick_Smooth"
    },
    {
      "x": -8,
      "y": 53,
      "z": 3,
      "name": "Soil_Clay_Ocean_Brick"
    },
    {
      "x": -8,
      "y": 54,
      "z": 3,
      "name": "Soil_Clay_Ocean_Brick"
    },
    {
      "x": -8,
      "y": 55,
      "z": 3,
      "name": "Soil_Clay_Ocean_Brick"
    },
    {
      "x": -8,
      "y": 30,
      "z": 4,
      "name": "Rock_Sandstone_Brick_Stairs",
      "rotation": 8
    },
    {
      "x": -8,
      "y": 31,
      "z": 4,
      "name": "Rock_Sandstone"
    },
    {
      "x": -8,
      "y": 32,
      "z": 4,
      "name": "Rock_Sandstone_Cobble"
    },
    {
      "x": -8,
      "y": 33,
      "z": 4,
      "name": "Rock_Sandstone_Brick"
    },
    {
      "x": -8,
      "y": 34,
      "z": 4,
      "name": "Rock_Sandstone_Brick"
    },
    {
      "x": -8,
      "y": 35,
      "z": 4,
      "name": "Rock_Sandstone_Brick"
    },
    {
      "x": -8,
      "y": 36,
      "z": 4,
      "name": "Rock_Sandstone_White_Cobble"
    },
    {
      "x": -8,
      "y": 37,
      "z": 4,
      "name": "Rock_Sandstone_White_Cobble"
    },
    {
      "x": -8,
      "y": 40,
      "z": 4,
      "name": "Rock_Sandstone_Brick",
      "rotation": 3
    },
    {
      "x": -8,
      "y": 41,
      "z": 4,
      "name": "Rock_Sandstone_Brick",
      "rotation": 3
    },
    {
      "x": -8,
      "y": 42,
      "z": 4,
      "name": "Rock_Sandstone_Brick",
      "rotation": 3
    },
    {
      "x": -8,
      "y": 43,
      "z": 4,
      "name": "Rock_Sandstone_Brick",
      "rotation": 3
    },
    {
      "x": -8,
      "y": 44,
      "z": 4,
      "name": "Rock_Sandstone_Brick",
      "rotation": 3
    },
    {
      "x": -8,
      "y": 45,
      "z": 4,
      "name": "Rock_Sandstone_Brick",
      "rotation": 3
    },
    {
      "x": -8,
      "y": 46,
      "z": 4,
      "name": "Rock_Sandstone_Red_Brick"
    },
    {
      "x": -8,
      "y": 47,
      "z": 4,
      "name": "Soil_Clay_Smooth_Orange"
    },
    {
      "x": -8,
      "y": 48,
      "z": 4,
      "name": "Rock_Sandstone_Red_Brick"
    },
    {
      "x": -8,
      "y": 49,
      "z": 4,
      "name": "Soil_Clay"
    },
    {
      "x": -8,
      "y": 50,
      "z": 4,
      "name": "Soil_Sand_Red"
    },
    {
      "x": -8,
      "y": 51,
      "z": 4,
      "name": "Soil_Clay_Smooth_Orange"
    },
    {
      "x": -8,
      "y": 52,
      "z": 4,
      "name": "Soil_Clay_Ocean_Brick_Smooth"
    },
    {
      "x": -8,
      "y": 53,
      "z": 4,
      "name": "Soil_Clay_Ocean_Brick"
    },
    {
      "x": -8,
      "y": 54,
      "z": 4,
      "name": "Soil_Clay_Ocean_Brick"
    },
    {
      "x": -8,
      "y": 27,
      "z": 5,
      "name": "Rock_Sandstone_Brick_Stairs",
      "rotation": 8
    },
    {
      "x": -8,
      "y": 28,
      "z": 5,
      "name": "Rock_Sandstone_Brick"
    },
    {
      "x": -8,
      "y": 29,
      "z": 5,
      "name": "Rock_Sandstone_Brick"
    },
    {
      "x": -8,
      "y": 30,
      "z": 5,
      "name": "Rock_Sandstone"
    },
    {
      "x": -8,
      "y": 31,
      "z": 5,
      "name": "Rock_Sandstone_Brick"
    },
    {
      "x": -8,
      "y": 32,
      "z": 5,
      "name": "Rock_Sandstone_Cobble"
    },
    {
      "x": -8,
      "y": 33,
      "z": 5,
      "name": "Rock_Sandstone_Brick"
    },
    {
      "x": -8,
      "y": 34,
      "z": 5,
      "name": "Rock_Sandstone_Brick"
    },
    {
      "x": -8,
      "y": 35,
      "z": 5,
      "name": "Rock_Sandstone_Brick"
    },
    {
      "x": -8,
      "y": 36,
      "z": 5,
      "name": "Rock_Sandstone_Red_Cobble"
    },
    {
      "x": -8,
      "y": 37,
      "z": 5,
      "name": "Rock_Sandstone_Red_Cobble"
    },
    {
      "x": -8,
      "y": 38,
      "z": 5,
      "name": "Rock_Sandstone_Red_Cobble"
    },
    {
      "x": -8,
      "y": 39,
      "z": 5,
      "name": "Rock_Sandstone_Red"
    },
    {
      "x": -8,
      "y": 40,
      "z": 5,
      "name": "Rock_Sandstone_Cobble",
      "rotation": 3
    },
    {
      "x": -8,
      "y": 41,
      "z": 5,
      "name": "Rock_Sandstone_Brick",
      "rotation": 3
    },
    {
      "x": -8,
      "y": 42,
      "z": 5,
      "name": "Rock_Sandstone_Brick",
      "rotation": 3
    },
    {
      "x": -8,
      "y": 43,
      "z": 5,
      "name": "Rock_Sandstone_Cobble",
      "rotation": 3
    },
    {
      "x": -8,
      "y": 44,
      "z": 5,
      "name": "Rock_Sandstone_Cobble",
      "rotation": 3
    },
    {
      "x": -8,
      "y": 45,
      "z": 5,
      "name": "Rock_Sandstone_Brick",
      "rotation": 3
    },
    {
      "x": -8,
      "y": 52,
      "z": 5,
      "name": "Soil_Clay_Ocean_Brick"
    },
    {
      "x": -8,
      "y": 53,
      "z": 5,
      "name": "Soil_Clay_Ocean_Brick"
    },
    {
      "x": -8,
      "y": 54,
      "z": 5,
      "name": "Soil_Clay_Ocean_Brick"
    },
    {
      "x": -8,
      "y": 0,
      "z": 6,
      "name": "Rock_Sandstone_Brick"
    },
    {
      "x": -8,
      "y": 1,
      "z": 6,
      "name": "Rock_Sandstone_Brick"
    },
    {
      "x": -8,
      "y": 2,
      "z": 6,
      "name": "Rock_Sandstone"
    },
    {
      "x": -8,
      "y": 3,
      "z": 6,
      "name": "Rock_Sandstone_Brick"
    },
    {
      "x": -8,
      "y": 4,
      "z": 6,
      "name": "Rock_Sandstone_Brick"
    },
    {
      "x": -8,
      "y": 5,
      "z": 6,
      "name": "Rock_Sandstone_Cobble"
    },
    {
      "x": -8,
      "y": 6,
      "z": 6,
      "name": "Rock_Sandstone_Brick"
    },
    {
      "x": -8,
      "y": 7,
      "z": 6,
      "name": "Rock_Sandstone_Cobble"
    },
    {
      "x": -8,
      "y": 8,
      "z": 6,
      "name": "Rock_Sandstone_Brick"
    },
    {
      "x": -8,
      "y": 9,
      "z": 6,
      "name": "Rock_Sandstone"
    },
    {
      "x": -8,
      "y": 10,
      "z": 6,
      "name": "Rock_Sandstone"
    },
    {
      "x": -8,
      "y": 11,
      "z": 6,
      "name": "Rock_Sandstone_Brick"
    },
    {
      "x": -8,
      "y": 12,
      "z": 6,
      "name": "Rock_Sandstone"
    },
    {
      "x": -8,
      "y": 13,
      "z": 6,
      "name": "Rock_Sandstone_Brick"
    },
    {
      "x": -8,
      "y": 14,
      "z": 6,
      "name": "Rock_Sandstone"
    },
    {
      "x": -8,
      "y": 15,
      "z": 6,
      "name": "Rock_Sandstone_Brick"
    },
    {
      "x": -8,
      "y": 16,
      "z": 6,
      "name": "Rock_Sandstone"
    },
    {
      "x": -8,
      "y": 17,
      "z": 6,
      "name": "Rock_Sandstone_Cobble"
    },
    {
      "x": -8,
      "y": 18,
      "z": 6,
      "name": "Rock_Sandstone"
    },
    {
      "x": -8,
      "y": 19,
      "z": 6,
      "name": "Rock_Sandstone_Brick"
    },
    {
      "x": -8,
      "y": 20,
      "z": 6,
      "name": "Rock_Sandstone_Cobble"
    },
    {
      "x": -8,
      "y": 21,
      "z": 6,
      "name": "Rock_Sandstone_Brick"
    },
    {
      "x": -8,
      "y": 22,
      "z": 6,
      "name": "Rock_Sandstone"
    },
    {
      "x": -8,
      "y": 23,
      "z": 6,
      "name": "Rock_Sandstone_Brick"
    },
    {
      "x": -8,
      "y": 24,
      "z": 6,
      "name": "Rock_Sandstone_Brick"
    },
    {
      "x": -8,
      "y": 25,
      "z": 6,
      "name": "Rock_Sandstone_Brick"
    },
    {
      "x": -8,
      "y": 26,
      "z": 6,
      "name": "Rock_Sandstone_Brick"
    },
    {
      "x": -8,
      "y": 27,
      "z": 6,
      "name": "Rock_Sandstone_Brick"
    },
    {
      "x": -8,
      "y": 28,
      "z": 6,
      "name": "Rock_Sandstone_Brick"
    },
    {
      "x": -8,
      "y": 29,
      "z": 6,
      "name": "Rock_Sandstone_Brick"
    },
    {
      "x": -8,
      "y": 30,
      "z": 6,
      "name": "Rock_Sandstone_Brick"
    },
    {
      "x": -8,
      "y": 31,
      "z": 6,
      "name": "Rock_Sandstone"
    },
    {
      "x": -8,
      "y": 32,
      "z": 6,
      "name": "Rock_Sandstone_Cobble"
    },
    {
      "x": -8,
      "y": 33,
      "z": 6,
      "name": "Rock_Sandstone_Brick"
    },
    {
      "x": -8,
      "y": 34,
      "z": 6,
      "name": "Rock_Sandstone_Brick"
    },
    {
      "x": -8,
      "y": 35,
      "z": 6,
      "name": "Rock_Sandstone_Brick"
    },
    {
      "x": -8,
      "y": 52,
      "z": 6,
      "name": "Soil_Clay_Ocean_Brick"
    },
    {
      "x": -8,
      "y": 0,
      "z": 7,
      "name": "Rock_Sandstone_Brick"
    },
    {
      "x": -8,
      "y": 1,
      "z": 7,
      "name": "Rock_Sandstone_Brick"
    },
    {
      "x": -8,
      "y": 2,
      "z": 7,
      "name": "Rock_Sandstone"
    },
    {
      "x": -8,
      "y": 3,
      "z": 7,
      "name": "Rock_Sandstone_Brick"
    },
    {
      "x": -8,
      "y": 4,
      "z": 7,
      "name": "Rock_Sandstone_Cobble"
    },
    {
      "x": -8,
      "y": 5,
      "z": 7,
      "name": "Rock_Sandstone_Brick"
    },
    {
      "x": -8,
      "y": 6,
      "z": 7,
      "name": "Rock_Sandstone"
    },
    {
      "x": -8,
      "y": 7,
      "z": 7,
      "name": "Rock_Sandstone_Brick"
    },
    {
      "x": -8,
      "y": 8,
      "z": 7,
      "name": "Rock_Sandstone_Brick"
    },
    {
      "x": -8,
      "y": 9,
      "z": 7,
      "name": "Rock_Sandstone"
    },
    {
      "x": -8,
      "y": 10,
      "z": 7,
      "name": "Rock_Sandstone_Cobble"
    },
    {
      "x": -8,
      "y": 11,
      "z": 7,
      "name": "Rock_Sandstone_Cobble"
    },
    {
      "x": -8,
      "y": 12,
      "z": 7,
      "name": "Rock_Sandstone"
    },
    {
      "x": -8,
      "y": 13,
      "z": 7,
      "name": "Rock_Sandstone_Brick"
    },
    {
      "x": -8,
      "y": 14,
      "z": 7,
      "name": "Rock_Sandstone_Brick"
    },
    {
      "x": -8,
      "y": 15,
      "z": 7,
      "name": "Rock_Sandstone"
    },
    {
      "x": -8,
      "y": 16,
      "z": 7,
      "name": "Rock_Sandstone"
    },
    {
      "x": -8,
      "y": 17,
      "z": 7,
      "name": "Rock_Sandstone_Brick"
    },
    {
      "x": -8,
      "y": 18,
      "z": 7,
      "name": "Rock_Sandstone_Brick"
    },
    {
      "x": -8,
      "y": 19,
      "z": 7,
      "name": "Rock_Sandstone_Brick"
    },
    {
      "x": -8,
      "y": 20,
      "z": 7,
      "name": "Rock_Sandstone_Brick"
    },
    {
      "x": -8,
      "y": 21,
      "z": 7,
      "name": "Rock_Sandstone_Brick"
    },
    {
      "x": -8,
      "y": 22,
      "z": 7,
      "name": "Rock_Sandstone_Brick"
    },
    {
      "x": -8,
      "y": 23,
      "z": 7,
      "name": "Rock_Sandstone_Brick"
    },
    {
      "x": -8,
      "y": 24,
      "z": 7,
      "name": "Rock_Sandstone_Brick"
    },
    {
      "x": -8,
      "y": 25,
      "z": 7,
      "name": "Rock_Sandstone_Brick"
    },
    {
      "x": -8,
      "y": 26,
      "z": 7,
      "name": "Rock_Sandstone_Cobble"
    },
    {
      "x": -8,
      "y": 27,
      "z": 7,
      "name": "Rock_Sandstone"
    },
    {
      "x": -8,
      "y": 28,
      "z": 7,
      "name": "Rock_Sandstone_Brick"
    },
    {
      "x": -8,
      "y": 29,
      "z": 7,
      "name": "Rock_Sandstone_Brick"
    },
    {
      "x": -8,
      "y": 30,
      "z": 7,
      "name": "Rock_Sandstone_Brick"
    },
    {
      "x": -8,
      "y": 31,
      "z": 7,
      "name": "Rock_Sandstone_Brick"
    },
    {
      "x": -8,
      "y": 32,
      "z": 7,
      "name": "Rock_Sandstone_Brick"
    },
    {
      "x": -8,
      "y": 33,
      "z": 7,
      "name": "Rock_Sandstone_Brick"
    },
    {
      "x": -8,
      "y": 34,
      "z": 7,
      "name": "Rock_Sandstone_Brick"
    },
    {
      "x": -8,
      "y": 35,
      "z": 7,
      "name": "Rock_Sandstone_Brick"
    },
    {
      "x": -8,
      "y": 0,
      "z": 8,
      "name": "Rock_Sandstone_Brick"
    },
    {
      "x": -8,
      "y": 1,
      "z": 8,
      "name": "Rock_Sandstone"
    },
    {
      "x": -8,
      "y": 2,
      "z": 8,
      "name": "Rock_Sandstone"
    },
    {
      "x": -8,
      "y": 3,
      "z": 8,
      "name": "Rock_Sandstone_Cobble"
    },
    {
      "x": -8,
      "y": 4,
      "z": 8,
      "name": "Rock_Sandstone_Brick"
    },
    {
      "x": -8,
      "y": 5,
      "z": 8,
      "name": "Rock_Sandstone_Brick"
    },
    {
      "x": -8,
      "y": 6,
      "z": 8,
      "name": "Rock_Sandstone_Brick"
    },
    {
      "x": -8,
      "y": 7,
      "z": 8,
      "name": "Rock_Sandstone_Brick"
    },
    {
      "x": -8,
      "y": 8,
      "z": 8,
      "name": "Rock_Sandstone_Brick"
    },
    {
      "x": -8,
      "y": 9,
      "z": 8,
      "name": "Rock_Sandstone"
    },
    {
      "x": -8,
      "y": 10,
      "z": 8,
      "name": "Rock_Sandstone_Brick"
    },
    {
      "x": -8,
      "y": 11,
      "z": 8,
      "name": "Rock_Sandstone_Brick",
