{
  "version": 8,
  "blockIdVersion": 10,
  "anchorX": 0,
  "anchorY": 3,
  "anchorZ": 0,
  "blocks": [
    {
      "x": -1,
      "y": 4,
      "z": 0,
      "name": "Plant_Moss_Block_Yellow"
    },
    {
      "x": 1,
      "y": 4,
      "z": 0,
      "name": "Rock_Volcanic_Cracked_Poisoned"
    },
    {
      "x": 2,
      "y": 4,
      "z": 0,
      "name": "Plant_Moss_Block_Yellow"
    },
    {
      "x": 3,
      "y": 4,
      "z": 0,
      "name": "Plant_Moss_Block_Yellow"
    },
    {
      "x": -1,
      "y": 5,
      "z": 0,
      "name": "Plant_Moss_Block_Yellow"
    },
    {
      "x": 2,
      "y": 5,
      "z": 0,
      "name": "Rock_Volcanic_Cracked_Poisoned"
    },
    {
      "x": 3,
      "y": 5,
      "z": 0,
      "name": "Plant_Moss_Block_Yellow"
    },
    {
      "x": 3,
      "y": 6,
      "z": 0,
      "name": "Plant_Moss_Block_Yellow"
    },
    {
      "x": -1,
      "y": 4,
      "z": 1,
      "name": "Wood_Wisteria_Wild_Trunk_Full"
    },
    {
      "x": 0,
      "y": 4,
      "z": 1,
      "name": "Rock_Volcanic_Cracked_Poisoned"
    },
    {
      "x": 1,
      "y": 4,
      "z": 1,
      "name": "Rock_Volcanic_Cracked_Poisoned"
    },
    {
      "x": 2,
      "y": 4,
      "z": 1,
      "name": "Plant_Moss_Block_Yellow"
    },
    {
      "x": -1,
      "y": 5,
      "z": 1,
      "name": "Rock_Volcanic_Cracked_Poisoned"
    },
    {
      "x": 2,
      "y": 5,
      "z": 1,
      "name": "Rock_Volcanic_Cracked_Poisoned"
    },
    {
      "x": 3,
      "y": 5,
      "z": 1,
      "name": "Plant_Moss_Block_Yellow"
    },
    {
      "x": 3,
      "y": 6,
      "z": 1,
      "name": "Plant_Moss_Block_Yellow"
    },
    {
      "x": 0,
      "y": 4,
      "z": 2,
      "name": "Plant_Moss_Block_Yellow"
    },
    {
      "x": 1,
      "y": 4,
      "z": 2,
      "name": "Plant_Moss_Block_Yellow"
    },
    {
      "x": 2,
      "y": 4,
      "z": 2,
      "name": "Plant_Moss_Block_Yellow"
    },
    {
      "x": -1,
      "y": 5,
      "z": 2,
      "name": "Plant_Moss_Block_Yellow"
    },
    {
      "x": 0,
      "y": 5,
      "z": 2,
      "name": "Rock_Volcanic_Cracked_Poisoned"
    },
    {
      "x": 1,
      "y": 5,
      "z": 2,
      "name": "Rock_Volcanic_Cracked_Poisoned"
    },
    {
      "x": 2,
      "y": 5,
      "z": 2,
      "name": "Plant_Moss_Block_Yellow"
    },
    {
      "x": -1,
      "y": 6,
      "z": 2,
      "name": "Plant_Moss_Block_Yellow"
    },
    {
      "x": 2,
      "y": 6,
      "z": 2,
      "name": "Plant_Moss_Block_Yellow"
    },
    {
      "x": 0,
      "y": 5,
      "z": 3,
      "name": "Plant_Moss_Block_Yellow"
    },
    {
      "x": 1,
      "y": 5,
      "z": 3,
      "name": "Plant_Moss_Block_Yellow"
    },
    {
      "x": 0,
      "y": 6,
      "z": 3,
      "name": "Plant_Moss_Block_Yellow"
    },
    {
      "x": 1,
      "y": 6,
      "z": 3,
      "name": "Plant_Moss_Block_Yellow"
    },
    {
      "x": 0,
      "y": 0,
      "z": -1,
      "name": "Wood_Wisteria_Wild_Trunk_Full"
    },
    {
      "x": 1,
      "y": 0,
      "z": -1,
      "name": "Wood_Wisteria_Wild_Trunk_Full"
    },
    {
      "x": 0,
      "y": 1,
      "z": -1,
      "name": "Wood_Wisteria_Wild_Trunk_Full"
    },
    {
      "x": 1,
      "y": 1,
      "z": -1,
      "name": "Wood_Wisteria_Wild_Trunk_Full"
    },
    {
      "x": 0,
      "y": 2,
      "z": -1,
      "name": "Wood_Wisteria_Wild_Trunk_Full"
    },
    {
      "x": 1,
      "y": 2,
      "z": -1,
      "name": "Wood_Wisteria_Wild_Trunk_Full"
    },
    {
      "x": 0,
      "y": 3,
      "z": -1,
      "name": "Wood_Wisteria_Wild_Trunk_Full"
    },
    {
      "x": 1,
      "y": 3,
      "z": -1,
      "name": "Wood_Wisteria_Wild_Trunk_Full"
    },
    {
      "x": 2,
      "y": 3,
      "z": -1,
      "name": "Wood_Wisteria_Wild_Trunk_Full"
    },
    {
      "x": 0,
      "y": 4,
      "z": -2,
      "name": "Wood_Wisteria_Wild_Trunk_Full"
    },
    {
      "x": 1,
      "y": 4,
      "z": -2,
      "name": "Wood_Wisteria_Wild_Trunk_Full"
    },
    {
      "x": 0,
      "y": 5,
      "z": -2,
      "name": "Wood_Wisteria_Wild_Trunk_Full"
    },
    {
      "x": 1,
      "y": 5,
      "z": -2,
      "name": "Plant_Moss_Block_Yellow"
    },
    {
      "x": 0,
      "y": 6,
      "z": -2,
      "name": "Plant_Moss_Block_Yellow"
    },
    {
      "x": 1,
      "y": 6,
      "z": -2,
      "name": "Plant_Moss_Block_Yellow"
    },
    {
      "x": -1,
      "y": 4,
      "z": -1,
      "name": "Wood_Wisteria_Wild_Trunk_Full"
    },
    {
      "x": 0,
      "y": 4,
      "z": -1,
      "name": "Plant_Moss_Block_Yellow"
    },
    {
      "x": 1,
      "y": 4,
      "z": -1,
      "name": "Plant_Moss_Block_Yellow"
    },
    {
      "x": 2,
      "y": 4,
      "z": -1,
      "name": "Plant_Moss_Block_Yellow"
    },
    {
      "x": -1,
      "y": 5,
      "z": -1,
      "name": "Wood_Wisteria_Wild_Trunk_Full"
    },
    {
      "x": 0,
      "y": 5,
      "z": -1,
      "name": "Rock_Volcanic_Cracked_Poisoned"
    },
    {
      "x": 1,
      "y": 5,
      "z": -1,
      "name": "Rock_Volcanic_Cracked_Poisoned"
    },
    {
      "x": 2,
      "y": 5,
      "z": -1,
      "name": "Plant_Moss_Block_Yellow"
    },
    {
      "x": -1,
      "y": 6,
      "z": -1,
      "name": "Plant_Moss_Block_Yellow"
    },
    {
      "x": 2,
      "y": 6,
      "z": -1,
      "name": "Plant_Moss_Block_Yellow"
    },
    {
      "x": -1,
      "y": 0,
      "z": 0,
      "name": "Wood_Wisteria_Wild_Trunk_Full"
    },
    {
      "x": 1,
      "y": 0,
      "z": 0,
      "name": "Wood_Wisteria_Wild_Trunk_Full"
    },
    {
      "x": -1,
      "y": 1,
      "z": 0,
      "name": "Wood_Wisteria_Wild_Trunk_Full"
    },
    {
      "x": 1,
      "y": 1,
      "z": 0,
      "name": "Wood_Wisteria_Wild_Trunk_Full"
    },
    {
      "x": -1,
      "y": 2,
      "z": 0,
      "name": "Wood_Wisteria_Wild_Trunk_Full"
    },
    {
      "x": 1,
      "y": 2,
      "z": 0,
      "name": "Wood_Wisteria_Wild_Trunk_Full"
    },
    {
      "x": -1,
      "y": 3,
      "z": 0,
      "name": "Wood_Wisteria_Wild_Trunk_Full"
    },
    {
      "x": 0,
      "y": 3,
      "z": 0,
      "name": "Rock_Volcanic_Cracked_Poisoned"
    },
    {
      "x": 1,
      "y": 3,
      "z": 0,
      "name": "Plant_Moss_Block_Yellow"
    },
    {
      "x": 2,
      "y": 3,
      "z": 0,
      "name": "Wood_Wisteria_Wild_Trunk_Full"
    },
    {
      "x": 0,
      "y": 0,
      "z": 1,
      "name": "Wood_Wisteria_Wild_Trunk_Full"
    },
    {
      "x": 1,
      "y": 0,
      "z": 1,
      "name": "Wood_Wisteria_Wild_Trunk_Full"
    },
    {
      "x": 0,
      "y": 1,
      "z": 1,
      "name": "Wood_Wisteria_Wild_Trunk_Full"
    },
    {
      "x": 1,
      "y": 1,
      "z": 1,
      "name": "Wood_Wisteria_Wild_Trunk_Full"
    },
    {
      "x": 0,
      "y": 2,
      "z": 1,
      "name": "Wood_Wisteria_Wild_Trunk_Full"
    },
    {
      "x": 1,
      "y": 2,
      "z": 1,
      "name": "Wood_Wisteria_Wild_Trunk_Full"
    },
    {
      "x": 0,
      "y": 3,
      "z": 1,
      "name": "Plant_Moss_Block_Yellow"
    },
    {
      "x": 1,
      "y": 3,
      "z": 1,
      "name": "Plant_Moss_Block_Yellow"
    },
    {
      "x": 2,
      "y": 3,
      "z": 1,
      "name": "Wood_Wisteria_Wild_Trunk_Full"
    },
    {
      "x": 1,
      "y": 3,
      "z": 2,
      "name": "Plant_Moss_Block_Yellow"
    },
    {
      "x": -2,
      "y": 6,
      "z": 0,
      "name": "Plant_Moss_Block_Yellow"
    },
    {
      "x": -2,
      "y": 5,
      "z": 1,
      "name": "Plant_Moss_Block_Yellow"
    },
    {
      "x": -2,
      "y": 6,
      "z": 1,
      "name": "Plant_Moss_Block_Yellow"
    }
  ],
  "fluids": [],
  "entities": []
}