{
  "version": 8,
  "blockIdVersion": 10,
  "anchorX": 0,
  "anchorY": 3,
  "anchorZ": 0,
  "blocks": [
    {
      "x": 4,
      "y": 8,
      "z": 0,
      "name": "Plant_Seaweed_Navi_Stack"
    },
    {
      "x": 6,
      "y": 8,
      "z": 0,
      "name": "Plant_Seaweed_Navi_Stack"
    },
    {
      "x": 8,
      "y": 8,
      "z": 0,
      "name": "Plant_Coral_Block_Cyan"
    },
    {
      "x": 10,
      "y": 8,
      "z": 0,
      "name": "Plant_Seaweed_Navi_Stack"
    },
    {
      "x": 13,
      "y": 8,
      "z": 0,
      "name": "Wood_Azure_Trunk_Full"
    },
    {
      "x": 14,
      "y": 8,
      "z": 0,
      "name": "Wood_Azure_Trunk_Full"
    },
    {
      "x": 15,
      "y": 8,
      "z": 0,
      "name": "Wood_Azure_Trunk_Full"
    },
    {
      "x": 4,
      "y": 9,
      "z": 0,
      "name": "Plant_Seaweed_Navi_Stack"
    },
    {
      "x": 6,
      "y": 9,
      "z": 0,
      "name": "Plant_Seaweed_Navi_Stack"
    },
    {
      "x": 8,
      "y": 9,
      "z": 0,
      "name": "Plant_Seaweed_Navi_Stack"
    },
    {
      "x": 10,
      "y": 9,
      "z": 0,
      "name": "Plant_Seaweed_Navi_Stack"
    },
    {
      "x": 13,
      "y": 9,
      "z": 0,
      "name": "Wood_Azure_Trunk_Full"
    },
    {
      "x": 14,
      "y": 9,
      "z": 0,
      "name": "Wood_Azure_Trunk_Full"
    },
    {
      "x": 6,
      "y": 10,
      "z": 0,
      "name": "Plant_Seaweed_Navi_Stack"
    },
    {
      "x": 8,
      "y": 10,
      "z": 0,
      "name": "Plant_Seaweed_Navi_Stack"
    },
    {
      "x": 10,
      "y": 10,
      "z": 0,
      "name": "Plant_Seaweed_Navi_Stack"
    },
    {
      "x": 6,
      "y": 11,
      "z": 0,
      "name": "Plant_Seaweed_Navi_Stack"
    },
    {
      "x": 8,
      "y": 11,
      "z": 0,
      "name": "Plant_Seaweed_Navi_Stack"
    },
    {
      "x": 10,
      "y": 11,
      "z": 0,
      "name": "Plant_Seaweed_Navi_Stack"
    },
    {
      "x": 8,
      "y": 12,
      "z": 0,
      "name": "Plant_Seaweed_Navi_Stack"
    },
    {
      "x": 8,
      "y": 13,
      "z": 0,
      "name": "Plant_Seaweed_Navi_Stack"
    },
    {
      "x": 8,
      "y": 14,
      "z": 0,
      "name": "Plant_Seaweed_Navi_Stack"
    },
    {
      "x": 4,
      "y": 8,
      "z": 1,
      "name": "Plant_Seaweed_Navi_Stack"
    },
    {
      "x": 5,
      "y": 8,
      "z": 1,
      "name": "Plant_Seaweed_Navi_Stack"
    },
    {
      "x": 8,
      "y": 8,
      "z": 1,
      "name": "Plant_Coral_Block_Cyan"
    },
    {
      "x": 9,
      "y": 8,
      "z": 1,
      "name": "Plant_Coral_Block_Cyan"
    },
    {
      "x": 10,
      "y": 8,
      "z": 1,
      "name": "Plant_Seaweed_Navi_Stack"
    },
    {
      "x": 12,
      "y": 8,
      "z": 1,
      "name": "Wood_Azure_Trunk_Full"
    },
    {
      "x": 13,
      "y": 8,
      "z": 1,
      "name": "Wood_Azure_Trunk_Full"
    },
    {
      "x": 14,
      "y": 8,
      "z": 1,
      "name": "Wood_Azure_Trunk_Full"
    },
    {
      "x": 15,
      "y": 8,
      "z": 1,
      "name": "Wood_Azure_Trunk_Full"
    },
    {
      "x": 5,
      "y": 9,
      "z": 1,
      "name": "Plant_Seaweed_Navi_Stack"
    },
    {
      "x": 8,
      "y": 9,
      "z": 1,
      "name": "Plant_Seaweed_Navi_Stack"
    },
    {
      "x": 10,
      "y": 9,
      "z": 1,
      "name": "Plant_Seaweed_Navi_Stack"
    },
    {
      "x": 12,
      "y": 9,
      "z": 1,
      "name": "Wood_Azure_Trunk_Full"
    },
    {
      "x": 13,
      "y": 9,
      "z": 1,
      "name": "Wood_Azure_Trunk_Full"
    },
    {
      "x": 14,
      "y": 9,
      "z": 1,
      "name": "Plant_Coral_Block_Red"
    },
    {
      "x": 15,
      "y": 9,
      "z": 1,
      "name": "Plant_Coral_Block_Red"
    },
    {
      "x": 5,
      "y": 10,
      "z": 1,
      "name": "Plant_Seaweed_Navi_Stack"
    },
    {
      "x": 8,
      "y": 10,
      "z": 1,
      "name": "Plant_Seaweed_Navi_Stack"
    },
    {
      "x": 10,
      "y": 10,
      "z": 1,
      "name": "Plant_Seaweed_Navi_Stack"
    },
    {
      "x": 13,
      "y": 10,
      "z": 1,
      "name": "Plant_Coral_Block_Red"
    },
    {
      "x": 14,
      "y": 10,
      "z": 1,
      "name": "Plant_Coral_Block_Red"
    },
    {
      "x": 15,
      "y": 10,
      "z": 1,
      "name": "Plant_Coral_Block_Red"
    },
    {
      "x": 8,
      "y": 11,
      "z": 1,
      "name": "Plant_Seaweed_Navi_Stack"
    },
    {
      "x": 10,
      "y": 11,
      "z": 1,
      "name": "Plant_Seaweed_Navi_Stack"
    },
    {
      "x": 13,
      "y": 11,
      "z": 1,
      "name": "Plant_Coral_Model_Red"
    },
    {
      "x": 14,
      "y": 11,
      "z": 1,
      "name": "Plant_Coral_Model_Red"
    },
    {
      "x": 15,
      "y": 11,
      "z": 1,
      "name": "Plant_Coral_Block_Red"
    },
    {
      "x": 8,
      "y": 12,
      "z": 1,
      "name": "Plant_Seaweed_Navi_Stack"
    },
    {
      "x": 10,
      "y": 12,
      "z": 1,
      "name": "Plant_Seaweed_Navi_Stack"
    },
    {
      "x": 15,
      "y": 12,
      "z": 1,
      "name": "Plant_Coral_Block_Red"
    },
    {
      "x": 8,
      "y": 13,
      "z": 1,
      "name": "Plant_Seaweed_Navi_Stack"
    },
    {
      "x": 10,
      "y": 13,
      "z": 1,
      "name": "Plant_Seaweed_Navi_Stack"
    },
    {
      "x": 15,
      "y": 13,
      "z": 1,
      "name": "Plant_Coral_Block_Red"
    },
    {
      "x": 8,
      "y": 14,
      "z": 1,
      "name": "Plant_Seaweed_Navi_Stack"
    },
    {
      "x": 15,
      "y": 14,
      "z": 1,
      "name": "Plant_Coral_Block_Red"
    },
    {
      "x": 8,
      "y": 15,
      "z": 1,
      "name": "Plant_Seaweed_Navi_Stack"
    },
    {
      "x": 15,
      "y": 15,
      "z": 1,
      "name": "Plant_Coral_Block_Red"
    },
    {
      "x": 15,
      "y": 16,
      "z": 1,
      "name": "Plant_Coral_Model_Red"
    },
    {
      "x": 4,
      "y": 8,
      "z": 2,
      "name": "Plant_Seaweed_Navi_Stack"
    },
    {
      "x": 5,
      "y": 8,
      "z": 2,
      "name": "Plant_Seaweed_Navi_Stack"
    },
    {
      "x": 10,
      "y": 8,
      "z": 2,
      "name": "Plant_Seaweed_Navi_Stack"
    },
    {
      "x": 12,
      "y": 8,
      "z": 2,
      "name": "Wood_Azure_Trunk_Full"
    },
    {
      "x": 13,
      "y": 8,
      "z": 2,
      "name": "Wood_Azure_Trunk_Full"
    },
    {
      "x": 14,
      "y": 8,
      "z": 2,
      "name": "Plant_Coral_Block_Red"
    },
    {
      "x": 15,
      "y": 8,
      "z": 2,
      "name": "Wood_Azure_Trunk_Full"
    },
    {
      "x": 5,
      "y": 9,
      "z": 2,
      "name": "Plant_Seaweed_Navi_Stack"
    },
    {
      "x": 10,
      "y": 9,
      "z": 2,
      "name": "Plant_Seaweed_Navi_Stack"
    },
    {
      "x": 12,
      "y": 9,
      "z": 2,
      "name": "Wood_Azure_Trunk_Full"
    },
    {
      "x": 13,
      "y": 9,
      "z": 2,
      "name": "Wood_Azure_Trunk_Full"
    },
    {
      "x": 14,
      "y": 9,
      "z": 2,
      "name": "Plant_Coral_Block_Red"
    },
    {
      "x": 15,
      "y": 9,
      "z": 2,
      "name": "Wood_Azure_Trunk_Full"
    },
    {
      "x": 5,
      "y": 10,
      "z": 2,
      "name": "Plant_Seaweed_Navi_Stack"
    },
    {
      "x": 10,
      "y": 10,
      "z": 2,
      "name": "Plant_Seaweed_Navi_Stack"
    },
    {
      "x": 13,
      "y": 10,
      "z": 2,
      "name": "Plant_Coral_Block_Red"
    },
    {
      "x": 14,
      "y": 10,
      "z": 2,
      "name": "Plant_Coral_Block_Red"
    },
    {
      "x": 15,
      "y": 10,
      "z": 2,
      "name": "Plant_Coral_Block_Red"
    },
    {
      "x": 10,
      "y": 11,
      "z": 2,
      "name": "Plant_Seaweed_Navi_Stack"
    },
    {
      "x": 13,
      "y": 11,
      "z": 2,
      "name": "Plant_Coral_Model_Red"
    },
    {
      "x": 14,
      "y": 11,
      "z": 2,
      "name": "Plant_Coral_Block_Red"
    },
    {
      "x": 15,
      "y": 11,
      "z": 2,
      "name": "Wood_Azure_Trunk_Full"
    },
    {
      "x": 10,
      "y": 12,
      "z": 2,
      "name": "Plant_Seaweed_Navi_Stack"
    },
    {
      "x": 14,
      "y": 12,
      "z": 2,
      "name": "Plant_Coral_Block_Red"
    },
    {
      "x": 15,
      "y": 12,
      "z": 2,
      "name": "Plant_Coral_Block_Red"
    },
    {
      "x": 10,
      "y": 13,
      "z": 2,
      "name": "Plant_Seaweed_Navi_Stack"
    },
    {
      "x": 14,
      "y": 13,
      "z": 2,
      "name": "Plant_Coral_Block_Red"
    },
    {
      "x": 15,
      "y": 13,
      "z": 2,
      "name": "Plant_Coral_Block_Red"
    },
    {
      "x": 14,
      "y": 14,
      "z": 2,
      "name": "Plant_Coral_Block_Red"
    },
    {
      "x": 15,
      "y": 14,
      "z": 2,
      "name": "Plant_Coral_Block_Red"
    },
    {
      "x": 14,
      "y": 15,
      "z": 2,
      "name": "Plant_Coral_Block_Red"
    },
    {
      "x": 15,
      "y": 15,
      "z": 2,
      "name": "Plant_Coral_Block_Red"
    },
    {
      "x": 14,
      "y": 16,
      "z": 2,
      "name": "Plant_Coral_Model_Red"
    },
    {
      "x": 15,
      "y": 16,
      "z": 2,
      "name": "Plant_Coral_Model_Red"
    },
    {
      "x": 3,
      "y": 8,
      "z": 3,
      "name": "Plant_Seaweed_Navi_Stack"
    },
    {
      "x": 5,
      "y": 8,
      "z": 3,
      "name": "Plant_Seaweed_Navi_Stack"
    },
    {
      "x": 6,
      "y": 8,
      "z": 3,
      "name": "Plant_Seaweed_Navi_Stack"
    },
    {
      "x": 7,
      "y": 8,
      "z": 3,
      "name": "Plant_Coral_Block_Cyan"
    },
    {
      "x": 3,
      "y": 9,
      "z": 3,
      "name": "Plant_Seaweed_Navi_Stack"
    },
    {
      "x": 5,
      "y": 9,
      "z": 3,
      "name": "Plant_Seaweed_Navi_Stack"
    },
    {
      "x": 6,
      "y": 9,
      "z": 3,
      "name": "Plant_Seaweed_Navi_Stack"
    },
    {
      "x": 7,
      "y": 9,
      "z": 3,
      "name": "Plant_Seaweed_Navi_Stack"
    },
    {
      "x": 5,
      "y": 10,
      "z": 3,
      "name": "Plant_Seaweed_Navi_Stack"
    },
    {
      "x": 6,
      "y": 10,
      "z": 3,
      "name": "Plant_Seaweed_Navi_Stack"
    },
    {
      "x": 7,
      "y": 10,
      "z": 3,
      "name": "Plant_Seaweed_Navi_Stack"
    },
    {
      "x": 5,
      "y": 11,
      "z": 3,
      "name": "Plant_Seaweed_Navi_Stack"
    },
    {
      "x": 6,
      "y": 11,
      "z": 3,
      "name": "Plant_Seaweed_Navi_Stack"
    },
    {
      "x": 7,
      "y": 11,
      "z": 3,
      "name": "Plant_Seaweed_Navi_Stack"
    },
    {
      "x": 5,
      "y": 12,
      "z": 3,
      "name": "Plant_Seaweed_Navi_Stack"
    },
    {
      "x": 7,
      "y": 12,
      "z": 3,
      "name": "Plant_Seaweed_Navi_Stack"
    },
    {
      "x": 7,
      "y": 13,
      "z": 3,
      "name": "Plant_Seaweed_Navi_Stack"
    },
    {
      "x": 0,
      "y": 8,
      "z": 4,
      "name": "Plant_Seaweed_Navi_Stack"
    },
    {
      "x": 2,
      "y": 8,
      "z": 4,
      "name": "Plant_Seaweed_Navi_Stack"
    },
    {
      "x": 3,
      "y": 8,
      "z": 4,
      "name": "Plant_Seaweed_Navi_Stack"
    },
    {
      "x": 7,
      "y": 8,
      "z": 4,
      "name": "Plant_Coral_Block_Cyan"
    },
    {
      "x": 8,
      "y": 8,
      "z": 4,
      "name": "Plant_Seaweed_Navi_Stack"
    },
    {
      "x": 9,
      "y": 8,
      "z": 4,
      "name": "Plant_Seaweed_Navi_Stack"
    },
    {
      "x": 0,
      "y": 9,
      "z": 4,
      "name": "Plant_Seaweed_Navi_Stack"
    },
    {
      "x": 2,
      "y": 9,
      "z": 4,
      "name": "Plant_Seaweed_Navi_Stack"
    },
    {
      "x": 3,
      "y": 9,
      "z": 4,
      "name": "Plant_Seaweed_Navi_Stack"
    },
    {
      "x": 8,
      "y": 9,
      "z": 4,
      "name": "Plant_Seaweed_Navi_Stack"
    },
    {
      "x": 9,
      "y": 9,
      "z": 4,
      "name": "Plant_Seaweed_Navi_Stack"
    },
    {
      "x": 0,
      "y": 10,
      "z": 4,
      "name": "Plant_Seaweed_Navi_Stack"
    },
    {
      "x": 8,
      "y": 10,
      "z": 4,
      "name": "Plant_Seaweed_Navi_Stack"
    },
    {
      "x": 9,
      "y": 10,
      "z": 4,
      "name": "Plant_Seaweed_Navi_Stack"
    },
    {
      "x": 8,
      "y": 11,
      "z": 4,
      "name": "Plant_Seaweed_Navi_Stack"
    },
    {
      "x": 9,
      "y": 11,
      "z": 4,
      "name": "Plant_Seaweed_Navi_Stack"
    },
    {
      "x": 8,
      "y": 12,
      "z": 4,
      "name": "Plant_Seaweed_Navi_Stack"
    },
    {
      "x": 9,
      "y": 12,
      "z": 4,
      "name": "Plant_Seaweed_Navi_Stack"
    },
    {
      "x": 8,
      "y": 13,
      "z": 4,
      "name": "Plant_Seaweed_Navi_Stack"
    },
    {
      "x": 9,
      "y": 13,
      "z": 4,
      "name": "Plant_Seaweed_Navi_Stack"
    },
    {
      "x": 8,
      "y": 14,
      "z": 4,
      "name": "Plant_Seaweed_Navi_Stack"
    },
    {
      "x": 1,
      "y": 8,
      "z": 5,
      "name": "Plant_Seaweed_Navi_Stack"
    },
    {
      "x": 7,
      "y": 8,
      "z": 5,
      "name": "Plant_Coral_Block_Cyan"
    },
    {
      "x": 9,
      "y": 8,
      "z": 5,
      "name": "Plant_Seaweed_Navi_Stack"
    },
    {
      "x": 12,
      "y": 8,
      "z": 5,
      "name": "Wood_Azure_Trunk_Full"
    },
    {
      "x": 13,
      "y": 8,
      "z": 5,
      "name": "Wood_Azure_Trunk_Full"
    },
    {
      "x": 14,
      "y": 8,
      "z": 5,
      "name": "Plant_Coral_Block_Red"
    },
    {
      "x": 15,
      "y": 8,
      "z": 5,
      "name": "Plant_Coral_Block_Red"
    },
    {
      "x": 1,
      "y": 9,
      "z": 5,
      "name": "Plant_Seaweed_Navi_Stack"
    },
    {
      "x": 9,
      "y": 9,
      "z": 5,
      "name": "Plant_Seaweed_Navi_Stack"
    },
    {
      "x": 14,
      "y": 9,
      "z": 5,
      "name": "Wood_Azure_Trunk_Full"
    },
    {
      "x": 15,
      "y": 9,
      "z": 5,
      "name": "Plant_Coral_Block_Red"
    },
    {
      "x": 1,
      "y": 10,
      "z": 5,
      "name": "Plant_Seaweed_Navi_Stack"
    },
    {
      "x": 9,
      "y": 10,
      "z": 5,
      "name": "Plant_Seaweed_Navi_Stack"
    },
    {
      "x": 14,
      "y": 10,
      "z": 5,
      "name": "Plant_Coral_Block_Red"
    },
    {
      "x": 15,
      "y": 10,
      "z": 5,
      "name": "Plant_Coral_Block_Red"
    },
    {
      "x": 1,
      "y": 11,
      "z": 5,
      "name": "Plant_Seaweed_Navi_Stack"
    },
    {
      "x": 9,
      "y": 11,
      "z": 5,
      "name": "Plant_Seaweed_Navi_Stack"
    },
    {
      "x": 14,
      "y": 11,
      "z": 5,
      "name": "Plant_Coral_Block_Red"
    },
    {
      "x": 15,
      "y": 11,
      "z": 5,
      "name": "Plant_Coral_Block_Red"
    },
    {
      "x": 9,
      "y": 12,
      "z": 5,
      "name": "Plant_Seaweed_Navi_Stack"
    },
    {
      "x": 14,
      "y": 12,
      "z": 5,
      "name": "Plant_Coral_Block_Red"
    },
    {
      "x": 15,
      "y": 12,
      "z": 5,
      "name": "Plant_Coral_Block_Red"
    },
    {
      "x": 14,
      "y": 13,
      "z": 5,
      "name": "Plant_Coral_Model_Red"
    },
    {
      "x": 15,
      "y": 13,
      "z": 5,
      "name": "Plant_Coral_Model_Red"
    },
    {
      "x": 3,
      "y": 8,
      "z": 6,
      "name": "Plant_Seaweed_Navi_Stack"
    },
    {
      "x": 4,
      "y": 8,
      "z": 6,
      "name": "Plant_Seaweed_Navi_Stack"
    },
    {
      "x": 8,
      "y": 8,
      "z": 6,
      "name": "Plant_Seaweed_Navi_Stack"
    },
    {
      "x": 13,
      "y": 8,
      "z": 6,
      "name": "Wood_Azure_Trunk_Full"
    },
    {
      "x": 14,
      "y": 8,
      "z": 6,
      "name": "Plant_Coral_Block_Red"
    },
    {
      "x": 15,
      "y": 8,
      "z": 6,
      "name": "Plant_Coral_Block_Red"
    },
    {
      "x": 3,
      "y": 9,
      "z": 6,
      "name": "Plant_Seaweed_Navi_Stack"
    },
    {
      "x": 4,
      "y": 9,
      "z": 6,
      "name": "Plant_Seaweed_Navi_Stack"
    },
    {
      "x": 8,
      "y": 9,
      "z": 6,
      "name": "Plant_Seaweed_Navi_Stack"
    },
    {
      "x": 14,
      "y": 9,
      "z": 6,
      "name": "Plant_Coral_Block_Red"
    },
    {
      "x": 15,
      "y": 9,
      "z": 6,
      "name": "Wood_Azure_Trunk_Full"
    },
    {
      "x": 3,
      "y": 10,
      "z": 6,
      "name": "Plant_Seaweed_Navi_Stack"
    },
    {
      "x": 4,
      "y": 10,
      "z": 6,
      "name": "Plant_Seaweed_Navi_Stack"
    },
    {
      "x": 8,
      "y": 10,
      "z": 6,
      "name": "Plant_Seaweed_Navi_Stack"
    },
    {
      "x": 14,
      "y": 10,
      "z": 6,
      "name": "Plant_Coral_Block_Red"
    },
    {
      "x": 15,
      "y": 10,
      "z": 6,
      "name": "Plant_Coral_Block_Red"
    },
    {
      "x": 4,
      "y": 11,
      "z": 6,
      "name": "Plant_Seaweed_Navi_Stack"
    },
    {
      "x": 8,
      "y": 11,
      "z": 6,
      "name": "Plant_Seaweed_Navi_Stack"
    },
    {
      "x": 14,
      "y": 11,
      "z": 6,
      "name": "Plant_Coral_Block_Red"
    },
    {
      "x": 15,
      "y": 11,
      "z": 6,
      "name": "Plant_Coral_Block_Red"
    },
    {
      "x": 4,
      "y": 12,
      "z": 6,
      "name": "Plant_Seaweed_Navi_Stack"
    },
    {
      "x": 8,
      "y": 12,
      "z": 6,
      "name": "Plant_Seaweed_Navi_Stack"
    },
    {
      "x": 14,
      "y": 12,
      "z": 6,
      "name": "Plant_Coral_Block_Red"
    },
    {
      "x": 15,
      "y": 12,
      "z": 6,
      "name": "Plant_Coral_Block_Red"
    },
    {
      "x": 4,
      "y": 13,
      "z": 6,
      "name": "Plant_Seaweed_Navi_Stack"
    },
    {
      "x": 14,
      "y": 13,
      "z": 6,
      "name": "Plant_Coral_Model_Red"
    },
    {
      "x": 15,
      "y": 13,
      "z": 6,
      "name": "Plant_Coral_Model_Red"
    },
    {
      "x": 4,
      "y": 14,
      "z": 6,
      "name": "Plant_Seaweed_Navi_Stack"
    },
    {
      "x": 1,
      "y": 8,
      "z": 7,
      "name": "Plant_Seaweed_Navi_Stack"
    },
    {
      "x": 4,
      "y": 8,
      "z": 7,
      "name": "Plant_Coral_Block_Cyan"
    },
    {
      "x": 1,
      "y": 9,
      "z": 7,
      "name": "Plant_Seaweed_Navi_Stack"
    },
    {
      "x": 4,
      "y": 9,
      "z": 7,
      "name": "Plant_Seaweed_Navi_Stack"
    },
    {
      "x": 1,
      "y": 10,
      "z": 7,
      "name": "Plant_Seaweed_Navi_Stack"
    },
    {
      "x": 4,
      "y": 10,
      "z": 7,
      "name": "Plant_Seaweed_Navi_Stack"
    },
    {
      "x": 1,
      "y": 11,
      "z": 7,
      "name": "Plant_Seaweed_Navi_Stack"
    },
    {
      "x": 4,
      "y": 11,
      "z": 7,
      "name": "Plant_Seaweed_Navi_Stack"
    },
    {
      "x": 1,
      "y": 12,
      "z": 7,
      "name": "Plant_Seaweed_Navi_Stack"
    },
    {
      "x": 4,
      "y": 12,
      "z": 7,
      "name": "Plant_Seaweed_Navi_Stack"
    },
    {
      "x": 1,
      "y": 13,
      "z": 7,
      "name": "Plant_Seaweed_Navi_Stack"
    },
    {
      "x": 1,
      "y": 14,
      "z": 7,
      "name": "Plant_Seaweed_Navi_Stack"
    },
    {
      "x": 0,
      "y": 8,
      "z": 8,
      "name": "Plant_Coral_Block_Cyan"
    },
    {
      "x": 1,
      "y": 8,
      "z": 8,
      "name": "Plant_Coral_Block_Cyan"
    },
    {
      "x": 4,
      "y": 8,
      "z": 8,
      "name": "Plant_Seaweed_Navi_Stack"
    },
    {
      "x": 5,
      "y": 8,
      "z": 8,
      "name": "Plant_Seaweed_Navi_Stack"
    },
    {
      "x": 13,
      "y": 8,
      "z": 8,
      "name": "Wood_Azure_Trunk_Full"
    },
    {
      "x": 14,
      "y": 8,
      "z": 8,
      "name": "Wood_Azure_Trunk_Full"
    },
    {
      "x": 0,
      "y": 9,
      "z": 8,
      "name": "Plant_Seaweed_Navi_Stack"
    },
    {
      "x": 1,
      "y": 9,
      "z": 8,
      "name": "Plant_Seaweed_Navi_Stack"
    },
    {
      "x": 4,
      "y": 9,
      "z": 8,
      "name": "Plant_Seaweed_Navi_Stack"
    },
    {
      "x": 5,
      "y": 9,
      "z": 8,
      "name": "Plant_Seaweed_Navi_Stack"
    },
    {
      "x": 13,
      "y": 9,
      "z": 8,
      "name": "Wood_Azure_Trunk_Full"
    },
    {
      "x": 14,
      "y": 9,
      "z": 8,
      "name": "Wood_Azure_Trunk_Full"
    },
    {
      "x": 0,
      "y": 10,
      "z": 8,
      "name": "Plant_Seaweed_Navi_Stack"
    },
    {
      "x": 1,
      "y": 10,
      "z": 8,
      "name": "Plant_Seaweed_Navi_Stack"
    },
    {
      "x": 4,
      "y": 10,
      "z": 8,
      "name": "Plant_Seaweed_Navi_Stack"
    },
    {
      "x": 5,
      "y": 10,
      "z": 8,
      "name": "Plant_Seaweed_Navi_Stack"
    },
    {
      "x": 13,
      "y": 10,
      "z": 8,
      "name": "Wood_Azure_Trunk_Full"
    },
    {
      "x": 14,
      "y": 10,
      "z": 8,
      "name": "Wood_Azure_Trunk_Full"
    },
    {
      "x": 0,
      "y": 11,
      "z": 8,
      "name": "Plant_Seaweed_Navi_Stack"
    },
    {
      "x": 1,
      "y": 11,
      "z": 8,
      "name": "Plant_Seaweed_Navi_Stack"
    },
    {
      "x": 4,
      "y": 11,
      "z": 8,
      "name": "Plant_Seaweed_Navi_Stack"
    },
    {
      "x": 5,
      "y": 11,
      "z": 8,
      "name": "Plant_Seaweed_Navi_Stack"
    },
    {
      "x": 13,
      "y": 11,
      "z": 8,
      "name": "Wood_Azure_Trunk_Full"
    },
    {
      "x": 14,
      "y": 11,
      "z": 8,
      "name": "Wood_Azure_Trunk_Full"
    },
    {
      "x": 0,
      "y": 12,
      "z": 8,
      "name": "Plant_Seaweed_Navi_Stack"
    },
    {
      "x": 1,
      "y": 12,
      "z": 8,
      "name": "Plant_Seaweed_Navi_Stack"
    },
    {
      "x": 4,
      "y": 12,
      "z": 8,
      "name": "Plant_Seaweed_Navi_Stack"
    },
    {
      "x": 5,
      "y": 12,
      "z": 8,
      "name": "Plant_Seaweed_Navi_Stack"
    },
    {
      "x": 13,
      "y": 12,
      "z": 8,
      "name": "Plant_Coral_Block_Red"
    },
    {
      "x": 14,
      "y": 12,
      "z": 8,
      "name": "Wood_Azure_Trunk_Full"
    },
    {
      "x": 0,
      "y": 13,
      "z": 8,
      "name": "Plant_Seaweed_Navi_Stack"
    },
    {
      "x": 1,
      "y": 13,
      "z": 8,
      "name": "Plant_Seaweed_Navi_Stack"
    },
    {
      "x": 4,
      "y": 13,
      "z": 8,
      "name": "Plant_Seaweed_Navi_Stack"
    },
    {
      "x": 5,
      "y": 13,
      "z": 8,
      "name": "Plant_Seaweed_Navi_Stack"
    },
    {
      "x": 13,
      "y": 13,
      "z": 8,
      "name": "Plant_Coral_Block_Red"
    },
    {
      "x": 14,
      "y": 13,
      "z": 8,
      "name": "Plant_Coral_Block_Red"
    },
    {
      "x": 0,
      "y": 14,
      "z": 8,
      "name": "Plant_Seaweed_Navi_Stack"
    },
    {
      "x": 1,
      "y": 14,
      "z": 8,
      "name": "Plant_Seaweed_Navi_Stack"
    },
    {
      "x": 5,
      "y": 14,
      "z": 8,
      "name": "Plant_Seaweed_Navi_Stack"
    },
    {
      "x": 13,
      "y": 14,
      "z": 8,
      "name": "Plant_Coral_Block_Red"
    },
    {
      "x": 14,
      "y": 14,
      "z": 8,
      "name": "Plant_Coral_Block_Red"
    },
    {
      "x": 13,
      "y": 15,
      "z": 8,
      "name": "Plant_Coral_Block_Red"
    },
    {
      "x": 14,
      "y": 15,
      "z": 8,
      "name": "Plant_Coral_Block_Red"
    },
    {
      "x": 13,
      "y": 16,
      "z": 8,
      "name": "Plant_Coral_Model_Red"
    },
    {
      "x": 14,
      "y": 16,
      "z": 8,
      "name": "Plant_Coral_Model_Red"
    },
    {
      "x": 1,
      "y": 8,
      "z": 9,
      "name": "Plant_Seaweed_Navi_Stack"
    },
    {
      "x": 4,
      "y": 8,
      "z": 9,
      "name": "Plant_Seaweed_Navi_Stack"
    },
    {
      "x": 5,
      "y": 8,
      "z": 9,
      "name": "Plant_Seaweed_Navi_Stack"
    },
    {
      "x": 14,
      "y": 8,
      "z": 9,
      "name": "Wood_Azure_Trunk_Full"
    },
    {
      "x": 1,
      "y": 9,
      "z": 9,
      "name": "Plant_Seaweed_Navi_Stack"
    },
    {
      "x": 4,
      "y": 9,
      "z": 9,
      "name": "Plant_Seaweed_Navi_Stack"
    },
    {
      "x": 5,
      "y": 9,
      "z": 9,
      "name": "Plant_Seaweed_Navi_Stack"
    },
    {
      "x": 14,
      "y": 9,
      "z": 9,
      "name": "Wood_Azure_Trunk_Full"
    },
    {
      "x": 1,
      "y": 10,
      "z": 9,
      "name": "Plant_Seaweed_Navi_Stack"
    },
    {
      "x": 4,
      "y": 10,
      "z": 9,
      "name": "Plant_Seaweed_Navi_Stack"
    },
    {
      "x": 5,
      "y": 10,
      "z": 9,
      "name": "Plant_Seaweed_Navi_Stack"
    },
    {
      "x": 14,
      "y": 10,
      "z": 9,
      "name": "Wood_Azure_Trunk_Full"
    },
    {
      "x": 1,
      "y": 11,
      "z": 9,
      "name": "Plant_Seaweed_Navi_Stack"
    },
    {
      "x": 4,
      "y": 11,
      "z": 9,
      "name": "Plant_Seaweed_Navi_Stack"
    },
    {
      "x": 5,
      "y": 11,
      "z": 9,
      "name": "Plant_Seaweed_Navi_Stack"
    },
    {
      "x": 14,
      "y": 11,
      "z": 9,
      "name": "Wood_Azure_Trunk_Full"
    },
    {
      "x": 1,
      "y": 12,
      "z": 9,
      "name": "Plant_Seaweed_Navi_Stack"
    },
    {
      "x": 4,
      "y": 12,
      "z": 9,
      "name": "Plant_Seaweed_Navi_Stack"
    },
    {
      "x": 5,
      "y": 12,
      "z": 9,
      "name": "Plant_Seaweed_Navi_Stack"
    },
    {
      "x": 14,
      "y": 12,
      "z": 9,
      "name": "Plant_Coral_Block_Red"
    },
    {
      "x": 5,
      "y": 13,
      "z": 9,
      "name": "Plant_Seaweed_Navi_Stack"
    },
    {
      "x": 14,
      "y": 13,
      "z": 9,
      "name": "Plant_Coral_Block_Red"
    },
    {
      "x": 14,
      "y": 14,
      "z": 9,
      "name": "Plant_Coral_Block_Red"
    },
    {
      "x": 14,
      "y": 15,
      "z": 9,
      "name": "Plant_Coral_Block_Red"
    },
    {
      "x": 14,
      "y": 16,
      "z": 9,
      "name": "Plant_Coral_Model_Red"
    },
    {
      "x": 0,
      "y": 8,
      "z": 10,
      "name": "Plant_Seaweed_Navi_Stack"
    },
    {
      "x": 2,
      "y": 8,
      "z": 10,
      "name": "Plant_Seaweed_Navi_Stack"
    },
    {
      "x": 11,
      "y": 8,
      "z": 10,
      "name": "Wood_Azure_Trunk_Full"
    },
    {
      "x": 0,
      "y": 9,
      "z": 10,
      "name": "Plant_Seaweed_Navi_Stack"
    },
    {
      "x": 2,
      "y": 9,
      "z": 10,
      "name": "Plant_Seaweed_Navi_Stack"
    },
    {
      "x": 11,
      "y": 9,
      "z": 10,
      "name": "Plant_Coral_Block_Red"
    },
    {
      "x": 0,
      "y": 10,
      "z": 10,
      "name": "Plant_Seaweed_Navi_Stack"
    },
    {
      "x": 2,
      "y": 10,
      "z": 10,
      "name": "Plant_Seaweed_Navi_Stack"
    },
    {
      "x": 11,
      "y": 10,
      "z": 10,
      "name": "Plant_Coral_Block_Red"
    },
    {
      "x": 0,
      "y": 11,
      "z": 10,
      "name": "Plant_Seaweed_Navi_Stack"
    },
    {
      "x": 2,
      "y": 11,
      "z": 10,
      "name": "Plant_Seaweed_Navi_Stack"
    },
    {
      "x": 11,
      "y": 11,
      "z": 10,
      "name": "Plant_Coral_Block_Red"
    },
    {
      "x": 0,
      "y": 12,
      "z": 10,
      "name": "Plant_Seaweed_Navi_Stack"
    },
    {
      "x": 2,
      "y": 12,
      "z": 10,
      "name": "Plant_Seaweed_Navi_Stack"
    },
    {
      "x": 11,
      "y": 12,
      "z": 10,
      "name": "Plant_Coral_Block_Red"
    },
    {
      "x": 0,
      "y": 13,
      "z": 10,
      "name": "Plant_Seaweed_Navi_Stack"
    },
    {
      "x": 11,
      "y": 13,
      "z": 10,
      "name": "Plant_Coral_Model_Red"
    },
    {
      "x": 12,
      "y": 8,
      "z": 11,
      "name": "Wood_Azure_Trunk_Full"
    },
    {
      "x": 12,
      "y": 9,
      "z": 11,
      "name": "Plant_Coral_Block_Red"
    },
    {
      "x": 12,
      "y": 10,
      "z": 11,
      "name": "Plant_Coral_Block_Red"
    },
    {
      "x": 12,
      "y": 11,
      "z": 11,
      "name": "Plant_Coral_Block_Red"
    },
    {
      "x": 12,
      "y": 12,
      "z": 11,
      "name": "Plant_Coral_Block_Red"
    },
    {
      "x": 12,
      "y": 13,
      "z": 11,
      "name": "Plant_Coral_Model_Red"
    },
    {
      "x": 0,
      "y": 8,
      "z": 12,
      "name": "Wood_Azure_Trunk_Full"
    },
    {
      "x": 1,
      "y": 8,
      "z": 12,
      "name": "Wood_Azure_Trunk_Full"
    },
    {
      "x": 2,
      "y": 8,
      "z": 12,
      "name": "Wood_Azure_Trunk_Full"
    },
    {
      "x": 0,
      "y": 8,
      "z": 13,
      "name": "Wood_Azure_Trunk_Full"
    },
    {
      "x": 1,
      "y": 8,
      "z": 13,
      "name": "Wood_Azure_Trunk_Full"
    },
    {
      "x": 2,
      "y": 8,
      "z": 13,
      "name": "Wood_Azure_Trunk_Full"
    },
    {
      "x": 5,
      "y": 8,
      "z": 13,
      "name": "Wood_Azure_Trunk_Full"
    },
    {
      "x": 8,
      "y": 8,
      "z": 13,
      "name": "Wood_Azure_Trunk_Full"
    },
    {
      "x": 9,
      "y": 8,
      "z": 13,
      "name": "Wood_Azure_Trunk_Full"
    },
    {
      "x": 1,
      "y": 9,
      "z": 13,
      "name": "Wood_Azure_Trunk_Full"
    },
    {
      "x": 2,
      "y": 9,
      "z": 13,
      "name": "Wood_Azure_Trunk_Full"
    },
    {
      "x": 5,
      "y": 9,
      "z": 13,
      "name": "Wood_Azure_Trunk_Full"
    },
    {
      "x": 8,
      "y": 9,
      "z": 13,
      "name": "Wood_Azure_Trunk_Full"
    },
    {
      "x": 9,
      "y": 9,
      "z": 13,
      "name": "Wood_Azure_Trunk_Full"
    },
    {
      "x": 5,
      "y": 10,
      "z": 13,
      "name": "Plant_Coral_Block_Red"
    },
    {
      "x": 8,
      "y": 10,
      "z": 13,
      "name": "Wood_Azure_Trunk_Full"
    },
    {
      "x": 9,
      "y": 10,
      "z": 13,
      "name": "Wood_Azure_Trunk_Full"
    },
    {
      "x": 5,
      "y": 11,
      "z": 13,
      "name": "Plant_Coral_Block_Red"
    },
    {
      "x": 8,
      "y": 11,
      "z": 13,
      "name": "Plant_Coral_Block_Red"
    },
    {
      "x": 9,
      "y": 11,
      "z": 13,
      "name": "Wood_Azure_Trunk_Full"
    },
    {
      "x": 5,
      "y": 12,
      "z": 13,
      "name": "Plant_Coral_Block_Red"
    },
    {
      "x": 8,
      "y": 12,
      "z": 13,
      "name": "Plant_Coral_Block_Red"
    },
    {
      "x": 9,
      "y": 12,
      "z": 13,
      "name": "Plant_Coral_Block_Red"
    },
    {
      "x": 5,
      "y": 13,
      "z": 13,
      "name": "Plant_Coral_Model_Red"
    },
    {
      "x": 8,
      "y": 13,
      "z": 13,
      "name": "Plant_Coral_Block_Red"
    },
    {
      "x": 9,
      "y": 13,
      "z": 13,
      "name": "Plant_Coral_Block_Red"
    },
    {
      "x": 8,
      "y": 14,
      "z": 13,
      "name": "Plant_Coral_Block_Red"
    },
    {
      "x": 9,
      "y": 14,
      "z": 13,
      "name": "Plant_Coral_Block_Red"
    },
    {
      "x": 8,
      "y": 15,
      "z": 13,
      "name": "Plant_Coral_Block_Red"
    },
    {
      "x": 9,
      "y": 15,
      "z": 13,
      "name": "Plant_Coral_Block_Red"
    },
    {
      "x": 8,
      "y": 16,
      "z": 13,
      "name": "Plant_Coral_Model_Red"
    },
    {
      "x": 9,
      "y": 16,
      "z": 13,
      "name": "Plant_Coral_Model_Red"
    },
    {
      "x": 0,
      "y": 8,
      "z": 14,
      "name": "Wood_Azure_Trunk_Full"
    },
    {
      "x": 1,
      "y": 8,
      "z": 14,
      "name": "Wood_Azure_Trunk_Full"
    },
    {
      "x": 2,
      "y": 8,
      "z": 14,
      "name": "Wood_Azure_Trunk_Full"
    },
    {
      "x": 5,
      "y": 8,
      "z": 14,
      "name": "Wood_Azure_Trunk_Full"
    },
    {
      "x": 9,
      "y": 8,
      "z": 14,
      "name": "Wood_Azure_Trunk_Full"
    },
    {
      "x": 1,
      "y": 9,
      "z": 14,
      "name": "Wood_Azure_Trunk_Full"
    },
    {
      "x": 2,
      "y": 9,
      "z": 14,
      "name": "Wood_Azure_Trunk_Full"
    },
    {
      "x": 5,
      "y": 9,
      "z": 14,
      "name": "Wood_Azure_Trunk_Full"
    },
    {
      "x": 9,
      "y": 9,
      "z": 14,
      "name": "Wood_Azure_Trunk_Full"
    },
    {
      "x": 2,
      "y": 10,
      "z": 14,
      "name": "Plant_Coral_Block_Red"
    },
    {
      "x": 5,
      "y": 10,
      "z": 14,
      "name": "Wood_Azure_Trunk_Full"
    },
    {
      "x": 9,
      "y": 10,
      "z": 14,
      "name": "Plant_Coral_Block_Red"
    },
    {
      "x": 2,
      "y": 11,
      "z": 14,
      "name": "Plant_Coral_Block_Red"
    },
    {
      "x": 5,
      "y": 11,
      "z": 14,
      "name": "Plant_Coral_Block_Red"
    },
    {
      "x": 9,
      "y": 11,
      "z": 14,
      "name": "Plant_Coral_Block_Red"
    },
    {
      "x": 2,
      "y": 12,
      "z": 14,
      "name": "Plant_Coral_Block_Red"
    },
    {
      "x": 5,
      "y": 12,
      "z": 14,
      "name": "Plant_Coral_Block_Red"
    },
    {
      "x": 9,
      "y": 12,
      "z": 14,
      "name": "Plant_Coral_Block_Red"
    },
    {
      "x": 2,
      "y": 13,
      "z": 14,
      "name": "Plant_Coral_Block_Red"
    },
    {
      "x": 5,
      "y": 13,
      "z": 14,
      "name": "Plant_Coral_Model_Red"
    },
    {
      "x": 9,
      "y": 13,
      "z": 14,
      "name": "Plant_Coral_Block_Red"
    },
    {
      "x": 2,
      "y": 14,
      "z": 14,
      "name": "Plant_Coral_Block_Red"
    },
    {
      "x": 9,
      "y": 14,
      "z": 14,
      "name": "Plant_Coral_Block_Red"
    },
    {
      "x": 2,
      "y": 15,
      "z": 14,
      "name": "Plant_Coral_Block_Red"
    },
    {
      "x": 9,
      "y": 15,
      "z": 14,
      "name": "Plant_Coral_Block_Red"
    },
    {
      "x": 2,
      "y": 16,
      "z": 14,
      "name": "Plant_Coral_Model_Red"
    },
    {
      "x": 9,
      "y": 16,
      "z": 14,
      "name": "Plant_Coral_Model_Red"
    },
    {
      "x": 1,
      "y": 8,
      "z": 15,
      "name": "Wood_Azure_Trunk_Full"
    },
    {
      "x": 2,
      "y": 8,
      "z": 15,
      "name": "Wood_Azure_Trunk_Full"
    },
    {
      "x": 1,
      "y": 9,
      "z": 15,
      "name": "Wood_Azure_Trunk_Full"
    },
    {
      "x": 2,
      "y": 9,
      "z": 15,
      "name": "Wood_Azure_Trunk_Full"
    },
    {
      "x": 1,
      "y": 10,
      "z": 15,
      "name": "Wood_Azure_Trunk_Full"
    },
    {
      "x": 2,
      "y": 10,
      "z": 15,
      "name": "Plant_Coral_Block_Red"
    },
    {
      "x": 1,
      "y": 11,
      "z": 15,
      "name": "Plant_Coral_Block_Red"
    },
    {
      "x": 2,
      "y": 11,
      "z": 15,
      "name": "Plant_Coral_Block_Red"
    },
    {
      "x": 1,
      "y": 12,
      "z": 15,
      "name": "Plant_Coral_Block_Red"
    },
    {
      "x": 2,
      "y": 12,
      "z": 15,
      "name": "Plant_Coral_Block_Red"
    },
    {
      "x": 1,
      "y": 13,
      "z": 15,
      "name": "Plant_Coral_Block_Red"
    },
    {
      "x": 2,
      "y": 13,
      "z": 15,
      "name": "Plant_Coral_Block_Red"
    },
    {
      "x": 1,
      "y": 14,
      "z": 15,
      "name": "Plant_Coral_Block_Red"
    },
    {
      "x": 2,
      "y": 14,
      "z": 15,
      "name": "Plant_Coral_Block_Red"
    },
    {
      "x": 1,
      "y": 15,
      "z": 15,
      "name": "Plant_Coral_Block_Red"
    },
    {
      "x": 2,
      "y": 15,
      "z": 15,
      "name": "Plant_Coral_Block_Red"
    },
    {
      "x": 1,
      "y": 16,
      "z": 15,
      "name": "Plant_Coral_Model_Red"
    },
    {
      "x": 2,
      "y": 16,
      "z": 15,
      "name": "Plant_Coral_Model_Red"
    },
    {
      "x": 2,
      "y": 7,
      "z": -15,
      "name": "Plant_Coral_Block_Red"
    },
    {
      "x": 1,
      "y": 5,
      "z": -14,
      "name": "Wood_Azure_Trunk_Full"
    },
    {
      "x": 2,
      "y": 5,
      "z": -14,
      "name": "Wood_Azure_Trunk_Full"
    },
    {
      "x": 1,
      "y": 6,
      "z": -14,
      "name": "Wood_Azure_Trunk_Full"
    },
    {
      "x": 2,
      "y": 6,
      "z": -14,
      "name": "Wood_Azure_Trunk_Full"
    },
    {
      "x": 2,
      "y": 7,
      "z": -14,
      "name": "Wood_Azure_Trunk_Full"
    },
    {
      "x": 1,
      "y": 5,
      "z": -13,
      "name": "Wood_Azure_Trunk_Full"
    },
    {
      "x": 2,
      "y": 5,
      "z": -13,
      "name": "Wood_Azure_Trunk_Full"
    },
    {
      "x": 5,
      "y": 5,
      "z": -13,
      "name": "Wood_Azure_Trunk_Full"
    },
    {
      "x": 1,
      "y": 6,
      "z": -13,
      "name": "Wood_Azure_Trunk_Full"
    },
    {
      "x": 2,
      "y": 6,
      "z": -13,
      "name": "Wood_Azure_Trunk_Full"
    },
    {
      "x": 5,
      "y": 6,
      "z": -13,
      "name": "Wood_Azure_Trunk_Full"
    },
    {
      "x": 6,
      "y": 6,
      "z": -13,
      "name": "Wood_Azure_Trunk_Full"
    },
    {
      "x": 6,
      "y": 7,
      "z": -13,
      "name": "Wood_Azure_Trunk_Full"
    },
    {
      "x": 0,
      "y": 3,
      "z": -12,
      "name": "Soil_Clay_Blue"
    },
    {
      "x": 1,
      "y": 4,
      "z": -12,
      "name": "Soil_Clay_Blue"
    },
    {
      "x": 1,
      "y": 5,
      "z": -12,
      "name": "Wood_Azure_Trunk_Full"
    },
    {
      "x": 2,
      "y": 5,
      "z": -12,
      "name": "Wood_Azure_Trunk_Full"
    },
    {
      "x": 4,
      "y": 5,
      "z": -12,
      "name": "Wood_Azure_Trunk_Full"
    },
    {
      "x": 5,
      "y": 5,
      "z": -12,
      "name": "Wood_Azure_Trunk_Full"
    },
    {
      "x": 6,
      "y": 5,
      "z": -12,
      "name": "Wood_Azure_Trunk_Full"
    },
    {
      "x": 4,
      "y": 6,
      "z": -12,
      "name": "Wood_Azure_Trunk_Full"
    },
    {
      "x": 5,
      "y": 6,
      "z": -12,
      "name": "Wood_Azure_Trunk_Full"
    },
    {
      "x": 6,
      "y": 6,
      "z": -12,
      "name": "Wood_Azure_Trunk_Full"
    },
    {
      "x": 5,
      "y": 7,
      "z": -12,
      "name": "Wood_Azure_Trunk_Full"
    },
    {
      "x": 0,
      "y": 3,
      "z": -11,
      "name": "Soil_Clay_Blue"
    },
    {
      "x": 2,
      "y": 3,
      "z": -11,
      "name": "Soil_Clay_Blue"
    },
    {
      "x": 3,
      "y": 3,
      "z": -11,
      "name": "Soil_Clay_Blue"
    },
    {
      "x": 0,
      "y": 4,
      "z": -11,
      "name": "Soil_Clay_Blue"
    },
    {
      "x": 1,
      "y": 4,
      "z": -11,
      "name": "Soil_Clay_Blue"
    },
    {
      "x": 2,
      "y": 4,
      "z": -11,
      "name": "Soil_Clay_Blue"
    },
    {
      "x": 3,
      "y": 4,
      "z": -11,
      "name": "Soil_Clay_Blue"
    },
    {
      "x": 4,
      "y": 4,
      "z": -11,
      "name": "Soil_Clay_Blue"
    },
    {
      "x": 0,
      "y": 5,
      "z": -11,
      "name": "Soil_Clay_Blue"
    },
    {
      "x": 1,
      "y": 5,
      "z": -11,
      "name": "Soil_Clay_Blue"
    },
    {
      "x": 2,
      "y": 5,
      "z": -11,
      "name": "Wood_Azure_Trunk_Full"
    },
    {
      "x": 3,
      "y": 5,
      "z": -11,
      "name": "Plant_Coral_Model_Blue"
    },
    {
      "x": 4,
      "y": 5,
      "z": -11,
      "name": "Wood_Azure_Trunk_Full"
    },
    {
      "x": 5,
      "y": 5,
      "z": -11,
      "name": "Wood_Azure_Trunk_Full"
    },
    {
      "x": 8,
      "y": 5,
      "z": -11,
      "name": "Soil_Clay_Blue"
    },
    {
      "x": 0,
      "y": 6,
      "z": -11,
      "name": "Plant_Coral_Model_Blue"
    },
    {
      "x": 5,
      "y": 6,
      "z": -11,
      "name": "Wood_Azure_Trunk_Full"
    },
    {
      "x": 8,
      "y": 6,
      "z": -11,
      "name": "Soil_Clay_Blue"
    },
    {
      "x": 9,
      "y": 6,
      "z": -11,
      "name": "Wood_Azure_Trunk_Full"
    },
    {
      "x": 9,
      "y": 7,
      "z": -11,
      "name": "Wood_Azure_Trunk_Full"
    },
    {
      "x": 0,
      "y": 3,
      "z": -10,
      "name": "Soil_Clay_Blue"
    },
    {
      "x": 2,
      "y": 3,
      "z": -10,
      "name": "Soil_Clay_Blue"
    },
    {
      "x": 3,
      "y": 3,
      "z": -10,
      "name": "Soil_Clay_Blue"
    },
    {
      "x": 6,
      "y": 3,
      "z": -10,
      "name": "Soil_Clay_Blue"
    },
    {
      "x": 0,
      "y": 4,
      "z": -10,
      "name": "Soil_Clay_Blue"
    },
    {
      "x": 1,
      "y": 4,
      "z": -10,
      "name": "Soil_Clay_Blue"
    },
    {
      "x": 2,
      "y": 4,
      "z": -10,
      "name": "Soil_Clay_Blue"
    },
    {
      "x": 3,
      "y": 4,
      "z": -10,
      "name": "Soil_Clay_Blue"
    },
    {
      "x": 4,
      "y": 4,
      "z": -10,
      "name": "Soil_Clay_Blue"
    },
    {
      "x": 5,
      "y": 4,
      "z": -10,
      "name": "Soil_Clay_Blue"
    },
    {
      "x": 6,
      "y": 4,
      "z": -10,
      "name": "Soil_Clay_Blue"
    },
    {
      "x": 0,
      "y": 5,
      "z": -10,
      "name": "Soil_Clay_Blue"
    },
    {
      "x": 1,
      "y": 5,
      "z": -10,
      "name": "Soil_Clay_Blue"
    },
    {
      "x": 2,
      "y": 5,
      "z": -10,
      "name": "Soil_Clay_Blue"
    },
    {
      "x": 3,
      "y": 5,
      "z": -10,
      "name": "Soil_Clay_Blue"
    },
    {
      "x": 4,
      "y": 5,
      "z": -10,
      "name": "Soil_Clay_Blue"
    },
    {
      "x": 5,
      "y": 5,
      "z": -10,
      "name": "Wood_Azure_Trunk_Full"
    },
    {
      "x": 6,
      "y": 5,
      "z": -10,
      "name": "Plant_Coral_Model_Blue"
    },
    {
      "x": 8,
      "y": 5,
      "z": -10,
      "name": "Soil_Clay_Blue"
    },
    {
      "x": 9,
      "y": 5,
      "z": -10,
      "name": "Soil_Clay_Blue"
    },
    {
      "x": 1,
      "y": 6,
      "z": -10,
      "name": "Plant_Coral_Model_Blue"
    },
    {
      "x": 3,
      "y": 6,
      "z": -10,
      "name": "Plant_Coral_Model_Blue"
    },
    {
      "x": 4,
      "y": 6,
      "z": -10,
      "name": "Plant_Coral_Model_Blue"
    },
    {
      "x": 7,
      "y": 6,
      "z": -10,
      "name": "Soil_Clay_Blue"
    },
    {
      "x": 8,
      "y": 6,
      "z": -10,
      "name": "Soil_Clay_Blue"
    },
    {
      "x": 9,
      "y": 6,
      "z": -10,
      "name": "Soil_Clay_Blue"
    },
    {
      "x": 7,
      "y": 7,
      "z": -10,
      "name": "Soil_Clay_Blue"
    },
    {
      "x": 8,
      "y": 7,
      "z": -10,
      "name": "Wood_Azure_Trunk_Full"
    },
    {
      "x": 0,
      "y": 3,
      "z": -9,
      "name": "Soil_Clay_Blue"
    },
    {
      "x": 1,
      "y": 3,
      "z": -9,
      "name": "Soil_Clay_Blue"
    },
    {
      "x": 2,
      "y": 3,
      "z": -9,
      "name": "Soil_Clay_Blue"
    },
    {
      "x": 3,
      "y": 3,
      "z": -9,
      "name": "Soil_Clay_Blue"
    },
    {
      "x": 4,
      "y": 3,
      "z": -9,
      "name": "Soil_Clay_Blue"
    },
    {
      "x": 5,
      "y": 3,
      "z": -9,
      "name": "Soil_Clay_Blue"
    },
    {
      "x": 6,
      "y": 3,
      "z": -9,
      "name": "Soil_Clay_Blue"
    },
    {
      "x": 0,
      "y": 4,
      "z": -9,
      "name": "Soil_Clay_Blue"
    },
    {
      "x": 1,
      "y": 4,
      "z": -9,
      "name": "Soil_Clay_Blue"
    },
    {
      "x": 2,
      "y": 4,
      "z": -9,
      "name": "Soil_Clay_Blue"
    },
    {
      "x": 3,
      "y": 4,
      "z": -9,
      "name": "Soil_Clay_Blue"
    },
    {
      "x": 4,
      "y": 4,
      "z": -9,
      "name": "Soil_Clay_Blue"
    },
    {
      "x": 5,
      "y": 4,
      "z": -9,
      "name": "Soil_Clay_Blue"
    },
    {
      "x": 6,
      "y": 4,
      "z": -9,
      "name": "Soil_Clay_Blue"
    },
    {
      "x": 7,
      "y": 4,
      "z": -9,
      "name": "Soil_Clay_Blue"
    },
    {
      "x": 8,
      "y": 4,
      "z": -9,
      "name": "Soil_Clay_Blue"
    },
    {
      "x": 0,
      "y": 5,
      "z": -9,
      "name": "Soil_Clay_Blue"
    },
    {
      "x": 1,
      "y": 5,
      "z": -9,
      "name": "Soil_Clay_Blue"
    },
    {
      "x": 2,
      "y": 5,
      "z": -9,
      "name": "Soil_Clay_Blue"
    },
    {
      "x": 3,
      "y": 5,
      "z": -9,
      "name": "Soil_Clay_Blue"
    },
    {
      "x": 4,
      "y": 5,
      "z": -9,
      "name": "Soil_Clay_Blue"
    },
    {
      "x": 5,
      "y": 5,
      "z": -9,
      "name": "Soil_Clay_Blue"
    },
    {
      "x": 6,
      "y": 5,
      "z": -9,
      "name": "Soil_Clay_Blue"
    },
    {
      "x": 7,
      "y": 5,
      "z": -9,
      "name": "Soil_Clay_Blue"
    },
    {
      "x": 8,
      "y": 5,
      "z": -9,
      "name": "Soil_Clay_Blue"
    },
    {
      "x": 12,
      "y": 5,
      "z": -9,
      "name": "Wood_Azure_Trunk_Full"
    },
    {
      "x": 2,
      "y": 6,
      "z": -9,
      "name": "Plant_Coral_Model_Blue"
    },
    {
      "x": 3,
      "y": 6,
      "z": -9,
      "name": "Plant_Coral_Model_Blue"
    },
    {
      "x": 4,
      "y": 6,
      "z": -9,
      "name": "Plant_Coral_Model_Blue"
    },
    {
      "x": 5,
      "y": 6,
      "z": -9,
      "name": "Plant_Coral_Model_Blue"
    },
    {
      "x": 6,
      "y": 6,
      "z": -9,
      "name": "Soil_Clay_Blue"
    },
    {
      "x": 7,
      "y": 6,
      "z": -9,
      "name": "Soil_Clay_Blue"
    },
    {
      "x": 8,
      "y": 6,
      "z": -9,
      "name": "Soil_Clay_Blue"
    },
    {
      "x": 12,
      "y": 6,
      "z": -9,
      "name": "Wood_Azure_Trunk_Full"
    },
    {
      "x": 6,
      "y": 7,
      "z": -9,
      "name": "Soil_Clay_Blue"
    },
    {
      "x": 7,
      "y": 7,
      "z": -9,
      "name": "Soil_Clay_Blue"
    },
    {
      "x": 8,
      "y": 7,
      "z": -9,
      "name": "Soil_Clay_Blue"
    },
    {
      "x": 12,
      "y": 7,
      "z": -9,
      "name": "Wood_Azure_Trunk_Full"
    },
    {
      "x": 0,
      "y": 3,
      "z": -8,
      "name": "Soil_Clay_Blue"
    },
    {
      "x": 1,
      "y": 3,
      "z": -8,
      "name": "Soil_Clay_Blue"
    },
    {
      "x": 2,
      "y": 3,
      "z": -8,
      "name": "Soil_Clay_Blue"
    },
    {
      "x": 3,
      "y": 3,
      "z": -8,
      "name": "Soil_Clay_Blue"
    },
    {
      "x": 4,
      "y": 3,
      "z": -8,
      "name": "Soil_Clay_Blue"
    },
    {
      "x": 5,
      "y": 3,
      "z": -8,
      "name": "Soil_Clay_Blue"
    },
    {
      "x": 6,
      "y": 3,
      "z": -8,
      "name": "Soil_Clay_Blue"
    },
    {
      "x": 8,
      "y": 3,
      "z": -8,
      "name": "Soil_Clay_Blue"
    },
    {
      "x": 9,
      "y": 3,
      "z": -8,
      "name": "Soil_Clay_Blue"
    },
    {
      "x": 10,
      "y": 3,
      "z": -8,
      "name": "Wood_Azure_Trunk_Full"
    },
    {
      "x": 0,
      "y": 4,
      "z": -8,
      "name": "Soil_Clay_Blue"
    },
    {
      "x": 1,
      "y": 4,
      "z": -8,
      "name": "Soil_Clay_Blue"
    },
    {
      "x": 2,
      "y": 4,
      "z": -8,
      "name": "Soil_Clay_Blue"
    },
    {
      "x": 3,
      "y": 4,
      "z": -8,
      "name": "Soil_Clay_Blue"
    },
    {
      "x": 4,
      "y": 4,
      "z": -8,
      "name": "Soil_Clay_Blue"
    },
    {
      "x": 5,
      "y": 4,
      "z": -8,
      "name": "Soil_Clay_Blue"
    },
    {
      "x": 6,
      "y": 4,
      "z": -8,
      "name": "Soil_Clay_Blue"
    },
    {
      "x": 7,
      "y": 4,
      "z": -8,
      "name": "Soil_Clay_Blue"
    },
    {
      "x": 8,
      "y": 4,
      "z": -8,
      "name": "Soil_Clay_Blue"
    },
    {
      "x": 9,
      "y": 4,
      "z": -8,
      "name": "Wood_Azure_Trunk_Full"
    },
    {
      "x": 10,
      "y": 4,
      "z": -8,
      "name": "Wood_Azure_Trunk_Full"
    },
    {
      "x": 0,
      "y": 5,
      "z": -8,
      "name": "Soil_Clay_Blue"
    },
    {
      "x": 1,
      "y": 5,
      "z": -8,
      "name": "Soil_Clay_Blue"
    },
    {
      "x": 2,
      "y": 5,
      "z": -8,
      "name": "Soil_Clay_Blue"
    },
    {
      "x": 3,
      "y": 5,
      "z": -8,
      "name": "Soil_Clay_Blue"
    },
    {
      "x": 4,
      "y": 5,
      "z": -8,
      "name": "Soil_Clay_Blue"
    },
    {
      "x": 5,
      "y": 5,
      "z": -8,
      "name": "Soil_Clay_Blue"
    },
    {
      "x": 6,
      "y": 5,
      "z": -8,
      "name": "Soil_Clay_Blue"
    },
    {
      "x": 7,
      "y": 5,
      "z": -8,
      "name": "Soil_Clay_Blue"
    },
    {
      "x": 8,
      "y": 5,
      "z": -8,
      "name": "Wood_Azure_Trunk_Full"
    },
    {
      "x": 9,
      "y": 5,
      "z": -8,
      "name": "Wood_Azure_Trunk_Full"
    },
    {
      "x": 10,
      "y": 5,
      "z": -8,
      "name": "Wood_Azure_Trunk_Full"
    },
    {
      "x": 11,
      "y": 5,
      "z": -8,
      "name": "Wood_Azure_Trunk_Full"
    },
    {
      "x": 12,
      "y": 5,
      "z": -8,
      "name": "Wood_Azure_Trunk_Full"
    },
    {
      "x": 1,
      "y": 6,
      "z": -8,
      "name": "Plant_Coral_Block_Cyan"
    },
    {
      "x": 2,
      "y": 6,
      "z": -8,
      "name": "Plant_Coral_Block_Cyan"
    },
    {
      "x": 4,
      "y": 6,
      "z": -8,
      "name": "Plant_Coral_Model_Blue"
    },
    {
      "x": 6,
      "y": 6,
      "z": -8,
      "name": "Soil_Clay_Blue"
    },
    {
      "x": 7,
      "y": 6,
      "z": -8,
      "name": "Soil_Clay_Blue"
    },
    {
      "x": 8,
      "y": 6,
      "z": -8,
      "name": "Soil_Clay_Blue"
    },
    {
      "x": 11,
      "y": 6,
      "z": -8,
      "name": "Wood_Azure_Trunk_Full"
    },
    {
      "x": 12,
      "y": 6,
      "z": -8,
      "name": "Wood_Azure_Trunk_Full"
    },
    {
      "x": 1,
      "y": 7,
      "z": -8,
      "name": "Plant_Seaweed_Navi_Stack"
    },
    {
      "x": 2,
      "y": 7,
      "z": -8,
      "name": "Plant_Seaweed_Navi_Stack"
    },
    {
      "x": 7,
      "y": 7,
      "z": -8,
      "name": "Soil_Clay_Blue"
    },
    {
      "x": 8,
      "y": 7,
      "z": -8,
      "name": "Soil_Clay_Blue"
    },
    {
      "x": 11,
      "y": 7,
      "z": -8,
      "name": "Wood_Azure_Trunk_Full"
    },
    {
      "x": 3,
      "y": 2,
      "z": -7,
      "name": "Soil_Clay_Blue"
    },
    {
      "x": 0,
      "y": 3,
      "z": -7,
      "name": "Soil_Clay_Blue"
    },
    {
      "x": 1,
      "y": 3,
      "z": -7,
      "name": "Soil_Clay_Blue"
    },
    {
      "x": 2,
      "y": 3,
      "z": -7,
      "name": "Soil_Clay_Blue"
    },
    {
      "x": 3,
      "y": 3,
      "z": -7,
      "name": "Soil_Clay_Blue"
    },
    {
      "x": 4,
      "y": 3,
      "z": -7,
      "name": "Soil_Clay_Blue"
    },
    {
      "x": 5,
      "y": 3,
      "z": -7,
      "name": "Soil_Clay_Blue"
    },
    {
      "x": 6,
      "y": 3,
      "z": -7,
      "name": "Soil_Clay_Blue"
    },
    {
      "x": 7,
      "y": 3,
      "z": -7,
      "name": "Soil_Clay_Blue"
    },
    {
      "x": 8,
      "y": 3,
      "z": -7,
      "name": "Soil_Clay_Blue"
    },
    {
      "x": 9,
      "y": 3,
      "z": -7,
      "name": "Soil_Clay_Blue"
    },
    {
      "x": 0,
      "y": 4,
      "z": -7,
      "name": "Soil_Clay_Blue"
    },
    {
      "x": 1,
      "y": 4,
      "z": -7,
      "name": "Soil_Clay_Blue"
    },
    {
      "x": 2,
      "y": 4,
      "z": -7,
      "name": "Soil_Clay_Blue"
    },
    {
      "x": 3,
      "y": 4,
      "z": -7,
      "name": "Soil_Clay_Blue"
    },
    {
      "x": 4,
      "y": 4,
      "z": -7,
      "name": "Soil_Clay_Blue"
    },
    {
      "x": 5,
      "y": 4,
      "z": -7,
      "name": "Soil_Clay_Blue"
    },
    {
      "x": 6,
      "y": 4,
      "z": -7,
      "name": "Soil_Clay_Blue"
    },
    {
      "x": 7,
      "y": 4,
      "z": -7,
      "name": "Soil_Clay_Blue"
    },
    {
      "x": 8,
      "y": 4,
      "z": -7,
      "name": "Soil_Clay_Blue"
    },
    {
      "x": 9,
      "y": 4,
      "z": -7,
      "name": "Soil_Clay_Blue"
    },
    {
      "x": 10,
      "y": 4,
      "z": -7,
      "name": "Wood_Azure_Trunk_Full"
    },
    {
      "x": 0,
      "y": 5,
      "z": -7,
      "name": "Soil_Clay_Blue"
    },
    {
      "x": 1,
      "y": 5,
      "z": -7,
      "name": "Soil_Clay_Blue"
    },
    {
      "x": 2,
      "y": 5,
      "z": -7,
      "name": "Soil_Clay_Blue"
    },
    {
      "x": 3,
      "y": 5,
      "z": -7,
      "name": "Plant_Coral_Block_Cyan"
    },
    {
      "x": 4,
      "y": 5,
      "z": -7,
      "name": "Soil_Clay_Blue"
    },
    {
      "x": 5,
      "y": 5,
      "z": -7,
      "name": "Soil_Clay_Blue"
    },
    {
      "x": 6,
      "y": 5,
      "z": -7,
      "name": "Soil_Clay_Blue"
    },
    {
      "x": 7,
      "y": 5,
      "z": -7,
      "name": "Soil_Clay_Blue"
    },
    {
      "x": 8,
      "y": 5,
      "z": -7,
      "name": "Soil_Clay_Blue"
    },
    {
      "x": 9,
      "y": 5,
      "z": -7,
      "name": "Wood_Azure_Trunk_Full"
    },
    {
      "x": 10,
      "y": 5,
      "z": -7,
      "name": "Wood_Azure_Trunk_Full"
    },
    {
      "x": 11,
      "y": 5,
      "z": -7,
      "name": "Wood_Azure_Trunk_Full"
    },
    {
      "x": 0,
      "y": 6,
      "z": -7,
      "name": "Plant_Coral_Block_Blue"
    },
    {
      "x": 1,
      "y": 6,
      "z": -7,
      "name": "Plant_Coral_Block_Cyan"
    },
    {
      "x": 2,
      "y": 6,
      "z": -7,
      "name": "Plant_Coral_Block_Cyan"
    },
    {
      "x": 3,
      "y": 6,
      "z": -7,
      "name": "Plant_Coral_Block_Cyan"
    },
    {
      "x": 4,
      "y": 6,
      "z": -7,
      "name": "Plant_Coral_Model_Blue"
    },
    {
      "x": 6,
      "y": 6,
      "z": -7,
      "name": "Plant_Coral_Model_Blue"
    },
    {
      "x": 7,
      "y": 6,
      "z": -7,
      "name": "Plant_Coral_Model_Blue"
    },
    {
      "x": 1,
      "y": 7,
      "z": -7,
      "name": "Plant_Coral_Block_Cyan"
    },
    {
      "x": 2,
      "y": 7,
      "z": -7,
      "name": "Plant_Coral_Block_Cyan"
    },
    {
      "x": 3,
      "y": 7,
      "z": -7,
      "name": "Plant_Seaweed_Navi_Stack"
    },
    {
      "x": 0,
      "y": 2,
      "z": -6,
      "name": "Soil_Clay_Blue"
    },
    {
      "x": 1,
      "y": 2,
      "z": -6,
      "name": "Soil_Clay_Blue"
    },
    {
      "x": 2,
      "y": 2,
      "z": -6,
      "name": "Soil_Clay_Blue"
    },
    {
      "x": 3,
      "y": 2,
      "z": -6,
      "name": "Soil_Clay_Blue"
    },
    {
      "x": 4,
      "y": 2,
      "z": -6,
      "name": "Soil_Clay_Blue"
    },
    {
      "x": 5,
      "y": 2,
      "z": -6,
      "name": "Soil_Clay_Blue"
    },
    {
      "x": 0,
      "y": 3,
      "z": -6,
      "name": "Soil_Clay_Blue"
    },
    {
      "x": 1,
      "y": 3,
      "z": -6,
      "name": "Soil_Clay_Blue"
    },
    {
      "x": 2,
      "y": 3,
      "z": -6,
      "name": "Soil_Clay_Blue"
    },
    {
      "x": 3,
      "y": 3,
      "z": -6,
      "name": "Soil_Clay_Blue"
    },
    {
      "x": 4,
      "y": 3,
      "z": -6,
      "name": "Soil_Clay_Blue"
    },
    {
      "x": 5,
      "y": 3,
      "z": -6,
      "name": "Soil_Clay_Blue"
    },
    {
      "x": 6,
      "y": 3,
      "z": -6,
      "name": "Soil_Clay_Blue"
    },
    {
      "x": 7,
      "y": 3,
      "z": -6,
      "name": "Soil_Clay_Blue"
    },
    {
      "x": 8,
      "y": 3,
      "z": -6,
      "name": "Soil_Clay_Blue"
    },
    {
      "x": 10,
      "y": 3,
      "z": -6,
      "name": "Soil_Clay_Blue"
    },
    {
      "x": 11,
      "y": 3,
      "z": -6,
      "name": "Soil_Clay_Blue"
    },
    {
      "x": 12,
      "y": 3,
      "z": -6,
      "name": "Soil_Clay_Blue"
    },
    {
      "x": 0,
      "y": 4,
      "z": -6,
      "name": "Soil_Clay_Blue"
    },
    {
      "x": 1,
      "y": 4,
      "z": -6,
      "name": "Soil_Clay_Blue"
    },
    {
      "x": 2,
      "y": 4,
      "z": -6,
      "name": "Soil_Clay_Blue"
    },
    {
      "x": 3,
      "y": 4,
      "z": -6,
      "name": "Soil_Clay_Blue"
    },
    {
      "x": 4,
      "y": 4,
      "z": -6,
      "name": "Soil_Clay_Blue"
    },
    {
      "x": 5,
      "y": 4,
      "z": -6,
      "name": "Soil_Clay_Blue"
    },
    {
      "x": 6,
      "y": 4,
      "z": -6,
      "name": "Soil_Clay_Blue"
    },
    {
      "x": 7,
      "y": 4,
      "z": -6,
      "name": "Soil_Clay_Blue"
    },
    {
      "x": 8,
      "y": 4,
      "z": -6,
      "name": "Soil_Clay_Blue"
    },
    {
      "x": 9,
      "y": 4,
      "z": -6,
      "name": "Soil_Clay_Blue"
    },
    {
      "x": 10,
      "y": 4,
      "z": -6,
      "name": "Soil_Clay_Blue"
    },
    {
      "x": 11,
      "y": 4,
      "z": -6,
      "name": "Wood_Azure_Trunk_Full"
    },
    {
      "x": 0,
      "y": 5,
      "z": -6,
      "name": "Plant_Coral_Block_Cyan"
    },
    {
      "x": 1,
      "y": 5,
      "z": -6,
      "name": "Plant_Coral_Block_Cyan"
    },
    {
      "x": 2,
      "y": 5,
      "z": -6,
      "name": "Plant_Coral_Block_Cyan"
    },
    {
      "x": 3,
      "y": 5,
      "z": -6,
      "name": "Soil_Clay_Blue"
    },
    {
      "x": 4,
      "y": 5,
      "z": -6,
      "name": "Plant_Coral_Block_Cyan"
    },
    {
      "x": 5,
      "y": 5,
      "z": -6,
      "name": "Plant_Coral_Block_Blue"
    },
    {
      "x": 6,
      "y": 5,
      "z": -6,
      "name": "Soil_Clay_Blue"
    },
    {
      "x": 7,
      "y": 5,
      "z": -6,
      "name": "Soil_Clay_Blue"
    },
    {
      "x": 8,
      "y": 5,
      "z": -6,
      "name": "Soil_Clay_Blue"
    },
    {
      "x": 9,
      "y": 5,
      "z": -6,
      "name": "Soil_Clay_Blue"
    },
    {
      "x": 10,
      "y": 5,
      "z": -6,
      "name": "Wood_Azure_Trunk_Full"
    },
    {
      "x": 11,
      "y": 5,
      "z": -6,
      "name": "Wood_Azure_Trunk_Full"
    },
    {
      "x": 13,
      "y": 5,
      "z": -6,
      "name": "Wood_Azure_Trunk_Full"
    },
    {
      "x": 0,
      "y": 6,
      "z": -6,
      "name": "Plant_Coral_Block_Blue"
    },
    {
      "x": 1,
      "y": 6,
      "z": -6,
      "name": "Plant_Coral_Block_Cyan"
    },
    {
      "x": 2,
      "y": 6,
      "z": -6,
      "name": "Plant_Coral_Block_Cyan"
    },
    {
      "x": 3,
      "y": 6,
      "z": -6,
      "name": "Plant_Coral_Block_Blue"
    },
    {
      "x": 4,
      "y": 6,
      "z": -6,
      "name": "Plant_Coral_Block_Blue"
    },
    {
      "x": 6,
      "y": 6,
      "z": -6,
      "name": "Plant_Coral_Block_Cyan"
    },
    {
      "x": 8,
      "y": 6,
      "z": -6,
      "name": "Plant_Coral_Model_Blue"
    },
    {
      "x": 9,
      "y": 6,
      "z": -6,
      "name": "Plant_Coral_Model_Blue"
    },
    {
      "x": 11,
      "y": 6,
      "z": -6,
      "name": "Wood_Azure_Trunk_Full"
    },
    {
      "x": 12,
      "y": 6,
      "z": -6,
      "name": "Wood_Azure_Trunk_Full"
    },
    {
      "x": 13,
      "y": 6,
      "z": -6,
      "name": "Wood_Azure_Trunk_Full"
    },
    {
      "x": 1,
      "y": 7,
      "z": -6,
      "name": "Plant_Coral_Block_Cyan"
    },
    {
      "x": 2,
      "y": 7,
      "z": -6,
      "name": "Plant_Coral_Block_Cyan"
    },
    {
      "x": 6,
      "y": 7,
      "z": -6,
      "name": "Plant_Seaweed_Navi_Stack"
    },
    {
      "x": 12,
      "y": 7,
      "z": -6,
      "name": "Wood_Azure_Trunk_Full"
    },
    {
      "x": 13,
      "y": 7,
      "z": -6,
      "name": "Wood_Azure_Trunk_Full"
    },
    {
      "x": 14,
      "y": 7,
      "z": -6,
      "name": "Wood_Azure_Trunk_Full"
    },
    {
      "x": 0,
      "y": 1,
      "z": -5,
      "name": "Soil_Clay_Blue"
    },
    {
      "x": 1,
      "y": 1,
      "z": -5,
      "name": "Soil_Clay_Blue"
    },
    {
      "x": 2,
      "y": 1,
      "z": -5,
      "name": "Soil_Clay_Blue"
    },
    {
      "x": 3,
      "y": 1,
      "z": -5,
      "name": "Soil_Clay_Blue"
    },
    {
      "x": 4,
      "y": 1,
      "z": -5,
      "name": "Soil_Clay_Blue"
    },
    {
      "x": 0,
      "y": 2,
      "z": -5,
      "name": "Plant_Coral_Block_Cyan"
    },
    {
      "x": 1,
      "y": 2,
      "z": -5,
      "name": "Soil_Clay_Blue"
    },
    {
      "x": 2,
      "y": 2,
      "z": -5,
      "name": "Soil_Clay_Blue"
    },
    {
      "x": 3,
      "y": 2,
      "z": -5,
      "name": "Soil_Clay_Blue"
    },
    {
      "x": 4,
      "y": 2,
      "z": -5,
      "name": "Soil_Clay_Blue"
    },
    {
      "x": 5,
      "y": 2,
      "z": -5,
      "name": "Soil_Clay_Blue"
    },
    {
      "x": 0,
      "y": 3,
      "z": -5,
      "name": "Plant_Coral_Block_Cyan"
    },
    {
      "x": 1,
      "y": 3,
      "z": -5,
      "name": "Plant_Coral_Block_Cyan"
    },
    {
      "x": 2,
      "y": 3,
      "z": -5,
      "name": "Plant_Coral_Block_Cyan"
    },
    {
      "x": 3,
      "y": 3,
      "z": -5,
      "name": "Plant_Coral_Block_Cyan"
    },
    {
      "x": 4,
      "y": 3,
      "z": -5,
      "name": "Soil_Clay_Blue"
    },
    {
      "x": 5,
      "y": 3,
      "z": -5,
      "name": "Soil_Clay_Blue"
    },
    {
      "x": 6,
      "y": 3,
      "z": -5,
      "name": "Soil_Clay_Blue"
    },
    {
      "x": 7,
      "y": 3,
      "z": -5,
      "name": "Soil_Clay_Blue"
    },
    {
      "x": 8,
      "y": 3,
      "z": -5,
      "name": "Soil_Clay_Blue"
    },
    {
      "x": 9,
      "y": 3,
      "z": -5,
      "name": "Soil_Clay_Blue"
    },
    {
      "x": 10,
      "y": 3,
      "z": -5,
      "name": "Soil_Clay_Blue"
    },
    {
      "x": 11,
      "y": 3,
      "z": -5,
      "name": "Soil_Clay_Blue"
    },
    {
      "x": 0,
      "y": 4,
      "z": -5,
      "name": "Plant_Coral_Block_Cyan"
    },
    {
      "x": 1,
      "y": 4,
      "z": -5,
      "name": "Plant_Coral_Block_Cyan"
    },
    {
      "x": 2,
      "y": 4,
      "z": -5,
      "name": "Plant_Coral_Block_Cyan"
    },
    {
      "x": 3,
      "y": 4,
      "z": -5,
      "name": "Plant_Coral_Block_Cyan"
    },
    {
      "x": 4,
      "y": 4,
      "z": -5,
      "name": "Plant_Coral_Block_Cyan"
    },
    {
      "x": 5,
      "y": 4,
      "z": -5,
      "name": "Soil_Clay_Blue"
    },
    {
      "x": 6,
      "y": 4,
      "z": -5,
      "name": "Soil_Clay_Blue"
    },
    {
      "x": 7,
      "y": 4,
      "z": -5,
      "name": "Soil_Clay_Blue"
    },
    {
      "x": 8,
      "y": 4,
      "z": -5,
      "name": "Soil_Clay_Blue"
    },
    {
      "x": 9,
      "y": 4,
      "z": -5,
      "name": "Soil_Clay_Blue"
    },
    {
      "x": 10,
      "y": 4,
      "z": -5,
      "name": "Soil_Clay_Blue"
    },
    {
      "x": 11,
      "y": 4,
      "z": -5,
      "name": "Soil_Clay_Blue"
    },
    {
      "x": 12,
      "y": 4,
      "z": -5,
      "name": "Wood_Azure_Trunk_Full"
    },
    {
      "x": 0,
      "y": 5,
      "z": -5,
      "name": "Plant_Coral_Block_Cyan"
    },
    {
      "x": 1,
      "y": 5,
      "z": -5,
      "name": "Plant_Coral_Block_Cyan"
    },
    {
      "x": 2,
      "y": 5,
      "z": -5,
      "name": "Plant_Coral_Block_Cyan"
    },
    {
      "x": 3,
      "y": 5,
      "z": -5,
      "name": "Plant_Coral_Block_Cyan"
    },
    {
      "x": 4,
      "y": 5,
      "z": -5,
      "name": "Plant_Coral_Block_Cyan"
    },
    {
      "x": 5,
      "y": 5,
      "z": -5,
      "name": "Plant_Coral_Block_Cyan"
    },
    {
      "x": 6,
      "y": 5,
      "z": -5,
      "name": "Plant_Coral_Block_Cyan"
    },
    {
      "x": 7,
      "y": 5,
      "z": -5,
      "name": "Soil_Clay_Blue"
    },
    {
      "x": 8,
      "y": 5,
      "z": -5,
      "name": "Soil_Clay_Blue"
    },
    {
      "x": 9,
      "y": 5,
      "z": -5,
      "name": "Soil_Clay_Blue"
    },
    {
      "x": 10,
      "y": 5,
      "z": -5,
      "name": "Soil_Clay_Blue"
    },
    {
      "x": 11,
      "y": 5,
      "z": -5,
      "name": "Wood_Azure_Trunk_Full"
    },
    {
      "x": 12,
      "y": 5,
      "z": -5,
      "name": "Wood_Azure_Trunk_Full"
    },
    {
      "x": 13,
      "y": 5,
      "z": -5,
      "name": "Wood_Azure_Trunk_Full"
    },
    {
      "x": 14,
      "y": 5,
      "z": -5,
      "name": "Wood_Azure_Trunk_Full"
    },
    {
      "x": 0,
      "y": 6,
      "z": -5,
      "name": "Plant_Coral_Block_Blue"
    },
    {
      "x": 1,
      "y": 6,
      "z": -5,
      "name": "Plant_Coral_Block_Cyan"
    },
    {
      "x": 2,
      "y": 6,
      "z": -5,
      "name": "Plant_Coral_Block_Cyan"
    },
    {
      "x": 3,
      "y": 6,
      "z": -5,
      "name": "Plant_Coral_Block_Blue"
    },
    {
      "x": 4,
      "y": 6,
      "z": -5,
      "name": "Plant_Coral_Block_Cyan"
    },
    {
      "x": 5,
      "y": 6,
      "z": -5,
      "name": "Plant_Coral_Block_Cyan"
    },
    {
      "x": 6,
      "y": 6,
      "z": -5,
      "name": "Plant_Coral_Block_Cyan"
    },
    {
      "x": 7,
      "y": 6,
      "z": -5,
      "name": "Plant_Coral_Block_Cyan"
    },
    {
      "x": 8,
      "y": 6,
      "z": -5,
      "name": "Plant_Coral_Model_Blue"
    },
    {
      "x": 9,
      "y": 6,
      "z": -5,
      "name": "Plant_Coral_Model_Blue"
    },
    {
      "x": 10,
      "y": 6,
      "z": -5,
      "name": "Plant_Coral_Model_Blue"
    },
    {
      "x": 11,
      "y": 6,
      "z": -5,
      "name": "Wood_Azure_Trunk_Full"
    },
    {
      "x": 12,
      "y": 6,
      "z": -5,
      "name": "Wood_Azure_Trunk_Full"
    },
    {
      "x": 13,
      "y": 6,
      "z": -5,
      "name": "Wood_Azure_Trunk_Full"
    },
    {
      "x": 14,
      "y": 6,
      "z": -5,
      "name": "Wood_Azure_Trunk_Full"
    },
    {
      "x": 1,
      "y": 7,
      "z": -5,
      "name": "Plant_Coral_Block_Cyan"
    },
    {
      "x": 2,
      "y": 7,
      "z": -5,
      "name": "Plant_Coral_Block_Cyan"
    },
    {
      "x": 4,
      "y": 7,
      "z": -5,
      "name": "Plant_Coral_Block_Blue"
    },
    {
      "x": 5,
      "y": 7,
      "z": -5,
      "name": "Plant_Coral_Block_Cyan"
    },
    {
      "x": 6,
      "y": 7,
      "z": -5,
      "name": "Plant_Seaweed_Navi_Stack"
    },
    {
      "x": 7,
      "y": 7,
      "z": -5,
      "name": "Plant_Seaweed_Navi_Stack"
    },
    {
      "x": 11,
      "y": 7,
      "z": -5,
      "name": "Wood_Azure_Trunk_Full"
    },
    {
      "x": 12,
      "y": 7,
      "z": -5,
      "name": "Wood_Azure_Trunk_Full"
    },
    {
      "x": 13,
      "y": 7,
      "z": -5,
      "name": "Wood_Azure_Trunk_Full"
    },
    {
      "x": 14,
      "y": 7,
      "z": -5,
      "name": "Wood_Azure_Trunk_Full"
    },
    {
      "x": 0,
      "y": 1,
      "z": -4,
      "name": "Soil_Clay_Blue"
    },
    {
      "x": 1,
      "y": 1,
      "z": -4,
      "name": "Soil_Clay_Blue"
    },
    {
      "x": 2,
      "y": 1,
      "z": -4,
      "name": "Soil_Clay_Blue"
    },
    {
      "x": 3,
      "y": 1,
      "z": -4,
      "name": "Soil_Clay_Blue"
    },
    {
      "x": 4,
      "y": 1,
      "z": -4,
      "name": "Soil_Clay_Blue"
    },
    {
      "x": 5,
      "y": 1,
      "z": -4,
      "name": "Soil_Clay_Blue"
    },
    {
      "x": 0,
      "y": 2,
      "z": -4,
      "name": "Plant_Coral_Block_Cyan"
    },
    {
      "x": 1,
      "y": 2,
      "z": -4,
      "name": "Plant_Coral_Block_Cyan"
    },
    {
      "x": 2,
      "y": 2,
      "z": -4,
      "name": "Plant_Coral_Block_Cyan"
    },
    {
      "x": 3,
      "y": 2,
      "z": -4,
      "name": "Plant_Coral_Block_Cyan"
    },
    {
      "x": 4,
      "y": 2,
      "z": -4,
      "name": "Soil_Clay_Blue"
    },
    {
      "x": 5,
      "y": 2,
      "z": -4,
      "name": "Soil_Clay_Blue"
    },
    {
      "x": 6,
      "y": 2,
      "z": -4,
      "name": "Soil_Clay_Blue"
    },
    {
      "x": 0,
      "y": 3,
      "z": -4,
      "name": "Plant_Coral_Block_Cyan"
    },
    {
      "x": 1,
      "y": 3,
      "z": -4,
      "name": "Plant_Coral_Block_Cyan"
    },
    {
      "x": 2,
      "y": 3,
      "z": -4,
      "name": "Plant_Coral_Block_Cyan"
    },
    {
      "x": 3,
      "y": 3,
      "z": -4,
      "name": "Plant_Coral_Block_Cyan"
    },
    {
      "x": 4,
      "y": 3,
      "z": -4,
      "name": "Plant_Coral_Block_Cyan"
    },
    {
      "x": 5,
      "y": 3,
      "z": -4,
      "name": "Soil_Clay_Blue"
    },
    {
      "x": 6,
      "y": 3,
      "z": -4,
      "name": "Soil_Clay_Blue"
    },
    {
      "x": 7,
      "y": 3,
      "z": -4,
      "name": "Soil_Clay_Blue"
    },
    {
      "x": 8,
      "y": 3,
      "z": -4,
      "name": "Soil_Clay_Blue"
    },
    {
      "x": 9,
      "y": 3,
      "z": -4,
      "name": "Soil_Clay_Blue"
    },
    {
      "x": 10,
      "y": 3,
      "z": -4,
      "name": "Soil_Clay_Blue"
    },
    {
      "x": 0,
      "y": 4,
      "z": -4,
      "name": "Plant_Coral_Block_Cyan"
    },
    {
      "x": 1,
      "y": 4,
      "z": -4,
      "name": "Plant_Coral_Block_Cyan"
    },
    {
      "x": 2,
      "y": 4,
      "z": -4,
      "name": "Plant_Coral_Block_Cyan"
    },
    {
      "x": 3,
      "y": 4,
      "z": -4,
      "name": "Plant_Coral_Block_Cyan"
    },
    {
      "x": 4,
      "y": 4,
      "z": -4,
      "name": "Plant_Coral_Block_Cyan"
    },
    {
      "x": 5,
      "y": 4,
      "z": -4,
      "name": "Plant_Coral_Block_Cyan"
    },
    {
      "x": 6,
      "y": 4,
      "z": -4,
      "name": "Soil_Clay_Blue"
    },
    {
      "x": 7,
      "y": 4,
      "z": -4,
      "name": "Soil_Clay_Blue"
    },
    {
      "x": 8,
      "y": 4,
      "z": -4,
      "name": "Soil_Clay_Blue"
    },
    {
      "x": 9,
      "y": 4,
      "z": -4,
      "name": "Soil_Clay_Blue"
    },
    {
      "x": 10,
      "y": 4,
      "z": -4,
      "name": "Soil_Clay_Blue"
    },
    {
      "x": 11,
      "y": 4,
      "z": -4,
      "name": "Soil_Clay_Blue"
    },
    {
      "x": 12,
      "y": 4,
      "z": -4,
      "name": "Soil_Clay_Blue"
    },
    {
      "x": 0,
      "y": 5,
      "z": -4,
      "name": "Plant_Coral_Block_Blue"
    },
    {
      "x": 1,
      "y": 5,
      "z": -4,
      "name": "Plant_Coral_Block_Cyan"
    },
    {
      "x": 2,
      "y": 5,
      "z": -4,
      "name": "Plant_Coral_Block_Blue"
    },
    {
      "x": 3,
      "y": 5,
      "z": -4,
      "name": "Plant_Coral_Block_Blue"
    },
    {
      "x": 4,
      "y": 5,
      "z": -4,
      "name": "Plant_Coral_Block_Cyan"
    },
    {
      "x": 5,
      "y": 5,
      "z": -4,
      "name": "Plant_Coral_Block_Cyan"
    },
    {
      "x": 6,
      "y": 5,
      "z": -4,
      "name": "Plant_Coral_Block_Cyan"
    },
    {
      "x": 7,
      "y": 5,
      "z": -4,
      "name": "Soil_Clay_Blue"
    },
    {
      "x": 8,
      "y": 5,
      "z": -4,
      "name": "Soil_Clay_Blue"
    },
    {
      "x": 9,
      "y": 5,
      "z": -4,
      "name": "Soil_Clay_Blue"
    },
    {
      "x": 10,
      "y": 5,
      "z": -4,
      "name": "Soil_Clay_Blue"
    },
    {
      "x": 11,
      "y": 5,
      "z": -4,
      "name": "Soil_Clay_Blue"
    },
    {
      "x": 12,
      "y": 5,
      "z": -4,
      "name": "Wood_Azure_Trunk_Full"
    },
    {
      "x": 1,
      "y": 6,
      "z": -4,
      "name": "Plant_Coral_Block_Cyan"
    },
    {
      "x": 4,
      "y": 6,
      "z": -4,
      "name": "Plant_Coral_Block_Blue"
    },
    {
      "x": 5,
      "y": 6,
      "z": -4,
      "name": "Plant_Coral_Block_Cyan"
    },
    {
      "x": 6,
      "y": 6,
      "z": -4,
      "name": "Plant_Coral_Block_Cyan"
    },
    {
      "x": 7,
      "y": 6,
      "z": -4,
      "name": "Plant_Coral_Block_Blue"
    },
    {
      "x": 8,
      "y": 6,
      "z": -4,
      "name": "Plant_Coral_Model_Blue"
    },
    {
      "x": 9,
      "y": 6,
      "z": -4,
      "name": "Plant_Coral_Model_Blue"
    },
    {
      "x": 11,
      "y": 6,
      "z": -4,
      "name": "Wood_Azure_Trunk_Full"
    },
    {
      "x": 12,
      "y": 6,
      "z": -4,
      "name": "Wood_Azure_Trunk_Full"
    },
    {
      "x": 13,
      "y": 6,
      "z": -4,
      "name": "Wood_Azure_Trunk_Full"
    },
    {
      "x": 1,
      "y": 7,
      "z": -4,
      "name": "Plant_Seaweed_Navi_Stack"
    },
    {
      "x": 5,
      "y": 7,
      "z": -4,
      "name": "Plant_Coral_Block_Cyan"
    },
    {
      "x": 6,
      "y": 7,
      "z": -4,
      "name": "Plant_Coral_Block_Cyan"
    },
    {
      "x": 12,
      "y": 7,
      "z": -4,
      "name": "Wood_Azure_Trunk_Full"
    },
    {
      "x": 13,
      "y": 7,
      "z": -4,
      "name": "Wood_Azure_Trunk_Full"
    },
    {
      "x": 1,
      "y": 0,
      "z": -3,
      "name": "Soil_Clay_Blue"
    },
    {
      "x": 2,
      "y": 0,
      "z": -3,
      "name": "Soil_Clay_Blue"
    },
    {
      "x": 0,
      "y": 1,
      "z": -3,
      "name": "Soil_Clay_Blue"
    },
    {
      "x": 1,
      "y": 1,
      "z": -3,
      "name": "Plant_Coral_Block_Cyan"
    },
    {
      "x": 2,
      "y": 1,
      "z": -3,
      "name": "Plant_Coral_Block_Cyan"
    },
    {
      "x": 3,
      "y": 1,
      "z": -3,
      "name": "Soil_Clay_Blue"
    },
    {
      "x": 4,
      "y": 1,
      "z": -3,
      "name": "Soil_Clay_Blue"
    },
    {
      "x": 5,
      "y": 1,
      "z": -3,
      "name": "Soil_Clay_Blue"
    },
    {
      "x": 6,
      "y": 1,
      "z": -3,
      "name": "Soil_Clay_Blue"
    },
    {
      "x": 0,
      "y": 2,
      "z": -3,
      "name": "Plant_Coral_Block_Cyan"
    },
    {
      "x": 1,
      "y": 2,
      "z": -3,
      "name": "Plant_Coral_Block_Cyan"
    },
    {
      "x": 2,
      "y": 2,
      "z": -3,
      "name": "Plant_Coral_Block_Cyan"
    },
    {
      "x": 3,
      "y": 2,
      "z": -3,
      "name": "Plant_Coral_Block_Cyan"
    },
    {
      "x": 4,
      "y": 2,
      "z": -3,
      "name": "Plant_Coral_Block_Cyan"
    },
    {
      "x": 5,
      "y": 2,
      "z": -3,
      "name": "Soil_Clay_Blue"
    },
    {
      "x": 6,
      "y": 2,
      "z": -3,
      "name": "Soil_Clay_Blue"
    },
    {
      "x": 7,
      "y": 2,
      "z": -3,
      "name": "Soil_Clay_Blue"
    },
    {
      "x": 0,
      "y": 3,
      "z": -3,
      "name": "Plant_Coral_Block_Cyan"
    },
    {
      "x": 1,
      "y": 3,
      "z": -3,
      "name": "Plant_Coral_Block_Cyan"
    },
    {
      "x": 2,
      "y": 3,
      "z": -3,
      "name": "Plant_Coral_Block_Cyan"
    },
    {
      "x": 3,
      "y": 3,
      "z": -3,
      "name": "Plant_Coral_Block_Cyan"
    },
    {
      "x": 4,
      "y": 3,
      "z": -3,
      "name": "Plant_Coral_Block_Cyan"
    },
    {
      "x": 5,
      "y": 3,
      "z": -3,
      "name": "Plant_Coral_Block_Cyan"
    },
    {
      "x": 6,
      "y": 3,
      "z": -3,
      "name": "Soil_Clay_Blue"
    },
    {
      "x": 7,
      "y": 3,
      "z": -3,
      "name": "Soil_Clay_Blue"
    },
    {
      "x": 8,
      "y": 3,
      "z": -3,
      "name": "Soil_Clay_Blue"
    },
    {
      "x": 9,
      "y": 3,
      "z": -3,
      "name": "Soil_Clay_Blue"
    },
    {
      "x": 10,
      "y": 3,
      "z": -3,
      "name": "Soil_Clay_Blue"
    },
    {
      "x": 11,
      "y": 3,
      "z": -3,
      "name": "Soil_Clay_Blue"
    },
    {
      "x": 12,
      "y": 3,
      "z": -3,
      "name": "Soil_Clay_Blue"
    },
    {
      "x": 13,
      "y": 3,
      "z": -3,
      "name": "Soil_Clay_Blue"
    },
    {
      "x": 0,
      "y": 4,
      "z": -3,
      "name": "Plant_Coral_Block_Blue"
    },
    {
      "x": 1,
      "y": 4,
      "z": -3,
      "name": "Plant_Coral_Block_Cyan"
    },
    {
      "x": 2,
      "y": 4,
      "z": -3,
      "name": "Plant_Coral_Block_Blue"
    },
    {
      "x": 3,
      "y": 4,
      "z": -3,
      "name": "Plant_Coral_Block_Cyan"
    },
    {
      "x": 4,
      "y": 4,
      "z": -3,
      "name": "Plant_Coral_Block_Cyan"
    },
    {
      "x": 5,
      "y": 4,
      "z": -3,
      "name": "Plant_Coral_Block_Cyan"
    },
    {
      "x": 6,
      "y": 4,
      "z": -3,
      "name": "Plant_Coral_Block_Cyan"
    },
    {
      "x": 7,
      "y": 4,
      "z": -3,
      "name": "Soil_Clay_Blue"
    },
    {
      "x": 8,
      "y": 4,
      "z": -3,
      "name": "Soil_Clay_Blue"
    },
    {
      "x": 9,
      "y": 4,
      "z": -3,
      "name": "Soil_Clay_Blue"
    },
    {
      "x": 10,
      "y": 4,
      "z": -3,
      "name": "Soil_Clay_Blue"
    },
    {
      "x": 11,
      "y": 4,
      "z": -3,
      "name": "Soil_Clay_Blue"
    },
    {
      "x": 12,
      "y": 4,
      "z": -3,
      "name": "Wood_Azure_Trunk_Full"
    },
    {
      "x": 1,
      "y": 5,
      "z": -3,
      "name": "Plant_Seaweed_Navi_Stack"
    },
    {
      "x": 3,
      "y": 5,
      "z": -3,
      "name": "Plant_Coral_Block_Blue"
    },
    {
      "x": 4,
      "y": 5,
      "z": -3,
      "name": "Plant_Coral_Block_Cyan"
    },
    {
      "x": 5,
      "y": 5,
      "z": -3,
      "name": "Plant_Coral_Block_Cyan"
    },
    {
      "x": 6,
      "y": 5,
      "z": -3,
      "name": "Plant_Coral_Block_Cyan"
    },
    {
      "x": 7,
      "y": 5,
      "z": -3,
      "name": "Plant_Coral_Block_Cyan"
    },
    {
      "x": 8,
      "y": 5,
      "z": -3,
      "name": "Soil_Clay_Blue"
    },
    {
      "x": 9,
      "y": 5,
      "z": -3,
      "name": "Soil_Clay_Blue"
    },
    {
      "x": 10,
      "y": 5,
      "z": -3,
      "name": "Soil_Clay_Blue"
    },
    {
      "x": 11,
      "y": 5,
      "z": -3,
      "name": "Wood_Azure_Trunk_Full"
    },
    {
      "x": 12,
      "y": 5,
      "z": -3,
      "name": "Wood_Azure_Trunk_Full"
    },
    {
      "x": 15,
      "y": 5,
      "z": -3,
      "name": "Wood_Azure_Trunk_Full"
    },
    {
      "x": 1,
      "y": 6,
      "z": -3,
      "name": "Plant_Seaweed_Navi_Stack"
    },
    {
      "x": 4,
      "y": 6,
      "z": -3,
      "name": "Plant_Coral_Block_Cyan"
    },
    {
      "x": 5,
      "y": 6,
      "z": -3,
      "name": "Plant_Coral_Block_Cyan"
    },
    {
      "x": 6,
      "y": 6,
      "z": -3,
      "name": "Plant_Coral_Block_Cyan"
    },
    {
      "x": 7,
      "y": 6,
      "z": -3,
      "name": "Plant_Coral_Block_Cyan"
    },
    {
      "x": 8,
      "y": 6,
      "z": -3,
      "name": "Plant_Coral_Block_Blue"
    },
    {
      "x": 9,
      "y": 6,
      "z": -3,
      "name": "Plant_Coral_Model_Blue"
    },
    {
      "x": 10,
      "y": 6,
      "z": -3,
      "name": "Plant_Coral_Model_Blue"
    },
    {
      "x": 15,
      "y": 6,
      "z": -3,
      "name": "Wood_Azure_Trunk_Full"
    },
    {
      "x": 1,
      "y": 7,
      "z": -3,
      "name": "Plant_Seaweed_Navi_Stack"
    },
    {
      "x": 4,
      "y": 7,
      "z": -3,
      "name": "Plant_Seaweed_Navi_Stack"
    },
    {
      "x": 5,
      "y": 7,
      "z": -3,
      "name": "Plant_Coral_Block_Cyan"
    },
    {
      "x": 6,
      "y": 7,
      "z": -3,
      "name": "Plant_Coral_Block_Blue"
    },
    {
      "x": 7,
      "y": 7,
      "z": -3,
      "name": "Plant_Coral_Block_Blue"
    },
    {
      "x": 0,
      "y": 0,
      "z": -2,
      "name": "Soil_Clay_Blue"
    },
    {
      "x": 1,
      "y": 0,
      "z": -2,
      "name": "Soil_Clay_Blue"
    },
    {
      "x": 2,
      "y": 0,
      "z": -2,
      "name": "Soil_Clay_Blue"
    },
    {
      "x": 3,
      "y": 0,
      "z": -2,
      "name": "Soil_Clay_Blue"
    },
    {
      "x": 0,
      "y": 1,
      "z": -2,
      "name": "Plant_Coral_Block_Cyan"
    },
    {
      "x": 1,
      "y": 1,
      "z": -2,
      "name": "Plant_Coral_Block_Cyan"
    },
    {
      "x": 2,
      "y": 1,
      "z": -2,
      "name": "Plant_Coral_Block_Cyan"
    },
    {
      "x": 3,
      "y": 1,
      "z": -2,
      "name": "Plant_Coral_Block_Cyan"
    },
    {
      "x": 4,
      "y": 1,
      "z": -2,
      "name": "Soil_Clay_Blue"
    },
    {
      "x": 5,
      "y": 1,
      "z": -2,
      "name": "Soil_Clay_Blue"
    },
    {
      "x": 6,
      "y": 1,
      "z": -2,
      "name": "Soil_Clay_Blue"
    },
    {
      "x": 0,
      "y": 2,
      "z": -2,
      "name": "Plant_Coral_Block_Cyan"
    },
    {
      "x": 1,
      "y": 2,
      "z": -2,
      "name": "Plant_Coral_Block_Cyan"
    },
    {
      "x": 2,
      "y": 2,
      "z": -2,
      "name": "Plant_Coral_Block_Cyan"
    },
    {
      "x": 3,
      "y": 2,
      "z": -2,
      "name": "Plant_Coral_Block_Cyan"
    },
    {
      "x": 4,
      "y": 2,
      "z": -2,
      "name": "Plant_Coral_Block_Cyan"
    },
    {
      "x": 5,
      "y": 2,
      "z": -2,
      "name": "Plant_Coral_Block_Cyan"
    },
    {
      "x": 6,
      "y": 2,
      "z": -2,
      "name": "Plant_Coral_Block_Cyan"
    },
    {
      "x": 7,
      "y": 2,
      "z": -2,
      "name": "Soil_Clay_Blue"
    },
    {
      "x": 8,
      "y": 2,
      "z": -2,
      "name": "Soil_Clay_Blue"
    },
    {
      "x": 0,
      "y": 3,
      "z": -2,
      "name": "Plant_Coral_Block_Cyan"
    },
    {
      "x": 1,
      "y": 3,
      "z": -2,
      "name": "Plant_Coral_Block_Cyan"
    },
    {
      "x": 2,
      "y": 3,
      "z": -2,
      "name": "Plant_Coral_Block_Cyan"
    },
    {
      "x": 3,
      "y": 3,
      "z": -2,
      "name": "Plant_Coral_Block_Cyan"
    },
    {
      "x": 4,
      "y": 3,
      "z": -2,
      "name": "Plant_Coral_Block_Cyan"
    },
    {
      "x": 5,
      "y": 3,
      "z": -2,
      "name": "Plant_Coral_Block_Cyan"
    },
    {
      "x": 6,
      "y": 3,
      "z": -2,
      "name": "Plant_Coral_Block_Cyan"
    },
    {
      "x": 7,
      "y": 3,
      "z": -2,
      "name": "Soil_Clay_Blue"
    },
    {
      "x": 8,
      "y": 3,
      "z": -2,
      "name": "Soil_Clay_Blue"
    },
    {
      "x": 9,
      "y": 3,
      "z": -2,
      "name": "Soil_Clay_Blue"
    },
    {
      "x": 10,
      "y": 3,
      "z": -2,
      "name": "Soil_Clay_Blue"
    },
    {
      "x": 11,
      "y": 3,
      "z": -2,
      "name": "Soil_Clay_Blue"
    },
    {
      "x": 0,
      "y": 4,
      "z": -2,
      "name": "Plant_Seaweed_Navi_Stack"
    },
    {
      "x": 1,
      "y": 4,
      "z": -2,
      "name": "Plant_Seaweed_Navi_Stack"
    },
    {
      "x": 2,
      "y": 4,
      "z": -2,
      "name": "Plant_Seaweed_Navi_Stack"
    },
    {
      "x": 3,
      "y": 4,
      "z": -2,
      "name": "Plant_Coral_Block_Cyan"
    },
    {
      "x": 4,
      "y": 4,
      "z": -2,
      "name": "Plant_Coral_Block_Cyan"
    },
    {
      "x": 5,
      "y": 4,
      "z": -2,
      "name": "Plant_Coral_Block_Cyan"
    },
    {
      "x": 6,
      "y": 4,
      "z": -2,
      "name": "Plant_Coral_Block_Cyan"
    },
    {
      "x": 7,
      "y": 4,
      "z": -2,
      "name": "Plant_Coral_Block_Cyan"
    },
    {
      "x": 8,
      "y": 4,
      "z": -2,
      "name": "Soil_Clay_Blue"
    },
    {
      "x": 9,
      "y": 4,
      "z": -2,
      "name": "Soil_Clay_Blue"
    },
    {
      "x": 10,
      "y": 4,
      "z": -2,
      "name": "Soil_Clay_Blue"
    },
    {
      "x": 11,
      "y": 4,
      "z": -2,
      "name": "Wood_Azure_Trunk_Full"
    },
    {
      "x": 12,
      "y": 4,
      "z": -2,
      "name": "Wood_Azure_Trunk_Full"
    },
    {
      "x": 0,
      "y": 5,
      "z": -2,
      "name": "Plant_Seaweed_Navi_Stack"
    },
    {
      "x": 1,
      "y": 5,
      "z": -2,
      "name": "Plant_Seaweed_Navi_Stack"
    },
    {
      "x": 2,
      "y": 5,
      "z": -2,
      "name": "Plant_Seaweed_Navi_Stack"
    },
    {
      "x": 3,
      "y": 5,
      "z": -2,
      "name": "Plant_Seaweed_Navi_Stack"
    },
    {
      "x": 4,
      "y": 5,
      "z": -2,
      "name": "Plant_Coral_Block_Cyan"
    },
    {
      "x": 5,
      "y": 5,
      "z": -2,
      "name": "Plant_Coral_Block_Blue"
    },
    {
      "x": 6,
      "y": 5,
      "z": -2,
      "name": "Plant_Coral_Block_Cyan"
    },
    {
      "x": 7,
      "y": 5,
      "z": -2,
      "name": "Plant_Coral_Block_Cyan"
    },
    {
      "x": 8,
      "y": 5,
      "z": -2,
      "name": "Soil_Clay_Blue"
    },
    {
      "x": 9,
      "y": 5,
      "z": -2,
      "name": "Soil_Clay_Blue"
    },
    {
      "x": 10,
      "y": 5,
      "z": -2,
      "name": "Wood_Azure_Trunk_Full"
    },
    {
      "x": 11,
      "y": 5,
      "z": -2,
      "name": "Wood_Azure_Trunk_Full"
    },
    {
      "x": 12,
      "y": 5,
      "z": -2,
      "name": "Wood_Azure_Trunk_Full"
    },
    {
      "x": 13,
      "y": 5,
      "z": -2,
      "name": "Wood_Azure_Trunk_Full"
    },
    {
      "x": 14,
      "y": 5,
      "z": -2,
      "name": "Wood_Azure_Trunk_Full"
    },
    {
      "x": 15,
      "y": 5,
      "z": -2,
      "name": "Wood_Azure_Trunk_Full"
    },
    {
      "x": 0,
      "y": 6,
      "z": -2,
      "name": "Plant_Seaweed_Navi_Stack"
    },
    {
      "x": 1,
      "y": 6,
      "z": -2,
      "name": "Plant_Seaweed_Navi_Stack"
    },
    {
      "x": 2,
      "y": 6,
      "z": -2,
      "name": "Plant_Seaweed_Navi_Stack"
    },
    {
      "x": 3,
      "y": 6,
      "z": -2,
      "name": "Plant_Seaweed_Navi_Stack"
    },
    {
      "x": 4,
      "y": 6,
      "z": -2,
      "name": "Plant_Seaweed_Navi_Stack"
    },
    {
      "x": 6,
      "y": 6,
      "z": -2,
      "name": "Plant_Coral_Block_Blue"
    },
    {
      "x": 7,
      "y": 6,
      "z": -2,
      "name": "Plant_Coral_Block_Cyan"
    },
    {
      "x": 8,
      "y": 6,
      "z": -2,
      "name": "Plant_Coral_Block_Blue"
    },
    {
      "x": 9,
      "y": 6,
      "z": -2,
      "name": "Plant_Coral_Block_Cyan"
    },
    {
      "x": 14,
      "y": 6,
      "z": -2,
      "name": "Wood_Azure_Trunk_Full"
    },
    {
      "x": 15,
      "y": 6,
      "z": -2,
      "name": "Wood_Azure_Trunk_Full"
    },
    {
      "x": 0,
      "y": 7,
      "z": -2,
      "name": "Plant_Seaweed_Navi_Stack"
    },
    {
      "x": 1,
      "y": 7,
      "z": -2,
      "name": "Plant_Seaweed_Navi_Stack"
    },
    {
      "x": 2,
      "y": 7,
      "z": -2,
      "name": "Plant_Seaweed_Navi_Stack"
    },
    {
      "x": 3,
      "y": 7,
      "z": -2,
      "name": "Plant_Seaweed_Navi_Stack"
    },
    {
      "x": 4,
      "y": 7,
      "z": -2,
      "name": "Plant_Seaweed_Navi_Stack"
    },
    {
      "x": 7,
      "y": 7,
      "z": -2,
      "name": "Plant_Coral_Block_Blue"
    },
    {
      "x": 9,
      "y": 7,
      "z": -2,
      "name": "Plant_Seaweed_Navi_Stack"
    },
    {
      "x": 14,
      "y": 7,
      "z": -2,
      "name": "Plant_Coral_Block_Red"
    },
    {
      "x": 15,
      "y": 7,
      "z": -2,
      "name": "Wood_Azure_Trunk_Full"
    },
    {
      "x": 3,
      "y": 0,
      "z": -1,
      "name": "Soil_Clay_Blue"
    },
    {
      "x": 4,
      "y": 0,
      "z": -1,
      "name": "Soil_Clay_Blue"
    },
    {
      "x": 3,
      "y": 1,
      "z": -1,
      "name": "Plant_Coral_Block_Cyan"
    },
    {
      "x": 4,
      "y": 1,
      "z": -1,
      "name": "Plant_Coral_Block_Cyan"
    },
    {
      "x": 5,
      "y": 1,
      "z": -1,
      "name": "Soil_Clay_Blue"
    },
    {
      "x": 6,
      "y": 1,
      "z": -1,
      "name": "Soil_Clay_Blue"
    },
    {
      "x": 3,
      "y": 2,
      "z": -1,
      "name": "Plant_Coral_Block_Cyan"
    },
    {
      "x": 4,
      "y": 2,
      "z": -1,
      "name": "Plant_Coral_Block_Cyan"
    },
    {
      "x": 5,
      "y": 2,
      "z": -1,
      "name": "Plant_Coral_Block_Cyan"
    },
    {
      "x": 6,
      "y": 2,
      "z": -1,
      "name": "Plant_Coral_Block_Cyan"
    },
    {
      "x": 7,
      "y": 2,
      "z": -1,
      "name": "Soil_Clay_Blue"
    },
    {
      "x": 8,
      "y": 2,
      "z": -1,
      "name": "Soil_Clay_Blue"
    },
    {
      "x": 3,
      "y": 3,
      "z": -1,
      "name": "Plant_Coral_Block_Cyan"
    },
    {
      "x": 4,
      "y": 3,
      "z": -1,
      "name": "Plant_Coral_Block_Cyan"
    },
    {
      "x": 5,
      "y": 3,
      "z": -1,
      "name": "Plant_Coral_Block_Cyan"
    },
    {
      "x": 6,
      "y": 3,
      "z": -1,
      "name": "Plant_Coral_Block_Cyan"
    },
    {
      "x": 7,
      "y": 3,
      "z": -1,
      "name": "Plant_Coral_Block_Cyan"
    },
    {
      "x": 8,
      "y": 3,
      "z": -1,
      "name": "Soil_Clay_Blue"
    },
    {
      "x": 9,
      "y": 3,
      "z": -1,
      "name": "Soil_Clay_Blue"
    },
    {
      "x": 10,
      "y": 3,
      "z": -1,
      "name": "Soil_Clay_Blue"
    },
    {
      "x": 3,
      "y": 4,
      "z": -1,
      "name": "Plant_Seaweed_Navi_Stack"
    },
    {
      "x": 4,
      "y": 4,
      "z": -1,
      "name": "Plant_Coral_Block_Cyan"
    },
    {
      "x": 5,
      "y": 4,
      "z": -1,
      "name": "Plant_Coral_Block_Blue"
    },
    {
      "x": 6,
      "y": 4,
      "z": -1,
      "name": "Plant_Coral_Block_Cyan"
    },
    {
      "x": 7,
      "y": 4,
      "z": -1,
      "name": "Plant_Coral_Block_Cyan"
    },
    {
      "x": 8,
      "y": 4,
      "z": -1,
      "name": "Soil_Clay_Blue"
    },
    {
      "x": 9,
      "y": 4,
      "z": -1,
      "name": "Soil_Clay_Blue"
    },
    {
      "x": 10,
      "y": 4,
      "z": -1,
      "name": "Soil_Clay_Blue"
    },
    {
      "x": 11,
      "y": 4,
      "z": -1,
      "name": "Soil_Clay_Blue"
    },
    {
      "x": 12,
      "y": 4,
      "z": -1,
      "name": "Wood_Azure_Trunk_Full"
    },
    {
      "x": 3,
      "y": 5,
      "z": -1,
      "name": "Plant_Seaweed_Navi_Stack"
    },
    {
      "x": 6,
      "y": 5,
      "z": -1,
      "name": "Plant_Coral_Block_Blue"
    },
    {
      "x": 7,
      "y": 5,
      "z": -1,
      "name": "Plant_Coral_Block_Cyan"
    },
    {
      "x": 8,
      "y": 5,
      "z": -1,
      "name": "Soil_Clay_Blue"
    },
    {
      "x": 9,
      "y": 5,
      "z": -1,
      "name": "Soil_Clay_Blue"
    },
    {
      "x": 10,
      "y": 5,
      "z": -1,
      "name": "Soil_Clay_Blue"
    },
    {
      "x": 11,
      "y": 5,
      "z": -1,
      "name": "Wood_Azure_Trunk_Full"
    },
    {
      "x": 12,
      "y": 5,
      "z": -1,
      "name": "Wood_Azure_Trunk_Full"
    },
    {
      "x": 13,
      "y": 5,
      "z": -1,
      "name": "Wood_Azure_Trunk_Full"
    },
    {
      "x": 14,
      "y": 5,
      "z": -1,
      "name": "Wood_Azure_Trunk_Full"
    },
    {
      "x": 3,
      "y": 6,
      "z": -1,
      "name": "Plant_Seaweed_Navi_Stack"
    },
    {
      "x": 7,
      "y": 6,
      "z": -1,
      "name": "Plant_Coral_Block_Cyan"
    },
    {
      "x": 8,
      "y": 6,
      "z": -1,
      "name": "Plant_Coral_Block_Cyan"
    },
    {
      "x": 9,
      "y": 6,
      "z": -1,
      "name": "Plant_Coral_Block_Cyan"
    },
    {
      "x": 14,
      "y": 6,
      "z": -1,
      "name": "Wood_Azure_Trunk_Full"
    },
    {
      "x": 3,
      "y": 7,
      "z": -1,
      "name": "Plant_Seaweed_Navi_Stack"
    },
    {
      "x": 7,
      "y": 7,
      "z": -1,
      "name": "Plant_Coral_Block_Cyan"
    },
    {
      "x": 8,
      "y": 7,
      "z": -1,
      "name": "Plant_Coral_Block_Cyan"
    },
    {
      "x": 9,
      "y": 7,
      "z": -1,
      "name": "Plant_Seaweed_Navi_Stack"
    },
    {
      "x": 14,
      "y": 7,
      "z": -1,
      "name": "Wood_Azure_Trunk_Full"
    },
    {
      "x": 2,
      "y": 8,
      "z": -15,
      "name": "Plant_Coral_Block_Red"
    },
    {
      "x": 2,
      "y": 9,
      "z": -15,
      "name": "Plant_Coral_Block_Red"
    },
    {
      "x": 2,
      "y": 10,
      "z": -15,
      "name": "Plant_Coral_Block_Red"
    },
    {
      "x": 2,
      "y": 11,
      "z": -15,
      "name": "Plant_Coral_Block_Red"
    },
    {
      "x": 2,
      "y": 12,
      "z": -15,
      "name": "Plant_Coral_Block_Red"
    },
    {
      "x": 2,
      "y": 13,
      "z": -15,
      "name": "Plant_Coral_Model_Red"
    },
    {
      "x": 2,
      "y": 8,
      "z": -14,
      "name": "Plant_Coral_Block_Red"
    },
    {
      "x": 2,
      "y": 9,
      "z": -14,
      "name": "Plant_Coral_Block_Red"
    },
    {
      "x": 2,
      "y": 10,
      "z": -14,
      "name": "Plant_Coral_Block_Red"
    },
    {
      "x": 2,
      "y": 11,
      "z": -14,
      "name": "Plant_Coral_Block_Red"
    },
    {
      "x": 2,
      "y": 12,
      "z": -14,
      "name": "Plant_Coral_Block_Red"
    },
    {
      "x": 2,
      "y": 13,
      "z": -14,
      "name": "Plant_Coral_Model_Red"
    },
    {
      "x": 6,
      "y": 8,
      "z": -13,
      "name": "Plant_Coral_Block_Red"
    },
    {
      "x": 6,
      "y": 9,
      "z": -13,
      "name": "Plant_Coral_Block_Red"
    },
    {
      "x": 6,
      "y": 10,
      "z": -13,
      "name": "Plant_Coral_Block_Red"
    },
    {
      "x": 6,
      "y": 11,
      "z": -13,
      "name": "Plant_Coral_Block_Red"
    },
    {
      "x": 6,
      "y": 12,
      "z": -13,
      "name": "Plant_Coral_Block_Red"
    },
    {
      "x": 6,
      "y": 13,
      "z": -13,
      "name": "Plant_Coral_Model_Red"
    },
    {
      "x": 5,
      "y": 8,
      "z": -12,
      "name": "Wood_Azure_Trunk_Full"
    },
    {
      "x": 5,
      "y": 9,
      "z": -12,
      "name": "Plant_Coral_Block_Red"
    },
    {
      "x": 5,
      "y": 10,
      "z": -12,
      "name": "Plant_Coral_Block_Red"
    },
    {
      "x": 5,
      "y": 11,
      "z": -12,
      "name": "Plant_Coral_Block_Red"
    },
    {
      "x": 5,
      "y": 12,
      "z": -12,
      "name": "Plant_Coral_Block_Red"
    },
    {
      "x": 5,
      "y": 13,
      "z": -12,
      "name": "Plant_Coral_Model_Red"
    },
    {
      "x": 9,
      "y": 8,
      "z": -11,
      "name": "Wood_Azure_Trunk_Full"
    },
    {
      "x": 9,
      "y": 9,
      "z": -11,
      "name": "Wood_Azure_Trunk_Full"
    },
    {
      "x": 9,
      "y": 10,
      "z": -11,
      "name": "Wood_Azure_Trunk_Full"
    },
    {
      "x": 9,
      "y": 11,
      "z": -11,
      "name": "Wood_Azure_Trunk_Full"
    },
    {
      "x": 9,
      "y": 12,
      "z": -11,
      "name": "Plant_Coral_Block_Red"
    },
    {
      "x": 9,
      "y": 13,
      "z": -11,
      "name": "Plant_Coral_Block_Red"
    },
    {
      "x": 9,
      "y": 14,
      "z": -11,
      "name": "Plant_Coral_Block_Red"
    },
    {
      "x": 9,
      "y": 15,
      "z": -11,
      "name": "Plant_Coral_Block_Red"
    },
    {
      "x": 9,
      "y": 16,
      "z": -11,
      "name": "Plant_Coral_Model_Red"
    },
    {
      "x": 7,
      "y": 8,
      "z": -10,
      "name": "Wood_Azure_Trunk_Full"
    },
    {
      "x": 8,
      "y": 8,
      "z": -10,
      "name": "Wood_Azure_Trunk_Full"
    },
    {
      "x": 8,
      "y": 9,
      "z": -10,
      "name": "Wood_Azure_Trunk_Full"
    },
    {
      "x": 8,
      "y": 10,
      "z": -10,
      "name": "Wood_Azure_Trunk_Full"
    },
    {
      "x": 8,
      "y": 11,
      "z": -10,
      "name": "Wood_Azure_Trunk_Full"
    },
    {
      "x": 8,
      "y": 12,
      "z": -10,
      "name": "Wood_Azure_Trunk_Full"
    },
    {
      "x": 8,
      "y": 13,
      "z": -10,
      "name": "Plant_Coral_Block_Red"
    },
    {
      "x": 8,
      "y": 14,
      "z": -10,
      "name": "Plant_Coral_Block_Red"
    },
    {
      "x": 8,
      "y": 15,
      "z": -10,
      "name": "Plant_Coral_Block_Red"
    },
    {
      "x": 8,
      "y": 16,
      "z": -10,
      "name": "Plant_Coral_Model_Red"
    },
    {
      "x": 6,
      "y": 8,
      "z": -9,
      "name": "Plant_Coral_Model_Blue"
    },
    {
      "x": 7,
      "y": 8,
      "z": -9,
      "name": "Soil_Clay_Blue"
    },
    {
      "x": 8,
      "y": 8,
      "z": -9,
      "name": "Wood_Azure_Trunk_Full"
    },
    {
      "x": 12,
      "y": 8,
      "z": -9,
      "name": "Plant_Coral_Block_Red"
    },
    {
      "x": 7,
      "y": 9,
      "z": -9,
      "name": "Plant_Coral_Model_Blue"
    },
    {
      "x": 12,
      "y": 9,
      "z": -9,
      "name": "Plant_Coral_Block_Red"
    },
    {
      "x": 12,
      "y": 10,
      "z": -9,
      "name": "Plant_Coral_Block_Red"
    },
    {
      "x": 12,
      "y": 11,
      "z": -9,
      "name": "Plant_Coral_Block_Red"
    },
    {
      "x": 12,
      "y": 12,
      "z": -9,
      "name": "Plant_Coral_Block_Red"
    },
    {
      "x": 12,
      "y": 13,
      "z": -9,
      "name": "Plant_Coral_Model_Red"
    },
    {
      "x": 1,
      "y": 8,
      "z": -8,
      "name": "Plant_Seaweed_Navi_Stack"
    },
    {
      "x": 2,
      "y": 8,
      "z": -8,
      "name": "Plant_Seaweed_Navi_Stack"
    },
    {
      "x": 8,
      "y": 8,
      "z": -8,
      "name": "Plant_Coral_Model_Blue"
    },
    {
      "x": 11,
      "y": 8,
      "z": -8,
      "name": "Plant_Coral_Block_Red"
    },
    {
      "x": 1,
      "y": 9,
      "z": -8,
      "name": "Plant_Seaweed_Navi_Stack"
    },
    {
      "x": 2,
      "y": 9,
      "z": -8,
      "name": "Plant_Seaweed_Navi_Stack"
    },
    {
      "x": 11,
      "y": 9,
      "z": -8,
      "name": "Plant_Coral_Block_Red"
    },
    {
      "x": 1,
      "y": 10,
      "z": -8,
      "name": "Plant_Seaweed_Navi_Stack"
    },
    {
      "x": 2,
      "y": 10,
      "z": -8,
      "name": "Plant_Seaweed_Navi_Stack"
    },
    {
      "x": 11,
      "y": 10,
      "z": -8,
      "name": "Plant_Coral_Block_Red"
    },
    {
      "x": 1,
      "y": 11,
      "z": -8,
      "name": "Plant_Seaweed_Navi_Stack"
    },
    {
      "x": 2,
      "y": 11,
      "z": -8,
      "name": "Plant_Seaweed_Navi_Stack"
    },
    {
      "x": 11,
      "y": 11,
      "z": -8,
      "name": "Plant_Coral_Block_Red"
    },
    {
      "x": 11,
      "y": 12,
      "z": -8,
      "name": "Plant_Coral_Model_Red"
    },
    {
      "x": 2,
      "y": 8,
      "z": -7,
      "name": "Plant_Seaweed_Navi_Stack"
    },
    {
      "x": 3,
      "y": 8,
      "z": -7,
      "name": "Plant_Seaweed_Navi_Stack"
    },
    {
      "x": 2,
      "y": 9,
      "z": -7,
      "name": "Plant_Seaweed_Navi_Stack"
    },
    {
      "x": 3,
      "y": 9,
      "z": -7,
      "name": "Plant_Seaweed_Navi_Stack"
    },
    {
      "x": 2,
      "y": 10,
      "z": -7,
      "name": "Plant_Seaweed_Navi_Stack"
    },
    {
      "x": 3,
      "y": 10,
      "z": -7,
      "name": "Plant_Seaweed_Navi_Stack"
    },
    {
      "x": 2,
      "y": 11,
      "z": -7,
      "name": "Plant_Seaweed_Navi_Stack"
    },
    {
      "x": 2,
      "y": 12,
      "z": -7,
      "name": "Plant_Seaweed_Navi_Stack"
    },
    {
      "x": 2,
      "y": 13,
      "z": -7,
      "name": "Plant_Seaweed_Navi_Stack"
    },
    {
      "x": 2,
      "y": 8,
      "z": -6,
      "name": "Plant_Seaweed_Navi_Stack"
    },
    {
      "x": 6,
      "y": 8,
      "z": -6,
      "name": "Plant_Seaweed_Navi_Stack"
    },
    {
      "x": 12,
      "y": 8,
      "z": -6,
      "name": "Wood_Azure_Trunk_Full"
    },
    {
      "x": 13,
      "y": 8,
      "z": -6,
      "name": "Wood_Azure_Trunk_Full"
    },
    {
      "x": 14,
      "y": 8,
      "z": -6,
      "name": "Wood_Azure_Trunk_Full"
    },
    {
      "x": 2,
      "y": 9,
      "z": -6,
      "name": "Plant_Seaweed_Navi_Stack"
    },
    {
      "x": 6,
      "y": 9,
      "z": -6,
      "name": "Plant_Seaweed_Navi_Stack"
    },
    {
      "x": 14,
      "y": 9,
      "z": -6,
      "name": "Wood_Azure_Trunk_Full"
    },
    {
      "x": 2,
      "y": 10,
      "z": -6,
      "name": "Plant_Seaweed_Navi_Stack"
    },
    {
      "x": 6,
      "y": 10,
      "z": -6,
      "name": "Plant_Seaweed_Navi_Stack"
    },
    {
      "x": 14,
      "y": 10,
      "z": -6,
      "name": "Wood_Azure_Trunk_Full"
    },
    {
      "x": 2,
      "y": 11,
      "z": -6,
      "name": "Plant_Seaweed_Navi_Stack"
    },
    {
      "x": 6,
      "y": 11,
      "z": -6,
      "name": "Plant_Seaweed_Navi_Stack"
    },
    {
      "x": 14,
      "y": 11,
      "z": -6,
      "name": "Wood_Azure_Trunk_Full"
    },
    {
      "x": 14,
      "y": 12,
      "z": -6,
      "name": "Wood_Azure_Trunk_Full"
    },
    {
      "x": 14,
      "y": 13,
      "z": -6,
      "name": "Plant_Coral_Block_Red"
    },
    {
      "x": 14,
      "y": 14,
      "z": -6,
      "name": "Plant_Coral_Block_Red"
    },
    {
      "x": 14,
      "y": 15,
      "z": -6,
      "name": "Plant_Coral_Block_Red"
    },
    {
      "x": 14,
      "y": 16,
      "z": -6,
      "name": "Plant_Coral_Model_Red"
    },
    {
      "x": 1,
      "y": 8,
      "z": -5,
      "name": "Plant_Coral_Block_Cyan"
    },
    {
      "x": 2,
      "y": 8,
      "z": -5,
      "name": "Plant_Coral_Block_Cyan"
    },
    {
      "x": 6,
      "y": 8,
      "z": -5,
      "name": "Plant_Seaweed_Navi_Stack"
    },
    {
      "x": 7,
      "y": 8,
      "z": -5,
      "name": "Plant_Seaweed_Navi_Stack"
    },
    {
      "x": 12,
      "y": 8,
      "z": -5,
      "name": "Wood_Azure_Trunk_Full"
    },
