{
  "version": 8,
  "blockIdVersion": 11,
  "anchorX": 0,
  "anchorY": 3,
  "anchorZ": 0,
  "blocks": [
    {
      "x": -5,
      "y": 4,
      "z": -2,
      "name": "Rock_Marble_Cobble"
    },
    {
      "x": -5,
      "y": 3,
      "z": -1,
      "name": "Rock_Marble"
    },
    {
      "x": -5,
      "y": 4,
      "z": -1,
      "name": "Rock_Marble_Cobble"
    },
    {
      "x": -5,
      "y": 5,
      "z": -1,
      "name": "Rock_Marble_Cobble"
    },
    {
      "x": -5,
      "y": 3,
      "z": 0,
      "name": "Rock_Marble"
    },
    {
      "x": -5,
      "y": 4,
      "z": 0,
      "name": "Rock_Marble_Cobble"
    },
    {
      "x": -5,
      "y": 5,
      "z": 0,
      "name": "Rock_Marble_Cobble"
    },
    {
      "x": -5,
      "y": 4,
      "z": 1,
      "name": "Rock_Marble_Cobble"
    },
    {
      "x": -4,
      "y": 4,
      "z": -3,
      "name": "Rock_Marble_Cobble"
    },
    {
      "x": -4,
      "y": 5,
      "z": -3,
      "name": "Rock_Marble_Cobble"
    },
    {
      "x": -4,
      "y": 3,
      "z": -2,
      "name": "Rock_Marble"
    },
    {
      "x": -4,
      "y": 4,
      "z": -2,
      "name": "Rock_Marble_Cobble"
    },
    {
      "x": -4,
      "y": 5,
      "z": -2,
      "name": "Rock_Marble_Cobble"
    },
    {
      "x": -4,
      "y": 6,
      "z": -2,
      "name": "Rock_Marble"
    },
    {
      "x": -4,
      "y": 2,
      "z": -1,
      "name": "Rock_Marble_Cobble"
    },
    {
      "x": -4,
      "y": 3,
      "z": -1,
      "name": "Rock_Marble"
    },
    {
      "x": -4,
      "y": 4,
      "z": -1,
      "name": "Rock_Marble_Cobble"
    },
    {
      "x": -4,
      "y": 5,
      "z": -1,
      "name": "Rock_Marble_Cobble"
    },
    {
      "x": -4,
      "y": 6,
      "z": -1,
      "name": "Rock_Marble"
    },
    {
      "x": -4,
      "y": 2,
      "z": 0,
      "name": "Rock_Marble_Cobble"
    },
    {
      "x": -4,
      "y": 3,
      "z": 0,
      "name": "Rock_Marble"
    },
    {
      "x": -4,
      "y": 4,
      "z": 0,
      "name": "Rock_Marble_Cobble"
    },
    {
      "x": -4,
      "y": 5,
      "z": 0,
      "name": "Rock_Marble_Cobble"
    },
    {
      "x": -4,
      "y": 6,
      "z": 0,
      "name": "Rock_Marble"
    },
    {
      "x": -4,
      "y": 7,
      "z": 0,
      "name": "Rock_Marble"
    },
    {
      "x": -4,
      "y": 2,
      "z": 1,
      "name": "Rock_Marble_Cobble"
    },
    {
      "x": -4,
      "y": 3,
      "z": 1,
      "name": "Rock_Marble"
    },
    {
      "x": -4,
      "y": 4,
      "z": 1,
      "name": "Rock_Marble_Cobble"
    },
    {
      "x": -4,
      "y": 5,
      "z": 1,
      "name": "Rock_Marble_Cobble"
    },
    {
      "x": -4,
      "y": 6,
      "z": 1,
      "name": "Rock_Marble"
    },
    {
      "x": -4,
      "y": 7,
      "z": 1,
      "name": "Rock_Marble"
    },
    {
      "x": -4,
      "y": 3,
      "z": 2,
      "name": "Rock_Marble"
    },
    {
      "x": -4,
      "y": 4,
      "z": 2,
      "name": "Rock_Marble_Cobble"
    },
    {
      "x": -4,
      "y": 5,
      "z": 2,
      "name": "Rock_Marble_Cobble"
    },
    {
      "x": -4,
      "y": 6,
      "z": 2,
      "name": "Rock_Marble"
    },
    {
      "x": -3,
      "y": 3,
      "z": -3,
      "name": "Rock_Marble_Cobble"
    },
    {
      "x": -3,
      "y": 4,
      "z": -3,
      "name": "Rock_Marble_Cobble"
    },
    {
      "x": -3,
      "y": 5,
      "z": -3,
      "name": "Rock_Marble_Cobble"
    },
    {
      "x": -3,
      "y": 2,
      "z": -2,
      "name": "Rock_Marble_Cobble"
    },
    {
      "x": -3,
      "y": 3,
      "z": -2,
      "name": "Rock_Marble_Cobble"
    },
    {
      "x": -3,
      "y": 4,
      "z": -2,
      "name": "Rock_Marble_Cobble"
    },
    {
      "x": -3,
      "y": 5,
      "z": -2,
      "name": "Rock_Marble_Cobble"
    },
    {
      "x": -3,
      "y": 6,
      "z": -2,
      "name": "Rock_Marble"
    },
    {
      "x": -3,
      "y": 2,
      "z": -1,
      "name": "Rock_Marble_Cobble"
    },
    {
      "x": -3,
      "y": 3,
      "z": -1,
      "name": "Rock_Marble"
    },
    {
      "x": -3,
      "y": 4,
      "z": -1,
      "name": "Rock_Marble_Cobble"
    },
    {
      "x": -3,
      "y": 5,
      "z": -1,
      "name": "Rock_Marble_Cobble"
    },
    {
      "x": -3,
      "y": 6,
      "z": -1,
      "name": "Rock_Marble"
    },
    {
      "x": -3,
      "y": 7,
      "z": -1,
      "name": "Rock_Marble"
    },
    {
      "x": -3,
      "y": 1,
      "z": 0,
      "name": "Rock_Marble_Cobble"
    },
    {
      "x": -3,
      "y": 2,
      "z": 0,
      "name": "Rock_Marble_Cobble"
    },
    {
      "x": -3,
      "y": 3,
      "z": 0,
      "name": "Rock_Marble"
    },
    {
      "x": -3,
      "y": 4,
      "z": 0,
      "name": "Rock_Marble_Cobble"
    },
    {
      "x": -3,
      "y": 5,
      "z": 0,
      "name": "Rock_Marble_Cobble"
    },
    {
      "x": -3,
      "y": 6,
      "z": 0,
      "name": "Rock_Marble"
    },
    {
      "x": -3,
      "y": 7,
      "z": 0,
      "name": "Rock_Marble"
    },
    {
      "x": -3,
      "y": 8,
      "z": 0,
      "name": "Rock_Marble"
    },
    {
      "x": -3,
      "y": 9,
      "z": 0,
      "name": "Rock_Marble"
    },
    {
      "x": -3,
      "y": 10,
      "z": 0,
      "name": "Soil_Clay_White"
    },
    {
      "x": -3,
      "y": 11,
      "z": 0,
      "name": "Rock_Marble"
    },
    {
      "x": -3,
      "y": 12,
      "z": 0,
      "name": "Rock_Marble_Cobble"
    },
    {
      "x": -3,
      "y": 13,
      "z": 0,
      "name": "Rock_Marble"
    },
    {
      "x": -3,
      "y": 1,
      "z": 1,
      "name": "Rock_Marble_Cobble"
    },
    {
      "x": -3,
      "y": 2,
      "z": 1,
      "name": "Rock_Marble_Cobble"
    },
    {
      "x": -3,
      "y": 3,
      "z": 1,
      "name": "Rock_Marble"
    },
    {
      "x": -3,
      "y": 4,
      "z": 1,
      "name": "Rock_Marble_Cobble"
    },
    {
      "x": -3,
      "y": 5,
      "z": 1,
      "name": "Rock_Marble_Cobble"
    },
    {
      "x": -3,
      "y": 6,
      "z": 1,
      "name": "Rock_Marble"
    },
    {
      "x": -3,
      "y": 7,
      "z": 1,
      "name": "Rock_Marble"
    },
    {
      "x": -3,
      "y": 8,
      "z": 1,
      "name": "Rock_Marble"
    },
    {
      "x": -3,
      "y": 9,
      "z": 1,
      "name": "Rock_Marble"
    },
    {
      "x": -3,
      "y": 10,
      "z": 1,
      "name": "Soil_Clay_White"
    },
    {
      "x": -3,
      "y": 11,
      "z": 1,
      "name": "Rock_Marble"
    },
    {
      "x": -3,
      "y": 2,
      "z": 2,
      "name": "Rock_Marble_Cobble"
    },
    {
      "x": -3,
      "y": 3,
      "z": 2,
      "name": "Rock_Marble"
    },
    {
      "x": -3,
      "y": 4,
      "z": 2,
      "name": "Rock_Marble_Cobble"
    },
    {
      "x": -3,
      "y": 5,
      "z": 2,
      "name": "Rock_Marble_Cobble"
    },
    {
      "x": -3,
      "y": 6,
      "z": 2,
      "name": "Rock_Marble"
    },
    {
      "x": -3,
      "y": 7,
      "z": 2,
      "name": "Rock_Marble"
    },
    {
      "x": -3,
      "y": 8,
      "z": 2,
      "name": "Rock_Marble"
    },
    {
      "x": -3,
      "y": 9,
      "z": 2,
      "name": "Rock_Marble"
    },
    {
      "x": -3,
      "y": 3,
      "z": 3,
      "name": "Rock_Marble"
    },
    {
      "x": -3,
      "y": 4,
      "z": 3,
      "name": "Rock_Marble_Cobble"
    },
    {
      "x": -3,
      "y": 5,
      "z": 3,
      "name": "Rock_Marble_Cobble"
    },
    {
      "x": -3,
      "y": 6,
      "z": 3,
      "name": "Rock_Marble"
    },
    {
      "x": -3,
      "y": 7,
      "z": 3,
      "name": "Rock_Marble"
    },
    {
      "x": -3,
      "y": 8,
      "z": 3,
      "name": "Rock_Marble"
    },
    {
      "x": -3,
      "y": 5,
      "z": 4,
      "name": "Rock_Marble_Cobble"
    },
    {
      "x": -3,
      "y": 6,
      "z": 4,
      "name": "Rock_Marble"
    },
    {
      "x": -2,
      "y": 4,
      "z": -4,
      "name": "Rock_Marble_Cobble"
    },
    {
      "x": -2,
      "y": 2,
      "z": -3,
      "name": "Rock_Marble_Cobble"
    },
    {
      "x": -2,
      "y": 3,
      "z": -3,
      "name": "Rock_Marble_Cobble"
    },
    {
      "x": -2,
      "y": 4,
      "z": -3,
      "name": "Rock_Marble_Cobble"
    },
    {
      "x": -2,
      "y": 5,
      "z": -3,
      "name": "Rock_Marble_Cobble"
    },
    {
      "x": -2,
      "y": 6,
      "z": -3,
      "name": "Rock_Marble"
    },
    {
      "x": -2,
      "y": 2,
      "z": -2,
      "name": "Rock_Marble_Cobble"
    },
    {
      "x": -2,
      "y": 3,
      "z": -2,
      "name": "Rock_Marble_Cobble"
    },
    {
      "x": -2,
      "y": 4,
      "z": -2,
      "name": "Rock_Marble_Cobble"
    },
    {
      "x": -2,
      "y": 5,
      "z": -2,
      "name": "Rock_Marble_Cobble"
    },
    {
      "x": -2,
      "y": 6,
      "z": -2,
      "name": "Rock_Marble"
    },
    {
      "x": -2,
      "y": 7,
      "z": -2,
      "name": "Rock_Marble"
    },
    {
      "x": -2,
      "y": 1,
      "z": -1,
      "name": "Rock_Marble_Cobble"
    },
    {
      "x": -2,
      "y": 2,
      "z": -1,
      "name": "Rock_Marble_Cobble"
    },
    {
      "x": -2,
      "y": 3,
      "z": -1,
      "name": "Rock_Marble_Cobble"
    },
    {
      "x": -2,
      "y": 4,
      "z": -1,
      "name": "Rock_Marble_Cobble"
    },
    {
      "x": -2,
      "y": 5,
      "z": -1,
      "name": "Rock_Marble_Cobble"
    },
    {
      "x": -2,
      "y": 6,
      "z": -1,
      "name": "Rock_Marble"
    },
    {
      "x": -2,
      "y": 7,
      "z": -1,
      "name": "Rock_Marble"
    },
    {
      "x": -2,
      "y": 8,
      "z": -1,
      "name": "Rock_Marble"
    },
    {
      "x": -2,
      "y": 9,
      "z": -1,
      "name": "Rock_Marble"
    },
    {
      "x": -2,
      "y": 10,
      "z": -1,
      "name": "Soil_Clay_White"
    },
    {
      "x": -2,
      "y": 11,
      "z": -1,
      "name": "Rock_Marble"
    },
    {
      "x": -2,
      "y": 12,
      "z": -1,
      "name": "Rock_Marble_Cobble"
    },
    {
      "x": -2,
      "y": 13,
      "z": -1,
      "name": "Rock_Marble"
    },
    {
      "x": -2,
      "y": 14,
      "z": -1,
      "name": "Soil_Clay_White"
    },
    {
      "x": -2,
      "y": 15,
      "z": -1,
      "name": "Rock_Marble"
    },
    {
      "x": -2,
      "y": 1,
      "z": 0,
      "name": "Rock_Marble_Cobble"
    },
    {
      "x": -2,
      "y": 2,
      "z": 0,
      "name": "Rock_Marble_Cobble"
    },
    {
      "x": -2,
      "y": 3,
      "z": 0,
      "name": "Rock_Marble_Cobble"
    },
    {
      "x": -2,
      "y": 4,
      "z": 0,
      "name": "Rock_Marble_Cobble"
    },
    {
      "x": -2,
      "y": 5,
      "z": 0,
      "name": "Rock_Marble_Cobble"
    },
    {
      "x": -2,
      "y": 6,
      "z": 0,
      "name": "Rock_Marble"
    },
    {
      "x": -2,
      "y": 7,
      "z": 0,
      "name": "Rock_Marble"
    },
    {
      "x": -2,
      "y": 8,
      "z": 0,
      "name": "Rock_Marble"
    },
    {
      "x": -2,
      "y": 9,
      "z": 0,
      "name": "Rock_Marble"
    },
    {
      "x": -2,
      "y": 10,
      "z": 0,
      "name": "Soil_Clay_White"
    },
    {
      "x": -2,
      "y": 11,
      "z": 0,
      "name": "Rock_Marble"
    },
    {
      "x": -2,
      "y": 12,
      "z": 0,
      "name": "Rock_Marble_Cobble"
    },
    {
      "x": -2,
      "y": 13,
      "z": 0,
      "name": "Rock_Marble"
    },
    {
      "x": -2,
      "y": 14,
      "z": 0,
      "name": "Soil_Clay_White"
    },
    {
      "x": -2,
      "y": 15,
      "z": 0,
      "name": "Rock_Marble"
    },
    {
      "x": -2,
      "y": 16,
      "z": 0,
      "name": "Rock_Marble_Cobble"
    },
    {
      "x": -2,
      "y": 17,
      "z": 0,
      "name": "Rock_Marble_Cobble"
    },
    {
      "x": -2,
      "y": 18,
      "z": 0,
      "name": "Rock_Marble_Cobble"
    },
    {
      "x": -2,
      "y": 1,
      "z": 1,
      "name": "Rock_Marble_Cobble"
    },
    {
      "x": -2,
      "y": 2,
      "z": 1,
      "name": "Rock_Marble_Cobble"
    },
    {
      "x": -2,
      "y": 3,
      "z": 1,
      "name": "Rock_Marble"
    },
    {
      "x": -2,
      "y": 4,
      "z": 1,
      "name": "Rock_Marble_Cobble"
    },
    {
      "x": -2,
      "y": 5,
      "z": 1,
      "name": "Rock_Marble_Cobble"
    },
    {
      "x": -2,
      "y": 6,
      "z": 1,
      "name": "Rock_Marble"
    },
    {
      "x": -2,
      "y": 7,
      "z": 1,
      "name": "Rock_Marble"
    },
    {
      "x": -2,
      "y": 8,
      "z": 1,
      "name": "Rock_Marble"
    },
    {
      "x": -2,
      "y": 9,
      "z": 1,
      "name": "Rock_Marble"
    },
    {
      "x": -2,
      "y": 10,
      "z": 1,
      "name": "Soil_Clay_White"
    },
    {
      "x": -2,
      "y": 11,
      "z": 1,
      "name": "Rock_Marble"
    },
    {
      "x": -2,
      "y": 12,
      "z": 1,
      "name": "Rock_Marble_Cobble"
    },
    {
      "x": -2,
      "y": 13,
      "z": 1,
      "name": "Rock_Marble"
    },
    {
      "x": -2,
      "y": 14,
      "z": 1,
      "name": "Soil_Clay_White"
    },
    {
      "x": -2,
      "y": 15,
      "z": 1,
      "name": "Rock_Marble"
    },
    {
      "x": -2,
      "y": 16,
      "z": 1,
      "name": "Rock_Marble_Cobble"
    },
    {
      "x": -2,
      "y": 17,
      "z": 1,
      "name": "Rock_Marble_Cobble"
    },
    {
      "x": -2,
      "y": 18,
      "z": 1,
      "name": "Rock_Marble_Cobble"
    },
    {
      "x": -2,
      "y": 19,
      "z": 1,
      "name": "Rock_Marble_Cobble"
    },
    {
      "x": -2,
      "y": 1,
      "z": 2,
      "name": "Rock_Marble_Cobble"
    },
    {
      "x": -2,
      "y": 2,
      "z": 2,
      "name": "Rock_Marble_Cobble"
    },
    {
      "x": -2,
      "y": 3,
      "z": 2,
      "name": "Rock_Marble"
    },
    {
      "x": -2,
      "y": 4,
      "z": 2,
      "name": "Rock_Marble_Cobble"
    },
    {
      "x": -2,
      "y": 5,
      "z": 2,
      "name": "Rock_Marble_Cobble"
    },
    {
      "x": -2,
      "y": 6,
      "z": 2,
      "name": "Rock_Marble"
    },
    {
      "x": -2,
      "y": 7,
      "z": 2,
      "name": "Rock_Marble"
    },
    {
      "x": -2,
      "y": 8,
      "z": 2,
      "name": "Rock_Marble"
    },
    {
      "x": -2,
      "y": 9,
      "z": 2,
      "name": "Rock_Marble"
    },
    {
      "x": -2,
      "y": 10,
      "z": 2,
      "name": "Soil_Clay_White"
    },
    {
      "x": -2,
      "y": 11,
      "z": 2,
      "name": "Rock_Marble"
    },
    {
      "x": -2,
      "y": 12,
      "z": 2,
      "name": "Rock_Marble_Cobble"
    },
    {
      "x": -2,
      "y": 13,
      "z": 2,
      "name": "Rock_Marble"
    },
    {
      "x": -2,
      "y": 2,
      "z": 3,
      "name": "Rock_Marble_Cobble"
    },
    {
      "x": -2,
      "y": 3,
      "z": 3,
      "name": "Rock_Marble"
    },
    {
      "x": -2,
      "y": 4,
      "z": 3,
      "name": "Rock_Marble_Cobble"
    },
    {
      "x": -2,
      "y": 5,
      "z": 3,
      "name": "Rock_Marble_Cobble"
    },
    {
      "x": -2,
      "y": 6,
      "z": 3,
      "name": "Rock_Marble"
    },
    {
      "x": -2,
      "y": 7,
      "z": 3,
      "name": "Rock_Marble"
    },
    {
      "x": -2,
      "y": 8,
      "z": 3,
      "name": "Rock_Marble"
    },
    {
      "x": -2,
      "y": 9,
      "z": 3,
      "name": "Rock_Marble"
    },
    {
      "x": -2,
      "y": 10,
      "z": 3,
      "name": "Soil_Clay_White"
    },
    {
      "x": -2,
      "y": 3,
      "z": 4,
      "name": "Rock_Marble"
    },
    {
      "x": -2,
      "y": 4,
      "z": 4,
      "name": "Rock_Marble_Cobble"
    },
    {
      "x": -2,
      "y": 5,
      "z": 4,
      "name": "Rock_Marble_Cobble"
    },
    {
      "x": -2,
      "y": 6,
      "z": 4,
      "name": "Rock_Marble"
    },
    {
      "x": -2,
      "y": 7,
      "z": 4,
      "name": "Rock_Marble"
    },
    {
      "x": -2,
      "y": 8,
      "z": 4,
      "name": "Rock_Marble"
    },
    {
      "x": -2,
      "y": 5,
      "z": 5,
      "name": "Rock_Marble_Cobble"
    },
    {
      "x": -1,
      "y": 4,
      "z": -4,
      "name": "Rock_Marble_Cobble"
    },
    {
      "x": -1,
      "y": 5,
      "z": -4,
      "name": "Rock_Marble_Cobble"
    },
    {
      "x": -1,
      "y": 2,
      "z": -3,
      "name": "Rock_Marble_Cobble"
    },
    {
      "x": -1,
      "y": 3,
      "z": -3,
      "name": "Rock_Marble_Cobble"
    },
    {
      "x": -1,
      "y": 4,
      "z": -3,
      "name": "Rock_Marble_Cobble"
    },
    {
      "x": -1,
      "y": 5,
      "z": -3,
      "name": "Rock_Marble_Cobble"
    },
    {
      "x": -1,
      "y": 6,
      "z": -3,
      "name": "Rock_Marble"
    },
    {
      "x": -1,
      "y": 2,
      "z": -2,
      "name": "Rock_Marble_Cobble"
    },
    {
      "x": -1,
      "y": 3,
      "z": -2,
      "name": "Rock_Marble_Cobble"
    },
    {
      "x": -1,
      "y": 4,
      "z": -2,
      "name": "Rock_Marble_Cobble"
    },
    {
      "x": -1,
      "y": 5,
      "z": -2,
      "name": "Rock_Marble_Cobble"
    },
    {
      "x": -1,
      "y": 6,
      "z": -2,
      "name": "Rock_Marble"
    },
    {
      "x": -1,
      "y": 7,
      "z": -2,
      "name": "Rock_Marble"
    },
    {
      "x": -1,
      "y": 8,
      "z": -2,
      "name": "Rock_Marble"
    },
    {
      "x": -1,
      "y": 9,
      "z": -2,
      "name": "Rock_Marble"
    },
    {
      "x": -1,
      "y": 10,
      "z": -2,
      "name": "Soil_Clay_White"
    },
    {
      "x": -1,
      "y": 11,
      "z": -2,
      "name": "Rock_Marble"
    },
    {
      "x": -1,
      "y": 12,
      "z": -2,
      "name": "Rock_Marble_Cobble"
    },
    {
      "x": -1,
      "y": 13,
      "z": -2,
      "name": "Rock_Marble"
    },
    {
      "x": -1,
      "y": 1,
      "z": -1,
      "name": "Rock_Marble_Cobble"
    },
    {
      "x": -1,
      "y": 2,
      "z": -1,
      "name": "Rock_Marble_Cobble"
    },
    {
      "x": -1,
      "y": 3,
      "z": -1,
      "name": "Rock_Marble_Cobble"
    },
    {
      "x": -1,
      "y": 4,
      "z": -1,
      "name": "Rock_Marble_Cobble"
    },
    {
      "x": -1,
      "y": 5,
      "z": -1,
      "name": "Rock_Marble_Cobble"
    },
    {
      "x": -1,
      "y": 6,
      "z": -1,
      "name": "Rock_Marble"
    },
    {
      "x": -1,
      "y": 7,
      "z": -1,
      "name": "Rock_Marble"
    },
    {
      "x": -1,
      "y": 8,
      "z": -1,
      "name": "Rock_Marble"
    },
    {
      "x": -1,
      "y": 9,
      "z": -1,
      "name": "Rock_Marble"
    },
    {
      "x": -1,
      "y": 10,
      "z": -1,
      "name": "Soil_Clay_White"
    },
    {
      "x": -1,
      "y": 11,
      "z": -1,
      "name": "Rock_Marble"
    },
    {
      "x": -1,
      "y": 12,
      "z": -1,
      "name": "Rock_Marble_Cobble"
    },
    {
      "x": -1,
      "y": 13,
      "z": -1,
      "name": "Rock_Marble"
    },
    {
      "x": -1,
      "y": 14,
      "z": -1,
      "name": "Soil_Clay_White"
    },
    {
      "x": -1,
      "y": 15,
      "z": -1,
      "name": "Rock_Marble"
    },
    {
      "x": -1,
      "y": 16,
      "z": -1,
      "name": "Rock_Marble_Cobble"
    },
    {
      "x": -1,
      "y": 17,
      "z": -1,
      "name": "Rock_Marble_Cobble"
    },
    {
      "x": -1,
      "y": 18,
      "z": -1,
      "name": "Rock_Marble_Cobble"
    },
    {
      "x": -1,
      "y": 1,
      "z": 0,
      "name": "Rock_Marble_Cobble"
    },
    {
      "x": -1,
      "y": 2,
      "z": 0,
      "name": "Rock_Marble_Cobble"
    },
    {
      "x": -1,
      "y": 3,
      "z": 0,
      "name": "Rock_Marble_Cobble"
    },
    {
      "x": -1,
      "y": 4,
      "z": 0,
      "name": "Rock_Marble_Cobble"
    },
    {
      "x": -1,
      "y": 5,
      "z": 0,
      "name": "Rock_Marble_Cobble"
    },
    {
      "x": -1,
      "y": 6,
      "z": 0,
      "name": "Rock_Marble"
    },
    {
      "x": -1,
      "y": 7,
      "z": 0,
      "name": "Rock_Marble"
    },
    {
      "x": -1,
      "y": 8,
      "z": 0,
      "name": "Rock_Marble"
    },
    {
      "x": -1,
      "y": 9,
      "z": 0,
      "name": "Rock_Marble"
    },
    {
      "x": -1,
      "y": 10,
      "z": 0,
      "name": "Soil_Clay_White"
    },
    {
      "x": -1,
      "y": 11,
      "z": 0,
      "name": "Rock_Marble"
    },
    {
      "x": -1,
      "y": 12,
      "z": 0,
      "name": "Rock_Marble_Cobble"
    },
    {
      "x": -1,
      "y": 13,
      "z": 0,
      "name": "Rock_Marble"
    },
    {
      "x": -1,
      "y": 14,
      "z": 0,
      "name": "Soil_Clay_White"
    },
    {
      "x": -1,
      "y": 15,
      "z": 0,
      "name": "Rock_Marble"
    },
    {
      "x": -1,
      "y": 16,
      "z": 0,
      "name": "Rock_Marble_Cobble"
    },
    {
      "x": -1,
      "y": 17,
      "z": 0,
      "name": "Rock_Marble_Cobble"
    },
    {
      "x": -1,
      "y": 18,
      "z": 0,
      "name": "Rock_Marble_Cobble"
    },
    {
      "x": -1,
      "y": 19,
      "z": 0,
      "name": "Rock_Marble_Cobble"
    },
    {
      "x": -1,
      "y": 20,
      "z": 0,
      "name": "Rock_Marble_Cobble"
    },
    {
      "x": -1,
      "y": 0,
      "z": 1,
      "name": "Rock_Marble_Cobble"
    },
    {
      "x": -1,
      "y": 1,
      "z": 1,
      "name": "Rock_Marble_Cobble"
    },
    {
      "x": -1,
      "y": 2,
      "z": 1,
      "name": "Rock_Marble_Cobble"
    },
    {
      "x": -1,
      "y": 3,
      "z": 1,
      "name": "Rock_Marble_Cobble"
    },
    {
      "x": -1,
      "y": 4,
      "z": 1,
      "name": "Rock_Marble_Cobble"
    },
    {
      "x": -1,
      "y": 5,
      "z": 1,
      "name": "Rock_Marble_Cobble"
    },
    {
      "x": -1,
      "y": 6,
      "z": 1,
      "name": "Rock_Marble"
    },
    {
      "x": -1,
      "y": 7,
      "z": 1,
      "name": "Rock_Marble"
    },
    {
      "x": -1,
      "y": 8,
      "z": 1,
      "name": "Rock_Marble"
    },
    {
      "x": -1,
      "y": 9,
      "z": 1,
      "name": "Rock_Marble"
    },
    {
      "x": -1,
      "y": 10,
      "z": 1,
      "name": "Soil_Clay_White"
    },
    {
      "x": -1,
      "y": 11,
      "z": 1,
      "name": "Rock_Marble"
    },
    {
      "x": -1,
      "y": 12,
      "z": 1,
      "name": "Rock_Marble_Cobble"
    },
    {
      "x": -1,
      "y": 13,
      "z": 1,
      "name": "Rock_Marble"
    },
    {
      "x": -1,
      "y": 14,
      "z": 1,
      "name": "Soil_Clay_White"
    },
    {
      "x": -1,
      "y": 15,
      "z": 1,
      "name": "Rock_Marble"
    },
    {
      "x": -1,
      "y": 16,
      "z": 1,
      "name": "Rock_Marble_Cobble"
    },
    {
      "x": -1,
      "y": 17,
      "z": 1,
      "name": "Rock_Marble_Cobble"
    },
    {
      "x": -1,
      "y": 18,
      "z": 1,
      "name": "Rock_Marble_Cobble"
    },
    {
      "x": -1,
      "y": 19,
      "z": 1,
      "name": "Rock_Marble_Cobble"
    },
    {
      "x": -1,
      "y": 20,
      "z": 1,
      "name": "Rock_Marble_Cobble"
    },
    {
      "x": -1,
      "y": 1,
      "z": 2,
      "name": "Rock_Marble_Cobble"
    },
    {
      "x": -1,
      "y": 2,
      "z": 2,
      "name": "Rock_Marble_Cobble"
    },
    {
      "x": -1,
      "y": 3,
      "z": 2,
      "name": "Rock_Marble_Cobble"
    },
    {
      "x": -1,
      "y": 4,
      "z": 2,
      "name": "Rock_Marble_Cobble"
    },
    {
      "x": -1,
      "y": 5,
      "z": 2,
      "name": "Rock_Marble_Cobble"
    },
    {
      "x": -1,
      "y": 6,
      "z": 2,
      "name": "Rock_Marble"
    },
    {
      "x": -1,
      "y": 7,
      "z": 2,
      "name": "Rock_Marble"
    },
    {
      "x": -1,
      "y": 8,
      "z": 2,
      "name": "Rock_Marble"
    },
    {
      "x": -1,
      "y": 9,
      "z": 2,
      "name": "Rock_Marble"
    },
    {
      "x": -1,
      "y": 10,
      "z": 2,
      "name": "Soil_Clay_White"
    },
    {
      "x": -1,
      "y": 11,
      "z": 2,
      "name": "Rock_Marble"
    },
    {
      "x": -1,
      "y": 12,
      "z": 2,
      "name": "Rock_Marble_Cobble"
    },
    {
      "x": -1,
      "y": 13,
      "z": 2,
      "name": "Rock_Marble"
    },
    {
      "x": -1,
      "y": 14,
      "z": 2,
      "name": "Soil_Clay_White"
    },
    {
      "x": -1,
      "y": 15,
      "z": 2,
      "name": "Rock_Marble"
    },
    {
      "x": -1,
      "y": 16,
      "z": 2,
      "name": "Rock_Marble_Cobble"
    },
    {
      "x": -1,
      "y": 17,
      "z": 2,
      "name": "Rock_Marble_Cobble"
    },
    {
      "x": -1,
      "y": 18,
      "z": 2,
      "name": "Rock_Marble_Cobble"
    },
    {
      "x": -1,
      "y": 19,
      "z": 2,
      "name": "Rock_Marble_Cobble"
    },
    {
      "x": -1,
      "y": 1,
      "z": 3,
      "name": "Rock_Marble_Cobble"
    },
    {
      "x": -1,
      "y": 2,
      "z": 3,
      "name": "Rock_Marble_Cobble"
    },
    {
      "x": -1,
      "y": 3,
      "z": 3,
      "name": "Rock_Marble"
    },
    {
      "x": -1,
      "y": 4,
      "z": 3,
      "name": "Rock_Marble_Cobble"
    },
    {
      "x": -1,
      "y": 5,
      "z": 3,
      "name": "Rock_Marble_Cobble"
    },
    {
      "x": -1,
      "y": 6,
      "z": 3,
      "name": "Rock_Marble"
    },
    {
      "x": -1,
      "y": 7,
      "z": 3,
      "name": "Rock_Marble"
    },
    {
      "x": -1,
      "y": 8,
      "z": 3,
      "name": "Rock_Marble"
    },
    {
      "x": -1,
      "y": 9,
      "z": 3,
      "name": "Rock_Marble"
    },
    {
      "x": -1,
      "y": 10,
      "z": 3,
      "name": "Soil_Clay_White"
    },
    {
      "x": -1,
      "y": 11,
      "z": 3,
      "name": "Rock_Marble"
    },
    {
      "x": -1,
      "y": 12,
      "z": 3,
      "name": "Rock_Marble_Cobble"
    },
    {
      "x": -1,
      "y": 2,
      "z": 4,
      "name": "Rock_Marble_Cobble"
    },
    {
      "x": -1,
      "y": 3,
      "z": 4,
      "name": "Rock_Marble"
    },
    {
      "x": -1,
      "y": 4,
      "z": 4,
      "name": "Rock_Marble_Cobble"
    },
    {
      "x": -1,
      "y": 5,
      "z": 4,
      "name": "Rock_Marble_Cobble"
    },
    {
      "x": -1,
      "y": 6,
      "z": 4,
      "name": "Rock_Marble"
    },
    {
      "x": -1,
      "y": 7,
      "z": 4,
      "name": "Rock_Marble"
    },
    {
      "x": -1,
      "y": 8,
      "z": 4,
      "name": "Rock_Marble"
    },
    {
      "x": -1,
      "y": 9,
      "z": 4,
      "name": "Rock_Marble"
    },
    {
      "x": -1,
      "y": 4,
      "z": 5,
      "name": "Rock_Marble_Cobble"
    },
    {
      "x": -1,
      "y": 5,
      "z": 5,
      "name": "Rock_Marble_Cobble"
    },
    {
      "x": -1,
      "y": 6,
      "z": 5,
      "name": "Rock_Marble"
    },
    {
      "x": -1,
      "y": 7,
      "z": 5,
      "name": "Rock_Marble"
    },
    {
      "x": 0,
      "y": 4,
      "z": -4,
      "name": "Rock_Marble_Cobble"
    },
    {
      "x": 0,
      "y": 5,
      "z": -4,
      "name": "Rock_Marble_Cobble"
    },
    {
      "x": 0,
      "y": 2,
      "z": -3,
      "name": "Rock_Marble_Cobble"
    },
    {
      "x": 0,
      "y": 3,
      "z": -3,
      "name": "Rock_Marble_Cobble"
    },
    {
      "x": 0,
      "y": 4,
      "z": -3,
      "name": "Rock_Marble_Cobble"
    },
    {
      "x": 0,
      "y": 5,
      "z": -3,
      "name": "Rock_Marble_Cobble"
    },
    {
      "x": 0,
      "y": 6,
      "z": -3,
      "name": "Rock_Marble"
    },
    {
      "x": 0,
      "y": 7,
      "z": -3,
      "name": "Rock_Marble"
    },
    {
      "x": 0,
      "y": 2,
      "z": -2,
      "name": "Rock_Marble_Cobble"
    },
    {
      "x": 0,
      "y": 3,
      "z": -2,
      "name": "Rock_Marble_Cobble"
    },
    {
      "x": 0,
      "y": 4,
      "z": -2,
      "name": "Rock_Marble_Cobble"
    },
    {
      "x": 0,
      "y": 5,
      "z": -2,
      "name": "Rock_Marble_Cobble"
    },
    {
      "x": 0,
      "y": 6,
      "z": -2,
      "name": "Rock_Marble"
    },
    {
      "x": 0,
      "y": 7,
      "z": -2,
      "name": "Rock_Marble"
    },
    {
      "x": 0,
      "y": 8,
      "z": -2,
      "name": "Rock_Marble"
    },
    {
      "x": 0,
      "y": 9,
      "z": -2,
      "name": "Rock_Marble"
    },
    {
      "x": 0,
      "y": 10,
      "z": -2,
      "name": "Soil_Clay_White"
    },
    {
      "x": 0,
      "y": 11,
      "z": -2,
      "name": "Rock_Marble"
    },
    {
      "x": 0,
      "y": 12,
      "z": -2,
      "name": "Rock_Marble_Cobble"
    },
    {
      "x": 0,
      "y": 13,
      "z": -2,
      "name": "Rock_Marble"
    },
    {
      "x": 0,
      "y": 14,
      "z": -2,
      "name": "Soil_Clay_White"
    },
    {
      "x": 0,
      "y": 1,
      "z": -1,
      "name": "Rock_Marble_Cobble"
    },
    {
      "x": 0,
      "y": 2,
      "z": -1,
      "name": "Rock_Marble_Cobble"
    },
    {
      "x": 0,
      "y": 3,
      "z": -1,
      "name": "Rock_Marble_Cobble"
    },
    {
      "x": 0,
      "y": 4,
      "z": -1,
      "name": "Rock_Marble_Cobble"
    },
    {
      "x": 0,
      "y": 5,
      "z": -1,
      "name": "Rock_Marble_Cobble"
    },
    {
      "x": 0,
      "y": 6,
      "z": -1,
      "name": "Rock_Marble"
    },
    {
      "x": 0,
      "y": 7,
      "z": -1,
      "name": "Rock_Marble"
    },
    {
      "x": 0,
      "y": 8,
      "z": -1,
      "name": "Rock_Marble"
    },
    {
      "x": 0,
      "y": 9,
      "z": -1,
      "name": "Rock_Marble"
    },
    {
      "x": 0,
      "y": 10,
      "z": -1,
      "name": "Soil_Clay_White"
    },
    {
      "x": 0,
      "y": 11,
      "z": -1,
      "name": "Rock_Marble"
    },
    {
      "x": 0,
      "y": 12,
      "z": -1,
      "name": "Rock_Marble_Cobble"
    },
    {
      "x": 0,
      "y": 13,
      "z": -1,
      "name": "Rock_Marble"
    },
    {
      "x": 0,
      "y": 14,
      "z": -1,
      "name": "Soil_Clay_White"
    },
    {
      "x": 0,
      "y": 15,
      "z": -1,
      "name": "Rock_Marble"
    },
    {
      "x": 0,
      "y": 16,
      "z": -1,
      "name": "Rock_Marble_Cobble"
    },
    {
      "x": 0,
      "y": 17,
      "z": -1,
      "name": "Rock_Marble_Cobble"
    },
    {
      "x": 0,
      "y": 0,
      "z": 0,
      "name": "Rock_Marble_Cobble"
    },
    {
      "x": 0,
      "y": 1,
      "z": 0,
      "name": "Rock_Marble_Cobble"
    },
    {
      "x": 0,
      "y": 2,
      "z": 0,
      "name": "Rock_Marble_Cobble"
    },
    {
      "x": 0,
      "y": 3,
      "z": 0,
      "name": "Rock_Marble_Cobble"
    },
    {
      "x": 0,
      "y": 4,
      "z": 0,
      "name": "Rock_Marble_Cobble"
    },
    {
      "x": 0,
      "y": 5,
      "z": 0,
      "name": "Rock_Marble_Cobble"
    },
    {
      "x": 0,
      "y": 6,
      "z": 0,
      "name": "Rock_Marble"
    },
    {
      "x": 0,
      "y": 7,
      "z": 0,
      "name": "Rock_Marble"
    },
    {
      "x": 0,
      "y": 8,
      "z": 0,
      "name": "Rock_Marble"
    },
    {
      "x": 0,
      "y": 9,
      "z": 0,
      "name": "Rock_Marble"
    },
    {
      "x": 0,
      "y": 10,
      "z": 0,
      "name": "Soil_Clay_White"
    },
    {
      "x": 0,
      "y": 11,
      "z": 0,
      "name": "Rock_Marble"
    },
    {
      "x": 0,
      "y": 12,
      "z": 0,
      "name": "Rock_Marble_Cobble"
    },
    {
      "x": 0,
      "y": 13,
      "z": 0,
      "name": "Rock_Marble"
    },
    {
      "x": 0,
      "y": 14,
      "z": 0,
      "name": "Soil_Clay_White"
    },
    {
      "x": 0,
      "y": 15,
      "z": 0,
      "name": "Rock_Marble"
    },
    {
      "x": 0,
      "y": 16,
      "z": 0,
      "name": "Rock_Marble_Cobble"
    },
    {
      "x": 0,
      "y": 17,
      "z": 0,
      "name": "Rock_Marble_Cobble"
    },
    {
      "x": 0,
      "y": 18,
      "z": 0,
      "name": "Rock_Marble_Cobble"
    },
    {
      "x": 0,
      "y": 19,
      "z": 0,
      "name": "Rock_Marble_Cobble"
    },
    {
      "x": 0,
      "y": 0,
      "z": 1,
      "name": "Rock_Marble_Cobble"
    },
    {
      "x": 0,
      "y": 1,
      "z": 1,
      "name": "Rock_Marble_Cobble"
    },
    {
      "x": 0,
      "y": 2,
      "z": 1,
      "name": "Rock_Marble_Cobble"
    },
    {
      "x": 0,
      "y": 3,
      "z": 1,
      "name": "Rock_Marble_Cobble"
    },
    {
      "x": 0,
      "y": 4,
      "z": 1,
      "name": "Rock_Marble_Cobble"
    },
    {
      "x": 0,
      "y": 5,
      "z": 1,
      "name": "Rock_Marble_Cobble"
    },
    {
      "x": 0,
      "y": 6,
      "z": 1,
      "name": "Rock_Marble"
    },
    {
      "x": 0,
      "y": 7,
      "z": 1,
      "name": "Rock_Marble"
    },
    {
      "x": 0,
      "y": 8,
      "z": 1,
      "name": "Rock_Marble"
    },
    {
      "x": 0,
      "y": 9,
      "z": 1,
      "name": "Rock_Marble"
    },
    {
      "x": 0,
      "y": 10,
      "z": 1,
      "name": "Soil_Clay_White"
    },
    {
      "x": 0,
      "y": 11,
      "z": 1,
      "name": "Rock_Marble"
    },
    {
      "x": 0,
      "y": 12,
      "z": 1,
      "name": "Rock_Marble_Cobble"
    },
    {
      "x": 0,
      "y": 13,
      "z": 1,
      "name": "Rock_Marble"
    },
    {
      "x": 0,
      "y": 14,
      "z": 1,
      "name": "Soil_Clay_White"
    },
    {
      "x": 0,
      "y": 15,
      "z": 1,
      "name": "Rock_Marble"
    },
    {
      "x": 0,
      "y": 16,
      "z": 1,
      "name": "Rock_Marble_Cobble"
    },
    {
      "x": 0,
      "y": 17,
      "z": 1,
      "name": "Rock_Marble_Cobble"
    },
    {
      "x": 0,
      "y": 18,
      "z": 1,
      "name": "Rock_Marble_Cobble"
    },
    {
      "x": 0,
      "y": 19,
      "z": 1,
      "name": "Rock_Marble_Cobble"
    },
    {
      "x": 0,
      "y": 20,
      "z": 1,
      "name": "Rock_Marble_Cobble"
    },
    {
      "x": 0,
      "y": 0,
      "z": 2,
      "name": "Rock_Marble_Cobble"
    },
    {
      "x": 0,
      "y": 1,
      "z": 2,
      "name": "Rock_Marble_Cobble"
    },
    {
      "x": 0,
      "y": 2,
      "z": 2,
      "name": "Rock_Marble_Cobble"
    },
    {
      "x": 0,
      "y": 3,
      "z": 2,
      "name": "Rock_Marble_Cobble"
    },
    {
      "x": 0,
      "y": 4,
      "z": 2,
      "name": "Rock_Marble_Cobble"
    },
    {
      "x": 0,
      "y": 5,
      "z": 2,
      "name": "Rock_Marble_Cobble"
    },
    {
      "x": 0,
      "y": 6,
      "z": 2,
      "name": "Rock_Marble"
    },
    {
      "x": 0,
      "y": 7,
      "z": 2,
      "name": "Rock_Marble"
    },
    {
      "x": 0,
      "y": 8,
      "z": 2,
      "name": "Rock_Marble"
    },
    {
      "x": 0,
      "y": 9,
      "z": 2,
      "name": "Rock_Marble"
    },
    {
      "x": 0,
      "y": 10,
      "z": 2,
      "name": "Soil_Clay_White"
    },
    {
      "x": 0,
      "y": 11,
      "z": 2,
      "name": "Rock_Marble"
    },
    {
      "x": 0,
      "y": 12,
      "z": 2,
      "name": "Rock_Marble_Cobble"
    },
    {
      "x": 0,
      "y": 13,
      "z": 2,
      "name": "Rock_Marble"
    },
    {
      "x": 0,
      "y": 14,
      "z": 2,
      "name": "Soil_Clay_White"
    },
    {
      "x": 0,
      "y": 15,
      "z": 2,
      "name": "Rock_Marble"
    },
    {
      "x": 0,
      "y": 16,
      "z": 2,
      "name": "Rock_Marble_Cobble"
    },
    {
      "x": 0,
      "y": 17,
      "z": 2,
      "name": "Rock_Marble_Cobble"
    },
    {
      "x": 0,
      "y": 1,
      "z": 3,
      "name": "Rock_Marble_Cobble"
    },
    {
      "x": 0,
      "y": 2,
      "z": 3,
      "name": "Rock_Marble_Cobble"
    },
    {
      "x": 0,
      "y": 3,
      "z": 3,
      "name": "Rock_Marble_Cobble"
    },
    {
      "x": 0,
      "y": 4,
      "z": 3,
      "name": "Rock_Marble_Cobble"
    },
    {
      "x": 0,
      "y": 5,
      "z": 3,
      "name": "Rock_Marble_Cobble"
    },
    {
      "x": 0,
      "y": 6,
      "z": 3,
      "name": "Rock_Marble"
    },
    {
      "x": 0,
      "y": 7,
      "z": 3,
      "name": "Rock_Marble"
    },
    {
      "x": 0,
      "y": 8,
      "z": 3,
      "name": "Rock_Marble"
    },
    {
      "x": 0,
      "y": 9,
      "z": 3,
      "name": "Rock_Marble"
    },
    {
      "x": 0,
      "y": 10,
      "z": 3,
      "name": "Soil_Clay_White"
    },
    {
      "x": 0,
      "y": 11,
      "z": 3,
      "name": "Rock_Marble"
    },
    {
      "x": 0,
      "y": 12,
      "z": 3,
      "name": "Rock_Marble_Cobble"
    },
    {
      "x": 0,
      "y": 2,
      "z": 4,
      "name": "Rock_Marble_Cobble"
    },
    {
      "x": 0,
      "y": 3,
      "z": 4,
      "name": "Rock_Marble_Cobble"
    },
    {
      "x": 0,
      "y": 4,
      "z": 4,
      "name": "Rock_Marble_Cobble"
    },
    {
      "x": 0,
      "y": 5,
      "z": 4,
      "name": "Rock_Marble_Cobble"
    },
    {
      "x": 0,
      "y": 6,
      "z": 4,
      "name": "Rock_Marble"
    },
    {
      "x": 0,
      "y": 7,
      "z": 4,
      "name": "Rock_Marble"
    },
    {
      "x": 0,
      "y": 8,
      "z": 4,
      "name": "Rock_Marble"
    },
    {
      "x": 0,
      "y": 9,
      "z": 4,
      "name": "Rock_Marble"
    },
    {
      "x": 0,
      "y": 10,
      "z": 4,
      "name": "Soil_Clay_White"
    },
    {
      "x": 0,
      "y": 4,
      "z": 5,
      "name": "Rock_Marble_Cobble"
    },
    {
      "x": 0,
      "y": 5,
      "z": 5,
      "name": "Rock_Marble_Cobble"
    },
    {
      "x": 0,
      "y": 6,
      "z": 5,
      "name": "Rock_Marble"
    },
    {
      "x": 0,
      "y": 7,
      "z": 5,
      "name": "Rock_Marble"
    },
    {
      "x": 0,
      "y": 8,
      "z": 5,
      "name": "Rock_Marble"
    },
    {
      "x": 1,
      "y": 4,
      "z": -4,
      "name": "Rock_Marble_Cobble"
    },
    {
      "x": 1,
      "y": 5,
      "z": -4,
      "name": "Rock_Marble_Cobble"
    },
    {
      "x": 1,
      "y": 3,
      "z": -3,
      "name": "Rock_Marble_Cobble"
    },
    {
      "x": 1,
      "y": 4,
      "z": -3,
      "name": "Rock_Marble_Cobble"
    },
    {
      "x": 1,
      "y": 5,
      "z": -3,
      "name": "Rock_Marble_Cobble"
    },
    {
      "x": 1,
      "y": 6,
      "z": -3,
      "name": "Rock_Marble"
    },
    {
      "x": 1,
      "y": 7,
      "z": -3,
      "name": "Rock_Marble"
    },
    {
      "x": 1,
      "y": 2,
      "z": -2,
      "name": "Rock_Marble_Cobble"
    },
    {
      "x": 1,
      "y": 3,
      "z": -2,
      "name": "Rock_Marble_Cobble"
    },
    {
      "x": 1,
      "y": 4,
      "z": -2,
      "name": "Rock_Marble_Cobble"
    },
    {
      "x": 1,
      "y": 5,
      "z": -2,
      "name": "Rock_Marble_Cobble"
    },
    {
      "x": 1,
      "y": 6,
      "z": -2,
      "name": "Rock_Marble"
    },
    {
      "x": 1,
      "y": 7,
      "z": -2,
      "name": "Rock_Marble"
    },
    {
      "x": 1,
      "y": 8,
      "z": -2,
      "name": "Rock_Marble"
    },
    {
      "x": 1,
      "y": 9,
      "z": -2,
      "name": "Rock_Marble"
    },
    {
      "x": 1,
      "y": 10,
      "z": -2,
      "name": "Soil_Clay_White"
    },
    {
      "x": 1,
      "y": 11,
      "z": -2,
      "name": "Rock_Marble"
    },
    {
      "x": 1,
      "y": 12,
      "z": -2,
      "name": "Rock_Marble_Cobble"
    },
    {
      "x": 1,
      "y": 1,
      "z": -1,
      "name": "Rock_Marble_Cobble"
    },
    {
      "x": 1,
      "y": 2,
      "z": -1,
      "name": "Rock_Marble_Cobble"
    },
    {
      "x": 1,
      "y": 3,
      "z": -1,
      "name": "Rock_Marble_Cobble"
    },
    {
      "x": 1,
      "y": 4,
      "z": -1,
      "name": "Rock_Marble_Cobble"
    },
    {
      "x": 1,
      "y": 5,
      "z": -1,
      "name": "Rock_Marble_Cobble"
    },
    {
      "x": 1,
      "y": 6,
      "z": -1,
      "name": "Rock_Marble"
    },
    {
      "x": 1,
      "y": 7,
      "z": -1,
      "name": "Rock_Marble"
    },
    {
      "x": 1,
      "y": 8,
      "z": -1,
      "name": "Rock_Marble"
    },
    {
      "x": 1,
      "y": 9,
      "z": -1,
      "name": "Rock_Marble"
    },
    {
      "x": 1,
      "y": 10,
      "z": -1,
      "name": "Soil_Clay_White"
    },
    {
      "x": 1,
      "y": 11,
      "z": -1,
      "name": "Rock_Marble"
    },
    {
      "x": 1,
      "y": 12,
      "z": -1,
      "name": "Rock_Marble_Cobble"
    },
    {
      "x": 1,
      "y": 13,
      "z": -1,
      "name": "Rock_Marble"
    },
    {
      "x": 1,
      "y": 14,
      "z": -1,
      "name": "Soil_Clay_White"
    },
    {
      "x": 1,
      "y": 1,
      "z": 0,
      "name": "Rock_Marble_Cobble"
    },
    {
      "x": 1,
      "y": 2,
      "z": 0,
      "name": "Rock_Marble_Cobble"
    },
    {
      "x": 1,
      "y": 3,
      "z": 0,
      "name": "Rock_Marble_Cobble"
    },
    {
      "x": 1,
      "y": 4,
      "z": 0,
      "name": "Rock_Marble_Cobble"
    },
    {
      "x": 1,
      "y": 5,
      "z": 0,
      "name": "Rock_Marble_Cobble"
    },
    {
      "x": 1,
      "y": 6,
      "z": 0,
      "name": "Rock_Marble"
    },
    {
      "x": 1,
      "y": 7,
      "z": 0,
      "name": "Rock_Marble"
    },
    {
      "x": 1,
      "y": 8,
      "z": 0,
      "name": "Rock_Marble"
    },
    {
      "x": 1,
      "y": 9,
      "z": 0,
      "name": "Rock_Marble"
    },
    {
      "x": 1,
      "y": 10,
      "z": 0,
      "name": "Soil_Clay_White"
    },
    {
      "x": 1,
      "y": 11,
      "z": 0,
      "name": "Rock_Marble"
    },
    {
      "x": 1,
      "y": 12,
      "z": 0,
      "name": "Rock_Marble_Cobble"
    },
    {
      "x": 1,
      "y": 13,
      "z": 0,
      "name": "Rock_Marble"
    },
    {
      "x": 1,
      "y": 14,
      "z": 0,
      "name": "Soil_Clay_White"
    },
    {
      "x": 1,
      "y": 15,
      "z": 0,
      "name": "Rock_Marble"
    },
    {
      "x": 1,
      "y": 16,
      "z": 0,
      "name": "Rock_Marble_Cobble"
    },
    {
      "x": 1,
      "y": 0,
      "z": 1,
      "name": "Rock_Marble_Cobble"
    },
    {
      "x": 1,
      "y": 1,
      "z": 1,
      "name": "Rock_Marble_Cobble"
    },
    {
      "x": 1,
      "y": 2,
      "z": 1,
      "name": "Rock_Marble_Cobble"
    },
    {
      "x": 1,
      "y": 3,
      "z": 1,
      "name": "Rock_Marble_Cobble"
    },
    {
      "x": 1,
      "y": 4,
      "z": 1,
      "name": "Rock_Marble_Cobble"
    },
    {
      "x": 1,
      "y": 5,
      "z": 1,
      "name": "Rock_Marble_Cobble"
    },
    {
      "x": 1,
      "y": 6,
      "z": 1,
      "name": "Rock_Marble"
    },
    {
      "x": 1,
      "y": 7,
      "z": 1,
      "name": "Rock_Marble"
    },
    {
      "x": 1,
      "y": 8,
      "z": 1,
      "name": "Rock_Marble"
    },
    {
      "x": 1,
      "y": 9,
      "z": 1,
      "name": "Rock_Marble"
    },
    {
      "x": 1,
      "y": 10,
      "z": 1,
      "name": "Soil_Clay_White"
    },
    {
      "x": 1,
      "y": 11,
      "z": 1,
      "name": "Rock_Marble"
    },
    {
      "x": 1,
      "y": 12,
      "z": 1,
      "name": "Rock_Marble_Cobble"
    },
    {
      "x": 1,
      "y": 13,
      "z": 1,
      "name": "Rock_Marble"
    },
    {
      "x": 1,
      "y": 14,
      "z": 1,
      "name": "Soil_Clay_White"
    },
    {
      "x": 1,
      "y": 15,
      "z": 1,
      "name": "Rock_Marble"
    },
    {
      "x": 1,
      "y": 16,
      "z": 1,
      "name": "Rock_Marble_Cobble"
    },
    {
      "x": 1,
      "y": 17,
      "z": 1,
      "name": "Rock_Marble_Cobble"
    },
    {
      "x": 1,
      "y": 0,
      "z": 2,
      "name": "Rock_Marble_Cobble"
    },
    {
      "x": 1,
      "y": 1,
      "z": 2,
      "name": "Rock_Marble_Cobble"
    },
    {
      "x": 1,
      "y": 2,
      "z": 2,
      "name": "Rock_Marble_Cobble"
    },
    {
      "x": 1,
      "y": 3,
      "z": 2,
      "name": "Rock_Marble_Cobble"
    },
    {
      "x": 1,
      "y": 4,
      "z": 2,
      "name": "Rock_Marble_Cobble"
    },
    {
      "x": 1,
      "y": 5,
      "z": 2,
      "name": "Rock_Marble_Cobble"
    },
    {
      "x": 1,
      "y": 6,
      "z": 2,
      "name": "Rock_Marble"
    },
    {
      "x": 1,
      "y": 7,
      "z": 2,
      "name": "Rock_Marble"
    },
    {
      "x": 1,
      "y": 8,
      "z": 2,
      "name": "Rock_Marble"
    },
    {
      "x": 1,
      "y": 9,
      "z": 2,
      "name": "Rock_Marble"
    },
    {
      "x": 1,
      "y": 10,
      "z": 2,
      "name": "Soil_Clay_White"
    },
    {
      "x": 1,
      "y": 11,
      "z": 2,
      "name": "Rock_Marble"
    },
    {
      "x": 1,
      "y": 12,
      "z": 2,
      "name": "Rock_Marble_Cobble"
    },
    {
      "x": 1,
      "y": 13,
      "z": 2,
      "name": "Rock_Marble"
    },
    {
      "x": 1,
      "y": 14,
      "z": 2,
      "name": "Soil_Clay_White"
    },
    {
      "x": 1,
      "y": 1,
      "z": 3,
      "name": "Rock_Marble_Cobble"
    },
    {
      "x": 1,
      "y": 2,
      "z": 3,
      "name": "Rock_Marble_Cobble"
    },
    {
      "x": 1,
      "y": 3,
      "z": 3,
      "name": "Rock_Marble_Cobble"
    },
    {
      "x": 1,
      "y": 4,
      "z": 3,
      "name": "Rock_Marble_Cobble"
    },
    {
      "x": 1,
      "y": 5,
      "z": 3,
      "name": "Rock_Marble_Cobble"
    },
    {
      "x": 1,
      "y": 6,
      "z": 3,
      "name": "Rock_Marble"
    },
    {
      "x": 1,
      "y": 7,
      "z": 3,
      "name": "Rock_Marble"
    },
    {
      "x": 1,
      "y": 8,
      "z": 3,
      "name": "Rock_Marble"
    },
    {
      "x": 1,
      "y": 9,
      "z": 3,
      "name": "Rock_Marble"
    },
    {
      "x": 1,
      "y": 10,
      "z": 3,
      "name": "Soil_Clay_White"
    },
    {
      "x": 1,
      "y": 11,
      "z": 3,
      "name": "Rock_Marble"
    },
    {
      "x": 1,
      "y": 2,
      "z": 4,
      "name": "Rock_Marble_Cobble"
    },
    {
      "x": 1,
      "y": 3,
      "z": 4,
      "name": "Rock_Marble_Cobble"
    },
    {
      "x": 1,
      "y": 4,
      "z": 4,
      "name": "Rock_Marble_Cobble"
    },
    {
      "x": 1,
      "y": 5,
      "z": 4,
      "name": "Rock_Marble_Cobble"
    },
    {
      "x": 1,
      "y": 6,
      "z": 4,
      "name": "Rock_Marble"
    },
    {
      "x": 1,
      "y": 7,
      "z": 4,
      "name": "Rock_Marble"
    },
    {
      "x": 1,
      "y": 8,
      "z": 4,
      "name": "Rock_Marble"
    },
    {
      "x": 1,
      "y": 9,
      "z": 4,
      "name": "Rock_Marble"
    },
    {
      "x": 1,
      "y": 10,
      "z": 4,
      "name": "Soil_Clay_White"
    },
    {
      "x": 1,
      "y": 3,
      "z": 5,
      "name": "Rock_Marble_Cobble"
    },
    {
      "x": 1,
      "y": 4,
      "z": 5,
      "name": "Rock_Marble_Cobble"
    },
    {
      "x": 1,
      "y": 5,
      "z": 5,
      "name": "Rock_Marble_Cobble"
    },
    {
      "x": 1,
      "y": 6,
      "z": 5,
      "name": "Rock_Marble"
    },
    {
      "x": 1,
      "y": 7,
      "z": 5,
      "name": "Rock_Marble"
    },
    {
      "x": 1,
      "y": 8,
      "z": 5,
      "name": "Rock_Marble"
    },
    {
      "x": 2,
      "y": 3,
      "z": -3,
      "name": "Rock_Marble_Cobble"
    },
    {
      "x": 2,
      "y": 4,
      "z": -3,
      "name": "Rock_Marble_Cobble"
    },
    {
      "x": 2,
      "y": 5,
      "z": -3,
      "name": "Rock_Marble_Cobble"
    },
    {
      "x": 2,
      "y": 6,
      "z": -3,
      "name": "Rock_Marble"
    },
    {
      "x": 2,
      "y": 2,
      "z": -2,
      "name": "Rock_Marble_Cobble"
    },
    {
      "x": 2,
      "y": 3,
      "z": -2,
      "name": "Rock_Marble_Cobble"
    },
    {
      "x": 2,
      "y": 4,
      "z": -2,
      "name": "Rock_Marble_Cobble"
    },
    {
      "x": 2,
      "y": 5,
      "z": -2,
      "name": "Rock_Marble_Cobble"
    },
    {
      "x": 2,
      "y": 6,
      "z": -2,
      "name": "Rock_Marble"
    },
    {
      "x": 2,
      "y": 7,
      "z": -2,
      "name": "Rock_Marble"
    },
    {
      "x": 2,
      "y": 8,
      "z": -2,
      "name": "Rock_Marble"
    },
    {
      "x": 2,
      "y": 9,
      "z": -2,
      "name": "Rock_Marble"
    },
    {
      "x": 2,
      "y": 10,
      "z": -2,
      "name": "Soil_Clay_White"
    },
    {
      "x": 2,
      "y": 1,
      "z": -1,
      "name": "Rock_Marble_Cobble"
    },
    {
      "x": 2,
      "y": 2,
      "z": -1,
      "name": "Rock_Marble_Cobble"
    },
    {
      "x": 2,
      "y": 3,
      "z": -1,
      "name": "Rock_Marble_Cobble"
    },
    {
      "x": 2,
      "y": 4,
      "z": -1,
      "name": "Rock_Marble_Cobble"
    },
    {
      "x": 2,
      "y": 5,
      "z": -1,
      "name": "Rock_Marble_Cobble"
    },
    {
      "x": 2,
      "y": 6,
      "z": -1,
      "name": "Rock_Marble"
    },
    {
      "x": 2,
      "y": 7,
      "z": -1,
      "name": "Rock_Marble"
    },
    {
      "x": 2,
      "y": 8,
      "z": -1,
      "name": "Rock_Marble"
    },
    {
      "x": 2,
      "y": 9,
      "z": -1,
      "name": "Rock_Marble"
    },
    {
      "x": 2,
      "y": 10,
      "z": -1,
      "name": "Soil_Clay_White"
    },
    {
      "x": 2,
      "y": 11,
      "z": -1,
      "name": "Rock_Marble"
    },
    {
      "x": 2,
      "y": 12,
      "z": -1,
      "name": "Rock_Marble_Cobble"
    },
    {
      "x": 2,
      "y": 1,
      "z": 0,
      "name": "Rock_Marble_Cobble"
    },
    {
      "x": 2,
      "y": 2,
      "z": 0,
      "name": "Rock_Marble_Cobble"
    },
    {
      "x": 2,
      "y": 3,
      "z": 0,
      "name": "Rock_Marble_Cobble"
    },
    {
      "x": 2,
      "y": 4,
      "z": 0,
      "name": "Rock_Marble_Cobble"
    },
    {
      "x": 2,
      "y": 5,
      "z": 0,
      "name": "Rock_Marble_Cobble"
    },
    {
      "x": 2,
      "y": 6,
      "z": 0,
      "name": "Rock_Marble"
    },
    {
      "x": 2,
      "y": 7,
      "z": 0,
      "name": "Rock_Marble"
    },
    {
      "x": 2,
      "y": 8,
      "z": 0,
      "name": "Rock_Marble"
    },
    {
      "x": 2,
      "y": 9,
      "z": 0,
      "name": "Rock_Marble"
    },
    {
      "x": 2,
      "y": 10,
      "z": 0,
      "name": "Soil_Clay_White"
    },
    {
      "x": 2,
      "y": 11,
      "z": 0,
      "name": "Rock_Marble"
    },
    {
      "x": 2,
      "y": 12,
      "z": 0,
      "name": "Rock_Marble_Cobble"
    },
    {
      "x": 2,
      "y": 13,
      "z": 0,
      "name": "Rock_Marble"
    },
    {
      "x": 2,
      "y": 1,
      "z": 1,
      "name": "Rock_Marble_Cobble"
    },
    {
      "x": 2,
      "y": 2,
      "z": 1,
      "name": "Rock_Marble_Cobble"
    },
    {
      "x": 2,
      "y": 3,
      "z": 1,
      "name": "Rock_Marble_Cobble"
    },
    {
      "x": 2,
      "y": 4,
      "z": 1,
      "name": "Rock_Marble_Cobble"
    },
    {
      "x": 2,
      "y": 5,
      "z": 1,
      "name": "Rock_Marble_Cobble"
    },
    {
      "x": 2,
      "y": 6,
      "z": 1,
      "name": "Rock_Marble"
    },
    {
      "x": 2,
      "y": 7,
      "z": 1,
      "name": "Rock_Marble"
    },
    {
      "x": 2,
      "y": 8,
      "z": 1,
      "name": "Rock_Marble"
    },
    {
      "x": 2,
      "y": 9,
      "z": 1,
      "name": "Rock_Marble"
    },
    {
      "x": 2,
      "y": 10,
      "z": 1,
      "name": "Soil_Clay_White"
    },
    {
      "x": 2,
      "y": 11,
      "z": 1,
      "name": "Rock_Marble"
    },
    {
      "x": 2,
      "y": 12,
      "z": 1,
      "name": "Rock_Marble_Cobble"
    },
    {
      "x": 2,
      "y": 13,
      "z": 1,
      "name": "Rock_Marble"
    },
    {
      "x": 2,
      "y": 1,
      "z": 2,
      "name": "Rock_Marble_Cobble"
    },
    {
      "x": 2,
      "y": 2,
      "z": 2,
      "name": "Rock_Marble_Cobble"
    },
    {
      "x": 2,
      "y": 3,
      "z": 2,
      "name": "Rock_Marble_Cobble"
    },
    {
      "x": 2,
      "y": 4,
      "z": 2,
      "name": "Rock_Marble_Cobble"
    },
    {
      "x": 2,
      "y": 5,
      "z": 2,
      "name": "Rock_Marble_Cobble"
    },
    {
      "x": 2,
      "y": 6,
      "z": 2,
      "name": "Rock_Marble"
    },
    {
      "x": 2,
      "y": 7,
      "z": 2,
      "name": "Rock_Marble"
    },
    {
      "x": 2,
      "y": 8,
      "z": 2,
      "name": "Rock_Marble"
    },
    {
      "x": 2,
      "y": 9,
      "z": 2,
      "name": "Rock_Marble"
    },
    {
      "x": 2,
      "y": 10,
      "z": 2,
      "name": "Soil_Clay_White"
    },
    {
      "x": 2,
      "y": 11,
      "z": 2,
      "name": "Rock_Marble"
    },
    {
      "x": 2,
      "y": 12,
      "z": 2,
      "name": "Rock_Marble_Cobble"
    },
    {
      "x": 2,
      "y": 1,
      "z": 3,
      "name": "Rock_Marble_Cobble"
    },
    {
      "x": 2,
      "y": 2,
      "z": 3,
      "name": "Rock_Marble_Cobble"
    },
    {
      "x": 2,
      "y": 3,
      "z": 3,
      "name": "Rock_Marble_Cobble"
    },
    {
      "x": 2,
      "y": 4,
      "z": 3,
      "name": "Rock_Marble_Cobble"
    },
    {
      "x": 2,
      "y": 5,
      "z": 3,
      "name": "Rock_Marble_Cobble"
    },
    {
      "x": 2,
      "y": 6,
      "z": 3,
      "name": "Rock_Marble"
    },
    {
      "x": 2,
      "y": 7,
      "z": 3,
      "name": "Rock_Marble"
    },
    {
      "x": 2,
      "y": 8,
      "z": 3,
      "name": "Rock_Marble"
    },
    {
      "x": 2,
      "y": 9,
      "z": 3,
      "name": "Rock_Marble"
    },
    {
      "x": 2,
      "y": 10,
      "z": 3,
      "name": "Soil_Clay_White"
    },
    {
      "x": 2,
      "y": 2,
      "z": 4,
      "name": "Rock_Marble_Cobble"
    },
    {
      "x": 2,
      "y": 3,
      "z": 4,
      "name": "Rock_Marble_Cobble"
    },
    {
      "x": 2,
      "y": 4,
      "z": 4,
      "name": "Rock_Marble_Cobble"
    },
    {
      "x": 2,
      "y": 5,
      "z": 4,
      "name": "Rock_Marble_Cobble"
    },
    {
      "x": 2,
      "y": 6,
      "z": 4,
      "name": "Rock_Marble"
    },
    {
      "x": 2,
      "y": 7,
      "z": 4,
      "name": "Rock_Marble"
    },
    {
      "x": 2,
      "y": 8,
      "z": 4,
      "name": "Rock_Marble"
    },
    {
      "x": 2,
      "y": 9,
      "z": 4,
      "name": "Rock_Marble"
    },
    {
      "x": 2,
      "y": 4,
      "z": 5,
      "name": "Rock_Marble_Cobble"
    },
    {
      "x": 2,
      "y": 5,
      "z": 5,
      "name": "Rock_Marble_Cobble"
    },
    {
      "x": 2,
      "y": 6,
      "z": 5,
      "name": "Rock_Marble"
    },
    {
      "x": 2,
      "y": 7,
      "z": 5,
      "name": "Rock_Marble"
    },
    {
      "x": 3,
      "y": 4,
      "z": -3,
      "name": "Rock_Marble_Cobble"
    },
    {
      "x": 3,
      "y": 5,
      "z": -3,
      "name": "Rock_Marble_Cobble"
    },
    {
      "x": 3,
      "y": 3,
      "z": -2,
      "name": "Rock_Marble_Cobble"
    },
    {
      "x": 3,
      "y": 4,
      "z": -2,
      "name": "Rock_Marble_Cobble"
    },
    {
      "x": 3,
      "y": 5,
      "z": -2,
      "name": "Rock_Marble_Cobble"
    },
    {
      "x": 3,
      "y": 6,
      "z": -2,
      "name": "Rock_Marble"
    },
    {
      "x": 3,
      "y": 7,
      "z": -2,
      "name": "Rock_Marble"
    },
    {
      "x": 3,
      "y": 2,
      "z": -1,
      "name": "Rock_Marble_Cobble"
    },
    {
      "x": 3,
      "y": 3,
      "z": -1,
      "name": "Rock_Marble_Cobble"
    },
    {
      "x": 3,
      "y": 4,
      "z": -1,
      "name": "Rock_Marble_Cobble"
    },
    {
      "x": 3,
      "y": 5,
      "z": -1,
      "name": "Rock_Marble_Cobble"
    },
    {
      "x": 3,
      "y": 6,
      "z": -1,
      "name": "Rock_Marble"
    },
    {
      "x": 3,
      "y": 7,
      "z": -1,
      "name": "Rock_Marble"
    },
    {
      "x": 3,
      "y": 8,
      "z": -1,
      "name": "Rock_Marble"
    },
    {
      "x": 3,
      "y": 9,
      "z": -1,
      "name": "Rock_Marble"
    },
    {
      "x": 3,
      "y": 2,
      "z": 0,
      "name": "Rock_Marble_Cobble"
    },
    {
      "x": 3,
      "y": 3,
      "z": 0,
      "name": "Rock_Marble_Cobble"
    },
    {
      "x": 3,
      "y": 4,
      "z": 0,
      "name": "Rock_Marble_Cobble"
    },
    {
      "x": 3,
      "y": 5,
      "z": 0,
      "name": "Rock_Marble_Cobble"
    },
    {
      "x": 3,
      "y": 6,
      "z": 0,
      "name": "Rock_Marble"
    },
    {
      "x": 3,
      "y": 7,
      "z": 0,
      "name": "Rock_Marble"
    },
    {
      "x": 3,
      "y": 8,
      "z": 0,
      "name": "Rock_Marble"
    },
    {
      "x": 3,
      "y": 9,
      "z": 0,
      "name": "Rock_Marble"
    },
    {
      "x": 3,
      "y": 10,
      "z": 0,
      "name": "Soil_Clay_White"
    },
    {
      "x": 3,
      "y": 11,
      "z": 0,
      "name": "Rock_Marble"
    },
    {
      "x": 3,
      "y": 1,
      "z": 1,
      "name": "Rock_Marble_Cobble"
    },
    {
      "x": 3,
      "y": 2,
      "z": 1,
      "name": "Rock_Marble_Cobble"
    },
    {
      "x": 3,
      "y": 3,
      "z": 1,
      "name": "Rock_Marble_Cobble"
    },
    {
      "x": 3,
      "y": 4,
      "z": 1,
      "name": "Rock_Marble_Cobble"
    },
    {
      "x": 3,
      "y": 5,
      "z": 1,
      "name": "Rock_Marble_Cobble"
    },
    {
      "x": 3,
      "y": 6,
      "z": 1,
      "name": "Rock_Marble"
    },
    {
      "x": 3,
      "y": 7,
      "z": 1,
      "name": "Rock_Marble"
    },
    {
      "x": 3,
      "y": 8,
      "z": 1,
      "name": "Rock_Marble"
    },
    {
      "x": 3,
      "y": 9,
      "z": 1,
      "name": "Rock_Marble"
    },
    {
      "x": 3,
      "y": 10,
      "z": 1,
      "name": "Soil_Clay_White"
    },
    {
      "x": 3,
      "y": 11,
      "z": 1,
      "name": "Rock_Marble"
    },
    {
      "x": 3,
      "y": 2,
      "z": 2,
      "name": "Rock_Marble_Cobble"
    },
    {
      "x": 3,
      "y": 3,
      "z": 2,
      "name": "Rock_Marble_Cobble"
    },
    {
      "x": 3,
      "y": 4,
      "z": 2,
      "name": "Rock_Marble_Cobble"
    },
    {
      "x": 3,
      "y": 5,
      "z": 2,
      "name": "Rock_Marble_Cobble"
    },
    {
      "x": 3,
      "y": 6,
      "z": 2,
      "name": "Rock_Marble"
    },
    {
      "x": 3,
      "y": 7,
      "z": 2,
      "name": "Rock_Marble"
    },
    {
      "x": 3,
      "y": 8,
      "z": 2,
      "name": "Rock_Marble"
    },
    {
      "x": 3,
      "y": 9,
      "z": 2,
      "name": "Rock_Marble"
    },
    {
      "x": 3,
      "y": 10,
      "z": 2,
      "name": "Soil_Clay_White"
    },
    {
      "x": 3,
      "y": 2,
      "z": 3,
      "name": "Rock_Marble_Cobble"
    },
    {
      "x": 3,
      "y": 3,
      "z": 3,
      "name": "Rock_Marble_Cobble"
    },
    {
      "x": 3,
      "y": 4,
      "z": 3,
      "name": "Rock_Marble_Cobble"
    },
    {
      "x": 3,
      "y": 5,
      "z": 3,
      "name": "Rock_Marble_Cobble"
    },
    {
      "x": 3,
      "y": 6,
      "z": 3,
      "name": "Rock_Marble"
    },
    {
      "x": 3,
      "y": 7,
      "z": 3,
      "name": "Rock_Marble"
    },
    {
      "x": 3,
      "y": 8,
      "z": 3,
      "name": "Rock_Marble"
    },
    {
      "x": 3,
      "y": 9,
      "z": 3,
      "name": "Rock_Marble"
    },
    {
      "x": 3,
      "y": 4,
      "z": 4,
      "name": "Rock_Marble_Cobble"
    },
    {
      "x": 3,
      "y": 5,
      "z": 4,
      "name": "Rock_Marble_Cobble"
    },
    {
      "x": 3,
      "y": 6,
      "z": 4,
      "name": "Rock_Marble"
    },
    {
      "x": 3,
      "y": 7,
      "z": 4,
      "name": "Rock_Marble"
    },
    {
      "x": 3,
      "y": 8,
      "z": 4,
      "name": "Rock_Marble"
    },
    {
      "x": 4,
      "y": 3,
      "z": -2,
      "name": "Rock_Marble_Cobble"
    },
    {
      "x": 4,
      "y": 4,
      "z": -2,
      "name": "Rock_Marble_Cobble"
    },
    {
      "x": 4,
      "y": 5,
      "z": -2,
      "name": "Rock_Marble_Cobble"
    },
    {
      "x": 4,
      "y": 3,
      "z": -1,
      "name": "Rock_Marble_Cobble"
    },
    {
      "x": 4,
      "y": 4,
      "z": -1,
      "name": "Rock_Marble_Cobble"
    },
    {
      "x": 4,
      "y": 5,
      "z": -1,
      "name": "Rock_Marble_Cobble"
    },
    {
      "x": 4,
      "y": 6,
      "z": -1,
      "name": "Rock_Marble"
    },
    {
      "x": 4,
      "y": 7,
      "z": -1,
      "name": "Rock_Marble"
    },
    {
      "x": 4,
      "y": 2,
      "z": 0,
      "name": "Rock_Marble_Cobble"
    },
    {
      "x": 4,
      "y": 3,
      "z": 0,
      "name": "Rock_Marble_Cobble"
    },
    {
      "x": 4,
      "y": 4,
      "z": 0,
      "name": "Rock_Marble_Cobble"
    },
    {
      "x": 4,
      "y": 5,
      "z": 0,
      "name": "Rock_Marble_Cobble"
    },
    {
      "x": 4,
      "y": 6,
      "z": 0,
      "name": "Rock_Marble"
    },
    {
      "x": 4,
      "y": 7,
      "z": 0,
      "name": "Rock_Marble"
    },
    {
      "x": 4,
      "y": 8,
      "z": 0,
      "name": "Rock_Marble"
    },
    {
      "x": 4,
      "y": 2,
      "z": 1,
      "name": "Rock_Marble_Cobble"
    },
    {
      "x": 4,
      "y": 3,
      "z": 1,
      "name": "Rock_Marble_Cobble"
    },
    {
      "x": 4,
      "y": 4,
      "z": 1,
      "name": "Rock_Marble_Cobble"
    },
    {
      "x": 4,
      "y": 5,
      "z": 1,
      "name": "Rock_Marble_Cobble"
    },
    {
      "x": 4,
      "y": 6,
      "z": 1,
      "name": "Rock_Marble"
    },
    {
      "x": 4,
      "y": 7,
      "z": 1,
      "name": "Rock_Marble"
    },
    {
      "x": 4,
      "y": 8,
      "z": 1,
      "name": "Rock_Marble"
    },
    {
      "x": 4,
      "y": 9,
      "z": 1,
      "name": "Rock_Marble"
    },
    {
      "x": 4,
      "y": 3,
      "z": 2,
      "name": "Rock_Marble_Cobble"
    },
    {
      "x": 4,
      "y": 4,
      "z": 2,
      "name": "Rock_Marble_Cobble"
    },
    {
      "x": 4,
      "y": 5,
      "z": 2,
      "name": "Rock_Marble_Cobble"
    },
    {
      "x": 4,
      "y": 6,
      "z": 2,
      "name": "Rock_Marble"
    },
    {
      "x": 4,
      "y": 7,
      "z": 2,
      "name": "Rock_Marble"
    },
    {
      "x": 4,
      "y": 8,
      "z": 2,
      "name": "Rock_Marble"
    },
    {
      "x": 4,
      "y": 4,
      "z": 3,
      "name": "Rock_Marble_Cobble"
    },
    {
      "x": 4,
      "y": 5,
      "z": 3,
      "name": "Rock_Marble_Cobble"
    },
    {
      "x": 4,
      "y": 6,
      "z": 3,
      "name": "Rock_Marble"
    },
    {
      "x": 4,
      "y": 7,
      "z": 3,
      "name": "Rock_Marble"
    },
    {
      "x": 5,
      "y": 4,
      "z": 0,
      "name": "Rock_Marble_Cobble"
    },
    {
      "x": 5,
      "y": 5,
      "z": 0,
      "name": "Rock_Marble_Cobble"
    },
    {
      "x": 5,
      "y": 4,
      "z": 1,
      "name": "Rock_Marble_Cobble"
    },
    {
      "x": 5,
      "y": 5,
      "z": 1,
      "name": "Rock_Marble_Cobble"
    },
    {
      "x": 5,
      "y": 6,
      "z": 1,
      "name": "Rock_Marble"
    },
    {
      "x": 5,
      "y": 5,
      "z": 2,
      "name": "Rock_Marble_Cobble"
    },
    {
      "x": 5,
      "y": 6,
      "z": 2,
      "name": "Rock_Marble"
    }
  ]
}