{
  "version": 8,
  "blockIdVersion": 11,
  "anchorX": 10,
  "anchorY": 9,
  "anchorZ": 10,
  "blocks": [
    {
      "x": -2,
      "y": -35,
      "z": -1,
      "name": "Rock_Sandstone_Brick"
    },
    {
      "x": -2,
      "y": -34,
      "z": -1,
      "name": "Rock_Sandstone_Brick"
    },
    {
      "x": -2,
      "y": -33,
      "z": -1,
      "name": "Rock_Sandstone_Brick"
    },
    {
      "x": -2,
      "y": -32,
      "z": -1,
      "name": "Rock_Sandstone_Brick"
    },
    {
      "x": -2,
      "y": -31,
      "z": -1,
      "name": "Rock_Sandstone"
    },
    {
      "x": -2,
      "y": -30,
      "z": -1,
      "name": "Rock_Sandstone_Brick"
    },
    {
      "x": -2,
      "y": -29,
      "z": -1,
      "name": "Rock_Sandstone_Brick"
    },
    {
      "x": -2,
      "y": -28,
      "z": -1,
      "name": "Rock_Sandstone_Brick"
    },
    {
      "x": -2,
      "y": -27,
      "z": -1,
      "name": "Rock_Sandstone"
    },
    {
      "x": -2,
      "y": -26,
      "z": -1,
      "name": "Rock_Sandstone_Brick"
    },
    {
      "x": -2,
      "y": -25,
      "z": -1,
      "name": "Rock_Sandstone_Brick"
    },
    {
      "x": -2,
      "y": -24,
      "z": -1,
      "name": "Rock_Sandstone_Brick"
    },
    {
      "x": -2,
      "y": -23,
      "z": -1,
      "name": "Rock_Sandstone_Brick"
    },
    {
      "x": -2,
      "y": -22,
      "z": -1,
      "name": "Rock_Sandstone"
    },
    {
      "x": -2,
      "y": -21,
      "z": -1,
      "name": "Rock_Sandstone_Brick"
    },
    {
      "x": -2,
      "y": -20,
      "z": -1,
      "name": "Rock_Sandstone_Brick"
    },
    {
      "x": -2,
      "y": -19,
      "z": -1,
      "name": "Rock_Sandstone_Brick"
    },
    {
      "x": -2,
      "y": -18,
      "z": -1,
      "name": "Rock_Sandstone"
    },
    {
      "x": -2,
      "y": -17,
      "z": -1,
      "name": "Rock_Sandstone_Brick"
    },
    {
      "x": -2,
      "y": -16,
      "z": -1,
      "name": "Rock_Sandstone_Brick",
      "rotation": 3
    },
    {
      "x": -2,
      "y": -15,
      "z": -1,
      "name": "Rock_Sandstone_Brick",
      "rotation": 3
    },
    {
      "x": -2,
      "y": -14,
      "z": -1,
      "name": "Rock_Sandstone_Brick",
      "rotation": 3
    },
    {
      "x": -2,
      "y": -13,
      "z": -1,
      "name": "Rock_Sandstone_Brick",
      "rotation": 3
    },
    {
      "x": -2,
      "y": -12,
      "z": -1,
      "name": "Rock_Sandstone",
      "rotation": 3
    },
    {
      "x": -2,
      "y": -11,
      "z": -1,
      "name": "Rock_Sandstone_Brick",
      "rotation": 3
    },
    {
      "x": -2,
      "y": -10,
      "z": -1,
      "name": "Rock_Sandstone_Brick",
      "rotation": 3
    },
    {
      "x": -2,
      "y": -9,
      "z": -1,
      "name": "Rock_Sandstone_Brick",
      "rotation": 3
    },
    {
      "x": -2,
      "y": -8,
      "z": -1,
      "name": "Rock_Sandstone_Brick",
      "rotation": 3
    },
    {
      "x": -2,
      "y": -7,
      "z": -1,
      "name": "Rock_Sandstone_Brick",
      "rotation": 3
    },
    {
      "x": -2,
      "y": -6,
      "z": -1,
      "name": "Rock_Sandstone",
      "rotation": 3
    },
    {
      "x": -2,
      "y": -5,
      "z": -1,
      "name": "Rock_Sandstone_Brick",
      "rotation": 3
    },
    {
      "x": -2,
      "y": -4,
      "z": -1,
      "name": "Rock_Sandstone_Brick",
      "rotation": 3
    },
    {
      "x": -2,
      "y": -3,
      "z": -1,
      "name": "Rock_Sandstone_Brick",
      "rotation": 3
    },
    {
      "x": -2,
      "y": -2,
      "z": -1,
      "name": "Rock_Sandstone_Brick",
      "rotation": 3
    },
    {
      "x": -2,
      "y": -1,
      "z": -1,
      "name": "Rock_Sandstone_Brick",
      "rotation": 3
    },
    {
      "x": -2,
      "y": 0,
      "z": -1,
      "name": "Rock_Sandstone",
      "rotation": 3
    },
    {
      "x": -2,
      "y": 1,
      "z": -1,
      "name": "Rock_Sandstone_Brick",
      "rotation": 3
    },
    {
      "x": -2,
      "y": 2,
      "z": -1,
      "name": "Rock_Sandstone_Brick",
      "rotation": 3
    },
    {
      "x": -2,
      "y": 3,
      "z": -1,
      "name": "Rock_Sandstone_Brick",
      "rotation": 3
    },
    {
      "x": -2,
      "y": 4,
      "z": -1,
      "name": "Rock_Sandstone_Brick",
      "rotation": 3
    },
    {
      "x": -2,
      "y": 5,
      "z": -1,
      "name": "Rock_Sandstone_Brick",
      "rotation": 3
    },
    {
      "x": -2,
      "y": 6,
      "z": -1,
      "name": "Rock_Sandstone_Brick",
      "rotation": 3
    },
    {
      "x": -2,
      "y": 7,
      "z": -1,
      "name": "Rock_Sandstone_Brick",
      "rotation": 3
    },
    {
      "x": -2,
      "y": 8,
      "z": -1,
      "name": "Rock_Sandstone_Brick",
      "rotation": 3
    },
    {
      "x": -2,
      "y": 9,
      "z": -1,
      "name": "Rock_Sandstone_Brick"
    },
    {
      "x": -2,
      "y": -35,
      "z": 0,
      "name": "Rock_Sandstone_Cobble"
    },
    {
      "x": -2,
      "y": -34,
      "z": 0,
      "name": "Rock_Sandstone_Brick"
    },
    {
      "x": -2,
      "y": -33,
      "z": 0,
      "name": "Rock_Sandstone_Brick"
    },
    {
      "x": -2,
      "y": -32,
      "z": 0,
      "name": "Rock_Sandstone_Brick"
    },
    {
      "x": -2,
      "y": -31,
      "z": 0,
      "name": "Rock_Sandstone_Brick"
    },
    {
      "x": -2,
      "y": -30,
      "z": 0,
      "name": "Rock_Sandstone_Brick"
    },
    {
      "x": -2,
      "y": -29,
      "z": 0,
      "name": "Rock_Sandstone"
    },
    {
      "x": -2,
      "y": -28,
      "z": 0,
      "name": "Rock_Sandstone_Cobble"
    },
    {
      "x": -2,
      "y": -27,
      "z": 0,
      "name": "Rock_Sandstone_Brick"
    },
    {
      "x": -2,
      "y": -15,
      "z": 0,
      "name": "Rock_Sandstone_Brick",
      "rotation": 3
    },
    {
      "x": -2,
      "y": -14,
      "z": 0,
      "name": "Rock_Sandstone_Brick",
      "rotation": 3
    },
    {
      "x": -2,
      "y": -13,
      "z": 0,
      "name": "Rock_Sandstone_Brick",
      "rotation": 3
    },
    {
      "x": -2,
      "y": -12,
      "z": 0,
      "name": "Rock_Sandstone_Brick",
      "rotation": 3
    },
    {
      "x": -2,
      "y": -11,
      "z": 0,
      "name": "Rock_Sandstone",
      "rotation": 3
    },
    {
      "x": -2,
      "y": -10,
      "z": 0,
      "name": "Rock_Sandstone_Brick",
      "rotation": 3
    },
    {
      "x": -2,
      "y": -9,
      "z": 0,
      "name": "Rock_Sandstone_Brick",
      "rotation": 3
    },
    {
      "x": -2,
      "y": -8,
      "z": 0,
      "name": "Rock_Sandstone",
      "rotation": 3
    },
    {
      "x": -2,
      "y": -7,
      "z": 0,
      "name": "Rock_Sandstone_Brick",
      "rotation": 3
    },
    {
      "x": -2,
      "y": -6,
      "z": 0,
      "name": "Rock_Sandstone_Brick",
      "rotation": 3
    },
    {
      "x": -2,
      "y": -5,
      "z": 0,
      "name": "Rock_Sandstone",
      "rotation": 3
    },
    {
      "x": -2,
      "y": -4,
      "z": 0,
      "name": "Rock_Sandstone_Brick",
      "rotation": 3
    },
    {
      "x": -2,
      "y": -3,
      "z": 0,
      "name": "Rock_Sandstone_Cobble",
      "rotation": 3
    },
    {
      "x": -2,
      "y": -2,
      "z": 0,
      "name": "Rock_Sandstone_Brick",
      "rotation": 3
    },
    {
      "x": -2,
      "y": -1,
      "z": 0,
      "name": "Rock_Sandstone_Cobble",
      "rotation": 3
    },
    {
      "x": -2,
      "y": 0,
      "z": 0,
      "name": "Rock_Sandstone_Brick",
      "rotation": 3
    },
    {
      "x": -2,
      "y": 1,
      "z": 0,
      "name": "Rock_Sandstone_Brick",
      "rotation": 3
    },
    {
      "x": -2,
      "y": 2,
      "z": 0,
      "name": "Rock_Sandstone_Brick",
      "rotation": 3
    },
    {
      "x": -2,
      "y": 3,
      "z": 0,
      "name": "Rock_Sandstone_Brick",
      "rotation": 3
    },
    {
      "x": -2,
      "y": 4,
      "z": 0,
      "name": "Rock_Sandstone_Brick",
      "rotation": 3
    },
    {
      "x": -2,
      "y": 5,
      "z": 0,
      "name": "Rock_Sandstone_Brick",
      "rotation": 3
    },
    {
      "x": -2,
      "y": 6,
      "z": 0,
      "name": "Rock_Sandstone_Cobble",
      "rotation": 3
    },
    {
      "x": -2,
      "y": 7,
      "z": 0,
      "name": "Rock_Sandstone_Brick",
      "rotation": 3
    },
    {
      "x": -2,
      "y": 8,
      "z": 0,
      "name": "Rock_Sandstone_Brick",
      "rotation": 3
    },
    {
      "x": -2,
      "y": 9,
      "z": 0,
      "name": "Rock_Sandstone_Brick"
    },
    {
      "x": -2,
      "y": -35,
      "z": 1,
      "name": "Rock_Sandstone_Brick"
    },
    {
      "x": -2,
      "y": -34,
      "z": 1,
      "name": "Rock_Sandstone_Brick"
    },
    {
      "x": -2,
      "y": -33,
      "z": 1,
      "name": "Rock_Sandstone_Brick"
    },
    {
      "x": -2,
      "y": -32,
      "z": 1,
      "name": "Rock_Sandstone"
    },
    {
      "x": -2,
      "y": -31,
      "z": 1,
      "name": "Rock_Sandstone_Cobble"
    },
    {
      "x": -2,
      "y": -30,
      "z": 1,
      "name": "Rock_Sandstone_Brick"
    },
    {
      "x": -2,
      "y": -29,
      "z": 1,
      "name": "Rock_Sandstone_Brick"
    },
    {
      "x": -2,
      "y": -28,
      "z": 1,
      "name": "Rock_Sandstone"
    },
    {
      "x": -2,
      "y": -12,
      "z": 1,
      "name": "Rock_Sandstone_Brick",
      "rotation": 3
    },
    {
      "x": -2,
      "y": -11,
      "z": 1,
      "name": "Rock_Sandstone_Cobble",
      "rotation": 3
    },
    {
      "x": -2,
      "y": -10,
      "z": 1,
      "name": "Rock_Sandstone_Brick",
      "rotation": 3
    },
    {
      "x": -2,
      "y": -9,
      "z": 1,
      "name": "Rock_Sandstone_Brick",
      "rotation": 3
    },
    {
      "x": -2,
      "y": -8,
      "z": 1,
      "name": "Rock_Sandstone",
      "rotation": 3
    },
    {
      "x": -2,
      "y": -7,
      "z": 1,
      "name": "Rock_Sandstone_Brick",
      "rotation": 3
    },
    {
      "x": -2,
      "y": -6,
      "z": 1,
      "name": "Rock_Sandstone_Brick",
      "rotation": 3
    },
    {
      "x": -2,
      "y": -5,
      "z": 1,
      "name": "Rock_Sandstone_Cobble",
      "rotation": 3
    },
    {
      "x": -2,
      "y": -4,
      "z": 1,
      "name": "Rock_Sandstone",
      "rotation": 3
    },
    {
      "x": -2,
      "y": -3,
      "z": 1,
      "name": "Rock_Sandstone_Brick",
      "rotation": 3
    },
    {
      "x": -2,
      "y": -2,
      "z": 1,
      "name": "Rock_Sandstone_Cobble",
      "rotation": 3
    },
    {
      "x": -2,
      "y": -1,
      "z": 1,
      "name": "Rock_Sandstone_Cobble",
      "rotation": 3
    },
    {
      "x": -2,
      "y": 0,
      "z": 1,
      "name": "Rock_Sandstone_Brick",
      "rotation": 3
    },
    {
      "x": -2,
      "y": 1,
      "z": 1,
      "name": "Rock_Sandstone",
      "rotation": 3
    },
    {
      "x": -2,
      "y": 2,
      "z": 1,
      "name": "Rock_Sandstone_Brick",
      "rotation": 3
    },
    {
      "x": -2,
      "y": 3,
      "z": 1,
      "name": "Rock_Sandstone_Cobble",
      "rotation": 3
    },
    {
      "x": -2,
      "y": 4,
      "z": 1,
      "name": "Rock_Sandstone_Brick",
      "rotation": 3
    },
    {
      "x": -2,
      "y": 5,
      "z": 1,
      "name": "Rock_Sandstone",
      "rotation": 3
    },
    {
      "x": -2,
      "y": 6,
      "z": 1,
      "name": "Rock_Sandstone_Cobble",
      "rotation": 3
    },
    {
      "x": -2,
      "y": 7,
      "z": 1,
      "name": "Rock_Sandstone_Brick",
      "rotation": 3
    },
    {
      "x": -2,
      "y": 8,
      "z": 1,
      "name": "Rock_Sandstone_Brick",
      "rotation": 3
    },
    {
      "x": -2,
      "y": 9,
      "z": 1,
      "name": "Rock_Sandstone_Brick"
    },
    {
      "x": -2,
      "y": 4,
      "z": 2,
      "name": "Rock_Sandstone_Brick_Stairs",
      "rotation": 10
    },
    {
      "x": -2,
      "y": 5,
      "z": 2,
      "name": "Rock_Sandstone_Brick"
    },
    {
      "x": -2,
      "y": 6,
      "z": 2,
      "name": "Rock_Sandstone_Brick"
    },
    {
      "x": -2,
      "y": 7,
      "z": 2,
      "name": "Rock_Sandstone_Brick",
      "rotation": 2
    },
    {
      "x": -2,
      "y": 8,
      "z": 2,
      "name": "Rock_Sandstone_Brick"
    },
    {
      "x": -2,
      "y": 9,
      "z": 2,
      "name": "Rock_Sandstone_Brick"
    },
    {
      "x": -2,
      "y": 5,
      "z": 3,
      "name": "Rock_Sandstone_Brick_Stairs",
      "rotation": 10
    },
    {
      "x": -2,
      "y": 6,
      "z": 3,
      "name": "Rock_Sandstone_Brick"
    },
    {
      "x": -2,
      "y": 7,
      "z": 3,
      "name": "Rock_Sandstone_Brick",
      "rotation": 2
    },
    {
      "x": -2,
      "y": 8,
      "z": 3,
      "name": "Rock_Sandstone_Brick"
    },
    {
      "x": -2,
      "y": 9,
      "z": 3,
      "name": "Rock_Sandstone_Brick"
    },
    {
      "x": -2,
      "y": 6,
      "z": 4,
      "name": "Rock_Sandstone_Brick"
    },
    {
      "x": -2,
      "y": 7,
      "z": 4,
      "name": "Rock_Sandstone_Brick"
    },
    {
      "x": -2,
      "y": 8,
      "z": 4,
      "name": "Rock_Sandstone_Brick"
    },
    {
      "x": -2,
      "y": 9,
      "z": 4,
      "name": "Rock_Sandstone_Brick"
    },
    {
      "x": -2,
      "y": 6,
      "z": 5,
      "name": "Rock_Sandstone_Brick_Half",
      "rotation": 8
    },
    {
      "x": -2,
      "y": 7,
      "z": 5,
      "name": "Rock_Sandstone_Brick"
    },
    {
      "x": -2,
      "y": 8,
      "z": 5,
      "name": "Rock_Sandstone_Brick"
    },
    {
      "x": -2,
      "y": 9,
      "z": 5,
      "name": "Rock_Sandstone_Brick"
    },
    {
      "x": -2,
      "y": 7,
      "z": 6,
      "name": "Rock_Sandstone_Brick"
    },
    {
      "x": -2,
      "y": 8,
      "z": 6,
      "name": "Rock_Sandstone_Brick"
    },
    {
      "x": -2,
      "y": 9,
      "z": 6,
      "name": "Rock_Sandstone_Brick"
    },
    {
      "x": -2,
      "y": 7,
      "z": 7,
      "name": "Rock_Sandstone_Brick_Stairs",
      "rotation": 10
    },
    {
      "x": -2,
      "y": 8,
      "z": 7,
      "name": "Rock_Sandstone_Brick",
      "rotation": 3
    },
    {
      "x": -2,
      "y": 9,
      "z": 7,
      "name": "Rock_Sandstone_Brick",
      "rotation": 3
    },
    {
      "x": -2,
      "y": 7,
      "z": 8,
      "name": "Rock_Sandstone_Brick_Half",
      "rotation": 11
    },
    {
      "x": -2,
      "y": 8,
      "z": 8,
      "name": "Rock_Sandstone_Brick",
      "rotation": 3
    },
    {
      "x": -2,
      "y": 9,
      "z": 8,
      "name": "Rock_Sandstone_Brick",
      "rotation": 3
    },
    {
      "x": -2,
      "y": 8,
      "z": 9,
      "name": "Rock_Sandstone_Brick"
    },
    {
      "x": -2,
      "y": 9,
      "z": 9,
      "name": "Rock_Sandstone_Brick",
      "rotation": 3
    },
    {
      "x": -2,
      "y": 8,
      "z": 10,
      "name": "Rock_Sandstone_Brick"
    },
    {
      "x": -2,
      "y": 9,
      "z": 10,
      "name": "Rock_Sandstone_Brick",
      "rotation": 3
    },
    {
      "x": -2,
      "y": 8,
      "z": 11,
      "name": "Rock_Sandstone_Brick"
    },
    {
      "x": -2,
      "y": 9,
      "z": 11,
      "name": "Rock_Sandstone_Brick",
      "rotation": 3
    },
    {
      "x": -2,
      "y": 8,
      "z": 12,
      "name": "Rock_Sandstone_Brick"
    },
    {
      "x": -2,
      "y": 9,
      "z": 12,
      "name": "Rock_Sandstone_Brick",
      "rotation": 3
    },
    {
      "x": -2,
      "y": 7,
      "z": 13,
      "name": "Rock_Sandstone_Brick_Half",
      "rotation": 11
    },
    {
      "x": -2,
      "y": 8,
      "z": 13,
      "name": "Rock_Sandstone_Brick",
      "rotation": 3
    },
    {
      "x": -2,
      "y": 9,
      "z": 13,
      "name": "Rock_Sandstone_Brick",
      "rotation": 3
    },
    {
      "x": -2,
      "y": 7,
      "z": 14,
      "name": "Rock_Sandstone_Brick_Stairs",
      "rotation": 8
    },
    {
      "x": -2,
      "y": 8,
      "z": 14,
      "name": "Rock_Sandstone_Brick",
      "rotation": 3
    },
    {
      "x": -2,
      "y": 9,
      "z": 14,
      "name": "Rock_Sandstone_Brick",
      "rotation": 3
    },
    {
      "x": -2,
      "y": 7,
      "z": 15,
      "name": "Rock_Sandstone_Brick"
    },
    {
      "x": -2,
      "y": 8,
      "z": 15,
      "name": "Rock_Sandstone_Brick"
    },
    {
      "x": -2,
      "y": 9,
      "z": 15,
      "name": "Rock_Sandstone_Brick"
    },
    {
      "x": -2,
      "y": 6,
      "z": 16,
      "name": "Rock_Sandstone_Brick_Half",
      "rotation": 8
    },
    {
      "x": -2,
      "y": 7,
      "z": 16,
      "name": "Rock_Sandstone_Brick"
    },
    {
      "x": -2,
      "y": 8,
      "z": 16,
      "name": "Rock_Sandstone_Brick"
    },
    {
      "x": -2,
      "y": 9,
      "z": 16,
      "name": "Rock_Sandstone_Brick"
    },
    {
      "x": -2,
      "y": 6,
      "z": 17,
      "name": "Rock_Sandstone_Brick"
    },
    {
      "x": -2,
      "y": 7,
      "z": 17,
      "name": "Rock_Sandstone_Brick"
    },
    {
      "x": -2,
      "y": 8,
      "z": 17,
      "name": "Rock_Sandstone_Brick"
    },
    {
      "x": -2,
      "y": 9,
      "z": 17,
      "name": "Rock_Sandstone_Brick"
    },
    {
      "x": -2,
      "y": 5,
      "z": 18,
      "name": "Rock_Sandstone_Brick_Stairs",
      "rotation": 8
    },
    {
      "x": -2,
      "y": 6,
      "z": 18,
      "name": "Rock_Sandstone_Brick"
    },
    {
      "x": -2,
      "y": 7,
      "z": 18,
      "name": "Rock_Sandstone_Brick"
    },
    {
      "x": -2,
      "y": 8,
      "z": 18,
      "name": "Rock_Sandstone_Brick"
    },
    {
      "x": -2,
      "y": 9,
      "z": 18,
      "name": "Rock_Sandstone_Brick"
    },
    {
      "x": -2,
      "y": 4,
      "z": 19,
      "name": "Rock_Sandstone_Brick_Stairs",
      "rotation": 8
    },
    {
      "x": -2,
      "y": 5,
      "z": 19,
      "name": "Rock_Sandstone_Brick"
    },
    {
      "x": -2,
      "y": 6,
      "z": 19,
      "name": "Rock_Sandstone"
    },
    {
      "x": -2,
      "y": 7,
      "z": 19,
      "name": "Rock_Sandstone_Brick"
    },
    {
      "x": -2,
      "y": 8,
      "z": 19,
      "name": "Rock_Sandstone_Brick"
    },
    {
      "x": -2,
      "y": 9,
      "z": 19,
      "name": "Rock_Sandstone_Brick"
    },
    {
      "x": -2,
      "y": -35,
      "z": 20,
      "name": "Rock_Sandstone_Brick"
    },
    {
      "x": -2,
      "y": -34,
      "z": 20,
      "name": "Rock_Sandstone_Brick"
    },
    {
      "x": -2,
      "y": -33,
      "z": 20,
      "name": "Rock_Sandstone_Cobble"
    },
    {
      "x": -2,
      "y": -32,
      "z": 20,
      "name": "Rock_Sandstone_Brick"
    },
    {
      "x": -2,
      "y": -21,
      "z": 20,
      "name": "Rock_Sandstone_Brick"
    },
    {
      "x": -2,
      "y": -20,
      "z": 20,
      "name": "Rock_Sandstone_Brick"
    },
    {
      "x": -2,
      "y": -19,
      "z": 20,
      "name": "Rock_Sandstone_Brick"
    },
    {
      "x": -2,
      "y": -18,
      "z": 20,
      "name": "Rock_Sandstone_Cobble"
    },
    {
      "x": -2,
      "y": -17,
      "z": 20,
      "name": "Rock_Sandstone_Brick"
    },
    {
      "x": -2,
      "y": -16,
      "z": 20,
      "name": "Rock_Sandstone_Brick"
    },
    {
      "x": -2,
      "y": -15,
      "z": 20,
      "name": "Rock_Sandstone",
      "rotation": 1
    },
    {
      "x": -2,
      "y": -14,
      "z": 20,
      "name": "Rock_Sandstone_Brick",
      "rotation": 1
    },
    {
      "x": -2,
      "y": -13,
      "z": 20,
      "name": "Rock_Sandstone",
      "rotation": 1
    },
    {
      "x": -2,
      "y": -12,
      "z": 20,
      "name": "Rock_Sandstone_Brick",
      "rotation": 1
    },
    {
      "x": -2,
      "y": -11,
      "z": 20,
      "name": "Rock_Sandstone",
      "rotation": 1
    },
    {
      "x": -2,
      "y": -10,
      "z": 20,
      "name": "Rock_Sandstone",
      "rotation": 1
    },
    {
      "x": -2,
      "y": -9,
      "z": 20,
      "name": "Rock_Sandstone_Brick",
      "rotation": 1
    },
    {
      "x": -2,
      "y": -8,
      "z": 20,
      "name": "Rock_Sandstone_Brick",
      "rotation": 1
    },
    {
      "x": -2,
      "y": -7,
      "z": 20,
      "name": "Rock_Sandstone_Brick",
      "rotation": 1
    },
    {
      "x": -2,
      "y": -6,
      "z": 20,
      "name": "Rock_Sandstone_Cobble",
      "rotation": 1
    },
    {
      "x": -2,
      "y": -5,
      "z": 20,
      "name": "Rock_Sandstone_Brick",
      "rotation": 1
    },
    {
      "x": -2,
      "y": -4,
      "z": 20,
      "name": "Rock_Sandstone_Brick",
      "rotation": 1
    },
    {
      "x": -2,
      "y": -3,
      "z": 20,
      "name": "Rock_Sandstone_Cobble",
      "rotation": 1
    },
    {
      "x": -2,
      "y": -2,
      "z": 20,
      "name": "Rock_Sandstone_Brick",
      "rotation": 1
    },
    {
      "x": -2,
      "y": -1,
      "z": 20,
      "name": "Rock_Sandstone_Cobble",
      "rotation": 1
    },
    {
      "x": -2,
      "y": 0,
      "z": 20,
      "name": "Rock_Sandstone_Brick",
      "rotation": 1
    },
    {
      "x": -2,
      "y": 1,
      "z": 20,
      "name": "Rock_Sandstone_Brick",
      "rotation": 1
    },
    {
      "x": -2,
      "y": 2,
      "z": 20,
      "name": "Rock_Sandstone_Brick",
      "rotation": 1
    },
    {
      "x": -2,
      "y": 3,
      "z": 20,
      "name": "Rock_Sandstone_Brick",
      "rotation": 1
    },
    {
      "x": -2,
      "y": 4,
      "z": 20,
      "name": "Rock_Sandstone_Brick",
      "rotation": 1
    },
    {
      "x": -2,
      "y": 5,
      "z": 20,
      "name": "Rock_Sandstone_Brick",
      "rotation": 1
    },
    {
      "x": -2,
      "y": 6,
      "z": 20,
      "name": "Rock_Sandstone",
      "rotation": 1
    },
    {
      "x": -2,
      "y": 7,
      "z": 20,
      "name": "Rock_Sandstone_Brick",
      "rotation": 1
    },
    {
      "x": -2,
      "y": 8,
      "z": 20,
      "name": "Rock_Sandstone_Brick",
      "rotation": 1
    },
    {
      "x": -2,
      "y": 9,
      "z": 20,
      "name": "Rock_Sandstone_Brick"
    },
    {
      "x": -2,
      "y": -35,
      "z": 21,
      "name": "Rock_Sandstone_Brick"
    },
    {
      "x": -2,
      "y": -34,
      "z": 21,
      "name": "Rock_Sandstone_Brick"
    },
    {
      "x": -2,
      "y": -33,
      "z": 21,
      "name": "Rock_Sandstone_Brick"
    },
    {
      "x": -2,
      "y": -32,
      "z": 21,
      "name": "Rock_Sandstone_Brick"
    },
    {
      "x": -2,
      "y": -31,
      "z": 21,
      "name": "Rock_Sandstone_Brick"
    },
    {
      "x": -2,
      "y": -30,
      "z": 21,
      "name": "Rock_Sandstone_Brick"
    },
    {
      "x": -2,
      "y": -29,
      "z": 21,
      "name": "Rock_Sandstone_Brick"
    },
    {
      "x": -2,
      "y": -24,
      "z": 21,
      "name": "Rock_Sandstone_Brick"
    },
    {
      "x": -2,
      "y": -23,
      "z": 21,
      "name": "Rock_Sandstone_Brick"
    },
    {
      "x": -2,
      "y": -22,
      "z": 21,
      "name": "Rock_Sandstone_Brick"
    },
    {
      "x": -2,
      "y": -21,
      "z": 21,
      "name": "Rock_Sandstone_Brick"
    },
    {
      "x": -2,
      "y": -20,
      "z": 21,
      "name": "Rock_Sandstone_Brick"
    },
    {
      "x": -2,
      "y": -19,
      "z": 21,
      "name": "Rock_Sandstone"
    },
    {
      "x": -2,
      "y": -18,
      "z": 21,
      "name": "Rock_Sandstone_Brick"
    },
    {
      "x": -2,
      "y": -17,
      "z": 21,
      "name": "Rock_Sandstone_Cobble"
    },
    {
      "x": -2,
      "y": -16,
      "z": 21,
      "name": "Rock_Sandstone_Brick"
    },
    {
      "x": -2,
      "y": -15,
      "z": 21,
      "name": "Rock_Sandstone_Brick",
      "rotation": 1
    },
    {
      "x": -2,
      "y": -14,
      "z": 21,
      "name": "Rock_Sandstone_Brick",
      "rotation": 1
    },
    {
      "x": -2,
      "y": -13,
      "z": 21,
      "name": "Rock_Sandstone_Brick",
      "rotation": 1
    },
    {
      "x": -2,
      "y": -12,
      "z": 21,
      "name": "Rock_Sandstone_Brick",
      "rotation": 1
    },
    {
      "x": -2,
      "y": -11,
      "z": 21,
      "name": "Rock_Sandstone_Brick",
      "rotation": 1
    },
    {
      "x": -2,
      "y": -10,
      "z": 21,
      "name": "Rock_Sandstone",
      "rotation": 1
    },
    {
      "x": -2,
      "y": -9,
      "z": 21,
      "name": "Rock_Sandstone_Cobble",
      "rotation": 1
    },
    {
      "x": -2,
      "y": -8,
      "z": 21,
      "name": "Rock_Sandstone_Cobble",
      "rotation": 1
    },
    {
      "x": -2,
      "y": -7,
      "z": 21,
      "name": "Rock_Sandstone_Brick",
      "rotation": 1
    },
    {
      "x": -2,
      "y": -6,
      "z": 21,
      "name": "Rock_Sandstone_Cobble",
      "rotation": 1
    },
    {
      "x": -2,
      "y": -5,
      "z": 21,
      "name": "Rock_Sandstone_Brick",
      "rotation": 1
    },
    {
      "x": -2,
      "y": -4,
      "z": 21,
      "name": "Rock_Sandstone_Brick",
      "rotation": 1
    },
    {
      "x": -2,
      "y": -3,
      "z": 21,
      "name": "Rock_Sandstone",
      "rotation": 1
    },
    {
      "x": -2,
      "y": -2,
      "z": 21,
      "name": "Rock_Sandstone_Brick",
      "rotation": 1
    },
    {
      "x": -2,
      "y": -1,
      "z": 21,
      "name": "Rock_Sandstone_Brick",
      "rotation": 1
    },
    {
      "x": -2,
      "y": 0,
      "z": 21,
      "name": "Rock_Sandstone_Cobble",
      "rotation": 1
    },
    {
      "x": -2,
      "y": 1,
      "z": 21,
      "name": "Rock_Sandstone_Brick",
      "rotation": 1
    },
    {
      "x": -2,
      "y": 2,
      "z": 21,
      "name": "Rock_Sandstone_Brick",
      "rotation": 1
    },
    {
      "x": -2,
      "y": 3,
      "z": 21,
      "name": "Rock_Sandstone",
      "rotation": 1
    },
    {
      "x": -2,
      "y": 4,
      "z": 21,
      "name": "Rock_Sandstone_Cobble",
      "rotation": 1
    },
    {
      "x": -2,
      "y": 5,
      "z": 21,
      "name": "Rock_Sandstone_Brick",
      "rotation": 1
    },
    {
      "x": -2,
      "y": 6,
      "z": 21,
      "name": "Rock_Sandstone_Brick",
      "rotation": 1
    },
    {
      "x": -2,
      "y": 7,
      "z": 21,
      "name": "Rock_Sandstone_Brick",
      "rotation": 1
    },
    {
      "x": -2,
      "y": 8,
      "z": 21,
      "name": "Rock_Sandstone_Brick",
      "rotation": 1
    },
    {
      "x": -2,
      "y": 9,
      "z": 21,
      "name": "Rock_Sandstone_Brick"
    },
    {
      "x": -2,
      "y": -35,
      "z": 22,
      "name": "Rock_Sandstone"
    },
    {
      "x": -2,
      "y": -34,
      "z": 22,
      "name": "Rock_Sandstone_Cobble"
    },
    {
      "x": -2,
      "y": -33,
      "z": 22,
      "name": "Rock_Sandstone_Brick"
    },
    {
      "x": -2,
      "y": -32,
      "z": 22,
      "name": "Rock_Sandstone_Brick"
    },
    {
      "x": -2,
      "y": -31,
      "z": 22,
      "name": "Rock_Sandstone_Brick"
    },
    {
      "x": -2,
      "y": -30,
      "z": 22,
      "name": "Rock_Sandstone_Brick"
    },
    {
      "x": -2,
      "y": -29,
      "z": 22,
      "name": "Rock_Sandstone_Brick"
    },
    {
      "x": -2,
      "y": -28,
      "z": 22,
      "name": "Rock_Sandstone_Cobble"
    },
    {
      "x": -2,
      "y": -27,
      "z": 22,
      "name": "Rock_Sandstone_Brick"
    },
    {
      "x": -2,
      "y": -26,
      "z": 22,
      "name": "Rock_Sandstone"
    },
    {
      "x": -2,
      "y": -25,
      "z": 22,
      "name": "Rock_Sandstone_Cobble"
    },
    {
      "x": -2,
      "y": -24,
      "z": 22,
      "name": "Rock_Sandstone_Brick"
    },
    {
      "x": -2,
      "y": -23,
      "z": 22,
      "name": "Rock_Sandstone_Brick"
    },
    {
      "x": -2,
      "y": -22,
      "z": 22,
      "name": "Rock_Sandstone_Brick"
    },
    {
      "x": -2,
      "y": -21,
      "z": 22,
      "name": "Rock_Sandstone_Brick"
    },
    {
      "x": -2,
      "y": -20,
      "z": 22,
      "name": "Rock_Sandstone_Brick"
    },
    {
      "x": -2,
      "y": -19,
      "z": 22,
      "name": "Rock_Sandstone_Cobble"
    },
    {
      "x": -2,
      "y": -18,
      "z": 22,
      "name": "Rock_Sandstone_Brick"
    },
    {
      "x": -2,
      "y": -17,
      "z": 22,
      "name": "Rock_Sandstone_Brick"
    },
    {
      "x": -2,
      "y": -16,
      "z": 22,
      "name": "Rock_Sandstone_Cobble"
    },
    {
      "x": -2,
      "y": -15,
      "z": 22,
      "name": "Rock_Sandstone_Brick",
      "rotation": 1
    },
    {
      "x": -2,
      "y": -14,
      "z": 22,
      "name": "Rock_Sandstone_Brick",
      "rotation": 1
    },
    {
      "x": -2,
      "y": -13,
      "z": 22,
      "name": "Rock_Sandstone_Brick",
      "rotation": 1
    },
    {
      "x": -2,
      "y": -12,
      "z": 22,
      "name": "Rock_Sandstone",
      "rotation": 1
    },
    {
      "x": -2,
      "y": -11,
      "z": 22,
      "name": "Rock_Sandstone_Brick",
      "rotation": 1
    },
    {
      "x": -2,
      "y": -10,
      "z": 22,
      "name": "Rock_Sandstone_Brick",
      "rotation": 1
    },
    {
      "x": -2,
      "y": -9,
      "z": 22,
      "name": "Rock_Sandstone",
      "rotation": 1
    },
    {
      "x": -2,
      "y": -8,
      "z": 22,
      "name": "Rock_Sandstone_Brick",
      "rotation": 1
    },
    {
      "x": -2,
      "y": -7,
      "z": 22,
      "name": "Rock_Sandstone",
      "rotation": 1
    },
    {
      "x": -2,
      "y": -6,
      "z": 22,
      "name": "Rock_Sandstone_Brick",
      "rotation": 1
    },
    {
      "x": -2,
      "y": -5,
      "z": 22,
      "name": "Rock_Sandstone",
      "rotation": 1
    },
    {
      "x": -2,
      "y": -4,
      "z": 22,
      "name": "Rock_Sandstone_Brick",
      "rotation": 1
    },
    {
      "x": -2,
      "y": -3,
      "z": 22,
      "name": "Rock_Sandstone_Brick",
      "rotation": 1
    },
    {
      "x": -2,
      "y": -2,
      "z": 22,
      "name": "Rock_Sandstone_Brick",
      "rotation": 1
    },
    {
      "x": -2,
      "y": -1,
      "z": 22,
      "name": "Rock_Sandstone_Brick",
      "rotation": 1
    },
    {
      "x": -2,
      "y": 0,
      "z": 22,
      "name": "Rock_Sandstone",
      "rotation": 1
    },
    {
      "x": -2,
      "y": 1,
      "z": 22,
      "name": "Rock_Sandstone_Brick",
      "rotation": 1
    },
    {
      "x": -2,
      "y": 2,
      "z": 22,
      "name": "Rock_Sandstone_Brick",
      "rotation": 1
    },
    {
      "x": -2,
      "y": 3,
      "z": 22,
      "name": "Rock_Sandstone_Brick",
      "rotation": 1
    },
    {
      "x": -2,
      "y": 4,
      "z": 22,
      "name": "Rock_Sandstone_Brick",
      "rotation": 1
    },
    {
      "x": -2,
      "y": 5,
      "z": 22,
      "name": "Rock_Sandstone_Brick",
      "rotation": 1
    },
    {
      "x": -2,
      "y": 6,
      "z": 22,
      "name": "Rock_Sandstone_Brick",
      "rotation": 1
    },
    {
      "x": -2,
      "y": 7,
      "z": 22,
      "name": "Rock_Sandstone_Brick",
      "rotation": 1
    },
    {
      "x": -2,
      "y": 8,
      "z": 22,
      "name": "Rock_Sandstone_Brick",
      "rotation": 1
    },
    {
      "x": -2,
      "y": 9,
      "z": 22,
      "name": "Rock_Sandstone_Brick"
    },
    {
      "x": -1,
      "y": -35,
      "z": -2,
      "name": "Rock_Sandstone_Cobble"
    },
    {
      "x": -1,
      "y": -34,
      "z": -2,
      "name": "Rock_Sandstone"
    },
    {
      "x": -1,
      "y": -33,
      "z": -2,
      "name": "Rock_Sandstone_Brick"
    },
    {
      "x": -1,
      "y": -32,
      "z": -2,
      "name": "Rock_Sandstone_Brick"
    },
    {
      "x": -1,
      "y": -31,
      "z": -2,
      "name": "Rock_Sandstone"
    },
    {
      "x": -1,
      "y": -30,
      "z": -2,
      "name": "Rock_Sandstone_Brick"
    },
    {
      "x": -1,
      "y": -29,
      "z": -2,
      "name": "Rock_Sandstone_Brick"
    },
    {
      "x": -1,
      "y": -28,
      "z": -2,
      "name": "Rock_Sandstone_Brick"
    },
    {
      "x": -1,
      "y": -27,
      "z": -2,
      "name": "Rock_Sandstone"
    },
    {
      "x": -1,
      "y": -26,
      "z": -2,
      "name": "Rock_Sandstone_Cobble"
    },
    {
      "x": -1,
      "y": -25,
      "z": -2,
      "name": "Rock_Sandstone"
    },
    {
      "x": -1,
      "y": -24,
      "z": -2,
      "name": "Rock_Sandstone_Brick"
    },
    {
      "x": -1,
      "y": -23,
      "z": -2,
      "name": "Rock_Sandstone_Brick"
    },
    {
      "x": -1,
      "y": -22,
      "z": -2,
      "name": "Rock_Sandstone"
    },
    {
      "x": -1,
      "y": -21,
      "z": -2,
      "name": "Rock_Sandstone_Brick"
    },
    {
      "x": -1,
      "y": -20,
      "z": -2,
      "name": "Rock_Sandstone_Brick"
    },
    {
      "x": -1,
      "y": -19,
      "z": -2,
      "name": "Rock_Sandstone_Brick"
    },
    {
      "x": -1,
      "y": -18,
      "z": -2,
      "name": "Rock_Sandstone"
    },
    {
      "x": -1,
      "y": -17,
      "z": -2,
      "name": "Rock_Sandstone_Cobble"
    },
    {
      "x": -1,
      "y": -16,
      "z": -2,
      "name": "Rock_Sandstone_Brick"
    },
    {
      "x": -1,
      "y": -15,
      "z": -2,
      "name": "Rock_Sandstone_Brick"
    },
    {
      "x": -1,
      "y": -14,
      "z": -2,
      "name": "Rock_Sandstone_Brick"
    },
    {
      "x": -1,
      "y": -13,
      "z": -2,
      "name": "Rock_Sandstone"
    },
    {
      "x": -1,
      "y": -12,
      "z": -2,
      "name": "Rock_Sandstone_Brick"
    },
    {
      "x": -1,
      "y": -11,
      "z": -2,
      "name": "Rock_Sandstone_Brick"
    },
    {
      "x": -1,
      "y": -10,
      "z": -2,
      "name": "Rock_Sandstone_Brick"
    },
    {
      "x": -1,
      "y": -9,
      "z": -2,
      "name": "Rock_Sandstone_Brick"
    },
    {
      "x": -1,
      "y": -8,
      "z": -2,
      "name": "Rock_Sandstone_Brick"
    },
    {
      "x": -1,
      "y": -7,
      "z": -2,
      "name": "Rock_Sandstone_Cobble"
    },
    {
      "x": -1,
      "y": -6,
      "z": -2,
      "name": "Rock_Sandstone_Cobble"
    },
    {
      "x": -1,
      "y": -5,
      "z": -2,
      "name": "Rock_Sandstone_Brick"
    },
    {
      "x": -1,
      "y": -4,
      "z": -2,
      "name": "Rock_Sandstone_Brick"
    },
    {
      "x": -1,
      "y": -3,
      "z": -2,
      "name": "Rock_Sandstone"
    },
    {
      "x": -1,
      "y": -2,
      "z": -2,
      "name": "Rock_Sandstone_Brick"
    },
    {
      "x": -1,
      "y": -1,
      "z": -2,
      "name": "Rock_Sandstone_Brick"
    },
    {
      "x": -1,
      "y": 0,
      "z": -2,
      "name": "Rock_Sandstone"
    },
    {
      "x": -1,
      "y": 1,
      "z": -2,
      "name": "Rock_Sandstone_Brick"
    },
    {
      "x": -1,
      "y": 2,
      "z": -2,
      "name": "Rock_Sandstone_Brick"
    },
    {
      "x": -1,
      "y": 3,
      "z": -2,
      "name": "Rock_Sandstone_Brick"
    },
    {
      "x": -1,
      "y": 4,
      "z": -2,
      "name": "Rock_Sandstone_Brick"
    },
    {
      "x": -1,
      "y": 5,
      "z": -2,
      "name": "Rock_Sandstone_Brick"
    },
    {
      "x": -1,
      "y": 6,
      "z": -2,
      "name": "Rock_Sandstone_Brick"
    },
    {
      "x": -1,
      "y": 7,
      "z": -2,
      "name": "Rock_Sandstone_Brick"
    },
    {
      "x": -1,
      "y": 8,
      "z": -2,
      "name": "Rock_Sandstone_Brick"
    },
    {
      "x": -1,
      "y": 9,
      "z": -2,
      "name": "Rock_Sandstone_Brick"
    },
    {
      "x": -1,
      "y": -35,
      "z": -1,
      "name": "Rock_Sandstone_Brick"
    },
    {
      "x": -1,
      "y": -34,
      "z": -1,
      "name": "Rock_Sandstone_Brick"
    },
    {
      "x": -1,
      "y": -33,
      "z": -1,
      "name": "Rock_Sandstone_Brick"
    },
    {
      "x": -1,
      "y": -32,
      "z": -1,
      "name": "Rock_Sandstone_Cobble"
    },
    {
      "x": -1,
      "y": -31,
      "z": -1,
      "name": "Rock_Sandstone"
    },
    {
      "x": -1,
      "y": -30,
      "z": -1,
      "name": "Rock_Sandstone_Brick"
    },
    {
      "x": -1,
      "y": -29,
      "z": -1,
      "name": "Rock_Sandstone"
    },
    {
      "x": -1,
      "y": -28,
      "z": -1,
      "name": "Rock_Sandstone_Brick"
    },
    {
      "x": -1,
      "y": -27,
      "z": -1,
      "name": "Rock_Sandstone_Brick"
    },
    {
      "x": -1,
      "y": -19,
      "z": -1,
      "name": "Rock_Sandstone_Brick"
    },
    {
      "x": -1,
      "y": -18,
      "z": -1,
      "name": "Rock_Sandstone_Brick"
    },
    {
      "x": -1,
      "y": -17,
      "z": -1,
      "name": "Rock_Sandstone"
    },
    {
      "x": -1,
      "y": -16,
      "z": -1,
      "name": "Rock_Sandstone_Brick",
      "rotation": 3
    },
    {
      "x": -1,
      "y": -15,
      "z": -1,
      "name": "Rock_Sandstone_Brick",
      "rotation": 3
    },
    {
      "x": -1,
      "y": -14,
      "z": -1,
      "name": "Rock_Sandstone_Cobble",
      "rotation": 3
    },
    {
      "x": -1,
      "y": -13,
      "z": -1,
      "name": "Rock_Sandstone_Brick",
      "rotation": 3
    },
    {
      "x": -1,
      "y": -12,
      "z": -1,
      "name": "Rock_Sandstone_Brick",
      "rotation": 3
    },
    {
      "x": -1,
      "y": -11,
      "z": -1,
      "name": "Rock_Sandstone_Brick",
      "rotation": 3
    },
    {
      "x": -1,
      "y": -10,
      "z": -1,
      "name": "Rock_Sandstone_Brick",
      "rotation": 3
    },
    {
      "x": -1,
      "y": -9,
      "z": -1,
      "name": "Rock_Sandstone_Brick",
      "rotation": 3
    },
    {
      "x": -1,
      "y": -8,
      "z": -1,
      "name": "Rock_Sandstone_Brick",
      "rotation": 3
    },
    {
      "x": -1,
      "y": -7,
      "z": -1,
      "name": "Rock_Sandstone_Brick",
      "rotation": 3
    },
    {
      "x": -1,
      "y": -6,
      "z": -1,
      "name": "Rock_Sandstone_Brick",
      "rotation": 3
    },
    {
      "x": -1,
      "y": -5,
      "z": -1,
      "name": "Rock_Sandstone_Brick",
      "rotation": 3
    },
    {
      "x": -1,
      "y": -4,
      "z": -1,
      "name": "Rock_Sandstone_Brick",
      "rotation": 3
    },
    {
      "x": -1,
      "y": -3,
      "z": -1,
      "name": "Rock_Sandstone_Brick",
      "rotation": 3
    },
    {
      "x": -1,
      "y": -2,
      "z": -1,
      "name": "Rock_Sandstone_Brick",
      "rotation": 3
    },
    {
      "x": -1,
      "y": -1,
      "z": -1,
      "name": "Rock_Sandstone_Brick",
      "rotation": 3
    },
    {
      "x": -1,
      "y": 0,
      "z": -1,
      "name": "Rock_Sandstone",
      "rotation": 3
    },
    {
      "x": -1,
      "y": 1,
      "z": -1,
      "name": "Rock_Sandstone_Brick",
      "rotation": 3
    },
    {
      "x": -1,
      "y": 2,
      "z": -1,
      "name": "Rock_Sandstone_Brick",
      "rotation": 3
    },
    {
      "x": -1,
      "y": 3,
      "z": -1,
      "name": "Rock_Sandstone",
      "rotation": 3
    },
    {
      "x": -1,
      "y": 4,
      "z": -1,
      "name": "Rock_Sandstone_Brick",
      "rotation": 3
    },
    {
      "x": -1,
      "y": 5,
      "z": -1,
      "name": "Rock_Sandstone_Brick",
      "rotation": 3
    },
    {
      "x": -1,
      "y": 6,
      "z": -1,
      "name": "Rock_Sandstone_Brick",
      "rotation": 3
    },
    {
      "x": -1,
      "y": 7,
      "z": -1,
      "name": "Rock_Sandstone_Brick",
      "rotation": 3
    },
    {
      "x": -1,
      "y": 8,
      "z": -1,
      "name": "Rock_Sandstone_Brick",
      "rotation": 3
    },
    {
      "x": -1,
      "y": 9,
      "z": -1,
      "name": "Rock_Sandstone_Brick"
    },
    {
      "x": -1,
      "y": -35,
      "z": 0,
      "name": "Rock_Sandstone_Cobble"
    },
    {
      "x": -1,
      "y": -34,
      "z": 0,
      "name": "Rock_Sandstone"
    },
    {
      "x": -1,
      "y": -33,
      "z": 0,
      "name": "Rock_Sandstone_Brick"
    },
    {
      "x": -1,
      "y": -32,
      "z": 0,
      "name": "Rock_Sandstone_Brick"
    },
    {
      "x": -1,
      "y": -31,
      "z": 0,
      "name": "Rock_Sandstone_Brick"
    },
    {
      "x": -1,
      "y": -30,
      "z": 0,
      "name": "Rock_Sandstone_Brick"
    },
    {
      "x": -1,
      "y": -29,
      "z": 0,
      "name": "Rock_Sandstone"
    },
    {
      "x": -1,
      "y": -28,
      "z": 0,
      "name": "Rock_Sandstone"
    },
    {
      "x": -1,
      "y": -27,
      "z": 0,
      "name": "Rock_Sandstone_Cobble"
    },
    {
      "x": -1,
      "y": -13,
      "z": 0,
      "name": "Rock_Sandstone_Cobble",
      "rotation": 3
    },
    {
      "x": -1,
      "y": -12,
      "z": 0,
      "name": "Rock_Sandstone_Cobble",
      "rotation": 3
    },
    {
      "x": -1,
      "y": -11,
      "z": 0,
      "name": "Rock_Sandstone_Brick",
      "rotation": 3
    },
    {
      "x": -1,
      "y": -10,
      "z": 0,
      "name": "Rock_Sandstone_Brick",
      "rotation": 3
    },
    {
      "x": -1,
      "y": -9,
      "z": 0,
      "name": "Rock_Sandstone_Brick",
      "rotation": 3
    },
    {
      "x": -1,
      "y": -8,
      "z": 0,
      "name": "Rock_Sandstone_Brick",
      "rotation": 3
    },
    {
      "x": -1,
      "y": -7,
      "z": 0,
      "name": "Rock_Sandstone_Brick",
      "rotation": 3
    },
    {
      "x": -1,
      "y": -6,
      "z": 0,
      "name": "Rock_Sandstone_Brick",
      "rotation": 3
    },
    {
      "x": -1,
      "y": -5,
      "z": 0,
      "name": "Rock_Sandstone",
      "rotation": 3
    },
    {
      "x": -1,
      "y": -4,
      "z": 0,
      "name": "Rock_Sandstone_Brick",
      "rotation": 3
    },
    {
      "x": -1,
      "y": -3,
      "z": 0,
      "name": "Rock_Sandstone_Brick",
      "rotation": 3
    },
    {
      "x": -1,
      "y": -2,
      "z": 0,
      "name": "Rock_Sandstone",
      "rotation": 3
    },
    {
      "x": -1,
      "y": -1,
      "z": 0,
      "name": "Rock_Sandstone_Cobble",
      "rotation": 3
    },
    {
      "x": -1,
      "y": 0,
      "z": 0,
      "name": "Rock_Sandstone_Brick",
      "rotation": 3
    },
    {
      "x": -1,
      "y": 1,
      "z": 0,
      "name": "Rock_Sandstone",
      "rotation": 3
    },
    {
      "x": -1,
      "y": 2,
      "z": 0,
      "name": "Rock_Sandstone_Brick",
      "rotation": 3
    },
    {
      "x": -1,
      "y": 3,
      "z": 0,
      "name": "Rock_Sandstone",
      "rotation": 3
    },
    {
      "x": -1,
      "y": 4,
      "z": 0,
      "name": "Rock_Sandstone_Brick",
      "rotation": 3
    },
    {
      "x": -1,
      "y": 5,
      "z": 0,
      "name": "Rock_Sandstone_Brick",
      "rotation": 3
    },
    {
      "x": -1,
      "y": 6,
      "z": 0,
      "name": "Rock_Sandstone_Brick",
      "rotation": 3
    },
    {
      "x": -1,
      "y": 7,
      "z": 0,
      "name": "Rock_Sandstone_Brick",
      "rotation": 3
    },
    {
      "x": -1,
      "y": 8,
      "z": 0,
      "name": "Rock_Sandstone_Brick",
      "rotation": 3
    },
    {
      "x": -1,
      "y": 9,
      "z": 0,
      "name": "Rock_Sandstone_Brick"
    },
    {
      "x": -1,
      "y": -35,
      "z": 1,
      "name": "Rock_Sandstone_Brick"
    },
    {
      "x": -1,
      "y": -34,
      "z": 1,
      "name": "Rock_Sandstone_Brick"
    },
    {
      "x": -1,
      "y": -33,
      "z": 1,
      "name": "Rock_Sandstone_Brick"
    },
    {
      "x": -1,
      "y": -32,
      "z": 1,
      "name": "Rock_Sandstone_Brick"
    },
    {
      "x": -1,
      "y": -31,
      "z": 1,
      "name": "Rock_Sandstone_Brick"
    },
    {
      "x": -1,
      "y": -30,
      "z": 1,
      "name": "Rock_Sandstone"
    },
    {
      "x": -1,
      "y": -29,
      "z": 1,
      "name": "Rock_Sandstone_Brick"
    },
    {
      "x": -1,
      "y": -28,
      "z": 1,
      "name": "Rock_Sandstone"
    },
    {
      "x": -1,
      "y": -10,
      "z": 1,
      "name": "Rock_Sandstone_Brick",
      "rotation": 3
    },
    {
      "x": -1,
      "y": -9,
      "z": 1,
      "name": "Rock_Sandstone_Cobble",
      "rotation": 3
    },
    {
      "x": -1,
      "y": -8,
      "z": 1,
      "name": "Rock_Sandstone_Brick",
      "rotation": 3
    },
    {
      "x": -1,
      "y": -7,
      "z": 1,
      "name": "Rock_Sandstone_Brick",
      "rotation": 3
    },
    {
      "x": -1,
      "y": -6,
      "z": 1,
      "name": "Rock_Sandstone_Cobble",
      "rotation": 3
    },
    {
      "x": -1,
      "y": -5,
      "z": 1,
      "name": "Rock_Sandstone_Brick",
      "rotation": 3
    },
    {
      "x": -1,
      "y": -4,
      "z": 1,
      "name": "Rock_Sandstone",
      "rotation": 3
    },
    {
      "x": -1,
      "y": -3,
      "z": 1,
      "name": "Rock_Sandstone_Brick",
      "rotation": 3
    },
    {
      "x": -1,
      "y": -2,
      "z": 1,
      "name": "Rock_Sandstone_Brick",
      "rotation": 3
    },
    {
      "x": -1,
      "y": -1,
      "z": 1,
      "name": "Rock_Sandstone_Brick",
      "rotation": 3
    },
    {
      "x": -1,
      "y": 0,
      "z": 1,
      "name": "Rock_Sandstone_Brick",
      "rotation": 3
    },
    {
      "x": -1,
      "y": 1,
      "z": 1,
      "name": "Rock_Sandstone_Brick",
      "rotation": 3
    },
    {
      "x": -1,
      "y": 2,
      "z": 1,
      "name": "Rock_Sandstone_Brick",
      "rotation": 3
    },
    {
      "x": -1,
      "y": 3,
      "z": 1,
      "name": "Rock_Sandstone",
      "rotation": 3
    },
    {
      "x": -1,
      "y": 4,
      "z": 1,
      "name": "Rock_Sandstone_Brick",
      "rotation": 3
    },
    {
      "x": -1,
      "y": 5,
      "z": 1,
      "name": "Rock_Sandstone",
      "rotation": 3
    },
    {
      "x": -1,
      "y": 6,
      "z": 1,
      "name": "Rock_Sandstone_Brick",
      "rotation": 3
    },
    {
      "x": -1,
      "y": 7,
      "z": 1,
      "name": "Rock_Sandstone_Brick",
      "rotation": 3
    },
    {
      "x": -1,
      "y": 8,
      "z": 1,
      "name": "Rock_Sandstone_Brick",
      "rotation": 3
    },
    {
      "x": -1,
      "y": 9,
      "z": 1,
      "name": "Rock_Sandstone_Brick"
    },
    {
      "x": -1,
      "y": 4,
      "z": 2,
      "name": "Rock_Sandstone_Brick_Stairs",
      "rotation": 10
    },
    {
      "x": -1,
      "y": 5,
      "z": 2,
      "name": "Rock_Sandstone_Cobble"
    },
    {
      "x": -1,
      "y": 6,
      "z": 2,
      "name": "Rock_Sandstone_Brick"
    },
    {
      "x": -1,
      "y": 7,
      "z": 2,
      "name": "Rock_Sandstone_Brick",
      "rotation": 2
    },
    {
      "x": -1,
      "y": 8,
      "z": 2,
      "name": "Rock_Sandstone_Brick"
    },
    {
      "x": -1,
      "y": 9,
      "z": 2,
      "name": "Rock_Sandstone_Brick"
    },
    {
      "x": -1,
      "y": 5,
      "z": 3,
      "name": "Rock_Sandstone_Brick_Stairs",
      "rotation": 10
    },
    {
      "x": -1,
      "y": 6,
      "z": 3,
      "name": "Rock_Sandstone"
    },
    {
      "x": -1,
      "y": 7,
      "z": 3,
      "name": "Rock_Sandstone_Brick",
      "rotation": 2
    },
    {
      "x": -1,
      "y": 8,
      "z": 3,
      "name": "Rock_Sandstone_Brick"
    },
    {
      "x": -1,
      "y": 9,
      "z": 3,
      "name": "Rock_Sandstone_Brick"
    },
    {
      "x": -1,
      "y": 6,
      "z": 4,
      "name": "Rock_Sandstone_Brick"
    },
    {
      "x": -1,
      "y": 7,
      "z": 4,
      "name": "Rock_Sandstone_Brick"
    },
    {
      "x": -1,
      "y": 8,
      "z": 4,
      "name": "Rock_Sandstone_Brick"
    },
    {
      "x": -1,
      "y": 9,
      "z": 4,
      "name": "Rock_Sandstone_Brick"
    },
    {
      "x": -1,
      "y": 6,
      "z": 5,
      "name": "Rock_Sandstone_Brick_Half",
      "rotation": 8
    },
    {
      "x": -1,
      "y": 7,
      "z": 5,
      "name": "Rock_Sandstone_Brick"
    },
    {
      "x": -1,
      "y": 8,
      "z": 5,
      "name": "Rock_Sandstone_Brick"
    },
    {
      "x": -1,
      "y": 9,
      "z": 5,
      "name": "Rock_Sandstone_Brick"
    },
    {
      "x": -1,
      "y": 7,
      "z": 6,
      "name": "Rock_Sandstone_Brick"
    },
    {
      "x": -1,
      "y": 8,
      "z": 6,
      "name": "Rock_Sandstone_Brick"
    },
    {
      "x": -1,
      "y": 9,
      "z": 6,
      "name": "Rock_Sandstone_Brick"
    },
    {
      "x": -1,
      "y": 7,
      "z": 7,
      "name": "Rock_Sandstone_Brick_Stairs",
      "rotation": 10
    },
    {
      "x": -1,
      "y": 8,
      "z": 7,
      "name": "Rock_Sandstone_Brick",
      "rotation": 3
    },
    {
      "x": -1,
      "y": 9,
      "z": 7,
      "name": "Rock_Sandstone_Brick",
      "rotation": 3
    },
    {
      "x": -1,
      "y": 7,
      "z": 8,
      "name": "Rock_Sandstone_Brick_Half",
      "rotation": 11
    },
    {
      "x": -1,
      "y": 8,
      "z": 8,
      "name": "Rock_Sandstone_Brick",
      "rotation": 3
    },
    {
      "x": -1,
      "y": 9,
      "z": 8,
      "name": "Rock_Sandstone_Brick",
      "rotation": 3
    },
    {
      "x": -1,
      "y": 8,
      "z": 9,
      "name": "Rock_Sandstone_Brick"
    },
    {
      "x": -1,
      "y": 9,
      "z": 9,
      "name": "Rock_Sandstone_Brick",
      "rotation": 3
    },
    {
      "x": -1,
      "y": 8,
      "z": 10,
      "name": "Rock_Sandstone_Brick"
    },
    {
      "x": -1,
      "y": 9,
      "z": 10,
      "name": "Rock_Sandstone_Brick",
      "rotation": 3
    },
    {
      "x": -1,
      "y": 8,
      "z": 11,
      "name": "Rock_Sandstone_Brick"
    },
    {
      "x": -1,
      "y": 9,
      "z": 11,
      "name": "Rock_Sandstone_Brick",
      "rotation": 3
    },
    {
      "x": -1,
      "y": 8,
      "z": 12,
      "name": "Rock_Sandstone_Brick",
      "rotation": 3
    },
    {
      "x": -1,
      "y": 9,
      "z": 12,
      "name": "Rock_Sandstone_Brick",
      "rotation": 3
    },
    {
      "x": -1,
      "y": 7,
      "z": 13,
      "name": "Rock_Sandstone_Brick_Half",
      "rotation": 11
    },
    {
      "x": -1,
      "y": 8,
      "z": 13,
      "name": "Rock_Sandstone_Brick",
      "rotation": 3
    },
    {
      "x": -1,
      "y": 9,
      "z": 13,
      "name": "Rock_Sandstone_Brick",
      "rotation": 3
    },
    {
      "x": -1,
      "y": 7,
      "z": 14,
      "name": "Rock_Sandstone_Brick_Stairs",
      "rotation": 8
    },
    {
      "x": -1,
      "y": 8,
      "z": 14,
      "name": "Rock_Sandstone_Brick",
      "rotation": 3
    },
    {
      "x": -1,
      "y": 9,
      "z": 14,
      "name": "Rock_Sandstone_Brick",
      "rotation": 3
    },
    {
      "x": -1,
      "y": 7,
      "z": 15,
      "name": "Rock_Sandstone_Brick"
    },
    {
      "x": -1,
      "y": 8,
      "z": 15,
      "name": "Rock_Sandstone_Brick"
    },
    {
      "x": -1,
      "y": 9,
      "z": 15,
      "name": "Rock_Sandstone_Brick"
    },
    {
      "x": -1,
      "y": 6,
      "z": 16,
      "name": "Rock_Sandstone_Brick_Half",
      "rotation": 8
    },
    {
      "x": -1,
      "y": 7,
      "z": 16,
      "name": "Rock_Sandstone_Brick"
    },
    {
      "x": -1,
      "y": 8,
      "z": 16,
      "name": "Rock_Sandstone_Brick"
    },
    {
      "x": -1,
      "y": 9,
      "z": 16,
      "name": "Rock_Sandstone_Brick"
    },
    {
      "x": -1,
      "y": 6,
      "z": 17,
      "name": "Rock_Sandstone_Brick"
    },
    {
      "x": -1,
      "y": 7,
      "z": 17,
      "name": "Rock_Sandstone_Brick"
    },
    {
      "x": -1,
      "y": 8,
      "z": 17,
      "name": "Rock_Sandstone_Brick"
    },
    {
      "x": -1,
      "y": 9,
      "z": 17,
      "name": "Rock_Sandstone_Brick"
    },
    {
      "x": -1,
      "y": 5,
      "z": 18,
      "name": "Rock_Sandstone_Brick_Stairs",
      "rotation": 8
    },
    {
      "x": -1,
      "y": 6,
      "z": 18,
      "name": "Rock_Sandstone_Cobble"
    },
    {
      "x": -1,
      "y": 7,
      "z": 18,
      "name": "Rock_Sandstone_Brick"
    },
    {
      "x": -1,
      "y": 8,
      "z": 18,
      "name": "Rock_Sandstone_Brick"
    },
    {
      "x": -1,
      "y": 9,
      "z": 18,
      "name": "Rock_Sandstone_Brick"
    },
    {
      "x": -1,
      "y": 4,
      "z": 19,
      "name": "Rock_Sandstone_Brick_Stairs",
      "rotation": 8
    },
    {
      "x": -1,
      "y": 5,
      "z": 19,
      "name": "Rock_Sandstone"
    },
    {
      "x": -1,
      "y": 6,
      "z": 19,
      "name": "Rock_Sandstone_Brick"
    },
    {
      "x": -1,
      "y": 7,
      "z": 19,
      "name": "Rock_Sandstone_Brick"
    },
    {
      "x": -1,
      "y": 8,
      "z": 19,
      "name": "Rock_Sandstone_Brick"
    },
    {
      "x": -1,
      "y": 9,
      "z": 19,
      "name": "Rock_Sandstone_Brick"
    },
    {
      "x": -1,
      "y": -35,
      "z": 20,
      "name": "Rock_Sandstone_Brick"
    },
    {
      "x": -1,
      "y": -34,
      "z": 20,
      "name": "Rock_Sandstone"
    },
    {
      "x": -1,
      "y": -33,
      "z": 20,
      "name": "Rock_Sandstone_Brick"
    },
    {
      "x": -1,
      "y": -32,
      "z": 20,
      "name": "Rock_Sandstone_Brick"
    },
    {
      "x": -1,
      "y": -31,
      "z": 20,
      "name": "Rock_Sandstone_Brick"
    },
    {
      "x": -1,
      "y": -30,
      "z": 20,
      "name": "Rock_Sandstone_Brick"
    },
    {
      "x": -1,
      "y": -20,
      "z": 20,
      "name": "Rock_Sandstone_Brick"
    },
    {
      "x": -1,
      "y": -19,
      "z": 20,
      "name": "Rock_Sandstone_Cobble"
    },
    {
      "x": -1,
      "y": -18,
      "z": 20,
      "name": "Rock_Sandstone_Brick"
    },
    {
      "x": -1,
      "y": -17,
      "z": 20,
      "name": "Rock_Sandstone_Brick"
    },
    {
      "x": -1,
      "y": -16,
      "z": 20,
      "name": "Rock_Sandstone"
    },
    {
      "x": -1,
      "y": -15,
      "z": 20,
      "name": "Rock_Sandstone_Brick",
      "rotation": 1
    },
    {
      "x": -1,
      "y": -14,
      "z": 20,
      "name": "Rock_Sandstone_Brick",
      "rotation": 1
    },
    {
      "x": -1,
      "y": -13,
      "z": 20,
      "name": "Rock_Sandstone_Brick",
      "rotation": 1
    },
    {
      "x": -1,
      "y": -12,
      "z": 20,
      "name": "Rock_Sandstone_Cobble",
      "rotation": 1
    },
    {
      "x": -1,
      "y": -11,
      "z": 20,
      "name": "Rock_Sandstone_Brick",
      "rotation": 1
    },
    {
      "x": -1,
      "y": -10,
      "z": 20,
      "name": "Rock_Sandstone_Brick",
      "rotation": 1
    },
    {
      "x": -1,
      "y": -9,
      "z": 20,
      "name": "Rock_Sandstone_Brick",
      "rotation": 1
    },
    {
      "x": -1,
      "y": -8,
      "z": 20,
      "name": "Rock_Sandstone_Brick",
      "rotation": 1
    },
    {
      "x": -1,
      "y": -7,
      "z": 20,
      "name": "Rock_Sandstone_Brick",
      "rotation": 1
    },
    {
      "x": -1,
      "y": -6,
      "z": 20,
      "name": "Rock_Sandstone_Brick",
      "rotation": 1
    },
    {
      "x": -1,
      "y": -5,
      "z": 20,
      "name": "Rock_Sandstone_Brick",
      "rotation": 1
    },
    {
      "x": -1,
      "y": -4,
      "z": 20,
      "name": "Rock_Sandstone_Cobble",
      "rotation": 1
    },
    {
      "x": -1,
      "y": -3,
      "z": 20,
      "name": "Rock_Sandstone_Brick",
      "rotation": 1
    },
    {
      "x": -1,
      "y": -2,
      "z": 20,
      "name": "Rock_Sandstone_Cobble",
      "rotation": 1
    },
    {
      "x": -1,
      "y": -1,
      "z": 20,
      "name": "Rock_Sandstone_Brick",
      "rotation": 1
    },
    {
      "x": -1,
      "y": 0,
      "z": 20,
      "name": "Rock_Sandstone_Brick",
      "rotation": 1
    },
    {
      "x": -1,
      "y": 1,
      "z": 20,
      "name": "Rock_Sandstone_Brick",
      "rotation": 1
    },
    {
      "x": -1,
      "y": 2,
      "z": 20,
      "name": "Rock_Sandstone_Brick",
      "rotation": 1
    },
    {
      "x": -1,
      "y": 3,
      "z": 20,
      "name": "Rock_Sandstone_Brick",
      "rotation": 1
    },
    {
      "x": -1,
      "y": 4,
      "z": 20,
      "name": "Rock_Sandstone_Brick",
      "rotation": 1
    },
    {
      "x": -1,
      "y": 5,
      "z": 20,
      "name": "Rock_Sandstone_Brick",
      "rotation": 1
    },
    {
      "x": -1,
      "y": 6,
      "z": 20,
      "name": "Rock_Sandstone_Brick",
      "rotation": 1
    },
    {
      "x": -1,
      "y": 7,
      "z": 20,
      "name": "Rock_Sandstone_Brick",
      "rotation": 1
    },
    {
      "x": -1,
      "y": 8,
      "z": 20,
      "name": "Rock_Sandstone_Brick",
      "rotation": 1
    },
    {
      "x": -1,
      "y": 9,
      "z": 20,
      "name": "Rock_Sandstone_Brick"
    },
    {
      "x": -1,
      "y": -35,
      "z": 21,
      "name": "Rock_Sandstone_Brick"
    },
    {
      "x": -1,
      "y": -34,
      "z": 21,
      "name": "Rock_Sandstone"
    },
    {
      "x": -1,
      "y": -33,
      "z": 21,
      "name": "Rock_Sandstone_Brick"
    },
    {
      "x": -1,
      "y": -32,
      "z": 21,
      "name": "Rock_Sandstone_Brick"
    },
    {
      "x": -1,
      "y": -31,
      "z": 21,
      "name": "Rock_Sandstone"
    },
    {
      "x": -1,
      "y": -30,
      "z": 21,
      "name": "Rock_Sandstone_Brick"
    },
    {
      "x": -1,
      "y": -29,
      "z": 21,
      "name": "Rock_Sandstone_Cobble"
    },
    {
      "x": -1,
      "y": -28,
      "z": 21,
      "name": "Rock_Sandstone_Brick"
    },
    {
      "x": -1,
      "y": -27,
      "z": 21,
      "name": "Rock_Sandstone_Brick"
    },
    {
      "x": -1,
      "y": -23,
      "z": 21,
      "name": "Rock_Sandstone_Brick"
    },
    {
      "x": -1,
      "y": -22,
      "z": 21,
      "name": "Rock_Sandstone"
    },
    {
      "x": -1,
      "y": -21,
      "z": 21,
      "name": "Rock_Sandstone_Brick"
    },
    {
      "x": -1,
      "y": -20,
      "z": 21,
      "name": "Rock_Sandstone_Cobble"
    },
    {
      "x": -1,
      "y": -19,
      "z": 21,
      "name": "Rock_Sandstone_Brick"
    },
    {
      "x": -1,
      "y": -18,
      "z": 21,
      "name": "Rock_Sandstone_Brick"
    },
    {
      "x": -1,
      "y": -17,
      "z": 21,
      "name": "Rock_Sandstone_Brick"
    },
    {
      "x": -1,
      "y": -16,
      "z": 21,
      "name": "Rock_Sandstone_Cobble"
    },
    {
      "x": -1,
      "y": -15,
      "z": 21,
      "name": "Rock_Sandstone_Brick",
      "rotation": 1
    },
    {
      "x": -1,
      "y": -14,
      "z": 21,
      "name": "Rock_Sandstone_Brick",
      "rotation": 1
    },
    {
      "x": -1,
      "y": -13,
      "z": 21,
      "name": "Rock_Sandstone_Brick",
      "rotation": 1
    },
    {
      "x": -1,
      "y": -12,
      "z": 21,
      "name": "Rock_Sandstone",
      "rotation": 1
    },
    {
      "x": -1,
      "y": -11,
      "z": 21,
      "name": "Rock_Sandstone_Brick",
      "rotation": 1
    },
    {
      "x": -1,
      "y": -10,
      "z": 21,
      "name": "Rock_Sandstone_Brick",
      "rotation": 1
    },
    {
      "x": -1,
      "y": -9,
      "z": 21,
      "name": "Rock_Sandstone_Cobble",
      "rotation": 1
    },
    {
      "x": -1,
      "y": -8,
      "z": 21,
      "name": "Rock_Sandstone_Brick",
      "rotation": 1
    },
    {
      "x": -1,
      "y": -7,
      "z": 21,
      "name": "Rock_Sandstone",
      "rotation": 1
    },
    {
      "x": -1,
      "y": -6,
      "z": 21,
      "name": "Rock_Sandstone",
      "rotation": 1
    },
    {
      "x": -1,
      "y": -5,
      "z": 21,
      "name": "Rock_Sandstone_Brick",
      "rotation": 1
    },
    {
      "x": -1,
      "y": -4,
      "z": 21,
      "name": "Rock_Sandstone_Brick",
      "rotation": 1
    },
    {
      "x": -1,
      "y": -3,
      "z": 21,
      "name": "Rock_Sandstone_Brick",
      "rotation": 1
    },
    {
      "x": -1,
      "y": -2,
      "z": 21,
      "name": "Rock_Sandstone_Cobble",
      "rotation": 1
    },
    {
      "x": -1,
      "y": -1,
      "z": 21,
      "name": "Rock_Sandstone_Brick",
      "rotation": 1
    },
    {
      "x": -1,
      "y": 0,
      "z": 21,
      "name": "Rock_Sandstone_Brick",
      "rotation": 1
    },
    {
      "x": -1,
      "y": 1,
      "z": 21,
      "name": "Rock_Sandstone",
      "rotation": 1
    },
    {
      "x": -1,
      "y": 2,
      "z": 21,
      "name": "Rock_Sandstone_Cobble",
      "rotation": 1
    },
    {
      "x": -1,
      "y": 3,
      "z": 21,
      "name": "Rock_Sandstone_Brick",
      "rotation": 1
    },
    {
      "x": -1,
      "y": 4,
      "z": 21,
      "name": "Rock_Sandstone_Brick",
      "rotation": 1
    },
    {
      "x": -1,
      "y": 5,
      "z": 21,
      "name": "Rock_Sandstone_Brick",
      "rotation": 1
    },
    {
      "x": -1,
      "y": 6,
      "z": 21,
      "name": "Rock_Sandstone_Brick",
      "rotation": 1
    },
    {
      "x": -1,
      "y": 7,
      "z": 21,
      "name": "Rock_Sandstone_Brick",
      "rotation": 1
    },
    {
      "x": -1,
      "y": 8,
      "z": 21,
      "name": "Rock_Sandstone_Brick",
      "rotation": 1
    },
    {
      "x": -1,
      "y": 9,
      "z": 21,
      "name": "Rock_Sandstone_Brick"
    },
    {
      "x": -1,
      "y": -35,
      "z": 22,
      "name": "Rock_Sandstone_Cobble"
    },
    {
      "x": -1,
      "y": -34,
      "z": 22,
      "name": "Rock_Sandstone_Brick"
    },
    {
      "x": -1,
      "y": -33,
      "z": 22,
      "name": "Rock_Sandstone_Brick"
    },
    {
      "x": -1,
      "y": -32,
      "z": 22,
      "name": "Rock_Sandstone"
    },
    {
      "x": -1,
      "y": -31,
      "z": 22,
      "name": "Rock_Sandstone_Brick"
    },
    {
      "x": -1,
      "y": -30,
      "z": 22,
      "name": "Rock_Sandstone_Brick"
    },
    {
      "x": -1,
      "y": -29,
      "z": 22,
      "name": "Rock_Sandstone_Brick"
    },
    {
      "x": -1,
      "y": -28,
      "z": 22,
      "name": "Rock_Sandstone"
    },
    {
      "x": -1,
      "y": -27,
      "z": 22,
      "name": "Rock_Sandstone_Brick"
    },
    {
      "x": -1,
      "y": -26,
      "z": 22,
      "name": "Rock_Sandstone_Cobble"
    },
    {
      "x": -1,
      "y": -25,
      "z": 22,
      "name": "Rock_Sandstone_Brick"
    },
    {
      "x": -1,
      "y": -24,
      "z": 22,
      "name": "Rock_Sandstone_Brick"
    },
    {
      "x": -1,
      "y": -23,
      "z": 22,
      "name": "Rock_Sandstone"
    },
    {
      "x": -1,
      "y": -22,
      "z": 22,
      "name": "Rock_Sandstone_Brick"
    },
    {
      "x": -1,
      "y": -21,
      "z": 22,
      "name": "Rock_Sandstone_Brick"
    },
    {
      "x": -1,
      "y": -20,
      "z": 22,
      "name": "Rock_Sandstone_Brick"
    },
    {
      "x": -1,
      "y": -19,
      "z": 22,
      "name": "Rock_Sandstone"
    },
    {
      "x": -1,
      "y": -18,
      "z": 22,
      "name": "Rock_Sandstone_Brick"
    },
    {
      "x": -1,
      "y": -17,
      "z": 22,
      "name": "Rock_Sandstone_Brick"
    },
    {
      "x": -1,
      "y": -16,
      "z": 22,
      "name": "Rock_Sandstone"
    },
    {
      "x": -1,
      "y": -15,
      "z": 22,
      "name": "Rock_Sandstone_Brick",
      "rotation": 1
    },
    {
      "x": -1,
      "y": -14,
      "z": 22,
      "name": "Rock_Sandstone_Brick",
      "rotation": 1
    },
    {
      "x": -1,
      "y": -13,
      "z": 22,
      "name": "Rock_Sandstone_Brick",
      "rotation": 1
    },
    {
      "x": -1,
      "y": -12,
      "z": 22,
      "name": "Rock_Sandstone",
      "rotation": 1
    },
    {
      "x": -1,
      "y": -11,
      "z": 22,
      "name": "Rock_Sandstone_Brick",
      "rotation": 1
    },
    {
      "x": -1,
      "y": -10,
      "z": 22,
      "name": "Rock_Sandstone_Brick",
      "rotation": 1
    },
    {
      "x": -1,
      "y": -9,
      "z": 22,
      "name": "Rock_Sandstone_Brick",
      "rotation": 1
    },
    {
      "x": -1,
      "y": -8,
      "z": 22,
      "name": "Rock_Sandstone_Cobble",
      "rotation": 1
    },
    {
      "x": -1,
      "y": -7,
      "z": 22,
      "name": "Rock_Sandstone_Brick",
      "rotation": 1
    },
    {
      "x": -1,
      "y": -6,
      "z": 22,
      "name": "Rock_Sandstone_Brick",
      "rotation": 1
    },
    {
      "x": -1,
      "y": -5,
      "z": 22,
      "name": "Rock_Sandstone_Brick",
      "rotation": 1
    },
    {
      "x": -1,
      "y": -4,
      "z": 22,
      "name": "Rock_Sandstone_Cobble",
      "rotation": 1
    },
    {
      "x": -1,
      "y": -3,
      "z": 22,
      "name": "Rock_Sandstone_Brick",
      "rotation": 1
    },
    {
      "x": -1,
      "y": -2,
      "z": 22,
      "name": "Rock_Sandstone_Brick",
      "rotation": 1
    },
    {
      "x": -1,
      "y": -1,
      "z": 22,
      "name": "Rock_Sandstone_Brick",
      "rotation": 1
    },
    {
      "x": -1,
      "y": 0,
      "z": 22,
      "name": "Rock_Sandstone_Brick",
      "rotation": 1
    },
    {
      "x": -1,
      "y": 1,
      "z": 22,
      "name": "Rock_Sandstone_Brick",
      "rotation": 1
    },
    {
      "x": -1,
      "y": 2,
      "z": 22,
      "name": "Rock_Sandstone_Cobble",
      "rotation": 1
    },
    {
      "x": -1,
      "y": 3,
      "z": 22,
      "name": "Rock_Sandstone_Brick",
      "rotation": 1
    },
    {
      "x": -1,
      "y": 4,
      "z": 22,
      "name": "Rock_Sandstone_Brick",
      "rotation": 1
    },
    {
      "x": -1,
      "y": 5,
      "z": 22,
      "name": "Rock_Sandstone_Brick",
      "rotation": 1
    },
    {
      "x": -1,
      "y": 6,
      "z": 22,
      "name": "Rock_Sandstone_Brick",
      "rotation": 1
    },
    {
      "x": -1,
      "y": 7,
      "z": 22,
      "name": "Rock_Sandstone_Brick",
      "rotation": 1
    },
    {
      "x": -1,
      "y": 8,
      "z": 22,
      "name": "Rock_Sandstone_Brick",
      "rotation": 1
    },
    {
      "x": -1,
      "y": 9,
      "z": 22,
      "name": "Rock_Sandstone_Brick"
    },
    {
      "x": -1,
      "y": -35,
      "z": 23,
      "name": "Rock_Sandstone_Brick"
    },
    {
      "x": -1,
      "y": -34,
      "z": 23,
      "name": "Rock_Sandstone_Brick"
    },
    {
      "x": -1,
      "y": -33,
      "z": 23,
      "name": "Rock_Sandstone_Brick"
    },
    {
      "x": -1,
      "y": -32,
      "z": 23,
      "name": "Rock_Sandstone_Brick"
    },
    {
      "x": -1,
      "y": -31,
      "z": 23,
      "name": "Rock_Sandstone_Cobble"
    },
    {
      "x": -1,
      "y": -30,
      "z": 23,
      "name": "Rock_Sandstone_Brick"
    },
    {
      "x": -1,
      "y": -29,
      "z": 23,
      "name": "Rock_Sandstone"
    },
    {
      "x": -1,
      "y": -28,
      "z": 23,
      "name": "Rock_Sandstone_Brick"
    },
    {
      "x": -1,
      "y": -27,
      "z": 23,
      "name": "Rock_Sandstone"
    },
    {
      "x": -1,
      "y": -26,
      "z": 23,
      "name": "Rock_Sandstone_Brick"
    },
    {
      "x": -1,
      "y": -25,
      "z": 23,
      "name": "Rock_Sandstone_Brick"
    },
    {
      "x": -1,
      "y": -24,
      "z": 23,
      "name": "Rock_Sandstone_Brick"
    },
    {
      "x": -1,
      "y": -23,
      "z": 23,
      "name": "Rock_Sandstone_Brick"
    },
    {
      "x": -1,
      "y": -22,
      "z": 23,
      "name": "Rock_Sandstone_Cobble"
    },
    {
      "x": -1,
      "y": -21,
      "z": 23,
      "name": "Rock_Sandstone_Brick"
    },
    {
      "x": -1,
      "y": -20,
      "z": 23,
      "name": "Rock_Sandstone"
    },
    {
      "x": -1,
      "y": -19,
      "z": 23,
      "name": "Rock_Sandstone_Brick"
    },
    {
      "x": -1,
      "y": -18,
      "z": 23,
      "name": "Rock_Sandstone"
    },
    {
      "x": -1,
      "y": -17,
      "z": 23,
      "name": "Rock_Sandstone"
    },
    {
      "x": -1,
      "y": -16,
      "z": 23,
      "name": "Rock_Sandstone_Brick"
    },
    {
      "x": -1,
      "y": -15,
      "z": 23,
      "name": "Rock_Sandstone"
    },
    {
      "x": -1,
      "y": -14,
      "z": 23,
      "name": "Rock_Sandstone_Brick"
    },
    {
      "x": -1,
      "y": -13,
      "z": 23,
      "name": "Rock_Sandstone_Brick"
    },
    {
      "x": -1,
      "y": -12,
      "z": 23,
      "name": "Rock_Sandstone_Brick"
    },
    {
      "x": -1,
      "y": -11,
      "z": 23,
      "name": "Rock_Sandstone_Brick"
    },
    {
      "x": -1,
      "y": -10,
      "z": 23,
      "name": "Rock_Sandstone_Cobble"
    },
    {
      "x": -1,
      "y": -9,
      "z": 23,
      "name": "Rock_Sandstone"
    },
    {
      "x": -1,
      "y": -8,
      "z": 23,
      "name": "Rock_Sandstone_Cobble"
    },
    {
      "x": -1,
      "y": -7,
      "z": 23,
      "name": "Rock_Sandstone_Brick"
    },
    {
      "x": -1,
      "y": -6,
      "z": 23,
      "name": "Rock_Sandstone_Brick"
    },
    {
      "x": -1,
      "y": -5,
      "z": 23,
      "name": "Rock_Sandstone_Brick"
    },
    {
      "x": -1,
      "y": -4,
      "z": 23,
      "name": "Rock_Sandstone"
    },
    {
      "x": -1,
      "y": -3,
      "z": 23,
      "name": "Rock_Sandstone_Brick"
    },
    {
      "x": -1,
      "y": -2,
      "z": 23,
      "name": "Rock_Sandstone_Brick"
    },
    {
      "x": -1,
      "y": -1,
      "z": 23,
      "name": "Rock_Sandstone_Brick"
    },
    {
      "x": -1,
      "y": 0,
      "z": 23,
      "name": "Rock_Sandstone_Brick"
    },
    {
      "x": -1,
      "y": 1,
      "z": 23,
      "name": "Rock_Sandstone_Brick"
    },
    {
      "x": -1,
      "y": 2,
      "z": 23,
      "name": "Rock_Sandstone_Brick"
    },
    {
      "x": -1,
      "y": 3,
      "z": 23,
      "name": "Rock_Sandstone_Brick"
    },
    {
      "x": -1,
      "y": 4,
      "z": 23,
      "name": "Rock_Sandstone_Brick"
    },
    {
      "x": -1,
      "y": 5,
      "z": 23,
      "name": "Rock_Sandstone_Brick"
    },
    {
      "x": -1,
      "y": 6,
      "z": 23,
      "name": "Rock_Sandstone_Cobble"
    },
    {
      "x": -1,
      "y": 7,
      "z": 23,
      "name": "Rock_Sandstone_Brick"
    },
    {
      "x": -1,
      "y": 8,
      "z": 23,
      "name": "Rock_Sandstone_Brick"
    },
    {
      "x": -1,
      "y": 9,
      "z": 23,
      "name": "Rock_Sandstone_Brick"
    },
    {
      "x": 0,
      "y": -35,
      "z": -2,
      "name": "Rock_Sandstone_Brick"
    },
    {
      "x": 0,
      "y": -34,
      "z": -2,
      "name": "Rock_Sandstone_Brick"
    },
    {
      "x": 0,
      "y": -33,
      "z": -2,
      "name": "Rock_Sandstone"
    },
    {
      "x": 0,
      "y": -32,
      "z": -2,
      "name": "Rock_Sandstone"
    },
    {
      "x": 0,
      "y": -31,
      "z": -2,
      "name": "Rock_Sandstone_Brick"
    },
    {
      "x": 0,
      "y": -30,
      "z": -2,
      "name": "Rock_Sandstone_Brick"
    },
    {
      "x": 0,
      "y": -29,
      "z": -2,
      "name": "Rock_Sandstone"
    },
    {
      "x": 0,
      "y": -28,
      "z": -2,
      "name": "Rock_Sandstone_Brick"
    },
    {
      "x": 0,
      "y": -27,
      "z": -2,
      "name": "Rock_Sandstone"
    },
    {
      "x": 0,
      "y": -26,
      "z": -2,
      "name": "Rock_Sandstone_Brick"
    },
    {
      "x": 0,
      "y": -25,
      "z": -2,
      "name": "Rock_Sandstone_Brick"
    },
    {
      "x": 0,
      "y": -24,
      "z": -2,
      "name": "Rock_Sandstone"
    },
    {
      "x": 0,
      "y": -23,
      "z": -2,
      "name": "Rock_Sandstone"
    },
    {
      "x": 0,
      "y": -22,
      "z": -2,
      "name": "Rock_Sandstone_Brick"
    },
    {
      "x": 0,
      "y": -21,
      "z": -2,
      "name": "Rock_Sandstone_Brick"
    },
    {
      "x": 0,
      "y": -20,
      "z": -2,
      "name": "Rock_Sandstone"
    },
    {
      "x": 0,
      "y": -19,
      "z": -2,
      "name": "Rock_Sandstone_Brick"
    },
    {
      "x": 0,
      "y": -18,
      "z": -2,
      "name": "Rock_Sandstone"
    },
    {
      "x": 0,
      "y": -17,
      "z": -2,
      "name": "Rock_Sandstone_Cobble"
    },
    {
      "x": 0,
      "y": -16,
      "z": -2,
      "name": "Rock_Sandstone_Brick"
    },
    {
      "x": 0,
      "y": -15,
      "z": -2,
      "name": "Rock_Sandstone"
    },
    {
      "x": 0,
      "y": -14,
      "z": -2,
      "name": "Rock_Sandstone_Brick"
    },
    {
      "x": 0,
      "y": -13,
      "z": -2,
      "name": "Rock_Sandstone"
    },
    {
      "x": 0,
      "y": -12,
      "z": -2,
      "name": "Rock_Sandstone_Brick"
    },
    {
      "x": 0,
      "y": -11,
      "z": -2,
      "name": "Rock_Sandstone_Brick"
    },
    {
      "x": 0,
      "y": -10,
      "z": -2,
      "name": "Rock_Sandstone_Brick"
    },
    {
      "x": 0,
      "y": -9,
      "z": -2,
      "name": "Rock_Sandstone_Brick"
    },
    {
      "x": 0,
      "y": -8,
      "z": -2,
      "name": "Rock_Sandstone_Brick"
    },
    {
      "x": 0,
      "y": -7,
      "z": -2,
      "name": "Rock_Sandstone_Cobble"
    },
    {
      "x": 0,
      "y": -6,
      "z": -2,
      "name": "Rock_Sandstone_Cobble"
    },
    {
      "x": 0,
      "y": -5,
      "z": -2,
      "name": "Rock_Sandstone_Brick"
    },
    {
      "x": 0,
      "y": -4,
      "z": -2,
      "name": "Rock_Sandstone_Brick"
    },
    {
      "x": 0,
      "y": -3,
      "z": -2,
      "name": "Rock_Sandstone_Cobble"
    },
    {
      "x": 0,
      "y": -2,
      "z": -2,
      "name": "Rock_Sandstone_Cobble"
    },
    {
      "x": 0,
      "y": -1,
      "z": -2,
      "name": "Rock_Sandstone_Brick"
    },
    {
      "x": 0,
      "y": 0,
      "z": -2,
      "name": "Rock_Sandstone_Brick"
    },
    {
      "x": 0,
      "y": 1,
      "z": -2,
      "name": "Rock_Sandstone_Brick"
    },
    {
      "x": 0,
      "y": 2,
      "z": -2,
      "name": "Rock_Sandstone_Brick"
    },
    {
      "x": 0,
      "y": 3,
      "z": -2,
      "name": "Rock_Sandstone_Brick"
    },
    {
      "x": 0,
      "y": 4,
      "z": -2,
      "name": "Rock_Sandstone_Brick"
    },
    {
      "x": 0,
      "y": 5,
      "z": -2,
      "name": "Rock_Sandstone_Brick"
    },
    {
      "x": 0,
      "y": 6,
      "z": -2,
      "name": "Rock_Sandstone"
    },
    {
      "x": 0,
      "y": 7,
      "z": -2,
      "name": "Rock_Sandstone_Brick"
    },
    {
      "x": 0,
      "y": 8,
      "z": -2,
      "name": "Rock_Sandstone_Brick"
    },
    {
      "x": 0,
      "y": 9,
      "z": -2,
      "name": "Rock_Sandstone_Brick"
    },
    {
      "x": 0,
      "y": -35,
      "z": -1,
      "name": "Rock_Sandstone_Cobble"
    },
    {
      "x": 0,
      "y": -34,
      "z": -1,
      "name": "Rock_Sandstone_Brick"
    },
    {
      "x": 0,
      "y": -33,
      "z": -1,
      "name": "Rock_Sandstone_Brick"
    },
    {
      "x": 0,
      "y": -32,
      "z": -1,
      "name": "Rock_Sandstone_Brick"
    },
    {
      "x": 0,
      "y": -31,
      "z": -1,
      "name": "Rock_Sandstone_Brick"
    },
    {
      "x": 0,
      "y": -30,
      "z": -1,
      "name": "Rock_Sandstone_Brick"
    },
    {
      "x": 0,
      "y": -29,
      "z": -1,
      "name": "Rock_Sandstone_Brick"
    },
    {
      "x": 0,
      "y": -28,
      "z": -1,
      "name": "Rock_Sandstone_Brick"
    },
    {
      "x": 0,
      "y": -27,
      "z": -1,
      "name": "Rock_Sandstone_Brick"
    },
    {
      "x": 0,
      "y": -18,
      "z": -1,
      "name": "Rock_Sandstone_Brick"
    },
    {
      "x": 0,
      "y": -17,
      "z": -1,
      "name": "Rock_Sandstone_Brick"
    },
    {
      "x": 0,
      "y": -16,
      "z": -1,
      "name": "Rock_Sandstone_Brick",
      "rotation": 3
    },
    {
      "x": 0,
      "y": -15,
      "z": -1,
      "name": "Rock_Sandstone_Brick",
      "rotation": 3
    },
    {
      "x": 0,
      "y": -14,
      "z": -1,
      "name": "Rock_Sandstone_Brick",
      "rotation": 3
    },
    {
      "x": 0,
      "y": -13,
      "z": -1,
      "name": "Rock_Sandstone_Brick",
      "rotation": 3
    },
    {
      "x": 0,
      "y": -12,
      "z": -1,
      "name": "Rock_Sandstone_Brick",
      "rotation": 3
    },
    {
      "x": 0,
      "y": -11,
      "z": -1,
      "name": "Rock_Sandstone_Brick",
      "rotation": 3
    },
    {
      "x": 0,
      "y": -10,
      "z": -1,
      "name": "Rock_Sandstone_Brick",
      "rotation": 3
    },
    {
      "x": 0,
      "y": -9,
      "z": -1,
      "name": "Rock_Sandstone_Brick",
      "rotation": 3
    },
    {
      "x": 0,
      "y": -8,
      "z": -1,
      "name": "Rock_Sandstone_Brick",
      "rotation": 3
    },
    {
      "x": 0,
      "y": -7,
      "z": -1,
      "name": "Rock_Sandstone_Brick",
      "rotation": 3
    },
    {
      "x": 0,
      "y": -6,
      "z": -1,
      "name": "Rock_Sandstone_Brick",
      "rotation": 3
    },
    {
      "x": 0,
      "y": -5,
      "z": -1,
      "name": "Rock_Sandstone",
      "rotation": 3
    },
    {
      "x": 0,
      "y": -4,
      "z": -1,
      "name": "Rock_Sandstone_Brick",
      "rotation": 3
    },
    {
      "x": 0,
      "y": -3,
      "z": -1,
      "name": "Rock_Sandstone_Brick",
      "rotation": 3
    },
    {
      "x": 0,
      "y": -2,
      "z": -1,
      "name": "Rock_Sandstone_Brick",
      "rotation": 3
    },
    {
      "x": 0,
      "y": -1,
      "z": -1,
      "name": "Rock_Sandstone_Brick",
      "rotation": 3
    },
    {
      "x": 0,
      "y": 0,
      "z": -1,
      "name": "Rock_Sandstone_Brick",
      "rotation": 3
    },
    {
      "x": 0,
      "y": 1,
      "z": -1,
      "name": "Rock_Sandstone_Brick",
      "rotation": 3
    },
    {
      "x": 0,
      "y": 2,
      "z": -1,
      "name": "Rock_Sandstone_Brick",
      "rotation": 3
    },
    {
      "x": 0,
      "y": 3,
      "z": -1,
      "name": "Rock_Sandstone_Brick",
      "rotation": 3
    },
    {
      "x": 0,
      "y": 4,
      "z": -1,
      "name": "Rock_Sandstone_Cobble",
      "rotation": 3
    },
    {
      "x": 0,
      "y": 5,
      "z": -1,
      "name": "Rock_Sandstone",
      "rotation": 3
    },
    {
      "x": 0,
      "y": 6,
      "z": -1,
      "name": "Rock_Sandstone_Brick",
      "rotation": 3
    },
    {
      "x": 0,
      "y": 7,
      "z": -1,
      "name": "Rock_Sandstone_Brick",
      "rotation": 3
    },
    {
      "x": 0,
      "y": 8,
      "z": -1,
      "name": "Rock_Sandstone_Brick",
      "rotation": 3
    },
    {
      "x": 0,
      "y": 9,
      "z": -1,
      "name": "Rock_Sandstone_Brick"
    },
    {
      "x": 0,
      "y": -35,
      "z": 0,
      "name": "Rock_Sandstone_Brick"
    },
    {
      "x": 0,
      "y": -34,
      "z": 0,
      "name": "Rock_Sandstone_Brick"
    },
    {
      "x": 0,
      "y": -33,
      "z": 0,
      "name": "Rock_Sandstone_Brick"
    },
    {
      "x": 0,
      "y": -32,
      "z": 0,
      "name": "Rock_Sandstone_Brick"
    },
    {
      "x": 0,
      "y": -31,
      "z": 0,
      "name": "Rock_Sandstone_Brick"
    },
    {
      "x": 0,
      "y": -30,
      "z": 0,
      "name": "Rock_Sandstone_Brick"
    },
    {
      "x": 0,
      "y": -29,
      "z": 0,
      "name": "Rock_Sandstone_Brick"
    },
    {
      "x": 0,
      "y": -28,
      "z": 0,
      "name": "Rock_Sandstone_Brick"
    },
    {
      "x": 0,
      "y": -13,
      "z": 0,
      "name": "Rock_Sandstone",
      "rotation": 3
    },
    {
      "x": 0,
      "y": -12,
      "z": 0,
      "name": "Rock_Sandstone_Brick",
      "rotation": 3
    },
    {
      "x": 0,
      "y": -11,
      "z": 0,
      "name": "Rock_Sandstone_Brick",
      "rotation": 3
    },
    {
      "x": 0,
      "y": -10,
      "z": 0,
      "name": "Rock_Sandstone_Brick",
      "rotation": 3
    },
    {
      "x": 0,
      "y": -9,
      "z": 0,
      "name": "Rock_Sandstone_Brick",
      "rotation": 3
    },
    {
      "x": 0,
      "y": -8,
      "z": 0,
      "name": "Rock_Sandstone_Brick",
      "rotation": 3
    },
    {
      "x": 0,
      "y": -7,
      "z": 0,
      "name": "Rock_Sandstone",
      "rotation": 3
    },
    {
      "x": 0,
      "y": -6,
      "z": 0,
      "name": "Rock_Sandstone_Brick",
      "rotation": 3
    },
    {
      "x": 0,
      "y": -5,
      "z": 0,
      "name": "Rock_Sandstone_Brick",
      "rotation": 3
    },
    {
      "x": 0,
      "y": -4,
      "z": 0,
      "name": "Rock_Sandstone_Brick",
      "rotation": 3
    },
    {
      "x": 0,
      "y": -3,
      "z": 0,
      "name": "Rock_Sandstone_Brick",
      "rotation": 3
    },
    {
      "x": 0,
      "y": -2,
      "z": 0,
      "name": "Rock_Sandstone_Brick",
      "rotation": 3
    },
    {
      "x": 0,
      "y": -1,
      "z": 0,
      "name": "Rock_Sandstone_Brick",
      "rotation": 3
    },
    {
      "x": 0,
      "y": 0,
      "z": 0,
      "name": "Rock_Sandstone",
      "rotation": 3
    },
    {
      "x": 0,
      "y": 1,
      "z": 0,
      "name": "Rock_Sandstone_Brick",
      "rotation": 3
    },
    {
      "x": 0,
      "y": 2,
      "z": 0,
      "name": "Rock_Sandstone_Brick",
      "rotation": 3
    },
    {
      "x": 0,
      "y": 3,
      "z": 0,
      "name": "Rock_Sandstone_Cobble",
      "rotation": 3
    },
    {
      "x": 0,
      "y": 4,
      "z": 0,
      "name": "Rock_Sandstone_Brick",
      "rotation": 3
    },
    {
      "x": 0,
      "y": 5,
      "z": 0,
      "name": "Rock_Sandstone_Brick",
      "rotation": 3
    },
    {
      "x": 0,
      "y": 6,
      "z": 0,
      "name": "Rock_Sandstone_Brick",
      "rotation": 3
    },
    {
      "x": 0,
      "y": 7,
      "z": 0,
      "name": "Rock_Sandstone_Brick",
      "rotation": 3
    },
    {
      "x": 0,
      "y": 8,
      "z": 0,
      "name": "Rock_Sandstone_Brick",
      "rotation": 3
    },
    {
      "x": 0,
      "y": 9,
      "z": 0,
      "name": "Rock_Sandstone_Brick"
    },
    {
      "x": 0,
      "y": -35,
      "z": 1,
      "name": "Rock_Sandstone"
    },
    {
      "x": 0,
      "y": -34,
      "z": 1,
      "name": "Rock_Sandstone"
    },
    {
      "x": 0,
      "y": -33,
      "z": 1,
      "name": "Rock_Sandstone_Brick"
    },
    {
      "x": 0,
      "y": -32,
      "z": 1,
      "name": "Rock_Sandstone_Brick"
    },
    {
      "x": 0,
      "y": -31,
      "z": 1,
      "name": "Rock_Sandstone_Brick"
    },
    {
      "x": 0,
      "y": -30,
      "z": 1,
      "name": "Rock_Sandstone_Brick"
    },
    {
      "x": 0,
      "y": -29,
      "z": 1,
      "name": "Rock_Sandstone_Brick"
    },
    {
      "x": 0,
      "y": -10,
      "z": 1,
      "name": "Rock_Sandstone_Brick",
      "rotation": 3
    },
    {
      "x": 0,
      "y": -9,
      "z": 1,
      "name": "Rock_Sandstone",
      "rotation": 3
    },
    {
      "x": 0,
      "y": -8,
      "z": 1,
      "name": "Rock_Sandstone_Brick",
      "rotation": 3
    },
    {
      "x": 0,
      "y": -7,
      "z": 1,
      "name": "Rock_Sandstone_Brick",
      "rotation": 3
    },
    {
      "x": 0,
      "y": -6,
      "z": 1,
      "name": "Rock_Sandstone",
      "rotation": 3
    },
    {
      "x": 0,
      "y": -5,
      "z": 1,
      "name": "Rock_Sandstone_Brick",
      "rotation": 3
    },
    {
      "x": 0,
      "y": -4,
      "z": 1,
      "name": "Rock_Sandstone_Brick",
      "rotation": 3
    },
    {
      "x": 0,
      "y": -3,
      "z": 1,
      "name": "Rock_Sandstone_Cobble",
      "rotation": 3
    },
    {
      "x": 0,
      "y": -2,
      "z": 1,
      "name": "Rock_Sandstone_Brick",
      "rotation": 3
    },
    {
      "x": 0,
      "y": -1,
      "z": 1,
      "name": "Rock_Sandstone_Brick",
      "rotation": 3
    },
    {
      "x": 0,
      "y": 0,
      "z": 1,
      "name": "Rock_Sandstone_Cobble",
      "rotation": 3
    },
    {
      "x": 0,
      "y": 1,
      "z": 1,
      "name": "Rock_Sandstone_Brick",
      "rotation": 3
    },
    {
      "x": 0,
      "y": 2,
      "z": 1,
      "name": "Rock_Sandstone_Brick",
      "rotation": 3
    },
    {
      "x": 0,
      "y": 3,
      "z": 1,
      "name": "Rock_Sandstone_Brick",
      "rotation": 3
    },
    {
      "x": 0,
      "y": 4,
      "z": 1,
      "name": "Rock_Sandstone_Brick",
      "rotation": 3
    },
    {
      "x": 0,
      "y": 5,
      "z": 1,
      "name": "Rock_Sandstone",
      "rotation": 3
    },
    {
      "x": 0,
      "y": 6,
      "z": 1,
      "name": "Rock_Sandstone_Brick",
      "rotation": 3
    },
    {
      "x": 0,
      "y": 7,
      "z": 1,
      "name": "Rock_Sandstone_Brick",
      "rotation": 3
    },
    {
      "x": 0,
      "y": 8,
      "z": 1,
      "name": "Rock_Sandstone_Brick",
      "rotation": 3
    },
    {
      "x": 0,
      "y": 9,
      "z": 1,
      "name": "Rock_Sandstone_Brick"
    },
    {
      "x": 0,
      "y": -35,
      "z": 2,
      "name": "Rock_Sandstone_Brick"
    },
    {
      "x": 0,
      "y": -34,
      "z": 2,
      "name": "Rock_Sandstone_Brick"
    },
    {
      "x": 0,
      "y": -33,
      "z": 2,
      "name": "Rock_Sandstone_Brick"
    },
    {
      "x": 0,
      "y": -32,
      "z": 2,
      "name": "Rock_Sandstone_Brick"
    },
    {
      "x": 0,
      "y": -31,
      "z": 2,
      "name": "Rock_Sandstone_Brick"
    },
    {
      "x": 0,
      "y": -30,
      "z": 2,
      "name": "Rock_Sandstone_Brick"
    },
    {
      "x": 0,
      "y": -9,
      "z": 2,
      "name": "Rock_Sandstone"
    },
    {
      "x": 0,
      "y": -8,
      "z": 2,
      "name": "Rock_Sandstone_Brick"
    },
    {
      "x": 0,
      "y": -7,
      "z": 2,
      "name": "Rock_Sandstone_Cobble"
    },
    {
      "x": 0,
      "y": -6,
      "z": 2,
      "name": "Rock_Sandstone_Brick"
    },
    {
      "x": 0,
      "y": -5,
      "z": 2,
      "name": "Rock_Sandstone_Brick"
    },
    {
      "x": 0,
      "y": -4,
      "z": 2,
      "name": "Rock_Sandstone_Brick"
    },
    {
      "x": 0,
      "y": -3,
      "z": 2,
      "name": "Rock_Sandstone_Cobble"
    },
    {
      "x": 0,
      "y": -2,
      "z": 2,
      "name": "Rock_Sandstone"
    },
    {
      "x": 0,
      "y": -1,
      "z": 2,
      "name": "Rock_Sandstone"
    },
    {
      "x": 0,
      "y": 0,
      "z": 2,
      "name": "Rock_Sandstone_Brick"
    },
    {
      "x": 0,
      "y": 1,
      "z": 2,
      "name": "Rock_Sandstone_Cobble"
    },
    {
      "x": 0,
      "y": 2,
      "z": 2,
      "name": "Rock_Sandstone_Brick"
    },
    {
      "x": 0,
      "y": 3,
      "z": 2,
      "name": "Rock_Sandstone_Cobble"
    },
    {
      "x": 0,
      "y": 4,
      "z": 2,
      "name": "Rock_Sandstone"
    },
    {
      "x": 0,
      "y": 5,
      "z": 2,
      "name": "Rock_Sandstone"
    },
    {
      "x": 0,
      "y": 6,
      "z": 2,
      "name": "Rock_Sandstone_Brick"
    },
    {
      "x": 0,
      "y": 7,
      "z": 2,
      "name": "Rock_Sandstone_Brick",
      "rotation": 2
    },
    {
      "x": 0,
      "y": 8,
      "z": 2,
      "name": "Rock_Sandstone_Brick"
    },
    {
      "x": 0,
      "y": 9,
      "z": 2,
      "name": "Rock_Sandstone_Brick"
    },
    {
      "x": 0,
      "y": -35,
      "z": 3,
      "name": "Rock_Sandstone_Brick"
    },
    {
      "x": 0,
      "y": -34,
      "z": 3,
      "name": "Rock_Sandstone_Brick"
    },
    {
      "x": 0,
      "y": -33,
      "z": 3,
      "name": "Rock_Sandstone_Cobble"
    },
    {
      "x": 0,
      "y": -32,
      "z": 3,
      "name": "Rock_Sandstone"
    },
    {
      "x": 0,
      "y": -9,
      "z": 3,
      "name": "Rock_Sandstone"
    },
    {
      "x": 0,
      "y": -8,
      "z": 3,
      "name": "Rock_Sandstone_Brick"
    },
    {
      "x": 0,
      "y": -7,
      "z": 3,
      "name": "Rock_Sandstone_Brick"
    },
    {
      "x": 0,
      "y": -6,
      "z": 3,
      "name": "Rock_Sandstone"
    },
    {
      "x": 0,
      "y": -5,
      "z": 3,
      "name": "Rock_Sandstone_Brick"
    },
    {
      "x": 0,
      "y": -4,
      "z": 3,
      "name": "Rock_Sandstone_Brick"
    },
    {
      "x": 0,
      "y": -3,
      "z": 3,
      "name": "Rock_Sandstone_Brick"
    },
    {
      "x": 0,
      "y": -2,
      "z": 3,
      "name": "Rock_Sandstone_Brick"
    },
    {
      "x": 0,
      "y": -1,
      "z": 3,
      "name": "Rock_Sandstone_Brick"
    },
    {
      "x": 0,
      "y": 0,
      "z": 3,
      "name": "Rock_Sandstone_Cobble"
    },
    {
      "x": 0,
      "y": 1,
      "z": 3,
      "name": "Rock_Sandstone_Cobble"
    },
    {
      "x": 0,
      "y": 2,
      "z": 3,
      "name": "Rock_Sandstone"
    },
    {
      "x": 0,
      "y": 3,
      "z": 3,
      "name": "Rock_Sandstone_Brick"
    },
    {
      "x": 0,
      "y": 4,
      "z": 3,
      "name": "Rock_Sandstone_Brick"
    },
    {
      "x": 0,
      "y": 5,
      "z": 3,
      "name": "Rock_Sandstone"
    },
    {
      "x": 0,
      "y": 6,
      "z": 3,
      "name": "Rock_Sandstone"
    },
    {
      "x": 0,
      "y": 7,
      "z": 3,
      "name": "Rock_Sandstone_Brick",
      "rotation": 2
    },
    {
      "x": 0,
      "y": 8,
      "z": 3,
      "name": "Rock_Sandstone_Brick"
    },
    {
      "x": 0,
      "y": 9,
      "z": 3,
      "name": "Rock_Sandstone_Brick"
    },
    {
      "x": 0,
      "y": 1,
      "z": 4,
      "name": "Rock_Sandstone_Brick_Stairs",
      "rotation": 10
    },
    {
      "x": 0,
      "y": 2,
      "z": 4,
      "name": "Rock_Sandstone_Cobble"
    },
    {
      "x": 0,
      "y": 3,
      "z": 4,
      "name": "Rock_Sandstone_Cobble"
    },
    {
      "x": 0,
      "y": 4,
      "z": 4,
      "name": "Rock_Sandstone_Brick"
    },
    {
      "x": 0,
      "y": 5,
      "z": 4,
      "name": "Rock_Sandstone_Brick"
    },
    {
      "x": 0,
      "y": 6,
      "z": 4,
      "name": "Rock_Sandstone_Brick"
    },
    {
      "x": 0,
      "y": 7,
      "z": 4,
      "name": "Rock_Sandstone_Brick"
    },
    {
      "x": 0,
      "y": 8,
      "z": 4,
      "name": "Rock_Sandstone_Brick"
    },
    {
      "x": 0,
      "y": 9,
      "z": 4,
      "name": "Rock_Sandstone_Brick"
    },
    {
      "x": 0,
      "y": 4,
      "z": 5,
      "name": "Rock_Sandstone_Brick_Stairs",
      "rotation": 10
    },
    {
      "x": 0,
      "y": 5,
      "z": 5,
      "name": "Rock_Sandstone_Brick"
    },
    {
      "x": 0,
      "y": 6,
      "z": 5,
      "name": "Rock_Sandstone_Brick"
    },
    {
      "x": 0,
      "y": 7,
      "z": 5,
      "name": "Rock_Sandstone_Brick"
    },
    {
      "x": 0,
      "y": 8,
      "z": 5,
      "name": "Rock_Sandstone_Brick"
    },
    {
      "x": 0,
      "y": 9,
      "z": 5,
      "name": "Rock_Sandstone_Brick"
    },
    {
      "x": 0,
      "y": 5,
      "z": 6,
      "name": "Rock_Sandstone_Brick"
    },
    {
      "x": 0,
      "y": 6,
      "z": 6,
      "name": "Rock_Sandstone"
    },
    {
      "x": 0,
      "y": 7,
      "z": 6,
      "name": "Rock_Sandstone_Brick"
    },
    {
      "x": 0,
      "y": 8,
      "z": 6,
      "name": "Rock_Sandstone_Brick"
    },
    {
      "x": 0,
      "y": 9,
      "z": 6,
      "name": "Rock_Sandstone_Brick"
    },
    {
      "x": 0,
      "y": 5,
      "z": 7,
      "name": "Rock_Sandstone_Brick_Stairs",
      "rotation": 10
    },
    {
      "x": 0,
      "y": 6,
      "z": 7,
      "name": "Rock_Sandstone_Brick",
      "rotation": 3
    },
    {
      "x": 0,
      "y": 7,
      "z": 7,
      "name": "Rock_Sandstone_Brick",
      "rotation": 3
    },
    {
      "x": 0,
      "y": 8,
      "z": 7,
      "name": "Rock_Sandstone_Brick",
      "rotation": 3
    },
    {
      "x": 0,
      "y": 9,
      "z": 7,
      "name": "Rock_Sandstone_Brick",
      "rotation": 3
    },
    {
      "x": 0,
      "y": 5,
      "z": 8,
      "name": "Rock_Sandstone_Brick_Half",
      "rotation": 11
    },
    {
      "x": 0,
      "y": 6,
      "z": 8,
      "name": "Rock_Sandstone_Brick",
      "rotation": 3
    },
    {
      "x": 0,
      "y": 7,
      "z": 8,
      "name": "Rock_Sandstone_Brick",
      "rotation": 3
    },
    {
      "x": 0,
      "y": 8,
      "z": 8,
      "name": "Rock_Sandstone_Brick",
      "rotation": 3
    },
    {
      "x": 0,
      "y": 9,
      "z": 8,
      "name": "Rock_Sandstone_Brick",
      "rotation": 3
    },
    {
      "x": 0,
      "y": 6,
      "z": 9,
      "name": "Rock_Sandstone_Brick"
    },
    {
      "x": 0,
      "y": 7,
      "z": 9,
      "name": "Rock_Sandstone_Brick"
    },
    {
      "x": 0,
      "y": 8,
      "z": 9,
      "name": "Rock_Sandstone_Brick"
    },
    {
      "x": 0,
      "y": 9,
      "z": 9,
      "name": "Rock_Sandstone_Brick",
      "rotation": 3
    },
    {
      "x": 0,
      "y": 6,
      "z": 10,
      "name": "Rock_Sandstone_Brick_Stairs",
      "rotation": 9
    },
    {
      "x": 0,
      "y": 7,
      "z": 10,
      "name": "Rock_Sandstone_Brick"
    },
    {
      "x": 0,
      "y": 8,
      "z": 10,
      "name": "Rock_Sandstone_Brick"
    },
    {
      "x": 0,
      "y": 9,
      "z": 10,
      "name": "Rock_Sandstone_Brick",
      "rotation": 3
    },
    {
      "x": 0,
      "y": 6,
      "z": 11,
      "name": "Rock_Sandstone_Brick_Stairs",
      "rotation": 9
    },
    {
      "x": 0,
      "y": 7,
      "z": 11,
      "name": "Rock_Sandstone_Brick"
    },
    {
      "x": 0,
      "y": 8,
      "z": 11,
      "name": "Rock_Sandstone_Brick"
    },
    {
      "x": 0,
      "y": 9,
      "z": 11,
      "name": "Rock_Sandstone_Brick",
      "rotation": 3
    },
    {
      "x": 0,
      "y": 6,
      "z": 12,
      "name": "Rock_Sandstone_Brick"
    },
    {
      "x": 0,
      "y": 7,
      "z": 12,
      "name": "Rock_Sandstone_Brick"
    },
    {
      "x": 0,
      "y": 8,
      "z": 12,
      "name": "Rock_Sandstone_Brick_Stairs",
      "rotation": 9
    },
    {
      "x": 0,
      "y": 9,
      "z": 12,
      "name": "Rock_Sandstone_Brick",
      "rotation": 3
    },
    {
      "x": 0,
      "y": 5,
      "z": 13,
      "name": "Rock_Sandstone_Brick_Half",
      "rotation": 11
    },
    {
      "x": 0,
      "y": 6,
      "z": 13,
      "name": "Rock_Sandstone_Brick",
      "rotation": 3
    },
    {
      "x": 0,
      "y": 7,
      "z": 13,
      "name": "Rock_Sandstone_Brick",
      "rotation": 3
    },
    {
      "x": 0,
      "y": 8,
      "z": 13,
      "name": "Rock_Sandstone_Brick",
      "rotation": 3
    },
    {
      "x": 0,
      "y": 9,
      "z": 13,
      "name": "Rock_Sandstone_Brick",
      "rotation": 3
    },
    {
      "x": 0,
      "y": 5,
      "z": 14,
      "name": "Rock_Sandstone_Brick_Stairs",
      "rotation": 8
    },
    {
      "x": 0,
      "y": 6,
      "z": 14,
      "name": "Rock_Sandstone_Brick",
      "rotation": 3
    },
    {
      "x": 0,
      "y": 7,
      "z": 14,
      "name": "Rock_Sandstone_Brick",
      "rotation": 3
    },
    {
      "x": 0,
      "y": 8,
      "z": 14,
      "name": "Rock_Sandstone_Brick",
      "rotation": 3
    },
    {
      "x": 0,
      "y": 9,
      "z": 14,
      "name": "Rock_Sandstone_Brick",
      "rotation": 3
    },
    {
      "x": 0,
      "y": 5,
      "z": 15,
      "name": "Rock_Sandstone_Cobble"
    },
    {
      "x": 0,
      "y": 6,
      "z": 15,
      "name": "Rock_Sandstone"
    },
    {
      "x": 0,
      "y": 7,
      "z": 15,
      "name": "Rock_Sandstone_Brick"
    },
    {
      "x": 0,
      "y": 8,
      "z": 15,
      "name": "Rock_Sandstone_Brick"
    },
    {
      "x": 0,
      "y": 9,
      "z": 15,
      "name": "Rock_Sandstone_Brick"
    },
    {
      "x": 0,
      "y": 4,
      "z": 16,
      "name": "Rock_Sandstone_Brick_Stairs",
      "rotation": 8
    },
    {
      "x": 0,
      "y": 5,
      "z": 16,
      "name": "Rock_Sandstone"
    },
    {
      "x": 0,
      "y": 6,
      "z": 16,
      "name": "Rock_Sandstone_Cobble"
    },
    {
      "x": 0,
      "y": 7,
      "z": 16,
      "name": "Rock_Sandstone_Brick"
    },
    {
      "x": 0,
      "y": 8,
      "z": 16,
      "name": "Rock_Sandstone_Brick"
    },
    {
      "x": 0,
      "y": 9,
      "z": 16,
      "name": "Rock_Sandstone_Brick"
    },
    {
      "x": 0,
      "y": 1,
      "z": 17,
      "name": "Rock_Sandstone_Brick_Stairs",
      "rotation": 8
    },
    {
      "x": 0,
      "y": 2,
      "z": 17,
      "name": "Rock_Sandstone_Brick"
    },
    {
      "x": 0,
      "y": 3,
      "z": 17,
      "name": "Rock_Sandstone_Brick"
    },
    {
      "x": 0,
      "y": 4,
      "z": 17,
      "name": "Rock_Sandstone"
    },
    {
      "x": 0,
      "y": 5,
      "z": 17,
      "name": "Rock_Sandstone_Brick"
    },
    {
      "x": 0,
      "y": 6,
      "z": 17,
      "name": "Rock_Sandstone_Cobble"
    },
    {
      "x": 0,
      "y": 7,
      "z": 17,
      "name": "Rock_Sandstone_Brick"
    },
    {
      "x": 0,
      "y": 8,
      "z": 17,
      "name": "Rock_Sandstone_Brick"
    },
    {
      "x": 0,
      "y": 9,
      "z": 17,
      "name": "Rock_Sandstone_Brick"
    },
    {
      "x": 0,
      "y": -35,
      "z": 18,
      "name": "Rock_Sandstone_Brick"
    },
    {
      "x": 0,
      "y": -34,
      "z": 18,
      "name": "Rock_Sandstone_Brick"
    },
    {
      "x": 0,
      "y": -33,
      "z": 18,
      "name": "Rock_Sandstone"
    },
    {
      "x": 0,
      "y": -32,
      "z": 18,
      "name": "Rock_Sandstone_Brick"
    },
    {
      "x": 0,
      "y": -31,
      "z": 18,
      "name": "Rock_Sandstone_Brick"
    },
    {
      "x": 0,
      "y": -10,
      "z": 18,
      "name": "Rock_Sandstone"
    },
    {
      "x": 0,
      "y": -9,
      "z": 18,
      "name": "Rock_Sandstone_Cobble"
    },
    {
      "x": 0,
      "y": -8,
      "z": 18,
      "name": "Rock_Sandstone"
    },
    {
      "x": 0,
      "y": -7,
      "z": 18,
      "name": "Rock_Sandstone_Brick"
    },
    {
      "x": 0,
      "y": -6,
      "z": 18,
      "name": "Rock_Sandstone_Cobble"
    },
    {
      "x": 0,
      "y": -5,
      "z": 18,
      "name": "Rock_Sandstone_Brick"
    },
    {
      "x": 0,
      "y": -4,
      "z": 18,
      "name": "Rock_Sandstone"
    },
    {
      "x": 0,
      "y": -3,
      "z": 18,
      "name": "Rock_Sandstone_Brick"
    },
    {
      "x": 0,
      "y": -2,
      "z": 18,
      "name": "Rock_Sandstone_Brick"
    },
    {
      "x": 0,
      "y": -1,
      "z": 18,
      "name": "Rock_Sandstone_Brick"
    },
    {
      "x": 0,
      "y": 0,
      "z": 18,
      "name": "Rock_Sandstone_Brick"
    },
    {
      "x": 0,
      "y": 1,
      "z": 18,
      "name": "Rock_Sandstone_Brick"
    },
    {
      "x": 0,
      "y": 2,
      "z": 18,
      "name": "Rock_Sandstone_Brick"
    },
    {
      "x": 0,
      "y": 3,
      "z": 18,
      "name": "Rock_Sandstone_Brick"
    },
    {
      "x": 0,
      "y": 4,
      "z": 18,
      "name": "Rock_Sandstone_Brick"
    },
    {
      "x": 0,
      "y": 5,
      "z": 18,
      "name": "Rock_Sandstone"
    },
    {
      "x": 0,
      "y": 6,
      "z": 18,
      "name": "Rock_Sandstone_Cobble"
    },
    {
      "x": 0,
      "y": 7,
      "z": 18,
      "name": "Rock_Sandstone_Brick"
    },
    {
      "x": 0,
      "y": 8,
      "z": 18,
      "name": "Rock_Sandstone_Brick"
    },
    {
      "x": 0,
      "y": 9,
      "z": 18,
      "name": "Rock_Sandstone_Brick"
    },
    {
      "x": 0,
      "y": -35,
      "z": 19,
      "name": "Rock_Sandstone_Brick"
    },
    {
      "x": 0,
      "y": -34,
      "z": 19,
      "name": "Rock_Sandstone_Brick"
    },
    {
      "x": 0,
      "y": -33,
      "z": 19,
      "name": "Rock_Sandstone"
    },
    {
      "x": 0,
      "y": -32,
      "z": 19,
      "name": "Rock_Sandstone_Brick"
    },
    {
      "x": 0,
      "y": -31,
      "z": 19,
      "name": "Rock_Sandstone_Cobble"
    },
    {
      "x": 0,
      "y": -30,
      "z": 19,
      "name": "Rock_Sandstone_Brick"
    },
    {
      "x": 0,
      "y": -29,
      "z": 19,
      "name": "Rock_Sandstone"
    },
    {
      "x": 0,
      "y": -15,
      "z": 19,
      "name": "Rock_Sandstone_Cobble"
    },
    {
      "x": 0,
      "y": -14,
      "z": 19,
      "name": "Rock_Sandstone"
    },
    {
      "x": 0,
      "y": -13,
      "z": 19,
      "name": "Rock_Sandstone_Brick"
    },
    {
      "x": 0,
      "y": -12,
      "z": 19,
      "name": "Rock_Sandstone_Brick"
