{
  "version": 8,
  "blockIdVersion": 10,
  "anchorX": 0,
  "anchorY": 0,
  "anchorZ": 0,
  "blocks": [
    {
      "x": 5,
      "y": 13,
      "z": 0,
      "name": "Plant_Coral_Block_Yellow"
    },
    {
      "x": 6,
      "y": 13,
      "z": 0,
      "name": "Plant_Coral_Block_Yellow"
    },
    {
      "x": 2,
      "y": 14,
      "z": 0,
      "name": "Wood_Bamboo_Roots_Deco"
    },
    {
      "x": 3,
      "y": 14,
      "z": 0,
      "name": "Wood_Bamboo_Roots_Deco"
    },
    {
      "x": 5,
      "y": 14,
      "z": 0,
      "name": "Plant_Coral_Block_Yellow"
    },
    {
      "x": 0,
      "y": 15,
      "z": 0,
      "name": "Plant_Coral_Block_Pink"
    },
    {
      "x": 1,
      "y": 15,
      "z": 0,
      "name": "Plant_Coral_Block_Pink"
    },
    {
      "x": 2,
      "y": 15,
      "z": 0,
      "name": "Plant_Coral_Block_Purple"
    },
    {
      "x": 3,
      "y": 15,
      "z": 0,
      "name": "Plant_Coral_Block_Yellow"
    },
    {
      "x": 4,
      "y": 13,
      "z": 1,
      "name": "Wood_Bamboo_Roots_Deco"
    },
    {
      "x": 7,
      "y": 13,
      "z": 1,
      "name": "Plant_Coral_Block_Purple"
    },
    {
      "x": 0,
      "y": 14,
      "z": 1,
      "name": "Wood_Bamboo_Roots_Deco"
    },
    {
      "x": 2,
      "y": 14,
      "z": 1,
      "name": "Plant_Coral_Block_Pink"
    },
    {
      "x": 4,
      "y": 14,
      "z": 1,
      "name": "Plant_Coral_Block_Purple"
    },
    {
      "x": 5,
      "y": 14,
      "z": 1,
      "name": "Plant_Coral_Block_Purple"
    },
    {
      "x": 0,
      "y": 15,
      "z": 1,
      "name": "Plant_Coral_Block_Purple"
    },
    {
      "x": 1,
      "y": 15,
      "z": 1,
      "name": "Plant_Coral_Block_Pink"
    },
    {
      "x": 2,
      "y": 15,
      "z": 1,
      "name": "Plant_Coral_Block_Pink"
    },
    {
      "x": 4,
      "y": 13,
      "z": 2,
      "name": "Plant_Coral_Block_Pink"
    },
    {
      "x": 7,
      "y": 13,
      "z": 2,
      "name": "Plant_Coral_Block_Purple"
    },
    {
      "x": 0,
      "y": 14,
      "z": 2,
      "name": "Wood_Bamboo_Roots_Deco"
    },
    {
      "x": 2,
      "y": 14,
      "z": 2,
      "name": "Plant_Coral_Block_Pink"
    },
    {
      "x": 3,
      "y": 14,
      "z": 2,
      "name": "Plant_Coral_Block_Pink"
    },
    {
      "x": 4,
      "y": 14,
      "z": 2,
      "name": "Plant_Coral_Block_Pink"
    },
    {
      "x": 0,
      "y": 15,
      "z": 2,
      "name": "Plant_Coral_Block_Purple"
    },
    {
      "x": 2,
      "y": 13,
      "z": 3,
      "name": "Wood_Bamboo_Roots_Deco"
    },
    {
      "x": 4,
      "y": 13,
      "z": 3,
      "name": "Plant_Coral_Block_Pink"
    },
    {
      "x": 5,
      "y": 13,
      "z": 3,
      "name": "Plant_Coral_Block_Pink"
    },
    {
      "x": 6,
      "y": 13,
      "z": 3,
      "name": "Plant_Coral_Block_Pink"
    },
    {
      "x": 7,
      "y": 13,
      "z": 3,
      "name": "Plant_Coral_Block_Pink"
    },
    {
      "x": 0,
      "y": 14,
      "z": 3,
      "name": "Plant_Coral_Block_Yellow"
    },
    {
      "x": 2,
      "y": 14,
      "z": 3,
      "name": "Plant_Coral_Block_Purple"
    },
    {
      "x": 0,
      "y": 15,
      "z": 3,
      "name": "Plant_Coral_Block_Yellow"
    },
    {
      "x": 0,
      "y": 17,
      "z": 3,
      "name": "Plant_Coral_Block_Yellow"
    },
    {
      "x": 1,
      "y": 17,
      "z": 3,
      "name": "Plant_Coral_Block_Yellow"
    },
    {
      "x": 2,
      "y": 13,
      "z": 4,
      "name": "Plant_Coral_Block_Purple"
    },
    {
      "x": 3,
      "y": 13,
      "z": 4,
      "name": "Plant_Coral_Block_Yellow"
    },
    {
      "x": 5,
      "y": 13,
      "z": 4,
      "name": "Plant_Coral_Block_Purple"
    },
    {
      "x": 0,
      "y": 14,
      "z": 4,
      "name": "Plant_Coral_Block_Yellow"
    },
    {
      "x": 2,
      "y": 14,
      "z": 4,
      "name": "Plant_Coral_Block_Purple"
    },
    {
      "x": 3,
      "y": 13,
      "z": 5,
      "name": "Plant_Coral_Block_Yellow"
    },
    {
      "x": 5,
      "y": 13,
      "z": 5,
      "name": "Plant_Coral_Block_Purple"
    },
    {
      "x": 0,
      "y": 14,
      "z": 5,
      "name": "Plant_Coral_Block_Yellow"
    },
    {
      "x": 0,
      "y": 17,
      "z": 5,
      "name": "Plant_Coral_Block_Yellow"
    },
    {
      "x": 3,
      "y": 13,
      "z": 6,
      "name": "Plant_Coral_Block_Yellow"
    },
    {
      "x": 0,
      "y": 15,
      "z": 6,
      "name": "Wood_Bamboo_Roots_Deco"
    },
    {
      "x": 1,
      "y": 15,
      "z": 6,
      "name": "Wood_Bamboo_Roots_Deco"
    },
    {
      "x": 2,
      "y": 15,
      "z": 6,
      "name": "Wood_Bamboo_Roots_Deco"
    },
    {
      "x": 0,
      "y": 16,
      "z": 6,
      "name": "Plant_Coral_Block_Purple"
    },
    {
      "x": 1,
      "y": 16,
      "z": 6,
      "name": "Plant_Coral_Block_Yellow"
    },
    {
      "x": 2,
      "y": 16,
      "z": 6,
      "name": "Plant_Coral_Block_Yellow"
    },
    {
      "x": 0,
      "y": 17,
      "z": 6,
      "name": "Plant_Coral_Block_Yellow"
    },
    {
      "x": 0,
      "y": 15,
      "z": 7,
      "name": "Wood_Bamboo_Roots_Deco"
    },
    {
      "x": 0,
      "y": 16,
      "z": 7,
      "name": "Plant_Coral_Block_Purple"
    },
    {
      "x": 1,
      "y": 14,
      "z": 8,
      "name": "Wood_Bamboo_Roots_Deco"
    },
    {
      "x": 0,
      "y": 15,
      "z": 8,
      "name": "Wood_Bamboo_Roots_Deco"
    },
    {
      "x": 1,
      "y": 15,
      "z": 8,
      "name": "Rock_Crystal_Yellow_Block"
    },
    {
      "x": 2,
      "y": 15,
      "z": 8,
      "name": "Rock_Crystal_Yellow_Block"
    },
    {
      "x": 0,
      "y": 16,
      "z": 8,
      "name": "Plant_Coral_Block_Yellow"
    },
    {
      "x": 1,
      "y": 16,
      "z": 8,
      "name": "Plant_Coral_Block_Yellow"
    },
    {
      "x": 2,
      "y": 13,
      "z": 10,
      "name": "Wood_Bamboo_Roots_Deco"
    },
    {
      "x": 0,
      "y": 14,
      "z": 10,
      "name": "Wood_Bamboo_Roots_Deco"
    },
    {
      "x": 1,
      "y": 14,
      "z": 10,
      "name": "Wood_Bamboo_Roots_Deco"
    },
    {
      "x": 2,
      "y": 14,
      "z": 10,
      "name": "Plant_Coral_Block_Yellow"
    },
    {
      "x": 3,
      "y": 14,
      "z": 10,
      "name": "Plant_Coral_Block_Yellow"
    },
    {
      "x": 4,
      "y": 14,
      "z": 10,
      "name": "Wood_Bamboo_Roots_Deco"
    },
    {
      "x": 7,
      "y": 14,
      "z": 10,
      "name": "Wood_Bamboo_Roots_Deco"
    },
    {
      "x": 0,
      "y": 15,
      "z": 10,
      "name": "Plant_Coral_Block_Purple"
    },
    {
      "x": 1,
      "y": 15,
      "z": 10,
      "name": "Plant_Coral_Block_Purple"
    },
    {
      "x": 2,
      "y": 15,
      "z": 10,
      "name": "Plant_Coral_Block_Yellow"
    },
    {
      "x": 4,
      "y": 15,
      "z": 10,
      "name": "Plant_Coral_Block_Yellow"
    },
    {
      "x": 6,
      "y": 15,
      "z": 10,
      "name": "Plant_Coral_Block_Yellow"
    },
    {
      "x": 7,
      "y": 15,
      "z": 10,
      "name": "Rock_Crystal_Yellow_Block"
    },
    {
      "x": 3,
      "y": 14,
      "z": 11,
      "name": "Wood_Bamboo_Roots_Deco"
    },
    {
      "x": 4,
      "y": 14,
      "z": 11,
      "name": "Wood_Bamboo_Roots_Deco"
    },
    {
      "x": 0,
      "y": 15,
      "z": 11,
      "name": "Plant_Coral_Block_Pink"
    },
    {
      "x": 3,
      "y": 15,
      "z": 11,
      "name": "Plant_Coral_Block_Purple"
    },
    {
      "x": 4,
      "y": 15,
      "z": 11,
      "name": "Plant_Coral_Block_Purple"
    },
    {
      "x": 6,
      "y": 15,
      "z": 11,
      "name": "Plant_Coral_Block_Yellow"
    },
    {
      "x": 3,
      "y": 14,
      "z": 12,
      "name": "Wood_Bamboo_Roots_Deco"
    },
    {
      "x": 5,
      "y": 14,
      "z": 12,
      "name": "Wood_Bamboo_Roots_Deco"
    },
    {
      "x": 6,
      "y": 14,
      "z": 12,
      "name": "Wood_Bamboo_Roots_Deco"
    },
    {
      "x": 0,
      "y": 15,
      "z": 12,
      "name": "Plant_Coral_Block_Pink"
    },
    {
      "x": 1,
      "y": 15,
      "z": 12,
      "name": "Plant_Coral_Block_Pink"
    },
    {
      "x": 2,
      "y": 15,
      "z": 12,
      "name": "Plant_Coral_Block_Pink"
    },
    {
      "x": 3,
      "y": 15,
      "z": 12,
      "name": "Plant_Coral_Block_Purple"
    },
    {
      "x": 5,
      "y": 15,
      "z": 12,
      "name": "Plant_Coral_Block_Purple"
    },
    {
      "x": 6,
      "y": 15,
      "z": 12,
      "name": "Plant_Coral_Block_Yellow"
    },
    {
      "x": 9,
      "y": 13,
      "z": 13,
      "name": "Wood_Bamboo_Roots_Deco"
    },
    {
      "x": 5,
      "y": 14,
      "z": 13,
      "name": "Wood_Bamboo_Roots_Deco"
    },
    {
      "x": 6,
      "y": 14,
      "z": 13,
      "name": "Wood_Bamboo_Roots_Deco"
    },
    {
      "x": 7,
      "y": 14,
      "z": 13,
      "name": "Plant_Coral_Block_Yellow"
    },
    {
      "x": 8,
      "y": 14,
      "z": 13,
      "name": "Plant_Coral_Block_Yellow"
    },
    {
      "x": 9,
      "y": 14,
      "z": 13,
      "name": "Plant_Coral_Block_Yellow"
    },
    {
      "x": 0,
      "y": 15,
      "z": 13,
      "name": "Plant_Coral_Block_Purple"
    },
    {
      "x": 2,
      "y": 15,
      "z": 13,
      "name": "Plant_Coral_Block_Pink"
    },
    {
      "x": 3,
      "y": 15,
      "z": 13,
      "name": "Plant_Coral_Block_Pink"
    },
    {
      "x": 4,
      "y": 15,
      "z": 13,
      "name": "Plant_Coral_Block_Pink"
    },
    {
      "x": 5,
      "y": 15,
      "z": 13,
      "name": "Plant_Coral_Block_Purple"
    },
    {
      "x": 6,
      "y": 15,
      "z": 13,
      "name": "Plant_Coral_Block_Purple"
    },
    {
      "x": 7,
      "y": 15,
      "z": 13,
      "name": "Plant_Coral_Block_Yellow"
    },
    {
      "x": 0,
      "y": 14,
      "z": 14,
      "name": "Wood_Bamboo_Roots_Deco"
    },
    {
      "x": 2,
      "y": 14,
      "z": 14,
      "name": "Wood_Bamboo_Roots_Deco"
    },
    {
      "x": 4,
      "y": 14,
      "z": 14,
      "name": "Wood_Bamboo_Roots_Deco"
    },
    {
      "x": 5,
      "y": 14,
      "z": 14,
      "name": "Wood_Bamboo_Roots_Deco"
    },
    {
      "x": 0,
      "y": 15,
      "z": 14,
      "name": "Plant_Coral_Block_Purple"
    },
    {
      "x": 2,
      "y": 15,
      "z": 14,
      "name": "Plant_Coral_Block_Purple"
    },
    {
      "x": 4,
      "y": 15,
      "z": 14,
      "name": "Plant_Coral_Block_Purple"
    },
    {
      "x": 5,
      "y": 15,
      "z": 14,
      "name": "Plant_Coral_Block_Yellow"
    },
    {
      "x": 2,
      "y": 14,
      "z": 15,
      "name": "Wood_Bamboo_Roots_Deco"
    },
    {
      "x": 0,
      "y": 15,
      "z": 15,
      "name": "Plant_Coral_Block_Yellow"
    },
    {
      "x": 2,
      "y": 15,
      "z": 15,
      "name": "Plant_Coral_Block_Purple"
    },
    {
      "x": 5,
      "y": 15,
      "z": 15,
      "name": "Plant_Coral_Block_Yellow"
    },
    {
      "x": 6,
      "y": 15,
      "z": 15,
      "name": "Rock_Crystal_Yellow_Block"
    },
    {
      "x": 7,
      "y": 15,
      "z": 15,
      "name": "Rock_Crystal_Yellow_Block"
    },
    {
      "x": 0,
      "y": 16,
      "z": 15,
      "name": "Plant_Coral_Block_Yellow"
    },
    {
      "x": 8,
      "y": 5,
      "z": -13,
      "name": "Plant_Coral_Block_Yellow"
    },
    {
      "x": 11,
      "y": 3,
      "z": -12,
      "name": "Wood_Bamboo_Roots_Deco"
    },
    {
      "x": 10,
      "y": 4,
      "z": -12,
      "name": "Plant_Coral_Block_Yellow"
    },
    {
      "x": 11,
      "y": 4,
      "z": -12,
      "name": "Plant_Coral_Block_Yellow"
    },
    {
      "x": 14,
      "y": 4,
      "z": -12,
      "name": "Plant_Coral_Block_Yellow"
    },
    {
      "x": 15,
      "y": 4,
      "z": -12,
      "name": "Plant_Coral_Block_Yellow"
    },
    {
      "x": 7,
      "y": 5,
      "z": -12,
      "name": "Plant_Coral_Block_Yellow"
    },
    {
      "x": 8,
      "y": 5,
      "z": -12,
      "name": "Plant_Coral_Block_Yellow"
    },
    {
      "x": 13,
      "y": 3,
      "z": -11,
      "name": "Wood_Bamboo_Roots_Deco"
    },
    {
      "x": 14,
      "y": 3,
      "z": -11,
      "name": "Wood_Bamboo_Roots_Deco"
    },
    {
      "x": 7,
      "y": 4,
      "z": -11,
      "name": "Wood_Bamboo_Roots_Deco"
    },
    {
      "x": 10,
      "y": 4,
      "z": -11,
      "name": "Plant_Coral_Block_Yellow"
    },
    {
      "x": 13,
      "y": 4,
      "z": -11,
      "name": "Plant_Coral_Block_Purple"
    },
    {
      "x": 14,
      "y": 4,
      "z": -11,
      "name": "Plant_Coral_Block_Yellow"
    },
    {
      "x": 7,
      "y": 5,
      "z": -11,
      "name": "Rock_Crystal_Yellow_Block"
    },
    {
      "x": 9,
      "y": 5,
      "z": -11,
      "name": "Plant_Coral_Block_Yellow"
    },
    {
      "x": 10,
      "y": 5,
      "z": -11,
      "name": "Plant_Coral_Block_Yellow"
    },
    {
      "x": 5,
      "y": 6,
      "z": -11,
      "name": "Wood_Bamboo_Roots_Deco"
    },
    {
      "x": 7,
      "y": 6,
      "z": -11,
      "name": "Plant_Coral_Block_Yellow"
    },
    {
      "x": 5,
      "y": 7,
      "z": -11,
      "name": "Rock_Crystal_Yellow_Block"
    },
    {
      "x": 1,
      "y": 12,
      "z": -11,
      "name": "Wood_Bamboo_Roots_Deco"
    },
    {
      "x": 11,
      "y": 3,
      "z": -10,
      "name": "Wood_Bamboo_Roots_Deco"
    },
    {
      "x": 13,
      "y": 3,
      "z": -10,
      "name": "Wood_Bamboo_Roots_Deco"
    },
    {
      "x": 11,
      "y": 4,
      "z": -10,
      "name": "Plant_Coral_Block_Purple"
    },
    {
      "x": 12,
      "y": 4,
      "z": -10,
      "name": "Plant_Coral_Block_Purple"
    },
    {
      "x": 13,
      "y": 4,
      "z": -10,
      "name": "Plant_Coral_Block_Purple"
    },
    {
      "x": 7,
      "y": 5,
      "z": -10,
      "name": "Wood_Bamboo_Roots_Deco"
    },
    {
      "x": 9,
      "y": 5,
      "z": -10,
      "name": "Plant_Coral_Block_Purple"
    },
    {
      "x": 7,
      "y": 6,
      "z": -10,
      "name": "Plant_Coral_Block_Purple"
    },
    {
      "x": 5,
      "y": 7,
      "z": -10,
      "name": "Plant_Coral_Block_Yellow"
    },
    {
      "x": 3,
      "y": 12,
      "z": -10,
      "name": "Rock_Crystal_Yellow_Block"
    },
    {
      "x": 15,
      "y": 3,
      "z": -9,
      "name": "Wood_Bamboo_Roots_Deco"
    },
    {
      "x": 10,
      "y": 4,
      "z": -9,
      "name": "Plant_Coral_Block_Pink"
    },
    {
      "x": 11,
      "y": 4,
      "z": -9,
      "name": "Plant_Coral_Block_Pink"
    },
    {
      "x": 12,
      "y": 4,
      "z": -9,
      "name": "Plant_Coral_Block_Pink"
    },
    {
      "x": 13,
      "y": 4,
      "z": -9,
      "name": "Plant_Coral_Block_Pink"
    },
    {
      "x": 14,
      "y": 4,
      "z": -9,
      "name": "Plant_Coral_Block_Purple"
    },
    {
      "x": 15,
      "y": 4,
      "z": -9,
      "name": "Plant_Coral_Block_Yellow"
    },
    {
      "x": 7,
      "y": 5,
      "z": -9,
      "name": "Wood_Bamboo_Roots_Deco"
    },
    {
      "x": 8,
      "y": 5,
      "z": -9,
      "name": "Plant_Coral_Block_Pink"
    },
    {
      "x": 9,
      "y": 5,
      "z": -9,
      "name": "Plant_Coral_Block_Pink"
    },
    {
      "x": 10,
      "y": 5,
      "z": -9,
      "name": "Plant_Coral_Block_Pink"
    },
    {
      "x": 15,
      "y": 5,
      "z": -9,
      "name": "Plant_Coral_Block_Yellow"
    },
    {
      "x": 5,
      "y": 6,
      "z": -9,
      "name": "Wood_Bamboo_Roots_Deco"
    },
    {
      "x": 7,
      "y": 6,
      "z": -9,
      "name": "Plant_Coral_Block_Purple"
    },
    {
      "x": 8,
      "y": 6,
      "z": -9,
      "name": "Plant_Coral_Block_Pink"
    },
    {
      "x": 5,
      "y": 7,
      "z": -9,
      "name": "Plant_Coral_Block_Yellow"
    },
    {
      "x": 5,
      "y": 8,
      "z": -9,
      "name": "Plant_Coral_Block_Yellow"
    },
    {
      "x": 3,
      "y": 10,
      "z": -9,
      "name": "Wood_Bamboo_Roots_Deco"
    },
    {
      "x": 0,
      "y": 11,
      "z": -9,
      "name": "Wood_Bamboo_Roots_Deco"
    },
    {
      "x": 3,
      "y": 11,
      "z": -9,
      "name": "Plant_Coral_Block_Yellow"
    },
    {
      "x": 0,
      "y": 12,
      "z": -9,
      "name": "Plant_Coral_Block_Yellow"
    },
    {
      "x": 1,
      "y": 12,
      "z": -9,
      "name": "Wood_Bamboo_Roots_Deco"
    },
    {
      "x": 3,
      "y": 12,
      "z": -9,
      "name": "Plant_Coral_Block_Yellow"
    },
    {
      "x": 12,
      "y": 3,
      "z": -8,
      "name": "Wood_Bamboo_Roots_Deco"
    },
    {
      "x": 13,
      "y": 3,
      "z": -8,
      "name": "Wood_Bamboo_Roots_Deco"
    },
    {
      "x": 9,
      "y": 4,
      "z": -8,
      "name": "Wood_Bamboo_Roots_Deco"
    },
    {
      "x": 10,
      "y": 4,
      "z": -8,
      "name": "Wood_Bamboo_Roots_Deco"
    },
    {
      "x": 12,
      "y": 4,
      "z": -8,
      "name": "Plant_Coral_Block_Purple"
    },
    {
      "x": 13,
      "y": 4,
      "z": -8,
      "name": "Plant_Coral_Block_Purple"
    },
    {
      "x": 9,
      "y": 5,
      "z": -8,
      "name": "Plant_Coral_Block_Purple"
    },
    {
      "x": 10,
      "y": 5,
      "z": -8,
      "name": "Plant_Coral_Block_Purple"
    },
    {
      "x": 7,
      "y": 6,
      "z": -8,
      "name": "Plant_Coral_Block_Pink"
    },
    {
      "x": 8,
      "y": 6,
      "z": -8,
      "name": "Plant_Coral_Block_Pink"
    },
    {
      "x": 3,
      "y": 7,
      "z": -8,
      "name": "Wood_Bamboo_Roots_Deco"
    },
    {
      "x": 5,
      "y": 7,
      "z": -8,
      "name": "Wood_Bamboo_Roots_Deco"
    },
    {
      "x": 7,
      "y": 7,
      "z": -8,
      "name": "Plant_Coral_Block_Pink"
    },
    {
      "x": 3,
      "y": 8,
      "z": -8,
      "name": "Plant_Coral_Block_Yellow"
    },
    {
      "x": 5,
      "y": 8,
      "z": -8,
      "name": "Plant_Coral_Block_Purple"
    },
    {
      "x": 2,
      "y": 9,
      "z": -8,
      "name": "Wood_Bamboo_Roots_Deco"
    },
    {
      "x": 2,
      "y": 10,
      "z": -8,
      "name": "Plant_Coral_Block_Yellow"
    },
    {
      "x": 3,
      "y": 10,
      "z": -8,
      "name": "Wood_Bamboo_Roots_Deco"
    },
    {
      "x": 2,
      "y": 11,
      "z": -8,
      "name": "Plant_Coral_Block_Yellow"
    },
    {
      "x": 3,
      "y": 11,
      "z": -8,
      "name": "Rock_Crystal_Yellow_Block"
    },
    {
      "x": 0,
      "y": 12,
      "z": -8,
      "name": "Plant_Coral_Block_Yellow"
    },
    {
      "x": 10,
      "y": 3,
      "z": -7,
      "name": "Wood_Bamboo_Roots_Deco"
    },
    {
      "x": 13,
      "y": 3,
      "z": -7,
      "name": "Wood_Bamboo_Roots_Deco"
    },
    {
      "x": 14,
      "y": 3,
      "z": -7,
      "name": "Wood_Bamboo_Roots_Deco"
    },
    {
      "x": 10,
      "y": 4,
      "z": -7,
      "name": "Plant_Coral_Block_Yellow"
    },
    {
      "x": 11,
      "y": 4,
      "z": -7,
      "name": "Rock_Crystal_Yellow_Block"
    },
    {
      "x": 13,
      "y": 4,
      "z": -7,
      "name": "Plant_Coral_Block_Purple"
    },
    {
      "x": 14,
      "y": 4,
      "z": -7,
      "name": "Plant_Coral_Block_Yellow"
    },
    {
      "x": 15,
      "y": 4,
      "z": -7,
      "name": "Plant_Coral_Block_Yellow"
    },
    {
      "x": 10,
      "y": 5,
      "z": -7,
      "name": "Plant_Coral_Block_Purple"
    },
    {
      "x": 8,
      "y": 6,
      "z": -7,
      "name": "Wood_Bamboo_Roots_Deco"
    },
    {
      "x": 5,
      "y": 7,
      "z": -7,
      "name": "Wood_Bamboo_Roots_Deco"
    },
    {
      "x": 6,
      "y": 7,
      "z": -7,
      "name": "Plant_Coral_Block_Pink"
    },
    {
      "x": 7,
      "y": 7,
      "z": -7,
      "name": "Plant_Coral_Block_Pink"
    },
    {
      "x": 8,
      "y": 7,
      "z": -7,
      "name": "Plant_Coral_Block_Purple"
    },
    {
      "x": 1,
      "y": 8,
      "z": -7,
      "name": "Wood_Bamboo_Roots_Deco"
    },
    {
      "x": 3,
      "y": 8,
      "z": -7,
      "name": "Plant_Coral_Block_Yellow"
    },
    {
      "x": 5,
      "y": 8,
      "z": -7,
      "name": "Plant_Coral_Block_Purple"
    },
    {
      "x": 6,
      "y": 8,
      "z": -7,
      "name": "Plant_Coral_Block_Pink"
    },
    {
      "x": 1,
      "y": 9,
      "z": -7,
      "name": "Plant_Coral_Block_Purple"
    },
    {
      "x": 2,
      "y": 9,
      "z": -7,
      "name": "Wood_Bamboo_Roots_Deco"
    },
    {
      "x": 1,
      "y": 10,
      "z": -7,
      "name": "Plant_Coral_Block_Yellow"
    },
    {
      "x": 2,
      "y": 10,
      "z": -7,
      "name": "Plant_Coral_Block_Yellow"
    },
    {
      "x": 0,
      "y": 12,
      "z": -7,
      "name": "Plant_Coral_Block_Purple"
    },
    {
      "x": 11,
      "y": 4,
      "z": -6,
      "name": "Plant_Coral_Block_Yellow"
    },
    {
      "x": 8,
      "y": 6,
      "z": -6,
      "name": "Plant_Coral_Block_Yellow"
    },
    {
      "x": 9,
      "y": 6,
      "z": -6,
      "name": "Plant_Coral_Block_Yellow"
    },
    {
      "x": 4,
      "y": 7,
      "z": -6,
      "name": "Wood_Bamboo_Roots_Deco"
    },
    {
      "x": 8,
      "y": 7,
      "z": -6,
      "name": "Plant_Coral_Block_Yellow"
    },
    {
      "x": 0,
      "y": 8,
      "z": -6,
      "name": "Wood_Bamboo_Roots_Deco"
    },
    {
      "x": 1,
      "y": 8,
      "z": -6,
      "name": "Wood_Bamboo_Roots_Deco"
    },
    {
      "x": 3,
      "y": 8,
      "z": -6,
      "name": "Plant_Coral_Block_Yellow"
    },
    {
      "x": 4,
      "y": 8,
      "z": -6,
      "name": "Plant_Coral_Block_Purple"
    },
    {
      "x": 6,
      "y": 8,
      "z": -6,
      "name": "Plant_Coral_Block_Pink"
    },
    {
      "x": 0,
      "y": 9,
      "z": -6,
      "name": "Plant_Coral_Block_Purple"
    },
    {
      "x": 1,
      "y": 9,
      "z": -6,
      "name": "Plant_Coral_Block_Purple"
    },
    {
      "x": 9,
      "y": 5,
      "z": -5,
      "name": "Wood_Bamboo_Roots_Deco"
    },
    {
      "x": 9,
      "y": 6,
      "z": -5,
      "name": "Plant_Coral_Block_Yellow"
    },
    {
      "x": 10,
      "y": 6,
      "z": -5,
      "name": "Plant_Coral_Block_Yellow"
    },
    {
      "x": 4,
      "y": 7,
      "z": -5,
      "name": "Wood_Bamboo_Roots_Deco"
    },
    {
      "x": 2,
      "y": 8,
      "z": -5,
      "name": "Plant_Coral_Block_Yellow"
    },
    {
      "x": 4,
      "y": 8,
      "z": -5,
      "name": "Plant_Coral_Block_Purple"
    },
    {
      "x": 5,
      "y": 8,
      "z": -5,
      "name": "Plant_Coral_Block_Pink"
    },
    {
      "x": 6,
      "y": 8,
      "z": -5,
      "name": "Plant_Coral_Block_Pink"
    },
    {
      "x": 7,
      "y": 6,
      "z": -4,
      "name": "Wood_Bamboo_Roots_Deco"
    },
    {
      "x": 8,
      "y": 6,
      "z": -4,
      "name": "Wood_Bamboo_Roots_Deco"
    },
    {
      "x": 2,
      "y": 7,
      "z": -4,
      "name": "Plant_Coral_Block_Yellow"
    },
    {
      "x": 4,
      "y": 7,
      "z": -4,
      "name": "Wood_Bamboo_Roots_Deco"
    },
    {
      "x": 6,
      "y": 7,
      "z": -4,
      "name": "Wood_Bamboo_Roots_Deco"
    },
    {
      "x": 7,
      "y": 7,
      "z": -4,
      "name": "Plant_Coral_Block_Yellow"
    },
    {
      "x": 8,
      "y": 7,
      "z": -4,
      "name": "Plant_Coral_Block_Yellow"
    },
    {
      "x": 9,
      "y": 7,
      "z": -4,
      "name": "Plant_Coral_Block_Yellow"
    },
    {
      "x": 2,
      "y": 8,
      "z": -4,
      "name": "Plant_Coral_Block_Yellow"
    },
    {
      "x": 4,
      "y": 8,
      "z": -4,
      "name": "Plant_Coral_Block_Purple"
    },
    {
      "x": 5,
      "y": 8,
      "z": -4,
      "name": "Plant_Coral_Block_Pink"
    },
    {
      "x": 6,
      "y": 8,
      "z": -4,
      "name": "Plant_Coral_Block_Purple"
    },
    {
      "x": 7,
      "y": 8,
      "z": -4,
      "name": "Plant_Coral_Block_Purple"
    },
    {
      "x": 3,
      "y": 6,
      "z": -3,
      "name": "Wood_Bamboo_Roots_Deco"
    },
    {
      "x": 2,
      "y": 7,
      "z": -3,
      "name": "Plant_Coral_Block_Yellow"
    },
    {
      "x": 3,
      "y": 7,
      "z": -3,
      "name": "Plant_Coral_Block_Purple"
    },
    {
      "x": 5,
      "y": 8,
      "z": -3,
      "name": "Plant_Coral_Block_Pink"
    },
    {
      "x": 0,
      "y": 0,
      "z": -2,
      "name": "Plant_Coral_Block_Pink"
    },
    {
      "x": 0,
      "y": 1,
      "z": -2,
      "name": "Plant_Coral_Block_Pink"
    },
    {
      "x": 0,
      "y": 2,
      "z": -2,
      "name": "Plant_Coral_Block_Pink"
    },
    {
      "x": 1,
      "y": 2,
      "z": -2,
      "name": "Plant_Coral_Block_Pink"
    },
    {
      "x": 1,
      "y": 3,
      "z": -2,
      "name": "Plant_Coral_Block_Pink"
    },
    {
      "x": 1,
      "y": 4,
      "z": -2,
      "name": "Plant_Coral_Block_Pink"
    },
    {
      "x": 3,
      "y": 6,
      "z": -2,
      "name": "Wood_Bamboo_Roots_Deco"
    },
    {
      "x": 8,
      "y": 6,
      "z": -2,
      "name": "Wood_Bamboo_Roots_Deco"
    },
    {
      "x": 9,
      "y": 6,
      "z": -2,
      "name": "Wood_Bamboo_Roots_Deco"
    },
    {
      "x": 10,
      "y": 6,
      "z": -2,
      "name": "Wood_Bamboo_Roots_Deco"
    },
    {
      "x": 3,
      "y": 7,
      "z": -2,
      "name": "Plant_Coral_Block_Purple"
    },
    {
      "x": 4,
      "y": 7,
      "z": -2,
      "name": "Plant_Coral_Block_Pink"
    },
    {
      "x": 6,
      "y": 7,
      "z": -2,
      "name": "Wood_Bamboo_Roots_Deco"
    },
    {
      "x": 7,
      "y": 7,
      "z": -2,
      "name": "Wood_Bamboo_Roots_Deco"
    },
    {
      "x": 8,
      "y": 7,
      "z": -2,
      "name": "Plant_Coral_Block_Yellow"
    },
    {
      "x": 9,
      "y": 7,
      "z": -2,
      "name": "Rock_Crystal_Yellow_Block"
    },
    {
      "x": 10,
      "y": 7,
      "z": -2,
      "name": "Plant_Coral_Block_Yellow"
    },
    {
      "x": 4,
      "y": 8,
      "z": -2,
      "name": "Plant_Coral_Block_Pink"
    },
    {
      "x": 5,
      "y": 8,
      "z": -2,
      "name": "Plant_Coral_Block_Pink"
    },
    {
      "x": 6,
      "y": 8,
      "z": -2,
      "name": "Plant_Coral_Block_Purple"
    },
    {
      "x": 7,
      "y": 8,
      "z": -2,
      "name": "Plant_Coral_Block_Purple"
    },
    {
      "x": 8,
      "y": 8,
      "z": -2,
      "name": "Plant_Coral_Block_Yellow"
    },
    {
      "x": 0,
      "y": 0,
      "z": -1,
      "name": "Plant_Coral_Block_Pink"
    },
    {
      "x": 0,
      "y": 1,
      "z": -1,
      "name": "Plant_Coral_Block_Pink"
    },
    {
      "x": 0,
      "y": 2,
      "z": -1,
      "name": "Plant_Coral_Block_Pink"
    },
    {
      "x": 0,
      "y": 3,
      "z": -1,
      "name": "Plant_Coral_Block_Pink"
    },
    {
      "x": 1,
      "y": 4,
      "z": -1,
      "name": "Plant_Coral_Block_Pink"
    },
    {
      "x": 2,
      "y": 4,
      "z": -1,
      "name": "Plant_Coral_Block_Pink"
    },
    {
      "x": 1,
      "y": 5,
      "z": -1,
      "name": "Plant_Coral_Block_Pink"
    },
    {
      "x": 2,
      "y": 5,
      "z": -1,
      "name": "Plant_Coral_Block_Pink"
    },
    {
      "x": 1,
      "y": 6,
      "z": -1,
      "name": "Plant_Coral_Block_Pink"
    },
    {
      "x": 2,
      "y": 6,
      "z": -1,
      "name": "Plant_Coral_Block_Pink"
    },
    {
      "x": 3,
      "y": 6,
      "z": -1,
      "name": "Plant_Coral_Block_Pink"
    },
    {
      "x": 2,
      "y": 7,
      "z": -1,
      "name": "Plant_Coral_Block_Pink"
    },
    {
      "x": 3,
      "y": 7,
      "z": -1,
      "name": "Plant_Coral_Block_Pink"
    },
    {
      "x": 4,
      "y": 7,
      "z": -1,
      "name": "Plant_Coral_Block_Pink"
    },
    {
      "x": 12,
      "y": 11,
      "z": -1,
      "name": "Plant_Coral_Block_Yellow"
    },
    {
      "x": 7,
      "y": 12,
      "z": -1,
      "name": "Wood_Bamboo_Roots_Deco"
    },
    {
      "x": 16,
      "y": 4,
      "z": -9,
      "name": "Wood_Bamboo_Roots_Deco"
    },
    {
      "x": 16,
      "y": 5,
      "z": -9,
      "name": "Plant_Coral_Block_Yellow"
    },
    {
      "x": 17,
      "y": 5,
      "z": -9,
      "name": "Plant_Coral_Block_Yellow"
    },
    {
      "x": 1,
      "y": 13,
      "z": -11,
      "name": "Plant_Coral_Block_Yellow"
    },
    {
      "x": 1,
      "y": 13,
      "z": -10,
      "name": "Plant_Coral_Block_Yellow"
    },
    {
      "x": 0,
      "y": 13,
      "z": -9,
      "name": "Plant_Coral_Block_Yellow"
    },
    {
      "x": 1,
      "y": 13,
      "z": -9,
      "name": "Rock_Crystal_Yellow_Block"
    },
    {
      "x": 3,
      "y": 14,
      "z": -4,
      "name": "Wood_Bamboo_Roots_Deco"
    },
    {
      "x": 3,
      "y": 15,
      "z": -4,
      "name": "Plant_Coral_Block_Yellow"
    },
    {
      "x": 4,
      "y": 15,
      "z": -4,
      "name": "Plant_Coral_Block_Yellow"
    },
    {
      "x": 1,
      "y": 14,
      "z": -3,
      "name": "Wood_Bamboo_Roots_Deco"
    },
    {
      "x": 2,
      "y": 14,
      "z": -3,
      "name": "Wood_Bamboo_Roots_Deco"
    },
    {
      "x": 1,
      "y": 15,
      "z": -3,
      "name": "Plant_Coral_Block_Yellow"
    },
    {
      "x": 2,
      "y": 15,
      "z": -3,
      "name": "Plant_Coral_Block_Yellow"
    },
    {
      "x": 3,
      "y": 15,
      "z": -3,
      "name": "Plant_Coral_Block_Yellow"
    },
    {
      "x": 4,
      "y": 13,
      "z": -2,
      "name": "Wood_Bamboo_Roots_Deco"
    },
    {
      "x": 0,
      "y": 14,
      "z": -2,
      "name": "Wood_Bamboo_Roots_Deco"
    },
    {
      "x": 4,
      "y": 14,
      "z": -2,
      "name": "Plant_Coral_Block_Yellow"
    },
    {
      "x": 5,
      "y": 14,
      "z": -2,
      "name": "Plant_Coral_Block_Yellow"
    },
    {
      "x": 0,
      "y": 15,
      "z": -2,
      "name": "Plant_Coral_Block_Purple"
    },
    {
      "x": 1,
      "y": 15,
      "z": -2,
      "name": "Plant_Coral_Block_Purple"
    },
    {
      "x": 6,
      "y": 13,
      "z": -1,
      "name": "Plant_Coral_Block_Yellow"
    },
    {
      "x": 7,
      "y": 13,
      "z": -1,
      "name": "Plant_Coral_Block_Yellow"
    },
    {
      "x": 4,
      "y": 14,
      "z": -1,
      "name": "Rock_Crystal_Yellow_Block"
    },
    {
      "x": 0,
      "y": 15,
      "z": -1,
      "name": "Plant_Coral_Block_Pink"
    },
    {
      "x": 3,
      "y": 15,
      "z": -1,
      "name": "Plant_Coral_Block_Yellow"
    },
    {
      "x": 4,
      "y": 15,
      "z": -1,
      "name": "Rock_Crystal_Yellow_Block"
    },
    {
      "x": -6,
      "y": 14,
      "z": -16,
      "name": "Rock_Crystal_Yellow_Block"
    },
    {
      "x": -6,
      "y": 13,
      "z": -15,
      "name": "Rock_Crystal_Yellow_Block"
    },
    {
      "x": -6,
      "y": 14,
      "z": -15,
      "name": "Plant_Coral_Block_Yellow"
    },
    {
      "x": -6,
      "y": 13,
      "z": -14,
      "name": "Plant_Coral_Block_Yellow"
    },
    {
      "x": -4,
      "y": 14,
      "z": -14,
      "name": "Plant_Coral_Block_Yellow"
    },
    {
      "x": -4,
      "y": 14,
      "z": -13,
      "name": "Plant_Coral_Block_Yellow"
    },
    {
      "x": -2,
      "y": 14,
      "z": -13,
      "name": "Plant_Coral_Block_Yellow"
    },
    {
      "x": -4,
      "y": 13,
      "z": -12,
      "name": "Plant_Coral_Block_Purple"
    },
    {
      "x": -4,
      "y": 14,
      "z": -12,
      "name": "Plant_Coral_Block_Yellow"
    },
    {
      "x": -2,
      "y": 14,
      "z": -12,
      "name": "Plant_Coral_Block_Yellow"
    },
    {
      "x": -5,
      "y": 13,
      "z": -11,
      "name": "Plant_Coral_Block_Pink"
    },
    {
      "x": -4,
      "y": 13,
      "z": -11,
      "name": "Plant_Coral_Block_Purple"
    },
    {
      "x": -2,
      "y": 13,
      "z": -11,
      "name": "Plant_Coral_Block_Yellow"
    },
    {
      "x": -2,
      "y": 14,
      "z": -11,
      "name": "Plant_Coral_Block_Yellow"
    },
    {
      "x": -5,
      "y": 13,
      "z": -10,
      "name": "Plant_Coral_Block_Pink"
    },
    {
      "x": -4,
      "y": 13,
      "z": -10,
      "name": "Plant_Coral_Block_Pink"
    },
    {
      "x": -2,
      "y": 13,
      "z": -10,
      "name": "Plant_Coral_Block_Yellow"
    },
    {
      "x": -4,
      "y": 13,
      "z": -9,
      "name": "Plant_Coral_Block_Pink"
    },
    {
      "x": -3,
      "y": 13,
      "z": -9,
      "name": "Plant_Coral_Block_Pink"
    },
    {
      "x": -2,
      "y": 13,
      "z": -9,
      "name": "Plant_Coral_Block_Purple"
    },
    {
      "x": -3,
      "y": 13,
      "z": -8,
      "name": "Plant_Coral_Block_Pink"
    },
    {
      "x": -2,
      "y": 13,
      "z": -8,
      "name": "Plant_Coral_Block_Pink"
    },
    {
      "x": -1,
      "y": 13,
      "z": -3,
      "name": "Plant_Coral_Block_Pink"
    },
    {
      "x": -1,
      "y": 14,
      "z": -3,
      "name": "Plant_Coral_Block_Pink"
    },
    {
      "x": -3,
      "y": 14,
      "z": -2,
      "name": "Wood_Bamboo_Roots_Deco"
    },
    {
      "x": -1,
      "y": 14,
      "z": -2,
      "name": "Plant_Coral_Block_Pink"
    },
    {
      "x": -5,
      "y": 15,
      "z": -2,
      "name": "Wood_Bamboo_Roots_Deco"
    },
    {
      "x": -4,
      "y": 15,
      "z": -2,
      "name": "Plant_Coral_Block_Purple"
    },
    {
      "x": -3,
      "y": 15,
      "z": -2,
      "name": "Plant_Coral_Block_Purple"
    },
    {
      "x": -2,
      "y": 15,
      "z": -2,
      "name": "Plant_Coral_Block_Pink"
    },
    {
      "x": -1,
      "y": 15,
      "z": -2,
      "name": "Plant_Coral_Block_Pink"
    },
    {
      "x": -5,
      "y": 16,
      "z": -2,
      "name": "Plant_Coral_Block_Yellow"
    },
    {
      "x": -4,
      "y": 16,
      "z": -2,
      "name": "Plant_Coral_Block_Yellow"
    },
    {
      "x": -2,
      "y": 16,
      "z": -2,
      "name": "Plant_Coral_Block_Pink"
    },
    {
      "x": -1,
      "y": 15,
      "z": -1,
      "name": "Plant_Coral_Block_Pink"
    },
    {
      "x": -7,
      "y": 16,
      "z": -1,
      "name": "Rock_Crystal_Yellow_Block"
    },
    {
      "x": -6,
      "y": 16,
      "z": -1,
      "name": "Rock_Crystal_Yellow_Block"
    },
    {
      "x": -5,
      "y": 16,
      "z": -1,
      "name": "Rock_Crystal_Yellow_Block"
    },
    {
      "x": -3,
      "y": 16,
      "z": -1,
      "name": "Wood_Bamboo_Roots_Deco"
    },
    {
      "x": -2,
      "y": 16,
      "z": -1,
      "name": "Plant_Coral_Block_Pink"
    },
    {
      "x": -4,
      "y": 17,
      "z": -1,
      "name": "Plant_Coral_Block_Purple"
    },
    {
      "x": -3,
      "y": 17,
      "z": -1,
      "name": "Plant_Coral_Block_Purple"
    },
    {
      "x": -2,
      "y": 17,
      "z": -1,
      "name": "Plant_Coral_Block_Pink"
    },
    {
      "x": -11,
      "y": 7,
      "z": -16,
      "name": "Plant_Coral_Block_Yellow"
    },
    {
      "x": -10,
      "y": 7,
      "z": -16,
      "name": "Plant_Coral_Block_Yellow"
    },
    {
      "x": -7,
      "y": 9,
      "z": -16,
      "name": "Wood_Bamboo_Roots_Deco"
    },
    {
      "x": -7,
      "y": 10,
      "z": -16,
      "name": "Plant_Coral_Block_Purple"
    },
    {
      "x": -8,
      "y": 11,
      "z": -16,
      "name": "Plant_Coral_Block_Yellow"
    },
    {
      "x": -7,
      "y": 11,
      "z": -16,
      "name": "Plant_Coral_Block_Yellow"
    },
    {
      "x": -10,
      "y": 7,
      "z": -15,
      "name": "Plant_Coral_Block_Yellow"
    },
    {
      "x": -10,
      "y": 8,
      "z": -15,
      "name": "Plant_Coral_Block_Yellow"
    },
    {
      "x": -9,
      "y": 8,
      "z": -15,
      "name": "Plant_Coral_Block_Purple"
    },
    {
      "x": -7,
      "y": 9,
      "z": -15,
      "name": "Wood_Bamboo_Roots_Deco"
    },
    {
      "x": -7,
      "y": 10,
      "z": -15,
      "name": "Plant_Coral_Block_Purple"
    },
    {
      "x": -9,
      "y": 7,
      "z": -14,
      "name": "Wood_Bamboo_Roots_Deco"
    },
    {
      "x": -8,
      "y": 7,
      "z": -14,
      "name": "Wood_Bamboo_Roots_Deco"
    },
    {
      "x": -9,
      "y": 8,
      "z": -14,
      "name": "Plant_Coral_Block_Purple"
    },
    {
      "x": -8,
      "y": 8,
      "z": -14,
      "name": "Plant_Coral_Block_Purple"
    },
    {
      "x": -7,
      "y": 9,
      "z": -14,
      "name": "Wood_Bamboo_Roots_Deco"
    },
    {
      "x": -7,
      "y": 10,
      "z": -14,
      "name": "Plant_Coral_Block_Purple"
    },
    {
      "x": -7,
      "y": 11,
      "z": -14,
      "name": "Wood_Bamboo_Roots_Deco"
    },
    {
      "x": -6,
      "y": 11,
      "z": -14,
      "name": "Wood_Bamboo_Roots_Deco"
    },
    {
      "x": -7,
      "y": 12,
      "z": -14,
      "name": "Plant_Coral_Block_Purple"
    },
    {
      "x": -6,
      "y": 12,
      "z": -14,
      "name": "Plant_Coral_Block_Yellow"
    },
    {
      "x": -13,
      "y": 4,
      "z": -13,
      "name": "Wood_Bamboo_Roots_Deco"
    },
    {
      "x": -13,
      "y": 5,
      "z": -13,
      "name": "Plant_Coral_Block_Yellow"
    },
    {
      "x": -12,
      "y": 5,
      "z": -13,
      "name": "Plant_Coral_Block_Yellow"
    },
    {
      "x": -11,
      "y": 5,
      "z": -13,
      "name": "Plant_Coral_Block_Yellow"
    },
    {
      "x": -10,
      "y": 5,
      "z": -13,
      "name": "Wood_Bamboo_Roots_Deco"
    },
    {
      "x": -11,
      "y": 6,
      "z": -13,
      "name": "Plant_Coral_Block_Yellow"
    },
    {
      "x": -10,
      "y": 6,
      "z": -13,
      "name": "Plant_Coral_Block_Yellow"
    },
    {
      "x": -8,
      "y": 7,
      "z": -13,
      "name": "Plant_Coral_Block_Pink"
    },
    {
      "x": -8,
      "y": 8,
      "z": -13,
      "name": "Plant_Coral_Block_Pink"
    },
    {
      "x": -8,
      "y": 9,
      "z": -13,
      "name": "Plant_Coral_Block_Pink"
    },
    {
      "x": -7,
      "y": 9,
      "z": -13,
      "name": "Plant_Coral_Block_Pink"
    },
    {
      "x": -7,
      "y": 10,
      "z": -13,
      "name": "Plant_Coral_Block_Pink"
    },
    {
      "x": -7,
      "y": 11,
      "z": -13,
      "name": "Plant_Coral_Block_Pink"
    },
    {
      "x": -7,
      "y": 12,
      "z": -13,
      "name": "Plant_Coral_Block_Purple"
    },
    {
      "x": -10,
      "y": 5,
      "z": -12,
      "name": "Wood_Bamboo_Roots_Deco"
    },
    {
      "x": -9,
      "y": 5,
      "z": -12,
      "name": "Wood_Bamboo_Roots_Deco"
    },
    {
      "x": -10,
      "y": 6,
      "z": -12,
      "name": "Plant_Coral_Block_Purple"
    },
    {
      "x": -9,
      "y": 6,
      "z": -12,
      "name": "Plant_Coral_Block_Purple"
    },
    {
      "x": -8,
      "y": 6,
      "z": -12,
      "name": "Plant_Coral_Block_Pink"
    },
    {
      "x": -7,
      "y": 6,
      "z": -12,
      "name": "Wood_Bamboo_Roots_Deco"
    },
    {
      "x": -8,
      "y": 7,
      "z": -12,
      "name": "Plant_Coral_Block_Pink"
    },
    {
      "x": -7,
      "y": 7,
      "z": -12,
      "name": "Plant_Coral_Block_Purple"
    },
    {
      "x": -8,
      "y": 9,
      "z": -12,
      "name": "Plant_Coral_Block_Purple"
    },
    {
      "x": -7,
      "y": 11,
      "z": -12,
      "name": "Plant_Coral_Block_Pink"
    },
    {
      "x": -6,
      "y": 11,
      "z": -12,
      "name": "Plant_Coral_Block_Pink"
    },
    {
      "x": -6,
      "y": 12,
      "z": -12,
      "name": "Plant_Coral_Block_Pink"
    },
    {
      "x": -4,
      "y": 12,
      "z": -12,
      "name": "Wood_Bamboo_Roots_Deco"
    },
    {
      "x": -8,
      "y": 6,
      "z": -11,
      "name": "Plant_Coral_Block_Pink"
    },
    {
      "x": -7,
      "y": 6,
      "z": -11,
      "name": "Wood_Bamboo_Roots_Deco"
    },
    {
      "x": -6,
      "y": 6,
      "z": -11,
      "name": "Wood_Bamboo_Roots_Deco"
    },
    {
      "x": -7,
      "y": 7,
      "z": -11,
      "name": "Plant_Coral_Block_Purple"
    },
    {
      "x": -6,
      "y": 7,
      "z": -11,
      "name": "Plant_Coral_Block_Purple"
    },
    {
      "x": -5,
      "y": 7,
      "z": -11,
      "name": "Plant_Coral_Block_Yellow"
    },
    {
      "x": -8,
      "y": 8,
      "z": -11,
      "name": "Wood_Bamboo_Roots_Deco"
    },
    {
      "x": -8,
      "y": 9,
      "z": -11,
      "name": "Plant_Coral_Block_Yellow"
    },
    {
      "x": -6,
      "y": 10,
      "z": -11,
      "name": "Wood_Bamboo_Roots_Deco"
    },
    {
      "x": -6,
      "y": 11,
      "z": -11,
      "name": "Plant_Coral_Block_Purple"
    },
    {
      "x": -6,
      "y": 12,
      "z": -11,
      "name": "Plant_Coral_Block_Pink"
    },
    {
      "x": -5,
      "y": 12,
      "z": -11,
      "name": "Plant_Coral_Block_Pink"
    },
    {
      "x": -4,
      "y": 12,
      "z": -11,
      "name": "Wood_Bamboo_Roots_Deco"
    },
    {
      "x": -11,
      "y": 4,
      "z": -10,
      "name": "Wood_Bamboo_Roots_Deco"
    },
    {
      "x": -11,
      "y": 5,
      "z": -10,
      "name": "Plant_Coral_Block_Yellow"
    },
    {
      "x": -10,
      "y": 5,
      "z": -10,
      "name": "Plant_Coral_Block_Yellow"
    },
    {
      "x": -9,
      "y": 5,
      "z": -10,
      "name": "Wood_Bamboo_Roots_Deco"
    },
    {
      "x": -7,
      "y": 5,
      "z": -10,
      "name": "Wood_Bamboo_Roots_Deco"
    },
    {
      "x": -10,
      "y": 6,
      "z": -10,
      "name": "Plant_Coral_Block_Purple"
    },
    {
      "x": -9,
      "y": 6,
      "z": -10,
      "name": "Plant_Coral_Block_Purple"
    },
    {
      "x": -8,
      "y": 6,
      "z": -10,
      "name": "Plant_Coral_Block_Pink"
    },
    {
      "x": -7,
      "y": 6,
      "z": -10,
      "name": "Plant_Coral_Block_Purple"
    },
    {
      "x": -5,
      "y": 6,
      "z": -10,
      "name": "Plant_Coral_Block_Yellow"
    },
    {
      "x": -4,
      "y": 6,
      "z": -10,
      "name": "Rock_Crystal_Yellow_Block"
    },
    {
      "x": -5,
      "y": 7,
      "z": -10,
      "name": "Plant_Coral_Block_Yellow"
    },
    {
      "x": -8,
      "y": 8,
      "z": -10,
      "name": "Wood_Bamboo_Roots_Deco"
    },
    {
      "x": -7,
      "y": 8,
      "z": -10,
      "name": "Wood_Bamboo_Roots_Deco"
    },
    {
      "x": -8,
      "y": 9,
      "z": -10,
      "name": "Plant_Coral_Block_Yellow"
    },
    {
      "x": -7,
      "y": 9,
      "z": -10,
      "name": "Plant_Coral_Block_Yellow"
    },
    {
      "x": -7,
      "y": 10,
      "z": -10,
      "name": "Plant_Coral_Block_Yellow"
    },
    {
      "x": -7,
      "y": 11,
      "z": -10,
      "name": "Plant_Coral_Block_Yellow"
    },
    {
      "x": -6,
      "y": 11,
      "z": -10,
      "name": "Plant_Coral_Block_Yellow"
    },
    {
      "x": -11,
      "y": 5,
      "z": -9,
      "name": "Plant_Coral_Block_Yellow"
    },
    {
      "x": -8,
      "y": 5,
      "z": -9,
      "name": "Wood_Bamboo_Roots_Deco"
    },
    {
      "x": -6,
      "y": 5,
      "z": -9,
      "name": "Plant_Coral_Block_Yellow"
    },
    {
      "x": -8,
      "y": 6,
      "z": -9,
      "name": "Plant_Coral_Block_Purple"
    },
    {
      "x": -7,
      "y": 6,
      "z": -9,
      "name": "Plant_Coral_Block_Yellow"
    },
    {
      "x": -6,
      "y": 6,
      "z": -9,
      "name": "Plant_Coral_Block_Yellow"
    },
    {
      "x": -8,
      "y": 9,
      "z": -9,
      "name": "Wood_Bamboo_Roots_Deco"
    },
    {
      "x": -7,
      "y": 9,
      "z": -9,
      "name": "Plant_Coral_Block_Yellow"
    },
    {
      "x": -8,
      "y": 10,
      "z": -9,
      "name": "Plant_Coral_Block_Yellow"
    },
    {
      "x": -7,
      "y": 10,
      "z": -9,
      "name": "Plant_Coral_Block_Yellow"
    },
    {
      "x": -5,
      "y": 11,
      "z": -9,
      "name": "Wood_Bamboo_Roots_Deco"
    },
    {
      "x": -4,
      "y": 11,
      "z": -9,
      "name": "Wood_Bamboo_Roots_Deco"
    },
    {
      "x": -6,
      "y": 12,
      "z": -9,
      "name": "Plant_Coral_Block_Yellow"
    },
    {
      "x": -5,
      "y": 12,
      "z": -9,
      "name": "Plant_Coral_Block_Purple"
    },
    {
      "x": -4,
      "y": 12,
      "z": -9,
      "name": "Plant_Coral_Block_Purple"
    },
    {
      "x": -2,
      "y": 12,
      "z": -9,
      "name": "Wood_Bamboo_Roots_Deco"
    },
    {
      "x": -8,
      "y": 4,
      "z": -8,
      "name": "Wood_Bamboo_Roots_Deco"
    },
    {
      "x": -11,
      "y": 5,
      "z": -8,
      "name": "Rock_Crystal_Yellow_Block"
    },
    {
      "x": -8,
      "y": 5,
      "z": -8,
      "name": "Plant_Coral_Block_Yellow"
    },
    {
      "x": -6,
      "y": 5,
      "z": -8,
      "name": "Plant_Coral_Block_Yellow"
    },
    {
      "x": -5,
      "y": 5,
      "z": -8,
      "name": "Plant_Coral_Block_Yellow"
    },
    {
      "x": -8,
      "y": 6,
      "z": -8,
      "name": "Plant_Coral_Block_Purple"
    },
    {
      "x": -7,
      "y": 10,
      "z": -8,
      "name": "Wood_Bamboo_Roots_Deco"
    },
    {
      "x": -7,
      "y": 11,
      "z": -8,
      "name": "Plant_Coral_Block_Yellow"
    },
    {
      "x": -6,
      "y": 11,
      "z": -8,
      "name": "Plant_Coral_Block_Yellow"
    },
    {
      "x": -6,
      "y": 12,
      "z": -8,
      "name": "Plant_Coral_Block_Yellow"
    },
    {
      "x": -2,
      "y": 12,
      "z": -8,
      "name": "Plant_Coral_Block_Pink"
    },
    {
      "x": -8,
      "y": 4,
      "z": -7,
      "name": "Wood_Bamboo_Roots_Deco"
    },
    {
      "x": -8,
      "y": 5,
      "z": -7,
      "name": "Plant_Coral_Block_Yellow"
    },
    {
      "x": -5,
      "y": 5,
      "z": -7,
      "name": "Plant_Coral_Block_Yellow"
    },
    {
      "x": -7,
      "y": 10,
      "z": -7,
      "name": "Wood_Bamboo_Roots_Deco"
    },
    {
      "x": -4,
      "y": 10,
      "z": -7,
      "name": "Wood_Bamboo_Roots_Deco"
    },
    {
      "x": -7,
      "y": 11,
      "z": -7,
      "name": "Rock_Crystal_Yellow_Block"
    },
    {
      "x": -5,
      "y": 11,
      "z": -7,
      "name": "Rock_Crystal_Yellow_Block"
    },
    {
      "x": -4,
      "y": 11,
      "z": -7,
      "name": "Plant_Coral_Block_Yellow"
    },
    {
      "x": -3,
      "y": 11,
      "z": -7,
      "name": "Plant_Coral_Block_Yellow"
    },
    {
      "x": -1,
      "y": 11,
      "z": -7,
      "name": "Plant_Coral_Block_Pink"
    },
    {
      "x": -3,
      "y": 12,
      "z": -7,
      "name": "Plant_Coral_Block_Purple"
    },
    {
      "x": -2,
      "y": 12,
      "z": -7,
      "name": "Plant_Coral_Block_Pink"
    },
    {
      "x": -1,
      "y": 12,
      "z": -7,
      "name": "Plant_Coral_Block_Pink"
    },
    {
      "x": -8,
      "y": 4,
      "z": -6,
      "name": "Wood_Bamboo_Roots_Deco"
    },
    {
      "x": -8,
      "y": 5,
      "z": -6,
      "name": "Plant_Coral_Block_Yellow"
    },
    {
      "x": -4,
      "y": 8,
      "z": -6,
      "name": "Wood_Bamboo_Roots_Deco"
    },
    {
      "x": -3,
      "y": 8,
      "z": -6,
      "name": "Wood_Bamboo_Roots_Deco"
    },
    {
      "x": -2,
      "y": 8,
      "z": -6,
      "name": "Wood_Bamboo_Roots_Deco"
    },
    {
      "x": -5,
      "y": 9,
      "z": -6,
      "name": "Plant_Coral_Block_Yellow"
    },
    {
      "x": -4,
      "y": 9,
      "z": -6,
      "name": "Plant_Coral_Block_Yellow"
    },
    {
      "x": -3,
      "y": 9,
      "z": -6,
      "name": "Plant_Coral_Block_Yellow"
    },
    {
      "x": -2,
      "y": 9,
      "z": -6,
      "name": "Plant_Coral_Block_Purple"
    },
    {
      "x": -1,
      "y": 9,
      "z": -6,
      "name": "Plant_Coral_Block_Pink"
    },
    {
      "x": -1,
      "y": 10,
      "z": -6,
      "name": "Plant_Coral_Block_Pink"
    },
    {
      "x": -1,
      "y": 11,
      "z": -6,
      "name": "Plant_Coral_Block_Pink"
    },
    {
      "x": -1,
      "y": 7,
      "z": -5,
      "name": "Plant_Coral_Block_Pink"
    },
    {
      "x": -1,
      "y": 8,
      "z": -5,
      "name": "Plant_Coral_Block_Pink"
    },
    {
      "x": -1,
      "y": 9,
      "z": -5,
      "name": "Plant_Coral_Block_Pink"
    },
    {
      "x": -10,
      "y": 10,
      "z": -5,
      "name": "Plant_Coral_Block_Yellow"
    },
    {
      "x": -1,
      "y": 6,
      "z": -4,
      "name": "Plant_Coral_Block_Pink"
    },
    {
      "x": -1,
      "y": 7,
      "z": -4,
      "name": "Plant_Coral_Block_Pink"
    },
    {
      "x": -1,
      "y": 8,
      "z": -4,
      "name": "Plant_Coral_Block_Pink"
    },
    {
      "x": -10,
      "y": 9,
      "z": -4,
      "name": "Wood_Bamboo_Roots_Deco"
    },
    {
      "x": -1,
      "y": 9,
      "z": -4,
      "name": "Plant_Coral_Block_Pink"
    },
    {
      "x": -10,
      "y": 10,
      "z": -4,
      "name": "Plant_Coral_Block_Yellow"
    },
    {
      "x": -9,
      "y": 10,
      "z": -4,
      "name": "Plant_Coral_Block_Yellow"
    },
    {
      "x": -1,
      "y": 10,
      "z": -4,
      "name": "Plant_Coral_Block_Pink"
    },
    {
      "x": -1,
      "y": 11,
      "z": -4,
      "name": "Plant_Coral_Block_Pink"
    },
    {
      "x": -1,
      "y": 3,
      "z": -3,
      "name": "Plant_Coral_Block_Pink"
    },
    {
      "x": -1,
      "y": 4,
      "z": -3,
      "name": "Plant_Coral_Block_Pink"
    },
    {
      "x": -1,
      "y": 5,
      "z": -3,
      "name": "Plant_Coral_Block_Pink"
    },
    {
      "x": -1,
      "y": 6,
      "z": -3,
      "name": "Plant_Coral_Block_Pink"
    },
    {
      "x": -6,
      "y": 9,
      "z": -3,
      "name": "Wood_Bamboo_Roots_Deco"
    },
    {
      "x": -11,
      "y": 10,
      "z": -3,
      "name": "Wood_Bamboo_Roots_Deco"
    },
    {
      "x": -9,
      "y": 10,
      "z": -3,
      "name": "Plant_Coral_Block_Yellow"
    },
    {
      "x": -6,
      "y": 10,
      "z": -3,
      "name": "Plant_Coral_Block_Yellow"
    },
    {
      "x": -14,
      "y": 11,
      "z": -3,
      "name": "Plant_Coral_Block_Yellow"
    },
    {
      "x": -13,
      "y": 11,
      "z": -3,
      "name": "Rock_Crystal_Yellow_Block"
    },
    {
      "x": -12,
      "y": 11,
      "z": -3,
      "name": "Plant_Coral_Block_Yellow"
    },
    {
      "x": -11,
      "y": 11,
      "z": -3,
      "name": "Plant_Coral_Block_Purple"
    },
    {
      "x": -9,
      "y": 11,
      "z": -3,
      "name": "Plant_Coral_Block_Yellow"
    },
    {
      "x": -8,
      "y": 11,
      "z": -3,
      "name": "Plant_Coral_Block_Yellow"
    },
    {
      "x": -1,
      "y": 11,
      "z": -3,
      "name": "Plant_Coral_Block_Pink"
    },
    {
      "x": -1,
      "y": 12,
      "z": -3,
      "name": "Plant_Coral_Block_Pink"
    },
    {
      "x": -1,
      "y": 0,
      "z": -2,
      "name": "Plant_Coral_Block_Pink"
    },
    {
      "x": -1,
      "y": 1,
      "z": -2,
      "name": "Plant_Coral_Block_Pink"
    },
    {
      "x": -1,
      "y": 2,
      "z": -2,
      "name": "Plant_Coral_Block_Pink"
    },
    {
      "x": -1,
      "y": 3,
      "z": -2,
      "name": "Plant_Coral_Block_Pink"
    },
    {
      "x": -4,
      "y": 9,
      "z": -2,
      "name": "Plant_Coral_Block_Yellow"
    },
    {
      "x": -11,
      "y": 10,
      "z": -2,
      "name": "Wood_Bamboo_Roots_Deco"
    },
    {
      "x": -8,
      "y": 10,
      "z": -2,
      "name": "Wood_Bamboo_Roots_Deco"
    },
    {
      "x": -6,
      "y": 10,
      "z": -2,
      "name": "Plant_Coral_Block_Yellow"
    },
    {
      "x": -11,
      "y": 11,
      "z": -2,
      "name": "Plant_Coral_Block_Purple"
    },
    {
      "x": -10,
      "y": 11,
      "z": -2,
      "name": "Plant_Coral_Block_Purple"
    },
    {
      "x": -8,
      "y": 11,
      "z": -2,
      "name": "Plant_Coral_Block_Purple"
    },
    {
      "x": -2,
      "y": 8,
      "z": -1,
      "name": "Wood_Bamboo_Roots_Deco"
    },
    {
      "x": -4,
      "y": 9,
      "z": -1,
      "name": "Plant_Coral_Block_Yellow"
    },
    {
      "x": -2,
      "y": 9,
      "z": -1,
      "name": "Plant_Coral_Block_Yellow"
    },
    {
      "x": -13,
      "y": 10,
      "z": -1,
      "name": "Wood_Bamboo_Roots_Deco"
    },
    {
      "x": -6,
      "y": 10,
      "z": -1,
      "name": "Plant_Coral_Block_Yellow"
    },
    {
      "x": -16,
      "y": 11,
      "z": -1,
      "name": "Plant_Coral_Block_Yellow"
    },
    {
      "x": -15,
      "y": 11,
      "z": -1,
      "name": "Plant_Coral_Block_Yellow"
    },
    {
      "x": -14,
      "y": 11,
      "z": -1,
      "name": "Plant_Coral_Block_Yellow"
    },
    {
      "x": -13,
      "y": 11,
      "z": -1,
      "name": "Plant_Coral_Block_Purple"
    },
    {
      "x": -12,
      "y": 11,
      "z": -1,
      "name": "Plant_Coral_Block_Purple"
    },
    {
      "x": -11,
      "y": 11,
      "z": -1,
      "name": "Plant_Coral_Block_Pink"
    },
    {
      "x": -10,
      "y": 11,
      "z": -1,
      "name": "Plant_Coral_Block_Pink"
    },
    {
      "x": -9,
      "y": 11,
      "z": -1,
      "name": "Plant_Coral_Block_Pink"
    },
    {
      "x": -8,
      "y": 11,
      "z": -1,
      "name": "Plant_Coral_Block_Pink"
    },
    {
      "x": 3,
      "y": 14,
      "z": 16,
      "name": "Wood_Bamboo_Roots_Deco"
    },
    {
      "x": 0,
      "y": 15,
      "z": 16,
      "name": "Wood_Bamboo_Roots_Deco"
    },
    {
      "x": 2,
      "y": 15,
      "z": 16,
      "name": "Plant_Coral_Block_Yellow"
    },
    {
      "x": 3,
      "y": 15,
      "z": 16,
      "name": "Plant_Coral_Block_Yellow"
    },
    {
      "x": 0,
      "y": 16,
      "z": 16,
      "name": "Plant_Coral_Block_Yellow"
    },
    {
      "x": 1,
      "y": 16,
      "z": 16,
      "name": "Plant_Coral_Block_Yellow"
    },
    {
      "x": 3,
      "y": 14,
      "z": 17,
      "name": "Wood_Bamboo_Roots_Deco"
    },
    {
      "x": 3,
      "y": 15,
      "z": 17,
      "name": "Plant_Coral_Block_Yellow"
    },
    {
      "x": 1,
      "y": 16,
      "z": 17,
      "name": "Rock_Crystal_Yellow_Block"
    },
    {
      "x": 16,
      "y": 10,
      "z": 3,
      "name": "Wood_Bamboo_Roots_Deco"
    },
    {
      "x": 16,
      "y": 11,
      "z": 3,
      "name": "Plant_Coral_Block_Yellow"
    },
    {
      "x": 0,
      "y": 6,
      "z": 0,
      "name": "Wood_Bamboo_Roots_Deco"
    },
    {
      "x": 4,
      "y": 6,
      "z": 0,
      "name": "Wood_Bamboo_Roots_Deco"
    },
    {
      "x": 0,
      "y": 7,
      "z": 0,
      "name": "Plant_Coral_Block_Purple"
    },
    {
      "x": 1,
      "y": 7,
      "z": 0,
      "name": "Plant_Coral_Block_Purple"
    },
    {
      "x": 2,
      "y": 7,
      "z": 0,
      "name": "Plant_Coral_Block_Pink"
    },
    {
      "x": 4,
      "y": 7,
      "z": 0,
      "name": "Plant_Coral_Block_Purple"
    },
    {
      "x": 5,
      "y": 7,
      "z": 0,
      "name": "Plant_Coral_Block_Purple"
    },
    {
      "x": 6,
      "y": 7,
      "z": 0,
      "name": "Plant_Coral_Block_Yellow"
    },
    {
      "x": 2,
      "y": 8,
      "z": 0,
      "name": "Plant_Coral_Block_Pink"
    },
    {
      "x": 11,
      "y": 11,
      "z": 0,
      "name": "Plant_Coral_Block_Yellow"
    },
    {
      "x": 5,
      "y": 12,
      "z": 0,
      "name": "Wood_Bamboo_Roots_Deco"
    },
    {
      "x": 8,
      "y": 12,
      "z": 0,
      "name": "Plant_Coral_Block_Yellow"
    },
    {
      "x": 9,
      "y": 12,
      "z": 0,
      "name": "Plant_Coral_Block_Yellow"
    },
    {
      "x": 3,
      "y": 7,
      "z": 1,
      "name": "Wood_Bamboo_Roots_Deco"
    },
    {
      "x": 6,
      "y": 7,
      "z": 1,
      "name": "Plant_Coral_Block_Yellow"
    },
    {
      "x": 7,
      "y": 7,
      "z": 1,
      "name": "Plant_Coral_Block_Yellow"
    },
    {
      "x": 8,
      "y": 7,
      "z": 1,
      "name": "Rock_Crystal_Yellow_Block"
    },
    {
      "x": 1,
      "y": 8,
      "z": 1,
      "name": "Plant_Coral_Block_Pink"
    },
    {
      "x": 2,
      "y": 8,
      "z": 1,
      "name": "Plant_Coral_Block_Pink"
    },
    {
      "x": 3,
      "y": 8,
      "z": 1,
      "name": "Plant_Coral_Block_Purple"
    },
    {
      "x": 7,
      "y": 11,
      "z": 1,
      "name": "Wood_Bamboo_Roots_Deco"
    },
    {
      "x": 10,
      "y": 11,
      "z": 1,
      "name": "Plant_Coral_Block_Yellow"
    },
    {
      "x": 11,
      "y": 11,
      "z": 1,
      "name": "Rock_Crystal_Yellow_Block"
    },
    {
      "x": 13,
      "y": 11,
      "z": 1,
      "name": "Plant_Coral_Block_Yellow"
    },
    {
      "x": 14,
      "y": 11,
      "z": 1,
      "name": "Plant_Coral_Block_Yellow"
    },
    {
      "x": 7,
      "y": 12,
      "z": 1,
      "name": "Plant_Coral_Block_Yellow"
    },
    {
      "x": 8,
      "y": 12,
      "z": 1,
      "name": "Plant_Coral_Block_Yellow"
    },
    {
      "x": 10,
      "y": 12,
      "z": 1,
      "name": "Plant_Coral_Block_Yellow"
    },
    {
      "x": 3,
      "y": 7,
      "z": 2,
      "name": "Wood_Bamboo_Roots_Deco"
    },
    {
      "x": 1,
      "y": 8,
      "z": 2,
      "name": "Plant_Coral_Block_Pink"
    },
    {
      "x": 3,
      "y": 8,
      "z": 2,
      "name": "Plant_Coral_Block_Purple"
    },
    {
      "x": 0,
      "y": 9,
      "z": 2,
      "name": "Plant_Coral_Block_Pink"
    },
    {
      "x": 1,
      "y": 9,
      "z": 2,
      "name": "Plant_Coral_Block_Pink"
    },
    {
      "x": 3,
      "y": 9,
      "z": 2,
      "name": "Plant_Coral_Block_Yellow"
    },
    {
      "x": 10,
      "y": 11,
      "z": 2,
      "name": "Wood_Bamboo_Roots_Deco"
    },
    {
      "x": 12,
      "y": 11,
      "z": 2,
      "name": "Plant_Coral_Block_Yellow"
    },
    {
      "x": 13,
      "y": 11,
      "z": 2,
      "name": "Plant_Coral_Block_Yellow"
    },
    {
      "x": 9,
      "y": 12,
      "z": 2,
      "name": "Plant_Coral_Block_Purple"
    },
    {
      "x": 10,
      "y": 12,
      "z": 2,
      "name": "Plant_Coral_Block_Purple"
    },
    {
      "x": 12,
      "y": 12,
      "z": 2,
      "name": "Plant_Coral_Block_Yellow"
    },
    {
      "x": 1,
      "y": 8,
      "z": 3,
      "name": "Wood_Bamboo_Roots_Deco"
    },
    {
      "x": 3,
      "y": 8,
      "z": 3,
      "name": "Wood_Bamboo_Roots_Deco"
    },
    {
      "x": 0,
      "y": 9,
      "z": 3,
      "name": "Plant_Coral_Block_Pink"
    },
    {
      "x": 1,
      "y": 9,
      "z": 3,
      "name": "Plant_Coral_Block_Purple"
    },
    {
      "x": 3,
      "y": 9,
      "z": 3,
      "name": "Plant_Coral_Block_Yellow"
    },
    {
      "x": 4,
      "y": 9,
      "z": 3,
      "name": "Plant_Coral_Block_Yellow"
    },
    {
      "x": 13,
      "y": 11,
      "z": 3,
      "name": "Plant_Coral_Block_Yellow"
    },
    {
      "x": 14,
      "y": 11,
      "z": 3,
      "name": "Rock_Crystal_Yellow_Block"
    },
    {
      "x": 15,
      "y": 11,
      "z": 3,
      "name": "Plant_Coral_Block_Yellow"
    },
    {
      "x": 7,
      "y": 12,
      "z": 3,
      "name": "Plant_Coral_Block_Pink"
    },
    {
      "x": 8,
      "y": 12,
      "z": 3,
      "name": "Plant_Coral_Block_Pink"
    },
    {
      "x": 9,
      "y": 12,
      "z": 3,
      "name": "Plant_Coral_Block_Pink"
    },
    {
      "x": 10,
      "y": 12,
      "z": 3,
      "name": "Plant_Coral_Block_Pink"
    },
    {
      "x": 11,
      "y": 12,
      "z": 3,
      "name": "Plant_Coral_Block_Pink"
    },
    {
      "x": 12,
      "y": 12,
      "z": 3,
      "name": "Plant_Coral_Block_Purple"
    },
    {
      "x": 13,
      "y": 12,
      "z": 3,
      "name": "Plant_Coral_Block_Purple"
    },
    {
      "x": 1,
      "y": 8,
      "z": 4,
      "name": "Wood_Bamboo_Roots_Deco"
    },
    {
      "x": 1,
      "y": 9,
      "z": 4,
      "name": "Plant_Coral_Block_Yellow"
    },
    {
      "x": 4,
      "y": 9,
      "z": 4,
      "name": "Plant_Coral_Block_Yellow"
    },
    {
      "x": 1,
      "y": 10,
      "z": 4,
      "name": "Plant_Coral_Block_Yellow"
    },
    {
      "x": 7,
      "y": 11,
      "z": 4,
      "name": "Wood_Bamboo_Roots_Deco"
    },
    {
      "x": 8,
      "y": 11,
      "z": 4,
      "name": "Wood_Bamboo_Roots_Deco"
    },
    {
      "x": 10,
      "y": 11,
      "z": 4,
      "name": "Wood_Bamboo_Roots_Deco"
    },
    {
      "x": 2,
      "y": 12,
      "z": 4,
      "name": "Wood_Bamboo_Roots_Deco"
    },
    {
      "x": 7,
      "y": 12,
      "z": 4,
      "name": "Plant_Coral_Block_Purple"
    },
    {
      "x": 8,
      "y": 12,
      "z": 4,
      "name": "Plant_Coral_Block_Purple"
    },
    {
      "x": 10,
      "y": 12,
      "z": 4,
      "name": "Plant_Coral_Block_Purple"
    },
    {
      "x": 11,
      "y": 12,
      "z": 4,
      "name": "Plant_Coral_Block_Purple"
    },
    {
      "x": 4,
      "y": 9,
      "z": 5,
      "name": "Plant_Coral_Block_Yellow"
    },
    {
      "x": 1,
      "y": 10,
      "z": 5,
      "name": "Plant_Coral_Block_Yellow"
    },
    {
      "x": 8,
      "y": 10,
      "z": 5,
      "name": "Wood_Bamboo_Roots_Deco"
    },
    {
      "x": 6,
      "y": 11,
      "z": 5,
      "name": "Wood_Bamboo_Roots_Deco"
    },
    {
      "x": 8,
      "y": 11,
      "z": 5,
      "name": "Plant_Coral_Block_Purple"
    },
    {
      "x": 11,
      "y": 11,
      "z": 5,
      "name": "Plant_Coral_Block_Yellow"
    },
    {
      "x": 12,
      "y": 11,
      "z": 5,
      "name": "Plant_Coral_Block_Yellow"
    },
    {
      "x": 3,
      "y": 12,
      "z": 5,
      "name": "Wood_Bamboo_Roots_Deco"
    },
    {
      "x": 5,
      "y": 12,
      "z": 5,
      "name": "Plant_Coral_Block_Purple"
    },
    {
      "x": 6,
      "y": 12,
      "z": 5,
      "name": "Plant_Coral_Block_Yellow"
    },
    {
      "x": 8,
      "y": 12,
      "z": 5,
      "name": "Plant_Coral_Block_Purple"
    },
    {
      "x": 11,
      "y": 12,
      "z": 5,
      "name": "Plant_Coral_Block_Purple"
    },
    {
      "x": 0,
      "y": 9,
      "z": 6,
      "name": "Wood_Bamboo_Roots_Deco"
    },
    {
      "x": 0,
      "y": 10,
      "z": 6,
      "name": "Plant_Coral_Block_Yellow"
    },
    {
      "x": 1,
      "y": 10,
      "z": 6,
      "name": "Plant_Coral_Block_Yellow"
    },
    {
      "x": 9,
      "y": 10,
      "z": 6,
      "name": "Wood_Bamboo_Roots_Deco"
    },
    {
      "x": 6,
      "y": 11,
      "z": 6,
      "name": "Wood_Bamboo_Roots_Deco"
    },
    {
      "x": 8,
      "y": 11,
      "z": 6,
      "name": "Plant_Coral_Block_Yellow"
    },
    {
      "x": 9,
      "y": 11,
      "z": 6,
      "name": "Plant_Coral_Block_Yellow"
    },
    {
      "x": 12,
      "y": 11,
      "z": 6,
      "name": "Rock_Crystal_Yellow_Block"
    },
    {
      "x": 13,
      "y": 11,
      "z": 6,
      "name": "Plant_Coral_Block_Yellow"
    },
    {
      "x": 6,
      "y": 12,
      "z": 6,
      "name": "Plant_Coral_Block_Yellow"
    },
    {
      "x": 0,
      "y": 10,
      "z": 7,
      "name": "Plant_Coral_Block_Yellow"
    },
    {
      "x": 9,
      "y": 11,
      "z": 7,
      "name": "Rock_Crystal_Yellow_Block"
    },
    {
      "x": 6,
      "y": 12,
      "z": 7,
      "name": "Rock_Crystal_Yellow_Block"
    },
    {
      "x": -1,
      "y": 7,
      "z": 0,
      "name": "Plant_Coral_Block_Yellow"
    },
    {
      "x": -6,
      "y": 9,
      "z": 0,
      "name": "Wood_Bamboo_Roots_Deco"
    },
    {
      "x": -4,
      "y": 9,
      "z": 0,
      "name": "Rock_Crystal_Yellow_Block"
    },
    {
      "x": -2,
      "y": 9,
      "z": 0,
      "name": "Plant_Coral_Block_Yellow"
    },
    {
      "x": -10,
      "y": 10,
      "z": 0,
      "name": "Wood_Bamboo_Roots_Deco"
    },
    {
      "x": -9,
      "y": 10,
      "z": 0,
      "name": "Wood_Bamboo_Roots_Deco"
    },
    {
      "x": -6,
      "y": 10,
      "z": 0,
      "name": "Plant_Coral_Block_Purple"
    },
    {
      "x": -10,
      "y": 11,
      "z": 0,
      "name": "Plant_Coral_Block_Purple"
    },
    {
      "x": -9,
      "y": 11,
      "z": 0,
      "name": "Plant_Coral_Block_Purple"
    },
    {
      "x": -8,
      "y": 11,
      "z": 0,
      "name": "Plant_Coral_Block_Pink"
    },
    {
      "x": -7,
      "y": 11,
      "z": 0,
      "name": "Plant_Coral_Block_Pink"
    },
    {
      "x": -1,
      "y": 6,
      "z": 1,
      "name": "Wood_Bamboo_Roots_Deco"
    },
    {
      "x": -3,
      "y": 7,
      "z": 1,
      "name": "Plant_Coral_Block_Yellow"
    },
    {
      "x": -2,
      "y": 7,
      "z": 1,
      "name": "Plant_Coral_Block_Yellow"
    },
    {
      "x": -1,
      "y": 7,
      "z": 1,
      "name": "Rock_Crystal_Yellow_Block"
    },
    {
      "x": -4,
      "y": 8,
      "z": 1,
      "name": "Wood_Bamboo_Roots_Deco"
    },
    {
      "x": -2,
      "y": 8,
      "z": 1,
      "name": "Wood_Bamboo_Roots_Deco"
    },
    {
      "x": -1,
      "y": 8,
      "z": 1,
      "name": "Wood_Bamboo_Roots_Deco"
    },
    {
      "x": -4,
      "y": 9,
      "z": 1,
      "name": "Plant_Coral_Block_Yellow"
    },
    {
      "x": -3,
      "y": 9,
      "z": 1,
      "name": "Plant_Coral_Block_Yellow"
    },
    {
      "x": -2,
      "y": 9,
      "z": 1,
      "name": "Plant_Coral_Block_Yellow"
    },
    {
      "x": -1,
      "y": 9,
      "z": 1,
      "name": "Plant_Coral_Block_Yellow"
    },
    {
      "x": -11,
      "y": 10,
      "z": 1,
      "name": "Wood_Bamboo_Roots_Deco"
    },
    {
      "x": -10,
      "y": 10,
      "z": 1,
      "name": "Wood_Bamboo_Roots_Deco"
    },
    {
      "x": -8,
      "y": 10,
      "z": 1,
      "name": "Wood_Bamboo_Roots_Deco"
    },
    {
      "x": -7,
      "y": 10,
      "z": 1,
      "name": "Plant_Coral_Block_Pink"
    },
    {
      "x": -6,
      "y": 10,
      "z": 1,
      "name": "Plant_Coral_Block_Pink"
    },
    {
      "x": -12,
      "y": 11,
      "z": 1,
      "name": "Plant_Coral_Block_Yellow"
    },
    {
      "x": -11,
      "y": 11,
      "z": 1,
      "name": "Plant_Coral_Block_Yellow"
    },
    {
      "x": -10,
      "y": 11,
      "z": 1,
      "name": "Plant_Coral_Block_Purple"
    },
    {
      "x": -8,
      "y": 11,
      "z": 1,
      "name": "Plant_Coral_Block_Purple"
    },
    {
      "x": -7,
      "y": 11,
      "z": 1,
      "name": "Plant_Coral_Block_Pink"
    },
    {
      "x": -14,
      "y": 12,
      "z": 1,
      "name": "Plant_Coral_Block_Yellow"
    },
    {
      "x": -13,
      "y": 12,
      "z": 1,
      "name": "Plant_Coral_Block_Yellow"
    },
    {
      "x": -12,
      "y": 12,
      "z": 1,
      "name": "Plant_Coral_Block_Yellow"
    },
    {
      "x": -1,
      "y": 8,
      "z": 2,
      "name": "Wood_Bamboo_Roots_Deco"
    },
    {
      "x": -3,
      "y": 9,
      "z": 2,
      "name": "Plant_Coral_Block_Purple"
    },
    {
      "x": -1,
      "y": 9,
      "z": 2,
      "name": "Plant_Coral_Block_Purple"
    },
    {
      "x": -9,
      "y": 10,
      "z": 2,
      "name": "Wood_Bamboo_Roots_Deco"
    },
    {
      "x": -8,
      "y": 10,
      "z": 2,
      "name": "Wood_Bamboo_Roots_Deco"
    },
    {
      "x": -6,
      "y": 10,
      "z": 2,
      "name": "Plant_Coral_Block_Pink"
    },
    {
      "x": -5,
      "y": 10,
      "z": 2,
      "name": "Plant_Coral_Block_Pink"
    },
    {
      "x": -4,
      "y": 10,
      "z": 2,
      "name": "Plant_Coral_Block_Pink"
    },
    {
      "x": -9,
      "y": 11,
      "z": 2,
      "name": "Plant_Coral_Block_Yellow"
    },
    {
      "x": -8,
      "y": 11,
      "z": 2,
      "name": "Plant_Coral_Block_Purple"
    },
    {
      "x": -6,
      "y": 9,
      "z": 3,
      "name": "Wood_Bamboo_Roots_Deco"
    },
    {
      "x": -3,
      "y": 9,
      "z": 3,
      "name": "Plant_Coral_Block_Pink"
    },
    {
      "x": -2,
      "y": 9,
      "z": 3,
      "name": "Plant_Coral_Block_Pink"
    },
    {
      "x": -1,
      "y": 9,
      "z": 3,
      "name": "Plant_Coral_Block_Pink"
    },
    {
      "x": -6,
      "y": 10,
      "z": 3,
      "name": "Plant_Coral_Block_Purple"
    },
    {
      "x": -4,
      "y": 10,
      "z": 3,
      "name": "Plant_Coral_Block_Pink"
    },
    {
      "x": -3,
      "y": 10,
      "z": 3,
      "name": "Plant_Coral_Block_Pink"
    },
    {
      "x": -10,
      "y": 11,
      "z": 3,
      "name": "Rock_Crystal_Yellow_Block"
    },
    {
      "x": -9,
      "y": 11,
      "z": 3,
      "name": "Plant_Coral_Block_Yellow"
    },
    {
      "x": -1,
      "y": 8,
      "z": 4,
      "name": "Wood_Bamboo_Roots_Deco"
    },
    {
      "x": -7,
      "y": 9,
      "z": 4,
      "name": "Wood_Bamboo_Roots_Deco"
    },
    {
      "x": -4,
      "y": 9,
      "z": 4,
      "name": "Wood_Bamboo_Roots_Deco"
    },
    {
      "x": -3,
      "y": 9,
      "z": 4,
      "name": "Wood_Bamboo_Roots_Deco"
    },
    {
      "x": -1,
      "y": 9,
      "z": 4,
      "name": "Plant_Coral_Block_Purple"
    },
    {
      "x": -7,
      "y": 10,
      "z": 4,
      "name": "Plant_Coral_Block_Yellow"
    },
    {
      "x": -6,
      "y": 10,
      "z": 4,
      "name": "Plant_Coral_Block_Purple"
    },
    {
      "x": -4,
      "y": 10,
      "z": 4,
      "name": "Plant_Coral_Block_Purple"
    },
    {
      "x": -3,
      "y": 10,
      "z": 4,
      "name": "Plant_Coral_Block_Purple"
    },
    {
      "x": -10,
      "y": 11,
      "z": 4,
      "name": "Plant_Coral_Block_Yellow"
    },
    {
      "x": -7,
      "y": 11,
      "z": 4,
      "name": "Plant_Coral_Block_Yellow"
    },
    {
      "x": -2,
      "y": 8,
      "z": 5,
      "name": "Wood_Bamboo_Roots_Deco"
    },
    {
      "x": -1,
      "y": 8,
      "z": 5,
      "name": "Wood_Bamboo_Roots_Deco"
    },
    {
      "x": -4,
      "y": 9,
      "z": 5,
      "name": "Wood_Bamboo_Roots_Deco"
    },
    {
      "x": -2,
      "y": 9,
      "z": 5,
      "name": "Plant_Coral_Block_Yellow"
    },
    {
      "x": -1,
      "y": 9,
      "z": 5,
      "name": "Plant_Coral_Block_Yellow"
    },
    {
      "x": -4,
      "y": 10,
      "z": 5,
      "name": "Plant_Coral_Block_Purple"
    },
    {
      "x": -2,
      "y": 10,
      "z": 5,
      "name": "Plant_Coral_Block_Yellow"
    },
    {
      "x": -8,
      "y": 11,
      "z": 5,
      "name": "Plant_Coral_Block_Yellow"
    },
    {
      "x": -7,
      "y": 11,
      "z": 5,
      "name": "Plant_Coral_Block_Yellow"
    },
    {
      "x": -4,
      "y": 11,
      "z": 5,
      "name": "Plant_Coral_Block_Yellow"
    },
    {
      "x": -5,
      "y": 10,
      "z": 6,
      "name": "Wood_Bamboo_Roots_Deco"
    },
    {
      "x": -2,
      "y": 10,
      "z": 6,
      "name": "Rock_Crystal_Yellow_Block"
    },
    {
      "x": -8,
      "y": 11,
      "z": 6,
      "name": "Rock_Crystal_Yellow_Block"
    },
    {
      "x": -5,
      "y": 11,
      "z": 6,
      "name": "Plant_Coral_Block_Yellow"
    },
    {
      "x": -4,
      "y": 11,
      "z": 6,
      "name": "Rock_Crystal_Yellow_Block"
    },
    {
      "x": -2,
      "y": 10,
      "z": 7,
      "name": "Plant_Coral_Block_Yellow"
    },
    {
      "x": -5,
      "y": 11,
      "z": 7,
      "name": "Rock_Crystal_Yellow_Block"
    },
    {
      "x": -8,
      "y": 10,
      "z": -17,
      "name": "Wood_Bamboo_Roots_Deco"
    },
    {
      "x": -8,
      "y": 11,
      "z": -17,
      "name": "Plant_Coral_Block_Yellow"
    },
    {
      "x": -5,
      "y": 17,
      "z": 0,
      "name": "Wood_Bamboo_Roots_Deco"
    },
    {
      "x": -4,
      "y": 17,
      "z": 0,
      "name": "Plant_Coral_Block_Yellow"
    },
    {
      "x": -2,
      "y": 17,
      "z": 0,
      "name": "Plant_Coral_Block_Pink"
    },
    {
      "x": -5,
      "y": 18,
      "z": 0,
      "name": "Rock_Crystal_Yellow_Block"
    },
    {
      "x": -4,
      "y": 18,
      "z": 0,
      "name": "Plant_Coral_Block_Yellow"
    },
    {
      "x": -6,
      "y": 17,
      "z": 1,
      "name": "Wood_Bamboo_Roots_Deco"
    },
    {
      "x": -3,
      "y": 17,
      "z": 1,
      "name": "Plant_Coral_Block_Pink"
    },
    {
      "x": -2,
      "y": 17,
      "z": 1,
      "name": "Plant_Coral_Block_Pink"
    },
    {
      "x": -6,
      "y": 18,
      "z": 1,
      "name": "Plant_Coral_Block_Yellow"
    },
    {
      "x": -5,
      "y": 18,
      "z": 1,
      "name": "Plant_Coral_Block_Yellow"
    },
    {
      "x": -4,
      "y": 16,
      "z": 2,
      "name": "Wood_Bamboo_Roots_Deco"
    },
    {
      "x": -2,
      "y": 16,
      "z": 2,
      "name": "Wood_Bamboo_Roots_Deco"
    },
    {
      "x": -1,
      "y": 16,
      "z": 2,
      "name": "Wood_Bamboo_Roots_Deco"
    },
    {
      "x": -4,
      "y": 17,
      "z": 2,
      "name": "Plant_Coral_Block_Purple"
    },
    {
      "x": -3,
      "y": 17,
      "z": 2,
      "name": "Plant_Coral_Block_Pink"
    },
    {
      "x": -2,
      "y": 17,
      "z": 2,
      "name": "Plant_Coral_Block_Purple"
    },
    {
      "x": -1,
      "y": 17,
      "z": 2,
      "name": "Plant_Coral_Block_Purple"
    },
    {
      "x": -5,
      "y": 18,
      "z": 2,
      "name": "Plant_Coral_Block_Yellow"
    },
    {
      "x": -4,
      "y": 18,
      "z": 2,
      "name": "Plant_Coral_Block_Yellow"
    },
    {
      "x": -1,
      "y": 16,
      "z": 3,
      "name": "Wood_Bamboo_Roots_Deco"
    },
    {
      "x": -5,
      "y": 17,
      "z": 3,
      "name": "Wood_Bamboo_Roots_Deco"
    },
    {
      "x": -3,
      "y": 17,
      "z": 3,
      "name": "Plant_Coral_Block_Pink"
    },
    {
      "x": -1,
      "y": 17,
      "z": 3,
      "name": "Plant_Coral_Block_Yellow"
    },
    {
      "x": -5,
      "y": 18,
      "z": 3,
      "name": "Plant_Coral_Block_Yellow"
    },
    {
      "x": -7,
      "y": 19,
      "z": 3,
      "name": "Rock_Crystal_Yellow_Block"
    },
    {
      "x": -6,
      "y": 19,
      "z": 3,
      "name": "Plant_Coral_Block_Yellow"
    },
    {
      "x": -5,
      "y": 19,
      "z": 3,
      "name": "Plant_Coral_Block_Yellow"
    },
    {
      "x": -3,
      "y": 17,
      "z": 4,
      "name": "Plant_Coral_Block_Pink"
    },
    {
      "x": -4,
      "y": 16,
      "z": 5,
      "name": "Wood_Bamboo_Roots_Deco"
    },
    {
      "x": -3,
      "y": 16,
      "z": 5,
      "name": "Plant_Coral_Block_Pink"
    },
    {
      "x": -2,
      "y": 16,
      "z": 5,
      "name": "Wood_Bamboo_Roots_Deco"
    },
    {
      "x": -5,
      "y": 17,
      "z": 5,
      "name": "Plant_Coral_Block_Yellow"
    },
    {
      "x": -4,
      "y": 17,
      "z": 5,
      "name": "Plant_Coral_Block_Purple"
    },
    {
      "x": -3,
      "y": 17,
      "z": 5,
      "name": "Plant_Coral_Block_Pink"
    },
    {
      "x": -2,
      "y": 17,
      "z": 5,
      "name": "Plant_Coral_Block_Purple"
    },
    {
      "x": -1,
      "y": 17,
      "z": 5,
      "name": "Plant_Coral_Block_Yellow"
    },
    {
      "x": -5,
      "y": 18,
      "z": 5,
      "name": "Plant_Coral_Block_Yellow"
    },
    {
      "x": -3,
      "y": 16,
      "z": 6,
      "name": "Plant_Coral_Block_Pink"
    },
    {
      "x": -6,
      "y": 17,
      "z": 6,
      "name": "Wood_Bamboo_Roots_Deco"
    },
    {
      "x": -7,
      "y": 18,
      "z": 6,
      "name": "Plant_Coral_Block_Yellow"
    },
    {
      "x": -6,
      "y": 18,
      "z": 6,
      "name": "Plant_Coral_Block_Yellow"
    },
    {
      "x": -5,
      "y": 18,
      "z": 6,
      "name": "Plant_Coral_Block_Yellow"
    },
    {
      "x": -4,
      "y": 15,
      "z": 7,
      "name": "Wood_Bamboo_Roots_Deco"
    },
    {
      "x": -1,
      "y": 15,
      "z": 7,
      "name": "Wood_Bamboo_Roots_Deco"
    },
    {
      "x": -4,
      "y": 16,
      "z": 7,
      "name": "Plant_Coral_Block_Purple"
    },
    {
      "x": -3,
      "y": 16,
      "z": 7,
      "name": "Plant_Coral_Block_Pink"
    },
    {
      "x": -2,
      "y": 16,
      "z": 7,
      "name": "Plant_Coral_Block_Pink"
    },
    {
      "x": -1,
      "y": 16,
      "z": 7,
      "name": "Plant_Coral_Block_Purple"
    },
    {
      "x": -4,
      "y": 17,
      "z": 7,
      "name": "Plant_Coral_Block_Purple"
    },
    {
      "x": -5,
      "y": 16,
      "z": 8,
      "name": "Wood_Bamboo_Roots_Deco"
    },
    {
      "x": -2,
      "y": 16,
      "z": 8,
      "name": "Plant_Coral_Block_Pink"
    },
    {
      "x": -5,
      "y": 17,
      "z": 8,
      "name": "Plant_Coral_Block_Yellow"
    },
    {
      "x": -4,
      "y": 17,
      "z": 8,
      "name": "Plant_Coral_Block_Yellow"
    },
    {
      "x": -3,
      "y": 15,
      "z": 9,
      "name": "Plant_Coral_Block_Purple"
    },
    {
      "x": -2,
      "y": 15,
      "z": 9,
      "name": "Plant_Coral_Block_Pink"
    },
    {
      "x": -1,
      "y": 15,
      "z": 9,
      "name": "Plant_Coral_Block_Pink"
    },
    {
      "x": -2,
      "y": 16,
      "z": 9,
      "name": "Plant_Coral_Block_Pink"
    },
    {
      "x": -6,
      "y": 17,
      "z": 9,
      "name": "Plant_Coral_Block_Yellow"
    },
    {
      "x": -5,
      "y": 17,
      "z": 9,
      "name": "Plant_Coral_Block_Yellow"
    },
    {
      "x": -4,
      "y": 15,
      "z": 10,
      "name": "Plant_Coral_Block_Yellow"
    },
    {
      "x": -3,
      "y": 15,
      "z": 10,
      "name": "Plant_Coral_Block_Yellow"
    },
    {
      "x": -1,
      "y": 15,
      "z": 10,
      "name": "Plant_Coral_Block_Pink"
    },
    {
      "x": -4,
      "y": 16,
      "z": 10,
      "name": "Plant_Coral_Block_Yellow"
    },
    {
      "x": -2,
      "y": 14,
      "z": 11,
      "name": "Wood_Bamboo_Roots_Deco"
    },
    {
      "x": -2,
      "y": 15,
      "z": 11,
      "name": "Plant_Coral_Block_Purple"
    },
    {
      "x": -1,
      "y": 15,
      "z": 11,
      "name": "Plant_Coral_Block_Pink"
    },
    {
      "x": -6,
      "y": 16,
      "z": 11,
      "name": "Rock_Crystal_Yellow_Block"
    },
    {
      "x": -5,
      "y": 16,
      "z": 11,
      "name": "Plant_Coral_Block_Yellow"
    },
    {
      "x": -4,
      "y": 16,
      "z": 11,
      "name": "Plant_Coral_Block_Yellow"
    },
    {
      "x": -3,
      "y": 14,
      "z": 12,
      "name": "Wood_Bamboo_Roots_Deco"
    },
    {
      "x": -2,
      "y": 14,
      "z": 12,
      "name": "Wood_Bamboo_Roots_Deco"
    },
    {
      "x": -3,
      "y": 15,
      "z": 12,
      "name": "Plant_Coral_Block_Yellow"
    },
    {
      "x": -2,
      "y": 15,
      "z": 12,
      "name": "Plant_Coral_Block_Purple"
    },
    {
      "x": -3,
      "y": 14,
      "z": 13,
      "name": "Wood_Bamboo_Roots_Deco"
    },
    {
      "x": -3,
      "y": 15,
      "z": 13,
      "name": "Plant_Coral_Block_Yellow"
    },
    {
      "x": -4,
      "y": 16,
      "z": 13,
      "name": "Plant_Coral_Block_Yellow"
    },
    {
      "x": -3,
      "y": 16,
      "z": 13,
      "name": "Plant_Coral_Block_Yellow"
    },
    {
      "x": -4,
      "y": 16,
      "z": 14,
      "name": "Plant_Coral_Block_Yellow"
    },
    {
      "x": -4,
      "y": 16,
      "z": 15,
      "name": "Plant_Coral_Block_Yellow"
    }
  ],
  "fluids": [],
  "entities": []
}