{
  "version": 8,
  "blockIdVersion": 11,
  "anchorX": 0,
  "anchorY": 0,
  "anchorZ": 0,
  "blocks": [
    {
      "x": -3,
      "y": 9,
      "z": -5,
      "name": "Rock_Sandstone_Brick_Smooth_Half",
      "rotation": 7
    },
    {
      "x": -3,
      "y": 10,
      "z": -5,
      "name": "Rock_Sandstone_Brick_Smooth_Half",
      "rotation": 7
    },
    {
      "x": -3,
      "y": 9,
      "z": -4,
      "name": "Rock_Sandstone_Brick_Smooth_Half",
      "rotation": 7
    },
    {
      "x": -3,
      "y": 9,
      "z": -3,
      "name": "Rock_Sandstone_Brick_Smooth_Half",
      "rotation": 7
    },
    {
      "x": -3,
      "y": 10,
      "z": -3,
      "name": "Rock_Sandstone_Brick_Smooth_Half",
      "rotation": 7
    },
    {
      "x": -3,
      "y": 9,
      "z": -2,
      "name": "Rock_Sandstone_Brick_Smooth_Half",
      "rotation": 7
    },
    {
      "x": -2,
      "y": 0,
      "z": -9,
      "name": "Rock_Sandstone_Cobble"
    },
    {
      "x": -2,
      "y": 1,
      "z": -9,
      "name": "Rock_Sandstone_Cobble"
    },
    {
      "x": -2,
      "y": 2,
      "z": -9,
      "name": "Rock_Sandstone_Cobble"
    },
    {
      "x": -2,
      "y": 3,
      "z": -9,
      "name": "Rock_Sandstone_Cobble"
    },
    {
      "x": -2,
      "y": 4,
      "z": -9,
      "name": "Rock_Sandstone_Brick"
    },
    {
      "x": -2,
      "y": 5,
      "z": -9,
      "name": "Rock_Sandstone_Brick"
    },
    {
      "x": -2,
      "y": 6,
      "z": -9,
      "name": "Rock_Sandstone_Brick"
    },
    {
      "x": -2,
      "y": 7,
      "z": -9,
      "name": "Rock_Sandstone_Brick_Ornate"
    },
    {
      "x": -2,
      "y": 8,
      "z": -9,
      "name": "Rock_Sandstone_Brick"
    },
    {
      "x": -2,
      "y": 9,
      "z": -9,
      "name": "Rock_Sandstone_Brick"
    },
    {
      "x": -2,
      "y": 0,
      "z": -8,
      "name": "Rock_Sandstone_Cobble"
    },
    {
      "x": -2,
      "y": 1,
      "z": -8,
      "name": "Rock_Sandstone_Cobble"
    },
    {
      "x": -2,
      "y": 2,
      "z": -8,
      "name": "Rock_Sandstone_Cobble"
    },
    {
      "x": -2,
      "y": 3,
      "z": -8,
      "name": "Rock_Sandstone_Cobble"
    },
    {
      "x": -2,
      "y": 4,
      "z": -8,
      "name": "Rock_Sandstone_Brick"
    },
    {
      "x": -2,
      "y": 5,
      "z": -8,
      "name": "Rock_Sandstone_Brick"
    },
    {
      "x": -2,
      "y": 6,
      "z": -8,
      "name": "Rock_Sandstone_Brick"
    },
    {
      "x": -2,
      "y": 7,
      "z": -8,
      "name": "Rock_Sandstone_Brick_Ornate"
    },
    {
      "x": -2,
      "y": 8,
      "z": -8,
      "name": "Rock_Sandstone_Brick"
    },
    {
      "x": -2,
      "y": 9,
      "z": -8,
      "name": "Rock_Sandstone_Brick"
    },
    {
      "x": -2,
      "y": 0,
      "z": -7,
      "name": "Rock_Sandstone_Cobble"
    },
    {
      "x": -2,
      "y": 1,
      "z": -7,
      "name": "Rock_Sandstone_Cobble"
    },
    {
      "x": -2,
      "y": 2,
      "z": -7,
      "name": "Rock_Sandstone_Cobble"
    },
    {
      "x": -2,
      "y": 3,
      "z": -7,
      "name": "Rock_Sandstone_Cobble"
    },
    {
      "x": -2,
      "y": 4,
      "z": -7,
      "name": "Rock_Sandstone_Brick"
    },
    {
      "x": -2,
      "y": 5,
      "z": -7,
      "name": "Rock_Sandstone_Brick"
    },
    {
      "x": -2,
      "y": 6,
      "z": -7,
      "name": "Rock_Sandstone_Brick_Half",
      "rotation": 4
    },
    {
      "x": -2,
      "y": 0,
      "z": -6,
      "name": "Rock_Sandstone_Cobble"
    },
    {
      "x": -2,
      "y": 1,
      "z": -6,
      "name": "Rock_Sandstone_Cobble"
    },
    {
      "x": -2,
      "y": 2,
      "z": -6,
      "name": "Rock_Sandstone_Cobble"
    },
    {
      "x": -2,
      "y": 3,
      "z": -6,
      "name": "Rock_Sandstone_Cobble"
    },
    {
      "x": -2,
      "y": 4,
      "z": -6,
      "name": "Rock_Sandstone_Brick"
    },
    {
      "x": -2,
      "y": 5,
      "z": -6,
      "name": "Rock_Sandstone_Brick"
    },
    {
      "x": -2,
      "y": 6,
      "z": -6,
      "name": "Rock_Sandstone_Brick"
    },
    {
      "x": -2,
      "y": 7,
      "z": -6,
      "name": "Rock_Sandstone_Brick_Ornate"
    },
    {
      "x": -2,
      "y": 0,
      "z": -5,
      "name": "Rock_Sandstone_Cobble"
    },
    {
      "x": -2,
      "y": 1,
      "z": -5,
      "name": "Rock_Sandstone_Cobble"
    },
    {
      "x": -2,
      "y": 2,
      "z": -5,
      "name": "Rock_Sandstone_Cobble"
    },
    {
      "x": -2,
      "y": 3,
      "z": -5,
      "name": "Rock_Sandstone_Brick"
    },
    {
      "x": -2,
      "y": 4,
      "z": -5,
      "name": "Rock_Sandstone_Brick"
    },
    {
      "x": -2,
      "y": 5,
      "z": -5,
      "name": "Rock_Sandstone_Brick"
    },
    {
      "x": -2,
      "y": 6,
      "z": -5,
      "name": "Rock_Sandstone_Brick"
    },
    {
      "x": -2,
      "y": 7,
      "z": -5,
      "name": "Rock_Sandstone_Brick_Ornate"
    },
    {
      "x": -2,
      "y": 8,
      "z": -5,
      "name": "Rock_Sandstone_Brick"
    },
    {
      "x": -2,
      "y": 9,
      "z": -5,
      "name": "Rock_Sandstone_Brick"
    },
    {
      "x": -2,
      "y": 10,
      "z": -5,
      "name": "Rock_Sandstone_Brick_Smooth"
    },
    {
      "x": -2,
      "y": 0,
      "z": -4,
      "name": "Rock_Sandstone_Cobble"
    },
    {
      "x": -2,
      "y": 1,
      "z": -4,
      "name": "Rock_Sandstone_Cobble"
    },
    {
      "x": -2,
      "y": 2,
      "z": -4,
      "name": "Rock_Sandstone_Cobble"
    },
    {
      "x": -2,
      "y": 3,
      "z": -4,
      "name": "Rock_Sandstone_Cobble"
    },
    {
      "x": -2,
      "y": 4,
      "z": -4,
      "name": "Rock_Sandstone_Brick"
    },
    {
      "x": -2,
      "y": 5,
      "z": -4,
      "name": "Rock_Sandstone_Brick"
    },
    {
      "x": -2,
      "y": 6,
      "z": -4,
      "name": "Rock_Sandstone_Brick"
    },
    {
      "x": -2,
      "y": 7,
      "z": -4,
      "name": "Rock_Sandstone_Brick_Ornate"
    },
    {
      "x": -2,
      "y": 8,
      "z": -4,
      "name": "Rock_Sandstone_Brick"
    },
    {
      "x": -2,
      "y": 9,
      "z": -4,
      "name": "Rock_Sandstone_Brick"
    },
    {
      "x": -2,
      "y": 10,
      "z": -4,
      "name": "Rock_Sandstone_Brick_Smooth_Half"
    },
    {
      "x": -2,
      "y": 0,
      "z": -3,
      "name": "Rock_Sandstone_Cobble"
    },
    {
      "x": -2,
      "y": 1,
      "z": -3,
      "name": "Rock_Sandstone_Cobble"
    },
    {
      "x": -2,
      "y": 2,
      "z": -3,
      "name": "Rock_Sandstone_Cobble"
    },
    {
      "x": -2,
      "y": 3,
      "z": -3,
      "name": "Rock_Sandstone_Cobble"
    },
    {
      "x": -2,
      "y": 4,
      "z": -3,
      "name": "Rock_Sandstone_Cobble"
    },
    {
      "x": -2,
      "y": 5,
      "z": -3,
      "name": "Rock_Sandstone_Cobble"
    },
    {
      "x": -2,
      "y": 6,
      "z": -3,
      "name": "Rock_Sandstone_Brick"
    },
    {
      "x": -2,
      "y": 7,
      "z": -3,
      "name": "Rock_Sandstone_Brick_Ornate"
    },
    {
      "x": -2,
      "y": 8,
      "z": -3,
      "name": "Rock_Sandstone_Brick"
    },
    {
      "x": -2,
      "y": 9,
      "z": -3,
      "name": "Rock_Sandstone_Brick"
    },
    {
      "x": -2,
      "y": 10,
      "z": -3,
      "name": "Rock_Sandstone_Brick_Smooth"
    },
    {
      "x": -2,
      "y": 0,
      "z": -2,
      "name": "Rock_Sandstone_Cobble"
    },
    {
      "x": -2,
      "y": 1,
      "z": -2,
      "name": "Rock_Sandstone_Cobble"
    },
    {
      "x": -2,
      "y": 2,
      "z": -2,
      "name": "Rock_Sandstone_Cobble"
    },
    {
      "x": -2,
      "y": 3,
      "z": -2,
      "name": "Rock_Sandstone_Cobble"
    },
    {
      "x": -2,
      "y": 4,
      "z": -2,
      "name": "Rock_Sandstone_Cobble"
    },
    {
      "x": -2,
      "y": 5,
      "z": -2,
      "name": "Rock_Sandstone_Cobble"
    },
    {
      "x": -2,
      "y": 6,
      "z": -2,
      "name": "Rock_Sandstone_Cobble"
    },
    {
      "x": -2,
      "y": 7,
      "z": -2,
      "name": "Rock_Sandstone_Brick_Ornate"
    },
    {
      "x": -2,
      "y": 8,
      "z": -2,
      "name": "Rock_Sandstone_Brick"
    },
    {
      "x": -2,
      "y": 9,
      "z": -2,
      "name": "Rock_Sandstone_Brick"
    },
    {
      "x": -2,
      "y": 10,
      "z": -2,
      "name": "Rock_Sandstone_Brick_Smooth_Half"
    },
    {
      "x": -2,
      "y": 0,
      "z": -1,
      "name": "Rock_Sandstone_Cobble"
    },
    {
      "x": -2,
      "y": 1,
      "z": -1,
      "name": "Rock_Sandstone_Cobble"
    },
    {
      "x": -2,
      "y": 2,
      "z": -1,
      "name": "Rock_Sandstone_Cobble"
    },
    {
      "x": -2,
      "y": 3,
      "z": -1,
      "name": "Rock_Sandstone_Cobble"
    },
    {
      "x": -2,
      "y": 4,
      "z": -1,
      "name": "Rock_Sandstone_Cobble"
    },
    {
      "x": -2,
      "y": 5,
      "z": -1,
      "name": "Rock_Sandstone_Cobble"
    },
    {
      "x": -2,
      "y": 6,
      "z": -1,
      "name": "Rock_Sandstone_Cobble"
    },
    {
      "x": -2,
      "y": 7,
      "z": -1,
      "name": "Rock_Sandstone_Brick_Ornate"
    },
    {
      "x": -2,
      "y": 8,
      "z": -1,
      "name": "Rock_Sandstone_Brick"
    },
    {
      "x": -2,
      "y": 9,
      "z": -1,
      "name": "Rock_Sandstone_Brick"
    },
    {
      "x": -2,
      "y": 10,
      "z": -1,
      "name": "Rock_Sandstone_Brick_Smooth"
    },
    {
      "x": -2,
      "y": 8,
      "z": 0,
      "name": "Rock_Sandstone_Brick_Half",
      "rotation": 4
    },
    {
      "x": -2,
      "y": 9,
      "z": 0,
      "name": "Rock_Sandstone_Brick_Half",
      "rotation": 4
    },
    {
      "x": -2,
      "y": 4,
      "z": 1,
      "name": "Rock_Sandstone_Cobble"
    },
    {
      "x": -2,
      "y": 5,
      "z": 1,
      "name": "Rock_Sandstone_Cobble"
    },
    {
      "x": -2,
      "y": 6,
      "z": 1,
      "name": "Soil_Gravel_Sand_White"
    },
    {
      "x": -2,
      "y": 0,
      "z": 2,
      "name": "Rock_Sandstone_Cobble"
    },
    {
      "x": -2,
      "y": 1,
      "z": 2,
      "name": "Rock_Sandstone_Cobble"
    },
    {
      "x": -2,
      "y": 2,
      "z": 2,
      "name": "Rock_Sandstone_Cobble"
    },
    {
      "x": -2,
      "y": 3,
      "z": 2,
      "name": "Rock_Sandstone_Cobble"
    },
    {
      "x": -2,
      "y": 4,
      "z": 2,
      "name": "Rock_Sandstone_Cobble"
    },
    {
      "x": -2,
      "y": 5,
      "z": 2,
      "name": "Rock_Sandstone_Cobble"
    },
    {
      "x": -2,
      "y": 6,
      "z": 2,
      "name": "Soil_Gravel_Sand_White"
    },
    {
      "x": -2,
      "y": 7,
      "z": 2,
      "name": "Soil_Gravel_Sand_White"
    },
    {
      "x": -2,
      "y": 0,
      "z": 3,
      "name": "Rock_Sandstone_Cobble"
    },
    {
      "x": -2,
      "y": 1,
      "z": 3,
      "name": "Rock_Sandstone_Cobble"
    },
    {
      "x": -2,
      "y": 2,
      "z": 3,
      "name": "Rock_Sandstone_Cobble"
    },
    {
      "x": -2,
      "y": 3,
      "z": 3,
      "name": "Rock_Sandstone_Cobble"
    },
    {
      "x": -2,
      "y": 4,
      "z": 3,
      "name": "Rock_Sandstone_Cobble"
    },
    {
      "x": -2,
      "y": 5,
      "z": 3,
      "name": "Rock_Sandstone_Cobble"
    },
    {
      "x": -2,
      "y": 6,
      "z": 3,
      "name": "Rock_Sandstone_Brick"
    },
    {
      "x": -2,
      "y": 7,
      "z": 3,
      "name": "Soil_Gravel_Sand_White"
    },
    {
      "x": -2,
      "y": 0,
      "z": 4,
      "name": "Rock_Sandstone_Cobble"
    },
    {
      "x": -2,
      "y": 1,
      "z": 4,
      "name": "Rock_Sandstone_Cobble"
    },
    {
      "x": -2,
      "y": 2,
      "z": 4,
      "name": "Rock_Sandstone_Cobble"
    },
    {
      "x": -2,
      "y": 3,
      "z": 4,
      "name": "Rock_Sandstone_Cobble"
    },
    {
      "x": -2,
      "y": 4,
      "z": 4,
      "name": "Rock_Sandstone_Cobble"
    },
    {
      "x": -2,
      "y": 5,
      "z": 4,
      "name": "Rock_Sandstone_Brick"
    },
    {
      "x": -2,
      "y": 6,
      "z": 4,
      "name": "Rock_Sandstone_Brick"
    },
    {
      "x": -2,
      "y": 7,
      "z": 4,
      "name": "Rock_Sandstone_Brick_Ornate"
    },
    {
      "x": -2,
      "y": 8,
      "z": 4,
      "name": "Rock_Sandstone_Brick"
    },
    {
      "x": -2,
      "y": 0,
      "z": 5,
      "name": "Rock_Sandstone_Cobble"
    },
    {
      "x": -2,
      "y": 1,
      "z": 5,
      "name": "Rock_Sandstone_Cobble"
    },
    {
      "x": -2,
      "y": 2,
      "z": 5,
      "name": "Rock_Sandstone_Cobble"
    },
    {
      "x": -2,
      "y": 3,
      "z": 5,
      "name": "Rock_Sandstone_Cobble"
    },
    {
      "x": -2,
      "y": 4,
      "z": 5,
      "name": "Rock_Sandstone_Cobble"
    },
    {
      "x": -2,
      "y": 5,
      "z": 5,
      "name": "Rock_Sandstone_Brick"
    },
    {
      "x": -2,
      "y": 6,
      "z": 5,
      "name": "Rock_Sandstone_Brick"
    },
    {
      "x": -2,
      "y": 7,
      "z": 5,
      "name": "Rock_Sandstone_Brick_Ornate"
    },
    {
      "x": -2,
      "y": 8,
      "z": 5,
      "name": "Rock_Sandstone_Brick"
    },
    {
      "x": -2,
      "y": 0,
      "z": 6,
      "name": "Rock_Sandstone_Cobble"
    },
    {
      "x": -2,
      "y": 1,
      "z": 6,
      "name": "Rock_Sandstone_Cobble"
    },
    {
      "x": -2,
      "y": 2,
      "z": 6,
      "name": "Rock_Sandstone_Cobble"
    },
    {
      "x": -2,
      "y": 3,
      "z": 6,
      "name": "Rock_Sandstone_Cobble"
    },
    {
      "x": -2,
      "y": 4,
      "z": 6,
      "name": "Rock_Sandstone_Brick"
    },
    {
      "x": -2,
      "y": 5,
      "z": 6,
      "name": "Rock_Sandstone_Brick"
    },
    {
      "x": -2,
      "y": 6,
      "z": 6,
      "name": "Rock_Sandstone_Brick"
    },
    {
      "x": -2,
      "y": 7,
      "z": 6,
      "name": "Rock_Sandstone_Brick_Ornate"
    },
    {
      "x": -2,
      "y": 8,
      "z": 6,
      "name": "Rock_Sandstone_Brick_Half"
    },
    {
      "x": -2,
      "y": 0,
      "z": 7,
      "name": "Rock_Sandstone_Cobble"
    },
    {
      "x": -2,
      "y": 1,
      "z": 7,
      "name": "Rock_Sandstone_Cobble"
    },
    {
      "x": -2,
      "y": 2,
      "z": 7,
      "name": "Rock_Sandstone_Cobble"
    },
    {
      "x": -2,
      "y": 3,
      "z": 7,
      "name": "Rock_Sandstone_Cobble"
    },
    {
      "x": -2,
      "y": 4,
      "z": 7,
      "name": "Rock_Sandstone_Brick"
    },
    {
      "x": -2,
      "y": 5,
      "z": 7,
      "name": "Rock_Sandstone_Brick"
    },
    {
      "x": -2,
      "y": 0,
      "z": 8,
      "name": "Rock_Sandstone_Cobble"
    },
    {
      "x": -2,
      "y": 1,
      "z": 8,
      "name": "Rock_Sandstone_Cobble"
    },
    {
      "x": -2,
      "y": 2,
      "z": 8,
      "name": "Rock_Sandstone_Cobble"
    },
    {
      "x": -2,
      "y": 3,
      "z": 8,
      "name": "Rock_Sandstone_Cobble"
    },
    {
      "x": -2,
      "y": 4,
      "z": 8,
      "name": "Rock_Sandstone_Cobble"
    },
    {
      "x": -2,
      "y": 5,
      "z": 8,
      "name": "Rock_Sandstone_Brick"
    },
    {
      "x": -2,
      "y": 0,
      "z": 9,
      "name": "Rock_Sandstone_Cobble"
    },
    {
      "x": -2,
      "y": 1,
      "z": 9,
      "name": "Rock_Sandstone_Cobble"
    },
    {
      "x": -2,
      "y": 2,
      "z": 9,
      "name": "Rock_Sandstone_Cobble"
    },
    {
      "x": -2,
      "y": 3,
      "z": 9,
      "name": "Rock_Sandstone_Cobble"
    },
    {
      "x": -2,
      "y": 4,
      "z": 9,
      "name": "Rock_Sandstone_Cobble"
    },
    {
      "x": -2,
      "y": 5,
      "z": 9,
      "name": "Rock_Sandstone_Brick_Half"
    },
    {
      "x": -1,
      "y": 0,
      "z": -9,
      "name": "Rock_Sandstone"
    },
    {
      "x": -1,
      "y": 1,
      "z": -9,
      "name": "Rock_Sandstone"
    },
    {
      "x": -1,
      "y": 2,
      "z": -9,
      "name": "Rock_Sandstone"
    },
    {
      "x": -1,
      "y": 3,
      "z": -9,
      "name": "Rock_Sandstone"
    },
    {
      "x": -1,
      "y": 4,
      "z": -9,
      "name": "Rock_Sandstone"
    },
    {
      "x": -1,
      "y": 5,
      "z": -9,
      "name": "Rock_Sandstone"
    },
    {
      "x": -1,
      "y": 6,
      "z": -9,
      "name": "Rock_Sandstone"
    },
    {
      "x": -1,
      "y": 7,
      "z": -9,
      "name": "Rock_Sandstone"
    },
    {
      "x": -1,
      "y": 8,
      "z": -9,
      "name": "Rock_Sandstone"
    },
    {
      "x": -1,
      "y": 9,
      "z": -9,
      "name": "Rock_Sandstone_White_Cobble"
    },
    {
      "x": -1,
      "y": 0,
      "z": -8,
      "name": "Rock_Sandstone"
    },
    {
      "x": -1,
      "y": 1,
      "z": -8,
      "name": "Rock_Sandstone"
    },
    {
      "x": -1,
      "y": 2,
      "z": -8,
      "name": "Rock_Sandstone"
    },
    {
      "x": -1,
      "y": 3,
      "z": -8,
      "name": "Rock_Sandstone"
    },
    {
      "x": -1,
      "y": 4,
      "z": -8,
      "name": "Rock_Sandstone"
    },
    {
      "x": -1,
      "y": 5,
      "z": -8,
      "name": "Rock_Sandstone"
    },
    {
      "x": -1,
      "y": 6,
      "z": -8,
      "name": "Rock_Sandstone"
    },
    {
      "x": -1,
      "y": 7,
      "z": -8,
      "name": "Rock_Sandstone"
    },
    {
      "x": -1,
      "y": 8,
      "z": -8,
      "name": "Rock_Sandstone"
    },
    {
      "x": -1,
      "y": 9,
      "z": -8,
      "name": "Rock_Sandstone_White_Cobble"
    },
    {
      "x": -1,
      "y": 0,
      "z": -7,
      "name": "Rock_Sandstone"
    },
    {
      "x": -1,
      "y": 1,
      "z": -7,
      "name": "Rock_Sandstone"
    },
    {
      "x": -1,
      "y": 2,
      "z": -7,
      "name": "Rock_Sandstone"
    },
    {
      "x": -1,
      "y": 3,
      "z": -7,
      "name": "Rock_Sandstone"
    },
    {
      "x": -1,
      "y": 4,
      "z": -7,
      "name": "Rock_Sandstone"
    },
    {
      "x": -1,
      "y": 5,
      "z": -7,
      "name": "Rock_Sandstone"
    },
    {
      "x": -1,
      "y": 6,
      "z": -7,
      "name": "Rock_Sandstone"
    },
    {
      "x": -1,
      "y": 7,
      "z": -7,
      "name": "Rock_Sandstone"
    },
    {
      "x": -1,
      "y": 8,
      "z": -7,
      "name": "Rock_Sandstone"
    },
    {
      "x": -1,
      "y": 9,
      "z": -7,
      "name": "Rock_Sandstone_White_Cobble_Half"
    },
    {
      "x": -1,
      "y": 0,
      "z": -6,
      "name": "Rock_Sandstone"
    },
    {
      "x": -1,
      "y": 1,
      "z": -6,
      "name": "Rock_Sandstone"
    },
    {
      "x": -1,
      "y": 2,
      "z": -6,
      "name": "Rock_Sandstone"
    },
    {
      "x": -1,
      "y": 3,
      "z": -6,
      "name": "Rock_Sandstone"
    },
    {
      "x": -1,
      "y": 4,
      "z": -6,
      "name": "Rock_Sandstone"
    },
    {
      "x": -1,
      "y": 5,
      "z": -6,
      "name": "Rock_Sandstone"
    },
    {
      "x": -1,
      "y": 6,
      "z": -6,
      "name": "Rock_Sandstone"
    },
    {
      "x": -1,
      "y": 7,
      "z": -6,
      "name": "Rock_Sandstone"
    },
    {
      "x": -1,
      "y": 8,
      "z": -6,
      "name": "Rock_Sandstone"
    },
    {
      "x": -1,
      "y": 9,
      "z": -6,
      "name": "Rock_Sandstone_White_Cobble_Half"
    },
    {
      "x": -1,
      "y": 0,
      "z": -5,
      "name": "Rock_Sandstone"
    },
    {
      "x": -1,
      "y": 1,
      "z": -5,
      "name": "Rock_Sandstone"
    },
    {
      "x": -1,
      "y": 2,
      "z": -5,
      "name": "Rock_Sandstone"
    },
    {
      "x": -1,
      "y": 3,
      "z": -5,
      "name": "Rock_Sandstone"
    },
    {
      "x": -1,
      "y": 4,
      "z": -5,
      "name": "Rock_Sandstone"
    },
    {
      "x": -1,
      "y": 5,
      "z": -5,
      "name": "Rock_Sandstone"
    },
    {
      "x": -1,
      "y": 6,
      "z": -5,
      "name": "Rock_Sandstone"
    },
    {
      "x": -1,
      "y": 7,
      "z": -5,
      "name": "Rock_Sandstone"
    },
    {
      "x": -1,
      "y": 8,
      "z": -5,
      "name": "Rock_Sandstone"
    },
    {
      "x": -1,
      "y": 9,
      "z": -5,
      "name": "Rock_Sandstone_White_Cobble_Half"
    },
    {
      "x": -1,
      "y": 0,
      "z": -4,
      "name": "Rock_Sandstone"
    },
    {
      "x": -1,
      "y": 1,
      "z": -4,
      "name": "Rock_Sandstone"
    },
    {
      "x": -1,
      "y": 2,
      "z": -4,
      "name": "Rock_Sandstone"
    },
    {
      "x": -1,
      "y": 3,
      "z": -4,
      "name": "Rock_Sandstone"
    },
    {
      "x": -1,
      "y": 4,
      "z": -4,
      "name": "Rock_Sandstone"
    },
    {
      "x": -1,
      "y": 5,
      "z": -4,
      "name": "Rock_Sandstone"
    },
    {
      "x": -1,
      "y": 6,
      "z": -4,
      "name": "Rock_Sandstone"
    },
    {
      "x": -1,
      "y": 7,
      "z": -4,
      "name": "Rock_Sandstone"
    },
    {
      "x": -1,
      "y": 8,
      "z": -4,
      "name": "Rock_Sandstone"
    },
    {
      "x": -1,
      "y": 9,
      "z": -4,
      "name": "Rock_Sandstone_White_Cobble"
    },
    {
      "x": -1,
      "y": 0,
      "z": -3,
      "name": "Rock_Sandstone"
    },
    {
      "x": -1,
      "y": 1,
      "z": -3,
      "name": "Rock_Sandstone"
    },
    {
      "x": -1,
      "y": 2,
      "z": -3,
      "name": "Rock_Sandstone"
    },
    {
      "x": -1,
      "y": 3,
      "z": -3,
      "name": "Rock_Sandstone"
    },
    {
      "x": -1,
      "y": 4,
      "z": -3,
      "name": "Rock_Sandstone"
    },
    {
      "x": -1,
      "y": 5,
      "z": -3,
      "name": "Rock_Sandstone"
    },
    {
      "x": -1,
      "y": 6,
      "z": -3,
      "name": "Rock_Sandstone"
    },
    {
      "x": -1,
      "y": 7,
      "z": -3,
      "name": "Rock_Sandstone"
    },
    {
      "x": -1,
      "y": 8,
      "z": -3,
      "name": "Rock_Sandstone"
    },
    {
      "x": -1,
      "y": 9,
      "z": -3,
      "name": "Rock_Sandstone_White_Cobble"
    },
    {
      "x": -1,
      "y": 0,
      "z": -2,
      "name": "Rock_Sandstone"
    },
    {
      "x": -1,
      "y": 1,
      "z": -2,
      "name": "Rock_Sandstone"
    },
    {
      "x": -1,
      "y": 2,
      "z": -2,
      "name": "Rock_Sandstone"
    },
    {
      "x": -1,
      "y": 3,
      "z": -2,
      "name": "Rock_Sandstone"
    },
    {
      "x": -1,
      "y": 4,
      "z": -2,
      "name": "Rock_Sandstone"
    },
    {
      "x": -1,
      "y": 5,
      "z": -2,
      "name": "Rock_Sandstone"
    },
    {
      "x": -1,
      "y": 6,
      "z": -2,
      "name": "Rock_Sandstone"
    },
    {
      "x": -1,
      "y": 7,
      "z": -2,
      "name": "Rock_Sandstone"
    },
    {
      "x": -1,
      "y": 8,
      "z": -2,
      "name": "Rock_Sandstone"
    },
    {
      "x": -1,
      "y": 9,
      "z": -2,
      "name": "Rock_Sandstone_White_Cobble"
    },
    {
      "x": -1,
      "y": 0,
      "z": -1,
      "name": "Rock_Sandstone"
    },
    {
      "x": -1,
      "y": 1,
      "z": -1,
      "name": "Rock_Sandstone"
    },
    {
      "x": -1,
      "y": 2,
      "z": -1,
      "name": "Rock_Sandstone"
    },
    {
      "x": -1,
      "y": 3,
      "z": -1,
      "name": "Rock_Sandstone"
    },
    {
      "x": -1,
      "y": 4,
      "z": -1,
      "name": "Rock_Sandstone"
    },
    {
      "x": -1,
      "y": 5,
      "z": -1,
      "name": "Rock_Sandstone"
    },
    {
      "x": -1,
      "y": 6,
      "z": -1,
      "name": "Rock_Sandstone"
    },
    {
      "x": -1,
      "y": 7,
      "z": -1,
      "name": "Rock_Sandstone"
    },
    {
      "x": -1,
      "y": 8,
      "z": -1,
      "name": "Soil_Gravel_Sand_White"
    },
    {
      "x": -1,
      "y": 0,
      "z": 0,
      "name": "Rock_Sandstone"
    },
    {
      "x": -1,
      "y": 1,
      "z": 0,
      "name": "Rock_Sandstone"
    },
    {
      "x": -1,
      "y": 2,
      "z": 0,
      "name": "Rock_Sandstone"
    },
    {
      "x": -1,
      "y": 3,
      "z": 0,
      "name": "Rock_Sandstone"
    },
    {
      "x": -1,
      "y": 4,
      "z": 0,
      "name": "Rock_Sandstone"
    },
    {
      "x": -1,
      "y": 5,
      "z": 0,
      "name": "Rock_Sandstone"
    },
    {
      "x": -1,
      "y": 6,
      "z": 0,
      "name": "Rock_Sandstone"
    },
    {
      "x": -1,
      "y": 7,
      "z": 0,
      "name": "Rock_Sandstone"
    },
    {
      "x": -1,
      "y": 8,
      "z": 0,
      "name": "Soil_Gravel_Sand_White"
    },
    {
      "x": -1,
      "y": 0,
      "z": 1,
      "name": "Rock_Sandstone"
    },
    {
      "x": -1,
      "y": 1,
      "z": 1,
      "name": "Rock_Sandstone"
    },
    {
      "x": -1,
      "y": 2,
      "z": 1,
      "name": "Rock_Sandstone"
    },
    {
      "x": -1,
      "y": 3,
      "z": 1,
      "name": "Rock_Sandstone"
    },
    {
      "x": -1,
      "y": 4,
      "z": 1,
      "name": "Rock_Sandstone"
    },
    {
      "x": -1,
      "y": 5,
      "z": 1,
      "name": "Rock_Sandstone"
    },
    {
      "x": -1,
      "y": 6,
      "z": 1,
      "name": "Rock_Sandstone"
    },
    {
      "x": -1,
      "y": 7,
      "z": 1,
      "name": "Soil_Gravel_Sand_White"
    },
    {
      "x": -1,
      "y": 8,
      "z": 1,
      "name": "Soil_Gravel_Sand_White"
    },
    {
      "x": -1,
      "y": 0,
      "z": 2,
      "name": "Rock_Sandstone"
    },
    {
      "x": -1,
      "y": 1,
      "z": 2,
      "name": "Rock_Sandstone"
    },
    {
      "x": -1,
      "y": 2,
      "z": 2,
      "name": "Rock_Sandstone"
    },
    {
      "x": -1,
      "y": 3,
      "z": 2,
      "name": "Rock_Sandstone"
    },
    {
      "x": -1,
      "y": 4,
      "z": 2,
      "name": "Rock_Sandstone"
    },
    {
      "x": -1,
      "y": 5,
      "z": 2,
      "name": "Rock_Sandstone"
    },
    {
      "x": -1,
      "y": 6,
      "z": 2,
      "name": "Rock_Sandstone"
    },
    {
      "x": -1,
      "y": 7,
      "z": 2,
      "name": "Soil_Gravel_Sand_White"
    },
    {
      "x": -1,
      "y": 8,
      "z": 2,
      "name": "Soil_Gravel_Sand_White"
    },
    {
      "x": -1,
      "y": 0,
      "z": 3,
      "name": "Rock_Sandstone"
    },
    {
      "x": -1,
      "y": 1,
      "z": 3,
      "name": "Rock_Sandstone"
    },
    {
      "x": -1,
      "y": 2,
      "z": 3,
      "name": "Rock_Sandstone"
    },
    {
      "x": -1,
      "y": 3,
      "z": 3,
      "name": "Rock_Sandstone"
    },
    {
      "x": -1,
      "y": 4,
      "z": 3,
      "name": "Rock_Sandstone"
    },
    {
      "x": -1,
      "y": 5,
      "z": 3,
      "name": "Rock_Sandstone"
    },
    {
      "x": -1,
      "y": 6,
      "z": 3,
      "name": "Rock_Sandstone"
    },
    {
      "x": -1,
      "y": 7,
      "z": 3,
      "name": "Soil_Gravel_Sand_White"
    },
    {
      "x": -1,
      "y": 0,
      "z": 4,
      "name": "Rock_Sandstone"
    },
    {
      "x": -1,
      "y": 1,
      "z": 4,
      "name": "Rock_Sandstone"
    },
    {
      "x": -1,
      "y": 2,
      "z": 4,
      "name": "Rock_Sandstone"
    },
    {
      "x": -1,
      "y": 3,
      "z": 4,
      "name": "Rock_Sandstone"
    },
    {
      "x": -1,
      "y": 4,
      "z": 4,
      "name": "Rock_Sandstone"
    },
    {
      "x": -1,
      "y": 5,
      "z": 4,
      "name": "Rock_Sandstone"
    },
    {
      "x": -1,
      "y": 6,
      "z": 4,
      "name": "Rock_Sandstone"
    },
    {
      "x": -1,
      "y": 7,
      "z": 4,
      "name": "Soil_Gravel_Sand_White"
    },
    {
      "x": -1,
      "y": 0,
      "z": 5,
      "name": "Rock_Sandstone"
    },
    {
      "x": -1,
      "y": 1,
      "z": 5,
      "name": "Rock_Sandstone"
    },
    {
      "x": -1,
      "y": 2,
      "z": 5,
      "name": "Rock_Sandstone"
    },
    {
      "x": -1,
      "y": 3,
      "z": 5,
      "name": "Rock_Sandstone"
    },
    {
      "x": -1,
      "y": 4,
      "z": 5,
      "name": "Rock_Sandstone"
    },
    {
      "x": -1,
      "y": 5,
      "z": 5,
      "name": "Rock_Sandstone"
    },
    {
      "x": -1,
      "y": 6,
      "z": 5,
      "name": "Rock_Sandstone"
    },
    {
      "x": -1,
      "y": 7,
      "z": 5,
      "name": "Soil_Gravel_Sand_White"
    },
    {
      "x": -1,
      "y": 0,
      "z": 6,
      "name": "Rock_Sandstone"
    },
    {
      "x": -1,
      "y": 1,
      "z": 6,
      "name": "Rock_Sandstone"
    },
    {
      "x": -1,
      "y": 2,
      "z": 6,
      "name": "Rock_Sandstone"
    },
    {
      "x": -1,
      "y": 3,
      "z": 6,
      "name": "Rock_Sandstone"
    },
    {
      "x": -1,
      "y": 4,
      "z": 6,
      "name": "Rock_Sandstone"
    },
    {
      "x": -1,
      "y": 5,
      "z": 6,
      "name": "Rock_Sandstone"
    },
    {
      "x": -1,
      "y": 6,
      "z": 6,
      "name": "Soil_Gravel_Sand_White"
    },
    {
      "x": -1,
      "y": 0,
      "z": 7,
      "name": "Rock_Sandstone"
    },
    {
      "x": -1,
      "y": 1,
      "z": 7,
      "name": "Rock_Sandstone"
    },
    {
      "x": -1,
      "y": 2,
      "z": 7,
      "name": "Rock_Sandstone"
    },
    {
      "x": -1,
      "y": 3,
      "z": 7,
      "name": "Rock_Sandstone"
    },
    {
      "x": -1,
      "y": 4,
      "z": 7,
      "name": "Rock_Sandstone"
    },
    {
      "x": -1,
      "y": 5,
      "z": 7,
      "name": "Soil_Gravel_Sand_White"
    },
    {
      "x": -1,
      "y": 0,
      "z": 8,
      "name": "Rock_Sandstone"
    },
    {
      "x": -1,
      "y": 1,
      "z": 8,
      "name": "Rock_Sandstone"
    },
    {
      "x": -1,
      "y": 2,
      "z": 8,
      "name": "Rock_Sandstone"
    },
    {
      "x": -1,
      "y": 3,
      "z": 8,
      "name": "Rock_Sandstone"
    },
    {
      "x": -1,
      "y": 4,
      "z": 8,
      "name": "Rock_Sandstone"
    },
    {
      "x": -1,
      "y": 5,
      "z": 8,
      "name": "Soil_Gravel_Sand_White"
    },
    {
      "x": -1,
      "y": 0,
      "z": 9,
      "name": "Rock_Sandstone"
    },
    {
      "x": -1,
      "y": 1,
      "z": 9,
      "name": "Rock_Sandstone"
    },
    {
      "x": -1,
      "y": 2,
      "z": 9,
      "name": "Rock_Sandstone"
    },
    {
      "x": -1,
      "y": 3,
      "z": 9,
      "name": "Rock_Sandstone"
    },
    {
      "x": -1,
      "y": 4,
      "z": 9,
      "name": "Soil_Gravel_Sand_White"
    },
    {
      "x": 0,
      "y": 0,
      "z": -9,
      "name": "Rock_Sandstone"
    },
    {
      "x": 0,
      "y": 1,
      "z": -9,
      "name": "Rock_Sandstone"
    },
    {
      "x": 0,
      "y": 2,
      "z": -9,
      "name": "Rock_Sandstone"
    },
    {
      "x": 0,
      "y": 3,
      "z": -9,
      "name": "Rock_Sandstone"
    },
    {
      "x": 0,
      "y": 4,
      "z": -9,
      "name": "Rock_Sandstone"
    },
    {
      "x": 0,
      "y": 5,
      "z": -9,
      "name": "Rock_Sandstone"
    },
    {
      "x": 0,
      "y": 6,
      "z": -9,
      "name": "Rock_Sandstone"
    },
    {
      "x": 0,
      "y": 7,
      "z": -9,
      "name": "Rock_Sandstone"
    },
    {
      "x": 0,
      "y": 8,
      "z": -9,
      "name": "Rock_Sandstone"
    },
    {
      "x": 0,
      "y": 9,
      "z": -9,
      "name": "Rock_Sandstone_White_Cobble"
    },
    {
      "x": 0,
      "y": 0,
      "z": -8,
      "name": "Rock_Sandstone"
    },
    {
      "x": 0,
      "y": 1,
      "z": -8,
      "name": "Rock_Sandstone"
    },
    {
      "x": 0,
      "y": 2,
      "z": -8,
      "name": "Rock_Sandstone"
    },
    {
      "x": 0,
      "y": 3,
      "z": -8,
      "name": "Rock_Sandstone"
    },
    {
      "x": 0,
      "y": 4,
      "z": -8,
      "name": "Rock_Sandstone"
    },
    {
      "x": 0,
      "y": 5,
      "z": -8,
      "name": "Rock_Sandstone"
    },
    {
      "x": 0,
      "y": 6,
      "z": -8,
      "name": "Rock_Sandstone"
    },
    {
      "x": 0,
      "y": 7,
      "z": -8,
      "name": "Rock_Sandstone"
    },
    {
      "x": 0,
      "y": 8,
      "z": -8,
      "name": "Rock_Sandstone"
    },
    {
      "x": 0,
      "y": 9,
      "z": -8,
      "name": "Rock_Sandstone_White_Cobble"
    },
    {
      "x": 0,
      "y": 0,
      "z": -7,
      "name": "Rock_Sandstone"
    },
    {
      "x": 0,
      "y": 1,
      "z": -7,
      "name": "Rock_Sandstone"
    },
    {
      "x": 0,
      "y": 2,
      "z": -7,
      "name": "Rock_Sandstone"
    },
    {
      "x": 0,
      "y": 3,
      "z": -7,
      "name": "Rock_Sandstone"
    },
    {
      "x": 0,
      "y": 4,
      "z": -7,
      "name": "Rock_Sandstone"
    },
    {
      "x": 0,
      "y": 5,
      "z": -7,
      "name": "Rock_Sandstone"
    },
    {
      "x": 0,
      "y": 6,
      "z": -7,
      "name": "Rock_Sandstone"
    },
    {
      "x": 0,
      "y": 7,
      "z": -7,
      "name": "Rock_Sandstone"
    },
    {
      "x": 0,
      "y": 8,
      "z": -7,
      "name": "Rock_Sandstone"
    },
    {
      "x": 0,
      "y": 9,
      "z": -7,
      "name": "Rock_Sandstone_White_Cobble"
    },
    {
      "x": 0,
      "y": 0,
      "z": -6,
      "name": "Rock_Sandstone"
    },
    {
      "x": 0,
      "y": 1,
      "z": -6,
      "name": "Rock_Sandstone"
    },
    {
      "x": 0,
      "y": 2,
      "z": -6,
      "name": "Rock_Sandstone"
    },
    {
      "x": 0,
      "y": 3,
      "z": -6,
      "name": "Rock_Sandstone"
    },
    {
      "x": 0,
      "y": 4,
      "z": -6,
      "name": "Rock_Sandstone"
    },
    {
      "x": 0,
      "y": 5,
      "z": -6,
      "name": "Rock_Sandstone"
    },
    {
      "x": 0,
      "y": 6,
      "z": -6,
      "name": "Rock_Sandstone"
    },
    {
      "x": 0,
      "y": 7,
      "z": -6,
      "name": "Rock_Sandstone"
    },
    {
      "x": 0,
      "y": 8,
      "z": -6,
      "name": "Rock_Sandstone"
    },
    {
      "x": 0,
      "y": 9,
      "z": -6,
      "name": "Rock_Sandstone_White_Cobble_Half"
    },
    {
      "x": 0,
      "y": 0,
      "z": -5,
      "name": "Rock_Sandstone"
    },
    {
      "x": 0,
      "y": 1,
      "z": -5,
      "name": "Rock_Sandstone"
    },
    {
      "x": 0,
      "y": 2,
      "z": -5,
      "name": "Rock_Sandstone"
    },
    {
      "x": 0,
      "y": 3,
      "z": -5,
      "name": "Rock_Sandstone"
    },
    {
      "x": 0,
      "y": 4,
      "z": -5,
      "name": "Rock_Sandstone"
    },
    {
      "x": 0,
      "y": 5,
      "z": -5,
      "name": "Rock_Sandstone"
    },
    {
      "x": 0,
      "y": 6,
      "z": -5,
      "name": "Rock_Sandstone"
    },
    {
      "x": 0,
      "y": 7,
      "z": -5,
      "name": "Rock_Sandstone"
    },
    {
      "x": 0,
      "y": 8,
      "z": -5,
      "name": "Rock_Sandstone"
    },
    {
      "x": 0,
      "y": 9,
      "z": -5,
      "name": "Rock_Sandstone_White_Cobble_Half"
    },
    {
      "x": 0,
      "y": 0,
      "z": -4,
      "name": "Rock_Sandstone"
    },
    {
      "x": 0,
      "y": 1,
      "z": -4,
      "name": "Rock_Sandstone"
    },
    {
      "x": 0,
      "y": 2,
      "z": -4,
      "name": "Rock_Sandstone"
    },
    {
      "x": 0,
      "y": 3,
      "z": -4,
      "name": "Rock_Sandstone"
    },
    {
      "x": 0,
      "y": 4,
      "z": -4,
      "name": "Rock_Sandstone"
    },
    {
      "x": 0,
      "y": 5,
      "z": -4,
      "name": "Rock_Sandstone"
    },
    {
      "x": 0,
      "y": 6,
      "z": -4,
      "name": "Rock_Sandstone"
    },
    {
      "x": 0,
      "y": 7,
      "z": -4,
      "name": "Rock_Sandstone"
    },
    {
      "x": 0,
      "y": 8,
      "z": -4,
      "name": "Rock_Sandstone"
    },
    {
      "x": 0,
      "y": 9,
      "z": -4,
      "name": "Rock_Sandstone_White_Cobble"
    },
    {
      "x": 0,
      "y": 0,
      "z": -3,
      "name": "Rock_Sandstone"
    },
    {
      "x": 0,
      "y": 1,
      "z": -3,
      "name": "Rock_Sandstone"
    },
    {
      "x": 0,
      "y": 2,
      "z": -3,
      "name": "Rock_Sandstone"
    },
    {
      "x": 0,
      "y": 3,
      "z": -3,
      "name": "Rock_Sandstone"
    },
    {
      "x": 0,
      "y": 4,
      "z": -3,
      "name": "Rock_Sandstone"
    },
    {
      "x": 0,
      "y": 5,
      "z": -3,
      "name": "Rock_Sandstone"
    },
    {
      "x": 0,
      "y": 6,
      "z": -3,
      "name": "Rock_Sandstone"
    },
    {
      "x": 0,
      "y": 7,
      "z": -3,
      "name": "Rock_Sandstone"
    },
    {
      "x": 0,
      "y": 8,
      "z": -3,
      "name": "Rock_Sandstone"
    },
    {
      "x": 0,
      "y": 9,
      "z": -3,
      "name": "Rock_Sandstone_White_Cobble"
    },
    {
      "x": 0,
      "y": 0,
      "z": -2,
      "name": "Rock_Sandstone"
    },
    {
      "x": 0,
      "y": 1,
      "z": -2,
      "name": "Rock_Sandstone"
    },
    {
      "x": 0,
      "y": 2,
      "z": -2,
      "name": "Rock_Sandstone"
    },
    {
      "x": 0,
      "y": 3,
      "z": -2,
      "name": "Rock_Sandstone"
    },
    {
      "x": 0,
      "y": 4,
      "z": -2,
      "name": "Rock_Sandstone"
    },
    {
      "x": 0,
      "y": 5,
      "z": -2,
      "name": "Rock_Sandstone"
    },
    {
      "x": 0,
      "y": 6,
      "z": -2,
      "name": "Rock_Sandstone"
    },
    {
      "x": 0,
      "y": 7,
      "z": -2,
      "name": "Rock_Sandstone"
    },
    {
      "x": 0,
      "y": 8,
      "z": -2,
      "name": "Rock_Sandstone"
    },
    {
      "x": 0,
      "y": 9,
      "z": -2,
      "name": "Rock_Sandstone_White_Cobble"
    },
    {
      "x": 0,
      "y": 0,
      "z": -1,
      "name": "Rock_Sandstone"
    },
    {
      "x": 0,
      "y": 1,
      "z": -1,
      "name": "Rock_Sandstone"
    },
    {
      "x": 0,
      "y": 2,
      "z": -1,
      "name": "Rock_Sandstone"
    },
    {
      "x": 0,
      "y": 3,
      "z": -1,
      "name": "Rock_Sandstone"
    },
    {
      "x": 0,
      "y": 4,
      "z": -1,
      "name": "Rock_Sandstone"
    },
    {
      "x": 0,
      "y": 5,
      "z": -1,
      "name": "Rock_Sandstone"
    },
    {
      "x": 0,
      "y": 6,
      "z": -1,
      "name": "Rock_Sandstone"
    },
    {
      "x": 0,
      "y": 7,
      "z": -1,
      "name": "Rock_Sandstone"
    },
    {
      "x": 0,
      "y": 8,
      "z": -1,
      "name": "Rock_Sandstone"
    },
    {
      "x": 0,
      "y": 9,
      "z": -1,
      "name": "Rock_Sandstone_White_Cobble"
    },
    {
      "x": 0,
      "y": 0,
      "z": 0,
      "name": "Rock_Sandstone"
    },
    {
      "x": 0,
      "y": 1,
      "z": 0,
      "name": "Rock_Sandstone"
    },
    {
      "x": 0,
      "y": 2,
      "z": 0,
      "name": "Rock_Sandstone"
    },
    {
      "x": 0,
      "y": 3,
      "z": 0,
      "name": "Rock_Sandstone"
    },
    {
      "x": 0,
      "y": 4,
      "z": 0,
      "name": "Rock_Sandstone"
    },
    {
      "x": 0,
      "y": 5,
      "z": 0,
      "name": "Rock_Sandstone"
    },
    {
      "x": 0,
      "y": 6,
      "z": 0,
      "name": "Rock_Sandstone"
    },
    {
      "x": 0,
      "y": 7,
      "z": 0,
      "name": "Rock_Sandstone"
    },
    {
      "x": 0,
      "y": 8,
      "z": 0,
      "name": "Rock_Sandstone"
    },
    {
      "x": 0,
      "y": 9,
      "z": 0,
      "name": "Rock_Sandstone_White_Cobble_Half"
    },
    {
      "x": 0,
      "y": 0,
      "z": 1,
      "name": "Rock_Sandstone"
    },
    {
      "x": 0,
      "y": 1,
      "z": 1,
      "name": "Rock_Sandstone"
    },
    {
      "x": 0,
      "y": 2,
      "z": 1,
      "name": "Rock_Sandstone"
    },
    {
      "x": 0,
      "y": 3,
      "z": 1,
      "name": "Rock_Sandstone"
    },
    {
      "x": 0,
      "y": 4,
      "z": 1,
      "name": "Rock_Sandstone"
    },
    {
      "x": 0,
      "y": 5,
      "z": 1,
      "name": "Rock_Sandstone"
    },
    {
      "x": 0,
      "y": 6,
      "z": 1,
      "name": "Rock_Sandstone"
    },
    {
      "x": 0,
      "y": 7,
      "z": 1,
      "name": "Rock_Sandstone"
    },
    {
      "x": 0,
      "y": 8,
      "z": 1,
      "name": "Soil_Gravel_Sand_White"
    },
    {
      "x": 0,
      "y": 0,
      "z": 2,
      "name": "Rock_Sandstone"
    },
    {
      "x": 0,
      "y": 1,
      "z": 2,
      "name": "Rock_Sandstone"
    },
    {
      "x": 0,
      "y": 2,
      "z": 2,
      "name": "Rock_Sandstone"
    },
    {
      "x": 0,
      "y": 3,
      "z": 2,
      "name": "Rock_Sandstone"
    },
    {
      "x": 0,
      "y": 4,
      "z": 2,
      "name": "Rock_Sandstone"
    },
    {
      "x": 0,
      "y": 5,
      "z": 2,
      "name": "Rock_Sandstone"
    },
    {
      "x": 0,
      "y": 6,
      "z": 2,
      "name": "Rock_Sandstone"
    },
    {
      "x": 0,
      "y": 7,
      "z": 2,
      "name": "Soil_Gravel_Sand_White"
    },
    {
      "x": 0,
      "y": 8,
      "z": 2,
      "name": "Soil_Gravel_Sand_White"
    },
    {
      "x": 0,
      "y": 0,
      "z": 3,
      "name": "Rock_Sandstone"
    },
    {
      "x": 0,
      "y": 1,
      "z": 3,
      "name": "Rock_Sandstone"
    },
    {
      "x": 0,
      "y": 2,
      "z": 3,
      "name": "Rock_Sandstone"
    },
    {
      "x": 0,
      "y": 3,
      "z": 3,
      "name": "Rock_Sandstone"
    },
    {
      "x": 0,
      "y": 4,
      "z": 3,
      "name": "Rock_Sandstone"
    },
    {
      "x": 0,
      "y": 5,
      "z": 3,
      "name": "Rock_Sandstone"
    },
    {
      "x": 0,
      "y": 6,
      "z": 3,
      "name": "Rock_Sandstone"
    },
    {
      "x": 0,
      "y": 7,
      "z": 3,
      "name": "Soil_Gravel_Sand_White"
    },
    {
      "x": 0,
      "y": 0,
      "z": 4,
      "name": "Rock_Sandstone"
    },
    {
      "x": 0,
      "y": 1,
      "z": 4,
      "name": "Rock_Sandstone"
    },
    {
      "x": 0,
      "y": 2,
      "z": 4,
      "name": "Rock_Sandstone"
    },
    {
      "x": 0,
      "y": 3,
      "z": 4,
      "name": "Rock_Sandstone"
    },
    {
      "x": 0,
      "y": 4,
      "z": 4,
      "name": "Rock_Sandstone"
    },
    {
      "x": 0,
      "y": 5,
      "z": 4,
      "name": "Rock_Sandstone"
    },
    {
      "x": 0,
      "y": 6,
      "z": 4,
      "name": "Rock_Sandstone"
    },
    {
      "x": 0,
      "y": 7,
      "z": 4,
      "name": "Soil_Gravel_Sand_White"
    },
    {
      "x": 0,
      "y": 0,
      "z": 5,
      "name": "Rock_Sandstone"
    },
    {
      "x": 0,
      "y": 1,
      "z": 5,
      "name": "Rock_Sandstone"
    },
    {
      "x": 0,
      "y": 2,
      "z": 5,
      "name": "Rock_Sandstone"
    },
    {
      "x": 0,
      "y": 3,
      "z": 5,
      "name": "Rock_Sandstone"
    },
    {
      "x": 0,
      "y": 4,
      "z": 5,
      "name": "Rock_Sandstone"
    },
    {
      "x": 0,
      "y": 5,
      "z": 5,
      "name": "Rock_Sandstone"
    },
    {
      "x": 0,
      "y": 6,
      "z": 5,
      "name": "Rock_Sandstone"
    },
    {
      "x": 0,
      "y": 7,
      "z": 5,
      "name": "Soil_Gravel_Sand_White"
    },
    {
      "x": 0,
      "y": 0,
      "z": 6,
      "name": "Rock_Sandstone"
    },
    {
      "x": 0,
      "y": 1,
      "z": 6,
      "name": "Rock_Sandstone"
    },
    {
      "x": 0,
      "y": 2,
      "z": 6,
      "name": "Rock_Sandstone"
    },
    {
      "x": 0,
      "y": 3,
      "z": 6,
      "name": "Rock_Sandstone"
    },
    {
      "x": 0,
      "y": 4,
      "z": 6,
      "name": "Rock_Sandstone"
    },
    {
      "x": 0,
      "y": 5,
      "z": 6,
      "name": "Rock_Sandstone"
    },
    {
      "x": 0,
      "y": 6,
      "z": 6,
      "name": "Soil_Gravel_Sand_White"
    },
    {
      "x": 0,
      "y": 0,
      "z": 7,
      "name": "Rock_Sandstone"
    },
    {
      "x": 0,
      "y": 1,
      "z": 7,
      "name": "Rock_Sandstone"
    },
    {
      "x": 0,
      "y": 2,
      "z": 7,
      "name": "Rock_Sandstone"
    },
    {
      "x": 0,
      "y": 3,
      "z": 7,
      "name": "Rock_Sandstone"
    },
    {
      "x": 0,
      "y": 4,
      "z": 7,
      "name": "Rock_Sandstone"
    },
    {
      "x": 0,
      "y": 5,
      "z": 7,
      "name": "Soil_Gravel_Sand_White"
    },
    {
      "x": 0,
      "y": 0,
      "z": 8,
      "name": "Rock_Sandstone"
    },
    {
      "x": 0,
      "y": 1,
      "z": 8,
      "name": "Rock_Sandstone"
    },
    {
      "x": 0,
      "y": 2,
      "z": 8,
      "name": "Rock_Sandstone"
    },
    {
      "x": 0,
      "y": 3,
      "z": 8,
      "name": "Rock_Sandstone"
    },
    {
      "x": 0,
      "y": 4,
      "z": 8,
      "name": "Rock_Sandstone"
    },
    {
      "x": 0,
      "y": 5,
      "z": 8,
      "name": "Soil_Gravel_Sand_White"
    },
    {
      "x": 0,
      "y": 0,
      "z": 9,
      "name": "Rock_Sandstone"
    },
    {
      "x": 0,
      "y": 1,
      "z": 9,
      "name": "Rock_Sandstone"
    },
    {
      "x": 0,
      "y": 2,
      "z": 9,
      "name": "Rock_Sandstone"
    },
    {
      "x": 0,
      "y": 3,
      "z": 9,
      "name": "Rock_Sandstone"
    },
    {
      "x": 0,
      "y": 4,
      "z": 9,
      "name": "Soil_Gravel_Sand_White"
    },
    {
      "x": 1,
      "y": 0,
      "z": -9,
      "name": "Rock_Sandstone"
    },
    {
      "x": 1,
      "y": 1,
      "z": -9,
      "name": "Rock_Sandstone"
    },
    {
      "x": 1,
      "y": 2,
      "z": -9,
      "name": "Rock_Sandstone"
    },
    {
      "x": 1,
      "y": 3,
      "z": -9,
      "name": "Rock_Sandstone"
    },
    {
      "x": 1,
      "y": 4,
      "z": -9,
      "name": "Rock_Sandstone"
    },
    {
      "x": 1,
      "y": 5,
      "z": -9,
      "name": "Rock_Sandstone"
    },
    {
      "x": 1,
      "y": 6,
      "z": -9,
      "name": "Rock_Sandstone"
    },
    {
      "x": 1,
      "y": 7,
      "z": -9,
      "name": "Rock_Sandstone"
    },
    {
      "x": 1,
      "y": 8,
      "z": -9,
      "name": "Rock_Sandstone"
    },
    {
      "x": 1,
      "y": 9,
      "z": -9,
      "name": "Rock_Sandstone_White_Cobble"
    },
    {
      "x": 1,
      "y": 0,
      "z": -8,
      "name": "Rock_Sandstone"
    },
    {
      "x": 1,
      "y": 1,
      "z": -8,
      "name": "Rock_Sandstone"
    },
    {
      "x": 1,
      "y": 2,
      "z": -8,
      "name": "Rock_Sandstone"
    },
    {
      "x": 1,
      "y": 3,
      "z": -8,
      "name": "Rock_Sandstone"
    },
    {
      "x": 1,
      "y": 4,
      "z": -8,
      "name": "Rock_Sandstone"
    },
    {
      "x": 1,
      "y": 5,
      "z": -8,
      "name": "Rock_Sandstone"
    },
    {
      "x": 1,
      "y": 6,
      "z": -8,
      "name": "Rock_Sandstone"
    },
    {
      "x": 1,
      "y": 7,
      "z": -8,
      "name": "Rock_Sandstone"
    },
    {
      "x": 1,
      "y": 8,
      "z": -8,
      "name": "Rock_Sandstone"
    },
    {
      "x": 1,
      "y": 9,
      "z": -8,
      "name": "Rock_Sandstone_White_Cobble"
    },
    {
      "x": 1,
      "y": 0,
      "z": -7,
      "name": "Rock_Sandstone"
    },
    {
      "x": 1,
      "y": 1,
      "z": -7,
      "name": "Rock_Sandstone"
    },
    {
      "x": 1,
      "y": 2,
      "z": -7,
      "name": "Rock_Sandstone"
    },
    {
      "x": 1,
      "y": 3,
      "z": -7,
      "name": "Rock_Sandstone"
    },
    {
      "x": 1,
      "y": 4,
      "z": -7,
      "name": "Rock_Sandstone"
    },
    {
      "x": 1,
      "y": 5,
      "z": -7,
      "name": "Rock_Sandstone"
    },
    {
      "x": 1,
      "y": 6,
      "z": -7,
      "name": "Rock_Sandstone"
    },
    {
      "x": 1,
      "y": 7,
      "z": -7,
      "name": "Rock_Sandstone"
    },
    {
      "x": 1,
      "y": 8,
      "z": -7,
      "name": "Rock_Sandstone"
    },
    {
      "x": 1,
      "y": 9,
      "z": -7,
      "name": "Rock_Sandstone_White_Cobble"
    },
    {
      "x": 1,
      "y": 0,
      "z": -6,
      "name": "Rock_Sandstone"
    },
    {
      "x": 1,
      "y": 1,
      "z": -6,
      "name": "Rock_Sandstone"
    },
    {
      "x": 1,
      "y": 2,
      "z": -6,
      "name": "Rock_Sandstone"
    },
    {
      "x": 1,
      "y": 3,
      "z": -6,
      "name": "Rock_Sandstone"
    },
    {
      "x": 1,
      "y": 4,
      "z": -6,
      "name": "Rock_Sandstone"
    },
    {
      "x": 1,
      "y": 5,
      "z": -6,
      "name": "Rock_Sandstone"
    },
    {
      "x": 1,
      "y": 6,
      "z": -6,
      "name": "Rock_Sandstone"
    },
    {
      "x": 1,
      "y": 7,
      "z": -6,
      "name": "Rock_Sandstone"
    },
    {
      "x": 1,
      "y": 8,
      "z": -6,
      "name": "Rock_Sandstone"
    },
    {
      "x": 1,
      "y": 9,
      "z": -6,
      "name": "Rock_Sandstone_White_Cobble_Half"
    },
    {
      "x": 1,
      "y": 0,
      "z": -5,
      "name": "Rock_Sandstone"
    },
    {
      "x": 1,
      "y": 1,
      "z": -5,
      "name": "Rock_Sandstone"
    },
    {
      "x": 1,
      "y": 2,
      "z": -5,
      "name": "Rock_Sandstone"
    },
    {
      "x": 1,
      "y": 3,
      "z": -5,
      "name": "Rock_Sandstone"
    },
    {
      "x": 1,
      "y": 4,
      "z": -5,
      "name": "Rock_Sandstone"
    },
    {
      "x": 1,
      "y": 5,
      "z": -5,
      "name": "Rock_Sandstone"
    },
    {
      "x": 1,
      "y": 6,
      "z": -5,
      "name": "Rock_Sandstone"
    },
    {
      "x": 1,
      "y": 7,
      "z": -5,
      "name": "Rock_Sandstone"
    },
    {
      "x": 1,
      "y": 8,
      "z": -5,
      "name": "Rock_Sandstone"
    },
    {
      "x": 1,
      "y": 9,
      "z": -5,
      "name": "Rock_Sandstone_White_Cobble_Half"
    },
    {
      "x": 1,
      "y": 0,
      "z": -4,
      "name": "Rock_Sandstone"
    },
    {
      "x": 1,
      "y": 1,
      "z": -4,
      "name": "Rock_Sandstone"
    },
    {
      "x": 1,
      "y": 2,
      "z": -4,
      "name": "Rock_Sandstone"
    },
    {
      "x": 1,
      "y": 3,
      "z": -4,
      "name": "Rock_Sandstone"
    },
    {
      "x": 1,
      "y": 4,
      "z": -4,
      "name": "Rock_Sandstone"
    },
    {
      "x": 1,
      "y": 5,
      "z": -4,
      "name": "Rock_Sandstone"
    },
    {
      "x": 1,
      "y": 6,
      "z": -4,
      "name": "Rock_Sandstone"
    },
    {
      "x": 1,
      "y": 7,
      "z": -4,
      "name": "Rock_Sandstone"
    },
    {
      "x": 1,
      "y": 8,
      "z": -4,
      "name": "Rock_Sandstone"
    },
    {
      "x": 1,
      "y": 9,
      "z": -4,
      "name": "Rock_Sandstone_White_Cobble_Half"
    },
    {
      "x": 1,
      "y": 0,
      "z": -3,
      "name": "Rock_Sandstone"
    },
    {
      "x": 1,
      "y": 1,
      "z": -3,
      "name": "Rock_Sandstone"
    },
    {
      "x": 1,
      "y": 2,
      "z": -3,
      "name": "Rock_Sandstone"
    },
    {
      "x": 1,
      "y": 3,
      "z": -3,
      "name": "Rock_Sandstone"
    },
    {
      "x": 1,
      "y": 4,
      "z": -3,
      "name": "Rock_Sandstone"
    },
    {
      "x": 1,
      "y": 5,
      "z": -3,
      "name": "Rock_Sandstone"
    },
    {
      "x": 1,
      "y": 6,
      "z": -3,
      "name": "Rock_Sandstone"
    },
    {
      "x": 1,
      "y": 7,
      "z": -3,
      "name": "Rock_Sandstone"
    },
    {
      "x": 1,
      "y": 8,
      "z": -3,
      "name": "Rock_Sandstone"
    },
    {
      "x": 1,
      "y": 9,
      "z": -3,
      "name": "Rock_Sandstone_White_Cobble"
    },
    {
      "x": 1,
      "y": 0,
      "z": -2,
      "name": "Rock_Sandstone"
    },
    {
      "x": 1,
      "y": 1,
      "z": -2,
      "name": "Rock_Sandstone"
    },
    {
      "x": 1,
      "y": 2,
      "z": -2,
      "name": "Rock_Sandstone"
    },
    {
      "x": 1,
      "y": 3,
      "z": -2,
      "name": "Rock_Sandstone"
    },
    {
      "x": 1,
      "y": 4,
      "z": -2,
      "name": "Rock_Sandstone"
    },
    {
      "x": 1,
      "y": 5,
      "z": -2,
      "name": "Rock_Sandstone"
    },
    {
      "x": 1,
      "y": 6,
      "z": -2,
      "name": "Rock_Sandstone"
    },
    {
      "x": 1,
      "y": 7,
      "z": -2,
      "name": "Rock_Sandstone"
    },
    {
      "x": 1,
      "y": 8,
      "z": -2,
      "name": "Rock_Sandstone"
    },
    {
      "x": 1,
      "y": 9,
      "z": -2,
      "name": "Rock_Sandstone_White_Cobble"
    },
    {
      "x": 1,
      "y": 0,
      "z": -1,
      "name": "Rock_Sandstone"
    },
    {
      "x": 1,
      "y": 1,
      "z": -1,
      "name": "Rock_Sandstone"
    },
    {
      "x": 1,
      "y": 2,
      "z": -1,
      "name": "Rock_Sandstone"
    },
    {
      "x": 1,
      "y": 3,
      "z": -1,
      "name": "Rock_Sandstone"
    },
    {
      "x": 1,
      "y": 4,
      "z": -1,
      "name": "Rock_Sandstone"
    },
    {
      "x": 1,
      "y": 5,
      "z": -1,
      "name": "Rock_Sandstone"
    },
    {
      "x": 1,
      "y": 6,
      "z": -1,
      "name": "Rock_Sandstone"
    },
    {
      "x": 1,
      "y": 7,
      "z": -1,
      "name": "Rock_Sandstone"
    },
    {
      "x": 1,
      "y": 8,
      "z": -1,
      "name": "Rock_Sandstone"
    },
    {
      "x": 1,
      "y": 9,
      "z": -1,
      "name": "Rock_Sandstone_White_Cobble"
    },
    {
      "x": 1,
      "y": 0,
      "z": 0,
      "name": "Rock_Sandstone"
    },
    {
      "x": 1,
      "y": 1,
      "z": 0,
      "name": "Rock_Sandstone"
    },
    {
      "x": 1,
      "y": 2,
      "z": 0,
      "name": "Rock_Sandstone"
    },
    {
      "x": 1,
      "y": 3,
      "z": 0,
      "name": "Rock_Sandstone"
    },
    {
      "x": 1,
      "y": 4,
      "z": 0,
      "name": "Rock_Sandstone"
    },
    {
      "x": 1,
      "y": 5,
      "z": 0,
      "name": "Rock_Sandstone"
    },
    {
      "x": 1,
      "y": 6,
      "z": 0,
      "name": "Rock_Sandstone"
    },
    {
      "x": 1,
      "y": 7,
      "z": 0,
      "name": "Rock_Sandstone"
    },
    {
      "x": 1,
      "y": 8,
      "z": 0,
      "name": "Rock_Sandstone"
    },
    {
      "x": 1,
      "y": 9,
      "z": 0,
      "name": "Rock_Sandstone_White_Cobble_Half"
    },
    {
      "x": 1,
      "y": 0,
      "z": 1,
      "name": "Rock_Sandstone"
    },
    {
      "x": 1,
      "y": 1,
      "z": 1,
      "name": "Rock_Sandstone"
    },
    {
      "x": 1,
      "y": 2,
      "z": 1,
      "name": "Rock_Sandstone"
    },
    {
      "x": 1,
      "y": 3,
      "z": 1,
      "name": "Rock_Sandstone"
    },
    {
      "x": 1,
      "y": 4,
      "z": 1,
      "name": "Rock_Sandstone"
    },
    {
      "x": 1,
      "y": 5,
      "z": 1,
      "name": "Rock_Sandstone"
    },
    {
      "x": 1,
      "y": 6,
      "z": 1,
      "name": "Rock_Sandstone"
    },
    {
      "x": 1,
      "y": 7,
      "z": 1,
      "name": "Soil_Gravel_Sand_White"
    },
    {
      "x": 1,
      "y": 8,
      "z": 1,
      "name": "Soil_Gravel_Sand_White"
    },
    {
      "x": 1,
      "y": 0,
      "z": 2,
      "name": "Rock_Sandstone"
    },
    {
      "x": 1,
      "y": 1,
      "z": 2,
      "name": "Rock_Sandstone"
    },
    {
      "x": 1,
      "y": 2,
      "z": 2,
      "name": "Rock_Sandstone"
    },
    {
      "x": 1,
      "y": 3,
      "z": 2,
      "name": "Rock_Sandstone"
    },
    {
      "x": 1,
      "y": 4,
      "z": 2,
      "name": "Rock_Sandstone"
    },
    {
      "x": 1,
      "y": 5,
      "z": 2,
      "name": "Rock_Sandstone"
    },
    {
      "x": 1,
      "y": 6,
      "z": 2,
      "name": "Rock_Sandstone"
    },
    {
      "x": 1,
      "y": 7,
      "z": 2,
      "name": "Soil_Gravel_Sand_White"
    },
    {
      "x": 1,
      "y": 0,
      "z": 3,
      "name": "Rock_Sandstone"
    },
    {
      "x": 1,
      "y": 1,
      "z": 3,
      "name": "Rock_Sandstone"
    },
    {
      "x": 1,
      "y": 2,
      "z": 3,
      "name": "Rock_Sandstone"
    },
    {
      "x": 1,
      "y": 3,
      "z": 3,
      "name": "Rock_Sandstone"
    },
    {
      "x": 1,
      "y": 4,
      "z": 3,
      "name": "Rock_Sandstone"
    },
    {
      "x": 1,
      "y": 5,
      "z": 3,
      "name": "Rock_Sandstone"
    },
    {
      "x": 1,
      "y": 6,
      "z": 3,
      "name": "Soil_Gravel_Sand_White"
    },
    {
      "x": 1,
      "y": 7,
      "z": 3,
      "name": "Soil_Gravel_Sand_White"
    },
    {
      "x": 1,
      "y": 0,
      "z": 4,
      "name": "Rock_Sandstone"
    },
    {
      "x": 1,
      "y": 1,
      "z": 4,
      "name": "Rock_Sandstone"
    },
    {
      "x": 1,
      "y": 2,
      "z": 4,
      "name": "Rock_Sandstone"
    },
    {
      "x": 1,
      "y": 3,
      "z": 4,
      "name": "Rock_Sandstone"
    },
    {
      "x": 1,
      "y": 4,
      "z": 4,
      "name": "Rock_Sandstone"
    },
    {
      "x": 1,
      "y": 5,
      "z": 4,
      "name": "Rock_Sandstone"
    },
    {
      "x": 1,
      "y": 6,
      "z": 4,
      "name": "Soil_Gravel_Sand_White"
    },
    {
      "x": 1,
      "y": 7,
      "z": 4,
      "name": "Soil_Gravel_Sand_White"
    },
    {
      "x": 1,
      "y": 0,
      "z": 5,
      "name": "Rock_Sandstone"
    },
    {
      "x": 1,
      "y": 1,
      "z": 5,
      "name": "Rock_Sandstone"
    },
    {
      "x": 1,
      "y": 2,
      "z": 5,
      "name": "Rock_Sandstone"
    },
    {
      "x": 1,
      "y": 3,
      "z": 5,
      "name": "Rock_Sandstone"
    },
    {
      "x": 1,
      "y": 4,
      "z": 5,
      "name": "Rock_Sandstone"
    },
    {
      "x": 1,
      "y": 5,
      "z": 5,
      "name": "Rock_Sandstone"
    },
    {
      "x": 1,
      "y": 6,
      "z": 5,
      "name": "Soil_Gravel_Sand_White"
    },
    {
      "x": 1,
      "y": 0,
      "z": 6,
      "name": "Rock_Sandstone"
    },
    {
      "x": 1,
      "y": 1,
      "z": 6,
      "name": "Rock_Sandstone"
    },
    {
      "x": 1,
      "y": 2,
      "z": 6,
      "name": "Rock_Sandstone"
    },
    {
      "x": 1,
      "y": 3,
      "z": 6,
      "name": "Rock_Sandstone"
    },
    {
      "x": 1,
      "y": 4,
      "z": 6,
      "name": "Rock_Sandstone"
    },
    {
      "x": 1,
      "y": 5,
      "z": 6,
      "name": "Soil_Gravel_Sand_White"
    },
    {
      "x": 1,
      "y": 6,
      "z": 6,
      "name": "Soil_Gravel_Sand_White"
    },
    {
      "x": 1,
      "y": 0,
      "z": 7,
      "name": "Rock_Sandstone"
    },
    {
      "x": 1,
      "y": 1,
      "z": 7,
      "name": "Rock_Sandstone"
    },
    {
      "x": 1,
      "y": 2,
      "z": 7,
      "name": "Rock_Sandstone"
    },
    {
      "x": 1,
      "y": 3,
      "z": 7,
      "name": "Rock_Sandstone"
    },
    {
      "x": 1,
      "y": 4,
      "z": 7,
      "name": "Soil_Gravel_Sand_White"
    },
    {
      "x": 1,
      "y": 5,
      "z": 7,
      "name": "Soil_Gravel_Sand_White"
    },
    {
      "x": 1,
      "y": 0,
      "z": 8,
      "name": "Rock_Sandstone"
    },
    {
      "x": 1,
      "y": 1,
      "z": 8,
      "name": "Rock_Sandstone"
    },
    {
      "x": 1,
      "y": 2,
      "z": 8,
      "name": "Rock_Sandstone"
    },
    {
      "x": 1,
      "y": 3,
      "z": 8,
      "name": "Rock_Sandstone"
    },
    {
      "x": 1,
      "y": 4,
      "z": 8,
      "name": "Soil_Gravel_Sand_White"
    },
    {
      "x": 1,
      "y": 0,
      "z": 9,
      "name": "Rock_Sandstone"
    },
    {
      "x": 1,
      "y": 1,
      "z": 9,
      "name": "Rock_Sandstone"
    },
    {
      "x": 1,
      "y": 2,
      "z": 9,
      "name": "Rock_Sandstone"
    },
    {
      "x": 1,
      "y": 3,
      "z": 9,
      "name": "Soil_Gravel_Sand_White"
    },
    {
      "x": 1,
      "y": 4,
      "z": 9,
      "name": "Soil_Gravel_Sand_White"
    },
    {
      "x": 2,
      "y": 0,
      "z": -9,
      "name": "Rock_Sandstone_Cobble"
    },
    {
      "x": 2,
      "y": 1,
      "z": -9,
      "name": "Rock_Sandstone_Cobble"
    },
    {
      "x": 2,
      "y": 2,
      "z": -9,
      "name": "Rock_Sandstone_Cobble"
    },
    {
      "x": 2,
      "y": 3,
      "z": -9,
      "name": "Rock_Sandstone_Cobble"
    },
    {
      "x": 2,
      "y": 4,
      "z": -9,
      "name": "Rock_Sandstone_Cobble"
    },
    {
      "x": 2,
      "y": 5,
      "z": -9,
      "name": "Rock_Sandstone_Brick"
    },
    {
      "x": 2,
      "y": 6,
      "z": -9,
      "name": "Rock_Sandstone_Brick"
    },
    {
      "x": 2,
      "y": 7,
      "z": -9,
      "name": "Rock_Sandstone_Brick_Ornate"
    },
    {
      "x": 2,
      "y": 8,
      "z": -9,
      "name": "Rock_Sandstone_Brick"
    },
    {
      "x": 2,
      "y": 9,
      "z": -9,
      "name": "Rock_Sandstone_Brick"
    },
    {
      "x": 2,
      "y": 0,
      "z": -8,
      "name": "Rock_Sandstone_Cobble"
    },
    {
      "x": 2,
      "y": 1,
      "z": -8,
      "name": "Rock_Sandstone_Cobble"
    },
    {
      "x": 2,
      "y": 2,
      "z": -8,
      "name": "Rock_Sandstone_Cobble"
    },
    {
      "x": 2,
      "y": 3,
      "z": -8,
      "name": "Rock_Sandstone_Cobble"
    },
    {
      "x": 2,
      "y": 4,
      "z": -8,
      "name": "Rock_Sandstone_Cobble"
    },
    {
      "x": 2,
      "y": 5,
      "z": -8,
      "name": "Rock_Sandstone_Cobble"
    },
    {
      "x": 2,
      "y": 6,
      "z": -8,
      "name": "Rock_Sandstone_Brick"
    },
    {
      "x": 2,
      "y": 7,
      "z": -8,
      "name": "Rock_Sandstone_Brick_Ornate"
    },
    {
      "x": 2,
      "y": 8,
      "z": -8,
      "name": "Rock_Sandstone_Brick"
    },
    {
      "x": 2,
      "y": 9,
      "z": -8,
      "name": "Rock_Sandstone_Brick"
    },
    {
      "x": 2,
      "y": 10,
      "z": -8,
      "name": "Rock_Sandstone_Brick_Smooth_Half"
    },
    {
      "x": 2,
      "y": 0,
      "z": -7,
      "name": "Rock_Sandstone_Cobble"
    },
    {
      "x": 2,
      "y": 1,
      "z": -7,
      "name": "Rock_Sandstone_Cobble"
    },
    {
      "x": 2,
      "y": 2,
      "z": -7,
      "name": "Rock_Sandstone_Cobble"
    },
    {
      "x": 2,
      "y": 3,
      "z": -7,
      "name": "Rock_Sandstone_Cobble"
    },
    {
      "x": 2,
      "y": 4,
      "z": -7,
      "name": "Rock_Sandstone_Cobble"
    },
    {
      "x": 2,
      "y": 5,
      "z": -7,
      "name": "Rock_Sandstone_Cobble"
    },
    {
      "x": 2,
      "y": 6,
      "z": -7,
      "name": "Rock_Sandstone_Brick"
    },
    {
      "x": 2,
      "y": 7,
      "z": -7,
      "name": "Rock_Sandstone_Brick_Ornate"
    },
    {
      "x": 2,
      "y": 8,
      "z": -7,
      "name": "Rock_Sandstone_Brick"
    },
    {
      "x": 2,
      "y": 9,
      "z": -7,
      "name": "Rock_Sandstone_Brick"
    },
    {
      "x": 2,
      "y": 10,
      "z": -7,
      "name": "Rock_Sandstone_Brick_Smooth"
    },
    {
      "x": 2,
      "y": 0,
      "z": -6,
      "name": "Rock_Sandstone_Cobble"
    },
    {
      "x": 2,
      "y": 1,
      "z": -6,
      "name": "Rock_Sandstone_Cobble"
    },
    {
      "x": 2,
      "y": 2,
      "z": -6,
      "name": "Rock_Sandstone_Cobble"
    },
    {
      "x": 2,
      "y": 3,
      "z": -6,
      "name": "Rock_Sandstone_Cobble"
    },
    {
      "x": 2,
      "y": 4,
      "z": -6,
      "name": "Rock_Sandstone_Cobble"
    },
    {
      "x": 2,
      "y": 5,
      "z": -6,
      "name": "Rock_Sandstone_Cobble"
    },
    {
      "x": 2,
      "y": 6,
      "z": -6,
      "name": "Rock_Sandstone_Cobble"
    },
    {
      "x": 2,
      "y": 7,
      "z": -6,
      "name": "Rock_Sandstone_Brick_Ornate"
    },
    {
      "x": 2,
      "y": 8,
      "z": -6,
      "name": "Rock_Sandstone_Brick"
    },
    {
      "x": 2,
      "y": 9,
      "z": -6,
      "name": "Rock_Sandstone_Brick"
    },
    {
      "x": 2,
      "y": 10,
      "z": -6,
      "name": "Rock_Sandstone_Brick_Smooth_Half"
    },
    {
      "x": 2,
      "y": 0,
      "z": -5,
      "name": "Rock_Sandstone_Cobble"
    },
    {
      "x": 2,
      "y": 1,
      "z": -5,
      "name": "Rock_Sandstone_Cobble"
    },
    {
      "x": 2,
      "y": 2,
      "z": -5,
      "name": "Rock_Sandstone_Cobble"
    },
    {
      "x": 2,
      "y": 3,
      "z": -5,
      "name": "Rock_Sandstone_Cobble"
    },
    {
      "x": 2,
      "y": 4,
      "z": -5,
      "name": "Rock_Sandstone_Cobble"
    },
    {
      "x": 2,
      "y": 5,
      "z": -5,
      "name": "Rock_Sandstone_Cobble"
    },
    {
      "x": 2,
      "y": 6,
      "z": -5,
      "name": "Rock_Sandstone_Cobble"
    },
    {
      "x": 2,
      "y": 7,
      "z": -5,
      "name": "Rock_Sandstone_Brick_Ornate"
    },
    {
      "x": 2,
      "y": 0,
      "z": -4,
      "name": "Rock_Sandstone_Cobble"
    },
    {
      "x": 2,
      "y": 1,
      "z": -4,
      "name": "Rock_Sandstone_Cobble"
    },
    {
      "x": 2,
      "y": 2,
      "z": -4,
      "name": "Rock_Sandstone_Cobble"
    },
    {
      "x": 2,
      "y": 3,
      "z": -4,
      "name": "Rock_Sandstone_Cobble"
    },
    {
      "x": 2,
      "y": 4,
      "z": -4,
      "name": "Rock_Sandstone_Cobble"
    },
    {
      "x": 2,
      "y": 5,
      "z": -4,
      "name": "Rock_Sandstone_Cobble"
    },
    {
      "x": 2,
      "y": 6,
      "z": -4,
      "name": "Rock_Sandstone_Cobble"
    },
    {
      "x": 2,
      "y": 0,
      "z": -3,
      "name": "Rock_Sandstone_Cobble"
    },
    {
      "x": 2,
      "y": 1,
      "z": -3,
      "name": "Rock_Sandstone_Cobble"
    },
    {
      "x": 2,
      "y": 2,
      "z": -3,
      "name": "Rock_Sandstone_Cobble"
    },
    {
      "x": 2,
      "y": 3,
      "z": -3,
      "name": "Rock_Sandstone_Cobble"
    },
    {
      "x": 2,
      "y": 4,
      "z": -3,
      "name": "Rock_Sandstone_Cobble"
    },
    {
      "x": 2,
      "y": 5,
      "z": -3,
      "name": "Rock_Sandstone_Cobble"
    },
    {
      "x": 2,
      "y": 6,
      "z": -3,
      "name": "Rock_Sandstone_Cobble"
    },
    {
      "x": 2,
      "y": 7,
      "z": -3,
      "name": "Rock_Sandstone_Brick_Ornate"
    },
    {
      "x": 2,
      "y": 8,
      "z": -3,
      "name": "Rock_Sandstone_Brick"
    },
    {
      "x": 2,
      "y": 9,
      "z": -3,
      "name": "Rock_Sandstone_Brick"
    },
    {
      "x": 2,
      "y": 10,
      "z": -3,
      "name": "Rock_Sandstone_Brick_Smooth"
    },
    {
      "x": 2,
      "y": 0,
      "z": -2,
      "name": "Rock_Sandstone_Cobble"
    },
    {
      "x": 2,
      "y": 1,
      "z": -2,
      "name": "Rock_Sandstone_Cobble"
    },
    {
      "x": 2,
      "y": 2,
      "z": -2,
      "name": "Rock_Sandstone_Cobble"
    },
    {
      "x": 2,
      "y": 3,
      "z": -2,
      "name": "Rock_Sandstone_Cobble"
    },
    {
      "x": 2,
      "y": 4,
      "z": -2,
      "name": "Rock_Sandstone_Cobble"
    },
    {
      "x": 2,
      "y": 5,
      "z": -2,
      "name": "Rock_Sandstone_Brick"
    },
    {
      "x": 2,
      "y": 6,
      "z": -2,
      "name": "Rock_Sandstone_Brick"
    },
    {
      "x": 2,
      "y": 7,
      "z": -2,
      "name": "Rock_Sandstone_Brick_Ornate"
    },
    {
      "x": 2,
      "y": 8,
      "z": -2,
      "name": "Rock_Sandstone_Brick"
    },
    {
      "x": 2,
      "y": 9,
      "z": -2,
      "name": "Rock_Sandstone_Brick"
    },
    {
      "x": 2,
      "y": 10,
      "z": -2,
      "name": "Rock_Sandstone_Brick_Smooth_Half"
    },
    {
      "x": 2,
      "y": 0,
      "z": -1,
      "name": "Rock_Sandstone_Cobble"
    },
    {
      "x": 2,
      "y": 1,
      "z": -1,
      "name": "Rock_Sandstone_Cobble"
    },
    {
      "x": 2,
      "y": 2,
      "z": -1,
      "name": "Rock_Sandstone_Cobble"
    },
    {
      "x": 2,
      "y": 3,
      "z": -1,
      "name": "Rock_Sandstone_Cobble"
    },
    {
      "x": 2,
      "y": 4,
      "z": -1,
      "name": "Rock_Sandstone_Cobble"
    },
    {
      "x": 2,
      "y": 5,
      "z": -1,
      "name": "Rock_Sandstone_Brick"
    },
    {
      "x": 2,
      "y": 6,
      "z": -1,
      "name": "Rock_Sandstone_Brick"
    },
    {
      "x": 2,
      "y": 7,
      "z": -1,
      "name": "Rock_Sandstone_Brick_Ornate"
    },
    {
      "x": 2,
      "y": 8,
      "z": -1,
      "name": "Rock_Sandstone_Brick"
    },
    {
      "x": 2,
      "y": 9,
      "z": -1,
      "name": "Rock_Sandstone_Brick"
    },
    {
      "x": 2,
      "y": 0,
      "z": 0,
      "name": "Rock_Sandstone_Cobble"
    },
    {
      "x": 2,
      "y": 1,
      "z": 0,
      "name": "Rock_Sandstone_Cobble"
    },
    {
      "x": 2,
      "y": 2,
      "z": 0,
      "name": "Rock_Sandstone_Cobble"
    },
    {
      "x": 2,
      "y": 3,
      "z": 0,
      "name": "Rock_Sandstone_Cobble"
    },
    {
      "x": 2,
      "y": 4,
      "z": 0,
      "name": "Rock_Sandstone_Brick"
    },
    {
      "x": 2,
      "y": 5,
      "z": 0,
      "name": "Rock_Sandstone_Brick"
    },
    {
      "x": 2,
      "y": 6,
      "z": 0,
      "name": "Rock_Sandstone_Brick"
    },
    {
      "x": 2,
      "y": 7,
      "z": 0,
      "name": "Rock_Sandstone_Brick_Ornate"
    },
    {
      "x": 2,
      "y": 8,
      "z": 0,
      "name": "Rock_Sandstone_Brick"
    },
    {
      "x": 2,
      "y": 0,
      "z": 1,
      "name": "Rock_Sandstone_Cobble"
    },
    {
      "x": 2,
      "y": 1,
      "z": 1,
      "name": "Rock_Sandstone_Cobble"
    },
    {
      "x": 2,
      "y": 2,
      "z": 1,
      "name": "Rock_Sandstone_Cobble"
    },
    {
      "x": 2,
      "y": 3,
      "z": 1,
      "name": "Rock_Sandstone_Cobble"
    },
    {
      "x": 2,
      "y": 4,
      "z": 1,
      "name": "Rock_Sandstone_Brick"
    },
    {
      "x": 2,
      "y": 5,
      "z": 1,
      "name": "Rock_Sandstone_Brick"
    },
    {
      "x": 2,
      "y": 6,
      "z": 1,
      "name": "Rock_Sandstone_Brick_Half",
      "rotation": 4
    },
    {
      "x": 2,
      "y": 0,
      "z": 3,
      "name": "Rock_Sandstone_Cobble"
    },
    {
      "x": 2,
      "y": 1,
      "z": 3,
      "name": "Rock_Sandstone_Cobble"
    },
    {
      "x": 2,
      "y": 2,
      "z": 3,
      "name": "Rock_Sandstone_Cobble"
    },
    {
      "x": 2,
      "y": 3,
      "z": 3,
      "name": "Rock_Sandstone_Cobble"
    },
    {
      "x": 2,
      "y": 4,
      "z": 3,
      "name": "Rock_Sandstone_Cobble"
    },
    {
      "x": 2,
      "y": 0,
      "z": 4,
      "name": "Rock_Sandstone_Cobble"
    },
    {
      "x": 2,
      "y": 1,
      "z": 4,
      "name": "Rock_Sandstone_Cobble"
    },
    {
      "x": 2,
      "y": 2,
      "z": 4,
      "name": "Rock_Sandstone_Cobble"
    },
    {
      "x": 2,
      "y": 3,
      "z": 4,
      "name": "Rock_Sandstone_Cobble"
    },
    {
      "x": 2,
      "y": 4,
      "z": 4,
      "name": "Rock_Sandstone_Cobble"
    },
    {
      "x": 2,
      "y": 5,
      "z": 4,
      "name": "Rock_Sandstone_Cobble"
    },
    {
      "x": 2,
      "y": 6,
      "z": 4,
      "name": "Rock_Sandstone_Brick"
    },
    {
      "x": 2,
      "y": 7,
      "z": 4,
      "name": "Rock_Sandstone_Brick_Ornate"
    },
    {
      "x": 2,
      "y": 0,
      "z": 5,
      "name": "Rock_Sandstone_Cobble"
    },
    {
      "x": 2,
      "y": 1,
      "z": 5,
      "name": "Rock_Sandstone_Cobble"
    },
    {
      "x": 2,
      "y": 2,
      "z": 5,
      "name": "Rock_Sandstone_Cobble"
    },
    {
      "x": 2,
      "y": 3,
      "z": 5,
      "name": "Rock_Sandstone_Cobble"
    },
    {
      "x": 2,
      "y": 4,
      "z": 5,
      "name": "Rock_Sandstone_Cobble"
    },
    {
      "x": 2,
      "y": 5,
      "z": 5,
      "name": "Rock_Sandstone_Cobble"
    },
    {
      "x": 2,
      "y": 6,
      "z": 5,
      "name": "Rock_Sandstone_Brick"
    },
    {
      "x": 2,
      "y": 7,
      "z": 5,
      "name": "Rock_Sandstone_Brick_Ornate"
    },
    {
      "x": 2,
      "y": 0,
      "z": 6,
      "name": "Rock_Sandstone_Cobble"
    },
    {
      "x": 2,
      "y": 1,
      "z": 6,
      "name": "Rock_Sandstone_Cobble"
    },
    {
      "x": 2,
      "y": 2,
      "z": 6,
      "name": "Rock_Sandstone_Cobble"
    },
    {
      "x": 2,
      "y": 3,
      "z": 6,
      "name": "Rock_Sandstone_Cobble"
    },
    {
      "x": 2,
      "y": 4,
      "z": 6,
      "name": "Rock_Sandstone_Cobble"
    },
    {
      "x": 2,
      "y": 5,
      "z": 6,
      "name": "Rock_Sandstone_Cobble"
    },
    {
      "x": 2,
      "y": 6,
      "z": 6,
      "name": "Rock_Sandstone_Brick"
    },
    {
      "x": 2,
      "y": 7,
      "z": 6,
      "name": "Rock_Sandstone_Brick_Half",
      "rotation": 4
    },
    {
      "x": 2,
      "y": 0,
      "z": 7,
      "name": "Rock_Sandstone_Cobble"
    },
    {
      "x": 2,
      "y": 1,
      "z": 7,
      "name": "Rock_Sandstone_Cobble"
    },
    {
      "x": 2,
      "y": 2,
      "z": 7,
      "name": "Rock_Sandstone_Cobble"
    },
    {
      "x": 2,
      "y": 3,
      "z": 7,
      "name": "Rock_Sandstone_Cobble"
    },
    {
      "x": 2,
      "y": 4,
      "z": 7,
      "name": "Soil_Gravel_Sand_White"
    },
    {
      "x": 2,
      "y": 5,
      "z": 7,
      "name": "Soil_Gravel_Sand_White"
    },
    {
      "x": 2,
      "y": 0,
      "z": 8,
      "name": "Rock_Sandstone_Cobble"
    },
    {
      "x": 2,
      "y": 1,
      "z": 8,
      "name": "Rock_Sandstone_Cobble"
    },
    {
      "x": 2,
      "y": 2,
      "z": 8,
      "name": "Rock_Sandstone_Cobble"
    },
    {
      "x": 2,
      "y": 3,
      "z": 8,
      "name": "Rock_Sandstone_Cobble"
    },
    {
      "x": 2,
      "y": 4,
      "z": 8,
      "name": "Soil_Gravel_Sand_White"
    },
    {
      "x": 2,
      "y": 0,
      "z": 9,
      "name": "Rock_Sandstone_Cobble"
    },
    {
      "x": 2,
      "y": 1,
      "z": 9,
      "name": "Rock_Sandstone_Cobble"
    },
    {
      "x": 2,
      "y": 2,
      "z": 9,
      "name": "Rock_Sandstone_Cobble"
    },
    {
      "x": 2,
      "y": 3,
      "z": 9,
      "name": "Soil_Gravel_Sand_White"
    },
    {
      "x": 3,
      "y": 9,
      "z": -8,
      "name": "Rock_Sandstone_Brick_Smooth_Half",
      "rotation": 5
    },
    {
      "x": 3,
      "y": 9,
      "z": -7,
      "name": "Rock_Sandstone_Brick_Smooth_Half",
      "rotation": 5
    },
    {
      "x": 3,
      "y": 10,
      "z": -7,
      "name": "Rock_Sandstone_Brick_Smooth_Half",
      "rotation": 5
    },
    {
      "x": 3,
      "y": 9,
      "z": -3,
      "name": "Rock_Sandstone_Brick_Smooth_Half",
      "rotation": 5
    },
    {
      "x": 3,
      "y": 10,
      "z": -3,
      "name": "Rock_Sandstone_Brick_Smooth_Half",
      "rotation": 5
    },
    {
      "x": 3,
      "y": 9,
      "z": -2,
      "name": "Rock_Sandstone_Brick_Smooth_Half",
      "rotation": 5
    },
    {
      "x": 3,
      "y": 9,
      "z": -1,
      "name": "Rock_Sandstone_Brick_Smooth_Half",
      "rotation": 5
    }
  ],
  "fluids": [
    {
      "x": -3,
      "y": 9,
      "z": -5,
      "name": "Empty",
      "level": 0
    },
    {
      "x": -3,
      "y": 10,
      "z": -5,
      "name": "Empty",
      "level": 0
    },
    {
      "x": -3,
      "y": 9,
      "z": -4,
      "name": "Empty",
      "level": 0
    },
    {
      "x": -3,
      "y": 9,
      "z": -3,
      "name": "Empty",
      "level": 0
    },
    {
      "x": -3,
      "y": 10,
      "z": -3,
      "name": "Empty",
      "level": 0
    },
    {
      "x": -3,
      "y": 9,
      "z": -2,
      "name": "Empty",
      "level": 0
    },
    {
      "x": -2,
      "y": 0,
      "z": -9,
      "name": "Empty",
      "level": 0
    },
    {
      "x": -2,
      "y": 1,
      "z": -9,
      "name": "Empty",
      "level": 0
    },
    {
      "x": -2,
      "y": 2,
      "z": -9,
      "name": "Empty",
      "level": 0
    },
    {
      "x": -2,
      "y": 3,
      "z": -9,
      "name": "Empty",
      "level": 0
    },
    {
      "x": -2,
      "y": 4,
      "z": -9,
      "name": "Empty",
      "level": 0
    },
    {
      "x": -2,
      "y": 5,
      "z": -9,
      "name": "Empty",
      "level": 0
    },
    {
      "x": -2,
      "y": 6,
      "z": -9,
      "name": "Empty",
      "level": 0
    },
    {
      "x": -2,
      "y": 7,
      "z": -9,
      "name": "Empty",
      "level": 0
    },
    {
      "x": -2,
      "y": 8,
      "z": -9,
      "name": "Empty",
      "level": 0
    },
    {
      "x": -2,
      "y": 9,
      "z": -9,
      "name": "Empty",
      "level": 0
    },
    {
      "x": -2,
      "y": 0,
      "z": -8,
      "name": "Empty",
      "level": 0
    },
    {
      "x": -2,
      "y": 1,
      "z": -8,
      "name": "Empty",
      "level": 0
    },
    {
      "x": -2,
      "y": 2,
      "z": -8,
      "name": "Empty",
      "level": 0
    },
    {
      "x": -2,
      "y": 3,
      "z": -8,
      "name": "Empty",
      "level": 0
    },
    {
      "x": -2,
      "y": 4,
      "z": -8,
      "name": "Empty",
      "level": 0
    },
    {
      "x": -2,
      "y": 5,
      "z": -8,
      "name": "Empty",
      "level": 0
    },
    {
      "x": -2,
      "y": 6,
      "z": -8,
      "name": "Empty",
      "level": 0
    },
    {
      "x": -2,
      "y": 7,
      "z": -8,
      "name": "Empty",
      "level": 0
    },
    {
      "x": -2,
      "y": 8,
      "z": -8,
      "name": "Empty",
      "level": 0
    },
    {
      "x": -2,
      "y": 9,
      "z": -8,
      "name": "Empty",
      "level": 0
    },
    {
      "x": -2,
      "y": 0,
      "z": -7,
      "name": "Empty",
      "level": 0
    },
    {
      "x": -2,
      "y": 1,
      "z": -7,
      "name": "Empty",
      "level": 0
    },
    {
      "x": -2,
      "y": 2,
      "z": -7,
      "name": "Empty",
      "level": 0
    },
    {
      "x": -2,
      "y": 3,
      "z": -7,
      "name": "Empty",
      "level": 0
    },
    {
      "x": -2,
      "y": 4,
      "z": -7,
      "name": "Empty",
      "level": 0
    },
    {
      "x": -2,
      "y": 5,
      "z": -7,
      "name": "Empty",
      "level": 0
    },
    {
      "x": -2,
      "y": 6,
      "z": -7,
      "name": "Empty",
      "level": 0
    },
    {
      "x": -2,
      "y": 0,
      "z": -6,
      "name": "Empty",
      "level": 0
    },
    {
      "x": -2,
      "y": 1,
      "z": -6,
      "name": "Empty",
      "level": 0
    },
    {
      "x": -2,
      "y": 2,
      "z": -6,
      "name": "Empty",
      "level": 0
    },
    {
      "x": -2,
      "y": 3,
      "z": -6,
      "name": "Empty",
      "level": 0
    },
    {
      "x": -2,
      "y": 4,
      "z": -6,
      "name": "Empty",
      "level": 0
    },
    {
      "x": -2,
      "y": 5,
      "z": -6,
      "name": "Empty",
      "level": 0
    },
    {
      "x": -2,
      "y": 6,
      "z": -6,
      "name": "Empty",
      "level": 0
    },
    {
      "x": -2,
      "y": 7,
      "z": -6,
      "name": "Empty",
      "level": 0
    },
    {
      "x": -2,
      "y": 0,
      "z": -5,
      "name": "Empty",
      "level": 0
    },
    {
      "x": -2,
      "y": 1,
      "z": -5,
      "name": "Empty",
      "level": 0
    },
    {
      "x": -2,
      "y": 2,
      "z": -5,
      "name": "Empty",
      "level": 0
    },
    {
      "x": -2,
      "y": 3,
      "z": -5,
      "name": "Empty",
      "level": 0
    },
    {
      "x": -2,
      "y": 4,
      "z": -5,
      "name": "Empty",
      "level": 0
    },
    {
      "x": -2,
      "y": 5,
      "z": -5,
      "name": "Empty",
      "level": 0
    },
    {
      "x": -2,
      "y": 6,
      "z": -5,
      "name": "Empty",
      "level": 0
    },
    {
      "x": -2,
      "y": 7,
      "z": -5,
      "name": "Empty",
      "level": 0
    },
    {
      "x": -2,
      "y": 8,
      "z": -5,
      "name": "Empty",
      "level": 0
    },
    {
      "x": -2,
      "y": 9,
      "z": -5,
      "name": "Empty",
      "level": 0
    },
    {
      "x": -2,
      "y": 10,
      "z": -5,
      "name": "Empty",
      "level": 0
    },
    {
      "x": -2,
      "y": 0,
      "z": -4,
      "name": "Empty",
      "level": 0
    },
    {
      "x": -2,
      "y": 1,
      "z": -4,
      "name": "Empty",
      "level": 0
    },
    {
      "x": -2,
      "y": 2,
      "z": -4,
      "name": "Empty",
      "level": 0
    },
    {
      "x": -2,
      "y": 3,
      "z": -4,
      "name": "Empty",
      "level": 0
    },
    {
      "x": -2,
      "y": 4,
      "z": -4,
      "name": "Empty",
      "level": 0
    },
    {
      "x": -2,
      "y": 5,
      "z": -4,
      "name": "Empty",
      "level": 0
    },
    {
      "x": -2,
      "y": 6,
      "z": -4,
      "name": "Empty",
      "level": 0
    },
    {
      "x": -2,
      "y": 7,
      "z": -4,
      "name": "Empty",
      "level": 0
    },
    {
      "x": -2,
      "y": 8,
      "z": -4,
      "name": "Empty",
      "level": 0
    },
    {
      "x": -2,
      "y": 9,
      "z": -4,
      "name": "Empty",
      "level": 0
    },
    {
      "x": -2,
      "y": 10,
      "z": -4,
      "name": "Empty",
      "level": 0
    },
    {
      "x": -2,
      "y": 0,
      "z": -3,
      "name": "Empty",
      "level": 0
    },
    {
      "x": -2,
      "y": 1,
      "z": -3,
      "name": "Empty",
      "level": 0
    },
    {
      "x": -2,
      "y": 2,
      "z": -3,
      "name": "Empty",
      "level": 0
    },
    {
      "x": -2,
      "y": 3,
      "z": -3,
      "name": "Empty",
      "level": 0
    },
    {
      "x": -2,
      "y": 4,
      "z": -3,
      "name": "Empty",
      "level": 0
    },
    {
      "x": -2,
      "y": 5,
      "z": -3,
      "name": "Empty",
      "level": 0
    },
    {
      "x": -2,
      "y": 6,
      "z": -3,
      "name": "Empty",
      "level": 0
    },
    {
      "x": -2,
      "y": 7,
      "z": -3,
      "name": "Empty",
      "level": 0
    },
    {
      "x": -2,
      "y": 8,
      "z": -3,
      "name": "Empty",
      "level": 0
    },
    {
      "x": -2,
      "y": 9,
      "z": -3,
      "name": "Empty",
      "level": 0
    },
    {
      "x": -2,
      "y": 10,
      "z": -3,
      "name": "Empty",
      "level": 0
    },
    {
      "x": -2,
      "y": 0,
      "z": -2,
      "name": "Empty",
      "level": 0
    },
    {
      "x": -2,
      "y": 1,
      "z": -2,
      "name": "Empty",
      "level": 0
    },
    {
      "x": -2,
      "y": 2,
      "z": -2,
      "name": "Empty",
      "level": 0
    },
    {
      "x": -2,
      "y": 3,
      "z": -2,
      "name": "Empty",
      "level": 0
    },
    {
      "x": -2,
      "y": 4,
      "z": -2,
      "name": "Empty",
      "level": 0
    },
    {
      "x": -2,
      "y": 5,
      "z": -2,
      "name": "Empty",
      "level": 0
    },
    {
      "x": -2,
      "y": 6,
      "z": -2,
      "name": "Empty",
      "level": 0
    },
    {
      "x": -2,
      "y": 7,
      "z": -2,
      "name": "Empty",
      "level": 0
    },
    {
      "x": -2,
      "y": 8,
      "z": -2,
      "name": "Empty",
      "level": 0
    },
    {
      "x": -2,
      "y": 9,
      "z": -2,
      "name": "Empty",
      "level": 0
    },
    {
      "x": -2,
      "y": 10,
      "z": -2,
      "name": "Empty",
      "level": 0
    },
    {
      "x": -2,
      "y": 0,
      "z": -1,
      "name": "Empty",
      "level": 0
    },
    {
      "x": -2,
      "y": 1,
      "z": -1,
      "name": "Empty",
      "level": 0
    },
    {
      "x": -2,
      "y": 2,
      "z": -1,
      "name": "Empty",
      "level": 0
    },
    {
      "x": -2,
      "y": 3,
      "z": -1,
      "name": "Empty",
      "level": 0
    },
    {
      "x": -2,
      "y": 4,
      "z": -1,
      "name": "Empty",
      "level": 0
    },
    {
      "x": -2,
      "y": 5,
      "z": -1,
      "name": "Empty",
      "level": 0
    },
    {
      "x": -2,
      "y": 6,
      "z": -1,
      "name": "Empty",
      "level": 0
    },
    {
      "x": -2,
      "y": 7,
      "z": -1,
      "name": "Empty",
      "level": 0
    },
    {
      "x": -2,
      "y": 8,
      "z": -1,
      "name": "Empty",
      "level": 0
    },
    {
      "x": -2,
      "y": 9,
      "z": -1,
      "name": "Empty",
      "level": 0
    },
    {
      "x": -2,
      "y": 10,
      "z": -1,
      "name": "Empty",
      "level": 0
    },
    {
      "x": -2,
      "y": 8,
      "z": 0,
      "name": "Empty",
      "level": 0
    },
    {
      "x": -2,
      "y": 9,
      "z": 0,
      "name": "Empty",
      "level": 0
    },
    {
      "x": -2,
      "y": 4,
      "z": 1,
      "name": "Empty",
      "level": 0
    },
    {
      "x": -2,
      "y": 5,
      "z": 1,
      "name": "Empty",
      "level": 0
    },
    {
      "x": -2,
      "y": 6,
      "z": 1,
      "name": "Empty",
      "level": 0
    },
    {
      "x": -2,
      "y": 0,
      "z": 2,
      "name": "Empty",
      "level": 0
    },
    {
      "x": -2,
      "y": 1,
      "z": 2,
      "name": "Empty",
      "level": 0
    },
    {
      "x": -2,
      "y": 2,
      "z": 2,
      "name": "Empty",
      "level": 0
    },
    {
      "x": -2,
      "y": 3,
      "z": 2,
      "name": "Empty",
      "level": 0
    },
    {
      "x": -2,
      "y": 4,
      "z": 2,
      "name": "Empty",
      "level": 0
    },
    {
      "x": -2,
      "y": 5,
      "z": 2,
      "name": "Empty",
      "level": 0
    },
    {
      "x": -2,
      "y": 6,
      "z": 2,
      "name": "Empty",
      "level": 0
    },
    {
      "x": -2,
      "y": 7,
      "z": 2,
      "name": "Empty",
      "level": 0
    },
    {
      "x": -2,
      "y": 0,
      "z": 3,
      "name": "Empty",
      "level": 0
    },
    {
      "x": -2,
      "y": 1,
      "z": 3,
      "name": "Empty",
      "level": 0
    },
    {
      "x": -2,
      "y": 2,
      "z": 3,
      "name": "Empty",
      "level": 0
    },
    {
      "x": -2,
      "y": 3,
      "z": 3,
      "name": "Empty",
      "level": 0
    },
    {
      "x": -2,
      "y": 4,
      "z": 3,
      "name": "Empty",
      "level": 0
    },
    {
      "x": -2,
      "y": 5,
      "z": 3,
      "name": "Empty",
      "level": 0
    },
    {
      "x": -2,
      "y": 6,
      "z": 3,
      "name": "Empty",
      "level": 0
    },
    {
      "x": -2,
      "y": 7,
      "z": 3,
      "name": "Empty",
      "level": 0
    },
    {
      "x": -2,
      "y": 0,
      "z": 4,
      "name": "Empty",
      "level": 0
    },
    {
      "x": -2,
      "y": 1,
      "z": 4,
      "name": "Empty",
      "level": 0
    },
    {
      "x": -2,
      "y": 2,
      "z": 4,
      "name": "Empty",
      "level": 0
    },
    {
      "x": -2,
      "y": 3,
      "z": 4,
      "name": "Empty",
      "level": 0
    },
    {
      "x": -2,
      "y": 4,
      "z": 4,
      "name": "Empty",
      "level": 0
    },
    {
      "x": -2,
      "y": 5,
      "z": 4,
      "name": "Empty",
      "level": 0
    },
    {
      "x": -2,
      "y": 6,
      "z": 4,
      "name": "Empty",
      "level": 0
    },
    {
      "x": -2,
      "y": 7,
      "z": 4,
      "name": "Empty",
      "level": 0
    },
    {
      "x": -2,
      "y": 8,
      "z": 4,
      "name": "Empty",
      "level": 0
    },
    {
      "x": -2,
      "y": 0,
      "z": 5,
      "name": "Empty",
      "level": 0
    },
    {
      "x": -2,
      "y": 1,
      "z": 5,
      "name": "Empty",
      "level": 0
    },
    {
      "x": -2,
      "y": 2,
      "z": 5,
      "name": "Empty",
      "level": 0
    },
    {
      "x": -2,
      "y": 3,
      "z": 5,
      "name": "Empty",
      "level": 0
    },
    {
      "x": -2,
      "y": 4,
      "z": 5,
      "name": "Empty",
      "level": 0
    },
    {
      "x": -2,
      "y": 5,
      "z": 5,
      "name": "Empty",
      "level": 0
    },
    {
      "x": -2,
      "y": 6,
      "z": 5,
      "name": "Empty",
      "level": 0
    },
    {
      "x": -2,
      "y": 7,
      "z": 5,
      "name": "Empty",
      "level": 0
    },
    {
      "x": -2,
      "y": 8,
      "z": 5,
      "name": "Empty",
      "level": 0
    },
    {
      "x": -2,
      "y": 0,
      "z": 6,
      "name": "Empty",
      "level": 0
    },
    {
      "x": -2,
      "y": 1,
      "z": 6,
      "name": "Empty",
      "level": 0
    },
    {
      "x": -2,
      "y": 2,
      "z": 6,
      "name": "Empty",
      "level": 0
    },
    {
      "x": -2,
      "y": 3,
      "z": 6,
      "name": "Empty",
      "level": 0
    },
    {
      "x": -2,
      "y": 4,
      "z": 6,
      "name": "Empty",
      "level": 0
    },
    {
      "x": -2,
      "y": 5,
      "z": 6,
      "name": "Empty",
      "level": 0
    },
    {
      "x": -2,
      "y": 6,
      "z": 6,
      "name": "Empty",
      "level": 0
    },
    {
      "x": -2,
      "y": 7,
      "z": 6,
      "name": "Empty",
      "level": 0
    },
    {
      "x": -2,
      "y": 8,
      "z": 6,
      "name": "Empty",
      "level": 0
    },
    {
      "x": -2,
      "y": 0,
      "z": 7,
      "name": "Empty",
      "level": 0
    },
    {
      "x": -2,
      "y": 1,
      "z": 7,
      "name": "Empty",
      "level": 0
    },
    {
      "x": -2,
      "y": 2,
      "z": 7,
      "name": "Empty",
      "level": 0
    },
    {
      "x": -2,
      "y": 3,
      "z": 7,
      "name": "Empty",
      "level": 0
    },
    {
      "x": -2,
      "y": 4,
      "z": 7,
      "name": "Empty",
      "level": 0
    },
    {
      "x": -2,
      "y": 5,
      "z": 7,
      "name": "Empty",
      "level": 0
    },
    {
      "x": -2,
      "y": 0,
      "z": 8,
      "name": "Empty",
      "level": 0
    },
    {
      "x": -2,
      "y": 1,
      "z": 8,
      "name": "Empty",
      "level": 0
    },
    {
      "x": -2,
      "y": 2,
      "z": 8,
      "name": "Empty",
      "level": 0
    },
    {
      "x": -2,
      "y": 3,
      "z": 8,
      "name": "Empty",
      "level": 0
    },
    {
      "x": -2,
      "y": 4,
      "z": 8,
      "name": "Empty",
      "level": 0
    },
    {
      "x": -2,
      "y": 5,
      "z": 8,
      "name": "Empty",
      "level": 0
    },
    {
      "x": -2,
      "y": 0,
      "z": 9,
      "name": "Empty",
      "level": 0
    },
    {
      "x": -2,
      "y": 1,
      "z": 9,
      "name": "Empty",
      "level": 0
    },
    {
      "x": -2,
      "y": 2,
      "z": 9,
      "name": "Empty",
      "level": 0
    },
    {
      "x": -2,
      "y": 3,
      "z": 9,
      "name": "Empty",
      "level": 0
    },
    {
      "x": -2,
      "y": 4,
      "z": 9,
      "name": "Empty",
      "level": 0
    },
    {
      "x": -2,
      "y": 5,
      "z": 9,
      "name": "Empty",
      "level": 0
    },
    {
      "x": -1,
      "y": 0,
      "z": -9,
      "name": "Empty",
      "level": 0
    },
    {
      "x": -1,
      "y": 1,
      "z": -9,
      "name": "Empty",
      "level": 0
    },
    {
      "x": -1,
      "y": 2,
      "z": -9,
      "name": "Empty",
      "level": 0
    },
    {
      "x": -1,
      "y": 3,
      "z": -9,
      "name": "Empty",
      "level": 0
    },
    {
      "x": -1,
      "y": 4,
      "z": -9,
      "name": "Empty",
      "level": 0
    },
    {
      "x": -1,
      "y": 5,
      "z": -9,
      "name": "Empty",
      "level": 0
    },
    {
      "x": -1,
      "y": 6,
      "z": -9,
      "name": "Empty",
      "level": 0
    },
    {
      "x": -1,
      "y": 7,
      "z": -9,
      "name": "Empty",
      "level": 0
    },
    {
      "x": -1,
      "y": 8,
      "z": -9,
      "name": "Empty",
      "level": 0
    },
    {
      "x": -1,
      "y": 9,
      "z": -9,
      "name": "Empty",
      "level": 0
    },
    {
      "x": -1,
      "y": 0,
      "z": -8,
      "name": "Empty",
      "level": 0
    },
    {
      "x": -1,
      "y": 1,
      "z": -8,
      "name": "Empty",
      "level": 0
    },
    {
      "x": -1,
      "y": 2,
      "z": -8,
      "name": "Empty",
      "level": 0
    },
    {
      "x": -1,
      "y": 3,
      "z": -8,
      "name": "Empty",
      "level": 0
    },
    {
      "x": -1,
      "y": 4,
      "z": -8,
      "name": "Empty",
      "level": 0
    },
    {
      "x": -1,
      "y": 5,
      "z": -8,
      "name": "Empty",
      "level": 0
    },
    {
      "x": -1,
      "y": 6,
      "z": -8,
      "name": "Empty",
      "level": 0
    },
    {
      "x": -1,
      "y": 7,
      "z": -8,
      "name": "Empty",
      "level": 0
    },
    {
      "x": -1,
      "y": 8,
      "z": -8,
      "name": "Empty",
      "level": 0
    },
    {
      "x": -1,
      "y": 9,
      "z": -8,
      "name": "Empty",
      "level": 0
    },
    {
      "x": -1,
      "y": 0,
      "z": -7,
      "name": "Empty",
      "level": 0
    },
    {
      "x": -1,
      "y": 1,
      "z": -7,
      "name": "Empty",
      "level": 0
    },
    {
      "x": -1,
      "y": 2,
      "z": -7,
      "name": "Empty",
      "level": 0
    },
    {
      "x": -1,
      "y": 3,
      "z": -7,
      "name": "Empty",
      "level": 0
    },
    {
      "x": -1,
      "y": 4,
      "z": -7,
      "name": "Empty",
      "level": 0
    },
    {
      "x": -1,
      "y": 5,
      "z": -7,
      "name": "Empty",
      "level": 0
    },
    {
      "x": -1,
      "y": 6,
      "z": -7,
      "name": "Empty",
      "level": 0
    },
    {
      "x": -1,
      "y": 7,
      "z": -7,
      "name": "Empty",
      "level": 0
    },
    {
      "x": -1,
      "y": 8,
      "z": -7,
      "name": "Empty",
      "level": 0
    },
    {
      "x": -1,
      "y": 9,
      "z": -7,
      "name": "Empty",
      "level": 0
    },
    {
      "x": -1,
      "y": 0,
      "z": -6,
      "name": "Empty",
      "level": 0
    },
    {
      "x": -1,
      "y": 1,
      "z": -6,
      "name": "Empty",
      "level": 0
    },
    {
      "x": -1,
      "y": 2,
      "z": -6,
      "name": "Empty",
      "level": 0
    },
    {
      "x": -1,
      "y": 3,
      "z": -6,
      "name": "Empty",
      "level": 0
    },
    {
      "x": -1,
      "y": 4,
      "z": -6,
      "name": "Empty",
      "level": 0
    },
    {
      "x": -1,
      "y": 5,
      "z": -6,
      "name": "Empty",
      "level": 0
    },
    {
      "x": -1,
      "y": 6,
      "z": -6,
      "name": "Empty",
      "level": 0
    },
    {
      "x": -1,
      "y": 7,
      "z": -6,
      "name": "Empty",
      "level": 0
    },
    {
      "x": -1,
      "y": 8,
      "z": -6,
      "name": "Empty",
      "level": 0
    },
    {
      "x": -1,
      "y": 9,
      "z": -6,
      "name": "Empty",
      "level": 0
    },
    {
      "x": -1,
      "y": 0,
      "z": -5,
      "name": "Empty",
      "level": 0
    },
    {
      "x": -1,
      "y": 1,
      "z": -5,
      "name": "Empty",
      "level": 0
    },
    {
      "x": -1,
      "y": 2,
      "z": -5,
      "name": "Empty",
      "level": 0
    },
    {
      "x": -1,
      "y": 3,
      "z": -5,
      "name": "Empty",
      "level": 0
    },
    {
      "x": -1,
      "y": 4,
      "z": -5,
      "name": "Empty",
      "level": 0
    },
    {
      "x": -1,
      "y": 5,
      "z": -5,
      "name": "Empty",
      "level": 0
    },
    {
      "x": -1,
      "y": 6,
      "z": -5,
      "name": "Empty",
      "level": 0
    },
    {
      "x": -1,
      "y": 7,
      "z": -5,
      "name": "Empty",
      "level": 0
    },
    {
      "x": -1,
      "y": 8,
      "z": -5,
      "name": "Empty",
      "level": 0
    },
    {
      "x": -1,
      "y": 9,
      "z": -5,
      "name": "Empty",
      "level": 0
    },
    {
      "x": -1,
      "y": 0,
      "z": -4,
      "name": "Empty",
      "level": 0
    },
    {
      "x": -1,
      "y": 1,
      "z": -4,
      "name": "Empty",
      "level": 0
    },
    {
      "x": -1,
      "y": 2,
      "z": -4,
      "name": "Empty",
      "level": 0
    },
    {
      "x": -1,
      "y": 3,
      "z": -4,
      "name": "Empty",
      "level": 0
    },
    {
      "x": -1,
      "y": 4,
      "z": -4,
      "name": "Empty",
      "level": 0
    },
    {
      "x": -1,
      "y": 5,
      "z": -4,
      "name": "Empty",
      "level": 0
    },
    {
      "x": -1,
      "y": 6,
      "z": -4,
      "name": "Empty",
      "level": 0
    },
    {
      "x": -1,
      "y": 7,
      "z": -4,
      "name": "Empty",
      "level": 0
    },
    {
      "x": -1,
      "y": 8,
      "z": -4,
      "name": "Empty",
      "level": 0
    },
    {
      "x": -1,
      "y": 9,
      "z": -4,
      "name": "Empty",
      "level": 0
    },
    {
      "x": -1,
      "y": 0,
      "z": -3,
      "name": "Empty",
      "level": 0
    },
    {
      "x": -1,
      "y": 1,
      "z": -3,
      "name": "Empty",
      "level": 0
    },
    {
      "x": -1,
      "y": 2,
      "z": -3,
      "name": "Empty",
      "level": 0
    },
    {
      "x": -1,
      "y": 3,
      "z": -3,
      "name": "Empty",
      "level": 0
    },
    {
      "x": -1,
      "y": 4,
      "z": -3,
      "name": "Empty",
      "level": 0
    },
    {
      "x": -1,
      "y": 5,
      "z": -3,
      "name": "Empty",
      "level": 0
    },
    {
      "x": -1,
      "y": 6,
      "z": -3,
      "name": "Empty",
      "level": 0
    },
    {
      "x": -1,
      "y": 7,
      "z": -3,
      "name": "Empty",
      "level": 0
    },
    {
      "x": -1,
      "y": 8,
      "z": -3,
      "name": "Empty",
      "level": 0
    },
    {
      "x": -1,
      "y": 9,
      "z": -3,
      "name": "Empty",
      "level": 0
    },
    {
      "x": -1,
      "y": 0,
      "z": -2,
      "name": "Empty",
      "level": 0
    },
    {
      "x": -1,
      "y": 1,
      "z": -2,
      "name": "Empty",
      "level": 0
    },
    {
      "x": -1,
      "y": 2,
      "z": -2,
      "name": "Empty",
      "level": 0
    },
    {
      "x": -1,
      "y": 3,
      "z": -2,
      "name": "Empty",
      "level": 0
    },
    {
      "x": -1,
      "y": 4,
      "z": -2,
      "name": "Empty",
      "level": 0
    },
    {
      "x": -1,
      "y": 5,
      "z": -2,
      "name": "Empty",
      "level": 0
    },
    {
      "x": -1,
      "y": 6,
      "z": -2,
      "name": "Empty",
      "level": 0
    },
    {
      "x": -1,
      "y": 7,
      "z": -2,
      "name": "Empty",
      "level": 0
    },
    {
      "x": -1,
      "y": 8,
      "z": -2,
      "name": "Empty",
      "level": 0
    },
    {
      "x": -1,
      "y": 9,
      "z": -2,
      "name": "Empty",
      "level": 0
    },
    {
      "x": -1,
      "y": 0,
      "z": -1,
      "name": "Empty",
      "level": 0
    },
    {
      "x": -1,
      "y": 1,
      "z": -1,
      "name": "Empty",
      "level": 0
    },
    {
      "x": -1,
      "y": 2,
      "z": -1,
      "name": "Empty",
      "level": 0
    },
    {
      "x": -1,
      "y": 3,
      "z": -1,
      "name": "Empty",
      "level": 0
    },
    {
      "x": -1,
      "y": 4,
      "z": -1,
      "name": "Empty",
      "level": 0
    },
    {
      "x": -1,
      "y": 5,
      "z": -1,
      "name": "Empty",
      "level": 0
    },
    {
      "x": -1,
      "y": 6,
      "z": -1,
      "name": "Empty",
      "level": 0
    },
    {
      "x": -1,
      "y": 7,
      "z": -1,
      "name": "Empty",
      "level": 0
    },
    {
      "x": -1,
      "y": 8,
      "z": -1,
      "name": "Empty",
      "level": 0
    },
    {
      "x": -1,
      "y": 0,
      "z": 0,
      "name": "Empty",
      "level": 0
    },
    {
      "x": -1,
      "y": 1,
      "z": 0,
      "name": "Empty",
      "level": 0
    },
    {
      "x": -1,
      "y": 2,
      "z": 0,
      "name": "Empty",
      "level": 0
    },
    {
      "x": -1,
      "y": 3,
      "z": 0,
      "name": "Empty",
      "level": 0
    },
    {
      "x": -1,
      "y": 4,
      "z": 0,
      "name": "Empty",
      "level": 0
    },
    {
      "x": -1,
      "y": 5,
      "z": 0,
      "name": "Empty",
      "level": 0
    },
    {
      "x": -1,
      "y": 6,
      "z": 0,
      "name": "Empty",
      "level": 0
    },
    {
      "x": -1,
      "y": 7,
      "z": 0,
      "name": "Empty",
      "level": 0
    },
    {
      "x": -1,
      "y": 8,
      "z": 0,
      "name": "Empty",
      "level": 0
    },
    {
      "x": -1,
      "y": 0,
      "z": 1,
      "name": "Empty",
      "level": 0
    },
    {
      "x": -1,
      "y": 1,
      "z": 1,
      "name": "Empty",
      "level": 0
    },
    {
      "x": -1,
      "y": 2,
      "z": 1,
      "name": "Empty",
      "level": 0
    },
    {
      "x": -1,
      "y": 3,
      "z": 1,
      "name": "Empty",
      "level": 0
    },
    {
      "x": -1,
      "y": 4,
      "z": 1,
