{
  "version": 8,
  "blockIdVersion": 11,
  "anchorX": 1,
  "anchorY": 0,
  "anchorZ": 3,
  "blocks": [
    {
      "x": -3,
      "y": 3,
      "z": 0,
      "name": "Plant_Crop_Mushroom_Block_Yellow_Mycelium",
      "rotation": 10
    },
    {
      "x": -3,
      "y": 4,
      "z": 0,
      "name": "Plant_Crop_Mushroom_Block_Yellow",
      "rotation": 2
    },
    {
      "x": -3,
      "y": 3,
      "z": 1,
      "name": "Plant_Crop_Mushroom_Block_Yellow_Mycelium",
      "rotation": 10
    },
    {
      "x": -3,
      "y": 4,
      "z": 1,
      "name": "Plant_Crop_Mushroom_Block_Yellow",
      "rotation": 2
    },
    {
      "x": -3,
      "y": 4,
      "z": 2,
      "name": "Plant_Crop_Mushroom_Block_Yellow_Mycelium",
      "rotation": 10
    },
    {
      "x": -3,
      "y": 5,
      "z": 2,
      "name": "Plant_Crop_Mushroom_Block_Yellow",
      "rotation": 2
    },
    {
      "x": -2,
      "y": 2,
      "z": -1,
      "name": "Plant_Crop_Mushroom_Block_Yellow_Mycelium",
      "rotation": 10
    },
    {
      "x": -2,
      "y": 3,
      "z": -1,
      "name": "Plant_Crop_Mushroom_Block_Yellow",
      "rotation": 2
    },
    {
      "x": -2,
      "y": 4,
      "z": 0,
      "name": "Plant_Crop_Mushroom_Block_Yellow",
      "rotation": 2
    },
    {
      "x": -2,
      "y": 4,
      "z": 1,
      "name": "Plant_Crop_Mushroom_Block_Yellow",
      "rotation": 2
    },
    {
      "x": -2,
      "y": 5,
      "z": 2,
      "name": "Plant_Crop_Mushroom_Block_Yellow",
      "rotation": 2
    },
    {
      "x": -2,
      "y": 5,
      "z": 3,
      "name": "Plant_Crop_Mushroom_Block_Yellow_Mycelium",
      "rotation": 10
    },
    {
      "x": -2,
      "y": 6,
      "z": 3,
      "name": "Plant_Crop_Mushroom_Block_Yellow",
      "rotation": 2
    },
    {
      "x": -1,
      "y": 2,
      "z": -1,
      "name": "Plant_Crop_Mushroom_Block_Yellow_Mycelium",
      "rotation": 10
    },
    {
      "x": -1,
      "y": 3,
      "z": -1,
      "name": "Plant_Crop_Mushroom_Block_Yellow",
      "rotation": 2
    },
    {
      "x": -1,
      "y": 3,
      "z": 0,
      "name": "Plant_Crop_Mushroom_Block_Yellow",
      "rotation": 2
    },
    {
      "x": -1,
      "y": 4,
      "z": 1,
      "name": "Plant_Crop_Mushroom_Block_Yellow",
      "rotation": 2
    },
    {
      "x": -1,
      "y": 5,
      "z": 2,
      "name": "Plant_Crop_Mushroom_Block_Yellow",
      "rotation": 2
    },
    {
      "x": -1,
      "y": 5,
      "z": 3,
      "name": "Plant_Crop_Mushroom_Block_Yellow_Mycelium",
      "rotation": 10
    },
    {
      "x": -1,
      "y": 6,
      "z": 3,
      "name": "Plant_Crop_Mushroom_Block_Yellow",
      "rotation": 2
    },
    {
      "x": 0,
      "y": 2,
      "z": -2,
      "name": "Plant_Crop_Mushroom_Block_Yellow_Mycelium",
      "rotation": 10
    },
    {
      "x": 0,
      "y": 3,
      "z": -2,
      "name": "Plant_Crop_Mushroom_Block_Yellow",
      "rotation": 2
    },
    {
      "x": 0,
      "y": 3,
      "z": -1,
      "name": "Plant_Crop_Mushroom_Block_Yellow",
      "rotation": 2
    },
    {
      "x": 0,
      "y": 3,
      "z": 0,
      "name": "Plant_Crop_Mushroom_Block_Yellow",
      "rotation": 2
    },
    {
      "x": 0,
      "y": 4,
      "z": 1,
      "name": "Plant_Crop_Mushroom_Block_Yellow",
      "rotation": 2
    },
    {
      "x": 0,
      "y": 4,
      "z": 2,
      "name": "Plant_Crop_Mushroom_Block_Yellow",
      "rotation": 2
    },
    {
      "x": 0,
      "y": 5,
      "z": 2,
      "name": "Plant_Crop_Mushroom_Block_Yellow",
      "rotation": 2
    },
    {
      "x": 0,
      "y": 5,
      "z": 3,
      "name": "Plant_Crop_Mushroom_Block_Yellow",
      "rotation": 2
    },
    {
      "x": 0,
      "y": 6,
      "z": 3,
      "name": "Plant_Crop_Mushroom_Block_Yellow",
      "rotation": 2
    },
    {
      "x": 0,
      "y": 6,
      "z": 4,
      "name": "Plant_Crop_Mushroom_Block_Yellow_Mycelium",
      "rotation": 10
    },
    {
      "x": 0,
      "y": 7,
      "z": 4,
      "name": "Plant_Crop_Mushroom_Block_Yellow",
      "rotation": 2
    },
    {
      "x": 1,
      "y": 2,
      "z": -2,
      "name": "Plant_Crop_Mushroom_Block_Yellow_Mycelium",
      "rotation": 10
    },
    {
      "x": 1,
      "y": 3,
      "z": -2,
      "name": "Plant_Crop_Mushroom_Block_Yellow",
      "rotation": 2
    },
    {
      "x": 1,
      "y": 3,
      "z": -1,
      "name": "Plant_Crop_Mushroom_Block_Yellow",
      "rotation": 2
    },
    {
      "x": 1,
      "y": 3,
      "z": 0,
      "name": "Plant_Crop_Mushroom_Block_Yellow",
      "rotation": 2
    },
    {
      "x": 1,
      "y": 3,
      "z": 1,
      "name": "Plant_Crop_Mushroom_Block_Yellow_Trunk",
      "rotation": 2
    },
    {
      "x": 1,
      "y": 4,
      "z": 1,
      "name": "Plant_Crop_Mushroom_Block_Yellow",
      "rotation": 2
    },
    {
      "x": 1,
      "y": 2,
      "z": 2,
      "name": "Plant_Crop_Mushroom_Block_Yellow_Trunk",
      "rotation": 2
    },
    {
      "x": 1,
      "y": 3,
      "z": 2,
      "name": "Plant_Crop_Mushroom_Block_Yellow_Trunk",
      "rotation": 2
    },
    {
      "x": 1,
      "y": 4,
      "z": 2,
      "name": "Plant_Crop_Mushroom_Block_Yellow_Trunk",
      "rotation": 2
    },
    {
      "x": 1,
      "y": 5,
      "z": 2,
      "name": "Plant_Crop_Mushroom_Block_Yellow",
      "rotation": 2
    },
    {
      "x": 1,
      "y": 0,
      "z": 3,
      "name": "Plant_Crop_Mushroom_Block_Yellow_Trunk",
      "rotation": 2
    },
    {
      "x": 1,
      "y": 1,
      "z": 3,
      "name": "Plant_Crop_Mushroom_Block_Yellow_Trunk",
      "rotation": 2
    },
    {
      "x": 1,
      "y": 2,
      "z": 3,
      "name": "Plant_Crop_Mushroom_Block_Yellow_Trunk",
      "rotation": 2
    },
    {
      "x": 1,
      "y": 5,
      "z": 3,
      "name": "Plant_Crop_Mushroom_Block_Yellow",
      "rotation": 2
    },
    {
      "x": 1,
      "y": 6,
      "z": 3,
      "name": "Plant_Crop_Mushroom_Block_Yellow",
      "rotation": 2
    },
    {
      "x": 1,
      "y": 6,
      "z": 4,
      "name": "Plant_Crop_Mushroom_Block_Yellow",
      "rotation": 2
    },
    {
      "x": 1,
      "y": 7,
      "z": 4,
      "name": "Plant_Crop_Mushroom_Block_Yellow",
      "rotation": 2
    },
    {
      "x": 2,
      "y": 2,
      "z": -2,
      "name": "Plant_Crop_Mushroom_Block_Yellow_Mycelium",
      "rotation": 10
    },
    {
      "x": 2,
      "y": 3,
      "z": -2,
      "name": "Plant_Crop_Mushroom_Block_Yellow",
      "rotation": 2
    },
    {
      "x": 2,
      "y": 3,
      "z": -1,
      "name": "Plant_Crop_Mushroom_Block_Yellow",
      "rotation": 2
    },
    {
      "x": 2,
      "y": 3,
      "z": 0,
      "name": "Plant_Crop_Mushroom_Block_Yellow",
      "rotation": 2
    },
    {
      "x": 2,
      "y": 4,
      "z": 1,
      "name": "Plant_Crop_Mushroom_Block_Yellow",
      "rotation": 2
    },
    {
      "x": 2,
      "y": 4,
      "z": 2,
      "name": "Plant_Crop_Mushroom_Block_Yellow",
      "rotation": 2
    },
    {
      "x": 2,
      "y": 5,
      "z": 2,
      "name": "Plant_Crop_Mushroom_Block_Yellow",
      "rotation": 2
    },
    {
      "x": 2,
      "y": 5,
      "z": 3,
      "name": "Plant_Crop_Mushroom_Block_Yellow",
      "rotation": 2
    },
    {
      "x": 2,
      "y": 6,
      "z": 3,
      "name": "Plant_Crop_Mushroom_Block_Yellow",
      "rotation": 2
    },
    {
      "x": 2,
      "y": 6,
      "z": 4,
      "name": "Plant_Crop_Mushroom_Block_Yellow_Mycelium",
      "rotation": 10
    },
    {
      "x": 2,
      "y": 7,
      "z": 4,
      "name": "Plant_Crop_Mushroom_Block_Yellow",
      "rotation": 2
    },
    {
      "x": 3,
      "y": 2,
      "z": -1,
      "name": "Plant_Crop_Mushroom_Block_Yellow_Mycelium",
      "rotation": 10
    },
    {
      "x": 3,
      "y": 3,
      "z": -1,
      "name": "Plant_Crop_Mushroom_Block_Yellow",
      "rotation": 2
    },
    {
      "x": 3,
      "y": 3,
      "z": 0,
      "name": "Plant_Crop_Mushroom_Block_Yellow",
      "rotation": 2
    },
    {
      "x": 3,
      "y": 4,
      "z": 1,
      "name": "Plant_Crop_Mushroom_Block_Yellow",
      "rotation": 2
    },
    {
      "x": 3,
      "y": 5,
      "z": 2,
      "name": "Plant_Crop_Mushroom_Block_Yellow",
      "rotation": 2
    },
    {
      "x": 3,
      "y": 5,
      "z": 3,
      "name": "Plant_Crop_Mushroom_Block_Yellow_Mycelium",
      "rotation": 10
    },
    {
      "x": 3,
      "y": 6,
      "z": 3,
      "name": "Plant_Crop_Mushroom_Block_Yellow",
      "rotation": 2
    },
    {
      "x": 4,
      "y": 2,
      "z": -1,
      "name": "Plant_Crop_Mushroom_Block_Yellow_Mycelium",
      "rotation": 10
    },
    {
      "x": 4,
      "y": 3,
      "z": -1,
      "name": "Plant_Crop_Mushroom_Block_Yellow",
      "rotation": 2
    },
    {
      "x": 4,
      "y": 4,
      "z": 0,
      "name": "Plant_Crop_Mushroom_Block_Yellow",
      "rotation": 2
    },
    {
      "x": 4,
      "y": 4,
      "z": 1,
      "name": "Plant_Crop_Mushroom_Block_Yellow",
      "rotation": 2
    },
    {
      "x": 4,
      "y": 5,
      "z": 2,
      "name": "Plant_Crop_Mushroom_Block_Yellow",
      "rotation": 2
    },
    {
      "x": 4,
      "y": 5,
      "z": 3,
      "name": "Plant_Crop_Mushroom_Block_Yellow_Mycelium",
      "rotation": 10
    },
    {
      "x": 4,
      "y": 6,
      "z": 3,
      "name": "Plant_Crop_Mushroom_Block_Yellow",
      "rotation": 2
    },
    {
      "x": 5,
      "y": 3,
      "z": 0,
      "name": "Plant_Crop_Mushroom_Block_Yellow_Mycelium",
      "rotation": 8
    },
    {
      "x": 5,
      "y": 4,
      "z": 0,
      "name": "Plant_Crop_Mushroom_Block_Yellow"
    },
    {
      "x": 5,
      "y": 3,
      "z": 1,
      "name": "Plant_Crop_Mushroom_Block_Yellow_Mycelium",
      "rotation": 8
    },
    {
      "x": 5,
      "y": 4,
      "z": 1,
      "name": "Plant_Crop_Mushroom_Block_Yellow"
    },
    {
      "x": 5,
      "y": 4,
      "z": 2,
      "name": "Plant_Crop_Mushroom_Block_Yellow_Mycelium",
      "rotation": 8
    },
    {
      "x": 5,
      "y": 5,
      "z": 2,
      "name": "Plant_Crop_Mushroom_Block_Yellow"
    }
  ]
}