{
  "version": 8,
  "blockIdVersion": 11,
  "anchorX": 0,
  "anchorY": 0,
  "anchorZ": 0,
  "blocks": [
    {
      "x": -3,
      "y": 3,
      "z": -2,
      "name": "Plant_Crop_Mushroom_Block_Yellow_Mycelium",
      "rotation": 8
    },
    {
      "x": -3,
      "y": 4,
      "z": -2,
      "name": "Plant_Crop_Mushroom_Block_Yellow"
    },
    {
      "x": -3,
      "y": 4,
      "z": -1,
      "name": "Plant_Crop_Mushroom_Block_Yellow_Mycelium",
      "rotation": 8
    },
    {
      "x": -3,
      "y": 5,
      "z": -1,
      "name": "Plant_Crop_Mushroom_Block_Yellow"
    },
    {
      "x": -3,
      "y": 4,
      "z": 0,
      "name": "Plant_Crop_Mushroom_Block_Yellow_Mycelium",
      "rotation": 8
    },
    {
      "x": -3,
      "y": 5,
      "z": 0,
      "name": "Plant_Crop_Mushroom_Block_Yellow"
    },
    {
      "x": -3,
      "y": 4,
      "z": 1,
      "name": "Plant_Crop_Mushroom_Block_Yellow_Mycelium",
      "rotation": 8
    },
    {
      "x": -3,
      "y": 5,
      "z": 1,
      "name": "Plant_Crop_Mushroom_Block_Yellow"
    },
    {
      "x": -3,
      "y": 3,
      "z": 2,
      "name": "Plant_Crop_Mushroom_Block_Yellow_Mycelium",
      "rotation": 8
    },
    {
      "x": -3,
      "y": 4,
      "z": 2,
      "name": "Plant_Crop_Mushroom_Block_Yellow"
    },
    {
      "x": -2,
      "y": 3,
      "z": -3,
      "name": "Plant_Crop_Mushroom_Block_Yellow_Mycelium",
      "rotation": 8
    },
    {
      "x": -2,
      "y": 4,
      "z": -3,
      "name": "Plant_Crop_Mushroom_Block_Yellow"
    },
    {
      "x": -2,
      "y": 4,
      "z": -2,
      "name": "Plant_Crop_Mushroom_Block_Yellow"
    },
    {
      "x": -2,
      "y": 4,
      "z": -1,
      "name": "Plant_Crop_Mushroom_Block_Yellow"
    },
    {
      "x": -2,
      "y": 5,
      "z": 0,
      "name": "Plant_Crop_Mushroom_Block_Yellow"
    },
    {
      "x": -2,
      "y": 4,
      "z": 1,
      "name": "Plant_Crop_Mushroom_Block_Yellow"
    },
    {
      "x": -2,
      "y": 4,
      "z": 2,
      "name": "Plant_Crop_Mushroom_Block_Yellow"
    },
    {
      "x": -2,
      "y": 3,
      "z": 3,
      "name": "Plant_Crop_Mushroom_Block_Yellow_Mycelium",
      "rotation": 8
    },
    {
      "x": -2,
      "y": 4,
      "z": 3,
      "name": "Plant_Crop_Mushroom_Block_Yellow"
    },
    {
      "x": -1,
      "y": 4,
      "z": -3,
      "name": "Plant_Crop_Mushroom_Block_Yellow_Mycelium",
      "rotation": 8
    },
    {
      "x": -1,
      "y": 5,
      "z": -3,
      "name": "Plant_Crop_Mushroom_Block_Yellow"
    },
    {
      "x": -1,
      "y": 4,
      "z": -2,
      "name": "Plant_Crop_Mushroom_Block_Yellow"
    },
    {
      "x": -1,
      "y": 5,
      "z": -1,
      "name": "Plant_Crop_Mushroom_Block_Yellow"
    },
    {
      "x": -1,
      "y": 5,
      "z": 0,
      "name": "Plant_Crop_Mushroom_Block_Yellow"
    },
    {
      "x": -1,
      "y": 5,
      "z": 1,
      "name": "Plant_Crop_Mushroom_Block_Yellow"
    },
    {
      "x": -1,
      "y": 4,
      "z": 2,
      "name": "Plant_Crop_Mushroom_Block_Yellow"
    },
    {
      "x": -1,
      "y": 4,
      "z": 3,
      "name": "Plant_Crop_Mushroom_Block_Yellow_Mycelium",
      "rotation": 8
    },
    {
      "x": -1,
      "y": 5,
      "z": 3,
      "name": "Plant_Crop_Mushroom_Block_Yellow"
    },
    {
      "x": 0,
      "y": 4,
      "z": -3,
      "name": "Plant_Crop_Mushroom_Block_Yellow_Mycelium",
      "rotation": 8
    },
    {
      "x": 0,
      "y": 5,
      "z": -3,
      "name": "Plant_Crop_Mushroom_Block_Yellow"
    },
    {
      "x": 0,
      "y": 5,
      "z": -2,
      "name": "Plant_Crop_Mushroom_Block_Yellow"
    },
    {
      "x": 0,
      "y": 5,
      "z": -1,
      "name": "Plant_Crop_Mushroom_Block_Yellow"
    },
    {
      "x": 0,
      "y": 0,
      "z": 0,
      "name": "Plant_Crop_Mushroom_Block_Yellow_Trunk"
    },
    {
      "x": 0,
      "y": 1,
      "z": 0,
      "name": "Plant_Crop_Mushroom_Block_Yellow_Trunk"
    },
    {
      "x": 0,
      "y": 2,
      "z": 0,
      "name": "Plant_Crop_Mushroom_Block_Yellow_Trunk"
    },
    {
      "x": 0,
      "y": 3,
      "z": 0,
      "name": "Plant_Crop_Mushroom_Block_Yellow_Trunk"
    },
    {
      "x": 0,
      "y": 4,
      "z": 0,
      "name": "Plant_Crop_Mushroom_Block_Yellow_Trunk"
    },
    {
      "x": 0,
      "y": 5,
      "z": 0,
      "name": "Plant_Crop_Mushroom_Block_Yellow"
    },
    {
      "x": 0,
      "y": 5,
      "z": 1,
      "name": "Plant_Crop_Mushroom_Block_Yellow"
    },
    {
      "x": 0,
      "y": 5,
      "z": 2,
      "name": "Plant_Crop_Mushroom_Block_Yellow"
    },
    {
      "x": 0,
      "y": 4,
      "z": 3,
      "name": "Plant_Crop_Mushroom_Block_Yellow_Mycelium",
      "rotation": 8
    },
    {
      "x": 0,
      "y": 5,
      "z": 3,
      "name": "Plant_Crop_Mushroom_Block_Yellow"
    },
    {
      "x": 1,
      "y": 4,
      "z": -3,
      "name": "Plant_Crop_Mushroom_Block_Yellow_Mycelium",
      "rotation": 8
    },
    {
      "x": 1,
      "y": 5,
      "z": -3,
      "name": "Plant_Crop_Mushroom_Block_Yellow"
    },
    {
      "x": 1,
      "y": 4,
      "z": -2,
      "name": "Plant_Crop_Mushroom_Block_Yellow"
    },
    {
      "x": 1,
      "y": 5,
      "z": -1,
      "name": "Plant_Crop_Mushroom_Block_Yellow"
    },
    {
      "x": 1,
      "y": 5,
      "z": 0,
      "name": "Plant_Crop_Mushroom_Block_Yellow"
    },
    {
      "x": 1,
      "y": 5,
      "z": 1,
      "name": "Plant_Crop_Mushroom_Block_Yellow"
    },
    {
      "x": 1,
      "y": 4,
      "z": 2,
      "name": "Plant_Crop_Mushroom_Block_Yellow"
    },
    {
      "x": 1,
      "y": 4,
      "z": 3,
      "name": "Plant_Crop_Mushroom_Block_Yellow_Mycelium",
      "rotation": 8
    },
    {
      "x": 1,
      "y": 5,
      "z": 3,
      "name": "Plant_Crop_Mushroom_Block_Yellow"
    },
    {
      "x": 2,
      "y": 3,
      "z": -3,
      "name": "Plant_Crop_Mushroom_Block_Yellow_Mycelium",
      "rotation": 8
    },
    {
      "x": 2,
      "y": 4,
      "z": -3,
      "name": "Plant_Crop_Mushroom_Block_Yellow"
    },
    {
      "x": 2,
      "y": 4,
      "z": -2,
      "name": "Plant_Crop_Mushroom_Block_Yellow"
    },
    {
      "x": 2,
      "y": 4,
      "z": -1,
      "name": "Plant_Crop_Mushroom_Block_Yellow"
    },
    {
      "x": 2,
      "y": 5,
      "z": 0,
      "name": "Plant_Crop_Mushroom_Block_Yellow"
    },
    {
      "x": 2,
      "y": 4,
      "z": 1,
      "name": "Plant_Crop_Mushroom_Block_Yellow"
    },
    {
      "x": 2,
      "y": 4,
      "z": 2,
      "name": "Plant_Crop_Mushroom_Block_Yellow"
    },
    {
      "x": 2,
      "y": 3,
      "z": 3,
      "name": "Plant_Crop_Mushroom_Block_Yellow_Mycelium",
      "rotation": 8
    },
    {
      "x": 2,
      "y": 4,
      "z": 3,
      "name": "Plant_Crop_Mushroom_Block_Yellow"
    },
    {
      "x": 3,
      "y": 3,
      "z": -2,
      "name": "Plant_Crop_Mushroom_Block_Yellow_Mycelium",
      "rotation": 8
    },
    {
      "x": 3,
      "y": 4,
      "z": -2,
      "name": "Plant_Crop_Mushroom_Block_Yellow"
    },
    {
      "x": 3,
      "y": 4,
      "z": -1,
      "name": "Plant_Crop_Mushroom_Block_Yellow_Mycelium",
      "rotation": 8
    },
    {
      "x": 3,
      "y": 5,
      "z": -1,
      "name": "Plant_Crop_Mushroom_Block_Yellow"
    },
    {
      "x": 3,
      "y": 4,
      "z": 0,
      "name": "Plant_Crop_Mushroom_Block_Yellow_Mycelium",
      "rotation": 8
    },
    {
      "x": 3,
      "y": 5,
      "z": 0,
      "name": "Plant_Crop_Mushroom_Block_Yellow"
    },
    {
      "x": 3,
      "y": 4,
      "z": 1,
      "name": "Plant_Crop_Mushroom_Block_Yellow_Mycelium",
      "rotation": 8
    },
    {
      "x": 3,
      "y": 5,
      "z": 1,
      "name": "Plant_Crop_Mushroom_Block_Yellow"
    },
    {
      "x": 3,
      "y": 3,
      "z": 2,
      "name": "Plant_Crop_Mushroom_Block_Yellow_Mycelium",
      "rotation": 8
    },
    {
      "x": 3,
      "y": 4,
      "z": 2,
      "name": "Plant_Crop_Mushroom_Block_Yellow"
    }
  ]
}