{
  "version": 8,
  "blockIdVersion": 11,
  "anchorX": -2,
  "anchorY": 0,
  "anchorZ": 2,
  "blocks": [
    {
      "x": -4,
      "y": 0,
      "z": 1,
      "name": "Rock_Crystal_Ultramarine_Small",
      "rotation": 7
    },
    {
      "x": -4,
      "y": 0,
      "z": 2,
      "name": "Rock_Crystal_Ultramarine_Medium",
      "rotation": 7
    },
    {
      "x": -3,
      "y": 0,
      "z": -2,
      "name": "Rock_Crystal_Ultramarine_Small",
      "rotation": 7
    },
    {
      "x": -3,
      "y": 0,
      "z": -1,
      "name": "Rock_Crystal_Ultramarine_Medium",
      "rotation": 7
    },
    {
      "x": -3,
      "y": -1,
      "z": 0,
      "name": "Rock_Crystal_Ultramarine_Small",
      "rotation": 7
    },
    {
      "x": -3,
      "y": 0,
      "z": 0,
      "name": "Rock_Crystal_Ultramarine_Block",
      "rotation": 4
    },
    {
      "x": -3,
      "y": 1,
      "z": 0,
      "name": "Rock_Crystal_Ultramarine_Small",
      "rotation": 7
    },
    {
      "x": -3,
      "y": -1,
      "z": 1,
      "name": "Rock_Crystal_Ultramarine_Medium",
      "rotation": 7
    },
    {
      "x": -3,
      "y": 0,
      "z": 1,
      "name": "Rock_Crystal_Ultramarine_Block",
      "rotation": 4
    },
    {
      "x": -3,
      "y": 1,
      "z": 1,
      "name": "Rock_Crystal_Ultramarine_Medium",
      "rotation": 7
    },
    {
      "x": -3,
      "y": -1,
      "z": 2,
      "name": "Rock_Crystal_Ultramarine_Block",
      "rotation": 4
    },
    {
      "x": -3,
      "y": 0,
      "z": 2,
      "name": "Rock_Crystal_Ultramarine_Block",
      "rotation": 4
    },
    {
      "x": -3,
      "y": 1,
      "z": 2,
      "name": "Rock_Crystal_Ultramarine_Block",
      "rotation": 4
    },
    {
      "x": -3,
      "y": 0,
      "z": 3,
      "name": "Rock_Crystal_Ultramarine_Block",
      "rotation": 4
    },
    {
      "x": -2,
      "y": 0,
      "z": -4,
      "name": "Rock_Crystal_Ultramarine_Medium",
      "rotation": 6
    },
    {
      "x": -2,
      "y": 0,
      "z": -3,
      "name": "Rock_Crystal_Ultramarine_Block",
      "rotation": 4
    },
    {
      "x": -2,
      "y": -1,
      "z": -2,
      "name": "Rock_Crystal_Ultramarine_Small",
      "rotation": 11
    },
    {
      "x": -2,
      "y": 0,
      "z": -2,
      "name": "Rock_Crystal_Ultramarine_Block",
      "rotation": 4
    },
    {
      "x": -2,
      "y": 1,
      "z": -2,
      "name": "Rock_Crystal_Ultramarine_Small",
      "rotation": 3
    },
    {
      "x": -2,
      "y": -1,
      "z": -1,
      "name": "Rock_Crystal_Ultramarine_Medium",
      "rotation": 11
    },
    {
      "x": -2,
      "y": 0,
      "z": -1,
      "name": "Rock_Crystal_Ultramarine_Block",
      "rotation": 4
    },
    {
      "x": -2,
      "y": 1,
      "z": -1,
      "name": "Rock_Crystal_Ultramarine_Medium",
      "rotation": 3
    },
    {
      "x": -2,
      "y": -1,
      "z": 0,
      "name": "Rock_Crystal_Ultramarine_Block",
      "rotation": 4
    },
    {
      "x": -2,
      "y": 0,
      "z": 0,
      "name": "Rock_Crystal_Ultramarine_Block",
      "rotation": 4
    },
    {
      "x": -2,
      "y": 1,
      "z": 0,
      "name": "Rock_Crystal_Ultramarine_Block",
      "rotation": 4
    },
    {
      "x": -2,
      "y": -2,
      "z": 1,
      "name": "Rock_Crystal_Ultramarine_Small",
      "rotation": 11
    },
    {
      "x": -2,
      "y": -1,
      "z": 1,
      "name": "Rock_Crystal_Ultramarine_Block",
      "rotation": 4
    },
    {
      "x": -2,
      "y": 0,
      "z": 1,
      "name": "Rock_Crystal_Ultramarine_Block",
      "rotation": 4
    },
    {
      "x": -2,
      "y": 1,
      "z": 1,
      "name": "Rock_Crystal_Ultramarine_Block",
      "rotation": 4
    },
    {
      "x": -2,
      "y": 2,
      "z": 1,
      "name": "Rock_Crystal_Ultramarine_Small",
      "rotation": 3
    },
    {
      "x": -2,
      "y": -2,
      "z": 2,
      "name": "Rock_Crystal_Ultramarine_Medium",
      "rotation": 11
    },
    {
      "x": -2,
      "y": -1,
      "z": 2,
      "name": "Rock_Crystal_Ultramarine_Block",
      "rotation": 4
    },
    {
      "x": -2,
      "y": 0,
      "z": 2,
      "name": "Rock_Crystal_Ultramarine_Block",
      "rotation": 3
    },
    {
      "x": -2,
      "y": 1,
      "z": 2,
      "name": "Rock_Crystal_Ultramarine_Block",
      "rotation": 4
    },
    {
      "x": -2,
      "y": 2,
      "z": 2,
      "name": "Rock_Crystal_Ultramarine_Medium",
      "rotation": 3
    },
    {
      "x": -2,
      "y": -1,
      "z": 3,
      "name": "Rock_Crystal_Ultramarine_Block",
      "rotation": 4
    },
    {
      "x": -2,
      "y": 0,
      "z": 3,
      "name": "Rock_Crystal_Ultramarine_Block",
      "rotation": 4
    },
    {
      "x": -2,
      "y": 1,
      "z": 3,
      "name": "Rock_Crystal_Ultramarine_Block",
      "rotation": 4
    },
    {
      "x": -2,
      "y": 0,
      "z": 4,
      "name": "Rock_Crystal_Ultramarine_Block",
      "rotation": 4
    },
    {
      "x": -1,
      "y": 0,
      "z": -2,
      "name": "Rock_Crystal_Ultramarine_Small",
      "rotation": 5
    },
    {
      "x": -1,
      "y": 0,
      "z": -1,
      "name": "Rock_Crystal_Ultramarine_Medium",
      "rotation": 5
    },
    {
      "x": -1,
      "y": -1,
      "z": 0,
      "name": "Rock_Crystal_Ultramarine_Small",
      "rotation": 5
    },
    {
      "x": -1,
      "y": 0,
      "z": 0,
      "name": "Rock_Crystal_Ultramarine_Block",
      "rotation": 4
    },
    {
      "x": -1,
      "y": 1,
      "z": 0,
      "name": "Rock_Crystal_Ultramarine_Small",
      "rotation": 5
    },
    {
      "x": -1,
      "y": -1,
      "z": 1,
      "name": "Rock_Crystal_Ultramarine_Medium",
      "rotation": 5
    },
    {
      "x": -1,
      "y": 0,
      "z": 1,
      "name": "Rock_Crystal_Ultramarine_Block",
      "rotation": 4
    },
    {
      "x": -1,
      "y": 1,
      "z": 1,
      "name": "Rock_Crystal_Ultramarine_Medium",
      "rotation": 5
    },
    {
      "x": -1,
      "y": -1,
      "z": 2,
      "name": "Rock_Crystal_Ultramarine_Block",
      "rotation": 4
    },
    {
      "x": -1,
      "y": 0,
      "z": 2,
      "name": "Rock_Crystal_Ultramarine_Block",
      "rotation": 4
    },
    {
      "x": -1,
      "y": 1,
      "z": 2,
      "name": "Rock_Crystal_Ultramarine_Block",
      "rotation": 4
    },
    {
      "x": -1,
      "y": 0,
      "z": 3,
      "name": "Rock_Crystal_Ultramarine_Block",
      "rotation": 4
    },
    {
      "x": 0,
      "y": 0,
      "z": 1,
      "name": "Rock_Crystal_Ultramarine_Small",
      "rotation": 5
    },
    {
      "x": 0,
      "y": 0,
      "z": 2,
      "name": "Rock_Crystal_Ultramarine_Medium",
      "rotation": 5
    }
  ],
  "fluids": [
    {
      "x": -4,
      "y": 0,
      "z": 1,
      "name": "Water_Source",
      "level": 1
    },
    {
      "x": -4,
      "y": 0,
      "z": 2,
      "name": "Water_Source",
      "level": 1
    },
    {
      "x": -3,
      "y": 0,
      "z": -2,
      "name": "Water_Source",
      "level": 1
    },
    {
      "x": -3,
      "y": 0,
      "z": -1,
      "name": "Water_Source",
      "level": 1
    },
    {
      "x": -3,
      "y": -1,
      "z": 0,
      "name": "Water_Source",
      "level": 1
    },
    {
      "x": -3,
      "y": 1,
      "z": 0,
      "name": "Water_Source",
      "level": 1
    },
    {
      "x": -3,
      "y": -1,
      "z": 1,
      "name": "Water_Source",
      "level": 1
    },
    {
      "x": -3,
      "y": 1,
      "z": 1,
      "name": "Water_Source",
      "level": 1
    },
    {
      "x": -2,
      "y": 0,
      "z": -4,
      "name": "Water_Source",
      "level": 1
    },
    {
      "x": -2,
      "y": -1,
      "z": -2,
      "name": "Water_Source",
      "level": 1
    },
    {
      "x": -2,
      "y": 1,
      "z": -2,
      "name": "Water_Source",
      "level": 1
    },
    {
      "x": -2,
      "y": -1,
      "z": -1,
      "name": "Water_Source",
      "level": 1
    },
    {
      "x": -2,
      "y": 1,
      "z": -1,
      "name": "Water_Source",
      "level": 1
    },
    {
      "x": -2,
      "y": -2,
      "z": 1,
      "name": "Water_Source",
      "level": 1
    },
    {
      "x": -2,
      "y": 2,
      "z": 1,
      "name": "Water_Source",
      "level": 1
    },
    {
      "x": -2,
      "y": -2,
      "z": 2,
      "name": "Water_Source",
      "level": 1
    },
    {
      "x": -2,
      "y": 2,
      "z": 2,
      "name": "Water_Source",
      "level": 1
    },
    {
      "x": -1,
      "y": 0,
      "z": -2,
      "name": "Water_Source",
      "level": 1
    },
    {
      "x": -1,
      "y": 0,
      "z": -1,
      "name": "Water_Source",
      "level": 1
    },
    {
      "x": -1,
      "y": -1,
      "z": 0,
      "name": "Water_Source",
      "level": 1
    },
    {
      "x": -1,
      "y": 1,
      "z": 0,
      "name": "Water_Source",
      "level": 1
    },
    {
      "x": -1,
      "y": -1,
      "z": 1,
      "name": "Water_Source",
      "level": 1
    },
    {
      "x": -1,
      "y": 1,
      "z": 1,
      "name": "Water_Source",
      "level": 1
    },
    {
      "x": 0,
      "y": 0,
      "z": 1,
      "name": "Water_Source",
      "level": 1
    },
    {
      "x": 0,
      "y": 0,
      "z": 2,
      "name": "Water_Source",
      "level": 1
    }
  ]
}