{
  "version": 8,
  "blockIdVersion": 10,
  "anchorX": 0,
  "anchorY": 0,
  "anchorZ": 0,
  "blocks": [
    {
      "x": 0,
      "y": 14,
      "z": 0,
      "name": "Plant_Coral_Block_Orange"
    },
    {
      "x": 2,
      "y": 15,
      "z": 0,
      "name": "Plant_Coral_Block_Orange"
    },
    {
      "x": 3,
      "y": 15,
      "z": 0,
      "name": "Plant_Coral_Block_Orange"
    },
    {
      "x": 4,
      "y": 15,
      "z": 0,
      "name": "Plant_Crop_Mushroom_Block_Blue_Mycelium"
    },
    {
      "x": 5,
      "y": 15,
      "z": 0,
      "name": "Plant_Crop_Mushroom_Block_Blue_Mycelium"
    },
    {
      "x": 6,
      "y": 15,
      "z": 0,
      "name": "Plant_Crop_Mushroom_Block_Blue_Mycelium"
    },
    {
      "x": 3,
      "y": 16,
      "z": 0,
      "name": "Plant_Coral_Block_Orange"
    },
    {
      "x": 4,
      "y": 16,
      "z": 0,
      "name": "Plant_Coral_Block_Cyan"
    },
    {
      "x": 5,
      "y": 16,
      "z": 0,
      "name": "Rock_Crystal_Cyan_Block"
    },
    {
      "x": 6,
      "y": 16,
      "z": 0,
      "name": "Plant_Coral_Block_Cyan"
    },
    {
      "x": 0,
      "y": 14,
      "z": 1,
      "name": "Plant_Coral_Block_Orange"
    },
    {
      "x": 1,
      "y": 14,
      "z": 1,
      "name": "Plant_Coral_Block_Orange"
    },
    {
      "x": 3,
      "y": 14,
      "z": 1,
      "name": "Plant_Crop_Mushroom_Block_Blue_Mycelium"
    },
    {
      "x": 1,
      "y": 15,
      "z": 1,
      "name": "Plant_Coral_Block_Orange"
    },
    {
      "x": 2,
      "y": 15,
      "z": 1,
      "name": "Plant_Coral_Block_Orange"
    },
    {
      "x": 3,
      "y": 15,
      "z": 1,
      "name": "Plant_Coral_Block_Cyan"
    },
    {
      "x": 6,
      "y": 15,
      "z": 1,
      "name": "Plant_Crop_Mushroom_Block_Blue_Mycelium"
    },
    {
      "x": 7,
      "y": 15,
      "z": 1,
      "name": "Plant_Crop_Mushroom_Block_Blue_Mycelium"
    },
    {
      "x": 6,
      "y": 16,
      "z": 1,
      "name": "Plant_Coral_Block_Cyan"
    },
    {
      "x": 7,
      "y": 16,
      "z": 1,
      "name": "Plant_Coral_Block_Cyan"
    },
    {
      "x": 8,
      "y": 16,
      "z": 1,
      "name": "Plant_Crop_Mushroom_Block_Blue_Mycelium"
    },
    {
      "x": 9,
      "y": 16,
      "z": 1,
      "name": "Plant_Crop_Mushroom_Block_Blue_Mycelium"
    },
    {
      "x": 7,
      "y": 17,
      "z": 1,
      "name": "Plant_Coral_Block_Cyan"
    },
    {
      "x": 8,
      "y": 17,
      "z": 1,
      "name": "Plant_Coral_Block_Cyan"
    },
    {
      "x": 9,
      "y": 17,
      "z": 1,
      "name": "Plant_Crop_Mushroom_Block_Blue"
    },
    {
      "x": 1,
      "y": 13,
      "z": 2,
      "name": "Plant_Crop_Mushroom_Block_Blue_Mycelium"
    },
    {
      "x": 1,
      "y": 14,
      "z": 2,
      "name": "Plant_Coral_Block_Cyan"
    },
    {
      "x": 4,
      "y": 14,
      "z": 2,
      "name": "Plant_Crop_Mushroom_Block_Blue_Mycelium"
    },
    {
      "x": 3,
      "y": 15,
      "z": 2,
      "name": "Plant_Coral_Block_Cyan"
    },
    {
      "x": 4,
      "y": 15,
      "z": 2,
      "name": "Plant_Coral_Block_Cyan"
    },
    {
      "x": 1,
      "y": 13,
      "z": 3,
      "name": "Plant_Crop_Mushroom_Block_Blue"
    },
    {
      "x": 4,
      "y": 13,
      "z": 3,
      "name": "Plant_Crop_Mushroom_Block_Blue_Mycelium"
    },
    {
      "x": 5,
      "y": 13,
      "z": 3,
      "name": "Plant_Crop_Mushroom_Block_Blue_Mycelium"
    },
    {
      "x": 1,
      "y": 14,
      "z": 3,
      "name": "Plant_Coral_Block_Cyan"
    },
    {
      "x": 4,
      "y": 14,
      "z": 3,
      "name": "Plant_Coral_Block_Cyan"
    },
    {
      "x": 5,
      "y": 14,
      "z": 3,
      "name": "Plant_Coral_Block_Cyan"
    },
    {
      "x": 4,
      "y": 15,
      "z": 3,
      "name": "Rock_Crystal_Cyan_Block"
    },
    {
      "x": 1,
      "y": 13,
      "z": 4,
      "name": "Plant_Coral_Block_Cyan"
    },
    {
      "x": 5,
      "y": 13,
      "z": 4,
      "name": "Plant_Crop_Mushroom_Block_Blue_Mycelium"
    },
    {
      "x": 6,
      "y": 13,
      "z": 4,
      "name": "Plant_Crop_Mushroom_Block_Blue_Mycelium"
    },
    {
      "x": 5,
      "y": 14,
      "z": 4,
      "name": "Plant_Coral_Block_Cyan"
    },
    {
      "x": 6,
      "y": 14,
      "z": 4,
      "name": "Plant_Coral_Block_Cyan"
    },
    {
      "x": 1,
      "y": 13,
      "z": 5,
      "name": "Plant_Coral_Block_Cyan"
    },
    {
      "x": 2,
      "y": 13,
      "z": 5,
      "name": "Plant_Coral_Block_Cyan"
    },
    {
      "x": 2,
      "y": 13,
      "z": 6,
      "name": "Plant_Coral_Block_Cyan"
    },
    {
      "x": 0,
      "y": 12,
      "z": -15,
      "name": "Plant_Crop_Mushroom_Block_Blue_Mycelium"
    },
    {
      "x": 3,
      "y": 12,
      "z": -14,
      "name": "Plant_Crop_Mushroom_Block_Blue_Mycelium"
    },
    {
      "x": 3,
      "y": 12,
      "z": -13,
      "name": "Plant_Crop_Mushroom_Block_Blue_Mycelium"
    },
    {
      "x": 0,
      "y": 11,
      "z": -12,
      "name": "Plant_Crop_Mushroom_Block_Blue_Mycelium"
    },
    {
      "x": 1,
      "y": 11,
      "z": -12,
      "name": "Plant_Crop_Mushroom_Block_Blue_Mycelium"
    },
    {
      "x": 0,
      "y": 12,
      "z": -12,
      "name": "Plant_Coral_Block_Cyan"
    },
    {
      "x": 1,
      "y": 12,
      "z": -12,
      "name": "Rock_Crystal_Cyan_Block"
    },
    {
      "x": 0,
      "y": 11,
      "z": -11,
      "name": "Plant_Crop_Mushroom_Block_Blue_Mycelium"
    },
    {
      "x": 0,
      "y": 12,
      "z": -11,
      "name": "Plant_Coral_Block_Cyan"
    },
    {
      "x": 3,
      "y": 12,
      "z": -11,
      "name": "Plant_Coral_Block_Cyan"
    },
    {
      "x": 7,
      "y": 9,
      "z": -10,
      "name": "Plant_Crop_Mushroom_Block_Blue_Mycelium"
    },
    {
      "x": 7,
      "y": 10,
      "z": -10,
      "name": "Plant_Coral_Block_Cyan"
    },
    {
      "x": 2,
      "y": 11,
      "z": -10,
      "name": "Plant_Crop_Mushroom_Block_Blue_Mycelium"
    },
    {
      "x": 3,
      "y": 11,
      "z": -10,
      "name": "Plant_Crop_Mushroom_Block_Blue_Mycelium"
    },
    {
      "x": 2,
      "y": 12,
      "z": -10,
      "name": "Plant_Crop_Mushroom_Block_Blue"
    },
    {
      "x": 3,
      "y": 12,
      "z": -10,
      "name": "Plant_Crop_Mushroom_Block_Blue"
    },
    {
      "x": 8,
      "y": 9,
      "z": -9,
      "name": "Plant_Coral_Block_Cyan"
    },
    {
      "x": 0,
      "y": 10,
      "z": -9,
      "name": "Plant_Crop_Mushroom_Block_Blue_Mycelium"
    },
    {
      "x": 1,
      "y": 10,
      "z": -9,
      "name": "Plant_Crop_Mushroom_Block_Blue_Mycelium"
    },
    {
      "x": 7,
      "y": 10,
      "z": -9,
      "name": "Plant_Coral_Block_Cyan"
    },
    {
      "x": 8,
      "y": 10,
      "z": -9,
      "name": "Plant_Crop_Mushroom_Block_Blue"
    },
    {
      "x": 0,
      "y": 11,
      "z": -9,
      "name": "Plant_Coral_Block_Cyan"
    },
    {
      "x": 1,
      "y": 11,
      "z": -9,
      "name": "Plant_Crop_Mushroom_Block_Blue"
    },
    {
      "x": 2,
      "y": 11,
      "z": -9,
      "name": "Plant_Crop_Mushroom_Block_Blue_Mycelium"
    },
    {
      "x": 1,
      "y": 12,
      "z": -9,
      "name": "Plant_Crop_Mushroom_Block_Blue"
    },
    {
      "x": 2,
      "y": 12,
      "z": -9,
      "name": "Plant_Crop_Mushroom_Block_Blue"
    },
    {
      "x": 4,
      "y": 8,
      "z": -8,
      "name": "Plant_Crop_Mushroom_Block_Blue_Mycelium"
    },
    {
      "x": 8,
      "y": 8,
      "z": -8,
      "name": "Plant_Crop_Mushroom_Block_Blue_Mycelium"
    },
    {
      "x": 4,
      "y": 9,
      "z": -8,
      "name": "Plant_Coral_Block_Cyan"
    },
    {
      "x": 8,
      "y": 9,
      "z": -8,
      "name": "Plant_Coral_Block_Cyan"
    },
    {
      "x": 10,
      "y": 10,
      "z": -8,
      "name": "Plant_Crop_Mushroom_Block_Blue_Mycelium"
    },
    {
      "x": 10,
      "y": 11,
      "z": -8,
      "name": "Plant_Crop_Mushroom_Block_Blue"
    },
    {
      "x": 5,
      "y": 7,
      "z": -7,
      "name": "Plant_Crop_Mushroom_Block_Blue_Mycelium"
    },
    {
      "x": 4,
      "y": 8,
      "z": -7,
      "name": "Plant_Crop_Mushroom_Block_Blue_Mycelium"
    },
    {
      "x": 5,
      "y": 8,
      "z": -7,
      "name": "Plant_Coral_Block_Cyan"
    },
    {
      "x": 4,
      "y": 9,
      "z": -7,
      "name": "Plant_Coral_Block_Cyan"
    },
    {
      "x": 5,
      "y": 9,
      "z": -7,
      "name": "Plant_Coral_Block_Cyan"
    },
    {
      "x": 8,
      "y": 9,
      "z": -7,
      "name": "Plant_Crop_Mushroom_Block_Blue"
    },
    {
      "x": 9,
      "y": 9,
      "z": -7,
      "name": "Plant_Crop_Mushroom_Block_Blue_Mycelium"
    },
    {
      "x": 10,
      "y": 9,
      "z": -7,
      "name": "Plant_Crop_Mushroom_Block_Blue_Mycelium"
    },
    {
      "x": 9,
      "y": 10,
      "z": -7,
      "name": "Plant_Crop_Mushroom_Block_Blue"
    },
    {
      "x": 10,
      "y": 10,
      "z": -7,
      "name": "Plant_Crop_Mushroom_Block_Blue"
    },
    {
      "x": 10,
      "y": 11,
      "z": -7,
      "name": "Plant_Crop_Mushroom_Block_Blue"
    },
    {
      "x": 2,
      "y": 6,
      "z": -6,
      "name": "Plant_Crop_Mushroom_Block_Blue_Mycelium"
    },
    {
      "x": 2,
      "y": 7,
      "z": -6,
      "name": "Plant_Coral_Block_Cyan"
    },
    {
      "x": 5,
      "y": 7,
      "z": -6,
      "name": "Plant_Crop_Mushroom_Block_Blue_Mycelium"
    },
    {
      "x": 6,
      "y": 7,
      "z": -6,
      "name": "Plant_Crop_Mushroom_Block_Blue"
    },
    {
      "x": 5,
      "y": 8,
      "z": -6,
      "name": "Plant_Coral_Block_Cyan"
    },
    {
      "x": 6,
      "y": 8,
      "z": -6,
      "name": "Plant_Coral_Block_Cyan"
    },
    {
      "x": 7,
      "y": 8,
      "z": -6,
      "name": "Plant_Coral_Block_Orange"
    },
    {
      "x": 8,
      "y": 8,
      "z": -6,
      "name": "Plant_Coral_Block_Orange"
    },
    {
      "x": 8,
      "y": 9,
      "z": -6,
      "name": "Plant_Coral_Block_Orange"
    },
    {
      "x": 9,
      "y": 9,
      "z": -6,
      "name": "Plant_Crop_Mushroom_Block_Blue_Mycelium"
    },
    {
      "x": 8,
      "y": 10,
      "z": -6,
      "name": "Plant_Coral_Block_Orange"
    },
    {
      "x": 9,
      "y": 10,
      "z": -6,
      "name": "Plant_Crop_Mushroom_Block_Blue"
    },
    {
      "x": 0,
      "y": 11,
      "z": -6,
      "name": "Plant_Coral_Block_Cyan"
    },
    {
      "x": 1,
      "y": 11,
      "z": -6,
      "name": "Plant_Coral_Block_Cyan"
    },
    {
      "x": 2,
      "y": 6,
      "z": -5,
      "name": "Plant_Crop_Mushroom_Block_Blue_Mycelium"
    },
    {
      "x": 3,
      "y": 6,
      "z": -5,
      "name": "Plant_Coral_Block_Cyan"
    },
    {
      "x": 6,
      "y": 6,
      "z": -5,
      "name": "Plant_Crop_Mushroom_Block_Blue_Mycelium"
    },
    {
      "x": 2,
      "y": 7,
      "z": -5,
      "name": "Plant_Crop_Mushroom_Block_Blue"
    },
    {
      "x": 3,
      "y": 7,
      "z": -5,
      "name": "Plant_Coral_Block_Cyan"
    },
    {
      "x": 6,
      "y": 7,
      "z": -5,
      "name": "Plant_Crop_Mushroom_Block_Blue"
    },
    {
      "x": 7,
      "y": 7,
      "z": -5,
      "name": "Plant_Coral_Block_Orange"
    },
    {
      "x": 8,
      "y": 7,
      "z": -5,
      "name": "Plant_Crop_Mushroom_Block_Blue_Mycelium"
    },
    {
      "x": 7,
      "y": 8,
      "z": -5,
      "name": "Plant_Coral_Block_Orange"
    },
    {
      "x": 8,
      "y": 8,
      "z": -5,
      "name": "Plant_Coral_Block_Cyan"
    },
    {
      "x": 9,
      "y": 8,
      "z": -5,
      "name": "Plant_Crop_Mushroom_Block_Blue"
    },
    {
      "x": 10,
      "y": 8,
      "z": -5,
      "name": "Plant_Crop_Mushroom_Block_Blue_Mycelium"
    },
    {
      "x": 9,
      "y": 9,
      "z": -5,
      "name": "Plant_Coral_Block_Cyan"
    },
    {
      "x": 10,
      "y": 9,
      "z": -5,
      "name": "Plant_Coral_Block_Cyan"
    },
    {
      "x": 0,
      "y": 3,
      "z": -4,
      "name": "Plant_Coral_Block_Orange"
    },
    {
      "x": 1,
      "y": 3,
      "z": -4,
      "name": "Plant_Coral_Block_Orange"
    },
    {
      "x": 3,
      "y": 5,
      "z": -4,
      "name": "Plant_Crop_Mushroom_Block_Blue_Mycelium"
    },
    {
      "x": 4,
      "y": 5,
      "z": -4,
      "name": "Plant_Crop_Mushroom_Block_Blue_Mycelium"
    },
    {
      "x": 3,
      "y": 6,
      "z": -4,
      "name": "Plant_Coral_Block_Cyan"
    },
    {
      "x": 4,
      "y": 6,
      "z": -4,
      "name": "Plant_Coral_Block_Cyan"
    },
    {
      "x": 6,
      "y": 6,
      "z": -4,
      "name": "Plant_Coral_Block_Orange"
    },
    {
      "x": 6,
      "y": 7,
      "z": -4,
      "name": "Plant_Coral_Block_Orange"
    },
    {
      "x": 7,
      "y": 7,
      "z": -4,
      "name": "Plant_Coral_Block_Orange"
    },
    {
      "x": 10,
      "y": 8,
      "z": -4,
      "name": "Plant_Crop_Mushroom_Block_Blue_Mycelium"
    },
    {
      "x": 11,
      "y": 8,
      "z": -4,
      "name": "Plant_Crop_Mushroom_Block_Blue_Mycelium"
    },
    {
      "x": 10,
      "y": 9,
      "z": -4,
      "name": "Plant_Coral_Block_Cyan"
    },
    {
      "x": 11,
      "y": 9,
      "z": -4,
      "name": "Plant_Crop_Mushroom_Block_Blue"
    },
    {
      "x": 0,
      "y": 3,
      "z": -3,
      "name": "Plant_Coral_Block_Orange"
    },
    {
      "x": 1,
      "y": 3,
      "z": -3,
      "name": "Plant_Coral_Block_Orange"
    },
    {
      "x": 1,
      "y": 4,
      "z": -3,
      "name": "Plant_Coral_Block_Orange"
    },
    {
      "x": 2,
      "y": 4,
      "z": -3,
      "name": "Plant_Coral_Block_Orange"
    },
    {
      "x": 4,
      "y": 5,
      "z": -3,
      "name": "Plant_Crop_Mushroom_Block_Blue_Mycelium"
    },
    {
      "x": 4,
      "y": 6,
      "z": -3,
      "name": "Plant_Coral_Block_Cyan"
    },
    {
      "x": 5,
      "y": 6,
      "z": -3,
      "name": "Plant_Coral_Block_Orange"
    },
    {
      "x": 6,
      "y": 6,
      "z": -3,
      "name": "Plant_Coral_Block_Orange"
    },
    {
      "x": 7,
      "y": 6,
      "z": -3,
      "name": "Plant_Coral_Block_Cyan"
    },
    {
      "x": 8,
      "y": 6,
      "z": -3,
      "name": "Plant_Crop_Mushroom_Block_Blue_Mycelium"
    },
    {
      "x": 7,
      "y": 7,
      "z": -3,
      "name": "Plant_Coral_Block_Cyan"
    },
    {
      "x": 8,
      "y": 7,
      "z": -3,
      "name": "Plant_Coral_Block_Cyan"
    },
    {
      "x": 1,
      "y": 4,
      "z": -2,
      "name": "Plant_Coral_Block_Orange"
    },
    {
      "x": 2,
      "y": 4,
      "z": -2,
      "name": "Plant_Coral_Block_Orange"
    },
    {
      "x": 3,
      "y": 4,
      "z": -2,
      "name": "Plant_Coral_Block_Orange"
    },
    {
      "x": 3,
      "y": 5,
      "z": -2,
      "name": "Plant_Coral_Block_Orange"
    },
    {
      "x": 4,
      "y": 5,
      "z": -2,
      "name": "Plant_Coral_Block_Orange"
    },
    {
      "x": 5,
      "y": 5,
      "z": -2,
      "name": "Plant_Coral_Block_Orange"
    },
    {
      "x": 5,
      "y": 6,
      "z": -2,
      "name": "Plant_Coral_Block_Orange"
    },
    {
      "x": 8,
      "y": 7,
      "z": -2,
      "name": "Plant_Coral_Block_Cyan"
    },
    {
      "x": 9,
      "y": 7,
      "z": -2,
      "name": "Plant_Coral_Block_Cyan"
    },
    {
      "x": 9,
      "y": 8,
      "z": -2,
      "name": "Plant_Coral_Block_Cyan"
    },
    {
      "x": 2,
      "y": 4,
      "z": -1,
      "name": "Plant_Coral_Block_Orange"
    },
    {
      "x": 3,
      "y": 4,
      "z": -1,
      "name": "Plant_Coral_Block_Orange"
    },
    {
      "x": 3,
      "y": 5,
      "z": -1,
      "name": "Plant_Coral_Block_Orange"
    },
    {
      "x": 5,
      "y": 5,
      "z": -1,
      "name": "Plant_Crop_Mushroom_Block_Blue_Mycelium"
    },
    {
      "x": 6,
      "y": 5,
      "z": -1,
      "name": "Plant_Crop_Mushroom_Block_Blue_Mycelium"
    },
    {
      "x": 5,
      "y": 6,
      "z": -1,
      "name": "Plant_Crop_Mushroom_Block_Blue"
    },
    {
      "x": 6,
      "y": 6,
      "z": -1,
      "name": "Plant_Coral_Block_Cyan"
    },
    {
      "x": 9,
      "y": 7,
      "z": -1,
      "name": "Plant_Crop_Mushroom_Block_Blue_Mycelium"
    },
    {
      "x": 9,
      "y": 8,
      "z": -1,
      "name": "Plant_Coral_Block_Cyan"
    },
    {
      "x": 10,
      "y": 8,
      "z": -1,
      "name": "Rock_Crystal_Cyan_Block"
    },
    {
      "x": 0,
      "y": 13,
      "z": -16,
      "name": "Plant_Coral_Block_Cyan"
    },
    {
      "x": 0,
      "y": 13,
      "z": -15,
      "name": "Rock_Crystal_Cyan_Block"
    },
    {
      "x": 3,
      "y": 13,
      "z": -14,
      "name": "Plant_Crop_Mushroom_Block_Blue"
    },
    {
      "x": 1,
      "y": 13,
      "z": -13,
      "name": "Plant_Coral_Block_Cyan"
    },
    {
      "x": 2,
      "y": 13,
      "z": -13,
      "name": "Plant_Coral_Block_Cyan"
    },
    {
      "x": 3,
      "y": 13,
      "z": -13,
      "name": "Plant_Coral_Block_Cyan"
    },
    {
      "x": 1,
      "y": 13,
      "z": -12,
      "name": "Plant_Coral_Block_Cyan"
    },
    {
      "x": 0,
      "y": 18,
      "z": -11,
      "name": "Plant_Crop_Mushroom_Block_Blue_Mycelium"
    },
    {
      "x": 0,
      "y": 19,
      "z": -11,
      "name": "Plant_Coral_Block_Cyan"
    },
    {
      "x": 0,
      "y": 17,
      "z": -10,
      "name": "Plant_Crop_Mushroom_Block_Blue_Mycelium"
    },
    {
      "x": 0,
      "y": 18,
      "z": -10,
      "name": "Plant_Coral_Block_Cyan"
    },
    {
      "x": 0,
      "y": 19,
      "z": -10,
      "name": "Plant_Coral_Block_Cyan"
    },
    {
      "x": 2,
      "y": 19,
      "z": -9,
      "name": "Plant_Crop_Mushroom_Block_Blue_Mycelium"
    },
    {
      "x": 2,
      "y": 20,
      "z": -9,
      "name": "Plant_Coral_Block_Cyan"
    },
    {
      "x": 2,
      "y": 21,
      "z": -9,
      "name": "Plant_Coral_Block_Cyan"
    },
    {
      "x": 2,
      "y": 18,
      "z": -8,
      "name": "Plant_Crop_Mushroom_Block_Blue_Mycelium"
    },
    {
      "x": 1,
      "y": 19,
      "z": -8,
      "name": "Plant_Coral_Block_Cyan"
    },
    {
      "x": 2,
      "y": 19,
      "z": -8,
      "name": "Rock_Crystal_Cyan_Block"
    },
    {
      "x": 2,
      "y": 20,
      "z": -8,
      "name": "Rock_Crystal_Cyan_Block"
    },
    {
      "x": 0,
      "y": 17,
      "z": -7,
      "name": "Plant_Coral_Block_Orange"
    },
    {
      "x": 0,
      "y": 18,
      "z": -7,
      "name": "Plant_Coral_Block_Orange"
    },
    {
      "x": 1,
      "y": 18,
      "z": -7,
      "name": "Plant_Crop_Mushroom_Block_Blue"
    },
    {
      "x": 1,
      "y": 19,
      "z": -7,
      "name": "Plant_Crop_Mushroom_Block_Blue"
    },
    {
      "x": 1,
      "y": 16,
      "z": -6,
      "name": "Plant_Crop_Mushroom_Block_Blue_Mycelium"
    },
    {
      "x": 0,
      "y": 17,
      "z": -6,
      "name": "Plant_Coral_Block_Orange"
    },
    {
      "x": 1,
      "y": 17,
      "z": -6,
      "name": "Plant_Crop_Mushroom_Block_Blue"
    },
    {
      "x": 3,
      "y": 17,
      "z": -6,
      "name": "Plant_Crop_Mushroom_Block_Blue_Mycelium"
    },
    {
      "x": 3,
      "y": 18,
      "z": -6,
      "name": "Plant_Coral_Block_Cyan"
    },
    {
      "x": 4,
      "y": 18,
      "z": -6,
      "name": "Plant_Coral_Block_Cyan"
    },
    {
      "x": 2,
      "y": 14,
      "z": -5,
      "name": "Plant_Crop_Mushroom_Block_Blue_Mycelium"
    },
    {
      "x": 3,
      "y": 14,
      "z": -5,
      "name": "Plant_Crop_Mushroom_Block_Blue_Mycelium"
    },
    {
      "x": 2,
      "y": 15,
      "z": -5,
      "name": "Plant_Crop_Mushroom_Block_Blue"
    },
    {
      "x": 3,
      "y": 15,
      "z": -5,
      "name": "Plant_Coral_Block_Cyan"
    },
    {
      "x": 1,
      "y": 16,
      "z": -5,
      "name": "Plant_Crop_Mushroom_Block_Blue_Mycelium"
    },
    {
      "x": 2,
      "y": 16,
      "z": -5,
      "name": "Plant_Crop_Mushroom_Block_Blue_Mycelium"
    },
    {
      "x": 1,
      "y": 17,
      "z": -5,
      "name": "Plant_Coral_Block_Cyan"
    },
    {
      "x": 2,
      "y": 17,
      "z": -5,
      "name": "Plant_Crop_Mushroom_Block_Blue"
    },
    {
      "x": 3,
      "y": 17,
      "z": -5,
      "name": "Plant_Crop_Mushroom_Block_Blue_Mycelium"
    },
    {
      "x": 2,
      "y": 18,
      "z": -5,
      "name": "Plant_Coral_Block_Cyan"
    },
    {
      "x": 3,
      "y": 18,
      "z": -5,
      "name": "Plant_Coral_Block_Cyan"
    },
    {
      "x": 0,
      "y": 14,
      "z": -4,
      "name": "Plant_Coral_Block_Cyan"
    },
    {
      "x": 2,
      "y": 14,
      "z": -4,
      "name": "Plant_Crop_Mushroom_Block_Blue_Mycelium"
    },
    {
      "x": 0,
      "y": 15,
      "z": -4,
      "name": "Rock_Crystal_Cyan_Block"
    },
    {
      "x": 1,
      "y": 15,
      "z": -4,
      "name": "Plant_Coral_Block_Cyan"
    },
    {
      "x": 2,
      "y": 15,
      "z": -4,
      "name": "Plant_Coral_Block_Cyan"
    },
    {
      "x": 7,
      "y": 18,
      "z": -4,
      "name": "Plant_Crop_Mushroom_Block_Blue_Mycelium"
    },
    {
      "x": 7,
      "y": 19,
      "z": -4,
      "name": "Plant_Crop_Mushroom_Block_Blue"
    },
    {
      "x": 8,
      "y": 19,
      "z": -4,
      "name": "Plant_Coral_Block_Cyan"
    },
    {
      "x": 1,
      "y": 16,
      "z": -3,
      "name": "Plant_Crop_Mushroom_Block_Blue_Mycelium"
    },
    {
      "x": 0,
      "y": 17,
      "z": -3,
      "name": "Plant_Crop_Mushroom_Block_Blue_Mycelium"
    },
    {
      "x": 1,
      "y": 17,
      "z": -3,
      "name": "Plant_Coral_Block_Cyan"
    },
    {
      "x": 6,
      "y": 17,
      "z": -3,
      "name": "Plant_Crop_Mushroom_Block_Blue_Mycelium"
    },
    {
      "x": 0,
      "y": 18,
      "z": -3,
      "name": "Plant_Coral_Block_Cyan"
    },
    {
      "x": 1,
      "y": 18,
      "z": -3,
      "name": "Plant_Coral_Block_Cyan"
    },
    {
      "x": 3,
      "y": 18,
      "z": -3,
      "name": "Plant_Crop_Mushroom_Block_Blue"
    },
    {
      "x": 6,
      "y": 18,
      "z": -3,
      "name": "Plant_Coral_Block_Cyan"
    },
    {
      "x": 7,
      "y": 18,
      "z": -3,
      "name": "Plant_Coral_Block_Cyan"
    },
    {
      "x": 3,
      "y": 19,
      "z": -3,
      "name": "Plant_Crop_Mushroom_Block_Blue"
    },
    {
      "x": 7,
      "y": 19,
      "z": -3,
      "name": "Plant_Coral_Block_Cyan"
    },
    {
      "x": 3,
      "y": 20,
      "z": -3,
      "name": "Plant_Coral_Block_Cyan"
    },
    {
      "x": 1,
      "y": 16,
      "z": -2,
      "name": "Plant_Crop_Mushroom_Block_Blue_Mycelium"
    },
    {
      "x": 2,
      "y": 16,
      "z": -2,
      "name": "Plant_Crop_Mushroom_Block_Blue"
    },
    {
      "x": 5,
      "y": 16,
      "z": -2,
      "name": "Plant_Crop_Mushroom_Block_Blue_Mycelium"
    },
    {
      "x": 6,
      "y": 16,
      "z": -2,
      "name": "Plant_Crop_Mushroom_Block_Blue_Mycelium"
    },
    {
      "x": 1,
      "y": 17,
      "z": -2,
      "name": "Plant_Coral_Block_Cyan"
    },
    {
      "x": 2,
      "y": 17,
      "z": -2,
      "name": "Plant_Crop_Mushroom_Block_Blue"
    },
    {
      "x": 3,
      "y": 17,
      "z": -2,
      "name": "Plant_Crop_Mushroom_Block_Blue_Mycelium"
    },
    {
      "x": 4,
      "y": 17,
      "z": -2,
      "name": "Plant_Coral_Block_Cyan"
    },
    {
      "x": 5,
      "y": 17,
      "z": -2,
      "name": "Plant_Coral_Block_Cyan"
    },
    {
      "x": 6,
      "y": 17,
      "z": -2,
      "name": "Plant_Coral_Block_Cyan"
    },
    {
      "x": 3,
      "y": 18,
      "z": -2,
      "name": "Plant_Crop_Mushroom_Block_Blue"
    },
    {
      "x": 4,
      "y": 18,
      "z": -2,
      "name": "Plant_Coral_Block_Cyan"
    },
    {
      "x": 6,
      "y": 18,
      "z": -2,
      "name": "Plant_Coral_Block_Cyan"
    },
    {
      "x": 2,
      "y": 15,
      "z": -1,
      "name": "Plant_Crop_Mushroom_Block_Blue_Mycelium"
    },
    {
      "x": 2,
      "y": 16,
      "z": -1,
      "name": "Plant_Crop_Mushroom_Block_Blue"
    },
    {
      "x": 3,
      "y": 16,
      "z": -1,
      "name": "Plant_Coral_Block_Orange"
    },
    {
      "x": 4,
      "y": 16,
      "z": -1,
      "name": "Plant_Coral_Block_Orange"
    },
    {
      "x": 5,
      "y": 16,
      "z": -1,
      "name": "Plant_Crop_Mushroom_Block_Blue_Mycelium"
    },
    {
      "x": 4,
      "y": 17,
      "z": -1,
      "name": "Plant_Coral_Block_Orange"
    },
    {
      "x": 5,
      "y": 17,
      "z": -1,
      "name": "Plant_Coral_Block_Cyan"
    },
    {
      "x": -1,
      "y": 13,
      "z": -15,
      "name": "Rock_Crystal_Cyan_Block"
    },
    {
      "x": -5,
      "y": 13,
      "z": -14,
      "name": "Plant_Crop_Mushroom_Block_Blue"
    },
    {
      "x": -3,
      "y": 13,
      "z": -14,
      "name": "Plant_Crop_Mushroom_Block_Blue_Mycelium"
    },
    {
      "x": -1,
      "y": 13,
      "z": -14,
      "name": "Plant_Coral_Block_Cyan"
    },
    {
      "x": -3,
      "y": 14,
      "z": -14,
      "name": "Plant_Coral_Block_Cyan"
    },
    {
      "x": -5,
      "y": 13,
      "z": -13,
      "name": "Plant_Crop_Mushroom_Block_Blue"
    },
    {
      "x": -3,
      "y": 13,
      "z": -13,
      "name": "Plant_Crop_Mushroom_Block_Blue_Mycelium"
    },
    {
      "x": -3,
      "y": 14,
      "z": -13,
      "name": "Plant_Coral_Block_Cyan"
    },
    {
      "x": -3,
      "y": 13,
      "z": -12,
      "name": "Plant_Coral_Block_Cyan"
    },
    {
      "x": -2,
      "y": 13,
      "z": -12,
      "name": "Plant_Coral_Block_Cyan"
    },
    {
      "x": -3,
      "y": 14,
      "z": -12,
      "name": "Plant_Coral_Block_Cyan"
    },
    {
      "x": -2,
      "y": 13,
      "z": -11,
      "name": "Plant_Coral_Block_Cyan"
    },
    {
      "x": -3,
      "y": 17,
      "z": -10,
      "name": "Plant_Coral_Block_Cyan"
    },
    {
      "x": -1,
      "y": 17,
      "z": -10,
      "name": "Plant_Crop_Mushroom_Block_Blue_Mycelium"
    },
    {
      "x": -1,
      "y": 18,
      "z": -10,
      "name": "Plant_Coral_Block_Cyan"
    },
    {
      "x": -3,
      "y": 16,
      "z": -9,
      "name": "Plant_Crop_Mushroom_Block_Blue_Mycelium"
    },
    {
      "x": -1,
      "y": 16,
      "z": -9,
      "name": "Plant_Crop_Mushroom_Block_Blue_Mycelium"
    },
    {
      "x": -3,
      "y": 17,
      "z": -9,
      "name": "Plant_Crop_Mushroom_Block_Blue"
    },
    {
      "x": -1,
      "y": 17,
      "z": -9,
      "name": "Plant_Coral_Block_Cyan"
    },
    {
      "x": -1,
      "y": 18,
      "z": -9,
      "name": "Plant_Coral_Block_Cyan"
    },
    {
      "x": -5,
      "y": 14,
      "z": -8,
      "name": "Plant_Crop_Mushroom_Block_Blue_Mycelium"
    },
    {
      "x": -5,
      "y": 15,
      "z": -8,
      "name": "Plant_Coral_Block_Cyan"
    },
    {
      "x": -3,
      "y": 15,
      "z": -8,
      "name": "Plant_Crop_Mushroom_Block_Blue_Mycelium"
    },
    {
      "x": -3,
      "y": 16,
      "z": -8,
      "name": "Plant_Crop_Mushroom_Block_Blue"
    },
    {
      "x": -1,
      "y": 16,
      "z": -8,
      "name": "Plant_Crop_Mushroom_Block_Blue_Mycelium"
    },
    {
      "x": -3,
      "y": 17,
      "z": -8,
      "name": "Plant_Coral_Block_Cyan"
    },
    {
      "x": -1,
      "y": 17,
      "z": -8,
      "name": "Plant_Coral_Block_Cyan"
    },
    {
      "x": -5,
      "y": 14,
      "z": -7,
      "name": "Plant_Crop_Mushroom_Block_Blue_Mycelium"
    },
    {
      "x": -5,
      "y": 15,
      "z": -7,
      "name": "Plant_Coral_Block_Cyan"
    },
    {
      "x": -2,
      "y": 15,
      "z": -7,
      "name": "Plant_Crop_Mushroom_Block_Blue_Mycelium"
    },
    {
      "x": -3,
      "y": 16,
      "z": -7,
      "name": "Plant_Crop_Mushroom_Block_Blue"
    },
    {
      "x": -2,
      "y": 16,
      "z": -7,
      "name": "Plant_Crop_Mushroom_Block_Blue"
    },
    {
      "x": -1,
      "y": 16,
      "z": -7,
      "name": "Plant_Crop_Mushroom_Block_Blue_Mycelium"
    },
    {
      "x": -1,
      "y": 17,
      "z": -7,
      "name": "Plant_Crop_Mushroom_Block_Blue"
    },
    {
      "x": -5,
      "y": 19,
      "z": -7,
      "name": "Plant_Crop_Mushroom_Block_Blue_Mycelium"
    },
    {
      "x": -5,
      "y": 20,
      "z": -7,
      "name": "Plant_Coral_Block_Cyan"
    },
    {
      "x": -5,
      "y": 14,
      "z": -6,
      "name": "Plant_Crop_Mushroom_Block_Blue_Mycelium"
    },
    {
      "x": -4,
      "y": 14,
      "z": -6,
      "name": "Plant_Coral_Block_Cyan"
    },
    {
      "x": -5,
      "y": 15,
      "z": -6,
      "name": "Plant_Coral_Block_Cyan"
    },
    {
      "x": -4,
      "y": 15,
      "z": -6,
      "name": "Plant_Coral_Block_Cyan"
    },
    {
      "x": -2,
      "y": 15,
      "z": -6,
      "name": "Plant_Coral_Block_Orange"
    },
    {
      "x": -2,
      "y": 16,
      "z": -6,
      "name": "Plant_Coral_Block_Orange"
    },
    {
      "x": -1,
      "y": 16,
      "z": -6,
      "name": "Plant_Coral_Block_Orange"
    },
    {
      "x": -1,
      "y": 17,
      "z": -6,
      "name": "Plant_Coral_Block_Orange"
    },
    {
      "x": -5,
      "y": 19,
      "z": -6,
      "name": "Plant_Crop_Mushroom_Block_Blue_Mycelium"
    },
    {
      "x": -10,
      "y": 20,
      "z": -6,
      "name": "Plant_Crop_Mushroom_Block_Blue_Mycelium"
    },
    {
      "x": -9,
      "y": 20,
      "z": -6,
      "name": "Plant_Crop_Mushroom_Block_Blue_Mycelium"
    },
    {
      "x": -5,
      "y": 20,
      "z": -6,
      "name": "Plant_Coral_Block_Cyan"
    },
    {
      "x": -10,
      "y": 21,
      "z": -6,
      "name": "Plant_Coral_Block_Cyan"
    },
    {
      "x": -9,
      "y": 21,
      "z": -6,
      "name": "Plant_Coral_Block_Cyan"
    },
    {
      "x": -4,
      "y": 13,
      "z": -5,
      "name": "Plant_Crop_Mushroom_Block_Blue_Mycelium"
    },
    {
      "x": -4,
      "y": 14,
      "z": -5,
      "name": "Plant_Coral_Block_Cyan"
    },
    {
      "x": -3,
      "y": 14,
      "z": -5,
      "name": "Plant_Coral_Block_Cyan"
    },
    {
      "x": -2,
      "y": 14,
      "z": -5,
      "name": "Plant_Coral_Block_Orange"
    },
    {
      "x": -2,
      "y": 15,
      "z": -5,
      "name": "Plant_Coral_Block_Orange"
    },
    {
      "x": -4,
      "y": 16,
      "z": -5,
      "name": "Plant_Crop_Mushroom_Block_Blue_Mycelium"
    },
    {
      "x": -4,
      "y": 17,
      "z": -5,
      "name": "Plant_Coral_Block_Cyan"
    },
    {
      "x": -6,
      "y": 18,
      "z": -5,
      "name": "Plant_Crop_Mushroom_Block_Blue_Mycelium"
    },
    {
      "x": -6,
      "y": 19,
      "z": -5,
      "name": "Plant_Coral_Block_Cyan"
    },
    {
      "x": -9,
      "y": 20,
      "z": -5,
      "name": "Plant_Coral_Block_Cyan"
    },
    {
      "x": -6,
      "y": 20,
      "z": -5,
      "name": "Plant_Coral_Block_Cyan"
    },
    {
      "x": -5,
      "y": 20,
      "z": -5,
      "name": "Rock_Crystal_Cyan_Block"
    },
    {
      "x": -9,
      "y": 21,
      "z": -5,
      "name": "Plant_Coral_Block_Cyan"
    },
    {
      "x": -2,
      "y": 13,
      "z": -4,
      "name": "Plant_Coral_Block_Orange"
    },
    {
      "x": -1,
      "y": 13,
      "z": -4,
      "name": "Plant_Crop_Mushroom_Block_Blue_Mycelium"
    },
    {
      "x": -2,
      "y": 14,
      "z": -4,
      "name": "Plant_Coral_Block_Orange"
    },
    {
      "x": -1,
      "y": 14,
      "z": -4,
      "name": "Plant_Coral_Block_Cyan"
    },
    {
      "x": -5,
      "y": 17,
      "z": -4,
      "name": "Plant_Coral_Block_Cyan"
    },
    {
      "x": -4,
      "y": 17,
      "z": -4,
      "name": "Plant_Coral_Block_Cyan"
    },
    {
      "x": -8,
      "y": 18,
      "z": -4,
      "name": "Plant_Crop_Mushroom_Block_Blue_Mycelium"
    },
    {
      "x": -9,
      "y": 19,
      "z": -4,
      "name": "Plant_Crop_Mushroom_Block_Blue_Mycelium"
    },
    {
      "x": -8,
      "y": 19,
      "z": -4,
      "name": "Plant_Coral_Block_Cyan"
    },
    {
      "x": -6,
      "y": 19,
      "z": -4,
      "name": "Plant_Coral_Block_Cyan"
    },
    {
      "x": -9,
      "y": 20,
      "z": -4,
      "name": "Plant_Coral_Block_Cyan"
    },
    {
      "x": -8,
      "y": 20,
      "z": -4,
      "name": "Plant_Coral_Block_Cyan"
    },
    {
      "x": -4,
      "y": 13,
      "z": -3,
      "name": "Plant_Coral_Block_Orange"
    },
    {
      "x": -5,
      "y": 16,
      "z": -3,
      "name": "Plant_Coral_Block_Cyan"
    },
    {
      "x": -5,
      "y": 17,
      "z": -3,
      "name": "Plant_Coral_Block_Cyan"
    },
    {
      "x": -8,
      "y": 19,
      "z": -3,
      "name": "Plant_Coral_Block_Orange"
    },
    {
      "x": -7,
      "y": 19,
      "z": -3,
      "name": "Plant_Coral_Block_Cyan"
    },
    {
      "x": -6,
      "y": 19,
      "z": -3,
      "name": "Plant_Coral_Block_Cyan"
    },
    {
      "x": -12,
      "y": 20,
      "z": -3,
      "name": "Plant_Crop_Mushroom_Block_Blue_Mycelium"
    },
    {
      "x": -11,
      "y": 20,
      "z": -3,
      "name": "Plant_Crop_Mushroom_Block_Blue_Mycelium"
    },
    {
      "x": -12,
      "y": 21,
      "z": -3,
      "name": "Plant_Coral_Block_Cyan"
    },
    {
      "x": -11,
      "y": 21,
      "z": -3,
      "name": "Plant_Coral_Block_Cyan"
    },
    {
      "x": -5,
      "y": 13,
      "z": -2,
      "name": "Plant_Coral_Block_Orange"
    },
    {
      "x": -4,
      "y": 13,
      "z": -2,
      "name": "Plant_Coral_Block_Orange"
    },
    {
      "x": -2,
      "y": 13,
      "z": -2,
      "name": "Plant_Coral_Block_Orange"
    },
    {
      "x": -1,
      "y": 13,
      "z": -2,
      "name": "Plant_Coral_Block_Orange"
    },
    {
      "x": -5,
      "y": 14,
      "z": -2,
      "name": "Plant_Coral_Block_Orange"
    },
    {
      "x": -6,
      "y": 15,
      "z": -2,
      "name": "Plant_Crop_Mushroom_Block_Blue_Mycelium"
    },
    {
      "x": -5,
      "y": 15,
      "z": -2,
      "name": "Plant_Crop_Mushroom_Block_Blue_Mycelium"
    },
    {
      "x": -6,
      "y": 16,
      "z": -2,
      "name": "Plant_Coral_Block_Cyan"
    },
    {
      "x": -5,
      "y": 16,
      "z": -2,
      "name": "Plant_Coral_Block_Cyan"
    },
    {
      "x": -7,
      "y": 17,
      "z": -2,
      "name": "Plant_Coral_Block_Orange"
    },
    {
      "x": -10,
      "y": 18,
      "z": -2,
      "name": "Plant_Crop_Mushroom_Block_Blue_Mycelium"
    },
    {
      "x": -7,
      "y": 18,
      "z": -2,
      "name": "Plant_Coral_Block_Orange"
    },
    {
      "x": -10,
      "y": 19,
      "z": -2,
      "name": "Plant_Coral_Block_Cyan"
    },
    {
      "x": -9,
      "y": 19,
      "z": -2,
      "name": "Rock_Crystal_Cyan_Block"
    },
    {
      "x": -8,
      "y": 19,
      "z": -2,
      "name": "Plant_Coral_Block_Orange"
    },
    {
      "x": -7,
      "y": 19,
      "z": -2,
      "name": "Plant_Coral_Block_Orange"
    },
    {
      "x": -11,
      "y": 20,
      "z": -2,
      "name": "Plant_Coral_Block_Cyan"
    },
    {
      "x": -10,
      "y": 20,
      "z": -2,
      "name": "Plant_Coral_Block_Cyan"
    },
    {
      "x": -11,
      "y": 21,
      "z": -2,
      "name": "Plant_Coral_Block_Cyan"
    },
    {
      "x": -1,
      "y": 13,
      "z": -1,
      "name": "Plant_Coral_Block_Orange"
    },
    {
      "x": -5,
      "y": 14,
      "z": -1,
      "name": "Plant_Coral_Block_Orange"
    },
    {
      "x": -6,
      "y": 15,
      "z": -1,
      "name": "Plant_Coral_Block_Orange"
    },
    {
      "x": -5,
      "y": 15,
      "z": -1,
      "name": "Plant_Coral_Block_Orange"
    },
    {
      "x": -8,
      "y": 16,
      "z": -1,
      "name": "Plant_Crop_Mushroom_Block_Blue_Mycelium"
    },
    {
      "x": -6,
      "y": 16,
      "z": -1,
      "name": "Plant_Coral_Block_Orange"
    },
    {
      "x": -8,
      "y": 17,
      "z": -1,
      "name": "Plant_Coral_Block_Cyan"
    },
    {
      "x": -7,
      "y": 17,
      "z": -1,
      "name": "Plant_Coral_Block_Orange"
    },
    {
      "x": -6,
      "y": 17,
      "z": -1,
      "name": "Plant_Coral_Block_Orange"
    },
    {
      "x": -1,
      "y": 12,
      "z": -15,
      "name": "Plant_Crop_Mushroom_Block_Blue_Mycelium"
    },
    {
      "x": -1,
      "y": 11,
      "z": -14,
      "name": "Plant_Crop_Mushroom_Block_Blue_Mycelium"
    },
    {
      "x": -5,
      "y": 12,
      "z": -14,
      "name": "Plant_Crop_Mushroom_Block_Blue_Mycelium"
    },
    {
      "x": -1,
      "y": 12,
      "z": -14,
      "name": "Plant_Coral_Block_Cyan"
    },
    {
      "x": -5,
      "y": 11,
      "z": -13,
      "name": "Plant_Crop_Mushroom_Block_Blue_Mycelium"
    },
    {
      "x": -5,
      "y": 12,
      "z": -13,
      "name": "Plant_Crop_Mushroom_Block_Blue"
    },
    {
      "x": -1,
      "y": 12,
      "z": -13,
      "name": "Plant_Coral_Block_Cyan"
    },
    {
      "x": -5,
      "y": 11,
      "z": -12,
      "name": "Plant_Crop_Mushroom_Block_Blue_Mycelium"
    },
    {
      "x": -5,
      "y": 12,
      "z": -12,
      "name": "Plant_Crop_Mushroom_Block_Blue"
    },
    {
      "x": -3,
      "y": 12,
      "z": -12,
      "name": "Plant_Crop_Mushroom_Block_Blue_Mycelium"
    },
    {
      "x": -1,
      "y": 12,
      "z": -12,
      "name": "Plant_Coral_Block_Orange"
    },
    {
      "x": -8,
      "y": 10,
      "z": -11,
      "name": "Plant_Crop_Mushroom_Block_Blue_Mycelium"
    },
    {
      "x": -7,
      "y": 10,
      "z": -11,
      "name": "Plant_Crop_Mushroom_Block_Blue_Mycelium"
    },
    {
      "x": -4,
      "y": 10,
      "z": -11,
      "name": "Plant_Crop_Mushroom_Block_Blue_Mycelium"
    },
    {
      "x": -8,
      "y": 11,
      "z": -11,
      "name": "Plant_Coral_Block_Cyan"
    },
    {
      "x": -7,
      "y": 11,
      "z": -11,
      "name": "Plant_Coral_Block_Cyan"
    },
    {
      "x": -4,
      "y": 11,
      "z": -11,
      "name": "Plant_Crop_Mushroom_Block_Blue"
    },
    {
      "x": -2,
      "y": 11,
      "z": -11,
      "name": "Plant_Crop_Mushroom_Block_Blue_Mycelium"
    },
    {
      "x": -5,
      "y": 12,
      "z": -11,
      "name": "Plant_Crop_Mushroom_Block_Blue"
    },
    {
      "x": -4,
      "y": 12,
      "z": -11,
      "name": "Plant_Coral_Block_Cyan"
    },
    {
      "x": -2,
      "y": 12,
      "z": -11,
      "name": "Plant_Coral_Block_Cyan"
    },
    {
      "x": -1,
      "y": 12,
      "z": -11,
      "name": "Plant_Coral_Block_Orange"
    },
    {
      "x": -9,
      "y": 7,
      "z": -10,
      "name": "Plant_Crop_Mushroom_Block_Blue_Mycelium"
    },
    {
      "x": -9,
      "y": 8,
      "z": -10,
      "name": "Plant_Coral_Block_Cyan"
    },
    {
      "x": -7,
      "y": 10,
      "z": -10,
      "name": "Plant_Crop_Mushroom_Block_Blue_Mycelium"
    },
    {
      "x": -6,
      "y": 10,
      "z": -10,
      "name": "Plant_Crop_Mushroom_Block_Blue_Mycelium"
    },
    {
      "x": -4,
      "y": 10,
      "z": -10,
      "name": "Plant_Crop_Mushroom_Block_Blue_Mycelium"
    },
    {
      "x": -3,
      "y": 10,
      "z": -10,
      "name": "Plant_Crop_Mushroom_Block_Blue_Mycelium"
    },
    {
      "x": -7,
      "y": 11,
      "z": -10,
      "name": "Plant_Coral_Block_Cyan"
    },
    {
      "x": -6,
      "y": 11,
      "z": -10,
      "name": "Plant_Coral_Block_Cyan"
    },
    {
      "x": -4,
      "y": 11,
      "z": -10,
      "name": "Plant_Crop_Mushroom_Block_Blue"
    },
    {
      "x": -3,
      "y": 11,
      "z": -10,
      "name": "Plant_Crop_Mushroom_Block_Blue"
    },
    {
      "x": -2,
      "y": 11,
      "z": -10,
      "name": "Plant_Coral_Block_Orange"
    },
    {
      "x": -2,
      "y": 12,
      "z": -10,
      "name": "Plant_Coral_Block_Orange"
    },
    {
      "x": -1,
      "y": 12,
      "z": -10,
      "name": "Plant_Coral_Block_Orange"
    },
    {
      "x": -9,
      "y": 7,
      "z": -9,
      "name": "Plant_Crop_Mushroom_Block_Blue_Mycelium"
    },
    {
      "x": -8,
      "y": 7,
      "z": -9,
      "name": "Plant_Crop_Mushroom_Block_Blue_Mycelium"
    },
    {
      "x": -11,
      "y": 8,
      "z": -9,
      "name": "Plant_Crop_Mushroom_Block_Blue_Mycelium"
    },
    {
      "x": -9,
      "y": 8,
      "z": -9,
      "name": "Plant_Coral_Block_Cyan"
    },
    {
      "x": -8,
      "y": 8,
      "z": -9,
      "name": "Plant_Crop_Mushroom_Block_Blue"
    },
    {
      "x": -11,
      "y": 9,
      "z": -9,
      "name": "Rock_Crystal_Cyan_Block"
    },
    {
      "x": -6,
      "y": 9,
      "z": -9,
      "name": "Plant_Crop_Mushroom_Block_Blue_Mycelium"
    },
    {
      "x": -5,
      "y": 9,
      "z": -9,
      "name": "Plant_Crop_Mushroom_Block_Blue_Mycelium"
    },
    {
      "x": -6,
      "y": 10,
      "z": -9,
      "name": "Rock_Crystal_Cyan_Block"
    },
    {
      "x": -5,
      "y": 10,
      "z": -9,
      "name": "Plant_Coral_Block_Cyan"
    },
    {
      "x": -1,
      "y": 10,
      "z": -9,
      "name": "Plant_Crop_Mushroom_Block_Blue_Mycelium"
    },
    {
      "x": -6,
      "y": 11,
      "z": -9,
      "name": "Plant_Coral_Block_Cyan"
    },
    {
      "x": -4,
      "y": 11,
      "z": -9,
      "name": "Plant_Coral_Block_Orange"
    },
    {
      "x": -3,
      "y": 11,
      "z": -9,
      "name": "Plant_Coral_Block_Orange"
    },
    {
      "x": -2,
      "y": 11,
      "z": -9,
      "name": "Plant_Coral_Block_Orange"
    },
    {
      "x": -1,
      "y": 11,
      "z": -9,
      "name": "Plant_Coral_Block_Cyan"
    },
    {
      "x": -11,
      "y": 8,
      "z": -8,
      "name": "Plant_Crop_Mushroom_Block_Blue_Mycelium"
    },
    {
      "x": -8,
      "y": 8,
      "z": -8,
      "name": "Plant_Crop_Mushroom_Block_Blue"
    },
    {
      "x": -7,
      "y": 8,
      "z": -8,
      "name": "Plant_Crop_Mushroom_Block_Blue_Mycelium"
    },
    {
      "x": -11,
      "y": 9,
      "z": -8,
      "name": "Rock_Crystal_Cyan_Block"
    },
    {
      "x": -8,
      "y": 9,
      "z": -8,
      "name": "Plant_Coral_Block_Cyan"
    },
    {
      "x": -7,
      "y": 9,
      "z": -8,
      "name": "Plant_Coral_Block_Cyan"
    },
    {
      "x": -5,
      "y": 10,
      "z": -8,
      "name": "Plant_Coral_Block_Orange"
    },
    {
      "x": -4,
      "y": 10,
      "z": -8,
      "name": "Plant_Coral_Block_Orange"
    },
    {
      "x": -4,
      "y": 11,
      "z": -8,
      "name": "Plant_Coral_Block_Orange"
    },
    {
      "x": -10,
      "y": 8,
      "z": -7,
      "name": "Plant_Crop_Mushroom_Block_Blue_Mycelium"
    },
    {
      "x": -7,
      "y": 8,
      "z": -7,
      "name": "Plant_Crop_Mushroom_Block_Blue_Mycelium"
    },
    {
      "x": -11,
      "y": 9,
      "z": -7,
      "name": "Plant_Coral_Block_Cyan"
    },
    {
      "x": -10,
      "y": 9,
      "z": -7,
      "name": "Plant_Coral_Block_Cyan"
    },
    {
      "x": -9,
      "y": 9,
      "z": -7,
      "name": "Plant_Crop_Mushroom_Block_Blue_Mycelium"
    },
    {
      "x": -7,
      "y": 9,
      "z": -7,
      "name": "Plant_Crop_Mushroom_Block_Blue"
    },
    {
      "x": -4,
      "y": 9,
      "z": -7,
      "name": "Plant_Crop_Mushroom_Block_Blue_Mycelium"
    },
    {
      "x": -2,
      "y": 9,
      "z": -7,
      "name": "Plant_Crop_Mushroom_Block_Blue_Mycelium"
    },
    {
      "x": -10,
      "y": 10,
      "z": -7,
      "name": "Plant_Coral_Block_Cyan"
    },
    {
      "x": -9,
      "y": 10,
      "z": -7,
      "name": "Plant_Coral_Block_Cyan"
    },
    {
      "x": -6,
      "y": 10,
      "z": -7,
      "name": "Plant_Coral_Block_Orange"
    },
    {
      "x": -5,
      "y": 10,
      "z": -7,
      "name": "Plant_Coral_Block_Orange"
    },
    {
      "x": -4,
      "y": 10,
      "z": -7,
      "name": "Rock_Crystal_Cyan_Block"
    },
    {
      "x": -3,
      "y": 10,
      "z": -7,
      "name": "Rock_Crystal_Cyan_Block"
    },
    {
      "x": -2,
      "y": 10,
      "z": -7,
      "name": "Plant_Coral_Block_Cyan"
    },
    {
      "x": -13,
      "y": 11,
      "z": -7,
      "name": "Plant_Coral_Block_Cyan"
    },
    {
      "x": -12,
      "y": 11,
      "z": -7,
      "name": "Plant_Coral_Block_Cyan"
    },
    {
      "x": -2,
      "y": 11,
      "z": -7,
      "name": "Plant_Coral_Block_Cyan"
    },
    {
      "x": -13,
      "y": 12,
      "z": -7,
      "name": "Plant_Coral_Block_Cyan"
    },
    {
      "x": -8,
      "y": 9,
      "z": -6,
      "name": "Plant_Coral_Block_Orange"
    },
    {
      "x": -7,
      "y": 9,
      "z": -6,
      "name": "Plant_Coral_Block_Orange"
    },
    {
      "x": -6,
      "y": 9,
      "z": -6,
      "name": "Plant_Coral_Block_Orange"
    },
    {
      "x": -5,
      "y": 9,
      "z": -6,
      "name": "Plant_Coral_Block_Orange"
    },
    {
      "x": -9,
      "y": 10,
      "z": -6,
      "name": "Plant_Coral_Block_Orange"
    },
    {
      "x": -8,
      "y": 10,
      "z": -6,
      "name": "Plant_Coral_Block_Orange"
    },
    {
      "x": -5,
      "y": 10,
      "z": -6,
      "name": "Plant_Coral_Block_Orange"
    },
    {
      "x": -2,
      "y": 10,
      "z": -6,
      "name": "Plant_Crop_Mushroom_Block_Blue_Mycelium"
    },
    {
      "x": -1,
      "y": 10,
      "z": -6,
      "name": "Plant_Crop_Mushroom_Block_Blue_Mycelium"
    },
    {
      "x": -12,
      "y": 11,
      "z": -6,
      "name": "Plant_Crop_Mushroom_Block_Blue"
    },
    {
      "x": -11,
      "y": 11,
      "z": -6,
      "name": "Plant_Coral_Block_Cyan"
    },
    {
      "x": -2,
      "y": 11,
      "z": -6,
      "name": "Plant_Coral_Block_Cyan"
    },
    {
      "x": -1,
      "y": 11,
      "z": -6,
      "name": "Plant_Coral_Block_Cyan"
    },
    {
      "x": -7,
      "y": 8,
      "z": -5,
      "name": "Plant_Crop_Mushroom_Block_Blue_Mycelium"
    },
    {
      "x": -5,
      "y": 8,
      "z": -5,
      "name": "Plant_Coral_Block_Orange"
    },
    {
      "x": -4,
      "y": 8,
      "z": -5,
      "name": "Plant_Coral_Block_Orange"
    },
    {
      "x": -7,
      "y": 9,
      "z": -5,
      "name": "Plant_Coral_Block_Cyan"
    },
    {
      "x": -5,
      "y": 9,
      "z": -5,
      "name": "Plant_Coral_Block_Orange"
    },
    {
      "x": -4,
      "y": 9,
      "z": -5,
      "name": "Plant_Coral_Block_Orange"
    },
    {
      "x": -11,
      "y": 10,
      "z": -5,
      "name": "Plant_Crop_Mushroom_Block_Blue_Mycelium"
    },
    {
      "x": -10,
      "y": 10,
      "z": -5,
      "name": "Plant_Coral_Block_Orange"
    },
    {
      "x": -9,
      "y": 10,
      "z": -5,
      "name": "Plant_Coral_Block_Orange"
    },
    {
      "x": -16,
      "y": 11,
      "z": -5,
      "name": "Plant_Crop_Mushroom_Block_Blue_Mycelium"
    },
    {
      "x": -11,
      "y": 11,
      "z": -5,
      "name": "Plant_Coral_Block_Cyan"
    },
    {
      "x": -16,
      "y": 12,
      "z": -5,
      "name": "Plant_Coral_Block_Cyan"
    },
    {
      "x": -15,
      "y": 12,
      "z": -5,
      "name": "Plant_Coral_Block_Cyan"
    },
    {
      "x": -2,
      "y": 2,
      "z": -4,
      "name": "Plant_Coral_Block_Orange"
    },
    {
      "x": -1,
      "y": 3,
      "z": -4,
      "name": "Plant_Coral_Block_Orange"
    },
    {
      "x": -4,
      "y": 5,
      "z": -4,
      "name": "Plant_Coral_Block_Orange"
    },
    {
      "x": -3,
      "y": 5,
      "z": -4,
      "name": "Plant_Coral_Block_Orange"
    },
    {
      "x": -4,
      "y": 6,
      "z": -4,
      "name": "Plant_Coral_Block_Orange"
    },
    {
      "x": -3,
      "y": 6,
      "z": -4,
      "name": "Plant_Coral_Block_Orange"
    },
    {
      "x": -4,
      "y": 7,
      "z": -4,
      "name": "Plant_Coral_Block_Orange"
    },
    {
      "x": -3,
      "y": 7,
      "z": -4,
      "name": "Plant_Coral_Block_Orange"
    },
    {
      "x": -7,
      "y": 8,
      "z": -4,
      "name": "Plant_Crop_Mushroom_Block_Blue_Mycelium"
    },
    {
      "x": -4,
      "y": 8,
      "z": -4,
      "name": "Plant_Coral_Block_Orange"
    },
    {
      "x": -3,
      "y": 8,
      "z": -4,
      "name": "Plant_Coral_Block_Orange"
    },
    {
      "x": -7,
      "y": 9,
      "z": -4,
      "name": "Plant_Coral_Block_Cyan"
    },
    {
      "x": -4,
      "y": 9,
      "z": -4,
      "name": "Plant_Coral_Block_Orange"
    },
    {
      "x": -13,
      "y": 10,
      "z": -4,
      "name": "Plant_Crop_Mushroom_Block_Blue_Mycelium"
    },
    {
      "x": -10,
      "y": 10,
      "z": -4,
      "name": "Plant_Coral_Block_Orange"
    },
    {
      "x": -4,
      "y": 10,
      "z": -4,
      "name": "Plant_Coral_Block_Orange"
    },
    {
      "x": -14,
      "y": 11,
      "z": -4,
      "name": "Plant_Crop_Mushroom_Block_Blue_Mycelium"
    },
    {
      "x": -13,
      "y": 11,
      "z": -4,
      "name": "Plant_Crop_Mushroom_Block_Blue"
    },
    {
      "x": -12,
      "y": 11,
      "z": -4,
      "name": "Plant_Coral_Block_Orange"
    },
    {
      "x": -11,
      "y": 11,
      "z": -4,
      "name": "Plant_Coral_Block_Orange"
    },
    {
      "x": -10,
      "y": 11,
      "z": -4,
      "name": "Plant_Coral_Block_Orange"
    },
    {
      "x": -15,
      "y": 12,
      "z": -4,
      "name": "Plant_Coral_Block_Cyan"
    },
    {
      "x": -14,
      "y": 12,
      "z": -4,
      "name": "Plant_Coral_Block_Cyan"
    },
    {
      "x": -13,
      "y": 12,
      "z": -4,
      "name": "Plant_Coral_Block_Cyan"
    },
    {
      "x": -2,
      "y": 12,
      "z": -4,
      "name": "Plant_Coral_Block_Orange"
    },
    {
      "x": -3,
      "y": 0,
      "z": -3,
      "name": "Plant_Coral_Block_Orange"
    },
    {
      "x": -3,
      "y": 1,
      "z": -3,
      "name": "Plant_Coral_Block_Orange"
    },
    {
      "x": -2,
      "y": 1,
      "z": -3,
      "name": "Plant_Coral_Block_Orange"
    },
    {
      "x": -3,
      "y": 2,
      "z": -3,
      "name": "Plant_Coral_Block_Orange"
    },
    {
      "x": -2,
      "y": 2,
      "z": -3,
      "name": "Plant_Coral_Block_Orange"
    },
    {
      "x": -1,
      "y": 2,
      "z": -3,
      "name": "Plant_Coral_Block_Orange"
    },
    {
      "x": -3,
      "y": 3,
      "z": -3,
      "name": "Plant_Coral_Block_Orange"
    },
    {
      "x": -2,
      "y": 3,
      "z": -3,
      "name": "Plant_Coral_Block_Orange"
    },
    {
      "x": -1,
      "y": 3,
      "z": -3,
      "name": "Plant_Coral_Block_Orange"
    },
    {
      "x": -3,
      "y": 4,
      "z": -3,
      "name": "Plant_Coral_Block_Orange"
    },
    {
      "x": -2,
      "y": 4,
      "z": -3,
      "name": "Plant_Coral_Block_Orange"
    },
    {
      "x": -3,
      "y": 5,
      "z": -3,
      "name": "Plant_Coral_Block_Orange"
    },
    {
      "x": -2,
      "y": 5,
      "z": -3,
      "name": "Plant_Coral_Block_Orange"
    },
    {
      "x": -7,
      "y": 8,
      "z": -3,
      "name": "Plant_Crop_Mushroom_Block_Blue_Mycelium"
    },
    {
      "x": -10,
      "y": 9,
      "z": -3,
      "name": "Plant_Crop_Mushroom_Block_Blue_Mycelium"
    },
    {
      "x": -7,
      "y": 9,
      "z": -3,
      "name": "Plant_Coral_Block_Cyan"
    },
    {
      "x": -13,
      "y": 10,
      "z": -3,
      "name": "Plant_Crop_Mushroom_Block_Blue_Mycelium"
    },
    {
      "x": -12,
      "y": 10,
      "z": -3,
      "name": "Plant_Crop_Mushroom_Block_Blue_Mycelium"
    },
    {
      "x": -10,
      "y": 10,
      "z": -3,
      "name": "Plant_Coral_Block_Cyan"
    },
    {
      "x": -7,
      "y": 10,
      "z": -3,
      "name": "Plant_Crop_Mushroom_Block_Blue"
    },
    {
      "x": -4,
      "y": 10,
      "z": -3,
      "name": "Plant_Coral_Block_Orange"
    },
    {
      "x": -13,
      "y": 11,
      "z": -3,
      "name": "Plant_Crop_Mushroom_Block_Blue"
    },
    {
      "x": -12,
      "y": 11,
      "z": -3,
      "name": "Plant_Crop_Mushroom_Block_Blue"
    },
    {
      "x": -4,
      "y": 11,
      "z": -3,
      "name": "Plant_Coral_Block_Orange"
    },
    {
      "x": -3,
      "y": 11,
      "z": -3,
      "name": "Plant_Coral_Block_Orange"
    },
    {
      "x": -4,
      "y": 12,
      "z": -3,
      "name": "Plant_Coral_Block_Orange"
    },
    {
      "x": -3,
      "y": 12,
      "z": -3,
      "name": "Plant_Coral_Block_Orange"
    },
    {
      "x": -2,
      "y": 12,
      "z": -3,
      "name": "Plant_Coral_Block_Orange"
    },
    {
      "x": -3,
      "y": 0,
      "z": -2,
      "name": "Plant_Coral_Block_Orange"
    },
    {
      "x": -2,
      "y": 0,
      "z": -2,
      "name": "Plant_Coral_Block_Orange"
    },
    {
      "x": -3,
      "y": 1,
      "z": -2,
      "name": "Plant_Coral_Block_Orange"
    },
    {
      "x": -2,
      "y": 1,
      "z": -2,
      "name": "Plant_Coral_Block_Orange"
    },
    {
      "x": -3,
      "y": 2,
      "z": -2,
      "name": "Plant_Coral_Block_Orange"
    },
    {
      "x": -2,
      "y": 2,
      "z": -2,
      "name": "Plant_Coral_Block_Orange"
    },
    {
      "x": -10,
      "y": 9,
      "z": -2,
      "name": "Plant_Crop_Mushroom_Block_Blue_Mycelium"
    },
    {
      "x": -7,
      "y": 9,
      "z": -2,
      "name": "Plant_Crop_Mushroom_Block_Blue_Mycelium"
    },
    {
      "x": -10,
      "y": 10,
      "z": -2,
      "name": "Plant_Coral_Block_Cyan"
    },
    {
      "x": -8,
      "y": 10,
      "z": -2,
      "name": "Plant_Coral_Block_Cyan"
    },
    {
      "x": -7,
      "y": 10,
      "z": -2,
      "name": "Plant_Crop_Mushroom_Block_Blue"
    },
    {
      "x": -13,
      "y": 11,
      "z": -2,
      "name": "Plant_Crop_Mushroom_Block_Blue"
    },
    {
      "x": -10,
      "y": 11,
      "z": -2,
      "name": "Plant_Coral_Block_Cyan"
    },
    {
      "x": -14,
      "y": 12,
      "z": -2,
      "name": "Plant_Crop_Mushroom_Block_Blue"
    },
    {
      "x": -13,
      "y": 12,
      "z": -2,
      "name": "Plant_Crop_Mushroom_Block_Blue"
    },
    {
      "x": -2,
      "y": 12,
      "z": -2,
      "name": "Plant_Coral_Block_Orange"
    },
    {
      "x": -3,
      "y": 0,
      "z": -1,
      "name": "Plant_Coral_Block_Orange"
    },
    {
      "x": -3,
      "y": 1,
      "z": -1,
      "name": "Plant_Coral_Block_Orange"
    },
    {
      "x": -8,
      "y": 9,
      "z": -1,
      "name": "Plant_Crop_Mushroom_Block_Blue_Mycelium"
    },
    {
      "x": -11,
      "y": 10,
      "z": -1,
      "name": "Plant_Crop_Mushroom_Block_Blue_Mycelium"
    },
    {
      "x": -10,
      "y": 10,
      "z": -1,
      "name": "Plant_Crop_Mushroom_Block_Blue_Mycelium"
    },
    {
      "x": -8,
      "y": 10,
      "z": -1,
      "name": "Plant_Coral_Block_Cyan"
    },
    {
      "x": -14,
      "y": 11,
      "z": -1,
      "name": "Plant_Crop_Mushroom_Block_Blue_Mycelium"
    },
    {
      "x": -11,
      "y": 11,
      "z": -1,
      "name": "Plant_Crop_Mushroom_Block_Blue"
    },
    {
      "x": -10,
      "y": 11,
      "z": -1,
      "name": "Plant_Coral_Block_Cyan"
    },
    {
      "x": -14,
      "y": 12,
      "z": -1,
      "name": "Plant_Coral_Block_Cyan"
    },
    {
      "x": 0,
      "y": 13,
      "z": -17,
      "name": "Plant_Coral_Block_Cyan"
    },
    {
      "x": 0,
      "y": 12,
      "z": -17,
      "name": "Plant_Crop_Mushroom_Block_Blue_Mycelium"
    },
    {
      "x": 0,
      "y": 10,
      "z": 16,
      "name": "Plant_Crop_Mushroom_Block_Blue_Mycelium"
    },
    {
      "x": 0,
      "y": 11,
      "z": 16,
      "name": "Plant_Coral_Block_Cyan"
    },
    {
      "x": -1,
      "y": 4,
      "z": 0,
      "name": "Plant_Coral_Block_Cyan"
    },
    {
      "x": -8,
      "y": 9,
      "z": 0,
      "name": "Plant_Crop_Mushroom_Block_Blue_Mycelium"
    },
    {
      "x": -11,
      "y": 10,
      "z": 0,
      "name": "Plant_Crop_Mushroom_Block_Blue_Mycelium"
    },
    {
      "x": -8,
      "y": 10,
      "z": 0,
      "name": "Plant_Coral_Block_Cyan"
    },
    {
      "x": -14,
      "y": 11,
      "z": 0,
      "name": "Plant_Crop_Mushroom_Block_Blue_Mycelium"
    },
    {
      "x": -11,
      "y": 11,
      "z": 0,
      "name": "Plant_Coral_Block_Cyan"
    },
    {
      "x": -14,
      "y": 12,
      "z": 0,
      "name": "Plant_Coral_Block_Cyan"
    },
    {
      "x": -1,
      "y": 4,
      "z": 3,
      "name": "Plant_Crop_Mushroom_Block_Blue_Mycelium"
    },
    {
      "x": -1,
      "y": 5,
      "z": 3,
      "name": "Plant_Coral_Block_Cyan"
    },
    {
      "x": -4,
      "y": 5,
      "z": 5,
      "name": "Plant_Crop_Mushroom_Block_Blue_Mycelium"
    },
    {
      "x": -3,
      "y": 5,
      "z": 5,
      "name": "Plant_Crop_Mushroom_Block_Blue_Mycelium"
    },
    {
      "x": -4,
      "y": 6,
      "z": 5,
      "name": "Plant_Coral_Block_Cyan"
    },
    {
      "x": -3,
      "y": 6,
      "z": 5,
      "name": "Plant_Coral_Block_Cyan"
    },
    {
      "x": -2,
      "y": 6,
      "z": 5,
      "name": "Plant_Crop_Mushroom_Block_Blue_Mycelium"
    },
    {
      "x": -3,
      "y": 7,
      "z": 5,
      "name": "Rock_Crystal_Cyan_Block"
    },
    {
      "x": -2,
      "y": 7,
      "z": 5,
      "name": "Rock_Crystal_Cyan_Block"
    },
    {
      "x": -2,
      "y": 6,
      "z": 6,
      "name": "Plant_Crop_Mushroom_Block_Blue_Mycelium"
    },
    {
      "x": -1,
      "y": 6,
      "z": 6,
      "name": "Plant_Crop_Mushroom_Block_Blue_Mycelium"
    },
    {
      "x": -2,
      "y": 7,
      "z": 6,
      "name": "Plant_Coral_Block_Cyan"
    },
    {
      "x": -1,
      "y": 7,
      "z": 6,
      "name": "Plant_Coral_Block_Cyan"
    },
    {
      "x": -1,
      "y": 8,
      "z": 6,
      "name": "Plant_Coral_Block_Cyan"
    },
    {
      "x": -5,
      "y": 7,
      "z": 8,
      "name": "Plant_Crop_Mushroom_Block_Blue_Mycelium"
    },
    {
      "x": -4,
      "y": 7,
      "z": 8,
      "name": "Plant_Crop_Mushroom_Block_Blue_Mycelium"
    },
    {
      "x": -3,
      "y": 7,
      "z": 8,
      "name": "Plant_Crop_Mushroom_Block_Blue_Mycelium"
    },
    {
      "x": -5,
      "y": 8,
      "z": 8,
      "name": "Plant_Coral_Block_Cyan"
    },
    {
      "x": -4,
      "y": 8,
      "z": 8,
      "name": "Plant_Coral_Block_Cyan"
    },
    {
      "x": -3,
      "y": 8,
      "z": 8,
      "name": "Plant_Crop_Mushroom_Block_Blue"
    },
    {
      "x": -2,
      "y": 8,
      "z": 8,
      "name": "Plant_Crop_Mushroom_Block_Blue_Mycelium"
    },
    {
      "x": -3,
      "y": 9,
      "z": 8,
      "name": "Plant_Coral_Block_Cyan"
    },
    {
      "x": -2,
      "y": 9,
      "z": 8,
      "name": "Plant_Crop_Mushroom_Block_Blue"
    },
    {
      "x": -1,
      "y": 9,
      "z": 8,
      "name": "Plant_Coral_Block_Orange"
    },
    {
      "x": -1,
      "y": 9,
      "z": 9,
      "name": "Plant_Coral_Block_Orange"
    },
    {
      "x": -4,
      "y": 8,
      "z": 10,
      "name": "Plant_Crop_Mushroom_Block_Blue_Mycelium"
    },
    {
      "x": -3,
      "y": 8,
      "z": 10,
      "name": "Plant_Crop_Mushroom_Block_Blue_Mycelium"
    },
    {
      "x": -2,
      "y": 8,
      "z": 10,
      "name": "Plant_Crop_Mushroom_Block_Blue_Mycelium"
    },
    {
      "x": -4,
      "y": 9,
      "z": 10,
      "name": "Plant_Coral_Block_Cyan"
    },
    {
      "x": -3,
      "y": 9,
      "z": 10,
      "name": "Plant_Coral_Block_Cyan"
    },
    {
      "x": -2,
      "y": 9,
      "z": 10,
      "name": "Plant_Crop_Mushroom_Block_Blue"
    },
    {
      "x": -1,
      "y": 9,
      "z": 10,
      "name": "Plant_Coral_Block_Orange"
    },
    {
      "x": -1,
      "y": 10,
      "z": 10,
      "name": "Plant_Coral_Block_Orange"
    },
    {
      "x": -5,
      "y": 7,
      "z": 11,
      "name": "Plant_Crop_Mushroom_Block_Blue_Mycelium"
    },
    {
      "x": -4,
      "y": 7,
      "z": 11,
      "name": "Plant_Crop_Mushroom_Block_Blue_Mycelium"
    },
    {
      "x": -5,
      "y": 8,
      "z": 11,
      "name": "Plant_Coral_Block_Cyan"
    },
    {
      "x": -4,
      "y": 8,
      "z": 11,
      "name": "Plant_Coral_Block_Cyan"
    },
    {
      "x": -4,
      "y": 9,
      "z": 11,
      "name": "Plant_Crop_Mushroom_Block_Blue"
    },
    {
      "x": -1,
      "y": 10,
      "z": 11,
      "name": "Plant_Coral_Block_Orange"
    },
    {
      "x": -3,
      "y": 9,
      "z": 12,
      "name": "Plant_Crop_Mushroom_Block_Blue_Mycelium"
    },
    {
      "x": -2,
      "y": 9,
      "z": 12,
      "name": "Plant_Crop_Mushroom_Block_Blue_Mycelium"
    },
    {
      "x": -3,
      "y": 10,
      "z": 12,
      "name": "Plant_Crop_Mushroom_Block_Blue"
    },
    {
      "x": -2,
      "y": 10,
      "z": 12,
      "name": "Plant_Coral_Block_Cyan"
    },
    {
      "x": -1,
      "y": 10,
      "z": 12,
      "name": "Plant_Coral_Block_Orange"
    },
    {
      "x": -4,
      "y": 9,
      "z": 13,
      "name": "Plant_Crop_Mushroom_Block_Blue_Mycelium"
    },
    {
      "x": -3,
      "y": 9,
      "z": 13,
      "name": "Plant_Crop_Mushroom_Block_Blue_Mycelium"
    },
    {
      "x": -1,
      "y": 9,
      "z": 13,
      "name": "Plant_Crop_Mushroom_Block_Blue_Mycelium"
    },
    {
      "x": -5,
      "y": 10,
      "z": 13,
      "name": "Plant_Coral_Block_Cyan"
    },
    {
      "x": -4,
      "y": 10,
      "z": 13,
      "name": "Plant_Crop_Mushroom_Block_Blue"
    },
    {
      "x": -3,
      "y": 10,
      "z": 13,
      "name": "Plant_Crop_Mushroom_Block_Blue"
    },
    {
      "x": -1,
      "y": 10,
      "z": 13,
      "name": "Plant_Coral_Block_Cyan"
    },
    {
      "x": -1,
      "y": 11,
      "z": 13,
      "name": "Plant_Coral_Block_Cyan"
    },
    {
      "x": -1,
      "y": 11,
      "z": 14,
      "name": "Plant_Coral_Block_Cyan"
    },
    {
      "x": 0,
      "y": 3,
      "z": 0,
      "name": "Plant_Crop_Mushroom_Block_Blue_Mycelium"
    },
    {
      "x": 0,
      "y": 4,
      "z": 0,
      "name": "Plant_Coral_Block_Cyan"
    },
    {
      "x": 2,
      "y": 4,
      "z": 0,
      "name": "Plant_Coral_Block_Orange"
    },
    {
      "x": 2,
      "y": 5,
      "z": 0,
      "name": "Plant_Coral_Block_Orange"
    },
    {
      "x": 3,
      "y": 5,
      "z": 0,
      "name": "Plant_Coral_Block_Orange"
    },
    {
      "x": 4,
      "y": 5,
      "z": 0,
      "name": "Plant_Coral_Block_Orange"
    },
    {
      "x": 6,
      "y": 6,
      "z": 0,
      "name": "Plant_Coral_Block_Cyan"
    },
    {
      "x": 6,
      "y": 7,
      "z": 0,
      "name": "Plant_Coral_Block_Cyan"
    },
    {
      "x": 7,
      "y": 7,
      "z": 0,
      "name": "Plant_Coral_Block_Cyan"
    },
    {
      "x": 0,
      "y": 3,
      "z": 1,
      "name": "Plant_Crop_Mushroom_Block_Blue_Mycelium"
    },
    {
      "x": 1,
      "y": 3,
      "z": 1,
      "name": "Plant_Crop_Mushroom_Block_Blue_Mycelium"
    },
    {
      "x": 0,
      "y": 4,
      "z": 1,
      "name": "Plant_Coral_Block_Cyan"
    },
    {
      "x": 1,
      "y": 4,
      "z": 1,
      "name": "Rock_Crystal_Cyan_Block"
    },
    {
      "x": 9,
      "y": 4,
      "z": 1,
      "name": "Plant_Crop_Mushroom_Block_Blue_Mycelium"
    },
    {
      "x": 1,
      "y": 5,
      "z": 1,
      "name": "Plant_Coral_Block_Cyan"
    },
    {
      "x": 3,
      "y": 5,
      "z": 1,
      "name": "Plant_Coral_Block_Orange"
    },
    {
      "x": 4,
      "y": 5,
      "z": 1,
      "name": "Plant_Coral_Block_Orange"
    },
    {
      "x": 9,
      "y": 5,
      "z": 1,
      "name": "Plant_Coral_Block_Cyan"
    },
    {
      "x": 7,
      "y": 6,
      "z": 1,
      "name": "Plant_Crop_Mushroom_Block_Blue_Mycelium"
    },
    {
      "x": 7,
      "y": 7,
      "z": 1,
      "name": "Plant_Coral_Block_Cyan"
    },
    {
      "x": 7,
      "y": 8,
      "z": 1,
      "name": "Plant_Crop_Mushroom_Block_Blue"
    },
    {
      "x": 1,
      "y": 4,
      "z": 2,
      "name": "Plant_Crop_Mushroom_Block_Blue_Mycelium"
    },
    {
      "x": 2,
      "y": 4,
      "z": 2,
      "name": "Plant_Crop_Mushroom_Block_Blue_Mycelium"
    },
    {
      "x": 8,
      "y": 4,
      "z": 2,
      "name": "Plant_Crop_Mushroom_Block_Blue_Mycelium"
    },
    {
      "x": 9,
      "y": 4,
      "z": 2,
      "name": "Plant_Crop_Mushroom_Block_Blue_Mycelium"
    },
    {
      "x": 1,
      "y": 5,
      "z": 2,
      "name": "Plant_Coral_Block_Cyan"
    },
    {
      "x": 2,
      "y": 5,
      "z": 2,
      "name": "Plant_Coral_Block_Cyan"
    },
    {
      "x": 3,
      "y": 5,
      "z": 2,
      "name": "Plant_Coral_Block_Orange"
    },
    {
      "x": 4,
      "y": 5,
      "z": 2,
      "name": "Plant_Coral_Block_Orange"
    },
    {
      "x": 7,
      "y": 5,
      "z": 2,
      "name": "Plant_Crop_Mushroom_Block_Blue"
    },
    {
      "x": 8,
      "y": 5,
      "z": 2,
      "name": "Plant_Crop_Mushroom_Block_Blue"
    },
    {
      "x": 9,
      "y": 5,
      "z": 2,
      "name": "Plant_Crop_Mushroom_Block_Blue"
    },
    {
      "x": 11,
      "y": 5,
      "z": 2,
      "name": "Plant_Crop_Mushroom_Block_Blue_Mycelium"
    },
    {
      "x": 12,
      "y": 5,
      "z": 2,
      "name": "Plant_Crop_Mushroom_Block_Blue_Mycelium"
    },
    {
      "x": 11,
      "y": 6,
      "z": 2,
      "name": "Plant_Crop_Mushroom_Block_Blue"
    },
    {
      "x": 12,
      "y": 6,
      "z": 2,
      "name": "Plant_Crop_Mushroom_Block_Blue"
    },
    {
      "x": 0,
      "y": 4,
      "z": 3,
      "name": "Plant_Crop_Mushroom_Block_Blue_Mycelium"
    },
    {
      "x": 0,
      "y": 5,
      "z": 3,
      "name": "Plant_Coral_Block_Cyan"
    },
    {
      "x": 3,
      "y": 5,
      "z": 3,
      "name": "Plant_Coral_Block_Orange"
    },
    {
      "x": 6,
      "y": 5,
      "z": 3,
      "name": "Plant_Crop_Mushroom_Block_Blue_Mycelium"
    },
    {
      "x": 7,
      "y": 5,
      "z": 3,
      "name": "Plant_Crop_Mushroom_Block_Blue"
    },
    {
      "x": 10,
      "y": 5,
      "z": 3,
      "name": "Plant_Crop_Mushroom_Block_Blue_Mycelium"
    },
    {
      "x": 0,
      "y": 6,
      "z": 3,
      "name": "Plant_Coral_Block_Cyan"
    },
    {
      "x": 3,
      "y": 6,
      "z": 3,
      "name": "Plant_Coral_Block_Orange"
    },
    {
      "x": 4,
      "y": 6,
      "z": 3,
      "name": "Plant_Coral_Block_Orange"
    },
    {
      "x": 6,
      "y": 6,
      "z": 3,
      "name": "Plant_Coral_Block_Cyan"
    },
    {
      "x": 7,
      "y": 6,
      "z": 3,
      "name": "Plant_Crop_Mushroom_Block_Blue"
    },
    {
      "x": 10,
      "y": 6,
      "z": 3,
      "name": "Plant_Coral_Block_Cyan"
    },
    {
      "x": 11,
      "y": 6,
      "z": 3,
      "name": "Plant_Crop_Mushroom_Block_Blue"
    },
    {
      "x": 13,
      "y": 7,
      "z": 3,
      "name": "Plant_Crop_Mushroom_Block_Blue_Mycelium"
    },
    {
      "x": 14,
      "y": 7,
      "z": 3,
      "name": "Plant_Crop_Mushroom_Block_Blue_Mycelium"
    },
    {
      "x": 13,
      "y": 8,
      "z": 3,
      "name": "Plant_Crop_Mushroom_Block_Blue"
    },
    {
      "x": 14,
      "y": 8,
      "z": 3,
      "name": "Plant_Crop_Mushroom_Block_Blue"
    },
    {
      "x": 15,
      "y": 8,
      "z": 3,
      "name": "Plant_Crop_Mushroom_Block_Blue_Mycelium"
    },
    {
      "x": 14,
      "y": 9,
      "z": 3,
      "name": "Plant_Crop_Mushroom_Block_Blue"
    },
    {
      "x": 15,
      "y": 9,
      "z": 3,
      "name": "Plant_Coral_Block_Cyan"
    },
    {
      "x": 1,
      "y": 12,
      "z": 3,
      "name": "Plant_Crop_Mushroom_Block_Blue_Mycelium"
    },
    {
      "x": 0,
      "y": 5,
      "z": 4,
      "name": "Plant_Crop_Mushroom_Block_Blue_Mycelium"
    },
    {
      "x": 1,
      "y": 5,
      "z": 4,
      "name": "Plant_Crop_Mushroom_Block_Blue_Mycelium"
    },
    {
      "x": 6,
      "y": 5,
      "z": 4,
      "name": "Plant_Crop_Mushroom_Block_Blue_Mycelium"
    },
    {
      "x": 10,
      "y": 5,
      "z": 4,
      "name": "Plant_Crop_Mushroom_Block_Blue_Mycelium"
    },
    {
      "x": 0,
      "y": 6,
      "z": 4,
      "name": "Plant_Crop_Mushroom_Block_Blue"
    },
    {
      "x": 1,
      "y": 6,
      "z": 4,
      "name": "Plant_Crop_Mushroom_Block_Blue"
    },
    {
      "x": 3,
      "y": 6,
      "z": 4,
      "name": "Plant_Coral_Block_Orange"
    },
    {
      "x": 4,
      "y": 6,
      "z": 4,
      "name": "Plant_Coral_Block_Orange"
    },
    {
      "x": 5,
      "y": 6,
      "z": 4,
      "name": "Plant_Coral_Block_Orange"
    },
    {
      "x": 6,
      "y": 6,
      "z": 4,
      "name": "Plant_Coral_Block_Cyan"
    },
    {
      "x": 10,
      "y": 6,
      "z": 4,
      "name": "Plant_Crop_Mushroom_Block_Blue"
    },
    {
      "x": 1,
      "y": 7,
      "z": 4,
      "name": "Plant_Coral_Block_Cyan"
    },
    {
      "x": 9,
      "y": 7,
      "z": 4,
      "name": "Plant_Crop_Mushroom_Block_Blue"
    },
    {
      "x": 10,
      "y": 7,
      "z": 4,
      "name": "Plant_Crop_Mushroom_Block_Blue"
    },
    {
      "x": 12,
      "y": 8,
      "z": 4,
      "name": "Plant_Crop_Mushroom_Block_Blue"
    },
    {
      "x": 13,
      "y": 8,
      "z": 4,
      "name": "Plant_Crop_Mushroom_Block_Blue"
    },
    {
      "x": 1,
      "y": 12,
      "z": 4,
      "name": "Plant_Crop_Mushroom_Block_Blue_Mycelium"
    },
    {
      "x": 1,
      "y": 6,
      "z": 5,
      "name": "Plant_Crop_Mushroom_Block_Blue_Mycelium"
    },
    {
      "x": 2,
      "y": 6,
      "z": 5,
      "name": "Plant_Crop_Mushroom_Block_Blue_Mycelium"
    },
    {
      "x": 3,
      "y": 6,
      "z": 5,
      "name": "Plant_Coral_Block_Orange"
    },
    {
      "x": 5,
      "y": 6,
      "z": 5,
      "name": "Plant_Coral_Block_Orange"
    },
    {
      "x": 9,
      "y": 6,
      "z": 5,
      "name": "Plant_Crop_Mushroom_Block_Blue_Mycelium"
    },
    {
      "x": 1,
      "y": 7,
      "z": 5,
      "name": "Plant_Coral_Block_Cyan"
    },
    {
      "x": 2,
      "y": 7,
      "z": 5,
      "name": "Plant_Coral_Block_Cyan"
    },
    {
      "x": 3,
      "y": 7,
      "z": 5,
      "name": "Plant_Coral_Block_Orange"
    },
    {
      "x": 5,
      "y": 7,
      "z": 5,
      "name": "Plant_Coral_Block_Orange"
    },
    {
      "x": 6,
      "y": 7,
      "z": 5,
      "name": "Plant_Coral_Block_Orange"
    },
    {
      "x": 8,
      "y": 7,
      "z": 5,
      "name": "Plant_Crop_Mushroom_Block_Blue"
    },
    {
      "x": 9,
      "y": 7,
      "z": 5,
      "name": "Plant_Crop_Mushroom_Block_Blue"
    },
    {
      "x": 12,
      "y": 7,
      "z": 5,
      "name": "Plant_Crop_Mushroom_Block_Blue_Mycelium"
    },
    {
      "x": 10,
      "y": 8,
      "z": 5,
      "name": "Plant_Coral_Block_Orange"
    },
    {
      "x": 11,
      "y": 8,
      "z": 5,
      "name": "Plant_Coral_Block_Orange"
    },
    {
      "x": 12,
      "y": 8,
      "z": 5,
      "name": "Plant_Coral_Block_Cyan"
    },
    {
      "x": 1,
      "y": 12,
      "z": 5,
      "name": "Plant_Crop_Mushroom_Block_Blue_Mycelium"
    },
    {
      "x": 2,
      "y": 12,
      "z": 5,
      "name": "Plant_Crop_Mushroom_Block_Blue_Mycelium"
    },
    {
      "x": 0,
      "y": 7,
      "z": 6,
      "name": "Plant_Crop_Mushroom_Block_Blue_Mycelium"
    },
    {
      "x": 2,
      "y": 7,
      "z": 6,
      "name": "Plant_Coral_Block_Orange"
    },
    {
      "x": 3,
      "y": 7,
      "z": 6,
      "name": "Plant_Coral_Block_Orange"
    },
    {
      "x": 4,
      "y": 7,
      "z": 6,
      "name": "Plant_Crop_Mushroom_Block_Blue_Mycelium"
    },
    {
      "x": 6,
      "y": 7,
      "z": 6,
      "name": "Plant_Coral_Block_Orange"
    },
    {
      "x": 7,
      "y": 7,
      "z": 6,
      "name": "Plant_Coral_Block_Orange"
    },
    {
      "x": 8,
      "y": 7,
      "z": 6,
      "name": "Plant_Coral_Block_Orange"
    },
    {
      "x": 9,
      "y": 7,
      "z": 6,
      "name": "Plant_Coral_Block_Orange"
    },
    {
      "x": 11,
      "y": 7,
      "z": 6,
      "name": "Plant_Crop_Mushroom_Block_Blue_Mycelium"
    },
    {
      "x": 12,
      "y": 7,
      "z": 6,
      "name": "Plant_Crop_Mushroom_Block_Blue_Mycelium"
    },
    {
      "x": 0,
      "y": 8,
      "z": 6,
      "name": "Plant_Coral_Block_Cyan"
    },
    {
      "x": 2,
      "y": 8,
      "z": 6,
      "name": "Plant_Coral_Block_Orange"
    },
    {
      "x": 3,
      "y": 8,
      "z": 6,
      "name": "Plant_Coral_Block_Cyan"
    },
    {
      "x": 4,
      "y": 8,
      "z": 6,
      "name": "Plant_Coral_Block_Cyan"
    },
    {
      "x": 9,
      "y": 8,
      "z": 6,
      "name": "Plant_Coral_Block_Orange"
    },
    {
      "x": 10,
      "y": 8,
      "z": 6,
      "name": "Plant_Coral_Block_Orange"
    },
    {
      "x": 11,
      "y": 8,
      "z": 6,
      "name": "Plant_Coral_Block_Cyan"
    },
    {
      "x": 12,
      "y": 8,
      "z": 6,
      "name": "Plant_Coral_Block_Cyan"
    },
    {
      "x": 2,
      "y": 12,
      "z": 6,
      "name": "Plant_Crop_Mushroom_Block_Blue_Mycelium"
    },
    {
      "x": 6,
      "y": 6,
      "z": 7,
      "name": "Plant_Crop_Mushroom_Block_Blue_Mycelium"
    },
    {
      "x": 8,
      "y": 6,
      "z": 7,
      "name": "Plant_Crop_Mushroom_Block_Blue_Mycelium"
    },
    {
      "x": 4,
      "y": 7,
      "z": 7,
      "name": "Plant_Crop_Mushroom_Block_Blue_Mycelium"
    },
    {
      "x": 6,
      "y": 7,
      "z": 7,
      "name": "Plant_Coral_Block_Cyan"
    },
    {
      "x": 8,
      "y": 7,
      "z": 7,
      "name": "Plant_Coral_Block_Cyan"
    },
    {
      "x": 10,
      "y": 7,
      "z": 7,
      "name": "Plant_Crop_Mushroom_Block_Blue_Mycelium"
    },
    {
      "x": 0,
      "y": 8,
      "z": 7,
      "name": "Plant_Coral_Block_Orange"
    },
    {
      "x": 1,
      "y": 8,
      "z": 7,
      "name": "Plant_Coral_Block_Orange"
    },
    {
      "x": 2,
      "y": 8,
      "z": 7,
      "name": "Plant_Coral_Block_Orange"
    },
    {
      "x": 4,
      "y": 8,
      "z": 7,
      "name": "Plant_Coral_Block_Cyan"
    },
    {
      "x": 10,
      "y": 8,
      "z": 7,
      "name": "Plant_Coral_Block_Cyan"
    },
    {
      "x": 12,
      "y": 8,
      "z": 7,
      "name": "Plant_Crop_Mushroom_Block_Blue"
    },
    {
      "x": 13,
      "y": 8,
      "z": 7,
      "name": "Plant_Crop_Mushroom_Block_Blue_Mycelium"
    },
    {
      "x": 4,
      "y": 9,
      "z": 7,
      "name": "Plant_Coral_Block_Cyan"
    },
    {
      "x": 5,
      "y": 9,
      "z": 7,
      "name": "Plant_Crop_Mushroom_Block_Blue_Mycelium"
    },
    {
      "x": 12,
      "y": 9,
      "z": 7,
      "name": "Plant_Crop_Mushroom_Block_Blue"
    },
    {
      "x": 13,
      "y": 9,
      "z": 7,
      "name": "Plant_Crop_Mushroom_Block_Blue"
    },
    {
      "x": 4,
      "y": 10,
      "z": 7,
      "name": "Plant_Coral_Block_Cyan"
    },
    {
      "x": 5,
      "y": 10,
      "z": 7,
      "name": "Plant_Coral_Block_Cyan"
    },
    {
      "x": 5,
      "y": 11,
      "z": 7,
      "name": "Plant_Coral_Block_Cyan"
    },
    {
      "x": 6,
      "y": 6,
      "z": 8,
      "name": "Plant_Crop_Mushroom_Block_Blue_Mycelium"
    },
    {
      "x": 8,
      "y": 6,
      "z": 8,
      "name": "Plant_Crop_Mushroom_Block_Blue_Mycelium"
    },
    {
      "x": 2,
      "y": 7,
      "z": 8,
      "name": "Plant_Crop_Mushroom_Block_Blue_Mycelium"
    },
    {
      "x": 6,
      "y": 7,
      "z": 8,
      "name": "Plant_Coral_Block_Cyan"
    },
    {
      "x": 8,
      "y": 7,
      "z": 8,
      "name": "Plant_Coral_Block_Cyan"
    },
    {
      "x": 0,
      "y": 8,
      "z": 8,
      "name": "Plant_Coral_Block_Orange"
    },
    {
      "x": 1,
      "y": 8,
      "z": 8,
      "name": "Plant_Coral_Block_Cyan"
    },
    {
      "x": 2,
      "y": 8,
      "z": 8,
      "name": "Rock_Crystal_Cyan_Block"
    },
    {
      "x": 6,
      "y": 8,
      "z": 8,
      "name": "Plant_Crop_Mushroom_Block_Blue"
    },
    {
      "x": 10,
      "y": 8,
      "z": 8,
      "name": "Plant_Coral_Block_Cyan"
    },
    {
      "x": 13,
      "y": 8,
      "z": 8,
      "name": "Plant_Crop_Mushroom_Block_Blue_Mycelium"
    },
    {
      "x": 14,
      "y": 8,
      "z": 8,
      "name": "Plant_Crop_Mushroom_Block_Blue_Mycelium"
    },
    {
      "x": 0,
      "y": 9,
      "z": 8,
      "name": "Plant_Coral_Block_Orange"
    },
    {
      "x": 2,
      "y": 9,
      "z": 8,
      "name": "Plant_Coral_Block_Cyan"
    },
    {
      "x": 13,
      "y": 9,
      "z": 8,
      "name": "Plant_Crop_Mushroom_Block_Blue"
    },
    {
      "x": 14,
      "y": 9,
      "z": 8,
      "name": "Plant_Coral_Block_Cyan"
    },
    {
      "x": 7,
      "y": 5,
      "z": 9,
      "name": "Plant_Crop_Mushroom_Block_Blue_Mycelium"
    },
    {
      "x": 7,
      "y": 6,
      "z": 9,
      "name": "Plant_Coral_Block_Cyan"
    },
    {
      "x": 8,
      "y": 6,
      "z": 9,
      "name": "Plant_Coral_Block_Cyan"
    },
    {
      "x": 5,
      "y": 7,
      "z": 9,
      "name": "Plant_Crop_Mushroom_Block_Blue_Mycelium"
    },
    {
      "x": 8,
      "y": 7,
      "z": 9,
      "name": "Plant_Coral_Block_Cyan"
    },
    {
      "x": 10,
      "y": 7,
      "z": 9,
      "name": "Plant_Crop_Mushroom_Block_Blue_Mycelium"
    },
    {
      "x": 11,
      "y": 7,
      "z": 9,
      "name": "Plant_Coral_Block_Cyan"
    },
    {
      "x": 2,
      "y": 8,
      "z": 9,
      "name": "Plant_Crop_Mushroom_Block_Blue_Mycelium"
    },
    {
      "x": 3,
      "y": 8,
      "z": 9,
      "name": "Plant_Crop_Mushroom_Block_Blue_Mycelium"
    },
    {
      "x": 5,
      "y": 8,
      "z": 9,
      "name": "Plant_Crop_Mushroom_Block_Blue"
    },
    {
      "x": 6,
      "y": 8,
      "z": 9,
      "name": "Plant_Crop_Mushroom_Block_Blue"
    },
    {
      "x": 10,
      "y": 8,
      "z": 9,
      "name": "Plant_Coral_Block_Cyan"
    },
    {
      "x": 11,
      "y": 8,
      "z": 9,
      "name": "Plant_Coral_Block_Cyan"
    },
    {
      "x": 14,
      "y": 8,
      "z": 9,
      "name": "Plant_Crop_Mushroom_Block_Blue_Mycelium"
    },
    {
      "x": 2,
      "y": 9,
      "z": 9,
      "name": "Plant_Coral_Block_Cyan"
    },
    {
      "x": 3,
      "y": 9,
      "z": 9,
      "name": "Plant_Coral_Block_Cyan"
    },
    {
      "x": 14,
      "y": 9,
      "z": 9,
      "name": "Plant_Coral_Block_Cyan"
    },
    {
      "x": 3,
      "y": 10,
      "z": 9,
      "name": "Plant_Coral_Block_Cyan"
    },
    {
      "x": 7,
      "y": 5,
      "z": 10,
      "name": "Plant_Crop_Mushroom_Block_Blue_Mycelium"
    },
    {
      "x": 7,
      "y": 6,
      "z": 10,
      "name": "Plant_Crop_Mushroom_Block_Blue"
    },
    {
      "x": 12,
      "y": 6,
      "z": 10,
      "name": "Plant_Crop_Mushroom_Block_Blue_Mycelium"
    },
    {
      "x": 5,
      "y": 7,
      "z": 10,
      "name": "Plant_Crop_Mushroom_Block_Blue_Mycelium"
    },
    {
      "x": 11,
      "y": 7,
      "z": 10,
      "name": "Plant_Coral_Block_Cyan"
    },
    {
      "x": 12,
      "y": 7,
      "z": 10,
      "name": "Plant_Coral_Block_Cyan"
    },
    {
      "x": 5,
      "y": 8,
      "z": 10,
      "name": "Plant_Coral_Block_Cyan"
    },
    {
      "x": 0,
      "y": 9,
      "z": 10,
      "name": "Plant_Coral_Block_Cyan"
    },
    {
      "x": 3,
      "y": 9,
      "z": 10,
      "name": "Plant_Crop_Mushroom_Block_Blue_Mycelium"
    },
    {
      "x": 3,
      "y": 10,
      "z": 10,
      "name": "Plant_Coral_Block_Cyan"
    },
    {
      "x": 7,
      "y": 5,
      "z": 11,
      "name": "Plant_Crop_Mushroom_Block_Blue_Mycelium"
    },
    {
      "x": 7,
      "y": 6,
      "z": 11,
      "name": "Plant_Coral_Block_Cyan"
    },
    {
      "x": 12,
      "y": 6,
      "z": 11,
      "name": "Plant_Crop_Mushroom_Block_Blue_Mycelium"
    },
    {
      "x": 5,
      "y": 7,
      "z": 11,
      "name": "Plant_Crop_Mushroom_Block_Blue_Mycelium"
    },
    {
      "x": 12,
      "y": 7,
      "z": 11,
      "name": "Plant_Coral_Block_Cyan"
    },
    {
      "x": 0,
      "y": 8,
      "z": 11,
      "name": "Plant_Crop_Mushroom_Block_Blue_Mycelium"
    },
    {
      "x": 1,
      "y": 8,
      "z": 11,
      "name": "Plant_Crop_Mushroom_Block_Blue_Mycelium"
    },
    {
      "x": 5,
      "y": 8,
      "z": 11,
      "name": "Plant_Coral_Block_Cyan"
    },
    {
      "x": 0,
      "y": 9,
      "z": 11,
      "name": "Plant_Coral_Block_Cyan"
    },
    {
      "x": 1,
      "y": 9,
      "z": 11,
      "name": "Plant_Coral_Block_Cyan"
    },
    {
      "x": 1,
      "y": 10,
      "z": 11,
      "name": "Plant_Coral_Block_Cyan"
    },
    {
      "x": 1,
      "y": 9,
      "z": 12,
      "name": "Plant_Crop_Mushroom_Block_Blue_Mycelium"
    },
    {
      "x": 2,
      "y": 9,
      "z": 12,
      "name": "Plant_Crop_Mushroom_Block_Blue_Mycelium"
    },
    {
      "x": 1,
      "y": 10,
      "z": 12,
      "name": "Plant_Coral_Block_Cyan"
    },
    {
      "x": 2,
      "y": 10,
      "z": 12,
      "name": "Plant_Coral_Block_Cyan"
    },
    {
      "x": 2,
      "y": 11,
      "z": 12,
      "name": "Plant_Coral_Block_Cyan"
    },
    {
      "x": 2,
      "y": 10,
      "z": 13,
      "name": "Plant_Crop_Mushroom_Block_Blue_Mycelium"
    },
    {
      "x": 2,
      "y": 11,
      "z": 13,
      "name": "Plant_Coral_Block_Cyan"
    },
    {
      "x": 0,
      "y": 10,
      "z": 14,
      "name": "Plant_Crop_Mushroom_Block_Blue_Mycelium"
    },
    {
      "x": 0,
      "y": 11,
      "z": 14,
      "name": "Plant_Coral_Block_Cyan"
    },
    {
      "x": 0,
      "y": 11,
      "z": 15,
      "name": "Plant_Coral_Block_Cyan"
    },
    {
      "x": -1,
      "y": 13,
      "z": 0,
      "name": "Plant_Coral_Block_Orange"
    },
    {
      "x": -6,
      "y": 14,
      "z": 0,
      "name": "Plant_Crop_Mushroom_Block_Blue_Mycelium"
    },
    {
      "x": -1,
      "y": 14,
      "z": 0,
      "name": "Plant_Coral_Block_Orange"
    },
    {
      "x": -6,
      "y": 15,
      "z": 0,
      "name": "Plant_Crop_Mushroom_Block_Blue"
    },
    {
      "x": -9,
      "y": 17,
      "z": 0,
      "name": "Plant_Crop_Mushroom_Block_Blue_Mycelium"
    },
    {
      "x": -8,
      "y": 17,
      "z": 0,
      "name": "Plant_Crop_Mushroom_Block_Blue"
    },
    {
      "x": -9,
      "y": 18,
      "z": 0,
      "name": "Plant_Coral_Block_Cyan"
    },
    {
      "x": -8,
      "y": 18,
      "z": 0,
      "name": "Plant_Coral_Block_Cyan"
    },
    {
      "x": -6,
      "y": 14,
      "z": 1,
      "name": "Plant_Crop_Mushroom_Block_Blue_Mycelium"
    },
    {
      "x": -1,
      "y": 14,
      "z": 1,
      "name": "Plant_Coral_Block_Cyan"
    },
    {
      "x": -7,
      "y": 15,
      "z": 1,
      "name": "Plant_Crop_Mushroom_Block_Blue_Mycelium"
    },
    {
      "x": -6,
      "y": 15,
      "z": 1,
      "name": "Plant_Crop_Mushroom_Block_Blue"
    },
    {
      "x": -7,
      "y": 16,
      "z": 1,
      "name": "Plant_Crop_Mushroom_Block_Blue"
    },
    {
      "x": -6,
      "y": 16,
      "z": 1,
      "name": "Plant_Coral_Block_Cyan"
    },
    {
      "x": -10,
      "y": 17,
      "z": 1,
      "name": "Plant_Crop_Mushroom_Block_Blue_Mycelium"
    },
    {
      "x": -10,
      "y": 18,
      "z": 1,
      "name": "Plant_Coral_Block_Cyan"
    },
    {
      "x": -9,
      "y": 18,
      "z": 1,
      "name": "Plant_Crop_Mushroom_Block_Blue"
    },
    {
      "x": -10,
      "y": 19,
      "z": 1,
      "name": "Plant_Coral_Block_Cyan"
    },
    {
      "x": -2,
      "y": 13,
      "z": 2,
      "name": "Plant_Crop_Mushroom_Block_Blue_Mycelium"
    },
    {
      "x": -1,
      "y": 13,
      "z": 2,
      "name": "Plant_Crop_Mushroom_Block_Blue_Mycelium"
    },
    {
      "x": -2,
      "y": 14,
      "z": 2,
      "name": "Plant_Crop_Mushroom_Block_Blue"
    },
    {
      "x": -1,
      "y": 14,
      "z": 2,
      "name": "Plant_Coral_Block_Cyan"
    },
    {
      "x": -8,
      "y": 15,
      "z": 2,
      "name": "Plant_Crop_Mushroom_Block_Blue_Mycelium"
    },
    {
      "x": -7,
      "y": 15,
      "z": 2,
      "name": "Plant_Crop_Mushroom_Block_Blue_Mycelium"
    },
    {
      "x": -8,
      "y": 16,
      "z": 2,
      "name": "Plant_Coral_Block_Cyan"
    },
    {
      "x": -7,
      "y": 16,
      "z": 2,
      "name": "Plant_Coral_Block_Cyan"
    },
    {
      "x": -8,
      "y": 17,
      "z": 2,
      "name": "Plant_Coral_Block_Cyan"
    },
    {
      "x": -2,
      "y": 13,
      "z": 3,
      "name": "Plant_Crop_Mushroom_Block_Blue_Mycelium"
    },
    {
      "x": -2,
      "y": 14,
      "z": 3,
      "name": "Plant_Coral_Block_Cyan"
    },
    {
      "x": -8,
      "y": 16,
      "z": 3,
      "name": "Plant_Crop_Mushroom_Block_Blue_Mycelium"
    },
    {
      "x": -8,
      "y": 17,
      "z": 3,
      "name": "Plant_Coral_Block_Cyan"
    },
    {
      "x": -2,
      "y": 14,
      "z": 4,
      "name": "Rock_Crystal_Cyan_Block"
    },
    {
      "x": -3,
      "y": 15,
      "z": 4,
      "name": "Plant_Coral_Block_Cyan"
    },
    {
      "x": -2,
      "y": 15,
      "z": 4,
      "name": "Plant_Coral_Block_Cyan"
    },
    {
      "x": -3,
      "y": 14,
      "z": 5,
      "name": "Plant_Crop_Mushroom_Block_Blue_Mycelium"
    },
    {
      "x": -3,
      "y": 15,
      "z": 5,
      "name": "Plant_Coral_Block_Cyan"
    },
    {
      "x": -3,
      "y": 14,
      "z": 6,
      "name": "Plant_Crop_Mushroom_Block_Blue_Mycelium"
    },
    {
      "x": -3,
      "y": 15,
      "z": 6,
      "name": "Plant_Coral_Block_Cyan"
    }
  ],
  "fluids": [],
  "entities": []
}