{
  "version": 8,
  "blockIdVersion": 11,
  "anchorX": 0,
  "anchorY": 0,
  "anchorZ": 0,
  "blocks": [
    {
      "x": -14,
      "y": 30,
      "z": 3,
      "name": "Plant_Coral_Block_Green"
    },
    {
      "x": -14,
      "y": 30,
      "z": 4,
      "name": "Plant_Coral_Block_Green"
    },
    {
      "x": -14,
      "y": 30,
      "z": 5,
      "name": "Plant_Coral_Block_Green"
    },
    {
      "x": -14,
      "y": 31,
      "z": 5,
      "name": "Plant_Coral_Bush_Green"
    },
    {
      "x": -13,
      "y": 30,
      "z": 1,
      "name": "Plant_Coral_Block_Green"
    },
    {
      "x": -13,
      "y": 30,
      "z": 2,
      "name": "Plant_Coral_Block_Green"
    },
    {
      "x": -13,
      "y": 29,
      "z": 3,
      "name": "Plant_Coral_Block_Green"
    },
    {
      "x": -13,
      "y": 30,
      "z": 3,
      "name": "Plant_Coral_Block_Green"
    },
    {
      "x": -13,
      "y": 31,
      "z": 3,
      "name": "Plant_Coral_Bush_Green"
    },
    {
      "x": -13,
      "y": 29,
      "z": 4,
      "name": "Plant_Coral_Block_Green"
    },
    {
      "x": -13,
      "y": 30,
      "z": 4,
      "name": "Plant_Coral_Block_Green"
    },
    {
      "x": -13,
      "y": 29,
      "z": 5,
      "name": "Plant_Coral_Block_Green"
    },
    {
      "x": -13,
      "y": 30,
      "z": 5,
      "name": "Plant_Coral_Block_Green"
    },
    {
      "x": -13,
      "y": 30,
      "z": 6,
      "name": "Plant_Coral_Block_Green"
    },
    {
      "x": -13,
      "y": 30,
      "z": 7,
      "name": "Plant_Coral_Block_Green"
    },
    {
      "x": -13,
      "y": 31,
      "z": 7,
      "name": "Plant_Coral_Bush_Green"
    },
    {
      "x": -12,
      "y": 18,
      "z": -4,
      "name": "Plant_Coral_Block_Green"
    },
    {
      "x": -12,
      "y": 19,
      "z": -4,
      "name": "Plant_Coral_Bush_Green"
    },
    {
      "x": -12,
      "y": 27,
      "z": -4,
      "name": "Plant_Coral_Block_Green"
    },
    {
      "x": -12,
      "y": 28,
      "z": -4,
      "name": "Plant_Coral_Bush_Green"
    },
    {
      "x": -12,
      "y": 18,
      "z": -3,
      "name": "Plant_Coral_Block_Green"
    },
    {
      "x": -12,
      "y": 27,
      "z": -3,
      "name": "Plant_Coral_Block_Green"
    },
    {
      "x": -12,
      "y": 18,
      "z": -2,
      "name": "Plant_Coral_Block_Green"
    },
    {
      "x": -12,
      "y": 19,
      "z": -2,
      "name": "Plant_Coral_Bush_Green"
    },
    {
      "x": -12,
      "y": 23,
      "z": -2,
      "name": "Plant_Coral_Block_Green"
    },
    {
      "x": -12,
      "y": 24,
      "z": -2,
      "name": "Plant_Coral_Bush_Green"
    },
    {
      "x": -12,
      "y": 27,
      "z": -2,
      "name": "Plant_Coral_Block_Green"
    },
    {
      "x": -12,
      "y": 28,
      "z": -2,
      "name": "Plant_Coral_Bush_Green"
    },
    {
      "x": -12,
      "y": 23,
      "z": -1,
      "name": "Plant_Coral_Block_Green"
    },
    {
      "x": -12,
      "y": 23,
      "z": 0,
      "name": "Plant_Coral_Block_Green"
    },
    {
      "x": -12,
      "y": 24,
      "z": 0,
      "name": "Plant_Coral_Bush_Green"
    },
    {
      "x": -12,
      "y": 30,
      "z": 0,
      "name": "Plant_Coral_Block_Green"
    },
    {
      "x": -12,
      "y": 30,
      "z": 1,
      "name": "Plant_Coral_Block_Green"
    },
    {
      "x": -12,
      "y": 31,
      "z": 1,
      "name": "Plant_Coral_Bush_Green"
    },
    {
      "x": -12,
      "y": 20,
      "z": 2,
      "name": "Plant_Coral_Block_Green"
    },
    {
      "x": -12,
      "y": 21,
      "z": 2,
      "name": "Plant_Coral_Bush_Green"
    },
    {
      "x": -12,
      "y": 29,
      "z": 2,
      "name": "Plant_Coral_Block_Green"
    },
    {
      "x": -12,
      "y": 30,
      "z": 2,
      "name": "Plant_Coral_Block_Green"
    },
    {
      "x": -12,
      "y": 20,
      "z": 3,
      "name": "Plant_Coral_Block_Green"
    },
    {
      "x": -12,
      "y": 25,
      "z": 3,
      "name": "Plant_Coral_Block_Green"
    },
    {
      "x": -12,
      "y": 26,
      "z": 3,
      "name": "Plant_Coral_Bush_Green"
    },
    {
      "x": -12,
      "y": 29,
      "z": 3,
      "name": "Plant_Coral_Block_Green"
    },
    {
      "x": -12,
      "y": 30,
      "z": 3,
      "name": "Plant_Coral_Block_Green"
    },
    {
      "x": -12,
      "y": 20,
      "z": 4,
      "name": "Plant_Coral_Block_Green"
    },
    {
      "x": -12,
      "y": 21,
      "z": 4,
      "name": "Plant_Coral_Bush_Green"
    },
    {
      "x": -12,
      "y": 25,
      "z": 4,
      "name": "Plant_Coral_Block_Green"
    },
    {
      "x": -12,
      "y": 29,
      "z": 4,
      "name": "Plant_Coral_Block_Green"
    },
    {
      "x": -12,
      "y": 30,
      "z": 4,
      "name": "Plant_Coral_Block_Green"
    },
    {
      "x": -12,
      "y": 25,
      "z": 5,
      "name": "Plant_Coral_Block_Green"
    },
    {
      "x": -12,
      "y": 26,
      "z": 5,
      "name": "Plant_Coral_Bush_Green"
    },
    {
      "x": -12,
      "y": 29,
      "z": 5,
      "name": "Plant_Coral_Block_Green"
    },
    {
      "x": -12,
      "y": 30,
      "z": 5,
      "name": "Plant_Coral_Block_Green"
    },
    {
      "x": -12,
      "y": 29,
      "z": 6,
      "name": "Plant_Coral_Block_Green"
    },
    {
      "x": -12,
      "y": 30,
      "z": 6,
      "name": "Plant_Coral_Block_Green"
    },
    {
      "x": -12,
      "y": 30,
      "z": 7,
      "name": "Plant_Coral_Block_Green"
    },
    {
      "x": -12,
      "y": 30,
      "z": 8,
      "name": "Plant_Coral_Block_Green"
    },
    {
      "x": -11,
      "y": 18,
      "z": -5,
      "name": "Plant_Coral_Block_Green"
    },
    {
      "x": -11,
      "y": 27,
      "z": -5,
      "name": "Plant_Coral_Block_Green"
    },
    {
      "x": -11,
      "y": 18,
      "z": -4,
      "name": "Plant_Coral_Block_Green"
    },
    {
      "x": -11,
      "y": 27,
      "z": -4,
      "name": "Plant_Coral_Block_Green"
    },
    {
      "x": -11,
      "y": 17,
      "z": -3,
      "name": "Plant_Coral_Block_Green"
    },
    {
      "x": -11,
      "y": 18,
      "z": -3,
      "name": "Plant_Coral_Block_Green"
    },
    {
      "x": -11,
      "y": 23,
      "z": -3,
      "name": "Plant_Coral_Block_Green"
    },
    {
      "x": -11,
      "y": 26,
      "z": -3,
      "name": "Plant_Coral_Block_Green"
    },
    {
      "x": -11,
      "y": 27,
      "z": -3,
      "name": "Plant_Coral_Block_Green"
    },
    {
      "x": -11,
      "y": 18,
      "z": -2,
      "name": "Plant_Coral_Block_Green"
    },
    {
      "x": -11,
      "y": 23,
      "z": -2,
      "name": "Plant_Coral_Block_Green"
    },
    {
      "x": -11,
      "y": 27,
      "z": -2,
      "name": "Plant_Coral_Block_Green"
    },
    {
      "x": -11,
      "y": 18,
      "z": -1,
      "name": "Plant_Coral_Block_Green"
    },
    {
      "x": -11,
      "y": 22,
      "z": -1,
      "name": "Plant_Coral_Block_Green"
    },
    {
      "x": -11,
      "y": 23,
      "z": -1,
      "name": "Plant_Coral_Block_Green"
    },
    {
      "x": -11,
      "y": 27,
      "z": -1,
      "name": "Plant_Coral_Block_Green"
    },
    {
      "x": -11,
      "y": 16,
      "z": 0,
      "name": "Plant_Coral_Block_Green"
    },
    {
      "x": -11,
      "y": 23,
      "z": 0,
      "name": "Plant_Coral_Block_Green"
    },
    {
      "x": -11,
      "y": 30,
      "z": 0,
      "name": "Plant_Coral_Block_Green"
    },
    {
      "x": -11,
      "y": 16,
      "z": 1,
      "name": "Plant_Coral_Block_Green"
    },
    {
      "x": -11,
      "y": 17,
      "z": 1,
      "name": "Plant_Coral_Bush_Green"
    },
    {
      "x": -11,
      "y": 20,
      "z": 1,
      "name": "Plant_Coral_Block_Green"
    },
    {
      "x": -11,
      "y": 23,
      "z": 1,
      "name": "Plant_Coral_Block_Green"
    },
    {
      "x": -11,
      "y": 29,
      "z": 1,
      "name": "Plant_Coral_Block_Green"
    },
    {
      "x": -11,
      "y": 30,
      "z": 1,
      "name": "Plant_Coral_Block_Green"
    },
    {
      "x": -11,
      "y": 16,
      "z": 2,
      "name": "Plant_Coral_Block_Green"
    },
    {
      "x": -11,
      "y": 17,
      "z": 2,
      "name": "Plant_Coral_Bush_Green"
    },
    {
      "x": -11,
      "y": 20,
      "z": 2,
      "name": "Plant_Coral_Block_Green"
    },
    {
      "x": -11,
      "y": 25,
      "z": 2,
      "name": "Plant_Coral_Block_Green"
    },
    {
      "x": -11,
      "y": 29,
      "z": 2,
      "name": "Plant_Coral_Block_Green"
    },
    {
      "x": -11,
      "y": 30,
      "z": 2,
      "name": "Plant_Coral_Block_Green"
    },
    {
      "x": -11,
      "y": 19,
      "z": 3,
      "name": "Plant_Coral_Block_Green"
    },
    {
      "x": -11,
      "y": 20,
      "z": 3,
      "name": "Plant_Coral_Block_Green"
    },
    {
      "x": -11,
      "y": 25,
      "z": 3,
      "name": "Plant_Coral_Block_Green"
    },
    {
      "x": -11,
      "y": 28,
      "z": 3,
      "name": "Plant_Coral_Block_Green"
    },
    {
      "x": -11,
      "y": 29,
      "z": 3,
      "name": "Plant_Coral_Block_Green"
    },
    {
      "x": -11,
      "y": 20,
      "z": 4,
      "name": "Plant_Coral_Block_Green"
    },
    {
      "x": -11,
      "y": 24,
      "z": 4,
      "name": "Plant_Coral_Block_Green"
    },
    {
      "x": -11,
      "y": 25,
      "z": 4,
      "name": "Plant_Coral_Block_Green"
    },
    {
      "x": -11,
      "y": 28,
      "z": 4,
      "name": "Plant_Coral_Block_Green"
    },
    {
      "x": -11,
      "y": 29,
      "z": 4,
      "name": "Plant_Coral_Block_Green"
    },
    {
      "x": -11,
      "y": 30,
      "z": 4,
      "name": "Plant_Coral_Bush_Green"
    },
    {
      "x": -11,
      "y": 20,
      "z": 5,
      "name": "Plant_Coral_Block_Green"
    },
    {
      "x": -11,
      "y": 25,
      "z": 5,
      "name": "Plant_Coral_Block_Green"
    },
    {
      "x": -11,
      "y": 28,
      "z": 5,
      "name": "Plant_Coral_Block_Green"
    },
    {
      "x": -11,
      "y": 29,
      "z": 5,
      "name": "Plant_Coral_Block_Green"
    },
    {
      "x": -11,
      "y": 25,
      "z": 6,
      "name": "Plant_Coral_Block_Green"
    },
    {
      "x": -11,
      "y": 29,
      "z": 6,
      "name": "Plant_Coral_Block_Green"
    },
    {
      "x": -11,
      "y": 30,
      "z": 6,
      "name": "Plant_Coral_Block_Green"
    },
    {
      "x": -11,
      "y": 29,
      "z": 7,
      "name": "Plant_Coral_Block_Green"
    },
    {
      "x": -11,
      "y": 30,
      "z": 7,
      "name": "Plant_Coral_Block_Green"
    },
    {
      "x": -11,
      "y": 30,
      "z": 8,
      "name": "Plant_Coral_Block_Green"
    },
    {
      "x": -11,
      "y": 31,
      "z": 8,
      "name": "Plant_Coral_Bush_Green"
    },
    {
      "x": -10,
      "y": 23,
      "z": -7,
      "name": "Plant_Coral_Block_Green"
    },
    {
      "x": -10,
      "y": 24,
      "z": -7,
      "name": "Plant_Coral_Bush_Green"
    },
    {
      "x": -10,
      "y": 3,
      "z": -6,
      "name": "Cloth_Roof_Leather_Flap",
      "rotation": 3
    },
    {
      "x": -10,
      "y": 23,
      "z": -6,
      "name": "Plant_Coral_Block_Green"
    },
    {
      "x": -10,
      "y": 6,
      "z": -5,
      "name": "Rock_Sandstone_Brick_Half",
      "rotation": 7
    },
    {
      "x": -10,
      "y": 18,
      "z": -5,
      "name": "Plant_Coral_Block_Green"
    },
    {
      "x": -10,
      "y": 19,
      "z": -5,
      "name": "Plant_Coral_Bush_Green"
    },
    {
      "x": -10,
      "y": 23,
      "z": -5,
      "name": "Plant_Coral_Block_Green"
    },
    {
      "x": -10,
      "y": 24,
      "z": -5,
      "name": "Plant_Coral_Bush_Green"
    },
    {
      "x": -10,
      "y": 27,
      "z": -5,
      "name": "Plant_Coral_Block_Green"
    },
    {
      "x": -10,
      "y": 28,
      "z": -5,
      "name": "Plant_Coral_Bush_Green"
    },
    {
      "x": -10,
      "y": 6,
      "z": -4,
      "name": "Rock_Sandstone_Brick_Half",
      "rotation": 7
    },
    {
      "x": -10,
      "y": 10,
      "z": -4,
      "name": "Plant_Coral_Block_Green"
    },
    {
      "x": -10,
      "y": 17,
      "z": -4,
      "name": "Plant_Coral_Block_Green"
    },
    {
      "x": -10,
      "y": 18,
      "z": -4,
      "name": "Plant_Coral_Block_Green"
    },
    {
      "x": -10,
      "y": 19,
      "z": -4,
      "name": "Cloth_Roof_Leather_Flap",
      "rotation": 3
    },
    {
      "x": -10,
      "y": 26,
      "z": -4,
      "name": "Plant_Coral_Block_Green"
    },
    {
      "x": -10,
      "y": 27,
      "z": -4,
      "name": "Plant_Coral_Block_Green"
    },
    {
      "x": -10,
      "y": 3,
      "z": -3,
      "name": "Cloth_Roof_Leather_Flap",
      "rotation": 3
    },
    {
      "x": -10,
      "y": 10,
      "z": -3,
      "name": "Plant_Coral_Block_Green"
    },
    {
      "x": -10,
      "y": 11,
      "z": -3,
      "name": "Plant_Coral_Bush_Green"
    },
    {
      "x": -10,
      "y": 13,
      "z": -3,
      "name": "Rock_Sandstone_Brick_Half",
      "rotation": 32
    },
    {
      "x": -10,
      "y": 14,
      "z": -3,
      "name": "Rock_Sandstone_Brick_Half",
      "rotation": 6
    },
    {
      "x": -10,
      "y": 15,
      "z": -3,
      "name": "Rock_Sandstone_Brick_Half",
      "rotation": 6
    },
    {
      "x": -10,
      "y": 16,
      "z": -3,
      "name": "Rock_Sandstone_Brick_Half",
      "rotation": 6
    },
    {
      "x": -10,
      "y": 17,
      "z": -3,
      "name": "Plant_Coral_Block_Green"
    },
    {
      "x": -10,
      "y": 18,
      "z": -3,
      "name": "Plant_Coral_Block_Green"
    },
    {
      "x": -10,
      "y": 19,
      "z": -3,
      "name": "Cloth_Roof_Leather_Flap",
      "rotation": 3
    },
    {
      "x": -10,
      "y": 23,
      "z": -3,
      "name": "Rock_Sandstone_Brick_Half",
      "rotation": 32
    },
    {
      "x": -10,
      "y": 24,
      "z": -3,
      "name": "Rock_Sandstone_Brick_Half",
      "rotation": 6
    },
    {
      "x": -10,
      "y": 25,
      "z": -3,
      "name": "Rock_Sandstone_Brick_Half",
      "rotation": 6
    },
    {
      "x": -10,
      "y": 26,
      "z": -3,
      "name": "Rock_Sandstone_Brick_Half",
      "rotation": 6
    },
    {
      "x": -10,
      "y": 27,
      "z": -3,
      "name": "Rock_Sandstone_Brick_Half",
      "rotation": 7
    },
    {
      "x": -10,
      "y": 28,
      "z": -3,
      "name": "Plant_Coral_Bush_Green"
    },
    {
      "x": -10,
      "y": 10,
      "z": -2,
      "name": "Plant_Coral_Block_Green"
    },
    {
      "x": -10,
      "y": 11,
      "z": -2,
      "name": "Plant_Coral_Bush_Green"
    },
    {
      "x": -10,
      "y": 13,
      "z": -2,
      "name": "Rock_Sandstone_Brick_Stairs",
      "rotation": 35
    },
    {
      "x": -10,
      "y": 17,
      "z": -2,
      "name": "Rock_Sandstone_Brick_Half"
    },
    {
      "x": -10,
      "y": 18,
      "z": -2,
      "name": "Plant_Coral_Block_Green"
    },
    {
      "x": -10,
      "y": 19,
      "z": -2,
      "name": "Cloth_Roof_Leather_Flap",
      "rotation": 3
    },
    {
      "x": -10,
      "y": 22,
      "z": -2,
      "name": "Plant_Coral_Block_Green"
    },
    {
      "x": -10,
      "y": 23,
      "z": -2,
      "name": "Rock_Sandstone_Brick_Stairs",
      "rotation": 35
    },
    {
      "x": -10,
      "y": 26,
      "z": -2,
      "name": "Plant_Coral_Block_Green"
    },
    {
      "x": -10,
      "y": 27,
      "z": -2,
      "name": "Rock_Sandstone_Brick_Stairs",
      "rotation": 3
    },
    {
      "x": -10,
      "y": 14,
      "z": -1,
      "name": "Rock_Sandstone_Brick_Half",
      "rotation": 4
    },
    {
      "x": -10,
      "y": 15,
      "z": -1,
      "name": "Rock_Sandstone_Brick_Half",
      "rotation": 4
    },
    {
      "x": -10,
      "y": 16,
      "z": -1,
      "name": "Rock_Sandstone_Brick_Half",
      "rotation": 4
    },
    {
      "x": -10,
      "y": 18,
      "z": -1,
      "name": "Plant_Coral_Block_Green"
    },
    {
      "x": -10,
      "y": 19,
      "z": -1,
      "name": "Cloth_Roof_Leather_Flap",
      "rotation": 3
    },
    {
      "x": -10,
      "y": 22,
      "z": -1,
      "name": "Plant_Coral_Block_Green"
    },
    {
      "x": -10,
      "y": 23,
      "z": -1,
      "name": "Rock_Sandstone_Brick_Half",
      "rotation": 32
    },
    {
      "x": -10,
      "y": 24,
      "z": -1,
      "name": "Rock_Sandstone_Brick_Half",
      "rotation": 4
    },
    {
      "x": -10,
      "y": 25,
      "z": -1,
      "name": "Rock_Sandstone_Brick_Half",
      "rotation": 4
    },
    {
      "x": -10,
      "y": 26,
      "z": -1,
      "name": "Rock_Sandstone_Brick_Half",
      "rotation": 4
    },
    {
      "x": -10,
      "y": 27,
      "z": -1,
      "name": "Rock_Sandstone_Brick_Half",
      "rotation": 7
    },
    {
      "x": -10,
      "y": 28,
      "z": -1,
      "name": "Plant_Coral_Bush_Green"
    },
    {
      "x": -10,
      "y": 30,
      "z": -1,
      "name": "Plant_Coral_Block_Green"
    },
    {
      "x": -10,
      "y": 16,
      "z": 0,
      "name": "Plant_Coral_Block_Green"
    },
    {
      "x": -10,
      "y": 19,
      "z": 0,
      "name": "Cloth_Roof_Leather_Flap",
      "rotation": 3
    },
    {
      "x": -10,
      "y": 22,
      "z": 0,
      "name": "Plant_Coral_Block_Green"
    },
    {
      "x": -10,
      "y": 23,
      "z": 0,
      "name": "Plant_Coral_Block_Green"
    },
    {
      "x": -10,
      "y": 29,
      "z": 0,
      "name": "Plant_Coral_Block_Green"
    },
    {
      "x": -10,
      "y": 30,
      "z": 0,
      "name": "Plant_Coral_Block_Green"
    },
    {
      "x": -10,
      "y": 13,
      "z": 1,
      "name": "Rock_Sandstone_Brick_Half",
      "rotation": 32
    },
    {
      "x": -10,
      "y": 14,
      "z": 1,
      "name": "Rock_Sandstone_Brick_Half",
      "rotation": 6
    },
    {
      "x": -10,
      "y": 15,
      "z": 1,
      "name": "Rock_Sandstone_Brick_Half",
      "rotation": 6
    },
    {
      "x": -10,
      "y": 16,
      "z": 1,
      "name": "Rock_Sandstone_Brick_Half",
      "rotation": 6
    },
    {
      "x": -10,
      "y": 19,
      "z": 1,
      "name": "Cloth_Roof_Leather_Flap",
      "rotation": 3
    },
    {
      "x": -10,
      "y": 20,
      "z": 1,
      "name": "Plant_Coral_Block_Green"
    },
    {
      "x": -10,
      "y": 21,
      "z": 1,
      "name": "Plant_Coral_Bush_Green"
    },
    {
      "x": -10,
      "y": 23,
      "z": 1,
      "name": "Rock_Sandstone_Brick_Half",
      "rotation": 32
    },
    {
      "x": -10,
      "y": 24,
      "z": 1,
      "name": "Rock_Sandstone_Brick_Half",
      "rotation": 6
    },
    {
      "x": -10,
      "y": 25,
      "z": 1,
      "name": "Rock_Sandstone_Brick_Half",
      "rotation": 6
    },
    {
      "x": -10,
      "y": 26,
      "z": 1,
      "name": "Rock_Sandstone_Brick_Half",
      "rotation": 6
    },
    {
      "x": -10,
      "y": 27,
      "z": 1,
      "name": "Rock_Sandstone_Brick_Half",
      "rotation": 7
    },
    {
      "x": -10,
      "y": 29,
      "z": 1,
      "name": "Plant_Coral_Block_Green"
    },
    {
      "x": -10,
      "y": 30,
      "z": 1,
      "name": "Plant_Coral_Block_Green"
    },
    {
      "x": -10,
      "y": 31,
      "z": 1,
      "name": "Plant_Coral_Bush_Green"
    },
    {
      "x": -10,
      "y": 11,
      "z": 2,
      "name": "Plant_Coral_Block_Green"
    },
    {
      "x": -10,
      "y": 13,
      "z": 2,
      "name": "Rock_Sandstone_Brick_Stairs",
      "rotation": 35
    },
    {
      "x": -10,
      "y": 16,
      "z": 2,
      "name": "Plant_Coral_Block_Green"
    },
    {
      "x": -10,
      "y": 17,
      "z": 2,
      "name": "Rock_Sandstone_Brick_Half"
    },
    {
      "x": -10,
      "y": 19,
      "z": 2,
      "name": "Cloth_Roof_Leather_Flap",
      "rotation": 3
    },
    {
      "x": -10,
      "y": 20,
      "z": 2,
      "name": "Plant_Coral_Block_Green"
    },
    {
      "x": -10,
      "y": 23,
      "z": 2,
      "name": "Rock_Sandstone_Brick_Stairs",
      "rotation": 35
    },
    {
      "x": -10,
      "y": 25,
      "z": 2,
      "name": "Plant_Coral_Block_Green"
    },
    {
      "x": -10,
      "y": 26,
      "z": 2,
      "name": "Plant_Coral_Bush_Green"
    },
    {
      "x": -10,
      "y": 27,
      "z": 2,
      "name": "Rock_Sandstone_Brick_Stairs",
      "rotation": 3
    },
    {
      "x": -10,
      "y": 28,
      "z": 2,
      "name": "Plant_Coral_Block_Green"
    },
    {
      "x": -10,
      "y": 29,
      "z": 2,
      "name": "Plant_Coral_Block_Green"
    },
    {
      "x": -10,
      "y": 30,
      "z": 2,
      "name": "Plant_Coral_Bush_Green"
    },
    {
      "x": -10,
      "y": 6,
      "z": 3,
      "name": "Rock_Sandstone_Brick_Half",
      "rotation": 7
    },
    {
      "x": -10,
      "y": 11,
      "z": 3,
      "name": "Plant_Coral_Block_Green"
    },
    {
      "x": -10,
      "y": 12,
      "z": 3,
      "name": "Plant_Coral_Bush_Green"
    },
    {
      "x": -10,
      "y": 13,
      "z": 3,
      "name": "Rock_Sandstone_Brick_Half",
      "rotation": 32
    },
    {
      "x": -10,
      "y": 14,
      "z": 3,
      "name": "Rock_Sandstone_Brick_Half",
      "rotation": 4
    },
    {
      "x": -10,
      "y": 15,
      "z": 3,
      "name": "Rock_Sandstone_Brick_Half",
      "rotation": 4
    },
    {
      "x": -10,
      "y": 16,
      "z": 3,
      "name": "Rock_Sandstone_Brick_Half",
      "rotation": 4
    },
    {
      "x": -10,
      "y": 19,
      "z": 3,
      "name": "Cloth_Roof_Leather_Flap",
      "rotation": 3
    },
    {
      "x": -10,
      "y": 20,
      "z": 3,
      "name": "Plant_Coral_Block_Green"
    },
    {
      "x": -10,
      "y": 21,
      "z": 3,
      "name": "Plant_Coral_Bush_Green"
    },
    {
      "x": -10,
      "y": 23,
      "z": 3,
      "name": "Rock_Sandstone_Brick_Half",
      "rotation": 32
    },
    {
      "x": -10,
      "y": 24,
      "z": 3,
      "name": "Rock_Sandstone_Brick_Half",
      "rotation": 4
    },
    {
      "x": -10,
      "y": 25,
      "z": 3,
      "name": "Rock_Sandstone_Brick_Half",
      "rotation": 4
    },
    {
      "x": -10,
      "y": 26,
      "z": 3,
      "name": "Rock_Sandstone_Brick_Half",
      "rotation": 4
    },
    {
      "x": -10,
      "y": 27,
      "z": 3,
      "name": "Rock_Sandstone_Brick_Half",
      "rotation": 7
    },
    {
      "x": -10,
      "y": 28,
      "z": 3,
      "name": "Plant_Coral_Block_Green"
    },
    {
      "x": -10,
      "y": 29,
      "z": 3,
      "name": "Plant_Coral_Block_Green"
    },
    {
      "x": -10,
      "y": 6,
      "z": 4,
      "name": "Rock_Sandstone_Brick_Half",
      "rotation": 7
    },
    {
      "x": -10,
      "y": 11,
      "z": 4,
      "name": "Plant_Coral_Block_Green"
    },
    {
      "x": -10,
      "y": 12,
      "z": 4,
      "name": "Plant_Coral_Bush_Green"
    },
    {
      "x": -10,
      "y": 14,
      "z": 4,
      "name": "Plant_Coral_Block_Green"
    },
    {
      "x": -10,
      "y": 15,
      "z": 4,
      "name": "Plant_Coral_Bush_Green"
    },
    {
      "x": -10,
      "y": 19,
      "z": 4,
      "name": "Cloth_Roof_Leather_Flap",
      "rotation": 3
    },
    {
      "x": -10,
      "y": 20,
      "z": 4,
      "name": "Plant_Coral_Block_Green"
    },
    {
      "x": -10,
      "y": 24,
      "z": 4,
      "name": "Plant_Coral_Block_Green"
    },
    {
      "x": -10,
      "y": 25,
      "z": 4,
      "name": "Plant_Coral_Block_Green"
    },
    {
      "x": -10,
      "y": 26,
      "z": 4,
      "name": "Plant_Coral_Bush_Green"
    },
    {
      "x": -10,
      "y": 28,
      "z": 4,
      "name": "Plant_Coral_Block_Green"
    },
    {
      "x": -10,
      "y": 29,
      "z": 4,
      "name": "Plant_Coral_Block_Green"
    },
    {
      "x": -10,
      "y": 6,
      "z": 5,
      "name": "Rock_Sandstone_Brick_Half",
      "rotation": 7
    },
    {
      "x": -10,
      "y": 14,
      "z": 5,
      "name": "Plant_Coral_Block_Green"
    },
    {
      "x": -10,
      "y": 15,
      "z": 5,
      "name": "Plant_Coral_Bush_Green"
    },
    {
      "x": -10,
      "y": 20,
      "z": 5,
      "name": "Plant_Coral_Block_Green"
    },
    {
      "x": -10,
      "y": 21,
      "z": 5,
      "name": "Plant_Coral_Bush_Green"
    },
    {
      "x": -10,
      "y": 24,
      "z": 5,
      "name": "Plant_Coral_Block_Green"
    },
    {
      "x": -10,
      "y": 25,
      "z": 5,
      "name": "Plant_Coral_Block_Green"
    },
    {
      "x": -10,
      "y": 28,
      "z": 5,
      "name": "Plant_Coral_Block_Green"
    },
    {
      "x": -10,
      "y": 29,
      "z": 5,
      "name": "Plant_Coral_Block_Green"
    },
    {
      "x": -10,
      "y": 6,
      "z": 6,
      "name": "Rock_Sandstone_Brick_Half",
      "rotation": 7
    },
    {
      "x": -10,
      "y": 25,
      "z": 6,
      "name": "Plant_Coral_Block_Green"
    },
    {
      "x": -10,
      "y": 26,
      "z": 6,
      "name": "Plant_Coral_Bush_Green"
    },
    {
      "x": -10,
      "y": 28,
      "z": 6,
      "name": "Plant_Coral_Block_Green"
    },
    {
      "x": -10,
      "y": 29,
      "z": 6,
      "name": "Plant_Coral_Block_Green"
    },
    {
      "x": -10,
      "y": 6,
      "z": 7,
      "name": "Rock_Sandstone_Brick_Half",
      "rotation": 7
    },
    {
      "x": -10,
      "y": 16,
      "z": 7,
      "name": "Plant_Coral_Block_Green"
    },
    {
      "x": -10,
      "y": 29,
      "z": 7,
      "name": "Plant_Coral_Block_Green"
    },
    {
      "x": -10,
      "y": 30,
      "z": 7,
      "name": "Plant_Coral_Block_Green"
    },
    {
      "x": -10,
      "y": 6,
      "z": 8,
      "name": "Rock_Sandstone_Brick_Half",
      "rotation": 7
    },
    {
      "x": -10,
      "y": 16,
      "z": 8,
      "name": "Plant_Coral_Block_Green"
    },
    {
      "x": -10,
      "y": 17,
      "z": 8,
      "name": "Plant_Coral_Bush_Green"
    },
    {
      "x": -10,
      "y": 29,
      "z": 8,
      "name": "Plant_Coral_Block_Green"
    },
    {
      "x": -10,
      "y": 30,
      "z": 8,
      "name": "Plant_Coral_Block_Green"
    },
    {
      "x": -10,
      "y": 6,
      "z": 9,
      "name": "Rock_Sandstone_Brick_Half",
      "rotation": 7
    },
    {
      "x": -10,
      "y": 16,
      "z": 9,
      "name": "Plant_Coral_Block_Green"
    },
    {
      "x": -10,
      "y": 17,
      "z": 9,
      "name": "Plant_Coral_Bush_Green"
    },
    {
      "x": -10,
      "y": 30,
      "z": 9,
      "name": "Plant_Coral_Block_Green"
    },
    {
      "x": -10,
      "y": 6,
      "z": 10,
      "name": "Rock_Sandstone_Brick_Half",
      "rotation": 7
    },
    {
      "x": -9,
      "y": 1,
      "z": -9,
      "name": "Rock_Sandstone_Brick"
    },
    {
      "x": -9,
      "y": 2,
      "z": -9,
      "name": "Rock_Sandstone_Brick"
    },
    {
      "x": -9,
      "y": 3,
      "z": -9,
      "name": "Rock_Sandstone_White_Brick"
    },
    {
      "x": -9,
      "y": 4,
      "z": -9,
      "name": "Rock_Sandstone_Brick"
    },
    {
      "x": -9,
      "y": 5,
      "z": -9,
      "name": "Rock_Sandstone_Red_Brick"
    },
    {
      "x": -9,
      "y": 1,
      "z": -8,
      "name": "Rock_Sandstone_Brick"
    },
    {
      "x": -9,
      "y": 2,
      "z": -8,
      "name": "Rock_Sandstone_Brick"
    },
    {
      "x": -9,
      "y": 3,
      "z": -8,
      "name": "Rock_Sandstone_White_Brick"
    },
    {
      "x": -9,
      "y": 4,
      "z": -8,
      "name": "Rock_Sandstone_Brick"
    },
    {
      "x": -9,
      "y": 5,
      "z": -8,
      "name": "Rock_Sandstone_Red_Brick"
    },
    {
      "x": -9,
      "y": 23,
      "z": -8,
      "name": "Plant_Coral_Block_Green"
    },
    {
      "x": -9,
      "y": 0,
      "z": -7,
      "name": "Rock_Sandstone_Red_Cobble"
    },
    {
      "x": -9,
      "y": 1,
      "z": -7,
      "name": "Rock_Sandstone_Brick"
    },
    {
      "x": -9,
      "y": 2,
      "z": -7,
      "name": "Rock_Sandstone_Brick"
    },
    {
      "x": -9,
      "y": 3,
      "z": -7,
      "name": "Rock_Sandstone_White_Brick"
    },
    {
      "x": -9,
      "y": 4,
      "z": -7,
      "name": "Rock_Sandstone_Brick"
    },
    {
      "x": -9,
      "y": 5,
      "z": -7,
      "name": "Rock_Sandstone_Red_Brick"
    },
    {
      "x": -9,
      "y": 15,
      "z": -7,
      "name": "Plant_Coral_Block_Green",
      "rotation": 2
    },
    {
      "x": -9,
      "y": 16,
      "z": -7,
      "name": "Plant_Coral_Bush_Green",
      "rotation": 2
    },
    {
      "x": -9,
      "y": 23,
      "z": -7,
      "name": "Plant_Coral_Block_Green"
    },
    {
      "x": -9,
      "y": 0,
      "z": -6,
      "name": "Rock_Sandstone_Red_Cobble"
    },
    {
      "x": -9,
      "y": 1,
      "z": -6,
      "name": "Rock_Sandstone_Brick"
    },
    {
      "x": -9,
      "y": 2,
      "z": -6,
      "name": "Rock_Sandstone_Brick_Half"
    },
    {
      "x": -9,
      "y": 3,
      "z": -6,
      "name": "Cloth_Roof_Leather_Flap",
      "rotation": 3
    },
    {
      "x": -9,
      "y": 4,
      "z": -6,
      "name": "Rock_Sandstone_Brick"
    },
    {
      "x": -9,
      "y": 5,
      "z": -6,
      "name": "Rock_Sandstone_Red_Brick"
    },
    {
      "x": -9,
      "y": 6,
      "z": -6,
      "name": "Rock_Sandstone_Brick_Pillar_Middle"
    },
    {
      "x": -9,
      "y": 7,
      "z": -6,
      "name": "Rock_Sandstone_Brick_Pillar_Base",
      "rotation": 8
    },
    {
      "x": -9,
      "y": 8,
      "z": -6,
      "name": "Rock_Sandstone_Brick"
    },
    {
      "x": -9,
      "y": 9,
      "z": -6,
      "name": "Rock_Sandstone_Brick"
    },
    {
      "x": -9,
      "y": 15,
      "z": -6,
      "name": "Plant_Coral_Block_Green",
      "rotation": 2
    },
    {
      "x": -9,
      "y": 22,
      "z": -6,
      "name": "Plant_Coral_Block_Green"
    },
    {
      "x": -9,
      "y": 23,
      "z": -6,
      "name": "Plant_Coral_Block_Green"
    },
    {
      "x": -9,
      "y": 0,
      "z": -5,
      "name": "Rock_Sandstone_Red_Cobble"
    },
    {
      "x": -9,
      "y": 1,
      "z": -5,
      "name": "Rock_Sandstone_Brick"
    },
    {
      "x": -9,
      "y": 2,
      "z": -5,
      "name": "Rock_Sandstone_Brick"
    },
    {
      "x": -9,
      "y": 3,
      "z": -5,
      "name": "Rock_Sandstone_White_Brick"
    },
    {
      "x": -9,
      "y": 4,
      "z": -5,
      "name": "Rock_Sandstone_Brick"
    },
    {
      "x": -9,
      "y": 5,
      "z": -5,
      "name": "Rock_Sandstone_Red_Brick"
    },
    {
      "x": -9,
      "y": 6,
      "z": -5,
      "name": "Rock_Sandstone_Brick"
    },
    {
      "x": -9,
      "y": 7,
      "z": -5,
      "name": "Rock_Sandstone_Brick"
    },
    {
      "x": -9,
      "y": 8,
      "z": -5,
      "name": "Rock_Sandstone_Brick"
    },
    {
      "x": -9,
      "y": 9,
      "z": -5,
      "name": "Rock_Sandstone_Brick"
    },
    {
      "x": -9,
      "y": 10,
      "z": -5,
      "name": "Rock_Sandstone_Brick_Half",
      "rotation": 7
    },
    {
      "x": -9,
      "y": 11,
      "z": -5,
      "name": "Rock_Sandstone_Brick_Half",
      "rotation": 7
    },
    {
      "x": -9,
      "y": 12,
      "z": -5,
      "name": "Rock_Sandstone_Brick_Half",
      "rotation": 7
    },
    {
      "x": -9,
      "y": 13,
      "z": -5,
      "name": "Rock_Sandstone_Red_Brick_Half",
      "rotation": 7
    },
    {
      "x": -9,
      "y": 14,
      "z": -5,
      "name": "Rock_Sandstone_Red_Brick_Half",
      "rotation": 7
    },
    {
      "x": -9,
      "y": 15,
      "z": -5,
      "name": "Rock_Sandstone_Red_Brick_Half",
      "rotation": 7
    },
    {
      "x": -9,
      "y": 16,
      "z": -5,
      "name": "Plant_Coral_Bush_Green",
      "rotation": 2
    },
    {
      "x": -9,
      "y": 18,
      "z": -5,
      "name": "Plant_Coral_Block_Green"
    },
    {
      "x": -9,
      "y": 23,
      "z": -5,
      "name": "Plant_Coral_Block_Green"
    },
    {
      "x": -9,
      "y": 27,
      "z": -5,
      "name": "Plant_Coral_Block_Green"
    },
    {
      "x": -9,
      "y": 0,
      "z": -4,
      "name": "Rock_Sandstone_Red_Cobble"
    },
    {
      "x": -9,
      "y": 1,
      "z": -4,
      "name": "Rock_Sandstone_Brick"
    },
    {
      "x": -9,
      "y": 2,
      "z": -4,
      "name": "Rock_Sandstone_Brick"
    },
    {
      "x": -9,
      "y": 3,
      "z": -4,
      "name": "Rock_Sandstone_White_Brick"
    },
    {
      "x": -9,
      "y": 4,
      "z": -4,
      "name": "Rock_Sandstone_Brick"
    },
    {
      "x": -9,
      "y": 5,
      "z": -4,
      "name": "Rock_Sandstone_Red_Brick"
    },
    {
      "x": -9,
      "y": 6,
      "z": -4,
      "name": "Rock_Sandstone_Brick"
    },
    {
      "x": -9,
      "y": 7,
      "z": -4,
      "name": "Rock_Sandstone_Brick"
    },
    {
      "x": -9,
      "y": 8,
      "z": -4,
      "name": "Rock_Sandstone_Brick"
    },
    {
      "x": -9,
      "y": 9,
      "z": -4,
      "name": "Rock_Sandstone_Brick"
    },
    {
      "x": -9,
      "y": 10,
      "z": -4,
      "name": "Rock_Sandstone_Brick"
    },
    {
      "x": -9,
      "y": 11,
      "z": -4,
      "name": "Rock_Sandstone_Brick"
    },
    {
      "x": -9,
      "y": 12,
      "z": -4,
      "name": "Rock_Sandstone_Brick"
    },
    {
      "x": -9,
      "y": 13,
      "z": -4,
      "name": "Rock_Sandstone_Red_Brick"
    },
    {
      "x": -9,
      "y": 14,
      "z": -4,
      "name": "Rock_Sandstone_Red_Brick"
    },
    {
      "x": -9,
      "y": 15,
      "z": -4,
      "name": "Rock_Sandstone_Red_Brick"
    },
    {
      "x": -9,
      "y": 16,
      "z": -4,
      "name": "Rock_Sandstone_Brick"
    },
    {
      "x": -9,
      "y": 17,
      "z": -4,
      "name": "Rock_Sandstone_Brick"
    },
    {
      "x": -9,
      "y": 18,
      "z": -4,
      "name": "Rock_Sandstone_Brick"
    },
    {
      "x": -9,
      "y": 19,
      "z": -4,
      "name": "Rock_Sandstone_Brick"
    },
    {
      "x": -9,
      "y": 20,
      "z": -4,
      "name": "Rock_Sandstone_Brick"
    },
    {
      "x": -9,
      "y": 21,
      "z": -4,
      "name": "Rock_Sandstone_Brick"
    },
    {
      "x": -9,
      "y": 22,
      "z": -4,
      "name": "Rock_Gold_Brick_Smooth"
    },
    {
      "x": -9,
      "y": 23,
      "z": -4,
      "name": "Rock_Sandstone_Brick"
    },
    {
      "x": -9,
      "y": 24,
      "z": -4,
      "name": "Soil_Clay_Ocean_Brick_Ornate"
    },
    {
      "x": -9,
      "y": 25,
      "z": -4,
      "name": "Soil_Clay_Ocean_Brick_Ornate"
    },
    {
      "x": -9,
      "y": 26,
      "z": -4,
      "name": "Rock_Sandstone_Brick"
    },
    {
      "x": -9,
      "y": 27,
      "z": -4,
      "name": "Rock_Sandstone_Brick"
    },
    {
      "x": -9,
      "y": 28,
      "z": -4,
      "name": "Rock_Sandstone_Brick"
    },
    {
      "x": -9,
      "y": 0,
      "z": -3,
      "name": "Rock_Sandstone_Red_Cobble"
    },
    {
      "x": -9,
      "y": 1,
      "z": -3,
      "name": "Rock_Sandstone_Brick"
    },
    {
      "x": -9,
      "y": 2,
      "z": -3,
      "name": "Rock_Sandstone_Brick_Half"
    },
    {
      "x": -9,
      "y": 3,
      "z": -3,
      "name": "Cloth_Roof_Leather_Flap",
      "rotation": 3
    },
    {
      "x": -9,
      "y": 4,
      "z": -3,
      "name": "Rock_Sandstone_Brick"
    },
    {
      "x": -9,
      "y": 5,
      "z": -3,
      "name": "Rock_Sandstone_Red_Brick"
    },
    {
      "x": -9,
      "y": 6,
      "z": -3,
      "name": "Rock_Sandstone_Brick_Stairs",
      "rotation": 10
    },
    {
      "x": -9,
      "y": 7,
      "z": -3,
      "name": "Rock_Sandstone_Brick"
    },
    {
      "x": -9,
      "y": 8,
      "z": -3,
      "name": "Rock_Sandstone_Brick"
    },
    {
      "x": -9,
      "y": 9,
      "z": -3,
      "name": "Rock_Sandstone_Brick"
    },
    {
      "x": -9,
      "y": 10,
      "z": -3,
      "name": "Rock_Sandstone_Brick"
    },
    {
      "x": -9,
      "y": 11,
      "z": -3,
      "name": "Rock_Sandstone_Brick"
    },
    {
      "x": -9,
      "y": 12,
      "z": -3,
      "name": "Rock_Sandstone_Brick"
    },
    {
      "x": -9,
      "y": 13,
      "z": -3,
      "name": "Rock_Sandstone_Red_Brick"
    },
    {
      "x": -9,
      "y": 14,
      "z": -3,
      "name": "Rock_Sandstone_Red_Brick"
    },
    {
      "x": -9,
      "y": 15,
      "z": -3,
      "name": "Rock_Sandstone_Red_Brick"
    },
    {
      "x": -9,
      "y": 16,
      "z": -3,
      "name": "Rock_Sandstone_Brick"
    },
    {
      "x": -9,
      "y": 17,
      "z": -3,
      "name": "Rock_Sandstone_Brick"
    },
    {
      "x": -9,
      "y": 18,
      "z": -3,
      "name": "Rock_Sandstone_Brick"
    },
    {
      "x": -9,
      "y": 19,
      "z": -3,
      "name": "Rock_Sandstone_Brick"
    },
    {
      "x": -9,
      "y": 20,
      "z": -3,
      "name": "Rock_Sandstone_Brick"
    },
    {
      "x": -9,
      "y": 21,
      "z": -3,
      "name": "Rock_Sandstone_Brick"
    },
    {
      "x": -9,
      "y": 22,
      "z": -3,
      "name": "Rock_Gold_Brick_Smooth"
    },
    {
      "x": -9,
      "y": 23,
      "z": -3,
      "name": "Rock_Sandstone_Brick"
    },
    {
      "x": -9,
      "y": 24,
      "z": -3,
      "name": "Soil_Clay_Ocean_Brick_Ornate"
    },
    {
      "x": -9,
      "y": 25,
      "z": -3,
      "name": "Soil_Clay_Ocean_Brick_Ornate"
    },
    {
      "x": -9,
      "y": 26,
      "z": -3,
      "name": "Rock_Sandstone_Brick"
    },
    {
      "x": -9,
      "y": 27,
      "z": -3,
      "name": "Rock_Sandstone_Cobble",
      "rotation": 2
    },
    {
      "x": -9,
      "y": 28,
      "z": -3,
      "name": "Rock_Sandstone_Brick"
    },
    {
      "x": -9,
      "y": 0,
      "z": -2,
      "name": "Rock_Sandstone_Red_Cobble"
    },
    {
      "x": -9,
      "y": 1,
      "z": -2,
      "name": "Rock_Sandstone_Brick"
    },
    {
      "x": -9,
      "y": 2,
      "z": -2,
      "name": "Rock_Sandstone_Brick"
    },
    {
      "x": -9,
      "y": 3,
      "z": -2,
      "name": "Rock_Sandstone_White_Brick"
    },
    {
      "x": -9,
      "y": 4,
      "z": -2,
      "name": "Rock_Sandstone_Brick"
    },
    {
      "x": -9,
      "y": 5,
      "z": -2,
      "name": "Rock_Sandstone_Red_Brick"
    },
    {
      "x": -9,
      "y": 6,
      "z": -2,
      "name": "Rock_Sandstone_Brick_Half",
      "rotation": 8
    },
    {
      "x": -9,
      "y": 7,
      "z": -2,
      "name": "Rock_Sandstone_Brick"
    },
    {
      "x": -9,
      "y": 8,
      "z": -2,
      "name": "Rock_Sandstone_Brick"
    },
    {
      "x": -9,
      "y": 9,
      "z": -2,
      "name": "Rock_Sandstone_Brick"
    },
    {
      "x": -9,
      "y": 10,
      "z": -2,
      "name": "Rock_Sandstone_Brick"
    },
    {
      "x": -9,
      "y": 11,
      "z": -2,
      "name": "Rock_Sandstone_Brick"
    },
    {
      "x": -9,
      "y": 12,
      "z": -2,
      "name": "Rock_Sandstone_Brick"
    },
    {
      "x": -9,
      "y": 13,
      "z": -2,
      "name": "Rock_Sandstone_Red_Brick"
    },
    {
      "x": -9,
      "y": 14,
      "z": -2,
      "name": "Furniture_Desert_Window",
      "rotation": 3
    },
    {
      "x": -9,
      "y": 15,
      "z": -2,
      "name": "Furniture_Desert_Window",
      "rotation": 3
    },
    {
      "x": -9,
      "y": 16,
      "z": -2,
      "name": "Furniture_Desert_Window",
      "rotation": 3
    },
    {
      "x": -9,
      "y": 17,
      "z": -2,
      "name": "Rock_Sandstone_Brick"
    },
    {
      "x": -9,
      "y": 18,
      "z": -2,
      "name": "Rock_Sandstone_Brick"
    },
    {
      "x": -9,
      "y": 19,
      "z": -2,
      "name": "Rock_Sandstone_Brick"
    },
    {
      "x": -9,
      "y": 20,
      "z": -2,
      "name": "Rock_Sandstone_Brick"
    },
    {
      "x": -9,
      "y": 21,
      "z": -2,
      "name": "Rock_Sandstone_Brick"
    },
    {
      "x": -9,
      "y": 22,
      "z": -2,
      "name": "Rock_Gold_Brick_Smooth"
    },
    {
      "x": -9,
      "y": 23,
      "z": -2,
      "name": "Rock_Sandstone_Cobble",
      "rotation": 2
    },
    {
      "x": -9,
      "y": 24,
      "z": -2,
      "name": "Furniture_Desert_Window",
      "rotation": 3
    },
    {
      "x": -9,
      "y": 25,
      "z": -2,
      "name": "Furniture_Desert_Window",
      "rotation": 3
    },
    {
      "x": -9,
      "y": 26,
      "z": -2,
      "name": "Furniture_Desert_Window",
      "rotation": 3
    },
    {
      "x": -9,
      "y": 27,
      "z": -2,
      "name": "Rock_Sandstone_Cobble",
      "rotation": 2
    },
    {
      "x": -9,
      "y": 28,
      "z": -2,
      "name": "Rock_Sandstone_Brick"
    },
    {
      "x": -9,
      "y": 0,
      "z": -1,
      "name": "Rock_Sandstone_Red_Cobble"
    },
    {
      "x": -9,
      "y": 1,
      "z": -1,
      "name": "Rock_Sandstone_Brick"
    },
    {
      "x": -9,
      "y": 2,
      "z": -1,
      "name": "Rock_Sandstone_Brick"
    },
    {
      "x": -9,
      "y": 3,
      "z": -1,
      "name": "Rock_Sandstone_White_Brick"
    },
    {
      "x": -9,
      "y": 4,
      "z": -1,
      "name": "Rock_Sandstone_Brick"
    },
    {
      "x": -9,
      "y": 5,
      "z": -1,
      "name": "Rock_Sandstone_Red_Brick"
    },
    {
      "x": -9,
      "y": 7,
      "z": -1,
      "name": "Rock_Sandstone_Brick"
    },
    {
      "x": -9,
      "y": 8,
      "z": -1,
      "name": "Rock_Sandstone_Brick"
    },
    {
      "x": -9,
      "y": 9,
      "z": -1,
      "name": "Rock_Sandstone_Brick"
    },
    {
      "x": -9,
      "y": 10,
      "z": -1,
      "name": "Rock_Sandstone_Brick"
    },
    {
      "x": -9,
      "y": 11,
      "z": -1,
      "name": "Rock_Sandstone_Brick"
    },
    {
      "x": -9,
      "y": 12,
      "z": -1,
      "name": "Rock_Sandstone_Brick_Stairs"
    },
    {
      "x": -9,
      "y": 13,
      "z": -1,
      "name": "Rock_Sandstone_Red_Brick_Stairs",
      "rotation": 10
    },
    {
      "x": -9,
      "y": 14,
      "z": -1,
      "name": "Rock_Sandstone_Red_Brick"
    },
    {
      "x": -9,
      "y": 15,
      "z": -1,
      "name": "Rock_Sandstone_Red_Brick"
    },
    {
      "x": -9,
      "y": 16,
      "z": -1,
      "name": "Rock_Sandstone_Brick"
    },
    {
      "x": -9,
      "y": 17,
      "z": -1,
      "name": "Rock_Sandstone_Brick"
    },
    {
      "x": -9,
      "y": 18,
      "z": -1,
      "name": "Rock_Sandstone_Brick"
    },
    {
      "x": -9,
      "y": 19,
      "z": -1,
      "name": "Rock_Sandstone_Brick"
    },
    {
      "x": -9,
      "y": 20,
      "z": -1,
      "name": "Rock_Sandstone_Brick"
    },
    {
      "x": -9,
      "y": 21,
      "z": -1,
      "name": "Rock_Sandstone_Brick"
    },
    {
      "x": -9,
      "y": 22,
      "z": -1,
      "name": "Rock_Gold_Brick_Smooth"
    },
    {
      "x": -9,
      "y": 23,
      "z": -1,
      "name": "Rock_Sandstone_Brick"
    },
    {
      "x": -9,
      "y": 24,
      "z": -1,
      "name": "Soil_Clay_Ocean_Brick_Ornate"
    },
    {
      "x": -9,
      "y": 25,
      "z": -1,
      "name": "Soil_Clay_Ocean_Brick_Ornate"
    },
    {
      "x": -9,
      "y": 26,
      "z": -1,
      "name": "Rock_Sandstone_Brick"
    },
    {
      "x": -9,
      "y": 27,
      "z": -1,
      "name": "Rock_Sandstone_Cobble",
      "rotation": 2
    },
    {
      "x": -9,
      "y": 28,
      "z": -1,
      "name": "Rock_Sandstone_Brick"
    },
    {
      "x": -9,
      "y": 30,
      "z": -1,
      "name": "Plant_Coral_Block_Green"
    },
    {
      "x": -9,
      "y": 31,
      "z": -1,
      "name": "Plant_Coral_Bush_Green"
    },
    {
      "x": -9,
      "y": 0,
      "z": 0,
      "name": "Rock_Sandstone_Red_Cobble"
    },
    {
      "x": -9,
      "y": 1,
      "z": 0,
      "name": "Rock_Sandstone_Brick"
    },
    {
      "x": -9,
      "y": 2,
      "z": 0,
      "name": "Rock_Sandstone_Brick"
    },
    {
      "x": -9,
      "y": 3,
      "z": 0,
      "name": "Rock_Sandstone_White_Brick"
    },
    {
      "x": -9,
      "y": 4,
      "z": 0,
      "name": "Rock_Sandstone_Brick"
    },
    {
      "x": -9,
      "y": 5,
      "z": 0,
      "name": "Rock_Sandstone_Red_Brick"
    },
    {
      "x": -9,
      "y": 8,
      "z": 0,
      "name": "Rock_Sandstone_Brick_Half",
      "rotation": 4
    },
    {
      "x": -9,
      "y": 9,
      "z": 0,
      "name": "Rock_Sandstone_Brick_Stairs",
      "rotation": 10
    },
    {
      "x": -9,
      "y": 10,
      "z": 0,
      "name": "Rock_Sandstone_Brick"
    },
    {
      "x": -9,
      "y": 11,
      "z": 0,
      "name": "Rock_Sandstone_Brick_Stairs"
    },
    {
      "x": -9,
      "y": 13,
      "z": 0,
      "name": "Rock_Sandstone_Red_Brick_Half",
      "rotation": 6
    },
    {
      "x": -9,
      "y": 14,
      "z": 0,
      "name": "Rock_Sandstone_Red_Brick"
    },
    {
      "x": -9,
      "y": 15,
      "z": 0,
      "name": "Rock_Sandstone_Red_Brick"
    },
    {
      "x": -9,
      "y": 16,
      "z": 0,
      "name": "Rock_Sandstone_Brick"
    },
    {
      "x": -9,
      "y": 17,
      "z": 0,
      "name": "Rock_Sandstone_Brick"
    },
    {
      "x": -9,
      "y": 18,
      "z": 0,
      "name": "Rock_Sandstone_Brick"
    },
    {
      "x": -9,
      "y": 19,
      "z": 0,
      "name": "Rock_Sandstone_Brick"
    },
    {
      "x": -9,
      "y": 20,
      "z": 0,
      "name": "Rock_Sandstone_Brick"
    },
    {
      "x": -9,
      "y": 21,
      "z": 0,
      "name": "Rock_Sandstone_Brick"
    },
    {
      "x": -9,
      "y": 22,
      "z": 0,
      "name": "Rock_Gold_Brick_Smooth"
    },
    {
      "x": -9,
      "y": 23,
      "z": 0,
      "name": "Rock_Sandstone_Brick"
    },
    {
      "x": -9,
      "y": 24,
      "z": 0,
      "name": "Soil_Clay_Ocean_Brick_Ornate"
    },
    {
      "x": -9,
      "y": 25,
      "z": 0,
      "name": "Soil_Clay_Ocean_Brick_Ornate"
    },
    {
      "x": -9,
      "y": 26,
      "z": 0,
      "name": "Rock_Sandstone_Brick"
    },
    {
      "x": -9,
      "y": 27,
      "z": 0,
      "name": "Rock_Sandstone_Brick"
    },
    {
      "x": -9,
      "y": 28,
      "z": 0,
      "name": "Rock_Sandstone_Brick"
    },
    {
      "x": -9,
      "y": 29,
      "z": 0,
      "name": "Plant_Coral_Block_Green"
    },
    {
      "x": -9,
      "y": 30,
      "z": 0,
      "name": "Plant_Coral_Block_Green"
    },
    {
      "x": -9,
      "y": 0,
      "z": 1,
      "name": "Rock_Sandstone_Red_Cobble"
    },
    {
      "x": -9,
      "y": 1,
      "z": 1,
      "name": "Rock_Sandstone_Brick"
    },
    {
      "x": -9,
      "y": 2,
      "z": 1,
      "name": "Rock_Sandstone_Brick"
    },
    {
      "x": -9,
      "y": 3,
      "z": 1,
      "name": "Rock_Sandstone_White_Brick"
    },
    {
      "x": -9,
      "y": 4,
      "z": 1,
      "name": "Rock_Sandstone_Brick"
    },
    {
      "x": -9,
      "y": 5,
      "z": 1,
      "name": "Rock_Sandstone_Red_Brick"
    },
    {
      "x": -9,
      "y": 9,
      "z": 1,
      "name": "Rock_Sandstone_Brick_Half",
      "rotation": 6
    },
    {
      "x": -9,
      "y": 10,
      "z": 1,
      "name": "Rock_Sandstone_Brick"
    },
    {
      "x": -9,
      "y": 11,
      "z": 1,
      "name": "Rock_Sandstone_Brick_Half",
      "rotation": 6
    },
    {
      "x": -9,
      "y": 12,
      "z": 1,
      "name": "Rock_Sandstone_Brick_Stairs",
      "rotation": 8
    },
    {
      "x": -9,
      "y": 13,
      "z": 1,
      "name": "Rock_Sandstone_Red_Brick"
    },
    {
      "x": -9,
      "y": 14,
      "z": 1,
      "name": "Rock_Sandstone_Red_Brick"
    },
    {
      "x": -9,
      "y": 15,
      "z": 1,
      "name": "Rock_Sandstone_Red_Brick"
    },
    {
      "x": -9,
      "y": 16,
      "z": 1,
      "name": "Rock_Sandstone_Brick"
    },
    {
      "x": -9,
      "y": 17,
      "z": 1,
      "name": "Rock_Sandstone_Brick"
    },
    {
      "x": -9,
      "y": 18,
      "z": 1,
      "name": "Rock_Sandstone_Brick"
    },
    {
      "x": -9,
      "y": 19,
      "z": 1,
      "name": "Rock_Sandstone_Brick"
    },
    {
      "x": -9,
      "y": 20,
      "z": 1,
      "name": "Rock_Sandstone_Brick"
    },
    {
      "x": -9,
      "y": 21,
      "z": 1,
      "name": "Rock_Sandstone_Brick"
    },
    {
      "x": -9,
      "y": 22,
      "z": 1,
      "name": "Rock_Gold_Brick_Smooth"
    },
    {
      "x": -9,
      "y": 23,
      "z": 1,
      "name": "Rock_Sandstone_Brick"
    },
    {
      "x": -9,
      "y": 24,
      "z": 1,
      "name": "Soil_Clay_Ocean_Brick_Ornate"
    },
    {
      "x": -9,
      "y": 25,
      "z": 1,
      "name": "Soil_Clay_Ocean_Brick_Ornate"
    },
    {
      "x": -9,
      "y": 26,
      "z": 1,
      "name": "Rock_Sandstone_Brick"
    },
    {
      "x": -9,
      "y": 27,
      "z": 1,
      "name": "Rock_Sandstone_Cobble",
      "rotation": 2
    },
    {
      "x": -9,
      "y": 28,
      "z": 1,
      "name": "Rock_Sandstone_Brick"
    },
    {
      "x": -9,
      "y": 29,
      "z": 1,
      "name": "Plant_Coral_Block_Green"
    },
    {
      "x": -9,
      "y": 30,
      "z": 1,
      "name": "Plant_Coral_Block_Green"
    },
    {
      "x": -9,
      "y": 0,
      "z": 2,
      "name": "Rock_Sandstone_Red_Cobble"
    },
    {
      "x": -9,
      "y": 1,
      "z": 2,
      "name": "Rock_Sandstone_Brick"
    },
    {
      "x": -9,
      "y": 2,
      "z": 2,
      "name": "Rock_Sandstone_Brick"
    },
    {
      "x": -9,
      "y": 3,
      "z": 2,
      "name": "Rock_Sandstone_White_Brick"
    },
    {
      "x": -9,
      "y": 4,
      "z": 2,
      "name": "Rock_Sandstone_Brick"
    },
    {
      "x": -9,
      "y": 5,
      "z": 2,
      "name": "Rock_Sandstone_Red_Brick"
    },
    {
      "x": -9,
      "y": 8,
      "z": 2,
      "name": "Rock_Sandstone_Brick_Stairs",
      "rotation": 8
    },
    {
      "x": -9,
      "y": 9,
      "z": 2,
      "name": "Rock_Sandstone_Brick"
    },
    {
      "x": -9,
      "y": 10,
      "z": 2,
      "name": "Rock_Sandstone_Brick"
    },
    {
      "x": -9,
      "y": 11,
      "z": 2,
      "name": "Rock_Sandstone_Brick"
    },
    {
      "x": -9,
      "y": 12,
      "z": 2,
      "name": "Rock_Sandstone_Brick"
    },
    {
      "x": -9,
      "y": 13,
      "z": 2,
      "name": "Rock_Sandstone_Red_Brick"
    },
    {
      "x": -9,
      "y": 14,
      "z": 2,
      "name": "Furniture_Desert_Window",
      "rotation": 3
    },
    {
      "x": -9,
      "y": 15,
      "z": 2,
      "name": "Furniture_Desert_Window",
      "rotation": 3
    },
    {
      "x": -9,
      "y": 16,
      "z": 2,
      "name": "Furniture_Desert_Window",
      "rotation": 3
    },
    {
      "x": -9,
      "y": 17,
      "z": 2,
      "name": "Rock_Sandstone_Brick"
    },
    {
      "x": -9,
      "y": 18,
      "z": 2,
      "name": "Rock_Sandstone_Brick"
    },
    {
      "x": -9,
      "y": 19,
      "z": 2,
      "name": "Rock_Sandstone_Brick"
    },
    {
      "x": -9,
      "y": 20,
      "z": 2,
      "name": "Rock_Sandstone_Brick"
    },
    {
      "x": -9,
      "y": 21,
      "z": 2,
      "name": "Rock_Sandstone_Brick"
    },
    {
      "x": -9,
      "y": 22,
      "z": 2,
      "name": "Rock_Gold_Brick_Smooth"
    },
    {
      "x": -9,
      "y": 23,
      "z": 2,
      "name": "Rock_Sandstone_Cobble",
      "rotation": 2
    },
    {
      "x": -9,
      "y": 24,
      "z": 2,
      "name": "Furniture_Desert_Window",
      "rotation": 3
    },
    {
      "x": -9,
      "y": 25,
      "z": 2,
      "name": "Furniture_Desert_Window",
      "rotation": 3
    },
    {
      "x": -9,
      "y": 26,
      "z": 2,
      "name": "Furniture_Desert_Window",
      "rotation": 3
    },
    {
      "x": -9,
      "y": 27,
      "z": 2,
      "name": "Rock_Sandstone_Cobble",
      "rotation": 2
    },
    {
      "x": -9,
      "y": 28,
      "z": 2,
      "name": "Plant_Coral_Block_Green"
    },
    {
      "x": -9,
      "y": 29,
      "z": 2,
      "name": "Plant_Coral_Block_Green"
    },
    {
      "x": -9,
      "y": 0,
      "z": 3,
      "name": "Rock_Sandstone_Red_Cobble"
    },
    {
      "x": -9,
      "y": 1,
      "z": 3,
      "name": "Rock_Sandstone_Brick"
    },
    {
      "x": -9,
      "y": 2,
      "z": 3,
      "name": "Rock_Sandstone_Brick_Half"
    },
    {
      "x": -9,
      "y": 3,
      "z": 3,
      "name": "Cloth_Roof_Leather_Flap",
      "rotation": 1
    },
    {
      "x": -9,
      "y": 4,
      "z": 3,
      "name": "Rock_Sandstone_Brick"
    },
    {
      "x": -9,
      "y": 5,
      "z": 3,
      "name": "Rock_Sandstone_Red_Brick"
    },
    {
      "x": -9,
      "y": 6,
      "z": 3,
      "name": "Rock_Sandstone_Brick"
    },
    {
      "x": -9,
      "y": 7,
      "z": 3,
      "name": "Rock_Sandstone_Brick"
    },
    {
      "x": -9,
      "y": 8,
      "z": 3,
      "name": "Rock_Sandstone_Brick"
    },
    {
      "x": -9,
      "y": 9,
      "z": 3,
      "name": "Rock_Sandstone_Brick"
    },
    {
      "x": -9,
      "y": 10,
      "z": 3,
      "name": "Rock_Sandstone_Brick"
    },
    {
      "x": -9,
      "y": 11,
      "z": 3,
      "name": "Rock_Sandstone_Brick"
    },
    {
      "x": -9,
      "y": 12,
      "z": 3,
      "name": "Rock_Sandstone_Brick"
    },
    {
      "x": -9,
      "y": 13,
      "z": 3,
      "name": "Rock_Sandstone_Red_Brick"
    },
    {
      "x": -9,
      "y": 14,
      "z": 3,
      "name": "Rock_Sandstone_Red_Brick"
    },
    {
      "x": -9,
      "y": 15,
      "z": 3,
      "name": "Rock_Sandstone_Red_Brick"
    },
    {
      "x": -9,
      "y": 16,
      "z": 3,
      "name": "Rock_Sandstone_Brick"
    },
    {
      "x": -9,
      "y": 17,
      "z": 3,
      "name": "Rock_Sandstone_Brick"
    },
    {
      "x": -9,
      "y": 18,
      "z": 3,
      "name": "Rock_Sandstone_Brick"
    },
    {
      "x": -9,
      "y": 19,
      "z": 3,
      "name": "Rock_Sandstone_Brick"
    },
    {
      "x": -9,
      "y": 20,
      "z": 3,
      "name": "Rock_Sandstone_Brick"
    },
    {
      "x": -9,
      "y": 21,
      "z": 3,
      "name": "Rock_Sandstone_Brick"
    },
    {
      "x": -9,
      "y": 22,
      "z": 3,
      "name": "Rock_Gold_Brick_Smooth"
    },
    {
      "x": -9,
      "y": 23,
      "z": 3,
      "name": "Rock_Sandstone_Brick"
    },
    {
      "x": -9,
      "y": 24,
      "z": 3,
      "name": "Soil_Clay_Ocean_Brick_Ornate"
    },
    {
      "x": -9,
      "y": 25,
      "z": 3,
      "name": "Soil_Clay_Ocean_Brick_Ornate"
    },
    {
      "x": -9,
      "y": 26,
      "z": 3,
      "name": "Rock_Sandstone_Brick"
    },
    {
      "x": -9,
      "y": 27,
      "z": 3,
      "name": "Rock_Sandstone_Cobble",
      "rotation": 2
    },
    {
      "x": -9,
      "y": 28,
      "z": 3,
      "name": "Plant_Coral_Block_Green"
    },
    {
      "x": -9,
      "y": 29,
      "z": 3,
      "name": "Plant_Coral_Block_Green"
    },
    {
      "x": -9,
      "y": 0,
      "z": 4,
      "name": "Rock_Sandstone_Red_Cobble_Half",
      "rotation": 4
    },
    {
      "x": -9,
      "y": 2,
      "z": 4,
      "name": "Rock_Sandstone_Brick"
    },
    {
      "x": -9,
      "y": 3,
      "z": 4,
      "name": "Rock_Sandstone_White_Brick"
    },
    {
      "x": -9,
      "y": 4,
      "z": 4,
      "name": "Rock_Sandstone_Brick"
    },
    {
      "x": -9,
      "y": 5,
      "z": 4,
      "name": "Rock_Sandstone_Red_Brick"
    },
    {
      "x": -9,
      "y": 6,
      "z": 4,
      "name": "Rock_Sandstone_Brick"
    },
    {
      "x": -9,
      "y": 7,
      "z": 4,
      "name": "Rock_Sandstone_Brick"
    },
    {
      "x": -9,
      "y": 8,
      "z": 4,
      "name": "Rock_Sandstone_Brick"
    },
    {
      "x": -9,
      "y": 9,
      "z": 4,
      "name": "Rock_Sandstone_Brick"
    },
    {
      "x": -9,
      "y": 10,
      "z": 4,
      "name": "Rock_Sandstone_Brick_Half",
      "rotation": 8
    },
    {
      "x": -9,
      "y": 11,
      "z": 4,
      "name": "Rock_Sandstone_Brick"
    },
    {
      "x": -9,
      "y": 12,
      "z": 4,
      "name": "Rock_Sandstone_Brick"
    },
    {
      "x": -9,
      "y": 13,
      "z": 4,
      "name": "Rock_Sandstone_Red_Brick"
    },
    {
      "x": -9,
      "y": 14,
      "z": 4,
      "name": "Rock_Sandstone_Red_Brick"
    },
    {
      "x": -9,
      "y": 15,
      "z": 4,
      "name": "Rock_Sandstone_Red_Brick"
    },
    {
      "x": -9,
      "y": 16,
      "z": 4,
      "name": "Rock_Sandstone_Brick",
      "support": 15
    },
    {
      "x": -9,
      "y": 17,
      "z": 4,
      "name": "Rock_Sandstone_Brick"
    },
    {
      "x": -9,
      "y": 18,
      "z": 4,
      "name": "Rock_Sandstone_Brick"
    },
    {
      "x": -9,
      "y": 19,
      "z": 4,
      "name": "Rock_Sandstone_Brick"
    },
    {
      "x": -9,
      "y": 20,
      "z": 4,
      "name": "Rock_Sandstone_Brick"
    },
    {
      "x": -9,
      "y": 21,
      "z": 4,
      "name": "Rock_Sandstone_Brick"
    },
    {
      "x": -9,
      "y": 22,
      "z": 4,
      "name": "Rock_Gold_Brick_Smooth"
    },
    {
      "x": -9,
      "y": 23,
      "z": 4,
      "name": "Rock_Sandstone_Brick"
    },
    {
      "x": -9,
      "y": 24,
      "z": 4,
      "name": "Soil_Clay_Ocean_Brick_Ornate"
    },
    {
      "x": -9,
      "y": 25,
      "z": 4,
      "name": "Soil_Clay_Ocean_Brick_Ornate"
    },
    {
      "x": -9,
      "y": 26,
      "z": 4,
      "name": "Rock_Sandstone_Brick"
    },
    {
      "x": -9,
      "y": 27,
      "z": 4,
      "name": "Rock_Sandstone_Brick"
    },
    {
      "x": -9,
      "y": 28,
      "z": 4,
      "name": "Plant_Coral_Block_Green"
    },
    {
      "x": -9,
      "y": 29,
      "z": 4,
      "name": "Plant_Coral_Block_Green"
    },
    {
      "x": -9,
      "y": 3,
      "z": 5,
      "name": "Rock_Sandstone_White_Brick"
    },
    {
      "x": -9,
      "y": 4,
      "z": 5,
      "name": "Rock_Sandstone_Brick"
    },
    {
      "x": -9,
      "y": 5,
      "z": 5,
      "name": "Rock_Sandstone_Red_Brick"
    },
    {
      "x": -9,
      "y": 6,
      "z": 5,
      "name": "Rock_Sandstone_Brick"
    },
    {
      "x": -9,
      "y": 7,
      "z": 5,
      "name": "Rock_Sandstone_Brick_Stairs",
      "rotation": 10
    },
    {
      "x": -9,
      "y": 8,
      "z": 5,
      "name": "Rock_Sandstone_Brick"
    },
    {
      "x": -9,
      "y": 9,
      "z": 5,
      "name": "Rock_Sandstone_Brick"
    },
    {
      "x": -9,
      "y": 11,
      "z": 5,
      "name": "Rock_Sandstone_Brick"
    },
    {
      "x": -9,
      "y": 12,
      "z": 5,
      "name": "Rock_Sandstone_Brick"
    },
    {
      "x": -9,
      "y": 13,
      "z": 5,
      "name": "Rock_Sandstone_Red_Brick"
    },
    {
      "x": -9,
      "y": 14,
      "z": 5,
      "name": "Rock_Sandstone_Red_Brick"
    },
    {
      "x": -9,
      "y": 15,
      "z": 5,
      "name": "Rock_Gold_Brick_Wall",
      "rotation": 1
    },
    {
      "x": -9,
      "y": 16,
      "z": 5,
      "name": "Rock_Sandstone_Brick"
    },
    {
      "x": -9,
      "y": 17,
      "z": 5,
      "name": "Rock_Sandstone_Brick"
    },
    {
      "x": -9,
      "y": 20,
      "z": 5,
      "name": "Plant_Coral_Block_Green"
    },
    {
      "x": -9,
      "y": 25,
      "z": 5,
      "name": "Plant_Coral_Block_Green"
    },
    {
      "x": -9,
      "y": 28,
      "z": 5,
      "name": "Plant_Coral_Block_Green"
    },
    {
      "x": -9,
      "y": 29,
      "z": 5,
      "name": "Plant_Coral_Block_Green"
    },
    {
      "x": -9,
      "y": 4,
      "z": 6,
      "name": "Rock_Sandstone_Brick"
    },
    {
      "x": -9,
      "y": 5,
      "z": 6,
      "name": "Rock_Sandstone_Red_Brick"
    },
    {
      "x": -9,
      "y": 6,
      "z": 6,
      "name": "Rock_Sandstone_Brick"
    },
    {
      "x": -9,
      "y": 8,
      "z": 6,
      "name": "Rock_Sandstone_Brick"
    },
    {
      "x": -9,
      "y": 9,
      "z": 6,
      "name": "Rock_Sandstone_Brick"
    },
    {
      "x": -9,
      "y": 10,
      "z": 6,
      "name": "Rock_Sandstone_Brick_Half"
    },
    {
      "x": -9,
      "y": 11,
      "z": 6,
      "name": "Rock_Sandstone_Brick_Half",
      "rotation": 8
    },
    {
      "x": -9,
      "y": 12,
      "z": 6,
      "name": "Rock_Sandstone_Brick"
    },
    {
      "x": -9,
      "y": 13,
      "z": 6,
      "name": "Rock_Sandstone_Red_Brick"
    },
    {
      "x": -9,
      "y": 14,
      "z": 6,
      "name": "Rock_Sandstone_Red_Brick"
    },
    {
      "x": -9,
      "y": 15,
      "z": 6,
      "name": "Rock_Sandstone_Red_Brick"
    },
    {
      "x": -9,
      "y": 16,
      "z": 6,
      "name": "Rock_Sandstone_Brick"
    },
    {
      "x": -9,
      "y": 17,
      "z": 6,
      "name": "Rock_Sandstone_Brick"
    },
    {
      "x": -9,
      "y": 18,
      "z": 6,
      "name": "Rock_Sandstone_Brick_Half"
    },
    {
      "x": -9,
      "y": 25,
      "z": 6,
      "name": "Plant_Coral_Block_Green"
    },
    {
      "x": -9,
      "y": 28,
      "z": 6,
      "name": "Plant_Coral_Block_Green"
    },
    {
      "x": -9,
      "y": 29,
      "z": 6,
      "name": "Plant_Coral_Block_Green"
    },
    {
      "x": -9,
      "y": 30,
      "z": 6,
      "name": "Plant_Coral_Bush_Green"
    },
    {
      "x": -9,
      "y": 5,
      "z": 7,
      "name": "Rock_Sandstone_Red_Brick"
    },
    {
      "x": -9,
      "y": 6,
      "z": 7,
      "name": "Rock_Sandstone_Brick"
    },
    {
      "x": -9,
      "y": 7,
      "z": 7,
      "name": "Rock_Sandstone_Brick_Stairs",
      "rotation": 8
    },
    {
      "x": -9,
      "y": 8,
      "z": 7,
      "name": "Rock_Sandstone_Brick"
    },
    {
      "x": -9,
      "y": 9,
      "z": 7,
      "name": "Rock_Sandstone_Brick"
    },
    {
      "x": -9,
      "y": 10,
      "z": 7,
      "name": "Rock_Sandstone_Brick_Half"
    },
    {
      "x": -9,
      "y": 11,
      "z": 7,
      "name": "Rock_Sandstone_Brick_Half",
      "rotation": 8
    },
    {
      "x": -9,
      "y": 12,
      "z": 7,
      "name": "Rock_Sandstone_Brick"
    },
    {
      "x": -9,
      "y": 13,
      "z": 7,
      "name": "Rock_Sandstone_Red_Brick"
    },
    {
      "x": -9,
      "y": 14,
      "z": 7,
      "name": "Rock_Sandstone_Red_Brick"
    },
    {
      "x": -9,
      "y": 15,
      "z": 7,
      "name": "Rock_Gold_Brick_Wall",
      "rotation": 1
    },
    {
      "x": -9,
      "y": 16,
      "z": 7,
      "name": "Rock_Sandstone_Brick"
    },
    {
      "x": -9,
      "y": 17,
      "z": 7,
      "name": "Rock_Sandstone_Brick"
    },
    {
      "x": -9,
      "y": 29,
      "z": 7,
      "name": "Plant_Coral_Block_Green"
    },
    {
      "x": -9,
      "y": 30,
      "z": 7,
      "name": "Plant_Coral_Block_Green"
    },
    {
      "x": -9,
      "y": 5,
      "z": 8,
      "name": "Rock_Sandstone_Red_Brick"
    },
    {
      "x": -9,
      "y": 6,
      "z": 8,
      "name": "Rock_Sandstone_Brick"
    },
    {
      "x": -9,
      "y": 7,
      "z": 8,
      "name": "Rock_Sandstone_Brick"
    },
    {
      "x": -9,
      "y": 8,
      "z": 8,
      "name": "Rock_Sandstone_Brick"
    },
    {
      "x": -9,
      "y": 9,
      "z": 8,
      "name": "Rock_Sandstone_Brick"
    },
    {
      "x": -9,
      "y": 11,
      "z": 8,
      "name": "Rock_Sandstone_Brick_Half",
      "rotation": 8
    },
    {
      "x": -9,
      "y": 12,
      "z": 8,
      "name": "Rock_Sandstone_Brick"
    },
    {
      "x": -9,
      "y": 13,
      "z": 8,
      "name": "Rock_Sandstone_Red_Brick"
    },
    {
      "x": -9,
      "y": 14,
      "z": 8,
      "name": "Rock_Sandstone_Red_Brick"
    },
    {
      "x": -9,
      "y": 15,
      "z": 8,
      "name": "Rock_Sandstone_Red_Brick"
    },
    {
      "x": -9,
      "y": 16,
      "z": 8,
      "name": "Rock_Sandstone_Brick"
    },
    {
      "x": -9,
      "y": 17,
      "z": 8,
      "name": "Rock_Sandstone_Brick"
    },
    {
      "x": -9,
      "y": 18,
      "z": 8,
      "name": "Rock_Sandstone_Brick_Half"
    },
    {
      "x": -9,
      "y": 29,
      "z": 8,
      "name": "Plant_Coral_Block_Green"
    },
    {
      "x": -9,
      "y": 30,
      "z": 8,
      "name": "Plant_Coral_Block_Green"
    },
    {
      "x": -9,
      "y": 6,
      "z": 9,
      "name": "Rock_Sandstone_Brick"
    },
    {
      "x": -9,
      "y": 7,
      "z": 9,
      "name": "Rock_Sandstone_Brick"
    },
    {
      "x": -9,
      "y": 8,
      "z": 9,
      "name": "Rock_Sandstone_Brick"
    },
    {
      "x": -9,
      "y": 12,
      "z": 9,
      "name": "Rock_Sandstone_Brick_Half",
      "rotation": 4
    },
    {
      "x": -9,
      "y": 14,
      "z": 9,
      "name": "Rock_Sandstone_Red_Brick"
    },
    {
      "x": -9,
      "y": 15,
      "z": 9,
      "name": "Rock_Gold_Brick_Wall",
      "rotation": 1
    },
    {
      "x": -9,
      "y": 16,
      "z": 9,
      "name": "Rock_Sandstone_Brick"
    },
    {
      "x": -9,
      "y": 17,
      "z": 9,
      "name": "Rock_Sandstone_Brick"
    },
    {
      "x": -9,
      "y": 30,
      "z": 9,
      "name": "Plant_Coral_Block_Green"
    },
    {
      "x": -9,
      "y": 6,
      "z": 10,
      "name": "Rock_Sandstone_Brick"
    },
    {
      "x": -9,
      "y": 7,
      "z": 10,
      "name": "Rock_Sandstone_Brick"
    },
    {
      "x": -9,
      "y": 8,
      "z": 10,
      "name": "Rock_Sandstone_Brick_Half",
      "rotation": 7
    },
    {
      "x": -9,
      "y": 9,
      "z": 10,
      "name": "Rock_Sandstone_Brick_Half",
      "rotation": 7
    },
    {
      "x": -9,
      "y": 15,
      "z": 10,
      "name": "Rock_Sandstone_Red_Brick_Half",
      "rotation": 7
    },
    {
      "x": -9,
      "y": 16,
      "z": 10,
      "name": "Rock_Sandstone_Brick"
    },
    {
      "x": -9,
      "y": 17,
      "z": 10,
      "name": "Rock_Sandstone_Brick"
    },
    {
      "x": -9,
      "y": 18,
      "z": 10,
      "name": "Rock_Sandstone_Brick_Half"
    },
    {
      "x": -9,
      "y": 6,
      "z": 11,
      "name": "Rock_Sandstone_Brick_Half",
      "rotation": 4
    },
    {
      "x": -9,
      "y": 16,
      "z": 11,
      "name": "Rock_Sandstone_Brick"
    },
    {
      "x": -9,
      "y": 17,
      "z": 11,
      "name": "Rock_Sandstone_Brick"
    },
    {
      "x": -8,
      "y": 1,
      "z": -9,
      "name": "Rock_Sandstone_Brick"
    },
    {
      "x": -8,
      "y": 2,
      "z": -9,
      "name": "Rock_Sandstone_Brick"
    },
    {
      "x": -8,
      "y": 3,
      "z": -9,
      "name": "Rock_Sandstone_White_Brick"
    },
    {
      "x": -8,
      "y": 4,
      "z": -9,
      "name": "Rock_Sandstone_Brick"
    },
    {
      "x": -8,
      "y": 5,
      "z": -9,
      "name": "Rock_Sandstone_Red_Brick"
    },
    {
      "x": -8,
      "y": 5,
      "z": -8,
      "name": "Rock_Sandstone_Red_Brick"
    },
    {
      "x": -8,
      "y": 23,
      "z": -8,
      "name": "Plant_Coral_Block_Green"
    },
    {
      "x": -8,
      "y": 24,
      "z": -8,
      "name": "Plant_Coral_Bush_Green"
    },
    {
      "x": -8,
      "y": 5,
      "z": -7,
      "name": "Rock_Sandstone_Red_Brick"
    },
    {
      "x": -8,
      "y": 15,
      "z": -7,
      "name": "Plant_Coral_Block_Green",
      "rotation": 2
    },
    {
      "x": -8,
      "y": 22,
      "z": -7,
      "name": "Plant_Coral_Block_Green"
    },
    {
      "x": -8,
      "y": 23,
      "z": -7,
      "name": "Plant_Coral_Block_Green"
    },
    {
      "x": -8,
      "y": 0,
      "z": -6,
      "name": "Rock_Sandstone_Red_Cobble"
    },
    {
      "x": -8,
      "y": 5,
      "z": -6,
      "name": "Rock_Sandstone_Red_Brick"
    },
    {
      "x": -8,
      "y": 6,
      "z": -6,
      "name": "Rock_Sandstone_Brick"
    },
    {
      "x": -8,
      "y": 7,
      "z": -6,
      "name": "Rock_Sandstone_Brick"
    },
    {
      "x": -8,
      "y": 8,
      "z": -6,
      "name": "Rock_Sandstone_Brick"
    },
    {
      "x": -8,
      "y": 9,
      "z": -6,
      "name": "Rock_Sandstone_Brick"
    },
    {
      "x": -8,
      "y": 10,
      "z": -6,
      "name": "Rock_Sandstone_Brick_Half",
      "rotation": 6
    },
    {
      "x": -8,
      "y": 11,
      "z": -6,
      "name": "Rock_Sandstone_Brick_Half",
      "rotation": 6
    },
    {
      "x": -8,
      "y": 12,
      "z": -6,
      "name": "Rock_Sandstone_Brick_Half",
      "rotation": 6
    },
    {
      "x": -8,
      "y": 13,
      "z": -6,
      "name": "Rock_Sandstone_Red_Brick_Half",
      "rotation": 6
    },
    {
      "x": -8,
      "y": 14,
      "z": -6,
      "name": "Rock_Sandstone_Red_Brick_Half",
      "rotation": 6
    },
    {
      "x": -8,
      "y": 15,
      "z": -6,
      "name": "Rock_Sandstone_Red_Brick_Half",
      "rotation": 6
    },
    {
      "x": -8,
      "y": 22,
      "z": -6,
      "name": "Plant_Coral_Block_Green"
    },
    {
      "x": -8,
      "y": 23,
      "z": -6,
      "name": "Plant_Coral_Block_Green"
    },
    {
      "x": -8,
      "y": 24,
      "z": -6,
      "name": "Plant_Coral_Bush_Green"
    },
    {
      "x": -8,
      "y": 0,
      "z": -5,
      "name": "Rock_Sandstone_Red_Cobble"
    },
    {
      "x": -8,
      "y": 5,
      "z": -5,
      "name": "Rock_Sandstone_Red_Brick"
    },
    {
      "x": -8,
      "y": 6,
      "z": -5,
      "name": "Rock_Sandstone_Brick"
    },
    {
      "x": -8,
      "y": 7,
      "z": -5,
      "name": "Rock_Sandstone_Brick"
    },
    {
      "x": -8,
      "y": 8,
      "z": -5,
      "name": "Rock_Sandstone_Brick"
    },
    {
      "x": -8,
      "y": 9,
      "z": -5,
      "name": "Rock_Sandstone_Brick"
    },
    {
      "x": -8,
      "y": 10,
      "z": -5,
      "name": "Rock_Sandstone_Brick"
    },
    {
      "x": -8,
      "y": 11,
      "z": -5,
      "name": "Rock_Sandstone_Brick"
    },
    {
      "x": -8,
      "y": 12,
      "z": -5,
      "name": "Rock_Sandstone_Brick"
    },
    {
      "x": -8,
      "y": 13,
      "z": -5,
      "name": "Rock_Sandstone_Red_Brick"
    },
    {
      "x": -8,
      "y": 14,
      "z": -5,
      "name": "Rock_Sandstone_Red_Brick"
    },
    {
      "x": -8,
      "y": 15,
      "z": -5,
      "name": "Rock_Sandstone_Red_Brick"
    },
    {
      "x": -8,
      "y": 16,
      "z": -5,
      "name": "Rock_Sandstone_Brick"
    },
    {
      "x": -8,
      "y": 17,
      "z": -5,
      "name": "Rock_Sandstone_Brick"
    },
    {
      "x": -8,
      "y": 18,
      "z": -5,
      "name": "Rock_Sandstone_Brick"
    },
    {
      "x": -8,
      "y": 19,
      "z": -5,
      "name": "Rock_Sandstone_Brick"
    },
    {
      "x": -8,
      "y": 20,
      "z": -5,
      "name": "Rock_Sandstone_Brick"
    },
    {
      "x": -8,
      "y": 21,
      "z": -5,
      "name": "Rock_Sandstone_Brick"
    },
    {
      "x": -8,
      "y": 22,
      "z": -5,
      "name": "Rock_Gold_Brick_Smooth"
    },
    {
      "x": -8,
      "y": 23,
      "z": -5,
      "name": "Rock_Sandstone_Brick"
    },
    {
      "x": -8,
      "y": 24,
      "z": -5,
      "name": "Soil_Clay_Ocean_Brick_Ornate"
    },
    {
      "x": -8,
      "y": 25,
      "z": -5,
      "name": "Soil_Clay_Ocean_Brick_Ornate"
    },
    {
      "x": -8,
      "y": 26,
      "z": -5,
      "name": "Rock_Sandstone_Brick"
    },
    {
      "x": -8,
      "y": 27,
      "z": -5,
      "name": "Rock_Sandstone_Brick"
    },
    {
      "x": -8,
      "y": 28,
      "z": -5,
      "name": "Rock_Sandstone_Brick"
    },
    {
      "x": -8,
      "y": 0,
      "z": -4,
      "name": "Rock_Sandstone_Red_Cobble"
    },
    {
      "x": -8,
      "y": 5,
      "z": -4,
      "name": "Rock_Sandstone_Red_Brick"
    },
    {
      "x": -8,
      "y": 7,
      "z": -4,
      "name": "Rock_Sandstone_Brick"
    },
    {
      "x": -8,
      "y": 8,
      "z": -4,
      "name": "Rock_Sandstone_Brick"
    },
    {
      "x": -8,
      "y": 9,
      "z": -4,
      "name": "Rock_Sandstone_Brick"
    },
    {
      "x": -8,
      "y": 10,
      "z": -4,
      "name": "Rock_Sandstone_Brick"
    },
    {
      "x": -8,
      "y": 11,
      "z": -4,
      "name": "Rock_Sandstone_Brick"
    },
    {
      "x": -8,
      "y": 16,
      "z": -4,
      "name": "Rock_Sandstone_Brick"
    },
    {
      "x": -8,
      "y": 17,
      "z": -4,
      "name": "Wood_Drywood_Planks"
    },
    {
      "x": -8,
      "y": 18,
      "z": -4,
      "name": "Plant_Coral_Block_Green"
    },
    {
      "x": -8,
      "y": 23,
      "z": -4,
      "name": "Plant_Coral_Block_Green"
    },
    {
      "x": -8,
      "y": 24,
      "z": -4,
      "name": "Plant_Coral_Bush_Green"
    },
    {
      "x": -8,
      "y": 27,
      "z": -4,
      "name": "Plant_Coral_Block_Green"
    },
    {
      "x": -8,
      "y": 28,
      "z": -4,
      "name": "Rock_Sandstone_Brick"
    },
    {
      "x": -8,
      "y": 29,
      "z": -4,
      "name": "*Rock_Sandstone_Brick_Stairs_State_Definitions_Corner_Right",
      "rotation": 3
    },
    {
      "x": -8,
      "y": 0,
      "z": -3,
      "name": "Rock_Sandstone_Red_Cobble"
    },
    {
      "x": -8,
      "y": 5,
      "z": -3,
      "name": "Rock_Sandstone_Red_Brick"
    },
    {
      "x": -8,
      "y": 10,
      "z": -3,
      "name": "Rock_Sandstone_Brick"
    },
    {
      "x": -8,
      "y": 11,
      "z": -3,
      "name": "Rock_Sandstone_Brick"
    },
    {
      "x": -8,
      "y": 17,
      "z": -3,
      "name": "Wood_Drywood_Planks"
    },
    {
      "x": -8,
      "y": 18,
      "z": -3,
      "name": "Plant_Coral_Block_Green"
    },
    {
      "x": -8,
      "y": 19,
      "z": -3,
      "name": "Plant_Coral_Bush_Green"
    },
    {
      "x": -8,
      "y": 27,
      "z": -3,
      "name": "Plant_Coral_Block_Green"
    },
    {
      "x": -8,
      "y": 28,
      "z": -3,
      "name": "Rock_Sandstone_Brick"
    },
    {
      "x": -8,
      "y": 29,
      "z": -3,
      "name": "Rock_Sandstone_Brick_Stairs",
      "rotation": 3
    },
    {
      "x": -8,
      "y": 34,
      "z": -3,
      "name": "Rock_Sandstone_Brick_Stairs",
      "rotation": 9
    },
    {
      "x": -8,
      "y": 35,
      "z": -3,
      "name": "Soil_Clay_Ocean_Brick_Smooth",
      "rotation": 3
    },
    {
      "x": -8,
      "y": 0,
      "z": -2,
      "name": "Rock_Sandstone_Red_Cobble"
    },
    {
      "x": -8,
      "y": 5,
      "z": -2,
      "name": "Rock_Sandstone_Red_Brick"
    },
    {
      "x": -8,
      "y": 10,
      "z": -2,
      "name": "Rock_Sandstone_Brick"
    },
    {
      "x": -8,
      "y": 11,
      "z": -2,
      "name": "Rock_Sandstone_Brick"
    },
    {
      "x": -8,
      "y": 17,
      "z": -2,
      "name": "Wood_Drywood_Planks"
    },
    {
      "x": -8,
      "y": 18,
      "z": -2,
      "name": "Plant_Coral_Block_Green"
    },
    {
      "x": -8,
      "y": 23,
      "z": -2,
      "name": "Plant_Coral_Block_Green"
    },
    {
      "x": -8,
      "y": 27,
      "z": -2,
      "name": "Plant_Coral_Block_Green"
    },
    {
      "x": -8,
      "y": 28,
      "z": -2,
      "name": "Rock_Sandstone_Brick"
    },
    {
      "x": -8,
      "y": 29,
      "z": -2,
      "name": "Rock_Sandstone_Brick_Stairs",
      "rotation": 3
    },
    {
      "x": -8,
      "y": 34,
      "z": -2,
      "name": "Rock_Sandstone_Brick_Stairs",
      "rotation": 9
    },
    {
      "x": -8,
      "y": 35,
      "z": -2,
      "name": "Soil_Clay_Ocean_Brick_Smooth",
      "rotation": 3
    },
    {
      "x": -8,
      "y": 0,
      "z": -1,
      "name": "Rock_Sandstone_Red_Cobble"
    },
    {
      "x": -8,
      "y": 5,
      "z": -1,
      "name": "Rock_Sandstone_Red_Brick"
    },
    {
      "x": -8,
      "y": 10,
      "z": -1,
      "name": "Rock_Sandstone_Brick"
    },
    {
      "x": -8,
      "y": 11,
      "z": -1,
      "name": "Rock_Sandstone_Cobble"
    },
    {
      "x": -8,
      "y": 17,
      "z": -1,
      "name": "Wood_Drywood_Planks"
    },
    {
      "x": -8,
      "y": 23,
      "z": -1,
      "name": "Plant_Coral_Block_Green"
    },
    {
      "x": -8,
      "y": 24,
      "z": -1,
      "name": "Plant_Coral_Bush_Green"
    },
    {
      "x": -8,
      "y": 28,
      "z": -1,
      "name": "Rock_Sandstone_Brick"
    },
    {
      "x": -8,
      "y": 29,
      "z": -1,
      "name": "Rock_Sandstone_Brick_Stairs",
      "rotation": 3
    },
    {
      "x": -8,
      "y": 30,
      "z": -1,
      "name": "Plant_Coral_Block_Green"
    },
    {
      "x": -8,
      "y": 34,
      "z": -1,
      "name": "Rock_Sandstone_Brick_Stairs",
      "rotation": 9
    },
    {
      "x": -8,
      "y": 35,
      "z": -1,
      "name": "Soil_Clay_Ocean_Brick_Smooth",
      "rotation": 3
    },
    {
      "x": -8,
      "y": 0,
      "z": 0,
      "name": "Rock_Sandstone_Red_Cobble"
    },
    {
      "x": -8,
      "y": 1,
      "z": 0,
      "name": "Rock_Sandstone_Brick"
    },
    {
      "x": -8,
      "y": 2,
      "z": 0,
      "name": "Rock_Sandstone_Brick"
    },
    {
      "x": -8,
      "y": 3,
      "z": 0,
      "name": "Rock_Sandstone_White_Brick"
    },
    {
      "x": -8,
      "y": 4,
      "z": 0,
      "name": "Rock_Sandstone_Brick"
    },
    {
      "x": -8,
      "y": 5,
      "z": 0,
      "name": "Rock_Sandstone_Red_Brick"
    },
    {
      "x": -8,
      "y": 10,
      "z": 0,
      "name": "Rock_Sandstone_Brick"
    },
    {
      "x": -8,
      "y": 11,
      "z": 0,
      "name": "Rock_Sandstone_Cobble"
    },
    {
      "x": -8,
      "y": 17,
      "z": 0,
      "name": "Wood_Drywood_Planks"
    },
    {
      "x": -8,
      "y": 23,
      "z": 0,
      "name": "Plant_Coral_Block_Green"
    },
    {
      "x": -8,
      "y": 28,
      "z": 0,
      "name": "Rock_Sandstone_Brick"
    },
    {
      "x": -8,
      "y": 29,
      "z": 0,
      "name": "Plant_Coral_Block_Green"
    },
    {
      "x": -8,
      "y": 30,
      "z": 0,
      "name": "Plant_Coral_Block_Green"
    },
    {
      "x": -8,
      "y": 34,
      "z": 0,
      "name": "Rock_Sandstone_Brick_Stairs",
      "rotation": 9
    },
    {
      "x": -8,
      "y": 35,
      "z": 0,
      "name": "Soil_Clay_Ocean_Brick_Smooth",
      "rotation": 3
    },
    {
      "x": -8,
      "y": 0,
      "z": 1,
      "name": "Rock_Sandstone_Red_Cobble"
    },
    {
      "x": -8,
      "y": 5,
      "z": 1,
      "name": "Rock_Sandstone_Red_Brick"
    },
    {
      "x": -8,
      "y": 10,
      "z": 1,
      "name": "Rock_Sandstone_Brick"
    },
    {
      "x": -8,
      "y": 11,
      "z": 1,
      "name": "Rock_Sandstone_Cobble"
    },
    {
      "x": -8,
      "y": 17,
      "z": 1,
      "name": "Wood_Drywood_Planks"
    },
    {
      "x": -8,
      "y": 28,
      "z": 1,
      "name": "Rock_Sandstone_Brick"
    },
    {
      "x": -8,
      "y": 29,
      "z": 1,
      "name": "Plant_Coral_Block_Green"
    },
    {
      "x": -8,
      "y": 30,
      "z": 1,
      "name": "Plant_Coral_Block_Green"
    },
    {
      "x": -8,
      "y": 34,
      "z": 1,
      "name": "Rock_Sandstone_Brick_Stairs",
      "rotation": 9
    },
    {
      "x": -8,
      "y": 35,
      "z": 1,
      "name": "Soil_Clay_Ocean_Brick_Smooth",
      "rotation": 3
    },
    {
      "x": -8,
      "y": 0,
      "z": 2,
      "name": "Rock_Sandstone_Red_Cobble"
    },
    {
      "x": -8,
      "y": 5,
      "z": 2,
      "name": "Rock_Sandstone_Red_Brick"
    },
    {
      "x": -8,
      "y": 10,
      "z": 2,
      "name": "Rock_Sandstone_Brick"
    },
    {
      "x": -8,
      "y": 11,
      "z": 2,
      "name": "Rock_Sandstone_Cobble"
    },
    {
      "x": -8,
      "y": 12,
      "z": 2,
      "name": "Plant_Coral_Bush_Green"
    },
    {
      "x": -8,
      "y": 17,
      "z": 2,
      "name": "Wood_Drywood_Planks"
    },
    {
      "x": -8,
      "y": 20,
      "z": 2,
      "name": "Plant_Coral_Block_Green"
    },
    {
      "x": -8,
      "y": 28,
      "z": 2,
      "name": "Plant_Coral_Block_Green"
    },
    {
      "x": -8,
      "y": 29,
      "z": 2,
      "name": "Plant_Coral_Block_Green"
    },
    {
      "x": -8,
      "y": 34,
      "z": 2,
      "name": "Rock_Sandstone_Brick_Stairs",
      "rotation": 9
    },
    {
      "x": -8,
      "y": 35,
      "z": 2,
      "name": "Soil_Clay_Ocean_Brick_Smooth",
      "rotation": 3
    },
    {
      "x": -8,
      "y": 0,
      "z": 3,
      "name": "Rock_Sandstone_Red_Cobble"
    },
    {
      "x": -8,
      "y": 5,
      "z": 3,
      "name": "Rock_Sandstone_Red_Brick"
    },
    {
      "x": -8,
      "y": 6,
      "z": 3,
      "name": "Soil_Clay_Ocean_Brick_Smooth"
    },
    {
      "x": -8,
      "y": 7,
      "z": 3,
      "name": "Soil_Clay_Ocean_Brick_Wall"
    },
    {
      "x": -8,
      "y": 10,
      "z": 3,
      "name": "Rock_Sandstone_Brick"
    },
    {
      "x": -8,
      "y": 11,
      "z": 3,
      "name": "Rock_Sandstone_Cobble"
    },
    {
      "x": -8,
      "y": 14,
      "z": 3,
      "name": "Plant_Coral_Block_Green"
    },
    {
      "x": -8,
      "y": 15,
      "z": 3,
      "name": "Plant_Coral_Bush_Green"
    },
    {
      "x": -8,
      "y": 17,
      "z": 3,
      "name": "Wood_Drywood_Planks"
    },
    {
      "x": -8,
      "y": 20,
      "z": 3,
      "name": "Plant_Coral_Block_Green"
    },
    {
      "x": -8,
      "y": 21,
      "z": 3,
      "name": "Plant_Coral_Bush_Green"
    },
    {
      "x": -8,
      "y": 25,
      "z": 3,
      "name": "Plant_Coral_Block_Green"
    },
    {
      "x": -8,
      "y": 28,
      "z": 3,
      "name": "Plant_Coral_Block_Green"
    },
    {
      "x": -8,
      "y": 29,
      "z": 3,
      "name": "Plant_Coral_Block_Green"
    },
    {
      "x": -8,
      "y": 30,
      "z": 3,
      "name": "Plant_Coral_Bush_Green"
    },
    {
      "x": -8,
      "y": 0,
      "z": 4,
      "name": "Rock_Sandstone_Red_Cobble"
    },
    {
      "x": -8,
      "y": 5,
      "z": 4,
      "name": "Rock_Sandstone_Red_Brick"
    },
    {
      "x": -8,
      "y": 6,
      "z": 4,
      "name": "Soil_Clay_Ocean_Brick_Smooth"
    },
    {
      "x": -8,
      "y": 7,
      "z": 4,
      "name": "Soil_Clay_Ocean_Brick_Wall"
    },
    {
      "x": -8,
      "y": 10,
      "z": 4,
      "name": "Rock_Sandstone_Brick"
    },
    {
      "x": -8,
      "y": 11,
      "z": 4,
      "name": "Rock_Sandstone_Cobble"
    },
    {
      "x": -8,
      "y": 12,
      "z": 4,
      "name": "Plant_Coral_Bush_Green"
    },
    {
      "x": -8,
      "y": 14,
      "z": 4,
      "name": "Plant_Coral_Block_Green"
    },
    {
      "x": -8,
      "y": 17,
      "z": 4,
      "name": "Rock_Sandstone_Brick"
    },
    {
      "x": -8,
      "y": 18,
      "z": 4,
      "name": "Rock_Sandstone_Brick"
    },
    {
      "x": -8,
      "y": 19,
      "z": 4,
      "name": "Rock_Sandstone_Brick"
    },
    {
      "x": -8,
      "y": 20,
      "z": 4,
      "name": "Rock_Sandstone_Brick"
    },
    {
      "x": -8,
      "y": 21,
      "z": 4,
      "name": "Rock_Sandstone_Brick"
    },
    {
      "x": -8,
      "y": 22,
      "z": 4,
      "name": "Rock_Gold_Brick_Smooth"
    },
    {
      "x": -8,
      "y": 23,
      "z": 4,
      "name": "Rock_Sandstone_Brick"
    },
    {
      "x": -8,
      "y": 24,
      "z": 4,
      "name": "Soil_Clay_Ocean_Brick_Ornate"
    },
    {
      "x": -8,
      "y": 25,
      "z": 4,
      "name": "Soil_Clay_Ocean_Brick_Ornate"
    },
    {
      "x": -8,
      "y": 26,
      "z": 4,
      "name": "Rock_Sandstone_Brick"
    },
    {
      "x": -8,
      "y": 27,
      "z": 4,
      "name": "Rock_Sandstone_Brick"
    },
    {
      "x": -8,
      "y": 28,
      "z": 4,
      "name": "Plant_Coral_Block_Green"
    },
    {
      "x": -8,
      "y": 29,
      "z": 4,
      "name": "Plant_Coral_Block_Green"
    },
    {
      "x": -8,
      "y": 5,
      "z": 5,
      "name": "Rock_Sandstone_Red_Brick"
    },
    {
      "x": -8,
      "y": 10,
      "z": 5,
      "name": "Rock_Sandstone_Brick"
    },
    {
      "x": -8,
      "y": 11,
      "z": 5,
      "name": "Rock_Sandstone_Cobble"
    },
    {
      "x": -8,
      "y": 14,
      "z": 5,
      "name": "Plant_Coral_Block_Green"
    },
    {
      "x": -8,
      "y": 15,
      "z": 5,
      "name": "Plant_Coral_Bush_Green"
    },
    {
      "x": -8,
      "y": 16,
      "z": 5,
      "name": "Cloth_Roof_Leather_Flap"
    },
    {
      "x": -8,
      "y": 25,
      "z": 5,
      "name": "Plant_Coral_Block_Green"
    },
    {
      "x": -8,
      "y": 28,
      "z": 5,
      "name": "Plant_Coral_Block_Green"
    },
    {
      "x": -8,
      "y": 29,
      "z": 5,
      "name": "Plant_Coral_Block_Green"
    },
    {
      "x": -8,
      "y": 5,
      "z": 6,
      "name": "Rock_Sandstone_Red_Brick"
    },
    {
      "x": -8,
      "y": 10,
      "z": 6,
      "name": "Rock_Sandstone_Brick"
    },
    {
      "x": -8,
      "y": 11,
      "z": 6,
      "name": "Rock_Sandstone_Cobble"
    },
    {
      "x": -8,
      "y": 28,
      "z": 6,
      "name": "Plant_Coral_Block_Green"
    },
    {
      "x": -8,
      "y": 29,
      "z": 6,
      "name": "Plant_Coral_Block_Green"
    },
    {
      "x": -8,
      "y": 30,
      "z": 6,
      "name": "Plant_Coral_Bush_Green"
    },
    {
      "x": -8,
      "y": 5,
      "z": 7,
      "name": "Rock_Sandstone_Red_Brick"
    },
    {
      "x": -8,
      "y": 16,
      "z": 7,
      "name": "Plant_Coral_Block_Green"
    },
    {
      "x": -8,
      "y": 17,
      "z": 7,
      "name": "Plant_Coral_Bush_Green"
    },
    {
      "x": -8,
      "y": 29,
      "z": 7,
      "name": "Plant_Coral_Block_Green"
    },
    {
      "x": -8,
      "y": 30,
      "z": 7,
      "name": "Plant_Coral_Block_Green"
    },
    {
      "x": -8,
      "y": 5,
      "z": 8,
      "name": "Rock_Sandstone_Red_Brick"
    },
    {
      "x": -8,
      "y": 13,
      "z": 8,
      "name": "Rock_Sandstone_Brick_Stairs",
      "rotation": 2
    },
    {
      "x": -8,
      "y": 16,
      "z": 8,
      "name": "Plant_Coral_Block_Green"
    },
    {
      "x": -8,
      "y": 29,
      "z": 8,
      "name": "Plant_Coral_Block_Green"
    },
    {
      "x": -8,
      "y": 30,
      "z": 8,
      "name": "Plant_Coral_Block_Green"
    },
    {
      "x": -8,
      "y": 5,
      "z": 9,
      "name": "Rock_Sandstone_Red_Brick"
    },
    {
      "x": -8,
      "y": 16,
      "z": 9,
      "name": "Plant_Coral_Block_Green"
    },
    {
      "x": -8,
      "y": 17,
      "z": 9,
      "name": "Plant_Coral_Bush_Green"
    },
    {
      "x": -8,
      "y": 30,
      "z": 9,
      "name": "Plant_Coral_Block_Green"
    },
    {
      "x": -8,
      "y": 31,
      "z": 9,
      "name": "Plant_Coral_Bush_Green"
    },
    {
      "x": -8,
      "y": 6,
      "z": 10,
      "name": "Rock_Sandstone_Brick"
    },
    {
      "x": -8,
      "y": 7,
      "z": 10,
      "name": "Rock_Sandstone_Brick_Stairs",
      "rotation": 9
    },
    {
      "x": -8,
      "y": 8,
      "z": 10,
      "name": "Rock_Sandstone_Brick"
    },
    {
      "x": -8,
      "y": 9,
      "z": 10,
      "name": "Rock_Sandstone_Brick"
    },
    {
      "x": -8,
      "y": 10,
      "z": 10,
      "name": "Rock_Sandstone_Brick_Half"
    },
    {
      "x": -8,
      "y": 14,
      "z": 10,
      "name": "Rock_Sandstone_Red_Brick_Half",
      "rotation": 7
    },
    {
      "x": -8,
      "y": 15,
      "z": 10,
      "name": "Rock_Sandstone_Red_Brick"
    },
    {
      "x": -8,
      "y": 16,
      "z": 10,
      "name": "Rock_Sandstone_Brick_Half"
    },
    {
      "x": -8,
      "y": 6,
      "z": 11,
      "name": "Rock_Sandstone_Brick_Half",
      "rotation": 4
    },
    {
      "x": -8,
      "y": 8,
      "z": 11,
      "name": "Rock_Sandstone_Brick_Half",
      "rotation": 4
    },
    {
      "x": -8,
      "y": 9,
      "z": 11,
      "name": "Rock_Sandstone_Brick_Half",
      "rotation": 4
    },
    {
      "x": -8,
      "y": 16,
      "z": 11,
      "name": "Rock_Sandstone_Brick"
    },
    {
      "x": -8,
      "y": 17,
      "z": 11,
      "name": "Rock_Sandstone_Brick"
    },
    {
      "x": -8,
      "y": 18,
      "z": 11,
      "name": "Rock_Sandstone_Brick_Half"
    },
    {
      "x": -7,
      "y": 2,
      "z": -9,
      "name": "Rock_Sandstone_Brick"
    },
    {
      "x": -7,
      "y": 3,
      "z": -9,
      "name": "Rock_Sandstone_White_Brick"
    },
    {
      "x": -7,
      "y": 4,
      "z": -9,
      "name": "Rock_Sandstone_Brick"
    },
    {
      "x": -7,
      "y": 5,
      "z": -9,
      "name": "Rock_Sandstone_Red_Brick"
    },
    {
      "x": -7,
      "y": 5,
      "z": -8,
      "name": "Rock_Sandstone_Red_Brick"
    },
    {
      "x": -7,
      "y": 9,
      "z": -8,
      "name": "Plant_Coral_Block_Green",
      "rotation": 2
    },
    {
      "x": -7,
      "y": 10,
      "z": -8,
      "name": "Plant_Coral_Bush_Green",
      "rotation": 2
    },
    {
      "x": -7,
      "y": 23,
      "z": -8,
      "name": "Plant_Coral_Block_Green"
    },
    {
      "x": -7,
      "y": 5,
      "z": -7,
      "name": "Rock_Sandstone_Red_Brick"
    },
    {
      "x": -7,
      "y": 9,
      "z": -7,
      "name": "Plant_Coral_Block_Green",
      "rotation": 2
    },
    {
      "x": -7,
      "y": 15,
      "z": -7,
      "name": "Plant_Coral_Block_Green",
      "rotation": 2
    },
    {
      "x": -7,
      "y": 16,
      "z": -7,
      "name": "Plant_Coral_Bush_Green",
      "rotation": 2
    },
    {
      "x": -7,
      "y": 19,
      "z": -7,
      "name": "Plant_Coral_Block_Green",
      "rotation": 1
    },
    {
      "x": -7,
      "y": 20,
      "z": -7,
      "name": "Plant_Coral_Bush_Green",
      "rotation": 1
    },
    {
      "x": -7,
      "y": 23,
      "z": -7,
      "name": "Plant_Coral_Block_Green"
    },
    {
      "x": -7,
      "y": 24,
      "z": -7,
      "name": "Plant_Coral_Bush_Green"
    },
    {
      "x": -7,
      "y": 0,
      "z": -6,
      "name": "Rock_Sandstone_Red_Cobble"
    },
    {
      "x": -7,
      "y": 5,
      "z": -6,
      "name": "Rock_Sandstone_Red_Brick"
    },
    {
      "x": -7,
      "y": 6,
      "z": -6,
      "name": "Rock_Sandstone_Brick"
    },
    {
      "x": -7,
      "y": 7,
      "z": -6,
      "name": "Rock_Sandstone_Brick"
    },
    {
      "x": -7,
      "y": 8,
      "z": -6,
      "name": "Rock_Sandstone_Brick"
    },
    {
      "x": -7,
      "y": 9,
      "z": -6,
      "name": "Rock_Sandstone_Brick"
    },
    {
      "x": -7,
      "y": 10,
      "z": -6,
      "name": "Rock_Sandstone_Brick"
    },
    {
      "x": -7,
      "y": 11,
      "z": -6,
      "name": "Rock_Sandstone_Brick"
    },
    {
      "x": -7,
      "y": 12,
      "z": -6,
      "name": "Rock_Sandstone_Brick"
    },
    {
      "x": -7,
      "y": 13,
      "z": -6,
      "name": "Rock_Sandstone_Red_Brick"
    },
    {
      "x": -7,
      "y": 14,
      "z": -6,
      "name": "Rock_Sandstone_Red_Brick"
    },
    {
      "x": -7,
      "y": 15,
      "z": -6,
      "name": "Rock_Sandstone_Red_Brick"
    },
    {
      "x": -7,
      "y": 16,
      "z": -6,
      "name": "Rock_Sandstone_Brick"
    },
    {
      "x": -7,
      "y": 17,
      "z": -6,
      "name": "Rock_Sandstone_Brick"
    },
    {
      "x": -7,
      "y": 18,
      "z": -6,
      "name": "Rock_Sandstone_Brick"
    },
    {
      "x": -7,
      "y": 19,
      "z": -6,
      "name": "Rock_Sandstone_Brick"
    },
    {
      "x": -7,
      "y": 20,
      "z": -6,
      "name": "Rock_Sandstone_Brick"
    },
    {
      "x": -7,
      "y": 21,
      "z": -6,
      "name": "Rock_Sandstone_Brick"
    },
    {
      "x": -7,
      "y": 22,
      "z": -6,
      "name": "Rock_Gold_Brick_Smooth"
    },
    {
      "x": -7,
      "y": 23,
      "z": -6,
      "name": "Rock_Sandstone_Brick"
    },
    {
      "x": -7,
      "y": 24,
      "z": -6,
      "name": "Soil_Clay_Ocean_Brick_Ornate"
    },
    {
      "x": -7,
      "y": 25,
      "z": -6,
      "name": "Soil_Clay_Ocean_Brick_Ornate"
    },
    {
      "x": -7,
      "y": 26,
      "z": -6,
      "name": "Rock_Sandstone_Brick"
    },
    {
      "x": -7,
      "y": 27,
      "z": -6,
      "name": "Rock_Sandstone_Brick"
    },
    {
      "x": -7,
      "y": 28,
      "z": -6,
      "name": "Rock_Sandstone_Brick"
    },
    {
      "x": -7,
      "y": 29,
      "z": -6,
      "name": "*Rock_Sandstone_Brick_Stairs_State_Definitions_Corner_Left",
      "rotation": 2
    },
    {
      "x": -7,
      "y": 0,
      "z": -5,
      "name": "Rock_Sandstone_Red_Cobble"
    },
    {
      "x": -7,
      "y": 5,
      "z": -5,
      "name": "Rock_Sandstone_Red_Brick"
    },
    {
      "x": -7,
      "y": 7,
      "z": -5,
      "name": "Rock_Sandstone_Brick"
    },
    {
      "x": -7,
      "y": 8,
      "z": -5,
      "name": "Rock_Sandstone_Brick"
    },
    {
      "x": -7,
      "y": 9,
      "z": -5,
      "name": "Rock_Sandstone_Brick"
    },
    {
      "x": -7,
      "y": 10,
      "z": -5,
      "name": "Rock_Sandstone_Brick"
    },
    {
      "x": -7,
      "y": 11,
      "z": -5,
      "name": "Rock_Sandstone_Brick"
    },
    {
      "x": -7,
      "y": 12,
      "z": -5,
      "name": "Rock_Sandstone_Brick"
    },
    {
      "x": -7,
      "y": 13,
      "z": -5,
      "name": "Rock_Sandstone_Brick"
    },
    {
      "x": -7,
      "y": 14,
      "z": -5,
      "name": "Rock_Sandstone_Brick"
    },
    {
      "x": -7,
      "y": 15,
      "z": -5,
      "name": "Rock_Sandstone_Brick"
    },
    {
      "x": -7,
      "y": 16,
      "z": -5,
      "name": "Rock_Sandstone_Brick"
    },
    {
      "x": -7,
      "y": 17,
      "z": -5,
      "name": "Wood_Drywood_Planks"
    },
    {
      "x": -7,
      "y": 19,
      "z": -5,
      "name": "Plant_Coral_Block_Green",
      "rotation": 1
    },
    {
      "x": -7,
      "y": 23,
      "z": -5,
      "name": "Plant_Coral_Block_Green"
    },
    {
      "x": -7,
      "y": 24,
      "z": -5,
      "name": "Rock_Sandstone_Brick"
    },
    {
      "x": -7,
      "y": 28,
      "z": -5,
      "name": "Rock_Sandstone_Brick"
    },
    {
      "x": -7,
      "y": 29,
      "z": -5,
      "name": "Rock_Sandstone_Brick_Stairs",
      "rotation": 3
    },
    {
      "x": -7,
      "y": 34,
      "z": -5,
      "name": "Rock_Sandstone_Brick_Stairs",
      "rotation": 9
    },
    {
      "x": -7,
      "y": 35,
      "z": -5,
      "name": "Soil_Clay_Ocean_Brick_Smooth",
      "rotation": 3
    },
    {
      "x": -7,
      "y": 0,
      "z": -4,
      "name": "Rock_Sandstone_Red_Cobble"
    },
    {
      "x": -7,
      "y": 5,
      "z": -4,
      "name": "Rock_Sandstone_Red_Brick"
    },
    {
      "x": -7,
      "y": 10,
      "z": -4,
      "name": "Rock_Sandstone_Brick"
    },
    {
      "x": -7,
      "y": 11,
      "z": -4,
      "name": "Rock_Sandstone_Brick"
    },
    {
      "x": -7,
      "y": 16,
      "z": -4,
      "name": "Rock_Sandstone_Brick"
    },
    {
      "x": -7,
      "y": 17,
      "z": -4,
      "name": "Wood_Drywood_Planks"
    },
    {
      "x": -7,
      "y": 23,
      "z": -4,
      "name": "Plant_Coral_Block_Green"
    },
    {
      "x": -7,
      "y": 24,
      "z": -4,
      "name": "Rock_Sandstone_Brick"
    },
    {
      "x": -7,
      "y": 28,
      "z": -4,
      "name": "Rock_Sandstone_Brick"
    },
    {
      "x": -7,
      "y": 29,
      "z": -4,
      "name": "*Rock_Sandstone_Brick_Stairs_State_Definitions_Inverted_Corner_Left",
      "rotation": 2
    },
    {
      "x": -7,
      "y": 34,
      "z": -4,
      "name": "Rock_Sandstone_Brick_Stairs",
      "rotation": 9
    },
    {
      "x": -7,
      "y": 35,
      "z": -4,
      "name": "Soil_Clay_Ocean_Brick_Smooth",
      "rotation": 3
    },
    {
      "x": -7,
      "y": 5,
      "z": -3,
      "name": "Rock_Sandstone_Red_Brick"
    },
    {
      "x": -7,
      "y": 10,
      "z": -3,
      "name": "Rock_Sandstone_Brick"
    },
    {
      "x": -7,
      "y": 11,
      "z": -3,
      "name": "Rock_Sandstone_Brick"
    },
    {
      "x": -7,
      "y": 17,
      "z": -3,
      "name": "Wood_Drywood_Planks"
    },
    {
      "x": -7,
      "y": 24,
      "z": -3,
      "name": "Rock_Sandstone_Brick"
    },
    {
      "x": -7,
      "y": 28,
      "z": -3,
      "name": "Rock_Sandstone_Brick"
    },
    {
      "x": -7,
      "y": 29,
      "z": -3,
      "name": "Rock_Sandstone_Brick"
    },
    {
      "x": -7,
      "y": 30,
      "z": -3,
      "name": "Rock_Sandstone_Brick",
      "rotation": 3
    },
    {
      "x": -7,
      "y": 31,
      "z": -3,
      "name": "Rock_Sandstone_Brick",
      "rotation": 3
    },
    {
      "x": -7,
      "y": 32,
      "z": -3,
      "name": "Rock_Sandstone_Brick",
      "rotation": 3
    },
    {
      "x": -7,
      "y": 33,
      "z": -3,
      "name": "Rock_Sandstone_Brick",
      "rotation": 3
    },
    {
      "x": -7,
      "y": 34,
      "z": -3,
      "name": "Rock_Sandstone_Brick",
      "rotation": 3
    },
    {
      "x": -7,
      "y": 35,
      "z": -3,
      "name": "Soil_Clay_Ocean_Brick_Smooth",
      "rotation": 3
    },
    {
      "x": -7,
      "y": 0,
      "z": -2,
      "name": "Rock_Sandstone_Red_Cobble"
    },
    {
      "x": -7,
      "y": 5,
      "z": -2,
      "name": "Rock_Sandstone_Red_Brick"
    },
    {
      "x": -7,
      "y": 10,
      "z": -2,
      "name": "Rock_Sandstone_Brick"
    },
    {
      "x": -7,
      "y": 11,
      "z": -2,
      "name": "Rock_Sandstone_Brick"
    },
    {
      "x": -7,
      "y": 17,
      "z": -2,
      "name": "Wood_Drywood_Planks"
    },
    {
      "x": -7,
      "y": 24,
      "z": -2,
      "name": "Rock_Sandstone_Brick"
    },
    {
      "x": -7,
      "y": 28,
      "z": -2,
      "name": "Rock_Sandstone_Brick"
    },
    {
      "x": -7,
      "y": 29,
      "z": -2,
      "name": "Rock_Sandstone_Brick"
    },
    {
      "x": -7,
      "y": 30,
      "z": -2,
      "name": "Rock_Sandstone_Brick",
      "rotation": 3
    },
    {
      "x": -7,
      "y": 31,
      "z": -2,
      "name": "Rock_Sandstone_Brick",
      "rotation": 3
    },
    {
      "x": -7,
      "y": 32,
      "z": -2,
      "name": "Furniture_Desert_Window",
      "rotation": 3
    },
    {
      "x": -7,
      "y": 33,
      "z": -2,
      "name": "Furniture_Desert_Window",
      "rotation": 3
    },
    {
      "x": -7,
      "y": 34,
      "z": -2,
      "name": "Rock_Sandstone_Brick",
      "rotation": 3
    },
    {
      "x": -7,
      "y": 35,
      "z": -2,
      "name": "Soil_Clay_Ocean_Brick_Smooth",
      "rotation": 3
    },
    {
      "x": -7,
      "y": 36,
      "z": -2,
      "name": "Soil_Clay_Ocean_Brick_Half",
      "rotation": 3
    },
    {
      "x": -7,
      "y": 0,
      "z": -1,
      "name": "Rock_Sandstone_Red_Cobble"
    },
    {
      "x": -7,
      "y": 5,
      "z": -1,
      "name": "Rock_Sandstone_Red_Brick"
    },
    {
      "x": -7,
      "y": 10,
      "z": -1,
      "name": "Rock_Sandstone_Brick"
    },
    {
      "x": -7,
      "y": 11,
      "z": -1,
      "name": "Rock_Sandstone_Cobble"
    },
    {
      "x": -7,
      "y": 17,
      "z": -1,
      "name": "Wood_Drywood_Planks"
    },
    {
      "x": -7,
      "y": 24,
      "z": -1,
      "name": "Rock_Sandstone_Brick"
    },
    {
      "x": -7,
      "y": 25,
      "z": -1,
      "name": "Rock_Sandstone_Brick"
    },
    {
      "x": -7,
      "y": 26,
      "z": -1,
      "name": "Rock_Sandstone_Brick"
    },
    {
      "x": -7,
      "y": 27,
      "z": -1,
      "name": "Rock_Sandstone_Brick"
    },
    {
      "x": -7,
      "y": 28,
      "z": -1,
      "name": "Rock_Sandstone_Brick"
    },
    {
      "x": -7,
      "y": 29,
      "z": -1,
      "name": "Rock_Sandstone_Brick"
    },
    {
      "x": -7,
      "y": 30,
      "z": -1,
      "name": "Rock_Sandstone_Brick",
