{
  "version": 8,
  "blockIdVersion": 11,
  "anchorX": 0,
  "anchorY": 0,
  "anchorZ": 0,
  "blocks": [
    {
      "x": -6,
      "y": 10,
      "z": 10,
      "name": "Plant_Coral_Block_Red",
      "rotation": 3
    },
    {
      "x": -6,
      "y": 10,
      "z": 11,
      "name": "Plant_Coral_Block_Red",
      "rotation": 3
    },
    {
      "x": -6,
      "y": 11,
      "z": 11,
      "name": "Plant_Coral_Bush_Red",
      "rotation": 3
    },
    {
      "x": -6,
      "y": 10,
      "z": 12,
      "name": "Plant_Coral_Block_Red",
      "rotation": 3
    },
    {
      "x": -5,
      "y": 8,
      "z": 6,
      "name": "Plant_Coral_Block_Red",
      "rotation": 3
    },
    {
      "x": -5,
      "y": 8,
      "z": 7,
      "name": "Plant_Coral_Block_Red",
      "rotation": 3
    },
    {
      "x": -5,
      "y": 9,
      "z": 7,
      "name": "Plant_Coral_Bush_Red",
      "rotation": 3
    },
    {
      "x": -5,
      "y": 8,
      "z": 8,
      "name": "Plant_Coral_Block_Red",
      "rotation": 3
    },
    {
      "x": -5,
      "y": 10,
      "z": 10,
      "name": "Plant_Coral_Block_Red",
      "rotation": 3
    },
    {
      "x": -5,
      "y": 11,
      "z": 10,
      "name": "Plant_Coral_Bush_Red",
      "rotation": 3
    },
    {
      "x": -5,
      "y": 9,
      "z": 11,
      "name": "Plant_Coral_Block_Red",
      "rotation": 3
    },
    {
      "x": -5,
      "y": 10,
      "z": 11,
      "name": "Plant_Coral_Block_Red",
      "rotation": 3
    },
    {
      "x": -5,
      "y": 11,
      "z": 11,
      "name": "Plant_Coral_Bush_Red",
      "rotation": 3
    },
    {
      "x": -5,
      "y": 9,
      "z": 12,
      "name": "Plant_Coral_Block_Red",
      "rotation": 3
    },
    {
      "x": -5,
      "y": 10,
      "z": 12,
      "name": "Plant_Coral_Bush_Red",
      "rotation": 3
    },
    {
      "x": -5,
      "y": 9,
      "z": 13,
      "name": "Plant_Coral_Block_Red",
      "rotation": 3
    },
    {
      "x": -4,
      "y": 15,
      "z": -5,
      "name": "Plant_Coral_Block_Red",
      "rotation": 2
    },
    {
      "x": -4,
      "y": 15,
      "z": -4,
      "name": "Plant_Coral_Block_Red",
      "rotation": 2
    },
    {
      "x": -4,
      "y": 15,
      "z": -3,
      "name": "Plant_Coral_Block_Red",
      "rotation": 2
    },
    {
      "x": -4,
      "y": 16,
      "z": -3,
      "name": "Plant_Coral_Bush_Red",
      "rotation": 2
    },
    {
      "x": -4,
      "y": 8,
      "z": 6,
      "name": "Plant_Coral_Block_Red",
      "rotation": 3
    },
    {
      "x": -4,
      "y": 9,
      "z": 6,
      "name": "Plant_Coral_Bush_Red",
      "rotation": 3
    },
    {
      "x": -4,
      "y": 7,
      "z": 7,
      "name": "Plant_Coral_Block_Red"
    },
    {
      "x": -4,
      "y": 8,
      "z": 7,
      "name": "Plant_Coral_Block_Red",
      "rotation": 3
    },
    {
      "x": -4,
      "y": 9,
      "z": 7,
      "name": "Plant_Coral_Bush_Red",
      "rotation": 3
    },
    {
      "x": -4,
      "y": 7,
      "z": 8,
      "name": "Plant_Coral_Block_Red"
    },
    {
      "x": -4,
      "y": 8,
      "z": 8,
      "name": "Plant_Coral_Bush_Red"
    },
    {
      "x": -4,
      "y": 7,
      "z": 9,
      "name": "Plant_Coral_Block_Red"
    },
    {
      "x": -4,
      "y": 8,
      "z": 10,
      "name": "Plant_Coral_Block_Red",
      "rotation": 3
    },
    {
      "x": -4,
      "y": 10,
      "z": 10,
      "name": "Plant_Coral_Block_Red",
      "rotation": 3
    },
    {
      "x": -4,
      "y": 8,
      "z": 11,
      "name": "Plant_Coral_Block_Red",
      "rotation": 3
    },
    {
      "x": -4,
      "y": 9,
      "z": 11,
      "name": "Plant_Coral_Bush_Red",
      "rotation": 3
    },
    {
      "x": -4,
      "y": 10,
      "z": 11,
      "name": "Plant_Coral_Bush_Red",
      "rotation": 3
    },
    {
      "x": -4,
      "y": 8,
      "z": 12,
      "name": "Plant_Coral_Block_Red",
      "rotation": 3
    },
    {
      "x": -4,
      "y": 9,
      "z": 12,
      "name": "Plant_Coral_Block_Red",
      "rotation": 3
    },
    {
      "x": -4,
      "y": 10,
      "z": 12,
      "name": "Plant_Coral_Bush_Red",
      "rotation": 3
    },
    {
      "x": -4,
      "y": 11,
      "z": 12,
      "name": "Plant_Coral_Bush_Red",
      "rotation": 3
    },
    {
      "x": -4,
      "y": 9,
      "z": 13,
      "name": "Plant_Coral_Block_Red",
      "rotation": 3
    },
    {
      "x": -3,
      "y": 15,
      "z": -5,
      "name": "Plant_Coral_Block_Red",
      "rotation": 2
    },
    {
      "x": -3,
      "y": 16,
      "z": -5,
      "name": "Plant_Coral_Bush_Red",
      "rotation": 2
    },
    {
      "x": -3,
      "y": 20,
      "z": -5,
      "name": "Plant_Coral_Block_Red"
    },
    {
      "x": -3,
      "y": 21,
      "z": -5,
      "name": "Plant_Coral_Bush_Red"
    },
    {
      "x": -3,
      "y": 14,
      "z": -4,
      "name": "Wood_Drywood_Planks_Half",
      "rotation": 7
    },
    {
      "x": -3,
      "y": 15,
      "z": -4,
      "name": "Wood_Drywood_Planks_Half",
      "rotation": 7
    },
    {
      "x": -3,
      "y": 16,
      "z": -4,
      "name": "Plant_Coral_Bush_Red",
      "rotation": 2
    },
    {
      "x": -3,
      "y": 20,
      "z": -4,
      "name": "Plant_Coral_Block_Red"
    },
    {
      "x": -3,
      "y": 15,
      "z": -3,
      "name": "Plant_Coral_Block_Red",
      "rotation": 2
    },
    {
      "x": -3,
      "y": 20,
      "z": -3,
      "name": "Plant_Coral_Block_Red"
    },
    {
      "x": -3,
      "y": 21,
      "z": -3,
      "name": "Plant_Coral_Bush_Red"
    },
    {
      "x": -3,
      "y": 0,
      "z": 2,
      "name": "Rock_Sandstone_Brick_Half",
      "rotation": 7
    },
    {
      "x": -3,
      "y": 8,
      "z": 3,
      "name": "Plant_Coral_Block_Red",
      "rotation": 3
    },
    {
      "x": -3,
      "y": 8,
      "z": 4,
      "name": "Plant_Coral_Block_Red",
      "rotation": 3
    },
    {
      "x": -3,
      "y": 9,
      "z": 4,
      "name": "Plant_Coral_Bush_Red",
      "rotation": 3
    },
    {
      "x": -3,
      "y": 7,
      "z": 5,
      "name": "Plant_Coral_Block_Red"
    },
    {
      "x": -3,
      "y": 8,
      "z": 5,
      "name": "Plant_Coral_Block_Red",
      "rotation": 3
    },
    {
      "x": -3,
      "y": 7,
      "z": 6,
      "name": "Plant_Coral_Block_Red"
    },
    {
      "x": -3,
      "y": 8,
      "z": 6,
      "name": "Plant_Coral_Bush_Red"
    },
    {
      "x": -3,
      "y": 6,
      "z": 7,
      "name": "Plant_Coral_Block_Red"
    },
    {
      "x": -3,
      "y": 7,
      "z": 7,
      "name": "Plant_Coral_Block_Red"
    },
    {
      "x": -3,
      "y": 8,
      "z": 7,
      "name": "Plant_Coral_Block_Red",
      "rotation": 3
    },
    {
      "x": -3,
      "y": 6,
      "z": 8,
      "name": "Plant_Coral_Block_Red"
    },
    {
      "x": -3,
      "y": 7,
      "z": 8,
      "name": "Plant_Coral_Block_Red"
    },
    {
      "x": -3,
      "y": 8,
      "z": 8,
      "name": "Plant_Coral_Block_Red",
      "rotation": 3
    },
    {
      "x": -3,
      "y": 9,
      "z": 8,
      "name": "Plant_Coral_Bush_Red",
      "rotation": 3
    },
    {
      "x": -3,
      "y": 6,
      "z": 9,
      "name": "Plant_Coral_Block_Red"
    },
    {
      "x": -3,
      "y": 7,
      "z": 9,
      "name": "Plant_Coral_Block_Red"
    },
    {
      "x": -3,
      "y": 7,
      "z": 10,
      "name": "Plant_Coral_Block_Red"
    },
    {
      "x": -3,
      "y": 8,
      "z": 10,
      "name": "Plant_Coral_Block_Red",
      "rotation": 3
    },
    {
      "x": -3,
      "y": 9,
      "z": 10,
      "name": "Plant_Coral_Bush_Red",
      "rotation": 3
    },
    {
      "x": -3,
      "y": 7,
      "z": 11,
      "name": "Plant_Coral_Block_Red"
    },
    {
      "x": -3,
      "y": 8,
      "z": 11,
      "name": "Plant_Coral_Block_Red",
      "rotation": 3
    },
    {
      "x": -3,
      "y": 9,
      "z": 11,
      "name": "Plant_Coral_Bush_Red",
      "rotation": 3
    },
    {
      "x": -3,
      "y": 8,
      "z": 12,
      "name": "Plant_Coral_Block_Red",
      "rotation": 3
    },
    {
      "x": -3,
      "y": 9,
      "z": 12,
      "name": "Plant_Coral_Block_Red",
      "rotation": 3
    },
    {
      "x": -3,
      "y": 9,
      "z": 13,
      "name": "Plant_Coral_Block_Red",
      "rotation": 3
    },
    {
      "x": -3,
      "y": 10,
      "z": 13,
      "name": "Plant_Coral_Bush_Red",
      "rotation": 3
    },
    {
      "x": -2,
      "y": 15,
      "z": -6,
      "name": "Plant_Coral_Block_Red",
      "rotation": 2
    },
    {
      "x": -2,
      "y": 20,
      "z": -6,
      "name": "Plant_Coral_Block_Red"
    },
    {
      "x": -2,
      "y": 13,
      "z": -5,
      "name": "Plant_Coral_Block_Red",
      "rotation": 2
    },
    {
      "x": -2,
      "y": 15,
      "z": -5,
      "name": "Plant_Coral_Block_Red",
      "rotation": 2
    },
    {
      "x": -2,
      "y": 20,
      "z": -5,
      "name": "Plant_Coral_Block_Red"
    },
    {
      "x": -2,
      "y": 13,
      "z": -4,
      "name": "Wood_Drywood_Planks_Half",
      "rotation": 8
    },
    {
      "x": -2,
      "y": 14,
      "z": -4,
      "name": "Wood_Drywood_Planks"
    },
    {
      "x": -2,
      "y": 15,
      "z": -4,
      "name": "Wood_Drywood_Planks"
    },
    {
      "x": -2,
      "y": 16,
      "z": -4,
      "name": "Wood_Drywood_Planks"
    },
    {
      "x": -2,
      "y": 17,
      "z": -4,
      "name": "Wood_Drywood_Planks_Half",
      "rotation": 7
    },
    {
      "x": -2,
      "y": 19,
      "z": -4,
      "name": "Plant_Coral_Block_Red"
    },
    {
      "x": -2,
      "y": 20,
      "z": -4,
      "name": "Plant_Coral_Block_Red"
    },
    {
      "x": -2,
      "y": 13,
      "z": -3,
      "name": "Plant_Coral_Block_Red",
      "rotation": 2
    },
    {
      "x": -2,
      "y": 14,
      "z": -3,
      "name": "Plant_Coral_Bush_Red",
      "rotation": 2
    },
    {
      "x": -2,
      "y": 15,
      "z": -3,
      "name": "Plant_Coral_Block_Red",
      "rotation": 2
    },
    {
      "x": -2,
      "y": 20,
      "z": -3,
      "name": "Plant_Coral_Block_Red"
    },
    {
      "x": -2,
      "y": 20,
      "z": -2,
      "name": "Plant_Coral_Block_Red"
    },
    {
      "x": -2,
      "y": 0,
      "z": 2,
      "name": "Rock_Sandstone_Brick"
    },
    {
      "x": -2,
      "y": 0,
      "z": 3,
      "name": "Rock_Sandstone_Brick"
    },
    {
      "x": -2,
      "y": 8,
      "z": 3,
      "name": "Plant_Coral_Block_Red",
      "rotation": 3
    },
    {
      "x": -2,
      "y": 9,
      "z": 3,
      "name": "Plant_Coral_Bush_Red",
      "rotation": 3
    },
    {
      "x": -2,
      "y": 7,
      "z": 4,
      "name": "Plant_Coral_Block_Red"
    },
    {
      "x": -2,
      "y": 8,
      "z": 4,
      "name": "Plant_Coral_Bush_Red"
    },
    {
      "x": -2,
      "y": 9,
      "z": 4,
      "name": "Plant_Coral_Bush_Red",
      "rotation": 3
    },
    {
      "x": -2,
      "y": 7,
      "z": 5,
      "name": "Plant_Coral_Block_Red"
    },
    {
      "x": -2,
      "y": 8,
      "z": 5,
      "name": "Plant_Coral_Block_Red",
      "rotation": 3
    },
    {
      "x": -2,
      "y": 6,
      "z": 6,
      "name": "Plant_Coral_Block_Red"
    },
    {
      "x": -2,
      "y": 7,
      "z": 6,
      "name": "Plant_Coral_Block_Red"
    },
    {
      "x": -2,
      "y": 6,
      "z": 7,
      "name": "Plant_Coral_Block_Red"
    },
    {
      "x": -2,
      "y": 7,
      "z": 7,
      "name": "Plant_Coral_Block_Red"
    },
    {
      "x": -2,
      "y": 6,
      "z": 8,
      "name": "Plant_Coral_Block_Red"
    },
    {
      "x": -2,
      "y": 7,
      "z": 8,
      "name": "Plant_Coral_Block_Red"
    },
    {
      "x": -2,
      "y": 6,
      "z": 9,
      "name": "Plant_Coral_Block_Red"
    },
    {
      "x": -2,
      "y": 7,
      "z": 9,
      "name": "Plant_Coral_Block_Red"
    },
    {
      "x": -2,
      "y": 8,
      "z": 9,
      "name": "Plant_Coral_Bush_Red"
    },
    {
      "x": -2,
      "y": 6,
      "z": 10,
      "name": "Plant_Coral_Block_Red"
    },
    {
      "x": -2,
      "y": 7,
      "z": 10,
      "name": "Plant_Coral_Block_Red"
    },
    {
      "x": -2,
      "y": 8,
      "z": 10,
      "name": "Plant_Coral_Block_Red",
      "rotation": 3
    },
    {
      "x": -2,
      "y": 7,
      "z": 11,
      "name": "Plant_Coral_Block_Red"
    },
    {
      "x": -2,
      "y": 8,
      "z": 11,
      "name": "Plant_Coral_Bush_Red"
    },
    {
      "x": -2,
      "y": 7,
      "z": 12,
      "name": "Plant_Coral_Block_Red"
    },
    {
      "x": -2,
      "y": 8,
      "z": 12,
      "name": "Plant_Coral_Bush_Red"
    },
    {
      "x": -2,
      "y": 9,
      "z": 12,
      "name": "Plant_Coral_Bush_Red",
      "rotation": 3
    },
    {
      "x": -1,
      "y": 15,
      "z": -6,
      "name": "Plant_Coral_Block_Red",
      "rotation": 2
    },
    {
      "x": -1,
      "y": 16,
      "z": -6,
      "name": "Plant_Coral_Bush_Red",
      "rotation": 2
    },
    {
      "x": -1,
      "y": 20,
      "z": -6,
      "name": "Plant_Coral_Block_Red"
    },
    {
      "x": -1,
      "y": 21,
      "z": -6,
      "name": "Plant_Coral_Bush_Red"
    },
    {
      "x": -1,
      "y": 13,
      "z": -5,
      "name": "Plant_Coral_Block_Red",
      "rotation": 2
    },
    {
      "x": -1,
      "y": 14,
      "z": -5,
      "name": "Wood_Drywood_Planks_Half",
      "rotation": 7
    },
    {
      "x": -1,
      "y": 15,
      "z": -5,
      "name": "Wood_Drywood_Planks"
    },
    {
      "x": -1,
      "y": 16,
      "z": -5,
      "name": "Wood_Drywood_Planks_Half",
      "rotation": 7
    },
    {
      "x": -1,
      "y": 17,
      "z": -5,
      "name": "Wood_Drywood_Planks_Half",
      "rotation": 7
    },
    {
      "x": -1,
      "y": 19,
      "z": -5,
      "name": "Plant_Coral_Block_Red"
    },
    {
      "x": -1,
      "y": 20,
      "z": -5,
      "name": "Plant_Coral_Block_Red"
    },
    {
      "x": -1,
      "y": 12,
      "z": -4,
      "name": "Rock_Sandstone_Brick"
    },
    {
      "x": -1,
      "y": 13,
      "z": -4,
      "name": "Wood_Drywood_Planks"
    },
    {
      "x": -1,
      "y": 14,
      "z": -4,
      "name": "Wood_Drywood_Planks"
    },
    {
      "x": -1,
      "y": 15,
      "z": -4,
      "name": "Wood_Drywood_Planks"
    },
    {
      "x": -1,
      "y": 16,
      "z": -4,
      "name": "Wood_Drywood_Planks"
    },
    {
      "x": -1,
      "y": 17,
      "z": -4,
      "name": "Wood_Drywood_Planks"
    },
    {
      "x": -1,
      "y": 18,
      "z": -4,
      "name": "Wood_Drywood_Planks"
    },
    {
      "x": -1,
      "y": 19,
      "z": -4,
      "name": "Rock_Sandstone_Brick"
    },
    {
      "x": -1,
      "y": 20,
      "z": -4,
      "name": "Rock_Sandstone_Brick"
    },
    {
      "x": -1,
      "y": 21,
      "z": -4,
      "name": "Plant_Coral_Bush_Red"
    },
    {
      "x": -1,
      "y": 13,
      "z": -3,
      "name": "Plant_Coral_Block_Red",
      "rotation": 2
    },
    {
      "x": -1,
      "y": 19,
      "z": -3,
      "name": "Plant_Coral_Block_Red"
    },
    {
      "x": -1,
      "y": 20,
      "z": -3,
      "name": "Plant_Coral_Block_Red"
    },
    {
      "x": -1,
      "y": 20,
      "z": -2,
      "name": "Plant_Coral_Block_Red"
    },
    {
      "x": -1,
      "y": 21,
      "z": -2,
      "name": "Plant_Coral_Bush_Red"
    },
    {
      "x": -1,
      "y": 17,
      "z": -1,
      "name": "Plant_Coral_Block_Red",
      "rotation": 3
    },
    {
      "x": -1,
      "y": 17,
      "z": 0,
      "name": "Plant_Coral_Block_Red",
      "rotation": 3
    },
    {
      "x": -1,
      "y": 18,
      "z": 0,
      "name": "Plant_Coral_Bush_Red",
      "rotation": 3
    },
    {
      "x": -1,
      "y": 0,
      "z": 1,
      "name": "Rock_Sandstone_Brick_Half",
      "rotation": 6
    },
    {
      "x": -1,
      "y": 17,
      "z": 1,
      "name": "Plant_Coral_Block_Red",
      "rotation": 3
    },
    {
      "x": -1,
      "y": 0,
      "z": 2,
      "name": "Rock_Sandstone_Brick"
    },
    {
      "x": -1,
      "y": 0,
      "z": 3,
      "name": "Rock_Sandstone_Brick"
    },
    {
      "x": -1,
      "y": 8,
      "z": 3,
      "name": "Plant_Coral_Block_Red",
      "rotation": 3
    },
    {
      "x": -1,
      "y": 0,
      "z": 4,
      "name": "Rock_Sandstone_Brick_Half",
      "rotation": 4
    },
    {
      "x": -1,
      "y": 7,
      "z": 4,
      "name": "Plant_Coral_Block_Red"
    },
    {
      "x": -1,
      "y": 8,
      "z": 4,
      "name": "Plant_Coral_Block_Red",
      "rotation": 3
    },
    {
      "x": -1,
      "y": 6,
      "z": 5,
      "name": "Plant_Coral_Block_Red"
    },
    {
      "x": -1,
      "y": 7,
      "z": 5,
      "name": "Plant_Coral_Block_Red"
    },
    {
      "x": -1,
      "y": 8,
      "z": 5,
      "name": "Plant_Coral_Block_Red",
      "rotation": 3
    },
    {
      "x": -1,
      "y": 9,
      "z": 5,
      "name": "Plant_Coral_Bush_Red",
      "rotation": 3
    },
    {
      "x": -1,
      "y": 6,
      "z": 6,
      "name": "Plant_Coral_Block_Red"
    },
    {
      "x": -1,
      "y": 7,
      "z": 6,
      "name": "Plant_Coral_Block_Red"
    },
    {
      "x": -1,
      "y": 9,
      "z": 6,
      "name": "Plant_Coral_Block_Red"
    },
    {
      "x": -1,
      "y": 10,
      "z": 6,
      "name": "Plant_Coral_Bush_Red"
    },
    {
      "x": -1,
      "y": 5,
      "z": 7,
      "name": "Plant_Coral_Block_Red"
    },
    {
      "x": -1,
      "y": 6,
      "z": 7,
      "name": "Plant_Coral_Block_Red"
    },
    {
      "x": -1,
      "y": 9,
      "z": 7,
      "name": "Plant_Coral_Block_Red"
    },
    {
      "x": -1,
      "y": 5,
      "z": 8,
      "name": "Plant_Coral_Block_Red"
    },
    {
      "x": -1,
      "y": 6,
      "z": 8,
      "name": "Plant_Coral_Block_Red"
    },
    {
      "x": -1,
      "y": 9,
      "z": 8,
      "name": "Plant_Coral_Block_Red"
    },
    {
      "x": -1,
      "y": 10,
      "z": 8,
      "name": "Plant_Coral_Bush_Red"
    },
    {
      "x": -1,
      "y": 0,
      "z": 9,
      "name": "Rock_Sandstone_Brick_Half",
      "rotation": 7
    },
    {
      "x": -1,
      "y": 5,
      "z": 9,
      "name": "Plant_Coral_Block_Red"
    },
    {
      "x": -1,
      "y": 6,
      "z": 9,
      "name": "Plant_Coral_Block_Red"
    },
    {
      "x": -1,
      "y": 6,
      "z": 10,
      "name": "Plant_Coral_Block_Red"
    },
    {
      "x": -1,
      "y": 7,
      "z": 10,
      "name": "Plant_Coral_Block_Red"
    },
    {
      "x": -1,
      "y": 6,
      "z": 11,
      "name": "Plant_Coral_Block_Red"
    },
    {
      "x": -1,
      "y": 7,
      "z": 11,
      "name": "Plant_Coral_Block_Red"
    },
    {
      "x": -1,
      "y": 7,
      "z": 12,
      "name": "Plant_Coral_Block_Red"
    },
    {
      "x": 0,
      "y": 10,
      "z": -9,
      "name": "Plant_Coral_Block_Red"
    },
    {
      "x": 0,
      "y": 9,
      "z": -8,
      "name": "Rock_Sandstone_Brick_Stairs",
      "rotation": 8
    },
    {
      "x": 0,
      "y": 10,
      "z": -8,
      "name": "Rock_Sandstone_Brick",
      "rotation": 3
    },
    {
      "x": 0,
      "y": 11,
      "z": -8,
      "name": "Rock_Sandstone_Brick",
      "rotation": 3
    },
    {
      "x": 0,
      "y": 12,
      "z": -8,
      "name": "Plant_Coral_Block_Red",
      "rotation": 1
    },
    {
      "x": 0,
      "y": 13,
      "z": -8,
      "name": "Plant_Coral_Bush_Red",
      "rotation": 1
    },
    {
      "x": 0,
      "y": 8,
      "z": -7,
      "name": "Rock_Sandstone_Cobble",
      "rotation": 3
    },
    {
      "x": 0,
      "y": 9,
      "z": -7,
      "name": "Rock_Sandstone_Cobble",
      "rotation": 3
    },
    {
      "x": 0,
      "y": 10,
      "z": -7,
      "name": "Rock_Sandstone_Brick",
      "rotation": 3
    },
    {
      "x": 0,
      "y": 11,
      "z": -7,
      "name": "Rock_Sandstone_Brick",
      "rotation": 3
    },
    {
      "x": 0,
      "y": 12,
      "z": -7,
      "name": "Plant_Coral_Block_Red",
      "rotation": 1
    },
    {
      "x": 0,
      "y": 7,
      "z": -6,
      "name": "Rock_Sandstone_Brick_Stairs",
      "rotation": 10
    },
    {
      "x": 0,
      "y": 8,
      "z": -6,
      "name": "Rock_Sandstone_Red_Cobble",
      "rotation": 3
    },
    {
      "x": 0,
      "y": 9,
      "z": -6,
      "name": "Rock_Sandstone_Red_Brick",
      "rotation": 3
    },
    {
      "x": 0,
      "y": 10,
      "z": -6,
      "name": "Rock_Sandstone_Cobble",
      "rotation": 3
    },
    {
      "x": 0,
      "y": 11,
      "z": -6,
      "name": "Rock_Sandstone_Brick",
      "rotation": 1
    },
    {
      "x": 0,
      "y": 12,
      "z": -6,
      "name": "Rock_Sandstone_Brick_Smooth_Half",
      "rotation": 7
    },
    {
      "x": 0,
      "y": 13,
      "z": -6,
      "name": "Rock_Sandstone_Brick_Half",
      "rotation": 7
    },
    {
      "x": 0,
      "y": 14,
      "z": -6,
      "name": "Rock_Sandstone_Brick_Half",
      "rotation": 7
    },
    {
      "x": 0,
      "y": 15,
      "z": -6,
      "name": "Rock_Sandstone_Brick_Half",
      "rotation": 7
    },
    {
      "x": 0,
      "y": 16,
      "z": -6,
      "name": "Rock_Sandstone_Brick_Half",
      "rotation": 7
    },
    {
      "x": 0,
      "y": 17,
      "z": -6,
      "name": "Rock_Sandstone_Brick_Smooth_Half",
      "rotation": 7
    },
    {
      "x": 0,
      "y": 20,
      "z": -6,
      "name": "Plant_Coral_Block_Red"
    },
    {
      "x": 0,
      "y": 10,
      "z": -5,
      "name": "Rock_Sandstone_Cobble"
    },
    {
      "x": 0,
      "y": 11,
      "z": -5,
      "name": "Wood_Drywood_Planks",
      "rotation": 1
    },
    {
      "x": 0,
      "y": 12,
      "z": -5,
      "name": "Rock_Sandstone_Brick",
      "rotation": 1
    },
    {
      "x": 0,
      "y": 13,
      "z": -5,
      "name": "Wood_Drywood_Planks",
      "rotation": 1
    },
    {
      "x": 0,
      "y": 14,
      "z": -5,
      "name": "Wood_Drywood_Planks",
      "rotation": 1
    },
    {
      "x": 0,
      "y": 15,
      "z": -5,
      "name": "Wood_Drywood_Planks",
      "rotation": 1
    },
    {
      "x": 0,
      "y": 16,
      "z": -5,
      "name": "Wood_Drywood_Planks",
      "rotation": 1
    },
    {
      "x": 0,
      "y": 17,
      "z": -5,
      "name": "Wood_Drywood_Planks",
      "rotation": 1
    },
    {
      "x": 0,
      "y": 18,
      "z": -5,
      "name": "Wood_Drywood_Planks",
      "rotation": 1
    },
    {
      "x": 0,
      "y": 19,
      "z": -5,
      "name": "Rock_Sandstone_Brick",
      "rotation": 1
    },
    {
      "x": 0,
      "y": 20,
      "z": -5,
      "name": "Rock_Sandstone_Brick_Smooth",
      "rotation": 1
    },
    {
      "x": 0,
      "y": 21,
      "z": -5,
      "name": "Plant_Coral_Bush_Red"
    },
    {
      "x": 0,
      "y": 0,
      "z": -4,
      "name": "Rock_Sandstone_Brick_Half"
    },
    {
      "x": 0,
      "y": 10,
      "z": -4,
      "name": "Rock_Sandstone_Cobble_Half",
      "rotation": 4
    },
    {
      "x": 0,
      "y": 13,
      "z": -4,
      "name": "Plant_Coral_Block_Red",
      "rotation": 2
    },
    {
      "x": 0,
      "y": 14,
      "z": -4,
      "name": "Plant_Coral_Bush_Red",
      "rotation": 2
    },
    {
      "x": 0,
      "y": 15,
      "z": -4,
      "name": "Plant_Coral_Block_Red",
      "rotation": 2
    },
    {
      "x": 0,
      "y": 19,
      "z": -4,
      "name": "Rock_Sandstone_Brick",
      "rotation": 1
    },
    {
      "x": 0,
      "y": 20,
      "z": -4,
      "name": "Rock_Sandstone_Brick",
      "rotation": 1
    },
    {
      "x": 0,
      "y": 0,
      "z": -3,
      "name": "Rock_Sandstone_Brick"
    },
    {
      "x": 0,
      "y": 13,
      "z": -3,
      "name": "Plant_Coral_Block_Red",
      "rotation": 2
    },
    {
      "x": 0,
      "y": 20,
      "z": -3,
      "name": "Plant_Coral_Block_Red"
    },
    {
      "x": 0,
      "y": 0,
      "z": -2,
      "name": "Rubble_Sandstone",
      "support": 15
    },
    {
      "x": 0,
      "y": 16,
      "z": -2,
      "name": "Plant_Coral_Block_Red"
    },
    {
      "x": 0,
      "y": 20,
      "z": -2,
      "name": "Plant_Coral_Block_Red"
    },
    {
      "x": 0,
      "y": 16,
      "z": -1,
      "name": "Plant_Coral_Block_Red"
    },
    {
      "x": 0,
      "y": 17,
      "z": -1,
      "name": "Plant_Coral_Bush_Red"
    },
    {
      "x": 0,
      "y": 18,
      "z": -1,
      "name": "Plant_Coral_Bush_Red",
      "rotation": 3
    },
    {
      "x": 0,
      "y": 16,
      "z": 0,
      "name": "Plant_Coral_Block_Red"
    },
    {
      "x": 0,
      "y": 17,
      "z": 0,
      "name": "Plant_Coral_Block_Red",
      "rotation": 3
    },
    {
      "x": 0,
      "y": 18,
      "z": 0,
      "name": "Plant_Coral_Bush_Red",
      "rotation": 3
    },
    {
      "x": 0,
      "y": 0,
      "z": 1,
      "name": "Rock_Sandstone_Brick_Half",
      "rotation": 6
    },
    {
      "x": 0,
      "y": 17,
      "z": 1,
      "name": "Plant_Coral_Block_Red",
      "rotation": 3
    },
    {
      "x": 0,
      "y": 0,
      "z": 2,
      "name": "Rock_Sandstone_Brick"
    },
    {
      "x": 0,
      "y": 1,
      "z": 2,
      "name": "Rock_Sandstone_Brick"
    },
    {
      "x": 0,
      "y": 0,
      "z": 3,
      "name": "Rock_Sandstone_Brick"
    },
    {
      "x": 0,
      "y": 1,
      "z": 3,
      "name": "Rock_Sandstone_Brick_Half"
    },
    {
      "x": 0,
      "y": 7,
      "z": 3,
      "name": "Plant_Coral_Block_Red"
    },
    {
      "x": 0,
      "y": 0,
      "z": 4,
      "name": "Rock_Sandstone_Brick"
    },
    {
      "x": 0,
      "y": 6,
      "z": 4,
      "name": "Plant_Coral_Block_Red"
    },
    {
      "x": 0,
      "y": 7,
      "z": 4,
      "name": "Plant_Coral_Block_Red"
    },
    {
      "x": 0,
      "y": 6,
      "z": 5,
      "name": "Plant_Coral_Block_Red"
    },
    {
      "x": 0,
      "y": 7,
      "z": 5,
      "name": "Plant_Coral_Block_Red"
    },
    {
      "x": 0,
      "y": 8,
      "z": 5,
      "name": "Plant_Coral_Bush_Red"
    },
    {
      "x": 0,
      "y": 9,
      "z": 5,
      "name": "Plant_Coral_Block_Red"
    },
    {
      "x": 0,
      "y": 5,
      "z": 6,
      "name": "Plant_Coral_Block_Red"
    },
    {
      "x": 0,
      "y": 6,
      "z": 6,
      "name": "Plant_Coral_Block_Red"
    },
    {
      "x": 0,
      "y": 9,
      "z": 6,
      "name": "Plant_Coral_Block_Red"
    },
    {
      "x": 0,
      "y": 5,
      "z": 7,
      "name": "Plant_Coral_Block_Red"
    },
    {
      "x": 0,
      "y": 6,
      "z": 7,
      "name": "Plant_Coral_Block_Red"
    },
    {
      "x": 0,
      "y": 7,
      "z": 7,
      "name": "Rock_Sandstone_Brick_Stairs",
      "rotation": 34
    },
    {
      "x": 0,
      "y": 8,
      "z": 7,
      "name": "Plant_Coral_Block_Red"
    },
    {
      "x": 0,
      "y": 9,
      "z": 7,
      "name": "Plant_Coral_Block_Red"
    },
    {
      "x": 0,
      "y": 0,
      "z": 8,
      "name": "Rock_Sandstone_Brick_Half",
      "rotation": 6
    },
    {
      "x": 0,
      "y": 3,
      "z": 8,
      "name": "Plant_Coral_Block_Red"
    },
    {
      "x": 0,
      "y": 4,
      "z": 8,
      "name": "Plant_Coral_Bush_Red"
    },
    {
      "x": 0,
      "y": 5,
      "z": 8,
      "name": "Plant_Coral_Block_Red"
    },
    {
      "x": 0,
      "y": 6,
      "z": 8,
      "name": "Plant_Coral_Block_Red"
    },
    {
      "x": 0,
      "y": 9,
      "z": 8,
      "name": "Plant_Coral_Block_Red"
    },
    {
      "x": 0,
      "y": 0,
      "z": 9,
      "name": "Rock_Sandstone_Brick",
      "rotation": 3
    },
    {
      "x": 0,
      "y": 3,
      "z": 9,
      "name": "Plant_Coral_Block_Red"
    },
    {
      "x": 0,
      "y": 5,
      "z": 9,
      "name": "Plant_Coral_Block_Red"
    },
    {
      "x": 0,
      "y": 6,
      "z": 9,
      "name": "Plant_Coral_Block_Red"
    },
    {
      "x": 0,
      "y": 7,
      "z": 9,
      "name": "Plant_Coral_Bush_Red"
    },
    {
      "x": 0,
      "y": 9,
      "z": 9,
      "name": "Plant_Coral_Block_Red"
    },
    {
      "x": 0,
      "y": 3,
      "z": 10,
      "name": "Plant_Coral_Block_Red"
    },
    {
      "x": 0,
      "y": 4,
      "z": 10,
      "name": "Plant_Coral_Bush_Red"
    },
    {
      "x": 0,
      "y": 5,
      "z": 10,
      "name": "Plant_Coral_Block_Red"
    },
    {
      "x": 0,
      "y": 6,
      "z": 10,
      "name": "Plant_Coral_Block_Red"
    },
    {
      "x": 0,
      "y": 0,
      "z": 11,
      "name": "Rock_Sandstone_Red_Brick",
      "rotation": 3
    },
    {
      "x": 0,
      "y": 6,
      "z": 11,
      "name": "Plant_Coral_Block_Red"
    },
    {
      "x": 0,
      "y": 7,
      "z": 11,
      "name": "Plant_Coral_Block_Red"
    },
    {
      "x": 0,
      "y": 6,
      "z": 12,
      "name": "Plant_Coral_Block_Red"
    },
    {
      "x": 0,
      "y": 7,
      "z": 12,
      "name": "Plant_Coral_Block_Red"
    },
    {
      "x": 0,
      "y": 8,
      "z": 12,
      "name": "Plant_Coral_Bush_Red"
    },
    {
      "x": 0,
      "y": 7,
      "z": 13,
      "name": "Plant_Coral_Block_Red"
    },
    {
      "x": 1,
      "y": 10,
      "z": -9,
      "name": "Plant_Coral_Block_Red"
    },
    {
      "x": 1,
      "y": 4,
      "z": -8,
      "name": "Rock_Sandstone_Brick_Ornate",
      "rotation": 3
    },
    {
      "x": 1,
      "y": 5,
      "z": -8,
      "name": "Rock_Sandstone_Brick_Stairs",
      "rotation": 2
    },
    {
      "x": 1,
      "y": 9,
      "z": -8,
      "name": "Rock_Sandstone_Brick_Stairs",
      "rotation": 8
    },
    {
      "x": 1,
      "y": 10,
      "z": -8,
      "name": "Rock_Sandstone_Brick",
      "rotation": 3
    },
    {
      "x": 1,
      "y": 11,
      "z": -8,
      "name": "Rock_Sandstone_Brick",
      "rotation": 3
    },
    {
      "x": 1,
      "y": 12,
      "z": -8,
      "name": "Plant_Coral_Block_Red",
      "rotation": 1
    },
    {
      "x": 1,
      "y": 4,
      "z": -7,
      "name": "Rock_Sandstone_Brick",
      "rotation": 3
    },
    {
      "x": 1,
      "y": 5,
      "z": -7,
      "name": "Rock_Sandstone_Cobble",
      "rotation": 3
    },
    {
      "x": 1,
      "y": 6,
      "z": -7,
      "name": "Rock_Sandstone_Cobble",
      "rotation": 3
    },
    {
      "x": 1,
      "y": 7,
      "z": -7,
      "name": "Rock_Sandstone_Cobble",
      "rotation": 3
    },
    {
      "x": 1,
      "y": 8,
      "z": -7,
      "name": "Rock_Sandstone_Cobble",
      "rotation": 3
    },
    {
      "x": 1,
      "y": 9,
      "z": -7,
      "name": "Rock_Sandstone_Cobble",
      "rotation": 3
    },
    {
      "x": 1,
      "y": 10,
      "z": -7,
      "name": "Rock_Sandstone_Brick",
      "rotation": 3
    },
    {
      "x": 1,
      "y": 11,
      "z": -7,
      "name": "Rock_Sandstone_Brick",
      "rotation": 3
    },
    {
      "x": 1,
      "y": 12,
      "z": -7,
      "name": "Plant_Coral_Block_Red",
      "rotation": 1
    },
    {
      "x": 1,
      "y": 13,
      "z": -7,
      "name": "Plant_Coral_Bush_Red",
      "rotation": 1
    },
    {
      "x": 1,
      "y": 3,
      "z": -6,
      "name": "Rock_Sandstone_Red_Brick_Half",
      "rotation": 4
    },
    {
      "x": 1,
      "y": 7,
      "z": -6,
      "name": "Rock_Sandstone_Brick_Stairs",
      "rotation": 10
    },
    {
      "x": 1,
      "y": 8,
      "z": -6,
      "name": "Rock_Sandstone_Red_Cobble",
      "rotation": 3
    },
    {
      "x": 1,
      "y": 9,
      "z": -6,
      "name": "Rock_Sandstone_Red_Brick",
      "rotation": 3
    },
    {
      "x": 1,
      "y": 10,
      "z": -6,
      "name": "Rock_Sandstone_Cobble",
      "rotation": 3
    },
    {
      "x": 1,
      "y": 11,
      "z": -6,
      "name": "Rock_Sandstone_Brick",
      "rotation": 1
    },
    {
      "x": 1,
      "y": 12,
      "z": -6,
      "name": "Plant_Coral_Block_Red",
      "rotation": 1
    },
    {
      "x": 1,
      "y": 13,
      "z": -6,
      "name": "Plant_Coral_Bush_Red",
      "rotation": 1
    },
    {
      "x": 1,
      "y": 17,
      "z": -6,
      "name": "Rock_Sandstone_Brick_Smooth_Half",
      "rotation": 5
    },
    {
      "x": 1,
      "y": 18,
      "z": -6,
      "name": "Rock_Sandstone_Brick_Stairs",
      "rotation": 3
    },
    {
      "x": 1,
      "y": 19,
      "z": -6,
      "name": "Rock_Gold_Brick_Smooth_Half",
      "rotation": 6
    },
    {
      "x": 1,
      "y": 20,
      "z": -6,
      "name": "Rock_Sandstone_Brick",
      "rotation": 1
    },
    {
      "x": 1,
      "y": 21,
      "z": -6,
      "name": "Rock_Sandstone_Brick",
      "rotation": 1
    },
    {
      "x": 1,
      "y": 22,
      "z": -6,
      "name": "Rock_Sandstone_Brick_Beam",
      "rotation": 1
    },
    {
      "x": 1,
      "y": 23,
      "z": -6,
      "name": "Rock_Sandstone_Brick_Beam",
      "rotation": 1
    },
    {
      "x": 1,
      "y": 10,
      "z": -5,
      "name": "Rock_Sandstone_Cobble",
      "rotation": 3
    },
    {
      "x": 1,
      "y": 11,
      "z": -5,
      "name": "Wood_Drywood_Planks",
      "rotation": 1
    },
    {
      "x": 1,
      "y": 12,
      "z": -5,
      "name": "Furniture_Desert_Window",
      "rotation": 2
    },
    {
      "x": 1,
      "y": 13,
      "z": -5,
      "name": "Furniture_Desert_Window",
      "rotation": 2
    },
    {
      "x": 1,
      "y": 14,
      "z": -5,
      "name": "Furniture_Desert_Window",
      "rotation": 2
    },
    {
      "x": 1,
      "y": 15,
      "z": -5,
      "name": "Furniture_Desert_Window",
      "rotation": 2
    },
    {
      "x": 1,
      "y": 16,
      "z": -5,
      "name": "Furniture_Desert_Window",
      "rotation": 2
    },
    {
      "x": 1,
      "y": 17,
      "z": -5,
      "name": "Furniture_Desert_Window",
      "rotation": 2
    },
    {
      "x": 1,
      "y": 18,
      "z": -5,
      "name": "Wood_Drywood_Planks",
      "rotation": 1
    },
    {
      "x": 1,
      "y": 19,
      "z": -5,
      "name": "Rock_Sandstone_Brick",
      "rotation": 1
    },
    {
      "x": 1,
      "y": 20,
      "z": -5,
      "name": "Rock_Sandstone_Brick",
      "rotation": 1
    },
    {
      "x": 1,
      "y": 0,
      "z": -4,
      "name": "Rock_Sandstone_Brick_Half"
    },
    {
      "x": 1,
      "y": 10,
      "z": -4,
      "name": "Rock_Sandstone_Cobble_Half",
      "rotation": 4
    },
    {
      "x": 1,
      "y": 16,
      "z": -4,
      "name": "Plant_Coral_Block_Red"
    },
    {
      "x": 1,
      "y": 19,
      "z": -4,
      "name": "Furniture_Village_Bookcase"
    },
    {
      "x": 1,
      "y": 20,
      "z": -4,
      "name": "Furniture_Village_Bookcase"
    },
    {
      "x": 1,
      "y": 21,
      "z": -4,
      "name": "Plant_Coral_Bush_Red"
    },
    {
      "x": 1,
      "y": 0,
      "z": -3,
      "name": "Rubble_Sandstone_Medium",
      "support": 15
    },
    {
      "x": 1,
      "y": 16,
      "z": -3,
      "name": "Plant_Coral_Block_Red"
    },
    {
      "x": 1,
      "y": 17,
      "z": -3,
      "name": "Plant_Coral_Bush_Red"
    },
    {
      "x": 1,
      "y": 20,
      "z": -3,
      "name": "Plant_Coral_Block_Red"
    },
    {
      "x": 1,
      "y": 15,
      "z": -2,
      "name": "Plant_Coral_Block_Red"
    },
    {
      "x": 1,
      "y": 16,
      "z": -2,
      "name": "Plant_Coral_Block_Red"
    },
    {
      "x": 1,
      "y": 15,
      "z": -1,
      "name": "Plant_Coral_Block_Red"
    },
    {
      "x": 1,
      "y": 16,
      "z": -1,
      "name": "Plant_Coral_Block_Red"
    },
    {
      "x": 1,
      "y": 17,
      "z": -1,
      "name": "Plant_Coral_Block_Red",
      "rotation": 3
    },
    {
      "x": 1,
      "y": 15,
      "z": 0,
      "name": "Plant_Coral_Block_Red"
    },
    {
      "x": 1,
      "y": 16,
      "z": 0,
      "name": "Plant_Coral_Block_Red"
    },
    {
      "x": 1,
      "y": 17,
      "z": 0,
      "name": "Plant_Coral_Block_Red",
      "rotation": 3
    },
    {
      "x": 1,
      "y": 0,
      "z": 1,
      "name": "Rock_Sandstone_Brick",
      "rotation": 3
    },
    {
      "x": 1,
      "y": 16,
      "z": 1,
      "name": "Plant_Coral_Block_Red"
    },
    {
      "x": 1,
      "y": 17,
      "z": 1,
      "name": "Plant_Coral_Block_Red",
      "rotation": 3
    },
    {
      "x": 1,
      "y": 18,
      "z": 1,
      "name": "Plant_Coral_Bush_Red",
      "rotation": 3
    },
    {
      "x": 1,
      "y": 0,
      "z": 2,
      "name": "Rock_Sandstone_Brick"
    },
    {
      "x": 1,
      "y": 1,
      "z": 2,
      "name": "Rock_Sandstone_Brick_Half",
      "rotation": 5
    },
    {
      "x": 1,
      "y": 16,
      "z": 2,
      "name": "Plant_Coral_Block_Red"
    },
    {
      "x": 1,
      "y": 0,
      "z": 3,
      "name": "Rock_Sandstone_Brick"
    },
    {
      "x": 1,
      "y": 1,
      "z": 3,
      "name": "Rubble_Sandstone_Medium",
      "support": 15
    },
    {
      "x": 1,
      "y": 7,
      "z": 3,
      "name": "Plant_Coral_Block_Red"
    },
    {
      "x": 1,
      "y": 0,
      "z": 4,
      "name": "Rock_Sandstone_Brick"
    },
    {
      "x": 1,
      "y": 6,
      "z": 4,
      "name": "Plant_Coral_Block_Red"
    },
    {
      "x": 1,
      "y": 7,
      "z": 4,
      "name": "Plant_Coral_Block_Red"
    },
    {
      "x": 1,
      "y": 6,
      "z": 5,
      "name": "Plant_Coral_Block_Red"
    },
    {
      "x": 1,
      "y": 7,
      "z": 5,
      "name": "Plant_Coral_Block_Red"
    },
    {
      "x": 1,
      "y": 9,
      "z": 5,
      "name": "Plant_Coral_Block_Red"
    },
    {
      "x": 1,
      "y": 10,
      "z": 5,
      "name": "Plant_Coral_Bush_Red"
    },
    {
      "x": 1,
      "y": 5,
      "z": 6,
      "name": "Plant_Coral_Block_Red"
    },
    {
      "x": 1,
      "y": 6,
      "z": 6,
      "name": "Plant_Coral_Block_Red"
    },
    {
      "x": 1,
      "y": 8,
      "z": 6,
      "name": "Plant_Coral_Block_Red"
    },
    {
      "x": 1,
      "y": 9,
      "z": 6,
      "name": "Plant_Coral_Block_Red"
    },
    {
      "x": 1,
      "y": 10,
      "z": 6,
      "name": "Rock_Sandstone_Cobble",
      "rotation": 3
    },
    {
      "x": 1,
      "y": 0,
      "z": 7,
      "name": "Rock_Sandstone_Brick_Half",
      "rotation": 7
    },
    {
      "x": 1,
      "y": 3,
      "z": 7,
      "name": "Rock_Sandstone_Red_Brick_Half",
      "rotation": 6
    },
    {
      "x": 1,
      "y": 5,
      "z": 7,
      "name": "Plant_Coral_Block_Red"
    },
    {
      "x": 1,
      "y": 6,
      "z": 7,
      "name": "Plant_Coral_Block_Red"
    },
    {
      "x": 1,
      "y": 7,
      "z": 7,
      "name": "Rock_Sandstone_Brick_Stairs",
      "rotation": 34
    },
    {
      "x": 1,
      "y": 8,
      "z": 7,
      "name": "Rock_Sandstone_Red_Brick",
      "rotation": 3
    },
    {
      "x": 1,
      "y": 9,
      "z": 7,
      "name": "Rock_Sandstone_Red_Brick",
      "rotation": 3
    },
    {
      "x": 1,
      "y": 10,
      "z": 7,
      "name": "Plant_Coral_Bush_Red"
    },
    {
      "x": 1,
      "y": 12,
      "z": 7,
      "name": "Plant_Coral_Block_Red",
      "rotation": 3
    },
    {
      "x": 1,
      "y": 0,
      "z": 8,
      "name": "Rock_Sandstone_Brick",
      "rotation": 3
    },
    {
      "x": 1,
      "y": 1,
      "z": 8,
      "name": "Rock_Sandstone_Brick",
      "rotation": 3
    },
    {
      "x": 1,
      "y": 2,
      "z": 8,
      "name": "Rock_Sandstone_Brick",
      "rotation": 3
    },
    {
      "x": 1,
      "y": 3,
      "z": 8,
      "name": "Rock_Sandstone_Brick",
      "rotation": 3
    },
    {
      "x": 1,
      "y": 4,
      "z": 8,
      "name": "Rock_Sandstone_Brick",
      "rotation": 3
    },
    {
      "x": 1,
      "y": 5,
      "z": 8,
      "name": "Rock_Sandstone_Cobble",
      "rotation": 3
    },
    {
      "x": 1,
      "y": 6,
      "z": 8,
      "name": "Rock_Sandstone_Cobble",
      "rotation": 3
    },
    {
      "x": 1,
      "y": 7,
      "z": 8,
      "name": "Rock_Sandstone_Cobble",
      "rotation": 3
    },
    {
      "x": 1,
      "y": 8,
      "z": 8,
      "name": "Plant_Coral_Block_Red"
    },
    {
      "x": 1,
      "y": 9,
      "z": 8,
      "name": "Plant_Coral_Block_Red"
    },
    {
      "x": 1,
      "y": 12,
      "z": 8,
      "name": "Plant_Coral_Block_Red",
      "rotation": 3
    },
    {
      "x": 1,
      "y": 13,
      "z": 8,
      "name": "Plant_Coral_Bush_Red",
      "rotation": 3
    },
    {
      "x": 1,
      "y": 0,
      "z": 9,
      "name": "Rock_Sandstone_Brick",
      "rotation": 3
    },
    {
      "x": 1,
      "y": 1,
      "z": 9,
      "name": "Rock_Sandstone_Brick",
      "rotation": 3
    },
    {
      "x": 1,
      "y": 2,
      "z": 9,
      "name": "Rock_Sandstone_Brick",
      "rotation": 3
    },
    {
      "x": 1,
      "y": 3,
      "z": 9,
      "name": "Rock_Sandstone_Brick",
      "rotation": 3
    },
    {
      "x": 1,
      "y": 4,
      "z": 9,
      "name": "Rock_Sandstone_Brick_Ornate",
      "rotation": 3
    },
    {
      "x": 1,
      "y": 5,
      "z": 9,
      "name": "Rock_Sandstone_Brick_Stairs"
    },
    {
      "x": 1,
      "y": 6,
      "z": 9,
      "name": "Plant_Coral_Block_Red"
    },
    {
      "x": 1,
      "y": 9,
      "z": 9,
      "name": "Plant_Coral_Block_Red"
    },
    {
      "x": 1,
      "y": 10,
      "z": 9,
      "name": "Plant_Coral_Bush_Red"
    },
    {
      "x": 1,
      "y": 12,
      "z": 9,
      "name": "Plant_Coral_Block_Red",
      "rotation": 3
    },
    {
      "x": 1,
      "y": 0,
      "z": 10,
      "name": "Rock_Sandstone_Red_Brick",
      "rotation": 3
    },
    {
      "x": 1,
      "y": 1,
      "z": 10,
      "name": "Rock_Sandstone_Red_Brick",
      "rotation": 3
    },
    {
      "x": 1,
      "y": 3,
      "z": 10,
      "name": "Plant_Coral_Block_Red"
    },
    {
      "x": 1,
      "y": 5,
      "z": 10,
      "name": "Plant_Coral_Block_Red"
    },
    {
      "x": 1,
      "y": 6,
      "z": 10,
      "name": "Plant_Coral_Block_Red"
    },
    {
      "x": 1,
      "y": 0,
      "z": 11,
      "name": "Rock_Sandstone_Red_Brick",
      "rotation": 3
    },
    {
      "x": 1,
      "y": 1,
      "z": 11,
      "name": "Rock_Sandstone_Red_Brick",
      "rotation": 3
    },
    {
      "x": 1,
      "y": 3,
      "z": 11,
      "name": "Plant_Coral_Block_Red"
    },
    {
      "x": 1,
      "y": 6,
      "z": 11,
      "name": "Plant_Coral_Block_Red"
    },
    {
      "x": 1,
      "y": 7,
      "z": 11,
      "name": "Plant_Coral_Block_Red"
    },
    {
      "x": 1,
      "y": 6,
      "z": 12,
      "name": "Plant_Coral_Block_Red"
    },
    {
      "x": 1,
      "y": 7,
      "z": 12,
      "name": "Plant_Coral_Block_Red"
    },
    {
      "x": 1,
      "y": 7,
      "z": 13,
      "name": "Plant_Coral_Block_Red"
    },
    {
      "x": 2,
      "y": 6,
      "z": -9,
      "name": "Plant_Coral_Block_Red"
    },
    {
      "x": 2,
      "y": 10,
      "z": -9,
      "name": "Plant_Coral_Block_Red"
    },
    {
      "x": 2,
      "y": 11,
      "z": -9,
      "name": "Plant_Coral_Bush_Red"
    },
    {
      "x": 2,
      "y": 3,
      "z": -8,
      "name": "Rock_Sandstone_Cobble",
      "rotation": 3
    },
    {
      "x": 2,
      "y": 4,
      "z": -8,
      "name": "Rock_Sandstone_Brick_Ornate",
      "rotation": 3
    },
    {
      "x": 2,
      "y": 5,
      "z": -8,
      "name": "Rock_Sandstone_Brick_Stairs",
      "rotation": 2
    },
    {
      "x": 2,
      "y": 6,
      "z": -8,
      "name": "Plant_Coral_Block_Red"
    },
    {
      "x": 2,
      "y": 7,
      "z": -8,
      "name": "Plant_Coral_Bush_Red"
    },
    {
      "x": 2,
      "y": 9,
      "z": -8,
      "name": "Rock_Sandstone_Brick_Stairs",
      "rotation": 8
    },
    {
      "x": 2,
      "y": 10,
      "z": -8,
      "name": "Rock_Sandstone_Brick",
      "rotation": 3
    },
    {
      "x": 2,
      "y": 11,
      "z": -8,
      "name": "Rock_Sandstone_Brick",
      "rotation": 3
    },
    {
      "x": 2,
      "y": 12,
      "z": -8,
      "name": "Plant_Coral_Block_Red",
      "rotation": 1
    },
    {
      "x": 2,
      "y": 2,
      "z": -7,
      "name": "Rock_Sandstone_Brick",
      "rotation": 3
    },
    {
      "x": 2,
      "y": 3,
      "z": -7,
      "name": "Rock_Sandstone_Brick",
      "rotation": 3
    },
    {
      "x": 2,
      "y": 4,
      "z": -7,
      "name": "Rock_Sandstone_Brick",
      "rotation": 3
    },
    {
      "x": 2,
      "y": 5,
      "z": -7,
      "name": "Rock_Sandstone_Cobble",
      "rotation": 3
    },
    {
      "x": 2,
      "y": 6,
      "z": -7,
      "name": "Rock_Sandstone_Cobble",
      "rotation": 3
    },
    {
      "x": 2,
      "y": 7,
      "z": -7,
      "name": "Rock_Sandstone_Cobble",
      "rotation": 3
    },
    {
      "x": 2,
      "y": 8,
      "z": -7,
      "name": "Rock_Sandstone_Cobble",
      "rotation": 3
    },
    {
      "x": 2,
      "y": 9,
      "z": -7,
      "name": "Rock_Sandstone_Cobble",
      "rotation": 3
    },
    {
      "x": 2,
      "y": 10,
      "z": -7,
      "name": "Rock_Sandstone_Brick",
      "rotation": 3
    },
    {
      "x": 2,
      "y": 11,
      "z": -7,
      "name": "Rock_Sandstone_Brick",
      "rotation": 3
    },
    {
      "x": 2,
      "y": 12,
      "z": -7,
      "name": "Plant_Coral_Block_Red",
      "rotation": 1
    },
    {
      "x": 2,
      "y": 13,
      "z": -7,
      "name": "Plant_Coral_Bush_Red",
      "rotation": 1
    },
    {
      "x": 2,
      "y": 19,
      "z": -7,
      "name": "Plant_Coral_Block_Red",
      "rotation": 3
    },
    {
      "x": 2,
      "y": 22,
      "z": -7,
      "name": "Plant_Coral_Block_Red"
    },
    {
      "x": 2,
      "y": 23,
      "z": -7,
      "name": "Plant_Coral_Bush_Red"
    },
    {
      "x": 2,
      "y": 3,
      "z": -6,
      "name": "Rock_Sandstone_Red_Brick_Half",
      "rotation": 4
    },
    {
      "x": 2,
      "y": 7,
      "z": -6,
      "name": "Rock_Sandstone_Brick_Stairs",
      "rotation": 10
    },
    {
      "x": 2,
      "y": 8,
      "z": -6,
      "name": "Rock_Sandstone_Red_Brick",
      "rotation": 3
    },
    {
      "x": 2,
      "y": 9,
      "z": -6,
      "name": "Rock_Sandstone_Red_Brick",
      "rotation": 3
    },
    {
      "x": 2,
      "y": 10,
      "z": -6,
      "name": "Rock_Sandstone_Cobble",
      "rotation": 3
    },
    {
      "x": 2,
      "y": 11,
      "z": -6,
      "name": "Rock_Sandstone_Brick",
      "rotation": 1
    },
    {
      "x": 2,
      "y": 12,
      "z": -6,
      "name": "Plant_Coral_Block_Red",
      "rotation": 1
    },
    {
      "x": 2,
      "y": 18,
      "z": -6,
      "name": "Rock_Sandstone_Brick_Smooth_Half",
      "rotation": 35
    },
    {
      "x": 2,
      "y": 19,
      "z": -6,
      "name": "Rock_Sandstone_Brick_Smooth_Half",
      "rotation": 1
    },
    {
      "x": 2,
      "y": 20,
      "z": -6,
      "name": "Rock_Sandstone_Brick_Smooth",
      "rotation": 1
    },
    {
      "x": 2,
      "y": 22,
      "z": -6,
      "name": "Plant_Coral_Block_Red"
    },
    {
      "x": 2,
      "y": 0,
      "z": -5,
      "name": "Rock_Sandstone_Brick"
    },
    {
      "x": 2,
      "y": 1,
      "z": -5,
      "name": "Rock_Sandstone_Cobble_Half"
    },
    {
      "x": 2,
      "y": 10,
      "z": -5,
      "name": "Rock_Sandstone_Cobble",
      "rotation": 3
    },
    {
      "x": 2,
      "y": 11,
      "z": -5,
      "name": "Wood_Drywood_Planks",
      "rotation": 1
    },
    {
      "x": 2,
      "y": 12,
      "z": -5,
      "name": "Furniture_Desert_Window",
      "rotation": 2
    },
    {
      "x": 2,
      "y": 13,
      "z": -5,
      "name": "Furniture_Desert_Window",
      "rotation": 2
    },
    {
      "x": 2,
      "y": 16,
      "z": -5,
      "name": "Furniture_Desert_Window",
      "rotation": 2
    },
    {
      "x": 2,
      "y": 17,
      "z": -5,
      "name": "Furniture_Desert_Window",
      "rotation": 2
    },
    {
      "x": 2,
      "y": 18,
      "z": -5,
      "name": "Furniture_Desert_Window",
      "rotation": 2
    },
    {
      "x": 2,
      "y": 19,
      "z": -5,
      "name": "Rock_Sandstone_Brick",
      "rotation": 1
    },
    {
      "x": 2,
      "y": 20,
      "z": -5,
      "name": "Rock_Sandstone_Brick",
      "rotation": 1
    },
    {
      "x": 2,
      "y": 22,
      "z": -5,
      "name": "Plant_Coral_Block_Red"
    },
    {
      "x": 2,
      "y": 23,
      "z": -5,
      "name": "Plant_Coral_Bush_Red"
    },
    {
      "x": 2,
      "y": 0,
      "z": -4,
      "name": "Rock_Sandstone_Cobble_Half"
    },
    {
      "x": 2,
      "y": 10,
      "z": -4,
      "name": "Rock_Sandstone_Cobble"
    },
    {
      "x": 2,
      "y": 16,
      "z": -4,
      "name": "Plant_Coral_Block_Red"
    },
    {
      "x": 2,
      "y": 19,
      "z": -4,
      "name": "Furniture_Village_Bookcase"
    },
    {
      "x": 2,
      "y": 20,
      "z": -4,
      "name": "Furniture_Village_Bookcase"
    },
    {
      "x": 2,
      "y": 15,
      "z": -3,
      "name": "Plant_Coral_Block_Red"
    },
    {
      "x": 2,
      "y": 16,
      "z": -3,
      "name": "Plant_Coral_Block_Red"
    },
    {
      "x": 2,
      "y": 19,
      "z": -3,
      "name": "Plant_Coral_Block_Red",
      "rotation": 3
    },
    {
      "x": 2,
      "y": 20,
      "z": -3,
      "name": "Plant_Coral_Bush_Red",
      "rotation": 3
    },
    {
      "x": 2,
      "y": 15,
      "z": -2,
      "name": "Plant_Coral_Block_Red"
    },
    {
      "x": 2,
      "y": 16,
      "z": -2,
      "name": "Plant_Coral_Block_Red"
    },
    {
      "x": 2,
      "y": 19,
      "z": -2,
      "name": "Plant_Coral_Block_Red",
      "rotation": 3
    },
    {
      "x": 2,
      "y": 0,
      "z": -1,
      "name": "Rubble_Sandstone",
      "support": 15
    },
    {
      "x": 2,
      "y": 15,
      "z": -1,
      "name": "Plant_Coral_Block_Red"
    },
    {
      "x": 2,
      "y": 16,
      "z": -1,
      "name": "Plant_Coral_Block_Red"
    },
    {
      "x": 2,
      "y": 0,
      "z": 0,
      "name": "Soil_Sand"
    },
    {
      "x": 2,
      "y": 15,
      "z": 0,
      "name": "Plant_Coral_Block_Red"
    },
    {
      "x": 2,
      "y": 16,
      "z": 0,
      "name": "Plant_Coral_Block_Red"
    },
    {
      "x": 2,
      "y": 17,
      "z": 0,
      "name": "Plant_Coral_Bush_Red"
    },
    {
      "x": 2,
      "y": 0,
      "z": 1,
      "name": "Rock_Sandstone_Brick"
    },
    {
      "x": 2,
      "y": 15,
      "z": 1,
      "name": "Plant_Coral_Block_Red"
    },
    {
      "x": 2,
      "y": 16,
      "z": 1,
      "name": "Plant_Coral_Block_Red"
    },
    {
      "x": 2,
      "y": 21,
      "z": 1,
      "name": "Plant_Coral_Block_Red",
      "rotation": 2
    },
    {
      "x": 2,
      "y": 0,
      "z": 2,
      "name": "Rock_Sandstone_Brick"
    },
    {
      "x": 2,
      "y": 11,
      "z": 2,
      "name": "Plant_Coral_Block_Red"
    },
    {
      "x": 2,
      "y": 12,
      "z": 2,
      "name": "Plant_Coral_Bush_Red"
    },
    {
      "x": 2,
      "y": 16,
      "z": 2,
      "name": "Plant_Coral_Block_Red"
    },
    {
      "x": 2,
      "y": 17,
      "z": 2,
      "name": "Plant_Coral_Bush_Red"
    },
    {
      "x": 2,
      "y": 21,
      "z": 2,
      "name": "Plant_Coral_Block_Red",
      "rotation": 2
    },
    {
      "x": 2,
      "y": 0,
      "z": 3,
      "name": "Rock_Sandstone_Brick"
    },
    {
      "x": 2,
      "y": 7,
      "z": 3,
      "name": "Plant_Coral_Block_Red"
    },
    {
      "x": 2,
      "y": 8,
      "z": 3,
      "name": "Plant_Coral_Bush_Red"
    },
    {
      "x": 2,
      "y": 11,
      "z": 3,
      "name": "Plant_Coral_Block_Red"
    },
    {
      "x": 2,
      "y": 16,
      "z": 3,
      "name": "Plant_Coral_Block_Red"
    },
    {
      "x": 2,
      "y": 17,
      "z": 3,
      "name": "Plant_Coral_Bush_Red"
    },
    {
      "x": 2,
      "y": 21,
      "z": 3,
      "name": "Plant_Coral_Block_Red",
      "rotation": 2
    },
    {
      "x": 2,
      "y": 22,
      "z": 3,
      "name": "Plant_Coral_Bush_Red",
      "rotation": 2
    },
    {
      "x": 2,
      "y": 6,
      "z": 4,
      "name": "Plant_Coral_Block_Red"
    },
    {
      "x": 2,
      "y": 7,
      "z": 4,
      "name": "Plant_Coral_Block_Red"
    },
    {
      "x": 2,
      "y": 11,
      "z": 4,
      "name": "Plant_Coral_Block_Red"
    },
    {
      "x": 2,
      "y": 12,
      "z": 4,
      "name": "Plant_Coral_Bush_Red"
    },
    {
      "x": 2,
      "y": 6,
      "z": 5,
      "name": "Plant_Coral_Block_Red"
    },
    {
      "x": 2,
      "y": 7,
      "z": 5,
      "name": "Plant_Coral_Block_Red"
    },
    {
      "x": 2,
      "y": 9,
      "z": 5,
      "name": "Plant_Coral_Block_Red"
    },
    {
      "x": 2,
      "y": 10,
      "z": 5,
      "name": "Rock_Sandstone_Cobble"
    },
    {
      "x": 2,
      "y": 0,
      "z": 6,
      "name": "Rock_Sandstone_Brick"
    },
    {
      "x": 2,
      "y": 5,
      "z": 6,
      "name": "Plant_Coral_Block_Red"
    },
    {
      "x": 2,
      "y": 6,
      "z": 6,
      "name": "Plant_Coral_Block_Red"
    },
    {
      "x": 2,
      "y": 7,
      "z": 6,
      "name": "Plant_Coral_Bush_Red"
    },
    {
      "x": 2,
      "y": 9,
      "z": 6,
      "name": "Plant_Coral_Block_Red"
    },
    {
      "x": 2,
      "y": 10,
      "z": 6,
      "name": "Rock_Sandstone",
      "rotation": 3
    },
    {
      "x": 2,
      "y": 0,
      "z": 7,
      "name": "Rock_Sandstone_Brick"
    },
    {
      "x": 2,
      "y": 3,
      "z": 7,
      "name": "Rock_Sandstone_Red_Brick_Half",
      "rotation": 6
    },
    {
      "x": 2,
      "y": 4,
      "z": 7,
      "name": "Plant_Coral_Bush_Red"
    },
    {
      "x": 2,
      "y": 5,
      "z": 7,
      "name": "Plant_Coral_Block_Red"
    },
    {
      "x": 2,
      "y": 6,
      "z": 7,
      "name": "Plant_Coral_Block_Red"
    },
    {
      "x": 2,
      "y": 8,
      "z": 7,
      "name": "Rock_Sandstone_Red_Brick",
      "rotation": 3
    },
    {
      "x": 2,
      "y": 9,
      "z": 7,
      "name": "Rock_Sandstone_Red_Brick",
      "rotation": 3
    },
    {
      "x": 2,
      "y": 10,
      "z": 7,
      "name": "Rock_Sandstone",
      "rotation": 3
    },
    {
      "x": 2,
      "y": 11,
      "z": 7,
      "name": "Wood_Drywood_Planks"
    },
    {
      "x": 2,
      "y": 12,
      "z": 7,
      "name": "Plant_Coral_Block_Red",
      "rotation": 3
    },
    {
      "x": 2,
      "y": 13,
      "z": 7,
      "name": "Plant_Coral_Bush_Red",
      "rotation": 3
    },
    {
      "x": 2,
      "y": 0,
      "z": 8,
      "name": "Rock_Sandstone_Brick",
      "rotation": 3
    },
    {
      "x": 2,
      "y": 1,
      "z": 8,
      "name": "Rock_Sandstone_Brick",
      "rotation": 3
    },
    {
      "x": 2,
      "y": 2,
      "z": 8,
      "name": "Rock_Sandstone_Brick",
      "rotation": 3
    },
    {
      "x": 2,
      "y": 3,
      "z": 8,
      "name": "Rock_Sandstone_Brick",
      "rotation": 3
    },
    {
      "x": 2,
      "y": 4,
      "z": 8,
      "name": "Rock_Sandstone_Brick",
      "rotation": 3
    },
    {
      "x": 2,
      "y": 5,
      "z": 8,
      "name": "Rock_Sandstone_Cobble",
      "rotation": 3
    },
    {
      "x": 2,
      "y": 6,
      "z": 8,
      "name": "Rock_Sandstone_Cobble",
      "rotation": 3
    },
    {
      "x": 2,
      "y": 7,
      "z": 8,
      "name": "Rock_Sandstone_Cobble",
      "rotation": 3
    },
    {
      "x": 2,
      "y": 8,
      "z": 8,
      "name": "Rock_Sandstone_Cobble",
      "rotation": 3
    },
    {
      "x": 2,
      "y": 9,
      "z": 8,
      "name": "Rock_Sandstone_Cobble",
      "rotation": 3
    },
    {
      "x": 2,
      "y": 10,
      "z": 8,
      "name": "Rock_Sandstone_Brick",
      "rotation": 3
    },
    {
      "x": 2,
      "y": 11,
      "z": 8,
      "name": "Rock_Sandstone_Brick",
      "rotation": 3
    },
    {
      "x": 2,
      "y": 12,
      "z": 8,
      "name": "Plant_Coral_Block_Red",
      "rotation": 3
    },
    {
      "x": 2,
      "y": 13,
      "z": 8,
      "name": "Plant_Coral_Bush_Red",
      "rotation": 3
    },
    {
      "x": 2,
      "y": 0,
      "z": 9,
      "name": "Rock_Sandstone_Brick",
      "rotation": 3
    },
    {
      "x": 2,
      "y": 1,
      "z": 9,
      "name": "Rock_Sandstone_Brick",
      "rotation": 3
    },
    {
      "x": 2,
      "y": 2,
      "z": 9,
      "name": "Rock_Sandstone_Cobble",
      "rotation": 3
    },
    {
      "x": 2,
      "y": 3,
      "z": 9,
      "name": "Rock_Sandstone_Cobble",
      "rotation": 3
    },
    {
      "x": 2,
      "y": 4,
      "z": 9,
      "name": "Rock_Sandstone_Brick_Ornate",
      "rotation": 3
    },
    {
      "x": 2,
      "y": 5,
      "z": 9,
      "name": "Rock_Sandstone_Brick_Stairs"
    },
    {
      "x": 2,
      "y": 6,
      "z": 9,
      "name": "Plant_Coral_Block_Red"
    },
    {
      "x": 2,
      "y": 9,
      "z": 9,
      "name": "Plant_Coral_Block_Red"
    },
    {
      "x": 2,
      "y": 12,
      "z": 9,
      "name": "Plant_Coral_Block_Red",
      "rotation": 3
    },
    {
      "x": 2,
      "y": 0,
      "z": 10,
      "name": "Soil_Sand"
    },
    {
      "x": 2,
      "y": 2,
      "z": 10,
      "name": "Plant_Coral_Block_Red"
    },
    {
      "x": 2,
      "y": 3,
      "z": 10,
      "name": "Plant_Coral_Block_Red"
    },
    {
      "x": 2,
      "y": 5,
      "z": 10,
      "name": "Plant_Coral_Block_Red"
    },
    {
      "x": 2,
      "y": 6,
      "z": 10,
      "name": "Plant_Coral_Block_Red"
    },
    {
      "x": 2,
      "y": 7,
      "z": 10,
      "name": "Plant_Coral_Bush_Red"
    },
    {
      "x": 2,
      "y": 3,
      "z": 11,
      "name": "Plant_Coral_Block_Red"
    },
    {
      "x": 2,
      "y": 4,
      "z": 11,
      "name": "Plant_Coral_Bush_Red"
    },
    {
      "x": 2,
      "y": 6,
      "z": 11,
      "name": "Plant_Coral_Block_Red"
    },
    {
      "x": 2,
      "y": 7,
      "z": 11,
      "name": "Plant_Coral_Block_Red"
    },
    {
      "x": 2,
      "y": 8,
      "z": 11,
      "name": "Plant_Coral_Bush_Red"
    },
    {
      "x": 2,
      "y": 6,
      "z": 12,
      "name": "Plant_Coral_Block_Red"
    },
    {
      "x": 2,
      "y": 7,
      "z": 12,
      "name": "Plant_Coral_Block_Red"
    },
    {
      "x": 2,
      "y": 7,
      "z": 13,
      "name": "Plant_Coral_Block_Red"
    },
    {
      "x": 3,
      "y": 0,
      "z": -9,
      "name": "Rock_Sandstone"
    },
    {
      "x": 3,
      "y": 6,
      "z": -9,
      "name": "Plant_Coral_Block_Red"
    },
    {
      "x": 3,
      "y": 0,
      "z": -8,
      "name": "Rock_Sandstone_Cobble",
      "rotation": 3
    },
    {
      "x": 3,
      "y": 1,
      "z": -8,
      "name": "Rock_Sandstone_Cobble",
      "rotation": 3
    },
    {
      "x": 3,
      "y": 2,
      "z": -8,
      "name": "Rock_Sandstone_Cobble",
      "rotation": 3
    },
    {
      "x": 3,
      "y": 3,
      "z": -8,
      "name": "Rock_Sandstone_Cobble",
      "rotation": 3
    },
    {
      "x": 3,
      "y": 4,
      "z": -8,
      "name": "Rock_Sandstone_Brick_Ornate",
      "rotation": 3
    },
    {
      "x": 3,
      "y": 5,
      "z": -8,
      "name": "Rock_Sandstone_Brick_Stairs",
      "rotation": 2
    },
    {
      "x": 3,
      "y": 6,
      "z": -8,
      "name": "Plant_Coral_Block_Red"
    },
    {
      "x": 3,
      "y": 7,
      "z": -8,
      "name": "Plant_Coral_Bush_Red"
    },
    {
      "x": 3,
      "y": 10,
      "z": -8,
      "name": "Rock_Sandstone_Brick",
      "rotation": 3
    },
    {
      "x": 3,
      "y": 11,
      "z": -8,
      "name": "Rock_Sandstone_Brick",
      "rotation": 3
    },
    {
      "x": 3,
      "y": 22,
      "z": -8,
      "name": "Plant_Coral_Block_Red"
    },
    {
      "x": 3,
      "y": 0,
      "z": -7,
      "name": "Rock_Sandstone_Brick",
      "rotation": 3
    },
    {
      "x": 3,
      "y": 1,
      "z": -7,
      "name": "Rock_Sandstone_Brick",
      "rotation": 3
    },
    {
      "x": 3,
      "y": 2,
      "z": -7,
      "name": "Rock_Sandstone_Brick",
      "rotation": 3
    },
    {
      "x": 3,
      "y": 3,
      "z": -7,
      "name": "Rock_Sandstone_Brick",
      "rotation": 3
    },
    {
      "x": 3,
      "y": 4,
      "z": -7,
      "name": "Rock_Sandstone_Brick",
      "rotation": 3
    },
    {
      "x": 3,
      "y": 5,
      "z": -7,
      "name": "Rock_Sandstone_Cobble",
      "rotation": 3
    },
    {
      "x": 3,
      "y": 6,
      "z": -7,
      "name": "Rock_Sandstone_Cobble",
      "rotation": 3
    },
    {
      "x": 3,
      "y": 7,
      "z": -7,
      "name": "Rock_Sandstone_Cobble",
      "rotation": 3
    },
    {
      "x": 3,
      "y": 8,
      "z": -7,
      "name": "Rock_Sandstone_Cobble",
      "rotation": 3
    },
    {
      "x": 3,
      "y": 9,
      "z": -7,
      "name": "Rock_Sandstone_Cobble",
      "rotation": 3
    },
    {
      "x": 3,
      "y": 10,
      "z": -7,
      "name": "Rock_Sandstone_Brick",
      "rotation": 3
    },
    {
      "x": 3,
      "y": 11,
      "z": -7,
      "name": "Rock_Sandstone_Brick",
      "rotation": 3
    },
    {
      "x": 3,
      "y": 19,
      "z": -7,
      "name": "Plant_Coral_Block_Red",
      "rotation": 3
    },
    {
      "x": 3,
      "y": 20,
      "z": -7,
      "name": "Plant_Coral_Bush_Red",
      "rotation": 3
    },
    {
      "x": 3,
      "y": 22,
      "z": -7,
      "name": "Plant_Coral_Block_Red"
    },
    {
      "x": 3,
      "y": 0,
      "z": -6,
      "name": "Rock_Sandstone_Brick"
    },
    {
      "x": 3,
      "y": 3,
      "z": -6,
      "name": "Rock_Sandstone_Red_Brick_Half",
      "rotation": 4
    },
    {
      "x": 3,
      "y": 7,
      "z": -6,
      "name": "Rock_Sandstone_Brick_Stairs",
      "rotation": 10
    },
    {
      "x": 3,
      "y": 8,
      "z": -6,
      "name": "Rock_Sandstone_Red_Cobble",
      "rotation": 3
    },
    {
      "x": 3,
      "y": 9,
      "z": -6,
      "name": "Rock_Sandstone_Red_Brick",
      "rotation": 3
    },
    {
      "x": 3,
      "y": 11,
      "z": -6,
      "name": "Rock_Sandstone_Brick",
      "rotation": 1
    },
    {
      "x": 3,
      "y": 17,
      "z": -6,
      "name": "Rock_Sandstone_Brick_Smooth_Half",
      "rotation": 7
    },
    {
      "x": 3,
      "y": 18,
      "z": -6,
      "name": "Rock_Sandstone_Brick_Stairs",
      "rotation": 1
    },
    {
      "x": 3,
      "y": 19,
      "z": -6,
      "name": "Rock_Gold_Brick_Smooth_Half",
      "rotation": 6
    },
    {
      "x": 3,
      "y": 20,
      "z": -6,
      "name": "Rock_Sandstone_Brick_Smooth",
      "rotation": 1
    },
    {
      "x": 3,
      "y": 21,
      "z": -6,
      "name": "Plant_Coral_Block_Red"
    },
    {
      "x": 3,
      "y": 22,
      "z": -6,
      "name": "Plant_Coral_Block_Red"
    },
    {
      "x": 3,
      "y": 0,
      "z": -5,
      "name": "Rock_Sandstone_Brick"
    },
    {
      "x": 3,
      "y": 1,
      "z": -5,
      "name": "Rubble_Sandstone",
      "support": 15
    },
    {
      "x": 3,
      "y": 10,
      "z": -5,
      "name": "Rock_Sandstone_Cobble"
    },
    {
      "x": 3,
      "y": 11,
      "z": -5,
      "name": "Wood_Drywood_Planks",
      "rotation": 1
    },
    {
      "x": 3,
      "y": 12,
      "z": -5,
      "name": "Furniture_Desert_Window",
      "rotation": 2
    },
    {
      "x": 3,
      "y": 13,
      "z": -5,
      "name": "Furniture_Desert_Window",
      "rotation": 2
    },
    {
      "x": 3,
      "y": 14,
      "z": -5,
      "name": "Furniture_Desert_Window",
      "rotation": 2
    },
    {
      "x": 3,
      "y": 16,
      "z": -5,
      "name": "Plant_Coral_Block_Red"
    },
    {
      "x": 3,
      "y": 17,
      "z": -5,
      "name": "Furniture_Desert_Window",
      "rotation": 2
    },
    {
      "x": 3,
      "y": 18,
      "z": -5,
      "name": "Wood_Drywood_Planks",
      "rotation": 1
    },
    {
      "x": 3,
      "y": 19,
      "z": -5,
      "name": "Rock_Sandstone_Brick",
      "rotation": 1
    },
    {
      "x": 3,
      "y": 20,
      "z": -5,
      "name": "Rock_Sandstone_Brick",
      "rotation": 1
    },
    {
      "x": 3,
      "y": 22,
      "z": -5,
      "name": "Plant_Coral_Block_Red"
    },
    {
      "x": 3,
      "y": 0,
      "z": -4,
      "name": "Rock_Sandstone_Brick"
    },
    {
      "x": 3,
      "y": 1,
      "z": -4,
      "name": "Rock_Sandstone_Cobble_Half"
    },
    {
      "x": 3,
      "y": 10,
      "z": -4,
      "name": "Rock_Sandstone_Cobble"
    },
    {
      "x": 3,
      "y": 15,
      "z": -4,
      "name": "Plant_Coral_Block_Red"
    },
    {
      "x": 3,
      "y": 16,
      "z": -4,
      "name": "Plant_Coral_Block_Red"
    },
    {
      "x": 3,
      "y": 18,
      "z": -4,
      "name": "Plant_Coral_Block_Red",
      "rotation": 3
    },
    {
      "x": 3,
      "y": 19,
      "z": -4,
      "name": "Furniture_Village_Bookcase"
    },
    {
      "x": 3,
      "y": 20,
      "z": -4,
      "name": "Furniture_Village_Bookcase"
    },
    {
      "x": 3,
      "y": 22,
      "z": -4,
      "name": "Plant_Coral_Block_Red"
    },
    {
      "x": 3,
      "y": 10,
      "z": -3,
      "name": "Rock_Sandstone_Cobble"
    },
    {
      "x": 3,
      "y": 15,
      "z": -3,
      "name": "Plant_Coral_Block_Red"
    },
    {
      "x": 3,
      "y": 16,
      "z": -3,
      "name": "Plant_Coral_Block_Red"
    },
    {
      "x": 3,
      "y": 18,
      "z": -3,
      "name": "Plant_Coral_Block_Red",
      "rotation": 3
    },
    {
      "x": 3,
      "y": 19,
      "z": -3,
      "name": "Plant_Coral_Block_Red",
      "rotation": 3
    },
    {
      "x": 3,
      "y": 20,
      "z": -3,
      "name": "Plant_Coral_Bush_Red",
      "rotation": 3
    },
    {
      "x": 3,
      "y": 14,
      "z": -2,
      "name": "Plant_Coral_Block_Red"
    },
    {
      "x": 3,
      "y": 15,
      "z": -2,
      "name": "Plant_Coral_Block_Red"
    },
    {
      "x": 3,
      "y": 19,
      "z": -2,
      "name": "Plant_Coral_Block_Red",
      "rotation": 3
    },
    {
      "x": 3,
      "y": 0,
      "z": -1,
      "name": "Soil_Sand"
    },
    {
      "x": 3,
      "y": 14,
      "z": -1,
      "name": "Plant_Coral_Block_Red"
    },
    {
      "x": 3,
      "y": 15,
      "z": -1,
      "name": "Plant_Coral_Block_Red"
    },
    {
      "x": 3,
      "y": 21,
      "z": -1,
      "name": "Plant_Coral_Block_Red",
      "rotation": 2
    },
    {
      "x": 3,
      "y": 0,
      "z": 0,
      "name": "Soil_Sand"
    },
    {
      "x": 3,
      "y": 14,
      "z": 0,
      "name": "Plant_Coral_Block_Red"
    },
    {
      "x": 3,
      "y": 15,
      "z": 0,
      "name": "Plant_Coral_Block_Red"
    },
    {
      "x": 3,
      "y": 21,
      "z": 0,
      "name": "Plant_Coral_Block_Red",
      "rotation": 2
    },
    {
      "x": 3,
      "y": 22,
      "z": 0,
      "name": "Plant_Coral_Bush_Red",
      "rotation": 2
    },
    {
      "x": 3,
      "y": 0,
      "z": 1,
      "name": "Rock_Sandstone_Brick"
    },
    {
      "x": 3,
      "y": 11,
      "z": 1,
      "name": "Plant_Coral_Block_Red"
    },
    {
      "x": 3,
      "y": 15,
      "z": 1,
      "name": "Plant_Coral_Block_Red"
    },
    {
      "x": 3,
      "y": 16,
      "z": 1,
      "name": "Plant_Coral_Block_Red"
    },
    {
      "x": 3,
      "y": 20,
      "z": 1,
      "name": "Plant_Coral_Block_Red",
      "rotation": 2
    },
    {
      "x": 3,
      "y": 21,
      "z": 1,
      "name": "Plant_Coral_Block_Red",
      "rotation": 2
    },
    {
      "x": 3,
      "y": 0,
      "z": 2,
      "name": "Rock_Sandstone_Brick"
    },
    {
      "x": 3,
      "y": 11,
      "z": 2,
      "name": "Plant_Coral_Block_Red"
    },
    {
      "x": 3,
      "y": 15,
      "z": 2,
      "name": "Plant_Coral_Block_Red"
    },
    {
      "x": 3,
      "y": 16,
      "z": 2,
      "name": "Plant_Coral_Block_Red"
    },
    {
      "x": 3,
      "y": 20,
      "z": 2,
      "name": "Plant_Coral_Block_Red",
      "rotation": 2
    },
    {
      "x": 3,
      "y": 21,
      "z": 2,
      "name": "Plant_Coral_Block_Red",
      "rotation": 2
    },
    {
      "x": 3,
      "y": 0,
      "z": 3,
      "name": "Rock_Sandstone_Brick"
    },
    {
      "x": 3,
      "y": 10,
      "z": 3,
      "name": "Plant_Coral_Block_Red"
    },
    {
      "x": 3,
      "y": 11,
      "z": 3,
      "name": "Plant_Coral_Block_Red"
    },
    {
      "x": 3,
      "y": 16,
      "z": 3,
      "name": "Plant_Coral_Block_Red"
    },
    {
      "x": 3,
      "y": 17,
      "z": 3,
      "name": "Plant_Coral_Block_Red",
      "rotation": 3
    },
    {
      "x": 3,
      "y": 20,
      "z": 3,
      "name": "Plant_Coral_Block_Red",
      "rotation": 2
    },
    {
      "x": 3,
      "y": 21,
      "z": 3,
      "name": "Plant_Coral_Block_Red",
      "rotation": 2
    },
    {
      "x": 3,
      "y": 7,
      "z": 4,
      "name": "Plant_Coral_Block_Red"
    },
    {
      "x": 3,
      "y": 8,
      "z": 4,
      "name": "Plant_Coral_Bush_Red"
    },
    {
      "x": 3,
      "y": 10,
      "z": 4,
      "name": "Rock_Sandstone_Cobble"
    },
    {
      "x": 3,
      "y": 11,
      "z": 4,
      "name": "Plant_Coral_Block_Red"
    },
    {
      "x": 3,
      "y": 17,
      "z": 4,
      "name": "Plant_Coral_Block_Red",
      "rotation": 3
    },
    {
      "x": 3,
      "y": 18,
      "z": 4,
      "name": "Plant_Coral_Bush_Red",
      "rotation": 3
    },
    {
      "x": 3,
      "y": 21,
      "z": 4,
      "name": "Plant_Coral_Block_Red",
      "rotation": 2
    },
    {
      "x": 3,
      "y": 0,
      "z": 5,
      "name": "Rock_Sandstone_Brick"
    },
    {
      "x": 3,
      "y": 6,
      "z": 5,
      "name": "Plant_Coral_Block_Red"
    },
    {
      "x": 3,
      "y": 7,
      "z": 5,
      "name": "Plant_Coral_Block_Red"
    },
    {
      "x": 3,
      "y": 10,
      "z": 5,
      "name": "Rock_Sandstone",
      "rotation": 3
    },
    {
      "x": 3,
      "y": 11,
      "z": 5,
      "name": "Plant_Coral_Block_Red"
    },
    {
      "x": 3,
      "y": 17,
      "z": 5,
      "name": "Plant_Coral_Block_Red",
      "rotation": 3
    },
    {
      "x": 3,
      "y": 20,
      "z": 5,
      "name": "Furniture_Village_Bookcase",
      "rotation": 2
    },
    {
      "x": 3,
      "y": 21,
      "z": 5,
      "name": "Plant_Coral_Block_Red",
      "rotation": 2
    },
    {
      "x": 3,
      "y": 0,
      "z": 6,
      "name": "Rock_Sandstone_Brick"
    },
    {
      "x": 3,
      "y": 6,
      "z": 6,
      "name": "Plant_Coral_Block_Red"
    },
    {
      "x": 3,
      "y": 7,
      "z": 6,
      "name": "Plant_Coral_Block_Red"
    },
    {
      "x": 3,
      "y": 9,
      "z": 6,
      "name": "Plant_Coral_Block_Red"
    },
    {
      "x": 3,
      "y": 10,
      "z": 6,
      "name": "Rock_Sandstone",
      "rotation": 3
    },
    {
      "x": 3,
      "y": 20,
      "z": 6,
      "name": "Rock_Sandstone_Brick",
      "rotation": 1
    },
    {
      "x": 3,
      "y": 0,
      "z": 7,
      "name": "Rock_Sandstone_Brick"
    },
    {
      "x": 3,
      "y": 1,
      "z": 7,
      "name": "Soil_Sand"
    },
    {
      "x": 3,
      "y": 3,
      "z": 7,
      "name": "Rock_Sandstone_Red_Brick_Half",
      "rotation": 6
    },
    {
      "x": 3,
      "y": 5,
      "z": 7,
      "name": "Plant_Coral_Block_Red"
    },
    {
      "x": 3,
      "y": 6,
      "z": 7,
      "name": "Plant_Coral_Block_Red"
    },
    {
      "x": 3,
      "y": 9,
      "z": 7,
      "name": "Rock_Sandstone_Red_Brick",
      "rotation": 3
    },
    {
      "x": 3,
      "y": 10,
      "z": 7,
      "name": "Rock_Sandstone",
      "rotation": 3
    },
    {
      "x": 3,
      "y": 11,
      "z": 7,
      "name": "Wood_Drywood_Planks"
    },
    {
      "x": 3,
      "y": 12,
      "z": 7,
      "name": "Plant_Coral_Block_Red",
      "rotation": 3
    },
    {
      "x": 3,
      "y": 20,
      "z": 7,
      "name": "Rock_Sandstone_Brick_Smooth",
      "rotation": 1
    },
    {
      "x": 3,
      "y": 0,
      "z": 8,
      "name": "Rock_Sandstone_Brick",
      "rotation": 3
    },
    {
      "x": 3,
      "y": 1,
      "z": 8,
      "name": "Rock_Sandstone_Brick",
      "rotation": 3
    },
    {
      "x": 3,
      "y": 2,
      "z": 8,
      "name": "Rock_Sandstone_Brick",
      "rotation": 3
    },
    {
      "x": 3,
      "y": 3,
      "z": 8,
      "name": "Rock_Sandstone_Brick",
      "rotation": 3
    },
    {
      "x": 3,
      "y": 4,
      "z": 8,
      "name": "Rock_Sandstone_Brick",
      "rotation": 3
    },
    {
      "x": 3,
      "y": 5,
      "z": 8,
      "name": "Rock_Sandstone_Cobble",
      "rotation": 3
    },
    {
      "x": 3,
      "y": 6,
      "z": 8,
      "name": "Rock_Sandstone_Cobble",
      "rotation": 3
    },
    {
      "x": 3,
      "y": 8,
      "z": 8,
      "name": "Rock_Sandstone_Cobble",
      "rotation": 3
    },
    {
      "x": 3,
      "y": 9,
      "z": 8,
      "name": "Rock_Sandstone_Cobble",
      "rotation": 3
    },
    {
      "x": 3,
      "y": 10,
      "z": 8,
      "name": "Rock_Sandstone_Brick",
      "rotation": 3
    },
    {
      "x": 3,
      "y": 11,
      "z": 8,
      "name": "Rock_Sandstone_Brick",
      "rotation": 3
    },
    {
      "x": 3,
      "y": 12,
      "z": 8,
      "name": "Plant_Coral_Block_Red",
      "rotation": 3
    },
    {
      "x": 3,
      "y": 0,
      "z": 9,
      "name": "Rock_Sandstone_Cobble",
      "rotation": 3
    },
    {
      "x": 3,
      "y": 1,
      "z": 9,
      "name": "Rock_Sandstone_Cobble",
      "rotation": 3
    },
    {
      "x": 3,
      "y": 2,
      "z": 9,
      "name": "Rock_Sandstone_Cobble",
      "rotation": 3
    },
    {
      "x": 3,
      "y": 3,
      "z": 9,
      "name": "Rock_Sandstone_Cobble",
      "rotation": 3
    },
    {
      "x": 3,
      "y": 4,
      "z": 9,
      "name": "Rock_Sandstone_Brick_Ornate",
      "rotation": 3
    },
    {
      "x": 3,
      "y": 5,
      "z": 9,
      "name": "Rock_Sandstone_Brick_Stairs"
    },
    {
      "x": 3,
      "y": 6,
      "z": 9,
      "name": "Plant_Coral_Block_Red"
    },
    {
      "x": 3,
      "y": 9,
      "z": 9,
      "name": "Rock_Sandstone_Brick_Stairs",
      "rotation": 32
    },
    {
      "x": 3,
      "y": 12,
      "z": 9,
      "name": "Plant_Coral_Block_Red",
      "rotation": 3
    },
    {
      "x": 3,
      "y": 13,
      "z": 9,
      "name": "Plant_Coral_Bush_Red",
      "rotation": 3
    },
    {
      "x": 3,
      "y": 0,
      "z": 10,
      "name": "Soil_Sand"
    },
    {
      "x": 3,
      "y": 1,
      "z": 10,
      "name": "Soil_Sand"
    },
    {
      "x": 3,
      "y": 3,
      "z": 10,
      "name": "Plant_Coral_Block_Red"
    },
    {
      "x": 3,
      "y": 6,
      "z": 10,
      "name": "Plant_Coral_Block_Red"
    },
    {
      "x": 3,
      "y": 7,
      "z": 10,
      "name": "Plant_Coral_Block_Red"
    },
    {
      "x": 3,
      "y": 0,
      "z": 11,
      "name": "Soil_Sand"
    },
    {
      "x": 3,
      "y": 3,
      "z": 11,
      "name": "Plant_Coral_Block_Red"
    },
    {
      "x": 3,
      "y": 6,
      "z": 11,
      "name": "Plant_Coral_Block_Red"
    },
    {
      "x": 3,
      "y": 7,
      "z": 11,
      "name": "Plant_Coral_Block_Red"
    },
    {
      "x": 3,
      "y": 7,
      "z": 12,
      "name": "Plant_Coral_Block_Red"
    },
    {
      "x": 4,
      "y": 0,
      "z": -10,
      "name": "Rock_Sandstone_Red_Cobble",
      "rotation": 3
    },
    {
      "x": 4,
      "y": 1,
      "z": -10,
      "name": "Rock_Sandstone_Red_Brick",
      "rotation": 3
    },
    {
      "x": 4,
      "y": 2,
      "z": -10,
      "name": "Rock_Sandstone_Red_Brick_Stairs",
      "rotation": 2
    },
    {
      "x": 4,
      "y": 4,
      "z": -10,
      "name": "Plant_Coral_Block_Red",
      "rotation": 2
    },
    {
      "x": 4,
      "y": 0,
      "z": -9,
      "name": "Rock_Sandstone_Red_Brick",
      "rotation": 3
    },
    {
      "x": 4,
      "y": 1,
      "z": -9,
      "name": "Rock_Sandstone_Red_Brick",
      "rotation": 3
    },
    {
      "x": 4,
      "y": 2,
      "z": -9,
      "name": "Rock_Sandstone_Red_Brick",
      "rotation": 3
    },
    {
      "x": 4,
      "y": 3,
      "z": -9,
      "name": "Rock_Sandstone_Red_Brick_Stairs",
      "rotation": 2
    },
    {
      "x": 4,
      "y": 4,
      "z": -9,
      "name": "Plant_Coral_Block_Red",
      "rotation": 2
    },
    {
      "x": 4,
      "y": 6,
      "z": -9,
      "name": "Plant_Coral_Block_Red"
    },
    {
      "x": 4,
      "y": 7,
      "z": -9,
      "name": "Plant_Coral_Bush_Red"
    },
    {
      "x": 4,
      "y": 11,
      "z": -9,
      "name": "Plant_Coral_Block_Red"
    },
    {
      "x": 4,
      "y": 12,
      "z": -9,
      "name": "Plant_Coral_Bush_Red"
    },
    {
      "x": 4,
      "y": 0,
      "z": -8,
      "name": "Rock_Sandstone_Brick",
      "rotation": 3
    },
    {
      "x": 4,
      "y": 1,
      "z": -8,
      "name": "Rock_Sandstone_Brick",
      "rotation": 3
    },
    {
      "x": 4,
      "y": 2,
      "z": -8,
      "name": "Rock_Sandstone_Brick",
      "rotation": 3
    },
    {
      "x": 4,
      "y": 3,
      "z": -8,
      "name": "Rock_Sandstone_Brick",
      "rotation": 3
    },
    {
      "x": 4,
      "y": 4,
      "z": -8,
      "name": "Rock_Sandstone_Brick_Ornate",
      "rotation": 3
    },
    {
      "x": 4,
      "y": 5,
      "z": -8,
      "name": "Rock_Sandstone_Brick_Stairs",
      "rotation": 2
    },
    {
      "x": 4,
      "y": 6,
      "z": -8,
      "name": "Plant_Coral_Block_Red"
    },
    {
      "x": 4,
      "y": 11,
      "z": -8,
      "name": "Plant_Coral_Block_Red"
    },
    {
      "x": 4,
      "y": 22,
      "z": -8,
      "name": "Plant_Coral_Block_Red"
    },
    {
      "x": 4,
      "y": 23,
      "z": -8,
      "name": "Plant_Coral_Bush_Red"
    },
    {
      "x": 4,
      "y": 0,
      "z": -7,
      "name": "Rock_Sandstone_Brick",
      "rotation": 3
    },
    {
      "x": 4,
      "y": 1,
      "z": -7,
      "name": "Rock_Sandstone_Brick",
      "rotation": 3
    },
    {
      "x": 4,
      "y": 2,
      "z": -7,
      "name": "Rock_Sandstone_Brick",
      "rotation": 3
    },
    {
      "x": 4,
      "y": 3,
      "z": -7,
      "name": "Rock_Sandstone_Brick",
      "rotation": 3
    },
    {
      "x": 4,
      "y": 4,
      "z": -7,
      "name": "Rock_Sandstone_Brick",
      "rotation": 3
    },
    {
      "x": 4,
      "y": 5,
      "z": -7,
      "name": "Rock_Sandstone_Cobble",
      "rotation": 3
    },
    {
      "x": 4,
      "y": 6,
      "z": -7,
      "name": "Plant_Coral_Block_Red"
    },
    {
      "x": 4,
      "y": 9,
      "z": -7,
      "name": "Rock_Sandstone_Cobble",
      "rotation": 3
    },
    {
      "x": 4,
      "y": 10,
      "z": -7,
      "name": "Rock_Sandstone_Brick",
      "rotation": 3
    },
    {
      "x": 4,
      "y": 11,
      "z": -7,
      "name": "Rock_Sandstone_Brick",
      "rotation": 3
    },
    {
      "x": 4,
      "y": 12,
      "z": -7,
      "name": "Plant_Coral_Bush_Red"
    },
    {
      "x": 4,
      "y": 13,
      "z": -7,
      "name": "Plant_Coral_Block_Red"
    },
    {
      "x": 4,
      "y": 19,
      "z": -7,
      "name": "Plant_Coral_Block_Red",
      "rotation": 3
    },
    {
      "x": 4,
      "y": 21,
      "z": -7,
      "name": "Plant_Coral_Block_Red"
    },
    {
      "x": 4,
      "y": 22,
      "z": -7,
      "name": "Plant_Coral_Block_Red"
    },
    {
      "x": 4,
      "y": 0,
      "z": -6,
      "name": "Rock_Sandstone_Brick"
    },
    {
      "x": 4,
      "y": 1,
      "z": -6,
      "name": "Soil_Sand"
    },
    {
      "x": 4,
      "y": 3,
      "z": -6,
      "name": "Rock_Sandstone_Red_Brick_Half",
      "rotation": 4
    },
    {
      "x": 4,
      "y": 8,
      "z": -6,
      "name": "Rock_Sandstone_Red_Cobble",
      "rotation": 3
    },
    {
      "x": 4,
      "y": 9,
      "z": -6,
      "name": "Rock_Sandstone_Red_Cobble",
      "rotation": 3
    },
    {
      "x": 4,
      "y": 10,
      "z": -6,
      "name": "Rock_Sandstone",
      "rotation": 3
    },
    {
      "x": 4,
      "y": 11,
      "z": -6,
      "name": "Rock_Sandstone_Brick",
      "rotation": 1
    },
    {
      "x": 4,
      "y": 12,
      "z": -6,
      "name": "Rock_Sandstone_Brick_Smooth_Half",
      "rotation": 5
    },
    {
      "x": 4,
      "y": 13,
      "z": -6,
      "name": "Rock_Sandstone_Brick_Half",
      "rotation": 5
    },
    {
      "x": 4,
      "y": 14,
      "z": -6,
      "name": "Rock_Sandstone_Brick_Half",
      "rotation": 5
    },
    {
      "x": 4,
      "y": 15,
      "z": -6,
      "name": "Rock_Sandstone_Brick_Half",
      "rotation": 5
    },
    {
      "x": 4,
      "y": 16,
      "z": -6,
      "name": "Rock_Sandstone_Brick_Half",
      "rotation": 5
    },
    {
      "x": 4,
      "y": 17,
      "z": -6,
      "name": "Rock_Sandstone_Brick_Smooth_Half",
      "rotation": 5
    },
    {
      "x": 4,
      "y": 19,
      "z": -6,
      "name": "Rock_Gold_Brick_Smooth_Half",
      "rotation": 6
    },
    {
      "x": 4,
      "y": 20,
      "z": -6,
      "name": "Rock_Sandstone_Brick",
      "rotation": 1
    },
    {
      "x": 4,
      "y": 21,
      "z": -6,
      "name": "Rock_Sandstone_Brick",
      "rotation": 1
    },
    {
      "x": 4,
      "y": 22,
      "z": -6,
      "name": "Rock_Sandstone_Brick_Beam",
      "rotation": 1
    },
    {
      "x": 4,
      "y": 23,
      "z": -6,
      "name": "Rock_Sandstone_Brick_Beam",
      "rotation": 1
    },
    {
      "x": 4,
      "y": 0,
      "z": -5,
      "name": "Rock_Sandstone_Brick"
    },
    {
      "x": 4,
      "y": 10,
      "z": -5,
      "name": "Rock_Sandstone",
      "rotation": 3
    },
    {
      "x": 4,
      "y": 11,
      "z": -5,
      "name": "Wood_Drywood_Planks",
      "rotation": 1
    },
    {
      "x": 4,
      "y": 12,
      "z": -5,
      "name": "Rock_Sandstone_Brick",
      "rotation": 1
    },
    {
      "x": 4,
      "y": 13,
      "z": -5,
      "name": "Wood_Drywood_Planks",
      "rotation": 1
    },
    {
      "x": 4,
      "y": 14,
      "z": -5,
      "name": "Wood_Drywood_Planks",
      "rotation": 1
    },
    {
      "x": 4,
      "y": 15,
      "z": -5,
      "name": "Wood_Drywood_Planks",
      "rotation": 1
    },
    {
      "x": 4,
      "y": 16,
      "z": -5,
      "name": "Wood_Drywood_Planks",
      "rotation": 1
    },
    {
      "x": 4,
      "y": 17,
      "z": -5,
      "name": "Wood_Drywood_Planks",
      "rotation": 1
    },
    {
      "x": 4,
      "y": 18,
      "z": -5,
      "name": "Wood_Drywood_Planks",
      "rotation": 1
    },
    {
      "x": 4,
      "y": 19,
      "z": -5,
      "name": "Rock_Sandstone_Brick",
      "rotation": 1
    },
    {
      "x": 4,
      "y": 20,
      "z": -5,
      "name": "Rock_Sandstone_Brick",
      "rotation": 1
    },
    {
      "x": 4,
      "y": 21,
      "z": -5,
      "name": "Plant_Coral_Block_Red"
    },
    {
      "x": 4,
      "y": 22,
      "z": -5,
      "name": "Plant_Coral_Block_Red"
    },
    {
      "x": 4,
      "y": 0,
      "z": -4,
      "name": "Rock_Sandstone_Brick"
    },
    {
      "x": 4,
      "y": 10,
      "z": -4,
      "name": "Rock_Sandstone",
      "rotation": 3
    },
    {
      "x": 4,
      "y": 15,
      "z": -4,
      "name": "Plant_Coral_Block_Red"
    },
    {
      "x": 4,
      "y": 16,
      "z": -4,
      "name": "Wood_Drywood_Planks_Half",
      "rotation": 8
    },
    {
      "x": 4,
      "y": 17,
      "z": -4,
      "name": "Plant_Coral_Bush_Red"
    },
    {
      "x": 4,
      "y": 18,
      "z": -4,
      "name": "Plant_Coral_Block_Red",
      "rotation": 3
    },
    {
      "x": 4,
      "y": 19,
      "z": -4,
      "name": "Furniture_Village_Bookcase"
    },
    {
      "x": 4,
      "y": 20,
      "z": -4,
      "name": "Furniture_Village_Bookcase"
    },
    {
      "x": 4,
      "y": 22,
      "z": -4,
      "name": "Plant_Coral_Block_Red"
    },
    {
      "x": 4,
      "y": 23,
      "z": -4,
      "name": "Plant_Coral_Bush_Red"
    },
    {
      "x": 4,
      "y": 0,
      "z": -3,
      "name": "Rock_Sandstone_Brick"
    },
    {
      "x": 4,
      "y": 10,
      "z": -3,
      "name": "Rock_Sandstone_Cobble"
    },
    {
      "x": 4,
      "y": 14,
      "z": -3,
      "name": "Plant_Coral_Block_Red"
    },
    {
      "x": 4,
      "y": 15,
      "z": -3,
      "name": "Plant_Coral_Block_Red"
    },
    {
      "x": 4,
      "y": 16,
      "z": -3,
      "name": "Wood_Drywood_Planks_Half",
      "rotation": 8
    },
    {
      "x": 4,
      "y": 18,
      "z": -3,
      "name": "Plant_Coral_Block_Red",
      "rotation": 3
    },
    {
      "x": 4,
      "y": 19,
      "z": -3,
      "name": "Plant_Coral_Block_Red",
      "rotation": 3
    },
    {
      "x": 4,
      "y": 0,
      "z": -2,
      "name": "Rock_Sandstone_Brick"
    },
    {
      "x": 4,
      "y": 10,
      "z": -2,
      "name": "Rock_Sandstone_Cobble"
    },
    {
      "x": 4,
      "y": 14,
      "z": -2,
      "name": "Plant_Coral_Block_Red"
    },
    {
      "x": 4,
      "y": 15,
      "z": -2,
      "name": "Plant_Coral_Block_Red"
    },
    {
      "x": 4,
      "y": 16,
      "z": -2,
      "name": "Plant_Coral_Bush_Red"
    },
    {
      "x": 4,
      "y": 19,
      "z": -2,
      "name": "Plant_Coral_Block_Red",
      "rotation": 3
    },
    {
      "x": 4,
      "y": 20,
      "z": -2,
      "name": "Plant_Coral_Bush_Red",
      "rotation": 3
    },
    {
      "x": 4,
      "y": 21,
      "z": -2,
      "name": "Plant_Coral_Block_Red",
      "rotation": 2
    },
    {
      "x": 4,
      "y": 22,
      "z": -2,
      "name": "Plant_Coral_Bush_Red",
      "rotation": 2
    },
    {
      "x": 4,
      "y": 0,
      "z": -1,
      "name": "Soil_Sand"
    },
    {
      "x": 4,
      "y": 1,
      "z": -1,
      "name": "Rubble_Sandstone",
      "support": 15
    },
    {
      "x": 4,
      "y": 14,
      "z": -1,
      "name": "Plant_Coral_Block_Red"
    },
    {
      "x": 4,
      "y": 15,
      "z": -1,
      "name": "Plant_Coral_Block_Red"
    },
    {
      "x": 4,
      "y": 21,
      "z": -1,
      "name": "Plant_Coral_Block_Red",
      "rotation": 2
    },
    {
      "x": 4,
      "y": 0,
      "z": 0,
      "name": "Rock_Sandstone_Brick"
    },
    {
      "x": 4,
      "y": 14,
      "z": 0,
      "name": "Plant_Coral_Block_Red"
    },
    {
      "x": 4,
      "y": 15,
      "z": 0,
      "name": "Plant_Coral_Block_Red"
    },
    {
      "x": 4,
      "y": 16,
      "z": 0,
      "name": "Plant_Coral_Bush_Red"
    },
    {
      "x": 4,
      "y": 20,
      "z": 0,
      "name": "Plant_Coral_Block_Red",
      "rotation": 2
    },
    {
      "x": 4,
      "y": 21,
      "z": 0,
      "name": "Plant_Coral_Block_Red",
      "rotation": 2
    },
    {
      "x": 4,
      "y": 0,
      "z": 1,
      "name": "Rock_Sandstone_Brick"
    },
    {
      "x": 4,
      "y": 11,
      "z": 1,
      "name": "Plant_Coral_Block_Red"
    },
    {
      "x": 4,
      "y": 12,
      "z": 1,
      "name": "Plant_Coral_Bush_Red"
    },
    {
      "x": 4,
      "y": 14,
      "z": 1,
      "name": "Plant_Coral_Block_Red"
    },
    {
      "x": 4,
      "y": 15,
      "z": 1,
      "name": "Plant_Coral_Block_Red"
    },
    {
      "x": 4,
      "y": 20,
      "z": 1,
      "name": "Plant_Coral_Block_Red",
      "rotation": 2
    },
    {
      "x": 4,
      "y": 21,
      "z": 1,
      "name": "Plant_Coral_Block_Red",
      "rotation": 2
    },
    {
      "x": 4,
      "y": 0,
      "z": 2,
      "name": "Rock_Sandstone_Brick"
    },
    {
      "x": 4,
      "y": 10,
      "z": 2,
      "name": "Rock_Sandstone_Cobble_Half",
      "rotation": 33
    },
    {
      "x": 4,
      "y": 11,
      "z": 2,
      "name": "Plant_Coral_Block_Red"
    },
    {
      "x": 4,
      "y": 15,
      "z": 2,
      "name": "Plant_Coral_Block_Red"
    },
    {
      "x": 4,
      "y": 16,
      "z": 2,
      "name": "Plant_Coral_Block_Red"
    },
    {
      "x": 4,
      "y": 20,
      "z": 2,
      "name": "Plant_Coral_Block_Red",
      "rotation": 2
    },
    {
      "x": 4,
      "y": 21,
      "z": 2,
      "name": "Plant_Coral_Block_Red",
      "rotation": 2
    },
    {
      "x": 4,
      "y": 22,
      "z": 2,
      "name": "Plant_Coral_Bush_Red",
      "rotation": 2
    },
    {
      "x": 4,
      "y": 10,
      "z": 3,
      "name": "Rock_Sandstone_Cobble_Half",
      "rotation": 33
    },
    {
      "x": 4,
      "y": 11,
      "z": 3,
      "name": "Plant_Coral_Block_Red"
    },
    {
      "x": 4,
      "y": 12,
      "z": 3,
      "name": "Plant_Coral_Bush_Red"
    },
    {
      "x": 4,
      "y": 15,
      "z": 3,
      "name": "Plant_Coral_Block_Red"
    },
    {
      "x": 4,
      "y": 16,
      "z": 3,
      "name": "Plant_Coral_Block_Red"
    },
    {
      "x": 4,
      "y": 17,
      "z": 3,
      "name": "Plant_Coral_Bush_Red"
    },
    {
      "x": 4,
      "y": 18,
      "z": 3,
      "name": "Plant_Coral_Bush_Red",
      "rotation": 3
    },
    {
      "x": 4,
      "y": 20,
      "z": 3,
      "name": "Plant_Coral_Block_Red",
      "rotation": 2
    },
    {
      "x": 4,
      "y": 21,
      "z": 3,
      "name": "Plant_Coral_Block_Red",
      "rotation": 2
    },
    {
      "x": 4,
      "y": 0,
      "z": 4,
      "name": "Rock_Sandstone_Brick"
    },
    {
      "x": 4,
      "y": 7,
      "z": 4,
      "name": "Plant_Coral_Block_Red"
    },
    {
      "x": 4,
      "y": 10,
      "z": 4,
      "name": "Rock_Sandstone_Cobble_Half",
      "rotation": 7
    },
    {
      "x": 4,
      "y": 11,
      "z": 4,
      "name": "Plant_Coral_Block_Red"
    },
    {
      "x": 4,
      "y": 16,
      "z": 4,
      "name": "Plant_Coral_Block_Red"
    },
    {
      "x": 4,
      "y": 17,
      "z": 4,
      "name": "Plant_Coral_Block_Red",
      "rotation": 3
    },
    {
      "x": 4,
      "y": 18,
      "z": 4,
      "name": "Plant_Coral_Bush_Red",
      "rotation": 3
    },
    {
      "x": 4,
      "y": 20,
      "z": 4,
      "name": "Plant_Coral_Block_Red",
      "rotation": 2
    },
    {
      "x": 4,
      "y": 21,
      "z": 4,
      "name": "Plant_Coral_Block_Red",
      "rotation": 2
    },
    {
      "x": 4,
      "y": 22,
      "z": 4,
      "name": "Plant_Coral_Bush_Red",
      "rotation": 2
    },
    {
      "x": 4,
      "y": 0,
      "z": 5,
      "name": "Rock_Sandstone_Brick"
    },
    {
      "x": 4,
      "y": 7,
      "z": 5,
      "name": "Plant_Coral_Block_Red"
    },
    {
      "x": 4,
      "y": 10,
      "z": 5,
      "name": "Rock_Sandstone",
      "rotation": 3
    },
    {
      "x": 4,
      "y": 11,
      "z": 5,
      "name": "Plant_Coral_Block_Red"
    },
    {
      "x": 4,
      "y": 12,
      "z": 5,
      "name": "Plant_Coral_Bush_Red"
    },
    {
      "x": 4,
      "y": 16,
      "z": 5,
      "name": "Wood_Drywood_Planks_Half",
      "rotation": 35
    },
    {
      "x": 4,
      "y": 17,
      "z": 5,
      "name": "Plant_Coral_Block_Red",
      "rotation": 3
    },
    {
      "x": 4,
      "y": 19,
      "z": 5,
      "name": "Furniture_Village_Bookcase",
      "rotation": 2
    },
    {
      "x": 4,
      "y": 20,
      "z": 5,
      "name": "Furniture_Village_Bookcase",
      "rotation": 2
    },
    {
      "x": 4,
      "y": 21,
      "z": 5,
      "name": "Plant_Coral_Block_Red",
      "rotation": 2
    },
    {
      "x": 4,
      "y": 0,
      "z": 6,
      "name": "Rock_Sandstone_Brick"
    },
    {
      "x": 4,
      "y": 6,
      "z": 6,
      "name": "Plant_Coral_Block_Red"
    },
    {
      "x": 4,
      "y": 7,
      "z": 6,
      "name": "Plant_Coral_Block_Red"
    },
    {
      "x": 4,
      "y": 8,
      "z": 6,
      "name": "Plant_Coral_Bush_Red"
    },
    {
      "x": 4,
      "y": 9,
      "z": 6,
      "name": "Rock_Sandstone_Cobble_Half",
      "rotation": 33
    },
    {
      "x": 4,
      "y": 10,
      "z": 6,
      "name": "Rock_Sandstone",
      "rotation": 3
    },
    {
      "x": 4,
      "y": 16,
      "z": 6,
      "name": "Wood_Drywood_Planks_Half",
      "rotation": 35
    },
    {
      "x": 4,
      "y": 17,
      "z": 6,
      "name": "Wood_Dry_Branch_Long",
      "rotation": 1
    },
    {
      "x": 4,
      "y": 18,
      "z": 6,
      "name": "Wood_Dry_Branch_Long",
      "rotation": 1
    },
    {
      "x": 4,
      "y": 19,
      "z": 6,
      "name": "Rock_Sandstone_Brick",
      "rotation": 1
    },
    {
      "x": 4,
      "y": 20,
      "z": 6,
      "name": "Rock_Sandstone_Brick",
      "rotation": 1
    },
    {
      "x": 4,
      "y": 21,
      "z": 6,
      "name": "Plant_Coral_Block_Red",
      "rotation": 2
    },
    {
      "x": 4,
      "y": 0,
      "z": 7,
      "name": "Rock_Sandstone_Brick"
    },
    {
      "x": 4,
      "y": 1,
      "z": 7,
      "name": "Soil_Sand"
    },
    {
      "x": 4,
      "y": 3,
      "z": 7,
      "name": "Rock_Sandstone_Red_Brick_Half",
      "rotation": 6
    },
    {
      "x": 4,
      "y": 6,
      "z": 7,
      "name": "Plant_Coral_Block_Red"
    },
    {
      "x": 4,
      "y": 7,
      "z": 7,
      "name": "Plant_Coral_Block_Red"
    },
    {
      "x": 4,
      "y": 9,
      "z": 7,
      "name": "Rock_Sandstone_Red_Brick",
      "rotation": 3
    },
    {
      "x": 4,
      "y": 10,
      "z": 7,
      "name": "Rock_Sandstone",
      "rotation": 3
    },
    {
      "x": 4,
      "y": 11,
      "z": 7,
      "name": "Wood_Drywood_Planks",
      "rotation": 1
    },
    {
      "x": 4,
      "y": 20,
      "z": 7,
      "name": "Rock_Sandstone_Brick",
      "rotation": 1
    },
    {
      "x": 4,
      "y": 21,
      "z": 7,
      "name": "Rock_Sandstone_Brick",
      "rotation": 1
    },
    {
      "x": 4,
      "y": 22,
      "z": 7,
      "name": "Rock_Sandstone_Brick_Beam",
      "rotation": 1
    },
    {
      "x": 4,
      "y": 23,
      "z": 7,
      "name": "Rock_Sandstone_Brick_Beam",
      "rotation": 1
    },
    {
      "x": 4,
      "y": 0,
      "z": 8,
      "name": "Rock_Sandstone_Brick",
      "rotation": 3
    },
    {
      "x": 4,
      "y": 1,
      "z": 8,
      "name": "Rock_Sandstone_Brick",
      "rotation": 3
    },
    {
      "x": 4,
      "y": 2,
      "z": 8,
      "name": "Rock_Sandstone_Brick",
      "rotation": 3
    },
    {
      "x": 4,
      "y": 3,
      "z": 8,
      "name": "Rock_Sandstone_Brick",
      "rotation": 3
    },
    {
      "x": 4,
      "y": 4,
      "z": 8,
      "name": "Rock_Sandstone_Brick",
      "rotation": 3
    },
    {
      "x": 4,
      "y": 5,
      "z": 8,
      "name": "Rock_Sandstone_Cobble",
      "rotation": 3
    },
    {
      "x": 4,
      "y": 6,
      "z": 8,
      "name": "Plant_Coral_Block_Red"
    },
    {
      "x": 4,
      "y": 7,
      "z": 8,
      "name": "Plant_Coral_Block_Red"
    },
    {
      "x": 4,
      "y": 8,
      "z": 8,
      "name": "Rock_Sandstone_Cobble",
      "rotation": 3
    },
    {
      "x": 4,
      "y": 9,
      "z": 8,
      "name": "Rock_Sandstone_Cobble",
      "rotation": 3
    },
    {
      "x": 4,
      "y": 10,
      "z": 8,
      "name": "Rock_Sandstone_Brick",
      "rotation": 3
    },
    {
      "x": 4,
      "y": 11,
      "z": 8,
      "name": "Rock_Sandstone_Brick",
      "rotation": 1
    },
    {
      "x": 4,
      "y": 0,
      "z": 9,
      "name": "Rock_Sandstone_Brick",
      "rotation": 3
    },
    {
      "x": 4,
      "y": 1,
      "z": 9,
      "name": "Rock_Sandstone_Brick",
      "rotation": 3
    },
    {
      "x": 4,
      "y": 2,
      "z": 9,
      "name": "Rock_Sandstone_Brick",
      "rotation": 3
    },
    {
      "x": 4,
      "y": 3,
      "z": 9,
      "name": "Rock_Sandstone_Brick",
      "rotation": 3
    },
    {
      "x": 4,
      "y": 4,
      "z": 9,
      "name": "Rock_Sandstone_Brick_Ornate",
      "rotation": 3
    },
    {
      "x": 4,
      "y": 5,
      "z": 9,
      "name": "Rock_Sandstone_Brick_Stairs"
    },
    {
      "x": 4,
      "y": 6,
      "z": 9,
      "name": "Plant_Coral_Block_Red"
    },
    {
      "x": 4,
      "y": 7,
      "z": 9,
      "name": "Plant_Coral_Block_Red"
    },
    {
      "x": 4,
      "y": 9,
      "z": 9,
      "name": "Rock_Sandstone_Brick_Stairs",
      "rotation": 32
    },
    {
      "x": 4,
      "y": 10,
      "z": 9,
      "name": "Rock_Sandstone_Brick",
      "rotation": 3
    },
    {
      "x": 4,
      "y": 11,
      "z": 9,
      "name": "Rock_Sandstone_Brick",
      "rotation": 3
    },
    {
      "x": 4,
      "y": 12,
      "z": 9,
      "name": "Plant_Coral_Bush_Red",
      "rotation": 3
    },
    {
      "x": 4,
      "y": 0,
      "z": 10,
      "name": "Rock_Sandstone_Red_Brick",
      "rotation": 3
    },
    {
      "x": 4,
      "y": 1,
      "z": 10,
      "name": "Rock_Sandstone_Red_Brick",
      "rotation": 3
    },
    {
      "x": 4,
      "y": 2,
      "z": 10,
      "name": "Rock_Sandstone_Red_Brick",
      "rotation": 3
    },
    {
      "x": 4,
      "y": 3,
      "z": 10,
      "name": "Rock_Sandstone_Red_Brick_Stairs"
    },
    {
      "x": 4,
      "y": 6,
      "z": 10,
      "name": "Plant_Coral_Block_Red"
    },
    {
      "x": 4,
      "y": 7,
      "z": 10,
      "name": "Plant_Coral_Block_Red"
    },
    {
      "x": 4,
      "y": 11,
      "z": 10,
      "name": "Plant_Coral_Block_Red",
      "rotation": 3
    },
    {
      "x": 4,
      "y": 0,
      "z": 11,
      "name": "Rock_Sandstone_Red_Brick",
      "rotation": 3
    },
    {
      "x": 4,
      "y": 1,
      "z": 11,
      "name": "Rock_Sandstone_Red_Brick",
      "rotation": 3
    },
    {
      "x": 4,
      "y": 2,
      "z": 11,
      "name": "Rock_Sandstone_Red_Brick_Stairs"
    },
    {
      "x": 4,
      "y": 7,
      "z": 11,
      "name": "Plant_Coral_Block_Red"
    },
    {
      "x": 4,
      "y": 7,
      "z": 12,
      "name": "Plant_Coral_Block_Red"
    },
    {
      "x": 4,
      "y": 8,
      "z": 12,
      "name": "Plant_Coral_Bush_Red"
    },
    {
      "x": 5,
      "y": 0,
      "z": -10,
      "name": "Rock_Sandstone_Red_Brick",
      "rotation": 3
    },
    {
      "x": 5,
      "y": 1,
      "z": -10,
      "name": "Rock_Sandstone_Red_Brick",
      "rotation": 3
    },
    {
      "x": 5,
      "y": 2,
      "z": -10,
      "name": "Rock_Sandstone_Red_Brick_Stairs",
      "rotation": 2
    },
    {
      "x": 5,
      "y": 4,
      "z": -10,
      "name": "Plant_Coral_Block_Red",
      "rotation": 2
    },
    {
      "x": 5,
      "y": 5,
      "z": -10,
      "name": "Plant_Coral_Bush_Red",
      "rotation": 2
    },
    {
      "x": 5,
      "y": 11,
      "z": -10,
      "name": "Plant_Coral_Block_Red"
    },
    {
      "x": 5,
      "y": 0,
      "z": -9,
      "name": "Rock_Sandstone_Red_Brick",
      "rotation": 3
    },
    {
      "x": 5,
      "y": 1,
      "z": -9,
      "name": "Rock_Sandstone_Red_Brick",
      "rotation": 3
    },
    {
      "x": 5,
      "y": 2,
      "z": -9,
      "name": "Rock_Sandstone_Red_Brick",
      "rotation": 3
    },
    {
      "x": 5,
      "y": 3,
      "z": -9,
      "name": "Rock_Sandstone_Red_Brick_Stairs",
      "rotation": 2
    },
    {
      "x": 5,
      "y": 4,
      "z": -9,
      "name": "Plant_Coral_Block_Red",
      "rotation": 2
    },
    {
      "x": 5,
      "y": 5,
      "z": -9,
      "name": "Plant_Coral_Bush_Red",
      "rotation": 2
    },
    {
      "x": 5,
      "y": 11,
      "z": -9,
