{
  "version": 8,
  "blockIdVersion": 11,
  "anchorX": 0,
  "anchorY": 0,
  "anchorZ": 0,
  "blocks": [
    {
      "x": -4,
      "y": 1,
      "z": -2,
      "name": "Rock_Sandstone_Brick_Half",
      "rotation": 6
    },
    {
      "x": -4,
      "y": 2,
      "z": -2,
      "name": "Rock_Sandstone_Brick_Half",
      "rotation": 6
    },
    {
      "x": -4,
      "y": 3,
      "z": -2,
      "name": "Rock_Sandstone_Brick"
    },
    {
      "x": -4,
      "y": 4,
      "z": -2,
      "name": "Rock_Sandstone_Brick"
    },
    {
      "x": -4,
      "y": 5,
      "z": -2,
      "name": "Rock_Sandstone_Brick"
    },
    {
      "x": -4,
      "y": 0,
      "z": -1,
      "name": "Rock_Sandstone_Brick"
    },
    {
      "x": -4,
      "y": 1,
      "z": -1,
      "name": "Rock_Sandstone_White_Brick"
    },
    {
      "x": -4,
      "y": 2,
      "z": -1,
      "name": "Rock_Sandstone_White_Brick"
    },
    {
      "x": -4,
      "y": 3,
      "z": -1,
      "name": "Rock_Sandstone_White_Brick"
    },
    {
      "x": -4,
      "y": 4,
      "z": -1,
      "name": "Rock_Sandstone_White_Brick"
    },
    {
      "x": -4,
      "y": 0,
      "z": 0,
      "name": "Rock_Sandstone_Brick"
    },
    {
      "x": -4,
      "y": 1,
      "z": 0,
      "name": "Rock_Sandstone_White_Brick"
    },
    {
      "x": -4,
      "y": 2,
      "z": 0,
      "name": "Furniture_Desert_Window",
      "rotation": 1
    },
    {
      "x": -4,
      "y": 0,
      "z": 1,
      "name": "Rock_Sandstone_Brick"
    },
    {
      "x": -4,
      "y": 1,
      "z": 1,
      "name": "Rock_Sandstone_White_Brick"
    },
    {
      "x": -4,
      "y": 2,
      "z": 1,
      "name": "Furniture_Desert_Window",
      "rotation": 1
    },
    {
      "x": -4,
      "y": 3,
      "z": 1,
      "name": "Furniture_Desert_Window",
      "rotation": 1
    },
    {
      "x": -4,
      "y": 4,
      "z": 1,
      "name": "Wood_Dry_Trunk",
      "support": 15,
      "rotation": 4
    },
    {
      "x": -4,
      "y": 0,
      "z": 2,
      "name": "Rock_Sandstone_Brick"
    },
    {
      "x": -4,
      "y": 1,
      "z": 2,
      "name": "Rock_Sandstone_White_Brick"
    },
    {
      "x": -4,
      "y": 2,
      "z": 2,
      "name": "Furniture_Desert_Window",
      "rotation": 1
    },
    {
      "x": -4,
      "y": 3,
      "z": 2,
      "name": "Furniture_Desert_Window",
      "rotation": 1
    },
    {
      "x": -4,
      "y": 4,
      "z": 2,
      "name": "Wood_Dry_Trunk",
      "support": 15,
      "rotation": 4
    },
    {
      "x": -4,
      "y": 5,
      "z": 2,
      "name": "Rock_Sandstone_White_Brick"
    },
    {
      "x": -4,
      "y": 0,
      "z": 3,
      "name": "Rock_Sandstone_Brick"
    },
    {
      "x": -4,
      "y": 1,
      "z": 3,
      "name": "Rock_Sandstone_White_Brick"
    },
    {
      "x": -4,
      "y": 2,
      "z": 3,
      "name": "Rock_Sandstone_White_Brick"
    },
    {
      "x": -4,
      "y": 3,
      "z": 3,
      "name": "Rock_Sandstone_White_Brick"
    },
    {
      "x": -4,
      "y": 4,
      "z": 3,
      "name": "Rock_Sandstone_White_Brick"
    },
    {
      "x": -4,
      "y": 5,
      "z": 3,
      "name": "Rock_Sandstone_White_Brick"
    },
    {
      "x": -4,
      "y": 6,
      "z": 3,
      "name": "Rock_Sandstone_Brick_Ornate"
    },
    {
      "x": -4,
      "y": 0,
      "z": 4,
      "name": "Rock_Sandstone_Brick"
    },
    {
      "x": -4,
      "y": 1,
      "z": 4,
      "name": "Rock_Sandstone_Brick"
    },
    {
      "x": -4,
      "y": 2,
      "z": 4,
      "name": "Rock_Sandstone_Brick"
    },
    {
      "x": -4,
      "y": 3,
      "z": 4,
      "name": "Rock_Sandstone_Brick"
    },
    {
      "x": -4,
      "y": 4,
      "z": 4,
      "name": "Rock_Sandstone_Brick"
    },
    {
      "x": -4,
      "y": 5,
      "z": 4,
      "name": "Rock_Sandstone_Brick"
    },
    {
      "x": -3,
      "y": 0,
      "z": -4,
      "name": "Rock_Sandstone_Brick"
    },
    {
      "x": -3,
      "y": 1,
      "z": -4,
      "name": "Rock_Sandstone_Brick"
    },
    {
      "x": -3,
      "y": 2,
      "z": -4,
      "name": "Rock_Sandstone_White_Cobble"
    },
    {
      "x": -3,
      "y": 0,
      "z": -3,
      "name": "Rock_Sandstone_Brick"
    },
    {
      "x": -3,
      "y": 1,
      "z": -3,
      "name": "Rock_Sandstone_Brick"
    },
    {
      "x": -3,
      "y": 2,
      "z": -3,
      "name": "Rock_Sandstone_White_Cobble"
    },
    {
      "x": -3,
      "y": 3,
      "z": -3,
      "name": "Rock_Sandstone_White_Cobble"
    },
    {
      "x": -3,
      "y": 0,
      "z": -2,
      "name": "Rock_Sandstone_Brick"
    },
    {
      "x": -3,
      "y": 1,
      "z": -2,
      "name": "Rock_Sandstone_Brick"
    },
    {
      "x": -3,
      "y": 2,
      "z": -2,
      "name": "Rock_Sandstone_Brick"
    },
    {
      "x": -3,
      "y": 3,
      "z": -2,
      "name": "Rock_Sandstone_Brick"
    },
    {
      "x": -3,
      "y": 4,
      "z": -2,
      "name": "Rock_Sandstone_Brick"
    },
    {
      "x": -3,
      "y": 0,
      "z": -1,
      "name": "Rock_Sandstone_Cobble"
    },
    {
      "x": -3,
      "y": 0,
      "z": 0,
      "name": "Rock_Sandstone_Cobble"
    },
    {
      "x": -3,
      "y": 0,
      "z": 1,
      "name": "Rock_Sandstone_Cobble"
    },
    {
      "x": -3,
      "y": 0,
      "z": 2,
      "name": "Rock_Sandstone_Cobble"
    },
    {
      "x": -3,
      "y": 1,
      "z": 2,
      "name": "Wood_Sticks",
      "support": 15
    },
    {
      "x": -3,
      "y": 0,
      "z": 3,
      "name": "Rock_Sandstone_Cobble"
    },
    {
      "x": -3,
      "y": 0,
      "z": 4,
      "name": "Rock_Sandstone_Brick"
    },
    {
      "x": -3,
      "y": 1,
      "z": 4,
      "name": "Rock_Sandstone_White_Brick"
    },
    {
      "x": -3,
      "y": 2,
      "z": 4,
      "name": "Rock_Sandstone_White_Brick"
    },
    {
      "x": -3,
      "y": 3,
      "z": 4,
      "name": "Rock_Sandstone_White_Brick"
    },
    {
      "x": -3,
      "y": 4,
      "z": 4,
      "name": "Rock_Sandstone_White_Brick"
    },
    {
      "x": -3,
      "y": 5,
      "z": 4,
      "name": "Rock_Sandstone_White_Brick"
    },
    {
      "x": -3,
      "y": 6,
      "z": 4,
      "name": "Rock_Sandstone_Brick_Ornate"
    },
    {
      "x": -3,
      "y": 7,
      "z": 4,
      "name": "Rock_Sandstone_White_Cobble_Half"
    },
    {
      "x": -3,
      "y": 0,
      "z": 5,
      "name": "*Rock_Sandstone_Brick_Stairs_State_Definitions_Corner_Left",
      "rotation": 3
    },
    {
      "x": -2,
      "y": 0,
      "z": -2,
      "name": "Rock_Sandstone_Cobble_Stairs",
      "rotation": 2
    },
    {
      "x": -2,
      "y": 0,
      "z": -1,
      "name": "Rock_Sandstone_Cobble"
    },
    {
      "x": -2,
      "y": 0,
      "z": 0,
      "name": "Rock_Sandstone_Cobble"
    },
    {
      "x": -2,
      "y": 0,
      "z": 1,
      "name": "Rock_Sandstone_Cobble"
    },
    {
      "x": -2,
      "y": 1,
      "z": 1,
      "name": "Rubble_Sandstone_Medium",
      "support": 15
    },
    {
      "x": -2,
      "y": 0,
      "z": 2,
      "name": "Rock_Sandstone_Cobble"
    },
    {
      "x": -2,
      "y": 0,
      "z": 3,
      "name": "Rock_Sandstone_Cobble"
    },
    {
      "x": -2,
      "y": 0,
      "z": 4,
      "name": "Rock_Sandstone_Brick"
    },
    {
      "x": -2,
      "y": 1,
      "z": 4,
      "name": "Rock_Sandstone_White_Brick"
    },
    {
      "x": -2,
      "y": 2,
      "z": 4,
      "name": "Furniture_Desert_Window"
    },
    {
      "x": -2,
      "y": 3,
      "z": 4,
      "name": "Furniture_Desert_Window"
    },
    {
      "x": -2,
      "y": 4,
      "z": 4,
      "name": "Wood_Dry_Trunk",
      "support": 15,
      "rotation": 5
    },
    {
      "x": -2,
      "y": 5,
      "z": 4,
      "name": "Rock_Sandstone_White_Brick"
    },
    {
      "x": -2,
      "y": 6,
      "z": 4,
      "name": "Rock_Sandstone_Brick_Ornate"
    },
    {
      "x": -2,
      "y": 7,
      "z": 4,
      "name": "Rock_Sandstone_White_Cobble"
    },
    {
      "x": -2,
      "y": 8,
      "z": 4,
      "name": "Rock_Sandstone_White_Cobble_Half"
    },
    {
      "x": -2,
      "y": 0,
      "z": 5,
      "name": "Rock_Sandstone_Brick_Stairs"
    },
    {
      "x": -1,
      "y": 0,
      "z": -2,
      "name": "Rock_Sandstone_Cobble_Stairs",
      "rotation": 2
    },
    {
      "x": -1,
      "y": 0,
      "z": -1,
      "name": "Rock_Sandstone_Cobble"
    },
    {
      "x": -1,
      "y": 0,
      "z": 0,
      "name": "Rock_Sandstone_Cobble"
    },
    {
      "x": -1,
      "y": 0,
      "z": 1,
      "name": "Rock_Sandstone_Cobble"
    },
    {
      "x": -1,
      "y": 0,
      "z": 2,
      "name": "Rock_Sandstone_Cobble"
    },
    {
      "x": -1,
      "y": 0,
      "z": 3,
      "name": "Rock_Sandstone_Cobble"
    },
    {
      "x": -1,
      "y": 3,
      "z": 3,
      "name": "Cloth_Roof_Hide_Flap",
      "rotation": 2
    },
    {
      "x": -1,
      "y": 0,
      "z": 4,
      "name": "Rock_Sandstone_Brick"
    },
    {
      "x": -1,
      "y": 1,
      "z": 4,
      "name": "Rock_Sandstone_White_Brick"
    },
    {
      "x": -1,
      "y": 3,
      "z": 4,
      "name": "Furniture_Desert_Window"
    },
    {
      "x": -1,
      "y": 4,
      "z": 4,
      "name": "Wood_Dry_Trunk",
      "support": 15,
      "rotation": 5
    },
    {
      "x": -1,
      "y": 5,
      "z": 4,
      "name": "Rock_Sandstone_White_Brick"
    },
    {
      "x": -1,
      "y": 6,
      "z": 4,
      "name": "Rock_Sandstone_Brick_Ornate"
    },
    {
      "x": -1,
      "y": 7,
      "z": 4,
      "name": "Rock_Sandstone_White_Brick"
    },
    {
      "x": -1,
      "y": 8,
      "z": 4,
      "name": "Rock_Sandstone_White_Cobble_Half"
    },
    {
      "x": -1,
      "y": 0,
      "z": 5,
      "name": "Rock_Sandstone_Brick_Stairs"
    },
    {
      "x": -1,
      "y": 4,
      "z": 5,
      "name": "Soil_Clay_Ocean_Brick_Roof_Hollow"
    },
    {
      "x": 0,
      "y": 0,
      "z": -2,
      "name": "Rock_Sandstone_Cobble_Stairs",
      "rotation": 2
    },
    {
      "x": 0,
      "y": 3,
      "z": -2,
      "name": "Rock_Sandstone_Brick_Stairs",
      "rotation": 9
    },
    {
      "x": 0,
      "y": 0,
      "z": -1,
      "name": "Rock_Sandstone_Cobble"
    },
    {
      "x": 0,
      "y": 0,
      "z": 0,
      "name": "Rock_Sandstone_Cobble"
    },
    {
      "x": 0,
      "y": 0,
      "z": 1,
      "name": "Rock_Sandstone_Cobble"
    },
    {
      "x": 0,
      "y": 0,
      "z": 2,
      "name": "Rock_Sandstone_Cobble"
    },
    {
      "x": 0,
      "y": 0,
      "z": 3,
      "name": "Rock_Sandstone_Cobble"
    },
    {
      "x": 0,
      "y": 0,
      "z": 4,
      "name": "Rock_Sandstone_Brick"
    },
    {
      "x": 0,
      "y": 1,
      "z": 4,
      "name": "Rock_Sandstone_White_Brick"
    },
    {
      "x": 0,
      "y": 4,
      "z": 4,
      "name": "Wood_Dry_Trunk",
      "support": 15,
      "rotation": 5
    },
    {
      "x": 0,
      "y": 5,
      "z": 4,
      "name": "Rock_Sandstone_White_Brick"
    },
    {
      "x": 0,
      "y": 6,
      "z": 4,
      "name": "Rock_Sandstone_Brick_Ornate"
    },
    {
      "x": 0,
      "y": 7,
      "z": 4,
      "name": "Rock_Sandstone_White_Brick"
    },
    {
      "x": 0,
      "y": 8,
      "z": 4,
      "name": "Rock_Sandstone_White_Brick"
    },
    {
      "x": 0,
      "y": 0,
      "z": 5,
      "name": "Rock_Sandstone_Brick_Stairs"
    },
    {
      "x": 1,
      "y": 0,
      "z": -4,
      "name": "Rock_Sandstone_Brick"
    },
    {
      "x": 1,
      "y": 1,
      "z": -4,
      "name": "Rock_Sandstone_Brick"
    },
    {
      "x": 1,
      "y": 2,
      "z": -4,
      "name": "Rock_Sandstone_White_Cobble"
    },
    {
      "x": 1,
      "y": 3,
      "z": -4,
      "name": "Rock_Sandstone_White_Cobble"
    },
    {
      "x": 1,
      "y": 0,
      "z": -3,
      "name": "Rock_Sandstone_Brick"
    },
    {
      "x": 1,
      "y": 1,
      "z": -3,
      "name": "Rock_Sandstone_Brick"
    },
    {
      "x": 1,
      "y": 2,
      "z": -3,
      "name": "Rock_Sandstone_White_Cobble"
    },
    {
      "x": 1,
      "y": 3,
      "z": -3,
      "name": "Rock_Sandstone_White_Cobble"
    },
    {
      "x": 1,
      "y": 0,
      "z": -2,
      "name": "Rock_Sandstone_Brick"
    },
    {
      "x": 1,
      "y": 1,
      "z": -2,
      "name": "Rock_Sandstone_Brick"
    },
    {
      "x": 1,
      "y": 2,
      "z": -2,
      "name": "Rock_Sandstone_Brick"
    },
    {
      "x": 1,
      "y": 3,
      "z": -2,
      "name": "Rock_Sandstone_Brick"
    },
    {
      "x": 1,
      "y": 4,
      "z": -2,
      "name": "Rock_Sandstone_Brick"
    },
    {
      "x": 1,
      "y": 0,
      "z": -1,
      "name": "Rock_Sandstone_Cobble"
    },
    {
      "x": 1,
      "y": 1,
      "z": -1,
      "name": "Rubble_Sandstone"
    },
    {
      "x": 1,
      "y": 0,
      "z": 0,
      "name": "Rock_Sandstone_Cobble"
    },
    {
      "x": 1,
      "y": 0,
      "z": 1,
      "name": "Rock_Sandstone_Cobble"
    },
    {
      "x": 1,
      "y": 0,
      "z": 2,
      "name": "Rock_Sandstone_Cobble"
    },
    {
      "x": 1,
      "y": 1,
      "z": 2,
      "name": "Rubble_Sandstone",
      "support": 15
    },
    {
      "x": 1,
      "y": 0,
      "z": 3,
      "name": "Rock_Sandstone_Cobble"
    },
    {
      "x": 1,
      "y": 0,
      "z": 4,
      "name": "Rock_Sandstone_Brick"
    },
    {
      "x": 1,
      "y": 1,
      "z": 4,
      "name": "Rock_Sandstone_White_Brick"
    },
    {
      "x": 1,
      "y": 2,
      "z": 4,
      "name": "Rock_Sandstone_White_Brick"
    },
    {
      "x": 1,
      "y": 3,
      "z": 4,
      "name": "Rock_Sandstone_White_Brick"
    },
    {
      "x": 1,
      "y": 4,
      "z": 4,
      "name": "Rock_Sandstone_White_Brick"
    },
    {
      "x": 1,
      "y": 5,
      "z": 4,
      "name": "Rock_Sandstone_White_Brick"
    },
    {
      "x": 1,
      "y": 6,
      "z": 4,
      "name": "Rock_Sandstone_Brick_Ornate"
    },
    {
      "x": 1,
      "y": 7,
      "z": 4,
      "name": "Rock_Sandstone_White_Brick"
    },
    {
      "x": 1,
      "y": 8,
      "z": 4,
      "name": "Rock_Sandstone_White_Brick"
    },
    {
      "x": 1,
      "y": 0,
      "z": 5,
      "name": "Rock_Sandstone_Brick_Stairs"
    },
    {
      "x": 2,
      "y": 0,
      "z": -2,
      "name": "Rock_Sandstone_Brick"
    },
    {
      "x": 2,
      "y": 1,
      "z": -2,
      "name": "Rock_Sandstone_Brick"
    },
    {
      "x": 2,
      "y": 2,
      "z": -2,
      "name": "Rock_Sandstone_Brick"
    },
    {
      "x": 2,
      "y": 3,
      "z": -2,
      "name": "Rock_Sandstone_Brick"
    },
    {
      "x": 2,
      "y": 4,
      "z": -2,
      "name": "Rock_Sandstone_Brick"
    },
    {
      "x": 2,
      "y": 5,
      "z": -2,
      "name": "Rock_Sandstone_Brick"
    },
    {
      "x": 2,
      "y": 6,
      "z": -2,
      "name": "Rock_Sandstone_Brick"
    },
    {
      "x": 2,
      "y": 0,
      "z": -1,
      "name": "Soil_Dirt_Dry"
    },
    {
      "x": 2,
      "y": 0,
      "z": 0,
      "name": "Rock_Sandstone_Cobble"
    },
    {
      "x": 2,
      "y": 0,
      "z": 1,
      "name": "Rock_Sandstone_Cobble"
    },
    {
      "x": 2,
      "y": 0,
      "z": 2,
      "name": "Rock_Sandstone_Cobble"
    },
    {
      "x": 2,
      "y": 6,
      "z": 2,
      "name": "Rock_Sandstone_Brick_Ornate"
    },
    {
      "x": 2,
      "y": 7,
      "z": 2,
      "name": "Rock_Sandstone_Brick"
    },
    {
      "x": 2,
      "y": 0,
      "z": 3,
      "name": "Rock_Sandstone_Cobble"
    },
    {
      "x": 2,
      "y": 1,
      "z": 3,
      "name": "Rubble_Sandstone",
      "support": 15
    },
    {
      "x": 2,
      "y": 6,
      "z": 3,
      "name": "Rock_Sandstone_Brick_Ornate"
    },
    {
      "x": 2,
      "y": 7,
      "z": 3,
      "name": "Rock_Sandstone_Brick"
    },
    {
      "x": 2,
      "y": 8,
      "z": 3,
      "name": "Rock_Sandstone_Brick"
    },
    {
      "x": 2,
      "y": 2,
      "z": 4,
      "name": "Rock_Sandstone_Brick_Half",
      "rotation": 5
    },
    {
      "x": 2,
      "y": 3,
      "z": 4,
      "name": "Rock_Sandstone_Brick_Half",
      "rotation": 5
    },
    {
      "x": 2,
      "y": 4,
      "z": 4,
      "name": "Rock_Sandstone_Brick"
    },
    {
      "x": 2,
      "y": 5,
      "z": 4,
      "name": "Rock_Sandstone_Brick"
    },
    {
      "x": 2,
      "y": 6,
      "z": 4,
      "name": "Rock_Sandstone_Brick_Ornate"
    },
    {
      "x": 2,
      "y": 7,
      "z": 4,
      "name": "Rock_Sandstone_Brick"
    },
    {
      "x": 2,
      "y": 8,
      "z": 4,
      "name": "Rock_Sandstone_Brick"
    },
    {
      "x": 3,
      "y": 0,
      "z": -2,
      "name": "Rock_Sandstone_Brick"
    },
    {
      "x": 3,
      "y": 1,
      "z": -2,
      "name": "Rock_Sandstone_Brick"
    },
    {
      "x": 3,
      "y": 2,
      "z": -2,
      "name": "Rock_Sandstone_Brick"
    },
    {
      "x": 3,
      "y": 3,
      "z": -2,
      "name": "Rock_Sandstone_White_Cobble"
    },
    {
      "x": 3,
      "y": 4,
      "z": -2,
      "name": "Rock_Sandstone_White_Cobble"
    },
    {
      "x": 3,
      "y": 5,
      "z": -2,
      "name": "Rock_Sandstone_White_Cobble"
    },
    {
      "x": 3,
      "y": 6,
      "z": -2,
      "name": "Rock_Sandstone_White_Cobble"
    },
    {
      "x": 3,
      "y": 0,
      "z": -1,
      "name": "Rock_Sandstone_Cobble"
    },
    {
      "x": 3,
      "y": 1,
      "z": -1,
      "name": "Rock_Sandstone_White_Cobble_Half"
    },
    {
      "x": 3,
      "y": 2,
      "z": -1,
      "name": "Furniture_Temple_Emerald_Ladder"
    },
    {
      "x": 3,
      "y": 4,
      "z": -1,
      "name": "Furniture_Temple_Emerald_Ladder"
    },
    {
      "x": 3,
      "y": 5,
      "z": -1,
      "name": "Furniture_Temple_Emerald_Ladder"
    },
    {
      "x": 3,
      "y": 0,
      "z": 0,
      "name": "Rock_Sandstone_Cobble"
    },
    {
      "x": 3,
      "y": 1,
      "z": 0,
      "name": "Rock_Sandstone_White_Cobble_Half"
    },
    {
      "x": 3,
      "y": 0,
      "z": 1,
      "name": "Rock_Sandstone_Cobble"
    },
    {
      "x": 3,
      "y": 1,
      "z": 1,
      "name": "Rubble_Sandstone",
      "support": 15
    },
    {
      "x": 3,
      "y": 0,
      "z": 2,
      "name": "Rock_Sandstone_Cobble"
    },
    {
      "x": 4,
      "y": 0,
      "z": -2,
      "name": "Rock_Sandstone_Brick"
    },
    {
      "x": 4,
      "y": 1,
      "z": -2,
      "name": "Rock_Sandstone_Brick"
    },
    {
      "x": 4,
      "y": 2,
      "z": -2,
      "name": "Rock_Sandstone_Brick"
    },
    {
      "x": 4,
      "y": 3,
      "z": -2,
      "name": "Rock_Sandstone_White_Cobble"
    },
    {
      "x": 4,
      "y": 4,
      "z": -2,
      "name": "Rock_Sandstone_White_Cobble"
    },
    {
      "x": 4,
      "y": 5,
      "z": -2,
      "name": "Rock_Sandstone_White_Cobble"
    },
    {
      "x": 4,
      "y": 0,
      "z": -1,
      "name": "Rock_Sandstone_Cobble"
    },
    {
      "x": 4,
      "y": 1,
      "z": -1,
      "name": "Rock_Sandstone_White_Cobble_Half"
    },
    {
      "x": 4,
      "y": 2,
      "z": -1,
      "name": "Furniture_Temple_Emerald_Ladder"
    },
    {
      "x": 4,
      "y": 3,
      "z": -1,
      "name": "Furniture_Temple_Emerald_Ladder"
    },
    {
      "x": 4,
      "y": 5,
      "z": -1,
      "name": "Furniture_Temple_Emerald_Ladder"
    },
    {
      "x": 4,
      "y": 0,
      "z": 0,
      "name": "Rock_Sandstone_Cobble"
    },
    {
      "x": 4,
      "y": 1,
      "z": 0,
      "name": "Rock_Sandstone_White_Cobble_Half"
    },
    {
      "x": 4,
      "y": 0,
      "z": 1,
      "name": "Rock_Sandstone_Cobble"
    },
    {
      "x": 4,
      "y": 0,
      "z": 5,
      "name": "Rubble_Sandstone_Medium",
      "support": 15
    },
    {
      "x": 5,
      "y": 0,
      "z": -2,
      "name": "Rock_Sandstone_Brick"
    },
    {
      "x": 5,
      "y": 1,
      "z": -2,
      "name": "Rock_Sandstone_Brick"
    },
    {
      "x": 5,
      "y": 0,
      "z": -1,
      "name": "Rock_Sandstone_Brick"
    },
    {
      "x": 5,
      "y": 1,
      "z": -1,
      "name": "Rock_Sandstone_White_Brick"
    },
    {
      "x": 5,
      "y": 2,
      "z": -1,
      "name": "Rock_Sandstone_White_Brick"
    },
    {
      "x": 5,
      "y": 0,
      "z": 0,
      "name": "Rock_Sandstone_Brick"
    },
    {
      "x": 5,
      "y": 1,
      "z": 0,
      "name": "Rock_Sandstone_White_Cobble_Half"
    },
    {
      "x": 5,
      "y": 0,
      "z": 1,
      "name": "Rock_Sandstone_Brick"
    },
    {
      "x": 5,
      "y": 1,
      "z": 1,
      "name": "Rock_Sandstone_White_Cobble_Half"
    },
    {
      "x": 5,
      "y": 0,
      "z": 3,
      "name": "Rubble_Sandstone_Medium",
      "support": 15
    }
  ],
  "fluids": [
    {
      "x": -4,
      "y": 1,
      "z": -2,
      "name": "Empty",
      "level": 0
    },
    {
      "x": -4,
      "y": 2,
      "z": -2,
      "name": "Empty",
      "level": 0
    },
    {
      "x": -4,
      "y": 3,
      "z": -2,
      "name": "Empty",
      "level": 0
    },
    {
      "x": -4,
      "y": 4,
      "z": -2,
      "name": "Empty",
      "level": 0
    },
    {
      "x": -4,
      "y": 5,
      "z": -2,
      "name": "Empty",
      "level": 0
    },
    {
      "x": -4,
      "y": 0,
      "z": -1,
      "name": "Empty",
      "level": 0
    },
    {
      "x": -4,
      "y": 1,
      "z": -1,
      "name": "Empty",
      "level": 0
    },
    {
      "x": -4,
      "y": 2,
      "z": -1,
      "name": "Empty",
      "level": 0
    },
    {
      "x": -4,
      "y": 3,
      "z": -1,
      "name": "Empty",
      "level": 0
    },
    {
      "x": -4,
      "y": 4,
      "z": -1,
      "name": "Empty",
      "level": 0
    },
    {
      "x": -4,
      "y": 0,
      "z": 0,
      "name": "Empty",
      "level": 0
    },
    {
      "x": -4,
      "y": 1,
      "z": 0,
      "name": "Empty",
      "level": 0
    },
    {
      "x": -4,
      "y": 2,
      "z": 0,
      "name": "Empty",
      "level": 0
    },
    {
      "x": -4,
      "y": 0,
      "z": 1,
      "name": "Empty",
      "level": 0
    },
    {
      "x": -4,
      "y": 1,
      "z": 1,
      "name": "Empty",
      "level": 0
    },
    {
      "x": -4,
      "y": 2,
      "z": 1,
      "name": "Empty",
      "level": 0
    },
    {
      "x": -4,
      "y": 3,
      "z": 1,
      "name": "Empty",
      "level": 0
    },
    {
      "x": -4,
      "y": 4,
      "z": 1,
      "name": "Empty",
      "level": 0
    },
    {
      "x": -4,
      "y": 0,
      "z": 2,
      "name": "Empty",
      "level": 0
    },
    {
      "x": -4,
      "y": 1,
      "z": 2,
      "name": "Empty",
      "level": 0
    },
    {
      "x": -4,
      "y": 2,
      "z": 2,
      "name": "Empty",
      "level": 0
    },
    {
      "x": -4,
      "y": 3,
      "z": 2,
      "name": "Empty",
      "level": 0
    },
    {
      "x": -4,
      "y": 4,
      "z": 2,
      "name": "Empty",
      "level": 0
    },
    {
      "x": -4,
      "y": 5,
      "z": 2,
      "name": "Empty",
      "level": 0
    },
    {
      "x": -4,
      "y": 0,
      "z": 3,
      "name": "Empty",
      "level": 0
    },
    {
      "x": -4,
      "y": 1,
      "z": 3,
      "name": "Empty",
      "level": 0
    },
    {
      "x": -4,
      "y": 2,
      "z": 3,
      "name": "Empty",
      "level": 0
    },
    {
      "x": -4,
      "y": 3,
      "z": 3,
      "name": "Empty",
      "level": 0
    },
    {
      "x": -4,
      "y": 4,
      "z": 3,
      "name": "Empty",
      "level": 0
    },
    {
      "x": -4,
      "y": 5,
      "z": 3,
      "name": "Empty",
      "level": 0
    },
    {
      "x": -4,
      "y": 6,
      "z": 3,
      "name": "Empty",
      "level": 0
    },
    {
      "x": -4,
      "y": 0,
      "z": 4,
      "name": "Empty",
      "level": 0
    },
    {
      "x": -4,
      "y": 1,
      "z": 4,
      "name": "Empty",
      "level": 0
    },
    {
      "x": -4,
      "y": 2,
      "z": 4,
      "name": "Empty",
      "level": 0
    },
    {
      "x": -4,
      "y": 3,
      "z": 4,
      "name": "Empty",
      "level": 0
    },
    {
      "x": -4,
      "y": 4,
      "z": 4,
      "name": "Empty",
      "level": 0
    },
    {
      "x": -4,
      "y": 5,
      "z": 4,
      "name": "Empty",
      "level": 0
    },
    {
      "x": -3,
      "y": 0,
      "z": -4,
      "name": "Empty",
      "level": 0
    },
    {
      "x": -3,
      "y": 1,
      "z": -4,
      "name": "Empty",
      "level": 0
    },
    {
      "x": -3,
      "y": 2,
      "z": -4,
      "name": "Empty",
      "level": 0
    },
    {
      "x": -3,
      "y": 0,
      "z": -3,
      "name": "Empty",
      "level": 0
    },
    {
      "x": -3,
      "y": 1,
      "z": -3,
      "name": "Empty",
      "level": 0
    },
    {
      "x": -3,
      "y": 2,
      "z": -3,
      "name": "Empty",
      "level": 0
    },
    {
      "x": -3,
      "y": 3,
      "z": -3,
      "name": "Empty",
      "level": 0
    },
    {
      "x": -3,
      "y": 0,
      "z": -2,
      "name": "Empty",
      "level": 0
    },
    {
      "x": -3,
      "y": 1,
      "z": -2,
      "name": "Empty",
      "level": 0
    },
    {
      "x": -3,
      "y": 2,
      "z": -2,
      "name": "Empty",
      "level": 0
    },
    {
      "x": -3,
      "y": 3,
      "z": -2,
      "name": "Empty",
      "level": 0
    },
    {
      "x": -3,
      "y": 4,
      "z": -2,
      "name": "Empty",
      "level": 0
    },
    {
      "x": -3,
      "y": 0,
      "z": -1,
      "name": "Empty",
      "level": 0
    },
    {
      "x": -3,
      "y": 0,
      "z": 0,
      "name": "Empty",
      "level": 0
    },
    {
      "x": -3,
      "y": 0,
      "z": 1,
      "name": "Empty",
      "level": 0
    },
    {
      "x": -3,
      "y": 0,
      "z": 2,
      "name": "Empty",
      "level": 0
    },
    {
      "x": -3,
      "y": 1,
      "z": 2,
      "name": "Empty",
      "level": 0
    },
    {
      "x": -3,
      "y": 0,
      "z": 3,
      "name": "Empty",
      "level": 0
    },
    {
      "x": -3,
      "y": 0,
      "z": 4,
      "name": "Empty",
      "level": 0
    },
    {
      "x": -3,
      "y": 1,
      "z": 4,
      "name": "Empty",
      "level": 0
    },
    {
      "x": -3,
      "y": 2,
      "z": 4,
      "name": "Empty",
      "level": 0
    },
    {
      "x": -3,
      "y": 3,
      "z": 4,
      "name": "Empty",
      "level": 0
    },
    {
      "x": -3,
      "y": 4,
      "z": 4,
      "name": "Empty",
      "level": 0
    },
    {
      "x": -3,
      "y": 5,
      "z": 4,
      "name": "Empty",
      "level": 0
    },
    {
      "x": -3,
      "y": 6,
      "z": 4,
      "name": "Empty",
      "level": 0
    },
    {
      "x": -3,
      "y": 7,
      "z": 4,
      "name": "Empty",
      "level": 0
    },
    {
      "x": -3,
      "y": 0,
      "z": 5,
      "name": "Empty",
      "level": 0
    },
    {
      "x": -2,
      "y": 0,
      "z": -2,
      "name": "Empty",
      "level": 0
    },
    {
      "x": -2,
      "y": 0,
      "z": -1,
      "name": "Empty",
      "level": 0
    },
    {
      "x": -2,
      "y": 0,
      "z": 0,
      "name": "Empty",
      "level": 0
    },
    {
      "x": -2,
      "y": 0,
      "z": 1,
      "name": "Empty",
      "level": 0
    },
    {
      "x": -2,
      "y": 1,
      "z": 1,
      "name": "Empty",
      "level": 0
    },
    {
      "x": -2,
      "y": 0,
      "z": 2,
      "name": "Empty",
      "level": 0
    },
    {
      "x": -2,
      "y": 0,
      "z": 3,
      "name": "Empty",
      "level": 0
    },
    {
      "x": -2,
      "y": 0,
      "z": 4,
      "name": "Empty",
      "level": 0
    },
    {
      "x": -2,
      "y": 1,
      "z": 4,
      "name": "Empty",
      "level": 0
    },
    {
      "x": -2,
      "y": 2,
      "z": 4,
      "name": "Empty",
      "level": 0
    },
    {
      "x": -2,
      "y": 3,
      "z": 4,
      "name": "Empty",
      "level": 0
    },
    {
      "x": -2,
      "y": 4,
      "z": 4,
      "name": "Empty",
      "level": 0
    },
    {
      "x": -2,
      "y": 5,
      "z": 4,
      "name": "Empty",
      "level": 0
    },
    {
      "x": -2,
      "y": 6,
      "z": 4,
      "name": "Empty",
      "level": 0
    },
    {
      "x": -2,
      "y": 7,
      "z": 4,
      "name": "Empty",
      "level": 0
    },
    {
      "x": -2,
      "y": 8,
      "z": 4,
      "name": "Empty",
      "level": 0
    },
    {
      "x": -2,
      "y": 0,
      "z": 5,
      "name": "Empty",
      "level": 0
    },
    {
      "x": -1,
      "y": 0,
      "z": -2,
      "name": "Empty",
      "level": 0
    },
    {
      "x": -1,
      "y": 0,
      "z": -1,
      "name": "Empty",
      "level": 0
    },
    {
      "x": -1,
      "y": 0,
      "z": 0,
      "name": "Empty",
      "level": 0
    },
    {
      "x": -1,
      "y": 0,
      "z": 1,
      "name": "Empty",
      "level": 0
    },
    {
      "x": -1,
      "y": 0,
      "z": 2,
      "name": "Empty",
      "level": 0
    },
    {
      "x": -1,
      "y": 0,
      "z": 3,
      "name": "Empty",
      "level": 0
    },
    {
      "x": -1,
      "y": 3,
      "z": 3,
      "name": "Empty",
      "level": 0
    },
    {
      "x": -1,
      "y": 0,
      "z": 4,
      "name": "Empty",
      "level": 0
    },
    {
      "x": -1,
      "y": 1,
      "z": 4,
      "name": "Empty",
      "level": 0
    },
    {
      "x": -1,
      "y": 3,
      "z": 4,
      "name": "Empty",
      "level": 0
    },
    {
      "x": -1,
      "y": 4,
      "z": 4,
      "name": "Empty",
      "level": 0
    },
    {
      "x": -1,
      "y": 5,
      "z": 4,
      "name": "Empty",
      "level": 0
    },
    {
      "x": -1,
      "y": 6,
      "z": 4,
      "name": "Empty",
      "level": 0
    },
    {
      "x": -1,
      "y": 7,
      "z": 4,
      "name": "Empty",
      "level": 0
    },
    {
      "x": -1,
      "y": 8,
      "z": 4,
      "name": "Empty",
      "level": 0
    },
    {
      "x": -1,
      "y": 0,
      "z": 5,
      "name": "Empty",
      "level": 0
    },
    {
      "x": -1,
      "y": 4,
      "z": 5,
      "name": "Empty",
      "level": 0
    },
    {
      "x": 0,
      "y": 0,
      "z": -2,
      "name": "Empty",
      "level": 0
    },
    {
      "x": 0,
      "y": 3,
      "z": -2,
      "name": "Empty",
      "level": 0
    },
    {
      "x": 0,
      "y": 0,
      "z": -1,
      "name": "Empty",
      "level": 0
    },
    {
      "x": 0,
      "y": 0,
      "z": 0,
      "name": "Empty",
      "level": 0
    },
    {
      "x": 0,
      "y": 0,
      "z": 1,
      "name": "Empty",
      "level": 0
    },
    {
      "x": 0,
      "y": 0,
      "z": 2,
      "name": "Empty",
      "level": 0
    },
    {
      "x": 0,
      "y": 0,
      "z": 3,
      "name": "Empty",
      "level": 0
    },
    {
      "x": 0,
      "y": 0,
      "z": 4,
      "name": "Empty",
      "level": 0
    },
    {
      "x": 0,
      "y": 1,
      "z": 4,
      "name": "Empty",
      "level": 0
    },
    {
      "x": 0,
      "y": 4,
      "z": 4,
      "name": "Empty",
      "level": 0
    },
    {
      "x": 0,
      "y": 5,
      "z": 4,
      "name": "Empty",
      "level": 0
    },
    {
      "x": 0,
      "y": 6,
      "z": 4,
      "name": "Empty",
      "level": 0
    },
    {
      "x": 0,
      "y": 7,
      "z": 4,
      "name": "Empty",
      "level": 0
    },
    {
      "x": 0,
      "y": 8,
      "z": 4,
      "name": "Empty",
      "level": 0
    },
    {
      "x": 0,
      "y": 0,
      "z": 5,
      "name": "Empty",
      "level": 0
    },
    {
      "x": 1,
      "y": 0,
      "z": -4,
      "name": "Empty",
      "level": 0
    },
    {
      "x": 1,
      "y": 1,
      "z": -4,
      "name": "Empty",
      "level": 0
    },
    {
      "x": 1,
      "y": 2,
      "z": -4,
      "name": "Empty",
      "level": 0
    },
    {
      "x": 1,
      "y": 3,
      "z": -4,
      "name": "Empty",
      "level": 0
    },
    {
      "x": 1,
      "y": 0,
      "z": -3,
      "name": "Empty",
      "level": 0
    },
    {
      "x": 1,
      "y": 1,
      "z": -3,
      "name": "Empty",
      "level": 0
    },
    {
      "x": 1,
      "y": 2,
      "z": -3,
      "name": "Empty",
      "level": 0
    },
    {
      "x": 1,
      "y": 3,
      "z": -3,
      "name": "Empty",
      "level": 0
    },
    {
      "x": 1,
      "y": 0,
      "z": -2,
      "name": "Empty",
      "level": 0
    },
    {
      "x": 1,
      "y": 1,
      "z": -2,
      "name": "Empty",
      "level": 0
    },
    {
      "x": 1,
      "y": 2,
      "z": -2,
      "name": "Empty",
      "level": 0
    },
    {
      "x": 1,
      "y": 3,
      "z": -2,
      "name": "Empty",
      "level": 0
    },
    {
      "x": 1,
      "y": 4,
      "z": -2,
      "name": "Empty",
      "level": 0
    },
    {
      "x": 1,
      "y": 0,
      "z": -1,
      "name": "Empty",
      "level": 0
    },
    {
      "x": 1,
      "y": 1,
      "z": -1,
      "name": "Empty",
      "level": 0
    },
    {
      "x": 1,
      "y": 0,
      "z": 0,
      "name": "Empty",
      "level": 0
    },
    {
      "x": 1,
      "y": 0,
      "z": 1,
      "name": "Empty",
      "level": 0
    },
    {
      "x": 1,
      "y": 0,
      "z": 2,
      "name": "Empty",
      "level": 0
    },
    {
      "x": 1,
      "y": 1,
      "z": 2,
      "name": "Empty",
      "level": 0
    },
    {
      "x": 1,
      "y": 0,
      "z": 3,
      "name": "Empty",
      "level": 0
    },
    {
      "x": 1,
      "y": 0,
      "z": 4,
      "name": "Empty",
      "level": 0
    },
    {
      "x": 1,
      "y": 1,
      "z": 4,
      "name": "Empty",
      "level": 0
    },
    {
      "x": 1,
      "y": 2,
      "z": 4,
      "name": "Empty",
      "level": 0
    },
    {
      "x": 1,
      "y": 3,
      "z": 4,
      "name": "Empty",
      "level": 0
    },
    {
      "x": 1,
      "y": 4,
      "z": 4,
      "name": "Empty",
      "level": 0
    },
    {
      "x": 1,
      "y": 5,
      "z": 4,
      "name": "Empty",
      "level": 0
    },
    {
      "x": 1,
      "y": 6,
      "z": 4,
      "name": "Empty",
      "level": 0
    },
    {
      "x": 1,
      "y": 7,
      "z": 4,
      "name": "Empty",
      "level": 0
    },
    {
      "x": 1,
      "y": 8,
      "z": 4,
      "name": "Empty",
      "level": 0
    },
    {
      "x": 1,
      "y": 0,
      "z": 5,
      "name": "Empty",
      "level": 0
    },
    {
      "x": 2,
      "y": 0,
      "z": -2,
      "name": "Empty",
      "level": 0
    },
    {
      "x": 2,
      "y": 1,
      "z": -2,
      "name": "Empty",
      "level": 0
    },
    {
      "x": 2,
      "y": 2,
      "z": -2,
      "name": "Empty",
      "level": 0
    },
    {
      "x": 2,
      "y": 3,
      "z": -2,
      "name": "Empty",
      "level": 0
    },
    {
      "x": 2,
      "y": 4,
      "z": -2,
      "name": "Empty",
      "level": 0
    },
    {
      "x": 2,
      "y": 5,
      "z": -2,
      "name": "Empty",
      "level": 0
    },
    {
      "x": 2,
      "y": 6,
      "z": -2,
      "name": "Empty",
      "level": 0
    },
    {
      "x": 2,
      "y": 0,
      "z": -1,
      "name": "Empty",
      "level": 0
    },
    {
      "x": 2,
      "y": 0,
      "z": 0,
      "name": "Empty",
      "level": 0
    },
    {
      "x": 2,
      "y": 0,
      "z": 1,
      "name": "Empty",
      "level": 0
    },
    {
      "x": 2,
      "y": 0,
      "z": 2,
      "name": "Empty",
      "level": 0
    },
    {
      "x": 2,
      "y": 6,
      "z": 2,
      "name": "Empty",
      "level": 0
    },
    {
      "x": 2,
      "y": 7,
      "z": 2,
      "name": "Empty",
      "level": 0
    },
    {
      "x": 2,
      "y": 0,
      "z": 3,
      "name": "Empty",
      "level": 0
    },
    {
      "x": 2,
      "y": 1,
      "z": 3,
      "name": "Empty",
      "level": 0
    },
    {
      "x": 2,
      "y": 6,
      "z": 3,
      "name": "Empty",
      "level": 0
    },
    {
      "x": 2,
      "y": 7,
      "z": 3,
      "name": "Empty",
      "level": 0
    },
    {
      "x": 2,
      "y": 8,
      "z": 3,
      "name": "Empty",
      "level": 0
    },
    {
      "x": 2,
      "y": 2,
      "z": 4,
      "name": "Empty",
      "level": 0
    },
    {
      "x": 2,
      "y": 3,
      "z": 4,
      "name": "Empty",
      "level": 0
    },
    {
      "x": 2,
      "y": 4,
      "z": 4,
      "name": "Empty",
      "level": 0
    },
    {
      "x": 2,
      "y": 5,
      "z": 4,
      "name": "Empty",
      "level": 0
    },
    {
      "x": 2,
      "y": 6,
      "z": 4,
      "name": "Empty",
      "level": 0
    },
    {
      "x": 2,
      "y": 7,
      "z": 4,
      "name": "Empty",
      "level": 0
    },
    {
      "x": 2,
      "y": 8,
      "z": 4,
      "name": "Empty",
      "level": 0
    },
    {
      "x": 3,
      "y": 0,
      "z": -2,
      "name": "Empty",
      "level": 0
    },
    {
      "x": 3,
      "y": 1,
      "z": -2,
      "name": "Empty",
      "level": 0
    },
    {
      "x": 3,
      "y": 2,
      "z": -2,
      "name": "Empty",
      "level": 0
    },
    {
      "x": 3,
      "y": 3,
      "z": -2,
      "name": "Empty",
      "level": 0
    },
    {
      "x": 3,
      "y": 4,
      "z": -2,
      "name": "Empty",
      "level": 0
    },
    {
      "x": 3,
      "y": 5,
      "z": -2,
      "name": "Empty",
      "level": 0
    },
    {
      "x": 3,
      "y": 6,
      "z": -2,
      "name": "Empty",
      "level": 0
    },
    {
      "x": 3,
      "y": 0,
      "z": -1,
      "name": "Empty",
      "level": 0
    },
    {
      "x": 3,
      "y": 1,
      "z": -1,
      "name": "Empty",
      "level": 0
    },
    {
      "x": 3,
      "y": 2,
      "z": -1,
      "name": "Empty",
      "level": 0
    },
    {
      "x": 3,
      "y": 4,
      "z": -1,
      "name": "Empty",
      "level": 0
    },
    {
      "x": 3,
      "y": 5,
      "z": -1,
      "name": "Empty",
      "level": 0
    },
    {
      "x": 3,
      "y": 0,
      "z": 0,
      "name": "Empty",
      "level": 0
    },
    {
      "x": 3,
      "y": 1,
      "z": 0,
      "name": "Empty",
      "level": 0
    },
    {
      "x": 3,
      "y": 0,
      "z": 1,
      "name": "Empty",
      "level": 0
    },
    {
      "x": 3,
      "y": 1,
      "z": 1,
      "name": "Empty",
      "level": 0
    },
    {
      "x": 3,
      "y": 0,
      "z": 2,
      "name": "Empty",
      "level": 0
    },
    {
      "x": 4,
      "y": 0,
      "z": -2,
      "name": "Empty",
      "level": 0
    },
    {
      "x": 4,
      "y": 1,
      "z": -2,
      "name": "Empty",
      "level": 0
    },
    {
      "x": 4,
      "y": 2,
      "z": -2,
      "name": "Empty",
      "level": 0
    },
    {
      "x": 4,
      "y": 3,
      "z": -2,
      "name": "Empty",
      "level": 0
    },
    {
      "x": 4,
      "y": 4,
      "z": -2,
      "name": "Empty",
      "level": 0
    },
    {
      "x": 4,
      "y": 5,
      "z": -2,
      "name": "Empty",
      "level": 0
    },
    {
      "x": 4,
      "y": 0,
      "z": -1,
      "name": "Empty",
      "level": 0
    },
    {
      "x": 4,
      "y": 1,
      "z": -1,
      "name": "Empty",
      "level": 0
    },
    {
      "x": 4,
      "y": 2,
      "z": -1,
      "name": "Empty",
      "level": 0
    },
    {
      "x": 4,
      "y": 3,
      "z": -1,
      "name": "Empty",
      "level": 0
    },
    {
      "x": 4,
      "y": 5,
      "z": -1,
      "name": "Empty",
      "level": 0
    },
    {
      "x": 4,
      "y": 0,
      "z": 0,
      "name": "Empty",
      "level": 0
    },
    {
      "x": 4,
      "y": 1,
      "z": 0,
      "name": "Empty",
      "level": 0
    },
    {
      "x": 4,
      "y": 0,
      "z": 1,
      "name": "Empty",
      "level": 0
    },
    {
      "x": 4,
      "y": 0,
      "z": 5,
      "name": "Empty",
      "level": 0
    },
    {
      "x": 5,
      "y": 0,
      "z": -2,
      "name": "Empty",
      "level": 0
    },
    {
      "x": 5,
      "y": 1,
      "z": -2,
      "name": "Empty",
      "level": 0
    },
    {
      "x": 5,
      "y": 0,
      "z": -1,
      "name": "Empty",
      "level": 0
    },
    {
      "x": 5,
      "y": 1,
      "z": -1,
      "name": "Empty",
      "level": 0
    },
    {
      "x": 5,
      "y": 2,
      "z": -1,
      "name": "Empty",
      "level": 0
    },
    {
      "x": 5,
      "y": 0,
      "z": 0,
      "name": "Empty",
      "level": 0
    },
    {
      "x": 5,
      "y": 1,
      "z": 0,
      "name": "Empty",
      "level": 0
    },
    {
      "x": 5,
      "y": 0,
      "z": 1,
      "name": "Empty",
      "level": 0
    },
    {
      "x": 5,
      "y": 1,
      "z": 1,
      "name": "Empty",
      "level": 0
    },
    {
      "x": 5,
      "y": 0,
      "z": 3,
      "name": "Empty",
      "level": 0
    }
  ]
}