{
  "version": 8,
  "blockIdVersion": 11,
  "anchorX": 4,
  "anchorY": 1,
  "anchorZ": -5,
  "blocks": [
    {
      "x": 0,
      "y": 2,
      "z": -7,
      "name": "Rock_Sandstone_Brick_Half",
      "rotation": 6
    },
    {
      "x": 0,
      "y": 1,
      "z": -6,
      "name": "Rock_Sandstone_Brick"
    },
    {
      "x": 0,
      "y": 2,
      "z": -6,
      "name": "Rock_Sandstone_White_Brick"
    },
    {
      "x": 0,
      "y": 1,
      "z": -5,
      "name": "Rock_Sandstone_Brick"
    },
    {
      "x": 0,
      "y": 2,
      "z": -5,
      "name": "Rock_Sandstone_White_Brick"
    },
    {
      "x": 0,
      "y": 3,
      "z": -5,
      "name": "Furniture_Desert_Window",
      "rotation": 1
    },
    {
      "x": 0,
      "y": 4,
      "z": -5,
      "name": "Wood_Drywood_Beam"
    },
    {
      "x": 0,
      "y": 1,
      "z": -4,
      "name": "Rock_Sandstone_Brick"
    },
    {
      "x": 0,
      "y": 2,
      "z": -4,
      "name": "Rock_Sandstone_White_Brick"
    },
    {
      "x": 0,
      "y": 1,
      "z": -3,
      "name": "Rock_Sandstone_Brick"
    },
    {
      "x": 0,
      "y": 2,
      "z": -3,
      "name": "Rock_Sandstone_White_Brick"
    },
    {
      "x": 0,
      "y": 3,
      "z": -3,
      "name": "Furniture_Desert_Window",
      "rotation": 1
    },
    {
      "x": 0,
      "y": 1,
      "z": -2,
      "name": "Rock_Sandstone_Brick"
    },
    {
      "x": 0,
      "y": 2,
      "z": -2,
      "name": "Rock_Sandstone_White_Brick"
    },
    {
      "x": 0,
      "y": 3,
      "z": -2,
      "name": "Rock_Sandstone_White_Brick"
    },
    {
      "x": 0,
      "y": 4,
      "z": -2,
      "name": "Rock_Sandstone_White_Brick"
    },
    {
      "x": 0,
      "y": 1,
      "z": -1,
      "name": "Rock_Sandstone_Brick"
    },
    {
      "x": 0,
      "y": 2,
      "z": -1,
      "name": "Rock_Sandstone_Brick_Stairs",
      "rotation": 10
    },
    {
      "x": 0,
      "y": 3,
      "z": -1,
      "name": "Rock_Sandstone_Brick_Stairs",
      "rotation": 3
    },
    {
      "x": 1,
      "y": 1,
      "z": -9,
      "name": "Rock_Sandstone_Brick_Stairs",
      "rotation": 1
    },
    {
      "x": 1,
      "y": 2,
      "z": -9,
      "name": "Rock_Sandstone_Brick_Stairs",
      "rotation": 8
    },
    {
      "x": 1,
      "y": 3,
      "z": -9,
      "name": "Rock_Sandstone_White_Cobble_Half",
      "rotation": 6
    },
    {
      "x": 1,
      "y": 1,
      "z": -8,
      "name": "Rock_Sandstone_Brick"
    },
    {
      "x": 1,
      "y": 2,
      "z": -8,
      "name": "Rock_Sandstone_Brick"
    },
    {
      "x": 1,
      "y": 3,
      "z": -8,
      "name": "Rock_Sandstone_White_Cobble"
    },
    {
      "x": 1,
      "y": 1,
      "z": -7,
      "name": "Rock_Sandstone_Brick"
    },
    {
      "x": 1,
      "y": 2,
      "z": -7,
      "name": "Rock_Sandstone_Brick"
    },
    {
      "x": 1,
      "y": 1,
      "z": -6,
      "name": "Rock_Sandstone_Cobble"
    },
    {
      "x": 1,
      "y": 1,
      "z": -5,
      "name": "Rock_Sandstone_Cobble"
    },
    {
      "x": 1,
      "y": 1,
      "z": -4,
      "name": "Rock_Sandstone_Cobble"
    },
    {
      "x": 1,
      "y": 1,
      "z": -3,
      "name": "Rock_Sandstone_Cobble"
    },
    {
      "x": 1,
      "y": 2,
      "z": -3,
      "name": "Wood_Sticks",
      "support": 15
    },
    {
      "x": 1,
      "y": 1,
      "z": -2,
      "name": "Rock_Sandstone_Cobble"
    },
    {
      "x": 1,
      "y": 1,
      "z": -1,
      "name": "Rock_Sandstone_Brick"
    },
    {
      "x": 1,
      "y": 2,
      "z": -1,
      "name": "Rock_Sandstone_White_Brick"
    },
    {
      "x": 1,
      "y": 3,
      "z": -1,
      "name": "Rock_Sandstone_White_Brick"
    },
    {
      "x": 2,
      "y": 1,
      "z": -7,
      "name": "Rock_Sandstone_Cobble_Stairs",
      "rotation": 2
    },
    {
      "x": 2,
      "y": 1,
      "z": -6,
      "name": "Rock_Sandstone_Cobble"
    },
    {
      "x": 2,
      "y": 1,
      "z": -5,
      "name": "Rock_Sandstone_Cobble"
    },
    {
      "x": 2,
      "y": 1,
      "z": -4,
      "name": "Rock_Sandstone_Cobble"
    },
    {
      "x": 2,
      "y": 2,
      "z": -4,
      "name": "Rubble_Sandstone_Medium",
      "support": 15
    },
    {
      "x": 2,
      "y": 1,
      "z": -3,
      "name": "Rock_Sandstone_Cobble"
    },
    {
      "x": 2,
      "y": 1,
      "z": -2,
      "name": "Rock_Sandstone_Cobble"
    },
    {
      "x": 2,
      "y": 1,
      "z": -1,
      "name": "Rock_Sandstone_Brick"
    },
    {
      "x": 2,
      "y": 2,
      "z": -1,
      "name": "Rock_Sandstone_White_Brick"
    },
    {
      "x": 2,
      "y": 3,
      "z": -1,
      "name": "Furniture_Desert_Window"
    },
    {
      "x": 3,
      "y": 1,
      "z": -7,
      "name": "Rock_Sandstone_Cobble_Stairs",
      "rotation": 2
    },
    {
      "x": 3,
      "y": 1,
      "z": -6,
      "name": "Rock_Sandstone_Cobble"
    },
    {
      "x": 3,
      "y": 1,
      "z": -5,
      "name": "Rock_Sandstone_Cobble"
    },
    {
      "x": 3,
      "y": 1,
      "z": -4,
      "name": "Rock_Sandstone_Cobble"
    },
    {
      "x": 3,
      "y": 1,
      "z": -3,
      "name": "Rock_Sandstone_Cobble"
    },
    {
      "x": 3,
      "y": 1,
      "z": -2,
      "name": "Rock_Sandstone_Cobble"
    },
    {
      "x": 3,
      "y": 1,
      "z": -1,
      "name": "Rock_Sandstone_Brick"
    },
    {
      "x": 3,
      "y": 2,
      "z": -1,
      "name": "Rock_Sandstone_White_Brick"
    },
    {
      "x": 3,
      "y": 1,
      "z": 0,
      "name": "Rock_Sandstone_Brick_Stairs"
    },
    {
      "x": 4,
      "y": 1,
      "z": -7,
      "name": "Rock_Sandstone_Cobble_Stairs",
      "rotation": 2
    },
    {
      "x": 4,
      "y": 1,
      "z": -6,
      "name": "Rock_Sandstone_Cobble"
    },
    {
      "x": 4,
      "y": 1,
      "z": -5,
      "name": "Rock_Sandstone_Cobble"
    },
    {
      "x": 4,
      "y": 1,
      "z": -4,
      "name": "Rock_Sandstone_Cobble"
    },
    {
      "x": 4,
      "y": 1,
      "z": -3,
      "name": "Rock_Sandstone_Cobble"
    },
    {
      "x": 4,
      "y": 1,
      "z": -2,
      "name": "Rock_Sandstone_Cobble"
    },
    {
      "x": 4,
      "y": 1,
      "z": -1,
      "name": "Rock_Sandstone_Brick"
    },
    {
      "x": 4,
      "y": 2,
      "z": -1,
      "name": "Rock_Sandstone_White_Brick"
    },
    {
      "x": 4,
      "y": 1,
      "z": 0,
      "name": "Rock_Sandstone_Cobble_Stairs"
    },
    {
      "x": 5,
      "y": 1,
      "z": -9,
      "name": "Rock_Sandstone_Brick"
    },
    {
      "x": 5,
      "y": 2,
      "z": -9,
      "name": "Rock_Sandstone_Brick_Stairs",
      "rotation": 2
    },
    {
      "x": 5,
      "y": 3,
      "z": -9,
      "name": "Rock_Sandstone_White_Cobble_Half",
      "rotation": 6
    },
    {
      "x": 5,
      "y": 4,
      "z": -9,
      "name": "Rock_Sandstone_White_Cobble_Half",
      "rotation": 6
    },
    {
      "x": 5,
      "y": 5,
      "z": -9,
      "name": "Rock_Sandstone_White_Cobble_Half",
      "rotation": 6
    },
    {
      "x": 5,
      "y": 6,
      "z": -9,
      "name": "Rock_Sandstone_White_Cobble_Half",
      "rotation": 6
    },
    {
      "x": 5,
      "y": 1,
      "z": -8,
      "name": "Rock_Sandstone_Brick"
    },
    {
      "x": 5,
      "y": 2,
      "z": -8,
      "name": "Rock_Sandstone_Brick"
    },
    {
      "x": 5,
      "y": 3,
      "z": -8,
      "name": "Rock_Sandstone_White_Cobble"
    },
    {
      "x": 5,
      "y": 4,
      "z": -8,
      "name": "Rock_Sandstone_White_Cobble"
    },
    {
      "x": 5,
      "y": 5,
      "z": -8,
      "name": "Rock_Sandstone_White_Cobble"
    },
    {
      "x": 5,
      "y": 1,
      "z": -7,
      "name": "Rock_Sandstone_Brick"
    },
    {
      "x": 5,
      "y": 2,
      "z": -7,
      "name": "Rock_Sandstone_Brick"
    },
    {
      "x": 5,
      "y": 3,
      "z": -7,
      "name": "Rock_Sandstone_Brick"
    },
    {
      "x": 5,
      "y": 1,
      "z": -6,
      "name": "Rock_Sandstone_Cobble"
    },
    {
      "x": 5,
      "y": 2,
      "z": -6,
      "name": "Rubble_Sandstone"
    },
    {
      "x": 5,
      "y": 1,
      "z": -5,
      "name": "Rock_Sandstone_Cobble"
    },
    {
      "x": 5,
      "y": 1,
      "z": -4,
      "name": "Rock_Sandstone_Cobble"
    },
    {
      "x": 5,
      "y": 1,
      "z": -3,
      "name": "Rock_Sandstone_Cobble"
    },
    {
      "x": 5,
      "y": 1,
      "z": -2,
      "name": "Rock_Sandstone_Cobble"
    },
    {
      "x": 5,
      "y": 1,
      "z": -1,
      "name": "Rock_Sandstone_Brick"
    },
    {
      "x": 5,
      "y": 2,
      "z": -1,
      "name": "Rock_Sandstone_White_Brick"
    },
    {
      "x": 5,
      "y": 3,
      "z": -1,
      "name": "Rock_Sandstone_White_Brick"
    },
    {
      "x": 5,
      "y": 4,
      "z": -1,
      "name": "Rock_Sandstone_White_Brick"
    },
    {
      "x": 5,
      "y": 1,
      "z": 0,
      "name": "Rock_Sandstone_Cobble_Stairs"
    },
    {
      "x": 6,
      "y": 1,
      "z": -9,
      "name": "Rock_Sandstone_Cobble_Stairs",
      "rotation": 2
    },
    {
      "x": 6,
      "y": 1,
      "z": -8,
      "name": "Rock_Sandstone_Brick"
    },
    {
      "x": 6,
      "y": 2,
      "z": -8,
      "name": "Rock_Sandstone_Brick"
    },
    {
      "x": 6,
      "y": 3,
      "z": -8,
      "name": "Rock_Sandstone_Brick"
    },
    {
      "x": 6,
      "y": 1,
      "z": -7,
      "name": "Rock_Sandstone_Brick"
    },
    {
      "x": 6,
      "y": 2,
      "z": -7,
      "name": "Rock_Sandstone_Brick"
    },
    {
      "x": 6,
      "y": 3,
      "z": -7,
      "name": "Rock_Sandstone_Brick"
    },
    {
      "x": 6,
      "y": 4,
      "z": -7,
      "name": "Rock_Sandstone_Brick"
    },
    {
      "x": 6,
      "y": 1,
      "z": -6,
      "name": "Soil_Dirt_Dry"
    },
    {
      "x": 6,
      "y": 1,
      "z": -5,
      "name": "Rock_Sandstone_Cobble"
    },
    {
      "x": 6,
      "y": 1,
      "z": -4,
      "name": "Rock_Sandstone_Cobble"
    },
    {
      "x": 6,
      "y": 2,
      "z": -4,
      "name": "Rock_Sandstone_White_Brick_Stairs",
      "rotation": 2
    },
    {
      "x": 6,
      "y": 3,
      "z": -4,
      "name": "Rock_Sandstone_White_Brick_Stairs",
      "rotation": 3
    },
    {
      "x": 6,
      "y": 1,
      "z": -3,
      "name": "Soil_Dirt_Dry"
    },
    {
      "x": 6,
      "y": 2,
      "z": -3,
      "name": "Rock_Sandstone_White_Brick"
    },
    {
      "x": 6,
      "y": 3,
      "z": -3,
      "name": "Rock_Sandstone_White_Brick"
    },
    {
      "x": 6,
      "y": 1,
      "z": -2,
      "name": "Soil_Dirt_Dry"
    },
    {
      "x": 6,
      "y": 2,
      "z": -2,
      "name": "Rock_Sandstone_White_Brick"
    },
    {
      "x": 6,
      "y": 1,
      "z": -1,
      "name": "Rock_Sandstone_Brick"
    },
    {
      "x": 6,
      "y": 2,
      "z": -1,
      "name": "Rock_Sandstone_Brick"
    },
    {
      "x": 6,
      "y": 3,
      "z": -1,
      "name": "Rock_Sandstone_Brick"
    },
    {
      "x": 6,
      "y": 1,
      "z": 0,
      "name": "Rock_Sandstone_Brick_Stairs"
    },
    {
      "x": 7,
      "y": 1,
      "z": -9,
      "name": "Rock_Sandstone_Cobble_Stairs",
      "rotation": 2
    },
    {
      "x": 7,
      "y": 1,
      "z": -8,
      "name": "Rock_Sandstone_Brick"
    },
    {
      "x": 7,
      "y": 2,
      "z": -8,
      "name": "Rock_Sandstone_Brick"
    },
    {
      "x": 7,
      "y": 3,
      "z": -8,
      "name": "Rock_Sandstone_Brick"
    },
    {
      "x": 7,
      "y": 1,
      "z": -7,
      "name": "Rock_Sandstone_Brick"
    },
    {
      "x": 7,
      "y": 2,
      "z": -7,
      "name": "Rock_Sandstone_Brick"
    },
    {
      "x": 7,
      "y": 3,
      "z": -7,
      "name": "Rock_Sandstone_Brick"
    },
    {
      "x": 7,
      "y": 4,
      "z": -7,
      "name": "Rock_Sandstone_White_Cobble"
    },
    {
      "x": 7,
      "y": 5,
      "z": -7,
      "name": "Rock_Sandstone_White_Cobble"
    },
    {
      "x": 7,
      "y": 1,
      "z": -6,
      "name": "Soil_Dirt_Dry"
    },
    {
      "x": 7,
      "y": 2,
      "z": -6,
      "name": "Rock_Sandstone_White_Cobble_Half"
    },
    {
      "x": 7,
      "y": 3,
      "z": -6,
      "name": "Furniture_Temple_Emerald_Ladder"
    },
    {
      "x": 7,
      "y": 4,
      "z": -6,
      "name": "Furniture_Temple_Emerald_Ladder"
    },
    {
      "x": 7,
      "y": 5,
      "z": -6,
      "name": "Furniture_Temple_Emerald_Ladder"
    },
    {
      "x": 7,
      "y": 1,
      "z": -5,
      "name": "Soil_Dirt_Dry"
    },
    {
      "x": 7,
      "y": 2,
      "z": -5,
      "name": "Rock_Sandstone_White_Cobble_Half"
    },
    {
      "x": 7,
      "y": 1,
      "z": -4,
      "name": "Soil_Dirt_Dry"
    },
    {
      "x": 7,
      "y": 1,
      "z": -3,
      "name": "Soil_Dirt_Dry"
    },
    {
      "x": 7,
      "y": 1,
      "z": -2,
      "name": "Soil_Dirt_Dry"
    },
    {
      "x": 7,
      "y": 1,
      "z": -1,
      "name": "Rock_Sandstone_Brick"
    },
    {
      "x": 7,
      "y": 1,
      "z": 0,
      "name": "Rock_Sandstone_Brick_Stairs"
    },
    {
      "x": 8,
      "y": 1,
      "z": -9,
      "name": "*Rock_Sandstone_Brick_Stairs_State_Definitions_Corner_Left",
      "rotation": 1
    },
    {
      "x": 8,
      "y": 1,
      "z": -8,
      "name": "*Rock_Sandstone_Brick_Stairs_State_Definitions_Inverted_Corner_Left",
      "rotation": 1
    },
    {
      "x": 8,
      "y": 1,
      "z": -7,
      "name": "Rock_Sandstone_Brick"
    },
    {
      "x": 8,
      "y": 2,
      "z": -7,
      "name": "Rock_Sandstone_Brick"
    },
    {
      "x": 8,
      "y": 3,
      "z": -7,
      "name": "Rock_Sandstone_Brick"
    },
    {
      "x": 8,
      "y": 4,
      "z": -7,
      "name": "Rock_Sandstone_White_Cobble"
    },
    {
      "x": 8,
      "y": 5,
      "z": -7,
      "name": "Rock_Sandstone_White_Cobble"
    },
    {
      "x": 8,
      "y": 6,
      "z": -7,
      "name": "Rock_Sandstone_White_Cobble"
    },
    {
      "x": 8,
      "y": 7,
      "z": -7,
      "name": "Rock_Sandstone_White_Cobble"
    },
    {
      "x": 8,
      "y": 8,
      "z": -7,
      "name": "Rock_Sandstone_Brick_Half"
    },
    {
      "x": 8,
      "y": 1,
      "z": -6,
      "name": "Soil_Dirt_Dry"
    },
    {
      "x": 8,
      "y": 2,
      "z": -6,
      "name": "Rock_Sandstone_White_Cobble_Half"
    },
    {
      "x": 8,
      "y": 3,
      "z": -6,
      "name": "Furniture_Temple_Emerald_Ladder"
    },
    {
      "x": 8,
      "y": 4,
      "z": -6,
      "name": "Furniture_Temple_Emerald_Ladder"
    },
    {
      "x": 8,
      "y": 5,
      "z": -6,
      "name": "Furniture_Temple_Emerald_Ladder"
    },
    {
      "x": 8,
      "y": 6,
      "z": -6,
      "name": "Furniture_Temple_Emerald_Ladder"
    },
    {
      "x": 8,
      "y": 1,
      "z": -5,
      "name": "Soil_Dirt_Dry"
    },
    {
      "x": 8,
      "y": 2,
      "z": -5,
      "name": "Rock_Sandstone_White_Cobble_Half"
    },
    {
      "x": 8,
      "y": 1,
      "z": -4,
      "name": "Soil_Dirt_Dry"
    },
    {
      "x": 8,
      "y": 1,
      "z": -3,
      "name": "Soil_Dirt_Dry"
    },
    {
      "x": 8,
      "y": 1,
      "z": -2,
      "name": "Soil_Dirt_Dry"
    },
    {
      "x": 8,
      "y": 1,
      "z": -1,
      "name": "Rock_Sandstone_Brick_Stairs",
      "rotation": 1
    },
    {
      "x": 8,
      "y": 1,
      "z": 0,
      "name": "*Rock_Sandstone_Brick_Stairs_State_Definitions_Corner_Right",
      "rotation": 1
    },
    {
      "x": 9,
      "y": 1,
      "z": -8,
      "name": "*Rock_Sandstone_Brick_Stairs_State_Definitions_Corner_Right",
      "rotation": 2
    },
    {
      "x": 9,
      "y": 1,
      "z": -7,
      "name": "Rock_Sandstone_Brick_Stairs",
      "rotation": 1
    },
    {
      "x": 9,
      "y": 2,
      "z": -7,
      "name": "Rock_Sandstone_Brick_Half",
      "rotation": 5
    },
    {
      "x": 9,
      "y": 3,
      "z": -7,
      "name": "Rock_Sandstone_Brick_Half",
      "rotation": 5
    },
    {
      "x": 9,
      "y": 4,
      "z": -7,
      "name": "Rock_Sandstone_Brick_Half",
      "rotation": 5
    },
    {
      "x": 9,
      "y": 5,
      "z": -7,
      "name": "Rock_Sandstone_Brick_Half",
      "rotation": 5
    },
    {
      "x": 9,
      "y": 6,
      "z": -7,
      "name": "Rock_Sandstone_Brick_Half",
      "rotation": 5
    },
    {
      "x": 9,
      "y": 7,
      "z": -7,
      "name": "Rock_Sandstone_Brick_Half",
      "rotation": 5
    },
    {
      "x": 9,
      "y": 8,
      "z": -7,
      "name": "Rock_Sandstone_Brick_Half",
      "rotation": 5
    },
    {
      "x": 9,
      "y": 1,
      "z": -6,
      "name": "Rock_Sandstone_Brick_Stairs",
      "rotation": 1
    },
    {
      "x": 9,
      "y": 2,
      "z": -6,
      "name": "Rock_Sandstone_Brick_Half",
      "rotation": 5
    },
    {
      "x": 9,
      "y": 3,
      "z": -6,
      "name": "Rock_Sandstone_Brick_Half",
      "rotation": 5
    },
    {
      "x": 9,
      "y": 4,
      "z": -6,
      "name": "Rock_Sandstone_Brick_Half",
      "rotation": 5
    },
    {
      "x": 9,
      "y": 5,
      "z": -6,
      "name": "Rock_Sandstone_Brick_Half",
      "rotation": 5
    },
    {
      "x": 9,
      "y": 6,
      "z": -6,
      "name": "Rock_Sandstone_Brick_Half",
      "rotation": 5
    },
    {
      "x": 9,
      "y": 7,
      "z": -6,
      "name": "Rock_Sandstone_Brick_Half",
      "rotation": 5
    },
    {
      "x": 9,
      "y": 8,
      "z": -6,
      "name": "Rock_Sandstone_Brick_Half",
      "rotation": 5
    },
    {
      "x": 9,
      "y": 1,
      "z": -5,
      "name": "Rock_Sandstone_Brick_Stairs",
      "rotation": 1
    },
    {
      "x": 9,
      "y": 1,
      "z": -4,
      "name": "Rock_Sandstone_Cobble_Stairs",
      "rotation": 1
    },
    {
      "x": 9,
      "y": 1,
      "z": -3,
      "name": "Rock_Sandstone_Cobble_Stairs",
      "rotation": 1
    },
    {
      "x": 9,
      "y": 1,
      "z": -2,
      "name": "Rock_Sandstone_Cobble_Stairs",
      "rotation": 1
    }
  ]
}