{
  "version": 8,
  "blockIdVersion": 11,
  "anchorX": -1,
  "anchorY": 0,
  "anchorZ": 0,
  "blocks": [
    {
      "x": -5,
      "y": -3,
      "z": -1,
      "name": "Soil_Pathway"
    },
    {
      "x": -5,
      "y": -2,
      "z": -1,
      "name": "Soil_Pathway"
    },
    {
      "x": -5,
      "y": -1,
      "z": -1,
      "name": "Soil_Pathway"
    },
    {
      "x": -5,
      "y": 0,
      "z": -1,
      "name": "Soil_Pathway"
    },
    {
      "x": -5,
      "y": -3,
      "z": 0,
      "name": "Soil_Pathway"
    },
    {
      "x": -5,
      "y": -2,
      "z": 0,
      "name": "Soil_Pathway"
    },
    {
      "x": -5,
      "y": -1,
      "z": 0,
      "name": "Soil_Pathway"
    },
    {
      "x": -5,
      "y": 0,
      "z": 0,
      "name": "Soil_Pathway"
    },
    {
      "x": -5,
      "y": -3,
      "z": 1,
      "name": "Soil_Pathway"
    },
    {
      "x": -5,
      "y": -2,
      "z": 1,
      "name": "Soil_Pathway"
    },
    {
      "x": -5,
      "y": -1,
      "z": 1,
      "name": "Soil_Pathway"
    },
    {
      "x": -5,
      "y": 0,
      "z": 1,
      "name": "Soil_Pathway"
    },
    {
      "x": -5,
      "y": -3,
      "z": 2,
      "name": "Soil_Pathway"
    },
    {
      "x": -5,
      "y": -2,
      "z": 2,
      "name": "Soil_Pathway"
    },
    {
      "x": -5,
      "y": -1,
      "z": 2,
      "name": "Soil_Pathway"
    },
    {
      "x": -5,
      "y": 0,
      "z": 2,
      "name": "Soil_Pathway"
    },
    {
      "x": -4,
      "y": -3,
      "z": -2,
      "name": "Soil_Pathway"
    },
    {
      "x": -4,
      "y": -2,
      "z": -2,
      "name": "Soil_Pathway"
    },
    {
      "x": -4,
      "y": -1,
      "z": -2,
      "name": "Soil_Pathway"
    },
    {
      "x": -4,
      "y": 0,
      "z": -2,
      "name": "Soil_Pathway"
    },
    {
      "x": -4,
      "y": -3,
      "z": -1,
      "name": "Soil_Pathway"
    },
    {
      "x": -4,
      "y": -2,
      "z": -1,
      "name": "Soil_Pathway"
    },
    {
      "x": -4,
      "y": -1,
      "z": -1,
      "name": "Soil_Pathway"
    },
    {
      "x": -4,
      "y": 0,
      "z": -1,
      "name": "Empty"
    },
    {
      "x": -4,
      "y": 1,
      "z": -1,
      "name": "Empty"
    },
    {
      "x": -4,
      "y": -3,
      "z": 0,
      "name": "Soil_Pathway"
    },
    {
      "x": -4,
      "y": -2,
      "z": 0,
      "name": "Soil_Pathway"
    },
    {
      "x": -4,
      "y": -1,
      "z": 0,
      "name": "Soil_Pathway"
    },
    {
      "x": -4,
      "y": 0,
      "z": 0,
      "name": "Empty"
    },
    {
      "x": -4,
      "y": 1,
      "z": 0,
      "name": "Empty"
    },
    {
      "x": -4,
      "y": -3,
      "z": 1,
      "name": "Soil_Pathway"
    },
    {
      "x": -4,
      "y": -2,
      "z": 1,
      "name": "Soil_Pathway"
    },
    {
      "x": -4,
      "y": -1,
      "z": 1,
      "name": "Soil_Pathway"
    },
    {
      "x": -4,
      "y": 0,
      "z": 1,
      "name": "Empty"
    },
    {
      "x": -4,
      "y": 1,
      "z": 1,
      "name": "Empty"
    },
    {
      "x": -4,
      "y": -3,
      "z": 2,
      "name": "Soil_Pathway"
    },
    {
      "x": -4,
      "y": -2,
      "z": 2,
      "name": "Soil_Pathway"
    },
    {
      "x": -4,
      "y": -1,
      "z": 2,
      "name": "Soil_Pathway"
    },
    {
      "x": -4,
      "y": 0,
      "z": 2,
      "name": "Soil_Pathway"
    },
    {
      "x": -4,
      "y": -3,
      "z": 3,
      "name": "Soil_Pathway"
    },
    {
      "x": -4,
      "y": -2,
      "z": 3,
      "name": "Soil_Pathway"
    },
    {
      "x": -4,
      "y": -1,
      "z": 3,
      "name": "Soil_Pathway"
    },
    {
      "x": -4,
      "y": 0,
      "z": 3,
      "name": "Soil_Pathway"
    },
    {
      "x": -3,
      "y": -3,
      "z": -2,
      "name": "Soil_Pathway"
    },
    {
      "x": -3,
      "y": -2,
      "z": -2,
      "name": "Soil_Pathway"
    },
    {
      "x": -3,
      "y": -1,
      "z": -2,
      "name": "Soil_Pathway"
    },
    {
      "x": -3,
      "y": 0,
      "z": -2,
      "name": "Empty"
    },
    {
      "x": -3,
      "y": 1,
      "z": -2,
      "name": "Empty"
    },
    {
      "x": -3,
      "y": -3,
      "z": -1,
      "name": "Soil_Pathway"
    },
    {
      "x": -3,
      "y": -2,
      "z": -1,
      "name": "Soil_Pathway"
    },
    {
      "x": -3,
      "y": -1,
      "z": -1,
      "name": "Soil_Pathway"
    },
    {
      "x": -3,
      "y": 0,
      "z": -1,
      "name": "Empty"
    },
    {
      "x": -3,
      "y": 1,
      "z": -1,
      "name": "Empty"
    },
    {
      "x": -3,
      "y": -3,
      "z": 0,
      "name": "Soil_Pathway"
    },
    {
      "x": -3,
      "y": -2,
      "z": 0,
      "name": "Soil_Pathway"
    },
    {
      "x": -3,
      "y": -1,
      "z": 0,
      "name": "Soil_Pathway"
    },
    {
      "x": -3,
      "y": 0,
      "z": 0,
      "name": "Furniture_Tavern_Barrel"
    },
    {
      "x": -3,
      "y": 1,
      "z": 0,
      "name": "Empty"
    },
    {
      "x": -3,
      "y": -3,
      "z": 1,
      "name": "Soil_Pathway"
    },
    {
      "x": -3,
      "y": -2,
      "z": 1,
      "name": "Soil_Pathway"
    },
    {
      "x": -3,
      "y": -1,
      "z": 1,
      "name": "Soil_Pathway"
    },
    {
      "x": -3,
      "y": 0,
      "z": 1,
      "name": "Empty"
    },
    {
      "x": -3,
      "y": 1,
      "z": 1,
      "name": "Empty"
    },
    {
      "x": -3,
      "y": -3,
      "z": 2,
      "name": "Soil_Pathway"
    },
    {
      "x": -3,
      "y": -2,
      "z": 2,
      "name": "Soil_Pathway"
    },
    {
      "x": -3,
      "y": -1,
      "z": 2,
      "name": "Soil_Pathway"
    },
    {
      "x": -3,
      "y": 0,
      "z": 2,
      "name": "Empty"
    },
    {
      "x": -3,
      "y": 1,
      "z": 2,
      "name": "Empty"
    },
    {
      "x": -3,
      "y": -3,
      "z": 3,
      "name": "Soil_Pathway"
    },
    {
      "x": -3,
      "y": -2,
      "z": 3,
      "name": "Soil_Pathway"
    },
    {
      "x": -3,
      "y": -1,
      "z": 3,
      "name": "Soil_Pathway"
    },
    {
      "x": -3,
      "y": 0,
      "z": 3,
      "name": "Empty"
    },
    {
      "x": -3,
      "y": 1,
      "z": 3,
      "name": "Empty"
    },
    {
      "x": -2,
      "y": -3,
      "z": -2,
      "name": "Soil_Pathway"
    },
    {
      "x": -2,
      "y": -2,
      "z": -2,
      "name": "Soil_Pathway"
    },
    {
      "x": -2,
      "y": -1,
      "z": -2,
      "name": "Soil_Pathway"
    },
    {
      "x": -2,
      "y": 0,
      "z": -2,
      "name": "Empty"
    },
    {
      "x": -2,
      "y": 1,
      "z": -2,
      "name": "Empty"
    },
    {
      "x": -2,
      "y": -3,
      "z": -1,
      "name": "Soil_Pathway"
    },
    {
      "x": -2,
      "y": -2,
      "z": -1,
      "name": "Soil_Dirt"
    },
    {
      "x": -2,
      "y": -1,
      "z": -1,
      "name": "Soil_Dirt"
    },
    {
      "x": -2,
      "y": 0,
      "z": -1,
      "name": "Cloth_Roof_White",
      "rotation": 3
    },
    {
      "x": -2,
      "y": 1,
      "z": -1,
      "name": "Empty"
    },
    {
      "x": -2,
      "y": -3,
      "z": 0,
      "name": "Soil_Pathway"
    },
    {
      "x": -2,
      "y": -2,
      "z": 0,
      "name": "Soil_Dirt"
    },
    {
      "x": -2,
      "y": -1,
      "z": 0,
      "name": "Soil_Dirt"
    },
    {
      "x": -2,
      "y": 0,
      "z": 0,
      "name": "Cloth_Roof_White",
      "rotation": 3
    },
    {
      "x": -2,
      "y": 1,
      "z": 0,
      "name": "Empty"
    },
    {
      "x": -2,
      "y": -3,
      "z": 1,
      "name": "Soil_Pathway"
    },
    {
      "x": -2,
      "y": -2,
      "z": 1,
      "name": "Soil_Dirt"
    },
    {
      "x": -2,
      "y": -1,
      "z": 1,
      "name": "Soil_Dirt"
    },
    {
      "x": -2,
      "y": 0,
      "z": 1,
      "name": "Cloth_Roof_White",
      "rotation": 3
    },
    {
      "x": -2,
      "y": 1,
      "z": 1,
      "name": "Empty"
    },
    {
      "x": -2,
      "y": -3,
      "z": 2,
      "name": "Soil_Pathway"
    },
    {
      "x": -2,
      "y": -2,
      "z": 2,
      "name": "Soil_Dirt"
    },
    {
      "x": -2,
      "y": -1,
      "z": 2,
      "name": "Soil_Dirt"
    },
    {
      "x": -2,
      "y": 0,
      "z": 2,
      "name": "Cloth_Roof_White",
      "rotation": 3
    },
    {
      "x": -2,
      "y": 1,
      "z": 2,
      "name": "Empty"
    },
    {
      "x": -2,
      "y": -3,
      "z": 3,
      "name": "Soil_Pathway"
    },
    {
      "x": -2,
      "y": -2,
      "z": 3,
      "name": "Soil_Pathway"
    },
    {
      "x": -2,
      "y": -1,
      "z": 3,
      "name": "Soil_Pathway"
    },
    {
      "x": -2,
      "y": 0,
      "z": 3,
      "name": "Empty"
    },
    {
      "x": -2,
      "y": 1,
      "z": 3,
      "name": "Empty"
    },
    {
      "x": -2,
      "y": -3,
      "z": 4,
      "name": "Soil_Pathway"
    },
    {
      "x": -2,
      "y": -2,
      "z": 4,
      "name": "Soil_Pathway"
    },
    {
      "x": -2,
      "y": -1,
      "z": 4,
      "name": "Soil_Pathway"
    },
    {
      "x": -2,
      "y": 0,
      "z": 4,
      "name": "Empty"
    },
    {
      "x": -2,
      "y": 1,
      "z": 4,
      "name": "Empty"
    },
    {
      "x": -1,
      "y": -3,
      "z": -3,
      "name": "Soil_Pathway"
    },
    {
      "x": -1,
      "y": -2,
      "z": -3,
      "name": "Soil_Pathway"
    },
    {
      "x": -1,
      "y": -1,
      "z": -3,
      "name": "Soil_Pathway"
    },
    {
      "x": -1,
      "y": 0,
      "z": -3,
      "name": "Soil_Pathway"
    },
    {
      "x": -1,
      "y": -3,
      "z": -2,
      "name": "Soil_Pathway"
    },
    {
      "x": -1,
      "y": -2,
      "z": -2,
      "name": "Soil_Pathway"
    },
    {
      "x": -1,
      "y": -1,
      "z": -2,
      "name": "Soil_Pathway"
    },
    {
      "x": -1,
      "y": 0,
      "z": -2,
      "name": "Empty"
    },
    {
      "x": -1,
      "y": 1,
      "z": -2,
      "name": "Empty"
    },
    {
      "x": -1,
      "y": -3,
      "z": -1,
      "name": "Soil_Pathway"
    },
    {
      "x": -1,
      "y": -2,
      "z": -1,
      "name": "Soil_Dirt"
    },
    {
      "x": -1,
      "y": -1,
      "z": -1,
      "name": "Soil_Dirt"
    },
    {
      "x": -1,
      "y": 0,
      "z": -1,
      "name": "Empty"
    },
    {
      "x": -1,
      "y": 1,
      "z": -1,
      "name": "Cloth_Roof_White",
      "rotation": 3
    },
    {
      "x": -1,
      "y": -3,
      "z": 0,
      "name": "Soil_Pathway"
    },
    {
      "x": -1,
      "y": -2,
      "z": 0,
      "name": "Soil_Dirt"
    },
    {
      "x": -1,
      "y": -1,
      "z": 0,
      "name": "Soil_Dirt"
    },
    {
      "x": -1,
      "y": 0,
      "z": 0,
      "name": "Furniture_Crude_Bed",
      "components": {
        "Components": {
          "PlacedByInteraction": {
            "WhoPlacedUuid": {
              "$binary": "JMPNY5cWR9+IOfPEr8/h7w==",
              "$type": "04"
            }
          },
          "RespawnBlock": {}
        }
      }
    },
    {
      "x": -1,
      "y": 1,
      "z": 0,
      "name": "Cloth_Roof_White",
      "rotation": 3
    },
    {
      "x": -1,
      "y": -3,
      "z": 1,
      "name": "Soil_Pathway"
    },
    {
      "x": -1,
      "y": -2,
      "z": 1,
      "name": "Soil_Dirt"
    },
    {
      "x": -1,
      "y": -1,
      "z": 1,
      "name": "Soil_Dirt"
    },
    {
      "x": -1,
      "y": 0,
      "z": 1,
      "name": "Furniture_Crude_Bed",
      "filler": 32
    },
    {
      "x": -1,
      "y": 1,
      "z": 1,
      "name": "Cloth_Roof_White",
      "rotation": 3
    },
    {
      "x": -1,
      "y": -3,
      "z": 2,
      "name": "Soil_Pathway"
    },
    {
      "x": -1,
      "y": -2,
      "z": 2,
      "name": "Soil_Dirt"
    },
    {
      "x": -1,
      "y": -1,
      "z": 2,
      "name": "Soil_Dirt"
    },
    {
      "x": -1,
      "y": 0,
      "z": 2,
      "name": "Empty"
    },
    {
      "x": -1,
      "y": 1,
      "z": 2,
      "name": "Cloth_Roof_White",
      "rotation": 3
    },
    {
      "x": -1,
      "y": -3,
      "z": 3,
      "name": "Soil_Pathway"
    },
    {
      "x": -1,
      "y": -2,
      "z": 3,
      "name": "Soil_Pathway"
    },
    {
      "x": -1,
      "y": -1,
      "z": 3,
      "name": "Soil_Pathway"
    },
    {
      "x": -1,
      "y": 0,
      "z": 3,
      "name": "Empty"
    },
    {
      "x": -1,
      "y": 1,
      "z": 3,
      "name": "Empty"
    },
    {
      "x": -1,
      "y": -3,
      "z": 4,
      "name": "Soil_Pathway"
    },
    {
      "x": -1,
      "y": -2,
      "z": 4,
      "name": "Soil_Pathway"
    },
    {
      "x": -1,
      "y": -1,
      "z": 4,
      "name": "Soil_Pathway"
    },
    {
      "x": -1,
      "y": 0,
      "z": 4,
      "name": "Empty"
    },
    {
      "x": -1,
      "y": 1,
      "z": 4,
      "name": "Empty"
    },
    {
      "x": 0,
      "y": -3,
      "z": -3,
      "name": "Soil_Pathway"
    },
    {
      "x": 0,
      "y": -2,
      "z": -3,
      "name": "Soil_Pathway"
    },
    {
      "x": 0,
      "y": -1,
      "z": -3,
      "name": "Soil_Pathway"
    },
    {
      "x": 0,
      "y": 0,
      "z": -3,
      "name": "Soil_Pathway"
    },
    {
      "x": 0,
      "y": -3,
      "z": -2,
      "name": "Soil_Pathway"
    },
    {
      "x": 0,
      "y": -2,
      "z": -2,
      "name": "Soil_Pathway"
    },
    {
      "x": 0,
      "y": -1,
      "z": -2,
      "name": "Soil_Pathway"
    },
    {
      "x": 0,
      "y": 0,
      "z": -2,
      "name": "Empty"
    },
    {
      "x": 0,
      "y": 1,
      "z": -2,
      "name": "Empty"
    },
    {
      "x": 0,
      "y": -3,
      "z": -1,
      "name": "Soil_Pathway"
    },
    {
      "x": 0,
      "y": -2,
      "z": -1,
      "name": "Soil_Dirt"
    },
    {
      "x": 0,
      "y": -1,
      "z": -1,
      "name": "Soil_Dirt"
    },
    {
      "x": 0,
      "y": 0,
      "z": -1,
      "name": "Empty"
    },
    {
      "x": 0,
      "y": 1,
      "z": -1,
      "name": "Cloth_Roof_White",
      "rotation": 1
    },
    {
      "x": 0,
      "y": -3,
      "z": 0,
      "name": "Soil_Pathway"
    },
    {
      "x": 0,
      "y": -2,
      "z": 0,
      "name": "Soil_Dirt"
    },
    {
      "x": 0,
      "y": -1,
      "z": 0,
      "name": "Soil_Dirt"
    },
    {
      "x": 0,
      "y": 0,
      "z": 0,
      "name": "Furniture_Ancient_Sack",
      "rotation": 2
    },
    {
      "x": 0,
      "y": 1,
      "z": 0,
      "name": "Cloth_Roof_White",
      "rotation": 1
    },
    {
      "x": 0,
      "y": -3,
      "z": 1,
      "name": "Soil_Pathway"
    },
    {
      "x": 0,
      "y": -2,
      "z": 1,
      "name": "Soil_Dirt"
    },
    {
      "x": 0,
      "y": -1,
      "z": 1,
      "name": "Soil_Dirt"
    },
    {
      "x": 0,
      "y": 0,
      "z": 1,
      "name": "Empty"
    },
    {
      "x": 0,
      "y": 1,
      "z": 1,
      "name": "Cloth_Roof_White",
      "rotation": 1
    },
    {
      "x": 0,
      "y": -3,
      "z": 2,
      "name": "Soil_Pathway"
    },
    {
      "x": 0,
      "y": -2,
      "z": 2,
      "name": "Soil_Dirt"
    },
    {
      "x": 0,
      "y": -1,
      "z": 2,
      "name": "Soil_Dirt"
    },
    {
      "x": 0,
      "y": 0,
      "z": 2,
      "name": "Empty"
    },
    {
      "x": 0,
      "y": 1,
      "z": 2,
      "name": "Cloth_Roof_White",
      "rotation": 1
    },
    {
      "x": 0,
      "y": -3,
      "z": 3,
      "name": "Soil_Pathway"
    },
    {
      "x": 0,
      "y": -2,
      "z": 3,
      "name": "Soil_Pathway"
    },
    {
      "x": 0,
      "y": -1,
      "z": 3,
      "name": "Soil_Pathway"
    },
    {
      "x": 0,
      "y": 0,
      "z": 3,
      "name": "Empty"
    },
    {
      "x": 0,
      "y": 1,
      "z": 3,
      "name": "Empty"
    },
    {
      "x": 0,
      "y": -3,
      "z": 4,
      "name": "Soil_Pathway"
    },
    {
      "x": 0,
      "y": -2,
      "z": 4,
      "name": "Soil_Pathway"
    },
    {
      "x": 0,
      "y": -1,
      "z": 4,
      "name": "Soil_Pathway"
    },
    {
      "x": 0,
      "y": 0,
      "z": 4,
      "name": "Empty"
    },
    {
      "x": 0,
      "y": 1,
      "z": 4,
      "name": "Empty"
    },
    {
      "x": 0,
      "y": -3,
      "z": 5,
      "name": "Soil_Pathway"
    },
    {
      "x": 0,
      "y": -2,
      "z": 5,
      "name": "Soil_Pathway"
    },
    {
      "x": 0,
      "y": -1,
      "z": 5,
      "name": "Soil_Pathway"
    },
    {
      "x": 0,
      "y": 0,
      "z": 5,
      "name": "Empty"
    },
    {
      "x": 0,
      "y": 1,
      "z": 5,
      "name": "Empty"
    },
    {
      "x": 1,
      "y": -3,
      "z": -2,
      "name": "Soil_Pathway"
    },
    {
      "x": 1,
      "y": -2,
      "z": -2,
      "name": "Soil_Pathway"
    },
    {
      "x": 1,
      "y": -1,
      "z": -2,
      "name": "Soil_Pathway"
    },
    {
      "x": 1,
      "y": 0,
      "z": -2,
      "name": "Empty"
    },
    {
      "x": 1,
      "y": 1,
      "z": -2,
      "name": "Empty"
    },
    {
      "x": 1,
      "y": -3,
      "z": -1,
      "name": "Soil_Pathway"
    },
    {
      "x": 1,
      "y": -2,
      "z": -1,
      "name": "Soil_Dirt"
    },
    {
      "x": 1,
      "y": -1,
      "z": -1,
      "name": "Soil_Dirt"
    },
    {
      "x": 1,
      "y": 0,
      "z": -1,
      "name": "Cloth_Roof_White",
      "rotation": 1
    },
    {
      "x": 1,
      "y": 1,
      "z": -1,
      "name": "Empty"
    },
    {
      "x": 1,
      "y": -3,
      "z": 0,
      "name": "Soil_Pathway"
    },
    {
      "x": 1,
      "y": -2,
      "z": 0,
      "name": "Soil_Dirt"
    },
    {
      "x": 1,
      "y": -1,
      "z": 0,
      "name": "Soil_Dirt"
    },
    {
      "x": 1,
      "y": 0,
      "z": 0,
      "name": "Cloth_Roof_White",
      "rotation": 1
    },
    {
      "x": 1,
      "y": 1,
      "z": 0,
      "name": "Empty"
    },
    {
      "x": 1,
      "y": -3,
      "z": 1,
      "name": "Soil_Pathway"
    },
    {
      "x": 1,
      "y": -2,
      "z": 1,
      "name": "Soil_Dirt"
    },
    {
      "x": 1,
      "y": -1,
      "z": 1,
      "name": "Soil_Dirt"
    },
    {
      "x": 1,
      "y": 0,
      "z": 1,
      "name": "Cloth_Roof_White",
      "rotation": 1
    },
    {
      "x": 1,
      "y": 1,
      "z": 1,
      "name": "Empty"
    },
    {
      "x": 1,
      "y": -3,
      "z": 2,
      "name": "Soil_Pathway"
    },
    {
      "x": 1,
      "y": -2,
      "z": 2,
      "name": "Soil_Dirt"
    },
    {
      "x": 1,
      "y": -1,
      "z": 2,
      "name": "Soil_Dirt"
    },
    {
      "x": 1,
      "y": 0,
      "z": 2,
      "name": "Cloth_Roof_White",
      "rotation": 1
    },
    {
      "x": 1,
      "y": 1,
      "z": 2,
      "name": "Empty"
    },
    {
      "x": 1,
      "y": -3,
      "z": 3,
      "name": "Soil_Pathway"
    },
    {
      "x": 1,
      "y": -2,
      "z": 3,
      "name": "Soil_Pathway"
    },
    {
      "x": 1,
      "y": -1,
      "z": 3,
      "name": "Soil_Pathway"
    },
    {
      "x": 1,
      "y": 0,
      "z": 3,
      "name": "Empty"
    },
    {
      "x": 1,
      "y": 1,
      "z": 3,
      "name": "Empty"
    },
    {
      "x": 1,
      "y": -3,
      "z": 4,
      "name": "Soil_Pathway"
    },
    {
      "x": 1,
      "y": -2,
      "z": 4,
      "name": "Soil_Pathway"
    },
    {
      "x": 1,
      "y": -1,
      "z": 4,
      "name": "Soil_Pathway"
    },
    {
      "x": 1,
      "y": 0,
      "z": 4,
      "name": "Empty"
    },
    {
      "x": 1,
      "y": 1,
      "z": 4,
      "name": "Empty"
    },
    {
      "x": 2,
      "y": -3,
      "z": -2,
      "name": "Soil_Pathway"
    },
    {
      "x": 2,
      "y": -2,
      "z": -2,
      "name": "Soil_Pathway"
    },
    {
      "x": 2,
      "y": -1,
      "z": -2,
      "name": "Soil_Pathway"
    },
    {
      "x": 2,
      "y": 0,
      "z": -2,
      "name": "Empty"
    },
    {
      "x": 2,
      "y": 1,
      "z": -2,
      "name": "Empty"
    },
    {
      "x": 2,
      "y": -3,
      "z": -1,
      "name": "Soil_Pathway"
    },
    {
      "x": 2,
      "y": -2,
      "z": -1,
      "name": "Soil_Pathway"
    },
    {
      "x": 2,
      "y": -1,
      "z": -1,
      "name": "Soil_Pathway"
    },
    {
      "x": 2,
      "y": 0,
      "z": -1,
      "name": "Empty"
    },
    {
      "x": 2,
      "y": 1,
      "z": -1,
      "name": "Empty"
    },
    {
      "x": 2,
      "y": -3,
      "z": 0,
      "name": "Soil_Pathway"
    },
    {
      "x": 2,
      "y": -2,
      "z": 0,
      "name": "Soil_Pathway"
    },
    {
      "x": 2,
      "y": -1,
      "z": 0,
      "name": "Soil_Pathway"
    },
    {
      "x": 2,
      "y": 0,
      "z": 0,
      "name": "Empty"
    },
    {
      "x": 2,
      "y": 1,
      "z": 0,
      "name": "Empty"
    },
    {
      "x": 2,
      "y": -3,
      "z": 1,
      "name": "Soil_Pathway"
    },
    {
      "x": 2,
      "y": -2,
      "z": 1,
      "name": "Soil_Pathway"
    },
    {
      "x": 2,
      "y": -1,
      "z": 1,
      "name": "Soil_Pathway"
    },
    {
      "x": 2,
      "y": 0,
      "z": 1,
      "name": "Empty"
    },
    {
      "x": 2,
      "y": 1,
      "z": 1,
      "name": "Empty"
    },
    {
      "x": 2,
      "y": -3,
      "z": 2,
      "name": "Soil_Pathway"
    },
    {
      "x": 2,
      "y": -2,
      "z": 2,
      "name": "Soil_Pathway"
    },
    {
      "x": 2,
      "y": -1,
      "z": 2,
      "name": "Soil_Pathway"
    },
    {
      "x": 2,
      "y": 0,
      "z": 2,
      "name": "Empty"
    },
    {
      "x": 2,
      "y": 1,
      "z": 2,
      "name": "Empty"
    },
    {
      "x": 2,
      "y": -3,
      "z": 3,
      "name": "Soil_Pathway"
    },
    {
      "x": 2,
      "y": -2,
      "z": 3,
      "name": "Soil_Pathway"
    },
    {
      "x": 2,
      "y": -1,
      "z": 3,
      "name": "Soil_Pathway"
    },
    {
      "x": 2,
      "y": 0,
      "z": 3,
      "name": "Empty"
    },
    {
      "x": 2,
      "y": 1,
      "z": 3,
      "name": "Empty"
    },
    {
      "x": 3,
      "y": -3,
      "z": -1,
      "name": "Soil_Pathway"
    },
    {
      "x": 3,
      "y": -2,
      "z": -1,
      "name": "Soil_Pathway"
    },
    {
      "x": 3,
      "y": -1,
      "z": -1,
      "name": "Soil_Pathway"
    },
    {
      "x": 3,
      "y": 0,
      "z": -1,
      "name": "Soil_Pathway"
    },
    {
      "x": 3,
      "y": -3,
      "z": 0,
      "name": "Soil_Pathway"
    },
    {
      "x": 3,
      "y": -2,
      "z": 0,
      "name": "Soil_Pathway"
    },
    {
      "x": 3,
      "y": -1,
      "z": 0,
      "name": "Soil_Pathway"
    },
    {
      "x": 3,
      "y": 0,
      "z": 0,
      "name": "Soil_Pathway"
    }
  ]
}