{"anchorX":-3,"anchorY":0,"anchorZ":-1,"blockIdVersion":11,"blocks":[{"name":"Rock_Sandstone_Red_Brick","rotation":3,"x":-4,"y":0,"z":-1},{"name":"Plant_Seaweed_Grass","support":15,"x":-4,"y":1,"z":-1},{"name":"Rock_Sandstone_Red_Cobble","rotation":3,"x":-4,"y":0,"z":0},{"name":"Rock_Sandstone_Red_Brick","rotation":3,"x":-4,"y":1,"z":0},{"name":"Rock_Sandstone_Red_Brick_Stairs","rotation":3,"x":-4,"y":2,"z":0},{"name":"Rock_Sandstone_Red_Brick","rotation":3,"x":-3,"y":0,"z":-1},{"name":"Rock_Sandstone_Red_Brick","rotation":3,"x":-3,"y":1,"z":-1},{"name":"Plant_Seaweed_Grass_Tall","support":15,"x":-3,"y":2,"z":-1},{"filler":1024,"name":"Plant_Seaweed_Grass_Tall","x":-3,"y":3,"z":-1},{"name":"Rock_Sandstone_Red_Cobble","rotation":3,"x":-3,"y":0,"z":0},{"name":"Rock_Sandstone_Red_Brick","rotation":3,"x":-3,"y":1,"z":0},{"name":"Rock_Sandstone_Red_Brick","rotation":3,"x":-3,"y":2,"z":0},{"name":"Plant_Seaweed_Grass_Tall","support":15,"x":-3,"y":3,"z":0},{"filler":1024,"name":"Plant_Seaweed_Grass_Tall","x":-3,"y":4,"z":0},{"name":"Rock_Sandstone_Red_Cobble","rotation":3,"x":-2,"y":0,"z":-3},{"name":"Rock_Sandstone_Red_Brick","rotation":3,"x":-2,"y":1,"z":-3},{"name":"Plant_Seaweed_Grass","support":15,"x":-2,"y":2,"z":-3},{"name":"Rock_Sandstone_Red_Brick","rotation":3,"x":-2,"y":0,"z":-2},{"name":"Rock_Sandstone_Red_Brick","rotation":3,"x":-2,"y":1,"z":-2},{"name":"Rock_Sandstone_Red_Brick","rotation":3,"x":-2,"y":2,"z":-2},{"name":"Plant_Seaweed_Grass","support":15,"x":-2,"y":3,"z":-2},{"name":"Rock_Sandstone_Brick","rotation":3,"x":-2,"y":0,"z":-1},{"name":"Rock_Sandstone_Brick","rotation":3,"x":-2,"y":1,"z":-1},{"name":"Rock_Sandstone_Brick","rotation":3,"x":-2,"y":2,"z":-1},{"name":"Rock_Sandstone_Brick","rotation":3,"x":-2,"y":3,"z":-1},{"name":"Rock_Sandstone_Brick_Ornate","rotation":3,"x":-2,"y":4,"z":-1},{"name":"Plant_Seaweed_Grass","support":15,"x":-2,"y":5,"z":-1},{"name":"Rock_Sandstone_Brick","rotation":3,"x":-2,"y":0,"z":0},{"name":"Rock_Sandstone_Brick","rotation":3,"x":-2,"y":1,"z":0},{"name":"Rock_Sandstone_Brick","rotation":3,"x":-2,"y":2,"z":0},{"name":"Rock_Sandstone_Brick","rotation":3,"x":-2,"y":3,"z":0},{"name":"Rock_Sandstone_Brick_Ornate","rotation":3,"x":-2,"y":4,"z":0},{"name":"Rock_Sandstone_Brick_Half","x":-2,"y":5,"z":0},{"name":"Rock_Sandstone_Brick","rotation":3,"x":-2,"y":0,"z":1},{"name":"Rock_Sandstone_Cobble","rotation":3,"x":-2,"y":1,"z":1},{"name":"Rock_Sandstone_Brick","rotation":3,"x":-2,"y":2,"z":1},{"name":"Rock_Sandstone_Cobble","rotation":3,"x":-2,"y":3,"z":1},{"name":"Rock_Sandstone_Brick_Ornate","rotation":3,"x":-2,"y":4,"z":1},{"name":"Rock_Sandstone_Brick_Stairs","rotation":3,"x":-2,"y":5,"z":1},{"name":"Rock_Sandstone_Brick_Ornate","rotation":3,"x":-2,"y":4,"z":2},{"name":"Rock_Sandstone_Brick_Stairs","rotation":3,"x":-2,"y":5,"z":2},{"name":"Rock_Sandstone_Red_Brick","rotation":3,"x":-1,"y":0,"z":-3},{"name":"Rock_Sandstone_Red_Brick","rotation":3,"x":-1,"y":1,"z":-3},{"name":"Rock_Sandstone_Red_Brick_Stairs","rotation":2,"x":-1,"y":2,"z":-3},{"name":"Rock_Sandstone_Red_Brick","rotation":3,"x":-1,"y":0,"z":-2},{"name":"Rock_Sandstone_Red_Brick","rotation":3,"x":-1,"y":1,"z":-2},{"name":"Rock_Sandstone_Red_Brick","rotation":3,"x":-1,"y":2,"z":-2},{"name":"Plant_Seaweed_Grass","support":15,"x":-1,"y":3,"z":-2},{"name":"Rock_Sandstone_Brick","rotation":3,"x":-1,"y":0,"z":-1},{"name":"Rock_Sandstone_Brick","rotation":3,"x":-1,"y":1,"z":-1},{"name":"Rock_Sandstone_Brick","rotation":3,"x":-1,"y":2,"z":-1},{"name":"Rock_Sandstone_Brick","rotation":3,"x":-1,"y":3,"z":-1},{"name":"Rock_Sandstone_Brick_Ornate","rotation":3,"x":-1,"y":4,"z":-1},{"name":"Rock_Sandstone_Brick_Half","x":-1,"y":5,"z":-1},{"name":"Rock_Sandstone_Brick","rotation":3,"x":-1,"y":0,"z":0},{"name":"Rock_Sandstone_Brick","rotation":3,"x":-1,"y":1,"z":0},{"name":"Rock_Sandstone_Brick","rotation":3,"x":-1,"y":2,"z":0},{"name":"Rock_Sandstone_Brick","rotation":3,"x":-1,"y":3,"z":0},{"name":"Rock_Sandstone_Brick","rotation":3,"x":-1,"y":4,"z":0},{"name":"Rock_Sandstone_Cobble","rotation":3,"x":-1,"y":5,"z":0},{"name":"Rock_Sandstone_Cobble","rotation":3,"x":-1,"y":6,"z":0},{"name":"Plant_Coral_Bush_Green","x":-1,"y":7,"z":0},{"name":"Rock_Sandstone_Brick","rotation":3,"x":-1,"y":0,"z":1},{"name":"Rock_Sandstone_Brick","rotation":3,"x":-1,"y":1,"z":1},{"name":"Rock_Sandstone_Brick","rotation":3,"x":-1,"y":2,"z":1},{"name":"Rock_Sandstone_Red_Brick","rotation":3,"x":-1,"y":3,"z":1},{"name":"Rock_Sandstone_Brick","rotation":3,"x":-1,"y":4,"z":1},{"name":"Rock_Sandstone_Cobble","rotation":3,"x":-1,"y":5,"z":1},{"name":"Rock_Sandstone_Cobble","rotation":3,"x":-1,"y":6,"z":1},{"name":"Rock_Sandstone_Cobble","rotation":3,"x":-1,"y":7,"z":1},{"name":"Plant_Coral_Bush_Green","x":-1,"y":8,"z":1},{"name":"Rock_Sandstone_Red_Brick","rotation":3,"x":-1,"y":3,"z":2},{"name":"Rock_Sandstone_Brick","rotation":3,"x":-1,"y":4,"z":2},{"name":"Rock_Sandstone_Cobble","rotation":3,"x":-1,"y":5,"z":2},{"name":"Rock_Sandstone_Cobble","rotation":3,"x":-1,"y":6,"z":2},{"name":"Rock_Sandstone_Cobble","rotation":3,"x":-1,"y":7,"z":2},{"name":"Plant_Seaweed_Grass","support":15,"x":-1,"y":8,"z":2},{"name":"Rock_Sandstone_Cobble_Half","rotation":8,"x":-1,"y":5,"z":3},{"name":"Rock_Sandstone_Cobble","x":-1,"y":6,"z":3},{"name":"Rock_Sandstone_Cobble","x":-1,"y":7,"z":3},{"name":"Plant_Coral_Bush_Green","x":-1,"y":8,"z":3},{"name":"Rock_Sandstone_Cobble_Half","rotation":4,"x":-1,"y":6,"z":4},{"name":"Rock_Sandstone_Cobble_Half","x":0,"y":0,"z":-2},{"name":"Rock_Sandstone_Cobble","rotation":3,"x":0,"y":0,"z":-1},{"name":"Rock_Sandstone_Cobble","rotation":3,"x":0,"y":1,"z":-1},{"name":"Rock_Sandstone_Cobble","rotation":3,"x":0,"y":2,"z":-1},{"name":"Rock_Sandstone_Cobble","rotation":3,"x":0,"y":3,"z":-1},{"name":"Rock_Sandstone_Brick_Ornate","rotation":3,"x":0,"y":4,"z":-1},{"name":"Rock_Sandstone_Brick_Stairs","rotation":2,"x":0,"y":5,"z":-1},{"name":"Rock_Sandstone_Brick","rotation":3,"x":0,"y":0,"z":0},{"name":"Rock_Sandstone_Brick","rotation":3,"x":0,"y":1,"z":0},{"name":"Rock_Sandstone_Brick","rotation":3,"x":0,"y":2,"z":0},{"name":"Rock_Sandstone_Brick","rotation":3,"x":0,"y":3,"z":0},{"name":"Rock_Sandstone_Brick","rotation":3,"x":0,"y":4,"z":0},{"name":"Rock_Sandstone_Cobble","rotation":3,"x":0,"y":5,"z":0},{"name":"Rock_Sandstone_Cobble","x":0,"y":6,"z":0},{"name":"Rock_Sandstone_Cobble","x":0,"y":7,"z":0},{"name":"Plant_Coral_Bush_Green","x":0,"y":8,"z":0},{"name":"Rock_Sandstone_Brick","rotation":3,"x":0,"y":1,"z":1},{"name":"Rock_Sandstone_Brick","rotation":3,"x":0,"y":2,"z":1},{"name":"Soil_Dirt","x":0,"y":3,"z":1},{"name":"Soil_Grass_Full","rotation":3,"x":0,"y":4,"z":1},{"name":"Rubble_Sandstone","support":15,"x":0,"y":5,"z":1},{"name":"Rock_Sandstone_Red_Brick","x":0,"y":8,"z":1},{"name":"Plant_Coral_Bush_Green","x":0,"y":9,"z":1},{"name":"Rock_Sandstone_Red_Brick","x":0,"y":8,"z":2},{"name":"Rock_Sandstone_Red_Brick","x":0,"y":9,"z":2},{"name":"Plant_Coral_Bush_Green","x":0,"y":10,"z":2},{"name":"Rock_Sandstone","x":1,"y":0,"z":-2},{"name":"Plant_Seaweed_Grass","support":15,"x":1,"y":1,"z":-2},{"name":"Rock_Sandstone_Cobble","rotation":3,"x":1,"y":0,"z":-1},{"name":"Rock_Sandstone_Cobble","rotation":3,"x":1,"y":1,"z":-1},{"name":"Rock_Sandstone_Cobble","rotation":3,"x":1,"y":2,"z":-1},{"name":"Rock_Sandstone_Cobble","rotation":3,"x":1,"y":3,"z":-1},{"name":"Plant_Coral_Bush_Green","x":1,"y":4,"z":-1},{"name":"Rock_Sandstone_Brick","rotation":3,"x":1,"y":0,"z":0},{"name":"Rock_Sandstone_Brick","rotation":3,"x":1,"y":1,"z":0},{"name":"Rock_Sandstone_Brick","rotation":3,"x":1,"y":2,"z":0},{"name":"Rock_Sandstone_Brick","rotation":3,"x":1,"y":3,"z":0},{"name":"Plant_Coral_Bush_Green","x":1,"y":4,"z":0},{"name":"Rock_Sandstone_Cobble","rotation":3,"x":1,"y":5,"z":0},{"name":"Rock_Sandstone_Cobble","rotation":3,"x":1,"y":6,"z":0},{"name":"Rock_Sandstone_Cobble","rotation":3,"x":1,"y":7,"z":0},{"name":"Rock_Sandstone_Cobble","x":1,"y":8,"z":0},{"name":"Plant_Coral_Bush_Green","x":1,"y":9,"z":0},{"name":"Rock_Sandstone_Brick","rotation":3,"x":1,"y":2,"z":1},{"name":"Soil_Grass_Full","rotation":3,"x":1,"y":3,"z":1},{"name":"Plant_Coral_Bush_Green","x":1,"y":4,"z":1},{"name":"Rock_Sandstone_Red_Brick","x":1,"y":8,"z":1},{"name":"Rock_Sandstone_Red_Brick","x":1,"y":9,"z":1},{"name":"Plant_Seaweed_Grass","support":15,"x":1,"y":10,"z":1},{"name":"Rock_Sandstone_Cobble_Half","rotation":8,"x":2,"y":6,"z":0},{"name":"Rock_Sandstone_Cobble","x":2,"y":7,"z":0},{"name":"Rock_Sandstone_Cobble_Half","x":2,"y":8,"z":0},{"name":"Rock_Sandstone_Cobble","x":3,"y":7,"z":0},{"name":"Rock_Sandstone_Cobble_Half","x":3,"y":8,"z":0},{"name":"Rock_Sandstone_Cobble_Half","rotation":5,"x":4,"y":7,"z":0}],"fluids":[{"level":1,"name":"Water_Source","x":-4,"y":0,"z":-1},{"level":1,"name":"Water_Source","x":-4,"y":1,"z":-1},{"level":1,"name":"Water_Source","x":-4,"y":0,"z":0},{"level":1,"name":"Water_Source","x":-4,"y":1,"z":0},{"level":1,"name":"Water_Source","x":-4,"y":2,"z":0},{"level":1,"name":"Water_Source","x":-3,"y":0,"z":-1},{"level":1,"name":"Water_Source","x":-3,"y":1,"z":-1},{"level":1,"name":"Water_Source","x":-3,"y":2,"z":-1},{"level":1,"name":"Water_Source","x":-3,"y":3,"z":-1},{"level":1,"name":"Water_Source","x":-3,"y":0,"z":0},{"level":1,"name":"Water_Source","x":-3,"y":1,"z":0},{"level":1,"name":"Water_Source","x":-3,"y":2,"z":0},{"level":1,"name":"Water_Source","x":-3,"y":3,"z":0},{"level":1,"name":"Water_Source","x":-3,"y":4,"z":0},{"level":1,"name":"Water_Source","x":-2,"y":0,"z":-3},{"level":1,"name":"Water_Source","x":-2,"y":1,"z":-3},{"level":1,"name":"Water_Source","x":-2,"y":2,"z":-3},{"level":1,"name":"Water_Source","x":-2,"y":0,"z":-2},{"level":1,"name":"Water_Source","x":-2,"y":1,"z":-2},{"level":1,"name":"Water_Source","x":-2,"y":2,"z":-2},{"level":1,"name":"Water_Source","x":-2,"y":3,"z":-2},{"level":1,"name":"Water_Source","x":-2,"y":0,"z":-1},{"level":1,"name":"Water_Source","x":-2,"y":1,"z":-1},{"level":1,"name":"Water_Source","x":-2,"y":2,"z":-1},{"level":1,"name":"Water_Source","x":-2,"y":3,"z":-1},{"level":1,"name":"Water_Source","x":-2,"y":4,"z":-1},{"level":1,"name":"Water_Source","x":-2,"y":5,"z":-1},{"level":1,"name":"Water_Source","x":-2,"y":0,"z":0},{"level":1,"name":"Water_Source","x":-2,"y":1,"z":0},{"level":1,"name":"Water_Source","x":-2,"y":2,"z":0},{"level":1,"name":"Water_Source","x":-2,"y":3,"z":0},{"level":1,"name":"Water_Source","x":-2,"y":4,"z":0},{"level":1,"name":"Water_Source","x":-2,"y":5,"z":0},{"level":1,"name":"Water_Source","x":-2,"y":0,"z":1},{"level":1,"name":"Water_Source","x":-2,"y":1,"z":1},{"level":1,"name":"Water_Source","x":-2,"y":2,"z":1},{"level":1,"name":"Water_Source","x":-2,"y":3,"z":1},{"level":1,"name":"Water_Source","x":-2,"y":4,"z":1},{"level":1,"name":"Water_Source","x":-2,"y":5,"z":1},{"level":1,"name":"Water_Source","x":-2,"y":4,"z":2},{"level":1,"name":"Water_Source","x":-2,"y":5,"z":2},{"level":1,"name":"Water_Source","x":-1,"y":0,"z":-3},{"level":1,"name":"Water_Source","x":-1,"y":1,"z":-3},{"level":1,"name":"Water_Source","x":-1,"y":2,"z":-3},{"level":1,"name":"Water_Source","x":-1,"y":0,"z":-2},{"level":1,"name":"Water_Source","x":-1,"y":1,"z":-2},{"level":1,"name":"Water_Source","x":-1,"y":2,"z":-2},{"level":1,"name":"Water_Source","x":-1,"y":3,"z":-2},{"level":1,"name":"Water_Source","x":-1,"y":0,"z":-1},{"level":1,"name":"Water_Source","x":-1,"y":1,"z":-1},{"level":1,"name":"Water_Source","x":-1,"y":2,"z":-1},{"level":1,"name":"Water_Source","x":-1,"y":3,"z":-1},{"level":1,"name":"Water_Source","x":-1,"y":4,"z":-1},{"level":1,"name":"Water_Source","x":-1,"y":5,"z":-1},{"level":1,"name":"Water_Source","x":-1,"y":0,"z":0},{"level":1,"name":"Water_Source","x":-1,"y":1,"z":0},{"level":1,"name":"Water_Source","x":-1,"y":2,"z":0},{"level":1,"name":"Water_Source","x":-1,"y":3,"z":0},{"level":1,"name":"Water_Source","x":-1,"y":4,"z":0},{"level":1,"name":"Water_Source","x":-1,"y":5,"z":0},{"level":1,"name":"Water_Source","x":-1,"y":6,"z":0},{"level":1,"name":"Water_Source","x":-1,"y":7,"z":0},{"level":1,"name":"Water_Source","x":-1,"y":0,"z":1},{"level":1,"name":"Water_Source","x":-1,"y":1,"z":1},{"level":1,"name":"Water_Source","x":-1,"y":2,"z":1},{"level":1,"name":"Water_Source","x":-1,"y":3,"z":1},{"level":1,"name":"Water_Source","x":-1,"y":4,"z":1},{"level":1,"name":"Water_Source","x":-1,"y":5,"z":1},{"level":1,"name":"Water_Source","x":-1,"y":6,"z":1},{"level":1,"name":"Water_Source","x":-1,"y":7,"z":1},{"level":1,"name":"Water_Source","x":-1,"y":8,"z":1},{"level":1,"name":"Water_Source","x":-1,"y":3,"z":2},{"level":1,"name":"Water_Source","x":-1,"y":4,"z":2},{"level":1,"name":"Water_Source","x":-1,"y":5,"z":2},{"level":1,"name":"Water_Source","x":-1,"y":6,"z":2},{"level":1,"name":"Water_Source","x":-1,"y":7,"z":2},{"level":1,"name":"Water_Source","x":-1,"y":8,"z":2},{"level":1,"name":"Water_Source","x":-1,"y":5,"z":3},{"level":1,"name":"Water_Source","x":-1,"y":6,"z":3},{"level":1,"name":"Water_Source","x":-1,"y":7,"z":3},{"level":1,"name":"Water_Source","x":-1,"y":8,"z":3},{"level":1,"name":"Water_Source","x":-1,"y":6,"z":4},{"level":1,"name":"Water_Source","x":0,"y":0,"z":-2},{"level":1,"name":"Water_Source","x":0,"y":0,"z":-1},{"level":1,"name":"Water_Source","x":0,"y":1,"z":-1},{"level":1,"name":"Water_Source","x":0,"y":2,"z":-1},{"level":1,"name":"Water_Source","x":0,"y":3,"z":-1},{"level":1,"name":"Water_Source","x":0,"y":4,"z":-1},{"level":1,"name":"Water_Source","x":0,"y":5,"z":-1},{"level":1,"name":"Water_Source","x":0,"y":0,"z":0},{"level":1,"name":"Water_Source","x":0,"y":1,"z":0},{"level":1,"name":"Water_Source","x":0,"y":2,"z":0},{"level":1,"name":"Water_Source","x":0,"y":3,"z":0},{"level":1,"name":"Water_Source","x":0,"y":4,"z":0},{"level":1,"name":"Water_Source","x":0,"y":5,"z":0},{"level":1,"name":"Water_Source","x":0,"y":6,"z":0},{"level":1,"name":"Water_Source","x":0,"y":7,"z":0},{"level":1,"name":"Water_Source","x":0,"y":8,"z":0},{"level":1,"name":"Water_Source","x":0,"y":1,"z":1},{"level":1,"name":"Water_Source","x":0,"y":2,"z":1},{"level":1,"name":"Water_Source","x":0,"y":3,"z":1},{"level":1,"name":"Water_Source","x":0,"y":4,"z":1},{"level":1,"name":"Water_Source","x":0,"y":5,"z":1},{"level":1,"name":"Water_Source","x":0,"y":8,"z":1},{"level":1,"name":"Water_Source","x":0,"y":9,"z":1},{"level":1,"name":"Water_Source","x":0,"y":8,"z":2},{"level":1,"name":"Water_Source","x":0,"y":9,"z":2},{"level":1,"name":"Water_Source","x":0,"y":10,"z":2},{"level":1,"name":"Water_Source","x":1,"y":0,"z":-2},{"level":1,"name":"Water_Source","x":1,"y":1,"z":-2},{"level":1,"name":"Water_Source","x":1,"y":0,"z":-1},{"level":1,"name":"Water_Source","x":1,"y":1,"z":-1},{"level":1,"name":"Water_Source","x":1,"y":2,"z":-1},{"level":1,"name":"Water_Source","x":1,"y":3,"z":-1},{"level":1,"name":"Water_Source","x":1,"y":4,"z":-1},{"level":1,"name":"Water_Source","x":1,"y":0,"z":0},{"level":1,"name":"Water_Source","x":1,"y":1,"z":0},{"level":1,"name":"Water_Source","x":1,"y":2,"z":0},{"level":1,"name":"Water_Source","x":1,"y":3,"z":0},{"level":1,"name":"Water_Source","x":1,"y":4,"z":0},{"level":1,"name":"Water_Source","x":1,"y":5,"z":0},{"level":1,"name":"Water_Source","x":1,"y":6,"z":0},{"level":1,"name":"Water_Source","x":1,"y":7,"z":0},{"level":1,"name":"Water_Source","x":1,"y":8,"z":0},{"level":1,"name":"Water_Source","x":1,"y":9,"z":0},{"level":1,"name":"Water_Source","x":1,"y":2,"z":1},{"level":1,"name":"Water_Source","x":1,"y":3,"z":1},{"level":1,"name":"Water_Source","x":1,"y":4,"z":1},{"level":1,"name":"Water_Source","x":1,"y":8,"z":1},{"level":1,"name":"Water_Source","x":1,"y":9,"z":1},{"level":1,"name":"Water_Source","x":1,"y":10,"z":1},{"level":1,"name":"Water_Source","x":2,"y":6,"z":0},{"level":1,"name":"Water_Source","x":2,"y":7,"z":0},{"level":1,"name":"Water_Source","x":2,"y":8,"z":0},{"level":1,"name":"Water_Source","x":3,"y":7,"z":0},{"level":1,"name":"Water_Source","x":3,"y":8,"z":0},{"level":1,"name":"Water_Source","x":4,"y":7,"z":0}],"version":8}