{"anchorX":1,"anchorY":0,"anchorZ":-1,"blockIdVersion":11,"blocks":[{"name":"Rock_Sandstone_Red_Brick","rotation":3,"x":-10,"y":1,"z":-8},{"name":"Rock_Sandstone_Red_Brick","rotation":3,"x":-10,"y":2,"z":-8},{"name":"Rock_Sandstone_Red_Brick_Stairs","rotation":3,"x":-10,"y":3,"z":-8},{"name":"Rock_Sandstone_Red_Cobble","rotation":3,"x":-10,"y":1,"z":-7},{"name":"Rock_Sandstone_Red_Brick","rotation":3,"x":-10,"y":2,"z":-7},{"name":"Rock_Sandstone_Red_Brick_Stairs","rotation":3,"x":-10,"y":3,"z":-7},{"name":"Rock_Sandstone","x":-10,"y":1,"z":-5},{"name":"Plant_Seaweed_Grass","support":15,"x":-10,"y":2,"z":-5},{"name":"Rock_Sandstone_Red_Brick","rotation":3,"x":-10,"y":1,"z":-4},{"name":"Rock_Sandstone_Red_Brick","rotation":3,"x":-10,"y":2,"z":-4},{"name":"Rock_Sandstone_Red_Brick_Stairs","rotation":3,"x":-10,"y":3,"z":-4},{"name":"Rock_Sandstone_Red_Cobble","rotation":3,"x":-10,"y":1,"z":-3},{"name":"Rock_Sandstone_Red_Brick","rotation":3,"x":-10,"y":2,"z":-3},{"name":"Rock_Sandstone_Red_Brick_Stairs","rotation":3,"x":-10,"y":3,"z":-3},{"name":"Rock_Sandstone_Red_Cobble","rotation":3,"x":-10,"y":1,"z":0},{"name":"Rock_Sandstone_Red_Brick","rotation":3,"x":-10,"y":1,"z":1},{"name":"Rock_Sandstone_Red_Brick","rotation":3,"x":-10,"y":2,"z":1},{"name":"Rock_Sandstone_Red_Brick_Stairs","rotation":3,"x":-10,"y":3,"z":1},{"name":"Rock_Sandstone_Red_Brick","rotation":3,"x":-10,"y":1,"z":4},{"name":"Rock_Sandstone_Red_Brick","rotation":3,"x":-10,"y":2,"z":4},{"name":"Rock_Sandstone_Red_Brick_Stairs","rotation":3,"x":-10,"y":3,"z":4},{"name":"Rock_Sandstone_Red_Brick","rotation":3,"x":-10,"y":1,"z":5},{"name":"Rock_Sandstone_Red_Brick","rotation":3,"x":-10,"y":2,"z":5},{"name":"Rock_Sandstone_Red_Brick_Stairs","rotation":3,"x":-10,"y":3,"z":5},{"name":"Rock_Sandstone","rotation":3,"x":-10,"y":1,"z":6},{"name":"Rock_Sandstone_Red_Cobble","rotation":3,"x":-10,"y":1,"z":8},{"name":"Rock_Sandstone_Red_Brick","rotation":3,"x":-10,"y":2,"z":8},{"name":"Rock_Sandstone_Red_Brick_Stairs","rotation":3,"x":-10,"y":3,"z":8},{"name":"Rock_Sandstone_Red_Brick","rotation":3,"x":-10,"y":1,"z":9},{"name":"Rock_Sandstone_Red_Brick","rotation":3,"x":-10,"y":2,"z":9},{"name":"Rock_Sandstone_Red_Brick_Stairs","rotation":3,"x":-10,"y":3,"z":9},{"name":"Rock_Sandstone_Red_Brick","rotation":3,"x":-9,"y":1,"z":-8},{"name":"Rock_Sandstone_Red_Brick","rotation":3,"x":-9,"y":2,"z":-8},{"name":"Rock_Sandstone_Red_Brick","rotation":3,"x":-9,"y":3,"z":-8},{"name":"Rock_Sandstone_Red_Brick_Stairs","rotation":3,"x":-9,"y":4,"z":-8},{"name":"Rock_Sandstone_Red_Cobble","rotation":3,"x":-9,"y":1,"z":-7},{"name":"Rock_Sandstone_Red_Brick","rotation":3,"x":-9,"y":2,"z":-7},{"name":"Rock_Sandstone_Red_Brick","rotation":3,"x":-9,"y":3,"z":-7},{"name":"Rock_Sandstone_Red_Brick_Stairs","rotation":3,"x":-9,"y":4,"z":-7},{"name":"Rock_Sandstone","x":-9,"y":1,"z":-6},{"name":"Plant_Seaweed_Grass","support":15,"x":-9,"y":2,"z":-6},{"name":"Rock_Sandstone","x":-9,"y":1,"z":-5},{"name":"Plant_Seaweed_Grass","support":15,"x":-9,"y":2,"z":-5},{"name":"Rock_Sandstone_Red_Brick","rotation":3,"x":-9,"y":1,"z":-4},{"name":"Rock_Sandstone_Red_Brick","rotation":3,"x":-9,"y":2,"z":-4},{"name":"Rock_Sandstone_Red_Brick","rotation":3,"x":-9,"y":3,"z":-4},{"name":"Rock_Sandstone_Red_Brick_Stairs","rotation":3,"x":-9,"y":4,"z":-4},{"name":"Rock_Sandstone_Red_Brick","rotation":3,"x":-9,"y":1,"z":-3},{"name":"Rock_Sandstone_Red_Brick","rotation":3,"x":-9,"y":2,"z":-3},{"name":"Rock_Sandstone_Red_Brick","rotation":3,"x":-9,"y":3,"z":-3},{"name":"Rock_Sandstone_Red_Brick_Stairs","rotation":3,"x":-9,"y":4,"z":-3},{"name":"Rock_Sandstone","x":-9,"y":1,"z":-2},{"name":"Rock_Sandstone","x":-9,"y":2,"z":-2},{"name":"Plant_Seaweed_Grass","support":15,"x":-9,"y":3,"z":-2},{"name":"Rock_Sandstone","x":-9,"y":1,"z":-1},{"name":"Plant_Seaweed_Grass","support":15,"x":-9,"y":2,"z":-1},{"name":"Rock_Sandstone_Red_Cobble","rotation":3,"x":-9,"y":1,"z":0},{"name":"Plant_Seaweed_Grass","support":15,"x":-9,"y":2,"z":0},{"name":"Rock_Sandstone_Red_Brick","rotation":3,"x":-9,"y":1,"z":1},{"name":"Rock_Sandstone_Red_Brick","rotation":3,"x":-9,"y":2,"z":1},{"name":"Rock_Sandstone_Red_Brick","rotation":3,"x":-9,"y":3,"z":1},{"name":"Rock_Sandstone_Red_Brick_Stairs","rotation":3,"x":-9,"y":4,"z":1},{"name":"Rock_Sandstone_Cobble","rotation":3,"x":-9,"y":1,"z":2},{"name":"Plant_Seaweed_Grass_Tall","support":15,"x":-9,"y":2,"z":2},{"filler":1024,"name":"Plant_Seaweed_Grass_Tall","x":-9,"y":3,"z":2},{"name":"Rock_Sandstone_Red_Brick","rotation":3,"x":-9,"y":1,"z":4},{"name":"Rock_Sandstone_Red_Brick","rotation":3,"x":-9,"y":2,"z":4},{"name":"Rock_Sandstone_Red_Brick","rotation":3,"x":-9,"y":3,"z":4},{"name":"Rock_Sandstone_Red_Brick_Stairs","rotation":3,"x":-9,"y":4,"z":4},{"name":"Rock_Sandstone_Red_Brick","rotation":3,"x":-9,"y":1,"z":5},{"name":"Rock_Sandstone_Red_Brick","rotation":3,"x":-9,"y":2,"z":5},{"name":"Rock_Sandstone_Red_Brick","rotation":3,"x":-9,"y":3,"z":5},{"name":"Rock_Sandstone_Red_Brick_Stairs","rotation":3,"x":-9,"y":4,"z":5},{"name":"Rock_Sandstone","rotation":3,"x":-9,"y":1,"z":6},{"name":"Rock_Sandstone","rotation":3,"x":-9,"y":1,"z":7},{"name":"Rock_Sandstone_Red_Brick","rotation":3,"x":-9,"y":1,"z":8},{"name":"Rock_Sandstone_Red_Brick","rotation":3,"x":-9,"y":2,"z":8},{"name":"Rock_Sandstone_Red_Brick","rotation":3,"x":-9,"y":3,"z":8},{"name":"Rock_Sandstone_Red_Brick_Stairs","rotation":3,"x":-9,"y":4,"z":8},{"name":"Rock_Sandstone_Red_Brick","rotation":3,"x":-9,"y":1,"z":9},{"name":"Rock_Sandstone_Red_Brick","rotation":3,"x":-9,"y":2,"z":9},{"name":"Rock_Sandstone_Red_Brick","rotation":3,"x":-9,"y":3,"z":9},{"name":"Rock_Sandstone_Red_Brick_Stairs","rotation":3,"x":-9,"y":4,"z":9},{"name":"Rock_Sandstone_Red_Cobble","rotation":3,"x":-8,"y":1,"z":-10},{"name":"Rock_Sandstone_Red_Brick","rotation":3,"x":-8,"y":2,"z":-10},{"name":"Rock_Sandstone_Red_Brick_Stairs","rotation":2,"x":-8,"y":3,"z":-10},{"name":"Rock_Sandstone_Red_Brick","rotation":3,"x":-8,"y":1,"z":-9},{"name":"Rock_Sandstone_Red_Brick","rotation":3,"x":-8,"y":2,"z":-9},{"name":"Rock_Sandstone_Red_Brick","rotation":3,"x":-8,"y":3,"z":-9},{"name":"Rock_Sandstone_Red_Brick_Stairs","rotation":2,"x":-8,"y":4,"z":-9},{"name":"Rock_Sandstone_Brick","rotation":3,"x":-8,"y":1,"z":-8},{"name":"Rock_Sandstone_Brick","rotation":3,"x":-8,"y":2,"z":-8},{"name":"Rock_Sandstone_Brick","rotation":3,"x":-8,"y":3,"z":-8},{"name":"Rock_Sandstone_Brick","rotation":3,"x":-8,"y":4,"z":-8},{"name":"Rock_Sandstone_Brick_Ornate","rotation":3,"x":-8,"y":5,"z":-8},{"name":"*Rock_Sandstone_Brick_Stairs_State_Definitions_Corner_Right","rotation":3,"x":-8,"y":6,"z":-8},{"name":"Rock_Sandstone_Brick","rotation":3,"x":-8,"y":1,"z":-7},{"name":"Rock_Sandstone_Brick","rotation":3,"x":-8,"y":2,"z":-7},{"name":"Rock_Sandstone_Brick","rotation":3,"x":-8,"y":3,"z":-7},{"name":"Rock_Sandstone_Brick","rotation":3,"x":-8,"y":4,"z":-7},{"name":"Rock_Sandstone_Brick_Ornate","rotation":3,"x":-8,"y":5,"z":-7},{"name":"Rock_Sandstone_Brick_Stairs","rotation":3,"x":-8,"y":6,"z":-7},{"name":"Rock_Sandstone_Brick","rotation":3,"x":-8,"y":1,"z":-6},{"name":"Rock_Sandstone_Cobble","rotation":3,"x":-8,"y":2,"z":-6},{"name":"Rock_Sandstone_Brick","rotation":3,"x":-8,"y":3,"z":-6},{"name":"Rock_Sandstone_Cobble","rotation":3,"x":-8,"y":4,"z":-6},{"name":"Rock_Sandstone_Brick_Ornate","rotation":3,"x":-8,"y":5,"z":-6},{"name":"Rock_Sandstone_Brick_Stairs","rotation":3,"x":-8,"y":6,"z":-6},{"name":"Rock_Sandstone_Brick","rotation":3,"x":-8,"y":1,"z":-5},{"name":"Rock_Sandstone_Brick","rotation":3,"x":-8,"y":2,"z":-5},{"name":"Rock_Sandstone_Cobble","rotation":3,"x":-8,"y":3,"z":-5},{"name":"Rock_Sandstone_Cobble","rotation":3,"x":-8,"y":4,"z":-5},{"name":"Rock_Sandstone_Brick_Ornate","rotation":3,"x":-8,"y":5,"z":-5},{"name":"Rock_Sandstone_Brick_Stairs","rotation":3,"x":-8,"y":6,"z":-5},{"name":"Rock_Sandstone_Brick","rotation":3,"x":-8,"y":1,"z":-4},{"name":"Rock_Sandstone_Brick","rotation":3,"x":-8,"y":2,"z":-4},{"name":"Rock_Sandstone_Brick","rotation":3,"x":-8,"y":3,"z":-4},{"name":"Rock_Sandstone_Brick","rotation":3,"x":-8,"y":4,"z":-4},{"name":"Rock_Sandstone_Brick_Ornate","rotation":3,"x":-8,"y":5,"z":-4},{"name":"Rock_Sandstone_Brick_Stairs","rotation":3,"x":-8,"y":6,"z":-4},{"name":"Rock_Sandstone_Brick","rotation":3,"x":-8,"y":1,"z":-3},{"name":"Rock_Sandstone_Brick","rotation":3,"x":-8,"y":2,"z":-3},{"name":"Rock_Sandstone_Brick","rotation":3,"x":-8,"y":3,"z":-3},{"name":"Rock_Sandstone_Brick","rotation":3,"x":-8,"y":4,"z":-3},{"name":"Rock_Sandstone_Brick_Ornate","rotation":3,"x":-8,"y":5,"z":-3},{"name":"Rock_Sandstone_Brick_Stairs","rotation":3,"x":-8,"y":6,"z":-3},{"name":"Rock_Sandstone_Cobble","rotation":3,"x":-8,"y":1,"z":-2},{"name":"Rock_Sandstone_Cobble","rotation":3,"x":-8,"y":2,"z":-2},{"name":"Rock_Sandstone_Cobble","rotation":3,"x":-8,"y":3,"z":-2},{"name":"Rock_Sandstone_Cobble","rotation":3,"x":-8,"y":4,"z":-2},{"name":"Plant_Seaweed_Grass","support":15,"x":-8,"y":5,"z":-2},{"name":"Rock_Sandstone_Brick","rotation":3,"x":-8,"y":1,"z":-1},{"name":"Plant_Coral_Model_Green","x":-8,"y":2,"z":-1},{"name":"*Rock_Sandstone_Brick_Stairs_State_Definitions_Corner_Left","rotation":2,"x":-8,"y":6,"z":-1},{"name":"Rock_Sandstone_Brick","rotation":3,"x":-8,"y":1,"z":0},{"name":"Plant_Seaweed_Grass_Tall","support":15,"x":-8,"y":2,"z":0},{"filler":1024,"name":"Plant_Seaweed_Grass_Tall","x":-8,"y":3,"z":0},{"name":"Rock_Sandstone_Brick_Ornate","rotation":3,"x":-8,"y":5,"z":0},{"name":"Rock_Sandstone_Brick_Stairs","rotation":3,"x":-8,"y":6,"z":0},{"name":"Rock_Sandstone_Brick","rotation":3,"x":-8,"y":1,"z":1},{"name":"Rock_Sandstone_Brick","rotation":3,"x":-8,"y":2,"z":1},{"name":"Rock_Sandstone_Brick","rotation":3,"x":-8,"y":3,"z":1},{"name":"Rock_Sandstone_Brick","rotation":3,"x":-8,"y":4,"z":1},{"name":"Rock_Sandstone_Brick_Ornate","rotation":3,"x":-8,"y":5,"z":1},{"name":"Rock_Sandstone_Brick_Stairs","rotation":3,"x":-8,"y":6,"z":1},{"name":"Rock_Sandstone_Brick","rotation":3,"x":-8,"y":1,"z":2},{"name":"Rock_Sandstone_Cobble","rotation":3,"x":-8,"y":2,"z":2},{"name":"Rock_Sandstone_Brick","rotation":3,"x":-8,"y":3,"z":2},{"name":"Rock_Sandstone_Cobble","rotation":3,"x":-8,"y":4,"z":2},{"name":"Rock_Sandstone_Brick_Ornate","rotation":3,"x":-8,"y":5,"z":2},{"name":"Rock_Sandstone_Brick_Stairs","rotation":3,"x":-8,"y":6,"z":2},{"name":"Rock_Sandstone_Brick","rotation":3,"x":-8,"y":1,"z":3},{"name":"Rock_Sandstone_Brick","rotation":3,"x":-8,"y":2,"z":3},{"name":"Rock_Sandstone_Cobble","rotation":3,"x":-8,"y":3,"z":3},{"name":"Rock_Sandstone_Cobble","rotation":3,"x":-8,"y":4,"z":3},{"name":"Rock_Sandstone_Brick_Ornate","rotation":3,"x":-8,"y":5,"z":3},{"name":"Plant_Coral_Model_Green","x":-8,"y":6,"z":3},{"name":"Rock_Sandstone_Brick","rotation":3,"x":-8,"y":1,"z":4},{"name":"Rock_Sandstone_Brick","rotation":3,"x":-8,"y":2,"z":4},{"name":"Rock_Sandstone_Brick","rotation":3,"x":-8,"y":3,"z":4},{"name":"Rock_Sandstone_Brick","rotation":3,"x":-8,"y":4,"z":4},{"name":"Rock_Sandstone_Brick_Ornate","rotation":3,"x":-8,"y":5,"z":4},{"name":"Plant_Seaweed_Grass","support":15,"x":-8,"y":6,"z":4},{"name":"Rock_Sandstone_Brick","rotation":3,"x":-8,"y":1,"z":5},{"name":"Rock_Sandstone_Brick","rotation":3,"x":-8,"y":2,"z":5},{"name":"Rock_Sandstone_Brick","rotation":3,"x":-8,"y":3,"z":5},{"name":"Rock_Sandstone_Brick","rotation":3,"x":-8,"y":4,"z":5},{"name":"Rock_Sandstone_Brick_Ornate","rotation":3,"x":-8,"y":5,"z":5},{"name":"Rock_Sandstone_Brick_Stairs","rotation":3,"x":-8,"y":6,"z":5},{"name":"Rock_Sandstone_Cobble","rotation":3,"x":-8,"y":1,"z":6},{"name":"Rock_Sandstone_Cobble","rotation":3,"x":-8,"y":2,"z":6},{"name":"Rock_Sandstone_Cobble","rotation":3,"x":-8,"y":3,"z":6},{"name":"Rock_Sandstone_Cobble","rotation":3,"x":-8,"y":4,"z":6},{"name":"Rock_Sandstone_Brick_Ornate","rotation":3,"x":-8,"y":5,"z":6},{"name":"Rock_Sandstone_Brick_Stairs","rotation":3,"x":-8,"y":6,"z":6},{"name":"Rock_Sandstone_Brick","rotation":3,"x":-8,"y":1,"z":7},{"name":"Rock_Sandstone_Cobble","rotation":3,"x":-8,"y":2,"z":7},{"name":"Rock_Sandstone_Cobble","rotation":3,"x":-8,"y":3,"z":7},{"name":"Rock_Sandstone_Cobble","rotation":3,"x":-8,"y":4,"z":7},{"name":"Rock_Sandstone_Brick_Ornate","rotation":3,"x":-8,"y":5,"z":7},{"name":"Rock_Sandstone_Brick_Stairs","rotation":3,"x":-8,"y":6,"z":7},{"name":"Rock_Sandstone_Brick","rotation":3,"x":-8,"y":1,"z":8},{"name":"Rock_Sandstone_Brick","rotation":3,"x":-8,"y":2,"z":8},{"name":"Rock_Sandstone_Brick","rotation":3,"x":-8,"y":3,"z":8},{"name":"Rock_Sandstone_Brick","rotation":3,"x":-8,"y":4,"z":8},{"name":"Rock_Sandstone_Brick_Ornate","rotation":3,"x":-8,"y":5,"z":8},{"name":"Plant_Seaweed_Grass","support":15,"x":-8,"y":6,"z":8},{"name":"Rock_Sandstone_Brick","rotation":3,"x":-8,"y":1,"z":9},{"name":"Rock_Sandstone_Brick","rotation":3,"x":-8,"y":2,"z":9},{"name":"Rock_Sandstone_Brick","rotation":3,"x":-8,"y":3,"z":9},{"name":"Rock_Sandstone_Brick","rotation":3,"x":-8,"y":4,"z":9},{"name":"Rock_Sandstone_Brick_Ornate","rotation":3,"x":-8,"y":5,"z":9},{"name":"Plant_Seaweed_Grass","support":15,"x":-8,"y":6,"z":9},{"name":"Rock_Sandstone_Red_Brick","rotation":3,"x":-8,"y":1,"z":10},{"name":"Rock_Sandstone_Red_Brick","rotation":3,"x":-8,"y":2,"z":10},{"name":"Rock_Sandstone_Red_Brick","rotation":3,"x":-8,"y":3,"z":10},{"name":"Rock_Sandstone_Red_Brick_Stairs","x":-8,"y":4,"z":10},{"name":"Rock_Sandstone_Red_Cobble","rotation":3,"x":-8,"y":1,"z":11},{"name":"Rock_Sandstone_Red_Brick","rotation":3,"x":-8,"y":2,"z":11},{"name":"Rock_Sandstone_Red_Brick_Stairs","x":-8,"y":3,"z":11},{"name":"Rock_Sandstone_Red_Brick","rotation":3,"x":-7,"y":1,"z":-10},{"name":"Rock_Sandstone_Red_Brick","rotation":3,"x":-7,"y":2,"z":-10},{"name":"Rock_Sandstone_Red_Brick_Stairs","rotation":2,"x":-7,"y":3,"z":-10},{"name":"Rock_Sandstone_Red_Brick","rotation":3,"x":-7,"y":1,"z":-9},{"name":"Rock_Sandstone_Red_Brick","rotation":3,"x":-7,"y":2,"z":-9},{"name":"Rock_Sandstone_Red_Brick","rotation":3,"x":-7,"y":3,"z":-9},{"name":"Rock_Sandstone_Red_Brick_Stairs","rotation":2,"x":-7,"y":4,"z":-9},{"name":"Rock_Sandstone_Brick","rotation":3,"x":-7,"y":1,"z":-8},{"name":"Rock_Sandstone_Brick","rotation":3,"x":-7,"y":2,"z":-8},{"name":"Rock_Sandstone_Brick","rotation":3,"x":-7,"y":3,"z":-8},{"name":"Rock_Sandstone_Brick","rotation":3,"x":-7,"y":4,"z":-8},{"name":"Rock_Sandstone_Brick_Ornate","rotation":3,"x":-7,"y":5,"z":-8},{"name":"Rock_Sandstone_Brick_Stairs","rotation":2,"x":-7,"y":6,"z":-8},{"name":"Rock_Sandstone_Brick","rotation":3,"x":-7,"y":1,"z":-7},{"name":"Rock_Sandstone_Brick","rotation":3,"x":-7,"y":2,"z":-7},{"name":"Rock_Sandstone_Brick","rotation":3,"x":-7,"y":3,"z":-7},{"name":"Rock_Sandstone_Brick","rotation":3,"x":-7,"y":4,"z":-7},{"name":"Rock_Sandstone_Brick","rotation":3,"x":-7,"y":5,"z":-7},{"name":"Rock_Sandstone_Cobble","rotation":3,"x":-7,"y":6,"z":-7},{"name":"Rock_Sandstone_Cobble","rotation":3,"x":-7,"y":7,"z":-7},{"name":"Rock_Sandstone_Cobble","x":-7,"y":8,"z":-7},{"name":"Rock_Sandstone_Cobble","x":-7,"y":9,"z":-7},{"name":"Rock_Sandstone_Cobble","x":-7,"y":10,"z":-7},{"name":"Rock_Sandstone_Cobble","x":-7,"y":11,"z":-7},{"name":"Rock_Sandstone_Cobble_Half","x":-7,"y":12,"z":-7},{"name":"Rock_Sandstone_Brick","rotation":3,"x":-7,"y":1,"z":-6},{"name":"Rock_Sandstone_Brick","rotation":3,"x":-7,"y":2,"z":-6},{"name":"Rock_Sandstone_Brick","rotation":3,"x":-7,"y":3,"z":-6},{"name":"Rock_Sandstone_Red_Brick","rotation":3,"x":-7,"y":4,"z":-6},{"name":"Rock_Sandstone_Brick","rotation":3,"x":-7,"y":5,"z":-6},{"name":"Rock_Sandstone_Cobble","rotation":3,"x":-7,"y":6,"z":-6},{"name":"Rock_Sandstone_Cobble","rotation":3,"x":-7,"y":7,"z":-6},{"name":"Rock_Sandstone_Cobble","rotation":3,"x":-7,"y":8,"z":-6},{"name":"Rock_Sandstone_Cobble","x":-7,"y":9,"z":-6},{"name":"Rock_Sandstone_Cobble","x":-7,"y":10,"z":-6},{"name":"Rock_Sandstone_Cobble","x":-7,"y":11,"z":-6},{"name":"Plant_Seaweed_Grass_Tall","support":15,"x":-7,"y":12,"z":-6},{"filler":1024,"name":"Plant_Seaweed_Grass_Tall","x":-7,"y":13,"z":-6},{"name":"Rock_Sandstone_Brick","rotation":3,"x":-7,"y":1,"z":-5},{"name":"Rock_Sandstone_Brick","rotation":3,"x":-7,"y":2,"z":-5},{"name":"Rock_Sandstone_Brick","rotation":3,"x":-7,"y":3,"z":-5},{"name":"Rock_Sandstone_Red_Brick","rotation":3,"x":-7,"y":4,"z":-5},{"name":"Rock_Sandstone_Brick","rotation":3,"x":-7,"y":5,"z":-5},{"name":"Rock_Sandstone_Cobble","rotation":3,"x":-7,"y":6,"z":-5},{"name":"Rock_Sandstone_Cobble","rotation":3,"x":-7,"y":7,"z":-5},{"name":"Rock_Sandstone_Cobble","rotation":3,"x":-7,"y":8,"z":-5},{"name":"Rock_Sandstone_Cobble","x":-7,"y":9,"z":-5},{"name":"Rock_Sandstone_Cobble","x":-7,"y":10,"z":-5},{"name":"Plant_Seaweed_Grass","support":15,"x":-7,"y":11,"z":-5},{"name":"Rock_Sandstone_Brick","rotation":3,"x":-7,"y":1,"z":-4},{"name":"Rock_Sandstone_Brick","rotation":3,"x":-7,"y":2,"z":-4},{"name":"Rock_Sandstone_Brick","rotation":3,"x":-7,"y":3,"z":-4},{"name":"Rock_Sandstone_Red_Brick","rotation":3,"x":-7,"y":4,"z":-4},{"name":"Rock_Sandstone_Brick","rotation":3,"x":-7,"y":5,"z":-4},{"name":"Rock_Sandstone_Cobble","rotation":3,"x":-7,"y":6,"z":-4},{"name":"Rock_Sandstone_Cobble","rotation":3,"x":-7,"y":7,"z":-4},{"name":"Rock_Sandstone_Cobble","x":-7,"y":8,"z":-4},{"name":"Rock_Sandstone_Cobble_Half","rotation":4,"x":-7,"y":9,"z":-4},{"name":"Rock_Sandstone_Brick","rotation":3,"x":-7,"y":1,"z":-3},{"name":"Rock_Sandstone_Brick","rotation":3,"x":-7,"y":2,"z":-3},{"name":"Rock_Sandstone_Brick","rotation":3,"x":-7,"y":3,"z":-3},{"name":"Rock_Sandstone_Red_Brick","rotation":3,"x":-7,"y":4,"z":-3},{"name":"Rock_Sandstone_Brick","rotation":3,"x":-7,"y":5,"z":-3},{"name":"Rock_Sandstone_Cobble","rotation":3,"x":-7,"y":6,"z":-3},{"name":"Rock_Sandstone_Cobble_Half","rotation":4,"x":-7,"y":7,"z":-3},{"name":"Rock_Sandstone_Brick","rotation":3,"x":-7,"y":1,"z":-2},{"name":"Rock_Sandstone_Brick","rotation":3,"x":-7,"y":2,"z":-2},{"name":"Rock_Sandstone_Brick","rotation":3,"x":-7,"y":3,"z":-2},{"name":"Rock_Sandstone_Red_Brick","rotation":3,"x":-7,"y":4,"z":-2},{"name":"Plant_Seaweed_Grass","support":15,"x":-7,"y":5,"z":-2},{"name":"Rock_Sandstone_Brick","rotation":3,"x":-7,"y":1,"z":-1},{"name":"Rock_Sandstone_Cobble_Half","rotation":6,"x":-7,"y":7,"z":-1},{"name":"Rock_Sandstone_Cobble_Half","rotation":6,"x":-7,"y":8,"z":-1},{"name":"Rock_Sandstone_Red_Brick","rotation":3,"x":-7,"y":1,"z":0},{"name":"Plant_Seaweed_Grass_Tall","support":15,"x":-7,"y":2,"z":0},{"filler":1024,"name":"Plant_Seaweed_Grass_Tall","x":-7,"y":3,"z":0},{"name":"Rock_Sandstone_Brick","rotation":3,"x":-7,"y":5,"z":0},{"name":"Rock_Sandstone_Cobble","rotation":3,"x":-7,"y":6,"z":0},{"name":"Rock_Sandstone_Cobble","rotation":3,"x":-7,"y":7,"z":0},{"name":"Rock_Sandstone_Cobble","rotation":3,"x":-7,"y":8,"z":0},{"name":"Rock_Sandstone_Cobble_Half","x":-7,"y":9,"z":0},{"name":"Rock_Sandstone_Brick","rotation":3,"x":-7,"y":1,"z":1},{"name":"Rock_Sandstone_Brick","rotation":3,"x":-7,"y":2,"z":1},{"name":"Rock_Sandstone_Brick","rotation":3,"x":-7,"y":3,"z":1},{"name":"Rock_Sandstone_Brick","rotation":3,"x":-7,"y":4,"z":1},{"name":"Rock_Sandstone_Brick","rotation":3,"x":-7,"y":5,"z":1},{"name":"Rock_Sandstone_Cobble","rotation":3,"x":-7,"y":6,"z":1},{"name":"Rock_Sandstone_Cobble","rotation":3,"x":-7,"y":7,"z":1},{"name":"Rock_Sandstone_Cobble","rotation":3,"x":-7,"y":8,"z":1},{"name":"Rock_Sandstone_Cobble","rotation":3,"x":-7,"y":9,"z":1},{"name":"Rock_Sandstone_Cobble_Half","rotation":6,"x":-7,"y":10,"z":1},{"name":"Rock_Sandstone_Cobble_Half","rotation":6,"x":-7,"y":11,"z":1},{"name":"Rock_Sandstone_Brick","rotation":3,"x":-7,"y":1,"z":2},{"name":"Rock_Sandstone_Brick","rotation":3,"x":-7,"y":2,"z":2},{"name":"Rock_Sandstone_Brick","rotation":3,"x":-7,"y":3,"z":2},{"name":"Rock_Sandstone_Red_Brick","rotation":3,"x":-7,"y":4,"z":2},{"name":"Rock_Sandstone_Brick","rotation":3,"x":-7,"y":5,"z":2},{"name":"Rock_Sandstone_Cobble","rotation":3,"x":-7,"y":6,"z":2},{"name":"Rock_Sandstone_Cobble","rotation":3,"x":-7,"y":7,"z":2},{"name":"Rock_Sandstone_Cobble","rotation":3,"x":-7,"y":8,"z":2},{"name":"Rock_Sandstone_Cobble","rotation":3,"x":-7,"y":9,"z":2},{"name":"Rock_Sandstone_Cobble","x":-7,"y":10,"z":2},{"name":"Rock_Sandstone_Cobble","x":-7,"y":11,"z":2},{"name":"Rock_Sandstone_Cobble","x":-7,"y":12,"z":2},{"name":"Rock_Sandstone_Cobble_Half","rotation":6,"x":-7,"y":13,"z":2},{"name":"Rock_Sandstone_Brick","rotation":3,"x":-7,"y":1,"z":3},{"name":"Rock_Sandstone_Brick","rotation":3,"x":-7,"y":2,"z":3},{"name":"Rock_Sandstone_Brick","rotation":3,"x":-7,"y":3,"z":3},{"name":"Rock_Sandstone_Red_Brick","rotation":3,"x":-7,"y":4,"z":3},{"name":"Rock_Sandstone_Brick","rotation":3,"x":-7,"y":5,"z":3},{"name":"Rock_Sandstone_Cobble","rotation":3,"x":-7,"y":6,"z":3},{"name":"Rock_Sandstone_Cobble","rotation":3,"x":-7,"y":7,"z":3},{"name":"Rock_Sandstone_Cobble","rotation":3,"x":-7,"y":8,"z":3},{"name":"Rock_Sandstone_Cobble","rotation":3,"x":-7,"y":9,"z":3},{"name":"Rock_Sandstone_Cobble","x":-7,"y":10,"z":3},{"name":"Rock_Sandstone_Cobble","x":-7,"y":11,"z":3},{"name":"Rock_Sandstone_Cobble","x":-7,"y":12,"z":3},{"name":"Rock_Sandstone_Cobble","x":-7,"y":13,"z":3},{"name":"Rock_Sandstone_Cobble_Half","x":-7,"y":14,"z":3},{"name":"Rock_Sandstone_Brick","x":-7,"y":1,"z":4},{"name":"Rock_Sandstone_Brick","rotation":3,"x":-7,"y":2,"z":4},{"name":"Rock_Sandstone_Brick","rotation":3,"x":-7,"y":3,"z":4},{"name":"Rock_Sandstone_Red_Brick","rotation":3,"x":-7,"y":4,"z":4},{"name":"Rock_Sandstone_Brick","rotation":3,"x":-7,"y":5,"z":4},{"name":"Rock_Sandstone_Cobble","rotation":3,"x":-7,"y":6,"z":4},{"name":"Rock_Sandstone_Cobble","rotation":3,"x":-7,"y":7,"z":4},{"name":"Rock_Sandstone_Cobble","rotation":3,"x":-7,"y":8,"z":4},{"name":"Rock_Sandstone_Cobble","rotation":3,"x":-7,"y":9,"z":4},{"name":"Rock_Sandstone_Cobble","x":-7,"y":10,"z":4},{"name":"Rock_Sandstone_Cobble","x":-7,"y":11,"z":4},{"name":"Rock_Sandstone_Cobble_Half","rotation":4,"x":-7,"y":12,"z":4},{"name":"Rock_Sandstone_Cobble_Half","rotation":4,"x":-7,"y":13,"z":4},{"name":"Rock_Sandstone_Brick","rotation":3,"x":-7,"y":1,"z":5},{"name":"Rock_Sandstone_Brick","rotation":3,"x":-7,"y":2,"z":5},{"name":"Rock_Sandstone_Brick","rotation":3,"x":-7,"y":3,"z":5},{"name":"Rock_Sandstone_Red_Brick","rotation":3,"x":-7,"y":4,"z":5},{"name":"Rock_Sandstone_Brick","rotation":3,"x":-7,"y":5,"z":5},{"name":"Rock_Sandstone_Cobble","rotation":3,"x":-7,"y":6,"z":5},{"name":"Rock_Sandstone_Cobble","rotation":3,"x":-7,"y":7,"z":5},{"name":"Rock_Sandstone_Cobble","rotation":3,"x":-7,"y":8,"z":5},{"name":"Rock_Sandstone_Cobble","rotation":3,"x":-7,"y":9,"z":5},{"name":"Rock_Sandstone_Cobble","x":-7,"y":10,"z":5},{"name":"Rock_Sandstone_Cobble_Half","x":-7,"y":11,"z":5},{"name":"Rock_Sandstone_Brick","rotation":3,"x":-7,"y":1,"z":6},{"name":"Rock_Sandstone_Brick","rotation":3,"x":-7,"y":2,"z":6},{"name":"Rock_Sandstone_Brick","rotation":3,"x":-7,"y":3,"z":6},{"name":"Rock_Sandstone_Red_Brick","rotation":3,"x":-7,"y":4,"z":6},{"name":"Rock_Sandstone_Brick","rotation":3,"x":-7,"y":5,"z":6},{"name":"Rock_Sandstone_Cobble","rotation":3,"x":-7,"y":6,"z":6},{"name":"Rock_Sandstone_Cobble","rotation":3,"x":-7,"y":7,"z":6},{"name":"Rock_Sandstone_Cobble","rotation":3,"x":-7,"y":8,"z":6},{"name":"Rock_Sandstone_Cobble","rotation":3,"x":-7,"y":9,"z":6},{"name":"Rock_Sandstone_Cobble_Half","rotation":4,"x":-7,"y":10,"z":6},{"name":"Rock_Sandstone_Brick","rotation":3,"x":-7,"y":1,"z":7},{"name":"Rock_Sandstone_Brick","rotation":3,"x":-7,"y":2,"z":7},{"name":"Rock_Sandstone_Brick","rotation":3,"x":-7,"y":3,"z":7},{"name":"Rock_Sandstone_Red_Brick","rotation":3,"x":-7,"y":4,"z":7},{"name":"Rock_Sandstone_Brick","rotation":3,"x":-7,"y":5,"z":7},{"name":"Rock_Sandstone_Cobble","rotation":3,"x":-7,"y":6,"z":7},{"name":"Rock_Sandstone_Cobble","rotation":3,"x":-7,"y":7,"z":7},{"name":"Rock_Sandstone_Cobble","rotation":3,"x":-7,"y":8,"z":7},{"name":"Rock_Sandstone_Cobble","rotation":3,"x":-7,"y":9,"z":7},{"name":"Plant_Seaweed_Grass","support":15,"x":-7,"y":10,"z":7},{"name":"Rock_Sandstone_Brick","rotation":3,"x":-7,"y":1,"z":8},{"name":"Rock_Sandstone_Brick","rotation":3,"x":-7,"y":2,"z":8},{"name":"Rock_Sandstone_Brick","rotation":3,"x":-7,"y":3,"z":8},{"name":"Rock_Sandstone_Brick","rotation":3,"x":-7,"y":4,"z":8},{"name":"Rock_Sandstone_Brick","rotation":3,"x":-7,"y":5,"z":8},{"name":"Rock_Sandstone_Cobble","rotation":3,"x":-7,"y":6,"z":8},{"name":"Plant_Coral_Model_Green","x":-7,"y":7,"z":8},{"name":"Rock_Sandstone_Brick","rotation":3,"x":-7,"y":8,"z":8},{"name":"Rock_Sandstone_Brick","rotation":3,"x":-7,"y":9,"z":8},{"name":"Rock_Sandstone_Cobble_Half","x":-7,"y":10,"z":8},{"name":"Rock_Sandstone_Brick","rotation":3,"x":-7,"y":1,"z":9},{"name":"Rock_Sandstone_Brick","rotation":3,"x":-7,"y":2,"z":9},{"name":"Rock_Sandstone_Brick","rotation":3,"x":-7,"y":3,"z":9},{"name":"Rock_Sandstone_Brick","rotation":3,"x":-7,"y":4,"z":9},{"name":"Rock_Sandstone_Brick_Ornate","rotation":3,"x":-7,"y":5,"z":9},{"name":"Plant_Seaweed_Grass_Tall","support":15,"x":-7,"y":6,"z":9},{"filler":1024,"name":"Plant_Seaweed_Grass_Tall","x":-7,"y":7,"z":9},{"name":"Rock_Sandstone_Red_Brick","rotation":3,"x":-7,"y":1,"z":10},{"name":"Rock_Sandstone_Red_Brick","rotation":3,"x":-7,"y":2,"z":10},{"name":"Rock_Sandstone_Red_Brick","rotation":3,"x":-7,"y":3,"z":10},{"name":"Rock_Sandstone_Red_Brick_Stairs","x":-7,"y":4,"z":10},{"name":"Rock_Sandstone_Red_Cobble","rotation":3,"x":-7,"y":1,"z":11},{"name":"Rock_Sandstone_Red_Brick","rotation":3,"x":-7,"y":2,"z":11},{"name":"Rock_Sandstone_Red_Brick_Stairs","x":-7,"y":3,"z":11},{"name":"Rock_Sandstone_Cobble_Half","x":-6,"y":1,"z":-9},{"name":"Rock_Sandstone_Cobble","rotation":3,"x":-6,"y":1,"z":-8},{"name":"Rock_Sandstone_Cobble","rotation":3,"x":-6,"y":2,"z":-8},{"name":"Rock_Sandstone_Cobble","rotation":3,"x":-6,"y":3,"z":-8},{"name":"Rock_Sandstone_Cobble","rotation":3,"x":-6,"y":4,"z":-8},{"name":"Rock_Sandstone_Brick_Ornate","rotation":3,"x":-6,"y":5,"z":-8},{"name":"Rock_Sandstone_Brick_Stairs","rotation":2,"x":-6,"y":6,"z":-8},{"name":"Rock_Sandstone_Brick","rotation":3,"x":-6,"y":1,"z":-7},{"name":"Rock_Sandstone_Brick","rotation":3,"x":-6,"y":2,"z":-7},{"name":"Rock_Sandstone_Brick","rotation":3,"x":-6,"y":3,"z":-7},{"name":"Rock_Sandstone_Brick","rotation":3,"x":-6,"y":4,"z":-7},{"name":"Rock_Sandstone_Brick","rotation":3,"x":-6,"y":5,"z":-7},{"name":"Rock_Sandstone_Cobble","rotation":3,"x":-6,"y":6,"z":-7},{"name":"Rock_Sandstone_Cobble","x":-6,"y":7,"z":-7},{"name":"Rock_Sandstone_Cobble","x":-6,"y":8,"z":-7},{"name":"Rock_Sandstone_Cobble","x":-6,"y":9,"z":-7},{"name":"Rock_Sandstone_Cobble","x":-6,"y":10,"z":-7},{"name":"Rock_Sandstone_Cobble_Half","rotation":5,"x":-6,"y":11,"z":-7},{"name":"Rock_Sandstone_Brick","x":-6,"y":1,"z":-6},{"name":"Rock_Sandstone_Brick","rotation":3,"x":-6,"y":2,"z":-6},{"name":"Rock_Sandstone_Brick","rotation":3,"x":-6,"y":3,"z":-6},{"name":"Soil_Dirt","x":-6,"y":4,"z":-6},{"name":"Soil_Grass_Full","rotation":3,"x":-6,"y":5,"z":-6},{"name":"Rubble_Sandstone","support":15,"x":-6,"y":6,"z":-6},{"name":"Rock_Sandstone_Brick","x":-6,"y":1,"z":-5},{"name":"Rock_Sandstone_Brick","rotation":3,"x":-6,"y":2,"z":-5},{"name":"Soil_Dirt","x":-6,"y":3,"z":-5},{"name":"Soil_Grass_Full","rotation":3,"x":-6,"y":4,"z":-5},{"name":"Rock_Sandstone_Brick","x":-6,"y":1,"z":-4},{"name":"Rock_Sandstone_Brick","rotation":3,"x":-6,"y":2,"z":-4},{"name":"Soil_Grass_Full","rotation":3,"x":-6,"y":3,"z":-4},{"name":"Plant_Seaweed_Grass","support":15,"x":-6,"y":4,"z":-4},{"name":"Rock_Sandstone_Brick","x":-6,"y":1,"z":-3},{"name":"Rock_Sandstone_Brick","rotation":3,"x":-6,"y":2,"z":-3},{"name":"Soil_Grass_Full","rotation":3,"x":-6,"y":3,"z":-3},{"name":"Rubble_Sandstone","rotation":3,"x":-6,"y":4,"z":-3},{"name":"Rock_Sandstone_Brick","x":-6,"y":1,"z":-2},{"name":"Rock_Sandstone_Brick","rotation":3,"x":-6,"y":2,"z":-2},{"name":"Rock_Sandstone_Brick","rotation":3,"x":-6,"y":3,"z":-2},{"name":"Plant_Seaweed_Grass","support":15,"x":-6,"y":4,"z":-2},{"name":"Rock_Sandstone_Brick","x":-6,"y":1,"z":-1},{"name":"Soil_Grass_Full","x":-6,"y":2,"z":-1},{"name":"Rock_Sandstone_Brick","x":-6,"y":1,"z":0},{"name":"Plant_Seaweed_Grass","support":15,"x":-6,"y":2,"z":0},{"name":"Soil_Grass_Full","x":-6,"y":1,"z":1},{"name":"Plant_Seaweed_Grass","support":15,"x":-6,"y":2,"z":1},{"name":"Rock_Sandstone_Brick_Stairs","rotation":11,"x":-6,"y":8,"z":1},{"name":"Plant_Coral_Bush_Green","x":-6,"y":9,"z":1},{"name":"Soil_Dirt","x":-6,"y":1,"z":2},{"name":"Soil_Grass_Full","x":-6,"y":2,"z":2},{"name":"Rock_Sandstone_Brick_Stairs","rotation":33,"x":-6,"y":8,"z":2},{"name":"Rock_Sandstone_Brick","rotation":3,"x":-6,"y":1,"z":3},{"name":"Rock_Sandstone_Brick","rotation":3,"x":-6,"y":2,"z":3},{"name":"Rock_Sandstone_Brick","rotation":3,"x":-6,"y":3,"z":3},{"name":"Rock_Sandstone_Brick_Stairs","rotation":33,"x":-6,"y":8,"z":3},{"name":"Plant_Coral_Bush_Green","x":-6,"y":9,"z":3},{"name":"Rock_Sandstone_Brick","x":-6,"y":1,"z":4},{"name":"Rock_Sandstone_Brick","rotation":3,"x":-6,"y":2,"z":4},{"name":"Soil_Grass_Full","x":-6,"y":3,"z":4},{"name":"Plant_Coral_Bush_Green","x":-6,"y":4,"z":4},{"name":"Rock_Sandstone_Brick_Stairs","rotation":33,"x":-6,"y":8,"z":4},{"name":"Plant_Coral_Bush_Green","x":-6,"y":9,"z":4},{"name":"Rock_Sandstone_Brick","x":-6,"y":1,"z":5},{"name":"Rock_Sandstone_Brick","rotation":3,"x":-6,"y":2,"z":5},{"name":"Soil_Dirt","x":-6,"y":3,"z":5},{"name":"Soil_Grass_Full","x":-6,"y":4,"z":5},{"name":"Rock_Sandstone_Brick_Stairs","rotation":33,"x":-6,"y":8,"z":5},{"name":"Rock_Sandstone_Brick","x":-6,"y":1,"z":6},{"name":"Rock_Sandstone_Brick","rotation":3,"x":-6,"y":2,"z":6},{"name":"Soil_Dirt","x":-6,"y":3,"z":6},{"name":"Soil_Dirt","x":-6,"y":4,"z":6},{"name":"Soil_Grass_Full","x":-6,"y":5,"z":6},{"name":"Rock_Sandstone_Brick_Stairs","rotation":33,"x":-6,"y":8,"z":6},{"name":"Plant_Seaweed_Grass","support":15,"x":-6,"y":9,"z":6},{"name":"Rock_Sandstone_Brick","x":-6,"y":1,"z":7},{"name":"Rock_Sandstone_Brick","rotation":3,"x":-6,"y":2,"z":7},{"name":"Rock_Sandstone_Brick","rotation":3,"x":-6,"y":3,"z":7},{"name":"Soil_Dirt","x":-6,"y":4,"z":7},{"name":"Soil_Dirt","x":-6,"y":5,"z":7},{"name":"Soil_Grass_Full","x":-6,"y":6,"z":7},{"name":"*Rock_Sandstone_Brick_Stairs_State_Definitions_Inverted_Corner_Left","rotation":33,"x":-6,"y":8,"z":7},{"name":"Plant_Seaweed_Grass","support":15,"x":-6,"y":9,"z":7},{"name":"Rock_Sandstone_Brick","rotation":3,"x":-6,"y":1,"z":8},{"name":"Rock_Sandstone_Brick","rotation":3,"x":-6,"y":2,"z":8},{"name":"Rock_Sandstone_Brick","rotation":3,"x":-6,"y":3,"z":8},{"name":"Rock_Sandstone_Brick","rotation":3,"x":-6,"y":4,"z":8},{"name":"Rock_Sandstone_Brick","rotation":3,"x":-6,"y":5,"z":8},{"name":"Rock_Sandstone_Cobble","rotation":3,"x":-6,"y":6,"z":8},{"name":"Rock_Sandstone_Cobble","rotation":3,"x":-6,"y":7,"z":8},{"name":"Rock_Sandstone_Cobble","rotation":3,"x":-6,"y":8,"z":8},{"name":"Rock_Sandstone_Brick","rotation":3,"x":-6,"y":9,"z":8},{"name":"Rock_Sandstone_Cobble","x":-6,"y":10,"z":8},{"name":"Rock_Sandstone_Cobble_Half","rotation":7,"x":-6,"y":11,"z":8},{"name":"Rock_Sandstone_Cobble","rotation":3,"x":-6,"y":1,"z":9},{"name":"Rock_Sandstone_Cobble","rotation":3,"x":-6,"y":2,"z":9},{"name":"Rock_Sandstone_Cobble","rotation":3,"x":-6,"y":3,"z":9},{"name":"Rock_Sandstone_Cobble","rotation":3,"x":-6,"y":4,"z":9},{"name":"Rock_Sandstone_Brick_Ornate","rotation":3,"x":-6,"y":5,"z":9},{"name":"Rock_Sandstone_Brick_Stairs","x":-6,"y":6,"z":9},{"name":"Soil_Dirt","x":-6,"y":1,"z":10},{"name":"Soil_Grass_Full","x":-6,"y":2,"z":10},{"name":"Plant_Seaweed_Grass","support":15,"x":-6,"y":3,"z":10},{"name":"Rock_Sandstone","x":-5,"y":1,"z":-9},{"name":"Rock_Sandstone_Cobble","rotation":3,"x":-5,"y":1,"z":-8},{"name":"Rock_Sandstone_Cobble","rotation":3,"x":-5,"y":2,"z":-8},{"name":"Rock_Sandstone_Cobble","rotation":3,"x":-5,"y":3,"z":-8},{"name":"Rock_Sandstone_Cobble","rotation":3,"x":-5,"y":4,"z":-8},{"name":"Rock_Sandstone_Brick_Ornate","rotation":3,"x":-5,"y":5,"z":-8},{"name":"Rock_Sandstone_Brick_Stairs","rotation":2,"x":-5,"y":6,"z":-8},{"name":"Rock_Sandstone_Brick","rotation":3,"x":-5,"y":1,"z":-7},{"name":"Rock_Sandstone_Brick","rotation":3,"x":-5,"y":2,"z":-7},{"name":"Rock_Sandstone_Brick","rotation":3,"x":-5,"y":3,"z":-7},{"name":"Rock_Sandstone_Brick","rotation":3,"x":-5,"y":4,"z":-7},{"name":"Rock_Sandstone_Brick","rotation":3,"x":-5,"y":5,"z":-7},{"name":"Rock_Sandstone_Cobble","rotation":3,"x":-5,"y":6,"z":-7},{"name":"Rock_Sandstone_Cobble","rotation":3,"x":-5,"y":7,"z":-7},{"name":"Rock_Sandstone_Cobble","rotation":3,"x":-5,"y":8,"z":-7},{"name":"Rock_Sandstone_Cobble","x":-5,"y":9,"z":-7},{"name":"Rock_Sandstone_Cobble_Half","x":-5,"y":10,"z":-7},{"name":"Rock_Sandstone_Brick","x":-5,"y":1,"z":-6},{"name":"Soil_Dirt","x":-5,"y":2,"z":-6},{"name":"Rock_Sandstone_Brick","rotation":3,"x":-5,"y":3,"z":-6},{"name":"Soil_Grass_Full","rotation":3,"x":-5,"y":4,"z":-6},{"name":"Rock_Sandstone_Brick","x":-5,"y":1,"z":-5},{"name":"Soil_Dirt","x":-5,"y":2,"z":-5},{"name":"Rock_Sandstone_Brick","rotation":3,"x":-5,"y":3,"z":-5},{"name":"Plant_Seaweed_Grass","support":15,"x":-5,"y":4,"z":-5},{"name":"Rock_Sandstone_Brick","x":-5,"y":1,"z":-4},{"name":"Soil_Dirt","x":-5,"y":2,"z":-4},{"name":"Rock_Sandstone_Brick","rotation":3,"x":-5,"y":3,"z":-4},{"name":"Plant_Seaweed_Grass","support":15,"x":-5,"y":4,"z":-4},{"name":"Rock_Sandstone_Brick","x":-5,"y":1,"z":-3},{"name":"Soil_Dirt","x":-5,"y":2,"z":-3},{"name":"Rock_Sandstone_Brick","rotation":3,"x":-5,"y":3,"z":-3},{"name":"Plant_Seaweed_Grass","support":15,"x":-5,"y":4,"z":-3},{"name":"Rock_Sandstone_Brick","x":-5,"y":1,"z":-2},{"name":"Soil_Dirt","x":-5,"y":2,"z":-2},{"name":"Rock_Sandstone_Brick","rotation":3,"x":-5,"y":3,"z":-2},{"name":"Plant_Seaweed_Grass","support":15,"x":-5,"y":4,"z":-2},{"name":"Rock_Sandstone_Brick","x":-5,"y":1,"z":-1},{"name":"Soil_Grass_Full","x":-5,"y":2,"z":-1},{"name":"Plant_Seaweed_Grass_Tall","support":15,"x":-5,"y":3,"z":-1},{"filler":1024,"name":"Plant_Seaweed_Grass_Tall","x":-5,"y":4,"z":-1},{"name":"Rock_Sandstone_Brick","x":-5,"y":1,"z":0},{"name":"Plant_Seaweed_Grass_Tall","support":15,"x":-5,"y":2,"z":0},{"filler":1024,"name":"Plant_Seaweed_Grass_Tall","x":-5,"y":3,"z":0},{"name":"Soil_Grass_Full","x":-5,"y":1,"z":1},{"name":"Plant_Seaweed_Grass","support":15,"x":-5,"y":2,"z":1},{"name":"Soil_Dirt","x":-5,"y":1,"z":2},{"name":"Soil_Grass_Full","x":-5,"y":2,"z":2},{"name":"Plant_Coral_Bush_Green","x":-5,"y":3,"z":2},{"name":"Rock_Sandstone_Brick","x":-5,"y":1,"z":3},{"name":"Soil_Dirt","x":-5,"y":2,"z":3},{"name":"Rock_Sandstone_Brick","rotation":3,"x":-5,"y":3,"z":3},{"name":"Rock_Sandstone_Brick","x":-5,"y":1,"z":4},{"name":"Soil_Dirt","x":-5,"y":2,"z":4},{"name":"Rock_Sandstone_Brick","rotation":3,"x":-5,"y":3,"z":4},{"name":"Rock_Sandstone_Brick","x":-5,"y":1,"z":5},{"name":"Soil_Dirt","x":-5,"y":2,"z":5},{"name":"Rock_Sandstone_Brick","rotation":3,"x":-5,"y":3,"z":5},{"name":"Soil_Grass_Full","x":-5,"y":4,"z":5},{"name":"Rock_Sandstone_Brick","x":-5,"y":1,"z":6},{"name":"Soil_Dirt","x":-5,"y":2,"z":6},{"name":"Rock_Sandstone_Brick","rotation":3,"x":-5,"y":3,"z":6},{"name":"Soil_Grass_Full","x":-5,"y":4,"z":6},{"name":"Rock_Sandstone_Brick","x":-5,"y":1,"z":7},{"name":"Soil_Dirt","x":-5,"y":2,"z":7},{"name":"Rock_Sandstone_Brick","rotation":3,"x":-5,"y":3,"z":7},{"name":"Soil_Dirt","x":-5,"y":4,"z":7},{"name":"Soil_Grass_Full","x":-5,"y":5,"z":7},{"name":"Rock_Sandstone_Brick_Stairs","rotation":34,"x":-5,"y":8,"z":7},{"name":"Plant_Coral_Bush_Green","x":-5,"y":9,"z":7},{"name":"Rock_Sandstone_Brick","rotation":3,"x":-5,"y":1,"z":8},{"name":"Rock_Sandstone_Brick","rotation":3,"x":-5,"y":2,"z":8},{"name":"Rock_Sandstone_Brick","rotation":3,"x":-5,"y":3,"z":8},{"name":"Rock_Sandstone_Brick","rotation":3,"x":-5,"y":4,"z":8},{"name":"Rock_Sandstone_Brick","rotation":3,"x":-5,"y":5,"z":8},{"name":"Rock_Sandstone_Cobble","rotation":3,"x":-5,"y":6,"z":8},{"name":"Rock_Sandstone_Cobble","rotation":3,"x":-5,"y":7,"z":8},{"name":"Rock_Sandstone_Cobble","rotation":3,"x":-5,"y":8,"z":8},{"name":"Rock_Sandstone_Cobble","rotation":3,"x":-5,"y":9,"z":8},{"name":"Rock_Sandstone_Cobble","x":-5,"y":10,"z":8},{"name":"Rock_Sandstone_Cobble","x":-5,"y":11,"z":8},{"name":"Rock_Sandstone_Cobble_Half","x":-5,"y":12,"z":8},{"name":"Rock_Sandstone_Cobble","rotation":3,"x":-5,"y":1,"z":9},{"name":"Rock_Sandstone_Cobble","rotation":3,"x":-5,"y":2,"z":9},{"name":"Rock_Sandstone_Cobble","rotation":3,"x":-5,"y":3,"z":9},{"name":"Rock_Sandstone_Cobble","rotation":3,"x":-5,"y":4,"z":9},{"name":"Rock_Sandstone_Brick_Ornate","rotation":3,"x":-5,"y":5,"z":9},{"name":"Rock_Sandstone_Brick_Stairs","x":-5,"y":6,"z":9},{"name":"Soil_Dirt","x":-5,"y":1,"z":10},{"name":"Soil_Dirt","x":-5,"y":2,"z":10},{"name":"Soil_Grass_Full","x":-5,"y":3,"z":10},{"name":"Plant_Seaweed_Grass","support":15,"x":-5,"y":4,"z":10},{"name":"Soil_Grass_Full","x":-5,"y":1,"z":11},{"name":"Plant_Seaweed_Grass_Tall","support":15,"x":-5,"y":2,"z":11},{"filler":1024,"name":"Plant_Seaweed_Grass_Tall","x":-5,"y":3,"z":11},{"name":"Rock_Sandstone_Red_Brick","rotation":3,"x":-4,"y":1,"z":-10},{"name":"Rock_Sandstone_Red_Brick","rotation":3,"x":-4,"y":2,"z":-10},{"name":"Rock_Sandstone_Red_Brick_Stairs","rotation":2,"x":-4,"y":3,"z":-10},{"name":"Rock_Sandstone_Red_Brick","rotation":3,"x":-4,"y":1,"z":-9},{"name":"Rock_Sandstone_Red_Brick","rotation":3,"x":-4,"y":2,"z":-9},{"name":"Rock_Sandstone_Red_Brick","rotation":3,"x":-4,"y":3,"z":-9},{"name":"Rock_Sandstone_Red_Brick_Stairs","rotation":2,"x":-4,"y":4,"z":-9},{"name":"Rock_Sandstone_Brick","rotation":3,"x":-4,"y":1,"z":-8},{"name":"Rock_Sandstone_Brick","rotation":3,"x":-4,"y":2,"z":-8},{"name":"Rock_Sandstone_Brick","rotation":3,"x":-4,"y":3,"z":-8},{"name":"Rock_Sandstone_Brick","rotation":3,"x":-4,"y":4,"z":-8},{"name":"Rock_Sandstone_Brick_Ornate","rotation":3,"x":-4,"y":5,"z":-8},{"name":"Rock_Sandstone_Brick_Stairs","rotation":2,"x":-4,"y":6,"z":-8},{"name":"Rock_Sandstone_Brick","rotation":3,"x":-4,"y":1,"z":-7},{"name":"Rock_Sandstone_Brick","rotation":3,"x":-4,"y":2,"z":-7},{"name":"Rock_Sandstone_Brick","rotation":3,"x":-4,"y":3,"z":-7},{"name":"Rock_Sandstone_Brick","rotation":3,"x":-4,"y":4,"z":-7},{"name":"Rock_Sandstone_Brick","rotation":3,"x":-4,"y":5,"z":-7},{"name":"Rock_Sandstone_Cobble","rotation":3,"x":-4,"y":6,"z":-7},{"name":"Rock_Sandstone_Cobble","rotation":3,"x":-4,"y":7,"z":-7},{"name":"Rock_Sandstone_Cobble","rotation":3,"x":-4,"y":8,"z":-7},{"name":"Rock_Sandstone_Cobble_Half","rotation":5,"x":-4,"y":9,"z":-7},{"name":"Rock_Sandstone_Brick","x":-4,"y":1,"z":-6},{"name":"Soil_Dirt","x":-4,"y":2,"z":-6},{"name":"Soil_Grass_Full","x":-4,"y":3,"z":-6},{"name":"Rock_Sandstone_Red_Brick_Half","rotation":4,"x":-4,"y":4,"z":-6},{"name":"Rock_Sandstone_Brick","x":-4,"y":1,"z":-5},{"name":"Soil_Dirt","x":-4,"y":2,"z":-5},{"name":"Soil_Grass_Full","x":-4,"y":3,"z":-5},{"name":"Rock_Sandstone_Brick","x":-4,"y":1,"z":-4},{"name":"Soil_Dirt","x":-4,"y":2,"z":-4},{"name":"Soil_Grass_Full","x":-4,"y":3,"z":-4},{"name":"Rock_Sandstone_Brick","x":-4,"y":1,"z":-3},{"name":"Soil_Grass_Full","x":-4,"y":2,"z":-3},{"name":"Plant_Seaweed_Grass_Tall","support":15,"x":-4,"y":3,"z":-3},{"filler":1024,"name":"Plant_Seaweed_Grass_Tall","x":-4,"y":4,"z":-3},{"name":"Rock_Sandstone_Brick","x":-4,"y":1,"z":-2},{"name":"Soil_Grass_Full","x":-4,"y":2,"z":-2},{"name":"Rock_Sandstone_Brick","x":-4,"y":1,"z":-1},{"name":"Soil_Grass_Full","x":-4,"y":1,"z":0},{"name":"Plant_Seaweed_Grass","support":15,"x":-4,"y":2,"z":0},{"name":"Soil_Grass_Full","x":-4,"y":1,"z":1},{"name":"Soil_Dirt","x":-4,"y":1,"z":2},{"name":"Soil_Grass_Full","x":-4,"y":2,"z":2},{"name":"Rock_Sandstone_Brick","x":-4,"y":1,"z":3},{"name":"Soil_Grass_Full","x":-4,"y":2,"z":3},{"name":"Rock_Sandstone_Brick","x":-4,"y":1,"z":4},{"name":"Soil_Dirt","x":-4,"y":2,"z":4},{"name":"Soil_Grass_Full","x":-4,"y":3,"z":4},{"name":"Rock_Sandstone_Brick","x":-4,"y":1,"z":5},{"name":"Soil_Dirt","x":-4,"y":2,"z":5},{"name":"Soil_Grass_Full","x":-4,"y":3,"z":5},{"name":"Rock_Sandstone_Brick","x":-4,"y":1,"z":6},{"name":"Soil_Dirt","x":-4,"y":2,"z":6},{"name":"Soil_Dirt","x":-4,"y":3,"z":6},{"name":"Soil_Grass_Full","x":-4,"y":4,"z":6},{"name":"Plant_Coral_Bush_Green","x":-4,"y":5,"z":6},{"name":"Rock_Sandstone_Brick","x":-4,"y":1,"z":7},{"name":"Soil_Dirt","x":-4,"y":2,"z":7},{"name":"Soil_Dirt","x":-4,"y":3,"z":7},{"name":"Soil_Dirt","x":-4,"y":4,"z":7},{"name":"Soil_Grass_Full","x":-4,"y":5,"z":7},{"name":"Plant_Coral_Bush_Green","x":-4,"y":6,"z":7},{"name":"Rock_Sandstone_Brick_Stairs","rotation":34,"x":-4,"y":8,"z":7},{"name":"Rock_Sandstone_Brick","rotation":3,"x":-4,"y":1,"z":8},{"name":"Rock_Sandstone_Brick","rotation":3,"x":-4,"y":2,"z":8},{"name":"Rock_Sandstone_Brick","rotation":3,"x":-4,"y":3,"z":8},{"name":"Rock_Sandstone_Brick","rotation":3,"x":-4,"y":4,"z":8},{"name":"Rock_Sandstone_Brick","rotation":3,"x":-4,"y":5,"z":8},{"name":"Rock_Sandstone_Cobble","rotation":3,"x":-4,"y":6,"z":8},{"name":"Rock_Sandstone_Cobble","rotation":3,"x":-4,"y":7,"z":8},{"name":"Rock_Sandstone_Cobble","rotation":3,"x":-4,"y":8,"z":8},{"name":"Rock_Sandstone_Cobble","rotation":3,"x":-4,"y":9,"z":8},{"name":"Rock_Sandstone_Cobble","x":-4,"y":10,"z":8},{"name":"Rock_Sandstone_Cobble","x":-4,"y":11,"z":8},{"name":"Plant_Seaweed_Grass","support":15,"x":-4,"y":12,"z":8},{"name":"Rock_Sandstone_Brick","rotation":3,"x":-4,"y":1,"z":9},{"name":"Rock_Sandstone_Brick","rotation":3,"x":-4,"y":2,"z":9},{"name":"Rock_Sandstone_Brick","rotation":3,"x":-4,"y":3,"z":9},{"name":"Rock_Sandstone_Brick","rotation":3,"x":-4,"y":4,"z":9},{"name":"Rock_Sandstone_Brick_Ornate","rotation":3,"x":-4,"y":5,"z":9},{"name":"Rock_Sandstone_Brick_Stairs","x":-4,"y":6,"z":9},{"name":"Rock_Sandstone_Red_Cobble","rotation":3,"x":-4,"y":1,"z":10},{"name":"Rock_Sandstone_Red_Brick","rotation":3,"x":-4,"y":2,"z":10},{"name":"Rock_Sandstone_Red_Brick","rotation":3,"x":-4,"y":3,"z":10},{"name":"Rock_Sandstone_Red_Brick_Stairs","x":-4,"y":4,"z":10},{"name":"Rock_Sandstone_Red_Brick","rotation":3,"x":-4,"y":1,"z":11},{"name":"Rock_Sandstone_Red_Brick","rotation":3,"x":-4,"y":2,"z":11},{"name":"Rock_Sandstone_Red_Brick_Stairs","x":-4,"y":3,"z":11},{"name":"Rock_Sandstone_Red_Cobble","rotation":3,"x":-3,"y":1,"z":-10},{"name":"Rock_Sandstone_Red_Brick","rotation":3,"x":-3,"y":2,"z":-10},{"name":"Rock_Sandstone_Red_Brick_Stairs","rotation":2,"x":-3,"y":3,"z":-10},{"name":"Rock_Sandstone_Red_Brick","rotation":3,"x":-3,"y":1,"z":-9},{"name":"Rock_Sandstone_Red_Brick","rotation":3,"x":-3,"y":2,"z":-9},{"name":"Rock_Sandstone_Red_Brick","rotation":3,"x":-3,"y":3,"z":-9},{"name":"Rock_Sandstone_Red_Brick_Stairs","rotation":2,"x":-3,"y":4,"z":-9},{"name":"Rock_Sandstone_Brick","rotation":3,"x":-3,"y":1,"z":-8},{"name":"Rock_Sandstone_Brick","rotation":3,"x":-3,"y":2,"z":-8},{"name":"Rock_Sandstone_Brick","rotation":3,"x":-3,"y":3,"z":-8},{"name":"Rock_Sandstone_Brick","rotation":3,"x":-3,"y":4,"z":-8},{"name":"Plant_Seaweed_Grass","support":15,"x":-3,"y":5,"z":-8},{"name":"Rock_Sandstone_Brick","rotation":3,"x":-3,"y":1,"z":-7},{"name":"Rock_Sandstone_Brick","rotation":3,"x":-3,"y":2,"z":-7},{"name":"Rock_Sandstone_Brick","rotation":3,"x":-3,"y":3,"z":-7},{"name":"Rock_Sandstone_Brick","rotation":3,"x":-3,"y":4,"z":-7},{"name":"Plant_Seaweed_Grass","support":15,"x":-3,"y":5,"z":-7},{"name":"Rock_Sandstone_Cobble_Half","rotation":5,"x":-3,"y":6,"z":-7},{"name":"Rock_Sandstone_Cobble_Half","rotation":5,"x":-3,"y":7,"z":-7},{"name":"Rock_Sandstone_Brick","x":-3,"y":1,"z":-6},{"name":"Soil_Dirt","x":-3,"y":2,"z":-6},{"name":"Soil_Grass_Full","x":-3,"y":3,"z":-6},{"name":"Rock_Sandstone_Red_Brick_Half","rotation":4,"x":-3,"y":4,"z":-6},{"name":"Rock_Sandstone_Brick","x":-3,"y":1,"z":-5},{"name":"Soil_Dirt","x":-3,"y":2,"z":-5},{"name":"Soil_Grass_Full","x":-3,"y":3,"z":-5},{"name":"Plant_Seaweed_Grass","support":15,"x":-3,"y":4,"z":-5},{"name":"Rock_Sandstone_Brick","x":-3,"y":1,"z":-4},{"name":"Soil_Grass_Full","x":-3,"y":2,"z":-4},{"name":"Rock_Sandstone_Brick","x":-3,"y":1,"z":-3},{"name":"Plant_Seaweed_Grass","support":15,"x":-3,"y":2,"z":-3},{"name":"Rock_Sandstone_Brick","x":-3,"y":1,"z":-2},{"name":"Plant_Seaweed_Grass","support":15,"x":-3,"y":2,"z":-2},{"name":"Soil_Grass_Full","x":-3,"y":1,"z":-1},{"name":"Rubble_Sandstone","support":15,"x":-3,"y":2,"z":-1},{"name":"Soil_Grass_Full","x":-3,"y":1,"z":0},{"name":"Plant_Seaweed_Grass","support":15,"x":-3,"y":2,"z":0},{"name":"Soil_Grass_Full","x":-3,"y":1,"z":1},{"name":"Plant_Seaweed_Grass","support":15,"x":-3,"y":2,"z":1},{"name":"Soil_Grass_Full","x":-3,"y":1,"z":2},{"name":"Rock_Sandstone_Brick","x":-3,"y":1,"z":3},{"name":"Soil_Grass_Full","x":-3,"y":2,"z":3},{"name":"Rock_Sandstone_Brick","x":-3,"y":1,"z":4},{"name":"Soil_Grass_Full","x":-3,"y":2,"z":4},{"name":"Plant_Coral_Model_Green","x":-3,"y":3,"z":4},{"name":"Rock_Sandstone_Brick","x":-3,"y":1,"z":5},{"name":"Soil_Dirt","x":-3,"y":2,"z":5},{"name":"Soil_Grass_Full","x":-3,"y":3,"z":5},{"name":"Plant_Coral_Bush_Green","x":-3,"y":4,"z":5},{"name":"Rock_Sandstone_Brick","x":-3,"y":1,"z":6},{"name":"Soil_Dirt","x":-3,"y":2,"z":6},{"name":"Soil_Dirt","x":-3,"y":3,"z":6},{"name":"Soil_Grass_Full","x":-3,"y":4,"z":6},{"name":"Plant_Coral_Bush_Green","x":-3,"y":5,"z":6},{"name":"Rock_Sandstone_Brick","x":-3,"y":1,"z":7},{"name":"Soil_Dirt","x":-3,"y":2,"z":7},{"name":"Soil_Dirt","x":-3,"y":3,"z":7},{"name":"Soil_Grass_Full","x":-3,"y":4,"z":7},{"name":"Plant_Coral_Bush_Green","x":-3,"y":5,"z":7},{"name":"Rock_Sandstone_Brick_Stairs","rotation":34,"x":-3,"y":8,"z":7},{"name":"Plant_Coral_Bush_Green","x":-3,"y":9,"z":7},{"name":"Rock_Sandstone_Brick","rotation":3,"x":-3,"y":1,"z":8},{"name":"Rock_Sandstone_Brick","rotation":3,"x":-3,"y":2,"z":8},{"name":"Rock_Sandstone_Brick","rotation":3,"x":-3,"y":3,"z":8},{"name":"Rock_Sandstone_Brick","rotation":3,"x":-3,"y":4,"z":8},{"name":"Rock_Sandstone_Brick","rotation":3,"x":-3,"y":5,"z":8},{"name":"Rock_Sandstone_Cobble","rotation":3,"x":-3,"y":6,"z":8},{"name":"Plant_Coral_Bush_Green","x":-3,"y":7,"z":8},{"name":"Rock_Sandstone_Cobble","rotation":3,"x":-3,"y":8,"z":8},{"name":"Rock_Sandstone_Cobble","rotation":3,"x":-3,"y":9,"z":8},{"name":"Rock_Sandstone_Cobble","x":-3,"y":10,"z":8},{"name":"Rock_Sandstone_Cobble_Half","x":-3,"y":11,"z":8},{"name":"Rock_Sandstone_Brick","rotation":3,"x":-3,"y":1,"z":9},{"name":"Rock_Sandstone_Brick","rotation":3,"x":-3,"y":2,"z":9},{"name":"Rock_Sandstone_Brick","rotation":3,"x":-3,"y":3,"z":9},{"name":"Rock_Sandstone_Brick","rotation":3,"x":-3,"y":4,"z":9},{"name":"Rock_Sandstone_Brick_Ornate","rotation":3,"x":-3,"y":5,"z":9},{"name":"Rock_Sandstone_Brick_Stairs","x":-3,"y":6,"z":9},{"name":"Rock_Sandstone_Red_Brick","rotation":3,"x":-3,"y":1,"z":10},{"name":"Rock_Sandstone_Red_Brick","rotation":3,"x":-3,"y":2,"z":10},{"name":"Rock_Sandstone_Red_Brick","rotation":3,"x":-3,"y":3,"z":10},{"name":"Rock_Sandstone_Red_Brick_Stairs","x":-3,"y":4,"z":10},{"name":"Rock_Sandstone_Red_Brick","rotation":3,"x":-3,"y":1,"z":11},{"name":"Rock_Sandstone_Red_Brick","rotation":3,"x":-3,"y":2,"z":11},{"name":"Rock_Sandstone_Red_Brick_Stairs","x":-3,"y":3,"z":11},{"name":"Rock_Sandstone_Brick","rotation":3,"x":-2,"y":1,"z":-7},{"name":"Rock_Sandstone_Cobble_Half","rotation":7,"x":-2,"y":5,"z":-7},{"name":"Rock_Sandstone_Cobble_Half","rotation":7,"x":-2,"y":6,"z":-7},{"name":"Rock_Sandstone_Cobble_Half","rotation":7,"x":-2,"y":7,"z":-7},{"name":"Rock_Sandstone_Cobble_Half","rotation":7,"x":-2,"y":8,"z":-7},{"name":"Rock_Sandstone_Brick","x":-2,"y":1,"z":-6},{"name":"Soil_Dirt","x":-2,"y":2,"z":-6},{"name":"Soil_Grass_Full","x":-2,"y":3,"z":-6},{"name":"Plant_Seaweed_Grass_Tall","support":15,"x":-2,"y":4,"z":-6},{"filler":1024,"name":"Plant_Seaweed_Grass_Tall","x":-2,"y":5,"z":-6},{"name":"Rock_Sandstone_Brick","x":-2,"y":1,"z":-5},{"name":"Soil_Grass_Full","x":-2,"y":2,"z":-5},{"name":"Plant_Seaweed_Grass","support":15,"x":-2,"y":3,"z":-5},{"name":"Rock_Sandstone_Brick","x":-2,"y":1,"z":-4},{"name":"Rock_Sandstone_Brick","x":-2,"y":2,"z":-4},{"name":"Rock_Sandstone_Brick","x":-2,"y":1,"z":-3},{"name":"Rock_Sandstone_Brick_Half","x":-2,"y":2,"z":-3},{"name":"Rock_Sandstone_Brick","x":-2,"y":1,"z":-2},{"name":"Rock_Sandstone_Brick","x":-2,"y":1,"z":-1},{"name":"Plant_Seaweed_Grass","support":15,"x":-2,"y":2,"z":-1},{"name":"Soil_Grass_Full","x":-2,"y":1,"z":0},{"name":"Soil_Grass_Full","x":-2,"y":1,"z":1},{"name":"Soil_Grass_Full","x":-2,"y":1,"z":2},{"name":"Plant_Seaweed_Grass","support":15,"x":-2,"y":2,"z":2},{"name":"Rock_Sandstone_Brick","x":-2,"y":1,"z":3},{"name":"Soil_Grass_Full","x":-2,"y":2,"z":3},{"name":"Rock_Sandstone_Brick","x":-2,"y":1,"z":4},{"name":"Soil_Dirt","x":-2,"y":2,"z":4},{"name":"Soil_Grass_Full","x":-2,"y":3,"z":4},{"name":"Rock_Sandstone_Brick","x":-2,"y":1,"z":5},{"name":"Soil_Dirt","x":-2,"y":2,"z":5},{"name":"Soil_Grass_Full","x":-2,"y":3,"z":5},{"name":"Plant_Coral_Bush_Green","x":-2,"y":4,"z":5},{"name":"Rock_Sandstone_Brick","x":-2,"y":1,"z":6},{"name":"Soil_Dirt","x":-2,"y":2,"z":6},{"name":"Soil_Grass_Full","x":-2,"y":3,"z":6},{"name":"Plant_Coral_Bush_Green","x":-2,"y":4,"z":6},{"name":"Rock_Sandstone_Brick","x":-2,"y":1,"z":7},{"name":"Soil_Dirt","x":-2,"y":2,"z":7},{"name":"Soil_Dirt","x":-2,"y":3,"z":7},{"name":"Soil_Grass_Full","x":-2,"y":4,"z":7},{"name":"Plant_Coral_Bush_Green","x":-2,"y":5,"z":7},{"name":"Rock_Sandstone_Brick_Stairs","rotation":34,"x":-2,"y":8,"z":7},{"name":"Plant_Coral_Bush_Green","x":-2,"y":9,"z":7},{"name":"Rock_Sandstone_Brick","rotation":3,"x":-2,"y":1,"z":8},{"name":"Rock_Sandstone_Brick","rotation":3,"x":-2,"y":2,"z":8},{"name":"Rock_Sandstone_Brick","rotation":3,"x":-2,"y":3,"z":8},{"name":"Rock_Sandstone_Brick","rotation":3,"x":-2,"y":4,"z":8},{"name":"Rock_Sandstone_Brick","rotation":3,"x":-2,"y":5,"z":8},{"name":"Rock_Sandstone_Cobble","rotation":3,"x":-2,"y":6,"z":8},{"name":"Plant_Coral_Bush_Green","x":-2,"y":7,"z":8},{"name":"Rock_Sandstone_Cobble","rotation":3,"x":-2,"y":8,"z":8},{"name":"Rock_Sandstone_Cobble","rotation":3,"x":-2,"y":9,"z":8},{"name":"Rock_Sandstone_Cobble_Half","rotation":5,"x":-2,"y":10,"z":8},{"name":"Rock_Sandstone_Brick","rotation":3,"x":-2,"y":1,"z":9},{"name":"Rock_Sandstone_Brick","rotation":3,"x":-2,"y":2,"z":9},{"name":"Rock_Sandstone_Cobble","rotation":3,"x":-2,"y":3,"z":9},{"name":"Rock_Sandstone_Cobble","rotation":3,"x":-2,"y":4,"z":9},{"name":"Rock_Sandstone_Brick_Ornate","rotation":3,"x":-2,"y":5,"z":9},{"name":"Rock_Sandstone_Brick_Stairs","x":-2,"y":6,"z":9},{"name":"Soil_Grass_Full","x":-2,"y":1,"z":10},{"name":"Plant_Seaweed_Grass_Tall","support":15,"x":-2,"y":2,"z":10},{"filler":1024,"name":"Plant_Seaweed_Grass_Tall","x":-2,"y":3,"z":10},{"name":"Rock_Sandstone_Brick","x":-1,"y":1,"z":-9},{"name":"Plant_Seaweed_Grass_Tall","support":15,"x":-1,"y":2,"z":-9},{"filler":1024,"name":"Plant_Seaweed_Grass_Tall","x":-1,"y":3,"z":-9},{"name":"Rock_Sandstone_Brick","rotation":3,"x":-1,"y":1,"z":-8},{"name":"Rock_Sandstone_Brick","rotation":3,"x":-1,"y":2,"z":-8},{"name":"Rock_Sandstone_Cobble","rotation":3,"x":-1,"y":3,"z":-8},{"name":"Rock_Sandstone_Cobble","rotation":3,"x":-1,"y":4,"z":-8},{"name":"Rock_Sandstone_Brick_Ornate","rotation":3,"x":-1,"y":5,"z":-8},{"name":"Rock_Sandstone_Brick_Stairs","rotation":2,"x":-1,"y":6,"z":-8},{"name":"Rock_Sandstone_Brick","rotation":3,"x":-1,"y":1,"z":-7},{"name":"Rock_Sandstone_Brick","rotation":3,"x":-1,"y":2,"z":-7},{"name":"Rock_Sandstone_Brick","rotation":3,"x":-1,"y":3,"z":-7},{"name":"Rock_Sandstone_Brick","rotation":3,"x":-1,"y":4,"z":-7},{"name":"Rock_Sandstone_Brick","rotation":3,"x":-1,"y":5,"z":-7},{"name":"Rock_Sandstone_Cobble","rotation":3,"x":-1,"y":6,"z":-7},{"name":"Rock_Sandstone_Cobble","rotation":3,"x":-1,"y":7,"z":-7},{"name":"Rock_Sandstone_Cobble","rotation":3,"x":-1,"y":8,"z":-7},{"name":"Rock_Sandstone_Cobble_Half","x":-1,"y":9,"z":-7},{"name":"Rock_Sandstone_Brick","x":-1,"y":1,"z":-6},{"name":"Soil_Grass_Full","x":-1,"y":2,"z":-6},{"name":"Rock_Sandstone_Red_Brick_Half","rotation":4,"x":-1,"y":4,"z":-6},{"name":"Rock_Sandstone_Brick","x":-1,"y":1,"z":-5},{"name":"Soil_Grass_Full","x":-1,"y":2,"z":-5},{"name":"Plant_Seaweed_Grass_Tall","support":15,"x":-1,"y":3,"z":-5},{"filler":1024,"name":"Plant_Seaweed_Grass_Tall","x":-1,"y":4,"z":-5},{"name":"Rock_Sandstone_Brick","x":-1,"y":1,"z":-4},{"name":"Rubble_Sandstone_Medium","support":15,"x":-1,"y":1,"z":-3},{"name":"Plant_Coral_Model_Green","x":-1,"y":1,"z":-2},{"name":"Rubble_Sandstone","support":15,"x":-1,"y":1,"z":0},{"name":"Soil_Grass_Full","x":-1,"y":1,"z":1},{"name":"Plant_Seaweed_Grass","support":15,"x":-1,"y":2,"z":1},{"name":"Rock_Sandstone_Brick","x":-1,"y":1,"z":2},{"name":"Rock_Sandstone_Cobble_Half","x":-1,"y":2,"z":2},{"name":"Rock_Sandstone_Brick","x":-1,"y":1,"z":3},{"name":"Soil_Grass_Full","x":-1,"y":2,"z":3},{"name":"Plant_Coral_Bush_Green","x":-1,"y":3,"z":3},{"name":"Rock_Sandstone_Brick","x":-1,"y":1,"z":4},{"name":"Rock_Sandstone_Brick","x":-1,"y":2,"z":4},{"name":"Rock_Sandstone_Brick","x":-1,"y":1,"z":5},{"name":"Soil_Dirt","x":-1,"y":2,"z":5},{"name":"Soil_Grass_Full","x":-1,"y":3,"z":5},{"name":"Plant_Coral_Bush_Green","x":-1,"y":4,"z":5},{"name":"Rock_Sandstone_Brick","x":-1,"y":1,"z":6},{"name":"Soil_Dirt","x":-1,"y":2,"z":6},{"name":"Soil_Grass_Full","x":-1,"y":3,"z":6},{"name":"Plant_Coral_Bush_Green","x":-1,"y":4,"z":6},{"name":"Rock_Sandstone_Brick","x":-1,"y":1,"z":7},{"name":"Soil_Dirt","x":-1,"y":2,"z":7},{"name":"Soil_Grass_Full","x":-1,"y":3,"z":7},{"name":"Rock_Sandstone_Red_Brick_Half","rotation":6,"x":-1,"y":4,"z":7},{"name":"Rock_Sandstone_Brick_Stairs","rotation":34,"x":-1,"y":8,"z":7},{"name":"Plant_Coral_Bush_Green","x":-1,"y":9,"z":7},{"name":"Rock_Sandstone_Brick","rotation":3,"x":-1,"y":1,"z":8},{"name":"Rock_Sandstone_Brick","rotation":3,"x":-1,"y":2,"z":8},{"name":"Rock_Sandstone_Brick","rotation":3,"x":-1,"y":3,"z":8},{"name":"Rock_Sandstone_Brick","rotation":3,"x":-1,"y":4,"z":8},{"name":"Rock_Sandstone_Brick","rotation":3,"x":-1,"y":5,"z":8},{"name":"Plant_Coral_Bush_Green","x":-1,"y":6,"z":8},{"name":"Rock_Sandstone_Cobble","rotation":3,"x":-1,"y":8,"z":8},{"name":"Rock_Sandstone_Cobble","rotation":3,"x":-1,"y":9,"z":8},{"name":"Plant_Coral_Bush_Green","x":-1,"y":10,"z":8},{"name":"Rock_Sandstone_Cobble","rotation":3,"x":-1,"y":1,"z":9},{"name":"Rock_Sandstone_Brick","rotation":3,"x":-1,"y":2,"z":9},{"name":"Rock_Sandstone_Brick","rotation":3,"x":-1,"y":3,"z":9},{"name":"Rock_Sandstone_Cobble","rotation":3,"x":-1,"y":4,"z":9},{"name":"Rock_Sandstone_Brick_Ornate","rotation":3,"x":-1,"y":5,"z":9},{"name":"Rock_Sandstone_Brick_Stairs","x":-1,"y":6,"z":9},{"name":"Soil_Grass_Full","x":-1,"y":1,"z":10},{"name":"Plant_Seaweed_Grass","support":15,"x":-1,"y":2,"z":10},{"name":"Rock_Sandstone_Red_Brick","rotation":3,"x":0,"y":1,"z":-10},{"name":"Rock_Sandstone_Red_Brick","rotation":3,"x":0,"y":2,"z":-10},{"name":"Rock_Sandstone_Red_Brick_Stairs","rotation":2,"x":0,"y":3,"z":-10},{"name":"Rock_Sandstone_Red_Brick","rotation":3,"x":0,"y":1,"z":-9},{"name":"Rock_Sandstone_Red_Brick","rotation":3,"x":0,"y":2,"z":-9},{"name":"Rock_Sandstone_Red_Brick","rotation":3,"x":0,"y":3,"z":-9},{"name":"Rock_Sandstone_Red_Brick_Stairs","rotation":2,"x":0,"y":4,"z":-9},{"name":"Rock_Sandstone_Brick","rotation":3,"x":0,"y":1,"z":-8},{"name":"Rock_Sandstone_Brick","rotation":3,"x":0,"y":2,"z":-8},{"name":"Rock_Sandstone_Brick","rotation":3,"x":0,"y":3,"z":-8},{"name":"Rock_Sandstone_Brick","rotation":3,"x":0,"y":4,"z":-8},{"name":"Rock_Sandstone_Brick_Ornate","rotation":3,"x":0,"y":5,"z":-8},{"name":"Rock_Sandstone_Brick_Stairs","rotation":2,"x":0,"y":6,"z":-8},{"name":"Rock_Sandstone_Brick","rotation":3,"x":0,"y":1,"z":-7},{"name":"Rock_Sandstone_Brick","rotation":3,"x":0,"y":2,"z":-7},{"name":"Rock_Sandstone_Brick","rotation":3,"x":0,"y":3,"z":-7},{"name":"Rock_Sandstone_Brick","rotation":3,"x":0,"y":4,"z":-7},{"name":"Rock_Sandstone_Brick","rotation":3,"x":0,"y":5,"z":-7},{"name":"Rock_Sandstone_Cobble","rotation":3,"x":0,"y":6,"z":-7},{"name":"Rock_Sandstone_Cobble","rotation":3,"x":0,"y":7,"z":-7},{"name":"Rock_Sandstone_Cobble","rotation":3,"x":0,"y":8,"z":-7},{"name":"Rock_Sandstone_Cobble","rotation":3,"x":0,"y":9,"z":-7},{"name":"Rock_Sandstone_Cobble_Half","rotation":7,"x":0,"y":10,"z":-7},{"name":"Rock_Sandstone_Cobble_Half","rotation":7,"x":0,"y":11,"z":-7},{"name":"Rock_Sandstone_Cobble_Half","rotation":7,"x":0,"y":12,"z":-7},{"name":"Rock_Sandstone_Brick","x":0,"y":1,"z":-6},{"name":"Soil_Grass_Full","x":0,"y":2,"z":-6},{"name":"Plant_Seaweed_Grass","support":15,"x":0,"y":3,"z":-6},{"name":"Rock_Sandstone_Red_Brick_Half","rotation":4,"x":0,"y":4,"z":-6},{"name":"Rock_Sandstone_Brick_Stairs","rotation":10,"x":0,"y":8,"z":-6},{"name":"Rock_Sandstone_Brick","x":0,"y":1,"z":-5},{"name":"Plant_Seaweed_Grass","support":15,"x":0,"y":2,"z":-5},{"name":"Rock_Sandstone_Brick_Half","x":0,"y":1,"z":-4},{"name":"Rock_Sandstone_Brick","x":0,"y":1,"z":-3},{"name":"Rubble_Sandstone","support":15,"x":0,"y":1,"z":-2},{"name":"Soil_Grass_Full","x":0,"y":1,"z":0},{"name":"Plant_Seaweed_Grass","support":15,"x":0,"y":2,"z":0},{"name":"Soil_Grass_Full","x":0,"y":1,"z":1},{"name":"Rubble_Sandstone","support":15,"x":0,"y":2,"z":1},{"name":"Rock_Sandstone_Brick","x":0,"y":1,"z":2},{"name":"Rock_Sandstone_Brick","x":0,"y":2,"z":2},{"name":"Rock_Sandstone_Brick","x":0,"y":1,"z":3},{"name":"Soil_Grass_Full","x":0,"y":2,"z":3},{"name":"Rock_Sandstone_Brick","x":0,"y":1,"z":4},{"name":"Soil_Grass_Full","x":0,"y":2,"z":4},{"name":"Rock_Sandstone_Brick","x":0,"y":1,"z":5},{"name":"Soil_Grass_Full","x":0,"y":2,"z":5},{"name":"Soil_Grass_Full","x":0,"y":3,"z":5},{"name":"Plant_Coral_Bush_Green","x":0,"y":4,"z":5},{"name":"Rock_Sandstone_Brick","x":0,"y":1,"z":6},{"name":"Soil_Dirt","x":0,"y":2,"z":6},{"name":"Soil_Grass_Full","x":0,"y":3,"z":6},{"name":"Plant_Coral_Bush_Green","x":0,"y":4,"z":6},{"name":"Rock_Sandstone_Brick","x":0,"y":1,"z":7},{"name":"Soil_Dirt","x":0,"y":2,"z":7},{"name":"Soil_Dirt","x":0,"y":3,"z":7},{"name":"Soil_Grass_Full","x":0,"y":4,"z":7},{"name":"Plant_Coral_Bush_Green","x":0,"y":5,"z":7},{"name":"Rock_Sandstone_Brick_Stairs","rotation":34,"x":0,"y":8,"z":7},{"name":"Plant_Coral_Bush_Green","x":0,"y":9,"z":7},{"name":"Rock_Sandstone_Brick","rotation":3,"x":0,"y":1,"z":8},{"name":"Rock_Sandstone_Brick","rotation":3,"x":0,"y":2,"z":8},{"name":"Rock_Sandstone_Brick","rotation":3,"x":0,"y":3,"z":8},{"name":"Rock_Sandstone_Brick","rotation":3,"x":0,"y":4,"z":8},{"name":"Rock_Sandstone_Brick","rotation":3,"x":0,"y":5,"z":8},{"name":"Plant_Coral_Bush_Green","x":0,"y":6,"z":8},{"name":"Rock_Sandstone_Cobble","rotation":3,"x":0,"y":7,"z":8},{"name":"Rock_Sandstone_Cobble","rotation":3,"x":0,"y":8,"z":8},{"name":"Rock_Sandstone_Cobble_Half","x":0,"y":9,"z":8},{"name":"Rock_Sandstone_Brick","rotation":3,"x":0,"y":1,"z":9},{"name":"Rock_Sandstone_Brick","rotation":3,"x":0,"y":2,"z":9},{"name":"Rock_Sandstone_Brick","rotation":3,"x":0,"y":3,"z":9},{"name":"Rock_Sandstone_Brick","rotation":3,"x":0,"y":4,"z":9},{"name":"Rock_Sandstone_Brick_Ornate","rotation":3,"x":0,"y":5,"z":9},{"name":"Rock_Sandstone_Brick_Stairs","x":0,"y":6,"z":9},{"name":"Rock_Sandstone_Red_Brick","rotation":3,"x":0,"y":1,"z":10},{"name":"Rock_Sandstone_Red_Brick","rotation":3,"x":0,"y":2,"z":10},{"name":"Rock_Sandstone_Red_Brick","rotation":3,"x":0,"y":3,"z":10},{"name":"Rock_Sandstone_Red_Brick_Stairs","x":0,"y":4,"z":10},{"name":"Rock_Sandstone_Red_Brick","rotation":3,"x":0,"y":1,"z":11},{"name":"Rock_Sandstone_Red_Brick","rotation":3,"x":0,"y":2,"z":11},{"name":"Rock_Sandstone_Red_Brick_Stairs","x":0,"y":3,"z":11},{"name":"Rock_Sandstone_Red_Cobble","rotation":3,"x":1,"y":1,"z":-10},{"name":"Rock_Sandstone_Red_Brick","rotation":3,"x":1,"y":2,"z":-10},{"name":"Rock_Sandstone_Red_Brick_Stairs","rotation":2,"x":1,"y":3,"z":-10},{"name":"Rock_Sandstone_Red_Brick","rotation":3,"x":1,"y":1,"z":-9},{"name":"Rock_Sandstone_Red_Brick","rotation":3,"x":1,"y":2,"z":-9},{"name":"Rock_Sandstone_Red_Brick","rotation":3,"x":1,"y":3,"z":-9},{"name":"Rock_Sandstone_Red_Brick_Stairs","rotation":2,"x":1,"y":4,"z":-9},{"name":"Rock_Sandstone_Brick","rotation":3,"x":1,"y":1,"z":-8},{"name":"Rock_Sandstone_Brick","rotation":3,"x":1,"y":2,"z":-8},{"name":"Rock_Sandstone_Brick","rotation":3,"x":1,"y":3,"z":-8},{"name":"Rock_Sandstone_Brick","rotation":3,"x":1,"y":4,"z":-8},{"name":"Rock_Sandstone_Brick_Ornate","rotation":3,"x":1,"y":5,"z":-8},{"name":"Rock_Sandstone_Brick_Stairs","rotation":2,"x":1,"y":6,"z":-8},{"name":"Rock_Sandstone_Brick","rotation":3,"x":1,"y":1,"z":-7},{"name":"Rock_Sandstone_Brick","rotation":3,"x":1,"y":2,"z":-7},{"name":"Rock_Sandstone_Brick","rotation":3,"x":1,"y":3,"z":-7},{"name":"Rock_Sandstone_Brick","rotation":3,"x":1,"y":4,"z":-7},{"name":"Rock_Sandstone_Brick","rotation":3,"x":1,"y":5,"z":-7},{"name":"Rock_Sandstone_Cobble","rotation":3,"x":1,"y":6,"z":-7},{"name":"Rock_Sandstone_Cobble","rotation":3,"x":1,"y":7,"z":-7},{"name":"Rock_Sandstone_Cobble","rotation":3,"x":1,"y":8,"z":-7},{"name":"Rock_Sandstone_Cobble","rotation":3,"x":1,"y":9,"z":-7},{"name":"Rock_Sandstone_Cobble","x":1,"y":10,"z":-7},{"name":"Rock_Sandstone_Cobble","x":1,"y":11,"z":-7},{"name":"Rock_Sandstone_Cobble","x":1,"y":12,"z":-7},{"name":"Rock_Sandstone_Cobble_Half","x":1,"y":13,"z":-7},{"name":"Rock_Sandstone_Brick","x":1,"y":1,"z":-6},{"name":"Soil_Grass_Full","x":1,"y":2,"z":-6},{"name":"Rock_Sandstone_Red_Brick_Half","rotation":4,"x":1,"y":4,"z":-6},{"name":"Rock_Sandstone_Brick_Stairs","rotation":10,"x":1,"y":8,"z":-6},{"name":"Plant_Seaweed_Grass_Tall","support":15,"x":1,"y":9,"z":-6},{"filler":1024,"name":"Plant_Seaweed_Grass_Tall","x":1,"y":10,"z":-6},{"name":"Rock_Sandstone_Brick","x":1,"y":1,"z":-5},{"name":"Plant_Seaweed_Grass","support":15,"x":1,"y":2,"z":-5},{"name":"Rock_Sandstone_Brick_Half","x":1,"y":1,"z":-4},{"name":"Rubble_Sandstone_Medium","support":15,"x":1,"y":1,"z":-3},{"name":"Soil_Grass_Full","x":1,"y":1,"z":-1},{"name":"Soil_Grass_Full","x":1,"y":1,"z":0},{"name":"Plant_Seaweed_Grass","support":15,"x":1,"y":2,"z":0},{"name":"Rock_Sandstone_Brick","rotation":3,"x":1,"y":1,"z":1},{"name":"Plant_Seaweed_Grass","support":15,"x":1,"y":2,"z":1},{"name":"Rock_Sandstone_Brick","x":1,"y":1,"z":2},{"name":"Soil_Grass_Full","x":1,"y":2,"z":2},{"name":"Rock_Sandstone_Brick","x":1,"y":1,"z":3},{"name":"Soil_Grass_Full","x":1,"y":2,"z":3},{"name":"Rock_Sandstone_Brick","x":1,"y":1,"z":4},{"name":"Soil_Dirt","x":1,"y":2,"z":4},{"name":"Soil_Grass_Full","x":1,"y":3,"z":4},{"name":"Rock_Sandstone_Brick","x":1,"y":1,"z":5},{"name":"Soil_Dirt","x":1,"y":2,"z":5},{"name":"Soil_Grass_Full","x":1,"y":3,"z":5},{"name":"Rock_Sandstone_Brick","x":1,"y":1,"z":6},{"name":"Soil_Dirt","x":1,"y":2,"z":6},{"name":"Soil_Dirt","x":1,"y":3,"z":6},{"name":"Soil_Grass_Full","x":1,"y":4,"z":6},{"name":"Plant_Coral_Bush_Green","x":1,"y":5,"z":6},{"name":"Rock_Sandstone_Brick","x":1,"y":1,"z":7},{"name":"Soil_Dirt","x":1,"y":2,"z":7},{"name":"Soil_Dirt","x":1,"y":3,"z":7},{"name":"Soil_Dirt","x":1,"y":4,"z":7},{"name":"Soil_Grass_Full","x":1,"y":5,"z":7},{"name":"Plant_Coral_Bush_Green","x":1,"y":6,"z":7},{"name":"Rock_Sandstone_Brick_Stairs","rotation":34,"x":1,"y":8,"z":7},{"name":"Plant_Coral_Bush_Green","x":1,"y":9,"z":7},{"name":"Rock_Sandstone_Brick","rotation":3,"x":1,"y":1,"z":8},{"name":"Rock_Sandstone_Brick","rotation":3,"x":1,"y":2,"z":8},{"name":"Rock_Sandstone_Brick","rotation":3,"x":1,"y":3,"z":8},{"name":"Rock_Sandstone_Brick","rotation":3,"x":1,"y":4,"z":8},{"name":"Rock_Sandstone_Brick","rotation":3,"x":1,"y":5,"z":8},{"name":"Rock_Sandstone_Cobble","rotation":3,"x":1,"y":6,"z":8},{"name":"Rock_Sandstone_Cobble","rotation":3,"x":1,"y":7,"z":8},{"name":"Rock_Sandstone_Cobble","rotation":3,"x":1,"y":8,"z":8},{"name":"Rock_Sandstone_Cobble","rotation":3,"x":1,"y":9,"z":8},{"name":"Plant_Seaweed_Grass_Tall","support":15,"x":1,"y":10,"z":8},{"filler":1024,"name":"Plant_Seaweed_Grass_Tall","x":1,"y":11,"z":8},{"name":"Rock_Sandstone_Brick","rotation":3,"x":1,"y":1,"z":9},{"name":"Rock_Sandstone_Brick","rotation":3,"x":1,"y":2,"z":9},{"name":"Rock_Sandstone_Brick","rotation":3,"x":1,"y":3,"z":9},{"name":"Rock_Sandstone_Brick","rotation":3,"x":1,"y":4,"z":9},{"name":"Rock_Sandstone_Brick_Ornate","rotation":3,"x":1,"y":5,"z":9},{"name":"Rock_Sandstone_Brick_Stairs","x":1,"y":6,"z":9},{"name":"Rock_Sandstone_Red_Brick","rotation":3,"x":1,"y":1,"z":10},{"name":"Rock_Sandstone_Red_Brick","rotation":3,"x":1,"y":2,"z":10},{"name":"Rock_Sandstone_Red_Brick","rotation":3,"x":1,"y":3,"z":10},{"name":"Rock_Sandstone_Red_Brick_Stairs","x":1,"y":4,"z":10},{"name":"Rock_Sandstone_Red_Brick","rotation":3,"x":1,"y":1,"z":11},{"name":"Rock_Sandstone_Red_Brick","rotation":3,"x":1,"y":2,"z":11},{"name":"Rock_Sandstone_Red_Brick_Stairs","x":1,"y":3,"z":11},{"name":"Rock_Sandstone","x":2,"y":1,"z":-9},{"name":"Plant_Coral_Bush_Green","x":2,"y":2,"z":-9},{"name":"Rock_Sandstone_Cobble","rotation":3,"x":2,"y":1,"z":-8},{"name":"Rock_Sandstone_Cobble","rotation":3,"x":2,"y":2,"z":-8},{"name":"Rock_Sandstone_Cobble","rotation":3,"x":2,"y":3,"z":-8},{"name":"Rock_Sandstone_Cobble","rotation":3,"x":2,"y":4,"z":-8},{"name":"Rock_Sandstone_Brick_Ornate","rotation":3,"x":2,"y":5,"z":-8},{"name":"Rock_Sandstone_Brick_Stairs","rotation":2,"x":2,"y":6,"z":-8},{"name":"Rock_Sandstone_Brick","rotation":3,"x":2,"y":1,"z":-7},{"name":"Rock_Sandstone_Brick","rotation":3,"x":2,"y":2,"z":-7},{"name":"Rock_Sandstone_Brick","rotation":3,"x":2,"y":3,"z":-7},{"name":"Rock_Sandstone_Brick","rotation":3,"x":2,"y":4,"z":-7},{"name":"Rock_Sandstone_Brick","rotation":3,"x":2,"y":5,"z":-7},{"name":"Rock_Sandstone_Cobble","rotation":3,"x":2,"y":6,"z":-7},{"name":"Rock_Sandstone_Cobble","rotation":3,"x":2,"y":7,"z":-7},{"name":"Rock_Sandstone_Cobble","rotation":3,"x":2,"y":8,"z":-7},{"name":"Rock_Sandstone_Cobble","rotation":3,"x":2,"y":9,"z":-7},{"name":"Rock_Sandstone_Cobble","x":2,"y":10,"z":-7},{"name":"Rock_Sandstone_Cobble_Half","rotation":5,"x":2,"y":11,"z":-7},{"name":"Rock_Sandstone_Brick","x":2,"y":1,"z":-6},{"name":"Soil_Grass_Full","x":2,"y":2,"z":-6},{"name":"Rock_Sandstone_Red_Brick_Half","rotation":4,"x":2,"y":4,"z":-6},{"name":"Rock_Sandstone_Brick_Stairs","rotation":10,"x":2,"y":8,"z":-6},{"name":"Plant_Seaweed_Grass","support":15,"x":2,"y":9,"z":-6},{"name":"Rock_Sandstone_Brick","x":2,"y":1,"z":-5},{"name":"Rock_Sandstone_Cobble_Half","x":2,"y":2,"z":-5},{"name":"Rock_Sandstone_Cobble_Half","x":2,"y":1,"z":-4},{"name":"Soil_Grass_Full","x":2,"y":1,"z":-2},{"name":"Rubble_Sandstone","support":15,"x":2,"y":1,"z":-1},{"name":"Soil_Grass_Full","x":2,"y":1,"z":0},{"name":"Plant_Seaweed_Grass","support":15,"x":2,"y":2,"z":0},{"name":"Rock_Sandstone_Brick","x":2,"y":1,"z":1},{"name":"Plant_Seaweed_Grass","support":15,"x":2,"y":2,"z":1},{"name":"Soil_Grass_Full","x":2,"y":1,"z":2},{"name":"Rock_Sandstone_Brick","x":2,"y":1,"z":3},{"name":"Soil_Grass_Full","x":2,"y":2,"z":3},{"name":"Rock_Sandstone_Brick","x":2,"y":1,"z":4},{"name":"Soil_Dirt","x":2,"y":2,"z":4},{"name":"Soil_Grass_Full","x":2,"y":3,"z":4},{"name":"Rock_Sandstone_Brick","x":2,"y":1,"z":5},{"name":"Soil_Dirt","x":2,"y":2,"z":5},{"name":"Soil_Grass_Full","x":2,"y":3,"z":5},{"name":"Rock_Sandstone_Brick","x":2,"y":1,"z":6},{"name":"Soil_Dirt","x":2,"y":2,"z":6},{"name":"Soil_Dirt","x":2,"y":3,"z":6},{"name":"Soil_Grass_Full","x":2,"y":4,"z":6},{"name":"Rock_Sandstone_Brick","x":2,"y":1,"z":7},{"name":"Soil_Dirt","x":2,"y":2,"z":7},{"name":"Soil_Dirt","x":2,"y":3,"z":7},{"name":"Soil_Grass_Full","x":2,"y":4,"z":7},{"name":"Plant_Coral_Bush_Green","x":2,"y":5,"z":7},{"name":"Rock_Sandstone_Brick","rotation":3,"x":2,"y":1,"z":8},{"name":"Rock_Sandstone_Brick","rotation":3,"x":2,"y":2,"z":8},{"name":"Rock_Sandstone_Brick","rotation":3,"x":2,"y":3,"z":8},{"name":"Rock_Sandstone_Brick","rotation":3,"x":2,"y":4,"z":8},{"name":"Rock_Sandstone_Brick","rotation":3,"x":2,"y":5,"z":8},{"name":"Rock_Sandstone_Cobble","rotation":3,"x":2,"y":6,"z":8},{"name":"Rock_Sandstone_Cobble","rotation":3,"x":2,"y":7,"z":8},{"name":"Rock_Sandstone_Cobble","rotation":3,"x":2,"y":8,"z":8},{"name":"Rock_Sandstone_Cobble_Half","x":2,"y":9,"z":8},{"name":"Rock_Sandstone_Brick","rotation":3,"x":2,"y":1,"z":9},{"name":"Rock_Sandstone_Brick","rotation":3,"x":2,"y":2,"z":9},{"name":"Rock_Sandstone_Cobble","rotation":3,"x":2,"y":3,"z":9},{"name":"Rock_Sandstone_Cobble","rotation":3,"x":2,"y":4,"z":9},{"name":"Rock_Sandstone_Brick_Ornate","rotation":3,"x":2,"y":5,"z":9},{"name":"Rock_Sandstone_Brick_Stairs","x":2,"y":6,"z":9},{"name":"Soil_Grass_Full","x":2,"y":1,"z":10},{"name":"Plant_Seaweed_Grass","support":15,"x":2,"y":2,"z":10},{"name":"Rock_Sandstone","x":3,"y":1,"z":-9},{"name":"Plant_Coral_Bush_Green","x":3,"y":2,"z":-9},{"name":"Rock_Sandstone_Cobble","rotation":3,"x":3,"y":1,"z":-8},{"name":"Rock_Sandstone_Cobble","rotation":3,"x":3,"y":2,"z":-8},{"name":"Rock_Sandstone_Cobble","rotation":3,"x":3,"y":3,"z":-8},{"name":"Rock_Sandstone_Cobble","rotation":3,"x":3,"y":4,"z":-8},{"name":"Rock_Sandstone_Brick_Ornate","rotation":3,"x":3,"y":5,"z":-8},{"name":"Rock_Sandstone_Brick_Stairs","rotation":2,"x":3,"y":6,"z":-8},{"name":"Rock_Sandstone_Brick","rotation":3,"x":3,"y":1,"z":-7},{"name":"Rock_Sandstone_Brick","rotation":3,"x":3,"y":2,"z":-7},{"name":"Rock_Sandstone_Brick","rotation":3,"x":3,"y":3,"z":-7},{"name":"Rock_Sandstone_Brick","rotation":3,"x":3,"y":4,"z":-7},{"name":"Rock_Sandstone_Brick","rotation":3,"x":3,"y":5,"z":-7},{"name":"Rock_Sandstone_Cobble","rotation":3,"x":3,"y":6,"z":-7},{"name":"Rock_Sandstone_Cobble","rotation":3,"x":3,"y":7,"z":-7},{"name":"Rock_Sandstone_Cobble","rotation":3,"x":3,"y":8,"z":-7},{"name":"Rock_Sandstone_Cobble","rotation":3,"x":3,"y":9,"z":-7},{"name":"Rock_Sandstone_Cobble_Half","x":3,"y":10,"z":-7},{"name":"Rock_Sandstone_Brick","x":3,"y":1,"z":-6},{"name":"Soil_Grass_Full","x":3,"y":2,"z":-6},{"name":"Plant_Coral_Bush_Green","x":3,"y":3,"z":-6},{"name":"Rock_Sandstone_Red_Brick_Half","rotation":4,"x":3,"y":4,"z":-6},{"name":"Rock_Sandstone_Brick_Stairs","rotation":10,"x":3,"y":8,"z":-6},{"name":"Rock_Sandstone_Brick","x":3,"y":1,"z":-5},{"name":"Rubble_Sandstone","support":15,"x":3,"y":2,"z":-5},{"name":"Rock_Sandstone_Brick","x":3,"y":1,"z":-4},{"name":"Rock_Sandstone_Cobble_Half","x":3,"y":2,"z":-4},{"name":"Soil_Grass_Full","x":3,"y":1,"z":-3},{"name":"Soil_Grass_Full","x":3,"y":1,"z":-2},{"name":"Soil_Grass_Full","x":3,"y":1,"z":-1},{"name":"Soil_Grass_Full","x":3,"y":1,"z":0},{"name":"Rock_Sandstone_Brick","x":3,"y":1,"z":1},{"name":"Plant_Seaweed_Grass","support":15,"x":3,"y":2,"z":1},{"name":"Rock_Sandstone_Brick","x":3,"y":1,"z":2},{"name":"Plant_Seaweed_Grass","support":15,"x":3,"y":2,"z":2},{"name":"Rock_Sandstone_Brick","x":3,"y":1,"z":3},{"name":"Soil_Grass_Full","x":3,"y":2,"z":3},{"name":"Plant_Seaweed_Grass","support":15,"x":3,"y":3,"z":3},{"name":"Rock_Sandstone_Brick","x":3,"y":1,"z":4},{"name":"Soil_Grass_Full","x":3,"y":2,"z":4},{"name":"Rock_Sandstone_Brick","x":3,"y":1,"z":5},{"name":"Soil_Dirt","x":3,"y":2,"z":5},{"name":"Soil_Grass_Full","x":3,"y":3,"z":5},{"name":"Rock_Sandstone_Brick","x":3,"y":1,"z":6},{"name":"Soil_Dirt","x":3,"y":2,"z":6},{"name":"Soil_Grass_Full","x":3,"y":3,"z":6},{"name":"Plant_Coral_Model_Green","x":3,"y":4,"z":6},{"name":"Rock_Sandstone_Brick","x":3,"y":1,"z":7},{"name":"Soil_Dirt","x":3,"y":2,"z":7},{"name":"Soil_Grass_Full","x":3,"y":3,"z":7},{"name":"Rock_Sandstone_Red_Brick_Half","rotation":6,"x":3,"y":4,"z":7},{"name":"Rock_Sandstone_Brick","rotation":3,"x":3,"y":1,"z":8},{"name":"Rock_Sandstone_Brick","rotation":3,"x":3,"y":2,"z":8},{"name":"Rock_Sandstone_Brick","rotation":3,"x":3,"y":3,"z":8},{"name":"Rock_Sandstone_Brick","rotation":3,"x":3,"y":4,"z":8},{"name":"Rock_Sandstone_Brick","rotation":3,"x":3,"y":5,"z":8},{"name":"Rock_Sandstone_Cobble","rotation":3,"x":3,"y":6,"z":8},{"name":"Rock_Sandstone_Cobble","rotation":3,"x":3,"y":7,"z":8},{"name":"Rock_Sandstone_Cobble_Half","rotation":5,"x":3,"y":8,"z":8},{"name":"Rock_Sandstone_Cobble","rotation":3,"x":3,"y":1,"z":9},{"name":"Rock_Sandstone_Cobble","rotation":3,"x":3,"y":2,"z":9},{"name":"Rock_Sandstone_Cobble","rotation":3,"x":3,"y":3,"z":9},{"name":"Rock_Sandstone_Cobble","rotation":3,"x":3,"y":4,"z":9},{"name":"Rock_Sandstone_Brick_Ornate","rotation":3,"x":3,"y":5,"z":9},{"name":"Rock_Sandstone_Brick_Stairs","x":3,"y":6,"z":9},{"name":"Soil_Dirt","x":3,"y":1,"z":10},{"name":"Soil_Grass_Full","x":3,"y":2,"z":10},{"name":"Plant_Seaweed_Grass","support":15,"x":3,"y":3,"z":10},{"name":"Soil_Grass_Full","x":3,"y":1,"z":11},{"name":"Plant_Seaweed_Grass","support":15,"x":3,"y":2,"z":11},{"name":"Rock_Sandstone_Red_Cobble","rotation":3,"x":4,"y":1,"z":-10},{"name":"Rock_Sandstone_Red_Brick","rotation":3,"x":4,"y":2,"z":-10},{"name":"Rock_Sandstone_Red_Brick_Stairs","rotation":2,"x":4,"y":3,"z":-10},{"name":"Rock_Sandstone_Red_Brick","rotation":3,"x":4,"y":1,"z":-9},{"name":"Rock_Sandstone_Red_Brick","rotation":3,"x":4,"y":2,"z":-9},{"name":"Rock_Sandstone_Red_Brick","rotation":3,"x":4,"y":3,"z":-9},{"name":"Rock_Sandstone_Red_Brick_Stairs","rotation":2,"x":4,"y":4,"z":-9},{"name":"Rock_Sandstone_Brick","rotation":3,"x":4,"y":1,"z":-8},{"name":"Rock_Sandstone_Brick","rotation":3,"x":4,"y":2,"z":-8},{"name":"Rock_Sandstone_Brick","rotation":3,"x":4,"y":3,"z":-8},{"name":"Rock_Sandstone_Brick","rotation":3,"x":4,"y":4,"z":-8},{"name":"Rock_Sandstone_Brick_Ornate","rotation":3,"x":4,"y":5,"z":-8},{"name":"Rock_Sandstone_Brick_Stairs","rotation":2,"x":4,"y":6,"z":-8},{"name":"Rock_Sandstone_Brick","rotation":3,"x":4,"y":1,"z":-7},{"name":"Rock_Sandstone_Brick","rotation":3,"x":4,"y":2,"z":-7},{"name":"Rock_Sandstone_Brick","rotation":3,"x":4,"y":3,"z":-7},{"name":"Rock_Sandstone_Brick","rotation":3,"x":4,"y":4,"z":-7},{"name":"Rock_Sandstone_Brick","rotation":3,"x":4,"y":5,"z":-7},{"name":"Rock_Sandstone_Cobble","rotation":3,"x":4,"y":6,"z":-7},{"name":"Plant_Seaweed_Grass","support":15,"x":4,"y":7,"z":-7},{"name":"Rock_Sandstone_Cobble_Half","rotation":5,"x":4,"y":8,"z":-7},{"name":"Rock_Sandstone_Cobble_Half","rotation":5,"x":4,"y":9,"z":-7},{"name":"Rock_Sandstone_Brick","x":4,"y":1,"z":-6},{"name":"Soil_Grass_Full","x":4,"y":2,"z":-6},{"name":"Plant_Coral_Bush_Green","x":4,"y":3,"z":-6},{"name":"Rock_Sandstone_Red_Brick_Half","rotation":4,"x":4,"y":4,"z":-6},{"name":"Rock_Sandstone_Brick","x":4,"y":1,"z":-5},{"name":"Soil_Grass_Full","x":4,"y":2,"z":-5},{"name":"Plant_Coral_Bush_Green","x":4,"y":3,"z":-5},{"name":"Soil_Grass_Full","x":4,"y":1,"z":-4},{"name":"Rock_Sandstone_Brick","x":4,"y":1,"z":-3},{"name":"Rock_Sandstone_Brick","x":4,"y":1,"z":-2},{"name":"Soil_Grass_Full","x":4,"y":1,"z":-1},{"name":"Rubble_Sandstone","support":15,"x":4,"y":2,"z":-1},{"name":"Rock_Sandstone_Brick","x":4,"y":1,"z":0},{"name":"Rock_Sandstone_Brick","x":4,"y":1,"z":1},{"name":"Plant_Seaweed_Grass","support":15,"x":4,"y":2,"z":1},{"name":"Soil_Grass_Full","x":4,"y":1,"z":2},{"name":"Plant_Seaweed_Grass","support":15,"x":4,"y":2,"z":2},{"name":"Rock_Sandstone_Brick","x":4,"y":1,"z":3},{"name":"Soil_Grass_Full","x":4,"y":2,"z":3},{"name":"Plant_Seaweed_Grass","support":15,"x":4,"y":3,"z":3},{"name":"Rock_Sandstone_Brick","x":4,"y":1,"z":4},{"name":"Soil_Grass_Full","x":4,"y":2,"z":4},{"name":"Plant_Seaweed_Grass_Tall","support":15,"x":4,"y":3,"z":4},{"filler":1024,"name":"Plant_Seaweed_Grass_Tall","x":4,"y":4,"z":4},{"name":"Rock_Sandstone_Brick","x":4,"y":1,"z":5},{"name":"Soil_Grass_Full","x":4,"y":2,"z":5},{"name":"Plant_Seaweed_Grass","support":15,"x":4,"y":3,"z":5},{"name":"Rock_Sandstone_Brick","x":4,"y":1,"z":6},{"name":"Soil_Dirt","x":4,"y":2,"z":6},{"name":"Soil_Grass_Full","x":4,"y":3,"z":6},{"name":"Rock_Sandstone_Brick","x":4,"y":1,"z":7},{"name":"Soil_Dirt","x":4,"y":2,"z":7},{"name":"Soil_Grass_Full","x":4,"y":3,"z":7},{"name":"Rock_Sandstone_Red_Brick_Half","rotation":6,"x":4,"y":4,"z":7},{"name":"Rock_Sandstone_Brick","rotation":3,"x":4,"y":1,"z":8},{"name":"Rock_Sandstone_Brick","rotation":3,"x":4,"y":2,"z":8},{"name":"Rock_Sandstone_Brick","rotation":3,"x":4,"y":3,"z":8},{"name":"Rock_Sandstone_Brick","rotation":3,"x":4,"y":4,"z":8},{"name":"Rock_Sandstone_Brick","rotation":3,"x":4,"y":5,"z":8},{"name":"Rock_Sandstone_Cobble","rotation":3,"x":4,"y":6,"z":8},{"name":"Rock_Sandstone_Cobble_Half","x":4,"y":7,"z":8},{"name":"Rock_Sandstone_Cobble_Half","rotation":7,"x":4,"y":9,"z":8},{"name":"Rock_Sandstone_Brick","rotation":3,"x":4,"y":1,"z":9},{"name":"Rock_Sandstone_Brick","rotation":3,"x":4,"y":2,"z":9},{"name":"Rock_Sandstone_Brick","rotation":3,"x":4,"y":3,"z":9},{"name":"Rock_Sandstone_Brick","rotation":3,"x":4,"y":4,"z":9},{"name":"Rock_Sandstone_Brick_Ornate","rotation":3,"x":4,"y":5,"z":9},{"name":"Rock_Sandstone_Brick_Stairs","x":4,"y":6,"z":9},{"name":"Rock_Sandstone_Red_Brick","rotation":3,"x":4,"y":1,"z":10},{"name":"Rock_Sandstone_Red_Brick","rotation":3,"x":4,"y":2,"z":10},{"name":"Rock_Sandstone_Red_Brick","rotation":3,"x":4,"y":3,"z":10},{"name":"Rock_Sandstone_Red_Brick_Stairs","x":4,"y":4,"z":10},{"name":"Rock_Sandstone_Red_Brick","rotation":3,"x":4,"y":1,"z":11},{"name":"Rock_Sandstone_Red_Brick","rotation":3,"x":4,"y":2,"z":11},{"name":"Rock_Sandstone_Red_Brick_Stairs","x":4,"y":3,"z":11},{"name":"Rock_Sandstone_Red_Brick","rotation":3,"x":5,"y":1,"z":-10},{"name":"Rock_Sandstone_Red_Brick","rotation":3,"x":5,"y":2,"z":-10},{"name":"Plant_Coral_Bush_Green","x":5,"y":3,"z":-10},{"name":"Rock_Sandstone_Red_Brick","rotation":3,"x":5,"y":1,"z":-9},{"name":"Rock_Sandstone_Red_Brick","rotation":3,"x":5,"y":2,"z":-9},{"name":"Rock_Sandstone_Red_Brick","rotation":3,"x":5,"y":3,"z":-9},{"name":"Plant_Coral_Bush_Green","x":5,"y":4,"z":-9},{"name":"Rock_Sandstone_Brick","rotation":3,"x":5,"y":1,"z":-8},{"name":"Rock_Sandstone_Brick","rotation":3,"x":5,"y":2,"z":-8},{"name":"Rock_Sandstone_Brick","rotation":3,"x":5,"y":3,"z":-8},{"name":"Rock_Sandstone_Brick","rotation":3,"x":5,"y":4,"z":-8},{"name":"Rock_Sandstone_Brick_Ornate","rotation":3,"x":5,"y":5,"z":-8},{"name":"Plant_Coral_Bush_Green","x":5,"y":6,"z":-8},{"name":"Rock_Sandstone_Brick","rotation":3,"x":5,"y":1,"z":-7},{"name":"Rock_Sandstone_Brick","rotation":3,"x":5,"y":2,"z":-7},{"name":"Rock_Sandstone_Brick","rotation":3,"x":5,"y":3,"z":-7},{"name":"Rock_Sandstone_Brick","rotation":3,"x":5,"y":4,"z":-7},{"name":"Rock_Sandstone_Brick","rotation":3,"x":5,"y":5,"z":-7},{"name":"Plant_Coral_Bush_Green","x":5,"y":6,"z":-7},{"name":"Rock_Sandstone_Brick","x":5,"y":1,"z":-6},{"name":"Soil_Grass_Full","x":5,"y":2,"z":-6},{"name":"Plant_Coral_Bush_Green","x":5,"y":3,"z":-6},{"name":"Rock_Sandstone_Red_Brick_Half","rotation":4,"x":5,"y":4,"z":-6},{"name":"Rock_Sandstone_Brick","x":5,"y":1,"z":-5},{"name":"Soil_Grass_Full","x":5,"y":2,"z":-5},{"name":"Plant_Coral_Bush_Green","x":5,"y":3,"z":-5},{"name":"Rock_Sandstone_Brick","x":5,"y":1,"z":-4},{"name":"Soil_Grass_Full","x":5,"y":2,"z":-4},{"name":"Plant_Coral_Bush_Green","x":5,"y":3,"z":-4},{"name":"Rock_Sandstone_Brick","x":5,"y":1,"z":-3},{"name":"Soil_Grass_Full","x":5,"y":2,"z":-3},{"name":"Soil_Grass_Full","x":5,"y":1,"z":-2},{"name":"Rock_Sandstone_Brick","x":5,"y":1,"z":-1},{"name":"Soil_Grass_Full","x":5,"y":1,"z":0},{"name":"Rock_Sandstone_Brick","x":5,"y":1,"z":1},{"name":"Soil_Grass_Full","x":5,"y":2,"z":1},{"name":"Plant_Seaweed_Grass","support":15,"x":5,"y":3,"z":1},{"name":"Rock_Sandstone_Brick","x":5,"y":1,"z":2},{"name":"Soil_Grass_Full","x":5,"y":2,"z":2},{"name":"Rock_Sandstone_Brick","x":5,"y":1,"z":3},{"name":"Soil_Grass_Full","x":5,"y":2,"z":3},{"name":"Plant_Seaweed_Grass","support":15,"x":5,"y":3,"z":3},{"name":"Rock_Sandstone_Brick","x":5,"y":1,"z":4},{"name":"Soil_Grass_Full","x":5,"y":2,"z":4},{"name":"Plant_Seaweed_Grass","support":15,"x":5,"y":3,"z":4},{"name":"Rock_Sandstone_Brick","x":5,"y":1,"z":5},{"name":"Soil_Grass_Full","x":5,"y":2,"z":5},{"name":"Plant_Seaweed_Grass","support":15,"x":5,"y":3,"z":5},{"name":"Rock_Sandstone_Brick","x":5,"y":1,"z":6},{"name":"Soil_Grass_Full","x":5,"y":2,"z":6},{"name":"Plant_Seaweed_Grass","support":15,"x":5,"y":3,"z":6},{"name":"Rock_Sandstone_Brick","x":5,"y":1,"z":7},{"name":"Soil_Grass_Full","x":5,"y":2,"z":7},{"name":"Plant_Seaweed_Grass","support":15,"x":5,"y":3,"z":7},{"name":"Rock_Sandstone_Red_Brick_Half","rotation":6,"x":5,"y":4,"z":7},{"name":"Rock_Sandstone_Brick","rotation":3,"x":5,"y":1,"z":8},{"name":"Rock_Sandstone_Brick","rotation":3,"x":5,"y":2,"z":8},{"name":"Rock_Sandstone_Brick","rotation":3,"x":5,"y":3,"z":8},{"name":"Rock_Sandstone_Brick","rotation":3,"x":5,"y":4,"z":8},{"name":"Rubble_Sandstone","support":15,"x":5,"y":5,"z":8},{"name":"Rock_Sandstone_Cobble_Half","rotation":7,"x":5,"y":7,"z":8},{"name":"Rock_Sandstone_Cobble","x":5,"y":8,"z":8},{"name":"Rock_Sandstone_Cobble","rotation":3,"x":5,"y":9,"z":8},{"name":"Rock_Sandstone_Cobble_Half","x":5,"y":10,"z":8},{"name":"Rock_Sandstone_Brick","rotation":3,"x":5,"y":1,"z":9},{"name":"Rock_Sandstone_Brick","rotation":3,"x":5,"y":2,"z":9},{"name":"Rock_Sandstone_Brick","rotation":3,"x":5,"y":3,"z":9},{"name":"Rock_Sandstone_Brick","rotation":3,"x":5,"y":4,"z":9},{"name":"Plant_Seaweed_Grass","support":15,"x":5,"y":5,"z":9},{"name":"Rock_Sandstone_Red_Brick","rotation":3,"x":5,"y":1,"z":10},{"name":"Rock_Sandstone_Red_Brick","rotation":3,"x":5,"y":2,"z":10},{"name":"Rock_Sandstone_Red_Brick","rotation":3,"x":5,"y":3,"z":10},{"name":"Rock_Sandstone_Red_Brick_Stairs","x":5,"y":4,"z":10},{"name":"Rock_Sandstone_Red_Cobble","rotation":3,"x":5,"y":1,"z":11},{"name":"Rock_Sandstone_Red_Brick","rotation":3,"x":5,"y":2,"z":11},{"name":"Rock_Sandstone_Red_Brick_Stairs","x":5,"y":3,"z":11},{"name":"Rock_Sandstone","rotation":3,"x":6,"y":1,"z":-10},{"name":"Plant_Coral_Bush_Green","x":6,"y":2,"z":-10},{"name":"Rock_Sandstone","rotation":3,"x":6,"y":1,"z":-9},{"name":"Plant_Coral_Bush_Green","x":6,"y":2,"z":-9},{"name":"Rock_Sandstone_Cobble","rotation":3,"x":6,"y":1,"z":-8},{"name":"Rock_Sandstone_Cobble","rotation":3,"x":6,"y":2,"z":-8},{"name":"Rock_Sandstone_Cobble","rotation":3,"x":6,"y":3,"z":-8},{"name":"Rock_Sandstone_Cobble","rotation":3,"x":6,"y":4,"z":-8},{"name":"Plant_Coral_Bush_Green","x":6,"y":5,"z":-8},{"name":"Rock_Sandstone_Brick","rotation":3,"x":6,"y":1,"z":-7},{"name":"Rock_Sandstone_Brick","rotation":3,"x":6,"y":2,"z":-7},{"name":"Rock_Sandstone_Brick","rotation":3,"x":6,"y":3,"z":-7},{"name":"Rock_Sandstone_Brick","rotation":3,"x":6,"y":4,"z":-7},{"name":"Rock_Sandstone_Brick","rotation":3,"x":6,"y":5,"z":-7},{"name":"Rock_Sandstone_Cobble","rotation":3,"x":6,"y":6,"z":-7},{"name":"Plant_Seaweed_Grass","support":15,"x":6,"y":7,"z":-7},{"name":"Rock_Sandstone_Cobble","rotation":3,"x":6,"y":8,"z":-7},{"name":"Rock_Sandstone_Cobble","rotation":3,"x":6,"y":9,"z":-7},{"name":"Rock_Sandstone_Cobble_Half","rotation":7,"x":6,"y":10,"z":-7},{"name":"Rock_Sandstone_Brick","x":6,"y":1,"z":-6},{"name":"Soil_Dirt","x":6,"y":2,"z":-6},{"name":"Soil_Dirt","x":6,"y":3,"z":-6},{"name":"Soil_Grass_Full","x":6,"y":4,"z":-6},{"name":"Plant_Coral_Bush_Green","x":6,"y":5,"z":-6},{"name":"Rock_Sandstone_Brick","x":6,"y":1,"z":-5},{"name":"Soil_Dirt","x":6,"y":2,"z":-5},{"name":"Soil_Dirt","x":6,"y":3,"z":-5},{"name":"Soil_Grass_Full","x":6,"y":4,"z":-5},{"name":"Plant_Coral_Bush_Green","x":6,"y":5,"z":-5},{"name":"Rock_Sandstone_Brick","x":6,"y":1,"z":-4},{"name":"Soil_Dirt","x":6,"y":2,"z":-4},{"name":"Soil_Grass_Full","x":6,"y":3,"z":-4},{"name":"Plant_Coral_Bush_Green","x":6,"y":4,"z":-4},{"name":"Rock_Sandstone_Brick","x":6,"y":1,"z":-3},{"name":"Soil_Grass_Full","x":6,"y":2,"z":-3},{"name":"Plant_Coral_Bush_Green","x":6,"y":3,"z":-3},{"name":"Rock_Sandstone_Brick","x":6,"y":1,"z":-2},{"name":"Soil_Grass_Full","x":6,"y":2,"z":-2},{"name":"Plant_Coral_Model_Green","x":6,"y":3,"z":-2},{"name":"Rock_Sandstone_Brick","x":6,"y":1,"z":-1},{"name":"Soil_Grass_Full","x":6,"y":2,"z":-1},{"name":"Rock_Sandstone_Brick","x":6,"y":1,"z":0},{"name":"Soil_Grass_Full","x":6,"y":2,"z":0},{"name":"Plant_Seaweed_Grass","support":15,"x":6,"y":3,"z":0},{"name":"Rock_Sandstone_Brick","x":6,"y":1,"z":1},{"name":"Soil_Grass_Full","x":6,"y":2,"z":1},{"name":"Plant_Seaweed_Grass","support":15,"x":6,"y":3,"z":1},{"name":"Rock_Sandstone_Brick","x":6,"y":1,"z":2},{"name":"Soil_Grass_Full","x":6,"y":2,"z":2},{"name":"Rock_Sandstone_Brick","x":6,"y":1,"z":3},{"name":"Soil_Grass_Full","x":6,"y":2,"z":3},{"name":"Rock_Sandstone_Brick","x":6,"y":1,"z":4},{"name":"Soil_Grass_Full","x":6,"y":2,"z":4},{"name":"Plant_Seaweed_Grass_Tall","support":15,"x":6,"y":3,"z":4},{"filler":1024,"name":"Plant_Seaweed_Grass_Tall","x":6,"y":4,"z":4},{"name":"Rock_Sandstone_Brick","x":6,"y":1,"z":5},{"name":"Soil_Grass_Full","x":6,"y":2,"z":5},{"name":"Plant_Seaweed_Grass_Tall","support":15,"x":6,"y":3,"z":5},{"filler":1024,"name":"Plant_Seaweed_Grass_Tall","x":6,"y":4,"z":5},{"name":"Rock_Sandstone_Brick","x":6,"y":1,"z":6},{"name":"Soil_Grass_Full","x":6,"y":2,"z":6},{"name":"Rock_Sandstone_Brick","x":6,"y":1,"z":7},{"name":"Soil_Grass_Full","x":6,"y":2,"z":7},{"name":"Rubble_Sandstone_Medium","support":15,"x":6,"y":3,"z":7},{"name":"Rock_Sandstone_Brick","rotation":3,"x":6,"y":1,"z":8},{"name":"Rock_Sandstone_Cobble","rotation":3,"x":6,"y":2,"z":8},{"name":"Rock_Sandstone_Cobble","rotation":3,"x":6,"y":3,"z":8},{"name":"Rubble_Sandstone_Medium","support":15,"x":6,"y":4,"z":8},{"name":"Rock_Sandstone_Cobble","rotation":3,"x":6,"y":6,"z":8},{"name":"Rock_Sandstone_Cobble","rotation":3,"x":6,"y":7,"z":8},{"name":"Rock_Sandstone_Cobble","rotation":3,"x":6,"y":8,"z":8},{"name":"Rock_Sandstone_Cobble","rotation":3,"x":6,"y":9,"z":8},{"name":"Plant_Seaweed_Grass","support":15,"x":6,"y":10,"z":8},{"name":"Rock_Sandstone_Cobble","rotation":3,"x":6,"y":1,"z":9},{"name":"Rock_Sandstone_Cobble","rotation":3,"x":6,"y":2,"z":9},{"name":"Rock_Sandstone_Cobble","rotation":3,"x":6,"y":3,"z":9},{"name":"Rock_Sandstone_Brick","x":6,"y":4,"z":9},{"name":"Plant_Seaweed_Grass","support":15,"x":6,"y":5,"z":9},{"name":"Rock_Sandstone","rotation":3,"x":7,"y":1,"z":-10},{"name":"Rock_Sandstone","rotation":3,"x":7,"y":1,"z":-9},{"name":"Plant_Coral_Bush_Green","x":7,"y":2,"z":-9},{"name":"Rock_Sandstone_Brick","rotation":3,"x":7,"y":1,"z":-8},{"name":"Rock_Sandstone_Cobble","rotation":3,"x":7,"y":2,"z":-8},{"name":"Rock_Sandstone_Cobble","rotation":3,"x":7,"y":3,"z":-8},{"name":"Rock_Sandstone_Cobble","rotation":3,"x":7,"y":4,"z":-8},{"name":"Rock_Sandstone_Brick_Ornate","rotation":3,"x":7,"y":5,"z":-8},{"name":"Rock_Sandstone_Brick_Stairs","rotation":2,"x":7,"y":6,"z":-8},{"name":"Rock_Sandstone_Brick","rotation":3,"x":7,"y":1,"z":-7},{"name":"Rock_Sandstone_Brick","rotation":3,"x":7,"y":2,"z":-7},{"name":"Rock_Sandstone_Brick","rotation":3,"x":7,"y":3,"z":-7},{"name":"Rock_Sandstone_Brick","rotation":3,"x":7,"y":4,"z":-7},{"name":"Rock_Sandstone_Brick","rotation":3,"x":7,"y":5,"z":-7},{"name":"Rock_Sandstone_Cobble","rotation":3,"x":7,"y":6,"z":-7},{"name":"Rock_Sandstone_Cobble","rotation":3,"x":7,"y":7,"z":-7},{"name":"Rock_Sandstone_Cobble","rotation":3,"x":7,"y":8,"z":-7},{"name":"Rock_Sandstone_Cobble","rotation":3,"x":7,"y":9,"z":-7},{"name":"Rock_Sandstone_Cobble","x":7,"y":10,"z":-7},{"name":"Rock_Sandstone_Cobble","x":7,"y":11,"z":-7},{"name":"Rock_Sandstone_Cobble_Half","x":7,"y":12,"z":-7},{"name":"Rock_Sandstone_Brick","x":7,"y":1,"z":-6},{"name":"Soil_Dirt","x":7,"y":2,"z":-6},{"name":"Soil_Dirt","x":7,"y":3,"z":-6},{"name":"Soil_Dirt","x":7,"y":4,"z":-6},{"name":"Soil_Grass_Full","x":7,"y":5,"z":-6},{"name":"Plant_Coral_Bush_Green","x":7,"y":6,"z":-6},{"name":"Rock_Sandstone_Brick","x":7,"y":1,"z":-5},{"name":"Soil_Dirt","x":7,"y":2,"z":-5},{"name":"Soil_Dirt","x":7,"y":3,"z":-5},{"name":"Soil_Grass_Full","x":7,"y":4,"z":-5},{"name":"Plant_Coral_Bush_Green","x":7,"y":5,"z":-5},{"name":"Rock_Sandstone_Brick","x":7,"y":1,"z":-4},{"name":"Soil_Dirt","x":7,"y":2,"z":-4},{"name":"Soil_Dirt","x":7,"y":3,"z":-4},{"name":"Soil_Grass_Full","x":7,"y":4,"z":-4},{"name":"Plant_Coral_Bush_Green","x":7,"y":5,"z":-4},{"name":"Rock_Sandstone_Brick_Stairs","rotation":9,"x":7,"y":8,"z":-4},{"name":"Plant_Coral_Bush_Green","x":7,"y":9,"z":-4},{"name":"Rock_Sandstone_Brick","x":7,"y":1,"z":-3},{"name":"Soil_Grass_Full","x":7,"y":2,"z":-3},{"name":"Plant_Coral_Bush_Green","x":7,"y":3,"z":-3},{"name":"Rock_Sandstone_Brick","rotation":3,"x":7,"y":1,"z":-2},{"name":"Rock_Sandstone_Brick","rotation":3,"x":7,"y":2,"z":-2},{"name":"Rock_Sandstone_Brick_Stairs","rotation":3,"x":7,"y":3,"z":-2},{"name":"Rock_Sandstone_Brick_Stairs","rotation":9,"x":7,"y":8,"z":-2},{"name":"Plant_Seaweed_Grass_Tall","support":15,"x":7,"y":9,"z":-2},{"filler":1024,"name":"Plant_Seaweed_Grass_Tall","x":7,"y":10,"z":-2},{"name":"Rock_Sandstone_Brick","rotation":3,"x":7,"y":1,"z":-1},{"name":"Rock_Sandstone_Brick","rotation":3,"x":7,"y":2,"z":-1},{"name":"Rock_Sandstone_Brick_Stairs","rotation":3,"x":7,"y":3,"z":-1},{"name":"Rock_Sandstone_Brick_Stairs","rotation":9,"x":7,"y":8,"z":-1},{"name":"Plant_Coral_Bush_Green","x":7,"y":9,"z":-1},{"name":"Rock_Sandstone_Brick","x":7,"y":1,"z":0},{"name":"Soil_Grass_Full","x":7,"y":2,"z":0},{"name":"Plant_Seaweed_Grass","support":15,"x":7,"y":3,"z":0},{"name":"Rock_Sandstone_Brick_Half","rotation":11,"x":7,"y":8,"z":0},{"name":"Plant_Coral_Bush_Green","x":7,"y":9,"z":0},{"name":"Rock_Sandstone_Brick","x":7,"y":1,"z":1},{"name":"Soil_Grass_Full","x":7,"y":2,"z":1},{"name":"Plant_Seaweed_Grass","support":15,"x":7,"y":3,"z":1},{"name":"Rock_Sandstone_Brick_Half","rotation":11,"x":7,"y":8,"z":1},{"name":"Plant_Seaweed_Grass","support":15,"x":7,"y":9,"z":1},{"name":"Rock_Sandstone_Brick","rotation":3,"x":7,"y":1,"z":2},{"name":"Rock_Sandstone_Brick","rotation":3,"x":7,"y":2,"z":2},{"name":"Rock_Sandstone_Brick_Stairs","rotation":3,"x":7,"y":3,"z":2},{"name":"Rock_Sandstone_Brick_Stairs","rotation":35,"x":7,"y":8,"z":2},{"name":"Plant_Seaweed_Grass_Tall","support":15,"x":7,"y":9,"z":2},{"filler":1024,"name":"Plant_Seaweed_Grass_Tall","x":7,"y":10,"z":2},{"name":"Rock_Sandstone_Brick","rotation":3,"x":7,"y":1,"z":3},{"name":"Rock_Sandstone_Brick","rotation":3,"x":7,"y":2,"z":3},{"name":"Rock_Sandstone_Brick_Stairs","rotation":3,"x":7,"y":3,"z":3},{"name":"Rock_Sandstone_Brick_Stairs","rotation":35,"x":7,"y":8,"z":3},{"name":"Plant_Seaweed_Grass","support":15,"x":7,"y":9,"z":3},{"name":"Rock_Sandstone_Brick","x":7,"y":1,"z":4},{"name":"Soil_Grass_Full","x":7,"y":2,"z":4},{"name":"Rock_Sandstone_Brick","x":7,"y":1,"z":5},{"name":"Soil_Grass_Full","x":7,"y":2,"z":5},{"name":"Plant_Seaweed_Grass","support":15,"x":7,"y":3,"z":5},{"name":"Rock_Sandstone_Brick_Stairs","rotation":35,"x":7,"y":8,"z":5},{"name":"Plant_Seaweed_Grass","support":15,"x":7,"y":9,"z":5},{"name":"Rock_Sandstone_Brick","x":7,"y":1,"z":6},{"name":"Soil_Grass_Full","x":7,"y":2,"z":6},{"name":"Rubble_Sandstone","support":15,"x":7,"y":3,"z":6},{"name":"Rock_Sandstone_Brick","x":7,"y":1,"z":7},{"name":"Soil_Dirt","x":7,"y":2,"z":7},{"name":"Soil_Grass_Full","x":7,"y":3,"z":7},{"name":"Rock_Sandstone_Brick_Stairs","rotation":35,"x":7,"y":8,"z":7},{"name":"Plant_Seaweed_Grass_Tall","support":15,"x":7,"y":9,"z":7},{"filler":1024,"name":"Plant_Seaweed_Grass_Tall","x":7,"y":10,"z":7},{"name":"Rock_Sandstone_Cobble","rotation":3,"x":7,"y":1,"z":8},{"name":"Rock_Sandstone_Brick","x":7,"y":2,"z":8},{"name":"Rock_Sandstone_Brick","x":7,"y":3,"z":8},{"name":"Rock_Sandstone_Brick","rotation":3,"x":7,"y":4,"z":8},{"name":"Rock_Sandstone_Brick","rotation":3,"x":7,"y":5,"z":8},{"name":"Rock_Sandstone_Cobble","rotation":3,"x":7,"y":6,"z":8},{"name":"Rock_Sandstone_Cobble","rotation":3,"x":7,"y":7,"z":8},{"name":"Rock_Sandstone_Cobble","rotation":3,"x":7,"y":8,"z":8},{"name":"Rock_Sandstone_Cobble_Half","x":7,"y":9,"z":8},{"name":"Rock_Sandstone_Cobble_Half","x":7,"y":1,"z":9},{"name":"Rock_Sandstone_Red_Brick","rotation":3,"x":8,"y":1,"z":-10},{"name":"Rock_Sandstone_Red_Cobble","rotation":3,"x":8,"y":2,"z":-10},{"name":"Rock_Sandstone_Red_Brick_Stairs","rotation":2,"x":8,"y":3,"z":-10},{"name":"Rock_Sandstone_Red_Brick","rotation":3,"x":8,"y":1,"z":-9},{"name":"Rock_Sandstone_Red_Brick","rotation":3,"x":8,"y":2,"z":-9},{"name":"Rock_Sandstone_Red_Brick","rotation":3,"x":8,"y":3,"z":-9},{"name":"Rock_Sandstone_Red_Brick_Stairs","rotation":2,"x":8,"y":4,"z":-9},{"name":"Rock_Sandstone_Brick","rotation":3,"x":8,"y":1,"z":-8},{"name":"Rock_Sandstone_Brick","rotation":3,"x":8,"y":2,"z":-8},{"name":"Rock_Sandstone_Brick","rotation":3,"x":8,"y":3,"z":-8},{"name":"Rock_Sandstone_Brick","rotation":3,"x":8,"y":4,"z":-8},{"name":"Rock_Sandstone_Brick_Ornate","rotation":3,"x":8,"y":5,"z":-8},{"name":"Rock_Sandstone_Brick_Stairs","rotation":2,"x":8,"y":6,"z":-8},{"name":"Rock_Sandstone_Brick","rotation":3,"x":8,"y":1,"z":-7},{"name":"Rock_Sandstone_Brick","rotation":3,"x":8,"y":2,"z":-7},{"name":"Rock_Sandstone_Brick","rotation":3,"x":8,"y":3,"z":-7},{"name":"Rock_Sandstone_Brick","rotation":3,"x":8,"y":4,"z":-7},{"name":"Rock_Sandstone_Brick","rotation":3,"x":8,"y":5,"z":-7},{"name":"Rock_Sandstone_Cobble","rotation":3,"x":8,"y":6,"z":-7},{"name":"Rock_Sandstone_Cobble","rotation":3,"x":8,"y":7,"z":-7},{"name":"Rock_Sandstone_Brick","rotation":3,"x":8,"y":8,"z":-7},{"name":"Rock_Sandstone_Brick","rotation":3,"x":8,"y":9,"z":-7},{"name":"Rock_Sandstone_Cobble","x":8,"y":10,"z":-7},{"name":"Rock_Sandstone_Cobble","x":8,"y":11,"z":-7},{"name":"Rock_Sandstone_Cobble","x":8,"y":12,"z":-7},{"name":"Rock_Sandstone_Cobble_Half","x":8,"y":13,"z":-7},{"name":"Rock_Sandstone_Brick","rotation":3,"x":8,"y":1,"z":-6},{"name":"Rock_Sandstone_Brick","rotation":3,"x":8,"y":2,"z":-6},{"name":"Rock_Sandstone_Brick","rotation":3,"x":8,"y":3,"z":-6},{"name":"Rock_Sandstone_Red_Brick","rotation":3,"x":8,"y":4,"z":-6},{"name":"Rock_Sandstone_Brick","rotation":3,"x":8,"y":5,"z":-6},{"name":"Rock_Sandstone_Cobble","rotation":3,"x":8,"y":6,"z":-6},{"name":"Rock_Sandstone_Cobble","rotation":3,"x":8,"y":7,"z":-6},{"name":"Rock_Sandstone_Cobble","rotation":3,"x":8,"y":8,"z":-6},{"name":"Rock_Sandstone_Brick","rotation":3,"x":8,"y":9,"z":-6},{"name":"Rock_Sandstone_Cobble","x":8,"y":10,"z":-6},{"name":"Rock_Sandstone_Cobble_Half","x":8,"y":11,"z":-6},{"name":"Rock_Sandstone_Cobble_Half","rotation":4,"x":8,"y":12,"z":-6},{"name":"Rock_Sandstone_Brick","rotation":3,"x":8,"y":1,"z":-5},{"name":"Rock_Sandstone_Brick","rotation":3,"x":8,"y":2,"z":-5},{"name":"Rock_Sandstone_Brick","rotation":3,"x":8,"y":3,"z":-5},{"name":"Rock_Sandstone_Red_Brick","rotation":3,"x":8,"y":4,"z":-5},{"name":"Rock_Sandstone_Brick","rotation":3,"x":8,"y":5,"z":-5},{"name":"Plant_Coral_Bush_Green","x":8,"y":6,"z":-5},{"name":"Rock_Sandstone_Cobble_Half","rotation":4,"x":8,"y":8,"z":-5},{"name":"Rock_Sandstone_Cobble","rotation":3,"x":8,"y":9,"z":-5},{"name":"Rock_Sandstone_Cobble_Half","rotation":4,"x":8,"y":10,"z":-5},{"name":"Rock_Sandstone_Brick","rotation":3,"x":8,"y":1,"z":-4},{"name":"Rock_Sandstone_Brick","rotation":3,"x":8,"y":2,"z":-4},{"name":"Rock_Sandstone_Brick","rotation":3,"x":8,"y":3,"z":-4},{"name":"Rock_Sandstone_Red_Brick","rotation":3,"x":8,"y":4,"z":-4},{"name":"Rock_Sandstone_Brick","rotation":3,"x":8,"y":5,"z":-4},{"name":"Rock_Sandstone_Cobble","rotation":3,"x":8,"y":6,"z":-4},{"name":"Rock_Sandstone_Cobble","rotation":3,"x":8,"y":7,"z":-4},{"name":"Rock_Sandstone_Cobble","rotation":3,"x":8,"y":8,"z":-4},{"name":"Rock_Sandstone_Cobble","rotation":3,"x":8,"y":9,"z":-4},{"name":"Plant_Coral_Bush_Green","x":8,"y":10,"z":-4},{"name":"Rock_Sandstone_Brick","rotation":3,"x":8,"y":1,"z":-3},{"name":"Rock_Sandstone_Brick","rotation":3,"x":8,"y":2,"z":-3},{"name":"Rock_Sandstone_Brick","rotation":3,"x":8,"y":3,"z":-3},{"name":"Rock_Sandstone_Red_Brick","rotation":3,"x":8,"y":4,"z":-3},{"name":"Rock_Sandstone_Red_Brick","rotation":3,"x":8,"y":5,"z":-3},{"name":"Rock_Sandstone_Red_Brick","rotation":3,"x":8,"y":6,"z":-3},{"name":"Rock_Sandstone_Red_Brick","rotation":3,"x":8,"y":7,"z":-3},{"name":"Rock_Sandstone_Red_Brick","rotation":3,"x":8,"y":8,"z":-3},{"name":"Rock_Sandstone_Red_Brick","rotation":3,"x":8,"y":9,"z":-3},{"name":"Plant_Coral_Bush_Green","x":8,"y":10,"z":-3},{"name":"Rock_Sandstone_Brick","rotation":3,"x":8,"y":1,"z":-2},{"name":"Rock_Sandstone_Brick","rotation":3,"x":8,"y":2,"z":-2},{"name":"Rock_Sandstone_Brick","rotation":3,"x":8,"y":3,"z":-2},{"name":"Rock_Sandstone_Brick","rotation":3,"x":8,"y":4,"z":-2},{"name":"Rock_Sandstone_Brick","rotation":3,"x":8,"y":5,"z":-2},{"name":"Rock_Sandstone_Cobble","rotation":3,"x":8,"y":6,"z":-2},{"name":"Rock_Sandstone_Cobble","rotation":3,"x":8,"y":7,"z":-2},{"name":"Rock_Sandstone_Cobble","rotation":3,"x":8,"y":8,"z":-2},{"name":"Rock_Sandstone_Cobble","rotation":3,"x":8,"y":9,"z":-2},{"name":"Plant_Coral_Bush_Green","x":8,"y":10,"z":-2},{"name":"Rock_Sandstone_Brick","rotation":3,"x":8,"y":1,"z":-1},{"name":"Rock_Sandstone_Brick_Decorative","rotation":3,"x":8,"y":2,"z":-1},{"name":"Rock_Sandstone_Brick","rotation":3,"x":8,"y":3,"z":-1},{"name":"Rock_Sandstone_Brick","rotation":3,"x":8,"y":4,"z":-1},{"name":"Rock_Sandstone_Cobble","rotation":3,"x":8,"y":5,"z":-1},{"name":"Rock_Sandstone_Cobble","rotation":3,"x":8,"y":6,"z":-1},{"name":"Rock_Sandstone_Cobble","rotation":3,"x":8,"y":7,"z":-1},{"name":"Rock_Sandstone_Cobble","rotation":3,"x":8,"y":8,"z":-1},{"name":"Rock_Sandstone_Cobble","rotation":3,"x":8,"y":9,"z":-1},{"name":"Plant_Coral_Bush_Green","x":8,"y":10,"z":-1},{"name":"Rock_Sandstone_Brick_Stairs","rotation":1,"x":8,"y":1,"z":0},{"name":"Rock_Sandstone_Brick_Half","rotation":11,"x":8,"y":8,"z":0},{"name":"Rock_Sandstone_Red_Brick","rotation":3,"x":8,"y":9,"z":0},{"name":"Plant_Seaweed_Grass","support":15,"x":8,"y":10,"z":0},{"name":"Rock_Sandstone_Brick_Stairs","rotation":1,"x":8,"y":1,"z":1},{"name":"Rock_Sandstone_Brick_Half","rotation":11,"x":8,"y":8,"z":1},{"name":"Rock_Sandstone_Red_Cobble","rotation":3,"x":8,"y":9,"z":1},{"name":"Plant_Seaweed_Grass_Tall","support":15,"x":8,"y":10,"z":1},{"filler":1024,"name":"Plant_Seaweed_Grass_Tall","x":8,"y":11,"z":1},{"name":"Rock_Sandstone_Brick","rotation":3,"x":8,"y":1,"z":2},{"name":"Rock_Sandstone_Brick_Decorative","rotation":3,"x":8,"y":2,"z":2},{"name":"Rock_Sandstone_Brick","rotation":3,"x":8,"y":3,"z":2},{"name":"Rock_Sandstone_Brick","rotation":3,"x":8,"y":4,"z":2},{"name":"Rock_Sandstone_Brick","rotation":3,"x":8,"y":5,"z":2},{"name":"Rock_Sandstone_Cobble","rotation":3,"x":8,"y":6,"z":2},{"name":"Rock_Sandstone_Cobble","rotation":3,"x":8,"y":7,"z":2},{"name":"Rock_Sandstone_Cobble","rotation":3,"x":8,"y":8,"z":2},{"name":"Rock_Sandstone_Cobble","rotation":3,"x":8,"y":9,"z":2},{"name":"Plant_Seaweed_Grass","support":15,"x":8,"y":10,"z":2},{"name":"Rock_Sandstone_Brick","rotation":3,"x":8,"y":1,"z":3},{"name":"Rock_Sandstone_Brick","rotation":3,"x":8,"y":2,"z":3},{"name":"Rock_Sandstone_Brick","rotation":3,"x":8,"y":3,"z":3},{"name":"Rock_Sandstone_Brick","rotation":3,"x":8,"y":4,"z":3},{"name":"Rock_Sandstone_Brick","rotation":3,"x":8,"y":5,"z":3},{"name":"Rock_Sandstone_Cobble","rotation":3,"x":8,"y":6,"z":3},{"name":"Rock_Sandstone_Cobble","rotation":3,"x":8,"y":7,"z":3},{"name":"Rock_Sandstone_Cobble","rotation":3,"x":8,"y":8,"z":3},{"name":"Rock_Sandstone_Cobble","rotation":3,"x":8,"y":9,"z":3},{"name":"Plant_Seaweed_Grass","support":15,"x":8,"y":10,"z":3},{"name":"Rock_Sandstone_Brick","rotation":3,"x":8,"y":1,"z":4},{"name":"Rock_Sandstone_Brick","rotation":3,"x":8,"y":2,"z":4},{"name":"Rock_Sandstone_Brick","rotation":3,"x":8,"y":3,"z":4},{"name":"Rock_Sandstone_Red_Brick","rotation":3,"x":8,"y":4,"z":4},{"name":"Rock_Sandstone_Red_Brick","rotation":3,"x":8,"y":5,"z":4},{"name":"Rock_Sandstone_Red_Brick","rotation":3,"x":8,"y":6,"z":4},{"name":"Rock_Sandstone_Red_Brick","rotation":3,"x":8,"y":7,"z":4},