{"anchorX":-4,"anchorY":0,"anchorZ":2,"blockIdVersion":11,"blocks":[{"name":"Rock_Sandstone_Red_Brick","rotation":7,"x":-4,"y":1,"z":-4},{"name":"Rock_Sandstone_Red_Brick","rotation":7,"x":-4,"y":1,"z":-3},{"name":"Plant_Seaweed_Grass","support":15,"x":-4,"y":2,"z":-3},{"name":"Rock_Sandstone_Red_Brick","x":-4,"y":0,"z":-2},{"name":"Soil_Grass_Full","x":-4,"y":1,"z":-2},{"name":"Plant_Seaweed_Grass_Tall","support":15,"x":-4,"y":2,"z":-2},{"filler":1024,"name":"Plant_Seaweed_Grass_Tall","x":-4,"y":3,"z":-2},{"name":"Rock_Sandstone_Red_Brick","x":-4,"y":0,"z":-1},{"name":"Rock_Sandstone_Red_Brick","rotation":7,"x":-4,"y":1,"z":-1},{"name":"Rock_Sandstone_Cobble_Half","rotation":15,"x":-4,"y":2,"z":-1},{"name":"Rock_Sandstone_Red_Brick","x":-4,"y":0,"z":0},{"name":"Rock_Sandstone_Red_Brick","rotation":7,"x":-4,"y":1,"z":0},{"name":"Rock_Sandstone_Cobble_Half","rotation":15,"x":-4,"y":2,"z":0},{"name":"Rock_Sandstone_Cobble_Half","rotation":15,"x":-4,"y":3,"z":0},{"name":"Rock_Sandstone_Red_Brick","x":-4,"y":0,"z":1},{"name":"Rock_Sandstone_Red_Brick","rotation":7,"x":-4,"y":1,"z":1},{"name":"Rock_Sandstone_Cobble_Half","rotation":15,"x":-4,"y":2,"z":1},{"name":"Rock_Sandstone_Cobble_Half","rotation":15,"x":-4,"y":3,"z":1},{"name":"Rock_Sandstone_Cobble_Half","rotation":15,"x":-4,"y":4,"z":1},{"name":"Rock_Sandstone_Cobble_Half","rotation":15,"x":-4,"y":5,"z":1},{"name":"Rock_Sandstone_Red_Brick","x":-4,"y":0,"z":2},{"name":"Rock_Sandstone_Red_Brick","rotation":7,"x":-4,"y":1,"z":2},{"name":"Rock_Sandstone_Red_Brick","rotation":7,"x":-4,"y":2,"z":2},{"name":"Rock_Sandstone_Red_Cobble","rotation":7,"x":-4,"y":3,"z":2},{"name":"Rock_Sandstone_Red_Cobble","rotation":7,"x":-4,"y":4,"z":2},{"name":"Rock_Sandstone_Red_Cobble","rotation":7,"x":-4,"y":5,"z":2},{"name":"Rock_Sandstone_Red_Brick","rotation":7,"x":-4,"y":6,"z":2},{"name":"Rock_Sandstone_Red_Brick","x":-4,"y":0,"z":3},{"name":"Rock_Sandstone_Brick","rotation":7,"x":-4,"y":1,"z":3},{"name":"Rock_Sandstone_Cobble","rotation":7,"x":-4,"y":2,"z":3},{"name":"Rock_Sandstone_Cobble","rotation":7,"x":-4,"y":3,"z":3},{"name":"Rock_Sandstone_Cobble","rotation":7,"x":-4,"y":4,"z":3},{"name":"Rock_Sandstone_Cobble","rotation":7,"x":-4,"y":5,"z":3},{"name":"Rock_Sandstone_Brick_Stairs","rotation":48,"x":-4,"y":1,"z":4},{"name":"Rock_Sandstone_Brick_Stairs","rotation":48,"x":-4,"y":2,"z":4},{"name":"Rock_Sandstone_Brick_Stairs","rotation":48,"x":-4,"y":3,"z":4},{"name":"Rock_Sandstone_Brick_Stairs","rotation":48,"x":-4,"y":4,"z":4},{"name":"Rock_Sandstone_Brick_Stairs","rotation":48,"x":-4,"y":5,"z":4},{"name":"Rock_Sandstone_Red_Cobble","rotation":7,"x":-3,"y":1,"z":-5},{"name":"Plant_Seaweed_Grass","support":15,"x":-3,"y":2,"z":-5},{"name":"Rock_Sandstone_Red_Brick","x":-3,"y":0,"z":-4},{"name":"Soil_Grass_Full","x":-3,"y":1,"z":-4},{"name":"Plant_Seaweed_Grass_Tall","support":15,"x":-3,"y":2,"z":-4},{"filler":1024,"name":"Plant_Seaweed_Grass_Tall","x":-3,"y":3,"z":-4},{"name":"Rock_Sandstone_Red_Brick","x":-3,"y":0,"z":-3},{"name":"Rock_Sandstone_Red_Brick","rotation":7,"x":-3,"y":1,"z":-3},{"name":"Plant_Seaweed_Grass","support":15,"x":-3,"y":2,"z":-3},{"name":"Rock_Sandstone_Red_Brick","x":-3,"y":0,"z":-2},{"name":"Rock_Sandstone_Red_Brick","rotation":7,"x":-3,"y":1,"z":-2},{"name":"Plant_Seaweed_Grass","support":15,"x":-3,"y":2,"z":-2},{"name":"Rock_Sandstone_Red_Brick","x":-3,"y":0,"z":-1},{"name":"Rock_Sandstone_Red_Brick","rotation":7,"x":-3,"y":1,"z":-1},{"name":"Plant_Seaweed_Grass","support":15,"x":-3,"y":2,"z":-1},{"name":"Rock_Sandstone_Red_Brick","x":-3,"y":0,"z":0},{"name":"Soil_Grass_Full","x":-3,"y":1,"z":0},{"name":"Plant_Seaweed_Grass_Tall","support":15,"x":-3,"y":2,"z":0},{"filler":1024,"name":"Plant_Seaweed_Grass_Tall","x":-3,"y":3,"z":0},{"name":"Rock_Sandstone_Red_Brick","x":-3,"y":0,"z":1},{"name":"Rock_Sandstone_Red_Brick","rotation":7,"x":-3,"y":1,"z":1},{"name":"*Furniture_Temple_Dark_Candle_State_Definitions_Off","x":-3,"y":2,"z":1},{"filler":1024,"name":"*Furniture_Temple_Dark_Candle_State_Definitions_Off","x":-3,"y":3,"z":1},{"name":"Rock_Sandstone_Red_Brick","x":-3,"y":0,"z":2},{"name":"Rock_Sandstone_Red_Brick","rotation":7,"x":-3,"y":1,"z":2},{"name":"Plant_Seaweed_Grass","support":15,"x":-3,"y":2,"z":2},{"name":"Rock_Sandstone_Red_Cobble","rotation":7,"x":-3,"y":5,"z":2},{"name":"Rock_Sandstone_Red_Cobble","rotation":7,"x":-3,"y":6,"z":2},{"name":"Plant_Coral_Model_Green","x":-3,"y":7,"z":2},{"name":"Rock_Sandstone_Red_Brick","x":-3,"y":0,"z":3},{"name":"Rock_Sandstone_Brick","rotation":7,"x":-3,"y":1,"z":3},{"name":"Rock_Sandstone_Brick_Half","x":-3,"y":2,"z":3},{"name":"Rock_Sandstone_Cobble_Half","rotation":5,"x":-3,"y":4,"z":3},{"name":"Rock_Sandstone_Cobble","rotation":7,"x":-3,"y":5,"z":3},{"name":"Rock_Sandstone_Cobble","rotation":7,"x":-3,"y":6,"z":3},{"name":"Rock_Sandstone_Cobble_Half","x":-3,"y":7,"z":3},{"name":"Rock_Sandstone_Brick_Half","rotation":4,"x":-3,"y":1,"z":4},{"name":"Rock_Sandstone_Brick_Half","x":-2,"y":1,"z":-3},{"name":"Rock_Sandstone_Brick_Stairs","rotation":15,"x":-2,"y":1,"z":-2},{"name":"Rock_Sandstone_Brick_Stairs","rotation":15,"x":-2,"y":1,"z":-1},{"name":"Rock_Sandstone_Brick_Half","x":-2,"y":1,"z":0},{"name":"Rock_Sandstone_Brick_Half","x":-2,"y":1,"z":1},{"name":"Rock_Sandstone_Brick_Stairs","rotation":15,"x":-2,"y":1,"z":2},{"name":"Rock_Sandstone_Brick_Stairs","rotation":18,"x":-2,"y":6,"z":2},{"name":"Rock_Sandstone_Cobble","rotation":7,"x":-2,"y":1,"z":3},{"name":"Plant_Seaweed_Grass","support":15,"x":-2,"y":2,"z":3},{"name":"Rock_Sandstone_Cobble_Half","rotation":8,"x":-2,"y":5,"z":3},{"name":"Rock_Sandstone_Cobble","rotation":7,"x":-2,"y":6,"z":3},{"name":"Plant_Coral_Bush_Green","x":-2,"y":7,"z":3},{"name":"Rock_Sandstone_Cobble","rotation":7,"x":-1,"y":1,"z":3},{"name":"Rock_Sandstone_Cobble_Half","rotation":7,"x":-1,"y":2,"z":3},{"name":"Rock_Sandstone_Cobble_Half","rotation":7,"x":-1,"y":4,"z":3},{"name":"Rock_Sandstone_Cobble","rotation":7,"x":-1,"y":5,"z":3},{"name":"Rock_Sandstone_Cobble","rotation":7,"x":-1,"y":6,"z":3},{"name":"Rock_Sandstone_Cobble_Half","x":-1,"y":7,"z":3},{"name":"Rock_Sandstone_Cobble","rotation":7,"x":0,"y":1,"z":3},{"name":"Rock_Sandstone_Cobble","rotation":7,"x":0,"y":2,"z":3},{"name":"Rock_Sandstone_Cobble","rotation":7,"x":0,"y":3,"z":3},{"name":"Rock_Sandstone_Cobble","rotation":7,"x":0,"y":4,"z":3},{"name":"Rock_Sandstone_Cobble","rotation":7,"x":0,"y":5,"z":3},{"name":"Rock_Sandstone_Cobble","rotation":7,"x":0,"y":6,"z":3},{"name":"Rock_Sandstone_Cobble_Half","x":0,"y":7,"z":3},{"name":"Rock_Sandstone_Brick_Stairs","rotation":16,"x":0,"y":1,"z":4},{"name":"Rock_Sandstone_Brick_Stairs","rotation":16,"x":0,"y":2,"z":4},{"name":"Rock_Sandstone_Brick_Stairs","rotation":16,"x":0,"y":3,"z":4},{"name":"Rock_Sandstone_Brick_Stairs","rotation":16,"x":0,"y":4,"z":4},{"name":"Rock_Sandstone_Brick_Stairs","rotation":16,"x":0,"y":5,"z":4},{"name":"Rock_Sandstone_Brick_Stairs","rotation":16,"x":0,"y":6,"z":4},{"name":"Soil_Grass_Full","x":1,"y":1,"z":2},{"name":"Plant_Seaweed_Grass_Tall","support":15,"x":1,"y":2,"z":2},{"filler":1024,"name":"Plant_Seaweed_Grass_Tall","x":1,"y":3,"z":2},{"name":"Rock_Sandstone_Brick","rotation":7,"x":1,"y":1,"z":3},{"name":"Rock_Sandstone_Brick","rotation":7,"x":1,"y":2,"z":3},{"name":"Rock_Sandstone_Brick","rotation":7,"x":1,"y":3,"z":3},{"name":"Rock_Sandstone_Brick","rotation":7,"x":1,"y":4,"z":3},{"name":"Rock_Sandstone_Brick","rotation":7,"x":1,"y":5,"z":3},{"name":"Rock_Sandstone_Brick_Half","x":1,"y":6,"z":3},{"name":"Rock_Sandstone_Brick_Ornate","rotation":7,"x":1,"y":1,"z":4},{"name":"Rock_Sandstone_Brick_Ornate","rotation":7,"x":1,"y":2,"z":4},{"name":"Rock_Sandstone_Brick_Ornate","rotation":7,"x":1,"y":3,"z":4},{"name":"Rock_Sandstone_Brick_Ornate","rotation":7,"x":1,"y":4,"z":4},{"name":"Rock_Sandstone_Brick_Ornate","rotation":7,"x":1,"y":5,"z":4},{"name":"Rock_Sandstone_Brick_Ornate","rotation":7,"x":1,"y":6,"z":4},{"name":"Plant_Coral_Bush_Green","x":1,"y":7,"z":4},{"name":"Soil_Grass_Full","x":2,"y":1,"z":1},{"name":"Plant_Seaweed_Grass_Tall","support":15,"x":2,"y":2,"z":1},{"filler":1024,"name":"Plant_Seaweed_Grass_Tall","x":2,"y":3,"z":1},{"name":"Soil_Grass_Full","x":2,"y":1,"z":2},{"name":"Rock_Sandstone_Red_Brick_Half","rotation":49,"x":2,"y":2,"z":2},{"name":"Rock_Sandstone_Red_Brick_Half","rotation":49,"x":2,"y":3,"z":2},{"name":"Rock_Sandstone_Red_Brick_Half","rotation":49,"x":2,"y":4,"z":2},{"name":"Rock_Sandstone_Red_Brick_Half","rotation":49,"x":2,"y":5,"z":2},{"name":"Rock_Sandstone_Brick","rotation":7,"x":2,"y":1,"z":3},{"name":"Rock_Sandstone_Brick","rotation":7,"x":2,"y":2,"z":3},{"name":"Rock_Sandstone_Brick","rotation":7,"x":2,"y":3,"z":3},{"name":"Rock_Sandstone_Brick","rotation":7,"x":2,"y":4,"z":3},{"name":"Rock_Sandstone_Brick","rotation":7,"x":2,"y":5,"z":3},{"name":"Rock_Sandstone_Brick_Half","x":2,"y":6,"z":3},{"name":"Rock_Sandstone_Cobble","rotation":7,"x":2,"y":1,"z":4},{"name":"Rock_Sandstone_Cobble","rotation":7,"x":2,"y":2,"z":4},{"name":"Rock_Sandstone_Brick","rotation":7,"x":2,"y":3,"z":4},{"name":"Rock_Sandstone_Brick","rotation":7,"x":2,"y":4,"z":4},{"name":"Rock_Sandstone_Cobble","rotation":7,"x":2,"y":5,"z":4},{"name":"Rock_Sandstone_Cobble","rotation":7,"x":2,"y":6,"z":4},{"name":"Plant_Coral_Bush_Green","x":2,"y":7,"z":4},{"name":"Rock_Sandstone_Red_Brick_Stairs","rotation":16,"x":2,"y":3,"z":5},{"name":"Rock_Sandstone_Red_Brick_Stairs","rotation":16,"x":2,"y":4,"z":5},{"name":"Plant_Coral_Bush_Green","x":2,"y":5,"z":5},{"name":"Rock_Sandstone_Brick","rotation":7,"x":3,"y":1,"z":-2},{"name":"Rock_Sandstone_Brick","rotation":7,"x":3,"y":2,"z":-2},{"name":"Plant_Seaweed_Grass","support":15,"x":3,"y":3,"z":-2},{"name":"Soil_Dirt","x":3,"y":1,"z":-1},{"name":"Rock_Sandstone_Brick","rotation":7,"x":3,"y":2,"z":-1},{"name":"Plant_Seaweed_Grass","support":15,"x":3,"y":3,"z":-1},{"name":"Soil_Dirt","x":3,"y":1,"z":0},{"name":"Rock_Sandstone_Brick","rotation":7,"x":3,"y":2,"z":0},{"name":"Plant_Seaweed_Grass","support":15,"x":3,"y":3,"z":0},{"name":"Soil_Dirt","x":3,"y":1,"z":1},{"name":"Rock_Sandstone_Brick","rotation":7,"x":3,"y":2,"z":1},{"name":"Plant_Coral_Model_Green","x":3,"y":3,"z":1},{"name":"Rock_Sandstone_Brick","rotation":7,"x":3,"y":1,"z":2},{"name":"Rock_Sandstone_Brick","rotation":7,"x":3,"y":2,"z":2},{"name":"Rock_Sandstone_Brick","rotation":7,"x":3,"y":1,"z":3},{"name":"Rock_Sandstone_Brick","rotation":7,"x":3,"y":2,"z":3},{"name":"Rock_Sandstone_Brick","rotation":7,"x":3,"y":3,"z":3},{"name":"Rock_Sandstone_Brick","rotation":7,"x":3,"y":4,"z":3},{"name":"Rock_Sandstone_Brick","rotation":7,"x":3,"y":5,"z":3},{"name":"Rock_Sandstone_Brick_Half","x":3,"y":6,"z":3},{"name":"Rock_Sandstone_Cobble","rotation":7,"x":3,"y":1,"z":4},{"name":"Rock_Sandstone_Cobble","rotation":7,"x":3,"y":2,"z":4},{"name":"Rock_Sandstone_Brick","rotation":7,"x":3,"y":3,"z":4},{"name":"Rock_Sandstone_Brick","rotation":7,"x":3,"y":4,"z":4},{"name":"Rock_Sandstone_Cobble","rotation":7,"x":3,"y":5,"z":4},{"name":"Rock_Sandstone_Brick_Half","x":3,"y":6,"z":4},{"name":"Rock_Sandstone_Red_Brick","rotation":7,"x":3,"y":3,"z":5},{"name":"Rock_Sandstone_Red_Brick","rotation":7,"x":3,"y":4,"z":5},{"name":"Plant_Coral_Bush_Green","x":3,"y":5,"z":5},{"name":"Rock_Sandstone_Red_Brick_Stairs","rotation":16,"x":3,"y":3,"z":6},{"name":"Rock_Sandstone_Red_Brick_Stairs","rotation":16,"x":3,"y":4,"z":6},{"name":"Rock_Sandstone_Brick","rotation":7,"x":4,"y":1,"z":-2},{"name":"Rock_Sandstone_Brick_Stairs","rotation":15,"x":4,"y":2,"z":-2},{"name":"Rock_Sandstone_Brick","rotation":7,"x":4,"y":1,"z":-1},{"name":"Rock_Sandstone_Brick_Stairs","rotation":15,"x":4,"y":2,"z":-1},{"name":"Rock_Sandstone_Brick","rotation":7,"x":4,"y":1,"z":0},{"name":"Rock_Sandstone_Brick_Stairs","rotation":15,"x":4,"y":2,"z":0},{"name":"Rock_Sandstone_Brick","rotation":7,"x":4,"y":1,"z":1},{"name":"Rock_Sandstone_Brick_Stairs","rotation":15,"x":4,"y":2,"z":1},{"name":"Rock_Sandstone_Brick","rotation":7,"x":4,"y":1,"z":2},{"name":"Rock_Sandstone_Brick_Stairs","rotation":15,"x":4,"y":2,"z":2},{"name":"Rock_Sandstone_Brick","rotation":7,"x":4,"y":1,"z":3},{"name":"Rock_Sandstone_Brick","rotation":7,"x":4,"y":2,"z":3},{"name":"Rock_Sandstone_Brick","rotation":7,"x":4,"y":3,"z":3},{"name":"Rock_Sandstone_Brick","rotation":7,"x":4,"y":4,"z":3},{"name":"Rock_Sandstone_Brick","rotation":7,"x":4,"y":5,"z":3},{"name":"Rock_Sandstone_Brick_Half","x":4,"y":6,"z":3},{"name":"Rock_Sandstone_Cobble","rotation":7,"x":4,"y":1,"z":4},{"name":"Rock_Sandstone_Cobble","rotation":7,"x":4,"y":2,"z":4},{"name":"Rock_Sandstone_Brick","rotation":7,"x":4,"y":3,"z":4},{"name":"Rock_Sandstone_Brick","rotation":7,"x":4,"y":4,"z":4},{"name":"Rock_Sandstone_Brick","rotation":7,"x":4,"y":5,"z":4},{"name":"Rock_Sandstone_Brick_Half","x":4,"y":6,"z":4},{"name":"Rock_Sandstone_Red_Brick","rotation":7,"x":4,"y":3,"z":5},{"name":"Rock_Sandstone_Red_Brick","rotation":7,"x":4,"y":4,"z":5},{"name":"Plant_Coral_Bush_Green","x":4,"y":5,"z":5},{"name":"Rock_Sandstone_Red_Brick","rotation":7,"x":4,"y":3,"z":6},{"name":"Rock_Sandstone_Red_Brick","rotation":7,"x":4,"y":4,"z":6},{"name":"Plant_Coral_Bush_Green","x":4,"y":5,"z":6},{"name":"Rock_Sandstone_Brick","rotation":7,"x":5,"y":1,"z":3},{"name":"Rock_Sandstone_Brick","rotation":7,"x":5,"y":2,"z":3},{"name":"Rock_Sandstone_Brick","rotation":7,"x":5,"y":3,"z":3},{"name":"Rock_Sandstone_Brick","rotation":7,"x":5,"y":4,"z":3},{"name":"Rock_Sandstone_Brick","rotation":7,"x":5,"y":5,"z":3},{"name":"Rock_Sandstone_Brick_Half","x":5,"y":6,"z":3},{"name":"Rock_Sandstone_Cobble","rotation":7,"x":5,"y":1,"z":4},{"name":"Rock_Sandstone_Cobble","rotation":7,"x":5,"y":2,"z":4},{"name":"Rock_Sandstone_Brick","rotation":7,"x":5,"y":3,"z":4},{"name":"Rock_Sandstone_Brick","rotation":7,"x":5,"y":4,"z":4},{"name":"Rock_Sandstone_Brick","rotation":7,"x":5,"y":5,"z":4},{"name":"Rock_Sandstone_Cobble","rotation":7,"x":5,"y":6,"z":4},{"name":"Plant_Coral_Bush_Green","x":5,"y":7,"z":4},{"name":"Rock_Sandstone_Red_Cobble","rotation":7,"x":5,"y":3,"z":5},{"name":"Rock_Sandstone_Red_Brick","rotation":7,"x":5,"y":4,"z":5},{"name":"Plant_Coral_Bush_Green","x":5,"y":5,"z":5},{"name":"Rock_Sandstone_Red_Brick","rotation":7,"x":5,"y":3,"z":6},{"name":"Rock_Sandstone_Red_Brick","rotation":7,"x":5,"y":4,"z":6},{"name":"Plant_Coral_Bush_Green","x":5,"y":5,"z":6}],"fluids":[{"level":1,"name":"Water_Source","x":-4,"y":1,"z":-4},{"level":1,"name":"Water_Source","x":-4,"y":1,"z":-3},{"level":1,"name":"Water_Source","x":-4,"y":2,"z":-3},{"level":1,"name":"Water_Source","x":-4,"y":0,"z":-2},{"level":1,"name":"Water_Source","x":-4,"y":1,"z":-2},{"level":1,"name":"Water_Source","x":-4,"y":2,"z":-2},{"level":1,"name":"Water_Source","x":-4,"y":3,"z":-2},{"level":1,"name":"Water_Source","x":-4,"y":0,"z":-1},{"level":1,"name":"Water_Source","x":-4,"y":1,"z":-1},{"level":1,"name":"Water_Source","x":-4,"y":2,"z":-1},{"level":1,"name":"Water_Source","x":-4,"y":0,"z":0},{"level":1,"name":"Water_Source","x":-4,"y":1,"z":0},{"level":1,"name":"Water_Source","x":-4,"y":2,"z":0},{"level":1,"name":"Water_Source","x":-4,"y":3,"z":0},{"level":1,"name":"Water_Source","x":-4,"y":0,"z":1},{"level":1,"name":"Water_Source","x":-4,"y":1,"z":1},{"level":1,"name":"Water_Source","x":-4,"y":2,"z":1},{"level":1,"name":"Water_Source","x":-4,"y":3,"z":1},{"level":1,"name":"Water_Source","x":-4,"y":4,"z":1},{"level":1,"name":"Water_Source","x":-4,"y":5,"z":1},{"level":1,"name":"Water_Source","x":-4,"y":0,"z":2},{"level":1,"name":"Water_Source","x":-4,"y":1,"z":2},{"level":1,"name":"Water_Source","x":-4,"y":2,"z":2},{"level":1,"name":"Water_Source","x":-4,"y":3,"z":2},{"level":1,"name":"Water_Source","x":-4,"y":4,"z":2},{"level":1,"name":"Water_Source","x":-4,"y":5,"z":2},{"level":1,"name":"Water_Source","x":-4,"y":6,"z":2},{"level":1,"name":"Water_Source","x":-4,"y":0,"z":3},{"level":1,"name":"Water_Source","x":-4,"y":1,"z":3},{"level":1,"name":"Water_Source","x":-4,"y":2,"z":3},{"level":1,"name":"Water_Source","x":-4,"y":3,"z":3},{"level":1,"name":"Water_Source","x":-4,"y":4,"z":3},{"level":1,"name":"Water_Source","x":-4,"y":5,"z":3},{"level":1,"name":"Water_Source","x":-4,"y":1,"z":4},{"level":1,"name":"Water_Source","x":-4,"y":2,"z":4},{"level":1,"name":"Water_Source","x":-4,"y":3,"z":4},{"level":1,"name":"Water_Source","x":-4,"y":4,"z":4},{"level":1,"name":"Water_Source","x":-4,"y":5,"z":4},{"level":1,"name":"Water_Source","x":-3,"y":1,"z":-5},{"level":1,"name":"Water_Source","x":-3,"y":2,"z":-5},{"level":1,"name":"Water_Source","x":-3,"y":0,"z":-4},{"level":1,"name":"Water_Source","x":-3,"y":1,"z":-4},{"level":1,"name":"Water_Source","x":-3,"y":2,"z":-4},{"level":1,"name":"Water_Source","x":-3,"y":3,"z":-4},{"level":1,"name":"Water_Source","x":-3,"y":0,"z":-3},{"level":1,"name":"Water_Source","x":-3,"y":1,"z":-3},{"level":1,"name":"Water_Source","x":-3,"y":2,"z":-3},{"level":1,"name":"Water_Source","x":-3,"y":0,"z":-2},{"level":1,"name":"Water_Source","x":-3,"y":1,"z":-2},{"level":1,"name":"Water_Source","x":-3,"y":2,"z":-2},{"level":1,"name":"Water_Source","x":-3,"y":0,"z":-1},{"level":1,"name":"Water_Source","x":-3,"y":1,"z":-1},{"level":1,"name":"Water_Source","x":-3,"y":2,"z":-1},{"level":1,"name":"Water_Source","x":-3,"y":0,"z":0},{"level":1,"name":"Water_Source","x":-3,"y":1,"z":0},{"level":1,"name":"Water_Source","x":-3,"y":2,"z":0},{"level":1,"name":"Water_Source","x":-3,"y":3,"z":0},{"level":1,"name":"Water_Source","x":-3,"y":0,"z":1},{"level":1,"name":"Water_Source","x":-3,"y":1,"z":1},{"level":1,"name":"Water_Source","x":-3,"y":2,"z":1},{"level":1,"name":"Water_Source","x":-3,"y":3,"z":1},{"level":1,"name":"Water_Source","x":-3,"y":0,"z":2},{"level":1,"name":"Water_Source","x":-3,"y":1,"z":2},{"level":1,"name":"Water_Source","x":-3,"y":2,"z":2},{"level":1,"name":"Water_Source","x":-3,"y":5,"z":2},{"level":1,"name":"Water_Source","x":-3,"y":6,"z":2},{"level":1,"name":"Water_Source","x":-3,"y":7,"z":2},{"level":1,"name":"Water_Source","x":-3,"y":0,"z":3},{"level":1,"name":"Water_Source","x":-3,"y":1,"z":3},{"level":1,"name":"Water_Source","x":-3,"y":2,"z":3},{"level":1,"name":"Water_Source","x":-3,"y":4,"z":3},{"level":1,"name":"Water_Source","x":-3,"y":5,"z":3},{"level":1,"name":"Water_Source","x":-3,"y":6,"z":3},{"level":1,"name":"Water_Source","x":-3,"y":7,"z":3},{"level":1,"name":"Water_Source","x":-3,"y":1,"z":4},{"level":1,"name":"Water_Source","x":-2,"y":1,"z":-3},{"level":1,"name":"Water_Source","x":-2,"y":1,"z":-2},{"level":1,"name":"Water_Source","x":-2,"y":1,"z":-1},{"level":1,"name":"Water_Source","x":-2,"y":1,"z":0},{"level":1,"name":"Water_Source","x":-2,"y":1,"z":1},{"level":1,"name":"Water_Source","x":-2,"y":1,"z":2},{"level":1,"name":"Water_Source","x":-2,"y":6,"z":2},{"level":1,"name":"Water_Source","x":-2,"y":1,"z":3},{"level":1,"name":"Water_Source","x":-2,"y":2,"z":3},{"level":1,"name":"Water_Source","x":-2,"y":5,"z":3},{"level":1,"name":"Water_Source","x":-2,"y":6,"z":3},{"level":1,"name":"Water_Source","x":-2,"y":7,"z":3},{"level":1,"name":"Water_Source","x":-1,"y":1,"z":3},{"level":1,"name":"Water_Source","x":-1,"y":2,"z":3},{"level":1,"name":"Water_Source","x":-1,"y":4,"z":3},{"level":1,"name":"Water_Source","x":-1,"y":5,"z":3},{"level":1,"name":"Water_Source","x":-1,"y":6,"z":3},{"level":1,"name":"Water_Source","x":-1,"y":7,"z":3},{"level":1,"name":"Water_Source","x":0,"y":1,"z":3},{"level":1,"name":"Water_Source","x":0,"y":2,"z":3},{"level":1,"name":"Water_Source","x":0,"y":3,"z":3},{"level":1,"name":"Water_Source","x":0,"y":4,"z":3},{"level":1,"name":"Water_Source","x":0,"y":5,"z":3},{"level":1,"name":"Water_Source","x":0,"y":6,"z":3},{"level":1,"name":"Water_Source","x":0,"y":7,"z":3},{"level":1,"name":"Water_Source","x":0,"y":1,"z":4},{"level":1,"name":"Water_Source","x":0,"y":2,"z":4},{"level":1,"name":"Water_Source","x":0,"y":3,"z":4},{"level":1,"name":"Water_Source","x":0,"y":4,"z":4},{"level":1,"name":"Water_Source","x":0,"y":5,"z":4},{"level":1,"name":"Water_Source","x":0,"y":6,"z":4},{"level":1,"name":"Water_Source","x":1,"y":1,"z":2},{"level":1,"name":"Water_Source","x":1,"y":2,"z":2},{"level":1,"name":"Water_Source","x":1,"y":3,"z":2},{"level":1,"name":"Water_Source","x":1,"y":1,"z":3},{"level":1,"name":"Water_Source","x":1,"y":2,"z":3},{"level":1,"name":"Water_Source","x":1,"y":3,"z":3},{"level":1,"name":"Water_Source","x":1,"y":4,"z":3},{"level":1,"name":"Water_Source","x":1,"y":5,"z":3},{"level":1,"name":"Water_Source","x":1,"y":6,"z":3},{"level":1,"name":"Water_Source","x":1,"y":1,"z":4},{"level":1,"name":"Water_Source","x":1,"y":2,"z":4},{"level":1,"name":"Water_Source","x":1,"y":3,"z":4},{"level":1,"name":"Water_Source","x":1,"y":4,"z":4},{"level":1,"name":"Water_Source","x":1,"y":5,"z":4},{"level":1,"name":"Water_Source","x":1,"y":6,"z":4},{"level":1,"name":"Water_Source","x":1,"y":7,"z":4},{"level":1,"name":"Water_Source","x":2,"y":1,"z":1},{"level":1,"name":"Water_Source","x":2,"y":2,"z":1},{"level":1,"name":"Water_Source","x":2,"y":3,"z":1},{"level":1,"name":"Water_Source","x":2,"y":1,"z":2},{"level":1,"name":"Water_Source","x":2,"y":2,"z":2},{"level":1,"name":"Water_Source","x":2,"y":3,"z":2},{"level":1,"name":"Water_Source","x":2,"y":4,"z":2},{"level":1,"name":"Water_Source","x":2,"y":5,"z":2},{"level":1,"name":"Water_Source","x":2,"y":1,"z":3},{"level":1,"name":"Water_Source","x":2,"y":2,"z":3},{"level":1,"name":"Water_Source","x":2,"y":3,"z":3},{"level":1,"name":"Water_Source","x":2,"y":4,"z":3},{"level":1,"name":"Water_Source","x":2,"y":5,"z":3},{"level":1,"name":"Water_Source","x":2,"y":6,"z":3},{"level":1,"name":"Water_Source","x":2,"y":1,"z":4},{"level":1,"name":"Water_Source","x":2,"y":2,"z":4},{"level":1,"name":"Water_Source","x":2,"y":3,"z":4},{"level":1,"name":"Water_Source","x":2,"y":4,"z":4},{"level":1,"name":"Water_Source","x":2,"y":5,"z":4},{"level":1,"name":"Water_Source","x":2,"y":6,"z":4},{"level":1,"name":"Water_Source","x":2,"y":7,"z":4},{"level":1,"name":"Water_Source","x":2,"y":3,"z":5},{"level":1,"name":"Water_Source","x":2,"y":4,"z":5},{"level":1,"name":"Water_Source","x":2,"y":5,"z":5},{"level":1,"name":"Water_Source","x":3,"y":1,"z":-2},{"level":1,"name":"Water_Source","x":3,"y":2,"z":-2},{"level":1,"name":"Water_Source","x":3,"y":3,"z":-2},{"level":1,"name":"Water_Source","x":3,"y":1,"z":-1},{"level":1,"name":"Water_Source","x":3,"y":2,"z":-1},{"level":1,"name":"Water_Source","x":3,"y":3,"z":-1},{"level":1,"name":"Water_Source","x":3,"y":1,"z":0},{"level":1,"name":"Water_Source","x":3,"y":2,"z":0},{"level":1,"name":"Water_Source","x":3,"y":3,"z":0},{"level":1,"name":"Water_Source","x":3,"y":1,"z":1},{"level":1,"name":"Water_Source","x":3,"y":2,"z":1},{"level":1,"name":"Water_Source","x":3,"y":3,"z":1},{"level":1,"name":"Water_Source","x":3,"y":1,"z":2},{"level":1,"name":"Water_Source","x":3,"y":2,"z":2},{"level":1,"name":"Water_Source","x":3,"y":1,"z":3},{"level":1,"name":"Water_Source","x":3,"y":2,"z":3},{"level":1,"name":"Water_Source","x":3,"y":3,"z":3},{"level":1,"name":"Water_Source","x":3,"y":4,"z":3},{"level":1,"name":"Water_Source","x":3,"y":5,"z":3},{"level":1,"name":"Water_Source","x":3,"y":6,"z":3},{"level":1,"name":"Water_Source","x":3,"y":1,"z":4},{"level":1,"name":"Water_Source","x":3,"y":2,"z":4},{"level":1,"name":"Water_Source","x":3,"y":3,"z":4},{"level":1,"name":"Water_Source","x":3,"y":4,"z":4},{"level":1,"name":"Water_Source","x":3,"y":5,"z":4},{"level":1,"name":"Water_Source","x":3,"y":6,"z":4},{"level":1,"name":"Water_Source","x":3,"y":3,"z":5},{"level":1,"name":"Water_Source","x":3,"y":4,"z":5},{"level":1,"name":"Water_Source","x":3,"y":5,"z":5},{"level":1,"name":"Water_Source","x":3,"y":3,"z":6},{"level":1,"name":"Water_Source","x":3,"y":4,"z":6},{"level":1,"name":"Water_Source","x":4,"y":1,"z":-2},{"level":1,"name":"Water_Source","x":4,"y":2,"z":-2},{"level":1,"name":"Water_Source","x":4,"y":1,"z":-1},{"level":1,"name":"Water_Source","x":4,"y":2,"z":-1},{"level":1,"name":"Water_Source","x":4,"y":1,"z":0},{"level":1,"name":"Water_Source","x":4,"y":2,"z":0},{"level":1,"name":"Water_Source","x":4,"y":1,"z":1},{"level":1,"name":"Water_Source","x":4,"y":2,"z":1},{"level":1,"name":"Water_Source","x":4,"y":1,"z":2},{"level":1,"name":"Water_Source","x":4,"y":2,"z":2},{"level":1,"name":"Water_Source","x":4,"y":1,"z":3},{"level":1,"name":"Water_Source","x":4,"y":2,"z":3},{"level":1,"name":"Water_Source","x":4,"y":3,"z":3},{"level":1,"name":"Water_Source","x":4,"y":4,"z":3},{"level":1,"name":"Water_Source","x":4,"y":5,"z":3},{"level":1,"name":"Water_Source","x":4,"y":6,"z":3},{"level":1,"name":"Water_Source","x":4,"y":1,"z":4},{"level":1,"name":"Water_Source","x":4,"y":2,"z":4},{"level":1,"name":"Water_Source","x":4,"y":3,"z":4},{"level":1,"name":"Water_Source","x":4,"y":4,"z":4},{"level":1,"name":"Water_Source","x":4,"y":5,"z":4},{"level":1,"name":"Water_Source","x":4,"y":6,"z":4},{"level":1,"name":"Water_Source","x":4,"y":3,"z":5},{"level":1,"name":"Water_Source","x":4,"y":4,"z":5},{"level":1,"name":"Water_Source","x":4,"y":5,"z":5},{"level":1,"name":"Water_Source","x":4,"y":3,"z":6},{"level":1,"name":"Water_Source","x":4,"y":4,"z":6},{"level":1,"name":"Water_Source","x":4,"y":5,"z":6},{"level":1,"name":"Water_Source","x":5,"y":1,"z":3},{"level":1,"name":"Water_Source","x":5,"y":2,"z":3},{"level":1,"name":"Water_Source","x":5,"y":3,"z":3},{"level":1,"name":"Water_Source","x":5,"y":4,"z":3},{"level":1,"name":"Water_Source","x":5,"y":5,"z":3},{"level":1,"name":"Water_Source","x":5,"y":6,"z":3},{"level":1,"name":"Water_Source","x":5,"y":1,"z":4},{"level":1,"name":"Water_Source","x":5,"y":2,"z":4},{"level":1,"name":"Water_Source","x":5,"y":3,"z":4},{"level":1,"name":"Water_Source","x":5,"y":4,"z":4},{"level":1,"name":"Water_Source","x":5,"y":5,"z":4},{"level":1,"name":"Water_Source","x":5,"y":6,"z":4},{"level":1,"name":"Water_Source","x":5,"y":7,"z":4},{"level":1,"name":"Water_Source","x":5,"y":3,"z":5},{"level":1,"name":"Water_Source","x":5,"y":4,"z":5},{"level":1,"name":"Water_Source","x":5,"y":5,"z":5},{"level":1,"name":"Water_Source","x":5,"y":3,"z":6},{"level":1,"name":"Water_Source","x":5,"y":4,"z":6},{"level":1,"name":"Water_Source","x":5,"y":5,"z":6}],"version":8}