{
  "version": 8,
  "blockIdVersion": 11,
  "anchorX": -1,
  "anchorY": 7,
  "anchorZ": 2,
  "blocks": [
    {
      "x": -6,
      "y": 7,
      "z": 4,
      "name": "Rock_Marble_Cobble",
      "rotation": 35
    },
    {
      "x": -6,
      "y": 7,
      "z": 5,
      "name": "Rock_Marble_Cobble",
      "rotation": 35
    },
    {
      "x": -6,
      "y": 8,
      "z": 5,
      "name": "Rock_Marble_Cobble",
      "rotation": 35
    },
    {
      "x": -5,
      "y": 7,
      "z": -2,
      "name": "Rock_Marble_Cobble",
      "rotation": 35
    },
    {
      "x": -5,
      "y": 8,
      "z": -2,
      "name": "Soil_Clay_GreyLight",
      "rotation": 35
    },
    {
      "x": -5,
      "y": 7,
      "z": -1,
      "name": "Rock_Marble_Cobble",
      "rotation": 35
    },
    {
      "x": -5,
      "y": 8,
      "z": -1,
      "name": "Soil_Clay_GreyLight",
      "rotation": 35
    },
    {
      "x": -5,
      "y": 7,
      "z": 3,
      "name": "Rock_Marble_Cobble",
      "rotation": 35
    },
    {
      "x": -5,
      "y": 8,
      "z": 3,
      "name": "Rock_Marble_Cobble",
      "rotation": 35
    },
    {
      "x": -5,
      "y": 6,
      "z": 4,
      "name": "Rock_Marble_Cobble",
      "rotation": 35
    },
    {
      "x": -5,
      "y": 7,
      "z": 4,
      "name": "Rock_Marble_Cobble",
      "rotation": 35
    },
    {
      "x": -5,
      "y": 8,
      "z": 4,
      "name": "Rock_Marble_Cobble",
      "rotation": 35
    },
    {
      "x": -5,
      "y": 9,
      "z": 4,
      "name": "Rock_Marble_Cobble",
      "rotation": 35
    },
    {
      "x": -5,
      "y": 6,
      "z": 5,
      "name": "Rock_Marble_Cobble",
      "rotation": 35
    },
    {
      "x": -5,
      "y": 7,
      "z": 5,
      "name": "Rock_Marble_Cobble",
      "rotation": 35
    },
    {
      "x": -5,
      "y": 8,
      "z": 5,
      "name": "Rock_Marble_Cobble",
      "rotation": 35
    },
    {
      "x": -5,
      "y": 9,
      "z": 5,
      "name": "Rock_Marble_Cobble",
      "rotation": 35
    },
    {
      "x": -5,
      "y": 7,
      "z": 6,
      "name": "Rock_Marble_Cobble",
      "rotation": 35
    },
    {
      "x": -5,
      "y": 8,
      "z": 6,
      "name": "Rock_Marble_Cobble",
      "rotation": 35
    },
    {
      "x": -4,
      "y": 7,
      "z": -4,
      "name": "Rock_Marble_Cobble",
      "rotation": 35
    },
    {
      "x": -4,
      "y": 8,
      "z": -4,
      "name": "Soil_Clay_GreyLight",
      "rotation": 35
    },
    {
      "x": -4,
      "y": 6,
      "z": -3,
      "name": "Rock_Marble_Cobble",
      "rotation": 35
    },
    {
      "x": -4,
      "y": 7,
      "z": -3,
      "name": "Rock_Marble_Cobble",
      "rotation": 35
    },
    {
      "x": -4,
      "y": 8,
      "z": -3,
      "name": "Soil_Clay_GreyLight",
      "rotation": 35
    },
    {
      "x": -4,
      "y": 9,
      "z": -3,
      "name": "Rock_Marble_Cobble",
      "rotation": 35
    },
    {
      "x": -4,
      "y": 6,
      "z": -2,
      "name": "Rock_Marble_Cobble",
      "rotation": 35
    },
    {
      "x": -4,
      "y": 7,
      "z": -2,
      "name": "Rock_Marble_Cobble",
      "rotation": 35
    },
    {
      "x": -4,
      "y": 8,
      "z": -2,
      "name": "Soil_Clay_GreyLight",
      "rotation": 35
    },
    {
      "x": -4,
      "y": 9,
      "z": -2,
      "name": "Rock_Marble_Cobble",
      "rotation": 35
    },
    {
      "x": -4,
      "y": 6,
      "z": -1,
      "name": "Rock_Marble_Cobble",
      "rotation": 35
    },
    {
      "x": -4,
      "y": 7,
      "z": -1,
      "name": "Rock_Marble_Cobble",
      "rotation": 35
    },
    {
      "x": -4,
      "y": 8,
      "z": -1,
      "name": "Soil_Clay_GreyLight",
      "rotation": 35
    },
    {
      "x": -4,
      "y": 9,
      "z": -1,
      "name": "Rock_Marble_Cobble",
      "rotation": 35
    },
    {
      "x": -4,
      "y": 7,
      "z": 0,
      "name": "Rock_Marble_Cobble",
      "rotation": 35
    },
    {
      "x": -4,
      "y": 8,
      "z": 0,
      "name": "Soil_Clay_GreyLight",
      "rotation": 35
    },
    {
      "x": -4,
      "y": 7,
      "z": 1,
      "name": "Rock_Marble_Cobble",
      "rotation": 35
    },
    {
      "x": -4,
      "y": 8,
      "z": 1,
      "name": "Rock_Marble_Cobble",
      "rotation": 35
    },
    {
      "x": -4,
      "y": 6,
      "z": 2,
      "name": "Rock_Marble_Cobble",
      "rotation": 35
    },
    {
      "x": -4,
      "y": 7,
      "z": 2,
      "name": "Rock_Marble_Cobble",
      "rotation": 35
    },
    {
      "x": -4,
      "y": 8,
      "z": 2,
      "name": "Rock_Marble_Cobble",
      "rotation": 35
    },
    {
      "x": -4,
      "y": 9,
      "z": 2,
      "name": "Rock_Marble_Cobble",
      "rotation": 35
    },
    {
      "x": -4,
      "y": 6,
      "z": 3,
      "name": "Rock_Marble_Cobble",
      "rotation": 35
    },
    {
      "x": -4,
      "y": 7,
      "z": 3,
      "name": "Rock_Marble_Cobble",
      "rotation": 35
    },
    {
      "x": -4,
      "y": 8,
      "z": 3,
      "name": "Rock_Marble_Cobble",
      "rotation": 35
    },
    {
      "x": -4,
      "y": 9,
      "z": 3,
      "name": "Rock_Marble_Cobble",
      "rotation": 35
    },
    {
      "x": -4,
      "y": 10,
      "z": 3,
      "name": "Rock_Marble_Cobble",
      "rotation": 35
    },
    {
      "x": -4,
      "y": 5,
      "z": 4,
      "name": "Rock_Marble",
      "rotation": 35
    },
    {
      "x": -4,
      "y": 6,
      "z": 4,
      "name": "Rock_Marble_Cobble",
      "rotation": 35
    },
    {
      "x": -4,
      "y": 7,
      "z": 4,
      "name": "Rock_Marble_Cobble",
      "rotation": 35
    },
    {
      "x": -4,
      "y": 8,
      "z": 4,
      "name": "Rock_Marble_Cobble",
      "rotation": 35
    },
    {
      "x": -4,
      "y": 9,
      "z": 4,
      "name": "Rock_Marble_Cobble",
      "rotation": 35
    },
    {
      "x": -4,
      "y": 10,
      "z": 4,
      "name": "Rock_Marble_Cobble",
      "rotation": 35
    },
    {
      "x": -4,
      "y": 5,
      "z": 5,
      "name": "Rock_Marble",
      "rotation": 35
    },
    {
      "x": -4,
      "y": 6,
      "z": 5,
      "name": "Rock_Marble_Cobble",
      "rotation": 35
    },
    {
      "x": -4,
      "y": 7,
      "z": 5,
      "name": "Rock_Marble_Cobble",
      "rotation": 35
    },
    {
      "x": -4,
      "y": 8,
      "z": 5,
      "name": "Rock_Marble_Cobble",
      "rotation": 35
    },
    {
      "x": -4,
      "y": 9,
      "z": 5,
      "name": "Rock_Marble_Cobble",
      "rotation": 35
    },
    {
      "x": -4,
      "y": 10,
      "z": 5,
      "name": "Rock_Marble_Cobble",
      "rotation": 35
    },
    {
      "x": -4,
      "y": 6,
      "z": 6,
      "name": "Rock_Marble_Cobble",
      "rotation": 35
    },
    {
      "x": -4,
      "y": 7,
      "z": 6,
      "name": "Rock_Marble_Cobble",
      "rotation": 35
    },
    {
      "x": -4,
      "y": 8,
      "z": 6,
      "name": "Rock_Marble_Cobble",
      "rotation": 35
    },
    {
      "x": -4,
      "y": 9,
      "z": 6,
      "name": "Rock_Marble_Cobble",
      "rotation": 35
    },
    {
      "x": -3,
      "y": 7,
      "z": -5,
      "name": "Rock_Marble_Cobble",
      "rotation": 35
    },
    {
      "x": -3,
      "y": 8,
      "z": -5,
      "name": "Soil_Clay_GreyLight",
      "rotation": 35
    },
    {
      "x": -3,
      "y": 6,
      "z": -4,
      "name": "Rock_Marble_Cobble",
      "rotation": 35
    },
    {
      "x": -3,
      "y": 7,
      "z": -4,
      "name": "Rock_Marble_Cobble",
      "rotation": 35
    },
    {
      "x": -3,
      "y": 8,
      "z": -4,
      "name": "Soil_Clay_GreyLight",
      "rotation": 35
    },
    {
      "x": -3,
      "y": 9,
      "z": -4,
      "name": "Rock_Marble_Cobble",
      "rotation": 35
    },
    {
      "x": -3,
      "y": 5,
      "z": -3,
      "name": "Rock_Marble",
      "rotation": 35
    },
    {
      "x": -3,
      "y": 6,
      "z": -3,
      "name": "Rock_Marble_Cobble",
      "rotation": 35
    },
    {
      "x": -3,
      "y": 7,
      "z": -3,
      "name": "Rock_Marble_Cobble",
      "rotation": 35
    },
    {
      "x": -3,
      "y": 8,
      "z": -3,
      "name": "Soil_Clay_GreyLight",
      "rotation": 35
    },
    {
      "x": -3,
      "y": 9,
      "z": -3,
      "name": "Rock_Marble_Cobble",
      "rotation": 35
    },
    {
      "x": -3,
      "y": 10,
      "z": -3,
      "name": "Rock_Marble_Cobble",
      "rotation": 35
    },
    {
      "x": -3,
      "y": 5,
      "z": -2,
      "name": "Rock_Marble",
      "rotation": 35
    },
    {
      "x": -3,
      "y": 6,
      "z": -2,
      "name": "Rock_Marble_Cobble",
      "rotation": 35
    },
    {
      "x": -3,
      "y": 7,
      "z": -2,
      "name": "Rock_Marble_Cobble",
      "rotation": 35
    },
    {
      "x": -3,
      "y": 8,
      "z": -2,
      "name": "Soil_Clay_GreyLight",
      "rotation": 35
    },
    {
      "x": -3,
      "y": 9,
      "z": -2,
      "name": "Rock_Marble_Cobble",
      "rotation": 35
    },
    {
      "x": -3,
      "y": 10,
      "z": -2,
      "name": "Rock_Marble_Cobble",
      "rotation": 35
    },
    {
      "x": -3,
      "y": 5,
      "z": -1,
      "name": "Rock_Marble",
      "rotation": 35
    },
    {
      "x": -3,
      "y": 6,
      "z": -1,
      "name": "Rock_Marble_Cobble",
      "rotation": 35
    },
    {
      "x": -3,
      "y": 7,
      "z": -1,
      "name": "Rock_Marble_Cobble",
      "rotation": 35
    },
    {
      "x": -3,
      "y": 8,
      "z": -1,
      "name": "Soil_Clay_GreyLight",
      "rotation": 35
    },
    {
      "x": -3,
      "y": 9,
      "z": -1,
      "name": "Rock_Marble_Cobble",
      "rotation": 35
    },
    {
      "x": -3,
      "y": 10,
      "z": -1,
      "name": "Rock_Marble_Cobble",
      "rotation": 35
    },
    {
      "x": -3,
      "y": 6,
      "z": 0,
      "name": "Rock_Marble_Cobble",
      "rotation": 35
    },
    {
      "x": -3,
      "y": 7,
      "z": 0,
      "name": "Rock_Marble_Cobble",
      "rotation": 35
    },
    {
      "x": -3,
      "y": 8,
      "z": 0,
      "name": "Soil_Clay_GreyLight",
      "rotation": 35
    },
    {
      "x": -3,
      "y": 9,
      "z": 0,
      "name": "Rock_Marble_Cobble",
      "rotation": 35
    },
    {
      "x": -3,
      "y": 10,
      "z": 0,
      "name": "Rock_Marble_Cobble",
      "rotation": 35
    },
    {
      "x": -3,
      "y": 6,
      "z": 1,
      "name": "Rock_Marble_Cobble",
      "rotation": 35
    },
    {
      "x": -3,
      "y": 7,
      "z": 1,
      "name": "Rock_Marble_Cobble",
      "rotation": 35
    },
    {
      "x": -3,
      "y": 8,
      "z": 1,
      "name": "Rock_Marble_Cobble",
      "rotation": 35
    },
    {
      "x": -3,
      "y": 9,
      "z": 1,
      "name": "Rock_Marble_Cobble",
      "rotation": 35
    },
    {
      "x": -3,
      "y": 10,
      "z": 1,
      "name": "Rock_Marble_Cobble",
      "rotation": 35
    },
    {
      "x": -3,
      "y": 5,
      "z": 2,
      "name": "Rock_Marble",
      "rotation": 35
    },
    {
      "x": -3,
      "y": 6,
      "z": 2,
      "name": "Rock_Marble_Cobble",
      "rotation": 35
    },
    {
      "x": -3,
      "y": 7,
      "z": 2,
      "name": "Rock_Marble_Cobble",
      "rotation": 35
    },
    {
      "x": -3,
      "y": 8,
      "z": 2,
      "name": "Rock_Marble_Cobble",
      "rotation": 35
    },
    {
      "x": -3,
      "y": 9,
      "z": 2,
      "name": "Rock_Marble_Cobble",
      "rotation": 35
    },
    {
      "x": -3,
      "y": 10,
      "z": 2,
      "name": "Rock_Marble_Cobble",
      "rotation": 35
    },
    {
      "x": -3,
      "y": 11,
      "z": 2,
      "name": "Rock_Marble",
      "rotation": 35
    },
    {
      "x": -3,
      "y": 5,
      "z": 3,
      "name": "Rock_Marble",
      "rotation": 35
    },
    {
      "x": -3,
      "y": 6,
      "z": 3,
      "name": "Rock_Marble_Cobble",
      "rotation": 35
    },
    {
      "x": -3,
      "y": 7,
      "z": 3,
      "name": "Rock_Marble_Cobble",
      "rotation": 35
    },
    {
      "x": -3,
      "y": 8,
      "z": 3,
      "name": "Rock_Marble_Cobble",
      "rotation": 35
    },
    {
      "x": -3,
      "y": 9,
      "z": 3,
      "name": "Rock_Marble_Cobble",
      "rotation": 35
    },
    {
      "x": -3,
      "y": 10,
      "z": 3,
      "name": "Rock_Marble_Cobble",
      "rotation": 35
    },
    {
      "x": -3,
      "y": 11,
      "z": 3,
      "name": "Rock_Marble",
      "rotation": 35
    },
    {
      "x": -3,
      "y": 5,
      "z": 4,
      "name": "Rock_Marble",
      "rotation": 35
    },
    {
      "x": -3,
      "y": 6,
      "z": 4,
      "name": "Rock_Marble_Cobble",
      "rotation": 35
    },
    {
      "x": -3,
      "y": 7,
      "z": 4,
      "name": "Rock_Marble_Cobble",
      "rotation": 35
    },
    {
      "x": -3,
      "y": 8,
      "z": 4,
      "name": "Rock_Marble_Cobble",
      "rotation": 35
    },
    {
      "x": -3,
      "y": 9,
      "z": 4,
      "name": "Rock_Marble_Cobble",
      "rotation": 35
    },
    {
      "x": -3,
      "y": 10,
      "z": 4,
      "name": "Rock_Marble_Cobble",
      "rotation": 35
    },
    {
      "x": -3,
      "y": 11,
      "z": 4,
      "name": "Rock_Marble",
      "rotation": 35
    },
    {
      "x": -3,
      "y": 5,
      "z": 5,
      "name": "Rock_Marble",
      "rotation": 35
    },
    {
      "x": -3,
      "y": 6,
      "z": 5,
      "name": "Rock_Marble_Cobble",
      "rotation": 35
    },
    {
      "x": -3,
      "y": 7,
      "z": 5,
      "name": "Rock_Marble_Cobble",
      "rotation": 35
    },
    {
      "x": -3,
      "y": 8,
      "z": 5,
      "name": "Rock_Marble_Cobble",
      "rotation": 35
    },
    {
      "x": -3,
      "y": 9,
      "z": 5,
      "name": "Rock_Marble_Cobble",
      "rotation": 35
    },
    {
      "x": -3,
      "y": 10,
      "z": 5,
      "name": "Rock_Marble_Cobble",
      "rotation": 35
    },
    {
      "x": -3,
      "y": 6,
      "z": 6,
      "name": "Rock_Marble_Cobble",
      "rotation": 35
    },
    {
      "x": -3,
      "y": 7,
      "z": 6,
      "name": "Rock_Marble_Cobble",
      "rotation": 35
    },
    {
      "x": -3,
      "y": 8,
      "z": 6,
      "name": "Rock_Marble_Cobble",
      "rotation": 35
    },
    {
      "x": -3,
      "y": 9,
      "z": 6,
      "name": "Rock_Marble_Cobble",
      "rotation": 35
    },
    {
      "x": -3,
      "y": 7,
      "z": 7,
      "name": "Rock_Marble_Cobble",
      "rotation": 35
    },
    {
      "x": -3,
      "y": 8,
      "z": 7,
      "name": "Rock_Marble_Cobble",
      "rotation": 35
    },
    {
      "x": -2,
      "y": 8,
      "z": -5,
      "name": "Soil_Clay_GreyLight",
      "rotation": 35
    },
    {
      "x": -2,
      "y": 6,
      "z": -4,
      "name": "Rock_Marble_Cobble",
      "rotation": 35
    },
    {
      "x": -2,
      "y": 7,
      "z": -4,
      "name": "Rock_Marble_Cobble",
      "rotation": 35
    },
    {
      "x": -2,
      "y": 8,
      "z": -4,
      "name": "Soil_Clay_GreyLight",
      "rotation": 35
    },
    {
      "x": -2,
      "y": 9,
      "z": -4,
      "name": "Rock_Marble_Cobble",
      "rotation": 35
    },
    {
      "x": -2,
      "y": 5,
      "z": -3,
      "name": "Rock_Marble",
      "rotation": 35
    },
    {
      "x": -2,
      "y": 6,
      "z": -3,
      "name": "Rock_Marble_Cobble",
      "rotation": 35
    },
    {
      "x": -2,
      "y": 7,
      "z": -3,
      "name": "Rock_Marble_Cobble",
      "rotation": 35
    },
    {
      "x": -2,
      "y": 8,
      "z": -3,
      "name": "Soil_Clay_GreyLight",
      "rotation": 35
    },
    {
      "x": -2,
      "y": 9,
      "z": -3,
      "name": "Rock_Marble_Cobble",
      "rotation": 35
    },
    {
      "x": -2,
      "y": 10,
      "z": -3,
      "name": "Rock_Marble_Cobble",
      "rotation": 35
    },
    {
      "x": -2,
      "y": 5,
      "z": -2,
      "name": "Rock_Marble",
      "rotation": 35
    },
    {
      "x": -2,
      "y": 6,
      "z": -2,
      "name": "Rock_Marble_Cobble",
      "rotation": 35
    },
    {
      "x": -2,
      "y": 7,
      "z": -2,
      "name": "Rock_Marble_Cobble",
      "rotation": 35
    },
    {
      "x": -2,
      "y": 8,
      "z": -2,
      "name": "Soil_Clay_GreyLight",
      "rotation": 35
    },
    {
      "x": -2,
      "y": 9,
      "z": -2,
      "name": "Rock_Marble_Cobble",
      "rotation": 35
    },
    {
      "x": -2,
      "y": 10,
      "z": -2,
      "name": "Rock_Marble_Cobble",
      "rotation": 35
    },
    {
      "x": -2,
      "y": 5,
      "z": -1,
      "name": "Rock_Marble",
      "rotation": 35
    },
    {
      "x": -2,
      "y": 6,
      "z": -1,
      "name": "Rock_Marble_Cobble",
      "rotation": 35
    },
    {
      "x": -2,
      "y": 7,
      "z": -1,
      "name": "Rock_Marble_Cobble",
      "rotation": 35
    },
    {
      "x": -2,
      "y": 8,
      "z": -1,
      "name": "Soil_Clay_GreyLight",
      "rotation": 35
    },
    {
      "x": -2,
      "y": 9,
      "z": -1,
      "name": "Rock_Marble_Cobble",
      "rotation": 35
    },
    {
      "x": -2,
      "y": 10,
      "z": -1,
      "name": "Rock_Marble_Cobble",
      "rotation": 35
    },
    {
      "x": -2,
      "y": 11,
      "z": -1,
      "name": "Rock_Marble",
      "rotation": 35
    },
    {
      "x": -2,
      "y": 5,
      "z": 0,
      "name": "Rock_Marble",
      "rotation": 35
    },
    {
      "x": -2,
      "y": 6,
      "z": 0,
      "name": "Rock_Marble_Cobble",
      "rotation": 35
    },
    {
      "x": -2,
      "y": 7,
      "z": 0,
      "name": "Rock_Marble_Cobble",
      "rotation": 35
    },
    {
      "x": -2,
      "y": 8,
      "z": 0,
      "name": "Rock_Marble_Cobble",
      "rotation": 35
    },
    {
      "x": -2,
      "y": 9,
      "z": 0,
      "name": "Rock_Marble_Cobble",
      "rotation": 35
    },
    {
      "x": -2,
      "y": 10,
      "z": 0,
      "name": "Rock_Marble_Cobble",
      "rotation": 35
    },
    {
      "x": -2,
      "y": 11,
      "z": 0,
      "name": "Rock_Marble",
      "rotation": 35
    },
    {
      "x": -2,
      "y": 5,
      "z": 1,
      "name": "Rock_Marble",
      "rotation": 35
    },
    {
      "x": -2,
      "y": 6,
      "z": 1,
      "name": "Rock_Marble_Cobble",
      "rotation": 35
    },
    {
      "x": -2,
      "y": 7,
      "z": 1,
      "name": "Rock_Marble_Cobble",
      "rotation": 35
    },
    {
      "x": -2,
      "y": 8,
      "z": 1,
      "name": "Rock_Marble_Cobble",
      "rotation": 35
    },
    {
      "x": -2,
      "y": 9,
      "z": 1,
      "name": "Rock_Marble_Cobble",
      "rotation": 35
    },
    {
      "x": -2,
      "y": 10,
      "z": 1,
      "name": "Rock_Marble_Cobble",
      "rotation": 35
    },
    {
      "x": -2,
      "y": 11,
      "z": 1,
      "name": "Rock_Marble",
      "rotation": 35
    },
    {
      "x": -2,
      "y": 5,
      "z": 2,
      "name": "Rock_Marble",
      "rotation": 35
    },
    {
      "x": -2,
      "y": 6,
      "z": 2,
      "name": "Rock_Marble_Cobble",
      "rotation": 35
    },
    {
      "x": -2,
      "y": 7,
      "z": 2,
      "name": "Rock_Marble_Cobble",
      "rotation": 35
    },
    {
      "x": -2,
      "y": 8,
      "z": 2,
      "name": "Rock_Marble_Cobble",
      "rotation": 35
    },
    {
      "x": -2,
      "y": 9,
      "z": 2,
      "name": "Rock_Marble_Cobble",
      "rotation": 35
    },
    {
      "x": -2,
      "y": 10,
      "z": 2,
      "name": "Rock_Marble_Cobble",
      "rotation": 35
    },
    {
      "x": -2,
      "y": 11,
      "z": 2,
      "name": "Rock_Marble",
      "rotation": 35
    },
    {
      "x": -2,
      "y": 12,
      "z": 2,
      "name": "Soil_Clay_White",
      "rotation": 35
    },
    {
      "x": -2,
      "y": 5,
      "z": 3,
      "name": "Rock_Marble",
      "rotation": 35
    },
    {
      "x": -2,
      "y": 6,
      "z": 3,
      "name": "Rock_Marble_Cobble",
      "rotation": 35
    },
    {
      "x": -2,
      "y": 7,
      "z": 3,
      "name": "Rock_Marble_Cobble",
      "rotation": 35
    },
    {
      "x": -2,
      "y": 8,
      "z": 3,
      "name": "Rock_Marble_Cobble",
      "rotation": 35
    },
    {
      "x": -2,
      "y": 9,
      "z": 3,
      "name": "Rock_Marble_Cobble",
      "rotation": 35
    },
    {
      "x": -2,
      "y": 10,
      "z": 3,
      "name": "Rock_Marble_Cobble",
      "rotation": 35
    },
    {
      "x": -2,
      "y": 11,
      "z": 3,
      "name": "Rock_Marble",
      "rotation": 35
    },
    {
      "x": -2,
      "y": 12,
      "z": 3,
      "name": "Soil_Clay_White",
      "rotation": 35
    },
    {
      "x": -2,
      "y": 5,
      "z": 4,
      "name": "Rock_Marble",
      "rotation": 35
    },
    {
      "x": -2,
      "y": 6,
      "z": 4,
      "name": "Rock_Marble_Cobble",
      "rotation": 35
    },
    {
      "x": -2,
      "y": 7,
      "z": 4,
      "name": "Rock_Marble_Cobble",
      "rotation": 35
    },
    {
      "x": -2,
      "y": 8,
      "z": 4,
      "name": "Rock_Marble_Cobble",
      "rotation": 35
    },
    {
      "x": -2,
      "y": 9,
      "z": 4,
      "name": "Rock_Marble_Cobble",
      "rotation": 35
    },
    {
      "x": -2,
      "y": 10,
      "z": 4,
      "name": "Rock_Marble_Cobble",
      "rotation": 35
    },
    {
      "x": -2,
      "y": 11,
      "z": 4,
      "name": "Rock_Marble",
      "rotation": 35
    },
    {
      "x": -2,
      "y": 12,
      "z": 4,
      "name": "Soil_Clay_White",
      "rotation": 35
    },
    {
      "x": -2,
      "y": 5,
      "z": 5,
      "name": "Rock_Marble",
      "rotation": 35
    },
    {
      "x": -2,
      "y": 6,
      "z": 5,
      "name": "Rock_Marble_Cobble",
      "rotation": 35
    },
    {
      "x": -2,
      "y": 7,
      "z": 5,
      "name": "Rock_Marble_Cobble",
      "rotation": 35
    },
    {
      "x": -2,
      "y": 8,
      "z": 5,
      "name": "Rock_Marble_Cobble",
      "rotation": 35
    },
    {
      "x": -2,
      "y": 9,
      "z": 5,
      "name": "Rock_Marble_Cobble",
      "rotation": 35
    },
    {
      "x": -2,
      "y": 10,
      "z": 5,
      "name": "Rock_Marble_Cobble",
      "rotation": 35
    },
    {
      "x": -2,
      "y": 11,
      "z": 5,
      "name": "Rock_Marble",
      "rotation": 35
    },
    {
      "x": -2,
      "y": 6,
      "z": 6,
      "name": "Rock_Marble_Cobble",
      "rotation": 35
    },
    {
      "x": -2,
      "y": 7,
      "z": 6,
      "name": "Rock_Marble_Cobble",
      "rotation": 35
    },
    {
      "x": -2,
      "y": 8,
      "z": 6,
      "name": "Rock_Marble_Cobble",
      "rotation": 35
    },
    {
      "x": -2,
      "y": 9,
      "z": 6,
      "name": "Rock_Marble_Cobble",
      "rotation": 35
    },
    {
      "x": -2,
      "y": 10,
      "z": 6,
      "name": "Rock_Marble_Cobble",
      "rotation": 35
    },
    {
      "x": -2,
      "y": 7,
      "z": 7,
      "name": "Rock_Marble_Cobble",
      "rotation": 35
    },
    {
      "x": -2,
      "y": 8,
      "z": 7,
      "name": "Rock_Marble_Cobble",
      "rotation": 35
    },
    {
      "x": -1,
      "y": 7,
      "z": -4,
      "name": "Rock_Marble_Cobble",
      "rotation": 35
    },
    {
      "x": -1,
      "y": 8,
      "z": -4,
      "name": "Soil_Clay_GreyLight",
      "rotation": 35
    },
    {
      "x": -1,
      "y": 9,
      "z": -4,
      "name": "Rock_Marble_Cobble",
      "rotation": 35
    },
    {
      "x": -1,
      "y": 6,
      "z": -3,
      "name": "Rock_Marble_Cobble",
      "rotation": 35
    },
    {
      "x": -1,
      "y": 7,
      "z": -3,
      "name": "Rock_Marble_Cobble",
      "rotation": 35
    },
    {
      "x": -1,
      "y": 8,
      "z": -3,
      "name": "Soil_Clay_GreyLight",
      "rotation": 35
    },
    {
      "x": -1,
      "y": 9,
      "z": -3,
      "name": "Rock_Marble_Cobble",
      "rotation": 35
    },
    {
      "x": -1,
      "y": 10,
      "z": -3,
      "name": "Rock_Marble_Cobble",
      "rotation": 35
    },
    {
      "x": -1,
      "y": 5,
      "z": -2,
      "name": "Rock_Marble",
      "rotation": 35
    },
    {
      "x": -1,
      "y": 6,
      "z": -2,
      "name": "Rock_Marble_Cobble",
      "rotation": 35
    },
    {
      "x": -1,
      "y": 7,
      "z": -2,
      "name": "Rock_Marble_Cobble",
      "rotation": 35
    },
    {
      "x": -1,
      "y": 8,
      "z": -2,
      "name": "Soil_Clay_GreyLight",
      "rotation": 35
    },
    {
      "x": -1,
      "y": 9,
      "z": -2,
      "name": "Rock_Marble_Cobble",
      "rotation": 35
    },
    {
      "x": -1,
      "y": 10,
      "z": -2,
      "name": "Rock_Marble_Cobble",
      "rotation": 35
    },
    {
      "x": -1,
      "y": 11,
      "z": -2,
      "name": "Rock_Marble",
      "rotation": 35
    },
    {
      "x": -1,
      "y": 5,
      "z": -1,
      "name": "Rock_Marble",
      "rotation": 35
    },
    {
      "x": -1,
      "y": 6,
      "z": -1,
      "name": "Rock_Marble_Cobble",
      "rotation": 35
    },
    {
      "x": -1,
      "y": 7,
      "z": -1,
      "name": "Rock_Marble_Cobble",
      "rotation": 35
    },
    {
      "x": -1,
      "y": 8,
      "z": -1,
      "name": "Soil_Clay_GreyLight",
      "rotation": 35
    },
    {
      "x": -1,
      "y": 9,
      "z": -1,
      "name": "Rock_Marble_Cobble",
      "rotation": 35
    },
    {
      "x": -1,
      "y": 10,
      "z": -1,
      "name": "Rock_Marble_Cobble",
      "rotation": 35
    },
    {
      "x": -1,
      "y": 11,
      "z": -1,
      "name": "Rock_Marble",
      "rotation": 35
    },
    {
      "x": -1,
      "y": 5,
      "z": 0,
      "name": "Rock_Marble",
      "rotation": 35
    },
    {
      "x": -1,
      "y": 6,
      "z": 0,
      "name": "Rock_Marble_Cobble",
      "rotation": 35
    },
    {
      "x": -1,
      "y": 7,
      "z": 0,
      "name": "Rock_Marble_Cobble",
      "rotation": 35
    },
    {
      "x": -1,
      "y": 8,
      "z": 0,
      "name": "Rock_Marble_Cobble",
      "rotation": 35
    },
    {
      "x": -1,
      "y": 9,
      "z": 0,
      "name": "Rock_Marble_Cobble",
      "rotation": 35
    },
    {
      "x": -1,
      "y": 10,
      "z": 0,
      "name": "Rock_Marble_Cobble",
      "rotation": 35
    },
    {
      "x": -1,
      "y": 11,
      "z": 0,
      "name": "Rock_Marble",
      "rotation": 35
    },
    {
      "x": -1,
      "y": 5,
      "z": 1,
      "name": "Rock_Marble",
      "rotation": 35
    },
    {
      "x": -1,
      "y": 6,
      "z": 1,
      "name": "Rock_Marble_Cobble",
      "rotation": 35
    },
    {
      "x": -1,
      "y": 7,
      "z": 1,
      "name": "Rock_Marble_Cobble",
      "rotation": 35
    },
    {
      "x": -1,
      "y": 8,
      "z": 1,
      "name": "Rock_Marble_Cobble",
      "rotation": 35
    },
    {
      "x": -1,
      "y": 9,
      "z": 1,
      "name": "Rock_Marble_Cobble",
      "rotation": 35
    },
    {
      "x": -1,
      "y": 10,
      "z": 1,
      "name": "Rock_Marble_Cobble",
      "rotation": 35
    },
    {
      "x": -1,
      "y": 11,
      "z": 1,
      "name": "Rock_Marble",
      "rotation": 35
    },
    {
      "x": -1,
      "y": 12,
      "z": 1,
      "name": "Soil_Clay_White",
      "rotation": 35
    },
    {
      "x": -1,
      "y": 5,
      "z": 2,
      "name": "Rock_Marble",
      "rotation": 35
    },
    {
      "x": -1,
      "y": 6,
      "z": 2,
      "name": "Rock_Marble_Cobble",
      "rotation": 35
    },
    {
      "x": -1,
      "y": 7,
      "z": 2,
      "name": "Rock_Marble_Cobble",
      "rotation": 35
    },
    {
      "x": -1,
      "y": 8,
      "z": 2,
      "name": "Rock_Marble_Cobble",
      "rotation": 35
    },
    {
      "x": -1,
      "y": 9,
      "z": 2,
      "name": "Rock_Marble_Cobble",
      "rotation": 35
    },
    {
      "x": -1,
      "y": 10,
      "z": 2,
      "name": "Rock_Marble_Cobble",
      "rotation": 35
    },
    {
      "x": -1,
      "y": 11,
      "z": 2,
      "name": "Rock_Marble",
      "rotation": 35
    },
    {
      "x": -1,
      "y": 12,
      "z": 2,
      "name": "Soil_Clay_White",
      "rotation": 35
    },
    {
      "x": -1,
      "y": 5,
      "z": 3,
      "name": "Rock_Marble",
      "rotation": 35
    },
    {
      "x": -1,
      "y": 6,
      "z": 3,
      "name": "Rock_Marble_Cobble",
      "rotation": 35
    },
    {
      "x": -1,
      "y": 7,
      "z": 3,
      "name": "Rock_Marble_Cobble",
      "rotation": 35
    },
    {
      "x": -1,
      "y": 8,
      "z": 3,
      "name": "Rock_Marble_Cobble",
      "rotation": 35
    },
    {
      "x": -1,
      "y": 9,
      "z": 3,
      "name": "Rock_Marble_Cobble",
      "rotation": 35
    },
    {
      "x": -1,
      "y": 10,
      "z": 3,
      "name": "Rock_Marble_Cobble",
      "rotation": 35
    },
    {
      "x": -1,
      "y": 11,
      "z": 3,
      "name": "Rock_Marble",
      "rotation": 35
    },
    {
      "x": -1,
      "y": 12,
      "z": 3,
      "name": "Soil_Clay_White",
      "rotation": 35
    },
    {
      "x": -1,
      "y": 13,
      "z": 3,
      "name": "Rock_Marble",
      "rotation": 35
    },
    {
      "x": -1,
      "y": 5,
      "z": 4,
      "name": "Rock_Marble",
      "rotation": 35
    },
    {
      "x": -1,
      "y": 6,
      "z": 4,
      "name": "Rock_Marble_Cobble",
      "rotation": 35
    },
    {
      "x": -1,
      "y": 7,
      "z": 4,
      "name": "Rock_Marble_Cobble",
      "rotation": 35
    },
    {
      "x": -1,
      "y": 8,
      "z": 4,
      "name": "Rock_Marble_Cobble",
      "rotation": 35
    },
    {
      "x": -1,
      "y": 9,
      "z": 4,
      "name": "Rock_Marble_Cobble",
      "rotation": 35
    },
    {
      "x": -1,
      "y": 10,
      "z": 4,
      "name": "Rock_Marble_Cobble",
      "rotation": 35
    },
    {
      "x": -1,
      "y": 11,
      "z": 4,
      "name": "Rock_Marble",
      "rotation": 35
    },
    {
      "x": -1,
      "y": 12,
      "z": 4,
      "name": "Soil_Clay_White",
      "rotation": 35
    },
    {
      "x": -1,
      "y": 5,
      "z": 5,
      "name": "Rock_Marble",
      "rotation": 35
    },
    {
      "x": -1,
      "y": 6,
      "z": 5,
      "name": "Rock_Marble_Cobble",
      "rotation": 35
    },
    {
      "x": -1,
      "y": 7,
      "z": 5,
      "name": "Rock_Marble_Cobble",
      "rotation": 35
    },
    {
      "x": -1,
      "y": 8,
      "z": 5,
      "name": "Rock_Marble_Cobble",
      "rotation": 35
    },
    {
      "x": -1,
      "y": 9,
      "z": 5,
      "name": "Rock_Marble_Cobble",
      "rotation": 35
    },
    {
      "x": -1,
      "y": 10,
      "z": 5,
      "name": "Rock_Marble_Cobble",
      "rotation": 35
    },
    {
      "x": -1,
      "y": 11,
      "z": 5,
      "name": "Rock_Marble",
      "rotation": 35
    },
    {
      "x": -1,
      "y": 6,
      "z": 6,
      "name": "Rock_Marble_Cobble",
      "rotation": 35
    },
    {
      "x": -1,
      "y": 7,
      "z": 6,
      "name": "Rock_Marble_Cobble",
      "rotation": 35
    },
    {
      "x": -1,
      "y": 8,
      "z": 6,
      "name": "Rock_Marble_Cobble",
      "rotation": 35
    },
    {
      "x": -1,
      "y": 9,
      "z": 6,
      "name": "Rock_Marble_Cobble",
      "rotation": 35
    },
    {
      "x": -1,
      "y": 10,
      "z": 6,
      "name": "Rock_Marble_Cobble",
      "rotation": 35
    },
    {
      "x": 0,
      "y": 6,
      "z": -3,
      "name": "Rock_Marble_Cobble",
      "rotation": 35
    },
    {
      "x": 0,
      "y": 7,
      "z": -3,
      "name": "Rock_Marble_Cobble",
      "rotation": 35
    },
    {
      "x": 0,
      "y": 8,
      "z": -3,
      "name": "Soil_Clay_GreyLight",
      "rotation": 35
    },
    {
      "x": 0,
      "y": 9,
      "z": -3,
      "name": "Rock_Marble_Cobble",
      "rotation": 35
    },
    {
      "x": 0,
      "y": 5,
      "z": -2,
      "name": "Rock_Marble",
      "rotation": 35
    },
    {
      "x": 0,
      "y": 6,
      "z": -2,
      "name": "Rock_Marble_Cobble",
      "rotation": 35
    },
    {
      "x": 0,
      "y": 7,
      "z": -2,
      "name": "Rock_Marble_Cobble",
      "rotation": 35
    },
    {
      "x": 0,
      "y": 8,
      "z": -2,
      "name": "Soil_Clay_GreyLight",
      "rotation": 35
    },
    {
      "x": 0,
      "y": 9,
      "z": -2,
      "name": "Rock_Marble_Cobble",
      "rotation": 35
    },
    {
      "x": 0,
      "y": 10,
      "z": -2,
      "name": "Rock_Marble_Cobble",
      "rotation": 35
    },
    {
      "x": 0,
      "y": 5,
      "z": -1,
      "name": "Rock_Marble",
      "rotation": 35
    },
    {
      "x": 0,
      "y": 6,
      "z": -1,
      "name": "Rock_Marble_Cobble",
      "rotation": 35
    },
    {
      "x": 0,
      "y": 7,
      "z": -1,
      "name": "Rock_Marble_Cobble",
      "rotation": 35
    },
    {
      "x": 0,
      "y": 8,
      "z": -1,
      "name": "Rock_Marble_Cobble",
      "rotation": 35
    },
    {
      "x": 0,
      "y": 9,
      "z": -1,
      "name": "Rock_Marble_Cobble",
      "rotation": 35
    },
    {
      "x": 0,
      "y": 10,
      "z": -1,
      "name": "Rock_Marble_Cobble",
      "rotation": 35
    },
    {
      "x": 0,
      "y": 11,
      "z": -1,
      "name": "Rock_Marble",
      "rotation": 35
    },
    {
      "x": 0,
      "y": 5,
      "z": 0,
      "name": "Rock_Marble",
      "rotation": 35
    },
    {
      "x": 0,
      "y": 6,
      "z": 0,
      "name": "Rock_Marble_Cobble",
      "rotation": 35
    },
    {
      "x": 0,
      "y": 7,
      "z": 0,
      "name": "Rock_Marble_Cobble",
      "rotation": 35
    },
    {
      "x": 0,
      "y": 8,
      "z": 0,
      "name": "Rock_Marble_Cobble",
      "rotation": 35
    },
    {
      "x": 0,
      "y": 9,
      "z": 0,
      "name": "Rock_Marble_Cobble",
      "rotation": 35
    },
    {
      "x": 0,
      "y": 10,
      "z": 0,
      "name": "Rock_Marble_Cobble",
      "rotation": 35
    },
    {
      "x": 0,
      "y": 11,
      "z": 0,
      "name": "Rock_Marble",
      "rotation": 35
    },
    {
      "x": 0,
      "y": 5,
      "z": 1,
      "name": "Rock_Marble",
      "rotation": 35
    },
    {
      "x": 0,
      "y": 6,
      "z": 1,
      "name": "Rock_Marble_Cobble",
      "rotation": 35
    },
    {
      "x": 0,
      "y": 7,
      "z": 1,
      "name": "Rock_Marble_Cobble",
      "rotation": 35
    },
    {
      "x": 0,
      "y": 8,
      "z": 1,
      "name": "Rock_Marble_Cobble",
      "rotation": 35
    },
    {
      "x": 0,
      "y": 9,
      "z": 1,
      "name": "Rock_Marble_Cobble",
      "rotation": 35
    },
    {
      "x": 0,
      "y": 10,
      "z": 1,
      "name": "Rock_Marble_Cobble",
      "rotation": 35
    },
    {
      "x": 0,
      "y": 11,
      "z": 1,
      "name": "Rock_Marble",
      "rotation": 35
    },
    {
      "x": 0,
      "y": 12,
      "z": 1,
      "name": "Soil_Clay_White",
      "rotation": 35
    },
    {
      "x": 0,
      "y": 5,
      "z": 2,
      "name": "Rock_Marble",
      "rotation": 35
    },
    {
      "x": 0,
      "y": 6,
      "z": 2,
      "name": "Rock_Marble_Cobble",
      "rotation": 35
    },
    {
      "x": 0,
      "y": 7,
      "z": 2,
      "name": "Rock_Marble_Cobble",
      "rotation": 35
    },
    {
      "x": 0,
      "y": 8,
      "z": 2,
      "name": "Rock_Marble_Cobble",
      "rotation": 35
    },
    {
      "x": 0,
      "y": 9,
      "z": 2,
      "name": "Rock_Marble_Cobble",
      "rotation": 35
    },
    {
      "x": 0,
      "y": 10,
      "z": 2,
      "name": "Rock_Marble_Cobble",
      "rotation": 35
    },
    {
      "x": 0,
      "y": 11,
      "z": 2,
      "name": "Rock_Marble",
      "rotation": 35
    },
    {
      "x": 0,
      "y": 12,
      "z": 2,
      "name": "Soil_Clay_White",
      "rotation": 35
    },
    {
      "x": 0,
      "y": 13,
      "z": 2,
      "name": "Rock_Marble",
      "rotation": 35
    },
    {
      "x": 0,
      "y": 5,
      "z": 3,
      "name": "Rock_Marble",
      "rotation": 35
    },
    {
      "x": 0,
      "y": 6,
      "z": 3,
      "name": "Rock_Marble_Cobble",
      "rotation": 35
    },
    {
      "x": 0,
      "y": 7,
      "z": 3,
      "name": "Rock_Marble_Cobble",
      "rotation": 35
    },
    {
      "x": 0,
      "y": 8,
      "z": 3,
      "name": "Rock_Marble_Cobble",
      "rotation": 35
    },
    {
      "x": 0,
      "y": 9,
      "z": 3,
      "name": "Rock_Marble_Cobble",
      "rotation": 35
    },
    {
      "x": 0,
      "y": 10,
      "z": 3,
      "name": "Rock_Marble_Cobble",
      "rotation": 35
    },
    {
      "x": 0,
      "y": 11,
      "z": 3,
      "name": "Rock_Marble",
      "rotation": 35
    },
    {
      "x": 0,
      "y": 12,
      "z": 3,
      "name": "Soil_Clay_White",
      "rotation": 35
    },
    {
      "x": 0,
      "y": 13,
      "z": 3,
      "name": "Rock_Marble",
      "rotation": 35
    },
    {
      "x": 0,
      "y": 5,
      "z": 4,
      "name": "Rock_Marble",
      "rotation": 35
    },
    {
      "x": 0,
      "y": 6,
      "z": 4,
      "name": "Rock_Marble_Cobble",
      "rotation": 35
    },
    {
      "x": 0,
      "y": 7,
      "z": 4,
      "name": "Rock_Marble_Cobble",
      "rotation": 35
    },
    {
      "x": 0,
      "y": 8,
      "z": 4,
      "name": "Rock_Marble_Cobble",
      "rotation": 35
    },
    {
      "x": 0,
      "y": 9,
      "z": 4,
      "name": "Rock_Marble_Cobble",
      "rotation": 35
    },
    {
      "x": 0,
      "y": 10,
      "z": 4,
      "name": "Rock_Marble_Cobble",
      "rotation": 35
    },
    {
      "x": 0,
      "y": 11,
      "z": 4,
      "name": "Rock_Marble",
      "rotation": 35
    },
    {
      "x": 0,
      "y": 12,
      "z": 4,
      "name": "Soil_Clay_White",
      "rotation": 35
    },
    {
      "x": 0,
      "y": 5,
      "z": 5,
      "name": "Rock_Marble",
      "rotation": 35
    },
    {
      "x": 0,
      "y": 6,
      "z": 5,
      "name": "Rock_Marble_Cobble",
      "rotation": 35
    },
    {
      "x": 0,
      "y": 7,
      "z": 5,
      "name": "Rock_Marble_Cobble",
      "rotation": 35
    },
    {
      "x": 0,
      "y": 8,
      "z": 5,
      "name": "Rock_Marble_Cobble",
      "rotation": 35
    },
    {
      "x": 0,
      "y": 9,
      "z": 5,
      "name": "Rock_Marble_Cobble",
      "rotation": 35
    },
    {
      "x": 0,
      "y": 10,
      "z": 5,
      "name": "Rock_Marble_Cobble",
      "rotation": 35
    },
    {
      "x": 0,
      "y": 11,
      "z": 5,
      "name": "Rock_Marble",
      "rotation": 35
    },
    {
      "x": 0,
      "y": 12,
      "z": 5,
      "name": "Soil_Clay_White",
      "rotation": 35
    },
    {
      "x": 0,
      "y": 6,
      "z": 6,
      "name": "Rock_Marble_Cobble",
      "rotation": 35
    },
    {
      "x": 0,
      "y": 7,
      "z": 6,
      "name": "Rock_Marble_Cobble",
      "rotation": 35
    },
    {
      "x": 0,
      "y": 8,
      "z": 6,
      "name": "Rock_Marble_Cobble",
      "rotation": 35
    },
    {
      "x": 0,
      "y": 9,
      "z": 6,
      "name": "Rock_Marble_Cobble",
      "rotation": 35
    },
    {
      "x": 0,
      "y": 10,
      "z": 6,
      "name": "Rock_Marble_Cobble",
      "rotation": 35
    },
    {
      "x": 0,
      "y": 8,
      "z": 7,
      "name": "Rock_Marble_Cobble",
      "rotation": 35
    },
    {
      "x": 1,
      "y": 6,
      "z": -2,
      "name": "Rock_Marble_Cobble",
      "rotation": 35
    },
    {
      "x": 1,
      "y": 7,
      "z": -2,
      "name": "Rock_Marble_Cobble",
      "rotation": 35
    },
    {
      "x": 1,
      "y": 8,
      "z": -2,
      "name": "Soil_Clay_GreyLight",
      "rotation": 35
    },
    {
      "x": 1,
      "y": 9,
      "z": -2,
      "name": "Rock_Marble_Cobble",
      "rotation": 35
    },
    {
      "x": 1,
      "y": 6,
      "z": -1,
      "name": "Rock_Marble_Cobble",
      "rotation": 35
    },
    {
      "x": 1,
      "y": 7,
      "z": -1,
      "name": "Rock_Marble_Cobble",
      "rotation": 35
    },
    {
      "x": 1,
      "y": 8,
      "z": -1,
      "name": "Rock_Marble_Cobble",
      "rotation": 35
    },
    {
      "x": 1,
      "y": 9,
      "z": -1,
      "name": "Rock_Marble_Cobble",
      "rotation": 35
    },
    {
      "x": 1,
      "y": 10,
      "z": -1,
      "name": "Rock_Marble_Cobble",
      "rotation": 35
    },
    {
      "x": 1,
      "y": 5,
      "z": 0,
      "name": "Rock_Marble",
      "rotation": 35
    },
    {
      "x": 1,
      "y": 6,
      "z": 0,
      "name": "Rock_Marble_Cobble",
      "rotation": 35
    },
    {
      "x": 1,
      "y": 7,
      "z": 0,
      "name": "Rock_Marble_Cobble",
      "rotation": 35
    },
    {
      "x": 1,
      "y": 8,
      "z": 0,
      "name": "Rock_Marble_Cobble",
      "rotation": 35
    },
    {
      "x": 1,
      "y": 9,
      "z": 0,
      "name": "Rock_Marble_Cobble",
      "rotation": 35
    },
    {
      "x": 1,
      "y": 10,
      "z": 0,
      "name": "Rock_Marble_Cobble",
      "rotation": 35
    },
    {
      "x": 1,
      "y": 11,
      "z": 0,
      "name": "Rock_Marble",
      "rotation": 35
    },
    {
      "x": 1,
      "y": 5,
      "z": 1,
      "name": "Rock_Marble",
      "rotation": 35
    },
    {
      "x": 1,
      "y": 6,
      "z": 1,
      "name": "Rock_Marble_Cobble",
      "rotation": 35
    },
    {
      "x": 1,
      "y": 7,
      "z": 1,
      "name": "Rock_Marble_Cobble",
      "rotation": 35
    },
    {
      "x": 1,
      "y": 8,
      "z": 1,
      "name": "Rock_Marble_Cobble",
      "rotation": 35
    },
    {
      "x": 1,
      "y": 9,
      "z": 1,
      "name": "Rock_Marble_Cobble",
      "rotation": 35
    },
    {
      "x": 1,
      "y": 10,
      "z": 1,
      "name": "Rock_Marble_Cobble",
      "rotation": 35
    },
    {
      "x": 1,
      "y": 11,
      "z": 1,
      "name": "Rock_Marble",
      "rotation": 35
    },
    {
      "x": 1,
      "y": 12,
      "z": 1,
      "name": "Soil_Clay_White",
      "rotation": 35
    },
    {
      "x": 1,
      "y": 5,
      "z": 2,
      "name": "Rock_Marble",
      "rotation": 35
    },
    {
      "x": 1,
      "y": 6,
      "z": 2,
      "name": "Rock_Marble_Cobble",
      "rotation": 35
    },
    {
      "x": 1,
      "y": 7,
      "z": 2,
      "name": "Rock_Marble_Cobble",
      "rotation": 35
    },
    {
      "x": 1,
      "y": 8,
      "z": 2,
      "name": "Rock_Marble_Cobble",
      "rotation": 35
    },
    {
      "x": 1,
      "y": 9,
      "z": 2,
      "name": "Rock_Marble_Cobble",
      "rotation": 35
    },
    {
      "x": 1,
      "y": 10,
      "z": 2,
      "name": "Rock_Marble_Cobble",
      "rotation": 35
    },
    {
      "x": 1,
      "y": 11,
      "z": 2,
      "name": "Rock_Marble",
      "rotation": 35
    },
    {
      "x": 1,
      "y": 12,
      "z": 2,
      "name": "Soil_Clay_White",
      "rotation": 35
    },
    {
      "x": 1,
      "y": 5,
      "z": 3,
      "name": "Rock_Marble",
      "rotation": 35
    },
    {
      "x": 1,
      "y": 6,
      "z": 3,
      "name": "Rock_Marble_Cobble",
      "rotation": 35
    },
    {
      "x": 1,
      "y": 7,
      "z": 3,
      "name": "Rock_Marble_Cobble",
      "rotation": 35
    },
    {
      "x": 1,
      "y": 8,
      "z": 3,
      "name": "Rock_Marble_Cobble",
      "rotation": 35
    },
    {
      "x": 1,
      "y": 9,
      "z": 3,
      "name": "Rock_Marble_Cobble",
      "rotation": 35
    },
    {
      "x": 1,
      "y": 10,
      "z": 3,
      "name": "Rock_Marble_Cobble",
      "rotation": 35
    },
    {
      "x": 1,
      "y": 11,
      "z": 3,
      "name": "Rock_Marble",
      "rotation": 35
    },
    {
      "x": 1,
      "y": 12,
      "z": 3,
      "name": "Soil_Clay_White",
      "rotation": 35
    },
    {
      "x": 1,
      "y": 5,
      "z": 4,
      "name": "Rock_Marble",
      "rotation": 35
    },
    {
      "x": 1,
      "y": 6,
      "z": 4,
      "name": "Rock_Marble_Cobble",
      "rotation": 35
    },
    {
      "x": 1,
      "y": 7,
      "z": 4,
      "name": "Rock_Marble_Cobble",
      "rotation": 35
    },
    {
      "x": 1,
      "y": 8,
      "z": 4,
      "name": "Rock_Marble_Cobble",
      "rotation": 35
    },
    {
      "x": 1,
      "y": 9,
      "z": 4,
      "name": "Rock_Marble_Cobble",
      "rotation": 35
    },
    {
      "x": 1,
      "y": 10,
      "z": 4,
      "name": "Rock_Marble_Cobble",
      "rotation": 35
    },
    {
      "x": 1,
      "y": 11,
      "z": 4,
      "name": "Rock_Marble",
      "rotation": 35
    },
    {
      "x": 1,
      "y": 12,
      "z": 4,
      "name": "Soil_Clay_White",
      "rotation": 35
    },
    {
      "x": 1,
      "y": 5,
      "z": 5,
      "name": "Rock_Marble",
      "rotation": 35
    },
    {
      "x": 1,
      "y": 6,
      "z": 5,
      "name": "Rock_Marble_Cobble",
      "rotation": 35
    },
    {
      "x": 1,
      "y": 7,
      "z": 5,
      "name": "Rock_Marble_Cobble",
      "rotation": 35
    },
    {
      "x": 1,
      "y": 8,
      "z": 5,
      "name": "Rock_Marble_Cobble",
      "rotation": 35
    },
    {
      "x": 1,
      "y": 9,
      "z": 5,
      "name": "Rock_Marble_Cobble",
      "rotation": 35
    },
    {
      "x": 1,
      "y": 10,
      "z": 5,
      "name": "Rock_Marble_Cobble",
      "rotation": 35
    },
    {
      "x": 1,
      "y": 11,
      "z": 5,
      "name": "Rock_Marble",
      "rotation": 35
    },
    {
      "x": 1,
      "y": 6,
      "z": 6,
      "name": "Rock_Marble_Cobble",
      "rotation": 35
    },
    {
      "x": 1,
      "y": 7,
      "z": 6,
      "name": "Rock_Marble_Cobble",
      "rotation": 35
    },
    {
      "x": 1,
      "y": 8,
      "z": 6,
      "name": "Rock_Marble_Cobble",
      "rotation": 35
    },
    {
      "x": 1,
      "y": 9,
      "z": 6,
      "name": "Rock_Marble_Cobble",
      "rotation": 35
    },
    {
      "x": 1,
      "y": 10,
      "z": 6,
      "name": "Rock_Marble_Cobble",
      "rotation": 35
    },
    {
      "x": 1,
      "y": 7,
      "z": 7,
      "name": "Rock_Marble_Cobble",
      "rotation": 35
    },
    {
      "x": 1,
      "y": 8,
      "z": 7,
      "name": "Rock_Marble_Cobble",
      "rotation": 35
    },
    {
      "x": 1,
      "y": 9,
      "z": 7,
      "name": "Rock_Marble_Cobble",
      "rotation": 35
    },
    {
      "x": 2,
      "y": 7,
      "z": -1,
      "name": "Rock_Marble_Cobble",
      "rotation": 35
    },
    {
      "x": 2,
      "y": 8,
      "z": -1,
      "name": "Rock_Marble_Cobble",
      "rotation": 35
    },
    {
      "x": 2,
      "y": 9,
      "z": -1,
      "name": "Rock_Marble_Cobble",
      "rotation": 35
    },
    {
      "x": 2,
      "y": 6,
      "z": 0,
      "name": "Rock_Marble_Cobble",
      "rotation": 35
    },
    {
      "x": 2,
      "y": 7,
      "z": 0,
      "name": "Rock_Marble_Cobble",
      "rotation": 35
    },
    {
      "x": 2,
      "y": 8,
      "z": 0,
      "name": "Rock_Marble_Cobble",
      "rotation": 35
    },
    {
      "x": 2,
      "y": 9,
      "z": 0,
      "name": "Rock_Marble_Cobble",
      "rotation": 35
    },
    {
      "x": 2,
      "y": 10,
      "z": 0,
      "name": "Rock_Marble_Cobble",
      "rotation": 35
    },
    {
      "x": 2,
      "y": 5,
      "z": 1,
      "name": "Rock_Marble",
      "rotation": 35
    },
    {
      "x": 2,
      "y": 6,
      "z": 1,
      "name": "Rock_Marble_Cobble",
      "rotation": 35
    },
    {
      "x": 2,
      "y": 7,
      "z": 1,
      "name": "Rock_Marble_Cobble",
      "rotation": 35
    },
    {
      "x": 2,
      "y": 8,
      "z": 1,
      "name": "Rock_Marble_Cobble",
      "rotation": 35
    },
    {
      "x": 2,
      "y": 9,
      "z": 1,
      "name": "Rock_Marble_Cobble",
      "rotation": 35
    },
    {
      "x": 2,
      "y": 10,
      "z": 1,
      "name": "Rock_Marble_Cobble",
      "rotation": 35
    },
    {
      "x": 2,
      "y": 11,
      "z": 1,
      "name": "Rock_Marble",
      "rotation": 35
    },
    {
      "x": 2,
      "y": 5,
      "z": 2,
      "name": "Rock_Marble",
      "rotation": 35
    },
    {
      "x": 2,
      "y": 6,
      "z": 2,
      "name": "Rock_Marble_Cobble",
      "rotation": 35
    },
    {
      "x": 2,
      "y": 7,
      "z": 2,
      "name": "Rock_Marble_Cobble",
      "rotation": 35
    },
    {
      "x": 2,
      "y": 8,
      "z": 2,
      "name": "Rock_Marble_Cobble",
      "rotation": 35
    },
    {
      "x": 2,
      "y": 9,
      "z": 2,
      "name": "Rock_Marble_Cobble",
      "rotation": 35
    },
    {
      "x": 2,
      "y": 10,
      "z": 2,
      "name": "Rock_Marble_Cobble",
      "rotation": 35
    },
    {
      "x": 2,
      "y": 11,
      "z": 2,
      "name": "Rock_Marble",
      "rotation": 35
    },
    {
      "x": 2,
      "y": 5,
      "z": 3,
      "name": "Rock_Marble",
      "rotation": 35
    },
    {
      "x": 2,
      "y": 6,
      "z": 3,
      "name": "Rock_Marble_Cobble",
      "rotation": 35
    },
    {
      "x": 2,
      "y": 7,
      "z": 3,
      "name": "Rock_Marble_Cobble",
      "rotation": 35
    },
    {
      "x": 2,
      "y": 8,
      "z": 3,
      "name": "Rock_Marble_Cobble",
      "rotation": 35
    },
    {
      "x": 2,
      "y": 9,
      "z": 3,
      "name": "Rock_Marble_Cobble",
      "rotation": 35
    },
    {
      "x": 2,
      "y": 10,
      "z": 3,
      "name": "Rock_Marble_Cobble",
      "rotation": 35
    },
    {
      "x": 2,
      "y": 11,
      "z": 3,
      "name": "Rock_Marble",
      "rotation": 35
    },
    {
      "x": 2,
      "y": 12,
      "z": 3,
      "name": "Soil_Clay_White",
      "rotation": 35
    },
    {
      "x": 2,
      "y": 5,
      "z": 4,
      "name": "Rock_Marble",
      "rotation": 35
    },
    {
      "x": 2,
      "y": 6,
      "z": 4,
      "name": "Rock_Marble_Cobble",
      "rotation": 35
    },
    {
      "x": 2,
      "y": 7,
      "z": 4,
      "name": "Rock_Marble_Cobble",
      "rotation": 35
    },
    {
      "x": 2,
      "y": 8,
      "z": 4,
      "name": "Rock_Marble_Cobble",
      "rotation": 35
    },
    {
      "x": 2,
      "y": 9,
      "z": 4,
      "name": "Rock_Marble_Cobble",
      "rotation": 35
    },
    {
      "x": 2,
      "y": 10,
      "z": 4,
      "name": "Rock_Marble_Cobble",
      "rotation": 35
    },
    {
      "x": 2,
      "y": 11,
      "z": 4,
      "name": "Rock_Marble",
      "rotation": 35
    },
    {
      "x": 2,
      "y": 12,
      "z": 4,
      "name": "Soil_Clay_White",
      "rotation": 35
    },
    {
      "x": 2,
      "y": 5,
      "z": 5,
      "name": "Rock_Marble",
      "rotation": 35
    },
    {
      "x": 2,
      "y": 6,
      "z": 5,
      "name": "Rock_Marble_Cobble",
      "rotation": 35
    },
    {
      "x": 2,
      "y": 7,
      "z": 5,
      "name": "Rock_Marble_Cobble",
      "rotation": 35
    },
    {
      "x": 2,
      "y": 8,
      "z": 5,
      "name": "Rock_Marble_Cobble",
      "rotation": 35
    },
    {
      "x": 2,
      "y": 9,
      "z": 5,
      "name": "Rock_Marble_Cobble",
      "rotation": 35
    },
    {
      "x": 2,
      "y": 10,
      "z": 5,
      "name": "Rock_Marble_Cobble",
      "rotation": 35
    },
    {
      "x": 2,
      "y": 11,
      "z": 5,
      "name": "Rock_Marble",
      "rotation": 35
    },
    {
      "x": 2,
      "y": 6,
      "z": 6,
      "name": "Rock_Marble_Cobble",
      "rotation": 35
    },
    {
      "x": 2,
      "y": 7,
      "z": 6,
      "name": "Rock_Marble_Cobble",
      "rotation": 35
    },
    {
      "x": 2,
      "y": 8,
      "z": 6,
      "name": "Rock_Marble_Cobble",
      "rotation": 35
    },
    {
      "x": 2,
      "y": 9,
      "z": 6,
      "name": "Rock_Marble_Cobble",
      "rotation": 35
    },
    {
      "x": 2,
      "y": 10,
      "z": 6,
      "name": "Rock_Marble_Cobble",
      "rotation": 35
    },
    {
      "x": 2,
      "y": 8,
      "z": 7,
      "name": "Rock_Marble_Cobble",
      "rotation": 35
    },
    {
      "x": 2,
      "y": 9,
      "z": 7,
      "name": "Rock_Marble_Cobble",
      "rotation": 35
    },
    {
      "x": 3,
      "y": 7,
      "z": 0,
      "name": "Rock_Marble_Cobble",
      "rotation": 35
    },
    {
      "x": 3,
      "y": 8,
      "z": 0,
      "name": "Rock_Marble_Cobble",
      "rotation": 35
    },
    {
      "x": 3,
      "y": 6,
      "z": 1,
      "name": "Rock_Marble_Cobble",
      "rotation": 35
    },
    {
      "x": 3,
      "y": 7,
      "z": 1,
      "name": "Rock_Marble_Cobble",
      "rotation": 35
    },
    {
      "x": 3,
      "y": 8,
      "z": 1,
      "name": "Rock_Marble_Cobble",
      "rotation": 35
    },
    {
      "x": 3,
      "y": 9,
      "z": 1,
      "name": "Rock_Marble_Cobble",
      "rotation": 35
    },
    {
      "x": 3,
      "y": 6,
      "z": 2,
      "name": "Rock_Marble_Cobble",
      "rotation": 35
    },
    {
      "x": 3,
      "y": 7,
      "z": 2,
      "name": "Rock_Marble_Cobble",
      "rotation": 35
    },
    {
      "x": 3,
      "y": 8,
      "z": 2,
      "name": "Rock_Marble_Cobble",
      "rotation": 35
    },
    {
      "x": 3,
      "y": 9,
      "z": 2,
      "name": "Rock_Marble_Cobble",
      "rotation": 35
    },
    {
      "x": 3,
      "y": 10,
      "z": 2,
      "name": "Rock_Marble_Cobble",
      "rotation": 35
    },
    {
      "x": 3,
      "y": 6,
      "z": 3,
      "name": "Rock_Marble_Cobble",
      "rotation": 35
    },
    {
      "x": 3,
      "y": 7,
      "z": 3,
      "name": "Rock_Marble_Cobble",
      "rotation": 35
    },
    {
      "x": 3,
      "y": 8,
      "z": 3,
      "name": "Rock_Marble_Cobble",
      "rotation": 35
    },
    {
      "x": 3,
      "y": 9,
      "z": 3,
      "name": "Rock_Marble_Cobble",
      "rotation": 35
    },
    {
      "x": 3,
      "y": 10,
      "z": 3,
      "name": "Rock_Marble_Cobble",
      "rotation": 35
    },
    {
      "x": 3,
      "y": 11,
      "z": 3,
      "name": "Rock_Marble",
      "rotation": 35
    },
    {
      "x": 3,
      "y": 6,
      "z": 4,
      "name": "Rock_Marble_Cobble",
      "rotation": 35
    },
    {
      "x": 3,
      "y": 7,
      "z": 4,
      "name": "Rock_Marble_Cobble",
      "rotation": 35
    },
    {
      "x": 3,
      "y": 8,
      "z": 4,
      "name": "Rock_Marble_Cobble",
      "rotation": 35
    },
    {
      "x": 3,
      "y": 9,
      "z": 4,
      "name": "Rock_Marble_Cobble",
      "rotation": 35
    },
    {
      "x": 3,
      "y": 10,
      "z": 4,
      "name": "Rock_Marble_Cobble",
      "rotation": 35
    },
    {
      "x": 3,
      "y": 11,
      "z": 4,
      "name": "Rock_Marble",
      "rotation": 35
    },
    {
      "x": 3,
      "y": 6,
      "z": 5,
      "name": "Rock_Marble_Cobble",
      "rotation": 35
    },
    {
      "x": 3,
      "y": 7,
      "z": 5,
      "name": "Rock_Marble_Cobble",
      "rotation": 35
    },
    {
      "x": 3,
      "y": 8,
      "z": 5,
      "name": "Rock_Marble_Cobble",
      "rotation": 35
    },
    {
      "x": 3,
      "y": 9,
      "z": 5,
      "name": "Rock_Marble_Cobble",
      "rotation": 35
    },
    {
      "x": 3,
      "y": 10,
      "z": 5,
      "name": "Rock_Marble_Cobble",
      "rotation": 35
    },
    {
      "x": 3,
      "y": 7,
      "z": 6,
      "name": "Rock_Marble_Cobble",
      "rotation": 35
    },
    {
      "x": 3,
      "y": 8,
      "z": 6,
      "name": "Rock_Marble_Cobble",
      "rotation": 35
    },
    {
      "x": 3,
      "y": 9,
      "z": 6,
      "name": "Rock_Marble_Cobble",
      "rotation": 35
    },
    {
      "x": 4,
      "y": 7,
      "z": 2,
      "name": "Rock_Marble_Cobble",
      "rotation": 35
    },
    {
      "x": 4,
      "y": 8,
      "z": 2,
      "name": "Rock_Marble_Cobble",
      "rotation": 35
    },
    {
      "x": 4,
      "y": 7,
      "z": 3,
      "name": "Rock_Marble_Cobble",
      "rotation": 35
    },
    {
      "x": 4,
      "y": 8,
      "z": 3,
      "name": "Rock_Marble_Cobble",
      "rotation": 35
    },
    {
      "x": 4,
      "y": 9,
      "z": 3,
      "name": "Rock_Marble_Cobble",
      "rotation": 35
    },
    {
      "x": 4,
      "y": 7,
      "z": 4,
      "name": "Rock_Marble_Cobble",
      "rotation": 35
    },
    {
      "x": 4,
      "y": 8,
      "z": 4,
      "name": "Rock_Marble_Cobble",
      "rotation": 35
    },
    {
      "x": 4,
      "y": 9,
      "z": 4,
      "name": "Rock_Marble_Cobble",
      "rotation": 35
    },
    {
      "x": 4,
      "y": 8,
      "z": 5,
      "name": "Rock_Marble_Cobble",
      "rotation": 35
    }
  ]
}