{
  "version": 8,
  "blockIdVersion": 11,
  "anchorX": 0,
  "anchorY": 3,
  "anchorZ": 0,
  "blocks": [
    {
      "x": -8,
      "y": 0,
      "z": -3,
      "name": "Plant_Coral_Block_Blue"
    },
    {
      "x": -8,
      "y": 1,
      "z": -3,
      "name": "Plant_Coral_Block_Blue"
    },
    {
      "x": -8,
      "y": 2,
      "z": -3,
      "name": "Plant_Coral_Block_Blue"
    },
    {
      "x": -8,
      "y": 3,
      "z": -3,
      "name": "Plant_Coral_Block_Blue"
    },
    {
      "x": -8,
      "y": 4,
      "z": -3,
      "name": "Plant_Coral_Block_Blue"
    },
    {
      "x": -8,
      "y": 5,
      "z": -3,
      "name": "Plant_Coral_Block_Blue"
    },
    {
      "x": -8,
      "y": 0,
      "z": -2,
      "name": "Plant_Coral_Block_Blue"
    },
    {
      "x": -8,
      "y": 1,
      "z": -2,
      "name": "Plant_Coral_Block_Blue"
    },
    {
      "x": -8,
      "y": 2,
      "z": -2,
      "name": "Plant_Coral_Block_Blue"
    },
    {
      "x": -8,
      "y": 3,
      "z": -2,
      "name": "Plant_Coral_Block_Blue"
    },
    {
      "x": -8,
      "y": 4,
      "z": -2,
      "name": "Plant_Coral_Block_Blue"
    },
    {
      "x": -8,
      "y": 5,
      "z": -2,
      "name": "Plant_Coral_Block_Blue"
    },
    {
      "x": -8,
      "y": 6,
      "z": -2,
      "name": "Plant_Coral_Block_Blue"
    },
    {
      "x": -8,
      "y": 7,
      "z": -2,
      "name": "Plant_Coral_Block_Blue"
    },
    {
      "x": -8,
      "y": 20,
      "z": -1,
      "name": "Plant_Coral_Block_BSOD"
    },
    {
      "x": -8,
      "y": 20,
      "z": 0,
      "name": "Plant_Coral_Block_BSOD"
    },
    {
      "x": -8,
      "y": 15,
      "z": 1,
      "name": "Plant_Coral_Block_BSOD"
    },
    {
      "x": -8,
      "y": 14,
      "z": 2,
      "name": "Plant_Coral_Block_BSOD"
    },
    {
      "x": -8,
      "y": 15,
      "z": 2,
      "name": "Plant_Coral_Block_BSOD"
    },
    {
      "x": -8,
      "y": 14,
      "z": 3,
      "name": "Plant_Coral_Block_BSOD"
    },
    {
      "x": -8,
      "y": 15,
      "z": 3,
      "name": "Plant_Coral_Block_BSOD"
    },
    {
      "x": -7,
      "y": 0,
      "z": -3,
      "name": "Plant_Coral_Block_Blue"
    },
    {
      "x": -7,
      "y": 1,
      "z": -3,
      "name": "Plant_Coral_Block_Blue"
    },
    {
      "x": -7,
      "y": 2,
      "z": -3,
      "name": "Plant_Coral_Block_Blue"
    },
    {
      "x": -7,
      "y": 3,
      "z": -3,
      "name": "Plant_Coral_Block_Blue"
    },
    {
      "x": -7,
      "y": 4,
      "z": -3,
      "name": "Plant_Coral_Block_Blue"
    },
    {
      "x": -7,
      "y": 5,
      "z": -3,
      "name": "Plant_Coral_Block_Blue"
    },
    {
      "x": -7,
      "y": 6,
      "z": -3,
      "name": "Plant_Coral_Block_Blue"
    },
    {
      "x": -7,
      "y": 7,
      "z": -3,
      "name": "Plant_Coral_Block_Blue"
    },
    {
      "x": -7,
      "y": 24,
      "z": -3,
      "name": "Plant_Coral_Block_BSOD"
    },
    {
      "x": -7,
      "y": 25,
      "z": -3,
      "name": "Plant_Coral_Block_BSOD"
    },
    {
      "x": -7,
      "y": 0,
      "z": -2,
      "name": "Plant_Coral_Block_Blue"
    },
    {
      "x": -7,
      "y": 1,
      "z": -2,
      "name": "Plant_Coral_Block_Blue"
    },
    {
      "x": -7,
      "y": 2,
      "z": -2,
      "name": "Plant_Coral_Block_Blue"
    },
    {
      "x": -7,
      "y": 3,
      "z": -2,
      "name": "Plant_Coral_Block_Blue"
    },
    {
      "x": -7,
      "y": 4,
      "z": -2,
      "name": "Plant_Coral_Block_Blue"
    },
    {
      "x": -7,
      "y": 5,
      "z": -2,
      "name": "Plant_Coral_Block_Blue"
    },
    {
      "x": -7,
      "y": 6,
      "z": -2,
      "name": "Plant_Coral_Block_Blue"
    },
    {
      "x": -7,
      "y": 7,
      "z": -2,
      "name": "Plant_Coral_Block_Blue"
    },
    {
      "x": -7,
      "y": 8,
      "z": -2,
      "name": "Plant_Coral_Block_Blue"
    },
    {
      "x": -7,
      "y": 9,
      "z": -2,
      "name": "Plant_Coral_Block_Blue"
    },
    {
      "x": -7,
      "y": 20,
      "z": -2,
      "name": "Plant_Coral_Block_BSOD"
    },
    {
      "x": -7,
      "y": 23,
      "z": -2,
      "name": "Plant_Coral_Block_BSOD"
    },
    {
      "x": -7,
      "y": 24,
      "z": -2,
      "name": "Plant_Coral_Block_BSOD"
    },
    {
      "x": -7,
      "y": 25,
      "z": -2,
      "name": "Plant_Coral_Block_BSOD"
    },
    {
      "x": -7,
      "y": 7,
      "z": -1,
      "name": "Plant_Coral_Block_Blue"
    },
    {
      "x": -7,
      "y": 8,
      "z": -1,
      "name": "Plant_Coral_Block_Blue"
    },
    {
      "x": -7,
      "y": 9,
      "z": -1,
      "name": "Plant_Coral_Block_Blue"
    },
    {
      "x": -7,
      "y": 19,
      "z": -1,
      "name": "Plant_Coral_Block_BSOD"
    },
    {
      "x": -7,
      "y": 15,
      "z": 0,
      "name": "Plant_Coral_Block_BSOD"
    },
    {
      "x": -7,
      "y": 18,
      "z": 0,
      "name": "Plant_Coral_Block_BSOD"
    },
    {
      "x": -7,
      "y": 19,
      "z": 0,
      "name": "Plant_Coral_Block_BSOD"
    },
    {
      "x": -7,
      "y": 22,
      "z": 0,
      "name": "Plant_Coral_Block_BSOD"
    },
    {
      "x": -7,
      "y": 23,
      "z": 0,
      "name": "Plant_Coral_Block_BSOD"
    },
    {
      "x": -7,
      "y": 24,
      "z": 0,
      "name": "Plant_Coral_Block_BSOD"
    },
    {
      "x": -7,
      "y": 25,
      "z": 0,
      "name": "Plant_Coral_Block_BSOD"
    },
    {
      "x": -7,
      "y": 6,
      "z": 1,
      "name": "Plant_Coral_Block_Blue"
    },
    {
      "x": -7,
      "y": 7,
      "z": 1,
      "name": "Plant_Coral_Block_Blue"
    },
    {
      "x": -7,
      "y": 10,
      "z": 1,
      "name": "Plant_Coral_Block_Blue"
    },
    {
      "x": -7,
      "y": 11,
      "z": 1,
      "name": "Plant_Coral_Block_Blue"
    },
    {
      "x": -7,
      "y": 14,
      "z": 1,
      "name": "Plant_Coral_Block_BSOD"
    },
    {
      "x": -7,
      "y": 19,
      "z": 1,
      "name": "Plant_Coral_Block_BSOD"
    },
    {
      "x": -7,
      "y": 20,
      "z": 1,
      "name": "Plant_Coral_Block_BSOD"
    },
    {
      "x": -7,
      "y": 23,
      "z": 1,
      "name": "Plant_Coral_Block_BSOD"
    },
    {
      "x": -7,
      "y": 24,
      "z": 1,
      "name": "Plant_Coral_Block_BSOD"
    },
    {
      "x": -7,
      "y": 25,
      "z": 1,
      "name": "Plant_Coral_Block_BSOD"
    },
    {
      "x": -7,
      "y": 0,
      "z": 2,
      "name": "Plant_Coral_Block_Blue"
    },
    {
      "x": -7,
      "y": 1,
      "z": 2,
      "name": "Plant_Coral_Block_Blue"
    },
    {
      "x": -7,
      "y": 2,
      "z": 2,
      "name": "Plant_Coral_Block_Blue"
    },
    {
      "x": -7,
      "y": 3,
      "z": 2,
      "name": "Plant_Coral_Block_Blue"
    },
    {
      "x": -7,
      "y": 4,
      "z": 2,
      "name": "Plant_Coral_Block_Blue"
    },
    {
      "x": -7,
      "y": 5,
      "z": 2,
      "name": "Plant_Coral_Block_Blue"
    },
    {
      "x": -7,
      "y": 6,
      "z": 2,
      "name": "Plant_Coral_Block_Blue"
    },
    {
      "x": -7,
      "y": 7,
      "z": 2,
      "name": "Plant_Coral_Block_Blue"
    },
    {
      "x": -7,
      "y": 10,
      "z": 2,
      "name": "Plant_Coral_Block_Blue"
    },
    {
      "x": -7,
      "y": 11,
      "z": 2,
      "name": "Plant_Coral_Block_Blue"
    },
    {
      "x": -7,
      "y": 13,
      "z": 2,
      "name": "Plant_Coral_Block_BSOD"
    },
    {
      "x": -7,
      "y": 14,
      "z": 2,
      "name": "Rock_Volcanic_Cracked_Poisoned"
    },
    {
      "x": -7,
      "y": 0,
      "z": 3,
      "name": "Plant_Coral_Block_Blue"
    },
    {
      "x": -7,
      "y": 1,
      "z": 3,
      "name": "Plant_Coral_Block_Blue"
    },
    {
      "x": -7,
      "y": 2,
      "z": 3,
      "name": "Plant_Coral_Block_Blue"
    },
    {
      "x": -7,
      "y": 3,
      "z": 3,
      "name": "Plant_Coral_Block_Blue"
    },
    {
      "x": -7,
      "y": 4,
      "z": 3,
      "name": "Plant_Coral_Block_Blue"
    },
    {
      "x": -7,
      "y": 5,
      "z": 3,
      "name": "Plant_Coral_Block_Blue"
    },
    {
      "x": -7,
      "y": 6,
      "z": 3,
      "name": "Plant_Coral_Block_Blue"
    },
    {
      "x": -7,
      "y": 13,
      "z": 3,
      "name": "Plant_Coral_Block_BSOD"
    },
    {
      "x": -7,
      "y": 14,
      "z": 3,
      "name": "Rock_Volcanic_Cracked_Poisoned"
    },
    {
      "x": -7,
      "y": 12,
      "z": 4,
      "name": "Plant_Coral_Block_Blue"
    },
    {
      "x": -7,
      "y": 13,
      "z": 4,
      "name": "Plant_Coral_Block_BSOD"
    },
    {
      "x": -7,
      "y": 14,
      "z": 4,
      "name": "Plant_Coral_Block_BSOD"
    },
    {
      "x": -7,
      "y": 15,
      "z": 4,
      "name": "Plant_Coral_Block_BSOD"
    },
    {
      "x": -7,
      "y": 23,
      "z": 4,
      "name": "Plant_Coral_Block_BSOD"
    },
    {
      "x": -7,
      "y": 13,
      "z": 5,
      "name": "Plant_Coral_Block_Blue"
    },
    {
      "x": -7,
      "y": 14,
      "z": 5,
      "name": "Plant_Coral_Block_BSOD"
    },
    {
      "x": -7,
      "y": 22,
      "z": 5,
      "name": "Plant_Coral_Block_BSOD"
    },
    {
      "x": -7,
      "y": 23,
      "z": 5,
      "name": "Plant_Coral_Block_BSOD"
    },
    {
      "x": -7,
      "y": 22,
      "z": 6,
      "name": "Plant_Coral_Block_BSOD"
    },
    {
      "x": -7,
      "y": 23,
      "z": 6,
      "name": "Plant_Coral_Block_BSOD"
    },
    {
      "x": -6,
      "y": 24,
      "z": -5,
      "name": "Plant_Coral_Block_BSOD"
    },
    {
      "x": -6,
      "y": 25,
      "z": -5,
      "name": "Plant_Coral_Block_BSOD"
    },
    {
      "x": -6,
      "y": 23,
      "z": -4,
      "name": "Plant_Coral_Block_BSOD"
    },
    {
      "x": -6,
      "y": 24,
      "z": -4,
      "name": "Plant_Coral_Block_BSOD"
    },
    {
      "x": -6,
      "y": 25,
      "z": -4,
      "name": "Plant_Coral_Block_BSOD"
    },
    {
      "x": -6,
      "y": 20,
      "z": -3,
      "name": "Plant_Coral_Block_BSOD"
    },
    {
      "x": -6,
      "y": 21,
      "z": -3,
      "name": "Plant_Coral_Block_BSOD"
    },
    {
      "x": -6,
      "y": 22,
      "z": -3,
      "name": "Plant_Coral_Block_BSOD"
    },
    {
      "x": -6,
      "y": 23,
      "z": -3,
      "name": "Plant_Coral_Block_BSOD"
    },
    {
      "x": -6,
      "y": 24,
      "z": -3,
      "name": "Rock_Volcanic_Cracked_Poisoned"
    },
    {
      "x": -6,
      "y": 19,
      "z": -2,
      "name": "Plant_Coral_Block_BSOD"
    },
    {
      "x": -6,
      "y": 20,
      "z": -2,
      "name": "Plant_Coral_Block_BSOD"
    },
    {
      "x": -6,
      "y": 21,
      "z": -2,
      "name": "Plant_Coral_Block_BSOD"
    },
    {
      "x": -6,
      "y": 22,
      "z": -2,
      "name": "Plant_Coral_Block_BSOD"
    },
    {
      "x": -6,
      "y": 23,
      "z": -2,
      "name": "Plant_Coral_Block_BSOD"
    },
    {
      "x": -6,
      "y": 24,
      "z": -2,
      "name": "Rock_Volcanic_Cracked_Poisoned"
    },
    {
      "x": -6,
      "y": 9,
      "z": -1,
      "name": "Plant_Coral_Block_Blue"
    },
    {
      "x": -6,
      "y": 10,
      "z": -1,
      "name": "Plant_Coral_Block_Blue"
    },
    {
      "x": -6,
      "y": 11,
      "z": -1,
      "name": "Plant_Coral_Block_Blue"
    },
    {
      "x": -6,
      "y": 12,
      "z": -1,
      "name": "Plant_Coral_Block_Blue"
    },
    {
      "x": -6,
      "y": 18,
      "z": -1,
      "name": "Plant_Coral_Block_BSOD"
    },
    {
      "x": -6,
      "y": 23,
      "z": -1,
      "name": "Plant_Coral_Block_BSOD"
    },
    {
      "x": -6,
      "y": 24,
      "z": -1,
      "name": "Plant_Coral_Block_BSOD"
    },
    {
      "x": -6,
      "y": 25,
      "z": -1,
      "name": "Plant_Coral_Block_BSOD"
    },
    {
      "x": -6,
      "y": 8,
      "z": 0,
      "name": "Plant_Coral_Block_Blue"
    },
    {
      "x": -6,
      "y": 9,
      "z": 0,
      "name": "Plant_Coral_Block_Blue"
    },
    {
      "x": -6,
      "y": 10,
      "z": 0,
      "name": "Plant_Coral_Block_Blue"
    },
    {
      "x": -6,
      "y": 11,
      "z": 0,
      "name": "Plant_Coral_Block_Blue"
    },
    {
      "x": -6,
      "y": 12,
      "z": 0,
      "name": "Plant_Coral_Block_Blue"
    },
    {
      "x": -6,
      "y": 13,
      "z": 0,
      "name": "Plant_Coral_Block_BSOD"
    },
    {
      "x": -6,
      "y": 14,
      "z": 0,
      "name": "Plant_Coral_Block_BSOD"
    },
    {
      "x": -6,
      "y": 15,
      "z": 0,
      "name": "Plant_Coral_Block_BSOD"
    },
    {
      "x": -6,
      "y": 17,
      "z": 0,
      "name": "Plant_Coral_Block_BSOD"
    },
    {
      "x": -6,
      "y": 18,
      "z": 0,
      "name": "Plant_Coral_Block_BSOD"
    },
    {
      "x": -6,
      "y": 19,
      "z": 0,
      "name": "Plant_Coral_Block_BSOD"
    },
    {
      "x": -6,
      "y": 20,
      "z": 0,
      "name": "Plant_Coral_Block_BSOD"
    },
    {
      "x": -6,
      "y": 21,
      "z": 0,
      "name": "Plant_Coral_Block_BSOD"
    },
    {
      "x": -6,
      "y": 22,
      "z": 0,
      "name": "Plant_Coral_Block_BSOD"
    },
    {
      "x": -6,
      "y": 23,
      "z": 0,
      "name": "Rock_Volcanic_Cracked_Poisoned"
    },
    {
      "x": -6,
      "y": 6,
      "z": 1,
      "name": "Plant_Coral_Block_Blue"
    },
    {
      "x": -6,
      "y": 7,
      "z": 1,
      "name": "Plant_Coral_Block_Blue"
    },
    {
      "x": -6,
      "y": 8,
      "z": 1,
      "name": "Plant_Coral_Block_Blue"
    },
    {
      "x": -6,
      "y": 9,
      "z": 1,
      "name": "Plant_Coral_Block_Blue"
    },
    {
      "x": -6,
      "y": 10,
      "z": 1,
      "name": "Plant_Coral_Block_Blue"
    },
    {
      "x": -6,
      "y": 11,
      "z": 1,
      "name": "Plant_Coral_Block_Blue"
    },
    {
      "x": -6,
      "y": 12,
      "z": 1,
      "name": "Plant_Coral_Block_BSOD"
    },
    {
      "x": -6,
      "y": 13,
      "z": 1,
      "name": "Plant_Coral_Block_BSOD"
    },
    {
      "x": -6,
      "y": 14,
      "z": 1,
      "name": "Rock_Volcanic_Cracked_Poisoned"
    },
    {
      "x": -6,
      "y": 18,
      "z": 1,
      "name": "Plant_Coral_Block_BSOD"
    },
    {
      "x": -6,
      "y": 19,
      "z": 1,
      "name": "Plant_Coral_Block_BSOD"
    },
    {
      "x": -6,
      "y": 20,
      "z": 1,
      "name": "Plant_Coral_Block_BSOD"
    },
    {
      "x": -6,
      "y": 21,
      "z": 1,
      "name": "Plant_Coral_Block_BSOD"
    },
    {
      "x": -6,
      "y": 22,
      "z": 1,
      "name": "Plant_Coral_Block_BSOD"
    },
    {
      "x": -6,
      "y": 23,
      "z": 1,
      "name": "Plant_Coral_Block_BSOD"
    },
    {
      "x": -6,
      "y": 24,
      "z": 1,
      "name": "Rock_Volcanic_Cracked_Poisoned"
    },
    {
      "x": -6,
      "y": 0,
      "z": 2,
      "name": "Plant_Coral_Block_Blue"
    },
    {
      "x": -6,
      "y": 1,
      "z": 2,
      "name": "Plant_Coral_Block_Blue"
    },
    {
      "x": -6,
      "y": 2,
      "z": 2,
      "name": "Plant_Coral_Block_Blue"
    },
    {
      "x": -6,
      "y": 3,
      "z": 2,
      "name": "Plant_Coral_Block_Blue"
    },
    {
      "x": -6,
      "y": 4,
      "z": 2,
      "name": "Plant_Coral_Block_Blue"
    },
    {
      "x": -6,
      "y": 5,
      "z": 2,
      "name": "Plant_Coral_Block_Blue"
    },
    {
      "x": -6,
      "y": 6,
      "z": 2,
      "name": "Plant_Coral_Block_Blue"
    },
    {
      "x": -6,
      "y": 7,
      "z": 2,
      "name": "Plant_Coral_Block_Blue"
    },
    {
      "x": -6,
      "y": 9,
      "z": 2,
      "name": "Plant_Coral_Block_Blue"
    },
    {
      "x": -6,
      "y": 10,
      "z": 2,
      "name": "Plant_Coral_Block_Blue"
    },
    {
      "x": -6,
      "y": 11,
      "z": 2,
      "name": "Plant_Coral_Block_Blue"
    },
    {
      "x": -6,
      "y": 12,
      "z": 2,
      "name": "Plant_Coral_Block_BSOD"
    },
    {
      "x": -6,
      "y": 13,
      "z": 2,
      "name": "Plant_Coral_Block_BSOD"
    },
    {
      "x": -6,
      "y": 14,
      "z": 2,
      "name": "Rock_Volcanic_Cracked_Poisoned"
    },
    {
      "x": -6,
      "y": 19,
      "z": 2,
      "name": "Plant_Coral_Block_BSOD"
    },
    {
      "x": -6,
      "y": 20,
      "z": 2,
      "name": "Plant_Coral_Block_BSOD"
    },
    {
      "x": -6,
      "y": 21,
      "z": 2,
      "name": "Plant_Coral_Block_Blue"
    },
    {
      "x": -6,
      "y": 22,
      "z": 2,
      "name": "Plant_Coral_Block_BSOD"
    },
    {
      "x": -6,
      "y": 23,
      "z": 2,
      "name": "Plant_Coral_Block_BSOD"
    },
    {
      "x": -6,
      "y": 24,
      "z": 2,
      "name": "Plant_Coral_Block_BSOD"
    },
    {
      "x": -6,
      "y": 25,
      "z": 2,
      "name": "Plant_Coral_Block_BSOD"
    },
    {
      "x": -6,
      "y": 0,
      "z": 3,
      "name": "Plant_Coral_Block_Blue"
    },
    {
      "x": -6,
      "y": 1,
      "z": 3,
      "name": "Plant_Coral_Block_Blue"
    },
    {
      "x": -6,
      "y": 2,
      "z": 3,
      "name": "Plant_Coral_Block_Blue"
    },
    {
      "x": -6,
      "y": 3,
      "z": 3,
      "name": "Plant_Coral_Block_Blue"
    },
    {
      "x": -6,
      "y": 4,
      "z": 3,
      "name": "Plant_Coral_Block_Blue"
    },
    {
      "x": -6,
      "y": 5,
      "z": 3,
      "name": "Plant_Coral_Block_Blue"
    },
    {
      "x": -6,
      "y": 6,
      "z": 3,
      "name": "Plant_Coral_Block_Blue"
    },
    {
      "x": -6,
      "y": 10,
      "z": 3,
      "name": "Plant_Coral_Block_Blue"
    },
    {
      "x": -6,
      "y": 11,
      "z": 3,
      "name": "Plant_Coral_Block_Blue"
    },
    {
      "x": -6,
      "y": 12,
      "z": 3,
      "name": "Plant_Coral_Block_BSOD"
    },
    {
      "x": -6,
      "y": 13,
      "z": 3,
      "name": "Plant_Coral_Block_BSOD"
    },
    {
      "x": -6,
      "y": 14,
      "z": 3,
      "name": "Rock_Volcanic_Cracked_Poisoned"
    },
    {
      "x": -6,
      "y": 20,
      "z": 3,
      "name": "Plant_Coral_Block_Blue"
    },
    {
      "x": -6,
      "y": 21,
      "z": 3,
      "name": "Plant_Coral_Block_BSOD"
    },
    {
      "x": -6,
      "y": 22,
      "z": 3,
      "name": "Plant_Coral_Block_BSOD"
    },
    {
      "x": -6,
      "y": 23,
      "z": 3,
      "name": "Plant_Coral_Block_BSOD"
    },
    {
      "x": -6,
      "y": 24,
      "z": 3,
      "name": "Plant_Coral_Block_BSOD"
    },
    {
      "x": -6,
      "y": 25,
      "z": 3,
      "name": "Plant_Coral_Block_BSOD"
    },
    {
      "x": -6,
      "y": 10,
      "z": 4,
      "name": "Plant_Coral_Block_Blue"
    },
    {
      "x": -6,
      "y": 11,
      "z": 4,
      "name": "Plant_Coral_Block_Blue"
    },
    {
      "x": -6,
      "y": 12,
      "z": 4,
      "name": "Plant_Coral_Block_BSOD"
    },
    {
      "x": -6,
      "y": 13,
      "z": 4,
      "name": "Plant_Coral_Block_BSOD"
    },
    {
      "x": -6,
      "y": 14,
      "z": 4,
      "name": "Rock_Volcanic_Cracked_Poisoned"
    },
    {
      "x": -6,
      "y": 20,
      "z": 4,
      "name": "Plant_Coral_Block_BSOD"
    },
    {
      "x": -6,
      "y": 21,
      "z": 4,
      "name": "Plant_Coral_Block_BSOD"
    },
    {
      "x": -6,
      "y": 22,
      "z": 4,
      "name": "Plant_Coral_Block_BSOD"
    },
    {
      "x": -6,
      "y": 12,
      "z": 5,
      "name": "Plant_Coral_Block_Blue"
    },
    {
      "x": -6,
      "y": 13,
      "z": 5,
      "name": "Plant_Coral_Block_BSOD"
    },
    {
      "x": -6,
      "y": 14,
      "z": 5,
      "name": "Plant_Coral_Block_BSOD"
    },
    {
      "x": -6,
      "y": 15,
      "z": 5,
      "name": "Plant_Coral_Block_BSOD"
    },
    {
      "x": -6,
      "y": 20,
      "z": 5,
      "name": "Plant_Coral_Block_BSOD"
    },
    {
      "x": -6,
      "y": 21,
      "z": 5,
      "name": "Plant_Coral_Block_BSOD"
    },
    {
      "x": -6,
      "y": 22,
      "z": 5,
      "name": "Rock_Volcanic_Cracked_Poisoned"
    },
    {
      "x": -6,
      "y": 21,
      "z": 6,
      "name": "Plant_Coral_Block_BSOD"
    },
    {
      "x": -6,
      "y": 22,
      "z": 6,
      "name": "Rock_Volcanic_Cracked_Poisoned"
    },
    {
      "x": -6,
      "y": 22,
      "z": 7,
      "name": "Plant_Coral_Block_BSOD"
    },
    {
      "x": -6,
      "y": 23,
      "z": 7,
      "name": "Plant_Coral_Block_BSOD"
    },
    {
      "x": -5,
      "y": 22,
      "z": -7,
      "name": "Plant_Coral_Block_BSOD"
    },
    {
      "x": -5,
      "y": 23,
      "z": -7,
      "name": "Plant_Coral_Block_BSOD"
    },
    {
      "x": -5,
      "y": 21,
      "z": -6,
      "name": "Plant_Coral_Block_BSOD"
    },
    {
      "x": -5,
      "y": 22,
      "z": -6,
      "name": "Plant_Coral_Block_BSOD"
    },
    {
      "x": -5,
      "y": 23,
      "z": -6,
      "name": "Plant_Coral_Block_BSOD"
    },
    {
      "x": -5,
      "y": 24,
      "z": -6,
      "name": "Plant_Coral_Block_BSOD"
    },
    {
      "x": -5,
      "y": 25,
      "z": -6,
      "name": "Plant_Coral_Block_BSOD"
    },
    {
      "x": -5,
      "y": 20,
      "z": -5,
      "name": "Plant_Coral_Block_Blue"
    },
    {
      "x": -5,
      "y": 21,
      "z": -5,
      "name": "Plant_Coral_Block_Blue"
    },
    {
      "x": -5,
      "y": 22,
      "z": -5,
      "name": "Plant_Coral_Block_BSOD"
    },
    {
      "x": -5,
      "y": 23,
      "z": -5,
      "name": "Plant_Coral_Block_BSOD"
    },
    {
      "x": -5,
      "y": 24,
      "z": -5,
      "name": "Rock_Volcanic_Cracked_Poisoned"
    },
    {
      "x": -5,
      "y": 18,
      "z": -4,
      "name": "Plant_Coral_Block_Blue"
    },
    {
      "x": -5,
      "y": 19,
      "z": -4,
      "name": "Plant_Coral_Block_Blue"
    },
    {
      "x": -5,
      "y": 20,
      "z": -4,
      "name": "Plant_Coral_Block_Blue"
    },
    {
      "x": -5,
      "y": 21,
      "z": -4,
      "name": "Plant_Coral_Block_Blue"
    },
    {
      "x": -5,
      "y": 22,
      "z": -4,
      "name": "Plant_Coral_Block_BSOD"
    },
    {
      "x": -5,
      "y": 23,
      "z": -4,
      "name": "Plant_Coral_Block_BSOD"
    },
    {
      "x": -5,
      "y": 24,
      "z": -4,
      "name": "Rock_Volcanic_Cracked_Poisoned"
    },
    {
      "x": -5,
      "y": 16,
      "z": -3,
      "name": "Plant_Coral_Block_Blue"
    },
    {
      "x": -5,
      "y": 17,
      "z": -3,
      "name": "Plant_Coral_Block_Blue"
    },
    {
      "x": -5,
      "y": 18,
      "z": -3,
      "name": "Plant_Coral_Block_Blue"
    },
    {
      "x": -5,
      "y": 19,
      "z": -3,
      "name": "Plant_Coral_Block_BSOD"
    },
    {
      "x": -5,
      "y": 20,
      "z": -3,
      "name": "Plant_Coral_Block_BSOD"
    },
    {
      "x": -5,
      "y": 21,
      "z": -3,
      "name": "Plant_Coral_Block_Blue"
    },
    {
      "x": -5,
      "y": 22,
      "z": -3,
      "name": "Plant_Coral_Block_BSOD"
    },
    {
      "x": -5,
      "y": 23,
      "z": -3,
      "name": "Plant_Coral_Block_BSOD"
    },
    {
      "x": -5,
      "y": 24,
      "z": -3,
      "name": "Rock_Volcanic_Cracked_Poisoned"
    },
    {
      "x": -5,
      "y": 10,
      "z": -2,
      "name": "Plant_Coral_Block_Blue"
    },
    {
      "x": -5,
      "y": 11,
      "z": -2,
      "name": "Plant_Coral_Block_Blue"
    },
    {
      "x": -5,
      "y": 15,
      "z": -2,
      "name": "Plant_Coral_Block_Blue"
    },
    {
      "x": -5,
      "y": 16,
      "z": -2,
      "name": "Plant_Coral_Block_Blue"
    },
    {
      "x": -5,
      "y": 17,
      "z": -2,
      "name": "Plant_Coral_Block_Blue"
    },
    {
      "x": -5,
      "y": 18,
      "z": -2,
      "name": "Plant_Coral_Block_BSOD"
    },
    {
      "x": -5,
      "y": 19,
      "z": -2,
      "name": "Plant_Coral_Block_BSOD"
    },
    {
      "x": -5,
      "y": 20,
      "z": -2,
      "name": "Plant_Coral_Block_BSOD"
    },
    {
      "x": -5,
      "y": 21,
      "z": -2,
      "name": "Plant_Coral_Block_BSOD"
    },
    {
      "x": -5,
      "y": 22,
      "z": -2,
      "name": "Plant_Coral_Block_BSOD"
    },
    {
      "x": -5,
      "y": 23,
      "z": -2,
      "name": "Plant_Coral_Block_BSOD"
    },
    {
      "x": -5,
      "y": 24,
      "z": -2,
      "name": "Rock_Volcanic_Cracked_Poisoned"
    },
    {
      "x": -5,
      "y": 8,
      "z": -1,
      "name": "Plant_Coral_Block_Blue"
    },
    {
      "x": -5,
      "y": 9,
      "z": -1,
      "name": "Plant_Coral_Block_Blue"
    },
    {
      "x": -5,
      "y": 10,
      "z": -1,
      "name": "Plant_Coral_Block_Blue"
    },
    {
      "x": -5,
      "y": 11,
      "z": -1,
      "name": "Plant_Coral_Block_Blue"
    },
    {
      "x": -5,
      "y": 12,
      "z": -1,
      "name": "Plant_Coral_Block_Blue"
    },
    {
      "x": -5,
      "y": 13,
      "z": -1,
      "name": "Plant_Coral_Block_Blue"
    },
    {
      "x": -5,
      "y": 14,
      "z": -1,
      "name": "Plant_Coral_Block_Blue"
    },
    {
      "x": -5,
      "y": 15,
      "z": -1,
      "name": "Plant_Coral_Block_BSOD"
    },
    {
      "x": -5,
      "y": 16,
      "z": -1,
      "name": "Plant_Coral_Block_Blue"
    },
    {
      "x": -5,
      "y": 17,
      "z": -1,
      "name": "Plant_Coral_Block_BSOD"
    },
    {
      "x": -5,
      "y": 18,
      "z": -1,
      "name": "Plant_Coral_Block_BSOD"
    },
    {
      "x": -5,
      "y": 19,
      "z": -1,
      "name": "Plant_Coral_Block_BSOD"
    },
    {
      "x": -5,
      "y": 20,
      "z": -1,
      "name": "Plant_Coral_Block_BSOD"
    },
    {
      "x": -5,
      "y": 21,
      "z": -1,
      "name": "Plant_Coral_Block_BSOD"
    },
    {
      "x": -5,
      "y": 22,
      "z": -1,
      "name": "Plant_Coral_Block_BSOD"
    },
    {
      "x": -5,
      "y": 23,
      "z": -1,
      "name": "Rock_Volcanic_Cracked_Poisoned"
    },
    {
      "x": -5,
      "y": 7,
      "z": 0,
      "name": "Plant_Coral_Block_Blue"
    },
    {
      "x": -5,
      "y": 8,
      "z": 0,
      "name": "Plant_Coral_Block_Blue"
    },
    {
      "x": -5,
      "y": 9,
      "z": 0,
      "name": "Plant_Coral_Block_Blue"
    },
    {
      "x": -5,
      "y": 10,
      "z": 0,
      "name": "Plant_Coral_Block_Blue"
    },
    {
      "x": -5,
      "y": 11,
      "z": 0,
      "name": "Plant_Coral_Block_Blue"
    },
    {
      "x": -5,
      "y": 12,
      "z": 0,
      "name": "Plant_Coral_Block_Blue"
    },
    {
      "x": -5,
      "y": 13,
      "z": 0,
      "name": "Plant_Coral_Block_Blue"
    },
    {
      "x": -5,
      "y": 14,
      "z": 0,
      "name": "Plant_Coral_Block_BSOD"
    },
    {
      "x": -5,
      "y": 15,
      "z": 0,
      "name": "Plant_Coral_Block_BSOD"
    },
    {
      "x": -5,
      "y": 16,
      "z": 0,
      "name": "Plant_Coral_Block_BSOD"
    },
    {
      "x": -5,
      "y": 17,
      "z": 0,
      "name": "Plant_Coral_Block_Blue"
    },
    {
      "x": -5,
      "y": 18,
      "z": 0,
      "name": "Plant_Coral_Block_BSOD"
    },
    {
      "x": -5,
      "y": 19,
      "z": 0,
      "name": "Plant_Coral_Block_BSOD"
    },
    {
      "x": -5,
      "y": 20,
      "z": 0,
      "name": "Plant_Coral_Block_BSOD"
    },
    {
      "x": -5,
      "y": 21,
      "z": 0,
      "name": "Plant_Coral_Block_BSOD"
    },
    {
      "x": -5,
      "y": 22,
      "z": 0,
      "name": "Plant_Coral_Block_BSOD"
    },
    {
      "x": -5,
      "y": 23,
      "z": 0,
      "name": "Rock_Volcanic_Cracked_Poisoned"
    },
    {
      "x": -5,
      "y": 7,
      "z": 1,
      "name": "Plant_Coral_Block_Blue"
    },
    {
      "x": -5,
      "y": 8,
      "z": 1,
      "name": "Plant_Coral_Block_Blue"
    },
    {
      "x": -5,
      "y": 9,
      "z": 1,
      "name": "Plant_Coral_Block_Blue"
    },
    {
      "x": -5,
      "y": 10,
      "z": 1,
      "name": "Plant_Coral_Block_Blue"
    },
    {
      "x": -5,
      "y": 11,
      "z": 1,
      "name": "Plant_Coral_Block_Blue"
    },
    {
      "x": -5,
      "y": 12,
      "z": 1,
      "name": "Plant_Coral_Block_Blue"
    },
    {
      "x": -5,
      "y": 13,
      "z": 1,
      "name": "Plant_Coral_Block_BSOD"
    },
    {
      "x": -5,
      "y": 14,
      "z": 1,
      "name": "Plant_Coral_Block_BSOD"
    },
    {
      "x": -5,
      "y": 15,
      "z": 1,
      "name": "Plant_Coral_Block_BSOD"
    },
    {
      "x": -5,
      "y": 16,
      "z": 1,
      "name": "Plant_Coral_Block_BSOD"
    },
    {
      "x": -5,
      "y": 17,
      "z": 1,
      "name": "Plant_Coral_Block_BSOD"
    },
    {
      "x": -5,
      "y": 18,
      "z": 1,
      "name": "Plant_Coral_Block_Blue"
    },
    {
      "x": -5,
      "y": 19,
      "z": 1,
      "name": "Plant_Coral_Block_BSOD"
    },
    {
      "x": -5,
      "y": 20,
      "z": 1,
      "name": "Plant_Coral_Block_BSOD"
    },
    {
      "x": -5,
      "y": 21,
      "z": 1,
      "name": "Plant_Coral_Block_Blue"
    },
    {
      "x": -5,
      "y": 22,
      "z": 1,
      "name": "Plant_Coral_Block_BSOD"
    },
    {
      "x": -5,
      "y": 23,
      "z": 1,
      "name": "Plant_Coral_Block_BSOD"
    },
    {
      "x": -5,
      "y": 24,
      "z": 1,
      "name": "Rock_Volcanic_Cracked_Poisoned"
    },
    {
      "x": -5,
      "y": 7,
      "z": 2,
      "name": "Plant_Coral_Block_Blue"
    },
    {
      "x": -5,
      "y": 8,
      "z": 2,
      "name": "Plant_Coral_Block_Blue"
    },
    {
      "x": -5,
      "y": 9,
      "z": 2,
      "name": "Plant_Coral_Block_Blue"
    },
    {
      "x": -5,
      "y": 10,
      "z": 2,
      "name": "Plant_Coral_Block_Blue"
    },
    {
      "x": -5,
      "y": 11,
      "z": 2,
      "name": "Plant_Coral_Block_Blue"
    },
    {
      "x": -5,
      "y": 12,
      "z": 2,
      "name": "Plant_Coral_Block_Blue"
    },
    {
      "x": -5,
      "y": 13,
      "z": 2,
      "name": "Plant_Coral_Block_BSOD"
    },
    {
      "x": -5,
      "y": 14,
      "z": 2,
      "name": "Plant_Coral_Block_BSOD"
    },
    {
      "x": -5,
      "y": 15,
      "z": 2,
      "name": "Plant_Coral_Block_BSOD"
    },
    {
      "x": -5,
      "y": 16,
      "z": 2,
      "name": "Plant_Coral_Block_BSOD"
    },
    {
      "x": -5,
      "y": 17,
      "z": 2,
      "name": "Plant_Coral_Block_BSOD"
    },
    {
      "x": -5,
      "y": 18,
      "z": 2,
      "name": "Plant_Coral_Block_Blue"
    },
    {
      "x": -5,
      "y": 19,
      "z": 2,
      "name": "Plant_Coral_Block_Blue"
    },
    {
      "x": -5,
      "y": 20,
      "z": 2,
      "name": "Plant_Coral_Block_Blue"
    },
    {
      "x": -5,
      "y": 21,
      "z": 2,
      "name": "Plant_Coral_Block_BSOD"
    },
    {
      "x": -5,
      "y": 22,
      "z": 2,
      "name": "Plant_Coral_Block_BSOD"
    },
    {
      "x": -5,
      "y": 23,
      "z": 2,
      "name": "Plant_Coral_Block_BSOD"
    },
    {
      "x": -5,
      "y": 24,
      "z": 2,
      "name": "Plant_Coral_Block_BSOD"
    },
    {
      "x": -5,
      "y": 25,
      "z": 2,
      "name": "Plant_Coral_Block_BSOD"
    },
    {
      "x": -5,
      "y": 8,
      "z": 3,
      "name": "Plant_Coral_Block_Blue"
    },
    {
      "x": -5,
      "y": 9,
      "z": 3,
      "name": "Plant_Coral_Block_Blue"
    },
    {
      "x": -5,
      "y": 10,
      "z": 3,
      "name": "Plant_Coral_Block_Blue"
    },
    {
      "x": -5,
      "y": 11,
      "z": 3,
      "name": "Plant_Coral_Block_Blue"
    },
    {
      "x": -5,
      "y": 12,
      "z": 3,
      "name": "Plant_Coral_Block_BSOD"
    },
    {
      "x": -5,
      "y": 13,
      "z": 3,
      "name": "Plant_Coral_Block_BSOD"
    },
    {
      "x": -5,
      "y": 14,
      "z": 3,
      "name": "Rock_Volcanic_Cracked_Poisoned"
    },
    {
      "x": -5,
      "y": 16,
      "z": 3,
      "name": "Plant_Coral_Block_BSOD"
    },
    {
      "x": -5,
      "y": 17,
      "z": 3,
      "name": "Plant_Coral_Block_BSOD"
    },
    {
      "x": -5,
      "y": 18,
      "z": 3,
      "name": "Plant_Coral_Block_BSOD"
    },
    {
      "x": -5,
      "y": 19,
      "z": 3,
      "name": "Plant_Coral_Block_BSOD"
    },
    {
      "x": -5,
      "y": 20,
      "z": 3,
      "name": "Plant_Coral_Block_BSOD"
    },
    {
      "x": -5,
      "y": 21,
      "z": 3,
      "name": "Plant_Coral_Block_BSOD"
    },
    {
      "x": -5,
      "y": 22,
      "z": 3,
      "name": "Plant_Coral_Block_BSOD"
    },
    {
      "x": -5,
      "y": 23,
      "z": 3,
      "name": "Plant_Coral_Block_BSOD"
    },
    {
      "x": -5,
      "y": 24,
      "z": 3,
      "name": "Plant_Coral_Block_BSOD"
    },
    {
      "x": -5,
      "y": 25,
      "z": 3,
      "name": "Plant_Coral_Block_BSOD"
    },
    {
      "x": -5,
      "y": 9,
      "z": 4,
      "name": "Plant_Coral_Block_Blue"
    },
    {
      "x": -5,
      "y": 10,
      "z": 4,
      "name": "Plant_Coral_Block_Blue"
    },
    {
      "x": -5,
      "y": 11,
      "z": 4,
      "name": "Plant_Coral_Block_Blue"
    },
    {
      "x": -5,
      "y": 12,
      "z": 4,
      "name": "Plant_Coral_Block_BSOD"
    },
    {
      "x": -5,
      "y": 13,
      "z": 4,
      "name": "Plant_Coral_Block_BSOD"
    },
    {
      "x": -5,
      "y": 14,
      "z": 4,
      "name": "Rock_Volcanic_Cracked_Poisoned"
    },
    {
      "x": -5,
      "y": 17,
      "z": 4,
      "name": "Plant_Coral_Block_BSOD"
    },
    {
      "x": -5,
      "y": 18,
      "z": 4,
      "name": "Plant_Coral_Block_BSOD"
    },
    {
      "x": -5,
      "y": 19,
      "z": 4,
      "name": "Plant_Coral_Block_BSOD"
    },
    {
      "x": -5,
      "y": 20,
      "z": 4,
      "name": "Plant_Coral_Block_BSOD"
    },
    {
      "x": -5,
      "y": 21,
      "z": 4,
      "name": "Rock_Volcanic_Cracked_Poisoned"
    },
    {
      "x": -5,
      "y": 24,
      "z": 4,
      "name": "Plant_Coral_Block_BSOD"
    },
    {
      "x": -5,
      "y": 25,
      "z": 4,
      "name": "Plant_Coral_Block_BSOD"
    },
    {
      "x": -5,
      "y": 13,
      "z": 5,
      "name": "Plant_Coral_Block_BSOD"
    },
    {
      "x": -5,
      "y": 14,
      "z": 5,
      "name": "Plant_Coral_Block_BSOD"
    },
    {
      "x": -5,
      "y": 15,
      "z": 5,
      "name": "Plant_Coral_Block_BSOD"
    },
    {
      "x": -5,
      "y": 18,
      "z": 5,
      "name": "Plant_Coral_Block_BSOD"
    },
    {
      "x": -5,
      "y": 19,
      "z": 5,
      "name": "Plant_Coral_Block_BSOD"
    },
    {
      "x": -5,
      "y": 20,
      "z": 5,
      "name": "Plant_Coral_Block_BSOD"
    },
    {
      "x": -5,
      "y": 21,
      "z": 5,
      "name": "Rock_Volcanic_Cracked_Poisoned"
    },
    {
      "x": -5,
      "y": 25,
      "z": 5,
      "name": "Plant_Coral_Block_BSOD"
    },
    {
      "x": -5,
      "y": 19,
      "z": 6,
      "name": "Plant_Coral_Block_BSOD"
    },
    {
      "x": -5,
      "y": 20,
      "z": 6,
      "name": "Plant_Coral_Block_BSOD"
    },
    {
      "x": -5,
      "y": 21,
      "z": 6,
      "name": "Plant_Coral_Block_BSOD"
    },
    {
      "x": -5,
      "y": 22,
      "z": 6,
      "name": "Rock_Volcanic_Cracked_Poisoned"
    },
    {
      "x": -5,
      "y": 19,
      "z": 7,
      "name": "Plant_Coral_Block_BSOD"
    },
    {
      "x": -5,
      "y": 22,
      "z": 7,
      "name": "Plant_Coral_Block_BSOD"
    },
    {
      "x": -5,
      "y": 23,
      "z": 7,
      "name": "Plant_Coral_Block_BSOD"
    },
    {
      "x": -4,
      "y": 22,
      "z": -8,
      "name": "Plant_Coral_Block_BSOD"
    },
    {
      "x": -4,
      "y": 23,
      "z": -8,
      "name": "Plant_Coral_Block_BSOD"
    },
    {
      "x": -4,
      "y": 21,
      "z": -7,
      "name": "Plant_Coral_Block_BSOD"
    },
    {
      "x": -4,
      "y": 22,
      "z": -7,
      "name": "Rock_Volcanic_Cracked_Poisoned"
    },
    {
      "x": -4,
      "y": 25,
      "z": -7,
      "name": "Plant_Coral_Block_BSOD"
    },
    {
      "x": -4,
      "y": 19,
      "z": -6,
      "name": "Plant_Coral_Block_Blue"
    },
    {
      "x": -4,
      "y": 20,
      "z": -6,
      "name": "Plant_Coral_Block_Blue"
    },
    {
      "x": -4,
      "y": 21,
      "z": -6,
      "name": "Plant_Coral_Block_BSOD"
    },
    {
      "x": -4,
      "y": 22,
      "z": -6,
      "name": "Plant_Coral_Block_BSOD"
    },
    {
      "x": -4,
      "y": 23,
      "z": -6,
      "name": "Plant_Coral_Block_BSOD"
    },
    {
      "x": -4,
      "y": 24,
      "z": -6,
      "name": "Plant_Coral_Block_BSOD"
    },
    {
      "x": -4,
      "y": 0,
      "z": -5,
      "name": "Plant_Coral_Block_Blue"
    },
    {
      "x": -4,
      "y": 1,
      "z": -5,
      "name": "Plant_Coral_Block_Blue"
    },
    {
      "x": -4,
      "y": 2,
      "z": -5,
      "name": "Plant_Coral_Block_Blue"
    },
    {
      "x": -4,
      "y": 3,
      "z": -5,
      "name": "Plant_Coral_Block_Blue"
    },
    {
      "x": -4,
      "y": 4,
      "z": -5,
      "name": "Plant_Coral_Block_Blue"
    },
    {
      "x": -4,
      "y": 5,
      "z": -5,
      "name": "Plant_Coral_Block_Blue"
    },
    {
      "x": -4,
      "y": 6,
      "z": -5,
      "name": "Plant_Coral_Block_Blue"
    },
    {
      "x": -4,
      "y": 7,
      "z": -5,
      "name": "Plant_Coral_Block_Blue"
    },
    {
      "x": -4,
      "y": 8,
      "z": -5,
      "name": "Plant_Coral_Block_Blue"
    },
    {
      "x": -4,
      "y": 9,
      "z": -5,
      "name": "Plant_Coral_Block_Blue"
    },
    {
      "x": -4,
      "y": 10,
      "z": -5,
      "name": "Plant_Coral_Block_Blue"
    },
    {
      "x": -4,
      "y": 15,
      "z": -5,
      "name": "Plant_Coral_Block_BSOD"
    },
    {
      "x": -4,
      "y": 17,
      "z": -5,
      "name": "Plant_Coral_Block_Blue"
    },
    {
      "x": -4,
      "y": 18,
      "z": -5,
      "name": "Plant_Coral_Block_Blue"
    },
    {
      "x": -4,
      "y": 19,
      "z": -5,
      "name": "Plant_Coral_Block_Blue"
    },
    {
      "x": -4,
      "y": 20,
      "z": -5,
      "name": "Plant_Coral_Block_Blue"
    },
    {
      "x": -4,
      "y": 21,
      "z": -5,
      "name": "Plant_Coral_Block_Blue"
    },
    {
      "x": -4,
      "y": 22,
      "z": -5,
      "name": "Plant_Coral_Block_BSOD"
    },
    {
      "x": -4,
      "y": 23,
      "z": -5,
      "name": "Plant_Coral_Block_BSOD"
    },
    {
      "x": -4,
      "y": 24,
      "z": -5,
      "name": "Rock_Volcanic_Cracked_Poisoned"
    },
    {
      "x": -4,
      "y": 8,
      "z": -4,
      "name": "Plant_Coral_Block_Blue"
    },
    {
      "x": -4,
      "y": 9,
      "z": -4,
      "name": "Plant_Coral_Block_Blue"
    },
    {
      "x": -4,
      "y": 10,
      "z": -4,
      "name": "Plant_Coral_Block_Blue"
    },
    {
      "x": -4,
      "y": 11,
      "z": -4,
      "name": "Plant_Coral_Block_Blue"
    },
    {
      "x": -4,
      "y": 13,
      "z": -4,
      "name": "Plant_Coral_Block_BSOD"
    },
    {
      "x": -4,
      "y": 14,
      "z": -4,
      "name": "Plant_Coral_Block_BSOD"
    },
    {
      "x": -4,
      "y": 15,
      "z": -4,
      "name": "Plant_Coral_Block_BSOD"
    },
    {
      "x": -4,
      "y": 16,
      "z": -4,
      "name": "Plant_Coral_Block_Blue"
    },
    {
      "x": -4,
      "y": 17,
      "z": -4,
      "name": "Plant_Coral_Block_Blue"
    },
    {
      "x": -4,
      "y": 18,
      "z": -4,
      "name": "Plant_Coral_Block_Blue"
    },
    {
      "x": -4,
      "y": 19,
      "z": -4,
      "name": "Plant_Coral_Block_Blue"
    },
    {
      "x": -4,
      "y": 20,
      "z": -4,
      "name": "Plant_Coral_Block_Blue"
    },
    {
      "x": -4,
      "y": 21,
      "z": -4,
      "name": "Plant_Coral_Block_Blue"
    },
    {
      "x": -4,
      "y": 22,
      "z": -4,
      "name": "Plant_Coral_Block_BSOD"
    },
    {
      "x": -4,
      "y": 23,
      "z": -4,
      "name": "Plant_Coral_Block_BSOD"
    },
    {
      "x": -4,
      "y": 24,
      "z": -4,
      "name": "Rock_Volcanic_Cracked_Poisoned"
    },
    {
      "x": -4,
      "y": 27,
      "z": -4,
      "name": "Plant_Coral_Block_BSOD"
    },
    {
      "x": -4,
      "y": 28,
      "z": -4,
      "name": "Plant_Coral_Block_BSOD"
    },
    {
      "x": -4,
      "y": 10,
      "z": -3,
      "name": "Plant_Coral_Block_Blue"
    },
    {
      "x": -4,
      "y": 11,
      "z": -3,
      "name": "Plant_Coral_Block_Blue"
    },
    {
      "x": -4,
      "y": 12,
      "z": -3,
      "name": "Plant_Coral_Block_Blue"
    },
    {
      "x": -4,
      "y": 13,
      "z": -3,
      "name": "Plant_Coral_Block_Blue"
    },
    {
      "x": -4,
      "y": 14,
      "z": -3,
      "name": "Plant_Coral_Block_BSOD"
    },
    {
      "x": -4,
      "y": 15,
      "z": -3,
      "name": "Plant_Coral_Block_Blue"
    },
    {
      "x": -4,
      "y": 16,
      "z": -3,
      "name": "Plant_Coral_Block_Blue"
    },
    {
      "x": -4,
      "y": 17,
      "z": -3,
      "name": "Plant_Coral_Block_Blue"
    },
    {
      "x": -4,
      "y": 18,
      "z": -3,
      "name": "Plant_Coral_Block_Blue"
    },
    {
      "x": -4,
      "y": 19,
      "z": -3,
      "name": "Plant_Coral_Block_Blue"
    },
    {
      "x": -4,
      "y": 20,
      "z": -3,
      "name": "Plant_Coral_Block_Blue"
    },
    {
      "x": -4,
      "y": 21,
      "z": -3,
      "name": "Plant_Coral_Block_Blue"
    },
    {
      "x": -4,
      "y": 22,
      "z": -3,
      "name": "Plant_Coral_Block_BSOD"
    },
    {
      "x": -4,
      "y": 23,
      "z": -3,
      "name": "Plant_Coral_Block_BSOD"
    },
    {
      "x": -4,
      "y": 24,
      "z": -3,
      "name": "Rock_Volcanic_Cracked_Poisoned"
    },
    {
      "x": -4,
      "y": 27,
      "z": -3,
      "name": "Plant_Coral_Block_BSOD"
    },
    {
      "x": -4,
      "y": 28,
      "z": -3,
      "name": "Plant_Coral_Block_BSOD"
    },
    {
      "x": -4,
      "y": 9,
      "z": -2,
      "name": "Plant_Coral_Block_Blue"
    },
    {
      "x": -4,
      "y": 10,
      "z": -2,
      "name": "Plant_Coral_Block_Blue"
    },
    {
      "x": -4,
      "y": 11,
      "z": -2,
      "name": "Plant_Coral_Block_Blue"
    },
    {
      "x": -4,
      "y": 12,
      "z": -2,
      "name": "Plant_Coral_Block_Blue"
    },
    {
      "x": -4,
      "y": 13,
      "z": -2,
      "name": "Plant_Coral_Block_Blue"
    },
    {
      "x": -4,
      "y": 14,
      "z": -2,
      "name": "Plant_Coral_Block_Blue"
    },
    {
      "x": -4,
      "y": 15,
      "z": -2,
      "name": "Plant_Coral_Block_Blue"
    },
    {
      "x": -4,
      "y": 16,
      "z": -2,
      "name": "Plant_Coral_Block_Blue"
    },
    {
      "x": -4,
      "y": 17,
      "z": -2,
      "name": "Plant_Coral_Block_Blue"
    },
    {
      "x": -4,
      "y": 18,
      "z": -2,
      "name": "Plant_Coral_Block_Blue"
    },
    {
      "x": -4,
      "y": 19,
      "z": -2,
      "name": "Plant_Coral_Block_BSOD"
    },
    {
      "x": -4,
      "y": 20,
      "z": -2,
      "name": "Plant_Coral_Block_BSOD"
    },
    {
      "x": -4,
      "y": 21,
      "z": -2,
      "name": "Plant_Coral_Block_Blue"
    },
    {
      "x": -4,
      "y": 22,
      "z": -2,
      "name": "Plant_Coral_Block_BSOD"
    },
    {
      "x": -4,
      "y": 23,
      "z": -2,
      "name": "Plant_Coral_Block_BSOD"
    },
    {
      "x": -4,
      "y": 24,
      "z": -2,
      "name": "Rock_Volcanic_Cracked_Poisoned"
    },
    {
      "x": -4,
      "y": 7,
      "z": -1,
      "name": "Plant_Coral_Block_Blue"
    },
    {
      "x": -4,
      "y": 8,
      "z": -1,
      "name": "Plant_Coral_Block_Blue"
    },
    {
      "x": -4,
      "y": 9,
      "z": -1,
      "name": "Plant_Coral_Block_Blue"
    },
    {
      "x": -4,
      "y": 10,
      "z": -1,
      "name": "Plant_Coral_Block_Blue"
    },
    {
      "x": -4,
      "y": 11,
      "z": -1,
      "name": "Plant_Coral_Block_Blue"
    },
    {
      "x": -4,
      "y": 12,
      "z": -1,
      "name": "Plant_Coral_Block_Blue"
    },
    {
      "x": -4,
      "y": 13,
      "z": -1,
      "name": "Plant_Coral_Block_Blue"
    },
    {
      "x": -4,
      "y": 14,
      "z": -1,
      "name": "Plant_Coral_Block_Blue"
    },
    {
      "x": -4,
      "y": 15,
      "z": -1,
      "name": "Plant_Coral_Block_Blue"
    },
    {
      "x": -4,
      "y": 16,
      "z": -1,
      "name": "Plant_Coral_Block_Blue"
    },
    {
      "x": -4,
      "y": 17,
      "z": -1,
      "name": "Plant_Coral_Block_Blue"
    },
    {
      "x": -4,
      "y": 18,
      "z": -1,
      "name": "Plant_Coral_Block_BSOD"
    },
    {
      "x": -4,
      "y": 19,
      "z": -1,
      "name": "Plant_Coral_Block_BSOD"
    },
    {
      "x": -4,
      "y": 20,
      "z": -1,
      "name": "Plant_Coral_Block_BSOD"
    },
    {
      "x": -4,
      "y": 21,
      "z": -1,
      "name": "Plant_Coral_Block_BSOD"
    },
    {
      "x": -4,
      "y": 22,
      "z": -1,
      "name": "Plant_Coral_Block_BSOD"
    },
    {
      "x": -4,
      "y": 23,
      "z": -1,
      "name": "Plant_Coral_Block_BSOD"
    },
    {
      "x": -4,
      "y": 24,
      "z": -1,
      "name": "Rock_Volcanic_Cracked_Poisoned"
    },
    {
      "x": -4,
      "y": 6,
      "z": 0,
      "name": "Plant_Coral_Block_Blue"
    },
    {
      "x": -4,
      "y": 7,
      "z": 0,
      "name": "Plant_Coral_Block_Blue"
    },
    {
      "x": -4,
      "y": 8,
      "z": 0,
      "name": "Plant_Coral_Block_Blue"
    },
    {
      "x": -4,
      "y": 9,
      "z": 0,
      "name": "Plant_Coral_Block_Blue"
    },
    {
      "x": -4,
      "y": 10,
      "z": 0,
      "name": "Plant_Coral_Block_Blue"
    },
    {
      "x": -4,
      "y": 11,
      "z": 0,
      "name": "Plant_Coral_Block_Blue"
    },
    {
      "x": -4,
      "y": 12,
      "z": 0,
      "name": "Plant_Coral_Block_Blue"
    },
    {
      "x": -4,
      "y": 13,
      "z": 0,
      "name": "Plant_Coral_Block_Blue"
    },
    {
      "x": -4,
      "y": 14,
      "z": 0,
      "name": "Plant_Coral_Block_Blue"
    },
    {
      "x": -4,
      "y": 15,
      "z": 0,
      "name": "Plant_Coral_Block_BSOD"
    },
    {
      "x": -4,
      "y": 16,
      "z": 0,
      "name": "Plant_Coral_Block_Blue"
    },
    {
      "x": -4,
      "y": 17,
      "z": 0,
      "name": "Plant_Coral_Block_Blue"
    },
    {
      "x": -4,
      "y": 18,
      "z": 0,
      "name": "Plant_Coral_Block_Blue"
    },
    {
      "x": -4,
      "y": 19,
      "z": 0,
      "name": "Plant_Coral_Block_BSOD"
    },
    {
      "x": -4,
      "y": 20,
      "z": 0,
      "name": "Plant_Coral_Block_BSOD"
    },
    {
      "x": -4,
      "y": 21,
      "z": 0,
      "name": "Plant_Coral_Block_Blue"
    },
    {
      "x": -4,
      "y": 22,
      "z": 0,
      "name": "Plant_Coral_Block_BSOD"
    },
    {
      "x": -4,
      "y": 23,
      "z": 0,
      "name": "Plant_Coral_Block_BSOD"
    },
    {
      "x": -4,
      "y": 24,
      "z": 0,
      "name": "Rock_Volcanic_Cracked_Poisoned"
    },
    {
      "x": -4,
      "y": 6,
      "z": 1,
      "name": "Plant_Coral_Block_Blue"
    },
    {
      "x": -4,
      "y": 7,
      "z": 1,
      "name": "Plant_Coral_Block_Blue"
    },
    {
      "x": -4,
      "y": 8,
      "z": 1,
      "name": "Plant_Coral_Block_Blue"
    },
    {
      "x": -4,
      "y": 9,
      "z": 1,
      "name": "Plant_Coral_Block_Blue"
    },
    {
      "x": -4,
      "y": 10,
      "z": 1,
      "name": "Plant_Coral_Block_Blue"
    },
    {
      "x": -4,
      "y": 11,
      "z": 1,
      "name": "Plant_Coral_Block_Blue"
    },
    {
      "x": -4,
      "y": 12,
      "z": 1,
      "name": "Plant_Coral_Block_Blue"
    },
    {
      "x": -4,
      "y": 13,
      "z": 1,
      "name": "Plant_Coral_Block_Blue"
    },
    {
      "x": -4,
      "y": 14,
      "z": 1,
      "name": "Plant_Coral_Block_BSOD"
    },
    {
      "x": -4,
      "y": 15,
      "z": 1,
      "name": "Plant_Coral_Block_BSOD"
    },
    {
      "x": -4,
      "y": 16,
      "z": 1,
      "name": "Plant_Coral_Block_BSOD"
    },
    {
      "x": -4,
      "y": 17,
      "z": 1,
      "name": "Plant_Coral_Block_Blue"
    },
    {
      "x": -4,
      "y": 18,
      "z": 1,
      "name": "Plant_Coral_Block_Blue"
    },
    {
      "x": -4,
      "y": 19,
      "z": 1,
      "name": "Plant_Coral_Block_Blue"
    },
    {
      "x": -4,
      "y": 20,
      "z": 1,
      "name": "Plant_Coral_Block_Blue"
    },
    {
      "x": -4,
      "y": 21,
      "z": 1,
      "name": "Plant_Coral_Block_Blue"
    },
    {
      "x": -4,
      "y": 22,
      "z": 1,
      "name": "Plant_Coral_Block_BSOD"
    },
    {
      "x": -4,
      "y": 23,
      "z": 1,
      "name": "Plant_Coral_Block_BSOD"
    },
    {
      "x": -4,
      "y": 24,
      "z": 1,
      "name": "Plant_Coral_Block_BSOD"
    },
    {
      "x": -4,
      "y": 25,
      "z": 1,
      "name": "Plant_Coral_Block_BSOD"
    },
    {
      "x": -4,
      "y": 7,
      "z": 2,
      "name": "Plant_Coral_Block_Blue"
    },
    {
      "x": -4,
      "y": 8,
      "z": 2,
      "name": "Plant_Coral_Block_Blue"
    },
    {
      "x": -4,
      "y": 9,
      "z": 2,
      "name": "Plant_Coral_Block_Blue"
    },
    {
      "x": -4,
      "y": 10,
      "z": 2,
      "name": "Plant_Coral_Block_Blue"
    },
    {
      "x": -4,
      "y": 11,
      "z": 2,
      "name": "Plant_Coral_Block_Blue"
    },
    {
      "x": -4,
      "y": 12,
      "z": 2,
      "name": "Plant_Coral_Block_Blue"
    },
    {
      "x": -4,
      "y": 13,
      "z": 2,
      "name": "Plant_Coral_Block_Blue"
    },
    {
      "x": -4,
      "y": 14,
      "z": 2,
      "name": "Plant_Coral_Block_BSOD"
    },
    {
      "x": -4,
      "y": 15,
      "z": 2,
      "name": "Plant_Coral_Block_BSOD"
    },
    {
      "x": -4,
      "y": 16,
      "z": 2,
      "name": "Plant_Coral_Block_BSOD"
    },
    {
      "x": -4,
      "y": 17,
      "z": 2,
      "name": "Plant_Coral_Block_Blue"
    },
    {
      "x": -4,
      "y": 18,
      "z": 2,
      "name": "Plant_Coral_Block_Blue"
    },
    {
      "x": -4,
      "y": 19,
      "z": 2,
      "name": "Plant_Coral_Block_Blue"
    },
    {
      "x": -4,
      "y": 20,
      "z": 2,
      "name": "Plant_Coral_Block_Blue"
    },
    {
      "x": -4,
      "y": 21,
      "z": 2,
      "name": "Plant_Coral_Block_BSOD"
    },
    {
      "x": -4,
      "y": 22,
      "z": 2,
      "name": "Plant_Coral_Block_BSOD"
    },
    {
      "x": -4,
      "y": 23,
      "z": 2,
      "name": "Plant_Coral_Block_BSOD"
    },
    {
      "x": -4,
      "y": 24,
      "z": 2,
      "name": "Plant_Coral_Block_BSOD"
    },
    {
      "x": -4,
      "y": 25,
      "z": 2,
      "name": "Plant_Coral_Block_BSOD"
    },
    {
      "x": -4,
      "y": 7,
      "z": 3,
      "name": "Plant_Coral_Block_Blue"
    },
    {
      "x": -4,
      "y": 8,
      "z": 3,
      "name": "Plant_Coral_Block_Blue"
    },
    {
      "x": -4,
      "y": 9,
      "z": 3,
      "name": "Plant_Coral_Block_Blue"
    },
    {
      "x": -4,
      "y": 10,
      "z": 3,
      "name": "Plant_Coral_Block_Blue"
    },
    {
      "x": -4,
      "y": 11,
      "z": 3,
      "name": "Plant_Coral_Block_Blue"
    },
    {
      "x": -4,
      "y": 12,
      "z": 3,
      "name": "Plant_Coral_Block_Blue"
    },
    {
      "x": -4,
      "y": 13,
      "z": 3,
      "name": "Plant_Coral_Block_BSOD"
    },
    {
      "x": -4,
      "y": 14,
      "z": 3,
      "name": "Plant_Coral_Block_BSOD"
    },
    {
      "x": -4,
      "y": 15,
      "z": 3,
      "name": "Plant_Coral_Block_BSOD"
    },
    {
      "x": -4,
      "y": 16,
      "z": 3,
      "name": "Plant_Coral_Block_BSOD"
    },
    {
      "x": -4,
      "y": 17,
      "z": 3,
      "name": "Plant_Coral_Block_BSOD"
    },
    {
      "x": -4,
      "y": 18,
      "z": 3,
      "name": "Plant_Coral_Block_Blue"
    },
    {
      "x": -4,
      "y": 19,
      "z": 3,
      "name": "Plant_Coral_Block_BSOD"
    },
    {
      "x": -4,
      "y": 20,
      "z": 3,
      "name": "Plant_Coral_Block_BSOD"
    },
    {
      "x": -4,
      "y": 21,
      "z": 3,
      "name": "Plant_Coral_Block_BSOD"
    },
    {
      "x": -4,
      "y": 22,
      "z": 3,
      "name": "Plant_Coral_Block_BSOD"
    },
    {
      "x": -4,
      "y": 23,
      "z": 3,
      "name": "Plant_Coral_Block_BSOD"
    },
    {
      "x": -4,
      "y": 24,
      "z": 3,
      "name": "Rock_Volcanic_Cracked_Poisoned"
    },
    {
      "x": -4,
      "y": 8,
      "z": 4,
      "name": "Plant_Coral_Block_Blue"
    },
    {
      "x": -4,
      "y": 9,
      "z": 4,
      "name": "Plant_Coral_Block_Blue"
    },
    {
      "x": -4,
      "y": 10,
      "z": 4,
      "name": "Plant_Coral_Block_Blue"
    },
    {
      "x": -4,
      "y": 11,
      "z": 4,
      "name": "Plant_Coral_Block_Blue"
    },
    {
      "x": -4,
      "y": 12,
      "z": 4,
      "name": "Plant_Coral_Block_Blue"
    },
    {
      "x": -4,
      "y": 13,
      "z": 4,
      "name": "Plant_Coral_Block_BSOD"
    },
    {
      "x": -4,
      "y": 14,
      "z": 4,
      "name": "Plant_Coral_Block_BSOD"
    },
    {
      "x": -4,
      "y": 15,
      "z": 4,
      "name": "Plant_Coral_Block_BSOD"
    },
    {
      "x": -4,
      "y": 16,
      "z": 4,
      "name": "Plant_Coral_Block_BSOD"
    },
    {
      "x": -4,
      "y": 17,
      "z": 4,
      "name": "Plant_Coral_Block_BSOD"
    },
    {
      "x": -4,
      "y": 18,
      "z": 4,
      "name": "Plant_Coral_Block_BSOD"
    },
    {
      "x": -4,
      "y": 19,
      "z": 4,
      "name": "Plant_Coral_Block_BSOD"
    },
    {
      "x": -4,
      "y": 20,
      "z": 4,
      "name": "Plant_Coral_Block_BSOD"
    },
    {
      "x": -4,
      "y": 21,
      "z": 4,
      "name": "Rock_Volcanic_Cracked_Poisoned"
    },
    {
      "x": -4,
      "y": 23,
      "z": 4,
      "name": "Plant_Coral_Block_BSOD"
    },
    {
      "x": -4,
      "y": 24,
      "z": 4,
      "name": "Plant_Coral_Block_BSOD"
    },
    {
      "x": -4,
      "y": 25,
      "z": 4,
      "name": "Plant_Coral_Block_BSOD"
    },
    {
      "x": -4,
      "y": 11,
      "z": 5,
      "name": "Plant_Coral_Block_Blue"
    },
    {
      "x": -4,
      "y": 12,
      "z": 5,
      "name": "Plant_Coral_Block_Blue"
    },
    {
      "x": -4,
      "y": 13,
      "z": 5,
      "name": "Plant_Coral_Block_Blue"
    },
    {
      "x": -4,
      "y": 14,
      "z": 5,
      "name": "Plant_Coral_Block_BSOD"
    },
    {
      "x": -4,
      "y": 17,
      "z": 5,
      "name": "Plant_Coral_Block_BSOD"
    },
    {
      "x": -4,
      "y": 18,
      "z": 5,
      "name": "Plant_Coral_Block_BSOD"
    },
    {
      "x": -4,
      "y": 19,
      "z": 5,
      "name": "Plant_Coral_Block_BSOD"
    },
    {
      "x": -4,
      "y": 20,
      "z": 5,
      "name": "Plant_Coral_Block_BSOD"
    },
    {
      "x": -4,
      "y": 21,
      "z": 5,
      "name": "Rock_Volcanic_Cracked_Poisoned"
    },
    {
      "x": -4,
      "y": 24,
      "z": 5,
      "name": "Plant_Coral_Block_BSOD"
    },
    {
      "x": -4,
      "y": 25,
      "z": 5,
      "name": "Plant_Coral_Block_BSOD"
    },
    {
      "x": -4,
      "y": 13,
      "z": 6,
      "name": "Plant_Coral_Block_Blue"
    },
    {
      "x": -4,
      "y": 14,
      "z": 6,
      "name": "Plant_Coral_Block_Blue"
    },
    {
      "x": -4,
      "y": 17,
      "z": 6,
      "name": "Plant_Coral_Block_BSOD"
    },
    {
      "x": -4,
      "y": 18,
      "z": 6,
      "name": "Plant_Coral_Block_BSOD"
    },
    {
      "x": -4,
      "y": 21,
      "z": 6,
      "name": "Plant_Coral_Block_BSOD"
    },
    {
      "x": -4,
      "y": 22,
      "z": 6,
      "name": "Plant_Coral_Block_BSOD"
    },
    {
      "x": -4,
      "y": 18,
      "z": 7,
      "name": "Plant_Coral_Block_BSOD"
    },
    {
      "x": -4,
      "y": 23,
      "z": 7,
      "name": "Plant_Coral_Block_BSOD"
    },
    {
      "x": -4,
      "y": 19,
      "z": 8,
      "name": "Plant_Coral_Block_BSOD"
    },
    {
      "x": -3,
      "y": 25,
      "z": -8,
      "name": "Plant_Coral_Block_BSOD"
    },
    {
      "x": -3,
      "y": 21,
      "z": -7,
      "name": "Plant_Coral_Block_BSOD"
    },
    {
      "x": -3,
      "y": 22,
      "z": -7,
      "name": "Plant_Coral_Block_BSOD"
    },
    {
      "x": -3,
      "y": 23,
      "z": -7,
      "name": "Plant_Coral_Block_BSOD"
    },
    {
      "x": -3,
      "y": 24,
      "z": -7,
      "name": "Plant_Coral_Block_BSOD"
    },
    {
      "x": -3,
      "y": 14,
      "z": -6,
      "name": "Plant_Coral_Block_BSOD"
    },
    {
      "x": -3,
      "y": 15,
      "z": -6,
      "name": "Plant_Coral_Block_BSOD"
    },
    {
      "x": -3,
      "y": 18,
      "z": -6,
      "name": "Plant_Coral_Block_Blue"
    },
    {
      "x": -3,
      "y": 19,
      "z": -6,
      "name": "Plant_Coral_Block_Blue"
    },
    {
      "x": -3,
      "y": 20,
      "z": -6,
      "name": "Plant_Coral_Block_Blue"
    },
    {
      "x": -3,
      "y": 21,
      "z": -6,
      "name": "Plant_Coral_Block_Blue"
    },
    {
      "x": -3,
      "y": 22,
      "z": -6,
      "name": "Plant_Coral_Block_BSOD"
    },
    {
      "x": -3,
      "y": 23,
      "z": -6,
      "name": "Plant_Coral_Block_BSOD"
    },
    {
      "x": -3,
      "y": 24,
      "z": -6,
      "name": "Rock_Volcanic_Cracked_Poisoned"
    },
    {
      "x": -3,
      "y": 0,
      "z": -5,
      "name": "Plant_Coral_Block_Blue"
    },
    {
      "x": -3,
      "y": 1,
      "z": -5,
      "name": "Plant_Coral_Block_Blue"
    },
    {
      "x": -3,
      "y": 2,
      "z": -5,
      "name": "Plant_Coral_Block_Blue"
    },
    {
      "x": -3,
      "y": 3,
      "z": -5,
      "name": "Plant_Coral_Block_Blue"
    },
    {
      "x": -3,
      "y": 4,
      "z": -5,
      "name": "Plant_Coral_Block_Blue"
    },
    {
      "x": -3,
      "y": 5,
      "z": -5,
      "name": "Plant_Coral_Block_Blue"
    },
    {
      "x": -3,
      "y": 6,
      "z": -5,
      "name": "Plant_Coral_Block_Blue"
    },
    {
      "x": -3,
      "y": 7,
      "z": -5,
      "name": "Plant_Coral_Block_Blue"
    },
    {
      "x": -3,
      "y": 8,
      "z": -5,
      "name": "Plant_Coral_Block_Blue"
    },
    {
      "x": -3,
      "y": 9,
      "z": -5,
      "name": "Plant_Coral_Block_Blue"
    },
    {
      "x": -3,
      "y": 10,
      "z": -5,
      "name": "Plant_Coral_Block_Blue"
    },
    {
      "x": -3,
      "y": 13,
      "z": -5,
      "name": "Plant_Coral_Block_BSOD"
    },
    {
      "x": -3,
      "y": 14,
      "z": -5,
      "name": "Plant_Coral_Block_BSOD"
    },
    {
      "x": -3,
      "y": 16,
      "z": -5,
      "name": "Plant_Coral_Block_Blue"
    },
    {
      "x": -3,
      "y": 17,
      "z": -5,
      "name": "Plant_Coral_Block_Blue"
    },
    {
      "x": -3,
      "y": 18,
      "z": -5,
      "name": "Plant_Coral_Block_Blue"
    },
    {
      "x": -3,
      "y": 19,
      "z": -5,
      "name": "Plant_Coral_Block_Blue"
    },
    {
      "x": -3,
      "y": 20,
      "z": -5,
      "name": "Plant_Coral_Block_Blue"
    },
    {
      "x": -3,
      "y": 21,
      "z": -5,
      "name": "Plant_Coral_Block_Blue"
    },
    {
      "x": -3,
      "y": 22,
      "z": -5,
      "name": "Plant_Coral_Block_BSOD"
    },
    {
      "x": -3,
      "y": 23,
      "z": -5,
      "name": "Plant_Coral_Block_BSOD"
    },
    {
      "x": -3,
      "y": 24,
      "z": -5,
      "name": "Rock_Volcanic_Cracked_Poisoned"
    },
    {
      "x": -3,
      "y": 27,
      "z": -5,
      "name": "Plant_Coral_Block_BSOD"
    },
    {
      "x": -3,
      "y": 28,
      "z": -5,
      "name": "Plant_Coral_Block_BSOD"
    },
    {
      "x": -3,
      "y": 0,
      "z": -4,
      "name": "Plant_Coral_Block_Blue"
    },
    {
      "x": -3,
      "y": 1,
      "z": -4,
      "name": "Plant_Coral_Block_Blue"
    },
    {
      "x": -3,
      "y": 2,
      "z": -4,
      "name": "Plant_Coral_Block_Blue"
    },
    {
      "x": -3,
      "y": 3,
      "z": -4,
      "name": "Plant_Coral_Block_Blue"
    },
    {
      "x": -3,
      "y": 4,
      "z": -4,
      "name": "Plant_Coral_Block_Blue"
    },
    {
      "x": -3,
      "y": 5,
      "z": -4,
      "name": "Plant_Coral_Block_Blue"
    },
    {
      "x": -3,
      "y": 6,
      "z": -4,
      "name": "Plant_Coral_Block_Blue"
    },
    {
      "x": -3,
      "y": 7,
      "z": -4,
      "name": "Plant_Coral_Block_Blue"
    },
    {
      "x": -3,
      "y": 8,
      "z": -4,
      "name": "Plant_Coral_Block_Blue"
    },
    {
      "x": -3,
      "y": 9,
      "z": -4,
      "name": "Plant_Coral_Block_Blue"
    },
    {
      "x": -3,
      "y": 10,
      "z": -4,
      "name": "Plant_Coral_Block_Blue"
    },
    {
      "x": -3,
      "y": 11,
      "z": -4,
      "name": "Plant_Coral_Block_Blue"
    },
    {
      "x": -3,
      "y": 12,
      "z": -4,
      "name": "Plant_Coral_Block_BSOD"
    },
    {
      "x": -3,
      "y": 13,
      "z": -4,
      "name": "Plant_Coral_Block_BSOD"
    },
    {
      "x": -3,
      "y": 14,
      "z": -4,
      "name": "Plant_Coral_Block_BSOD"
    },
    {
      "x": -3,
      "y": 15,
      "z": -4,
      "name": "Plant_Coral_Block_BSOD"
    },
    {
      "x": -3,
      "y": 16,
      "z": -4,
      "name": "Plant_Coral_Block_BSOD"
    },
    {
      "x": -3,
      "y": 17,
      "z": -4,
      "name": "Plant_Coral_Block_Blue"
    },
    {
      "x": -3,
      "y": 18,
      "z": -4,
      "name": "Plant_Coral_Block_Blue"
    },
    {
      "x": -3,
      "y": 19,
      "z": -4,
      "name": "Plant_Coral_Block_Blue"
    },
    {
      "x": -3,
      "y": 20,
      "z": -4,
      "name": "Plant_Coral_Block_Blue"
    },
    {
      "x": -3,
      "y": 21,
      "z": -4,
      "name": "Plant_Coral_Block_Blue"
    },
    {
      "x": -3,
      "y": 22,
      "z": -4,
      "name": "Plant_Coral_Block_BSOD"
    },
    {
      "x": -3,
      "y": 23,
      "z": -4,
      "name": "Plant_Coral_Block_BSOD"
    },
    {
      "x": -3,
      "y": 24,
      "z": -4,
      "name": "Rock_Volcanic_Cracked_Poisoned"
    },
    {
      "x": -3,
      "y": 26,
      "z": -4,
      "name": "Plant_Coral_Block_BSOD"
    },
    {
      "x": -3,
      "y": 27,
      "z": -4,
      "name": "Rock_Volcanic_Cracked_Poisoned"
    },
    {
      "x": -3,
      "y": 9,
      "z": -3,
      "name": "Plant_Coral_Block_Blue"
    },
    {
      "x": -3,
      "y": 10,
      "z": -3,
      "name": "Plant_Coral_Block_Blue"
    },
    {
      "x": -3,
      "y": 11,
      "z": -3,
      "name": "Plant_Coral_Block_Blue"
    },
    {
      "x": -3,
      "y": 12,
      "z": -3,
      "name": "Plant_Coral_Block_Blue"
    },
    {
      "x": -3,
      "y": 13,
      "z": -3,
      "name": "Plant_Coral_Block_BSOD"
    },
    {
      "x": -3,
      "y": 14,
      "z": -3,
      "name": "Plant_Coral_Block_BSOD"
    },
    {
      "x": -3,
      "y": 15,
      "z": -3,
      "name": "Plant_Coral_Block_BSOD"
    },
    {
      "x": -3,
      "y": 16,
      "z": -3,
      "name": "Plant_Coral_Block_Blue"
    },
    {
      "x": -3,
      "y": 17,
      "z": -3,
      "name": "Plant_Coral_Block_Blue"
    },
    {
      "x": -3,
      "y": 18,
      "z": -3,
      "name": "Plant_Coral_Block_Blue"
    },
    {
      "x": -3,
      "y": 19,
      "z": -3,
      "name": "Plant_Coral_Block_Blue"
    },
    {
      "x": -3,
      "y": 20,
      "z": -3,
      "name": "Plant_Coral_Block_Blue"
    },
    {
      "x": -3,
      "y": 21,
      "z": -3,
      "name": "Plant_Coral_Block_Blue"
    },
    {
      "x": -3,
      "y": 22,
      "z": -3,
      "name": "Plant_Coral_Block_Blue"
    },
    {
      "x": -3,
      "y": 23,
      "z": -3,
      "name": "Plant_Coral_Block_BSOD"
    },
    {
      "x": -3,
      "y": 24,
      "z": -3,
      "name": "Plant_Coral_Block_BSOD"
    },
    {
      "x": -3,
      "y": 25,
      "z": -3,
      "name": "Plant_Coral_Block_BSOD"
    },
    {
      "x": -3,
      "y": 26,
      "z": -3,
      "name": "Plant_Coral_Block_BSOD"
    },
    {
      "x": -3,
      "y": 27,
      "z": -3,
      "name": "Rock_Volcanic_Cracked_Poisoned"
    },
    {
      "x": -3,
      "y": 8,
      "z": -2,
      "name": "Plant_Coral_Block_Blue"
    },
    {
      "x": -3,
      "y": 9,
      "z": -2,
      "name": "Plant_Coral_Block_Blue"
    },
    {
      "x": -3,
      "y": 10,
      "z": -2,
      "name": "Plant_Coral_Block_Blue"
    },
    {
      "x": -3,
      "y": 11,
      "z": -2,
      "name": "Plant_Coral_Block_Blue"
    },
    {
      "x": -3,
      "y": 12,
      "z": -2,
      "name": "Plant_Coral_Block_Blue"
    },
    {
      "x": -3,
      "y": 13,
      "z": -2,
      "name": "Plant_Coral_Block_Blue"
    },
    {
      "x": -3,
      "y": 14,
      "z": -2,
      "name": "Plant_Coral_Block_BSOD"
    },
    {
      "x": -3,
      "y": 15,
      "z": -2,
      "name": "Plant_Coral_Block_Blue"
    },
    {
      "x": -3,
      "y": 16,
      "z": -2,
      "name": "Plant_Coral_Block_Blue"
    },
    {
      "x": -3,
      "y": 17,
      "z": -2,
      "name": "Plant_Coral_Block_Blue"
    },
    {
      "x": -3,
      "y": 18,
      "z": -2,
      "name": "Plant_Coral_Block_Blue"
    },
    {
      "x": -3,
      "y": 19,
      "z": -2,
      "name": "Plant_Coral_Block_Blue"
    },
    {
      "x": -3,
      "y": 20,
      "z": -2,
      "name": "Plant_Coral_Block_Blue"
    },
    {
      "x": -3,
      "y": 21,
      "z": -2,
      "name": "Plant_Coral_Block_Blue"
    },
    {
      "x": -3,
      "y": 22,
      "z": -2,
      "name": "Plant_Coral_Block_Blue"
    },
    {
      "x": -3,
      "y": 23,
      "z": -2,
      "name": "Plant_Coral_Block_BSOD"
    },
    {
      "x": -3,
      "y": 24,
      "z": -2,
      "name": "Plant_Coral_Block_BSOD"
    },
    {
      "x": -3,
      "y": 25,
      "z": -2,
      "name": "Plant_Coral_Block_BSOD"
    },
    {
      "x": -3,
      "y": 26,
      "z": -2,
      "name": "Plant_Coral_Block_BSOD"
    },
    {
      "x": -3,
      "y": 27,
      "z": -2,
      "name": "Plant_Coral_Block_BSOD"
    },
    {
      "x": -3,
      "y": 28,
      "z": -2,
      "name": "Plant_Coral_Block_BSOD"
    },
    {
      "x": -3,
      "y": 0,
      "z": -1,
      "name": "Plant_Coral_Block_Blue"
    },
    {
      "x": -3,
      "y": 1,
      "z": -1,
      "name": "Plant_Coral_Block_Blue"
    },
    {
      "x": -3,
      "y": 2,
      "z": -1,
      "name": "Plant_Coral_Block_Blue"
    },
    {
      "x": -3,
      "y": 3,
      "z": -1,
      "name": "Plant_Coral_Block_Blue"
    },
    {
      "x": -3,
      "y": 4,
      "z": -1,
      "name": "Plant_Coral_Block_Blue"
    },
    {
      "x": -3,
      "y": 5,
      "z": -1,
      "name": "Plant_Coral_Block_Blue"
    },
    {
      "x": -3,
      "y": 6,
      "z": -1,
      "name": "Plant_Coral_Block_Blue"
    },
    {
      "x": -3,
      "y": 7,
      "z": -1,
      "name": "Plant_Coral_Block_Blue"
    },
    {
      "x": -3,
      "y": 8,
      "z": -1,
      "name": "Plant_Coral_Block_Blue"
    },
    {
      "x": -3,
      "y": 9,
      "z": -1,
      "name": "Plant_Coral_Block_Blue"
    },
    {
      "x": -3,
      "y": 10,
      "z": -1,
      "name": "Plant_Coral_Block_Blue"
    },
    {
      "x": -3,
      "y": 11,
      "z": -1,
      "name": "Plant_Coral_Block_Blue"
    },
    {
      "x": -3,
      "y": 12,
      "z": -1,
      "name": "Plant_Coral_Block_Blue"
    },
    {
      "x": -3,
      "y": 13,
      "z": -1,
      "name": "Plant_Coral_Block_Blue"
    },
    {
      "x": -3,
      "y": 14,
      "z": -1,
      "name": "Plant_Coral_Block_Blue"
    },
    {
      "x": -3,
      "y": 15,
      "z": -1,
      "name": "Plant_Coral_Block_Blue"
    },
    {
      "x": -3,
      "y": 16,
      "z": -1,
      "name": "Plant_Coral_Block_Blue"
    },
    {
      "x": -3,
      "y": 17,
      "z": -1,
      "name": "Plant_Coral_Block_Blue"
    },
    {
      "x": -3,
      "y": 18,
      "z": -1,
      "name": "Plant_Coral_Block_Blue"
    },
    {
      "x": -3,
      "y": 19,
      "z": -1,
      "name": "Plant_Coral_Block_BSOD"
    },
    {
      "x": -3,
      "y": 20,
      "z": -1,
      "name": "Plant_Coral_Block_BSOD"
    },
    {
      "x": -3,
      "y": 21,
      "z": -1,
      "name": "Plant_Coral_Block_Blue"
    },
    {
      "x": -3,
      "y": 22,
      "z": -1,
      "name": "Plant_Coral_Block_Blue"
    },
    {
      "x": -3,
      "y": 23,
      "z": -1,
      "name": "Plant_Coral_Block_BSOD"
    },
    {
      "x": -3,
      "y": 24,
      "z": -1,
      "name": "Plant_Coral_Block_BSOD"
    },
    {
      "x": -3,
      "y": 25,
      "z": -1,
      "name": "Plant_Coral_Block_BSOD"
    },
    {
      "x": -3,
      "y": 26,
      "z": -1,
      "name": "Plant_Coral_Block_BSOD"
    },
    {
      "x": -3,
      "y": 0,
      "z": 0,
      "name": "Plant_Coral_Block_Blue"
    },
    {
      "x": -3,
      "y": 1,
      "z": 0,
      "name": "Plant_Coral_Block_Blue"
    },
    {
      "x": -3,
      "y": 2,
      "z": 0,
      "name": "Plant_Coral_Block_Blue"
    },
    {
      "x": -3,
      "y": 3,
      "z": 0,
      "name": "Plant_Coral_Block_Blue"
    },
    {
      "x": -3,
      "y": 4,
      "z": 0,
      "name": "Plant_Coral_Block_Blue"
    },
    {
      "x": -3,
      "y": 5,
      "z": 0,
      "name": "Plant_Coral_Block_Blue"
    },
    {
      "x": -3,
      "y": 6,
      "z": 0,
      "name": "Plant_Coral_Block_Blue"
    },
    {
      "x": -3,
      "y": 7,
      "z": 0,
      "name": "Plant_Coral_Block_Blue"
    },
    {
      "x": -3,
      "y": 8,
      "z": 0,
      "name": "Plant_Coral_Block_Blue"
    },
    {
      "x": -3,
      "y": 9,
      "z": 0,
      "name": "Plant_Coral_Block_Blue"
    },
    {
      "x": -3,
      "y": 10,
      "z": 0,
      "name": "Plant_Coral_Block_Blue"
    },
    {
      "x": -3,
      "y": 11,
      "z": 0,
      "name": "Plant_Coral_Block_Blue"
    },
    {
      "x": -3,
      "y": 12,
      "z": 0,
      "name": "Plant_Coral_Block_Blue"
    },
    {
      "x": -3,
      "y": 13,
      "z": 0,
      "name": "Plant_Coral_Block_Blue"
    },
    {
      "x": -3,
      "y": 14,
      "z": 0,
      "name": "Plant_Coral_Block_Blue"
    },
    {
      "x": -3,
      "y": 15,
      "z": 0,
      "name": "Plant_Coral_Block_Blue"
    },
    {
      "x": -3,
      "y": 16,
      "z": 0,
      "name": "Plant_Coral_Block_Blue"
    },
    {
      "x": -3,
      "y": 17,
      "z": 0,
      "name": "Plant_Coral_Block_Blue"
    },
    {
      "x": -3,
      "y": 18,
      "z": 0,
      "name": "Plant_Coral_Block_Blue"
    },
    {
      "x": -3,
      "y": 19,
      "z": 0,
      "name": "Plant_Coral_Block_Blue"
    },
    {
      "x": -3,
      "y": 20,
      "z": 0,
      "name": "Plant_Coral_Block_Blue"
    },
    {
      "x": -3,
      "y": 21,
      "z": 0,
      "name": "Plant_Coral_Block_Blue"
    },
    {
      "x": -3,
      "y": 22,
      "z": 0,
      "name": "Plant_Coral_Block_Blue"
    },
    {
      "x": -3,
      "y": 23,
      "z": 0,
      "name": "Plant_Coral_Block_BSOD"
    },
    {
      "x": -3,
      "y": 24,
      "z": 0,
      "name": "Plant_Coral_Block_BSOD"
    },
    {
      "x": -3,
      "y": 25,
      "z": 0,
      "name": "Plant_Coral_Block_BSOD"
    },
    {
      "x": -3,
      "y": 6,
      "z": 1,
      "name": "Plant_Coral_Block_Blue"
    },
    {
      "x": -3,
      "y": 7,
      "z": 1,
      "name": "Plant_Coral_Block_Blue"
    },
    {
      "x": -3,
      "y": 8,
      "z": 1,
      "name": "Plant_Coral_Block_Blue"
    },
    {
      "x": -3,
      "y": 9,
      "z": 1,
      "name": "Plant_Coral_Block_Blue"
    },
    {
      "x": -3,
      "y": 10,
      "z": 1,
      "name": "Plant_Coral_Block_Blue"
    },
    {
      "x": -3,
      "y": 11,
      "z": 1,
      "name": "Plant_Coral_Block_Blue"
    },
    {
      "x": -3,
      "y": 12,
      "z": 1,
      "name": "Plant_Coral_Block_Blue"
    },
    {
      "x": -3,
      "y": 13,
      "z": 1,
      "name": "Plant_Coral_Block_Blue"
    },
    {
      "x": -3,
      "y": 14,
      "z": 1,
      "name": "Plant_Coral_Block_Blue"
    },
    {
      "x": -3,
      "y": 15,
      "z": 1,
      "name": "Plant_Coral_Block_BSOD"
    },
    {
      "x": -3,
      "y": 16,
      "z": 1,
      "name": "Plant_Coral_Block_Blue"
    },
    {
      "x": -3,
      "y": 17,
      "z": 1,
      "name": "Plant_Coral_Block_Blue"
    },
    {
      "x": -3,
      "y": 18,
      "z": 1,
      "name": "Plant_Coral_Block_Blue"
    },
    {
      "x": -3,
      "y": 19,
      "z": 1,
      "name": "Plant_Coral_Block_Blue"
    },
    {
      "x": -3,
      "y": 20,
      "z": 1,
      "name": "Plant_Coral_Block_Blue"
    },
    {
      "x": -3,
      "y": 21,
      "z": 1,
      "name": "Plant_Coral_Block_Blue"
    },
    {
      "x": -3,
      "y": 22,
      "z": 1,
      "name": "Plant_Coral_Block_BSOD"
    },
    {
      "x": -3,
      "y": 23,
      "z": 1,
      "name": "Plant_Coral_Block_BSOD"
    },
    {
      "x": -3,
      "y": 24,
      "z": 1,
      "name": "Rock_Volcanic_Cracked_Poisoned"
    },
    {
      "x": -3,
      "y": 6,
      "z": 2,
      "name": "Plant_Coral_Block_Blue"
    },
    {
      "x": -3,
      "y": 7,
      "z": 2,
      "name": "Plant_Coral_Block_Blue"
    },
    {
      "x": -3,
      "y": 8,
      "z": 2,
      "name": "Plant_Coral_Block_Blue"
    },
    {
      "x": -3,
      "y": 9,
      "z": 2,
      "name": "Plant_Coral_Block_Blue"
    },
    {
      "x": -3,
      "y": 10,
      "z": 2,
      "name": "Plant_Coral_Block_Blue"
    },
    {
      "x": -3,
      "y": 11,
      "z": 2,
      "name": "Plant_Coral_Block_Blue"
    },
    {
      "x": -3,
      "y": 12,
      "z": 2,
      "name": "Plant_Coral_Block_Blue"
    },
    {
      "x": -3,
      "y": 13,
      "z": 2,
      "name": "Plant_Coral_Block_Blue"
    },
    {
      "x": -3,
      "y": 14,
      "z": 2,
      "name": "Plant_Coral_Block_Blue"
    },
    {
      "x": -3,
      "y": 15,
      "z": 2,
      "name": "Plant_Coral_Block_BSOD"
    },
    {
      "x": -3,
      "y": 16,
      "z": 2,
      "name": "Plant_Coral_Block_Blue"
    },
    {
      "x": -3,
      "y": 17,
      "z": 2,
      "name": "Plant_Coral_Block_Blue"
    },
    {
      "x": -3,
      "y": 18,
      "z": 2,
      "name": "Plant_Coral_Block_Blue"
    },
    {
      "x": -3,
      "y": 19,
      "z": 2,
      "name": "Plant_Coral_Block_BSOD"
    },
    {
      "x": -3,
      "y": 20,
      "z": 2,
      "name": "Plant_Coral_Block_Blue"
    },
    {
      "x": -3,
      "y": 21,
      "z": 2,
      "name": "Plant_Coral_Block_Blue"
    },
    {
      "x": -3,
      "y": 22,
      "z": 2,
      "name": "Plant_Coral_Block_BSOD"
    },
    {
      "x": -3,
      "y": 23,
      "z": 2,
      "name": "Plant_Coral_Block_BSOD"
    },
    {
      "x": -3,
      "y": 24,
      "z": 2,
      "name": "Rock_Volcanic_Cracked_Poisoned"
    },
    {
      "x": -3,
      "y": 6,
      "z": 3,
      "name": "Plant_Coral_Block_Blue"
    },
    {
      "x": -3,
      "y": 7,
      "z": 3,
      "name": "Plant_Coral_Block_Blue"
    },
    {
      "x": -3,
      "y": 8,
      "z": 3,
      "name": "Plant_Coral_Block_Blue"
    },
    {
      "x": -3,
      "y": 9,
      "z": 3,
      "name": "Plant_Coral_Block_Blue"
    },
    {
      "x": -3,
      "y": 10,
      "z": 3,
      "name": "Plant_Coral_Block_Blue"
    },
    {
      "x": -3,
      "y": 11,
      "z": 3,
      "name": "Plant_Coral_Block_Blue"
    },
    {
      "x": -3,
      "y": 12,
      "z": 3,
      "name": "Plant_Coral_Block_Blue"
    },
    {
      "x": -3,
      "y": 13,
      "z": 3,
      "name": "Plant_Coral_Block_Blue"
    },
    {
      "x": -3,
      "y": 14,
      "z": 3,
      "name": "Plant_Coral_Block_BSOD"
    },
    {
      "x": -3,
      "y": 15,
      "z": 3,
      "name": "Plant_Coral_Block_BSOD"
    },
    {
      "x": -3,
      "y": 16,
      "z": 3,
      "name": "Plant_Coral_Block_BSOD"
    },
    {
      "x": -3,
      "y": 17,
      "z": 3,
      "name": "Plant_Coral_Block_Blue"
    },
    {
      "x": -3,
      "y": 18,
      "z": 3,
      "name": "Plant_Coral_Block_BSOD"
    },
    {
      "x": -3,
      "y": 19,
      "z": 3,
      "name": "Plant_Coral_Block_BSOD"
    },
    {
      "x": -3,
      "y": 20,
      "z": 3,
      "name": "Plant_Coral_Block_BSOD"
    },
    {
      "x": -3,
      "y": 21,
      "z": 3,
      "name": "Plant_Coral_Block_BSOD"
    },
    {
      "x": -3,
      "y": 22,
      "z": 3,
      "name": "Plant_Coral_Block_BSOD"
    },
    {
      "x": -3,
      "y": 23,
      "z": 3,
      "name": "Plant_Coral_Block_BSOD"
    },
    {
      "x": -3,
      "y": 24,
      "z": 3,
      "name": "Rock_Volcanic_Cracked_Poisoned"
    },
    {
      "x": -3,
      "y": 7,
      "z": 4,
      "name": "Plant_Coral_Block_Blue"
    },
    {
      "x": -3,
      "y": 8,
      "z": 4,
      "name": "Plant_Coral_Block_Blue"
    },
    {
      "x": -3,
      "y": 9,
      "z": 4,
      "name": "Plant_Coral_Block_Blue"
    },
    {
      "x": -3,
      "y": 10,
      "z": 4,
      "name": "Plant_Coral_Block_Blue"
    },
    {
      "x": -3,
      "y": 11,
      "z": 4,
      "name": "Plant_Coral_Block_Blue"
    },
    {
      "x": -3,
      "y": 12,
      "z": 4,
      "name": "Plant_Coral_Block_Blue"
    },
    {
      "x": -3,
      "y": 13,
      "z": 4,
      "name": "Plant_Coral_Block_Blue"
    },
    {
      "x": -3,
      "y": 14,
      "z": 4,
      "name": "Plant_Coral_Block_BSOD"
    },
    {
      "x": -3,
      "y": 15,
      "z": 4,
      "name": "Plant_Coral_Block_BSOD"
    },
    {
      "x": -3,
      "y": 16,
      "z": 4,
      "name": "Plant_Coral_Block_BSOD"
    },
    {
      "x": -3,
      "y": 17,
      "z": 4,
      "name": "Plant_Coral_Block_BSOD"
    },
    {
      "x": -3,
      "y": 18,
      "z": 4,
      "name": "Plant_Coral_Block_BSOD"
    },
    {
      "x": -3,
      "y": 19,
      "z": 4,
      "name": "Plant_Coral_Block_BSOD"
    },
    {
      "x": -3,
      "y": 20,
      "z": 4,
      "name": "Plant_Coral_Block_BSOD"
    },
    {
      "x": -3,
      "y": 21,
      "z": 4,
      "name": "Plant_Coral_Block_BSOD"
    },
    {
      "x": -3,
      "y": 22,
      "z": 4,
      "name": "Plant_Coral_Block_BSOD"
    },
    {
      "x": -3,
      "y": 23,
      "z": 4,
      "name": "Plant_Coral_Block_BSOD"
    },
    {
      "x": -3,
      "y": 24,
      "z": 4,
      "name": "Rock_Volcanic_Cracked_Poisoned"
    },
    {
      "x": -3,
      "y": 9,
      "z": 5,
      "name": "Plant_Coral_Block_Blue"
    },
    {
      "x": -3,
      "y": 10,
      "z": 5,
      "name": "Plant_Coral_Block_BSOD"
    },
    {
      "x": -3,
      "y": 11,
      "z": 5,
      "name": "Plant_Coral_Block_BSOD"
    },
    {
      "x": -3,
      "y": 12,
      "z": 5,
      "name": "Plant_Coral_Block_Blue"
    },
    {
      "x": -3,
      "y": 13,
      "z": 5,
      "name": "Plant_Coral_Block_Blue"
    },
    {
      "x": -3,
      "y": 14,
      "z": 5,
      "name": "Plant_Coral_Block_Blue"
    },
    {
      "x": -3,
      "y": 15,
      "z": 5,
      "name": "Plant_Coral_Block_BSOD"
    },
    {
      "x": -3,
      "y": 16,
      "z": 5,
      "name": "Plant_Coral_Block_BSOD"
    },
    {
      "x": -3,
      "y": 17,
      "z": 5,
      "name": "Plant_Coral_Block_BSOD"
    },
    {
      "x": -3,
      "y": 18,
      "z": 5,
      "name": "Rock_Volcanic_Cracked_Poisoned"
    },
    {
      "x": -3,
      "y": 20,
      "z": 5,
      "name": "Plant_Coral_Block_BSOD"
    },
    {
      "x": -3,
      "y": 21,
      "z": 5,
      "name": "Plant_Coral_Block_BSOD"
    },
    {
      "x": -3,
      "y": 22,
      "z": 5,
      "name": "Plant_Coral_Block_BSOD"
    },
    {
      "x": -3,
      "y": 23,
      "z": 5,
      "name": "Plant_Coral_Block_BSOD"
    },
    {
      "x": -3,
      "y": 24,
      "z": 5,
      "name": "Rock_Volcanic_Cracked_Poisoned"
    },
    {
      "x": -3,
      "y": 13,
      "z": 6,
      "name": "Plant_Coral_Block_Blue"
    },
    {
      "x": -3,
      "y": 14,
      "z": 6,
      "name": "Plant_Coral_Block_Blue"
    },
    {
      "x": -3,
      "y": 16,
      "z": 6,
      "name": "Plant_Coral_Block_BSOD"
    },
    {
      "x": -3,
      "y": 17,
      "z": 6,
      "name": "Rock_Volcanic_Cracked_Poisoned"
    },
    {
      "x": -3,
      "y": 22,
      "z": 6,
      "name": "Plant_Coral_Block_BSOD"
    },
    {
      "x": -3,
      "y": 23,
      "z": 6,
      "name": "Plant_Coral_Block_BSOD"
    },
    {
      "x": -3,
      "y": 24,
      "z": 6,
      "name": "Plant_Coral_Block_BSOD"
    },
    {
      "x": -3,
      "y": 25,
      "z": 6,
      "name": "Plant_Coral_Block_BSOD"
    },
    {
      "x": -3,
      "y": 17,
      "z": 7,
      "name": "Plant_Coral_Block_BSOD"
    },
    {
      "x": -3,
      "y": 18,
      "z": 7,
      "name": "Rock_Volcanic_Cracked_Poisoned"
    },
    {
      "x": -3,
      "y": 18,
      "z": 8,
      "name": "Plant_Coral_Block_BSOD"
    },
    {
      "x": -3,
      "y": 19,
      "z": 8,
      "name": "Plant_Coral_Block_BSOD"
    },
    {
      "x": -2,
      "y": 24,
      "z": -8,
      "name": "Plant_Coral_Block_BSOD"
    },
    {
      "x": -2,
      "y": 25,
      "z": -8,
      "name": "Plant_Coral_Block_BSOD"
    },
    {
      "x": -2,
      "y": 15,
      "z": -7,
      "name": "Plant_Coral_Block_BSOD"
    },
    {
      "x": -2,
      "y": 23,
      "z": -7,
      "name": "Plant_Coral_Block_BSOD"
    },
    {
      "x": -2,
      "y": 24,
      "z": -7,
      "name": "Rock_Volcanic_Cracked_Poisoned"
    },
    {
      "x": -2,
      "y": 13,
      "z": -6,
      "name": "Plant_Coral_Block_BSOD"
    },
    {
      "x": -2,
      "y": 14,
      "z": -6,
      "name": "Plant_Coral_Block_BSOD"
    },
    {
      "x": -2,
      "y": 20,
      "z": -6,
      "name": "Plant_Coral_Block_Blue"
    },
    {
      "x": -2,
      "y": 21,
      "z": -6,
      "name": "Plant_Coral_Block_Blue"
    },
    {
      "x": -2,
      "y": 22,
      "z": -6,
      "name": "Plant_Coral_Block_BSOD"
    },
    {
      "x": -2,
      "y": 23,
      "z": -6,
      "name": "Plant_Coral_Block_BSOD"
    },
    {
      "x": -2,
      "y": 24,
      "z": -6,
      "name": "Rock_Volcanic_Cracked_Poisoned"
    },
    {
      "x": -2,
      "y": 27,
      "z": -6,
      "name": "Plant_Coral_Block_BSOD"
    },
    {
      "x": -2,
      "y": 28,
      "z": -6,
      "name": "Plant_Coral_Block_BSOD"
    },
    {
      "x": -2,
      "y": 12,
      "z": -5,
      "name": "Plant_Coral_Block_BSOD"
    },
    {
      "x": -2,
      "y": 13,
      "z": -5,
      "name": "Rock_Volcanic_Cracked_Poisoned"
    },
    {
      "x": -2,
      "y": 17,
      "z": -5,
      "name": "Plant_Coral_Block_Blue"
    },
    {
      "x": -2,
      "y": 18,
      "z": -5,
      "name": "Plant_Coral_Block_Blue"
    },
    {
      "x": -2,
      "y": 19,
      "z": -5,
      "name": "Plant_Coral_Block_Blue"
    },
    {
      "x": -2,
      "y": 20,
      "z": -5,
      "name": "Plant_Coral_Block_Blue"
    },
    {
      "x": -2,
      "y": 21,
      "z": -5,
      "name": "Plant_Coral_Block_Blue"
    },
    {
      "x": -2,
      "y": 22,
      "z": -5,
      "name": "Plant_Coral_Block_BSOD"
    },
    {
      "x": -2,
      "y": 23,
      "z": -5,
      "name": "Plant_Coral_Block_BSOD"
    },
    {
      "x": -2,
      "y": 24,
      "z": -5,
      "name": "Rock_Volcanic_Cracked_Poisoned"
    },
    {
      "x": -2,
      "y": 26,
      "z": -5,
      "name": "Plant_Coral_Block_Blue"
    },
    {
      "x": -2,
      "y": 27,
      "z": -5,
      "name": "Rock_Volcanic_Cracked_Poisoned"
    },
    {
      "x": -2,
      "y": 10,
      "z": -4,
      "name": "Plant_Coral_Block_Blue"
    },
    {
      "x": -2,
      "y": 11,
      "z": -4,
      "name": "Plant_Coral_Block_BSOD"
    },
    {
      "x": -2,
      "y": 12,
      "z": -4,
      "name": "Plant_Coral_Block_BSOD"
    },
    {
      "x": -2,
      "y": 13,
      "z": -4,
      "name": "Plant_Coral_Block_BSOD"
    },
    {
      "x": -2,
      "y": 14,
      "z": -4,
      "name": "Plant_Coral_Block_BSOD"
    },
    {
      "x": -2,
      "y": 15,
      "z": -4,
      "name": "Plant_Coral_Block_BSOD"
    },
    {
      "x": -2,
      "y": 16,
      "z": -4,
      "name": "Plant_Coral_Block_BSOD"
    },
    {
      "x": -2,
      "y": 17,
      "z": -4,
      "name": "Plant_Coral_Block_Blue"
    },
    {
      "x": -2,
      "y": 18,
      "z": -4,
      "name": "Plant_Coral_Block_Blue"
    },
    {
      "x": -2,
      "y": 19,
      "z": -4,
      "name": "Plant_Coral_Block_Blue"
    },
    {
      "x": -2,
      "y": 20,
      "z": -4,
      "name": "Plant_Coral_Block_Blue"
    },
    {
      "x": -2,
      "y": 21,
      "z": -4,
      "name": "Plant_Coral_Block_Blue"
    },
    {
      "x": -2,
      "y": 22,
      "z": -4,
      "name": "Plant_Coral_Block_Blue"
    },
    {
      "x": -2,
      "y": 23,
      "z": -4,
      "name": "Plant_Coral_Block_BSOD"
    },
    {
      "x": -2,
      "y": 25,
      "z": -4,
      "name": "Plant_Coral_Block_BSOD"
    },
    {
      "x": -2,
      "y": 26,
      "z": -4,
      "name": "Rock_Volcanic_Cracked_Poisoned"
    },
    {
      "x": -2,
      "y": 9,
      "z": -3,
      "name": "Plant_Coral_Block_Blue"
    },
    {
      "x": -2,
      "y": 10,
      "z": -3,
      "name": "Plant_Coral_Block_Blue"
    },
    {
      "x": -2,
      "y": 11,
      "z": -3,
      "name": "Plant_Coral_Block_Blue"
    },
    {
      "x": -2,
      "y": 12,
      "z": -3,
      "name": "Plant_Coral_Block_BSOD"
    },
    {
      "x": -2,
      "y": 13,
      "z": -3,
      "name": "Plant_Coral_Block_BSOD"
    },
    {
      "x": -2,
      "y": 14,
      "z": -3,
      "name": "Plant_Coral_Block_BSOD"
    },
    {
      "x": -2,
      "y": 15,
      "z": -3,
      "name": "Plant_Coral_Block_BSOD"
    },
    {
      "x": -2,
      "y": 16,
      "z": -3,
      "name": "Plant_Coral_Block_Blue"
    },
    {
      "x": -2,
      "y": 17,
      "z": -3,
      "name": "Plant_Coral_Block_BSOD"
    },
    {
      "x": -2,
      "y": 18,
      "z": -3,
      "name": "Plant_Coral_Block_BSOD"
    },
    {
      "x": -2,
      "y": 19,
      "z": -3,
      "name": "Plant_Coral_Block_BSOD"
    },
    {
      "x": -2,
      "y": 20,
      "z": -3,
      "name": "Plant_Coral_Block_BSOD"
    },
    {
      "x": -2,
      "y": 21,
      "z": -3,
      "name": "Plant_Coral_Block_Blue"
    },
    {
      "x": -2,
      "y": 22,
      "z": -3,
      "name": "Plant_Coral_Block_Blue"
    },
    {
      "x": -2,
      "y": 23,
      "z": -3,
      "name": "Plant_Coral_Block_Blue"
    },
    {
      "x": -2,
      "y": 25,
      "z": -3,
      "name": "Plant_Coral_Block_BSOD"
    },
    {
      "x": -2,
      "y": 26,
      "z": -3,
      "name": "Rock_Volcanic_Cracked_Poisoned"
    },
    {
      "x": -2,
      "y": 9,
      "z": -2,
      "name": "Plant_Coral_Block_Blue"
    },
    {
      "x": -2,
      "y": 10,
      "z": -2,
      "name": "Plant_Coral_Block_Blue"
    },
    {
      "x": -2,
      "y": 11,
      "z": -2,
      "name": "Plant_Coral_Block_Blue"
    },
    {
      "x": -2,
      "y": 12,
      "z": -2,
      "name": "Plant_Coral_Block_Blue"
    },
    {
      "x": -2,
      "y": 13,
      "z": -2,
      "name": "Plant_Coral_Block_BSOD"
    },
    {
      "x": -2,
      "y": 14,
      "z": -2,
      "name": "Plant_Coral_Block_BSOD"
    },
    {
      "x": -2,
      "y": 15,
      "z": -2,
      "name": "Plant_Coral_Block_Blue"
    },
    {
      "x": -2,
      "y": 16,
      "z": -2,
      "name": "Plant_Coral_Block_Blue"
    },
    {
      "x": -2,
      "y": 17,
      "z": -2,
      "name": "Plant_Coral_Block_Blue"
    },
    {
      "x": -2,
      "y": 18,
      "z": -2,
      "name": "Plant_Coral_Block_Blue"
    },
    {
      "x": -2,
      "y": 19,
      "z": -2,
      "name": "Plant_Coral_Block_Blue"
    },
    {
      "x": -2,
      "y": 20,
      "z": -2,
      "name": "Plant_Coral_Block_Blue"
    },
    {
      "x": -2,
      "y": 21,
      "z": -2,
      "name": "Plant_Coral_Block_Blue"
    },
    {
      "x": -2,
      "y": 22,
      "z": -2,
      "name": "Plant_Coral_Block_Blue"
    },
    {
      "x": -2,
      "y": 23,
      "z": -2,
      "name": "Plant_Coral_Block_Blue"
    },
    {
      "x": -2,
      "y": 24,
      "z": -2,
      "name": "Plant_Coral_Block_BSOD"
    },
    {
      "x": -2,
      "y": 25,
      "z": -2,
      "name": "Plant_Coral_Block_BSOD"
    },
    {
      "x": -2,
      "y": 26,
      "z": -2,
      "name": "Plant_Coral_Block_BSOD"
    },
    {
      "x": -2,
      "y": 27,
      "z": -2,
      "name": "Rock_Volcanic_Cracked_Poisoned"
    },
    {
      "x": -2,
      "y": 0,
      "z": -1,
      "name": "Plant_Coral_Block_Blue"
    },
    {
      "x": -2,
      "y": 1,
      "z": -1,
      "name": "Plant_Coral_Block_Blue"
    },
    {
      "x": -2,
      "y": 2,
      "z": -1,
      "name": "Plant_Coral_Block_Blue"
    },
    {
      "x": -2,
      "y": 3,
      "z": -1,
      "name": "Plant_Coral_Block_Blue"
    },
    {
      "x": -2,
      "y": 4,
      "z": -1,
      "name": "Plant_Coral_Block_Blue"
    },
    {
      "x": -2,
      "y": 5,
      "z": -1,
      "name": "Plant_Coral_Block_Blue"
    },
    {
      "x": -2,
      "y": 6,
      "z": -1,
      "name": "Plant_Coral_Block_Blue"
    },
    {
      "x": -2,
      "y": 7,
      "z": -1,
      "name": "Plant_Coral_Block_Blue"
    },
    {
      "x": -2,
      "y": 8,
      "z": -1,
      "name": "Plant_Coral_Block_Blue"
    },
    {
      "x": -2,
      "y": 9,
      "z": -1,
      "name": "Plant_Coral_Block_Blue"
    },
    {
      "x": -2,
      "y": 10,
      "z": -1,
      "name": "Plant_Coral_Block_Blue"
    },
    {
      "x": -2,
      "y": 11,
      "z": -1,
      "name": "Plant_Coral_Block_Blue"
    },
    {
      "x": -2,
      "y": 12,
      "z": -1,
      "name": "Plant_Coral_Block_Blue"
    },
    {
      "x": -2,
      "y": 13,
      "z": -1,
      "name": "Plant_Coral_Block_Blue"
    },
    {
      "x": -2,
      "y": 14,
      "z": -1,
      "name": "Plant_Coral_Block_Blue"
    },
    {
      "x": -2,
      "y": 15,
      "z": -1,
      "name": "Plant_Coral_Block_Blue"
    },
    {
      "x": -2,
      "y": 16,
      "z": -1,
      "name": "Plant_Coral_Block_Blue"
    },
    {
      "x": -2,
      "y": 17,
      "z": -1,
      "name": "Plant_Coral_Block_Blue"
    },
    {
      "x": -2,
      "y": 18,
      "z": -1,
      "name": "Plant_Coral_Block_Blue"
    },
    {
      "x": -2,
      "y": 19,
      "z": -1,
      "name": "Plant_Coral_Block_Blue"
    },
    {
      "x": -2,
      "y": 20,
      "z": -1,
      "name": "Plant_Coral_Block_Blue"
    },
    {
      "x": -2,
      "y": 21,
      "z": -1,
      "name": "Plant_Coral_Block_Blue"
    },
    {
      "x": -2,
      "y": 22,
      "z": -1,
      "name": "Plant_Coral_Block_Blue"
    },
    {
      "x": -2,
      "y": 23,
      "z": -1,
      "name": "Plant_Coral_Block_BSOD"
    },
    {
      "x": -2,
      "y": 24,
      "z": -1,
      "name": "Plant_Coral_Block_BSOD"
    },
    {
      "x": -2,
      "y": 25,
      "z": -1,
      "name": "Plant_Coral_Block_BSOD"
    },
    {
      "x": -2,
      "y": 26,
      "z": -1,
      "name": "Plant_Coral_Block_BSOD"
    },
    {
      "x": -2,
      "y": 27,
      "z": -1,
      "name": "Plant_Coral_Block_BSOD"
    },
    {
      "x": -2,
      "y": 28,
      "z": -1,
      "name": "Plant_Coral_Block_BSOD"
    },
    {
      "x": -2,
      "y": 0,
      "z": 0,
      "name": "Plant_Coral_Block_Blue"
    },
    {
      "x": -2,
      "y": 1,
      "z": 0,
      "name": "Plant_Coral_Block_Blue"
    },
    {
      "x": -2,
      "y": 2,
      "z": 0,
      "name": "Plant_Coral_Block_Blue"
    },
    {
      "x": -2,
      "y": 3,
      "z": 0,
      "name": "Plant_Coral_Block_Blue"
    },
    {
      "x": -2,
      "y": 4,
      "z": 0,
      "name": "Plant_Coral_Block_Blue"
    },
    {
      "x": -2,
      "y": 5,
      "z": 0,
      "name": "Plant_Coral_Block_Blue"
    },
    {
      "x": -2,
      "y": 6,
      "z": 0,
      "name": "Plant_Coral_Block_Blue"
    },
    {
      "x": -2,
      "y": 7,
      "z": 0,
      "name": "Plant_Coral_Block_Blue"
    },
    {
      "x": -2,
      "y": 8,
      "z": 0,
      "name": "Plant_Coral_Block_Blue"
    },
    {
      "x": -2,
      "y": 9,
      "z": 0,
      "name": "Plant_Coral_Block_Blue"
    },
    {
      "x": -2,
      "y": 10,
      "z": 0,
      "name": "Plant_Coral_Block_Blue"
    },
    {
      "x": -2,
      "y": 11,
      "z": 0,
      "name": "Plant_Coral_Block_Blue"
    },
    {
      "x": -2,
      "y": 12,
      "z": 0,
      "name": "Plant_Coral_Block_Blue"
    },
    {
      "x": -2,
      "y": 13,
      "z": 0,
      "name": "Plant_Coral_Block_Blue"
    },
    {
      "x": -2,
      "y": 14,
      "z": 0,
      "name": "Plant_Coral_Block_Blue"
    },
    {
      "x": -2,
      "y": 15,
      "z": 0,
      "name": "Plant_Coral_Block_Blue"
    },
    {
      "x": -2,
      "y": 16,
      "z": 0,
      "name": "Plant_Coral_Block_Blue"
    },
    {
      "x": -2,
      "y": 17,
      "z": 0,
      "name": "Plant_Coral_Block_Blue"
    },
    {
      "x": -2,
      "y": 18,
      "z": 0,
      "name": "Plant_Coral_Block_Blue"
    },
    {
      "x": -2,
      "y": 19,
      "z": 0,
      "name": "Plant_Coral_Block_Blue"
    },
    {
      "x": -2,
      "y": 20,
      "z": 0,
      "name": "Plant_Coral_Block_Blue"
    },
    {
      "x": -2,
      "y": 21,
      "z": 0,
      "name": "Plant_Coral_Block_Blue"
    },
    {
      "x": -2,
      "y": 22,
      "z": 0,
      "name": "Plant_Coral_Block_BSOD"
    },
    {
      "x": -2,
      "y": 23,
      "z": 0,
      "name": "Plant_Coral_Block_BSOD"
    },
    {
      "x": -2,
      "y": 24,
      "z": 0,
      "name": "Rock_Volcanic_Cracked_Poisoned"
    },
    {
      "x": -2,
      "y": 4,
      "z": 1,
      "name": "Plant_Coral_Block_Blue"
    },
    {
      "x": -2,
      "y": 5,
      "z": 1,
      "name": "Plant_Coral_Block_Blue"
    },
    {
      "x": -2,
      "y": 6,
      "z": 1,
      "name": "Plant_Coral_Block_Blue"
    },
    {
      "x": -2,
      "y": 7,
      "z": 1,
      "name": "Plant_Coral_Block_Blue"
    },
    {
      "x": -2,
      "y": 8,
      "z": 1,
      "name": "Plant_Coral_Block_Blue"
    },
    {
      "x": -2,
      "y": 9,
      "z": 1,
      "name": "Plant_Coral_Block_Blue"
    },
    {
      "x": -2,
      "y": 10,
      "z": 1,
      "name": "Plant_Coral_Block_Blue"
    },
    {
      "x": -2,
      "y": 11,
      "z": 1,
      "name": "Plant_Coral_Block_Blue"
    },
    {
      "x": -2,
      "y": 12,
      "z": 1,
      "name": "Plant_Coral_Block_Blue"
    },
    {
      "x": -2,
      "y": 13,
      "z": 1,
      "name": "Plant_Coral_Block_Blue"
    },
    {
      "x": -2,
      "y": 14,
      "z": 1,
      "name": "Plant_Coral_Block_Blue"
    },
    {
      "x": -2,
      "y": 15,
      "z": 1,
      "name": "Plant_Coral_Block_Blue"
    },
    {
      "x": -2,
      "y": 16,
      "z": 1,
      "name": "Plant_Coral_Block_Blue"
    },
    {
      "x": -2,
      "y": 17,
      "z": 1,
      "name": "Plant_Coral_Block_Blue"
    },
    {
      "x": -2,
      "y": 18,
      "z": 1,
      "name": "Plant_Coral_Block_Blue"
    },
    {
      "x": -2,
      "y": 19,
      "z": 1,
      "name": "Plant_Coral_Block_Blue"
    },
    {
      "x": -2,
      "y": 20,
      "z": 1,
      "name": "Plant_Coral_Block_Blue"
    },
    {
      "x": -2,
      "y": 21,
      "z": 1,
      "name": "Plant_Coral_Block_Blue"
    },
    {
      "x": -2,
      "y": 22,
      "z": 1,
      "name": "Plant_Coral_Block_BSOD"
    },
    {
      "x": -2,
      "y": 23,
      "z": 1,
      "name": "Plant_Coral_Block_BSOD"
    },
    {
      "x": -2,
      "y": 24,
      "z": 1,
      "name": "Rock_Volcanic_Cracked_Poisoned"
    },
    {
      "x": -2,
      "y": 6,
      "z": 2,
      "name": "Plant_Coral_Block_Blue"
    },
    {
      "x": -2,
      "y": 7,
      "z": 2,
      "name": "Plant_Coral_Block_Blue"
    },
    {
      "x": -2,
      "y": 8,
      "z": 2,
      "name": "Plant_Coral_Block_Blue"
    },
    {
      "x": -2,
      "y": 9,
      "z": 2,
      "name": "Plant_Coral_Block_Blue"
    },
    {
      "x": -2,
      "y": 10,
      "z": 2,
      "name": "Plant_Coral_Block_Blue"
    },
    {
      "x": -2,
      "y": 11,
      "z": 2,
      "name": "Plant_Coral_Block_Blue"
    },
    {
      "x": -2,
      "y": 12,
      "z": 2,
      "name": "Plant_Coral_Block_Blue"
    },
    {
      "x": -2,
      "y": 13,
      "z": 2,
      "name": "Plant_Coral_Block_Blue"
    },
    {
      "x": -2,
      "y": 14,
      "z": 2,
      "name": "Plant_Coral_Block_Blue"
    },
    {
      "x": -2,
      "y": 15,
      "z": 2,
      "name": "Plant_Coral_Block_Blue"
    },
    {
      "x": -2,
      "y": 16,
      "z": 2,
      "name": "Plant_Coral_Block_Blue"
    },
    {
      "x": -2,
      "y": 17,
      "z": 2,
      "name": "Plant_Coral_Block_Blue"
    },
    {
      "x": -2,
      "y": 18,
      "z": 2,
      "name": "Plant_Coral_Block_Blue"
    },
    {
      "x": -2,
      "y": 19,
      "z": 2,
      "name": "Plant_Coral_Block_Blue"
    },
    {
      "x": -2,
      "y": 20,
      "z": 2,
      "name": "Plant_Coral_Block_Blue"
    },
    {
      "x": -2,
      "y": 21,
      "z": 2,
      "name": "Plant_Coral_Block_Blue"
    },
    {
      "x": -2,
      "y": 22,
      "z": 2,
      "name": "Plant_Coral_Block_BSOD"
    },
    {
      "x": -2,
      "y": 23,
      "z": 2,
      "name": "Plant_Coral_Block_BSOD"
    },
    {
      "x": -2,
      "y": 24,
      "z": 2,
      "name": "Rock_Volcanic_Cracked_Poisoned"
    },
    {
      "x": -2,
      "y": 6,
      "z": 3,
      "name": "Plant_Coral_Block_Blue"
    },
    {
      "x": -2,
      "y": 7,
      "z": 3,
      "name": "Plant_Coral_Block_Blue"
    },
    {
      "x": -2,
      "y": 8,
      "z": 3,
      "name": "Plant_Coral_Block_Blue"
    },
    {
      "x": -2,
      "y": 9,
      "z": 3,
      "name": "Plant_Coral_Block_Blue"
    },
    {
      "x": -2,
      "y": 10,
      "z": 3,
      "name": "Plant_Coral_Block_Blue"
    },
    {
      "x": -2,
      "y": 11,
      "z": 3,
      "name": "Plant_Coral_Block_Blue"
    },
    {
      "x": -2,
      "y": 12,
      "z": 3,
      "name": "Plant_Coral_Block_Blue"
    },
    {
      "x": -2,
      "y": 13,
      "z": 3,
      "name": "Plant_Coral_Block_Blue"
    },
    {
      "x": -2,
      "y": 14,
      "z": 3,
      "name": "Plant_Coral_Block_Blue"
    },
    {
      "x": -2,
      "y": 15,
      "z": 3,
      "name": "Plant_Coral_Block_BSOD"
    },
    {
      "x": -2,
      "y": 16,
      "z": 3,
      "name": "Plant_Coral_Block_Blue"
    },
    {
      "x": -2,
      "y": 17,
      "z": 3,
      "name": "Plant_Coral_Block_Blue"
    },
    {
      "x": -2,
      "y": 18,
      "z": 3,
      "name": "Plant_Coral_Block_Blue"
    },
    {
      "x": -2,
      "y": 19,
      "z": 3,
      "name": "Plant_Coral_Block_BSOD"
    },
    {
      "x": -2,
      "y": 20,
      "z": 3,
      "name": "Plant_Coral_Block_Blue"
    },
    {
      "x": -2,
      "y": 21,
      "z": 3,
      "name": "Plant_Coral_Block_BSOD"
    },
    {
      "x": -2,
      "y": 22,
      "z": 3,
      "name": "Plant_Coral_Block_BSOD"
    },
    {
      "x": -2,
      "y": 23,
      "z": 3,
      "name": "Rock_Volcanic_Cracked_Poisoned"
    },
    {
      "x": -2,
      "y": 0,
      "z": 4,
      "name": "Plant_Coral_Block_Blue"
    },
    {
      "x": -2,
      "y": 1,
      "z": 4,
      "name": "Plant_Coral_Block_Blue"
    },
    {
      "x": -2,
      "y": 2,
      "z": 4,
      "name": "Plant_Coral_Block_Blue"
    },
    {
      "x": -2,
      "y": 3,
      "z": 4,
      "name": "Plant_Coral_Block_Blue"
    },
    {
