{
  "version": 8,
  "blockIdVersion": 11,
  "anchorX": 9,
  "anchorY": 10,
  "anchorZ": 8,
  "blocks": [
    {
      "x": 8,
      "y": 18,
      "z": 7,
      "name": "Plant_Leaves_Bottle"
    },
    {
      "x": 8,
      "y": 19,
      "z": 7,
      "name": "Plant_Leaves_Bottle"
    },
    {
      "x": 8,
      "y": 26,
      "z": 8,
      "name": "Plant_Leaves_Bottle"
    },
    {
      "x": 8,
      "y": 26,
      "z": 9,
      "name": "Plant_Leaves_Bottle"
    },
    {
      "x": 8,
      "y": 27,
      "z": 9,
      "name": "Plant_Leaves_Bottle"
    },
    {
      "x": 8,
      "y": 27,
      "z": 10,
      "name": "Plant_Leaves_Bottle"
    },
    {
      "x": 9,
      "y": 24,
      "z": 4,
      "name": "Plant_Leaves_Bottle"
    },
    {
      "x": 9,
      "y": 23,
      "z": 5,
      "name": "Plant_Leaves_Bottle"
    },
    {
      "x": 9,
      "y": 24,
      "z": 5,
      "name": "Plant_Leaves_Bottle"
    },
    {
      "x": 9,
      "y": 25,
      "z": 5,
      "name": "Plant_Leaves_Bottle"
    },
    {
      "x": 9,
      "y": 18,
      "z": 6,
      "name": "Plant_Leaves_Bottle"
    },
    {
      "x": 9,
      "y": 23,
      "z": 6,
      "name": "Plant_Leaves_Bottle"
    },
    {
      "x": 9,
      "y": 24,
      "z": 6,
      "name": "Plant_Leaves_Bottle"
    },
    {
      "x": 9,
      "y": 9,
      "z": 7,
      "name": "Soil_Plant_Vine_Block"
    },
    {
      "x": 9,
      "y": 10,
      "z": 7,
      "name": "Soil_Plant_Vine_Block"
    },
    {
      "x": 9,
      "y": 11,
      "z": 7,
      "name": "Soil_Plant_Vine_Block"
    },
    {
      "x": 9,
      "y": 16,
      "z": 7,
      "name": "Vine_Branch_Corner",
      "rotation": 3
    },
    {
      "x": 9,
      "y": 17,
      "z": 7,
      "name": "Vine_Branch_Long"
    },
    {
      "x": 9,
      "y": 18,
      "z": 7,
      "name": "Vine_Branch_Long"
    },
    {
      "x": 9,
      "y": 19,
      "z": 7,
      "name": "Plant_Leaves_Bottle"
    },
    {
      "x": 9,
      "y": 20,
      "z": 7,
      "name": "Plant_Leaves_Bottle"
    },
    {
      "x": 9,
      "y": 26,
      "z": 7,
      "name": "Plant_Leaves_Bottle"
    },
    {
      "x": 9,
      "y": 9,
      "z": 8,
      "name": "Soil_Plant_Vine_Block"
    },
    {
      "x": 9,
      "y": 10,
      "z": 8,
      "name": "Soil_Plant_Vine_Block"
    },
    {
      "x": 9,
      "y": 11,
      "z": 8,
      "name": "Soil_Plant_Vine_Block"
    },
    {
      "x": 9,
      "y": 12,
      "z": 8,
      "name": "Soil_Plant_Vine_Block"
    },
    {
      "x": 9,
      "y": 19,
      "z": 8,
      "name": "Plant_Leaves_Bottle"
    },
    {
      "x": 9,
      "y": 20,
      "z": 8,
      "name": "Plant_Leaves_Bottle"
    },
    {
      "x": 9,
      "y": 26,
      "z": 8,
      "name": "Plant_Leaves_Bottle"
    },
    {
      "x": 9,
      "y": 27,
      "z": 8,
      "name": "Plant_Leaves_Bottle"
    },
    {
      "x": 9,
      "y": 27,
      "z": 9,
      "name": "Plant_Leaves_Bottle"
    },
    {
      "x": 9,
      "y": 28,
      "z": 9,
      "name": "Plant_Leaves_Bottle"
    },
    {
      "x": 9,
      "y": 27,
      "z": 10,
      "name": "Plant_Leaves_Bottle"
    },
    {
      "x": 9,
      "y": 28,
      "z": 10,
      "name": "Plant_Leaves_Bottle"
    },
    {
      "x": 9,
      "y": 26,
      "z": 11,
      "name": "Plant_Leaves_Bottle"
    },
    {
      "x": 9,
      "y": 27,
      "z": 11,
      "name": "Plant_Leaves_Bottle"
    },
    {
      "x": 10,
      "y": 23,
      "z": 3,
      "name": "Plant_Leaves_Bottle"
    },
    {
      "x": 10,
      "y": 24,
      "z": 3,
      "name": "Plant_Leaves_Bottle"
    },
    {
      "x": 10,
      "y": 25,
      "z": 4,
      "name": "Plant_Leaves_Bottle"
    },
    {
      "x": 10,
      "y": 26,
      "z": 4,
      "name": "Plant_Leaves_Bottle"
    },
    {
      "x": 10,
      "y": 25,
      "z": 5,
      "name": "Plant_Leaves_Bottle"
    },
    {
      "x": 10,
      "y": 26,
      "z": 5,
      "name": "Plant_Leaves_Bottle"
    },
    {
      "x": 10,
      "y": 18,
      "z": 6,
      "name": "Plant_Leaves_Bottle"
    },
    {
      "x": 10,
      "y": 19,
      "z": 6,
      "name": "Plant_Leaves_Bottle"
    },
    {
      "x": 10,
      "y": 25,
      "z": 6,
      "name": "Plant_Leaves_Bottle"
    },
    {
      "x": 10,
      "y": 9,
      "z": 7,
      "name": "Soil_Plant_Vine_Block"
    },
    {
      "x": 10,
      "y": 10,
      "z": 7,
      "name": "Soil_Plant_Vine_Block"
    },
    {
      "x": 10,
      "y": 11,
      "z": 7,
      "name": "Soil_Plant_Vine_Block"
    },
    {
      "x": 10,
      "y": 12,
      "z": 7,
      "name": "Soil_Plant_Vine_Block"
    },
    {
      "x": 10,
      "y": 13,
      "z": 7,
      "name": "Soil_Plant_Vine_Block"
    },
    {
      "x": 10,
      "y": 14,
      "z": 7,
      "name": "Soil_Plant_Vine_Block"
    },
    {
      "x": 10,
      "y": 15,
      "z": 7,
      "name": "Soil_Plant_Vine_Block"
    },
    {
      "x": 10,
      "y": 16,
      "z": 7,
      "name": "Soil_Plant_Vine_Block"
    },
    {
      "x": 10,
      "y": 17,
      "z": 7,
      "name": "Soil_Plant_Vine_Block"
    },
    {
      "x": 10,
      "y": 18,
      "z": 7,
      "name": "Soil_Plant_Vine_Block"
    },
    {
      "x": 10,
      "y": 26,
      "z": 7,
      "name": "Plant_Leaves_Bottle"
    },
    {
      "x": 10,
      "y": 27,
      "z": 7,
      "name": "Plant_Leaves_Bottle"
    },
    {
      "x": 10,
      "y": 18,
      "z": 8,
      "name": "Soil_Plant_Vine_Block"
    },
    {
      "x": 10,
      "y": 19,
      "z": 8,
      "name": "Soil_Plant_Vine_Block"
    },
    {
      "x": 10,
      "y": 20,
      "z": 8,
      "name": "Soil_Plant_Vine_Block"
    },
    {
      "x": 10,
      "y": 21,
      "z": 8,
      "name": "Soil_Plant_Vine_Block"
    },
    {
      "x": 10,
      "y": 22,
      "z": 8,
      "name": "Soil_Plant_Vine_Block"
    },
    {
      "x": 10,
      "y": 28,
      "z": 8,
      "name": "Plant_Leaves_Bottle"
    },
    {
      "x": 10,
      "y": 21,
      "z": 9,
      "name": "Soil_Plant_Vine_Block"
    },
    {
      "x": 10,
      "y": 22,
      "z": 9,
      "name": "Soil_Plant_Vine_Block"
    },
    {
      "x": 10,
      "y": 23,
      "z": 9,
      "name": "Soil_Plant_Vine_Block"
    },
    {
      "x": 10,
      "y": 24,
      "z": 9,
      "name": "Soil_Plant_Vine_Block"
    },
    {
      "x": 10,
      "y": 25,
      "z": 9,
      "name": "Soil_Plant_Vine_Block"
    },
    {
      "x": 10,
      "y": 26,
      "z": 9,
      "name": "Vine_Branch_Long"
    },
    {
      "x": 10,
      "y": 27,
      "z": 9,
      "name": "Plant_Leaves_Bottle"
    },
    {
      "x": 10,
      "y": 28,
      "z": 9,
      "name": "Plant_Leaves_Bottle"
    },
    {
      "x": 10,
      "y": 24,
      "z": 10,
      "name": "Vine_Branch_Corner"
    },
    {
      "x": 10,
      "y": 25,
      "z": 10,
      "name": "Vine_Branch_Long"
    },
    {
      "x": 10,
      "y": 26,
      "z": 10,
      "name": "Vine_Branch_Long"
    },
    {
      "x": 10,
      "y": 27,
      "z": 10,
      "name": "Vine_Branch_Long"
    },
    {
      "x": 10,
      "y": 28,
      "z": 10,
      "name": "Plant_Leaves_Bottle"
    },
    {
      "x": 10,
      "y": 27,
      "z": 11,
      "name": "Plant_Leaves_Bottle"
    },
    {
      "x": 10,
      "y": 28,
      "z": 11,
      "name": "Plant_Leaves_Bottle"
    },
    {
      "x": 10,
      "y": 26,
      "z": 12,
      "name": "Plant_Leaves_Bottle"
    },
    {
      "x": 10,
      "y": 27,
      "z": 12,
      "name": "Plant_Leaves_Bottle"
    },
    {
      "x": 11,
      "y": 22,
      "z": 2,
      "name": "Plant_Leaves_Bottle"
    },
    {
      "x": 11,
      "y": 23,
      "z": 2,
      "name": "Plant_Leaves_Bottle"
    },
    {
      "x": 11,
      "y": 24,
      "z": 2,
      "name": "Plant_Leaves_Bottle"
    },
    {
      "x": 11,
      "y": 24,
      "z": 3,
      "name": "Plant_Leaves_Bottle"
    },
    {
      "x": 11,
      "y": 25,
      "z": 3,
      "name": "Plant_Leaves_Bottle"
    },
    {
      "x": 11,
      "y": 26,
      "z": 3,
      "name": "Plant_Leaves_Bottle"
    },
    {
      "x": 11,
      "y": 23,
      "z": 4,
      "name": "Vine_Branch_Corner",
      "rotation": 2
    },
    {
      "x": 11,
      "y": 24,
      "z": 4,
      "name": "Vine_Branch_Long"
    },
    {
      "x": 11,
      "y": 25,
      "z": 4,
      "name": "Vine_Branch_Long"
    },
    {
      "x": 11,
      "y": 26,
      "z": 4,
      "name": "Plant_Leaves_Bottle"
    },
    {
      "x": 11,
      "y": 20,
      "z": 5,
      "name": "Soil_Plant_Vine_Block"
    },
    {
      "x": 11,
      "y": 21,
      "z": 5,
      "name": "Soil_Plant_Vine_Block"
    },
    {
      "x": 11,
      "y": 22,
      "z": 5,
      "name": "Soil_Plant_Vine_Block"
    },
    {
      "x": 11,
      "y": 23,
      "z": 5,
      "name": "Soil_Plant_Vine_Block"
    },
    {
      "x": 11,
      "y": 24,
      "z": 5,
      "name": "Vine_Branch_Long"
    },
    {
      "x": 11,
      "y": 25,
      "z": 5,
      "name": "Vine_Branch_Long"
    },
    {
      "x": 11,
      "y": 26,
      "z": 5,
      "name": "Plant_Leaves_Bottle"
    },
    {
      "x": 11,
      "y": 18,
      "z": 6,
      "name": "Soil_Plant_Vine_Block"
    },
    {
      "x": 11,
      "y": 19,
      "z": 6,
      "name": "Soil_Plant_Vine_Block"
    },
    {
      "x": 11,
      "y": 20,
      "z": 6,
      "name": "Soil_Plant_Vine_Block"
    },
    {
      "x": 11,
      "y": 21,
      "z": 6,
      "name": "Vine_Branch_Long"
    },
    {
      "x": 11,
      "y": 22,
      "z": 6,
      "name": "Vine_Branch_Long"
    },
    {
      "x": 11,
      "y": 23,
      "z": 6,
      "name": "Vine_Branch_Long"
    },
    {
      "x": 11,
      "y": 24,
      "z": 6,
      "name": "Vine_Branch_Long"
    },
    {
      "x": 11,
      "y": 25,
      "z": 6,
      "name": "Plant_Leaves_Bottle"
    },
    {
      "x": 11,
      "y": 26,
      "z": 6,
      "name": "Plant_Leaves_Bottle"
    },
    {
      "x": 11,
      "y": 14,
      "z": 7,
      "name": "Vine_Branch_Corner",
      "rotation": 1
    },
    {
      "x": 11,
      "y": 15,
      "z": 7,
      "name": "Vine_Branch_Long"
    },
    {
      "x": 11,
      "y": 17,
      "z": 7,
      "name": "Soil_Plant_Vine_Block"
    },
    {
      "x": 11,
      "y": 18,
      "z": 7,
      "name": "Soil_Plant_Vine_Block"
    },
    {
      "x": 11,
      "y": 24,
      "z": 7,
      "name": "Plant_Leaves_Bottle"
    },
    {
      "x": 11,
      "y": 25,
      "z": 7,
      "name": "Plant_Leaves_Bottle"
    },
    {
      "x": 11,
      "y": 26,
      "z": 7,
      "name": "Plant_Leaves_Bottle"
    },
    {
      "x": 11,
      "y": 27,
      "z": 7,
      "name": "Plant_Leaves_Bottle"
    },
    {
      "x": 11,
      "y": 27,
      "z": 8,
      "name": "Plant_Leaves_Bottle"
    },
    {
      "x": 11,
      "y": 28,
      "z": 8,
      "name": "Plant_Leaves_Bottle"
    },
    {
      "x": 11,
      "y": 28,
      "z": 9,
      "name": "Plant_Leaves_Bottle"
    },
    {
      "x": 11,
      "y": 28,
      "z": 10,
      "name": "Plant_Leaves_Bottle"
    },
    {
      "x": 11,
      "y": 26,
      "z": 11,
      "name": "Plant_Leaves_Bottle"
    },
    {
      "x": 11,
      "y": 27,
      "z": 11,
      "name": "Plant_Leaves_Bottle"
    },
    {
      "x": 11,
      "y": 26,
      "z": 12,
      "name": "Plant_Leaves_Bottle"
    },
    {
      "x": 12,
      "y": 22,
      "z": 2,
      "name": "Plant_Leaves_Bottle"
    },
    {
      "x": 12,
      "y": 23,
      "z": 2,
      "name": "Plant_Leaves_Bottle"
    },
    {
      "x": 12,
      "y": 24,
      "z": 2,
      "name": "Plant_Leaves_Bottle"
    },
    {
      "x": 12,
      "y": 24,
      "z": 3,
      "name": "Plant_Leaves_Bottle"
    },
    {
      "x": 12,
      "y": 24,
      "z": 4,
      "name": "Plant_Leaves_Bottle"
    },
    {
      "x": 12,
      "y": 25,
      "z": 4,
      "name": "Plant_Leaves_Bottle"
    },
    {
      "x": 12,
      "y": 24,
      "z": 5,
      "name": "Plant_Leaves_Bottle"
    },
    {
      "x": 12,
      "y": 25,
      "z": 5,
      "name": "Plant_Leaves_Bottle"
    },
    {
      "x": 12,
      "y": 26,
      "z": 5,
      "name": "Plant_Leaves_Bottle"
    },
    {
      "x": 12,
      "y": 25,
      "z": 6,
      "name": "Plant_Leaves_Bottle"
    },
    {
      "x": 12,
      "y": 24,
      "z": 7,
      "name": "Plant_Leaves_Bottle"
    },
    {
      "x": 12,
      "y": 26,
      "z": 8,
      "name": "Plant_Leaves_Bottle"
    },
    {
      "x": 12,
      "y": 27,
      "z": 8,
      "name": "Plant_Leaves_Bottle"
    },
    {
      "x": 12,
      "y": 27,
      "z": 9,
      "name": "Plant_Leaves_Bottle"
    },
    {
      "x": 12,
      "y": 27,
      "z": 10,
      "name": "Plant_Leaves_Bottle"
    },
    {
      "x": 12,
      "y": 26,
      "z": 11,
      "name": "Plant_Leaves_Bottle"
    },
    {
      "x": 13,
      "y": 23,
      "z": 2,
      "name": "Plant_Leaves_Bottle"
    },
    {
      "x": 13,
      "y": 23,
      "z": 3,
      "name": "Plant_Leaves_Bottle"
    },
    {
      "x": 13,
      "y": 24,
      "z": 3,
      "name": "Plant_Leaves_Bottle"
    },
    {
      "x": 13,
      "y": 23,
      "z": 4,
      "name": "Plant_Leaves_Bottle"
    },
    {
      "x": 13,
      "y": 24,
      "z": 4,
      "name": "Plant_Leaves_Bottle"
    },
    {
      "x": 13,
      "y": 23,
      "z": 5,
      "name": "Plant_Leaves_Bottle"
    },
    {
      "x": 13,
      "y": 24,
      "z": 5,
      "name": "Plant_Leaves_Bottle"
    },
    {
      "x": 13,
      "y": 25,
      "z": 5,
      "name": "Plant_Leaves_Bottle"
    },
    {
      "x": 13,
      "y": 24,
      "z": 6,
      "name": "Plant_Leaves_Bottle"
    },
    {
      "x": 14,
      "y": 23,
      "z": 3,
      "name": "Plant_Leaves_Bottle"
    },
    {
      "x": 14,
      "y": 23,
      "z": 4,
      "name": "Plant_Leaves_Bottle"
    },
    {
      "x": 14,
      "y": 24,
      "z": 4,
      "name": "Plant_Leaves_Bottle"
    },
    {
      "x": 14,
      "y": 23,
      "z": 5,
      "name": "Plant_Leaves_Bottle"
    }
  ]
}