{
  "version": 8,
  "blockIdVersion": 11,
  "anchorX": 6,
  "anchorY": 10,
  "anchorZ": 11,
  "blocks": [
    {
      "x": 5,
      "y": 22,
      "z": 5,
      "name": "Plant_Leaves_Bottle"
    },
    {
      "x": 5,
      "y": 21,
      "z": 6,
      "name": "Plant_Leaves_Bottle"
    },
    {
      "x": 5,
      "y": 22,
      "z": 6,
      "name": "Plant_Leaves_Bottle"
    },
    {
      "x": 5,
      "y": 23,
      "z": 6,
      "name": "Plant_Leaves_Bottle"
    },
    {
      "x": 5,
      "y": 21,
      "z": 7,
      "name": "Plant_Leaves_Bottle"
    },
    {
      "x": 5,
      "y": 22,
      "z": 7,
      "name": "Plant_Leaves_Bottle"
    },
    {
      "x": 5,
      "y": 23,
      "z": 7,
      "name": "Plant_Leaves_Bottle"
    },
    {
      "x": 5,
      "y": 21,
      "z": 8,
      "name": "Plant_Leaves_Bottle"
    },
    {
      "x": 5,
      "y": 22,
      "z": 8,
      "name": "Plant_Leaves_Bottle"
    },
    {
      "x": 5,
      "y": 22,
      "z": 9,
      "name": "Plant_Leaves_Bottle"
    },
    {
      "x": 5,
      "y": 17,
      "z": 12,
      "name": "Plant_Leaves_Bottle"
    },
    {
      "x": 5,
      "y": 18,
      "z": 12,
      "name": "Plant_Leaves_Bottle"
    },
    {
      "x": 5,
      "y": 17,
      "z": 13,
      "name": "Plant_Leaves_Bottle"
    },
    {
      "x": 6,
      "y": 21,
      "z": 4,
      "name": "Plant_Leaves_Bottle"
    },
    {
      "x": 6,
      "y": 22,
      "z": 4,
      "name": "Plant_Leaves_Bottle"
    },
    {
      "x": 6,
      "y": 23,
      "z": 5,
      "name": "Plant_Leaves_Bottle"
    },
    {
      "x": 6,
      "y": 23,
      "z": 6,
      "name": "Plant_Leaves_Bottle"
    },
    {
      "x": 6,
      "y": 24,
      "z": 6,
      "name": "Plant_Leaves_Bottle"
    },
    {
      "x": 6,
      "y": 23,
      "z": 7,
      "name": "Plant_Leaves_Bottle"
    },
    {
      "x": 6,
      "y": 24,
      "z": 7,
      "name": "Plant_Leaves_Bottle"
    },
    {
      "x": 6,
      "y": 23,
      "z": 8,
      "name": "Plant_Leaves_Bottle"
    },
    {
      "x": 6,
      "y": 18,
      "z": 9,
      "name": "Soil_Plant_Vine_Block"
    },
    {
      "x": 6,
      "y": 19,
      "z": 9,
      "name": "Vine_Branch_Long"
    },
    {
      "x": 6,
      "y": 20,
      "z": 9,
      "name": "Vine_Branch_Long"
    },
    {
      "x": 6,
      "y": 21,
      "z": 9,
      "name": "Plant_Leaves_Bottle"
    },
    {
      "x": 6,
      "y": 23,
      "z": 9,
      "name": "Plant_Leaves_Bottle"
    },
    {
      "x": 6,
      "y": 14,
      "z": 10,
      "name": "Soil_Plant_Vine_Block"
    },
    {
      "x": 6,
      "y": 15,
      "z": 10,
      "name": "Soil_Plant_Vine_Block"
    },
    {
      "x": 6,
      "y": 16,
      "z": 10,
      "name": "Soil_Plant_Vine_Block"
    },
    {
      "x": 6,
      "y": 17,
      "z": 10,
      "name": "Soil_Plant_Vine_Block"
    },
    {
      "x": 6,
      "y": 18,
      "z": 10,
      "name": "Soil_Plant_Vine_Block"
    },
    {
      "x": 6,
      "y": 21,
      "z": 10,
      "name": "Plant_Leaves_Bottle"
    },
    {
      "x": 6,
      "y": 22,
      "z": 10,
      "name": "Plant_Leaves_Bottle"
    },
    {
      "x": 6,
      "y": 9,
      "z": 11,
      "name": "Soil_Plant_Vine_Block"
    },
    {
      "x": 6,
      "y": 10,
      "z": 11,
      "name": "Soil_Plant_Vine_Block"
    },
    {
      "x": 6,
      "y": 11,
      "z": 11,
      "name": "Soil_Plant_Vine_Block"
    },
    {
      "x": 6,
      "y": 12,
      "z": 11,
      "name": "Soil_Plant_Vine_Block"
    },
    {
      "x": 6,
      "y": 13,
      "z": 11,
      "name": "Soil_Plant_Vine_Block"
    },
    {
      "x": 6,
      "y": 14,
      "z": 11,
      "name": "Soil_Plant_Vine_Block"
    },
    {
      "x": 6,
      "y": 15,
      "z": 11,
      "name": "Soil_Plant_Vine_Block"
    },
    {
      "x": 6,
      "y": 17,
      "z": 11,
      "name": "Plant_Leaves_Bottle"
    },
    {
      "x": 6,
      "y": 18,
      "z": 11,
      "name": "Plant_Leaves_Bottle"
    },
    {
      "x": 6,
      "y": 20,
      "z": 11,
      "name": "Plant_Leaves_Bottle"
    },
    {
      "x": 6,
      "y": 21,
      "z": 11,
      "name": "Plant_Leaves_Bottle"
    },
    {
      "x": 6,
      "y": 15,
      "z": 12,
      "name": "Vine_Branch_Corner"
    },
    {
      "x": 6,
      "y": 16,
      "z": 12,
      "name": "Vine_Branch_Long"
    },
    {
      "x": 6,
      "y": 17,
      "z": 12,
      "name": "Vine_Branch_Long"
    },
    {
      "x": 6,
      "y": 18,
      "z": 12,
      "name": "Plant_Leaves_Bottle"
    },
    {
      "x": 6,
      "y": 20,
      "z": 12,
      "name": "Plant_Leaves_Bottle"
    },
    {
      "x": 6,
      "y": 16,
      "z": 13,
      "name": "Plant_Leaves_Bottle"
    },
    {
      "x": 6,
      "y": 17,
      "z": 13,
      "name": "Plant_Leaves_Bottle"
    },
    {
      "x": 6,
      "y": 18,
      "z": 13,
      "name": "Plant_Leaves_Bottle"
    },
    {
      "x": 7,
      "y": 21,
      "z": 3,
      "name": "Plant_Leaves_Bottle"
    },
    {
      "x": 7,
      "y": 22,
      "z": 3,
      "name": "Plant_Leaves_Bottle"
    },
    {
      "x": 7,
      "y": 20,
      "z": 4,
      "name": "Plant_Leaves_Bottle"
    },
    {
      "x": 7,
      "y": 21,
      "z": 4,
      "name": "Plant_Leaves_Bottle"
    },
    {
      "x": 7,
      "y": 22,
      "z": 4,
      "name": "Plant_Leaves_Bottle"
    },
    {
      "x": 7,
      "y": 23,
      "z": 4,
      "name": "Plant_Leaves_Bottle"
    },
    {
      "x": 7,
      "y": 23,
      "z": 5,
      "name": "Plant_Leaves_Bottle"
    },
    {
      "x": 7,
      "y": 24,
      "z": 5,
      "name": "Plant_Leaves_Bottle"
    },
    {
      "x": 7,
      "y": 20,
      "z": 6,
      "name": "Soil_Plant_Vine_Block"
    },
    {
      "x": 7,
      "y": 21,
      "z": 6,
      "name": "Soil_Plant_Vine_Block"
    },
    {
      "x": 7,
      "y": 22,
      "z": 6,
      "name": "Vine_Branch_Long"
    },
    {
      "x": 7,
      "y": 23,
      "z": 6,
      "name": "Vine_Branch_Long"
    },
    {
      "x": 7,
      "y": 24,
      "z": 6,
      "name": "Plant_Leaves_Bottle"
    },
    {
      "x": 7,
      "y": 19,
      "z": 7,
      "name": "Soil_Plant_Vine_Block"
    },
    {
      "x": 7,
      "y": 20,
      "z": 7,
      "name": "Soil_Plant_Vine_Block"
    },
    {
      "x": 7,
      "y": 23,
      "z": 7,
      "name": "Plant_Leaves_Bottle"
    },
    {
      "x": 7,
      "y": 24,
      "z": 7,
      "name": "Plant_Leaves_Bottle"
    },
    {
      "x": 7,
      "y": 19,
      "z": 8,
      "name": "Soil_Plant_Vine_Block"
    },
    {
      "x": 7,
      "y": 23,
      "z": 8,
      "name": "Plant_Leaves_Bottle"
    },
    {
      "x": 7,
      "y": 18,
      "z": 9,
      "name": "Soil_Plant_Vine_Block"
    },
    {
      "x": 7,
      "y": 19,
      "z": 9,
      "name": "Soil_Plant_Vine_Block"
    },
    {
      "x": 7,
      "y": 22,
      "z": 9,
      "name": "Plant_Leaves_Bottle"
    },
    {
      "x": 7,
      "y": 23,
      "z": 9,
      "name": "Plant_Leaves_Bottle"
    },
    {
      "x": 7,
      "y": 19,
      "z": 10,
      "name": "Vine_Branch_Corner"
    },
    {
      "x": 7,
      "y": 20,
      "z": 10,
      "name": "Vine_Branch_Long"
    },
    {
      "x": 7,
      "y": 21,
      "z": 10,
      "name": "Vine_Branch_Long"
    },
    {
      "x": 7,
      "y": 22,
      "z": 10,
      "name": "Plant_Leaves_Bottle"
    },
    {
      "x": 7,
      "y": 23,
      "z": 10,
      "name": "Plant_Leaves_Bottle"
    },
    {
      "x": 7,
      "y": 17,
      "z": 11,
      "name": "Plant_Leaves_Bottle"
    },
    {
      "x": 7,
      "y": 20,
      "z": 11,
      "name": "Plant_Leaves_Bottle"
    },
    {
      "x": 7,
      "y": 21,
      "z": 11,
      "name": "Plant_Leaves_Bottle"
    },
    {
      "x": 7,
      "y": 22,
      "z": 11,
      "name": "Plant_Leaves_Bottle"
    },
    {
      "x": 7,
      "y": 17,
      "z": 12,
      "name": "Plant_Leaves_Bottle"
    },
    {
      "x": 7,
      "y": 18,
      "z": 12,
      "name": "Plant_Leaves_Bottle"
    },
    {
      "x": 7,
      "y": 20,
      "z": 12,
      "name": "Plant_Leaves_Bottle"
    },
    {
      "x": 7,
      "y": 21,
      "z": 12,
      "name": "Plant_Leaves_Bottle"
    },
    {
      "x": 7,
      "y": 16,
      "z": 13,
      "name": "Plant_Leaves_Bottle"
    },
    {
      "x": 7,
      "y": 17,
      "z": 13,
      "name": "Plant_Leaves_Bottle"
    },
    {
      "x": 8,
      "y": 21,
      "z": 4,
      "name": "Plant_Leaves_Bottle"
    },
    {
      "x": 8,
      "y": 22,
      "z": 4,
      "name": "Plant_Leaves_Bottle"
    },
    {
      "x": 8,
      "y": 22,
      "z": 5,
      "name": "Plant_Leaves_Bottle"
    },
    {
      "x": 8,
      "y": 23,
      "z": 5,
      "name": "Plant_Leaves_Bottle"
    },
    {
      "x": 8,
      "y": 22,
      "z": 6,
      "name": "Plant_Leaves_Bottle"
    },
    {
      "x": 8,
      "y": 23,
      "z": 6,
      "name": "Plant_Leaves_Bottle"
    },
    {
      "x": 8,
      "y": 24,
      "z": 6,
      "name": "Plant_Leaves_Bottle"
    },
    {
      "x": 8,
      "y": 23,
      "z": 7,
      "name": "Plant_Leaves_Bottle"
    },
    {
      "x": 8,
      "y": 24,
      "z": 7,
      "name": "Plant_Leaves_Bottle"
    },
    {
      "x": 8,
      "y": 19,
      "z": 8,
      "name": "Vine_Branch_Corner",
      "rotation": 1
    },
    {
      "x": 8,
      "y": 20,
      "z": 8,
      "name": "Vine_Branch_Long"
    },
    {
      "x": 8,
      "y": 21,
      "z": 8,
      "name": "Vine_Branch_Long"
    },
    {
      "x": 8,
      "y": 22,
      "z": 8,
      "name": "Vine_Branch_Long"
    },
    {
      "x": 8,
      "y": 23,
      "z": 8,
      "name": "Plant_Leaves_Bottle"
    },
    {
      "x": 8,
      "y": 22,
      "z": 9,
      "name": "Plant_Leaves_Bottle"
    },
    {
      "x": 8,
      "y": 20,
      "z": 10,
      "name": "Plant_Leaves_Bottle"
    },
    {
      "x": 8,
      "y": 21,
      "z": 10,
      "name": "Plant_Leaves_Bottle"
    },
    {
      "x": 8,
      "y": 22,
      "z": 10,
      "name": "Plant_Leaves_Bottle"
    },
    {
      "x": 8,
      "y": 20,
      "z": 11,
      "name": "Plant_Leaves_Bottle"
    },
    {
      "x": 9,
      "y": 22,
      "z": 4,
      "name": "Plant_Leaves_Bottle"
    },
    {
      "x": 9,
      "y": 21,
      "z": 5,
      "name": "Plant_Leaves_Bottle"
    },
    {
      "x": 9,
      "y": 22,
      "z": 5,
      "name": "Plant_Leaves_Bottle"
    },
    {
      "x": 9,
      "y": 23,
      "z": 5,
      "name": "Plant_Leaves_Bottle"
    },
    {
      "x": 9,
      "y": 21,
      "z": 6,
      "name": "Plant_Leaves_Bottle"
    },
    {
      "x": 9,
      "y": 22,
      "z": 6,
      "name": "Plant_Leaves_Bottle"
    },
    {
      "x": 9,
      "y": 23,
      "z": 6,
      "name": "Plant_Leaves_Bottle"
    },
    {
      "x": 9,
      "y": 21,
      "z": 7,
      "name": "Plant_Leaves_Bottle"
    },
    {
      "x": 9,
      "y": 22,
      "z": 7,
      "name": "Plant_Leaves_Bottle"
    },
    {
      "x": 9,
      "y": 23,
      "z": 7,
      "name": "Plant_Leaves_Bottle"
    },
    {
      "x": 9,
      "y": 21,
      "z": 8,
      "name": "Plant_Leaves_Bottle"
    },
    {
      "x": 9,
      "y": 22,
      "z": 8,
      "name": "Plant_Leaves_Bottle"
    },
    {
      "x": 9,
      "y": 20,
      "z": 9,
      "name": "Plant_Leaves_Bottle"
    },
    {
      "x": 9,
      "y": 21,
      "z": 9,
      "name": "Plant_Leaves_Bottle"
    },
    {
      "x": 9,
      "y": 22,
      "z": 9,
      "name": "Plant_Leaves_Bottle"
    }
  ]
}