{
  "version": 8,
  "blockIdVersion": 11,
  "anchorX": 9,
  "anchorY": 10,
  "anchorZ": 6,
  "blocks": [
    {
      "x": 3,
      "y": 23,
      "z": 4,
      "name": "Plant_Leaves_Bottle"
    },
    {
      "x": 3,
      "y": 22,
      "z": 5,
      "name": "Plant_Leaves_Bottle"
    },
    {
      "x": 3,
      "y": 23,
      "z": 5,
      "name": "Plant_Leaves_Bottle"
    },
    {
      "x": 3,
      "y": 24,
      "z": 5,
      "name": "Plant_Leaves_Bottle"
    },
    {
      "x": 3,
      "y": 22,
      "z": 6,
      "name": "Plant_Leaves_Bottle"
    },
    {
      "x": 3,
      "y": 23,
      "z": 6,
      "name": "Plant_Leaves_Bottle"
    },
    {
      "x": 3,
      "y": 24,
      "z": 6,
      "name": "Plant_Leaves_Bottle"
    },
    {
      "x": 4,
      "y": 23,
      "z": 3,
      "name": "Plant_Leaves_Bottle"
    },
    {
      "x": 4,
      "y": 23,
      "z": 4,
      "name": "Plant_Leaves_Bottle"
    },
    {
      "x": 4,
      "y": 24,
      "z": 4,
      "name": "Plant_Leaves_Bottle"
    },
    {
      "x": 4,
      "y": 24,
      "z": 5,
      "name": "Plant_Leaves_Bottle"
    },
    {
      "x": 4,
      "y": 24,
      "z": 6,
      "name": "Plant_Leaves_Bottle"
    },
    {
      "x": 4,
      "y": 25,
      "z": 6,
      "name": "Plant_Leaves_Bottle"
    },
    {
      "x": 4,
      "y": 26,
      "z": 6,
      "name": "Plant_Leaves_Bottle"
    },
    {
      "x": 4,
      "y": 23,
      "z": 7,
      "name": "Plant_Leaves_Bottle"
    },
    {
      "x": 4,
      "y": 24,
      "z": 7,
      "name": "Plant_Leaves_Bottle"
    },
    {
      "x": 5,
      "y": 23,
      "z": 3,
      "name": "Plant_Leaves_Bottle"
    },
    {
      "x": 5,
      "y": 24,
      "z": 3,
      "name": "Plant_Leaves_Bottle"
    },
    {
      "x": 5,
      "y": 23,
      "z": 4,
      "name": "Plant_Leaves_Bottle"
    },
    {
      "x": 5,
      "y": 24,
      "z": 4,
      "name": "Plant_Leaves_Bottle"
    },
    {
      "x": 5,
      "y": 24,
      "z": 5,
      "name": "Plant_Leaves_Bottle"
    },
    {
      "x": 5,
      "y": 25,
      "z": 5,
      "name": "Plant_Leaves_Bottle"
    },
    {
      "x": 5,
      "y": 23,
      "z": 6,
      "name": "Vine_Branch_Corner",
      "rotation": 3
    },
    {
      "x": 5,
      "y": 24,
      "z": 6,
      "name": "Vine_Branch_Long"
    },
    {
      "x": 5,
      "y": 25,
      "z": 6,
      "name": "Vine_Branch_Long"
    },
    {
      "x": 5,
      "y": 26,
      "z": 6,
      "name": "Plant_Leaves_Bottle"
    },
    {
      "x": 5,
      "y": 25,
      "z": 7,
      "name": "Plant_Leaves_Bottle"
    },
    {
      "x": 5,
      "y": 26,
      "z": 7,
      "name": "Plant_Leaves_Bottle"
    },
    {
      "x": 5,
      "y": 24,
      "z": 8,
      "name": "Plant_Leaves_Bottle"
    },
    {
      "x": 6,
      "y": 23,
      "z": 3,
      "name": "Plant_Leaves_Bottle"
    },
    {
      "x": 6,
      "y": 23,
      "z": 4,
      "name": "Plant_Leaves_Bottle"
    },
    {
      "x": 6,
      "y": 24,
      "z": 4,
      "name": "Plant_Leaves_Bottle"
    },
    {
      "x": 6,
      "y": 25,
      "z": 4,
      "name": "Plant_Leaves_Bottle"
    },
    {
      "x": 6,
      "y": 24,
      "z": 5,
      "name": "Plant_Leaves_Bottle"
    },
    {
      "x": 6,
      "y": 25,
      "z": 5,
      "name": "Plant_Leaves_Bottle"
    },
    {
      "x": 6,
      "y": 26,
      "z": 5,
      "name": "Plant_Leaves_Bottle"
    },
    {
      "x": 6,
      "y": 20,
      "z": 6,
      "name": "Soil_Plant_Vine_Block"
    },
    {
      "x": 6,
      "y": 21,
      "z": 6,
      "name": "Soil_Plant_Vine_Block"
    },
    {
      "x": 6,
      "y": 22,
      "z": 6,
      "name": "Soil_Plant_Vine_Block"
    },
    {
      "x": 6,
      "y": 23,
      "z": 6,
      "name": "Soil_Plant_Vine_Block"
    },
    {
      "x": 6,
      "y": 24,
      "z": 6,
      "name": "Vine_Branch_Long"
    },
    {
      "x": 6,
      "y": 25,
      "z": 6,
      "name": "Vine_Branch_Long"
    },
    {
      "x": 6,
      "y": 26,
      "z": 6,
      "name": "Plant_Leaves_Bottle"
    },
    {
      "x": 6,
      "y": 25,
      "z": 7,
      "name": "Plant_Leaves_Bottle"
    },
    {
      "x": 6,
      "y": 26,
      "z": 7,
      "name": "Plant_Leaves_Bottle"
    },
    {
      "x": 6,
      "y": 23,
      "z": 8,
      "name": "Plant_Leaves_Bottle"
    },
    {
      "x": 6,
      "y": 24,
      "z": 8,
      "name": "Plant_Leaves_Bottle"
    },
    {
      "x": 6,
      "y": 25,
      "z": 8,
      "name": "Plant_Leaves_Bottle"
    },
    {
      "x": 6,
      "y": 20,
      "z": 11,
      "name": "Plant_Leaves_Bottle"
    },
    {
      "x": 6,
      "y": 21,
      "z": 11,
      "name": "Plant_Leaves_Bottle"
    },
    {
      "x": 6,
      "y": 21,
      "z": 12,
      "name": "Plant_Leaves_Bottle"
    },
    {
      "x": 7,
      "y": 20,
      "z": 2,
      "name": "Plant_Leaves_Bottle"
    },
    {
      "x": 7,
      "y": 20,
      "z": 3,
      "name": "Plant_Leaves_Bottle"
    },
    {
      "x": 7,
      "y": 21,
      "z": 3,
      "name": "Plant_Leaves_Bottle"
    },
    {
      "x": 7,
      "y": 19,
      "z": 4,
      "name": "Plant_Leaves_Bottle"
    },
    {
      "x": 7,
      "y": 20,
      "z": 4,
      "name": "Plant_Leaves_Bottle"
    },
    {
      "x": 7,
      "y": 21,
      "z": 4,
      "name": "Plant_Leaves_Bottle"
    },
    {
      "x": 7,
      "y": 24,
      "z": 4,
      "name": "Plant_Leaves_Bottle"
    },
    {
      "x": 7,
      "y": 25,
      "z": 5,
      "name": "Plant_Leaves_Bottle"
    },
    {
      "x": 7,
      "y": 18,
      "z": 6,
      "name": "Soil_Plant_Vine_Block"
    },
    {
      "x": 7,
      "y": 19,
      "z": 6,
      "name": "Soil_Plant_Vine_Block"
    },
    {
      "x": 7,
      "y": 20,
      "z": 6,
      "name": "Soil_Plant_Vine_Block"
    },
    {
      "x": 7,
      "y": 21,
      "z": 6,
      "name": "Vine_Branch_Long"
    },
    {
      "x": 7,
      "y": 22,
      "z": 6,
      "name": "Vine_Branch_Long"
    },
    {
      "x": 7,
      "y": 23,
      "z": 6,
      "name": "Vine_Branch_Long"
    },
    {
      "x": 7,
      "y": 24,
      "z": 6,
      "name": "Vine_Branch_Long"
    },
    {
      "x": 7,
      "y": 25,
      "z": 6,
      "name": "Plant_Leaves_Bottle"
    },
    {
      "x": 7,
      "y": 26,
      "z": 6,
      "name": "Plant_Leaves_Bottle"
    },
    {
      "x": 7,
      "y": 25,
      "z": 7,
      "name": "Plant_Leaves_Bottle"
    },
    {
      "x": 7,
      "y": 23,
      "z": 8,
      "name": "Plant_Leaves_Bottle"
    },
    {
      "x": 7,
      "y": 24,
      "z": 8,
      "name": "Plant_Leaves_Bottle"
    },
    {
      "x": 7,
      "y": 20,
      "z": 9,
      "name": "Plant_Leaves_Bottle"
    },
    {
      "x": 7,
      "y": 20,
      "z": 10,
      "name": "Plant_Leaves_Bottle"
    },
    {
      "x": 7,
      "y": 21,
      "z": 10,
      "name": "Plant_Leaves_Bottle"
    },
    {
      "x": 7,
      "y": 22,
      "z": 11,
      "name": "Plant_Leaves_Bottle"
    },
    {
      "x": 7,
      "y": 21,
      "z": 12,
      "name": "Plant_Leaves_Bottle"
    },
    {
      "x": 7,
      "y": 22,
      "z": 12,
      "name": "Plant_Leaves_Bottle"
    },
    {
      "x": 7,
      "y": 21,
      "z": 13,
      "name": "Plant_Leaves_Bottle"
    },
    {
      "x": 8,
      "y": 20,
      "z": 1,
      "name": "Plant_Leaves_Bottle"
    },
    {
      "x": 8,
      "y": 21,
      "z": 2,
      "name": "Plant_Leaves_Bottle"
    },
    {
      "x": 8,
      "y": 22,
      "z": 3,
      "name": "Plant_Leaves_Bottle"
    },
    {
      "x": 8,
      "y": 18,
      "z": 4,
      "name": "Vine_Branch_Corner",
      "rotation": 3
    },
    {
      "x": 8,
      "y": 19,
      "z": 4,
      "name": "Vine_Branch_Long"
    },
    {
      "x": 8,
      "y": 20,
      "z": 4,
      "name": "Vine_Branch_Long"
    },
    {
      "x": 8,
      "y": 21,
      "z": 4,
      "name": "Plant_Leaves_Bottle"
    },
    {
      "x": 8,
      "y": 22,
      "z": 4,
      "name": "Plant_Leaves_Bottle"
    },
    {
      "x": 8,
      "y": 20,
      "z": 5,
      "name": "Plant_Leaves_Bottle"
    },
    {
      "x": 8,
      "y": 21,
      "z": 5,
      "name": "Plant_Leaves_Bottle"
    },
    {
      "x": 8,
      "y": 24,
      "z": 5,
      "name": "Plant_Leaves_Bottle"
    },
    {
      "x": 8,
      "y": 17,
      "z": 6,
      "name": "Soil_Plant_Vine_Block"
    },
    {
      "x": 8,
      "y": 18,
      "z": 6,
      "name": "Soil_Plant_Vine_Block"
    },
    {
      "x": 8,
      "y": 24,
      "z": 6,
      "name": "Plant_Leaves_Bottle"
    },
    {
      "x": 8,
      "y": 25,
      "z": 6,
      "name": "Plant_Leaves_Bottle"
    },
    {
      "x": 8,
      "y": 16,
      "z": 7,
      "name": "Soil_Plant_Vine_Block"
    },
    {
      "x": 8,
      "y": 20,
      "z": 7,
      "name": "Plant_Leaves_Bottle"
    },
    {
      "x": 8,
      "y": 21,
      "z": 7,
      "name": "Plant_Leaves_Bottle"
    },
    {
      "x": 8,
      "y": 22,
      "z": 7,
      "name": "Plant_Leaves_Bottle"
    },
    {
      "x": 8,
      "y": 16,
      "z": 8,
      "name": "Soil_Plant_Vine_Block"
    },
    {
      "x": 8,
      "y": 17,
      "z": 8,
      "name": "Soil_Plant_Vine_Block"
    },
    {
      "x": 8,
      "y": 20,
      "z": 8,
      "name": "Plant_Leaves_Bottle"
    },
    {
      "x": 8,
      "y": 21,
      "z": 8,
      "name": "Plant_Leaves_Bottle"
    },
    {
      "x": 8,
      "y": 17,
      "z": 9,
      "name": "Soil_Plant_Vine_Block"
    },
    {
      "x": 8,
      "y": 18,
      "z": 9,
      "name": "Soil_Plant_Vine_Block"
    },
    {
      "x": 8,
      "y": 20,
      "z": 9,
      "name": "Plant_Leaves_Bottle"
    },
    {
      "x": 8,
      "y": 21,
      "z": 9,
      "name": "Plant_Leaves_Bottle"
    },
    {
      "x": 8,
      "y": 18,
      "z": 10,
      "name": "Soil_Plant_Vine_Block"
    },
    {
      "x": 8,
      "y": 21,
      "z": 10,
      "name": "Plant_Leaves_Bottle"
    },
    {
      "x": 8,
      "y": 22,
      "z": 10,
      "name": "Plant_Leaves_Bottle"
    },
    {
      "x": 8,
      "y": 18,
      "z": 11,
      "name": "Soil_Plant_Vine_Block"
    },
    {
      "x": 8,
      "y": 19,
      "z": 11,
      "name": "Soil_Plant_Vine_Block"
    },
    {
      "x": 8,
      "y": 20,
      "z": 11,
      "name": "Vine_Branch_Long"
    },
    {
      "x": 8,
      "y": 21,
      "z": 11,
      "name": "Vine_Branch_Long"
    },
    {
      "x": 8,
      "y": 22,
      "z": 11,
      "name": "Plant_Leaves_Bottle"
    },
    {
      "x": 8,
      "y": 21,
      "z": 12,
      "name": "Plant_Leaves_Bottle"
    },
    {
      "x": 8,
      "y": 22,
      "z": 12,
      "name": "Plant_Leaves_Bottle"
    },
    {
      "x": 8,
      "y": 20,
      "z": 13,
      "name": "Plant_Leaves_Bottle"
    },
    {
      "x": 8,
      "y": 21,
      "z": 13,
      "name": "Plant_Leaves_Bottle"
    },
    {
      "x": 9,
      "y": 20,
      "z": 1,
      "name": "Plant_Leaves_Bottle"
    },
    {
      "x": 9,
      "y": 21,
      "z": 1,
      "name": "Plant_Leaves_Bottle"
    },
    {
      "x": 9,
      "y": 21,
      "z": 2,
      "name": "Plant_Leaves_Bottle"
    },
    {
      "x": 9,
      "y": 22,
      "z": 2,
      "name": "Plant_Leaves_Bottle"
    },
    {
      "x": 9,
      "y": 18,
      "z": 3,
      "name": "Soil_Plant_Vine_Block"
    },
    {
      "x": 9,
      "y": 19,
      "z": 3,
      "name": "Soil_Plant_Vine_Block"
    },
    {
      "x": 9,
      "y": 20,
      "z": 3,
      "name": "Vine_Branch_Long"
    },
    {
      "x": 9,
      "y": 21,
      "z": 3,
      "name": "Vine_Branch_Long"
    },
    {
      "x": 9,
      "y": 22,
      "z": 3,
      "name": "Plant_Leaves_Bottle"
    },
    {
      "x": 9,
      "y": 18,
      "z": 4,
      "name": "Soil_Plant_Vine_Block"
    },
    {
      "x": 9,
      "y": 21,
      "z": 4,
      "name": "Plant_Leaves_Bottle"
    },
    {
      "x": 9,
      "y": 22,
      "z": 4,
      "name": "Plant_Leaves_Bottle"
    },
    {
      "x": 9,
      "y": 14,
      "z": 5,
      "name": "Vine_Branch_Corner",
      "rotation": 2
    },
    {
      "x": 9,
      "y": 17,
      "z": 5,
      "name": "Soil_Plant_Vine_Block"
    },
    {
      "x": 9,
      "y": 18,
      "z": 5,
      "name": "Soil_Plant_Vine_Block"
    },
    {
      "x": 9,
      "y": 20,
      "z": 5,
      "name": "Plant_Leaves_Bottle"
    },
    {
      "x": 9,
      "y": 21,
      "z": 5,
      "name": "Plant_Leaves_Bottle"
    },
    {
      "x": 9,
      "y": 9,
      "z": 6,
      "name": "Soil_Plant_Vine_Block"
    },
    {
      "x": 9,
      "y": 10,
      "z": 6,
      "name": "Soil_Plant_Vine_Block"
    },
    {
      "x": 9,
      "y": 11,
      "z": 6,
      "name": "Soil_Plant_Vine_Block"
    },
    {
      "x": 9,
      "y": 12,
      "z": 6,
      "name": "Soil_Plant_Vine_Block"
    },
    {
      "x": 9,
      "y": 13,
      "z": 6,
      "name": "Soil_Plant_Vine_Block"
    },
    {
      "x": 9,
      "y": 14,
      "z": 6,
      "name": "Soil_Plant_Vine_Block"
    },
    {
      "x": 9,
      "y": 15,
      "z": 6,
      "name": "Soil_Plant_Vine_Block"
    },
    {
      "x": 9,
      "y": 16,
      "z": 6,
      "name": "Soil_Plant_Vine_Block"
    },
    {
      "x": 9,
      "y": 17,
      "z": 6,
      "name": "Soil_Plant_Vine_Block"
    },
    {
      "x": 9,
      "y": 18,
      "z": 6,
      "name": "Soil_Plant_Vine_Block"
    },
    {
      "x": 9,
      "y": 21,
      "z": 6,
      "name": "Plant_Leaves_Bottle"
    },
    {
      "x": 9,
      "y": 22,
      "z": 6,
      "name": "Plant_Leaves_Bottle"
    },
    {
      "x": 9,
      "y": 14,
      "z": 7,
      "name": "Soil_Plant_Vine_Block"
    },
    {
      "x": 9,
      "y": 15,
      "z": 7,
      "name": "Soil_Plant_Vine_Block"
    },
    {
      "x": 9,
      "y": 16,
      "z": 7,
      "name": "Soil_Plant_Vine_Block"
    },
    {
      "x": 9,
      "y": 19,
      "z": 7,
      "name": "Vine_Branch_Corner",
      "rotation": 3
    },
    {
      "x": 9,
      "y": 20,
      "z": 7,
      "name": "Vine_Branch_Long"
    },
    {
      "x": 9,
      "y": 21,
      "z": 7,
      "name": "Vine_Branch_Long"
    },
    {
      "x": 9,
      "y": 22,
      "z": 7,
      "name": "Plant_Leaves_Bottle"
    },
    {
      "x": 9,
      "y": 23,
      "z": 7,
      "name": "Plant_Leaves_Bottle"
    },
    {
      "x": 9,
      "y": 20,
      "z": 8,
      "name": "Plant_Leaves_Bottle"
    },
    {
      "x": 9,
      "y": 21,
      "z": 8,
      "name": "Plant_Leaves_Bottle"
    },
    {
      "x": 9,
      "y": 22,
      "z": 8,
      "name": "Plant_Leaves_Bottle"
    },
    {
      "x": 9,
      "y": 20,
      "z": 9,
      "name": "Plant_Leaves_Bottle"
    },
    {
      "x": 9,
      "y": 21,
      "z": 9,
      "name": "Plant_Leaves_Bottle"
    },
    {
      "x": 9,
      "y": 18,
      "z": 10,
      "name": "Vine_Branch_Corner",
      "rotation": 1
    },
    {
      "x": 9,
      "y": 19,
      "z": 10,
      "name": "Vine_Branch_Long"
    },
    {
      "x": 9,
      "y": 20,
      "z": 10,
      "name": "Vine_Branch_Long"
    },
    {
      "x": 9,
      "y": 21,
      "z": 10,
      "name": "Plant_Leaves_Bottle"
    },
    {
      "x": 9,
      "y": 22,
      "z": 10,
      "name": "Plant_Leaves_Bottle"
    },
    {
      "x": 9,
      "y": 22,
      "z": 11,
      "name": "Plant_Leaves_Bottle"
    },
    {
      "x": 9,
      "y": 21,
      "z": 12,
      "name": "Plant_Leaves_Bottle"
    },
    {
      "x": 9,
      "y": 20,
      "z": 13,
      "name": "Plant_Leaves_Bottle"
    },
    {
      "x": 10,
      "y": 21,
      "z": 1,
      "name": "Plant_Leaves_Bottle"
    },
    {
      "x": 10,
      "y": 21,
      "z": 2,
      "name": "Plant_Leaves_Bottle"
    },
    {
      "x": 10,
      "y": 22,
      "z": 2,
      "name": "Plant_Leaves_Bottle"
    },
    {
      "x": 10,
      "y": 22,
      "z": 3,
      "name": "Plant_Leaves_Bottle"
    },
    {
      "x": 10,
      "y": 20,
      "z": 4,
      "name": "Plant_Leaves_Bottle"
    },
    {
      "x": 10,
      "y": 21,
      "z": 4,
      "name": "Plant_Leaves_Bottle"
    },
    {
      "x": 10,
      "y": 20,
      "z": 5,
      "name": "Plant_Leaves_Bottle"
    },
    {
      "x": 10,
      "y": 22,
      "z": 5,
      "name": "Plant_Leaves_Bottle"
    },
    {
      "x": 10,
      "y": 18,
      "z": 6,
      "name": "Soil_Plant_Vine_Block"
    },
    {
      "x": 10,
      "y": 19,
      "z": 6,
      "name": "Vine_Branch_Long"
    },
    {
      "x": 10,
      "y": 20,
      "z": 6,
      "name": "Vine_Branch_Long"
    },
    {
      "x": 10,
      "y": 21,
      "z": 6,
      "name": "Plant_Leaves_Bottle"
    },
    {
      "x": 10,
      "y": 23,
      "z": 6,
      "name": "Plant_Leaves_Bottle"
    },
    {
      "x": 10,
      "y": 18,
      "z": 7,
      "name": "Soil_Plant_Vine_Block"
    },
    {
      "x": 10,
      "y": 19,
      "z": 7,
      "name": "Soil_Plant_Vine_Block"
    },
    {
      "x": 10,
      "y": 22,
      "z": 7,
      "name": "Plant_Leaves_Bottle"
    },
    {
      "x": 10,
      "y": 23,
      "z": 7,
      "name": "Plant_Leaves_Bottle"
    },
    {
      "x": 10,
      "y": 22,
      "z": 8,
      "name": "Plant_Leaves_Bottle"
    },
    {
      "x": 10,
      "y": 19,
      "z": 9,
      "name": "Plant_Leaves_Bottle"
    },
    {
      "x": 10,
      "y": 20,
      "z": 9,
      "name": "Plant_Leaves_Bottle"
    },
    {
      "x": 10,
      "y": 21,
      "z": 9,
      "name": "Plant_Leaves_Bottle"
    },
    {
      "x": 10,
      "y": 22,
      "z": 9,
      "name": "Plant_Leaves_Bottle"
    },
    {
      "x": 10,
      "y": 19,
      "z": 10,
      "name": "Plant_Leaves_Bottle"
    },
    {
      "x": 10,
      "y": 20,
      "z": 10,
      "name": "Plant_Leaves_Bottle"
    },
    {
      "x": 10,
      "y": 21,
      "z": 10,
      "name": "Plant_Leaves_Bottle"
    },
    {
      "x": 10,
      "y": 20,
      "z": 11,
      "name": "Plant_Leaves_Bottle"
    },
    {
      "x": 10,
      "y": 21,
      "z": 11,
      "name": "Plant_Leaves_Bottle"
    },
    {
      "x": 10,
      "y": 20,
      "z": 12,
      "name": "Plant_Leaves_Bottle"
    },
    {
      "x": 11,
      "y": 21,
      "z": 2,
      "name": "Plant_Leaves_Bottle"
    },
    {
      "x": 11,
      "y": 20,
      "z": 3,
      "name": "Plant_Leaves_Bottle"
    },
    {
      "x": 11,
      "y": 21,
      "z": 3,
      "name": "Plant_Leaves_Bottle"
    },
    {
      "x": 11,
      "y": 21,
      "z": 5,
      "name": "Plant_Leaves_Bottle"
    },
    {
      "x": 11,
      "y": 22,
      "z": 5,
      "name": "Plant_Leaves_Bottle"
    },
    {
      "x": 11,
      "y": 23,
      "z": 6,
      "name": "Plant_Leaves_Bottle"
    },
    {
      "x": 11,
      "y": 19,
      "z": 7,
      "name": "Soil_Plant_Vine_Block"
    },
    {
      "x": 11,
      "y": 23,
      "z": 7,
      "name": "Plant_Leaves_Bottle"
    },
    {
      "x": 11,
      "y": 19,
      "z": 8,
      "name": "Vine_Branch_Corner"
    },
    {
      "x": 11,
      "y": 20,
      "z": 8,
      "name": "Vine_Branch_Long"
    },
    {
      "x": 11,
      "y": 21,
      "z": 8,
      "name": "Vine_Branch_Long"
    },
    {
      "x": 11,
      "y": 22,
      "z": 8,
      "name": "Vine_Branch_Long"
    },
    {
      "x": 11,
      "y": 23,
      "z": 8,
      "name": "Plant_Leaves_Bottle"
    },
    {
      "x": 11,
      "y": 21,
      "z": 9,
      "name": "Plant_Leaves_Bottle"
    },
    {
      "x": 11,
      "y": 22,
      "z": 9,
      "name": "Plant_Leaves_Bottle"
    },
    {
      "x": 12,
      "y": 21,
      "z": 5,
      "name": "Plant_Leaves_Bottle"
    },
    {
      "x": 12,
      "y": 22,
      "z": 5,
      "name": "Plant_Leaves_Bottle"
    },
    {
      "x": 12,
      "y": 23,
      "z": 5,
      "name": "Plant_Leaves_Bottle"
    },
    {
      "x": 12,
      "y": 23,
      "z": 6,
      "name": "Plant_Leaves_Bottle"
    },
    {
      "x": 12,
      "y": 24,
      "z": 6,
      "name": "Plant_Leaves_Bottle"
    },
    {
      "x": 12,
      "y": 19,
      "z": 7,
      "name": "Soil_Plant_Vine_Block"
    },
    {
      "x": 12,
      "y": 20,
      "z": 7,
      "name": "Soil_Plant_Vine_Block"
    },
    {
      "x": 12,
      "y": 23,
      "z": 7,
      "name": "Plant_Leaves_Bottle"
    },
    {
      "x": 12,
      "y": 24,
      "z": 7,
      "name": "Plant_Leaves_Bottle"
    },
    {
      "x": 12,
      "y": 23,
      "z": 8,
      "name": "Plant_Leaves_Bottle"
    },
    {
      "x": 12,
      "y": 24,
      "z": 8,
      "name": "Plant_Leaves_Bottle"
    },
    {
      "x": 12,
      "y": 21,
      "z": 9,
      "name": "Plant_Leaves_Bottle"
    },
    {
      "x": 12,
      "y": 22,
      "z": 9,
      "name": "Plant_Leaves_Bottle"
    },
    {
      "x": 12,
      "y": 23,
      "z": 9,
      "name": "Plant_Leaves_Bottle"
    },
    {
      "x": 13,
      "y": 21,
      "z": 5,
      "name": "Plant_Leaves_Bottle"
    },
    {
      "x": 13,
      "y": 22,
      "z": 5,
      "name": "Plant_Leaves_Bottle"
    },
    {
      "x": 13,
      "y": 23,
      "z": 5,
      "name": "Plant_Leaves_Bottle"
    },
    {
      "x": 13,
      "y": 23,
      "z": 6,
      "name": "Plant_Leaves_Bottle"
    },
    {
      "x": 13,
      "y": 24,
      "z": 6,
      "name": "Plant_Leaves_Bottle"
    },
    {
      "x": 13,
      "y": 20,
      "z": 7,
      "name": "Soil_Plant_Vine_Block"
    },
    {
      "x": 13,
      "y": 21,
      "z": 7,
      "name": "Soil_Plant_Vine_Block"
    },
    {
      "x": 13,
      "y": 22,
      "z": 7,
      "name": "Vine_Branch_Long"
    },
    {
      "x": 13,
      "y": 23,
      "z": 7,
      "name": "Vine_Branch_Long"
    },
    {
      "x": 13,
      "y": 24,
      "z": 7,
      "name": "Plant_Leaves_Bottle"
    },
    {
      "x": 13,
      "y": 22,
      "z": 8,
      "name": "Plant_Leaves_Bottle"
    },
    {
      "x": 13,
      "y": 23,
      "z": 8,
      "name": "Plant_Leaves_Bottle"
    },
    {
      "x": 13,
      "y": 24,
      "z": 8,
      "name": "Plant_Leaves_Bottle"
    },
    {
      "x": 13,
      "y": 21,
      "z": 9,
      "name": "Plant_Leaves_Bottle"
    },
    {
      "x": 13,
      "y": 22,
      "z": 9,
      "name": "Plant_Leaves_Bottle"
    },
    {
      "x": 13,
      "y": 23,
      "z": 9,
      "name": "Plant_Leaves_Bottle"
    },
    {
      "x": 14,
      "y": 22,
      "z": 5,
      "name": "Plant_Leaves_Bottle"
    },
    {
      "x": 14,
      "y": 23,
      "z": 6,
      "name": "Plant_Leaves_Bottle"
    },
    {
      "x": 14,
      "y": 23,
      "z": 7,
      "name": "Plant_Leaves_Bottle"
    },
    {
      "x": 14,
      "y": 24,
      "z": 7,
      "name": "Plant_Leaves_Bottle"
    },
    {
      "x": 14,
      "y": 22,
      "z": 8,
      "name": "Plant_Leaves_Bottle"
    },
    {
      "x": 14,
      "y": 23,
      "z": 8,
      "name": "Plant_Leaves_Bottle"
    },
    {
      "x": 14,
      "y": 21,
      "z": 9,
      "name": "Plant_Leaves_Bottle"
    },
    {
      "x": 14,
      "y": 22,
      "z": 9,
      "name": "Plant_Leaves_Bottle"
    },
    {
      "x": 14,
      "y": 23,
      "z": 9,
      "name": "Plant_Leaves_Bottle"
    },
    {
      "x": 15,
      "y": 21,
      "z": 6,
      "name": "Plant_Leaves_Bottle"
    },
    {
      "x": 15,
      "y": 22,
      "z": 6,
      "name": "Plant_Leaves_Bottle"
    },
    {
      "x": 15,
      "y": 20,
      "z": 7,
      "name": "Plant_Leaves_Bottle"
    },
    {
      "x": 15,
      "y": 21,
      "z": 7,
      "name": "Plant_Leaves_Bottle"
    },
    {
      "x": 15,
      "y": 22,
      "z": 7,
      "name": "Plant_Leaves_Bottle"
    },
    {
      "x": 15,
      "y": 23,
      "z": 7,
      "name": "Plant_Leaves_Bottle"
    },
    {
      "x": 15,
      "y": 21,
      "z": 8,
      "name": "Plant_Leaves_Bottle"
    },
    {
      "x": 15,
      "y": 22,
      "z": 8,
      "name": "Plant_Leaves_Bottle"
    },
    {
      "x": 15,
      "y": 22,
      "z": 9,
      "name": "Plant_Leaves_Bottle"
    }
  ]
}