{
  "version": 8,
  "blockIdVersion": 11,
  "anchorX": 9,
  "anchorY": 10,
  "anchorZ": 14,
  "blocks": [
    {
      "x": 7,
      "y": 20,
      "z": 14,
      "name": "Plant_Leaves_Bottle"
    },
    {
      "x": 7,
      "y": 21,
      "z": 14,
      "name": "Plant_Leaves_Bottle"
    },
    {
      "x": 7,
      "y": 22,
      "z": 14,
      "name": "Plant_Leaves_Bottle"
    },
    {
      "x": 7,
      "y": 21,
      "z": 15,
      "name": "Plant_Leaves_Bottle"
    },
    {
      "x": 7,
      "y": 22,
      "z": 15,
      "name": "Plant_Leaves_Bottle"
    },
    {
      "x": 7,
      "y": 21,
      "z": 16,
      "name": "Plant_Leaves_Bottle"
    },
    {
      "x": 7,
      "y": 22,
      "z": 16,
      "name": "Plant_Leaves_Bottle"
    },
    {
      "x": 7,
      "y": 23,
      "z": 16,
      "name": "Plant_Leaves_Bottle"
    },
    {
      "x": 7,
      "y": 21,
      "z": 17,
      "name": "Plant_Leaves_Bottle"
    },
    {
      "x": 7,
      "y": 22,
      "z": 17,
      "name": "Plant_Leaves_Bottle"
    },
    {
      "x": 7,
      "y": 23,
      "z": 17,
      "name": "Plant_Leaves_Bottle"
    },
    {
      "x": 7,
      "y": 21,
      "z": 18,
      "name": "Plant_Leaves_Bottle"
    },
    {
      "x": 7,
      "y": 22,
      "z": 18,
      "name": "Plant_Leaves_Bottle"
    },
    {
      "x": 7,
      "y": 23,
      "z": 18,
      "name": "Plant_Leaves_Bottle"
    },
    {
      "x": 7,
      "y": 22,
      "z": 19,
      "name": "Plant_Leaves_Bottle"
    },
    {
      "x": 8,
      "y": 20,
      "z": 6,
      "name": "Plant_Leaves_Bottle"
    },
    {
      "x": 8,
      "y": 19,
      "z": 7,
      "name": "Plant_Leaves_Bottle"
    },
    {
      "x": 8,
      "y": 20,
      "z": 7,
      "name": "Plant_Leaves_Bottle"
    },
    {
      "x": 8,
      "y": 20,
      "z": 8,
      "name": "Plant_Leaves_Bottle"
    },
    {
      "x": 8,
      "y": 19,
      "z": 9,
      "name": "Plant_Leaves_Bottle"
    },
    {
      "x": 8,
      "y": 19,
      "z": 10,
      "name": "Plant_Leaves_Bottle"
    },
    {
      "x": 8,
      "y": 18,
      "z": 11,
      "name": "Plant_Leaves_Bottle"
    },
    {
      "x": 8,
      "y": 19,
      "z": 11,
      "name": "Plant_Leaves_Bottle"
    },
    {
      "x": 8,
      "y": 20,
      "z": 12,
      "name": "Plant_Leaves_Bottle"
    },
    {
      "x": 8,
      "y": 21,
      "z": 12,
      "name": "Plant_Leaves_Bottle"
    },
    {
      "x": 8,
      "y": 20,
      "z": 13,
      "name": "Plant_Leaves_Bottle"
    },
    {
      "x": 8,
      "y": 21,
      "z": 13,
      "name": "Plant_Leaves_Bottle"
    },
    {
      "x": 8,
      "y": 22,
      "z": 13,
      "name": "Plant_Leaves_Bottle"
    },
    {
      "x": 8,
      "y": 22,
      "z": 14,
      "name": "Plant_Leaves_Bottle"
    },
    {
      "x": 8,
      "y": 19,
      "z": 15,
      "name": "Vine_Branch_Corner",
      "rotation": 3
    },
    {
      "x": 8,
      "y": 20,
      "z": 15,
      "name": "Vine_Branch_Long"
    },
    {
      "x": 8,
      "y": 21,
      "z": 15,
      "name": "Vine_Branch_Long"
    },
    {
      "x": 8,
      "y": 22,
      "z": 15,
      "name": "Vine_Branch_Long"
    },
    {
      "x": 8,
      "y": 23,
      "z": 15,
      "name": "Plant_Leaves_Bottle"
    },
    {
      "x": 8,
      "y": 23,
      "z": 16,
      "name": "Plant_Leaves_Bottle"
    },
    {
      "x": 8,
      "y": 24,
      "z": 16,
      "name": "Plant_Leaves_Bottle"
    },
    {
      "x": 8,
      "y": 22,
      "z": 17,
      "name": "Plant_Leaves_Bottle"
    },
    {
      "x": 8,
      "y": 23,
      "z": 17,
      "name": "Plant_Leaves_Bottle"
    },
    {
      "x": 8,
      "y": 24,
      "z": 17,
      "name": "Plant_Leaves_Bottle"
    },
    {
      "x": 8,
      "y": 22,
      "z": 18,
      "name": "Plant_Leaves_Bottle"
    },
    {
      "x": 8,
      "y": 23,
      "z": 18,
      "name": "Plant_Leaves_Bottle"
    },
    {
      "x": 8,
      "y": 21,
      "z": 19,
      "name": "Plant_Leaves_Bottle"
    },
    {
      "x": 8,
      "y": 22,
      "z": 19,
      "name": "Plant_Leaves_Bottle"
    },
    {
      "x": 9,
      "y": 19,
      "z": 4,
      "name": "Plant_Leaves_Bottle"
    },
    {
      "x": 9,
      "y": 18,
      "z": 5,
      "name": "Plant_Leaves_Bottle"
    },
    {
      "x": 9,
      "y": 19,
      "z": 5,
      "name": "Plant_Leaves_Bottle"
    },
    {
      "x": 9,
      "y": 20,
      "z": 5,
      "name": "Plant_Leaves_Bottle"
    },
    {
      "x": 9,
      "y": 21,
      "z": 5,
      "name": "Plant_Leaves_Bottle"
    },
    {
      "x": 9,
      "y": 20,
      "z": 6,
      "name": "Plant_Leaves_Bottle"
    },
    {
      "x": 9,
      "y": 21,
      "z": 6,
      "name": "Plant_Leaves_Bottle"
    },
    {
      "x": 9,
      "y": 20,
      "z": 7,
      "name": "Plant_Leaves_Bottle"
    },
    {
      "x": 9,
      "y": 21,
      "z": 7,
      "name": "Plant_Leaves_Bottle"
    },
    {
      "x": 9,
      "y": 20,
      "z": 9,
      "name": "Plant_Leaves_Bottle"
    },
    {
      "x": 9,
      "y": 21,
      "z": 9,
      "name": "Plant_Leaves_Bottle"
    },
    {
      "x": 9,
      "y": 19,
      "z": 10,
      "name": "Plant_Leaves_Bottle"
    },
    {
      "x": 9,
      "y": 16,
      "z": 11,
      "name": "Vine_Branch_Corner",
      "rotation": 3
    },
    {
      "x": 9,
      "y": 17,
      "z": 11,
      "name": "Vine_Branch_Long"
    },
    {
      "x": 9,
      "y": 18,
      "z": 11,
      "name": "Vine_Branch_Long"
    },
    {
      "x": 9,
      "y": 19,
      "z": 11,
      "name": "Plant_Leaves_Bottle"
    },
    {
      "x": 9,
      "y": 20,
      "z": 11,
      "name": "Plant_Leaves_Bottle"
    },
    {
      "x": 9,
      "y": 20,
      "z": 12,
      "name": "Plant_Leaves_Bottle"
    },
    {
      "x": 9,
      "y": 21,
      "z": 12,
      "name": "Plant_Leaves_Bottle"
    },
    {
      "x": 9,
      "y": 22,
      "z": 12,
      "name": "Plant_Leaves_Bottle"
    },
    {
      "x": 9,
      "y": 9,
      "z": 13,
      "name": "Soil_Plant_Vine_Block"
    },
    {
      "x": 9,
      "y": 10,
      "z": 13,
      "name": "Soil_Plant_Vine_Block"
    },
    {
      "x": 9,
      "y": 11,
      "z": 13,
      "name": "Soil_Plant_Vine_Block"
    },
    {
      "x": 9,
      "y": 19,
      "z": 13,
      "name": "Vine_Branch_Corner",
      "rotation": 2
    },
    {
      "x": 9,
      "y": 20,
      "z": 13,
      "name": "Vine_Branch_Long"
    },
    {
      "x": 9,
      "y": 21,
      "z": 13,
      "name": "Vine_Branch_Long"
    },
    {
      "x": 9,
      "y": 22,
      "z": 13,
      "name": "Plant_Leaves_Bottle"
    },
    {
      "x": 9,
      "y": 23,
      "z": 13,
      "name": "Plant_Leaves_Bottle"
    },
    {
      "x": 9,
      "y": 9,
      "z": 14,
      "name": "Soil_Plant_Vine_Block"
    },
    {
      "x": 9,
      "y": 10,
      "z": 14,
      "name": "Soil_Plant_Vine_Block"
    },
    {
      "x": 9,
      "y": 11,
      "z": 14,
      "name": "Soil_Plant_Vine_Block"
    },
    {
      "x": 9,
      "y": 12,
      "z": 14,
      "name": "Soil_Plant_Vine_Block"
    },
    {
      "x": 9,
      "y": 13,
      "z": 14,
      "name": "Soil_Plant_Vine_Block"
    },
    {
      "x": 9,
      "y": 14,
      "z": 14,
      "name": "Soil_Plant_Vine_Block"
    },
    {
      "x": 9,
      "y": 18,
      "z": 14,
      "name": "Soil_Plant_Vine_Block"
    },
    {
      "x": 9,
      "y": 19,
      "z": 14,
      "name": "Soil_Plant_Vine_Block"
    },
    {
      "x": 9,
      "y": 22,
      "z": 14,
      "name": "Plant_Leaves_Bottle"
    },
    {
      "x": 9,
      "y": 23,
      "z": 14,
      "name": "Plant_Leaves_Bottle"
    },
    {
      "x": 9,
      "y": 19,
      "z": 15,
      "name": "Soil_Plant_Vine_Block"
    },
    {
      "x": 9,
      "y": 23,
      "z": 15,
      "name": "Plant_Leaves_Bottle"
    },
    {
      "x": 9,
      "y": 19,
      "z": 16,
      "name": "Soil_Plant_Vine_Block"
    },
    {
      "x": 9,
      "y": 20,
      "z": 16,
      "name": "Soil_Plant_Vine_Block"
    },
    {
      "x": 9,
      "y": 23,
      "z": 16,
      "name": "Plant_Leaves_Bottle"
    },
    {
      "x": 9,
      "y": 24,
      "z": 16,
      "name": "Plant_Leaves_Bottle"
    },
    {
      "x": 9,
      "y": 20,
      "z": 17,
      "name": "Soil_Plant_Vine_Block"
    },
    {
      "x": 9,
      "y": 21,
      "z": 17,
      "name": "Soil_Plant_Vine_Block"
    },
    {
      "x": 9,
      "y": 22,
      "z": 17,
      "name": "Vine_Branch_Long"
    },
    {
      "x": 9,
      "y": 23,
      "z": 17,
      "name": "Vine_Branch_Long"
    },
    {
      "x": 9,
      "y": 24,
      "z": 17,
      "name": "Plant_Leaves_Bottle"
    },
    {
      "x": 9,
      "y": 23,
      "z": 18,
      "name": "Plant_Leaves_Bottle"
    },
    {
      "x": 9,
      "y": 24,
      "z": 18,
      "name": "Plant_Leaves_Bottle"
    },
    {
      "x": 9,
      "y": 20,
      "z": 19,
      "name": "Plant_Leaves_Bottle"
    },
    {
      "x": 9,
      "y": 21,
      "z": 19,
      "name": "Plant_Leaves_Bottle"
    },
    {
      "x": 9,
      "y": 22,
      "z": 19,
      "name": "Plant_Leaves_Bottle"
    },
    {
      "x": 9,
      "y": 23,
      "z": 19,
      "name": "Plant_Leaves_Bottle"
    },
    {
      "x": 9,
      "y": 21,
      "z": 20,
      "name": "Plant_Leaves_Bottle"
    },
    {
      "x": 9,
      "y": 22,
      "z": 20,
      "name": "Plant_Leaves_Bottle"
    },
    {
      "x": 10,
      "y": 18,
      "z": 4,
      "name": "Plant_Leaves_Bottle"
    },
    {
      "x": 10,
      "y": 19,
      "z": 4,
      "name": "Plant_Leaves_Bottle"
    },
    {
      "x": 10,
      "y": 20,
      "z": 4,
      "name": "Plant_Leaves_Bottle"
    },
    {
      "x": 10,
      "y": 19,
      "z": 5,
      "name": "Plant_Leaves_Bottle"
    },
    {
      "x": 10,
      "y": 20,
      "z": 5,
      "name": "Plant_Leaves_Bottle"
    },
    {
      "x": 10,
      "y": 21,
      "z": 5,
      "name": "Plant_Leaves_Bottle"
    },
    {
      "x": 10,
      "y": 22,
      "z": 6,
      "name": "Plant_Leaves_Bottle"
    },
    {
      "x": 10,
      "y": 22,
      "z": 7,
      "name": "Plant_Leaves_Bottle"
    },
    {
      "x": 10,
      "y": 21,
      "z": 8,
      "name": "Plant_Leaves_Bottle"
    },
    {
      "x": 10,
      "y": 22,
      "z": 8,
      "name": "Plant_Leaves_Bottle"
    },
    {
      "x": 10,
      "y": 20,
      "z": 9,
      "name": "Plant_Leaves_Bottle"
    },
    {
      "x": 10,
      "y": 21,
      "z": 9,
      "name": "Plant_Leaves_Bottle"
    },
    {
      "x": 10,
      "y": 19,
      "z": 10,
      "name": "Plant_Leaves_Bottle"
    },
    {
      "x": 10,
      "y": 20,
      "z": 10,
      "name": "Plant_Leaves_Bottle"
    },
    {
      "x": 10,
      "y": 21,
      "z": 10,
      "name": "Plant_Leaves_Bottle"
    },
    {
      "x": 10,
      "y": 16,
      "z": 11,
      "name": "Soil_Plant_Vine_Block"
    },
    {
      "x": 10,
      "y": 19,
      "z": 11,
      "name": "Plant_Leaves_Bottle"
    },
    {
      "x": 10,
      "y": 14,
      "z": 12,
      "name": "Vine_Branch_Long"
    },
    {
      "x": 10,
      "y": 15,
      "z": 12,
      "name": "Soil_Plant_Vine_Block"
    },
    {
      "x": 10,
      "y": 16,
      "z": 12,
      "name": "Soil_Plant_Vine_Block"
    },
    {
      "x": 10,
      "y": 9,
      "z": 13,
      "name": "Soil_Plant_Vine_Block"
    },
    {
      "x": 10,
      "y": 10,
      "z": 13,
      "name": "Soil_Plant_Vine_Block"
    },
    {
      "x": 10,
      "y": 11,
      "z": 13,
      "name": "Soil_Plant_Vine_Block"
    },
    {
      "x": 10,
      "y": 12,
      "z": 13,
      "name": "Soil_Plant_Vine_Block"
    },
    {
      "x": 10,
      "y": 13,
      "z": 13,
      "name": "Soil_Plant_Vine_Block"
    },
    {
      "x": 10,
      "y": 14,
      "z": 13,
      "name": "Soil_Plant_Vine_Block"
    },
    {
      "x": 10,
      "y": 15,
      "z": 13,
      "name": "Soil_Plant_Vine_Block"
    },
    {
      "x": 10,
      "y": 16,
      "z": 13,
      "name": "Soil_Plant_Vine_Block"
    },
    {
      "x": 10,
      "y": 17,
      "z": 13,
      "name": "Soil_Plant_Vine_Block"
    },
    {
      "x": 10,
      "y": 18,
      "z": 13,
      "name": "Soil_Plant_Vine_Block"
    },
    {
      "x": 10,
      "y": 21,
      "z": 13,
      "name": "Plant_Leaves_Bottle"
    },
    {
      "x": 10,
      "y": 22,
      "z": 13,
      "name": "Plant_Leaves_Bottle"
    },
    {
      "x": 10,
      "y": 9,
      "z": 14,
      "name": "Soil_Plant_Vine_Block"
    },
    {
      "x": 10,
      "y": 10,
      "z": 14,
      "name": "Soil_Plant_Vine_Block"
    },
    {
      "x": 10,
      "y": 11,
      "z": 14,
      "name": "Soil_Plant_Vine_Block"
    },
    {
      "x": 10,
      "y": 12,
      "z": 14,
      "name": "Soil_Plant_Vine_Block"
    },
    {
      "x": 10,
      "y": 13,
      "z": 14,
      "name": "Soil_Plant_Vine_Block"
    },
    {
      "x": 10,
      "y": 16,
      "z": 14,
      "name": "Vine_Branch_Corner"
    },
    {
      "x": 10,
      "y": 17,
      "z": 14,
      "name": "Vine_Branch_Long"
    },
    {
      "x": 10,
      "y": 18,
      "z": 14,
      "name": "Soil_Plant_Vine_Block"
    },
    {
      "x": 10,
      "y": 19,
      "z": 14,
      "name": "Vine_Branch_Long"
    },
    {
      "x": 10,
      "y": 20,
      "z": 14,
      "name": "Vine_Branch_Long"
    },
    {
      "x": 10,
      "y": 21,
      "z": 14,
      "name": "Plant_Leaves_Bottle"
    },
    {
      "x": 10,
      "y": 23,
      "z": 14,
      "name": "Plant_Leaves_Bottle"
    },
    {
      "x": 10,
      "y": 23,
      "z": 15,
      "name": "Plant_Leaves_Bottle"
    },
    {
      "x": 10,
      "y": 23,
      "z": 16,
      "name": "Plant_Leaves_Bottle"
    },
    {
      "x": 10,
      "y": 24,
      "z": 16,
      "name": "Plant_Leaves_Bottle"
    },
    {
      "x": 10,
      "y": 23,
      "z": 17,
      "name": "Plant_Leaves_Bottle"
    },
    {
      "x": 10,
      "y": 24,
      "z": 17,
      "name": "Plant_Leaves_Bottle"
    },
    {
      "x": 10,
      "y": 23,
      "z": 18,
      "name": "Plant_Leaves_Bottle"
    },
    {
      "x": 10,
      "y": 21,
      "z": 19,
      "name": "Plant_Leaves_Bottle"
    },
    {
      "x": 10,
      "y": 22,
      "z": 19,
      "name": "Plant_Leaves_Bottle"
    },
    {
      "x": 11,
      "y": 18,
      "z": 4,
      "name": "Plant_Leaves_Bottle"
    },
    {
      "x": 11,
      "y": 19,
      "z": 4,
      "name": "Plant_Leaves_Bottle"
    },
    {
      "x": 11,
      "y": 20,
      "z": 4,
      "name": "Plant_Leaves_Bottle"
    },
    {
      "x": 11,
      "y": 21,
      "z": 4,
      "name": "Plant_Leaves_Bottle"
    },
    {
      "x": 11,
      "y": 20,
      "z": 5,
      "name": "Plant_Leaves_Bottle"
    },
    {
      "x": 11,
      "y": 21,
      "z": 5,
      "name": "Plant_Leaves_Bottle"
    },
    {
      "x": 11,
      "y": 22,
      "z": 5,
      "name": "Plant_Leaves_Bottle"
    },
    {
      "x": 11,
      "y": 22,
      "z": 6,
      "name": "Plant_Leaves_Bottle"
    },
    {
      "x": 11,
      "y": 18,
      "z": 7,
      "name": "Soil_Plant_Vine_Block"
    },
    {
      "x": 11,
      "y": 19,
      "z": 7,
      "name": "Soil_Plant_Vine_Block"
    },
    {
      "x": 11,
      "y": 20,
      "z": 7,
      "name": "Vine_Branch_Long"
    },
    {
      "x": 11,
      "y": 21,
      "z": 7,
      "name": "Vine_Branch_Long"
    },
    {
      "x": 11,
      "y": 22,
      "z": 7,
      "name": "Plant_Leaves_Bottle"
    },
    {
      "x": 11,
      "y": 17,
      "z": 8,
      "name": "Soil_Plant_Vine_Block"
    },
    {
      "x": 11,
      "y": 18,
      "z": 8,
      "name": "Soil_Plant_Vine_Block"
    },
    {
      "x": 11,
      "y": 22,
      "z": 8,
      "name": "Plant_Leaves_Bottle"
    },
    {
      "x": 11,
      "y": 16,
      "z": 9,
      "name": "Soil_Plant_Vine_Block"
    },
    {
      "x": 11,
      "y": 17,
      "z": 9,
      "name": "Soil_Plant_Vine_Block"
    },
    {
      "x": 11,
      "y": 19,
      "z": 9,
      "name": "Plant_Leaves_Bottle"
    },
    {
      "x": 11,
      "y": 20,
      "z": 9,
      "name": "Plant_Leaves_Bottle"
    },
    {
      "x": 11,
      "y": 21,
      "z": 9,
      "name": "Plant_Leaves_Bottle"
    },
    {
      "x": 11,
      "y": 16,
      "z": 10,
      "name": "Soil_Plant_Vine_Block"
    },
    {
      "x": 11,
      "y": 17,
      "z": 10,
      "name": "Vine_Branch_Long"
    },
    {
      "x": 11,
      "y": 18,
      "z": 10,
      "name": "Vine_Branch_Long"
    },
    {
      "x": 11,
      "y": 19,
      "z": 10,
      "name": "Vine_Branch_Long"
    },
    {
      "x": 11,
      "y": 20,
      "z": 10,
      "name": "Plant_Leaves_Bottle"
    },
    {
      "x": 11,
      "y": 16,
      "z": 11,
      "name": "Soil_Plant_Vine_Block"
    },
    {
      "x": 11,
      "y": 18,
      "z": 11,
      "name": "Plant_Leaves_Bottle"
    },
    {
      "x": 11,
      "y": 19,
      "z": 11,
      "name": "Plant_Leaves_Bottle"
    },
    {
      "x": 11,
      "y": 20,
      "z": 11,
      "name": "Plant_Leaves_Bottle"
    },
    {
      "x": 11,
      "y": 19,
      "z": 12,
      "name": "Plant_Leaves_Bottle"
    },
    {
      "x": 11,
      "y": 20,
      "z": 12,
      "name": "Plant_Leaves_Bottle"
    },
    {
      "x": 11,
      "y": 9,
      "z": 13,
      "name": "Soil_Plant_Vine_Block"
    },
    {
      "x": 11,
      "y": 10,
      "z": 13,
      "name": "Soil_Plant_Vine_Block"
    },
    {
      "x": 11,
      "y": 11,
      "z": 13,
      "name": "Soil_Plant_Vine_Block"
    },
    {
      "x": 11,
      "y": 12,
      "z": 13,
      "name": "Soil_Plant_Vine_Block"
    },
    {
      "x": 11,
      "y": 16,
      "z": 13,
      "name": "Soil_Plant_Vine_Block"
    },
    {
      "x": 11,
      "y": 17,
      "z": 13,
      "name": "Soil_Plant_Vine_Block"
    },
    {
      "x": 11,
      "y": 19,
      "z": 13,
      "name": "Plant_Leaves_Bottle"
    },
    {
      "x": 11,
      "y": 20,
      "z": 13,
      "name": "Plant_Leaves_Bottle"
    },
    {
      "x": 11,
      "y": 9,
      "z": 14,
      "name": "Soil_Plant_Vine_Block"
    },
    {
      "x": 11,
      "y": 10,
      "z": 14,
      "name": "Soil_Plant_Vine_Block"
    },
    {
      "x": 11,
      "y": 11,
      "z": 14,
      "name": "Soil_Plant_Vine_Block"
    },
    {
      "x": 11,
      "y": 19,
      "z": 14,
      "name": "Plant_Leaves_Bottle"
    },
    {
      "x": 11,
      "y": 22,
      "z": 14,
      "name": "Plant_Leaves_Bottle"
    },
    {
      "x": 11,
      "y": 21,
      "z": 15,
      "name": "Plant_Leaves_Bottle"
    },
    {
      "x": 11,
      "y": 22,
      "z": 15,
      "name": "Plant_Leaves_Bottle"
    },
    {
      "x": 11,
      "y": 21,
      "z": 16,
      "name": "Plant_Leaves_Bottle"
    },
    {
      "x": 11,
      "y": 22,
      "z": 16,
      "name": "Plant_Leaves_Bottle"
    },
    {
      "x": 11,
      "y": 23,
      "z": 16,
      "name": "Plant_Leaves_Bottle"
    },
    {
      "x": 11,
      "y": 21,
      "z": 17,
      "name": "Plant_Leaves_Bottle"
    },
    {
      "x": 11,
      "y": 22,
      "z": 17,
      "name": "Plant_Leaves_Bottle"
    },
    {
      "x": 11,
      "y": 23,
      "z": 17,
      "name": "Plant_Leaves_Bottle"
    },
    {
      "x": 11,
      "y": 22,
      "z": 18,
      "name": "Plant_Leaves_Bottle"
    },
    {
      "x": 12,
      "y": 19,
      "z": 4,
      "name": "Plant_Leaves_Bottle"
    },
    {
      "x": 12,
      "y": 20,
      "z": 4,
      "name": "Plant_Leaves_Bottle"
    },
    {
      "x": 12,
      "y": 20,
      "z": 5,
      "name": "Plant_Leaves_Bottle"
    },
    {
      "x": 12,
      "y": 21,
      "z": 5,
      "name": "Plant_Leaves_Bottle"
    },
    {
      "x": 12,
      "y": 22,
      "z": 5,
      "name": "Plant_Leaves_Bottle"
    },
    {
      "x": 12,
      "y": 22,
      "z": 7,
      "name": "Plant_Leaves_Bottle"
    },
    {
      "x": 12,
      "y": 18,
      "z": 8,
      "name": "Vine_Branch_Corner",
      "rotation": 1
    },
    {
      "x": 12,
      "y": 19,
      "z": 8,
      "name": "Vine_Branch_Long"
    },
    {
      "x": 12,
      "y": 20,
      "z": 8,
      "name": "Vine_Branch_Long"
    },
    {
      "x": 12,
      "y": 21,
      "z": 8,
      "name": "Vine_Branch_Long"
    },
    {
      "x": 12,
      "y": 22,
      "z": 8,
      "name": "Plant_Leaves_Bottle"
    },
    {
      "x": 12,
      "y": 19,
      "z": 9,
      "name": "Plant_Leaves_Bottle"
    },
    {
      "x": 12,
      "y": 20,
      "z": 9,
      "name": "Plant_Leaves_Bottle"
    },
    {
      "x": 12,
      "y": 21,
      "z": 9,
      "name": "Plant_Leaves_Bottle"
    },
    {
      "x": 12,
      "y": 19,
      "z": 10,
      "name": "Plant_Leaves_Bottle"
    },
    {
      "x": 12,
      "y": 20,
      "z": 10,
      "name": "Plant_Leaves_Bottle"
    },
    {
      "x": 12,
      "y": 18,
      "z": 11,
      "name": "Plant_Leaves_Bottle"
    },
    {
      "x": 12,
      "y": 19,
      "z": 11,
      "name": "Plant_Leaves_Bottle"
    },
    {
      "x": 12,
      "y": 20,
      "z": 11,
      "name": "Plant_Leaves_Bottle"
    },
    {
      "x": 12,
      "y": 17,
      "z": 12,
      "name": "Vine_Branch_Corner",
      "rotation": 2
    },
    {
      "x": 12,
      "y": 18,
      "z": 12,
      "name": "Vine_Branch_Long"
    },
    {
      "x": 12,
      "y": 19,
      "z": 12,
      "name": "Vine_Branch_Long"
    },
    {
      "x": 12,
      "y": 20,
      "z": 12,
      "name": "Plant_Leaves_Bottle"
    },
    {
      "x": 12,
      "y": 21,
      "z": 12,
      "name": "Plant_Leaves_Bottle"
    },
    {
      "x": 12,
      "y": 17,
      "z": 13,
      "name": "Soil_Plant_Vine_Block"
    },
    {
      "x": 12,
      "y": 20,
      "z": 13,
      "name": "Plant_Leaves_Bottle"
    },
    {
      "x": 12,
      "y": 21,
      "z": 13,
      "name": "Plant_Leaves_Bottle"
    },
    {
      "x": 12,
      "y": 19,
      "z": 14,
      "name": "Plant_Leaves_Bottle"
    },
    {
      "x": 12,
      "y": 20,
      "z": 14,
      "name": "Plant_Leaves_Bottle"
    },
    {
      "x": 13,
      "y": 19,
      "z": 5,
      "name": "Plant_Leaves_Bottle"
    },
    {
      "x": 13,
      "y": 20,
      "z": 5,
      "name": "Plant_Leaves_Bottle"
    },
    {
      "x": 13,
      "y": 21,
      "z": 5,
      "name": "Plant_Leaves_Bottle"
    },
    {
      "x": 13,
      "y": 21,
      "z": 6,
      "name": "Plant_Leaves_Bottle"
    },
    {
      "x": 13,
      "y": 22,
      "z": 6,
      "name": "Plant_Leaves_Bottle"
    },
    {
      "x": 13,
      "y": 22,
      "z": 7,
      "name": "Plant_Leaves_Bottle"
    },
    {
      "x": 13,
      "y": 20,
      "z": 9,
      "name": "Plant_Leaves_Bottle"
    },
    {
      "x": 13,
      "y": 21,
      "z": 9,
      "name": "Plant_Leaves_Bottle"
    },
    {
      "x": 13,
      "y": 19,
      "z": 11,
      "name": "Plant_Leaves_Bottle"
    },
    {
      "x": 13,
      "y": 20,
      "z": 11,
      "name": "Plant_Leaves_Bottle"
    },
    {
      "x": 13,
      "y": 21,
      "z": 12,
      "name": "Plant_Leaves_Bottle"
    },
    {
      "x": 13,
      "y": 17,
      "z": 13,
      "name": "Soil_Plant_Vine_Block"
    },
    {
      "x": 13,
      "y": 18,
      "z": 13,
      "name": "Soil_Plant_Vine_Block"
    },
    {
      "x": 13,
      "y": 19,
      "z": 13,
      "name": "Vine_Branch_Long"
    },
    {
      "x": 13,
      "y": 20,
      "z": 13,
      "name": "Vine_Branch_Long"
    },
    {
      "x": 13,
      "y": 21,
      "z": 13,
      "name": "Plant_Leaves_Bottle"
    },
    {
      "x": 13,
      "y": 21,
      "z": 14,
      "name": "Plant_Leaves_Bottle"
    },
    {
      "x": 13,
      "y": 19,
      "z": 15,
      "name": "Plant_Leaves_Bottle"
    },
    {
      "x": 13,
      "y": 20,
      "z": 15,
      "name": "Plant_Leaves_Bottle"
    },
    {
      "x": 14,
      "y": 19,
      "z": 5,
      "name": "Plant_Leaves_Bottle"
    },
    {
      "x": 14,
      "y": 18,
      "z": 6,
      "name": "Plant_Leaves_Bottle"
    },
    {
      "x": 14,
      "y": 19,
      "z": 6,
      "name": "Plant_Leaves_Bottle"
    },
    {
      "x": 14,
      "y": 20,
      "z": 6,
      "name": "Plant_Leaves_Bottle"
    },
    {
      "x": 14,
      "y": 21,
      "z": 6,
      "name": "Plant_Leaves_Bottle"
    },
    {
      "x": 14,
      "y": 18,
      "z": 7,
      "name": "Plant_Leaves_Bottle"
    },
    {
      "x": 14,
      "y": 19,
      "z": 7,
      "name": "Plant_Leaves_Bottle"
    },
    {
      "x": 14,
      "y": 20,
      "z": 7,
      "name": "Plant_Leaves_Bottle"
    },
    {
      "x": 14,
      "y": 21,
      "z": 7,
      "name": "Plant_Leaves_Bottle"
    },
    {
      "x": 14,
      "y": 22,
      "z": 7,
      "name": "Plant_Leaves_Bottle"
    },
    {
      "x": 14,
      "y": 19,
      "z": 8,
      "name": "Plant_Leaves_Bottle"
    },
    {
      "x": 14,
      "y": 20,
      "z": 8,
      "name": "Plant_Leaves_Bottle"
    },
    {
      "x": 14,
      "y": 21,
      "z": 8,
      "name": "Plant_Leaves_Bottle"
    },
    {
      "x": 14,
      "y": 20,
      "z": 9,
      "name": "Plant_Leaves_Bottle"
    },
    {
      "x": 14,
      "y": 19,
      "z": 11,
      "name": "Plant_Leaves_Bottle"
    },
    {
      "x": 14,
      "y": 20,
      "z": 12,
      "name": "Plant_Leaves_Bottle"
    },
    {
      "x": 14,
      "y": 20,
      "z": 13,
      "name": "Plant_Leaves_Bottle"
    },
    {
      "x": 14,
      "y": 21,
      "z": 13,
      "name": "Plant_Leaves_Bottle"
    },
    {
      "x": 14,
      "y": 20,
      "z": 14,
      "name": "Plant_Leaves_Bottle"
    },
    {
      "x": 14,
      "y": 21,
      "z": 14,
      "name": "Plant_Leaves_Bottle"
    },
    {
      "x": 14,
      "y": 20,
      "z": 15,
      "name": "Plant_Leaves_Bottle"
    },
    {
      "x": 15,
      "y": 20,
      "z": 6,
      "name": "Plant_Leaves_Bottle"
    },
    {
      "x": 15,
      "y": 19,
      "z": 7,
      "name": "Plant_Leaves_Bottle"
    },
    {
      "x": 15,
      "y": 20,
      "z": 7,
      "name": "Plant_Leaves_Bottle"
    },
    {
      "x": 15,
      "y": 21,
      "z": 7,
      "name": "Plant_Leaves_Bottle"
    },
    {
      "x": 15,
      "y": 19,
      "z": 12,
      "name": "Plant_Leaves_Bottle"
    },
    {
      "x": 15,
      "y": 19,
      "z": 13,
      "name": "Plant_Leaves_Bottle"
    },
    {
      "x": 15,
      "y": 20,
      "z": 13,
      "name": "Plant_Leaves_Bottle"
    },
    {
      "x": 15,
      "y": 20,
      "z": 14,
      "name": "Plant_Leaves_Bottle"
    }
  ]
}