{
  "version": 8,
  "blockIdVersion": 11,
  "anchorX": 1,
  "anchorY": 1,
  "anchorZ": 0,
  "blocks": [
    {
      "x": -5,
      "y": 3,
      "z": 0,
      "name": "*Furniture_Temple_Light_Lantern_Ceiling_State_Definitions_Off"
    },
    {
      "x": -5,
      "y": 4,
      "z": 0,
      "name": "Rock_Marble_Cobble_Wall"
    },
    {
      "x": -4,
      "y": 23,
      "z": -3,
      "name": "Rock_Runic_Blue_Brick"
    },
    {
      "x": -4,
      "y": 24,
      "z": -3,
      "name": "*Metal_Iron_Fence_State_Definitions_Corner",
      "rotation": 1
    },
    {
      "x": -4,
      "y": 0,
      "z": -2,
      "name": "Rock_Marble_Cobble"
    },
    {
      "x": -4,
      "y": 1,
      "z": -2,
      "name": "Rock_Marble_Cobble"
    },
    {
      "x": -4,
      "y": 2,
      "z": -2,
      "name": "Rock_Marble_Cobble"
    },
    {
      "x": -4,
      "y": 3,
      "z": -2,
      "name": "Rock_Marble_Cobble"
    },
    {
      "x": -4,
      "y": 4,
      "z": -2,
      "name": "Rock_Marble_Cobble"
    },
    {
      "x": -4,
      "y": 5,
      "z": -2,
      "name": "Rock_Marble_Cobble"
    },
    {
      "x": -4,
      "y": 22,
      "z": -2,
      "name": "Rock_Runic_Blue_Brick"
    },
    {
      "x": -4,
      "y": 23,
      "z": -2,
      "name": "Rock_Runic_Blue_Brick"
    },
    {
      "x": -4,
      "y": 24,
      "z": -2,
      "name": "Metal_Iron_Fence",
      "rotation": 1
    },
    {
      "x": -4,
      "y": 0,
      "z": -1,
      "name": "Rock_Marble_Cobble"
    },
    {
      "x": -4,
      "y": 1,
      "z": -1,
      "name": "Rock_Marble_Cobble"
    },
    {
      "x": -4,
      "y": 2,
      "z": -1,
      "name": "Rock_Marble_Cobble"
    },
    {
      "x": -4,
      "y": 3,
      "z": -1,
      "name": "Rock_Marble_Cobble"
    },
    {
      "x": -4,
      "y": 4,
      "z": -1,
      "name": "Rock_Marble_Cobble"
    },
    {
      "x": -4,
      "y": 5,
      "z": -1,
      "name": "Rock_Marble_Cobble"
    },
    {
      "x": -4,
      "y": 6,
      "z": -1,
      "name": "Rock_Marble_Cobble_Half"
    },
    {
      "x": -4,
      "y": 21,
      "z": -1,
      "name": "Rock_Runic_Blue_Brick_Stairs",
      "rotation": 9
    },
    {
      "x": -4,
      "y": 22,
      "z": -1,
      "name": "Rock_Runic_Blue_Brick"
    },
    {
      "x": -4,
      "y": 23,
      "z": -1,
      "name": "Rock_Runic_Blue_Brick"
    },
    {
      "x": -4,
      "y": 24,
      "z": -1,
      "name": "Metal_Iron_Fence",
      "rotation": 3
    },
    {
      "x": -4,
      "y": 0,
      "z": 0,
      "name": "Wood_Hardwood_Planks"
    },
    {
      "x": -4,
      "y": 1,
      "z": 0,
      "name": "*Furniture_Village_Door_State_Definitions_CloseDoorIn",
      "rotation": 3
    },
    {
      "x": -4,
      "y": 2,
      "z": 0,
      "name": "*Furniture_Village_Door_State_Definitions_CloseDoorIn",
      "filler": 1024,
      "rotation": 3
    },
    {
      "x": -4,
      "y": 3,
      "z": 0,
      "name": "Rock_Marble_Cobble"
    },
    {
      "x": -4,
      "y": 4,
      "z": 0,
      "name": "Rock_Marble_Cobble"
    },
    {
      "x": -4,
      "y": 5,
      "z": 0,
      "name": "Rock_Marble_Cobble"
    },
    {
      "x": -4,
      "y": 22,
      "z": 0,
      "name": "Rock_Runic_Blue_Brick"
    },
    {
      "x": -4,
      "y": 23,
      "z": 0,
      "name": "Rock_Runic_Blue_Brick"
    },
    {
      "x": -4,
      "y": 24,
      "z": 0,
      "name": "Metal_Iron_Fence",
      "rotation": 3
    },
    {
      "x": -4,
      "y": 0,
      "z": 1,
      "name": "Rock_Marble_Cobble"
    },
    {
      "x": -4,
      "y": 1,
      "z": 1,
      "name": "Rock_Marble_Cobble"
    },
    {
      "x": -4,
      "y": 2,
      "z": 1,
      "name": "Rock_Marble_Cobble"
    },
    {
      "x": -4,
      "y": 3,
      "z": 1,
      "name": "Rock_Marble_Cobble"
    },
    {
      "x": -4,
      "y": 4,
      "z": 1,
      "name": "Rock_Marble_Cobble"
    },
    {
      "x": -4,
      "y": 5,
      "z": 1,
      "name": "Rock_Marble_Cobble"
    },
    {
      "x": -4,
      "y": 6,
      "z": 1,
      "name": "Rock_Marble_Cobble_Half"
    },
    {
      "x": -4,
      "y": 21,
      "z": 1,
      "name": "Rock_Runic_Blue_Brick_Stairs",
      "rotation": 9
    },
    {
      "x": -4,
      "y": 22,
      "z": 1,
      "name": "Rock_Runic_Blue_Brick"
    },
    {
      "x": -4,
      "y": 23,
      "z": 1,
      "name": "Rock_Runic_Blue_Brick"
    },
    {
      "x": -4,
      "y": 24,
      "z": 1,
      "name": "Metal_Iron_Fence",
      "rotation": 3
    },
    {
      "x": -4,
      "y": 0,
      "z": 2,
      "name": "Rock_Marble_Cobble"
    },
    {
      "x": -4,
      "y": 1,
      "z": 2,
      "name": "Rock_Marble_Cobble"
    },
    {
      "x": -4,
      "y": 2,
      "z": 2,
      "name": "Rock_Marble_Cobble"
    },
    {
      "x": -4,
      "y": 3,
      "z": 2,
      "name": "Rock_Marble_Cobble"
    },
    {
      "x": -4,
      "y": 4,
      "z": 2,
      "name": "Rock_Marble_Cobble"
    },
    {
      "x": -4,
      "y": 5,
      "z": 2,
      "name": "Rock_Marble_Cobble"
    },
    {
      "x": -4,
      "y": 22,
      "z": 2,
      "name": "Rock_Runic_Blue_Brick"
    },
    {
      "x": -4,
      "y": 23,
      "z": 2,
      "name": "Rock_Runic_Blue_Brick"
    },
    {
      "x": -4,
      "y": 24,
      "z": 2,
      "name": "Metal_Iron_Fence",
      "rotation": 3
    },
    {
      "x": -4,
      "y": 23,
      "z": 3,
      "name": "Rock_Runic_Blue_Brick"
    },
    {
      "x": -4,
      "y": 24,
      "z": 3,
      "name": "*Metal_Iron_Fence_State_Definitions_Corner",
      "rotation": 2
    },
    {
      "x": -3,
      "y": 23,
      "z": -4,
      "name": "Rock_Runic_Blue_Brick"
    },
    {
      "x": -3,
      "y": 24,
      "z": -4,
      "name": "*Metal_Iron_Fence_State_Definitions_Corner",
      "rotation": 1
    },
    {
      "x": -3,
      "y": 0,
      "z": -3,
      "name": "Rock_Marble_Cobble"
    },
    {
      "x": -3,
      "y": 1,
      "z": -3,
      "name": "Rock_Marble_Cobble"
    },
    {
      "x": -3,
      "y": 2,
      "z": -3,
      "name": "Rock_Marble_Cobble"
    },
    {
      "x": -3,
      "y": 3,
      "z": -3,
      "name": "Rock_Marble_Cobble"
    },
    {
      "x": -3,
      "y": 4,
      "z": -3,
      "name": "Rock_Marble_Cobble"
    },
    {
      "x": -3,
      "y": 5,
      "z": -3,
      "name": "Rock_Marble_Cobble"
    },
    {
      "x": -3,
      "y": 6,
      "z": -3,
      "name": "Rock_Marble_Cobble_Stairs",
      "rotation": 3
    },
    {
      "x": -3,
      "y": 22,
      "z": -3,
      "name": "Rock_Runic_Blue_Brick"
    },
    {
      "x": -3,
      "y": 23,
      "z": -3,
      "name": "Rock_Runic_Blue_Brick"
    },
    {
      "x": -3,
      "y": 24,
      "z": -3,
      "name": "*Metal_Iron_Fence_State_Definitions_Corner",
      "rotation": 3
    },
    {
      "x": -3,
      "y": 0,
      "z": -2,
      "name": "Rock_Marble_Cobble"
    },
    {
      "x": -3,
      "y": 1,
      "z": -2,
      "name": "Rock_Marble_Cobble"
    },
    {
      "x": -3,
      "y": 2,
      "z": -2,
      "name": "Rock_Marble_Cobble"
    },
    {
      "x": -3,
      "y": 3,
      "z": -2,
      "name": "Rock_Marble_Cobble"
    },
    {
      "x": -3,
      "y": 4,
      "z": -2,
      "name": "Rock_Marble_Cobble"
    },
    {
      "x": -3,
      "y": 5,
      "z": -2,
      "name": "Rock_Marble_Cobble"
    },
    {
      "x": -3,
      "y": 6,
      "z": -2,
      "name": "*Rock_Marble_Cobble_Stairs_State_Definitions_Inverted_Corner_Left",
      "rotation": 2
    },
    {
      "x": -3,
      "y": 21,
      "z": -2,
      "name": "Rock_Runic_Blue_Brick_Half",
      "rotation": 8
    },
    {
      "x": -3,
      "y": 22,
      "z": -2,
      "name": "Rock_Runic_Blue_Brick"
    },
    {
      "x": -3,
      "y": 23,
      "z": -2,
      "name": "Rock_Runic_Blue_Brick"
    },
    {
      "x": -3,
      "y": 32,
      "z": -2,
      "name": "*Rock_Marble_Cobble_Roof_Steep_State_Definitions_Corner_Right",
      "rotation": 3
    },
    {
      "x": -3,
      "y": 33,
      "z": -2,
      "name": "*Rock_Marble_Cobble_Roof_Steep_State_Definitions_Corner_Right",
      "filler": 1024,
      "rotation": 3
    },
    {
      "x": -3,
      "y": 0,
      "z": -1,
      "name": "Wood_Hardwood_Planks"
    },
    {
      "x": -3,
      "y": 1,
      "z": -1,
      "name": "Empty"
    },
    {
      "x": -3,
      "y": 5,
      "z": -1,
      "name": "Rock_Marble_Cobble"
    },
    {
      "x": -3,
      "y": 6,
      "z": -1,
      "name": "Rock_Runic_Blue_Brick"
    },
    {
      "x": -3,
      "y": 7,
      "z": -1,
      "name": "Rock_Runic_Blue_Brick"
    },
    {
      "x": -3,
      "y": 8,
      "z": -1,
      "name": "Rock_Runic_Blue_Brick"
    },
    {
      "x": -3,
      "y": 9,
      "z": -1,
      "name": "Rock_Runic_Blue_Brick"
    },
    {
      "x": -3,
      "y": 10,
      "z": -1,
      "name": "Rock_Marble_Cobble"
    },
    {
      "x": -3,
      "y": 11,
      "z": -1,
      "name": "Rock_Marble_Cobble"
    },
    {
      "x": -3,
      "y": 12,
      "z": -1,
      "name": "Rock_Marble_Cobble"
    },
    {
      "x": -3,
      "y": 13,
      "z": -1,
      "name": "Rock_Marble_Cobble"
    },
    {
      "x": -3,
      "y": 14,
      "z": -1,
      "name": "Rock_Runic_Blue_Brick"
    },
    {
      "x": -3,
      "y": 15,
      "z": -1,
      "name": "Rock_Runic_Blue_Brick"
    },
    {
      "x": -3,
      "y": 16,
      "z": -1,
      "name": "Rock_Runic_Blue_Brick"
    },
    {
      "x": -3,
      "y": 17,
      "z": -1,
      "name": "Rock_Runic_Blue_Brick"
    },
    {
      "x": -3,
      "y": 18,
      "z": -1,
      "name": "Rock_Marble_Cobble"
    },
    {
      "x": -3,
      "y": 19,
      "z": -1,
      "name": "Rock_Marble_Cobble"
    },
    {
      "x": -3,
      "y": 20,
      "z": -1,
      "name": "Rock_Marble_Cobble"
    },
    {
      "x": -3,
      "y": 21,
      "z": -1,
      "name": "Rock_Marble_Cobble"
    },
    {
      "x": -3,
      "y": 22,
      "z": -1,
      "name": "Rock_Runic_Blue_Brick"
    },
    {
      "x": -3,
      "y": 23,
      "z": -1,
      "name": "Rock_Runic_Blue_Brick"
    },
    {
      "x": -3,
      "y": 27,
      "z": -1,
      "name": "Rock_Runic_Blue_Brick_Stairs",
      "rotation": 9
    },
    {
      "x": -3,
      "y": 28,
      "z": -1,
      "name": "Rock_Runic_Blue_Brick"
    },
    {
      "x": -3,
      "y": 32,
      "z": -1,
      "name": "Rock_Marble_Cobble_Roof_Steep",
      "rotation": 3
    },
    {
      "x": -3,
      "y": 33,
      "z": -1,
      "name": "Rock_Marble_Cobble_Roof_Steep",
      "filler": 1024,
      "rotation": 3
    },
    {
      "x": -3,
      "y": 0,
      "z": 0,
      "name": "Wood_Hardwood_Planks"
    },
    {
      "x": -3,
      "y": 1,
      "z": 0,
      "name": "Empty"
    },
    {
      "x": -3,
      "y": 4,
      "z": 0,
      "name": "Rock_Marble_Cobble_Half",
      "rotation": 8
    },
    {
      "x": -3,
      "y": 5,
      "z": 0,
      "name": "Rock_Marble_Cobble"
    },
    {
      "x": -3,
      "y": 6,
      "z": 0,
      "name": "Rock_Runic_Blue_Brick"
    },
    {
      "x": -3,
      "y": 7,
      "z": 0,
      "name": "Furniture_Village_Window",
      "rotation": 1
    },
    {
      "x": -3,
      "y": 8,
      "z": 0,
      "name": "Furniture_Village_Window",
      "rotation": 1
    },
    {
      "x": -3,
      "y": 9,
      "z": 0,
      "name": "Rock_Runic_Blue_Brick"
    },
    {
      "x": -3,
      "y": 10,
      "z": 0,
      "name": "Rock_Marble_Cobble"
    },
    {
      "x": -3,
      "y": 11,
      "z": 0,
      "name": "Furniture_Village_Window",
      "rotation": 1
    },
    {
      "x": -3,
      "y": 12,
      "z": 0,
      "name": "Furniture_Village_Window",
      "rotation": 1
    },
    {
      "x": -3,
      "y": 13,
      "z": 0,
      "name": "Rock_Marble_Cobble"
    },
    {
      "x": -3,
      "y": 14,
      "z": 0,
      "name": "Rock_Runic_Blue_Brick"
    },
    {
      "x": -3,
      "y": 15,
      "z": 0,
      "name": "Furniture_Village_Window",
      "rotation": 1
    },
    {
      "x": -3,
      "y": 16,
      "z": 0,
      "name": "Furniture_Village_Window",
      "rotation": 1
    },
    {
      "x": -3,
      "y": 17,
      "z": 0,
      "name": "Rock_Runic_Blue_Brick"
    },
    {
      "x": -3,
      "y": 18,
      "z": 0,
      "name": "Rock_Marble_Cobble"
    },
    {
      "x": -3,
      "y": 19,
      "z": 0,
      "name": "Furniture_Village_Window",
      "rotation": 1
    },
    {
      "x": -3,
      "y": 20,
      "z": 0,
      "name": "Furniture_Village_Window",
      "rotation": 1
    },
    {
      "x": -3,
      "y": 21,
      "z": 0,
      "name": "Rock_Marble_Cobble"
    },
    {
      "x": -3,
      "y": 22,
      "z": 0,
      "name": "Rock_Runic_Blue_Brick"
    },
    {
      "x": -3,
      "y": 23,
      "z": 0,
      "name": "Rock_Runic_Blue_Brick"
    },
    {
      "x": -3,
      "y": 27,
      "z": 0,
      "name": "Rock_Runic_Blue_Brick_Half",
      "rotation": 7
    },
    {
      "x": -3,
      "y": 28,
      "z": 0,
      "name": "Rock_Runic_Blue_Brick"
    },
    {
      "x": -3,
      "y": 32,
      "z": 0,
      "name": "Rock_Marble_Cobble_Roof_Steep",
      "rotation": 3
    },
    {
      "x": -3,
      "y": 33,
      "z": 0,
      "name": "Rock_Marble_Cobble_Roof_Steep",
      "filler": 1024,
      "rotation": 3
    },
    {
      "x": -3,
      "y": 0,
      "z": 1,
      "name": "Wood_Hardwood_Planks"
    },
    {
      "x": -3,
      "y": 1,
      "z": 1,
      "name": "Empty"
    },
    {
      "x": -3,
      "y": 5,
      "z": 1,
      "name": "Rock_Marble_Cobble"
    },
    {
      "x": -3,
      "y": 6,
      "z": 1,
      "name": "Rock_Runic_Blue_Brick"
    },
    {
      "x": -3,
      "y": 7,
      "z": 1,
      "name": "Rock_Runic_Blue_Brick"
    },
    {
      "x": -3,
      "y": 8,
      "z": 1,
      "name": "Rock_Runic_Blue_Brick"
    },
    {
      "x": -3,
      "y": 9,
      "z": 1,
      "name": "Rock_Runic_Blue_Brick"
    },
    {
      "x": -3,
      "y": 10,
      "z": 1,
      "name": "Rock_Marble_Cobble"
    },
    {
      "x": -3,
      "y": 11,
      "z": 1,
      "name": "Rock_Marble_Cobble"
    },
    {
      "x": -3,
      "y": 12,
      "z": 1,
      "name": "Rock_Marble_Cobble"
    },
    {
      "x": -3,
      "y": 13,
      "z": 1,
      "name": "Rock_Marble_Cobble"
    },
    {
      "x": -3,
      "y": 14,
      "z": 1,
      "name": "Rock_Runic_Blue_Brick"
    },
    {
      "x": -3,
      "y": 15,
      "z": 1,
      "name": "Rock_Runic_Blue_Brick"
    },
    {
      "x": -3,
      "y": 16,
      "z": 1,
      "name": "Rock_Runic_Blue_Brick"
    },
    {
      "x": -3,
      "y": 17,
      "z": 1,
      "name": "Rock_Runic_Blue_Brick"
    },
    {
      "x": -3,
      "y": 18,
      "z": 1,
      "name": "Rock_Marble_Cobble"
    },
    {
      "x": -3,
      "y": 19,
      "z": 1,
      "name": "Rock_Marble_Cobble"
    },
    {
      "x": -3,
      "y": 20,
      "z": 1,
      "name": "Rock_Marble_Cobble"
    },
    {
      "x": -3,
      "y": 21,
      "z": 1,
      "name": "Rock_Marble_Cobble"
    },
    {
      "x": -3,
      "y": 22,
      "z": 1,
      "name": "Rock_Runic_Blue_Brick"
    },
    {
      "x": -3,
      "y": 23,
      "z": 1,
      "name": "Rock_Runic_Blue_Brick"
    },
    {
      "x": -3,
      "y": 27,
      "z": 1,
      "name": "Rock_Runic_Blue_Brick_Stairs",
      "rotation": 9
    },
    {
      "x": -3,
      "y": 28,
      "z": 1,
      "name": "Rock_Runic_Blue_Brick"
    },
    {
      "x": -3,
      "y": 32,
      "z": 1,
      "name": "Rock_Marble_Cobble_Roof_Steep",
      "rotation": 3
    },
    {
      "x": -3,
      "y": 33,
      "z": 1,
      "name": "Rock_Marble_Cobble_Roof_Steep",
      "filler": 1024,
      "rotation": 3
    },
    {
      "x": -3,
      "y": 0,
      "z": 2,
      "name": "Rock_Marble_Cobble"
    },
    {
      "x": -3,
      "y": 1,
      "z": 2,
      "name": "Rock_Marble_Cobble"
    },
    {
      "x": -3,
      "y": 2,
      "z": 2,
      "name": "Rock_Marble_Cobble"
    },
    {
      "x": -3,
      "y": 3,
      "z": 2,
      "name": "Rock_Marble_Cobble"
    },
    {
      "x": -3,
      "y": 4,
      "z": 2,
      "name": "Rock_Marble_Cobble"
    },
    {
      "x": -3,
      "y": 5,
      "z": 2,
      "name": "Rock_Marble_Cobble"
    },
    {
      "x": -3,
      "y": 6,
      "z": 2,
      "name": "*Rock_Marble_Cobble_Stairs_State_Definitions_Inverted_Corner_Right"
    },
    {
      "x": -3,
      "y": 21,
      "z": 2,
      "name": "Rock_Runic_Blue_Brick_Half",
      "rotation": 8
    },
    {
      "x": -3,
      "y": 22,
      "z": 2,
      "name": "Rock_Runic_Blue_Brick"
    },
    {
      "x": -3,
      "y": 23,
      "z": 2,
      "name": "Rock_Runic_Blue_Brick"
    },
    {
      "x": -3,
      "y": 32,
      "z": 2,
      "name": "*Rock_Marble_Cobble_Roof_Steep_State_Definitions_Corner_Left",
      "rotation": 3
    },
    {
      "x": -3,
      "y": 33,
      "z": 2,
      "name": "*Rock_Marble_Cobble_Roof_Steep_State_Definitions_Corner_Left",
      "filler": 1024,
      "rotation": 3
    },
    {
      "x": -3,
      "y": 0,
      "z": 3,
      "name": "Rock_Marble_Cobble"
    },
    {
      "x": -3,
      "y": 1,
      "z": 3,
      "name": "Rock_Marble_Cobble"
    },
    {
      "x": -3,
      "y": 2,
      "z": 3,
      "name": "Rock_Marble_Cobble"
    },
    {
      "x": -3,
      "y": 3,
      "z": 3,
      "name": "Rock_Marble_Cobble"
    },
    {
      "x": -3,
      "y": 4,
      "z": 3,
      "name": "Rock_Marble_Cobble"
    },
    {
      "x": -3,
      "y": 5,
      "z": 3,
      "name": "Rock_Marble_Cobble"
    },
    {
      "x": -3,
      "y": 6,
      "z": 3,
      "name": "Rock_Marble_Cobble_Stairs",
      "rotation": 3
    },
    {
      "x": -3,
      "y": 22,
      "z": 3,
      "name": "Rock_Runic_Blue_Brick"
    },
    {
      "x": -3,
      "y": 23,
      "z": 3,
      "name": "Rock_Runic_Blue_Brick"
    },
    {
      "x": -3,
      "y": 24,
      "z": 3,
      "name": "*Metal_Iron_Fence_State_Definitions_Corner"
    },
    {
      "x": -3,
      "y": 23,
      "z": 4,
      "name": "Rock_Runic_Blue_Brick"
    },
    {
      "x": -3,
      "y": 24,
      "z": 4,
      "name": "*Metal_Iron_Fence_State_Definitions_Corner",
      "rotation": 2
    },
    {
      "x": -2,
      "y": 23,
      "z": -5,
      "name": "Rock_Runic_Blue_Brick"
    },
    {
      "x": -2,
      "y": 24,
      "z": -5,
      "name": "*Metal_Iron_Fence_State_Definitions_Corner",
      "rotation": 1
    },
    {
      "x": -2,
      "y": 0,
      "z": -4,
      "name": "Rock_Marble_Cobble"
    },
    {
      "x": -2,
      "y": 1,
      "z": -4,
      "name": "Rock_Marble_Cobble"
    },
    {
      "x": -2,
      "y": 2,
      "z": -4,
      "name": "Rock_Marble_Cobble"
    },
    {
      "x": -2,
      "y": 3,
      "z": -4,
      "name": "Rock_Marble_Cobble"
    },
    {
      "x": -2,
      "y": 4,
      "z": -4,
      "name": "Rock_Marble_Cobble"
    },
    {
      "x": -2,
      "y": 5,
      "z": -4,
      "name": "Rock_Marble_Cobble"
    },
    {
      "x": -2,
      "y": 6,
      "z": -4,
      "name": "Rock_Marble_Cobble_Stairs",
      "rotation": 2
    },
    {
      "x": -2,
      "y": 22,
      "z": -4,
      "name": "Rock_Runic_Blue_Brick"
    },
    {
      "x": -2,
      "y": 23,
      "z": -4,
      "name": "Rock_Runic_Blue_Brick"
    },
    {
      "x": -2,
      "y": 24,
      "z": -4,
      "name": "*Metal_Iron_Fence_State_Definitions_Corner",
      "rotation": 3
    },
    {
      "x": -2,
      "y": 0,
      "z": -3,
      "name": "Wood_Hardwood_Planks"
    },
    {
      "x": -2,
      "y": 1,
      "z": -3,
      "name": "Wood_Hardwood_Planks"
    },
    {
      "x": -2,
      "y": 5,
      "z": -3,
      "name": "Rock_Marble_Cobble"
    },
    {
      "x": -2,
      "y": 6,
      "z": -3,
      "name": "Rock_Runic_Blue_Brick"
    },
    {
      "x": -2,
      "y": 7,
      "z": -3,
      "name": "Rock_Runic_Blue_Brick"
    },
    {
      "x": -2,
      "y": 8,
      "z": -3,
      "name": "Rock_Runic_Blue_Brick"
    },
    {
      "x": -2,
      "y": 9,
      "z": -3,
      "name": "Rock_Runic_Blue_Brick"
    },
    {
      "x": -2,
      "y": 10,
      "z": -3,
      "name": "Rock_Marble_Cobble"
    },
    {
      "x": -2,
      "y": 11,
      "z": -3,
      "name": "Rock_Marble_Cobble"
    },
    {
      "x": -2,
      "y": 12,
      "z": -3,
      "name": "Rock_Marble_Cobble"
    },
    {
      "x": -2,
      "y": 13,
      "z": -3,
      "name": "Rock_Marble_Cobble"
    },
    {
      "x": -2,
      "y": 14,
      "z": -3,
      "name": "Rock_Runic_Blue_Brick"
    },
    {
      "x": -2,
      "y": 15,
      "z": -3,
      "name": "Rock_Runic_Blue_Brick"
    },
    {
      "x": -2,
      "y": 16,
      "z": -3,
      "name": "Rock_Runic_Blue_Brick"
    },
    {
      "x": -2,
      "y": 17,
      "z": -3,
      "name": "Rock_Runic_Blue_Brick"
    },
    {
      "x": -2,
      "y": 18,
      "z": -3,
      "name": "Rock_Marble_Cobble"
    },
    {
      "x": -2,
      "y": 19,
      "z": -3,
      "name": "Rock_Marble_Cobble"
    },
    {
      "x": -2,
      "y": 20,
      "z": -3,
      "name": "Rock_Marble_Cobble"
    },
    {
      "x": -2,
      "y": 21,
      "z": -3,
      "name": "Rock_Marble_Cobble"
    },
    {
      "x": -2,
      "y": 22,
      "z": -3,
      "name": "Rock_Runic_Blue_Brick"
    },
    {
      "x": -2,
      "y": 23,
      "z": -3,
      "name": "Rock_Runic_Blue_Brick"
    },
    {
      "x": -2,
      "y": 32,
      "z": -3,
      "name": "*Rock_Marble_Cobble_Roof_Steep_State_Definitions_Corner_Right",
      "rotation": 3
    },
    {
      "x": -2,
      "y": 33,
      "z": -3,
      "name": "*Rock_Marble_Cobble_Roof_Steep_State_Definitions_Corner_Right",
      "filler": 1024,
      "rotation": 3
    },
    {
      "x": -2,
      "y": 0,
      "z": -2,
      "name": "Wood_Hardwood_Planks"
    },
    {
      "x": -2,
      "y": 1,
      "z": -2,
      "name": "Wood_Hardwood_Stairs"
    },
    {
      "x": -2,
      "y": 5,
      "z": -2,
      "name": "Rock_Marble_Cobble"
    },
    {
      "x": -2,
      "y": 6,
      "z": -2,
      "name": "Rock_Runic_Blue_Brick"
    },
    {
      "x": -2,
      "y": 7,
      "z": -2,
      "name": "Rock_Runic_Blue_Brick"
    },
    {
      "x": -2,
      "y": 8,
      "z": -2,
      "name": "Rock_Runic_Blue_Brick"
    },
    {
      "x": -2,
      "y": 9,
      "z": -2,
      "name": "Rock_Runic_Blue_Brick"
    },
    {
      "x": -2,
      "y": 10,
      "z": -2,
      "name": "Rock_Marble_Cobble"
    },
    {
      "x": -2,
      "y": 11,
      "z": -2,
      "name": "Rock_Marble_Cobble"
    },
    {
      "x": -2,
      "y": 12,
      "z": -2,
      "name": "Rock_Marble_Cobble"
    },
    {
      "x": -2,
      "y": 13,
      "z": -2,
      "name": "Rock_Marble_Cobble"
    },
    {
      "x": -2,
      "y": 14,
      "z": -2,
      "name": "Rock_Runic_Blue_Brick"
    },
    {
      "x": -2,
      "y": 15,
      "z": -2,
      "name": "Rock_Runic_Blue_Brick"
    },
    {
      "x": -2,
      "y": 16,
      "z": -2,
      "name": "Rock_Runic_Blue_Brick"
    },
    {
      "x": -2,
      "y": 17,
      "z": -2,
      "name": "Rock_Runic_Blue_Brick"
    },
    {
      "x": -2,
      "y": 18,
      "z": -2,
      "name": "Rock_Marble_Cobble"
    },
    {
      "x": -2,
      "y": 19,
      "z": -2,
      "name": "Rock_Marble_Cobble"
    },
    {
      "x": -2,
      "y": 20,
      "z": -2,
      "name": "Rock_Marble_Cobble"
    },
    {
      "x": -2,
      "y": 21,
      "z": -2,
      "name": "Rock_Marble_Cobble"
    },
    {
      "x": -2,
      "y": 22,
      "z": -2,
      "name": "Rock_Runic_Blue_Brick"
    },
    {
      "x": -2,
      "y": 23,
      "z": -2,
      "name": "Rock_Runic_Blue_Brick"
    },
    {
      "x": -2,
      "y": 27,
      "z": -2,
      "name": "Rock_Runic_Blue_Brick_Stairs",
      "rotation": 8
    },
    {
      "x": -2,
      "y": 28,
      "z": -2,
      "name": "Rock_Runic_Blue_Brick"
    },
    {
      "x": -2,
      "y": 32,
      "z": -2,
      "name": "*Rock_Marble_Cobble_Roof_Steep_State_Definitions_Inverted_Corner_Left",
      "rotation": 2
    },
    {
      "x": -2,
      "y": 33,
      "z": -2,
      "name": "*Rock_Marble_Cobble_Roof_Steep_State_Definitions_Inverted_Corner_Left",
      "filler": 1024,
      "rotation": 2
    },
    {
      "x": -2,
      "y": 0,
      "z": -1,
      "name": "Wood_Hardwood_Planks"
    },
    {
      "x": -2,
      "y": 1,
      "z": -1,
      "name": "Empty"
    },
    {
      "x": -2,
      "y": 6,
      "z": -1,
      "name": "Wood_Hardwood_Stairs"
    },
    {
      "x": -2,
      "y": 10,
      "z": -1,
      "name": "Wood_Hardwood_Stairs"
    },
    {
      "x": -2,
      "y": 14,
      "z": -1,
      "name": "Wood_Hardwood_Stairs"
    },
    {
      "x": -2,
      "y": 18,
      "z": -1,
      "name": "Wood_Hardwood_Stairs"
    },
    {
      "x": -2,
      "y": 22,
      "z": -1,
      "name": "*Rock_Runic_Blue_Brick_Stairs_State_Definitions_Inverted_Corner_Right",
      "rotation": 10
    },
    {
      "x": -2,
      "y": 23,
      "z": -1,
      "name": "Rock_Runic_Blue_Brick"
    },
    {
      "x": -2,
      "y": 24,
      "z": -1,
      "name": "Rock_Marble_Cobble"
    },
    {
      "x": -2,
      "y": 25,
      "z": -1,
      "name": "Rock_Marble_Cobble"
    },
    {
      "x": -2,
      "y": 26,
      "z": -1,
      "name": "Rock_Marble_Cobble"
    },
    {
      "x": -2,
      "y": 27,
      "z": -1,
      "name": "Rock_Marble_Cobble"
    },
    {
      "x": -2,
      "y": 28,
      "z": -1,
      "name": "Rock_Runic_Blue_Brick"
    },
    {
      "x": -2,
      "y": 33,
      "z": -1,
      "name": "Rock_Marble_Cobble_Stairs",
      "rotation": 11
    },
    {
      "x": -2,
      "y": 34,
      "z": -1,
      "name": "*Rock_Marble_Cobble_Roof_State_Definitions_Corner_Right",
      "rotation": 3
    },
    {
      "x": -2,
      "y": 0,
      "z": 0,
      "name": "Wood_Hardwood_Planks"
    },
    {
      "x": -2,
      "y": 1,
      "z": 0,
      "name": "Empty"
    },
    {
      "x": -2,
      "y": 5,
      "z": 0,
      "name": "Wood_Hardwood_Planks_Half",
      "rotation": 8
    },
    {
      "x": -2,
      "y": 9,
      "z": 0,
      "name": "Wood_Hardwood_Planks_Half",
      "rotation": 8
    },
    {
      "x": -2,
      "y": 13,
      "z": 0,
      "name": "Wood_Hardwood_Planks_Half",
      "rotation": 8
    },
    {
      "x": -2,
      "y": 17,
      "z": 0,
      "name": "Wood_Hardwood_Planks_Half",
      "rotation": 8
    },
    {
      "x": -2,
      "y": 22,
      "z": 0,
      "name": "Rock_Runic_Blue_Brick_Stairs",
      "rotation": 11
    },
    {
      "x": -2,
      "y": 23,
      "z": 0,
      "name": "Rock_Runic_Blue_Brick"
    },
    {
      "x": -2,
      "y": 24,
      "z": 0,
      "name": "*Furniture_Village_Door_State_Definitions_CloseDoorOut",
      "rotation": 3
    },
    {
      "x": -2,
      "y": 25,
      "z": 0,
      "name": "*Furniture_Village_Door_State_Definitions_CloseDoorOut",
      "filler": 1024,
      "rotation": 3
    },
    {
      "x": -2,
      "y": 26,
      "z": 0,
      "name": "Rock_Marble_Cobble"
    },
    {
      "x": -2,
      "y": 27,
      "z": 0,
      "name": "Rock_Marble_Cobble"
    },
    {
      "x": -2,
      "y": 28,
      "z": 0,
      "name": "Rock_Runic_Blue_Brick"
    },
    {
      "x": -2,
      "y": 33,
      "z": 0,
      "name": "Rock_Marble_Cobble_Half",
      "rotation": 8
    },
    {
      "x": -2,
      "y": 34,
      "z": 0,
      "name": "Rock_Marble_Cobble_Roof",
      "rotation": 3
    },
    {
      "x": -2,
      "y": 0,
      "z": 1,
      "name": "Wood_Hardwood_Planks"
    },
    {
      "x": -2,
      "y": 1,
      "z": 1,
      "name": "Empty"
    },
    {
      "x": -2,
      "y": 5,
      "z": 1,
      "name": "Wood_Hardwood_Planks_Half",
      "rotation": 8
    },
    {
      "x": -2,
      "y": 9,
      "z": 1,
      "name": "Wood_Hardwood_Planks_Half",
      "rotation": 8
    },
    {
      "x": -2,
      "y": 13,
      "z": 1,
      "name": "Wood_Hardwood_Planks_Half",
      "rotation": 8
    },
    {
      "x": -2,
      "y": 17,
      "z": 1,
      "name": "Wood_Hardwood_Planks_Half",
      "rotation": 8
    },
    {
      "x": -2,
      "y": 22,
      "z": 1,
      "name": "*Rock_Runic_Blue_Brick_Stairs_State_Definitions_Inverted_Corner_Left",
      "rotation": 8
    },
    {
      "x": -2,
      "y": 23,
      "z": 1,
      "name": "Rock_Runic_Blue_Brick"
    },
    {
      "x": -2,
      "y": 24,
      "z": 1,
      "name": "Rock_Marble_Cobble"
    },
    {
      "x": -2,
      "y": 25,
      "z": 1,
      "name": "Rock_Marble_Cobble"
    },
    {
      "x": -2,
      "y": 26,
      "z": 1,
      "name": "Rock_Marble_Cobble"
    },
    {
      "x": -2,
      "y": 27,
      "z": 1,
      "name": "Rock_Marble_Cobble"
    },
    {
      "x": -2,
      "y": 28,
      "z": 1,
      "name": "Rock_Runic_Blue_Brick"
    },
    {
      "x": -2,
      "y": 33,
      "z": 1,
      "name": "Rock_Marble_Cobble_Stairs",
      "rotation": 11
    },
    {
      "x": -2,
      "y": 34,
      "z": 1,
      "name": "*Rock_Marble_Cobble_Roof_State_Definitions_Corner_Right"
    },
    {
      "x": -2,
      "y": 0,
      "z": 2,
      "name": "Wood_Hardwood_Planks"
    },
    {
      "x": -2,
      "y": 1,
      "z": 2,
      "name": "Empty"
    },
    {
      "x": -2,
      "y": 5,
      "z": 2,
      "name": "Rock_Marble_Cobble"
    },
    {
      "x": -2,
      "y": 6,
      "z": 2,
      "name": "Rock_Runic_Blue_Brick"
    },
    {
      "x": -2,
      "y": 7,
      "z": 2,
      "name": "Rock_Runic_Blue_Brick"
    },
    {
      "x": -2,
      "y": 8,
      "z": 2,
      "name": "Rock_Runic_Blue_Brick"
    },
    {
      "x": -2,
      "y": 9,
      "z": 2,
      "name": "Rock_Runic_Blue_Brick"
    },
    {
      "x": -2,
      "y": 10,
      "z": 2,
      "name": "Rock_Marble_Cobble"
    },
    {
      "x": -2,
      "y": 11,
      "z": 2,
      "name": "Rock_Marble_Cobble"
    },
    {
      "x": -2,
      "y": 12,
      "z": 2,
      "name": "Rock_Marble_Cobble"
    },
    {
      "x": -2,
      "y": 13,
      "z": 2,
      "name": "Rock_Marble_Cobble"
    },
    {
      "x": -2,
      "y": 14,
      "z": 2,
      "name": "Rock_Runic_Blue_Brick"
    },
    {
      "x": -2,
      "y": 15,
      "z": 2,
      "name": "Rock_Runic_Blue_Brick"
    },
    {
      "x": -2,
      "y": 16,
      "z": 2,
      "name": "Rock_Runic_Blue_Brick"
    },
    {
      "x": -2,
      "y": 17,
      "z": 2,
      "name": "Rock_Runic_Blue_Brick"
    },
    {
      "x": -2,
      "y": 18,
      "z": 2,
      "name": "Rock_Marble_Cobble"
    },
    {
      "x": -2,
      "y": 19,
      "z": 2,
      "name": "Rock_Marble_Cobble"
    },
    {
      "x": -2,
      "y": 20,
      "z": 2,
      "name": "Rock_Marble_Cobble"
    },
    {
      "x": -2,
      "y": 21,
      "z": 2,
      "name": "Rock_Marble_Cobble"
    },
    {
      "x": -2,
      "y": 22,
      "z": 2,
      "name": "Rock_Runic_Blue_Brick"
    },
    {
      "x": -2,
      "y": 23,
      "z": 2,
      "name": "Rock_Runic_Blue_Brick"
    },
    {
      "x": -2,
      "y": 27,
      "z": 2,
      "name": "Rock_Runic_Blue_Brick_Stairs",
      "rotation": 10
    },
    {
      "x": -2,
      "y": 28,
      "z": 2,
      "name": "Rock_Runic_Blue_Brick"
    },
    {
      "x": -2,
      "y": 32,
      "z": 2,
      "name": "*Rock_Marble_Cobble_Roof_Steep_State_Definitions_Inverted_Corner_Right"
    },
    {
      "x": -2,
      "y": 33,
      "z": 2,
      "name": "*Rock_Marble_Cobble_Roof_Steep_State_Definitions_Inverted_Corner_Right",
      "filler": 1024
    },
    {
      "x": -2,
      "y": 0,
      "z": 3,
      "name": "Wood_Hardwood_Planks"
    },
    {
      "x": -2,
      "y": 1,
      "z": 3,
      "name": "Empty"
    },
    {
      "x": -2,
      "y": 2,
      "z": 3,
      "name": "Deco_Wallchain",
      "rotation": 1
    },
    {
      "x": -2,
      "y": 3,
      "z": 3,
      "name": "Deco_Wallchain",
      "rotation": 1
    },
    {
      "x": -2,
      "y": 5,
      "z": 3,
      "name": "Rock_Marble_Cobble"
    },
    {
      "x": -2,
      "y": 6,
      "z": 3,
      "name": "Rock_Runic_Blue_Brick"
    },
    {
      "x": -2,
      "y": 7,
      "z": 3,
      "name": "Rock_Runic_Blue_Brick"
    },
    {
      "x": -2,
      "y": 8,
      "z": 3,
      "name": "Rock_Runic_Blue_Brick"
    },
    {
      "x": -2,
      "y": 9,
      "z": 3,
      "name": "Rock_Runic_Blue_Brick"
    },
    {
      "x": -2,
      "y": 10,
      "z": 3,
      "name": "Rock_Marble_Cobble"
    },
    {
      "x": -2,
      "y": 11,
      "z": 3,
      "name": "Rock_Marble_Cobble"
    },
    {
      "x": -2,
      "y": 12,
      "z": 3,
      "name": "Rock_Marble_Cobble"
    },
    {
      "x": -2,
      "y": 13,
      "z": 3,
      "name": "Rock_Marble_Cobble"
    },
    {
      "x": -2,
      "y": 14,
      "z": 3,
      "name": "Rock_Runic_Blue_Brick"
    },
    {
      "x": -2,
      "y": 15,
      "z": 3,
      "name": "Rock_Runic_Blue_Brick"
    },
    {
      "x": -2,
      "y": 16,
      "z": 3,
      "name": "Rock_Runic_Blue_Brick"
    },
    {
      "x": -2,
      "y": 17,
      "z": 3,
      "name": "Rock_Runic_Blue_Brick"
    },
    {
      "x": -2,
      "y": 18,
      "z": 3,
      "name": "Rock_Marble_Cobble"
    },
    {
      "x": -2,
      "y": 19,
      "z": 3,
      "name": "Rock_Marble_Cobble"
    },
    {
      "x": -2,
      "y": 20,
      "z": 3,
      "name": "Rock_Marble_Cobble"
    },
    {
      "x": -2,
      "y": 21,
      "z": 3,
      "name": "Rock_Marble_Cobble"
    },
    {
      "x": -2,
      "y": 22,
      "z": 3,
      "name": "Rock_Runic_Blue_Brick"
    },
    {
      "x": -2,
      "y": 23,
      "z": 3,
      "name": "Rock_Runic_Blue_Brick"
    },
    {
      "x": -2,
      "y": 32,
      "z": 3,
      "name": "*Rock_Marble_Cobble_Roof_Steep_State_Definitions_Corner_Left",
      "rotation": 3
    },
    {
      "x": -2,
      "y": 33,
      "z": 3,
      "name": "*Rock_Marble_Cobble_Roof_Steep_State_Definitions_Corner_Left",
      "filler": 1024,
      "rotation": 3
    },
    {
      "x": -2,
      "y": 0,
      "z": 4,
      "name": "Rock_Marble_Cobble"
    },
    {
      "x": -2,
      "y": 1,
      "z": 4,
      "name": "Rock_Marble_Cobble"
    },
    {
      "x": -2,
      "y": 2,
      "z": 4,
      "name": "Rock_Marble_Cobble"
    },
    {
      "x": -2,
      "y": 3,
      "z": 4,
      "name": "Rock_Marble_Cobble"
    },
    {
      "x": -2,
      "y": 4,
      "z": 4,
      "name": "Rock_Marble_Cobble"
    },
    {
      "x": -2,
      "y": 5,
      "z": 4,
      "name": "Rock_Marble_Cobble"
    },
    {
      "x": -2,
      "y": 6,
      "z": 4,
      "name": "Rock_Marble_Cobble_Stairs"
    },
    {
      "x": -2,
      "y": 22,
      "z": 4,
      "name": "Rock_Runic_Blue_Brick"
    },
    {
      "x": -2,
      "y": 23,
      "z": 4,
      "name": "Rock_Runic_Blue_Brick"
    },
    {
      "x": -2,
      "y": 24,
      "z": 4,
      "name": "*Metal_Iron_Fence_State_Definitions_Corner"
    },
    {
      "x": -2,
      "y": 23,
      "z": 5,
      "name": "Rock_Runic_Blue_Brick"
    },
    {
      "x": -2,
      "y": 24,
      "z": 5,
      "name": "*Metal_Iron_Fence_State_Definitions_Corner",
      "rotation": 2
    },
    {
      "x": -1,
      "y": 0,
      "z": -5,
      "name": "Rock_Marble_Cobble"
    },
    {
      "x": -1,
      "y": 1,
      "z": -5,
      "name": "Rock_Marble_Cobble"
    },
    {
      "x": -1,
      "y": 2,
      "z": -5,
      "name": "Rock_Marble_Cobble"
    },
    {
      "x": -1,
      "y": 3,
      "z": -5,
      "name": "Rock_Marble_Cobble"
    },
    {
      "x": -1,
      "y": 4,
      "z": -5,
      "name": "Rock_Marble_Cobble"
    },
    {
      "x": -1,
      "y": 5,
      "z": -5,
      "name": "Rock_Marble_Cobble"
    },
    {
      "x": -1,
      "y": 22,
      "z": -5,
      "name": "Rock_Runic_Blue_Brick"
    },
    {
      "x": -1,
      "y": 23,
      "z": -5,
      "name": "Rock_Runic_Blue_Brick"
    },
    {
      "x": -1,
      "y": 24,
      "z": -5,
      "name": "Metal_Iron_Fence",
      "rotation": 2
    },
    {
      "x": -1,
      "y": 0,
      "z": -4,
      "name": "Rock_Marble_Cobble"
    },
    {
      "x": -1,
      "y": 1,
      "z": -4,
      "name": "Rock_Marble_Cobble"
    },
    {
      "x": -1,
      "y": 2,
      "z": -4,
      "name": "Rock_Marble_Cobble"
    },
    {
      "x": -1,
      "y": 3,
      "z": -4,
      "name": "Rock_Marble_Cobble"
    },
    {
      "x": -1,
      "y": 4,
      "z": -4,
      "name": "Rock_Marble_Cobble"
    },
    {
      "x": -1,
      "y": 5,
      "z": -4,
      "name": "Rock_Marble_Cobble"
    },
    {
      "x": -1,
      "y": 6,
      "z": -4,
      "name": "*Rock_Marble_Cobble_Stairs_State_Definitions_Inverted_Corner_Right",
      "rotation": 3
    },
    {
      "x": -1,
      "y": 21,
      "z": -4,
      "name": "Rock_Runic_Blue_Brick_Half",
      "rotation": 8
    },
    {
      "x": -1,
      "y": 22,
      "z": -4,
      "name": "Rock_Runic_Blue_Brick"
    },
    {
      "x": -1,
      "y": 23,
      "z": -4,
      "name": "Rock_Runic_Blue_Brick"
    },
    {
      "x": -1,
      "y": 32,
      "z": -4,
      "name": "*Rock_Marble_Cobble_Roof_Steep_State_Definitions_Corner_Right",
      "rotation": 3
    },
    {
      "x": -1,
      "y": 33,
      "z": -4,
      "name": "*Rock_Marble_Cobble_Roof_Steep_State_Definitions_Corner_Right",
      "filler": 1024,
      "rotation": 3
    },
    {
      "x": -1,
      "y": 0,
      "z": -3,
      "name": "Wood_Hardwood_Planks"
    },
    {
      "x": -1,
      "y": 1,
      "z": -3,
      "name": "Wood_Hardwood_Planks"
    },
    {
      "x": -1,
      "y": 5,
      "z": -3,
      "name": "Rock_Marble_Cobble"
    },
    {
      "x": -1,
      "y": 6,
      "z": -3,
      "name": "Rock_Runic_Blue_Brick"
    },
    {
      "x": -1,
      "y": 7,
      "z": -3,
      "name": "Rock_Runic_Blue_Brick"
    },
    {
      "x": -1,
      "y": 8,
      "z": -3,
      "name": "Rock_Runic_Blue_Brick"
    },
    {
      "x": -1,
      "y": 9,
      "z": -3,
      "name": "Rock_Runic_Blue_Brick"
    },
    {
      "x": -1,
      "y": 10,
      "z": -3,
      "name": "Rock_Marble_Cobble"
    },
    {
      "x": -1,
      "y": 11,
      "z": -3,
      "name": "Rock_Marble_Cobble"
    },
    {
      "x": -1,
      "y": 12,
      "z": -3,
      "name": "Rock_Marble_Cobble"
    },
    {
      "x": -1,
      "y": 13,
      "z": -3,
      "name": "Rock_Marble_Cobble"
    },
    {
      "x": -1,
      "y": 14,
      "z": -3,
      "name": "Rock_Runic_Blue_Brick"
    },
    {
      "x": -1,
      "y": 15,
      "z": -3,
      "name": "Rock_Runic_Blue_Brick"
    },
    {
      "x": -1,
      "y": 16,
      "z": -3,
      "name": "Rock_Runic_Blue_Brick"
    },
    {
      "x": -1,
      "y": 17,
      "z": -3,
      "name": "Rock_Runic_Blue_Brick"
    },
    {
      "x": -1,
      "y": 18,
      "z": -3,
      "name": "Rock_Marble_Cobble"
    },
    {
      "x": -1,
      "y": 19,
      "z": -3,
      "name": "Rock_Marble_Cobble"
    },
    {
      "x": -1,
      "y": 20,
      "z": -3,
      "name": "Rock_Marble_Cobble"
    },
    {
      "x": -1,
      "y": 21,
      "z": -3,
      "name": "Rock_Marble_Cobble"
    },
    {
      "x": -1,
      "y": 22,
      "z": -3,
      "name": "Rock_Runic_Blue_Brick"
    },
    {
      "x": -1,
      "y": 23,
      "z": -3,
      "name": "Rock_Runic_Blue_Brick"
    },
    {
      "x": -1,
      "y": 27,
      "z": -3,
      "name": "Rock_Runic_Blue_Brick_Stairs",
      "rotation": 9
    },
    {
      "x": -1,
      "y": 28,
      "z": -3,
      "name": "Rock_Runic_Blue_Brick"
    },
    {
      "x": -1,
      "y": 32,
      "z": -3,
      "name": "*Rock_Marble_Cobble_Roof_Steep_State_Definitions_Inverted_Corner_Left",
      "rotation": 2
    },
    {
      "x": -1,
      "y": 33,
      "z": -3,
      "name": "*Rock_Marble_Cobble_Roof_Steep_State_Definitions_Inverted_Corner_Left",
      "filler": 1024,
      "rotation": 2
    },
    {
      "x": -1,
      "y": 0,
      "z": -2,
      "name": "Wood_Hardwood_Planks"
    },
    {
      "x": -1,
      "y": 1,
      "z": -2,
      "name": "*Wood_Hardwood_Stairs_State_Definitions_Inverted_Corner_Left",
      "rotation": 3
    },
    {
      "x": -1,
      "y": 6,
      "z": -2,
      "name": "Wood_Hardwood_Planks_Half",
      "rotation": 8
    },
    {
      "x": -1,
      "y": 10,
      "z": -2,
      "name": "Wood_Hardwood_Planks_Half",
      "rotation": 8
    },
    {
      "x": -1,
      "y": 14,
      "z": -2,
      "name": "Wood_Hardwood_Planks_Half",
      "rotation": 8
    },
    {
      "x": -1,
      "y": 18,
      "z": -2,
      "name": "Wood_Hardwood_Planks_Half",
      "rotation": 8
    },
    {
      "x": -1,
      "y": 22,
      "z": -2,
      "name": "Rock_Runic_Blue_Brick"
    },
    {
      "x": -1,
      "y": 23,
      "z": -2,
      "name": "Rock_Runic_Blue_Brick"
    },
    {
      "x": -1,
      "y": 24,
      "z": -2,
      "name": "Rock_Marble_Cobble"
    },
    {
      "x": -1,
      "y": 25,
      "z": -2,
      "name": "Rock_Marble_Cobble"
    },
    {
      "x": -1,
      "y": 26,
      "z": -2,
      "name": "Rock_Marble_Cobble"
    },
    {
      "x": -1,
      "y": 27,
      "z": -2,
      "name": "Rock_Marble_Cobble"
    },
    {
      "x": -1,
      "y": 28,
      "z": -2,
      "name": "Rock_Marble_Cobble"
    },
    {
      "x": -1,
      "y": 29,
      "z": -2,
      "name": "Rock_Marble_Brick_Pillar_Base"
    },
    {
      "x": -1,
      "y": 30,
      "z": -2,
      "name": "Rock_Marble_Brick_Pillar_Middle"
    },
    {
      "x": -1,
      "y": 31,
      "z": -2,
      "name": "Rock_Marble_Brick_Pillar_Middle",
      "rotation": 8
    },
    {
      "x": -1,
      "y": 32,
      "z": -2,
      "name": "Rock_Marble_Brick_Pillar_Middle",
      "rotation": 8
    },
    {
      "x": -1,
      "y": 33,
      "z": -2,
      "name": "Rock_Marble_Brick_Pillar_Base",
      "rotation": 8
    },
    {
      "x": -1,
      "y": 34,
      "z": -2,
      "name": "*Rock_Marble_Cobble_Roof_State_Definitions_Corner_Right",
      "rotation": 3
    },
    {
      "x": -1,
      "y": 0,
      "z": -1,
      "name": "Wood_Hardwood_Planks"
    },
    {
      "x": -1,
      "y": 1,
      "z": -1,
      "name": "Empty"
    },
    {
      "x": -1,
      "y": 6,
      "z": -1,
      "name": "*Wood_Hardwood_Stairs_State_Definitions_Inverted_Corner_Left",
      "rotation": 3
    },
    {
      "x": -1,
      "y": 10,
      "z": -1,
      "name": "*Wood_Hardwood_Stairs_State_Definitions_Inverted_Corner_Right"
    },
    {
      "x": -1,
      "y": 14,
      "z": -1,
      "name": "*Wood_Hardwood_Stairs_State_Definitions_Inverted_Corner_Right"
    },
    {
      "x": -1,
      "y": 18,
      "z": -1,
      "name": "*Wood_Hardwood_Stairs_State_Definitions_Inverted_Corner_Right"
    },
    {
      "x": -1,
      "y": 23,
      "z": -1,
      "name": "Wood_Hardwood_Planks"
    },
    {
      "x": -1,
      "y": 28,
      "z": -1,
      "name": "Rock_Marble_Cobble"
    },
    {
      "x": -1,
      "y": 29,
      "z": -1,
      "name": "Deco_Iron_Bars",
      "rotation": 1
    },
    {
      "x": -1,
      "y": 34,
      "z": -1,
      "name": "*Rock_Marble_Cobble_Roof_Hollow_State_Definitions_Inverted_Corner_Left",
      "rotation": 2
    },
    {
      "x": -1,
      "y": 0,
      "z": 0,
      "name": "Wood_Hardwood_Planks"
    },
    {
      "x": -1,
      "y": 1,
      "z": 0,
      "name": "Empty"
    },
    {
      "x": -1,
      "y": 6,
      "z": 0,
      "name": "*Wood_Hardwood_Stairs_State_Definitions_Corner_Right"
    },
    {
      "x": -1,
      "y": 10,
      "z": 0,
      "name": "*Wood_Hardwood_Stairs_State_Definitions_Corner_Left",
      "rotation": 3
    },
    {
      "x": -1,
      "y": 14,
      "z": 0,
      "name": "*Wood_Hardwood_Stairs_State_Definitions_Corner_Left",
      "rotation": 3
    },
    {
      "x": -1,
      "y": 18,
      "z": 0,
      "name": "*Wood_Hardwood_Stairs_State_Definitions_Corner_Left",
      "rotation": 3
    },
    {
      "x": -1,
      "y": 23,
      "z": 0,
      "name": "Wood_Hardwood_Planks"
    },
    {
      "x": -1,
      "y": 28,
      "z": 0,
      "name": "Rock_Marble_Cobble"
    },
    {
      "x": -1,
      "y": 29,
      "z": 0,
      "name": "Deco_Iron_Bars",
      "rotation": 1
    },
    {
      "x": -1,
      "y": 34,
      "z": 0,
      "name": "Rock_Marble_Cobble_Half",
      "rotation": 8
    },
    {
      "x": -1,
      "y": 35,
      "z": 0,
      "name": "Rock_Marble_Cobble_Roof_Shallow",
      "rotation": 3
    },
    {
      "x": -1,
      "y": 0,
      "z": 1,
      "name": "Wood_Hardwood_Planks"
    },
    {
      "x": -1,
      "y": 1,
      "z": 1,
      "name": "Empty"
    },
    {
      "x": -1,
      "y": 5,
      "z": 1,
      "name": "Wood_Hardwood_Planks_Half",
      "rotation": 8
    },
    {
      "x": -1,
      "y": 9,
      "z": 1,
      "name": "Wood_Hardwood_Planks_Half",
      "rotation": 8
    },
    {
      "x": -1,
      "y": 13,
      "z": 1,
      "name": "Wood_Hardwood_Planks_Half",
      "rotation": 8
    },
    {
      "x": -1,
      "y": 17,
      "z": 1,
      "name": "Wood_Hardwood_Planks_Half",
      "rotation": 8
    },
    {
      "x": -1,
      "y": 23,
      "z": 1,
      "name": "Wood_Hardwood_Planks"
    },
    {
      "x": -1,
      "y": 28,
      "z": 1,
      "name": "Rock_Marble_Cobble"
    },
    {
      "x": -1,
      "y": 29,
      "z": 1,
      "name": "Deco_Iron_Bars",
      "rotation": 1
    },
    {
      "x": -1,
      "y": 34,
      "z": 1,
      "name": "*Rock_Marble_Cobble_Roof_Hollow_State_Definitions_Inverted_Corner_Left",
      "rotation": 3
    },
    {
      "x": -1,
      "y": 0,
      "z": 2,
      "name": "Wood_Hardwood_Planks"
    },
    {
      "x": -1,
      "y": 1,
      "z": 2,
      "name": "Empty"
    },
    {
      "x": -1,
      "y": 5,
      "z": 2,
      "name": "Wood_Hardwood_Planks_Half",
      "rotation": 8
    },
    {
      "x": -1,
      "y": 9,
      "z": 2,
      "name": "Wood_Hardwood_Planks_Half",
      "rotation": 8
    },
    {
      "x": -1,
      "y": 13,
      "z": 2,
      "name": "Wood_Hardwood_Planks_Half",
      "rotation": 8
    },
    {
      "x": -1,
      "y": 17,
      "z": 2,
      "name": "Wood_Hardwood_Planks_Half",
      "rotation": 8
    },
    {
      "x": -1,
      "y": 22,
      "z": 2,
      "name": "Rock_Runic_Blue_Brick"
    },
    {
      "x": -1,
      "y": 23,
      "z": 2,
      "name": "Rock_Runic_Blue_Brick"
    },
    {
      "x": -1,
      "y": 24,
      "z": 2,
      "name": "Rock_Marble_Cobble"
    },
    {
      "x": -1,
      "y": 25,
      "z": 2,
      "name": "Rock_Marble_Cobble"
    },
    {
      "x": -1,
      "y": 26,
      "z": 2,
      "name": "Rock_Marble_Cobble"
    },
    {
      "x": -1,
      "y": 27,
      "z": 2,
      "name": "Rock_Marble_Cobble"
    },
    {
      "x": -1,
      "y": 28,
      "z": 2,
      "name": "Rock_Marble_Cobble"
    },
    {
      "x": -1,
      "y": 29,
      "z": 2,
      "name": "Rock_Marble_Brick_Pillar_Base"
    },
    {
      "x": -1,
      "y": 30,
      "z": 2,
      "name": "Rock_Marble_Brick_Pillar_Middle"
    },
    {
      "x": -1,
      "y": 31,
      "z": 2,
      "name": "Rock_Marble_Brick_Pillar_Middle"
    },
    {
      "x": -1,
      "y": 32,
      "z": 2,
      "name": "Rock_Marble_Brick_Pillar_Middle"
    },
    {
      "x": -1,
      "y": 33,
      "z": 2,
      "name": "Rock_Marble_Brick_Pillar_Base",
      "rotation": 8
    },
    {
      "x": -1,
      "y": 34,
      "z": 2,
      "name": "*Rock_Marble_Cobble_Roof_State_Definitions_Corner_Right"
    },
    {
      "x": -1,
      "y": 0,
      "z": 3,
      "name": "Wood_Hardwood_Planks"
    },
    {
      "x": -1,
      "y": 1,
      "z": 3,
      "name": "Empty"
    },
    {
      "x": -1,
      "y": 5,
      "z": 3,
      "name": "Rock_Marble_Cobble"
    },
    {
      "x": -1,
      "y": 6,
      "z": 3,
      "name": "Rock_Runic_Blue_Brick"
    },
    {
      "x": -1,
      "y": 7,
      "z": 3,
      "name": "Rock_Runic_Blue_Brick"
    },
    {
      "x": -1,
      "y": 8,
      "z": 3,
      "name": "Rock_Runic_Blue_Brick"
    },
    {
      "x": -1,
      "y": 9,
      "z": 3,
      "name": "Rock_Runic_Blue_Brick"
    },
    {
      "x": -1,
      "y": 10,
      "z": 3,
      "name": "Rock_Marble_Cobble"
    },
    {
      "x": -1,
      "y": 11,
      "z": 3,
      "name": "Rock_Marble_Cobble"
    },
    {
      "x": -1,
      "y": 12,
      "z": 3,
      "name": "Rock_Marble_Cobble"
    },
    {
      "x": -1,
      "y": 13,
      "z": 3,
      "name": "Rock_Marble_Cobble"
    },
    {
      "x": -1,
      "y": 14,
      "z": 3,
      "name": "Rock_Runic_Blue_Brick"
    },
    {
      "x": -1,
      "y": 15,
      "z": 3,
      "name": "Rock_Runic_Blue_Brick"
    },
    {
      "x": -1,
      "y": 16,
      "z": 3,
      "name": "Rock_Runic_Blue_Brick"
    },
    {
      "x": -1,
      "y": 17,
      "z": 3,
      "name": "Rock_Runic_Blue_Brick"
    },
    {
      "x": -1,
      "y": 18,
      "z": 3,
      "name": "Rock_Marble_Cobble"
    },
    {
      "x": -1,
      "y": 19,
      "z": 3,
      "name": "Rock_Marble_Cobble"
    },
    {
      "x": -1,
      "y": 20,
      "z": 3,
      "name": "Rock_Marble_Cobble"
    },
    {
      "x": -1,
      "y": 21,
      "z": 3,
      "name": "Rock_Marble_Cobble"
    },
    {
      "x": -1,
      "y": 22,
      "z": 3,
      "name": "Rock_Runic_Blue_Brick"
    },
    {
      "x": -1,
      "y": 23,
      "z": 3,
      "name": "Rock_Runic_Blue_Brick"
    },
    {
      "x": -1,
      "y": 27,
      "z": 3,
      "name": "Rock_Runic_Blue_Brick_Stairs",
      "rotation": 9
    },
    {
      "x": -1,
      "y": 28,
      "z": 3,
      "name": "Rock_Runic_Blue_Brick"
    },
    {
      "x": -1,
      "y": 32,
      "z": 3,
      "name": "*Rock_Marble_Cobble_Roof_Steep_State_Definitions_Inverted_Corner_Right"
    },
    {
      "x": -1,
      "y": 33,
      "z": 3,
      "name": "*Rock_Marble_Cobble_Roof_Steep_State_Definitions_Inverted_Corner_Right",
      "filler": 1024
    },
    {
      "x": -1,
      "y": 0,
      "z": 4,
      "name": "Rock_Marble_Cobble"
    },
    {
      "x": -1,
      "y": 1,
      "z": 4,
      "name": "Rock_Marble_Cobble"
    },
    {
      "x": -1,
      "y": 2,
      "z": 4,
      "name": "Rock_Marble_Cobble"
    },
    {
      "x": -1,
      "y": 3,
      "z": 4,
      "name": "Rock_Marble_Cobble"
    },
    {
      "x": -1,
      "y": 4,
      "z": 4,
      "name": "Rock_Marble_Cobble"
    },
    {
      "x": -1,
      "y": 5,
      "z": 4,
      "name": "Rock_Marble_Cobble"
    },
    {
      "x": -1,
      "y": 6,
      "z": 4,
      "name": "*Rock_Marble_Cobble_Stairs_State_Definitions_Inverted_Corner_Left",
      "rotation": 3
    },
    {
      "x": -1,
      "y": 21,
      "z": 4,
      "name": "Rock_Runic_Blue_Brick_Half",
      "rotation": 8
    },
    {
      "x": -1,
      "y": 22,
      "z": 4,
      "name": "Rock_Runic_Blue_Brick"
    },
    {
      "x": -1,
      "y": 23,
      "z": 4,
      "name": "Rock_Runic_Blue_Brick"
    },
    {
      "x": -1,
      "y": 32,
      "z": 4,
      "name": "*Rock_Marble_Cobble_Roof_Steep_State_Definitions_Corner_Left",
      "rotation": 3
    },
    {
      "x": -1,
      "y": 33,
      "z": 4,
      "name": "*Rock_Marble_Cobble_Roof_Steep_State_Definitions_Corner_Left",
      "filler": 1024,
      "rotation": 3
    },
    {
      "x": -1,
      "y": 0,
      "z": 5,
      "name": "Rock_Marble_Cobble"
    },
    {
      "x": -1,
      "y": 1,
      "z": 5,
      "name": "Rock_Marble_Cobble"
    },
    {
      "x": -1,
      "y": 2,
      "z": 5,
      "name": "Rock_Marble_Cobble"
    },
    {
      "x": -1,
      "y": 3,
      "z": 5,
      "name": "Rock_Marble_Cobble"
    },
    {
      "x": -1,
      "y": 4,
      "z": 5,
      "name": "Rock_Marble_Cobble"
    },
    {
      "x": -1,
      "y": 5,
      "z": 5,
      "name": "Rock_Marble_Cobble"
    },
    {
      "x": -1,
      "y": 22,
      "z": 5,
      "name": "Rock_Runic_Blue_Brick"
    },
    {
      "x": -1,
      "y": 23,
      "z": 5,
      "name": "Rock_Runic_Blue_Brick"
    },
    {
      "x": -1,
      "y": 24,
      "z": 5,
      "name": "Metal_Iron_Fence",
      "rotation": 2
    },
    {
      "x": 0,
      "y": 0,
      "z": -5,
      "name": "Rock_Marble_Cobble"
    },
    {
      "x": 0,
      "y": 1,
      "z": -5,
      "name": "Rock_Marble_Cobble"
    },
    {
      "x": 0,
      "y": 2,
      "z": -5,
      "name": "Rock_Marble_Cobble"
    },
    {
      "x": 0,
      "y": 3,
      "z": -5,
      "name": "Rock_Marble_Cobble"
    },
    {
      "x": 0,
      "y": 4,
      "z": -5,
      "name": "Rock_Marble_Cobble"
    },
    {
      "x": 0,
      "y": 5,
      "z": -5,
      "name": "Rock_Marble_Cobble"
    },
    {
      "x": 0,
      "y": 6,
      "z": -5,
      "name": "Rock_Marble_Cobble_Half"
    },
    {
      "x": 0,
      "y": 21,
      "z": -5,
      "name": "Rock_Runic_Blue_Brick_Stairs",
      "rotation": 8
    },
    {
      "x": 0,
      "y": 22,
      "z": -5,
      "name": "Rock_Runic_Blue_Brick"
    },
    {
      "x": 0,
      "y": 23,
      "z": -5,
      "name": "Rock_Runic_Blue_Brick"
    },
    {
      "x": 0,
      "y": 24,
      "z": -5,
      "name": "Metal_Iron_Fence",
      "rotation": 2
    },
    {
      "x": 0,
      "y": 0,
      "z": -4,
      "name": "Wood_Hardwood_Planks"
    },
    {
      "x": 0,
      "y": 2,
      "z": -4,
      "name": "*Wood_Hardwood_Stairs_State_Definitions_Inverted_Corner_Right"
    },
    {
      "x": 0,
      "y": 5,
      "z": -4,
      "name": "Rock_Marble_Cobble"
    },
    {
      "x": 0,
      "y": 6,
      "z": -4,
      "name": "Rock_Runic_Blue_Brick"
    },
    {
      "x": 0,
      "y": 7,
      "z": -4,
      "name": "Rock_Runic_Blue_Brick"
    },
    {
      "x": 0,
      "y": 8,
      "z": -4,
      "name": "Rock_Runic_Blue_Brick"
    },
    {
      "x": 0,
      "y": 9,
      "z": -4,
      "name": "Rock_Runic_Blue_Brick"
    },
    {
      "x": 0,
      "y": 10,
      "z": -4,
      "name": "Rock_Marble_Cobble"
    },
    {
      "x": 0,
      "y": 11,
      "z": -4,
      "name": "Rock_Marble_Cobble"
    },
    {
      "x": 0,
      "y": 12,
      "z": -4,
      "name": "Rock_Marble_Cobble"
    },
    {
      "x": 0,
      "y": 13,
      "z": -4,
      "name": "Rock_Marble_Cobble"
    },
    {
      "x": 0,
      "y": 14,
      "z": -4,
      "name": "Rock_Runic_Blue_Brick"
    },
    {
      "x": 0,
      "y": 15,
      "z": -4,
      "name": "Rock_Runic_Blue_Brick"
    },
    {
      "x": 0,
      "y": 16,
      "z": -4,
      "name": "Rock_Runic_Blue_Brick"
    },
    {
      "x": 0,
      "y": 17,
      "z": -4,
      "name": "Rock_Runic_Blue_Brick"
    },
    {
      "x": 0,
      "y": 18,
      "z": -4,
      "name": "Rock_Marble_Cobble"
    },
    {
      "x": 0,
      "y": 19,
      "z": -4,
      "name": "Rock_Marble_Cobble"
    },
    {
      "x": 0,
      "y": 20,
      "z": -4,
      "name": "Rock_Marble_Cobble"
    },
    {
      "x": 0,
      "y": 21,
      "z": -4,
      "name": "Rock_Marble_Cobble"
    },
    {
      "x": 0,
      "y": 22,
      "z": -4,
      "name": "Rock_Runic_Blue_Brick"
    },
    {
      "x": 0,
      "y": 23,
      "z": -4,
      "name": "Rock_Runic_Blue_Brick"
    },
    {
      "x": 0,
      "y": 27,
      "z": -4,
      "name": "Rock_Runic_Blue_Brick_Stairs",
      "rotation": 8
    },
    {
      "x": 0,
      "y": 28,
      "z": -4,
      "name": "Rock_Runic_Blue_Brick"
    },
    {
      "x": 0,
      "y": 32,
      "z": -4,
      "name": "Rock_Marble_Cobble_Roof_Steep",
      "rotation": 2
    },
    {
      "x": 0,
      "y": 33,
      "z": -4,
      "name": "Rock_Marble_Cobble_Roof_Steep",
      "filler": 1024,
      "rotation": 2
    },
    {
      "x": 0,
      "y": 0,
      "z": -3,
      "name": "Wood_Hardwood_Planks"
    },
    {
      "x": 0,
      "y": 1,
      "z": -3,
      "name": "Wood_Hardwood_Stairs",
      "rotation": 11
    },
    {
      "x": 0,
      "y": 2,
      "z": -3,
      "name": "Wood_Hardwood_Stairs",
      "rotation": 3
    },
    {
      "x": 0,
      "y": 6,
      "z": -3,
      "name": "Wood_Hardwood_Planks_Half",
      "rotation": 8
    },
    {
      "x": 0,
      "y": 10,
      "z": -3,
      "name": "Wood_Hardwood_Planks_Half",
      "rotation": 8
    },
    {
      "x": 0,
      "y": 14,
      "z": -3,
      "name": "Wood_Hardwood_Planks_Half",
      "rotation": 8
    },
    {
      "x": 0,
      "y": 18,
      "z": -3,
      "name": "Wood_Hardwood_Planks_Half",
      "rotation": 8
    },
    {
      "x": 0,
      "y": 22,
      "z": -3,
      "name": "*Rock_Runic_Blue_Brick_Stairs_State_Definitions_Inverted_Corner_Left",
      "rotation": 11
    },
    {
      "x": 0,
      "y": 23,
      "z": -3,
      "name": "Rock_Runic_Blue_Brick"
    },
    {
      "x": 0,
      "y": 24,
      "z": -3,
      "name": "Rock_Marble_Cobble"
    },
    {
      "x": 0,
      "y": 25,
      "z": -3,
      "name": "Rock_Marble_Cobble"
    },
    {
      "x": 0,
      "y": 26,
      "z": -3,
      "name": "Rock_Marble_Cobble"
    },
    {
      "x": 0,
      "y": 27,
      "z": -3,
      "name": "Rock_Marble_Cobble"
    },
    {
      "x": 0,
      "y": 28,
      "z": -3,
      "name": "Rock_Runic_Blue_Brick"
    },
    {
      "x": 0,
      "y": 33,
      "z": -3,
      "name": "Rock_Marble_Cobble_Stairs",
      "rotation": 10
    },
    {
      "x": 0,
      "y": 34,
      "z": -3,
      "name": "*Rock_Marble_Cobble_Roof_State_Definitions_Corner_Right",
      "rotation": 3
    },
    {
      "x": 0,
      "y": 0,
      "z": -2,
      "name": "Wood_Hardwood_Planks"
    },
    {
      "x": 0,
      "y": 1,
      "z": -2,
      "name": "Wood_Hardwood_Stairs",
      "rotation": 11
    },
    {
      "x": 0,
      "y": 2,
      "z": -2,
      "name": "Wood_Hardwood_Stairs",
      "rotation": 3
    },
    {
      "x": 0,
      "y": 6,
      "z": -2,
      "name": "Wood_Hardwood_Planks_Half",
      "rotation": 8
    },
    {
      "x": 0,
      "y": 10,
      "z": -2,
      "name": "Wood_Hardwood_Planks_Half",
      "rotation": 8
    },
    {
      "x": 0,
      "y": 14,
      "z": -2,
      "name": "Wood_Hardwood_Planks_Half",
      "rotation": 8
    },
    {
      "x": 0,
      "y": 18,
      "z": -2,
      "name": "Wood_Hardwood_Planks_Half",
      "rotation": 8
    },
    {
      "x": 0,
      "y": 23,
      "z": -2,
      "name": "Wood_Hardwood_Planks"
    },
    {
      "x": 0,
      "y": 24,
      "z": -2,
      "name": "Furniture_Village_Counter",
      "filler": 31
    },
    {
      "x": 0,
      "y": 25,
      "z": -2,
      "name": "*Furniture_Lumberjack_Lantern_State_Definitions_Off"
    },
    {
      "x": 0,
      "y": 28,
      "z": -2,
      "name": "Rock_Marble_Cobble"
    },
    {
      "x": 0,
      "y": 29,
      "z": -2,
      "name": "Deco_Iron_Bars"
    },
    {
      "x": 0,
      "y": 34,
      "z": -2,
      "name": "*Rock_Marble_Cobble_Roof_Hollow_State_Definitions_Inverted_Corner_Left",
      "rotation": 2
    },
    {
      "x": 0,
      "y": 0,
      "z": -1,
      "name": "Wood_Hardwood_Planks"
    },
    {
      "x": 0,
      "y": 1,
      "z": -1,
      "name": "Cloth_Roof_Blue_Flat"
    },
    {
      "x": 0,
      "y": 6,
      "z": -1,
      "name": "Wood_Hardwood_Planks_Half",
      "rotation": 8
    },
    {
      "x": 0,
      "y": 10,
      "z": -1,
      "name": "Wood_Hardwood_Planks_Half",
      "rotation": 8
    },
    {
      "x": 0,
      "y": 14,
      "z": -1,
      "name": "Wood_Hardwood_Planks_Half",
      "rotation": 8
    },
    {
      "x": 0,
      "y": 18,
      "z": -1,
      "name": "Wood_Hardwood_Planks_Half",
      "rotation": 8
    },
    {
      "x": 0,
      "y": 23,
      "z": -1,
      "name": "Wood_Hardwood_Planks"
    },
    {
      "x": 0,
      "y": 28,
      "z": -1,
      "name": "Rock_Marble_Cobble"
    },
    {
      "x": 0,
      "y": 35,
      "z": -1,
      "name": "*Rock_Marble_Cobble_Roof_Hollow_State_Definitions_Corner_Left",
      "rotation": 2
    },
    {
      "x": 0,
      "y": 0,
      "z": 0,
      "name": "Wood_Hardwood_Planks"
    },
    {
      "x": 0,
      "y": 1,
      "z": 0,
      "name": "Cloth_Roof_Blue_Flat"
    },
    {
      "x": 0,
      "y": 6,
      "z": 0,
      "name": "Wood_Hardwood_Stairs"
    },
    {
      "x": 0,
      "y": 10,
      "z": 0,
      "name": "Wood_Hardwood_Stairs"
    },
    {
      "x": 0,
      "y": 14,
      "z": 0,
      "name": "Wood_Hardwood_Stairs"
    },
    {
      "x": 0,
      "y": 18,
      "z": 0,
      "name": "Wood_Hardwood_Stairs"
    },
    {
      "x": 0,
      "y": 23,
      "z": 0,
      "name": "Wood_Hardwood_Planks"
    },
    {
      "x": 0,
      "y": 28,
      "z": 0,
      "name": "Rock_Marble_Cobble"
    },
    {
      "x": 0,
      "y": 35,
      "z": 0,
      "name": "Rock_Marble_Cobble_Roof_Shallow",
      "filler": 1,
      "rotation": 3
    },
    {
      "x": 0,
      "y": 0,
      "z": 1,
      "name": "Wood_Hardwood_Planks"
    },
    {
      "x": 0,
      "y": 1,
      "z": 1,
      "name": "Cloth_Roof_Blue_Flat"
    },
    {
      "x": 0,
      "y": 5,
      "z": 1,
      "name": "Wood_Hardwood_Planks_Half",
      "rotation": 8
    },
    {
      "x": 0,
      "y": 9,
      "z": 1,
      "name": "Wood_Hardwood_Planks_Half",
      "rotation": 8
    },
    {
      "x": 0,
      "y": 13,
      "z": 1,
      "name": "Wood_Hardwood_Planks_Half",
      "rotation": 8
    },
    {
      "x": 0,
      "y": 17,
      "z": 1,
      "name": "Wood_Hardwood_Planks_Half",
      "rotation": 8
    },
    {
      "x": 0,
      "y": 23,
      "z": 1,
      "name": "Wood_Hardwood_Planks"
    },
    {
      "x": 0,
      "y": 28,
      "z": 1,
      "name": "Rock_Marble_Cobble"
    },
    {
      "x": 0,
      "y": 35,
      "z": 1,
      "name": "*Rock_Marble_Cobble_Roof_Hollow_State_Definitions_Corner_Right"
    },
    {
      "x": 0,
      "y": 0,
      "z": 2,
      "name": "Wood_Hardwood_Planks"
    },
    {
      "x": 0,
      "y": 1,
      "z": 2,
      "name": "Empty"
    },
    {
      "x": 0,
      "y": 5,
      "z": 2,
      "name": "*Wood_Hardwood_Stairs_State_Definitions_Inverted_Corner_Left"
    },
    {
      "x": 0,
      "y": 9,
      "z": 2,
      "name": "*Wood_Hardwood_Stairs_State_Definitions_Inverted_Corner_Right",
      "rotation": 1
    },
    {
      "x": 0,
      "y": 13,
      "z": 2,
      "name": "*Wood_Hardwood_Stairs_State_Definitions_Inverted_Corner_Right",
      "rotation": 1
    },
    {
      "x": 0,
      "y": 17,
      "z": 2,
      "name": "*Wood_Hardwood_Stairs_State_Definitions_Inverted_Corner_Right",
      "rotation": 1
    },
    {
      "x": 0,
      "y": 23,
      "z": 2,
      "name": "Wood_Hardwood_Planks"
    },
    {
      "x": 0,
      "y": 24,
      "z": 2,
      "name": "Deco_Book_Pile_Small",
      "rotation": 2
    },
    {
      "x": 0,
      "y": 28,
      "z": 2,
      "name": "Rock_Marble_Cobble"
    },
    {
      "x": 0,
      "y": 29,
      "z": 2,
      "name": "Deco_Iron_Bars"
    },
    {
      "x": 0,
      "y": 34,
      "z": 2,
      "name": "*Rock_Marble_Cobble_Roof_Hollow_State_Definitions_Inverted_Corner_Left",
      "rotation": 3
    },
    {
      "x": 0,
      "y": 0,
      "z": 3,
      "name": "Wood_Hardwood_Planks"
    },
    {
      "x": 0,
      "y": 1,
      "z": 3,
      "name": "Empty"
    },
    {
      "x": 0,
      "y": 5,
      "z": 3,
      "name": "Wood_Hardwood_Stairs",
      "rotation": 1
    },
    {
      "x": 0,
      "y": 9,
      "z": 3,
      "name": "Wood_Hardwood_Stairs",
      "rotation": 1
    },
    {
      "x": 0,
      "y": 13,
      "z": 3,
      "name": "Wood_Hardwood_Stairs",
      "rotation": 1
    },
    {
      "x": 0,
      "y": 17,
      "z": 3,
      "name": "Wood_Hardwood_Stairs",
      "rotation": 1
    },
    {
      "x": 0,
      "y": 22,
      "z": 3,
      "name": "*Rock_Runic_Blue_Brick_Stairs_State_Definitions_Inverted_Corner_Right",
      "rotation": 11
    },
    {
      "x": 0,
      "y": 23,
      "z": 3,
      "name": "Rock_Runic_Blue_Brick"
    },
    {
      "x": 0,
      "y": 24,
      "z": 3,
      "name": "Rock_Marble_Cobble"
    },
    {
      "x": 0,
      "y": 25,
      "z": 3,
      "name": "Rock_Marble_Cobble"
    },
    {
      "x": 0,
      "y": 26,
      "z": 3,
      "name": "Rock_Marble_Cobble"
    },
    {
      "x": 0,
      "y": 27,
      "z": 3,
      "name": "Rock_Marble_Cobble"
    },
    {
      "x": 0,
      "y": 28,
      "z": 3,
      "name": "Rock_Runic_Blue_Brick"
    },
    {
      "x": 0,
      "y": 33,
      "z": 3,
      "name": "Rock_Marble_Cobble_Stairs",
      "rotation": 8
    },
    {
      "x": 0,
      "y": 34,
      "z": 3,
      "name": "*Rock_Marble_Cobble_Roof_State_Definitions_Corner_Right"
    },
    {
      "x": 0,
      "y": 0,
      "z": 4,
      "name": "Wood_Hardwood_Planks"
    },
    {
      "x": 0,
      "y": 1,
      "z": 4,
      "name": "Furniture_Village_Bookcase",
      "rotation": 2
    },
    {
      "x": 0,
      "y": 2,
      "z": 4,
      "name": "Furniture_Village_Bookcase",
      "rotation": 2
    },
    {
      "x": 0,
      "y": 3,
      "z": 4,
      "name": "Furniture_Village_Shelf_Full",
      "rotation": 2
    },
    {
      "x": 0,
      "y": 5,
      "z": 4,
      "name": "Rock_Marble_Cobble"
    },
    {
      "x": 0,
      "y": 6,
      "z": 4,
      "name": "Rock_Runic_Blue_Brick"
    },
    {
      "x": 0,
      "y": 7,
      "z": 4,
      "name": "Rock_Runic_Blue_Brick"
    },
    {
      "x": 0,
      "y": 8,
      "z": 4,
      "name": "Rock_Runic_Blue_Brick"
    },
    {
      "x": 0,
      "y": 9,
      "z": 4,
      "name": "Rock_Runic_Blue_Brick"
    },
    {
      "x": 0,
      "y": 10,
      "z": 4,
      "name": "Rock_Marble_Cobble"
    },
    {
      "x": 0,
      "y": 11,
      "z": 4,
      "name": "Rock_Marble_Cobble"
    },
    {
      "x": 0,
      "y": 12,
      "z": 4,
      "name": "Rock_Marble_Cobble"
    },
    {
      "x": 0,
      "y": 13,
      "z": 4,
      "name": "Rock_Marble_Cobble"
    },
    {
      "x": 0,
      "y": 14,
      "z": 4,
      "name": "Rock_Runic_Blue_Brick"
    },
    {
      "x": 0,
      "y": 15,
      "z": 4,
      "name": "Rock_Runic_Blue_Brick"
    },
    {
      "x": 0,
      "y": 16,
      "z": 4,
      "name": "Rock_Runic_Blue_Brick"
    },
    {
      "x": 0,
      "y": 17,
      "z": 4,
      "name": "Rock_Runic_Blue_Brick"
    },
    {
      "x": 0,
      "y": 18,
      "z": 4,
      "name": "Rock_Marble_Cobble"
    },
    {
      "x": 0,
      "y": 19,
      "z": 4,
      "name": "Rock_Marble_Cobble"
    },
    {
      "x": 0,
      "y": 20,
      "z": 4,
      "name": "Rock_Marble_Cobble"
    },
    {
      "x": 0,
      "y": 21,
      "z": 4,
      "name": "Rock_Marble_Cobble"
    },
    {
      "x": 0,
      "y": 22,
      "z": 4,
      "name": "Rock_Runic_Blue_Brick"
    },
    {
      "x": 0,
      "y": 23,
      "z": 4,
      "name": "Rock_Runic_Blue_Brick"
    },
    {
      "x": 0,
      "y": 27,
      "z": 4,
      "name": "Rock_Runic_Blue_Brick_Stairs",
      "rotation": 10
    },
    {
      "x": 0,
      "y": 28,
      "z": 4,
      "name": "Rock_Runic_Blue_Brick"
    },
    {
      "x": 0,
      "y": 32,
      "z": 4,
      "name": "Rock_Marble_Cobble_Roof_Steep"
    },
    {
      "x": 0,
      "y": 33,
      "z": 4,
      "name": "Rock_Marble_Cobble_Roof_Steep",
      "filler": 1024
    },
    {
      "x": 0,
      "y": 0,
      "z": 5,
      "name": "Rock_Marble_Cobble"
    },
    {
      "x": 0,
      "y": 1,
      "z": 5,
      "name": "Rock_Marble_Cobble"
    },
    {
      "x": 0,
      "y": 2,
      "z": 5,
      "name": "Rock_Marble_Cobble"
    },
    {
      "x": 0,
      "y": 3,
      "z": 5,
      "name": "Rock_Marble_Cobble"
    },
    {
      "x": 0,
      "y": 4,
      "z": 5,
      "name": "Rock_Marble_Cobble"
    },
    {
      "x": 0,
      "y": 5,
      "z": 5,
      "name": "Rock_Marble_Cobble"
    },
    {
      "x": 0,
      "y": 6,
      "z": 5,
      "name": "Rock_Marble_Cobble_Half"
    },
    {
      "x": 0,
      "y": 21,
      "z": 5,
      "name": "Rock_Runic_Blue_Brick_Stairs",
      "rotation": 10
    },
    {
      "x": 0,
      "y": 22,
      "z": 5,
      "name": "Rock_Runic_Blue_Brick"
    },
    {
      "x": 0,
      "y": 23,
      "z": 5,
      "name": "Rock_Runic_Blue_Brick"
    },
    {
      "x": 0,
      "y": 24,
      "z": 5,
      "name": "Metal_Iron_Fence"
    },
    {
      "x": 1,
      "y": 0,
      "z": -5,
      "name": "Rock_Marble_Cobble"
    },
    {
      "x": 1,
      "y": 1,
      "z": -5,
      "name": "Rock_Marble_Cobble"
    },
    {
      "x": 1,
      "y": 2,
      "z": -5,
      "name": "Rock_Marble_Cobble"
    },
    {
      "x": 1,
      "y": 3,
      "z": -5,
      "name": "Rock_Marble_Cobble"
    },
    {
      "x": 1,
      "y": 4,
      "z": -5,
      "name": "Rock_Marble_Cobble"
    },
    {
      "x": 1,
      "y": 5,
      "z": -5,
      "name": "Rock_Marble_Cobble"
    },
    {
      "x": 1,
      "y": 21,
      "z": -5,
      "name": "Rock_Runic_Blue_Brick_Half",
      "rotation": 8
    },
    {
      "x": 1,
      "y": 22,
      "z": -5,
      "name": "Rock_Runic_Blue_Brick"
    },
    {
      "x": 1,
      "y": 23,
      "z": -5,
      "name": "Rock_Runic_Blue_Brick"
    },
    {
      "x": 1,
      "y": 24,
      "z": -5,
      "name": "Metal_Iron_Fence",
      "rotation": 2
    },
    {
      "x": 1,
      "y": 0,
      "z": -4,
      "name": "Wood_Hardwood_Planks"
    },
    {
      "x": 1,
      "y": 1,
      "z": -4,
      "name": "Empty"
    },
    {
      "x": 1,
      "y": 2,
      "z": -4,
      "name": "Wood_Hardwood_Stairs",
      "rotation": 11
    },
    {
      "x": 1,
      "y": 3,
      "z": -4,
      "name": "Wood_Hardwood_Planks_Half"
    },
    {
      "x": 1,
      "y": 4,
      "z": -4,
      "name": "Rock_Marble_Cobble_Half",
      "rotation": 8
    },
    {
      "x": 1,
      "y": 5,
      "z": -4,
      "name": "Rock_Marble_Cobble"
    },
    {
      "x": 1,
      "y": 6,
      "z": -4,
      "name": "Rock_Runic_Blue_Brick"
    },
    {
      "x": 1,
      "y": 7,
      "z": -4,
      "name": "Furniture_Village_Window"
    },
    {
      "x": 1,
      "y": 8,
      "z": -4,
      "name": "Furniture_Village_Window"
    },
    {
      "x": 1,
      "y": 9,
      "z": -4,
      "name": "Rock_Runic_Blue_Brick"
    },
    {
      "x": 1,
      "y": 10,
      "z": -4,
      "name": "Rock_Marble_Cobble"
    },
    {
      "x": 1,
      "y": 11,
      "z": -4,
      "name": "Furniture_Village_Window"
    },
    {
      "x": 1,
      "y": 12,
      "z": -4,
      "name": "Furniture_Village_Window"
    },
    {
      "x": 1,
      "y": 13,
      "z": -4,
      "name": "Rock_Marble_Cobble"
    },
    {
      "x": 1,
      "y": 14,
      "z": -4,
      "name": "Rock_Runic_Blue_Brick"
    },
    {
      "x": 1,
      "y": 15,
      "z": -4,
      "name": "Furniture_Village_Window"
    },
    {
      "x": 1,
      "y": 16,
      "z": -4,
      "name": "Furniture_Village_Window"
    },
    {
      "x": 1,
      "y": 17,
      "z": -4,
      "name": "Rock_Runic_Blue_Brick"
    },
    {
      "x": 1,
      "y": 18,
      "z": -4,
      "name": "Rock_Marble_Cobble"
    },
    {
      "x": 1,
      "y": 19,
      "z": -4,
      "name": "Furniture_Village_Window"
    },
    {
      "x": 1,
      "y": 20,
      "z": -4,
      "name": "Furniture_Village_Window"
    },
    {
      "x": 1,
      "y": 21,
      "z": -4,
      "name": "Rock_Marble_Cobble"
    },
    {
      "x": 1,
      "y": 22,
      "z": -4,
      "name": "Rock_Runic_Blue_Brick"
    },
    {
      "x": 1,
      "y": 23,
      "z": -4,
      "name": "Rock_Runic_Blue_Brick"
    },
    {
      "x": 1,
      "y": 27,
      "z": -4,
      "name": "Rock_Runic_Blue_Brick_Half",
      "rotation": 6
    },
    {
      "x": 1,
      "y": 28,
      "z": -4,
      "name": "Rock_Runic_Blue_Brick"
    },
    {
      "x": 1,
      "y": 32,
      "z": -4,
      "name": "Rock_Marble_Cobble_Roof_Steep",
      "rotation": 2
    },
    {
      "x": 1,
      "y": 33,
      "z": -4,
      "name": "Rock_Marble_Cobble_Roof_Steep",
      "filler": 1024,
      "rotation": 2
    },
    {
      "x": 1,
      "y": 0,
      "z": -3,
      "name": "Wood_Hardwood_Planks"
    },
    {
      "x": 1,
      "y": 1,
      "z": -3,
      "name": "Empty"
    },
    {
      "x": 1,
      "y": 2,
      "z": -3,
      "name": "Wood_Hardwood_Stairs",
      "rotation": 11
    },
    {
      "x": 1,
      "y": 3,
      "z": -3,
      "name": "Wood_Hardwood_Planks_Half"
    },
    {
      "x": 1,
      "y": 6,
      "z": -3,
      "name": "Wood_Hardwood_Planks_Half",
      "rotation": 8
    },
    {
      "x": 1,
      "y": 10,
      "z": -3,
      "name": "Wood_Hardwood_Planks_Half",
      "rotation": 8
    },
    {
      "x": 1,
      "y": 14,
      "z": -3,
      "name": "Wood_Hardwood_Planks_Half",
      "rotation": 8
    },
    {
      "x": 1,
      "y": 18,
      "z": -3,
      "name": "Wood_Hardwood_Planks_Half",
      "rotation": 8
    },
    {
      "x": 1,
      "y": 22,
      "z": -3,
      "name": "Rock_Runic_Blue_Brick_Stairs",
      "rotation": 10
    },
    {
      "x": 1,
      "y": 23,
      "z": -3,
      "name": "Rock_Runic_Blue_Brick"
    },
    {
      "x": 1,
      "y": 24,
      "z": -3,
      "name": "Rock_Marble_Cobble"
    },
    {
      "x": 1,
      "y": 25,
      "z": -3,
      "name": "Furniture_Village_Window"
    },
    {
      "x": 1,
      "y": 26,
      "z": -3,
      "name": "Furniture_Village_Window"
    },
    {
      "x": 1,
      "y": 27,
      "z": -3,
      "name": "Rock_Marble_Cobble"
    },
    {
      "x": 1,
      "y": 28,
      "z": -3,
      "name": "Rock_Runic_Blue_Brick"
    },
    {
      "x": 1,
      "y": 33,
      "z": -3,
      "name": "Rock_Marble_Cobble_Half",
      "rotation": 8
    },
    {
      "x": 1,
      "y": 34,
      "z": -3,
      "name": "Rock_Marble_Cobble_Roof",
      "rotation": 2
    },
    {
      "x": 1,
      "y": 0,
      "z": -2,
      "name": "Wood_Hardwood_Planks"
    },
    {
      "x": 1,
      "y": 1,
      "z": -2,
      "name": "Empty"
    },
    {
      "x": 1,
      "y": 2,
      "z": -2,
      "name": "Wood_Hardwood_Stairs",
      "rotation": 11
    },
    {
      "x": 1,
      "y": 3,
      "z": -2,
      "name": "*Wood_Hardwood_Stairs_State_Definitions_Corner_Right",
      "rotation": 3
    },
    {
      "x": 1,
      "y": 7,
      "z": -2,
      "name": "*Wood_Hardwood_Stairs_State_Definitions_Corner_Right",
      "rotation": 3
    },
    {
      "x": 1,
      "y": 11,
      "z": -2,
      "name": "*Wood_Hardwood_Stairs_State_Definitions_Corner_Left",
      "rotation": 2
    },
    {
      "x": 1,
      "y": 15,
      "z": -2,
      "name": "*Wood_Hardwood_Stairs_State_Definitions_Corner_Left",
      "rotation": 2
    },
    {
      "x": 1,
      "y": 19,
      "z": -2,
      "name": "*Wood_Hardwood_Stairs_State_Definitions_Corner_Left",
      "rotation": 2
    },
    {
      "x": 1,
      "y": 23,
      "z": -2,
      "name": "Wood_Hardwood_Planks"
    },
    {
      "x": 1,
      "y": 24,
      "z": -2,
      "name": "Furniture_Village_Counter"
    },
    {
      "x": 1,
      "y": 25,
      "z": -2,
      "name": "Deco_Map"
    },
    {
      "x": 1,
      "y": 28,
      "z": -2,
      "name": "Rock_Marble_Cobble"
    },
    {
      "x": 1,
      "y": 29,
      "z": -2,
      "name": "Deco_Iron_Bars"
    },
    {
      "x": 1,
      "y": 34,
      "z": -2,
      "name": "Rock_Marble_Cobble_Half",
      "rotation": 8
    },
    {
      "x": 1,
      "y": 35,
      "z": -2,
      "name": "Rock_Marble_Cobble_Roof_Shallow",
      "rotation": 2
    },
    {
      "x": 1,
      "y": 0,
      "z": -1,
      "name": "Wood_Hardwood_Planks"
    },
    {
      "x": 1,
      "y": 1,
      "z": -1,
      "name": "Cloth_Roof_Blue_Flat"
    },
    {
      "x": 1,
      "y": 3,
      "z": -1,
      "name": "Wood_Hardwood_Stairs",
      "rotation": 3
    },
    {
      "x": 1,
      "y": 7,
      "z": -1,
      "name": "Wood_Hardwood_Stairs",
      "rotation": 3
    },
    {
      "x": 1,
      "y": 11,
      "z": -1,
      "name": "Wood_Hardwood_Stairs",
      "rotation": 3
    },
    {
      "x": 1,
      "y": 15,
      "z": -1,
      "name": "Wood_Hardwood_Stairs",
      "rotation": 3
    },
    {
      "x": 1,
      "y": 19,
      "z": -1,
      "name": "Wood_Hardwood_Stairs",
      "rotation": 3
    },
    {
      "x": 1,
      "y": 23,
      "z": -1,
      "name": "Wood_Hardwood_Planks"
    },
    {
      "x": 1,
      "y": 24,
      "z": -1,
      "name": "Furniture_Tavern_Chair",
      "rotation": 2
    },
    {
      "x": 1,
      "y": 28,
      "z": -1,
      "name": "Rock_Marble_Cobble"
    },
    {
      "x": 1,
      "y": 35,
      "z": -1,
      "name": "Rock_Marble_Cobble_Roof_Shallow",
      "filler": 32,
      "rotation": 2
    },
    {
      "x": 1,
      "y": 0,
      "z": 0,
      "name": "Wood_Hardwood_Planks"
    },
    {
      "x": 1,
      "y": 1,
      "z": 0,
      "name": "Cloth_Roof_Blue_Flat"
    },
    {
      "x": 1,
      "y": 23,
      "z": 0,
      "name": "Wood_Hardwood_Planks"
    },
    {
      "x": 1,
      "y": 28,
      "z": 0,
      "name": "Rock_Marble_Cobble"
    },
    {
      "x": 1,
      "y": 29,
      "z": 0,
      "name": "*Furniture_Temple_Light_Brazier_State_Definitions_Off"
    },
    {
      "x": 1,
      "y": 35,
      "z": 0,
      "name": "*Rock_Marble_Cobble_Half_State_Definitions_Block",
      "rotation": 8
    },
    {
      "x": 1,
      "y": 36,
      "z": 0,
      "name": "Rock_Marble_Cobble_Roof_Flat",
      "rotation": 3
    },
    {
      "x": 1,
      "y": 0,
      "z": 1,
      "name": "Wood_Hardwood_Planks"
    },
    {
      "x": 1,
      "y": 1,
      "z": 1,
      "name": "Cloth_Roof_Blue_Flat"
    },
    {
      "x": 1,
      "y": 5,
      "z": 1,
      "name": "Wood_Hardwood_Stairs",
      "rotation": 1
    },
    {
      "x": 1,
      "y": 9,
      "z": 1,
      "name": "Wood_Hardwood_Stairs",
      "rotation": 1
    },
    {
      "x": 1,
      "y": 13,
      "z": 1,
      "name": "Wood_Hardwood_Stairs",
      "rotation": 1
    },
    {
      "x": 1,
      "y": 17,
      "z": 1,
      "name": "Wood_Hardwood_Stairs",
      "rotation": 1
    },
    {
      "x": 1,
      "y": 23,
      "z": 1,
      "name": "Wood_Hardwood_Planks"
    },
    {
      "x": 1,
      "y": 28,
      "z": 1,
      "name": "Rock_Marble_Cobble"
    },
    {
      "x": 1,
      "y": 35,
      "z": 1,
      "name": "Rock_Marble_Cobble_Roof_Shallow",
      "filler": 992
    },
    {
      "x": 1,
      "y": 0,
      "z": 2,
      "name": "Wood_Hardwood_Planks"
    },
    {
      "x": 1,
      "y": 1,
      "z": 2,
      "name": "Empty"
    },
    {
      "x": 1,
      "y": 5,
      "z": 2,
      "name": "*Wood_Hardwood_Stairs_State_Definitions_Corner_Right",
      "rotation": 1
    },
    {
      "x": 1,
      "y": 9,
      "z": 2,
      "name": "*Wood_Hardwood_Stairs_State_Definitions_Corner_Left"
    },
    {
      "x": 1,
      "y": 13,
      "z": 2,
      "name": "*Wood_Hardwood_Stairs_State_Definitions_Corner_Left"
    },
    {
      "x": 1,
      "y": 17,
      "z": 2,
      "name": "*Wood_Hardwood_Stairs_State_Definitions_Corner_Left"
    },
    {
      "x": 1,
      "y": 23,
      "z": 2,
      "name": "Wood_Hardwood_Planks"
    },
    {
      "x": 1,
      "y": 28,
      "z": 2,
      "name": "Rock_Marble_Cobble"
    },
    {
      "x": 1,
      "y": 29,
      "z": 2,
      "name": "Deco_Iron_Bars"
    },
    {
      "x": 1,
      "y": 34,
      "z": 2,
      "name": "Rock_Marble_Cobble_Half",
      "rotation": 8
    },
    {
      "x": 1,
      "y": 35,
      "z": 2,
      "name": "Rock_Marble_Cobble_Roof_Shallow"
    },
    {
      "x": 1,
      "y": 0,
      "z": 3,
      "name": "Wood_Hardwood_Planks"
    },
    {
      "x": 1,
      "y": 1,
      "z": 3,
      "name": "Empty"
    },
    {
      "x": 1,
      "y": 4,
      "z": 3,
      "name": "Wood_Hardwood_Planks_Half",
      "rotation": 8
    },
    {
      "x": 1,
      "y": 8,
      "z": 3,
      "name": "Wood_Hardwood_Planks_Half",
      "rotation": 8
    },
    {
      "x": 1,
      "y": 12,
      "z": 3,
      "name": "Wood_Hardwood_Planks_Half",
      "rotation": 8
    },
    {
      "x": 1,
      "y": 16,
      "z": 3,
      "name": "Wood_Hardwood_Planks_Half",
      "rotation": 8
    },
    {
      "x": 1,
      "y": 22,
      "z": 3,
      "name": "Rock_Runic_Blue_Brick_Stairs",
      "rotation": 8
    },
    {
      "x": 1,
      "y": 23,
      "z": 3,
      "name": "Rock_Runic_Blue_Brick"
    },
    {
      "x": 1,
      "y": 24,
      "z": 3,
      "name": "Rock_Marble_Cobble"
    },
    {
      "x": 1,
      "y": 25,
      "z": 3,
      "name": "Furniture_Village_Window"
    },
    {
      "x": 1,
      "y": 26,
      "z": 3,
      "name": "Furniture_Village_Window"
    },
    {
      "x": 1,
      "y": 27,
      "z": 3,
      "name": "Rock_Marble_Cobble"
    },
    {
      "x": 1,
      "y": 28,
      "z": 3,
      "name": "Rock_Runic_Blue_Brick"
    },
    {
      "x": 1,
      "y": 33,
      "z": 3,
      "name": "Rock_Marble_Cobble_Half",
      "rotation": 8
    },
    {
      "x": 1,
      "y": 34,
      "z": 3,
      "name": "Rock_Marble_Cobble_Roof"
    },
    {
      "x": 1,
      "y": 0,
      "z": 4,
      "name": "Wood_Hardwood_Planks"
    },
    {
      "x": 1,
      "y": 1,
      "z": 4,
      "name": "Furniture_Village_Bookcase",
      "rotation": 2
    },
    {
      "x": 1,
      "y": 2,
      "z": 4,
      "name": "Furniture_Village_Shelf_Full",
      "rotation": 2
    },
    {
      "x": 1,
      "y": 3,
      "z": 4,
      "name": "Furniture_Village_Shelf_Full",
      "rotation": 2
    },
    {
      "x": 1,
      "y": 4,
      "z": 4,
      "name": "Rock_Marble_Cobble_Half",
      "rotation": 8
    },
    {
      "x": 1,
      "y": 5,
      "z": 4,
      "name": "Rock_Marble_Cobble"
    },
    {
      "x": 1,
      "y": 6,
      "z": 4,
      "name": "Rock_Runic_Blue_Brick"
    },
    {
      "x": 1,
      "y": 7,
      "z": 4,
      "name": "Furniture_Village_Window"
    },
    {
      "x": 1,
      "y": 8,
      "z": 4,
      "name": "Furniture_Village_Window"
    },
    {
      "x": 1,
      "y": 9,
      "z": 4,
      "name": "Rock_Runic_Blue_Brick"
    },
    {
      "x": 1,
      "y": 10,
      "z": 4,
      "name": "Rock_Marble_Cobble"
    },
    {
      "x": 1,
      "y": 11,
      "z": 4,
      "name": "Furniture_Village_Window"
    },
    {
      "x": 1,
      "y": 12,
      "z": 4,
      "name": "Furniture_Village_Window"
    },
    {
      "x": 1,
      "y": 13,
      "z": 4,
      "name": "Rock_Marble_Cobble"
    },
    {
      "x": 1,
      "y": 14,
      "z": 4,
      "name": "Rock_Runic_Blue_Brick"
    },
    {
      "x": 1,
      "y": 15,
      "z": 4,
      "name": "Furniture_Village_Window"
    },
    {
      "x": 1,
      "y": 16,
      "z": 4,
      "name": "Furniture_Village_Window"
    },
    {
      "x": 1,
      "y": 17,
      "z": 4,
      "name": "Rock_Runic_Blue_Brick"
    },
    {
      "x": 1,
      "y": 18,
      "z": 4,
      "name": "Rock_Marble_Cobble"
    },
    {
      "x": 1,
      "y": 19,
      "z": 4,
      "name": "Furniture_Village_Window"
    },
    {
      "x": 1,
      "y": 20,
      "z": 4,
      "name": "Furniture_Village_Window"
    },
    {
      "x": 1,
      "y": 21,
      "z": 4,
      "name": "Rock_Marble_Cobble"
    },
    {
      "x": 1,
      "y": 22,
      "z": 4,
      "name": "Rock_Runic_Blue_Brick"
    },
    {
      "x": 1,
      "y": 23,
      "z": 4,
      "name": "Rock_Runic_Blue_Brick"
    },
    {
      "x": 1,
      "y": 27,
      "z": 4,
      "name": "Rock_Runic_Blue_Brick_Half",
      "rotation": 4
    },
    {
      "x": 1,
      "y": 28,
      "z": 4,
      "name": "Rock_Runic_Blue_Brick"
    },
    {
      "x": 1,
      "y": 32,
      "z": 4,
      "name": "Rock_Marble_Cobble_Roof_Steep"
    },
    {
      "x": 1,
      "y": 33,
      "z": 4,
      "name": "Rock_Marble_Cobble_Roof_Steep",
      "filler": 1024
    },
    {
      "x": 1,
      "y": 0,
      "z": 5,
      "name": "Rock_Marble_Cobble"
    },
    {
      "x": 1,
      "y": 1,
      "z": 5,
      "name": "Rock_Marble_Cobble"
    },
    {
      "x": 1,
      "y": 2,
      "z": 5,
      "name": "Rock_Marble_Cobble"
    },
    {
      "x": 1,
      "y": 3,
      "z": 5,
      "name": "Rock_Marble_Cobble"
    },
    {
      "x": 1,
      "y": 4,
      "z": 5,
      "name": "Rock_Marble_Cobble"
    },
    {
      "x": 1,
      "y": 5,
      "z": 5,
      "name": "Rock_Marble_Cobble"
    },
    {
      "x": 1,
      "y": 21,
      "z": 5,
      "name": "Rock_Runic_Blue_Brick_Half",
      "rotation": 8
    },
    {
      "x": 1,
      "y": 22,
      "z": 5,
      "name": "Rock_Runic_Blue_Brick"
    },
    {
      "x": 1,
      "y": 23,
      "z": 5,
      "name": "Rock_Runic_Blue_Brick"
    },
    {
      "x": 1,
      "y": 24,
      "z": 5,
      "name": "Metal_Iron_Fence"
    },
    {
      "x": 2,
      "y": 0,
      "z": -5,
      "name": "Rock_Marble_Cobble"
    },
    {
      "x": 2,
      "y": 1,
      "z": -5,
      "name": "Rock_Marble_Cobble"
    },
    {
      "x": 2,
      "y": 2,
      "z": -5,
      "name": "Rock_Marble_Cobble"
    },
    {
      "x": 2,
      "y": 3,
      "z": -5,
      "name": "Rock_Marble_Cobble"
    },
    {
      "x": 2,
      "y": 4,
      "z": -5,
      "name": "Rock_Marble_Cobble"
    },
    {
      "x": 2,
      "y": 5,
      "z": -5,
      "name": "Rock_Marble_Cobble"
    },
    {
      "x": 2,
      "y": 6,
      "z": -5,
      "name": "Rock_Marble_Cobble_Half"
    },
    {
      "x": 2,
      "y": 21,
      "z": -5,
      "name": "Rock_Runic_Blue_Brick_Stairs",
      "rotation": 8
    },
    {
      "x": 2,
      "y": 22,
      "z": -5,
      "name": "Rock_Runic_Blue_Brick"
    },
    {
      "x": 2,
      "y": 23,
      "z": -5,
      "name": "Rock_Runic_Blue_Brick"
    },
    {
      "x": 2,
      "y": 24,
      "z": -5,
      "name": "Metal_Iron_Fence",
      "rotation": 2
    },
    {
      "x": 2,
      "y": 0,
      "z": -4,
      "name": "Wood_Hardwood_Planks"
    },
    {
      "x": 2,
      "y": 1,
      "z": -4,
      "name": "Empty"
    },
    {
      "x": 2,
      "y": 3,
      "z": -4,
      "name": "Wood_Hardwood_Planks_Half"
    },
    {
      "x": 2,
      "y": 5,
      "z": -4,
      "name": "Rock_Marble_Cobble"
    },
    {
      "x": 2,
      "y": 6,
      "z": -4,
      "name": "Rock_Runic_Blue_Brick"
    },
    {
      "x": 2,
      "y": 7,
      "z": -4,
      "name": "Rock_Runic_Blue_Brick"
    },
    {
      "x": 2,
      "y": 8,
      "z": -4,
      "name": "Rock_Runic_Blue_Brick"
    },
    {
      "x": 2,
      "y": 9,
      "z": -4,
      "name": "Rock_Runic_Blue_Brick"
    },
    {
      "x": 2,
      "y": 10,
      "z": -4,
      "name": "Rock_Marble_Cobble"
    },
    {
      "x": 2,
      "y": 11,
      "z": -4,
      "name": "Rock_Marble_Cobble"
    },
    {
      "x": 2,
      "y": 12,
      "z": -4,
      "name": "Rock_Marble_Cobble"
    },
    {
      "x": 2,
      "y": 13,
      "z": -4,
      "name": "Rock_Marble_Cobble"
    },
    {
      "x": 2,
      "y": 14,
      "z": -4,
      "name": "Rock_Runic_Blue_Brick"
    },
    {
      "x": 2,
      "y": 15,
      "z": -4,
      "name": "Rock_Runic_Blue_Brick"
    },
    {
      "x": 2,
      "y": 16,
      "z": -4,
      "name": "Rock_Runic_Blue_Brick"
    },
    {
      "x": 2,
      "y": 17,
      "z": -4,
      "name": "Rock_Runic_Blue_Brick"
    },
    {
      "x": 2,
      "y": 18,
      "z": -4,
      "name": "Rock_Marble_Cobble"
    },
    {
      "x": 2,
      "y": 19,
      "z": -4,
      "name": "Rock_Marble_Cobble"
    },
    {
      "x": 2,
      "y": 20,
      "z": -4,
      "name": "Rock_Marble_Cobble"
    },
    {
      "x": 2,
      "y": 21,
      "z": -4,
      "name": "Rock_Marble_Cobble"
    },
    {
      "x": 2,
      "y": 22,
      "z": -4,
      "name": "Rock_Runic_Blue_Brick"
    },
    {
      "x": 2,
      "y": 23,
      "z": -4,
      "name": "Rock_Runic_Blue_Brick"
    },
    {
      "x": 2,
      "y": 27,
      "z": -4,
      "name": "Rock_Runic_Blue_Brick_Stairs",
      "rotation": 8
    },
    {
      "x": 2,
      "y": 28,
      "z": -4,
      "name": "Rock_Runic_Blue_Brick"
    },
    {
      "x": 2,
      "y": 32,
      "z": -4,
      "name": "Rock_Marble_Cobble_Roof_Steep",
      "rotation": 2
    },
    {
      "x": 2,
      "y": 33,
      "z": -4,
      "name": "Rock_Marble_Cobble_Roof_Steep",
      "filler": 1024,
      "rotation": 2
    },
    {
      "x": 2,
      "y": 0,
      "z": -3,
      "name": "Wood_Hardwood_Planks"
    },
    {
      "x": 2,
      "y": 1,
      "z": -3,
      "name": "Furniture_Village_Chest_Small",
      "components": {
        "Components": {
          "PlacedByInteraction": {
            "WhoPlacedUuid": {
              "$binary": "JMPNY5cWR9+IOfPEr8/h7w==",
              "$type": "04"
            }
          },
          "ItemContainerBlock": {
            "ItemContainer": {
              "Capacity": 18,
              "Items": {}
            },
            "Capacity": 18
          }
        }
      },
      "rotation": 3
    },
    {
      "x": 2,
      "y": 3,
      "z": -3,
      "name": "Wood_Hardwood_Stairs",
      "rotation": 3
    },
    {
      "x": 2,
      "y": 7,
      "z": -3,
      "name": "Wood_Hardwood_Stairs",
      "rotation": 3
    },
    {
      "x": 2,
      "y": 11,
      "z": -3,
      "name": "Wood_Hardwood_Stairs",
      "rotation": 3
    },
    {
      "x": 2,
      "y": 15,
      "z": -3,
      "name": "Wood_Hardwood_Stairs",
      "rotation": 3
    },
    {
      "x": 2,
      "y": 19,
      "z": -3,
      "name": "Wood_Hardwood_Stairs",
      "rotation": 3
    },
    {
      "x": 2,
      "y": 22,
      "z": -3,
      "name": "*Rock_Runic_Blue_Brick_Stairs_State_Definitions_Inverted_Corner_Right",
      "rotation": 9
    },
    {
      "x": 2,
      "y": 23,
      "z": -3,
      "name": "Rock_Runic_Blue_Brick"
    },
    {
      "x": 2,
      "y": 24,
      "z": -3,
      "name": "Rock_Marble_Cobble"
    },
    {
      "x": 2,
      "y": 25,
      "z": -3,
      "name": "Rock_Marble_Cobble"
    },
    {
      "x": 2,
      "y": 26,
      "z": -3,
      "name": "Rock_Marble_Cobble"
    },
    {
      "x": 2,
      "y": 27,
      "z": -3,
      "name": "Rock_Marble_Cobble"
    },
    {
      "x": 2,
      "y": 28,
      "z": -3,
      "name": "Rock_Runic_Blue_Brick"
    },
    {
      "x": 2,
      "y": 33,
      "z": -3,
      "name": "Rock_Marble_Cobble_Stairs",
      "rotation": 10
    },
    {
      "x": 2,
      "y": 34,
      "z": -3,
      "name": "*Rock_Marble_Cobble_Roof_State_Definitions_Corner_Right",
      "rotation": 2
    },
    {
      "x": 2,
      "y": 0,
      "z": -2,
      "name": "Wood_Hardwood_Planks"
    },
    {
      "x": 2,
      "y": 1,
      "z": -2,
      "name": "Empty"
    },
    {
      "x": 2,
      "y": 3,
      "z": -2,
      "name": "*Wood_Hardwood_Stairs_State_Definitions_Inverted_Corner_Left",
      "rotation": 2
    },
    {
      "x": 2,
      "y": 7,
      "z": -2,
      "name": "*Wood_Hardwood_Stairs_State_Definitions_Inverted_Corner_Left",
      "rotation": 2
    },
    {
      "x": 2,
      "y": 11,
      "z": -2,
      "name": "*Wood_Hardwood_Stairs_State_Definitions_Inverted_Corner_Right",
      "rotation": 3
    },
    {
      "x": 2,
      "y": 15,
      "z": -2,
      "name": "*Wood_Hardwood_Stairs_State_Definitions_Inverted_Corner_Right",
      "rotation": 3
    },
    {
      "x": 2,
      "y": 19,
      "z": -2,
      "name": "*Wood_Hardwood_Stairs_State_Definitions_Inverted_Corner_Right",
      "rotation": 3
    },
    {
      "x": 2,
      "y": 23,
      "z": -2,
      "name": "Wood_Hardwood_Planks"
    },
    {
      "x": 2,
      "y": 28,
      "z": -2,
      "name": "Rock_Marble_Cobble"
    },
    {
      "x": 2,
      "y": 29,
      "z": -2,
      "name": "Deco_Iron_Bars"
    },
    {
      "x": 2,
      "y": 34,
      "z": -2,
      "name": "*Rock_Marble_Cobble_Roof_Hollow_State_Definitions_Inverted_Corner_Left",
      "rotation": 1
    },
    {
      "x": 2,
      "y": 0,
      "z": -1,
      "name": "Wood_Hardwood_Planks"
    },
    {
      "x": 2,
      "y": 1,
      "z": -1,
      "name": "Cloth_Roof_Blue_Flat"
    },
    {
      "x": 2,
      "y": 3,
      "z": -1,
      "name": "Wood_Hardwood_Planks_Half",
      "rotation": 8
    },
    {
      "x": 2,
      "y": 7,
      "z": -1,
      "name": "Wood_Hardwood_Planks_Half",
      "rotation": 8
    },
    {
      "x": 2,
      "y": 11,
      "z": -1,
      "name": "Wood_Hardwood_Planks_Half",
      "rotation": 8
    },
    {
      "x": 2,
      "y": 15,
      "z": -1,
      "name": "Wood_Hardwood_Planks_Half",
      "rotation": 8
    },
    {
      "x": 2,
      "y": 19,
      "z": -1,
      "name": "Wood_Hardwood_Planks_Half",
      "rotation": 8
    },
    {
      "x": 2,
      "y": 23,
      "z": -1,
      "name": "Wood_Hardwood_Planks"
    },
    {
      "x": 2,
      "y": 28,
      "z": -1,
      "name": "Rock_Marble_Cobble"
    },
    {
      "x": 2,
      "y": 35,
      "z": -1,
      "name": "*Rock_Marble_Cobble_Roof_Hollow_State_Definitions_Corner_Right",
      "rotation": 2
    },
    {
      "x": 2,
      "y": 0,
      "z": 0,
      "name": "Wood_Hardwood_Planks"
    },
    {
      "x": 2,
      "y": 1,
      "z": 0,
      "name": "Cloth_Roof_Blue_Flat"
    },
    {
      "x": 2,
      "y": 4,
      "z": 0,
      "name": "Wood_Hardwood_Stairs",
      "rotation": 2
    },
    {
      "x": 2,
      "y": 8,
      "z": 0,
      "name": "Wood_Hardwood_Stairs",
      "rotation": 2
    },
    {
      "x": 2,
      "y": 12,
      "z": 0,
      "name": "Wood_Hardwood_Stairs",
      "rotation": 2
    },
    {
      "x": 2,
      "y": 16,
      "z": 0,
      "name": "Wood_Hardwood_Stairs",
      "rotation": 2
    },
    {
      "x": 2,
      "y": 19,
      "z": 0,
      "name": "Wood_Hardwood_Planks_Half",
      "rotation": 8
    },
    {
      "x": 2,
      "y": 23,
      "z": 0,
      "name": "Wood_Hardwood_Planks"
    },
    {
      "x": 2,
      "y": 28,
      "z": 0,
      "name": "Rock_Marble_Cobble"
    },
    {
      "x": 2,
      "y": 35,
      "z": 0,
      "name": "Rock_Marble_Cobble_Roof_Shallow",
      "filler": 31,
      "rotation": 1
    },
    {
      "x": 2,
      "y": 0,
      "z": 1,
      "name": "Wood_Hardwood_Planks"
    },
    {
      "x": 2,
      "y": 1,
      "z": 1,
      "name": "Cloth_Roof_Blue_Flat"
    },
    {
      "x": 2,
      "y": 4,
      "z": 1,
      "name": "Wood_Hardwood_Planks_Half",
      "rotation": 8
    },
    {
      "x": 2,
      "y": 8,
      "z": 1,
      "name": "Wood_Hardwood_Planks_Half",
      "rotation": 8
    },
    {
      "x": 2,
      "y": 12,
      "z": 1,
      "name": "Wood_Hardwood_Planks_Half",
      "rotation": 8
    },
    {
      "x": 2,
      "y": 16,
      "z": 1,
      "name": "Wood_Hardwood_Planks_Half",
      "rotation": 8
    },
    {
      "x": 2,
      "y": 23,
      "z": 1,
      "name": "Wood_Hardwood_Planks"
    },
    {
      "x": 2,
      "y": 24,
      "z": 1,
      "name": "Furniture_Tavern_Ladder",
      "rotation": 2
    },
    {
      "x": 2,
      "y": 25,
      "z": 1,
      "name": "Furniture_Tavern_Ladder",
      "rotation": 2
    },
    {
      "x": 2,
      "y": 26,
      "z": 1,
      "name": "Furniture_Tavern_Ladder",
      "rotation": 2
    },
    {
      "x": 2,
      "y": 27,
      "z": 1,
      "name": "Furniture_Tavern_Ladder",
      "rotation": 2
    },
    {
      "x": 2,
      "y": 28,
      "z": 1,
      "name": "*Furniture_Village_Trapdoor_State_Definitions_CloseDoorOut",
      "rotation": 2
    },
    {
      "x": 2,
      "y": 35,
      "z": 1,
      "name": "*Rock_Marble_Cobble_Roof_Hollow_State_Definitions_Corner_Left"
    },
    {
      "x": 2,
      "y": 0,
      "z": 2,
      "name": "Wood_Hardwood_Planks"
    },
    {
      "x": 2,
      "y": 1,
      "z": 2,
      "name": "Empty"
    },
    {
      "x": 2,
      "y": 4,
      "z": 2,
      "name": "Wood_Hardwood_Planks_Half",
      "rotation": 8
    },
    {
      "x": 2,
      "y": 8,
      "z": 2,
      "name": "Wood_Hardwood_Planks_Half",
      "rotation": 8
    },
    {
      "x": 2,
      "y": 12,
      "z": 2,
      "name": "Wood_Hardwood_Planks_Half",
      "rotation": 8
    },
    {
      "x": 2,
      "y": 16,
      "z": 2,
      "name": "Wood_Hardwood_Planks_Half",
      "rotation": 8
    },
    {
      "x": 2,
      "y": 23,
      "z": 2,
      "name": "Wood_Hardwood_Planks"
    },
    {
      "x": 2,
      "y": 28,
      "z": 2,
      "name": "Rock_Marble_Cobble"
    },
    {
      "x": 2,
      "y": 29,
      "z": 2,
      "name": "Deco_Iron_Bars"
    },
    {
      "x": 2,
      "y": 34,
      "z": 2,
      "name": "*Rock_Marble_Cobble_Roof_Hollow_State_Definitions_Inverted_Corner_Left"
    },
    {
      "x": 2,
      "y": 0,
      "z": 3,
      "name": "Wood_Hardwood_Planks"
    },
    {
      "x": 2,
      "y": 1,
      "z": 3,
      "name": "Furniture_Tavern_Chair",
      "rotation": 1
    },
    {
      "x": 2,
      "y": 4,
      "z": 3,
      "name": "Wood_Hardwood_Planks_Half",
      "rotation": 8
    },
    {
      "x": 2,
      "y": 8,
      "z": 3,
      "name": "Wood_Hardwood_Planks_Half",
      "rotation": 8
    },
    {
      "x": 2,
      "y": 12,
      "z": 3,
      "name": "Wood_Hardwood_Planks_Half",
      "rotation": 8
    },
    {
      "x": 2,
      "y": 16,
      "z": 3,
      "name": "Wood_Hardwood_Planks_Half",
      "rotation": 8
    },
    {
      "x": 2,
      "y": 22,
      "z": 3,
      "name": "*Rock_Runic_Blue_Brick_Stairs_State_Definitions_Inverted_Corner_Left",
      "rotation": 9
    },
    {
      "x": 2,
      "y": 23,
      "z": 3,
      "name": "Rock_Runic_Blue_Brick"
    },
    {
      "x": 2,
      "y": 24,
      "z": 3,
      "name": "Rock_Marble_Cobble"
    },
    {
      "x": 2,
      "y": 25,
      "z": 3,
      "name": "Rock_Marble_Cobble"
    },
    {
      "x": 2,
      "y": 26,
      "z": 3,
      "name": "Rock_Marble_Cobble"
    },
    {
      "x": 2,
      "y": 27,
      "z": 3,
      "name": "Rock_Marble_Cobble"
    },
    {
      "x": 2,
      "y": 28,
      "z": 3,
      "name": "Rock_Runic_Blue_Brick"
    },
    {
      "x": 2,
      "y": 33,
      "z": 3,
      "name": "Rock_Marble_Cobble_Stairs",
      "rotation": 8
    },
    {
      "x": 2,
      "y": 34,
      "z": 3,
      "name": "*Rock_Marble_Cobble_Roof_State_Definitions_Corner_Right",
      "rotation": 1
    },
    {
      "x": 2,
      "y": 0,
      "z": 4,
      "name": "Wood_Hardwood_Planks"
    },
    {
      "x": 2,
      "y": 1,
      "z": 4,
      "name": "Furniture_Village_Bookcase",
      "rotation": 2
    },
    {
      "x": 2,
      "y": 2,
      "z": 4,
      "name": "Furniture_Village_Shelf_Full",
      "rotation": 2
    },
    {
      "x": 2,
      "y": 3,
      "z": 4,
      "name": "Furniture_Village_Shelf_Full",
      "rotation": 2
    },
    {
      "x": 2,
      "y": 5,
      "z": 4,
      "name": "Rock_Marble_Cobble"
    },
    {
      "x": 2,
      "y": 6,
      "z": 4,
      "name": "Rock_Runic_Blue_Brick"
    },
    {
      "x": 2,
      "y": 7,
      "z": 4,
      "name": "Rock_Runic_Blue_Brick"
    },
    {
      "x": 2,
      "y": 8,
      "z": 4,
      "name": "Rock_Runic_Blue_Brick"
