{
  "version": 8,
  "blockIdVersion": 10,
  "anchorX": 0,
  "anchorY": 5,
  "anchorZ": 0,
  "blocks": [
    {
      "x": 0,
      "y": 9,
      "z": 0,
      "name": "Soil_Moss_Purple"
    },
    {
      "x": 1,
      "y": 9,
      "z": 0,
      "name": "Rock_Crystal_Purple_Block"
    },
    {
      "x": 2,
      "y": 9,
      "z": 0,
      "name": "Soil_Moss_Purple"
    },
    {
      "x": 0,
      "y": 10,
      "z": 0,
      "name": "Soil_Moss_Purple"
    },
    {
      "x": 1,
      "y": 10,
      "z": 0,
      "name": "Rock_Crystal_Purple_Block"
    },
    {
      "x": 2,
      "y": 10,
      "z": 0,
      "name": "Soil_Moss_Purple"
    },
    {
      "x": 0,
      "y": 11,
      "z": 0,
      "name": "Soil_Moss_Purple"
    },
    {
      "x": 2,
      "y": 11,
      "z": 0,
      "name": "Soil_Moss_Purple"
    },
    {
      "x": 3,
      "y": 11,
      "z": 0,
      "name": "Soil_Moss_Purple"
    },
    {
      "x": 5,
      "y": 14,
      "z": 0,
      "name": "Plant_Coral_Block_Green"
    },
    {
      "x": 6,
      "y": 14,
      "z": 0,
      "name": "Plant_Coral_Block_Green"
    },
    {
      "x": 7,
      "y": 14,
      "z": 0,
      "name": "Plant_Coral_Block_Green"
    },
    {
      "x": 5,
      "y": 15,
      "z": 0,
      "name": "Plant_Coral_Bush_Green"
    },
    {
      "x": 6,
      "y": 15,
      "z": 0,
      "name": "Plant_Coral_Bush_Green"
    },
    {
      "x": 7,
      "y": 15,
      "z": 0,
      "name": "Plant_Coral_Bush_Green"
    },
    {
      "x": 1,
      "y": 9,
      "z": 1,
      "name": "Soil_Moss_Purple"
    },
    {
      "x": 1,
      "y": 10,
      "z": 1,
      "name": "Soil_Moss_Purple"
    },
    {
      "x": 0,
      "y": 11,
      "z": 1,
      "name": "Soil_Moss_Purple"
    },
    {
      "x": 1,
      "y": 11,
      "z": 1,
      "name": "Soil_Moss_Purple"
    },
    {
      "x": 2,
      "y": 11,
      "z": 1,
      "name": "Soil_Moss_Purple"
    },
    {
      "x": 1,
      "y": 11,
      "z": 2,
      "name": "Soil_Moss_Purple"
    },
    {
      "x": 2,
      "y": 11,
      "z": 2,
      "name": "Soil_Moss_Purple"
    },
    {
      "x": 2,
      "y": 12,
      "z": 2,
      "name": "Soil_Moss_Purple"
    },
    {
      "x": 2,
      "y": 12,
      "z": 3,
      "name": "Soil_Moss_Purple"
    },
    {
      "x": 3,
      "y": 12,
      "z": 3,
      "name": "Soil_Moss_Purple"
    },
    {
      "x": 3,
      "y": 12,
      "z": 4,
      "name": "Soil_Moss_Purple"
    },
    {
      "x": 3,
      "y": 13,
      "z": 4,
      "name": "Soil_Moss_Purple"
    },
    {
      "x": 3,
      "y": 14,
      "z": 4,
      "name": "Plant_Coral_Block_Green"
    },
    {
      "x": 4,
      "y": 14,
      "z": 4,
      "name": "Plant_Coral_Block_Green"
    },
    {
      "x": 5,
      "y": 14,
      "z": 4,
      "name": "Plant_Coral_Block_Green"
    },
    {
      "x": 3,
      "y": 15,
      "z": 4,
      "name": "Plant_Coral_Bush_Green"
    },
    {
      "x": 4,
      "y": 15,
      "z": 4,
      "name": "Plant_Coral_Bush_Green"
    },
    {
      "x": 5,
      "y": 15,
      "z": 4,
      "name": "Plant_Coral_Bush_Green"
    },
    {
      "x": 2,
      "y": 13,
      "z": 5,
      "name": "Plant_Coral_Block_Green"
    },
    {
      "x": 3,
      "y": 13,
      "z": 5,
      "name": "Soil_Moss_Purple"
    },
    {
      "x": 2,
      "y": 14,
      "z": 5,
      "name": "Plant_Coral_Block_Green"
    },
    {
      "x": 3,
      "y": 14,
      "z": 5,
      "name": "Plant_Coral_Block_Green"
    },
    {
      "x": 4,
      "y": 14,
      "z": 5,
      "name": "Plant_Coral_Block_Green"
    },
    {
      "x": 5,
      "y": 14,
      "z": 5,
      "name": "Plant_Coral_Block_Green"
    },
    {
      "x": 6,
      "y": 14,
      "z": 5,
      "name": "Plant_Coral_Block_Green"
    },
    {
      "x": 2,
      "y": 15,
      "z": 5,
      "name": "Plant_Coral_Bush_Green"
    },
    {
      "x": 3,
      "y": 15,
      "z": 5,
      "name": "Plant_Coral_Block_Green"
    },
    {
      "x": 4,
      "y": 15,
      "z": 5,
      "name": "Plant_Coral_Block_Green"
    },
    {
      "x": 5,
      "y": 15,
      "z": 5,
      "name": "Plant_Coral_Bush_Green"
    },
    {
      "x": 3,
      "y": 16,
      "z": 5,
      "name": "Plant_Coral_Bush_Green"
    },
    {
      "x": 4,
      "y": 16,
      "z": 5,
      "name": "Plant_Coral_Bush_Green"
    },
    {
      "x": 2,
      "y": 14,
      "z": 6,
      "name": "Plant_Coral_Block_Lime"
    },
    {
      "x": 3,
      "y": 14,
      "z": 6,
      "name": "Plant_Coral_Block_Green"
    },
    {
      "x": 4,
      "y": 14,
      "z": 6,
      "name": "Soil_Moss_Purple"
    },
    {
      "x": 5,
      "y": 14,
      "z": 6,
      "name": "Plant_Coral_Block_Green"
    },
    {
      "x": 6,
      "y": 14,
      "z": 6,
      "name": "Plant_Coral_Block_Green"
    },
    {
      "x": 7,
      "y": 14,
      "z": 6,
      "name": "Plant_Coral_Block_Green"
    },
    {
      "x": 3,
      "y": 15,
      "z": 6,
      "name": "Plant_Coral_Block_Green"
    },
    {
      "x": 4,
      "y": 15,
      "z": 6,
      "name": "Plant_Coral_Block_Green"
    },
    {
      "x": 5,
      "y": 15,
      "z": 6,
      "name": "Plant_Coral_Block_Green"
    },
    {
      "x": 6,
      "y": 15,
      "z": 6,
      "name": "Plant_Coral_Bush_Green"
    },
    {
      "x": 7,
      "y": 15,
      "z": 6,
      "name": "Plant_Coral_Bush_Green"
    },
    {
      "x": 3,
      "y": 16,
      "z": 6,
      "name": "Plant_Coral_Bush_Green"
    },
    {
      "x": 2,
      "y": 14,
      "z": 7,
      "name": "Plant_Coral_Block_Lime"
    },
    {
      "x": 3,
      "y": 14,
      "z": 7,
      "name": "Plant_Coral_Block_Green"
    },
    {
      "x": 4,
      "y": 14,
      "z": 7,
      "name": "Plant_Coral_Block_Green"
    },
    {
      "x": 5,
      "y": 14,
      "z": 7,
      "name": "Plant_Coral_Block_Green"
    },
    {
      "x": 6,
      "y": 14,
      "z": 7,
      "name": "Plant_Coral_Block_Green"
    },
    {
      "x": 7,
      "y": 14,
      "z": 7,
      "name": "Plant_Coral_Block_Green"
    },
    {
      "x": 3,
      "y": 15,
      "z": 7,
      "name": "Plant_Coral_Bush_Green"
    },
    {
      "x": 4,
      "y": 15,
      "z": 7,
      "name": "Plant_Coral_Block_Green"
    },
    {
      "x": 5,
      "y": 15,
      "z": 7,
      "name": "Plant_Coral_Block_Green"
    },
    {
      "x": 7,
      "y": 15,
      "z": 7,
      "name": "Plant_Coral_Bush_Green"
    },
    {
      "x": 3,
      "y": 14,
      "z": 8,
      "name": "Plant_Coral_Block_Green"
    },
    {
      "x": 4,
      "y": 14,
      "z": 8,
      "name": "Plant_Coral_Block_Green"
    },
    {
      "x": 5,
      "y": 14,
      "z": 8,
      "name": "Plant_Coral_Block_Green"
    },
    {
      "x": 6,
      "y": 14,
      "z": 8,
      "name": "Plant_Coral_Block_Green"
    },
    {
      "x": 5,
      "y": 15,
      "z": 8,
      "name": "Plant_Coral_Bush_Green"
    },
    {
      "x": 4,
      "y": 14,
      "z": 9,
      "name": "Plant_Coral_Block_Green"
    },
    {
      "x": 0,
      "y": 0,
      "z": -1,
      "name": "Soil_Moss_Purple"
    },
    {
      "x": 0,
      "y": 1,
      "z": -1,
      "name": "Soil_Moss_Purple"
    },
    {
      "x": 0,
      "y": 2,
      "z": -1,
      "name": "Soil_Moss_Purple"
    },
    {
      "x": 0,
      "y": 3,
      "z": -1,
      "name": "Soil_Moss_Purple"
    },
    {
      "x": 0,
      "y": 4,
      "z": -1,
      "name": "Soil_Moss_Purple"
    },
    {
      "x": 0,
      "y": 5,
      "z": -1,
      "name": "Soil_Moss_Purple"
    },
    {
      "x": 0,
      "y": 6,
      "z": -1,
      "name": "Soil_Moss_Purple"
    },
    {
      "x": 1,
      "y": 6,
      "z": -1,
      "name": "Soil_Moss_Purple"
    },
    {
      "x": 0,
      "y": 7,
      "z": -1,
      "name": "Soil_Moss_Purple"
    },
    {
      "x": 1,
      "y": 7,
      "z": -1,
      "name": "Soil_Moss_Purple"
    },
    {
      "x": 1,
      "y": 8,
      "z": -1,
      "name": "Soil_Moss_Purple"
    },
    {
      "x": 5,
      "y": 13,
      "z": -6,
      "name": "Plant_Coral_Block_Green"
    },
    {
      "x": 5,
      "y": 14,
      "z": -6,
      "name": "Plant_Coral_Block_Green"
    },
    {
      "x": 6,
      "y": 14,
      "z": -6,
      "name": "Plant_Coral_Block_Green"
    },
    {
      "x": 7,
      "y": 14,
      "z": -6,
      "name": "Plant_Coral_Block_Lime"
    },
    {
      "x": 5,
      "y": 15,
      "z": -6,
      "name": "Plant_Coral_Bush_Green"
    },
    {
      "x": 6,
      "y": 15,
      "z": -6,
      "name": "Plant_Coral_Bush_Green"
    },
    {
      "x": 4,
      "y": 13,
      "z": -5,
      "name": "Plant_Coral_Block_Green"
    },
    {
      "x": 5,
      "y": 13,
      "z": -5,
      "name": "Plant_Coral_Block_Green"
    },
    {
      "x": 4,
      "y": 14,
      "z": -5,
      "name": "Plant_Coral_Block_Green"
    },
    {
      "x": 5,
      "y": 14,
      "z": -5,
      "name": "Plant_Coral_Block_Green"
    },
    {
      "x": 6,
      "y": 14,
      "z": -5,
      "name": "Plant_Coral_Block_Green"
    },
    {
      "x": 7,
      "y": 14,
      "z": -5,
      "name": "Plant_Coral_Block_Green"
    },
    {
      "x": 8,
      "y": 14,
      "z": -5,
      "name": "Plant_Coral_Block_Lime"
    },
    {
      "x": 4,
      "y": 15,
      "z": -5,
      "name": "Plant_Coral_Bush_Green"
    },
    {
      "x": 5,
      "y": 15,
      "z": -5,
      "name": "Plant_Coral_Bush_Green"
    },
    {
      "x": 6,
      "y": 15,
      "z": -5,
      "name": "Plant_Coral_Bush_Green"
    },
    {
      "x": 3,
      "y": 13,
      "z": -4,
      "name": "Soil_Moss_Purple"
    },
    {
      "x": 4,
      "y": 13,
      "z": -4,
      "name": "Plant_Coral_Block_Green"
    },
    {
      "x": 5,
      "y": 13,
      "z": -4,
      "name": "Plant_Coral_Block_Green"
    },
    {
      "x": 6,
      "y": 13,
      "z": -4,
      "name": "Plant_Coral_Block_Green"
    },
    {
      "x": 4,
      "y": 14,
      "z": -4,
      "name": "Plant_Coral_Block_Green"
    },
    {
      "x": 5,
      "y": 14,
      "z": -4,
      "name": "Plant_Coral_Block_Green"
    },
    {
      "x": 6,
      "y": 14,
      "z": -4,
      "name": "Plant_Coral_Block_Green"
    },
    {
      "x": 7,
      "y": 14,
      "z": -4,
      "name": "Plant_Coral_Block_Lime"
    },
    {
      "x": 8,
      "y": 14,
      "z": -4,
      "name": "Plant_Coral_Block_Green"
    },
    {
      "x": 9,
      "y": 14,
      "z": -4,
      "name": "Plant_Coral_Block_Lime"
    },
    {
      "x": 4,
      "y": 15,
      "z": -4,
      "name": "Plant_Coral_Bush_Green"
    },
    {
      "x": 5,
      "y": 15,
      "z": -4,
      "name": "Plant_Coral_Block_Green"
    },
    {
      "x": 6,
      "y": 15,
      "z": -4,
      "name": "Plant_Coral_Block_Green"
    },
    {
      "x": 5,
      "y": 16,
      "z": -4,
      "name": "Plant_Coral_Bush_Green"
    },
    {
      "x": 6,
      "y": 16,
      "z": -4,
      "name": "Plant_Coral_Bush_Green"
    },
    {
      "x": 2,
      "y": 12,
      "z": -3,
      "name": "Soil_Moss_Purple"
    },
    {
      "x": 2,
      "y": 13,
      "z": -3,
      "name": "Soil_Moss_Purple"
    },
    {
      "x": 3,
      "y": 13,
      "z": -3,
      "name": "Soil_Moss_Purple"
    },
    {
      "x": 4,
      "y": 13,
      "z": -3,
      "name": "Plant_Coral_Block_Green"
    },
    {
      "x": 5,
      "y": 13,
      "z": -3,
      "name": "Plant_Coral_Block_Green"
    },
    {
      "x": 3,
      "y": 14,
      "z": -3,
      "name": "Plant_Coral_Block_Green"
    },
    {
      "x": 4,
      "y": 14,
      "z": -3,
      "name": "Plant_Coral_Block_Green"
    },
    {
      "x": 5,
      "y": 14,
      "z": -3,
      "name": "Plant_Coral_Block_Green"
    },
    {
      "x": 6,
      "y": 14,
      "z": -3,
      "name": "Soil_Moss_Purple"
    },
    {
      "x": 7,
      "y": 14,
      "z": -3,
      "name": "Plant_Coral_Block_Green"
    },
    {
      "x": 8,
      "y": 14,
      "z": -3,
      "name": "Plant_Coral_Block_Green"
    },
    {
      "x": 9,
      "y": 14,
      "z": -3,
      "name": "Plant_Coral_Block_Green"
    },
    {
      "x": 3,
      "y": 15,
      "z": -3,
      "name": "Plant_Coral_Bush_Green"
    },
    {
      "x": 4,
      "y": 15,
      "z": -3,
      "name": "Plant_Coral_Bush_Green"
    },
    {
      "x": 5,
      "y": 15,
      "z": -3,
      "name": "Plant_Coral_Block_Green"
    },
    {
      "x": 6,
      "y": 15,
      "z": -3,
      "name": "Rock_Crystal_Green_Block"
    },
    {
      "x": 7,
      "y": 15,
      "z": -3,
      "name": "Plant_Coral_Block_Green"
    },
    {
      "x": 8,
      "y": 15,
      "z": -3,
      "name": "Plant_Coral_Bush_Green"
    },
    {
      "x": 6,
      "y": 16,
      "z": -3,
      "name": "Plant_Coral_Bush_Green"
    },
    {
      "x": 7,
      "y": 16,
      "z": -3,
      "name": "Plant_Coral_Bush_Green"
    },
    {
      "x": 0,
      "y": 11,
      "z": -2,
      "name": "Soil_Moss_Purple"
    },
    {
      "x": 1,
      "y": 12,
      "z": -2,
      "name": "Soil_Moss_Purple"
    },
    {
      "x": 2,
      "y": 12,
      "z": -2,
      "name": "Soil_Moss_Purple"
    },
    {
      "x": 4,
      "y": 12,
      "z": -2,
      "name": "Soil_Moss_Purple"
    },
    {
      "x": 3,
      "y": 13,
      "z": -2,
      "name": "Plant_Coral_Block_Green"
    },
    {
      "x": 4,
      "y": 13,
      "z": -2,
      "name": "Plant_Coral_Block_Green"
    },
    {
      "x": 5,
      "y": 13,
      "z": -2,
      "name": "Soil_Moss_Purple"
    },
    {
      "x": 3,
      "y": 14,
      "z": -2,
      "name": "Plant_Coral_Block_Green"
    },
    {
      "x": 4,
      "y": 14,
      "z": -2,
      "name": "Plant_Coral_Block_Green"
    },
    {
      "x": 5,
      "y": 14,
      "z": -2,
      "name": "Plant_Coral_Block_Green"
    },
    {
      "x": 6,
      "y": 14,
      "z": -2,
      "name": "Plant_Coral_Block_Green"
    },
    {
      "x": 7,
      "y": 14,
      "z": -2,
      "name": "Plant_Coral_Block_Green"
    },
    {
      "x": 8,
      "y": 14,
      "z": -2,
      "name": "Plant_Coral_Block_Green"
    },
    {
      "x": 9,
      "y": 14,
      "z": -2,
      "name": "Plant_Coral_Block_Lime"
    },
    {
      "x": 4,
      "y": 15,
      "z": -2,
      "name": "Plant_Coral_Bush_Green"
    },
    {
      "x": 5,
      "y": 15,
      "z": -2,
      "name": "Plant_Coral_Bush_Green"
    },
    {
      "x": 6,
      "y": 15,
      "z": -2,
      "name": "Plant_Coral_Block_Green"
    },
    {
      "x": 7,
      "y": 15,
      "z": -2,
      "name": "Plant_Coral_Block_Green"
    },
    {
      "x": 8,
      "y": 15,
      "z": -2,
      "name": "Plant_Coral_Bush_Green"
    },
    {
      "x": 6,
      "y": 16,
      "z": -2,
      "name": "Plant_Coral_Bush_Green"
    },
    {
      "x": 1,
      "y": 9,
      "z": -1,
      "name": "Soil_Moss_Purple"
    },
    {
      "x": 1,
      "y": 10,
      "z": -1,
      "name": "Soil_Moss_Purple"
    },
    {
      "x": 0,
      "y": 11,
      "z": -1,
      "name": "Soil_Moss_Purple"
    },
    {
      "x": 1,
      "y": 11,
      "z": -1,
      "name": "Soil_Moss_Purple"
    },
    {
      "x": 2,
      "y": 11,
      "z": -1,
      "name": "Soil_Moss_Purple"
    },
    {
      "x": 3,
      "y": 11,
      "z": -1,
      "name": "Soil_Moss_Purple"
    },
    {
      "x": 1,
      "y": 12,
      "z": -1,
      "name": "Soil_Moss_Purple"
    },
    {
      "x": 3,
      "y": 12,
      "z": -1,
      "name": "Soil_Moss_Purple"
    },
    {
      "x": 4,
      "y": 12,
      "z": -1,
      "name": "Soil_Moss_Purple"
    },
    {
      "x": 3,
      "y": 13,
      "z": -1,
      "name": "Plant_Coral_Block_Green"
    },
    {
      "x": 3,
      "y": 14,
      "z": -1,
      "name": "Plant_Coral_Bush_Green"
    },
    {
      "x": 4,
      "y": 14,
      "z": -1,
      "name": "Plant_Coral_Block_Green"
    },
    {
      "x": 5,
      "y": 14,
      "z": -1,
      "name": "Plant_Coral_Block_Green"
    },
    {
      "x": 6,
      "y": 14,
      "z": -1,
      "name": "Plant_Coral_Block_Green"
    },
    {
      "x": 7,
      "y": 14,
      "z": -1,
      "name": "Plant_Coral_Block_Green"
    },
    {
      "x": 8,
      "y": 14,
      "z": -1,
      "name": "Plant_Coral_Block_Lime"
    },
    {
      "x": 4,
      "y": 15,
      "z": -1,
      "name": "Plant_Coral_Bush_Green"
    },
    {
      "x": 5,
      "y": 15,
      "z": -1,
      "name": "Plant_Coral_Bush_Green"
    },
    {
      "x": 6,
      "y": 15,
      "z": -1,
      "name": "Plant_Coral_Bush_Green"
    },
    {
      "x": 7,
      "y": 15,
      "z": -1,
      "name": "Plant_Coral_Bush_Green"
    },
    {
      "x": -5,
      "y": 14,
      "z": -8,
      "name": "Plant_Coral_Block_Lime"
    },
    {
      "x": -4,
      "y": 14,
      "z": -8,
      "name": "Plant_Coral_Block_Lime"
    },
    {
      "x": -6,
      "y": 14,
      "z": -7,
      "name": "Plant_Coral_Block_Lime"
    },
    {
      "x": -5,
      "y": 14,
      "z": -7,
      "name": "Plant_Coral_Block_Green"
    },
    {
      "x": -4,
      "y": 14,
      "z": -7,
      "name": "Plant_Coral_Block_Lime"
    },
    {
      "x": -3,
      "y": 14,
      "z": -7,
      "name": "Plant_Coral_Block_Lime"
    },
    {
      "x": -7,
      "y": 14,
      "z": -6,
      "name": "Plant_Coral_Block_Green"
    },
    {
      "x": -6,
      "y": 14,
      "z": -6,
      "name": "Plant_Coral_Block_Green"
    },
    {
      "x": -5,
      "y": 14,
      "z": -6,
      "name": "Plant_Coral_Block_Green"
    },
    {
      "x": -4,
      "y": 14,
      "z": -6,
      "name": "Plant_Coral_Block_Green"
    },
    {
      "x": -3,
      "y": 14,
      "z": -6,
      "name": "Plant_Coral_Block_Green"
    },
    {
      "x": -2,
      "y": 14,
      "z": -6,
      "name": "Plant_Coral_Block_Lime"
    },
    {
      "x": -7,
      "y": 15,
      "z": -6,
      "name": "Plant_Coral_Bush_Green"
    },
    {
      "x": -6,
      "y": 15,
      "z": -6,
      "name": "Plant_Coral_Bush_Green"
    },
    {
      "x": -5,
      "y": 15,
      "z": -6,
      "name": "Plant_Coral_Block_Green"
    },
    {
      "x": -4,
      "y": 15,
      "z": -6,
      "name": "Plant_Coral_Block_Green"
    },
    {
      "x": -5,
      "y": 16,
      "z": -6,
      "name": "Plant_Coral_Bush_Green"
    },
    {
      "x": -7,
      "y": 14,
      "z": -5,
      "name": "Plant_Coral_Block_Lime"
    },
    {
      "x": -6,
      "y": 14,
      "z": -5,
      "name": "Plant_Coral_Block_Green"
    },
    {
      "x": -5,
      "y": 14,
      "z": -5,
      "name": "Plant_Coral_Block_Green"
    },
    {
      "x": -4,
      "y": 14,
      "z": -5,
      "name": "Soil_Moss_Purple"
    },
    {
      "x": -3,
      "y": 14,
      "z": -5,
      "name": "Plant_Coral_Block_Green"
    },
    {
      "x": -2,
      "y": 14,
      "z": -5,
      "name": "Plant_Coral_Block_Green"
    },
    {
      "x": -6,
      "y": 15,
      "z": -5,
      "name": "Plant_Coral_Bush_Green"
    },
    {
      "x": -5,
      "y": 15,
      "z": -5,
      "name": "Plant_Coral_Block_Green"
    },
    {
      "x": -4,
      "y": 15,
      "z": -5,
      "name": "Plant_Coral_Block_Green"
    },
    {
      "x": -3,
      "y": 15,
      "z": -5,
      "name": "Plant_Coral_Block_Green"
    },
    {
      "x": -5,
      "y": 16,
      "z": -5,
      "name": "Plant_Coral_Bush_Green"
    },
    {
      "x": -4,
      "y": 16,
      "z": -5,
      "name": "Plant_Coral_Bush_Green"
    },
    {
      "x": -3,
      "y": 16,
      "z": -5,
      "name": "Plant_Coral_Bush_Green"
    },
    {
      "x": -3,
      "y": 13,
      "z": -4,
      "name": "Soil_Moss_Purple"
    },
    {
      "x": -7,
      "y": 14,
      "z": -4,
      "name": "Plant_Coral_Block_Lime"
    },
    {
      "x": -6,
      "y": 14,
      "z": -4,
      "name": "Plant_Coral_Block_Lime"
    },
    {
      "x": -5,
      "y": 14,
      "z": -4,
      "name": "Plant_Coral_Block_Green"
    },
    {
      "x": -4,
      "y": 14,
      "z": -4,
      "name": "Plant_Coral_Block_Green"
    },
    {
      "x": -3,
      "y": 14,
      "z": -4,
      "name": "Plant_Coral_Block_Green"
    },
    {
      "x": -2,
      "y": 14,
      "z": -4,
      "name": "Plant_Coral_Block_Green"
    },
    {
      "x": -5,
      "y": 15,
      "z": -4,
      "name": "Plant_Coral_Bush_Green"
    },
    {
      "x": -4,
      "y": 15,
      "z": -4,
      "name": "Plant_Coral_Block_Green"
    },
    {
      "x": -3,
      "y": 15,
      "z": -4,
      "name": "Plant_Coral_Block_Green"
    },
    {
      "x": -2,
      "y": 15,
      "z": -4,
      "name": "Plant_Coral_Bush_Green"
    },
    {
      "x": -4,
      "y": 16,
      "z": -4,
      "name": "Plant_Coral_Bush_Green"
    },
    {
      "x": -3,
      "y": 16,
      "z": -4,
      "name": "Plant_Coral_Bush_Green"
    },
    {
      "x": -2,
      "y": 12,
      "z": -3,
      "name": "Soil_Moss_Purple"
    },
    {
      "x": -3,
      "y": 13,
      "z": -3,
      "name": "Soil_Moss_Purple"
    },
    {
      "x": -2,
      "y": 13,
      "z": -3,
      "name": "Soil_Moss_Purple"
    },
    {
      "x": -6,
      "y": 14,
      "z": -3,
      "name": "Plant_Coral_Block_Lime"
    },
    {
      "x": -5,
      "y": 14,
      "z": -3,
      "name": "Plant_Coral_Block_Lime"
    },
    {
      "x": -4,
      "y": 14,
      "z": -3,
      "name": "Plant_Coral_Block_Green"
    },
    {
      "x": -3,
      "y": 14,
      "z": -3,
      "name": "Plant_Coral_Block_Green"
    },
    {
      "x": -2,
      "y": 14,
      "z": -3,
      "name": "Plant_Coral_Block_Green"
    },
    {
      "x": -4,
      "y": 15,
      "z": -3,
      "name": "Plant_Coral_Bush_Green"
    },
    {
      "x": -3,
      "y": 15,
      "z": -3,
      "name": "Plant_Coral_Bush_Green"
    },
    {
      "x": -2,
      "y": 15,
      "z": -3,
      "name": "Plant_Coral_Bush_Green"
    },
    {
      "x": -2,
      "y": 12,
      "z": -2,
      "name": "Soil_Moss_Purple"
    },
    {
      "x": -1,
      "y": 12,
      "z": -2,
      "name": "Soil_Moss_Purple"
    },
    {
      "x": -5,
      "y": 14,
      "z": -2,
      "name": "Plant_Coral_Block_Green"
    },
    {
      "x": -4,
      "y": 14,
      "z": -2,
      "name": "Plant_Coral_Block_Green"
    },
    {
      "x": -3,
      "y": 14,
      "z": -2,
      "name": "Plant_Coral_Block_Green"
    },
    {
      "x": -5,
      "y": 15,
      "z": -2,
      "name": "Plant_Coral_Bush_Green"
    },
    {
      "x": -4,
      "y": 15,
      "z": -2,
      "name": "Plant_Coral_Bush_Green"
    },
    {
      "x": -1,
      "y": 11,
      "z": -1,
      "name": "Soil_Moss_Purple"
    },
    {
      "x": -1,
      "y": 12,
      "z": -1,
      "name": "Soil_Moss_Purple"
    },
    {
      "x": -1,
      "y": 5,
      "z": -1,
      "name": "Soil_Moss_Purple"
    },
    {
      "x": -1,
      "y": 0,
      "z": 0,
      "name": "Soil_Moss_Purple"
    },
    {
      "x": -1,
      "y": 1,
      "z": 0,
      "name": "Soil_Moss_Purple"
    },
    {
      "x": -1,
      "y": 2,
      "z": 0,
      "name": "Soil_Moss_Purple"
    },
    {
      "x": -1,
      "y": 3,
      "z": 0,
      "name": "Soil_Moss_Purple"
    },
    {
      "x": -1,
      "y": 4,
      "z": 0,
      "name": "Soil_Moss_Purple"
    },
    {
      "x": -1,
      "y": 5,
      "z": 0,
      "name": "Soil_Moss_Purple"
    },
    {
      "x": -1,
      "y": 6,
      "z": 0,
      "name": "Soil_Moss_Purple"
    },
    {
      "x": -1,
      "y": 7,
      "z": 0,
      "name": "Soil_Moss_Purple"
    },
    {
      "x": -1,
      "y": 6,
      "z": 2,
      "name": "Soil_Moss_Purple"
    },
    {
      "x": -1,
      "y": 7,
      "z": 2,
      "name": "Soil_Moss_Purple"
    },
    {
      "x": -1,
      "y": 7,
      "z": 3,
      "name": "Soil_Moss_Purple"
    },
    {
      "x": -2,
      "y": 8,
      "z": 3,
      "name": "Soil_Moss_Purple"
    },
    {
      "x": 0,
      "y": 0,
      "z": 0,
      "name": "Rock_Crystal_Purple_Block"
    },
    {
      "x": 1,
      "y": 0,
      "z": 0,
      "name": "Soil_Moss_Purple"
    },
    {
      "x": 0,
      "y": 1,
      "z": 0,
      "name": "Rock_Crystal_Purple_Block"
    },
    {
      "x": 1,
      "y": 1,
      "z": 0,
      "name": "Soil_Moss_Purple"
    },
    {
      "x": 0,
      "y": 2,
      "z": 0,
      "name": "Rock_Crystal_Purple_Block"
    },
    {
      "x": 1,
      "y": 2,
      "z": 0,
      "name": "Soil_Moss_Purple"
    },
    {
      "x": 0,
      "y": 3,
      "z": 0,
      "name": "Rock_Crystal_Purple_Block"
    },
    {
      "x": 1,
      "y": 3,
      "z": 0,
      "name": "Soil_Moss_Purple"
    },
    {
      "x": 0,
      "y": 4,
      "z": 0,
      "name": "Rock_Crystal_Purple_Block"
    },
    {
      "x": 1,
      "y": 4,
      "z": 0,
      "name": "Soil_Moss_Purple"
    },
    {
      "x": 0,
      "y": 5,
      "z": 0,
      "name": "Rock_Crystal_Purple_Block"
    },
    {
      "x": 1,
      "y": 5,
      "z": 0,
      "name": "Soil_Moss_Purple"
    },
    {
      "x": 0,
      "y": 6,
      "z": 0,
      "name": "Rock_Crystal_Purple_Block"
    },
    {
      "x": 1,
      "y": 6,
      "z": 0,
      "name": "Rock_Crystal_Purple_Block"
    },
    {
      "x": 2,
      "y": 6,
      "z": 0,
      "name": "Soil_Moss_Purple"
    },
    {
      "x": 0,
      "y": 7,
      "z": 0,
      "name": "Rock_Crystal_Purple_Block"
    },
    {
      "x": 1,
      "y": 7,
      "z": 0,
      "name": "Rock_Crystal_Purple_Block"
    },
    {
      "x": 0,
      "y": 8,
      "z": 0,
      "name": "Soil_Moss_Purple"
    },
    {
      "x": 1,
      "y": 8,
      "z": 0,
      "name": "Rock_Crystal_Purple_Block"
    },
    {
      "x": 2,
      "y": 8,
      "z": 0,
      "name": "Soil_Moss_Purple"
    },
    {
      "x": 0,
      "y": 0,
      "z": 1,
      "name": "Soil_Moss_Purple"
    },
    {
      "x": 0,
      "y": 1,
      "z": 1,
      "name": "Soil_Moss_Purple"
    },
    {
      "x": 0,
      "y": 2,
      "z": 1,
      "name": "Soil_Moss_Purple"
    },
    {
      "x": 0,
      "y": 3,
      "z": 1,
      "name": "Soil_Moss_Purple"
    },
    {
      "x": 0,
      "y": 4,
      "z": 1,
      "name": "Soil_Moss_Purple"
    },
    {
      "x": 0,
      "y": 5,
      "z": 1,
      "name": "Soil_Moss_Purple"
    },
    {
      "x": 0,
      "y": 6,
      "z": 1,
      "name": "Soil_Moss_Purple"
    },
    {
      "x": 1,
      "y": 6,
      "z": 1,
      "name": "Soil_Moss_Purple"
    },
    {
      "x": 0,
      "y": 7,
      "z": 1,
      "name": "Soil_Moss_Purple"
    },
    {
      "x": 1,
      "y": 7,
      "z": 1,
      "name": "Soil_Moss_Purple"
    },
    {
      "x": 1,
      "y": 8,
      "z": 1,
      "name": "Soil_Moss_Purple"
    },
    {
      "x": -6,
      "y": 14,
      "z": 0,
      "name": "Plant_Coral_Block_Lime"
    },
    {
      "x": -5,
      "y": 14,
      "z": 0,
      "name": "Plant_Coral_Block_Green"
    },
    {
      "x": -4,
      "y": 14,
      "z": 0,
      "name": "Plant_Coral_Block_Green"
    },
    {
      "x": -4,
      "y": 15,
      "z": 0,
      "name": "Plant_Coral_Bush_Green"
    },
    {
      "x": -2,
      "y": 11,
      "z": 1,
      "name": "Soil_Moss_Purple"
    },
    {
      "x": -1,
      "y": 11,
      "z": 1,
      "name": "Soil_Moss_Purple"
    },
    {
      "x": -2,
      "y": 12,
      "z": 1,
      "name": "Soil_Moss_Purple"
    },
    {
      "x": -7,
      "y": 14,
      "z": 1,
      "name": "Plant_Coral_Block_Lime"
    },
    {
      "x": -6,
      "y": 14,
      "z": 1,
      "name": "Plant_Coral_Block_Lime"
    },
    {
      "x": -5,
      "y": 14,
      "z": 1,
      "name": "Plant_Coral_Block_Lime"
    },
    {
      "x": -4,
      "y": 14,
      "z": 1,
      "name": "Plant_Coral_Block_Green"
    },
    {
      "x": -3,
      "y": 14,
      "z": 1,
      "name": "Plant_Coral_Block_Green"
    },
    {
      "x": -4,
      "y": 15,
      "z": 1,
      "name": "Plant_Coral_Bush_Green"
    },
    {
      "x": -2,
      "y": 9,
      "z": 2,
      "name": "Plant_Coral_Block_Lime"
    },
    {
      "x": -3,
      "y": 12,
      "z": 2,
      "name": "Soil_Moss_Purple"
    },
    {
      "x": -4,
      "y": 13,
      "z": 2,
      "name": "Soil_Moss_Purple"
    },
    {
      "x": -8,
      "y": 14,
      "z": 2,
      "name": "Plant_Coral_Block_Lime"
    },
    {
      "x": -7,
      "y": 14,
      "z": 2,
      "name": "Plant_Coral_Block_Green"
    },
    {
      "x": -6,
      "y": 14,
      "z": 2,
      "name": "Plant_Coral_Block_Green"
    },
    {
      "x": -5,
      "y": 14,
      "z": 2,
      "name": "Plant_Coral_Block_Green"
    },
    {
      "x": -4,
      "y": 14,
      "z": 2,
      "name": "Plant_Coral_Block_Green"
    },
    {
      "x": -3,
      "y": 14,
      "z": 2,
      "name": "Plant_Coral_Block_Green"
    },
    {
      "x": -7,
      "y": 15,
      "z": 2,
      "name": "Plant_Coral_Bush_Green"
    },
    {
      "x": -6,
      "y": 15,
      "z": 2,
      "name": "Plant_Coral_Bush_Green"
    },
    {
      "x": -5,
      "y": 15,
      "z": 2,
      "name": "Plant_Coral_Block_Green"
    },
    {
      "x": -4,
      "y": 15,
      "z": 2,
      "name": "Plant_Coral_Bush_Green"
    },
    {
      "x": -5,
      "y": 16,
      "z": 2,
      "name": "Plant_Coral_Bush_Green"
    },
    {
      "x": -3,
      "y": 9,
      "z": 3,
      "name": "Plant_Coral_Block_Lime"
    },
    {
      "x": -2,
      "y": 9,
      "z": 3,
      "name": "Soil_Moss_Purple"
    },
    {
      "x": -1,
      "y": 9,
      "z": 3,
      "name": "Plant_Coral_Block_Lime"
    },
    {
      "x": -2,
      "y": 10,
      "z": 3,
      "name": "Plant_Coral_Block_Lime"
    },
    {
      "x": -3,
      "y": 13,
      "z": 3,
      "name": "Plant_Coral_Block_Green"
    },
    {
      "x": -8,
      "y": 14,
      "z": 3,
      "name": "Plant_Coral_Block_Green"
    },
    {
      "x": -7,
      "y": 14,
      "z": 3,
      "name": "Plant_Coral_Block_Green"
    },
    {
      "x": -6,
      "y": 14,
      "z": 3,
      "name": "Plant_Coral_Block_Green"
    },
    {
      "x": -5,
      "y": 14,
      "z": 3,
      "name": "Soil_Moss_Purple"
    },
    {
      "x": -4,
      "y": 14,
      "z": 3,
      "name": "Plant_Coral_Block_Green"
    },
    {
      "x": -3,
      "y": 14,
      "z": 3,
      "name": "Plant_Coral_Block_Green"
    },
    {
      "x": -8,
      "y": 15,
      "z": 3,
      "name": "Plant_Coral_Bush_Green"
    },
    {
      "x": -7,
      "y": 15,
      "z": 3,
      "name": "Plant_Coral_Bush_Green"
    },
    {
      "x": -6,
      "y": 15,
      "z": 3,
      "name": "Plant_Coral_Block_Green"
    },
    {
      "x": -5,
      "y": 15,
      "z": 3,
      "name": "Plant_Coral_Block_Green"
    },
    {
      "x": -4,
      "y": 15,
      "z": 3,
      "name": "Plant_Coral_Block_Green"
    },
    {
      "x": -3,
      "y": 15,
      "z": 3,
      "name": "Plant_Coral_Bush_Green"
    },
    {
      "x": -6,
      "y": 16,
      "z": 3,
      "name": "Plant_Coral_Bush_Green"
    },
    {
      "x": -5,
      "y": 16,
      "z": 3,
      "name": "Plant_Coral_Bush_Green"
    },
    {
      "x": -4,
      "y": 16,
      "z": 3,
      "name": "Plant_Coral_Bush_Green"
    },
    {
      "x": -2,
      "y": 9,
      "z": 4,
      "name": "Plant_Coral_Block_Lime"
    },
    {
      "x": -3,
      "y": 13,
      "z": 4,
      "name": "Plant_Coral_Block_Green"
    },
    {
      "x": -8,
      "y": 14,
      "z": 4,
      "name": "Plant_Coral_Block_Green"
    },
    {
      "x": -7,
      "y": 14,
      "z": 4,
      "name": "Plant_Coral_Block_Green"
    },
    {
      "x": -6,
      "y": 14,
      "z": 4,
      "name": "Plant_Coral_Block_Green"
    },
    {
      "x": -5,
      "y": 14,
      "z": 4,
      "name": "Plant_Coral_Block_Green"
    },
    {
      "x": -4,
      "y": 14,
      "z": 4,
      "name": "Plant_Coral_Block_Green"
    },
    {
      "x": -3,
      "y": 14,
      "z": 4,
      "name": "Plant_Coral_Block_Green"
    },
    {
      "x": -8,
      "y": 15,
      "z": 4,
      "name": "Plant_Coral_Bush_Green"
    },
    {
      "x": -5,
      "y": 15,
      "z": 4,
      "name": "Plant_Coral_Block_Green"
    },
    {
      "x": -4,
      "y": 15,
      "z": 4,
      "name": "Plant_Coral_Bush_Green"
    },
    {
      "x": -5,
      "y": 16,
      "z": 4,
      "name": "Plant_Coral_Bush_Green"
    },
    {
      "x": -4,
      "y": 13,
      "z": 5,
      "name": "Plant_Coral_Block_Green"
    },
    {
      "x": -7,
      "y": 14,
      "z": 5,
      "name": "Plant_Coral_Block_Lime"
    },
    {
      "x": -6,
      "y": 14,
      "z": 5,
      "name": "Plant_Coral_Block_Green"
    },
    {
      "x": -5,
      "y": 14,
      "z": 5,
      "name": "Plant_Coral_Block_Lime"
    },
    {
      "x": -4,
      "y": 14,
      "z": 5,
      "name": "Plant_Coral_Block_Green"
    },
    {
      "x": -6,
      "y": 15,
      "z": 5,
      "name": "Plant_Coral_Bush_Green"
    },
    {
      "x": -4,
      "y": 15,
      "z": 5,
      "name": "Plant_Coral_Bush_Green"
    },
    {
      "x": -6,
      "y": 14,
      "z": 6,
      "name": "Plant_Coral_Block_Lime"
    },
    {
      "x": -5,
      "y": 14,
      "z": 6,
      "name": "Plant_Coral_Block_Green"
    },
    {
      "x": -4,
      "y": 14,
      "z": 6,
      "name": "Plant_Coral_Block_Green"
    },
    {
      "x": -5,
      "y": 15,
      "z": 6,
      "name": "Plant_Coral_Bush_Green"
    }
  ],
  "fluids": [],
  "entities": []
}