{"anchorX":0,"anchorY":0,"anchorZ":0,"blockIdVersion":11,"blocks":[{"name":"Rock_Sandstone_Brick_Stairs","rotation":3,"x":-2,"y":0,"z":-2},{"name":"Rock_Sandstone_Brick_Stairs","rotation":3,"x":-2,"y":0,"z":-1},{"name":"Rock_Sandstone_Brick_Stairs","rotation":3,"x":-2,"y":0,"z":0},{"name":"Rock_Sandstone_Brick_Stairs","rotation":3,"x":-2,"y":0,"z":1},{"name":"Rock_Sandstone_Cobble","x":-1,"y":0,"z":-2},{"name":"Rock_Sandstone_Cobble","x":-1,"y":0,"z":-1},{"name":"Rock_Sandstone_Cobble","x":-1,"y":0,"z":0},{"name":"Rock_Sandstone_White_Brick","x":-1,"y":1,"z":0},{"name":"Rock_Sandstone_Cobble","x":-1,"y":0,"z":1},{"name":"Rock_Sandstone_Brick","x":-1,"y":1,"z":1},{"name":"Rock_Sandstone_Brick","x":-1,"y":2,"z":1},{"name":"Rock_Sandstone_Brick","x":-1,"y":3,"z":1},{"name":"Rock_Sandstone_Brick_Stairs","x":-1,"y":0,"z":2},{"name":"Rock_Sandstone_Cobble","x":0,"y":0,"z":-2},{"name":"Deco_Pot_Clay_Broken","x":0,"y":1,"z":-2},{"name":"Rock_Sandstone_Cobble","x":0,"y":0,"z":-1},{"name":"Rock_Sandstone_Cobble","x":0,"y":0,"z":0},{"name":"Rock_Sandstone_Brick","x":0,"y":0,"z":1},{"name":"Rock_Sandstone_White_Brick","x":0,"y":1,"z":1},{"name":"Rock_Sandstone_White_Brick","x":0,"y":2,"z":1},{"name":"Rock_Sandstone_White_Brick","x":0,"y":3,"z":1},{"name":"Rock_Sandstone_Brick_Half","x":0,"y":0,"z":2},{"name":"Rock_Sandstone_Cobble","x":1,"y":0,"z":-2},{"name":"Rock_Sandstone_Cobble","x":1,"y":0,"z":-1},{"name":"Rock_Sandstone_Cobble","x":1,"y":0,"z":0},{"name":"Rock_Sandstone_Cobble_Stairs","x":1,"y":0,"z":1},{"name":"Furniture_Desert_Window","x":1,"y":3,"z":1},{"name":"Rock_Sandstone_Cobble","x":2,"y":0,"z":-2},{"name":"Rock_Sandstone_Cobble","x":2,"y":0,"z":-1},{"name":"Rubble_Sandstone","support":15,"x":2,"y":1,"z":-1},{"name":"Rock_Sandstone_Cobble","x":2,"y":0,"z":0},{"name":"Rock_Sandstone_Cobble_Half","x":2,"y":0,"z":1},{"name":"Rock_Sandstone_Brick_Half","x":2,"y":0,"z":2}],"fluids":[{"level":1,"name":"Water_Source","x":-2,"y":0,"z":-2},{"level":1,"name":"Water_Source","x":-2,"y":0,"z":-1},{"level":1,"name":"Water_Source","x":-2,"y":0,"z":0},{"level":1,"name":"Water_Source","x":-2,"y":0,"z":1},{"level":1,"name":"Water_Source","x":-1,"y":0,"z":-2},{"level":1,"name":"Water_Source","x":-1,"y":0,"z":-1},{"level":1,"name":"Water_Source","x":-1,"y":0,"z":0},{"level":1,"name":"Water_Source","x":-1,"y":1,"z":0},{"level":1,"name":"Water_Source","x":-1,"y":0,"z":1},{"level":1,"name":"Water_Source","x":-1,"y":1,"z":1},{"level":1,"name":"Water_Source","x":-1,"y":2,"z":1},{"level":1,"name":"Water_Source","x":-1,"y":3,"z":1},{"level":1,"name":"Water_Source","x":-1,"y":0,"z":2},{"level":1,"name":"Water_Source","x":0,"y":0,"z":-2},{"level":1,"name":"Water_Source","x":0,"y":1,"z":-2},{"level":1,"name":"Water_Source","x":0,"y":0,"z":-1},{"level":1,"name":"Water_Source","x":0,"y":0,"z":0},{"level":1,"name":"Water_Source","x":0,"y":0,"z":1},{"level":1,"name":"Water_Source","x":0,"y":1,"z":1},{"level":1,"name":"Water_Source","x":0,"y":2,"z":1},{"level":1,"name":"Water_Source","x":0,"y":3,"z":1},{"level":1,"name":"Water_Source","x":0,"y":0,"z":2},{"level":1,"name":"Water_Source","x":1,"y":0,"z":-2},{"level":1,"name":"Water_Source","x":1,"y":0,"z":-1},{"level":1,"name":"Water_Source","x":1,"y":0,"z":0},{"level":1,"name":"Water_Source","x":1,"y":0,"z":1},{"level":1,"name":"Water_Source","x":1,"y":3,"z":1},{"level":1,"name":"Water_Source","x":2,"y":0,"z":-2},{"level":1,"name":"Water_Source","x":2,"y":0,"z":-1},{"level":1,"name":"Water_Source","x":2,"y":1,"z":-1},{"level":1,"name":"Water_Source","x":2,"y":0,"z":0},{"level":1,"name":"Water_Source","x":2,"y":0,"z":1},{"level":1,"name":"Water_Source","x":2,"y":0,"z":2}],"version":8}