{"anchorX":0,"anchorY":0,"anchorZ":0,"blockIdVersion":11,"blocks":[{"name":"Rock_Sandstone_Brick_Half","x":-2,"y":0,"z":1},{"name":"Rock_Sandstone_Brick_Half","x":-2,"y":0,"z":2},{"name":"Rock_Sandstone_Brick","x":-1,"y":0,"z":0},{"name":"Rock_Sandstone_Brick","x":-1,"y":1,"z":0},{"name":"Rock_Sandstone_Brick_Half","x":-1,"y":0,"z":1},{"name":"Rock_Sandstone_Brick_Half","x":-1,"y":0,"z":2},{"name":"Rock_Sandstone_Brick","x":0,"y":0,"z":0},{"name":"Rock_Sandstone_Brick","x":0,"y":1,"z":0},{"name":"Rock_Sandstone_Brick","x":0,"y":2,"z":0},{"name":"Rock_Sandstone_Cobble","x":0,"y":3,"z":0},{"name":"Rock_Sandstone_Brick_Half","x":0,"y":0,"z":1},{"name":"Rock_Sandstone_Brick_Half","x":0,"y":0,"z":2},{"name":"Rock_Sandstone_Brick","x":1,"y":0,"z":-1},{"name":"Rock_Sandstone_Brick","x":1,"y":1,"z":-1},{"name":"Rock_Sandstone_Brick","x":1,"y":0,"z":0},{"name":"Rock_Sandstone_Brick","support":15,"x":1,"y":1,"z":0},{"name":"Rubble_Sandstone","x":1,"y":2,"z":0},{"name":"Rock_Sandstone_Cobble","x":1,"y":3,"z":0},{"name":"Rock_Sandstone_Cobble","x":1,"y":4,"z":0},{"name":"Rock_Sandstone_Brick_Half","x":1,"y":0,"z":1},{"name":"Rock_Sandstone_Brick_Half","x":1,"y":0,"z":2},{"name":"Rock_Sandstone_Brick_Half","rotation":4,"x":2,"y":0,"z":-1},{"name":"Rock_Sandstone_Brick_Half","rotation":6,"x":2,"y":0,"z":0},{"name":"Rock_Sandstone_Brick_Half","rotation":6,"x":2,"y":1,"z":0},{"name":"Rock_Sandstone_Brick_Pillar_Base","x":2,"y":0,"z":1},{"name":"Rock_Sandstone_Brick_Pillar_Middle","x":2,"y":1,"z":1},{"name":"Rock_Sandstone_Brick_Pillar_Middle","x":2,"y":2,"z":1},{"name":"Rock_Sandstone_Brick_Pillar_Middle","x":2,"y":3,"z":1},{"name":"Rock_Sandstone_Brick_Pillar_Middle","rotation":8,"x":2,"y":4,"z":1},{"name":"Rock_Sandstone_Brick_Pillar_Base","rotation":8,"x":2,"y":5,"z":1},{"name":"Rock_Sandstone_Brick_Half","rotation":6,"x":3,"y":0,"z":0}],"fluids":[{"level":1,"name":"Water_Source","x":-2,"y":0,"z":1},{"level":1,"name":"Water_Source","x":-2,"y":0,"z":2},{"level":1,"name":"Water_Source","x":-1,"y":0,"z":0},{"level":1,"name":"Water_Source","x":-1,"y":1,"z":0},{"level":1,"name":"Water_Source","x":-1,"y":0,"z":1},{"level":1,"name":"Water_Source","x":-1,"y":0,"z":2},{"level":1,"name":"Water_Source","x":0,"y":0,"z":0},{"level":1,"name":"Water_Source","x":0,"y":1,"z":0},{"level":1,"name":"Water_Source","x":0,"y":2,"z":0},{"level":1,"name":"Water_Source","x":0,"y":3,"z":0},{"level":1,"name":"Water_Source","x":0,"y":0,"z":1},{"level":1,"name":"Water_Source","x":0,"y":0,"z":2},{"level":1,"name":"Water_Source","x":1,"y":0,"z":-1},{"level":1,"name":"Water_Source","x":1,"y":1,"z":-1},{"level":1,"name":"Water_Source","x":1,"y":0,"z":0},{"level":1,"name":"Water_Source","x":1,"y":1,"z":0},{"level":1,"name":"Water_Source","x":1,"y":2,"z":0},{"level":1,"name":"Water_Source","x":1,"y":3,"z":0},{"level":1,"name":"Water_Source","x":1,"y":4,"z":0},{"level":1,"name":"Water_Source","x":1,"y":0,"z":1},{"level":1,"name":"Water_Source","x":1,"y":0,"z":2},{"level":1,"name":"Water_Source","x":2,"y":0,"z":-1},{"level":1,"name":"Water_Source","x":2,"y":0,"z":0},{"level":1,"name":"Water_Source","x":2,"y":1,"z":0},{"level":1,"name":"Water_Source","x":2,"y":0,"z":1},{"level":1,"name":"Water_Source","x":2,"y":1,"z":1},{"level":1,"name":"Water_Source","x":2,"y":2,"z":1},{"level":1,"name":"Water_Source","x":2,"y":3,"z":1},{"level":1,"name":"Water_Source","x":2,"y":4,"z":1},{"level":1,"name":"Water_Source","x":2,"y":5,"z":1},{"level":1,"name":"Water_Source","x":3,"y":0,"z":0}],"version":8}