{"anchorX":0,"anchorY":0,"anchorZ":0,"blockIdVersion":11,"blocks":[{"name":"Rock_Sandstone_Cobble","rotation":26,"x":-1,"y":0,"z":-2},{"name":"Soil_Dirt_Dry","rotation":26,"x":-1,"y":0,"z":-1},{"name":"Rock_Sandstone_Cobble","rotation":26,"x":-1,"y":1,"z":-1},{"name":"Soil_Dirt_Dry","rotation":26,"x":-1,"y":0,"z":0},{"name":"Rock_Sandstone_Cobble","rotation":26,"x":-1,"y":1,"z":0},{"name":"Rock_Sandstone_Cobble","rotation":26,"x":-1,"y":2,"z":0},{"name":"Rock_Sandstone_Brick","rotation":26,"x":-1,"y":0,"z":1},{"name":"Rock_Sandstone_Brick","rotation":26,"x":-1,"y":1,"z":1},{"name":"Rock_Sandstone_Brick","rotation":26,"x":-1,"y":2,"z":1},{"name":"Rock_Sandstone_Brick_Stairs","rotation":26,"x":-1,"y":0,"z":2},{"name":"Rock_Sandstone_Cobble_Stairs","rotation":26,"x":-1,"y":1,"z":2},{"name":"Rock_Sandstone_Cobble_Stairs","rotation":26,"x":-1,"y":2,"z":2},{"name":"Rock_Sandstone_White_Brick_Stairs","rotation":18,"x":0,"y":0,"z":-2},{"name":"Rock_Sandstone_White_Brick","rotation":26,"x":0,"y":0,"z":-1},{"name":"Rock_Sandstone_White_Brick","rotation":26,"x":0,"y":0,"z":0},{"name":"Rock_Sandstone_Brick","rotation":26,"x":0,"y":0,"z":1},{"name":"Rock_Sandstone_White_Brick","rotation":26,"x":0,"y":1,"z":1},{"name":"Rock_Sandstone_White_Brick","rotation":26,"x":0,"y":2,"z":1},{"name":"Rock_Sandstone_White_Brick_Stairs","rotation":15,"x":1,"y":0,"z":-2},{"name":"Rock_Sandstone_White_Brick","rotation":26,"x":1,"y":0,"z":-1},{"name":"Rock_Sandstone_Brick","rotation":26,"x":1,"y":0,"z":1},{"name":"Rock_Sandstone_White_Brick","rotation":26,"x":1,"y":1,"z":1},{"name":"Rock_Sandstone_White_Brick","rotation":26,"x":2,"y":1,"z":1}],"fluids":[{"level":1,"name":"Water_Source","x":-1,"y":0,"z":-2},{"level":1,"name":"Water_Source","x":-1,"y":0,"z":-1},{"level":1,"name":"Water_Source","x":-1,"y":1,"z":-1},{"level":1,"name":"Water_Source","x":-1,"y":0,"z":0},{"level":1,"name":"Water_Source","x":-1,"y":1,"z":0},{"level":1,"name":"Water_Source","x":-1,"y":2,"z":0},{"level":1,"name":"Water_Source","x":-1,"y":0,"z":1},{"level":1,"name":"Water_Source","x":-1,"y":1,"z":1},{"level":1,"name":"Water_Source","x":-1,"y":2,"z":1},{"level":1,"name":"Water_Source","x":-1,"y":0,"z":2},{"level":1,"name":"Water_Source","x":-1,"y":1,"z":2},{"level":1,"name":"Water_Source","x":-1,"y":2,"z":2},{"level":1,"name":"Water_Source","x":0,"y":0,"z":-2},{"level":1,"name":"Water_Source","x":0,"y":0,"z":-1},{"level":1,"name":"Water_Source","x":0,"y":0,"z":0},{"level":1,"name":"Water_Source","x":0,"y":0,"z":1},{"level":1,"name":"Water_Source","x":0,"y":1,"z":1},{"level":1,"name":"Water_Source","x":0,"y":2,"z":1},{"level":1,"name":"Water_Source","x":1,"y":0,"z":-2},{"level":1,"name":"Water_Source","x":1,"y":0,"z":-1},{"level":1,"name":"Water_Source","x":1,"y":0,"z":1},{"level":1,"name":"Water_Source","x":1,"y":1,"z":1},{"level":1,"name":"Water_Source","x":2,"y":1,"z":1}],"version":8}