{"anchorX":0,"anchorY":0,"anchorZ":0,"blockIdVersion":11,"blocks":[{"name":"Rock_Sandstone_Cobble_Stairs","rotation":3,"x":-1,"y":0,"z":0},{"name":"Rock_Sandstone_Brick_Pillar_Base","x":-1,"y":0,"z":1},{"name":"Rock_Sandstone_Brick","x":-1,"y":3,"z":1},{"name":"Soil_Clay_Ocean_Brick_Smooth_Half","x":-1,"y":4,"z":1},{"name":"Rock_Sandstone_Cobble","x":-1,"y":0,"z":2},{"name":"Rock_Sandstone_Brick","x":-1,"y":1,"z":2},{"name":"Rock_Sandstone_Brick","x":-1,"y":2,"z":2},{"name":"Rock_Sandstone_Brick","x":-1,"y":3,"z":2},{"name":"Rock_Sandstone_Brick","x":-1,"y":4,"z":2},{"name":"Rock_Sandstone_Brick_Stairs","rotation":2,"x":0,"y":0,"z":-1},{"name":"Rock_Sandstone_Brick","x":0,"y":0,"z":0},{"name":"Rock_Sandstone_Cobble","x":0,"y":1,"z":0},{"name":"Rock_Sandstone_Cobble","x":0,"y":2,"z":0},{"name":"Rock_Sandstone_Brick","x":0,"y":3,"z":0},{"name":"Soil_Clay_Ocean_Brick_Ornate","x":0,"y":0,"z":1},{"name":"Soil_Clay_Ocean_Brick_Roof","x":0,"y":1,"z":1},{"name":"Soil_Clay_Ocean_Brick_Stairs","x":0,"y":0,"z":2},{"name":"Rock_Sandstone_Brick_Pillar_Base","x":1,"y":0,"z":-1},{"name":"Rock_Sandstone_Brick_Pillar_Middle","x":1,"y":1,"z":-1},{"name":"Rock_Sandstone_Brick_Pillar_Base","rotation":8,"x":1,"y":2,"z":-1},{"name":"Rock_Sandstone_Brick","x":1,"y":3,"z":-1},{"name":"Rock_Sandstone_Brick","x":1,"y":4,"z":-1},{"name":"Soil_Clay_Ocean_Brick_Smooth_Half","rotation":4,"x":1,"y":0,"z":0}],"fluids":[{"level":1,"name":"Water_Source","x":-1,"y":0,"z":0},{"level":1,"name":"Water_Source","x":-1,"y":0,"z":1},{"level":1,"name":"Water_Source","x":-1,"y":3,"z":1},{"level":1,"name":"Water_Source","x":-1,"y":4,"z":1},{"level":1,"name":"Water_Source","x":-1,"y":0,"z":2},{"level":1,"name":"Water_Source","x":-1,"y":1,"z":2},{"level":1,"name":"Water_Source","x":-1,"y":2,"z":2},{"level":1,"name":"Water_Source","x":-1,"y":3,"z":2},{"level":1,"name":"Water_Source","x":-1,"y":4,"z":2},{"level":1,"name":"Water_Source","x":0,"y":0,"z":-1},{"level":1,"name":"Water_Source","x":0,"y":0,"z":0},{"level":1,"name":"Water_Source","x":0,"y":1,"z":0},{"level":1,"name":"Water_Source","x":0,"y":2,"z":0},{"level":1,"name":"Water_Source","x":0,"y":3,"z":0},{"level":1,"name":"Water_Source","x":0,"y":0,"z":1},{"level":1,"name":"Water_Source","x":0,"y":1,"z":1},{"level":1,"name":"Water_Source","x":0,"y":0,"z":2},{"level":1,"name":"Water_Source","x":1,"y":0,"z":-1},{"level":1,"name":"Water_Source","x":1,"y":1,"z":-1},{"level":1,"name":"Water_Source","x":1,"y":2,"z":-1},{"level":1,"name":"Water_Source","x":1,"y":3,"z":-1},{"level":1,"name":"Water_Source","x":1,"y":4,"z":-1},{"level":1,"name":"Water_Source","x":1,"y":0,"z":0}],"version":8}