{"anchorX":0,"anchorY":0,"anchorZ":0,"blockIdVersion":11,"blocks":[{"name":"Rock_Sandstone_Brick_Half","x":-1,"y":0,"z":-1},{"name":"Rock_Sandstone_Cobble_Stairs","rotation":8,"x":-1,"y":5,"z":-1},{"name":"Soil_Clay_Ocean_Brick_Roof","rotation":2,"x":-1,"y":6,"z":-1},{"name":"Rock_Sandstone_Brick","x":-1,"y":0,"z":0},{"name":"Rock_Sandstone_Brick","x":-1,"y":1,"z":0},{"name":"Rock_Sandstone_Brick","x":-1,"y":2,"z":0},{"name":"Rock_Sandstone_Cobble","x":-1,"y":3,"z":0},{"name":"Rock_Sandstone_Cobble","x":-1,"y":4,"z":0},{"name":"Rock_Sandstone_Cobble","x":-1,"y":5,"z":0},{"name":"Deco_Pot_Clay_Broken","x":-1,"y":0,"z":2},{"name":"Rock_Sandstone_Brick_Half","x":0,"y":0,"z":-1},{"name":"Rock_Sandstone_Cobble_Stairs","rotation":8,"x":0,"y":5,"z":-1},{"name":"Soil_Clay_Ocean_Brick_Roof","rotation":2,"x":0,"y":6,"z":-1},{"name":"Rock_Sandstone_Brick","x":0,"y":0,"z":0},{"name":"Rock_Sandstone_Brick","x":0,"y":1,"z":0},{"name":"Rock_Sandstone_Brick","x":0,"y":2,"z":0},{"name":"Rock_Sandstone_Cobble","x":0,"y":3,"z":0},{"name":"Rock_Sandstone_Cobble","x":0,"y":4,"z":0},{"name":"Rock_Sandstone_Cobble","x":0,"y":5,"z":0},{"name":"Rock_Sandstone_Brick","x":0,"y":0,"z":1},{"name":"Rock_Sandstone_Brick","x":0,"y":1,"z":1},{"name":"Rock_Sandstone_Brick","x":0,"y":2,"z":1},{"name":"Rock_Sandstone_Cobble","x":0,"y":4,"z":1},{"name":"Rock_Sandstone_Brick_Stairs","rotation":9,"x":0,"y":0,"z":2},{"name":"Rock_Sandstone_Brick","x":0,"y":4,"z":2},{"name":"Rock_Sandstone_Brick_Pillar_Base","x":1,"y":0,"z":-1},{"name":"Rock_Sandstone_Brick_Pillar_Middle","x":1,"y":1,"z":-1},{"name":"Rock_Sandstone_Brick_Pillar_Middle","rotation":8,"x":1,"y":2,"z":-1},{"name":"Rock_Sandstone_Brick_Pillar_Middle","rotation":8,"x":1,"y":3,"z":-1},{"name":"Rock_Sandstone_Brick_Pillar_Middle","rotation":8,"x":1,"y":4,"z":-1},{"name":"Rock_Sandstone_Brick_Pillar_Base","rotation":8,"x":1,"y":5,"z":-1},{"name":"*Soil_Clay_Ocean_Brick_Roof_State_Definitions_Corner_Right","rotation":2,"x":1,"y":6,"z":-1},{"name":"Rock_Sandstone_Brick_Half","rotation":4,"x":1,"y":0,"z":0},{"name":"Rock_Sandstone_Cobble_Stairs","rotation":11,"x":1,"y":5,"z":0},{"name":"Soil_Clay_Ocean_Brick_Roof","rotation":1,"x":1,"y":6,"z":0},{"name":"Rock_Sandstone_Cobble_Stairs","rotation":11,"x":1,"y":5,"z":1}],"fluids":[{"level":1,"name":"Water_Source","x":-1,"y":0,"z":-1},{"level":1,"name":"Water_Source","x":-1,"y":5,"z":-1},{"level":1,"name":"Water_Source","x":-1,"y":6,"z":-1},{"level":1,"name":"Water_Source","x":-1,"y":0,"z":0},{"level":1,"name":"Water_Source","x":-1,"y":1,"z":0},{"level":1,"name":"Water_Source","x":-1,"y":2,"z":0},{"level":1,"name":"Water_Source","x":-1,"y":3,"z":0},{"level":1,"name":"Water_Source","x":-1,"y":4,"z":0},{"level":1,"name":"Water_Source","x":-1,"y":5,"z":0},{"level":1,"name":"Water_Source","x":-1,"y":0,"z":2},{"level":1,"name":"Water_Source","x":0,"y":0,"z":-1},{"level":1,"name":"Water_Source","x":0,"y":5,"z":-1},{"level":1,"name":"Water_Source","x":0,"y":6,"z":-1},{"level":1,"name":"Water_Source","x":0,"y":0,"z":0},{"level":1,"name":"Water_Source","x":0,"y":1,"z":0},{"level":1,"name":"Water_Source","x":0,"y":2,"z":0},{"level":1,"name":"Water_Source","x":0,"y":3,"z":0},{"level":1,"name":"Water_Source","x":0,"y":4,"z":0},{"level":1,"name":"Water_Source","x":0,"y":5,"z":0},{"level":1,"name":"Water_Source","x":0,"y":0,"z":1},{"level":1,"name":"Water_Source","x":0,"y":1,"z":1},{"level":1,"name":"Water_Source","x":0,"y":2,"z":1},{"level":1,"name":"Water_Source","x":0,"y":4,"z":1},{"level":1,"name":"Water_Source","x":0,"y":0,"z":2},{"level":1,"name":"Water_Source","x":0,"y":4,"z":2},{"level":1,"name":"Water_Source","x":1,"y":0,"z":-1},{"level":1,"name":"Water_Source","x":1,"y":1,"z":-1},{"level":1,"name":"Water_Source","x":1,"y":2,"z":-1},{"level":1,"name":"Water_Source","x":1,"y":3,"z":-1},{"level":1,"name":"Water_Source","x":1,"y":4,"z":-1},{"level":1,"name":"Water_Source","x":1,"y":5,"z":-1},{"level":1,"name":"Water_Source","x":1,"y":6,"z":-1},{"level":1,"name":"Water_Source","x":1,"y":0,"z":0},{"level":1,"name":"Water_Source","x":1,"y":5,"z":0},{"level":1,"name":"Water_Source","x":1,"y":6,"z":0},{"level":1,"name":"Water_Source","x":1,"y":5,"z":1}],"version":8}