{
  "version": 8,
  "blockIdVersion": 11,
  "anchorX": 1,
  "anchorY": 1,
  "anchorZ": 0,
  "blocks": [
    {
      "x": -6,
      "y": -4,
      "z": 2,
      "name": "Soil_Pathway"
    },
    {
      "x": -6,
      "y": -3,
      "z": 2,
      "name": "Soil_Pathway"
    },
    {
      "x": -6,
      "y": -2,
      "z": 2,
      "name": "Soil_Pathway"
    },
    {
      "x": -6,
      "y": -1,
      "z": 2,
      "name": "Soil_Pathway"
    },
    {
      "x": -6,
      "y": 0,
      "z": 2,
      "name": "Soil_Pathway"
    },
    {
      "x": -6,
      "y": -4,
      "z": 3,
      "name": "Soil_Pathway"
    },
    {
      "x": -6,
      "y": -3,
      "z": 3,
      "name": "Soil_Pathway"
    },
    {
      "x": -6,
      "y": -2,
      "z": 3,
      "name": "Soil_Pathway"
    },
    {
      "x": -6,
      "y": -1,
      "z": 3,
      "name": "Soil_Pathway"
    },
    {
      "x": -6,
      "y": 0,
      "z": 3,
      "name": "Soil_Pathway"
    },
    {
      "x": -6,
      "y": -4,
      "z": 4,
      "name": "Soil_Pathway"
    },
    {
      "x": -6,
      "y": -3,
      "z": 4,
      "name": "Soil_Pathway"
    },
    {
      "x": -6,
      "y": -2,
      "z": 4,
      "name": "Soil_Pathway"
    },
    {
      "x": -6,
      "y": -1,
      "z": 4,
      "name": "Soil_Pathway"
    },
    {
      "x": -6,
      "y": 0,
      "z": 4,
      "name": "Soil_Pathway"
    },
    {
      "x": -5,
      "y": -4,
      "z": -6,
      "name": "Soil_Pathway"
    },
    {
      "x": -5,
      "y": -3,
      "z": -6,
      "name": "Soil_Pathway"
    },
    {
      "x": -5,
      "y": -2,
      "z": -6,
      "name": "Soil_Pathway"
    },
    {
      "x": -5,
      "y": -1,
      "z": -6,
      "name": "Soil_Pathway"
    },
    {
      "x": -5,
      "y": 0,
      "z": -6,
      "name": "Soil_Pathway"
    },
    {
      "x": -5,
      "y": -4,
      "z": -5,
      "name": "Soil_Pathway"
    },
    {
      "x": -5,
      "y": -3,
      "z": -5,
      "name": "Soil_Pathway"
    },
    {
      "x": -5,
      "y": -2,
      "z": -5,
      "name": "Soil_Pathway"
    },
    {
      "x": -5,
      "y": -1,
      "z": -5,
      "name": "Soil_Pathway"
    },
    {
      "x": -5,
      "y": 0,
      "z": -5,
      "name": "Soil_Pathway"
    },
    {
      "x": -5,
      "y": -4,
      "z": -4,
      "name": "Soil_Pathway"
    },
    {
      "x": -5,
      "y": -3,
      "z": -4,
      "name": "Soil_Pathway"
    },
    {
      "x": -5,
      "y": -2,
      "z": -4,
      "name": "Soil_Pathway"
    },
    {
      "x": -5,
      "y": -1,
      "z": -4,
      "name": "Soil_Pathway"
    },
    {
      "x": -5,
      "y": 0,
      "z": -4,
      "name": "Soil_Pathway"
    },
    {
      "x": -5,
      "y": -4,
      "z": -3,
      "name": "Soil_Pathway"
    },
    {
      "x": -5,
      "y": -3,
      "z": -3,
      "name": "Soil_Pathway"
    },
    {
      "x": -5,
      "y": -2,
      "z": -3,
      "name": "Soil_Pathway"
    },
    {
      "x": -5,
      "y": -1,
      "z": -3,
      "name": "Soil_Pathway"
    },
    {
      "x": -5,
      "y": 0,
      "z": -3,
      "name": "Soil_Pathway"
    },
    {
      "x": -5,
      "y": -4,
      "z": -2,
      "name": "Soil_Pathway"
    },
    {
      "x": -5,
      "y": -3,
      "z": -2,
      "name": "Soil_Pathway"
    },
    {
      "x": -5,
      "y": -2,
      "z": -2,
      "name": "Soil_Pathway"
    },
    {
      "x": -5,
      "y": -1,
      "z": -2,
      "name": "Soil_Pathway"
    },
    {
      "x": -5,
      "y": 0,
      "z": -2,
      "name": "Soil_Pathway"
    },
    {
      "x": -5,
      "y": -4,
      "z": -1,
      "name": "Soil_Pathway"
    },
    {
      "x": -5,
      "y": -3,
      "z": -1,
      "name": "Soil_Pathway"
    },
    {
      "x": -5,
      "y": -2,
      "z": -1,
      "name": "Soil_Pathway"
    },
    {
      "x": -5,
      "y": -1,
      "z": -1,
      "name": "Soil_Pathway"
    },
    {
      "x": -5,
      "y": 0,
      "z": -1,
      "name": "Soil_Pathway"
    },
    {
      "x": -5,
      "y": -4,
      "z": 0,
      "name": "Soil_Pathway"
    },
    {
      "x": -5,
      "y": -3,
      "z": 0,
      "name": "Soil_Pathway"
    },
    {
      "x": -5,
      "y": -2,
      "z": 0,
      "name": "Soil_Pathway"
    },
    {
      "x": -5,
      "y": -1,
      "z": 0,
      "name": "Soil_Pathway"
    },
    {
      "x": -5,
      "y": 0,
      "z": 0,
      "name": "Soil_Pathway"
    },
    {
      "x": -5,
      "y": -4,
      "z": 1,
      "name": "Soil_Pathway"
    },
    {
      "x": -5,
      "y": -3,
      "z": 1,
      "name": "Soil_Pathway"
    },
    {
      "x": -5,
      "y": -2,
      "z": 1,
      "name": "Soil_Pathway"
    },
    {
      "x": -5,
      "y": -1,
      "z": 1,
      "name": "Soil_Pathway"
    },
    {
      "x": -5,
      "y": 0,
      "z": 1,
      "name": "Soil_Pathway"
    },
    {
      "x": -5,
      "y": -4,
      "z": 2,
      "name": "Soil_Pathway"
    },
    {
      "x": -5,
      "y": -3,
      "z": 2,
      "name": "Soil_Pathway"
    },
    {
      "x": -5,
      "y": -2,
      "z": 2,
      "name": "Soil_Pathway"
    },
    {
      "x": -5,
      "y": -1,
      "z": 2,
      "name": "Soil_Pathway"
    },
    {
      "x": -5,
      "y": 0,
      "z": 2,
      "name": "Soil_Pathway"
    },
    {
      "x": -5,
      "y": -4,
      "z": 3,
      "name": "Soil_Pathway"
    },
    {
      "x": -5,
      "y": -3,
      "z": 3,
      "name": "Soil_Pathway"
    },
    {
      "x": -5,
      "y": -2,
      "z": 3,
      "name": "Soil_Pathway"
    },
    {
      "x": -5,
      "y": -1,
      "z": 3,
      "name": "Soil_Pathway"
    },
    {
      "x": -5,
      "y": 0,
      "z": 3,
      "name": "Soil_Pathway"
    },
    {
      "x": -5,
      "y": -4,
      "z": 4,
      "name": "Soil_Pathway"
    },
    {
      "x": -5,
      "y": -3,
      "z": 4,
      "name": "Soil_Pathway"
    },
    {
      "x": -5,
      "y": -2,
      "z": 4,
      "name": "Soil_Pathway"
    },
    {
      "x": -5,
      "y": -1,
      "z": 4,
      "name": "Soil_Pathway"
    },
    {
      "x": -5,
      "y": 0,
      "z": 4,
      "name": "Soil_Pathway"
    },
    {
      "x": -5,
      "y": -4,
      "z": 5,
      "name": "Soil_Pathway"
    },
    {
      "x": -5,
      "y": -3,
      "z": 5,
      "name": "Soil_Pathway"
    },
    {
      "x": -5,
      "y": -2,
      "z": 5,
      "name": "Soil_Pathway"
    },
    {
      "x": -5,
      "y": -1,
      "z": 5,
      "name": "Soil_Pathway"
    },
    {
      "x": -5,
      "y": 0,
      "z": 5,
      "name": "Soil_Pathway"
    },
    {
      "x": -5,
      "y": -4,
      "z": 6,
      "name": "Soil_Pathway"
    },
    {
      "x": -5,
      "y": -3,
      "z": 6,
      "name": "Soil_Pathway"
    },
    {
      "x": -5,
      "y": -2,
      "z": 6,
      "name": "Soil_Pathway"
    },
    {
      "x": -5,
      "y": -1,
      "z": 6,
      "name": "Soil_Pathway"
    },
    {
      "x": -5,
      "y": 0,
      "z": 6,
      "name": "Soil_Pathway"
    },
    {
      "x": -4,
      "y": -4,
      "z": -6,
      "name": "Soil_Pathway"
    },
    {
      "x": -4,
      "y": -3,
      "z": -6,
      "name": "Soil_Pathway"
    },
    {
      "x": -4,
      "y": -2,
      "z": -6,
      "name": "Soil_Pathway"
    },
    {
      "x": -4,
      "y": -1,
      "z": -6,
      "name": "Soil_Pathway"
    },
    {
      "x": -4,
      "y": 0,
      "z": -6,
      "name": "Soil_Pathway"
    },
    {
      "x": -4,
      "y": -4,
      "z": -5,
      "name": "Soil_Pathway"
    },
    {
      "x": -4,
      "y": -3,
      "z": -5,
      "name": "Soil_Pathway"
    },
    {
      "x": -4,
      "y": -2,
      "z": -5,
      "name": "Soil_Pathway"
    },
    {
      "x": -4,
      "y": -1,
      "z": -5,
      "name": "Soil_Pathway"
    },
    {
      "x": -4,
      "y": 0,
      "z": -5,
      "name": "Soil_Pathway"
    },
    {
      "x": -4,
      "y": -4,
      "z": -4,
      "name": "Soil_Pathway"
    },
    {
      "x": -4,
      "y": -3,
      "z": -4,
      "name": "Soil_Pathway"
    },
    {
      "x": -4,
      "y": -2,
      "z": -4,
      "name": "Soil_Pathway"
    },
    {
      "x": -4,
      "y": -1,
      "z": -4,
      "name": "Soil_Pathway"
    },
    {
      "x": -4,
      "y": 0,
      "z": -4,
      "name": "Soil_Pathway"
    },
    {
      "x": -4,
      "y": -4,
      "z": -3,
      "name": "Soil_Pathway"
    },
    {
      "x": -4,
      "y": -3,
      "z": -3,
      "name": "Soil_Pathway"
    },
    {
      "x": -4,
      "y": -2,
      "z": -3,
      "name": "Soil_Pathway"
    },
    {
      "x": -4,
      "y": -1,
      "z": -3,
      "name": "Soil_Pathway"
    },
    {
      "x": -4,
      "y": 0,
      "z": -3,
      "name": "Soil_Pathway"
    },
    {
      "x": -4,
      "y": -4,
      "z": -2,
      "name": "Soil_Pathway"
    },
    {
      "x": -4,
      "y": -3,
      "z": -2,
      "name": "Soil_Pathway"
    },
    {
      "x": -4,
      "y": -2,
      "z": -2,
      "name": "Soil_Pathway"
    },
    {
      "x": -4,
      "y": -1,
      "z": -2,
      "name": "Soil_Pathway"
    },
    {
      "x": -4,
      "y": 0,
      "z": -2,
      "name": "Soil_Pathway"
    },
    {
      "x": -4,
      "y": -4,
      "z": -1,
      "name": "Soil_Pathway"
    },
    {
      "x": -4,
      "y": -3,
      "z": -1,
      "name": "Soil_Pathway"
    },
    {
      "x": -4,
      "y": -2,
      "z": -1,
      "name": "Soil_Pathway"
    },
    {
      "x": -4,
      "y": -1,
      "z": -1,
      "name": "Soil_Pathway"
    },
    {
      "x": -4,
      "y": 0,
      "z": -1,
      "name": "Soil_Pathway"
    },
    {
      "x": -4,
      "y": -4,
      "z": 0,
      "name": "Soil_Pathway"
    },
    {
      "x": -4,
      "y": -3,
      "z": 0,
      "name": "Soil_Pathway"
    },
    {
      "x": -4,
      "y": -2,
      "z": 0,
      "name": "Soil_Pathway"
    },
    {
      "x": -4,
      "y": -1,
      "z": 0,
      "name": "Soil_Pathway"
    },
    {
      "x": -4,
      "y": 0,
      "z": 0,
      "name": "Soil_Pathway"
    },
    {
      "x": -4,
      "y": -4,
      "z": 1,
      "name": "Soil_Pathway"
    },
    {
      "x": -4,
      "y": -3,
      "z": 1,
      "name": "Soil_Pathway"
    },
    {
      "x": -4,
      "y": -2,
      "z": 1,
      "name": "Soil_Pathway"
    },
    {
      "x": -4,
      "y": -1,
      "z": 1,
      "name": "Soil_Pathway"
    },
    {
      "x": -4,
      "y": 0,
      "z": 1,
      "name": "Soil_Pathway"
    },
    {
      "x": -4,
      "y": -4,
      "z": 2,
      "name": "Soil_Pathway"
    },
    {
      "x": -4,
      "y": -3,
      "z": 2,
      "name": "Soil_Pathway"
    },
    {
      "x": -4,
      "y": -2,
      "z": 2,
      "name": "Soil_Pathway"
    },
    {
      "x": -4,
      "y": -1,
      "z": 2,
      "name": "Soil_Pathway"
    },
    {
      "x": -4,
      "y": 0,
      "z": 2,
      "name": "Soil_Pathway"
    },
    {
      "x": -4,
      "y": -4,
      "z": 3,
      "name": "Soil_Pathway"
    },
    {
      "x": -4,
      "y": -3,
      "z": 3,
      "name": "Soil_Pathway"
    },
    {
      "x": -4,
      "y": -2,
      "z": 3,
      "name": "Soil_Pathway"
    },
    {
      "x": -4,
      "y": -1,
      "z": 3,
      "name": "Soil_Pathway"
    },
    {
      "x": -4,
      "y": 0,
      "z": 3,
      "name": "Soil_Pathway"
    },
    {
      "x": -4,
      "y": -4,
      "z": 4,
      "name": "Soil_Pathway"
    },
    {
      "x": -4,
      "y": -3,
      "z": 4,
      "name": "Soil_Pathway"
    },
    {
      "x": -4,
      "y": -2,
      "z": 4,
      "name": "Soil_Pathway"
    },
    {
      "x": -4,
      "y": -1,
      "z": 4,
      "name": "Soil_Pathway"
    },
    {
      "x": -4,
      "y": 0,
      "z": 4,
      "name": "Soil_Pathway"
    },
    {
      "x": -4,
      "y": -4,
      "z": 5,
      "name": "Soil_Pathway"
    },
    {
      "x": -4,
      "y": -3,
      "z": 5,
      "name": "Soil_Pathway"
    },
    {
      "x": -4,
      "y": -2,
      "z": 5,
      "name": "Soil_Pathway"
    },
    {
      "x": -4,
      "y": -1,
      "z": 5,
      "name": "Soil_Pathway"
    },
    {
      "x": -4,
      "y": 0,
      "z": 5,
      "name": "Soil_Pathway"
    },
    {
      "x": -4,
      "y": -4,
      "z": 6,
      "name": "Soil_Pathway"
    },
    {
      "x": -4,
      "y": -3,
      "z": 6,
      "name": "Soil_Pathway"
    },
    {
      "x": -4,
      "y": -2,
      "z": 6,
      "name": "Soil_Pathway"
    },
    {
      "x": -4,
      "y": -1,
      "z": 6,
      "name": "Soil_Pathway"
    },
    {
      "x": -4,
      "y": 0,
      "z": 6,
      "name": "Soil_Pathway"
    },
    {
      "x": -3,
      "y": -4,
      "z": -7,
      "name": "Soil_Pathway"
    },
    {
      "x": -3,
      "y": -3,
      "z": -7,
      "name": "Soil_Pathway"
    },
    {
      "x": -3,
      "y": -2,
      "z": -7,
      "name": "Soil_Pathway"
    },
    {
      "x": -3,
      "y": -1,
      "z": -7,
      "name": "Soil_Pathway"
    },
    {
      "x": -3,
      "y": 0,
      "z": -7,
      "name": "Soil_Pathway"
    },
    {
      "x": -3,
      "y": -4,
      "z": -6,
      "name": "Soil_Pathway"
    },
    {
      "x": -3,
      "y": -3,
      "z": -6,
      "name": "Soil_Pathway"
    },
    {
      "x": -3,
      "y": -2,
      "z": -6,
      "name": "Soil_Pathway"
    },
    {
      "x": -3,
      "y": -1,
      "z": -6,
      "name": "Soil_Pathway"
    },
    {
      "x": -3,
      "y": 0,
      "z": -6,
      "name": "Soil_Pathway"
    },
    {
      "x": -3,
      "y": -4,
      "z": -5,
      "name": "Soil_Pathway"
    },
    {
      "x": -3,
      "y": -3,
      "z": -5,
      "name": "Soil_Pathway"
    },
    {
      "x": -3,
      "y": -2,
      "z": -5,
      "name": "Soil_Pathway"
    },
    {
      "x": -3,
      "y": -1,
      "z": -5,
      "name": "Soil_Pathway"
    },
    {
      "x": -3,
      "y": 0,
      "z": -5,
      "name": "Soil_Pathway"
    },
    {
      "x": -3,
      "y": -4,
      "z": -4,
      "name": "Soil_Pathway"
    },
    {
      "x": -3,
      "y": -3,
      "z": -4,
      "name": "Soil_Pathway"
    },
    {
      "x": -3,
      "y": -2,
      "z": -4,
      "name": "Soil_Pathway"
    },
    {
      "x": -3,
      "y": -1,
      "z": -4,
      "name": "Soil_Pathway"
    },
    {
      "x": -3,
      "y": 0,
      "z": -4,
      "name": "Soil_Pathway"
    },
    {
      "x": -3,
      "y": -4,
      "z": -3,
      "name": "Soil_Pathway"
    },
    {
      "x": -3,
      "y": -3,
      "z": -3,
      "name": "Soil_Pathway"
    },
    {
      "x": -3,
      "y": -2,
      "z": -3,
      "name": "Soil_Pathway"
    },
    {
      "x": -3,
      "y": -1,
      "z": -3,
      "name": "Soil_Pathway"
    },
    {
      "x": -3,
      "y": 0,
      "z": -3,
      "name": "Soil_Pathway"
    },
    {
      "x": -3,
      "y": -4,
      "z": -2,
      "name": "Soil_Pathway"
    },
    {
      "x": -3,
      "y": -3,
      "z": -2,
      "name": "Soil_Pathway"
    },
    {
      "x": -3,
      "y": -2,
      "z": -2,
      "name": "Soil_Pathway"
    },
    {
      "x": -3,
      "y": -1,
      "z": -2,
      "name": "Soil_Pathway"
    },
    {
      "x": -3,
      "y": 0,
      "z": -2,
      "name": "Soil_Pathway"
    },
    {
      "x": -3,
      "y": -4,
      "z": -1,
      "name": "Soil_Pathway"
    },
    {
      "x": -3,
      "y": -3,
      "z": -1,
      "name": "Soil_Pathway"
    },
    {
      "x": -3,
      "y": -2,
      "z": -1,
      "name": "Soil_Pathway"
    },
    {
      "x": -3,
      "y": -1,
      "z": -1,
      "name": "Soil_Pathway"
    },
    {
      "x": -3,
      "y": 0,
      "z": -1,
      "name": "Soil_Pathway"
    },
    {
      "x": -3,
      "y": -4,
      "z": 0,
      "name": "Soil_Pathway"
    },
    {
      "x": -3,
      "y": -3,
      "z": 0,
      "name": "Soil_Pathway"
    },
    {
      "x": -3,
      "y": -2,
      "z": 0,
      "name": "Soil_Pathway"
    },
    {
      "x": -3,
      "y": -1,
      "z": 0,
      "name": "Soil_Pathway"
    },
    {
      "x": -3,
      "y": 0,
      "z": 0,
      "name": "Soil_Pathway"
    },
    {
      "x": -3,
      "y": -4,
      "z": 1,
      "name": "Soil_Pathway"
    },
    {
      "x": -3,
      "y": -3,
      "z": 1,
      "name": "Soil_Pathway"
    },
    {
      "x": -3,
      "y": -2,
      "z": 1,
      "name": "Soil_Pathway"
    },
    {
      "x": -3,
      "y": -1,
      "z": 1,
      "name": "Soil_Pathway"
    },
    {
      "x": -3,
      "y": 0,
      "z": 1,
      "name": "Soil_Pathway"
    },
    {
      "x": -3,
      "y": -4,
      "z": 2,
      "name": "Soil_Pathway"
    },
    {
      "x": -3,
      "y": -3,
      "z": 2,
      "name": "Soil_Pathway"
    },
    {
      "x": -3,
      "y": -2,
      "z": 2,
      "name": "Soil_Pathway"
    },
    {
      "x": -3,
      "y": -1,
      "z": 2,
      "name": "Soil_Pathway"
    },
    {
      "x": -3,
      "y": 0,
      "z": 2,
      "name": "Soil_Pathway"
    },
    {
      "x": -3,
      "y": -4,
      "z": 3,
      "name": "Soil_Pathway"
    },
    {
      "x": -3,
      "y": -3,
      "z": 3,
      "name": "Soil_Pathway"
    },
    {
      "x": -3,
      "y": -2,
      "z": 3,
      "name": "Soil_Pathway"
    },
    {
      "x": -3,
      "y": -1,
      "z": 3,
      "name": "Soil_Pathway"
    },
    {
      "x": -3,
      "y": 0,
      "z": 3,
      "name": "Soil_Pathway"
    },
    {
      "x": -3,
      "y": -4,
      "z": 4,
      "name": "Soil_Pathway"
    },
    {
      "x": -3,
      "y": -3,
      "z": 4,
      "name": "Soil_Pathway"
    },
    {
      "x": -3,
      "y": -2,
      "z": 4,
      "name": "Soil_Pathway"
    },
    {
      "x": -3,
      "y": -1,
      "z": 4,
      "name": "Soil_Pathway"
    },
    {
      "x": -3,
      "y": 0,
      "z": 4,
      "name": "Soil_Pathway"
    },
    {
      "x": -3,
      "y": -4,
      "z": 5,
      "name": "Soil_Pathway"
    },
    {
      "x": -3,
      "y": -3,
      "z": 5,
      "name": "Soil_Pathway"
    },
    {
      "x": -3,
      "y": -2,
      "z": 5,
      "name": "Soil_Pathway"
    },
    {
      "x": -3,
      "y": -1,
      "z": 5,
      "name": "Soil_Pathway"
    },
    {
      "x": -3,
      "y": 0,
      "z": 5,
      "name": "Soil_Pathway"
    },
    {
      "x": -3,
      "y": -4,
      "z": 6,
      "name": "Soil_Pathway"
    },
    {
      "x": -3,
      "y": -3,
      "z": 6,
      "name": "Soil_Pathway"
    },
    {
      "x": -3,
      "y": -2,
      "z": 6,
      "name": "Soil_Pathway"
    },
    {
      "x": -3,
      "y": -1,
      "z": 6,
      "name": "Soil_Pathway"
    },
    {
      "x": -3,
      "y": 0,
      "z": 6,
      "name": "Soil_Pathway"
    },
    {
      "x": -3,
      "y": -4,
      "z": 7,
      "name": "Soil_Pathway"
    },
    {
      "x": -3,
      "y": -3,
      "z": 7,
      "name": "Soil_Pathway"
    },
    {
      "x": -3,
      "y": -2,
      "z": 7,
      "name": "Soil_Pathway"
    },
    {
      "x": -3,
      "y": -1,
      "z": 7,
      "name": "Soil_Pathway"
    },
    {
      "x": -3,
      "y": 0,
      "z": 7,
      "name": "Soil_Pathway"
    },
    {
      "x": -2,
      "y": -4,
      "z": -7,
      "name": "Soil_Pathway"
    },
    {
      "x": -2,
      "y": -3,
      "z": -7,
      "name": "Soil_Pathway"
    },
    {
      "x": -2,
      "y": -2,
      "z": -7,
      "name": "Soil_Pathway"
    },
    {
      "x": -2,
      "y": -1,
      "z": -7,
      "name": "Soil_Pathway"
    },
    {
      "x": -2,
      "y": 0,
      "z": -7,
      "name": "Soil_Pathway"
    },
    {
      "x": -2,
      "y": -4,
      "z": -6,
      "name": "Soil_Pathway"
    },
    {
      "x": -2,
      "y": -3,
      "z": -6,
      "name": "Soil_Pathway"
    },
    {
      "x": -2,
      "y": -2,
      "z": -6,
      "name": "Soil_Pathway"
    },
    {
      "x": -2,
      "y": -1,
      "z": -6,
      "name": "Soil_Pathway"
    },
    {
      "x": -2,
      "y": 0,
      "z": -6,
      "name": "Soil_Pathway"
    },
    {
      "x": -2,
      "y": -4,
      "z": -5,
      "name": "Soil_Pathway"
    },
    {
      "x": -2,
      "y": -3,
      "z": -5,
      "name": "Soil_Pathway"
    },
    {
      "x": -2,
      "y": -2,
      "z": -5,
      "name": "Soil_Pathway"
    },
    {
      "x": -2,
      "y": -1,
      "z": -5,
      "name": "Soil_Pathway"
    },
    {
      "x": -2,
      "y": 0,
      "z": -5,
      "name": "Soil_Pathway"
    },
    {
      "x": -2,
      "y": -4,
      "z": -4,
      "name": "Soil_Pathway"
    },
    {
      "x": -2,
      "y": -3,
      "z": -4,
      "name": "Soil_Pathway"
    },
    {
      "x": -2,
      "y": -2,
      "z": -4,
      "name": "Soil_Pathway"
    },
    {
      "x": -2,
      "y": -1,
      "z": -4,
      "name": "Soil_Pathway"
    },
    {
      "x": -2,
      "y": 0,
      "z": -4,
      "name": "Soil_Pathway"
    },
    {
      "x": -2,
      "y": -4,
      "z": -3,
      "name": "Soil_Pathway"
    },
    {
      "x": -2,
      "y": -3,
      "z": -3,
      "name": "Soil_Pathway"
    },
    {
      "x": -2,
      "y": -2,
      "z": -3,
      "name": "Soil_Pathway"
    },
    {
      "x": -2,
      "y": -1,
      "z": -3,
      "name": "Soil_Pathway"
    },
    {
      "x": -2,
      "y": 0,
      "z": -3,
      "name": "Soil_Pathway"
    },
    {
      "x": -2,
      "y": -4,
      "z": -2,
      "name": "Soil_Pathway"
    },
    {
      "x": -2,
      "y": -3,
      "z": -2,
      "name": "Soil_Pathway"
    },
    {
      "x": -2,
      "y": -2,
      "z": -2,
      "name": "Soil_Pathway"
    },
    {
      "x": -2,
      "y": -1,
      "z": -2,
      "name": "Soil_Pathway"
    },
    {
      "x": -2,
      "y": 0,
      "z": -2,
      "name": "Soil_Pathway"
    },
    {
      "x": -2,
      "y": -4,
      "z": -1,
      "name": "Soil_Pathway"
    },
    {
      "x": -2,
      "y": -3,
      "z": -1,
      "name": "Soil_Pathway"
    },
    {
      "x": -2,
      "y": -2,
      "z": -1,
      "name": "Soil_Pathway"
    },
    {
      "x": -2,
      "y": -1,
      "z": -1,
      "name": "Soil_Pathway"
    },
    {
      "x": -2,
      "y": 0,
      "z": -1,
      "name": "Soil_Pathway"
    },
    {
      "x": -2,
      "y": -4,
      "z": 0,
      "name": "Soil_Pathway"
    },
    {
      "x": -2,
      "y": -3,
      "z": 0,
      "name": "Soil_Pathway"
    },
    {
      "x": -2,
      "y": -2,
      "z": 0,
      "name": "Soil_Pathway"
    },
    {
      "x": -2,
      "y": -1,
      "z": 0,
      "name": "Soil_Pathway"
    },
    {
      "x": -2,
      "y": 0,
      "z": 0,
      "name": "Soil_Pathway"
    },
    {
      "x": -2,
      "y": -4,
      "z": 1,
      "name": "Soil_Pathway"
    },
    {
      "x": -2,
      "y": -3,
      "z": 1,
      "name": "Soil_Pathway"
    },
    {
      "x": -2,
      "y": -2,
      "z": 1,
      "name": "Soil_Pathway"
    },
    {
      "x": -2,
      "y": -1,
      "z": 1,
      "name": "Soil_Pathway"
    },
    {
      "x": -2,
      "y": 0,
      "z": 1,
      "name": "Soil_Pathway"
    },
    {
      "x": -2,
      "y": -4,
      "z": 2,
      "name": "Soil_Pathway"
    },
    {
      "x": -2,
      "y": -3,
      "z": 2,
      "name": "Soil_Pathway"
    },
    {
      "x": -2,
      "y": -2,
      "z": 2,
      "name": "Soil_Pathway"
    },
    {
      "x": -2,
      "y": -1,
      "z": 2,
      "name": "Soil_Pathway"
    },
    {
      "x": -2,
      "y": 0,
      "z": 2,
      "name": "Soil_Pathway"
    },
    {
      "x": -2,
      "y": -4,
      "z": 3,
      "name": "Soil_Pathway"
    },
    {
      "x": -2,
      "y": -3,
      "z": 3,
      "name": "Soil_Pathway"
    },
    {
      "x": -2,
      "y": -2,
      "z": 3,
      "name": "Soil_Pathway"
    },
    {
      "x": -2,
      "y": -1,
      "z": 3,
      "name": "Soil_Pathway"
    },
    {
      "x": -2,
      "y": 0,
      "z": 3,
      "name": "Soil_Pathway"
    },
    {
      "x": -2,
      "y": -4,
      "z": 4,
      "name": "Soil_Pathway"
    },
    {
      "x": -2,
      "y": -3,
      "z": 4,
      "name": "Soil_Pathway"
    },
    {
      "x": -2,
      "y": -2,
      "z": 4,
      "name": "Soil_Pathway"
    },
    {
      "x": -2,
      "y": -1,
      "z": 4,
      "name": "Soil_Pathway"
    },
    {
      "x": -2,
      "y": 0,
      "z": 4,
      "name": "Soil_Pathway"
    },
    {
      "x": -2,
      "y": -4,
      "z": 5,
      "name": "Soil_Pathway"
    },
    {
      "x": -2,
      "y": -3,
      "z": 5,
      "name": "Soil_Pathway"
    },
    {
      "x": -2,
      "y": -2,
      "z": 5,
      "name": "Soil_Pathway"
    },
    {
      "x": -2,
      "y": -1,
      "z": 5,
      "name": "Soil_Pathway"
    },
    {
      "x": -2,
      "y": 0,
      "z": 5,
      "name": "Soil_Pathway"
    },
    {
      "x": -2,
      "y": -4,
      "z": 6,
      "name": "Soil_Pathway"
    },
    {
      "x": -2,
      "y": -3,
      "z": 6,
      "name": "Soil_Pathway"
    },
    {
      "x": -2,
      "y": -2,
      "z": 6,
      "name": "Soil_Pathway"
    },
    {
      "x": -2,
      "y": -1,
      "z": 6,
      "name": "Soil_Pathway"
    },
    {
      "x": -2,
      "y": 0,
      "z": 6,
      "name": "Soil_Pathway"
    },
    {
      "x": -2,
      "y": -4,
      "z": 7,
      "name": "Soil_Pathway"
    },
    {
      "x": -2,
      "y": -3,
      "z": 7,
      "name": "Soil_Pathway"
    },
    {
      "x": -2,
      "y": -2,
      "z": 7,
      "name": "Soil_Pathway"
    },
    {
      "x": -2,
      "y": -1,
      "z": 7,
      "name": "Soil_Pathway"
    },
    {
      "x": -2,
      "y": 0,
      "z": 7,
      "name": "Soil_Pathway"
    },
    {
      "x": -1,
      "y": -4,
      "z": -7,
      "name": "Soil_Pathway"
    },
    {
      "x": -1,
      "y": -3,
      "z": -7,
      "name": "Soil_Pathway"
    },
    {
      "x": -1,
      "y": -2,
      "z": -7,
      "name": "Soil_Pathway"
    },
    {
      "x": -1,
      "y": -1,
      "z": -7,
      "name": "Soil_Pathway"
    },
    {
      "x": -1,
      "y": 0,
      "z": -7,
      "name": "Soil_Pathway"
    },
    {
      "x": -1,
      "y": -4,
      "z": -6,
      "name": "Soil_Pathway"
    },
    {
      "x": -1,
      "y": -3,
      "z": -6,
      "name": "Soil_Pathway"
    },
    {
      "x": -1,
      "y": -2,
      "z": -6,
      "name": "Soil_Pathway"
    },
    {
      "x": -1,
      "y": -1,
      "z": -6,
      "name": "Soil_Pathway"
    },
    {
      "x": -1,
      "y": 0,
      "z": -6,
      "name": "Soil_Pathway"
    },
    {
      "x": -1,
      "y": -4,
      "z": -5,
      "name": "Soil_Pathway"
    },
    {
      "x": -1,
      "y": -3,
      "z": -5,
      "name": "Soil_Pathway"
    },
    {
      "x": -1,
      "y": -2,
      "z": -5,
      "name": "Soil_Pathway"
    },
    {
      "x": -1,
      "y": -1,
      "z": -5,
      "name": "Soil_Pathway"
    },
    {
      "x": -1,
      "y": 0,
      "z": -5,
      "name": "Soil_Pathway"
    },
    {
      "x": -1,
      "y": -4,
      "z": -4,
      "name": "Soil_Pathway"
    },
    {
      "x": -1,
      "y": -3,
      "z": -4,
      "name": "Soil_Pathway"
    },
    {
      "x": -1,
      "y": -2,
      "z": -4,
      "name": "Soil_Pathway"
    },
    {
      "x": -1,
      "y": -1,
      "z": -4,
      "name": "Soil_Pathway"
    },
    {
      "x": -1,
      "y": 0,
      "z": -4,
      "name": "Soil_Pathway"
    },
    {
      "x": -1,
      "y": -4,
      "z": -3,
      "name": "Soil_Pathway"
    },
    {
      "x": -1,
      "y": -3,
      "z": -3,
      "name": "Soil_Pathway"
    },
    {
      "x": -1,
      "y": -2,
      "z": -3,
      "name": "Soil_Pathway"
    },
    {
      "x": -1,
      "y": -1,
      "z": -3,
      "name": "Soil_Pathway"
    },
    {
      "x": -1,
      "y": 0,
      "z": -3,
      "name": "Soil_Pathway"
    },
    {
      "x": -1,
      "y": -4,
      "z": -2,
      "name": "Soil_Pathway"
    },
    {
      "x": -1,
      "y": -3,
      "z": -2,
      "name": "Soil_Pathway"
    },
    {
      "x": -1,
      "y": -2,
      "z": -2,
      "name": "Soil_Pathway"
    },
    {
      "x": -1,
      "y": -1,
      "z": -2,
      "name": "Soil_Pathway"
    },
    {
      "x": -1,
      "y": 0,
      "z": -2,
      "name": "Soil_Pathway"
    },
    {
      "x": -1,
      "y": -4,
      "z": -1,
      "name": "Soil_Pathway"
    },
    {
      "x": -1,
      "y": -3,
      "z": -1,
      "name": "Soil_Pathway"
    },
    {
      "x": -1,
      "y": -2,
      "z": -1,
      "name": "Soil_Pathway"
    },
    {
      "x": -1,
      "y": -1,
      "z": -1,
      "name": "Soil_Pathway"
    },
    {
      "x": -1,
      "y": 0,
      "z": -1,
      "name": "Soil_Pathway"
    },
    {
      "x": -1,
      "y": -4,
      "z": 0,
      "name": "Soil_Pathway"
    },
    {
      "x": -1,
      "y": -3,
      "z": 0,
      "name": "Soil_Pathway"
    },
    {
      "x": -1,
      "y": -2,
      "z": 0,
      "name": "Soil_Pathway"
    },
    {
      "x": -1,
      "y": -1,
      "z": 0,
      "name": "Soil_Pathway"
    },
    {
      "x": -1,
      "y": 0,
      "z": 0,
      "name": "Soil_Pathway"
    },
    {
      "x": -1,
      "y": -4,
      "z": 1,
      "name": "Soil_Pathway"
    },
    {
      "x": -1,
      "y": -3,
      "z": 1,
      "name": "Soil_Pathway"
    },
    {
      "x": -1,
      "y": -2,
      "z": 1,
      "name": "Soil_Pathway"
    },
    {
      "x": -1,
      "y": -1,
      "z": 1,
      "name": "Soil_Pathway"
    },
    {
      "x": -1,
      "y": 0,
      "z": 1,
      "name": "Soil_Pathway"
    },
    {
      "x": -1,
      "y": 1,
      "z": 1,
      "name": "Empty"
    },
    {
      "x": -1,
      "y": -4,
      "z": 2,
      "name": "Soil_Pathway"
    },
    {
      "x": -1,
      "y": -3,
      "z": 2,
      "name": "Soil_Pathway"
    },
    {
      "x": -1,
      "y": -2,
      "z": 2,
      "name": "Soil_Pathway"
    },
    {
      "x": -1,
      "y": -1,
      "z": 2,
      "name": "Soil_Pathway"
    },
    {
      "x": -1,
      "y": 0,
      "z": 2,
      "name": "Soil_Pathway"
    },
    {
      "x": -1,
      "y": 1,
      "z": 2,
      "name": "Empty"
    },
    {
      "x": -1,
      "y": -4,
      "z": 3,
      "name": "Soil_Pathway"
    },
    {
      "x": -1,
      "y": -3,
      "z": 3,
      "name": "Soil_Pathway"
    },
    {
      "x": -1,
      "y": -2,
      "z": 3,
      "name": "Soil_Pathway"
    },
    {
      "x": -1,
      "y": -1,
      "z": 3,
      "name": "Soil_Pathway"
    },
    {
      "x": -1,
      "y": 0,
      "z": 3,
      "name": "Soil_Pathway"
    },
    {
      "x": -1,
      "y": -4,
      "z": 4,
      "name": "Soil_Pathway"
    },
    {
      "x": -1,
      "y": -3,
      "z": 4,
      "name": "Soil_Pathway"
    },
    {
      "x": -1,
      "y": -2,
      "z": 4,
      "name": "Soil_Pathway"
    },
    {
      "x": -1,
      "y": -1,
      "z": 4,
      "name": "Soil_Pathway"
    },
    {
      "x": -1,
      "y": 0,
      "z": 4,
      "name": "Soil_Pathway"
    },
    {
      "x": -1,
      "y": -4,
      "z": 5,
      "name": "Soil_Pathway"
    },
    {
      "x": -1,
      "y": -3,
      "z": 5,
      "name": "Soil_Pathway"
    },
    {
      "x": -1,
      "y": -2,
      "z": 5,
      "name": "Soil_Pathway"
    },
    {
      "x": -1,
      "y": -1,
      "z": 5,
      "name": "Soil_Pathway"
    },
    {
      "x": -1,
      "y": 0,
      "z": 5,
      "name": "Soil_Pathway"
    },
    {
      "x": -1,
      "y": -4,
      "z": 6,
      "name": "Soil_Pathway"
    },
    {
      "x": -1,
      "y": -3,
      "z": 6,
      "name": "Soil_Pathway"
    },
    {
      "x": -1,
      "y": -2,
      "z": 6,
      "name": "Soil_Pathway"
    },
    {
      "x": -1,
      "y": -1,
      "z": 6,
      "name": "Soil_Pathway"
    },
    {
      "x": -1,
      "y": 0,
      "z": 6,
      "name": "Soil_Pathway"
    },
    {
      "x": -1,
      "y": -4,
      "z": 7,
      "name": "Soil_Pathway"
    },
    {
      "x": -1,
      "y": -3,
      "z": 7,
      "name": "Soil_Pathway"
    },
    {
      "x": -1,
      "y": -2,
      "z": 7,
      "name": "Soil_Pathway"
    },
    {
      "x": -1,
      "y": -1,
      "z": 7,
      "name": "Soil_Pathway"
    },
    {
      "x": -1,
      "y": 0,
      "z": 7,
      "name": "Soil_Pathway"
    },
    {
      "x": 0,
      "y": -4,
      "z": -6,
      "name": "Soil_Pathway"
    },
    {
      "x": 0,
      "y": -3,
      "z": -6,
      "name": "Soil_Pathway"
    },
    {
      "x": 0,
      "y": -2,
      "z": -6,
      "name": "Soil_Pathway"
    },
    {
      "x": 0,
      "y": -1,
      "z": -6,
      "name": "Soil_Pathway"
    },
    {
      "x": 0,
      "y": 0,
      "z": -6,
      "name": "Soil_Pathway"
    },
    {
      "x": 0,
      "y": -4,
      "z": -5,
      "name": "Soil_Pathway"
    },
    {
      "x": 0,
      "y": -3,
      "z": -5,
      "name": "Soil_Pathway"
    },
    {
      "x": 0,
      "y": -2,
      "z": -5,
      "name": "Soil_Pathway"
    },
    {
      "x": 0,
      "y": -1,
      "z": -5,
      "name": "Soil_Pathway"
    },
    {
      "x": 0,
      "y": 0,
      "z": -5,
      "name": "Soil_Pathway"
    },
    {
      "x": 0,
      "y": -4,
      "z": -4,
      "name": "Soil_Pathway"
    },
    {
      "x": 0,
      "y": -3,
      "z": -4,
      "name": "Soil_Pathway"
    },
    {
      "x": 0,
      "y": -2,
      "z": -4,
      "name": "Soil_Pathway"
    },
    {
      "x": 0,
      "y": -1,
      "z": -4,
      "name": "Soil_Pathway"
    },
    {
      "x": 0,
      "y": 0,
      "z": -4,
      "name": "Soil_Pathway"
    },
    {
      "x": 0,
      "y": -4,
      "z": -3,
      "name": "Soil_Pathway"
    },
    {
      "x": 0,
      "y": -3,
      "z": -3,
      "name": "Soil_Pathway"
    },
    {
      "x": 0,
      "y": -2,
      "z": -3,
      "name": "Soil_Pathway"
    },
    {
      "x": 0,
      "y": -1,
      "z": -3,
      "name": "Soil_Pathway"
    },
    {
      "x": 0,
      "y": 0,
      "z": -3,
      "name": "Soil_Pathway"
    },
    {
      "x": 0,
      "y": -4,
      "z": -2,
      "name": "Soil_Pathway"
    },
    {
      "x": 0,
      "y": -3,
      "z": -2,
      "name": "Soil_Pathway"
    },
    {
      "x": 0,
      "y": -2,
      "z": -2,
      "name": "Soil_Pathway"
    },
    {
      "x": 0,
      "y": -1,
      "z": -2,
      "name": "Soil_Dirt"
    },
    {
      "x": 0,
      "y": 0,
      "z": -2,
      "name": "Soil_Dirt"
    },
    {
      "x": 0,
      "y": 1,
      "z": -2,
      "name": "Rubble_Stone_Medium",
      "support": 15
    },
    {
      "x": 0,
      "y": -4,
      "z": -1,
      "name": "Soil_Pathway"
    },
    {
      "x": 0,
      "y": -3,
      "z": -1,
      "name": "Soil_Pathway"
    },
    {
      "x": 0,
      "y": -2,
      "z": -1,
      "name": "Soil_Pathway"
    },
    {
      "x": 0,
      "y": -1,
      "z": -1,
      "name": "Soil_Pathway"
    },
    {
      "x": 0,
      "y": 0,
      "z": -1,
      "name": "Soil_Pathway"
    },
    {
      "x": 0,
      "y": -4,
      "z": 0,
      "name": "Soil_Pathway"
    },
    {
      "x": 0,
      "y": -3,
      "z": 0,
      "name": "Soil_Pathway"
    },
    {
      "x": 0,
      "y": -2,
      "z": 0,
      "name": "Soil_Pathway"
    },
    {
      "x": 0,
      "y": -1,
      "z": 0,
      "name": "Soil_Pathway"
    },
    {
      "x": 0,
      "y": 0,
      "z": 0,
      "name": "Soil_Pathway"
    },
    {
      "x": 0,
      "y": 1,
      "z": 0,
      "name": "Empty"
    },
    {
      "x": 0,
      "y": -4,
      "z": 1,
      "name": "Soil_Pathway"
    },
    {
      "x": 0,
      "y": -3,
      "z": 1,
      "name": "Soil_Pathway"
    },
    {
      "x": 0,
      "y": -2,
      "z": 1,
      "name": "Soil_Pathway"
    },
    {
      "x": 0,
      "y": -1,
      "z": 1,
      "name": "Soil_Dirt"
    },
    {
      "x": 0,
      "y": 0,
      "z": 1,
      "name": "Soil_Dirt"
    },
    {
      "x": 0,
      "y": 1,
      "z": 1,
      "name": "Plant_Fruit_Apple"
    },
    {
      "x": 0,
      "y": -4,
      "z": 2,
      "name": "Soil_Pathway"
    },
    {
      "x": 0,
      "y": -3,
      "z": 2,
      "name": "Soil_Pathway"
    },
    {
      "x": 0,
      "y": -2,
      "z": 2,
      "name": "Soil_Pathway"
    },
    {
      "x": 0,
      "y": -1,
      "z": 2,
      "name": "Soil_Dirt"
    },
    {
      "x": 0,
      "y": 0,
      "z": 2,
      "name": "Soil_Dirt"
    },
    {
      "x": 0,
      "y": 1,
      "z": 2,
      "name": "Deco_Plate"
    },
    {
      "x": 0,
      "y": -4,
      "z": 3,
      "name": "Soil_Pathway"
    },
    {
      "x": 0,
      "y": -3,
      "z": 3,
      "name": "Soil_Pathway"
    },
    {
      "x": 0,
      "y": -2,
      "z": 3,
      "name": "Soil_Pathway"
    },
    {
      "x": 0,
      "y": -1,
      "z": 3,
      "name": "Soil_Dirt"
    },
    {
      "x": 0,
      "y": 0,
      "z": 3,
      "name": "Soil_Dirt"
    },
    {
      "x": 0,
      "y": 1,
      "z": 3,
      "name": "Rubble_Stone",
      "support": 15
    },
    {
      "x": 0,
      "y": -4,
      "z": 4,
      "name": "Soil_Pathway"
    },
    {
      "x": 0,
      "y": -3,
      "z": 4,
      "name": "Soil_Pathway"
    },
    {
      "x": 0,
      "y": -2,
      "z": 4,
      "name": "Soil_Pathway"
    },
    {
      "x": 0,
      "y": -1,
      "z": 4,
      "name": "Soil_Pathway"
    },
    {
      "x": 0,
      "y": 0,
      "z": 4,
      "name": "Soil_Pathway"
    },
    {
      "x": 0,
      "y": -4,
      "z": 5,
      "name": "Soil_Pathway"
    },
    {
      "x": 0,
      "y": -3,
      "z": 5,
      "name": "Soil_Pathway"
    },
    {
      "x": 0,
      "y": -2,
      "z": 5,
      "name": "Soil_Pathway"
    },
    {
      "x": 0,
      "y": -1,
      "z": 5,
      "name": "Soil_Pathway"
    },
    {
      "x": 0,
      "y": 0,
      "z": 5,
      "name": "Soil_Pathway"
    },
    {
      "x": 0,
      "y": -4,
      "z": 6,
      "name": "Soil_Pathway"
    },
    {
      "x": 0,
      "y": -3,
      "z": 6,
      "name": "Soil_Pathway"
    },
    {
      "x": 0,
      "y": -2,
      "z": 6,
      "name": "Soil_Pathway"
    },
    {
      "x": 0,
      "y": -1,
      "z": 6,
      "name": "Soil_Pathway"
    },
    {
      "x": 0,
      "y": 0,
      "z": 6,
      "name": "Soil_Pathway"
    },
    {
      "x": 1,
      "y": -4,
      "z": -6,
      "name": "Soil_Pathway"
    },
    {
      "x": 1,
      "y": -3,
      "z": -6,
      "name": "Soil_Pathway"
    },
    {
      "x": 1,
      "y": -2,
      "z": -6,
      "name": "Soil_Pathway"
    },
    {
      "x": 1,
      "y": -1,
      "z": -6,
      "name": "Soil_Pathway"
    },
    {
      "x": 1,
      "y": 0,
      "z": -6,
      "name": "Soil_Pathway"
    },
    {
      "x": 1,
      "y": -4,
      "z": -5,
      "name": "Soil_Pathway"
    },
    {
      "x": 1,
      "y": -3,
      "z": -5,
      "name": "Soil_Pathway"
    },
    {
      "x": 1,
      "y": -2,
      "z": -5,
      "name": "Soil_Pathway"
    },
    {
      "x": 1,
      "y": -1,
      "z": -5,
      "name": "Soil_Pathway"
    },
    {
      "x": 1,
      "y": 0,
      "z": -5,
      "name": "Soil_Pathway"
    },
    {
      "x": 1,
      "y": -4,
      "z": -4,
      "name": "Soil_Pathway"
    },
    {
      "x": 1,
      "y": -3,
      "z": -4,
      "name": "Soil_Pathway"
    },
    {
      "x": 1,
      "y": -2,
      "z": -4,
      "name": "Soil_Pathway"
    },
    {
      "x": 1,
      "y": -1,
      "z": -4,
      "name": "Soil_Pathway"
    },
    {
      "x": 1,
      "y": 0,
      "z": -4,
      "name": "Soil_Pathway"
    },
    {
      "x": 1,
      "y": -4,
      "z": -3,
      "name": "Soil_Pathway"
    },
    {
      "x": 1,
      "y": -3,
      "z": -3,
      "name": "Soil_Pathway"
    },
    {
      "x": 1,
      "y": -2,
      "z": -3,
      "name": "Soil_Pathway"
    },
    {
      "x": 1,
      "y": -1,
      "z": -3,
      "name": "Soil_Pathway"
    },
    {
      "x": 1,
      "y": 0,
      "z": -3,
      "name": "Soil_Pathway"
    },
    {
      "x": 1,
      "y": -4,
      "z": -2,
      "name": "Soil_Pathway"
    },
    {
      "x": 1,
      "y": -3,
      "z": -2,
      "name": "Soil_Pathway"
    },
    {
      "x": 1,
      "y": -2,
      "z": -2,
      "name": "Soil_Pathway"
    },
    {
      "x": 1,
      "y": -1,
      "z": -2,
      "name": "Soil_Dirt"
    },
    {
      "x": 1,
      "y": 0,
      "z": -2,
      "name": "Soil_Dirt"
    },
    {
      "x": 1,
      "y": 1,
      "z": -2,
      "name": "Rock_Stone_Cobble_Wall"
    },
    {
      "x": 1,
      "y": -4,
      "z": -1,
      "name": "Soil_Pathway"
    },
    {
      "x": 1,
      "y": -3,
      "z": -1,
      "name": "Soil_Pathway"
    },
    {
      "x": 1,
      "y": -2,
      "z": -1,
      "name": "Soil_Pathway"
    },
    {
      "x": 1,
      "y": -1,
      "z": -1,
      "name": "Soil_Dirt"
    },
    {
      "x": 1,
      "y": 0,
      "z": -1,
      "name": "Soil_Dirt"
    },
    {
      "x": 1,
      "y": -4,
      "z": 0,
      "name": "Soil_Pathway"
    },
    {
      "x": 1,
      "y": -3,
      "z": 0,
      "name": "Soil_Pathway"
    },
    {
      "x": 1,
      "y": -2,
      "z": 0,
      "name": "Soil_Pathway"
    },
    {
      "x": 1,
      "y": -1,
      "z": 0,
      "name": "Soil_Dirt"
    },
    {
      "x": 1,
      "y": 0,
      "z": 0,
      "name": "Soil_Dirt"
    },
    {
      "x": 1,
      "y": 1,
      "z": 0,
      "name": "Rock_Stone_Cobble_Mossy_Half",
      "rotation": 7
    },
    {
      "x": 1,
      "y": -4,
      "z": 1,
      "name": "Soil_Pathway"
    },
    {
      "x": 1,
      "y": -3,
      "z": 1,
      "name": "Soil_Pathway"
    },
    {
      "x": 1,
      "y": -2,
      "z": 1,
      "name": "Soil_Pathway"
    },
    {
      "x": 1,
      "y": -1,
      "z": 1,
      "name": "Soil_Dirt"
    },
    {
      "x": 1,
      "y": 0,
      "z": 1,
      "name": "Soil_Dirt"
    },
    {
      "x": 1,
      "y": 1,
      "z": 1,
      "name": "Rock_Stone_Cobble_Half",
      "rotation": 7
    },
    {
      "x": 1,
      "y": -4,
      "z": 2,
      "name": "Soil_Pathway"
    },
    {
      "x": 1,
      "y": -3,
      "z": 2,
      "name": "Soil_Pathway"
    },
    {
      "x": 1,
      "y": -2,
      "z": 2,
      "name": "Soil_Pathway"
    },
    {
      "x": 1,
      "y": -1,
      "z": 2,
      "name": "Soil_Dirt"
    },
    {
      "x": 1,
      "y": 0,
      "z": 2,
      "name": "Soil_Dirt"
    },
    {
      "x": 1,
      "y": 1,
      "z": 2,
      "name": "Rock_Stone_Cobble_Half",
      "rotation": 7
    },
    {
      "x": 1,
      "y": -4,
      "z": 3,
      "name": "Soil_Pathway"
    },
    {
      "x": 1,
      "y": -3,
      "z": 3,
      "name": "Soil_Pathway"
    },
    {
      "x": 1,
      "y": -2,
      "z": 3,
      "name": "Soil_Pathway"
    },
    {
      "x": 1,
      "y": -1,
      "z": 3,
      "name": "Soil_Dirt"
    },
    {
      "x": 1,
      "y": 0,
      "z": 3,
      "name": "Soil_Dirt"
    },
    {
      "x": 1,
      "y": 1,
      "z": 3,
      "name": "Rock_Stone_Cobble_Mossy_Half",
      "rotation": 7
    },
    {
      "x": 1,
      "y": -4,
      "z": 4,
      "name": "Soil_Pathway"
    },
    {
      "x": 1,
      "y": -3,
      "z": 4,
      "name": "Soil_Pathway"
    },
    {
      "x": 1,
      "y": -2,
      "z": 4,
      "name": "Soil_Pathway"
    },
    {
      "x": 1,
      "y": -1,
      "z": 4,
      "name": "Soil_Dirt"
    },
    {
      "x": 1,
      "y": 0,
      "z": 4,
      "name": "Soil_Dirt"
    },
    {
      "x": 1,
      "y": 1,
      "z": 4,
      "name": "Rock_Stone_Cobble_Mossy_Half",
      "rotation": 7
    },
    {
      "x": 1,
      "y": -4,
      "z": 5,
      "name": "Soil_Pathway"
    },
    {
      "x": 1,
      "y": -3,
      "z": 5,
      "name": "Soil_Pathway"
    },
    {
      "x": 1,
      "y": -2,
      "z": 5,
      "name": "Soil_Pathway"
    },
    {
      "x": 1,
      "y": -1,
      "z": 5,
      "name": "Soil_Pathway"
    },
    {
      "x": 1,
      "y": 0,
      "z": 5,
      "name": "Soil_Pathway"
    },
    {
      "x": 1,
      "y": -4,
      "z": 6,
      "name": "Soil_Pathway"
    },
    {
      "x": 1,
      "y": -3,
      "z": 6,
      "name": "Soil_Pathway"
    },
    {
      "x": 1,
      "y": -2,
      "z": 6,
      "name": "Soil_Pathway"
    },
    {
      "x": 1,
      "y": -1,
      "z": 6,
      "name": "Soil_Pathway"
    },
    {
      "x": 1,
      "y": 0,
      "z": 6,
      "name": "Soil_Pathway"
    },
    {
      "x": 1,
      "y": -4,
      "z": 7,
      "name": "Soil_Pathway"
    },
    {
      "x": 1,
      "y": -3,
      "z": 7,
      "name": "Soil_Pathway"
    },
    {
      "x": 1,
      "y": -2,
      "z": 7,
      "name": "Soil_Pathway"
    },
    {
      "x": 1,
      "y": -1,
      "z": 7,
      "name": "Soil_Pathway"
    },
    {
      "x": 1,
      "y": 0,
      "z": 7,
      "name": "Soil_Pathway"
    },
    {
      "x": 2,
      "y": -4,
      "z": -4,
      "name": "Soil_Pathway"
    },
    {
      "x": 2,
      "y": -3,
      "z": -4,
      "name": "Soil_Pathway"
    },
    {
      "x": 2,
      "y": -2,
      "z": -4,
      "name": "Soil_Pathway"
    },
    {
      "x": 2,
      "y": -1,
      "z": -4,
      "name": "Soil_Pathway"
    },
    {
      "x": 2,
      "y": 0,
      "z": -4,
      "name": "Soil_Pathway"
    },
    {
      "x": 2,
      "y": -4,
      "z": -3,
      "name": "Soil_Pathway"
    },
    {
      "x": 2,
      "y": -3,
      "z": -3,
      "name": "Soil_Pathway"
    },
    {
      "x": 2,
      "y": -2,
      "z": -3,
      "name": "Soil_Pathway"
    },
    {
      "x": 2,
      "y": -1,
      "z": -3,
      "name": "Soil_Pathway"
    },
    {
      "x": 2,
      "y": 0,
      "z": -3,
      "name": "Soil_Pathway"
    },
    {
      "x": 2,
      "y": -4,
      "z": -2,
      "name": "Soil_Pathway"
    },
    {
      "x": 2,
      "y": -3,
      "z": -2,
      "name": "Soil_Pathway"
    },
    {
      "x": 2,
      "y": -2,
      "z": -2,
      "name": "Soil_Pathway"
    },
    {
      "x": 2,
      "y": -1,
      "z": -2,
      "name": "Soil_Dirt"
    },
    {
      "x": 2,
      "y": 0,
      "z": -2,
      "name": "Soil_Dirt"
    },
    {
      "x": 2,
      "y": 1,
      "z": -2,
      "name": "*Rock_Stone_Cobble_Wall_State_Definitions_Corner"
    },
    {
      "x": 2,
      "y": -4,
      "z": -1,
      "name": "Soil_Pathway"
    },
    {
      "x": 2,
      "y": -3,
      "z": -1,
      "name": "Soil_Pathway"
    },
    {
      "x": 2,
      "y": -2,
      "z": -1,
      "name": "Soil_Pathway"
    },
    {
      "x": 2,
      "y": -1,
      "z": -1,
      "name": "Soil_Dirt"
    },
    {
      "x": 2,
      "y": 0,
      "z": -1,
      "name": "Soil_Dirt"
    },
    {
      "x": 2,
      "y": 1,
      "z": -1,
      "name": "Rock_Stone_Cobble_Wall",
      "rotation": 1
    },
    {
      "x": 2,
      "y": -4,
      "z": 0,
      "name": "Soil_Pathway"
    },
    {
      "x": 2,
      "y": -3,
      "z": 0,
      "name": "Soil_Pathway"
    },
    {
      "x": 2,
      "y": -2,
      "z": 0,
      "name": "Soil_Pathway"
    },
    {
      "x": 2,
      "y": -1,
      "z": 0,
      "name": "Soil_Dirt"
    },
    {
      "x": 2,
      "y": 0,
      "z": 0,
      "name": "Soil_Dirt"
    },
    {
      "x": 2,
      "y": 1,
      "z": 0,
      "name": "Rock_Stone_Cobble_Mossy"
    },
    {
      "x": 2,
      "y": -4,
      "z": 1,
      "name": "Soil_Pathway"
    },
    {
      "x": 2,
      "y": -3,
      "z": 1,
      "name": "Soil_Pathway"
    },
    {
      "x": 2,
      "y": -2,
      "z": 1,
      "name": "Soil_Pathway"
    },
    {
      "x": 2,
      "y": -1,
      "z": 1,
      "name": "Soil_Dirt"
    },
    {
      "x": 2,
      "y": 0,
      "z": 1,
      "name": "Soil_Dirt"
    },
    {
      "x": 2,
      "y": 1,
      "z": 1,
      "name": "Rock_Stone_Cobble"
    },
    {
      "x": 2,
      "y": -4,
      "z": 2,
      "name": "Soil_Pathway"
    },
    {
      "x": 2,
      "y": -3,
      "z": 2,
      "name": "Soil_Pathway"
    },
    {
      "x": 2,
      "y": -2,
      "z": 2,
      "name": "Soil_Pathway"
    },
    {
      "x": 2,
      "y": -1,
      "z": 2,
      "name": "Soil_Dirt"
    },
    {
      "x": 2,
      "y": 0,
      "z": 2,
      "name": "Soil_Dirt"
    },
    {
      "x": 2,
      "y": 1,
      "z": 2,
      "name": "Rock_Stone_Cobble"
    },
    {
      "x": 2,
      "y": 2,
      "z": 2,
      "name": "Furniture_Human_Ruins_Statue_Broken",
      "rotation": 3
    },
    {
      "x": 2,
      "y": 3,
      "z": 2,
      "name": "Furniture_Human_Ruins_Statue_Broken",
      "filler": 1024,
      "rotation": 3
    },
    {
      "x": 2,
      "y": 4,
      "z": 2,
      "name": "Furniture_Human_Ruins_Statue_Broken",
      "filler": 2048,
      "rotation": 3
    },
    {
      "x": 2,
      "y": -4,
      "z": 3,
      "name": "Soil_Pathway"
    },
    {
      "x": 2,
      "y": -3,
      "z": 3,
      "name": "Soil_Pathway"
    },
    {
      "x": 2,
      "y": -2,
      "z": 3,
      "name": "Soil_Pathway"
    },
    {
      "x": 2,
      "y": -1,
      "z": 3,
      "name": "Soil_Dirt"
    },
    {
      "x": 2,
      "y": 0,
      "z": 3,
      "name": "Soil_Dirt"
    },
    {
      "x": 2,
      "y": 1,
      "z": 3,
      "name": "Rock_Stone_Cobble_Mossy"
    },
    {
      "x": 2,
      "y": -4,
      "z": 4,
      "name": "Soil_Pathway"
    },
    {
      "x": 2,
      "y": -3,
      "z": 4,
      "name": "Soil_Pathway"
    },
    {
      "x": 2,
      "y": -2,
      "z": 4,
      "name": "Soil_Pathway"
    },
    {
      "x": 2,
      "y": -1,
      "z": 4,
      "name": "Soil_Dirt"
    },
    {
      "x": 2,
      "y": 0,
      "z": 4,
      "name": "Soil_Dirt"
    },
    {
      "x": 2,
      "y": 1,
      "z": 4,
      "name": "Rock_Stone_Cobble_Mossy"
    },
    {
      "x": 2,
      "y": 2,
      "z": 4,
      "name": "*Deco_Lantern_State_Definitions_Off"
    },
    {
      "x": 2,
      "y": -4,
      "z": 5,
      "name": "Soil_Pathway"
    },
    {
      "x": 2,
      "y": -3,
      "z": 5,
      "name": "Soil_Pathway"
    },
    {
      "x": 2,
      "y": -2,
      "z": 5,
      "name": "Soil_Pathway"
    },
    {
      "x": 2,
      "y": -1,
      "z": 5,
      "name": "Soil_Pathway"
    },
    {
      "x": 2,
      "y": 0,
      "z": 5,
      "name": "Soil_Pathway"
    },
    {
      "x": 2,
      "y": -4,
      "z": 6,
      "name": "Soil_Pathway"
    },
    {
      "x": 2,
      "y": -3,
      "z": 6,
      "name": "Soil_Pathway"
    },
    {
      "x": 2,
      "y": -2,
      "z": 6,
      "name": "Soil_Pathway"
    },
    {
      "x": 2,
      "y": -1,
      "z": 6,
      "name": "Soil_Pathway"
    },
    {
      "x": 2,
      "y": 0,
      "z": 6,
      "name": "Soil_Pathway"
    },
    {
      "x": 2,
      "y": -4,
      "z": 7,
      "name": "Soil_Pathway"
    },
    {
      "x": 2,
      "y": -3,
      "z": 7,
      "name": "Soil_Pathway"
    },
    {
      "x": 2,
      "y": -2,
      "z": 7,
      "name": "Soil_Pathway"
    },
    {
      "x": 2,
      "y": -1,
      "z": 7,
      "name": "Soil_Pathway"
    },
    {
      "x": 2,
      "y": 0,
      "z": 7,
      "name": "Soil_Pathway"
    },
    {
      "x": 3,
      "y": -4,
      "z": -1,
      "name": "Soil_Pathway"
    },
    {
      "x": 3,
      "y": -3,
      "z": -1,
      "name": "Soil_Pathway"
    },
    {
      "x": 3,
      "y": -2,
      "z": -1,
      "name": "Soil_Pathway"
    },
    {
      "x": 3,
      "y": -1,
      "z": -1,
      "name": "Soil_Pathway"
    },
    {
      "x": 3,
      "y": 0,
      "z": -1,
      "name": "Soil_Pathway"
    },
    {
      "x": 3,
      "y": -4,
      "z": 0,
      "name": "Soil_Pathway"
    },
    {
      "x": 3,
      "y": -3,
      "z": 0,
      "name": "Soil_Pathway"
    },
    {
      "x": 3,
      "y": -2,
      "z": 0,
      "name": "Soil_Pathway"
    },
    {
      "x": 3,
      "y": -1,
      "z": 0,
      "name": "Soil_Pathway"
    },
    {
      "x": 3,
      "y": 0,
      "z": 0,
      "name": "Soil_Pathway"
    },
    {
      "x": 3,
      "y": -4,
      "z": 1,
      "name": "Soil_Pathway"
    },
    {
      "x": 3,
      "y": -3,
      "z": 1,
      "name": "Soil_Pathway"
    },
    {
      "x": 3,
      "y": -2,
      "z": 1,
      "name": "Soil_Pathway"
    },
    {
      "x": 3,
      "y": -1,
      "z": 1,
      "name": "Soil_Pathway"
    },
    {
      "x": 3,
      "y": 0,
      "z": 1,
      "name": "Soil_Pathway"
    },
    {
      "x": 3,
      "y": -4,
      "z": 2,
      "name": "Soil_Pathway"
    },
    {
      "x": 3,
      "y": -3,
      "z": 2,
      "name": "Soil_Pathway"
    },
    {
      "x": 3,
      "y": -2,
      "z": 2,
      "name": "Soil_Pathway"
    },
    {
      "x": 3,
      "y": -1,
      "z": 2,
      "name": "Soil_Dirt"
    },
    {
      "x": 3,
      "y": 0,
      "z": 2,
      "name": "Soil_Dirt"
    },
    {
      "x": 3,
      "y": 1,
      "z": 2,
      "name": "Rubble_Stone",
      "support": 15
    },
    {
      "x": 3,
      "y": -4,
      "z": 3,
      "name": "Soil_Pathway"
    },
    {
      "x": 3,
      "y": -3,
      "z": 3,
      "name": "Soil_Pathway"
    },
    {
      "x": 3,
      "y": -2,
      "z": 3,
      "name": "Soil_Pathway"
    },
    {
      "x": 3,
      "y": -1,
      "z": 3,
      "name": "Soil_Pathway"
    },
    {
      "x": 3,
      "y": 0,
      "z": 3,
      "name": "Soil_Pathway"
    },
    {
      "x": 3,
      "y": -4,
      "z": 4,
      "name": "Soil_Pathway"
    },
    {
      "x": 3,
      "y": -3,
      "z": 4,
      "name": "Soil_Pathway"
    },
    {
      "x": 3,
      "y": -2,
      "z": 4,
      "name": "Soil_Pathway"
    },
    {
      "x": 3,
      "y": -1,
      "z": 4,
      "name": "Soil_Pathway"
    },
    {
      "x": 3,
      "y": 0,
      "z": 4,
      "name": "Soil_Pathway"
    },
    {
      "x": 3,
      "y": -4,
      "z": 5,
      "name": "Soil_Pathway"
    },
    {
      "x": 3,
      "y": -3,
      "z": 5,
      "name": "Soil_Pathway"
    },
    {
      "x": 3,
      "y": -2,
      "z": 5,
      "name": "Soil_Pathway"
    },
    {
      "x": 3,
      "y": -1,
      "z": 5,
      "name": "Soil_Pathway"
    },
    {
      "x": 3,
      "y": 0,
      "z": 5,
      "name": "Soil_Pathway"
    },
    {
      "x": 3,
      "y": -4,
      "z": 6,
      "name": "Soil_Pathway"
    },
    {
      "x": 3,
      "y": -3,
      "z": 6,
      "name": "Soil_Pathway"
    },
    {
      "x": 3,
      "y": -2,
      "z": 6,
      "name": "Soil_Pathway"
    },
    {
      "x": 3,
      "y": -1,
      "z": 6,
      "name": "Soil_Pathway"
    },
    {
      "x": 3,
      "y": 0,
      "z": 6,
      "name": "Soil_Pathway"
    },
    {
      "x": 3,
      "y": -4,
      "z": 7,
      "name": "Soil_Pathway"
    },
    {
      "x": 3,
      "y": -3,
      "z": 7,
      "name": "Soil_Pathway"
    },
    {
      "x": 3,
      "y": -2,
      "z": 7,
      "name": "Soil_Pathway"
    },
    {
      "x": 3,
      "y": -1,
      "z": 7,
      "name": "Soil_Pathway"
    },
    {
      "x": 3,
      "y": 0,
      "z": 7,
      "name": "Soil_Pathway"
    },
    {
      "x": 4,
      "y": -4,
      "z": 0,
      "name": "Soil_Pathway"
    },
    {
      "x": 4,
      "y": -3,
      "z": 0,
      "name": "Soil_Pathway"
    },
    {
      "x": 4,
      "y": -2,
      "z": 0,
      "name": "Soil_Pathway"
    },
    {
      "x": 4,
      "y": -1,
      "z": 0,
      "name": "Soil_Pathway"
    },
    {
      "x": 4,
      "y": 0,
      "z": 0,
      "name": "Soil_Pathway"
    },
    {
      "x": 4,
      "y": -4,
      "z": 1,
      "name": "Soil_Pathway"
    },
    {
      "x": 4,
      "y": -3,
      "z": 1,
      "name": "Soil_Pathway"
    },
    {
      "x": 4,
      "y": -2,
      "z": 1,
      "name": "Soil_Pathway"
    },
    {
      "x": 4,
      "y": -1,
      "z": 1,
      "name": "Soil_Pathway"
    },
    {
      "x": 4,
      "y": 0,
      "z": 1,
      "name": "Soil_Pathway"
    },
    {
      "x": 4,
      "y": -4,
      "z": 2,
      "name": "Soil_Pathway"
    },
    {
      "x": 4,
      "y": -3,
      "z": 2,
      "name": "Soil_Pathway"
    },
    {
      "x": 4,
      "y": -2,
      "z": 2,
      "name": "Soil_Pathway"
    },
    {
      "x": 4,
      "y": -1,
      "z": 2,
      "name": "Soil_Pathway"
    },
    {
      "x": 4,
      "y": 0,
      "z": 2,
      "name": "Soil_Pathway"
    },
    {
      "x": 4,
      "y": -4,
      "z": 3,
      "name": "Soil_Pathway"
    },
    {
      "x": 4,
      "y": -3,
      "z": 3,
      "name": "Soil_Pathway"
    },
    {
      "x": 4,
      "y": -2,
      "z": 3,
      "name": "Soil_Pathway"
    },
    {
      "x": 4,
      "y": -1,
      "z": 3,
      "name": "Soil_Pathway"
    },
    {
      "x": 4,
      "y": 0,
      "z": 3,
      "name": "Soil_Pathway"
    },
    {
      "x": 4,
      "y": -4,
      "z": 4,
      "name": "Soil_Pathway"
    },
    {
      "x": 4,
      "y": -3,
      "z": 4,
      "name": "Soil_Pathway"
    },
    {
      "x": 4,
      "y": -2,
      "z": 4,
      "name": "Soil_Pathway"
    },
    {
      "x": 4,
      "y": -1,
      "z": 4,
      "name": "Soil_Pathway"
    },
    {
      "x": 4,
      "y": 0,
      "z": 4,
      "name": "Soil_Pathway"
    },
    {
      "x": 4,
      "y": -4,
      "z": 5,
      "name": "Soil_Pathway"
    },
    {
      "x": 4,
      "y": -3,
      "z": 5,
      "name": "Soil_Pathway"
    },
    {
      "x": 4,
      "y": -2,
      "z": 5,
      "name": "Soil_Pathway"
    },
    {
      "x": 4,
      "y": -1,
      "z": 5,
      "name": "Soil_Pathway"
    },
    {
      "x": 4,
      "y": 0,
      "z": 5,
      "name": "Soil_Pathway"
    },
    {
      "x": 4,
      "y": -4,
      "z": 6,
      "name": "Soil_Pathway"
    },
    {
      "x": 4,
      "y": -3,
      "z": 6,
      "name": "Soil_Pathway"
    },
    {
      "x": 4,
      "y": -2,
      "z": 6,
      "name": "Soil_Pathway"
    },
    {
      "x": 4,
      "y": -1,
      "z": 6,
      "name": "Soil_Pathway"
    },
    {
      "x": 4,
      "y": 0,
      "z": 6,
      "name": "Soil_Pathway"
    },
    {
      "x": 5,
      "y": -4,
      "z": 0,
      "name": "Soil_Pathway"
    },
    {
      "x": 5,
      "y": -3,
      "z": 0,
      "name": "Soil_Pathway"
    },
    {
      "x": 5,
      "y": -2,
      "z": 0,
      "name": "Soil_Pathway"
    },
    {
      "x": 5,
      "y": -1,
      "z": 0,
      "name": "Soil_Pathway"
    },
    {
      "x": 5,
      "y": 0,
      "z": 0,
      "name": "Soil_Pathway"
    },
    {
      "x": 5,
      "y": -4,
      "z": 1,
      "name": "Soil_Pathway"
    },
    {
      "x": 5,
      "y": -3,
      "z": 1,
      "name": "Soil_Pathway"
    },
    {
      "x": 5,
      "y": -2,
      "z": 1,
      "name": "Soil_Pathway"
    },
    {
      "x": 5,
      "y": -1,
      "z": 1,
      "name": "Soil_Pathway"
    },
    {
      "x": 5,
      "y": 0,
      "z": 1,
      "name": "Soil_Pathway"
    },
    {
      "x": 5,
      "y": -4,
      "z": 2,
      "name": "Soil_Pathway"
    },
    {
      "x": 5,
      "y": -3,
      "z": 2,
      "name": "Soil_Pathway"
    },
    {
      "x": 5,
      "y": -2,
      "z": 2,
      "name": "Soil_Pathway"
    },
    {
      "x": 5,
      "y": -1,
      "z": 2,
      "name": "Soil_Pathway"
    },
    {
      "x": 5,
      "y": 0,
      "z": 2,
      "name": "Soil_Pathway"
    },
    {
      "x": 5,
      "y": -4,
      "z": 3,
      "name": "Soil_Pathway"
    },
    {
      "x": 5,
      "y": -3,
      "z": 3,
      "name": "Soil_Pathway"
    },
    {
      "x": 5,
      "y": -2,
      "z": 3,
      "name": "Soil_Pathway"
    },
    {
      "x": 5,
      "y": -1,
      "z": 3,
      "name": "Soil_Pathway"
    },
    {
      "x": 5,
      "y": 0,
      "z": 3,
      "name": "Soil_Pathway"
    },
    {
      "x": 5,
      "y": -4,
      "z": 4,
      "name": "Soil_Pathway"
    },
    {
      "x": 5,
      "y": -3,
      "z": 4,
      "name": "Soil_Pathway"
    },
    {
      "x": 5,
      "y": -2,
      "z": 4,
      "name": "Soil_Pathway"
    },
    {
      "x": 5,
      "y": -1,
      "z": 4,
      "name": "Soil_Pathway"
    },
    {
      "x": 5,
      "y": 0,
      "z": 4,
      "name": "Soil_Pathway"
    },
    {
      "x": 5,
      "y": -4,
      "z": 5,
      "name": "Soil_Pathway"
    },
    {
      "x": 5,
      "y": -3,
      "z": 5,
      "name": "Soil_Pathway"
    },
    {
      "x": 5,
      "y": -2,
      "z": 5,
      "name": "Soil_Pathway"
    },
    {
      "x": 5,
      "y": -1,
      "z": 5,
      "name": "Soil_Pathway"
    },
    {
      "x": 5,
      "y": 0,
      "z": 5,
      "name": "Soil_Pathway"
    },
    {
      "x": 5,
      "y": -4,
      "z": 6,
      "name": "Soil_Pathway"
    },
    {
      "x": 5,
      "y": -3,
      "z": 6,
      "name": "Soil_Pathway"
    },
    {
      "x": 5,
      "y": -2,
      "z": 6,
      "name": "Soil_Pathway"
    },
    {
      "x": 5,
      "y": -1,
      "z": 6,
      "name": "Soil_Pathway"
    },
    {
      "x": 5,
      "y": 0,
      "z": 6,
      "name": "Soil_Pathway"
    },
    {
      "x": 6,
      "y": -4,
      "z": 2,
      "name": "Soil_Pathway"
    },
    {
      "x": 6,
      "y": -3,
      "z": 2,
      "name": "Soil_Pathway"
    },
    {
      "x": 6,
      "y": -2,
      "z": 2,
      "name": "Soil_Pathway"
    },
    {
      "x": 6,
      "y": -1,
      "z": 2,
      "name": "Soil_Pathway"
    },
    {
      "x": 6,
      "y": 0,
      "z": 2,
      "name": "Soil_Pathway"
    },
    {
      "x": 6,
      "y": -4,
      "z": 3,
      "name": "Soil_Pathway"
    },
    {
      "x": 6,
      "y": -3,
      "z": 3,
      "name": "Soil_Pathway"
    },
    {
      "x": 6,
      "y": -2,
      "z": 3,
      "name": "Soil_Pathway"
    },
    {
      "x": 6,
      "y": -1,
      "z": 3,
      "name": "Soil_Pathway"
    },
    {
      "x": 6,
      "y": 0,
      "z": 3,
      "name": "Soil_Pathway"
    },
    {
      "x": 6,
      "y": -4,
      "z": 4,
      "name": "Soil_Pathway"
    },
    {
      "x": 6,
      "y": -3,
      "z": 4,
      "name": "Soil_Pathway"
    },
    {
      "x": 6,
      "y": -2,
      "z": 4,
      "name": "Soil_Pathway"
    },
    {
      "x": 6,
      "y": -1,
      "z": 4,
      "name": "Soil_Pathway"
    },
    {
      "x": 6,
      "y": 0,
      "z": 4,
      "name": "Soil_Pathway"
    }
  ]
}