{
  "version": 8,
  "blockIdVersion": 11,
  "anchorX": 0,
  "anchorY": 1,
  "anchorZ": 0,
  "blocks": [
    {
      "x": -12,
      "y": 1,
      "z": -8,
      "name": "Cloth_Block_Wool_Cyan"
    },
    {
      "x": -12,
      "y": 2,
      "z": -8,
      "name": "Cloth_Block_Wool_Cyan"
    },
    {
      "x": -12,
      "y": 3,
      "z": -8,
      "name": "Cloth_Block_Wool_Cyan"
    },
    {
      "x": -12,
      "y": 4,
      "z": -8,
      "name": "Cloth_Block_Wool_Cyan"
    },
    {
      "x": -12,
      "y": 5,
      "z": -8,
      "name": "Cloth_Block_Wool_Cyan"
    },
    {
      "x": -12,
      "y": 6,
      "z": -8,
      "name": "Cloth_Block_Wool_Cyan"
    },
    {
      "x": -12,
      "y": 7,
      "z": -8,
      "name": "Cloth_Block_Wool_Cyan"
    },
    {
      "x": -12,
      "y": 8,
      "z": -8,
      "name": "Cloth_Block_Wool_Cyan"
    },
    {
      "x": -12,
      "y": 9,
      "z": -8,
      "name": "Cloth_Block_Wool_Cyan"
    },
    {
      "x": -12,
      "y": 10,
      "z": -8,
      "name": "Cloth_Block_Wool_Cyan"
    },
    {
      "x": -12,
      "y": 11,
      "z": -8,
      "name": "Cloth_Block_Wool_Cyan"
    },
    {
      "x": -12,
      "y": 12,
      "z": -8,
      "name": "Cloth_Block_Wool_Cyan"
    },
    {
      "x": -12,
      "y": 13,
      "z": -8,
      "name": "Cloth_Block_Wool_Cyan"
    },
    {
      "x": -12,
      "y": 14,
      "z": -8,
      "name": "Cloth_Block_Wool_Cyan"
    },
    {
      "x": -12,
      "y": 15,
      "z": -8,
      "name": "Cloth_Block_Wool_Cyan"
    },
    {
      "x": -12,
      "y": 16,
      "z": -8,
      "name": "Cloth_Block_Wool_Cyan"
    },
    {
      "x": -12,
      "y": 17,
      "z": -8,
      "name": "Cloth_Block_Wool_Cyan"
    },
    {
      "x": -12,
      "y": 18,
      "z": -8,
      "name": "Cloth_Block_Wool_Cyan"
    },
    {
      "x": -12,
      "y": 19,
      "z": -8,
      "name": "Cloth_Block_Wool_Cyan"
    },
    {
      "x": -12,
      "y": 20,
      "z": -8,
      "name": "Cloth_Block_Wool_Cyan"
    },
    {
      "x": -12,
      "y": 21,
      "z": -8,
      "name": "Cloth_Block_Wool_Cyan"
    },
    {
      "x": -12,
      "y": 22,
      "z": -8,
      "name": "Cloth_Block_Wool_Cyan"
    },
    {
      "x": -12,
      "y": 23,
      "z": -8,
      "name": "Cloth_Block_Wool_Cyan"
    },
    {
      "x": -12,
      "y": 24,
      "z": -8,
      "name": "Cloth_Block_Wool_Cyan"
    },
    {
      "x": -12,
      "y": 25,
      "z": -8,
      "name": "Cloth_Block_Wool_Cyan"
    },
    {
      "x": -12,
      "y": 26,
      "z": -8,
      "name": "Cloth_Block_Wool_Cyan"
    },
    {
      "x": -12,
      "y": 1,
      "z": -7,
      "name": "Cloth_Block_Wool_Cyan"
    },
    {
      "x": -12,
      "y": 2,
      "z": -7,
      "name": "Cloth_Block_Wool_Cyan"
    },
    {
      "x": -12,
      "y": 3,
      "z": -7,
      "name": "Cloth_Block_Wool_Cyan"
    },
    {
      "x": -12,
      "y": 4,
      "z": -7,
      "name": "Cloth_Block_Wool_Cyan"
    },
    {
      "x": -12,
      "y": 5,
      "z": -7,
      "name": "Cloth_Block_Wool_Cyan"
    },
    {
      "x": -12,
      "y": 6,
      "z": -7,
      "name": "Cloth_Block_Wool_Cyan"
    },
    {
      "x": -12,
      "y": 7,
      "z": -7,
      "name": "Cloth_Block_Wool_Cyan"
    },
    {
      "x": -12,
      "y": 8,
      "z": -7,
      "name": "Cloth_Block_Wool_Cyan"
    },
    {
      "x": -12,
      "y": 9,
      "z": -7,
      "name": "Cloth_Block_Wool_Cyan"
    },
    {
      "x": -12,
      "y": 10,
      "z": -7,
      "name": "Cloth_Block_Wool_Cyan"
    },
    {
      "x": -12,
      "y": 11,
      "z": -7,
      "name": "Cloth_Block_Wool_Cyan"
    },
    {
      "x": -12,
      "y": 12,
      "z": -7,
      "name": "Cloth_Block_Wool_Cyan"
    },
    {
      "x": -12,
      "y": 13,
      "z": -7,
      "name": "Cloth_Block_Wool_Cyan"
    },
    {
      "x": -12,
      "y": 14,
      "z": -7,
      "name": "Cloth_Block_Wool_Cyan"
    },
    {
      "x": -12,
      "y": 15,
      "z": -7,
      "name": "Cloth_Block_Wool_Cyan"
    },
    {
      "x": -12,
      "y": 16,
      "z": -7,
      "name": "Cloth_Block_Wool_Cyan"
    },
    {
      "x": -12,
      "y": 17,
      "z": -7,
      "name": "Cloth_Block_Wool_Cyan"
    },
    {
      "x": -12,
      "y": 18,
      "z": -7,
      "name": "Cloth_Block_Wool_Cyan"
    },
    {
      "x": -12,
      "y": 19,
      "z": -7,
      "name": "Cloth_Block_Wool_Cyan"
    },
    {
      "x": -12,
      "y": 20,
      "z": -7,
      "name": "Cloth_Block_Wool_Cyan"
    },
    {
      "x": -12,
      "y": 21,
      "z": -7,
      "name": "Cloth_Block_Wool_Cyan"
    },
    {
      "x": -12,
      "y": 22,
      "z": -7,
      "name": "Cloth_Block_Wool_Cyan"
    },
    {
      "x": -12,
      "y": 23,
      "z": -7,
      "name": "Cloth_Block_Wool_Cyan"
    },
    {
      "x": -12,
      "y": 24,
      "z": -7,
      "name": "Cloth_Block_Wool_Cyan"
    },
    {
      "x": -12,
      "y": 25,
      "z": -7,
      "name": "Cloth_Block_Wool_Cyan"
    },
    {
      "x": -12,
      "y": 26,
      "z": -7,
      "name": "Cloth_Block_Wool_Cyan"
    },
    {
      "x": -12,
      "y": 1,
      "z": -6,
      "name": "Cloth_Block_Wool_Cyan"
    },
    {
      "x": -12,
      "y": 2,
      "z": -6,
      "name": "Cloth_Block_Wool_Cyan"
    },
    {
      "x": -12,
      "y": 3,
      "z": -6,
      "name": "Cloth_Block_Wool_Cyan"
    },
    {
      "x": -12,
      "y": 4,
      "z": -6,
      "name": "Cloth_Block_Wool_Cyan"
    },
    {
      "x": -12,
      "y": 5,
      "z": -6,
      "name": "Cloth_Block_Wool_Cyan"
    },
    {
      "x": -12,
      "y": 6,
      "z": -6,
      "name": "Cloth_Block_Wool_Cyan"
    },
    {
      "x": -12,
      "y": 7,
      "z": -6,
      "name": "Cloth_Block_Wool_Cyan"
    },
    {
      "x": -12,
      "y": 8,
      "z": -6,
      "name": "Cloth_Block_Wool_Cyan"
    },
    {
      "x": -12,
      "y": 9,
      "z": -6,
      "name": "Cloth_Block_Wool_Cyan"
    },
    {
      "x": -12,
      "y": 10,
      "z": -6,
      "name": "Cloth_Block_Wool_Cyan"
    },
    {
      "x": -12,
      "y": 11,
      "z": -6,
      "name": "Cloth_Block_Wool_Cyan"
    },
    {
      "x": -12,
      "y": 12,
      "z": -6,
      "name": "Cloth_Block_Wool_Cyan"
    },
    {
      "x": -12,
      "y": 13,
      "z": -6,
      "name": "Cloth_Block_Wool_Cyan"
    },
    {
      "x": -12,
      "y": 14,
      "z": -6,
      "name": "Cloth_Block_Wool_Cyan"
    },
    {
      "x": -12,
      "y": 15,
      "z": -6,
      "name": "Cloth_Block_Wool_Cyan"
    },
    {
      "x": -12,
      "y": 16,
      "z": -6,
      "name": "Cloth_Block_Wool_Cyan"
    },
    {
      "x": -12,
      "y": 17,
      "z": -6,
      "name": "Cloth_Block_Wool_Cyan"
    },
    {
      "x": -12,
      "y": 18,
      "z": -6,
      "name": "Cloth_Block_Wool_Cyan"
    },
    {
      "x": -12,
      "y": 19,
      "z": -6,
      "name": "Cloth_Block_Wool_Cyan"
    },
    {
      "x": -12,
      "y": 20,
      "z": -6,
      "name": "Cloth_Block_Wool_Cyan"
    },
    {
      "x": -12,
      "y": 21,
      "z": -6,
      "name": "Cloth_Block_Wool_Cyan"
    },
    {
      "x": -12,
      "y": 22,
      "z": -6,
      "name": "Cloth_Block_Wool_Cyan"
    },
    {
      "x": -12,
      "y": 23,
      "z": -6,
      "name": "Cloth_Block_Wool_Cyan"
    },
    {
      "x": -12,
      "y": 24,
      "z": -6,
      "name": "Cloth_Block_Wool_Cyan"
    },
    {
      "x": -12,
      "y": 25,
      "z": -6,
      "name": "Cloth_Block_Wool_Cyan"
    },
    {
      "x": -12,
      "y": 26,
      "z": -6,
      "name": "Cloth_Block_Wool_Cyan"
    },
    {
      "x": -12,
      "y": 1,
      "z": -5,
      "name": "Cloth_Block_Wool_Cyan"
    },
    {
      "x": -12,
      "y": 2,
      "z": -5,
      "name": "Cloth_Block_Wool_Cyan"
    },
    {
      "x": -12,
      "y": 3,
      "z": -5,
      "name": "Cloth_Block_Wool_Cyan"
    },
    {
      "x": -12,
      "y": 4,
      "z": -5,
      "name": "Cloth_Block_Wool_Cyan"
    },
    {
      "x": -12,
      "y": 5,
      "z": -5,
      "name": "Cloth_Block_Wool_Cyan"
    },
    {
      "x": -12,
      "y": 6,
      "z": -5,
      "name": "Cloth_Block_Wool_Cyan"
    },
    {
      "x": -12,
      "y": 7,
      "z": -5,
      "name": "Cloth_Block_Wool_Cyan"
    },
    {
      "x": -12,
      "y": 8,
      "z": -5,
      "name": "Cloth_Block_Wool_Cyan"
    },
    {
      "x": -12,
      "y": 9,
      "z": -5,
      "name": "Cloth_Block_Wool_Cyan"
    },
    {
      "x": -12,
      "y": 10,
      "z": -5,
      "name": "Cloth_Block_Wool_Cyan"
    },
    {
      "x": -12,
      "y": 11,
      "z": -5,
      "name": "Cloth_Block_Wool_Cyan"
    },
    {
      "x": -12,
      "y": 12,
      "z": -5,
      "name": "Cloth_Block_Wool_Cyan"
    },
    {
      "x": -12,
      "y": 13,
      "z": -5,
      "name": "Cloth_Block_Wool_Cyan"
    },
    {
      "x": -12,
      "y": 14,
      "z": -5,
      "name": "Cloth_Block_Wool_Cyan"
    },
    {
      "x": -12,
      "y": 15,
      "z": -5,
      "name": "Cloth_Block_Wool_Cyan"
    },
    {
      "x": -12,
      "y": 16,
      "z": -5,
      "name": "Cloth_Block_Wool_Cyan"
    },
    {
      "x": -12,
      "y": 17,
      "z": -5,
      "name": "Cloth_Block_Wool_Cyan"
    },
    {
      "x": -12,
      "y": 18,
      "z": -5,
      "name": "Cloth_Block_Wool_Cyan"
    },
    {
      "x": -12,
      "y": 19,
      "z": -5,
      "name": "Cloth_Block_Wool_Cyan"
    },
    {
      "x": -12,
      "y": 20,
      "z": -5,
      "name": "Cloth_Block_Wool_Cyan"
    },
    {
      "x": -12,
      "y": 21,
      "z": -5,
      "name": "Cloth_Block_Wool_Cyan"
    },
    {
      "x": -12,
      "y": 22,
      "z": -5,
      "name": "Cloth_Block_Wool_Cyan"
    },
    {
      "x": -12,
      "y": 23,
      "z": -5,
      "name": "Cloth_Block_Wool_Cyan"
    },
    {
      "x": -12,
      "y": 24,
      "z": -5,
      "name": "Cloth_Block_Wool_Cyan"
    },
    {
      "x": -12,
      "y": 25,
      "z": -5,
      "name": "Cloth_Block_Wool_Cyan"
    },
    {
      "x": -12,
      "y": 26,
      "z": -5,
      "name": "Cloth_Block_Wool_Cyan"
    },
    {
      "x": -12,
      "y": 1,
      "z": -4,
      "name": "Cloth_Block_Wool_Cyan"
    },
    {
      "x": -12,
      "y": 2,
      "z": -4,
      "name": "Cloth_Block_Wool_Cyan"
    },
    {
      "x": -12,
      "y": 3,
      "z": -4,
      "name": "Cloth_Block_Wool_Cyan"
    },
    {
      "x": -12,
      "y": 4,
      "z": -4,
      "name": "Cloth_Block_Wool_Cyan"
    },
    {
      "x": -12,
      "y": 5,
      "z": -4,
      "name": "Cloth_Block_Wool_Cyan"
    },
    {
      "x": -12,
      "y": 6,
      "z": -4,
      "name": "Cloth_Block_Wool_Cyan"
    },
    {
      "x": -12,
      "y": 7,
      "z": -4,
      "name": "Cloth_Block_Wool_Cyan"
    },
    {
      "x": -12,
      "y": 8,
      "z": -4,
      "name": "Cloth_Block_Wool_Cyan"
    },
    {
      "x": -12,
      "y": 9,
      "z": -4,
      "name": "Cloth_Block_Wool_Cyan"
    },
    {
      "x": -12,
      "y": 10,
      "z": -4,
      "name": "Cloth_Block_Wool_Cyan"
    },
    {
      "x": -12,
      "y": 11,
      "z": -4,
      "name": "Cloth_Block_Wool_Cyan"
    },
    {
      "x": -12,
      "y": 12,
      "z": -4,
      "name": "Cloth_Block_Wool_Cyan"
    },
    {
      "x": -12,
      "y": 13,
      "z": -4,
      "name": "Cloth_Block_Wool_Cyan"
    },
    {
      "x": -12,
      "y": 14,
      "z": -4,
      "name": "Cloth_Block_Wool_Cyan"
    },
    {
      "x": -12,
      "y": 15,
      "z": -4,
      "name": "Cloth_Block_Wool_Cyan"
    },
    {
      "x": -12,
      "y": 16,
      "z": -4,
      "name": "Cloth_Block_Wool_Cyan"
    },
    {
      "x": -12,
      "y": 17,
      "z": -4,
      "name": "Cloth_Block_Wool_Cyan"
    },
    {
      "x": -12,
      "y": 18,
      "z": -4,
      "name": "Cloth_Block_Wool_Cyan"
    },
    {
      "x": -12,
      "y": 19,
      "z": -4,
      "name": "Cloth_Block_Wool_Cyan"
    },
    {
      "x": -12,
      "y": 20,
      "z": -4,
      "name": "Cloth_Block_Wool_Cyan"
    },
    {
      "x": -12,
      "y": 21,
      "z": -4,
      "name": "Cloth_Block_Wool_Cyan"
    },
    {
      "x": -12,
      "y": 22,
      "z": -4,
      "name": "Cloth_Block_Wool_Cyan"
    },
    {
      "x": -12,
      "y": 23,
      "z": -4,
      "name": "Cloth_Block_Wool_Cyan"
    },
    {
      "x": -12,
      "y": 24,
      "z": -4,
      "name": "Cloth_Block_Wool_Cyan"
    },
    {
      "x": -12,
      "y": 25,
      "z": -4,
      "name": "Cloth_Block_Wool_Cyan"
    },
    {
      "x": -12,
      "y": 26,
      "z": -4,
      "name": "Cloth_Block_Wool_Cyan"
    },
    {
      "x": -12,
      "y": 1,
      "z": -3,
      "name": "Cloth_Block_Wool_Cyan"
    },
    {
      "x": -12,
      "y": 2,
      "z": -3,
      "name": "Cloth_Block_Wool_Cyan"
    },
    {
      "x": -12,
      "y": 3,
      "z": -3,
      "name": "Cloth_Block_Wool_Cyan"
    },
    {
      "x": -12,
      "y": 4,
      "z": -3,
      "name": "Cloth_Block_Wool_Cyan"
    },
    {
      "x": -12,
      "y": 5,
      "z": -3,
      "name": "Cloth_Block_Wool_Cyan"
    },
    {
      "x": -12,
      "y": 6,
      "z": -3,
      "name": "Cloth_Block_Wool_Cyan"
    },
    {
      "x": -12,
      "y": 7,
      "z": -3,
      "name": "Cloth_Block_Wool_Cyan"
    },
    {
      "x": -12,
      "y": 8,
      "z": -3,
      "name": "Cloth_Block_Wool_Cyan"
    },
    {
      "x": -12,
      "y": 9,
      "z": -3,
      "name": "Cloth_Block_Wool_Cyan"
    },
    {
      "x": -12,
      "y": 10,
      "z": -3,
      "name": "Cloth_Block_Wool_Cyan"
    },
    {
      "x": -12,
      "y": 11,
      "z": -3,
      "name": "Cloth_Block_Wool_Cyan"
    },
    {
      "x": -12,
      "y": 12,
      "z": -3,
      "name": "Cloth_Block_Wool_Cyan"
    },
    {
      "x": -12,
      "y": 13,
      "z": -3,
      "name": "Cloth_Block_Wool_Cyan"
    },
    {
      "x": -12,
      "y": 14,
      "z": -3,
      "name": "Cloth_Block_Wool_Cyan"
    },
    {
      "x": -12,
      "y": 15,
      "z": -3,
      "name": "Cloth_Block_Wool_Cyan"
    },
    {
      "x": -12,
      "y": 16,
      "z": -3,
      "name": "Cloth_Block_Wool_Cyan"
    },
    {
      "x": -12,
      "y": 17,
      "z": -3,
      "name": "Cloth_Block_Wool_Cyan"
    },
    {
      "x": -12,
      "y": 18,
      "z": -3,
      "name": "Cloth_Block_Wool_Cyan"
    },
    {
      "x": -12,
      "y": 19,
      "z": -3,
      "name": "Cloth_Block_Wool_Cyan"
    },
    {
      "x": -12,
      "y": 20,
      "z": -3,
      "name": "Cloth_Block_Wool_Cyan"
    },
    {
      "x": -12,
      "y": 21,
      "z": -3,
      "name": "Cloth_Block_Wool_Cyan"
    },
    {
      "x": -12,
      "y": 22,
      "z": -3,
      "name": "Cloth_Block_Wool_Cyan"
    },
    {
      "x": -12,
      "y": 23,
      "z": -3,
      "name": "Cloth_Block_Wool_Cyan"
    },
    {
      "x": -12,
      "y": 24,
      "z": -3,
      "name": "Cloth_Block_Wool_Cyan"
    },
    {
      "x": -12,
      "y": 25,
      "z": -3,
      "name": "Cloth_Block_Wool_Cyan"
    },
    {
      "x": -12,
      "y": 26,
      "z": -3,
      "name": "Cloth_Block_Wool_Cyan"
    },
    {
      "x": -12,
      "y": 1,
      "z": -2,
      "name": "Cloth_Block_Wool_Cyan"
    },
    {
      "x": -12,
      "y": 2,
      "z": -2,
      "name": "Cloth_Block_Wool_Cyan"
    },
    {
      "x": -12,
      "y": 3,
      "z": -2,
      "name": "Cloth_Block_Wool_Cyan"
    },
    {
      "x": -12,
      "y": 4,
      "z": -2,
      "name": "Cloth_Block_Wool_Cyan"
    },
    {
      "x": -12,
      "y": 5,
      "z": -2,
      "name": "Cloth_Block_Wool_Cyan"
    },
    {
      "x": -12,
      "y": 6,
      "z": -2,
      "name": "Cloth_Block_Wool_Cyan"
    },
    {
      "x": -12,
      "y": 7,
      "z": -2,
      "name": "Cloth_Block_Wool_Cyan"
    },
    {
      "x": -12,
      "y": 8,
      "z": -2,
      "name": "Cloth_Block_Wool_Cyan"
    },
    {
      "x": -12,
      "y": 9,
      "z": -2,
      "name": "Cloth_Block_Wool_Cyan"
    },
    {
      "x": -12,
      "y": 10,
      "z": -2,
      "name": "Cloth_Block_Wool_Cyan"
    },
    {
      "x": -12,
      "y": 11,
      "z": -2,
      "name": "Cloth_Block_Wool_Cyan"
    },
    {
      "x": -12,
      "y": 12,
      "z": -2,
      "name": "Cloth_Block_Wool_Cyan"
    },
    {
      "x": -12,
      "y": 13,
      "z": -2,
      "name": "Cloth_Block_Wool_Cyan"
    },
    {
      "x": -12,
      "y": 14,
      "z": -2,
      "name": "Cloth_Block_Wool_Cyan"
    },
    {
      "x": -12,
      "y": 15,
      "z": -2,
      "name": "Cloth_Block_Wool_Cyan"
    },
    {
      "x": -12,
      "y": 16,
      "z": -2,
      "name": "Cloth_Block_Wool_Cyan"
    },
    {
      "x": -12,
      "y": 17,
      "z": -2,
      "name": "Cloth_Block_Wool_Cyan"
    },
    {
      "x": -12,
      "y": 18,
      "z": -2,
      "name": "Cloth_Block_Wool_Cyan"
    },
    {
      "x": -12,
      "y": 19,
      "z": -2,
      "name": "Cloth_Block_Wool_Cyan"
    },
    {
      "x": -12,
      "y": 20,
      "z": -2,
      "name": "Cloth_Block_Wool_Cyan"
    },
    {
      "x": -12,
      "y": 21,
      "z": -2,
      "name": "Cloth_Block_Wool_Cyan"
    },
    {
      "x": -12,
      "y": 22,
      "z": -2,
      "name": "Cloth_Block_Wool_Cyan"
    },
    {
      "x": -12,
      "y": 23,
      "z": -2,
      "name": "Cloth_Block_Wool_Cyan"
    },
    {
      "x": -12,
      "y": 24,
      "z": -2,
      "name": "Cloth_Block_Wool_Cyan"
    },
    {
      "x": -12,
      "y": 25,
      "z": -2,
      "name": "Cloth_Block_Wool_Cyan"
    },
    {
      "x": -12,
      "y": 26,
      "z": -2,
      "name": "Cloth_Block_Wool_Cyan"
    },
    {
      "x": -12,
      "y": 1,
      "z": -1,
      "name": "Cloth_Block_Wool_Cyan"
    },
    {
      "x": -12,
      "y": 2,
      "z": -1,
      "name": "Cloth_Block_Wool_Cyan"
    },
    {
      "x": -12,
      "y": 3,
      "z": -1,
      "name": "Cloth_Block_Wool_Cyan"
    },
    {
      "x": -12,
      "y": 4,
      "z": -1,
      "name": "Cloth_Block_Wool_Cyan"
    },
    {
      "x": -12,
      "y": 5,
      "z": -1,
      "name": "Cloth_Block_Wool_Cyan"
    },
    {
      "x": -12,
      "y": 6,
      "z": -1,
      "name": "Cloth_Block_Wool_Cyan"
    },
    {
      "x": -12,
      "y": 7,
      "z": -1,
      "name": "Cloth_Block_Wool_Cyan"
    },
    {
      "x": -12,
      "y": 8,
      "z": -1,
      "name": "Cloth_Block_Wool_Cyan"
    },
    {
      "x": -12,
      "y": 9,
      "z": -1,
      "name": "Cloth_Block_Wool_Cyan"
    },
    {
      "x": -12,
      "y": 10,
      "z": -1,
      "name": "Cloth_Block_Wool_Cyan"
    },
    {
      "x": -12,
      "y": 11,
      "z": -1,
      "name": "Cloth_Block_Wool_Cyan"
    },
    {
      "x": -12,
      "y": 12,
      "z": -1,
      "name": "Cloth_Block_Wool_Cyan"
    },
    {
      "x": -12,
      "y": 13,
      "z": -1,
      "name": "Cloth_Block_Wool_Cyan"
    },
    {
      "x": -12,
      "y": 14,
      "z": -1,
      "name": "Cloth_Block_Wool_Cyan"
    },
    {
      "x": -12,
      "y": 15,
      "z": -1,
      "name": "Cloth_Block_Wool_Cyan"
    },
    {
      "x": -12,
      "y": 16,
      "z": -1,
      "name": "Cloth_Block_Wool_Cyan"
    },
    {
      "x": -12,
      "y": 17,
      "z": -1,
      "name": "Cloth_Block_Wool_Cyan"
    },
    {
      "x": -12,
      "y": 18,
      "z": -1,
      "name": "Cloth_Block_Wool_Cyan"
    },
    {
      "x": -12,
      "y": 19,
      "z": -1,
      "name": "Cloth_Block_Wool_Cyan"
    },
    {
      "x": -12,
      "y": 20,
      "z": -1,
      "name": "Cloth_Block_Wool_Cyan"
    },
    {
      "x": -12,
      "y": 21,
      "z": -1,
      "name": "Cloth_Block_Wool_Cyan"
    },
    {
      "x": -12,
      "y": 22,
      "z": -1,
      "name": "Cloth_Block_Wool_Cyan"
    },
    {
      "x": -12,
      "y": 23,
      "z": -1,
      "name": "Cloth_Block_Wool_Cyan"
    },
    {
      "x": -12,
      "y": 24,
      "z": -1,
      "name": "Cloth_Block_Wool_Cyan"
    },
    {
      "x": -12,
      "y": 25,
      "z": -1,
      "name": "Cloth_Block_Wool_Cyan"
    },
    {
      "x": -12,
      "y": 26,
      "z": -1,
      "name": "Cloth_Block_Wool_Cyan"
    },
    {
      "x": -11,
      "y": 1,
      "z": -8,
      "name": "Cloth_Block_Wool_Cyan"
    },
    {
      "x": -11,
      "y": 2,
      "z": -8,
      "name": "Cloth_Block_Wool_Cyan"
    },
    {
      "x": -11,
      "y": 3,
      "z": -8,
      "name": "Cloth_Block_Wool_Cyan"
    },
    {
      "x": -11,
      "y": 4,
      "z": -8,
      "name": "Cloth_Block_Wool_Cyan"
    },
    {
      "x": -11,
      "y": 5,
      "z": -8,
      "name": "Cloth_Block_Wool_Cyan"
    },
    {
      "x": -11,
      "y": 6,
      "z": -8,
      "name": "Cloth_Block_Wool_Cyan"
    },
    {
      "x": -11,
      "y": 7,
      "z": -8,
      "name": "Cloth_Block_Wool_Cyan"
    },
    {
      "x": -11,
      "y": 8,
      "z": -8,
      "name": "Cloth_Block_Wool_Cyan"
    },
    {
      "x": -11,
      "y": 9,
      "z": -8,
      "name": "Cloth_Block_Wool_Cyan"
    },
    {
      "x": -11,
      "y": 10,
      "z": -8,
      "name": "Cloth_Block_Wool_Cyan"
    },
    {
      "x": -11,
      "y": 11,
      "z": -8,
      "name": "Cloth_Block_Wool_Cyan"
    },
    {
      "x": -11,
      "y": 12,
      "z": -8,
      "name": "Cloth_Block_Wool_Cyan"
    },
    {
      "x": -11,
      "y": 13,
      "z": -8,
      "name": "Cloth_Block_Wool_Cyan"
    },
    {
      "x": -11,
      "y": 14,
      "z": -8,
      "name": "Cloth_Block_Wool_Cyan"
    },
    {
      "x": -11,
      "y": 15,
      "z": -8,
      "name": "Cloth_Block_Wool_Cyan"
    },
    {
      "x": -11,
      "y": 16,
      "z": -8,
      "name": "Cloth_Block_Wool_Cyan"
    },
    {
      "x": -11,
      "y": 17,
      "z": -8,
      "name": "Cloth_Block_Wool_Cyan"
    },
    {
      "x": -11,
      "y": 18,
      "z": -8,
      "name": "Cloth_Block_Wool_Cyan"
    },
    {
      "x": -11,
      "y": 19,
      "z": -8,
      "name": "Cloth_Block_Wool_Cyan"
    },
    {
      "x": -11,
      "y": 20,
      "z": -8,
      "name": "Cloth_Block_Wool_Cyan"
    },
    {
      "x": -11,
      "y": 21,
      "z": -8,
      "name": "Cloth_Block_Wool_Cyan"
    },
    {
      "x": -11,
      "y": 22,
      "z": -8,
      "name": "Cloth_Block_Wool_Cyan"
    },
    {
      "x": -11,
      "y": 23,
      "z": -8,
      "name": "Cloth_Block_Wool_Cyan"
    },
    {
      "x": -11,
      "y": 24,
      "z": -8,
      "name": "Cloth_Block_Wool_Cyan"
    },
    {
      "x": -11,
      "y": 25,
      "z": -8,
      "name": "Cloth_Block_Wool_Cyan"
    },
    {
      "x": -11,
      "y": 26,
      "z": -8,
      "name": "Cloth_Block_Wool_Cyan"
    },
    {
      "x": -11,
      "y": 1,
      "z": -7,
      "name": "Cloth_Block_Wool_Cyan"
    },
    {
      "x": -11,
      "y": 2,
      "z": -7,
      "name": "Cloth_Block_Wool_Cyan"
    },
    {
      "x": -11,
      "y": 3,
      "z": -7,
      "name": "Cloth_Block_Wool_Cyan"
    },
    {
      "x": -11,
      "y": 4,
      "z": -7,
      "name": "Cloth_Block_Wool_Cyan"
    },
    {
      "x": -11,
      "y": 5,
      "z": -7,
      "name": "Cloth_Block_Wool_Cyan"
    },
    {
      "x": -11,
      "y": 6,
      "z": -7,
      "name": "Cloth_Block_Wool_Cyan"
    },
    {
      "x": -11,
      "y": 7,
      "z": -7,
      "name": "Cloth_Block_Wool_Cyan"
    },
    {
      "x": -11,
      "y": 8,
      "z": -7,
      "name": "Cloth_Block_Wool_Cyan"
    },
    {
      "x": -11,
      "y": 9,
      "z": -7,
      "name": "Cloth_Block_Wool_Cyan"
    },
    {
      "x": -11,
      "y": 10,
      "z": -7,
      "name": "Cloth_Block_Wool_Cyan"
    },
    {
      "x": -11,
      "y": 11,
      "z": -7,
      "name": "Cloth_Block_Wool_Cyan"
    },
    {
      "x": -11,
      "y": 12,
      "z": -7,
      "name": "Cloth_Block_Wool_Cyan"
    },
    {
      "x": -11,
      "y": 13,
      "z": -7,
      "name": "Cloth_Block_Wool_Cyan"
    },
    {
      "x": -11,
      "y": 14,
      "z": -7,
      "name": "Cloth_Block_Wool_Cyan"
    },
    {
      "x": -11,
      "y": 15,
      "z": -7,
      "name": "Cloth_Block_Wool_Cyan"
    },
    {
      "x": -11,
      "y": 16,
      "z": -7,
      "name": "Cloth_Block_Wool_Cyan"
    },
    {
      "x": -11,
      "y": 17,
      "z": -7,
      "name": "Cloth_Block_Wool_Cyan"
    },
    {
      "x": -11,
      "y": 18,
      "z": -7,
      "name": "Cloth_Block_Wool_Cyan"
    },
    {
      "x": -11,
      "y": 19,
      "z": -7,
      "name": "Cloth_Block_Wool_Cyan"
    },
    {
      "x": -11,
      "y": 20,
      "z": -7,
      "name": "Cloth_Block_Wool_Cyan"
    },
    {
      "x": -11,
      "y": 21,
      "z": -7,
      "name": "Cloth_Block_Wool_Cyan"
    },
    {
      "x": -11,
      "y": 22,
      "z": -7,
      "name": "Cloth_Block_Wool_Cyan"
    },
    {
      "x": -11,
      "y": 23,
      "z": -7,
      "name": "Cloth_Block_Wool_Cyan"
    },
    {
      "x": -11,
      "y": 24,
      "z": -7,
      "name": "Cloth_Block_Wool_Cyan"
    },
    {
      "x": -11,
      "y": 25,
      "z": -7,
      "name": "Cloth_Block_Wool_Cyan"
    },
    {
      "x": -11,
      "y": 26,
      "z": -7,
      "name": "Cloth_Block_Wool_Cyan"
    },
    {
      "x": -11,
      "y": 1,
      "z": -6,
      "name": "Cloth_Block_Wool_Cyan"
    },
    {
      "x": -11,
      "y": 2,
      "z": -6,
      "name": "Cloth_Block_Wool_Cyan"
    },
    {
      "x": -11,
      "y": 3,
      "z": -6,
      "name": "Cloth_Block_Wool_Cyan"
    },
    {
      "x": -11,
      "y": 4,
      "z": -6,
      "name": "Cloth_Block_Wool_Cyan"
    },
    {
      "x": -11,
      "y": 5,
      "z": -6,
      "name": "Cloth_Block_Wool_Cyan"
    },
    {
      "x": -11,
      "y": 6,
      "z": -6,
      "name": "Cloth_Block_Wool_Cyan"
    },
    {
      "x": -11,
      "y": 7,
      "z": -6,
      "name": "Cloth_Block_Wool_Cyan"
    },
    {
      "x": -11,
      "y": 8,
      "z": -6,
      "name": "Cloth_Block_Wool_Cyan"
    },
    {
      "x": -11,
      "y": 9,
      "z": -6,
      "name": "Cloth_Block_Wool_Cyan"
    },
    {
      "x": -11,
      "y": 10,
      "z": -6,
      "name": "Cloth_Block_Wool_Cyan"
    },
    {
      "x": -11,
      "y": 11,
      "z": -6,
      "name": "Cloth_Block_Wool_Cyan"
    },
    {
      "x": -11,
      "y": 12,
      "z": -6,
      "name": "Cloth_Block_Wool_Cyan"
    },
    {
      "x": -11,
      "y": 13,
      "z": -6,
      "name": "Cloth_Block_Wool_Cyan"
    },
    {
      "x": -11,
      "y": 14,
      "z": -6,
      "name": "Cloth_Block_Wool_Cyan"
    },
    {
      "x": -11,
      "y": 15,
      "z": -6,
      "name": "Cloth_Block_Wool_Cyan"
    },
    {
      "x": -11,
      "y": 16,
      "z": -6,
      "name": "Cloth_Block_Wool_Cyan"
    },
    {
      "x": -11,
      "y": 17,
      "z": -6,
      "name": "Cloth_Block_Wool_Cyan"
    },
    {
      "x": -11,
      "y": 18,
      "z": -6,
      "name": "Cloth_Block_Wool_Cyan"
    },
    {
      "x": -11,
      "y": 19,
      "z": -6,
      "name": "Cloth_Block_Wool_Cyan"
    },
    {
      "x": -11,
      "y": 20,
      "z": -6,
      "name": "Cloth_Block_Wool_Cyan"
    },
    {
      "x": -11,
      "y": 21,
      "z": -6,
      "name": "Cloth_Block_Wool_Cyan"
    },
    {
      "x": -11,
      "y": 22,
      "z": -6,
      "name": "Cloth_Block_Wool_Cyan"
    },
    {
      "x": -11,
      "y": 23,
      "z": -6,
      "name": "Cloth_Block_Wool_Cyan"
    },
    {
      "x": -11,
      "y": 24,
      "z": -6,
      "name": "Cloth_Block_Wool_Cyan"
    },
    {
      "x": -11,
      "y": 25,
      "z": -6,
      "name": "Cloth_Block_Wool_Cyan"
    },
    {
      "x": -11,
      "y": 26,
      "z": -6,
      "name": "Cloth_Block_Wool_Cyan"
    },
    {
      "x": -11,
      "y": 1,
      "z": -5,
      "name": "Cloth_Block_Wool_Cyan"
    },
    {
      "x": -11,
      "y": 2,
      "z": -5,
      "name": "Cloth_Block_Wool_Cyan"
    },
    {
      "x": -11,
      "y": 3,
      "z": -5,
      "name": "Cloth_Block_Wool_Cyan"
    },
    {
      "x": -11,
      "y": 4,
      "z": -5,
      "name": "Cloth_Block_Wool_Cyan"
    },
    {
      "x": -11,
      "y": 5,
      "z": -5,
      "name": "Cloth_Block_Wool_Cyan"
    },
    {
      "x": -11,
      "y": 6,
      "z": -5,
      "name": "Cloth_Block_Wool_Cyan"
    },
    {
      "x": -11,
      "y": 7,
      "z": -5,
      "name": "Cloth_Block_Wool_Cyan"
    },
    {
      "x": -11,
      "y": 8,
      "z": -5,
      "name": "Cloth_Block_Wool_Cyan"
    },
    {
      "x": -11,
      "y": 9,
      "z": -5,
      "name": "Cloth_Block_Wool_Cyan"
    },
    {
      "x": -11,
      "y": 10,
      "z": -5,
      "name": "Cloth_Block_Wool_Cyan"
    },
    {
      "x": -11,
      "y": 11,
      "z": -5,
      "name": "Cloth_Block_Wool_Cyan"
    },
    {
      "x": -11,
      "y": 12,
      "z": -5,
      "name": "Cloth_Block_Wool_Cyan"
    },
    {
      "x": -11,
      "y": 13,
      "z": -5,
      "name": "Cloth_Block_Wool_Cyan"
    },
    {
      "x": -11,
      "y": 14,
      "z": -5,
      "name": "Cloth_Block_Wool_Cyan"
    },
    {
      "x": -11,
      "y": 15,
      "z": -5,
      "name": "Cloth_Block_Wool_Cyan"
    },
    {
      "x": -11,
      "y": 16,
      "z": -5,
      "name": "Cloth_Block_Wool_Cyan"
    },
    {
      "x": -11,
      "y": 17,
      "z": -5,
      "name": "Cloth_Block_Wool_Cyan"
    },
    {
      "x": -11,
      "y": 18,
      "z": -5,
      "name": "Cloth_Block_Wool_Cyan"
    },
    {
      "x": -11,
      "y": 19,
      "z": -5,
      "name": "Cloth_Block_Wool_Cyan"
    },
    {
      "x": -11,
      "y": 20,
      "z": -5,
      "name": "Cloth_Block_Wool_Cyan"
    },
    {
      "x": -11,
      "y": 21,
      "z": -5,
      "name": "Cloth_Block_Wool_Cyan"
    },
    {
      "x": -11,
      "y": 22,
      "z": -5,
      "name": "Cloth_Block_Wool_Cyan"
    },
    {
      "x": -11,
      "y": 23,
      "z": -5,
      "name": "Cloth_Block_Wool_Cyan"
    },
    {
      "x": -11,
      "y": 24,
      "z": -5,
      "name": "Cloth_Block_Wool_Cyan"
    },
    {
      "x": -11,
      "y": 25,
      "z": -5,
      "name": "Cloth_Block_Wool_Cyan"
    },
    {
      "x": -11,
      "y": 26,
      "z": -5,
      "name": "Cloth_Block_Wool_Cyan"
    },
    {
      "x": -11,
      "y": 1,
      "z": -4,
      "name": "Cloth_Block_Wool_Cyan"
    },
    {
      "x": -11,
      "y": 2,
      "z": -4,
      "name": "Cloth_Block_Wool_Cyan"
    },
    {
      "x": -11,
      "y": 3,
      "z": -4,
      "name": "Cloth_Block_Wool_Cyan"
    },
    {
      "x": -11,
      "y": 4,
      "z": -4,
      "name": "Cloth_Block_Wool_Cyan"
    },
    {
      "x": -11,
      "y": 5,
      "z": -4,
      "name": "Cloth_Block_Wool_Cyan"
    },
    {
      "x": -11,
      "y": 6,
      "z": -4,
      "name": "Cloth_Block_Wool_Cyan"
    },
    {
      "x": -11,
      "y": 7,
      "z": -4,
      "name": "Cloth_Block_Wool_Cyan"
    },
    {
      "x": -11,
      "y": 8,
      "z": -4,
      "name": "Cloth_Block_Wool_Cyan"
    },
    {
      "x": -11,
      "y": 9,
      "z": -4,
      "name": "Cloth_Block_Wool_Cyan"
    },
    {
      "x": -11,
      "y": 10,
      "z": -4,
      "name": "Cloth_Block_Wool_Cyan"
    },
    {
      "x": -11,
      "y": 11,
      "z": -4,
      "name": "Cloth_Block_Wool_Cyan"
    },
    {
      "x": -11,
      "y": 12,
      "z": -4,
      "name": "Cloth_Block_Wool_Cyan"
    },
    {
      "x": -11,
      "y": 13,
      "z": -4,
      "name": "Cloth_Block_Wool_Cyan"
    },
    {
      "x": -11,
      "y": 14,
      "z": -4,
      "name": "Cloth_Block_Wool_Cyan"
    },
    {
      "x": -11,
      "y": 15,
      "z": -4,
      "name": "Cloth_Block_Wool_Cyan"
    },
    {
      "x": -11,
      "y": 16,
      "z": -4,
      "name": "Cloth_Block_Wool_Cyan"
    },
    {
      "x": -11,
      "y": 17,
      "z": -4,
      "name": "Cloth_Block_Wool_Cyan"
    },
    {
      "x": -11,
      "y": 18,
      "z": -4,
      "name": "Cloth_Block_Wool_Cyan"
    },
    {
      "x": -11,
      "y": 19,
      "z": -4,
      "name": "Cloth_Block_Wool_Cyan"
    },
    {
      "x": -11,
      "y": 20,
      "z": -4,
      "name": "Cloth_Block_Wool_Cyan"
    },
    {
      "x": -11,
      "y": 21,
      "z": -4,
      "name": "Cloth_Block_Wool_Cyan"
    },
    {
      "x": -11,
      "y": 22,
      "z": -4,
      "name": "Cloth_Block_Wool_Cyan"
    },
    {
      "x": -11,
      "y": 23,
      "z": -4,
      "name": "Cloth_Block_Wool_Cyan"
    },
    {
      "x": -11,
      "y": 24,
      "z": -4,
      "name": "Cloth_Block_Wool_Cyan"
    },
    {
      "x": -11,
      "y": 25,
      "z": -4,
      "name": "Cloth_Block_Wool_Cyan"
    },
    {
      "x": -11,
      "y": 26,
      "z": -4,
      "name": "Cloth_Block_Wool_Cyan"
    },
    {
      "x": -11,
      "y": 1,
      "z": -3,
      "name": "Cloth_Block_Wool_Cyan"
    },
    {
      "x": -11,
      "y": 2,
      "z": -3,
      "name": "Cloth_Block_Wool_Cyan"
    },
    {
      "x": -11,
      "y": 3,
      "z": -3,
      "name": "Cloth_Block_Wool_Cyan"
    },
    {
      "x": -11,
      "y": 4,
      "z": -3,
      "name": "Cloth_Block_Wool_Cyan"
    },
    {
      "x": -11,
      "y": 5,
      "z": -3,
      "name": "Cloth_Block_Wool_Cyan"
    },
    {
      "x": -11,
      "y": 6,
      "z": -3,
      "name": "Cloth_Block_Wool_Cyan"
    },
    {
      "x": -11,
      "y": 7,
      "z": -3,
      "name": "Cloth_Block_Wool_Cyan"
    },
    {
      "x": -11,
      "y": 8,
      "z": -3,
      "name": "Cloth_Block_Wool_Cyan"
    },
    {
      "x": -11,
      "y": 9,
      "z": -3,
      "name": "Cloth_Block_Wool_Cyan"
    },
    {
      "x": -11,
      "y": 10,
      "z": -3,
      "name": "Cloth_Block_Wool_Cyan"
    },
    {
      "x": -11,
      "y": 11,
      "z": -3,
      "name": "Cloth_Block_Wool_Cyan"
    },
    {
      "x": -11,
      "y": 12,
      "z": -3,
      "name": "Cloth_Block_Wool_Cyan"
    },
    {
      "x": -11,
      "y": 13,
      "z": -3,
      "name": "Cloth_Block_Wool_Cyan"
    },
    {
      "x": -11,
      "y": 14,
      "z": -3,
      "name": "Cloth_Block_Wool_Cyan"
    },
    {
      "x": -11,
      "y": 15,
      "z": -3,
      "name": "Cloth_Block_Wool_Cyan"
    },
    {
      "x": -11,
      "y": 16,
      "z": -3,
      "name": "Cloth_Block_Wool_Cyan"
    },
    {
      "x": -11,
      "y": 17,
      "z": -3,
      "name": "Cloth_Block_Wool_Cyan"
    },
    {
      "x": -11,
      "y": 18,
      "z": -3,
      "name": "Cloth_Block_Wool_Cyan"
    },
    {
      "x": -11,
      "y": 19,
      "z": -3,
      "name": "Cloth_Block_Wool_Cyan"
    },
    {
      "x": -11,
      "y": 20,
      "z": -3,
      "name": "Cloth_Block_Wool_Cyan"
    },
    {
      "x": -11,
      "y": 21,
      "z": -3,
      "name": "Cloth_Block_Wool_Cyan"
    },
    {
      "x": -11,
      "y": 22,
      "z": -3,
      "name": "Cloth_Block_Wool_Cyan"
    },
    {
      "x": -11,
      "y": 23,
      "z": -3,
      "name": "Cloth_Block_Wool_Cyan"
    },
    {
      "x": -11,
      "y": 24,
      "z": -3,
      "name": "Cloth_Block_Wool_Cyan"
    },
    {
      "x": -11,
      "y": 25,
      "z": -3,
      "name": "Cloth_Block_Wool_Cyan"
    },
    {
      "x": -11,
      "y": 26,
      "z": -3,
      "name": "Cloth_Block_Wool_Cyan"
    },
    {
      "x": -11,
      "y": 1,
      "z": -2,
      "name": "Cloth_Block_Wool_Cyan"
    },
    {
      "x": -11,
      "y": 2,
      "z": -2,
      "name": "Cloth_Block_Wool_Cyan"
    },
    {
      "x": -11,
      "y": 3,
      "z": -2,
      "name": "Cloth_Block_Wool_Cyan"
    },
    {
      "x": -11,
      "y": 4,
      "z": -2,
      "name": "Cloth_Block_Wool_Cyan"
    },
    {
      "x": -11,
      "y": 5,
      "z": -2,
      "name": "Cloth_Block_Wool_Cyan"
    },
    {
      "x": -11,
      "y": 6,
      "z": -2,
      "name": "Cloth_Block_Wool_Cyan"
    },
    {
      "x": -11,
      "y": 7,
      "z": -2,
      "name": "Cloth_Block_Wool_Cyan"
    },
    {
      "x": -11,
      "y": 8,
      "z": -2,
      "name": "Cloth_Block_Wool_Cyan"
    },
    {
      "x": -11,
      "y": 9,
      "z": -2,
      "name": "Cloth_Block_Wool_Cyan"
    },
    {
      "x": -11,
      "y": 10,
      "z": -2,
      "name": "Cloth_Block_Wool_Cyan"
    },
    {
      "x": -11,
      "y": 11,
      "z": -2,
      "name": "Cloth_Block_Wool_Cyan"
    },
    {
      "x": -11,
      "y": 12,
      "z": -2,
      "name": "Cloth_Block_Wool_Cyan"
    },
    {
      "x": -11,
      "y": 13,
      "z": -2,
      "name": "Cloth_Block_Wool_Cyan"
    },
    {
      "x": -11,
      "y": 14,
      "z": -2,
      "name": "Cloth_Block_Wool_Cyan"
    },
    {
      "x": -11,
      "y": 15,
      "z": -2,
      "name": "Cloth_Block_Wool_Cyan"
    },
    {
      "x": -11,
      "y": 16,
      "z": -2,
      "name": "Cloth_Block_Wool_Cyan"
    },
    {
      "x": -11,
      "y": 17,
      "z": -2,
      "name": "Cloth_Block_Wool_Cyan"
    },
    {
      "x": -11,
      "y": 18,
      "z": -2,
      "name": "Cloth_Block_Wool_Cyan"
    },
    {
      "x": -11,
      "y": 19,
      "z": -2,
      "name": "Cloth_Block_Wool_Cyan"
    },
    {
      "x": -11,
      "y": 20,
      "z": -2,
      "name": "Cloth_Block_Wool_Cyan"
    },
    {
      "x": -11,
      "y": 21,
      "z": -2,
      "name": "Cloth_Block_Wool_Cyan"
    },
    {
      "x": -11,
      "y": 22,
      "z": -2,
      "name": "Cloth_Block_Wool_Cyan"
    },
    {
      "x": -11,
      "y": 23,
      "z": -2,
      "name": "Cloth_Block_Wool_Cyan"
    },
    {
      "x": -11,
      "y": 24,
      "z": -2,
      "name": "Cloth_Block_Wool_Cyan"
    },
    {
      "x": -11,
      "y": 25,
      "z": -2,
      "name": "Cloth_Block_Wool_Cyan"
    },
    {
      "x": -11,
      "y": 26,
      "z": -2,
      "name": "Cloth_Block_Wool_Cyan"
    },
    {
      "x": -11,
      "y": 1,
      "z": -1,
      "name": "Cloth_Block_Wool_Cyan"
    },
    {
      "x": -11,
      "y": 2,
      "z": -1,
      "name": "Cloth_Block_Wool_Cyan"
    },
    {
      "x": -11,
      "y": 3,
      "z": -1,
      "name": "Cloth_Block_Wool_Cyan"
    },
    {
      "x": -11,
      "y": 4,
      "z": -1,
      "name": "Cloth_Block_Wool_Cyan"
    },
    {
      "x": -11,
      "y": 5,
      "z": -1,
      "name": "Cloth_Block_Wool_Cyan"
    },
    {
      "x": -11,
      "y": 6,
      "z": -1,
      "name": "Cloth_Block_Wool_Cyan"
    },
    {
      "x": -11,
      "y": 7,
      "z": -1,
      "name": "Cloth_Block_Wool_Cyan"
    },
    {
      "x": -11,
      "y": 8,
      "z": -1,
      "name": "Cloth_Block_Wool_Cyan"
    },
    {
      "x": -11,
      "y": 9,
      "z": -1,
      "name": "Cloth_Block_Wool_Cyan"
    },
    {
      "x": -11,
      "y": 10,
      "z": -1,
      "name": "Cloth_Block_Wool_Cyan"
    },
    {
      "x": -11,
      "y": 11,
      "z": -1,
      "name": "Cloth_Block_Wool_Cyan"
    },
    {
      "x": -11,
      "y": 12,
      "z": -1,
      "name": "Cloth_Block_Wool_Cyan"
    },
    {
      "x": -11,
      "y": 13,
      "z": -1,
      "name": "Cloth_Block_Wool_Cyan"
    },
    {
      "x": -11,
      "y": 14,
      "z": -1,
      "name": "Cloth_Block_Wool_Cyan"
    },
    {
      "x": -11,
      "y": 15,
      "z": -1,
      "name": "Cloth_Block_Wool_Cyan"
    },
    {
      "x": -11,
      "y": 16,
      "z": -1,
      "name": "Cloth_Block_Wool_Cyan"
    },
    {
      "x": -11,
      "y": 17,
      "z": -1,
      "name": "Cloth_Block_Wool_Cyan"
    },
    {
      "x": -11,
      "y": 18,
      "z": -1,
      "name": "Cloth_Block_Wool_Cyan"
    },
    {
      "x": -11,
      "y": 19,
      "z": -1,
      "name": "Cloth_Block_Wool_Cyan"
    },
    {
      "x": -11,
      "y": 20,
      "z": -1,
      "name": "Cloth_Block_Wool_Cyan"
    },
    {
      "x": -11,
      "y": 21,
      "z": -1,
      "name": "Cloth_Block_Wool_Cyan"
    },
    {
      "x": -11,
      "y": 22,
      "z": -1,
      "name": "Cloth_Block_Wool_Cyan"
    },
    {
      "x": -11,
      "y": 23,
      "z": -1,
      "name": "Cloth_Block_Wool_Cyan"
    },
    {
      "x": -11,
      "y": 24,
      "z": -1,
      "name": "Cloth_Block_Wool_Cyan"
    },
    {
      "x": -11,
      "y": 25,
      "z": -1,
      "name": "Cloth_Block_Wool_Cyan"
    },
    {
      "x": -11,
      "y": 26,
      "z": -1,
      "name": "Cloth_Block_Wool_Cyan"
    },
    {
      "x": -10,
      "y": 1,
      "z": -8,
      "name": "Cloth_Block_Wool_Cyan"
    },
    {
      "x": -10,
      "y": 2,
      "z": -8,
      "name": "Cloth_Block_Wool_Cyan"
    },
    {
      "x": -10,
      "y": 3,
      "z": -8,
      "name": "Cloth_Block_Wool_Cyan"
    },
    {
      "x": -10,
      "y": 4,
      "z": -8,
      "name": "Cloth_Block_Wool_Cyan"
    },
    {
      "x": -10,
      "y": 5,
      "z": -8,
      "name": "Cloth_Block_Wool_Cyan"
    },
    {
      "x": -10,
      "y": 6,
      "z": -8,
      "name": "Cloth_Block_Wool_Cyan"
    },
    {
      "x": -10,
      "y": 7,
      "z": -8,
      "name": "Cloth_Block_Wool_Cyan"
    },
    {
      "x": -10,
      "y": 8,
      "z": -8,
      "name": "Cloth_Block_Wool_Cyan"
    },
    {
      "x": -10,
      "y": 9,
      "z": -8,
      "name": "Cloth_Block_Wool_Cyan"
    },
    {
      "x": -10,
      "y": 10,
      "z": -8,
      "name": "Cloth_Block_Wool_Cyan"
    },
    {
      "x": -10,
      "y": 11,
      "z": -8,
      "name": "Cloth_Block_Wool_Cyan"
    },
    {
      "x": -10,
      "y": 12,
      "z": -8,
      "name": "Cloth_Block_Wool_Cyan"
    },
    {
      "x": -10,
      "y": 13,
      "z": -8,
      "name": "Cloth_Block_Wool_Cyan"
    },
    {
      "x": -10,
      "y": 14,
      "z": -8,
      "name": "Cloth_Block_Wool_Cyan"
    },
    {
      "x": -10,
      "y": 15,
      "z": -8,
      "name": "Cloth_Block_Wool_Cyan"
    },
    {
      "x": -10,
      "y": 16,
      "z": -8,
      "name": "Cloth_Block_Wool_Cyan"
    },
    {
      "x": -10,
      "y": 17,
      "z": -8,
      "name": "Cloth_Block_Wool_Cyan"
    },
    {
      "x": -10,
      "y": 18,
      "z": -8,
      "name": "Cloth_Block_Wool_Cyan"
    },
    {
      "x": -10,
      "y": 19,
      "z": -8,
      "name": "Cloth_Block_Wool_Cyan"
    },
    {
      "x": -10,
      "y": 20,
      "z": -8,
      "name": "Cloth_Block_Wool_Cyan"
    },
    {
      "x": -10,
      "y": 21,
      "z": -8,
      "name": "Cloth_Block_Wool_Cyan"
    },
    {
      "x": -10,
      "y": 22,
      "z": -8,
      "name": "Cloth_Block_Wool_Cyan"
    },
    {
      "x": -10,
      "y": 23,
      "z": -8,
      "name": "Cloth_Block_Wool_Cyan"
    },
    {
      "x": -10,
      "y": 24,
      "z": -8,
      "name": "Cloth_Block_Wool_Cyan"
    },
    {
      "x": -10,
      "y": 25,
      "z": -8,
      "name": "Cloth_Block_Wool_Cyan"
    },
    {
      "x": -10,
      "y": 26,
      "z": -8,
      "name": "Cloth_Block_Wool_Cyan"
    },
    {
      "x": -10,
      "y": 1,
      "z": -7,
      "name": "Cloth_Block_Wool_Cyan"
    },
    {
      "x": -10,
      "y": 2,
      "z": -7,
      "name": "Cloth_Block_Wool_Cyan"
    },
    {
      "x": -10,
      "y": 3,
      "z": -7,
      "name": "Cloth_Block_Wool_Cyan"
    },
    {
      "x": -10,
      "y": 4,
      "z": -7,
      "name": "Cloth_Block_Wool_Cyan"
    },
    {
      "x": -10,
      "y": 5,
      "z": -7,
      "name": "Cloth_Block_Wool_Cyan"
    },
    {
      "x": -10,
      "y": 6,
      "z": -7,
      "name": "Cloth_Block_Wool_Cyan"
    },
    {
      "x": -10,
      "y": 7,
      "z": -7,
      "name": "Cloth_Block_Wool_Cyan"
    },
    {
      "x": -10,
      "y": 8,
      "z": -7,
      "name": "Cloth_Block_Wool_Cyan"
    },
    {
      "x": -10,
      "y": 9,
      "z": -7,
      "name": "Cloth_Block_Wool_Cyan"
    },
    {
      "x": -10,
      "y": 10,
      "z": -7,
      "name": "Cloth_Block_Wool_Cyan"
    },
    {
      "x": -10,
      "y": 11,
      "z": -7,
      "name": "Cloth_Block_Wool_Cyan"
    },
    {
      "x": -10,
      "y": 12,
      "z": -7,
      "name": "Cloth_Block_Wool_Cyan"
    },
    {
      "x": -10,
      "y": 13,
      "z": -7,
      "name": "Cloth_Block_Wool_Cyan"
    },
    {
      "x": -10,
      "y": 14,
      "z": -7,
      "name": "Cloth_Block_Wool_Cyan"
    },
    {
      "x": -10,
      "y": 15,
      "z": -7,
      "name": "Cloth_Block_Wool_Cyan"
    },
    {
      "x": -10,
      "y": 16,
      "z": -7,
      "name": "Cloth_Block_Wool_Cyan"
    },
    {
      "x": -10,
      "y": 17,
      "z": -7,
      "name": "Cloth_Block_Wool_Cyan"
    },
    {
      "x": -10,
      "y": 18,
      "z": -7,
      "name": "Cloth_Block_Wool_Cyan"
    },
    {
      "x": -10,
      "y": 19,
      "z": -7,
      "name": "Cloth_Block_Wool_Cyan"
    },
    {
      "x": -10,
      "y": 20,
      "z": -7,
      "name": "Cloth_Block_Wool_Cyan"
    },
    {
      "x": -10,
      "y": 21,
      "z": -7,
      "name": "Cloth_Block_Wool_Cyan"
    },
    {
      "x": -10,
      "y": 22,
      "z": -7,
      "name": "Cloth_Block_Wool_Cyan"
    },
    {
      "x": -10,
      "y": 23,
      "z": -7,
      "name": "Cloth_Block_Wool_Cyan"
    },
    {
      "x": -10,
      "y": 24,
      "z": -7,
      "name": "Cloth_Block_Wool_Cyan"
    },
    {
      "x": -10,
      "y": 25,
      "z": -7,
      "name": "Cloth_Block_Wool_Cyan"
    },
    {
      "x": -10,
      "y": 26,
      "z": -7,
      "name": "Cloth_Block_Wool_Cyan"
    },
    {
      "x": -10,
      "y": 1,
      "z": -6,
      "name": "Cloth_Block_Wool_Cyan"
    },
    {
      "x": -10,
      "y": 2,
      "z": -6,
      "name": "Cloth_Block_Wool_Cyan"
    },
    {
      "x": -10,
      "y": 3,
      "z": -6,
      "name": "Cloth_Block_Wool_Cyan"
    },
    {
      "x": -10,
      "y": 4,
      "z": -6,
      "name": "Cloth_Block_Wool_Cyan"
    },
    {
      "x": -10,
      "y": 5,
      "z": -6,
      "name": "Cloth_Block_Wool_Cyan"
    },
    {
      "x": -10,
      "y": 6,
      "z": -6,
      "name": "Cloth_Block_Wool_Cyan"
    },
    {
      "x": -10,
      "y": 7,
      "z": -6,
      "name": "Cloth_Block_Wool_Cyan"
    },
    {
      "x": -10,
      "y": 8,
      "z": -6,
      "name": "Cloth_Block_Wool_Cyan"
    },
    {
      "x": -10,
      "y": 9,
      "z": -6,
      "name": "Cloth_Block_Wool_Cyan"
    },
    {
      "x": -10,
      "y": 10,
      "z": -6,
      "name": "Cloth_Block_Wool_Cyan"
    },
    {
      "x": -10,
      "y": 11,
      "z": -6,
      "name": "Cloth_Block_Wool_Cyan"
    },
    {
      "x": -10,
      "y": 12,
      "z": -6,
      "name": "Cloth_Block_Wool_Cyan"
    },
    {
      "x": -10,
      "y": 13,
      "z": -6,
      "name": "Cloth_Block_Wool_Cyan"
    },
    {
      "x": -10,
      "y": 14,
      "z": -6,
      "name": "Cloth_Block_Wool_Cyan"
    },
    {
      "x": -10,
      "y": 15,
      "z": -6,
      "name": "Cloth_Block_Wool_Cyan"
    },
    {
      "x": -10,
      "y": 16,
      "z": -6,
      "name": "Cloth_Block_Wool_Cyan"
    },
    {
      "x": -10,
      "y": 17,
      "z": -6,
      "name": "Cloth_Block_Wool_Cyan"
    },
    {
      "x": -10,
      "y": 18,
      "z": -6,
      "name": "Cloth_Block_Wool_Cyan"
    },
    {
      "x": -10,
      "y": 19,
      "z": -6,
      "name": "Cloth_Block_Wool_Cyan"
    },
    {
      "x": -10,
      "y": 20,
      "z": -6,
      "name": "Cloth_Block_Wool_Cyan"
    },
    {
      "x": -10,
      "y": 21,
      "z": -6,
      "name": "Cloth_Block_Wool_Cyan"
    },
    {
      "x": -10,
      "y": 22,
      "z": -6,
      "name": "Cloth_Block_Wool_Cyan"
    },
    {
      "x": -10,
      "y": 23,
      "z": -6,
      "name": "Cloth_Block_Wool_Cyan"
    },
    {
      "x": -10,
      "y": 24,
      "z": -6,
      "name": "Cloth_Block_Wool_Cyan"
    },
    {
      "x": -10,
      "y": 25,
      "z": -6,
      "name": "Cloth_Block_Wool_Cyan"
    },
    {
      "x": -10,
      "y": 26,
      "z": -6,
      "name": "Cloth_Block_Wool_Cyan"
    },
    {
      "x": -10,
      "y": 1,
      "z": -5,
      "name": "Cloth_Block_Wool_Cyan"
    },
    {
      "x": -10,
      "y": 2,
      "z": -5,
      "name": "Cloth_Block_Wool_Cyan"
    },
    {
      "x": -10,
      "y": 3,
      "z": -5,
      "name": "Cloth_Block_Wool_Cyan"
    },
    {
      "x": -10,
      "y": 4,
      "z": -5,
      "name": "Cloth_Block_Wool_Cyan"
    },
    {
      "x": -10,
      "y": 5,
      "z": -5,
      "name": "Cloth_Block_Wool_Cyan"
    },
    {
      "x": -10,
      "y": 6,
      "z": -5,
      "name": "Cloth_Block_Wool_Cyan"
    },
    {
      "x": -10,
      "y": 7,
      "z": -5,
      "name": "Cloth_Block_Wool_Cyan"
    },
    {
      "x": -10,
      "y": 8,
      "z": -5,
      "name": "Cloth_Block_Wool_Cyan"
    },
    {
      "x": -10,
      "y": 9,
      "z": -5,
      "name": "Cloth_Block_Wool_Cyan"
    },
    {
      "x": -10,
      "y": 10,
      "z": -5,
      "name": "Cloth_Block_Wool_Cyan"
    },
    {
      "x": -10,
      "y": 11,
      "z": -5,
      "name": "Cloth_Block_Wool_Cyan"
    },
    {
      "x": -10,
      "y": 12,
      "z": -5,
      "name": "Cloth_Block_Wool_Cyan"
    },
    {
      "x": -10,
      "y": 13,
      "z": -5,
      "name": "Cloth_Block_Wool_Cyan"
    },
    {
      "x": -10,
      "y": 14,
      "z": -5,
      "name": "Cloth_Block_Wool_Cyan"
    },
    {
      "x": -10,
      "y": 15,
      "z": -5,
      "name": "Cloth_Block_Wool_Cyan"
    },
    {
      "x": -10,
      "y": 16,
      "z": -5,
      "name": "Cloth_Block_Wool_Cyan"
    },
    {
      "x": -10,
      "y": 17,
      "z": -5,
      "name": "Cloth_Block_Wool_Cyan"
    },
    {
      "x": -10,
      "y": 18,
      "z": -5,
      "name": "Cloth_Block_Wool_Cyan"
    },
    {
      "x": -10,
      "y": 19,
      "z": -5,
      "name": "Cloth_Block_Wool_Cyan"
    },
    {
      "x": -10,
      "y": 20,
      "z": -5,
      "name": "Cloth_Block_Wool_Cyan"
    },
    {
      "x": -10,
      "y": 21,
      "z": -5,
      "name": "Cloth_Block_Wool_Cyan"
    },
    {
      "x": -10,
      "y": 22,
      "z": -5,
      "name": "Cloth_Block_Wool_Cyan"
    },
    {
      "x": -10,
      "y": 23,
      "z": -5,
      "name": "Cloth_Block_Wool_Cyan"
    },
    {
      "x": -10,
      "y": 24,
      "z": -5,
      "name": "Cloth_Block_Wool_Cyan"
    },
    {
      "x": -10,
      "y": 25,
      "z": -5,
      "name": "Cloth_Block_Wool_Cyan"
    },
    {
      "x": -10,
      "y": 26,
      "z": -5,
      "name": "Cloth_Block_Wool_Cyan"
    },
    {
      "x": -10,
      "y": 1,
      "z": -4,
      "name": "Cloth_Block_Wool_Cyan"
    },
    {
      "x": -10,
      "y": 2,
      "z": -4,
      "name": "Cloth_Block_Wool_Cyan"
    },
    {
      "x": -10,
      "y": 3,
      "z": -4,
      "name": "Cloth_Block_Wool_Cyan"
    },
    {
      "x": -10,
      "y": 4,
      "z": -4,
      "name": "Cloth_Block_Wool_Cyan"
    },
    {
      "x": -10,
      "y": 5,
      "z": -4,
      "name": "Cloth_Block_Wool_Cyan"
    },
    {
      "x": -10,
      "y": 6,
      "z": -4,
      "name": "Cloth_Block_Wool_Cyan"
    },
    {
      "x": -10,
      "y": 7,
      "z": -4,
      "name": "Cloth_Block_Wool_Cyan"
    },
    {
      "x": -10,
      "y": 8,
      "z": -4,
      "name": "Cloth_Block_Wool_Cyan"
    },
    {
      "x": -10,
      "y": 9,
      "z": -4,
      "name": "Cloth_Block_Wool_Cyan"
    },
    {
      "x": -10,
      "y": 10,
      "z": -4,
      "name": "Cloth_Block_Wool_Cyan"
    },
    {
      "x": -10,
      "y": 11,
      "z": -4,
      "name": "Cloth_Block_Wool_Cyan"
    },
    {
      "x": -10,
      "y": 12,
      "z": -4,
      "name": "Cloth_Block_Wool_Cyan"
    },
    {
      "x": -10,
      "y": 13,
      "z": -4,
      "name": "Cloth_Block_Wool_Cyan"
    },
    {
      "x": -10,
      "y": 14,
      "z": -4,
      "name": "Cloth_Block_Wool_Cyan"
    },
    {
      "x": -10,
      "y": 15,
      "z": -4,
      "name": "Cloth_Block_Wool_Cyan"
    },
    {
      "x": -10,
      "y": 16,
      "z": -4,
      "name": "Cloth_Block_Wool_Cyan"
    },
    {
      "x": -10,
      "y": 17,
      "z": -4,
      "name": "Cloth_Block_Wool_Cyan"
    },
    {
      "x": -10,
      "y": 18,
      "z": -4,
      "name": "Cloth_Block_Wool_Cyan"
    },
    {
      "x": -10,
      "y": 19,
      "z": -4,
      "name": "Cloth_Block_Wool_Cyan"
    },
    {
      "x": -10,
      "y": 20,
      "z": -4,
      "name": "Cloth_Block_Wool_Cyan"
    },
    {
      "x": -10,
      "y": 21,
      "z": -4,
      "name": "Cloth_Block_Wool_Cyan"
    },
    {
      "x": -10,
      "y": 22,
      "z": -4,
      "name": "Cloth_Block_Wool_Cyan"
    },
    {
      "x": -10,
      "y": 23,
      "z": -4,
      "name": "Cloth_Block_Wool_Cyan"
    },
    {
      "x": -10,
      "y": 24,
      "z": -4,
      "name": "Cloth_Block_Wool_Cyan"
    },
    {
      "x": -10,
      "y": 25,
      "z": -4,
      "name": "Cloth_Block_Wool_Cyan"
    },
    {
      "x": -10,
      "y": 26,
      "z": -4,
      "name": "Cloth_Block_Wool_Cyan"
    },
    {
      "x": -10,
      "y": 1,
      "z": -3,
      "name": "Cloth_Block_Wool_Cyan"
    },
    {
      "x": -10,
      "y": 2,
      "z": -3,
      "name": "Cloth_Block_Wool_Cyan"
    },
    {
      "x": -10,
      "y": 3,
      "z": -3,
      "name": "Cloth_Block_Wool_Cyan"
    },
    {
      "x": -10,
      "y": 4,
      "z": -3,
      "name": "Cloth_Block_Wool_Cyan"
    },
    {
      "x": -10,
      "y": 5,
      "z": -3,
      "name": "Cloth_Block_Wool_Cyan"
    },
    {
      "x": -10,
      "y": 6,
      "z": -3,
      "name": "Cloth_Block_Wool_Cyan"
    },
    {
      "x": -10,
      "y": 7,
      "z": -3,
      "name": "Cloth_Block_Wool_Cyan"
    },
    {
      "x": -10,
      "y": 8,
      "z": -3,
      "name": "Cloth_Block_Wool_Cyan"
    },
    {
      "x": -10,
      "y": 9,
      "z": -3,
      "name": "Cloth_Block_Wool_Cyan"
    },
    {
      "x": -10,
      "y": 10,
      "z": -3,
      "name": "Cloth_Block_Wool_Cyan"
    },
    {
      "x": -10,
      "y": 11,
      "z": -3,
      "name": "Cloth_Block_Wool_Cyan"
    },
    {
      "x": -10,
      "y": 12,
      "z": -3,
      "name": "Cloth_Block_Wool_Cyan"
    },
    {
      "x": -10,
      "y": 13,
      "z": -3,
      "name": "Cloth_Block_Wool_Cyan"
    },
    {
      "x": -10,
      "y": 14,
      "z": -3,
      "name": "Cloth_Block_Wool_Cyan"
    },
    {
      "x": -10,
      "y": 15,
      "z": -3,
      "name": "Cloth_Block_Wool_Cyan"
    },
    {
      "x": -10,
      "y": 16,
      "z": -3,
      "name": "Cloth_Block_Wool_Cyan"
    },
    {
      "x": -10,
      "y": 17,
      "z": -3,
      "name": "Cloth_Block_Wool_Cyan"
    },
    {
      "x": -10,
      "y": 18,
      "z": -3,
      "name": "Cloth_Block_Wool_Cyan"
    },
    {
      "x": -10,
      "y": 19,
      "z": -3,
      "name": "Cloth_Block_Wool_Cyan"
    },
    {
      "x": -10,
      "y": 20,
      "z": -3,
      "name": "Cloth_Block_Wool_Cyan"
    },
    {
      "x": -10,
      "y": 21,
      "z": -3,
      "name": "Cloth_Block_Wool_Cyan"
    },
    {
      "x": -10,
      "y": 22,
      "z": -3,
      "name": "Cloth_Block_Wool_Cyan"
    },
    {
      "x": -10,
      "y": 23,
      "z": -3,
      "name": "Cloth_Block_Wool_Cyan"
    },
    {
      "x": -10,
      "y": 24,
      "z": -3,
      "name": "Cloth_Block_Wool_Cyan"
    },
    {
      "x": -10,
      "y": 25,
      "z": -3,
      "name": "Cloth_Block_Wool_Cyan"
    },
    {
      "x": -10,
      "y": 26,
      "z": -3,
      "name": "Cloth_Block_Wool_Cyan"
    },
    {
      "x": -10,
      "y": 1,
      "z": -2,
      "name": "Cloth_Block_Wool_Cyan"
    },
    {
      "x": -10,
      "y": 2,
      "z": -2,
      "name": "Cloth_Block_Wool_Cyan"
    },
    {
      "x": -10,
      "y": 3,
      "z": -2,
      "name": "Cloth_Block_Wool_Cyan"
    },
    {
      "x": -10,
      "y": 4,
      "z": -2,
      "name": "Cloth_Block_Wool_Cyan"
    },
    {
      "x": -10,
      "y": 5,
      "z": -2,
      "name": "Cloth_Block_Wool_Cyan"
    },
    {
      "x": -10,
      "y": 6,
      "z": -2,
      "name": "Cloth_Block_Wool_Cyan"
    },
    {
      "x": -10,
      "y": 7,
      "z": -2,
      "name": "Cloth_Block_Wool_Cyan"
    },
    {
      "x": -10,
      "y": 8,
      "z": -2,
      "name": "Cloth_Block_Wool_Cyan"
    },
    {
      "x": -10,
      "y": 9,
      "z": -2,
      "name": "Cloth_Block_Wool_Cyan"
    },
    {
      "x": -10,
      "y": 10,
      "z": -2,
      "name": "Cloth_Block_Wool_Cyan"
    },
    {
      "x": -10,
      "y": 11,
      "z": -2,
      "name": "Cloth_Block_Wool_Cyan"
    },
    {
      "x": -10,
      "y": 12,
      "z": -2,
      "name": "Cloth_Block_Wool_Cyan"
    },
    {
      "x": -10,
      "y": 13,
      "z": -2,
      "name": "Cloth_Block_Wool_Cyan"
    },
    {
      "x": -10,
      "y": 14,
      "z": -2,
      "name": "Cloth_Block_Wool_Cyan"
    },
    {
      "x": -10,
      "y": 15,
      "z": -2,
      "name": "Cloth_Block_Wool_Cyan"
    },
    {
      "x": -10,
      "y": 16,
      "z": -2,
      "name": "Cloth_Block_Wool_Cyan"
    },
    {
      "x": -10,
      "y": 17,
      "z": -2,
      "name": "Cloth_Block_Wool_Cyan"
    },
    {
      "x": -10,
      "y": 18,
      "z": -2,
      "name": "Cloth_Block_Wool_Cyan"
    },
    {
      "x": -10,
      "y": 19,
      "z": -2,
      "name": "Cloth_Block_Wool_Cyan"
    },
    {
      "x": -10,
      "y": 20,
      "z": -2,
      "name": "Cloth_Block_Wool_Cyan"
    },
    {
      "x": -10,
      "y": 21,
      "z": -2,
      "name": "Cloth_Block_Wool_Cyan"
    },
    {
      "x": -10,
      "y": 22,
      "z": -2,
      "name": "Cloth_Block_Wool_Cyan"
    },
    {
      "x": -10,
      "y": 23,
      "z": -2,
      "name": "Cloth_Block_Wool_Cyan"
    },
    {
      "x": -10,
      "y": 24,
      "z": -2,
      "name": "Cloth_Block_Wool_Cyan"
    },
    {
      "x": -10,
      "y": 25,
      "z": -2,
      "name": "Cloth_Block_Wool_Cyan"
    },
    {
      "x": -10,
      "y": 26,
      "z": -2,
      "name": "Cloth_Block_Wool_Cyan"
    },
    {
      "x": -10,
      "y": 1,
      "z": -1,
      "name": "Cloth_Block_Wool_Cyan"
    },
    {
      "x": -10,
      "y": 2,
      "z": -1,
      "name": "Cloth_Block_Wool_Cyan"
    },
    {
      "x": -10,
      "y": 3,
      "z": -1,
      "name": "Cloth_Block_Wool_Cyan"
    },
    {
      "x": -10,
      "y": 4,
      "z": -1,
      "name": "Cloth_Block_Wool_Cyan"
    },
    {
      "x": -10,
      "y": 5,
      "z": -1,
      "name": "Cloth_Block_Wool_Cyan"
    },
    {
      "x": -10,
      "y": 6,
      "z": -1,
      "name": "Cloth_Block_Wool_Cyan"
    },
    {
      "x": -10,
      "y": 7,
      "z": -1,
      "name": "Cloth_Block_Wool_Cyan"
    },
    {
      "x": -10,
      "y": 8,
      "z": -1,
      "name": "Cloth_Block_Wool_Cyan"
    },
    {
      "x": -10,
      "y": 9,
      "z": -1,
      "name": "Cloth_Block_Wool_Cyan"
    },
    {
      "x": -10,
      "y": 10,
      "z": -1,
      "name": "Cloth_Block_Wool_Cyan"
    },
    {
      "x": -10,
      "y": 11,
      "z": -1,
      "name": "Cloth_Block_Wool_Cyan"
    },
    {
      "x": -10,
      "y": 12,
      "z": -1,
      "name": "Cloth_Block_Wool_Cyan"
    },
    {
      "x": -10,
      "y": 13,
      "z": -1,
      "name": "Cloth_Block_Wool_Cyan"
    },
    {
      "x": -10,
      "y": 14,
      "z": -1,
      "name": "Cloth_Block_Wool_Cyan"
    },
    {
      "x": -10,
      "y": 15,
      "z": -1,
      "name": "Cloth_Block_Wool_Cyan"
    },
    {
      "x": -10,
      "y": 16,
      "z": -1,
      "name": "Cloth_Block_Wool_Cyan"
    },
    {
      "x": -10,
      "y": 17,
      "z": -1,
      "name": "Cloth_Block_Wool_Cyan"
    },
    {
      "x": -10,
      "y": 18,
      "z": -1,
      "name": "Cloth_Block_Wool_Cyan"
    },
    {
      "x": -10,
      "y": 19,
      "z": -1,
      "name": "Cloth_Block_Wool_Cyan"
    },
    {
      "x": -10,
      "y": 20,
      "z": -1,
      "name": "Cloth_Block_Wool_Cyan"
    },
    {
      "x": -10,
      "y": 21,
      "z": -1,
      "name": "Cloth_Block_Wool_Cyan"
    },
    {
      "x": -10,
      "y": 22,
      "z": -1,
      "name": "Cloth_Block_Wool_Cyan"
    },
    {
      "x": -10,
      "y": 23,
      "z": -1,
      "name": "Cloth_Block_Wool_Cyan"
    },
    {
      "x": -10,
      "y": 24,
      "z": -1,
      "name": "Cloth_Block_Wool_Cyan"
    },
    {
      "x": -10,
      "y": 25,
      "z": -1,
      "name": "Cloth_Block_Wool_Cyan"
    },
    {
      "x": -10,
      "y": 26,
      "z": -1,
      "name": "Cloth_Block_Wool_Cyan"
    },
    {
      "x": -9,
      "y": 1,
      "z": -8,
      "name": "Cloth_Block_Wool_Cyan"
    },
    {
      "x": -9,
      "y": 2,
      "z": -8,
      "name": "Cloth_Block_Wool_Cyan"
    },
    {
      "x": -9,
      "y": 3,
      "z": -8,
      "name": "Cloth_Block_Wool_Cyan"
    },
    {
      "x": -9,
      "y": 4,
      "z": -8,
      "name": "Cloth_Block_Wool_Cyan"
    },
    {
      "x": -9,
      "y": 5,
      "z": -8,
      "name": "Cloth_Block_Wool_Cyan"
    },
    {
      "x": -9,
      "y": 6,
      "z": -8,
      "name": "Cloth_Block_Wool_Cyan"
    },
    {
      "x": -9,
      "y": 7,
      "z": -8,
      "name": "Cloth_Block_Wool_Cyan"
    },
    {
      "x": -9,
      "y": 8,
      "z": -8,
      "name": "Cloth_Block_Wool_Cyan"
    },
    {
      "x": -9,
      "y": 9,
      "z": -8,
      "name": "Cloth_Block_Wool_Cyan"
    },
    {
      "x": -9,
      "y": 10,
      "z": -8,
      "name": "Cloth_Block_Wool_Cyan"
    },
    {
      "x": -9,
      "y": 11,
      "z": -8,
      "name": "Cloth_Block_Wool_Cyan"
    },
    {
      "x": -9,
      "y": 12,
      "z": -8,
      "name": "Cloth_Block_Wool_Cyan"
    },
    {
      "x": -9,
      "y": 13,
      "z": -8,
      "name": "Cloth_Block_Wool_Cyan"
    },
    {
      "x": -9,
      "y": 14,
      "z": -8,
      "name": "Cloth_Block_Wool_Cyan"
    },
    {
      "x": -9,
      "y": 15,
      "z": -8,
      "name": "Cloth_Block_Wool_Cyan"
    },
    {
      "x": -9,
      "y": 16,
      "z": -8,
      "name": "Cloth_Block_Wool_Cyan"
    },
    {
      "x": -9,
      "y": 17,
      "z": -8,
      "name": "Cloth_Block_Wool_Cyan"
    },
    {
      "x": -9,
      "y": 18,
      "z": -8,
      "name": "Cloth_Block_Wool_Cyan"
    },
    {
      "x": -9,
      "y": 19,
      "z": -8,
      "name": "Cloth_Block_Wool_Cyan"
    },
    {
      "x": -9,
      "y": 20,
      "z": -8,
      "name": "Cloth_Block_Wool_Cyan"
    },
    {
      "x": -9,
      "y": 21,
      "z": -8,
      "name": "Cloth_Block_Wool_Cyan"
    },
    {
      "x": -9,
      "y": 22,
      "z": -8,
      "name": "Cloth_Block_Wool_Cyan"
    },
    {
      "x": -9,
      "y": 23,
      "z": -8,
      "name": "Cloth_Block_Wool_Cyan"
    },
    {
      "x": -9,
      "y": 24,
      "z": -8,
      "name": "Cloth_Block_Wool_Cyan"
    },
    {
      "x": -9,
      "y": 25,
      "z": -8,
      "name": "Cloth_Block_Wool_Cyan"
    },
    {
      "x": -9,
      "y": 26,
      "z": -8,
      "name": "Cloth_Block_Wool_Cyan"
    },
    {
      "x": -9,
      "y": 1,
      "z": -7,
      "name": "Cloth_Block_Wool_Cyan"
    },
    {
      "x": -9,
      "y": 2,
      "z": -7,
      "name": "Cloth_Block_Wool_Cyan"
    },
    {
      "x": -9,
      "y": 3,
      "z": -7,
      "name": "Cloth_Block_Wool_Cyan"
    },
    {
      "x": -9,
      "y": 4,
      "z": -7,
      "name": "Cloth_Block_Wool_Cyan"
    },
    {
      "x": -9,
      "y": 5,
      "z": -7,
      "name": "Cloth_Block_Wool_Cyan"
    },
    {
      "x": -9,
      "y": 6,
      "z": -7,
      "name": "Cloth_Block_Wool_Cyan"
    },
    {
      "x": -9,
      "y": 7,
      "z": -7,
      "name": "Cloth_Block_Wool_Cyan"
    },
    {
      "x": -9,
      "y": 8,
      "z": -7,
      "name": "Cloth_Block_Wool_Cyan"
    },
    {
      "x": -9,
      "y": 9,
      "z": -7,
      "name": "Cloth_Block_Wool_Cyan"
    },
    {
      "x": -9,
      "y": 10,
      "z": -7,
      "name": "Cloth_Block_Wool_Cyan"
    },
    {
      "x": -9,
      "y": 11,
      "z": -7,
      "name": "Cloth_Block_Wool_Cyan"
    },
    {
      "x": -9,
      "y": 12,
      "z": -7,
      "name": "Cloth_Block_Wool_Cyan"
    },
    {
      "x": -9,
      "y": 13,
      "z": -7,
      "name": "Cloth_Block_Wool_Cyan"
    },
    {
      "x": -9,
      "y": 14,
      "z": -7,
      "name": "Cloth_Block_Wool_Cyan"
    },
    {
      "x": -9,
      "y": 15,
      "z": -7,
      "name": "Cloth_Block_Wool_Cyan"
    },
    {
      "x": -9,
      "y": 16,
      "z": -7,
      "name": "Cloth_Block_Wool_Cyan"
    },
    {
      "x": -9,
      "y": 17,
      "z": -7,
      "name": "Cloth_Block_Wool_Cyan"
    },
    {
      "x": -9,
      "y": 18,
      "z": -7,
      "name": "Cloth_Block_Wool_Cyan"
    },
    {
      "x": -9,
      "y": 19,
      "z": -7,
      "name": "Cloth_Block_Wool_Cyan"
    },
    {
      "x": -9,
      "y": 20,
      "z": -7,
      "name": "Cloth_Block_Wool_Cyan"
    },
    {
      "x": -9,
      "y": 21,
      "z": -7,
      "name": "Cloth_Block_Wool_Cyan"
    },
    {
      "x": -9,
      "y": 22,
      "z": -7,
      "name": "Cloth_Block_Wool_Cyan"
    },
    {
      "x": -9,
      "y": 23,
      "z": -7,
      "name": "Cloth_Block_Wool_Cyan"
    },
    {
      "x": -9,
      "y": 24,
      "z": -7,
      "name": "Cloth_Block_Wool_Cyan"
    },
    {
      "x": -9,
      "y": 25,
      "z": -7,
      "name": "Cloth_Block_Wool_Cyan"
    },
    {
      "x": -9,
      "y": 26,
      "z": -7,
      "name": "Cloth_Block_Wool_Cyan"
    },
    {
      "x": -9,
      "y": 1,
      "z": -6,
      "name": "Cloth_Block_Wool_Cyan"
    },
    {
      "x": -9,
      "y": 2,
      "z": -6,
      "name": "Cloth_Block_Wool_Cyan"
    },
    {
      "x": -9,
      "y": 3,
      "z": -6,
      "name": "Cloth_Block_Wool_Cyan"
    },
    {
      "x": -9,
      "y": 4,
      "z": -6,
      "name": "Cloth_Block_Wool_Cyan"
    },
    {
      "x": -9,
      "y": 5,
      "z": -6,
      "name": "Cloth_Block_Wool_Cyan"
    },
    {
      "x": -9,
      "y": 6,
      "z": -6,
      "name": "Cloth_Block_Wool_Cyan"
    },
    {
      "x": -9,
      "y": 7,
      "z": -6,
      "name": "Cloth_Block_Wool_Cyan"
    },
    {
      "x": -9,
      "y": 8,
      "z": -6,
      "name": "Cloth_Block_Wool_Cyan"
    },
    {
      "x": -9,
      "y": 9,
      "z": -6,
      "name": "Cloth_Block_Wool_Cyan"
    },
    {
      "x": -9,
      "y": 10,
      "z": -6,
      "name": "Cloth_Block_Wool_Cyan"
    },
    {
      "x": -9,
      "y": 11,
      "z": -6,
      "name": "Cloth_Block_Wool_Cyan"
    },
    {
      "x": -9,
      "y": 12,
      "z": -6,
      "name": "Cloth_Block_Wool_Cyan"
    },
    {
      "x": -9,
      "y": 13,
      "z": -6,
      "name": "Cloth_Block_Wool_Cyan"
    },
    {
      "x": -9,
      "y": 14,
      "z": -6,
      "name": "Cloth_Block_Wool_Cyan"
    },
    {
      "x": -9,
      "y": 15,
      "z": -6,
      "name": "Cloth_Block_Wool_Cyan"
    },
    {
      "x": -9,
      "y": 16,
      "z": -6,
      "name": "Cloth_Block_Wool_Cyan"
    },
    {
      "x": -9,
      "y": 17,
      "z": -6,
      "name": "Cloth_Block_Wool_Cyan"
    },
    {
      "x": -9,
      "y": 18,
      "z": -6,
      "name": "Cloth_Block_Wool_Cyan"
    },
    {
      "x": -9,
      "y": 19,
      "z": -6,
      "name": "Cloth_Block_Wool_Cyan"
    },
    {
      "x": -9,
      "y": 20,
      "z": -6,
      "name": "Cloth_Block_Wool_Cyan"
    },
    {
      "x": -9,
      "y": 21,
      "z": -6,
      "name": "Cloth_Block_Wool_Cyan"
    },
    {
      "x": -9,
      "y": 22,
      "z": -6,
      "name": "Cloth_Block_Wool_Cyan"
    },
    {
      "x": -9,
      "y": 23,
      "z": -6,
      "name": "Cloth_Block_Wool_Cyan"
    },
    {
      "x": -9,
      "y": 24,
      "z": -6,
      "name": "Cloth_Block_Wool_Cyan"
    },
    {
      "x": -9,
      "y": 25,
      "z": -6,
      "name": "Cloth_Block_Wool_Cyan"
    },
    {
      "x": -9,
      "y": 26,
      "z": -6,
      "name": "Cloth_Block_Wool_Cyan"
    },
    {
      "x": -9,
      "y": 1,
      "z": -5,
      "name": "Cloth_Block_Wool_Cyan"
    },
    {
      "x": -9,
      "y": 2,
      "z": -5,
      "name": "Cloth_Block_Wool_Cyan"
    },
    {
      "x": -9,
      "y": 3,
      "z": -5,
      "name": "Cloth_Block_Wool_Cyan"
    },
    {
      "x": -9,
      "y": 4,
      "z": -5,
      "name": "Cloth_Block_Wool_Cyan"
    },
    {
      "x": -9,
      "y": 5,
      "z": -5,
      "name": "Cloth_Block_Wool_Cyan"
    },
    {
      "x": -9,
      "y": 6,
      "z": -5,
      "name": "Cloth_Block_Wool_Cyan"
    },
    {
      "x": -9,
      "y": 7,
      "z": -5,
      "name": "Cloth_Block_Wool_Cyan"
    },
    {
      "x": -9,
      "y": 8,
      "z": -5,
      "name": "Cloth_Block_Wool_Cyan"
    },
    {
      "x": -9,
      "y": 9,
      "z": -5,
      "name": "Cloth_Block_Wool_Cyan"
    },
    {
      "x": -9,
      "y": 10,
      "z": -5,
      "name": "Cloth_Block_Wool_Cyan"
    },
    {
      "x": -9,
      "y": 11,
      "z": -5,
      "name": "Cloth_Block_Wool_Cyan"
    },
    {
      "x": -9,
      "y": 12,
      "z": -5,
      "name": "Cloth_Block_Wool_Cyan"
    },
    {
      "x": -9,
      "y": 13,
      "z": -5,
      "name": "Cloth_Block_Wool_Cyan"
    },
    {
      "x": -9,
      "y": 14,
      "z": -5,
      "name": "Cloth_Block_Wool_Cyan"
    },
    {
      "x": -9,
      "y": 15,
      "z": -5,
      "name": "Cloth_Block_Wool_Cyan"
    },
    {
      "x": -9,
      "y": 16,
      "z": -5,
      "name": "Cloth_Block_Wool_Cyan"
    },
    {
      "x": -9,
      "y": 17,
      "z": -5,
      "name": "Cloth_Block_Wool_Cyan"
    },
    {
      "x": -9,
      "y": 18,
      "z": -5,
      "name": "Cloth_Block_Wool_Cyan"
    },
    {
      "x": -9,
      "y": 19,
      "z": -5,
      "name": "Cloth_Block_Wool_Cyan"
    },
    {
      "x": -9,
      "y": 20,
      "z": -5,
      "name": "Cloth_Block_Wool_Cyan"
    },
    {
      "x": -9,
      "y": 21,
      "z": -5,
      "name": "Cloth_Block_Wool_Cyan"
    },
    {
      "x": -9,
      "y": 22,
      "z": -5,
      "name": "Cloth_Block_Wool_Cyan"
    },
    {
      "x": -9,
      "y": 23,
      "z": -5,
      "name": "Cloth_Block_Wool_Cyan"
    },
    {
      "x": -9,
      "y": 24,
      "z": -5,
      "name": "Cloth_Block_Wool_Cyan"
    },
    {
      "x": -9,
      "y": 25,
      "z": -5,
      "name": "Cloth_Block_Wool_Cyan"
    },
    {
      "x": -9,
      "y": 26,
      "z": -5,
      "name": "Cloth_Block_Wool_Cyan"
    },
    {
      "x": -9,
      "y": 1,
      "z": -4,
      "name": "Cloth_Block_Wool_Cyan"
    },
    {
      "x": -9,
      "y": 2,
      "z": -4,
      "name": "Cloth_Block_Wool_Cyan"
    },
    {
      "x": -9,
      "y": 3,
      "z": -4,
      "name": "Cloth_Block_Wool_Cyan"
    },
    {
      "x": -9,
      "y": 4,
      "z": -4,
      "name": "Cloth_Block_Wool_Cyan"
    },
    {
      "x": -9,
      "y": 5,
      "z": -4,
      "name": "Cloth_Block_Wool_Cyan"
    },
    {
      "x": -9,
      "y": 6,
      "z": -4,
      "name": "Cloth_Block_Wool_Cyan"
    },
    {
      "x": -9,
      "y": 7,
      "z": -4,
      "name": "Cloth_Block_Wool_Cyan"
    },
    {
      "x": -9,
      "y": 8,
      "z": -4,
      "name": "Cloth_Block_Wool_Cyan"
    },
    {
      "x": -9,
      "y": 9,
      "z": -4,
      "name": "Cloth_Block_Wool_Cyan"
    },
    {
      "x": -9,
      "y": 10,
      "z": -4,
      "name": "Cloth_Block_Wool_Cyan"
    },
    {
      "x": -9,
      "y": 11,
      "z": -4,
      "name": "Cloth_Block_Wool_Cyan"
    },
    {
      "x": -9,
      "y": 12,
      "z": -4,
      "name": "Cloth_Block_Wool_Cyan"
    },
    {
      "x": -9,
      "y": 13,
      "z": -4,
      "name": "Cloth_Block_Wool_Cyan"
    },
    {
      "x": -9,
      "y": 14,
      "z": -4,
      "name": "Cloth_Block_Wool_Cyan"
    },
    {
      "x": -9,
      "y": 15,
      "z": -4,
      "name": "Cloth_Block_Wool_Cyan"
    },
    {
      "x": -9,
      "y": 16,
      "z": -4,
      "name": "Cloth_Block_Wool_Cyan"
    },
    {
      "x": -9,
      "y": 17,
      "z": -4,
      "name": "Cloth_Block_Wool_Cyan"
    },
    {
      "x": -9,
      "y": 18,
      "z": -4,
      "name": "Cloth_Block_Wool_Cyan"
    },
    {
      "x": -9,
      "y": 19,
      "z": -4,
      "name": "Cloth_Block_Wool_Cyan"
    },
    {
      "x": -9,
      "y": 20,
      "z": -4,
      "name": "Cloth_Block_Wool_Cyan"
    },
    {
      "x": -9,
      "y": 21,
      "z": -4,
      "name": "Cloth_Block_Wool_Cyan"
    },
    {
      "x": -9,
      "y": 22,
      "z": -4,
      "name": "Cloth_Block_Wool_Cyan"
    },
    {
      "x": -9,
      "y": 23,
      "z": -4,
      "name": "Cloth_Block_Wool_Cyan"
    },
    {
      "x": -9,
      "y": 24,
      "z": -4,
      "name": "Cloth_Block_Wool_Cyan"
    },
    {
      "x": -9,
      "y": 25,
      "z": -4,
      "name": "Cloth_Block_Wool_Cyan"
    },
    {
      "x": -9,
      "y": 26,
      "z": -4,
      "name": "Cloth_Block_Wool_Cyan"
    },
    {
      "x": -9,
      "y": 1,
      "z": -3,
      "name": "Cloth_Block_Wool_Cyan"
    },
    {
      "x": -9,
      "y": 2,
      "z": -3,
      "name": "Cloth_Block_Wool_Cyan"
    },
    {
      "x": -9,
      "y": 3,
      "z": -3,
      "name": "Cloth_Block_Wool_Cyan"
    },
    {
      "x": -9,
      "y": 4,
      "z": -3,
      "name": "Cloth_Block_Wool_Cyan"
    },
    {
      "x": -9,
      "y": 5,
      "z": -3,
      "name": "Cloth_Block_Wool_Cyan"
    },
    {
      "x": -9,
      "y": 6,
      "z": -3,
      "name": "Cloth_Block_Wool_Cyan"
    },
    {
      "x": -9,
      "y": 7,
      "z": -3,
      "name": "Cloth_Block_Wool_Cyan"
    },
    {
      "x": -9,
      "y": 8,
      "z": -3,
      "name": "Cloth_Block_Wool_Cyan"
    },
    {
      "x": -9,
      "y": 9,
      "z": -3,
      "name": "Cloth_Block_Wool_Cyan"
    },
    {
      "x": -9,
      "y": 10,
      "z": -3,
      "name": "Cloth_Block_Wool_Cyan"
    },
    {
      "x": -9,
      "y": 11,
      "z": -3,
      "name": "Cloth_Block_Wool_Cyan"
    },
    {
      "x": -9,
      "y": 12,
      "z": -3,
      "name": "Cloth_Block_Wool_Cyan"
    },
    {
      "x": -9,
      "y": 13,
      "z": -3,
      "name": "Cloth_Block_Wool_Cyan"
    },
    {
      "x": -9,
      "y": 14,
      "z": -3,
      "name": "Cloth_Block_Wool_Cyan"
    },
    {
      "x": -9,
      "y": 15,
      "z": -3,
      "name": "Cloth_Block_Wool_Cyan"
    },
    {
      "x": -9,
      "y": 16,
      "z": -3,
      "name": "Cloth_Block_Wool_Cyan"
    },
    {
      "x": -9,
      "y": 17,
      "z": -3,
      "name": "Cloth_Block_Wool_Cyan"
    },
    {
      "x": -9,
      "y": 18,
      "z": -3,
      "name": "Cloth_Block_Wool_Cyan"
    },
    {
      "x": -9,
      "y": 19,
      "z": -3,
      "name": "Cloth_Block_Wool_Cyan"
    },
    {
      "x": -9,
      "y": 20,
      "z": -3,
      "name": "Cloth_Block_Wool_Cyan"
    },
    {
      "x": -9,
      "y": 21,
      "z": -3,
      "name": "Cloth_Block_Wool_Cyan"
    },
    {
      "x": -9,
      "y": 22,
      "z": -3,
      "name": "Cloth_Block_Wool_Cyan"
    },
    {
      "x": -9,
      "y": 23,
      "z": -3,
      "name": "Cloth_Block_Wool_Cyan"
    },
    {
      "x": -9,
      "y": 24,
      "z": -3,
      "name": "Cloth_Block_Wool_Cyan"
    },
    {
      "x": -9,
      "y": 25,
      "z": -3,
      "name": "Cloth_Block_Wool_Cyan"
    },
    {
      "x": -9,
      "y": 26,
      "z": -3,
      "name": "Cloth_Block_Wool_Cyan"
    },
    {
      "x": -9,
      "y": 1,
      "z": -2,
      "name": "Cloth_Block_Wool_Cyan"
    },
    {
      "x": -9,
      "y": 2,
      "z": -2,
      "name": "Cloth_Block_Wool_Cyan"
    },
    {
      "x": -9,
      "y": 3,
      "z": -2,
      "name": "Cloth_Block_Wool_Cyan"
    },
    {
      "x": -9,
      "y": 4,
      "z": -2,
      "name": "Cloth_Block_Wool_Cyan"
    },
    {
      "x": -9,
      "y": 5,
      "z": -2,
      "name": "Cloth_Block_Wool_Cyan"
    },
    {
      "x": -9,
      "y": 6,
      "z": -2,
      "name": "Cloth_Block_Wool_Cyan"
    },
    {
      "x": -9,
      "y": 7,
      "z": -2,
      "name": "Cloth_Block_Wool_Cyan"
    },
    {
      "x": -9,
      "y": 8,
      "z": -2,
      "name": "Cloth_Block_Wool_Cyan"
    },
    {
      "x": -9,
      "y": 9,
      "z": -2,
      "name": "Cloth_Block_Wool_Cyan"
    },
    {
      "x": -9,
      "y": 10,
      "z": -2,
      "name": "Cloth_Block_Wool_Cyan"
    },
    {
      "x": -9,
      "y": 11,
      "z": -2,
      "name": "Cloth_Block_Wool_Cyan"
    },
    {
      "x": -9,
      "y": 12,
      "z": -2,
      "name": "Cloth_Block_Wool_Cyan"
    },
    {
      "x": -9,
      "y": 13,
      "z": -2,
      "name": "Cloth_Block_Wool_Cyan"
    },
    {
      "x": -9,
      "y": 14,
      "z": -2,
      "name": "Cloth_Block_Wool_Cyan"
    },
    {
      "x": -9,
      "y": 15,
      "z": -2,
      "name": "Cloth_Block_Wool_Cyan"
    },
    {
      "x": -9,
      "y": 16,
      "z": -2,
      "name": "Cloth_Block_Wool_Cyan"
    },
    {
      "x": -9,
      "y": 17,
      "z": -2,
      "name": "Cloth_Block_Wool_Cyan"
    },
    {
      "x": -9,
      "y": 18,
      "z": -2,
      "name": "Cloth_Block_Wool_Cyan"
    },
    {
      "x": -9,
      "y": 19,
      "z": -2,
      "name": "Cloth_Block_Wool_Cyan"
    },
    {
      "x": -9,
      "y": 20,
      "z": -2,
      "name": "Cloth_Block_Wool_Cyan"
    },
    {
      "x": -9,
      "y": 21,
      "z": -2,
      "name": "Cloth_Block_Wool_Cyan"
    },
    {
      "x": -9,
      "y": 22,
      "z": -2,
      "name": "Cloth_Block_Wool_Cyan"
    },
    {
      "x": -9,
      "y": 23,
      "z": -2,
      "name": "Cloth_Block_Wool_Cyan"
    },
    {
      "x": -9,
      "y": 24,
      "z": -2,
      "name": "Cloth_Block_Wool_Cyan"
    },
    {
      "x": -9,
      "y": 25,
      "z": -2,
      "name": "Cloth_Block_Wool_Cyan"
    },
    {
      "x": -9,
      "y": 26,
      "z": -2,
      "name": "Cloth_Block_Wool_Cyan"
    },
    {
      "x": -9,
      "y": 1,
      "z": -1,
      "name": "Cloth_Block_Wool_Cyan"
    },
    {
      "x": -9,
      "y": 2,
      "z": -1,
      "name": "Cloth_Block_Wool_Cyan"
    },
    {
      "x": -9,
      "y": 3,
      "z": -1,
      "name": "Cloth_Block_Wool_Cyan"
    },
    {
      "x": -9,
      "y": 4,
      "z": -1,
      "name": "Cloth_Block_Wool_Cyan"
    },
    {
      "x": -9,
      "y": 5,
      "z": -1,
      "name": "Cloth_Block_Wool_Cyan"
    },
    {
      "x": -9,
      "y": 6,
      "z": -1,
      "name": "Cloth_Block_Wool_Cyan"
    },
    {
      "x": -9,
      "y": 7,
      "z": -1,
      "name": "Cloth_Block_Wool_Cyan"
    },
    {
      "x": -9,
      "y": 8,
      "z": -1,
      "name": "Cloth_Block_Wool_Cyan"
    },
    {
      "x": -9,
      "y": 9,
      "z": -1,
      "name": "Cloth_Block_Wool_Cyan"
    },
    {
      "x": -9,
      "y": 10,
      "z": -1,
      "name": "Cloth_Block_Wool_Cyan"
    },
    {
      "x": -9,
      "y": 11,
      "z": -1,
      "name": "Cloth_Block_Wool_Cyan"
    },
    {
      "x": -9,
      "y": 12,
      "z": -1,
      "name": "Cloth_Block_Wool_Cyan"
    },
    {
      "x": -9,
      "y": 13,
      "z": -1,
      "name": "Cloth_Block_Wool_Cyan"
    },
    {
      "x": -9,
      "y": 14,
      "z": -1,
      "name": "Cloth_Block_Wool_Cyan"
    },
    {
      "x": -9,
      "y": 15,
      "z": -1,
      "name": "Cloth_Block_Wool_Cyan"
    },
    {
      "x": -9,
      "y": 16,
      "z": -1,
      "name": "Cloth_Block_Wool_Cyan"
    },
    {
      "x": -9,
      "y": 17,
      "z": -1,
      "name": "Cloth_Block_Wool_Cyan"
    },
    {
      "x": -9,
      "y": 18,
      "z": -1,
      "name": "Cloth_Block_Wool_Cyan"
    },
    {
      "x": -9,
      "y": 19,
      "z": -1,
      "name": "Cloth_Block_Wool_Cyan"
    },
    {
      "x": -9,
      "y": 20,
      "z": -1,
      "name": "Cloth_Block_Wool_Cyan"
    },
    {
      "x": -9,
      "y": 21,
      "z": -1,
      "name": "Cloth_Block_Wool_Cyan"
    },
    {
      "x": -9,
      "y": 22,
      "z": -1,
      "name": "Cloth_Block_Wool_Cyan"
    },
    {
      "x": -9,
      "y": 23,
      "z": -1,
      "name": "Cloth_Block_Wool_Cyan"
    },
    {
      "x": -9,
      "y": 24,
      "z": -1,
      "name": "Cloth_Block_Wool_Cyan"
    },
    {
      "x": -9,
      "y": 25,
      "z": -1,
      "name": "Cloth_Block_Wool_Cyan"
    },
    {
      "x": -9,
      "y": 26,
      "z": -1,
      "name": "Cloth_Block_Wool_Cyan"
    },
    {
      "x": -8,
      "y": 1,
      "z": -8,
      "name": "Cloth_Block_Wool_Cyan"
    },
    {
      "x": -8,
      "y": 2,
      "z": -8,
      "name": "Cloth_Block_Wool_Cyan"
    },
    {
      "x": -8,
      "y": 3,
      "z": -8,
      "name": "Cloth_Block_Wool_Cyan"
    },
    {
      "x": -8,
      "y": 4,
      "z": -8,
      "name": "Cloth_Block_Wool_Cyan"
    },
    {
      "x": -8,
      "y": 5,
      "z": -8,
      "name": "Cloth_Block_Wool_Cyan"
    },
    {
      "x": -8,
      "y": 6,
      "z": -8,
      "name": "Cloth_Block_Wool_Cyan"
    },
    {
      "x": -8,
      "y": 7,
      "z": -8,
      "name": "Cloth_Block_Wool_Cyan"
    },
    {
      "x": -8,
      "y": 8,
      "z": -8,
      "name": "Cloth_Block_Wool_Cyan"
    },
    {
      "x": -8,
      "y": 9,
      "z": -8,
      "name": "Cloth_Block_Wool_Cyan"
    },
    {
      "x": -8,
      "y": 10,
      "z": -8,
      "name": "Cloth_Block_Wool_Cyan"
    },
    {
      "x": -8,
      "y": 11,
      "z": -8,
      "name": "Cloth_Block_Wool_Cyan"
    },
    {
      "x": -8,
      "y": 12,
      "z": -8,
      "name": "Cloth_Block_Wool_Cyan"
    },
    {
      "x": -8,
      "y": 13,
      "z": -8,
      "name": "Cloth_Block_Wool_Cyan"
    },
    {
      "x": -8,
      "y": 14,
      "z": -8,
      "name": "Cloth_Block_Wool_Cyan"
    },
    {
      "x": -8,
      "y": 15,
      "z": -8,
      "name": "Cloth_Block_Wool_Cyan"
    },
    {
      "x": -8,
      "y": 16,
      "z": -8,
      "name": "Cloth_Block_Wool_Cyan"
    },
    {
      "x": -8,
      "y": 17,
      "z": -8,
      "name": "Cloth_Block_Wool_Cyan"
    },
    {
      "x": -8,
      "y": 18,
      "z": -8,
      "name": "Cloth_Block_Wool_Cyan"
    },
    {
      "x": -8,
      "y": 19,
      "z": -8,
      "name": "Cloth_Block_Wool_Cyan"
    },
    {
      "x": -8,
      "y": 20,
      "z": -8,
      "name": "Cloth_Block_Wool_Cyan"
    },
    {
      "x": -8,
      "y": 21,
      "z": -8,
      "name": "Cloth_Block_Wool_Cyan"
    },
    {
      "x": -8,
      "y": 22,
      "z": -8,
      "name": "Cloth_Block_Wool_Cyan"
    },
    {
      "x": -8,
      "y": 23,
      "z": -8,
      "name": "Cloth_Block_Wool_Cyan"
    },
    {
      "x": -8,
      "y": 24,
      "z": -8,
      "name": "Cloth_Block_Wool_Cyan"
    },
    {
      "x": -8,
      "y": 25,
      "z": -8,
      "name": "Cloth_Block_Wool_Cyan"
    },
    {
      "x": -8,
      "y": 26,
      "z": -8,
      "name": "Cloth_Block_Wool_Cyan"
    },
    {
      "x": -8,
      "y": 1,
      "z": -7,
      "name": "Cloth_Block_Wool_Cyan"
    },
    {
      "x": -8,
      "y": 2,
      "z": -7,
      "name": "Cloth_Block_Wool_Cyan"
    },
    {
      "x": -8,
      "y": 3,
      "z": -7,
      "name": "Cloth_Block_Wool_Cyan"
    },
    {
      "x": -8,
      "y": 4,
      "z": -7,
      "name": "Cloth_Block_Wool_Cyan"
    },
    {
      "x": -8,
      "y": 5,
      "z": -7,
      "name": "Cloth_Block_Wool_Cyan"
    },
    {
      "x": -8,
      "y": 6,
      "z": -7,
      "name": "Cloth_Block_Wool_Cyan"
    },
    {
      "x": -8,
      "y": 7,
      "z": -7,
      "name": "Cloth_Block_Wool_Cyan"
    },
    {
      "x": -8,
      "y": 8,
      "z": -7,
      "name": "Cloth_Block_Wool_Cyan"
    },
    {
      "x": -8,
      "y": 9,
      "z": -7,
      "name": "Cloth_Block_Wool_Cyan"
    },
    {
      "x": -8,
      "y": 10,
      "z": -7,
      "name": "Cloth_Block_Wool_Cyan"
    },
    {
      "x": -8,
      "y": 11,
      "z": -7,
      "name": "Cloth_Block_Wool_Cyan"
    },
    {
      "x": -8,
      "y": 12,
      "z": -7,
      "name": "Cloth_Block_Wool_Cyan"
    },
    {
      "x": -8,
      "y": 13,
      "z": -7,
      "name": "Cloth_Block_Wool_Cyan"
    },
    {
      "x": -8,
      "y": 14,
      "z": -7,
      "name": "Cloth_Block_Wool_Cyan"
    },
    {
      "x": -8,
      "y": 15,
      "z": -7,
      "name": "Cloth_Block_Wool_Cyan"
    },
    {
      "x": -8,
      "y": 16,
      "z": -7,
      "name": "Cloth_Block_Wool_Cyan"
    },
    {
      "x": -8,
      "y": 17,
      "z": -7,
      "name": "Cloth_Block_Wool_Cyan"
    },
    {
      "x": -8,
      "y": 18,
      "z": -7,
      "name": "Cloth_Block_Wool_Cyan"
    },
    {
      "x": -8,
      "y": 19,
      "z": -7,
      "name": "Cloth_Block_Wool_Cyan"
    },
    {
      "x": -8,
      "y": 20,
      "z": -7,
      "name": "Cloth_Block_Wool_Cyan"
    },
    {
      "x": -8,
      "y": 21,
      "z": -7,
      "name": "Cloth_Block_Wool_Cyan"
    },
    {
      "x": -8,
      "y": 22,
      "z": -7,
      "name": "Cloth_Block_Wool_Cyan"
    },
    {
      "x": -8,
      "y": 23,
      "z": -7,
      "name": "Cloth_Block_Wool_Cyan"
    },
    {
      "x": -8,
      "y": 24,
      "z": -7,
      "name": "Cloth_Block_Wool_Cyan"
    },
    {
      "x": -8,
      "y": 25,
      "z": -7,
      "name": "Cloth_Block_Wool_Cyan"
    },
    {
      "x": -8,
      "y": 26,
      "z": -7,
      "name": "Cloth_Block_Wool_Cyan"
    },
    {
      "x": -8,
      "y": 1,
      "z": -6,
      "name": "Cloth_Block_Wool_Cyan"
    },
    {
      "x": -8,
      "y": 2,
      "z": -6,
      "name": "Cloth_Block_Wool_Cyan"
    },
    {
      "x": -8,
      "y": 3,
      "z": -6,
      "name": "Cloth_Block_Wool_Cyan"
    },
    {
      "x": -8,
      "y": 4,
      "z": -6,
      "name": "Cloth_Block_Wool_Cyan"
    },
    {
      "x": -8,
      "y": 5,
      "z": -6,
      "name": "Cloth_Block_Wool_Cyan"
    },
    {
      "x": -8,
      "y": 6,
      "z": -6,
      "name": "Cloth_Block_Wool_Cyan"
    },
    {
      "x": -8,
      "y": 7,
      "z": -6,
      "name": "Cloth_Block_Wool_Cyan"
    },
    {
      "x": -8,
      "y": 8,
      "z": -6,
      "name": "Cloth_Block_Wool_Cyan"
    },
    {
      "x": -8,
      "y": 9,
      "z": -6,
      "name": "Cloth_Block_Wool_Cyan"
    },
    {
      "x": -8,
      "y": 10,
      "z": -6,
      "name": "Cloth_Block_Wool_Cyan"
    },
    {
      "x": -8,
      "y": 11,
      "z": -6,
      "name": "Cloth_Block_Wool_Cyan"
    },
    {
      "x": -8,
      "y": 12,
      "z": -6,
      "name": "Cloth_Block_Wool_Cyan"
    },
    {
      "x": -8,
      "y": 13,
      "z": -6,
      "name": "Cloth_Block_Wool_Cyan"
    },
    {
      "x": -8,
      "y": 14,
      "z": -6,
      "name": "Cloth_Block_Wool_Cyan"
    },
    {
      "x": -8,
      "y": 15,
      "z": -6,
      "name": "Cloth_Block_Wool_Cyan"
    },
    {
      "x": -8,
      "y": 16,
      "z": -6,
      "name": "Cloth_Block_Wool_Cyan"
    },
    {
      "x": -8,
      "y": 17,
      "z": -6,
      "name": "Cloth_Block_Wool_Cyan"
    },
    {
      "x": -8,
      "y": 18,
      "z": -6,
      "name": "Cloth_Block_Wool_Cyan"
    },
    {
      "x": -8,
      "y": 19,
      "z": -6,
      "name": "Cloth_Block_Wool_Cyan"
    },
    {
      "x": -8,
      "y": 20,
      "z": -6,
      "name": "Cloth_Block_Wool_Cyan"
    },
    {
      "x": -8,
      "y": 21,
      "z": -6,
      "name": "Cloth_Block_Wool_Cyan"
    },
    {
      "x": -8,
      "y": 22,
      "z": -6,
      "name": "Cloth_Block_Wool_Cyan"
    },
    {
      "x": -8,
      "y": 23,
      "z": -6,
      "name": "Cloth_Block_Wool_Cyan"
    },
    {
      "x": -8,
      "y": 24,
      "z": -6,
      "name": "Cloth_Block_Wool_Cyan"
    },
    {
      "x": -8,
      "y": 25,
      "z": -6,
      "name": "Cloth_Block_Wool_Cyan"
    },
    {
      "x": -8,
      "y": 26,
      "z": -6,
      "name": "Cloth_Block_Wool_Cyan"
    },
    {
      "x": -8,
      "y": 1,
      "z": -5,
      "name": "Cloth_Block_Wool_Cyan"
    },
    {
      "x": -8,
      "y": 2,
      "z": -5,
      "name": "Cloth_Block_Wool_Cyan"
    },
    {
      "x": -8,
      "y": 3,
      "z": -5,
      "name": "Cloth_Block_Wool_Cyan"
    },
    {
      "x": -8,
      "y": 4,
      "z": -5,
      "name": "Cloth_Block_Wool_Cyan"
    },
    {
      "x": -8,
      "y": 5,
      "z": -5,
      "name": "Cloth_Block_Wool_Cyan"
    },
    {
      "x": -8,
      "y": 6,
      "z": -5,
      "name": "Cloth_Block_Wool_Cyan"
    },
    {
      "x": -8,
      "y": 7,
      "z": -5,
      "name": "Cloth_Block_Wool_Cyan"
    },
    {
      "x": -8,
      "y": 8,
      "z": -5,
      "name": "Cloth_Block_Wool_Cyan"
    },
    {
      "x": -8,
      "y": 9,
      "z": -5,
      "name": "Cloth_Block_Wool_Cyan"
    },
    {
      "x": -8,
      "y": 10,
      "z": -5,
      "name": "Cloth_Block_Wool_Cyan"
    },
    {
      "x": -8,
      "y": 11,
      "z": -5,
      "name": "Cloth_Block_Wool_Cyan"
    },
    {
      "x": -8,
      "y": 12,
      "z": -5,
      "name": "Cloth_Block_Wool_Cyan"
    },
    {
      "x": -8,
      "y": 13,
      "z": -5,
      "name": "Cloth_Block_Wool_Cyan"
    },
    {
      "x": -8,
      "y": 14,
      "z": -5,
      "name": "Cloth_Block_Wool_Cyan"
    },
    {
      "x": -8,
      "y": 15,
      "z": -5,
      "name": "Cloth_Block_Wool_Cyan"
    },
    {
      "x": -8,
      "y": 16,
      "z": -5,
      "name": "Cloth_Block_Wool_Cyan"
    },
    {
      "x": -8,
      "y": 17,
      "z": -5,
      "name": "Cloth_Block_Wool_Cyan"
    },
    {
      "x": -8,
      "y": 18,
      "z": -5,
      "name": "Cloth_Block_Wool_Cyan"
    },
    {
      "x": -8,
      "y": 19,
      "z": -5,
      "name": "Cloth_Block_Wool_Cyan"
    },
    {
      "x": -8,
      "y": 20,
      "z": -5,
      "name": "Cloth_Block_Wool_Cyan"
    },
    {
      "x": -8,
      "y": 21,
      "z": -5,
      "name": "Cloth_Block_Wool_Cyan"
    },
    {
      "x": -8,
      "y": 22,
      "z": -5,
      "name": "Cloth_Block_Wool_Cyan"
    },
    {
      "x": -8,
      "y": 23,
      "z": -5,
      "name": "Cloth_Block_Wool_Cyan"
    },
    {
      "x": -8,
      "y": 24,
      "z": -5,
      "name": "Cloth_Block_Wool_Cyan"
    },
    {
      "x": -8,
      "y": 25,
      "z": -5,
      "name": "Cloth_Block_Wool_Cyan"
    },
    {
      "x": -8,
      "y": 26,
      "z": -5,
      "name": "Cloth_Block_Wool_Cyan"
    },
    {
      "x": -8,
      "y": 1,
      "z": -4,
      "name": "Cloth_Block_Wool_Cyan"
    },
    {
      "x": -8,
      "y": 2,
      "z": -4,
      "name": "Cloth_Block_Wool_Cyan"
    },
    {
      "x": -8,
      "y": 3,
      "z": -4,
      "name": "Cloth_Block_Wool_Cyan"
    },
    {
      "x": -8,
      "y": 4,
      "z": -4,
      "name": "Cloth_Block_Wool_Cyan"
    },
    {
      "x": -8,
      "y": 5,
      "z": -4,
      "name": "Cloth_Block_Wool_Cyan"
    },
    {
      "x": -8,
      "y": 6,
      "z": -4,
      "name": "Cloth_Block_Wool_Cyan"
    },
    {
      "x": -8,
      "y": 7,
      "z": -4,
      "name": "Cloth_Block_Wool_Cyan"
    },
    {
      "x": -8,
      "y": 8,
      "z": -4,
      "name": "Cloth_Block_Wool_Cyan"
    },
    {
      "x": -8,
      "y": 9,
      "z": -4,
      "name": "Cloth_Block_Wool_Cyan"
    },
    {
      "x": -8,
      "y": 10,
      "z": -4,
      "name": "Cloth_Block_Wool_Cyan"
    },
    {
      "x": -8,
      "y": 11,
      "z": -4,
      "name": "Cloth_Block_Wool_Cyan"
    },
    {
      "x": -8,
      "y": 12,
      "z": -4,
      "name": "Cloth_Block_Wool_Cyan"
    },
    {
      "x": -8,
      "y": 13,
      "z": -4,
      "name": "Cloth_Block_Wool_Cyan"
    },
    {
      "x": -8,
      "y": 14,
      "z": -4,
      "name": "Cloth_Block_Wool_Cyan"
    },
    {
      "x": -8,
      "y": 15,
      "z": -4,
      "name": "Cloth_Block_Wool_Cyan"
    },
    {
      "x": -8,
      "y": 16,
      "z": -4,
      "name": "Cloth_Block_Wool_Cyan"
    },
    {
      "x": -8,
      "y": 17,
      "z": -4,
      "name": "Cloth_Block_Wool_Cyan"
    },
    {
      "x": -8,
      "y": 18,
      "z": -4,
      "name": "Cloth_Block_Wool_Cyan"
    },
    {
      "x": -8,
      "y": 19,
      "z": -4,
      "name": "Cloth_Block_Wool_Cyan"
    },
    {
      "x": -8,
      "y": 20,
      "z": -4,
      "name": "Cloth_Block_Wool_Cyan"
    },
    {
      "x": -8,
      "y": 21,
      "z": -4,
      "name": "Cloth_Block_Wool_Cyan"
    },
    {
      "x": -8,
      "y": 22,
      "z": -4,
      "name": "Cloth_Block_Wool_Cyan"
    },
    {
      "x": -8,
      "y": 23,
      "z": -4,
      "name": "Cloth_Block_Wool_Cyan"
    },
    {
      "x": -8,
      "y": 24,
      "z": -4,
      "name": "Cloth_Block_Wool_Cyan"
    },
    {
      "x": -8,
      "y": 25,
      "z": -4,
      "name": "Cloth_Block_Wool_Cyan"
    },
    {
      "x": -8,
      "y": 26,
      "z": -4,
      "name": "Cloth_Block_Wool_Cyan"
    },
    {
      "x": -8,
      "y": 1,
      "z": -3,
      "name": "Cloth_Block_Wool_Cyan"
    },
    {
      "x": -8,
      "y": 2,
      "z": -3,
      "name": "Cloth_Block_Wool_Cyan"
    },
    {
      "x": -8,
      "y": 3,
      "z": -3,
      "name": "Cloth_Block_Wool_Cyan"
    },
    {
      "x": -8,
      "y": 4,
      "z": -3,
      "name": "Cloth_Block_Wool_Cyan"
    },
    {
      "x": -8,
      "y": 5,
      "z": -3,
      "name": "Cloth_Block_Wool_Cyan"
    },
    {
      "x": -8,
      "y": 6,
      "z": -3,
      "name": "Cloth_Block_Wool_Cyan"
    },
    {
      "x": -8,
      "y": 7,
      "z": -3,
      "name": "Cloth_Block_Wool_Cyan"
    },
    {
      "x": -8,
      "y": 8,
      "z": -3,
      "name": "Cloth_Block_Wool_Cyan"
    },
    {
      "x": -8,
      "y": 9,
      "z": -3,
      "name": "Cloth_Block_Wool_Cyan"
    },
    {
      "x": -8,
      "y": 10,
      "z": -3,
      "name": "Cloth_Block_Wool_Cyan"
    },
    {
      "x": -8,
      "y": 11,
      "z": -3,
      "name": "Cloth_Block_Wool_Cyan"
    },
    {
      "x": -8,
      "y": 12,
      "z": -3,
      "name": "Cloth_Block_Wool_Cyan"
    },
    {
      "x": -8,
      "y": 13,
      "z": -3,
      "name": "Cloth_Block_Wool_Cyan"
    },
    {
      "x": -8,
      "y": 14,
      "z": -3,
      "name": "Cloth_Block_Wool_Cyan"
    },
    {
      "x": -8,
      "y": 15,
      "z": -3,
      "name": "Cloth_Block_Wool_Cyan"
    },
    {
      "x": -8,
      "y": 16,
      "z": -3,
      "name": "Cloth_Block_Wool_Cyan"
    },
    {
      "x": -8,
      "y": 17,
      "z": -3,
      "name": "Cloth_Block_Wool_Cyan"
    },
    {
      "x": -8,
      "y": 18,
      "z": -3,
      "name": "Cloth_Block_Wool_Cyan"
    },
    {
      "x": -8,
      "y": 19,
      "z": -3,
      "name": "Cloth_Block_Wool_Cyan"
    },
    {
      "x": -8,
      "y": 20,
      "z": -3,
      "name": "Cloth_Block_Wool_Cyan"
    },
    {
      "x": -8,
      "y": 21,
      "z": -3,
      "name": "Cloth_Block_Wool_Cyan"
    },
    {
      "x": -8,
      "y": 22,
      "z": -3,
      "name": "Cloth_Block_Wool_Cyan"
    },
    {
      "x": -8,
      "y": 23,
      "z": -3,
      "name": "Cloth_Block_Wool_Cyan"
    },
    {
      "x": -8,
      "y": 24,
      "z": -3,
      "name": "Cloth_Block_Wool_Cyan"
    },
    {
      "x": -8,
      "y": 25,
      "z": -3,
      "name": "Cloth_Block_Wool_Cyan"
    },
    {
      "x": -8,
      "y": 26,
      "z": -3,
      "name": "Cloth_Block_Wool_Cyan"
    },
    {
      "x": -8,
      "y": 1,
      "z": -2,
      "name": "Cloth_Block_Wool_Cyan"
    },
    {
      "x": -8,
      "y": 2,
      "z": -2,
      "name": "Cloth_Block_Wool_Cyan"
    },
    {
      "x": -8,
      "y": 3,
      "z": -2,
      "name": "Cloth_Block_Wool_Cyan"
    },
    {
      "x": -8,
      "y": 4,
      "z": -2,
      "name": "Cloth_Block_Wool_Cyan"
    },
    {
      "x": -8,
      "y": 5,
      "z": -2,
      "name": "Cloth_Block_Wool_Cyan"
    },
    {
      "x": -8,
      "y": 6,
      "z": -2,
      "name": "Cloth_Block_Wool_Cyan"
    },
    {
      "x": -8,
      "y": 7,
      "z": -2,
      "name": "Cloth_Block_Wool_Cyan"
    },
    {
      "x": -8,
      "y": 8,
      "z": -2,
      "name": "Cloth_Block_Wool_Cyan"
    },
    {
      "x": -8,
      "y": 9,
      "z": -2,
      "name": "Cloth_Block_Wool_Cyan"
    },
    {
      "x": -8,
      "y": 10,
      "z": -2,
      "name": "Cloth_Block_Wool_Cyan"
    },
    {
      "x": -8,
      "y": 11,
      "z": -2,
      "name": "Cloth_Block_Wool_Cyan"
    },
    {
      "x": -8,
      "y": 12,
      "z": -2,
      "name": "Cloth_Block_Wool_Cyan"
    },
    {
      "x": -8,
      "y": 13,
      "z": -2,
      "name": "Cloth_Block_Wool_Cyan"
    },
    {
      "x": -8,
      "y": 14,
      "z": -2,
      "name": "Cloth_Block_Wool_Cyan"
    },
    {
      "x": -8,
      "y": 15,
      "z": -2,
      "name": "Cloth_Block_Wool_Cyan"
    },
    {
      "x": -8,
      "y": 16,
      "z": -2,
      "name": "Cloth_Block_Wool_Cyan"
    },
    {
      "x": -8,
      "y": 17,
      "z": -2,
      "name": "Cloth_Block_Wool_Cyan"
    },
    {
      "x": -8,
      "y": 18,
      "z": -2,
      "name": "Cloth_Block_Wool_Cyan"
    },
    {
      "x": -8,
      "y": 19,
      "z": -2,
      "name": "Cloth_Block_Wool_Cyan"
    },
    {
      "x": -8,
      "y": 20,
      "z": -2,
      "name": "Cloth_Block_Wool_Cyan"
    },
    {
      "x": -8,
      "y": 21,
      "z": -2,
      "name": "Cloth_Block_Wool_Cyan"
    },
    {
      "x": -8,
      "y": 22,
      "z": -2,
      "name": "Cloth_Block_Wool_Cyan"
    },
    {
      "x": -8,
      "y": 23,
      "z": -2,
      "name": "Cloth_Block_Wool_Cyan"
    },
    {
      "x": -8,
      "y": 24,
      "z": -2,
      "name": "Cloth_Block_Wool_Cyan"
    },
    {
      "x": -8,
      "y": 25,
      "z": -2,
      "name": "Cloth_Block_Wool_Cyan"
    },
    {
      "x": -8,
      "y": 26,
      "z": -2,
      "name": "Cloth_Block_Wool_Cyan"
    },
    {
      "x": -8,
      "y": 1,
      "z": -1,
      "name": "Cloth_Block_Wool_Cyan"
    },
    {
      "x": -8,
      "y": 2,
      "z": -1,
      "name": "Cloth_Block_Wool_Cyan"
    },
    {
      "x": -8,
      "y": 3,
      "z": -1,
      "name": "Cloth_Block_Wool_Cyan"
    },
    {
      "x": -8,
      "y": 4,
      "z": -1,
      "name": "Cloth_Block_Wool_Cyan"
    },
    {
      "x": -8,
      "y": 5,
      "z": -1,
      "name": "Cloth_Block_Wool_Cyan"
    },
    {
      "x": -8,
      "y": 6,
      "z": -1,
      "name": "Cloth_Block_Wool_Cyan"
    },
    {
      "x": -8,
      "y": 7,
      "z": -1,
      "name": "Cloth_Block_Wool_Cyan"
    },
    {
      "x": -8,
      "y": 8,
      "z": -1,
      "name": "Cloth_Block_Wool_Cyan"
    },
    {
      "x": -8,
      "y": 9,
      "z": -1,
      "name": "Cloth_Block_Wool_Cyan"
    },
    {
      "x": -8,
      "y": 10,
      "z": -1,
      "name": "Cloth_Block_Wool_Cyan"
    },
    {
      "x": -8,
      "y": 11,
      "z": -1,
      "name": "Cloth_Block_Wool_Cyan"
    },
    {
      "x": -8,
      "y": 12,
      "z": -1,
      "name": "Cloth_Block_Wool_Cyan"
    },
    {
      "x": -8,
      "y": 13,
      "z": -1,
      "name": "Cloth_Block_Wool_Cyan"
    },
    {
      "x": -8,
      "y": 14,
      "z": -1,
      "name": "Cloth_Block_Wool_Cyan"
    },
    {
      "x": -8,
      "y": 15,
      "z": -1,
      "name": "Cloth_Block_Wool_Cyan"
    },
    {
      "x": -8,
      "y": 16,
      "z": -1,
      "name": "Cloth_Block_Wool_Cyan"
    },
    {
      "x": -8,
      "y": 17,
      "z": -1,
      "name": "Cloth_Block_Wool_Cyan"
    },
    {
      "x": -8,
      "y": 18,
      "z": -1,
      "name": "Cloth_Block_Wool_Cyan"
    },
    {
      "x": -8,
      "y": 19,
      "z": -1,
      "name": "Cloth_Block_Wool_Cyan"
    },
    {
      "x": -8,
      "y": 20,
      "z": -1,
      "name": "Cloth_Block_Wool_Cyan"
    },
    {
      "x": -8,
      "y": 21,
      "z": -1,
      "name": "Cloth_Block_Wool_Cyan"
    },
    {
      "x": -8,
      "y": 22,
      "z": -1,
      "name": "Cloth_Block_Wool_Cyan"
    },
    {
      "x": -8,
      "y": 23,
      "z": -1,
      "name": "Cloth_Block_Wool_Cyan"
    },
    {
      "x": -8,
      "y": 24,
      "z": -1,
