{"anchorX":10,"anchorY":0,"anchorZ":10,"blockIdVersion":11,"blocks":[{"name":"Rock_Sandstone_Brick","x":0,"y":-35,"z":1},{"name":"Rock_Sandstone_Brick","x":0,"y":-34,"z":1},{"name":"Rock_Sandstone_Brick","x":0,"y":-33,"z":1},{"name":"Rock_Sandstone_Brick","x":0,"y":-32,"z":1},{"name":"Rock_Sandstone","x":0,"y":-31,"z":1},{"name":"Rock_Sandstone_Brick","x":0,"y":-30,"z":1},{"name":"Rock_Sandstone_Brick","x":0,"y":-29,"z":1},{"name":"Rock_Sandstone_Brick","x":0,"y":-28,"z":1},{"name":"Rock_Sandstone","x":0,"y":-27,"z":1},{"name":"Rock_Sandstone_Brick","x":0,"y":-26,"z":1},{"name":"Rock_Sandstone_Brick","rotation":3,"x":0,"y":-25,"z":1},{"name":"Rock_Sandstone_Brick","rotation":3,"x":0,"y":-24,"z":1},{"name":"Rock_Sandstone_Brick","rotation":3,"x":0,"y":-23,"z":1},{"name":"Rock_Sandstone_Brick","rotation":3,"x":0,"y":-22,"z":1},{"name":"Rock_Sandstone","rotation":3,"x":0,"y":-21,"z":1},{"name":"Rock_Sandstone_Brick","rotation":3,"x":0,"y":-20,"z":1},{"name":"Rock_Sandstone_Brick","rotation":3,"x":0,"y":-19,"z":1},{"name":"Rock_Sandstone_Brick","rotation":3,"x":0,"y":-18,"z":1},{"name":"Rock_Sandstone_Brick","rotation":3,"x":0,"y":-17,"z":1},{"name":"Rock_Sandstone_Brick","rotation":3,"x":0,"y":-16,"z":1},{"name":"Rock_Sandstone","rotation":3,"x":0,"y":-15,"z":1},{"name":"Rock_Sandstone_Brick","rotation":3,"x":0,"y":-14,"z":1},{"name":"Rock_Sandstone_Brick","rotation":3,"x":0,"y":-13,"z":1},{"name":"Rock_Sandstone_Brick","rotation":3,"x":0,"y":-12,"z":1},{"name":"Rock_Sandstone_Brick","rotation":3,"x":0,"y":-11,"z":1},{"name":"Rock_Sandstone_Brick","rotation":3,"x":0,"y":-10,"z":1},{"name":"Rock_Sandstone","rotation":3,"x":0,"y":-9,"z":1},{"name":"Rock_Sandstone_Brick","rotation":3,"x":0,"y":-8,"z":1},{"name":"Rock_Sandstone_Brick","rotation":3,"x":0,"y":-7,"z":1},{"name":"Rock_Sandstone_Brick","rotation":3,"x":0,"y":-6,"z":1},{"name":"Rock_Sandstone_Brick","rotation":3,"x":0,"y":-5,"z":1},{"name":"Rock_Sandstone_Brick","rotation":3,"x":0,"y":-4,"z":1},{"name":"Rock_Sandstone_Brick","rotation":3,"x":0,"y":-3,"z":1},{"name":"Rock_Sandstone_Brick","rotation":3,"x":0,"y":-2,"z":1},{"name":"Rock_Sandstone_Brick","rotation":3,"x":0,"y":-1,"z":1},{"name":"Rock_Sandstone_Brick","x":0,"y":0,"z":1},{"name":"Rock_Sandstone_Cobble","x":0,"y":-35,"z":2},{"name":"Rock_Sandstone_Brick","x":0,"y":-34,"z":2},{"name":"Rock_Sandstone_Brick","x":0,"y":-33,"z":2},{"name":"Rock_Sandstone_Brick","x":0,"y":-32,"z":2},{"name":"Rock_Sandstone_Brick","x":0,"y":-31,"z":2},{"name":"Rock_Sandstone_Brick","x":0,"y":-30,"z":2},{"name":"Rock_Sandstone","x":0,"y":-29,"z":2},{"name":"Rock_Sandstone_Cobble","x":0,"y":-28,"z":2},{"name":"Rock_Sandstone_Brick","x":0,"y":-27,"z":2},{"name":"Rock_Sandstone_Cobble","x":0,"y":-26,"z":2},{"name":"Rock_Sandstone_Brick","rotation":3,"x":0,"y":-25,"z":2},{"name":"Rock_Sandstone_Brick","rotation":3,"x":0,"y":-24,"z":2},{"name":"Rock_Sandstone_Brick","rotation":3,"x":0,"y":-23,"z":2},{"name":"Rock_Sandstone_Brick","rotation":3,"x":0,"y":-22,"z":2},{"name":"Rock_Sandstone_Brick","rotation":3,"x":0,"y":-21,"z":2},{"name":"Rock_Sandstone","rotation":3,"x":0,"y":-20,"z":2},{"name":"Rock_Sandstone_Brick","rotation":3,"x":0,"y":-19,"z":2},{"name":"Rock_Sandstone_Brick","rotation":3,"x":0,"y":-18,"z":2},{"name":"Rock_Sandstone","rotation":3,"x":0,"y":-17,"z":2},{"name":"Rock_Sandstone_Brick","rotation":3,"x":0,"y":-16,"z":2},{"name":"Rock_Sandstone_Brick","rotation":3,"x":0,"y":-15,"z":2},{"name":"Rock_Sandstone","rotation":3,"x":0,"y":-14,"z":2},{"name":"Rock_Sandstone_Brick","rotation":3,"x":0,"y":-13,"z":2},{"name":"Rock_Sandstone_Cobble","rotation":3,"x":0,"y":-12,"z":2},{"name":"Rock_Sandstone_Brick","rotation":3,"x":0,"y":-11,"z":2},{"name":"Rock_Sandstone_Cobble","rotation":3,"x":0,"y":-10,"z":2},{"name":"Rock_Sandstone_Brick","rotation":3,"x":0,"y":-9,"z":2},{"name":"Rock_Sandstone_Brick","rotation":3,"x":0,"y":-8,"z":2},{"name":"Rock_Sandstone_Brick","rotation":3,"x":0,"y":-7,"z":2},{"name":"Rock_Sandstone_Brick","rotation":3,"x":0,"y":-6,"z":2},{"name":"Rock_Sandstone_Brick","rotation":3,"x":0,"y":-5,"z":2},{"name":"Rock_Sandstone_Brick","rotation":3,"x":0,"y":-4,"z":2},{"name":"Rock_Sandstone_Cobble","rotation":3,"x":0,"y":-3,"z":2},{"name":"Rock_Sandstone_Brick","rotation":3,"x":0,"y":-2,"z":2},{"name":"Rock_Sandstone_Brick","rotation":3,"x":0,"y":-1,"z":2},{"name":"Rock_Sandstone_Brick","x":0,"y":0,"z":2},{"name":"Rock_Sandstone_Brick","x":0,"y":-35,"z":3},{"name":"Rock_Sandstone_Brick","x":0,"y":-34,"z":3},{"name":"Rock_Sandstone_Brick","x":0,"y":-33,"z":3},{"name":"Rock_Sandstone","x":0,"y":-32,"z":3},{"name":"Rock_Sandstone_Cobble","x":0,"y":-31,"z":3},{"name":"Rock_Sandstone_Brick","x":0,"y":-30,"z":3},{"name":"Rock_Sandstone_Brick","x":0,"y":-29,"z":3},{"name":"Rock_Sandstone","x":0,"y":-28,"z":3},{"name":"Rock_Sandstone_Brick","x":0,"y":-27,"z":3},{"name":"Rock_Sandstone_Cobble","x":0,"y":-26,"z":3},{"name":"Rock_Sandstone","rotation":3,"x":0,"y":-25,"z":3},{"name":"Rock_Sandstone_Brick","rotation":3,"x":0,"y":-24,"z":3},{"name":"Rock_Sandstone_Brick","rotation":3,"x":0,"y":-23,"z":3},{"name":"Rock_Sandstone_Brick","rotation":3,"x":0,"y":-22,"z":3},{"name":"Rock_Sandstone_Brick","rotation":3,"x":0,"y":-21,"z":3},{"name":"Rock_Sandstone_Cobble","rotation":3,"x":0,"y":-20,"z":3},{"name":"Rock_Sandstone_Brick","rotation":3,"x":0,"y":-19,"z":3},{"name":"Rock_Sandstone_Brick","rotation":3,"x":0,"y":-18,"z":3},{"name":"Rock_Sandstone","rotation":3,"x":0,"y":-17,"z":3},{"name":"Rock_Sandstone_Brick","rotation":3,"x":0,"y":-16,"z":3},{"name":"Rock_Sandstone_Brick","rotation":3,"x":0,"y":-15,"z":3},{"name":"Rock_Sandstone_Cobble","rotation":3,"x":0,"y":-14,"z":3},{"name":"Rock_Sandstone","rotation":3,"x":0,"y":-13,"z":3},{"name":"Rock_Sandstone_Brick","rotation":3,"x":0,"y":-12,"z":3},{"name":"Rock_Sandstone_Cobble","rotation":3,"x":0,"y":-11,"z":3},{"name":"Rock_Sandstone_Cobble","rotation":3,"x":0,"y":-10,"z":3},{"name":"Rock_Sandstone_Brick","rotation":3,"x":0,"y":-9,"z":3},{"name":"Rock_Sandstone","rotation":3,"x":0,"y":-8,"z":3},{"name":"Rock_Sandstone_Brick","rotation":3,"x":0,"y":-7,"z":3},{"name":"Rock_Sandstone_Cobble","rotation":3,"x":0,"y":-6,"z":3},{"name":"Rock_Sandstone_Brick","rotation":3,"x":0,"y":-5,"z":3},{"name":"Rock_Sandstone","rotation":3,"x":0,"y":-4,"z":3},{"name":"Rock_Sandstone_Cobble","rotation":3,"x":0,"y":-3,"z":3},{"name":"Rock_Sandstone_Brick","rotation":3,"x":0,"y":-2,"z":3},{"name":"Rock_Sandstone_Brick","rotation":3,"x":0,"y":-1,"z":3},{"name":"Rock_Sandstone_Brick","x":0,"y":0,"z":3},{"name":"Rock_Sandstone_Brick_Stairs","rotation":10,"x":0,"y":-5,"z":4},{"name":"Rock_Sandstone_Brick","x":0,"y":-4,"z":4},{"name":"Rock_Sandstone_Brick","x":0,"y":-3,"z":4},{"name":"Rock_Sandstone_Brick","rotation":2,"x":0,"y":-2,"z":4},{"name":"Rock_Sandstone_Brick","x":0,"y":-1,"z":4},{"name":"Rock_Sandstone_Brick","x":0,"y":0,"z":4},{"name":"Rock_Sandstone_Brick_Stairs","rotation":10,"x":0,"y":-4,"z":5},{"name":"Rock_Sandstone_Brick","x":0,"y":-3,"z":5},{"name":"Rock_Sandstone_Brick","rotation":2,"x":0,"y":-2,"z":5},{"name":"Rock_Sandstone_Brick","x":0,"y":-1,"z":5},{"name":"Rock_Sandstone_Brick","x":0,"y":0,"z":5},{"name":"Rock_Sandstone_Brick","x":0,"y":-3,"z":6},{"name":"Rock_Sandstone_Brick","x":0,"y":-2,"z":6},{"name":"Rock_Sandstone_Brick","x":0,"y":-1,"z":6},{"name":"Rock_Sandstone_Brick","x":0,"y":0,"z":6},{"name":"Rock_Sandstone_Brick_Half","rotation":8,"x":0,"y":-3,"z":7},{"name":"Rock_Sandstone_Brick","x":0,"y":-2,"z":7},{"name":"Rock_Sandstone_Brick","x":0,"y":-1,"z":7},{"name":"Rock_Sandstone_Brick","x":0,"y":0,"z":7},{"name":"Rock_Sandstone_Brick","x":0,"y":-2,"z":8},{"name":"Rock_Sandstone_Brick","x":0,"y":-1,"z":8},{"name":"Rock_Sandstone_Brick","x":0,"y":0,"z":8},{"name":"Rock_Sandstone_Brick_Stairs","rotation":10,"x":0,"y":-2,"z":9},{"name":"Rock_Sandstone_Brick","x":0,"y":-1,"z":9},{"name":"Rock_Sandstone_Brick","x":0,"y":0,"z":9},{"name":"Rock_Sandstone_Brick_Half","rotation":8,"x":0,"y":-2,"z":10},{"name":"Rock_Sandstone_Brick","x":0,"y":-1,"z":10},{"name":"Rock_Sandstone_Brick","x":0,"y":0,"z":10},{"name":"Rock_Sandstone_Brick_Half","rotation":8,"x":0,"y":-2,"z":11},{"name":"Rock_Sandstone_Brick","x":0,"y":-1,"z":11},{"name":"Rock_Sandstone_Brick","x":0,"y":0,"z":11},{"name":"Rock_Sandstone_Brick_Stairs","rotation":8,"x":0,"y":-2,"z":12},{"name":"Rock_Sandstone_Brick","x":0,"y":-1,"z":12},{"name":"Rock_Sandstone_Brick","x":0,"y":0,"z":12},{"name":"Rock_Sandstone_Brick","x":0,"y":-2,"z":13},{"name":"Rock_Sandstone_Brick","x":0,"y":-1,"z":13},{"name":"Rock_Sandstone_Brick","x":0,"y":0,"z":13},{"name":"Rock_Sandstone_Brick_Half","rotation":8,"x":0,"y":-3,"z":14},{"name":"Rock_Sandstone_Brick","x":0,"y":-2,"z":14},{"name":"Rock_Sandstone_Brick","x":0,"y":-1,"z":14},{"name":"Rock_Sandstone_Brick","x":0,"y":0,"z":14},{"name":"Rock_Sandstone_Brick","x":0,"y":-3,"z":15},{"name":"Rock_Sandstone_Brick","x":0,"y":-2,"z":15},{"name":"Rock_Sandstone_Brick","x":0,"y":-1,"z":15},{"name":"Rock_Sandstone_Brick","x":0,"y":0,"z":15},{"name":"Rock_Sandstone_Brick_Stairs","rotation":8,"x":0,"y":-4,"z":16},{"name":"Rock_Sandstone_Brick","x":0,"y":-3,"z":16},{"name":"Rock_Sandstone_Brick","x":0,"y":-2,"z":16},{"name":"Rock_Sandstone_Brick","x":0,"y":-1,"z":16},{"name":"Rock_Sandstone_Brick","x":0,"y":0,"z":16},{"name":"Rock_Sandstone_Brick_Stairs","rotation":8,"x":0,"y":-5,"z":17},{"name":"Rock_Sandstone_Brick","x":0,"y":-4,"z":17},{"name":"Rock_Sandstone","x":0,"y":-3,"z":17},{"name":"Rock_Sandstone_Brick","x":0,"y":-2,"z":17},{"name":"Rock_Sandstone_Brick","x":0,"y":-1,"z":17},{"name":"Rock_Sandstone_Brick","x":0,"y":0,"z":17},{"name":"Rock_Sandstone_Brick","x":0,"y":-35,"z":18},{"name":"Rock_Sandstone_Brick","x":0,"y":-34,"z":18},{"name":"Rock_Sandstone_Cobble","x":0,"y":-33,"z":18},{"name":"Rock_Sandstone_Brick","x":0,"y":-32,"z":18},{"name":"Rock_Sandstone_Brick","x":0,"y":-31,"z":18},{"name":"Rock_Sandstone_Brick","x":0,"y":-30,"z":18},{"name":"Rock_Sandstone_Brick","x":0,"y":-29,"z":18},{"name":"Rock_Sandstone_Brick","x":0,"y":-28,"z":18},{"name":"Rock_Sandstone_Cobble","x":0,"y":-27,"z":18},{"name":"Rock_Sandstone_Brick","x":0,"y":-26,"z":18},{"name":"Rock_Sandstone_Brick","x":0,"y":-25,"z":18},{"name":"Rock_Sandstone","rotation":1,"x":0,"y":-24,"z":18},{"name":"Rock_Sandstone_Brick","rotation":1,"x":0,"y":-23,"z":18},{"name":"Rock_Sandstone","rotation":1,"x":0,"y":-22,"z":18},{"name":"Rock_Sandstone_Brick","rotation":1,"x":0,"y":-21,"z":18},{"name":"Rock_Sandstone","rotation":1,"x":0,"y":-20,"z":18},{"name":"Rock_Sandstone","rotation":1,"x":0,"y":-19,"z":18},{"name":"Rock_Sandstone_Brick","rotation":1,"x":0,"y":-18,"z":18},{"name":"Rock_Sandstone_Brick","rotation":1,"x":0,"y":-17,"z":18},{"name":"Rock_Sandstone_Brick","rotation":1,"x":0,"y":-16,"z":18},{"name":"Rock_Sandstone_Cobble","rotation":1,"x":0,"y":-15,"z":18},{"name":"Rock_Sandstone_Brick","rotation":1,"x":0,"y":-14,"z":18},{"name":"Rock_Sandstone_Brick","rotation":1,"x":0,"y":-13,"z":18},{"name":"Rock_Sandstone_Cobble","rotation":1,"x":0,"y":-12,"z":18},{"name":"Rock_Sandstone_Brick","rotation":1,"x":0,"y":-11,"z":18},{"name":"Rock_Sandstone_Cobble","rotation":1,"x":0,"y":-10,"z":18},{"name":"Rock_Sandstone_Brick","rotation":1,"x":0,"y":-9,"z":18},{"name":"Rock_Sandstone_Brick","rotation":1,"x":0,"y":-8,"z":18},{"name":"Rock_Sandstone_Brick","rotation":1,"x":0,"y":-7,"z":18},{"name":"Rock_Sandstone_Brick","rotation":1,"x":0,"y":-6,"z":18},{"name":"Rock_Sandstone_Brick","rotation":1,"x":0,"y":-5,"z":18},{"name":"Rock_Sandstone_Brick","rotation":1,"x":0,"y":-4,"z":18},{"name":"Rock_Sandstone","rotation":1,"x":0,"y":-3,"z":18},{"name":"Rock_Sandstone_Brick","rotation":1,"x":0,"y":-2,"z":18},{"name":"Rock_Sandstone_Brick","rotation":1,"x":0,"y":-1,"z":18},{"name":"Rock_Sandstone_Brick","x":0,"y":0,"z":18},{"name":"Rock_Sandstone_Brick","x":0,"y":-35,"z":19},{"name":"Rock_Sandstone_Brick","x":0,"y":-34,"z":19},{"name":"Rock_Sandstone_Brick","x":0,"y":-33,"z":19},{"name":"Rock_Sandstone_Brick","x":0,"y":-32,"z":19},{"name":"Rock_Sandstone_Brick","x":0,"y":-31,"z":19},{"name":"Rock_Sandstone_Brick","x":0,"y":-30,"z":19},{"name":"Rock_Sandstone_Brick","x":0,"y":-29,"z":19},{"name":"Rock_Sandstone","x":0,"y":-28,"z":19},{"name":"Rock_Sandstone_Brick","x":0,"y":-27,"z":19},{"name":"Rock_Sandstone_Cobble","x":0,"y":-26,"z":19},{"name":"Rock_Sandstone_Brick","x":0,"y":-25,"z":19},{"name":"Rock_Sandstone_Brick","rotation":1,"x":0,"y":-24,"z":19},{"name":"Rock_Sandstone_Brick","rotation":1,"x":0,"y":-23,"z":19},{"name":"Rock_Sandstone_Brick","rotation":1,"x":0,"y":-22,"z":19},{"name":"Rock_Sandstone_Brick","rotation":1,"x":0,"y":-21,"z":19},{"name":"Rock_Sandstone_Brick","rotation":1,"x":0,"y":-20,"z":19},{"name":"Rock_Sandstone","rotation":1,"x":0,"y":-19,"z":19},{"name":"Rock_Sandstone_Cobble","rotation":1,"x":0,"y":-18,"z":19},{"name":"Rock_Sandstone_Cobble","rotation":1,"x":0,"y":-17,"z":19},{"name":"Rock_Sandstone_Brick","rotation":1,"x":0,"y":-16,"z":19},{"name":"Rock_Sandstone_Cobble","rotation":1,"x":0,"y":-15,"z":19},{"name":"Rock_Sandstone_Brick","rotation":1,"x":0,"y":-14,"z":19},{"name":"Rock_Sandstone_Brick","rotation":1,"x":0,"y":-13,"z":19},{"name":"Rock_Sandstone","rotation":1,"x":0,"y":-12,"z":19},{"name":"Rock_Sandstone_Brick","rotation":1,"x":0,"y":-11,"z":19},{"name":"Rock_Sandstone_Brick","rotation":1,"x":0,"y":-10,"z":19},{"name":"Rock_Sandstone_Cobble","rotation":1,"x":0,"y":-9,"z":19},{"name":"Rock_Sandstone_Brick","rotation":1,"x":0,"y":-8,"z":19},{"name":"Rock_Sandstone_Brick","rotation":1,"x":0,"y":-7,"z":19},{"name":"Rock_Sandstone","rotation":1,"x":0,"y":-6,"z":19},{"name":"Rock_Sandstone_Cobble","rotation":1,"x":0,"y":-5,"z":19},{"name":"Rock_Sandstone_Brick","rotation":1,"x":0,"y":-4,"z":19},{"name":"Rock_Sandstone_Brick","rotation":1,"x":0,"y":-3,"z":19},{"name":"Rock_Sandstone_Brick","rotation":1,"x":0,"y":-2,"z":19},{"name":"Rock_Sandstone_Brick","rotation":1,"x":0,"y":-1,"z":19},{"name":"Rock_Sandstone_Brick","x":0,"y":0,"z":19},{"name":"Rock_Sandstone","x":0,"y":-35,"z":20},{"name":"Rock_Sandstone_Cobble","x":0,"y":-34,"z":20},{"name":"Rock_Sandstone_Brick","x":0,"y":-33,"z":20},{"name":"Rock_Sandstone_Brick","x":0,"y":-32,"z":20},{"name":"Rock_Sandstone_Brick","x":0,"y":-31,"z":20},{"name":"Rock_Sandstone_Brick","x":0,"y":-30,"z":20},{"name":"Rock_Sandstone_Brick","x":0,"y":-29,"z":20},{"name":"Rock_Sandstone_Cobble","x":0,"y":-28,"z":20},{"name":"Rock_Sandstone_Brick","x":0,"y":-27,"z":20},{"name":"Rock_Sandstone_Brick","x":0,"y":-26,"z":20},{"name":"Rock_Sandstone_Cobble","x":0,"y":-25,"z":20},{"name":"Rock_Sandstone_Brick","rotation":1,"x":0,"y":-24,"z":20},{"name":"Rock_Sandstone_Brick","rotation":1,"x":0,"y":-23,"z":20},{"name":"Rock_Sandstone_Brick","rotation":1,"x":0,"y":-22,"z":20},{"name":"Rock_Sandstone","rotation":1,"x":0,"y":-21,"z":20},{"name":"Rock_Sandstone_Brick","rotation":1,"x":0,"y":-20,"z":20},{"name":"Rock_Sandstone_Brick","rotation":1,"x":0,"y":-19,"z":20},{"name":"Rock_Sandstone","rotation":1,"x":0,"y":-18,"z":20},{"name":"Rock_Sandstone_Brick","rotation":1,"x":0,"y":-17,"z":20},{"name":"Rock_Sandstone","rotation":1,"x":0,"y":-16,"z":20},{"name":"Rock_Sandstone_Brick","rotation":1,"x":0,"y":-15,"z":20},{"name":"Rock_Sandstone","rotation":1,"x":0,"y":-14,"z":20},{"name":"Rock_Sandstone_Brick","rotation":1,"x":0,"y":-13,"z":20},{"name":"Rock_Sandstone_Brick","rotation":1,"x":0,"y":-12,"z":20},{"name":"Rock_Sandstone_Brick","rotation":1,"x":0,"y":-11,"z":20},{"name":"Rock_Sandstone_Brick","rotation":1,"x":0,"y":-10,"z":20},{"name":"Rock_Sandstone","rotation":1,"x":0,"y":-9,"z":20},{"name":"Rock_Sandstone_Brick","rotation":1,"x":0,"y":-8,"z":20},{"name":"Rock_Sandstone_Brick","rotation":1,"x":0,"y":-7,"z":20},{"name":"Rock_Sandstone_Brick","rotation":1,"x":0,"y":-6,"z":20},{"name":"Rock_Sandstone_Brick","rotation":1,"x":0,"y":-5,"z":20},{"name":"Rock_Sandstone_Brick","rotation":1,"x":0,"y":-4,"z":20},{"name":"Rock_Sandstone_Brick","rotation":1,"x":0,"y":-3,"z":20},{"name":"Rock_Sandstone_Brick","rotation":1,"x":0,"y":-2,"z":20},{"name":"Rock_Sandstone_Brick","rotation":1,"x":0,"y":-1,"z":20},{"name":"Rock_Sandstone_Brick","x":0,"y":0,"z":20},{"name":"Rock_Sandstone_Cobble","x":1,"y":-35,"z":0},{"name":"Rock_Sandstone","x":1,"y":-34,"z":0},{"name":"Rock_Sandstone_Brick","x":1,"y":-33,"z":0},{"name":"Rock_Sandstone_Brick","x":1,"y":-32,"z":0},{"name":"Rock_Sandstone","x":1,"y":-31,"z":0},{"name":"Rock_Sandstone_Brick","x":1,"y":-30,"z":0},{"name":"Rock_Sandstone_Brick","x":1,"y":-29,"z":0},{"name":"Rock_Sandstone_Brick","x":1,"y":-28,"z":0},{"name":"Rock_Sandstone","x":1,"y":-27,"z":0},{"name":"Rock_Sandstone_Cobble","x":1,"y":-26,"z":0},{"name":"Rock_Sandstone_Brick","x":1,"y":-25,"z":0},{"name":"Rock_Sandstone_Brick","x":1,"y":-24,"z":0},{"name":"Rock_Sandstone_Brick","x":1,"y":-23,"z":0},{"name":"Rock_Sandstone","x":1,"y":-22,"z":0},{"name":"Rock_Sandstone_Brick","x":1,"y":-21,"z":0},{"name":"Rock_Sandstone_Brick","x":1,"y":-20,"z":0},{"name":"Rock_Sandstone_Brick","x":1,"y":-19,"z":0},{"name":"Rock_Sandstone_Brick","x":1,"y":-18,"z":0},{"name":"Rock_Sandstone_Brick","x":1,"y":-17,"z":0},{"name":"Rock_Sandstone_Cobble","x":1,"y":-16,"z":0},{"name":"Rock_Sandstone_Cobble","x":1,"y":-15,"z":0},{"name":"Rock_Sandstone_Brick","x":1,"y":-14,"z":0},{"name":"Rock_Sandstone_Brick","x":1,"y":-13,"z":0},{"name":"Rock_Sandstone","x":1,"y":-12,"z":0},{"name":"Rock_Sandstone_Brick","x":1,"y":-11,"z":0},{"name":"Rock_Sandstone_Brick","x":1,"y":-10,"z":0},{"name":"Rock_Sandstone","x":1,"y":-9,"z":0},{"name":"Rock_Sandstone_Brick","x":1,"y":-8,"z":0},{"name":"Rock_Sandstone_Brick","x":1,"y":-7,"z":0},{"name":"Rock_Sandstone_Brick","x":1,"y":-6,"z":0},{"name":"Rock_Sandstone_Brick","x":1,"y":-5,"z":0},{"name":"Rock_Sandstone_Brick","x":1,"y":-4,"z":0},{"name":"Rock_Sandstone_Brick","x":1,"y":-3,"z":0},{"name":"Rock_Sandstone_Brick","x":1,"y":-2,"z":0},{"name":"Rock_Sandstone_Brick","x":1,"y":-1,"z":0},{"name":"Rock_Sandstone_Brick","x":1,"y":0,"z":0},{"name":"Rock_Sandstone_Brick","x":1,"y":-35,"z":1},{"name":"Rock_Sandstone_Brick","x":1,"y":-34,"z":1},{"name":"Rock_Sandstone_Brick","x":1,"y":-33,"z":1},{"name":"Rock_Sandstone_Cobble","x":1,"y":-32,"z":1},{"name":"Rock_Sandstone","x":1,"y":-31,"z":1},{"name":"Rock_Sandstone_Brick","x":1,"y":-30,"z":1},{"name":"Rock_Sandstone","x":1,"y":-29,"z":1},{"name":"Rock_Sandstone_Brick","x":1,"y":-28,"z":1},{"name":"Rock_Sandstone_Brick","x":1,"y":-27,"z":1},{"name":"Rock_Sandstone","x":1,"y":-26,"z":1},{"name":"Rock_Sandstone_Brick","rotation":3,"x":1,"y":-25,"z":1},{"name":"Rock_Sandstone_Brick","rotation":3,"x":1,"y":-24,"z":1},{"name":"Rock_Sandstone_Cobble","rotation":3,"x":1,"y":-23,"z":1},{"name":"Rock_Sandstone_Brick","rotation":3,"x":1,"y":-22,"z":1},{"name":"Rock_Sandstone_Brick","rotation":3,"x":1,"y":-21,"z":1},{"name":"Rock_Sandstone_Brick","rotation":3,"x":1,"y":-20,"z":1},{"name":"Rock_Sandstone_Brick","rotation":3,"x":1,"y":-19,"z":1},{"name":"Rock_Sandstone_Brick","rotation":3,"x":1,"y":-18,"z":1},{"name":"Rock_Sandstone_Brick","rotation":3,"x":1,"y":-17,"z":1},{"name":"Rock_Sandstone_Brick","rotation":3,"x":1,"y":-16,"z":1},{"name":"Rock_Sandstone_Brick","rotation":3,"x":1,"y":-15,"z":1},{"name":"Rock_Sandstone_Brick","rotation":3,"x":1,"y":-14,"z":1},{"name":"Rock_Sandstone_Brick","rotation":3,"x":1,"y":-13,"z":1},{"name":"Rock_Sandstone_Brick","rotation":3,"x":1,"y":-12,"z":1},{"name":"Rock_Sandstone_Brick","rotation":3,"x":1,"y":-11,"z":1},{"name":"Rock_Sandstone_Brick","rotation":3,"x":1,"y":-10,"z":1},{"name":"Rock_Sandstone","rotation":3,"x":1,"y":-9,"z":1},{"name":"Rock_Sandstone_Brick","rotation":3,"x":1,"y":-8,"z":1},{"name":"Rock_Sandstone_Brick","rotation":3,"x":1,"y":-7,"z":1},{"name":"Rock_Sandstone","rotation":3,"x":1,"y":-6,"z":1},{"name":"Rock_Sandstone_Brick","rotation":3,"x":1,"y":-5,"z":1},{"name":"Rock_Sandstone_Brick","rotation":3,"x":1,"y":-4,"z":1},{"name":"Rock_Sandstone_Brick","rotation":3,"x":1,"y":-3,"z":1},{"name":"Rock_Sandstone_Brick","rotation":3,"x":1,"y":-2,"z":1},{"name":"Rock_Sandstone_Brick","rotation":3,"x":1,"y":-1,"z":1},{"name":"Rock_Sandstone_Brick","x":1,"y":0,"z":1},{"name":"Rock_Sandstone_Cobble","x":1,"y":-35,"z":2},{"name":"Rock_Sandstone","x":1,"y":-34,"z":2},{"name":"Rock_Sandstone_Brick","x":1,"y":-33,"z":2},{"name":"Rock_Sandstone_Brick","x":1,"y":-32,"z":2},{"name":"Rock_Sandstone_Brick","x":1,"y":-31,"z":2},{"name":"Rock_Sandstone_Brick","x":1,"y":-30,"z":2},{"name":"Rock_Sandstone","x":1,"y":-29,"z":2},{"name":"Rock_Sandstone","x":1,"y":-28,"z":2},{"name":"Rock_Sandstone_Cobble","x":1,"y":-27,"z":2},{"name":"Rock_Sandstone","x":1,"y":-26,"z":2},{"name":"Rock_Sandstone_Brick","rotation":3,"x":1,"y":-25,"z":2},{"name":"Rock_Sandstone_Cobble","rotation":3,"x":1,"y":-24,"z":2},{"name":"Rock_Sandstone_Brick","rotation":3,"x":1,"y":-23,"z":2},{"name":"Rock_Sandstone_Cobble","rotation":3,"x":1,"y":-22,"z":2},{"name":"Rock_Sandstone_Cobble","rotation":3,"x":1,"y":-21,"z":2},{"name":"Rock_Sandstone_Brick","rotation":3,"x":1,"y":-20,"z":2},{"name":"Rock_Sandstone_Brick","rotation":3,"x":1,"y":-19,"z":2},{"name":"Rock_Sandstone_Brick","rotation":3,"x":1,"y":-18,"z":2},{"name":"Rock_Sandstone_Brick","rotation":3,"x":1,"y":-17,"z":2},{"name":"Rock_Sandstone_Brick","rotation":3,"x":1,"y":-16,"z":2},{"name":"Rock_Sandstone_Brick","rotation":3,"x":1,"y":-15,"z":2},{"name":"Rock_Sandstone","rotation":3,"x":1,"y":-14,"z":2},{"name":"Rock_Sandstone_Brick","rotation":3,"x":1,"y":-13,"z":2},{"name":"Rock_Sandstone_Brick","rotation":3,"x":1,"y":-12,"z":2},{"name":"Rock_Sandstone","rotation":3,"x":1,"y":-11,"z":2},{"name":"Rock_Sandstone_Cobble","rotation":3,"x":1,"y":-10,"z":2},{"name":"Rock_Sandstone_Brick","rotation":3,"x":1,"y":-9,"z":2},{"name":"Rock_Sandstone","rotation":3,"x":1,"y":-8,"z":2},{"name":"Rock_Sandstone_Brick","rotation":3,"x":1,"y":-7,"z":2},{"name":"Rock_Sandstone","rotation":3,"x":1,"y":-6,"z":2},{"name":"Rock_Sandstone_Brick","rotation":3,"x":1,"y":-5,"z":2},{"name":"Rock_Sandstone_Brick","rotation":3,"x":1,"y":-4,"z":2},{"name":"Rock_Sandstone_Brick","rotation":3,"x":1,"y":-3,"z":2},{"name":"Rock_Sandstone_Brick","rotation":3,"x":1,"y":-2,"z":2},{"name":"Rock_Sandstone_Brick","rotation":3,"x":1,"y":-1,"z":2},{"name":"Rock_Sandstone_Brick","x":1,"y":0,"z":2},{"name":"Rock_Sandstone_Brick","x":1,"y":-35,"z":3},{"name":"Rock_Sandstone_Brick","x":1,"y":-34,"z":3},{"name":"Rock_Sandstone_Brick","x":1,"y":-33,"z":3},{"name":"Rock_Sandstone_Brick","x":1,"y":-32,"z":3},{"name":"Rock_Sandstone_Brick","x":1,"y":-31,"z":3},{"name":"Rock_Sandstone","x":1,"y":-30,"z":3},{"name":"Rock_Sandstone_Brick","x":1,"y":-29,"z":3},{"name":"Rock_Sandstone","x":1,"y":-28,"z":3},{"name":"Rock_Sandstone","x":1,"y":-27,"z":3},{"name":"Rock_Sandstone_Brick","x":1,"y":-26,"z":3},{"name":"Rock_Sandstone_Cobble","rotation":3,"x":1,"y":-25,"z":3},{"name":"Rock_Sandstone_Brick","rotation":3,"x":1,"y":-24,"z":3},{"name":"Rock_Sandstone_Brick","rotation":3,"x":1,"y":-23,"z":3},{"name":"Rock_Sandstone_Brick","rotation":3,"x":1,"y":-22,"z":3},{"name":"Rock_Sandstone_Brick","rotation":3,"x":1,"y":-21,"z":3},{"name":"Rock_Sandstone","rotation":3,"x":1,"y":-20,"z":3},{"name":"Rock_Sandstone_Brick","rotation":3,"x":1,"y":-19,"z":3},{"name":"Rock_Sandstone_Cobble","rotation":3,"x":1,"y":-18,"z":3},{"name":"Rock_Sandstone_Brick","rotation":3,"x":1,"y":-17,"z":3},{"name":"Rock_Sandstone_Brick","rotation":3,"x":1,"y":-16,"z":3},{"name":"Rock_Sandstone_Cobble","rotation":3,"x":1,"y":-15,"z":3},{"name":"Rock_Sandstone_Brick","rotation":3,"x":1,"y":-14,"z":3},{"name":"Rock_Sandstone","rotation":3,"x":1,"y":-13,"z":3},{"name":"Rock_Sandstone_Brick","rotation":3,"x":1,"y":-12,"z":3},{"name":"Rock_Sandstone_Brick","rotation":3,"x":1,"y":-11,"z":3},{"name":"Rock_Sandstone_Brick","rotation":3,"x":1,"y":-10,"z":3},{"name":"Rock_Sandstone_Brick","rotation":3,"x":1,"y":-9,"z":3},{"name":"Rock_Sandstone_Brick","rotation":3,"x":1,"y":-8,"z":3},{"name":"Rock_Sandstone_Brick","rotation":3,"x":1,"y":-7,"z":3},{"name":"Rock_Sandstone","rotation":3,"x":1,"y":-6,"z":3},{"name":"Rock_Sandstone_Brick","rotation":3,"x":1,"y":-5,"z":3},{"name":"Rock_Sandstone","rotation":3,"x":1,"y":-4,"z":3},{"name":"Rock_Sandstone_Brick","rotation":3,"x":1,"y":-3,"z":3},{"name":"Rock_Sandstone_Brick","rotation":3,"x":1,"y":-2,"z":3},{"name":"Rock_Sandstone_Brick","rotation":3,"x":1,"y":-1,"z":3},{"name":"Rock_Sandstone_Brick","x":1,"y":0,"z":3},{"name":"Rock_Sandstone_Brick_Stairs","rotation":10,"x":1,"y":-5,"z":4},{"name":"Rock_Sandstone_Cobble","x":1,"y":-4,"z":4},{"name":"Rock_Sandstone_Brick","x":1,"y":-3,"z":4},{"name":"Rock_Sandstone_Brick","rotation":2,"x":1,"y":-2,"z":4},{"name":"Rock_Sandstone_Brick","x":1,"y":-1,"z":4},{"name":"Rock_Sandstone_Brick","x":1,"y":0,"z":4},{"name":"Rock_Sandstone_Brick_Stairs","rotation":10,"x":1,"y":-4,"z":5},{"name":"Rock_Sandstone","x":1,"y":-3,"z":5},{"name":"Rock_Sandstone_Brick","rotation":2,"x":1,"y":-2,"z":5},{"name":"Rock_Sandstone_Brick","x":1,"y":-1,"z":5},{"name":"Rock_Sandstone_Brick","x":1,"y":0,"z":5},{"name":"Rock_Sandstone_Brick","x":1,"y":-3,"z":6},{"name":"Rock_Sandstone_Brick","x":1,"y":-2,"z":6},{"name":"Rock_Sandstone_Brick","x":1,"y":-1,"z":6},{"name":"Rock_Sandstone_Brick","x":1,"y":0,"z":6},{"name":"Rock_Sandstone_Brick_Half","rotation":8,"x":1,"y":-3,"z":7},{"name":"Rock_Sandstone_Brick","x":1,"y":-2,"z":7},{"name":"Rock_Sandstone_Brick","x":1,"y":-1,"z":7},{"name":"Rock_Sandstone_Brick","x":1,"y":0,"z":7},{"name":"Rock_Sandstone_Brick","x":1,"y":-2,"z":8},{"name":"Rock_Sandstone_Brick","x":1,"y":-1,"z":8},{"name":"Rock_Sandstone_Brick","x":1,"y":0,"z":8},{"name":"Rock_Sandstone_Brick_Stairs","rotation":10,"x":1,"y":-2,"z":9},{"name":"Rock_Sandstone_Brick","x":1,"y":-1,"z":9},{"name":"Rock_Sandstone_Brick","x":1,"y":0,"z":9},{"name":"Rock_Sandstone_Brick_Half","rotation":8,"x":1,"y":-2,"z":10},{"name":"Rock_Sandstone_Brick","x":1,"y":-1,"z":10},{"name":"Rock_Sandstone_Brick","x":1,"y":0,"z":10},{"name":"Rock_Sandstone_Brick_Half","rotation":8,"x":1,"y":-2,"z":11},{"name":"Rock_Sandstone_Brick","x":1,"y":-1,"z":11},{"name":"Rock_Sandstone_Brick","x":1,"y":0,"z":11},{"name":"Rock_Sandstone_Brick_Stairs","rotation":8,"x":1,"y":-2,"z":12},{"name":"Rock_Sandstone_Brick","x":1,"y":-1,"z":12},{"name":"Rock_Sandstone_Brick","x":1,"y":0,"z":12},{"name":"Rock_Sandstone_Brick","x":1,"y":-2,"z":13},{"name":"Rock_Sandstone_Brick","x":1,"y":-1,"z":13},{"name":"Rock_Sandstone_Brick","x":1,"y":0,"z":13},{"name":"Rock_Sandstone_Brick_Half","rotation":8,"x":1,"y":-3,"z":14},{"name":"Rock_Sandstone_Brick","x":1,"y":-2,"z":14},{"name":"Rock_Sandstone_Brick","x":1,"y":-1,"z":14},{"name":"Rock_Sandstone_Brick","x":1,"y":0,"z":14},{"name":"Rock_Sandstone_Brick","x":1,"y":-3,"z":15},{"name":"Rock_Sandstone_Brick","x":1,"y":-2,"z":15},{"name":"Rock_Sandstone_Brick","x":1,"y":-1,"z":15},{"name":"Rock_Sandstone_Brick","x":1,"y":0,"z":15},{"name":"Rock_Sandstone_Brick_Stairs","rotation":8,"x":1,"y":-4,"z":16},{"name":"Rock_Sandstone_Cobble","x":1,"y":-3,"z":16},{"name":"Rock_Sandstone_Brick","x":1,"y":-2,"z":16},{"name":"Rock_Sandstone_Brick","x":1,"y":-1,"z":16},{"name":"Rock_Sandstone_Brick","x":1,"y":0,"z":16},{"name":"Rock_Sandstone_Brick_Stairs","rotation":8,"x":1,"y":-5,"z":17},{"name":"Rock_Sandstone","x":1,"y":-4,"z":17},{"name":"Rock_Sandstone_Brick","x":1,"y":-3,"z":17},{"name":"Rock_Sandstone_Brick","x":1,"y":-2,"z":17},{"name":"Rock_Sandstone_Brick","x":1,"y":-1,"z":17},{"name":"Rock_Sandstone_Brick","x":1,"y":0,"z":17},{"name":"Rock_Sandstone_Brick","x":1,"y":-35,"z":18},{"name":"Rock_Sandstone","x":1,"y":-34,"z":18},{"name":"Rock_Sandstone_Brick","x":1,"y":-33,"z":18},{"name":"Rock_Sandstone_Brick","x":1,"y":-32,"z":18},{"name":"Rock_Sandstone_Brick","x":1,"y":-31,"z":18},{"name":"Rock_Sandstone_Brick","x":1,"y":-30,"z":18},{"name":"Rock_Sandstone_Brick","x":1,"y":-29,"z":18},{"name":"Rock_Sandstone_Cobble","x":1,"y":-28,"z":18},{"name":"Rock_Sandstone_Brick","x":1,"y":-27,"z":18},{"name":"Rock_Sandstone_Brick","x":1,"y":-26,"z":18},{"name":"Rock_Sandstone","x":1,"y":-25,"z":18},{"name":"Rock_Sandstone_Brick","rotation":1,"x":1,"y":-24,"z":18},{"name":"Rock_Sandstone_Brick","rotation":1,"x":1,"y":-23,"z":18},{"name":"Rock_Sandstone_Brick","rotation":1,"x":1,"y":-22,"z":18},{"name":"Rock_Sandstone_Cobble","rotation":1,"x":1,"y":-21,"z":18},{"name":"Rock_Sandstone_Brick","rotation":1,"x":1,"y":-20,"z":18},{"name":"Rock_Sandstone_Brick","rotation":1,"x":1,"y":-19,"z":18},{"name":"Rock_Sandstone_Brick","rotation":1,"x":1,"y":-18,"z":18},{"name":"Rock_Sandstone_Brick","rotation":1,"x":1,"y":-17,"z":18},{"name":"Rock_Sandstone_Brick","rotation":1,"x":1,"y":-16,"z":18},{"name":"Rock_Sandstone_Brick","rotation":1,"x":1,"y":-15,"z":18},{"name":"Rock_Sandstone_Brick","rotation":1,"x":1,"y":-14,"z":18},{"name":"Rock_Sandstone_Cobble","rotation":1,"x":1,"y":-13,"z":18},{"name":"Rock_Sandstone_Brick","rotation":1,"x":1,"y":-12,"z":18},{"name":"Rock_Sandstone_Cobble","rotation":1,"x":1,"y":-11,"z":18},{"name":"Rock_Sandstone_Brick","rotation":1,"x":1,"y":-10,"z":18},{"name":"Rock_Sandstone_Brick","rotation":1,"x":1,"y":-9,"z":18},{"name":"Rock_Sandstone_Brick","rotation":1,"x":1,"y":-8,"z":18},{"name":"Rock_Sandstone_Brick","rotation":1,"x":1,"y":-7,"z":18},{"name":"Rock_Sandstone_Brick","rotation":1,"x":1,"y":-6,"z":18},{"name":"Rock_Sandstone_Brick","rotation":1,"x":1,"y":-5,"z":18},{"name":"Rock_Sandstone_Brick","rotation":1,"x":1,"y":-4,"z":18},{"name":"Rock_Sandstone_Brick","rotation":1,"x":1,"y":-3,"z":18},{"name":"Rock_Sandstone_Brick","rotation":1,"x":1,"y":-2,"z":18},{"name":"Rock_Sandstone_Brick","rotation":1,"x":1,"y":-1,"z":18},{"name":"Rock_Sandstone_Brick","x":1,"y":0,"z":18},{"name":"Rock_Sandstone_Brick","x":1,"y":-35,"z":19},{"name":"Rock_Sandstone","x":1,"y":-34,"z":19},{"name":"Rock_Sandstone_Brick","x":1,"y":-33,"z":19},{"name":"Rock_Sandstone_Brick","x":1,"y":-32,"z":19},{"name":"Rock_Sandstone","x":1,"y":-31,"z":19},{"name":"Rock_Sandstone_Brick","x":1,"y":-30,"z":19},{"name":"Rock_Sandstone_Cobble","x":1,"y":-29,"z":19},{"name":"Rock_Sandstone_Brick","x":1,"y":-28,"z":19},{"name":"Rock_Sandstone_Brick","x":1,"y":-27,"z":19},{"name":"Rock_Sandstone_Brick","x":1,"y":-26,"z":19},{"name":"Rock_Sandstone_Cobble","x":1,"y":-25,"z":19},{"name":"Rock_Sandstone_Brick","rotation":1,"x":1,"y":-24,"z":19},{"name":"Rock_Sandstone_Brick","rotation":1,"x":1,"y":-23,"z":19},{"name":"Rock_Sandstone_Brick","rotation":1,"x":1,"y":-22,"z":19},{"name":"Rock_Sandstone","rotation":1,"x":1,"y":-21,"z":19},{"name":"Rock_Sandstone_Brick","rotation":1,"x":1,"y":-20,"z":19},{"name":"Rock_Sandstone_Brick","rotation":1,"x":1,"y":-19,"z":19},{"name":"Rock_Sandstone_Cobble","rotation":1,"x":1,"y":-18,"z":19},{"name":"Rock_Sandstone_Brick","rotation":1,"x":1,"y":-17,"z":19},{"name":"Rock_Sandstone","rotation":1,"x":1,"y":-16,"z":19},{"name":"Rock_Sandstone","rotation":1,"x":1,"y":-15,"z":19},{"name":"Rock_Sandstone_Brick","rotation":1,"x":1,"y":-14,"z":19},{"name":"Rock_Sandstone_Brick","rotation":1,"x":1,"y":-13,"z":19},{"name":"Rock_Sandstone_Brick","rotation":1,"x":1,"y":-12,"z":19},{"name":"Rock_Sandstone_Cobble","rotation":1,"x":1,"y":-11,"z":19},{"name":"Rock_Sandstone_Brick","rotation":1,"x":1,"y":-10,"z":19},{"name":"Rock_Sandstone_Brick","rotation":1,"x":1,"y":-9,"z":19},{"name":"Rock_Sandstone","rotation":1,"x":1,"y":-8,"z":19},{"name":"Rock_Sandstone_Cobble","rotation":1,"x":1,"y":-7,"z":19},{"name":"Rock_Sandstone_Brick","rotation":1,"x":1,"y":-6,"z":19},{"name":"Rock_Sandstone_Brick","rotation":1,"x":1,"y":-5,"z":19},{"name":"Rock_Sandstone_Brick","rotation":1,"x":1,"y":-4,"z":19},{"name":"Rock_Sandstone_Brick","rotation":1,"x":1,"y":-3,"z":19},{"name":"Rock_Sandstone_Brick","rotation":1,"x":1,"y":-2,"z":19},{"name":"Rock_Sandstone_Brick","rotation":1,"x":1,"y":-1,"z":19},{"name":"Rock_Sandstone_Brick","x":1,"y":0,"z":19},{"name":"Rock_Sandstone_Cobble","x":1,"y":-35,"z":20},{"name":"Rock_Sandstone_Brick","x":1,"y":-34,"z":20},{"name":"Rock_Sandstone_Brick","x":1,"y":-33,"z":20},{"name":"Rock_Sandstone","x":1,"y":-32,"z":20},{"name":"Rock_Sandstone_Brick","x":1,"y":-31,"z":20},{"name":"Rock_Sandstone_Brick","x":1,"y":-30,"z":20},{"name":"Rock_Sandstone_Brick","x":1,"y":-29,"z":20},{"name":"Rock_Sandstone","x":1,"y":-28,"z":20},{"name":"Rock_Sandstone_Brick","x":1,"y":-27,"z":20},{"name":"Rock_Sandstone_Brick","x":1,"y":-26,"z":20},{"name":"Rock_Sandstone","x":1,"y":-25,"z":20},{"name":"Rock_Sandstone_Brick","rotation":1,"x":1,"y":-24,"z":20},{"name":"Rock_Sandstone_Brick","rotation":1,"x":1,"y":-23,"z":20},{"name":"Rock_Sandstone_Brick","rotation":1,"x":1,"y":-22,"z":20},{"name":"Rock_Sandstone","rotation":1,"x":1,"y":-21,"z":20},{"name":"Rock_Sandstone_Brick","rotation":1,"x":1,"y":-20,"z":20},{"name":"Rock_Sandstone_Brick","rotation":1,"x":1,"y":-19,"z":20},{"name":"Rock_Sandstone_Brick","rotation":1,"x":1,"y":-18,"z":20},{"name":"Rock_Sandstone_Cobble","rotation":1,"x":1,"y":-17,"z":20},{"name":"Rock_Sandstone_Brick","rotation":1,"x":1,"y":-16,"z":20},{"name":"Rock_Sandstone_Brick","rotation":1,"x":1,"y":-15,"z":20},{"name":"Rock_Sandstone_Brick","rotation":1,"x":1,"y":-14,"z":20},{"name":"Rock_Sandstone_Cobble","rotation":1,"x":1,"y":-13,"z":20},{"name":"Rock_Sandstone_Brick","rotation":1,"x":1,"y":-12,"z":20},{"name":"Rock_Sandstone_Brick","rotation":1,"x":1,"y":-11,"z":20},{"name":"Rock_Sandstone_Brick","rotation":1,"x":1,"y":-10,"z":20},{"name":"Rock_Sandstone_Brick","rotation":1,"x":1,"y":-9,"z":20},{"name":"Rock_Sandstone_Brick","rotation":1,"x":1,"y":-8,"z":20},{"name":"Rock_Sandstone_Cobble","rotation":1,"x":1,"y":-7,"z":20},{"name":"Rock_Sandstone_Brick","rotation":1,"x":1,"y":-6,"z":20},{"name":"Rock_Sandstone_Brick","rotation":1,"x":1,"y":-5,"z":20},{"name":"Rock_Sandstone_Brick","rotation":1,"x":1,"y":-4,"z":20},{"name":"Rock_Sandstone_Brick","rotation":1,"x":1,"y":-3,"z":20},{"name":"Rock_Sandstone_Brick","rotation":1,"x":1,"y":-2,"z":20},{"name":"Rock_Sandstone_Brick","rotation":1,"x":1,"y":-1,"z":20},{"name":"Rock_Sandstone_Brick","x":1,"y":0,"z":20},{"name":"Rock_Sandstone_Brick","x":1,"y":-35,"z":21},{"name":"Rock_Sandstone_Brick","x":1,"y":-34,"z":21},{"name":"Rock_Sandstone_Brick","x":1,"y":-33,"z":21},{"name":"Rock_Sandstone_Brick","x":1,"y":-32,"z":21},{"name":"Rock_Sandstone_Cobble","x":1,"y":-31,"z":21},{"name":"Rock_Sandstone_Brick","x":1,"y":-30,"z":21},{"name":"Rock_Sandstone","x":1,"y":-29,"z":21},{"name":"Rock_Sandstone_Brick","x":1,"y":-28,"z":21},{"name":"Rock_Sandstone","x":1,"y":-27,"z":21},{"name":"Rock_Sandstone","x":1,"y":-26,"z":21},{"name":"Rock_Sandstone_Brick","x":1,"y":-25,"z":21},{"name":"Rock_Sandstone","x":1,"y":-24,"z":21},{"name":"Rock_Sandstone_Brick","x":1,"y":-23,"z":21},{"name":"Rock_Sandstone_Brick","x":1,"y":-22,"z":21},{"name":"Rock_Sandstone_Brick","x":1,"y":-21,"z":21},{"name":"Rock_Sandstone_Brick","x":1,"y":-20,"z":21},{"name":"Rock_Sandstone_Cobble","x":1,"y":-19,"z":21},{"name":"Rock_Sandstone","x":1,"y":-18,"z":21},{"name":"Rock_Sandstone_Cobble","x":1,"y":-17,"z":21},{"name":"Rock_Sandstone_Brick","x":1,"y":-16,"z":21},{"name":"Rock_Sandstone_Brick","x":1,"y":-15,"z":21},{"name":"Rock_Sandstone_Brick","x":1,"y":-14,"z":21},{"name":"Rock_Sandstone","x":1,"y":-13,"z":21},{"name":"Rock_Sandstone_Brick","x":1,"y":-12,"z":21},{"name":"Rock_Sandstone_Brick","x":1,"y":-11,"z":21},{"name":"Rock_Sandstone_Brick","x":1,"y":-10,"z":21},{"name":"Rock_Sandstone_Brick","x":1,"y":-9,"z":21},{"name":"Rock_Sandstone_Brick","x":1,"y":-8,"z":21},{"name":"Rock_Sandstone_Brick","x":1,"y":-7,"z":21},{"name":"Rock_Sandstone_Brick","x":1,"y":-6,"z":21},{"name":"Rock_Sandstone_Brick","x":1,"y":-5,"z":21},{"name":"Rock_Sandstone_Brick","x":1,"y":-4,"z":21},{"name":"Rock_Sandstone_Cobble","x":1,"y":-3,"z":21},{"name":"Rock_Sandstone_Brick","x":1,"y":-2,"z":21},{"name":"Rock_Sandstone_Brick","x":1,"y":-1,"z":21},{"name":"Rock_Sandstone_Brick","x":1,"y":0,"z":21},{"name":"Rock_Sandstone_Brick","x":2,"y":-35,"z":0},{"name":"Rock_Sandstone_Brick","x":2,"y":-34,"z":0},{"name":"Rock_Sandstone","x":2,"y":-33,"z":0},{"name":"Rock_Sandstone","x":2,"y":-32,"z":0},{"name":"Rock_Sandstone_Brick","x":2,"y":-31,"z":0},{"name":"Rock_Sandstone_Brick","x":2,"y":-30,"z":0},{"name":"Rock_Sandstone","x":2,"y":-29,"z":0},{"name":"Rock_Sandstone_Brick","x":2,"y":-28,"z":0},{"name":"Rock_Sandstone","x":2,"y":-27,"z":0},{"name":"Rock_Sandstone_Cobble","x":2,"y":-26,"z":0},{"name":"Rock_Sandstone_Brick","x":2,"y":-25,"z":0},{"name":"Rock_Sandstone","x":2,"y":-24,"z":0},{"name":"Rock_Sandstone_Brick","x":2,"y":-23,"z":0},{"name":"Rock_Sandstone","x":2,"y":-22,"z":0},{"name":"Rock_Sandstone_Brick","x":2,"y":-21,"z":0},{"name":"Rock_Sandstone_Brick","x":2,"y":-20,"z":0},{"name":"Rock_Sandstone_Brick","x":2,"y":-19,"z":0},{"name":"Rock_Sandstone_Brick","x":2,"y":-18,"z":0},{"name":"Rock_Sandstone_Brick","x":2,"y":-17,"z":0},{"name":"Rock_Sandstone_Cobble","x":2,"y":-16,"z":0},{"name":"Rock_Sandstone_Cobble","x":2,"y":-15,"z":0},{"name":"Rock_Sandstone_Brick","x":2,"y":-14,"z":0},{"name":"Rock_Sandstone_Brick","x":2,"y":-13,"z":0},{"name":"Rock_Sandstone_Cobble","x":2,"y":-12,"z":0},{"name":"Rock_Sandstone_Cobble","x":2,"y":-11,"z":0},{"name":"Rock_Sandstone_Brick","x":2,"y":-10,"z":0},{"name":"Rock_Sandstone_Brick","x":2,"y":-9,"z":0},{"name":"Rock_Sandstone_Brick","x":2,"y":-8,"z":0},{"name":"Rock_Sandstone_Brick","x":2,"y":-7,"z":0},{"name":"Rock_Sandstone_Brick","x":2,"y":-6,"z":0},{"name":"Rock_Sandstone_Brick","x":2,"y":-5,"z":0},{"name":"Rock_Sandstone_Brick","x":2,"y":-4,"z":0},{"name":"Rock_Sandstone","x":2,"y":-3,"z":0},{"name":"Rock_Sandstone_Brick","x":2,"y":-2,"z":0},{"name":"Rock_Sandstone_Brick","x":2,"y":-1,"z":0},{"name":"Rock_Sandstone_Brick","x":2,"y":0,"z":0},{"name":"Rock_Sandstone_Cobble","x":2,"y":-35,"z":1},{"name":"Rock_Sandstone_Brick","x":2,"y":-34,"z":1},{"name":"Rock_Sandstone_Brick","x":2,"y":-33,"z":1},{"name":"Rock_Sandstone_Brick","x":2,"y":-32,"z":1},{"name":"Rock_Sandstone_Brick","x":2,"y":-31,"z":1},{"name":"Rock_Sandstone_Brick","x":2,"y":-30,"z":1},{"name":"Rock_Sandstone_Brick","x":2,"y":-29,"z":1},{"name":"Rock_Sandstone_Brick","x":2,"y":-28,"z":1},{"name":"Rock_Sandstone_Brick","x":2,"y":-27,"z":1},{"name":"Rock_Sandstone_Brick","x":2,"y":-26,"z":1},{"name":"Rock_Sandstone_Brick","rotation":3,"x":2,"y":-25,"z":1},{"name":"Rock_Sandstone_Brick","rotation":3,"x":2,"y":-24,"z":1},{"name":"Rock_Sandstone_Brick","rotation":3,"x":2,"y":-23,"z":1},{"name":"Rock_Sandstone_Brick","rotation":3,"x":2,"y":-22,"z":1},{"name":"Rock_Sandstone_Brick","rotation":3,"x":2,"y":-21,"z":1},{"name":"Rock_Sandstone_Brick","rotation":3,"x":2,"y":-20,"z":1},{"name":"Rock_Sandstone_Brick","rotation":3,"x":2,"y":-19,"z":1},{"name":"Rock_Sandstone_Brick","rotation":3,"x":2,"y":-18,"z":1},{"name":"Rock_Sandstone_Brick","rotation":3,"x":2,"y":-17,"z":1},{"name":"Rock_Sandstone_Brick","rotation":3,"x":2,"y":-16,"z":1},{"name":"Rock_Sandstone_Brick","rotation":3,"x":2,"y":-15,"z":1},{"name":"Rock_Sandstone","rotation":3,"x":2,"y":-14,"z":1},{"name":"Rock_Sandstone_Brick","rotation":3,"x":2,"y":-13,"z":1},{"name":"Rock_Sandstone_Brick","rotation":3,"x":2,"y":-12,"z":1},{"name":"Rock_Sandstone_Brick","rotation":3,"x":2,"y":-11,"z":1},{"name":"Rock_Sandstone_Brick","rotation":3,"x":2,"y":-10,"z":1},{"name":"Rock_Sandstone_Brick","rotation":3,"x":2,"y":-9,"z":1},{"name":"Rock_Sandstone_Brick","rotation":3,"x":2,"y":-8,"z":1},{"name":"Rock_Sandstone_Brick","rotation":3,"x":2,"y":-7,"z":1},{"name":"Rock_Sandstone_Brick","rotation":3,"x":2,"y":-6,"z":1},{"name":"Rock_Sandstone_Cobble","rotation":3,"x":2,"y":-5,"z":1},{"name":"Rock_Sandstone","rotation":3,"x":2,"y":-4,"z":1},{"name":"Rock_Sandstone_Brick","rotation":3,"x":2,"y":-3,"z":1},{"name":"Rock_Sandstone_Brick","rotation":3,"x":2,"y":-2,"z":1},{"name":"Rock_Sandstone_Brick","rotation":3,"x":2,"y":-1,"z":1},{"name":"Rock_Sandstone_Brick","x":2,"y":0,"z":1},{"name":"Rock_Sandstone_Brick","x":2,"y":-35,"z":2},{"name":"Rock_Sandstone_Brick","x":2,"y":-34,"z":2},{"name":"Rock_Sandstone_Brick","x":2,"y":-33,"z":2},{"name":"Rock_Sandstone_Brick","x":2,"y":-32,"z":2},{"name":"Rock_Sandstone_Brick","x":2,"y":-31,"z":2},{"name":"Rock_Sandstone_Brick","x":2,"y":-30,"z":2},{"name":"Rock_Sandstone_Brick","x":2,"y":-29,"z":2},{"name":"Rock_Sandstone_Brick","x":2,"y":-28,"z":2},{"name":"Rock_Sandstone_Cobble","x":2,"y":-27,"z":2},{"name":"Rock_Sandstone_Brick","x":2,"y":-26,"z":2},{"name":"Rock_Sandstone_Cobble","rotation":3,"x":2,"y":-25,"z":2},{"name":"Rock_Sandstone_Brick","rotation":3,"x":2,"y":-24,"z":2},{"name":"Rock_Sandstone_Cobble","rotation":3,"x":2,"y":-23,"z":2},{"name":"Rock_Sandstone","rotation":3,"x":2,"y":-22,"z":2},{"name":"Rock_Sandstone_Brick","rotation":3,"x":2,"y":-21,"z":2},{"name":"Rock_Sandstone_Brick","rotation":3,"x":2,"y":-20,"z":2},{"name":"Rock_Sandstone_Brick","rotation":3,"x":2,"y":-19,"z":2},{"name":"Rock_Sandstone_Brick","rotation":3,"x":2,"y":-18,"z":2},{"name":"Rock_Sandstone_Brick","rotation":3,"x":2,"y":-17,"z":2},{"name":"Rock_Sandstone","rotation":3,"x":2,"y":-16,"z":2},{"name":"Rock_Sandstone_Brick","rotation":3,"x":2,"y":-15,"z":2},{"name":"Rock_Sandstone_Brick","rotation":3,"x":2,"y":-14,"z":2},{"name":"Rock_Sandstone_Brick","rotation":3,"x":2,"y":-13,"z":2},{"name":"Rock_Sandstone_Brick","rotation":3,"x":2,"y":-12,"z":2},{"name":"Rock_Sandstone_Brick","rotation":3,"x":2,"y":-11,"z":2},{"name":"Rock_Sandstone_Brick","rotation":3,"x":2,"y":-10,"z":2},{"name":"Rock_Sandstone","rotation":3,"x":2,"y":-9,"z":2},{"name":"Rock_Sandstone_Brick","rotation":3,"x":2,"y":-8,"z":2},{"name":"Rock_Sandstone_Brick","rotation":3,"x":2,"y":-7,"z":2},{"name":"Rock_Sandstone_Cobble","rotation":3,"x":2,"y":-6,"z":2},{"name":"Rock_Sandstone_Brick","rotation":3,"x":2,"y":-5,"z":2},{"name":"Rock_Sandstone_Brick","rotation":3,"x":2,"y":-4,"z":2},{"name":"Rock_Sandstone_Brick","rotation":3,"x":2,"y":-3,"z":2},{"name":"Rock_Sandstone_Brick","rotation":3,"x":2,"y":-2,"z":2},{"name":"Rock_Sandstone_Brick","rotation":3,"x":2,"y":-1,"z":2},{"name":"Rock_Sandstone_Brick","x":2,"y":0,"z":2},{"name":"Rock_Sandstone","x":2,"y":-35,"z":3},{"name":"Rock_Sandstone","x":2,"y":-34,"z":3},{"name":"Rock_Sandstone_Brick","x":2,"y":-33,"z":3},{"name":"Rock_Sandstone_Brick","x":2,"y":-32,"z":3},{"name":"Rock_Sandstone_Brick","x":2,"y":-31,"z":3},{"name":"Rock_Sandstone_Brick","x":2,"y":-30,"z":3},{"name":"Rock_Sandstone_Brick","x":2,"y":-29,"z":3},{"name":"Rock_Sandstone_Brick","x":2,"y":-28,"z":3},{"name":"Rock_Sandstone_Brick","x":2,"y":-27,"z":3},{"name":"Rock_Sandstone_Cobble","x":2,"y":-26,"z":3},{"name":"Rock_Sandstone_Brick","rotation":3,"x":2,"y":-25,"z":3},{"name":"Rock_Sandstone","rotation":3,"x":2,"y":-24,"z":3},{"name":"Rock_Sandstone_Brick","rotation":3,"x":2,"y":-23,"z":3},{"name":"Rock_Sandstone_Brick","rotation":3,"x":2,"y":-22,"z":3},{"name":"Rock_Sandstone_Brick","rotation":3,"x":2,"y":-21,"z":3},{"name":"Rock_Sandstone_Cobble","rotation":3,"x":2,"y":-20,"z":3},{"name":"Rock_Sandstone_Brick","rotation":3,"x":2,"y":-19,"z":3},{"name":"Rock_Sandstone","rotation":3,"x":2,"y":-18,"z":3},{"name":"Rock_Sandstone_Brick","rotation":3,"x":2,"y":-17,"z":3},{"name":"Rock_Sandstone_Brick","rotation":3,"x":2,"y":-16,"z":3},{"name":"Rock_Sandstone","rotation":3,"x":2,"y":-15,"z":3},{"name":"Rock_Sandstone_Brick","rotation":3,"x":2,"y":-14,"z":3},{"name":"Rock_Sandstone_Brick","rotation":3,"x":2,"y":-13,"z":3},{"name":"Rock_Sandstone_Cobble","rotation":3,"x":2,"y":-12,"z":3},{"name":"Rock_Sandstone_Brick","rotation":3,"x":2,"y":-11,"z":3},{"name":"Rock_Sandstone_Brick","rotation":3,"x":2,"y":-10,"z":3},{"name":"Rock_Sandstone_Cobble","rotation":3,"x":2,"y":-9,"z":3},{"name":"Rock_Sandstone_Brick","rotation":3,"x":2,"y":-8,"z":3},{"name":"Rock_Sandstone_Brick","rotation":3,"x":2,"y":-7,"z":3},{"name":"Rock_Sandstone_Brick","rotation":3,"x":2,"y":-6,"z":3},{"name":"Rock_Sandstone_Brick","rotation":3,"x":2,"y":-5,"z":3},{"name":"Rock_Sandstone","rotation":3,"x":2,"y":-4,"z":3},{"name":"Rock_Sandstone_Brick","rotation":3,"x":2,"y":-3,"z":3},{"name":"Rock_Sandstone_Brick","rotation":3,"x":2,"y":-2,"z":3},{"name":"Rock_Sandstone_Brick","rotation":3,"x":2,"y":-1,"z":3},{"name":"Rock_Sandstone_Brick","x":2,"y":0,"z":3},{"name":"Rock_Sandstone_Brick","x":2,"y":-35,"z":4},{"name":"Rock_Sandstone_Brick","x":2,"y":-34,"z":4},{"name":"Rock_Sandstone_Brick","x":2,"y":-33,"z":4},{"name":"Rock_Sandstone_Brick","x":2,"y":-32,"z":4},{"name":"Rock_Sandstone_Brick","x":2,"y":-31,"z":4},{"name":"Rock_Sandstone_Brick","x":2,"y":-30,"z":4},{"name":"Rock_Sandstone_Brick","x":2,"y":-29,"z":4},{"name":"Rock_Sandstone_Brick","x":2,"y":-28,"z":4},{"name":"Rock_Sandstone_Brick","x":2,"y":-27,"z":4},{"name":"Rock_Sandstone_Brick","x":2,"y":-26,"z":4},{"name":"Rock_Sandstone_Cobble","x":2,"y":-25,"z":4},{"name":"Rock_Sandstone_Cobble","x":2,"y":-24,"z":4},{"name":"Rock_Sandstone_Brick","x":2,"y":-23,"z":4},{"name":"Rock_Sandstone_Brick","x":2,"y":-22,"z":4},{"name":"Rock_Sandstone_Brick","x":2,"y":-21,"z":4},{"name":"Rock_Sandstone_Brick","x":2,"y":-20,"z":4},{"name":"Rock_Sandstone","x":2,"y":-19,"z":4},{"name":"Rock_Sandstone","x":2,"y":-18,"z":4},{"name":"Rock_Sandstone_Brick","x":2,"y":-17,"z":4},{"name":"Rock_Sandstone_Cobble","x":2,"y":-16,"z":4},{"name":"Rock_Sandstone_Brick","x":2,"y":-15,"z":4},{"name":"Rock_Sandstone_Brick","x":2,"y":-14,"z":4},{"name":"Rock_Sandstone_Brick","x":2,"y":-13,"z":4},{"name":"Rock_Sandstone_Cobble","x":2,"y":-12,"z":4},{"name":"Rock_Sandstone","x":2,"y":-11,"z":4},{"name":"Rock_Sandstone","x":2,"y":-10,"z":4},{"name":"Rock_Sandstone_Brick","x":2,"y":-9,"z":4},{"name":"Rock_Sandstone_Cobble","x":2,"y":-8,"z":4},{"name":"Rock_Sandstone_Brick","x":2,"y":-7,"z":4},{"name":"Rock_Sandstone_Cobble","x":2,"y":-6,"z":4},{"name":"Rock_Sandstone","x":2,"y":-5,"z":4},{"name":"Rock_Sandstone","x":2,"y":-4,"z":4},{"name":"Rock_Sandstone_Brick","x":2,"y":-3,"z":4},{"name":"Rock_Sandstone_Brick","rotation":2,"x":2,"y":-2,"z":4},{"name":"Rock_Sandstone_Brick","x":2,"y":-1,"z":4},{"name":"Rock_Sandstone_Brick","x":2,"y":0,"z":4},{"name":"Rock_Sandstone_Brick","x":2,"y":-35,"z":5},{"name":"Rock_Sandstone_Brick","x":2,"y":-34,"z":5},{"name":"Rock_Sandstone_Cobble","x":2,"y":-33,"z":5},{"name":"Rock_Sandstone","x":2,"y":-32,"z":5},{"name":"Rock_Sandstone","x":2,"y":-31,"z":5},{"name":"Rock_Sandstone_Brick","x":2,"y":-30,"z":5},{"name":"Rock_Sandstone","x":2,"y":-29,"z":5},{"name":"Rock_Sandstone","x":2,"y":-28,"z":5},{"name":"Rock_Sandstone","x":2,"y":-27,"z":5},{"name":"Rock_Sandstone_Cobble","x":2,"y":-26,"z":5},{"name":"Rock_Sandstone_Brick","x":2,"y":-25,"z":5},{"name":"Rock_Sandstone_Brick","x":2,"y":-24,"z":5},{"name":"Rock_Sandstone_Brick","x":2,"y":-23,"z":5},{"name":"Rock_Sandstone_Brick","x":2,"y":-22,"z":5},{"name":"Rock_Sandstone_Brick","x":2,"y":-21,"z":5},{"name":"Rock_Sandstone_Cobble","x":2,"y":-20,"z":5},{"name":"Rock_Sandstone_Brick","x":2,"y":-19,"z":5},{"name":"Rock_Sandstone","x":2,"y":-18,"z":5},{"name":"Rock_Sandstone_Brick","x":2,"y":-17,"z":5},{"name":"Rock_Sandstone_Brick","x":2,"y":-16,"z":5},{"name":"Rock_Sandstone","x":2,"y":-15,"z":5},{"name":"Rock_Sandstone_Brick","x":2,"y":-14,"z":5},{"name":"Rock_Sandstone_Brick","x":2,"y":-13,"z":5},{"name":"Rock_Sandstone_Brick","x":2,"y":-12,"z":5},{"name":"Rock_Sandstone_Brick","x":2,"y":-11,"z":5},{"name":"Rock_Sandstone_Brick","x":2,"y":-10,"z":5},{"name":"Rock_Sandstone_Cobble","x":2,"y":-9,"z":5},{"name":"Rock_Sandstone_Cobble","x":2,"y":-8,"z":5},{"name":"Rock_Sandstone","x":2,"y":-7,"z":5},{"name":"Rock_Sandstone_Brick","x":2,"y":-6,"z":5},{"name":"Rock_Sandstone_Brick","x":2,"y":-5,"z":5},{"name":"Rock_Sandstone","x":2,"y":-4,"z":5},{"name":"Rock_Sandstone","x":2,"y":-3,"z":5},{"name":"Rock_Sandstone_Brick","rotation":2,"x":2,"y":-2,"z":5},{"name":"Rock_Sandstone_Brick","x":2,"y":-1,"z":5},{"name":"Rock_Sandstone_Brick","x":2,"y":0,"z":5},{"name":"Rock_Sandstone_Brick_Stairs","rotation":10,"x":2,"y":-8,"z":6},{"name":"Rock_Sandstone_Cobble","x":2,"y":-7,"z":6},{"name":"Rock_Sandstone_Cobble","x":2,"y":-6,"z":6},{"name":"Rock_Sandstone_Brick","x":2,"y":-5,"z":6},{"name":"Rock_Sandstone_Brick","x":2,"y":-4,"z":6},{"name":"Rock_Sandstone_Brick","x":2,"y":-3,"z":6},{"name":"Rock_Sandstone_Brick","x":2,"y":-2,"z":6},{"name":"Rock_Sandstone_Brick","x":2,"y":-1,"z":6},{"name":"Rock_Sandstone_Brick","x":2,"y":0,"z":6},{"name":"Rock_Sandstone_Brick_Stairs","rotation":10,"x":2,"y":-5,"z":7},{"name":"Rock_Sandstone_Brick","x":2,"y":-4,"z":7},{"name":"Rock_Sandstone_Brick","x":2,"y":-3,"z":7},{"name":"Rock_Sandstone_Brick","x":2,"y":-2,"z":7},{"name":"Rock_Sandstone_Brick","x":2,"y":-1,"z":7},{"name":"Rock_Sandstone_Brick","x":2,"y":0,"z":7},{"name":"Rock_Sandstone_Brick","x":2,"y":-4,"z":8},{"name":"Rock_Sandstone","x":2,"y":-3,"z":8},{"name":"Rock_Sandstone_Brick","x":2,"y":-2,"z":8},{"name":"Rock_Sandstone_Brick","x":2,"y":-1,"z":8},{"name":"Rock_Sandstone_Brick","x":2,"y":0,"z":8},{"name":"Rock_Sandstone_Brick_Stairs","rotation":10,"x":2,"y":-4,"z":9},{"name":"Rock_Sandstone_Brick","x":2,"y":-3,"z":9},{"name":"Rock_Sandstone_Brick","x":2,"y":-2,"z":9},{"name":"Rock_Sandstone_Brick_Stairs","rotation":35,"x":2,"y":-1,"z":9},{"name":"Rock_Sandstone_Brick","x":2,"y":0,"z":9},{"name":"Rock_Sandstone_Brick","x":2,"y":-3,"z":10},{"name":"Rock_Sandstone_Brick","x":2,"y":-2,"z":10},{"name":"Rock_Sandstone_Brick","x":2,"y":-1,"z":10},{"name":"Rock_Sandstone_Brick","x":2,"y":0,"z":10},{"name":"Rock_Sandstone_Cobble","x":2,"y":-3,"z":11},{"name":"Rock_Sandstone_Brick","x":2,"y":-2,"z":11},{"name":"Rock_Sandstone_Brick","x":2,"y":-1,"z":11},{"name":"Rock_Sandstone_Brick","x":2,"y":0,"z":11},{"name":"Rock_Sandstone_Brick_Stairs","rotation":8,"x":2,"y":-4,"z":12},{"name":"Rock_Sandstone_Brick","x":2,"y":-3,"z":12},{"name":"Rock_Sandstone_Brick","x":2,"y":-2,"z":12},{"name":"Rock_Sandstone_Brick_Stairs","rotation":35,"x":2,"y":-1,"z":12},{"name":"Rock_Sandstone_Brick","x":2,"y":0,"z":12},{"name":"Rock_Sandstone_Cobble","x":2,"y":-4,"z":13},{"name":"Rock_Sandstone","x":2,"y":-3,"z":13},{"name":"Rock_Sandstone_Brick","x":2,"y":-2,"z":13},{"name":"Rock_Sandstone_Brick","x":2,"y":-1,"z":13},{"name":"Rock_Sandstone_Brick","x":2,"y":0,"z":13},{"name":"Rock_Sandstone_Brick_Stairs","rotation":8,"x":2,"y":-5,"z":14},{"name":"Rock_Sandstone","x":2,"y":-4,"z":14},{"name":"Rock_Sandstone_Cobble","x":2,"y":-3,"z":14},{"name":"Rock_Sandstone_Brick","x":2,"y":-2,"z":14},{"name":"Rock_Sandstone_Brick","x":2,"y":-1,"z":14},{"name":"Rock_Sandstone_Brick","x":2,"y":0,"z":14},{"name":"Rock_Sandstone_Brick_Stairs","rotation":8,"x":2,"y":-8,"z":15},{"name":"Rock_Sandstone_Brick","x":2,"y":-7,"z":15},{"name":"Rock_Sandstone_Brick","x":2,"y":-6,"z":15},{"name":"Rock_Sandstone","x":2,"y":-5,"z":15},{"name":"Rock_Sandstone_Brick","x":2,"y":-4,"z":15},{"name":"Rock_Sandstone_Cobble","x":2,"y":-3,"z":15},{"name":"Rock_Sandstone_Brick","x":2,"y":-2,"z":15},{"name":"Rock_Sandstone_Brick","x":2,"y":-1,"z":15},{"name":"Rock_Sandstone_Brick","x":2,"y":0,"z":15},{"name":"Rock_Sandstone_Brick","x":2,"y":-35,"z":16},{"name":"Rock_Sandstone_Brick","x":2,"y":-34,"z":16},{"name":"Rock_Sandstone","x":2,"y":-33,"z":16},{"name":"Rock_Sandstone_Brick","x":2,"y":-32,"z":16},{"name":"Rock_Sandstone_Brick","x":2,"y":-31,"z":16},{"name":"Rock_Sandstone_Cobble","x":2,"y":-30,"z":16},{"name":"Rock_Sandstone_Brick","x":2,"y":-29,"z":16},{"name":"Rock_Sandstone_Cobble","x":2,"y":-28,"z":16},{"name":"Rock_Sandstone_Brick","x":2,"y":-27,"z":16},{"name":"Rock_Sandstone","x":2,"y":-26,"z":16},{"name":"Rock_Sandstone","x":2,"y":-25,"z":16},{"name":"Rock_Sandstone_Brick","x":2,"y":-24,"z":16},{"name":"Rock_Sandstone","x":2,"y":-23,"z":16},{"name":"Rock_Sandstone_Brick","x":2,"y":-22,"z":16},{"name":"Rock_Sandstone","x":2,"y":-21,"z":16},{"name":"Rock_Sandstone_Brick","x":2,"y":-20,"z":16},{"name":"Rock_Sandstone","x":2,"y":-19,"z":16},{"name":"Rock_Sandstone_Cobble","x":2,"y":-18,"z":16},{"name":"Rock_Sandstone","x":2,"y":-17,"z":16},{"name":"Rock_Sandstone_Brick","x":2,"y":-16,"z":16},{"name":"Rock_Sandstone_Cobble","x":2,"y":-15,"z":16},{"name":"Rock_Sandstone_Brick","x":2,"y":-14,"z":16},{"name":"Rock_Sandstone","x":2,"y":-13,"z":16},{"name":"Rock_Sandstone_Brick","x":2,"y":-12,"z":16},{"name":"Rock_Sandstone_Brick","x":2,"y":-11,"z":16},{"name":"Rock_Sandstone_Brick","x":2,"y":-10,"z":16},{"name":"Rock_Sandstone_Brick","x":2,"y":-9,"z":16},{"name":"Rock_Sandstone_Brick","x":2,"y":-8,"z":16},{"name":"Rock_Sandstone_Brick","x":2,"y":-7,"z":16},{"name":"Rock_Sandstone_Brick","x":2,"y":-6,"z":16},{"name":"Rock_Sandstone_Brick","x":2,"y":-5,"z":16},{"name":"Rock_Sandstone","x":2,"y":-4,"z":16},{"name":"Rock_Sandstone_Cobble","x":2,"y":-3,"z":16},{"name":"Rock_Sandstone_Brick","x":2,"y":-2,"z":16},{"name":"Rock_Sandstone_Brick","x":2,"y":-1,"z":16},{"name":"Rock_Sandstone_Brick","x":2,"y":0,"z":16},{"name":"Rock_Sandstone_Brick","x":2,"y":-35,"z":17},{"name":"Rock_Sandstone_Brick","x":2,"y":-34,"z":17},{"name":"Rock_Sandstone","x":2,"y":-33,"z":17},{"name":"Rock_Sandstone_Brick","x":2,"y":-32,"z":17},{"name":"Rock_Sandstone_Cobble","x":2,"y":-31,"z":17},{"name":"Rock_Sandstone_Brick","x":2,"y":-30,"z":17},{"name":"Rock_Sandstone","x":2,"y":-29,"z":17},{"name":"Rock_Sandstone_Brick","x":2,"y":-28,"z":17},{"name":"Rock_Sandstone_Brick","x":2,"y":-27,"z":17},{"name":"Rock_Sandstone","x":2,"y":-26,"z":17},{"name":"Rock_Sandstone_Cobble","x":2,"y":-25,"z":17},{"name":"Rock_Sandstone_Cobble","x":2,"y":-24,"z":17},{"name":"Rock_Sandstone","x":2,"y":-23,"z":17},{"name":"Rock_Sandstone_Brick","x":2,"y":-22,"z":17},{"name":"Rock_Sandstone_Brick","x":2,"y":-21,"z":17},{"name":"Rock_Sandstone","x":2,"y":-20,"z":17},{"name":"Rock_Sandstone","x":2,"y":-19,"z":17},{"name":"Rock_Sandstone_Brick","x":2,"y":-18,"z":17},{"name":"Rock_Sandstone_Brick","x":2,"y":-17,"z":17},{"name":"Rock_Sandstone_Brick","x":2,"y":-16,"z":17},{"name":"Rock_Sandstone_Brick","x":2,"y":-15,"z":17},{"name":"Rock_Sandstone_Brick","x":2,"y":-14,"z":17},{"name":"Rock_Sandstone_Brick","x":2,"y":-13,"z":17},{"name":"Rock_Sandstone_Brick","x":2,"y":-12,"z":17},{"name":"Rock_Sandstone_Brick","x":2,"y":-11,"z":17},{"name":"Rock_Sandstone_Brick","x":2,"y":-10,"z":17},{"name":"Rock_Sandstone_Cobble","x":2,"y":-9,"z":17},{"name":"Rock_Sandstone","x":2,"y":-8,"z":17},{"name":"Rock_Sandstone_Brick","x":2,"y":-7,"z":17},{"name":"Rock_Sandstone_Brick","x":2,"y":-6,"z":17},{"name":"Rock_Sandstone_Brick","x":2,"y":-5,"z":17},{"name":"Rock_Sandstone_Brick","x":2,"y":-4,"z":17},{"name":"Rock_Sandstone_Brick","x":2,"y":-3,"z":17},{"name":"Rock_Sandstone_Brick","x":2,"y":-2,"z":17},{"name":"Rock_Sandstone_Brick","x":2,"y":-1,"z":17},{"name":"Rock_Sandstone_Brick","x":2,"y":0,"z":17},{"name":"Rock_Sandstone_Brick","x":2,"y":-35,"z":18},{"name":"Rock_Sandstone","x":2,"y":-34,"z":18},{"name":"Rock_Sandstone","x":2,"y":-33,"z":18},{"name":"Rock_Sandstone_Cobble","x":2,"y":-32,"z":18},{"name":"Rock_Sandstone_Brick","x":2,"y":-31,"z":18},{"name":"Rock_Sandstone_Brick","x":2,"y":-30,"z":18},{"name":"Rock_Sandstone_Brick","x":2,"y":-29,"z":18},{"name":"Rock_Sandstone_Brick","x":2,"y":-28,"z":18},{"name":"Rock_Sandstone_Brick","x":2,"y":-27,"z":18},{"name":"Rock_Sandstone","x":2,"y":-26,"z":18},{"name":"Rock_Sandstone_Brick","x":2,"y":-25,"z":18},{"name":"Rock_Sandstone_Brick","rotation":1,"x":2,"y":-24,"z":18},{"name":"Rock_Sandstone_Cobble","rotation":1,"x":2,"y":-23,"z":18},{"name":"Rock_Sandstone","rotation":1,"x":2,"y":-22,"z":18},{"name":"Rock_Sandstone_Brick","rotation":1,"x":2,"y":-21,"z":18},{"name":"Rock_Sandstone_Brick","rotation":1,"x":2,"y":-20,"z":18},{"name":"Rock_Sandstone_Brick","rotation":1,"x":2,"y":-19,"z":18},{"name":"Rock_Sandstone_Brick","rotation":1,"x":2,"y":-18,"z":18},{"name":"Rock_Sandstone_Brick","rotation":1,"x":2,"y":-17,"z":18},{"name":"Rock_Sandstone","rotation":1,"x":2,"y":-16,"z":18},{"name":"Rock_Sandstone_Brick","rotation":1,"x":2,"y":-15,"z":18},{"name":"Rock_Sandstone","rotation":1,"x":2,"y":-14,"z":18},{"name":"Rock_Sandstone_Brick","rotation":1,"x":2,"y":-13,"z":18},{"name":"Rock_Sandstone","rotation":1,"x":2,"y":-12,"z":18},{"name":"Rock_Sandstone_Brick","rotation":1,"x":2,"y":-11,"z":18},{"name":"Rock_Sandstone_Brick","rotation":1,"x":2,"y":-10,"z":18},{"name":"Rock_Sandstone_Brick","rotation":1,"x":2,"y":-9,"z":18},{"name":"Rock_Sandstone_Brick","rotation":1,"x":2,"y":-8,"z":18},{"name":"Rock_Sandstone_Brick","rotation":1,"x":2,"y":-7,"z":18},{"name":"Rock_Sandstone_Brick","rotation":1,"x":2,"y":-6,"z":18},{"name":"Rock_Sandstone_Brick","rotation":1,"x":2,"y":-5,"z":18},{"name":"Rock_Sandstone_Brick","rotation":1,"x":2,"y":-4,"z":18},{"name":"Rock_Sandstone_Brick","rotation":1,"x":2,"y":-3,"z":18},{"name":"Rock_Sandstone_Brick","rotation":1,"x":2,"y":-2,"z":18},{"name":"Rock_Sandstone_Brick","rotation":1,"x":2,"y":-1,"z":18},{"name":"Rock_Sandstone_Brick","x":2,"y":0,"z":18},{"name":"Rock_Sandstone_Brick","x":2,"y":-35,"z":19},{"name":"Rock_Sandstone_Brick","x":2,"y":-34,"z":19},{"name":"Rock_Sandstone_Cobble","x":2,"y":-33,"z":19},{"name":"Rock_Sandstone_Brick","x":2,"y":-32,"z":19},{"name":"Rock_Sandstone_Brick","x":2,"y":-31,"z":19},{"name":"Rock_Sandstone","x":2,"y":-30,"z":19},{"name":"Rock_Sandstone","x":2,"y":-29,"z":19},{"name":"Rock_Sandstone_Brick","x":2,"y":-28,"z":19},{"name":"Rock_Sandstone_Cobble","x":2,"y":-27,"z":19},{"name":"Rock_Sandstone_Brick","x":2,"y":-26,"z":19},{"name":"Rock_Sandstone_Brick","x":2,"y":-25,"z":19},{"name":"Rock_Sandstone_Brick","rotation":1,"x":2,"y":-24,"z":19},{"name":"Rock_Sandstone_Brick","rotation":1,"x":2,"y":-23,"z":19},{"name":"Rock_Sandstone_Brick","rotation":1,"x":2,"y":-22,"z":19},{"name":"Rock_Sandstone_Brick","rotation":1,"x":2,"y":-21,"z":19},{"name":"Rock_Sandstone_Cobble","rotation":1,"x":2,"y":-20,"z":19},{"name":"Rock_Sandstone_Brick","rotation":1,"x":2,"y":-19,"z":19},{"name":"Rock_Sandstone_Brick","rotation":1,"x":2,"y":-18,"z":19},{"name":"Rock_Sandstone_Brick","rotation":1,"x":2,"y":-17,"z":19},{"name":"Rock_Sandstone_Cobble","rotation":1,"x":2,"y":-16,"z":19},{"name":"Rock_Sandstone_Brick","rotation":1,"x":2,"y":-15,"z":19},{"name":"Rock_Sandstone_Brick","rotation":1,"x":2,"y":-14,"z":19},{"name":"Rock_Sandstone_Brick","rotation":1,"x":2,"y":-13,"z":19},{"name":"Rock_Sandstone_Brick","rotation":1,"x":2,"y":-12,"z":19},{"name":"Rock_Sandstone_Cobble","rotation":1,"x":2,"y":-11,"z":19},{"name":"Rock_Sandstone_Brick","rotation":1,"x":2,"y":-10,"z":19},{"name":"Rock_Sandstone_Brick","rotation":1,"x":2,"y":-9,"z":19},{"name":"Rock_Sandstone_Brick","rotation":1,"x":2,"y":-8,"z":19},{"name":"Rock_Sandstone_Brick","rotation":1,"x":2,"y":-7,"z":19},{"name":"Rock_Sandstone_Cobble","rotation":1,"x":2,"y":-6,"z":19},{"name":"Rock_Sandstone_Brick","rotation":1,"x":2,"y":-5,"z":19},{"name":"Rock_Sandstone_Brick","rotation":1,"x":2,"y":-4,"z":19},{"name":"Rock_Sandstone_Cobble","rotation":1,"x":2,"y":-3,"z":19},{"name":"Rock_Sandstone_Brick","rotation":1,"x":2,"y":-2,"z":19},{"name":"Rock_Sandstone_Brick","rotation":1,"x":2,"y":-1,"z":19},{"name":"Rock_Sandstone_Brick","x":2,"y":0,"z":19},{"name":"Rock_Sandstone_Brick","x":2,"y":-35,"z":20},{"name":"Rock_Sandstone","x":2,"y":-34,"z":20},{"name":"Rock_Sandstone_Brick","x":2,"y":-33,"z":20},{"name":"Rock_Sandstone_Brick","x":2,"y":-32,"z":20},{"name":"Rock_Sandstone_Brick","x":2,"y":-31,"z":20},{"name":"Rock_Sandstone_Brick","x":2,"y":-30,"z":20},{"name":"Rock_Sandstone_Brick","x":2,"y":-29,"z":20},{"name":"Rock_Sandstone_Brick","x":2,"y":-28,"z":20},{"name":"Rock_Sandstone_Cobble","x":2,"y":-27,"z":20},{"name":"Rock_Sandstone_Brick","x":2,"y":-26,"z":20},{"name":"Rock_Sandstone_Brick","x":2,"y":-25,"z":20},{"name":"Rock_Sandstone","rotation":1,"x":2,"y":-24,"z":20},{"name":"Rock_Sandstone_Brick","rotation":1,"x":2,"y":-23,"z":20},{"name":"Rock_Sandstone","rotation":1,"x":2,"y":-22,"z":20},{"name":"Rock_Sandstone","rotation":1,"x":2,"y":-21,"z":20},{"name":"Rock_Sandstone_Brick","rotation":1,"x":2,"y":-20,"z":20},{"name":"Rock_Sandstone_Brick","rotation":1,"x":2,"y":-19,"z":20},{"name":"Rock_Sandstone_Brick","rotation":1,"x":2,"y":-18,"z":20},{"name":"Rock_Sandstone","rotation":1,"x":2,"y":-17,"z":20},{"name":"Rock_Sandstone_Brick","rotation":1,"x":2,"y":-16,"z":20},{"name":"Rock_Sandstone_Cobble","rotation":1,"x":2,"y":-15,"z":20},{"name":"Rock_Sandstone_Brick","rotation":1,"x":2,"y":-14,"z":20},{"name":"Rock_Sandstone_Cobble","rotation":1,"x":2,"y":-13,"z":20},{"name":"Rock_Sandstone_Brick","rotation":1,"x":2,"y":-12,"z":20},{"name":"Rock_Sandstone_Brick","rotation":1,"x":2,"y":-11,"z":20},{"name":"Rock_Sandstone_Cobble","rotation":1,"x":2,"y":-10,"z":20},{"name":"Rock_Sandstone_Brick","rotation":1,"x":2,"y":-9,"z":20},{"name":"Rock_Sandstone_Brick","rotation":1,"x":2,"y":-8,"z":20},{"name":"Rock_Sandstone","rotation":1,"x":2,"y":-7,"z":20},{"name":"Rock_Sandstone_Cobble","rotation":1,"x":2,"y":-6,"z":20},{"name":"Rock_Sandstone_Cobble","rotation":1,"x":2,"y":-5,"z":20},{"name":"Rock_Sandstone","rotation":1,"x":2,"y":-4,"z":20},{"name":"Rock_Sandstone","rotation":1,"x":2,"y":-3,"z":20},{"name":"Rock_Sandstone_Brick","rotation":1,"x":2,"y":-2,"z":20},{"name":"Rock_Sandstone_Brick","rotation":1,"x":2,"y":-1,"z":20},{"name":"Rock_Sandstone_Brick","x":2,"y":0,"z":20},{"name":"Rock_Sandstone_Brick","x":2,"y":-35,"z":21},{"name":"Rock_Sandstone_Cobble","x":2,"y":-34,"z":21},{"name":"Rock_Sandstone_Cobble","x":2,"y":-33,"z":21},{"name":"Rock_Sandstone_Brick","x":2,"y":-32,"z":21},{"name":"Rock_Sandstone_Brick","x":2,"y":-31,"z":21},{"name":"Rock_Sandstone","x":2,"y":-30,"z":21},{"name":"Rock_Sandstone_Cobble","x":2,"y":-29,"z":21},{"name":"Rock_Sandstone_Brick","x":2,"y":-28,"z":21},{"name":"Rock_Sandstone","x":2,"y":-27,"z":21},{"name":"Rock_Sandstone_Brick","x":2,"y":-26,"z":21},{"name":"Rock_Sandstone_Brick","x":2,"y":-25,"z":21},{"name":"Rock_Sandstone","x":2,"y":-24,"z":21},{"name":"Rock_Sandstone_Brick","x":2,"y":-23,"z":21},{"name":"Rock_Sandstone_Brick","x":2,"y":-22,"z":21},{"name":"Rock_Sandstone_Brick","x":2,"y":-21,"z":21},{"name":"Rock_Sandstone_Brick","x":2,"y":-20,"z":21},{"name":"Rock_Sandstone_Cobble","x":2,"y":-19,"z":21},{"name":"Rock_Sandstone","x":2,"y":-18,"z":21},{"name":"Rock_Sandstone_Cobble","x":2,"y":-17,"z":21},{"name":"Rock_Sandstone_Brick","x":2,"y":-16,"z":21},{"name":"Rock_Sandstone_Brick","x":2,"y":-15,"z":21},{"name":"Rock_Sandstone","x":2,"y":-14,"z":21},{"name":"Rock_Sandstone_Brick","x":2,"y":-13,"z":21},{"name":"Rock_Sandstone_Brick","x":2,"y":-12,"z":21},{"name":"Rock_Sandstone_Brick","x":2,"y":-11,"z":21},{"name":"Rock_Sandstone_Brick","x":2,"y":-10,"z":21},{"name":"Rock_Sandstone_Brick","x":2,"y":-9,"z":21},{"name":"Rock_Sandstone_Brick","x":2,"y":-8,"z":21},{"name":"Rock_Sandstone_Cobble","x":2,"y":-7,"z":21},{"name":"Rock_Sandstone_Cobble","x":2,"y":-6,"z":21},{"name":"Rock_Sandstone_Brick","x":2,"y":-5,"z":21},{"name":"Rock_Sandstone","x":2,"y":-4,"z":21},{"name":"Rock_Sandstone_Brick","x":2,"y":-3,"z":21},{"name":"Rock_Sandstone_Brick","x":2,"y":-2,"z":21},{"name":"Rock_Sandstone_Brick","x":2,"y":-1,"z":21},{"name":"Rock_Sandstone_Brick","x":2,"y":0,"z":21},{"name":"Rock_Sandstone_Brick","x":3,"y":-35,"z":0},{"name":"Rock_Sandstone_Brick","x":3,"y":-34,"z":0},{"name":"Rock_Sandstone_Brick","x":3,"y":-33,"z":0},{"name":"Rock_Sandstone","x":3,"y":-32,"z":0},{"name":"Rock_Sandstone_Brick","x":3,"y":-31,"z":0},{"name":"Rock_Sandstone_Brick","x":3,"y":-30,"z":0},{"name":"Rock_Sandstone","x":3,"y":-29,"z":0},{"name":"Rock_Sandstone_Cobble","x":3,"y":-28,"z":0},{"name":"Rock_Sandstone_Brick","x":3,"y":-27,"z":0},{"name":"Rock_Sandstone","x":3,"y":-26,"z":0},{"name":"Rock_Sandstone_Brick","x":3,"y":-25,"z":0},{"name":"Rock_Sandstone_Brick","x":3,"y":-24,"z":0},{"name":"Rock_Sandstone_Brick","x":3,"y":-23,"z":0},{"name":"Rock_Sandstone_Brick","x":3,"y":-22,"z":0},{"name":"Rock_Sandstone_Brick","x":3,"y":-21,"z":0},{"name":"Rock_Sandstone_Brick","x":3,"y":-20,"z":0},{"name":"Rock_Sandstone_Brick","x":3,"y":-19,"z":0},{"name":"Rock_Sandstone_Cobble","x":3,"y":-18,"z":0},{"name":"Rock_Sandstone_Brick","x":3,"y":-17,"z":0},{"name":"Rock_Sandstone_Cobble","x":3,"y":-16,"z":0},{"name":"Rock_Sandstone_Brick","x":3,"y":-15,"z":0},{"name":"Rock_Sandstone_Brick","x":3,"y":-14,"z":0},{"name":"Rock_Sandstone","x":3,"y":-13,"z":0},{"name":"Rock_Sandstone_Brick","x":3,"y":-12,"z":0},{"name":"Rock_Sandstone_Brick","x":3,"y":-11,"z":0},{"name":"Rock_Sandstone_Brick","x":3,"y":-10,"z":0},{"name":"Rock_Sandstone_Brick","x":3,"y":-9,"z":0},{"name":"Rock_Sandstone_Brick","x":3,"y":-8,"z":0},{"name":"Rock_Sandstone_Brick","x":3,"y":-7,"z":0},{"name":"Rock_Sandstone_Brick","x":3,"y":-6,"z":0},{"name":"Rock_Sandstone_Brick","x":3,"y":-5,"z":0},{"name":"Rock_Sandstone_Brick","x":3,"y":-4,"z":0},{"name":"Rock_Sandstone_Brick","x":3,"y":-3,"z":0},{"name":"Rock_Sandstone_Brick","x":3,"y":-2,"z":0},{"name":"Rock_Sandstone_Brick","x":3,"y":-1,"z":0},{"name":"Rock_Sandstone_Brick","x":3,"y":0,"z":0},{"name":"Rock_Sandstone_Brick","x":3,"y":-35,"z":1},{"name":"Rock_Sandstone_Cobble","x":3,"y":-34,"z":1},{"name":"Rock_Sandstone","x":3,"y":-33,"z":1},{"name":"Rock_Sandstone_Brick","x":3,"y":-32,"z":1},{"name":"Rock_Sandstone_Brick","x":3,"y":-31,"z":1},{"name":"Rock_Sandstone_Cobble","x":3,"y":-30,"z":1},{"name":"Rock_Sandstone_Brick","x":3,"y":-29,"z":1},{"name":"Rock_Sandstone_Cobble","x":3,"y":-28,"z":1},{"name":"Rock_Sandstone_Brick","x":3,"y":-27,"z":1},{"name":"Rock_Sandstone_Brick","x":3,"y":-26,"z":1},{"name":"Rock_Sandstone_Brick","rotation":3,"x":3,"y":-25,"z":1},{"name":"Rock_Sandstone_Cobble","rotation":3,"x":3,"y":-24,"z":1},{"name":"Rock_Sandstone_Cobble","rotation":3,"x":3,"y":-23,"z":1},{"name":"Rock_Sandstone_Brick","rotation":3,"x":3,"y":-22,"z":1},{"name":"Rock_Sandstone_Brick","rotation":3,"x":3,"y":-21,"z":1},{"name":"Rock_Sandstone","rotation":3,"x":3,"y":-20,"z":1},{"name":"Rock_Sandstone_Brick","rotation":3,"x":3,"y":-19,"z":1},{"name":"Rock_Sandstone_Cobble","rotation":3,"x":3,"y":-18,"z":1},{"name":"Rock_Sandstone_Brick","rotation":3,"x":3,"y":-17,"z":1},{"name":"Rock_Sandstone_Brick","rotation":3,"x":3,"y":-16,"z":1},{"name":"Rock_Sandstone_Brick","rotation":3,"x":3,"y":-15,"z":1},{"name":"Rock_Sandstone_Brick","rotation":3,"x":3,"y":-14,"z":1},{"name":"Rock_Sandstone","rotation":3,"x":3,"y":-13,"z":1},{"name":"Rock_Sandstone","rotation":3,"x":3,"y":-12,"z":1},{"name":"Rock_Sandstone_Brick","rotation":3,"x":3,"y":-11,"z":1},{"name":"Rock_Sandstone_Brick","rotation":3,"x":3,"y":-10,"z":1},{"name":"Rock_Sandstone_Cobble","rotation":3,"x":3,"y":-9,"z":1},{"name":"Rock_Sandstone_Brick","rotation":3,"x":3,"y":-8,"z":1},{"name":"Rock_Sandstone_Brick","rotation":3,"x":3,"y":-7,"z":1},{"name":"Rock_Sandstone_Cobble","rotation":3,"x":3,"y":-6,"z":1},{"name":"Rock_Sandstone_Brick","rotation":3,"x":3,"y":-5,"z":1},{"name":"Rock_Sandstone_Brick","rotation":3,"x":3,"y":-4,"z":1},{"name":"Rock_Sandstone_Brick","rotation":3,"x":3,"y":-3,"z":1},{"name":"Rock_Sandstone_Brick","rotation":3,"x":3,"y":-2,"z":1},{"name":"Rock_Sandstone_Brick","rotation":3,"x":3,"y":-1,"z":1},{"name":"Rock_Sandstone_Brick","x":3,"y":0,"z":1},{"name":"Rock_Sandstone_Brick","x":3,"y":-35,"z":2},{"name":"Rock_Sandstone_Cobble","x":3,"y":-34,"z":2},{"name":"Rock_Sandstone","x":3,"y":-33,"z":2},{"name":"Rock_Sandstone_Brick","x":3,"y":-32,"z":2},{"name":"Rock_Sandstone_Brick","x":3,"y":-31,"z":2},{"name":"Rock_Sandstone_Brick","x":3,"y":-30,"z":2},{"name":"Rock_Sandstone_Brick","x":3,"y":-29,"z":2},{"name":"Rock_Sandstone_Cobble","x":3,"y":-28,"z":2},{"name":"Rock_Sandstone_Brick","x":3,"y":-27,"z":2},{"name":"Rock_Sandstone_Cobble","x":3,"y":-26,"z":2},{"name":"Rock_Sandstone_Brick","rotation":3,"x":3,"y":-25,"z":2},{"name":"Rock_Sandstone_Brick","rotation":3,"x":3,"y":-24,"z":2},{"name":"Rock_Sandstone","rotation":3,"x":3,"y":-23,"z":2},{"name":"Rock_Sandstone","rotation":3,"x":3,"y":-22,"z":2},{"name":"Rock_Sandstone_Brick","rotation":3,"x":3,"y":-21,"z":2},{"name":"Rock_Sandstone_Brick","rotation":3,"x":3,"y":-20,"z":2},{"name":"Rock_Sandstone_Cobble","rotation":3,"x":3,"y":-19,"z":2},{"name":"Rock_Sandstone_Brick","rotation":3,"x":3,"y":-18,"z":2},{"name":"Rock_Sandstone","rotation":3,"x":3,"y":-17,"z":2},{"name":"Rock_Sandstone","rotation":3,"x":3,"y":-16,"z":2},{"name":"Rock_Sandstone_Brick","rotation":3,"x":3,"y":-15,"z":2},{"name":"Rock_Sandstone_Brick","rotation":3,"x":3,"y":-14,"z":2},{"name":"Rock_Sandstone_Brick","rotation":3,"x":3,"y":-13,"z":2},{"name":"Rock_Sandstone_Brick","rotation":3,"x":3,"y":-12,"z":2},{"name":"Rock_Sandstone","rotation":3,"x":3,"y":-11,"z":2},{"name":"Rock_Sandstone_Cobble","rotation":3,"x":3,"y":-10,"z":2},{"name":"Rock_Sandstone_Brick","rotation":3,"x":3,"y":-9,"z":2},{"name":"Rock_Sandstone_Brick","rotation":3,"x":3,"y":-8,"z":2},{"name":"Rock_Sandstone","rotation":3,"x":3,"y":-7,"z":2},{"name":"Rock_Sandstone","rotation":3,"x":3,"y":-6,"z":2},{"name":"Rock_Sandstone_Cobble","rotation":3,"x":3,"y":-5,"z":2},{"name":"Rock_Sandstone_Brick","rotation":3,"x":3,"y":-4,"z":2},{"name":"Rock_Sandstone_Brick","rotation":3,"x":3,"y":-3,"z":2},{"name":"Rock_Sandstone_Brick","rotation":3,"x":3,"y":-2,"z":2},{"name":"Rock_Sandstone_Brick","rotation":3,"x":3,"y":-1,"z":2},{"name":"Rock_Sandstone_Brick","x":3,"y":0,"z":2},{"name":"Rock_Sandstone_Brick","x":3,"y":-35,"z":3},{"name":"Rock_Sandstone_Brick","x":3,"y":-34,"z":3},{"name":"Rock_Sandstone_Brick","x":3,"y":-33,"z":3},{"name":"Rock_Sandstone_Brick","x":3,"y":-32,"z":3},{"name":"Rock_Sandstone_Brick","x":3,"y":-31,"z":3},{"name":"Rock_Sandstone_Brick","x":3,"y":-30,"z":3},{"name":"Rock_Sandstone_Brick","x":3,"y":-29,"z":3},{"name":"Rock_Sandstone_Brick","x":3,"y":-28,"z":3},{"name":"Rock_Sandstone","x":3,"y":-27,"z":3},{"name":"Rock_Sandstone_Brick","x":3,"y":-26,"z":3},{"name":"Rock_Sandstone","rotation":3,"x":3,"y":-25,"z":3},{"name":"Rock_Sandstone_Brick","rotation":3,"x":3,"y":-24,"z":3},{"name":"Rock_Sandstone","rotation":3,"x":3,"y":-23,"z":3},{"name":"Rock_Sandstone","rotation":3,"x":3,"y":-22,"z":3},{"name":"Rock_Sandstone_Brick","rotation":3,"x":3,"y":-21,"z":3},{"name":"Rock_Sandstone_Brick","rotation":3,"x":3,"y":-20,"z":3},{"name":"Rock_Sandstone_Brick","rotation":3,"x":3,"y":-19,"z":3},{"name":"Rock_Sandstone_Cobble","rotation":3,"x":3,"y":-18,"z":3},{"name":"Rock_Sandstone_Brick","rotation":3,"x":3,"y":-17,"z":3},{"name":"Rock_Sandstone","rotation":3,"x":3,"y":-16,"z":3},{"name":"Rock_Sandstone","rotation":3,"x":3,"y":-15,"z":3},{"name":"Rock_Sandstone_Brick","rotation":3,"x":3,"y":-14,"z":3},{"name":"Rock_Sandstone_Brick","rotation":3,"x":3,"y":-13,"z":3},{"name":"Rock_Sandstone_Brick","rotation":3,"x":3,"y":-12,"z":3},{"name":"Rock_Sandstone_Brick","rotation":3,"x":3,"y":-11,"z":3},{"name":"Rock_Sandstone_Brick","rotation":3,"x":3,"y":-10,"z":3},{"name":"Rock_Sandstone","rotation":3,"x":3,"y":-9,"z":3},{"name":"Rock_Sandstone_Brick","rotation":3,"x":3,"y":-8,"z":3},{"name":"Rock_Sandstone_Brick","rotation":3,"x":3,"y":-7,"z":3},{"name":"Rock_Sandstone_Brick","rotation":3,"x":3,"y":-6,"z":3},{"name":"Rock_Sandstone_Cobble","rotation":3,"x":3,"y":-5,"z":3},{"name":"Rock_Sandstone_Brick","rotation":3,"x":3,"y":-4,"z":3},{"name":"Rock_Sandstone_Brick","rotation":3,"x":3,"y":-3,"z":3},{"name":"Rock_Sandstone_Brick","rotation":3,"x":3,"y":-2,"z":3},{"name":"Rock_Sandstone_Brick","rotation":3,"x":3,"y":-1,"z":3},{"name":"Rock_Sandstone_Brick","x":3,"y":0,"z":3},{"name":"Rock_Sandstone_Brick","x":3,"y":-35,"z":4},{"name":"Rock_Sandstone_Brick","x":3,"y":-34,"z":4},{"name":"Rock_Sandstone_Brick","x":3,"y":-33,"z":4},{"name":"Rock_Sandstone_Cobble","x":3,"y":-32,"z":4},{"name":"Rock_Sandstone_Brick","x":3,"y":-31,"z":4},{"name":"Rock_Sandstone","x":3,"y":-30,"z":4},{"name":"Rock_Sandstone_Brick","x":3,"y":-29,"z":4},{"name":"Rock_Sandstone","x":3,"y":-28,"z":4},{"name":"Rock_Sandstone_Brick","x":3,"y":-27,"z":4},{"name":"Rock_Sandstone_Brick","x":3,"y":-26,"z":4},{"name":"Rock_Sandstone_Cobble","x":3,"y":-25,"z":4},{"name":"Rock_Sandstone_Brick","x":3,"y":-24,"z":4},{"name":"Rock_Sandstone_Brick","x":3,"y":-23,"z":4},{"name":"Rock_Sandstone_Brick","x":3,"y":-22,"z":4},{"name":"Rock_Sandstone","x":3,"y":-21,"z":4},{"name":"Rock_Sandstone","x":3,"y":-20,"z":4},{"name":"Rock_Sandstone_Brick","x":3,"y":-19,"z":4},{"name":"Rock_Sandstone_Brick","x":3,"y":-18,"z":4},{"name":"Rock_Sandstone_Brick","x":3,"y":-17,"z":4},{"name":"Rock_Sandstone_Brick","x":3,"y":-16,"z":4},{"name":"Rock_Sandstone_Brick","x":3,"y":-15,"z":4},{"name":"Rock_Sandstone_Brick","x":3,"y":-14,"z":4},{"name":"Rock_Sandstone_Brick","x":3,"y":-13,"z":4},{"name":"Rock_Sandstone_Brick","x":3,"y":-12,"z":4},{"name":"Rock_Sandstone_Cobble","x":3,"y":-11,"z":4},{"name":"Rock_Sandstone_Brick","x":3,"y":-10,"z":4},{"name":"Rock_Sandstone_Brick","x":3,"y":-9,"z":4},{"name":"Rock_Sandstone_Cobble","x":3,"y":-8,"z":4},{"name":"Rock_Sandstone","x":3,"y":-7,"z":4},{"name":"Rock_Sandstone","x":3,"y":-6,"z":4},{"name":"Rock_Sandstone_Brick","x":3,"y":-5,"z":4},{"name":"Rock_Sandstone","x":3,"y":-4,"z":4},{"name":"Rock_Sandstone_Brick","x":3,"y":-3,"z":4},{"name":"Rock_Sandstone_Brick","rotation":2,"x":3,"y":-2,"z":4},{"name":"Rock_Sandstone_Brick","x":3,"y":-1,"z":4},{"name":"Rock_Sandstone_Brick","x":3,"y":0,"z":4},{"name":"Rock_Sandstone_Brick","x":3,"y":-35,"z":5},{"name":"Rock_Sandstone_Brick","x":3,"y":-34,"z":5},{"name":"Rock_Sandstone_Brick","x":3,"y":-33,"z":5},{"name":"Rock_Sandstone_Brick","x":3,"y":-32,"z":5},{"name":"Rock_Sandstone","x":3,"y":-31,"z":5},{"name":"Rock_Sandstone_Brick","x":3,"y":-30,"z":5},{"name":"Rock_Sandstone_Cobble","x":3,"y":-29,"z":5},{"name":"Rock_Sandstone_Brick","x":3,"y":-28,"z":5},{"name":"Rock_Sandstone_Cobble","x":3,"y":-27,"z":5},{"name":"Rock_Sandstone_Cobble","x":3,"y":-26,"z":5},{"name":"Rock_Sandstone_Brick","x":3,"y":-25,"z":5},{"name":"Rock_Sandstone_Brick","x":3,"y":-24,"z":5},{"name":"Rock_Sandstone_Brick","x":3,"y":-23,"z":5},{"name":"Rock_Sandstone_Brick","x":3,"y":-22,"z":5},{"name":"Rock_Sandstone_Brick","x":3,"y":-21,"z":5},{"name":"Rock_Sandstone","x":3,"y":-20,"z":5},{"name":"Rock_Sandstone_Brick","x":3,"y":-19,"z":5},{"name":"Rock_Sandstone_Brick","x":3,"y":-18,"z":5},{"name":"Rock_Sandstone_Brick","x":3,"y":-17,"z":5},{"name":"Rock_Sandstone_Brick","x":3,"y":-16,"z":5},{"name":"Rock_Sandstone_Brick","x":3,"y":-15,"z":5},{"name":"Rock_Sandstone_Brick","x":3,"y":-14,"z":5},{"name":"Rock_Sandstone_Brick","x":3,"y":-13,"z":5},{"name":"Rock_Sandstone_Brick","x":3,"y":-12,"z":5},{"name":"Rock_Sandstone_Cobble","x":3,"y":-11,"z":5},{"name":"Rock_Sandstone_Brick","x":3,"y":-10,"z":5},{"name":"Rock_Sandstone_Cobble","x":3,"y":-9,"z":5},{"name":"Rock_Sandstone","x":3,"y":-8,"z":5},{"name":"Rock_Sandstone_Brick","x":3,"y":-7,"z":5},{"name":"Rock_Sandstone_Cobble","x":3,"y":-6,"z":5},{"name":"Rock_Sandstone_Cobble","x":3,"y":-5,"z":5},{"name":"Rock_Sandstone_Cobble","x":3,"y":-4,"z":5},{"name":"Rock_Sandstone_Brick","x":3,"y":-3,"z":5},{"name":"Rock_Sandstone_Brick","rotation":2,"x":3,"y":-2,"z":5},{"name":"Rock_Sandstone_Brick","x":3,"y":-1,"z":5},{"name":"Rock_Sandstone_Brick","x":3,"y":0,"z":5},{"name":"Rock_Sandstone_Brick_Stairs","rotation":10,"x":3,"y":-8,"z":6},{"name":"Rock_Sandstone_Brick","x":3,"y":-7,"z":6},{"name":"Rock_Sandstone","x":3,"y":-6,"z":6},{"name":"Rock_Sandstone_Brick","x":3,"y":-5,"z":6},{"name":"Rock_Sandstone_Brick","x":3,"y":-4,"z":6},{"name":"Rock_Sandstone_Brick","x":3,"y":-3,"z":6},{"name":"Rock_Sandstone_Brick","x":3,"y":-2,"z":6},{"name":"Rock_Sandstone_Brick","x":3,"y":-1,"z":6},{"name":"Rock_Sandstone_Brick","x":3,"y":0,"z":6},{"name":"Rock_Sandstone_Brick_Stairs","rotation":10,"x":3,"y":-5,"z":7},{"name":"Rock_Sandstone","x":3,"y":-4,"z":7},{"name":"Rock_Sandstone","x":3,"y":-3,"z":7},{"name":"Rock_Sandstone_Brick","x":3,"y":-2,"z":7},{"name":"Rock_Sandstone_Brick","x":3,"y":-1,"z":7},{"name":"Rock_Sandstone_Brick","x":3,"y":0,"z":7},{"name":"Rock_Sandstone_Brick","x":3,"y":-4,"z":8},{"name":"Rock_Sandstone_Brick","x":3,"y":-3,"z":8},{"name":"Rock_Sandstone_Brick","x":3,"y":-2,"z":8},{"name":"Rock_Sandstone_Brick","x":3,"y":-1,"z":8},{"name":"Rock_Sandstone_Brick","x":3,"y":0,"z":8},{"name":"Rock_Sandstone_Brick_Stairs","rotation":10,"x":3,"y":-4,"z":9},{"name":"Rock_Sandstone_Brick","x":3,"y":-3,"z":9},{"name":"Rock_Sandstone_Brick","x":3,"y":-2,"z":9},{"name":"Rock_Sandstone_Brick","rotation":3,"x":3,"y":-1,"z":9},{"name":"Rock_Sandstone_Brick","x":3,"y":0,"z":9},{"name":"Rock_Sandstone_Brick","x":3,"y":-3,"z":10},{"name":"Rock_Sandstone_Brick","x":3,"y":-2,"z":10},{"name":"Rock_Sandstone_Brick","x":3,"y":-1,"z":10},{"name":"Rock_Sandstone_Brick","x":3,"y":0,"z":10},{"name":"Rock_Sandstone_Brick","x":3,"y":-3,"z":11},{"name":"Rock_Sandstone_Brick","x":3,"y":-2,"z":11},{"name":"Rock_Sandstone_Brick","x":3,"y":-1,"z":11},{"name":"Rock_Sandstone_Brick","x":3,"y":0,"z":11},{"name":"Rock_Sandstone_Brick_Stairs","rotation":8,"x":3,"y":-4,"z":12},{"name":"Rock_Sandstone","x":3,"y":-3,"z":12},{"name":"Rock_Sandstone_Brick","x":3,"y":-2,"z":12},{"name":"Rock_Sandstone_Brick","rotation":1,"x":3,"y":-1,"z":12},{"name":"Rock_Sandstone_Brick","x":3,"y":0,"z":12},{"name":"Rock_Sandstone_Brick","x":3,"y":-4,"z":13},{"name":"Rock_Sandstone","x":3,"y":-3,"z":13},{"name":"Rock_Sandstone_Brick","x":3,"y":-2,"z":13},{"name":"Rock_Sandstone_Brick","x":3,"y":-1,"z":13},{"name":"Rock_Sandstone_Brick","x":3,"y":0,"z":13},{"name":"Rock_Sandstone_Brick_Stairs","rotation":8,"x":3,"y":-5,"z":14},{"name":"Rock_Sandstone_Cobble","x":3,"y":-4,"z":14},{"name":"Rock_Sandstone_Brick","x":3,"y":-3,"z":14},{"name":"Rock_Sandstone_Brick","x":3,"y":-2,"z":14},{"name":"Rock_Sandstone_Brick","x":3,"y":-1,"z":14},{"name":"Rock_Sandstone_Brick","x":3,"y":0,"z":14},{"name":"Rock_Sandstone_Brick_Stairs","rotation":8,"x":3,"y":-8,"z":15},{"name":"Rock_Sandstone","x":3,"y":-7,"z":15},{"name":"Rock_Sandstone_Brick","x":3,"y":-6,"z":15},{"name":"Rock_Sandstone_Brick","x":3,"y":-5,"z":15},{"name":"Rock_Sandstone_Brick","x":3,"y":-4,"z":15},{"name":"Rock_Sandstone_Brick","x":3,"y":-3,"z":15},{"name":"Rock_Sandstone_Brick","x":3,"y":-2,"z":15},{"name":"Rock_Sandstone_Brick","x":3,"y":-1,"z":15},{"name":"Rock_Sandstone_Brick","x":3,"y":0,"z":15},{"name":"Rock_Sandstone_Cobble","x":3,"y":-35,"z":16},{"name":"Rock_Sandstone_Cobble","x":3,"y":-34,"z":16},{"name":"Rock_Sandstone_Brick","x":3,"y":-33,"z":16},{"name":"Rock_Sandstone_Brick","x":3,"y":-32,"z":16},{"name":"Rock_Sandstone_Brick","x":3,"y":-31,"z":16},{"name":"Rock_Sandstone_Brick","x":3,"y":-30,"z":16},{"name":"Rock_Sandstone_Cobble","x":3,"y":-29,"z":16},{"name":"Rock_Sandstone_Brick","x":3,"y":-28,"z":16},{"name":"Rock_Sandstone","x":3,"y":-27,"z":16},{"name":"Rock_Sandstone_Brick","x":3,"y":-26,"z":16},{"name":"Rock_Sandstone_Brick","x":3,"y":-25,"z":16},{"name":"Rock_Sandstone","x":3,"y":-24,"z":16},{"name":"Rock_Sandstone","x":3,"y":-23,"z":16},{"name":"Rock_Sandstone","x":3,"y":-22,"z":16},{"name":"Rock_Sandstone_Brick","x":3,"y":-21,"z":16},{"name":"Rock_Sandstone_Cobble","x":3,"y":-20,"z":16},{"name":"Rock_Sandstone_Brick","x":3,"y":-19,"z":16},{"name":"Rock_Sandstone_Brick","x":3,"y":-18,"z":16},{"name":"Rock_Sandstone_Brick","x":3,"y":-17,"z":16},{"name":"Rock_Sandstone_Brick","x":3,"y":-16,"z":16},{"name":"Rock_Sandstone_Cobble","x":3,"y":-15,"z":16},{"name":"Rock_Sandstone_Brick","x":3,"y":-14,"z":16},{"name":"Rock_Sandstone_Brick","x":3,"y":-13,"z":16},{"name":"Rock_Sandstone_Cobble","x":3,"y":-12,"z":16},{"name":"Rock_Sandstone_Brick","x":3,"y":-11,"z":16},{"name":"Rock_Sandstone_Brick","x":3,"y":-10,"z":16},{"name":"Rock_Sandstone_Cobble","x":3,"y":-9,"z":16},{"name":"Rock_Sandstone_Cobble","x":3,"y":-8,"z":16},{"name":"Rock_Sandstone_Brick","x":3,"y":-7,"z":16},{"name":"Rock_Sandstone","x":3,"y":-6,"z":16},{"name":"Rock_Sandstone","x":3,"y":-5,"z":16},{"name":"Rock_Sandstone_Brick","x":3,"y":-4,"z":16},{"name":"Rock_Sandstone_Cobble","x":3,"y":-3,"z":16},{"name":"Rock_Sandstone_Brick","x":3,"y":-2,"z":16},{"name":"Rock_Sandstone_Brick","x":3,"y":-1,"z":16},{"name":"Rock_Sandstone_Brick","x":3,"y":0,"z":16},{"name":"Rock_Sandstone_Brick","x":3,"y":-35,"z":17},{"name":"Rock_Sandstone_Brick","x":3,"y":-34,"z":17},{"name":"Rock_Sandstone","x":3,"y":-33,"z":17},{"name":"Rock_Sandstone_Brick","x":3,"y":-32,"z":17},{"name":"Rock_Sandstone_Brick","x":3,"y":-31,"z":17},{"name":"Rock_Sandstone","x":3,"y":-30,"z":17},{"name":"Rock_Sandstone_Brick","x":3,"y":-29,"z":17},{"name":"Rock_Sandstone_Brick","x":3,"y":-28,"z":17},{"name":"Rock_Sandstone_Brick","x":3,"y":-27,"z":17},{"name":"Rock_Sandstone_Brick","x":3,"y":-26,"z":17},{"name":"Rock_Sandstone","x":3,"y":-25,"z":17},{"name":"Rock_Sandstone_Brick","x":3,"y":-24,"z":17},{"name":"Rock_Sandstone","x":3,"y":-23,"z":17},{"name":"Rock_Sandstone_Brick","x":3,"y":-22,"z":17},{"name":"Rock_Sandstone_Brick","x":3,"y":-21,"z":17},{"name":"Rock_Sandstone_Brick","x":3,"y":-20,"z":17},{"name":"Rock_Sandstone_Brick","x":3,"y":-19,"z":17},{"name":"Rock_Sandstone_Brick","x":3,"y":-18,"z":17},{"name":"Rock_Sandstone_Cobble","x":3,"y":-17,"z":17},{"name":"Rock_Sandstone_Brick","x":3,"y":-16,"z":17},{"name":"Rock_Sandstone_Brick","x":3,"y":-15,"z":17},{"name":"Rock_Sandstone","x":3,"y":-14,"z":17},{"name":"Rock_Sandstone_Brick","x":3,"y":-13,"z":17},{"name":"Rock_Sandstone_Brick","x":3,"y":-12,"z":17},{"name":"Rock_Sandstone_Brick","x":3,"y":-11,"z":17},{"name":"Rock_Sandstone_Brick","x":3,"y":-10,"z":17},{"name":"Rock_Sandstone_Brick","x":3,"y":-9,"z":17},{"name":"Rock_Sandstone_Brick","x":3,"y":-8,"z":17},{"name":"Rock_Sandstone","x":3,"y":-7,"z":17},{"name":"Rock_Sandstone","x":3,"y":-6,"z":17},{"name":"Rock_Sandstone_Brick","x":3,"y":-5,"z":17},{"name":"Rock_Sandstone","x":3,"y":-4,"z":17},{"name":"Rock_Sandstone_Brick","x":3,"y":-3,"z":17},{"name":"Rock_Sandstone_Brick","x":3,"y":-2,"z":17},{"name":"Rock_Sandstone_Brick","x":3,"y":-1,"z":17},{"name":"Rock_Sandstone_Brick","x":3,"y":0,"z":17},{"name":"Rock_Sandstone_Brick","x":3,"y":-35,"z":18},{"name":"Rock_Sandstone_Brick","x":3,"y":-34,"z":18},{"name":"Rock_Sandstone_Cobble","x":3,"y":-33,"z":18},{"name":"Rock_Sandstone","x":3,"y":-32,"z":18},{"name":"Rock_Sandstone_Brick","x":3,"y":-31,"z":18},{"name":"Rock_Sandstone_Brick","x":3,"y":-30,"z":18},{"name":"Rock_Sandstone_Brick","x":3,"y":-29,"z":18},{"name":"Rock_Sandstone","x":3,"y":-28,"z":18},{"name":"Rock_Sandstone","x":3,"y":-27,"z":18},{"name":"Rock_Sandstone_Brick","x":3,"y":-26,"z":18},{"name":"Rock_Sandstone_Brick","x":3,"y":-25,"z":18},{"name":"Rock_Sandstone_Brick","rotation":1,"x":3,"y":-24,"z":18},{"name":"Rock_Sandstone_Brick","rotation":1,"x":3,"y":-23,"z":18},{"name":"Rock_Sandstone","rotation":1,"x":3,"y":-22,"z":18},{"name":"Rock_Sandstone","rotation":1,"x":3,"y":-21,"z":18},{"name":"Rock_Sandstone_Brick","rotation":1,"x":3,"y":-20,"z":18},{"name":"Rock_Sandstone_Brick","rotation":1,"x":3,"y":-19,"z":18},{"name":"Rock_Sandstone","rotation":1,"x":3,"y":-18,"z":18},{"name":"Rock_Sandstone_Cobble","rotation":1,"x":3,"y":-17,"z":18},{"name":"Rock_Sandstone_Brick","rotation":1,"x":3,"y":-16,"z":18},{"name":"Rock_Sandstone_Brick","rotation":1,"x":3,"y":-15,"z":18},{"name":"Rock_Sandstone_Cobble","rotation":1,"x":3,"y":-14,"z":18},{"name":"Rock_Sandstone","rotation":1,"x":3,"y":-13,"z":18},{"name":"Rock_Sandstone_Brick","rotation":1,"x":3,"y":-12,"z":18},{"name":"Rock_Sandstone_Brick","rotation":1,"x":3,"y":-11,"z":18},{"name":"Rock_Sandstone_Brick","rotation":1,"x":3,"y":-10,"z":18},{"name":"Rock_Sandstone_Brick","rotation":1,"x":3,"y":-9,"z":18},{"name":"Rock_Sandstone_Brick","rotation":1,"x":3,"y":-8,"z":18},{"name":"Rock_Sandstone_Brick","rotation":1,"x":3,"y":-7,"z":18},{"name":"Rock_Sandstone_Brick","rotation":1,"x":3,"y":-6,"z":18},{"name":"Rock_Sandstone_Brick","rotation":1,"x":3,"y":-5,"z":18},{"name":"Rock_Sandstone_Brick","rotation":3,"x":3,"y":-4,"z":18},{"name":"Rock_Sandstone_Brick","rotation":3,"x":3,"y":-3,"z":18},{"name":"Rock_Sandstone_Brick","rotation":3,"x":3,"y":-2,"z":18},{"name":"Rock_Sandstone_Brick","rotation":1,"x":3,"y":-1,"z":18},{"name":"Rock_Sandstone_Brick","x":3,"y":0,"z":18},{"name":"Rock_Sandstone_Cobble","x":3,"y":-35,"z":19},{"name":"Rock_Sandstone_Cobble","x":3,"y":-34,"z":19},{"name":"Rock_Sandstone_Brick","x":3,"y":-33,"z":19},{"name":"Rock_Sandstone","x":3,"y":-32,"z":19},{"name":"Rock_Sandstone_Brick","x":3,"y":-31,"z":19},{"name":"Rock_Sandstone_Brick","x":3,"y":-30,"z":19},{"name":"Rock_Sandstone_Cobble","x":3,"y":-29,"z":19},{"name":"Rock_Sandstone_Cobble","x":3,"y":-28,"z":19},{"name":"Rock_Sandstone_Brick","x":3,"y":-27,"z":19},{"name":"Rock_Sandstone_Brick","x":3,"y":-26,"z":19},{"name":"Rock_Sandstone_Brick","x":3,"y":-25,"z":19},{"name":"Rock_Sandstone_Brick","rotation":1,"x":3,"y":-24,"z":19},{"name":"Rock_Sandstone_Brick","rotation":1,"x":3,"y":-23,"z":19},{"name":"Rock_Sandstone","rotation":1,"x":3,"y":-22,"z":19},{"name":"Rock_Sandstone","rotation":1,"x":3,"y":-21,"z":19},{"name":"Rock_Sandstone","rotation":1,"x":3,"y":-20,"z":19},{"name":"Rock_Sandstone_Cobble","rotation":1,"x":3,"y":-19,"z":19},{"name":"Rock_Sandstone_Brick","rotation":1,"x":3,"y":-18,"z":19},{"name":"Rock_Sandstone","rotation":1,"x":3,"y":-17,"z":19},{"name":"Rock_Sandstone_Brick","rotation":1,"x":3,"y":-16,"z":19},{"name":"Rock_Sandstone_Brick","rotation":1,"x":3,"y":-15,"z":19},{"name":"Rock_Sandstone_Brick","rotation":1,"x":3,"y":-14,"z":19},{"name":"Rock_Sandstone_Cobble","rotation":1,"x":3,"y":-13,"z":19},{"name":"Rock_Sandstone","rotation":1,"x":3,"y":-12,"z":19},{"name":"Rock_Sandstone_Brick","rotation":1,"x":3,"y":-11,"z":19},{"name":"Rock_Sandstone","rotation":1,"x":3,"y":-10,"z":19},{"name":"Rock_Sandstone_Brick","rotation":1,"x":3,"y":-9,"z":19},{"name":"Rock_Sandstone_Brick","rotation":1,"x":3,"y":-8,"z":19},{"name":"Rock_Sandstone_Brick","rotation":1,"x":3,"y":-7,"z":19},{"name":"Rock_Sandstone_Cobble","rotation":3,"x":3,"y":-6,"z":19},{"name":"Rock_Sandstone","rotation":3,"x":3,"y":-5,"z":19},{"name":"Rock_Sandstone_Brick","rotation":3,"x":3,"y":-4,"z":19},{"name":"Rock_Sandstone_Cobble","rotation":3,"x":3,"y":-3,"z":19},{"name":"Rock_Sandstone_Brick","rotation":3,"x":3,"y":-2,"z":19},{"name":"Rock_Sandstone_Brick","rotation":1,"x":3,"y":-1,"z":19},{"name":"Rock_Sandstone_Brick","x":3,"y":0,"z":19},{"name":"Rock_Sandstone_Brick","x":3,"y":-35,"z":20},{"name":"Rock_Sandstone_Brick","x":3,"y":-34,"z":20},{"name":"Rock_Sandstone","x":3,"y":-33,"z":20},{"name":"Rock_Sandstone_Brick","x":3,"y":-32,"z":20},{"name":"Rock_Sandstone_Brick","x":3,"y":-31,"z":20},{"name":"Rock_Sandstone_Cobble","x":3,"y":-30,"z":20},{"name":"Rock_Sandstone_Brick","x":3,"y":-29,"z":20},{"name":"Rock_Sandstone","x":3,"y":-28,"z":20},{"name":"Rock_Sandstone_Brick","x":3,"y":-27,"z":20},{"name":"Rock_Sandstone","x":3,"y":-26,"z":20},{"name":"Rock_Sandstone_Brick","x":3,"y":-25,"z":20},{"name":"Rock_Sandstone_Brick","rotation":1,"x":3,"y":-24,"z":20},{"name":"Rock_Sandstone","rotation":1,"x":3,"y":-23,"z":20},{"name":"Rock_Sandstone_Brick","rotation":1,"x":3,"y":-22,"z":20},{"name":"Rock_Sandstone_Brick","rotation":1,"x":3,"y":-21,"z":20},{"name":"Rock_Sandstone_Cobble","rotation":1,"x":3,"y":-20,"z":20},{"name":"Rock_Sandstone","rotation":1,"x":3,"y":-19,"z":20},{"name":"Rock_Sandstone_Brick","rotation":1,"x":3,"y":-18,"z":20},{"name":"Rock_Sandstone_Brick","rotation":1,"x":3,"y":-17,"z":20},{"name":"Rock_Sandstone_Cobble","rotation":1,"x":3,"y":-16,"z":20},{"name":"Rock_Sandstone_Cobble","rotation":1,"x":3,"y":-15,"z":20},{"name":"Rock_Sandstone_Cobble","rotation":1,"x":3,"y":-14,"z":20},{"name":"Rock_Sandstone_Brick","rotation":1,"x":3,"y":-13,"z":20},{"name":"Rock_Sandstone_Brick","rotation":1,"x":3,"y":-12,"z":20},{"name":"Rock_Sandstone_Brick","rotation":1,"x":3,"y":-11,"z":20},{"name":"Rock_Sandstone_Brick","rotation":1,"x":3,"y":-10,"z":20},{"name":"Rock_Sandstone_Cobble","rotation":1,"x":3,"y":-9,"z":20},{"name":"Rock_Sandstone_Brick","rotation":1,"x":3,"y":-8,"z":20},{"name":"Rock_Sandstone_Brick","rotation":1,"x":3,"y":-7,"z":20},{"name":"Rock_Sandstone","rotation":1,"x":3,"y":-6,"z":20},{"name":"Rock_Sandstone_Brick","rotation":1,"x":3,"y":-5,"z":20},{"name":"Rock_Sandstone_Brick","rotation":1,"x":3,"y":-4,"z":20},{"name":"Rock_Sandstone_Brick","rotation":3,"x":3,"y":-3,"z":20},{"name":"Rock_Sandstone_Brick","rotation":3,"x":3,"y":-2,"z":20},{"name":"Rock_Sandstone_Brick","rotation":1,"x":3,"y":-1,"z":20},{"name":"Rock_Sandstone_Brick","x":3,"y":0,"z":20},{"name":"Rock_Sandstone_Brick","x":3,"y":-35,"z":21},{"name":"Rock_Sandstone","x":3,"y":-34,"z":21},{"name":"Rock_Sandstone","x":3,"y":-33,"z":21},{"name":"Rock_Sandstone_Cobble","x":3,"y":-32,"z":21},{"name":"Rock_Sandstone_Brick","x":3,"y":-31,"z":21},{"name":"Rock_Sandstone_Brick","x":3,"y":-30,"z":21},{"name":"Rock_Sandstone_Brick","x":3,"y":-29,"z":21},{"name":"Rock_Sandstone","x":3,"y":-28,"z":21},{"name":"Rock_Sandstone","x":3,"y":-27,"z":21},{"name":"Rock_Sandstone_Cobble","x":3,"y":-26,"z":21},{"name":"Rock_Sandstone_Brick","x":3,"y":-25,"z":21},{"name":"Rock_Sandstone_Brick","x":3,"y":-24,"z":21},{"name":"Rock_Sandstone_Brick","x":3,"y":-23,"z":21},{"name":"Rock_Sandstone_Brick","x":3,"y":-22,"z":21},{"name":"Rock_Sandstone_Brick","x":3,"y":-21,"z":21},{"name":"Rock_Sandstone_Brick","x":3,"y":-20,"z":21},{"name":"Rock_Sandstone_Cobble","x":3,"y":-19,"z":21},{"name":"Rock_Sandstone_Brick","x":3,"y":-18,"z":21},{"name":"Rock_Sandstone","x":3,"y":-17,"z":21},{"name":"Rock_Sandstone_Brick","x":3,"y":-16,"z":21},{"name":"Rock_Sandstone_Brick","x":3,"y":-15,"z":21},{"name":"Rock_Sandstone","x":3,"y":-14,"z":21},{"name":"Rock_Sandstone","x":3,"y":-13,"z":21},{"name":"Rock_Sandstone_Brick","x":3,"y":-12,"z":21},{"name":"Rock_Sandstone_Brick","x":3,"y":-11,"z":21},{"name":"Rock_Sandstone_Brick","x":3,"y":-10,"z":21},{"name":"Rock_Sandstone_Brick","x":3,"y":-9,"z":21},{"name":"Rock_Sandstone","x":3,"y":-8,"z":21},{"name":"Rock_Sandstone","x":3,"y":-7,"z":21},{"name":"Rock_Sandstone_Brick","x":3,"y":-6,"z":21},{"name":"Rock_Sandstone","x":3,"y":-5,"z":21},{"name":"Rock_Sandstone_Brick","x":3,"y":-4,"z":21},{"name":"Rock_Sandstone","x":3,"y":-3,"z":21},{"name":"Rock_Sandstone_Brick","x":3,"y":-2,"z":21},{"name":"Rock_Sandstone_Brick","x":3,"y":-1,"z":21},{"name":"Rock_Sandstone_Brick","x":3,"y":0,"z":21},{"name":"Rock_Sandstone_Brick_Stairs","rotation":33,"x":4,"y":-5,"z":0},{"name":"Rock_Sandstone_Brick","rotation":3,"x":4,"y":-4,"z":0},{"name":"Rock_Sandstone_Cobble","rotation":3,"x":4,"y":-3,"z":0},{"name":"Rock_Sandstone_Brick","rotation":3,"x":4,"y":-2,"z":0},{"name":"Rock_Sandstone_Brick","rotation":3,"x":4,"y":-1,"z":0},{"name":"Rock_Sandstone_Brick","x":4,"y":0,"z":0},{"name":"Rock_Sandstone_Brick_Stairs","rotation":33,"x":4,"y":-5,"z":1},{"name":"Rock_Sandstone_Brick","rotation":3,"x":4,"y":-4,"z":1},{"name":"Rock_Sandstone_Brick","rotation":3,"x":4,"y":-3,"z":1},{"name":"Rock_Sandstone_Brick","rotation":3,"x":4,"y":-2,"z":1},{"name":"Rock_Sandstone_Brick","rotation":3,"x":4,"y":-1,"z":1},{"name":"Rock_Sandstone_Brick","x":4,"y":0,"z":1},{"name":"Rock_Sandstone_Brick","x":4,"y":-35,"z":2},{"name":"Rock_Sandstone_Brick","x":4,"y":-34,"z":2},{"name":"Rock_Sandstone_Brick","x":4,"y":-33,"z":2},{"name":"Rock_Sandstone_Brick","x":4,"y":-32,"z":2},{"name":"Rock_Sandstone_Brick","x":4,"y":-31,"z":2},{"name":"Rock_Sandstone_Brick","x":4,"y":-30,"z":2},{"name":"Rock_Sandstone_Brick","x":4,"y":-29,"z":2},{"name":"Rock_Sandstone","x":4,"y":-28,"z":2},{"name":"Rock_Sandstone_Brick","x":4,"y":-27,"z":2},{"name":"Rock_Sandstone_Cobble","x":4,"y":-26,"z":2},{"name":"Rock_Sandstone_Cobble","rotation":3,"x":4,"y":-25,"z":2},{"name":"Rock_Sandstone_Brick","rotation":3,"x":4,"y":-24,"z":2},{"name":"Rock_Sandstone_Cobble","rotation":3,"x":4,"y":-23,"z":2},{"name":"Rock_Sandstone_Brick","rotation":3,"x":4,"y":-22,"z":2},{"name":"Rock_Sandstone_Brick","rotation":3,"x":4,"y":-21,"z":2},{"name":"Rock_Sandstone_Brick","rotation":3,"x":4,"y":-20,"z":2},{"name":"Rock_Sandstone","rotation":3,"x":4,"y":-19,"z":2},{"name":"Rock_Sandstone","rotation":3,"x":4,"y":-18,"z":2},{"name":"Rock_Sandstone_Brick","rotation":3,"x":4,"y":-17,"z":2},{"name":"Rock_Sandstone_Brick","rotation":3,"x":4,"y":-16,"z":2},{"name":"Rock_Sandstone_Brick","rotation":3,"x":4,"y":-15,"z":2},{"name":"Rock_Sandstone_Cobble","rotation":3,"x":4,"y":-14,"z":2},{"name":"Rock_Sandstone_Brick","rotation":3,"x":4,"y":-13,"z":2},{"name":"Rock_Sandstone_Brick","rotation":3,"x":4,"y":-12,"z":2},{"name":"Rock_Sandstone_Cobble","rotation":3,"x":4,"y":-11,"z":2},{"name":"Rock_Sandstone_Brick","rotation":3,"x":4,"y":-10,"z":2},{"name":"Rock_Sandstone_Brick","rotation":3,"x":4,"y":-9,"z":2},{"name":"Rock_Sandstone_Brick","rotation":3,"x":4,"y":-8,"z":2},{"name":"Rock_Sandstone_Brick","rotation":3,"x":4,"y":-7,"z":2},{"name":"Rock_Sandstone","rotation":3,"x":4,"y":-6,"z":2},{"name":"Rock_Sandstone_Cobble","rotation":3,"x":4,"y":-5,"z":2},{"name":"Rock_Sandstone_Brick","rotation":3,"x":4,"y":-4,"z":2},{"name":"Rock_Sandstone_Cobble","rotation":3,"x":4,"y":-3,"z":2},{"name":"Rock_Sandstone_Brick","rotation":3,"x":4,"y":-2,"z":2},{"name":"Rock_Sandstone_Brick","rotation":3,"x":4,"y":-1,"z":2},{"name":"Rock_Sandstone_Brick","x":4,"y":0,"z":2},{"name":"Rock_Sandstone_Brick","x":4,"y":-35,"z":3},{"name":"Rock_Sandstone","x":4,"y":-34,"z":3},{"name":"Rock_Sandstone_Brick","x":4,"y":-33,"z":3},{"name":"Rock_Sandstone_Brick","x":4,"y":-32,"z":3},{"name":"Rock_Sandstone_Brick","x":4,"y":-31,"z":3},{"name":"Rock_Sandstone_Brick","x":4,"y":-30,"z":3},{"name":"Rock_Sandstone_Brick","x":4,"y":-29,"z":3},{"name":"Rock_Sandstone_Brick","x":4,"y":-28,"z":3},{"name":"Rock_Sandstone_Brick","x":4,"y":-27,"z":3},{"name":"Rock_Sandstone_Brick","x":4,"y":-26,"z":3},{"name":"Rock_Sandstone_Brick","rotation":3,"x":4,"y":-25,"z":3},{"name":"Rock_Sandstone_Brick","rotation":3,"x":4,"y":-24,"z":3},{"name":"Rock_Sandstone_Brick","rotation":3,"x":4,"y":-23,"z":3},{"name":"Rock_Sandstone","rotation":3,"x":4,"y":-22,"z":3},{"name":"Rock_Sandstone_Brick","rotation":3,"x":4,"y":-21,"z":3},{"name":"Rock_Sandstone_Cobble","rotation":3,"x":4,"y":-20,"z":3},{"name":"Rock_Sandstone_Brick","rotation":3,"x":4,"y":-19,"z":3},{"name":"Rock_Sandstone_Brick","rotation":3,"x":4,"y":-18,"z":3},{"name":"Rock_Sandstone_Brick","rotation":3,"x":4,"y":-17,"z":3},{"name":"Rock_Sandstone_Brick","rotation":3,"x":4,"y":-16,"z":3},{"name":"Rock_Sandstone","rotation":3,"x":4,"y":-15,"z":3},{"name":"Rock_Sandstone_Brick","rotation":3,"x":4,"y":-14,"z":3},{"name":"Rock_Sandstone_Brick","rotation":3,"x":4,"y":-13,"z":3},{"name":"Rock_Sandstone_Brick","rotation":3,"x":4,"y":-12,"z":3},{"name":"Rock_Sandstone","rotation":3,"x":4,"y":-11,"z":3},{"name":"Rock_Sandstone_Brick","rotation":3,"x":4,"y":-10,"z":3},{"name":"Rock_Sandstone_Brick","rotation":3,"x":4,"y":-9,"z":3},{"name":"Rock_Sandstone_Cobble","rotation":3,"x":4,"y":-8,"z":3},{"name":"Rock_Sandstone_Cobble","rotation":3,"x":4,"y":-7,"z":3},{"name":"Rock_Sandstone","rotation":3,"x":4,"y":-6,"z":3},{"name":"Rock_Sandstone_Brick","rotation":3,"x":4,"y":-5,"z":3},{"name":"Rock_Sandstone_Brick","rotation":3,"x":4,"y":-4,"z":3},{"name":"Rock_Sandstone_Brick","rotation":3,"x":4,"y":-3,"z":3},{"name":"Rock_Sandstone_Brick","rotation":3,"x":4,"y":-2,"z":3},{"name":"Rock_Sandstone_Brick","rotation":3,"x":4,"y":-1,"z":3},{"name":"Rock_Sandstone_Brick","x":4,"y":0,"z":3},{"name":"Rock_Sandstone_Brick_Half","rotation":33,"x":4,"y":-2,"z":9},{"name":"Rock_Sandstone_Brick","rotation":3,"x":4,"y":-1,"z":9},{"name":"Rock_Sandstone_Brick","x":4,"y":0,"z":9},{"name":"Rock_Sandstone_Brick_Stairs","rotation":9,"x":4,"y":-4,"z":10},{"name":"Rock_Sandstone_Brick","x":4,"y":-3,"z":10},{"name":"Rock_Sandstone_Brick","x":4,"y":-2,"z":10},{"name":"Rock_Sandstone_Brick","x":4,"y":-1,"z":10},{"name":"Rock_Sandstone_Brick","x":4,"y":0,"z":10},{"name":"Rock_Sandstone_Brick_Stairs","rotation":9,"x":4,"y":-4,"z":11},{"name":"Rock_Sandstone_Brick","x":4,"y":-3,"z":11},{"name":"Rock_Sandstone_Brick","x":4,"y":-2,"z":11},{"name":"Rock_Sandstone_Brick","x":4,"y":-1,"z":11},{"name":"Rock_Sandstone_Brick","x":4,"y":0,"z":11},{"name":"Rock_Sandstone_Brick_Half","rotation":35,"x":4,"y":-2,"z":12},{"name":"Rock_Sandstone_Brick","rotation":1,"x":4,"y":-1,"z":12},{"name":"Rock_Sandstone_Brick","x":4,"y":0,"z":12},{"name":"Rock_Sandstone_Brick","x":4,"y":-35,"z":18},{"name":"Rock_Sandstone","x":4,"y":-34,"z":18},{"name":"Rock_Sandstone_Brick","x":4,"y":-33,"z":18},{"name":"Rock_Sandstone_Brick","x":4,"y":-32,"z":18},{"name":"Rock_Sandstone_Brick","x":4,"y":-31,"z":18},{"name":"Rock_Sandstone_Brick","x":4,"y":-30,"z":18},{"name":"Rock_Sandstone_Brick","x":4,"y":-29,"z":18},{"name":"Rock_Sandstone","x":4,"y":-28,"z":18},{"name":"Rock_Sandstone_Brick","x":4,"y":-27,"z":18},{"name":"Rock_Sandstone_Brick","x":4,"y":-26,"z":18},{"name":"Rock_Sandstone_Brick","x":4,"y":-25,"z":18},{"name":"Rock_Sandstone_Brick","rotation":1,"x":4,"y":-24,"z":18},{"name":"Rock_Sandstone_Brick","rotation":1,"x":4,"y":-23,"z":18},{"name":"Rock_Sandstone_Brick","rotation":1,"x":4,"y":-22,"z":18},{"name":"Rock_Sandstone_Brick","rotation":1,"x":4,"y":-21,"z":18},{"name":"Rock_Sandstone_Brick","rotation":1,"x":4,"y":-20,"z":18},{"name":"Rock_Sandstone_Brick","rotation":1,"x":4,"y":-19,"z":18},{"name":"Rock_Sandstone_Brick","rotation":1,"x":4,"y":-18,"z":18},{"name":"Rock_Sandstone","rotation":1,"x":4,"y":-17,"z":18},{"name":"Rock_Sandstone_Brick","rotation":1,"x":4,"y":-16,"z":18},{"name":"Rock_Sandstone","rotation":1,"x":4,"y":-15,"z":18},{"name":"Rock_Sandstone_Brick","rotation":1,"x":4,"y":-14,"z":18},{"name":"Rock_Sandstone_Brick","rotation":1,"x":4,"y":-13,"z":18},{"name":"Rock_Sandstone_Brick","rotation":1,"x":4,"y":-12,"z":18},{"name":"Rock_Sandstone_Brick","rotation":1,"x":4,"y":-11,"z":18},{"name":"Rock_Sandstone_Brick","rotation":1,"x":4,"y":-10,"z":18},{"name":"Rock_Sandstone_Brick","rotation":1,"x":4,"y":-9,"z":18},{"name":"Rock_Sandstone_Brick","rotation":1,"x":4,"y":-8,"z":18},{"name":"Rock_Sandstone","rotation":1,"x":4,"y":-7,"z":18},{"name":"Rock_Sandstone_Brick","rotation":1,"x":4,"y":-6,"z":18},{"name":"Rock_Sandstone_Cobble","rotation":1,"x":4,"y":-5,"z":18},{"name":"Rock_Sandstone","rotation":1,"x":4,"y":-4,"z":18},{"name":"Rock_Sandstone_Brick","rotation":1,"x":4,"y":-3,"z":18},{"name":"Rock_Sandstone_Brick","rotation":3,"x":4,"y":-2,"z":18},{"name":"Rock_Sandstone_Brick","rotation":1,"x":4,"y":-1,"z":18},{"name":"Rock_Sandstone_Brick","x":4,"y":0,"z":18},{"name":"Rock_Sandstone","x":4,"y":-35,"z":19},{"name":"Rock_Sandstone_Cobble","x":4,"y":-34,"z":19},{"name":"Rock_Sandstone_Brick","x":4,"y":-33,"z":19},{"name":"Rock_Sandstone_Brick","x":4,"y":-32,"z":19},{"name":"Rock_Sandstone_Brick","x":4,"y":-31,"z":19},{"name":"Rock_Sandstone_Cobble","x":4,"y":-30,"z":19},{"name":"Rock_Sandstone_Brick","x":4,"y":-29,"z":19},{"name":"Rock_Sandstone","x":4,"y":-28,"z":19},{"name":"Rock_Sandstone","x":4,"y":-27,"z":19},{"name":"Rock_Sandstone","x":4,"y":-26,"z":19},{"name":"Rock_Sandstone_Brick","x":4,"y":-25,"z":19},{"name":"Rock_Sandstone_Brick","rotation":1,"x":4,"y":-24,"z":19},{"name":"Rock_Sandstone_Brick","rotation":1,"x":4,"y":-23,"z":19},{"name":"Rock_Sandstone_Brick","rotation":1,"x":4,"y":-22,"z":19},{"name":"Rock_Sandstone_Cobble","rotation":1,"x":4,"y":-21,"z":19},{"name":"Rock_Sandstone_Cobble","rotation":1,"x":4,"y":-20,"z":19},{"name":"Rock_Sandstone_Brick","rotation":1,"x":4,"y":-19,"z":19},{"name":"Rock_Sandstone_Cobble","rotation":1,"x":4,"y":-18,"z":19},{"name":"Rock_Sandstone_Cobble","rotation":1,"x":4,"y":-17,"z":19},{"name":"Rock_Sandstone_Brick","rotation":1,"x":4,"y":-16,"z":19},{"name":"Rock_Sandstone_Brick","rotation":1,"x":4,"y":-15,"z":19},{"name":"Rock_Sandstone_Brick","rotation":1,"x":4,"y":-14,"z":19},{"name":"Rock_Sandstone","rotation":1,"x":4,"y":-13,"z":19},{"name":"Rock_Sandstone","rotation":1,"x":4,"y":-12,"z":19},