{
  "version": 8,
  "blockIdVersion": 11,
  "anchorX": 0,
  "anchorY": 1,
  "anchorZ": 0,
  "blocks": [
    {
      "x": -8,
      "y": 1,
      "z": -3,
      "name": "Plant_Moss_Block_Green_Dark"
    },
    {
      "x": -8,
      "y": 1,
      "z": -2,
      "name": "Plant_Moss_Block_Green_Dark"
    },
    {
      "x": -8,
      "y": 1,
      "z": -1,
      "name": "Plant_Moss_Block_Green_Dark"
    },
    {
      "x": -8,
      "y": 1,
      "z": 0,
      "name": "Plant_Moss_Block_Green_Dark"
    },
    {
      "x": -8,
      "y": 1,
      "z": 1,
      "name": "Plant_Moss_Block_Green_Dark"
    },
    {
      "x": -7,
      "y": 1,
      "z": -3,
      "name": "Plant_Moss_Block_Green_Dark"
    },
    {
      "x": -7,
      "y": 1,
      "z": -2,
      "name": "Plant_Moss_Block_Green_Dark"
    },
    {
      "x": -7,
      "y": 0,
      "z": -1,
      "name": "Plant_Moss_Block_Green_Dark"
    },
    {
      "x": -7,
      "y": 1,
      "z": -1,
      "name": "Empty"
    },
    {
      "x": -7,
      "y": 0,
      "z": 0,
      "name": "Plant_Moss_Block_Green_Dark"
    },
    {
      "x": -7,
      "y": 1,
      "z": 0,
      "name": "Empty"
    },
    {
      "x": -7,
      "y": 1,
      "z": 1,
      "name": "Plant_Moss_Block_Green_Dark"
    },
    {
      "x": -7,
      "y": 1,
      "z": 2,
      "name": "Plant_Moss_Block_Green_Dark"
    },
    {
      "x": -7,
      "y": 1,
      "z": 3,
      "name": "Plant_Moss_Block_Green_Dark"
    },
    {
      "x": -6,
      "y": 0,
      "z": -2,
      "name": "Plant_Moss_Block_Green_Dark"
    },
    {
      "x": -6,
      "y": 1,
      "z": -2,
      "name": "Plant_Moss_Block_Green_Dark"
    },
    {
      "x": -6,
      "y": 0,
      "z": -1,
      "name": "Plant_Moss_Block_Green_Dark"
    },
    {
      "x": -6,
      "y": 1,
      "z": -1,
      "name": "Empty"
    },
    {
      "x": -6,
      "y": 4,
      "z": -1,
      "name": "Cloth_Block_Wool_Red_Half",
      "rotation": 7
    },
    {
      "x": -6,
      "y": 0,
      "z": 0,
      "name": "Plant_Moss_Block_Green_Dark"
    },
    {
      "x": -6,
      "y": 1,
      "z": 0,
      "name": "Empty"
    },
    {
      "x": -6,
      "y": 3,
      "z": 0,
      "name": "Cloth_Block_Wool_Red_Half",
      "rotation": 7
    },
    {
      "x": -6,
      "y": 4,
      "z": 0,
      "name": "Cloth_Block_Wool_Red_Half",
      "rotation": 5
    },
    {
      "x": -6,
      "y": 5,
      "z": 0,
      "name": "Cloth_Block_Wool_Red_Half",
      "rotation": 7
    },
    {
      "x": -6,
      "y": 0,
      "z": 1,
      "name": "Plant_Moss_Block_Green_Dark"
    },
    {
      "x": -6,
      "y": 1,
      "z": 1,
      "name": "Empty"
    },
    {
      "x": -6,
      "y": 4,
      "z": 1,
      "name": "Cloth_Block_Wool_Red_Half",
      "rotation": 7
    },
    {
      "x": -6,
      "y": 0,
      "z": 2,
      "name": "Plant_Moss_Block_Green_Dark"
    },
    {
      "x": -6,
      "y": 1,
      "z": 2,
      "name": "Empty"
    },
    {
      "x": -6,
      "y": 1,
      "z": 3,
      "name": "Plant_Moss_Block_Green_Dark"
    },
    {
      "x": -6,
      "y": 1,
      "z": 4,
      "name": "Plant_Moss_Block_Green_Dark"
    },
    {
      "x": -5,
      "y": 0,
      "z": -2,
      "name": "Plant_Moss_Block_Green_Dark"
    },
    {
      "x": -5,
      "y": 1,
      "z": -2,
      "name": "Empty"
    },
    {
      "x": -5,
      "y": 0,
      "z": -1,
      "name": "Plant_Moss_Block_Green_Dark"
    },
    {
      "x": -5,
      "y": 1,
      "z": -1,
      "name": "Empty"
    },
    {
      "x": -5,
      "y": 3,
      "z": -1,
      "name": "Cloth_Block_Wool_Red_Stairs",
      "rotation": 1
    },
    {
      "x": -5,
      "y": -1,
      "z": 0,
      "name": "Wood_Windwillow_Trunk_Full"
    },
    {
      "x": -5,
      "y": 0,
      "z": 0,
      "name": "Plant_Moss_Block_Green_Dark"
    },
    {
      "x": -5,
      "y": 1,
      "z": 0,
      "name": "Empty"
    },
    {
      "x": -5,
      "y": 2,
      "z": 0,
      "name": "Cloth_Block_Wool_Red_Stairs",
      "rotation": 35
    },
    {
      "x": -5,
      "y": 3,
      "z": 0,
      "name": "Cloth_Block_Wool_Red_Half"
    },
    {
      "x": -5,
      "y": 0,
      "z": 1,
      "name": "Plant_Moss_Block_Green_Dark"
    },
    {
      "x": -5,
      "y": 1,
      "z": 1,
      "name": "Empty"
    },
    {
      "x": -5,
      "y": 3,
      "z": 1,
      "name": "Cloth_Block_Wool_Red_Stairs",
      "rotation": 1
    },
    {
      "x": -5,
      "y": 0,
      "z": 2,
      "name": "Plant_Moss_Block_Green_Dark"
    },
    {
      "x": -5,
      "y": 1,
      "z": 2,
      "name": "Empty"
    },
    {
      "x": -5,
      "y": 0,
      "z": 3,
      "name": "Plant_Moss_Block_Green_Dark"
    },
    {
      "x": -5,
      "y": 1,
      "z": 3,
      "name": "Empty"
    },
    {
      "x": -5,
      "y": 1,
      "z": 4,
      "name": "Plant_Moss_Block_Green_Dark"
    },
    {
      "x": -5,
      "y": 1,
      "z": 5,
      "name": "Plant_Moss_Block_Green_Dark"
    },
    {
      "x": -4,
      "y": 4,
      "z": -4,
      "name": "Cloth_Block_Wool_Red_Half",
      "rotation": 8
    },
    {
      "x": -4,
      "y": 5,
      "z": -4,
      "name": "Cloth_Block_Wool_Red",
      "rotation": 2
    },
    {
      "x": -4,
      "y": 3,
      "z": -3,
      "name": "Cloth_Block_Wool_Red_Stairs",
      "rotation": 34
    },
    {
      "x": -4,
      "y": 4,
      "z": -3,
      "name": "Cloth_Block_Wool_Red_Half",
      "rotation": 4
    },
    {
      "x": -4,
      "y": 0,
      "z": -1,
      "name": "Plant_Moss_Block_Green_Dark"
    },
    {
      "x": -4,
      "y": 1,
      "z": -1,
      "name": "Empty"
    },
    {
      "x": -4,
      "y": 2,
      "z": -1,
      "name": "Cloth_Block_Wool_Red_Stairs",
      "rotation": 2
    },
    {
      "x": -4,
      "y": 5,
      "z": -1,
      "name": "Cloth_Block_Wool_Red_Half",
      "rotation": 7
    },
    {
      "x": -4,
      "y": -1,
      "z": 0,
      "name": "Wood_Windwillow_Trunk_Full"
    },
    {
      "x": -4,
      "y": 0,
      "z": 0,
      "name": "Plant_Moss_Block_Green_Dark"
    },
    {
      "x": -4,
      "y": 1,
      "z": 0,
      "name": "Cloth_Block_Wool_Red_Half",
      "rotation": 35
    },
    {
      "x": -4,
      "y": 2,
      "z": 0,
      "name": "Cloth_Block_Wool_Red",
      "rotation": 3
    },
    {
      "x": -4,
      "y": 4,
      "z": 0,
      "name": "Cloth_Block_Wool_Red_Half",
      "rotation": 7
    },
    {
      "x": -4,
      "y": 5,
      "z": 0,
      "name": "Cloth_Block_Wool_Red",
      "rotation": 2
    },
    {
      "x": -4,
      "y": 6,
      "z": 0,
      "name": "Cloth_Block_Wool_Red_Half",
      "rotation": 7
    },
    {
      "x": -4,
      "y": 0,
      "z": 1,
      "name": "Plant_Moss_Block_Green_Dark"
    },
    {
      "x": -4,
      "y": 1,
      "z": 1,
      "name": "Empty"
    },
    {
      "x": -4,
      "y": 2,
      "z": 1,
      "name": "Cloth_Block_Wool_Red_Stairs"
    },
    {
      "x": -4,
      "y": 5,
      "z": 1,
      "name": "Cloth_Block_Wool_Red_Half",
      "rotation": 7
    },
    {
      "x": -4,
      "y": -1,
      "z": 2,
      "name": "Wood_Windwillow_Trunk_Full"
    },
    {
      "x": -4,
      "y": 0,
      "z": 2,
      "name": "Plant_Moss_Block_Green_Dark"
    },
    {
      "x": -4,
      "y": 1,
      "z": 2,
      "name": "Empty"
    },
    {
      "x": -4,
      "y": 0,
      "z": 3,
      "name": "Plant_Moss_Block_Green_Dark"
    },
    {
      "x": -4,
      "y": 1,
      "z": 3,
      "name": "Empty"
    },
    {
      "x": -4,
      "y": 3,
      "z": 3,
      "name": "Cloth_Block_Wool_Red_Stairs",
      "rotation": 10
    },
    {
      "x": -4,
      "y": 4,
      "z": 3,
      "name": "Cloth_Block_Wool_Red_Half",
      "rotation": 6
    },
    {
      "x": -4,
      "y": 0,
      "z": 4,
      "name": "Plant_Moss_Block_Green_Dark"
    },
    {
      "x": -4,
      "y": 1,
      "z": 4,
      "name": "Empty"
    },
    {
      "x": -4,
      "y": 4,
      "z": 4,
      "name": "Cloth_Block_Wool_Red_Half",
      "rotation": 8
    },
    {
      "x": -4,
      "y": 5,
      "z": 4,
      "name": "Cloth_Block_Wool_Red"
    },
    {
      "x": -4,
      "y": 1,
      "z": 5,
      "name": "Plant_Moss_Block_Green_Dark"
    },
    {
      "x": -4,
      "y": 1,
      "z": 6,
      "name": "Plant_Moss_Block_Green_Dark"
    },
    {
      "x": -3,
      "y": 1,
      "z": -8,
      "name": "Plant_Moss_Block_Green_Dark"
    },
    {
      "x": -3,
      "y": 1,
      "z": -7,
      "name": "Plant_Moss_Block_Green_Dark"
    },
    {
      "x": -3,
      "y": 3,
      "z": -4,
      "name": "Cloth_Block_Wool_Red_Stairs",
      "rotation": 35
    },
    {
      "x": -3,
      "y": 4,
      "z": -4,
      "name": "Cloth_Block_Wool_Red_Half",
      "rotation": 5
    },
    {
      "x": -3,
      "y": 2,
      "z": -3,
      "name": "Cloth_Block_Wool_Red_Half",
      "rotation": 32
    },
    {
      "x": -3,
      "y": 3,
      "z": -3,
      "name": "Cloth_Block_Wool_Red_Half",
      "rotation": 2
    },
    {
      "x": -3,
      "y": 2,
      "z": -2,
      "name": "Cloth_Block_Wool_Red_Stairs"
    },
    {
      "x": -3,
      "y": 0,
      "z": -1,
      "name": "Plant_Moss_Block_Green_Dark"
    },
    {
      "x": -3,
      "y": 1,
      "z": -1,
      "name": "Cloth_Block_Wool_Red_Half",
      "rotation": 10
    },
    {
      "x": -3,
      "y": 2,
      "z": -1,
      "name": "Rock_Crystal_Red_Small"
    },
    {
      "x": -3,
      "y": 4,
      "z": -1,
      "name": "Cloth_Block_Wool_Red"
    },
    {
      "x": -3,
      "y": 5,
      "z": -1,
      "name": "Cloth_Block_Wool_Red_Half",
      "rotation": 5
    },
    {
      "x": -3,
      "y": 6,
      "z": -1,
      "name": "Cloth_Block_Wool_Red_Half",
      "rotation": 5
    },
    {
      "x": -3,
      "y": 0,
      "z": 0,
      "name": "Plant_Moss_Block_Green_Dark"
    },
    {
      "x": -3,
      "y": 1,
      "z": 0,
      "name": "Cloth_Block_Wool_Red_Half",
      "rotation": 10
    },
    {
      "x": -3,
      "y": 3,
      "z": 0,
      "name": "Cloth_Block_Wool_Red_Stairs",
      "rotation": 9
    },
    {
      "x": -3,
      "y": 4,
      "z": 0,
      "name": "Cloth_Block_Wool_Red_Stairs",
      "rotation": 1
    },
    {
      "x": -3,
      "y": 7,
      "z": 0,
      "name": "Cloth_Block_Wool_Red_Stairs",
      "rotation": 3
    },
    {
      "x": -3,
      "y": -1,
      "z": 1,
      "name": "Wood_Windwillow_Trunk_Full"
    },
    {
      "x": -3,
      "y": 0,
      "z": 1,
      "name": "Plant_Moss_Block_Green_Dark"
    },
    {
      "x": -3,
      "y": 1,
      "z": 1,
      "name": "Cloth_Block_Wool_Red_Half",
      "rotation": 10
    },
    {
      "x": -3,
      "y": 2,
      "z": 1,
      "name": "Rock_Crystal_Red_Small"
    },
    {
      "x": -3,
      "y": 4,
      "z": 1,
      "name": "Cloth_Block_Wool_Red"
    },
    {
      "x": -3,
      "y": 5,
      "z": 1,
      "name": "Cloth_Block_Wool_Red_Half",
      "rotation": 5
    },
    {
      "x": -3,
      "y": 6,
      "z": 1,
      "name": "Cloth_Block_Wool_Red_Half",
      "rotation": 5
    },
    {
      "x": -3,
      "y": 0,
      "z": 2,
      "name": "Plant_Moss_Block_Green_Dark"
    },
    {
      "x": -3,
      "y": 1,
      "z": 2,
      "name": "Empty"
    },
    {
      "x": -3,
      "y": 2,
      "z": 2,
      "name": "Cloth_Block_Wool_Red_Stairs",
      "rotation": 2
    },
    {
      "x": -3,
      "y": 0,
      "z": 3,
      "name": "Plant_Moss_Block_Green_Dark"
    },
    {
      "x": -3,
      "y": 1,
      "z": 3,
      "name": "Empty"
    },
    {
      "x": -3,
      "y": 2,
      "z": 3,
      "name": "Cloth_Block_Wool_Red_Half",
      "rotation": 33
    },
    {
      "x": -3,
      "y": 3,
      "z": 3,
      "name": "Cloth_Block_Wool_Red_Half",
      "rotation": 3
    },
    {
      "x": -3,
      "y": 0,
      "z": 4,
      "name": "Plant_Moss_Block_Green_Dark"
    },
    {
      "x": -3,
      "y": 1,
      "z": 4,
      "name": "Empty"
    },
    {
      "x": -3,
      "y": 3,
      "z": 4,
      "name": "Cloth_Block_Wool_Red_Stairs",
      "rotation": 9
    },
    {
      "x": -3,
      "y": 4,
      "z": 4,
      "name": "Cloth_Block_Wool_Red_Half",
      "rotation": 5
    },
    {
      "x": -3,
      "y": 0,
      "z": 5,
      "name": "Plant_Moss_Block_Green_Dark"
    },
    {
      "x": -3,
      "y": 1,
      "z": 5,
      "name": "Empty"
    },
    {
      "x": -3,
      "y": 1,
      "z": 6,
      "name": "Plant_Moss_Block_Green_Dark"
    },
    {
      "x": -2,
      "y": 1,
      "z": -8,
      "name": "Plant_Moss_Block_Green_Dark"
    },
    {
      "x": -2,
      "y": 1,
      "z": -7,
      "name": "Plant_Moss_Block_Green_Dark"
    },
    {
      "x": -2,
      "y": 0,
      "z": -6,
      "name": "Plant_Moss_Block_Green_Dark"
    },
    {
      "x": -2,
      "y": 1,
      "z": -6,
      "name": "Plant_Moss_Block_Green_Dark"
    },
    {
      "x": -2,
      "y": 0,
      "z": -5,
      "name": "Plant_Moss_Block_Green_Dark"
    },
    {
      "x": -2,
      "y": 1,
      "z": -5,
      "name": "Empty"
    },
    {
      "x": -2,
      "y": 2,
      "z": -3,
      "name": "Cloth_Block_Wool_Red_Stairs",
      "rotation": 1
    },
    {
      "x": -2,
      "y": 0,
      "z": -2,
      "name": "Plant_Moss_Block_Green_Dark"
    },
    {
      "x": -2,
      "y": 1,
      "z": -2,
      "name": "Cloth_Block_Wool_Red_Half",
      "rotation": 10
    },
    {
      "x": -2,
      "y": -1,
      "z": -1,
      "name": "Wood_Windwillow_Trunk_Full"
    },
    {
      "x": -2,
      "y": 0,
      "z": -1,
      "name": "Plant_Moss_Block_Green_Dark"
    },
    {
      "x": -2,
      "y": 1,
      "z": -1,
      "name": "Cloth_Block_Wool_Red"
    },
    {
      "x": -2,
      "y": 2,
      "z": -1,
      "name": "Cloth_Block_Wool_Red_Half",
      "rotation": 7
    },
    {
      "x": -2,
      "y": 3,
      "z": -1,
      "name": "Cloth_Block_Wool_Red"
    },
    {
      "x": -2,
      "y": 0,
      "z": 0,
      "name": "Plant_Moss_Block_Green_Dark"
    },
    {
      "x": -2,
      "y": 1,
      "z": 0,
      "name": "Cloth_Block_Wool_Red"
    },
    {
      "x": -2,
      "y": 2,
      "z": 0,
      "name": "Cloth_Block_Wool_Red"
    },
    {
      "x": -2,
      "y": 3,
      "z": 0,
      "name": "Cloth_Block_Wool_Red_Stairs",
      "rotation": 1
    },
    {
      "x": -2,
      "y": -1,
      "z": 1,
      "name": "Wood_Windwillow_Trunk_Full"
    },
    {
      "x": -2,
      "y": 0,
      "z": 1,
      "name": "Plant_Moss_Block_Green_Dark"
    },
    {
      "x": -2,
      "y": 1,
      "z": 1,
      "name": "Cloth_Block_Wool_Red",
      "rotation": 1
    },
    {
      "x": -2,
      "y": 2,
      "z": 1,
      "name": "Cloth_Block_Wool_Red_Half",
      "rotation": 7
    },
    {
      "x": -2,
      "y": 3,
      "z": 1,
      "name": "Cloth_Block_Wool_Red"
    },
    {
      "x": -2,
      "y": -1,
      "z": 2,
      "name": "Wood_Windwillow_Trunk_Full"
    },
    {
      "x": -2,
      "y": 0,
      "z": 2,
      "name": "Plant_Moss_Block_Green_Dark"
    },
    {
      "x": -2,
      "y": 1,
      "z": 2,
      "name": "Cloth_Block_Wool_Red_Half",
      "rotation": 10
    },
    {
      "x": -2,
      "y": -1,
      "z": 3,
      "name": "Wood_Windwillow_Trunk_Full"
    },
    {
      "x": -2,
      "y": 0,
      "z": 3,
      "name": "Plant_Moss_Block_Green_Dark"
    },
    {
      "x": -2,
      "y": 1,
      "z": 3,
      "name": "Empty"
    },
    {
      "x": -2,
      "y": 2,
      "z": 3,
      "name": "Cloth_Block_Wool_Red_Stairs",
      "rotation": 1
    },
    {
      "x": -2,
      "y": 0,
      "z": 4,
      "name": "Plant_Moss_Block_Green_Dark"
    },
    {
      "x": -2,
      "y": 1,
      "z": 4,
      "name": "Empty"
    },
    {
      "x": -2,
      "y": 0,
      "z": 5,
      "name": "Plant_Moss_Block_Green_Dark"
    },
    {
      "x": -2,
      "y": 1,
      "z": 5,
      "name": "Empty"
    },
    {
      "x": -2,
      "y": 1,
      "z": 6,
      "name": "Plant_Moss_Block_Green_Dark"
    },
    {
      "x": -2,
      "y": 1,
      "z": 7,
      "name": "Plant_Moss_Block_Green_Dark"
    },
    {
      "x": -1,
      "y": 1,
      "z": -8,
      "name": "Plant_Moss_Block_Green_Dark"
    },
    {
      "x": -1,
      "y": 0,
      "z": -7,
      "name": "Plant_Moss_Block_Green_Dark"
    },
    {
      "x": -1,
      "y": 1,
      "z": -7,
      "name": "Empty"
    },
    {
      "x": -1,
      "y": 0,
      "z": -6,
      "name": "Plant_Moss_Block_Green_Dark"
    },
    {
      "x": -1,
      "y": 1,
      "z": -6,
      "name": "Empty"
    },
    {
      "x": -1,
      "y": 4,
      "z": -6,
      "name": "Cloth_Block_Wool_Red_Half",
      "rotation": 6
    },
    {
      "x": -1,
      "y": 0,
      "z": -5,
      "name": "Plant_Moss_Block_Green_Dark"
    },
    {
      "x": -1,
      "y": 1,
      "z": -5,
      "name": "Empty"
    },
    {
      "x": -1,
      "y": 3,
      "z": -5,
      "name": "Cloth_Block_Wool_Red_Stairs"
    },
    {
      "x": -1,
      "y": 0,
      "z": -4,
      "name": "Plant_Moss_Block_Green_Dark"
    },
    {
      "x": -1,
      "y": 1,
      "z": -4,
      "name": "Empty"
    },
    {
      "x": -1,
      "y": 2,
      "z": -4,
      "name": "Cloth_Block_Wool_Red_Stairs",
      "rotation": 3
    },
    {
      "x": -1,
      "y": 5,
      "z": -4,
      "name": "Cloth_Block_Wool_Red_Half",
      "rotation": 6
    },
    {
      "x": -1,
      "y": 0,
      "z": -3,
      "name": "Plant_Moss_Block_Green_Dark"
    },
    {
      "x": -1,
      "y": 1,
      "z": -3,
      "name": "Cloth_Block_Wool_Red_Half",
      "rotation": 10
    },
    {
      "x": -1,
      "y": 2,
      "z": -3,
      "name": "Rock_Crystal_Red_Small"
    },
    {
      "x": -1,
      "y": 4,
      "z": -3,
      "name": "Cloth_Block_Wool_Red"
    },
    {
      "x": -1,
      "y": 5,
      "z": -3,
      "name": "Cloth_Block_Wool_Red_Half",
      "rotation": 4
    },
    {
      "x": -1,
      "y": 6,
      "z": -3,
      "name": "Cloth_Block_Wool_Red_Half",
      "rotation": 4
    },
    {
      "x": -1,
      "y": 0,
      "z": -2,
      "name": "Plant_Moss_Block_Green_Dark"
    },
    {
      "x": -1,
      "y": 1,
      "z": -2,
      "name": "Cloth_Block_Wool_Red"
    },
    {
      "x": -1,
      "y": 2,
      "z": -2,
      "name": "Cloth_Block_Wool_Red_Half",
      "rotation": 6
    },
    {
      "x": -1,
      "y": 3,
      "z": -2,
      "name": "Cloth_Block_Wool_Red"
    },
    {
      "x": -1,
      "y": -4,
      "z": -1,
      "name": "Wood_Windwillow_Trunk_Full"
    },
    {
      "x": -1,
      "y": 0,
      "z": -1,
      "name": "Plant_Moss_Block_Green_Dark"
    },
    {
      "x": -1,
      "y": 1,
      "z": -1,
      "name": "Cloth_Block_Wool_Red"
    },
    {
      "x": -1,
      "y": 2,
      "z": -1,
      "name": "Cloth_Block_Wool_Red"
    },
    {
      "x": -1,
      "y": 3,
      "z": -1,
      "name": "Cloth_Block_Wool_Red_Half",
      "rotation": 2
    },
    {
      "x": -1,
      "y": -10,
      "z": 0,
      "name": "Wood_Windwillow_Trunk_Full"
    },
    {
      "x": -1,
      "y": -2,
      "z": 0,
      "name": "Wood_Windwillow_Trunk_Full"
    },
    {
      "x": -1,
      "y": 0,
      "z": 0,
      "name": "Plant_Moss_Block_Green_Dark"
    },
    {
      "x": -1,
      "y": 1,
      "z": 0,
      "name": "Cloth_Block_Wool_Red"
    },
    {
      "x": -1,
      "y": 2,
      "z": 0,
      "name": "Cloth_Block_Wool_Red",
      "rotation": 2
    },
    {
      "x": -1,
      "y": 4,
      "z": 0,
      "name": "Wood_Windwillow_Trunk_Full"
    },
    {
      "x": -1,
      "y": 5,
      "z": 0,
      "name": "Rock_Crystal_Red_Small"
    },
    {
      "x": -1,
      "y": 0,
      "z": 1,
      "name": "Plant_Moss_Block_Green_Dark"
    },
    {
      "x": -1,
      "y": 1,
      "z": 1,
      "name": "Cloth_Block_Wool_Red",
      "rotation": 2
    },
    {
      "x": -1,
      "y": 2,
      "z": 1,
      "name": "Cloth_Block_Wool_Red"
    },
    {
      "x": -1,
      "y": 3,
      "z": 1,
      "name": "Cloth_Block_Wool_Red_Half",
      "rotation": 2
    },
    {
      "x": -1,
      "y": -8,
      "z": 2,
      "name": "Wood_Windwillow_Trunk_Full"
    },
    {
      "x": -1,
      "y": 0,
      "z": 2,
      "name": "Plant_Moss_Block_Green_Dark"
    },
    {
      "x": -1,
      "y": 1,
      "z": 2,
      "name": "Cloth_Block_Wool_Red",
      "rotation": 1
    },
    {
      "x": -1,
      "y": 2,
      "z": 2,
      "name": "Cloth_Block_Wool_Red_Half",
      "rotation": 4
    },
    {
      "x": -1,
      "y": 3,
      "z": 2,
      "name": "Cloth_Block_Wool_Red"
    },
    {
      "x": -1,
      "y": 0,
      "z": 3,
      "name": "Plant_Moss_Block_Green_Dark"
    },
    {
      "x": -1,
      "y": 1,
      "z": 3,
      "name": "Cloth_Block_Wool_Red_Half",
      "rotation": 10
    },
    {
      "x": -1,
      "y": 2,
      "z": 3,
      "name": "Rock_Crystal_Red_Small"
    },
    {
      "x": -1,
      "y": 4,
      "z": 3,
      "name": "Cloth_Block_Wool_Red"
    },
    {
      "x": -1,
      "y": 5,
      "z": 3,
      "name": "Cloth_Block_Wool_Red_Half",
      "rotation": 6
    },
    {
      "x": -1,
      "y": 6,
      "z": 3,
      "name": "Cloth_Block_Wool_Red_Half",
      "rotation": 6
    },
    {
      "x": -1,
      "y": -1,
      "z": 4,
      "name": "Wood_Windwillow_Trunk_Full"
    },
    {
      "x": -1,
      "y": 0,
      "z": 4,
      "name": "Plant_Moss_Block_Green_Dark"
    },
    {
      "x": -1,
      "y": 1,
      "z": 4,
      "name": "Empty"
    },
    {
      "x": -1,
      "y": 2,
      "z": 4,
      "name": "Cloth_Block_Wool_Red_Stairs",
      "rotation": 3
    },
    {
      "x": -1,
      "y": 5,
      "z": 4,
      "name": "Cloth_Block_Wool_Red_Half",
      "rotation": 4
    },
    {
      "x": -1,
      "y": 0,
      "z": 5,
      "name": "Plant_Moss_Block_Green_Dark"
    },
    {
      "x": -1,
      "y": 1,
      "z": 5,
      "name": "Empty"
    },
    {
      "x": -1,
      "y": 3,
      "z": 5,
      "name": "Cloth_Block_Wool_Red_Stairs",
      "rotation": 2
    },
    {
      "x": -1,
      "y": 0,
      "z": 6,
      "name": "Plant_Moss_Block_Green_Dark"
    },
    {
      "x": -1,
      "y": 1,
      "z": 6,
      "name": "Empty"
    },
    {
      "x": -1,
      "y": 4,
      "z": 6,
      "name": "Cloth_Block_Wool_Red_Half",
      "rotation": 4
    },
    {
      "x": -1,
      "y": 1,
      "z": 7,
      "name": "Plant_Moss_Block_Green_Dark"
    },
    {
      "x": 0,
      "y": 1,
      "z": -8,
      "name": "Plant_Moss_Block_Green_Dark"
    },
    {
      "x": 0,
      "y": 0,
      "z": -7,
      "name": "Plant_Moss_Block_Green_Dark"
    },
    {
      "x": 0,
      "y": 1,
      "z": -7,
      "name": "Empty"
    },
    {
      "x": 0,
      "y": 0,
      "z": -6,
      "name": "Plant_Moss_Block_Green_Dark"
    },
    {
      "x": 0,
      "y": 1,
      "z": -6,
      "name": "Empty"
    },
    {
      "x": 0,
      "y": 3,
      "z": -6,
      "name": "Cloth_Block_Wool_Red_Half",
      "rotation": 6
    },
    {
      "x": 0,
      "y": 4,
      "z": -6,
      "name": "Cloth_Block_Wool_Red_Half",
      "rotation": 4
    },
    {
      "x": 0,
      "y": 5,
      "z": -6,
      "name": "Cloth_Block_Wool_Red_Half",
      "rotation": 6
    },
    {
      "x": 0,
      "y": -1,
      "z": -5,
      "name": "Wood_Windwillow_Trunk_Full"
    },
    {
      "x": 0,
      "y": 0,
      "z": -5,
      "name": "Plant_Moss_Block_Green_Dark"
    },
    {
      "x": 0,
      "y": 1,
      "z": -5,
      "name": "Empty"
    },
    {
      "x": 0,
      "y": 2,
      "z": -5,
      "name": "Cloth_Block_Wool_Red_Stairs",
      "rotation": 34
    },
    {
      "x": 0,
      "y": 3,
      "z": -5,
      "name": "Cloth_Block_Wool_Red_Half"
    },
    {
      "x": 0,
      "y": -1,
      "z": -4,
      "name": "Wood_Windwillow_Trunk_Full"
    },
    {
      "x": 0,
      "y": 0,
      "z": -4,
      "name": "Plant_Moss_Block_Green_Dark"
    },
    {
      "x": 0,
      "y": 1,
      "z": -4,
      "name": "Cloth_Block_Wool_Red_Half",
      "rotation": 10
    },
    {
      "x": 0,
      "y": 2,
      "z": -4,
      "name": "Cloth_Block_Wool_Red",
      "rotation": 2
    },
    {
      "x": 0,
      "y": 4,
      "z": -4,
      "name": "Cloth_Block_Wool_Red_Half",
      "rotation": 6
    },
    {
      "x": 0,
      "y": 5,
      "z": -4,
      "name": "Cloth_Block_Wool_Red"
    },
    {
      "x": 0,
      "y": 6,
      "z": -4,
      "name": "Cloth_Block_Wool_Red_Half",
      "rotation": 6
    },
    {
      "x": 0,
      "y": 0,
      "z": -3,
      "name": "Plant_Moss_Block_Green_Dark"
    },
    {
      "x": 0,
      "y": 1,
      "z": -3,
      "name": "Cloth_Block_Wool_Red_Half",
      "rotation": 10
    },
    {
      "x": 0,
      "y": 3,
      "z": -3,
      "name": "Cloth_Block_Wool_Red_Stairs",
      "rotation": 8
    },
    {
      "x": 0,
      "y": 4,
      "z": -3,
      "name": "Cloth_Block_Wool_Red_Stairs"
    },
    {
      "x": 0,
      "y": 7,
      "z": -3,
      "name": "Cloth_Block_Wool_Red_Stairs",
      "rotation": 2
    },
    {
      "x": 0,
      "y": 0,
      "z": -2,
      "name": "Plant_Moss_Block_Green_Dark"
    },
    {
      "x": 0,
      "y": 1,
      "z": -2,
      "name": "Cloth_Block_Wool_Red",
      "rotation": 3
    },
    {
      "x": 0,
      "y": 2,
      "z": -2,
      "name": "Cloth_Block_Wool_Red"
    },
    {
      "x": 0,
      "y": 3,
      "z": -2,
      "name": "Cloth_Block_Wool_Red_Stairs"
    },
    {
      "x": 0,
      "y": -9,
      "z": -1,
      "name": "Wood_Windwillow_Trunk_Full"
    },
    {
      "x": 0,
      "y": -2,
      "z": -1,
      "name": "Wood_Windwillow_Trunk_Full"
    },
    {
      "x": 0,
      "y": 0,
      "z": -1,
      "name": "Plant_Moss_Block_Green_Dark"
    },
    {
      "x": 0,
      "y": 1,
      "z": -1,
      "name": "Cloth_Block_Wool_Red",
      "rotation": 3
    },
    {
      "x": 0,
      "y": 2,
      "z": -1,
      "name": "Cloth_Block_Wool_Red",
      "rotation": 2
    },
    {
      "x": 0,
      "y": 4,
      "z": -1,
      "name": "Wood_Windwillow_Trunk_Full"
    },
    {
      "x": 0,
      "y": 5,
      "z": -1,
      "name": "Rock_Crystal_Red_Small"
    },
    {
      "x": 0,
      "y": -8,
      "z": 0,
      "name": "Wood_Windwillow_Trunk_Full"
    },
    {
      "x": 0,
      "y": -3,
      "z": 0,
      "name": "Wood_Windwillow_Trunk_Full"
    },
    {
      "x": 0,
      "y": -2,
      "z": 0,
      "name": "Wood_Windwillow_Trunk_Full"
    },
    {
      "x": 0,
      "y": -1,
      "z": 0,
      "name": "Wood_Windwillow_Trunk_Full"
    },
    {
      "x": 0,
      "y": 0,
      "z": 0,
      "name": "Plant_Moss_Block_Green_Dark"
    },
    {
      "x": 0,
      "y": 1,
      "z": 0,
      "name": "Cloth_Block_Wool_Red",
      "rotation": 2
    },
    {
      "x": 0,
      "y": 2,
      "z": 0,
      "name": "Cloth_Block_Wool_Red",
      "rotation": 2
    },
    {
      "x": 0,
      "y": 3,
      "z": 0,
      "name": "Wood_Windwillow_Trunk_Full"
    },
    {
      "x": 0,
      "y": 4,
      "z": 0,
      "name": "Wood_Windwillow_Trunk_Full"
    },
    {
      "x": 0,
      "y": 5,
      "z": 0,
      "name": "Rock_Crystal_Red_Large"
    },
    {
      "x": 0,
      "y": -7,
      "z": 1,
      "name": "Wood_Windwillow_Trunk_Full"
    },
    {
      "x": 0,
      "y": 0,
      "z": 1,
      "name": "Plant_Moss_Block_Green_Dark"
    },
    {
      "x": 0,
      "y": 1,
      "z": 1,
      "name": "Cloth_Block_Wool_Red",
      "rotation": 1
    },
    {
      "x": 0,
      "y": 2,
      "z": 1,
      "name": "Cloth_Block_Wool_Red",
      "rotation": 2
    },
    {
      "x": 0,
      "y": 4,
      "z": 1,
      "name": "Wood_Windwillow_Trunk_Full"
    },
    {
      "x": 0,
      "y": 5,
      "z": 1,
      "name": "Rock_Crystal_Red_Small"
    },
    {
      "x": 0,
      "y": 0,
      "z": 2,
      "name": "Plant_Moss_Block_Green_Dark"
    },
    {
      "x": 0,
      "y": 1,
      "z": 2,
      "name": "Cloth_Block_Wool_Red",
      "rotation": 1
    },
    {
      "x": 0,
      "y": 2,
      "z": 2,
      "name": "Cloth_Block_Wool_Red"
    },
    {
      "x": 0,
      "y": 3,
      "z": 2,
      "name": "Cloth_Block_Wool_Red_Stairs",
      "rotation": 2
    },
    {
      "x": 0,
      "y": 0,
      "z": 3,
      "name": "Plant_Moss_Block_Green_Dark"
    },
    {
      "x": 0,
      "y": 1,
      "z": 3,
      "name": "Cloth_Block_Wool_Red_Half",
      "rotation": 10
    },
    {
      "x": 0,
      "y": 3,
      "z": 3,
      "name": "Cloth_Block_Wool_Red_Stairs",
      "rotation": 10
    },
    {
      "x": 0,
      "y": 4,
      "z": 3,
      "name": "Cloth_Block_Wool_Red_Stairs",
      "rotation": 2
    },
    {
      "x": 0,
      "y": 7,
      "z": 3,
      "name": "Cloth_Block_Wool_Red_Stairs"
    },
    {
      "x": 0,
      "y": 0,
      "z": 4,
      "name": "Plant_Moss_Block_Green_Dark"
    },
    {
      "x": 0,
      "y": 1,
      "z": 4,
      "name": "Cloth_Block_Wool_Red_Half",
      "rotation": 10
    },
    {
      "x": 0,
      "y": 2,
      "z": 4,
      "name": "Cloth_Block_Wool_Red"
    },
    {
      "x": 0,
      "y": 4,
      "z": 4,
      "name": "Cloth_Block_Wool_Red_Half",
      "rotation": 4
    },
    {
      "x": 0,
      "y": 5,
      "z": 4,
      "name": "Cloth_Block_Wool_Red",
      "rotation": 2
    },
    {
      "x": 0,
      "y": 6,
      "z": 4,
      "name": "Cloth_Block_Wool_Red_Half",
      "rotation": 4
    },
    {
      "x": 0,
      "y": 0,
      "z": 5,
      "name": "Plant_Moss_Block_Green_Dark"
    },
    {
      "x": 0,
      "y": 1,
      "z": 5,
      "name": "Empty"
    },
    {
      "x": 0,
      "y": 2,
      "z": 5,
      "name": "Cloth_Block_Wool_Red_Stairs",
      "rotation": 10
    },
    {
      "x": 0,
      "y": 3,
      "z": 5,
      "name": "Cloth_Block_Wool_Red_Half"
    },
    {
      "x": 0,
      "y": 0,
      "z": 6,
      "name": "Plant_Moss_Block_Green_Dark"
    },
    {
      "x": 0,
      "y": 1,
      "z": 6,
      "name": "Empty"
    },
    {
      "x": 0,
      "y": 3,
      "z": 6,
      "name": "Cloth_Block_Wool_Red_Half",
      "rotation": 4
    },
    {
      "x": 0,
      "y": 4,
      "z": 6,
      "name": "Cloth_Block_Wool_Red_Half",
      "rotation": 6
    },
    {
      "x": 0,
      "y": 5,
      "z": 6,
      "name": "Cloth_Block_Wool_Red_Half",
      "rotation": 4
    },
    {
      "x": 0,
      "y": 1,
      "z": 7,
      "name": "Plant_Moss_Block_Green_Dark"
    },
    {
      "x": 1,
      "y": 1,
      "z": -8,
      "name": "Plant_Moss_Block_Green_Dark"
    },
    {
      "x": 1,
      "y": 1,
      "z": -7,
      "name": "Plant_Moss_Block_Green_Dark"
    },
    {
      "x": 1,
      "y": 0,
      "z": -6,
      "name": "Plant_Moss_Block_Green_Dark"
    },
    {
      "x": 1,
      "y": 1,
      "z": -6,
      "name": "Empty"
    },
    {
      "x": 1,
      "y": 4,
      "z": -6,
      "name": "Cloth_Block_Wool_Red_Half",
      "rotation": 6
    },
    {
      "x": 1,
      "y": 0,
      "z": -5,
      "name": "Plant_Moss_Block_Green_Dark"
    },
    {
      "x": 1,
      "y": 1,
      "z": -5,
      "name": "Empty"
    },
    {
      "x": 1,
      "y": 3,
      "z": -5,
      "name": "Cloth_Block_Wool_Red_Stairs"
    },
    {
      "x": 1,
      "y": 0,
      "z": -4,
      "name": "Plant_Moss_Block_Green_Dark"
    },
    {
      "x": 1,
      "y": 1,
      "z": -4,
      "name": "Empty"
    },
    {
      "x": 1,
      "y": 2,
      "z": -4,
      "name": "Cloth_Block_Wool_Red_Stairs",
      "rotation": 1
    },
    {
      "x": 1,
      "y": 5,
      "z": -4,
      "name": "Cloth_Block_Wool_Red_Half",
      "rotation": 6
    },
    {
      "x": 1,
      "y": -1,
      "z": -3,
      "name": "Wood_Windwillow_Trunk_Full"
    },
    {
      "x": 1,
      "y": 0,
      "z": -3,
      "name": "Plant_Moss_Block_Green_Dark"
    },
    {
      "x": 1,
      "y": 1,
      "z": -3,
      "name": "Cloth_Block_Wool_Red_Half",
      "rotation": 10
    },
    {
      "x": 1,
      "y": 2,
      "z": -3,
      "name": "Rock_Crystal_Red_Small"
    },
    {
      "x": 1,
      "y": 4,
      "z": -3,
      "name": "Cloth_Block_Wool_Red"
    },
    {
      "x": 1,
      "y": 5,
      "z": -3,
      "name": "Cloth_Block_Wool_Red_Half",
      "rotation": 4
    },
    {
      "x": 1,
      "y": 6,
      "z": -3,
      "name": "Cloth_Block_Wool_Red_Half",
      "rotation": 4
    },
    {
      "x": 1,
      "y": -10,
      "z": -2,
      "name": "Wood_Windwillow_Trunk_Full"
    },
    {
      "x": 1,
      "y": -1,
      "z": -2,
      "name": "Wood_Windwillow_Trunk_Full"
    },
    {
      "x": 1,
      "y": 0,
      "z": -2,
      "name": "Plant_Moss_Block_Green_Dark"
    },
    {
      "x": 1,
      "y": 1,
      "z": -2,
      "name": "Cloth_Block_Wool_Red",
      "rotation": 3
    },
    {
      "x": 1,
      "y": 2,
      "z": -2,
      "name": "Cloth_Block_Wool_Red_Half",
      "rotation": 6
    },
    {
      "x": 1,
      "y": 3,
      "z": -2,
      "name": "Cloth_Block_Wool_Red"
    },
    {
      "x": 1,
      "y": 0,
      "z": -1,
      "name": "Plant_Moss_Block_Green_Dark"
    },
    {
      "x": 1,
      "y": 1,
      "z": -1,
      "name": "Cloth_Block_Wool_Red",
      "rotation": 3
    },
    {
      "x": 1,
      "y": 2,
      "z": -1,
      "name": "Cloth_Block_Wool_Red"
    },
    {
      "x": 1,
      "y": 3,
      "z": -1,
      "name": "Cloth_Block_Wool_Red_Half",
      "rotation": 2
    },
    {
      "x": 1,
      "y": -5,
      "z": 0,
      "name": "Wood_Windwillow_Trunk_Full"
    },
    {
      "x": 1,
      "y": -4,
      "z": 0,
      "name": "Wood_Windwillow_Trunk_Full"
    },
    {
      "x": 1,
      "y": 0,
      "z": 0,
      "name": "Plant_Moss_Block_Green_Dark"
    },
    {
      "x": 1,
      "y": 1,
      "z": 0,
      "name": "Cloth_Block_Wool_Red",
      "rotation": 2
    },
    {
      "x": 1,
      "y": 2,
      "z": 0,
      "name": "Cloth_Block_Wool_Red",
      "rotation": 2
    },
    {
      "x": 1,
      "y": 4,
      "z": 0,
      "name": "Wood_Windwillow_Trunk_Full"
    },
    {
      "x": 1,
      "y": 5,
      "z": 0,
      "name": "Rock_Crystal_Red_Small"
    },
    {
      "x": 1,
      "y": -6,
      "z": 1,
      "name": "Wood_Windwillow_Trunk_Full"
    },
    {
      "x": 1,
      "y": -2,
      "z": 1,
      "name": "Wood_Windwillow_Trunk_Full"
    },
    {
      "x": 1,
      "y": 0,
      "z": 1,
      "name": "Plant_Moss_Block_Green_Dark"
    },
    {
      "x": 1,
      "y": 1,
      "z": 1,
      "name": "Cloth_Block_Wool_Red",
      "rotation": 1
    },
    {
      "x": 1,
      "y": 2,
      "z": 1,
      "name": "Cloth_Block_Wool_Red"
    },
    {
      "x": 1,
      "y": 3,
      "z": 1,
      "name": "Cloth_Block_Wool_Red_Half",
      "rotation": 2
    },
    {
      "x": 1,
      "y": 0,
      "z": 2,
      "name": "Plant_Moss_Block_Green_Dark"
    },
    {
      "x": 1,
      "y": 1,
      "z": 2,
      "name": "Cloth_Block_Wool_Red",
      "rotation": 1
    },
    {
      "x": 1,
      "y": 2,
      "z": 2,
      "name": "Cloth_Block_Wool_Red_Half",
      "rotation": 4
    },
    {
      "x": 1,
      "y": 3,
      "z": 2,
      "name": "Cloth_Block_Wool_Red"
    },
    {
      "x": 1,
      "y": -1,
      "z": 3,
      "name": "Wood_Windwillow_Trunk_Full"
    },
    {
      "x": 1,
      "y": 0,
      "z": 3,
      "name": "Plant_Moss_Block_Green_Dark"
    },
    {
      "x": 1,
      "y": 1,
      "z": 3,
      "name": "Cloth_Block_Wool_Red_Half",
      "rotation": 10
    },
    {
      "x": 1,
      "y": 2,
      "z": 3,
      "name": "Rock_Crystal_Red_Small"
    },
    {
      "x": 1,
      "y": 4,
      "z": 3,
      "name": "Cloth_Block_Wool_Red"
    },
    {
      "x": 1,
      "y": 5,
      "z": 3,
      "name": "Cloth_Block_Wool_Red_Half",
      "rotation": 6
    },
    {
      "x": 1,
      "y": 6,
      "z": 3,
      "name": "Cloth_Block_Wool_Red_Half",
      "rotation": 6
    },
    {
      "x": 1,
      "y": -1,
      "z": 4,
      "name": "Wood_Windwillow_Trunk_Full"
    },
    {
      "x": 1,
      "y": 0,
      "z": 4,
      "name": "Plant_Moss_Block_Green_Dark"
    },
    {
      "x": 1,
      "y": 1,
      "z": 4,
      "name": "Empty"
    },
    {
      "x": 1,
      "y": 2,
      "z": 4,
      "name": "Cloth_Block_Wool_Red_Stairs",
      "rotation": 1
    },
    {
      "x": 1,
      "y": 5,
      "z": 4,
      "name": "Cloth_Block_Wool_Red_Half",
      "rotation": 4
    },
    {
      "x": 1,
      "y": 0,
      "z": 5,
      "name": "Plant_Moss_Block_Green_Dark"
    },
    {
      "x": 1,
      "y": 1,
      "z": 5,
      "name": "Empty"
    },
    {
      "x": 1,
      "y": 3,
      "z": 5,
      "name": "Cloth_Block_Wool_Red_Stairs",
      "rotation": 2
    },
    {
      "x": 1,
      "y": 0,
      "z": 6,
      "name": "Plant_Moss_Block_Green_Dark"
    },
    {
      "x": 1,
      "y": 1,
      "z": 6,
      "name": "Empty"
    },
    {
      "x": 1,
      "y": 4,
      "z": 6,
      "name": "Cloth_Block_Wool_Red_Half",
      "rotation": 4
    },
    {
      "x": 1,
      "y": 1,
      "z": 7,
      "name": "Plant_Moss_Block_Green_Dark"
    },
    {
      "x": 2,
      "y": 1,
      "z": -7,
      "name": "Plant_Moss_Block_Green_Dark"
    },
    {
      "x": 2,
      "y": 0,
      "z": -6,
      "name": "Plant_Moss_Block_Green_Dark"
    },
    {
      "x": 2,
      "y": 1,
      "z": -6,
      "name": "Empty"
    },
    {
      "x": 2,
      "y": 0,
      "z": -5,
      "name": "Plant_Moss_Block_Green_Dark"
    },
    {
      "x": 2,
      "y": 1,
      "z": -5,
      "name": "Empty"
    },
    {
      "x": 2,
      "y": -1,
      "z": -4,
      "name": "Wood_Windwillow_Trunk_Full"
    },
    {
      "x": 2,
      "y": 0,
      "z": -4,
      "name": "Plant_Moss_Block_Green_Dark"
    },
    {
      "x": 2,
      "y": 1,
      "z": -4,
      "name": "Empty"
    },
    {
      "x": 2,
      "y": 0,
      "z": -3,
      "name": "Plant_Moss_Block_Green_Dark"
    },
    {
      "x": 2,
      "y": 1,
      "z": -3,
      "name": "Empty"
    },
    {
      "x": 2,
      "y": 2,
      "z": -3,
      "name": "Cloth_Block_Wool_Red_Stairs",
      "rotation": 3
    },
    {
      "x": 2,
      "y": -1,
      "z": -2,
      "name": "Wood_Windwillow_Trunk_Full"
    },
    {
      "x": 2,
      "y": 0,
      "z": -2,
      "name": "Plant_Moss_Block_Green_Dark"
    },
    {
      "x": 2,
      "y": 1,
      "z": -2,
      "name": "Cloth_Block_Wool_Red_Half",
      "rotation": 10
    },
    {
      "x": 2,
      "y": 0,
      "z": -1,
      "name": "Plant_Moss_Block_Green_Dark"
    },
    {
      "x": 2,
      "y": 1,
      "z": -1,
      "name": "Cloth_Block_Wool_Red",
      "rotation": 3
    },
    {
      "x": 2,
      "y": 2,
      "z": -1,
      "name": "Cloth_Block_Wool_Red_Half",
      "rotation": 5
    },
    {
      "x": 2,
      "y": 3,
      "z": -1,
      "name": "Cloth_Block_Wool_Red"
    },
    {
      "x": 2,
      "y": 0,
      "z": 0,
      "name": "Plant_Moss_Block_Green_Dark"
    },
    {
      "x": 2,
      "y": 1,
      "z": 0,
      "name": "Cloth_Block_Wool_Red",
      "rotation": 2
    },
    {
      "x": 2,
      "y": 2,
      "z": 0,
      "name": "Cloth_Block_Wool_Red"
    },
    {
      "x": 2,
      "y": 3,
      "z": 0,
      "name": "Cloth_Block_Wool_Red_Stairs",
      "rotation": 3
    },
    {
      "x": 2,
      "y": -7,
      "z": 1,
      "name": "Wood_Windwillow_Trunk_Full"
    },
    {
      "x": 2,
      "y": -1,
      "z": 1,
      "name": "Wood_Windwillow_Trunk_Full"
    },
    {
      "x": 2,
      "y": 0,
      "z": 1,
      "name": "Plant_Moss_Block_Green_Dark"
    },
    {
      "x": 2,
      "y": 1,
      "z": 1,
      "name": "Cloth_Block_Wool_Red",
      "rotation": 2
    },
    {
      "x": 2,
      "y": 2,
      "z": 1,
      "name": "Cloth_Block_Wool_Red_Half",
      "rotation": 5
    },
    {
      "x": 2,
      "y": 3,
      "z": 1,
      "name": "Cloth_Block_Wool_Red"
    },
    {
      "x": 2,
      "y": -1,
      "z": 2,
      "name": "Wood_Windwillow_Trunk_Full"
    },
    {
      "x": 2,
      "y": 0,
      "z": 2,
      "name": "Plant_Moss_Block_Green_Dark"
    },
    {
      "x": 2,
      "y": 1,
      "z": 2,
      "name": "Cloth_Block_Wool_Red_Half",
      "rotation": 10
    },
    {
      "x": 2,
      "y": 0,
      "z": 3,
      "name": "Plant_Moss_Block_Green_Dark"
    },
    {
      "x": 2,
      "y": 1,
      "z": 3,
      "name": "Empty"
    },
    {
      "x": 2,
      "y": 2,
      "z": 3,
      "name": "Cloth_Block_Wool_Red_Stairs",
      "rotation": 3
    },
    {
      "x": 2,
      "y": 0,
      "z": 4,
      "name": "Plant_Moss_Block_Green_Dark"
    },
    {
      "x": 2,
      "y": 1,
      "z": 4,
      "name": "Empty"
    },
    {
      "x": 2,
      "y": 0,
      "z": 5,
      "name": "Plant_Moss_Block_Green_Dark"
    },
    {
      "x": 2,
      "y": 1,
      "z": 5,
      "name": "Empty"
    },
    {
      "x": 2,
      "y": 1,
      "z": 6,
      "name": "Plant_Moss_Block_Green_Dark"
    },
    {
      "x": 2,
      "y": 1,
      "z": 7,
      "name": "Plant_Moss_Block_Green_Dark"
    },
    {
      "x": 3,
      "y": 1,
      "z": -7,
      "name": "Plant_Moss_Block_Green_Dark"
    },
    {
      "x": 3,
      "y": 1,
      "z": -6,
      "name": "Plant_Moss_Block_Green_Dark"
    },
    {
      "x": 3,
      "y": 0,
      "z": -5,
      "name": "Plant_Moss_Block_Green_Dark"
    },
    {
      "x": 3,
      "y": 1,
      "z": -5,
      "name": "Empty"
    },
    {
      "x": 3,
      "y": 0,
      "z": -4,
      "name": "Plant_Moss_Block_Green_Dark"
    },
    {
      "x": 3,
      "y": 1,
      "z": -4,
      "name": "Empty"
    },
    {
      "x": 3,
      "y": 3,
      "z": -4,
      "name": "Cloth_Block_Wool_Red_Stairs",
      "rotation": 33
    },
    {
      "x": 3,
      "y": 4,
      "z": -4,
      "name": "Cloth_Block_Wool_Red_Half",
      "rotation": 7
    },
    {
      "x": 3,
      "y": 0,
      "z": -3,
      "name": "Plant_Moss_Block_Green_Dark"
    },
    {
      "x": 3,
      "y": 1,
      "z": -3,
      "name": "Empty"
    },
    {
      "x": 3,
      "y": 2,
      "z": -3,
      "name": "Cloth_Block_Wool_Red_Half",
      "rotation": 35
    },
    {
      "x": 3,
      "y": 3,
      "z": -3,
      "name": "Cloth_Block_Wool_Red_Half",
      "rotation": 1
    },
    {
      "x": 3,
      "y": 0,
      "z": -2,
      "name": "Plant_Moss_Block_Green_Dark"
    },
    {
      "x": 3,
      "y": 1,
      "z": -2,
      "name": "Empty"
    },
    {
      "x": 3,
      "y": 2,
      "z": -2,
      "name": "Cloth_Block_Wool_Red_Stairs"
    },
    {
      "x": 3,
      "y": -1,
      "z": -1,
      "name": "Wood_Windwillow_Trunk_Full"
    },
    {
      "x": 3,
      "y": 0,
      "z": -1,
      "name": "Plant_Moss_Block_Green_Dark"
    },
    {
      "x": 3,
      "y": 1,
      "z": -1,
      "name": "Cloth_Block_Wool_Red_Half",
      "rotation": 10
    },
    {
      "x": 3,
      "y": 2,
      "z": -1,
      "name": "Rock_Crystal_Red_Small"
    },
    {
      "x": 3,
      "y": 4,
      "z": -1,
      "name": "Cloth_Block_Wool_Red"
    },
    {
      "x": 3,
      "y": 5,
      "z": -1,
      "name": "Cloth_Block_Wool_Red_Half",
      "rotation": 7
    },
    {
      "x": 3,
      "y": 6,
      "z": -1,
      "name": "Cloth_Block_Wool_Red_Half",
      "rotation": 7
    },
    {
      "x": 3,
      "y": 0,
      "z": 0,
      "name": "Plant_Moss_Block_Green_Dark"
    },
    {
      "x": 3,
      "y": 1,
      "z": 0,
      "name": "Cloth_Block_Wool_Red_Half",
      "rotation": 10
    },
    {
      "x": 3,
      "y": 3,
      "z": 0,
      "name": "Cloth_Block_Wool_Red_Stairs",
      "rotation": 11
    },
    {
      "x": 3,
      "y": 4,
      "z": 0,
      "name": "Cloth_Block_Wool_Red_Stairs",
      "rotation": 3
    },
    {
      "x": 3,
      "y": 7,
      "z": 0,
      "name": "Cloth_Block_Wool_Red_Stairs",
      "rotation": 1
    },
    {
      "x": 3,
      "y": -1,
      "z": 1,
      "name": "Wood_Windwillow_Trunk_Full"
    },
    {
      "x": 3,
      "y": 0,
      "z": 1,
      "name": "Plant_Moss_Block_Green_Dark"
    },
    {
      "x": 3,
      "y": 1,
      "z": 1,
      "name": "Cloth_Block_Wool_Red_Half",
      "rotation": 10
    },
    {
      "x": 3,
      "y": 2,
      "z": 1,
      "name": "Rock_Crystal_Red_Small"
    },
    {
      "x": 3,
      "y": 4,
      "z": 1,
      "name": "Cloth_Block_Wool_Red"
    },
    {
      "x": 3,
      "y": 5,
      "z": 1,
      "name": "Cloth_Block_Wool_Red_Half",
      "rotation": 7
    },
    {
      "x": 3,
      "y": 6,
      "z": 1,
      "name": "Cloth_Block_Wool_Red_Half",
      "rotation": 7
    },
    {
      "x": 3,
      "y": 0,
      "z": 2,
      "name": "Plant_Moss_Block_Green_Dark"
    },
    {
      "x": 3,
      "y": 1,
      "z": 2,
      "name": "Empty"
    },
    {
      "x": 3,
      "y": 2,
      "z": 2,
      "name": "Cloth_Block_Wool_Red_Stairs",
      "rotation": 2
    },
    {
      "x": 3,
      "y": 0,
      "z": 3,
      "name": "Plant_Moss_Block_Green_Dark"
    },
    {
      "x": 3,
      "y": 1,
      "z": 3,
      "name": "Empty"
    },
    {
      "x": 3,
      "y": 2,
      "z": 3,
      "name": "Cloth_Block_Wool_Red_Half",
      "rotation": 8
    },
    {
      "x": 3,
      "y": 3,
      "z": 3,
      "name": "Cloth_Block_Wool_Red_Half"
    },
    {
      "x": 3,
      "y": 0,
      "z": 4,
      "name": "Plant_Moss_Block_Green_Dark"
    },
    {
      "x": 3,
      "y": 1,
      "z": 4,
      "name": "Empty"
    },
    {
      "x": 3,
      "y": 3,
      "z": 4,
      "name": "Cloth_Block_Wool_Red_Stairs",
      "rotation": 11
    },
    {
      "x": 3,
      "y": 4,
      "z": 4,
      "name": "Cloth_Block_Wool_Red_Half",
      "rotation": 7
    },
    {
      "x": 3,
      "y": 0,
      "z": 5,
      "name": "Plant_Moss_Block_Green_Dark"
    },
    {
      "x": 3,
      "y": 1,
      "z": 5,
      "name": "Empty"
    },
    {
      "x": 3,
      "y": 1,
      "z": 6,
      "name": "Plant_Moss_Block_Green_Dark"
    },
    {
      "x": 4,
      "y": 1,
      "z": -6,
      "name": "Plant_Moss_Block_Green_Dark"
    },
    {
      "x": 4,
      "y": 1,
      "z": -5,
      "name": "Plant_Moss_Block_Green_Dark"
    },
    {
      "x": 4,
      "y": 0,
      "z": -4,
      "name": "Plant_Moss_Block_Green_Dark"
    },
    {
      "x": 4,
      "y": 1,
      "z": -4,
      "name": "Empty"
    },
    {
      "x": 4,
      "y": 4,
      "z": -4,
      "name": "Cloth_Block_Wool_Red_Half",
      "rotation": 8
    },
    {
      "x": 4,
      "y": 5,
      "z": -4,
      "name": "Cloth_Block_Wool_Red",
      "rotation": 1
    },
    {
      "x": 4,
      "y": 0,
      "z": -3,
      "name": "Plant_Moss_Block_Green_Dark"
    },
    {
      "x": 4,
      "y": 1,
      "z": -3,
      "name": "Empty"
    },
    {
      "x": 4,
      "y": 3,
      "z": -3,
      "name": "Cloth_Block_Wool_Red_Stairs",
      "rotation": 34
    },
    {
      "x": 4,
      "y": 4,
      "z": -3,
      "name": "Cloth_Block_Wool_Red_Half",
      "rotation": 4
    },
    {
      "x": 4,
      "y": 0,
      "z": -2,
      "name": "Plant_Moss_Block_Green_Dark"
    },
    {
      "x": 4,
      "y": 1,
      "z": -2,
      "name": "Empty"
    },
    {
      "x": 4,
      "y": -1,
      "z": -1,
      "name": "Wood_Windwillow_Trunk_Full"
    },
    {
      "x": 4,
      "y": 0,
      "z": -1,
      "name": "Plant_Moss_Block_Green_Dark"
    },
    {
      "x": 4,
      "y": 1,
      "z": -1,
      "name": "Empty"
    },
    {
      "x": 4,
      "y": 2,
      "z": -1,
      "name": "Cloth_Block_Wool_Red_Stairs",
      "rotation": 2
    },
    {
      "x": 4,
      "y": 5,
      "z": -1,
      "name": "Cloth_Block_Wool_Red_Half",
      "rotation": 5
    },
    {
      "x": 4,
      "y": 0,
      "z": 0,
      "name": "Plant_Moss_Block_Green_Dark"
    },
    {
      "x": 4,
      "y": 1,
      "z": 0,
      "name": "Cloth_Block_Wool_Red_Half",
      "rotation": 8
    },
    {
      "x": 4,
      "y": 2,
      "z": 0,
      "name": "Cloth_Block_Wool_Red"
    },
    {
      "x": 4,
      "y": 4,
      "z": 0,
      "name": "Cloth_Block_Wool_Red_Half",
      "rotation": 5
    },
    {
      "x": 4,
      "y": 5,
      "z": 0,
      "name": "Cloth_Block_Wool_Red",
      "rotation": 2
    },
    {
      "x": 4,
      "y": 6,
      "z": 0,
      "name": "Cloth_Block_Wool_Red_Half",
      "rotation": 5
    },
    {
      "x": 4,
      "y": 0,
      "z": 1,
      "name": "Plant_Moss_Block_Green_Dark"
    },
    {
      "x": 4,
      "y": 1,
      "z": 1,
      "name": "Empty"
    },
    {
      "x": 4,
      "y": 2,
      "z": 1,
      "name": "Cloth_Block_Wool_Red_Stairs"
    },
    {
      "x": 4,
      "y": 5,
      "z": 1,
      "name": "Cloth_Block_Wool_Red_Half",
      "rotation": 5
    },
    {
      "x": 4,
      "y": -1,
      "z": 2,
      "name": "Wood_Windwillow_Trunk_Full"
    },
    {
      "x": 4,
      "y": 0,
      "z": 2,
      "name": "Plant_Moss_Block_Green_Dark"
    },
    {
      "x": 4,
      "y": 1,
      "z": 2,
      "name": "Empty"
    },
    {
      "x": 4,
      "y": 0,
      "z": 3,
      "name": "Plant_Moss_Block_Green_Dark"
    },
    {
      "x": 4,
      "y": 1,
      "z": 3,
      "name": "Empty"
    },
    {
      "x": 4,
      "y": 3,
      "z": 3,
      "name": "Cloth_Block_Wool_Red_Stairs",
      "rotation": 10
    },
    {
      "x": 4,
      "y": 4,
      "z": 3,
      "name": "Cloth_Block_Wool_Red_Half",
      "rotation": 6
    },
    {
      "x": 4,
      "y": 0,
      "z": 4,
      "name": "Plant_Moss_Block_Green_Dark"
    },
    {
      "x": 4,
      "y": 1,
      "z": 4,
      "name": "Empty"
    },
    {
      "x": 4,
      "y": 4,
      "z": 4,
      "name": "Cloth_Block_Wool_Red_Half",
      "rotation": 8
    },
    {
      "x": 4,
      "y": 5,
      "z": 4,
      "name": "Cloth_Block_Wool_Red"
    },
    {
      "x": 4,
      "y": 1,
      "z": 5,
      "name": "Plant_Moss_Block_Green_Dark"
    },
    {
      "x": 4,
      "y": 1,
      "z": 6,
      "name": "Plant_Moss_Block_Green_Dark"
    },
    {
      "x": 5,
      "y": 1,
      "z": -5,
      "name": "Plant_Moss_Block_Green_Dark"
    },
    {
      "x": 5,
      "y": 1,
      "z": -4,
      "name": "Plant_Moss_Block_Green_Dark"
    },
    {
      "x": 5,
      "y": 0,
      "z": -3,
      "name": "Plant_Moss_Block_Green_Dark"
    },
    {
      "x": 5,
      "y": 1,
      "z": -3,
      "name": "Empty"
    },
    {
      "x": 5,
      "y": 0,
      "z": -2,
      "name": "Plant_Moss_Block_Green_Dark"
    },
    {
      "x": 5,
      "y": 1,
      "z": -2,
      "name": "Empty"
    },
    {
      "x": 5,
      "y": 0,
      "z": -1,
      "name": "Plant_Moss_Block_Green_Dark"
    },
    {
      "x": 5,
      "y": 1,
      "z": -1,
      "name": "Empty"
    },
    {
      "x": 5,
      "y": 3,
      "z": -1,
      "name": "Cloth_Block_Wool_Red_Stairs",
      "rotation": 3
    },
    {
      "x": 5,
      "y": 0,
      "z": 0,
      "name": "Plant_Moss_Block_Green_Dark"
    },
    {
      "x": 5,
      "y": 1,
      "z": 0,
      "name": "Empty"
    },
    {
      "x": 5,
      "y": 2,
      "z": 0,
      "name": "Cloth_Block_Wool_Red_Stairs",
      "rotation": 33
    },
    {
      "x": 5,
      "y": 3,
      "z": 0,
      "name": "Cloth_Block_Wool_Red_Half"
    },
    {
      "x": 5,
      "y": 0,
      "z": 1,
      "name": "Plant_Moss_Block_Green_Dark"
    },
    {
      "x": 5,
      "y": 1,
      "z": 1,
      "name": "Empty"
    },
    {
      "x": 5,
      "y": 3,
      "z": 1,
      "name": "Cloth_Block_Wool_Red_Stairs",
      "rotation": 3
    },
    {
      "x": 5,
      "y": 0,
      "z": 2,
      "name": "Plant_Moss_Block_Green_Dark"
    },
    {
      "x": 5,
      "y": 1,
      "z": 2,
      "name": "Empty"
    },
    {
      "x": 5,
      "y": 0,
      "z": 3,
      "name": "Plant_Moss_Block_Green_Dark"
    },
    {
      "x": 5,
      "y": 1,
      "z": 3,
      "name": "Empty"
    },
    {
      "x": 5,
      "y": 1,
      "z": 4,
      "name": "Plant_Moss_Block_Green_Dark"
    },
    {
      "x": 5,
      "y": 1,
      "z": 5,
      "name": "Plant_Moss_Block_Green_Dark"
    },
    {
      "x": 6,
      "y": 1,
      "z": -4,
      "name": "Plant_Moss_Block_Green_Dark"
    },
    {
      "x": 6,
      "y": 1,
      "z": -3,
      "name": "Plant_Moss_Block_Green_Dark"
    },
    {
      "x": 6,
      "y": 1,
      "z": -2,
      "name": "Plant_Moss_Block_Green_Dark"
    },
    {
      "x": 6,
      "y": 0,
      "z": -1,
      "name": "Plant_Moss_Block_Green_Dark"
    },
    {
      "x": 6,
      "y": 1,
      "z": -1,
      "name": "Empty"
    },
    {
      "x": 6,
      "y": 4,
      "z": -1,
      "name": "Cloth_Block_Wool_Red_Half",
      "rotation": 5
    },
    {
      "x": 6,
      "y": 0,
      "z": 0,
      "name": "Plant_Moss_Block_Green_Dark"
    },
    {
      "x": 6,
      "y": 1,
      "z": 0,
      "name": "Empty"
    },
    {
      "x": 6,
      "y": 3,
      "z": 0,
      "name": "Cloth_Block_Wool_Red_Half",
      "rotation": 5
    },
    {
      "x": 6,
      "y": 4,
      "z": 0,
      "name": "Cloth_Block_Wool_Red_Half",
      "rotation": 7
    },
    {
      "x": 6,
      "y": 5,
      "z": 0,
      "name": "Cloth_Block_Wool_Red_Half",
      "rotation": 5
    },
    {
      "x": 6,
      "y": 0,
      "z": 1,
      "name": "Plant_Moss_Block_Green_Dark"
    },
    {
      "x": 6,
      "y": 1,
      "z": 1,
      "name": "Empty"
    },
    {
      "x": 6,
      "y": 4,
      "z": 1,
      "name": "Cloth_Block_Wool_Red_Half",
      "rotation": 5
    },
    {
      "x": 6,
      "y": 1,
      "z": 2,
      "name": "Plant_Moss_Block_Green_Dark"
    },
    {
      "x": 6,
      "y": 1,
      "z": 3,
      "name": "Plant_Moss_Block_Green_Dark"
    },
    {
      "x": 6,
      "y": 1,
      "z": 4,
      "name": "Plant_Moss_Block_Green_Dark"
    },
    {
      "x": 7,
      "y": 1,
      "z": -2,
      "name": "Plant_Moss_Block_Green_Dark"
    },
    {
      "x": 7,
      "y": 1,
      "z": -1,
      "name": "Plant_Moss_Block_Green_Dark"
    },
    {
      "x": 7,
      "y": 1,
      "z": 0,
      "name": "Plant_Moss_Block_Green_Dark"
    },
    {
      "x": 7,
      "y": 1,
      "z": 1,
      "name": "Plant_Moss_Block_Green_Dark"
    },
    {
      "x": 7,
      "y": 1,
      "z": 2,
      "name": "Plant_Moss_Block_Green_Dark"
    }
  ]
}