{"anchorX":0,"anchorY":0,"anchorZ":0,"blockIdVersion":11,"blocks":[{"name":"Rock_Sandstone_White_Brick_Half","rotation":7,"x":-4,"y":0,"z":-3},{"name":"Rock_Sandstone_White_Brick_Half","rotation":7,"x":-4,"y":0,"z":-2},{"name":"Rock_Sandstone_White_Brick_Half","rotation":7,"x":-4,"y":0,"z":-1},{"name":"Rock_Sandstone_White_Cobble_Half","rotation":7,"x":-4,"y":0,"z":0},{"name":"Rock_Sandstone_White_Cobble_Half","rotation":7,"x":-4,"y":0,"z":1},{"name":"Rock_Sandstone_White_Brick_Half","rotation":7,"x":-4,"y":0,"z":3},{"name":"Rock_Sandstone_Brick_Half","rotation":7,"x":-4,"y":1,"z":3},{"name":"Rock_Sandstone_Brick_Half","rotation":7,"x":-4,"y":2,"z":3},{"name":"Rock_Sandstone_White_Brick_Half","rotation":7,"x":-4,"y":0,"z":4},{"name":"Rock_Sandstone_Brick_Half","rotation":7,"x":-4,"y":1,"z":4},{"name":"Rock_Sandstone_Brick_Half","rotation":7,"x":-4,"y":2,"z":4},{"name":"Rock_Sandstone_Brick_Half","rotation":7,"x":-4,"y":3,"z":4},{"name":"Rock_Sandstone_White_Brick_Half","rotation":6,"x":-3,"y":0,"z":-4},{"name":"Rock_Sandstone_Cobble","x":-3,"y":0,"z":-3},{"name":"Rock_Sandstone_Brick","x":-3,"y":1,"z":-3},{"name":"Rock_Sandstone_Brick","x":-3,"y":2,"z":-3},{"name":"Rock_Sandstone_Cobble","x":-3,"y":0,"z":-2},{"name":"Rock_Sandstone_Brick","x":-3,"y":1,"z":-2},{"name":"Rock_Sandstone_Brick","x":-3,"y":2,"z":-2},{"name":"Rubble_Sandstone","support":15,"x":-3,"y":3,"z":-2},{"name":"Rock_Sandstone_Cobble","x":-3,"y":0,"z":-1},{"name":"Rock_Sandstone_Brick","x":-3,"y":1,"z":-1},{"name":"Rock_Sandstone_Brick","x":-3,"y":2,"z":-1},{"name":"Rock_Sandstone_Brick","x":-3,"y":3,"z":-1},{"name":"Rock_Sandstone_Cobble","x":-3,"y":0,"z":0},{"name":"Rock_Sandstone_Brick","x":-3,"y":1,"z":0},{"name":"Rock_Sandstone_Brick","x":-3,"y":2,"z":0},{"name":"Rock_Sandstone_Brick","x":-3,"y":3,"z":0},{"name":"Rock_Sandstone_Brick","x":-3,"y":4,"z":0},{"name":"Rock_Sandstone_Brick","x":-3,"y":5,"z":0},{"name":"Rock_Sandstone_Brick_Ornate","x":-3,"y":6,"z":0},{"name":"Rock_Sandstone_Brick","x":-3,"y":7,"z":0},{"name":"Rock_Sandstone_Brick_Stairs","rotation":2,"x":-3,"y":8,"z":0},{"name":"Rock_Sandstone_Brick","x":-3,"y":8,"z":1},{"name":"Rock_Sandstone_Cobble","x":-3,"y":0,"z":4},{"name":"Furniture_Human_Ruins_Shelf","rotation":1,"x":-3,"y":1,"z":4},{"name":"Furniture_Ancient_Sack","rotation":2,"x":-3,"y":2,"z":4},{"name":"Rock_Sandstone_Brick_Half","rotation":8,"x":-3,"y":3,"z":4},{"name":"Rock_Sandstone_White_Brick_Half","x":-3,"y":4,"z":4},{"name":"Rock_Sandstone_White_Cobble_Half","rotation":4,"x":-3,"y":0,"z":5},{"name":"Rock_Sandstone_Brick_Half","rotation":4,"x":-3,"y":1,"z":5},{"name":"Rock_Sandstone_Brick_Half","rotation":4,"x":-3,"y":2,"z":5},{"name":"Rock_Sandstone_Brick_Half","rotation":4,"x":-3,"y":3,"z":5},{"name":"Rock_Sandstone_White_Brick_Half","rotation":6,"x":-2,"y":0,"z":-4},{"name":"Rock_Sandstone_Cobble","x":-2,"y":0,"z":-3},{"name":"Rock_Sandstone_White_Brick","x":-2,"y":1,"z":-3},{"name":"Rubble_Sandstone_White","support":15,"x":-2,"y":2,"z":-3},{"name":"Rock_Sandstone_Cobble","x":-2,"y":0,"z":-2},{"name":"Rock_Sandstone_White_Brick","x":-2,"y":1,"z":-2},{"name":"Rock_Sandstone_White_Brick","x":-2,"y":2,"z":-2},{"name":"Rock_Sandstone_Cobble","x":-2,"y":0,"z":-1},{"name":"Rubble_Sandstone_White","support":15,"x":-2,"y":1,"z":-1},{"name":"Rock_Sandstone_Cobble","x":-2,"y":0,"z":0},{"name":"Rubble_Sandstone","support":15,"x":-2,"y":1,"z":0},{"name":"Rock_Sandstone_Cobble","x":-2,"y":0,"z":1},{"name":"Rock_Sandstone_Brick_Stairs","rotation":8,"x":-2,"y":3,"z":1},{"name":"Rock_Sandstone_Brick","x":-2,"y":4,"z":1},{"name":"Rock_Sandstone_Brick","x":-2,"y":5,"z":1},{"name":"Rock_Sandstone_Brick_Ornate","x":-2,"y":6,"z":1},{"name":"Rock_Sandstone_Brick","x":-2,"y":7,"z":1},{"name":"Rock_Sandstone_Brick_Stairs","rotation":1,"x":-2,"y":8,"z":1},{"name":"Rock_Sandstone_Cobble","x":-2,"y":0,"z":3},{"name":"Deco_Pot_Clay_Broken","x":-2,"y":1,"z":3},{"name":"Rock_Sandstone_Brick_Half","rotation":8,"x":-2,"y":3,"z":3},{"name":"Rock_Sandstone_White_Brick_Half","x":-2,"y":4,"z":3},{"name":"Rock_Sandstone_Cobble","x":-2,"y":0,"z":4},{"name":"Furniture_Human_Ruins_Bookshelf","rotation":2,"x":-2,"y":1,"z":4},{"name":"Furniture_Ancient_Barrel","x":-2,"y":2,"z":4},{"name":"Rock_Sandstone_Brick_Half","rotation":8,"x":-2,"y":3,"z":4},{"name":"Rock_Sandstone_White_Brick_Half","x":-2,"y":4,"z":4},{"name":"Rock_Sandstone_White_Cobble_Half","rotation":4,"x":-2,"y":0,"z":5},{"name":"Rock_Sandstone_Brick_Half","rotation":4,"x":-2,"y":1,"z":5},{"name":"Rock_Sandstone_Brick_Half","rotation":4,"x":-2,"y":2,"z":5},{"name":"Rock_Sandstone_Brick_Half","rotation":4,"x":-2,"y":3,"z":5},{"name":"Rock_Sandstone_White_Brick_Half","rotation":6,"x":-1,"y":0,"z":-4},{"name":"Rock_Sandstone_Cobble","x":-1,"y":0,"z":-3},{"name":"Rock_Sandstone_White_Brick","x":-1,"y":1,"z":-3},{"name":"Rock_Sandstone_Cobble","x":-1,"y":0,"z":-2},{"name":"Rock_Sandstone_White_Brick","x":-1,"y":1,"z":-2},{"name":"Wood_Drywood_Beam","x":-1,"y":2,"z":-2},{"name":"Rock_Sandstone_Cobble","x":-1,"y":0,"z":-1},{"name":"Rubble_Sandstone_White","support":15,"x":-1,"y":1,"z":-1},{"name":"Rock_Sandstone_Cobble","x":-1,"y":0,"z":0},{"name":"Rock_Sandstone_Cobble","x":-1,"y":0,"z":1},{"name":"Rock_Sandstone_Brick","x":-1,"y":1,"z":1},{"name":"Rock_Sandstone_Brick","x":-1,"y":2,"z":1},{"name":"Rock_Sandstone_Brick","x":-1,"y":3,"z":1},{"name":"Rock_Sandstone_Brick","x":-1,"y":4,"z":1},{"name":"Rock_Sandstone_Brick","x":-1,"y":5,"z":1},{"name":"Rock_Sandstone_Brick_Ornate","x":-1,"y":6,"z":1},{"name":"Rock_Sandstone_Brick","x":-1,"y":7,"z":1},{"name":"Rock_Sandstone_Brick_Stairs","rotation":3,"x":-1,"y":8,"z":1},{"name":"Rock_Sandstone_White_Brick","x":-1,"y":0,"z":3},{"name":"Rock_Sandstone_Brick_Half","rotation":5,"x":-1,"y":1,"z":3},{"name":"Rock_Sandstone_Brick_Half","rotation":5,"x":-1,"y":2,"z":3},{"name":"Rock_Sandstone_Brick_Half","rotation":5,"x":-1,"y":3,"z":3},{"name":"Rock_Sandstone_White_Cobble","x":-1,"y":0,"z":4},{"name":"Rock_Sandstone_Brick_Half","rotation":5,"x":-1,"y":1,"z":4},{"name":"Rock_Sandstone_Brick_Half","rotation":5,"x":-1,"y":2,"z":4},{"name":"Rock_Sandstone_Brick_Half","rotation":5,"x":-1,"y":3,"z":4},{"name":"Rubble_Sandstone","support":15,"x":-1,"y":0,"z":5},{"name":"Rock_Sandstone_White_Brick_Half","rotation":6,"x":0,"y":0,"z":-4},{"name":"Rock_Sandstone_Cobble","x":0,"y":0,"z":-3},{"name":"Rock_Sandstone_White_Brick","x":0,"y":1,"z":-3},{"name":"Rock_Sandstone_Cobble","x":0,"y":0,"z":-2},{"name":"Rock_Sandstone_White_Brick","x":0,"y":1,"z":-2},{"name":"Rock_Sandstone_White_Brick","x":0,"y":2,"z":-2},{"name":"Rock_Sandstone_White_Brick","x":0,"y":3,"z":-2},{"name":"Rock_Sandstone_Cobble","x":0,"y":0,"z":-1},{"name":"Rock_Sandstone_Cobble","x":0,"y":0,"z":0},{"name":"Rock_Sandstone_Brick","x":0,"y":7,"z":1},{"name":"Rock_Sandstone_Brick","x":0,"y":8,"z":1},{"name":"Rock_Sandstone_Brick","x":0,"y":7,"z":3},{"name":"Rock_Sandstone_Brick_Stairs","rotation":2,"x":0,"y":8,"z":3},{"name":"Rock_Sandstone_Cobble","x":0,"y":0,"z":4},{"name":"Rock_Sandstone_Brick_Stairs","rotation":3,"x":0,"y":1,"z":4},{"name":"Rock_Sandstone_Brick_Stairs","x":0,"y":2,"z":4},{"name":"Rock_Sandstone_Brick_Stairs","rotation":11,"x":0,"y":3,"z":4},{"name":"Rock_Sandstone_Cobble_Stairs","rotation":9,"x":0,"y":4,"z":4},{"name":"Rock_Sandstone_Brick_Stairs","rotation":10,"x":0,"y":5,"z":4},{"name":"Rock_Sandstone_Brick_Ornate","x":0,"y":6,"z":4},{"name":"Rock_Sandstone_Brick","x":0,"y":7,"z":4},{"name":"Rock_Sandstone_Brick","x":0,"y":8,"z":4},{"name":"Rock_Sandstone_White_Cobble_Half","rotation":4,"x":0,"y":0,"z":5},{"name":"Rock_Sandstone_White_Brick_Half","rotation":6,"x":1,"y":0,"z":-4},{"name":"Rock_Sandstone_Cobble","x":1,"y":0,"z":-2},{"name":"Rock_Sandstone_Brick","x":1,"y":1,"z":-2},{"name":"Rock_Sandstone_Cobble","x":1,"y":0,"z":-1},{"name":"Rock_Sandstone_Cobble","x":1,"y":0,"z":0},{"name":"Rock_Sandstone_Cobble","x":1,"y":0,"z":1},{"components":{"Components":{"BenchBlock":{"TierLevel":1,"UpgradeItems":[]},"PlacedByInteraction":{"WhoPlacedUuid":{"$binary":"HCpUQzdeSaiDYHpoRePv+w==","$type":"04"}}}},"name":"Bench_Cooking","rotation":1,"x":1,"y":1,"z":1},{"filler":1024,"name":"Bench_Cooking","rotation":1,"x":1,"y":2,"z":1},{"name":"Rock_Sandstone_Cobble","x":1,"y":0,"z":3},{"name":"Rock_Sandstone_White_Brick","x":1,"y":1,"z":3},{"name":"Rock_Sandstone_White_Brick","x":1,"y":2,"z":3},{"name":"Rock_Sandstone_White_Brick","x":1,"y":3,"z":3},{"name":"Rock_Sandstone_White_Brick","x":1,"y":4,"z":3},{"name":"Rock_Sandstone_White_Brick","x":1,"y":5,"z":3},{"name":"Rock_Sandstone_Brick_Ornate","x":1,"y":6,"z":3},{"name":"Rock_Sandstone_White_Brick","x":1,"y":7,"z":3},{"name":"Rock_Sandstone_Cobble","x":1,"y":0,"z":4},{"name":"Rock_Sandstone_White_Brick","x":1,"y":1,"z":4},{"name":"Rubble_Sandstone","support":15,"x":1,"y":2,"z":4},{"name":"Rock_Sandstone_White_Cobble_Half","rotation":4,"x":1,"y":0,"z":5},{"name":"*Rock_Sandstone_Brick_Stairs_State_Definitions_Corner_Right","rotation":11,"x":2,"y":3,"z":-4},{"name":"Rock_Sandstone_Cobble_Stairs","rotation":2,"x":2,"y":0,"z":-3},{"name":"Rock_Sandstone_Cobble","x":2,"y":0,"z":-2},{"name":"Rock_Sandstone_Cobble","x":2,"y":0,"z":-1},{"name":"Rock_Sandstone_Cobble","x":2,"y":0,"z":0},{"name":"Rock_Sandstone_Cobble","x":2,"y":0,"z":1},{"name":"Rock_Sandstone_Cobble","x":2,"y":0,"z":2},{"name":"Deco_Pot_Clay_Broken","x":2,"y":1,"z":2},{"name":"Rock_Sandstone_Cobble","x":2,"y":0,"z":4},{"name":"Rock_Sandstone_White_Brick","x":2,"y":1,"z":4},{"name":"Rock_Sandstone_White_Cobble_Half","rotation":4,"x":2,"y":0,"z":5},{"name":"*Rock_Sandstone_Brick_Stairs_State_Definitions_Corner_Left","rotation":9,"x":3,"y":3,"z":-4},{"name":"Rock_Sandstone_Cobble_Stairs","rotation":2,"x":3,"y":0,"z":-3},{"name":"Rock_Sandstone_Brick_Stairs","rotation":9,"x":3,"y":3,"z":-3},{"name":"Rock_Sandstone_Brick","x":3,"y":4,"z":-3},{"name":"Rock_Sandstone_Brick","x":3,"y":5,"z":-3},{"name":"Rock_Sandstone_Brick_Ornate","x":3,"y":6,"z":-3},{"name":"Rock_Sandstone_Brick","x":3,"y":7,"z":-3},{"name":"Rock_Sandstone_Brick_Stairs","rotation":3,"x":3,"y":8,"z":-3},{"name":"Rock_Sandstone_Cobble","x":3,"y":0,"z":-2},{"name":"Wood_Drywood_Planks","x":3,"y":6,"z":-2},{"name":"Rock_Sandstone_Cobble","x":3,"y":0,"z":-1},{"name":"Wood_Drywood_Planks","x":3,"y":6,"z":-1},{"name":"Rock_Sandstone_Cobble","x":3,"y":0,"z":0},{"name":"Rock_Sandstone_White_Brick_Half","rotation":4,"x":3,"y":0,"z":5},{"name":"Rock_Sandstone_White_Brick_Half","rotation":6,"x":4,"y":0,"z":-4},{"name":"Rock_Sandstone_Brick_Stairs","rotation":8,"x":4,"y":3,"z":-4},{"name":"Rock_Sandstone_Cobble","x":4,"y":0,"z":-3},{"name":"Rock_Sandstone_Brick","x":4,"y":1,"z":-3},{"name":"Rock_Sandstone_Brick","x":4,"y":2,"z":-3},{"name":"Rock_Sandstone_Brick","x":4,"y":3,"z":-3},{"name":"Rock_Sandstone_Brick","x":4,"y":4,"z":-3},{"name":"Rock_Sandstone_Brick","x":4,"y":5,"z":-3},{"name":"Rock_Sandstone_Brick_Ornate","x":4,"y":6,"z":-3},{"name":"Rock_Sandstone_Brick","x":4,"y":7,"z":-3},{"name":"Rock_Sandstone_Brick","x":4,"y":8,"z":-3},{"name":"Rock_Sandstone_Cobble_Stairs","rotation":1,"x":4,"y":0,"z":-2},{"name":"Rock_Sandstone_Brick_Stairs","rotation":10,"x":4,"y":3,"z":-2},{"name":"Rock_Sandstone_Brick","x":4,"y":4,"z":-2},{"name":"Rock_Sandstone_Brick","x":4,"y":5,"z":-2},{"name":"Rock_Sandstone_Brick_Ornate","x":4,"y":6,"z":-2},{"name":"Rock_Sandstone_Brick","x":4,"y":7,"z":-2},{"name":"Rock_Sandstone_Brick_Stairs","x":4,"y":8,"z":-2},{"name":"Rock_Sandstone_Cobble_Stairs","rotation":1,"x":4,"y":0,"z":-1},{"name":"Rock_Sandstone_Brick","x":4,"y":4,"z":-1},{"name":"Rock_Sandstone_Brick","x":4,"y":5,"z":-1},{"name":"Rock_Sandstone_Brick_Ornate","x":4,"y":6,"z":-1},{"name":"Rock_Sandstone_Brick","x":4,"y":7,"z":-1},{"name":"Rock_Sandstone_Cobble_Stairs","rotation":2,"x":4,"y":8,"z":3},{"name":"Rock_Sandstone_Cobble","x":4,"y":0,"z":4},{"name":"Rock_Sandstone_Brick","x":4,"y":1,"z":4},{"name":"Rock_Sandstone_Brick","x":4,"y":2,"z":4},{"name":"Rock_Sandstone_Brick","x":4,"y":3,"z":4},{"name":"Rock_Sandstone_Brick","x":4,"y":4,"z":4},{"name":"Rock_Sandstone_Brick","x":4,"y":5,"z":4},{"name":"Rock_Sandstone_Brick_Ornate","x":4,"y":6,"z":4},{"name":"Rock_Sandstone_Brick","x":4,"y":7,"z":4},{"name":"Rock_Sandstone_Cobble","x":4,"y":8,"z":4},{"name":"Rock_Sandstone_White_Brick_Half","rotation":4,"x":4,"y":0,"z":5},{"name":"Rock_Sandstone_White_Brick_Half","rotation":5,"x":5,"y":0,"z":-3},{"name":"Rock_Sandstone_Brick_Stairs","rotation":11,"x":5,"y":3,"z":-3},{"name":"*Rock_Sandstone_Brick_Stairs_State_Definitions_Corner_Right","rotation":10,"x":5,"y":3,"z":-2},{"name":"Rubble_Sandstone_Medium","support":15,"x":5,"y":0,"z":0},{"name":"Rock_Sandstone_White_Cobble_Half","rotation":5,"x":5,"y":0,"z":2},{"name":"Rock_Sandstone_White_Brick_Half","rotation":5,"x":5,"y":0,"z":3},{"name":"Rock_Sandstone_White_Brick_Half","rotation":5,"x":5,"y":0,"z":4}],"fluids":[{"level":1,"name":"Water_Source","x":-4,"y":0,"z":-3},{"level":1,"name":"Water_Source","x":-4,"y":0,"z":-2},{"level":1,"name":"Water_Source","x":-4,"y":0,"z":-1},{"level":1,"name":"Water_Source","x":-4,"y":0,"z":0},{"level":1,"name":"Water_Source","x":-4,"y":0,"z":1},{"level":1,"name":"Water_Source","x":-4,"y":0,"z":3},{"level":1,"name":"Water_Source","x":-4,"y":1,"z":3},{"level":1,"name":"Water_Source","x":-4,"y":2,"z":3},{"level":1,"name":"Water_Source","x":-4,"y":0,"z":4},{"level":1,"name":"Water_Source","x":-4,"y":1,"z":4},{"level":1,"name":"Water_Source","x":-4,"y":2,"z":4},{"level":1,"name":"Water_Source","x":-4,"y":3,"z":4},{"level":1,"name":"Water_Source","x":-3,"y":0,"z":-4},{"level":1,"name":"Water_Source","x":-3,"y":0,"z":-3},{"level":1,"name":"Water_Source","x":-3,"y":1,"z":-3},{"level":1,"name":"Water_Source","x":-3,"y":2,"z":-3},{"level":1,"name":"Water_Source","x":-3,"y":0,"z":-2},{"level":1,"name":"Water_Source","x":-3,"y":1,"z":-2},{"level":1,"name":"Water_Source","x":-3,"y":2,"z":-2},{"level":1,"name":"Water_Source","x":-3,"y":3,"z":-2},{"level":1,"name":"Water_Source","x":-3,"y":0,"z":-1},{"level":1,"name":"Water_Source","x":-3,"y":1,"z":-1},{"level":1,"name":"Water_Source","x":-3,"y":2,"z":-1},{"level":1,"name":"Water_Source","x":-3,"y":3,"z":-1},{"level":1,"name":"Water_Source","x":-3,"y":0,"z":0},{"level":1,"name":"Water_Source","x":-3,"y":1,"z":0},{"level":1,"name":"Water_Source","x":-3,"y":2,"z":0},{"level":1,"name":"Water_Source","x":-3,"y":3,"z":0},{"level":1,"name":"Water_Source","x":-3,"y":4,"z":0},{"level":1,"name":"Water_Source","x":-3,"y":5,"z":0},{"level":1,"name":"Water_Source","x":-3,"y":6,"z":0},{"level":1,"name":"Water_Source","x":-3,"y":7,"z":0},{"level":1,"name":"Water_Source","x":-3,"y":8,"z":0},{"level":1,"name":"Water_Source","x":-3,"y":8,"z":1},{"level":1,"name":"Water_Source","x":-3,"y":0,"z":4},{"level":1,"name":"Water_Source","x":-3,"y":1,"z":4},{"level":1,"name":"Water_Source","x":-3,"y":2,"z":4},{"level":1,"name":"Water_Source","x":-3,"y":3,"z":4},{"level":1,"name":"Water_Source","x":-3,"y":4,"z":4},{"level":1,"name":"Water_Source","x":-3,"y":0,"z":5},{"level":1,"name":"Water_Source","x":-3,"y":1,"z":5},{"level":1,"name":"Water_Source","x":-3,"y":2,"z":5},{"level":1,"name":"Water_Source","x":-3,"y":3,"z":5},{"level":1,"name":"Water_Source","x":-2,"y":0,"z":-4},{"level":1,"name":"Water_Source","x":-2,"y":0,"z":-3},{"level":1,"name":"Water_Source","x":-2,"y":1,"z":-3},{"level":1,"name":"Water_Source","x":-2,"y":2,"z":-3},{"level":1,"name":"Water_Source","x":-2,"y":0,"z":-2},{"level":1,"name":"Water_Source","x":-2,"y":1,"z":-2},{"level":1,"name":"Water_Source","x":-2,"y":2,"z":-2},{"level":1,"name":"Water_Source","x":-2,"y":0,"z":-1},{"level":1,"name":"Water_Source","x":-2,"y":1,"z":-1},{"level":1,"name":"Water_Source","x":-2,"y":0,"z":0},{"level":1,"name":"Water_Source","x":-2,"y":1,"z":0},{"level":1,"name":"Water_Source","x":-2,"y":0,"z":1},{"level":1,"name":"Water_Source","x":-2,"y":3,"z":1},{"level":1,"name":"Water_Source","x":-2,"y":4,"z":1},{"level":1,"name":"Water_Source","x":-2,"y":5,"z":1},{"level":1,"name":"Water_Source","x":-2,"y":6,"z":1},{"level":1,"name":"Water_Source","x":-2,"y":7,"z":1},{"level":1,"name":"Water_Source","x":-2,"y":8,"z":1},{"level":1,"name":"Water_Source","x":-2,"y":0,"z":3},{"level":1,"name":"Water_Source","x":-2,"y":1,"z":3},{"level":1,"name":"Water_Source","x":-2,"y":3,"z":3},{"level":1,"name":"Water_Source","x":-2,"y":4,"z":3},{"level":1,"name":"Water_Source","x":-2,"y":0,"z":4},{"level":1,"name":"Water_Source","x":-2,"y":1,"z":4},{"level":1,"name":"Water_Source","x":-2,"y":2,"z":4},{"level":1,"name":"Water_Source","x":-2,"y":3,"z":4},{"level":1,"name":"Water_Source","x":-2,"y":4,"z":4},{"level":1,"name":"Water_Source","x":-2,"y":0,"z":5},{"level":1,"name":"Water_Source","x":-2,"y":1,"z":5},{"level":1,"name":"Water_Source","x":-2,"y":2,"z":5},{"level":1,"name":"Water_Source","x":-2,"y":3,"z":5},{"level":1,"name":"Water_Source","x":-1,"y":0,"z":-4},{"level":1,"name":"Water_Source","x":-1,"y":0,"z":-3},{"level":1,"name":"Water_Source","x":-1,"y":1,"z":-3},{"level":1,"name":"Water_Source","x":-1,"y":0,"z":-2},{"level":1,"name":"Water_Source","x":-1,"y":1,"z":-2},{"level":1,"name":"Water_Source","x":-1,"y":2,"z":-2},{"level":1,"name":"Water_Source","x":-1,"y":0,"z":-1},{"level":1,"name":"Water_Source","x":-1,"y":1,"z":-1},{"level":1,"name":"Water_Source","x":-1,"y":0,"z":0},{"level":1,"name":"Water_Source","x":-1,"y":0,"z":1},{"level":1,"name":"Water_Source","x":-1,"y":1,"z":1},{"level":1,"name":"Water_Source","x":-1,"y":2,"z":1},{"level":1,"name":"Water_Source","x":-1,"y":3,"z":1},{"level":1,"name":"Water_Source","x":-1,"y":4,"z":1},{"level":1,"name":"Water_Source","x":-1,"y":5,"z":1},{"level":1,"name":"Water_Source","x":-1,"y":6,"z":1},{"level":1,"name":"Water_Source","x":-1,"y":7,"z":1},{"level":1,"name":"Water_Source","x":-1,"y":8,"z":1},{"level":1,"name":"Water_Source","x":-1,"y":0,"z":3},{"level":1,"name":"Water_Source","x":-1,"y":1,"z":3},{"level":1,"name":"Water_Source","x":-1,"y":2,"z":3},{"level":1,"name":"Water_Source","x":-1,"y":3,"z":3},{"level":1,"name":"Water_Source","x":-1,"y":0,"z":4},{"level":1,"name":"Water_Source","x":-1,"y":1,"z":4},{"level":1,"name":"Water_Source","x":-1,"y":2,"z":4},{"level":1,"name":"Water_Source","x":-1,"y":3,"z":4},{"level":1,"name":"Water_Source","x":-1,"y":0,"z":5},{"level":1,"name":"Water_Source","x":0,"y":0,"z":-4},{"level":1,"name":"Water_Source","x":0,"y":0,"z":-3},{"level":1,"name":"Water_Source","x":0,"y":1,"z":-3},{"level":1,"name":"Water_Source","x":0,"y":0,"z":-2},{"level":1,"name":"Water_Source","x":0,"y":1,"z":-2},{"level":1,"name":"Water_Source","x":0,"y":2,"z":-2},{"level":1,"name":"Water_Source","x":0,"y":3,"z":-2},{"level":1,"name":"Water_Source","x":0,"y":0,"z":-1},{"level":1,"name":"Water_Source","x":0,"y":0,"z":0},{"level":1,"name":"Water_Source","x":0,"y":7,"z":1},{"level":1,"name":"Water_Source","x":0,"y":8,"z":1},{"level":1,"name":"Water_Source","x":0,"y":7,"z":3},{"level":1,"name":"Water_Source","x":0,"y":8,"z":3},{"level":1,"name":"Water_Source","x":0,"y":0,"z":4},{"level":1,"name":"Water_Source","x":0,"y":1,"z":4},{"level":1,"name":"Water_Source","x":0,"y":2,"z":4},{"level":1,"name":"Water_Source","x":0,"y":3,"z":4},{"level":1,"name":"Water_Source","x":0,"y":4,"z":4},{"level":1,"name":"Water_Source","x":0,"y":5,"z":4},{"level":1,"name":"Water_Source","x":0,"y":6,"z":4},{"level":1,"name":"Water_Source","x":0,"y":7,"z":4},{"level":1,"name":"Water_Source","x":0,"y":8,"z":4},{"level":1,"name":"Water_Source","x":0,"y":0,"z":5},{"level":1,"name":"Water_Source","x":1,"y":0,"z":-4},{"level":1,"name":"Water_Source","x":1,"y":0,"z":-2},{"level":1,"name":"Water_Source","x":1,"y":1,"z":-2},{"level":1,"name":"Water_Source","x":1,"y":0,"z":-1},{"level":1,"name":"Water_Source","x":1,"y":0,"z":0},{"level":1,"name":"Water_Source","x":1,"y":0,"z":1},{"level":1,"name":"Water_Source","x":1,"y":1,"z":1},{"level":1,"name":"Water_Source","x":1,"y":2,"z":1},{"level":1,"name":"Water_Source","x":1,"y":0,"z":3},{"level":1,"name":"Water_Source","x":1,"y":1,"z":3},{"level":1,"name":"Water_Source","x":1,"y":2,"z":3},{"level":1,"name":"Water_Source","x":1,"y":3,"z":3},{"level":1,"name":"Water_Source","x":1,"y":4,"z":3},{"level":1,"name":"Water_Source","x":1,"y":5,"z":3},{"level":1,"name":"Water_Source","x":1,"y":6,"z":3},{"level":1,"name":"Water_Source","x":1,"y":7,"z":3},{"level":1,"name":"Water_Source","x":1,"y":0,"z":4},{"level":1,"name":"Water_Source","x":1,"y":1,"z":4},{"level":1,"name":"Water_Source","x":1,"y":2,"z":4},{"level":1,"name":"Water_Source","x":1,"y":0,"z":5},{"level":1,"name":"Water_Source","x":2,"y":3,"z":-4},{"level":1,"name":"Water_Source","x":2,"y":0,"z":-3},{"level":1,"name":"Water_Source","x":2,"y":0,"z":-2},{"level":1,"name":"Water_Source","x":2,"y":0,"z":-1},{"level":1,"name":"Water_Source","x":2,"y":0,"z":0},{"level":1,"name":"Water_Source","x":2,"y":0,"z":1},{"level":1,"name":"Water_Source","x":2,"y":0,"z":2},{"level":1,"name":"Water_Source","x":2,"y":1,"z":2},{"level":1,"name":"Water_Source","x":2,"y":0,"z":4},{"level":1,"name":"Water_Source","x":2,"y":1,"z":4},{"level":1,"name":"Water_Source","x":2,"y":0,"z":5},{"level":1,"name":"Water_Source","x":3,"y":3,"z":-4},{"level":1,"name":"Water_Source","x":3,"y":0,"z":-3},{"level":1,"name":"Water_Source","x":3,"y":3,"z":-3},{"level":1,"name":"Water_Source","x":3,"y":4,"z":-3},{"level":1,"name":"Water_Source","x":3,"y":5,"z":-3},{"level":1,"name":"Water_Source","x":3,"y":6,"z":-3},{"level":1,"name":"Water_Source","x":3,"y":7,"z":-3},{"level":1,"name":"Water_Source","x":3,"y":8,"z":-3},{"level":1,"name":"Water_Source","x":3,"y":0,"z":-2},{"level":1,"name":"Water_Source","x":3,"y":6,"z":-2},{"level":1,"name":"Water_Source","x":3,"y":0,"z":-1},{"level":1,"name":"Water_Source","x":3,"y":6,"z":-1},{"level":1,"name":"Water_Source","x":3,"y":0,"z":0},{"level":1,"name":"Water_Source","x":3,"y":0,"z":5},{"level":1,"name":"Water_Source","x":4,"y":0,"z":-4},{"level":1,"name":"Water_Source","x":4,"y":3,"z":-4},{"level":1,"name":"Water_Source","x":4,"y":0,"z":-3},{"level":1,"name":"Water_Source","x":4,"y":1,"z":-3},{"level":1,"name":"Water_Source","x":4,"y":2,"z":-3},{"level":1,"name":"Water_Source","x":4,"y":3,"z":-3},{"level":1,"name":"Water_Source","x":4,"y":4,"z":-3},{"level":1,"name":"Water_Source","x":4,"y":5,"z":-3},{"level":1,"name":"Water_Source","x":4,"y":6,"z":-3},{"level":1,"name":"Water_Source","x":4,"y":7,"z":-3},{"level":1,"name":"Water_Source","x":4,"y":8,"z":-3},{"level":1,"name":"Water_Source","x":4,"y":0,"z":-2},{"level":1,"name":"Water_Source","x":4,"y":3,"z":-2},{"level":1,"name":"Water_Source","x":4,"y":4,"z":-2},{"level":1,"name":"Water_Source","x":4,"y":5,"z":-2},{"level":1,"name":"Water_Source","x":4,"y":6,"z":-2},{"level":1,"name":"Water_Source","x":4,"y":7,"z":-2},{"level":1,"name":"Water_Source","x":4,"y":8,"z":-2},{"level":1,"name":"Water_Source","x":4,"y":0,"z":-1},{"level":1,"name":"Water_Source","x":4,"y":4,"z":-1},{"level":1,"name":"Water_Source","x":4,"y":5,"z":-1},{"level":1,"name":"Water_Source","x":4,"y":6,"z":-1},{"level":1,"name":"Water_Source","x":4,"y":7,"z":-1},{"level":1,"name":"Water_Source","x":4,"y":8,"z":3},{"level":1,"name":"Water_Source","x":4,"y":0,"z":4},{"level":1,"name":"Water_Source","x":4,"y":1,"z":4},{"level":1,"name":"Water_Source","x":4,"y":2,"z":4},{"level":1,"name":"Water_Source","x":4,"y":3,"z":4},{"level":1,"name":"Water_Source","x":4,"y":4,"z":4},{"level":1,"name":"Water_Source","x":4,"y":5,"z":4},{"level":1,"name":"Water_Source","x":4,"y":6,"z":4},{"level":1,"name":"Water_Source","x":4,"y":7,"z":4},{"level":1,"name":"Water_Source","x":4,"y":8,"z":4},{"level":1,"name":"Water_Source","x":4,"y":0,"z":5},{"level":1,"name":"Water_Source","x":5,"y":0,"z":-3},{"level":1,"name":"Water_Source","x":5,"y":3,"z":-3},{"level":1,"name":"Water_Source","x":5,"y":3,"z":-2},{"level":1,"name":"Water_Source","x":5,"y":0,"z":0},{"level":1,"name":"Water_Source","x":5,"y":0,"z":2},{"level":1,"name":"Water_Source","x":5,"y":0,"z":3},{"level":1,"name":"Water_Source","x":5,"y":0,"z":4}],"version":8}