{"anchorX":0,"anchorY":0,"anchorZ":0,"blockIdVersion":11,"blocks":[{"name":"Rock_Sandstone_White_Brick_Half","rotation":7,"x":-4,"y":0,"z":-3},{"name":"Rock_Sandstone_White_Brick_Half","rotation":7,"x":-4,"y":1,"z":-3},{"name":"Rock_Sandstone_Brick","x":-4,"y":0,"z":-2},{"name":"Rock_Sandstone_Brick_Pillar_Base","x":-4,"y":1,"z":-2},{"name":"Rock_Sandstone_Brick_Pillar_Middle","x":-4,"y":2,"z":-2},{"name":"Rock_Sandstone_Brick_Pillar_Middle","x":-4,"y":3,"z":-2},{"name":"Rock_Sandstone_Brick_Pillar_Middle","x":-4,"y":4,"z":-2},{"name":"Rock_Sandstone_Brick","x":-4,"y":0,"z":3},{"name":"Rock_Sandstone_Brick_Pillar_Base","x":-4,"y":1,"z":3},{"name":"Rock_Sandstone_Brick_Pillar_Middle","x":-4,"y":2,"z":3},{"name":"Rock_Sandstone_Brick_Pillar_Middle","x":-4,"y":3,"z":3},{"name":"Rock_Sandstone_Brick_Pillar_Middle","x":-4,"y":4,"z":3},{"name":"Rock_Sandstone_Brick_Pillar_Base","rotation":8,"x":-4,"y":5,"z":3},{"name":"Rock_Sandstone_Brick_Stairs","rotation":3,"x":-4,"y":6,"z":3},{"name":"Rock_Sandstone_White_Brick_Half","rotation":7,"x":-4,"y":0,"z":4},{"name":"Rock_Sandstone_White_Brick_Half","rotation":7,"x":-4,"y":1,"z":4},{"name":"Rock_Sandstone_White_Brick_Half","rotation":6,"x":-3,"y":0,"z":-4},{"name":"Rock_Sandstone_White_Brick_Half","rotation":6,"x":-3,"y":1,"z":-4},{"name":"Rock_Sandstone_White_Brick","x":-3,"y":0,"z":-3},{"name":"Rock_Sandstone_White_Brick","x":-3,"y":1,"z":-3},{"name":"Rock_Sandstone_White_Brick","x":-3,"y":2,"z":-3},{"name":"Rock_Sandstone_White_Brick","x":-3,"y":3,"z":-3},{"name":"Rock_Sandstone_White_Brick","x":-3,"y":4,"z":-3},{"name":"Rock_Sandstone_Brick","x":-3,"y":5,"z":-3},{"name":"Rubble_Sandstone","support":15,"x":-3,"y":6,"z":-3},{"name":"Rock_Sandstone_Cobble","x":-3,"y":0,"z":-2},{"name":"Rock_Sandstone_White_Brick","x":-3,"y":1,"z":-2},{"name":"Rock_Sandstone_White_Brick","x":-3,"y":2,"z":-2},{"name":"Rock_Sandstone_White_Brick","x":-3,"y":3,"z":-2},{"name":"Rock_Sandstone_Brick_Smooth","x":-3,"y":4,"z":-2},{"name":"Rock_Sandstone_Brick_Smooth","x":-3,"y":5,"z":-2},{"name":"Rubble_Sandstone_Medium","support":15,"x":-3,"y":6,"z":-2},{"name":"Rock_Sandstone_Cobble_Stairs","rotation":3,"x":-3,"y":0,"z":-1},{"name":"Rock_Sandstone_Brick_Half","rotation":8,"x":-3,"y":5,"z":-1},{"name":"Rock_Sandstone_Brick_Ornate","x":-3,"y":6,"z":-1},{"name":"Rock_Sandstone_White_Cobble","x":-3,"y":7,"z":-1},{"name":"Rock_Sandstone_Cobble_Stairs","rotation":3,"x":-3,"y":0,"z":0},{"name":"Rock_Sandstone_Brick_Half","rotation":8,"x":-3,"y":5,"z":0},{"name":"Rock_Sandstone_Brick_Ornate","x":-3,"y":6,"z":0},{"name":"Rock_Sandstone_White_Cobble","x":-3,"y":7,"z":0},{"name":"Rock_Sandstone_Cobble_Stairs","rotation":3,"x":-3,"y":0,"z":1},{"name":"Rock_Sandstone_Brick_Half","rotation":8,"x":-3,"y":5,"z":1},{"name":"Rock_Sandstone_Brick_Ornate","x":-3,"y":6,"z":1},{"name":"Rock_Sandstone_White_Brick","x":-3,"y":7,"z":1},{"name":"Rock_Sandstone_Cobble_Stairs","rotation":3,"x":-3,"y":0,"z":2},{"name":"Rock_Sandstone_Brick_Half","rotation":8,"x":-3,"y":5,"z":2},{"name":"Rock_Sandstone_Brick_Ornate","x":-3,"y":6,"z":2},{"name":"Rock_Sandstone_White_Brick","x":-3,"y":7,"z":2},{"name":"Rock_Sandstone_Cobble","x":-3,"y":0,"z":3},{"name":"Rock_Sandstone_White_Brick","x":-3,"y":1,"z":3},{"name":"Rock_Sandstone_White_Brick","x":-3,"y":2,"z":3},{"name":"Rock_Sandstone_White_Brick","x":-3,"y":3,"z":3},{"name":"Rock_Sandstone_Brick_Smooth","x":-3,"y":4,"z":3},{"name":"Rock_Sandstone_Brick_Smooth","x":-3,"y":5,"z":3},{"name":"Rock_Sandstone_Brick_Ornate","x":-3,"y":6,"z":3},{"name":"Rock_Sandstone_Brick","x":-3,"y":7,"z":3},{"name":"Rock_Sandstone_White_Brick","x":-3,"y":0,"z":4},{"name":"Rock_Sandstone_White_Brick","x":-3,"y":1,"z":4},{"name":"Rock_Sandstone_White_Brick","x":-3,"y":2,"z":4},{"name":"Rock_Sandstone_White_Brick","x":-3,"y":3,"z":4},{"name":"Rock_Sandstone_White_Brick","x":-3,"y":4,"z":4},{"name":"Rock_Sandstone_Brick","x":-3,"y":5,"z":4},{"name":"Rock_Sandstone_Brick_Ornate","x":-3,"y":6,"z":4},{"name":"Rock_Sandstone_Brick","x":-3,"y":7,"z":4},{"name":"Rock_Sandstone_White_Brick_Half","rotation":4,"x":-3,"y":0,"z":5},{"name":"Rock_Sandstone_White_Brick_Half","rotation":4,"x":-3,"y":1,"z":5},{"name":"Rock_Sandstone_Brick","x":-2,"y":0,"z":-4},{"name":"Rock_Sandstone_Brick_Pillar_Base","x":-2,"y":1,"z":-4},{"name":"Rock_Sandstone_Cobble","x":-2,"y":0,"z":-3},{"name":"Rock_Sandstone_White_Brick","x":-2,"y":1,"z":-3},{"name":"Rock_Sandstone_White_Brick","x":-2,"y":2,"z":-3},{"name":"Rock_Sandstone_White_Brick","x":-2,"y":3,"z":-3},{"name":"Rock_Sandstone_Brick_Smooth","x":-2,"y":4,"z":-3},{"name":"Rock_Sandstone_Brick_Smooth","x":-2,"y":5,"z":-3},{"name":"Rock_Sandstone_Brick_Ornate","x":-2,"y":6,"z":-3},{"name":"Rock_Sandstone_Brick","x":-2,"y":7,"z":-3},{"name":"Rock_Sandstone_Cobble","x":-2,"y":0,"z":-2},{"name":"Rock_Sandstone_Brick_Ornate","x":-2,"y":4,"z":-2},{"name":"Rock_Sandstone_Brick_Half","x":-2,"y":5,"z":-2},{"name":"Rock_Sandstone_Cobble","x":-2,"y":0,"z":-1},{"name":"Rock_Sandstone_Brick_Half","rotation":8,"x":-2,"y":4,"z":-1},{"name":"Rock_Sandstone_Brick","x":-2,"y":5,"z":-1},{"name":"Rock_Sandstone_Cobble","x":-2,"y":0,"z":0},{"name":"Cloth_Roof_Leather_Flap","rotation":1,"x":-2,"y":3,"z":0},{"name":"Cloth_Roof_Leather_Vertical","rotation":1,"x":-2,"y":4,"z":0},{"name":"Rock_Sandstone_Brick","x":-2,"y":5,"z":0},{"name":"Rock_Sandstone_Cobble","x":-2,"y":0,"z":1},{"name":"Rock_Sandstone_Brick","x":-2,"y":5,"z":1},{"name":"Rock_Sandstone_Cobble","x":-2,"y":0,"z":2},{"name":"Rock_Sandstone_Brick_Half","rotation":8,"x":-2,"y":4,"z":2},{"name":"Rock_Sandstone_Brick","x":-2,"y":5,"z":2},{"name":"Rock_Sandstone_Cobble","x":-2,"y":0,"z":3},{"name":"Rock_Sandstone_Brick_Ornate","x":-2,"y":4,"z":3},{"name":"Rock_Sandstone_Brick_Half","x":-2,"y":5,"z":3},{"name":"Rock_Sandstone_Cobble","x":-2,"y":0,"z":4},{"name":"Rock_Sandstone_White_Brick","x":-2,"y":1,"z":4},{"name":"Rock_Sandstone_White_Brick","x":-2,"y":2,"z":4},{"name":"Rock_Sandstone_White_Brick","x":-2,"y":3,"z":4},{"name":"Rock_Sandstone_Brick_Smooth","x":-2,"y":4,"z":4},{"name":"Rock_Sandstone_Brick_Smooth","x":-2,"y":5,"z":4},{"name":"Rock_Sandstone_Brick_Ornate","x":-2,"y":6,"z":4},{"name":"Rock_Sandstone_Brick","x":-2,"y":7,"z":4},{"name":"Rubble_Sandstone_Medium","support":15,"x":-2,"y":8,"z":4},{"name":"Rock_Sandstone_Brick","x":-2,"y":0,"z":5},{"name":"Rock_Sandstone_Brick_Pillar_Base","x":-2,"y":1,"z":5},{"name":"Rock_Sandstone_Brick_Pillar_Middle","x":-2,"y":2,"z":5},{"name":"Rock_Sandstone_Brick_Pillar_Middle","x":-2,"y":3,"z":5},{"name":"Rock_Sandstone_Brick_Pillar_Middle","x":-2,"y":4,"z":5},{"name":"Rock_Sandstone_Brick_Pillar_Base","rotation":8,"x":-2,"y":5,"z":5},{"name":"Rock_Sandstone_Brick_Stairs","x":-2,"y":6,"z":5},{"name":"Rubble_Sandstone","support":15,"x":-1,"y":0,"z":-4},{"name":"Rock_Sandstone_Cobble_Stairs","rotation":2,"x":-1,"y":0,"z":-3},{"name":"Rock_Sandstone_Brick_Half","rotation":8,"x":-1,"y":5,"z":-3},{"name":"Rock_Sandstone_Brick_Ornate","x":-1,"y":6,"z":-3},{"name":"Rock_Sandstone_White_Brick","x":-1,"y":7,"z":-3},{"name":"Rock_Sandstone_White_Cobble_Half","x":-1,"y":8,"z":-3},{"name":"Rock_Sandstone_Cobble","x":-1,"y":0,"z":-2},{"name":"Rock_Sandstone_Brick_Half","rotation":8,"x":-1,"y":4,"z":-2},{"name":"Rock_Sandstone_Brick","x":-1,"y":5,"z":-2},{"name":"Rock_Sandstone_Cobble","x":-1,"y":0,"z":-1},{"name":"Rock_Sandstone_Cobble","x":-1,"y":0,"z":0},{"name":"Rock_Sandstone_Cobble","x":-1,"y":0,"z":1},{"name":"Rock_Sandstone_Cobble","x":-1,"y":0,"z":2},{"name":"Rock_Sandstone_Cobble","x":-1,"y":0,"z":3},{"name":"Rock_Sandstone_Cobble","x":-1,"y":0,"z":4},{"name":"Rock_Sandstone_White_Brick","x":-1,"y":1,"z":4},{"name":"Rock_Sandstone_White_Brick","x":-1,"y":2,"z":4},{"name":"Rock_Sandstone_White_Brick","x":-1,"y":3,"z":4},{"name":"Rock_Sandstone_White_Brick","x":-1,"y":4,"z":4},{"name":"Rock_Sandstone_White_Brick","x":-1,"y":5,"z":4},{"name":"Rock_Sandstone_Brick_Ornate","x":-1,"y":6,"z":4},{"name":"Rock_Sandstone_White_Brick","x":-1,"y":7,"z":4},{"name":"Rock_Sandstone_Brick","x":-1,"y":0,"z":5},{"name":"Rubble_Sandstone","support":15,"x":0,"y":0,"z":-3},{"name":"Cloth_Roof_Leather_Flap","rotation":2,"x":0,"y":4,"z":-3},{"name":"Rock_Sandstone_Brick_Half","rotation":8,"x":0,"y":5,"z":-3},{"name":"Rock_Sandstone_Brick_Ornate","x":0,"y":6,"z":-3},{"name":"Rock_Sandstone_White_Cobble","x":0,"y":7,"z":-3},{"name":"Rubble_Sandstone_White","support":15,"x":0,"y":8,"z":-3},{"name":"Rock_Sandstone_Cobble","x":0,"y":0,"z":-2},{"name":"Rock_Sandstone_Brick","x":0,"y":5,"z":-2},{"name":"Rock_Sandstone_Cobble","x":0,"y":0,"z":-1},{"name":"Wood_Sticks","support":15,"x":0,"y":1,"z":-1},{"name":"Rock_Sandstone_Cobble","x":0,"y":0,"z":0},{"name":"Rock_Sandstone_Cobble","x":0,"y":0,"z":1},{"name":"Rock_Sandstone_Cobble","x":0,"y":0,"z":2},{"name":"Rock_Sandstone_Cobble","x":0,"y":0,"z":3},{"name":"Rock_Sandstone_Cobble","x":0,"y":0,"z":4},{"name":"Rock_Sandstone_White_Brick","x":0,"y":1,"z":4},{"name":"Rock_Sandstone_Brick_Ornate","x":0,"y":6,"z":4},{"name":"Rock_Sandstone_White_Brick","x":0,"y":7,"z":4},{"name":"Rock_Sandstone_Brick","x":0,"y":0,"z":5},{"name":"Rock_Sandstone_Brick_Pillar_Middle","rotation":5,"x":1,"y":0,"z":-4},{"name":"Rock_Sandstone_Cobble","x":1,"y":0,"z":-2},{"name":"Rock_Sandstone_Cobble","x":1,"y":0,"z":3},{"name":"Rock_Sandstone_Cobble","x":1,"y":0,"z":4},{"name":"Rock_Sandstone_White_Brick","x":1,"y":1,"z":4},{"name":"Rock_Sandstone_Brick_Pillar_Middle","rotation":5,"x":2,"y":0,"z":-4},{"name":"Rubble_Sandstone","support":15,"x":2,"y":0,"z":-1},{"name":"Rubble_Sandstone","support":15,"x":2,"y":0,"z":1},{"name":"Rock_Sandstone_Brick_Pillar_Middle","rotation":5,"x":3,"y":0,"z":-4},{"name":"Rubble_Sandstone","support":15,"x":4,"y":0,"z":-4},{"name":"Rock_Sandstone_Brick_Pillar_Middle","rotation":5,"x":5,"y":0,"z":-4},{"name":"Rubble_Sandstone","support":15,"x":5,"y":0,"z":-2},{"name":"Rubble_Sandstone","support":15,"x":5,"y":0,"z":0},{"name":"Rubble_Sandstone","support":15,"x":5,"y":0,"z":4}],"fluids":[{"level":1,"name":"Water_Source","x":-4,"y":0,"z":-3},{"level":1,"name":"Water_Source","x":-4,"y":1,"z":-3},{"level":1,"name":"Water_Source","x":-4,"y":0,"z":-2},{"level":1,"name":"Water_Source","x":-4,"y":1,"z":-2},{"level":1,"name":"Water_Source","x":-4,"y":2,"z":-2},{"level":1,"name":"Water_Source","x":-4,"y":3,"z":-2},{"level":1,"name":"Water_Source","x":-4,"y":4,"z":-2},{"level":1,"name":"Water_Source","x":-4,"y":0,"z":3},{"level":1,"name":"Water_Source","x":-4,"y":1,"z":3},{"level":1,"name":"Water_Source","x":-4,"y":2,"z":3},{"level":1,"name":"Water_Source","x":-4,"y":3,"z":3},{"level":1,"name":"Water_Source","x":-4,"y":4,"z":3},{"level":1,"name":"Water_Source","x":-4,"y":5,"z":3},{"level":1,"name":"Water_Source","x":-4,"y":6,"z":3},{"level":1,"name":"Water_Source","x":-4,"y":0,"z":4},{"level":1,"name":"Water_Source","x":-4,"y":1,"z":4},{"level":1,"name":"Water_Source","x":-3,"y":0,"z":-4},{"level":1,"name":"Water_Source","x":-3,"y":1,"z":-4},{"level":1,"name":"Water_Source","x":-3,"y":0,"z":-3},{"level":1,"name":"Water_Source","x":-3,"y":1,"z":-3},{"level":1,"name":"Water_Source","x":-3,"y":2,"z":-3},{"level":1,"name":"Water_Source","x":-3,"y":3,"z":-3},{"level":1,"name":"Water_Source","x":-3,"y":4,"z":-3},{"level":1,"name":"Water_Source","x":-3,"y":5,"z":-3},{"level":1,"name":"Water_Source","x":-3,"y":6,"z":-3},{"level":1,"name":"Water_Source","x":-3,"y":0,"z":-2},{"level":1,"name":"Water_Source","x":-3,"y":1,"z":-2},{"level":1,"name":"Water_Source","x":-3,"y":2,"z":-2},{"level":1,"name":"Water_Source","x":-3,"y":3,"z":-2},{"level":1,"name":"Water_Source","x":-3,"y":4,"z":-2},{"level":1,"name":"Water_Source","x":-3,"y":5,"z":-2},{"level":1,"name":"Water_Source","x":-3,"y":6,"z":-2},{"level":1,"name":"Water_Source","x":-3,"y":0,"z":-1},{"level":1,"name":"Water_Source","x":-3,"y":5,"z":-1},{"level":1,"name":"Water_Source","x":-3,"y":6,"z":-1},{"level":1,"name":"Water_Source","x":-3,"y":7,"z":-1},{"level":1,"name":"Water_Source","x":-3,"y":0,"z":0},{"level":1,"name":"Water_Source","x":-3,"y":5,"z":0},{"level":1,"name":"Water_Source","x":-3,"y":6,"z":0},{"level":1,"name":"Water_Source","x":-3,"y":7,"z":0},{"level":1,"name":"Water_Source","x":-3,"y":0,"z":1},{"level":1,"name":"Water_Source","x":-3,"y":5,"z":1},{"level":1,"name":"Water_Source","x":-3,"y":6,"z":1},{"level":1,"name":"Water_Source","x":-3,"y":7,"z":1},{"level":1,"name":"Water_Source","x":-3,"y":0,"z":2},{"level":1,"name":"Water_Source","x":-3,"y":5,"z":2},{"level":1,"name":"Water_Source","x":-3,"y":6,"z":2},{"level":1,"name":"Water_Source","x":-3,"y":7,"z":2},{"level":1,"name":"Water_Source","x":-3,"y":0,"z":3},{"level":1,"name":"Water_Source","x":-3,"y":1,"z":3},{"level":1,"name":"Water_Source","x":-3,"y":2,"z":3},{"level":1,"name":"Water_Source","x":-3,"y":3,"z":3},{"level":1,"name":"Water_Source","x":-3,"y":4,"z":3},{"level":1,"name":"Water_Source","x":-3,"y":5,"z":3},{"level":1,"name":"Water_Source","x":-3,"y":6,"z":3},{"level":1,"name":"Water_Source","x":-3,"y":7,"z":3},{"level":1,"name":"Water_Source","x":-3,"y":0,"z":4},{"level":1,"name":"Water_Source","x":-3,"y":1,"z":4},{"level":1,"name":"Water_Source","x":-3,"y":2,"z":4},{"level":1,"name":"Water_Source","x":-3,"y":3,"z":4},{"level":1,"name":"Water_Source","x":-3,"y":4,"z":4},{"level":1,"name":"Water_Source","x":-3,"y":5,"z":4},{"level":1,"name":"Water_Source","x":-3,"y":6,"z":4},{"level":1,"name":"Water_Source","x":-3,"y":7,"z":4},{"level":1,"name":"Water_Source","x":-3,"y":0,"z":5},{"level":1,"name":"Water_Source","x":-3,"y":1,"z":5},{"level":1,"name":"Water_Source","x":-2,"y":0,"z":-4},{"level":1,"name":"Water_Source","x":-2,"y":1,"z":-4},{"level":1,"name":"Water_Source","x":-2,"y":0,"z":-3},{"level":1,"name":"Water_Source","x":-2,"y":1,"z":-3},{"level":1,"name":"Water_Source","x":-2,"y":2,"z":-3},{"level":1,"name":"Water_Source","x":-2,"y":3,"z":-3},{"level":1,"name":"Water_Source","x":-2,"y":4,"z":-3},{"level":1,"name":"Water_Source","x":-2,"y":5,"z":-3},{"level":1,"name":"Water_Source","x":-2,"y":6,"z":-3},{"level":1,"name":"Water_Source","x":-2,"y":7,"z":-3},{"level":1,"name":"Water_Source","x":-2,"y":0,"z":-2},{"level":1,"name":"Water_Source","x":-2,"y":4,"z":-2},{"level":1,"name":"Water_Source","x":-2,"y":5,"z":-2},{"level":1,"name":"Water_Source","x":-2,"y":0,"z":-1},{"level":1,"name":"Water_Source","x":-2,"y":4,"z":-1},{"level":1,"name":"Water_Source","x":-2,"y":5,"z":-1},{"level":1,"name":"Water_Source","x":-2,"y":0,"z":0},{"level":1,"name":"Water_Source","x":-2,"y":3,"z":0},{"level":1,"name":"Water_Source","x":-2,"y":4,"z":0},{"level":1,"name":"Water_Source","x":-2,"y":5,"z":0},{"level":1,"name":"Water_Source","x":-2,"y":0,"z":1},{"level":1,"name":"Water_Source","x":-2,"y":5,"z":1},{"level":1,"name":"Water_Source","x":-2,"y":0,"z":2},{"level":1,"name":"Water_Source","x":-2,"y":4,"z":2},{"level":1,"name":"Water_Source","x":-2,"y":5,"z":2},{"level":1,"name":"Water_Source","x":-2,"y":0,"z":3},{"level":1,"name":"Water_Source","x":-2,"y":4,"z":3},{"level":1,"name":"Water_Source","x":-2,"y":5,"z":3},{"level":1,"name":"Water_Source","x":-2,"y":0,"z":4},{"level":1,"name":"Water_Source","x":-2,"y":1,"z":4},{"level":1,"name":"Water_Source","x":-2,"y":2,"z":4},{"level":1,"name":"Water_Source","x":-2,"y":3,"z":4},{"level":1,"name":"Water_Source","x":-2,"y":4,"z":4},{"level":1,"name":"Water_Source","x":-2,"y":5,"z":4},{"level":1,"name":"Water_Source","x":-2,"y":6,"z":4},{"level":1,"name":"Water_Source","x":-2,"y":7,"z":4},{"level":1,"name":"Water_Source","x":-2,"y":8,"z":4},{"level":1,"name":"Water_Source","x":-2,"y":0,"z":5},{"level":1,"name":"Water_Source","x":-2,"y":1,"z":5},{"level":1,"name":"Water_Source","x":-2,"y":2,"z":5},{"level":1,"name":"Water_Source","x":-2,"y":3,"z":5},{"level":1,"name":"Water_Source","x":-2,"y":4,"z":5},{"level":1,"name":"Water_Source","x":-2,"y":5,"z":5},{"level":1,"name":"Water_Source","x":-2,"y":6,"z":5},{"level":1,"name":"Water_Source","x":-1,"y":0,"z":-4},{"level":1,"name":"Water_Source","x":-1,"y":0,"z":-3},{"level":1,"name":"Water_Source","x":-1,"y":5,"z":-3},{"level":1,"name":"Water_Source","x":-1,"y":6,"z":-3},{"level":1,"name":"Water_Source","x":-1,"y":7,"z":-3},{"level":1,"name":"Water_Source","x":-1,"y":8,"z":-3},{"level":1,"name":"Water_Source","x":-1,"y":0,"z":-2},{"level":1,"name":"Water_Source","x":-1,"y":4,"z":-2},{"level":1,"name":"Water_Source","x":-1,"y":5,"z":-2},{"level":1,"name":"Water_Source","x":-1,"y":0,"z":-1},{"level":1,"name":"Water_Source","x":-1,"y":0,"z":0},{"level":1,"name":"Water_Source","x":-1,"y":0,"z":1},{"level":1,"name":"Water_Source","x":-1,"y":0,"z":2},{"level":1,"name":"Water_Source","x":-1,"y":0,"z":3},{"level":1,"name":"Water_Source","x":-1,"y":0,"z":4},{"level":1,"name":"Water_Source","x":-1,"y":1,"z":4},{"level":1,"name":"Water_Source","x":-1,"y":2,"z":4},{"level":1,"name":"Water_Source","x":-1,"y":3,"z":4},{"level":1,"name":"Water_Source","x":-1,"y":4,"z":4},{"level":1,"name":"Water_Source","x":-1,"y":5,"z":4},{"level":1,"name":"Water_Source","x":-1,"y":6,"z":4},{"level":1,"name":"Water_Source","x":-1,"y":7,"z":4},{"level":1,"name":"Water_Source","x":-1,"y":0,"z":5},{"level":1,"name":"Water_Source","x":0,"y":0,"z":-3},{"level":1,"name":"Water_Source","x":0,"y":4,"z":-3},{"level":1,"name":"Water_Source","x":0,"y":5,"z":-3},{"level":1,"name":"Water_Source","x":0,"y":6,"z":-3},{"level":1,"name":"Water_Source","x":0,"y":7,"z":-3},{"level":1,"name":"Water_Source","x":0,"y":8,"z":-3},{"level":1,"name":"Water_Source","x":0,"y":0,"z":-2},{"level":1,"name":"Water_Source","x":0,"y":5,"z":-2},{"level":1,"name":"Water_Source","x":0,"y":0,"z":-1},{"level":1,"name":"Water_Source","x":0,"y":1,"z":-1},{"level":1,"name":"Water_Source","x":0,"y":0,"z":0},{"level":1,"name":"Water_Source","x":0,"y":0,"z":1},{"level":1,"name":"Water_Source","x":0,"y":0,"z":2},{"level":1,"name":"Water_Source","x":0,"y":0,"z":3},{"level":1,"name":"Water_Source","x":0,"y":0,"z":4},{"level":1,"name":"Water_Source","x":0,"y":1,"z":4},{"level":1,"name":"Water_Source","x":0,"y":6,"z":4},{"level":1,"name":"Water_Source","x":0,"y":7,"z":4},{"level":1,"name":"Water_Source","x":0,"y":0,"z":5},{"level":1,"name":"Water_Source","x":1,"y":0,"z":-4},{"level":1,"name":"Water_Source","x":1,"y":0,"z":-2},{"level":1,"name":"Water_Source","x":1,"y":0,"z":3},{"level":1,"name":"Water_Source","x":1,"y":0,"z":4},{"level":1,"name":"Water_Source","x":1,"y":1,"z":4},{"level":1,"name":"Water_Source","x":2,"y":0,"z":-4},{"level":1,"name":"Water_Source","x":2,"y":0,"z":-1},{"level":1,"name":"Water_Source","x":2,"y":0,"z":1},{"level":1,"name":"Water_Source","x":3,"y":0,"z":-4},{"level":1,"name":"Water_Source","x":4,"y":0,"z":-4},{"level":1,"name":"Water_Source","x":5,"y":0,"z":-4},{"level":1,"name":"Water_Source","x":5,"y":0,"z":-2},{"level":1,"name":"Water_Source","x":5,"y":0,"z":0},{"level":1,"name":"Water_Source","x":5,"y":0,"z":4}],"version":8}