{"anchorX":0,"anchorY":0,"anchorZ":0,"blockIdVersion":11,"blocks":[{"name":"Rock_Sandstone_Brick_Half","rotation":6,"x":-4,"y":1,"z":-2},{"name":"Rock_Sandstone_Brick","x":-4,"y":0,"z":-1},{"name":"Rock_Sandstone_White_Brick","x":-4,"y":1,"z":-1},{"name":"Rock_Sandstone_Brick","x":-4,"y":0,"z":0},{"name":"Rock_Sandstone_White_Brick","x":-4,"y":1,"z":0},{"name":"Furniture_Desert_Window","rotation":1,"x":-4,"y":2,"z":0},{"name":"Wood_Drywood_Beam","x":-4,"y":3,"z":0},{"name":"Rock_Sandstone_Brick","x":-4,"y":0,"z":1},{"name":"Rock_Sandstone_White_Brick","x":-4,"y":1,"z":1},{"name":"Rock_Sandstone_Brick","x":-4,"y":0,"z":2},{"name":"Rock_Sandstone_White_Brick","x":-4,"y":1,"z":2},{"name":"Furniture_Desert_Window","rotation":1,"x":-4,"y":2,"z":2},{"name":"Rock_Sandstone_Brick","x":-4,"y":0,"z":3},{"name":"Rock_Sandstone_White_Brick","x":-4,"y":1,"z":3},{"name":"Rock_Sandstone_White_Brick","x":-4,"y":2,"z":3},{"name":"Rock_Sandstone_White_Brick","x":-4,"y":3,"z":3},{"name":"Rock_Sandstone_Brick","x":-4,"y":0,"z":4},{"name":"Rock_Sandstone_Brick_Stairs","rotation":10,"x":-4,"y":1,"z":4},{"name":"Rock_Sandstone_Brick_Stairs","rotation":3,"x":-4,"y":2,"z":4},{"name":"Rock_Sandstone_Brick_Stairs","rotation":1,"x":-3,"y":0,"z":-4},{"name":"Rock_Sandstone_Brick_Stairs","rotation":8,"x":-3,"y":1,"z":-4},{"name":"Rock_Sandstone_White_Cobble_Half","rotation":6,"x":-3,"y":2,"z":-4},{"name":"Rock_Sandstone_Brick","x":-3,"y":0,"z":-3},{"name":"Rock_Sandstone_Brick","x":-3,"y":1,"z":-3},{"name":"Rock_Sandstone_White_Cobble","x":-3,"y":2,"z":-3},{"name":"Rock_Sandstone_Brick","x":-3,"y":0,"z":-2},{"name":"Rock_Sandstone_Brick","x":-3,"y":1,"z":-2},{"name":"Rock_Sandstone_Cobble","x":-3,"y":0,"z":-1},{"name":"Rock_Sandstone_Cobble","x":-3,"y":0,"z":0},{"name":"Rock_Sandstone_Cobble","x":-3,"y":0,"z":1},{"name":"Rock_Sandstone_Cobble","x":-3,"y":0,"z":2},{"name":"Wood_Sticks","support":15,"x":-3,"y":1,"z":2},{"name":"Rock_Sandstone_Cobble","x":-3,"y":0,"z":3},{"name":"Rock_Sandstone_Brick","x":-3,"y":0,"z":4},{"name":"Rock_Sandstone_White_Brick","x":-3,"y":1,"z":4},{"name":"Rock_Sandstone_White_Brick","x":-3,"y":2,"z":4},{"name":"Rock_Sandstone_Cobble_Stairs","rotation":2,"x":-2,"y":0,"z":-2},{"name":"Rock_Sandstone_Cobble","x":-2,"y":0,"z":-1},{"name":"Rock_Sandstone_Cobble","x":-2,"y":0,"z":0},{"name":"Rock_Sandstone_Cobble","x":-2,"y":0,"z":1},{"name":"Rubble_Sandstone_Medium","support":15,"x":-2,"y":1,"z":1},{"name":"Rock_Sandstone_Cobble","x":-2,"y":0,"z":2},{"name":"Rock_Sandstone_Cobble","x":-2,"y":0,"z":3},{"name":"Rock_Sandstone_Brick","x":-2,"y":0,"z":4},{"name":"Rock_Sandstone_White_Brick","x":-2,"y":1,"z":4},{"name":"Furniture_Desert_Window","x":-2,"y":2,"z":4},{"name":"Rock_Sandstone_Cobble_Stairs","rotation":2,"x":-1,"y":0,"z":-2},{"name":"Rock_Sandstone_Cobble","x":-1,"y":0,"z":-1},{"name":"Rock_Sandstone_Cobble","x":-1,"y":0,"z":0},{"name":"Rock_Sandstone_Cobble","x":-1,"y":0,"z":1},{"name":"Rock_Sandstone_Cobble","x":-1,"y":0,"z":2},{"name":"Rock_Sandstone_Cobble","x":-1,"y":0,"z":3},{"name":"Rock_Sandstone_Brick","x":-1,"y":0,"z":4},{"name":"Rock_Sandstone_White_Brick","x":-1,"y":1,"z":4},{"name":"Rock_Sandstone_Brick_Stairs","x":-1,"y":0,"z":5},{"name":"Rock_Sandstone_Cobble_Stairs","rotation":2,"x":0,"y":0,"z":-2},{"name":"Rock_Sandstone_Cobble","x":0,"y":0,"z":-1},{"name":"Rock_Sandstone_Cobble","x":0,"y":0,"z":0},{"name":"Rock_Sandstone_Cobble","x":0,"y":0,"z":1},{"name":"Rock_Sandstone_Cobble","x":0,"y":0,"z":2},{"name":"Rock_Sandstone_Cobble","x":0,"y":0,"z":3},{"name":"Rock_Sandstone_Brick","x":0,"y":0,"z":4},{"name":"Rock_Sandstone_White_Brick","x":0,"y":1,"z":4},{"name":"Rock_Sandstone_Cobble_Stairs","x":0,"y":0,"z":5},{"name":"Rock_Sandstone_Brick","x":1,"y":0,"z":-4},{"name":"Rock_Sandstone_Brick_Stairs","rotation":2,"x":1,"y":1,"z":-4},{"name":"Rock_Sandstone_White_Cobble_Half","rotation":6,"x":1,"y":2,"z":-4},{"name":"Rock_Sandstone_White_Cobble_Half","rotation":6,"x":1,"y":3,"z":-4},{"name":"Rock_Sandstone_White_Cobble_Half","rotation":6,"x":1,"y":4,"z":-4},{"name":"Rock_Sandstone_White_Cobble_Half","rotation":6,"x":1,"y":5,"z":-4},{"name":"Rock_Sandstone_Brick","x":1,"y":0,"z":-3},{"name":"Rock_Sandstone_Brick","x":1,"y":1,"z":-3},{"name":"Rock_Sandstone_White_Cobble","x":1,"y":2,"z":-3},{"name":"Rock_Sandstone_White_Cobble","x":1,"y":3,"z":-3},{"name":"Rock_Sandstone_White_Cobble","x":1,"y":4,"z":-3},{"name":"Rock_Sandstone_Brick","x":1,"y":0,"z":-2},{"name":"Rock_Sandstone_Brick","x":1,"y":1,"z":-2},{"name":"Rock_Sandstone_Brick","x":1,"y":2,"z":-2},{"name":"Rock_Sandstone_Cobble","x":1,"y":0,"z":-1},{"name":"Rubble_Sandstone","x":1,"y":1,"z":-1},{"name":"Rock_Sandstone_Cobble","x":1,"y":0,"z":0},{"name":"Rock_Sandstone_Cobble","x":1,"y":0,"z":1},{"name":"Rock_Sandstone_Cobble","x":1,"y":0,"z":2},{"name":"Rock_Sandstone_Cobble","x":1,"y":0,"z":3},{"name":"Rock_Sandstone_Brick","x":1,"y":0,"z":4},{"name":"Rock_Sandstone_White_Brick","x":1,"y":1,"z":4},{"name":"Rock_Sandstone_White_Brick","x":1,"y":2,"z":4},{"name":"Rock_Sandstone_White_Brick","x":1,"y":3,"z":4},{"name":"Rock_Sandstone_Cobble_Stairs","x":1,"y":0,"z":5},{"name":"Rock_Sandstone_Cobble_Stairs","rotation":2,"x":2,"y":0,"z":-4},{"name":"Rock_Sandstone_Brick","x":2,"y":0,"z":-3},{"name":"Rock_Sandstone_Brick","x":2,"y":1,"z":-3},{"name":"Rock_Sandstone_Brick","x":2,"y":2,"z":-3},{"name":"Rock_Sandstone_Brick","x":2,"y":0,"z":-2},{"name":"Rock_Sandstone_Brick","x":2,"y":1,"z":-2},{"name":"Rock_Sandstone_Brick","x":2,"y":2,"z":-2},{"name":"Rock_Sandstone_Brick","x":2,"y":3,"z":-2},{"name":"Soil_Dirt_Dry","x":2,"y":0,"z":-1},{"name":"Rock_Sandstone_Cobble","x":2,"y":0,"z":0},{"name":"Rock_Sandstone_Cobble","x":2,"y":0,"z":1},{"name":"Rock_Sandstone_White_Brick_Stairs","rotation":2,"x":2,"y":1,"z":1},{"name":"Rock_Sandstone_White_Brick_Stairs","rotation":3,"x":2,"y":2,"z":1},{"name":"Soil_Dirt_Dry","x":2,"y":0,"z":2},{"name":"Rock_Sandstone_White_Brick","x":2,"y":1,"z":2},{"name":"Rock_Sandstone_White_Brick","x":2,"y":2,"z":2},{"name":"Soil_Dirt_Dry","x":2,"y":0,"z":3},{"name":"Rock_Sandstone_White_Brick","x":2,"y":1,"z":3},{"name":"Rock_Sandstone_Brick","x":2,"y":0,"z":4},{"name":"Rock_Sandstone_Brick","x":2,"y":1,"z":4},{"name":"Rock_Sandstone_Brick","x":2,"y":2,"z":4},{"name":"Rock_Sandstone_Brick_Stairs","x":2,"y":0,"z":5},{"name":"Rock_Sandstone_Cobble_Stairs","rotation":2,"x":3,"y":0,"z":-4},{"name":"Rock_Sandstone_Brick","x":3,"y":0,"z":-3},{"name":"Rock_Sandstone_Brick","x":3,"y":1,"z":-3},{"name":"Rock_Sandstone_Brick","x":3,"y":2,"z":-3},{"name":"Rock_Sandstone_Brick","x":3,"y":0,"z":-2},{"name":"Rock_Sandstone_Brick","x":3,"y":1,"z":-2},{"name":"Rock_Sandstone_Brick","x":3,"y":2,"z":-2},{"name":"Rock_Sandstone_White_Cobble","x":3,"y":3,"z":-2},{"name":"Rock_Sandstone_White_Cobble","x":3,"y":4,"z":-2},{"name":"Soil_Dirt_Dry","x":3,"y":0,"z":-1},{"name":"Rock_Sandstone_White_Cobble_Half","x":3,"y":1,"z":-1},{"name":"Furniture_Temple_Emerald_Ladder","x":3,"y":2,"z":-1},{"name":"Furniture_Temple_Emerald_Ladder","x":3,"y":3,"z":-1},{"name":"Furniture_Temple_Emerald_Ladder","x":3,"y":4,"z":-1},{"name":"Soil_Dirt_Dry","x":3,"y":0,"z":0},{"name":"Rock_Sandstone_White_Cobble_Half","x":3,"y":1,"z":0},{"name":"Soil_Dirt_Dry","x":3,"y":0,"z":1},{"name":"Soil_Dirt_Dry","x":3,"y":0,"z":2},{"name":"Soil_Dirt_Dry","x":3,"y":0,"z":3},{"name":"Rock_Sandstone_Brick","x":3,"y":0,"z":4},{"name":"Rock_Sandstone_Brick_Stairs","x":3,"y":0,"z":5},{"name":"*Rock_Sandstone_Brick_Stairs_State_Definitions_Corner_Left","rotation":1,"x":4,"y":0,"z":-4},{"name":"*Rock_Sandstone_Brick_Stairs_State_Definitions_Inverted_Corner_Left","rotation":1,"x":4,"y":0,"z":-3},{"name":"Rock_Sandstone_Brick","x":4,"y":0,"z":-2},{"name":"Rock_Sandstone_Brick","x":4,"y":1,"z":-2},{"name":"Rock_Sandstone_Brick","x":4,"y":2,"z":-2},{"name":"Rock_Sandstone_White_Cobble","x":4,"y":3,"z":-2},{"name":"Rock_Sandstone_White_Cobble","x":4,"y":4,"z":-2},{"name":"Rock_Sandstone_White_Cobble","x":4,"y":5,"z":-2},{"name":"Rock_Sandstone_White_Cobble","x":4,"y":6,"z":-2},{"name":"Rock_Sandstone_Brick_Half","x":4,"y":7,"z":-2},{"name":"Soil_Dirt_Dry","x":4,"y":0,"z":-1},{"name":"Rock_Sandstone_White_Cobble_Half","x":4,"y":1,"z":-1},{"name":"Furniture_Temple_Emerald_Ladder","x":4,"y":2,"z":-1},{"name":"Furniture_Temple_Emerald_Ladder","x":4,"y":3,"z":-1},{"name":"Furniture_Temple_Emerald_Ladder","x":4,"y":4,"z":-1},{"name":"Furniture_Temple_Emerald_Ladder","x":4,"y":5,"z":-1},{"name":"Soil_Dirt_Dry","x":4,"y":0,"z":0},{"name":"Rock_Sandstone_White_Cobble_Half","x":4,"y":1,"z":0},{"name":"Soil_Dirt_Dry","x":4,"y":0,"z":1},{"name":"Soil_Dirt_Dry","x":4,"y":0,"z":2},{"name":"Soil_Dirt_Dry","x":4,"y":0,"z":3},{"name":"Rock_Sandstone_Brick_Stairs","rotation":1,"x":4,"y":0,"z":4},{"name":"*Rock_Sandstone_Brick_Stairs_State_Definitions_Corner_Right","rotation":1,"x":4,"y":0,"z":5},{"name":"*Rock_Sandstone_Brick_Stairs_State_Definitions_Corner_Right","rotation":2,"x":5,"y":0,"z":-3},{"name":"Rock_Sandstone_Brick_Stairs","rotation":1,"x":5,"y":0,"z":-2},{"name":"Rock_Sandstone_Brick_Half","rotation":5,"x":5,"y":1,"z":-2},{"name":"Rock_Sandstone_Brick_Half","rotation":5,"x":5,"y":2,"z":-2},{"name":"Rock_Sandstone_Brick_Half","rotation":5,"x":5,"y":3,"z":-2},{"name":"Rock_Sandstone_Brick_Half","rotation":5,"x":5,"y":4,"z":-2},{"name":"Rock_Sandstone_Brick_Half","rotation":5,"x":5,"y":5,"z":-2},{"name":"Rock_Sandstone_Brick_Half","rotation":5,"x":5,"y":6,"z":-2},{"name":"Rock_Sandstone_Brick_Half","rotation":5,"x":5,"y":7,"z":-2},{"name":"Rock_Sandstone_Brick_Stairs","rotation":1,"x":5,"y":0,"z":-1},{"name":"Rock_Sandstone_Brick_Half","rotation":5,"x":5,"y":1,"z":-1},{"name":"Rock_Sandstone_Brick_Half","rotation":5,"x":5,"y":2,"z":-1},{"name":"Rock_Sandstone_Brick_Half","rotation":5,"x":5,"y":3,"z":-1},{"name":"Rock_Sandstone_Brick_Half","rotation":5,"x":5,"y":4,"z":-1},{"name":"Rock_Sandstone_Brick_Half","rotation":5,"x":5,"y":5,"z":-1},{"name":"Rock_Sandstone_Brick_Half","rotation":5,"x":5,"y":6,"z":-1},{"name":"Rock_Sandstone_Brick_Half","rotation":5,"x":5,"y":7,"z":-1},{"name":"Rock_Sandstone_Brick_Stairs","rotation":1,"x":5,"y":0,"z":0},{"name":"Rock_Sandstone_Cobble_Stairs","rotation":1,"x":5,"y":0,"z":1},{"name":"Rock_Sandstone_Cobble_Stairs","rotation":1,"x":5,"y":0,"z":2},{"name":"Rock_Sandstone_Cobble_Stairs","rotation":1,"x":5,"y":0,"z":3}],"fluids":[{"level":1,"name":"Water_Source","x":-4,"y":1,"z":-2},{"level":1,"name":"Water_Source","x":-4,"y":0,"z":-1},{"level":1,"name":"Water_Source","x":-4,"y":1,"z":-1},{"level":1,"name":"Water_Source","x":-4,"y":0,"z":0},{"level":1,"name":"Water_Source","x":-4,"y":1,"z":0},{"level":1,"name":"Water_Source","x":-4,"y":2,"z":0},{"level":1,"name":"Water_Source","x":-4,"y":3,"z":0},{"level":1,"name":"Water_Source","x":-4,"y":0,"z":1},{"level":1,"name":"Water_Source","x":-4,"y":1,"z":1},{"level":1,"name":"Water_Source","x":-4,"y":0,"z":2},{"level":1,"name":"Water_Source","x":-4,"y":1,"z":2},{"level":1,"name":"Water_Source","x":-4,"y":2,"z":2},{"level":1,"name":"Water_Source","x":-4,"y":0,"z":3},{"level":1,"name":"Water_Source","x":-4,"y":1,"z":3},{"level":1,"name":"Water_Source","x":-4,"y":2,"z":3},{"level":1,"name":"Water_Source","x":-4,"y":3,"z":3},{"level":1,"name":"Water_Source","x":-4,"y":0,"z":4},{"level":1,"name":"Water_Source","x":-4,"y":1,"z":4},{"level":1,"name":"Water_Source","x":-4,"y":2,"z":4},{"level":1,"name":"Water_Source","x":-3,"y":0,"z":-4},{"level":1,"name":"Water_Source","x":-3,"y":1,"z":-4},{"level":1,"name":"Water_Source","x":-3,"y":2,"z":-4},{"level":1,"name":"Water_Source","x":-3,"y":0,"z":-3},{"level":1,"name":"Water_Source","x":-3,"y":1,"z":-3},{"level":1,"name":"Water_Source","x":-3,"y":2,"z":-3},{"level":1,"name":"Water_Source","x":-3,"y":0,"z":-2},{"level":1,"name":"Water_Source","x":-3,"y":1,"z":-2},{"level":1,"name":"Water_Source","x":-3,"y":0,"z":-1},{"level":1,"name":"Water_Source","x":-3,"y":0,"z":0},{"level":1,"name":"Water_Source","x":-3,"y":0,"z":1},{"level":1,"name":"Water_Source","x":-3,"y":0,"z":2},{"level":1,"name":"Water_Source","x":-3,"y":1,"z":2},{"level":1,"name":"Water_Source","x":-3,"y":0,"z":3},{"level":1,"name":"Water_Source","x":-3,"y":0,"z":4},{"level":1,"name":"Water_Source","x":-3,"y":1,"z":4},{"level":1,"name":"Water_Source","x":-3,"y":2,"z":4},{"level":1,"name":"Water_Source","x":-2,"y":0,"z":-2},{"level":1,"name":"Water_Source","x":-2,"y":0,"z":-1},{"level":1,"name":"Water_Source","x":-2,"y":0,"z":0},{"level":1,"name":"Water_Source","x":-2,"y":0,"z":1},{"level":1,"name":"Water_Source","x":-2,"y":1,"z":1},{"level":1,"name":"Water_Source","x":-2,"y":0,"z":2},{"level":1,"name":"Water_Source","x":-2,"y":0,"z":3},{"level":1,"name":"Water_Source","x":-2,"y":0,"z":4},{"level":1,"name":"Water_Source","x":-2,"y":1,"z":4},{"level":1,"name":"Water_Source","x":-2,"y":2,"z":4},{"level":1,"name":"Water_Source","x":-1,"y":0,"z":-2},{"level":1,"name":"Water_Source","x":-1,"y":0,"z":-1},{"level":1,"name":"Water_Source","x":-1,"y":0,"z":0},{"level":1,"name":"Water_Source","x":-1,"y":0,"z":1},{"level":1,"name":"Water_Source","x":-1,"y":0,"z":2},{"level":1,"name":"Water_Source","x":-1,"y":0,"z":3},{"level":1,"name":"Water_Source","x":-1,"y":0,"z":4},{"level":1,"name":"Water_Source","x":-1,"y":1,"z":4},{"level":1,"name":"Water_Source","x":-1,"y":0,"z":5},{"level":1,"name":"Water_Source","x":0,"y":0,"z":-2},{"level":1,"name":"Water_Source","x":0,"y":0,"z":-1},{"level":1,"name":"Water_Source","x":0,"y":0,"z":0},{"level":1,"name":"Water_Source","x":0,"y":0,"z":1},{"level":1,"name":"Water_Source","x":0,"y":0,"z":2},{"level":1,"name":"Water_Source","x":0,"y":0,"z":3},{"level":1,"name":"Water_Source","x":0,"y":0,"z":4},{"level":1,"name":"Water_Source","x":0,"y":1,"z":4},{"level":1,"name":"Water_Source","x":0,"y":0,"z":5},{"level":1,"name":"Water_Source","x":1,"y":0,"z":-4},{"level":1,"name":"Water_Source","x":1,"y":1,"z":-4},{"level":1,"name":"Water_Source","x":1,"y":2,"z":-4},{"level":1,"name":"Water_Source","x":1,"y":3,"z":-4},{"level":1,"name":"Water_Source","x":1,"y":4,"z":-4},{"level":1,"name":"Water_Source","x":1,"y":5,"z":-4},{"level":1,"name":"Water_Source","x":1,"y":0,"z":-3},{"level":1,"name":"Water_Source","x":1,"y":1,"z":-3},{"level":1,"name":"Water_Source","x":1,"y":2,"z":-3},{"level":1,"name":"Water_Source","x":1,"y":3,"z":-3},{"level":1,"name":"Water_Source","x":1,"y":4,"z":-3},{"level":1,"name":"Water_Source","x":1,"y":0,"z":-2},{"level":1,"name":"Water_Source","x":1,"y":1,"z":-2},{"level":1,"name":"Water_Source","x":1,"y":2,"z":-2},{"level":1,"name":"Water_Source","x":1,"y":0,"z":-1},{"level":1,"name":"Water_Source","x":1,"y":1,"z":-1},{"level":1,"name":"Water_Source","x":1,"y":0,"z":0},{"level":1,"name":"Water_Source","x":1,"y":0,"z":1},{"level":1,"name":"Water_Source","x":1,"y":0,"z":2},{"level":1,"name":"Water_Source","x":1,"y":0,"z":3},{"level":1,"name":"Water_Source","x":1,"y":0,"z":4},{"level":1,"name":"Water_Source","x":1,"y":1,"z":4},{"level":1,"name":"Water_Source","x":1,"y":2,"z":4},{"level":1,"name":"Water_Source","x":1,"y":3,"z":4},{"level":1,"name":"Water_Source","x":1,"y":0,"z":5},{"level":1,"name":"Water_Source","x":2,"y":0,"z":-4},{"level":1,"name":"Water_Source","x":2,"y":0,"z":-3},{"level":1,"name":"Water_Source","x":2,"y":1,"z":-3},{"level":1,"name":"Water_Source","x":2,"y":2,"z":-3},{"level":1,"name":"Water_Source","x":2,"y":0,"z":-2},{"level":1,"name":"Water_Source","x":2,"y":1,"z":-2},{"level":1,"name":"Water_Source","x":2,"y":2,"z":-2},{"level":1,"name":"Water_Source","x":2,"y":3,"z":-2},{"level":1,"name":"Water_Source","x":2,"y":0,"z":-1},{"level":1,"name":"Water_Source","x":2,"y":0,"z":0},{"level":1,"name":"Water_Source","x":2,"y":0,"z":1},{"level":1,"name":"Water_Source","x":2,"y":1,"z":1},{"level":1,"name":"Water_Source","x":2,"y":2,"z":1},{"level":1,"name":"Water_Source","x":2,"y":0,"z":2},{"level":1,"name":"Water_Source","x":2,"y":1,"z":2},{"level":1,"name":"Water_Source","x":2,"y":2,"z":2},{"level":1,"name":"Water_Source","x":2,"y":0,"z":3},{"level":1,"name":"Water_Source","x":2,"y":1,"z":3},{"level":1,"name":"Water_Source","x":2,"y":0,"z":4},{"level":1,"name":"Water_Source","x":2,"y":1,"z":4},{"level":1,"name":"Water_Source","x":2,"y":2,"z":4},{"level":1,"name":"Water_Source","x":2,"y":0,"z":5},{"level":1,"name":"Water_Source","x":3,"y":0,"z":-4},{"level":1,"name":"Water_Source","x":3,"y":0,"z":-3},{"level":1,"name":"Water_Source","x":3,"y":1,"z":-3},{"level":1,"name":"Water_Source","x":3,"y":2,"z":-3},{"level":1,"name":"Water_Source","x":3,"y":0,"z":-2},{"level":1,"name":"Water_Source","x":3,"y":1,"z":-2},{"level":1,"name":"Water_Source","x":3,"y":2,"z":-2},{"level":1,"name":"Water_Source","x":3,"y":3,"z":-2},{"level":1,"name":"Water_Source","x":3,"y":4,"z":-2},{"level":1,"name":"Water_Source","x":3,"y":0,"z":-1},{"level":1,"name":"Water_Source","x":3,"y":1,"z":-1},{"level":1,"name":"Water_Source","x":3,"y":2,"z":-1},{"level":1,"name":"Water_Source","x":3,"y":3,"z":-1},{"level":1,"name":"Water_Source","x":3,"y":4,"z":-1},{"level":1,"name":"Water_Source","x":3,"y":0,"z":0},{"level":1,"name":"Water_Source","x":3,"y":1,"z":0},{"level":1,"name":"Water_Source","x":3,"y":0,"z":1},{"level":1,"name":"Water_Source","x":3,"y":0,"z":2},{"level":1,"name":"Water_Source","x":3,"y":0,"z":3},{"level":1,"name":"Water_Source","x":3,"y":0,"z":4},{"level":1,"name":"Water_Source","x":3,"y":0,"z":5},{"level":1,"name":"Water_Source","x":4,"y":0,"z":-4},{"level":1,"name":"Water_Source","x":4,"y":0,"z":-3},{"level":1,"name":"Water_Source","x":4,"y":0,"z":-2},{"level":1,"name":"Water_Source","x":4,"y":1,"z":-2},{"level":1,"name":"Water_Source","x":4,"y":2,"z":-2},{"level":1,"name":"Water_Source","x":4,"y":3,"z":-2},{"level":1,"name":"Water_Source","x":4,"y":4,"z":-2},{"level":1,"name":"Water_Source","x":4,"y":5,"z":-2},{"level":1,"name":"Water_Source","x":4,"y":6,"z":-2},{"level":1,"name":"Water_Source","x":4,"y":7,"z":-2},{"level":1,"name":"Water_Source","x":4,"y":0,"z":-1},{"level":1,"name":"Water_Source","x":4,"y":1,"z":-1},{"level":1,"name":"Water_Source","x":4,"y":2,"z":-1},{"level":1,"name":"Water_Source","x":4,"y":3,"z":-1},{"level":1,"name":"Water_Source","x":4,"y":4,"z":-1},{"level":1,"name":"Water_Source","x":4,"y":5,"z":-1},{"level":1,"name":"Water_Source","x":4,"y":0,"z":0},{"level":1,"name":"Water_Source","x":4,"y":1,"z":0},{"level":1,"name":"Water_Source","x":4,"y":0,"z":1},{"level":1,"name":"Water_Source","x":4,"y":0,"z":2},{"level":1,"name":"Water_Source","x":4,"y":0,"z":3},{"level":1,"name":"Water_Source","x":4,"y":0,"z":4},{"level":1,"name":"Water_Source","x":4,"y":0,"z":5},{"level":1,"name":"Water_Source","x":5,"y":0,"z":-3},{"level":1,"name":"Water_Source","x":5,"y":0,"z":-2},{"level":1,"name":"Water_Source","x":5,"y":1,"z":-2},{"level":1,"name":"Water_Source","x":5,"y":2,"z":-2},{"level":1,"name":"Water_Source","x":5,"y":3,"z":-2},{"level":1,"name":"Water_Source","x":5,"y":4,"z":-2},{"level":1,"name":"Water_Source","x":5,"y":5,"z":-2},{"level":1,"name":"Water_Source","x":5,"y":6,"z":-2},{"level":1,"name":"Water_Source","x":5,"y":7,"z":-2},{"level":1,"name":"Water_Source","x":5,"y":0,"z":-1},{"level":1,"name":"Water_Source","x":5,"y":1,"z":-1},{"level":1,"name":"Water_Source","x":5,"y":2,"z":-1},{"level":1,"name":"Water_Source","x":5,"y":3,"z":-1},{"level":1,"name":"Water_Source","x":5,"y":4,"z":-1},{"level":1,"name":"Water_Source","x":5,"y":5,"z":-1},{"level":1,"name":"Water_Source","x":5,"y":6,"z":-1},{"level":1,"name":"Water_Source","x":5,"y":7,"z":-1},{"level":1,"name":"Water_Source","x":5,"y":0,"z":0},{"level":1,"name":"Water_Source","x":5,"y":0,"z":1},{"level":1,"name":"Water_Source","x":5,"y":0,"z":2},{"level":1,"name":"Water_Source","x":5,"y":0,"z":3}],"version":8}