{"anchorX":4,"anchorY":0,"anchorZ":-5,"blockIdVersion":11,"blocks":[{"name":"Rock_Sandstone_White_Brick_Half","rotation":7,"x":0,"y":0,"z":-8},{"name":"Rock_Sandstone_White_Brick_Half","rotation":7,"x":0,"y":1,"z":-8},{"name":"Rock_Sandstone_Brick","x":0,"y":0,"z":-7},{"name":"Rock_Sandstone_Brick_Pillar_Base","x":0,"y":1,"z":-7},{"name":"Rock_Sandstone_Brick_Pillar_Middle","x":0,"y":2,"z":-7},{"name":"Rock_Sandstone_Brick_Pillar_Middle","x":0,"y":3,"z":-7},{"name":"Rock_Sandstone_Brick_Pillar_Middle","x":0,"y":4,"z":-7},{"name":"Rock_Sandstone_Brick","x":0,"y":0,"z":-2},{"name":"Rock_Sandstone_Brick_Pillar_Base","x":0,"y":1,"z":-2},{"name":"Rock_Sandstone_Brick_Pillar_Middle","x":0,"y":2,"z":-2},{"name":"Rock_Sandstone_Brick_Pillar_Middle","x":0,"y":3,"z":-2},{"name":"Rock_Sandstone_Brick_Pillar_Middle","x":0,"y":4,"z":-2},{"name":"Rock_Sandstone_Brick_Pillar_Base","rotation":8,"x":0,"y":5,"z":-2},{"name":"Rock_Sandstone_Brick_Stairs","rotation":3,"x":0,"y":6,"z":-2},{"name":"Rock_Sandstone_White_Brick_Half","rotation":7,"x":0,"y":0,"z":-1},{"name":"Rock_Sandstone_White_Brick_Half","rotation":7,"x":0,"y":1,"z":-1},{"name":"Rock_Sandstone_White_Brick_Half","rotation":6,"x":1,"y":0,"z":-9},{"name":"Rock_Sandstone_White_Brick_Half","rotation":6,"x":1,"y":1,"z":-9},{"name":"Rock_Sandstone_White_Brick","x":1,"y":0,"z":-8},{"name":"Rock_Sandstone_White_Brick","x":1,"y":1,"z":-8},{"name":"Rock_Sandstone_White_Brick","x":1,"y":2,"z":-8},{"name":"Rock_Sandstone_White_Brick","x":1,"y":3,"z":-8},{"name":"Rock_Sandstone_White_Brick","x":1,"y":4,"z":-8},{"name":"Rock_Sandstone_Brick","x":1,"y":5,"z":-8},{"name":"Rubble_Sandstone","support":15,"x":1,"y":6,"z":-8},{"name":"Rock_Sandstone_Cobble","x":1,"y":0,"z":-7},{"name":"Rock_Sandstone_White_Brick","x":1,"y":1,"z":-7},{"name":"Rock_Sandstone_White_Brick","x":1,"y":2,"z":-7},{"name":"Rock_Sandstone_White_Brick","x":1,"y":3,"z":-7},{"name":"Rock_Sandstone_Brick_Smooth","x":1,"y":4,"z":-7},{"name":"Rock_Sandstone_Brick_Smooth","x":1,"y":5,"z":-7},{"name":"Rubble_Sandstone_Medium","support":15,"x":1,"y":6,"z":-7},{"name":"Rock_Sandstone_Cobble_Stairs","rotation":3,"x":1,"y":0,"z":-6},{"name":"Cloth_Roof_Leather_Flap","rotation":3,"x":1,"y":4,"z":-6},{"name":"Rock_Sandstone_Brick_Half","rotation":8,"x":1,"y":5,"z":-6},{"name":"Rock_Sandstone_Brick_Ornate","x":1,"y":6,"z":-6},{"name":"Rock_Sandstone_White_Cobble","x":1,"y":7,"z":-6},{"name":"Rock_Sandstone_Cobble_Stairs","rotation":3,"x":1,"y":0,"z":-5},{"name":"Rock_Sandstone_Brick_Half","rotation":8,"x":1,"y":5,"z":-5},{"name":"Rock_Sandstone_Brick_Ornate","x":1,"y":6,"z":-5},{"name":"Rock_Sandstone_White_Cobble","x":1,"y":7,"z":-5},{"name":"Rock_Sandstone_Cobble_Stairs","rotation":3,"x":1,"y":0,"z":-4},{"name":"Rock_Sandstone_Brick_Half","rotation":8,"x":1,"y":5,"z":-4},{"name":"Rock_Sandstone_Brick_Ornate","x":1,"y":6,"z":-4},{"name":"Rock_Sandstone_White_Brick","x":1,"y":7,"z":-4},{"name":"Rock_Sandstone_Cobble_Stairs","rotation":3,"x":1,"y":0,"z":-3},{"name":"Rock_Sandstone_Brick_Half","rotation":8,"x":1,"y":5,"z":-3},{"name":"Rock_Sandstone_Brick_Ornate","x":1,"y":6,"z":-3},{"name":"Rock_Sandstone_White_Brick","x":1,"y":7,"z":-3},{"name":"Rock_Sandstone_Cobble","x":1,"y":0,"z":-2},{"name":"Rock_Sandstone_White_Brick","x":1,"y":1,"z":-2},{"name":"Rock_Sandstone_White_Brick","x":1,"y":2,"z":-2},{"name":"Rock_Sandstone_White_Brick","x":1,"y":3,"z":-2},{"name":"Rock_Sandstone_Brick_Smooth","x":1,"y":4,"z":-2},{"name":"Rock_Sandstone_Brick_Smooth","x":1,"y":5,"z":-2},{"name":"Rock_Sandstone_Brick_Ornate","x":1,"y":6,"z":-2},{"name":"Rock_Sandstone_Brick","x":1,"y":7,"z":-2},{"name":"Rock_Sandstone_Brick_Pillar_Base","x":1,"y":8,"z":-2},{"name":"Rock_Sandstone_White_Brick","x":1,"y":0,"z":-1},{"name":"Rock_Sandstone_White_Brick","x":1,"y":1,"z":-1},{"name":"Rock_Sandstone_White_Brick","x":1,"y":2,"z":-1},{"name":"Rock_Sandstone_White_Brick","x":1,"y":3,"z":-1},{"name":"Rock_Sandstone_White_Brick","x":1,"y":4,"z":-1},{"name":"Rock_Sandstone_Brick","x":1,"y":5,"z":-1},{"name":"Rock_Sandstone_Brick_Ornate","x":1,"y":6,"z":-1},{"name":"Rock_Sandstone_Brick","x":1,"y":7,"z":-1},{"name":"Rock_Sandstone_Brick_Pillar_Base","x":1,"y":8,"z":-1},{"name":"Rock_Sandstone_White_Brick_Half","rotation":4,"x":1,"y":0,"z":0},{"name":"Rock_Sandstone_White_Brick_Half","rotation":4,"x":1,"y":1,"z":0},{"name":"Rock_Sandstone_Brick","x":2,"y":0,"z":-9},{"name":"Rock_Sandstone_Brick_Pillar_Base","x":2,"y":1,"z":-9},{"name":"Rock_Sandstone_Brick_Pillar_Middle","x":2,"y":2,"z":-9},{"name":"Rock_Sandstone_Brick_Pillar_Middle","x":2,"y":3,"z":-9},{"name":"Rock_Sandstone_Brick_Pillar_Middle","x":2,"y":4,"z":-9},{"name":"Rock_Sandstone_Brick_Pillar_Base","rotation":8,"x":2,"y":5,"z":-9},{"name":"Rock_Sandstone_Brick_Stairs","rotation":2,"x":2,"y":6,"z":-9},{"name":"Rock_Sandstone_Cobble","x":2,"y":0,"z":-8},{"name":"Rock_Sandstone_White_Brick","x":2,"y":1,"z":-8},{"name":"Rock_Sandstone_White_Brick","x":2,"y":2,"z":-8},{"name":"Rock_Sandstone_White_Brick","x":2,"y":3,"z":-8},{"name":"Rock_Sandstone_Brick_Smooth","x":2,"y":4,"z":-8},{"name":"Rock_Sandstone_Brick_Smooth","x":2,"y":5,"z":-8},{"name":"Rock_Sandstone_Brick_Ornate","x":2,"y":6,"z":-8},{"name":"Rock_Sandstone_Brick","x":2,"y":7,"z":-8},{"name":"Rock_Sandstone_Brick_Pillar_Base","x":2,"y":8,"z":-8},{"name":"Rock_Sandstone_Cobble","x":2,"y":0,"z":-7},{"name":"Rock_Sandstone_Brick_Ornate","x":2,"y":4,"z":-7},{"name":"Rock_Sandstone_Brick_Half","x":2,"y":5,"z":-7},{"name":"Wood_Drywood_Planks","x":2,"y":6,"z":-7},{"name":"Rock_Sandstone_Cobble","x":2,"y":0,"z":-6},{"name":"Rock_Sandstone_Brick_Half","rotation":8,"x":2,"y":4,"z":-6},{"name":"Rock_Sandstone_Brick","x":2,"y":5,"z":-6},{"name":"Wood_Drywood_Planks","x":2,"y":6,"z":-6},{"name":"Rock_Sandstone_Cobble","x":2,"y":0,"z":-5},{"name":"Cloth_Roof_Leather_Flap","rotation":1,"x":2,"y":3,"z":-5},{"name":"Cloth_Roof_Leather_Vertical","rotation":1,"x":2,"y":4,"z":-5},{"name":"Rock_Sandstone_Brick","x":2,"y":5,"z":-5},{"name":"Wood_Drywood_Planks","x":2,"y":6,"z":-5},{"name":"Rock_Sandstone_Cobble","x":2,"y":0,"z":-4},{"name":"Cloth_Roof_Leather_Flap","rotation":1,"x":2,"y":3,"z":-4},{"name":"Cloth_Roof_Leather_Vertical","rotation":1,"x":2,"y":4,"z":-4},{"name":"Rock_Sandstone_Brick","x":2,"y":5,"z":-4},{"name":"Wood_Drywood_Planks","x":2,"y":6,"z":-4},{"name":"Rock_Sandstone_Cobble","x":2,"y":0,"z":-3},{"name":"Rock_Sandstone_Brick_Half","rotation":8,"x":2,"y":4,"z":-3},{"name":"Rock_Sandstone_Brick","x":2,"y":5,"z":-3},{"name":"Wood_Drywood_Planks","x":2,"y":6,"z":-3},{"name":"Rock_Sandstone_Cobble","x":2,"y":0,"z":-2},{"name":"Rock_Sandstone_Brick_Ornate","x":2,"y":4,"z":-2},{"name":"Rock_Sandstone_Brick_Half","x":2,"y":5,"z":-2},{"name":"Wood_Drywood_Planks","x":2,"y":6,"z":-2},{"name":"Rock_Sandstone_Cobble","x":2,"y":0,"z":-1},{"name":"Rock_Sandstone_White_Brick","x":2,"y":1,"z":-1},{"name":"Rock_Sandstone_White_Brick","x":2,"y":2,"z":-1},{"name":"Rock_Sandstone_White_Brick","x":2,"y":3,"z":-1},{"name":"Rock_Sandstone_Brick_Smooth","x":2,"y":4,"z":-1},{"name":"Rock_Sandstone_Brick_Smooth","x":2,"y":5,"z":-1},{"name":"Rock_Sandstone_Brick_Ornate","x":2,"y":6,"z":-1},{"name":"Rock_Sandstone_Brick","x":2,"y":7,"z":-1},{"name":"Rubble_Sandstone_Medium","support":15,"x":2,"y":8,"z":-1},{"name":"Rock_Sandstone_Brick","x":2,"y":0,"z":0},{"name":"Rock_Sandstone_Brick_Pillar_Base","x":2,"y":1,"z":0},{"name":"Rock_Sandstone_Brick_Pillar_Middle","x":2,"y":2,"z":0},{"name":"Rock_Sandstone_Brick_Pillar_Middle","x":2,"y":3,"z":0},{"name":"Rock_Sandstone_Brick_Pillar_Middle","x":2,"y":4,"z":0},{"name":"Rock_Sandstone_Brick_Pillar_Base","rotation":8,"x":2,"y":5,"z":0},{"name":"Rock_Sandstone_Brick_Stairs","x":2,"y":6,"z":0},{"name":"Rock_Sandstone_Cobble_Stairs","rotation":2,"x":3,"y":0,"z":-8},{"name":"Cloth_Roof_Leather_Flap","rotation":2,"x":3,"y":3,"z":-8},{"name":"Cloth_Roof_Leather_Vertical","rotation":2,"x":3,"y":4,"z":-8},{"name":"Rock_Sandstone_Brick_Half","rotation":8,"x":3,"y":5,"z":-8},{"name":"Rock_Sandstone_Brick_Ornate","x":3,"y":6,"z":-8},{"name":"Rock_Sandstone_White_Brick","x":3,"y":7,"z":-8},{"name":"Rock_Sandstone_White_Cobble_Half","x":3,"y":8,"z":-8},{"name":"Rock_Sandstone_Cobble","x":3,"y":0,"z":-7},{"name":"Rock_Sandstone_Brick_Half","rotation":8,"x":3,"y":4,"z":-7},{"name":"Rock_Sandstone_Brick","x":3,"y":5,"z":-7},{"name":"Wood_Drywood_Planks","x":3,"y":6,"z":-7},{"name":"Rock_Sandstone_Cobble","x":3,"y":0,"z":-6},{"name":"Wood_Dry_Trunk","support":15,"x":3,"y":1,"z":-6},{"name":"Wood_Dry_Trunk","support":15,"x":3,"y":2,"z":-6},{"name":"Wood_Dry_Trunk","support":15,"x":3,"y":3,"z":-6},{"name":"Wood_Dry_Trunk","support":15,"x":3,"y":4,"z":-6},{"name":"Wood_Dry_Trunk","support":15,"x":3,"y":5,"z":-6},{"name":"Wood_Drywood_Planks","x":3,"y":6,"z":-6},{"name":"Rock_Sandstone_Cobble","x":3,"y":0,"z":-5},{"name":"Furniture_Desert_Ladder","x":3,"y":1,"z":-5},{"name":"Furniture_Desert_Ladder","x":3,"y":2,"z":-5},{"name":"Furniture_Desert_Ladder","x":3,"y":3,"z":-5},{"name":"Furniture_Desert_Ladder","x":3,"y":4,"z":-5},{"name":"Rock_Sandstone_Cobble","x":3,"y":0,"z":-4},{"name":"Wood_Drywood_Planks_Half","rotation":6,"x":3,"y":6,"z":-4},{"name":"Rock_Sandstone_Cobble","x":3,"y":0,"z":-3},{"name":"Wood_Drywood_Planks","x":3,"y":6,"z":-3},{"name":"Rock_Sandstone_Cobble","x":3,"y":0,"z":-2},{"name":"Wood_Drywood_Planks","x":3,"y":6,"z":-2},{"name":"Rock_Sandstone_Cobble","x":3,"y":0,"z":-1},{"name":"Rock_Sandstone_White_Brick","x":3,"y":1,"z":-1},{"name":"Rock_Sandstone_White_Brick","x":3,"y":2,"z":-1},{"name":"Rock_Sandstone_White_Brick","x":3,"y":3,"z":-1},{"name":"Rock_Sandstone_White_Brick","x":3,"y":4,"z":-1},{"name":"Rock_Sandstone_White_Brick","x":3,"y":5,"z":-1},{"name":"Rock_Sandstone_Brick_Ornate","x":3,"y":6,"z":-1},{"name":"Rock_Sandstone_White_Brick","x":3,"y":7,"z":-1},{"name":"Rock_Sandstone_Brick","x":3,"y":0,"z":0},{"name":"Rock_Sandstone_Cobble_Stairs","rotation":2,"x":4,"y":0,"z":-8},{"name":"Cloth_Roof_Leather_Flap","rotation":2,"x":4,"y":4,"z":-8},{"name":"Rock_Sandstone_Brick_Half","rotation":8,"x":4,"y":5,"z":-8},{"name":"Rock_Sandstone_Brick_Ornate","x":4,"y":6,"z":-8},{"name":"Rock_Sandstone_White_Cobble","x":4,"y":7,"z":-8},{"name":"Rubble_Sandstone_White","support":15,"x":4,"y":8,"z":-8},{"name":"Rock_Sandstone_Cobble","x":4,"y":0,"z":-7},{"name":"Rock_Sandstone_Brick","x":4,"y":5,"z":-7},{"name":"Wood_Drywood_Planks","x":4,"y":6,"z":-7},{"name":"Rock_Sandstone_Cobble","x":4,"y":0,"z":-6},{"name":"Wood_Sticks","support":15,"x":4,"y":1,"z":-6},{"name":"Wood_Drywood_Planks","x":4,"y":6,"z":-6},{"name":"Rock_Sandstone_Cobble","x":4,"y":0,"z":-5},{"name":"Wood_Drywood_Beam","rotation":4,"x":4,"y":6,"z":-5},{"name":"Rock_Sandstone_Cobble","x":4,"y":0,"z":-4},{"name":"Wood_Drywood_Planks","x":4,"y":6,"z":-4},{"name":"Rock_Sandstone_Cobble","x":4,"y":0,"z":-3},{"name":"Wood_Drywood_Planks","x":4,"y":6,"z":-3},{"name":"Rock_Sandstone_Cobble","x":4,"y":0,"z":-2},{"name":"Wood_Drywood_Planks","x":4,"y":6,"z":-2},{"name":"Rock_Sandstone_Cobble","x":4,"y":0,"z":-1},{"name":"Rock_Sandstone_White_Brick","x":4,"y":1,"z":-1},{"name":"Wood_Drywood_Beam","x":4,"y":2,"z":-1},{"name":"Wood_Drywood_Beam","x":4,"y":3,"z":-1},{"name":"Rock_Sandstone_Brick_Ornate","x":4,"y":6,"z":-1},{"name":"Rock_Sandstone_White_Brick","x":4,"y":7,"z":-1},{"name":"Rock_Sandstone_Brick","x":4,"y":0,"z":0},{"name":"Rock_Sandstone_Cobble_Stairs","rotation":2,"x":5,"y":0,"z":-8},{"name":"Rock_Sandstone_Brick_Half","rotation":8,"x":5,"y":5,"z":-8},{"name":"Rock_Sandstone_Brick_Ornate","x":5,"y":6,"z":-8},{"name":"Rock_Sandstone_White_Cobble_Half","x":5,"y":7,"z":-8},{"name":"Rock_Sandstone_Cobble","x":5,"y":0,"z":-7},{"name":"Rock_Sandstone_Brick","x":5,"y":5,"z":-7},{"name":"Wood_Drywood_Planks","x":5,"y":6,"z":-7},{"name":"Rock_Sandstone_Cobble","x":5,"y":0,"z":-6},{"name":"Wood_Drywood_Beam","rotation":4,"x":5,"y":6,"z":-6},{"name":"Rock_Sandstone_Cobble","x":5,"y":0,"z":-5},{"name":"Wood_Drywood_Beam","rotation":4,"x":5,"y":6,"z":-5},{"name":"Rock_Sandstone_Cobble","x":5,"y":0,"z":-4},{"name":"Wood_Dry_Branch_Long","rotation":4,"support":15,"x":5,"y":6,"z":-4},{"name":"Rock_Sandstone_Cobble","x":5,"y":0,"z":-3},{"name":"Wood_Drywood_Planks","x":5,"y":6,"z":-3},{"name":"Rock_Sandstone_Cobble","x":5,"y":0,"z":-2},{"name":"Wood_Drywood_Planks","x":5,"y":6,"z":-2},{"name":"Rock_Sandstone_Cobble","x":5,"y":0,"z":-1},{"name":"Rock_Sandstone_White_Brick","x":5,"y":1,"z":-1},{"name":"Furniture_Desert_Window","x":5,"y":2,"z":-1},{"name":"Wood_Dry_Trunk","rotation":5,"support":15,"x":5,"y":5,"z":-1},{"name":"Rock_Sandstone_Brick_Ornate","x":5,"y":6,"z":-1},{"name":"Rock_Sandstone_White_Brick","x":5,"y":7,"z":-1},{"name":"Rock_Sandstone_Brick","x":5,"y":0,"z":0},{"name":"Soil_Clay_Ocean_Brick_Roof_Hollow","x":5,"y":5,"z":0},{"name":"Rock_Sandstone_Cobble_Stairs","rotation":2,"x":6,"y":0,"z":-8},{"name":"Rock_Sandstone_Cobble","x":6,"y":0,"z":-7},{"name":"Rubble_Sandstone_Medium","support":15,"x":6,"y":1,"z":-7},{"name":"Rock_Sandstone_Cobble","x":6,"y":0,"z":-6},{"name":"Rubble_Sandstone","support":15,"x":6,"y":1,"z":-6},{"name":"Wood_Drywood_Beam","rotation":4,"x":6,"y":6,"z":-6},{"name":"Rock_Sandstone_Cobble","x":6,"y":0,"z":-5},{"name":"Wood_Sticks","support":15,"x":6,"y":1,"z":-5},{"name":"Wood_Drywood_Beam","rotation":4,"x":6,"y":6,"z":-5},{"name":"Rock_Sandstone_Cobble","x":6,"y":0,"z":-4},{"name":"Wood_Drywood_Planks","x":6,"y":6,"z":-4},{"name":"Rock_Sandstone_Cobble","x":6,"y":0,"z":-3},{"name":"Wood_Drywood_Planks","x":6,"y":6,"z":-3},{"name":"Rock_Sandstone_Cobble","x":6,"y":0,"z":-2},{"name":"Wood_Drywood_Planks","x":6,"y":6,"z":-2},{"name":"Rock_Sandstone_Cobble","x":6,"y":0,"z":-1},{"name":"Rock_Sandstone_White_Brick","x":6,"y":1,"z":-1},{"name":"Rock_Sandstone_White_Brick","x":6,"y":2,"z":-1},{"name":"Rock_Sandstone_White_Brick","x":6,"y":3,"z":-1},{"name":"Rock_Sandstone_White_Brick","x":6,"y":4,"z":-1},{"name":"Rock_Sandstone_White_Brick","x":6,"y":5,"z":-1},{"name":"Rock_Sandstone_Brick_Ornate","x":6,"y":6,"z":-1},{"name":"Rock_Sandstone_White_Brick","x":6,"y":7,"z":-1},{"name":"Rock_Sandstone_Brick","x":6,"y":0,"z":0},{"name":"Rock_Sandstone_Brick","x":7,"y":0,"z":-9},{"name":"Rock_Sandstone_Brick_Pillar_Base","x":7,"y":1,"z":-9},{"name":"Rubble_Sandstone","support":15,"x":7,"y":2,"z":-9},{"name":"Rock_Sandstone_Cobble","x":7,"y":0,"z":-8},{"name":"Rock_Sandstone_White_Brick","x":7,"y":1,"z":-8},{"name":"Rock_Sandstone_Cobble","x":7,"y":0,"z":-7},{"name":"Rubble_Sandstone_White_Medium","support":15,"x":7,"y":1,"z":-7},{"name":"Wood_Drywood_Beam","rotation":4,"x":7,"y":6,"z":-7},{"name":"Rock_Sandstone_Cobble","x":7,"y":0,"z":-6},{"name":"Rubble_Sandstone_Medium","support":15,"x":7,"y":1,"z":-6},{"name":"Wood_Dry_Branch_Long","rotation":4,"support":15,"x":7,"y":6,"z":-6},{"name":"Rock_Sandstone_Cobble","x":7,"y":0,"z":-5},{"name":"Wood_Dry_Branch_Long","rotation":4,"support":15,"x":7,"y":6,"z":-5},{"name":"Rock_Sandstone_Cobble","x":7,"y":0,"z":-4},{"name":"Rock_Sandstone_Brick_Half","rotation":8,"x":7,"y":5,"z":-4},{"name":"Wood_Drywood_Planks","x":7,"y":6,"z":-4},{"name":"Rock_Sandstone_Cobble","x":7,"y":0,"z":-3},{"name":"Rock_Sandstone_Brick_Half","rotation":8,"x":7,"y":5,"z":-3},{"name":"Wood_Drywood_Planks","x":7,"y":6,"z":-3},{"name":"Rock_Sandstone_Cobble","x":7,"y":0,"z":-2},{"name":"Rock_Sandstone_Brick_Ornate","x":7,"y":4,"z":-2},{"name":"Rock_Sandstone_Brick_Half","x":7,"y":5,"z":-2},{"name":"Wood_Drywood_Planks","x":7,"y":6,"z":-2},{"name":"Rock_Sandstone_Cobble","x":7,"y":0,"z":-1},{"name":"Rock_Sandstone_White_Brick","x":7,"y":1,"z":-1},{"name":"Rock_Sandstone_White_Brick","x":7,"y":2,"z":-1},{"name":"Rock_Sandstone_White_Brick","x":7,"y":3,"z":-1},{"name":"*Rock_Sandstone_Brick_Smooth_Half_State_Definitions_Block","x":7,"y":4,"z":-1},{"name":"Rock_Sandstone_Brick_Smooth","x":7,"y":5,"z":-1},{"name":"Rock_Sandstone_Brick_Ornate","x":7,"y":6,"z":-1},{"name":"Rock_Sandstone_Brick","x":7,"y":7,"z":-1},{"name":"Rock_Sandstone_Brick_Pillar_Base","x":7,"y":8,"z":-1},{"name":"Rock_Sandstone_Brick","x":7,"y":0,"z":0},{"name":"Rock_Sandstone_Brick_Pillar_Base","x":7,"y":1,"z":0},{"name":"Rock_Sandstone_Brick_Pillar_Middle","x":7,"y":2,"z":0},{"name":"Rock_Sandstone_Brick_Pillar_Middle","x":7,"y":3,"z":0},{"name":"Rock_Sandstone_Brick_Pillar_Middle","x":7,"y":4,"z":0},{"name":"Rock_Sandstone_Brick_Pillar_Base","rotation":8,"x":7,"y":5,"z":0},{"name":"Rock_Sandstone_Brick_Stairs","x":7,"y":6,"z":0},{"name":"Rock_Sandstone_White_Brick_Half","rotation":6,"x":8,"y":0,"z":-9},{"name":"Rock_Sandstone_White_Brick_Half","rotation":6,"x":8,"y":1,"z":-9},{"name":"Rock_Sandstone_White_Brick","x":8,"y":0,"z":-8},{"name":"Rock_Sandstone_White_Brick","x":8,"y":1,"z":-8},{"name":"Rock_Sandstone_White_Brick","x":8,"y":2,"z":-8},{"name":"Rock_Sandstone_White_Cobble_Half","x":8,"y":3,"z":-8},{"name":"Rock_Sandstone_Cobble","x":8,"y":0,"z":-7},{"name":"Rock_Sandstone_White_Brick","x":8,"y":1,"z":-7},{"name":"Rock_Sandstone_White_Brick","x":8,"y":2,"z":-7},{"name":"Rock_Sandstone_White_Cobble","x":8,"y":3,"z":-7},{"name":"Rubble_Sandstone_White","support":15,"x":8,"y":4,"z":-7},{"name":"Rock_Sandstone_Cobble","x":8,"y":0,"z":-6},{"name":"Rock_Sandstone_White_Brick","x":8,"y":1,"z":-6},{"name":"Rock_Sandstone_White_Brick_Stairs","rotation":3,"x":8,"y":2,"z":-6},{"name":"Rock_Sandstone_White_Brick_Stairs","rotation":10,"x":8,"y":3,"z":-6},{"name":"Rock_Sandstone_White_Brick_Stairs","rotation":3,"x":8,"y":4,"z":-6},{"name":"Rock_Sandstone_White_Cobble_Half","x":8,"y":5,"z":-6},{"name":"Rock_Sandstone_Cobble","x":8,"y":0,"z":-5},{"name":"Rock_Sandstone_White_Brick","x":8,"y":1,"z":-5},{"name":"Furniture_Desert_Window","rotation":1,"x":8,"y":2,"z":-5},{"name":"Wood_Drywood_Beam","x":8,"y":3,"z":-5},{"name":"Wood_Dry_Trunk","rotation":4,"support":15,"x":8,"y":5,"z":-5},{"name":"Rock_Sandstone_Brick_Ornate","x":8,"y":6,"z":-5},{"name":"Rock_Sandstone_White_Cobble_Half","rotation":6,"x":8,"y":7,"z":-5},{"name":"Rock_Sandstone_Cobble","x":8,"y":0,"z":-4},{"name":"Rock_Sandstone_White_Brick","x":8,"y":1,"z":-4},{"name":"Furniture_Desert_Window","rotation":1,"x":8,"y":2,"z":-4},{"name":"Furniture_Desert_Window","rotation":1,"x":8,"y":3,"z":-4},{"name":"Furniture_Desert_Window","rotation":1,"x":8,"y":4,"z":-4},{"name":"Wood_Dry_Trunk","rotation":4,"support":15,"x":8,"y":5,"z":-4},{"name":"Rock_Sandstone_Brick_Ornate","x":8,"y":6,"z":-4},{"name":"Rock_Sandstone_White_Brick","x":8,"y":7,"z":-4},{"name":"Rock_Sandstone_Cobble","x":8,"y":0,"z":-3},{"name":"Rock_Sandstone_White_Brick","x":8,"y":1,"z":-3},{"name":"Rock_Sandstone_White_Brick","x":8,"y":2,"z":-3},{"name":"Rock_Sandstone_White_Brick","x":8,"y":3,"z":-3},{"name":"Rock_Sandstone_White_Brick","x":8,"y":4,"z":-3},{"name":"Rock_Sandstone_White_Brick","x":8,"y":5,"z":-3},{"name":"Rock_Sandstone_Brick_Ornate","x":8,"y":6,"z":-3},{"name":"Rock_Sandstone_White_Brick","x":8,"y":7,"z":-3},{"name":"Rock_Sandstone_Cobble","x":8,"y":0,"z":-2},{"name":"Rock_Sandstone_White_Brick","x":8,"y":1,"z":-2},{"name":"Rock_Sandstone_White_Brick","x":8,"y":2,"z":-2},{"name":"Rock_Sandstone_White_Brick","x":8,"y":3,"z":-2},{"name":"Rock_Sandstone_Brick_Smooth","x":8,"y":4,"z":-2},{"name":"Rock_Sandstone_Brick_Smooth","x":8,"y":5,"z":-2},{"name":"Rock_Sandstone_Brick_Ornate","x":8,"y":6,"z":-2},{"name":"Rock_Sandstone_Brick","x":8,"y":7,"z":-2},{"name":"Rubble_Sandstone","support":15,"x":8,"y":8,"z":-2},{"name":"Rock_Sandstone_White_Brick","x":8,"y":0,"z":-1},{"name":"Rock_Sandstone_White_Brick","x":8,"y":1,"z":-1},{"name":"Rock_Sandstone_White_Brick_Stairs","rotation":1,"x":8,"y":2,"z":-1},{"name":"Rock_Sandstone_White_Brick_Stairs","rotation":10,"x":8,"y":3,"z":-1},{"name":"Rock_Sandstone_White_Brick_Stairs","x":8,"y":4,"z":-1},{"name":"Rock_Sandstone_Brick","x":8,"y":5,"z":-1},{"name":"Rock_Sandstone_Brick_Ornate","x":8,"y":6,"z":-1},{"name":"Rock_Sandstone_Brick","x":8,"y":7,"z":-1},{"name":"Rubble_Sandstone_Medium","support":15,"x":8,"y":8,"z":-1},{"name":"Rock_Sandstone_White_Brick_Half","rotation":4,"x":8,"y":0,"z":0},{"name":"Rock_Sandstone_White_Brick_Half","rotation":4,"x":8,"y":1,"z":0},{"name":"Rock_Sandstone_White_Brick_Half","rotation":5,"x":9,"y":0,"z":-8},{"name":"Rock_Sandstone_White_Brick_Half","rotation":5,"x":9,"y":1,"z":-8},{"name":"Rock_Sandstone_Brick","x":9,"y":0,"z":-7},{"name":"Rock_Sandstone_Brick_Pillar_Base","x":9,"y":1,"z":-7},{"name":"Rock_Sandstone_Brick_Pillar_Middle","x":9,"y":2,"z":-7},{"name":"Rock_Sandstone_Brick_Pillar_Middle","x":9,"y":3,"z":-7},{"name":"Rock_Sandstone_Brick","x":9,"y":0,"z":-6},{"name":"Rock_Sandstone_Brick","x":9,"y":0,"z":-5},{"name":"Rock_Sandstone_Brick","x":9,"y":0,"z":-4},{"name":"Soil_Clay_Ocean_Brick_Roof_Hollow","rotation":1,"x":9,"y":5,"z":-4},{"name":"Rock_Sandstone_Brick","x":9,"y":0,"z":-3},{"name":"Rock_Sandstone_Brick","x":9,"y":0,"z":-2},{"name":"Rock_Sandstone_Brick_Pillar_Base","x":9,"y":1,"z":-2},{"name":"Rock_Sandstone_Brick_Pillar_Middle","x":9,"y":2,"z":-2},{"name":"Rock_Sandstone_Brick_Pillar_Middle","x":9,"y":3,"z":-2},{"name":"Rock_Sandstone_Brick_Pillar_Middle","x":9,"y":4,"z":-2},{"name":"Rock_Sandstone_Brick_Pillar_Base","rotation":8,"x":9,"y":5,"z":-2},{"name":"Rock_Sandstone_Brick_Stairs","rotation":1,"x":9,"y":6,"z":-2},{"name":"Rock_Sandstone_White_Brick_Half","rotation":5,"x":9,"y":0,"z":-1}],"fluids":[{"level":1,"name":"Water_Source","x":0,"y":0,"z":-8},{"level":1,"name":"Water_Source","x":0,"y":1,"z":-8},{"level":1,"name":"Water_Source","x":0,"y":0,"z":-7},{"level":1,"name":"Water_Source","x":0,"y":1,"z":-7},{"level":1,"name":"Water_Source","x":0,"y":2,"z":-7},{"level":1,"name":"Water_Source","x":0,"y":3,"z":-7},{"level":1,"name":"Water_Source","x":0,"y":4,"z":-7},{"level":1,"name":"Water_Source","x":0,"y":0,"z":-2},{"level":1,"name":"Water_Source","x":0,"y":1,"z":-2},{"level":1,"name":"Water_Source","x":0,"y":2,"z":-2},{"level":1,"name":"Water_Source","x":0,"y":3,"z":-2},{"level":1,"name":"Water_Source","x":0,"y":4,"z":-2},{"level":1,"name":"Water_Source","x":0,"y":5,"z":-2},{"level":1,"name":"Water_Source","x":0,"y":6,"z":-2},{"level":1,"name":"Water_Source","x":0,"y":0,"z":-1},{"level":1,"name":"Water_Source","x":0,"y":1,"z":-1},{"level":1,"name":"Water_Source","x":1,"y":0,"z":-9},{"level":1,"name":"Water_Source","x":1,"y":1,"z":-9},{"level":1,"name":"Water_Source","x":1,"y":0,"z":-8},{"level":1,"name":"Water_Source","x":1,"y":1,"z":-8},{"level":1,"name":"Water_Source","x":1,"y":2,"z":-8},{"level":1,"name":"Water_Source","x":1,"y":3,"z":-8},{"level":1,"name":"Water_Source","x":1,"y":4,"z":-8},{"level":1,"name":"Water_Source","x":1,"y":5,"z":-8},{"level":1,"name":"Water_Source","x":1,"y":6,"z":-8},{"level":1,"name":"Water_Source","x":1,"y":0,"z":-7},{"level":1,"name":"Water_Source","x":1,"y":1,"z":-7},{"level":1,"name":"Water_Source","x":1,"y":2,"z":-7},{"level":1,"name":"Water_Source","x":1,"y":3,"z":-7},{"level":1,"name":"Water_Source","x":1,"y":4,"z":-7},{"level":1,"name":"Water_Source","x":1,"y":5,"z":-7},{"level":1,"name":"Water_Source","x":1,"y":6,"z":-7},{"level":1,"name":"Water_Source","x":1,"y":0,"z":-6},{"level":1,"name":"Water_Source","x":1,"y":4,"z":-6},{"level":1,"name":"Water_Source","x":1,"y":5,"z":-6},{"level":1,"name":"Water_Source","x":1,"y":6,"z":-6},{"level":1,"name":"Water_Source","x":1,"y":7,"z":-6},{"level":1,"name":"Water_Source","x":1,"y":0,"z":-5},{"level":1,"name":"Water_Source","x":1,"y":5,"z":-5},{"level":1,"name":"Water_Source","x":1,"y":6,"z":-5},{"level":1,"name":"Water_Source","x":1,"y":7,"z":-5},{"level":1,"name":"Water_Source","x":1,"y":0,"z":-4},{"level":1,"name":"Water_Source","x":1,"y":5,"z":-4},{"level":1,"name":"Water_Source","x":1,"y":6,"z":-4},{"level":1,"name":"Water_Source","x":1,"y":7,"z":-4},{"level":1,"name":"Water_Source","x":1,"y":0,"z":-3},{"level":1,"name":"Water_Source","x":1,"y":5,"z":-3},{"level":1,"name":"Water_Source","x":1,"y":6,"z":-3},{"level":1,"name":"Water_Source","x":1,"y":7,"z":-3},{"level":1,"name":"Water_Source","x":1,"y":0,"z":-2},{"level":1,"name":"Water_Source","x":1,"y":1,"z":-2},{"level":1,"name":"Water_Source","x":1,"y":2,"z":-2},{"level":1,"name":"Water_Source","x":1,"y":3,"z":-2},{"level":1,"name":"Water_Source","x":1,"y":4,"z":-2},{"level":1,"name":"Water_Source","x":1,"y":5,"z":-2},{"level":1,"name":"Water_Source","x":1,"y":6,"z":-2},{"level":1,"name":"Water_Source","x":1,"y":7,"z":-2},{"level":1,"name":"Water_Source","x":1,"y":8,"z":-2},{"level":1,"name":"Water_Source","x":1,"y":0,"z":-1},{"level":1,"name":"Water_Source","x":1,"y":1,"z":-1},{"level":1,"name":"Water_Source","x":1,"y":2,"z":-1},{"level":1,"name":"Water_Source","x":1,"y":3,"z":-1},{"level":1,"name":"Water_Source","x":1,"y":4,"z":-1},{"level":1,"name":"Water_Source","x":1,"y":5,"z":-1},{"level":1,"name":"Water_Source","x":1,"y":6,"z":-1},{"level":1,"name":"Water_Source","x":1,"y":7,"z":-1},{"level":1,"name":"Water_Source","x":1,"y":8,"z":-1},{"level":1,"name":"Water_Source","x":1,"y":0,"z":0},{"level":1,"name":"Water_Source","x":1,"y":1,"z":0},{"level":1,"name":"Water_Source","x":2,"y":0,"z":-9},{"level":1,"name":"Water_Source","x":2,"y":1,"z":-9},{"level":1,"name":"Water_Source","x":2,"y":2,"z":-9},{"level":1,"name":"Water_Source","x":2,"y":3,"z":-9},{"level":1,"name":"Water_Source","x":2,"y":4,"z":-9},{"level":1,"name":"Water_Source","x":2,"y":5,"z":-9},{"level":1,"name":"Water_Source","x":2,"y":6,"z":-9},{"level":1,"name":"Water_Source","x":2,"y":0,"z":-8},{"level":1,"name":"Water_Source","x":2,"y":1,"z":-8},{"level":1,"name":"Water_Source","x":2,"y":2,"z":-8},{"level":1,"name":"Water_Source","x":2,"y":3,"z":-8},{"level":1,"name":"Water_Source","x":2,"y":4,"z":-8},{"level":1,"name":"Water_Source","x":2,"y":5,"z":-8},{"level":1,"name":"Water_Source","x":2,"y":6,"z":-8},{"level":1,"name":"Water_Source","x":2,"y":7,"z":-8},{"level":1,"name":"Water_Source","x":2,"y":8,"z":-8},{"level":1,"name":"Water_Source","x":2,"y":0,"z":-7},{"level":1,"name":"Water_Source","x":2,"y":4,"z":-7},{"level":1,"name":"Water_Source","x":2,"y":5,"z":-7},{"level":1,"name":"Water_Source","x":2,"y":6,"z":-7},{"level":1,"name":"Water_Source","x":2,"y":0,"z":-6},{"level":1,"name":"Water_Source","x":2,"y":4,"z":-6},{"level":1,"name":"Water_Source","x":2,"y":5,"z":-6},{"level":1,"name":"Water_Source","x":2,"y":6,"z":-6},{"level":1,"name":"Water_Source","x":2,"y":0,"z":-5},{"level":1,"name":"Water_Source","x":2,"y":3,"z":-5},{"level":1,"name":"Water_Source","x":2,"y":4,"z":-5},{"level":1,"name":"Water_Source","x":2,"y":5,"z":-5},{"level":1,"name":"Water_Source","x":2,"y":6,"z":-5},{"level":1,"name":"Water_Source","x":2,"y":0,"z":-4},{"level":1,"name":"Water_Source","x":2,"y":3,"z":-4},{"level":1,"name":"Water_Source","x":2,"y":4,"z":-4},{"level":1,"name":"Water_Source","x":2,"y":5,"z":-4},{"level":1,"name":"Water_Source","x":2,"y":6,"z":-4},{"level":1,"name":"Water_Source","x":2,"y":0,"z":-3},{"level":1,"name":"Water_Source","x":2,"y":4,"z":-3},{"level":1,"name":"Water_Source","x":2,"y":5,"z":-3},{"level":1,"name":"Water_Source","x":2,"y":6,"z":-3},{"level":1,"name":"Water_Source","x":2,"y":0,"z":-2},{"level":1,"name":"Water_Source","x":2,"y":4,"z":-2},{"level":1,"name":"Water_Source","x":2,"y":5,"z":-2},{"level":1,"name":"Water_Source","x":2,"y":6,"z":-2},{"level":1,"name":"Water_Source","x":2,"y":0,"z":-1},{"level":1,"name":"Water_Source","x":2,"y":1,"z":-1},{"level":1,"name":"Water_Source","x":2,"y":2,"z":-1},{"level":1,"name":"Water_Source","x":2,"y":3,"z":-1},{"level":1,"name":"Water_Source","x":2,"y":4,"z":-1},{"level":1,"name":"Water_Source","x":2,"y":5,"z":-1},{"level":1,"name":"Water_Source","x":2,"y":6,"z":-1},{"level":1,"name":"Water_Source","x":2,"y":7,"z":-1},{"level":1,"name":"Water_Source","x":2,"y":8,"z":-1},{"level":1,"name":"Water_Source","x":2,"y":0,"z":0},{"level":1,"name":"Water_Source","x":2,"y":1,"z":0},{"level":1,"name":"Water_Source","x":2,"y":2,"z":0},{"level":1,"name":"Water_Source","x":2,"y":3,"z":0},{"level":1,"name":"Water_Source","x":2,"y":4,"z":0},{"level":1,"name":"Water_Source","x":2,"y":5,"z":0},{"level":1,"name":"Water_Source","x":2,"y":6,"z":0},{"level":1,"name":"Water_Source","x":3,"y":0,"z":-8},{"level":1,"name":"Water_Source","x":3,"y":3,"z":-8},{"level":1,"name":"Water_Source","x":3,"y":4,"z":-8},{"level":1,"name":"Water_Source","x":3,"y":5,"z":-8},{"level":1,"name":"Water_Source","x":3,"y":6,"z":-8},{"level":1,"name":"Water_Source","x":3,"y":7,"z":-8},{"level":1,"name":"Water_Source","x":3,"y":8,"z":-8},{"level":1,"name":"Water_Source","x":3,"y":0,"z":-7},{"level":1,"name":"Water_Source","x":3,"y":4,"z":-7},{"level":1,"name":"Water_Source","x":3,"y":5,"z":-7},{"level":1,"name":"Water_Source","x":3,"y":6,"z":-7},{"level":1,"name":"Water_Source","x":3,"y":0,"z":-6},{"level":1,"name":"Water_Source","x":3,"y":1,"z":-6},{"level":1,"name":"Water_Source","x":3,"y":2,"z":-6},{"level":1,"name":"Water_Source","x":3,"y":3,"z":-6},{"level":1,"name":"Water_Source","x":3,"y":4,"z":-6},{"level":1,"name":"Water_Source","x":3,"y":5,"z":-6},{"level":1,"name":"Water_Source","x":3,"y":6,"z":-6},{"level":1,"name":"Water_Source","x":3,"y":0,"z":-5},{"level":1,"name":"Water_Source","x":3,"y":1,"z":-5},{"level":1,"name":"Water_Source","x":3,"y":2,"z":-5},{"level":1,"name":"Water_Source","x":3,"y":3,"z":-5},{"level":1,"name":"Water_Source","x":3,"y":4,"z":-5},{"level":1,"name":"Water_Source","x":3,"y":0,"z":-4},{"level":1,"name":"Water_Source","x":3,"y":6,"z":-4},{"level":1,"name":"Water_Source","x":3,"y":0,"z":-3},{"level":1,"name":"Water_Source","x":3,"y":6,"z":-3},{"level":1,"name":"Water_Source","x":3,"y":0,"z":-2},{"level":1,"name":"Water_Source","x":3,"y":6,"z":-2},{"level":1,"name":"Water_Source","x":3,"y":0,"z":-1},{"level":1,"name":"Water_Source","x":3,"y":1,"z":-1},{"level":1,"name":"Water_Source","x":3,"y":2,"z":-1},{"level":1,"name":"Water_Source","x":3,"y":3,"z":-1},{"level":1,"name":"Water_Source","x":3,"y":4,"z":-1},{"level":1,"name":"Water_Source","x":3,"y":5,"z":-1},{"level":1,"name":"Water_Source","x":3,"y":6,"z":-1},{"level":1,"name":"Water_Source","x":3,"y":7,"z":-1},{"level":1,"name":"Water_Source","x":3,"y":0,"z":0},{"level":1,"name":"Water_Source","x":4,"y":0,"z":-8},{"level":1,"name":"Water_Source","x":4,"y":4,"z":-8},{"level":1,"name":"Water_Source","x":4,"y":5,"z":-8},{"level":1,"name":"Water_Source","x":4,"y":6,"z":-8},{"level":1,"name":"Water_Source","x":4,"y":7,"z":-8},{"level":1,"name":"Water_Source","x":4,"y":8,"z":-8},{"level":1,"name":"Water_Source","x":4,"y":0,"z":-7},{"level":1,"name":"Water_Source","x":4,"y":5,"z":-7},{"level":1,"name":"Water_Source","x":4,"y":6,"z":-7},{"level":1,"name":"Water_Source","x":4,"y":0,"z":-6},{"level":1,"name":"Water_Source","x":4,"y":1,"z":-6},{"level":1,"name":"Water_Source","x":4,"y":6,"z":-6},{"level":1,"name":"Water_Source","x":4,"y":0,"z":-5},{"level":1,"name":"Water_Source","x":4,"y":6,"z":-5},{"level":1,"name":"Water_Source","x":4,"y":0,"z":-4},{"level":1,"name":"Water_Source","x":4,"y":6,"z":-4},{"level":1,"name":"Water_Source","x":4,"y":0,"z":-3},{"level":1,"name":"Water_Source","x":4,"y":6,"z":-3},{"level":1,"name":"Water_Source","x":4,"y":0,"z":-2},{"level":1,"name":"Water_Source","x":4,"y":6,"z":-2},{"level":1,"name":"Water_Source","x":4,"y":0,"z":-1},{"level":1,"name":"Water_Source","x":4,"y":1,"z":-1},{"level":1,"name":"Water_Source","x":4,"y":2,"z":-1},{"level":1,"name":"Water_Source","x":4,"y":3,"z":-1},{"level":1,"name":"Water_Source","x":4,"y":6,"z":-1},{"level":1,"name":"Water_Source","x":4,"y":7,"z":-1},{"level":1,"name":"Water_Source","x":4,"y":0,"z":0},{"level":1,"name":"Water_Source","x":5,"y":0,"z":-8},{"level":1,"name":"Water_Source","x":5,"y":5,"z":-8},{"level":1,"name":"Water_Source","x":5,"y":6,"z":-8},{"level":1,"name":"Water_Source","x":5,"y":7,"z":-8},{"level":1,"name":"Water_Source","x":5,"y":0,"z":-7},{"level":1,"name":"Water_Source","x":5,"y":5,"z":-7},{"level":1,"name":"Water_Source","x":5,"y":6,"z":-7},{"level":1,"name":"Water_Source","x":5,"y":0,"z":-6},{"level":1,"name":"Water_Source","x":5,"y":6,"z":-6},{"level":1,"name":"Water_Source","x":5,"y":0,"z":-5},{"level":1,"name":"Water_Source","x":5,"y":6,"z":-5},{"level":1,"name":"Water_Source","x":5,"y":0,"z":-4},{"level":1,"name":"Water_Source","x":5,"y":6,"z":-4},{"level":1,"name":"Water_Source","x":5,"y":0,"z":-3},{"level":1,"name":"Water_Source","x":5,"y":6,"z":-3},{"level":1,"name":"Water_Source","x":5,"y":0,"z":-2},{"level":1,"name":"Water_Source","x":5,"y":6,"z":-2},{"level":1,"name":"Water_Source","x":5,"y":0,"z":-1},{"level":1,"name":"Water_Source","x":5,"y":1,"z":-1},{"level":1,"name":"Water_Source","x":5,"y":2,"z":-1},{"level":1,"name":"Water_Source","x":5,"y":5,"z":-1},{"level":1,"name":"Water_Source","x":5,"y":6,"z":-1},{"level":1,"name":"Water_Source","x":5,"y":7,"z":-1},{"level":1,"name":"Water_Source","x":5,"y":0,"z":0},{"level":1,"name":"Water_Source","x":5,"y":5,"z":0},{"level":1,"name":"Water_Source","x":6,"y":0,"z":-8},{"level":1,"name":"Water_Source","x":6,"y":0,"z":-7},{"level":1,"name":"Water_Source","x":6,"y":1,"z":-7},{"level":1,"name":"Water_Source","x":6,"y":0,"z":-6},{"level":1,"name":"Water_Source","x":6,"y":1,"z":-6},{"level":1,"name":"Water_Source","x":6,"y":6,"z":-6},{"level":1,"name":"Water_Source","x":6,"y":0,"z":-5},{"level":1,"name":"Water_Source","x":6,"y":1,"z":-5},{"level":1,"name":"Water_Source","x":6,"y":6,"z":-5},{"level":1,"name":"Water_Source","x":6,"y":0,"z":-4},{"level":1,"name":"Water_Source","x":6,"y":6,"z":-4},{"level":1,"name":"Water_Source","x":6,"y":0,"z":-3},{"level":1,"name":"Water_Source","x":6,"y":6,"z":-3},{"level":1,"name":"Water_Source","x":6,"y":0,"z":-2},{"level":1,"name":"Water_Source","x":6,"y":6,"z":-2},{"level":1,"name":"Water_Source","x":6,"y":0,"z":-1},{"level":1,"name":"Water_Source","x":6,"y":1,"z":-1},{"level":1,"name":"Water_Source","x":6,"y":2,"z":-1},{"level":1,"name":"Water_Source","x":6,"y":3,"z":-1},{"level":1,"name":"Water_Source","x":6,"y":4,"z":-1},{"level":1,"name":"Water_Source","x":6,"y":5,"z":-1},{"level":1,"name":"Water_Source","x":6,"y":6,"z":-1},{"level":1,"name":"Water_Source","x":6,"y":7,"z":-1},{"level":1,"name":"Water_Source","x":6,"y":0,"z":0},{"level":1,"name":"Water_Source","x":7,"y":0,"z":-9},{"level":1,"name":"Water_Source","x":7,"y":1,"z":-9},{"level":1,"name":"Water_Source","x":7,"y":2,"z":-9},{"level":1,"name":"Water_Source","x":7,"y":0,"z":-8},{"level":1,"name":"Water_Source","x":7,"y":1,"z":-8},{"level":1,"name":"Water_Source","x":7,"y":0,"z":-7},{"level":1,"name":"Water_Source","x":7,"y":1,"z":-7},{"level":1,"name":"Water_Source","x":7,"y":6,"z":-7},{"level":1,"name":"Water_Source","x":7,"y":0,"z":-6},{"level":1,"name":"Water_Source","x":7,"y":1,"z":-6},{"level":1,"name":"Water_Source","x":7,"y":6,"z":-6},{"level":1,"name":"Water_Source","x":7,"y":0,"z":-5},{"level":1,"name":"Water_Source","x":7,"y":6,"z":-5},{"level":1,"name":"Water_Source","x":7,"y":0,"z":-4},{"level":1,"name":"Water_Source","x":7,"y":5,"z":-4},{"level":1,"name":"Water_Source","x":7,"y":6,"z":-4},{"level":1,"name":"Water_Source","x":7,"y":0,"z":-3},{"level":1,"name":"Water_Source","x":7,"y":5,"z":-3},{"level":1,"name":"Water_Source","x":7,"y":6,"z":-3},{"level":1,"name":"Water_Source","x":7,"y":0,"z":-2},{"level":1,"name":"Water_Source","x":7,"y":4,"z":-2},{"level":1,"name":"Water_Source","x":7,"y":5,"z":-2},{"level":1,"name":"Water_Source","x":7,"y":6,"z":-2},{"level":1,"name":"Water_Source","x":7,"y":0,"z":-1},{"level":1,"name":"Water_Source","x":7,"y":1,"z":-1},{"level":1,"name":"Water_Source","x":7,"y":2,"z":-1},{"level":1,"name":"Water_Source","x":7,"y":3,"z":-1},{"level":1,"name":"Water_Source","x":7,"y":4,"z":-1},{"level":1,"name":"Water_Source","x":7,"y":5,"z":-1},{"level":1,"name":"Water_Source","x":7,"y":6,"z":-1},{"level":1,"name":"Water_Source","x":7,"y":7,"z":-1},{"level":1,"name":"Water_Source","x":7,"y":8,"z":-1},{"level":1,"name":"Water_Source","x":7,"y":0,"z":0},{"level":1,"name":"Water_Source","x":7,"y":1,"z":0},{"level":1,"name":"Water_Source","x":7,"y":2,"z":0},{"level":1,"name":"Water_Source","x":7,"y":3,"z":0},{"level":1,"name":"Water_Source","x":7,"y":4,"z":0},{"level":1,"name":"Water_Source","x":7,"y":5,"z":0},{"level":1,"name":"Water_Source","x":7,"y":6,"z":0},{"level":1,"name":"Water_Source","x":8,"y":0,"z":-9},{"level":1,"name":"Water_Source","x":8,"y":1,"z":-9},{"level":1,"name":"Water_Source","x":8,"y":0,"z":-8},{"level":1,"name":"Water_Source","x":8,"y":1,"z":-8},{"level":1,"name":"Water_Source","x":8,"y":2,"z":-8},{"level":1,"name":"Water_Source","x":8,"y":3,"z":-8},{"level":1,"name":"Water_Source","x":8,"y":0,"z":-7},{"level":1,"name":"Water_Source","x":8,"y":1,"z":-7},{"level":1,"name":"Water_Source","x":8,"y":2,"z":-7},{"level":1,"name":"Water_Source","x":8,"y":3,"z":-7},{"level":1,"name":"Water_Source","x":8,"y":4,"z":-7},{"level":1,"name":"Water_Source","x":8,"y":0,"z":-6},{"level":1,"name":"Water_Source","x":8,"y":1,"z":-6},{"level":1,"name":"Water_Source","x":8,"y":2,"z":-6},{"level":1,"name":"Water_Source","x":8,"y":3,"z":-6},{"level":1,"name":"Water_Source","x":8,"y":4,"z":-6},{"level":1,"name":"Water_Source","x":8,"y":5,"z":-6},{"level":1,"name":"Water_Source","x":8,"y":0,"z":-5},{"level":1,"name":"Water_Source","x":8,"y":1,"z":-5},{"level":1,"name":"Water_Source","x":8,"y":2,"z":-5},{"level":1,"name":"Water_Source","x":8,"y":3,"z":-5},{"level":1,"name":"Water_Source","x":8,"y":5,"z":-5},{"level":1,"name":"Water_Source","x":8,"y":6,"z":-5},{"level":1,"name":"Water_Source","x":8,"y":7,"z":-5},{"level":1,"name":"Water_Source","x":8,"y":0,"z":-4},{"level":1,"name":"Water_Source","x":8,"y":1,"z":-4},{"level":1,"name":"Water_Source","x":8,"y":2,"z":-4},{"level":1,"name":"Water_Source","x":8,"y":3,"z":-4},{"level":1,"name":"Water_Source","x":8,"y":4,"z":-4},{"level":1,"name":"Water_Source","x":8,"y":5,"z":-4},{"level":1,"name":"Water_Source","x":8,"y":6,"z":-4},{"level":1,"name":"Water_Source","x":8,"y":7,"z":-4},{"level":1,"name":"Water_Source","x":8,"y":0,"z":-3},{"level":1,"name":"Water_Source","x":8,"y":1,"z":-3},{"level":1,"name":"Water_Source","x":8,"y":2,"z":-3},{"level":1,"name":"Water_Source","x":8,"y":3,"z":-3},{"level":1,"name":"Water_Source","x":8,"y":4,"z":-3},{"level":1,"name":"Water_Source","x":8,"y":5,"z":-3},{"level":1,"name":"Water_Source","x":8,"y":6,"z":-3},{"level":1,"name":"Water_Source","x":8,"y":7,"z":-3},{"level":1,"name":"Water_Source","x":8,"y":0,"z":-2},{"level":1,"name":"Water_Source","x":8,"y":1,"z":-2},{"level":1,"name":"Water_Source","x":8,"y":2,"z":-2},{"level":1,"name":"Water_Source","x":8,"y":3,"z":-2},{"level":1,"name":"Water_Source","x":8,"y":4,"z":-2},{"level":1,"name":"Water_Source","x":8,"y":5,"z":-2},{"level":1,"name":"Water_Source","x":8,"y":6,"z":-2},{"level":1,"name":"Water_Source","x":8,"y":7,"z":-2},{"level":1,"name":"Water_Source","x":8,"y":8,"z":-2},{"level":1,"name":"Water_Source","x":8,"y":0,"z":-1},{"level":1,"name":"Water_Source","x":8,"y":1,"z":-1},{"level":1,"name":"Water_Source","x":8,"y":2,"z":-1},{"level":1,"name":"Water_Source","x":8,"y":3,"z":-1},{"level":1,"name":"Water_Source","x":8,"y":4,"z":-1},{"level":1,"name":"Water_Source","x":8,"y":5,"z":-1},{"level":1,"name":"Water_Source","x":8,"y":6,"z":-1},{"level":1,"name":"Water_Source","x":8,"y":7,"z":-1},{"level":1,"name":"Water_Source","x":8,"y":8,"z":-1},{"level":1,"name":"Water_Source","x":8,"y":0,"z":0},{"level":1,"name":"Water_Source","x":8,"y":1,"z":0},{"level":1,"name":"Water_Source","x":9,"y":0,"z":-8},{"level":1,"name":"Water_Source","x":9,"y":1,"z":-8},{"level":1,"name":"Water_Source","x":9,"y":0,"z":-7},{"level":1,"name":"Water_Source","x":9,"y":1,"z":-7},{"level":1,"name":"Water_Source","x":9,"y":2,"z":-7},{"level":1,"name":"Water_Source","x":9,"y":3,"z":-7},{"level":1,"name":"Water_Source","x":9,"y":0,"z":-6},{"level":1,"name":"Water_Source","x":9,"y":0,"z":-5},{"level":1,"name":"Water_Source","x":9,"y":0,"z":-4},{"level":1,"name":"Water_Source","x":9,"y":5,"z":-4},{"level":1,"name":"Water_Source","x":9,"y":0,"z":-3},{"level":1,"name":"Water_Source","x":9,"y":0,"z":-2},{"level":1,"name":"Water_Source","x":9,"y":1,"z":-2},{"level":1,"name":"Water_Source","x":9,"y":2,"z":-2},{"level":1,"name":"Water_Source","x":9,"y":3,"z":-2},{"level":1,"name":"Water_Source","x":9,"y":4,"z":-2},{"level":1,"name":"Water_Source","x":9,"y":5,"z":-2},{"level":1,"name":"Water_Source","x":9,"y":6,"z":-2},{"level":1,"name":"Water_Source","x":9,"y":0,"z":-1}],"version":8}