{
  "version": 8,
  "blockIdVersion": 11,
  "anchorX": 0,
  "anchorY": 0,
  "anchorZ": -2,
  "blocks": [
    {
      "x": -2,
      "y": 0,
      "z": -1,
      "name": "Metal_Zinc_Stairs",
      "rotation": 3
    },
    {
      "x": -2,
      "y": 1,
      "z": -1,
      "name": "Metal_Zinc_Half",
      "rotation": 7
    },
    {
      "x": -2,
      "y": 2,
      "z": -1,
      "name": "Wood_Blackwood_Planks_Half",
      "rotation": 7
    },
    {
      "x": -2,
      "y": 3,
      "z": -1,
      "name": "Metal_Zinc_Half",
      "rotation": 7
    },
    {
      "x": -2,
      "y": 0,
      "z": 0,
      "name": "Metal_Zinc"
    },
    {
      "x": -2,
      "y": 1,
      "z": 0,
      "name": "Metal_Zinc_Half",
      "rotation": 7
    },
    {
      "x": -2,
      "y": 2,
      "z": 0,
      "name": "Furniture_Human_Ruins_Window",
      "rotation": 1
    },
    {
      "x": -2,
      "y": 3,
      "z": 0,
      "name": "Wood_Blackwood_Planks_Half",
      "rotation": 7
    },
    {
      "x": -2,
      "y": 4,
      "z": 0,
      "name": "Wood_Blackwood_Planks_Half",
      "rotation": 7
    },
    {
      "x": -2,
      "y": 0,
      "z": 1,
      "name": "Metal_Zinc_Stairs",
      "rotation": 3
    },
    {
      "x": -2,
      "y": 1,
      "z": 1,
      "name": "Metal_Zinc_Half",
      "rotation": 7
    },
    {
      "x": -2,
      "y": 2,
      "z": 1,
      "name": "Wood_Blackwood_Planks_Half",
      "rotation": 7
    },
    {
      "x": -2,
      "y": 3,
      "z": 1,
      "name": "Metal_Zinc_Half",
      "rotation": 7
    },
    {
      "x": -1,
      "y": 0,
      "z": -2,
      "name": "Metal_Zinc_Stairs",
      "rotation": 2
    },
    {
      "x": -1,
      "y": 1,
      "z": -2,
      "name": "Metal_Zinc_Half",
      "rotation": 6
    },
    {
      "x": -1,
      "y": 2,
      "z": -2,
      "name": "Wood_Blackwood_Planks_Half",
      "rotation": 6
    },
    {
      "x": -1,
      "y": 3,
      "z": -2,
      "name": "Metal_Zinc_Half",
      "rotation": 6
    },
    {
      "x": -1,
      "y": 0,
      "z": -1,
      "name": "Furniture_Temple_Dark_Shelf"
    },
    {
      "x": -1,
      "y": 3,
      "z": -1,
      "name": "Furniture_Ancient_Platform"
    },
    {
      "x": -1,
      "y": 4,
      "z": -1,
      "name": "Metal_Zinc"
    },
    {
      "x": -1,
      "y": 5,
      "z": 0,
      "name": "Wood_Blackwood_Stairs",
      "rotation": 3
    },
    {
      "x": -1,
      "y": 0,
      "z": 1,
      "name": "Furniture_Temple_Dark_Shelf",
      "rotation": 2
    },
    {
      "x": -1,
      "y": 3,
      "z": 1,
      "name": "Furniture_Ancient_Platform"
    },
    {
      "x": -1,
      "y": 4,
      "z": 1,
      "name": "Metal_Zinc"
    },
    {
      "x": -1,
      "y": 0,
      "z": 2,
      "name": "Metal_Zinc_Stairs"
    },
    {
      "x": -1,
      "y": 1,
      "z": 2,
      "name": "Metal_Zinc_Half",
      "rotation": 4
    },
    {
      "x": -1,
      "y": 2,
      "z": 2,
      "name": "Wood_Blackwood_Planks_Half",
      "rotation": 4
    },
    {
      "x": -1,
      "y": 3,
      "z": 2,
      "name": "Metal_Zinc_Half",
      "rotation": 4
    },
    {
      "x": 0,
      "y": 0,
      "z": -2,
      "name": "Metal_Zinc"
    },
    {
      "x": 0,
      "y": 1,
      "z": -2,
      "name": "Metal_Zinc_Half",
      "rotation": 6
    },
    {
      "x": 0,
      "y": 2,
      "z": -2,
      "name": "Furniture_Human_Ruins_Window"
    },
    {
      "x": 0,
      "y": 3,
      "z": -2,
      "name": "Wood_Blackwood_Planks_Half",
      "rotation": 6
    },
    {
      "x": 0,
      "y": 4,
      "z": -2,
      "name": "Wood_Blackwood_Planks_Half",
      "rotation": 6
    },
    {
      "x": 0,
      "y": 0,
      "z": -1,
      "name": "Furniture_Temple_Dark_Shelf"
    },
    {
      "x": 0,
      "y": 3,
      "z": -1,
      "name": "Furniture_Ancient_Platform"
    },
    {
      "x": 0,
      "y": 4,
      "z": -1,
      "name": "Furniture_Ancient_Chest_Small",
      "components": {
        "Components": {
          "PlacedByInteraction": {
            "WhoPlacedUuid": {
              "$binary": "1D6Z0/5hSoOPtypqdFwK+g==",
              "$type": "04"
            }
          },
          "ItemContainerBlock": {
            "ItemContainer": {
              "Capacity": 18,
              "Items": {}
            },
            "Capacity": 18
          }
        }
      }
    },
    {
      "x": 0,
      "y": 5,
      "z": -1,
      "name": "Wood_Blackwood_Stairs",
      "rotation": 2
    },
    {
      "x": 0,
      "y": 5,
      "z": 0,
      "name": "Metal_Zinc"
    },
    {
      "x": 0,
      "y": 6,
      "z": 0,
      "name": "Rock_Slate_Stalactite_Large"
    },
    {
      "x": 0,
      "y": 7,
      "z": 0,
      "name": "Rock_Slate_Stalactite_Large",
      "filler": 1024
    },
    {
      "x": 0,
      "y": 0,
      "z": 1,
      "name": "Furniture_Temple_Dark_Shelf",
      "rotation": 2
    },
    {
      "x": 0,
      "y": 3,
      "z": 1,
      "name": "Furniture_Ancient_Platform"
    },
    {
      "x": 0,
      "y": 4,
      "z": 1,
      "name": "Furniture_Human_Ruins_Lantern"
    },
    {
      "x": 0,
      "y": 5,
      "z": 1,
      "name": "Wood_Blackwood_Stairs"
    },
    {
      "x": 0,
      "y": 0,
      "z": 2,
      "name": "Metal_Zinc"
    },
    {
      "x": 0,
      "y": 1,
      "z": 2,
      "name": "Metal_Zinc_Half",
      "rotation": 4
    },
    {
      "x": 0,
      "y": 2,
      "z": 2,
      "name": "Furniture_Human_Ruins_Window"
    },
    {
      "x": 0,
      "y": 3,
      "z": 2,
      "name": "Wood_Blackwood_Planks_Half",
      "rotation": 4
    },
    {
      "x": 0,
      "y": 4,
      "z": 2,
      "name": "Wood_Blackwood_Planks_Half",
      "rotation": 4
    },
    {
      "x": 1,
      "y": 0,
      "z": -2,
      "name": "Metal_Zinc_Stairs",
      "rotation": 2
    },
    {
      "x": 1,
      "y": 1,
      "z": -2,
      "name": "Metal_Zinc_Half",
      "rotation": 6
    },
    {
      "x": 1,
      "y": 2,
      "z": -2,
      "name": "Wood_Blackwood_Planks_Half",
      "rotation": 6
    },
    {
      "x": 1,
      "y": 3,
      "z": -2,
      "name": "Metal_Zinc_Half",
      "rotation": 6
    },
    {
      "x": 1,
      "y": 0,
      "z": -1,
      "name": "Furniture_Temple_Dark_Shelf"
    },
    {
      "x": 1,
      "y": 3,
      "z": -1,
      "name": "Furniture_Ancient_Platform"
    },
    {
      "x": 1,
      "y": 4,
      "z": -1,
      "name": "Metal_Zinc"
    },
    {
      "x": 1,
      "y": 5,
      "z": 0,
      "name": "Wood_Blackwood_Stairs",
      "rotation": 1
    },
    {
      "x": 1,
      "y": 3,
      "z": 1,
      "name": "Furniture_Ancient_Platform"
    },
    {
      "x": 1,
      "y": 4,
      "z": 1,
      "name": "Metal_Zinc"
    },
    {
      "x": 1,
      "y": 1,
      "z": 2,
      "name": "Metal_Zinc_Half",
      "rotation": 4
    },
    {
      "x": 1,
      "y": 2,
      "z": 2,
      "name": "Wood_Blackwood_Planks_Half",
      "rotation": 4
    },
    {
      "x": 1,
      "y": 3,
      "z": 2,
      "name": "Metal_Zinc_Half",
      "rotation": 4
    },
    {
      "x": 2,
      "y": 0,
      "z": -1,
      "name": "Metal_Zinc_Stairs",
      "rotation": 1
    },
    {
      "x": 2,
      "y": 1,
      "z": -1,
      "name": "Metal_Zinc_Half",
      "rotation": 5
    },
    {
      "x": 2,
      "y": 2,
      "z": -1,
      "name": "Wood_Blackwood_Planks_Half",
      "rotation": 5
    },
    {
      "x": 2,
      "y": 3,
      "z": -1,
      "name": "Metal_Zinc_Half",
      "rotation": 5
    },
    {
      "x": 2,
      "y": 1,
      "z": 0,
      "name": "Metal_Zinc_Half",
      "rotation": 5
    },
    {
      "x": 2,
      "y": 3,
      "z": 0,
      "name": "Wood_Blackwood_Planks_Half",
      "rotation": 5
    },
    {
      "x": 2,
      "y": 4,
      "z": 0,
      "name": "Wood_Blackwood_Planks_Half",
      "rotation": 5
    },
    {
      "x": 2,
      "y": 2,
      "z": 1,
      "name": "Wood_Blackwood_Planks_Half",
      "rotation": 5
    },
    {
      "x": 2,
      "y": 3,
      "z": 1,
      "name": "Metal_Zinc_Half",
      "rotation": 5
    }
  ],
  "fluids": [
    {
      "x": -2,
      "y": 0,
      "z": -1,
      "name": "Water_Source",
      "level": 1
    },
    {
      "x": -2,
      "y": 1,
      "z": -1,
      "name": "Water_Source",
      "level": 1
    },
    {
      "x": -2,
      "y": 2,
      "z": -1,
      "name": "Water_Source",
      "level": 1
    },
    {
      "x": -2,
      "y": 3,
      "z": -1,
      "name": "Water_Source",
      "level": 1
    },
    {
      "x": -2,
      "y": 0,
      "z": 0,
      "name": "Water_Source",
      "level": 1
    },
    {
      "x": -2,
      "y": 1,
      "z": 0,
      "name": "Water_Source",
      "level": 1
    },
    {
      "x": -2,
      "y": 2,
      "z": 0,
      "name": "Water_Source",
      "level": 1
    },
    {
      "x": -2,
      "y": 3,
      "z": 0,
      "name": "Water_Source",
      "level": 1
    },
    {
      "x": -2,
      "y": 4,
      "z": 0,
      "name": "Water_Source",
      "level": 1
    },
    {
      "x": -2,
      "y": 0,
      "z": 1,
      "name": "Water_Source",
      "level": 1
    },
    {
      "x": -2,
      "y": 1,
      "z": 1,
      "name": "Water_Source",
      "level": 1
    },
    {
      "x": -2,
      "y": 2,
      "z": 1,
      "name": "Water_Source",
      "level": 1
    },
    {
      "x": -2,
      "y": 3,
      "z": 1,
      "name": "Water_Source",
      "level": 1
    },
    {
      "x": -1,
      "y": 0,
      "z": -2,
      "name": "Water_Source",
      "level": 1
    },
    {
      "x": -1,
      "y": 1,
      "z": -2,
      "name": "Water_Source",
      "level": 1
    },
    {
      "x": -1,
      "y": 2,
      "z": -2,
      "name": "Water_Source",
      "level": 1
    },
    {
      "x": -1,
      "y": 3,
      "z": -2,
      "name": "Water_Source",
      "level": 1
    },
    {
      "x": -1,
      "y": 0,
      "z": -1,
      "name": "Water_Source",
      "level": 1
    },
    {
      "x": -1,
      "y": 5,
      "z": 0,
      "name": "Water_Source",
      "level": 1
    },
    {
      "x": -1,
      "y": 0,
      "z": 1,
      "name": "Water_Source",
      "level": 1
    },
    {
      "x": -1,
      "y": 0,
      "z": 2,
      "name": "Water_Source",
      "level": 1
    },
    {
      "x": -1,
      "y": 1,
      "z": 2,
      "name": "Water_Source",
      "level": 1
    },
    {
      "x": -1,
      "y": 2,
      "z": 2,
      "name": "Water_Source",
      "level": 1
    },
    {
      "x": -1,
      "y": 3,
      "z": 2,
      "name": "Water_Source",
      "level": 1
    },
    {
      "x": 0,
      "y": 0,
      "z": -2,
      "name": "Water_Source",
      "level": 1
    },
    {
      "x": 0,
      "y": 1,
      "z": -2,
      "name": "Water_Source",
      "level": 1
    },
    {
      "x": 0,
      "y": 2,
      "z": -2,
      "name": "Water_Source",
      "level": 1
    },
    {
      "x": 0,
      "y": 3,
      "z": -2,
      "name": "Water_Source",
      "level": 1
    },
    {
      "x": 0,
      "y": 4,
      "z": -2,
      "name": "Water_Source",
      "level": 1
    },
    {
      "x": 0,
      "y": 0,
      "z": -1,
      "name": "Water_Source",
      "level": 1
    },
    {
      "x": 0,
      "y": 5,
      "z": -1,
      "name": "Water_Source",
      "level": 1
    },
    {
      "x": 0,
      "y": 5,
      "z": 0,
      "name": "Water_Source",
      "level": 1
    },
    {
      "x": 0,
      "y": 6,
      "z": 0,
      "name": "Water_Source",
      "level": 1
    },
    {
      "x": 0,
      "y": 7,
      "z": 0,
      "name": "Water_Source",
      "level": 1
    },
    {
      "x": 0,
      "y": 0,
      "z": 1,
      "name": "Water_Source",
      "level": 1
    },
    {
      "x": 0,
      "y": 5,
      "z": 1,
      "name": "Water_Source",
      "level": 1
    },
    {
      "x": 0,
      "y": 0,
      "z": 2,
      "name": "Water_Source",
      "level": 1
    },
    {
      "x": 0,
      "y": 1,
      "z": 2,
      "name": "Water_Source",
      "level": 1
    },
    {
      "x": 0,
      "y": 2,
      "z": 2,
      "name": "Water_Source",
      "level": 1
    },
    {
      "x": 0,
      "y": 3,
      "z": 2,
      "name": "Water_Source",
      "level": 1
    },
    {
      "x": 0,
      "y": 4,
      "z": 2,
      "name": "Water_Source",
      "level": 1
    },
    {
      "x": 1,
      "y": 0,
      "z": -2,
      "name": "Water_Source",
      "level": 1
    },
    {
      "x": 1,
      "y": 1,
      "z": -2,
      "name": "Water_Source",
      "level": 1
    },
    {
      "x": 1,
      "y": 2,
      "z": -2,
      "name": "Water_Source",
      "level": 1
    },
    {
      "x": 1,
      "y": 3,
      "z": -2,
      "name": "Water_Source",
      "level": 1
    },
    {
      "x": 1,
      "y": 0,
      "z": -1,
      "name": "Water_Source",
      "level": 1
    },
    {
      "x": 1,
      "y": 5,
      "z": 0,
      "name": "Water_Source",
      "level": 1
    },
    {
      "x": 1,
      "y": 1,
      "z": 2,
      "name": "Water_Source",
      "level": 1
    },
    {
      "x": 1,
      "y": 2,
      "z": 2,
      "name": "Water_Source",
      "level": 1
    },
    {
      "x": 1,
      "y": 3,
      "z": 2,
      "name": "Water_Source",
      "level": 1
    },
    {
      "x": 2,
      "y": 0,
      "z": -1,
      "name": "Water_Source",
      "level": 1
    },
    {
      "x": 2,
      "y": 1,
      "z": -1,
      "name": "Water_Source",
      "level": 1
    },
    {
      "x": 2,
      "y": 2,
      "z": -1,
      "name": "Water_Source",
      "level": 1
    },
    {
      "x": 2,
      "y": 3,
      "z": -1,
      "name": "Water_Source",
      "level": 1
    },
    {
      "x": 2,
      "y": 1,
      "z": 0,
      "name": "Water_Source",
      "level": 1
    },
    {
      "x": 2,
      "y": 3,
      "z": 0,
      "name": "Water_Source",
      "level": 1
    },
    {
      "x": 2,
      "y": 4,
      "z": 0,
      "name": "Water_Source",
      "level": 1
    },
    {
      "x": 2,
      "y": 2,
      "z": 1,
      "name": "Water_Source",
      "level": 1
    },
    {
      "x": 2,
      "y": 3,
      "z": 1,
      "name": "Water_Source",
      "level": 1
    }
  ]
}