{"anchorX":0,"anchorY":0,"anchorZ":0,"blockIdVersion":11,"blocks":[{"name":"Plant_Coral_Block_Yellow","x":-2,"y":1,"z":-1},{"name":"Plant_Coral_Block_Yellow","x":-2,"y":1,"z":0},{"name":"Plant_Coral_Bush_Yellow","x":-2,"y":2,"z":0},{"name":"Plant_Coral_Block_Yellow","x":-2,"y":1,"z":1},{"name":"Plant_Coral_Block_Yellow","x":-1,"y":1,"z":-2},{"name":"Plant_Coral_Bush_Yellow","x":-1,"y":2,"z":-2},{"name":"Plant_Coral_Block_Yellow","x":-1,"y":1,"z":-1},{"name":"Plant_Coral_Block_Yellow","x":-1,"y":0,"z":0},{"name":"Plant_Coral_Block_Yellow","x":-1,"y":1,"z":0},{"name":"Plant_Coral_Block_Yellow","x":-1,"y":1,"z":1},{"name":"Plant_Coral_Block_Yellow","x":-1,"y":1,"z":2},{"name":"Plant_Coral_Block_Yellow","x":0,"y":1,"z":-2},{"name":"Plant_Coral_Block_Yellow","x":0,"y":0,"z":-1},{"name":"Plant_Coral_Block_Yellow","x":0,"y":1,"z":-1},{"name":"Plant_Coral_Block_Yellow","x":0,"y":0,"z":0},{"name":"Plant_Coral_Block_Yellow","x":0,"y":1,"z":0},{"name":"Plant_Coral_Bush_Yellow","x":0,"y":2,"z":0},{"name":"Plant_Coral_Block_Yellow","x":0,"y":0,"z":1},{"name":"Plant_Coral_Block_Yellow","x":0,"y":1,"z":1},{"name":"Plant_Coral_Block_Yellow","x":0,"y":1,"z":2},{"name":"Plant_Coral_Bush_Yellow","x":0,"y":2,"z":2},{"name":"Plant_Coral_Block_Yellow","x":1,"y":1,"z":-2},{"name":"Plant_Coral_Bush_Yellow","x":1,"y":2,"z":-2},{"name":"Plant_Coral_Block_Yellow","x":1,"y":1,"z":-1},{"name":"Plant_Coral_Block_Yellow","x":1,"y":0,"z":0},{"name":"Plant_Coral_Block_Yellow","x":1,"y":1,"z":0},{"name":"Plant_Coral_Block_Yellow","x":1,"y":1,"z":1},{"name":"Plant_Coral_Block_Yellow","x":1,"y":1,"z":2},{"name":"Plant_Coral_Block_Yellow","x":2,"y":1,"z":-1},{"name":"Plant_Coral_Bush_Yellow","x":2,"y":2,"z":-1},{"name":"Plant_Coral_Block_Yellow","x":2,"y":1,"z":0},{"name":"Plant_Coral_Block_Yellow","x":2,"y":1,"z":1},{"name":"Plant_Coral_Bush_Yellow","x":2,"y":2,"z":1}],"fluids":[{"level":1,"name":"Water_Source","x":-2,"y":1,"z":-1},{"level":1,"name":"Water_Source","x":-2,"y":1,"z":0},{"level":1,"name":"Water_Source","x":-2,"y":2,"z":0},{"level":1,"name":"Water_Source","x":-2,"y":1,"z":1},{"level":1,"name":"Water_Source","x":-1,"y":1,"z":-2},{"level":1,"name":"Water_Source","x":-1,"y":2,"z":-2},{"level":1,"name":"Water_Source","x":-1,"y":1,"z":-1},{"level":1,"name":"Water_Source","x":-1,"y":0,"z":0},{"level":1,"name":"Water_Source","x":-1,"y":1,"z":0},{"level":1,"name":"Water_Source","x":-1,"y":1,"z":1},{"level":1,"name":"Water_Source","x":-1,"y":1,"z":2},{"level":1,"name":"Water_Source","x":0,"y":1,"z":-2},{"level":1,"name":"Water_Source","x":0,"y":0,"z":-1},{"level":1,"name":"Water_Source","x":0,"y":1,"z":-1},{"level":1,"name":"Water_Source","x":0,"y":0,"z":0},{"level":1,"name":"Water_Source","x":0,"y":1,"z":0},{"level":1,"name":"Water_Source","x":0,"y":2,"z":0},{"level":1,"name":"Water_Source","x":0,"y":0,"z":1},{"level":1,"name":"Water_Source","x":0,"y":1,"z":1},{"level":1,"name":"Water_Source","x":0,"y":1,"z":2},{"level":1,"name":"Water_Source","x":0,"y":2,"z":2},{"level":1,"name":"Water_Source","x":1,"y":1,"z":-2},{"level":1,"name":"Water_Source","x":1,"y":2,"z":-2},{"level":1,"name":"Water_Source","x":1,"y":1,"z":-1},{"level":1,"name":"Water_Source","x":1,"y":0,"z":0},{"level":1,"name":"Water_Source","x":1,"y":1,"z":0},{"level":1,"name":"Water_Source","x":1,"y":1,"z":1},{"level":1,"name":"Water_Source","x":1,"y":1,"z":2},{"level":1,"name":"Water_Source","x":2,"y":1,"z":-1},{"level":1,"name":"Water_Source","x":2,"y":2,"z":-1},{"level":1,"name":"Water_Source","x":2,"y":1,"z":0},{"level":1,"name":"Water_Source","x":2,"y":1,"z":1},{"level":1,"name":"Water_Source","x":2,"y":2,"z":1}],"version":8}