{"anchorX":0,"anchorY":-10,"anchorZ":0,"blockIdVersion":11,"blocks":[{"name":"Plant_Moss_Wall_Yellow","rotation":3,"support":15,"x":-1,"y":0,"z":0},{"name":"Empty","x":-1,"y":1,"z":0},{"name":"Empty","x":-1,"y":2,"z":0},{"name":"Empty","x":-1,"y":3,"z":0},{"name":"Empty","x":-1,"y":4,"z":0},{"name":"Empty","x":-1,"y":5,"z":0},{"name":"Empty","x":-1,"y":6,"z":0},{"name":"Empty","x":-1,"y":7,"z":0},{"name":"Empty","x":-1,"y":8,"z":0},{"name":"Empty","x":-1,"y":9,"z":0},{"name":"Empty","x":-1,"y":10,"z":0},{"name":"Empty","x":-1,"y":11,"z":0},{"name":"Empty","x":-1,"y":12,"z":0},{"name":"Empty","x":-1,"y":13,"z":0},{"name":"Empty","x":-1,"y":14,"z":0},{"name":"Empty","x":-1,"y":15,"z":0},{"name":"Empty","x":-1,"y":16,"z":0},{"name":"Plant_Moss_Wall_Yellow","rotation":2,"support":15,"x":0,"y":0,"z":-1},{"name":"Empty","x":0,"y":1,"z":-1},{"name":"Empty","x":0,"y":2,"z":-1},{"name":"Empty","x":0,"y":3,"z":-1},{"name":"Empty","x":0,"y":4,"z":-1},{"name":"Empty","x":0,"y":5,"z":-1},{"name":"Empty","x":0,"y":6,"z":-1},{"name":"Empty","x":0,"y":7,"z":-1},{"name":"Empty","x":0,"y":8,"z":-1},{"name":"Empty","x":0,"y":9,"z":-1},{"name":"Empty","x":0,"y":10,"z":-1},{"name":"Empty","x":0,"y":11,"z":-1},{"name":"Empty","x":0,"y":12,"z":-1},{"name":"Empty","x":0,"y":13,"z":-1},{"name":"Empty","x":0,"y":14,"z":-1},{"name":"Empty","x":0,"y":15,"z":-1},{"name":"Empty","x":0,"y":16,"z":-1},{"name":"Plant_Seaweed_Dead_Stack","x":0,"y":-10,"z":0},{"name":"Plant_Seaweed_Dead_Stack","x":0,"y":-9,"z":0},{"name":"Plant_Seaweed_Dead_Stack","x":0,"y":-8,"z":0},{"name":"Plant_Seaweed_Dead_Stack","x":0,"y":-7,"z":0},{"name":"Plant_Seaweed_Dead_Stack","x":0,"y":-6,"z":0},{"name":"Plant_Seaweed_Dead_Stack","x":0,"y":-5,"z":0},{"name":"Plant_Seaweed_Dead_Stack","x":0,"y":-4,"z":0},{"name":"Plant_Seaweed_Dead_Stack","x":0,"y":-3,"z":0},{"name":"Plant_Seaweed_Dead_Stack","x":0,"y":-2,"z":0},{"name":"Plant_Seaweed_Dead_Stack","x":0,"y":-1,"z":0},{"name":"Rock_Crystal_Yellow_Block","x":0,"y":0,"z":0},{"name":"Plant_Moss_Rug_Yellow","support":15,"x":0,"y":1,"z":0},{"name":"Empty","x":0,"y":2,"z":0},{"name":"Empty","x":0,"y":3,"z":0},{"name":"Empty","x":0,"y":4,"z":0},{"name":"Empty","x":0,"y":5,"z":0},{"name":"Empty","x":0,"y":6,"z":0},{"name":"Empty","x":0,"y":7,"z":0},{"name":"Empty","x":0,"y":8,"z":0},{"name":"Empty","x":0,"y":9,"z":0},{"name":"Empty","x":0,"y":10,"z":0},{"name":"Empty","x":0,"y":11,"z":0},{"name":"Empty","x":0,"y":12,"z":0},{"name":"Empty","x":0,"y":13,"z":0},{"name":"Empty","x":0,"y":14,"z":0},{"name":"Empty","x":0,"y":15,"z":0},{"name":"Empty","x":0,"y":16,"z":0},{"name":"Plant_Moss_Wall_Yellow","support":15,"x":0,"y":0,"z":1},{"name":"Empty","x":0,"y":1,"z":1},{"name":"Empty","x":0,"y":2,"z":1},{"name":"Empty","x":0,"y":3,"z":1},{"name":"Empty","x":0,"y":4,"z":1},{"name":"Empty","x":0,"y":5,"z":1},{"name":"Empty","x":0,"y":6,"z":1},{"name":"Empty","x":0,"y":7,"z":1},{"name":"Empty","x":0,"y":8,"z":1},{"name":"Empty","x":0,"y":9,"z":1},{"name":"Empty","x":0,"y":10,"z":1},{"name":"Empty","x":0,"y":11,"z":1},{"name":"Empty","x":0,"y":12,"z":1},{"name":"Empty","x":0,"y":13,"z":1},{"name":"Empty","x":0,"y":14,"z":1},{"name":"Empty","x":0,"y":15,"z":1},{"name":"Empty","x":0,"y":16,"z":1},{"name":"Plant_Moss_Wall_Yellow","rotation":1,"support":15,"x":1,"y":0,"z":0},{"name":"Empty","x":1,"y":1,"z":0},{"name":"Empty","x":1,"y":2,"z":0},{"name":"Empty","x":1,"y":3,"z":0},{"name":"Empty","x":1,"y":4,"z":0},{"name":"Empty","x":1,"y":5,"z":0},{"name":"Empty","x":1,"y":6,"z":0},{"name":"Empty","x":1,"y":7,"z":0},{"name":"Empty","x":1,"y":8,"z":0},{"name":"Empty","x":1,"y":9,"z":0},{"name":"Empty","x":1,"y":10,"z":0},{"name":"Empty","x":1,"y":11,"z":0},{"name":"Empty","x":1,"y":12,"z":0},{"name":"Empty","x":1,"y":13,"z":0},{"name":"Empty","x":1,"y":14,"z":0},{"name":"Empty","x":1,"y":15,"z":0},{"name":"Empty","x":1,"y":16,"z":0}],"fluids":[{"level":1,"name":"Water_Source","x":-1,"y":0,"z":0},{"level":1,"name":"Water_Source","x":-1,"y":1,"z":0},{"level":1,"name":"Water_Source","x":-1,"y":2,"z":0},{"level":1,"name":"Water_Source","x":-1,"y":3,"z":0},{"level":1,"name":"Water_Source","x":-1,"y":4,"z":0},{"level":1,"name":"Water_Source","x":-1,"y":5,"z":0},{"level":1,"name":"Water_Source","x":-1,"y":6,"z":0},{"level":1,"name":"Water_Source","x":-1,"y":7,"z":0},{"level":1,"name":"Water_Source","x":-1,"y":8,"z":0},{"level":1,"name":"Water_Source","x":-1,"y":9,"z":0},{"level":1,"name":"Water_Source","x":-1,"y":10,"z":0},{"level":1,"name":"Water_Source","x":-1,"y":11,"z":0},{"level":1,"name":"Water_Source","x":-1,"y":12,"z":0},{"level":1,"name":"Water_Source","x":-1,"y":13,"z":0},{"level":1,"name":"Water_Source","x":-1,"y":14,"z":0},{"level":1,"name":"Water_Source","x":-1,"y":15,"z":0},{"level":1,"name":"Water_Source","x":-1,"y":16,"z":0},{"level":1,"name":"Water_Source","x":0,"y":0,"z":-1},{"level":1,"name":"Water_Source","x":0,"y":1,"z":-1},{"level":1,"name":"Water_Source","x":0,"y":2,"z":-1},{"level":1,"name":"Water_Source","x":0,"y":3,"z":-1},{"level":1,"name":"Water_Source","x":0,"y":4,"z":-1},{"level":1,"name":"Water_Source","x":0,"y":5,"z":-1},{"level":1,"name":"Water_Source","x":0,"y":6,"z":-1},{"level":1,"name":"Water_Source","x":0,"y":7,"z":-1},{"level":1,"name":"Water_Source","x":0,"y":8,"z":-1},{"level":1,"name":"Water_Source","x":0,"y":9,"z":-1},{"level":1,"name":"Water_Source","x":0,"y":10,"z":-1},{"level":1,"name":"Water_Source","x":0,"y":11,"z":-1},{"level":1,"name":"Water_Source","x":0,"y":12,"z":-1},{"level":1,"name":"Water_Source","x":0,"y":13,"z":-1},{"level":1,"name":"Water_Source","x":0,"y":14,"z":-1},{"level":1,"name":"Water_Source","x":0,"y":15,"z":-1},{"level":1,"name":"Water_Source","x":0,"y":16,"z":-1},{"level":1,"name":"Water_Source","x":0,"y":-10,"z":0},{"level":1,"name":"Water_Source","x":0,"y":-9,"z":0},{"level":1,"name":"Water_Source","x":0,"y":-8,"z":0},{"level":1,"name":"Water_Source","x":0,"y":-7,"z":0},{"level":1,"name":"Water_Source","x":0,"y":-6,"z":0},{"level":1,"name":"Water_Source","x":0,"y":-5,"z":0},{"level":1,"name":"Water_Source","x":0,"y":-4,"z":0},{"level":1,"name":"Water_Source","x":0,"y":-3,"z":0},{"level":1,"name":"Water_Source","x":0,"y":-2,"z":0},{"level":1,"name":"Water_Source","x":0,"y":-1,"z":0},{"level":1,"name":"Water_Source","x":0,"y":0,"z":0},{"level":1,"name":"Water_Source","x":0,"y":1,"z":0},{"level":1,"name":"Water_Source","x":0,"y":2,"z":0},{"level":1,"name":"Water_Source","x":0,"y":3,"z":0},{"level":1,"name":"Water_Source","x":0,"y":4,"z":0},{"level":1,"name":"Water_Source","x":0,"y":5,"z":0},{"level":1,"name":"Water_Source","x":0,"y":6,"z":0},{"level":1,"name":"Water_Source","x":0,"y":7,"z":0},{"level":1,"name":"Water_Source","x":0,"y":8,"z":0},{"level":1,"name":"Water_Source","x":0,"y":9,"z":0},{"level":1,"name":"Water_Source","x":0,"y":10,"z":0},{"level":1,"name":"Water_Source","x":0,"y":11,"z":0},{"level":1,"name":"Water_Source","x":0,"y":12,"z":0},{"level":1,"name":"Water_Source","x":0,"y":13,"z":0},{"level":1,"name":"Water_Source","x":0,"y":14,"z":0},{"level":1,"name":"Water_Source","x":0,"y":15,"z":0},{"level":1,"name":"Water_Source","x":0,"y":16,"z":0},{"level":1,"name":"Water_Source","x":0,"y":0,"z":1},{"level":1,"name":"Water_Source","x":0,"y":1,"z":1},{"level":1,"name":"Water_Source","x":0,"y":2,"z":1},{"level":1,"name":"Water_Source","x":0,"y":3,"z":1},{"level":1,"name":"Water_Source","x":0,"y":4,"z":1},{"level":1,"name":"Water_Source","x":0,"y":5,"z":1},{"level":1,"name":"Water_Source","x":0,"y":6,"z":1},{"level":1,"name":"Water_Source","x":0,"y":7,"z":1},{"level":1,"name":"Water_Source","x":0,"y":8,"z":1},{"level":1,"name":"Water_Source","x":0,"y":9,"z":1},{"level":1,"name":"Water_Source","x":0,"y":10,"z":1},{"level":1,"name":"Water_Source","x":0,"y":11,"z":1},{"level":1,"name":"Water_Source","x":0,"y":12,"z":1},{"level":1,"name":"Water_Source","x":0,"y":13,"z":1},{"level":1,"name":"Water_Source","x":0,"y":14,"z":1},{"level":1,"name":"Water_Source","x":0,"y":15,"z":1},{"level":1,"name":"Water_Source","x":0,"y":16,"z":1},{"level":1,"name":"Water_Source","x":1,"y":0,"z":0},{"level":1,"name":"Water_Source","x":1,"y":1,"z":0},{"level":1,"name":"Water_Source","x":1,"y":2,"z":0},{"level":1,"name":"Water_Source","x":1,"y":3,"z":0},{"level":1,"name":"Water_Source","x":1,"y":4,"z":0},{"level":1,"name":"Water_Source","x":1,"y":5,"z":0},{"level":1,"name":"Water_Source","x":1,"y":6,"z":0},{"level":1,"name":"Water_Source","x":1,"y":7,"z":0},{"level":1,"name":"Water_Source","x":1,"y":8,"z":0},{"level":1,"name":"Water_Source","x":1,"y":9,"z":0},{"level":1,"name":"Water_Source","x":1,"y":10,"z":0},{"level":1,"name":"Water_Source","x":1,"y":11,"z":0},{"level":1,"name":"Water_Source","x":1,"y":12,"z":0},{"level":1,"name":"Water_Source","x":1,"y":13,"z":0},{"level":1,"name":"Water_Source","x":1,"y":14,"z":0},{"level":1,"name":"Water_Source","x":1,"y":15,"z":0},{"level":1,"name":"Water_Source","x":1,"y":16,"z":0}],"version":8}